File: Data/3-Raman/processed/bu02aw-a-ff1-fi04-v_1800 (450-850nm)_532nm_edge_100%_x100_vis_lwd_h100um_30sx2_01.txt
#Acq. time (s)=	30
#Accumulations=	2
#Range (cm-¹)=	1200...2365
#Windows=	3
#Auto scanning=	Off
#Autofocus=	Off
#Macrospot=	Off
#AutoExposure=	Off
#Spike filter=	Multiple accum.
#Delay time (s)=	2
#Binning=	1
#Readout mode=	Signal
#DeNoise=	Off
#ICS correction=	On
#Dark correction=	Off
#Inst. Process=	Off
#Detector Gain=	Best Dynamic
#Detector ADC=	50 kHz HS
#Detector temperature (°C)=	-60.09
#Instrument=	LabRAM HR Evol
#Detector=	SIN-EM FIVIS
#Objective=	x100_VIS_LWD
#Grating=	1800 (450-850nm)
#ND Filter=	100%
#Laser=	532nm_Edge
#Hole=	100.021
#Temperature=	0
#Range=	Visible
#StageXY=	75x50mm Scan+
#StageZ=	Z motor
#X (µm)=	0
#Y (µm)=	0
#Z (µm)=	-16.5
#Full time(mm:ss)=	3:18
#Project=	21_11_26
#Sample=	BU02Aw
#Site=
#Title=	BU02aW-A-FF1-FI04-S_1800 (450-850nm)_532nm_Edge_100%_x100_VIS_LWD_H100um_30sX2
#Remark=
#Date=	26.11.2021 11:05
#Acquired=	26.11.2021 11:05:18
#Base:Fit=	16.12.2021 16:15:35
#Base:Fit=	16.12.2021 16:19:21
#Base:Sub=	16.12.2021 16:19:22
1202.72	0.408371
1203.84	-1.41541
1204.95	4.19141
1206.06	1.12496
1207.17	0.162498
1208.28	-6.11302
1209.39	0.438553
1210.5	-7.96292
1211.61	1.71714
1212.72	-0.359604
1213.83	2.90491
1214.94	-0.182556
1216.05	-0.0944519
1217.16	2.02451
1218.27	-3.28542
1219.38	0.981369
1220.49	6.30504
1221.6	-2.16357
1222.71	2.01685
1223.81	-0.202778
1224.92	6.06554
1226.03	-6.60198
1227.14	-0.290028
1228.25	-4.6656
1229.35	4.62429
1230.46	0.562775
1231.57	2.44283
1232.67	-2.85615
1233.78	1.28111
1234.89	-0.852203
1235.99	-7.19304
1237.1	-0.96545
1238.2	3.08212
1239.31	-3.36285
1240.41	-2.41341
1241.52	4.85094
1242.62	6.83748
1243.73	5.72631
1244.83	3.54162
1245.94	5.48386
1247.04	3.26027
1248.14	10.4773
1249.25	4.06641
1250.35	1.87959
1251.45	-0.364685
1252.56	4.71515
1253.66	11.8765
1254.76	1.38557
1255.87	12.7897
1256.97	7.49163
1258.07	12.6034
1259.17	24.9969
1260.27	15.5668
1261.37	28.9502
1262.48	34.2987
1263.58	82.9535
1264.68	125.19
1265.78	67.4464
1266.88	30.7924
1267.98	19.3043
1269.08	26.6776
1270.18	19.2744
1271.28	22.2646
1272.38	25.348
1273.47	14.916
1274.57	18.0815
1275.67	18.0346
1276.77	21.1952
1277.87	24.3696
1278.97	29.6641
1280.07	40.1571
1281.16	66.4153
1282.26	182.255
1283.36	648.204
1284.45	1931.37
1285.55	927.972
1286.65	159.087
1287.75	60.0256
1288.84	42.0855
1289.94	26.3429
1291.03	16.8804
1292.13	18.9722
1293.22	13.7006
1294.32	14.8571
1295.42	11.719
1296.51	7.66908
1297.61	6.61555
1298.7	12.9277
1299.79	5.51707
1300.89	7.6762
1301.98	-2.84455
1303.08	5.65587
1304.17	3.55232
1305.26	4.64086
1306.35	3.56737
1307.45	3.60097
1308.54	-1.61705
1309.63	-1.54282
1310.73	2.74648
1311.82	7.04034
1312.91	2.91702
1314	10.3524
1315.09	1.98572
1316.18	-4.24106
1317.28	0.0511017
1318.37	0.153809
1319.46	4.46767
1320.55	-2.83856
1321.64	-1.73599
1322.73	0.409286
1323.82	1.53725
1324.91	-2.57652
1326	-2.51535
1327.09	-0.409592
1328.18	6.13412
1329.27	-5.27374
1330.35	2.21719
1331.44	8.60148
1332.53	5.45709
1333.62	-5.02557
1334.71	3.43146
1335.79	-0.694603
1336.88	3.58908
1337.97	3.69362
1339.06	-3.55623
1340.14	-0.280785
1341.23	6.14645
1342.32	7.30697
1343.4	2.15747
1344.49	3.34159
1345.58	7.6378
1346.66	2.46677
1347.75	4.62265
1348.83	-3.59477
1349.92	9.01319
1351	2.86817
1352.09	6.09518
1353.17	8.37712
1354.25	5.48294
1355.34	1.32945
1356.42	8.7575
1357.51	2.65467
1358.59	9.00506
1359.67	9.12062
1360.76	12.3278
1361.84	13.5077
1362.92	9.50594
1364	21.0918
1365.09	22.293
1366.17	23.4271
1367.25	17.3047
1368.33	13.339
1369.41	47.6508
1370.5	72.6018
1371.58	36.5164
1372.66	31.3941
1373.74	27.3834
1374.82	38.863
1375.9	42.1249
1376.98	41.2235
1378.06	46.5093
1379.14	62.3193
1380.22	75.8289
1381.3	83.9551
1382.38	83.9811
1383.46	108.572
1384.54	132.232
1385.61	206.472
1386.69	632.066
1387.77	3553.94
1388.85	1686.47
1389.93	272.041
1391	119.965
1392.08	70.8176
1393.16	49.3913
1394.23	50.5452
1395.31	35.3601
1396.39	43.7471
1397.46	30.565
1398.54	28.6691
1399.62	29.8952
1400.69	25.9964
1401.77	29.2722
1402.84	34.6931
1403.92	26.7276
1404.99	29.9117
1406.07	35.1459
1407.14	59.8808
1408.22	93.9078
1409.29	205.899
1410.37	138.413
1411.44	51.2699
1412.51	29.8891
1413.59	17.9418
1414.66	11.8538
1415.73	15.1151
1416.81	10.1521
1417.88	14.4404
1418.95	10.4898
1420.02	9.59356
1421.1	9.68992
1422.17	9.83754
1423.24	9.07981
1424.31	18.2505
1425.38	7.11195
1426.45	11.3694
1427.52	10.4191
1428.59	12.5436
1429.67	9.62298
1430.74	9.80711
1431.81	2.8303
1432.87	8.05846
1433.95	1.95313
1435.01	3.12125
1436.08	2.22025
1437.15	0.277649
1438.22	3.45738
1439.29	5.64375
1440.36	0.675526
1441.43	-0.220589
1442.49	3.98954
1443.56	4.09893
1444.63	2.14829
1445.7	3.32334
1446.77	7.51606
1447.83	2.47429
1448.9	3.61934
1449.97	2.6879
1451.03	0.713684
1452.1	4.89348
1453.17	1.9141
1454.23	8.16592
1455.3	-4.04093
1456.36	1.18586
1457.43	1.25579
1458.49	-3.78593
1459.56	-0.617985
1460.62	-3.61327
1461.69	-3.54962
1462.75	-3.49866
1463.82	1.65388
1464.88	-2.308
1465.94	-0.322361
1467.01	3.81837
1468.07	2.8628
1469.13	-0.132717
1470.2	-5.19009
1471.26	3.00693
1472.32	-0.00845337
1473.39	-0.969803
1474.45	-1.94667
1475.51	2.19364
1476.57	2.23627
1477.63	-0.78056
1478.69	0.275738
1479.76	-0.715702
1480.82	-0.711308
1481.88	-1.69071
1482.94	-4.65456
1484	4.54139
1485.06	2.45724
1486.12	0.462505
1487.18	2.53866
1488.24	-4.53264
1489.3	0.534626
1490.36	-4.49645
1491.42	0.575531
1492.48	-1.41412
1493.53	-5.42767
1494.59	-0.340069
1495.65	-3.35736
1496.71	0.671124
1497.77	-1.33016
1498.82	-3.32203
1499.88	-1.26578
1500.94	5.83092
1502	-2.23767
1503.05	-2.23034
1504.11	-2.22955
1505.17	1.82982
1506.22	-1.21501
1507.28	0.823036
1508.34	-5.20465
1509.39	-1.15679
1510.45	4.91254
1511.5	-3.17357
1512.56	-0.227573
1513.61	1.74253
1514.67	-2.23435
1515.72	-0.254169
1516.78	0.716579
1517.83	-2.29036
1518.88	-2.26672
1519.94	2.76798
1520.99	-2.24863
1522.05	2.78065
1523.1	4.76968
1524.15	4.71584
1525.2	-1.3123
1526.26	-3.29653
1527.31	0.735493
1528.36	-0.284302
1529.41	-2.30552
1530.47	-0.317314
1531.52	-0.290596
1532.57	-0.300835
1533.62	-0.257313
1534.67	1.75118
1535.72	-2.28673
1536.77	-5.35596
1537.82	3.5964
1538.87	-3.43816
1539.92	-5.38602
1540.97	-9.33956
1542.02	1.65221
1543.07	2.59767
1544.12	2.53316
1545.17	-5.45279
1546.22	-1.41841
1547.27	2.5871
1548.32	0.548161
1549.37	1.51029
1550.42	3.51641
1551.46	-0.369297
1552.51	2.63113
1553.56	-1.431
1554.61	3.53589
1555.65	3.47852
1556.7	3.46014
1557.75	2.4514
1558.79	1.39699
1559.84	2.32874
1560.89	-1.7081
1561.93	3.28257
1562.98	3.29333
1564.02	-5.73081
1565.07	-3.71313
1566.11	2.98198
1567.16	2.1699
1568.2	-3.80677
1569.25	2.18645
1570.29	-0.851486
1571.34	1.13
1572.38	5.08811
1573.43	-2.94531
1574.47	-2.96573
1575.51	-0.941826
1576.56	3.04586
1577.6	0.976322
1578.64	2.90076
1579.69	2.88185
1580.73	3.87809
1581.77	2.84373
1582.81	-0.187416
1583.85	3.77296
1584.9	2.76464
1585.94	-1.23651
1586.98	2.69638
1588.02	9.62833
1589.06	5.65283
1590.1	2.67192
1591.14	-1.31107
1592.18	1.65368
1593.22	-1.38791
1594.26	-0.471367
1595.3	1.51203
1596.34	4.46352
1597.38	1.47778
1598.42	4.4493
1599.46	3.40132
1600.5	0.381836
1601.54	6.26595
1602.58	6.20386
1603.62	-2.75146
1604.66	4.15129
1605.69	-0.796345
1606.73	3.17365
1607.77	5.07976
1608.81	3.86926
1609.84	-0.704067
1610.88	5.01661
1611.92	7.41142
1612.95	5.53841
1613.99	4.66468
1615.03	0.768204
1616.06	7.1803
1617.1	8.1815
1618.13	4.83451
1619.17	4.71811
1620.2	6.02446
1621.24	2.91008
1622.27	4.6402
1623.31	4.73603
1624.34	5.25955
1625.38	5.10939
1626.41	6.52322
1627.45	7.89072
1628.48	6.02098
1629.51	9.44434
1630.55	7.34316
1631.53	6.29607
1632.57	5.33889
1633.62	3.36815
1634.66	4.37098
1635.71	12.2571
1636.75	6.32735
1637.8	10.2429
1638.84	7.28035
1639.89	3.35113
1640.93	12.229
1641.98	2.393
1643.02	3.37709
1644.06	4.36365
1645.11	3.3693
1646.15	7.33239
1647.19	2.40535
1648.24	10.2699
1649.28	5.4133
1650.32	8.37893
1651.37	11.3996
1652.41	7.48444
1653.45	2.56178
1654.49	-2.33847
1655.53	6.57108
1656.57	7.6311
1657.62	6.66371
1658.66	6.6639
1659.7	5.66671
1660.74	-5.16677
1661.78	5.73727
1662.82	6.80531
1663.86	5.84566
1664.9	5.83358
1665.94	7.76111
1666.98	-1.03273
1668.02	3.90101
1669.06	1.96174
1670.1	1.03417
1671.14	5.04904
1672.18	4.07784
1673.21	2.13313
1674.25	4.1497
1675.29	6.18507
1676.33	9.19476
1677.37	8.23945
1678.4	-0.660477
1679.44	5.27155
1680.48	1.33032
1681.52	2.33306
1682.55	0.387451
1683.59	3.37989
1684.63	6.36293
1685.66	3.4234
1686.7	4.44917
1687.73	6.47081
1688.77	5.4949
1689.81	2.53343
1690.84	-0.403378
1691.88	1.62219
1692.91	-0.321033
1693.95	-1.31486
1694.98	4.59885
1696.01	0.702465
1697.05	-3.18927
1698.08	1.73842
1699.12	3.71241
1700.15	-3.13935
1701.18	-0.160339
1702.22	2.80557
1703.25	-2.09797
1704.28	-0.10445
1705.32	0.926937
1706.35	-0.0256042
1707.38	-1.99034
1708.41	-1.01668
1709.44	-1.0293
1710.48	2.91805
1711.51	1.99665
1712.54	3.02052
1713.57	0.0569801
1714.6	0.0526161
1715.63	4.97903
1716.66	-5.72498
1717.69	-0.852814
1718.72	-0.880844
1719.75	3.04019
1720.78	6.00187
1721.81	1.13813
1722.84	1.13704
1723.87	-1.76597
1724.9	-5.6186
1725.93	0.188797
1726.96	1.18531
1727.99	-0.721519
1729.02	5.03842
1730.05	-4.62516
1731.07	3.11814
1732.1	-4.51422
1733.13	0.343822
1734.16	-4.49376
1735.18	5.13676
1736.21	-1.60379
1737.24	2.26964
1738.26	-0.597534
1739.29	-3.47271
1740.32	2.2662
1741.34	-1.57488
1742.37	0.355194
1743.4	0.385815
1744.42	-4.37578
1745.45	7.13808
1746.47	-2.3988
1747.5	1.42184
1748.52	-5.24319
1749.55	1.49225
1750.57	-2.25097
1751.6	-6.01457
1752.62	0.679543
1753.64	1.63971
1754.67	-3.11967
1755.69	-2.14535
1756.71	-1.18696
1757.74	0.714077
1758.76	-1.13324
1759.78	1.76725
1760.81	2.74787
1761.83	2.75954
1762.85	0.895741
1763.87	1.89231
1764.89	1.01416
1765.92	-5.59064
1766.94	-0.793865
1767.96	3.03974
1768.98	2.10841
1770	1.11774
1771.02	-0.721127
1772.04	-0.649105
1773.06	-0.587605
1774.08	1.37162
1775.1	1.42274
1776.12	0.548084
1777.14	-4.1817
1778.16	3.45115
1779.18	2.49724
1780.2	2.52491
1781.22	2.57434
1782.24	-1.18744
1783.26	0.779182
1784.28	-2.02589
1785.29	0.896049
1786.31	-0.0361786
1787.33	2.87873
1788.35	2.99418
1789.37	-3.61319
1790.38	2.20211
1791.4	2.22693
1792.42	0.307632
1793.43	-0.608105
1794.45	3.26208
1795.47	0.452522
1796.48	-0.433437
1797.5	-4.21844
1798.51	-0.32737
1799.53	-2.22775
1800.55	-2.2281
1801.56	0.667027
1802.58	0.700008
1803.59	4.59942
1804.61	3.68165
1805.62	0.854179
1806.64	0.90974
1807.65	-6.76757
1808.66	3.85814
1809.68	2.92123
1810.69	-1.87376
1811.7	6.817
1812.72	-2.79882
1813.73	2.06298
1814.74	4.05088
1815.76	-1.69632
1816.77	-1.67126
1817.78	-0.712353
1818.79	6.07323
1819.8	0.302563
1820.82	6.13769
1821.83	1.33683
1822.84	0.399284
1823.85	-1.52443
1824.86	0.424828
1825.87	-2.45452
1826.88	-1.4734
1827.89	4.36043
1828.9	1.46172
1829.91	1.45709
1830.92	-0.48777
1831.93	4.37727
1832.94	1.50306
1833.95	4.4287
1834.96	1.49791
1835.97	2.40647
1836.98	4.5083
1837.99	-1.43554
1839	7.27381
1840	1.52636
1841.01	2.4135
1842.02	-2.49046
1843.03	4.22955
1844.04	5.1935
1845.04	2.29966
1846.05	5.2051
1847.06	-2.48061
1848.07	1.23821
1849.07	2.20496
1850.08	0.243973
1851.09	4.03308
1852.09	0.157391
1853.1	3.02929
1854.1	6.84449
1855.11	4.87014
1856.11	3.86081
1857.12	5.76092
1858.12	5.7342
1859.13	6.64323
1860.13	1.81961
1861.14	-1.99961
1862.14	6.62202
1863.15	3.70974
1864.15	0.791389
1865.15	6.47589
1866.16	7.3558
1867.16	5.35672
1868.16	4.33303
1869.17	2.41032
1870.17	3.33621
1871.17	2.36107
1872.17	9.92757
1873.18	6.08051
1874.18	14.5846
1875.18	9.7734
1876.18	7.78598
1877.18	8.66002
1878.18	2.90143
1879.19	6.73539
1880.19	13.3786
1881.19	7.66885
1882.19	8.52033
1883.19	1.78989
1884.19	8.3166
1885.19	11.1453
1886.19	11.1858
1887.19	14.929
1888.19	4.47517
1889.19	8.15472
1890.19	10.9235
1891.19	10.9276
1892.18	9.00457
1893.18	13.66
1894.18	7.90829
1895.18	6.91649
1896.18	5.96179
1897.18	6.90224
1898.17	16.2903
1899.17	4.00385
1900.17	10.5174
1901.16	6.72555
1902.16	11.4306
1903.16	0.1301
1904.16	12.304
1905.15	5.6801
1906.15	2.80784
1907.14	8.3765
1908.14	6.46908
1909.14	-2.00282
1910.13	12.1048
1911.13	14.9586
1912.12	6.46051
1913.12	8.29935
1914.11	3.57423
1915.11	8.2966
1916.1	3.5592
1917.1	1.61229
1918.09	10.0371
1919.08	4.37194
1920.08	5.34146
1921.07	5.31074
1922.06	10.0376
1923.06	5.26247
1924.05	8.9833
1925.04	4.19459
1926.04	5.13078
1927.03	8.92867
1928.02	8.91932
1929.01	3.21444
1930	5.10655
1931	3.21639
1931.99	4.11887
1932.98	3.10149
1933.97	4.01557
1934.96	5.05778
1935.95	5.11824
1936.94	5.03008
1937.93	5.89789
1938.92	3.9481
1939.91	1.07322
1940.9	4.87292
1941.89	-0.852535
1942.88	6.75834
1943.87	10.5022
1944.86	5.72236
1945.85	2.85806
1946.84	7.62638
1947.83	2.79335
1948.82	1.78725
1949.8	2.72835
1950.79	-0.126873
1951.78	1.81366
1952.77	2.76608
1953.76	2.72694
1954.74	8.33716
1955.73	1.55959
1956.72	4.4697
1957.7	3.50952
1958.69	-0.355888
1959.68	8.23322
1960.66	0.479752
1961.65	-1.51455
1962.63	2.2811
1963.62	1.28407
1964.61	1.25388
1965.59	-0.715984
1966.58	1.18416
1967.56	1.16124
1968.55	-1.75903
1969.53	2.97871
1970.52	3.84304
1971.5	-3.90303
1972.48	-2.98796
1973.47	-3.04046
1974.45	-3.10976
1975.44	-0.274078
1976.42	-2.21303
1977.4	-0.334709
1978.39	-0.399769
1979.37	1.46058
1980.35	-5.2881
1981.33	2.31319
1982.31	-0.619232
1983.3	-0.687893
1984.28	5.93594
1985.26	3.95879
1986.24	1.98976
1987.22	0.0520782
1988.21	-0.977127
1989.19	-1.07265
1990.17	2.49228
1991.15	-3.66719
1992.13	4.10682
1993.11	-1.37146
1994.09	-0.694138
1995.07	2.84325
1996.05	-1.61946
1997.03	0.717819
1998.01	0.938034
1998.99	2.06432
1999.97	-1.32071
2000.95	-0.649342
2001.92	-2.88742
2002.9	-1.02785
2003.88	0.12402
2004.86	0.562546
2005.84	-0.892689
2006.81	4.21593
2007.79	1.14758
2008.77	0.581825
2009.75	0.0855141
2010.73	-1.50194
2011.7	-1.91036
2012.68	1.65445
2013.67	1.56824
2014.66	-0.418571
2015.64	-3.28618
2016.63	2.33327
2017.62	-1.42659
2018.61	-4.33233
2019.6	0.260212
2020.58	0.208954
2021.57	3.92556
2022.56	0.135471
2023.55	0.062809
2024.54	2.79819
2025.52	0.837914
2026.51	0.770504
2027.5	-3.81403
2028.48	0.779743
2029.47	-5.7253
2030.45	-1.20971
2031.44	-3.08434
2032.43	1.56223
2033.41	-0.273823
2034.4	4.37848
2035.38	-1.3239
2036.37	4.35666
2037.35	-2.22912
2038.34	0.537582
2039.32	0.483887
2040.31	-0.513519
2041.29	-0.582294
2042.27	2.16929
2043.26	1.19401
2044.24	-2.50568
2045.23	0.242725
2046.21	-0.61932
2047.19	-5.35038
2048.17	1.10173
2049.16	2.02472
2050.14	-3.54387
2051.12	-4.4669
2052.11	-3.57742
2053.09	1.08677
2054.07	-3.55737
2055.05	-4.49842
2056.03	1.07253
2057.01	4.77747
2058	-1.77343
2058.98	1.98553
2059.96	-0.817783
2060.94	0.0839195
2061.92	1.02176
2062.9	4.7618
2063.88	1.02858
2064.86	0.0932503
2065.84	-3.63208
2066.82	2.95179
2067.8	3.89747
2068.78	0.146183
2069.76	3.87758
2070.73	-3.65872
2071.71	-0.824677
2072.69	0.166714
2073.67	1.0862
2074.65	-1.74085
2075.63	-2.6417
2076.6	1.16917
2077.58	-1.69797
2078.56	0.165325
2079.54	0.179005
2080.51	-3.56573
2081.49	-3.57891
2082.47	-0.756119
2083.45	-1.70638
2084.42	1.11421
2085.4	6.77538
2086.37	5.83679
2087.35	-1.70202
2088.32	-3.59237
2089.3	-2.64869
2090.28	-0.734245
2091.25	1.166
2092.23	0.24464
2093.2	0.294067
2094.18	-0.620911
2095.15	-0.62104
2096.13	4.09476
2097.1	-2.57716
2098.07	4.03233
2099.05	2.11303
2100.02	3.99533
2101	-1.69835
2101.97	-1.67844
2102.94	-1.69011
2103.92	-2.67023
2104.89	0.179047
2105.86	2.10385
2106.83	4.01957
2107.8	-2.6399
2108.78	-0.791775
2109.75	2.99993
2110.72	-2.6967
2111.69	2.9919
2112.66	-1.77879
2113.63	2.04007
2114.61	2.04031
2115.58	3.93356
2116.55	2.00369
2117.52	2.92771
2118.49	0.0537949
2119.46	-1.89658
2120.43	2.8008
2121.4	-0.985962
2122.37	0.94529
2123.34	-0.932293
2124.31	3.80342
2125.28	-1.00943
2126.25	-3.91984
2127.21	2.65502
2128.18	3.57289
2129.15	-2.11428
2130.12	-1.18713
2131.09	0.682037
2132.06	-1.24099
2133.02	-0.331947
2133.99	4.37735
2134.96	0.597664
2135.93	-0.363663
2136.89	-4.18526
2137.86	7.1305
2138.83	0.505131
2139.79	5.22229
2140.76	-4.24959
2141.73	3.26546
2142.69	3.23114
2143.66	-1.44916
2144.62	5.03387
2145.59	-0.6138
2146.55	-1.5713
2147.52	3.09966
2148.48	5.88405
2149.45	-3.54433
2150.42	1.08367
2151.38	-1.74979
2152.34	2.95173
2153.31	-3.63776
2154.27	-1.79617
2155.24	3.744
2156.2	0.862782
2157.16	-0.0997276
2158.13	-1.0265
2159.09	2.70793
2160.05	2.66778
2161.01	2.61075
2161.98	-1.15045
2162.94	-0.232002
2163.9	1.60052
2164.86	-2.17363
2165.83	0.608829
2166.79	1.51815
2167.75	-2.25427
2168.71	4.17815
2169.67	-3.25641
2170.63	2.37156
2171.59	-0.448418
2172.56	2.24814
2173.51	1.28738
2174.48	-1.50155
2175.44	2.20285
2176.4	1.24811
2177.36	-1.56834
2178.32	-2.50982
2179.28	0.23354
2180.23	-2.56451
2181.19	-2.58778
2182.15	-5.40258
2183.11	-2.65134
2184.07	0.998383
2185.03	0.0397644
2185.99	-1.8133
2186.95	-0.865814
2187.9	-2.6893
2188.86	-2.72547
2189.82	3.70129
2190.78	-0.973431
2191.73	-0.980942
2192.69	1.79947
2193.65	-2.83014
2194.6	0.00499344
2195.56	1.8406
2196.52	0.843678
2197.47	-4.78614
2198.43	1.68778
2199.38	-1.06182
2200.34	3.63578
2201.3	-1.88666
2202.25	-1.12891
2203.21	2.65192
2204.16	1.87917
2205.12	-1.0271
2206.07	4.4193
2207.03	3.46467
2207.98	-1.1762
2208.93	-7.67613
2209.89	-0.233936
2210.84	1.62149
2211.8	-0.232208
2212.75	-0.222115
2213.7	-0.263588
2214.66	1.6042
2215.61	-0.252323
2216.56	-0.270863
2217.51	-2.16504
2218.47	-4.05085
2219.42	-0.315987
2220.37	-0.312775
2221.32	2.45898
2222.27	-3.21055
2223.23	-2.29601
2224.18	-1.34455
2225.13	0.554382
2226.08	4.32581
2227.03	-4.08925
2227.98	1.53942
2228.93	-1.30704
2229.88	-0.388332
2230.83	5.26285
2231.78	-1.28628
2232.73	-3.15113
2233.68	5.32827
2234.63	2.50414
2235.58	0.564468
2236.53	-0.403889
2237.48	2.41616
2238.43	1.52392
2239.38	4.39351
2240.33	4.35009
2241.27	-0.363976
2242.22	3.40356
2243.17	-0.375034
2244.12	-0.414276
2245.07	-2.30084
2246.01	5.2977
2246.96	-0.360752
2247.91	-5.0906
2248.85	-2.27901
2249.8	-6.0823
2250.75	2.4058
2251.69	3.29372
2252.64	-0.494308
2253.59	-3.28391
2254.53	2.42814
2255.48	2.41647
2256.42	2.41281
2257.37	-0.415508
2258.32	-1.35789
2259.26	1.4926
2260.2	1.49958
2261.15	4.35989
2262.1	-3.23297
2263.04	4.39267
2263.98	-1.27921
2264.93	-2.18024
2265.87	0.702892
2266.81	-2.19869
2267.76	-5.10986
2268.7	-2.28834
2269.65	1.54676
2270.59	-1.2674
2271.53	0.668163
2272.47	1.64248
2273.42	3.55557
2274.36	-2.1849
2275.3	-1.22594
2276.24	0.692139
2277.18	0.729553
2278.13	4.62716
2279.07	-1.10664
2280.01	-1.14822
2280.95	-0.242775
2281.89	2.60426
2282.83	-2.16824
2283.77	0.761387
2284.71	-3.96971
2285.65	2.79271
2286.59	-3.97363
2287.54	-0.0748901
2288.47	-0.0540428
2289.41	-0.093895
2290.35	8.49565
2291.29	2.73061
2292.23	-1.06716
2293.17	1.86336
2294.11	-1.00147
2295.05	-1.98898
2295.99	3.76377
2296.93	1.79922
2297.86	-0.0903244
2298.8	0.925602
2299.74	-4.81467
2300.68	-1.91325
2301.61	4.87328
2302.55	-0.913525
2303.49	-1.87837
2304.43	5.86401
2305.36	-1.82324
2306.3	-1.7981
2307.24	-0.815449
2308.17	1.10965
2309.11	1.11166
2310.04	-1.73592
2310.98	2.15772
2311.92	-3.70758
2312.85	1.08519
2313.79	2.07458
2314.72	-0.748798
2315.66	7.02959
2316.59	-2.69035
2317.52	1.16484
2318.46	0.218491
2319.39	-2.69656
2320.33	2.12434
2321.26	3.11479
2322.2	1.23899
2323.13	6.11572
2324.06	8.07508
2325	17.7363
2325.93	16.709
2326.86	43.6809
2327.79	124.599
2328.73	355.899
2329.66	118.694
2330.59	30.0788
2331.52	13.7055
2332.46	3.13574
2333.39	6.00111
2334.32	-5.56433
2335.25	-3.66268
2336.18	0.19223
2337.11	3.07125
2338.04	4.98858
2338.97	7.86668
2339.91	1.14419
2340.84	1.12021
2341.77	0.102837
2342.7	0.0653496
2343.63	0.0564651
2344.56	0.055027
2345.49	-2.83094
2346.41	0.959488
2347.34	-1.93156
2348.27	-0.981651
2349.2	-1.94286
2350.13	1.80021
2351.06	0.596821
2351.99	0.780628
2352.91	-1.21835
2353.84	-1.30551
2354.77	-1.32427
2355.7	4.37215
2356.63	-0.450909
2357.55	-0.538132
2358.48	0.354885
2359.41	-0.651119
2360.33	0.234951
2361.26	1.09868
2362.19	1.00613
2363.11	-1.9283
2364.04	1.78086
2364.97	0.754139