File: Data/3-Raman/processed/bu02aw-a-ff1-fi01-v_1800 (450-850nm)_532nm_edge_100%_x100_vis_lwd_h50um_30sx2_01.txt
#Acq. time (s)=	30
#Accumulations=	2
#Range (cm-¹)=	1200...2365
#Windows=	3
#Auto scanning=	Off
#Autofocus=	Off
#Macrospot=	Off
#AutoExposure=	Off
#Spike filter=	Multiple accum.
#Delay time (s)=	2
#Binning=	1
#Readout mode=	Signal
#DeNoise=	Off
#ICS correction=	On
#Dark correction=	Off
#Inst. Process=	Off
#Detector Gain=	Best Dynamic
#Detector ADC=	50 kHz HS
#Detector temperature (°C)=	-60.09
#Instrument=	LabRAM HR Evol
#Detector=	SIN-EM FIVIS
#Objective=	x100_VIS_LWD
#Grating=	1800 (450-850nm)
#ND Filter=	100%
#Laser=	532nm_Edge
#Hole=	49.98
#Temperature=	0
#Range=	Visible
#StageXY=	75x50mm Scan+
#StageZ=	Z motor
#X (µm)=	0
#Y (µm)=	0
#Z (µm)=	-10.3
#Full time(mm:ss)=	3:11
#Project=	21_11_26
#Sample=	BU02Aw
#Site=
#Title=	BU02aW-A-FF1-FI01-V_1800 (450-850nm)_532nm_Edge_100%_x100_VIS_LWD_H50um_30sX2
#Remark=
#Date=	26.11.2021 10:39
#Acquired=	26.11.2021 10:39:57
#Base:Fit=	16.12.2021 16:15:35
#Base:Fit=	16.12.2021 16:17:26
#Base:Sub=	16.12.2021 16:17:28
1202.72	-0.0367336
1203.84	2.04509
1204.95	-0.205627
1206.06	3.96999
1207.17	4.90321
1208.28	3.718
1209.39	2.53477
1210.5	-0.768169
1211.61	-0.890213
1212.72	3.25489
1213.83	3.14399
1214.94	0.927099
1216.05	-2.35514
1217.16	0.715366
1218.27	-0.460306
1219.38	-2.68189
1220.49	0.406916
1221.6	-2.8654
1222.71	-0.860975
1223.81	2.18059
1224.92	2.0665
1226.03	-0.123425
1227.14	0.847639
1228.25	-1.40051
1229.35	2.66379
1230.46	-1.54658
1231.57	-0.644276
1232.67	0.331366
1233.78	0.2514
1234.89	1.23989
1235.99	0.129763
1237.1	1.1037
1238.2	5.19609
1239.31	-2.25122
1240.41	-1.27946
1241.52	-1.34284
1242.62	-3.51379
1243.73	0.62319
1244.83	-1.53603
1245.94	0.472862
1247.04	0.396963
1248.14	1.37807
1249.25	-0.787645
1250.35	4.38547
1251.45	1.16675
1252.56	-0.99612
1253.66	-1.06697
1254.76	-2.14564
1255.87	-0.101656
1256.97	6.12426
1258.07	1.89301
1259.17	6.00771
1260.27	4.94298
1261.37	6.95045
1262.48	8.03416
1263.58	16.2385
1264.68	28.8987
1265.78	13.1314
1266.88	3.69234
1267.98	11.0145
1269.08	2.65698
1270.18	7.86505
1271.28	8.8487
1272.38	11.9659
1273.47	8.8461
1274.57	5.7123
1275.67	8.84127
1276.77	5.70004
1277.87	6.76023
1278.97	8.87856
1280.07	14.1286
1281.16	22.5293
1282.26	32.0243
1283.36	105.634
1284.45	332.619
1285.55	172.102
1286.65	29.9048
1287.75	13.0313
1288.84	5.64786
1289.94	3.55836
1291.03	2.51118
1292.13	5.66544
1293.22	2.50373
1294.32	1.48942
1295.42	2.55362
1296.51	1.56783
1297.61	3.68155
1298.7	2.61244
1299.79	-2.67545
1300.89	1.56454
1301.98	-2.6457
1303.08	-0.515282
1304.17	-3.68234
1305.26	-0.504642
1306.35	1.5942
1307.45	1.60332
1308.54	0.566896
1309.63	1.64825
1310.73	-0.43915
1311.82	5.91709
1312.91	-0.381344
1314	2.79751
1315.09	0.711321
1316.18	2.86244
1317.28	4.99329
1318.37	3.97265
1319.46	2.94369
1320.55	-1.25494
1321.64	2.97615
1322.73	-2.29825
1323.82	-2.27849
1324.91	0.916452
1326	-0.126236
1327.09	0.90999
1328.18	-1.11422
1329.27	0.00736046
1330.35	0.0373688
1331.44	0.0476055
1332.53	-1.01123
1333.62	5.29489
1334.71	0.0433884
1335.79	1.10584
1336.88	2.17367
1337.97	1.15171
1339.06	0.120188
1340.14	2.25294
1341.23	4.38999
1342.32	3.37117
1343.4	4.43046
1344.49	0.285528
1345.58	2.40479
1346.66	5.53607
1347.75	0.325096
1348.83	-0.687031
1349.92	1.41996
1351	4.56293
1352.09	0.423788
1353.17	2.56748
1354.25	4.7264
1355.34	-0.499466
1356.42	2.66045
1357.51	1.65306
1358.59	3.75652
1359.67	2.74393
1360.76	2.76178
1361.84	-0.308069
1362.92	-0.270992
1364	4.96444
1365.09	8.11759
1366.17	10.2046
1367.25	9.1781
1368.33	10.2586
1369.41	11.351
1370.5	16.5572
1371.58	6.24117
1372.66	10.3665
1373.74	14.5118
1374.82	13.5172
1375.9	13.5648
1376.98	24.9222
1378.06	30.0995
1379.14	33.3335
1380.22	40.5652
1381.3	51.7879
1382.38	53.8093
1383.46	56.8202
1384.54	57.8468
1385.61	77.473
1386.69	136.15
1387.77	603.902
1388.85	315.235
1389.93	57.2007
1391	32.5148
1392.08	21.246
1393.16	13.0673
1394.23	15.1472
1395.31	11.0998
1396.39	13.2065
1397.46	12.2112
1398.54	6.11334
1399.62	7.1976
1400.69	7.25627
1401.77	-1.89849
1402.84	11.5187
1403.92	8.52036
1404.99	7.51707
1406.07	7.54201
1407.14	12.7035
1408.22	16.8615
1409.29	38.4568
1410.37	29.2847
1411.44	8.77924
1412.51	8.81783
1413.59	3.81887
1414.66	3.82894
1415.73	6.96634
1416.81	-2.22259
1417.88	2.96911
1418.95	1.98989
1420.02	0.99888
1421.1	5.12758
1422.17	6.19869
1423.24	0.132776
1424.31	1.11792
1425.38	3.2116
1426.45	4.28643
1427.52	3.27387
1428.59	1.2403
1429.67	4.36061
1430.74	0.325415
1431.81	3.47602
1432.87	1.44825
1433.95	0.42449
1435.01	2.52103
1436.08	2.55921
1437.15	3.61329
1438.22	3.64361
1439.29	3.69054
1440.36	0.672293
1441.43	-1.33533
1442.49	-3.35247
1443.56	3.85975
1444.63	1.83926
1445.7	0.868759
1446.77	0.895451
1447.83	2.97124
1448.9	-5.19121
1449.97	-1.05862
1451.03	4.08865
1452.1	1.03799
1453.17	1.06949
1454.23	-0.943737
1455.3	2.16066
1456.36	-1.90145
1457.43	-0.854595
1458.49	1.22126
1459.56	-2.84217
1460.62	2.3071
1461.69	1.30149
1462.75	1.3138
1463.82	-2.76885
1464.88	0.353382
1465.94	-3.77022
1467.01	-1.70798
1468.07	-1.68394
1469.13	-2.67962
1470.2	0.391973
1471.26	0.406406
1472.32	0.419926
1473.39	-0.576258
1474.45	1.47363
1475.51	-0.532593
1476.57	-0.515661
1477.63	2.54874
1478.69	0.530247
1479.76	-1.49321
1480.82	-5.55248
1481.88	-2.49204
1482.94	-1.43929
1484	1.63384
1485.06	-2.44827
1486.12	-1.41923
1487.18	6.71084
1488.24	-2.39758
1489.3	0.642591
1490.36	-1.3664
1491.42	4.70939
1492.48	-0.328405
1493.53	-0.311325
1494.59	1.72939
1495.65	3.75962
1496.71	-0.285246
1497.77	3.76427
1498.82	0.75366
1499.88	-4.27012
1500.94	-2.2317
1502	-2.22223
1503.05	-1.20387
1504.11	-1.19755
1505.17	0.838247
1506.22	0.83382
1507.28	-1.16307
1508.34	1.87599
1509.39	3.9075
1510.45	-0.104052
1511.5	4.92578
1512.56	-1.14233
1513.61	0.856707
1514.67	2.89528
1515.72	-0.123283
1516.78	3.88167
1517.83	0.883606
1518.88	1.90926
1519.94	0.926214
1520.99	2.94297
1522.05	-1.0527
1523.1	-1.04885
1524.15	3.94902
1525.2	5.95316
1526.26	1.96998
1527.31	-2.01446
1528.36	-0.00605011
1529.41	-0.00243378
1530.47	1.00416
1531.52	-0.973164
1532.57	-1.96692
1533.62	0.0715885
1534.67	4.09852
1535.72	3.09456
1536.77	-3.93849
1537.82	3.05403
1538.87	2.04946
1539.92	1.09451
1540.97	-0.862617
1542.02	0.136189
1543.07	8.13337
1544.12	1.10858
1545.17	0.13192
1546.22	1.16456
1547.27	1.17896
1548.32	1.17632
1549.37	1.17204
1550.42	2.1903
1551.46	4.27808
1552.51	2.27972
1553.56	4.27719
1554.61	0.256266
1555.65	4.25199
1556.7	3.25664
1557.75	3.26896
1558.79	-0.747061
1559.84	3.23664
1560.89	0.233932
1561.93	6.24357
1562.98	0.26606
1564.02	2.26963
1565.07	5.29901
1566.11	0.169619
1567.16	1.2684
1568.2	3.29335
1569.25	4.30691
1570.29	-0.695347
1571.34	3.3091
1572.38	6.30182
1573.43	3.29727
1574.47	2.30395
1575.51	5.33224
1576.56	3.34489
1577.6	6.31706
1578.64	3.30109
1579.69	4.30364
1580.73	3.32146
1581.77	5.31107
1582.81	10.2843
1583.85	4.30918
1584.9	6.30996
1585.94	5.31976
1586.98	4.31123
1588.02	6.29848
1589.06	5.3203
1590.1	4.34219
1591.14	7.34471
1592.18	5.35452
1593.22	5.3366
1594.26	6.29837
1595.3	3.33017
1596.34	6.30856
1597.38	2.34575
1598.42	4.34113
1599.46	4.32552
1600.5	2.33163
1601.54	7.2669
1602.58	8.23521
1603.62	8.21672
1604.66	5.25147
1605.69	7.23927
1606.73	14.185
1607.77	9.2474
1608.81	6.15869
1609.84	5.6573
1610.88	7.38575
1611.92	4.90549
1612.95	6.80579
1613.99	7.08815
1615.03	9.95331
1616.06	9.662
1617.1	8.71446
1618.13	7.14426
1619.17	7.5225
1620.2	7.99458
1621.24	5.31859
1622.27	8.96599
1623.31	8.91798
1624.34	8.23041
1625.38	7.76259
1626.41	10.5611
1627.45	8.41067
1628.48	6.49862
1629.51	9.86674
1630.55	7.90324
1631.53	7.46201
1632.57	14.3822
1633.62	13.4019
1634.66	10.4619
1635.71	11.4531
1636.75	10.4619
1637.8	7.49799
1638.84	10.4505
1639.89	13.4121
1640.93	9.48868
1641.98	10.4818
1643.02	10.4838
1644.06	11.4714
1645.11	10.482
1646.15	6.56434
1647.19	7.54583
1648.24	11.4789
1649.28	9.54974
1650.32	18.4167
1651.37	8.6107
1652.41	11.5822
1653.45	7.64265
1654.49	11.6002
1655.53	9.65245
1656.57	12.6559
1657.62	10.6921
1658.66	9.70329
1659.7	7.72219
1660.74	5.75522
1661.78	6.77159
1662.82	10.7653
1663.86	9.79096
1664.9	10.7669
1665.94	9.74801
1666.98	9.7983
1668.02	10.7777
1669.06	8.82021
1670.1	7.86484
1671.14	7.89696
1672.18	6.91323
1673.21	4.94937
1674.25	9.90976
1675.29	4.00197
1676.33	9.95591
1677.37	8.97949
1678.4	1.06073
1679.44	6.98762
1680.48	5.99908
1681.52	9.95153
1682.55	7.98527
1683.59	10.9573
1684.63	7.00894
1685.66	6.0263
1686.7	6.03946
1687.73	3.09315
1688.77	7.04234
1689.81	2.09892
1690.84	6.04906
1691.88	3.10912
1692.91	5.09013
1693.95	2.11692
1694.98	3.09452
1696.01	3.10861
1697.05	7.06802
1698.08	5.08611
1699.12	4.09421
1700.15	1.15152
1701.18	3.1235
1702.22	6.07111
1703.25	5.08173
1704.28	1.15569
1705.32	3.13575
1706.35	3.14054
1707.38	5.0906
1708.41	2.1302
1709.44	1.13237
1710.48	3.09551
1711.51	1.15558
1712.54	4.10528
1713.57	4.07693
1714.6	4.06046
1715.63	1.13985
1716.66	4.08
1717.69	2.1067
1718.72	3.05243
1719.75	5.00038
1720.78	1.11468
1721.81	1.10523
1722.84	2.06484
1723.87	2.0574
1724.9	2.05985
1725.93	3.97618
1726.96	3.00744
1727.99	1.07239
1729.02	-0.895693
1730.05	1.99092
1731.07	1.02144
1732.1	1.05688
1733.13	4.9211
1734.16	2.96634
1735.18	-0.908875
1736.21	0.0435257
1737.24	3.89138
1738.26	1.96266
1739.29	-2.85217
1740.32	2.88449
1741.34	0.949318
1742.37	-1.92967
1743.4	0.944656
1744.42	2.85556
1745.45	1.90258
1746.47	4.77079
1747.5	1.88612
1748.52	-1.93757
1749.55	-0.970255
1750.57	0.00959778
1751.6	0.0266438
1752.62	-0.940348
1753.64	-0.949501
1754.67	0.949951
1755.69	2.85201
1756.71	0.93399
1757.74	4.7233
1758.76	2.83602
1759.78	2.84565
1760.81	-0.959152
1761.83	-1.91584
1762.85	1.89256
1763.87	0.000497818
1764.89	3.82921
1765.92	0.990936
1766.94	1.94785
1767.96	3.85073
1768.98	-0.909842
1770	0.00988007
1771.02	0.0269909
1772.04	-0.900761
1773.06	2.92235
1774.08	0.0828438
1775.1	1.99969
1776.12	1.07412
1777.14	-0.826963
1778.16	0.118244
1779.18	2.96129
1780.2	-3.69915
1781.22	-0.83276
1782.24	-0.822195
1783.26	1.10155
1784.28	0.1639
1785.29	-0.771746
1786.31	1.13506
1787.33	0.195274
1788.35	1.19501
1789.37	1.23099
1790.38	7.00542
1791.4	5.08875
1792.42	1.24143
1793.43	2.2096
1794.45	1.25939
1795.47	1.28193
1796.48	-0.610992
1797.5	1.32935
1798.51	0.381533
1799.53	-0.579363
1800.55	-1.55132
1801.56	-0.594345
1802.58	2.29384
1803.59	1.35074
1804.61	0.40056
1805.62	1.3827
1806.64	0.438215
1807.65	4.3004
1808.66	0.447639
1809.68	0.451675
1810.69	0.455315
1811.7	-0.510836
1812.72	0.457075
1813.73	2.39804
1814.74	2.41935
1815.76	-0.462122
1816.77	1.4756
1817.78	-1.43593
1818.79	0.499378
1819.8	2.43837
1820.82	-0.45266
1821.83	-2.37847
1822.84	3.43607
1823.85	-0.436855
1824.86	3.43495
1825.87	4.41088
1826.88	2.47399
1827.89	-0.427269
1828.9	0.539026
1829.91	1.49896
1830.92	2.45629
1831.93	-0.442556
1832.94	2.47432
1833.95	3.44759
1834.96	1.49137
1835.97	0.487751
1836.98	0.561911
1837.99	-0.475342
1839	0.48752
1840	-1.42527
1841.01	0.468172
1842.02	-3.43563
1843.03	-0.560402
1844.04	-2.49376
1845.04	4.25526
1846.05	-3.46151
1847.06	1.3803
1848.07	-1.58718
1849.07	0.337214
1850.08	-0.645769
1851.09	1.24658
1852.09	-0.693422
1853.1	3.14099
1854.1	1.20635
1855.11	-2.65744
1856.11	-1.72244
1857.12	0.184433
1858.12	-0.786852
1859.13	0.147467
1860.13	2.03867
1861.14	-0.827358
1862.14	0.133877
1863.15	2.02635
1864.15	-1.82247
1865.15	1.97582
1866.16	-0.920782
1867.16	2.84685
1868.16	-0.993223
1869.17	0.8985
1870.17	0.886976
1871.17	-2.92593
1872.17	-1.99035
1873.18	-2.0097
1874.18	-2.02531
1875.18	2.69056
1876.18	-3.0331
1877.18	-0.222689
1878.18	0.683935
1879.19	0.710709
1880.19	1.66596
1881.19	6.38824
1882.19	0.667421
1883.19	0.613485
1884.19	2.46618
1885.19	0.583107
1886.19	-2.23128
1887.19	-2.24319
1888.19	-2.27057
1889.19	-3.24697
1890.19	-0.442757
1891.19	2.38574
1892.18	2.37082
1893.18	-0.473389
1894.18	2.30498
1895.18	0.405239
1896.18	2.28135
1897.18	-1.47532
1898.17	2.28202
1899.17	5.07841
1900.17	3.1711
1901.16	-0.598183
1902.16	1.2872
1903.16	1.2848
1904.16	0.325228
1905.15	1.25073
1906.15	3.11041
1907.14	0.265066
1908.14	3.07425
1909.14	0.254501
1910.13	-1.61846
1911.13	0.277098
1912.12	1.2138
1913.12	1.19868
1914.11	-3.51379
1915.11	1.20787
1916.1	4.03545
1917.1	-2.59079
1918.09	-0.726175
1919.08	2.10543
1920.08	1.18126
1921.07	1.17353
1922.06	0.234058
1923.06	1.16457
1924.05	0.198065
1925.04	-1.71381
1926.04	-0.767204
1927.03	2.08309
1928.02	0.191317
1929.01	2.08324
1930	1.14188
1931	2.10293
1931.99	2.08824
1932.98	0.165134
1933.97	-0.792517
1934.96	4.01256
1935.95	3.10172
1936.94	3.06606
1937.93	1.12831
1938.92	2.06678
1939.91	0.162445
1940.9	-0.788414
1941.89	-5.55302
1942.88	2.07802
1943.87	1.09787
1944.86	-0.808121
1945.85	2.06645
1946.84	-0.799376
1947.83	1.09745
1948.82	-0.830118
1949.8	0.127396
1950.79	-0.813112
1951.78	1.12543
1952.77	-0.789474
1953.76	0.161043
1954.74	1.06139
1955.73	-2.79503
1956.72	2.98246
1957.7	1.07197
1958.69	0.109934
1959.68	1.05135
1960.66	-1.85356
1961.65	1.95936
1962.63	0.987894
1963.62	3.8591
1964.61	-2.86692
1965.59	-1.9212
1966.58	-1.92284
1967.56	2.88029
1968.55	-1.93432
1969.53	1.88643
1970.52	-1.03119
1971.5	-1.05537
1972.48	1.81032
1973.47	2.75243
1974.45	-0.150423
1975.44	1.7567
1976.42	-1.12034
1977.4	-3.04907
1978.39	1.7235
1979.37	-2.12946
1980.35	-1.18079
1981.33	0.712755
1982.31	-1.22243
1983.3	0.66799
1984.28	2.55419
1985.26	3.48776
1986.24	0.600746
1987.22	3.4659
1988.21	1.52528
1989.19	1.4598
1990.17	1.33537
1991.15	0.330875
1992.13	0.257185
1993.11	-0.277847
1994.09	1.4148
1995.07	-0.248217
1996.05	-0.695553
1997.03	0.903223
1998.01	1.36607
1998.99	1.15486
1999.97	0.661329
2000.95	-0.863743
2001.92	-1.16379
2002.9	-0.706415
2003.88	-0.588951
2004.86	-0.215401
2005.84	0.244169
2006.81	0.961102
2007.79	0.498247
2008.77	0.244959
2009.75	-1.94346
2010.73	0.476192
2011.7	0.319838
2012.68	-0.731886
2013.67	-0.766041
2014.66	2.00631
2015.64	1.98651
2016.63	1.98757
2017.62	-0.824759
2018.61	-1.80136
2019.6	0.969727
2020.58	-0.922829
2021.57	0.00531197
2022.56	-0.00992012
2023.55	1.83138
2024.54	0.867188
2025.52	-0.105778
2026.51	-0.132744
2027.5	-0.0827847
2028.48	0.817043
2029.47	-2.89697
2030.45	-2.03171
2031.44	-0.164417
2032.43	0.764774
2033.41	0.78668
2034.4	2.65116
2035.38	1.67167
2036.37	-3.89593
2037.35	3.57152
2038.34	-2.98685
2039.32	-0.203644
2040.31	-1.1633
2041.29	1.60605
2042.27	-2.14031
2043.26	0.639372
2044.24	-1.20587
2045.23	-1.22513
2046.21	0.680754
2047.19	-0.280684
2048.17	0.61685
2049.16	-2.18072
2050.14	1.57007
2051.12	-1.22026
2052.11	-0.304699
2053.09	2.49914
2054.07	-1.21951
2055.05	2.52371
2056.03	-0.29879
2057.01	-2.18074
2058	1.55872
2058.98	-2.17043
2059.96	-0.293312
2060.94	-2.17816
2061.92	-1.23842
2062.9	-0.301683
2063.88	-1.22948
2064.86	-0.288115
2065.84	0.667416
2066.82	1.61669
2067.8	0.683729
2068.78	3.51045
2069.76	-1.19909
2070.73	-1.20506
2071.71	-0.254635
2072.69	-1.16839
2073.67	1.6486
2074.65	3.53458
2075.63	-3.03655
2076.6	0.7577
2077.58	1.68628
2078.56	-0.209366
2079.54	3.57571
2080.51	-2.06979
2081.49	1.70611
2082.47	-2.07609
2083.45	-2.07598
2084.42	0.754894
2085.4	0.753469
2086.37	1.70416
2087.35	-1.11744
2088.32	1.72576
2089.3	-3.00494
2090.28	-0.151711
2091.25	0.801355
2092.23	-0.130651
2093.2	-5.8012
2094.18	-0.0837135
2095.15	-2.9329
2096.13	1.80525
2097.1	0.847382
2098.07	-1.06721
2099.05	0.824478
2100.02	-0.129124
2101	0.823454
2101.97	4.63666
2102.94	3.68397
2103.92	-2.97518
2104.89	0.82601
2105.86	0.841745
2106.83	-1.99985
2107.8	-0.0977039
2108.78	1.77885
2109.75	-1.07058
2110.72	-0.116127
2111.69	0.83189
2112.66	0.824648
2113.63	-0.112103
2114.61	0.841867
2115.58	-2.00914
2116.55	2.73148
2117.52	2.72221
2118.49	-2.03329
2119.46	-2.05348
2120.43	0.774397
2121.4	-0.167217
2122.37	-3.94092
2123.34	0.817259
2124.31	-1.08189
2125.28	0.786785
2126.25	-0.191414
2127.21	1.681
2128.18	-0.21867
2129.15	0.72418
2130.12	-3.06023
2131.09	-0.230076
2132.06	-0.241419
2133.02	-1.19696
2133.99	-0.252354
2134.96	0.694397
2135.93	1.63479
2136.89	5.38479
2137.86	-0.264662
2138.83	1.61436
2139.79	1.62225
2140.76	1.60404
2141.73	0.658249
2142.69	-0.292864
2143.66	-2.15739
2144.62	-0.315161
2145.59	-1.25184
2146.55	-0.313171
2147.52	2.49943
2148.48	-0.327801
2149.45	-3.15476
2150.42	2.45085
2151.38	0.572889
2152.34	-2.22625
2153.31	3.39508
2154.27	1.5106
2155.24	2.41525
2156.2	0.516186
2157.16	0.510883
2158.13	1.45798
2159.09	0.530306
2160.05	-0.413864
2161.01	-0.430758
2161.98	-2.30103
2162.94	-0.432739
2163.9	-3.23625
2164.86	0.481133
2165.83	0.484678
2166.79	-0.447773
2167.75	1.40189
2168.71	2.30222
2169.67	-5.12475
2170.63	1.41944
2171.59	-1.37572
2172.56	-1.40676
2173.51	1.37729
2174.48	1.38842
2175.44	-2.32389
2176.4	0.46381
2177.36	2.3193
2178.32	-0.461447
2179.28	-3.2551
2180.23	-5.10605
2181.19	2.32281
2182.15	-1.39253
2183.11	1.38778
2184.07	-5.11729
2185.03	-0.484781
2185.99	-3.25207
2186.95	-0.448051
2187.9	-0.418276
2188.86	-2.27875
2189.82	0.487576
2190.78	1.41038
2191.73	-0.432867
2192.69	1.43565
2193.65	-3.18478
2194.6	3.3559
2195.56	-0.358198
2196.52	-0.374208
2197.47	1.46685
2198.43	-0.38228
2199.38	3.36409
2200.34	5.2679
2201.3	2.52677
2202.25	-0.334835
2203.21	2.50059
2204.16	-3.00473
2205.12	2.55858
2206.07	5.29511
2207.03	0.651716
2207.98	-1.18763
2208.93	0.69886
2209.89	2.5762
2210.84	-2.99891
2211.8	0.749929
2212.75	-2.02579
2213.7	-1.0942
2214.66	-1.07602
2215.61	0.812801
2216.56	1.75595
2217.51	-1.03934
2218.47	1.77129
2219.42	-1.01159
2220.37	-0.057457
2221.32	2.74983
2222.27	-0.998816
2223.23	-0.988825
2224.18	0.906977
2225.13	-1.86608
2226.08	1.90852
2227.03	2.87412
2227.98	-0.854095
2228.93	-2.7251
2229.88	0.0983181
2230.83	1.06583
2231.78	0.156847
2232.73	-0.755993
2233.68	-1.67132
2234.63	2.11146
2235.58	3.98488
2236.53	2.1106
2237.48	2.13024
2238.43	-3.47883
2239.38	2.21411
2240.33	0.32822
2241.27	1.29225
2242.22	3.19676
2243.17	4.16039
2244.12	0.386126
2245.07	0.407228
2246.01	2.33597
2246.96	-0.474117
2247.91	-1.39959
2248.85	-1.39212
2249.8	1.45886
2250.75	-3.26525
2251.69	-2.32253
2252.64	2.42269
2253.59	2.46974
2254.53	0.607971
2255.48	-0.325727
2256.42	2.53724
2257.37	1.61735
2258.32	-1.20769
2259.26	-0.238173
2260.2	-0.216049
2261.15	0.757215
2262.1	0.784296
2263.04	2.71293
2263.98	2.7539
2264.93	0.892406
2265.87	-0.0348778
2266.81	-0.0324955
2267.76	1.87177
2268.7	-0.0363636
2269.65	-0.00908852
2270.59	1.94196
2271.53	-1.85201
2272.47	-0.870882
2273.42	1.06001
2274.36	0.121313
2275.3	-0.817545
2276.24	0.158552
2277.18	-0.766523
2278.13	0.234409
2279.07	-3.57926
2280.01	0.26037
2280.95	-1.66517
2281.89	2.17298
2282.83	-0.67767
2283.77	-2.56026
2284.71	-3.47751
2285.65	0.397243
2286.59	0.397978
2287.54	-1.4901
2288.47	1.42286
2289.41	-1.46931
2290.35	2.36457
2291.29	0.456841
2292.23	0.492208
2293.17	5.34045
2294.11	0.547991
2295.05	0.549517
2295.99	-0.412392
2296.93	1.50775
2297.86	-2.31547
2298.8	-0.356556
2299.74	1.60314
2300.68	-0.311943
2301.61	3.57239
2302.55	-1.24173
2303.49	2.6283
2304.43	-0.249165
2305.36	-1.19056
2306.3	0.76132
2307.24	-0.189924
2308.17	2.71335
2309.11	0.788948
2310.04	-0.147825
2310.98	1.80406
2311.92	-1.11895
2312.85	-1.12757
2313.79	-2.0777
2314.72	1.82241
2315.66	-0.0886517
2316.59	0.859484
2317.52	-0.106468
2318.46	-0.0950642
2319.39	1.82988
2320.33	2.79454
2321.26	1.84254
2322.2	-0.0635986
2323.13	3.82226
2324.06	1.90001
2325	5.76475
2325.93	0.91161
2326.86	5.72129
2327.79	16.3077
2328.73	50.0373
2329.66	19.1704
2330.59	9.53704
2331.52	-1.06022
2332.46	0.872248
2333.39	-2.99289
2334.32	1.80907
2335.25	2.75321
2336.18	-4.94295
2337.11	2.74154
2338.04	2.73209
2338.97	5.60574
2339.91	1.75573
2340.84	4.61837
2341.77	0.74152
2342.7	5.5093
2343.63	1.66024
2344.56	1.64928
2345.49	4.50908
2346.41	-1.27058
2347.34	-1.29002
2348.27	2.52434
2349.2	0.595152
2350.13	-3.28014
2351.06	2.32593
2351.99	2.39981
2352.91	0.434605
2353.84	0.380276
2354.77	3.21468
2355.7	1.28482
2356.63	-0.662573
2357.55	-0.716768
2358.48	-1.70912
2359.41	-1.7503
2360.33	1.05316
2361.26	0.996878
2362.19	1.88478
2363.11	1.82299
2364.04	-1.06944
2364.97	-1.12368