File: Data/3-Raman/processed/bu02aw-a-ff1-fi01-v_1800 (450-850nm)_532nm_edge_100%_x100_vis_lwd_h50um_30sx2_edited.txt
#Acq. time (s)=	30
#Accumulations=	2
#Range (cm-¹)=	1200...2365
#Windows=	3
#Auto scanning=	Off
#Autofocus=	Off
#Macrospot=	Off
#AutoExposure=	Off
#Spike filter=	Multiple accum.
#Delay time (s)=	2
#Binning=	1
#Readout mode=	Signal
#DeNoise=	Off
#ICS correction=	On
#Dark correction=	Off
#Inst. Process=	Off
#Detector Gain=	Best Dynamic
#Detector ADC=	50 kHz HS
#Detector temperature (°C)=	-60.09
#Instrument=	LabRAM HR Evol
#Detector=	SIN-EM FIVIS
#Objective=	x100_VIS_LWD
#Grating=	1800 (450-850nm)
#ND Filter=	100%
#Laser=	532nm_Edge
#Hole=	49.98
#Temperature=	0
#Range=	Visible
#StageXY=	75x50mm Scan+
#StageZ=	Z motor
#X (µm)=	0
#Y (µm)=	0
#Z (µm)=	-10.3
#Full time(mm:ss)=	3:11
#Project=	21_11_26
#Sample=	BU02Aw
#Site=
#Title=	BU02aW-A-FF1-FI01-V_1800 (450-850nm)_532nm_Edge_100%_x100_VIS_LWD_H50um_30sX2
#Remark=
#Date=	26.11.2021 10:39
#Acquired=	26.11.2021 10:39:57
#Base:Fit=	26.11.2021 10:51:03
#Base:Fit=	26.11.2021 10:51:08
#Base:Fit=	26.11.2021 10:51:11
#Base:Fit=	26.11.2021 10:51:11
#Base:Fit=	26.11.2021 10:51:11
#Base:Fit=	26.11.2021 10:51:11
#Base:Fit=	26.11.2021 10:51:11
#Base:Fit=	26.11.2021 10:51:11
#Base:Fit=	26.11.2021 10:51:11
#Base:Fit=	26.11.2021 10:51:11
#Base:Fit=	26.11.2021 10:51:11
#Base:Fit=	26.11.2021 10:51:11
#Base:Fit=	26.11.2021 10:51:11
#Base:Fit=	26.11.2021 10:51:12
#Base:Fit=	26.11.2021 10:51:12
#Base:Fit=	26.11.2021 10:51:12
#Base:Edit=	26.11.2021 10:51:20
#Base:Edit=	26.11.2021 10:51:21
#Base:Edit=	26.11.2021 10:51:22
#Base:Edit=	26.11.2021 10:51:22
#Base:Edit=	26.11.2021 10:51:23
#Base:Fit=	26.11.2021 10:51:26
#Base:Edit=	26.11.2021 10:51:29
#Base:Edit=	26.11.2021 10:51:29
#Base:Edit=	26.11.2021 10:51:30
#Base:Edit=	26.11.2021 10:51:30
#Base:Edit=	26.11.2021 10:51:31
#Base:Edit=	26.11.2021 10:51:31
#Base:Sub=	26.11.2021 10:51:33
#Edit:Shape=	26.11.2021 10:52:28
#Edit:Shape=	26.11.2021 10:52:35
#Edit:Shape=	26.11.2021 10:53:25
#Base:Fit=	16.12.2021 16:15:35
#Base:Fit=	16.12.2021 16:17:33
#Base:Sub=	16.12.2021 16:17:34
1202.72	0.021189
1203.84	2.10202
1204.95	-0.149747
1206.06	4.02476
1207.17	4.95682
1208.28	3.77039
1209.39	2.58589
1210.5	-0.718352
1211.61	-0.841753
1212.72	3.30196
1213.83	3.18963
1214.94	0.971272
1216.05	-2.31247
1217.16	0.756514
1218.27	-0.420716
1219.38	-2.64388
1220.49	0.443325
1221.6	-2.83062
1222.71	-0.827834
1223.81	2.21207
1224.92	2.0963
1226.03	-0.0953062
1227.14	0.874058
1228.25	-1.3758
1229.35	2.68679
1230.46	-1.5253
1231.57	-0.624724
1232.67	0.349189
1233.78	0.267494
1234.89	1.25425
1235.99	0.142401
1237.1	1.11461
1238.2	5.20528
1239.31	-2.24375
1240.41	-1.27369
1241.52	-1.33877
1242.62	-3.51141
1243.73	0.623888
1244.83	-1.53701
1245.94	0.470232
1247.04	0.392686
1248.14	1.37216
1249.25	-0.795172
1250.35	4.37634
1251.45	1.15604
1252.56	-1.0084
1253.66	-1.0808
1254.76	-2.161
1255.87	-0.11853
1256.97	6.10589
1258.07	1.87317
1259.17	5.98642
1260.27	4.92026
1261.37	6.92632
1262.48	8.00864
1263.58	16.2116
1264.68	28.8705
1265.78	13.1019
1266.88	3.6615
1267.98	10.9824
1269.08	2.62362
1270.18	7.83048
1271.28	8.81293
1272.38	11.929
1273.47	8.80802
1274.57	5.6731
1275.67	8.80097
1276.77	5.65867
1277.87	6.71782
1278.97	8.83513
1280.07	14.0842
1281.16	22.4839
1282.26	31.978
1283.36	105.586
1284.45	332.571
1285.55	172.053
1286.65	29.855
1287.75	12.9807
1288.84	5.59647
1289.94	3.50621
1291.03	2.45831
1292.13	5.61186
1293.22	2.44948
1294.32	1.43452
1295.42	2.4981
1296.51	1.5117
1297.61	3.62485
1298.7	2.55519
1299.79	-2.73322
1300.89	1.50628
1301.98	-2.70444
1303.08	-0.574466
1304.17	-3.74195
1305.26	-0.564649
1306.35	1.53382
1307.45	1.54259
1308.54	0.505836
1309.63	1.58689
1310.73	-0.500795
1311.82	5.85519
1312.91	-0.443483
1314	2.73516
1315.09	0.64878
1316.18	2.79973
1317.28	4.93043
1318.37	3.90966
1319.46	2.8806
1320.55	-1.31811
1321.64	2.91291
1322.73	-2.36153
1323.82	-2.34179
1324.91	0.853148
1326	-0.189523
1327.09	0.846737
1328.18	-1.17742
1329.27	-0.0557661
1330.35	-0.0256677
1331.44	-0.0153208
1332.53	-1.07403
1333.62	5.23223
1334.71	-0.0191083
1335.79	1.04352
1336.88	2.11154
1337.97	1.0898
1339.06	0.0584977
1340.14	2.1915
1341.23	4.3288
1342.32	3.31025
1343.4	4.36982
1344.49	0.225193
1345.58	2.34476
1346.66	5.47638
1347.75	0.265744
1348.83	-0.746027
1349.92	1.36133
1351	4.50467
1352.09	0.365928
1353.17	2.51002
1354.25	4.66936
1355.34	-0.556081
1356.42	2.60427
1357.51	1.59733
1358.59	3.70125
1359.67	2.68913
1360.76	2.70745
1361.84	-0.361907
1362.92	-0.324334
1364	4.91161
1365.09	8.06526
1366.17	10.1528
1367.25	9.12683
1368.33	10.2079
1369.41	11.3009
1370.5	16.5076
1371.58	6.19211
1372.66	8.67272
1373.74	8.18537
1374.82	10.0742
1375.9	10.8475
1376.98	10.4142
1378.06	11.74
1379.14	11.9811
1380.22	13.9289
1381.3	19.0134
1382.38	27.7407
1383.46	31.7415
1384.54	39.6716
1385.61	63.8973
1386.69	136.11
1387.77	603.862
1388.85	315.196
1389.93	57.162
1391	32.4768
1392.08	21.2086
1393.16	13.0306
1394.23	15.1111
1395.31	11.0644
1396.39	13.1718
1397.46	12.1771
1398.54	6.07991
1399.62	7.16483
1400.69	7.22417
1401.77	-1.92993
1402.84	11.4879
1403.92	8.49026
1404.99	7.48764
1406.07	7.51324
1407.14	12.6754
1408.22	16.834
1409.29	38.4301
1410.37	29.2586
1411.44	8.75381
1412.51	8.79308
1413.59	3.79478
1414.66	3.80551
1415.73	6.94358
1416.81	-2.24468
1417.88	2.94768
1418.95	1.96911
1420.02	0.978765
1421.1	5.10813
1422.17	6.17989
1423.24	0.114631
1424.31	1.10043
1425.38	3.19476
1426.45	4.27024
1427.52	3.25833
1428.59	1.22539
1429.67	4.34634
1430.74	0.311789
1431.81	3.46304
1432.87	1.43589
1433.95	0.412766
1435.01	2.50993
1436.08	2.54874
1437.15	3.60343
1438.22	3.63437
1439.29	3.68192
1440.36	0.664286
1441.43	-1.34273
1442.49	-3.35927
1443.56	3.85356
1444.63	1.83367
1445.7	0.86376
1446.77	0.891043
1447.83	2.96742
1448.9	-5.19445
1449.97	-1.06128
1451.03	4.08656
1452.1	1.03648
1453.17	1.06855
1454.23	-0.944116
1455.3	2.16084
1456.36	-1.90071
1457.43	-0.853308
1458.49	1.22309
1459.56	-2.83979
1460.62	2.31001
1461.69	1.30494
1462.75	1.31778
1463.82	-2.76434
1464.88	0.358413
1465.94	-3.76467
1467.01	-1.70192
1468.07	-1.67737
1469.13	-2.67255
1470.2	0.39955
1471.26	0.414479
1472.32	0.428488
1473.39	-0.567209
1474.45	1.48316
1475.51	-0.522583
1476.57	-0.505179
1477.63	2.55969
1478.69	0.541665
1479.76	-1.48133
1480.82	-5.54015
1481.88	-2.47926
1482.94	-1.42606
1484	1.64751
1485.06	-2.43416
1486.12	-1.40469
1487.18	6.72581
1488.24	-2.38218
1489.3	0.658405
1490.36	-1.35017
1491.42	4.72602
1492.48	-0.311359
1493.53	-0.293879
1494.59	1.74723
1495.65	3.77786
1496.71	-0.266621
1497.77	3.78328
1498.82	0.773049
1499.88	-4.25036
1500.94	-2.21157
1502	-2.20172
1503.05	-1.183
1504.11	-1.17633
1505.17	0.85982
1506.22	0.855743
1507.28	-1.1408
1508.34	1.8986
1509.39	3.93044
1510.45	-0.0807736
1511.5	4.94938
1512.56	-1.1184
1513.61	0.880956
1514.67	2.91984
1515.72	-0.0984079
1516.78	3.90685
1517.83	0.909092
1518.88	1.93505
1519.94	0.952295
1520.99	2.96934
1522.05	-1.02604
1523.1	-1.02191
1524.15	3.97625
1525.2	5.98066
1526.26	1.99775
1527.31	-1.98642
1528.36	0.0222511
1529.41	0.0261277
1530.47	1.03298
1531.52	-0.944092
1532.57	-1.9376
1533.62	0.101153
1534.67	4.12832
1535.72	3.1246
1536.77	-3.90821
1537.82	3.08454
1538.87	2.0802
1539.92	1.12547
1540.97	-0.831438
1542.02	0.167582
1543.07	8.16497
1544.12	1.14039
1545.17	0.16394
1546.22	1.19679
1547.27	1.21138
1548.32	1.20893
1549.37	1.20485
1550.42	2.2233
1551.46	4.31127
1552.51	2.31308
1553.56	4.31074
1554.61	0.289985
1555.65	4.28588
1556.7	3.2907
1557.75	3.30319
1558.79	-0.712673
1559.84	3.27118
1560.89	0.268636
1561.93	6.27842
1562.98	0.301066
1564.02	2.30479
1565.07	5.3343
1566.11	0.205057
1567.16	1.30397
1568.2	3.32906
1569.25	4.34275
1570.29	-0.659375
1571.34	3.3452
1572.38	6.33804
1573.43	3.33361
1574.47	2.3404
1575.51	5.36881
1576.56	3.38157
1577.6	6.35385
1578.64	3.33798
1579.69	4.34064
1580.73	3.35855
1581.77	5.34826
1582.81	10.3216
1583.85	4.34655
1584.9	6.34743
1585.94	5.35732
1586.98	4.34886
1588.02	6.3362
1589.06	5.35809
1590.1	4.38006
1591.14	7.38265
1592.18	5.39253
1593.22	5.37468
1594.26	6.33651
1595.3	3.36838
1596.34	6.34682
1597.38	2.38407
1598.42	4.3795
1599.46	4.36394
1600.5	2.3701
1601.54	7.30541
1602.58	8.27377
1603.62	8.25532
1604.66	5.29011
1605.69	7.27795
1606.73	14.2237
1607.77	9.28613
1608.81	6.19745
1609.84	5.69609
1610.88	7.42456
1611.92	4.94432
1612.95	6.84464
1613.99	7.12702
1615.03	9.99218
1616.06	9.70089
1617.1	8.75335
1618.13	7.18316
1619.17	7.56139
1620.2	8.03348
1621.24	5.35748
1622.27	9.00489
1623.31	8.95687
1624.34	8.26928
1625.38	7.80146
1626.41	10.5999
1627.45	8.4495
1628.48	6.53743
1629.51	9.90553
1630.55	7.942
1631.53	7.50075
1632.57	14.4209
1633.62	13.4406
1634.66	10.5005
1635.71	11.4917
1636.75	10.5005
1637.8	7.53651
1638.84	10.489
1639.89	13.4505
1640.93	9.52705
1641.98	10.5202
1643.02	10.522
1644.06	11.5096
1645.11	10.5202
1646.15	6.60243
1647.19	7.58385
1648.24	11.5168
1649.28	9.58762
1650.32	18.4546
1651.37	8.64843
1652.41	11.6198
1653.45	7.68023
1654.49	11.6377
1655.53	9.68986
1656.57	12.6932
1657.62	10.7294
1658.66	9.74043
1659.7	7.75923
1660.74	5.79217
1661.78	6.80844
1662.82	10.802
1663.86	9.82761
1664.9	10.8035
1665.94	9.78444
1666.98	9.83462
1668.02	10.8139
1669.06	8.8563
1670.1	7.90081
1671.14	7.93281
1672.18	6.94895
1673.21	4.98497
1674.25	9.94522
1675.29	4.0373
1676.33	9.99111
1677.37	9.01455
1678.4	1.09566
1679.44	7.0224
1680.48	6.03372
1681.52	9.98602
1682.55	8.01961
1683.59	10.9915
1684.63	7.04298
1685.66	6.06019
1686.7	6.07319
1687.73	3.12672
1688.77	7.07575
1689.81	2.13216
1690.84	6.08214
1691.88	3.14203
1692.91	5.12287
1693.95	2.14948
1694.98	3.12691
1696.01	3.14082
1697.05	7.10005
1698.08	5.11795
1699.12	4.12587
1700.15	1.183
1701.18	3.15479
1702.22	6.10221
1703.25	5.11263
1704.28	1.1864
1705.32	3.16626
1706.35	3.17085
1707.38	5.12071
1708.41	2.1601
1709.44	1.16206
1710.48	3.12499
1711.51	1.18486
1712.54	4.13435
1713.57	4.10578
1714.6	4.0891
1715.63	1.16827
1716.66	4.10819
1717.69	2.13467
1718.72	3.08017
1719.75	5.0279
1720.78	1.14197
1721.81	1.1323
1722.84	2.09167
1723.87	2.084
1724.9	2.08621
1725.93	4.0023
1726.96	3.03332
1727.99	1.09803
1729.02	-0.870296
1730.05	2.01607
1731.07	1.04635
1732.1	1.08154
1733.13	4.94551
1734.16	2.9905
1735.18	-0.884967
1736.21	0.067178
1737.24	3.91478
1738.26	1.98579
1739.29	-2.82929
1740.32	2.90711
1741.34	0.971674
1742.37	-1.90758
1743.4	0.966485
1744.42	2.87712
1745.45	1.92388
1746.47	4.79181
1747.5	1.90688
1748.52	-1.91708
1749.55	-0.950041
1750.57	0.029537
1751.6	0.0463088
1752.62	-0.92096
1753.64	-0.93039
1754.67	0.968785
1755.69	2.87057
1756.71	0.952265
1757.74	4.7413
1758.76	2.85373
1759.78	2.86308
1760.81	-0.942006
1761.83	-1.89898
1762.85	1.90913
1763.87	0.0167873
1764.89	3.84521
1765.92	1.00665
1766.94	1.96328
1767.96	3.86587
1768.98	-0.894991
1770	0.0244397
1771.02	0.0412601
1772.04	-0.886782
1773.06	2.93604
1774.08	0.0962387
1775.1	2.01279
1776.12	1.08693
1777.14	-0.814444
1778.16	0.130471
1779.18	2.97323
1780.2	-3.68751
1781.22	-0.821414
1782.24	-0.811141
1783.26	1.11231
1784.28	0.174368
1785.29	-0.761573
1786.31	1.14494
1787.33	0.20486
1788.35	1.2043
1789.37	1.23999
1790.38	7.01412
1791.4	5.09716
1792.42	1.24956
1793.43	2.21743
1794.45	1.26693
1795.47	1.28918
1796.48	-0.604033
1797.5	1.33602
1798.51	0.387914
1799.53	-0.573271
1800.55	-1.54552
1801.56	-0.588829
1802.58	2.29907
1803.59	1.35569
1804.61	0.40522
1805.62	1.38707
1806.64	0.442304
1807.65	4.30421
1808.66	0.451168
1809.68	0.454924
1810.69	0.458282
1811.7	-0.508147
1812.72	0.459488
1813.73	2.40018
1814.74	2.42121
1815.76	-0.460532
1816.77	1.47692
1817.78	-1.43488
1818.79	0.500155
1819.8	2.43888
1820.82	-0.452416
1821.83	-2.37849
1822.84	3.43579
1823.85	-0.437403
1824.86	3.43414
1825.87	4.40981
1826.88	2.47267
1827.89	-0.428844
1828.9	0.537195
1829.91	1.49688
1830.92	2.45396
1831.93	-0.445135
1832.94	2.4715
1833.95	3.44453
1834.96	1.48807
1835.97	0.484204
1836.98	0.558125
1837.99	-0.479362
1839	0.483266
1840	-1.42975
1841.01	0.463459
1842.02	-3.44057
1843.03	-0.565565
1844.04	-2.49915
1845.04	4.24966
1846.05	-3.46733
1847.06	1.37426
1848.07	-1.59343
1849.07	0.330756
1850.08	-0.652433
1851.09	1.23971
1852.09	-0.700492
1853.1	3.13372
1854.1	1.19888
1855.11	-2.6651
1856.11	-1.73029
1857.12	0.176395
1858.12	-0.795075
1859.13	0.139059
1860.13	2.03008
1861.14	-0.836123
1862.14	0.124938
1863.15	2.01724
1864.15	-1.83174
1865.15	1.96638
1866.16	-0.930388
1867.16	2.83708
1868.16	-1.00315
1869.17	0.888427
1870.17	0.876751
1871.17	-2.9363
1872.17	-2.00086
1873.18	-2.02036
1874.18	-2.03611
1875.18	2.67963
1876.18	-3.04416
1877.18	-0.23388
1878.18	0.67262
1879.19	0.699271
1880.19	1.6544
1881.19	6.37656
1882.19	0.655638
1883.19	0.601592
1884.19	2.45418
1885.19	0.571006
1886.19	-2.24348
1887.19	-2.25549
1888.19	-2.28296
1889.19	-3.25945
1890.19	-0.455321
1891.19	2.37309
1892.18	2.3581
1893.18	-0.48619
1894.18	2.29211
1895.18	0.392295
1896.18	2.26834
1897.18	-1.48839
1898.17	2.26889
1899.17	5.06522
1900.17	3.15786
1901.16	-0.611471
1902.16	1.27387
1903.16	1.27142
1904.16	0.311812
1905.15	1.23728
1906.15	3.09692
1907.14	0.251551
1908.14	3.06071
1909.14	0.240938
1910.13	-1.63204
1911.13	0.263499
1912.12	1.20018
1913.12	1.18505
1914.11	-3.52742
1915.11	1.19424
1916.1	4.02182
1917.1	-2.60442
1918.09	-0.739798
1919.08	2.09182
1920.08	1.16766
1921.07	1.15994
1922.06	0.220492
1923.06	1.15103
1924.05	0.184544
1925.04	-1.72731
1926.04	-0.780667
1927.03	2.06966
1928.02	0.177924
1929.01	2.06989
1930	1.12857
1931	2.08966
1931.99	2.07502
1932.98	0.151967
1933.97	-0.805631
1934.96	3.9995
1935.95	3.08872
1936.94	3.05312
1937.93	1.11544
1938.92	2.05397
1939.91	0.149705
1940.9	-0.801082
1941.89	-5.56562
1942.88	2.0655
1943.87	1.08543
1944.86	-0.820478
1945.85	2.05418
1946.84	-0.811565
1947.83	1.08536
1948.82	-0.842129
1949.8	0.115476
1950.79	-0.824938
1951.78	1.1137
1952.77	-0.801104
1953.76	0.149514
1954.74	1.04996
1955.73	-2.80636
1956.72	2.97124
1957.7	1.06086
1958.69	0.0989282
1959.68	1.04046
1960.66	-1.86434
1961.65	1.94869
1962.63	0.97734
1963.62	3.84866
1964.61	-2.87724
1965.59	-1.9314
1966.58	-1.93292
1967.56	2.87033
1968.55	-1.94416
1969.53	1.87671
1970.52	-1.04078
1971.5	-1.06484
1972.48	1.80098
1973.47	2.74322
1974.45	-0.159508
1975.44	1.74774
1976.42	-1.12917
1977.4	-3.05777
1978.39	1.71494
1979.37	-2.1379
1980.35	-1.18909
1981.33	0.704578
1982.31	-1.23047
1983.3	0.660076
1984.28	2.5464
1985.26	3.48011
1986.24	0.593227
1987.22	3.45851
1988.21	1.51802
1989.19	1.45267
1990.17	1.32837
1991.15	0.324008
1992.13	0.250446
1993.11	-0.284458
1994.09	1.40832
1995.07	-0.254569
1996.05	-0.701781
1997.03	0.897123
1998.01	1.36009
1998.99	1.14901
1999.97	0.655601
2000.95	-0.869349
2001.92	-1.16927
2002.9	-0.711782
2003.88	-0.594198
2004.86	-0.220533
2005.84	0.239155
2006.81	0.9562
2007.79	0.493459
2008.77	0.240279
2009.75	-1.94803
2010.73	0.47173
2011.7	0.315479
2012.68	-0.736142
2013.67	-0.770194
2014.66	2.00226
2015.64	1.98255
2016.63	1.98371
2017.62	-0.828527
2018.61	-1.80504
2019.6	0.966139
2020.58	-0.926331
2021.57	0.00189137
2022.56	-0.0132592
2023.55	1.82812
2024.54	0.864
2025.52	-0.108894
2026.51	-0.135792
2027.5	-0.0857675
2028.48	0.814122
2029.47	-2.89983
2030.45	-2.03451
2031.44	-0.16717
2032.43	0.762069
2033.41	0.784021
2034.4	2.64854
2035.38	1.66909
2036.37	-3.89847
2037.35	3.569
2038.34	-2.98934
2039.32	-0.206107
2040.31	-1.16574
2041.29	1.60363
2042.27	-2.14273
2043.26	0.636961
2044.24	-1.20828
2045.23	-1.22754
2046.21	0.678338
2047.19	-0.283108
2048.17	0.614411
2049.16	-2.18317
2050.14	1.56759
2051.12	-1.22277
2052.11	-0.307239
2053.09	2.49656
2054.07	-1.22213
2055.05	2.52104
2056.03	-0.301505
2057.01	-2.18351
2058	1.55588
2058.98	-2.17332
2059.96	-0.29628
2060.94	-2.1812
2061.92	-1.24154
2062.9	-0.304892
2063.88	-1.23277
2064.86	-0.291509
2065.84	0.663921
2066.82	1.61309
2067.8	0.680021
2068.78	3.50663
2069.76	-1.20303
2070.73	-1.20913
2071.71	-0.258838
2072.69	-1.17273
2073.67	1.64412
2074.65	3.52995
2075.63	-3.04133
2076.6	0.752763
2077.58	1.68118
2078.56	-0.214633
2079.54	3.57026
2080.51	-2.07541
2081.49	1.70031
2082.47	-2.08208
2083.45	-2.08216
2084.42	0.748507
2085.4	0.746877
2086.37	1.69736
2087.35	-1.12446
2088.32	1.71852
2089.3	-3.0124
2090.28	-0.159405
2091.25	0.793424
2092.23	-0.138825
2093.2	-5.80962
2094.18	-0.0923858
2095.15	-2.94183
2096.13	1.79606
2097.1	0.837924
2098.07	-1.07694
2099.05	0.814472
2100.02	-0.13941
2101	0.812882
2101.97	4.62579
2102.94	3.67281
2103.92	-2.98664
2104.89	0.814245
2105.86	0.829669
2106.83	-2.01224
2107.8	-0.110413
2108.78	1.76582
2109.75	-1.08394
2110.72	-0.129817
2111.69	0.817864
2112.66	0.810281
2113.63	-0.126814
2114.61	0.826809
2115.58	-2.02455
2116.55	2.71572
2117.52	2.70609
2118.49	-2.04978
2119.46	-2.07034
2120.43	0.757169
2121.4	-0.184817
2122.37	-3.9589
2123.34	0.798901
2124.31	-1.10063
2125.28	0.767659
2126.25	-0.210932
2127.21	1.66109
2128.18	-0.238973
2129.15	0.703481
2130.12	-3.08133
2131.09	-0.251576
2132.06	-0.263324
2133.02	-1.21927
2133.99	-0.275073
2134.96	0.671268
2135.93	1.61125
2136.89	5.36084
2137.86	-0.289027
2138.83	1.58958
2139.79	1.59705
2140.76	1.57842
2141.73	0.632214
2142.69	-0.319319
2143.66	-2.18427
2144.62	-0.342455
2145.59	-1.27955
2146.55	-0.341306
2147.52	2.47088
2148.48	-0.356776
2149.45	-3.18416
2150.42	2.42103
2151.38	0.542655
2152.34	-2.2569
2153.31	3.36401
2154.27	1.47912
2155.24	2.38335
2156.2	0.483875
2157.16	0.478164
2158.13	1.42485
2159.09	0.496772
2160.05	-0.447805
2161.01	-0.4651
2161.98	-2.33577
2162.94	-0.467876
2163.9	-3.27178
2164.86	0.445211
2165.83	0.44837
2166.79	-0.484464
2167.75	1.36482
2168.71	2.26477
2169.67	-5.16256
2170.63	1.38126
2171.59	-1.41426
2172.56	-1.44567
2173.51	1.33804
2174.48	1.34881
2175.44	-2.36384
2176.4	0.423527
2177.36	2.27869
2178.32	-0.502385
2179.28	-3.29635
2180.23	-5.14762
2181.19	2.28094
2182.15	-1.43471
2183.11	1.34531
2184.07	-5.16004
2185.03	-0.527811
2185.99	-3.29537
2186.95	-0.491611
2187.9	-0.46209
2188.86	-2.32281
2189.82	0.443277
2190.78	1.36585
2191.73	-0.477616
2192.69	1.39069
2193.65	-3.22994
2194.6	3.31055
2195.56	-0.403735
2196.52	-0.419921
2197.47	1.42097
2198.43	-0.428308
2199.38	3.31791
2200.34	5.22159
2201.3	2.48034
2202.25	-0.381374
2203.21	2.45395
2204.16	-3.05146
2205.12	2.51178
2206.07	5.24824
2207.03	0.604791
2207.98	-1.2346
2208.93	0.65186
2209.89	2.52919
2210.84	-3.04594
2211.8	0.702913
2212.75	-2.07279
2213.7	-1.14117
2214.66	-1.12294
2215.61	0.765938
2216.56	1.70916
2217.51	-1.08605
2218.47	1.72468
2219.42	-1.05809
2220.37	-0.103829
2221.32	2.7036
2222.27	-1.0449
2223.23	-1.03474
2224.18	0.861244
2225.13	-1.91162
2226.08	1.8632
2227.03	2.82902
2227.98	-0.898963
2228.93	-2.76971
2229.88	0.0539706
2230.83	1.02176
2231.78	0.113076
2232.73	-0.799454
2233.68	-1.71446
2234.63	2.06867
2235.58	3.94243
2236.53	2.06853
2237.48	2.08855
2238.43	-3.52013
2239.38	2.17323
2240.33	0.287766
2241.27	1.25223
2242.22	3.1572
2243.17	4.1213
2244.12	0.347519
2245.07	0.369119
2246.01	2.29837
2246.96	-0.511189
2247.91	-1.43613
2248.85	-1.4281
2249.8	1.42344
2250.75	-3.30009
2251.69	-2.35678
2252.64	2.38905
2253.59	2.43672
2254.53	0.57558
2255.48	-0.357477
2256.42	2.50615
2257.37	1.58692
2258.32	-1.23744
2259.26	-0.267237
2260.2	-0.244415
2261.15	0.729559
2262.1	0.757357
2263.04	2.68673
2263.98	2.72843
2264.93	0.867681
2265.87	-0.0588496
2266.81	-0.055703
2267.76	1.84933
2268.7	-0.058022
2269.65	-0.0299615
2270.59	1.92188
2271.53	-1.8713
2272.47	-0.889368
2273.42	1.04234
2274.36	0.10444
2275.3	-0.833603
2276.24	0.143309
2277.18	-0.78095
2278.13	0.220801
2279.07	-3.59205
2280.01	0.248397
2280.95	-1.67633
2281.89	2.16264
2282.83	-0.687196
2283.77	-2.56897
2284.71	-3.48543
2285.65	0.390129
2286.59	0.391658
2287.54	-1.49563
2288.47	1.41811
2289.41	-1.4733
2290.35	2.36135
2291.29	0.454361
2292.23	0.490464
2293.17	5.33943
2294.11	0.547678
2295.05	0.549896
2295.99	-0.411338
2296.93	1.50946
2297.86	-2.31312
2298.8	-0.353591
2299.74	1.6067
2300.68	-0.307809
2301.61	3.57707
2302.55	-1.23653
2303.49	2.63399
2304.43	-0.243011
2305.36	-1.18397
2306.3	0.768306
2307.24	-0.182574
2308.17	2.72103
2309.11	0.796918
2310.04	-0.139604
2310.98	1.81249
2311.92	-1.11035
2312.85	-1.11884
2313.79	-2.0689
2314.72	1.83124
2315.66	-0.0798452
2316.59	0.868213
2317.52	-0.0978711
2318.46	-0.0866555
2319.39	1.83804
2320.33	2.80239
2321.26	1.85001
2322.2	-0.0565608
2323.13	3.82879
2324.06	1.90596
2325	5.77005
2325.93	0.916177
2326.86	5.72505
2327.79	16.3105
2328.73	50.0392
2329.66	19.1713
2330.59	9.53673
2331.52	-1.06177
2332.46	0.869354
2333.39	-2.99722
2334.32	1.8032
2335.25	2.7457
2336.18	-4.95221
2337.11	2.73041
2338.04	2.71899
2338.97	5.59055
2339.91	1.73831
2340.84	4.59862
2341.77	0.719301
2342.7	5.48448
2343.63	1.63269
2344.56	1.61885
2345.49	4.47563
2346.41	-1.30719
2347.34	-1.32994
2348.27	2.48094
2349.2	0.548126
2350.13	-3.33096
2351.06	2.27115
2351.99	2.3409
2352.91	0.371388
2353.84	0.312567
2354.77	3.14231
2355.7	1.20758
2356.63	-0.744871
2357.55	-0.804321
2358.48	-1.80214
2359.41	-1.84899
2360.33	0.948597
2361.26	0.88621
2362.19	1.76779
2363.11	1.69943
2364.04	-1.19979
2364.97	-1.26107