File: Data/3-Raman/processed/bu02aw-a-ff1-fi03-v_1800 (450-850nm)_532nm_edge_100%_x100_vis_lwd_h100um_30sx2_01.txt
#Acq. time (s)=	30
#Accumulations=	2
#Range (cm-¹)=	1200...2365
#Windows=	3
#Auto scanning=	Off
#Autofocus=	Off
#Macrospot=	Off
#AutoExposure=	Off
#Spike filter=	Multiple accum.
#Delay time (s)=	2
#Binning=	1
#Readout mode=	Signal
#DeNoise=	Off
#ICS correction=	On
#Dark correction=	Off
#Inst. Process=	Off
#Detector Gain=	Best Dynamic
#Detector ADC=	50 kHz HS
#Detector temperature (°C)=	-60.09
#Instrument=	LabRAM HR Evol
#Detector=	SIN-EM FIVIS
#Objective=	x100_VIS_LWD
#Grating=	1800 (450-850nm)
#ND Filter=	100%
#Laser=	532nm_Edge
#Hole=	100.021
#Temperature=	0
#Range=	Visible
#StageXY=	75x50mm Scan+
#StageZ=	Z motor
#X (µm)=	0
#Y (µm)=	0
#Z (µm)=	-11.5
#Full time(mm:ss)=	3:13
#Project=	21_11_26
#Sample=	BU02Aw
#Site=
#Title=	BU02aW-A-FF1-FI03-V_1800 (450-850nm)_532nm_Edge_100%_x100_VIS_LWD_H100um_30sX2
#Remark=
#Date=	26.11.2021 11:11
#Acquired=	26.11.2021 11:11:48
#Base:Fit=	16.12.2021 16:15:35
#Base:Fit=	16.12.2021 16:18:23
#Base:Sub=	16.12.2021 16:18:24
1202.72	4.65473
1203.84	-0.337341
1204.95	-4.36967
1206.06	0.115013
1207.17	-0.830864
1208.28	0.41227
1209.39	2.70241
1210.5	-1.39605
1211.61	4.01613
1212.72	-0.184212
1213.83	-4.35791
1214.94	0.0334015
1216.05	-3.04958
1217.16	6.51625
1218.27	6.51521
1219.38	-6.19102
1220.49	-4.03442
1221.6	-2.94528
1222.71	-1.94465
1223.81	0.0576096
1224.92	-4.23604
1226.03	5.27978
1227.14	-1.07084
1228.25	-1.25571
1229.35	3.79639
1230.46	-0.221649
1231.57	-1.52635
1232.67	1.58464
1233.78	2.57039
1234.89	3.59869
1235.99	-1.68002
1237.1	-1.76207
1238.2	-2.98004
1239.31	9.43909
1240.41	0.945
1241.52	0.872078
1242.62	-1.33851
1243.73	-0.353172
1244.83	-3.58862
1245.94	-4.79786
1247.04	8.67399
1248.14	-1.90742
1249.25	3.18172
1250.35	2.03654
1251.45	2.90986
1252.56	-2.46965
1253.66	-2.62242
1254.76	3.58739
1255.87	3.50245
1256.97	7.60107
1258.07	7.48311
1259.17	14.6482
1260.27	17.7486
1261.37	20.6762
1262.48	40.6706
1263.58	86.1366
1264.68	115.872
1265.78	53.9384
1266.88	30.8659
1267.98	19.3876
1269.08	12.1111
1270.18	14.1313
1271.28	20.2484
1272.38	16.0029
1273.47	12.9088
1274.57	9.78957
1275.67	16.0346
1276.77	12.9029
1277.87	24.4855
1278.97	23.4811
1280.07	42.3886
1281.16	73.9048
1282.26	179.232
1283.36	667.27
1284.45	2046.08
1285.55	757.494
1286.65	144.482
1287.75	66.4743
1288.84	41.1625
1289.94	35.9588
1291.03	12.8111
1292.13	19.1159
1293.22	11.739
1294.32	13.9675
1295.42	6.61654
1296.51	11.0444
1297.61	7.87809
1298.7	4.67966
1299.79	1.49182
1300.89	6.82611
1301.98	2.6482
1303.08	0.595764
1304.17	-2.56198
1305.26	-1.46857
1306.35	-1.48836
1307.45	-0.395432
1308.54	3.88712
1309.63	-2.35609
1310.73	-1.22295
1311.82	2.02494
1312.91	1.08212
1314	1.1328
1315.09	1.22105
1316.18	0.291687
1317.28	-2.80222
1318.37	-6.91159
1319.46	-1.53078
1320.55	3.85105
1321.64	-7.71891
1322.73	-2.40582
1323.82	2.94702
1324.91	-5.37196
1326	6.28486
1327.09	-0.0512695
1328.18	0.207191
1329.27	3.59332
1330.35	5.81964
1331.44	0.607765
1332.53	-0.426918
1333.62	-0.395203
1334.71	4.90494
1335.79	0.780304
1336.88	-1.22176
1337.97	5.18217
1339.06	-1.01754
1340.14	-6.10485
1341.23	1.38593
1342.32	1.51178
1343.4	5.78461
1344.49	-3.4753
1345.58	-2.30222
1346.66	-2.24297
1347.75	-6.33752
1348.83	1.09309
1349.92	1.20767
1351	1.31874
1352.09	-1.68518
1353.17	5.82067
1354.25	1.91403
1355.34	3.98905
1356.42	3.12113
1357.51	4.3018
1358.59	3.39561
1359.67	6.63499
1360.76	7.77744
1361.84	12.0802
1362.92	8.09235
1364	14.5221
1365.09	24.0272
1366.17	14.8187
1367.25	19.0464
1368.33	13.0317
1369.41	55.6374
1370.5	51.6595
1371.58	17.6647
1372.66	18.7565
1373.74	17.8559
1374.82	32.444
1375.9	40.8757
1376.98	35.8688
1378.06	44.2588
1379.14	41.5477
1380.22	67.446
1381.3	67.3536
1382.38	79.7295
1383.46	101.248
1384.54	128
1385.61	223.818
1386.69	666.916
1387.77	3978.96
1388.85	1271.36
1389.93	212.465
1391	105.593
1392.08	62.6118
1393.16	51.4375
1394.23	45.4404
1395.31	30.2731
1396.39	31.5155
1397.46	29.605
1398.54	27.7245
1399.62	19.7638
1400.69	30.215
1401.77	30.4442
1402.84	23.596
1403.92	32.0761
1404.99	21.9276
1406.07	36.4031
1407.14	48.8511
1408.22	112.629
1409.29	206.185
1410.37	125.383
1411.44	42.3559
1412.51	20.9906
1413.59	12.1528
1414.66	17.3606
1415.73	12.4326
1416.81	12.6235
1417.88	11.7971
1418.95	11.9743
1420.02	15.1994
1421.1	12.2163
1422.17	6.21948
1423.24	12.6973
1424.31	16.7013
1425.38	13.7817
1426.45	3.69708
1427.52	5.82997
1428.59	3.86491
1429.67	6.07967
1430.74	4.23478
1431.81	2.4119
1432.87	2.51705
1433.95	4.60825
1435.01	5.79404
1436.08	1.83117
1437.15	2.9699
1438.22	8.20566
1439.29	6.3117
1440.36	-0.685963
1441.43	1.50863
1442.49	0.601048
1443.56	0.720585
1444.63	2.87916
1445.7	5.10077
1446.77	1.09368
1447.83	3.23632
1448.9	0.292591
1449.97	-4.73277
1451.03	-9.7753
1452.1	1.58494
1453.17	-2.41086
1454.23	0.776375
1455.3	0.873657
1456.36	-0.0371704
1457.43	4.1341
1458.49	6.26807
1459.56	1.25072
1460.62	3.3826
1461.69	-4.74732
1462.75	3.48893
1463.82	-0.570934
1464.88	-0.421375
1465.94	1.52869
1467.01	3.63005
1468.07	-1.40253
1469.13	-7.45394
1470.2	-2.31627
1471.26	-2.27288
1472.32	4.89536
1473.39	-10.3184
1474.45	-0.0985336
1475.51	0.994541
1476.57	-0.998066
1477.63	4.12
1478.69	-1.94323
1479.76	-8.01818
1480.82	0.102825
1481.88	-7.98069
1482.94	-0.785282
1484	0.292099
1485.06	4.27367
1486.12	3.28961
1487.18	4.35574
1488.24	2.34217
1489.3	5.37125
1490.36	1.34809
1491.42	-2.6891
1492.48	0.375999
1493.53	3.43751
1494.59	6.50277
1495.65	-5.61699
1496.71	4.45869
1497.77	5.48024
1498.82	-6.60558
1499.88	-2.52929
1500.94	0.528961
1502	1.53871
1503.05	0.529732
1504.11	5.56286
1505.17	-0.461624
1506.22	-0.494865
1507.28	-0.473137
1508.34	-0.45739
1509.39	0.565254
1510.45	-4.45192
1511.5	-3.48135
1512.56	-3.57665
1513.61	-2.6236
1514.67	4.45112
1515.72	-3.62545
1516.78	2.34735
1517.83	2.34229
1518.88	1.36532
1519.94	-4.6361
1520.99	0.374111
1522.05	-3.62868
1523.1	-6.66164
1524.15	-1.7122
1525.2	4.26923
1526.26	-3.72362
1527.31	-2.69759
1528.36	1.28399
1529.41	0.253891
1530.47	-2.77461
1531.52	3.26504
1532.57	1.24286
1533.62	2.29806
1534.67	-0.712643
1535.72	5.26513
1536.77	1.16114
1537.82	1.08483
1538.87	-7.96154
1539.92	4.11118
1540.97	0.186729
1542.02	3.14111
1543.07	4.06601
1544.12	-2.02148
1545.17	0.99749
1546.22	1.03641
1547.27	-3.97866
1548.32	0.981247
1549.37	3.92998
1550.42	-2.07517
1551.46	-1.93228
1552.51	4.07289
1553.56	3.00267
1554.61	5.94418
1555.65	5.86572
1556.7	6.83972
1557.75	6.82715
1558.79	-0.254963
1559.84	3.6559
1560.89	0.603191
1561.93	1.58999
1562.98	7.59879
1564.02	4.56254
1565.07	7.59061
1566.11	6.17642
1567.16	1.42581
1568.2	-1.55144
1569.25	-5.56205
1570.29	5.38013
1571.34	0.356884
1572.38	-5.68826
1573.43	1.24279
1574.47	-3.77922
1575.51	5.24133
1576.56	2.22766
1577.6	-0.862881
1578.64	-0.953892
1579.69	4.00225
1580.73	1.00467
1581.77	6.93433
1582.81	3.88474
1583.85	-0.13546
1584.9	1.83588
1585.94	0.813156
1586.98	-3.23654
1588.02	4.67865
1589.06	-3.28421
1590.1	-0.298923
1591.14	2.68325
1592.18	3.64401
1593.22	-0.415195
1594.26	9.41286
1595.3	3.44289
1596.34	-1.56549
1597.38	7.36048
1598.42	0.390114
1599.46	2.30286
1600.5	6.20935
1601.54	-5.76984
1602.58	0.0969391
1603.62	5.96099
1604.66	4.94021
1605.69	-0.0149918
1606.73	0.984596
1607.77	6.84102
1608.81	3.77362
1609.84	7.49889
1610.88	0.0389633
1611.92	10.1392
1612.95	1.34928
1613.99	1.10494
1615.03	2.93835
1616.06	2.78876
1617.1	1.01324
1618.13	3.633
1619.17	4.30959
1620.2	-1.45672
1621.24	3.5915
1622.27	2.91922
1623.31	3.87997
1624.34	3.64918
1625.38	1.50061
1626.41	4.56149
1627.45	4.33982
1628.48	5.91975
1629.51	2.68056
1630.55	5.76458
1631.53	-6.5617
1632.57	6.26964
1633.62	4.29354
1634.66	4.30772
1635.71	-3.58077
1636.75	6.25177
1637.8	8.19011
1638.84	4.23756
1639.89	-1.6648
1640.93	3.27073
1641.98	9.18297
1643.02	0.31675
1644.06	-0.669777
1645.11	5.21774
1646.15	3.27467
1647.19	4.24513
1648.24	6.20275
1649.28	4.29711
1650.32	4.30585
1651.37	6.33932
1652.41	1.43522
1653.45	0.449852
1654.49	1.45975
1655.53	2.48295
1656.57	6.50261
1657.62	5.53202
1658.66	-0.392906
1659.7	1.56555
1660.74	-0.397659
1661.78	6.56461
1662.82	5.66196
1663.86	6.67604
1664.9	5.6691
1665.94	4.62785
1666.98	6.69601
1668.02	4.71184
1669.06	7.70665
1670.1	2.83438
1671.14	1.91011
1672.18	2.91277
1673.21	5.90889
1674.25	2.98191
1675.29	3.0393
1676.33	7.03721
1677.37	-6.7863
1678.4	4.1013
1679.44	4.09253
1680.48	4.1007
1681.52	6.08658
1682.55	4.13913
1683.59	6.14149
1684.63	5.17024
1685.66	4.20316
1686.7	-3.65991
1687.73	3.29897
1688.77	7.25747
1689.81	-1.63116
1690.84	-3.58324
1691.88	4.36346
1692.91	3.40496
1693.95	-0.557022
1694.98	-2.52982
1696.01	0.46912
1697.05	-1.45068
1698.08	-1.4537
1699.12	-1.45056
1700.15	-5.35102
1701.18	-1.38988
1702.22	1.57294
1703.25	1.57912
1704.28	3.56976
1705.32	-2.27556
1706.35	-1.26427
1707.38	0.691944
1708.41	-2.26611
1709.44	5.5483
1710.48	0.682152
1711.51	-3.17588
1712.54	3.72435
1713.57	-3.16127
1714.6	-1.21498
1715.63	3.71154
1716.66	-1.13122
1717.69	-1.15069
1718.72	-0.214203
1719.75	-2.13727
1720.78	2.77187
1721.81	1.79692
1722.84	5.67657
1723.87	1.79498
1724.9	-5.94324
1725.93	-2.0823
1726.96	3.75855
1727.99	-2.0253
1729.02	1.79185
1730.05	0.818573
1731.07	-1.09706
1732.1	3.83742
1733.13	6.75807
1734.16	-1.95456
1735.18	-1.00605
1736.21	0.91758
1737.24	4.78785
1738.26	-0.00669861
1739.29	-4.80838
1740.32	-0.0352707
1741.34	0.910831
1742.37	3.79332
1743.4	-0.00671387
1744.42	1.92674
1745.45	1.96094
1746.47	-1.83833
1747.5	1.9761
1748.52	-3.73733
1749.55	-0.818085
1750.57	-0.734642
1751.6	-0.669598
1752.62	3.14938
1753.64	0.286121
1754.67	-4.47584
1755.69	-8.26818
1756.71	-0.643265
1757.74	3.15427
1758.76	4.16562
1759.78	0.40712
1760.81	1.38763
1761.83	3.29888
1762.85	1.43583
1763.87	4.33613
1764.89	2.51422
1765.92	-2.1818
1766.94	-1.19234
1767.96	7.39915
1768.98	2.6594
1770	-4.03961
1771.02	-0.17643
1772.04	-1.04852
1773.06	-0.0310402
1774.08	1.93232
1775.1	-3.72653
1776.12	1.11986
1777.14	2.11027
1778.16	1.16308
1779.18	-5.50374
1780.2	4.99318
1781.22	3.14264
1782.24	-1.56837
1783.26	1.35606
1784.28	-1.44452
1785.29	2.43709
1786.31	-4.21947
1787.33	0.605919
1788.35	1.68578
1789.37	0.832298
1790.38	3.78242
1791.4	1.89022
1792.42	0.924801
1793.43	-1.90406
1794.45	-1.86507
1795.47	-1.79588
1796.48	0.203754
1797.5	1.22965
1798.51	3.20425
1799.53	-1.58071
1800.55	4.17946
1801.56	2.26884
1802.58	0.382397
1803.59	-2.44362
1804.61	1.44777
1805.62	2.47474
1806.64	0.60976
1807.65	1.60839
1808.66	1.63263
1809.68	3.58841
1810.69	10.3644
1811.7	-2.15631
1812.72	5.58318
1813.73	-2.08905
1814.74	0.866066
1815.76	-0.0470352
1816.77	-4.85374
1817.78	3.83172
1818.79	1.92241
1819.8	3.88439
1820.82	1.9873
1821.83	1.057
1822.84	-1.81463
1823.85	1.10092
1824.86	4.98595
1825.87	3.07828
1826.88	0.185387
1827.89	1.17663
1828.9	6.99584
1829.91	-1.72981
1830.92	5.03608
1831.93	6.03055
1832.94	5.09803
1833.95	0.269989
1834.96	0.242741
1835.97	5.97881
1836.98	4.23156
1837.99	-1.73234
1839	4.07165
1840	2.20291
1841.01	4.0421
1842.02	5.88018
1843.03	0.0457802
1844.04	0.0430603
1845.04	2.93515
1846.05	-4.7742
1847.06	7.81856
1848.07	2.81504
1849.07	5.70654
1850.08	2.77364
1851.09	10.3932
1852.09	4.5862
1853.1	2.65369
1854.1	-0.25518
1855.11	1.60401
1856.11	2.50487
1857.12	1.52783
1858.12	6.2846
1859.13	8.14165
1860.13	6.1775
1861.14	4.27247
1862.14	6.1988
1863.15	6.14839
1864.15	11.8187
1865.15	3.16447
1866.16	3.08337
1867.16	6.78926
1868.16	11.457
1869.17	5.72602
1870.17	5.69565
1871.17	10.4174
1872.17	8.47392
1873.18	8.41759
1874.18	10.2702
1875.18	4.50449
1876.18	9.13904
1877.18	9.05458
1878.18	8.94874
1879.19	9.01416
1880.19	10.9252
1881.19	8.99699
1882.19	16.4499
1883.19	6.8544
1884.19	13.3638
1885.19	12.4216
1886.19	17.187
1887.19	14.3153
1888.19	10.4521
1889.19	10.3423
1890.19	12.1593
1891.19	10.2785
1892.18	12.1153
1893.18	9.23023
1894.18	18.5074
1895.18	11.8651
1896.18	9.02845
1897.18	9.02851
1898.17	10.8872
1899.17	9.8752
1900.17	15.4345
1901.16	13.5147
1902.16	3.17982
1903.16	8.8024
1904.16	8.74053
1905.15	11.5102
1906.15	12.3852
1907.14	8.54461
1908.14	2.87391
1909.14	10.37
1910.13	7.55822
1911.13	11.3485
1912.12	5.66955
1913.12	9.38354
1914.11	5.59667
1915.11	7.48985
1916.1	8.40846
1917.1	11.1639
1918.09	10.1458
1919.08	14.8538
1920.08	12.0603
1921.07	6.35459
1922.06	7.29658
1923.06	7.24022
1924.05	6.22311
1925.04	11.816
1926.04	10.8626
1927.03	9.9333
1928.02	6.1315
1929.01	7.99944
1930	4.20209
1931	11.8025
1931.99	8.89732
1932.98	6.91551
1933.97	8.77105
1934.96	3.17507
1935.95	9.913
1936.94	4.08703
1937.93	7.79644
1938.92	7.74063
1939.91	2.95679
1940.9	0.0796051
1941.89	7.70437
1942.88	0.99287
1943.87	2.81782
1944.86	0.891304
1945.85	3.75282
1946.84	9.47235
1947.83	2.71516
1948.82	0.741615
1949.8	1.67584
1950.79	7.44124
1951.78	2.67598
1952.77	8.42609
1953.76	4.53545
1954.74	1.48954
1955.73	6.19769
1956.72	1.43864
1957.7	-1.45038
1958.69	-4.36494
1959.68	-2.51408
1960.66	2.20785
1961.65	3.07539
1962.63	-2.73785
1963.62	8.73315
1964.61	-1.86694
1965.59	4.79265
1966.58	6.68787
1967.56	2.81441
1968.55	-3.00031
1969.53	0.761467
1970.52	4.48792
1971.5	0.562454
1972.48	-0.453259
1973.47	0.439117
1974.45	4.18506
1975.44	5.09247
1976.42	2.18853
1977.4	0.218418
1978.39	3.01326
1979.37	1.98232
1980.35	1.93176
1981.33	1.84808
1982.31	-0.141796
1983.3	0.729279
1984.28	1.59496
1985.26	2.47185
1986.24	0.487919
1987.22	2.36389
1988.21	-0.596401
1989.19	-3.56312
1990.17	5.51252
1991.15	-0.571346
1992.13	-0.914913
1993.11	-2.33413
1994.09	-1.92456
1995.07	2.60828
1996.05	3.05039
1997.03	1.01892
1998.01	-0.752392
1998.99	2.41333
1999.97	0.799961
2000.95	-0.139248
2001.92	-1.9434
2002.9	-1.29899
2003.88	-0.852047
2004.86	-1.3181
2005.84	0.306572
2006.81	-1.40569
2007.79	-1.15651
2008.77	-4.53598
2009.75	-0.833233
2010.73	4.29661
2011.7	5.7168
2012.68	3.40419
2013.67	6.1255
2014.66	-2.45648
2015.64	-3.45475
2016.63	-2.53518
2017.62	-6.30188
2018.61	-0.768658
2019.6	0.993202
2020.58	3.74239
2021.57	-0.977497
2022.56	3.65291
2023.55	-0.1768
2024.54	1.61273
2025.52	-1.29318
2026.51	3.2934
2027.5	0.59201
2028.48	-3.23944
2029.47	3.34851
2030.45	-6.17773
2031.44	-8.05977
2032.43	3.11287
2033.41	-1.52584
2034.4	1.25001
2035.38	-1.663
2036.37	-0.656429
2037.35	-2.57455
2038.34	1.118
2039.32	1.05313
2040.31	0.0431938
2041.29	1.82611
2042.27	0.838196
2043.26	-1.07815
2044.24	0.814568
2045.23	-4.84031
2046.21	-1.03907
2047.19	-0.182205
2048.17	-1.20864
2049.16	-3.09023
2050.14	1.60185
2051.12	0.678848
2052.11	-3.11425
2053.09	1.54382
2054.07	1.57337
2055.05	-0.307678
2056.03	-0.359337
2057.01	2.40149
2058	1.45282
2058.98	0.531715
2059.96	-1.34182
2060.94	4.22916
2061.92	0.481411
2062.9	3.27777
2063.88	-0.461395
2064.86	4.2214
2065.84	5.1891
2066.82	-1.37287
2067.8	1.44373
2068.78	5.20489
2069.76	-2.35128
2070.73	1.37949
2071.71	0.450954
2072.69	-2.32318
2073.67	-3.29567
2074.65	0.461037
2075.63	1.44711
2076.6	-1.34793
2077.58	0.492611
2078.56	8.0055
2079.54	5.18663
2080.51	1.44403
2081.49	0.477203
2082.47	-0.487976
2083.45	1.38898
2084.42	-4.30418
2085.4	5.12835
2086.37	-1.48968
2087.35	4.2067
2088.32	3.25754
2089.3	4.19487
2090.28	2.32036
2091.25	7.05758
2092.23	0.446552
2093.2	-2.35406
2094.18	0.527065
2095.15	-0.431057
2096.13	-1.42825
2097.1	2.34037
2098.07	1.33992
2099.05	2.2586
2100.02	3.18242
2101	-0.620579
2101.97	0.344791
2102.94	-0.625828
2103.92	-0.668709
2104.89	-1.62441
2105.86	1.2446
2106.83	7.90702
2107.8	-0.661785
2108.78	2.11985
2109.75	1.15426
2110.72	3.04975
2111.69	-8.36958
2112.66	1.09739
2113.63	0.161705
2114.61	-3.64741
2115.58	3.93947
2116.55	2.94846
2117.52	0.0631523
2118.49	1.92582
2119.46	3.75249
2120.43	-1.04282
2121.4	-1.04628
2122.37	3.72787
2123.34	-1.00068
2124.31	1.8279
2125.28	3.63755
2126.25	5.43758
2127.21	2.53251
2128.18	-2.23267
2129.15	-4.14698
2130.12	8.11182
2131.09	-5.14811
2132.06	-0.469433
2133.02	-5.23462
2133.99	-2.42077
2134.96	2.2852
2135.93	-0.572762
2136.89	4.0766
2137.86	-3.47032
2138.83	-2.56138
2139.79	-2.56536
2140.76	2.08682
2141.73	-3.5939
2142.69	1.07107
2143.66	-1.72981
2144.62	4.73437
2145.59	0.959938
2146.55	-3.76667
2147.52	3.71441
2148.48	-2.90423
2149.45	-0.135456
2150.42	-3.02639
2151.38	2.56873
2152.34	-0.234425
2153.31	0.668282
2154.27	-4.06187
2155.24	-2.27695
2156.2	1.37619
2157.16	-4.26628
2158.13	-2.39555
2159.09	-3.34054
2160.05	-3.38741
2161.01	-1.58453
2161.98	2.11066
2162.94	2.08924
2163.9	-3.54836
2164.86	1.98892
2165.83	-5.48523
2166.79	1.93949
2167.75	1.88007
2168.71	2.71403
2169.67	-1.0046
2170.63	-1.89046
2171.59	0.869038
2172.56	3.54734
2173.51	2.5783
2174.48	0.715302
2175.44	-2.09121
2176.4	-0.264175
2177.36	-4.01627
2178.32	0.611183
2179.28	-3.15517
2180.23	2.39851
2181.19	-4.13003
2182.15	5.11367
2183.11	3.21535
2184.07	2.21489
2185.03	-3.38351
2185.99	1.24858
2186.95	0.343956
2187.9	-5.19047
2188.86	-0.590496
2189.82	-4.37794
2190.78	-1.63989
2191.73	0.20451
2192.69	-2.58149
2193.65	-1.64486
2194.6	3.05683
2195.56	7.67653
2196.52	-0.763844
2197.47	-1.76294
2198.43	-3.64091
2199.38	-1.74876
2200.34	9.46481
2201.3	-3.49303
2202.25	2.81829
2203.21	1.96333
2204.16	1.20858
2205.12	-2.6421
2206.07	1.86128
2207.03	2.76366
2207.98	-0.945393
2208.93	2.79942
2209.89	-0.930149
2210.84	2.78864
2211.8	3.73522
2212.75	4.68394
2213.7	2.77182
2214.66	-6.55202
2215.61	0.925171
2216.56	5.57483
2217.51	-2.85606
2218.47	2.72742
2219.42	2.7319
2220.37	8.3478
2221.32	-0.0966034
2222.27	-2.03501
2223.23	-0.185913
2224.18	-0.161179
2225.13	-1.99562
2226.08	-3.83855
2227.03	5.55318
2227.98	-1.93692
2228.93	0.842476
2229.88	-4.80038
2230.83	-3.83858
2231.78	-1.93454
2232.73	-0.972706
2233.68	0.929024
2234.63	1.87261
2235.58	-1.95017
2236.53	0.845154
2237.48	7.43412
2238.43	5.61838
2239.38	-1.8736
2240.33	4.68669
2241.27	3.75244
2242.22	-1.91098
2243.17	-2.85378
2244.12	-4.77849
2245.07	1.83683
2246.01	-0.00141907
2246.96	0.966682
2247.91	-2.80912
2248.85	2.84405
2249.8	-0.00812912
2250.75	-0.0335579
2251.69	-1.03496
2252.64	-4.81784
2253.59	-3.81136
2254.53	1.91095
2255.48	4.74951
2256.42	-0.937138
2257.37	-0.910782
2258.32	-5.64326
2259.26	-1.83658
2260.2	-4.67387
2261.15	1.04483
2262.1	0.120377
2263.04	-1.76318
2263.98	-2.66311
2264.93	4.08543
2265.87	-0.658268
2266.81	-0.691364
2267.76	2.12244
2268.7	3.03575
2269.65	1.16057
2270.59	-1.63942
2271.53	0.307339
2272.47	1.29205
2273.42	-3.48451
2274.36	0.35273
2275.3	-1.55087
2276.24	-0.581532
2277.18	-2.44921
2278.13	-2.37944
2279.07	-4.26459
2280.01	-2.38111
2280.95	-0.513901
2281.89	0.421364
2282.83	3.33033
2283.77	0.520733
2284.71	-3.23131
2285.65	2.58109
2286.59	-0.333549
2287.54	8.39839
2288.47	4.58065
2289.41	3.57783
2290.35	1.58736
2291.29	-1.28546
2292.23	-3.14846
2293.17	2.68312
2294.11	2.72109
2295.05	1.73624
2295.99	2.67719
2296.93	6.48869
2297.86	-4.05067
2298.8	-1.09803
2299.74	-4.89849
2300.68	-0.06007
2301.61	1.91203
2302.55	-1.93745
2303.49	-0.965755
2304.43	-0.937527
2305.36	-1.85691
2306.3	0.109772
2307.24	3.0334
2308.17	3.99542
2309.11	-1.79459
2310.04	-4.63377
2310.98	3.13596
2311.92	-3.70037
2312.85	3.02221
2313.79	4.98407
2314.72	-0.722961
2315.66	-0.674141
2316.59	-3.62566
2317.52	2.16271
2318.46	7.01593
2319.39	4.09635
2320.33	9.88106
2321.26	9.91267
2322.2	6.11792
2323.13	4.23641
2324.06	12.9668
2325	15.8591
2325.93	25.4499
2326.86	44.6912
2327.79	125.603
2328.73	378.106
2329.66	111.984
2330.59	34.9253
2331.52	18.5481
2332.46	10.8685
2333.39	4.09415
2334.32	0.221397
2335.25	1.14864
2336.18	-2.69553
2337.11	-4.63099
2338.04	0.163731
2338.97	5.91743
2339.91	0.147919
2340.84	1.0729
2341.77	1.95774
2342.7	-3.84911
2343.63	1.8818
2344.56	0.909401
2345.49	-1.03239
2346.41	-5.88169
2347.34	-2.08527
2348.27	2.67849
2349.2	-2.12906
2350.13	-1.28123
2351.06	-1.56585
2351.99	2.43495
2352.91	-1.50488
2353.84	2.18771
2354.77	-0.712223
2355.7	-0.756588
2356.63	-2.75015
2357.55	-0.0166092
2358.48	-2.00706
2359.41	-6.84455
2360.33	0.656223
2361.26	7.17243
2362.19	-7.18063
2363.11	-6.36214
2364.04	2.03965
2364.97	-4.70323