File: Data/3-Raman/processed/bu02aw-a-ff1-fi05-v_1800 (450-850nm)_532nm_edge_100%_x100_vis_lwd_h50um_30sx2_01.txt
#Acq. time (s)=	30
#Accumulations=	2
#Range (cm-¹)=	1200...2365
#Windows=	3
#Auto scanning=	Off
#Autofocus=	Off
#Macrospot=	Off
#AutoExposure=	Off
#Spike filter=	Multiple accum.
#Delay time (s)=	2
#Binning=	1
#Readout mode=	Signal
#DeNoise=	Off
#ICS correction=	On
#Dark correction=	Off
#Inst. Process=	Off
#Detector Gain=	Best Dynamic
#Detector ADC=	50 kHz HS
#Detector temperature (°C)=	-60.09
#Instrument=	LabRAM HR Evol
#Detector=	SIN-EM FIVIS
#Objective=	x100_VIS_LWD
#Grating=	1800 (450-850nm)
#ND Filter=	100%
#Laser=	532nm_Edge
#Hole=	49.98
#Temperature=	0
#Range=	Visible
#StageXY=	75x50mm Scan+
#StageZ=	Z motor
#X (µm)=	0
#Y (µm)=	0
#Z (µm)=	-17.2
#Full time(mm:ss)=	3:28
#Project=	21_11_26
#Sample=	BU02Aw
#Site=
#Title=	BU02aW-A-FF1-FI05-V_1800 (450-850nm)_532nm_Edge_100%_x100_VIS_LWD_H50um_30sX2
#Remark=
#Date=	26.11.2021 10:48
#Acquired=	26.11.2021 10:48:18
#Base:Fit=	16.12.2021 16:15:35
#Base:Fit=	16.12.2021 16:19:41
#Base:Sub=	16.12.2021 16:19:42
1202.72	-0.205326
1203.84	-1.16963
1204.95	3.1906
1206.06	-0.0138092
1207.17	-1.09105
1208.28	1.06506
1209.39	-0.000728607
1210.5	3.22163
1211.61	-2.15039
1212.72	-0.0499992
1213.83	-0.0765915
1214.94	-1.14709
1216.05	-1.1625
1217.16	-0.165688
1218.27	-3.41367
1219.38	-3.46309
1220.49	2.85159
1221.6	5.97867
1222.71	-0.476112
1223.81	-3.76366
1224.92	-3.85646
1226.03	-1.8031
1227.14	-1.87403
1228.25	-0.966244
1229.35	-7.42571
1230.46	2.05989
1231.57	-3.37891
1232.67	-1.35806
1233.78	-0.39806
1234.89	-0.469395
1235.99	2.61393
1237.1	-0.637314
1238.2	4.4746
1239.31	-0.908871
1240.41	-3.11106
1241.52	0.991673
1242.62	-0.16563
1243.73	-3.39434
1244.83	-2.44238
1245.94	-0.476295
1247.04	3.59348
1248.14	2.44079
1249.25	5.45971
1250.35	7.4548
1251.45	2.09399
1252.56	-5.33927
1253.66	4.97873
1254.76	2.82178
1255.87	0.647518
1256.97	6.83183
1258.07	6.73094
1259.17	14.9687
1260.27	7.60534
1261.37	12.6843
1262.48	20.0308
1263.58	42.7308
1264.68	75.3386
1265.78	41.7075
1266.88	22.8202
1267.98	12.3445
1269.08	9.19754
1270.18	10.1741
1271.28	14.2446
1272.38	8.95003
1273.47	17.3262
1274.57	4.73164
1275.67	13.069
1276.77	12.0016
1277.87	15.141
1278.97	23.5514
1280.07	16.1499
1281.16	40.296
1282.26	101.356
1283.36	371.648
1284.45	1201.88
1285.55	517.328
1286.65	93.8912
1287.75	28.5392
1288.84	21.124
1289.94	9.54934
1291.03	9.53774
1292.13	10.5626
1293.22	6.32711
1294.32	6.36678
1295.42	5.3083
1296.51	1.16497
1297.61	2.20606
1298.7	4.28687
1299.79	1.09169
1300.89	2.15815
1301.98	-1.00338
1303.08	-4.15879
1304.17	-4.16717
1305.26	2.172
1306.35	2.14571
1307.45	3.20513
1308.54	0.0592117
1309.63	0.0891609
1310.73	0.115616
1311.82	3.31052
1312.91	2.30025
1314	2.31379
1315.09	1.29136
1316.18	-1.82435
1317.28	1.37116
1318.37	2.47654
1319.46	3.57309
1320.55	-1.66846
1321.64	-4.82013
1322.73	1.52089
1323.82	7.87878
1324.91	-0.50592
1326	-1.53555
1327.09	-1.54642
1328.18	-2.48092
1329.27	-4.49055
1330.35	1.89196
1331.44	-0.191727
1332.53	0.86525
1333.62	-4.38102
1334.71	-2.25601
1335.79	-0.122581
1336.88	-0.0792274
1337.97	2.0703
1339.06	-8.36357
1340.14	2.17905
1341.23	0.16127
1342.32	-0.825733
1343.4	-1.82874
1344.49	-0.708965
1345.58	0.397141
1346.66	1.46632
1347.75	4.62716
1348.83	-3.64818
1349.92	1.61742
1351	5.83302
1352.09	10.0449
1353.17	-2.32465
1354.25	-0.118599
1355.34	5.07727
1356.42	2.04445
1357.51	3.15304
1358.59	4.25549
1359.67	2.24303
1360.76	8.51373
1361.84	1.34114
1362.92	7.63215
1364	7.74075
1365.09	5.76123
1366.17	13.063
1367.25	6.90158
1368.33	0.793667
1369.41	29.8497
1370.5	33.0289
1371.58	14.477
1372.66	11.4062
1373.74	12.5012
1374.82	8.46227
1375.9	15.7699
1376.98	18.9331
1378.06	26.2168
1379.14	30.5391
1380.22	28.5422
1381.3	35.7068
1382.38	42.9213
1383.46	56.2425
1384.54	59.3639
1385.61	118.045
1386.69	341.14
1387.77	2199.46
1388.85	824.227
1389.93	132.915
1391	56.8831
1392.08	34.3662
1393.16	24.1713
1394.23	23.2215
1395.31	19.2207
1396.39	21.38
1397.46	20.4233
1398.54	9.25443
1399.62	11.4133
1400.69	14.5933
1401.77	10.6123
1402.84	9.74642
1403.92	19.1188
1404.99	13.0179
1406.07	21.2811
1407.14	31.6054
1408.22	57.3457
1409.29	130.278
1410.37	79.113
1411.44	26.8241
1412.51	14.6046
1413.59	7.62872
1414.66	6.64044
1415.73	8.79645
1416.81	2.73158
1417.88	4.88618
1418.95	10.1138
1420.02	6.07543
1421.1	2.01952
1422.17	2.10165
1423.24	4.30979
1424.31	6.31999
1425.38	11.5267
1426.45	3.4087
1427.52	3.44959
1428.59	1.44344
1429.67	3.57519
1430.74	4.70347
1431.81	3.7953
1432.87	2.82109
1433.95	2.84073
1435.01	2.92156
1436.08	4.01427
1437.15	4.07068
1438.22	0.0312595
1439.29	11.3764
1440.36	4.29501
1441.43	3.34237
1442.49	-3.77704
1443.56	1.4095
1444.63	0.437994
1445.7	-1.53049
1446.77	0.569515
1447.83	2.66573
1448.9	1.70638
1449.97	-3.3707
1451.03	-0.254656
1452.1	2.86173
1453.17	0.863024
1454.23	6.0428
1455.3	-1.08263
1456.36	-6.15164
1457.43	2.0828
1458.49	-0.948717
1459.56	2.17588
1460.62	3.24053
1461.69	-0.826151
1462.75	-1.82662
1463.82	-1.80966
1464.88	2.35598
1465.94	2.3024
1467.01	1.31073
1468.07	-0.696854
1469.13	-1.68408
1470.2	2.41107
1471.26	-2.66463
1472.32	3.4645
1473.39	-0.580721
1474.45	0.454809
1475.51	1.50853
1476.57	-2.54232
1477.63	-4.56054
1478.69	-0.475178
1479.76	0.549175
1480.82	-1.48634
1481.88	-2.48583
1482.94	-6.50384
1484	0.632076
1485.06	-5.48704
1486.12	1.61939
1487.18	4.68333
1488.24	2.66045
1489.3	2.65383
1490.36	-2.39498
1491.42	-0.369625
1492.48	0.654984
1493.53	0.666943
1494.59	1.69175
1495.65	-3.35934
1496.71	1.67678
1497.77	2.68992
1498.82	-2.34624
1499.88	-2.32935
1500.94	-0.298094
1502	0.709112
1503.05	1.71534
1504.11	5.74117
1505.17	0.709816
1506.22	2.70497
1507.28	-1.31698
1508.34	-3.32701
1509.39	0.708385
1510.45	-2.30671
1511.5	-0.313463
1512.56	-0.366186
1513.61	3.61998
1514.67	3.64182
1515.72	1.60718
1516.78	2.58241
1517.83	3.57968
1518.88	-0.421196
1519.94	2.5949
1520.99	2.58883
1522.05	-3.42829
1523.1	1.57254
1524.15	2.53656
1525.2	-2.4881
1526.26	2.52746
1527.31	-1.47057
1528.36	-6.49636
1529.41	-4.50725
1530.47	-1.51657
1531.52	-2.50756
1532.57	-1.51681
1533.62	-0.492624
1534.67	2.5132
1535.72	0.485128
1536.77	-0.564978
1537.82	0.395996
1538.87	-3.62963
1539.92	0.402504
1540.97	-1.56493
1542.02	0.412069
1543.07	6.37979
1544.12	-2.67119
1545.17	2.33726
1546.22	-0.648636
1547.27	-2.6577
1548.32	-3.68417
1549.37	-3.71063
1550.42	2.29272
1551.46	0.363533
1552.51	3.36417
1553.56	-1.68871
1554.61	4.29413
1555.65	-0.756651
1556.7	4.2362
1557.75	-0.780731
1558.79	1.18535
1559.84	1.13793
1560.89	-1.88879
1561.93	3.10067
1562.98	0.10409
1564.02	-1.91481
1565.07	-3.90808
1566.11	-2.08362
1567.16	-1.98462
1568.2	2.02132
1569.25	2.01515
1570.29	-1.012
1571.34	-1.02629
1572.38	3.94184
1573.43	1.91162
1574.47	0.896807
1575.51	-3.08402
1576.56	0.90361
1577.6	3.84942
1578.64	1.80436
1579.69	-0.204582
1580.73	0.788406
1581.77	2.75579
1582.81	3.72149
1583.85	0.714588
1584.9	-0.292244
1585.94	-0.305824
1586.98	-2.33034
1588.02	-2.35231
1589.06	1.6266
1590.1	1.62697
1591.14	-6.34262
1592.18	-3.37127
1593.22	0.572863
1594.26	-0.474207
1595.3	3.49507
1596.34	-1.49239
1597.38	-3.4857
1598.42	2.4664
1599.46	-0.548658
1600.5	-1.56914
1601.54	1.3641
1602.58	-2.6345
1603.62	0.300734
1604.66	0.286249
1605.69	0.281528
1606.73	3.25571
1607.77	1.23989
1608.81	1.43708
1609.84	3.18888
1610.88	3.03425
1611.92	-0.232252
1612.95	0.275177
1613.99	0.779814
1615.03	3.07124
1616.06	1.61567
1617.1	0.474411
1618.13	-0.131882
1619.17	4.96882
1620.2	2.66795
1621.24	2.92335
1622.27	1.54521
1623.31	0.953844
1624.34	0.847582
1625.38	4.09081
1626.41	1.64429
1627.45	1.82851
1628.48	2.85853
1629.51	0.802614
1630.55	-0.958263
1631.53	-0.995714
1632.57	3.94296
1633.62	-0.00196075
1634.66	0.00452995
1635.71	-0.98321
1636.75	-0.00883293
1637.8	-1.0081
1638.84	2.9226
1639.89	4.89316
1640.93	-0.0216541
1641.98	2.9346
1643.02	-3.95911
1644.06	4.89818
1645.11	1.93682
1646.15	3.91825
1647.19	4.89445
1648.24	0.955479
1649.28	0.986963
1650.32	5.91366
1651.37	2.00986
1652.41	4.97877
1653.45	3.00793
1654.49	0.0657558
1655.53	1.07176
1656.57	-1.85084
1657.62	2.1066
1658.66	0.131891
1659.7	3.08375
1660.74	1.11711
1661.78	2.13505
1662.82	1.19169
1663.86	-2.74566
1664.9	3.17353
1665.94	1.17338
1666.98	0.234968
1668.02	1.21941
1669.06	6.17353
1670.1	1.27284
1671.14	2.29665
1672.18	2.30556
1673.21	5.28897
1674.25	5.31197
1675.29	-5.53683
1676.33	0.421635
1677.37	-0.549343
1678.4	-3.51368
1679.44	2.41907
1680.48	1.43701
1681.52	-1.51922
1682.55	-2.49005
1683.59	3.45358
1684.63	1.48907
1685.66	0.514812
1686.7	0.53665
1687.73	-1.41287
1688.77	-1.40448
1689.81	2.54418
1690.84	0.583845
1691.88	0.614603
1692.91	0.632202
1693.95	0.626026
1694.98	-0.35849
1696.01	0.652357
1697.05	4.62417
1698.08	4.62104
1699.12	1.66969
1700.15	-3.22886
1701.18	2.69045
1702.22	0.731977
1703.25	-1.22704
1704.28	-1.20995
1705.32	1.76686
1706.35	1.78451
1707.38	1.78178
1708.41	-3.12741
1709.44	-0.19422
1710.48	-1.15421
1711.51	-2.09966
1712.54	2.82396
1713.57	2.80482
1714.6	-0.130947
1715.63	0.871523
1716.66	1.8737
1717.69	0.888252
1718.72	3.79166
1719.75	-1.06166
1720.78	-0.0628338
1721.81	-0.0589886
1722.84	-0.0582142
1723.87	-2.964
1724.9	-1.00287
1725.93	-3.91896
1726.96	0.945084
1727.99	-1.94197
1729.02	0.937914
1730.05	-0.0278683
1731.07	-0.0158081
1732.1	1.97533
1733.13	-2.83906
1734.16	1.01695
1735.18	-1.87998
1736.21	1.97503
1737.24	0.065546
1738.26	-0.88341
1739.29	-0.877325
1740.32	1.03079
1741.34	1.02755
1742.37	2.9517
1743.4	2.97077
1744.42	3.94083
1745.45	-2.7331
1746.47	-1.75785
1747.5	-7.48647
1748.52	1.12134
1749.55	3.06485
1750.57	0.249111
1751.6	-0.668112
1752.62	-1.61911
1753.64	2.20529
1754.67	-3.50998
1755.69	2.22399
1756.71	-1.58217
1757.74	0.322466
1758.76	1.30944
1759.78	1.33913
1760.81	-0.543974
1761.83	2.319
1762.85	2.34375
1763.87	0.47205
1764.89	-1.38534
1765.92	1.5077
1766.94	2.48393
1767.96	1.54995
1768.98	0.613245
1770	-3.20572
1771.02	-1.26851
1772.04	1.6291
1773.06	-4.03898
1774.08	-0.197266
1775.1	3.64457
1776.12	-0.115643
1777.14	-2.95078
1778.16	-1.03517
1779.18	-1.03091
1780.2	3.74713
1781.22	2.82842
1782.24	1.90781
1783.26	-1.86279
1784.28	2.93924
1785.29	-0.835644
1786.31	1.08854
1787.33	-2.69423
1788.35	1.1941
1789.37	2.21146
1790.38	2.25698
1791.4	0.358145
1792.42	-4.4285
1793.43	0.388559
1794.45	4.24726
1795.47	2.37498
1796.48	-0.455515
1797.5	-0.417036
1798.51	-1.34703
1799.53	0.592855
1800.55	1.55576
1801.56	1.56669
1802.58	2.55096
1803.59	3.54963
1804.61	-1.22941
1805.62	2.65835
1806.64	0.769926
1807.65	1.75728
1808.66	1.7753
1809.68	-0.13283
1810.69	-0.113831
1811.7	-1.06557
1812.72	1.84583
1813.73	2.83909
1814.74	3.84388
1815.76	1.9467
1816.77	0.0330563
1817.78	0.998371
1818.79	1.01565
1819.8	2.0026
1820.82	2.02716
1821.83	1.08484
1822.84	-0.828728
1823.85	2.08673
1824.86	2.09897
1825.87	-0.785917
1826.88	0.194416
1827.89	4.08673
1828.9	0.220451
1829.91	1.19077
1830.92	0.221813
1831.93	0.23975
1832.94	1.23144
1833.95	1.24632
1834.96	1.2372
1835.97	7.0101
1836.98	2.27567
1837.99	4.1361
1839	-0.6987
1840	1.27679
1841.01	2.20054
1842.02	3.12383
1843.03	1.1762
1844.04	0.215792
1845.04	2.14976
1846.05	4.09082
1847.06	3.15523
1848.07	2.10377
1849.07	3.07388
1850.08	2.09344
1851.09	0.141874
1852.09	1.08796
1853.1	1.08748
1854.1	2.0381
1855.11	1.05272
1856.11	0.0710392
1857.12	4.85608
1858.12	1.0148
1859.13	3.86352
1860.13	1.93074
1861.14	0.983381
1862.14	0.994633
1863.15	1.93234
1864.15	1.90699
1865.15	1.88469
1866.16	2.8023
1867.16	4.65789
1868.16	3.66727
1869.17	6.51169
1870.17	4.60017
1871.17	4.59016
1872.17	0.773806
1873.18	6.44983
1874.18	-0.212301
1875.18	5.44898
1876.18	2.55884
1877.18	2.5238
1878.18	4.36768
1879.19	0.621923
1880.19	10.1016
1881.19	0.621717
1882.19	6.24955
1883.19	3.34749
1884.19	5.19383
1885.19	1.42749
1886.19	3.3378
1887.19	2.38
1888.19	6.11667
1889.19	4.18199
1890.19	2.27249
1891.19	6.04484
1892.18	2.25991
1893.18	7.88418
1894.18	1.24446
1895.18	4.03872
1896.18	4.03499
1897.18	2.15957
1898.17	4.03454
1899.17	2.12453
1900.17	1.15347
1901.16	-0.740267
1902.16	4.90469
1903.16	6.78235
1904.16	0.174265
1905.15	3.91561
1906.15	2.00993
1907.14	1.03712
1908.14	4.78156
1909.14	1.01962
1910.13	4.78855
1911.13	3.86572
1912.12	2.91537
1913.12	1.01064
1914.11	5.71733
1915.11	0.0699253
1916.1	5.72348
1917.1	1.91873
1918.09	2.83115
1919.08	7.54792
1920.08	0.961452
1921.07	-0.941732
1922.06	2.8416
1923.06	3.7649
1924.05	4.67987
1925.04	0.868261
1926.04	1.81206
1927.03	0.875982
1928.02	1.81971
1929.01	-0.0834732
1930	1.8137
1931	4.67029
1931.99	2.74915
1932.98	1.76518
1933.97	0.800838
1934.96	1.80531
1935.95	0.888823
1936.94	-2.01424
1937.93	1.75422
1938.92	3.63663
1939.91	4.58487
1940.9	-0.181816
1941.89	1.72821
1942.88	3.62807
1943.87	1.68287
1944.86	1.68085
1945.85	0.729832
1946.84	-0.230385
1947.83	4.52616
1948.82	4.50161
1949.8	1.6291
1950.79	2.60301
1951.78	1.66444
1952.77	0.704462
1953.76	2.60745
1954.74	2.52837
1955.73	3.45109
1956.72	0.598742
1957.7	1.56225
1958.69	1.55449
1959.68	0.563828
1960.66	0.529749
1961.65	0.490898
1962.63	-0.489422
1963.62	1.41323
1964.61	-3.40088
1965.59	2.33651
1966.58	-2.4734
1967.56	-3.44496
1968.55	-1.53942
1969.53	0.348598
1970.52	-0.660379
1971.5	2.18219
1972.48	-0.716789
1973.47	0.216227
1974.45	4.9721
1975.44	-1.75639
1976.42	-1.76487
1977.4	-2.74294
1978.39	0.101439
1979.37	-0.885439
1980.35	2.93075
1981.33	-2.85309
1982.31	-0.965921
1983.3	3.78518
1984.28	-0.0810604
1985.26	0.843513
1986.24	0.815189
1987.22	1.76087
1988.21	-1.14508
1989.19	-0.223999
1990.17	0.613295
1991.15	0.764856
1992.13	0.579529
1993.11	-1.27963
1994.09	-1.2289
1995.07	1.15256
1996.05	0.0302486
1997.03	0.779909
1998.01	0.00974083
1998.99	-0.804422
1999.97	-0.586899
2000.95	0.0771561
2001.92	-0.447353
2002.9	-0.0394154
2003.88	2.52705
2004.86	0.255756
2005.84	-0.0236378
2006.81	0.56904
2007.79	0.451729
2008.77	1.47694
2009.75	0.563875
2010.73	0.38541
2011.7	-2.89839
2012.68	-2.20615
2013.67	-2.24268
2014.66	-1.35065
2015.64	-2.31052
2016.63	2.38235
2017.62	1.44864
2018.61	1.40341
2019.6	-2.39356
2020.58	-0.540695
2021.57	-1.48751
2022.56	1.30478
2023.55	-1.53571
2024.54	-1.56508
2025.52	-1.60473
2026.51	-0.700321
2027.5	1.2213
2028.48	1.18259
2029.47	-2.52947
2030.45	1.1273
2031.44	0.196285
2032.43	0.191633
2033.41	1.14861
2034.4	-1.66091
2035.38	2.02972
2036.37	-1.66363
2037.35	-1.67814
2038.34	2.98178
2039.32	-0.779451
2040.31	-1.74009
2041.29	0.0957336
2042.27	-0.854414
2043.26	0.0607681
2044.24	-3.64886
2045.23	1.92627
2046.21	1.97378
2047.19	0.0767193
2048.17	-2.75644
2049.16	-0.891823
2050.14	-3.67187
2051.12	-0.858974
2052.11	2.85741
2053.09	0.993387
2054.07	0.0808964
2055.05	1.01969
2056.03	1.00316
2057.01	-2.74806
2058	-5.55197
2058.98	1.94405
2059.96	-2.7281
2060.94	-0.867939
2061.92	1.94684
2062.9	1.94964
2063.88	1.0257
2064.86	1.03259
2065.84	1.99244
2066.82	0.127975
2067.8	1.07557
2068.78	-2.67472
2069.76	-1.74316
2070.73	-1.74748
2071.71	-0.794662
2072.69	1.11961
2073.67	3.93781
2074.65	2.05976
2075.63	-0.737755
2076.6	-1.65734
2077.58	2.10425
2078.56	-1.67651
2079.54	4.94216
2080.51	1.19131
2081.49	-0.699928
2082.47	-2.59041
2083.45	-1.64312
2084.42	0.24472
2085.4	-4.47968
2086.37	5.92516
2087.35	2.16404
2088.32	1.22515
2089.3	-0.66361
2090.28	-0.647413
2091.25	-1.58717
2092.23	2.22373
2093.2	1.3079
2094.18	-3.41973
2095.15	-2.46457
2096.13	2.27443
2097.1	-0.581902
2098.07	2.25212
2099.05	1.29713
2100.02	2.24305
2101	-0.598608
2101.97	2.26649
2102.94	0.365767
2103.92	-1.5444
2104.89	0.360004
2105.86	-2.47257
2106.83	1.34074
2107.8	-0.558123
2108.78	1.31882
2109.75	6.06879
2110.72	-1.5234
2111.69	-1.52415
2112.66	2.26851
2113.63	-4.36674
2114.61	-1.51162
2115.58	0.390032
2116.55	-2.46981
2117.52	0.371763
2118.49	1.31258
2119.46	2.23642
2120.43	-2.52015
2121.4	2.22494
2122.37	2.24969
2123.34	1.31699
2124.31	-0.582283
2125.28	4.1277
2126.25	-3.48389
2127.21	3.11887
2128.18	0.272175
2129.15	1.21415
2130.12	2.15389
2131.09	-1.63219
2132.06	-0.700232
2133.02	0.229986
2133.99	0.229628
2134.96	-1.6561
2135.93	0.226549
2136.89	0.20417
2137.86	0.209473
2138.83	-0.741791
2139.79	0.206587
2140.76	2.07019
2141.73	0.179775
2142.69	0.166954
2143.66	-1.69878
2144.62	2.01722
2145.59	-1.74294
2146.55	-0.807608
2147.52	2.94097
2148.48	-1.76916
2149.45	2.90963
2150.42	2.87713
2151.38	1.93207
2152.34	0.0680122
2153.31	0.0585251
2154.27	-1.82954
2155.24	-0.926975
2156.2	-0.025032
2157.16	-0.969912
2158.13	2.77547
2159.09	0.908094
2160.05	0.891317
2161.01	0.865995
2161.98	2.7205
2162.94	-0.0822964
2163.9	0.836979
2164.86	0.816387
2165.83	0.813099
2166.79	-2.92173
2167.75	2.64532
2168.71	2.60464
2169.67	1.68104
2170.63	0.778276
2171.59	0.767757
2172.56	1.65165
2173.51	2.56749
2174.48	-0.217268
2175.44	0.708546
2176.4	1.62784
2177.36	-1.17134
2178.32	2.54123
2179.28	-1.19325
2180.23	-0.268246
2181.19	2.50773
2182.15	1.56572
2183.11	-1.23249
2184.07	-0.332432
2185.03	-4.97859
2185.99	-1.26949
2186.95	-0.329071
2187.9	1.54883
2188.86	0.603512
2189.82	-0.356508
2190.78	3.33482
2191.73	1.48019
2192.69	-0.37265
2193.65	1.49114
2194.6	-0.336958
2195.56	0.583231
2196.52	-0.377329
2197.47	1.44857
2198.43	1.44113
2199.38	0.534359
2200.34	6.14318
2201.3	-2.19754
2202.25	1.43608
2203.21	0.5425
2204.16	-1.24296
2205.12	-0.361055
2206.07	1.43295
2207.03	-1.36626
2207.98	-1.36058
2208.93	-0.419094
2209.89	-0.419792
2210.84	-1.35308
2211.8	0.517746
2212.75	-0.407177
2213.7	1.43902
2214.66	0.510149
2215.61	-3.21665
2216.56	0.51055
2217.51	0.498955
2218.47	-0.441736
2219.42	1.42873
2220.37	-5.10884
2221.32	-0.449574
2222.27	3.25391
2223.23	0.445738
2224.18	-0.476456
2225.13	-1.3953
2226.08	0.491207
2227.03	0.502249
2227.98	3.32028
2228.93	2.36711
2229.88	2.35988
2230.83	1.43622
2231.78	-0.428007
2232.73	-0.417774
2233.68	2.41385
2234.63	-0.408039
2235.58	0.506052
2236.53	-1.38695
2237.48	2.37686
2238.43	-2.30486
2239.38	1.48709
2240.33	0.524446
2241.27	-3.24634
2242.22	-1.3614
2243.17	2.4147
2244.12	0.508463
2245.07	-3.26477
2246.01	-1.35624
2246.96	0.544018
2247.91	1.49427
2248.85	-1.35709
2249.8	-0.417671
2250.75	1.46236
2251.69	-1.40137
2252.64	0.488827
2253.59	-0.42865
2254.53	0.534897
2255.48	0.531044
2256.42	1.47959
2257.37	0.542534
2258.32	-3.24963
2259.26	-1.34818
2260.2	-2.29387
2261.15	1.51425
2262.1	1.52578
2263.04	-0.369654
2263.98	-1.29974
2264.93	2.54694
2265.87	-1.26033
2266.81	-2.23112
2267.76	-2.25305
2268.7	0.589556
2269.65	2.51061
2270.59	0.630651
2271.53	-0.310432
2272.47	-2.213
2273.42	2.5724
2274.36	2.57571
2275.3	-1.24973
2276.24	-1.24633
2277.18	-1.22678
2278.13	0.722366
2279.07	-0.222496
2280.01	0.717928
2280.95	-2.18504
2281.89	-0.279669
2282.83	-0.267313
2283.77	0.720728
2284.71	-2.12264
2285.65	-2.10773
2286.59	2.68801
2287.54	2.71905
2288.47	-2.08416
2289.41	-1.13851
2290.35	2.67807
2291.29	-1.16452
2292.23	-0.176582
2293.17	2.73578
2294.11	-1.10371
2295.05	-0.150951
2295.99	-0.162443
2296.93	1.74405
2297.86	-1.12418
2298.8	-1.09772
2299.74	1.81935
2300.68	0.859814
2301.61	0.87702
2302.55	-0.0852909
2303.49	-2.97983
2304.43	-0.0739651
2305.36	-0.0549126
2306.3	0.924847
2307.24	-0.999598
2308.17	3.82821
2309.11	-1.00206
2310.04	-2.91067
2310.98	1.93743
2311.92	1.90014
2312.85	-1.01541
2313.79	1.89141
2314.72	2.89682
2315.66	-1.91762
2316.59	0.955446
2317.52	2.88055
2318.46	-0.974148
2319.39	-1.95051
2320.33	2.87022
2321.26	-0.979668
2322.2	-3.85417
2323.13	5.82892
2324.06	5.83946
2325	9.69947
2325.93	6.76686
2326.86	21.2148
2327.79	64.562
2328.73	197.557
2329.66	54.8555
2330.59	18.2486
2331.52	6.68528
2332.46	3.80315
2333.39	0.895592
2334.32	0.881256
2335.25	-0.10091
2336.18	0.857651
2337.11	0.846964
2338.04	2.75893
2338.97	-0.135798
2339.91	1.78038
2340.84	2.71875
2341.77	2.67678
2342.7	2.64522
2343.63	-3.1223
2344.56	-3.13446
2345.49	2.59959
2346.41	1.60556
2347.34	0.625267
2348.27	-0.349672
2349.2	-0.365671
2350.13	2.4453
2351.06	-0.561178
2351.99	0.46899
2352.91	-1.50247
2353.84	1.29457
2354.77	3.17236
2355.7	2.19087
2356.63	0.235037
2357.55	-0.781549
2358.48	2.01936
2359.41	-0.881968
2360.33	-5.68402
2361.26	-0.0544949
2362.19	-0.125885
2363.11	0.747547
2364.04	0.681606
2364.97	-2.22397