File: Data/3-Raman/processed/bu02aw-a-ff1-fi05-v_150 (500nm)_532nm_edge_100%_x100_vis_lwd_h50um_30sx2_01.txt
#Acq. time (s)=	30
#Accumulations=	2
#Range (cm-¹)=	99...4000
#Windows=	1
#Auto scanning=	Off
#Autofocus=	Off
#Macrospot=	Off
#AutoExposure=	Off
#Spike filter=	Multiple accum.
#Delay time (s)=	2
#Binning=	1
#Readout mode=	Signal
#DeNoise=	Off
#ICS correction=	On
#Dark correction=	Off
#Inst. Process=	Off
#Detector Gain=	Best Dynamic
#Detector ADC=	50 kHz HS
#Detector temperature (°C)=	-60.28
#Instrument=	LabRAM HR Evol
#Detector=	SIN-EM FIVIS
#Objective=	x100_VIS_LWD
#Grating=	150 (500nm)
#ND Filter=	100%
#Laser=	532nm_Edge
#Hole=	49.98
#Temperature=	0
#Range=	Visible
#StageXY=	75x50mm Scan+
#StageZ=	Z motor
#X (µm)=	0
#Y (µm)=	0
#Z (µm)=	-17.2
#Full time(mm:ss)=	1:05
#Project=	21_11_26
#Sample=	BU02Aw
#Site=
#Title=	BU02aW-A-FF1-FI05-V_150 (500nm)_532nm_Edge_100%_x100_VIS_LWD_H50um_30sX2
#Remark=
#Date=	26.11.2021 10:56
#Acquired=	26.11.2021 10:56:40
#Base:Fit=	16.12.2021 16:15:35
#Base:Edit=	16.12.2021 16:19:28
#Base:Edit=	16.12.2021 16:19:29
#Base:Edit=	16.12.2021 16:19:29
#Base:Edit=	16.12.2021 16:19:31
#Peaks:Remove=	16.12.2021 16:19:33
#Base:Edit=	16.12.2021 16:19:34
#Base:Sub=	16.12.2021 16:19:37
102.91	6315.51
107.534	4527.94
112.156	3538.08
116.775	2544.91
121.392	1773.72
126.005	1340.48
130.617	1050.68
135.227	908.992
139.835	891.887
144.439	1024.73
149.042	915.865
153.643	828.893
158.242	1258.23
162.839	1602.22
167.431	1410.28
172.023	833.852
176.613	368.876
181.198	87.0813
185.783	0.352661
190.366	49.8015
194.947	84.9019
199.524	70.1008
204.1	46.8866
208.674	62.8864
213.243	175.692
217.813	319.238
222.38	387.072
226.945	525.679
231.506	403.417
236.066	360.563
240.625	462.874
245.179	287.745
249.732	61.588
254.284	25.6953
258.831	-35.6777
263.378	101.224
267.923	361.777
272.464	743.2
277.004	522.742
281.54	53.4315
286.076	-90.1543
290.61	-41.2842
295.139	32.6162
299.669	105.517
304.196	155.341
308.718	372.64
313.241	755.423
317.759	746.697
322.278	498.225
326.794	256.673
331.305	161.374
335.817	130.681
340.324	43.2972
344.832	-0.918579
349.334	71.0377
353.837	119.447
358.338	124.739
362.834	171.472
367.33	208.645
371.822	188.706
376.314	218.048
380.802	253.432
385.289	252.484
389.772	305.255
394.255	418.034
398.734	568.572
403.213	797.604
407.688	988.004
412.162	946.076
416.632	759.176
421.102	596.898
425.568	487.488
430.033	521.356
434.495	651.572
438.956	826.287
443.413	860.347
447.87	718.821
452.323	680.451
456.776	668.707
461.224	742.286
465.673	743.37
470.117	751.725
474.561	833.038
479.001	1084.69
483.438	1461.32
487.876	1719.15
492.309	2123.67
496.742	2641.82
501.172	3547.86
505.601	4359.41
510.025	4984.49
514.448	5404.29
518.871	5457.25
523.289	5424.27
527.707	5378.83
532.121	5342.49
536.533	5140.5
540.945	4808.48
545.353	4565.88
549.758	4741.72
554.164	4978.36
558.565	4740.36
562.965	3992.94
567.364	3575.19
571.759	3500.69
576.151	3389.8
580.544	3240.3
584.933	3109.68
589.319	3264.4
593.706	3737.35
598.088	4776.65
602.468	5650.85
606.848	4923.32
611.224	3628.89
615.598	2677.01
619.972	2144.22
624.341	1736.28
628.709	1577.51
633.074	1407.64
637.44	1209.34
641.801	1101.93
646.16	1012.08
650.517	992.371
654.874	1056.25
659.227	1058.22
663.578	1014.54
667.927	906.93
672.275	731.673
676.62	601.984
680.962	475.206
685.302	412.765
689.643	386.281
693.979	349.23
698.313	325.546
702.645	297.844
706.975	290.269
711.305	303.787
715.631	294.595
719.955	275.52
724.276	315.59
728.596	305.489
732.913	329.082
737.231	382.909
741.544	382.89
745.856	436.987
750.165	516.091
754.472	480.805
758.778	521.736
763.081	500.698
767.384	532.787
771.683	502.88
775.98	538.236
780.275	518.974
784.568	578.692
788.859	602.626
793.147	576.054
797.434	595.088
801.719	555.188
806.004	466.689
810.284	391.793
814.563	309.329
818.839	261.059
823.114	213.839
827.386	159.07
831.657	134.03
835.925	92.4231
840.192	93.7175
844.456	57.4161
848.719	47.3522
852.979	22.6035
857.237	40.8678
861.493	8.41748
865.748	33.1547
870	46.6646
874.25	64.412
878.499	68.8016
882.745	42.3961
886.989	12.5849
891.231	-5.40491
895.471	3.65729
899.71	6.0199
903.946	19.3273
908.18	22.1355
912.412	25.363
916.642	30.0105
920.87	83.1272
925.096	119.695
929.321	164.362
933.543	220.46
937.763	329.994
941.981	466.842
946.197	586.035
950.412	698.399
954.622	806.496
958.832	985.772
963.04	1180.76
967.246	1457.29
971.451	1993.46
975.653	2750.84
979.853	3735.42
984.052	4494.26
988.248	4389.61
992.442	3318.27
996.633	2382.03
1000.82	2026
1005.01	2032.59
1009.2	2421.04
1013.38	3209.68
1017.57	4260.37
1021.75	5105.45
1025.92	5158.99
1030.1	4575.07
1034.27	4126.87
1038.45	3728.63
1042.62	3316.99
1046.78	2838.26
1050.95	2368.53
1055.12	2167.11
1059.28	2131.85
1063.44	2217.29
1067.6	2242.59
1071.75	2114.35
1075.91	1978.31
1080.06	1740.96
1084.21	1470.28
1088.36	1226.51
1092.51	976.496
1096.65	828.26
1100.8	739.795
1104.94	719.447
1109.08	820.238
1113.21	957.036
1117.35	1145.77
1121.48	1263.21
1125.61	1283.61
1129.74	1165.72
1133.87	954.73
1137.99	733.371
1142.12	678.67
1146.24	746.47
1150.36	752.305
1154.48	566.64
1158.59	391.682
1162.71	262.871
1166.82	197.818
1170.93	168.754
1175.04	105.511
1179.14	80.3967
1183.25	21.3651
1187.35	9.61697
1191.45	-8.47949
1195.55	-20.4693
1199.65	-20.2608
1203.74	-37.4511
1207.83	-19.0157
1211.92	-38.1217
1216.01	-21.7382
1220.1	-10.425
1224.19	-4.12213
1228.27	2.25034
1232.35	19.7659
1236.43	23.5567
1240.51	38.5799
1244.58	67.4757
1248.66	102.509
1252.73	134.805
1256.8	256.137
1260.87	609.589
1264.93	420.522
1269	254.311
1273.06	282.3
1277.12	952.581
1281.18	6103.73
1285.23	2717.3
1289.29	479.862
1293.34	244.97
1297.39	195.073
1301.44	164.222
1305.49	162.475
1309.53	139.517
1313.58	106.412
1317.62	122.523
1321.66	131.462
1325.7	106
1329.73	121.726
1333.77	135.355
1337.8	138.763
1341.83	135.07
1345.86	143.318
1349.88	137.564
1353.91	161.687
1357.93	180.773
1361.95	247.332
1365.97	383.035
1369.99	376.097
1374	404.863
1378.02	639.729
1382.03	3853.01
1386.04	9929.67
1390.05	2277.91
1394.05	491.387
1398.06	319.335
1402.06	388.418
1406.06	976.768
1410.06	524.718
1414.05	208.414
1418.05	134.51
1422.04	145.404
1426.03	125.614
1430.02	68.0652
1434.01	70.7684
1438	68.508
1441.98	27.7263
1445.96	40.19
1449.94	43.7263
1453.92	35.3471
1457.9	13.1221
1461.87	19.4224
1465.85	9.85187
1469.82	2.23004
1473.78	3.48096
1477.75	-1.21286
1481.72	7.76566
1485.68	-7.78012
1489.65	0.129059
1493.61	4.11246
1497.56	11.9695
1501.52	5.21176
1505.47	19.8902
1509.43	6.41344
1513.38	3.63498
1517.33	3.76266
1521.27	5.83549
1525.22	22.4485
1529.16	29.3501
1533.11	10.0849
1537.05	21.8239
1540.98	29.6662
1544.92	6.47504
1548.86	12.3313
1552.79	21.0667
1556.72	27.8046
1560.65	26.7267
1564.58	40.1095
1568.5	18.6111
1572.43	30.9193
1576.35	34.4901
1580.27	45.7399
1584.19	33.7992
1588.1	43.9913
1592.02	39.6958
1595.93	42.1107
1599.84	60.8328
1603.75	55.5206
1607.66	68.4663
1611.57	66.0374
1615.47	63.6084
1619.37	85.1476
1623.27	90.347
1627.17	81.2097
1631.07	96.0202
1634.97	91.7665
1638.86	84.6002
1642.75	91.852
1646.64	98.1952
1650.53	97.8428
1654.42	95.5624
1658.3	75.9451
1662.18	86.049
1666.07	83.5852
1669.94	82.0238
1673.82	61.1161
1677.7	79.5825
1681.57	69.0307
1685.44	54.5578
1689.31	65.9561
1693.18	47.5578
1697.05	52.1012
1700.92	51.789
1704.78	47.5849
1708.64	40.4624
1712.5	38.0413
1716.36	40.3504
1720.21	38.8583
1724.07	43.022
1727.92	31.1152
1731.77	32.3549
1735.62	34.5282
1739.47	27.2883
1743.32	20.9655
1747.16	15.599
1751.01	16.8876
1754.85	16.3859
1758.69	17.86
1762.52	21.5749
1766.36	35.3154
1770.19	11.9926
1774.02	18.4874
1777.85	3.58109
1781.68	1.75017
1785.51	17.6749
1789.33	16.8332
1793.16	15.0506
1796.98	24.5147
1800.8	14.2488
1804.62	1.90526
1808.43	1.74933
1812.25	0.612061
1816.06	-3.4097
1819.87	5.66447
1823.68	4.28888
1827.49	5.68886
1831.3	-4.3026
1835.1	3.54991
1838.9	17.929
1842.71	17.1845
1846.51	6.98093
1850.3	22.1493
1854.1	12.7971
1857.89	9.9469
1861.69	18.2126
1865.48	24.5416
1869.27	31.7867
1873.05	31.6084
1876.84	33.3274
1880.62	33.205
1884.4	47.9382
1888.19	31.339
1891.96	39.9176
1895.74	36.5352
1899.52	39.5896
1903.29	38.161
1907.06	18.3681
1910.83	28.9793
1914.6	33.2501
1918.37	14.4704
1922.13	28.166
1925.9	28.9684
1929.66	29.822
1933.42	43.724
1937.18	28.7907
1940.94	10.0548
1944.69	10.8845
1948.44	13.5936
1952.2	17.0436
1955.95	16.6379
1959.69	1.06554
1963.44	11.7056
1967.19	23.2687
1970.93	27.2299
1974.67	2.94984
1978.41	21.758
1982.15	5.85806
1985.89	3.97058
1989.62	-1.6718
1993.35	19.6744
1997.09	11.1426
2000.82	21.1495
2004.55	15.3908
2008.27	16.0953
2012	1.98447
2015.72	12.7791
2019.44	13.5659
2023.16	9.00015
2026.88	17.4359
2030.6	7.57065
2034.31	18.8983
2038.03	14.7697
2041.74	9.70508
2045.45	20.1905
2049.16	23.3644
2052.86	21.1089
2056.57	18.8768
2060.27	25.9654
2063.98	16.7334
2067.67	17.6684
2071.37	9.42596
2075.07	27.9351
2078.77	23.4256
2082.46	10.5913
2086.15	10.6779
2089.84	2.08563
2093.53	16.5945
2097.22	6.16422
2100.9	12.4233
2104.59	9.29877
2108.27	-2.23618
2111.95	5.72711
2115.63	9.96973
2119.31	2.10239
2122.98	4.35956
2126.66	-9.20773
2130.33	14.2864
2134	7.16702
2137.67	22.239
2141.34	15.0789
2145	5.14206
2148.67	-1.09137
2152.33	13.821
2155.99	0.286316
2159.65	15.1889
2163.31	4.50314
2166.96	6.67896
2170.62	-2.02869
2174.27	2.15656
2177.92	3.6788
2181.57	-5.67252
2185.22	-3.19101
2188.87	-11.5414
2192.51	-1.58383
2196.15	7.59677
2199.8	-3.1781
2203.44	-13.0183
2207.07	23.7376
2210.71	9.44992
2214.35	7.99152
2217.98	-1.6973
2221.61	12.4787
2225.24	-1.78799
2228.87	3.23752
2232.5	3.68271
2236.12	3.24033
2239.75	5.57513
2243.37	6.99387
2246.99	-4.58359
2250.61	1.4957
2254.23	6.70392
2257.85	-2.03357
2261.46	2.29037
2265.07	-2.7601
2268.68	9.09637
2272.29	13.5514
2275.9	7.59451
2279.51	6.26346
2283.11	9.47064
2286.72	19.2965
2290.32	9.29343
2293.92	16.2699
2297.52	7.18405
2301.11	17.0452
2304.71	0.346558
2308.3	27.1815
2311.9	17.0249
2315.49	9.6741
2319.08	30.7155
2322.66	150.208
2326.25	854.148
2329.84	406.957
2333.42	66.4872
2337	20.0997
2340.58	17.1192
2344.16	26.3436
2347.73	14.8633
2351.31	10.9022
2354.88	11.6217
2358.45	11.3943
2362.03	9.29269
2365.59	8.12997
2369.16	9.77805
2372.73	-7.02551
2376.29	22.4305
2379.85	8.42688
2383.41	12.9344
2386.97	7.34113
2390.53	22.0245
2394.09	15.6281
2397.64	16.667
2401.2	5.8891
2404.75	9.93057
2408.3	19.5094
2411.85	11.7899
2415.39	16.9784
2418.94	15.8115
2422.48	13.7648
2426.03	20.9932
2429.57	12.6215
2433.11	15.3712
2436.64	7.99396
2440.18	20.1192
2443.72	22.0751
2447.25	20.3087
2450.78	21.3958
2454.31	17.8393
2457.84	24.4254
2461.37	13.8292
2464.89	9.77664
2468.42	12.0889
2471.94	12.7304
2475.46	18.582
2478.98	27.2064
2482.5	9.47046
2486.01	22.732
2489.53	13.2162
2493.04	17.0161
2496.55	7.51764
2500.06	4.68843
2503.57	12.0635
2507.08	25.9
2510.58	31.2295
2514.09	20.7365
2517.59	34.4884
2521.09	14.8501
2524.59	25.6306
2528.09	23.7032
2531.59	18.1463
2535.08	20.0132
2538.58	37.636
2542.07	14.7107
2545.56	29.7393
2549.05	34.7349
2552.54	24.0261
2556.02	29.0907
2559.51	30.5864
2562.99	26.5084
2566.47	41.1275
2569.95	33.513
2573.43	26.8554
2576.91	24.8872
2580.38	22.9449
2583.85	34.1949
2587.33	39.8208
2590.8	50.1322
2594.27	21.3389
2597.74	34.2802
2601.2	30.1557
2604.67	25.9691
2608.13	32.1366
2611.59	36.1438
2615.06	40.8987
2618.51	35.1819
2621.97	35.0869
2625.43	32.995
2628.88	27.9255
2632.33	35.2767
2635.79	11.8242
2639.24	21.8622
2642.69	37.5515
2646.13	35.9128
2649.58	35.1922
2653.02	36.2911
2656.47	36.3363
2659.91	32.5015
2663.35	29.5752
2666.79	40.7835
2670.22	30.2283
2673.66	33.7879
2677.09	33.6006
2680.52	47.4763
2683.95	37.9779
2687.39	23.9263
2690.81	34.305
2694.24	27.9775
2697.66	36.4705
2701.09	30.1061
2704.51	42.337
2707.93	29.439
2711.35	30.6746
2714.77	42.1845
2718.18	19.291
2721.6	34.6051
2725.01	23.8406
2728.42	29.865
2731.84	34.961
2735.24	37.2192
2738.65	30.0866
2742.06	32.2811
2745.46	28.7616
2748.86	28.9273
2752.27	30.0115
2755.67	31.0458
2759.07	27.3139
2762.46	20.7311
2765.86	32.8824
2769.25	18.5771
2772.65	23.9823
2776.04	17.0829
2779.43	19.5266
2782.82	22.8388
2786.2	29.8596
2789.59	11.4385
2792.98	21.1966
2796.36	25.2674
2799.74	14.2826
2803.12	11.6751
2806.5	25.9169
2809.88	33.5423
2813.25	36.4267
2816.63	36.4506
2820	26.1616
2823.37	14.0441
2826.74	15.0145
2830.11	25.2996
2833.48	21.6125
2836.84	6.7807
2840.21	14.3343
2843.57	10.7451
2846.93	6.27228
2850.29	14.0083
2853.65	12.4737
2857.01	7.1347
2860.36	-12.2229
2863.72	18.0155
2867.07	23.0029
2870.42	12.9667
2873.77	4.74094
2877.12	-5.41772
2880.47	6.02304
2883.81	-16.4728
2887.16	-5.10547
2890.5	11.9151
2893.84	4.35583
2897.18	-4.26733
2900.52	9.72644
2903.86	-17.9771
2907.19	9.12103
2910.53	2.10226
2913.86	4.49371
2917.19	20.0807
2920.52	-11.72
2923.85	18.8683
2927.18	6.83249
2930.51	-1.49368
2933.83	-1.38242
2937.15	1.47595
2940.48	-4.18378
2943.8	4.26938
2947.11	12.6942
2950.43	0.395996
2953.75	9.69418
2957.06	-3.57855
2960.38	8.55026
2963.69	7.53979
2967	-0.973114
2970.31	-2.82068
2973.62	-0.865265
2976.92	9.52682
2980.23	11.5263
2983.53	16.2738
2986.84	25.724
2990.14	9.83484
2993.44	-2.31052
2996.73	8.09207
3000.03	10.9904
3003.33	34.5568
3006.62	29.905
3009.91	10.2111
3013.2	18.759
3016.49	19.7737
3019.78	30.1944
3023.07	24.5675
3026.35	38.7453
3029.64	36.8792
3032.92	34.9901
3036.2	71.8217
3039.48	41.5141
3042.76	41.4486
3046.04	76.4081
3049.32	57.4142
3052.59	62.0793
3055.86	29.7829
3059.14	53.3842
3062.41	68.2846
3065.68	79.4686
3068.94	95.3243
3072.21	97.7614
3075.48	119.585
3078.74	107.865
3082	143.345
3085.26	119.622
3088.52	144.243
3091.78	136.778
3095.04	172.132
3098.29	180.009
3101.55	184.524
3104.8	205.073
3108.05	205.992
3111.3	206.808
3114.55	231.187
3117.8	248.974
3121.04	262.982
3124.29	296.046
3127.53	291.002
3130.77	311.661
3134.02	336.154
3137.25	349.195
3140.49	378.398
3143.73	399.971
3146.96	387.235
3150.2	416.52
3153.43	474.455
3156.66	487.536
3159.89	517.83
3163.12	514.707
3166.35	565.036
3169.57	559.922
3172.8	579.547
3176.02	635.389
3179.24	677.767
3182.46	684.828
3185.68	711.953
3188.9	737.016
3192.12	748.696
3195.33	826.126
3198.55	860.631
3201.76	892.237
3204.97	908.67
3208.18	987.025
3211.39	982.649
3214.6	1062.13
3217.8	1092.25
3221.01	1156.64
3224.21	1205.88
3227.41	1213.47
3230.61	1282.01
3233.81	1377.38
3237.01	1416.52
3240.21	1460.91
3243.4	1545.47
3246.59	1638.81
3249.79	1698.91
3252.98	1775.54
3256.17	1829.45
3259.36	1883.39
3262.54	1971.42
3265.73	2033.37
3268.92	2102.63
3272.1	2123.88
3275.28	2180.34
3278.46	2187.1
3281.64	2231.5
3284.82	2238.13
3288	2236.26
3291.17	2209.39
3294.35	2238.1
3297.52	2279.07
3300.69	2222.02
3303.86	2230.45
3307.03	2217.21
3310.2	2211.34
3313.36	2234.51
3316.53	2228.08
3319.69	2258.61
3322.85	2206.56
3326.02	2200.12
3329.18	2229.71
3332.33	2229.1
3335.49	2208.9
3338.65	2279.65
3341.8	2312.84
3344.95	2320.65
3348.11	2390.53
3351.26	2430.08
3354.41	2500.74
3357.56	2504.88
3360.7	2592.2
3363.85	2657.36
3366.99	2685.9
3370.13	2697.71
3373.28	2761.63
3376.42	2794.9
3379.56	2853.92
3382.69	2827.23
3385.83	2854.28
3388.97	2920.51
3392.1	2907.41
3395.23	2933.95
3398.36	3019.31
3401.49	3095.55
3404.62	3140.05
3407.75	3169.87
3410.88	3261.84
3414	3240.64
3417.13	3270.92
3420.25	3183.75
3423.37	3164.83
3426.49	3029.64
3429.61	2935.74
3432.73	2907.23
3435.84	2881.84
3438.96	2893.86
3442.07	2938.83
3445.18	3074.39
3448.29	3253.02
3451.4	3428.58
3454.51	3733.93
3457.62	4049.33
3460.72	4457.87
3463.83	5035.92
3466.93	5492.16
3470.03	5965.67
3473.13	6343.21
3476.23	6589.66
3479.33	6683.79
3482.43	6509.62
3485.53	6384.15
3488.62	6122.48
3491.71	5771.62
3494.81	5320.93
3497.9	5039.17
3500.99	4645.96
3504.07	4281.48
3507.16	4023.95
3510.25	3597.13
3513.33	3356.86
3516.41	3102.73
3519.5	2778.48
3522.58	2571.42
3525.66	2325.82
3528.73	2160.24
3531.81	2029.04
3534.89	1928.38
3537.96	1768.91
3541.03	1728.76
3544.11	1666.12
3547.18	1649.39
3550.25	1648.56
3553.32	1579.14
3556.38	1559.63
3559.45	1558.52
3562.51	1554.65
3565.58	1484.03
3568.64	1440.57
3571.7	1378.86
3574.76	1278.22
3577.82	1175.8
3580.87	1106.47
3583.93	1062.66
3586.98	971.319
3590.04	944.533
3593.09	934.67
3596.14	910.612
3599.19	876.06
3602.24	891.789
3605.29	907.39
3608.33	847.221
3611.38	836.334
3614.42	829.216
3617.46	814.55
3620.5	817.961
3623.54	829.038
3626.58	856.233
3629.62	818.526
3632.65	791.183
3635.69	792.094
3638.72	754.829
3641.76	724.412
3644.79	706.439
3647.82	682.272
3650.84	656.838
3653.87	654.213
3656.9	663.165
3659.92	637.388
3662.95	651.015
3665.97	622.061
3668.99	636.837
3672.01	613.296
3675.03	575.672
3678.05	528.669
3681.07	448.644
3684.08	391.173
3687.1	282.61
3690.11	219.388
3693.12	169.39
3696.13	118.41
3699.14	94.7497
3702.15	57.9493
3705.16	38.2026
3708.16	33.6389
3711.17	30.9206
3714.17	4.39691
3717.17	9.19037
3720.17	30.2228
3723.17	-8.76196
3726.17	-3.04578
3729.17	0.735474
3732.16	-27.8885
3735.16	-27.9817
3738.15	-14.7864
3741.14	-26.3807
3744.13	-33.2593
3747.13	-22.0887
3750.11	-36.6365
3753.1	-35.9946
3756.09	-47.6958
3759.07	-42.2876
3762.06	-52.0695
3765.04	-33.4475
3768.02	-35.6724
3771	-52.0587
3773.98	-24.8884
3776.96	-37.4267
3779.94	-51.8313
3782.91	-52.9904
3785.89	-34.3289
3788.86	-33.6093
3791.83	-39.4958
3794.8	-39.6823
3797.77	-32.315
3800.74	-24.0097
3803.71	-15.6843
3806.68	-26.2598
3809.64	-17.0313
3812.61	-0.254761
3815.57	-14.7032
3818.53	-30.1488
3821.49	-14.4131
3824.45	-11.0153
3827.41	-9.5387
3830.36	-23.2841
3833.32	-9.60126
3836.27	0.273499
3839.23	0.611969
3842.18	17.9911
3845.13	9.63464
3848.08	4.05417
3851.03	-0.645844
3853.98	10.7941
3856.92	13.5867
3859.87	31.5844
3862.81	11.2836
3865.75	12.8427
3868.7	1.85837
3871.64	28.1087
3874.57	21.6779
3877.51	32.3945
3880.45	24.7339
3883.39	32.2929
3886.32	40.6671
3889.25	33.5263
3892.18	49.3268
3895.12	39.0327
3898.05	49.7283
3900.97	43.9117
3903.9	34.1119
3906.83	38.5642
3909.75	45.8029
3912.68	44.2202
3915.6	46.3076
3918.52	43.4261
3921.44	33.7337
3924.36	53.5864
3927.28	40.6107
3930.2	42.7991
3933.11	42.8918
3936.03	39.0644
3938.94	36.0926
3941.86	41.622
3944.77	45.0272
3947.68	40.6088
3950.59	42.7393
3953.49	42.7896
3956.4	27.3365
3959.31	20.3296
3962.21	38.0472
3965.12	22.9952
3968.02	20.2091
3970.92	14.3453
3973.82	15.9485
3976.72	25.0095
3979.61	-2.67606
3982.51	15.5006
3985.41	-0.197388
3988.3	8.84729
3991.19	-5.44177
3994.09	-5.58936
3996.98	-16.5114
3999.87	-8.45059