File: Data/3-Raman/processed/bu02aw-a-ff1-host_1800 (450-850nm)_532nm_edge_100%_x100_vis_lwd_h100um_30sx2_01.txt
#Acq. time (s)=	30
#Accumulations=	2
#Range (cm-¹)=	3200...3799
#Windows=	2
#Auto scanning=	Off
#Autofocus=	Off
#Macrospot=	Off
#AutoExposure=	Off
#Spike filter=	Multiple accum.
#Delay time (s)=	2
#Binning=	1
#Readout mode=	Signal
#DeNoise=	Off
#ICS correction=	On
#Dark correction=	Off
#Inst. Process=	Off
#Detector Gain=	Best Dynamic
#Detector ADC=	50 kHz HS
#Detector temperature (°C)=	-60.09
#Instrument=	LabRAM HR Evol
#Detector=	SIN-EM FIVIS
#Objective=	x100_VIS_LWD
#Grating=	1800 (450-850nm)
#ND Filter=	100%
#Laser=	532nm_Edge
#Hole=	100.021
#Temperature=	0
#Range=	Visible
#StageXY=	75x50mm Scan+
#StageZ=	Z motor
#X (µm)=	0
#Y (µm)=	0
#Z (µm)=	-10.3
#Full time(mm:ss)=	2:17
#Project=	21_11_26
#Sample=	BU02Aw
#Site=
#Title=	BU02aW-A-FF1-host_1800 (450-850nm)_532nm_Edge_100%_x100_VIS_LWD_H100um_30sX2
#Remark=
#Date=	26.11.2021 10:44
#Acquired=	26.11.2021 10:44:29
#Base:Fit=	16.12.2021 16:15:35
#Base:Clear=	16.12.2021 16:20:23
#Base:Edit=	16.12.2021 16:20:25
#Base:Edit=	16.12.2021 16:20:26
#Base:Edit=	16.12.2021 16:20:27
#Base:Edit=	16.12.2021 16:20:28
#Base:Edit=	16.12.2021 16:20:29
#Base:Edit=	16.12.2021 16:20:30
#Base:Edit=	16.12.2021 16:20:32
#Base:Edit=	16.12.2021 16:20:33
#Base:Edit=	16.12.2021 16:20:34
#Base:Sub=	16.12.2021 16:20:36
3200.06	21.1351
3200.67	10.4045
3201.29	8.39777
3201.9	17.9823
3202.52	9.37592
3203.14	-1.32925
3203.75	8.14743
3204.37	4.2627
3204.98	6.18204
3205.59	2.57269
3206.21	5.8175
3206.82	-3.52737
3207.44	9.14252
3208.05	0.90155
3208.67	-9.22488
3209.28	-12.4999
3209.9	-12.2091
3210.51	1.32388
3211.13	-10.924
3211.74	13.5871
3212.35	-0.139862
3212.97	14.8052
3213.58	-2.77682
3214.2	-9.88605
3214.81	-0.482086
3215.42	9.89667
3216.04	-3.10791
3216.65	10.6749
3217.26	1.75244
3217.88	-3.66876
3218.49	12.0562
3219.1	14.9301
3219.72	0.763123
3220.33	0.325684
3220.94	15.6988
3221.56	2.62457
3222.17	8.7326
3222.78	24.1259
3223.4	16.2812
3224.01	0.811096
3224.62	22.7727
3225.23	10.9316
3225.85	27.8625
3226.46	10.5917
3227.07	30.5453
3227.68	40.2783
3228.29	65.5685
3228.91	47.4791
3229.52	57.3729
3230.13	49.1124
3230.74	72.6288
3231.35	51.3218
3231.96	51.1265
3232.57	56.5042
3233.19	71.9598
3233.8	68.3222
3234.41	82.0775
3235.02	70.88
3235.63	71.3101
3236.24	93.4791
3236.85	122.1
3237.46	119.038
3238.08	122.126
3238.69	121.767
3239.3	119.549
3239.91	133.164
3240.52	150.625
3241.13	142.371
3241.74	147.551
3242.35	158.332
3242.96	148.962
3243.57	150.879
3244.18	166.039
3244.79	154.65
3245.4	171.445
3246.01	168.277
3246.62	172.347
3247.23	195.785
3247.84	181.273
3248.45	211.682
3249.06	223.74
3249.66	218.671
3250.27	238.794
3250.88	230.054
3251.49	230.366
3252.1	253.233
3252.71	252.572
3253.32	251.547
3253.93	244.645
3254.54	273.62
3255.14	262.7
3255.75	288.025
3256.36	276.663
3256.97	285.084
3257.58	280.201
3258.19	295.516
3258.79	321.439
3259.4	330.286
3260.01	312.574
3260.62	316.546
3261.23	326.347
3261.83	295.28
3262.44	344.488
3263.05	345.067
3263.66	342.971
3264.26	366.21
3264.87	375.579
3265.48	368.185
3266.08	354.271
3266.69	384.34
3267.3	377.275
3267.91	382.363
3268.51	365.74
3269.12	336.615
3269.73	363.23
3270.33	359.593
3270.94	414.381
3271.55	372.79
3272.15	387.94
3272.76	381.47
3273.36	391.512
3273.97	359.23
3274.58	412.704
3275.18	406.845
3275.79	399.724
3276.39	424.873
3277	415.706
3277.61	406.431
3278.21	419.885
3278.82	420.673
3279.42	395.487
3280.03	376.446
3280.63	403.874
3281.24	385.208
3281.84	386.481
3282.45	420.046
3283.05	370.83
3283.66	385.071
3284.26	369.33
3284.87	396.564
3285.47	385.771
3286.08	369.611
3286.68	355.773
3287.29	386.604
3287.89	346.994
3288.49	373.487
3289.1	330.141
3289.7	344.446
3290.31	378.319
3290.91	351.956
3291.52	331.277
3292.12	326.953
3292.72	327.813
3293.33	346.617
3293.93	320.761
3294.53	349.514
3295.14	329.056
3295.74	323.127
3296.34	317.912
3296.95	321.719
3297.55	306.689
3298.15	285.306
3298.76	295.626
3299.36	305.862
3299.96	303.738
3300.56	260.424
3301.17	278.454
3301.77	281.482
3302.37	263.029
3302.97	257.942
3303.58	284.542
3304.18	247.076
3304.78	225.788
3305.38	209.144
3305.98	235.931
3306.59	214.738
3307.19	209.356
3307.79	223.023
3308.39	198.665
3308.99	196.741
3309.59	183.078
3310.2	186.942
3310.8	153.895
3311.4	180.145
3312	187.131
3312.6	145.985
3313.2	162.688
3313.8	147.627
3314.4	109.798
3315	136.124
3315.6	130.754
3316.21	132.369
3316.81	111.109
3317.41	98.5201
3318.01	97.5044
3318.61	140.599
3319.21	125.508
3319.81	100.717
3320.41	84.816
3321.01	88.7751
3321.61	81.5345
3322.21	56.4543
3322.81	70.5505
3323.41	30.4824
3324.01	80.8511
3324.61	84.8861
3325.21	61.0802
3325.81	47.9777
3326.41	26.9688
3327	24.1991
3327.6	55.3468
3328.2	44.4188
3328.8	33.7629
3329.4	34.264
3330	27.9368
3330.6	24.09
3331.2	19.7292
3331.8	8.84644
3332.39	-4.51941
3332.99	20.4556
3333.59	20.5236
3334.19	-17.8112
3334.79	-4.60266
3335.39	25.4429
3335.98	4.55469
3336.58	17.605
3337.18	20.7838
3337.78	-21.3661
3338.37	-12.467
3338.97	0.397461
3339.57	20.3433
3340.17	-25.5092
3340.77	28.8353
3341.36	-5.52319
3341.96	-5.57605
3342.56	-3.21545
3343.15	-15.7181
3343.75	21.5682
3344.35	29.3468
3344.95	11.9026
3345.54	-2.8855
3346.14	33.4136
3346.74	14.5278
3347.33	6.4917
3347.93	19.6382
3348.53	4.85413
3349.12	25.9955
3349.72	13.7997
3350.31	32.9404
3350.91	13.5465
3351.51	20.4305
3352.1	62.468
3352.7	-5.38245
3353.29	44.246
3353.89	18.0693
3354.49	34.8334
3355.08	45.89
3355.68	27.5264
3356.27	59.8102
3356.87	54.3832
3357.46	83.3512
3358.06	34.6826
3358.65	73.7317
3359.25	70.3412
3359.84	69.3088
3360.44	72.4834
3361.03	92.0146
3361.63	101.016
3362.22	64.5275
3362.82	79.028
3363.41	104.645
3364.01	101.368
3364.6	105.646
3365.19	78.595
3365.79	119.111
3366.38	97.4629
3366.98	96.2638
3367.57	101.58
3368.16	105.28
3368.76	90.4677
3369.35	132.6
3369.95	124.143
3370.54	93.1688
3371.13	125.106
3371.73	131.136
3372.32	135.337
3372.91	128.596
3373.51	105.394
3374.1	108.866
3374.69	88.3264
3375.28	161.304
3375.88	139.282
3376.47	112.629
3377.06	91.0161
3377.66	148.352
3378.25	127.813
3378.84	103.463
3379.43	67.4786
3380.03	102.095
3380.62	118.432
3381.21	121.18
3381.8	103.652
3382.39	90.8107
3382.99	100.22
3383.58	124.295
3384.17	98.6381
3384.76	127.25
3385.35	138.886
3385.95	116.221
3386.54	92.1573
3387.13	106.862
3387.72	142.667
3388.31	132.746
3388.9	142.103
3389.49	134.647
3390.08	108.506
3390.68	129.514
3391.27	129.32
3391.86	137.601
3392.45	136.932
3393.04	136.107
3393.63	127.664
3394.22	122.81
3394.81	149.958
3395.4	116.547
3395.99	143.451
3396.58	143.761
3397.17	162.62
3397.76	174.516
3398.35	148.212
3398.94	186.056
3399.53	172.28
3400.12	194.213
3400.71	225.537
3401.3	209.115
3401.89	235.868
3402.48	261.158
3403.07	253.274
3403.66	269.147
3404.25	233.406
3404.83	250.244
3405.42	272.806
3406.01	314.103
3406.6	301.514
3407.19	301.161
3407.78	315.132
3408.37	322.379
3408.96	328.955
3409.55	335.676
3410.13	337.263
3410.72	362.776
3411.31	347.835
3411.9	359.899
3412.49	340.15
3413.07	361.599
3413.66	366.994
3414.25	355.458
3414.84	350.008
3415.43	392.551
3416.01	348.869
3416.6	372.144
3417.19	341.506
3417.78	346.757
3418.36	327.753
3418.95	353.515
3419.54	313.516
3420.12	338.165
3420.71	306.606
3421.3	300.079
3421.89	304.919
3422.47	279.603
3423.06	284.685
3423.64	258.826
3424.23	245.731
3424.82	235.814
3425.41	199.787
3425.99	154.999
3426.58	206.348
3427.16	162.344
3427.75	149.478
3428.34	169.331
3428.92	112.309
3429.51	125.875
3430.09	91.4387
3430.68	65.8029
3431.26	86.0173
3431.85	72.9138
3432.44	57.7694
3433.02	37.4534
3433.61	23.8037
3434.19	54.8281
3434.78	39.0402
3435.36	26.5469
3435.95	21.8929
3436.53	-1.12
3437.12	40.4652
3437.7	30.131
3438.29	38.3286
3438.87	4.89905
3439.46	12.535
3440.04	15.3855
3440.62	62.4193
3441.21	67.043
3441.79	58.5356
3442.38	45.8781
3442.96	78.6007
3443.55	63.2045
3444.13	109.208
3444.71	96.7388
3445.3	120.052
3445.88	116.029
3446.46	139.34
3447.05	218.066
3447.63	199.851
3448.21	174.823
3448.8	256.555
3449.38	265.844
3449.96	283.581
3450.55	335.347
3451.13	361.058
3451.71	401.894
3452.3	414.288
3452.88	445.114
3453.46	505.328
3454.04	530.505
3454.63	568.071
3455.21	592.294
3455.79	654.89
3456.37	667.958
3456.96	754.62
3457.54	762.396
3458.12	855.07
3458.7	855.045
3459.28	950.746
3459.87	1020.83
3460.45	1077.37
3461.03	1102.85
3461.61	1199.4
3462.19	1231.12
3462.78	1324.96
3463.36	1363.65
3463.94	1420.77
3464.52	1497.63
3465.1	1588.72
3465.68	1618.43
3466.26	1677.13
3466.84	1750.61
3467.42	1817.83
3468	1861.52
3468.58	1947.99
3469.17	2012.02
3469.75	2086.49
3470.33	2115.13
3470.91	2180.49
3471.49	2252.81
3472.07	2264.06
3472.65	2354.42
3473.23	2437.01
3473.81	2371.87
3474.39	2460.38
3474.97	2464.4
3475.55	2556.51
3476.13	2548.55
3476.71	2625.89
3477.29	2612.41
3477.87	2719.75
3478.45	2631.2
3479.03	2685.01
3479.6	2645.71
3480.18	2732.6
3480.76	2732
3481.34	2738.12
3481.92	2659.92
3482.5	2771.33
3483.08	2701.93
3483.66	2725.47
3484.24	2650.73
3484.82	2603.6
3485.39	2621.16
3485.97	2655.95
3486.55	2534.08
3487.13	2557.89
3487.71	2475.7
3488.28	2531.64
3488.86	2389.03
3489.44	2415
3490.02	2344.05
3490.6	2310.72
3491.17	2322.01
3491.75	2223.46
3492.33	2195
3492.91	2152.71
3493.49	2146.38
3494.06	2061.1
3494.64	2023.78
3495.22	1993.32
3495.79	1954.66
3496.37	1899.34
3496.95	1895.75
3497.52	1832.59
3498.1	1784.54
3498.68	1775.18
3499.25	1673.82
3499.83	1690.71
3500.41	1635.71
3500.98	1605.01
3501.56	1556.33
3502.14	1521.68
3502.71	1471.3
3503.29	1465.89
3503.86	1380.01
3504.44	1357.96
3505.02	1319.42
3505.59	1250.58
3506.17	1226.29
3506.75	1222.6
3507.32	1165.4
3507.9	1141.38
3508.47	1095.92
3509.05	1063.98
3509.62	1031.36
3510.2	1004.26
3510.77	941.092
3511.35	944.158
3511.92	902.665
3512.5	858.806
3513.07	823.12
3513.65	774.456
3514.22	735.614
3514.8	716.681
3515.2	721.689
3515.78	630.438
3516.36	667.225
3516.95	582.445
3517.53	588.012
3518.11	521.282
3518.7	520.557
3519.28	477.801
3519.86	447.255
3520.44	459.08
3521.02	423.026
3521.61	424.067
3522.19	365.457
3522.77	330.038
3523.35	338.872
3523.94	331.332
3524.52	271.084
3525.1	273.653
3525.68	263.504
3526.26	242.102
3526.84	236.032
3527.42	208.245
3528.01	181.882
3528.59	155.18
3529.17	161.444
3529.75	137.504
3530.33	137.952
3530.91	109.02
3531.49	98.2529
3532.07	102.044
3532.66	63.6113
3533.24	41.1006
3533.82	40.8243
3534.4	46.4179
3534.98	35.9145
3535.56	42.3808
3536.14	10.1688
3536.72	31.4352
3537.3	16.737
3537.88	41.6397
3538.46	19.5114
3539.04	-23.8129
3539.62	24.1641
3540.2	-0.512146
3540.78	1.37769
3541.36	-1.55597
3541.94	-2.19232
3542.52	17.1061
3543.1	-3.71564
3543.68	21.1319
3544.25	10.748
3544.83	21.1956
3545.41	-13.3185
3545.99	8.78973
3546.57	27.0648
3547.15	39.752
3547.73	24.3099
3548.31	42.1661
3548.89	30.6006
3549.47	40.0501
3550.04	50.4714
3550.62	54.9788
3551.2	67.9221
3551.78	56.8953
3552.36	70.6954
3552.94	80.6399
3553.51	69.75
3554.09	95.3536
3554.67	123.175
3555.25	95.3948
3555.83	103.387
3556.4	107.873
3556.98	118.834
3557.56	133.533
3558.14	132.893
3558.71	126.501
3559.29	137.347
3559.87	140.539
3560.44	142.249
3561.02	151.923
3561.6	150.641
3562.18	162.063
3562.75	146.303
3563.33	142.449
3563.91	123.953
3564.48	167.033
3565.06	146.108
3565.64	187.28
3566.21	150.137
3566.79	166.13
3567.37	156.552
3567.94	153.643
3568.52	156.901
3569.1	146.991
3569.67	125.231
3570.25	147.921
3570.82	138.653
3571.4	137.087
3571.97	132.753
3572.55	122.033
3573.13	123.642
3573.7	127.28
3574.28	102.86
3574.85	103.572
3575.43	94.2722
3576	90.6927
3576.58	89.9305
3577.15	83.3239
3577.73	47.9888
3578.3	72.2058
3578.88	47.595
3579.45	46.5755
3580.03	40.3464
3580.6	46.5913
3581.18	44.0899
3581.75	23.1843
3582.33	13.4104
3582.9	18.1173
3583.47	-21.8446
3584.05	10.4668
3584.62	-7.79639
3585.2	-15.338
3585.77	-5.06885
3586.34	14.963
3586.92	11.8122
3587.49	0.0367432
3588.07	-13.5947
3588.64	5.20502
3589.21	-9.7373
3589.79	-7.22504
3590.36	-21.277
3590.93	-16.8036
3591.51	0.335327
3592.08	6.22614
3592.65	3.87994
3593.23	-4.84003
3593.8	22.8509
3594.37	10.183
3594.94	-1.42755
3595.52	4.21381
3596.09	13.6278
3596.66	22.9323
3597.23	6.10107
3597.81	7.41321
3598.38	34.7135
3598.95	29.5801
3599.52	26.2885
3600.1	39.9835
3600.67	52.8961
3601.24	41.2242
3601.81	31.7263
3602.38	52.1746
3602.95	54.8897
3603.53	44.0054
3604.1	70.5554
3604.67	50.3294
3605.24	64.7921
3605.81	85.6391
3606.38	70.517
3606.96	83.5203
3607.53	77.3336
3608.1	85.4139
3608.67	96.1835
3609.24	89.6449
3609.81	103.179
3610.38	89.8747
3610.95	97.5903
3611.52	105.436
3612.09	92.5634
3612.66	108.498
3613.23	105.811
3613.8	103.759
3614.37	99.8409
3614.94	121.599
3615.52	120.79
3616.08	115.475
3616.66	114.474
3617.22	112.129
3617.79	132.921
3618.36	101.395
3618.93	134.505
3619.5	140.453
3620.07	121.069
3620.64	139.622
3621.21	142.578
3621.78	154.129
3622.35	169.107
3622.92	166.979
3623.49	157.659
3624.06	170.987
3624.63	185.53
3625.2	183.074
3625.76	181.32
3626.33	183.006
3626.9	178.087
3627.47	187.376
3628.04	182.623
3628.61	192.872
3629.18	198.631
3629.75	196.676
3630.31	206.135
3630.88	205.135
3631.45	221.258
3632.02	218.299
3632.59	241.906
3633.15	206.339
3633.72	227.631
3634.29	239.594
3634.86	227.563
3635.42	221.331
3635.99	239.429
3636.56	218.039
3637.13	247.069
3637.69	242.041
3638.26	251.345
3638.83	232.875
3639.39	234.13
3639.96	237.257
3640.53	241.475
3641.09	206.919
3641.66	212.578
3642.23	249.903
3642.8	252.831
3643.36	244.659
3643.93	228.97
3644.49	249.622
3645.06	242.646
3645.63	242.13
3646.19	248.087
3646.76	238.259
3647.33	236.625
3647.89	275.555
3648.46	254.181
3649.02	259.439
3649.59	249.742
3650.16	251.413
3650.72	262.274
3651.29	269.067
3651.85	258.712
3652.42	272.068
3652.98	274.412
3653.55	284.97
3654.11	294.082
3654.68	288.532
3655.24	260.729
3655.81	279.983
3656.37	285.037
3656.94	309.59
3657.5	313.401
3658.07	293.764
3658.63	295.935
3659.19	319.133
3659.76	321.187
3660.32	325.101
3660.89	328.589
3661.45	334.223
3662.02	346.044
3662.58	348.615
3663.14	337.762
3663.71	320.83
3664.27	363.42
3664.84	379.509
3665.4	365.59
3665.96	351.24
3666.53	348.325
3667.09	370.723
3667.65	393.703
3668.22	328.658
3668.78	378.927
3669.34	378.293
3669.91	385.531
3670.47	374.624
3671.03	390.189
3671.59	383.801
3672.16	376.309
3672.72	394.335
3673.28	377.616
3673.85	366.568
3674.41	370.123
3674.97	373.237
3675.53	345.155
3676.09	356.047
3676.66	376.248
3677.22	344.867
3677.78	358.019
3678.34	336.716
3678.91	346.866
3679.47	335.13
3680.03	317.54
3680.59	304.447
3681.15	310.343
3681.71	280.878
3682.28	272.343
3682.84	243.898
3683.4	272.691
3683.96	250.123
3684.52	235.08
3685.08	239.641
3685.64	207.41
3686.2	197.573
3686.76	189.21
3687.33	187.921
3687.89	183.559
3688.45	149.645
3689.01	152.862
3689.57	140.613
3690.13	130.231
3690.69	118.942
3691.25	123.994
3691.81	88.0623
3692.37	89.4124
3692.93	85.8722
3693.49	71.6287
3694.05	66.8795
3694.61	47.795
3695.17	55.408
3695.73	52.5506
3696.29	41.1396
3696.85	28.8148
3697.41	29.9232
3697.97	36.7566
3698.53	28.1318
3699.09	14.8839
3699.65	14.8723
3700.2	20.252
3700.76	10.6148
3701.32	3.89084
3701.88	18.2815
3702.44	4.06796
3703	1.41983
3703.56	-21.3613
3704.12	-7.81952
3704.68	10.1883
3705.23	2.09863
3705.79	-8.71432
3706.35	-1.82703
3706.91	-3.43112
3707.47	-7.2312
3708.03	3.49286
3708.58	-1.7088
3709.14	0.352783
3709.7	-2.10437
3710.26	-3.39099
3710.81	-4.58102
3711.37	3.47177
3711.93	-5.63588
3712.49	-9.73921
3713.05	-10.4796
3713.6	-4.71465
3714.16	-12.3123
3714.72	-1.81734
3715.27	4.83803
3715.83	3.99469
3716.39	-9.15361
3716.95	-1.38412
3717.5	6.43198
3718.06	-4.98618
3718.62	2.76801
3719.17	0.875336
3719.73	4.71809
3720.29	-5.81102
3720.84	-3.84032
3721.4	-3.64023
3721.96	-4.49611
3722.51	6.22102
3723.07	-4.27078
3723.62	9.25703
3724.18	18.7336
3724.74	-10.9194
3725.29	10.2649
3725.85	5.48991
3726.4	-1.30238
3726.96	8.19997
3727.51	-2.48804
3728.07	13.8518
3728.63	10.2234
3729.18	17.2759
3729.74	7.53793
3730.29	2.71254
3730.85	14.3857
3731.4	5.88338
3731.96	9.85263
3732.51	-13.1235
3733.07	5.15211
3733.62	10.7817
3734.18	5.79681
3734.73	10.4726
3735.28	-7.7263
3735.84	1.0405
3736.39	-15.2262
3736.95	3.92133
3737.5	8.80959
3738.06	5.41423
3738.61	-9.52823
3739.16	11.4944
3739.72	4.1711
3740.27	17.7521
3740.83	2.30254
3741.38	-0.753876
3741.94	2.12892
3742.49	5.08365
3743.04	9.92874
3743.6	12.7315
3744.15	6.89664
3744.7	15.6117
3745.26	1.85269
3745.81	6.23161
3746.36	-2.25334
3746.91	2.29048
3747.47	6.18323
3748.02	-8.65356
3748.57	7.23145
3749.13	-7.52179
3749.68	-2.33611
3750.23	8.67842
3750.78	7.57007
3751.34	6.62914
3751.89	3.66982
3752.44	2.49176
3752.99	3.24744
3753.55	8.04546
3754.1	6.15741
3754.65	12.903
3755.2	-1.53427
3755.75	7.88101
3756.31	18.4611
3756.86	-2.67894
3757.41	12.3844
3757.96	3.45493
3758.51	7.31656
3759.06	9.86797
3759.61	6.22528
3760.17	3.44687
3760.72	4.21616
3761.27	4.45514
3761.82	5.57481
3762.37	7.92055
3762.92	6.92117
3763.47	22.0194
3764.02	6.43193
3764.57	9.98396
3765.13	-4.62717
3765.68	1.75529
3766.23	11.1712
3766.78	3.20779
3767.33	19.144
3767.88	5.30385
3768.43	19.3087
3768.98	9.50294
3769.53	8.28214
3770.08	16.5679
3770.63	9.4946
3771.18	15.7682
3771.73	2.95113
3772.28	10.3363
3772.83	7.63963
3773.38	9.49654
3773.93	4.51175
3774.48	17.235
3775.02	21.4931
3775.57	16.3986
3776.12	6.39778
3776.67	12.2158
3777.22	13.0532
3777.77	19.5915
3778.32	15.0475
3778.87	6.72878
3779.42	19.3595
3779.97	1.53845
3780.51	8.86461
3781.06	8.78146
3781.61	6.0152
3782.16	4.52512
3782.71	21.9271
3783.26	15.3904
3783.8	13.6125
3784.35	18.0785
3784.9	8.10823
3785.45	12.8872
3786	21.4914
3786.55	10.0715
3787.09	10.9969
3787.64	24.318
3788.19	10.0638
3788.74	6.21724
3789.28	17.5214
3789.83	9.69295
3790.38	8.48122
3790.93	11.0487
3791.47	6.01889
3792.02	11.1306
3792.57	10.9921
3793.11	4.55685
3793.66	3.54982
3794.21	2.57755
3794.75	10.8239
3795.3	8.72801
3795.85	4.05794
3796.4	2.25766
3796.94	4.38452
3797.12	-11.2406