File: Data/3-Raman/processed/bu02aw-a-ff1-fi02-v_1800 (450-850nm)_532nm_edge_100%_x100_vis_lwd_h100um_30sx2_01.txt
#Acq. time (s)=	30
#Accumulations=	2
#Range (cm-¹)=	1200...2365
#Windows=	3
#Auto scanning=	Off
#Autofocus=	Off
#Macrospot=	Off
#AutoExposure=	Off
#Spike filter=	Multiple accum.
#Delay time (s)=	2
#Binning=	1
#Readout mode=	Signal
#DeNoise=	Off
#ICS correction=	On
#Dark correction=	Off
#Inst. Process=	Off
#Detector Gain=	Best Dynamic
#Detector ADC=	50 kHz HS
#Detector temperature (°C)=	-60.09
#Instrument=	LabRAM HR Evol
#Detector=	SIN-EM FIVIS
#Objective=	x100_VIS_LWD
#Grating=	1800 (450-850nm)
#ND Filter=	100%
#Laser=	532nm_Edge
#Hole=	100.021
#Temperature=	0
#Range=	Visible
#StageXY=	75x50mm Scan+
#StageZ=	Z motor
#X (µm)=	0
#Y (µm)=	0
#Z (µm)=	-18
#Full time(mm:ss)=	3:18
#Project=	21_11_26
#Sample=	BU02Aw
#Site=
#Title=	BU02aW-A-FF1-FI02-V_1800 (450-850nm)_532nm_Edge_100%_x100_VIS_LWD_H100um_30sX2
#Remark=
#Date=	26.11.2021 11:26
#Acquired=	26.11.2021 11:26:23
#Base:Fit=	16.12.2021 16:15:35
#Base:Fit=	16.12.2021 16:18:08
#Base:Sub=	16.12.2021 16:18:08
1202.72	4.12017
1203.84	0.931488
1204.95	-4.50592
1206.06	1.80925
1207.17	5.90963
1208.28	4.69008
1209.39	6.66365
1210.5	-3.09561
1211.61	-0.115318
1212.72	1.78652
1213.83	1.57093
1214.94	4.59245
1216.05	8.66047
1217.16	3.04462
1218.27	2.76363
1219.38	3.56979
1220.49	1.19744
1221.6	0.945251
1222.71	-1.50348
1223.81	-3.9897
1224.92	-2.2066
1226.03	1.76319
1227.14	-2.73691
1228.25	-0.00192261
1229.35	-2.54713
1230.46	1.57839
1231.57	-5.21497
1232.67	-1.29673
1233.78	3.65308
1234.89	-8.16609
1235.99	-1.06773
1237.1	-3.47894
1238.2	2.43558
1239.31	5.1968
1240.41	-3.51076
1241.52	-2.7484
1242.62	3.21843
1243.73	1.90272
1244.83	6.85262
1245.94	6.48705
1247.04	5.10654
1248.14	-1.47694
1249.25	1.33549
1250.35	3.14602
1251.45	3.84194
1252.56	8.73067
1253.66	-2.03486
1254.76	4.00697
1255.87	2.71384
1256.97	3.51836
1258.07	17.8646
1259.17	39.484
1260.27	25.7401
1261.37	36.8596
1262.48	61.9733
1263.58	131.227
1264.68	187.122
1265.78	111.402
1266.88	44.3088
1267.98	28.534
1269.08	18.0055
1270.18	27.2398
1271.28	26.9496
1272.38	29.9191
1273.47	22.5422
1274.57	26.6697
1275.67	23.3732
1276.77	24.3479
1277.87	29.5406
1278.97	34.7588
1280.07	58.8381
1281.16	120.772
1282.26	309.204
1283.36	1111.69
1284.45	3200.82
1285.55	1818.34
1286.65	346.871
1287.75	124.498
1288.84	69.6369
1289.94	48.5925
1291.03	39.0809
1292.13	30.5799
1293.22	23.1468
1294.32	20.0673
1295.42	16.8869
1296.51	17.0665
1297.61	19.1378
1298.7	8.49644
1299.79	9.48785
1300.89	9.50866
1301.98	0.0165558
1303.08	0.0444183
1304.17	5.30336
1305.26	-1.02254
1306.35	4.20433
1307.45	5.27274
1308.54	-1.01254
1309.63	-5.16451
1310.73	6.50518
1311.82	4.46356
1312.91	10.903
1314	-5.94955
1315.09	0.464912
1316.18	7.98106
1317.28	4.8819
1318.37	-4.50763
1319.46	2.98682
1320.55	3.08891
1321.64	2.07903
1322.73	0.00350189
1323.82	-0.963829
1324.91	-0.837372
1326	1.34245
1327.09	2.38738
1328.18	-0.491508
1329.27	-2.3614
1330.35	1.99373
1331.44	-7.41333
1332.53	-3.15603
1333.62	3.2059
1334.71	4.32399
1335.79	-6.07063
1336.88	6.63618
1337.97	-11.0397
1339.06	-3.58405
1340.14	2.87982
1341.23	-0.0675659
1342.32	-7.23529
1343.4	5.44689
1344.49	1.45356
1345.58	-4.65553
1346.66	1.70716
1347.75	5.98756
1348.83	-0.0944443
1349.92	2.14585
1351	1.25857
1352.09	-5.8605
1353.17	3.77192
1354.25	6.1624
1355.34	12.4284
1356.42	1.21919
1357.51	7.6433
1358.59	4.71
1359.67	18.3712
1360.76	8.15705
1361.84	9.40633
1362.92	14.793
1364	17.1387
1365.09	30.8434
1366.17	28.9294
1367.25	26.9966
1368.33	32.411
1369.41	56.4715
1370.5	116.64
1371.58	23.7825
1372.66	34.2073
1373.74	32.3274
1374.82	34.6109
1375.9	38.9854
1376.98	39.1921
1378.06	53.8217
1379.14	57.3786
1380.22	70.9683
1381.3	76.0757
1382.38	94.6726
1383.46	126.495
1384.54	174.83
1385.61	325.149
1386.69	1000.51
1387.77	5888.24
1388.85	3490.02
1389.93	502.065
1391	176.425
1392.08	115.015
1393.16	78.2766
1394.23	75.4099
1395.31	54.1718
1396.39	49.3507
1397.46	41.3638
1398.54	38.5292
1399.62	37.8075
1400.69	48.3362
1401.77	49.6691
1402.84	47.0234
1403.92	52.5165
1404.99	45.5041
1406.07	57.9867
1407.14	99.2003
1408.22	164.089
1409.29	366.444
1410.37	269.338
1411.44	88.8855
1412.51	50.1655
1413.59	36.3381
1414.66	34.408
1415.73	23.3989
1416.81	19.5565
1417.88	22.9141
1418.95	23.1647
1420.02	11.0476
1421.1	18.407
1422.17	17.6151
1423.24	18.0102
1424.31	22.075
1425.38	21.2774
1426.45	22.5488
1427.52	18.587
1428.59	8.49161
1429.67	9.75274
1430.74	12.0786
1431.81	5.19991
1432.87	8.45163
1433.95	5.48574
1435.01	9.81345
1436.08	11.0424
1437.15	6.10114
1438.22	7.3082
1439.29	8.55379
1440.36	4.69822
1441.43	5.93472
1442.49	5.09355
1443.56	4.25395
1444.63	5.4532
1445.7	4.66159
1446.77	2.77222
1447.83	2.92982
1448.9	5.17721
1449.97	5.34299
1451.03	2.41117
1452.1	-0.512878
1453.17	1.70185
1454.23	5.97629
1455.3	-3.08672
1456.36	-1.88801
1457.43	-4.82501
1458.49	1.46936
1459.56	-0.415604
1460.62	-1.29637
1461.69	3.94904
1462.75	-6.17799
1463.82	-0.96508
1464.88	-4.85727
1465.94	-0.78178
1467.01	4.43969
1468.07	5.58514
1469.13	1.62961
1470.2	0.70438
1471.26	-1.23364
1472.32	0.900101
1473.39	4.06844
1474.45	1.10826
1475.51	-6.90659
1476.57	0.315445
1477.63	0.40276
1478.69	4.56092
1479.76	0.568565
1480.82	2.64766
1481.88	-1.3263
1482.94	0.84322
1484	3.99999
1485.06	-3.11313
1486.12	2.03349
1487.18	-0.906498
1488.24	-0.8419
1489.3	0.217228
1490.36	-2.74521
1491.42	-2.68703
1492.48	2.44581
1493.53	-1.52422
1494.59	-2.45831
1495.65	-5.43399
1496.71	-0.35733
1497.77	-1.30886
1498.82	-3.25994
1499.88	2.87592
1500.94	-1.09188
1502	2.98877
1503.05	4.03901
1504.11	-1.97843
1505.17	1.10997
1506.22	6.15696
1507.28	-6.88264
1508.34	-1.79177
1509.39	-3.75563
1510.45	1.33964
1511.5	-1.68102
1512.56	0.27837
1513.61	3.27704
1514.67	0.339661
1515.72	-4.68296
1516.78	6.34396
1517.83	-3.65465
1518.88	6.42861
1519.94	-2.55186
1520.99	4.4962
1522.05	-1.48351
1523.1	-0.472694
1524.15	0.499866
1525.2	3.50797
1526.26	-2.45621
1527.31	2.604
1528.36	-4.40846
1529.41	-1.40044
1530.47	-3.39868
1531.52	4.66564
1532.57	-0.335972
1533.62	-1.27126
1534.67	6.77474
1535.72	-2.26328
1536.77	4.69068
1537.82	-1.35986
1538.87	2.61747
1539.92	-2.30223
1540.97	2.79665
1542.02	-2.24185
1543.07	6.72546
1544.12	2.66376
1545.17	3.69923
1546.22	-3.25877
1547.27	2.76244
1548.32	-1.27082
1549.37	-2.30164
1550.42	2.71795
1551.46	1.86509
1552.51	4.87451
1553.56	0.815502
1554.61	2.77728
1555.65	4.72706
1556.7	1.71001
1557.75	3.71336
1558.79	3.66092
1559.84	0.590588
1560.89	2.55338
1561.93	1.55261
1562.98	6.56936
1564.02	0.546894
1565.07	1.57553
1566.11	-4.71826
1567.16	1.45153
1568.2	6.47553
1569.25	1.47496
1570.29	0.434628
1571.34	-0.581715
1572.38	-1.61949
1573.43	-0.667423
1574.47	-0.689377
1575.51	-4.65493
1576.56	-0.668705
1577.6	-2.74138
1578.64	-2.81442
1579.69	-5.82678
1580.73	2.14576
1581.77	3.10019
1582.81	2.05495
1583.85	0.0336342
1584.9	3.00523
1585.94	-3.98909
1586.98	1.92776
1588.02	-0.101501
1589.06	1.88707
1590.1	4.87423
1591.14	1.88275
1592.18	-1.1351
1593.22	-0.206337
1594.26	3.67456
1595.3	0.684235
1596.34	-1.33957
1597.38	-0.36021
1598.42	0.616329
1599.46	2.53638
1600.5	-0.494656
1601.54	-1.55943
1602.58	2.33125
1603.62	1.27703
1604.66	-3.69683
1605.69	1.23345
1606.73	0.249878
1607.77	-2.67554
1608.81	0.00145721
1609.84	-1.33738
1610.88	0.205402
1611.92	-2.17363
1612.95	-1.58883
1613.99	2.93539
1615.03	-0.177872
1616.06	1.57703
1617.1	2.11162
1618.13	-0.168083
1619.17	-3.46976
1620.2	-0.101295
1621.24	2.36419
1622.27	3.09481
1623.31	2.83765
1624.34	2.32261
1625.38	-4.18992
1626.41	0.793705
1627.45	0.00726318
1628.48	4.11897
1629.51	-1.75279
1630.55	-0.128956
1631.53	-1.75214
1632.57	0.228489
1633.62	3.16801
1634.66	-3.7304
1635.71	2.16785
1636.75	1.14931
1637.8	7.01742
1638.84	2.06868
1639.89	2.05945
1640.93	2.05971
1641.98	1.06697
1643.02	-5.84186
1644.06	2.0172
1645.11	1.00432
1646.15	-1.93836
1647.19	-1.9627
1648.24	-2.96671
1649.28	4.94685
1650.32	6.91019
1651.37	4.0042
1652.41	0.0704651
1653.45	5.96807
1654.49	4.00805
1655.53	0.0875435
1656.57	7.0493
1657.62	0.141819
1658.66	-0.862076
1659.7	5.02711
1660.74	0.0907822
1661.78	-1.84312
1662.82	2.16695
1663.86	-2.76281
1664.9	-4.76507
1665.94	4.05455
1666.98	3.14279
1668.02	1.14594
1669.06	-3.77203
1670.1	7.1351
1671.14	-1.71077
1672.18	-0.722824
1673.21	2.25713
1674.25	5.24586
1675.29	1.33076
1676.33	0.364151
1677.37	0.380337
1678.4	2.34602
1679.44	2.32348
1680.48	-0.647823
1681.52	0.336319
1682.55	2.32484
1683.59	-2.60353
1684.63	-3.58821
1685.66	1.35544
1686.7	-0.598461
1687.73	-2.5454
1688.77	-0.574574
1689.81	2.36784
1690.84	-1.57368
1691.88	-0.550404
1692.91	-2.51084
1693.95	0.41869
1694.98	-5.50998
1696.01	-8.43868
1697.05	0.463314
1698.08	3.39797
1699.12	-1.53748
1700.15	0.45052
1701.18	5.37854
1702.22	-2.49313
1703.25	-1.51684
1704.28	-0.523186
1705.32	-3.43719
1706.35	-3.42335
1707.38	4.40916
1708.41	-0.528378
1709.44	2.37366
1710.48	-2.50694
1711.51	-1.48507
1712.54	-0.476311
1713.57	-1.50223
1714.6	-3.47952
1715.63	2.40881
1716.66	-3.42579
1717.69	4.34846
1718.72	0.391998
1719.75	-0.572254
1720.78	1.40129
1721.81	0.413342
1722.84	-2.52218
1723.87	-1.55653
1724.9	-2.5127
1725.93	-2.5479
1726.96	5.21707
1727.99	-2.51889
1729.02	4.18649
1730.05	3.1971
1731.07	-2.59483
1732.1	-0.576015
1733.13	-1.53144
1734.16	0.366009
1735.18	0.334808
1736.21	-4.49432
1737.24	0.327175
1738.26	2.25309
1739.29	-0.642162
1740.32	0.274628
1741.34	0.249359
1742.37	-0.710522
1743.4	-1.65062
1744.42	-4.5127
1745.45	-3.53351
1746.47	2.21817
1747.5	1.2402
1748.52	0.287529
1749.55	-0.62392
1750.57	-3.41964
1751.6	3.32398
1752.62	-2.42402
1753.64	3.29425
1754.67	1.37877
1755.69	-1.47546
1756.71	-2.43808
1757.74	-7.21097
1758.76	4.25196
1759.78	-2.3729
1760.81	1.45116
1761.83	1.44963
1762.85	-3.27655
1763.87	0.562889
1764.89	1.58181
1765.92	-4.07749
1766.94	0.709263
1767.96	-3.08234
1768.98	1.68469
1770	1.62386
1771.02	-8.7711
1772.04	0.799068
1773.06	-1.0467
1774.08	4.71387
1775.1	-3.81044
1776.12	6.74531
1777.14	1.05392
1778.16	0.0978737
1779.18	-0.866764
1780.2	-2.75106
1781.22	0.146488
1782.24	3.04375
1783.26	0.245026
1784.28	1.249
1785.29	0.353416
1786.31	-0.587902
1787.33	1.36796
1788.35	2.44141
1789.37	5.41185
1790.38	7.39981
1791.4	0.707169
1792.42	6.4385
1793.43	2.64589
1794.45	-3.07087
1795.47	-0.132645
1796.48	-0.0584984
1797.5	2.88219
1798.51	0.0433159
1799.53	1.02018
1800.55	5.81086
1801.56	-2.83047
1802.58	2.00046
1803.59	0.130878
1804.61	2.09359
1805.62	-0.735672
1806.64	-1.64556
1807.65	-1.61721
1808.66	2.25652
1809.68	-0.61335
1810.69	6.15653
1811.7	-1.54889
1812.72	-1.52829
1813.73	2.3676
1814.74	4.35656
1815.76	-0.424099
1816.77	5.39759
1817.78	-0.419151
1818.79	4.43012
1819.8	0.589176
1820.82	-2.28065
1821.83	-0.314533
1822.84	2.61721
1823.85	1.65697
1824.86	3.60217
1825.87	0.722012
1826.88	6.54188
1827.89	3.65663
1828.9	-2.1529
1829.91	-0.225723
1830.92	1.69577
1831.93	-1.18791
1832.94	-2.12743
1833.95	2.73379
1834.96	4.63957
1835.97	5.52942
1836.98	2.80897
1837.99	-0.250614
1839	-0.255344
1840	2.7141
1841.01	2.61513
1842.02	2.52237
1843.03	3.44118
1844.04	0.543148
1845.04	2.46927
1846.05	2.47845
1847.06	-1.34307
1848.07	-0.542007
1849.07	4.27365
1850.08	2.30282
1851.09	-2.56997
1852.09	3.15395
1853.1	3.14156
1854.1	4.07147
1855.11	4.96665
1856.11	6.82174
1857.12	5.84412
1858.12	3.89709
1859.13	7.66938
1860.13	4.74963
1861.14	3.80116
1862.14	5.72814
1863.15	10.4603
1864.15	6.57201
1865.15	5.5609
1866.16	6.43089
1867.16	2.51554
1868.16	10.0418
1869.17	3.36168
1870.17	12.8386
1871.17	9.00727
1872.17	9.9161
1873.18	7.96155
1874.18	8.86702
1875.18	7.8455
1876.18	9.63617
1877.18	9.55302
1878.18	6.61478
1879.19	12.356
1880.19	6.69794
1881.19	8.55994
1882.19	6.56203
1883.19	2.64963
1884.19	11.9933
1885.19	9.16795
1886.19	6.38018
1887.19	8.23301
1888.19	0.606354
1889.19	7.10549
1890.19	19.2821
1891.19	5.16519
1892.18	12.657
1893.18	6.95165
1894.18	8.71682
1895.18	15.2352
1896.18	3.00642
1897.18	15.2322
1898.17	4.86865
1899.17	11.3854
1900.17	8.49263
1901.16	6.57768
1902.16	5.64471
1903.16	6.57037
1904.16	7.45448
1905.15	9.28935
1906.15	7.35099
1907.14	8.21446
1908.14	5.36684
1909.14	1.59388
1910.13	7.24453
1911.13	4.44861
1912.12	11.0192
1913.12	4.37788
1914.11	9.07541
1915.11	10.0351
1916.1	4.35556
1917.1	5.23268
1918.09	7.05162
1919.08	5.16059
1920.08	5.19424
1921.07	7.99767
1922.06	8.94782
1923.06	4.1701
1924.05	3.16087
1925.04	9.70666
1926.04	5.92262
1927.03	7.83432
1928.02	6.87963
1929.01	1.17496
1930	10.6557
1931	7.82774
1931.99	6.82875
1932.98	6.75291
1933.97	12.4116
1934.96	4.93089
1935.95	7.86549
1936.94	3.0019
1937.93	9.57612
1938.92	7.62398
1939.91	8.56368
1940.9	5.69854
1941.89	6.65742
1942.88	9.49964
1943.87	5.60349
1944.86	2.73251
1945.85	6.5599
1946.84	-3.96862
1947.83	7.45305
1948.82	6.4436
1949.8	-0.264107
1950.79	5.50714
1951.78	5.54568
1952.77	4.58382
1953.76	0.70137
1954.74	6.29925
1955.73	3.34927
1956.72	3.39274
1957.7	6.27834
1958.69	-3.35122
1959.68	3.31263
1960.66	-0.602623
1961.65	1.23572
1962.63	2.15001
1963.62	5.95147
1964.61	5.92267
1965.59	0.108452
1966.58	2.01033
1967.56	0.0662498
1968.55	0.990055
1969.53	-0.0451279
1970.52	0.812355
1971.5	0.735756
1972.48	2.60751
1973.47	-0.327541
1974.45	1.51157
1975.44	4.34559
1976.42	-0.467445
1977.4	7.16416
1978.39	-2.49839
1979.37	-0.642418
1980.35	6.02659
1981.33	-2.67203
1982.31	4.92718
1983.3	-2.80944
1984.28	4.7646
1985.26	-1.04278
1986.24	-3.0156
1987.22	-1.13107
1988.21	-0.256611
1989.19	-2.30621
1990.17	-3.36512
1991.15	-1.58934
1992.13	1.05764
1993.11	-2.56982
1994.09	2.39078
1995.07	1.59824
1996.05	-1.81444
1997.03	-2.60408
1998.01	-1.71438
1998.99	-1.53385
1999.97	2.02396
2000.95	-1.78446
2001.92	2.83514
2002.9	1.8157
2003.88	-2.46419
2004.86	-2.54367
2005.84	0.91235
2006.81	-1.00833
2007.79	0.578098
2008.77	1.02065
2009.75	-1.64785
2010.73	-2.68798
2011.7	-2.12915
2012.68	1.40366
2013.67	-0.571556
2014.66	-1.62707
2015.64	3.01073
2016.63	2.99978
2017.62	3.00148
2018.61	-6.48898
2019.6	0.907082
2020.58	-1.02214
2021.57	1.75603
2022.56	-2.97351
2023.55	-6.793
2024.54	-0.320118
2025.52	2.38099
2026.51	2.30511
2027.5	1.47901
2028.48	-3.28389
2029.47	-1.36776
2030.45	1.24807
2031.44	0.30788
2032.43	0.286659
2033.41	4.06149
2034.4	4.03873
2035.38	2.99112
2036.37	2.14391
2037.35	-1.64087
2038.34	-2.61835
2039.32	3.86252
2040.31	1.92038
2041.29	1.83989
2042.27	-0.07621
2043.26	-2.91999
2044.24	0.841469
2045.23	-5.74205
2046.21	-7.54215
2047.19	-0.142391
2048.17	-4.89473
2049.16	-7.70557
2050.14	-4.88094
2051.12	-3.936
2052.11	0.680363
2053.09	-4.93085
2054.07	-2.09859
2055.05	-1.1707
2056.03	-3.08881
2057.01	-2.19333
2058	-1.26966
2058.98	-4.06033
2059.96	-4.99629
2060.94	3.38646
2061.92	-0.358135
2062.9	-3.17767
2063.88	-7.8546
2064.86	-1.29661
2065.84	-0.330708
2066.82	-6.89294
2067.8	0.621555
2068.78	4.38536
2069.76	3.40964
2070.73	3.38387
2071.71	-1.30142
2072.69	0.633533
2073.67	1.54562
2074.65	-2.22783
2075.63	4.4155
2076.6	1.62671
2077.58	-3.13749
2078.56	1.54787
2079.54	4.39067
2080.51	-4.07459
2081.49	5.35348
2082.47	-6.00363
2083.45	3.43399
2084.42	-1.3131
2085.4	0.560703
2086.37	1.50517
2087.35	-0.363251
2088.32	-1.31271
2089.3	0.571243
2090.28	4.37888
2091.25	0.589462
2092.23	2.50939
2093.2	1.61197
2094.18	5.44857
2095.15	-0.261696
2096.13	1.59118
2097.1	-5.09049
2098.07	-2.28961
2099.05	1.47688
2100.02	2.40034
2101	4.29206
2101.97	2.41112
2102.94	1.43964
2103.92	-2.4026
2104.89	-3.35941
2105.86	-0.492096
2106.83	1.41564
2107.8	2.35209
2108.78	5.12858
2109.75	0.362541
2110.72	4.15641
2111.69	9.83381
2112.66	1.25021
2113.63	1.26336
2114.61	2.2043
2115.58	0.285423
2116.55	-4.50636
2117.52	1.15471
2118.49	1.11567
2119.46	-0.853416
2120.43	2.87954
2121.4	2.87438
2122.37	-2.78566
2123.34	-3.72373
2124.31	-1.84748
2125.28	-2.88137
2126.25	-2.02357
2127.21	4.53173
2128.18	3.54336
2129.15	0.678917
2130.12	1.59177
2131.09	1.55648
2132.06	-4.16019
2133.02	-0.434727
2133.99	0.487194
2134.96	2.35761
2135.93	-0.505238
2136.89	-1.51768
2137.86	-4.35611
2138.83	-1.5671
2139.79	-3.46141
2140.76	2.12749
2141.73	4.91719
2142.69	3.92396
2143.66	-4.53191
2144.62	-1.8305
2145.59	-2.79048
2146.55	-0.00205231
2147.52	-0.0465889
2148.48	-0.0954247
2149.45	1.72599
2150.42	0.700424
2151.38	3.47572
2152.34	3.48029
2153.31	0.624435
2154.27	-0.364956
2155.24	0.470451
2156.2	1.30795
2157.16	-2.47393
2158.13	-0.609486
2159.09	-4.36565
2160.05	0.250481
2161.01	-1.69185
2161.98	0.129181
2162.94	0.0997849
2163.9	-0.883034
2164.86	1.84781
2165.83	-4.70287
2166.79	2.71301
2167.75	2.64364
2168.71	6.25534
2169.67	0.669647
2170.63	3.50325
2171.59	4.39009
2172.56	3.33383
2173.51	1.42617
2174.48	1.41256
2175.44	3.24366
2176.4	5.98902
2177.36	2.22509
2178.32	2.19843
2179.28	1.20592
2180.23	2.1076
2181.19	0.210728
2182.15	-4.47845
2183.11	-3.60069
2184.07	-3.6794
2185.03	-0.947517
2185.99	0.894745
2186.95	1.83578
2187.9	0.937664
2188.86	-0.0463409
2189.82	-2.91914
2190.78	-4.82809
2191.73	-0.213409
2192.69	-3.93763
2193.65	4.41293
2194.6	-2.9691
2195.56	-0.219067
2196.52	0.620815
2197.47	-0.392212
2198.43	0.501373
2199.38	2.38854
2200.34	8.94827
2201.3	1.57075
2202.25	-1.43742
2203.21	-6.02996
2204.16	-0.284752
2205.12	-3.21531
2206.07	0.344288
2207.03	-3.41341
2207.98	2.16488
2208.93	3.1086
2209.89	3.09292
2210.84	-2.51463
2211.8	-1.58265
2212.75	-3.44718
2213.7	-1.63888
2214.66	-1.6468
2215.61	-1.64607
2216.56	0.190304
2217.51	-1.7175
2218.47	-0.814297
2219.42	-2.69122
2220.37	1.04109
2221.32	3.79877
2222.27	1.84301
2223.23	0.879208
2224.18	7.43558
2225.13	-0.0140572
2226.08	-0.929077
2227.03	10.3287
2227.98	-5.60992
2228.93	6.53325
2229.88	-0.0588913
2230.83	-0.980389
2231.78	0.915791
2232.73	0.929115
2233.68	0.93985
2234.63	-0.0104179
2235.58	-0.0830231
2236.53	-1.06209
2237.48	-1.07114
2238.43	-2.90833
2239.38	-0.0433502
2240.33	-3.86936
2241.27	-7.64891
2242.22	7.43477
2243.17	-2.01217
2244.12	-0.174801
2245.07	-2.06541
2246.01	0.809093
2246.96	1.76773
2247.91	-0.125206
2248.85	-3.94725
2249.8	0.759911
2250.75	-0.223423
2251.69	0.653606
2252.64	1.58939
2253.59	-2.13809
2254.53	-3.05925
2255.48	1.66452
2256.42	-4.98147
2257.37	2.62591
2258.32	-3.06366
2259.26	1.68447
2260.2	-3.06113
2261.15	-4.95773
2262.1	-1.1371
2263.04	1.73025
2263.98	-2.03214
2264.93	2.80185
2265.87	-2.90585
2266.81	-3.90304
2267.76	-1.09769
2268.7	3.62107
2269.65	-5.89411
2270.59	1.79997
2271.53	0.874203
2272.47	1.85218
2273.42	-1.01837
2274.36	-0.0593147
2275.3	-1.9704
2276.24	-2.9235
2277.18	-2.88182
2278.13	2.94186
2279.07	0.0943489
2280.01	2.92573
2280.95	3.81972
2281.89	-0.0468597
2282.83	1.89768
2283.77	1.00304
2284.71	-2.75035
2285.65	4.98278
2286.59	-1.78762
2287.54	-3.65206
2288.47	-1.69968
2289.41	3.0711
2290.35	6.8418
2291.29	-0.842609
2292.23	-1.74464
2293.17	6.01262
2294.11	-0.697441
2295.05	-1.68568
2295.99	2.14062
2296.93	-1.74937
2297.86	1.18208
2298.8	-1.64253
2299.74	-0.621323
2300.68	1.32127
2301.61	8.11911
2302.55	-0.558323
2303.49	-0.553909
2304.43	-3.4225
2305.36	-1.4453
2306.3	-2.37768
2307.24	-0.421486
2308.17	7.30411
2309.11	1.51308
2310.04	0.613213
2310.98	4.51612
2311.92	1.53774
2312.85	-0.431248
2313.79	1.53117
2314.72	-0.309734
2315.66	1.67673
2316.59	-1.27927
2317.52	0.646591
2318.46	-3.19023
2319.39	1.61901
2320.33	7.4063
2321.26	-0.28091
2322.2	12.3436
2323.13	15.3046
2324.06	16.3066
2325	25.9678
2325.93	36.5147
2326.86	69.2568
2327.79	223.421
2328.73	577.113
2329.66	185.646
2330.59	50.7959
2331.52	21.9019
2332.46	11.3396
2333.39	6.49504
2334.32	3.58861
2335.25	8.36516
2336.18	3.56622
2337.11	3.55862
2338.04	1.62907
2338.97	3.54478
2339.91	4.51105
2340.84	5.44012
2341.77	-2.31089
2342.7	1.47957
2343.63	2.42441
2344.56	1.46052
2345.49	-0.473045
2346.41	-0.527172
2347.34	2.31883
2348.27	9.00675
2349.2	-0.578423
2350.13	-0.683083
2351.06	5.68945
2351.99	3.05045
2352.91	5.79424
2353.84	5.67258
2354.77	-0.0749397
2355.7	-5.82528
2356.63	-2.09399
2357.55	-0.304375
2358.48	-1.3349
2359.41	4.2865
2360.33	3.24574
2361.26	-3.51138
2362.19	-0.788193
2363.11	-0.913742
2364.04	4.65629
2364.97	3.59556