File: Data/3-Raman/processed/bu04w-a-ff3-fi08-v_150 (500nm)_633nm_edge_100%_x100_vis_lwd_h50um_45sx2_01.txt
#Acq. time (s)=	45
#Accumulations=	2
#Range (cm-¹)=	100...4000
#Windows=	1
#Auto scanning=	Off
#Autofocus=	Off
#Macrospot=	Off
#AutoExposure=	Off
#Spike filter=	Multiple accum.
#Delay time (s)=	2
#Binning=	1
#Readout mode=	Signal
#DeNoise=	Off
#ICS correction=	On
#Dark correction=	Off
#Inst. Process=	Off
#Detector Gain=	Best Dynamic
#Detector ADC=	50 kHz HS
#Detector temperature (°C)=	-60.09
#Instrument=	LabRAM HR Evol
#Detector=	SIN-EM FIVIS
#Objective=	x100_VIS_LWD
#Grating=	150 (500nm)
#ND Filter=	100%
#Laser=	633nm_Edge
#Hole=	49.98
#Temperature=	0
#Range=	Visible
#StageXY=	75x50mm Scan+
#StageZ=	Z motor
#X (µm)=	0
#Y (µm)=	0
#Z (µm)=	-40.5
#Full time(mm:ss)=	1:35
#Project=	21_11_22
#Sample=	BU04w
#Site=
#Title=	BU04w-A-FF3-FI08-V_150 (500nm)_633nm_Edge_100%_x100_VIS_LWD_H50um_45sX2
#Remark=
#Date=	22.11.2021 12:48
#Acquired=	22.11.2021 12:48:27
#Base:Fit=	16.12.2021 16:15:35
#Base:Fit=	16.12.2021 16:24:34
#Base:Edit=	16.12.2021 16:24:36
#Base:Edit=	16.12.2021 16:24:37
#Base:Edit=	16.12.2021 16:24:37
#Peaks:Remove=	16.12.2021 16:24:39
#Base:Sub=	16.12.2021 16:24:42
100.177	310.776
106.695	277.96
113.209	184.882
119.717	179.229
126.219	177.096
132.716	190.859
139.208	149.548
145.694	101.185
152.175	106.048
158.651	152.764
165.121	140.649
171.586	50.2287
178.045	24.238
184.5	18.5527
190.947	5.36804
197.39	-3.60297
203.829	-5.13177
210.262	-17.7737
216.688	-1.49701
223.11	22.6208
229.527	113.275
235.939	160.296
242.344	58.3919
248.745	18.8624
255.141	25.8987
261.53	21.8192
267.916	-0.997223
274.294	31.4468
280.669	16.6098
287.038	33.9986
293.402	-6.44818
299.76	11.9378
306.114	17.0947
312.461	52.5854
318.805	196.671
325.142	324.923
331.475	223.082
337.802	116.618
344.123	62.0987
350.441	38.653
356.752	49.0298
363.058	49.93
369.36	57.4085
375.656	32.9542
381.947	13.2782
388.232	45.6237
394.512	49.402
400.789	36.7265
407.059	46.5918
413.324	68.667
419.584	92.4683
425.839	153.559
432.089	198.103
438.333	166.963
444.573	128.37
450.807	137.509
457.037	135.529
463.261	101.36
469.48	69.5392
475.695	82.7721
481.904	112.949
488.108	78.749
494.307	95.8435
500.502	98.92
506.691	113.307
512.874	122.169
519.053	115.324
525.227	116.267
531.396	108.098
537.559	82.2057
543.718	72.786
549.873	86.3836
556.022	92.3542
562.165	66.35
568.304	66.3013
574.437	74.2291
580.567	56.5816
586.691	52.3987
592.81	71.947
598.924	43.445
605.033	64.221
611.138	59.12
617.236	74.9637
623.332	31.8848
629.42	22.3635
635.506	47.8103
641.585	27.2715
647.659	37.3944
653.73	26.663
659.794	22.2658
665.854	24.443
671.91	30.647
677.96	-10.7589
684.005	13.146
690.045	1.11014
696.082	8.99689
702.113	12.1686
708.139	-3.62122
714.16	20.2473
720.176	-19.0705
726.187	5.42612
732.194	-7.08215
738.196	-13.0202
744.193	6.32617
750.185	-4.05499
756.173	-3.87949
762.155	16.6151
768.133	-10.8568
774.107	-2.72784
780.075	-2.30057
786.039	-6.92706
791.998	12.7637
797.952	16.1397
803.902	10.644
809.845	7.79352
815.786	-19.7781
821.721	-20.2073
827.652	-0.131409
833.576	-10.3502
839.498	13.7937
845.415	-15.7956
851.327	22.1884
857.233	9.71945
863.135	-11.189
869.032	-8.54514
874.925	18.3918
880.813	5.1832
886.697	-5.43814
892.576	-3.04532
898.45	16.1094
904.318	3.49231
910.184	12.5349
916.044	-3.83121
921.9	25.5204
927.75	66.6998
933.596	88.7995
939.439	99.6232
945.275	129.804
951.107	157.583
956.936	159.556
962.759	113.263
968.577	103.751
974.391	96.6471
980.201	143.438
986.006	204.943
991.806	200.073
997.602	168.464
1003.39	152.501
1009.18	146.585
1014.96	179.68
1020.74	228.154
1026.51	217.234
1032.28	131.701
1038.04	79.6495
1043.8	48.5514
1049.56	26.8671
1055.31	29.9489
1061.05	45.3147
1066.8	42.6487
1072.53	9.79276
1078.26	39.8806
1083.99	71.7591
1089.72	117.288
1095.44	208.332
1101.15	159.91
1106.86	96.6384
1112.56	64.5277
1118.27	32.5589
1123.96	39.9398
1129.65	49.2878
1135.34	81.2712
1141.03	83.9699
1146.7	133.464
1152.38	245.937
1158.05	148.972
1163.71	69.0579
1169.37	35.3647
1175.03	9.58868
1180.68	18.1612
1186.33	27.1687
1191.98	7.31662
1197.61	-11.0967
1203.25	17.0837
1208.88	21.1985
1214.51	22.5333
1220.13	6.28604
1225.74	7.93036
1231.36	8.4509
1236.97	3.62463
1242.57	9.4071
1248.17	0.589722
1253.77	18.6816
1259.36	28.2136
1264.94	-2.9408
1270.53	-14.8937
1276.11	161.862
1281.68	112.216
1287.25	0.988312
1292.81	-9.72382
1298.38	2.89468
1303.93	4.80185
1309.48	11.2418
1315.03	-10.8749
1320.58	-11.8609
1326.12	-4.58112
1331.65	2.82144
1337.18	0.881958
1342.71	-16.6866
1348.23	-10.0403
1353.75	9.85406
1359.26	-0.238495
1364.77	5.8154
1370.28	-5.85092
1375.78	21.4823
1381.28	455.354
1386.77	61.6477
1392.26	13.073
1397.74	-0.106689
1403.23	48.4834
1408.7	-6.71176
1414.17	3.04202
1419.64	-12.9274
1425.11	9.48203
1430.56	10.1931
1436.02	6.70511
1441.47	7.31454
1446.92	15.2997
1452.36	-4.37714
1457.8	-17.0224
1463.23	-14.1521
1468.66	-17.7207
1474.09	4.97003
1479.51	-20.4506
1484.93	1.46103
1490.34	-9.01065
1495.75	-20.3648
1501.16	-10.5466
1506.56	20.5756
1511.96	5.34912
1517.35	21.0211
1522.74	4.84329
1528.13	20.7253
1533.51	30.3771
1538.88	-2.26639
1544.25	12.1959
1549.62	8.742
1554.99	32.8757
1560.35	-2.59418
1565.71	6.31827
1571.06	13.0185
1576.41	32.6884
1581.75	26.8445
1587.09	16.792
1592.43	13.3252
1597.76	-11.5309
1603.09	14.457
1608.41	26.6996
1613.73	36.0665
1619.05	5.38849
1624.36	21.5494
1629.67	22.407
1634.97	14.2683
1640.27	5.50119
1645.57	8.81427
1650.86	23.0865
1656.15	8.42255
1661.43	11.2918
1666.71	7.43225
1671.99	2.40613
1677.26	5.07001
1682.53	14.3109
1687.79	6.71552
1693.05	12.5419
1698.31	-4.53699
1703.56	9.50192
1708.81	-2.98788
1714.06	14.777
1719.3	-6.12091
1724.53	-11.8819
1729.77	1.59525
1735	-1.76352
1740.22	-9.6933
1745.44	12.8118
1750.66	9.22443
1755.87	5.50079
1761.08	-2.99203
1766.29	-0.187347
1771.49	7.21402
1776.69	-0.0458984
1781.88	4.23065
1787.07	17.7246
1792.26	4.07944
1797.44	-3.88089
1802.62	14.6028
1807.79	14.7658
1812.96	3.22205
1818.13	4.33459
1823.29	18.1562
1828.45	3.09473
1833.61	7.75156
1838.76	-1.56668
1843.91	6.3985
1849.05	8.47537
1854.19	-15.3114
1859.33	-7.40964
1864.46	4.13965
1869.59	0.472595
1874.71	4.82343
1879.83	-0.320709
1884.95	8.64218
1890.06	-0.272095
1895.17	9.53552
1900.28	-6.51828
1905.38	3.86816
1910.48	7.34708
1915.57	-16.2325
1920.66	15.6405
1925.75	-9.69821
1930.83	9.22174
1935.91	-5.45157
1940.99	-3.44882
1946.06	-11.1777
1951.13	12.2896
1956.19	7.94241
1961.26	10.7644
1966.31	1.46893
1971.36	-1.96051
1976.41	3.00488
1981.46	-7.6796
1986.5	-6.30374
1991.54	-0.0746155
1996.58	-20.2408
2001.61	-5.45532
2006.63	5.84634
2011.66	-8.01129
2016.68	19.0851
2021.69	11.1852
2026.71	7.09045
2031.72	1.91458
2036.72	-9.22562
2041.72	-4.61865
2046.72	7.35114
2051.71	-18.3828
2056.71	-17.5313
2061.69	-6.71204
2066.68	-11.768
2071.66	-13.2137
2076.63	-8.52008
2081.6	4.76901
2086.57	10.5737
2091.54	10.1922
2096.5	7.55301
2101.46	-4.97473
2106.41	-7.52072
2111.36	18.7348
2116.31	7.63034
2121.25	12.7934
2126.19	28.029
2131.13	15.458
2136.06	7.79645
2140.99	26.7072
2145.92	3.62979
2150.84	19.8435
2155.76	35.9877
2160.67	20.1125
2165.58	21.9815
2170.49	17.4064
2175.39	21.9373
2180.29	23.7787
2185.19	26.7432
2190.08	28.5254
2194.98	25.3167
2199.86	32.5465
2204.74	47.655
2209.62	29.4955
2214.5	33.2777
2219.37	48.8172
2224.24	15.2016
2229.11	32.0881
2233.97	58.1776
2238.83	58.2733
2243.68	60.9856
2248.53	54.541
2253.38	48.0268
2258.22	59.9793
2263.06	48.1473
2267.9	48.023
2272.73	58.3712
2277.56	64.64
2282.39	56.1392
2287.21	58.0966
2292.03	57.3935
2296.85	63.3614
2301.66	56.1985
2306.47	47.8868
2311.28	58.4462
2316.08	70.5148
2320.88	63.9407
2325.68	58.69
2330.47	29.1606
2335.26	78.106
2340.04	58.0983
2344.82	59.8623
2349.6	31.6133
2354.38	48.3615
2359.15	48.4802
2363.92	38.675
2368.68	37.2065
2373.44	42.6099
2378.2	35.5285
2382.95	28.2322
2387.71	19.3704
2392.45	17.3287
2397.2	6.82907
2401.94	31.0921
2406.68	37.1858
2411.41	24.1822
2416.14	6.20386
2420.87	26.4889
2425.59	17.6906
2430.31	19.042
2435.03	21.9105
2439.75	14.9365
2444.46	12.1562
2449.16	12.2204
2453.87	20.8477
2458.57	-2.0593
2463.27	-13.5958
2467.96	29.5997
2472.65	19.4233
2477.34	3.4101
2482.02	14.9185
2486.7	3.05743
2491.38	21.7732
2496.05	21.5536
2500.72	18.3487
2505.39	3.32944
2510.06	5.85089
2514.72	6.83398
2519.37	6.36093
2524.03	5.95581
2528.68	9.95081
2533.33	21.4086
2537.97	0.30777
2542.61	-0.0131226
2547.25	8.65115
2551.88	0.904755
2556.51	0.558136
2561.14	-8.80534
2565.77	17.9856
2570.39	-1.78799
2575.01	2.52502
2579.62	0.703369
2584.23	6.29895
2588.84	7.22729
2593.45	6.52615
2598.05	4.50461
2602.65	13.0984
2607.24	0.27832
2611.84	8.75577
2616.42	9.56802
2621.01	21.1255
2625.59	3.61755
2630.17	10.7272
2634.75	11.9173
2639.32	11.781
2643.89	-0.728867
2648.46	5.32816
2653.02	23.8527
2657.58	-7.81126
2662.14	8.79158
2666.69	-2.83885
2671.24	-25.3447
2675.79	5.74153
2680.33	-6.65758
2684.88	14.052
2689.41	25.3579
2693.95	2.93558
2698.48	-7.33531
2703.01	-4.66103
2707.53	1.17519
2712.06	11.8186
2716.57	6.46785
2721.09	5.86372
2725.6	-14.293
2730.11	-10.2392
2734.62	-6.26904
2739.12	-0.717484
2743.62	-1.53499
2748.12	12.3913
2752.61	5.43468
2757.1	9.77603
2761.59	9.00964
2766.08	-6.45544
2770.56	-26.9315
2775.04	-7.80646
2779.51	-1.72003
2783.98	11.1952
2788.45	2.5191
2792.92	13.7892
2797.38	4.91238
2801.84	-9.13554
2806.3	8.65753
2810.75	6.21268
2815.2	10.4409
2819.65	-14.1207
2824.09	-3.13033
2828.53	1.09821
2832.97	3.597
2837.41	-9.25647
2841.84	20.502
2846.27	2.56807
2850.69	-13.6746
2855.12	1.00133
2859.54	-10.0413
2863.95	9.97858
2868.37	-7.88478
2872.78	17.507
2877.18	16.948
2881.59	25.1685
2885.99	3.68845
2890.39	6.63838
2894.78	-4.55255
2899.18	10.8521
2903.57	10.2592
2907.95	-17.1781
2912.34	-14.4735
2916.72	9.66132
2921.09	-0.162994
2925.47	11.6071
2929.84	-1.78743
2934.21	8.25191
2938.57	-7.22379
2942.94	-8.27931
2947.29	-5.77869
2951.65	25.9018
2956	-11.751
2960.36	7.18658
2964.7	6.05659
2969.05	10.4751
2973.39	2.05428
2977.73	2.81165
2982.06	5.43759
2986.4	-6.63361
2990.73	-0.166229
2995.05	8.22084
2999.38	7.37674
3003.7	8.44389
3008.01	13.2903
3012.33	-4.52524
3016.64	13.549
3020.95	14.7066
3025.26	4.33922
3029.56	1.41783
3033.86	2.22906
3038.16	16.3396
3042.45	1.79431
3046.74	0.567291
3051.03	14.7385
3055.32	11.5898
3059.6	4.56648
3063.88	1.37967
3068.16	-1.8195
3072.43	18.3051
3076.7	13.1917
3080.97	-1.70052
3085.24	12.7304
3089.5	9.67268
3093.76	34.2343
3098.02	-4.12625
3102.27	22.5997
3106.52	29.7169
3110.77	18.9747
3115.01	24.177
3119.26	5.29317
3123.5	16.6017
3127.73	23.999
3131.97	27.4681
3136.2	28.9133
3140.43	34.4179
3144.65	33.6756
3148.87	30.7817
3153.09	27.7058
3157.31	60.0241
3161.52	52.7494
3165.73	55.9025
3169.94	31.621
3174.15	45.2657
3178.35	69.3165
3182.55	50.9843
3186.75	55.8728
3190.94	41.6246
3195.13	31.7394
3199.32	32.6778
3203.51	44.5564
3207.69	67.3253
3211.87	47.1743
3216.05	65.9155
3220.22	62.9906
3224.39	51.2821
3228.56	54.8301
3232.73	34.1577
3236.89	44.1503
3241.05	54.3279
3245.21	46.8824
3249.36	7.92139
3253.52	20.073
3257.66	14.188
3261.81	3.98518
3265.95	11.9256
3270.1	20.0593
3274.23	14.4813
3278.37	6.1237
3282.5	18.3738
3286.63	32.9712
3290.76	29.1975
3294.88	16.1562
3299	14.6174
3303.12	6.19524
3307.24	-6.91653
3311.35	-3.84833
3315.46	8.53604
3319.57	-4.65379
3323.68	19.5688
3327.78	6.47571
3331.88	0.456757
3335.98	18.0775
3340.07	2.58559
3344.16	15.2944
3348.25	-2.91545
3352.34	16.9072
3356.42	5.84161
3360.5	6.72249
3364.58	21.9792
3368.66	1.27444
3372.73	-9.90872
3376.8	10.1084
3380.87	10.8517
3384.93	16.4085
3388.99	-4.63977
3393.05	5.70918
3397.11	-5.66266
3401.16	4.78186
3405.21	3.01537
3409.26	13.418
3413.31	-29.7505
3417.35	7.4088
3421.39	-11.4507
3425.43	20.8839
3429.46	4.51122
3433.5	-2.07272
3437.53	-8.62357
3441.55	-15.1619
3445.58	10.2938
3449.6	-1.03268
3453.62	12.3142
3457.64	10.9659
3461.65	-7.76047
3465.66	3.34848
3469.67	9.50549
3473.68	-4.53247
3477.68	6.60411
3481.68	25.3772
3485.68	-6.46463
3489.67	-15.6319
3493.67	-4.47653
3497.66	19.4442
3501.64	10.1395
3505.63	3.3
3509.61	4.04263
3513.59	7.28197
3517.57	-25.4642
3521.54	8.60428
3525.52	-13.8737
3529.49	7.37378
3533.45	8.17656
3537.42	3.93216
3541.38	-8.07077
3545.34	-7.23178
3549.29	19.5435
3553.25	-8.39548
3557.2	0.110046
3561.15	-14.7567
3565.09	12.1228
3569.04	-0.00909424
3572.98	13.9699
3576.92	-0.818573
3580.85	0.176651
3584.79	-6.71788
3588.72	7.52673
3592.64	0.58728
3596.57	-17.0569
3600.49	13.2455
3604.41	0.82753
3608.33	-9.01558
3612.25	5.27016
3616.16	3.43845
3620.07	-3.83893
3623.98	4.94434
3627.88	-2.53029
3631.79	6.17749
3635.69	9.5014
3639.58	-0.629044
3643.48	-5.25925
3647.37	11.9074
3651.26	-1.08875
3655.15	5.0248
3659.03	11.1263
3662.92	-7.36125
3666.8	-1.26326
3670.67	-8.82768
3674.55	2.78351
3678.42	0.783279
3682.29	1.58034
3686.16	-3.06992
3690.02	6.08641
3693.89	-12.4468
3697.75	-3.31548
3701.61	-16.4205
3705.46	15.084
3709.31	7.5571
3713.16	11.2053
3717.01	-2.09409
3720.86	-9.85068
3724.7	19.0791
3728.54	-8.5573
3732.38	-10.7473
3736.21	-7.26282
3740.04	7.59991
3743.87	8.21959
3747.7	8.8103
3751.53	15.0735
3755.35	-15.9135
3759.17	4.5677
3762.99	13.5828
3766.81	2.52577
3770.62	-17.1157
3774.43	-5.19579
3778.24	-16.2461
3782.04	1.49124
3785.85	-0.869125
3789.65	-6.157
3793.45	5.89078
3797.24	12.2376
3801.04	9.91115
3804.83	1.7683
3808.62	-3.48639
3812.4	11.6521
3816.19	6.33498
3819.97	6.84845
3823.75	4.39183
3827.52	4.83369
3831.3	11.2034
3835.07	2.82561
3838.84	9.17615
3842.61	-5.16127
3846.37	-7.77839
3850.13	-16.413
3853.89	-4.27524
3857.65	4.87262
3861.41	8.04447
3865.16	-9.4948
3868.91	8.86747
3872.66	6.20036
3876.4	3.46252
3880.14	-8.25263
3883.89	-2.01842
3887.62	-4.7384
3891.36	-4.44809
3895.09	-7.08149
3898.82	2.28017
3902.55	-15.446
3906.28	-0.0488205
3910	-17.8552
3913.73	-5.41235
3917.45	7.10461
3921.16	-1.54989
3924.88	14.1351
3928.59	17.6456
3932.3	8.89919
3936.01	0.0686035
3939.71	9.63667
3943.42	0.859573
3947.12	-14.1258
3950.81	-1.41307
3954.51	-1.05042
3958.2	11.6737
3961.9	2.70368
3965.58	-3.18646
3969.27	12.576
3972.96	-8.83772
3976.64	-2.33955
3980.32	-11.362
3984	1.3159
3987.67	-10.7954
3991.34	5.04752
3995.01	2.34771
3998.68	-18.9269