File: Data/3-Raman/processed/bu04w-a-ff3-fi10-v_150 (500nm)_633nm_edge_100%_x100_vis_lwd_h50um_45sx2_01.txt
#Acq. time (s)=	45
#Accumulations=	2
#Range (cm-¹)=	100...4000
#Windows=	1
#Auto scanning=	Off
#Autofocus=	Off
#Macrospot=	Off
#AutoExposure=	Off
#Spike filter=	Multiple accum.
#Delay time (s)=	2
#Binning=	1
#Readout mode=	Signal
#DeNoise=	Off
#ICS correction=	On
#Dark correction=	Off
#Inst. Process=	Off
#Detector Gain=	Best Dynamic
#Detector ADC=	50 kHz EM
#Detector EM gain=	100
#Detector temperature (°C)=	-60.09
#Instrument=	LabRAM HR Evol
#Detector=	SIN-EM FIVIS
#Objective=	x100_VIS_LWD
#Grating=	150 (500nm)
#ND Filter=	100%
#Laser=	633nm_Edge
#Hole=	49.98
#Temperature=	0
#Range=	Visible
#StageXY=	75x50mm Scan+
#StageZ=	Z motor
#X (µm)=	0
#Y (µm)=	0
#Z (µm)=	4.4
#Full time(mm:ss)=	1:34
#Project=	21_11_22
#Sample=	BU04w
#Site=
#Title=	BU04w-A-FF3-FI10-V_150 (500nm)_633nm_Edge_100%_x100_VIS_LWD_H50um_45sX2
#Remark=
#Date=	22.11.2021 11:50
#Acquired=	22.11.2021 11:50:46
#Base:Fit=	16.12.2021 16:15:35
#Base:Edit=	16.12.2021 16:25:03
#Base:Edit=	16.12.2021 16:25:03
#Base:Edit=	16.12.2021 16:25:04
#Base:Edit=	16.12.2021 16:25:05
#Base:Edit=	16.12.2021 16:25:06
#Base:Edit=	16.12.2021 16:25:07
#Base:Edit=	16.12.2021 16:25:08
#Base:Sub=	16.12.2021 16:25:10
100.177	893.01
106.695	786.915
113.209	628.561
119.717	532.858
126.219	464.721
132.716	426.032
139.208	458.669
145.694	399.402
152.175	334.307
158.651	382.258
165.121	599.747
171.586	294.339
178.045	130.975
184.5	89.6088
190.947	60.9516
197.39	26.2391
203.829	-1.53973
210.262	-2.07477
216.688	12.1521
223.11	28.6297
229.527	236.374
235.939	524.964
242.344	325.196
248.745	135.138
255.141	113.274
261.53	86.1794
267.916	51.8782
274.294	70.1358
280.669	79.1288
287.038	144.038
293.402	78.1043
299.76	22.8429
306.114	64.1967
312.461	199.175
318.805	399.244
325.142	973.3
331.475	1057.75
337.802	496.214
344.123	237.662
350.441	110.187
356.752	123.979
363.058	147.092
369.36	189.908
375.656	116.237
381.947	27.7798
388.232	60.9518
394.512	38.476
400.789	87.9974
407.059	116.931
413.324	129.758
419.584	202.831
425.839	301.658
432.089	490.893
438.333	517.059
444.573	308.102
450.807	289.115
457.037	347.043
463.261	234.756
469.48	138.234
475.695	107.414
481.904	110.323
488.108	105.65
494.307	138.287
500.502	147.558
506.691	251.156
512.874	334.402
519.053	270.397
525.227	270.284
531.396	242.371
537.559	179.736
543.718	180.377
549.873	122.699
556.022	120.488
562.165	106.902
568.304	75.7984
574.437	79.9741
580.567	54.8058
586.691	46.8785
592.81	75.7458
598.924	165.543
605.033	126.777
611.138	113.352
617.236	126.476
623.332	102.262
629.42	109.76
635.506	84.111
641.585	90.5692
647.659	103.039
653.73	126.51
659.794	131.703
665.854	117.243
671.91	64.9773
677.96	31.465
684.005	25.9181
690.045	32.0081
696.082	12.1904
702.113	21.2739
708.139	26.4115
714.16	38.2395
720.176	39.4486
726.187	25.5215
732.194	13.9873
738.196	4.30948
744.193	-2.51083
750.185	29.9903
756.173	6.78329
762.155	21.5873
768.133	8.01544
774.107	17.887
780.075	3.08868
786.039	20.8249
791.998	20.4558
797.952	11.2599
803.902	23.3408
809.845	29.5297
815.786	31.6061
821.721	24.0909
827.652	23.0526
833.576	31.9545
839.498	25.6897
845.415	9.60321
851.327	27.3295
857.233	38.6992
863.135	19.086
869.032	55.1705
874.925	47.3854
880.813	54.3432
886.697	41.091
892.576	66.4186
898.45	61.0325
904.318	52.2594
910.184	52.839
916.044	91.9825
921.9	72.4567
927.75	119.317
933.596	156.536
939.439	237.335
945.275	313.398
951.107	485.384
956.936	505.593
962.759	398.909
968.577	359.17
974.391	384.868
980.201	499.539
986.006	644.739
991.806	744.195
997.602	585.416
1003.39	473.363
1009.18	472.797
1014.96	530.769
1020.74	648.097
1026.51	765.075
1032.28	558.769
1038.04	304.606
1043.8	226.549
1049.56	192.434
1055.31	157.661
1061.05	148.54
1066.8	125.115
1072.53	113.232
1078.26	175.865
1083.99	207.231
1089.72	282.3
1095.44	507.408
1101.15	596.717
1106.86	379.284
1112.56	216.185
1118.27	151.206
1123.96	123.32
1129.65	119.682
1135.34	113.159
1141.03	183.163
1146.7	331.619
1152.38	590.532
1158.05	682.059
1163.71	304.952
1169.37	153.537
1175.03	69.2199
1180.68	39.0208
1186.33	20.1176
1191.98	47.5664
1197.61	22.7737
1203.25	23.9991
1208.88	-1.96118
1214.51	16.4906
1220.13	4.59915
1225.74	16.6255
1231.36	18.6042
1236.97	30.3236
1242.57	14.4024
1248.17	43.3609
1253.77	63.8925
1259.36	91.9563
1264.94	73.1844
1270.53	44.3669
1276.11	124.895
1281.68	798.481
1287.25	33.9063
1292.81	44.4898
1298.38	21.4607
1303.93	32.7222
1309.48	32.5623
1315.03	18.9272
1320.58	21.4509
1326.12	-2.11288
1331.65	27.0353
1337.18	2.1279
1342.71	9.48679
1348.23	19.6354
1353.75	28.6625
1359.26	33.3333
1364.77	55.1602
1370.28	52.0288
1375.78	71.4458
1381.28	529.228
1386.77	546.29
1392.26	67.0049
1397.74	72.7172
1403.23	90.898
1408.7	63.9456
1414.17	54.59
1419.64	21.5213
1425.11	16.3922
1430.56	12.3062
1436.02	24.8466
1441.47	16.4761
1446.92	10.2047
1452.36	10.8125
1457.8	14.2621
1463.23	-1.45282
1468.66	4.72122
1474.09	8.81192
1479.51	-4.74789
1484.93	-4.56924
1490.34	21.0394
1495.75	22.7276
1501.16	18.2232
1506.56	22.2916
1511.96	5.34842
1517.35	21.4384
1522.74	23.8396
1528.13	1.66278
1533.51	15.9991
1538.88	23.65
1544.25	39.6527
1549.62	15.9853
1554.99	4.70184
1560.35	13.7651
1565.71	11.0386
1571.06	25.5078
1576.41	24.9503
1581.75	20.4576
1587.09	41.9153
1592.43	24.76
1597.76	15.3483
1603.09	8.23303
1608.41	14.3473
1613.73	31.7112
1619.05	21.114
1624.36	30.1495
1629.67	37.0095
1634.97	32.6805
1640.27	25.4149
1645.57	33.5407
1650.86	30.4632
1656.15	34.9619
1661.43	41.4475
1666.71	26.7683
1671.99	7.57794
1677.26	23.7843
1682.53	31.0221
1687.79	23.5894
1693.05	25.1768
1698.31	23.8676
1703.56	15.1674
1708.81	9.9364
1714.06	17.7636
1719.3	7.3598
1724.53	34.4232
1729.77	21.4373
1735	29.7311
1740.22	18.8402
1745.44	36.1132
1750.66	19.3168
1755.87	35.1357
1761.08	3.12048
1766.29	19.7509
1771.49	3.61011
1776.69	11.3507
1781.88	7.99838
1787.07	2.4881
1792.26	22.2487
1797.44	18.1423
1802.62	32.5196
1807.79	22.8003
1812.96	30.0662
1818.13	33.9174
1823.29	25.0384
1828.45	23.1241
1833.61	10.7888
1838.76	23.997
1843.91	16.0098
1849.05	32.4476
1854.19	37.0666
1859.33	30.1301
1864.46	24.4785
1869.59	27.0966
1874.71	24.7046
1879.83	32.8394
1884.95	31.4566
1890.06	21.5758
1895.17	27.9768
1900.28	10.9329
1905.38	7.44513
1910.48	27.9321
1915.57	12.0511
1920.66	10.8461
1925.75	40.8301
1930.83	30.2243
1935.91	35.1063
1940.99	26.6247
1946.06	28.7925
1951.13	38.0335
1956.19	22.9991
1961.26	15.0989
1966.31	9.51334
1971.36	19.3614
1976.41	25.527
1981.46	13.6277
1986.5	39.0511
1991.54	-1.61371
1996.58	16.7158
2001.61	15.934
2006.63	15.3187
2011.66	29.2877
2016.68	4.75848
2021.69	10.215
2026.71	32.8477
2031.72	7.40332
2036.72	13.507
2041.72	6.31458
2046.72	7.67401
2051.71	6.63113
2056.71	10.2054
2061.69	32.4196
2066.68	31.462
2071.66	16.8987
2076.63	36.7315
2081.6	31.8772
2086.57	0.880341
2091.54	14.3051
2096.5	8.267
2101.46	37.0966
2106.41	1.3992
2111.36	28.1018
2116.31	2.45078
2121.25	30.6954
2126.19	36.3425
2131.13	31.7971
2136.06	25.8151
2140.99	8.26199
2145.92	13.4637
2150.84	17.1747
2155.76	-2.2551
2160.67	29.2288
2165.58	3.02637
2170.49	1.0188
2175.39	32.502
2180.29	21.5618
2185.19	-3.70459
2190.08	-5.79425
2194.98	10.2292
2199.86	0.903778
2204.74	-10.7973
2209.62	16.2452
2214.5	0.983582
2219.37	34.9282
2224.24	5.5647
2229.11	-0.562439
2233.97	11.5168
2238.83	13.2028
2243.68	-8.67078
2248.53	7.43777
2253.38	27.5259
2258.22	12.1416
2263.06	23.0781
2267.9	25.8666
2272.73	16.5034
2277.56	-2.3634
2282.39	22.4068
2287.21	17.6773
2292.03	16.9319
2296.85	-5.09094
2301.66	9.07916
2306.47	-0.440765
2311.28	2.31113
2316.08	6.59555
2320.88	-11.7855
2325.68	72.0908
2330.47	-4.16589
2335.26	10.0284
2340.04	8.05658
2344.82	-23.7767
2349.6	-6.46783
2354.38	10.8021
2359.15	47.1256
2363.92	8.69769
2368.68	25.5369
2373.44	7.74634
2378.2	20.392
2382.95	0.801147
2387.71	14.2892
2392.45	5.30774
2397.2	-9.43329
2401.94	7.77527
2406.68	8.15271
2411.41	14.7611
2416.14	4.4071
2420.87	-6.52155
2425.59	17.2286
2430.31	-4.8764
2435.03	11.2485
2439.75	14.8331
2444.46	22.658
2449.16	2.02045
2453.87	8.41364
2458.57	7.65192
2463.27	3.9975
2467.96	17.5615
2472.65	44.1046
2477.34	-1.70294
2482.02	13.2889
2486.7	13.5872
2491.38	26.9501
2496.05	36.0107
2500.72	24.4832
2505.39	12.8212
2510.06	17.1781
2514.72	34.6649
2519.37	16.8303
2524.03	-2.39008
2528.68	15.257
2533.33	37.4896
2537.97	19.8603
2542.61	26.0403
2547.25	-6.44397
2551.88	29.6874
2556.51	14.9299
2561.14	15.1063
2565.77	18.5071
2570.39	-6.60547
2575.01	4.44464
2579.62	7.78253
2584.23	9.26801
2588.84	1.38275
2593.45	20.6313
2598.05	-3.79791
2602.65	24.9776
2607.24	33.8592
2611.84	5.90558
2616.42	0.7901
2621.01	-10.3984
2625.59	25.9774
2630.17	18.1726
2634.75	10.8077
2639.32	-10.0122
2643.89	27.8983
2648.46	24.1661
2653.02	14.1194
2657.58	1.75568
2662.14	29.8079
2666.69	20.1347
2671.24	13.9045
2675.79	16.1392
2680.33	37.0036
2684.88	10.195
2689.41	10.219
2693.95	16.209
2698.48	17.7149
2703.01	13.1448
2707.53	16.4482
2712.06	3.52814
2716.57	13.4761
2721.09	16.7901
2725.6	29.6315
2730.11	21.1835
2734.62	33.6081
2739.12	-2.84705
2743.62	4.91138
2748.12	29.1894
2752.61	6.94305
2757.1	20.3113
2761.59	11.9118
2766.08	25.1111
2770.56	31.7545
2775.04	5.6405
2779.51	29.3524
2783.98	-7.81836
2788.45	29.7272
2792.92	17.2379
2797.38	6.12396
2801.84	38.4553
2806.3	6.68561
2810.75	11.7706
2815.2	31.8929
2819.65	-7.22559
2824.09	28.2154
2828.53	0.937134
2832.97	15.994
2837.41	25.9143
2841.84	1.7843
2846.27	-3.48529
2850.69	30.7263
2855.12	31.0975
2859.54	21.2
2863.95	9.75342
2868.37	-11.9464
2872.78	18.233
2877.18	3.37372
2881.59	23.5026
2885.99	7.10339
2890.39	25.657
2894.78	8.94342
2899.18	3.04114
2903.57	27.0578
2907.95	36.7262
2912.34	24.6888
2916.72	19.508
2921.09	-8.86841
2925.47	34.7595
2929.84	19.209
2934.21	48.7603
2938.57	-3.66833
2942.94	16.2518
2947.29	23.243
2951.65	42.9973
2956	28.077
2960.36	42.3673
2964.7	38.4788
2969.05	36.5676
2973.39	29.1926
2977.73	25.4836
2982.06	36.6011
2986.4	40.6738
2990.73	15.257
2995.05	62.3503
2999.38	3.52533
3003.7	13.754
3008.01	42.9021
3012.33	68.2439
3016.64	75.124
3020.95	46.1288
3025.26	48.985
3029.56	32.353
3033.86	59.402
3038.16	61.2355
3042.45	73.0316
3046.74	46.0605
3051.03	42.0704
3055.32	47.7698
3059.6	24.4971
3063.88	59.2462
3068.16	45.5837
3072.43	68.8203
3076.7	64.9367
3080.97	49.3376
3085.24	92.5094
3089.5	69.5474
3093.76	50.7495
3098.02	85.3517
3102.27	70.7056
3106.52	99.9447
3110.77	49.7614
3115.01	93.3531
3119.26	125.244
3123.5	107.166
3127.73	105.342
3131.97	189.4
3136.2	106.319
3140.43	139.508
3144.65	149.936
3148.87	170.58
3153.09	157.487
3157.31	137.792
3161.52	174.488
3165.73	171.421
3169.94	237.502
3174.15	162.776
3178.35	194.733
3182.55	222.204
3186.75	221.98
3190.94	225.844
3195.13	172.889
3199.32	143.957
3203.51	192.766
3207.69	224.995
3211.87	240.363
3216.05	178.172
3220.22	252.237
3224.39	180.513
3228.56	209.091
3232.73	171.737
3236.89	193.345
3241.05	164.553
3245.21	162.649
3249.36	193.685
3253.52	159.043
3257.66	141.684
3261.81	154.487
3265.95	120.373
3270.1	168.356
3274.23	157.049
3278.37	150.543
3282.5	141.781
3286.63	162.841
3290.76	107.966
3294.88	91.9399
3299	98.9594
3303.12	134.038
3307.24	145.991
3311.35	148.55
3315.46	113.87
3319.57	146.781
3323.68	103.101
3327.78	122.682
3331.88	126.375
3335.98	116.396
3340.07	103.521
3344.16	108.765
3348.25	149.249
3352.34	154.313
3356.42	80.8527
3360.5	129.153
3364.58	141.757
3368.66	67.8891
3372.73	97.0667
3376.8	123.573
3380.87	147.564
3384.93	72.4985
3388.99	98.7142
3393.05	107.917
3397.11	88.3835
3401.16	66.3695
3405.21	124.072
3409.26	118.705
3413.31	115.541
3417.35	110.004
3421.39	111.706
3425.43	88.9834
3429.46	103.174
3433.5	98.0673
3437.53	83.4189
3441.55	90.9854
3445.58	128.409
3449.6	131.87
3453.62	73.6671
3457.64	82.5662
3461.65	74.3549
3465.66	91.0977
3469.67	70.2958
3473.68	76.3533
3477.68	105.44
3481.68	89.1469
3485.68	103.062
3489.67	78.8134
3493.67	95.127
3497.66	111.181
3501.64	73.2977
3505.63	88.7958
3509.61	111.504
3513.59	77.3425
3517.57	81.6332
3521.54	91.0443
3525.52	82.5678
3529.49	84.2849
3533.45	45.5122
3537.42	76.9852
3541.38	51.8012
3545.34	59.7902
3549.29	54.5521
3553.25	61.4008
3557.2	53.0162
3561.15	55.3469
3565.09	42.3289
3569.04	48.1495
3572.98	56.4244
3576.92	62.4464
3580.85	39.912
3584.79	54.4225
3588.72	50.4333
3592.64	83.5779
3596.57	34.3145
3600.49	78.0339
3604.41	12.0677
3608.33	47.536
3612.25	56.0595
3616.16	34.9771
3620.07	62.2198
3623.98	40.0677
3627.88	36.5603
3631.79	24.6989
3635.69	26.5074
3639.58	28.8569
3643.48	15.5826
3647.37	43.4116
3651.26	31.7081
3655.15	50.3317
3659.03	44.325
3662.92	32.7077
3666.8	21.2668
3670.67	18.0629
3674.55	45.1652
3678.42	9.75208
3682.29	15.8403
3686.16	-2.40308
3690.02	42.9572
3693.89	2.56982
3697.75	34.0872
3701.61	32.4598
3705.46	33.4984
3709.31	6.73071
3713.16	38.7446
3717.01	42.3801
3720.86	14.7607
3724.7	34.9056
3728.54	26.6692
3732.38	18.5466
3736.21	16.128
3740.04	27.8235
3743.87	13.7374
3747.7	19.4628
3751.53	16.3648
3755.35	24.4384
3759.17	26.5472
3762.99	19.9369
3766.81	4.68903
3770.62	18.4133
3774.43	29.4219
3778.24	-2.58521
3782.04	14.5983
3785.85	14.8055
3789.65	0.403564
3793.45	23.6572
3797.24	41.6194
3801.04	-6.97314
3804.83	2.54333
3808.62	35.5672
3812.4	21.8003
3816.19	2.01715
3819.97	17.3209
3823.75	6.06818
3827.52	0.473511
3831.3	33.4659
3835.07	-1.30389
3838.84	19.8292
3842.61	-11.967
3846.37	50.3698
3850.13	14.2706
3853.89	25.5789
3857.65	27.8193
3861.41	17.9693
3865.16	26.8589
3868.91	-4.54547
3872.66	19.4057
3876.4	25.0337
3880.14	0.791687
3883.89	0.597656
3887.62	-2.38055
3891.36	18.808
3895.09	31.7368
3898.82	38.4856
3902.55	3.12787
3906.28	21.8782
3910	1.36945
3913.73	20.5049
3917.45	3.58575
3921.16	35.6611
3924.88	25.2838
3928.59	11.6094
3932.3	12.9709
3936.01	7.82074
3939.71	18.1105
3943.42	59.7203
3947.12	33.6183
3950.81	38.0712
3954.51	42.2966
3958.2	43.2993
3961.9	6.79108
3965.58	13.5415
3969.27	19.9619
3972.96	-4.521
3976.64	42.3836
3980.32	14.6815
3984	42.6569
3987.67	58.3299
3991.34	46.3911
3995.01	28.6904
3998.68	26.9468