File: Data/3-Raman/processed/bu04w-a-ff3-fi06-l_150 (500nm)_633nm_edge_100%_x100_vis_lwd_h50um_45sx2_01.txt
#Acq. time (s)=	45
#Accumulations=	2
#Range (cm-¹)=	100...4000
#Windows=	1
#Auto scanning=	Off
#Autofocus=	Off
#Macrospot=	Off
#AutoExposure=	Off
#Spike filter=	Multiple accum.
#Delay time (s)=	2
#Binning=	1
#Readout mode=	Signal
#DeNoise=	Off
#ICS correction=	On
#Dark correction=	Off
#Inst. Process=	Off
#Detector Gain=	Best Dynamic
#Detector ADC=	50 kHz HS
#Detector temperature (°C)=	-60.09
#Instrument=	LabRAM HR Evol
#Detector=	SIN-EM FIVIS
#Objective=	x100_VIS_LWD
#Grating=	150 (500nm)
#ND Filter=	100%
#Laser=	633nm_Edge
#Hole=	49.98
#Temperature=	0
#Range=	Visible
#StageXY=	75x50mm Scan+
#StageZ=	Z motor
#X (µm)=	0
#Y (µm)=	0
#Z (µm)=	-8.5
#Full time(mm:ss)=	1:35
#Project=	21_11_22
#Sample=	BU04w
#Site=
#Title=	BU04w-A-FF3-FI06-L_150 (500nm)_633nm_Edge_100%_x100_VIS_LWD_H50um_45sX2
#Remark=
#Date=	22.11.2021 11:04
#Acquired=	22.11.2021 11:04:57
#Base:Fit=	16.12.2021 16:15:35
#Base:Edit=	16.12.2021 16:23:41
#Base:Edit=	16.12.2021 16:23:42
#Base:Edit=	16.12.2021 16:23:42
#Base:Edit=	16.12.2021 16:23:43
#Base:Edit=	16.12.2021 16:23:44
#Base:Edit=	16.12.2021 16:23:44
#Base:Edit=	16.12.2021 16:23:45
#Base:Sub=	16.12.2021 16:23:47
100.177	357.327
106.695	313.038
113.209	282.518
119.717	267.449
126.219	246.894
132.716	238.024
139.208	230.193
145.694	222.655
152.175	189.56
158.651	228.641
165.121	326.486
171.586	210.662
178.045	109.157
184.5	67.0985
190.947	48.0632
197.39	33.0666
203.829	14.7348
210.262	1.33652
216.688	3.33481
223.11	28.2968
229.527	91.1958
235.939	253.953
242.344	187.604
248.745	59.0186
255.141	35.8642
261.53	55.5616
267.916	11.8049
274.294	3.26726
280.669	40.2974
287.038	56.4104
293.402	11.8274
299.76	-4.26503
306.114	7.09097
312.461	50.5839
318.805	154.452
325.142	455.595
331.475	541.589
337.802	227.675
344.123	106.248
350.441	47.0373
356.752	46.2037
363.058	65.0811
369.36	69.8076
375.656	53.8541
381.947	21.9964
388.232	12.8807
394.512	16.168
400.789	21.537
407.059	31.599
413.324	56.7341
419.584	87.4789
425.839	142.525
432.089	236.323
438.333	244.829
444.573	161.161
450.807	136.791
457.037	159.337
463.261	126.098
469.48	62.4226
475.695	41.7994
481.904	58.4965
488.108	45.32
494.307	61.9616
500.502	96.2825
506.691	117.611
512.874	164.176
519.053	159.516
525.227	121.325
531.396	106.549
537.559	101.177
543.718	85.1908
549.873	65.0873
556.022	50.549
562.165	57.357
568.304	34.7218
574.437	45.8046
580.567	28.6237
586.691	32.178
592.81	35.8563
598.924	76.0023
605.033	92.2837
611.138	79.7354
617.236	71.9583
623.332	65.134
629.42	57.2479
635.506	55.5355
641.585	43.125
647.659	41.8421
653.73	57.3885
659.794	83.0303
665.854	71.1705
671.91	47.3721
677.96	16.4887
684.005	18.2296
690.045	12.6324
696.082	15.5212
702.113	7.11951
708.139	19.2922
714.16	19.9295
720.176	15.7769
726.187	15.344
732.194	6.3343
738.196	6.68867
744.193	13.5804
750.185	15.8285
756.173	9.76216
762.155	5.76464
768.133	5.64904
774.107	12.111
780.075	10.0546
786.039	2.21641
791.998	1.83285
797.952	2.29504
803.902	7.35292
809.845	6.68669
815.786	18.1438
821.721	16.3631
827.652	11.7517
833.576	12.9288
839.498	12.4372
845.415	19.5728
851.327	10.8042
857.233	10.4984
863.135	12.0969
869.032	29.7782
874.925	36.9791
880.813	35.5246
886.697	38.7191
892.576	31.3731
898.45	31.5118
904.318	36.2057
910.184	35.181
916.044	36.9841
921.9	50.238
927.75	58.0358
933.596	90.496
939.439	113.05
945.275	177.552
951.107	261.664
956.936	260.364
962.759	219.534
968.577	184.966
974.391	189.389
980.201	246.127
986.006	345.539
991.806	390.929
997.602	328.229
1003.39	255.43
1009.18	261.21
1014.96	284.698
1020.74	370.318
1026.51	430.896
1032.28	330.775
1038.04	188.907
1043.8	129.203
1049.56	105.883
1055.31	75.4846
1061.05	79.8096
1066.8	67.4014
1072.53	67.5813
1078.26	83.2168
1083.99	122.046
1089.72	154.085
1095.44	220.961
1101.15	331.265
1106.86	232.929
1112.56	129.777
1118.27	87.0322
1123.96	69.1937
1129.65	66.881
1135.34	85.1372
1141.03	120.167
1146.7	176.789
1152.38	305.353
1158.05	384.316
1163.71	169.53
1169.37	78.9913
1175.03	49.4898
1180.68	29.8857
1186.33	32.9263
1191.98	17.5338
1197.61	28.652
1203.25	17.4337
1208.88	20.0133
1214.51	4.86339
1220.13	12.4734
1225.74	16.1853
1231.36	4.86246
1236.97	19.5158
1242.57	13.967
1248.17	14.3268
1253.77	-2.58637
1259.36	11.7009
1264.94	16.8013
1270.53	15.8374
1276.11	9.78702
1281.68	10.7652
1287.25	12.7916
1292.81	15.8698
1298.38	8.03864
1303.93	9.27168
1309.48	11.6357
1315.03	11.1309
1320.58	10.6482
1326.12	7.17091
1331.65	6.72746
1337.18	3.16568
1342.71	12.804
1348.23	10.1151
1353.75	1.2254
1359.26	11.7729
1364.77	5.81602
1370.28	-0.204071
1375.78	56.4246
1381.28	50.369
1386.77	20.7056
1392.26	12.6358
1397.74	8.79512
1403.23	0.851173
1408.7	-2.97272
1414.17	10.7622
1419.64	9.05994
1425.11	0.107574
1430.56	3.59225
1436.02	0.830215
1441.47	2.21814
1446.92	4.66774
1452.36	3.8821
1457.8	7.22659
1463.23	9.46383
1468.66	7.46307
1474.09	8.61509
1479.51	4.56113
1484.93	-1.57739
1490.34	1.7767
1495.75	7.29236
1501.16	11.7994
1506.56	5.77638
1511.96	8.24415
1517.35	2.2472
1522.74	3.69889
1528.13	7.31004
1533.51	12.0469
1538.88	3.80029
1544.25	9.49327
1549.62	12.877
1554.99	8.55792
1560.35	6.36415
1565.71	2.03767
1571.06	3.09656
1576.41	12.7787
1581.75	-3.30093
1587.09	15.0906
1592.43	11.9833
1597.76	17.5488
1603.09	21.0067
1608.41	9.38168
1613.73	16.2373
1619.05	11.2053
1624.36	24.7443
1629.67	15.301
1634.97	12.357
1640.27	20.2886
1645.57	19.382
1650.86	17.3299
1656.15	21.8838
1661.43	19.7353
1666.71	13.1276
1671.99	23.1387
1677.26	16.4931
1682.53	6.50459
1687.79	16.4107
1693.05	14.1618
1698.31	13.1141
1703.56	6.83103
1708.81	3.88433
1714.06	13.7951
1719.3	7.36469
1724.53	5.26677
1729.77	-0.156967
1735	10.1329
1740.22	9.18415
1745.44	15.0015
1750.66	4.96697
1755.87	8.45489
1761.08	6.2262
1766.29	5.12269
1771.49	4.03365
1776.69	5.22934
1781.88	4.20647
1787.07	4.34404
1792.26	10.2257
1797.44	15.0008
1802.62	6.08447
1807.79	9.75203
1812.96	11.0846
1818.13	10.1183
1823.29	13.7698
1828.45	10.4925
1833.61	2.56144
1838.76	6.23645
1843.91	9.87927
1849.05	-1.67969
1854.19	1.91462
1859.33	10.2372
1864.46	5.69645
1869.59	8.21052
1874.71	16.5678
1879.83	4.86515
1884.95	0.209129
1890.06	8.51133
1895.17	3.76245
1900.28	2.59932
1905.38	3.91079
1910.48	1.71055
1915.57	1.96447
1920.66	5.65807
1925.75	1.01404
1930.83	8.34059
1935.91	-4.72525
1940.99	9.78951
1946.06	9.86992
1951.13	6.30714
1956.19	7.526
1961.26	8.7299
1966.31	3.89012
1971.36	11.0573
1976.41	9.77776
1981.46	8.49966
1986.5	6.02614
1991.54	10.7814
1996.58	5.93282
2001.61	1.10998
2006.63	5.93727
2011.66	1.16938
2016.68	10.8546
2021.69	7.27316
2026.71	9.77283
2031.72	-3.39278
2036.72	8.85149
2041.72	6.58955
2046.72	3.11649
2051.71	11.8199
2056.71	9.51898
2061.69	7.26399
2066.68	13.5862
2071.66	10.0903
2076.63	9.03929
2081.6	14.1349
2086.57	-1.78954
2091.54	13.1653
2096.5	10.8816
2101.46	2.39295
2106.41	16.3118
2111.36	4.09021
2116.31	13.1275
2121.25	8.38828
2126.19	7.39068
2131.13	12.6905
2136.06	7.84957
2140.99	15.6703
2145.92	9.50417
2150.84	16.0217
2155.76	12.3103
2160.67	9.83839
2165.58	14.9961
2170.49	6.07601
2175.39	9.98477
2180.29	6.17871
2185.19	7.44936
2190.08	8.74587
2194.98	13.9215
2199.86	10.1826
2204.74	5.19156
2209.62	4.07708
2214.5	24.905
2219.37	16.1294
2224.24	4.72214
2229.11	3.65099
2233.97	11.6928
2238.83	6.71368
2243.68	6.94591
2248.53	11.1217
2253.38	15.3087
2258.22	16.8864
2263.06	5.23569
2267.9	1.44201
2272.73	-1.07322
2277.56	14.98
2282.39	16.3949
2287.21	9.78008
2292.03	9.81377
2296.85	11.1819
2301.66	3.27384
2306.47	-7.27119
2311.28	8.92024
2316.08	5.11804
2320.88	-4.05064
2325.68	4.23986
2330.47	0.435745
2335.26	8.82285
2340.04	6.40076
2344.82	10.8022
2349.6	13.8865
2354.38	16.9603
2359.15	10.3542
2363.92	16.0554
2368.68	6.60049
2373.44	12.3275
2378.2	13.9089
2382.95	7.09955
2387.71	9.96574
2392.45	12.7968
2397.2	4.46008
2401.94	5.85428
2406.68	10.0094
2411.41	14.282
2416.14	7.60365
2420.87	9.45101
2425.59	10.986
2430.31	12.6251
2435.03	0.164978
2439.75	11.7581
2444.46	4.92056
2449.16	8.03068
2453.87	8.29054
2458.57	7.11236
2463.27	10.2417
2467.96	9.0439
2472.65	15.0534
2477.34	3.69212
2482.02	9.71521
2486.7	8.4458
2491.38	7.15608
2496.05	13.1829
2500.72	14.8175
2505.39	4.68841
2510.06	1.86083
2514.72	6.36881
2519.37	9.41828
2524.03	6.58868
2528.68	18.5365
2533.33	17.1943
2537.97	3.99136
2542.61	-1.81387
2547.25	11.7574
2551.88	13.4278
2556.51	12.089
2561.14	15.2432
2565.77	6.41245
2570.39	12.6378
2575.01	11.3339
2579.62	6.95938
2584.23	14.6544
2588.84	14.7268
2593.45	-1.97191
2598.05	5.72552
2602.65	2.7485
2607.24	11.9635
2611.84	10.4694
2616.42	7.43196
2621.01	7.46019
2625.59	9.03193
2630.17	7.57447
2634.75	10.7987
2639.32	12.5728
2643.89	9.71912
2648.46	2.19406
2653.02	17.9778
2657.58	2.50158
2662.14	7.26421
2666.69	18.2635
2671.24	8.96912
2675.79	10.7374
2680.33	20.6165
2684.88	5.14705
2689.41	11.8544
2693.95	4.13992
2698.48	10.6155
2703.01	12.3497
2707.53	14.0646
2712.06	1.25539
2716.57	7.82914
2721.09	14.3983
2725.6	11.2254
2730.11	-4.97858
2734.62	12.8731
2739.12	9.59567
2743.62	11.2485
2748.12	11.307
2752.61	11.4862
2757.1	6.6992
2761.59	3.46138
2766.08	11.7571
2770.56	-6.27045
2775.04	3.71713
2779.51	15.4539
2783.98	12.3831
2788.45	12.6205
2792.92	21.1971
2797.38	11.345
2801.84	8.13185
2806.3	14.9718
2810.75	11.6915
2815.2	16.8198
2819.65	5.02774
2824.09	5.07932
2828.53	15.3208
2832.97	1.76672
2837.41	6.8987
2841.84	-6.71146
2846.27	6.99082
2850.69	15.6273
2855.12	12.3426
2859.54	5.60957
2863.95	14.3996
2868.37	11.1615
2872.78	14.8371
2877.18	8.09567
2881.59	1.33234
2885.99	1.55722
2890.39	12.3241
2894.78	3.73209
2899.18	5.75487
2903.57	13.0872
2907.95	16.8641
2912.34	11.6749
2916.72	8.21513
2921.09	10.1558
2925.47	19.3286
2929.84	8.71397
2934.21	32.4416
2938.57	7.19781
2942.94	9.1052
2947.29	20.0903
2951.65	18.3368
2956	11.0958
2960.36	12.9796
2964.7	16.7173
2969.05	20.4931
2973.39	16.9388
2977.73	13.3742
2982.06	11.6545
2986.4	24.7768
2990.73	8.31171
2995.05	15.9575
2999.38	10.6129
3003.7	22.1102
3008.01	24.3025
3012.33	34.0119
3016.64	28.7057
3020.95	36.6717
3025.26	29.4035
3029.56	44.935
3033.86	35.6205
3038.16	33.8676
3042.45	28.3271
3046.74	32.3375
3051.03	44.0652
3055.32	36.5321
3059.6	50.2615
3063.88	56.2814
3068.16	44.8517
3072.43	48.9423
3076.7	55.0126
3080.97	47.4447
3085.24	49.6578
3089.5	61.7513
3093.76	62.1834
3098.02	76.4826
3102.27	69.1029
3106.52	83.589
3110.77	80.2652
3115.01	78.9276
3119.26	73.5633
3123.5	86.3791
3127.73	97.3205
3131.97	86.0144
3136.2	88.932
3140.43	106.231
3144.65	115.342
3148.87	107.876
3153.09	121.034
3157.31	136.299
3161.52	139.091
3165.73	133.48
3169.94	150.918
3174.15	151.631
3178.35	156.353
3182.55	180.056
3186.75	182.562
3190.94	182.908
3195.13	189.806
3199.32	182.061
3203.51	187.386
3207.69	214.304
3211.87	200.5
3216.05	184.501
3220.22	181.343
3224.39	186.871
3228.56	183.68
3232.73	189.23
3236.89	179.237
3241.05	184.819
3245.21	172.752
3249.36	182.772
3253.52	167.945
3257.66	161.883
3261.81	169.583
3265.95	159.382
3270.1	162.89
3274.23	141.219
3278.37	153.217
3282.5	162.989
3286.63	170.505
3290.76	127.406
3294.88	160.181
3299	142.275
3303.12	147.512
3307.24	152.748
3311.35	148.674
3315.46	153.889
3319.57	147.497
3323.68	162.21
3327.78	170.028
3331.88	166.269
3335.98	169.689
3340.07	163.532
3344.16	159.488
3348.25	160.066
3352.34	184.474
3356.42	158.947
3360.5	173.991
3364.58	184.315
3368.66	180.246
3372.73	164.117
3376.8	174.32
3380.87	196.561
3384.93	158.451
3388.99	178.255
3393.05	169.018
3397.11	179.242
3401.16	165.221
3405.21	168.055
3409.26	170.909
3413.31	178.573
3417.35	181.396
3421.39	167.141
3425.43	174.809
3429.46	187.468
3433.5	178.219
3437.53	186.162
3441.55	177.011
3445.58	175.292
3449.6	178.594
3453.62	194.296
3457.64	155.695
3461.65	164.169
3465.66	177.705
3469.67	176.274
3473.68	157.056
3477.68	183.166
3481.68	153.807
3485.68	157.194
3489.67	163.108
3493.67	146.089
3497.66	134.007
3501.64	152.527
3505.63	145.389
3509.61	148.364
3513.59	133.265
3517.57	143.832
3521.54	128.686
3525.52	128.984
3529.49	118.959
3533.45	116.81
3537.42	99.284
3541.38	102.428
3545.34	100.301
3549.29	105.905
3553.25	93.1354
3557.2	88.2196
3561.15	96.3718
3565.09	91.5556
3569.04	84.213
3572.98	84.66
3576.92	85.1642
3580.85	64.6657
3584.79	86.3358
3588.72	60.4371
3592.64	58.2863
3596.57	74.7693
3600.49	85.9524
3604.41	70.3867
3608.33	62.7512
3612.25	73.875
3616.16	66.1733
3620.07	47.6058
3623.98	47.7892
3627.88	34.4126
3631.79	58.8624
3635.69	34.6306
3639.58	34.8081
3643.48	35.062
3647.37	48.9591
3651.26	49.0733
3655.15	38.331
3659.03	38.4601
3662.92	46.7566
3666.8	30.495
3670.67	22.4083
3674.55	33.4895
3678.42	25.4532
3682.29	14.6755
3686.16	12.1553
3690.02	20.6856
3693.89	9.84603
3697.75	1.7087
3701.61	4.68091
3705.46	7.65292
3709.31	13.4561
3713.16	5.2316
3717.01	19.4549
3720.86	16.7809
3724.7	14.0722
3728.54	5.67184
3732.38	-14.0996
3736.21	-5.52062
3740.04	0.228821
3743.87	11.6855
3747.7	3.16417
3751.53	17.4724
3755.35	3.15457
3759.17	3.11058
3762.99	0.186592
3766.81	5.85393
3770.62	5.81409
3774.43	8.65424
3778.24	2.881
3782.04	25.9009
3785.85	8.65949
3789.65	5.78029
3793.45	2.90108
3797.24	14.5282
3801.04	11.7004
3804.83	5.96405
3808.62	0.213326
3812.4	-2.65788
3816.19	6.16022
3819.97	0.343666
3823.75	3.30668
3827.52	3.32016
3831.3	0.410614
3835.07	-2.50408
3838.84	6.39158
3842.61	6.45975
3846.37	3.49266
3850.13	-11.4027
3853.89	-5.51787
3857.65	-5.5818
3861.41	3.26166
3865.16	0.293724
3868.91	-2.55986
3872.66	9.40848
3876.4	-2.54353
3880.14	0.448936
3883.89	0.472382
3887.62	0.521591
3891.36	-11.399
3895.09	-5.27228
3898.82	-8.15675
3902.55	1.01716
3906.28	-1.84932
3910	-1.69302
3913.73	-10.5751
3917.45	1.77203
3921.16	-0.977058
3924.88	-6.76771
3928.59	2.68433
3932.3	9.11316
3936.01	-5.90366
3939.71	-2.52701
3943.42	-2.15274
3947.12	4.39664
3950.81	4.79957
3954.51	-7.15627
3958.2	-9.84845
3961.9	2.93505
3965.58	0.264221
3969.27	0.689072
3972.96	-8.15184
3976.64	4.74426
3980.32	2.15202
3984	8.88272
3987.67	0.148033
3991.34	10.077
3995.01	10.7752
3998.68	5.33532