File: Data/3-Raman/processed/bu04w-a-ff3-fi02-v_150 (500nm)_633nm_edge_100%_x100_vis_lwd_h50um_45sx2_01.txt
#Acq. time (s)=	45
#Accumulations=	2
#Range (cm-¹)=	100...4000
#Windows=	1
#Auto scanning=	Off
#Autofocus=	Off
#Macrospot=	Off
#AutoExposure=	Off
#Spike filter=	Multiple accum.
#Delay time (s)=	2
#Binning=	1
#Readout mode=	Signal
#DeNoise=	Off
#ICS correction=	On
#Dark correction=	Off
#Inst. Process=	Off
#Detector Gain=	Best Dynamic
#Detector ADC=	50 kHz HS
#Detector temperature (°C)=	-60.28
#Instrument=	LabRAM HR Evol
#Detector=	SIN-EM FIVIS
#Objective=	x100_VIS_LWD
#Grating=	150 (500nm)
#ND Filter=	100%
#Laser=	633nm_Edge
#Hole=	49.98
#Temperature=	0
#Range=	Visible
#StageXY=	75x50mm Scan+
#StageZ=	Z motor
#X (µm)=	0
#Y (µm)=	0
#Z (µm)=	5.5
#Full time(mm:ss)=	1:34
#Project=	21_11_22
#Sample=	BU04w
#Site=
#Title=	BU04w-A-FF3-FI02-V_150 (500nm)_633nm_Edge_100%_x100_VIS_LWD_H50um_45sX2
#Remark=
#Date=	22.11.2021 10:43
#Acquired=	22.11.2021 10:43:28
#Base:Fit=	16.12.2021 16:15:35
#Base:Edit=	16.12.2021 16:21:50
#Base:Edit=	16.12.2021 16:21:51
#Base:Edit=	16.12.2021 16:21:52
#Base:Edit=	16.12.2021 16:21:52
#Base:Sub=	16.12.2021 16:21:56
100.177	432.848
106.695	344.006
113.209	261.232
119.717	229.26
126.219	194.711
132.716	174.779
139.208	168.448
145.694	149.051
152.175	121.357
158.651	118.907
165.121	195.341
171.586	123.412
178.045	48.7167
184.5	39.3455
190.947	14.8092
197.39	8.69707
203.829	-1.81001
210.262	1.24796
216.688	6.39572
223.11	15.5075
229.527	39.8738
235.939	130.936
242.344	126.058
248.745	40.7803
255.141	26.8222
261.53	38.6627
267.916	14.6006
274.294	20.0986
280.669	33.2865
287.038	55.0361
293.402	19.9502
299.76	0.144684
306.114	12.5803
312.461	39.2498
318.805	92.3888
325.142	273.029
331.475	384.819
337.802	194.823
344.123	66.2486
350.441	43.3164
356.752	26.9886
363.058	36.1008
369.36	57.4415
375.656	29.9494
381.947	17.5615
388.232	0.687592
394.512	-0.0605011
400.789	15.351
407.059	17.6328
413.324	21.7893
419.584	43.8629
425.839	86.5795
432.089	129.635
438.333	162.09
444.573	119.207
450.807	91.4433
457.037	73.2509
463.261	69.3095
469.48	37.5987
475.695	23.7393
481.904	29.5044
488.108	23.1318
494.307	40.0734
500.502	35.5687
506.691	52.5501
512.874	97.5709
519.053	70.796
525.227	61.8468
531.396	63.2695
537.559	55.3545
543.718	44.4296
549.873	24.7825
556.022	29.6176
562.165	22.8721
568.304	14.1108
574.437	13.7059
580.567	15.1037
586.691	23.1065
592.81	28.396
598.924	49.6331
605.033	49.7072
611.138	47.9773
617.236	37.9149
623.332	46.6335
629.42	37.4395
635.506	42.0584
641.585	35.108
647.659	26.1383
653.73	35.9249
659.794	53.9949
665.854	57.9557
671.91	37.7655
677.96	21.6123
684.005	19.4381
690.045	6.16265
696.082	8.81854
702.113	8.63771
708.139	9.33432
714.16	17.339
720.176	11.1704
726.187	6.85427
732.194	8.05734
738.196	-0.115341
744.193	10.415
750.185	4.15886
756.173	7.29067
762.155	12.4574
768.133	8.4234
774.107	10.9426
780.075	6.81742
786.039	-2.13417
791.998	3.92228
797.952	8.95951
803.902	9.17685
809.845	7.45268
815.786	4.71194
821.721	6.61916
827.652	2.87691
833.576	21.6939
839.498	24.7942
845.415	13.0447
851.327	19.0966
857.233	10.153
863.135	16.2723
869.032	25.2537
874.925	33.2134
880.813	30.6413
886.697	24.189
892.576	27.1386
898.45	29.9916
904.318	26.0679
910.184	28.7299
916.044	24.7933
921.9	44.4992
927.75	41.8024
933.596	52.4245
939.439	76.537
945.275	116.06
951.107	158.81
956.936	173.139
962.759	152.903
968.577	131.423
974.391	147.115
980.201	153.81
986.006	223.496
991.806	247.905
997.602	210.139
1003.39	185.975
1009.18	159.216
1014.96	181.461
1020.74	217.126
1026.51	263.772
1032.28	231.14
1038.04	129.176
1043.8	84.5175
1049.56	68.6008
1055.31	55.387
1061.05	46.869
1066.8	38.1728
1072.53	49.8417
1078.26	56.5908
1083.99	71.0477
1089.72	90.3644
1095.44	130.973
1101.15	202.474
1106.86	173.6
1112.56	90.5609
1118.27	68.8588
1123.96	45.9088
1129.65	43.3478
1135.34	44.7072
1141.03	65.7034
1146.7	94.525
1152.38	173.581
1158.05	252.39
1163.71	125.145
1169.37	55.1557
1175.03	27.5248
1180.68	27.3769
1186.33	27.3481
1191.98	25.4799
1197.61	17.8697
1203.25	14.2999
1208.88	1.93327
1214.51	12.2303
1220.13	9.77322
1225.74	8.31138
1231.36	9.81123
1236.97	23.3193
1242.57	19.6512
1248.17	10.7965
1253.77	19.0177
1259.36	28.1301
1264.94	39.1535
1270.53	24.9667
1276.11	38.8987
1281.68	491.851
1287.25	80.6386
1292.81	25.569
1298.38	24.6362
1303.93	19.7819
1309.48	14.0513
1315.03	7.42021
1320.58	15.8918
1326.12	13.3422
1331.65	12.8219
1337.18	19.3816
1342.71	18.7544
1348.23	22.1453
1353.75	21.4126
1359.26	28.8333
1364.77	27.9626
1370.28	22.9118
1375.78	34.2886
1381.28	109.308
1386.77	696.337
1392.26	45.8031
1397.74	32.7112
1403.23	38.1291
1408.7	49.7806
1414.17	16.0962
1419.64	8.16138
1425.11	16.8047
1430.56	6.78163
1436.02	9.21172
1441.47	7.45972
1446.92	13.0431
1452.36	0.714684
1457.8	4.04978
1463.23	4.18563
1468.66	8.48904
1474.09	6.49865
1479.51	5.60044
1484.93	1.57154
1490.34	-0.320526
1495.75	2.03987
1501.16	10.7666
1506.56	12.1547
1511.96	1.92218
1517.35	2.29887
1522.74	4.82922
1528.13	9.52805
1533.51	6.75918
1538.88	3.90841
1544.25	11.7892
1549.62	7.63869
1554.99	10.9369
1560.35	8.79136
1565.71	7.74988
1571.06	4.5472
1576.41	3.51846
1581.75	13.3253
1587.09	14.5449
1592.43	6.1009
1597.76	6.31477
1603.09	9.80274
1608.41	11.193
1613.73	14.8366
1619.05	6.56632
1624.36	14.6535
1629.67	11.8047
1634.97	11.0978
1640.27	16.8736
1645.57	6.06388
1650.86	2.94691
1656.15	14.2009
1661.43	12.116
1666.71	0.0303345
1671.99	15.656
1677.26	16.8455
1682.53	21.3407
1687.79	18.0212
1693.05	-4.07732
1698.31	9.3311
1703.56	11.9702
1708.81	14.6688
1714.06	9.03677
1719.3	11.5879
1724.53	2.83735
1729.77	9.80699
1735	5.55444
1740.22	12.5382
1745.44	16.1592
1750.66	5.05354
1755.87	10.8645
1761.08	12.0975
1766.29	7.66234
1771.49	3.23643
1776.69	7.89252
1781.88	1.24721
1787.07	5.97932
1792.26	8.48718
1797.44	15.585
1802.62	7.85257
1807.79	16.1568
1812.96	14.0868
1818.13	9.70119
1823.29	13.387
1828.45	13.6193
1833.61	11.5359
1838.76	5.94188
1843.91	17.7843
1849.05	9.77638
1854.19	15.759
1859.33	18.2702
1864.46	5.5456
1869.59	15.1414
1874.71	8.20833
1879.83	21.3032
1884.95	8.41714
1890.06	7.29156
1895.17	12.0289
1900.28	6.16005
1905.38	12.2251
1910.48	-0.64566
1915.57	6.73848
1920.66	11.6352
1925.75	21.3496
1930.83	7.14233
1935.91	12.0722
1940.99	13.3821
1946.06	14.6643
1951.13	26.7579
1956.19	13.5221
1961.26	5.0807
1966.31	14.6988
1971.36	19.4482
1976.41	13.3428
1981.46	10.8517
1986.5	13.1774
1991.54	10.7012
1996.58	19.0566
2001.61	16.6147
2006.63	6.98575
2011.66	5.79322
2016.68	13.0334
2021.69	23.8765
2026.71	10.6605
2031.72	7.11001
2036.72	13.2591
2041.72	12.1552
2046.72	14.7054
2051.71	11.1771
2056.71	8.80622
2061.69	18.7057
2066.68	-0.77404
2071.66	7.90543
2076.63	17.8475
2081.6	9.30618
2086.57	19.2345
2091.54	10.6267
2096.5	20.6419
2101.46	9.59193
2106.41	3.48979
2111.36	11.1169
2116.31	3.7687
2121.25	22.7749
2126.19	26.748
2131.13	15.5458
2136.06	14.3979
2140.99	1.78938
2145.92	18.3908
2150.84	5.68003
2155.76	26.0944
2160.67	17.1296
2165.58	23.4531
2170.49	18.2548
2175.39	14.3717
2180.29	14.2856
2185.19	15.4341
2190.08	12.7656
2194.98	17.8131
2199.86	11.3778
2204.74	19.0906
2209.62	19.1441
2214.5	7.61669
2219.37	11.5732
2224.24	14.2568
2229.11	13.0535
2233.97	14.4476
2238.83	11.9278
2243.68	4.15622
2248.53	13.4124
2253.38	4.28179
2258.22	8.3038
2263.06	16.303
2267.9	11.0398
2272.73	12.3553
2277.56	10.9841
2282.39	14.8899
2287.21	14.7606
2292.03	7.97559
2296.85	13.1678
2301.66	10.4182
2306.47	9.04596
2311.28	19.745
2316.08	11.769
2320.88	10.4939
2325.68	36.1441
2330.47	5.24021
2335.26	9.39401
2340.04	13.5808
2344.82	15.0934
2349.6	16.6373
2354.38	18.1597
2359.15	5.86315
2363.92	-3.8027
2368.68	4.47959
2373.44	8.62865
2378.2	8.62585
2382.95	12.7378
2387.71	14.0282
2392.45	15.279
2397.2	3.96753
2401.94	9.34541
2406.68	10.5237
2411.41	14.6044
2416.14	16.1212
2420.87	19.2266
2425.59	9.33178
2430.31	9.3655
2435.03	5.1883
2439.75	22.2792
2444.46	11.0156
2449.16	5.39444
2453.87	11.1802
2458.57	6.95088
2463.27	7.01202
2467.96	5.61594
2472.65	18.6612
2477.34	17.2749
2482.02	12.963
2486.7	11.5106
2491.38	15.879
2496.05	21.7344
2500.72	9.99735
2505.39	8.48362
2510.06	8.41338
2514.72	8.31773
2519.37	9.703
2524.03	9.6395
2528.68	12.5222
2533.33	12.4636
2537.97	24.3138
2542.61	7.94704
2547.25	6.44071
2551.88	10.9061
2556.51	0.39167
2561.14	3.3394
2565.77	15.3609
2570.39	9.36647
2575.01	9.38956
2579.62	13.925
2584.23	6.26916
2588.84	9.1852
2593.45	18.1491
2598.05	13.51
2602.65	5.78485
2607.24	8.71082
2611.84	11.6137
2616.42	17.5694
2621.01	6.70409
2625.59	14.223
2630.17	1.85045
2634.75	9.50772
2639.32	17.2905
2643.89	9.6498
2648.46	22.1564
2653.02	9.80618
2657.58	9.75315
2662.14	9.66573
2666.69	-6.11588
2671.24	3.19341
2675.79	17.3699
2680.33	-2.8706
2684.88	3.64433
2689.41	13.4024
2693.95	10.3556
2698.48	16.6738
2703.01	15.0489
2707.53	3.73058
2712.06	6.86314
2716.57	18.1409
2721.09	13.2366
2725.6	16.3832
2730.11	11.3801
2734.62	16.0732
2739.12	9.36938
2743.62	15.7369
2748.12	9.11881
2752.61	4.24452
2757.1	15.6741
2761.59	12.2867
2766.08	7.29227
2770.56	20.3927
2775.04	18.7358
2779.51	2.23513
2783.98	10.6152
2788.45	19.0492
2792.92	10.7968
2797.38	4.13015
2801.84	12.5201
2806.3	14.1671
2810.75	10.7317
2815.2	14.0095
2819.65	10.516
2824.09	13.8094
2828.53	13.7175
2832.97	22.1105
2837.41	-0.143517
2841.84	11.6582
2846.27	9.85633
2850.69	9.78493
2855.12	16.6366
2859.54	18.3715
2863.95	8.08607
2868.37	18.5417
2872.78	8.22123
2877.18	16.9996
2881.59	17.1286
2885.99	1.50778
2890.39	22.7059
2894.78	-1.86838
2899.18	10.6465
2903.57	30.3134
2907.95	16.1725
2912.34	14.411
2916.72	19.761
2921.09	-8.95723
2925.47	16.2276
2929.84	18.107
2934.21	18.168
2938.57	21.777
2942.94	16.2687
2947.29	14.3367
2951.65	8.74663
2956	12.2695
2960.36	10.3127
2964.7	10.2006
2969.05	17.4581
2973.39	21.0767
2977.73	19.1848
2982.06	13.6093
2986.4	9.9177
2990.73	22.9375
2995.05	15.5821
2999.38	11.95
3003.7	19.5592
3008.01	19.7178
3012.33	21.7186
3016.64	31.3521
3020.95	24.0008
3025.26	20.344
3029.56	22.3137
3033.86	5.10815
3038.16	20.3517
3042.45	22.2754
3046.74	6.82466
3051.03	22.1558
3055.32	24.0316
3059.6	23.9857
3063.88	25.8705
3068.16	29.7051
3072.43	33.5525
3076.7	23.7903
3080.97	19.8515
3085.24	35.4884
3089.5	15.9682
3093.76	16.0769
3098.02	37.9392
3102.27	30.2523
3106.52	44.4264
3110.77	44.7767
3115.01	27.114
3119.26	39.4769
3123.5	47.9538
3127.73	56.5459
3131.97	55.0955
3136.2	41.3401
3140.43	43.8694
3144.65	27.7603
3148.87	59.1865
3153.09	55.3361
3157.31	59.7572
3161.52	70.4821
3165.73	68.6537
3169.94	64.6453
3174.15	77.5554
3178.35	64.9575
3182.55	81.8916
3186.75	86.1038
3190.94	77.5534
3195.13	90.3741
3199.32	69.3349
3203.51	80.4673
3207.69	80.9986
3211.87	75.0951
3216.05	88.7007
3220.22	71.9129
3224.39	72.4422
3228.56	81.7519
3232.73	88.9059
3236.89	62.8863
3241.05	78.8969
3245.21	72.866
3249.36	73.3602
3253.52	60.2141
3257.66	71.6052
3261.81	67.503
3265.95	49.9098
3270.1	61.8387
3274.23	64.6643
3278.37	46.4809
3282.5	71.7839
3286.63	53.5574
3290.76	42.1444
3294.88	65.2372
3299	37.6151
3303.12	46.9643
3307.24	49.3796
3311.35	44.8059
3315.46	37.8862
3319.57	44.952
3323.68	47.4534
3327.78	45.3289
3331.88	50.3377
3335.98	46.0431
3340.07	43.9891
3344.16	39.3893
3348.25	51.3151
3352.34	68.0698
3356.42	51.5414
3360.5	58.8854
3364.58	44.711
3368.66	59.2498
3372.73	57.0021
3376.8	49.8459
3380.87	54.6908
3384.93	42.6224
3388.99	28.0871
3393.05	49.8051
3397.11	54.6803
3401.16	49.8609
3405.21	44.9382
3409.26	52.1786
3413.31	52.0834
3417.35	37.3888
3421.39	68.9738
3425.43	34.7364
3429.46	46.9014
3433.5	49.3651
3437.53	39.6506
3441.55	42.2095
3445.58	52.2237
3449.6	54.9698
3453.62	35.5107
3457.64	35.8768
3461.65	36.2967
3465.66	49.2138
3469.67	49.6772
3473.68	39.9506
3477.68	42.8347
3481.68	73.5285
3485.68	51.1432
3489.67	59.1104
3493.67	36.5179
3497.66	49.5087
3501.64	31.7863
3505.63	47.2661
3509.61	42.1411
3513.59	36.9256
3517.57	36.8337
3521.54	52.1658
3525.52	36.6651
3529.49	54.5974
3533.45	31.4839
3537.42	36.84
3541.38	29.3089
3545.34	50.193
3549.29	45.1071
3553.25	24.2186
3557.2	16.3824
3561.15	37.2434
3565.09	42.5732
3569.04	34.979
3572.98	50.8932
3576.92	43.3186
3580.85	33.1541
3584.79	28.2554
3588.72	28.6181
3592.64	21.0057
3596.57	45.3245
3600.49	26.9783
3604.41	11.1972
3608.33	27.5051
3612.25	22.3259
3616.16	33.2989
3620.07	14.5742
3623.98	25.3761
3627.88	14.5125
3631.79	19.8266
3635.69	14.3488
3639.58	3.54523
3643.48	30.8355
3647.37	17.496
3651.26	22.8954
3655.15	6.57323
3659.03	3.84035
3662.92	25.6494
3666.8	31.1404
3670.67	25.713
3674.55	1.14197
3678.42	23.2237
3682.29	20.7285
3686.16	4.52654
3690.02	-3.44827
3693.89	24.5603
3697.75	24.897
3701.61	22.4747
3705.46	-2.33517
3709.31	11.9822
3713.16	23.5567
3717.01	15.4043
3720.86	24.1048
3724.7	10.1861
3728.54	13.1855
3732.38	16.2227
3736.21	-6.30229
3740.04	5.24321
3743.87	11.0974
3747.7	25.5137
3751.53	2.73904
3755.35	22.8059
3759.17	25.6702
3762.99	2.72423
3766.81	31.3538
3770.62	22.7848
3774.43	22.8425
3778.24	5.67047
3782.04	28.8121
3785.85	14.6029
3789.65	-5.45464
3793.45	14.9212
3797.24	32.5488
3801.04	21.2483
3804.83	21.5622
3808.62	30.651
3812.4	25.1335
3816.19	16.6447
3819.97	19.8484
3823.75	8.33965
3827.52	23.2445
3831.3	26.4605
3835.07	9.02138
3838.84	26.9901
3842.61	18.4122
3846.37	27.4701
3850.13	21.591
3853.89	3.79993
3857.65	3.80138
3861.41	-14.0688
3865.16	-2.06244
3868.91	10.222
3872.66	28.2885
3876.4	19.4047
3880.14	22.474
3883.89	22.5814
3887.62	25.7237
3891.36	16.9134
3895.09	26.2266
3898.82	2.43629
3902.55	26.7913
3906.28	11.9697
3910	6.16454
3913.73	18.5639
3917.45	24.9908
3921.16	19.3666
3924.88	35.0535
3928.59	1.90997
3932.3	2.24976
3936.01	-3.60495
3939.71	18.1579
3943.42	0.119385
3947.12	9.72005
3950.81	10.0581
3954.51	19.6237
3958.2	19.9042
3961.9	10.8287
3965.58	7.92227
3969.27	14.2495
3972.96	17.4943
3976.64	5.24516
3980.32	2.2614
3984	5.45314
3987.67	2.45734
3991.34	27.4205
3995.01	21.4498
3998.68	3.12521