File: Data/3-Raman/processed/bu04w-a-ff3-fi01-v_150 (500nm)_633nm_edge_100%_x100_vis_lwd_h100um_45sx2_01.txt
#Acq. time (s)=	45
#Accumulations=	2
#Range (cm-¹)=	100...4000
#Windows=	1
#Auto scanning=	Off
#Autofocus=	Off
#Macrospot=	Off
#AutoExposure=	Off
#Spike filter=	Multiple accum.
#Delay time (s)=	2
#Binning=	1
#Readout mode=	Signal
#DeNoise=	Off
#ICS correction=	On
#Dark correction=	Off
#Inst. Process=	Off
#Detector Gain=	Best Dynamic
#Detector ADC=	50 kHz HS
#Detector temperature (°C)=	-60.09
#Instrument=	LabRAM HR Evol
#Detector=	SIN-EM FIVIS
#Objective=	x100_VIS_LWD
#Grating=	150 (500nm)
#ND Filter=	100%
#Laser=	633nm_Edge
#Hole=	100.021
#Temperature=	0
#Range=	Visible
#StageXY=	75x50mm Scan+
#StageZ=	Z motor
#X (µm)=	0
#Y (µm)=	0
#Z (µm)=	14.3
#Full time(mm:ss)=	1:35
#Project=	21_11_22
#Sample=	BU04w
#Site=
#Title=	BU04w-A-FF3-V_150 (500nm)_633nm_Edge_100%_x100_VIS_LWD_H100um_45sX2
#Remark=
#Date=	22.11.2021 10:40
#Acquired=	22.11.2021 10:40:14
#Base:Fit=	16.12.2021 16:15:35
#Base:Edit=	16.12.2021 16:21:33
#Base:Edit=	16.12.2021 16:21:33
#Base:Edit=	16.12.2021 16:21:35
#Base:Sub=	16.12.2021 16:21:39
100.177	704.896
106.695	588.562
113.209	556.648
119.717	460.64
126.219	422.978
132.716	418.822
139.208	371.369
145.694	345.204
152.175	301.086
158.651	326.314
165.121	343.121
171.586	312.755
178.045	165.983
184.5	131.953
190.947	97.5968
197.39	29.026
203.829	57.6896
210.262	26.2548
216.688	1.50482
223.11	29.1103
229.527	89.498
235.939	192.613
242.344	190.156
248.745	79.859
255.141	48.1138
261.53	33.5325
267.916	20.8538
274.294	20.532
280.669	17.2572
287.038	60.1463
293.402	28.7993
299.76	9.67545
306.114	-0.140503
312.461	33.4258
318.805	148.024
325.142	351.354
331.475	500.761
337.802	325.531
344.123	162.485
350.441	84.0983
356.752	82.7237
363.058	97.1189
369.36	116.025
375.656	100.94
381.947	66.087
388.232	48.48
394.512	57.4907
400.789	72.4909
407.059	97.733
413.324	99.1929
419.584	139.997
425.839	198.087
432.089	286.674
438.333	294.553
444.573	268.375
450.807	206.365
457.037	233.506
463.261	179.801
469.48	135.888
475.695	113.677
481.904	114.83
488.108	113.945
494.307	127.928
500.502	130.605
506.691	164.091
512.874	180.794
519.053	210.689
525.227	179.16
531.396	152.378
537.559	164.136
543.718	115.17
549.873	138.14
556.022	122.279
562.165	97.1152
568.304	94.1393
574.437	83.1978
580.567	82.3664
586.691	62.1447
592.81	91.7105
598.924	119.679
605.033	142.796
611.138	130.65
617.236	96.262
623.332	112.544
629.42	95.7842
635.506	93.2224
641.585	92.7977
647.659	86.2967
653.73	101.253
659.794	106.498
665.854	114.511
671.91	98.5288
677.96	55.3908
684.005	37.4218
690.045	37.5103
696.082	40.6349
702.113	37.1345
708.139	38.1627
714.16	41.3863
720.176	24.6853
726.187	14.508
732.194	18.1029
738.196	35.688
744.193	16.8315
750.185	9.33963
756.173	13.2492
762.155	19.5593
768.133	31.0052
774.107	16.3022
780.075	16.3971
786.039	-0.731201
791.998	16.8468
797.952	8.75546
803.902	10.7641
809.845	23.9311
815.786	3.94754
821.721	17.6796
827.652	20.0687
833.576	23.8311
839.498	28.1299
845.415	8.47061
851.327	23.5402
857.233	15.2801
863.135	9.88608
869.032	38.5285
874.925	49.0044
880.813	52.5804
886.697	18.0077
892.576	15.4965
898.45	40.2617
904.318	14.4652
910.184	22.6819
916.044	26.1794
921.9	32.9041
927.75	51.3083
933.596	61.6911
939.439	94.4143
945.275	153.169
951.107	200.182
956.936	229.209
962.759	213.062
968.577	160.04
974.391	194.793
980.201	216.375
986.006	308.361
991.806	376.934
997.602	346.892
1003.39	278.145
1009.18	251.924
1014.96	252.227
1020.74	318.455
1026.51	386.52
1032.28	333.323
1038.04	225.258
1043.8	139.724
1049.56	99.1052
1055.31	73.5165
1061.05	66.0301
1066.8	48.4187
1072.53	67.6505
1078.26	73.1531
1083.99	100.87
1089.72	124.768
1095.44	197.09
1101.15	273.166
1106.86	252.031
1112.56	141.983
1118.27	72.3438
1123.96	57.5264
1129.65	54.3352
1135.34	70.7497
1141.03	107.855
1146.7	158.577
1152.38	238.847
1158.05	294.941
1163.71	199.775
1169.37	80.2388
1175.03	47.2974
1180.68	36.0105
1186.33	23.0968
1191.98	26.0866
1197.61	22.5422
1203.25	13.4718
1208.88	24.232
1214.51	33.1805
1220.13	17.5506
1225.74	1.81648
1231.36	9.89151
1236.97	19.8435
1242.57	7.38284
1248.17	19.8275
1253.77	2.76605
1259.36	31.8842
1264.94	21.4087
1270.53	39.1375
1276.11	57.6437
1281.68	94.0734
1287.25	26.4405
1292.81	27.1167
1298.38	30.9958
1303.93	28.0488
1309.48	9.38826
1315.03	21.0714
1320.58	11.7186
1326.12	17.571
1331.65	19.433
1337.18	19.1245
1342.71	9.43262
1348.23	16.9265
1353.75	28.4709
1359.26	20.3666
1364.77	28.5155
1370.28	40.6121
1375.78	77.3175
1381.28	145.799
1386.77	125.934
1392.26	35.3689
1397.74	28.2275
1403.23	24.1991
1408.7	33.607
1414.17	9.04712
1419.64	8.22456
1425.11	18.8418
1430.56	24.3173
1436.02	21.451
1441.47	30.0176
1446.92	12.4478
1452.36	23.9508
1457.8	26.905
1463.23	20.2606
1468.66	5.12582
1474.09	20.4377
1479.51	25.3474
1484.93	24.0025
1490.34	21.701
1495.75	30.0357
1501.16	25.7967
1506.56	16.3083
1511.96	23.8195
1517.35	13.3565
1522.74	15.6647
1528.13	24.4262
1533.51	19.3223
1538.88	26.9618
1544.25	24.7332
1549.62	21.0399
1554.99	24.6158
1560.35	28.083
1565.71	24.0365
1571.06	28.5886
1576.41	34.2397
1581.75	35.7633
1587.09	47.0295
1592.43	28.2119
1597.76	23.4874
1603.09	28.5469
1608.41	37.0016
1613.73	43.506
1619.05	41.4628
1624.36	30.6453
1629.67	46.0845
1634.97	48.289
1640.27	39.0908
1645.57	49.7313
1650.86	52.5671
1656.15	40.9038
1661.43	37.9765
1666.71	53.8513
1671.99	45.2905
1677.26	38.8992
1682.53	33.5719
1687.79	32.5544
1693.05	28.291
1698.31	28.6556
1703.56	21.9446
1708.81	26.4279
1714.06	33.0558
1719.3	28.3026
1724.53	22.1361
1729.77	30.6424
1735	16.679
1740.22	18.4022
1745.44	14.481
1750.66	24.0198
1755.87	22.1939
1761.08	13.4387
1766.29	20.5198
1771.49	9.51051
1776.69	15.5359
1781.88	21.683
1787.07	13.1173
1792.26	10.3094
1797.44	22.3644
1802.62	3.61052
1807.79	14.6152
1812.96	19.8141
1818.13	12.3471
1823.29	23.3443
1828.45	19.3416
1833.61	17.6644
1838.76	0.826981
1843.91	18.8354
1849.05	12.3216
1854.19	6.89607
1859.33	16.7553
1864.46	5.56332
1869.59	23.7749
1874.71	8.91927
1879.83	-3.64796
1884.95	28.6249
1890.06	7.66237
1895.17	13.78
1900.28	11.7069
1905.38	1.56325
1910.48	15.2244
1915.57	7.69453
1920.66	15.3495
1925.75	14.7042
1930.83	8.08096
1935.91	6.20845
1940.99	7.88229
1946.06	3.48717
1951.13	13.4837
1956.19	8.96727
1961.26	6.83029
1966.31	17.9205
1971.36	10.8475
1976.41	15.8053
1981.46	-3.30734
1986.5	4.07561
1991.54	1.86038
1996.58	2.08156
2001.61	8.36354
2006.63	9.90404
2011.66	10.3
2016.68	11.9149
2021.69	18.3147
2026.71	10.3562
2031.72	9.70277
2036.72	13.9509
2041.72	8.52159
2046.72	21.3369
2051.71	8.63127
2056.71	11.6521
2061.69	22.1281
2066.68	14.2711
2071.66	28.4674
2076.63	20.5563
2081.6	3.94734
2086.57	16.8749
2091.54	26.122
2096.5	13.2122
2101.46	23.8938
2106.41	-2.70679
2111.36	21.819
2116.31	18.9627
2121.25	9.79836
2126.19	4.33878
2131.13	20.3105
2136.06	9.69563
2140.99	12.9703
2145.92	11.1384
2150.84	6.67166
2155.76	20.0099
2160.67	19.267
2165.58	9.50771
2170.49	12.5035
2175.39	28.3775
2180.29	14.7524
2185.19	16.4067
2190.08	4.02759
2194.98	14.7576
2199.86	16.6203
2204.74	17.2787
2209.62	3.84825
2214.5	18.775
2219.37	11.8448
2224.24	10.0708
2229.11	17.3807
2233.97	16.9091
2238.83	28.1847
2243.68	25.112
2248.53	22.0302
2253.38	13.6497
2258.22	3.91891
2263.06	13.9588
2267.9	19.9902
2272.73	19.3364
2277.56	15.9655
2282.39	13.8484
2287.21	18.301
2292.03	20.0924
2296.85	9.91029
2301.66	21.1052
2306.47	21.7422
2311.28	26.4758
2316.08	-2.20506
2320.88	26.7587
2325.68	32.9823
2330.47	29.8095
2335.26	18.5376
2340.04	22.1485
2344.82	20.3672
2349.6	21.3385
2354.38	30.4957
2359.15	23.08
2363.92	15.4977
2368.68	17.593
2373.44	12.7447
2378.2	21.742
2382.95	30.6723
2387.71	21.452
2392.45	20.4995
2397.2	16.7035
2401.94	28.1949
2406.68	11.8088
2411.41	27.6223
2416.14	14.4975
2420.87	18.3607
2425.59	18.9025
2430.31	15.3682
2435.03	20.3382
2439.75	9.76474
2444.46	27.5528
2449.16	15.4854
2453.87	30.5139
2458.57	22.6556
2463.27	11.8608
2467.96	22.6221
2472.65	14.5908
2477.34	29.7299
2482.02	17.2916
2486.7	10.5651
2491.38	21.307
2496.05	23.3112
2500.72	28.2225
2505.39	18.4269
2510.06	32.0982
2514.72	31.0264
2519.37	21.1014
2524.03	20.0418
2528.68	24.8702
2533.33	20.8324
2537.97	16.8103
2542.61	27.6618
2547.25	23.6577
2551.88	36.068
2556.51	20.0301
2561.14	27.9266
2565.77	25.3748
2570.39	16.8
2575.01	17.2435
2579.62	19.1466
2584.23	34.6202
2588.84	28.7792
2593.45	13.7296
2598.05	23.1155
2602.65	21.8115
2607.24	31.1565
2611.84	28.2389
2616.42	17.6416
2621.01	29.9989
2625.59	22.4652
2630.17	11.8931
2634.75	33.6866
2639.32	10.9648
2643.89	23.7033
2648.46	14.7825
2653.02	26.0321
2657.58	15.2966
2662.14	24.7909
2666.69	13.8957
2671.24	35.9639
2675.79	22.1309
2680.33	17.9663
2684.88	8.93197
2689.41	12.5551
2693.95	17.6972
2698.48	20.9403
2703.01	1.77946
2707.53	21.1281
2712.06	21.1625
2716.57	24.4944
2721.09	11.5915
2725.6	9.93731
2730.11	21.2085
2734.62	24.3141
2739.12	22.5083
2743.62	24.0315
2748.12	12.5598
2752.61	6.11115
2757.1	-0.44873
2761.59	25.6733
2766.08	7.55646
2770.56	5.82994
2775.04	20.6448
2779.51	12.4297
2783.98	15.8787
2788.45	16.0075
2792.92	14.429
2797.38	12.7821
2801.84	14.4364
2806.3	10.9829
2810.75	5.78961
2815.2	22.5013
2819.65	5.39171
2824.09	1.80576
2828.53	6.69432
2832.97	13.2715
2837.41	1.11169
2841.84	17.9162
2846.27	17.7196
2850.69	5.56886
2855.12	5.44594
2859.54	13.9309
2863.95	-1.63785
2868.37	20.8111
2872.78	6.93036
2877.18	-3.54562
2881.59	19.1351
2885.99	3.43452
2890.39	21.0251
2894.78	15.7628
2899.18	8.76384
2903.57	21.2093
2907.95	10.4918
2912.34	6.79597
2916.72	13.7758
2921.09	8.2576
2925.47	-0.864594
2929.84	-0.965057
2934.21	0.725769
2938.57	5.9628
2942.94	11.1774
2947.29	12.7087
2951.65	1.47137
2956	8.46381
2960.36	2.67006
2964.7	0.547104
2969.05	14.9709
2973.39	11.077
2977.73	16.3846
2982.06	1.42975
2986.4	3.13354
2990.73	10.455
2995.05	12.2609
2999.38	1.05968
3003.7	1.06129
3008.01	6.71892
3012.33	10.482
3016.64	-0.789322
3020.95	22.0586
3025.26	14.5233
3029.56	24.0335
3033.86	8.65602
3038.16	6.54823
3042.45	37.1765
3046.74	33.2067
3051.03	11.8634
3055.32	25.2264
3059.6	17.3695
3063.88	46.3064
3068.16	26.8152
3072.43	34.4905
3076.7	40.2724
3080.97	42.1827
3085.24	40.2371
3089.5	52.1091
3093.76	42.5199
3098.02	50.7057
3102.27	62.9206
3106.52	53.4503
3110.77	75.8789
3115.01	98.5035
3119.26	85.1298
3123.5	75.7697
3127.73	88.704
3131.97	87.5954
3136.2	109.01
3140.43	99.6986
3144.65	112.939
3148.87	128.293
3153.09	124.838
3157.31	133.809
3161.52	119.807
3165.73	145.597
3169.94	158.803
3174.15	148.961
3178.35	195.884
3182.55	175.062
3186.75	183.805
3190.94	179.785
3195.13	197.247
3199.32	202.331
3203.51	222.815
3207.69	222.083
3211.87	204.157
3216.05	214.363
3220.22	213.685
3224.39	199.877
3228.56	225.441
3232.73	213.746
3236.89	217.266
3241.05	207.7
3245.21	227.184
3249.36	177.282
3253.52	198.472
3257.66	183.62
3261.81	189.365
3265.95	197.63
3270.1	208.476
3274.23	210.147
3278.37	213.287
3282.5	179.807
3286.63	205.912
3290.76	202.183
3294.88	214.528
3299	194.604
3303.12	190.923
3307.24	196.478
3311.35	195.036
3315.46	193.591
3319.57	224.835
3323.68	214.325
3327.78	210.896
3331.88	207.646
3335.98	216.365
3340.07	222.582
3344.16	226.12
3348.25	210.499
3352.34	221.057
3356.42	243.642
3360.5	252.089
3364.58	241.427
3368.66	235.469
3372.73	241.49
3376.8	244.961
3380.87	231.484
3384.93	246.92
3388.99	269.612
3393.05	246.309
3397.11	264.314
3401.16	258.103
3405.21	271.121
3409.26	269.604
3413.31	255.819
3417.35	283.459
3421.39	276.99
3425.43	275.381
3429.46	266.607
3433.5	282.377
3437.53	256.694
3441.55	262.907
3445.58	281.591
3449.6	275.886
3453.62	285.03
3457.64	252.324
3461.65	244.388
3465.66	301.331
3469.67	270.937
3473.68	262.656
3477.68	236.829
3481.68	253.786
3485.68	253.045
3489.67	231.912
3493.67	253.952
3497.66	222.306
3501.64	226.256
3505.63	217.267
3509.61	228.574
3513.59	211.489
3517.57	194.36
3521.54	200.344
3525.52	183.219
3529.49	184.06
3533.45	164.544
3537.42	173.591
3541.38	172.374
3545.34	170.99
3549.29	164.31
3553.25	146.912
3557.2	137.407
3561.15	135.788
3565.09	139.467
3569.04	117.187
3572.98	139.29
3576.92	116.94
3580.85	141.972
3584.79	109.09
3588.72	113.078
3592.64	117.068
3596.57	89.0957
3600.49	95.6266
3604.41	80.7294
3608.33	92.5321
3612.25	82.8084
3616.16	75.7315
3620.07	82.0728
3623.98	63.9125
3627.88	70.0001
3631.79	48.9813
3635.69	46.91
3639.58	36.7992
3643.48	37.6248
3647.37	49.3884
3651.26	41.8326
3655.15	26.1437
3659.03	43.1303
3662.92	40.9984
3666.8	33.4215
3670.67	28.5624
3674.55	34.6664
3678.42	7.93872
3682.29	33.3895
3686.16	1.13338
3690.02	15.6994
3693.89	16.462
3697.75	6.07549
3701.61	-1.57608
3705.46	15.8484
3709.31	10.9676
3713.16	-2.3931
3717.01	12.2777
3720.86	4.39296
3724.7	-0.733971
3728.54	5.41868
3732.38	14.4364
3736.21	0.741081
3740.04	4.05391
3743.87	7.34636
3747.7	4.90525
3751.53	-0.447296
3755.35	-0.130867
3759.17	-5.5834
3762.99	0.395454
3766.81	9.23275
3770.62	9.50443
3774.43	4.04188
3778.24	-1.43044
3782.04	1.75128
3785.85	13.6141
3789.65	11.0478
3793.45	8.48186
3797.24	-2.73521
3801.04	0.522652
3804.83	9.623
3808.62	7.11549
3812.4	13.3332
3816.19	-12.6439
3819.97	19.9342
3823.75	-0.28344
3827.52	-5.87732
3831.3	3.28268
3835.07	9.52955
3838.84	-7.8945
3842.61	1.34058
3846.37	10.5181
3850.13	4.80096
3853.89	-6.87115
3857.65	11.163
3861.41	8.3788
3865.16	-6.1916
3868.91	3.21841
3872.66	3.56101
3876.4	6.85548
3880.14	1.20226
3883.89	1.55983
3887.62	-7.02435
3891.36	5.40379
3895.09	-0.052742
3898.82	6.50713
3902.55	-13.9998
3906.28	-4.37585
3910	-9.80701
3913.73	-0.0534744
3917.45	0.699211
3921.16	10.6564
3924.88	-3.67413
3928.59	0.270782
3932.3	-7.98764
3936.01	8.2441
3939.71	9.23989
3943.42	13.4225
3947.12	11.4992
3950.81	9.59846
3954.51	7.72231
3958.2	-0.301147
3961.9	-11.4073
3965.58	14.7127
3969.27	12.9973
3972.96	11.3653
3976.64	22.2224
3980.32	11.4326
3984	13.1186
3987.67	24.2075
3991.34	29.2181
3995.01	21.9645
3998.68	24.1621