File: Data/3-Raman/processed/bu04w-a-ff3-fi10-l_150 (500nm)_633nm_edge_100%_x100_vis_lwd_h50um_45sx2_01.txt
#Acq. time (s)=	45
#Accumulations=	2
#Range (cm-¹)=	100...4000
#Windows=	1
#Auto scanning=	Off
#Autofocus=	Off
#Macrospot=	Off
#AutoExposure=	Off
#Spike filter=	Multiple accum.
#Delay time (s)=	2
#Binning=	1
#Readout mode=	Signal
#DeNoise=	Off
#ICS correction=	On
#Dark correction=	Off
#Inst. Process=	Off
#Detector Gain=	Best Dynamic
#Detector ADC=	50 kHz EM
#Detector EM gain=	100
#Detector temperature (°C)=	-60.09
#Instrument=	LabRAM HR Evol
#Detector=	SIN-EM FIVIS
#Objective=	x100_VIS_LWD
#Grating=	150 (500nm)
#ND Filter=	100%
#Laser=	633nm_Edge
#Hole=	49.98
#Temperature=	0
#Range=	Visible
#StageXY=	75x50mm Scan+
#StageZ=	Z motor
#X (µm)=	0
#Y (µm)=	0
#Z (µm)=	4.3
#Full time(mm:ss)=	1:34
#Project=	21_11_22
#Sample=	BU04w
#Site=
#Title=	BU04w-A-FF3-FI10-L_150 (500nm)_633nm_Edge_100%_x100_VIS_LWD_H50um_45sX2
#Remark=
#Date=	22.11.2021 11:48
#Acquired=	22.11.2021 11:48:48
#Base:Fit=	16.12.2021 16:15:35
#Base:Edit=	16.12.2021 16:24:58
#Base:Sub=	16.12.2021 16:25:00
100.177	1014.93
106.695	876.436
113.209	827.249
119.717	775.892
126.219	699.621
132.716	674.779
139.208	736.359
145.694	663.091
152.175	554.428
158.651	695.984
165.121	1058.05
171.586	601.775
178.045	295.741
184.5	169.882
190.947	98.6608
197.39	47.2751
203.829	30.0247
210.262	-2.9649
216.688	17.8593
223.11	75.1171
229.527	304.112
235.939	838.318
242.344	557.836
248.745	150.69
255.141	112.893
261.53	136.258
267.916	49.8826
274.294	60.6049
280.669	141.583
287.038	204.241
293.402	96.0121
299.76	63.6754
306.114	94.6428
312.461	198.359
318.805	612.494
325.142	1634.46
331.475	1739.22
337.802	859.258
344.123	385.036
350.441	235.001
356.752	241.061
363.058	297.643
369.36	269.388
375.656	226.968
381.947	105.807
388.232	94.272
394.512	68.4749
400.789	135.455
407.059	203.425
413.324	243.884
419.584	360.454
425.839	588.38
432.089	888.209
438.333	910.276
444.573	550.51
450.807	500.196
457.037	553.137
463.261	485.529
469.48	260.517
475.695	190.862
481.904	220.14
488.108	221.197
494.307	239.925
500.502	361.014
506.691	457.128
512.874	577.637
519.053	535.116
525.227	436.923
531.396	452.262
537.559	390.82
543.718	324.44
549.873	277.459
556.022	245.23
562.165	230.377
568.304	192.979
574.437	125.784
580.567	103.489
586.691	165.704
592.81	190.019
598.924	273.582
605.033	325.011
611.138	243.307
617.236	247.016
623.332	215.257
629.42	195.266
635.506	154.789
641.585	135.706
647.659	180.84
653.73	236.751
659.794	252.524
665.854	210.276
671.91	146.315
677.96	51.1273
684.005	37.9555
690.045	72.9423
696.082	33.5161
702.113	31.3051
708.139	38.1928
714.16	61.8828
720.176	40.1005
726.187	13.5038
732.194	2.34912
738.196	13.6073
744.193	17.3806
750.185	10.1225
756.173	13.4472
762.155	30.7108
768.133	39.3972
774.107	2.22321
780.075	17.2097
786.039	-1.20087
791.998	9.29993
797.952	-4.17072
803.902	12.9867
809.845	25.1431
815.786	1.15338
821.721	14.5316
827.652	25.8542
833.576	66.8292
839.498	42.3627
845.415	48.4303
851.327	68.7224
857.233	54.4929
863.135	48.7984
869.032	74.2807
874.925	115.458
880.813	140.069
886.697	114.969
892.576	114.116
898.45	97.6544
904.318	105.116
910.184	97.3089
916.044	103.67
921.9	137.099
927.75	224.842
933.596	253.388
939.439	387.117
945.275	596.159
951.107	799.604
956.936	766.404
962.759	717.655
968.577	599.677
974.391	635.88
980.201	858.422
986.006	1200.95
991.806	1292.21
997.602	1045.03
1003.39	934.742
1009.18	790.554
1014.96	857.12
1020.74	1183.63
1026.51	1342.7
1032.28	927.559
1038.04	564.656
1043.8	394.583
1049.56	336.593
1055.31	282.5
1061.05	245.091
1066.8	184.395
1072.53	192.516
1078.26	277.987
1083.99	379.613
1089.72	476.454
1095.44	848.227
1101.15	1030.77
1106.86	673.825
1112.56	385.733
1118.27	259.016
1123.96	212.709
1129.65	203.241
1135.34	272.143
1141.03	355.122
1146.7	554.749
1152.38	1096.24
1158.05	1101.75
1163.71	479.798
1169.37	238.312
1175.03	157.278
1180.68	117.652
1186.33	92.4207
1191.98	59.9542
1197.61	56.4081
1203.25	41.8243
1208.88	31.5025
1214.51	29.1733
1220.13	39.0396
1225.74	2.21805
1231.36	30.0148
1236.97	59.6595
1242.57	46.5509
1248.17	40.8601
1253.77	33.6954
1259.36	41.1037
1264.94	57.1734
1270.53	31.8761
1276.11	31.4852
1281.68	13.9797
1287.25	43.8165
1292.81	20.8666
1298.38	1.3403
1303.93	21.1139
1309.48	14.4975
1315.03	40.6101
1320.58	14.6056
1326.12	9.86874
1331.65	11.2572
1337.18	1.17123
1342.71	10.1127
1348.23	6.44016
1353.75	30.3091
1359.26	14.8947
1364.77	45.358
1370.28	79.6054
1375.78	156.904
1381.28	157.094
1386.77	51.5344
1392.26	31.3283
1397.74	44.581
1403.23	10.6571
1408.7	32.3836
1414.17	9.93787
1419.64	16.4762
1425.11	9.65036
1430.56	16.3292
1436.02	10.4841
1441.47	25.4245
1446.92	19.5241
1452.36	12.0526
1457.8	-16.7811
1463.23	27.5878
1468.66	36.0634
1474.09	13.0613
1479.51	0.763031
1484.93	16.911
1490.34	28.0381
1495.75	28.9123
1501.16	18.318
1506.56	33.1955
1511.96	13.3379
1517.35	39.27
1522.74	9.94635
1528.13	28.6635
1533.51	22.9095
1538.88	43.7308
1544.25	27.5182
1549.62	21.2599
1554.99	27.3219
1560.35	30.9926
1565.71	52.0115
1571.06	44.9128
1576.41	47.5909
1581.75	29.1496
1587.09	68.9622
1592.43	45.4127
1597.76	54.4288
1603.09	44.206
1608.41	52.6541
1613.73	52.8656
1619.05	75.1851
1624.36	65.9406
1629.67	45.5807
1634.97	53.5002
1640.27	68.3944
1645.57	78.8311
1650.86	99.0826
1656.15	69.282
1661.43	72.4338
1666.71	72.1476
1671.99	50.7033
1677.26	46.8963
1682.53	49.6365
1687.79	53.1848
1693.05	24.8033
1698.31	42.2831
1703.56	48.1836
1708.81	26.4376
1714.06	44.166
1719.3	24.9269
1724.53	55.3676
1729.77	17.748
1735	9.17523
1740.22	18.5266
1745.44	39.1882
1750.66	42.7311
1755.87	25.7354
1761.08	16.3142
1766.29	57.8211
1771.49	-0.265076
1776.69	6.30899
1781.88	44.9647
1787.07	4.25348
1792.26	21.7608
1797.44	27.9691
1802.62	17.2049
1807.79	37.3674
1812.96	4.38834
1818.13	28.9922
1823.29	23.6087
1828.45	61.1507
1833.61	19.9061
1838.76	28.5299
1843.91	21.7569
1849.05	28.889
1854.19	22.998
1859.33	33.6675
1864.46	35.1294
1869.59	22.5354
1874.71	16.6505
1879.83	22.4631
1884.95	5.7569
1890.06	8.90109
1895.17	3.50082
1900.28	18.4251
1905.38	9.11697
1910.48	30.9104
1915.57	23.5352
1920.66	9.32129
1925.75	27.4596
1930.83	18.15
1935.91	27.9362
1940.99	25.574
1946.06	25.4478
1951.13	23.9552
1956.19	31.911
1961.26	30.1417
1966.31	19.8377
1971.36	15.3158
1976.41	15.5576
1981.46	2.56107
1986.5	11.26
1991.54	29.6399
1996.58	21.6485
2001.61	25.8229
2006.63	22.9716
2011.66	17.8702
2016.68	-1.66025
2021.69	29.2916
2026.71	11.1331
2031.72	11.2673
2036.72	1.88611
2041.72	11.9141
2046.72	2.61032
2051.71	26.2035
2056.71	14.2068
2061.69	9.80539
2066.68	33.6134
2071.66	10.7495
2076.63	7.47641
2081.6	-0.833496
2086.57	31.4214
2091.54	9.30997
2096.5	46.9806
2101.46	10.3675
2106.41	31.0178
2111.36	35.6704
2116.31	17.9336
2121.25	37.7984
2126.19	56.4512
2131.13	29.5728
2136.06	26.4899
2140.99	39.7961
2145.92	31.4266
2150.84	10.0244
2155.76	13.9185
2160.67	35.5451
2165.58	21.1951
2170.49	-3.47992
2175.39	34.7574
2180.29	6.24786
2185.19	32.5301
2190.08	24.3999
2194.98	29.278
2199.86	28.049
2204.74	28.3424
2209.62	15.9749
2214.5	42.3914
2219.37	35.4904
2224.24	6.55118
2229.11	22.9405
2233.97	18.5692
2238.83	14.1689
2243.68	21.5286
2248.53	42.0808
2253.38	11.3604
2258.22	41.2185
2263.06	15.6219
2267.9	32.0655
2272.73	-7.40283
2277.56	15.3007
2282.39	33.834
2287.21	22.8472
2292.03	31.808
2296.85	24.8217
2301.66	32.7523
2306.47	21.0006
2311.28	21.5299
2316.08	14.2137
2320.88	15.0676
2325.68	44.2186
2330.47	23.6536
2335.26	39.6981
2340.04	27.3598
2344.82	12.3596
2349.6	46.6262
2354.38	19.1706
2359.15	11.8574
2363.92	41.3203
2368.68	43.4032
2373.44	30.1757
2378.2	41.8451
2382.95	7.3548
2387.71	33.7175
2392.45	37.6129
2397.2	28.779
2401.94	40.7503
2406.68	34.4861
2411.41	21.9453
2416.14	27.3187
2420.87	25.264
2425.59	54.9962
2430.31	41.7542
2435.03	7.41779
2439.75	19.7988
2444.46	17.9737
2449.16	7.59344
2453.87	25.7275
2458.57	3.76099
2463.27	24.8245
2467.96	34.3712
2472.65	43.8416
2477.34	44.6936
2482.02	17.8585
2486.7	27.1347
2491.38	34.8979
2496.05	48.5726
2500.72	43.1335
2505.39	33.1638
2510.06	45.0906
2514.72	56.8936
2519.37	36.3033
2524.03	29.0922
2528.68	35.0942
2533.33	41.1918
2537.97	23.6989
2542.61	35.9598
2547.25	33.4389
2551.88	69.7596
2556.51	26.7167
2561.14	52.5127
2565.77	19.9722
2570.39	44.697
2575.01	31.741
2579.62	26.0929
2584.23	53.4504
2588.84	42.6062
2593.45	19.3203
2598.05	29.9335
2602.65	37.3989
2607.24	37.122
2611.84	41.2516
2616.42	22.3676
2621.01	34.127
2625.59	9.19208
2630.17	30.468
2634.75	23.0613
2639.32	22.259
2643.89	50.8936
2648.46	40.9246
2653.02	37.0528
2657.58	48.0286
2662.14	24.4412
2666.69	31.8439
2671.24	39.6019
2675.79	19.7416
2680.33	32.5587
2684.88	34.13
2689.41	35.675
2693.95	51.1744
2698.48	38.1093
2703.01	38.1953
2707.53	25.2346
2712.06	26.6156
2716.57	46.0775
2721.09	63.7823
2725.6	34.2878
2730.11	27.2093
2734.62	24.7479
2739.12	41.6599
2743.62	29.6555
2748.12	43.8997
2752.61	11.592
2757.1	32.8595
2761.59	20.8835
2766.08	42.0004
2770.56	23.6453
2775.04	33.4962
2779.51	33.7775
2783.98	37.804
2788.45	51.8311
2792.92	34.0471
2797.38	34.3575
2801.84	41.1851
2806.3	29.2581
2810.75	12.0688
2815.2	50.3945
2819.65	27.8363
2824.09	30.7233
2828.53	21.7274
2832.97	17.6975
2837.41	49.3471
2841.84	18.0104
2846.27	32.8506
2850.69	17.0696
2855.12	-3.60034
2859.54	23.8387
2863.95	53.3823
2868.37	21.0215
2872.78	38.732
2877.18	-2.60187
2881.59	39.8017
2885.99	33.5668
2890.39	69.3873
2894.78	54.1617
2899.18	53.3318
2903.57	57.5383
2907.95	43.687
2912.34	45.5352
2916.72	50.7088
2921.09	39.9352
2925.47	36.431
2929.84	47.5533
2934.21	42.3393
2938.57	29.3922
2942.94	14.3746
2947.29	8.16156
2951.65	56.6274
2956	37.6232
2960.36	44.1616
2964.7	38.001
2969.05	20.9718
2973.39	38.8799
2977.73	8.97247
2982.06	10.4078
2986.4	30.6654
2990.73	45.645
2995.05	58.9485
2999.38	63.1926
3003.7	48.9144
3008.01	47.7672
3012.33	68.9973
3016.64	58.5198
3020.95	99.3632
3025.26	43.027
3029.56	92.8544
3033.86	89.0748
3038.16	81.014
3042.45	69.4609
3046.74	115.27
3051.03	82.1385
3055.32	139.72
3059.6	96.9423
3063.88	117.933
3068.16	137.07
3072.43	154.33
3076.7	132.778
3080.97	165.828
3085.24	142.464
3089.5	184.103
3093.76	149.696
3098.02	208.112
3102.27	199.632
3106.52	237.135
3110.77	225.246
3115.01	181.276
3119.26	217.419
3123.5	254.159
3127.73	305.657
3131.97	256.122
3136.2	298.262
3140.43	287.032
3144.65	335.234
3148.87	337.902
3153.09	327.384
3157.31	374.937
3161.52	368.328
3165.73	321.69
3169.94	398.638
3174.15	410.891
3178.35	451.732
3182.55	456.244
3186.75	498.685
3190.94	485.834
3195.13	492.87
3199.32	543.708
3203.51	551.272
3207.69	527.021
3211.87	543.752
3216.05	574.026
3220.22	562.878
3224.39	512.23
3228.56	441.485
3232.73	519.692
3236.89	478.651
3241.05	464.513
3245.21	466.411
3249.36	483.182
3253.52	498.897
3257.66	516.213
3261.81	438.096
3265.95	464.227
3270.1	452.721
3274.23	445.207
3278.37	489.838
3282.5	514.115
3286.63	467.314
3290.76	452.429
3294.88	414.255
3299	424.461
3303.12	465.174
3307.24	450.298
3311.35	439.814
3315.46	443.239
3319.57	393.215
3323.68	472.02
3327.78	455.479
3331.88	411.286
3335.98	412.231
3340.07	403.089
3344.16	461.583
3348.25	510.228
3352.34	537.817
3356.42	508.495
3360.5	512.82
3364.58	521.973
3368.66	490.188
3372.73	472.615
3376.8	529.113
3380.87	484.208
3384.93	451.127
3388.99	526.646
3393.05	490.798
3397.11	440.803
3401.16	521.754
3405.21	483.201
3409.26	571.121
3413.31	469.02
3417.35	537.367
3421.39	498.47
3425.43	508.258
3429.46	435.528
3433.5	578.114
3437.53	491.33
3441.55	475.672
3445.58	566.143
3449.6	489.975
3453.62	522.297
3457.64	498.544
3461.65	435.182
3465.66	408.882
3469.67	472.48
3473.68	450.091
3477.68	448.178
3481.68	468.911
3485.68	487.06
3489.67	436.51
3493.67	395.753
3497.66	430.965
3501.64	386.628
3505.63	428.856
3509.61	383.188
3513.59	385.709
3517.57	357.315
3521.54	416.275
3525.52	297.908
3529.49	364.644
3533.45	370.626
3537.42	354.224
3541.38	325.024
3545.34	315.857
3549.29	290.721
3553.25	274.779
3557.2	256.661
3561.15	262.326
3565.09	276.193
3569.04	306.531
3572.98	247.66
3576.92	233.574
3580.85	256.723
3584.79	293.443
3588.72	264.084
3592.64	191.981
3596.57	220.696
3600.49	241.238
3604.41	162.655
3608.33	185.385
3612.25	167.621
3616.16	174.033
3620.07	182.929
3623.98	161.172
3627.88	155.307
3631.79	124.806
3635.69	137.734
3639.58	118.754
3643.48	146.579
3647.37	109.59
3651.26	114.436
3655.15	108.77
3659.03	124.777
3662.92	126.99
3666.8	85.6835
3670.67	60.7468
3674.55	77.013
3678.42	115.778
3682.29	78.1368
3686.16	35.2612
3690.02	91.7789
3693.89	26.5507
3697.75	2.50006
3701.61	48.0989
3705.46	49.0952
3709.31	53.0896
3713.16	57.0141
3717.01	46.4716
3720.86	89.2458
3724.7	72.5983
3728.54	35.9087
3732.38	19.0744
3736.21	36.3192
3740.04	70.5774
3743.87	33.468
3747.7	56.0684
3751.53	55.5617
3755.35	46.1649
3759.17	39.3449
3762.99	35.2383
3766.81	33.9453
3770.62	58.7663
3774.43	34.937
3778.24	16.8739
3782.04	33.6374
3785.85	21.8866
3789.65	15.6798
3793.45	21.1246
3797.24	29.8962
3801.04	12.6978
3804.83	15.9222
3808.62	-6.94403
3812.4	13.7198
3816.19	5.08087
3819.97	34.498
3823.75	16.8304
3827.52	43.0469
3831.3	22.4672
3835.07	16.6309
3838.84	4.65674
3842.61	34.4987
3846.37	33.9572
3850.13	32.8754
3853.89	22.7784
3857.65	18.4568
3861.41	-9.84875
3865.16	31.1513
3868.91	-0.804871
3872.66	-13.268
3876.4	3.711
3880.14	29.7169
3883.89	-33.8524
3887.62	4.53137
3891.36	-16.7703
3895.09	-16.4053
3898.82	13.866
3902.55	-21.9788
3906.28	-15.7625
3910	-9.53156
3913.73	9.21851
3917.45	19.2422
3921.16	-0.610413
3924.88	10.0054
3928.59	8.29382
3932.3	-27.2512
3936.01	10.2802
3939.71	-16.3594
3943.42	-14.8414
3947.12	-19.5192
3950.81	-36.7092
3954.51	20.0419
3958.2	14.9798
3961.9	-8.96484
3965.58	-1.96185
3969.27	14.0732
3972.96	2.38464
3976.64	18.7509
3980.32	7.09973
3984	7.78876
3987.67	11.7726
3991.34	34.7524
3995.01	17.9596
3998.68	1.69781