File: Data/3-Raman/processed/bu04w-a-ff3-fi04-v_150 (500nm)_633nm_edge_100%_x100_vis_lwd_h50um_45sx2_01.txt
#Acq. time (s)=	45
#Accumulations=	2
#Range (cm-¹)=	100...4000
#Windows=	1
#Auto scanning=	Off
#Autofocus=	Off
#Macrospot=	Off
#AutoExposure=	Off
#Spike filter=	Multiple accum.
#Delay time (s)=	2
#Binning=	1
#Readout mode=	Signal
#DeNoise=	Off
#ICS correction=	On
#Dark correction=	Off
#Inst. Process=	Off
#Detector Gain=	Best Dynamic
#Detector ADC=	50 kHz HS
#Detector temperature (°C)=	-60.09
#Instrument=	LabRAM HR Evol
#Detector=	SIN-EM FIVIS
#Objective=	x100_VIS_LWD
#Grating=	150 (500nm)
#ND Filter=	100%
#Laser=	633nm_Edge
#Hole=	49.98
#Temperature=	0
#Range=	Visible
#StageXY=	75x50mm Scan+
#StageZ=	Z motor
#X (µm)=	0
#Y (µm)=	0
#Z (µm)=	5.7
#Full time(mm:ss)=	1:34
#Project=	21_11_22
#Sample=	BU04w
#Site=
#Title=	BU04w-A-FF3-FI04-V_150 (500nm)_633nm_Edge_100%_x100_VIS_LWD_H50um_45sX2
#Remark=
#Date=	22.11.2021 12:16
#Acquired=	22.11.2021 12:16:11
#Base:Fit=	16.12.2021 16:15:35
#Base:Fit=	16.12.2021 16:22:58
#Base:Sub=	16.12.2021 16:23:01
100.177	219.607
106.695	141.021
113.209	139.833
119.717	82.0966
126.219	115.082
132.716	118.361
139.208	95.5145
145.694	74.6605
152.175	38.5922
158.651	88.0165
165.121	104.069
171.586	32.7018
178.045	8.9021
184.5	-25.8137
190.947	-16.859
197.39	3.58081
203.829	-30.4773
210.262	-12.8859
216.688	-6.67444
223.11	4.27887
229.527	55.6126
235.939	64.2565
242.344	11.3783
248.745	13.3469
255.141	-13.4146
261.53	-13.2982
267.916	-29.0848
274.294	-45.5195
280.669	-30.555
287.038	-23.3414
293.402	-19.1712
299.76	-35.746
306.114	-22.0449
312.461	4.08032
318.805	62.4374
325.142	181.7
331.475	152.092
337.802	33.9608
344.123	-3.8681
350.441	-4.05621
356.752	-25.1274
363.058	-17.0355
369.36	-4.18622
375.656	-29.7681
381.947	-38.2455
388.232	6.81409
394.512	-17.3118
400.789	-13.1333
407.059	-11.6801
413.324	48.2751
419.584	16.3335
425.839	56.1875
432.089	99.3638
438.333	83.8474
444.573	53.3558
450.807	50.8054
457.037	54.2919
463.261	54.1025
469.48	0.853149
475.695	29.5171
481.904	41.021
488.108	1.27368
494.307	54.0563
500.502	61.2776
506.691	56.8059
512.874	61.96
519.053	46.1371
525.227	78.8281
531.396	42.0226
537.559	48.8754
543.718	38.1712
549.873	61.3344
556.022	49.5606
562.165	40.8986
568.304	24.7552
574.437	35.0469
580.567	20.5529
586.691	14.4203
592.81	58.7905
598.924	104.192
605.033	70.5861
611.138	67.4379
617.236	45.5591
623.332	35.383
629.42	50.4488
635.506	20.245
641.585	45.0488
647.659	22.7596
653.73	87.6463
659.794	58.9679
665.854	39.0067
671.91	22.7852
677.96	32.0698
684.005	17.2938
690.045	32.6212
696.082	46.9683
702.113	27.5288
708.139	2.03577
714.16	17.1066
720.176	26.0828
726.187	-9.17017
732.194	6.36078
738.196	21.8622
744.193	18.8399
750.185	-9.81702
756.173	0.514343
762.155	8.85193
768.133	8.32489
774.107	6.16223
780.075	16.6691
786.039	2.88287
791.998	4.68066
797.952	-2.65265
803.902	10.8913
809.845	12.7256
815.786	-0.166016
821.721	-16.1592
827.652	1.46259
833.576	-23.5278
839.498	16.6121
845.415	11.152
851.327	19.0598
857.233	-11.2129
863.135	-7.45532
869.032	-0.832031
874.925	5.96039
880.813	3.44989
886.697	28.8833
892.576	-27.8644
898.45	-16.9017
904.318	8.14661
910.184	-19.9073
916.044	-3.55481
921.9	4.5127
927.75	22.1489
933.596	27.7259
939.439	23.5114
945.275	55.7851
951.107	81.9581
956.936	84.0236
962.759	51.8745
968.577	52.4452
974.391	71.4381
980.201	65.0511
986.006	146.933
991.806	131.655
997.602	97.2869
1003.39	89.2053
1009.18	87.5939
1014.96	92.0548
1020.74	114.685
1026.51	166.155
1032.28	81.9887
1038.04	21.7962
1043.8	31.7084
1049.56	3.72009
1055.31	7.91022
1061.05	-7.0058
1066.8	9.14056
1072.53	-5.97809
1078.26	12.5587
1083.99	34.7433
1089.72	27.0566
1095.44	109.489
1101.15	110.475
1106.86	49.4385
1112.56	13.8434
1118.27	0.417114
1123.96	14.4387
1129.65	11.8364
1135.34	26.9041
1141.03	27.2768
1146.7	62.3798
1152.38	128.797
1158.05	108.493
1163.71	69.3389
1169.37	35.911
1175.03	-2.39014
1180.68	25.9569
1186.33	-8.5061
1191.98	13.3978
1197.61	25.3651
1203.25	17.7783
1208.88	17.5788
1214.51	-19.972
1220.13	9.03052
1225.74	-5.48395
1231.36	3.63599
1236.97	-8.86688
1242.57	2.98138
1248.17	2.9425
1253.77	37.6466
1259.36	42.2363
1264.94	2.88782
1270.53	25.0132
1276.11	119.981
1281.68	88.1011
1287.25	-2.33459
1292.81	-36.1821
1298.38	-3.53815
1303.93	10.5349
1309.48	-10.6071
1315.03	12.1392
1320.58	6.9505
1326.12	14.1232
1331.65	13.2932
1337.18	13.0821
1342.71	-3.97418
1348.23	14.2429
1353.75	11.7785
1359.26	13.0013
1364.77	9.63751
1370.28	12.0213
1375.78	39.9968
1381.28	341.004
1386.77	45.429
1392.26	16.9729
1397.74	23.1554
1403.23	41.8163
1408.7	26.6915
1414.17	3.41907
1419.64	-0.164124
1425.11	8.78229
1430.56	-6.12909
1436.02	2.79065
1441.47	0.139221
1446.92	-17.1566
1452.36	14.1879
1457.8	-24.143
1463.23	-26.1075
1468.66	7.39923
1474.09	-11.5722
1479.51	-21.8984
1484.93	25.6541
1490.34	10.4551
1495.75	-3.43732
1501.16	15.4872
1506.56	-4.48889
1511.96	10.6424
1517.35	22.8533
1522.74	-24.5468
1528.13	-1.54095
1533.51	-4.04559
1538.88	4.88483
1544.25	-19.0104
1549.62	3.72772
1554.99	13.8229
1560.35	16.093
1565.71	-9.56311
1571.06	5.71423
1576.41	-10.1679
1581.75	2.38367
1587.09	16.1439
1592.43	18.2426
1597.76	19.535
1603.09	2.65723
1608.41	3.35324
1613.73	16.4163
1619.05	5.88397
1624.36	8.40277
1629.67	2.07953
1634.97	-7.85156
1640.27	11.1867
1645.57	18.0354
1650.86	-5.17944
1656.15	5.716
1661.43	16.3588
1666.71	-0.828217
1671.99	-10.3359
1677.26	-9.96353
1682.53	-5.25735
1687.79	9.12814
1693.05	17.0288
1698.31	-4.48584
1703.56	23.3412
1708.81	16.9937
1714.06	0.986298
1719.3	2.6843
1724.53	-2.96664
1729.77	8.44858
1735	10.8764
1740.22	-10.4207
1745.44	7.68781
1750.66	8.67178
1755.87	14.0104
1761.08	11.1071
1766.29	-7.68542
1771.49	-1.48486
1776.69	-9.9259
1781.88	2.31296
1787.07	-3.4794
1792.26	-19.3416
1797.44	-0.951294
1802.62	21.1357
1807.79	14.5622
1812.96	0.790863
1818.13	16.9779
1823.29	-2.64984
1828.45	12.4564
1833.61	12.5679
1838.76	6.82596
1843.91	-8.52438
1849.05	2.86258
1854.19	-2.26123
1859.33	10.3266
1864.46	-1.5802
1869.59	-31.1452
1874.71	34.3957
1879.83	12.6832
1884.95	8.56158
1890.06	-1.68433
1895.17	-16.9101
1900.28	4.71176
1905.38	-1.51831
1910.48	-8.74332
1915.57	10.6075
1920.66	-0.52301
1925.75	5.13986
1930.83	-31.0862
1935.91	4.50497
1940.99	2.80634
1946.06	15.401
1951.13	-8.25662
1956.19	1.63843
1961.26	22.3124
1966.31	0.721588
1971.36	-16.2439
1976.41	2.8847
1981.46	-15.3142
1986.5	14.6427
1991.54	-15.4857
1996.58	9.76306
2001.61	-18.9758
2006.63	23.3672
2011.66	-3.91998
2016.68	7.31808
2021.69	-22.5062
2026.71	-12.3444
2031.72	6.46082
2036.72	4.87457
2041.72	-1.5549
2046.72	7.84909
2051.71	11.2187
2056.71	-8.81717
2061.69	4.3132
2066.68	0.349701
2071.66	-1.24753
2076.63	21.753
2081.6	-23.0823
2086.57	0.978485
2091.54	4.05234
2096.5	22.2683
2101.46	-9.07248
2106.41	-5.5993
2111.36	-12.0223
2116.31	-5.86484
2121.25	0.312225
2126.19	1.42078
2131.13	2.44699
2136.06	-14.3827
2140.99	-0.885773
2145.92	-12.8622
2150.84	9.37018
2155.76	-4.21341
2160.67	-0.0565796
2165.58	2.68195
2170.49	14.3128
2175.39	-0.751343
2180.29	4.5025
2185.19	-0.655853
2190.08	-3.15637
2194.98	3.43799
2199.86	-7.72055
2204.74	-2.06577
2209.62	-3.98828
2214.5	1.90524
2219.37	1.45993
2224.24	-8.05173
2229.11	-18.9234
2233.97	7.91702
2238.83	-1.68884
2243.68	-4.80835
2248.53	-21.0631
2253.38	-1.91141
2258.22	-1.1145
2263.06	15.512
2267.9	17.4631
2272.73	-3.2934
2277.56	-12.2654
2282.39	-4.10574
2287.21	-4.08258
2292.03	26.5394
2296.85	1.28525
2301.66	-3.85757
2306.47	8.50259
2311.28	2.36179
2316.08	7.01605
2320.88	21.174
2325.68	16.5548
2330.47	-12.3526
2335.26	-0.719543
2340.04	-3.94302
2344.82	10.6038
2349.6	-8.89429
2354.38	19.4095
2359.15	-6.01416
2363.92	15.0892
2368.68	0.414581
2373.44	0.861053
2378.2	2.6734
2382.95	14.0335
2387.71	-3.95502
2392.45	-5.39609
2397.2	-2.76968
2401.94	-19.6692
2406.68	0.938324
2411.41	-0.367279
2416.14	-3.84827
2420.87	5.75824
2425.59	8.75473
2430.31	2.19788
2435.03	-7.13809
2439.75	9.05032
2444.46	18.1842
2449.16	-2.58786
2453.87	9.39487
2458.57	7.07458
2463.27	11.9181
2467.96	0.857574
2472.65	1.24252
2477.34	4.53946
2482.02	-5.2724
2486.7	12.4581
2491.38	-0.460602
2496.05	11.453
2500.72	2.82718
2505.39	14.682
2510.06	5.90222
2514.72	-1.5079
2519.37	7.29922
2524.03	11.7613
2528.68	10.272
2533.33	-1.5679
2537.97	-13.3896
2542.61	-4.40395
2547.25	18.0722
2551.88	19.7066
2556.51	-8.67424
2561.14	-1.16719
2565.77	-10.09
2570.39	-0.917328
2575.01	9.80325
2579.62	17.4447
2584.23	-2.38403
2588.84	23.202
2593.45	16.7803
2598.05	16.6354
2602.65	5.74963
2607.24	10.0506
2611.84	9.69411
2616.42	7.77237
2621.01	-3.32021
2625.59	13.1782
2630.17	0.649368
2634.75	9.79497
2639.32	-8.59465
2643.89	0.766525
2648.46	5.53294
2653.02	-11.5173
2657.58	2.27904
2662.14	0.404373
2666.69	3.11752
2671.24	-5.01204
2675.79	-20.8082
2680.33	-7.86038
2684.88	-7.59605
2689.41	11.7767
2693.95	3.90688
2698.48	11.5026
2703.01	20.861
2707.53	15.6967
2712.06	-5.66426
2716.57	15.0049
2721.09	4.90942
2725.6	1.17496
2730.11	-1.03444
2734.62	8.03311
2739.12	5.681
2743.62	0.189957
2748.12	2.8998
2752.61	7.5237
2757.1	10.4025
2761.59	9.82076
2766.08	-2.18306
2770.56	7.16342
2775.04	10.0171
2779.51	-15.1502
2783.98	1.16875
2788.45	5.91513
2792.92	7.29247
2797.38	5.23447
2801.84	8.1292
2806.3	0.837433
2810.75	-13.2902
2815.2	-7.25461
2819.65	-14.768
2824.09	-7.02687
2828.53	-0.966049
2832.97	1.67166
2837.41	-17.8547
2841.84	-1.61469
2846.27	-2.36908
2850.69	7.17961
2855.12	6.5731
2859.54	14.5721
2863.95	-15.2684
2868.37	3.21436
2872.78	-5.98979
2877.18	-6.54053
2881.59	-0.0719299
2885.99	2.97214
2890.39	4.22974
2894.78	-15.7248
2899.18	10.327
2903.57	0.908615
2907.95	-1.51573
2912.34	8.46532
2916.72	14.8245
2921.09	15.8751
2925.47	-10.0563
2929.84	12.6818
2934.21	-0.714279
2938.57	7.47704
2942.94	-8.00552
2947.29	5.5276
2951.65	-13.7443
2956	10.7557
2960.36	-6.7554
2964.7	3.18382
2969.05	-8.82907
2973.39	-15.3592
2977.73	13.0848
2982.06	-11.8739
2986.4	5.68727
2990.73	-4.4493
2995.05	3.9817
2999.38	-2.42656
3003.7	2.3932
3008.01	-4.01741
3012.33	-2.99565
3016.64	7.55168
3020.95	-12.1656
3025.26	9.78911
3029.56	3.11815
3033.86	-9.3974
3038.16	-0.977539
3042.45	-2.0482
3046.74	2.56912
3051.03	-2.45534
3055.32	9.89207
3059.6	4.87511
3063.88	3.70262
3068.16	-3.30081
3072.43	1.33597
3076.7	11.8499
3080.97	0.928726
3085.24	5.6461
3089.5	-3.2655
3093.76	9.48715
3098.02	6.58649
3102.27	1.68654
3106.52	-13.1272
3110.77	-0.0980835
3115.01	7.0273
3119.26	6.16483
3123.5	1.30492
3127.73	2.52129
3131.97	16.0357
3136.2	25.5757
3140.43	4.28276
3144.65	11.6548
3148.87	4.51015
3153.09	11.7597
3157.31	8.56024
3161.52	17.8954
3165.73	10.467
3169.94	32.4034
3174.15	10.1828
3178.35	17.2961
3182.55	13.7702
3186.75	22.9174
3190.94	27.8083
3195.13	5.18663
3199.32	23.1265
3203.51	17.8286
3207.69	36.1631
3211.87	28.7858
3216.05	14.9011
3220.22	9.54659
3224.39	10.6807
3228.56	40.3262
3232.73	4.1441
3236.89	14.0005
3241.05	10.704
3245.21	18.5872
3249.36	17.4739
3253.52	0.492554
3257.66	8.04614
3261.81	0.0378876
3265.95	10.1636
3270.1	2.28821
3274.23	-5.72234
3278.37	-4.96817
3282.5	-8.78586
3286.63	17.2345
3290.76	-9.58202
3294.88	-1.94655
3299	-1.21082
3303.12	1.8875
3307.24	-6.61073
3311.35	1.09235
3315.46	-7.46968
3319.57	4.93533
3323.68	-17.5951
3327.78	4.30925
3331.88	-4.13818
3335.98	22.807
3340.07	-6.94197
3344.16	10.4424
3348.25	11.1939
3352.34	26.2449
3356.42	27.0722
3360.5	-3.12282
3364.58	16.8397
3368.66	-3.93541
3372.73	-12.7842
3376.8	2.36417
3380.87	-6.59387
3384.93	-8.34645
3388.99	-2.86491
3393.05	-2.23389
3397.11	-6.39902
3401.16	-10.5773
3405.21	-2.68137
3409.26	2.80432
3413.31	-1.47169
3417.35	-5.74536
3421.39	7.0269
3425.43	-4.58203
3429.46	-1.51256
3433.5	-3.29286
3437.53	-5.04063
3441.55	-6.76958
3445.58	3.83191
3449.6	4.67514
3453.62	-1.88007
3457.64	1.51486
3461.65	7.4527
3465.66	0.949203
3469.67	-15.6395
3473.68	2.75014
3477.68	-13.9912
3481.68	-25.7921
3485.68	-17.4019
3489.67	-1.35779
3493.67	-10.7305
3497.66	7.90071
3501.64	-1.58624
3505.63	6.78967
3509.61	-10.5615
3513.59	5.39278
3517.57	3.36667
3521.54	1.33148
3525.52	14.7456
3529.49	4.98709
3533.45	0.471016
3537.42	-1.39268
3541.38	-3.24569
3545.34	5.20381
3549.29	-4.54785
3553.25	-4.04568
3557.2	6.90895
3561.15	2.29902
3565.09	-15.3316
3569.04	-12.0459
3572.98	4.32445
3576.92	5.05072
3580.85	5.82678
3584.79	11.9111
3588.72	-0.525337
3592.64	5.55109
3596.57	-9.66038
3600.49	-0.949272
3604.41	-0.247414
3608.33	-2.26734
3612.25	-12.3964
3616.16	-11.791
3620.07	-0.411972
3623.98	-2.62318
3627.88	5.94307
3631.79	-4.4548
3635.69	-1.31479
3639.58	-3.52586
3643.48	7.90649
3647.37	-5.06211
3651.26	3.53049
3655.15	-12.3499
3659.03	-3.72697
3662.92	7.61839
3666.8	5.34103
3670.67	-10.6158
3674.55	9.01046
3678.42	12.2938
3682.29	1.89163
3686.16	-0.241112
3690.02	-7.90661
3693.89	-12.8562
3697.75	7.15929
3701.61	-0.577438
3705.46	16.7703
3709.31	-10.5962
3713.16	9.63271
3717.01	-3.88207
3720.86	2.26505
3724.7	11.2355
3728.54	17.3838
3732.38	3.70772
3736.21	7.03655
3740.04	1.81526
3743.87	5.11103
3747.7	-0.173836
3751.53	0.213425
3755.35	-2.29565
3759.17	-7.70341
3762.99	9.791
3766.81	-1.3726
3770.62	4.69489
3774.43	2.17102
3778.24	8.27087
3782.04	14.4234
3785.85	-2.43506
3789.65	6.61336
3793.45	1.2454
3797.24	4.59258
3801.04	-9.44891
3804.83	-8.99395
3808.62	6.05314
3812.4	12.3794
3816.19	-4.70193
3819.97	4.54424
3823.75	19.6827
3827.52	-9.29713
3831.3	5.87796
3835.07	-2.51466
3838.84	-13.9139
3842.61	-4.56838
3846.37	10.6692
3850.13	2.1177
3853.89	14.3511
3857.65	-3.1449
3861.41	9.06583
3865.16	0.563835
3868.91	-7.81679
3872.66	-4.39739
3876.4	-3.99538
3880.14	2.39748
3883.89	-6.14011
3887.62	-2.68285
3891.36	12.8027
3895.09	1.38381
3898.82	7.96725
3902.55	8.56075
3906.28	-8.94936
3910	15.8044
3913.73	7.39149
3917.45	-16.1761
3921.16	2.76121
3924.88	-5.61713
3928.59	-1.82117
3932.3	14.2249
3936.01	-3.40453
3939.71	15.7656
3943.42	10.4791
3947.12	2.10006
3950.81	12.2078
3954.51	0.711815
3958.2	10.8541
3961.9	2.42813
3965.58	18.7962
3969.27	1.07909
3972.96	20.5907
3976.64	2.93613
3980.32	0.796562
3984	14.1837
3987.67	9.00584
3991.34	16.2936
3995.01	11.2508
3998.68	15.5941