File: Data/3-Raman/processed/bu04w-a-ff3-fi06-v_1800 (450-850nm)_633nm_edge_100%_x100_vis_lwd_h50um_45sx2_01.txt
#Acq. time (s)=	45
#Accumulations=	2
#Range (cm-¹)=	1200...2380
#Windows=	6
#Auto scanning=	Off
#Autofocus=	Off
#Macrospot=	Off
#AutoExposure=	Off
#Spike filter=	Multiple accum.
#Delay time (s)=	2
#Binning=	1
#Readout mode=	Signal
#DeNoise=	Off
#ICS correction=	On
#Dark correction=	Off
#Inst. Process=	Off
#Detector Gain=	Best Dynamic
#Detector ADC=	50 kHz EM
#Detector EM gain=	100
#Detector temperature (°C)=	-60.09
#Instrument=	LabRAM HR Evol
#Detector=	SIN-EM FIVIS
#Objective=	x100_VIS_LWD
#Grating=	1800 (450-850nm)
#ND Filter=	100%
#Laser=	633nm_Edge
#Hole=	49.98
#Temperature=	0
#Range=	Visible
#StageXY=	75x50mm Scan+
#StageZ=	Z motor
#X (µm)=	0
#Y (µm)=	0
#Z (µm)=	-8.8
#Full time(mm:ss)=	9:33
#Project=	21_11_22
#Sample=	BU04w
#Site=
#Title=	BU04w-A-FF3-FI06-V_1800 (450-850nm)_633nm_Edge_100%_x100_VIS_LWD_H50um_45sX2
#Remark=
#Date=	22.11.2021 11:14
#Acquired=	22.11.2021 11:14:53
#Base:Fit=	16.12.2021 16:15:35
#Base:Fit=	16.12.2021 16:24:05
#Base:Sub=	16.12.2021 16:24:17
1200.03	0.171051
1201.07	1.96484
1202.1	0.95285
1203.13	-0.25354
1204.16	-1.27383
1205.2	1.40472
1206.23	1.86371
1207.26	1.29172
1208.29	-4.82803
1209.32	-0.0811462
1210.35	-0.922455
1211.38	1.48401
1212.41	-2.73068
1213.44	-1.50674
1214.47	5.38895
1215.5	-2.35117
1216.53	0.0448914
1217.56	-1.5708
1218.58	-0.84906
1219.61	0.880554
1220.64	2.58038
1221.67	-1.87848
1222.7	-0.757263
1223.72	1.91687
1224.75	-2.38785
1225.78	-2.9245
1226.8	12.3556
1227.83	-0.784821
1228.85	0.462555
1229.88	-1.97211
1230.91	-0.595245
1231.93	4.41705
1232.96	4.13351
1233.98	2.68283
1235	3.24438
1236.03	7.18784
1237.05	2.59793
1238.07	2.11084
1239.1	1.47305
1240.12	4.19708
1241.14	5.97345
1242.17	0.802124
1243.19	1.07184
1244.21	1.51733
1245.23	3.44318
1246.25	0.38678
1247.27	2.26114
1248.3	4.69089
1249.32	3.69998
1250.34	5.14194
1251.36	10.4132
1252.38	5.90338
1253.4	5.36984
1254.42	5.9201
1255.43	5.43253
1256.45	7.42838
1257.47	6.16394
1258.49	3.5842
1259.51	6.33578
1260.53	6.52032
1261.54	9.01297
1262.56	10.1359
1263.58	10.863
1264.59	10.4434
1265.61	7.65775
1266.63	5.12857
1267.64	5.22113
1268.66	6.00867
1269.67	5.47626
1270.69	7.85675
1271.7	6.56842
1272.72	6.59772
1273.73	6.24683
1274.75	3.56198
1275.76	3.90292
1276.77	5.36285
1277.79	4.29172
1278.8	7.85657
1279.82	3.04605
1280.83	3.89999
1281.84	7.41226
1282.85	9.51682
1283.86	50.9907
1284.88	39.5387
1285.89	3.24142
1286.9	5.76523
1287.91	1.81097
1288.92	0.491455
1289.93	5.18033
1290.94	4.99722
1291.95	2.47336
1292.96	1.19174
1293.97	-0.691406
1294.98	-3.1553
1295.99	-1.06702
1296.99	5.28867
1298	-1.60733
1299.01	-1.68317
1300.02	-0.440399
1301.03	0.299896
1302.03	1.30154
1303.04	0.0374451
1304.05	-1.48294
1305.05	0.61441
1306.06	1.91022
1307.07	-0.374115
1308.07	6.97556
1309.08	-1.38242
1310.08	0.697998
1311.09	-0.43811
1312.09	0.0588379
1313.1	1.96417
1314.1	-1.59467
1315.1	3.64822
1316.11	1.17975
1317.11	-1.63431
1318.12	-0.271362
1319.12	1.70386
1320.12	1.10422
1321.12	3.79901
1322.12	1.31839
1323.13	2.76019
1324.13	-1.08286
1325.13	1.67081
1326.13	0.469574
1327.13	2.85339
1328.13	4.9202
1329.13	0.295197
1330.13	3.39691
1331.13	4.61197
1332.13	3.59381
1333.13	4.92563
1334.13	7.34378
1335.13	7.504
1336.13	1.47275
1337.13	4.77914
1338.12	9.07773
1339.12	4.07059
1340.12	4.59982
1341.12	6.04184
1342.11	2.3793
1343.11	6.47855
1344.11	3.65582
1345.1	3.85754
1346.1	4.98877
1347.09	1.49283
1348.09	5.50092
1349.08	3.31039
1350.08	3.90771
1351.07	6.05212
1352.07	6.3299
1353.06	3.3187
1354.06	3.2114
1355.05	4.60571
1356.04	6.64487
1357.04	4.25696
1358.03	3.86734
1359.02	5.13226
1360.02	9.75772
1361.01	8.06824
1362	9.13882
1362.99	5.04578
1363.98	6.08881
1364.97	5.1785
1365.97	4.53613
1366.95	2.97351
1367.95	5.74954
1368.94	11.8312
1369.93	5.2363
1370.91	7.41699
1371.91	6.63647
1372.89	6.74359
1373.88	5.68445
1374.87	2.1853
1375.86	6.39792
1376.85	8.84326
1377.84	7.03439
1378.82	7.73343
1379.81	3.77292
1380.8	12.6667
1381.78	9.42334
1382.77	4.14441
1383.76	4.56638
1384.74	10.7773
1385.73	15.9572
1386.72	31.8756
1387.7	152.666
1388.68	14.9296
1389.67	6.90985
1390.65	9.19476
1391.64	6.89139
1392.62	4.51889
1393.61	3.75217
1394.59	1.97839
1395.57	7.3616
1396.56	2.89911
1397.54	6.80817
1398.52	4.10898
1399.5	-1.86325
1400.49	1.46213
1401.47	2.61258
1402.45	1.95102
1403.43	5.2352
1404.41	3.38773
1405.39	0.175659
1406.37	6.76086
1407.35	2.88425
1408.33	7.37238
1409.31	5.54031
1410.29	1.99594
1411.27	-0.757629
1412.25	-0.0228882
1413.23	1.77707
1414.21	2.58212
1415.19	-1.88107
1416.16	-0.456482
1417.14	-0.561401
1418.12	1.32895
1419.1	3.54562
1420.07	1.54163
1421.05	3.94122
1422.03	2.2262
1423	0.805695
1423.98	3.20734
1424.95	3.28271
1425.93	7.31778
1426.9	2.27814
1427.88	1.60141
1428.85	3.88297
1429.83	6.33984
1430.8	7.38748
1431.78	2.23694
1432.75	2.4761
1433.72	3.65494
1434.7	2.39166
1435.67	4.36722
1436.64	3.02798
1437.62	0.161255
1438.59	3.17468
1439.56	-1.60181
1440.53	13.8937
1441.5	4.84634
1442.47	-0.00778198
1443.44	0.617828
1444.42	6.56027
1445.39	0.695557
1446.36	3.49564
1447.33	3.23001
1448.29	4.18643
1449.26	7.05862
1450.23	2.87091
1451.2	4.04276
1452.17	2.18243
1453.14	7.09119
1454.11	2.35236
1455.07	0.786377
1456.04	4.58286
1457.01	2.82068
1457.98	3.44327
1458.94	1.80731
1459.91	1.66864
1460.88	2.21631
1461.84	1.56839
1462.81	-1.56863
1463.77	2.22321
1464.74	1.63034
1465.61	0.905609
1466.59	3.20657
1467.57	2.61664
1468.55	3.96561
1469.53	2.23566
1470.51	-1.10083
1471.49	1.83521
1472.47	-1.12149
1473.45	1.27927
1474.43	3.03613
1475.4	2.65204
1476.38	3.03516
1477.36	-0.332764
1478.34	4.10562
1479.32	1.78726
1480.29	0.784668
1481.27	0.072876
1482.25	3.39352
1483.22	0.860748
1484.2	-2.91345
1485.18	-0.27243
1486.15	-0.922913
1487.13	-2.74475
1488.1	-1.1698
1489.08	1.46829
1490.05	-2.64917
1491.03	0.651276
1492	1.56403
1492.98	3.33929
1493.95	-0.408234
1494.92	5.32758
1495.9	2.5517
1496.87	-2.48303
1497.84	-0.194427
1498.82	-0.917969
1499.79	1.33771
1500.76	0.240051
1501.73	0.108521
1502.7	-5.38049
1503.68	-0.444214
1504.65	-2.56332
1505.62	2.4653
1506.59	-0.822723
1507.56	2.0571
1508.53	2.83893
1509.5	-0.17868
1510.47	5.32687
1511.44	3.03018
1512.41	0.886749
1513.38	0.953918
1514.35	0.638947
1515.31	-0.871582
1516.28	5.56384
1517.25	1.77481
1518.22	-2.29483
1519.19	0.746033
1520.15	-0.833649
1521.12	1.11771
1522.09	3.84512
1523.05	2.61536
1524.02	1.92609
1524.99	-0.53363
1525.95	2.98752
1526.92	3.30872
1527.88	7.46753
1528.85	2.82437
1529.81	3.71472
1530.78	0.657379
1531.74	1.98325
1532.71	8.33856
1533.67	4.9198
1534.63	1.05121
1535.6	2.39993
1536.56	0.812256
1537.52	4.48416
1538.49	2.44995
1539.45	1.15775
1540.41	4.46765
1541.37	0.101929
1542.33	4.00131
1543.29	8.3197
1544.26	3.76404
1545.22	3.61301
1546.18	6.13312
1547.14	3.86536
1548.1	4.66638
1549.06	2.05905
1550.02	4.60114
1550.98	6.595
1551.94	2.245
1552.9	1.64835
1553.85	2.9303
1554.81	3.50552
1555.77	4.32074
1556.73	-1.49762
1557.69	1.19427
1558.64	2.74805
1559.6	1.16895
1560.56	2.86526
1561.52	6.85394
1562.47	4.70319
1563.43	8.01013
1564.38	-0.4841
1565.34	3.65631
1566.3	1.29178
1567.25	1.9884
1568.21	-0.773499
1569.16	5.8541
1570.12	8.96722
1571.07	2.19803
1572.02	2.32587
1572.98	1.87018
1573.93	5.48373
1574.89	4.08417
1575.84	3.52579
1576.79	-0.833099
1577.74	8.65149
1578.7	3.2598
1579.65	1.40823
1580.6	2.56683
1581.55	-1.6449
1582.5	-0.210968
1583.46	1.70547
1584.41	-0.45813
1585.36	1.27448
1586.31	2.23529
1587.26	2.67905
1588.21	0.216766
1589.16	3.09033
1590.11	15.8496
1591.06	2.15579
1592.01	-0.950256
1592.95	-0.858002
1593.9	8.12814
1594.85	2.16852
1595.8	-2.93991
1596.75	-1.53061
1597.69	4.65405
1598.64	0.289856
1599.59	-1.21985
1600.54	2.06244
1601.48	-1.39954
1602.43	-0.78714
1603.38	-0.0526733
1604.32	-3.2659
1605.27	1.19244
1606.21	-1.5368
1607.16	-1.07822
1608.1	2.49197
1609.05	0.252686
1609.99	-0.0423889
1610.94	0.664917
1611.88	-0.673431
1612.82	4.78333
1613.77	-1.70419
1614.71	1.94174
1615.65	-0.520935
1616.6	0.45694
1617.54	0.17453
1618.48	12.5222
1619.42	4.26489
1620.36	2.20383
1621.3	4.50586
1622.25	7.29877
1623.19	5.3103
1624.13	6.95206
1625.07	0.543579
1626.01	4.43237
1626.95	0.298248
1627.89	4.11002
1628.83	8.03177
1629.77	0.92514
1630.71	5.26779
1631.65	2.65656
1632.58	1.97186
1633.52	1.77048
1634.46	3.47589
1635.4	4.70099
1636.34	3.57324
1637.27	1.07224
1638.21	1.43338
1639.15	5.57169
1640.09	3.30362
1641.02	4.67203
1641.96	5.39056
1642.89	5.74509
1643.83	4.59232
1644.77	3.97113
1645.7	5.82578
1646.64	8.71481
1647.57	0.629425
1648.51	4.26517
1649.44	7.79175
1650.37	7.82971
1651.31	9.63019
1652.24	3.2406
1653.17	3.88971
1654.11	8.26166
1655.04	4.35275
1655.97	1.54321
1656.91	7.96808
1657.84	7.56076
1658.77	5.04037
1659.7	8.00198
1660.63	6.45358
1661.56	7.79962
1662.49	4.26453
1663.43	6.86307
1664.36	5.05688
1665.29	7.36386
1666.22	4.73578
1667.15	0.590332
1668.07	5.85956
1669.01	7.0563
1669.93	8.14807
1670.86	6.62149
1671.79	5.71909
1672.72	3.76624
1673.65	9.82187
1674.58	7.43512
1675.5	5.42905
1676.43	4.7359
1677.36	1.44257
1678.28	3.81131
1679.21	0.321655
1680.14	1.59866
1681.06	2.05933
1681.99	4.30017
1682.92	4.58798
1683.84	1.05753
1684.77	3.88107
1685.69	-0.0878296
1686.61	9.62234
1687.54	6.73691
1688.46	2.40997
1689.39	2.3942
1690.31	5.50217
1691.24	0.0976257
1692.16	-0.263977
1693.08	0.321136
1694.01	2.67517
1694.93	-0.166473
1695.85	0.733246
1696.77	-1.11307
1697.69	0.375519
1698.61	-1.13776
1699.54	-0.548218
1700.46	-1.20212
1701.38	-0.364014
1702.3	-0.588989
1703.22	-1.54346
1704.11	-1.20691
1705.04	6.918
1705.98	-2.92355
1706.92	-0.661896
1707.85	0.0822754
1708.78	-1.36407
1709.72	-1.00854
1710.65	-2.39807
1711.59	-2.46664
1712.52	-2.15768
1713.45	-2.69232
1714.39	0.521515
1715.32	-2.85739
1716.25	0.189697
1717.19	-0.450226
1718.12	-1.29779
1719.05	4.62921
1719.98	2.42029
1720.91	4.02594
1721.84	1.61111
1722.77	-3.58145
1723.7	-1.04449
1724.64	0.831329
1725.57	0.862335
1726.5	-1.95056
1727.43	1.02652
1728.36	0.727997
1729.29	-1.75052
1730.21	-2.04416
1731.14	-0.400726
1732.07	5.92175
1733	2.26633
1733.93	1.32486
1734.86	-1.12866
1735.78	1.57214
1736.71	5.40576
1737.64	-1.09286
1738.57	3.2753
1739.49	3.95193
1740.42	-0.876007
1741.35	-0.135437
1742.27	2.89813
1743.2	-1.22821
1744.12	-1.46768
1745.05	5.67044
1745.97	3.60483
1746.9	0.493439
1747.82	5.36371
1748.75	7.6041
1749.67	3.25668
1750.6	2.03168
1751.52	-0.394165
1752.44	0.43399
1753.37	2.9559
1754.29	2.07819
1755.21	3.17236
1756.14	0.490509
1757.06	-1.81937
1757.98	-0.476898
1758.9	0.693024
1759.82	0.707367
1760.75	1.72144
1761.67	1.09238
1762.59	-3.64694
1763.51	1.64117
1764.43	1.27579
1765.35	1.19687
1766.27	-0.308502
1767.19	0.154877
1768.11	1.78607
1769.03	-2.15421
1769.95	2.46722
1770.87	1.51208
1771.79	1.89792
1772.7	0.989075
1773.62	0.230682
1774.54	1.31238
1775.46	-1.1416
1776.38	0.605164
1777.29	-0.72995
1778.21	4.78305
1779.13	4.9743
1780.04	1.16925
1780.96	0.533722
1781.88	-0.866547
1782.79	0.778076
1783.71	-1.99847
1784.62	1.19046
1785.54	-3.54288
1786.45	2.07254
1787.37	2.53482
1788.28	-0.90802
1789.2	-0.898834
1790.11	1.63519
1791.02	-1.99103
1791.94	5.03833
1792.85	-0.976013
1793.76	-1.69873
1794.68	-2.74738
1795.59	-0.895844
1796.5	-3.91699
1797.42	-2.63934
1798.33	10.159
1799.24	0.183777
1800.15	-0.300232
1801.06	0.0857849
1801.97	1.23633
1802.88	-0.85321
1803.79	4.75156
1804.71	4.10138
1805.62	2.95303
1806.53	1.3981
1807.44	-4.33713
1808.34	0.491852
1809.25	0.262848
1810.16	-2.79565
1811.07	-2.51221
1811.98	2.18613
1812.89	-2.70557
1813.8	-0.480652
1814.7	4.64847
1815.61	7.18619
1816.52	2.45648
1817.43	4.09888
1818.33	-3.79443
1819.24	1.1817
1820.15	1.64145
1821.05	-3.32224
1821.96	-1.14334
1822.86	2.79202
1823.77	4.97046
1824.67	-1.76755
1825.58	-0.513794
1826.48	1.01517
1827.39	2.10315
1828.29	3.03809
1829.2	1.19049
1830.1	3.34427
1831	3.03726
1831.91	3.26804
1832.81	1.62994
1833.71	6.8266
1834.62	-0.681824
1835.52	-1.15921
1836.42	8.08493
1837.32	4.44647
1838.23	1.1683
1839.13	4.42426
1840.03	7.03516
1840.93	4.49023
1841.83	2.84537
1842.73	3.00232
1843.63	2.79031
1844.53	6.01511
1845.43	6.18588
1846.33	6.43619
1847.23	2.57993
1848.13	4.12399
1849.03	6.71225
1849.93	6.71472
1850.83	7.89893
1851.73	7.88919
1852.62	8.6217
1853.52	5.71649
1854.42	6.96112
1855.32	3.67184
1856.21	6.44885
1857.11	1.1972
1858.01	5.37881
1858.91	3.7616
1859.8	5.15146
1860.7	9.79025
1861.59	9.80753
1862.49	3.87659
1863.38	8.6608
1864.28	7.40826
1865.17	11.7847
1866.07	1.74432
1866.96	4.77374
1867.86	5.66187
1868.75	5.27393
1869.65	8.68878
1870.54	7.77951
1871.43	5.73032
1872.33	5.4805
1873.22	3.76566
1874.11	5.50571
1875	3.20358
1875.9	2.99969
1876.79	5.81046
1877.68	2.37219
1878.57	2.50186
1879.46	8.60202
1880.35	5.48315
1881.24	1.2193
1882.13	5.45233
1883.03	5.61407
1883.91	6.83051
1884.81	7.06714
1885.7	3.32785
1886.58	11.0098
1887.47	8.21249
1888.36	6.42426
1889.25	6.95383
1890.14	5.46231
1891.03	9.09058
1891.92	6.55319
1892.8	2.35779
1893.69	2.38391
1894.58	3.61642
1895.47	5.75998
1896.35	4.19141
1897.24	3.24341
1898.13	6.83701
1899.01	3.36011
1899.9	7.55579
1900.78	2.95474
1901.67	4.27878
1902.56	5.17587
1903.44	2.40887
1904.33	4.37198
1905.21	5.9346
1906.09	1.9588
1906.98	4.07526
1907.86	4.129
1908.75	3.75739
1909.63	2.17184
1910.51	8.49481
1911.4	10.8307
1912.28	2.52658
1913.16	5.68411
1914.04	3.48807
1914.93	5.76099
1915.81	3.64243
1916.69	9.8598
1917.57	9.4017
1918.45	5.83994
1919.33	3.68546
1920.21	8.4299
1921.09	9.19162
1921.97	4.53751
1922.86	9.07538
1923.74	4.09006
1924.61	5.44388
1925.49	6.87891
1926.37	7.27151
1927.25	5.35474
1928.13	5.28693
1929.01	2.73236
1929.89	4.02158
1930.77	3.95596
1931.55	9.36572
1932.44	6.2348
1933.33	8.04565
1934.22	7.42673
1935.12	5.85364
1936.01	6.49438
1936.9	5.20432
1937.79	6.98444
1938.68	2.44247
1939.57	8.65454
1940.46	6.11359
1941.35	7.2442
1942.25	5.50302
1943.14	8.04333
1944.03	6.71829
1944.92	6.65018
1945.8	15.6223
1946.69	8.38708
1947.58	5.56281
1948.47	5.72455
1949.36	6.517
1950.25	3.09976
1951.14	6.27023
1952.03	8.93304
1952.91	3.83563
1953.8	7.20139
1954.69	3.2803
1955.58	4.89886
1956.46	3.99564
1957.35	6.30283
1958.24	4.4549
1959.12	8.32083
1960.01	5.90445
1960.89	5.15793
1961.78	8.61264
1962.67	2.30652
1963.55	7.87476
1964.44	3.53183
1965.32	2.82663
1966.2	9.47839
1967.09	18.8578
1967.97	6.5311
1968.86	2.67352
1969.74	5.2226
1970.62	3.604
1971.51	6.27487
1972.39	-0.568787
1973.27	5.14935
1974.16	6.03098
1975.04	8.93091
1975.92	7.46918
1976.8	5.60709
1977.68	6.63062
1978.56	7.04428
1979.45	5.05667
1980.33	4.52866
1981.21	10.1441
1982.09	5.54047
1982.97	5.21487
1983.85	2.46506
1984.73	4.49811
1985.61	4.28668
1986.49	0.165558
1987.37	5.50256
1988.24	7.47043
1989.12	4.75552
1990	3.07162
1990.88	5.24918
1991.76	3.45065
1992.64	0.802155
1993.51	7.36914
1994.39	3.72775
1995.27	4.31699
1996.15	2.27405
1997.02	-0.24292
1997.9	5.23743
1998.77	-1.96753
1999.65	4.02786
2000.53	1.40717
2001.4	2.01218
2002.28	0.170349
2003.15	3.63126
2004.03	1.08783
2004.9	0.465485
2005.78	2.54337
2006.65	7.48016
2007.52	0.927582
2008.4	0.605469
2009.27	-2.00177
2010.15	3.2673
2011.02	-0.000518799
2011.89	-1.65997
2012.77	5.55389
2013.64	-0.517426
2014.51	2.11459
2015.38	2.59393
2016.25	-0.485321
2017.13	3.99026
2018	-0.61911
2018.87	0.207001
2019.74	0.421722
2020.61	0.297852
2021.48	2.091
2022.35	1.87955
2023.22	-3.27448
2024.09	8.95129
2024.96	0.671265
2025.83	-1.96176
2026.7	7.05045
2027.57	3.81699
2028.44	0.79892
2029.31	-3.32791
2030.17	-1.99277
2031.04	-1.9166
2031.91	-0.319672
2032.78	0.597076
2033.64	6.54739
2034.51	0.0137024
2035.38	0.765533
2036.25	1.57913
2037.11	0.00964355
2037.98	2.24371
2038.85	0.677551
2039.71	-0.766998
2040.58	2.65643
2041.44	-3.79117
2042.31	6.16156
2043.17	-4.58923
2044.04	2.2652
2044.9	-0.986633
2045.77	4.82477
2046.63	-1.70264
2047.49	2.33786
2048.36	-1.62939
2049.22	2.0361
2050.09	-1.75787
2050.95	2.25604
2051.81	6.78177
2052.67	0.20929
2053.54	2.78986
2054.4	3.50259
2055.26	2.75696
2056.12	4.78156
2056.98	-2.25757
2057.84	3.12073
2058.71	0.776855
2059.57	0.707092
2060.43	2.71741
2061.29	5.52997
2062.15	0.413361
2063.01	3.50287
2063.87	2.40149
2064.73	-3.5871
2065.59	2.96378
2066.45	3.93924
2067.3	1.02521
2068.16	1.85623
2069.02	-0.609955
2069.88	-1.78445
2070.74	-0.402435
2071.6	0.0412292
2072.45	3.47577
2073.31	0.991333
2074.17	-2.08102
2075.02	0.470917
2075.88	1.04141
2076.74	-1.23337
2077.59	-1.16443
2078.45	-1.76276
2079.31	0.476624
2080.16	2.64041
2081.02	-1.1861
2081.87	-1.58578
2082.73	5.69006
2083.58	1.41559
2084.44	3.22971
2085.29	1.96753
2086.15	3.83286
2087	3.35876
2087.85	-1.0448
2088.71	2.07565
2089.56	3.36166
2090.41	8.3992
2091.26	1.90967
2092.12	-1.94711
2092.97	3.44299
2093.82	0.932587
2094.67	0.271973
2095.53	0.666107
2096.38	4.2435
2097.23	1.31934
2098.08	6.84576
2098.93	2.22458
2099.78	2.7608
2100.63	-1.21576
2101.48	-1.04993
2102.33	7.85907
2103.18	2.38242
2104.03	1.87302
2104.88	-1.98221
2105.73	2.99789
2106.58	-2.01797
2107.43	-0.494934
2108.27	-3.58029
2109.12	-0.021759
2109.97	2.01541
2110.82	-1.25122
2111.67	3.06665
2112.51	6.20673
2113.36	3.67896
2114.21	-0.545135
2115.05	-3.62158
2115.9	2.74615
2116.75	6.28873
2117.59	3.29352
2118.44	7.91226
2119.28	7.65704
2120.13	10.8294
2120.98	8.10953
2121.82	3.65466
2122.66	2.65027
2123.51	-0.842224
2124.35	2.21573
2125.2	4.83594
2126.04	1.73047
2126.88	4.9108
2127.73	5.89337
2128.57	4.41544
2129.41	7.09827
2130.26	3.85678
2131.1	5.90665
2131.94	6.69543
2132.78	4.10886
2133.63	5.13889
2134.47	7.57581
2135.31	2.49811
2136.15	4.81116
2136.99	5.6337
2137.83	5.49075
2138.67	5.19186
2139.51	5.15582
2140.35	7.71808
2141.19	6.31708
2142.03	5.06082
2142.87	3.87231
2143.71	7.68347
2144.55	3.84344
2145.39	5.95609
2146.23	3.93228
2147.07	6.68283
2147.9	8.50287
2148.66	5.1889
2149.51	9.18649
2150.36	6.7406
2151.22	4.61462
2152.07	8.11847
2152.92	7.54745
2153.77	5.71515
2154.62	4.95737
2155.48	6.6553
2156.33	6.70618
2157.18	6.50812
2158.03	5.6731
2158.88	3.9754
2159.73	5.42261
2160.58	5.51385
2161.43	6.6127
2162.28	4.34909
2163.13	6.07404
2163.98	7.09106
2164.83	6.76941
2165.68	6.30576
2166.52	1.42334
2167.37	6.34436
2168.22	4.64923
2169.07	5.71719
2169.91	0.469299
2170.76	5.21271
2171.61	4.66235
2172.46	7.35376
2173.3	1.32712
2174.15	4.43018
2175	7.1265
2175.84	5.85507
2176.69	-0.00714111
2177.53	-1.07135
2178.38	7.95749
2179.23	1.12903
2180.07	4.57803
2180.92	1.50183
2181.76	9.63324
2182.61	-1.16455
2183.45	5.05728
2184.29	2.47687
2185.14	0.516815
2185.98	5.61185
2186.82	5.39221
2187.67	5.70563
2188.51	0.29538
2189.35	0.0433044
2190.2	3.09454
2191.04	1.46368
2191.88	-0.762909
2192.72	6.19864
2193.56	-0.00317383
2194.41	1.6311
2195.25	-1.65723
2196.09	3.14914
2196.93	-0.378784
2197.77	-2.12332
2198.61	5.84656
2199.45	-0.317017
2200.29	-0.132355
2201.13	0.598877
2201.97	-0.143402
2202.81	2.65472
2203.65	2.29312
2204.49	1.0166
2205.33	-4.1813
2206.16	-0.787842
2207	0.713409
2207.84	-2.70975
2208.68	-1.6788
2209.52	-0.398163
2210.35	1.00952
2211.19	3.87259
2212.03	-5.31903
2212.87	1.34064
2213.7	1.11734
2214.54	-2.72562
2215.38	3.81149
2216.21	1.54489
2217.05	-2.76016
2217.88	-0.65683
2218.72	2.48404
2219.55	-2.58713
2220.39	0.770996
2221.22	2.86346
2222.06	-0.958771
2222.89	-2.03821
2223.73	-1.01721
2224.56	-4.85638
2225.39	-2.40607
2226.23	2.0853
2227.06	-0.399292
2227.89	2.22095
2228.73	-1.31143
2229.56	-0.383606
2230.39	6.36035
2231.22	2.75806
2232.06	3.11307
2232.89	4.99619
2233.72	1.60187
2234.55	3.37964
2235.38	-0.0418396
2236.21	10.1932
2237.04	1.88477
2237.88	1.42889
2238.71	3.77267
2239.53	5.87573
2240.37	1.92526
2241.2	3.83994
2242.02	0.136932
2242.85	1.25723
2243.68	1.76834
2244.51	-1.39935
2245.34	-0.70932
2246.17	1.47467
2247	-0.47934
2247.83	1.37265
2248.65	2.13184
2249.48	6.11368
2250.31	7.76437
2251.14	6.50174
2251.96	0.787781
2252.79	8.22916
2253.62	0.818909
2254.44	0.0549316
2255.27	3.43008
2256.09	1.6868
2256.92	3.15759
2257.75	3.77213
2258.57	4.25967
2259.4	9.27463
2260.22	3.95197
2261.05	8.47729
2261.87	3.11774
2262.69	8.14865
2263.52	2.86578
2264.34	6.20517
2265.17	4.8876
2265.99	1.74463
2266.81	1.5629
2267.64	3.02588
2268.46	-1.043
2269.28	7.2977
2270.1	4.0683
2270.93	6.61539
2271.75	2.44025
2272.57	3.09866
2273.39	3.69028
2274.21	5.2547
2275.03	-1.58377
2275.85	4.09717
2276.67	3.0495
2277.5	6.29303
2278.32	3.08096
2279.14	2.09024
2279.96	6.61374
2280.78	2.01907
2281.59	0.150269
2282.41	4.52158
2283.23	7.69003
2284.05	-0.412628
2284.87	2.7923
2285.69	3.41806
2286.51	-0.536499
2287.33	3.19196
2288.14	-1.57358
2288.96	0.177856
2289.78	2.99942
2290.6	9.51468
2291.41	3.36209
2292.23	0.329407
2293.05	6.58478
2293.86	6.20593
2294.68	-0.656006
2295.49	0.0768738
2296.31	-1.28445
2297.13	-2.62646
2297.94	-1.69675
2298.75	1.33694
2299.57	2.54266
2300.39	2.65503
2301.2	2.92587
2302.01	1.4924
2302.83	2.36554
2303.64	1.44077
2304.46	1.64856
2305.27	7.35654
2306.08	2.5831
2306.89	0.270905
2307.71	-3.52805
2308.52	3.89587
2309.33	-0.04245
2310.14	2.89893
2310.96	0.161041
2311.77	0.78772
2312.58	1.83917
2313.39	2.2471
2314.2	0.396484
2315.01	-2.52158
2315.82	-2.63452
2316.63	0.722626
2317.44	0.965607
2318.26	0.384399
2319.06	1.08728
2319.87	-1.72903
2320.68	2.99884
2321.49	1.358
2322.3	1.43268
2323.11	1.08557
2323.92	-0.22641
2324.73	2.10315
2325.54	-0.756256
2326.34	2.94382
2327.15	3.19275
2327.96	2.59903
2328.77	1.89658
2329.57	2.68448
2330.38	4.52777
2331.19	1.05118
2331.99	0.885406
2332.8	-1.70999
2333.61	2.48648
2334.41	-0.511414
2335.22	-2.58054
2336.02	-0.0122986
2336.83	3.14444
2337.63	-3.03796
2338.44	5.23596
2339.24	1.59827
2340.05	1.80814
2340.85	-3.04062
2341.66	6.96387
2342.46	0.827637
2343.26	0.0620422
2344.07	1.1871
2344.87	4.57217
2345.67	-0.220612
2346.48	-0.0178833
2347.28	1.11954
2348.08	0.830841
2348.88	2.88254
2349.69	1.66818
2350.49	-1.30496
2351.29	-1.14249
2352.09	0.610718
2352.89	-0.369232
2353.69	0.481873
2354.49	2.22681
2355.17	-1.71747
2355.99	0.48111
2356.8	0.870117
2357.62	6.5191
2358.43	0.549316
2359.25	3.70682
2360.06	4.0813
2360.88	-0.651062
2361.69	1.91043
2362.5	1.66782
2363.32	1.99585
2364.13	2.14801
2364.94	1.93481
2365.76	0.633667
2366.57	0.596191
2367.38	0.815735
2368.19	0.447968
2369	1.72324
2369.82	-3.4227
2370.63	2.00815
2371.44	3.64899
2372.25	2.95834
2373.06	4.82266
2373.87	1.21045
2374.68	-1.68231
2375.49	-0.44809
2376.3	1.1265
2377.11	-0.886139
2377.92	1.51624
2378.73	-0.0803223
2379.54	1.31439
2379.94	4.71848