File: Data/3-Raman/processed/bu04w-a-ff3-fi05-v_1800 (450-850nm)_633nm_edge_100%_x100_vis_lwd_h50um_45sx2_01.txt
#Acq. time (s)=	45
#Accumulations=	2
#Range (cm-¹)=	1200...2380
#Windows=	6
#Auto scanning=	Off
#Autofocus=	Off
#Macrospot=	Off
#AutoExposure=	Off
#Spike filter=	Multiple accum.
#Delay time (s)=	2
#Binning=	1
#Readout mode=	Signal
#DeNoise=	Off
#ICS correction=	On
#Dark correction=	Off
#Inst. Process=	Off
#Detector Gain=	Best Dynamic
#Detector ADC=	50 kHz EM
#Detector EM gain=	100
#Detector temperature (°C)=	-60.09
#Instrument=	LabRAM HR Evol
#Detector=	SIN-EM FIVIS
#Objective=	x100_VIS_LWD
#Grating=	1800 (450-850nm)
#ND Filter=	100%
#Laser=	633nm_Edge
#Hole=	49.98
#Temperature=	0
#Range=	Visible
#StageXY=	75x50mm Scan+
#StageZ=	Z motor
#X (µm)=	0
#Y (µm)=	0
#Z (µm)=	16.9
#Full time(mm:ss)=	9:36
#Project=	21_11_22
#Sample=	BU04w
#Site=
#Title=	BU04w-A-FF3-FI05-V_1800 (450-850nm)_633nm_Edge_100%_x100_VIS_LWD_H50um_45sX2
#Remark=
#Date=	22.11.2021 11:27
#Acquired=	22.11.2021 11:27:50
#Base:Fit=	16.12.2021 16:15:35
#Base:Fit=	16.12.2021 16:23:33
#Base:Sub=	16.12.2021 16:23:35
1200.03	8.51492
1201.07	2.3699
1202.1	4.22208
1203.13	-0.995667
1204.16	1.81458
1205.2	1.48557
1206.23	-1.07883
1207.26	6.13629
1208.29	1.90613
1209.32	-0.296875
1210.35	3.71173
1211.38	-1.81763
1212.41	2.76474
1213.44	-0.995667
1214.47	-2.0535
1215.5	1.9899
1216.53	-1.60126
1217.56	-4.2562
1218.58	2.35007
1219.61	-1.91727
1220.64	3.7019
1221.67	1.16724
1222.7	-2.7092
1223.72	1.90424
1224.75	-2.43701
1225.78	-3.02487
1226.8	17.2021
1227.83	5.01346
1228.85	0.244751
1229.88	4.77927
1230.91	2.12967
1231.93	3.10098
1232.96	3.78195
1233.98	-0.702698
1235	-1.17578
1236.03	1.73248
1237.05	1.13959
1238.07	4.6427
1239.1	-0.038269
1240.12	-1.36523
1241.14	2.40295
1242.17	2.25244
1243.19	4.55493
1244.21	4.99478
1245.23	0.814026
1246.25	1.80029
1247.27	-2.42889
1248.3	4.05032
1249.32	4.06369
1250.34	3.46667
1251.36	7.71143
1252.38	8.27536
1253.4	0.613953
1254.42	7.26205
1255.43	1.68332
1256.45	8.77133
1257.47	11.5739
1258.49	3.90692
1259.51	5.63297
1260.53	5.82004
1261.54	6.26917
1262.56	6.37561
1263.58	8.12924
1264.59	10.7713
1265.61	9.01648
1266.63	10.5626
1267.64	5.56461
1268.66	12.4732
1269.67	4.80536
1270.69	11.2762
1271.7	5.91782
1272.72	1.88406
1273.73	1.54437
1274.75	9.06024
1275.76	4.32581
1276.77	5.79013
1277.79	5.7511
1278.8	5.25464
1279.82	0.454956
1280.83	2.3382
1281.84	6.87451
1282.85	3.93503
1283.86	20.1125
1284.88	13.6961
1285.89	2.77744
1286.9	1.27191
1287.91	1.38254
1288.92	0.0802612
1289.93	0.749695
1290.94	1.59714
1291.95	1.11838
1292.96	2.88626
1293.97	-0.990631
1294.98	0.599274
1295.99	5.74237
1296.99	1.02078
1298	-0.828735
1299.01	1.15216
1300.02	3.43552
1301.03	-0.843018
1302.03	1.19315
1303.04	3.98129
1304.05	1.49332
1305.05	-5.45673
1306.06	6.9422
1307.07	0.653442
1308.07	4.01022
1309.08	-1.30392
1310.08	0.806335
1311.09	-4.32913
1312.09	-3.80347
1313.1	4.18054
1314.1	2.68143
1315.1	4.91068
1316.11	-1.55646
1317.11	1.74606
1318.12	1.10068
1319.12	-1.95316
1320.12	0.506683
1321.12	3.23856
1322.12	-1.23816
1323.13	-2.80255
1324.13	-4.59045
1325.13	4.28952
1326.13	-3.99356
1327.13	0.452881
1328.13	1.53278
1329.13	-0.0155334
1330.13	5.16608
1331.13	0.294464
1332.13	2.36707
1333.13	1.68805
1334.13	10.274
1335.13	5.34976
1336.13	8.56723
1337.13	8.83725
1338.12	12.1451
1339.12	5.11768
1340.12	1.56934
1341.12	4.06735
1342.11	10.7212
1343.11	0.449036
1344.11	10.0095
1345.1	4.06369
1346.1	6.25623
1347.09	2.784
1348.09	3.73322
1349.08	7.76962
1350.08	2.19431
1351.07	5.39917
1352.07	7.77386
1353.06	3.75787
1354.06	6.80005
1355.05	10.3075
1356.04	12.374
1357.04	6.89136
1358.03	9.63385
1359.02	9.8945
1360.02	14.5341
1361.01	6.65253
1362	9.82532
1362.99	6.7973
1363.98	1.63162
1364.97	12.1814
1365.97	10.5081
1366.95	7.94537
1367.95	8.67831
1368.94	9.57126
1369.93	8.18784
1370.91	5.20273
1371.91	5.4841
1372.89	4.57394
1373.88	14.9791
1374.87	11.4903
1375.86	11.5948
1376.85	11.9649
1377.84	18.5208
1378.82	11.9183
1379.81	3.82773
1380.8	8.58151
1381.78	9.51462
1382.77	15.7119
1383.76	11.9728
1384.74	10.9288
1385.73	10.9297
1386.72	24.7966
1387.7	61.4608
1388.68	15.1541
1389.67	9.22336
1390.65	8.41129
1391.64	12.3559
1392.62	2.72858
1393.61	13.4083
1394.59	12.6629
1395.57	8.74146
1396.56	8.45407
1397.54	11.313
1398.52	0.338287
1399.5	2.66516
1400.49	3.93619
1401.47	8.21536
1402.45	5.49908
1403.43	7.75998
1404.41	3.83984
1405.39	2.71472
1406.37	5.16119
1407.35	5.44308
1408.33	5.79489
1409.31	-1.22311
1410.29	8.7449
1411.27	3.93411
1412.25	-0.520691
1413.23	2.32635
1414.21	5.22919
1415.19	5.9751
1416.16	5.3381
1417.14	2.1145
1418.12	0.885956
1419.1	5.19608
1420.07	4.24426
1421.05	6.65628
1422.03	4.95422
1423	5.6265
1423.98	5.94958
1424.95	1.84521
1425.93	2.74561
1426.9	7.13791
1427.88	2.27853
1428.85	6.66708
1429.83	4.92776
1430.8	5.97968
1431.78	1.88226
1432.75	5.26288
1433.72	2.25842
1434.7	5.20053
1435.67	7.19272
1436.64	5.85364
1437.62	5.10382
1438.59	2.84277
1439.56	9.65118
1440.53	1.95917
1441.5	8.73828
1442.47	4.92822
1443.44	6.59906
1444.42	2.02576
1445.39	7.76465
1446.36	3.177
1447.33	6.08664
1448.29	12.3296
1449.26	2.51572
1450.23	4.65576
1451.2	6.60907
1452.17	10.1981
1453.14	7.60867
1454.11	4.36292
1455.07	7.51694
1456.04	8.03641
1457.01	5.50543
1457.98	10.7086
1458.94	3.02917
1459.91	4.98013
1460.88	-0.54837
1461.84	4.78101
1462.81	0.838837
1463.77	0.567963
1464.74	3.08212
1465.61	4.8139
1466.59	2.8587
1467.57	0.147125
1468.55	0.431671
1469.53	-1.30536
1470.51	-2.52353
1471.49	1.46881
1472.47	2.737
1473.45	6.19894
1474.43	3.72
1475.4	1.20773
1476.38	5.83588
1477.36	1.39987
1478.34	-3.71033
1479.32	5.61957
1480.29	2.495
1481.27	4.96603
1482.25	8.28598
1483.22	0.437042
1484.2	3.0361
1485.18	1.41583
1486.15	-0.305298
1487.13	-0.0230408
1488.1	0.495178
1489.08	4.19482
1490.05	1.13644
1491.03	1.24643
1492	3.21527
1492.98	-1.38779
1493.95	1.2236
1494.92	-0.473999
1495.9	3.11798
1496.87	3.40326
1497.84	0.356476
1498.82	-1.43384
1499.79	-1.31213
1500.76	-1.35196
1501.73	-0.425598
1502.7	1.52676
1503.68	1.14444
1504.65	-2.04694
1505.62	-2.3573
1506.59	-1.38321
1507.56	-0.648682
1508.53	0.127319
1509.5	1.37973
1510.47	2.60422
1511.44	-1.83136
1512.41	-3.99277
1513.38	3.56186
1514.35	0.0274658
1515.31	-4.70432
1516.28	2.79694
1517.25	0.0744019
1518.22	4.57596
1519.19	-2.03876
1520.15	1.74371
1521.12	6.93408
1522.09	3.18979
1523.05	0.87796
1524.02	0.182678
1524.99	2.02359
1525.95	0.154266
1526.92	-0.603882
1527.88	2.46332
1528.85	-0.030304
1529.81	1.93625
1530.78	1.03098
1531.74	0.193542
1532.71	2.20963
1533.67	4.20233
1534.63	1.41528
1535.6	3.8364
1536.56	1.15811
1537.52	1.57596
1538.49	1.71048
1539.45	4.76059
1540.41	1.54364
1541.37	0.435699
1542.33	4.32794
1543.29	3.19821
1544.26	2.9985
1545.22	6.11172
1546.18	3.17776
1547.14	1.99683
1548.1	7.15533
1549.06	1.27518
1550.02	1.62955
1550.98	3.61621
1551.94	0.356506
1552.9	-1.33295
1553.85	4.31567
1554.81	10.3739
1555.77	2.41815
1556.73	7.54092
1557.69	1.4707
1558.64	7.4035
1559.6	4.73874
1560.56	2.04303
1561.52	3.83887
1562.47	8.255
1563.43	-0.487549
1564.38	-1.31921
1565.34	3.91821
1566.3	0.455231
1567.25	4.43289
1568.21	6.03482
1569.16	0.635376
1570.12	1.561
1571.07	4.62857
1572.02	-1.80396
1572.98	2.11856
1573.93	1.35114
1574.89	2.13818
1575.84	-1.70663
1576.79	-0.589691
1577.74	6.70316
1578.7	2.40607
1579.65	-1.63397
1580.6	2.80414
1581.55	0.782532
1582.5	-1.06497
1583.46	-1.33926
1584.41	5.26086
1585.36	3.70239
1586.31	1.38083
1587.26	1.8269
1588.21	4.84109
1589.16	-1.05176
1590.11	20.4849
1591.06	0.211487
1592.01	-3.98956
1592.95	1.58755
1593.9	0.716919
1594.85	3.51947
1595.8	1.68945
1596.75	3.10876
1597.69	-3.84735
1598.64	7.14905
1599.59	2.33984
1600.54	-0.961792
1601.48	2.16498
1602.43	0.580658
1603.38	3.52435
1604.32	0.316895
1605.27	-1.81671
1606.21	4.24445
1607.16	1.40274
1608.1	-2.7052
1609.05	2.74597
1609.99	-0.837189
1610.94	0.972992
1611.88	-3.66162
1612.82	0.691772
1613.77	-0.283203
1614.71	0.0653687
1615.65	0.922211
1616.6	-1.41083
1617.54	0.519897
1618.48	12.8741
1619.42	1.30338
1620.36	2.57129
1621.3	7.09717
1622.25	2.13727
1623.19	5.69318
1624.13	2.90213
1625.07	5.39029
1626.01	2.61432
1626.95	-0.406555
1627.89	0.076416
1628.83	6.23065
1629.77	-0.870148
1630.71	1.24219
1631.65	5.34192
1632.58	3.54016
1633.52	4.47372
1634.46	2.83206
1635.4	5.1857
1636.34	4.065
1637.27	6.0542
1638.21	-1.42401
1639.15	4.96179
1640.09	4.94495
1641.02	0.707672
1641.96	10.4351
1642.89	5.16486
1643.83	5.14325
1644.77	2.28168
1645.7	6.40079
1646.64	5.91284
1647.57	4.59644
1648.51	5.98953
1649.44	19.6853
1650.37	12.9606
1651.31	6.86545
1652.24	7.24069
1653.17	6.78177
1654.11	8.91229
1655.04	7.2695
1655.97	5.5907
1656.91	8.63525
1657.84	3.71854
1658.77	4.59808
1659.7	1.90643
1660.63	15.0835
1661.56	6.25217
1662.49	6.12332
1663.43	3.06448
1664.36	4.66699
1665.29	8.11551
1666.22	3.23099
1667.15	3.62711
1668.07	6.63654
1669.01	7.85068
1669.93	6.67816
1670.86	4.02853
1671.79	8.79874
1672.72	6.86023
1673.65	4.97974
1674.58	8.28134
1675.5	5.14578
1676.43	1.05841
1677.36	7.96719
1678.28	3.55829
1679.21	-1.05862
1680.14	5.8941
1681.06	0.697235
1681.99	4.07883
1682.92	6.64285
1683.84	5.38666
1684.77	4.8179
1685.69	3.12924
1686.61	8.31528
1687.54	5.43903
1688.46	2.25256
1689.39	2.22833
1690.31	5.08224
1691.24	0.285522
1692.16	3.76688
1693.08	3.41406
1694.01	0.988708
1694.93	2.06219
1695.85	-0.00134277
1696.77	-0.0367432
1697.69	-1.33389
1698.61	0.767487
1699.54	-2.38806
1700.46	-2.29141
1701.38	3.80133
1702.3	-0.373932
1703.22	0.244751
1704.11	-0.0754089
1705.04	2.38434
1705.98	6.17349
1706.92	3.90762
1707.85	-1.0134
1708.78	4.37134
1709.72	-0.951233
1710.65	3.3385
1711.59	-3.52579
1712.52	-2.07602
1713.45	-4.86752
1714.39	0.627106
1715.32	4.08606
1716.25	4.86136
1717.19	-3.72614
1718.12	-1.16138
1719.05	8.19272
1719.98	1.4415
1720.91	0.775452
1721.84	-2.77048
1722.77	-1.11938
1723.7	-1.98859
1724.64	1.03424
1725.57	2.22073
1726.5	-1.72784
1727.43	0.116425
1728.36	-2.45248
1729.29	-0.358063
1730.21	-1.78702
1731.14	1.01096
1732.07	-5.23212
1733	2.54813
1733.93	2.75912
1734.86	-1.97311
1735.78	-0.409241
1736.71	-2.30191
1737.64	2.67889
1738.57	2.46231
1739.49	1.99637
1740.42	0.618347
1741.35	-2.07425
1742.27	2.11566
1743.2	-2.0032
1744.12	1.21234
1745.05	2.60956
1745.97	0.549011
1746.9	3.19485
1747.82	1.17429
1748.75	2.271
1749.67	-3.24509
1750.6	-2.14087
1751.52	-2.25638
1752.44	-1.42062
1753.37	3.41464
1754.29	4.85895
1755.21	-0.971283
1756.14	-1.33908
1757.06	0.967926
1757.98	0.0123901
1758.9	5.80518
1759.82	1.20615
1760.75	-0.0784912
1761.67	0.452881
1762.59	0.34491
1763.51	2.17255
1764.43	2.97018
1765.35	4.05524
1766.27	1.39587
1767.19	7.66437
1768.11	1.18723
1769.03	0.720154
1769.95	0.723083
1770.87	0.929535
1771.79	1.32062
1772.7	0.416992
1773.62	4.29507
1774.54	0.750488
1775.46	-2.85626
1776.38	-2.267
1777.29	1.04257
1778.21	1.91446
1779.13	9.0773
1780.04	2.9628
1780.96	1.16666
1781.88	-0.229645
1782.79	-0.904724
1783.71	2.13339
1784.62	3.00156
1785.54	1.75604
1786.45	-0.76004
1787.37	4.36136
1788.28	0.923431
1789.2	-2.55762
1790.11	-1.18155
1791.02	1.01889
1791.94	1.07477
1792.85	-0.287811
1793.76	1.31607
1794.68	-0.89032
1795.59	0.969879
1796.5	7.25992
1797.42	-1.93439
1798.33	5.04239
1799.24	-2.59604
1800.15	1.58069
1801.06	-1.5253
1801.97	-1.54373
1802.88	2.2113
1803.79	-2.69785
1804.71	0.165222
1805.62	1.34821
1806.53	-0.203186
1807.44	3.4281
1808.34	1.23672
1809.25	4.52255
1810.16	0.300995
1811.07	2.93887
1811.98	1.76852
1812.89	5.09827
1813.8	0.279999
1814.7	-0.466522
1815.61	4.42297
1816.52	-0.305389
1817.43	0.167816
1818.33	2.86044
1819.24	0.779205
1820.15	0.0609741
1821.05	-0.184113
1821.96	4.35321
1822.86	0.034668
1823.77	3.39532
1824.67	6.11133
1825.58	0.276367
1826.48	1.80414
1827.39	6.44891
1828.29	0.274933
1829.2	3.17401
1830.1	0.587952
1831	5.02872
1831.91	6.45215
1832.81	2.439
1833.71	7.63434
1834.62	4.88245
1835.52	-0.351929
1836.42	7.70514
1837.32	1.68469
1838.23	3.16739
1839.13	7.62259
1840.03	3.07904
1840.93	5.31079
1841.83	0.0863342
1842.73	0.242126
1843.63	0.0233459
1844.53	0.843811
1845.43	8.20465
1846.33	2.48294
1847.23	3.40396
1848.13	3.75165
1849.03	2.74252
1849.93	5.14352
1850.83	7.52768
1851.73	6.31406
1852.62	5.84521
1853.52	2.94299
1854.42	4.18698
1855.32	4.50549
1856.21	4.87427
1857.11	2.03586
1858.01	5.00967
1858.91	3.39267
1859.8	10.8129
1860.7	9.42169
1861.59	2.17838
1862.49	4.71521
1863.38	9.50378
1864.28	4.61804
1865.17	5.36716
1866.07	1.3768
1866.96	8.02853
1867.86	1.6626
1868.75	8.53607
1869.65	4.68185
1870.54	3.78091
1871.43	5.36386
1872.33	6.32596
1873.22	5.82028
1874.11	1.51468
1875	2.83792
1875.9	6.27277
1876.79	7.86606
1877.68	5.64136
1878.57	7.00226
1879.46	2.17471
1880.35	9.97775
1881.24	2.06848
1882.13	2.66669
1883.03	4.03497
1883.91	10.1418
1884.81	9.14001
1885.7	5.39297
1886.58	4.61295
1887.47	9.07404
1888.36	3.63062
1889.25	5.37122
1890.14	6.32129
1891.03	8.73199
1891.92	6.19528
1892.8	9.30182
1893.69	5.67929
1894.58	0.825287
1895.47	0.520508
1896.35	5.05338
1897.24	4.11154
1898.13	2.81973
1899.01	4.23117
1899.9	5.98468
1900.78	6.25836
1901.67	2.70779
1902.56	4.82852
1903.44	4.50458
1904.33	1.57941
1905.21	4.36966
1906.09	2.83673
1906.98	4.95789
1907.86	5.01349
1908.75	2.19577
1909.63	5.50235
1910.51	5.70447
1911.4	6.81461
1912.28	10.7668
1913.16	10.2631
1914.04	6.84509
1914.93	9.13144
1915.81	4.5473
1916.69	8.30261
1917.57	6.71841
1918.45	9.05679
1919.33	4.95352
1920.21	6.42801
1921.09	7.42014
1921.97	8.05807
1922.86	4.39795
1923.74	4.35474
1924.61	6.91803
1925.49	9.80777
1926.37	7.83273
1927.25	7.67804
1928.13	7.61694
1929.01	6.33762
1929.89	5.94357
1930.77	5.29037
1931.55	6.61725
1932.44	5.9574
1933.33	10.2484
1934.22	4.68246
1935.12	5.58618
1936.01	12.4432
1936.9	9.91479
1937.79	4.24619
1938.68	7.14221
1939.57	8.40509
1940.46	9.59677
1941.35	4.51682
1942.25	8.98987
1943.14	9.05594
1944.03	10.2276
1944.92	3.93222
1945.8	7.91632
1946.69	6.92606
1947.58	5.35071
1948.47	8.01453
1949.36	8.8092
1950.25	5.39105
1951.14	4.83362
1952.03	8.74445
1952.91	-0.0800476
1953.8	4.53653
1954.69	6.84787
1955.58	8.47638
1956.46	10.0831
1957.35	11.1274
1958.24	5.55072
1959.12	9.42709
1960.01	5.76324
1960.89	5.02237
1961.78	7.23621
1962.67	3.4335
1963.55	4.00977
1964.44	7.16156
1965.32	2.72061
1966.2	5.62512
1967.09	13.7502
1967.97	7.69403
1968.86	3.84283
1969.74	6.39883
1970.62	8.55237
1971.51	6.21353
1972.39	1.86615
1973.27	5.10147
1974.16	8.49179
1975.04	7.64423
1975.92	3.68549
1976.8	8.09644
1977.68	6.61774
1978.56	4.5351
1979.45	10.0568
1980.33	4.53766
1981.21	5.1416
1982.09	1.80774
1982.97	6.49786
1983.85	2.50427
1984.73	4.54504
1985.61	4.3414
1986.49	3.97339
1987.37	8.07288
1988.24	7.54895
1989.12	3.58984
1990	0.664093
1990.88	5.35211
1991.76	6.07651
1992.64	4.68048
1993.51	6.24695
1994.39	6.35727
1995.27	3.21292
1996.15	2.42746
1997.02	1.1702
1997.9	2.90213
1998.77	1.96231
1999.65	0.467285
2000.53	-2.14435
2001.4	4.72205
2002.28	0.385345
2003.15	2.60565
2004.03	1.32089
2004.9	1.95572
2005.78	0.300751
2006.65	1.50504
2007.52	4.94925
2008.4	-0.361084
2009.27	0.786407
2010.15	-0.188141
2011.02	0.306732
2011.89	1.15234
2012.77	-0.355988
2013.64	-0.181641
2014.51	3.71304
2015.38	6.70154
2016.25	-0.120697
2017.13	0.60849
2018	-0.235077
2018.87	-0.647644
2019.74	-1.67371
2020.61	-1.78766
2021.48	0.0109863
2022.35	3.56375
2023.22	2.17261
2024.09	8.14944
2024.96	2.38632
2025.83	1.01544
2026.7	2.51913
2027.57	-0.71283
2028.44	-2.46124
2029.31	2.19781
2030.17	-2.7243
2031.04	-1.38419
2031.91	0.222778
2032.78	2.40482
2033.64	0.816376
2034.51	1.84442
2035.38	-1.16571
2036.25	-0.339844
2037.11	1.87149
2037.98	1.59763
2038.85	3.82465
2039.71	6.17551
2040.58	0.785187
2041.44	-0.625214
2042.31	-0.741272
2043.17	-0.139771
2044.04	-2.09726
2044.9	-1.54913
2045.77	1.75345
2046.63	0.271149
2047.49	9.37424
2048.36	4.15295
2049.22	0.252594
2050.09	1.51938
2050.95	1.75314
2051.81	3.75217
2052.67	0.989868
2053.54	3.58008
2054.4	6.83322
2055.26	2.30307
2056.12	0.535858
2056.98	2.36322
2057.84	6.49823
2058.71	0.357544
2059.57	4.09711
2060.43	-1.49481
2061.29	5.13434
2062.15	1.29776
2063.01	3.12317
2063.87	0.764282
2064.73	4.95383
2065.59	2.61612
2066.45	3.59686
2067.3	1.96362
2068.16	1.52921
2069.02	-0.924591
2069.88	-0.819885
2070.74	0.570709
2071.6	6.11835
2072.45	5.73877
2073.31	3.26328
2074.17	1.47858
2075.02	-1.06775
2075.88	3.33929
2076.74	4.90219
2077.59	2.42807
2078.45	3.12241
2079.31	1.53134
2080.16	6.26694
2081.02	1.16208
2081.87	3.3363
2082.73	-0.908142
2083.58	-0.0510254
2084.44	0.484314
2085.29	-2.05408
2086.15	8.81262
2087	5.76248
2087.85	0.0825806
2088.71	-0.642059
2089.56	3.21805
2090.41	6.96915
2091.26	-0.790314
2092.12	3.06747
2092.97	0.750641
2093.82	7.26898
2094.67	6.6069
2095.53	0.563354
2096.38	4.14276
2097.23	8.96228
2098.08	4.17282
2098.93	2.14145
2099.78	5.26321
2100.63	5.16562
2101.48	7.92471
2102.33	0.0399475
2103.18	2.31729
2104.03	6.992
2104.88	3.12949
2105.73	4.24197
2106.58	3.11743
2107.43	4.63486
2108.27	2.85831
2109.12	3.83679
2109.97	1.98126
2110.82	1.3118
2111.67	5.63925
2112.51	6.17609
2113.36	3.65512
2114.21	3.33438
2115.05	9.34894
2115.9	5.33429
2116.75	4.96317
2117.59	4.58347
2118.44	7.896
2119.28	6.3353
2120.13	8.20792
2120.98	5.48962
2121.82	7.58075
2122.66	9.19254
2123.51	3.07553
2124.35	4.82874
2125.2	6.14026
2126.04	8.271
2126.88	7.52774
2127.73	7.19971
2128.57	4.41187
2129.41	7.0899
2130.26	2.5365
2131.1	7.21356
2131.94	10.6324
2132.78	4.0994
2133.63	6.44452
2134.47	10.1859
2135.31	7.74899
2136.15	7.24838
2136.99	6.15012
2137.83	12.7171
2138.67	7.34225
2139.51	8.11472
2140.35	9.20804
2141.19	7.65698
2142.03	6.35211
2142.87	7.58386
2143.71	7.07892
2144.55	8.35648
2145.39	5.05576
2146.23	5.17163
2147.07	5.54608
2147.9	7.11856
2148.66	7.78485
2149.51	13.1069
2150.36	4.02911
2151.22	3.21912
2152.07	4.05276
2152.92	6.13113
2153.77	4.30585
2154.62	8.85623
2155.48	3.89771
2156.33	11.9316
2157.18	3.75296
2158.03	4.23547
2158.88	3.8577
2159.73	7.96561
2160.58	4.05826
2161.43	9.14465
2162.28	9.54825
2163.13	3.26138
2163.98	8.27087
2164.83	6.60675
2165.68	7.47266
2166.52	5.24847
2167.37	6.16629
2168.22	8.46606
2169.07	2.85239
2169.91	1.60144
2170.76	7.67139
2171.61	3.11472
2172.46	5.78848
2173.3	2.42899
2174.15	9.53659
2175	8.21246
2175.84	5.59424
2176.69	9.0593
2177.53	5.32648
2178.38	7.67209
2179.23	8.84036
2180.07	1.61716
2180.92	2.52823
2181.76	11.9871
2182.61	2.50775
2183.45	0.714844
2184.29	3.46674
2185.14	5.50067
2185.98	1.24646
2186.82	2.33881
2187.67	9.32785
2188.51	6.57919
2189.35	0.975342
2190.2	4.0166
2191.04	3.71194
2191.88	9.47464
2192.72	3.08505
2193.56	0.878235
2194.41	1.16809
2195.25	0.535736
2196.09	2.66364
2196.93	3.13599
2197.77	4.05231
2198.61	1.31689
2199.45	-0.848785
2200.29	1.99997
2201.13	0.0505066
2201.97	1.96799
2202.81	3.41861
2203.65	-0.963928
2204.49	-0.907166
2205.33	0.550629
2206.16	-2.75046
2207	4.0972
2207.84	-0.676849
2208.68	1.68634
2209.52	2.95624
2210.35	1.67331
2211.19	0.500854
2212.03	-0.663727
2212.87	-2.0578
2213.7	1.73618
2214.54	1.91278
2215.38	3.06439
2216.21	3.47086
2217.05	-2.18625
2217.88	-0.0941162
2218.72	-1.00027
2219.55	-0.704529
2220.39	-0.0446777
2221.22	6.07739
2222.06	-1.79623
2222.89	2.49548
2223.73	2.16745
2224.56	-1.68954
2225.39	-0.592285
2226.23	-0.158234
2227.06	-4.00504
2227.89	-2.74536
2228.73	0.455719
2229.56	2.72711
2230.39	-0.0177002
2231.22	3.14679
2232.06	0.782379
2232.89	1.29401
2233.72	-0.750061
2234.55	2.3707
2235.38	-1.05887
2236.21	11.8789
2237.04	4.91824
2237.88	-3.68893
2238.71	5.43188
2239.53	3.43863
2240.37	0.845734
2241.2	5.47272
2242.02	-0.964935
2242.85	2.87335
2243.68	0.646851
2244.51	2.92929
2245.34	7.72095
2246.17	-1.03864
2247	5.20657
2247.83	0.203583
2248.65	0.956451
2249.48	0.822144
2250.31	2.45966
2251.14	2.54416
2251.96	6.43707
2252.79	2.89102
2253.62	6.47693
2254.44	4.32275
2255.27	2.19379
2256.09	-0.927124
2256.92	6.0365
2257.75	1.13943
2258.57	2.99442
2259.4	3.85791
2260.22	4.05316
2261.05	1.67792
2261.87	1.8287
2262.69	5.47714
2263.52	0.187225
2264.34	3.51746
2265.17	4.96091
2265.99	1.81403
2266.81	3.01089
2267.64	7.23715
2268.46	0.399811
2269.28	-2.3364
2270.1	4.1217
2270.93	5.27405
2271.75	-0.28717
2272.57	8.70813
2273.39	7.90054
2274.21	2.51898
2275.03	2.61514
2275.85	1.35565
2276.67	4.4826
2277.5	4.9425
2278.32	1.73114
2279.14	3.52069
2279.96	-0.310059
2280.78	0.667419
2281.59	0.191101
2282.41	1.77054
2283.23	6.33963
2284.05	-1.75812
2284.87	4.23541
2285.69	-0.703247
2286.51	2.29645
2287.33	3.24521
2288.14	1.26904
2288.96	4.40775
2289.78	3.06186
2290.6	4.00275
2291.41	-0.747162
2292.23	4.56729
2293.05	5.26764
2293.86	6.28885
2294.68	2.21329
2295.49	0.169708
2296.31	0.21286
2297.13	-1.12766
2297.94	1.20071
2298.75	7.05255
2299.57	4.05975
2300.39	-0.00839233
2301.2	7.25327
2302.01	4.43018
2302.83	2.51508
2303.64	1.59778
2304.46	0.413452
2305.27	3.32733
2306.08	-0.0252075
2306.89	-0.936768
2307.71	-3.33066
2308.52	1.31058
2309.33	2.96652
2310.14	4.52563
2310.96	1.79297
2311.77	-5.95273
2312.58	-2.11063
2313.39	-4.48016
2314.2	-2.1348
2315.01	4.76855
2315.82	0.461029
2316.63	1.02487
2317.44	-1.53278
2318.26	2.11166
2319.06	-1.38339
2319.87	2.82361
2320.68	-2.26572
2321.49	-1.08524
2322.3	7.43173
2323.11	5.6882
2323.92	-1.23767
2324.73	-0.295807
2325.54	-0.33493
2326.34	4.78473
2327.15	0.826019
2327.96	-2.5799
2328.77	-1.85745
2329.57	1.75146
2330.38	3.60846
2331.19	1.5498
2331.99	-2.84973
2332.8	-1.18979
2333.61	3.0173
2334.41	2.8631
2335.22	-0.613922
2336.02	0.549591
2336.83	5.13739
2337.63	6.06335
2338.44	7.24701
2339.24	13.5779
2340.05	3.84171
2340.85	6.0827
2341.66	6.16837
2342.46	4.34644
2343.26	0.565491
2344.07	-1.0976
2344.87	2.46478
2345.67	5.0051
2346.48	0.997192
2347.28	0.987
2348.08	5.51544
2348.88	3.29712
2349.69	4.0452
2350.49	4.0834
2351.29	2.6954
2352.09	1.94391
2352.89	5.18393
2353.69	1.32535
2354.49	3.17679
2355.17	1.85803
2355.99	-1.67197
2356.8	8.74493
2357.62	8.66428
2358.43	1.25342
2359.25	-2.76831
2360.06	-0.970795
2360.88	-1.39642
2361.69	1.15915
2362.5	2.34521
2363.32	1.22244
2364.13	-1.50885
2364.94	-3.17133
2365.76	5.60596
2366.57	-0.219635
2367.38	2.86853
2368.19	1.04337
2369	-0.591156
2369.82	-1.41733
2370.63	1.10538
2371.44	-3.08255
2372.25	4.90552
2373.06	3.84616
2373.87	1.65955
2374.68	0.189911
2375.49	5.74612
2376.3	0.0380859
2377.11	5.24588
2377.92	-2.5351
2378.73	-4.18314
2379.54	-1.3728
2379.94	0.564972