File: Data/3-Raman/processed/bu04w-a-ff3-fi06-v_150 (500nm)_633nm_edge_100%_x100_vis_lwd_h50um_45sx2_01.txt
#Acq. time (s)=	45
#Accumulations=	2
#Range (cm-¹)=	100...4000
#Windows=	1
#Auto scanning=	Off
#Autofocus=	Off
#Macrospot=	Off
#AutoExposure=	Off
#Spike filter=	Multiple accum.
#Delay time (s)=	2
#Binning=	1
#Readout mode=	Signal
#DeNoise=	Off
#ICS correction=	On
#Dark correction=	Off
#Inst. Process=	Off
#Detector Gain=	Best Dynamic
#Detector ADC=	50 kHz HS
#Detector temperature (°C)=	-60.09
#Instrument=	LabRAM HR Evol
#Detector=	SIN-EM FIVIS
#Objective=	x100_VIS_LWD
#Grating=	150 (500nm)
#ND Filter=	100%
#Laser=	633nm_Edge
#Hole=	49.98
#Temperature=	0
#Range=	Visible
#StageXY=	75x50mm Scan+
#StageZ=	Z motor
#X (µm)=	0
#Y (µm)=	0
#Z (µm)=	-8
#Full time(mm:ss)=	1:34
#Project=	21_11_22
#Sample=	BU04w
#Site=
#Title=	BU04w-A-FF3-FI06-V_150 (500nm)_633nm_Edge_100%_x100_VIS_LWD_H50um_45sX2
#Remark=
#Date=	22.11.2021 11:07
#Acquired=	22.11.2021 11:07:08
#Base:Fit=	16.12.2021 16:15:35
#Base:Edit=	16.12.2021 16:23:51
#Base:Edit=	16.12.2021 16:23:53
#Base:Edit=	16.12.2021 16:23:53
#Base:Edit=	16.12.2021 16:23:54
#Base:Edit=	16.12.2021 16:23:55
#Base:Edit=	16.12.2021 16:23:55
#Base:Edit=	16.12.2021 16:23:56
#Base:Edit=	16.12.2021 16:23:57
#Base:Edit=	16.12.2021 16:23:57
#Base:Sub=	16.12.2021 16:23:59
100.177	256.506
106.695	228.895
113.209	196.939
119.717	165.26
126.219	164.492
132.716	158.308
139.208	164.802
145.694	153.457
152.175	108.94
158.651	128.927
165.121	231.669
171.586	142.936
178.045	58.1542
184.5	38.7217
190.947	20.4231
197.39	-0.464798
203.829	3.85411
210.262	9.33537
216.688	-0.250031
223.11	15.1261
229.527	78.1335
235.939	206.809
242.344	171.088
248.745	53.1381
255.141	37.8714
261.53	53.1603
267.916	22.1233
274.294	21.6087
280.669	40.1759
287.038	46.4603
293.402	25.3055
299.76	10.9021
306.114	18.3404
312.461	45.6997
318.805	136.345
325.142	391.275
331.475	450.935
337.802	225.818
344.123	91.3754
350.441	45.6212
356.752	43.2354
363.058	55.9236
369.36	65.8051
375.656	39.0901
381.947	10.606
388.232	9.5345
394.512	0.210327
400.789	21.1351
407.059	23.3053
413.324	33.9694
419.584	65.4133
425.839	122.232
432.089	181.179
438.333	185.188
444.573	125.275
450.807	102.121
457.037	118.414
463.261	85.4385
469.48	31.3095
475.695	18.3429
481.904	16.6178
488.108	37.2358
494.307	40.1761
500.502	58.0251
506.691	76.8681
512.874	110.694
519.053	101.678
525.227	95.5858
531.396	81.1363
537.559	70.4491
543.718	55.7911
549.873	39.9427
556.022	30.6418
562.165	37.1313
568.304	21.7828
574.437	14.8201
580.567	11.5766
586.691	15.8973
592.81	21.2419
598.924	63.9535
605.033	53.8248
611.138	35.3227
617.236	38.3836
623.332	27.4089
629.42	34.2249
635.506	24.743
641.585	27.2904
647.659	24.0441
653.73	40.4748
659.794	54.8576
665.854	51.416
671.91	24.7824
677.96	9.62206
684.005	-4.61993
690.045	-0.118279
696.082	3.51878
702.113	5.26364
708.139	-7.14429
714.16	5.63268
720.176	3.30276
726.187	2.82258
732.194	-10.8793
738.196	-0.231102
744.193	0.108795
750.185	4.20271
756.173	-8.43472
762.155	3.31263
768.133	5.86488
774.107	-4.70205
780.075	2.48575
786.039	-0.753845
791.998	-3.11417
797.952	1.99354
803.902	-9.96071
809.845	3.48006
815.786	1.76962
821.721	8.45673
827.652	6.6666
833.576	7.80774
839.498	9.09695
845.415	7.68077
851.327	12.8411
857.233	15.2281
863.135	22.3581
869.032	19.1098
874.925	16.69
880.813	31.2414
886.697	28.651
892.576	29.7711
898.45	30.7998
904.318	28.846
910.184	26.8686
916.044	36.1846
921.9	38.1018
927.75	50.4973
933.596	73.4123
939.439	98.573
945.275	148.63
951.107	202.952
956.936	210.795
962.759	189.747
968.577	166.468
974.391	166.89
980.201	193.788
986.006	275.941
991.806	328.069
997.602	280.679
1003.39	229.785
1009.18	217.359
1014.96	216.807
1020.74	298.394
1026.51	350.991
1032.28	279.271
1038.04	153.417
1043.8	114.649
1049.56	93.035
1055.31	67.2897
1061.05	55.9086
1066.8	57.942
1072.53	51.2029
1078.26	74.4963
1083.99	87.0484
1089.72	114.152
1095.44	201.264
1101.15	285.341
1106.86	183.946
1112.56	106.76
1118.27	54.0209
1123.96	54.4358
1129.65	47.0287
1135.34	57.2247
1141.03	97.8985
1146.7	132.694
1152.38	258.095
1158.05	322.168
1163.71	156.528
1169.37	62.9803
1175.03	30.4867
1180.68	32.3359
1186.33	15.7392
1191.98	18.7812
1197.61	15.0917
1203.25	7.59525
1208.88	9.96294
1214.51	1.50922
1220.13	2.95805
1225.74	5.43484
1231.36	2.8976
1236.97	1.28359
1242.57	10.6664
1248.17	3.82839
1253.77	9.03209
1259.36	16.1588
1264.94	13.1165
1270.53	9.07134
1276.11	13.0288
1281.68	233.499
1287.25	22.9212
1292.81	1.93404
1298.38	5.02612
1303.93	15.1732
1309.48	2.42469
1315.03	8.80387
1320.58	4.16036
1326.12	-0.479996
1331.65	-0.0647888
1337.18	4.39088
1342.71	-2.42652
1348.23	3.9874
1353.75	4.24453
1359.26	-1.70963
1364.77	10.7764
1370.28	7.79778
1375.78	12.0032
1381.28	56.2436
1386.77	236.925
1392.26	13.318
1397.74	1.21391
1403.23	12.7541
1408.7	10.9607
1414.17	5.05779
1419.64	4.32373
1425.11	-3.65762
1430.56	-3.35549
1436.02	-2.01448
1441.47	-5.90327
1446.92	3.81545
1452.36	-3.29262
1457.8	-3.11594
1463.23	-4.03107
1468.66	-3.92157
1474.09	4.58826
1479.51	-4.71284
1484.93	-3.50142
1490.34	-0.15271
1495.75	-4.1292
1501.16	2.45346
1506.56	2.73985
1511.96	-3.30579
1517.35	-0.851707
1522.74	1.63133
1528.13	-0.14679
1533.51	-0.843796
1538.88	3.79685
1544.25	4.08091
1549.62	0.99511
1554.99	3.21807
1560.35	0.00657654
1565.71	4.36781
1571.06	6.55759
1576.41	-0.931999
1581.75	-6.20485
1587.09	10.0716
1592.43	10.2282
1597.76	0.716545
1603.09	6.33055
1608.41	1.18282
1613.73	-1.7639
1619.05	5.12151
1624.36	7.68174
1629.67	3.66012
1634.97	7.29176
1640.27	1.98911
1645.57	1.08152
1650.86	2.36234
1656.15	4.72642
1661.43	2.6203
1666.71	4.93388
1671.99	8.3451
1677.26	3.97774
1682.53	5.13996
1687.79	6.25838
1693.05	0.759041
1698.31	5.2905
1703.56	4.52589
1708.81	6.01788
1714.06	0.397636
1719.3	3.99998
1724.53	5.28565
1729.77	5.49176
1735	1.19493
1740.22	5.88286
1745.44	9.4568
1750.66	8.48479
1755.87	0.692886
1761.08	8.69325
1766.29	9.89914
1771.49	11.1185
1776.69	-0.121559
1781.88	0.00682068
1787.07	3.56674
1792.26	2.61166
1797.44	1.65743
1802.62	-0.424137
1807.79	5.51935
1812.96	2.23943
1818.13	5.87099
1823.29	8.35668
1828.45	5.0635
1833.61	5.24676
1838.76	7.75538
1843.91	-6.10361
1849.05	4.52214
1854.19	8.13111
1859.33	8.25637
1864.46	8.402
1869.59	6.20115
1874.71	7.48085
1879.83	6.38836
1884.95	7.6423
1890.06	12.4099
1895.17	4.13045
1900.28	10.0707
1905.38	10.1916
1910.48	7.97545
1915.57	8.19975
1920.66	9.49471
1925.75	3.63434
1930.83	7.34051
1935.91	8.64689
1940.99	0.315556
1946.06	3.97387
1951.13	4.002
1956.19	0.387604
1961.26	7.60481
1966.31	5.16614
1971.36	5.10186
1976.41	5.02782
1981.46	9.7656
1986.5	3.67629
1991.54	10.8259
1996.58	3.55719
2001.61	4.72221
2006.63	4.70899
2011.66	3.51231
2016.68	3.52116
2021.69	10.744
2026.71	7.16287
2031.72	9.64397
2036.72	8.5248
2041.72	4.97769
2046.72	11.1528
2051.71	2.73537
2056.71	10.1141
2061.69	6.55505
2066.68	10.3389
2071.66	3.06715
2076.63	3.14891
2081.6	-0.483505
2086.57	10.6721
2091.54	9.48364
2096.5	10.8209
2101.46	4.72209
2106.41	6.08559
2111.36	7.47343
2116.31	0.113968
2121.25	16.5957
2126.19	10.4662
2131.13	4.28461
2136.06	4.38783
2140.99	0.6642
2145.92	9.64252
2150.84	3.31614
2155.76	7.15978
2160.67	10.9873
2165.58	5.84003
2170.49	12.185
2175.39	4.49549
2180.29	5.72884
2185.19	4.36711
2190.08	8.14597
2194.98	8.11297
2199.86	0.426926
2204.74	1.74077
2209.62	12.0924
2214.5	8.32306
2219.37	9.73031
2224.24	4.6681
2229.11	2.17811
2233.97	4.88592
2238.83	2.38228
2243.68	1.17493
2248.53	3.90296
2253.38	6.6375
2258.22	8.07303
2263.06	5.54014
2267.9	6.93657
2272.73	0.343506
2277.56	3.01058
2282.39	2.99302
2287.21	9.59131
2292.03	6.87832
2296.85	-5.15054
2301.66	10.8138
2306.47	2.8469
2311.28	8.25803
2316.08	7.02156
2320.88	-0.91449
2325.68	19.3875
2330.47	-0.693878
2335.26	-4.61914
2340.04	0.947517
2344.82	5.20695
2349.6	5.40889
2354.38	1.47013
2359.15	-5.28913
2363.92	-1.09682
2368.68	-1.01574
2373.44	7.36662
2378.2	3.28948
2382.95	-2.23381
2387.71	8.88883
2392.45	-0.880676
2397.2	-6.50463
2401.94	-3.78523
2406.68	0.309639
2411.41	0.316528
2416.14	-9.30447
2420.87	4.9754
2425.59	0.800362
2430.31	0.914322
2435.03	2.4667
2439.75	5.4639
2444.46	5.62788
2449.16	0.0897141
2453.87	-1.19303
2458.57	10.43
2463.27	9.16673
2467.96	-3.66072
2472.65	-4.99518
2477.34	6.7248
2482.02	5.40985
2486.7	8.43527
2491.38	10.0016
2496.05	5.72492
2500.72	1.41862
2505.39	2.96118
2510.06	1.54947
2514.72	4.53546
2519.37	-4.26749
2524.03	-1.25735
2528.68	0.273499
2533.33	7.74962
2537.97	3.39268
2542.61	12.4219
2547.25	-2.36171
2551.88	6.70647
2556.51	5.31274
2561.14	8.41396
2565.77	10.055
2570.39	1.16499
2575.01	5.83816
2579.62	5.96147
2584.23	1.48353
2588.84	-1.52039
2593.45	1.52514
2598.05	1.58913
2602.65	0.113243
2607.24	3.20136
2611.84	10.8604
2616.42	12.4047
2621.01	1.71191
2625.59	3.27008
2630.17	3.32841
2634.75	4.98632
2639.32	0.54406
2643.89	5.3667
2648.46	5.56698
2653.02	7.31828
2657.58	4.2994
2662.14	1.24489
2666.69	5.97818
2671.24	10.7703
2675.79	6.23985
2680.33	4.99879
2684.88	5.30102
2689.41	2.41226
2693.95	-0.556885
2698.48	5.91637
2703.01	2.8202
2707.53	2.91051
2712.06	1.37442
2716.57	6.33344
2721.09	6.42923
2725.6	0.0110474
2730.11	8.15948
2734.62	0.0457458
2739.12	6.53714
2743.62	4.94721
2748.12	1.74866
2752.61	-3.00409
2757.1	0.373169
2761.59	6.98527
2766.08	-1.14143
2770.56	-4.36026
2775.04	3.98699
2779.51	2.48348
2783.98	6.00378
2788.45	9.54482
2792.92	3.06092
2797.38	-0.137962
2801.84	1.66401
2806.3	6.81246
2810.75	-9.97381
2815.2	12.0332
2819.65	-1.44593
2824.09	0.301109
2828.53	3.75166
2832.97	3.79826
2837.41	7.24202
2841.84	3.87694
2846.27	2.22757
2850.69	0.588142
2855.12	7.55897
2859.54	-4.35178
2863.95	6.12397
2868.37	2.84379
2872.78	3.00627
2877.18	3.17467
2881.59	10.3499
2885.99	0.0599899
2890.39	1.99859
2894.78	3.9392
2899.18	9.47415
2903.57	15.012
2907.95	4.50156
2912.34	4.62246
2916.72	-2.4555
2921.09	4.82371
2925.47	12.1533
2929.84	1.48436
2934.21	14.2902
2938.57	-1.94363
2942.94	3.5584
2947.29	7.2268
2951.65	5.43009
2956	-0.0287704
2960.36	-3.67617
2964.7	16.4921
2969.05	7.38339
2973.39	12.9579
2977.73	-5.39445
2982.06	3.87704
2986.4	7.67432
2990.73	-8.89671
2995.05	6.07878
2999.38	6.23296
3003.7	12.0237
3008.01	8.46681
3012.33	16.1657
3016.64	1.25761
3020.95	10.9319
3025.26	14.9193
3029.56	-4.03485
3033.86	5.59355
3038.16	3.71188
3042.45	15.3098
3046.74	17.2899
3051.03	5.77353
3055.32	11.6036
3059.6	21.3272
3063.88	11.698
3068.16	15.626
3072.43	19.5665
3076.7	15.7367
3080.97	17.7503
3085.24	21.7473
3089.5	19.9243
3093.76	26.0059
3098.02	22.2921
3102.27	24.4961
3106.52	30.7266
3110.77	27.0508
3115.01	23.3511
3119.26	27.667
3123.5	34.0704
3127.73	32.4427
3131.97	43.0704
3136.2	31.2699
3140.43	39.9014
3144.65	32.0322
3148.87	63.4786
3153.09	65.9185
3157.31	55.8053
3161.52	60.2836
3165.73	56.3758
3169.94	67.1344
3174.15	69.5485
3178.35	76.0616
3182.55	80.4167
3186.75	84.7485
3190.94	97.5548
3195.13	65.8521
3199.32	74.6553
3203.51	81.5352
3207.69	84.2134
3211.87	89.0937
3216.05	87.5685
3220.22	92.5094
3224.39	69.0875
3228.56	58.6363
3232.73	74.4953
3236.89	57.2722
3241.05	57.7275
3245.21	53.7965
3249.36	54.216
3253.52	61.2348
3257.66	54.7255
3261.81	43.8223
3265.95	48.7568
3270.1	35.6307
3274.23	31.4757
3278.37	27.0393
3282.5	40.9293
3286.63	36.5054
3290.76	36.6558
3294.88	36.7891
3299	27.6898
3303.12	20.9061
3307.24	44.2272
3311.35	30.4536
3315.46	14.3027
3319.57	37.74
3323.68	30.9526
3327.78	24.1627
3331.88	12.692
3335.98	43.6515
3340.07	15.6053
3344.16	18.1453
3348.25	13.524
3352.34	30.3176
3356.42	25.7375
3360.5	25.946
3364.58	16.5795
3368.66	23.9602
3372.73	19.3422
3376.8	36.3438
3380.87	29.2537
3384.93	22.1349
3388.99	24.6622
3393.05	27.182
3397.11	10.3609
3401.16	25.0523
3405.21	8.14156
3409.26	25.2563
3413.31	20.472
3417.35	30.3066
3421.39	8.46258
3425.43	23.1768
3429.46	15.9838
3433.5	11.2486
3437.53	18.7773
3441.55	1.82327
3445.58	24.1761
3449.6	14.6374
3453.62	17.4208
3457.64	17.8034
3461.65	15.7321
3465.66	1.1698
3469.67	21.5775
3473.68	21.937
3477.68	14.7797
3481.68	12.6306
3485.68	20.5992
3489.67	15.8934
3493.67	6.05836
3497.66	11.471
3501.64	29.6825
3505.63	12.0285
3509.61	7.10664
3513.59	12.4143
3517.57	12.5873
3521.54	15.3335
3525.52	5.23413
3529.49	10.5652
3533.45	13.4121
3537.42	6.00747
3541.38	8.94997
3545.34	1.48418
3549.29	1.76703
3553.25	14.9649
3557.2	4.81102
3561.15	10.3001
3565.09	8.01321
3569.04	13.6258
3572.98	16.6252
3576.92	-1.33072
3580.85	9.62612
3584.79	12.7457
3588.72	7.93503
3592.64	16.3793
3596.57	6.22375
3600.49	-1.33823
3604.41	-3.58823
3608.33	-0.500015
3612.25	10.656
3616.16	-5.09037
3620.07	14.1898
3623.98	-7.09541
3627.88	9.42899
3631.79	9.71977
3635.69	-6.21087
3639.58	-5.86136
3643.48	-2.73885
3647.37	3.14986
3651.26	-1.9659
3655.15	6.57168
3659.03	-12.1607
3662.92	-0.901123
3666.8	2.19978
3670.67	-2.89158
3674.55	11.1948
3678.42	3.42533
3682.29	-18.0844
3686.16	-3.82986
3690.02	-6.07359
3693.89	-5.56149
3697.75	-7.83626
3701.61	-7.32616
3705.46	-9.61554
3709.31	7.71049
3713.16	-2.96864
3717.01	3.16557
3720.86	6.48631
3724.7	6.97705
3728.54	-3.86941
3732.38	-0.558044
3736.21	5.61214
3740.04	-2.44357
3743.87	6.57572
3747.7	-1.52834
3751.53	-6.81371
3755.35	-9.26663
3759.17	5.44492
3762.99	2.96932
3766.81	0.488449
3770.62	3.76406
3774.43	1.31124
3778.24	7.48014
3782.04	5.0549
3785.85	8.40556
3789.65	3.08949
3793.45	15.1084
3797.24	15.6153
3801.04	4.52115
3804.83	5.02065
3808.62	8.44351
3812.4	6.01816
3816.19	6.49697
3819.97	4.03608
3823.75	-4.3288
3827.52	7.8611
3831.3	14.21
3835.07	8.76427
3838.84	-8.55737
3842.61	0.751961
3846.37	15.9689
3850.13	19.2832
3853.89	13.6705
3857.65	-0.885418
3861.41	20.2062
3865.16	5.67627
3868.91	12.066
3872.66	9.41035
3876.4	-2.25657
3880.14	3.99363
3883.89	-4.71143
3887.62	7.53549
3891.36	13.8108
3895.09	8.12695
3898.82	2.39636
3902.55	-0.349594
3906.28	11.9631
3910	3.14117
3913.73	12.4602
3917.45	6.65223
3921.16	6.91064
3924.88	10.2034
3928.59	4.31817
3932.3	13.6749
3936.01	16.8874
3939.71	10.8919
3943.42	17.1914
3947.12	11.164
3950.81	5.07893
3954.51	8.20892
3958.2	8.22116
3961.9	20.5718
3965.58	14.32
3969.27	11.1114
3972.96	1.68104
3976.64	7.72921
3980.32	10.6388
3984	10.4084
3987.67	0.853165
3991.34	-2.5116
3995.01	0.323254
3998.68	9.37115