File: Data/3-Raman/processed/bu04w-a-ff3-fi03-v_1800 (450-850nm)_633nm_edge_100%_x100_vis_lwd_h50um_45sx2_01.txt
#Acq. time (s)=	45
#Accumulations=	2
#Range (cm-¹)=	1200...2399
#Windows=	6
#Auto scanning=	Off
#Autofocus=	Off
#Macrospot=	Off
#AutoExposure=	Off
#Spike filter=	Multiple accum.
#Delay time (s)=	2
#Binning=	1
#Readout mode=	Signal
#DeNoise=	Off
#ICS correction=	On
#Dark correction=	Off
#Inst. Process=	Off
#Detector Gain=	Best Dynamic
#Detector ADC=	50 kHz EM
#Detector EM gain=	100
#Detector temperature (°C)=	-60.09
#Instrument=	LabRAM HR Evol
#Detector=	SIN-EM FIVIS
#Objective=	x100_VIS_LWD
#Grating=	1800 (450-850nm)
#ND Filter=	100%
#Laser=	633nm_Edge
#Hole=	49.98
#Temperature=	0
#Range=	Visible
#StageXY=	75x50mm Scan+
#StageZ=	Z motor
#X (µm)=	0
#Y (µm)=	0
#Z (µm)=	57.9
#Full time(mm:ss)=	9:32
#Project=	21_11_22
#Sample=	BU04w
#Site=
#Title=	BU04w-A-FF3-FI03-V_1800 (450-850nm)_633nm_Edge_100%_x100_VIS_LWD_H50um_45sX2
#Remark=
#Date=	22.11.2021 12:24
#Acquired=	22.11.2021 12:24:12
#Base:Fit=	16.12.2021 16:15:35
#Base:Fit=	16.12.2021 16:22:50
#Base:Sub=	16.12.2021 16:22:52
1201.04	4.48245
1202.08	11.0354
1203.11	0.722443
1204.14	8.14972
1205.17	-2.07129
1206.2	0.962982
1207.24	3.20654
1208.27	2.61261
1209.3	1.32523
1210.33	-0.726105
1211.36	5.3288
1212.39	1.87997
1213.42	-1.09579
1214.45	2.72983
1215.48	-3.32922
1216.51	1.03397
1217.54	-1.86398
1218.56	2.61603
1219.59	7.2095
1220.62	7.81934
1221.65	-3.76321
1222.68	1.24966
1223.7	-3.13522
1224.73	5.42282
1225.76	-2.34537
1226.78	-0.136841
1227.81	-1.30365
1228.84	-0.195007
1229.86	1.24814
1230.89	2.59741
1231.91	-0.479492
1232.94	-3.82962
1233.96	-2.33984
1234.99	1.06519
1236.01	0.890594
1237.03	3.27512
1238.06	-3.31183
1239.08	2.12704
1240.1	-5.26337
1241.13	-0.566223
1242.15	4.2562
1243.17	0.556091
1244.19	5.99435
1245.21	0.801453
1246.24	2.71924
1247.26	5.6319
1248.28	-0.0558472
1249.3	-2.08704
1250.32	6.45206
1251.34	3.62155
1252.36	2.11642
1253.38	5.65079
1254.4	8.15396
1255.42	1.61166
1256.44	3.66779
1257.46	6.4418
1258.47	0.747711
1259.49	0.53952
1260.51	0.617035
1261.53	4.12964
1262.55	10.4987
1263.56	12.157
1264.58	23.9915
1265.6	7.98718
1266.61	5.41257
1267.63	-0.638275
1268.65	17.5756
1269.66	8.87057
1270.68	-2.0043
1271.69	6.92783
1272.71	2.98041
1273.72	4.61105
1274.74	2.02853
1275.75	4.49521
1276.76	3.88364
1277.78	-1.28622
1278.79	8.36218
1279.8	0.458405
1280.82	2.49573
1281.83	15.085
1282.84	59.7751
1283.85	200.486
1284.86	211.665
1285.88	21.1343
1286.89	8.51566
1287.9	9.59448
1288.91	1.28128
1289.92	3.9595
1290.93	-2.2431
1291.94	6.45242
1292.95	1.03607
1293.96	4.23215
1294.97	-1.23312
1295.98	3.91284
1296.99	-0.760986
1297.99	-3.64911
1299	0.432587
1300.01	-4.36484
1301.02	-6.63934
1302.03	-3.61514
1303.03	0.175323
1304.04	-0.246765
1305.05	1.8483
1306.05	2.2041
1307.06	4.98526
1308.06	11.3927
1309.07	8.05316
1310.07	-2.8967
1311.08	7.10687
1312.08	2.60983
1313.09	-4.54059
1314.09	0.0437622
1315.1	-0.798248
1316.1	1.80353
1317.1	-3.94043
1318.11	4.5014
1319.11	2.46692
1320.11	1.88031
1321.12	0.589417
1322.12	3.19553
1323.12	2.66248
1324.12	1.91129
1325.12	-0.358917
1326.13	7.5661
1327.13	-0.157013
1328.13	1.95941
1329.13	2.44431
1330.13	2.54807
1331.13	1.73871
1332.13	3.81467
1333.13	0.0796814
1334.13	10.7026
1335.13	0.671204
1336.12	12.0753
1337.12	6.19498
1338.12	1.31061
1339.12	11.7247
1340.12	6.13623
1341.11	9.62186
1342.11	11.1487
1343.11	3.96008
1344.1	6.31256
1345.1	6.5463
1346.1	8.73956
1347.09	9.37479
1348.09	4.14758
1349.08	8.17499
1350.08	2.59238
1351.07	1.66263
1352.07	10.2381
1353.06	4.14926
1354.06	9.27097
1355.05	3.42957
1356.04	9.64362
1357.04	13.4948
1358.03	8.95761
1359.02	13.3654
1360.02	5.54285
1361.01	10.1044
1362	9.12021
1362.99	4.00357
1363.98	12.3347
1364.98	9.3649
1365.97	6.64429
1366.96	5.10031
1367.95	12.0938
1368.94	10.8971
1369.93	13.6276
1370.92	5.44049
1371.91	2.6011
1372.9	4.79852
1373.89	14.1577
1374.87	7.52777
1375.86	10.7673
1376.85	5.90933
1377.84	6.18628
1378.83	5.86639
1379.81	14.3607
1380.8	11.8406
1381.79	13.7687
1382.78	10.6265
1383.76	12.0793
1384.75	17.2742
1385.73	29.7542
1386.72	139.004
1387.7	684.75
1388.69	57.8745
1389.68	20.6948
1390.66	6.37274
1391.64	15.4838
1392.63	6.89072
1393.61	7.1954
1394.6	10.5301
1395.58	7.73727
1396.56	7.40271
1397.55	6.10568
1398.53	-4.84918
1399.51	8.83096
1400.49	2.84567
1401.47	9.16669
1402.46	9.6001
1403.44	3.48514
1404.42	3.73395
1405.4	5.70819
1406.38	0.92276
1407.36	12.5315
1408.34	19.1338
1409.32	36.0379
1410.3	16.9179
1411.28	3.76593
1412.26	14.8595
1413.24	5.27948
1414.22	1.89996
1415.19	2.61496
1416.17	11.4609
1417.15	3.02054
1418.13	15.3134
1419.11	6.07257
1420.08	5.09589
1421.06	10.5891
1422.04	4.72876
1423.01	5.43863
1423.99	3.71393
1424.97	-1.53314
1425.94	8.80011
1426.92	5.88031
1427.89	1.00943
1428.87	-0.889191
1429.84	4.74478
1430.82	7.83865
1431.79	4.79074
1432.76	1.88156
1433.74	10.4561
1434.71	0.769165
1435.68	0.663666
1436.66	4.54803
1437.63	9.07166
1438.6	0.436432
1439.57	0.941589
1440.54	6.00659
1441.52	7.48126
1442.49	1.53632
1443.46	5.24866
1444.43	4.83578
1445.4	8.52618
1446.37	4.9552
1447.34	2.71848
1448.31	-0.60437
1449.28	5.47272
1450.25	3.30923
1451.22	1.45309
1452.19	5.25278
1453.16	9.37103
1454.12	8.33252
1455.09	7.91522
1456.06	2.09448
1457.03	8.06891
1457.99	4.46906
1458.96	3.26544
1459.93	4.09525
1460.9	2.23065
1461.86	1.31015
1462.83	1.87924
1463.79	3.86111
1464.76	3.75085
1465.72	0.914825
1466.69	7.55444
1467.59	3.94467
1468.57	0.90152
1469.56	2.26657
1470.53	3.24829
1471.51	-1.29718
1472.49	4.37524
1473.47	2.42508
1474.45	5.06403
1475.43	0.596039
1476.41	3.15057
1477.39	-2.48322
1478.36	17.9016
1479.34	-0.272675
1480.32	-3.33585
1481.3	1.21228
1482.27	8.74759
1483.25	-2.3392
1484.23	2.34406
1485.2	7.15585
1486.18	-1.88739
1487.15	0.508087
1488.13	-1.13223
1489.1	2.43958
1490.08	2.77734
1491.06	0.592224
1492.03	1.57605
1493	1.38351
1493.98	1.73193
1494.95	-2.04672
1495.92	-5.83636
1496.9	-3.64337
1497.87	-3.30804
1498.84	3.3909
1499.82	1.29126
1500.79	0.2771
1501.76	0.281647
1502.73	-3.10657
1503.7	0.833679
1504.68	-0.210632
1505.65	-0.793365
1506.62	2.34393
1507.59	-0.12146
1508.56	0.942505
1509.53	2.14316
1510.5	7.52924
1511.47	-2.20728
1512.44	-0.175659
1513.4	5.14484
1514.37	0.744537
1515.34	-1.82919
1516.31	2.57068
1517.28	3.11679
1518.25	4.21722
1519.21	1.97937
1520.18	1.40967
1521.15	3.53989
1522.12	3.99136
1523.08	-0.527649
1524.05	8.42181
1525.02	2.79675
1525.98	-1.36093
1526.95	5.81134
1527.91	1.09573
1528.88	-0.258698
1529.84	-0.475433
1530.81	0.742828
1531.77	1.0083
1532.74	-0.124146
1533.7	0.715912
1534.66	4.66898
1535.63	4.65536
1536.59	1.96136
1537.55	-3.10394
1538.52	4.83835
1539.48	1.18762
1540.44	3.62411
1541.4	-0.94696
1542.36	0.76767
1543.33	8.38428
1544.29	2.70221
1545.25	2.6795
1546.21	-1.15714
1547.17	-0.429657
1548.13	2.6691
1549.09	5.48877
1550.05	1.4978
1551.01	3.49216
1551.97	3.72141
1552.93	2.96146
1553.89	7.40338
1554.84	6.10284
1555.8	13.3774
1556.76	-2.30905
1557.72	3.67261
1558.68	0.830505
1559.63	8.8616
1560.59	1.96979
1561.55	3.80637
1562.5	3.91339
1563.46	7.21866
1564.42	3.00711
1565.37	0.486328
1566.33	-1.77802
1567.28	1.09119
1568.24	5.02817
1569.19	2.85989
1570.15	11.3308
1571.1	1.44211
1572.06	4.6749
1573.01	1.03162
1573.96	1.19022
1574.92	4.21814
1575.87	3.50073
1576.82	3.71036
1577.78	6.56073
1578.73	0.231415
1579.68	1.70099
1580.63	2.70093
1581.59	-1.5618
1582.54	-0.189178
1583.49	3.89401
1584.44	8.66769
1585.39	0.46521
1586.34	1.46548
1587.29	0.94873
1588.24	3.60092
1589.19	3.27048
1590.14	-0.28598
1591.09	2.43646
1592.04	-2.90225
1592.99	-0.62619
1593.94	-2.53864
1594.88	2.21545
1595.83	2.6915
1596.78	-0.282928
1597.73	2.66885
1598.68	0.48761
1599.62	1.10577
1600.57	-2.08484
1601.52	2.97888
1602.46	1.68353
1603.41	6.62839
1604.35	0.353821
1605.3	4.7041
1606.25	4.14377
1607.19	-4.25089
1608.14	-3.87488
1609.08	-1.5741
1610.03	11.3645
1610.97	-2.39548
1611.91	-2.54053
1612.86	5.25665
1613.8	2.90955
1614.75	-3.46701
1615.69	3.03159
1616.63	-2.44925
1617.57	-0.618744
1618.52	1.8551
1619.46	1.31064
1620.4	4.81961
1621.34	1.53564
1622.28	5.42755
1623.22	5.50281
1624.16	16.2326
1625.11	11.6021
1626.05	-2.01413
1626.99	4.02802
1627.93	3.02243
1628.87	3.73959
1629.8	2.32013
1630.74	2.1738
1631.68	-3.71381
1632.62	2.47226
1633.56	1.89728
1634.5	4.81705
1635.44	8.27042
1636.37	-0.487061
1637.31	7.17432
1638.25	5.14099
1639.19	5.94492
1640.12	2.58951
1641.06	13.0274
1642	5.72958
1642.93	4.06403
1643.87	7.01547
1644.8	9.96924
1645.74	7.18854
1646.67	3.42157
1647.61	4.27219
1648.54	4.65781
1649.48	4.88812
1650.41	10.5573
1651.35	2.28479
1652.28	3.4248
1653.21	4.14862
1654.15	7.26273
1655.08	5.99936
1656.01	5.26312
1656.94	4.82288
1657.88	4.59171
1658.81	6.61942
1659.74	0.325836
1660.67	2.44974
1661.6	3.73254
1662.53	6.87415
1663.46	7.03915
1664.39	2.90921
1665.33	8.78867
1666.26	7.12546
1667.18	2.95023
1668.11	9.58456
1669.04	4.9353
1669.97	4.93204
1670.9	0.0192261
1671.83	4.41849
1672.76	6.34885
1673.69	6.55511
1674.61	2.18811
1675.54	0.947021
1676.47	3.8064
1677.4	5.84195
1678.32	3.88803
1679.25	7.49194
1680.18	11.9968
1681.1	5.64771
1682.03	9.09616
1682.96	1.41946
1683.88	7.98328
1684.81	0.709839
1685.73	-2.1366
1686.66	2.90259
1687.58	1.10812
1688.5	2.60025
1689.43	2.60229
1690.35	2.44714
1691.28	0.436554
1692.2	0.334045
1693.12	5.12704
1694.05	-1.40668
1694.97	2.5047
1695.89	-1.1738
1696.81	1.98978
1697.74	0.871582
1698.66	1.1976
1699.58	1.12555
1700.5	-0.624054
1701.42	2.73376
1702.34	-2.90579
1703.26	-1.09085
1704.18	0.348999
1705.1	3.38248
1705.94	2.09085
1706.88	5.36575
1707.81	1.87253
1708.74	2.10651
1709.68	2.71353
1710.61	3.871
1711.55	-2.09918
1712.48	3.93127
1713.41	-3.4252
1714.35	0.843048
1715.28	8.88608
1716.21	2.70621
1717.14	-0.381836
1718.08	4.7276
1719.01	1.71948
1719.94	3.99332
1720.87	9.97943
1721.8	1.6282
1722.73	0.0382996
1723.66	-0.975983
1724.6	-2.36899
1725.53	2.34039
1726.45	1.55182
1727.38	1.02921
1728.31	-1.53702
1729.24	-3.84744
1730.17	1.64374
1731.1	0.897339
1732.03	-0.809296
1732.96	-1.03946
1733.89	-3.9314
1734.82	1.38898
1735.74	0.348816
1736.67	1.59991
1737.6	3.70175
1738.52	4.61975
1739.45	0.82785
1740.38	-1.97586
1741.3	3.35751
1742.23	-1.79605
1743.16	-1.14316
1744.08	0.823944
1745.01	-4.86444
1745.93	2.22943
1746.86	-1.57861
1747.78	6.57996
1748.71	-0.317352
1749.63	5.42667
1750.55	3.27811
1751.48	1.96857
1752.4	-1.59561
1753.33	6.27786
1754.25	4.31158
1755.17	-4.78198
1756.09	-0.589172
1757.02	0.613861
1757.94	-6.21268
1758.86	-1.66718
1759.78	0.559601
1760.7	2.99692
1761.62	4.42667
1762.54	4.24542
1763.47	6.12787
1764.39	4.50925
1765.31	4.46393
1766.23	-1.72226
1767.15	-3.65625
1768.07	-0.644684
1768.99	-2.22171
1769.9	1.15256
1770.82	0.280884
1771.74	-0.538666
1772.66	4.27124
1773.58	-1.50226
1774.5	-3.5592
1775.41	-0.318359
1776.33	-2.05444
1777.25	-0.0919189
1778.17	1.98682
1779.08	3.49524
1780	4.46249
1780.92	-1.90646
1781.83	-1.3811
1782.75	-1.92178
1783.66	-0.0254517
1784.58	0.49115
1785.49	3.28101
1786.41	0.537231
1787.32	-4.75604
1788.24	-3.60446
1789.15	6.45517
1790.07	-1.37396
1790.98	3.28235
1791.89	-0.884033
1792.81	-2.55078
1793.72	-3.37497
1794.63	-2.09113
1795.54	4.54352
1796.46	-3.27151
1797.37	0.239655
1798.28	-0.805237
1799.19	-0.975983
1800.1	-4.53781
1801.02	-0.400818
1801.93	6.53922
1802.84	3.27405
1803.75	0.943085
1804.66	2.78357
1805.57	0.0723572
1806.48	-1.4762
1807.39	-0.169647
1808.3	-1.13815
1809.21	0.800568
1810.12	-2.17392
1811.02	-1.73071
1811.93	0.245087
1812.84	2.64001
1813.75	-9.31311
1814.66	-0.315735
1815.56	-1.85718
1816.47	-3.16165
1817.38	-2.62958
1818.29	-0.980438
1819.19	5.15256
1820.1	5.57529
1821.01	-1.5549
1821.91	0.713348
1822.82	-0.100372
1823.72	-1.39172
1824.63	1.1297
1825.53	2.10913
1826.44	1.86237
1827.34	2.90546
1828.25	3.48169
1829.15	-5.76559
1830.05	1.4711
1830.96	1.07043
1831.86	2.57547
1832.76	7.77469
1833.67	4.6846
1834.57	3.58267
1835.47	1.88995
1836.37	5.09052
1837.28	1.1496
1838.18	0.472443
1839.08	-2.19058
1839.98	6.36661
1840.88	-0.648376
1841.78	-0.848083
1842.68	-0.141052
1843.58	10.3779
1844.48	3.06519
1845.38	3.19473
1846.28	-1.34116
1847.18	6.46527
1848.08	5.72577
1848.98	6.1749
1849.88	2.1395
1850.78	10.7617
1851.68	5.85992
1852.57	3.0257
1853.47	0.00512695
1854.37	3.53665
1855.27	5.19073
1856.16	0.738617
1857.06	-2.00064
1857.96	3.26123
1858.86	3.00665
1859.75	4.69077
1860.65	10.3062
1861.54	3.96817
1862.44	11.1496
1863.33	5.33255
1864.23	9.26395
1865.12	7.48984
1866.02	4.17477
1866.91	4.06561
1867.81	3.72415
1868.7	8.74973
1869.59	4.13535
1870.49	2.21118
1871.38	6.38391
1872.27	3.11444
1873.17	4.05862
1874.06	5.89487
1874.95	6.28394
1875.84	7.14307
1876.74	0.945892
1877.63	0.0602417
1878.52	11.4231
1879.41	7.77335
1880.3	10.6581
1881.19	6.10657
1882.08	-4.12137
1882.97	12.293
1883.86	5.68079
1884.75	9.62967
1885.64	-0.0865784
1886.53	4.65289
1887.42	7.60635
1888.31	1.75925
1889.2	2.01511
1890.09	2.18298
1890.98	4.64032
1891.86	3.17792
1892.75	3.93295
1893.64	3.69531
1894.53	8.98611
1895.41	2.4519
1896.3	2.94189
1897.19	12.8036
1898.07	6.99628
1898.96	-0.90509
1899.85	0.402863
1900.73	10.3311
1901.62	-0.487152
1902.5	13.0679
1903.39	2.32016
1904.27	0.439606
1905.16	10.3034
1906.04	4.93192
1906.92	8.25284
1907.81	5.10153
1908.69	10.5877
1909.58	7.2868
1910.46	8.30087
1911.34	7.46448
1912.23	11.127
1913.11	6.11099
1913.99	1.8396
1914.87	6.96542
1915.75	5.53714
1916.64	5.63913
1917.52	4.14243
1918.4	7.15378
1919.28	7.7326
1920.16	-0.730133
1921.04	5.75229
1921.92	5.88889
1922.8	6.75009
1923.68	5.62677
1924.56	5.9559
1925.44	7.13232
1926.32	8.43326
1927.2	7.24005
1928.08	2.14865
1928.95	4.55612
1929.83	6.00436
1930.64	8.14075
1931.53	7.00208
1932.43	2.7522
1933.32	4.46893
1934.21	6.48117
1935.1	8.53366
1935.99	5.46994
1936.89	7.90988
1937.78	6.0126
1938.67	26.1692
1939.56	12.669
1940.45	8.7666
1941.34	2.42957
1942.23	3.21558
1943.12	7.05515
1944.01	13.2087
1944.9	10.5831
1945.79	10.8613
1946.68	7.52368
1947.57	3.36072
1948.46	8.47839
1949.35	2.94891
1950.23	4.60318
1951.12	6.68948
1952.01	5.46527
1952.9	6.47964
1953.79	8.58929
1954.67	4.89694
1955.56	7.64413
1956.45	4.17798
1957.33	4.07892
1958.22	6.04929
1959.1	7.38715
1959.99	6.14627
1960.88	6.54861
1961.76	-1.03464
1962.65	11.3765
1963.53	0.640686
1964.42	6.32071
1965.3	13.0817
1966.19	6.07758
1967.07	4.15622
1967.95	10.4451
1968.84	4.15945
1969.72	6.88885
1970.6	5.12521
1971.49	6.25775
1972.37	0.921265
1973.25	5.42688
1974.13	6.43665
1975.02	2.92404
1975.9	6.48642
1976.78	2.19623
1977.66	8.3566
1978.54	2.21426
1979.42	-2.20248
1980.3	3.57758
1981.18	4.21735
1982.06	3.43744
1982.94	4.32959
1983.82	1.65964
1984.7	2.32748
1985.58	4.54871
1986.46	2.935
1987.34	2.21231
1988.22	2.75323
1989.1	3.81497
1989.98	3.34177
1990.85	4.28104
1991.73	1.44809
1992.61	9.98239
1993.49	3.65536
1994.36	1.54208
1995.24	3.5994
1996.12	5.23108
1996.99	-2.54187
1997.87	-0.70163
1998.75	7.15512
1999.62	0.700256
2000.5	-1.91342
2001.37	8.57019
2002.25	5.60306
2003.12	0.0923767
2004	1.29449
2004.87	4.57242
2005.75	3.14551
2006.62	1.52435
2007.5	-5.03751
2008.37	5.98779
2009.24	7.10287
2010.12	4.69016
2010.99	1.49054
2011.86	-3.8508
2012.73	2.40326
2013.61	9.7543
2014.48	0.0933838
2015.35	2.90857
2016.22	2.56741
2017.09	-0.540833
2017.96	3.5831
2018.84	4.35806
2019.71	-4.1178
2020.58	-0.238434
2021.45	-2.6261
2022.32	-0.31189
2023.19	-4.26285
2024.06	8.1532
2024.93	-2.54059
2025.8	-1.72165
2026.67	3.88254
2027.53	4.2587
2028.4	-2.57697
2029.27	5.93765
2030.14	-3.86133
2031.01	2.30328
2031.87	-2.71973
2032.74	-2.65927
2033.61	-1.94492
2034.48	-0.662659
2035.34	7.47903
2036.21	-0.185333
2037.08	-1.87415
2037.94	1.55911
2038.81	2.53073
2039.67	6.17313
2040.54	-3.08859
2041.41	0.5867
2042.27	0.0180054
2043.13	-1.61304
2044	-0.98584
2044.86	-6.80936
2045.73	-0.983734
2046.59	7.69653
2047.46	4.22925
2048.32	3.89398
2049.18	0.0953064
2050.05	-2.43521
2050.91	-0.567047
2051.77	0.567474
2052.63	-0.765015
2053.49	-1.34863
2054.36	-3.40842
2055.22	2.02994
2056.08	-1.12222
2056.94	-4.10095
2057.8	1.03778
2058.66	0.0700378
2059.52	-1.30334
2060.39	0.688568
2061.24	2.69357
2062.1	-0.413269
2062.97	5.23666
2063.83	-3.22238
2064.68	5.99554
2065.54	6.23795
2066.4	0.975555
2067.26	2.90771
2068.12	0.898499
2068.98	0.114227
2069.84	0.327515
2070.69	3.01367
2071.55	-4.77292
2072.41	-0.685333
2073.27	1.88733
2074.12	4.95126
2074.98	-2.93524
2075.84	-3.43393
2076.69	1.90302
2077.55	3.17828
2078.4	-1.00165
2079.26	2.30331
2080.11	5.65527
2080.97	-1.54956
2081.82	9.26648
2082.68	2.77112
2083.53	4.4787
2084.39	7.7951
2085.24	0.0183716
2086.1	0.325623
2086.95	-0.0903015
2087.8	3.83713
2088.66	-1.11581
2089.51	2.97977
2090.36	5.1933
2091.22	7.69333
2092.07	2.37506
2092.92	3.14911
2093.77	6.44147
2094.62	3.44958
2095.47	0.173798
2096.33	3.89496
2097.18	3.47705
2098.03	-0.183502
2098.88	-0.597168
2099.73	-0.24295
2100.58	2.02597
2101.43	7.62222
2102.28	7.48337
2103.13	6.91696
2103.98	5.38474
2104.83	-0.977386
2105.67	0.122772
2106.52	7.98215
2107.37	7.95978
2108.22	6.62976
2109.07	6.22784
2109.92	2.60828
2110.76	1.10928
2111.61	9.33975
2112.46	4.74762
2113.31	3.11172
2114.15	5.39746
2115	13.1142
2115.84	5.93152
2116.69	4.16132
2117.54	4.51382
2118.38	1.08447
2119.23	3.32608
2120.07	10.1184
2120.92	7.48544
2121.76	10.9131
2122.61	6.33923
2123.45	7.64609
2124.29	11.1301
2125.14	3.49146
2125.98	1.22586
2126.83	4.81094
2127.67	7.00418
2128.51	-1.24338
2129.35	7.93393
2130.2	6.02917
2131.04	6.62302
2131.88	4.83142
2132.72	9.63239
2133.57	7.23837
2134.41	5.13266
2135.25	0.921509
2136.09	6.71936
2136.93	6.4639
2137.77	11.5301
2138.61	2.95865
2139.45	8.0217
2140.29	5.79761
2141.13	7.49399
2141.97	6.53656
2142.81	5.21933
2143.65	5.39847
2144.49	5.6597
2145.33	6.54037
2146.16	12.8078
2147.01	7.49911
2147.86	8.86313
2148.72	5.84088
2149.57	7.78311
2150.42	7.29181
2151.27	2.41241
2152.12	4.44223
2152.98	4.60825
2153.83	3.7948
2154.68	22.7383
2155.53	6.92758
2156.38	12.9681
2157.23	11.4669
2158.08	2.43954
2158.93	11.8394
2159.78	7.46017
2160.63	6.41959
2161.48	6.92877
2162.33	2.31497
2163.18	0.33667
2164.03	1.29108
2164.88	4.41891
2165.73	5.60321
2166.58	8.76093
2167.42	5.87289
2168.27	3.9198
2169.12	-0.0977478
2169.97	2.43927
2170.81	1.80399
2171.66	5.18088
2172.51	13.3117
2173.35	0.848053
2174.2	6.41391
2175.05	7.58597
2175.89	8.02963
2176.74	5.974
2177.58	3.56223
2178.43	7.41357
2179.27	3.30405
2180.12	5.01895
2180.96	5.02429
2181.81	6.23688
2182.65	-1.42786
2183.5	2.7056
2184.34	3.98938
2185.18	4.13617
2186.03	2.72348
2186.87	10.4096
2187.71	5.19806
2188.56	1.07278
2189.4	7.28693
2190.24	3.81696
2191.08	-3.35056
2191.93	-1.08585
2192.77	0.103668
2193.61	5.7944
2194.45	0.0541382
2195.29	3.03369
2196.13	2.63419
2196.97	3.97922
2197.81	2.71811
2198.65	5.10516
2199.49	0.438782
2200.33	3.15558
2201.17	-0.378967
2202.01	0.0630188
2202.85	9.72653
2203.69	-1.13254
2204.53	1.54507
2205.37	-3.8511
2206.21	7.97714
2207.04	-0.0149536
2207.88	-3.26392
2208.72	1.27075
2209.56	0.191284
2210.4	0.201721
2211.23	-0.650269
2212.07	-1.03061
2212.91	1.88464
2213.74	0.543945
2214.58	1.9783
2215.41	-6.52966
2216.25	-0.423553
2217.09	0.456024
2217.92	-2.64691
2218.76	-3.61722
2219.59	-0.757477
2220.43	-0.13681
2221.26	-1.95712
2222.1	2.12662
2222.93	-1.63824
2223.76	0.914764
2224.6	1.0903
2225.43	7.35309
2226.26	5.31644
2227.1	6.90106
2227.93	4.21167
2228.76	-3.32739
2229.6	1.3884
2230.43	-2.9071
2231.26	-0.904724
2232.09	-0.521576
2232.92	4.11273
2233.76	-1.93094
2234.59	5.1485
2235.42	4.32083
2236.25	3.80606
2237.08	-2.9639
2237.91	0.434631
2238.74	2.64993
2239.57	3.47934
2240.4	7.42343
2241.23	-3.93393
2242.06	2.98807
2242.89	1.68774
2243.72	-3.34634
2244.54	-1.32364
2245.37	2.39319
2246.2	5.75717
2247.03	12.3208
2247.86	0.421082
2248.68	0.926697
2249.51	1.83044
2250.34	9.20316
2251.17	5.70322
2251.99	-4.58423
2252.82	8.46161
2253.65	2.31747
2254.47	-1.06665
2255.3	3.50534
2256.12	4.6239
2256.95	1.86993
2257.77	-0.108551
2258.6	0.388794
2259.42	-1.45044
2260.25	6.95328
2261.07	-2.54797
2261.9	1.86484
2262.72	1.19843
2263.54	7.28027
2264.37	5.10727
2265.19	-0.410126
2266.02	3.1944
2266.84	0.222443
2267.66	1.45889
2268.48	8.64279
2269.31	1.81693
2270.13	6.78616
2270.95	3.56671
2271.77	9.45886
2272.59	7.09915
2273.42	6.68948
2274.24	3.89063
2275.06	3.80692
2275.88	-0.364868
2276.7	-2.737
2277.52	4.88571
2278.34	6.9751
2279.16	-0.94339
2279.98	3.74039
2280.8	4.62036
2281.62	2.84409
2282.44	15.3942
2283.25	1.91791
2284.07	-1.96078
2284.89	5.41049
2285.71	3.0264
2286.53	-0.951599
2287.35	3.00922
2288.16	6.55881
2288.98	-2.99448
2289.8	3.84912
2290.61	4.81784
2291.43	5.85001
2292.25	-0.168488
2293.06	0.573425
2293.88	-3.96695
2294.7	-1.04654
2295.51	6.4679
2296.33	2.24393
2297.14	2.51599
2297.96	-0.777527
2298.77	2.09579
2299.59	-5.01437
2300.4	3.34698
2301.22	5.04413
2302.03	3.64166
2302.84	1.74899
2303.66	-3.32291
2304.47	7.95599
2305.28	9.47775
2306.1	-2.2587
2306.91	-1.85065
2307.72	1.35223
2308.53	3.14807
2309.35	-2.07825
2310.16	6.37848
2310.97	-0.551117
2311.78	-5.58752
2312.59	-1.73907
2313.4	1.5127
2314.22	2.40286
2315.03	3.76602
2315.84	-3.3656
2316.65	-1.42786
2317.46	-1.23639
2318.27	-1.80692
2319.08	-1.23129
2319.89	0.286652
2320.69	0.695221
2321.5	-0.709747
2322.31	-0.724609
2323.12	0.123474
2323.93	3.27597
2324.74	-1.51071
2325.55	-5.85181
2326.35	-3.52112
2327.16	7.99902
2327.97	20.0513
2328.78	9.4346
2329.58	3.24896
2330.39	7.88306
2331.2	-2.67548
2332	4.2782
2332.81	1.65372
2333.61	5.90683
2334.42	2.86365
2335.23	0.83252
2336.03	1.99887
2336.84	0.81488
2337.64	-2.35519
2338.45	1.33597
2339.25	3.33362
2340.05	1.64716
2340.86	-0.592743
2341.66	0.243469
2342.47	0.28537
2343.27	-1.17944
2344.07	0.288849
2344.87	1.09979
2345.68	-0.775604
2346.48	1.01071
2347.28	2.70947
2348.08	0.975311
2348.89	3.50565
2349.69	3.44925
2350.49	-0.90509
2351.29	-0.684296
2352.09	5.32147
2352.89	0.442993
2353.71	2.39499
2354.52	-2.20697
2355.34	5.7876
2356.15	-2.81424
2356.96	1.59805
2357.78	3.33636
2358.59	-1.3494
2359.41	-1.23929
2360.22	-0.0215454
2361.03	-0.414551
2361.85	1.81146
2362.66	3.97861
2363.47	6.34885
2364.29	-4.27643
2365.1	2.02414
2365.91	3.74442
2366.72	4.08664
2367.54	-0.00704956
2368.35	-2.75772
2369.16	3.06976
2369.97	1.67548
2370.78	3.38504
2371.59	-1.27795
2372.4	11.9218
2373.21	-1.72464
2374.02	1.35019
2374.83	6.11276
2375.64	0.695648
2376.45	0.825958
2377.26	-1.28928
2378.07	2.45038
2378.88	2.79459
2379.69	1.51578
2380.5	1.26285
2381.31	-1.23129
2382.12	6.62595
2382.92	0.140381
2383.73	8.28503
2384.54	-1.76126
2385.35	2.92258
2386.15	8.5192
2386.96	-0.305054
2387.77	2.53174
2388.57	-0.132202
2389.38	0.784882
2390.19	-2.04501
2390.99	-2.1868
2391.8	5.28448
2392.6	-0.744904
2393.41	2.56693
2394.22	2.85971
2395.02	0.527039
2395.83	-1.43777
2396.63	3.55145
2397.44	-2.91071
2398.24	-0.809204
2399.04	-5.51831
2399.85	0.460602
2399.98	-0.706848