File: Data/3-Raman/processed/bu04w-a-ff3-fi02-l_150 (500nm)_633nm_edge_100%_x100_vis_lwd_h50um_45sx2_01.txt
#Acq. time (s)=	45
#Accumulations=	2
#Range (cm-¹)=	100...4000
#Windows=	1
#Auto scanning=	Off
#Autofocus=	Off
#Macrospot=	Off
#AutoExposure=	Off
#Spike filter=	Multiple accum.
#Delay time (s)=	2
#Binning=	1
#Readout mode=	Signal
#DeNoise=	Off
#ICS correction=	On
#Dark correction=	Off
#Inst. Process=	Off
#Detector Gain=	Best Dynamic
#Detector ADC=	50 kHz HS
#Detector temperature (°C)=	-60.09
#Instrument=	LabRAM HR Evol
#Detector=	SIN-EM FIVIS
#Objective=	x100_VIS_LWD
#Grating=	150 (500nm)
#ND Filter=	100%
#Laser=	633nm_Edge
#Hole=	49.98
#Temperature=	0
#Range=	Visible
#StageXY=	75x50mm Scan+
#StageZ=	Z motor
#X (µm)=	0
#Y (µm)=	0
#Z (µm)=	4
#Full time(mm:ss)=	1:34
#Project=	21_11_22
#Sample=	BU04w
#Site=
#Title=	BU04w-A-FF3-FI02-L_150 (500nm)_633nm_Edge_100%_x100_VIS_LWD_H50um_45sX2
#Remark=
#Date=	22.11.2021 10:46
#Acquired=	22.11.2021 10:46:02
#Base:Fit=	16.12.2021 16:15:35
#Base:Edit=	16.12.2021 16:21:42
#Base:Edit=	16.12.2021 16:21:44
#Base:Edit=	16.12.2021 16:21:44
#Base:Sub=	16.12.2021 16:21:46
100.177	380.945
106.695	313.489
113.209	280.486
119.717	240.546
126.219	232.094
132.716	230.309
139.208	217.823
145.694	214.17
152.175	168.662
158.651	166.643
165.121	290.462
171.586	191.061
178.045	101.206
184.5	85.2073
190.947	65.493
197.39	20.4824
203.829	19.3811
210.262	18.7256
216.688	17.5605
223.11	23.4915
229.527	65.7941
235.939	198.921
242.344	152.843
248.745	47.839
255.141	27.8074
261.53	47.3362
267.916	18.1612
274.294	18.1064
280.669	21.4984
287.038	44.3651
293.402	34.58
299.76	-1.048
306.114	24.5237
312.461	46.0155
318.805	113.482
325.142	341.185
331.475	455.388
337.802	242.988
344.123	108.709
350.441	63.7683
356.752	76.0329
363.058	79.5664
369.36	76.3183
375.656	90.727
381.947	52.4379
388.232	48.0313
394.512	60.6226
400.789	68.6498
407.059	81.2522
413.324	91.8082
419.584	115.37
425.839	185.799
432.089	226.799
438.333	262.715
444.573	191.212
450.807	163.873
457.037	169.394
463.261	157.381
469.48	116.706
475.695	81.7844
481.904	80.4258
488.108	92.0065
494.307	89.5802
500.502	113.182
506.691	125.624
512.874	149.27
519.053	164.603
525.227	153.936
531.396	136.783
537.559	122.44
543.718	97.4169
549.873	100.311
556.022	88.9704
562.165	74.3714
568.304	63.3284
574.437	47.4094
580.567	63.298
586.691	54.0072
592.81	69.1624
598.924	97.5157
605.033	99.2621
611.138	78.6958
617.236	67.57
623.332	82.7696
629.42	65.005
635.506	69.394
641.585	54.5771
647.659	54.6493
653.73	58.4062
659.794	83.5584
665.854	80.5672
671.91	36.7291
677.96	44.6115
684.005	28.2585
690.045	18.5939
696.082	24.9267
702.113	20.0011
708.139	27.2108
714.16	21.9126
720.176	16.5343
726.187	13.0152
732.194	23.4188
738.196	7.59134
744.193	5.84686
750.185	12.5609
756.173	3.52289
762.155	2.18819
768.133	13.2048
774.107	10.2384
780.075	-2.22864
786.039	4.92897
791.998	-2.10427
797.952	3.02328
803.902	-2.3391
809.845	2.60905
815.786	10.2702
821.721	1.90609
827.652	1.04259
833.576	1.30708
839.498	14.8842
845.415	11.8102
851.327	-7.19469
857.233	11.3948
863.135	14.0768
869.032	21.5044
874.925	35.4659
880.813	23.7091
886.697	29.88
892.576	23.6159
898.45	31.469
904.318	31.5494
910.184	23.1108
916.044	28.8315
921.9	27.221
927.75	34.2602
933.596	51.8482
939.439	83.0177
945.275	131.568
951.107	169.173
956.936	192.614
962.759	181.512
968.577	146.155
974.391	145.01
980.201	177.995
986.006	265.252
991.806	311.942
997.602	263.911
1003.39	202.856
1009.18	201.267
1014.96	193.461
1020.74	260.141
1026.51	325.536
1032.28	247.487
1038.04	147.993
1043.8	102.923
1049.56	75.9306
1055.31	67.0805
1061.05	52.2242
1066.8	29.3741
1072.53	46.3098
1078.26	56.3708
1083.99	80.9138
1089.72	95.7759
1095.44	175.504
1101.15	252.205
1106.86	183.113
1112.56	104.375
1118.27	61.8053
1123.96	47.0778
1129.65	53.7492
1135.34	53.614
1141.03	75.0653
1146.7	116.114
1152.38	203.476
1158.05	305.301
1163.71	131.138
1169.37	61.473
1175.03	43.952
1180.68	20.6415
1186.33	17.051
1191.98	9.67042
1197.61	17.0711
1203.25	11.9148
1208.88	11.7331
1214.51	1.70039
1220.13	5.53448
1225.74	8.42208
1231.36	14.2993
1236.97	16.1075
1242.57	11.744
1248.17	10.2582
1253.77	13.7217
1259.36	23.1132
1264.94	15.2461
1270.53	35.5833
1276.11	25.6224
1281.68	18.6922
1287.25	16.8482
1292.81	17.0684
1298.38	13.3797
1303.93	2.7626
1309.48	3.25788
1315.03	9.90482
1320.58	7.54565
1326.12	8.24524
1331.65	5.91323
1337.18	-2.61398
1342.71	9.18388
1348.23	9.68826
1353.75	16.3159
1359.26	21.8642
1364.77	25.2793
1370.28	31.6993
1375.78	85.3475
1381.28	120.459
1386.77	49.822
1392.26	24.4112
1397.74	16.581
1403.23	12.866
1408.7	0.922462
1414.17	7.53973
1419.64	6.96363
1425.11	-3.97137
1430.56	3.75762
1436.02	10.4725
1441.47	-0.565155
1446.92	0.920021
1452.36	4.41479
1457.8	5.74783
1463.23	3.87178
1468.66	4.05835
1474.09	5.29613
1479.51	4.47437
1484.93	4.72068
1490.34	3.95583
1495.75	10.6072
1501.16	12.0322
1506.56	6.08572
1511.96	8.62868
1517.35	9.08926
1522.74	4.2303
1528.13	17.5545
1533.51	17.0225
1538.88	1.30991
1544.25	18.9591
1549.62	13.7662
1554.99	11.6825
1560.35	10.639
1565.71	10.6962
1571.06	12.8966
1576.41	17.2604
1581.75	18.4742
1587.09	13.2522
1592.43	23.1411
1597.76	25.5496
1603.09	20.4408
1608.41	30.5353
1613.73	27.7396
1619.05	33.7123
1624.36	30.9749
1629.67	38.0917
1634.97	34.1776
1640.27	28.957
1645.57	32.5494
1650.86	32.7908
1656.15	35.2045
1661.43	30.9077
1666.71	23.2578
1671.99	24.4617
1677.26	22.3169
1682.53	23.4773
1687.79	20.1459
1693.05	16.8543
1698.31	14.7627
1703.56	9.6464
1708.81	13.4585
1714.06	16.7342
1719.3	10.3636
1724.53	8.32679
1729.77	16.4289
1735	12.1887
1740.22	5.66461
1745.44	5.88487
1750.66	13.9783
1755.87	13.0058
1761.08	8.57361
1766.29	7.52964
1771.49	12.1656
1776.69	0.948044
1781.88	1.10755
1787.07	4.70354
1792.26	8.35316
1797.44	1.74102
1802.62	11.1693
1807.79	11.4467
1812.96	7.07067
1818.13	1.52383
1823.29	16.7676
1828.45	6.5846
1833.61	5.65843
1838.76	5.88765
1843.91	13.0743
1849.05	9.7468
1854.19	2.86745
1859.33	6.54475
1864.46	0.862251
1869.59	5.75893
1874.71	3.54543
1879.83	6.03107
1884.95	6.14433
1890.06	1.48978
1895.17	9.79218
1900.28	6.30939
1905.38	8.84695
1910.48	1.93753
1915.57	12.9405
1920.66	8.32937
1925.75	7.3082
1930.83	18.2704
1935.91	10.0525
1940.99	10.1938
1946.06	7.89886
1951.13	12.7978
1956.19	5.61851
1961.26	21.3187
1966.31	14.1032
1971.36	12.8689
1976.41	4.40027
1981.46	12.7877
1986.5	6.73756
1991.54	10.3222
1996.58	11.514
2001.61	18.7402
2006.63	9.16606
2011.66	15.2532
2016.68	18.9454
2021.69	14.1825
2026.71	7.05079
2031.72	13.2281
2036.72	14.6125
2041.72	7.51357
2046.72	21.0677
2051.71	16.4072
2056.71	14.1176
2061.69	10.648
2066.68	7.16615
2071.66	14.7118
2076.63	17.3602
2081.6	13.8329
2086.57	16.4371
2091.54	16.5688
2096.5	13.0436
2101.46	15.7337
2106.41	17.2125
2111.36	14.9727
2116.31	15.2494
2121.25	11.7527
2126.19	18.3099
2131.13	17.2963
2136.06	17.5171
2140.99	20.2583
2145.92	16.6284
2150.84	20.5903
2155.76	13.0395
2160.67	10.5542
2165.58	16.9785
2170.49	13.1621
2175.39	5.54262
2180.29	17.0832
2185.19	18.3409
2190.08	17.064
2194.98	6.85469
2199.86	10.7793
2204.74	5.76218
2209.62	11.0522
2214.5	12.5186
2219.37	12.7255
2224.24	10.345
2229.11	14.4479
2233.97	17.2677
2238.83	14.8755
2243.68	11.1606
2248.53	8.74299
2253.38	12.8833
2258.22	18.3706
2263.06	2.71417
2267.9	12.1278
2272.73	16.2283
2277.56	9.67729
2282.39	15.0448
2287.21	11.0601
2292.03	8.40241
2296.85	13.7321
2301.66	19.1125
2306.47	15.2202
2311.28	22.0562
2316.08	11.5406
2320.88	-0.345261
2325.68	1.17432
2330.47	9.46426
2335.26	16.4732
2340.04	12.6645
2344.82	15.6701
2349.6	14.612
2354.38	10.7705
2359.15	9.60387
2363.92	5.60417
2368.68	14.0484
2373.44	14.2046
2378.2	11.5808
2382.95	10.2852
2387.71	13.1153
2392.45	4.77788
2397.2	0.581421
2401.94	10.2934
2406.68	7.45755
2411.41	6.11644
2416.14	13.3348
2420.87	9.53178
2425.59	8.2132
2430.31	8.38882
2435.03	10.0066
2439.75	13.0716
2444.46	10.4564
2449.16	4.97495
2453.87	15.1941
2458.57	13.9889
2463.27	7.01708
2467.96	10.0945
2472.65	11.7222
2477.34	16.2656
2482.02	3.37115
2486.7	12.25
2491.38	5.08649
2496.05	28.6331
2500.72	15.5953
2505.39	15.7146
2510.06	11.3979
2514.72	8.51881
2519.37	13.0136
2524.03	10.1562
2528.68	16.1571
2533.33	1.4369
2537.97	8.96325
2542.61	16.5289
2547.25	4.75063
2551.88	9.36211
2556.51	9.48131
2561.14	6.59632
2565.77	6.73869
2570.39	8.40765
2575.01	8.57263
2579.62	8.70827
2584.23	13.3438
2588.84	4.27225
2593.45	4.27422
2598.05	4.34029
2602.65	12.016
2607.24	13.5842
2611.84	7.48617
2616.42	10.5465
2621.01	4.43406
2625.59	-0.14724
2630.17	4.50124
2634.75	12.3099
2639.32	12.5185
2643.89	18.9254
2648.46	8.29721
2653.02	16.2851
2657.58	8.58932
2662.14	13.3433
2666.69	11.8123
2671.24	7.19182
2675.79	7.35959
2680.33	10.8691
2684.88	8.02431
2689.41	11.526
2693.95	6.98518
2698.48	13.4491
2703.01	5.53168
2707.53	23.3119
2712.06	21.7884
2716.57	13.846
2721.09	9.07663
2725.6	4.25841
2730.11	12.3832
2734.62	7.49028
2739.12	10.7007
2743.62	7.45738
2748.12	12.3846
2752.61	10.9105
2757.1	9.37936
2761.59	14.3329
2766.08	9.4795
2770.56	9.54535
2775.04	11.2943
2779.51	4.82186
2783.98	5.00975
2788.45	3.52883
2792.92	15.3931
2797.38	5.49892
2801.84	3.92657
2806.3	2.31238
2810.75	9.10857
2815.2	22.6599
2819.65	9.16021
2824.09	10.8888
2828.53	9.22586
2832.97	10.9436
2837.41	7.54547
2841.84	10.9644
2846.27	14.4152
2850.69	14.4747
2855.12	16.2995
2859.54	0.938744
2863.95	16.576
2868.37	20.2248
2872.78	16.942
2877.18	17.1277
2881.59	15.5896
2885.99	7.04945
2890.39	16.0257
2894.78	14.4564
2899.18	7.60535
2903.57	18.4456
2907.95	13.2671
2912.34	15.1658
2916.72	17.034
2921.09	15.3459
2925.47	4.66032
2929.84	15.6155
2934.21	24.8068
2938.57	19.45
2942.94	23.1332
2947.29	15.859
2951.65	28.623
2956	14.0195
2960.36	24.9805
2964.7	26.8294
2969.05	17.6976
2973.39	21.412
2977.73	25.1412
2982.06	21.5131
2986.4	30.8693
2990.73	31.0259
2995.05	33.059
2999.38	18.3373
3003.7	35.3764
3008.01	43.1465
3012.33	45.27
3016.64	43.6764
3020.95	21.2169
3025.26	32.8272
3029.56	42.5252
3033.86	44.5695
3038.16	46.5469
3042.45	25.543
3046.74	60.2167
3051.03	48.7304
3055.32	58.4566
3059.6	50.8103
3063.88	58.6335
3068.16	58.7184
3072.43	66.5816
3076.7	70.5914
3080.97	80.4747
3085.24	78.6934
3089.5	88.7457
3093.76	79.268
3098.02	89.5187
3102.27	89.9417
3106.52	108.316
3110.77	100.933
3115.01	109.523
3119.26	114.163
3123.5	131.018
3127.73	131.845
3131.97	124.607
3136.2	148.016
3140.43	163.349
3144.65	153.921
3148.87	158.866
3153.09	153.27
3157.31	174.7
3161.52	206.719
3165.73	169.61
3169.94	189.041
3174.15	221.319
3178.35	217.502
3182.55	228.374
3186.75	245.568
3190.94	228.779
3195.13	244.042
3199.32	236.22
3203.51	250.086
3207.69	257.7
3211.87	258.953
3216.05	253.824
3220.22	270.306
3224.39	251.949
3228.56	257.57
3232.73	247.778
3236.89	248.805
3241.05	245.566
3245.21	258.042
3249.36	252.506
3253.52	262.299
3257.66	244.972
3261.81	254.969
3265.95	247.135
3270.1	253.089
3274.23	261.24
3278.37	243.489
3282.5	260.069
3286.63	235.38
3290.76	254.279
3294.88	261.669
3299	273.708
3303.12	235.003
3307.24	233.205
3311.35	233.669
3315.46	276.014
3319.57	239.296
3323.68	260.987
3327.78	268.818
3331.88	258.079
3335.98	254.526
3340.07	276.787
3344.16	275.117
3348.25	280.394
3352.34	245.292
3356.42	260.175
3360.5	291.935
3364.58	273.549
3368.66	271.831
3372.73	315.774
3376.8	265.763
3380.87	290.303
3384.93	297.964
3388.99	288.676
3393.05	310.782
3397.11	311.279
3401.16	309.352
3405.21	290.218
3409.26	312.418
3413.31	329.691
3417.35	315.36
3421.39	330.23
3425.43	318.276
3429.46	308.899
3433.5	302.052
3437.53	314.899
3441.55	303.346
3445.58	301.729
3449.6	302.731
3453.62	301.313
3457.64	314.992
3461.65	306.486
3465.66	297.94
3469.67	281.783
3473.68	272.783
3477.68	241.184
3481.68	270.034
3485.68	286.334
3489.67	249.3
3493.67	260.458
3497.66	238.331
3501.64	269.771
3505.63	231.972
3509.61	250.345
3513.59	224.94
3517.57	194.348
3521.54	215.145
3525.52	212.852
3529.49	197.656
3533.45	174.948
3537.42	154.942
3541.38	171.157
3545.34	174.332
3549.29	174.843
3553.25	143.89
3557.2	157.227
3561.15	155.059
3565.09	145.147
3569.04	135.365
3572.98	141.214
3576.92	123.547
3580.85	113.788
3584.79	125.153
3588.72	83.5952
3592.64	108.21
3596.57	111.656
3600.49	117.736
3604.41	94.3665
3608.33	89.6224
3612.25	82.1308
3616.16	88.09
3620.07	69.7356
3623.98	70.1022
3627.88	78.5406
3631.79	49.0731
3635.69	62.9162
3639.58	44.3666
3643.48	50.3046
3647.37	48.1655
3651.26	43.0631
3655.15	40.7396
3659.03	43.8551
3662.92	22.3892
3666.8	11.8476
3670.67	31.385
3674.55	18.1332
3678.42	18.6256
3682.29	19.1747
3686.16	17.03
3690.02	20.4202
3693.89	7.19094
3697.75	10.5528
3701.61	0.0154114
3705.46	-2.20601
3709.31	-4.41676
3713.16	-6.645
3717.01	-3.28621
3720.86	5.71067
3724.7	14.7247
3728.54	1.10201
3732.38	-4.04167
3736.21	-6.35587
3740.04	-8.68808
3743.87	-2.48325
3747.7	-19.1233
3751.53	-7.22758
3755.35	-23.954
3759.17	-9.21642
3762.99	5.52808
3766.81	-14.1168
3770.62	12.1426
3774.43	-7.48313
3778.24	7.35138
3782.04	7.8645
3785.85	-0.242363
3789.65	-17.0506
3793.45	9.46212
3797.24	4.24566
3801.04	-15.4945
3804.83	-3.31508
3808.62	-2.73377
3812.4	-16.7787
3816.19	-4.54546
3819.97	10.662
3823.75	2.39716
3827.52	-0.0316391
3831.3	0.498741
3835.07	1.02969
3838.84	1.53924
3842.61	-12.7483
3846.37	2.5378
3850.13	-2.99074
3853.89	-5.56884
3857.65	0.748901
3861.41	10.018
3865.16	-10.3869
3868.91	10.9946
3872.66	11.4144
3876.4	-3.15756
3880.14	-5.7958
3883.89	3.53148
3887.62	-5.09087
3891.36	4.2617
3895.09	10.6814
3898.82	17.0896
3902.55	-3.61103
3906.28	5.77806
3910	15.1749
3913.73	-2.62445
3917.45	3.7756
3921.16	-1.93967
3924.88	1.44435
3928.59	4.80843
3932.3	2.0294
3936.01	2.25298
3939.71	-6.74202
3943.42	-0.379585
3947.12	12.1392
3950.81	6.1437
3954.51	-12.2755
3958.2	6.35049
3961.9	6.37973
3965.58	12.5722
3969.27	9.41346
3972.96	12.4312
3976.64	-0.0801849
3980.32	-0.236496
3984	-3.53807
3987.67	2.43784
3991.34	2.1993
3995.01	1.95956
3998.68	-1.38786