File: Data/3-Raman/processed/bu04w-a-ff3-fi03-v_150 (500nm)_633nm_edge_100%_x100_vis_lwd_h50um_45sx2_01.txt
#Acq. time (s)=	45
#Accumulations=	2
#Range (cm-¹)=	100...4000
#Windows=	1
#Auto scanning=	Off
#Autofocus=	Off
#Macrospot=	Off
#AutoExposure=	Off
#Spike filter=	Multiple accum.
#Delay time (s)=	2
#Binning=	1
#Readout mode=	Signal
#DeNoise=	Off
#ICS correction=	On
#Dark correction=	Off
#Inst. Process=	Off
#Detector Gain=	Best Dynamic
#Detector ADC=	50 kHz HS
#Detector temperature (°C)=	-60.09
#Instrument=	LabRAM HR Evol
#Detector=	SIN-EM FIVIS
#Objective=	x100_VIS_LWD
#Grating=	150 (500nm)
#ND Filter=	100%
#Laser=	633nm_Edge
#Hole=	49.98
#Temperature=	0
#Range=	Visible
#StageXY=	75x50mm Scan+
#StageZ=	Z motor
#X (µm)=	0
#Y (µm)=	0
#Z (µm)=	57.9
#Full time(mm:ss)=	1:34
#Project=	21_11_22
#Sample=	BU04w
#Site=
#Title=	BU04w-A-FF3-FI03-V_150 (500nm)_633nm_Edge_100%_x100_VIS_LWD_H50um_45sX2
#Remark=
#Date=	22.11.2021 12:21
#Acquired=	22.11.2021 12:21:09
#Base:Fit=	16.12.2021 16:15:35
#Base:Fit=	16.12.2021 16:22:22
#Base:Clear=	16.12.2021 16:22:25
#Base:Edit=	16.12.2021 16:22:27
#Base:Edit=	16.12.2021 16:22:28
#Base:Edit=	16.12.2021 16:22:29
#Base:Edit=	16.12.2021 16:22:29
#Base:Edit=	16.12.2021 16:22:30
#Base:Edit=	16.12.2021 16:22:31
#Base:Edit=	16.12.2021 16:22:32
#Base:Edit=	16.12.2021 16:22:32
#Base:Edit=	16.12.2021 16:22:34
#Base:Edit=	16.12.2021 16:22:34
#Base:Edit=	16.12.2021 16:22:35
#Base:Edit=	16.12.2021 16:22:37
#Base:Edit=	16.12.2021 16:22:40
#Base:Edit=	16.12.2021 16:22:42
#Base:Sub=	16.12.2021 16:22:45
100.177	454.839
106.695	341.151
113.209	291.768
119.717	223.512
126.219	190.908
132.716	169.124
139.208	168.621
145.694	124.451
152.175	114.115
158.651	140.552
165.121	142.418
171.586	83.1257
178.045	39.3087
184.5	26.3173
190.947	21.129
197.39	0.8983
203.829	3.99275
210.262	8.24806
216.688	7.92369
223.11	43.0279
229.527	96.1663
235.939	129.413
242.344	48.7936
248.745	27.4494
255.141	19.4661
261.53	10.7154
267.916	19.1915
274.294	17.3913
280.669	10.956
287.038	13.0933
293.402	10.5172
299.76	-2.38316
306.114	8.43248
312.461	31.5966
318.805	135.977
325.142	242.349
331.475	174.261
337.802	78.9054
344.123	32.6708
350.441	14.7417
356.752	32.6004
363.058	47.6082
369.36	33.4796
375.656	25.9773
381.947	8.21713
388.232	-1.8085
394.512	12.785
400.789	21.0601
407.059	24.6612
413.324	11.2441
419.584	56.3495
425.839	92.7491
432.089	108.626
438.333	83.8849
444.573	75.2094
450.807	62.7337
457.037	67.2195
463.261	40.1941
469.48	15.2855
475.695	27.7982
481.904	23.623
488.108	17.5546
494.307	17.1017
500.502	51.1302
506.691	59.1278
512.874	69.0341
519.053	55.6803
525.227	48.0508
531.396	40.5058
537.559	54.6416
543.718	47.9358
549.873	34.3548
556.022	43.3758
562.165	16.1797
568.304	19.0042
574.437	4.71991
580.567	21.3231
586.691	20.2113
592.81	23.9359
598.924	25.9658
605.033	27.4076
611.138	29.8792
617.236	35.3206
623.332	31.4725
629.42	27.5446
635.506	32.647
641.585	23.2797
647.659	10.9176
653.73	50.1799
659.794	46.0415
665.854	32.5901
671.91	15.6084
677.96	8.34387
684.005	4.81624
690.045	14.539
696.082	13.1878
702.113	11.7991
708.139	5.62558
714.16	10.4074
720.176	10.3902
726.187	19.7229
732.194	17.6061
738.196	-1.3532
744.193	-0.621704
750.185	13.2248
756.173	18.7757
762.155	18.113
768.133	11.1479
774.107	10.7454
780.075	-0.106873
786.039	17.1164
791.998	0.344803
797.952	12.6689
803.902	1.2598
809.845	0.149139
815.786	21.4752
821.721	14.5046
827.652	15.0113
833.576	20.4389
839.498	12.1521
845.415	18.0987
851.327	10.9734
857.233	17.0515
863.135	20.3729
869.032	15.1969
874.925	20.2593
880.813	40.3517
886.697	15.7437
892.576	34.6523
898.45	23.0676
904.318	15.0824
910.184	34.4371
916.044	35.8313
921.9	31.848
927.75	45.9668
933.596	61.302
939.439	67.6535
945.275	105.442
951.107	136.015
956.936	120.881
962.759	96.82
968.577	96.4181
974.391	88.1117
980.201	125.468
986.006	154.815
991.806	139.97
997.602	102.244
1003.39	107.673
1009.18	116.174
1014.96	140.353
1020.74	161.727
1026.51	182.577
1032.28	110.596
1038.04	63.3653
1043.8	53.5067
1049.56	40.6424
1055.31	30.4627
1061.05	30.7808
1066.8	48.3459
1072.53	31.8753
1078.26	54.1585
1083.99	57.9357
1089.72	82.1091
1095.44	148.878
1101.15	152.655
1106.86	84.1732
1112.56	54.4657
1118.27	34.9051
1123.96	41.3566
1129.65	37.0836
1135.34	51.4203
1141.03	81.5334
1146.7	113.537
1152.38	202.648
1158.05	134.857
1163.71	51.0248
1169.37	23.327
1175.03	23.1341
1180.68	13.1826
1186.33	10.2757
1191.98	15.3553
1197.61	11.8419
1203.25	13.4616
1208.88	15.2353
1214.51	17.0833
1220.13	3.1752
1225.74	6.12723
1231.36	10.055
1236.97	7.85115
1242.57	17.5521
1248.17	16.9901
1253.77	20.3165
1259.36	55.7549
1264.94	28.4381
1270.53	24.3484
1276.11	254.274
1281.68	298.686
1287.25	32.916
1292.81	27.9207
1298.38	21.0884
1303.93	8.38103
1309.48	5.87247
1315.03	19.6381
1320.58	13.3826
1326.12	6.14836
1331.65	24.2826
1337.18	12.8898
1342.71	-0.737366
1348.23	4.91887
1353.75	16.7058
1359.26	8.90132
1364.77	38.9975
1370.28	33.0117
1375.78	47.5541
1381.28	793.098
1386.77	159.696
1392.26	34.6889
1397.74	26.9053
1403.23	82.9146
1408.7	24.8032
1414.17	30.5371
1419.64	16.686
1425.11	-0.306442
1430.56	10.7027
1436.02	4.03273
1441.47	3.57532
1446.92	2.08443
1452.36	-3.76662
1457.8	-6.58609
1463.23	-2.14493
1468.66	-7.20796
1474.09	5.58209
1479.51	-2.55061
1484.93	-12.756
1490.34	-3.98495
1495.75	6.99484
1501.16	3.2877
1506.56	-3.56232
1511.96	-1.90233
1517.35	9.3952
1522.74	5.85143
1528.13	9.79704
1533.51	3.06174
1538.88	20.9795
1544.25	4.26897
1549.62	6.72696
1554.99	3.57182
1560.35	-0.721481
1565.71	11.2067
1571.06	-0.607697
1576.41	13.4611
1581.75	-5.71748
1587.09	-3.3304
1592.43	-0.892365
1597.76	10.2539
1603.09	7.44377
1608.41	1.46805
1613.73	-3.33473
1619.05	0.636017
1624.36	-4.11688
1629.67	16.3493
1634.97	12.6333
1640.27	-0.178818
1645.57	-1.99471
1650.86	4.99666
1656.15	-0.245972
1661.43	1.08504
1666.71	11.2598
1671.99	4.77798
1677.26	7.13895
1682.53	-1.61565
1687.79	7.28091
1693.05	-0.385666
1698.31	2.04971
1703.56	-0.581024
1708.81	1.29306
1714.06	4.5744
1719.3	5.12433
1724.53	6.60808
1729.77	1.44421
1735	5.24489
1740.22	-6.73238
1745.44	7.20181
1750.66	-2.62321
1755.87	7.84798
1761.08	2.38837
1766.29	0.31369
1771.49	10.7274
1776.69	5.30836
1781.88	7.909
1787.07	-0.816162
1792.26	3.03252
1797.44	12.6271
1802.62	-5.17924
1807.79	12.5283
1812.96	7.20935
1818.13	7.6429
1823.29	3.44418
1828.45	0.400818
1833.61	7.81548
1838.76	11.7633
1843.91	5.14568
1849.05	1.98257
1854.19	-9.43047
1859.33	1.43839
1864.46	-7.5827
1869.59	-2.50093
1874.71	3.69089
1879.83	12.2334
1884.95	16.044
1890.06	4.4225
1895.17	-3.73817
1900.28	9.4474
1905.38	3.88213
1910.48	5.4922
1915.57	4.86311
1920.66	0.41748
1925.75	5.5528
1930.83	1.13188
1935.91	-6.92838
1940.99	-1.83295
1946.06	4.43526
1951.13	1.03517
1956.19	-1.21516
1961.26	-4.69568
1966.31	-10.6127
1971.36	3.89374
1976.41	-10.5284
1981.46	-2.07018
1986.5	-5.64088
1991.54	4.03448
1996.58	0.503296
2001.61	7.82864
2006.63	1.97815
2011.66	-3.83841
2016.68	6.00302
2021.69	3.77258
2026.71	4.03082
2031.72	-2.90575
2036.72	2.28441
2041.72	9.9285
2046.72	-9.12491
2051.71	8.30325
2056.71	7.41241
2061.69	-1.96508
2066.68	7.0121
2071.66	7.40373
2076.63	9.02283
2081.6	9.38838
2086.57	-7.59151
2091.54	1.35287
2096.5	-0.741432
2101.46	2.15137
2106.41	3.84358
2111.36	6.82629
2116.31	11.1148
2121.25	-2.1768
2126.19	15.9585
2131.13	0.024147
2136.06	11.8563
2140.99	8.4678
2145.92	10.1325
2150.84	6.63686
2155.76	-17.3405
2160.67	10.9822
2165.58	-9.28768
2170.49	10.0481
2175.39	1.3138
2180.29	4.03889
2185.19	16.9427
2190.08	-2.1185
2194.98	0.630608
2199.86	11.1478
2204.74	3.77358
2209.62	5.43008
2214.5	5.8397
2219.37	7.58385
2224.24	1.56649
2229.11	13.7083
2233.97	11.5809
2238.83	4.21576
2243.68	-5.80656
2248.53	5.12804
2253.38	12.1563
2258.22	-3.19684
2263.06	1.19723
2267.9	-1.07496
2272.73	9.86543
2277.56	0.857765
2282.39	6.40762
2287.21	6.5778
2292.03	0.0940933
2296.85	2.92883
2301.66	9.82671
2306.47	14.1468
2311.28	3.85307
2316.08	12.3145
2320.88	14.1386
2325.68	50.9847
2330.47	2.9911
2335.26	3.5108
2340.04	8.1196
2344.82	3.24976
2349.6	-4.3646
2354.38	-7.95307
2359.15	-6.12875
2363.92	9.40368
2368.68	-3.9933
2373.44	-4.99904
2378.2	7.86292
2382.95	6.79482
2387.71	-8.25018
2392.45	7.25432
2397.2	-0.93866
2401.94	0.5961
2406.68	-6.24788
2411.41	7.93845
2416.14	-5.48679
2420.87	7.85557
2425.59	-0.260048
2430.31	4.40617
2435.03	-6.41546
2439.75	9.66888
2444.46	10.1908
2449.16	-4.97374
2453.87	2.65591
2458.57	6.01948
2463.27	-3.55444
2467.96	4.11662
2472.65	11.8012
2477.34	19.5339
2482.02	2.5688
2486.7	17.5462
2491.38	3.35504
2496.05	12.5281
2500.72	-0.281364
2505.39	3.00101
2510.06	6.26551
2514.72	15.4001
2519.37	-1.98868
2524.03	-1.6686
2528.68	6.0359
2533.33	6.36954
2537.97	-8.11597
2542.61	-3.30044
2547.25	10.5005
2551.88	7.91685
2556.51	9.78946
2561.14	-3.34305
2565.77	4.56816
2570.39	-2.53904
2575.01	14.5085
2579.62	11.892
2584.23	12.2214
2588.84	0.334953
2593.45	5.10771
2598.05	-11.3427
2602.65	-4.98268
2607.24	-1.68331
2611.84	0.0613174
2616.42	4.85505
2621.01	2.01275
2625.59	6.84241
2630.17	8.66199
2634.75	4.43082
2639.32	-2.81526
2643.89	11.5698
2648.46	8.97095
2653.02	7.89854
2657.58	8.2339
2662.14	5.40298
2666.69	4.08075
2671.24	7.52274
2675.79	3.24489
2680.33	0.75058
2684.88	4.53273
2689.41	5.1505
2693.95	-3.91962
2698.48	9.16505
2703.01	7.90768
2707.53	11.4407
2712.06	2.06316
2716.57	12.0948
2721.09	-2.15977
2725.6	-0.289032
2730.11	-6.57133
2734.62	3.33986
2739.12	5.11245
2743.62	2.06945
2748.12	10.4652
2752.61	4.3343
2757.1	4.66302
2761.59	8.18137
2766.08	8.47212
2770.56	0.524055
2775.04	-0.815903
2779.51	9.47603
2783.98	-0.0205917
2788.45	5.40967
2792.92	-4.19607
2797.38	-5.5184
2801.84	11.6041
2806.3	3.49368
2810.75	7.13464
2815.2	7.37032
2819.65	9.28684
2824.09	6.13786
2828.53	2.9768
2832.97	15.0933
2837.41	-0.0214157
2841.84	1.88185
2846.27	-4.72727
2850.69	-6.20422
2855.12	6.0901
2859.54	9.85108
2863.95	5.04756
2868.37	-1.48155
2872.78	7.5582
2877.18	7.95418
2881.59	1.38844
2885.99	1.81453
2890.39	0.46067
2894.78	16.7346
2899.18	3.05614
2903.57	15.9006
2907.95	5.59685
2912.34	4.1213
2916.72	-2.782
2921.09	15.4586
2925.47	4.99529
2929.84	-0.0774231
2934.21	12.9174
2938.57	2.29892
2942.94	4.33459
2947.29	9.97649
2951.65	6.50941
2956	13.9869
2960.36	14.1653
2964.7	1.53678
2969.05	7.24306
2973.39	5.62435
2977.73	0.315819
2982.06	7.91862
2986.4	-2.89746
2990.73	6.66484
2995.05	3.2701
2999.38	12.9462
3003.7	-1.63166
3008.01	0.61042
3012.33	10.3691
3016.64	6.99873
3020.95	13.1149
3025.26	9.6964
3029.56	8.09772
3033.86	8.36243
3038.16	-4.8556
3042.45	-2.70776
3046.74	1.32684
3051.03	11.1497
3055.32	9.42669
3059.6	5.76722
3063.88	2.08799
3068.16	4.22098
3072.43	16.085
3076.7	14.3643
3080.97	16.5435
3085.24	22.6683
3089.5	15.1515
3093.76	19.453
3098.02	23.8216
3102.27	10.4026
3106.52	22.7649
3110.77	25.2708
3115.01	25.7992
3119.26	18.2915
3123.5	18.8366
3127.73	25.5001
3131.97	22.0834
3136.2	24.7745
3140.43	27.4536
3144.65	28.0368
3148.87	28.5857
3153.09	29.0461
3157.31	23.2062
3161.52	17.3288
3165.73	32.4004
3169.94	32.7725
3174.15	43.7394
3178.35	31.3543
3182.55	35.8163
3186.75	48.7424
3190.94	53.1825
3195.13	38.5974
3199.32	32.6094
3203.51	43.847
3207.69	59.5047
3211.87	40.8021
3216.05	56.6457
3220.22	46.4787
3224.39	44.9509
3228.56	52.1846
3232.73	30.8405
3236.89	37.9908
3241.05	34.1764
3245.21	37.0751
3249.36	28.7271
3253.52	33.6478
3257.66	29.526
3261.81	41.3097
3265.95	17.0553
3270.1	17.6811
3274.23	15.9812
3278.37	18.5741
3282.5	25.771
3286.63	26.1093
3290.76	14.9329
3294.88	8.30769
3299	15.5167
3303.12	15.8513
3307.24	11.5401
3311.35	16.4855
3315.46	14.4673
3319.57	12.4581
3323.68	10.4926
3327.78	22.6054
3331.88	9.00201
3335.98	16.5944
3340.07	17.0765
3344.16	0.854904
3348.25	13.0233
3352.34	15.7352
3356.42	11.3245
3360.5	16.4828
3364.58	21.667
3368.66	-4.3419
3372.73	12.8235
3376.8	1.09899
3380.87	15.8527
3384.93	1.65294
3388.99	11.5895
3393.05	28.7955
3397.11	12.1585
3401.16	10.0414
3405.21	10.2963
3409.26	10.5606
3413.31	18.1016
3417.35	6.17902
3421.39	18.6085
3425.43	28.6144
3429.46	14.2695
3433.5	4.81284
3437.53	12.5055
3441.55	3.07641
3445.58	5.94309
3449.6	11.3323
3453.62	1.9345
3457.64	14.856
3461.65	15.4565
3465.66	13.5702
3469.67	6.6498
3473.68	17.1941
3477.68	-2.39852
3481.68	23.3807
3485.68	8.73833
3489.67	6.70973
3493.67	9.75795
3497.66	12.7813
3501.64	5.54916
3505.63	-1.74612
3509.61	8.85026
3513.59	19.4204
3517.57	9.43896
3521.54	2.01605
3525.52	-2.82882
3529.49	7.76028
3533.45	10.7246
3537.42	13.7767
3541.38	3.91621
3545.34	9.53008
3549.29	-13.4465
3553.25	12.8358
3557.2	7.98078
3561.15	-2.05679
3565.09	13.999
3569.04	-14.2622
3572.98	1.87938
3576.92	-8.13361
3580.85	5.53866
3584.79	3.46339
3588.72	-1.27879
3592.64	1.91689
3596.57	10.4594
3600.49	-2.3532
3604.41	-1.85101
3608.33	-9.4267
3612.25	4.46419
3616.16	15.7162
3620.07	2.68729
3623.98	0.348221
3627.88	-12.8365
3631.79	3.70309
3635.69	-6.7934
3639.58	1.71189
3643.48	-0.550011
3647.37	2.65441
3651.26	-5.17474
3655.15	3.36985
3659.03	9.19102
3662.92	4.08627
3666.8	1.72488
3670.67	-6.10735
3674.55	2.49128
3678.42	-8.04104
3682.29	0.665176
3686.16	1.18496
3690.02	-3.81229
3693.89	-17.162
3697.75	2.75452
3701.61	8.8522
3705.46	0.996864
3709.31	4.32285
3713.16	7.65695
3717.01	-3.11298
3720.86	2.97749
3724.7	6.24403
3728.54	-1.82133
3732.38	1.44302
3736.21	-3.80666
3740.04	-3.39362
3743.87	8.41408
3747.7	0.24575
3751.53	0.609123
3755.35	6.67062
3759.17	1.25814
3762.99	-12.7704
3766.81	1.85057
3770.62	5.03765
3774.43	5.3677
3778.24	5.70179
3782.04	8.9429
3785.85	3.56751
3789.65	1.0427
3793.45	1.40739
3797.24	13.3908
3801.04	-6.49649
3804.83	-3.1922
3808.62	-8.6128
3812.4	-8.23323
3816.19	-2.00977
3819.97	-1.63594
3823.75	7.53584
3827.52	7.88664
3831.3	11.2071
3835.07	-0.229874
3838.84	0.106667
3842.61	9.36167
3846.37	15.603
3850.13	3.98009
3853.89	4.21693
3857.65	-4.48203
3861.41	4.6329
3865.16	7.87601
3868.91	2.29885
3872.66	5.54955
3876.4	2.78716
3880.14	17.9587
3883.89	-14.7191
3887.62	-11.5017
3891.36	12.7187
3895.09	4.02242
3898.82	7.30844
3902.55	10.603
3906.28	4.83939
3910	-6.99251
3913.73	11.4265
3917.45	-3.43063
3921.16	-3.12741
3924.88	-5.87243
3928.59	6.61871
3932.3	6.89868
3936.01	-5.11513
3939.71	4.31766
3943.42	1.51974
3947.12	-7.4645
3950.81	5.10096
3954.51	2.22826
3958.2	8.61309
3961.9	8.78262
3965.58	-0.354828
3969.27	-3.33331
3972.96	6.0882
3976.64	3.11044
3980.32	0.111229
3984	3.29794
3987.67	0.284142
3991.34	6.59008
3995.01	6.72312
3998.68	0.673775