File: Data/3-Raman/processed/bu04w-a-ff3-fi05-v_150 (500nm)_633nm_edge_100%_x100_vis_lwd_h50um_45sx2_02.txt
#Acq. time (s)=	45
#Accumulations=	2
#Range (cm-¹)=	100...4000
#Windows=	1
#Auto scanning=	Off
#Autofocus=	Off
#Macrospot=	Off
#AutoExposure=	Off
#Spike filter=	Multiple accum.
#Delay time (s)=	2
#Binning=	1
#Readout mode=	Signal
#DeNoise=	Off
#ICS correction=	On
#Dark correction=	Off
#Inst. Process=	Off
#Detector Gain=	Best Dynamic
#Detector ADC=	50 kHz EM
#Detector EM gain=	100
#Detector temperature (°C)=	-60.09
#Instrument=	LabRAM HR Evol
#Detector=	SIN-EM FIVIS
#Objective=	x100_VIS_LWD
#Grating=	150 (500nm)
#ND Filter=	100%
#Laser=	633nm_Edge
#Hole=	49.98
#Temperature=	0
#Range=	Visible
#StageXY=	75x50mm Scan+
#StageZ=	Z motor
#X (µm)=	0
#Y (µm)=	0
#Z (µm)=	16.6
#Full time(mm:ss)=	1:36
#Project=	21_11_22
#Sample=	BU04w
#Site=
#Title=	BU04w-A-FF3-FI05-V_150 (500nm)_633nm_Edge_100%_x100_VIS_LWD_H50um_45sX2
#Remark=
#Date=	22.11.2021 11:43
#Acquired=	22.11.2021 11:43:04
#Base:Fit=	16.12.2021 16:15:35
#Base:Edit=	16.12.2021 16:23:21
#Base:Edit=	16.12.2021 16:23:22
#Base:Edit=	16.12.2021 16:23:23
#Base:Edit=	16.12.2021 16:23:25
#Base:Edit=	16.12.2021 16:23:25
#Base:Sub=	16.12.2021 16:23:27
100.177	728.78
106.695	555.935
113.209	479.114
119.717	402.455
126.219	386.369
132.716	356.264
139.208	384.587
145.694	335.911
152.175	260.925
158.651	363.753
165.121	486.325
171.586	310.872
178.045	139.072
184.5	85.0881
190.947	97.0582
197.39	31.9486
203.829	38.6028
210.262	0.69635
216.688	-0.701965
223.11	32.3624
229.527	175.487
235.939	362.355
242.344	227.153
248.745	93.8229
255.141	84.8098
261.53	76.1219
267.916	31.6446
274.294	19.7101
280.669	90.3911
287.038	92.6562
293.402	33.1961
299.76	0.400574
306.114	7.37134
312.461	75.8469
318.805	252.872
325.142	646.251
331.475	700.02
337.802	375.617
344.123	133.413
350.441	66.5384
356.752	112.562
363.058	130.181
369.36	149.631
375.656	64.8245
381.947	47.7656
388.232	21.9815
394.512	7.1615
400.789	51.2198
407.059	71.8297
413.324	54.5662
419.584	122.992
425.839	212.449
432.089	287.605
438.333	294.422
444.573	226.871
450.807	168.703
457.037	213.818
463.261	192.234
469.48	73.4727
475.695	45.6009
481.904	68.2432
488.108	99.1589
494.307	74.22
500.502	105.14
506.691	174.464
512.874	222.473
519.053	210.06
525.227	144.707
531.396	158.214
537.559	188.018
543.718	157.074
549.873	89.3885
556.022	98.8847
562.165	79.9685
568.304	56.7169
574.437	71.5012
580.567	45.6358
586.691	43.6047
592.81	76.5507
598.924	93.1686
605.033	134.141
611.138	107.3
617.236	89.201
623.332	95.6296
629.42	99.0789
635.506	84.3765
641.585	80.021
647.659	70.3799
653.73	84.9739
659.794	123.475
665.854	72.112
671.91	58.6403
677.96	45.3158
684.005	31.9961
690.045	28.4992
696.082	31.8736
702.113	21.076
708.139	14.6971
714.16	30.9031
720.176	-1.10791
726.187	8.11337
732.194	29.0123
738.196	14.2404
744.193	10.7579
750.185	-2.81259
756.173	14.6825
762.155	30.1802
768.133	7.08252
774.107	9.25549
780.075	4.56546
786.039	18.2751
791.998	1.58688
797.952	15.6452
803.902	29.2462
809.845	18.0975
815.786	22.5994
821.721	3.42053
827.652	11.3422
833.576	32.0067
839.498	23.5338
845.415	23.9966
851.327	44.2627
857.233	45.0202
863.135	58.138
869.032	52.3814
874.925	41.3845
880.813	60.266
886.697	42.7864
892.576	75.2378
898.45	43.7626
904.318	61.9037
910.184	40.2189
916.044	73.1926
921.9	86.9764
927.75	96.7006
933.596	123.065
939.439	158.975
945.275	251.351
951.107	345.624
956.936	357.222
962.759	292.667
968.577	232.029
974.391	269.476
980.201	325.989
986.006	509.092
991.806	524.875
997.602	451.731
1003.39	351.557
1009.18	367.525
1014.96	358.901
1020.74	504.036
1026.51	522.423
1032.28	430.937
1038.04	222.878
1043.8	205.676
1049.56	138.852
1055.31	125.553
1061.05	121.461
1066.8	100.155
1072.53	98.1493
1078.26	117.27
1083.99	147.849
1089.72	203.707
1095.44	308.928
1101.15	451.689
1106.86	269.161
1112.56	157.428
1118.27	93.3812
1123.96	100.564
1129.65	99.9246
1135.34	140.469
1141.03	167.461
1146.7	228.47
1152.38	482.397
1158.05	480.442
1163.71	234.378
1169.37	91.9146
1175.03	81.1461
1180.68	63.6072
1186.33	39.7915
1191.98	35.0169
1197.61	20.9882
1203.25	23.235
1208.88	-2.67078
1214.51	37.5762
1220.13	24.8577
1225.74	5.13223
1231.36	24.1519
1236.97	16.8236
1242.57	28.1096
1248.17	15.6728
1253.77	25.044
1259.36	34.8995
1264.94	26.218
1270.53	24.5781
1276.11	32.7143
1281.68	331.475
1287.25	21.9701
1292.81	32.4909
1298.38	36.3873
1303.93	18.6158
1309.48	23.4186
1315.03	24.8307
1320.58	20.3322
1326.12	34.2263
1331.65	34.0885
1337.18	2.0882
1342.71	14.5647
1348.23	6.27493
1353.75	10.1347
1359.26	14.7609
1364.77	41.6829
1370.28	47.7548
1375.78	80.4785
1381.28	144.978
1386.77	247.356
1392.26	11.2618
1397.74	33.3413
1403.23	38.1008
1408.7	36.8301
1414.17	1.63715
1419.64	10.9019
1425.11	-0.434631
1430.56	25.642
1436.02	9.07669
1441.47	16.3975
1446.92	13.3296
1452.36	18.1822
1457.8	12.2207
1463.23	20.6825
1468.66	30.0225
1474.09	2.64987
1479.51	2.78171
1484.93	21.9284
1490.34	8.72971
1495.75	18.9137
1501.16	45.1083
1506.56	3.87149
1511.96	14.5843
1517.35	30.8478
1522.74	4.61328
1528.13	6.10037
1533.51	10.9525
1538.88	4.73389
1544.25	18.6896
1549.62	28.6762
1554.99	17.4933
1560.35	10.4557
1565.71	20.7957
1571.06	22.4514
1576.41	20.9568
1581.75	10.1659
1587.09	29.6398
1592.43	24.5152
1597.76	31.488
1603.09	17.053
1608.41	8.2627
1613.73	31.2978
1619.05	23.1565
1624.36	20.4431
1629.67	24.2592
1634.97	35.6082
1640.27	38.5526
1645.57	27.0622
1650.86	30.8932
1656.15	29.0148
1661.43	26.899
1666.71	8.05618
1671.99	24.6346
1677.26	5.63766
1682.53	5.40979
1687.79	24.8664
1693.05	19.0034
1698.31	4.72168
1703.56	14.1074
1708.81	26.0067
1714.06	21.8564
1719.3	14.0749
1724.53	33.6737
1729.77	17.696
1735	11.7458
1740.22	14.7247
1745.44	22.2216
1750.66	15.9694
1755.87	27.6508
1761.08	13.0059
1766.29	9.65033
1771.49	14.3059
1776.69	17.9296
1781.88	11.6003
1787.07	20.1771
1792.26	17.6085
1797.44	12.7899
1802.62	20.7242
1807.79	42.4515
1812.96	13.3604
1818.13	38.4056
1823.29	24.2127
1828.45	20.4417
1833.61	20.1882
1838.76	-2.22052
1843.91	29.8932
1849.05	15.2686
1854.19	25.0241
1859.33	7.99789
1864.46	9.83502
1869.59	18.7949
1874.71	34.5617
1879.83	-0.467407
1884.95	24.6017
1890.06	-4.8829
1895.17	24.4819
1900.28	20.9514
1905.38	12.0588
1910.48	11.6794
1915.57	26.0361
1920.66	17.0063
1925.75	29.5719
1930.83	12.2637
1935.91	22.4255
1940.99	22.8535
1946.06	25.5341
1951.13	24.453
1956.19	19.5771
1961.26	39.924
1966.31	21.6115
1971.36	31.9904
1976.41	23.0345
1981.46	16.4901
1986.5	23.2078
1991.54	15.5515
1996.58	3.16138
2001.61	14.9357
2006.63	14.8503
2011.66	6.47672
2016.68	12.5686
2021.69	7.71014
2026.71	10.3448
2031.72	10.7556
2036.72	22.2132
2041.72	13.1125
2046.72	12.5515
2051.71	22.9802
2056.71	18.5395
2061.69	15.5718
2066.68	29.7747
2071.66	37.811
2076.63	21.2355
2081.6	26.7072
2086.57	20.9034
2091.54	27.4253
2096.5	13.2093
2101.46	12.6888
2106.41	11.0271
2111.36	28.2076
2116.31	41.8506
2121.25	29.1588
2126.19	10.014
2131.13	12.1542
2136.06	19.2392
2140.99	28.7917
2145.92	25.5673
2150.84	22.1002
2155.76	14.6253
2160.67	14.6473
2165.58	31.0976
2170.49	24.4608
2175.39	37.2255
2180.29	29.3163
2185.19	22.4506
2190.08	31.0757
2194.98	24.515
2199.86	10.5064
2204.74	30.0548
2209.62	15.1068
2214.5	16.9872
2219.37	20.3092
2224.24	28.853
2229.11	11.4438
2233.97	18.6909
2238.83	24.657
2243.68	13.6257
2248.53	24.8729
2253.38	15.069
2258.22	26.3606
2263.06	32.3631
2267.9	35.505
2272.73	34.4668
2277.56	21.293
2282.39	34.4816
2287.21	16.8377
2292.03	31.1097
2296.85	14.7901
2301.66	2.68265
2306.47	9.48141
2311.28	4.52457
2316.08	22.4805
2320.88	15.1372
2325.68	17.1933
2330.47	9.87915
2335.26	10.7872
2340.04	26.6839
2344.82	22.3652
2349.6	14.016
2354.38	9.56796
2359.15	24.0652
2363.92	5.1351
2368.68	22.1824
2373.44	25.3778
2378.2	6.35364
2382.95	13.3859
2387.71	24.3603
2392.45	5.91431
2397.2	19.2962
2401.94	10.3454
2406.68	31.8898
2411.41	22.0333
2416.14	16.0067
2420.87	14.9839
2425.59	19.2669
2430.31	12.807
2435.03	7.88373
2439.75	5.87717
2444.46	32.2569
2449.16	25.998
2453.87	8.2186
2458.57	29.0594
2463.27	19.7836
2467.96	29.1375
2472.65	18.1736
2477.34	33.2983
2482.02	23.7274
2486.7	27.0495
2491.38	37.608
2496.05	39.4539
2500.72	29.4846
2505.39	31.1427
2510.06	26.7971
2514.72	25.2503
2519.37	8.97647
2524.03	34.1541
2528.68	11.98
2533.33	29.8295
2537.97	28.5726
2542.61	25.8793
2547.25	15.7928
2551.88	47.5096
2556.51	20.8332
2561.14	19.5454
2565.77	16.9386
2570.39	18.9513
2575.01	30.045
2579.62	7.66998
2584.23	21.3226
2588.84	21.0961
2593.45	51.0718
2598.05	34.3227
2602.65	21.9884
2607.24	29.3704
2611.84	21.3275
2616.42	4.03217
2621.01	11.2561
2625.59	13.9593
2630.17	21.4834
2634.75	21.7642
2639.32	16.3036
2643.89	7.74548
2648.46	16.2504
2653.02	30.9841
2657.58	35.7696
2662.14	15.3782
2666.69	36.9748
2671.24	-8.4776
2675.79	20.3049
2680.33	1.43866
2684.88	18.6888
2689.41	26.4969
2693.95	27.5601
2698.48	38.6427
2703.01	29.2015
2707.53	22.7937
2712.06	25.9315
2716.57	22.8928
2721.09	8.32349
2725.6	24.3205
2730.11	7.69305
2734.62	36.3177
2739.12	17.7204
2743.62	22.1844
2748.12	18.69
2752.61	12.5985
2757.1	6.18481
2761.59	15.7235
2766.08	7.4422
2770.56	8.99371
2775.04	19.0005
2779.51	22.713
2783.98	20.1796
2788.45	30.9404
2792.92	19.9194
2797.38	25.3892
2801.84	35.7492
2806.3	20.6652
2810.75	13.8256
2815.2	13.5468
2819.65	23.3683
2824.09	29.907
2828.53	9.29272
2832.97	14.0329
2837.41	5.09589
2841.84	13.2181
2846.27	24.9124
2850.69	16.2294
2855.12	9.51575
2859.54	20.0132
2863.95	32.4981
2868.37	31.4004
2872.78	14.6141
2877.18	1.24695
2881.59	12.38
2885.99	23.728
2890.39	5.13019
2894.78	11.0455
2899.18	19.0458
2903.57	48.1918
2907.95	29.1508
2912.34	20.4554
2916.72	22.2397
2921.09	17.0115
2925.47	31.669
2929.84	24.9019
2934.21	28.8777
2938.57	25.2216
2942.94	1.36694
2947.29	17.282
2951.65	16.8036
2956	29.0866
2960.36	21.2693
2964.7	9.85187
2969.05	37.0724
2973.39	9.28424
2977.73	20.0854
2982.06	36.5327
2986.4	12.6268
2990.73	11.0152
2995.05	29.9414
2999.38	32.3418
3003.7	21.7933
3008.01	56.3235
3012.33	17.3664
3016.64	29.4565
3020.95	30.3646
3025.26	30.9922
3029.56	40.7988
3033.86	27.4596
3038.16	38.6292
3042.45	42.4708
3046.74	53.7399
3051.03	43.787
3055.32	58.9489
3059.6	52.9095
3063.88	64.2537
3068.16	56.2267
3072.43	40.3854
3076.7	44.0392
3080.97	57.4784
3085.24	63.2825
3089.5	55.6947
3093.76	62.1584
3098.02	82.6991
3102.27	93.4968
3106.52	92.7046
3110.77	92.0494
3115.01	85.4177
3119.26	98.8596
3123.5	86.3882
3127.73	90.2038
3131.97	90.2515
3136.2	98.4816
3140.43	135.393
3144.65	102.077
3148.87	107.691
3153.09	164.864
3157.31	144.92
3161.52	158.339
3165.73	161.26
3169.94	168.132
3174.15	181.602
3178.35	156.284
3182.55	162.328
3186.75	191.535
3190.94	156.981
3195.13	212.158
3199.32	187.343
3203.51	206.048
3207.69	164.976
3211.87	201.347
3216.05	140.813
3220.22	188.302
3224.39	157.491
3228.56	176.885
3232.73	202.92
3236.89	162.502
3241.05	224.184
3245.21	135.348
3249.36	157.034
3253.52	160.141
3257.66	178.505
3261.81	170.859
3265.95	145.553
3270.1	159.208
3274.23	188.633
3278.37	179.69
3282.5	179.94
3286.63	129.673
3290.76	152.758
3294.88	120.477
3299	159.676
3303.12	150.703
3307.24	160.163
3311.35	174.162
3315.46	146.312
3319.57	123.129
3323.68	146.942
3327.78	175.775
3331.88	174.676
3335.98	169.308
3340.07	168.172
3344.16	168.607
3348.25	144.881
3352.34	180.679
3356.42	154.761
3360.5	138.501
3364.58	167.685
3368.66	153.673
3372.73	156.379
3376.8	192.443
3380.87	156.069
3384.93	201.621
3388.99	164.973
3393.05	162.002
3397.11	159.358
3401.16	154.283
3405.21	163.344
3409.26	172.478
3413.31	203.311
3417.35	178.24
3421.39	175.002
3425.43	169.289
3429.46	193.207
3433.5	175.858
3437.53	119.556
3441.55	168.741
3445.58	139.781
3449.6	135.693
3453.62	146.515
3457.64	160.398
3461.65	201.999
3465.66	154.056
3469.67	150.796
3473.68	116.698
3477.68	148.238
3481.68	200.133
3485.68	158.423
3489.67	118.906
3493.67	142.809
3497.66	133.284
3501.64	126.033
3505.63	118.433
3509.61	141.092
3513.59	137.711
3517.57	88.0143
3521.54	102.522
3525.52	106.866
3529.49	98.2529
3533.45	80.0464
3537.42	126.986
3541.38	52.6005
3545.34	96.8212
3549.29	83.7716
3553.25	75.0138
3557.2	97.821
3561.15	81.9205
3565.09	53.226
3569.04	64.2094
3572.98	90.7777
3576.92	75.7799
3580.85	79.5095
3584.79	94.0242
3588.72	60.9018
3592.64	91.3151
3596.57	65.9532
3600.49	82.9532
3604.41	51.7382
3608.33	73.8101
3612.25	44.6797
3616.16	53.1724
3620.07	75.0119
3623.98	31.2581
3627.88	27.7665
3631.79	40.2849
3635.69	28.5992
3639.58	60.7662
3643.48	42.098
3647.37	18.249
3651.26	28.3485
3655.15	41.5391
3659.03	21.9141
3662.92	7.58856
3666.8	18.0149
3670.67	23.0439
3674.55	14.5724
3678.42	17.5139
3682.29	1.60461
3686.16	21.8783
3690.02	28.5582
3693.89	18.5842
3697.75	8.42188
3701.61	9.474
3705.46	18.8045
3709.31	11.5682
3713.16	-1.3924
3717.01	13.3971
3720.86	13.9306
3724.7	28.4244
3728.54	34.3478
3732.38	3.5459
3736.21	12.4703
3740.04	29.8613
3743.87	10.0873
3747.7	12.9707
3751.53	21.3363
3755.35	3.69751
3759.17	2.98486
3762.99	13.6163
3766.81	-10.1749
3770.62	3.58008
3774.43	-5.49188
3778.24	8.48004
3782.04	19.9272
3785.85	17.2484
3789.65	2.84296
3793.45	17.4109
3797.24	17.9401
3801.04	9.87799
3804.83	4.82153
3808.62	5.70142
3812.4	6.40424
3816.19	12.8615
3819.97	7.57269
3823.75	5.03833
3827.52	8.19379
3831.3	2.77271
3835.07	-5.58026
3838.84	-2.31567
3842.61	7.21204
3846.37	10.1016
3850.13	6.55585
3853.89	-0.0662231
3857.65	16.9278
3861.41	27.7844
3865.16	-2.16199
3868.91	4.90088
3872.66	13.7384
3876.4	-4.72791
3880.14	15.6634
3883.89	12.2651
3887.62	18.0341
3891.36	11.9837
3895.09	12.5597
3898.82	21.9536
3902.55	-1.7323
3906.28	7.58899
3910	16.8891
3913.73	14.4372
3917.45	15.2427
3921.16	7.32458
3924.88	14.6348
3928.59	30.9317
3932.3	10.3548
3936.01	10.7616
3939.71	8.18213
3943.42	6.07227
3947.12	6.92163
3950.81	13.7214
3954.51	11.017
3958.2	14.3341
3961.9	20.3896
3965.58	29.4543
3969.27	19.5667
3972.96	3.52759
3976.64	9.22076
3980.32	14.7023
3984	-4.80682
3987.67	16.0589
3991.34	6.14941
3995.01	18.3345
3998.68	2.97357