File: Data/3-Raman/processed/bu04w-a-ff3-fi03-l_150 (500nm)_633nm_edge_100%_x100_vis_lwd_h50um_45sx2_01.txt
#Acq. time (s)=	45
#Accumulations=	2
#Range (cm-¹)=	100...4000
#Windows=	1
#Auto scanning=	Off
#Autofocus=	Off
#Macrospot=	Off
#AutoExposure=	Off
#Spike filter=	Multiple accum.
#Delay time (s)=	2
#Binning=	1
#Readout mode=	Signal
#DeNoise=	Off
#ICS correction=	On
#Dark correction=	Off
#Inst. Process=	Off
#Detector Gain=	Best Dynamic
#Detector ADC=	50 kHz HS
#Detector temperature (°C)=	-60.28
#Instrument=	LabRAM HR Evol
#Detector=	SIN-EM FIVIS
#Objective=	x100_VIS_LWD
#Grating=	150 (500nm)
#ND Filter=	100%
#Laser=	633nm_Edge
#Hole=	49.98
#Temperature=	0
#Range=	Visible
#StageXY=	75x50mm Scan+
#StageZ=	Z motor
#X (µm)=	0
#Y (µm)=	0
#Z (µm)=	-19.3
#Full time(mm:ss)=	1:38
#Project=	21_11_22
#Sample=	BU04w
#Site=
#Title=	BU04w-A-FF3-FI03-L_150 (500nm)_633nm_Edge_100%_x100_VIS_LWD_H50um_45sX2
#Remark=
#Date=	22.11.2021 12:35
#Acquired=	22.11.2021 12:35:00
#Base:Fit=	16.12.2021 16:15:35
#Base:Edit=	16.12.2021 16:22:08
#Base:Edit=	16.12.2021 16:22:09
#Base:Edit=	16.12.2021 16:22:10
#Base:Edit=	16.12.2021 16:22:11
#Base:Edit=	16.12.2021 16:22:13
#Base:Edit=	16.12.2021 16:22:15
#Base:Sub=	16.12.2021 16:22:17
100.177	425.398
106.695	343.616
113.209	308.222
119.717	284.572
126.219	250.843
132.716	265.363
139.208	259.127
145.694	227.679
152.175	193.998
158.651	284.631
165.121	284.975
171.586	163.976
178.045	112.322
184.5	84.062
190.947	58.1741
197.39	38.7816
203.829	31.0234
210.262	10.6082
216.688	16.6407
223.11	44.2914
229.527	153.243
235.939	199.967
242.344	74.4983
248.745	28.9792
255.141	18.2642
261.53	14.0501
267.916	0.18399
274.294	-12.8791
280.669	12.7334
287.038	6.76534
293.402	2.41986
299.76	-1.16194
306.114	11.1291
312.461	71.4173
318.805	223.013
325.142	428.276
331.475	282.432
337.802	128.003
344.123	64.0026
350.441	46.9636
356.752	45.7353
363.058	77.2597
369.36	73.8103
375.656	44.8881
381.947	16.8587
388.232	21.7655
394.512	32.4183
400.789	42.2651
407.059	60.5033
413.324	61.6424
419.584	105.126
425.839	167.175
432.089	207.449
438.333	171.099
444.573	125.412
450.807	144.404
457.037	127.813
463.261	76.0372
469.48	61.7891
475.695	63.475
481.904	56.7955
488.108	74.2458
494.307	87.9438
500.502	95.0536
506.691	132.958
512.874	149.429
519.053	112.724
525.227	102.241
531.396	109.624
537.559	88.8786
543.718	78.1887
549.873	75.6751
556.022	65.5284
562.165	52.1797
568.304	50.8915
574.437	43.7637
580.567	41.2472
586.691	51.9091
592.81	38.4378
598.924	51.2186
605.033	54.9831
611.138	67.2372
617.236	66.5599
623.332	62.178
629.42	52.0456
635.506	47.1648
641.585	43.8686
647.659	33.8107
653.73	52.8329
659.794	48.2341
665.854	36.1859
671.91	32.6884
677.96	23.909
684.005	18.8583
690.045	19.5444
696.082	11.8983
702.113	20.1425
708.139	9.54958
714.16	22.1971
720.176	8.45048
726.187	10.652
732.194	8.0348
738.196	8.22211
744.193	14.9578
750.185	-0.65786
756.173	8.99646
762.155	15.139
768.133	8.38368
774.107	0.673065
780.075	1.31927
786.039	5.63345
791.998	3.29706
797.952	3.70009
803.902	4.93781
809.845	4.23553
815.786	3.45221
821.721	-2.06387
827.652	4.58351
833.576	8.56987
839.498	5.27839
845.415	5.86057
851.327	7.41125
857.233	4.30666
863.135	3.09811
869.032	47.2931
874.925	35.6258
880.813	21.901
886.697	18.5199
892.576	23.5921
898.45	20.0353
904.318	22.9589
910.184	14.5255
916.044	38.1177
921.9	36.4517
927.75	46.2416
933.596	79.7449
939.439	107.103
945.275	156.556
951.107	203.629
956.936	163.131
962.759	130.776
968.577	128.768
974.391	143.83
980.201	166.197
986.006	233.3
991.806	228.348
997.602	176.605
1003.39	167.111
1009.18	163.57
1014.96	194.759
1020.74	271.859
1026.51	282.621
1032.28	164.051
1038.04	105.571
1043.8	67.9766
1049.56	58.1979
1055.31	51.1528
1061.05	47.8481
1066.8	55.0443
1072.53	51.5221
1078.26	68.3199
1083.99	89.896
1089.72	134.732
1095.44	237.621
1101.15	232.961
1106.86	123.147
1112.56	71.4117
1118.27	53.8902
1123.96	63.4073
1129.65	59.282
1135.34	82.5668
1141.03	119.704
1146.7	195.161
1152.38	321.935
1158.05	197.275
1163.71	81.2407
1169.37	40.1003
1175.03	29.4562
1180.68	23.7462
1186.33	25.977
1191.98	21.4781
1197.61	20.026
1203.25	16.7523
1208.88	7.63148
1214.51	11.3127
1220.13	8.13035
1225.74	5.92823
1231.36	6.67451
1236.97	12.3791
1242.57	12.9663
1248.17	11.4183
1253.77	11.8005
1259.36	15.1005
1264.94	39.4899
1270.53	36.6118
1276.11	20.6076
1281.68	25.7079
1287.25	16.8283
1292.81	8.02561
1298.38	9.29823
1303.93	10.6285
1309.48	11.071
1315.03	10.6251
1320.58	13.2188
1326.12	4.73779
1331.65	7.37256
1337.18	8.95426
1342.71	2.29977
1348.23	12.963
1353.75	14.3971
1359.26	15.7737
1364.77	30.442
1370.28	56.3417
1375.78	104.804
1381.28	81.3434
1386.77	36.3398
1392.26	17.0429
1397.74	16.3317
1403.23	10.4927
1408.7	8.77667
1414.17	9.13992
1419.64	3.31421
1425.11	2.65861
1430.56	6.15977
1436.02	11.753
1441.47	-6.68064
1446.92	14.6087
1452.36	1.26301
1457.8	9.87868
1463.23	11.0956
1468.66	15.4257
1474.09	2.96136
1479.51	10.4758
1484.93	6.45753
1490.34	10.8793
1495.75	7.98201
1501.16	15.6484
1506.56	8.56248
1511.96	8.89502
1517.35	13.5108
1522.74	10.6972
1528.13	12.1539
1533.51	0.737434
1538.88	22.6235
1544.25	9.9559
1549.62	14.4184
1554.99	7.95048
1560.35	10.0947
1565.71	14.4073
1571.06	20.8543
1576.41	17.6142
1581.75	33.8261
1587.09	20.9951
1592.43	17.8788
1597.76	18.0364
1603.09	30.1114
1608.41	28.2162
1613.73	27.4769
1619.05	25.6995
1624.36	19.5307
1629.67	25.3895
1634.97	20.2194
1640.27	36.9643
1645.57	24.991
1650.86	26.2391
1656.15	20.8006
1661.43	26.395
1666.71	29.7533
1671.99	25.3324
1677.26	22.0005
1682.53	21.9762
1687.79	17.4675
1693.05	16.3164
1698.31	17.4624
1703.56	18.9105
1708.81	19.2925
1714.06	20.2636
1719.3	9.325
1724.53	13.9119
1729.77	12.9502
1735	0.73423
1740.22	9.86436
1745.44	14.512
1750.66	12.3532
1755.87	10.1593
1761.08	9.04049
1766.29	6.78313
1771.49	7.93671
1776.69	-2.23369
1781.88	11.4625
1787.07	12.7111
1792.26	9.44378
1797.44	11.8842
1802.62	1.76125
1807.79	6.51566
1812.96	7.79754
1818.13	6.77982
1823.29	8.06734
1828.45	7.05083
1833.61	-3.25873
1838.76	9.67589
1843.91	3.95104
1849.05	9.88034
1854.19	5.26609
1859.33	11.2147
1864.46	10.1613
1869.59	2.05135
1874.71	0.938675
1879.83	5.71125
1884.95	9.30065
1890.06	5.76649
1895.17	-0.17704
1900.28	10.4688
1905.38	10.5758
1910.48	7.16343
1915.57	2.61662
1920.66	0.312653
1925.75	-1.98273
1930.83	0.511543
1935.91	1.80424
1940.99	10.2911
1946.06	6.73926
1951.13	-0.457352
1956.19	6.77049
1961.26	6.75867
1966.31	7.93779
1971.36	11.4879
1976.41	5.39267
1981.46	10.1353
1986.5	10.0672
1991.54	8.80866
1996.58	13.5749
2001.61	9.94923
2006.63	11.1625
2011.66	14.8104
2016.68	12.4471
2021.69	5.24023
2026.71	14.9599
2031.72	12.6572
2036.72	9.16399
2041.72	12.9422
2046.72	9.45404
2051.71	5.95638
2056.71	14.609
2061.69	18.4527
2066.68	18.6404
2071.66	5.29852
2076.63	11.5983
2081.6	8.03979
2086.57	6.91184
2091.54	7.01411
2096.5	15.8493
2101.46	21.0139
2106.41	15.0126
2111.36	12.7487
2116.31	14.2539
2121.25	11.9947
2126.19	16.0157
2131.13	9.92524
2136.06	10.118
2140.99	11.5647
2145.92	16.8224
2150.84	16.9574
2155.76	18.339
2160.67	8.19561
2165.58	9.512
2170.49	9.5379
2175.39	8.3212
2180.29	5.79062
2185.19	16.0234
2190.08	10.9183
2194.98	10.9647
2199.86	12.3384
2204.74	12.4686
2209.62	10.0572
2214.5	7.65807
2219.37	11.7356
2224.24	10.6534
2229.11	10.864
2233.97	0.65329
2238.83	6.06133
2243.68	8.87732
2248.53	15.6493
2253.38	13.2348
2258.22	6.85691
2263.06	11.0184
2267.9	3.23281
2272.73	12.6422
2277.56	3.44511
2282.39	11.486
2287.21	6.19159
2292.03	2.22364
2296.85	3.57978
2301.66	12.9669
2306.47	3.74545
2311.28	7.89832
2316.08	-1.30032
2320.88	10.963
2325.68	5.78677
2330.47	8.69475
2335.26	8.93369
2340.04	3.74559
2344.82	17.6275
2349.6	13.8392
2354.38	3.13163
2359.15	14.3367
2363.92	10.354
2368.68	13.2856
2373.44	3.75097
2378.2	10.8265
2382.95	12.3178
2387.71	6.81448
2392.45	13.7953
2397.2	11.006
2401.94	8.20499
2406.68	10.9505
2411.41	11.0118
2416.14	8.45486
2420.87	14.4374
2425.59	8.90697
2430.31	11.8965
2435.03	10.6857
2439.75	5.23041
2444.46	9.68964
2449.16	9.8968
2453.87	2.94368
2458.57	4.55519
2463.27	10.49
2467.96	7.78506
2472.65	18.0687
2477.34	8.10094
2482.02	3.88972
2486.7	9.83318
2491.38	8.48492
2496.05	20.3059
2500.72	13.0933
2505.39	13.1833
2510.06	-4.40479
2514.72	5.92999
2519.37	13.3447
2524.03	11.935
2528.68	7.54766
2533.33	3.15578
2537.97	9.16276
2542.61	10.7359
2547.25	3.37676
2551.88	9.43563
2556.51	15.5012
2561.14	12.5814
2565.77	6.66999
2570.39	3.76038
2575.01	6.88177
2579.62	2.41158
2584.23	5.46495
2588.84	10.0087
2593.45	9.96243
2598.05	16.0715
2602.65	8.44944
2607.24	17.5886
2611.84	11.433
2616.42	9.84458
2621.01	5.19759
2625.59	-0.983398
2630.17	9.73167
2634.75	3.62871
2639.32	9.89889
2643.89	17.7592
2648.46	16.3563
2653.02	11.8174
2657.58	11.8312
2662.14	2.43479
2666.69	13.326
2671.24	7.04961
2675.79	7.11966
2680.33	10.5196
2684.88	9.15249
2689.41	18.9278
2693.95	4.70373
2698.48	11.0635
2703.01	1.42987
2707.53	4.61097
2712.06	6.17377
2716.57	6.1664
2721.09	15.843
2725.6	9.30314
2730.11	7.58243
2734.62	4.19894
2739.12	12.1721
2743.62	3.93163
2748.12	8.73509
2752.61	7.12737
2757.1	0.54921
2761.59	-1.19595
2766.08	5.30339
2770.56	6.88206
2775.04	1.89414
2779.51	6.85122
2783.98	11.8952
2788.45	5.30426
2792.92	12.0244
2797.38	13.7206
2801.84	15.3947
2806.3	11.9849
2810.75	1.78885
2815.2	6.74087
2819.65	8.31322
2824.09	1.42424
2828.53	11.4938
2832.97	7.97209
2837.41	4.42881
2841.84	5.99584
2846.27	-6.08086
2850.69	9.20254
2855.12	14.3029
2859.54	2.2337
2863.95	3.9305
2868.37	3.93434
2872.78	9.13644
2877.18	0.447144
2881.59	10.9389
2885.99	5.74548
2890.39	4.01662
2894.78	4.02948
2899.18	9.40073
2903.57	18.3263
2907.95	9.43761
2912.34	7.60696
2916.72	0.355232
2921.09	0.279274
2925.47	12.8256
2929.84	7.40694
2934.21	14.6236
2938.57	5.47263
2942.94	7.16933
2947.29	10.6571
2951.65	3.20745
2956	15.826
2960.36	13.8448
2964.7	2.71309
2969.05	6.24837
2973.39	13.4831
2977.73	2.3253
2982.06	18.8231
2986.4	13.2404
2990.73	20.6438
2995.05	13.2198
2999.38	16.9776
3003.7	15.1684
3008.01	18.995
3012.33	15.2733
3016.64	24.8091
3020.95	23.0489
3025.26	38.3625
3029.56	23.1437
3033.86	30.7718
3038.16	44.1128
3042.45	36.4426
3046.74	30.6105
3051.03	40.1721
3055.32	40.1216
3059.6	30.4045
3063.88	41.9671
3068.16	43.8655
3072.43	49.6613
3076.7	45.7523
3080.97	51.5942
3085.24	61.4037
3089.5	61.5263
3093.76	65.6615
3098.02	83.6916
3102.27	86.0088
3106.52	84.4355
3110.77	94.8582
3115.01	85.3465
3119.26	77.7774
3123.5	108.568
3127.73	113.312
3131.97	110.028
3136.2	112.856
3140.43	123.883
3144.65	126.659
3148.87	131.469
3153.09	163.213
3157.31	149.159
3161.52	174.795
3165.73	156.466
3169.94	180.051
3174.15	182.735
3178.35	172.479
3182.55	195.969
3186.75	215.22
3190.94	211.116
3195.13	213.579
3199.32	235.529
3203.51	228.008
3207.69	229.112
3211.87	241.058
3216.05	261.876
3220.22	228.399
3224.39	238.297
3228.56	235.132
3232.73	223.093
3236.89	224.075
3241.05	220.787
3245.21	228.756
3249.36	218.693
3253.52	199.296
3257.66	217.824
3261.81	212.01
3265.95	195.026
3270.1	230.376
3274.23	217.966
3278.37	202.479
3282.5	214.457
3286.63	210.414
3290.76	204.027
3294.88	211.401
3299	204.955
3303.12	219.41
3307.24	196.8
3311.35	220.513
3315.46	195.444
3319.57	209.956
3323.68	212.986
3327.78	232.514
3331.88	226.477
3335.98	211.138
3340.07	221.556
3344.16	222.253
3348.25	244.179
3352.34	232.923
3356.42	221.678
3360.5	227.194
3364.58	254.296
3368.66	259.869
3372.73	246.205
3376.8	258.842
3380.87	247.326
3384.93	247.822
3388.99	265.211
3393.05	251.123
3397.11	241.984
3401.16	269.236
3405.21	255.07
3409.26	255.495
3413.31	270.441
3417.35	270.827
3421.39	271.192
3425.43	266.67
3429.46	259.839
3433.5	267.76
3437.53	266.023
3441.55	261.909
3445.58	250.538
3449.6	263.907
3453.62	262.56
3457.64	261.416
3461.65	242.951
3465.66	246.845
3469.67	253.241
3473.68	236.804
3477.68	243.075
3481.68	229.142
3485.68	230.295
3489.67	223.789
3493.67	181.537
3497.66	192.616
3501.64	213.904
3505.63	199.264
3509.61	176.71
3513.59	192.526
3517.57	177.51
3521.54	162.472
3525.52	162.891
3529.49	171.012
3533.45	166.488
3537.42	164.725
3541.38	150.06
3545.34	117.051
3549.29	146.225
3553.25	136.222
3557.2	115.898
3561.15	108.636
3565.09	114.47
3569.04	120.47
3572.98	110.731
3576.92	111.534
3580.85	80.8295
3584.79	86.9667
3588.72	90.4832
3592.64	75.415
3596.57	84.2406
3600.49	74.3636
3604.41	88.5224
3608.33	65.1148
3612.25	65.7802
3616.16	55.6699
3620.07	58.9889
3623.98	56.7745
3627.88	57.2207
3631.79	57.6299
3635.69	49.9468
3639.58	36.9202
3643.48	37.5268
3647.37	38.1876
3651.26	38.634
3655.15	33.6851
3659.03	25.9841
3662.92	23.7129
3666.8	15.9991
3670.67	13.7477
3674.55	16.9915
3678.42	9.33035
3682.29	7.18249
3686.16	-0.441467
3690.02	2.96137
3693.89	3.60264
3697.75	-1.32832
3701.61	16.0194
3705.46	-0.0850677
3709.31	0.552216
3713.16	-1.62617
3717.01	7.41021
3720.86	7.99477
3724.7	0.0783539
3728.54	3.44625
3732.38	4.00053
3736.21	-18.182
3740.04	-14.8288
3743.87	-8.62608
3747.7	-8.13178
3751.53	-1.9409
3755.35	4.23562
3759.17	-3.92559
3762.99	-3.51236
3766.81	-5.97079
3770.62	-2.67189
3774.43	-13.7163
3778.24	6.83668
3782.04	1.56402
3785.85	-3.70443
3789.65	-6.12135
3793.45	-2.75892
3797.24	6.43774
3801.04	6.96975
3804.83	1.69395
3808.62	-12.3459
3812.4	5.67038
3816.19	-11.3849
3819.97	3.74915
3823.75	10.1032
3827.52	-4.147
3831.3	-3.68833
3835.07	5.63075
3838.84	-2.79359
3842.61	12.4887
3846.37	1.02723
3850.13	1.3758
3853.89	1.71018
3857.65	2.02513
3861.41	11.236
3865.16	-6.25288
3868.91	-8.79224
3872.66	3.49352
3876.4	0.815628
3880.14	-1.87167
3883.89	7.40945
3887.62	4.73468
3891.36	14.0548
3895.09	-12.5917
3898.82	8.78692
3902.55	0.0951309
3906.28	-5.62276
3910	0.718422
3913.73	1.0427
3917.45	10.4763
3921.16	13.8964
3924.88	2.0906
3928.59	8.52775
3932.3	-3.39429
3936.01	-6.20243
3939.71	3.25272
3943.42	6.62092
3947.12	3.82182
3950.81	-2.10061
3954.51	-1.8884
3958.2	1.39735
3961.9	1.55624
3965.58	1.69876
3969.27	1.80483
3972.96	-1.19418
3976.64	-1.10051
3980.32	5.1714
3984	2.11595
3987.67	2.15736
3991.34	14.6135
3995.01	2.27752
3998.68	2.3677