File: Data/3-Raman/processed/bu04w-a-ff3-fi01-l_150 (500nm)_633nm_edge_100%_x100_vis_lwd_h50um_45sx2_01.txt
#Acq. time (s)=	45
#Accumulations=	2
#Range (cm-¹)=	100...4000
#Windows=	1
#Auto scanning=	Off
#Autofocus=	Off
#Macrospot=	Off
#AutoExposure=	Off
#Spike filter=	Multiple accum.
#Delay time (s)=	2
#Binning=	1
#Readout mode=	Signal
#DeNoise=	Off
#ICS correction=	On
#Dark correction=	Off
#Inst. Process=	Off
#Detector Gain=	Best Dynamic
#Detector ADC=	50 kHz HS
#Detector temperature (°C)=	-60.09
#Instrument=	LabRAM HR Evol
#Detector=	SIN-EM FIVIS
#Objective=	x100_VIS_LWD
#Grating=	150 (500nm)
#ND Filter=	100%
#Laser=	633nm_Edge
#Hole=	49.98
#Temperature=	0
#Range=	Visible
#StageXY=	75x50mm Scan+
#StageZ=	Z motor
#X (µm)=	0
#Y (µm)=	0
#Z (µm)=	14.5
#Full time(mm:ss)=	1:35
#Project=	21_11_22
#Sample=	BU04w
#Site=
#Title=	BU04w-A-FF3-L_150 (500nm)_633nm_Edge_100%_x100_VIS_LWD_H50um_45sX2
#Remark=
#Date=	22.11.2021 10:25
#Acquired=	22.11.2021 10:25:40
#Base:Fit=	16.12.2021 16:15:35
#Base:Edit=	16.12.2021 16:21:03
#Base:Edit=	16.12.2021 16:21:04
#Base:Sub=	16.12.2021 16:21:06
100.177	541.187
106.695	475.599
113.209	402.301
119.717	401.053
126.219	325.871
132.716	301.916
139.208	291.733
145.694	300.528
152.175	256.529
158.651	264.223
165.121	296.659
171.586	276.868
178.045	160.581
184.5	95.5152
190.947	97.9279
197.39	65.7625
203.829	23.4978
210.262	17.3036
216.688	0.383148
223.11	12.7418
229.527	63.5616
235.939	156.91
242.344	149.237
248.745	41.9648
255.141	34.9981
261.53	31.6878
267.916	11.1306
274.294	12.2347
280.669	22.5837
287.038	44.9016
293.402	22.3257
299.76	5.2323
306.114	9.65829
312.461	18.6045
318.805	99.0796
325.142	296.428
331.475	453.899
337.802	283.828
344.123	144.73
350.441	67.6385
356.752	69.4455
363.058	94.5214
369.36	81.7544
375.656	98.8572
381.947	78.2495
388.232	76.5289
394.512	70.2423
400.789	75.319
407.059	98.1168
413.324	116.026
419.584	125.15
425.839	198.08
432.089	237.709
438.333	339.083
444.573	243.428
450.807	191.068
457.037	187.556
463.261	189.837
469.48	137.313
475.695	117.534
481.904	116.374
488.108	129.96
494.307	116.445
500.502	133.56
506.691	169.31
512.874	183.577
519.053	194.144
525.227	169.299
531.396	166.004
537.559	163.663
543.718	139.313
549.873	128.642
556.022	111.216
562.165	110.282
568.304	100.555
574.437	79.3032
580.567	98.2653
586.691	80.7994
592.81	94.3103
598.924	107.019
605.033	133.172
611.138	121.171
617.236	110.201
623.332	106.738
629.42	97.4938
635.506	94.3294
641.585	96.4154
647.659	85.0616
653.73	84.9122
659.794	103.331
665.854	104.821
671.91	77.5461
677.96	74.0203
684.005	65.8212
690.045	54.0535
696.082	51.7174
702.113	37.1256
708.139	46.8332
714.16	44.0064
720.176	49.5305
726.187	37.1671
732.194	36.8477
738.196	27.1566
744.193	32.4493
750.185	32.1868
756.173	34.8232
762.155	29.3382
768.133	30.5952
774.107	16.8745
780.075	17.1104
786.039	33.2383
791.998	28.584
797.952	33.2438
803.902	0.997757
809.845	19.5943
815.786	7.02274
821.721	12.2642
827.652	15.587
833.576	11.6322
839.498	21.9424
845.415	14.6672
851.327	19.6076
857.233	13.3433
863.135	15.5797
869.032	28.2448
874.925	69.27
880.813	31.503
886.697	29.6653
892.576	24.887
898.45	20.0169
904.318	15.9456
910.184	24.1293
916.044	37.9313
921.9	24.6713
927.75	37.9341
933.596	44.844
939.439	73.788
945.275	114.427
951.107	165.937
956.936	187.182
962.759	173.883
968.577	146.881
974.391	131.086
980.201	155.192
986.006	224.991
991.806	289.692
997.602	267.263
1003.39	218.396
1009.18	194.69
1014.96	198.164
1020.74	260.879
1026.51	309.878
1032.28	257.585
1038.04	155.14
1043.8	97.4608
1049.56	78.1279
1055.31	54.6654
1061.05	48.4766
1066.8	37.2241
1072.53	36.6311
1078.26	53.4512
1083.99	76.9968
1089.72	84.0947
1095.44	134.78
1101.15	229.896
1106.86	190.825
1112.56	100.51
1118.27	63.831
1123.96	35.5422
1129.65	42.2699
1135.34	42.2002
1141.03	60.7817
1146.7	92.0796
1152.38	166.723
1158.05	297.208
1163.71	163.466
1169.37	75.2097
1175.03	36.2354
1180.68	15.0207
1186.33	19.3894
1191.98	14.1189
1197.61	8.00512
1203.25	14.7801
1208.88	2.01355
1214.51	-0.933678
1220.13	14.0239
1225.74	-3.77185
1231.36	3.2766
1236.97	13.313
1242.57	13.1964
1248.17	16.9797
1253.77	8.53831
1259.36	15.1174
1264.94	20.5835
1270.53	32.0673
1276.11	36.3968
1281.68	21.6413
1287.25	8.00642
1292.81	14.4627
1298.38	12.0072
1303.93	6.6252
1309.48	12.3766
1315.03	2.2207
1320.58	4.11457
1326.12	8.08438
1331.65	16.1588
1337.18	20.1473
1342.71	16.9165
1348.23	12.5551
1353.75	12.2432
1359.26	16.9966
1364.77	26.8118
1370.28	25.2445
1375.78	68.8552
1381.28	138.086
1386.77	58.4322
1392.26	38.3757
1397.74	33.8653
1403.23	23.1939
1408.7	10.4538
1414.17	18.3353
1419.64	1.43876
1425.11	9.36514
1430.56	10.0505
1436.02	12.8085
1441.47	13.4655
1446.92	19.3658
1452.36	15.7311
1457.8	4.65866
1463.23	14.517
1468.66	13.8317
1474.09	11.0455
1479.51	5.14645
1484.93	8.7095
1490.34	17.5713
1495.75	7.54422
1501.16	13.3297
1506.56	17.0445
1511.96	15.5068
1517.35	9.73019
1522.74	19.937
1528.13	18.4315
1533.51	14.7827
1538.88	19.6614
1544.25	6.10358
1549.62	23.7281
1554.99	21.747
1560.35	16.4811
1565.71	17.7133
1571.06	29.7007
1576.41	27.6831
1581.75	31.1319
1587.09	29.2192
1592.43	28.4122
1597.76	25.4934
1603.09	22.5982
1608.41	24.078
1613.73	36.504
1619.05	34.9012
1624.36	39.85
1629.67	38.2257
1634.97	39.8377
1640.27	37.9597
1645.57	43.7952
1650.86	31.8842
1656.15	44.2859
1661.43	37.7877
1666.71	35.6942
1671.99	34.6879
1677.26	30.3287
1682.53	29.272
1687.79	23.7232
1693.05	25.9611
1698.31	26.0752
1703.56	23.1866
1708.81	30.3617
1714.06	13.5332
1719.3	16.0565
1724.53	27.4302
1729.77	16.4537
1735	12.1691
1740.22	20.2446
1745.44	12.5432
1750.66	14.9469
1755.87	20.718
1761.08	12.848
1766.29	12.8919
1771.49	6.14914
1776.69	8.48409
1781.88	1.78181
1787.07	11.0063
1792.26	11.1836
1797.44	11.3682
1802.62	10.4374
1807.79	12.94
1812.96	21.1662
1818.13	8.65594
1823.29	7.65235
1828.45	8.97054
1833.61	9.14043
1838.76	4.64693
1843.91	21.0986
1849.05	14.2103
1854.19	11.9533
1859.33	12.0618
1864.46	0.448975
1869.59	5.2767
1874.71	5.35618
1879.83	8.96221
1884.95	0.747864
1890.06	-5.14912
1895.17	13.7405
1900.28	4.29123
1905.38	4.39587
1910.48	5.72959
1915.57	13.1061
1920.66	3.66657
1925.75	4.97488
1930.83	1.50224
1935.91	5.20815
1940.99	11.3068
1946.06	13.7846
1951.13	-1.82587
1956.19	7.8231
1961.26	-1.81787
1966.31	15.0429
1971.36	8.96533
1976.41	10.1106
1981.46	0.425499
1986.5	5.19056
1991.54	6.35699
1996.58	12.3458
2001.61	11.1463
2006.63	7.57295
2011.66	10.0402
2016.68	14.9275
2021.69	11.3664
2026.71	6.64389
2031.72	6.77796
2036.72	6.94101
2041.72	11.9647
2046.72	3.64935
2051.71	9.92783
2056.71	7.64334
2061.69	12.7387
2066.68	8.05478
2071.66	5.79617
2076.63	10.9151
2081.6	9.87348
2086.57	10.0366
2091.54	20.0959
2096.5	10.418
2101.46	11.9006
2106.41	9.67479
2111.36	8.70846
2116.31	6.50592
2121.25	9.31919
2126.19	15.9233
2131.13	12.4324
2136.06	10.1689
2140.99	5.33826
2145.92	10.6599
2150.84	13.4139
2155.76	9.76571
2160.67	13.7524
2165.58	10.0432
2170.49	15.2715
2175.39	11.5887
2180.29	9.15044
2185.19	6.67591
2190.08	11.9066
2194.98	10.7694
2199.86	8.3941
2204.74	13.7549
2209.62	11.4466
2214.5	18.1796
2219.37	14.6297
2224.24	11.0673
2229.11	8.78622
2233.97	5.19131
2238.83	12.0258
2243.68	5.80213
2248.53	0.863724
2253.38	3.78939
2258.22	19.9293
2263.06	8.36815
2267.9	8.64614
2272.73	12.8754
2277.56	11.774
2282.39	10.6371
2287.21	12.1214
2292.03	10.9451
2296.85	9.77168
2301.66	11.3001
2306.47	7.54015
2311.28	9.1539
2316.08	8.12153
2320.88	17.8483
2325.68	19.5481
2330.47	10.4675
2335.26	8.12753
2340.04	11.2126
2344.82	10.2473
2349.6	2.44907
2354.38	8.30047
2359.15	4.50414
2363.92	-0.746002
2368.68	20.2591
2373.44	8.09855
2378.2	6.98589
2382.95	5.82545
2387.71	3.23434
2392.45	22.877
2397.2	-0.648911
2401.94	7.82609
2406.68	7.9308
2411.41	12.3016
2416.14	9.86687
2420.87	1.91782
2425.59	14.781
2430.31	5.21671
2435.03	8.34532
2439.75	8.66935
2444.46	16.0968
2449.16	0.741882
2453.87	6.75022
2458.57	1.30732
2463.27	8.78025
2467.96	19.1672
2472.65	16.5664
2477.34	13.9539
2482.02	17.1344
2486.7	13.0105
2491.38	11.7748
2496.05	25.17
2500.72	12.2044
2505.39	0.642975
2510.06	12.5661
2514.72	18.6069
2519.37	9.91164
2524.03	11.5483
2528.68	25.0153
2533.33	11.85
2537.97	20.9312
2542.61	13.6823
2547.25	15.3584
2551.88	15.5415
2556.51	8.21583
2561.14	14.3608
2565.77	8.5214
2570.39	20.7612
2575.01	7.35383
2579.62	9.00771
2584.23	13.655
2588.84	13.7169
2593.45	12.222
2598.05	18.3924
2602.65	18.4578
2607.24	15.448
2611.84	10.8761
2616.42	9.3427
2621.01	16.9956
2625.59	15.4718
2630.17	3.22575
2634.75	20.2102
2639.32	6.48461
2643.89	11.2479
2648.46	11.3825
2653.02	11.5048
2657.58	9.97212
2662.14	11.5315
2666.69	5.2341
2671.24	6.7905
2675.79	6.85081
2680.33	19.6928
2684.88	5.63219
2689.41	15.3528
2693.95	10.6854
2698.48	15.4425
2703.01	13.8315
2707.53	5.74985
2712.06	7.2944
2716.57	8.87579
2721.09	10.434
2725.6	10.3442
2730.11	11.8453
2734.62	-1.30771
2739.12	-3.11779
2743.62	14.6311
2748.12	6.36698
2752.61	6.32641
2757.1	12.7959
2761.59	12.6587
2766.08	9.26201
2770.56	14.0804
2775.04	-0.864052
2779.51	5.66286
2783.98	-2.6721
2788.45	8.92702
2792.92	3.86555
2797.38	8.80186
2801.84	8.69437
2806.3	6.86782
2810.75	1.6377
2815.2	8.19402
2819.65	6.2962
2824.09	11.181
2828.53	7.58699
2832.97	3.96532
2837.41	12.2435
2841.84	1.78423
2846.27	-0.151466
2850.69	11.6122
2855.12	16.6033
2859.54	13.0225
2863.95	12.9012
2868.37	9.3435
2872.78	2.28185
2877.18	7.36906
2881.59	22.9896
2885.99	1.91832
2890.39	3.55574
2894.78	1.66209
2899.18	3.33467
2903.57	10.3191
2907.95	3.04909
2912.34	1.06483
2916.72	4.41547
2921.09	6.00756
2925.47	5.82072
2929.84	2.04371
2934.21	14.5357
2938.57	3.43066
2942.94	12.2613
2947.29	8.33701
2951.65	6.22152
2956	5.92322
2960.36	12.9391
2964.7	3.50145
2969.05	8.73476
2973.39	15.8346
2977.73	22.9633
2982.06	2.44469
2986.4	9.63058
2990.73	18.7342
2995.05	3.71645
2999.38	5.43134
3003.7	9.05277
3008.01	1.43737
3012.33	6.93892
3016.64	10.6252
3020.95	14.3594
3025.26	16.1724
3029.56	21.7568
3033.86	27.3326
3038.16	15.6167
3042.45	15.4351
3046.74	11.3608
3051.03	24.618
3055.32	26.3448
3059.6	28.0861
3063.88	33.7069
3068.16	37.4107
3072.43	31.4055
3076.7	48.7779
3080.97	38.891
3085.24	52.4707
3089.5	42.6492
3093.76	58.4137
3098.02	62.4907
3102.27	56.7044
3106.52	74.7836
3110.77	67.1039
3115.01	73.3971
3119.26	85.7819
3123.5	100.349
3127.73	94.8116
3131.97	89.299
3136.2	87.8316
3140.43	98.6504
3144.65	111.561
3148.87	105.854
3153.09	127.029
3157.31	110.704
3161.52	127.779
3165.73	142.839
3169.94	153.695
3174.15	156.242
3178.35	167.027
3182.55	158.689
3186.75	158.76
3190.94	186.392
3195.13	186.644
3199.32	202.085
3203.51	179.423
3207.69	203.929
3211.87	196.329
3216.05	193.093
3220.22	211.506
3224.39	184.19
3228.56	191.749
3232.73	190.529
3236.89	204.638
3241.05	194.613
3245.21	195.779
3249.36	199.003
3253.52	190.764
3257.66	202.542
3261.81	180.908
3265.95	172.867
3270.1	176.305
3274.23	170.538
3278.37	180.147
3282.5	198.988
3286.63	169.688
3290.76	167.864
3294.88	182.134
3299	194.156
3303.12	192.442
3307.24	195.336
3311.35	168.004
3315.46	149.883
3319.57	169.036
3323.68	202.415
3327.78	198.556
3331.88	197.185
3335.98	203.041
3340.07	213.511
3344.16	207.161
3348.25	229.15
3352.34	217.957
3356.42	218.696
3360.5	200.405
3364.58	208.386
3368.66	233.164
3372.73	224.36
3376.8	208.167
3380.87	228.049
3384.93	243.127
3388.99	212.269
3393.05	261.183
3397.11	237.637
3401.16	233.451
3405.21	243.678
3409.26	224.767
3413.31	222.789
3417.35	271.99
3421.39	238.368
3425.43	263.235
3429.46	241.89
3433.5	252.372
3437.53	231.16
3441.55	244.295
3445.58	242.86
3449.6	251.415
3453.62	240.286
3457.64	244.162
3461.65	233.232
3465.66	244.713
3469.67	253.739
3473.68	207.294
3477.68	228.729
3481.68	222.471
3485.68	198.392
3489.67	186.851
3493.67	205.805
3497.66	183.871
3501.64	187.365
3505.63	198.464
3509.61	196.592
3513.59	186.889
3517.57	177.16
3521.54	164.844
3525.52	162.84
3529.49	163.384
3533.45	156.409
3537.42	162.504
3541.38	142.779
3545.34	125.45
3549.29	126.187
3553.25	113.711
3557.2	103.905
3561.15	104.566
3565.09	105.293
3569.04	100.921
3572.98	112.209
3576.92	105.236
3580.85	71.9702
3584.79	88.73
3588.72	92.3323
3592.64	87.9739
3596.57	78.2574
3600.49	73.7803
3604.41	58.546
3608.33	64.6676
3612.25	62.7099
3616.16	60.7417
3620.07	53.3309
3623.98	70.0966
3627.88	57.0972
3631.79	57.5717
3635.69	47.2401
3639.58	47.805
3643.48	26.7428
3647.37	27.399
3651.26	38.7657
3655.15	31.1168
3659.03	23.435
3662.92	18.45
3666.8	29.8685
3670.67	3.01585
3674.55	3.50198
3678.42	12.2586
3682.29	23.833
3686.16	13.4526
3690.02	8.54874
3693.89	6.37597
3697.75	4.17028
3701.61	13.1034
3705.46	5.29991
3709.31	-5.33767
3713.16	0.808647
3717.01	-1.50144
3720.86	1.79552
3724.7	-0.572563
3728.54	2.69589
3732.38	-2.53197
3736.21	-7.78418
3740.04	1.16589
3743.87	-9.84016
3747.7	-3.75921
3751.53	2.31024
3755.35	-8.81208
3759.17	-8.51945
3762.99	-5.37721
3766.81	-7.97562
3770.62	-1.9576
3774.43	-4.5421
3778.24	4.3624
3782.04	10.4286
3785.85	-0.767883
3789.65	-3.35982
3793.45	-8.85005
3797.24	11.7275
3801.04	-2.43896
3804.83	3.69715
3808.62	1.11724
3812.4	-4.41813
3816.19	-1.20891
3819.97	2.00277
3823.75	-0.67054
3827.52	-0.430885
3831.3	-6.07391
3835.07	-2.87964
3838.84	0.305939
3842.61	0.557686
3846.37	3.717
3850.13	0.897423
3853.89	4.00576
3857.65	-1.81753
3861.41	13.149
3865.16	-7.50755
3868.91	-7.26797
3872.66	-7.11268
3876.4	-1.01043
3880.14	-3.87159
3883.89	2.24815
3887.62	-3.58865
3891.36	-6.42734
3895.09	5.78774
3898.82	2.98581
3902.55	6.20613
3906.28	3.39445
3910	3.5963
3913.73	-11.3068
3917.45	1.04903
3921.16	7.41225
3924.88	-4.46882
3928.59	-4.19572
3932.3	2.19077
3936.01	5.51482
3939.71	-12.6161
3943.42	9.2013
3947.12	-2.78208
3950.81	-2.46656
3954.51	-2.15294
3958.2	1.26002
3961.9	4.67078
3965.58	11.1956
3969.27	2.22103
3972.96	5.66658
3976.64	6.03763
3980.32	3.31489
3984	6.80714
3987.67	-2.07426
3991.34	4.59401
3995.01	2.0134
3998.68	11.9094