File: Data/3-Raman/processed/bu04w-a-ff3-fi07-v_150 (500nm)_633nm_edge_100%_x100_vis_lwd_h50um_45sx2_01.txt
#Acq. time (s)=	45
#Accumulations=	2
#Range (cm-¹)=	100...4000
#Windows=	1
#Auto scanning=	Off
#Autofocus=	Off
#Macrospot=	Off
#AutoExposure=	Off
#Spike filter=	Multiple accum.
#Delay time (s)=	2
#Binning=	1
#Readout mode=	Signal
#DeNoise=	Off
#ICS correction=	On
#Dark correction=	Off
#Inst. Process=	Off
#Detector Gain=	Best Dynamic
#Detector ADC=	50 kHz HS
#Detector temperature (°C)=	-60.09
#Instrument=	LabRAM HR Evol
#Detector=	SIN-EM FIVIS
#Objective=	x100_VIS_LWD
#Grating=	150 (500nm)
#ND Filter=	100%
#Laser=	633nm_Edge
#Hole=	49.98
#Temperature=	0
#Range=	Visible
#StageXY=	75x50mm Scan+
#StageZ=	Z motor
#X (µm)=	0
#Y (µm)=	0
#Z (µm)=	-18
#Full time(mm:ss)=	1:34
#Project=	21_11_22
#Sample=	BU04w
#Site=
#Title=	BU04w-A-FF3-FI07-V_150 (500nm)_633nm_Edge_100%_x100_VIS_LWD_H50um_45sX2
#Remark=
#Date=	22.11.2021 12:42
#Acquired=	22.11.2021 12:42:14
#Base:Fit=	16.12.2021 16:15:35
#Base:Edit=	16.12.2021 16:24:21
#Base:Edit=	16.12.2021 16:24:24
#Base:Edit=	16.12.2021 16:24:24
#Base:Edit=	16.12.2021 16:24:25
#Base:Edit=	16.12.2021 16:24:26
#Base:Sub=	16.12.2021 16:24:28
100.177	356.714
106.695	325.744
113.209	289.279
119.717	263.32
126.219	246.945
132.716	243.932
139.208	262.76
145.694	204.039
152.175	172.03
158.651	297.046
165.121	328.145
171.586	122.102
178.045	67.0549
184.5	37.4546
190.947	29.4216
197.39	18.1777
203.829	24.0133
210.262	13.2219
216.688	22.9784
223.11	69.3981
229.527	204.478
235.939	311.215
242.344	146.533
248.745	72.9382
255.141	100.248
261.53	106.133
267.916	52.6395
274.294	57.3969
280.669	97.5243
287.038	114.081
293.402	51.1724
299.76	34.0143
306.114	32.1916
312.461	129.778
318.805	357.666
325.142	752.784
331.475	492.37
337.802	217.123
344.123	61.8762
350.441	63.235
356.752	87.2047
363.058	103.652
369.36	103.233
375.656	21.2173
381.947	17.3067
388.232	-0.327286
394.512	42.4406
400.789	58.4132
407.059	67.8701
413.324	103.772
419.584	168.024
425.839	287.737
432.089	427.705
438.333	328.658
444.573	220.649
450.807	220.762
457.037	195.801
463.261	105.115
469.48	55.9366
475.695	55.4389
481.904	72.7424
488.108	84.4047
494.307	66.2713
500.502	117.08
506.691	170.793
512.874	185.403
519.053	172.118
525.227	146.847
531.396	137.578
537.559	118.015
543.718	103.74
549.873	80.5557
556.022	80.8575
562.165	56.1351
568.304	41.5606
574.437	26.7981
580.567	44.7561
586.691	62.7345
592.81	155.411
598.924	241.651
605.033	180.366
611.138	140.528
617.236	147.565
623.332	135.937
629.42	120.347
635.506	137.093
641.585	105.227
647.659	121.116
653.73	140.57
659.794	143.79
665.854	105.882
671.91	58.984
677.96	27.5014
684.005	24.8979
690.045	6.56729
696.082	12.5973
702.113	14.8351
708.139	8.51019
714.16	4.65823
720.176	17.5988
726.187	21.0705
732.194	1.84602
738.196	18.1931
744.193	4.59689
750.185	20.9165
756.173	20.5197
762.155	13.8597
768.133	24.2149
774.107	6.48044
780.075	10.1715
786.039	19.3647
791.998	26.5874
797.952	14.8028
803.902	12.2776
809.845	20.9593
815.786	23.8358
821.721	20.983
827.652	11.5455
833.576	5.14825
839.498	24.2291
845.415	27.6177
851.327	19.782
857.233	32.6535
863.135	33.3525
869.032	35.9313
874.925	44.9777
880.813	70.9447
886.697	68.3321
892.576	60.8218
898.45	58.8491
904.318	42.4531
910.184	36.4561
916.044	66.2251
921.9	79.2421
927.75	97.2158
933.596	124.906
939.439	172.979
945.275	243.345
951.107	307.733
956.936	330.412
962.759	278.227
968.577	305.049
974.391	379.561
980.201	512.801
986.006	679.656
991.806	663.025
997.602	544.23
1003.39	445.19
1009.18	438.309
1014.96	506.692
1020.74	622.982
1026.51	603.635
1032.28	371.49
1038.04	226.831
1043.8	165.291
1049.56	128.495
1055.31	134.958
1061.05	116.936
1066.8	116.06
1072.53	120.955
1078.26	171.349
1083.99	210.922
1089.72	240.837
1095.44	380.156
1101.15	364.466
1106.86	200.264
1112.56	117.385
1118.27	97.9931
1123.96	84.1165
1129.65	106.298
1135.34	115.895
1141.03	201.124
1146.7	267.745
1152.38	445.682
1158.05	285.393
1163.71	125.732
1169.37	80.3336
1175.03	56.6308
1180.68	44.768
1186.33	25.3196
1191.98	23.6325
1197.61	27.0211
1203.25	13.0075
1208.88	4.93735
1214.51	2.78723
1220.13	-4.25477
1225.74	7.61993
1231.36	11.5469
1236.97	6.34558
1242.57	2.97752
1248.17	7.51997
1253.77	4.88019
1259.36	15.2168
1264.94	15.3399
1270.53	4.38396
1276.11	75.7817
1281.68	56.6222
1287.25	9.61916
1292.81	3.82116
1298.38	-2.85076
1303.93	-2.43195
1309.48	10.1729
1315.03	2.93517
1320.58	-2.29413
1326.12	2.61803
1331.65	-9.6776
1337.18	-9.89535
1342.71	-6.1051
1348.23	-1.36048
1353.75	9.52413
1359.26	2.89339
1364.77	0.274544
1370.28	-2.42082
1375.78	21.5823
1381.28	192.383
1386.77	32.571
1392.26	4.2431
1397.74	3.78902
1403.23	13.6511
1408.7	0.918106
1414.17	8.82414
1419.64	4.38407
1425.11	0.988159
1430.56	-5.53555
1436.02	-2.71806
1441.47	2.18507
1446.92	-10.6846
1452.36	4.6113
1457.8	-7.44628
1463.23	-2.77927
1468.66	-9.70258
1474.09	-2.97082
1479.51	-4.58225
1484.93	4.33688
1490.34	3.86461
1495.75	-2.86305
1501.16	4.1384
1506.56	0.62793
1511.96	-13.4597
1517.35	-3.12531
1522.74	0.890717
1528.13	0.658737
1533.51	-1.69655
1538.88	0.164406
1544.25	-3.45789
1549.62	1.38107
1554.99	3.90498
1560.35	-3.34187
1565.71	-2.99796
1571.06	-1.58794
1576.41	0.914619
1581.75	3.50716
1587.09	3.97495
1592.43	6.6354
1597.76	-2.50854
1603.09	9.96891
1608.41	-2.34281
1613.73	2.74156
1619.05	11.1933
1624.36	5.47877
1629.67	1.90266
1634.97	12.5785
1640.27	-1.16986
1645.57	14.8807
1650.86	11.0023
1656.15	4.85289
1661.43	8.61852
1666.71	0.162888
1671.99	4.99683
1677.26	2.04531
1682.53	9.04975
1687.79	6.01428
1693.05	15.1951
1698.31	4.54967
1703.56	7.54295
1708.81	15.0692
1714.06	0.76989
1719.3	13.7025
1724.53	14.2266
1729.77	3.58861
1735	21.0072
1740.22	15.9433
1745.44	15.3686
1750.66	19.259
1755.87	8.40504
1761.08	12.1812
1766.29	11.4214
1771.49	-0.655487
1776.69	11.0843
1781.88	11.5486
1787.07	1.80248
1792.26	5.74221
1797.44	15.4205
1802.62	12.5776
1807.79	-0.636726
1812.96	21.7334
1818.13	11.8854
1823.29	4.29874
1828.45	15.2333
1833.61	9.95705
1838.76	10.4709
1843.91	8.59624
1849.05	11.3674
1854.19	5.91616
1859.33	13.3722
1864.46	15.0079
1869.59	15.4816
1874.71	4.09935
1879.83	6.82906
1884.95	11.9088
1890.06	7.4913
1895.17	18.3853
1900.28	8.03812
1905.38	13.185
1910.48	1.7728
1915.57	10.6349
1920.66	11.023
1925.75	12.6264
1930.83	7.05063
1935.91	7.43803
1940.99	11.4007
1946.06	4.5082
1951.13	13.2288
1956.19	3.847
1961.26	14.9304
1966.31	4.30047
1971.36	10.4971
1976.41	16.6746
1981.46	1.18171
1986.5	4.95322
1991.54	13.5406
1996.58	4.1051
2001.61	7.91623
2006.63	15.3672
2011.66	9.61464
2016.68	7.47004
2021.69	16.1471
2026.71	1.96667
2031.72	11.9505
2036.72	7.46635
2041.72	1.75372
2046.72	14.2658
2051.71	12.2126
2056.71	12.54
2061.69	5.5795
2066.68	12.0763
2071.66	9.98292
2076.63	11.5691
2081.6	13.1428
2086.57	14.6871
2091.54	5.09397
2096.5	4.19885
2101.46	13.2562
2106.41	18.6399
2111.36	7.82949
2116.31	13.269
2121.25	7.42192
2126.19	11.6138
2131.13	12.0152
2136.06	11.1239
2140.99	1.3148
2145.92	2.90579
2150.84	13.3891
2155.76	17.4868
2160.67	10.0629
2165.58	11.5426
2170.49	1.49992
2175.39	14.5151
2180.29	19.8269
2185.19	0.773598
2190.08	11.1856
2194.98	13.9507
2199.86	7.79079
2204.74	17.0613
2209.62	4.52164
2214.5	7.4254
2219.37	1.31628
2224.24	12.028
2229.11	11.0976
2233.97	19.2795
2238.83	10.5221
2243.68	9.57438
2248.53	9.93717
2253.38	6.34447
2258.22	6.6968
2263.06	8.36388
2267.9	11.3249
2272.73	-0.338036
2277.56	7.87442
2282.39	4.1006
2287.21	9.59727
2292.03	0.45916
2296.85	15.2768
2301.66	15.4999
2306.47	11.7689
2311.28	13.4147
2316.08	9.73714
2320.88	2.03347
2325.68	3.71664
2330.47	8.11909
2335.26	-0.974457
2340.04	-0.609825
2344.82	2.50032
2349.6	5.64661
2354.38	15.6536
2359.15	3.64365
2363.92	12.208
2368.68	7.00506
2373.44	5.92359
2378.2	3.44542
2382.95	9.25507
2387.71	2.52026
2392.45	11.0555
2397.2	14.0008
2401.94	3.01746
2406.68	-3.8056
2411.41	4.76539
2416.14	10.7302
2420.87	8.44676
2425.59	4.48195
2430.31	4.80376
2435.03	5.14883
2439.75	-2.99814
2444.46	8.71128
2449.16	6.22561
2453.87	5.14969
2458.57	8.36839
2463.27	-2.78943
2467.96	9.06937
2472.65	12.2931
2477.34	9.73486
2482.02	12.9726
2486.7	5.99487
2491.38	9.19935
2496.05	16.8106
2500.72	5.37392
2505.39	5.63469
2510.06	5.87916
2514.72	10.5254
2519.37	1.90996
2524.03	12.4942
2528.68	-0.578571
2533.33	8.55064
2537.97	4.36307
2542.61	3.14153
2547.25	1.92307
2551.88	12.6555
2556.51	2.44728
2561.14	5.7018
2565.77	2.97663
2570.39	7.79084
2575.01	6.5798
2579.62	5.33823
2584.23	5.56726
2588.84	14.8839
2593.45	5.93563
2598.05	6.15638
2602.65	9.41349
2607.24	6.55511
2611.84	6.72754
2616.42	3.83214
2621.01	2.46825
2625.59	1.10828
2630.17	7.44258
2634.75	6.15995
2639.32	-1.25082
2643.89	12.9649
2648.46	10.1918
2653.02	2.71827
2657.58	10.7383
2662.14	15.6357
2666.69	-2.96227
2671.24	9.77291
2675.79	8.48603
2680.33	4.16444
2684.88	6.12276
2689.41	3.30873
2693.95	10.0262
2698.48	10.2157
2703.01	12.0495
2707.53	7.43206
2712.06	4.396
2716.57	7.84068
2721.09	8.03776
2725.6	9.83179
2730.11	11.6049
2734.62	10.104
2739.12	5.3344
2743.62	2.21732
2748.12	12.1508
2752.61	14.0378
2757.1	1.14915
2761.59	11.1353
2766.08	9.67451
2770.56	11.4982
2775.04	6.7494
2779.51	10.2821
2783.98	0.592564
2788.45	9.16315
2792.92	9.41555
2797.38	4.61386
2801.84	8.16825
2806.3	4.97502
2810.75	3.44029
2815.2	5.26003
2819.65	13.8485
2824.09	5.51731
2828.53	3.94976
2832.97	12.5706
2837.41	7.58157
2841.84	7.69699
2846.27	4.40874
2850.69	13.102
2855.12	11.5707
2859.54	1.43463
2863.95	6.78825
2868.37	7.00037
2872.78	1.99825
2877.18	5.67356
2881.59	7.63773
2885.99	9.6287
2890.39	6.34068
2894.78	6.55101
2899.18	-2.07006
2903.57	26.5608
2907.95	7.19261
2912.34	12.7171
2916.72	0.321213
2921.09	4.04832
2925.47	9.60434
2929.84	6.1764
2934.21	9.96404
2938.57	10.0965
2942.94	-0.702778
2947.29	4.83215
2951.65	14.0281
2956	1.32756
2960.36	3.2224
2964.7	12.4586
2969.05	7.05775
2973.39	10.8353
2977.73	12.7849
2982.06	1.82774
2986.4	3.79934
2990.73	9.50579
2995.05	7.80929
2999.38	6.11796
3003.7	-3.06082
3008.01	10.2485
3012.33	14.1991
3016.64	10.6375
3020.95	14.6544
3025.26	16.7623
3029.56	9.2939
3033.86	3.67843
3038.16	13.3418
3042.45	17.3129
3046.74	7.79588
3051.03	11.7351
3055.32	17.6236
3059.6	25.4708
3063.88	13.9599
3068.16	23.7661
3072.43	21.9363
3076.7	25.9535
3080.97	24.1305
3085.24	22.3165
3089.5	20.5294
3093.76	32.5372
3098.02	42.6753
3102.27	41.0032
3106.52	31.4046
3110.77	35.7149
3115.01	46.0715
3119.26	40.4266
3123.5	44.8607
3127.73	39.2151
3131.97	49.8571
3136.2	44.2158
3140.43	40.5507
3144.65	71.9408
3148.87	62.0644
3153.09	58.2802
3157.31	77.3992
3161.52	71.5071
3165.73	69.7674
3169.94	74.291
3174.15	76.7644
3178.35	81.2405
3182.55	83.5605
3186.75	87.9781
3190.94	77.5229
3195.13	88.3879
3199.32	88.7697
3203.51	91.4424
3207.69	85.5813
3211.87	77.5375
3216.05	67.3007
3220.22	87.3942
3224.39	70.5159
3228.56	68.8527
3232.73	71.5616
3236.89	63.1916
3241.05	50.3817
3245.21	57.557
3249.36	46.8346
3253.52	38.1877
3257.66	42.9246
3261.81	43.2874
3265.95	23.3431
3270.1	32.8346
3274.23	35.5263
3278.37	26.5971
3282.5	26.807
3286.63	27.0194
3290.76	20.3235
3294.88	20.5074
3299	29.9311
3303.12	23.2219
3307.24	23.4349
3311.35	18.9917
3315.46	28.4942
3319.57	19.3928
3323.68	33.6547
3327.78	22.2384
3331.88	22.5488
3335.98	32.3363
3340.07	23.2173
3344.16	16.3521
3348.25	14.1786
3352.34	31.0443
3356.42	19.3783
3360.5	14.8505
3364.58	27.0691
3368.66	24.931
3372.73	8.3509
3376.8	13.3635
3380.87	11.1429
3384.93	13.7413
3388.99	26.0128
3393.05	6.8336
3397.11	9.44772
3401.16	14.4982
3405.21	17.0993
3409.26	7.55075
3413.31	7.70792
3417.35	15.1788
3421.39	5.59462
3425.43	13.0711
3429.46	20.5864
3433.5	8.57902
3437.53	6.35211
3441.55	6.5843
3445.58	11.7571
3449.6	14.5153
3453.62	14.8244
3457.64	10.2147
3461.65	0.615189
3465.66	0.937973
3469.67	8.77456
3473.68	4.05342
3477.68	-0.675491
3481.68	7.20142
3485.68	7.51241
3489.67	10.3595
3493.67	5.56995
3497.66	8.3989
3501.64	6.10432
3505.63	1.21691
3509.61	9.11953
3513.59	14.442
3517.57	1.77793
3521.54	9.66912
3525.52	7.28493
3529.49	7.46662
3533.45	12.8526
3537.42	5.38246
3541.38	8.24773
3545.34	11.0946
3549.29	8.73638
3553.25	3.71543
3557.2	6.51352
3561.15	6.73136
3565.09	6.96731
3569.04	20.313
3572.98	4.87953
3576.92	7.77996
3580.85	15.9837
3584.79	18.9642
3588.72	21.9571
3592.64	9.02143
3596.57	9.33095
3600.49	12.2957
3604.41	9.91048
3608.33	2.12645
3612.25	2.36552
3616.16	2.60376
3620.07	5.53006
3623.98	0.308487
3627.88	5.88092
3631.79	6.03324
3635.69	3.48565
3639.58	6.38108
3643.48	12.0358
3647.37	9.5704
3651.26	7.00547
3655.15	1.7296
3659.03	-0.836746
3662.92	4.77328
3666.8	4.93592
3670.67	-0.371544
3674.55	-0.206905
3678.42	-0.0205193
3682.29	0.183403
3686.16	14.1913
3690.02	11.6931
3693.89	-1.9149
3697.75	9.40771
3701.61	9.64697
3705.46	4.28886
3709.31	10.1163
3713.16	10.3491
3717.01	4.92538
3720.86	10.7495
3724.7	-0.380489
3728.54	11.0953
3732.38	8.43113
3736.21	2.91345
3740.04	14.4522
3743.87	6.0513
3747.7	3.32649
3751.53	9.15769
3755.35	9.25756
3759.17	9.34045
3762.99	6.54789
3766.81	9.48152
3770.62	3.82601
3774.43	6.77914
3778.24	9.73862
3782.04	21.3549
3785.85	4.19508
3789.65	-1.48167
3793.45	7.28163
3797.24	21.8872
3801.04	4.63059
3804.83	10.5748
3808.62	4.88931
3812.4	7.93147
3816.19	5.12317
3819.97	8.16619
3823.75	8.27102
3827.52	2.47799
3831.3	5.52194
3835.07	8.57815
3838.84	8.67448
3842.61	11.7534
3846.37	14.7974
3850.13	2.96464
3853.89	11.9141
3857.65	8.97158
3861.41	8.98987
3865.16	6.08005
3868.91	0.248936
3872.66	9.27203
3876.4	9.32324
3880.14	3.39656
3883.89	9.43953
3887.62	3.52495
3891.36	9.60318
3895.09	6.7264
3898.82	15.8662
3902.55	6.96124
3906.28	1.04499
3910	10.223
3913.73	-1.7353
3917.45	13.5731
3921.16	4.65736
3924.88	1.80136
3928.59	1.98311
3932.3	5.22198
3936.01	-3.79632
3939.71	5.58249
3943.42	2.72809
3947.12	6.02818
3950.81	9.33862
3954.51	9.5659
3958.2	6.70269
3961.9	10.0202
3965.58	4.05504
3969.27	10.4781
3972.96	13.8222
3976.64	14.0843
3980.32	5.04561
3984	8.42053
3987.67	11.8158
3991.34	5.93804
3995.01	6.29992
3998.68	9.80653