File: Data/3-Raman/processed/bu04w-a-ff3-fi05-l_150 (500nm)_633nm_edge_100%_x100_vis_lwd_h50um_45sx2_01.txt
#Acq. time (s)=	45
#Accumulations=	2
#Range (cm-¹)=	100...4000
#Windows=	1
#Auto scanning=	Off
#Autofocus=	Off
#Macrospot=	Off
#AutoExposure=	Off
#Spike filter=	Multiple accum.
#Delay time (s)=	2
#Binning=	1
#Readout mode=	Signal
#DeNoise=	Off
#ICS correction=	On
#Dark correction=	Off
#Inst. Process=	Off
#Detector Gain=	Best Dynamic
#Detector ADC=	50 kHz EM
#Detector EM gain=	100
#Detector temperature (°C)=	-60.09
#Instrument=	LabRAM HR Evol
#Detector=	SIN-EM FIVIS
#Objective=	x100_VIS_LWD
#Grating=	150 (500nm)
#ND Filter=	100%
#Laser=	633nm_Edge
#Hole=	49.98
#Temperature=	0
#Range=	Visible
#StageXY=	75x50mm Scan+
#StageZ=	Z motor
#X (µm)=	0
#Y (µm)=	0
#Z (µm)=	16.6
#Full time(mm:ss)=	1:34
#Project=	21_11_22
#Sample=	BU04w
#Site=
#Title=	BU04w-A-FF3-FI05-L_150 (500nm)_633nm_Edge_100%_x100_VIS_LWD_H50um_45sX2
#Remark=
#Date=	22.11.2021 11:45
#Acquired=	22.11.2021 11:45:51
#Base:Fit=	16.12.2021 16:15:35
#Base:Edit=	16.12.2021 16:23:09
#Base:Edit=	16.12.2021 16:23:10
#Base:Edit=	16.12.2021 16:23:12
#Base:Edit=	16.12.2021 16:23:14
#Base:Sub=	16.12.2021 16:23:17
100.177	1064.14
106.695	927.909
113.209	798.574
119.717	802.446
126.219	729.661
132.716	720.601
139.208	731.852
145.694	697.121
152.175	625.954
158.651	797.29
165.121	1064.54
171.586	708.956
178.045	282.218
184.5	137.384
190.947	161.126
197.39	102.285
203.829	71.8824
210.262	2.92725
216.688	40.3569
223.11	131.468
229.527	395.316
235.939	969.164
242.344	707.485
248.745	236.697
255.141	189.545
261.53	183.811
267.916	119.74
274.294	110.267
280.669	178.817
287.038	188.463
293.402	103.241
299.76	23.0811
306.114	66.0587
312.461	190.45
318.805	648.064
325.142	1705.2
331.475	1845.3
337.802	914.112
344.123	392.649
350.441	188.992
356.752	158.642
363.058	315.479
369.36	291.607
375.656	159.868
381.947	62.2952
388.232	-18.3095
394.512	66.2012
400.789	92.6327
407.059	121.956
413.324	193.7
419.584	292.639
425.839	576.864
432.089	938.55
438.333	921.555
444.573	559.697
450.807	486.809
457.037	566.045
463.261	417.606
469.48	196.915
475.695	115.894
481.904	145.124
488.108	177.011
494.307	154.016
500.502	233.484
506.691	396.244
512.874	534.128
519.053	542.771
525.227	412.749
531.396	370.927
537.559	328.323
543.718	288.49
549.873	203.065
556.022	155.07
562.165	173.62
568.304	82.9472
574.437	90.5673
580.567	54.6966
586.691	62.4186
592.81	144.36
598.924	279.91
605.033	293.061
611.138	226.283
617.236	236.622
623.332	197.486
629.42	178.569
635.506	158.93
641.585	161.562
647.659	121.044
653.73	200.584
659.794	260.497
665.854	239.769
671.91	105.012
677.96	59.4506
684.005	6.38782
690.045	19.1664
696.082	17.3591
702.113	34.1506
708.139	1.80353
714.16	9.69739
720.176	-7.19696
726.187	9.56732
732.194	14.463
738.196	-8.80222
744.193	21.2493
750.185	-4.57602
756.173	-15.1432
762.155	9.62976
768.133	8.9646
774.107	-8.56375
780.075	9.20398
786.039	31.2321
791.998	3.00934
797.952	8.27109
803.902	24.3147
809.845	25.9079
815.786	20.4897
821.721	50.4505
827.652	53.9247
833.576	48.7719
839.498	51.9601
845.415	76.3402
851.327	58.6618
857.233	79.6187
863.135	91.3225
869.032	102.082
874.925	139.785
880.813	117.221
886.697	157.799
892.576	162.797
898.45	145.485
904.318	146.356
910.184	152.692
916.044	183.429
921.9	200.783
927.75	261.198
933.596	351.701
939.439	496.78
945.275	682.213
951.107	949.307
956.936	1044.07
962.759	856.897
968.577	726.26
974.391	759.237
980.201	1044.58
986.006	1406.47
991.806	1579.14
997.602	1290.79
1003.39	1098.52
1009.18	985.032
1014.96	1042.44
1020.74	1424.68
1026.51	1623.57
1032.28	1208.21
1038.04	704.639
1043.8	554.232
1049.56	428.828
1055.31	347.656
1061.05	330.619
1066.8	282.456
1072.53	296.262
1078.26	385.413
1083.99	472.247
1089.72	617.272
1095.44	905.481
1101.15	1296.72
1106.86	807.94
1112.56	502.174
1118.27	330.68
1123.96	250.968
1129.65	297.765
1135.34	374.24
1141.03	489.349
1146.7	715.237
1152.38	1337.16
1158.05	1408.12
1163.71	635.835
1169.37	294.491
1175.03	227.553
1180.68	181.43
1186.33	113.604
1191.98	129.388
1197.61	96.9363
1203.25	70.0105
1208.88	75.8043
1214.51	74.892
1220.13	43.5119
1225.74	66.7881
1231.36	57.0376
1236.97	50.8311
1242.57	60.1642
1248.17	45.7092
1253.77	40.8899
1259.36	56.7148
1264.94	62.025
1270.53	46.1336
1276.11	46.0714
1281.68	42.9249
1287.25	56.0428
1292.81	32.4116
1298.38	39.1832
1303.93	32.2887
1309.48	14.9694
1315.03	33.3288
1320.58	34.8009
1326.12	24.362
1331.65	2.74258
1337.18	33.7257
1342.71	25.7153
1348.23	11.161
1353.75	24.118
1359.26	31.6838
1364.77	36.858
1370.28	48.915
1375.78	113.294
1381.28	104.693
1386.77	26.281
1392.26	44.4911
1397.74	33.5602
1403.23	6.25775
1408.7	34.6361
1414.17	17.8472
1419.64	-21.6496
1425.11	10.3271
1430.56	-2.21375
1436.02	31.022
1441.47	24.6358
1446.92	7.7963
1452.36	-2.23712
1457.8	14.6844
1463.23	10.3338
1468.66	-5.73703
1474.09	4.46399
1479.51	1.23538
1484.93	15.9716
1490.34	24.649
1495.75	7.28381
1501.16	5.83267
1506.56	10.8664
1511.96	-6.14877
1517.35	7.75809
1522.74	5.83942
1528.13	-3.5376
1533.51	33.3874
1538.88	23.8405
1544.25	17.1239
1549.62	2.02161
1554.99	36.0257
1560.35	26.5648
1565.71	22.6317
1571.06	30.5121
1576.41	16.9355
1581.75	18.8465
1587.09	-2.80344
1592.43	28.4836
1597.76	22.3272
1603.09	22.825
1608.41	36.6249
1613.73	35.7053
1619.05	32.9038
1624.36	30.1017
1629.67	14.0512
1634.97	71.5307
1640.27	26.8857
1645.57	66.0829
1650.86	36.5647
1656.15	14.5563
1661.43	58.8103
1666.71	66.3913
1671.99	38.4093
1677.26	21.4239
1682.53	38.7189
1687.79	8.08725
1693.05	26.3742
1698.31	45.1328
1703.56	20.1161
1708.81	29.7256
1714.06	26.4515
1719.3	29.7437
1724.53	26.8183
1729.77	15.1789
1735	20.3321
1740.22	6.29083
1745.44	17.0212
1750.66	0.440491
1755.87	19.8706
1761.08	26.5605
1766.29	12.8445
1771.49	13.936
1776.69	21.937
1781.88	-14.0576
1787.07	23.924
1792.26	5.28442
1797.44	16.3265
1802.62	13.8573
1807.79	17.0806
1812.96	12.0053
1818.13	12.6999
1823.29	13.3771
1828.45	44.2542
1833.61	13.7429
1838.76	12.1847
1843.91	10.3668
1849.05	3.77151
1854.19	-8.85593
1859.33	-1.43784
1864.46	12.0185
1869.59	17.3479
1874.71	20.0234
1879.83	-28.1343
1884.95	16.8578
1890.06	25.0529
1895.17	28.2452
1900.28	36.3967
1905.38	1.35434
1910.48	26.9905
1915.57	19.8909
1920.66	1.19138
1925.75	26.7793
1930.83	10.5645
1935.91	25.4206
1940.99	26.941
1946.06	17.4667
1951.13	24.6747
1956.19	2.78168
1961.26	30.202
1966.31	12.9339
1971.36	13.5012
1976.41	24.8437
1981.46	7.28595
1986.5	11.423
1991.54	15.6193
1996.58	-2.95102
2001.61	-8.16779
2006.63	16.8462
2011.66	7.13376
2016.68	21.5236
2021.69	11.7059
2026.71	38.3564
2031.72	10.907
2036.72	16.2152
2041.72	-3.91019
2046.72	5.13214
2051.71	37.3938
2056.71	20.665
2061.69	12.7247
2066.68	13.3515
2071.66	47.0663
2076.63	35.3443
2081.6	28.4091
2086.57	22.4958
2091.54	48.7011
2096.5	18.3233
2101.46	52.5316
2106.41	24.7345
2111.36	11.9015
2116.31	24.1876
2121.25	28.9899
2126.19	26.1785
2131.13	30.8238
2136.06	8.72
2140.99	39.757
2145.92	31.3664
2150.84	37.9922
2155.76	39.3414
2160.67	22.6302
2165.58	23.5822
2170.49	15.4943
2175.39	8.90393
2180.29	2.09476
2185.19	50.0833
2190.08	20.1252
2194.98	27.4834
2199.86	27.4403
2204.74	30.1934
2209.62	35.7236
2214.5	19.496
2219.37	11.1024
2224.24	32.4989
2229.11	13.7136
2233.97	22.1826
2238.83	7.17358
2243.68	18.2675
2248.53	33.3777
2253.38	3.76382
2258.22	36.0461
2263.06	31.3979
2267.9	21.1702
2272.73	35.9005
2277.56	18.5899
2282.39	15.6453
2287.21	17.7536
2292.03	15.8605
2296.85	4.66306
2301.66	28.3395
2306.47	11.0121
2311.28	23.3073
2316.08	30.4795
2320.88	21.716
2325.68	14.2672
2330.47	48.7114
2335.26	38.8278
2340.04	60.1753
2344.82	81.8141
2349.6	31.2185
2354.38	33.6277
2359.15	32.9539
2363.92	37.353
2368.68	32.2334
2373.44	9.00403
2378.2	31.4484
2382.95	17.5069
2387.71	4.64893
2392.45	17.9917
2397.2	26.9699
2401.94	9.43091
2406.68	-8.23907
2411.41	29.0378
2416.14	28.5473
2420.87	12.1519
2425.59	23.2938
2430.31	-4.41791
2435.03	7.47894
2439.75	12.477
2444.46	4.64996
2449.16	9.6333
2453.87	61.8263
2458.57	26.7643
2463.27	36.0972
2467.96	19.4165
2472.65	18.442
2477.34	18.9509
2482.02	25.2266
2486.7	12.3849
2491.38	5.24438
2496.05	43.473
2500.72	21.6309
2505.39	21.6476
2510.06	5.34467
2514.72	34.5228
2519.37	34.3074
2524.03	10.5936
2528.68	17.8069
2533.33	17.71
2537.97	4.3963
2542.61	17.8796
2547.25	16.5891
2551.88	36.2133
2556.51	-4.11346
2561.14	22.9151
2565.77	33.7287
2570.39	7.01678
2575.01	10.4073
2579.62	15.1348
2584.23	24.0769
2588.84	28.2166
2593.45	39.7256
2598.05	22.7859
2602.65	27.0303
2607.24	40.3302
2611.84	6.09778
2616.42	6.92706
2621.01	17.0024
2625.59	7.24506
2630.17	28.3953
2634.75	13.1809
2639.32	32.3097
2643.89	28.3774
2648.46	2.72235
2653.02	26.6932
2657.58	37.5691
2662.14	18.5793
2666.69	32.1641
2671.24	-4.04089
2675.79	2.66003
2680.33	28.0117
2684.88	16.8447
2689.41	13.5164
2693.95	22.5195
2698.48	14.1974
2703.01	-5.05566
2707.53	43.0603
2712.06	21.9003
2716.57	33.2838
2721.09	4.03021
2725.6	24.7289
2730.11	29.0268
2734.62	5.47302
2739.12	20.7802
2743.62	33.2101
2748.12	23.0604
2752.61	-1.06213
2757.1	21.8871
2761.59	34.579
2766.08	21.282
2770.56	30.9744
2775.04	22.7816
2779.51	21.485
2783.98	35.5519
2788.45	34.697
2792.92	30.3594
2797.38	-11.1203
2801.84	24.2974
2806.3	4.05011
2810.75	5.5152
2815.2	15.2424
2819.65	30.0184
2824.09	29.6727
2828.53	17.4382
2832.97	11.8647
2837.41	19.8295
2841.84	19.3243
2846.27	30.9283
2850.69	35.8687
2855.12	27.4457
2859.54	8.7135
2863.95	24.6144
2868.37	23.5171
2872.78	6.7276
2877.18	0.330444
2881.59	13.2581
2885.99	5.39325
2890.39	11.4266
2894.78	-19.6553
2899.18	25.5356
2903.57	33.4325
2907.95	14.3874
2912.34	32.4818
2916.72	7.39545
2921.09	7.5257
2925.47	14.9771
2929.84	0.984314
2934.21	19.4255
2938.57	17.5579
2942.94	15.4864
2947.29	25.9055
2951.65	12.619
2956	35.8035
2960.36	15.1407
2964.7	40.3191
2969.05	49.2271
2973.39	32.4908
2977.73	15.7045
2982.06	32.1571
2986.4	28.6484
2990.73	53.1327
2995.05	22.0358
2999.38	28.2621
3003.7	36.5646
3008.01	33.7209
3012.33	66.4381
3016.64	20.2395
3020.95	72.5466
3025.26	73.4627
3029.56	72.0358
3033.86	45.4572
3038.16	60.5337
3042.45	62.5883
3046.74	70.0978
3051.03	79.5018
3055.32	69.681
3059.6	63.7288
3063.88	106.169
3068.16	84.6973
3072.43	115.659
3076.7	107.849
3080.97	111.74
3085.24	141.245
3089.5	149.698
3093.76	146.806
3098.02	157.99
3102.27	143.537
3106.52	176.984
3110.77	176.949
3115.01	184.972
3119.26	181.021
3123.5	211.644
3127.73	200.161
3131.97	219.489
3136.2	206.223
3140.43	256.362
3144.65	215.652
3148.87	271.839
3153.09	304.865
3157.31	356.579
3161.52	335.307
3165.73	294.913
3169.94	380.249
3174.15	417.805
3178.35	388.902
3182.55	374.283
3186.75	446.327
3190.94	501.365
3195.13	429.745
3199.32	463.347
3203.51	487.707
3207.69	420.205
3211.87	477.435
3216.05	444.543
3220.22	448.028
3224.39	436.156
3228.56	459.302
3232.73	363.613
3236.89	403.663
3241.05	429.044
3245.21	288.143
3249.36	368.963
3253.52	319.233
3257.66	360.747
3261.81	322.564
3265.95	300.581
3270.1	295.003
3274.23	252.44
3278.37	296.552
3282.5	283.62
3286.63	238.493
3290.76	252.92
3294.88	283.378
3299	265.471
3303.12	210.803
3307.24	239.29
3311.35	263.075
3315.46	231.085
3319.57	236.409
3323.68	225.841
3327.78	241.251
3331.88	198.527
3335.98	198.482
3340.07	252.333
3344.16	260.481
3348.25	256.3
3352.34	280.808
3356.42	193.515
3360.5	259.027
3364.58	226.656
3368.66	232.406
3372.73	271.781
3376.8	190.413
3380.87	238.857
3384.93	289.741
3388.99	239.079
3393.05	212.363
3397.11	217.477
3401.16	271.162
3405.21	212.688
3409.26	190.65
3413.31	255.954
3417.35	280.034
3421.39	245.574
3425.43	269.574
3429.46	262.277
3433.5	174.558
3437.53	246.07
3441.55	217.465
3445.58	203.881
3449.6	230.085
3453.62	224.418
3457.64	244.113
3461.65	229.408
3465.66	199.671
3469.67	189.681
3473.68	236.664
3477.68	203.66
3481.68	241.162
3485.68	162.146
3489.67	194.407
3493.67	173.226
3497.66	161.784
3501.64	216.576
3505.63	204.531
3509.61	155.912
3513.59	163.287
3517.57	170.615
3521.54	183.07
3525.52	159.646
3529.49	118.071
3533.45	146.833
3537.42	153.151
3541.38	92.3636
3545.34	160.564
3549.29	109.184
3553.25	134.716
3557.2	113.861
3561.15	95.9106
3565.09	83.4471
3569.04	100.321
3572.98	140.645
3576.92	113.239
3580.85	141.402
3584.79	119.765
3588.72	105.901
3592.64	86.6016
3596.57	91.1716
3600.49	92.8287
3604.41	75.6439
3608.33	58.1025
3612.25	123.665
3616.16	62.8292
3620.07	44.7592
3623.98	69.066
3627.88	68.8149
3631.79	73.7316
3635.69	38.2094
3639.58	73.6317
3643.48	50.1264
3647.37	40.4862
3651.26	37.4916
3655.15	7.60675
3659.03	23.9296
3662.92	18.3014
3666.8	48.3799
3670.67	48.4829
3674.55	26.8698
3678.42	24.8879
3682.29	23.3004
3686.16	19.3973
3690.02	21.1193
3693.89	22.7841
3697.75	29.8677
3701.61	0.88385
3705.46	27.5065
3709.31	6.83997
3713.16	33.7448
3717.01	23.7959
3720.86	33.3248
3724.7	34.2141
3728.54	20.8071
3732.38	13.1605
3736.21	39.6377
3740.04	3.43787
3743.87	15.4508
3747.7	27.3531
3751.53	21.8609
3755.35	30.3901
3759.17	21.4907
3762.99	23.9116
3766.81	32.0269
3770.62	23.2337
3774.43	11.6754
3778.24	34.6477
3782.04	14.837
3785.85	24.0449
3789.65	15.7709
3793.45	24.9194
3797.24	51.8776
3801.04	12.2996
3804.83	10.4911
3808.62	32.1199
3812.4	21.5013
3816.19	28.2825
3819.97	2.77161
3823.75	35.7516
3827.52	21.5399
3831.3	-4.25623
3835.07	43.7272
3838.84	20.6517
3842.61	21.5352
3846.37	15.7025
3850.13	24.1746
3853.89	8.76294
3857.65	13.9655
3861.41	33.814
3865.16	-7.94501
3868.91	23.0804
3872.66	14.074
3876.4	31.4915
3880.14	1.07983
3883.89	27.5876
3887.62	15.381
3891.36	6.29669
3895.09	9.83539
3898.82	34.2104
3902.55	13.4816
3906.28	13.6729
3910	10.7734
3913.73	2.12561
3917.45	14.8929
3921.16	6.81982
3924.88	26.1425
3928.59	-3.54547
3932.3	45.9465
3936.01	12.4307
3939.71	31.0429
3943.42	13.3049
3947.12	4.59729
3950.81	1.77423
3954.51	11.0184
3958.2	4.62616
3961.9	19.4951
3965.58	28.0606
3969.27	20.7316
3972.96	10.3266
3976.64	27.8323
3980.32	4.7688
3984	-6.10608
3987.67	7.8584
3991.34	15.8355
3995.01	14.8757
3998.68	1.8645