File: Data/3-Raman/processed/bu04w-a-ff3-fi01-v_150 (500nm)_633nm_edge_100%_x100_vis_lwd_h100um_0_5sx60_01.txt
#Acq. time (s)=	0.5
#Accumulations=	60
#Range (cm-¹)=	100...4000
#Windows=	1
#Auto scanning=	Off
#Autofocus=	Off
#Macrospot=	Off
#AutoExposure=	Off
#Spike filter=	Multiple accum.
#Delay time (s)=	2
#Binning=	1
#Readout mode=	Signal
#DeNoise=	Off
#ICS correction=	On
#Dark correction=	Off
#Inst. Process=	Off
#Detector Gain=	Best Dynamic
#Detector ADC=	50 kHz HS
#Detector temperature (°C)=	-60.09
#Instrument=	LabRAM HR Evol
#Detector=	SIN-EM FIVIS
#Objective=	x100_VIS_LWD
#Grating=	150 (500nm)
#ND Filter=	100%
#Laser=	633nm_Edge
#Hole=	100.021
#Temperature=	0
#Range=	Visible
#StageXY=	75x50mm Scan+
#StageZ=	Z motor
#X (µm)=	0
#Y (µm)=	0
#Z (µm)=	14.3
#Full time(s)=	43
#Project=	21_11_22
#Sample=	BU04w
#Site=
#Title=	BU04w-A-FF3-V_150 (500nm)_633nm_Edge_100%_x100_VIS_LWD_H100um_0_5sX60
#Remark=
#Date=	22.11.2021 10:36
#Acquired=	22.11.2021 10:36:57
#Base:Fit=	16.12.2021 16:15:35
#Base:Fit=	16.12.2021 16:21:14
#Base:Edit=	16.12.2021 16:21:16
#Base:Edit=	16.12.2021 16:21:18
#Base:Sub=	16.12.2021 16:21:21
100.177	4.62372
106.695	3.25994
113.209	2.91718
119.717	2.50296
126.219	1.42186
132.716	1.53738
139.208	1.32212
145.694	1.1106
152.175	1.26078
158.651	1.35558
165.121	1.56959
171.586	1.81509
178.045	-0.137449
184.5	-0.306852
190.947	-1.06289
197.39	-0.838194
203.829	-1.22012
210.262	-1.41552
216.688	-1.15016
223.11	-1.45999
229.527	-0.303091
235.939	1.33052
242.344	1.07354
248.745	0.113444
255.141	-0.745616
261.53	-0.400106
267.916	-1.00656
274.294	-0.923633
280.669	-1.08686
287.038	-0.166778
293.402	-0.670053
299.76	-0.824241
306.114	-1.24028
312.461	-0.265503
318.805	0.673344
325.142	3.69401
331.475	5.30478
337.802	3.95442
344.123	1.06728
350.441	0.252582
356.752	0.405426
363.058	-0.196278
369.36	0.809092
375.656	0.154906
381.947	0.216135
388.232	-0.124254
394.512	-0.35671
400.789	-0.275318
407.059	-0.00457954
413.324	0.438552
419.584	-0.0229206
425.839	1.48628
432.089	2.28468
438.333	2.86763
444.573	2.04357
450.807	1.66113
457.037	1.44272
463.261	1.25271
469.48	0.758389
475.695	0.51029
481.904	0.282679
488.108	0.368355
494.307	0.344755
500.502	0.55705
506.691	1.51568
512.874	1.79694
519.053	1.25986
525.227	1.38048
531.396	1.38169
537.559	0.878105
543.718	0.457772
549.873	0.757105
556.022	0.606424
562.165	0.113976
568.304	0.00927544
574.437	0.322631
580.567	0.262922
586.691	0.0221853
592.81	0.473427
598.924	0.44634
605.033	1.21685
611.138	0.982749
617.236	0.805548
623.332	0.600756
629.42	0.870604
635.506	1.00389
641.585	0.620443
647.659	0.145506
653.73	0.861877
659.794	0.630553
665.854	0.733576
671.91	0.73487
677.96	0.209006
684.005	-0.126431
690.045	-0.180713
696.082	0.0113649
702.113	-0.147562
708.139	-0.152835
714.16	0.298449
720.176	-0.212528
726.187	0.277282
732.194	-0.0558167
738.196	-0.16656
744.193	-0.148956
750.185	-0.0162706
756.173	0.31359
762.155	-0.585214
768.133	0.192824
774.107	-0.0406485
780.075	0.483117
786.039	-0.295119
791.998	-0.0102358
797.952	-0.0854502
803.902	-0.107473
809.845	-0.00735855
815.786	-0.170885
821.721	-0.291142
827.652	0.125608
833.576	-0.0446892
839.498	-0.0692444
845.415	-0.334852
851.327	-0.0265112
857.233	-0.111646
863.135	0.124812
869.032	0.522452
874.925	0.62148
880.813	0.516846
886.697	0.533216
892.576	0.171414
898.45	-0.0218496
904.318	0.316562
910.184	0.106859
916.044	0.440244
921.9	0.277935
927.75	0.607677
933.596	0.776481
939.439	0.678108
945.275	2.30333
951.107	2.96249
956.936	3.02125
962.759	2.90678
968.577	2.6345
974.391	2.54424
980.201	2.59492
986.006	4.14231
991.806	5.01503
997.602	4.92851
1003.39	3.81487
1009.18	3.36117
1014.96	3.78495
1020.74	4.53337
1026.51	5.13904
1032.28	4.56665
1038.04	2.8724
1043.8	1.92057
1049.56	1.20615
1055.31	1.3165
1061.05	1.18631
1066.8	0.727672
1072.53	0.875141
1078.26	1.11598
1083.99	1.33666
1089.72	2.13448
1095.44	2.42361
1101.15	3.53103
1106.86	2.48765
1112.56	2.00682
1118.27	1.14507
1123.96	1.07583
1129.65	0.823005
1135.34	0.885454
1141.03	1.4635
1146.7	1.44997
1152.38	3.48439
1158.05	3.7665
1163.71	2.81066
1169.37	1.28734
1175.03	0.0169487
1180.68	0.557658
1186.33	0.281008
1191.98	-0.0837603
1197.61	0.259443
1203.25	0.220963
1208.88	-0.0755243
1214.51	0.165274
1220.13	0.128968
1225.74	-0.0575972
1231.36	0.106921
1236.97	0.0423756
1242.57	0.358089
1248.17	-0.00600529
1253.77	0.235785
1259.36	0.704058
1264.94	0.222002
1270.53	0.354794
1276.11	0.854679
1281.68	1.91127
1287.25	0.0696135
1292.81	0.492825
1298.38	-0.142126
1303.93	0.230143
1309.48	-0.180044
1315.03	-0.169106
1320.58	-0.155078
1326.12	0.138563
1331.65	-0.200637
1337.18	-0.0991764
1342.71	0.584291
1348.23	-0.161679
1353.75	0.129774
1359.26	0.432486
1364.77	0.32654
1370.28	0.509253
1375.78	0.707993
1381.28	2.12405
1386.77	2.99882
1392.26	0.624811
1397.74	-0.134394
1403.23	0.100839
1408.7	0.0781622
1414.17	-0.0285025
1419.64	0.393544
1425.11	0.187357
1430.56	-0.142321
1436.02	-0.0149946
1441.47	0.0581217
1446.92	0.00865364
1452.36	-0.177154
1457.8	-0.246807
1463.23	0.22845
1468.66	0.307858
1474.09	-0.234707
1479.51	-0.487219
1484.93	-0.363363
1490.34	0.211657
1495.75	-0.240661
1501.16	-0.136501
1506.56	-0.279263
1511.96	-0.220177
1517.35	-0.0302353
1522.74	0.0186319
1528.13	-0.057869
1533.51	-0.131517
1538.88	0.0239868
1544.25	0.190012
1549.62	0.281889
1554.99	0.247871
1560.35	-0.303477
1565.71	-0.0282993
1571.06	0.0443811
1576.41	0.15553
1581.75	0.0759449
1587.09	-0.16476
1592.43	-0.145923
1597.76	-0.0295944
1603.09	0.256448
1608.41	0.0188732
1613.73	0.34214
1619.05	-0.00876331
1624.36	0.324631
1629.67	0.212635
1634.97	0.711099
1640.27	0.201063
1645.57	0.156409
1650.86	0.464523
1656.15	-0.0765648
1661.43	-0.0790987
1666.71	0.386085
1671.99	0.454943
1677.26	0.352359
1682.53	0.191212
1687.79	0.492864
1693.05	-0.195781
1698.31	0.290491
1703.56	-0.216757
1708.81	0.0908279
1714.06	-0.217587
1719.3	-0.136015
1724.53	-0.372603
1729.77	0.252178
1735	0.192832
1740.22	-0.746632
1745.44	0.127632
1750.66	-0.226696
1755.87	-0.278972
1761.08	-0.20448
1766.29	0.0230675
1771.49	-0.207932
1776.69	-0.475197
1781.88	0.28371
1787.07	0.0652552
1792.26	-0.0902481
1797.44	0.0841322
1802.62	-0.377058
1807.79	0.210072
1812.96	-0.162657
1818.13	0.128612
1823.29	0.0285778
1828.45	-0.0705366
1833.61	0.0675402
1838.76	0.126775
1843.91	0.160177
1849.05	0.587544
1854.19	0.000228882
1859.33	-0.0285053
1864.46	-0.29275
1869.59	0.0019474
1874.71	0.230062
1879.83	0.296515
1884.95	0.0205927
1890.06	-0.0208254
1895.17	0.131435
1900.28	0.409506
1905.38	-0.220363
1910.48	0.0189419
1915.57	-0.0923481
1920.66	0.140204
1925.75	0.0722466
1930.83	0.167348
1935.91	-0.39016
1940.99	0.391486
1946.06	0.0287647
1951.13	0.0696716
1956.19	-0.016531
1961.26	-0.431822
1966.31	0.00846195
1971.36	-0.353771
1976.41	-0.206902
1981.46	-0.12154
1986.5	0.10705
1991.54	-0.192851
1996.58	-0.266663
2001.61	-0.0724354
2006.63	0.391111
2011.66	0.00212669
2016.68	-0.366422
2021.69	-0.0846462
2026.71	-0.654418
2031.72	-0.278794
2036.72	-0.185365
2041.72	-0.831309
2046.72	-0.324224
2051.71	-0.082799
2056.71	0.380338
2061.69	-0.495215
2066.68	0.0388603
2071.66	-0.301581
2076.63	-0.0596561
2081.6	-0.00731659
2086.57	-0.0640306
2091.54	-0.163623
2096.5	0.374905
2101.46	0.202094
2106.41	-0.0742693
2111.36	-0.116306
2116.31	0.120657
2121.25	0.102965
2126.19	0.318425
2131.13	-0.00349998
2136.06	0.0989361
2140.99	0.0482998
2145.92	-0.17745
2150.84	-0.258665
2155.76	0.153213
2160.67	-0.109529
2165.58	0.0556746
2170.49	-0.322999
2175.39	0.669791
2180.29	-0.121059
2185.19	-0.0936842
2190.08	0.088892
2194.98	-0.657333
2199.86	-0.159591
2204.74	0.018301
2209.62	-0.191156
2214.5	-0.135902
2219.37	-0.0109711
2224.24	-0.324222
2229.11	-0.352982
2233.97	0.037468
2238.83	-0.212343
2243.68	-0.152904
2248.53	-0.248376
2253.38	0.301112
2258.22	-0.241305
2263.06	0.0191002
2267.9	-0.421717
2272.73	-0.531861
2277.56	-0.0835114
2282.39	0.0446911
2287.21	-0.532392
2292.03	-0.32069
2296.85	-0.0408325
2301.66	0.403653
2306.47	-0.274045
2311.28	-0.109146
2316.08	0.287887
2320.88	-0.516032
2325.68	-0.0685596
2330.47	0.0170393
2335.26	-0.191471
2340.04	-0.331137
2344.82	-0.375976
2349.6	-0.16331
2354.38	0.0466623
2359.15	-0.0535307
2363.92	-0.000900269
2368.68	0.0786514
2373.44	0.273981
2378.2	-0.283323
2382.95	-0.308346
2387.71	-0.151313
2392.45	-0.306171
2397.2	0.0768251
2401.94	-0.108021
2406.68	-0.461192
2411.41	-0.444838
2416.14	-0.187524
2420.87	-0.0961685
2425.59	0.0450659
2430.31	-0.277063
2435.03	-0.165349
2439.75	-0.290321
2444.46	0.0889568
2449.16	-0.0126238
2453.87	-0.382484
2458.57	0.0232954
2463.27	-0.227511
2467.96	0.0319042
2472.65	0.338865
2477.34	0.0828867
2482.02	-0.0524206
2486.7	-0.464821
2491.38	-0.237353
2496.05	-0.305925
2500.72	-0.0290461
2505.39	0.271505
2510.06	0.120912
2514.72	0.191064
2519.37	-0.312845
2524.03	-0.614506
2528.68	-0.015872
2533.33	-0.0917673
2537.97	-0.0132275
2542.61	-0.159838
2547.25	-0.203891
2551.88	0.461139
2556.51	0.161379
2561.14	-0.0891285
2565.77	-0.15708
2570.39	-0.299094
2575.01	0.301394
2579.62	-0.127498
2584.23	-0.232162
2588.84	0.274802
2593.45	0.158224
2598.05	-0.0250406
2602.65	-0.418553
2607.24	-0.453379
2611.84	-0.103569
2616.42	-0.299212
2621.01	-0.104482
2625.59	-0.531063
2630.17	0.113493
2634.75	0.146116
2639.32	-0.0185976
2643.89	-0.734353
2648.46	-0.400855
2653.02	-0.330689
2657.58	-0.594547
2662.14	-0.333906
2666.69	-0.369983
2671.24	0.159839
2675.79	-0.225043
2680.33	0.0594616
2684.88	-0.224275
2689.41	-0.133004
2693.95	0.328108
2698.48	-0.273587
2703.01	-0.243043
2707.53	0.220325
2712.06	0.0266914
2716.57	-0.406809
2721.09	0.0312033
2725.6	-0.221585
2730.11	0.0975189
2734.62	-0.249343
2739.12	0.03409
2743.62	-0.335678
2748.12	0.0995884
2752.61	0.0290527
2757.1	0.172366
2761.59	-0.669171
2766.08	-0.309426
2770.56	-0.172095
2775.04	0.0830708
2779.51	-0.466505
2783.98	0.144412
2788.45	0.335309
2792.92	-0.0707836
2797.38	-0.513274
2801.84	-0.279128
2806.3	-0.335248
2810.75	-0.0804453
2815.2	-0.45971
2819.65	-0.640774
2824.09	-0.303164
2828.53	-0.367459
2832.97	0.0267897
2837.41	-0.0992117
2841.84	-0.166974
2846.27	-0.289364
2850.69	-0.263933
2855.12	-0.17247
2859.54	-0.370957
2863.95	-0.623554
2868.37	-0.374347
2872.78	-0.0957098
2877.18	0.333338
2881.59	0.176527
2885.99	-0.215391
2890.39	-0.255252
2894.78	-0.0581017
2899.18	-0.242632
2903.57	-0.0734787
2907.95	-0.211231
2912.34	-0.417608
2916.72	-0.0236301
2921.09	0.102552
2925.47	0.109985
2929.84	-0.0617676
2934.21	0.0701752
2938.57	-0.207676
2942.94	-0.368095
2947.29	-0.411612
2951.65	-0.332279
2956	0.118113
2960.36	0.197319
2964.7	-0.186703
2969.05	-0.350658
2973.39	0.389881
2977.73	-0.896169
2982.06	-0.277147
2986.4	0.195017
2990.73	0.139175
2995.05	-0.167109
2999.38	-0.565983
3003.7	-0.487785
3008.01	-0.948954
3012.33	-0.10866
3016.64	0.39101
3020.95	0.0931683
3025.26	0.172832
3029.56	-0.080616
3033.86	0.501831
3038.16	-0.482752
3042.45	-0.291145
3046.74	-0.0409451
3051.03	0.666075
3055.32	0.0673103
3059.6	-0.205093
3063.88	-0.315273
3068.16	0.396851
3072.43	0.484877
3076.7	0.277687
3080.97	0.136086
3085.24	0.295763
3089.5	0.0651646
3093.76	0.27495
3098.02	-0.143808
3102.27	0.307613
3106.52	1.10533
3110.77	0.8983
3115.01	0.996038
3119.26	0.890474
3123.5	0.242117
3127.73	1.31115
3131.97	1.05002
3136.2	1.51498
3140.43	1.17689
3144.65	1.31859
3148.87	1.70201
3153.09	2.00423
3157.31	1.84231
3161.52	1.89185
3165.73	2.04638
3169.94	2.51593
3174.15	1.52687
3178.35	2.44995
3182.55	1.60887
3186.75	2.55806
3190.94	1.63485
3195.13	2.12723
3199.32	2.35125
3203.51	2.38064
3207.69	1.61475
3211.87	1.83276
3216.05	2.7932
3220.22	2.61312
3224.39	3.46609
3228.56	2.72861
3232.73	3.54914
3236.89	3.35502
3241.05	2.15539
3245.21	1.71029
3249.36	2.04377
3253.52	2.62546
3257.66	2.39773
3261.81	2.15403
3265.95	2.80326
3270.1	2.04635
3274.23	2.74479
3278.37	3.04928
3282.5	3.31766
3286.63	1.95238
3290.76	2.56855
3294.88	2.67559
3299	2.93986
3303.12	1.99641
3307.24	2.894
3311.35	2.29524
3315.46	2.00938
3319.57	3.10824
3323.68	2.39972
3327.78	2.05078
3331.88	2.26891
3335.98	3.49945
3340.07	2.44013
3344.16	2.5604
3348.25	2.50952
3352.34	2.46164
3356.42	2.45745
3360.5	1.97274
3364.58	2.4198
3368.66	2.49956
3372.73	2.49663
3376.8	3.13713
3380.87	2.58919
3384.93	3.01981
3388.99	2.50635
3393.05	3.17822
3397.11	2.87466
3401.16	2.52923
3405.21	3.11886
3409.26	3.21647
3413.31	3.43216
3417.35	2.94825
3421.39	2.66848
3425.43	2.42888
3429.46	2.8599
3433.5	2.42798
3437.53	2.5002
3441.55	2.91048
3445.58	2.08125
3449.6	2.21861
3453.62	2.31768
3457.64	2.55725
3461.65	2.17282
3465.66	2.21028
3469.67	1.4817
3473.68	2.09429
3477.68	3.14627
3481.68	1.97551
3485.68	2.08398
3489.67	2.36265
3493.67	2.33838
3497.66	2.56488
3501.64	2.00493
3505.63	1.7821
3509.61	1.93637
3513.59	1.90649
3517.57	2.65944
3521.54	1.84375
3525.52	2.07701
3529.49	0.999115
3533.45	1.16252
3537.42	0.993324
3541.38	1.00382
3545.34	1.39838
3549.29	2.05166
3553.25	0.831123
3557.2	0.500772
3561.15	1.14956
3565.09	0.305027
3569.04	0.71389
3572.98	0.853336
3576.92	0.64658
3580.85	1.07392
3584.79	1.33036
3588.72	0.599745
3592.64	0.539648
3596.57	0.660234
3600.49	0.503456
3604.41	0.979204
3608.33	0.176567
3612.25	0.550991
3616.16	-0.625656
3620.07	0.568268
3623.98	0.461807
3627.88	-1.25531
3631.79	-0.50362
3635.69	0.344738
3639.58	0.52038
3643.48	0.760714
3647.37	-0.233332
3651.26	-0.529938
3655.15	-0.170509
3659.03	-0.367785
3662.92	-0.105898
3666.8	-0.903313
3670.67	-1.42238
3674.55	-1.00915
3678.42	-0.39583
3682.29	-0.514791
3686.16	-0.996025
3690.02	-1.57016
3693.89	-0.598183
3697.75	-0.896315
3701.61	-1.09796
3705.46	0.306757
3709.31	-0.507154
3713.16	-1.04139
3717.01	-0.394306
3720.86	-0.850006
3724.7	-0.545383
3728.54	0.0451603
3732.38	0.353317
3736.21	-0.63666
3740.04	-0.47468
3743.87	-0.895933
3747.7	-0.692486
3751.53	0.0866852
3755.35	0.763391
3759.17	0.123835
3762.99	-1.00522
3766.81	-1.30994
3770.62	-1.26685
3774.43	-1.26889
3778.24	-0.0510864
3782.04	-1.40661
3785.85	-0.609642
3789.65	-0.157337
3793.45	-0.484583
3797.24	-1.44035
3801.04	-1.0687
3804.83	0.195484
3808.62	0.233673
3812.4	-0.574957
3816.19	0.0491562
3819.97	-0.518555
3823.75	-0.29608
3827.52	-0.227789
3831.3	-0.801846
3835.07	-0.125376
3838.84	-0.70566
3842.61	-0.626169
3846.37	0.540216
3850.13	0.184124
3853.89	-0.276163
3857.65	0.568457
3861.41	-0.305624
3865.16	-0.452026
3868.91	0.246078
3872.66	-0.91082
3876.4	-0.308699
3880.14	-0.77029
3883.89	0.291832
3887.62	-0.0609589
3891.36	0.046854
3895.09	-0.388027
3898.82	0.546104
3902.55	0.257776
3906.28	0.118084
3910	-0.280134
3913.73	-0.36367
3917.45	-0.493385
3921.16	0.0558891
3924.88	-0.735121
3928.59	0.327065
3932.3	-1.10272
3936.01	-0.263792
3939.71	-0.669508
3943.42	-0.178875
3947.12	-0.212801
3950.81	0.530281
3954.51	0.272003
3958.2	-0.464708
3961.9	1.19989
3965.58	0.0268021
3969.27	0.206867
3972.96	-1.13691
3976.64	0.145838
3980.32	0.107164
3984	0.429554
3987.67	-0.825165
3991.34	0.447657
3995.01	-0.531557
3998.68	-0.134947