File: Data/3-Raman/processed/bu04w-a-ff3-fi09-v_150 (500nm)_633nm_edge_100%_x100_vis_lwd_h50um_45sx2_01.txt
#Acq. time (s)=	45
#Accumulations=	2
#Range (cm-¹)=	100...4000
#Windows=	1
#Auto scanning=	Off
#Autofocus=	Off
#Macrospot=	Off
#AutoExposure=	Off
#Spike filter=	Multiple accum.
#Delay time (s)=	2
#Binning=	1
#Readout mode=	Signal
#DeNoise=	Off
#ICS correction=	On
#Dark correction=	Off
#Inst. Process=	Off
#Detector Gain=	Best Dynamic
#Detector ADC=	50 kHz HS
#Detector temperature (°C)=	-60.09
#Instrument=	LabRAM HR Evol
#Detector=	SIN-EM FIVIS
#Objective=	x100_VIS_LWD
#Grating=	150 (500nm)
#ND Filter=	100%
#Laser=	633nm_Edge
#Hole=	49.98
#Temperature=	0
#Range=	Visible
#StageXY=	75x50mm Scan+
#StageZ=	Z motor
#X (µm)=	0
#Y (µm)=	0
#Z (µm)=	-9.5
#Full time(mm:ss)=	1:35
#Project=	21_11_22
#Sample=	BU04w
#Site=
#Title=	BU04w-A-FF3-FI09-V_150 (500nm)_633nm_Edge_100%_x100_VIS_LWD_H50um_45sX2
#Remark=
#Date=	22.11.2021 12:39
#Acquired=	22.11.2021 12:39:01
#Base:Fit=	16.12.2021 16:15:35
#Base:Edit=	16.12.2021 16:24:49
#Base:Edit=	16.12.2021 16:24:50
#Base:Sub=	16.12.2021 16:24:53
100.177	533.596
106.695	471.692
113.209	425.7
119.717	412.567
126.219	404.641
132.716	425.752
139.208	469.012
145.694	370.959
152.175	334.406
158.651	587.416
165.121	673.182
171.586	267.024
178.045	120.346
184.5	48.2707
190.947	38.2495
197.39	15.7042
203.829	7.6394
210.262	7.02481
216.688	34.7855
223.11	107.962
229.527	401.256
235.939	693.619
242.344	310.659
248.745	168.455
255.141	174.776
261.53	149.429
267.916	91.433
274.294	89.9416
280.669	213.083
287.038	178.078
293.402	74.1623
299.76	46.4492
306.114	115.488
312.461	263.126
318.805	727.955
325.142	1525.14
331.475	1072.47
337.802	462.715
344.123	216.434
350.441	118.362
356.752	174.891
363.058	250.215
369.36	201.466
375.656	79.7153
381.947	16.5105
388.232	0.675262
394.512	29.3593
400.789	54.7759
407.059	84.1145
413.324	151.327
419.584	264.004
425.839	474.668
432.089	643.563
438.333	528.079
444.573	339.83
450.807	365.001
457.037	380.91
463.261	212.681
469.48	101.195
475.695	80.4309
481.904	103.579
488.108	115.495
494.307	141.431
500.502	199.973
506.691	313.684
512.874	386.522
519.053	330.735
525.227	291.032
531.396	264.537
537.559	222.063
543.718	176.194
549.873	152.362
556.022	109.498
562.165	105.715
568.304	74.2933
574.437	54.9358
580.567	51.4615
586.691	75.2095
592.81	127.958
598.924	244.189
605.033	194.24
611.138	205.009
617.236	196.386
623.332	184.046
629.42	153.573
635.506	144.001
641.585	120.681
647.659	127.204
653.73	172.061
659.794	190.244
665.854	123.313
671.91	61.4969
677.96	36.5231
684.005	6.83133
690.045	15.4938
696.082	-1.9754
702.113	1.0446
708.139	10.5426
714.16	9.40161
720.176	6.25881
726.187	-5.39856
732.194	-0.322372
738.196	0.0102234
744.193	-3.41851
750.185	6.22556
756.173	-1.81056
762.155	0.57634
768.133	5.89961
774.107	3.72195
780.075	0.477402
786.039	10.2642
791.998	11.486
797.952	13.5212
803.902	5.97767
809.845	9.65665
815.786	6.62807
821.721	12.9076
827.652	25.6498
833.576	36.6387
839.498	32.8793
845.415	34.8619
851.327	38.7319
857.233	41.7003
863.135	51.2918
869.032	59.0131
874.925	82.7054
880.813	101.528
886.697	101.247
892.576	94.1647
898.45	110.618
904.318	96.4928
910.184	100.286
916.044	115.335
921.9	144.684
927.75	189.321
933.596	247.522
939.439	369.76
945.275	524.344
951.107	678.428
956.936	656.781
962.759	558.796
968.577	511.599
974.391	579.858
980.201	809.26
986.006	1071.85
991.806	1073.06
997.602	845.96
1003.39	764.942
1009.18	720.981
1014.96	847.057
1020.74	1083.23
1026.51	1059.22
1032.28	700.693
1038.04	430.99
1043.8	317.007
1049.56	274.866
1055.31	216.689
1061.05	197.89
1066.8	200.074
1072.53	216.753
1078.26	287.626
1083.99	360.223
1089.72	463.811
1095.44	756.108
1101.15	766.427
1106.86	432.114
1112.56	260.362
1118.27	216.1
1123.96	186.88
1129.65	200.47
1135.34	287.597
1141.03	389.878
1146.7	561.989
1152.38	1005.13
1158.05	702.119
1163.71	286.374
1169.37	176.049
1175.03	118.994
1180.68	94.4285
1186.33	81.837
1191.98	56.7237
1197.61	43.4715
1203.25	44.0754
1208.88	31.9937
1214.51	15.9073
1220.13	17.6114
1225.74	13.3674
1231.36	17.0672
1236.97	14.6864
1242.57	16.2183
1248.17	24.7124
1253.77	22.0173
1259.36	19.2072
1264.94	16.3276
1270.53	12.4458
1276.11	47.7105
1281.68	52.7323
1287.25	12.7691
1292.81	9.96082
1298.38	6.23252
1303.93	8.56228
1309.48	1.99549
1315.03	8.56134
1320.58	6.12164
1326.12	6.73781
1331.65	6.35635
1337.18	-1.21086
1342.71	0.322601
1348.23	1.80616
1353.75	2.24552
1359.26	-1.47072
1364.77	4.00562
1370.28	8.40607
1375.78	10.7417
1381.28	113.69
1386.77	25.6581
1392.26	6.4563
1397.74	3.77338
1403.23	12.4154
1408.7	-0.527931
1414.17	3.01955
1419.64	-0.641464
1425.11	-0.156921
1430.56	4.49347
1436.02	7.07562
1441.47	1.29652
1446.92	-1.36178
1452.36	-0.95504
1457.8	-2.69771
1463.23	9.1678
1468.66	-1.04424
1474.09	-0.752525
1479.51	2.72015
1484.93	-2.19194
1490.34	1.33063
1495.75	2.79211
1501.16	4.27863
1506.56	5.79117
1511.96	2.03615
1517.35	0.409126
1522.74	-0.150799
1528.13	0.360382
1533.51	4.11641
1538.88	4.60957
1544.25	-5.76184
1549.62	8.61657
1554.99	7.75868
1560.35	-5.00547
1565.71	7.07746
1571.06	10.5082
1576.41	2.10296
1581.75	3.44657
1587.09	6.95934
1592.43	-1.3548
1597.76	3.28951
1603.09	-6.07733
1608.41	1.87781
1613.73	0.147579
1619.05	1.70963
1624.36	2.18697
1629.67	1.55904
1634.97	9.71314
1640.27	2.33704
1645.57	3.77264
1650.86	4.08132
1656.15	4.36388
1661.43	5.72095
1666.71	1.51842
1671.99	10.6123
1677.26	-0.270416
1682.53	6.57473
1687.79	4.51265
1693.05	4.68758
1698.31	3.8124
1703.56	5.35963
1708.81	8.05999
1714.06	3.69714
1719.3	6.29182
1724.53	5.45455
1729.77	2.40087
1735	4.95008
1740.22	8.62473
1745.44	10.0517
1750.66	11.4506
1755.87	15.0906
1761.08	9.63058
1766.29	8.69043
1771.49	4.35887
1776.69	7.97035
1781.88	8.21562
1787.07	8.47781
1792.26	11.0491
1797.44	11.3503
1802.62	3.65231
1807.79	11.9926
1812.96	11.1232
1818.13	4.47947
1823.29	9.36782
1828.45	10.8045
1833.61	12.2523
1838.76	11.3717
1843.91	5.78349
1849.05	2.49976
1854.19	1.52647
1859.33	5.25526
1864.46	9.01206
1869.59	6.90381
1874.71	9.46349
1879.83	9.65645
1884.95	1.56719
1890.06	6.443
1895.17	6.55933
1900.28	9.06602
1905.38	2.17118
1910.48	5.96339
1915.57	7.4465
1920.66	6.45182
1925.75	10.2482
1930.83	4.47651
1935.91	4.67479
1940.99	0.046524
1946.06	2.60923
1951.13	5.15884
1956.19	0.460232
1961.26	11.4168
1966.31	10.3111
1971.36	3.15199
1976.41	8.03415
1981.46	4.4861
1986.5	4.55283
1991.54	8.23312
1996.58	1.10101
2001.61	8.40901
2006.63	1.30801
2011.66	2.63834
2016.68	3.97309
2021.69	0.475647
2026.71	4.23992
2031.72	-2.8418
2036.72	5.80753
2041.72	3.57307
2046.72	6.19999
2051.71	10.0594
2056.71	9.01884
2061.69	9.22964
2066.68	9.44339
2071.66	8.41891
2076.63	11.0812
2081.6	6.34129
2086.57	11.4489
2091.54	9.14468
2096.5	8.10913
2101.46	14.5361
2106.41	8.54863
2111.36	17.536
2116.31	6.53766
2121.25	14.3288
2126.19	10.8086
2131.13	9.78436
2136.06	11.2734
2140.99	7.67474
2145.92	14.235
2150.84	13.1401
2155.76	8.19167
2160.67	9.60396
2165.58	12.2746
2170.49	13.6592
2175.39	6.11389
2180.29	7.50037
2185.19	7.58212
2190.08	12.7996
2194.98	15.4805
2199.86	2.8105
2204.74	0.402355
2209.62	12.1567
2214.5	8.49948
2219.37	7.4262
2224.24	7.64561
2229.11	3.96683
2233.97	2.87382
2238.83	10.9159
2243.68	7.21392
2248.53	7.43291
2253.38	11.5949
2258.22	-0.0497169
2263.06	6.75727
2267.9	5.61929
2272.73	12.4197
2277.56	9.91782
2282.39	4.72823
2287.21	11.4814
2292.03	8.92325
2296.85	9.02721
2301.66	1.16388
2306.47	3.97895
2311.28	6.82755
2316.08	7.02537
2320.88	8.57978
2325.68	18.2218
2330.47	0.919464
2335.26	2.48872
2340.04	9.50476
2344.82	4.31011
2349.6	7.29676
2354.38	4.79593
2359.15	5.00297
2363.92	7.9314
2368.68	5.35446
2373.44	2.75878
2378.2	5.70042
2382.95	4.45414
2387.71	8.74518
2392.45	6.06208
2397.2	4.75162
2401.94	2.04254
2406.68	3.49754
2411.41	6.39994
2416.14	6.62011
2420.87	-0.101025
2425.59	8.46254
2430.31	7.24049
2435.03	3.19804
2439.75	7.64886
2444.46	3.58599
2449.16	2.35177
2453.87	3.96716
2458.57	2.71839
2463.27	1.45937
2467.96	4.51447
2472.65	11.915
2477.34	3.39844
2482.02	6.46662
2486.7	9.53136
2491.38	8.21815
2496.05	12.7545
2500.72	7.03323
2505.39	8.6264
2510.06	5.79762
2514.72	5.8938
2519.37	4.51583
2524.03	4.62056
2528.68	3.23779
2533.33	1.85464
2537.97	0.47538
2542.61	10.999
2547.25	5.16584
2551.88	9.76798
2556.51	6.88835
2561.14	0.992111
2565.77	7.11727
2570.39	11.772
2575.01	7.37607
2579.62	4.45625
2584.23	1.49597
2588.84	7.6252
2593.45	7.6616
2598.05	3.16202
2602.65	7.79072
2607.24	9.36541
2611.84	12.4559
2616.42	9.42476
2621.01	10.9847
2625.59	7.9536
2630.17	8.00156
2634.75	8.08475
2639.32	11.2903
2643.89	8.32485
2648.46	8.44728
2653.02	13.2365
2657.58	8.61993
2662.14	13.3489
2666.69	11.8074
2671.24	19.6953
2675.79	11.9561
2680.33	9.0005
2684.88	9.16949
2689.41	12.524
2693.95	6.26233
2698.48	11.0861
2703.01	12.7416
2707.53	11.1689
2712.06	4.74186
2716.57	8.00506
2721.09	12.8827
2725.6	16.135
2730.11	9.63382
2734.62	1.47397
2739.12	12.801
2743.62	3.01654
2748.12	16.0401
2752.61	11.2064
2757.1	9.59611
2761.59	11.22
2766.08	14.5132
2770.56	7.93386
2775.04	6.29524
2779.51	12.946
2783.98	6.38563
2788.45	11.4424
2792.92	3.14664
2797.38	13.224
2801.84	11.5724
2806.3	14.9437
2810.75	8.19008
2815.2	3.08625
2819.65	6.42447
2824.09	-0.394051
2828.53	8.04818
2832.97	8.00387
2837.41	7.95286
2841.84	11.3148
2846.27	6.15616
2850.69	9.54733
2855.12	2.68369
2859.54	7.83026
2863.95	11.2968
2868.37	9.60938
2872.78	7.90587
2877.18	6.19516
2881.59	4.48421
2885.99	1.01902
2890.39	6.31836
2894.78	4.58559
2899.18	11.7233
2903.57	11.7771
2907.95	10.028
2912.34	-0.694988
2916.72	2.84943
2921.09	1.03484
2925.47	2.8213
2929.84	4.6315
2934.21	4.63429
2938.57	6.42138
2942.94	2.74535
2947.29	6.32521
2951.65	11.7385
2956	8.03298
2960.36	2.48756
2964.7	4.2618
2969.05	7.88964
2973.39	9.69781
2977.73	7.83042
2982.06	11.5006
2986.4	9.66306
2990.73	5.97639
2995.05	17.1623
2999.38	9.76924
3003.7	15.4504
3008.01	2.38929
3012.33	19.3828
3016.64	11.9307
3020.95	15.8268
3025.26	27.3399
3029.56	15.9692
3033.86	23.6574
3038.16	27.5053
3042.45	19.8799
3046.74	27.5933
3051.03	37.2575
3055.32	31.5134
3059.6	33.4932
3063.88	23.8492
3068.16	31.6482
3072.43	43.3664
3076.7	51.2416
3080.97	47.4373
3085.24	51.4646
3089.5	51.6354
3093.76	57.7578
3098.02	52.1147
3102.27	66.2393
3106.52	54.6717
3110.77	68.9734
3115.01	61.3647
3119.26	83.8613
3123.5	84.3738
3127.73	91.0087
3131.97	85.5302
3136.2	88.1904
3140.43	99.0703
3144.65	114.123
3148.87	108.512
3153.09	111.081
3157.31	126.145
3161.52	139.205
3165.73	160.722
3169.94	146.506
3174.15	142.823
3178.35	162.209
3182.55	164.638
3186.75	175.512
3190.94	182.132
3195.13	163.399
3199.32	176.759
3203.51	166.897
3207.69	176.352
3211.87	157.878
3216.05	147.977
3220.22	157.517
3224.39	143.097
3228.56	137.338
3232.73	122.705
3236.89	118.935
3241.05	113
3245.21	95.955
3249.36	94.3276
3253.52	94.8
3257.66	74.9736
3261.81	68.6982
3265.95	78.289
3270.1	63.0355
3274.23	59.0218
3278.37	54.7487
3282.5	61.9281
3286.63	48.4714
3290.76	51.0616
3294.88	39.8189
3299	49.3224
3303.12	45.0122
3307.24	38.3597
3311.35	47.9298
3315.46	38.92
3319.57	32.2214
3323.68	41.8888
3327.78	44.5995
3331.88	45.0242
3335.98	43.1414
3340.07	31.737
3344.16	39.172
3348.25	29.9729
3352.34	54.0665
3356.42	32.9689
3360.5	26.14
3364.58	21.678
3368.66	29.1887
3372.73	31.9172
3376.8	24.9899
3380.87	32.5016
3384.93	30.3663
3388.99	20.965
3393.05	30.8996
3397.11	23.9198
3401.16	21.7766
3405.21	24.4573
3409.26	17.4201
3413.31	20.0926
3417.35	20.3393
3421.39	25.4581
3425.43	18.3862
3429.46	16.2089
3433.5	14.0422
3437.53	21.6821
3441.55	17.0945
3445.58	14.9687
3449.6	15.3197
3453.62	20.6209
3457.64	13.5904
3461.65	16.4784
3465.66	11.8971
3469.67	4.77155
3473.68	15.1526
3477.68	7.97159
3481.68	15.9073
3485.68	13.7408
3489.67	9.01125
3493.67	19.5411
3497.66	22.4352
3501.64	9.96449
3505.63	17.9394
3509.61	20.7675
3513.59	15.8674
3517.57	8.38597
3521.54	11.178
3525.52	16.5505
3529.49	14.1977
3533.45	11.8808
3537.42	17.3386
3541.38	15.0586
3545.34	15.3333
3549.29	15.5899
3553.25	18.3898
3557.2	18.6112
3561.15	11.034
3565.09	8.66538
3569.04	19.3867
3572.98	22.2771
3576.92	27.8232
3580.85	20.2521
3584.79	25.8509
3588.72	18.2291
3592.64	26.4957
3596.57	18.8176
3600.49	11.0762
3604.41	13.9976
3608.33	11.5444
3612.25	6.37544
3616.16	3.87545
3620.07	-1.34801
3623.98	9.59404
3627.88	20.5358
3631.79	4.41648
3635.69	9.93723
3639.58	15.4883
3643.48	4.79699
3647.37	10.3968
3651.26	5.04375
3655.15	13.3193
3659.03	16.1433
3662.92	16.2285
3666.8	-0.0765839
3670.67	16.4065
3674.55	13.7602
3678.42	0.152081
3682.29	11.2446
3686.16	3.10977
3690.02	3.22292
3693.89	11.6446
3697.75	6.20184
3701.61	14.6641
3705.46	14.7772
3709.31	9.29243
3713.16	0.959068
3717.01	9.46014
3720.86	9.51739
3724.7	12.388
3728.54	9.59364
3732.38	12.4656
3736.21	9.66106
3740.04	9.68402
3743.87	3.99124
3747.7	6.84064
3751.53	15.4021
3755.35	3.92664
3759.17	3.87711
3762.99	0.953979
3766.81	6.62449
3770.62	9.44385
3774.43	6.52909
3778.24	12.233
3782.04	17.9655
3785.85	12.1987
3789.65	9.29144
3793.45	12.1627
3797.24	17.9611
3801.04	6.37602
3804.83	3.47518
3808.62	9.31499
3812.4	6.4089
3816.19	9.34366
3819.97	6.42487
3823.75	15.2449
3827.52	9.37292
3831.3	12.344
3835.07	6.47241
3838.84	6.49477
3842.61	9.50407
3846.37	9.52542
3850.13	9.52994
3853.89	9.53844
3857.65	0.631111
3861.41	9.55988
3865.16	3.67243
3868.91	3.80142
3872.66	6.87602
3876.4	-2.00297
3880.14	7.06343
3883.89	4.19453
3887.62	10.3316
3891.36	10.5103
3895.09	4.73259
3898.82	7.97195
3902.55	14.2573
3906.28	5.48989
3910	5.7843
3913.73	6.11829
3917.45	15.5876
3921.16	3.86581
3924.88	16.4947
3928.59	7.82273
3932.3	11.3746
3936.01	8.82392
3939.71	12.4405
3943.42	6.90282
3947.12	1.37494
3950.81	14.3735
3954.51	15.0787
3958.2	12.726
3961.9	10.3967
3965.58	17.4011
3969.27	18.2452
3972.96	16.0426
3976.64	20.0951
3980.32	14.8888
3984	15.9349
3987.67	26.3459
3991.34	21.3231
3995.01	25.686
3998.68	23.9252