File: Data/3-Raman/processed/bu04w-a-ff3-fi02-v_1800 (450-850nm)_633nm_edge_100%_x100_vis_lwd_h50um_45sx2_01.txt
#Acq. time (s)=	45
#Accumulations=	2
#Range (cm-¹)=	1200...2355
#Windows=	5
#Auto scanning=	Off
#Autofocus=	Off
#Macrospot=	Off
#AutoExposure=	Off
#Spike filter=	Multiple accum.
#Delay time (s)=	2
#Binning=	1
#Readout mode=	Signal
#DeNoise=	Off
#ICS correction=	On
#Dark correction=	Off
#Inst. Process=	Off
#Detector Gain=	Best Dynamic
#Detector ADC=	50 kHz HS
#Detector temperature (°C)=	-60.28
#Instrument=	LabRAM HR Evol
#Detector=	SIN-EM FIVIS
#Objective=	x100_VIS_LWD
#Grating=	1800 (450-850nm)
#ND Filter=	100%
#Laser=	633nm_Edge
#Hole=	49.98
#Temperature=	0
#Range=	Visible
#StageXY=	75x50mm Scan+
#StageZ=	Z motor
#X (µm)=	0
#Y (µm)=	0
#Z (µm)=	5.3
#Full time(mm:ss)=	7:56
#Project=	21_11_22
#Sample=	BU04w
#Site=
#Title=	BU04w-A-FF3-FI02-L_1800 (450-850nm)_633nm_Edge_100%_x100_VIS_LWD_H50um_45sX2
#Remark=
#Date=	22.11.2021 10:49
#Acquired=	22.11.2021 10:49:33
#Base:Fit=	16.12.2021 16:15:35
#Base:Fit=	16.12.2021 16:22:03
#Base:Sub=	16.12.2021 16:22:04
1200.31	-0.37451
1201.34	1.52365
1202.37	0.530656
1203.4	-0.515396
1204.44	1.42535
1205.47	2.3644
1206.5	1.39303
1207.53	-0.659835
1208.56	2.2943
1209.59	0.300048
1210.62	-0.708287
1211.65	-0.729256
1212.68	0.214966
1213.71	-0.763601
1214.74	0.185284
1215.77	-0.823283
1216.8	2.11785
1217.83	-1.82767
1218.86	-0.850616
1219.89	1.13694
1220.91	-1.84163
1221.94	-2.85697
1222.97	-0.881848
1224	0.103346
1225.02	2.06933
1226.05	0.0638857
1227.08	1.10741
1228.1	-1.89619
1229.13	0.0834808
1230.15	2.08449
1231.18	1.07841
1232.2	0.0859127
1233.23	-0.940557
1234.25	2.11695
1235.28	1.11884
1236.3	0.114151
1237.32	3.13463
1238.35	-1.9093
1239.37	0.0958147
1240.39	0.124027
1241.42	0.118183
1242.44	0.107717
1243.46	2.16935
1244.48	-0.831944
1245.51	2.17523
1246.53	0.210047
1247.55	2.21494
1248.57	0.173557
1249.59	2.2099
1250.61	-0.829253
1251.63	0.192616
1252.65	0.196391
1253.67	-0.811467
1254.69	0.221582
1255.71	0.214746
1256.73	0.215375
1257.75	3.25123
1258.76	0.214866
1259.78	-1.84161
1260.8	-1.82341
1261.82	3.28018
1262.83	-0.768733
1263.85	4.33691
1264.87	4.32568
1265.88	2.28883
1266.9	2.26485
1267.92	4.31352
1268.93	0.227157
1269.95	0.226473
1270.96	0.22658
1271.98	-0.806617
1272.99	3.26883
1274.01	0.222251
1275.02	1.22929
1276.04	3.27227
1277.05	2.24634
1278.06	1.23974
1279.08	-0.802915
1280.09	1.27465
1281.1	3.23673
1282.12	6.29216
1283.13	17.3713
1284.14	83.1013
1285.15	43.8025
1286.16	10.3317
1287.17	1.22249
1288.18	1.19064
1289.19	2.20578
1290.2	1.20411
1291.22	0.14528
1292.22	3.19324
1293.23	1.21137
1294.24	-1.82458
1295.25	0.187843
1296.26	4.21439
1297.27	0.181494
1298.28	-3.86146
1299.29	1.16862
1300.29	1.18087
1301.3	2.18829
1302.31	-0.774692
1303.32	-0.767096
1304.32	0.217917
1305.33	1.2284
1306.34	-1.81223
1307.34	-0.799938
1308.35	-0.778353
1309.35	2.22817
1310.36	6.25404
1311.36	-0.777432
1312.37	0.258531
1313.37	1.2464
1314.38	-1.79898
1315.38	1.25298
1316.38	-0.748701
1317.39	-1.716
1318.39	-1.75398
1319.39	0.307779
1320.4	0.308011
1321.4	-0.706554
1322.4	-2.72145
1323.4	1.32688
1324.4	0.350788
1325.41	-0.651107
1326.41	0.381978
1327.41	-0.600038
1328.41	1.45527
1329.41	2.50583
1330.41	-0.561019
1331.41	-1.60878
1332.41	3.48497
1333.41	1.47758
1334.41	-1.57132
1335.41	1.53479
1336.4	0.499455
1337.4	0.525788
1338.4	-0.498861
1339.4	0.513685
1340.4	1.58736
1341.39	2.6205
1342.39	0.584897
1343.39	-0.439063
1344.38	0.602175
1345.38	1.66171
1346.38	0.577599
1347.37	-1.44478
1348.37	1.67289
1349.36	0.645603
1350.36	0.668023
1351.35	3.76129
1352.35	2.76074
1353.34	2.74828
1354.34	-0.342854
1355.33	0.670598
1356.32	-0.312279
1357.32	1.7866
1358.31	-0.303974
1359.3	3.84746
1360.29	0.699997
1361.29	-0.326319
1362.28	0.76287
1363.27	0.775182
1364.26	0.765173
1365.25	2.80196
1366.24	-1.31354
1367.23	-2.3631
1368.22	0.755919
1369.21	1.86099
1370.2	3.92469
1371.19	1.87505
1372.18	1.84298
1373.17	1.79702
1374.16	0.765066
1375.15	1.79596
1376.14	2.85433
1377.13	-0.220519
1378.11	2.87641
1379.1	4.94369
1380.09	1.8576
1381.08	-1.2914
1382.06	2.86629
1383.05	1.82899
1384.04	1.84039
1385.02	3.93069
1386.01	12.2908
1386.99	65.052
1387.98	168.955
1388.96	12.2465
1389.95	7.05281
1390.93	2.89206
1391.92	-0.235497
1392.9	2.91988
1393.89	1.82271
1394.87	1.8115
1395.85	2.88645
1396.84	0.807327
1397.82	0.81209
1398.8	-0.218057
1399.78	0.797489
1400.77	-1.25048
1401.75	1.86487
1402.73	0.81404
1403.71	-0.210141
1404.69	2.9046
1405.67	1.86232
1406.65	0.837057
1407.63	2.91242
1408.61	11.2088
1409.59	7.10478
1410.57	1.8876
1411.55	8.14209
1412.53	1.89885
1413.51	-0.170979
1414.49	2.9444
1415.47	-0.149534
1416.44	-0.133022
1417.42	4.0373
1418.4	1.99245
1419.38	-0.119578
1420.35	0.91412
1421.33	1.98438
1422.31	-0.0723724
1423.28	0.98002
1424.26	2.03578
1425.24	2.01664
1426.21	-0.0504141
1427.19	2.057
1428.16	-0.0478134
1429.14	0.975945
1430.11	1.03292
1431.08	-2.1126
1432.06	-0.00316906
1433.03	1.03177
1434.01	3.12938
1434.98	-1.06061
1435.95	1.07016
1436.92	0.0331993
1437.9	2.152
1438.87	-1.02852
1439.84	4.2526
1440.81	1.09319
1441.78	-0.983201
1442.76	0.0864439
1443.73	2.19564
1444.7	-0.973164
1445.67	0.0694723
1446.64	2.1828
1447.61	2.20429
1448.58	0.107848
1449.55	2.23385
1450.52	-0.946827
1451.48	0.155707
1452.45	1.16206
1453.42	1.03846
1454.39	0.953671
1455.36	0.440007
1456.32	-1.63195
1457.29	-1.92739
1458.26	0.0827503
1459.23	1.13159
1460.19	-0.251948
1461.16	0.810414
1462.13	0.561207
1463.09	-0.936789
1464.06	-0.816813
1465.02	-2.00605
1465.99	-0.794487
1466.95	0.219701
1467.93	1.24996
1468.91	0.226079
1469.89	0.211847
1470.87	0.20575
1471.85	-1.90405
1472.83	1.28047
1473.81	0.224251
1474.79	1.28454
1475.76	-0.843761
1476.74	1.2905
1477.72	-0.82889
1478.7	7.65691
1479.68	0.258165
1480.65	1.32732
1481.63	1.29863
1482.61	1.24942
1483.58	-0.807227
1484.56	1.33045
1485.54	-0.816585
1486.51	2.37682
1487.49	1.31233
1488.46	0.249698
1489.44	0.241318
1490.41	2.41552
1491.39	0.296622
1492.36	-0.736562
1493.34	1.37212
1494.31	1.37429
1495.28	1.35677
1496.26	-0.739174
1497.23	-1.79952
1498.2	1.38386
1499.18	1.39904
1500.15	2.4627
1501.12	3.52573
1502.09	0.350091
1503.06	1.42212
1504.04	0.384761
1505.01	1.46098
1505.98	-0.645859
1506.95	-0.66078
1507.92	-1.75193
1508.89	1.49783
1509.86	1.47808
1510.83	2.57654
1511.8	2.59448
1512.77	-0.638912
1513.74	0.423413
1514.7	-0.616418
1515.67	0.470228
1516.64	-0.610752
1517.61	2.64697
1518.58	-0.556677
1519.55	1.5522
1520.51	1.60628
1521.48	-1.61773
1522.45	-0.554729
1523.41	0.529057
1524.38	0.541606
1525.35	0.558341
1526.31	0.547832
1527.28	1.63271
1528.24	0.578005
1529.21	2.77595
1530.17	1.63386
1531.14	1.69604
1532.1	0.58076
1533.07	1.70406
1534.03	1.73943
1534.99	0.645907
1535.96	1.7399
1536.92	0.632136
1537.88	0.633359
1538.84	-0.421702
1539.81	2.82678
1540.77	-0.405924
1541.73	-0.385737
1542.69	0.701482
1543.65	1.80296
1544.62	0.68011
1545.58	-1.47077
1546.54	-1.46019
1547.5	0.733038
1548.46	0.725909
1549.42	1.82268
1550.38	0.735624
1551.34	-0.363832
1552.3	0.741419
1553.25	0.722746
1554.21	1.85629
1555.17	-1.43375
1556.13	4.04668
1557.09	-0.304858
1558.05	-1.42075
1559	1.86895
1559.96	1.85694
1560.92	1.84659
1561.88	-0.3535
1562.83	-0.326614
1563.79	0.786526
1564.74	-1.42707
1565.7	0.751131
1566.66	-3.61609
1567.61	-0.33887
1568.57	-1.42535
1569.52	0.777866
1570.48	-0.363692
1571.43	-0.364817
1572.38	1.86916
1573.34	0.758104
1574.29	0.788763
1575.24	0.772276
1576.2	-1.43925
1577.15	-0.348012
1578.1	1.83815
1579.06	0.774342
1580.01	-0.317439
1580.96	2.92148
1581.91	0.734828
1582.86	-0.330404
1583.81	1.85945
1584.77	2.96595
1585.72	-0.35279
1586.67	-0.342575
1587.62	1.84293
1588.57	-0.348929
1589.52	1.8762
1590.47	0.74416
1591.42	-0.362269
1592.36	0.737689
1593.31	1.83799
1594.26	1.83355
1595.21	0.741219
1596.16	-2.56498
1597.11	1.82304
1598.05	-0.366603
1599	-1.44837
1599.95	-1.44108
1600.9	0.731247
1601.84	-0.350667
1602.79	0.716231
1603.73	-0.363873
1604.68	-0.367021
1605.63	0.734356
1606.57	-0.376637
1607.52	-0.384431
1608.46	0.717205
1609.41	-1.44263
1610.35	-1.46475
1611.3	0.742967
1612.24	0.784803
1613.18	0.767659
1614.13	-0.334623
1615.07	0.775862
1616.01	0.767468
1616.96	0.80915
1617.9	-0.324196
1618.84	-0.3301
1619.78	1.9018
1620.72	1.90692
1621.67	-0.314998
1622.61	3.04044
1623.55	-1.41595
1624.49	1.92565
1625.43	-0.281996
1626.37	0.844655
1627.31	3.08358
1628.25	3.05315
1629.19	1.93868
1630.13	-1.39928
1631.07	-1.37437
1632.01	0.901813
1632.95	-0.253981
1633.88	-0.227035
1634.82	0.884829
1635.76	-0.225863
1636.7	2.05363
1637.64	2.05289
1638.57	-2.43211
1639.51	0.91336
1640.45	-0.212904
1641.38	-1.34177
1642.32	-0.18299
1643.25	0.938851
1644.19	0.905037
1645.13	0.909331
1646.06	0.941869
1647	0.942388
1647.93	2.06441
1648.87	2.02228
1649.8	-1.34227
1650.73	0.946224
1651.67	-0.180391
1652.6	0.901568
1653.53	2.04085
1654.47	-1.35226
1655.4	0.922628
1656.33	-1.36843
1657.27	3.14806
1658.2	-2.47574
1659.13	-0.245628
1660.06	2.03829
1660.99	0.917751
1661.92	2.06666
1662.85	-0.222046
1663.79	0.897393
1664.72	-0.239328
1665.65	-1.35283
1666.58	1.98999
1667.51	0.880737
1668.44	2.00759
1669.36	2.03241
1670.29	0.883495
1671.22	0.904502
1672.15	1.99508
1673.08	-1.40379
1674.01	1.99972
1674.94	0.880692
1675.86	2.0288
1676.79	-0.284081
1677.72	0.816378
1678.64	1.94406
1679.57	3.08889
1680.5	-0.295074
1681.42	1.92338
1682.35	6.41393
1683.28	0.805725
1684.2	-0.331101
1685.13	0.795554
1686.05	0.803345
1686.98	0.793586
1687.9	-2.61704
1688.82	0.767104
1689.75	1.93247
1690.67	1.90106
1691.6	-0.316598
1692.52	0.846881
1693.44	0.538197
1694.36	0.813567
1695.29	2.78379
1696.21	-0.229375
1697.13	0.913404
1698.05	1.24767
1698.98	-0.989224
1699.9	0.20097
1700.82	1.06962
1701.74	1.01094
1702.66	0.270101
1703.58	-0.452133
1704.5	0.90139
1705.42	0.40913
1706.32	0.720385
1707.25	0.695048
1708.19	-0.458499
1709.12	0.694188
1710.06	0.689847
1710.99	0.681755
1711.93	1.81625
1712.86	-0.470728
1713.79	0.708708
1714.73	-0.455389
1715.66	-1.57739
1716.59	5.2213
1717.52	0.66365
1718.46	-0.458368
1719.39	0.683505
1720.32	2.90717
1721.25	0.683287
1722.18	0.691072
1723.11	1.84148
1724.04	0.667318
1724.98	-1.60049
1725.91	1.82521
1726.84	5.21155
1727.77	-0.459113
1728.7	1.81193
1729.62	-2.75105
1730.55	-0.467862
1731.48	-0.459738
1732.41	1.83199
1733.34	-0.460363
1734.27	-1.61972
1735.2	-1.61709
1736.12	1.83068
1737.05	-0.435282
1737.98	1.83518
1738.91	0.694986
1739.83	0.715487
1740.76	-0.424529
1741.69	1.87539
1742.61	0.684491
1743.54	0.648425
1744.46	0.708965
1745.39	1.85801
1746.32	-0.460248
1747.24	0.694892
1748.17	-0.471678
1749.09	-0.470816
1750.01	-0.415209
1750.94	0.736167
1751.86	0.708727
1752.79	1.85486
1753.71	-2.76585
1754.63	-0.437423
1755.56	0.722433
1756.48	0.709297
1757.4	-0.443001
1758.32	-1.6078
1759.24	1.84509
1760.17	-0.453589
1761.09	3.01175
1762.01	1.85167
1762.93	0.698136
1763.85	0.712606
1764.77	-0.434755
1765.69	0.720904
1766.61	-1.62711
1767.53	-0.464046
1768.45	0.73854
1769.37	-0.437555
1770.29	-0.445001
1771.21	-0.476239
1772.13	1.85378
1773.05	-0.483842
1773.97	-0.447658
1774.88	1.84463
1775.8	1.85102
1776.72	3.02707
1777.64	0.693142
1778.55	1.84909
1779.47	1.84204
1780.39	-0.456044
1781.3	1.88626
1782.22	0.725738
1783.13	0.691772
1784.05	-1.65885
1784.97	-2.7914
1785.88	1.9117
1786.8	0.711515
1787.71	-1.62509
1788.63	0.670778
1789.54	0.702289
1790.45	1.87747
1791.37	0.71527
1792.28	-1.60232
1793.19	-3.95478
1794.11	0.706472
1795.02	0.714182
1795.93	-2.78882
1796.85	-0.446614
1797.76	0.690331
1798.67	0.674497
1799.58	-0.474199
1800.49	0.696977
1801.41	-1.61288
1802.32	3.05278
1803.23	-2.77135
1804.14	-0.438179
1805.05	-2.77681
1805.96	-0.43333
1806.87	0.730034
1807.78	-0.455608
1808.69	-1.59256
1809.6	-1.58625
1810.51	-0.404289
1811.41	0.762653
1812.32	0.774492
1813.23	1.98142
1814.14	-0.384082
1815.05	1.9451
1815.95	1.97456
1816.86	0.810968
1817.77	0.796553
1818.68	1.94877
1819.58	1.95943
1820.49	2.0093
1821.4	-0.362163
1822.3	-1.51882
1823.21	-0.365814
1824.11	3.15688
1825.02	0.84674
1825.92	0.867867
1826.83	0.881736
1827.73	-0.33099
1828.64	2.06551
1829.54	-0.307396
1830.45	0.886042
1831.35	0.875759
1832.25	0.893395
1833.16	0.910588
1834.06	2.11652
1834.96	2.09683
1835.86	3.25955
1836.77	2.09269
1837.67	-0.243043
1838.57	0.960399
1839.47	0.954565
1840.37	2.13219
1841.28	-0.24796
1842.18	0.976467
1843.08	0.941874
1843.98	0.968562
1844.88	2.16644
1845.78	-0.198893
1846.68	-1.40104
1847.58	-1.38286
1848.48	0.985364
1849.38	-0.169599
1850.27	-1.358
1851.17	-0.16986
1852.07	1.06565
1852.97	2.24329
1853.87	2.27264
1854.77	-0.139595
1855.66	1.07361
1856.56	1.08823
1857.46	-0.140284
1858.35	1.09521
1859.25	1.07657
1860.15	4.70329
1861.04	2.31505
1861.94	1.13766
1862.83	-1.29041
1863.73	-1.32987
1864.63	2.28482
1865.52	1.12541
1866.41	1.09594
1867.31	3.53819
1868.2	2.28701
1869.1	2.25906
1869.99	-1.29403
1870.89	-2.51855
1871.78	2.33798
1872.67	1.10074
1873.56	2.32035
1874.46	-1.28963
1875.35	3.54731
1876.24	1.0895
1877.13	-0.111586
1878.03	1.16743
1878.92	1.13086
1879.81	2.30954
1880.7	-0.0929174
1881.59	1.14829
1882.48	1.11085
1883.37	1.12376
1884.26	-2.44308
1885.15	-0.0625467
1886.04	1.22145
1886.93	2.40457
1887.82	-1.24406
1888.71	1.17616
1889.6	-1.15341
1890.49	1.19732
1891.38	2.38384
1892.26	1.14988
1893.15	2.39397
1894.04	1.17102
1894.93	2.39365
1895.81	-0.0244513
1896.7	1.19817
1897.59	-2.41763
1898.47	1.17321
1899.36	-0.0399027
1900.25	2.41958
1901.13	1.21355
1902.02	0.00250244
1902.9	-1.28362
1903.79	-0.0111408
1904.67	2.46362
1905.56	-0.0057478
1906.44	-0.0472307
1907.33	1.19931
1908.21	1.22425
1909.09	-1.19351
1909.98	2.46501
1910.86	3.67534
1911.74	2.46697
1912.63	2.51881
1913.51	1.27753
1914.39	0.0248346
1915.27	1.25086
1916.16	2.57309
1917.04	0.0298824
1917.92	-1.23091
1918.8	0.0599241
1919.68	0.197272
1920.56	1.04055
1921.44	1.05716
1922.32	0.2942
1923.2	1.32328
1924.08	0.480968
1924.96	0.384591
1925.84	1.40617
1926.72	0.55439
1927.6	0.34562
1928.48	0.489449
1929.36	-0.862476
1930.24	-0.747417
1931.12	-1.83205
1931.99	-0.496376
1932.87	-0.980405
1933.75	-1.13196
1934.64	1.38102
1935.54	2.60808
1936.43	1.36977
1937.32	2.55445
1938.21	1.35973
1939.1	0.135627
1939.99	2.6127
1940.89	-1.13798
1941.78	-3.57868
1942.67	1.39011
1943.56	-1.11116
1944.45	0.12652
1945.34	-1.10271
1946.23	0.165212
1947.12	0.142097
1948	1.37153
1948.89	-1.10826
1949.78	0.163663
1950.67	2.64201
1951.56	-2.36031
1952.45	-3.59963
1953.33	0.141463
1954.22	2.66866
1955.11	2.61329
1956	0.127905
1956.88	-1.09512
1957.77	2.67282
1958.66	0.154771
1959.54	1.39882
1960.43	1.39891
1961.31	2.61972
1962.2	-1.10818
1963.09	-1.12886
1963.97	0.148052
1964.86	0.17105
1965.74	1.38474
1966.63	0.129022
1967.51	-2.34767
1968.39	0.145985
1969.28	0.131664
1970.16	0.106591
1971.04	0.114054
1971.93	1.35893
1972.81	0.143352
1973.69	-1.15402
1974.58	1.3362
1975.46	2.61566
1976.34	0.132352
1977.22	1.39057
1978.1	-1.16452
1978.98	2.59526
1979.87	0.153509
1980.75	-2.36021
1981.63	1.2891
1982.51	1.32316
1983.39	0.0970516
1984.27	2.55266
1985.15	-1.20551
1986.03	-1.2117
1986.91	1.32634
1987.79	1.3154
1988.67	-2.48643
1989.54	0.0216789
1990.42	-1.19346
1991.3	3.76192
1992.18	-3.69014
1993.06	0.0163183
1993.93	-3.7239
1994.81	0.0138407
1995.69	0.000340462
1996.57	-0.0092392
1997.44	0.0234699
1998.32	1.25054
1999.2	-0.0165291
2000.07	-1.30281
2000.95	2.50737
2001.82	1.24006
2002.7	1.19389
2003.57	1.2046
2004.45	1.22452
2005.32	-0.0763073
2006.2	1.1793
2007.07	-0.0895424
2007.95	-2.58033
2008.82	1.16847
2009.69	-2.59675
2010.57	-0.104909
2011.44	-1.32428
2012.31	-0.100226
2013.19	-2.61442
2014.06	1.19189
2014.93	-1.3173
2015.8	1.18549
2016.68	-0.0988741
2017.55	-0.133322
2018.42	-0.108331
2019.29	1.10361
2020.16	-1.37001
2021.03	-2.63091
2021.9	-1.3744
2022.77	-2.62196
2023.64	-0.118798
2024.51	2.39568
2025.38	-1.38323
2026.25	-2.64371
2027.12	-0.119825
2027.99	-0.167847
2028.86	1.13588
2029.73	-0.136436
2030.6	-0.143989
2031.46	-0.148933
2032.33	-1.40266
2033.2	2.39862
2034.07	-0.147045
2034.93	1.09567
2035.8	3.62257
2036.67	-0.170605
2037.53	1.12108
2038.4	-0.128282
2039.27	1.13819
2040.13	1.08777
2041	-3.93202
2041.86	1.09336
2042.73	1.07273
2043.59	-0.145435
2044.46	1.06538
2045.32	1.07195
2046.19	-0.206326
2047.05	-1.40591
2047.92	-0.182321
2048.78	-0.172967
2049.64	-1.42459
2050.51	2.3582
2051.37	1.08336
2052.23	1.10171
2053.1	-2.66401
2053.96	-0.208982
2054.82	-0.199613
2055.68	-0.190022
2056.54	-2.6932
2057.41	-0.19928
2058.27	1.10579
2059.13	-0.188445
2059.99	1.089
2060.85	1.11673
2061.71	-0.12232
2062.57	1.15374
2063.43	-0.234161
2064.29	-1.46899
2065.15	1.08776
2066.01	-0.203572
2066.87	-0.191981
2067.73	1.0543
2068.59	-0.208624
2069.44	-5.28443
2070.3	-1.46297
2071.16	-0.190197
2072.02	3.61012
2072.88	-0.198231
2073.73	2.34327
2074.59	2.35683
2075.45	-0.182025
2076.3	-2.73065
2077.16	-1.49191
2078.02	1.06981
2078.87	1.11297
2079.73	-5.29235
2080.58	1.13
2081.44	1.09277
2082.29	1.08166
2083.15	-0.216099
2084	1.08517
2084.86	-4.03885
2085.71	-0.146732
2086.57	-0.183722
2087.42	1.10748
2088.28	-1.45872
2089.13	1.11441
2089.98	1.07263
2090.84	1.10091
2091.69	-0.193865
2092.54	-1.46914
2093.39	-0.173615
2094.24	2.38764
2095.1	-1.43969
2095.95	2.40826
2096.8	1.12843
2097.65	2.41729
2098.5	-0.123478
2099.35	-0.157057
2100.2	-0.166507
2101.05	-4.03439
2101.9	-0.204964
2102.75	-1.46121
2103.6	1.1222
2104.45	-2.7765
2105.3	-1.4633
2106.15	-0.207376
2107	1.1289
2107.85	-0.118398
2108.7	-0.146482
2109.55	-1.46263
2110.39	1.20331
2111.24	-0.125425
2112.09	-0.085783
2112.94	-0.15191
2113.78	2.45503
2114.63	2.44315
2115.48	-0.15916
2116.32	-1.46971
2117.17	1.17714
2118.02	2.50195
2118.86	3.77596
2119.71	-1.44601
2120.55	2.53205
2121.4	3.81072
2122.24	2.51296
2123.09	1.20977
2123.93	-1.41208
2124.78	-2.71901
2125.62	1.20895
2126.46	1.24189
2127.31	-0.0827055
2128.15	1.15912
2129	-0.0938883
2129.84	-0.0758324
2130.68	-2.72062
2131.52	-1.40084
2132.37	1.22748
2133.21	3.89694
2134.05	1.1986
2134.89	-2.72135
2135.73	-1.4056
2136.57	-0.040596
2137.41	-1.413
2138.26	2.40221
2139.1	1.15027
2139.94	0.965425
2140.78	2.13546
2141.62	1.12923
2142.46	1.00325
2143.3	-0.191672
2144.14	1.188
2144.97	0.764835
2145.81	0.776121
2146.65	1.24306
2147.49	1.57717
2148.33	-0.915861
2149.17	1.64469
2150	-0.351367
2150.77	1.30391
2151.62	-2.68083
2152.48	2.59102
2153.33	-0.019948
2154.18	-0.0195866
2155.03	-1.34977
2155.88	2.60477
2156.74	2.65615
2157.59	-1.33383
2158.44	1.28234
2159.29	-2.68537
2160.14	1.31391
2160.99	2.69384
2161.84	6.62757
2162.69	1.2839
2163.54	1.30177
2164.39	-1.3437
2165.24	5.31284
2166.08	-0.0210381
2166.93	-2.69771
2167.78	1.28747
2168.63	-0.0506639
2169.48	1.32632
2170.33	2.65109
2171.17	-1.39863
2172.02	2.62719
2172.87	2.67573
2173.71	1.31048
2174.56	1.30188
2175.41	-1.39727
2176.25	-0.0473347
2177.1	-0.0717182
2177.95	1.23716
2178.79	-0.0395393
2179.64	-0.0631723
2180.48	1.27875
2181.33	-2.76006
2182.17	1.25241
2183.02	-1.41292
2183.86	-0.041872
2184.71	-1.45591
2185.55	1.23461
2186.39	1.26837
2187.24	-1.41706
2188.08	-1.43077
2188.92	1.22385
2189.77	-1.43323
2190.61	-1.43094
2191.45	-1.42931
2192.29	1.2232
2193.13	1.27374
2193.98	-0.0837831
2194.82	-0.0959053
2195.66	-0.0962381
2196.5	1.19353
2197.34	1.23303
2198.18	-1.44968
2199.02	-1.43578
2199.86	1.18458
2200.7	2.55054
2201.54	-0.0918951
2202.38	-1.45908
2203.22	-0.142793
2204.06	-0.114967
2204.9	-1.49154
2205.74	-0.111703
2206.58	-0.130584
2207.42	-1.45994
2208.26	-1.4603
2209.09	-0.139447
2209.93	2.56108
2210.77	-0.108637
2211.61	2.57141
2212.44	2.51364
2213.28	-0.142434
2214.12	2.5645
2214.96	-0.0753832
2215.79	-0.104518
2216.63	-0.0899372
2217.46	-1.47364
2218.3	2.56117
2219.13	1.23582
2219.97	-1.46135
2220.8	-2.79575
2221.64	1.2288
2222.47	-1.4303
2223.31	2.62577
2224.14	1.20802
2224.98	-0.0695763
2225.81	-0.0747614
2226.65	1.28219
2227.48	-0.0869331
2228.31	2.63062
2229.14	2.63162
2229.98	1.25138
2230.81	-0.0858011
2231.64	1.28485
2232.47	1.27776
2233.31	-0.0908194
2234.14	1.27209
2234.97	-1.42734
2235.8	-1.43956
2236.63	-0.0788841
2237.46	-1.39915
2238.29	1.357
2239.12	1.31668
2239.95	1.29303
2240.78	1.31885
2241.61	-0.0329399
2242.44	1.30745
2243.27	-0.0227289
2244.1	1.35342
2244.93	-0.0267458
2245.76	-0.0265694
2246.59	-1.39004
2247.42	2.6903
2248.25	-0.0363798
2249.07	-0.00307655
2249.9	5.49749
2250.73	-1.41509
2251.56	-0.0339661
2252.38	1.36032
2253.21	-0.0117826
2254.04	1.30362
2254.86	2.72378
2255.69	-1.35125
2256.52	-0.0429983
2257.34	2.76861
2258.17	1.38961
2258.99	5.47149
2259.82	-1.40006
2260.64	-0.0126371
2261.47	-0.0138626
2262.29	1.3367
2263.12	-0.0235796
2263.94	-1.4095
2264.76	-1.42464
2265.59	1.3476
2266.41	-0.0416622
2267.24	-0.0396957
2268.06	-0.0829878
2268.88	4.15503
2269.7	1.34559
2270.53	-1.43515
2271.35	1.34448
2272.17	1.41198
2272.99	-0.0522413
2273.81	1.3148
2274.64	1.34172
2275.46	1.37475
2276.28	2.69601
2277.1	-1.47265
2277.92	-1.45299
2278.74	-2.86437
2279.56	1.26083
2280.38	2.69149
2281.2	-1.49518
2282.02	-1.48818
2282.84	2.6682
2283.66	5.47228
2284.48	-0.133841
2285.3	1.22316
2286.11	2.68677
2286.93	-0.148775
2287.75	-0.213473
2288.57	-0.195745
2289.39	-2.9631
2290.2	-1.61473
2291.02	-0.234439
2291.84	-0.171216
2292.65	-1.62098
2293.47	-0.276449
2294.29	1.14368
2295.1	1.20746
2295.92	-0.215029
2296.74	1.11073
2297.55	-1.62874
2298.37	1.09074
2299.18	1.13813
2300	3.91298
2300.81	-0.309673
2301.63	-0.355486
2302.44	-0.301345
2303.25	-0.330305
2304.07	1.03537
2304.88	2.41539
2305.7	2.48864
2306.51	1.03879
2307.32	1.0398
2308.14	-0.340554
2308.95	-0.369739
2309.76	-0.38358
2310.57	2.41955
2311.39	-3.19826
2312.2	0.994533
2313.01	-0.435665
2313.82	-0.406883
2314.63	-1.80417
2315.44	0.974986
2316.25	-0.444366
2317.06	-0.403337
2317.87	-0.408403
2318.68	-0.449395
2319.49	-1.83153
2320.3	2.35634
2321.11	0.947088
2321.92	2.3363
2322.73	-1.85285
2323.54	2.34069
2324.35	0.96263
2325.16	0.960697
2325.97	-0.45192
2326.77	2.38578
2327.58	3.74057
2328.39	7.97175
2329.2	0.916492
2330.01	2.32732
2330.81	0.913294
2331.62	-0.466008
2332.43	0.928676
2333.23	-0.473185
2334.04	-3.27562
2334.84	-1.83955
2335.65	-0.440072
2336.46	-0.421969
2337.26	-0.457283
2338.07	-1.80895
2338.87	1.00705
2339.68	-1.84958
2340.48	1.06049
2341.29	-0.379589
2342.09	-0.399568
2342.89	5.30861
2343.7	1.06747
2344.5	1.07243
2345.3	1.048
2346.11	-0.289912
2346.91	2.54924
2347.71	-1.76722
2348.52	1.15454
2349.32	-1.69854
2350.12	-0.298061
2350.92	-0.282695
2351.72	1.21536
2352.52	2.61506
2353.33	1.20787
2354.13	-1.6104
2354.93	-1.63043