File: Data/3-Raman/processed/bu04w-a-ff3-fi10-v_1800 (450-850nm)_633nm_edge_100%_x100_vis_lwd_h50um_45sx2_01.txt
#Acq. time (s)=	45
#Accumulations=	2
#Range (cm-¹)=	1200...2399
#Windows=	6
#Auto scanning=	Off
#Autofocus=	Off
#Macrospot=	Off
#AutoExposure=	Off
#Spike filter=	Multiple accum.
#Delay time (s)=	2
#Binning=	1
#Readout mode=	Signal
#DeNoise=	Off
#ICS correction=	On
#Dark correction=	Off
#Inst. Process=	Off
#Detector Gain=	Best Dynamic
#Detector ADC=	50 kHz EM
#Detector EM gain=	100
#Detector temperature (°C)=	-60.09
#Instrument=	LabRAM HR Evol
#Detector=	SIN-EM FIVIS
#Objective=	x100_VIS_LWD
#Grating=	1800 (450-850nm)
#ND Filter=	100%
#Laser=	633nm_Edge
#Hole=	49.98
#Temperature=	0
#Range=	Visible
#StageXY=	75x50mm Scan+
#StageZ=	Z motor
#X (µm)=	0
#Y (µm)=	0
#Z (µm)=	4.4
#Full time(mm:ss)=	9:31
#Project=	21_11_22
#Sample=	BU04w
#Site=
#Title=	BU04w-A-FF3-FI10-V_1800 (450-850nm)_633nm_Edge_100%_x100_VIS_LWD_H50um_45sX2
#Remark=
#Date=	22.11.2021 11:53
#Acquired=	22.11.2021 11:53:53
#Base:Fit=	16.12.2021 16:15:35
#Base:Fit=	16.12.2021 16:25:17
#Base:Sub=	16.12.2021 16:25:18
1201.04	0.581055
1202.08	4.34897
1203.11	6.96448
1204.14	0.839508
1205.17	0.544373
1206.2	-2.15753
1207.24	0.200531
1208.27	-1.23807
1209.3	0.545929
1210.33	-1.39194
1211.36	0.862457
1212.39	1.43182
1213.42	1.51151
1214.45	-2.45642
1215.48	2.43179
1216.51	-1.98615
1217.54	-0.8815
1218.56	-1.26245
1219.59	-0.543915
1220.62	1.0907
1221.65	-3.46133
1222.68	-2.39374
1223.7	0.256134
1224.73	2.87946
1225.76	-0.827759
1226.78	-1.56366
1227.81	0.311523
1228.84	-1.53079
1229.86	-0.061615
1230.89	2.31583
1231.91	2.28253
1232.94	3.98022
1233.96	2.4935
1234.99	5.92456
1236.01	0.756317
1237.03	3.15442
1238.06	2.63724
1239.08	3.06027
1240.1	3.7471
1241.13	3.42038
1242.15	2.21249
1243.17	0.502594
1244.19	1.88324
1245.21	3.80548
1246.24	3.7059
1247.26	4.60065
1248.28	6.01547
1249.3	5.0058
1250.32	3.37094
1251.34	3.58817
1252.36	3.11484
1253.38	5.61725
1254.4	7.11731
1255.42	4.63019
1256.44	4.6434
1257.46	3.34503
1258.47	9.87137
1259.49	2.51965
1260.51	6.66846
1261.53	7.1239
1262.55	4.30576
1263.56	13.0732
1264.58	4.50378
1265.6	6.84155
1266.61	11.41
1267.63	6.36667
1268.65	10.2952
1269.66	3.64026
1270.68	1.90735
1271.69	4.71967
1272.71	4.8511
1273.72	8.48779
1274.74	4.86334
1275.75	6.28561
1276.76	6.69049
1277.78	3.54257
1278.79	4.03186
1279.8	5.27121
1280.82	6.2774
1281.83	17.8466
1282.84	40.2372
1283.85	119.164
1284.86	85.4968
1285.88	11.6788
1286.89	10.1654
1287.9	1.13702
1288.91	0.900635
1289.92	2.52924
1290.93	0.380829
1291.94	-2.07175
1292.95	2.60941
1293.96	1.74316
1294.97	5.35373
1295.98	1.39905
1296.99	1.76532
1297.99	-0.119293
1299	-2.11893
1300.01	4.15079
1301.02	-1.16428
1302.03	-1.18069
1303.03	0.58316
1304.04	1.13739
1305.05	1.22452
1306.05	3.56708
1307.06	-3.72656
1308.06	0.568909
1309.07	0.31131
1310.07	-3.61282
1311.08	10.3875
1312.08	0.838989
1313.09	1.742
1314.09	4.28696
1315.1	-1.59674
1316.1	-0.0368958
1317.1	2.27072
1318.11	3.62042
1319.11	-0.451965
1320.11	-1.03244
1321.12	-2.36404
1322.12	2.26492
1323.12	1.70392
1324.12	1.94479
1325.12	-0.359222
1326.13	2.48004
1327.13	2.86169
1328.13	3.92691
1329.13	2.39832
1330.13	4.49911
1331.13	3.67361
1332.13	3.69632
1333.13	4.0267
1334.13	5.42648
1335.13	2.54074
1336.12	7.78546
1337.12	3.93393
1338.12	5.18753
1339.12	2.24173
1340.12	1.75397
1341.11	2.1727
1342.11	4.69342
1343.11	6.75211
1344.1	1.88205
1345.1	4.1582
1346.1	2.2128
1347.09	3.8862
1348.09	7.90924
1349.08	4.69781
1350.08	7.37704
1351.07	5.40643
1352.07	8.80234
1353.06	3.73633
1354.06	2.59991
1355.05	9.19928
1356.04	5.01697
1357.04	7.83383
1358.03	7.45349
1359.02	6.65613
1360.02	7.14319
1361.01	7.53854
1362	6.54584
1362.99	8.69174
1363.98	8.70502
1364.98	10.9221
1365.97	10.2842
1366.96	5.60901
1367.95	9.45297
1368.94	5.12924
1369.93	11.0262
1370.92	6.98279
1371.91	10.3697
1372.9	3.20374
1373.89	11.5176
1374.87	1.77771
1375.86	6.00589
1376.85	9.49832
1377.84	6.64133
1378.83	9.4624
1379.81	20.0286
1380.8	12.2969
1381.79	5.94827
1382.78	12.1199
1383.76	13.5813
1384.75	13.576
1385.73	21.893
1386.72	77.2166
1387.7	316.462
1388.69	39.5927
1389.68	11.809
1390.66	8.901
1391.64	3.47214
1392.63	8.38391
1393.61	3.48367
1394.6	9.95364
1395.58	7.12234
1396.56	6.79309
1397.55	1.37943
1398.53	1.82892
1399.51	3.07483
1400.49	1.22324
1401.47	3.38745
1402.46	4.83749
1403.44	5.99292
1404.42	7.28983
1405.4	4.07541
1406.38	4.47028
1407.36	4.68405
1408.34	7.11084
1409.32	13.5999
1410.3	5.92929
1411.28	7.3063
1412.26	14.2466
1413.24	5.70758
1414.22	1.26602
1415.19	6.14789
1416.17	4.56116
1417.15	3.4166
1418.13	10.5014
1419.11	3.336
1420.08	2.35306
1421.06	-0.521362
1422.04	3.00159
1423.01	6.85284
1423.99	1.97791
1424.97	9.2796
1425.94	1.8266
1426.92	5.17776
1427.89	3.44116
1428.87	4.68689
1429.84	7.16086
1430.82	2.93008
1431.79	0.922272
1432.76	0.130737
1433.74	3.40964
1434.71	9.48611
1435.68	0.949921
1436.66	5.89111
1437.63	6.18668
1438.6	8.09491
1439.57	4.38715
1440.54	-0.06427
1441.52	8.80911
1442.49	3.92545
1443.46	2.38809
1444.43	6.16156
1445.4	1.39603
1446.37	-2.16327
1447.34	5.06805
1448.31	3.85809
1449.28	1.4801
1450.25	2.48288
1451.22	2.73068
1452.19	3.60699
1453.16	3.58578
1454.12	2.86569
1455.09	5.22485
1456.06	2.70264
1457.03	1.2316
1457.99	8.58441
1458.96	1.57559
1459.93	-0.155823
1460.9	2.88651
1461.86	2.84937
1462.83	4.96524
1463.79	3.51346
1464.76	2.07547
1465.72	2.66522
1466.69	3.41235
1467.59	-0.822205
1468.57	3.54227
1469.56	2.78046
1470.53	4.82153
1471.51	1.33755
1472.49	0.664795
1473.47	-0.235535
1474.45	3.44681
1475.43	-1.0199
1476.41	8.95801
1477.39	1.19901
1478.36	18.4085
1479.34	2.35181
1480.32	5.64346
1481.3	0.643097
1482.27	0.739594
1483.25	-0.787994
1484.23	0.698853
1485.2	3.39548
1486.18	-2.45795
1487.15	-0.0513
1488.13	-1.70544
1489.1	2.91495
1490.08	1.11868
1491.06	-1.06992
1492.03	-0.0891724
1493	-0.282227
1493.98	0.0775146
1494.95	2.65396
1495.92	2.05051
1496.9	-2.14365
1497.87	-0.740814
1498.84	2.76056
1499.82	3.84698
1500.79	-2.49341
1501.76	-1.43005
1502.73	1.56677
1503.7	0.165405
1504.68	1.25049
1505.65	-0.39502
1506.62	1.65134
1507.59	3.46198
1508.56	4.52188
1509.53	-0.700836
1510.5	0.439148
1511.47	1.36636
1512.44	-0.892822
1513.4	1.21204
1514.37	-1.05075
1515.34	0.645233
1516.31	-0.326813
1517.28	0.22699
1518.25	0.248352
1519.21	0.151245
1520.18	1.71237
1521.15	3.81995
1522.12	2.12408
1523.08	6.2103
1524.05	0.0768738
1525.02	3.0679
1525.98	-1.09763
1526.95	-1.46063
1527.91	-1.8938
1528.88	1.05231
1529.84	-0.248199
1530.81	0.980408
1531.77	4.47617
1532.74	0.0812988
1533.7	-0.163055
1534.66	3.77054
1535.63	-0.556915
1536.59	10.8133
1537.55	5.75949
1538.52	5.00201
1539.48	0.265991
1540.44	0.516357
1541.4	0.294189
1542.36	-0.162018
1543.33	5.24789
1544.29	6.10257
1545.25	3.89658
1546.21	3.32321
1547.17	2.9646
1548.13	2.78168
1549.09	7.77167
1550.05	-1.67053
1551.01	4.6705
1551.97	3.81506
1552.93	5.24149
1553.89	3.10715
1554.84	3.96783
1555.8	6.86371
1556.76	7.60486
1557.72	2.64584
1558.68	-0.209839
1559.63	1.23135
1560.59	6.39685
1561.55	3.85269
1562.5	3.95358
1563.46	9.44559
1564.42	6.33246
1565.37	2.70758
1566.33	0.44046
1567.28	4.40503
1568.24	1.78061
1569.19	5.07642
1570.15	0.427765
1571.1	5.84201
1572.06	4.69836
1573.01	-0.0569763
1573.96	5.58337
1574.92	6.42398
1575.87	4.60559
1576.82	-2.85822
1577.78	0.00280762
1578.73	-0.863708
1579.68	-0.476563
1580.63	2.70816
1581.59	1.72208
1582.54	-0.194489
1583.49	-1.58115
1584.44	2.07953
1585.39	2.64764
1586.34	-0.731018
1587.29	0.928925
1588.24	1.39935
1589.19	3.24359
1590.14	-0.310822
1591.09	0.227722
1592.04	0.364075
1592.99	-1.74884
1593.94	-2.55295
1594.88	2.19302
1595.83	-0.605103
1596.78	-1.39938
1597.73	-2.82166
1598.68	-1.7467
1599.62	-2.21683
1600.57	2.2731
1601.52	1.85391
1602.46	0.560913
1603.41	4.39487
1604.35	3.61084
1605.3	-1.89957
1606.25	0.81366
1607.19	6.68973
1608.14	1.58432
1609.08	0.590088
1610.03	5.80902
1610.97	-1.33401
1611.91	-1.47723
1612.86	-1.42477
1613.8	-0.427826
1614.75	0.89856
1615.69	1.87018
1616.63	0.809967
1617.57	1.53961
1618.52	0.694824
1619.46	1.24707
1620.4	5.86212
1621.34	4.79669
1622.28	0.940308
1623.22	-0.0952759
1624.16	1.72302
1625.11	4.87445
1626.05	5.7041
1626.99	0.656281
1627.93	5.18137
1628.87	7.00848
1629.8	0.0212402
1630.74	5.44293
1631.68	4.02875
1632.62	4.63602
1633.56	4.05807
1634.5	3.612
1635.44	1.45981
1636.37	9.52625
1637.31	2.6069
1638.25	2.83972
1639.19	4.74887
1640.12	5.88483
1641.06	5.08646
1642	5.64801
1642.93	7.3674
1643.87	5.83182
1644.8	4.27039
1645.74	5.98441
1646.67	-0.0268555
1647.61	3.08661
1648.54	4.59567
1649.48	7.08411
1650.41	5.97873
1651.35	6.74985
1652.28	6.77289
1653.21	0.727539
1654.15	8.34686
1655.08	4.82703
1656.01	1.85083
1656.94	7.06464
1657.88	10.2227
1658.81	6.60242
1659.74	4.83545
1660.67	5.83273
1661.6	8.25311
1662.53	10.2684
1663.46	3.63565
1664.39	5.18646
1665.33	6.53851
1666.26	4.89151
1667.18	2.97757
1668.11	6.22195
1669.04	4.95816
1669.97	4.95984
1670.9	4.6041
1671.83	5.6152
1672.76	4.13675
1673.69	6.61398
1674.61	6.79529
1675.54	5.56488
1676.47	3.88907
1677.4	1.42923
1678.32	2.84436
1679.25	4.2056
1680.18	5.31573
1681.1	3.52075
1682.03	12.633
1682.96	0.428894
1683.88	-0.925903
1684.81	3.1387
1685.73	1.42691
1686.66	5.34534
1687.58	2.41916
1688.5	-1.67291
1689.43	-0.512695
1690.35	0.177246
1691.28	2.14673
1692.2	2.15198
1693.12	3.82944
1694.05	-0.33429
1694.97	1.21014
1695.89	1.14175
1696.81	0.594666
1697.74	-0.565155
1698.66	0.890625
1699.58	2.15948
1700.5	3.14114
1701.42	-0.253998
1702.34	1.10437
1703.26	-0.529877
1704.18	0.678955
1705.1	4.04956
1705.94	-0.223846
1706.88	3.05963
1707.81	-0.425903
1708.74	4.35342
1709.68	6.10596
1710.61	-2.94397
1711.55	0.175323
1712.48	-1.70682
1713.41	5.67215
1714.35	0.860229
1715.28	-1.33517
1716.21	-2.94238
1717.14	-0.327789
1718.08	-4.26923
1719.01	4.05151
1719.94	-1.63913
1720.87	2.06345
1721.8	-1.71274
1722.73	1.26624
1723.66	2.53574
1724.6	1.15158
1725.53	3.57861
1726.45	-0.617249
1727.38	2.29495
1728.31	0.877686
1729.24	0.85321
1730.17	1.78275
1731.1	3.32629
1732.03	0.488373
1732.96	2.55222
1733.89	1.95532
1734.82	-0.721039
1735.74	0.531158
1736.67	-5.08127
1737.6	7.32883
1738.52	2.51578
1739.45	-1.28598
1740.38	0.532654
1741.3	3.57132
1742.23	1.87344
1743.16	-3.19345
1744.08	7.95468
1745.01	1.12607
1745.93	0.175659
1746.86	0.979309
1747.78	2.24225
1748.71	1.10373
1749.63	-1.24066
1750.55	4.71164
1751.48	1.10696
1752.4	1.00604
1753.33	3.10394
1754.25	4.60544
1755.17	1.30063
1756.09	4.34744
1757.02	2.09842
1757.94	2.20126
1758.86	2.13855
1759.78	-1.37509
1760.7	-1.26767
1761.62	1.31577
1762.54	4.61163
1763.47	1.8558
1764.39	3.7265
1765.31	0.214172
1766.23	2.14084
1767.15	-0.945923
1768.07	5.55093
1768.99	-0.648712
1769.9	2.73254
1770.82	-2.7663
1771.74	1.04721
1772.66	8.18134
1773.58	-1.05157
1774.5	3.84045
1775.41	0.142822
1776.33	-2.75537
1777.25	-1.94083
1778.17	4.77338
1779.08	6.29309
1780	3.76932
1780.92	0.900421
1781.83	0.275452
1782.75	3.22208
1783.66	1.63983
1784.58	-2.47153
1785.49	1.47302
1786.41	1.0477
1787.32	1.58188
1788.24	2.73993
1789.15	-1.18378
1790.07	-5.48959
1790.98	-3.15823
1791.89	-0.327606
1792.81	-1.99881
1793.72	5.328
1794.63	-1.52142
1795.54	0.442322
1796.46	-0.366058
1797.37	-0.342743
1798.28	-2.5509
1799.19	-0.385834
1800.1	3.04584
1801.02	-2.12231
1801.93	3.63132
1802.84	5.03754
1803.75	2.71033
1804.66	4.55957
1805.57	4.18552
1806.48	0.302979
1807.39	2.78235
1808.3	0.644714
1809.21	3.76151
1810.12	0.78717
1811.02	3.58032
1811.93	3.21286
1812.84	-0.260468
1813.75	0.70636
1814.66	3.83511
1815.56	-1.22961
1816.47	-1.35388
1817.38	-1.98679
1818.29	-2.69394
1819.19	-0.0962219
1820.1	-0.864594
1821.01	1.44083
1821.91	-1.00461
1822.82	0.537292
1823.72	1.61096
1824.63	1.77045
1825.53	1.57294
1826.44	7.23636
1827.34	7.09775
1828.25	6.48764
1829.15	1.98572
1830.05	6.85681
1830.96	0.519043
1831.86	4.39844
1832.76	4.8302
1833.67	1.75656
1834.57	4.22202
1835.47	3.72549
1836.37	4.5163
1837.28	-0.58905
1838.18	2.31384
1839.08	3.21939
1839.98	3.42575
1840.88	10.7562
1841.78	2.18817
1842.68	-0.685944
1843.58	11.0131
1844.48	7.28635
1845.38	1.4371
1846.28	4.0831
1847.18	2.3201
1848.08	-2.02747
1848.98	2.00296
1849.88	6.3703
1850.78	1.74518
1851.68	7.67996
1852.57	3.64706
1853.47	3.03683
1854.37	1.76373
1855.27	2.20441
1856.16	7.38013
1857.06	4.64496
1857.96	6.29584
1858.86	6.03488
1859.75	4.0939
1860.65	6.06479
1861.54	5.77985
1862.44	4.53323
1863.33	3.50906
1864.23	6.22067
1865.12	8.08908
1866.02	2.36884
1866.91	4.67566
1867.81	5.53247
1868.7	3.31848
1869.59	9.577
1870.49	2.80804
1871.38	5.75879
1872.27	1.29059
1873.17	5.86859
1874.06	7.70929
1874.95	2.00946
1875.84	1.66138
1876.74	2.75702
1877.63	-0.554932
1878.52	3.47888
1879.41	-1.34409
1880.3	3.94745
1881.19	5.48212
1882.08	3.73499
1882.97	5.55643
1883.86	7.44287
1884.75	7.76016
1885.64	2.9184
1886.53	0.441132
1887.42	10.5891
1888.31	1.10553
1889.2	4.99902
1890.09	7.60922
1890.98	1.53284
1891.86	2.50949
1892.75	2.052
1893.64	-0.617737
1894.53	2.22104
1895.41	10.3134
1896.3	9.5744
1897.19	6.01941
1898.07	5.08282
1898.96	4.50775
1899.85	4.5939
1900.73	-0.0829468
1901.62	3.69901
1902.5	2.57828
1903.39	7.72522
1904.27	4.62088
1905.16	8.3689
1906.04	9.1106
1906.92	8.75256
1907.81	8.05286
1908.69	1.28339
1909.58	4.12277
1910.46	3.88333
1911.34	6.71542
1912.23	10.3949
1913.11	6.58514
1913.99	7.22382
1914.87	2.82266
1915.75	4.3382
1916.64	9.14343
1917.52	2.95343
1918.4	10.5329
1919.28	5.39511
1920.16	1.05499
1921.04	6.38699
1921.92	3.85294
1922.8	3.38977
1923.68	4.70917
1924.56	6.13327
1925.44	4.67862
1926.32	9.58194
1927.2	5.35217
1928.08	4.4212
1928.95	7.35376
1929.83	4.87198
1930.64	8.60028
1931.53	3.75546
1932.43	6.90472
1933.32	8.61835
1934.21	0.73114
1935.1	10.1967
1935.99	12.0952
1936.89	4.59045
1937.78	3.94217
1938.67	16.6796
1939.56	10.5819
1940.45	10.406
1941.34	4.06619
1942.23	7.33456
1943.12	6.18597
1944.01	9.8436
1944.9	5.9696
1945.79	8.73111
1946.68	9.138
1947.57	9.95831
1948.46	6.33301
1949.35	5.79742
1950.23	6.20654
1951.12	7.04831
1952.01	5.80771
1952.9	10.5645
1953.79	7.7001
1954.67	7.72906
1955.56	2.98093
1956.45	12.0018
1957.33	4.41367
1958.22	10.1185
1959.1	7.69437
1959.99	3.96371
1960.88	4.3761
1961.76	5.51846
1962.65	9.17822
1963.53	5.94437
1964.42	4.13629
1965.3	2.13913
1966.19	7.62292
1967.07	9.45572
1967.95	8.23941
1968.84	6.95102
1969.72	3.42142
1970.6	5.401
1971.49	4.0448
1972.37	4.95502
1973.25	5.716
1974.13	4.21036
1975.02	8.20477
1975.9	6.75677
1976.78	2.45673
1977.66	-0.126251
1978.54	3.73337
1979.42	0.568268
1980.3	5.08316
1981.18	3.21542
1982.06	9.95828
1982.94	3.33765
1983.82	9.42703
1984.7	5.08972
1985.58	3.56293
1986.46	1.95163
1987.34	3.72031
1988.22	6.76086
1989.1	4.06519
1989.98	4.84573
1990.85	5.78555
1991.73	7.96777
1992.61	2.7077
1993.49	2.66174
1994.36	0.558014
1995.24	1.35318
1996.12	4.22748
1996.99	5.21017
1997.87	2.04547
1998.75	4.90393
1999.62	0.950226
2000.5	0.835968
2001.37	3.80746
2002.25	0.848663
2003.12	4.09119
2004	1.54553
2004.87	3.57919
2005.75	5.89676
2006.62	5.5235
2007.5	0.212189
2008.37	2.51288
2009.24	3.60449
2010.12	3.68924
2010.99	1.73392
2011.86	-1.09686
2012.73	1.41376
2013.61	1.23871
2014.48	-0.916565
2015.35	3.16116
2016.22	1.55692
2017.09	-1.54373
2017.96	0.0922852
2018.84	-1.62112
2019.71	-5.10727
2020.58	-1.22977
2021.45	-1.11694
2022.32	-2.55325
2023.19	-2.74985
2024.06	2.13184
2024.93	1.47614
2025.8	4.79977
2026.67	1.63281
2027.53	-4.27466
2028.4	2.70004
2029.27	-1.31821
2030.14	-1.08929
2031.01	1.31372
2031.87	5.07507
2032.74	-1.13763
2033.61	-0.426788
2034.48	0.856689
2035.34	2.72095
2036.21	1.34219
2037.08	3.42844
2037.94	-0.690063
2038.81	-0.996338
2039.67	2.64932
2040.54	4.73471
2041.41	-0.386414
2042.27	2.81592
2043.13	-2.58786
2044	1.81567
2044.86	-2.74393
2045.73	1.82684
2046.59	4.19733
2047.46	-0.538544
2048.32	-0.865509
2049.18	-3.4007
2050.05	0.384613
2050.91	3.5188
2051.77	3.39114
2052.63	-2.9787
2053.49	1.4787
2054.36	0.690155
2055.22	-2.70987
2056.08	-2.07932
2056.94	0.00762939
2057.8	6.41901
2058.66	0.386353
2059.52	1.54919
2060.39	3.54196
2061.24	-0.811981
2062.1	-0.0948181
2062.97	3.00684
2063.83	3.45511
2064.68	-0.0367737
2065.54	5.30807
2066.4	0.0336609
2067.26	3.23453
2068.12	-0.0375061
2068.98	0.461884
2069.84	1.94778
2070.69	-0.479767
2071.55	3.21655
2072.41	3.4906
2073.27	6.06732
2074.12	-1.07498
2074.98	5.08063
2075.84	2.03302
2076.69	3.54807
2077.55	-1.55359
2078.4	8.32144
2079.26	1.3999
2080.11	3.46307
2080.97	9.06219
2081.82	1.9588
2082.68	4.43518
2083.53	2.31592
2084.39	3.05939
2085.24	4.25778
2086.1	4.56943
2086.95	4.15793
2087.8	-2.17126
2088.66	1.8577
2089.51	5.95645
2090.36	8.17102
2091.22	-0.877441
2092.07	2.79825
2092.92	0.994293
2093.77	5.56699
2094.62	-1.28214
2095.47	5.75311
2096.33	3.02902
2097.18	2.61966
2098.03	0.250153
2098.88	5.00342
2099.73	1.48944
2100.58	2.47339
2101.43	1.60602
2102.28	7.93466
2103.13	0.888214
2103.98	4.54306
2104.83	5.94727
2105.67	3.17404
2106.52	3.26123
2107.37	1.97888
2108.22	0.617157
2109.07	6.69247
2109.92	4.38327
2110.76	2.88928
2111.61	5.90085
2112.46	6.51917
2113.31	6.19794
2114.15	1.99121
2115	9.71158
2115.84	2.51862
2116.69	4.6492
2117.54	3.71188
2118.38	5.49646
2119.23	5.12637
2120.07	5.40466
2120.92	4.07889
2121.76	17.9668
2122.61	5.52863
2123.45	2.93472
2124.29	15.571
2125.14	5.31378
2125.98	6.98315
2126.83	6.63956
2127.67	12.7763
2128.51	8.45782
2129.35	7.13864
2130.2	2.61725
2131.04	7.14783
2131.88	6.47052
2132.72	5.31229
2133.57	10.3415
2134.41	6.73831
2135.25	5.08167
2136.09	6.49265
2136.93	7.38684
2137.77	8.01416
2138.61	5.72934
2139.45	7.91888
2140.29	5.40112
2141.13	7.6311
2141.97	6.24982
2142.81	8.22778
2143.65	7.603
2144.49	3.40088
2145.33	6.44739
2146.16	1.70874
2147.01	9.67023
2147.86	7.05154
2148.72	4.034
2149.57	5.96768
2150.42	2.85242
2151.27	0.614746
2152.12	7.94852
2152.98	5.44775
2153.83	7.30328
2154.68	28.9053
2155.53	6.44919
2156.38	7.15268
2157.23	8.33963
2158.08	5.95236
2158.93	7.34705
2159.78	8.30734
2160.63	5.94296
2161.48	7.77884
2162.33	4.49521
2163.18	7.85367
2164.03	6.14471
2164.88	5.2659
2165.73	6.45047
2166.58	2.95126
2167.42	4.06161
2168.27	3.43207
2169.12	3.41901
2169.97	7.28665
2170.81	5.32037
2171.66	0.705627
2172.51	3.45605
2173.35	3.03174
2174.2	3.24222
2175.05	0.40274
2175.89	8.86505
2176.74	4.15613
2177.58	4.4064
2178.43	1.55643
2179.27	5.48044
2180.12	4.53452
2180.96	3.18802
2181.81	3.0632
2182.65	4.74487
2183.5	3.54205
2184.34	6.15845
2185.18	2.29669
2186.03	7.55978
2186.87	7.21207
2187.71	6.02402
2188.56	7.24051
2189.4	0.102936
2190.24	1.96136
2191.08	6.81927
2191.93	1.06799
2192.77	0.920685
2193.61	3.93317
2194.45	-1.80569
2195.29	-0.149109
2196.13	-1.90485
2196.97	2.1084
2197.81	0.842133
2198.65	1.89188
2199.49	2.56784
2200.33	3.9502
2201.17	0.417908
2202.01	-1.81711
2202.85	1.15414
2203.69	-0.350433
2204.53	-2.99835
2205.37	0.931488
2206.21	-1.99185
2207.04	4.76654
2207.88	-3.832
2208.72	4.70834
2209.56	2.28592
2210.4	6.30463
2211.23	0.0928955
2212.07	1.05695
2212.91	-1.40811
2213.74	7.97833
2214.58	4.04877
2215.41	2.25345
2216.25	-1.04041
2217.09	-0.161224
2217.92	-0.590576
2218.76	9.19916
2219.59	-0.0489197
2220.43	3.25241
2221.26	-1.26794
2222.1	8.19678
2222.93	1.73959
2223.76	0.238281
2224.6	-2.27316
2225.43	-0.0811768
2226.26	4.63385
2227.1	-0.536713
2227.93	3.51587
2228.76	-2.67288
2229.6	-4.71921
2230.43	4.49911
2231.26	1.08032
2232.09	1.45758
2232.92	3.3714
2233.76	5.46069
2234.59	0.328644
2235.42	-0.489624
2236.25	1.68756
2237.08	1.70328
2237.91	1.02591
2238.74	1.87036
2239.57	1.3226
2240.4	6.63916
2241.23	2.07816
2242.06	6.27155
2242.89	0.875854
2243.72	2.66
2244.54	0.583496
2245.37	4.29233
2246.2	3.55734
2247.03	10.1005
2247.86	0.932068
2248.68	0.0692444
2249.51	5.07635
2250.34	1.4823
2251.17	3.43121
2251.99	2.76254
2252.82	4.8219
2253.65	1.41272
2254.47	-0.595367
2255.3	2.60535
2256.12	7.83765
2256.95	5.0798
2257.77	5.84897
2258.6	11.8586
2259.42	5.89258
2260.25	8.76556
2261.07	7.5372
2261.9	7.81271
2262.72	1.62512
2263.54	4.93689
2264.37	2.75049
2265.19	4.14706
2266.02	2.21646
2266.84	6.15381
2267.66	0.474884
2268.48	4.88373
2269.31	2.20453
2270.13	8.55212
2270.95	1.15137
2271.77	5.66412
2272.59	4.68243
2273.42	-1.28482
2274.24	7.02997
2275.06	1.40121
2275.88	2.76923
2276.7	1.7872
2277.52	3.84265
2278.34	5.93506
2279.16	4.96277
2279.98	9.64883
2280.8	6.34866
2281.62	4.57111
2282.44	12.9255
2283.25	6.42596
2284.07	1.15182
2284.89	5.72723
2285.71	10.3048
2286.53	0.765472
2287.35	1.92984
2288.16	1.30182
2288.98	4.28018
2289.8	-1.41843
2290.61	9.3129
2291.43	3.37585
2292.25	0.154114
2293.06	3.67041
2293.88	0.523712
2294.7	0.657196
2295.51	1.20117
2296.33	3.9386
2297.14	0.0274048
2297.96	2.31436
2298.77	5.18716
2299.59	-0.528351
2300.4	0.855804
2301.22	1.14972
2302.03	1.14218
2302.84	3.44327
2303.66	-0.232086
2304.47	1.25064
2305.28	-0.0344238
2306.1	3.62231
2306.91	-5.73978
2307.72	-2.54565
2308.53	-4.92154
2309.35	1.017
2310.16	5.26697
2310.97	-1.64981
2311.78	-1.09225
2312.59	1.36115
2313.4	-3.77301
2314.22	-5.70508
2315.03	1.26376
2315.84	2.54504
2316.65	3.08044
2317.46	0.468933
2318.27	-0.0981445
2319.08	-6.52747
2319.89	6.20963
2320.69	-1.80389
2321.5	-0.398041
2322.31	0.994476
2323.12	1.84656
2323.93	-0.647736
2324.74	5.83661
2325.55	0.0939331
2326.35	2.43497
2327.16	2.70914
2327.97	7.70386
2328.78	5.55054
2329.58	-2.05841
2330.39	-3.0329
2331.2	-2.33716
2332	7.43994
2332.81	-2.2381
2333.61	2.01553
2334.42	-2.46317
2335.23	-0.236664
2336.03	-0.480591
2336.84	-0.264374
2337.64	-0.615631
2338.45	1.72449
2339.25	-1.09717
2340.05	1.09357
2340.86	0.179016
2341.66	1.14484
2342.47	-1.77847
2343.27	-1.56009
2344.07	0.796783
2344.87	-1.98663
2345.68	1.49899
2346.48	-2.07968
2347.28	0.797241
2348.08	3.71268
2348.89	3.06323
2349.69	-0.242157
2350.49	1.00943
2351.29	-0.744507
2352.09	3.93005
2352.89	-3.99161
2353.71	3.68369
2354.52	-2.33838
2355.34	4.22534
2356.15	-0.0643311
2356.96	-2.79672
2357.78	3.23093
2358.59	4.30215
2359.41	0.115509
2360.22	2.77484
2361.03	-1.91953
2361.85	0.305267
2362.66	-0.390259
2363.47	6.29486
2364.29	2.88242
2365.1	4.86871
2365.91	2.26263
2366.72	1.16025
2367.54	-4.35599
2368.35	1.5567
2369.16	3.05704
2369.97	1.66653
2370.78	0.484528
2371.59	5.96616
2372.4	-1.10452
2373.21	2.6196
2374.02	-1.55597
2374.83	4.65536
2375.64	0.700073
2376.45	0.829895
2377.26	1.61942
2378.07	-3.33282
2378.88	-1.57285
2379.69	5.88043
2380.5	-1.63547
2381.31	1.67352
2382.12	2.22525
2382.92	-4.23123
2383.73	3.89212
2384.54	2.58698
2385.35	2.88635
2386.15	-0.282288
2386.96	-0.345276
2387.77	3.92865
2388.57	1.25928
2389.38	0.71698
2390.19	3.71066
2390.99	2.09576
2391.8	-3.56897
2392.6	0.58728
2393.41	-1.95026
2394.22	2.70206
2395.02	6.19141
2395.83	-1.63297
2396.63	0.402618
2397.44	2.70566
2398.24	0.39325
2399.04	-2.87274
2399.85	-4.22458
2399.98	0.448059