File: Data/3-Raman/processed/bu19w-e-ff11-fi06-l_150 (500nm)_633nm_edge_100%_x100_vis_h50um_60sx2_01_0.txt
#Acq. time (s)=	60
#Accumulations=	2
#Range (cm-¹)=	100...4000
#Windows=	1
#Auto scanning=	Off
#Autofocus=	Off
#Macrospot=	Off
#AutoExposure=	Off
#Spike filter=	Multiple accum.
#Delay time (s)=	2
#Binning=	1
#Readout mode=	Signal
#DeNoise=	Off
#ICS correction=	On
#Dark correction=	Off
#Inst. Process=	Off
#Detector Gain=	Best Dynamic
#Detector ADC=	50 kHz HS
#Detector temperature (°C)=	-60.09
#Instrument=	LabRAM HR Evol
#Detector=	SIN-EM FIVIS
#Objective=	x100_VIS
#Grating=	150 (500nm)
#ND Filter=	100%
#Laser=	633nm_Edge
#Hole=	49.98
#Temperature=	0
#Range=	Visible
#StageXY=	75x50mm Scan+
#StageZ=	Z motor
#X (µm)=	0
#Y (µm)=	0
#Z (µm)=	-271.9
#Full time(mm:ss)=	2:04
#Project=	21_11_04
#Sample=	BU19w
#Site=
#Title=	BU19w-E-FF11-FI06-L_150 (500nm)_633nm_Edge_100%_x100_VIS_H50um_60sX2
#Remark=
#Date=	04.11.2021 15:55
#Acquired=	04.11.2021 15:55:14
#Base:Fit=	16.12.2021 17:39:50
#Base:Edit=	16.12.2021 17:52:51
#Base:Edit=	16.12.2021 17:52:51
#Base:Edit=	16.12.2021 17:52:52
#Base:Edit=	16.12.2021 17:52:52
#Base:Edit=	16.12.2021 17:52:54
#Base:Edit=	16.12.2021 17:52:56
#Base:Edit=	16.12.2021 17:52:56
#Base:Sub=	16.12.2021 17:52:59
102.881	260.4
109.397	225.423
115.908	189.952
122.414	189.227
128.914	184.159
135.409	195.684
141.898	199.84
148.383	192.988
154.861	241.177
161.335	288.878
167.801	132.773
174.264	65.8993
180.721	51.8823
187.173	23.6168
193.62	15.6441
200.061	14.7268
206.496	3.81212
212.926	9.2794
219.352	79.8002
225.772	252.299
232.185	388.118
238.595	209.401
244.999	75.0189
251.397	81.492
257.791	108.93
264.178	101.447
270.561	95.1035
276.939	140.144
283.31	114.08
289.678	47.2843
296.039	30.7683
302.396	77.7426
308.746	161.528
315.093	413.346
321.433	699.918
327.768	408.282
334.099	190.487
340.423	121.785
346.743	117.213
353.058	128.633
359.367	161.607
365.671	103.281
371.971	40.4038
378.265	14.2529
384.553	0.412659
390.837	-0.0314789
397.116	0.632874
403.389	11.8098
409.657	22.037
415.92	50.1159
422.178	71.5632
428.431	138.785
434.678	145.939
440.921	146.424
447.158	164.643
453.391	186.415
459.618	138.265
465.84	69.1542
472.057	46.8593
478.27	57.3412
484.477	55.6813
490.679	60.5173
496.876	81.1919
503.068	107.482
509.255	141.259
515.436	166.721
521.613	154.06
527.785	150.849
533.952	134.623
540.113	103.189
546.27	82.7021
552.423	81.729
558.568	59.8392
564.711	41.396
570.848	46.3478
576.979	56.7206
583.107	80.1201
589.228	108.174
595.345	133.565
601.458	138.77
607.565	153.615
613.667	150.855
619.764	152.021
625.856	92.1094
631.944	87.1699
638.026	78.044
644.104	65.7618
650.177	89.1997
656.244	80.4369
662.308	51.0758
668.365	25.6091
674.418	8.84758
680.467	14.5181
686.511	4.40215
692.549	0.898674
698.582	6.75132
704.611	5.99799
710.635	7.01849
716.655	-1.6142
722.669	10.4178
728.679	4.48819
734.683	2.25816
740.683	-1.85334
746.678	2.45545
752.669	7.72737
758.654	8.39899
764.635	12.0677
770.611	13.0156
776.582	9.24282
782.549	7.22337
788.511	0.391045
794.466	13.2781
800.419	7.20143
806.366	13.282
812.309	17.4024
818.247	19.5382
824.18	18.8059
830.108	15.279
836.033	28.7773
841.952	28.448
847.865	29.0754
853.776	35.3878
859.681	48.352
865.58	66.1099
871.476	74.4383
877.366	91.125
883.253	84.0032
889.134	107.102
895.012	89.287
900.883	85.496
906.751	64.5967
912.614	83.3196
918.473	90.766
924.326	106.883
930.174	120.448
936.019	154.959
941.859	207.069
947.693	259.657
953.525	296.467
959.35	302.71
965.171	312.487
970.988	415.106
976.801	564.413
982.608	641.663
988.411	558.371
994.209	397.774
1000	353.294
1005.79	351.112
1011.58	383.791
1017.36	431.17
1023.13	391.921
1028.9	284.955
1034.67	227.509
1040.43	210.311
1046.19	186.239
1051.94	172.495
1057.69	144.93
1063.44	128.728
1069.17	128.784
1074.91	156.01
1080.64	200.546
1086.37	298.273
1092.09	426.01
1097.8	445.159
1103.52	326.994
1109.22	218.913
1114.93	193.48
1120.63	181.806
1126.32	188.343
1132.01	231.162
1137.7	274.175
1143.38	393.008
1149.06	527.623
1154.73	363.729
1160.4	194.318
1166.06	121.201
1171.72	93.4581
1177.38	73.6145
1183.03	64.6607
1188.67	66.6534
1194.31	34.5771
1199.95	31.9091
1205.58	18.586
1211.21	21.9778
1216.84	17.5304
1222.46	11.0928
1228.07	13.5862
1233.68	12.0292
1239.29	16.4237
1244.89	9.61559
1250.49	8.74361
1256.08	16.8934
1261.67	12.8036
1267.26	12.729
1272.84	10.5974
1278.42	3.41894
1283.99	9.30119
1289.56	5.20795
1295.12	10.1758
1300.68	5.20335
1306.23	9.31708
1311.78	8.55332
1317.33	-2.20975
1322.87	6.16055
1328.41	-2.60268
1333.94	5.84718
1339.47	10.2283
1345	4.31211
1350.52	4.48115
1356.04	13.8544
1361.55	11.8815
1367.06	14.9712
1372.56	35.4841
1378.06	14.9004
1383.56	8.69263
1389.05	4.53796
1394.53	-1.6182
1400.02	1.56464
1405.5	0.633041
1410.97	5.90785
1416.44	3.9984
1421.91	5.1974
1427.37	9.53252
1432.83	4.52279
1438.28	3.65157
1443.73	6.95446
1449.17	4.99308
1454.62	2.94382
1460.05	-1.26981
1465.48	1.82127
1470.91	-0.356857
1476.34	2.72955
1481.76	-2.54903
1487.17	3.74751
1492.59	2.73132
1497.99	4.91195
1503.4	2.90173
1508.8	5.14687
1514.19	9.55538
1519.59	7.62872
1524.97	11.0489
1530.36	9.12745
1535.74	10.4399
1541.11	5.19475
1546.48	6.30831
1551.85	13.7802
1557.21	13.5553
1562.57	1.47939
1567.93	8.82793
1573.28	3.23209
1578.62	5.2246
1583.97	5.10941
1589.3	12.5563
1594.64	12.5065
1599.97	12.4981
1605.3	12.5346
1610.62	12.6398
1615.94	18.2606
1621.25	10.8534
1626.56	19.8247
1631.87	6.84119
1637.17	14.6673
1642.47	12.4218
1647.76	15.7244
1653.05	16.7793
1658.34	13.3483
1663.62	12.0982
1668.9	7.49677
1674.18	10.6491
1679.45	10.4534
1684.71	7.98845
1689.98	4.40596
1695.23	6.41405
1700.49	6.33491
1705.74	11.0477
1710.99	16.5577
1716.23	5.24075
1721.47	7.53334
1726.7	18.6853
1731.94	17.5727
1737.16	8.56422
1742.39	15.2974
1747.61	13.0035
1752.82	7.25999
1758.03	12.7808
1763.24	15.9893
1768.44	10.1513
1773.64	2.05228
1778.84	6.45789
1784.03	4.10003
1789.22	8.604
1794.41	18.858
1799.59	6.3069
1804.76	6.32973
1809.94	14.3674
1815.11	12.0402
1820.27	8.54836
1825.43	9.6794
1830.59	7.34392
1835.74	9.66363
1840.89	6.11728
1846.04	13.0399
1851.18	5.9344
1856.32	3.45711
1861.45	6.88918
1866.58	12.7105
1871.71	7.92251
1876.83	4.25447
1881.95	8.82806
1887.07	1.56747
1892.18	7.23215
1897.29	11.7063
1902.39	15.0955
1907.49	13.8469
1912.59	13.8752
1917.68	13.9502
1922.77	4.2393
1927.86	2.95857
1932.94	2.86655
1938.02	11.157
1943.09	3.80103
1948.16	7.23335
1953.23	14.24
1958.29	5.55814
1963.35	7.70064
1968.41	6.19505
1973.46	7.05584
1978.51	6.71101
1983.55	7.56574
1988.59	10.8365
1993.63	15.32
1998.66	18.624
2003.69	12.3423
2008.72	12.1115
2013.74	1.07266
2018.76	3.25547
2023.77	17.513
2028.78	10.127
2033.79	20.9145
2038.79	8.73094
2043.79	8.65528
2048.79	8.59793
2053.78	6.05384
2058.77	7.19765
2063.76	9.5894
2068.74	20.5813
2073.72	15.6208
2078.69	21.7145
2083.66	21.6295
2088.63	9.13237
2093.59	26.3628
2098.55	20.1502
2103.51	32.59
2108.46	16.4361
2113.41	23.9974
2118.36	22.8375
2123.3	10.3304
2128.24	17.9309
2133.17	11.6174
2138.11	15.3906
2143.03	19.1618
2147.96	31.8255
2152.88	18.951
2157.79	16.2208
2162.71	15.9984
2167.62	13.1676
2172.52	16.7589
2177.43	24.2123
2182.32	9.83244
2187.22	15.9
2192.11	15.6276
2197	28.2153
2201.89	17.8108
2206.77	22.8505
2211.64	6.06607
2216.52	11.1816
2221.39	9.87973
2226.26	0.787643
2231.12	11.1606
2235.98	20.2816
2240.84	-1.93164
2245.69	19.0028
2250.54	11.1324
2255.39	12.4319
2260.23	5.83324
2265.07	17.6922
2269.9	20.2568
2274.74	14.8076
2279.57	3.98489
2284.39	5.05233
2289.21	18.0583
2294.03	13.7654
2298.84	13.5052
2303.66	7.97083
2308.46	13.1812
2313.27	6.43121
2318.07	5.06378
2322.87	2.34893
2327.66	5.0369
2332.45	5.05914
2337.24	11.8889
2342.02	13.3402
2346.8	5.29395
2351.58	12.2447
2356.35	1.31364
2361.12	6.75933
2365.89	6.69196
2370.65	6.62298
2375.41	5.15037
2380.17	10.5868
2384.92	-2.11468
2389.67	15.7215
2394.42	18.2054
2399.16	-1.63258
2403.9	11.9217
2408.64	6.01341
2413.37	14.2556
2418.1	4.76506
2422.83	4.83249
2427.55	3.28178
2432.27	1.85206
2436.99	4.71082
2441.7	10.4284
2446.41	16.1774
2451.11	11.9682
2455.82	-2.31223
2460.51	14.9355
2465.21	12.1044
2469.9	7.78508
2474.59	16.4583
2479.28	3.41096
2483.96	6.28079
2488.64	7.65823
2493.32	10.493
2497.99	13.35
2502.66	10.3177
2507.32	11.6574
2511.99	5.60381
2516.65	21.617
2521.3	14.1006
2525.96	10.9958
2530.61	12.3208
2535.25	15.1747
2539.89	9.14844
2544.53	28.4316
2549.17	16.4752
2553.8	4.45956
2558.43	14.8278
2563.06	8.76305
2567.68	7.23584
2572.3	16.2931
2576.92	13.2628
2581.53	11.6724
2586.14	2.38168
2590.75	9.70915
2595.35	15.5825
2599.96	6.29659
2604.55	10.6728
2609.15	16.5669
2613.74	8.65004
2618.33	5.32788
2622.91	12.7253
2627.49	24.7747
2632.07	17.0089
2636.64	10.8633
2641.22	10.9572
2645.78	25.0237
2650.35	23.5988
2654.91	12.7471
2659.47	15.7557
2664.03	-0.0471191
2668.58	24.8236
2673.13	18.5081
2677.67	20.2935
2682.22	22.3155
2686.76	6.79088
2691.29	30.9981
2695.83	24.6656
2700.36	13.4042
2704.89	31.0224
2709.41	16.4626
2713.93	9.90947
2718.45	5.01585
2722.96	1.67355
2727.47	33.9364
2731.98	22.3482
2736.49	0.971252
2740.99	15.3468
2745.49	13.5446
2749.98	16.7127
2754.47	3.74057
2758.96	11.8497
2763.45	29.7756
2767.93	8.37321
2772.41	16.5347
2776.89	11.62
2781.36	20.0386
2785.84	25.2415
2790.3	18.7855
2794.77	0.538544
2799.23	25.7551
2803.69	17.3957
2808.14	14.0036
2812.59	7.19107
2817.04	7.06358
2821.49	1.87096
2825.93	10.2596
2830.37	13.5603
2834.81	16.8457
2839.24	9.91797
2843.67	9.81078
2848.1	13.1776
2852.53	1.1944
2856.95	21.8605
2861.37	15.0938
2865.78	11.828
2870.19	1.63211
2874.6	17.4382
2879.01	8.96284
2883.41	24.9743
2887.81	7.75638
2892.21	6.24184
2896.6	11.8141
2901	3.27061
2905.38	15.9374
2909.77	9.00961
2914.15	10.8836
2918.53	-3.37822
2922.91	20.0924
2927.28	2.27654
2931.65	6.09138
2936.02	8.03479
2940.38	13.5262
2944.74	22.6606
2949.1	18.9855
2953.46	0.72023
2957.81	15.2926
2962.16	15.2827
2966.5	33.6418
2970.85	9.8604
2975.19	22.8104
2979.52	17.3758
2983.86	10.1373
2988.19	15.8981
2992.52	34.7427
2996.85	18.321
3001.17	35.4964
3005.49	30.3345
3009.8	13.8421
3014.12	36.8408
3018.43	44.9417
3022.74	49.2915
3027.04	40.1967
3031.34	27.146
3035.64	52.2485
3039.94	50.5681
3044.23	60.4219
3048.52	45.2284
3052.81	53.1258
3057.09	76.5534
3061.38	69.0722
3065.65	86.7834
3069.93	67.6415
3074.2	75.6963
3078.47	93.5567
3082.74	91.9468
3087	98.2771
3091.27	85.1398
3095.52	97.6443
3099.78	98.4046
3104.03	126.993
3108.28	110.097
3112.53	127.105
3116.77	110.126
3121.01	115.215
3125.25	124.474
3129.49	158.293
3133.72	139.433
3137.95	159.336
3142.18	164.875
3146.4	174.474
3150.62	198.581
3154.84	174.674
3159.06	173.563
3163.27	195.522
3167.48	202.792
3171.69	184.826
3175.89	179.303
3180.09	205.274
3184.29	197.301
3188.49	212.511
3192.68	198.213
3196.87	203.205
3201.06	195.892
3205.24	190.802
3209.42	226.716
3213.6	195.995
3217.78	199.807
3221.95	179.557
3226.12	152.593
3230.29	208.819
3234.45	181.654
3238.61	189.634
3242.77	168.967
3246.93	181.638
3251.08	178.442
3255.23	159.236
3259.38	153.474
3263.53	156.942
3267.67	179.158
3271.81	178.419
3275.95	172.579
3280.08	152.793
3284.21	130.625
3288.34	145.13
3292.47	155.046
3296.59	155.733
3300.71	133.412
3304.83	148.03
3308.95	153.422
3313.06	161.088
3317.17	136.227
3321.27	146.349
3325.38	147.281
3329.48	164.705
3333.58	173.118
3337.67	165.053
3341.77	177.923
3345.86	178.807
3349.95	155.795
3354.03	166.055
3358.11	171.756
3362.19	179.89
3366.27	176.019
3370.34	152.924
3374.42	172.954
3378.48	185.699
3382.55	181.544
3386.61	160.427
3390.68	180.335
3394.73	159.136
3398.79	164.672
3402.84	179.827
3406.89	148.757
3410.94	166.25
3414.98	161.84
3419.03	164.742
3423.06	162.732
3427.1	185.174
3431.14	178.459
3435.17	176.709
3439.2	175.055
3443.22	163.63
3447.25	159.718
3451.27	168.149
3455.28	161.905
3459.3	190.547
3463.31	157.136
3467.32	160.998
3471.33	149.764
3475.34	143.264
3479.34	149.463
3483.34	135.421
3487.33	123.793
3491.33	145.148
3495.32	148.682
3499.31	121.448
3503.3	132.416
3507.28	130.498
3511.26	112.961
3515.24	131.312
3519.22	126.528
3523.19	116.59
3527.16	109.267
3531.13	94.1843
3535.1	94.8101
3539.06	108.526
3543.02	104.065
3546.98	125.449
3550.93	102.587
3554.89	110.648
3558.84	95.4775
3562.78	116.839
3566.73	104.425
3570.67	118.251
3574.61	124.244
3578.55	117.23
3582.48	107.634
3586.41	113.866
3590.35	98.8919
3594.27	102.436
3598.2	79.3044
3602.12	53.2909
3606.04	70.0068
3609.95	70.6028
3613.87	52.3483
3617.78	66.34
3621.69	64.0582
3625.6	34.5661
3629.5	64.5141
3633.4	53.8394
3637.3	59.4867
3641.2	38.1808
3645.09	52.2138
3648.98	77.0679
3652.87	47.403
3656.76	31.2765
3660.64	53.3067
3664.53	37.1116
3668.4	37.3431
3672.28	37.5522
3676.16	13.1958
3680.03	35.5077
3683.9	13.9626
3687.76	31.0096
3691.63	20.4811
3695.49	7.05272
3699.35	26.9684
3703.2	21.8538
3707.06	16.744
3710.91	20.0099
3714.76	37.3167
3718.6	17.9834
3722.45	18.2948
3726.29	15.7307
3730.13	7.48207
3733.97	19.1057
3737.8	8.00241
3741.63	11.0709
3745.46	22.6882
3749.29	11.4305
3753.11	5.81029
3756.93	0.127426
3760.75	11.5849
3764.57	-11.3553
3768.39	-2.7614
3772.2	8.75932
3776.01	14.5573
3779.81	8.90543
3783.62	9.06073
3787.42	20.7638
3791.22	3.58542
3795.02	0.879318
3798.81	1.11034
3802.61	1.36098
3806.4	-4.18065
3810.18	1.92578
3813.97	8.02315
3817.75	-3.44279
3821.53	-9.09702
3825.31	5.77208
3829.09	5.97522
3832.86	3.27605
3836.63	30.1091
3840.4	3.7095
3844.17	3.97911
3847.93	12.9752
3851.69	10.0852
3855.45	13.1029
3859.21	-10.692
3862.96	10.1573
3866.71	-1.46159
3870.46	4.90285
3874.21	19.9465
3877.95	8.13577
3881.69	-15.6344
3885.44	-3.47832
3889.17	8.743
3892.91	-2.94487
3896.64	6.47714
3900.37	-8.18303
3904.1	1.23689
3907.82	13.711
3911.55	11.1579
3915.27	14.704
3918.99	-21.1134
3922.7	6.88332
3926.42	1.45605
3930.13	17.3913
3933.84	-0.338165
3937.54	0.261307
3941.25	16.3005
3944.95	-13.6764
3948.65	2.47867
3952.35	24.8382
3956.04	-2.20947
3959.73	4.70546
3963.42	5.44328
3967.11	-0.0193481
3970.8	16.2071
3974.48	20.1056
3978.16	8.52852
3981.84	9.34811
3985.52	16.4176
3989.19	11.1345
3992.86	2.86375
3996.53	0.903748
3998.37	17.0449