File: Data/3-Raman/processed/bu19w-d-ore2-fi08-v_150 (500nm)_532nm_edge_100%_x100_vis_lwd_h50um_15sx2_01_0.txt
#Acq. time (s)=	15
#Accumulations=	2
#Range (cm-¹)=	50...5000
#Windows=	1
#Auto scanning=	Off
#Autofocus=	Off
#Macrospot=	Off
#AutoExposure=	Off
#Spike filter=	Multiple accum.
#Delay time (s)=	2
#Binning=	1
#Readout mode=	Signal
#DeNoise=	Off
#ICS correction=	On
#Dark correction=	Off
#Inst. Process=	Off
#Detector Gain=	Best Dynamic
#Detector ADC=	50 kHz HS
#Detector temperature (°C)=	-60.09
#Instrument=	LabRAM HR Evol
#Detector=	SIN-EM FIVIS
#Objective=	x100_VIS_LWD
#Grating=	150 (500nm)
#ND Filter=	100%
#Laser=	532nm_Edge
#Hole=	49.98
#Temperature=	0
#Range=	Visible
#StageXY=	75x50mm Scan+
#StageZ=	Z motor
#X (µm)=	0
#Y (µm)=	0
#Z (µm)=	-19.9
#Full time(s)=	35
#Project=	21_05_28
#Sample=	BU19w
#Site=
#Title=	BU19w-FF-ore2-FI08-V_150 (500nm)_532nm_Edge_100%_x100_VIS_LWD_H50um_15sX2
#Remark=
#Date=	28.05.2021 15:12
#Acquired=	28.05.2021 15:12:10
#Base:Fit=	16.12.2021 17:39:50
#Base:Sub=	16.12.2021 18:00:34
51.5961	22512.6
56.2453	23195.4
60.8921	20151.8
65.5367	15522.3
70.1768	11770.5
74.8167	9190.75
79.4543	7089.82
84.0897	5588.31
88.7227	4669.29
93.3513	3766.15
97.9798	3113.08
102.606	2554.88
107.23	2249.95
111.851	2049.21
116.469	1844.99
121.086	2240.9
125.7	4375.11
130.313	6031.58
134.921	3643.66
139.529	1851.25
144.134	1527.06
148.738	1452.97
153.337	1263.88
157.936	1118.51
162.532	1071.69
167.126	1123.09
171.716	1196.7
176.306	1323.22
180.894	1604.14
185.477	2006.31
190.06	2784.14
194.64	3980.45
199.219	5734.7
203.793	7567.04
208.367	8215.94
212.939	7430.24
217.506	5705.49
222.073	4033.56
226.638	2861.62
231.199	2067.23
235.759	1593.4
240.318	1251.7
244.872	934.557
249.425	821.388
253.977	750.948
258.524	859.524
263.071	1326.53
267.616	1534.09
272.156	842.236
276.697	379.63
281.233	231.82
285.769	200.944
290.303	157.501
294.832	140.031
299.361	85.0057
303.886	43.2953
308.411	86.5273
312.934	47.6965
317.452	41.7863
321.97	24.655
326.484	16.5791
330.998	0.0236816
335.507	22.9056
340.017	31.3642
344.524	9.68756
349.027	97.465
353.53	726.404
358.028	1435.69
362.527	753.968
367.021	203.423
371.515	101.917
376.004	65.8088
380.494	61.2521
384.979	74.4984
389.465	98.0665
393.946	134.938
398.427	258.578
402.903	565.771
407.38	543.829
411.852	158.799
416.324	145.303
420.792	119.606
425.26	142.227
429.723	204.414
434.187	236.086
438.646	382.693
443.105	616.446
447.56	1086.32
452.015	2110.76
456.466	4328.11
460.914	12428.6
465.362	24746.1
469.807	21634.2
474.251	9956.75
478.69	4448.61
483.13	2600.8
487.566	1777.67
491.999	1322.39
496.432	997.743
500.861	756.555
505.29	556.914
509.715	683.797
514.138	697.331
518.56	569.88
522.979	415.276
527.395	321.112
531.811	273.431
536.223	207.456
540.635	198.215
545.042	199.361
549.448	169.272
553.853	176.156
558.255	137.145
562.654	108.374
567.053	62.2841
571.448	62.8975
575.841	89.9535
580.232	92.1002
584.622	63.8115
589.009	80.8011
593.393	91.2307
597.777	100.009
602.157	55.6614
606.535	73.1724
610.913	28.6281
615.287	51.0935
619.659	44.8668
624.029	60.7459
628.398	44.916
632.763	73.5392
637.127	20.6839
641.488	16.2783
645.849	25.28
650.206	36.2148
654.561	22.6241
658.914	10.4027
663.267	22.7577
667.615	24.5167
671.962	19.2941
676.307	56.6078
680.649	30.7349
684.991	26.0926
689.33	67.1571
693.666	129.927
698	193.755
702.332	186.039
706.662	101.058
710.992	44.6765
715.318	-5.53217
719.641	20.7932
723.963	30.9919
728.283	48.8149
732.6	24.3627
736.918	-4.84259
741.231	20.5674
745.542	17.6415
749.852	43.2718
754.159	4.24371
758.464	1.07343
762.767	30.4629
767.068	25.543
771.369	30.1351
775.666	49.8639
779.961	57.197
784.254	77.0564
788.545	146.335
792.834	229.015
797.12	276.547
801.405	377.392
805.688	526.428
809.968	834.32
814.247	616.874
818.524	296.228
822.798	137.155
827.071	135.708
831.341	100.227
835.612	90.0764
839.878	66.598
844.142	117.999
848.405	123.759
852.665	95.7495
856.923	92.0239
861.18	81.6628
865.434	99.7292
869.686	107.49
873.936	68.8477
878.185	56.3474
882.431	111.504
886.675	90.5819
890.915	138.795
895.155	82.0183
899.393	86.0425
903.63	50.213
907.864	71.4022
912.096	90.1023
916.326	88.8881
920.554	61.5227
924.78	53.2017
929.004	63.6576
933.227	9.91516
937.447	81.6736
941.665	19.0428
945.881	77.2727
950.095	16.7941
954.305	48.4442
958.516	52.4513
962.724	39.5823
966.93	20.4844
971.134	-0.558228
975.337	43.3165
979.537	43.8298
983.735	55.1483
987.93	36.7863
992.124	38.6461
996.316	39.1948
1000.51	18.189
1004.7	46.1709
1008.88	26.5809
1013.06	42.0745
1017.25	48.795
1021.43	57.6411
1025.61	26.7517
1029.78	64.8295
1033.96	49.1379
1038.13	44.032
1042.3	11.6038
1046.47	70.7217
1050.63	65.5149
1054.8	67.4656
1058.96	106.068
1063.12	135.662
1067.28	184.702
1071.44	219.639
1075.59	197.79
1079.74	424.965
1083.89	677.126
1088.04	531.484
1092.19	232.45
1096.33	107.393
1100.48	98.3285
1104.62	107.839
1108.76	62.6409
1112.89	70.1497
1117.03	87.0713
1121.16	80.1703
1125.29	47.9093
1129.42	93.6594
1133.55	70.285
1137.68	75.2123
1141.8	91.3772
1145.92	68.7196
1150.04	88.9103
1154.16	202.297
1158.27	349.355
1162.39	355.785
1166.5	280.205
1170.61	112.476
1174.72	68.2089
1178.82	78.3801
1182.93	78.1902
1187.03	31.3632
1191.13	57.8744
1195.23	48.0803
1199.33	71.6301
1203.42	40.7567
1207.51	92.1986
1211.6	58.3195
1215.69	71.1292
1219.78	56.7778
1223.86	112.997
1227.95	144.151
1232.03	151.624
1236.11	126.069
1240.18	85.2749
1244.26	106.171
1248.33	134.51
1252.41	152.54
1256.48	136.903
1260.54	182.43
1264.61	285.232
1268.67	235.303
1272.74	192.498
1276.8	187.724
1280.86	451.114
1284.91	2023.94
1288.97	1062.02
1293.02	254.596
1297.07	140.141
1301.12	149.411
1305.17	134.243
1309.21	129.058
1313.25	109.607
1317.3	162.248
1321.34	146.076
1325.37	87.1724
1329.41	102.592
1333.44	102.768
1337.48	93.4977
1341.5	101.039
1345.53	89.4285
1349.56	135.638
1353.59	99.1132
1357.61	126.335
1361.63	131.531
1365.65	141.881
1369.66	170.185
1373.68	195.758
1377.69	196.831
1381.7	289.747
1385.72	1413.03
1389.72	3205.29
1393.73	870.183
1397.73	280.822
1401.74	186.361
1405.74	185.396
1409.73	380.73
1413.73	246.991
1417.73	141.748
1421.72	135.101
1425.71	144.071
1429.7	109.9
1433.69	124.234
1437.67	89.1647
1441.66	99.5334
1445.64	96.8608
1449.62	81.2827
1453.6	100.999
1457.57	75.2146
1461.55	104.392
1465.52	71.0981
1469.49	94.8053
1473.46	77.3956
1477.43	67.6887
1481.39	53.9155
1485.36	59.6537
1489.32	40.8494
1493.28	76.8341
1497.24	30.8789
1501.19	83.4891
1505.15	69.1028
1509.1	95.9169
1513.05	46.0563
1517	75.9221
1520.95	70.969
1524.9	62.2244
1528.84	76.8539
1532.78	52.8649
1536.72	60.899
1540.66	67.0332
1544.6	86.7344
1548.53	65.7451
1552.46	68.0083
1556.4	96.2599
1560.32	71.0419
1564.25	56.3433
1568.18	108.253
1572.1	130.034
1576.02	52.2944
1579.94	80.7579
1583.86	82.1431
1587.78	81.4928
1591.69	94.285
1595.61	65.6733
1599.52	97.6486
1603.43	83.595
1607.34	110.066
1611.24	72.2921
1615.15	118.035
1619.05	83.4591
1622.95	91.9177
1626.85	91.9702
1630.74	122.828
1634.64	89.0474
1638.53	85.8224
1642.42	120.305
1646.31	71.7504
1650.2	59.7079
1654.09	101.45
1657.97	87.4468
1661.86	85.8627
1665.74	93.6254
1669.62	83.941
1673.49	119.972
1677.37	95.3574
1681.24	83.465
1685.12	76.0411
1688.99	72.3478
1692.86	99.0275
1696.72	69.0049
1700.59	70.3524
1704.45	63.7765
1708.31	37.8977
1712.17	44.1271
1716.03	48.4437
1719.89	60.3612
1723.74	23.1838
1727.6	74.5708
1731.45	54.0881
1735.3	73.1879
1739.14	81.744
1742.99	77.0186
1746.83	68.6663
1750.68	50.0358
1754.52	59.7975
1758.36	41.5748
1762.19	38.6038
1766.03	75.4965
1769.86	60.0134
1773.69	34.9525
1777.53	52.7023
1781.35	100.797
1785.18	44.7205
1789	62.4941
1792.83	33.5668
1796.65	96.5361
1800.47	75.0691
1804.29	78.0482
1808.1	45.137
1811.92	47.8317
1815.73	35.1947
1819.54	41.7629
1823.35	94.2133
1827.16	51.1106
1830.97	53.8595
1834.77	62.8397
1838.58	40.5089
1842.38	59.3846
1846.18	59.0997
1849.97	50.5522
1853.77	62.912
1857.56	0.0911865
1861.36	51.8107
1865.15	52.8906
1868.93	68.0376
1872.72	40.6515
1876.51	30.3075
1880.29	68.0994
1884.07	93.4747
1887.86	64.5298
1891.63	46.4738
1895.41	26.6252
1899.19	61.0717
1902.96	72.2229
1906.73	63.4121
1910.5	64.8743
1914.27	14.3159
1918.04	47.7599
1921.8	47.0808
1925.57	73.4037
1929.33	49.046
1933.09	55.4181
1936.85	48.7411
1940.6	66.2708
1944.36	107.226
1948.11	69.6091
1951.87	72.0258
1955.61	94.5255
1959.36	47.7146
1963.11	49.2668
1966.86	45.109
1970.6	36.7495
1974.34	60.7034
1978.08	54.3417
1981.82	41.2015
1985.56	61.483
1989.29	65.6819
1993.02	72.4236
1996.75	22.1451
2000.49	62.7062
2004.21	24.4833
2007.94	69.4011
2011.67	75.0551
2015.39	89.9293
2019.11	63.2467
2022.83	62.1752
2026.55	46.4319
2030.27	41.757
2033.98	51.5233
2037.69	53.5587
2041.41	51.8077
2045.12	52.692
2048.82	71.0135
2052.53	70.4073
2056.24	70.8101
2059.94	62.8225
2063.64	28.1952
2067.34	68.3175
2071.04	40.5269
2074.74	65.2776
2078.43	56.9478
2082.13	63.5258
2085.82	66.2295
2089.51	42.1038
2093.2	53.5387
2096.88	39.6694
2100.57	31.1062
2104.25	38.7949
2107.94	57.3938
2111.62	90.6429
2115.3	70.8475
2118.97	99.1995
2122.65	49.8446
2126.32	89.3199
2129.99	65.4683
2133.66	29.5062
2137.33	46.2235
2141	70.9524
2144.67	29.0367
2148.33	90.1844
2151.99	87.7426
2155.66	52.3713
2159.31	62.9379
2162.97	40.7612
2166.63	53.5664
2170.28	66.6078
2173.94	37.4436
2177.59	52.3497
2181.24	41.9681
2184.89	94.3013
2188.53	44.2495
2192.18	31.1661
2195.82	45.0864
2199.46	87.6083
2203.1	18.2183
2206.74	28.3538
2210.38	29.6307
2214.01	63.1705
2217.65	91.3967
2221.28	36.1846
2224.91	73.7894
2228.54	66.2734
2232.16	44.942
2235.79	74.5088
2239.41	67.1063
2243.04	64.288
2246.66	26.1223
2250.28	66.0387
2253.89	82.9714
2257.51	45.9802
2261.12	33.1377
2264.74	64.0947
2268.35	54.9843
2271.96	84.7314
2275.57	66.1478
2279.17	31.0594
2282.78	65.6947
2286.38	74.8649
2289.98	49.0609
2293.58	76.9323
2297.18	24.4526
2300.78	43.9386
2304.37	66.0396
2307.97	87.8425
2311.56	19.3909
2315.15	66.3564
2318.74	40.0824
2322.33	75.0688
2325.91	126.108
2329.5	431.182
2333.08	260.39
2336.66	79.4554
2340.24	34.4036
2343.82	0.621582
2347.4	63.4095
2350.97	70.6124
2354.54	50.6069
2358.12	79.105
2361.69	17.0697
2365.26	12.8796
2368.82	29.2135
2372.39	46.7874
2375.95	33.6831
2379.52	68.6512
2383.08	53.032
2386.64	66.1333
2390.19	34.4498
2393.75	64.6327
2397.31	51.2144
2400.86	47.4974
2404.41	25.3752
2407.96	58.4386
2411.51	46.3232
2415.06	43.7399
2418.6	95.7456
2422.15	56.1082
2425.69	20.4172
2429.23	49.615
2432.77	77.3801
2436.31	39.7906
2439.84	50.5049
2443.38	53.943
2446.91	68.6404
2450.44	54.7238
2453.97	14.7161
2457.5	41.2661
2461.03	36.4581
2464.55	53.1923
2468.08	48.8628
2471.6	19.3359
2475.12	33.559
2478.64	29.6307
2482.16	43.8641
2485.67	44.3328
2489.19	69.2559
2492.7	16.9998
2496.21	24.0695
2499.72	56.0116
2503.23	36.8523
2506.74	44.59
2510.25	26.8051
2513.75	27.8068
2517.25	57.0397
2520.75	68.8322
2524.25	46.2062
2527.75	59.3806
2531.25	58.1455
2534.74	73.7606
2538.24	65.8287
2541.73	59.1906
2545.22	55.1399
2548.71	30.5024
2552.2	57.6703
2555.68	72.3578
2559.17	64.6689
2562.65	48.6338
2566.13	71.3494
2569.61	20.998
2573.09	36.219
2576.57	42.4458
2580.04	48.0551
2583.51	36.8184
2586.99	58.6144
2590.46	39.3547
2593.93	62.9528
2597.4	54.9581
2600.86	79.8552
2604.33	45.3704
2607.79	32.8878
2611.25	25.8312
2614.71	79.2009
2618.17	58.2572
2621.63	-5.61743
2625.09	23.4235
2628.54	57.823
2631.99	76.5884
2635.45	32.5894
2638.9	24.6528
2642.34	25.0844
2645.79	42.4377
2649.24	44.3701
2652.68	80.2629
2656.12	11.9469
2659.56	45.1737
2663.01	12.7478
2666.44	64.4241
2669.88	4.60327
2673.32	66.2935
2676.75	44.4556
2680.18	0.473999
2683.61	71.9346
2687.04	82.1245
2690.47	34.5643
2693.9	45.3705
2697.32	67.0304
2700.75	28.5282
2704.17	39.4197
2707.59	21.5466
2711.01	54.0131
2714.43	43.0909
2717.84	44.5658
2721.26	57.5233
2724.67	69.775
2728.08	75.6443
2731.49	56.3717
2734.9	33.2297
2738.31	73.7709
2741.71	41.153
2745.12	57.0085
2748.52	67.0442
2751.92	31.0402
2755.32	40.0283
2758.72	30.0372
2762.12	35.1385
2765.52	37.9697
2768.91	58.4814
2772.3	60.8448
2775.7	33.8744
2779.09	63.1807
2782.47	53.6595
2785.86	69.4475
2789.25	11.8137
2792.63	28.452
2796.01	21.5477
2799.4	76.6147
2802.78	50.6938
2806.15	34.2098
2809.53	58.9308
2812.91	78.8541
2816.28	44.4342
2819.65	43.6824
2823.03	3.97009
2826.4	28.875
2829.76	37.0887
2833.13	54.8191
2836.5	39.2838
2839.86	55.6841
2843.22	62.136
2846.59	66.1591
2849.95	26.8989
2853.3	42.0597
2856.66	43.9966
2860.02	40.53
2863.37	44.729
2866.72	18.0676
2870.08	55.1714
2873.43	25.5621
2876.77	5.2489
2880.12	48.8759
2883.47	48.2509
2886.81	44.6785
2890.15	52.3981
2893.5	73.2743
2896.84	45.6074
2900.17	63.1036
2903.51	61.4634
2906.85	33.1499
2910.18	54.8608
2913.52	70.7928
2916.85	68.6453
2920.18	69.119
2923.51	41.1465
2926.83	55.605
2930.16	61.3408
2933.48	76.3453
2936.81	55.2574
2940.13	61.5498
2943.45	59.3641
2946.77	88.3007
2950.09	56.1024
2953.4	52.1021
2956.72	58.4955
2960.03	88.5981
2963.34	60.6299
2966.65	46.8531
2969.96	48.5331
2973.27	97.3743
2976.58	26.2203
2979.88	66.9353
2983.19	54.9475
2986.49	46.8046
2989.79	52.8319
2993.09	51.4014
2996.39	75.4238
2999.68	121.167
3002.98	79.4764
3006.27	50.9318
3009.57	83.662
3012.86	106.148
3016.15	76.8682
3019.43	76.7485
3022.72	90.7583
3026.01	81.1976
3029.29	88.6499
3032.57	62.0699
3035.86	111.019
3039.14	115.525
3042.41	61.3887
3045.69	103.789
3048.97	61.009
3052.24	103.467
3055.52	109.04
3058.79	78.5168
3062.06	98.7365
3065.33	90.7238
3068.6	95.8157
3071.86	118.625
3075.13	112.634
3078.39	139.445
3081.65	105.098
3084.91	90.9702
3088.17	75.8055
3091.43	166.469
3094.69	137.577
3097.95	140.032
3101.2	108.27
3104.45	120.916
3107.7	112.38
3110.95	175.969
3114.2	159.141
3117.45	161.488
3120.7	177.214
3123.94	181.517
3127.18	119.111
3130.43	198.619
3133.67	200.985
3136.91	210.935
3140.14	176.956
3143.38	198.25
3146.61	219.561
3149.85	211.421
3153.08	219.526
3156.31	235.203
3159.54	195.595
3162.77	273.292
3166	245.088
3169.22	277.814
3172.45	275.118
3175.67	250.412
3178.89	275.193
3182.11	241.763
3185.33	288.494
3188.55	277.812
3191.77	301.412
3194.98	322.14
3198.2	323.782
3201.41	328.248
3204.62	306.131
3207.83	324.061
3211.04	332.548
3214.25	320.219
3217.45	312.765
3220.66	351.933
3223.86	355.964
3227.06	337.333
3230.26	374.873
3233.46	399.228
3236.66	415.868
3239.85	411.004
3243.05	425.281
3246.24	380.594
3249.44	418.797
3252.63	411.435
3255.82	434.646
3259.01	365.253
3262.19	429.251
3265.38	414.72
3268.56	447.709
3271.75	402.197
3274.93	484.59
3278.11	431.315
3281.29	481.785
3284.47	441.229
3287.64	438.912
3290.82	425.965
3293.99	451.301
3297.17	487.979
3300.34	413.254
3303.51	492.236
3306.68	456.527
3309.84	461.581
3313.01	433.106
3316.18	502.369
3319.34	492.743
3322.5	542.785
3325.66	504.691
3328.82	470.465
3331.98	538.448
3335.14	497.816
3338.29	514.988
3341.45	549.254
3344.6	515.639
3347.75	522.095
3350.9	503.535
3354.05	533.029
3357.2	561.785
3360.35	566.135
3363.49	546.194
3366.64	564.011
3369.78	607.405
3372.92	563.154
3376.06	616.317
3379.2	611.057
3382.34	627.615
3385.48	603.451
3388.61	628.61
3391.75	631.108
3394.88	601.32
3398.01	640.195
3401.14	639.395
3404.27	644.453
3407.4	688.646
3410.52	680.735
3413.65	707.017
3416.77	633.799
3419.89	669.988
3423.01	695.554
3426.13	640.568
3429.25	649.177
3432.37	679.492
3435.49	689.366
3438.6	684.482
3441.72	693.202
3444.83	686.603
3447.94	713.957
3451.05	685.946
3454.16	654.832
3457.26	694.167
3460.37	690.371
3463.47	675.136
3466.58	646.529
3469.68	672.741
3472.78	661.603
3475.88	676.638
3478.98	640.65
3482.07	647.359
3485.17	594.577
3488.26	627.934
3491.36	626.614
3494.45	602.2
3497.54	552.263
3500.63	600.326
3503.72	587.12
3506.81	605.679
3509.89	595.007
3512.98	532.027
3516.06	544.724
3519.14	531.536
3522.22	491.809
3525.3	472.998
3528.38	506.14
3531.45	462.071
3534.53	482.772
3537.61	420.547
3540.68	434.013
3543.75	438.731
3546.82	430.912
3549.89	398.712
3552.96	398.219
3556.03	387.183
3559.09	382.076
3562.16	365.606
3565.22	379.114
3568.28	346.909
3571.34	336.019
3574.4	334.831
3577.46	308.103
3580.52	305.91
3583.57	321.621
3586.63	261.319
3589.68	278.782
3592.73	258.136
3595.78	254.526
3598.83	280.162
3601.88	256.533
3604.93	253.599
3607.97	255.294
3611.02	205.913
3614.06	212.276
3617.1	242.192
3620.14	223.997
3623.18	215.322
3626.22	181.243
3629.26	199.114
3632.3	195.229
3635.33	201.637
3638.36	167.906
3641.4	188
3644.43	133.917
3647.46	157.314
3650.49	138.957
3653.51	168.768
3656.54	116.078
3659.57	155.512
3662.59	120.505
3665.61	118.187
3668.63	114.351
3671.65	131.544
3674.67	109.192
3677.69	97.2678
3680.71	34.3899
3683.72	59.264
3686.74	48.2452
3689.75	66.5835
3692.76	56.5692
3695.77	72.1335
3698.78	49.5651
3701.79	37.652
3704.79	58.9449
3707.8	47.004
3710.81	46.3149
3713.81	55.9961
3716.81	48.4185
3719.81	36.155
3722.81	25.6438
3725.81	51.2147
3728.81	8.12573
3731.8	51.6133
3734.8	33.0897
3737.79	24.9188
3740.78	34.74
3743.77	38.7111
3746.76	18.8086
3749.75	11.1768
3752.74	37.6722
3755.73	-7.08289
3758.71	45.0226
3761.7	22.1266
3764.68	38.9669
3767.66	6.57751
3770.64	20.6808
3773.62	28.2505
3776.6	45.3479
3779.58	48.3229
3782.55	30.5875
3785.53	3.43701
3788.5	28.2866
3791.47	18.2709
3794.44	28.2479
3797.41	37.3694
3800.38	45.6145
3803.35	34.1799
3806.32	50.1842
3809.28	4.81836
3812.24	43.6029
3815.21	29.4933
3818.17	15.3973
3821.13	26.8834
3824.09	45.0354
3827.04	10.2262
3830	22.7845
3832.96	41.9894
3835.91	-3.22522
3838.86	26.5875
3841.82	4.15961
3844.77	39.7151
3847.72	21.0813
3850.67	20.5622
3853.61	45.845
3856.56	26.3337
3859.5	44.0515
3862.45	28.3447
3865.39	22.1141
3868.33	18.7408
3871.27	13.3563
3874.21	3.13562
3877.15	50.4366
3880.09	11.2474
3883.02	29.5508
3885.96	33.3254
3888.89	19.7196
3891.82	3.1792
3894.75	26.9703
3897.68	20.8204
3900.61	21.2848
3903.54	29.4113
3906.47	19.1433
3909.39	39.7569
3912.31	70.8365
3915.24	19.1755
3918.16	14.5417
3921.08	44.6544
3924	6.39807
3926.92	51.5253
3929.83	8.29944
3932.75	31.196
3935.67	19.8321
3938.58	-12.3851
3941.49	15.9037
3944.4	48.8828
3947.31	12.9799
3950.22	51.8572
3953.13	13.2515
3956.04	57.9974
3958.94	16.6364
3961.85	16.5021
3964.75	44.2119
3967.65	45.1473
3970.55	31.7411
3973.45	50.025
3976.35	39.4896
3979.25	19.2694
3982.15	46.0588
3985.04	34.3904
3987.94	40.9356
3990.83	13.7842
3993.72	84.6254
3996.61	10.3899
3999.5	56.4048
4002.39	6.21533
4005.28	25.3515
4008.16	44.5489
4011.05	19.4308
4013.93	11.6337
4016.81	23.1309
4019.7	42.3549
4022.58	26.83
4025.46	29.6465
4028.33	56.6402
4031.21	26.6258
4034.09	42.063
4036.96	41.0739
4039.84	13.9861
4042.71	3.30615
4045.58	54.4646
4048.45	44.6456
4051.32	25.173
4054.19	12.5223
4057.05	30.037
4059.92	35.8764
4062.78	43.6261
4065.65	46.5254
4068.51	13.433
4071.37	21.1594
4074.23	12.3365
4077.09	54.1274
4079.95	-1.49438
4082.81	21.7887
4085.66	-1.71326
4088.52	3.98376
4091.37	18.4668
4094.22	24.2369
4097.07	13.3298
4099.92	16.1457
4102.77	14.0505
4105.62	41.2615
4108.47	37.0685
4111.31	12.3358
4114.16	46.2056
4117	39.8575
4119.84	16.7375
4122.69	22.9922
4125.53	33.2701
4128.36	56.2939
4131.2	59.0213
4134.04	29.5641
4136.88	34.6569
4139.71	23.9043
4142.54	34.8846
4145.38	38.1964
4148.21	24.2562
4151.04	26.0428
4153.87	30.561
4156.69	18.1064
4159.52	44.4284
4162.35	23.1221
4165.17	17.5901
4168	56.0577
4170.82	31.9705
4173.64	33.3625
4176.46	27.932
4179.28	20.5455
4182.1	8.34076
4184.91	30.3968
4187.73	28.0517
4190.54	30.6195
4193.36	48.9865
4196.17	16.5388
4198.98	57.6722
4201.79	35.0871
4204.6	35.0778
4207.41	57.6061
4210.22	34.0134
4213.02	15.2714
4215.83	22.0657
4218.63	46.1176
4221.44	40.5974
4224.24	22.1569
4227.04	48.9822
4229.84	16.7059
4232.64	32.8705
4235.43	57.1035
4238.23	9.0351
4241.02	76.0704
4243.82	12.0242
4246.61	47.4413
4249.4	3.11841
4252.19	33.4824
4254.98	32.9021
4257.77	17.2238
4260.56	32.5541
4263.35	59.9903
4266.13	38.3143
4268.92	25.6909
4271.7	3.95807
4274.48	18.4266
4277.26	47.8879
4280.04	16.6912
4282.82	48.0366
4285.6	58.0985
4288.38	38.7172
4291.15	45.5406
4293.93	49.2928
4296.7	38.9818
4299.47	28.7245
4302.25	33.5895
4305.02	14.0894
4307.79	22.9974
4310.55	48.2086
4313.32	47.0967
4316.09	17.3624
4318.85	29.2435
4321.62	-5.74786
4324.38	22.2983
4327.14	37.0768
4329.9	26.4271
4332.66	41.1482
4335.42	28.4154
4338.18	35.973
4340.94	24.3269
4343.69	55.4932
4346.45	50.0527
4349.2	-5.31396
4351.95	12.7673
4354.7	19.8471
4357.45	19.6871
4360.2	-1.95496
4362.95	29.5478
4365.7	3.81506
4368.44	30.2415
4371.19	19.8654
4373.93	44.2137
4376.68	58.3016
4379.42	-10.8486
4382.16	52.4454
4384.9	27.4606
4387.64	51.9858
4390.37	28.4858
4393.11	18.4532
4395.85	18.2831
4398.58	38.2116
4401.31	54.0078
4404.05	19.9988
4406.78	4.63
4409.51	37.0496
4412.24	38.2423
4414.96	40.3603
4417.69	4.92957
4420.42	51.499
4423.14	57.5899
4425.87	29.2798
4428.59	33.3212
4431.31	19.5903
4434.03	13.1448
4436.75	63.1953
4439.47	34.6867
4442.19	27.0331
4444.91	46.6606
4447.62	32.6766
4450.34	16.5784
4453.05	6.69983
4455.76	19.9184
4458.47	22.5627
4461.19	19.9205
4463.89	32.0964
4466.6	56.8851
4469.31	4.90881
4472.02	44.5245
4474.72	27.3564
4477.43	29.2084
4480.13	24.7892
4482.83	43.6331
4485.53	22.3503
4488.23	-8.5412
4490.93	4.93188
4493.63	25.6508
4496.33	22.9731
4499.02	29.9619
4501.72	29.4956
4504.41	2.47363
4507.11	31.6949
4509.8	33.3833
4512.49	53.1136
4515.18	32.5372
4517.87	25.7682
4520.56	23.2728
4523.24	12.3411
4525.93	35.439
4528.61	15.9651
4531.3	44.4266
4533.98	39.8945
4536.66	0.173828
4539.34	11.6624
4542.02	55.263
4544.7	43.3188
4547.38	8.90594
4550.05	26.9218
4552.73	15.0192
4555.4	26.8181
4558.08	32.2987
4560.75	22.9303
4563.42	23.3502
4566.09	12.1002
4568.76	44.2903
4571.43	29.5236
4574.1	21.5539
4576.77	31.7502
4579.43	19.4738
4582.1	11.8093
4584.76	14.0427
4587.42	43.1412
4590.08	34.0676
4592.74	7.45178
4595.4	17.9701
4598.06	34.0401
4600.72	33.6633
4603.38	3.87109
4606.03	38.6818
4608.69	41.7711
4611.34	41.5825
4613.99	9.51788
4616.64	27.9463
4619.29	29.9374
4621.94	25.3581
4624.59	14.1268
4627.24	7.23315
4629.89	44.463
4632.53	13.212
4635.18	44.8469
4637.82	24.472
4640.46	22.8807
4643.1	-0.856567
4645.74	27.6179
4648.38	15.2493
4651.02	31.8959
4653.66	23.2277
4656.3	12.0159
4658.93	21.2956
4661.57	28.8149
4664.2	20.8156
4666.83	45.1308
4669.46	27.9329
4672.09	20.838
4674.72	39.4887
4677.35	25.6336
4679.98	30.8206
4682.61	48.3498
4685.23	11.9503
4687.86	22.7358
4690.48	45.9254
4693.1	13.9561
4695.73	24.72
4698.34	20.8206
4700.96	38.3738
4703.58	32.2043
4706.2	25.9679
4708.82	27.6168
4711.43	43.9477
4714.05	20.6669
4716.66	56.2173
4719.28	16.9991
4721.89	38.9187
4724.5	23.4124
4727.11	-4.50024
4729.72	39.0726
4732.33	46.3635
4734.93	52.525
4737.54	30.2534
4740.14	27.2474
4742.75	16.252
4745.35	32.499
4747.95	27.088
4750.55	26.1379
4753.15	57.0681
4755.75	27.6653
4758.35	52.8869
4760.95	26.9387
4763.54	47.7056
4766.14	19.5351
4768.73	32.4976
4771.33	45.5173
4773.92	27.6136
4776.51	29.1055
4779.1	54.5779
4781.69	21.7921
4784.28	14.1227
4786.87	47.6127
4789.45	42.2337
4792.04	26.5638
4794.63	-3.99261
4797.21	29.5996
4799.79	43.7932
4802.37	12.1363
4804.95	28.7044
4807.53	10.8792
4810.11	29.8765
4812.69	12.035
4815.27	20.7024
4817.84	52.5117
4820.42	24.3192
4822.99	15.7212
4825.57	8.26147
4828.14	18.1676
4830.71	19.9648
4833.28	32.2827
4835.85	27.1709
4838.42	38.4373
4840.98	26.4037
4843.55	24.8311
4846.12	45.4193
4848.68	35.4713
4851.24	37.066
4853.81	35.9328
4856.37	44.296
4858.93	36.723
4861.49	19.6443
4864.05	33.0558
4866.61	33.295
4869.16	39.4727
4871.72	55.2429
4874.27	29.4271
4876.83	10.6125
4879.38	40.4043
4881.93	4.88953
4884.49	12.0549
4887.04	34.6654
4889.58	31.1366
4892.13	27.5933
4894.68	34.7294
4897.23	9.67355
4899.77	45.3589
4902.32	54.816
4904.86	26.0795
4907.4	41.4471
4909.95	20.9703
4912.49	3.93451
4915.03	25.0683
4917.57	1.94193
4920.1	26.6414
4922.64	40.577
4925.18	31.8045
4927.71	46.9549
4930.25	-3.71167
4932.78	10.281
4935.31	31.5428
4937.84	15.6506
4940.38	16.482
4942.9	17.0716
4945.43	16.6378
4947.96	19.8633
4950.49	43.4301
4953.01	17.8831
4955.54	22.2214
4958.06	3.83487
4960.59	7.06763
4963.11	25.9602
4965.63	-7.93527
4968.15	17.1984
4970.67	7.24661
4973.19	16.5471
4975.71	35.4952
4978.22	10.9158
4980.74	0.820618
4983.25	13.7058
4985.77	13.2751
4988.28	29.8246
4990.79	22.0994
4993.3	0.939697
4995.81	15.002
4998.32	18.1893