File: Data/3-Raman/processed/bu19(2)w-a-ff1-fi08-v_150 (500nm)_532nm_edge_100%_x100_vis_lwd_h50um_30sx2_01.txt
#Acq. time (s)=	30
#Accumulations=	2
#Range (cm-¹)=	99...4000
#Windows=	1
#Auto scanning=	Off
#Autofocus=	Off
#Macrospot=	Off
#AutoExposure=	Off
#Spike filter=	Multiple accum.
#Delay time (s)=	2
#Binning=	1
#Readout mode=	Signal
#DeNoise=	Off
#ICS correction=	On
#Dark correction=	Off
#Inst. Process=	Off
#Detector Gain=	Best Dynamic
#Detector ADC=	50 kHz HS
#Detector temperature (°C)=	-60.09
#Instrument=	LabRAM HR Evol
#Detector=	SIN-EM FIVIS
#Objective=	x100_VIS_LWD
#Grating=	150 (500nm)
#ND Filter=	100%
#Laser=	532nm_Edge
#Hole=	49.98
#Temperature=	0
#Range=	Visible
#StageXY=	75x50mm Scan+
#StageZ=	Z motor
#X (µm)=	0
#Y (µm)=	0
#Z (µm)=	-65.3
#Full time(mm:ss)=	1:04
#Project=	21_11_26
#Sample=	BU19(2)w
#Site=
#Title=	BU19(2)w-A-FF1-FI08-V_150 (500nm)_532nm_Edge_100%_x100_VIS_LWD_H50um_30sX2
#Remark=
#Date=	26.11.2021 16:23
#Acquired=	26.11.2021 16:23:51
#Base:Fit=	16.12.2021 16:00:56
#Base:Edit=	16.12.2021 16:08:13
#Base:Edit=	16.12.2021 16:08:16
#Base:Sub=	16.12.2021 16:08:19
102.91	3347.44
107.534	3565.82
112.156	4179.67
116.775	3698.18
121.392	2557.95
126.005	1708.02
130.617	1518.32
135.227	1955.14
139.835	3235.72
144.439	5988.34
149.042	8639.88
153.643	7942.27
158.242	5015.44
162.839	2694.51
167.431	1347.88
172.023	744.624
176.613	402.76
181.198	211.709
185.783	85.6533
190.366	-1.18506
194.947	22.1288
199.524	124.995
204.1	454.205
208.674	1675.06
213.243	2784.59
217.813	1520.32
222.38	508.283
226.945	522.381
231.506	1165.83
236.066	2594.34
240.625	2607.34
245.179	1169.39
249.732	306.879
254.284	118.415
258.831	21.9138
263.378	6.22321
267.923	1.91052
272.464	55.0552
277.004	90.4111
281.54	257.19
286.076	302.359
290.61	148.616
295.139	120.438
299.669	106.1
304.196	121.422
308.718	126.068
313.241	200.649
317.759	265.863
322.278	362.837
326.794	542.043
331.305	942.875
335.817	1380.27
340.324	1314.97
344.832	1140.26
349.334	1290.67
353.837	1843.52
358.338	1721.99
362.834	1110.1
367.33	757.23
371.822	665.93
376.314	728.602
380.802	800.01
385.289	1158.11
389.772	1938.4
394.255	3187.59
398.734	3521.03
403.213	3145.74
407.688	2674.71
412.162	2248.55
416.632	1880.38
421.102	1837
425.568	2018.62
430.033	2271.38
434.495	2414.1
438.956	2397.94
443.413	2207.62
447.87	2344.84
452.323	2482.16
456.776	2535.91
461.224	2072.06
465.673	1468.72
470.117	1051.55
474.561	851.801
479.001	815.664
483.438	855.5
487.876	1046.91
492.309	1320.72
496.742	1838.95
501.172	2533.44
505.601	3531.11
510.025	4535.19
514.448	4970.87
518.871	4643.37
523.289	3968.49
527.707	3425.02
532.121	2966.2
536.533	2925.26
540.945	2985.05
545.353	3107.25
549.758	3165.89
554.164	3113.78
558.565	2901.68
562.965	2479.65
567.364	2037.45
571.759	1630.96
576.151	1328.95
580.544	1129.27
584.933	1076.38
589.319	1146.44
593.706	1259.2
598.088	1563.16
602.468	1894.77
606.848	2304.81
611.224	3218.91
615.598	5228.29
619.972	8881.26
624.341	10845.2
628.709	7972.1
633.074	4491.36
637.44	2582.85
641.801	1718.47
646.16	1197.02
650.517	847.638
654.874	619.015
659.227	525.744
663.578	394.901
667.927	304.078
672.275	273.515
676.62	215.854
680.962	177.631
685.302	180.968
689.643	159.676
693.979	189.666
698.313	331.293
702.645	409.618
706.975	441.104
711.305	417.832
715.631	272.99
719.955	237.187
724.276	199.876
728.596	167.143
732.913	142.802
737.231	91.9008
741.544	38.805
745.856	7.83289
750.165	36.937
754.472	4.4328
758.778	6.85226
763.081	-6.39236
767.384	8.14624
771.683	-3.27917
775.98	-11.9901
780.275	30.871
784.568	-18.0332
788.859	9.90845
793.147	60.064
797.434	65.7192
801.719	87.1046
806.004	79.29
810.284	114.66
814.563	124.911
818.839	165.045
823.114	242.67
827.386	345.963
831.657	484.777
835.925	665.742
840.192	894.328
844.456	1129.67
848.719	1231.08
852.979	1142.86
857.237	929.143
861.493	757.548
865.748	602.512
870	529.919
874.25	561.665
878.499	661.092
882.745	787.349
886.989	671.208
891.231	461.307
895.471	247.962
899.71	166.077
903.946	75.0406
908.18	85.1262
912.412	18.6945
916.642	36.128
920.87	35.0994
925.096	9.12744
929.321	18.4843
933.543	9.23358
937.763	-8.57111
941.981	14.2741
946.197	24.2017
950.412	11.72
954.622	-10.1037
958.832	25.7255
963.04	21.2015
967.246	64.5938
971.451	56.0482
975.653	49.8168
979.853	67.0326
984.052	103.469
988.248	146.265
992.442	215.596
996.633	292.945
1000.82	412.312
1005.01	428.217
1009.2	389.104
1013.38	290.369
1017.57	268.968
1021.75	268.873
1025.92	254.764
1030.1	276.694
1034.27	314.44
1038.45	430.315
1042.62	596.536
1046.78	866.548
1050.95	950.4
1055.12	914.885
1059.28	834.72
1063.44	866.386
1067.6	924.85
1071.75	1149.51
1075.91	1373.7
1080.06	1787.04
1084.21	2500.06
1088.36	3716.46
1092.51	5517.79
1096.65	7033.87
1100.8	6881.98
1104.94	4810.47
1109.08	2957.3
1113.21	1842.37
1117.35	1259.69
1121.48	969.531
1125.61	913.106
1129.74	880.568
1133.87	1000.91
1137.99	1236.14
1142.12	1703.14
1146.24	2168.01
1150.36	2226.53
1154.48	1895.75
1158.59	1375.77
1162.71	921.068
1166.82	705.301
1170.93	499.661
1175.04	383.611
1179.14	261.425
1183.25	218.684
1187.35	163.505
1191.45	136.872
1195.55	93.7979
1199.65	79.3481
1203.74	58.7365
1207.83	69.6944
1211.92	100.882
1216.01	87.5037
1220.1	112.543
1224.19	110.42
1228.27	113.453
1232.35	134.707
1236.43	203.335
1240.51	209.282
1244.58	295.966
1248.66	596.463
1252.73	727.749
1256.8	436.845
1260.87	433.633
1264.93	680.605
1269	5224.54
1273.06	6771.76
1277.12	1774.65
1281.18	475.309
1285.23	359.7
1289.29	259.85
1293.34	223.206
1297.39	220.664
1301.44	203.943
1305.49	210.267
1309.53	164.125
1313.58	165.279
1317.62	168.236
1321.66	164.011
1325.7	155.553
1329.73	185.218
1333.77	189.654
1337.8	207.91
1341.83	238.003
1345.86	246.944
1349.88	296.699
1353.91	391.059
1357.93	528.812
1361.95	489.509
1365.97	561.344
1369.99	1722.19
1374	12091.4
1378.02	8282.65
1382.03	1569.46
1386.04	520.915
1390.05	496.981
1394.05	980.175
1398.06	1106.67
1402.06	455.945
1406.06	233.366
1410.06	206.83
1414.05	165.51
1418.05	110.319
1422.04	81.7003
1426.03	71.7448
1430.02	70.4461
1434.01	69.1622
1438	44.156
1441.98	23.0867
1445.96	18.7298
1449.94	-12.3092
1453.92	0.987274
1457.9	9.28937
1461.87	-10.0807
1465.85	1.95602
1469.82	-9.66382
1473.78	-10.4304
1477.75	-10.273
1481.72	1.58313
1485.68	-2.28586
1489.65	-6.18405
1493.61	-19.8254
1497.56	2.61996
1501.52	-11.9682
1505.47	-12.8744
1509.43	-1.08087
1513.38	0.0162048
1517.33	-9.5687
1521.27	-3.60611
1525.22	-0.557648
1529.16	-14.9609
1533.11	12.3432
1537.05	-3.02121
1540.98	-2.88644
1544.92	8.85733
1548.86	11.8592
1552.79	1.27713
1556.72	-1.60864
1560.65	4.15625
1564.58	-12.3921
1568.5	9.71259
1572.43	12.4193
1576.35	-7.11246
1580.27	5.19803
1584.19	18.4279
1588.1	-7.90509
1592.02	6.21002
1595.93	12.5832
1599.84	14.124
1603.75	23.3492
1607.66	12.4416
1611.57	16.8799
1615.47	28.9834
1619.37	30.5632
1623.27	25.4028
1627.17	22.1906
1631.07	2.73227
1634.97	17.8057
1638.86	8.91864
1642.75	21.1518
1646.64	20.9844
1650.53	38.0875
1654.42	27.3857
1658.3	20.4666
1662.18	37.527
1666.07	29.5395
1669.94	26.3033
1673.82	24.8799
1677.7	28.229
1681.57	38.1255
1685.44	44.0736
1689.31	37.5035
1693.18	16.5037
1697.05	24.1965
1700.92	31.8051
1704.78	45.9877
1708.64	43.8611
1712.5	35.018
1716.36	36.6263
1720.21	28.7715
1724.07	32.27
1727.92	36.6585
1731.77	34.3892
1735.62	29.3299
1739.47	44.8291
1743.32	51.807
1747.16	55.9655
1751.01	52.8553
1754.85	66.5663
1758.69	80.425
1762.52	78.1346
1766.36	67.2351
1770.19	62.9427
1774.02	56.9325
1777.85	41.6024
1781.68	41.2403
1785.51	35.317
1789.33	48.0991
1793.16	42.1964
1796.98	30.6409
1800.8	37.8217
1804.62	27.8848
1808.43	36.7322
1812.25	29.5276
1816.06	50.5521
1819.87	20.4994
1823.68	41.3109
1827.49	42.2439
1831.3	14.7991
1835.1	28.7666
1838.9	35.1258
1842.71	18.8517
1846.51	41.9876
1850.3	24.7632
1854.1	25.2422
1857.89	35.9221
1861.69	22.2102
1865.48	30.8551
1869.27	17.2035
1873.05	29.5775
1876.84	22.539
1880.62	24.7735
1884.4	40.9444
1888.19	39.5908
1891.96	28.4559
1895.74	40.3367
1899.52	31.9698
1903.29	25.5674
1907.06	28.4214
1910.83	41.439
1914.6	22.3115
1918.37	26.2415
1922.13	30.3646
1925.9	36.3817
1929.66	27.6236
1933.42	19.786
1937.18	6.31735
1940.94	21.7271
1944.69	32.5118
1948.44	30.2153
1952.2	34.2485
1955.95	21.2654
1959.69	40.0582
1963.44	67.2047
1967.19	49.2511
1970.93	66.8777
1974.67	98.4263
1978.41	98.9266
1982.15	101.235
1985.89	110.95
1989.62	127.124
1993.35	120.831
1997.09	135.865
2000.82	127.572
2004.55	132.294
2008.27	94.4559
2012	104.629
2015.72	95.458
2019.44	86.4994
2023.16	76.8408
2026.88	71.074
2030.6	64.4178
2034.31	63.4165
2038.03	63.449
2041.74	47.8888
2045.45	47.8697
2049.16	41.4503
2052.86	27.7656
2056.57	34.248
2060.27	40.8937
2063.98	18.3655
2067.67	31.708
2071.37	16.5615
2075.07	27.212
2078.77	17.5817
2082.46	20.9096
2086.15	27.9287
2089.84	36.4815
2093.53	8.67612
2097.22	20.0236
2100.9	34.127
2104.59	23.9578
2108.27	15.6006
2111.95	12.7849
2115.63	12.7544
2119.31	13.6211
2122.98	32.0234
2126.66	20.6476
2130.33	12.9614
2134	8.97266
2137.67	15.1464
2141.34	17.5674
2145	14.4127
2148.67	12.1732
2152.33	3.51221
2155.99	26.9798
2159.65	0.962524
2163.31	18.9276
2166.96	12.2489
2170.62	-1.65335
2174.27	6.44348
2177.92	-5.43471
2181.57	1.84668
2185.22	15.4818
2188.87	9.17694
2192.51	21.1747
2196.15	-3.10913
2199.8	2.69684
2203.44	7.63474
2207.07	13.5415
2210.71	3.97067
2214.35	-3.75594
2217.98	4.09866
2221.61	15.6593
2225.24	14.3965
2228.87	15.8763
2232.5	-5.69641
2236.12	-0.513306
2239.75	9.30875
2243.37	-8.65523
2246.99	-10.8986
2250.61	2.6748
2254.23	20.05
2257.85	10.4477
2261.46	15.7656
2265.07	-0.469604
2268.68	-3.59836
2272.29	2.72079
2275.9	7.10977
2279.51	30.3001
2283.11	25.9836
2286.72	-1.95663
2290.32	20.1538
2293.92	18.6133
2297.52	13.2949
2301.11	18.3977
2304.71	20.6179
2308.3	15.1999
2311.9	66.6161
2315.49	509.475
2319.08	754.994
2322.66	208.156
2326.25	40.3669
2329.84	30.7771
2333.42	24.951
2337	15.3327
2340.58	35.832
2344.16	23.3406
2347.73	16.4854
2351.31	21.8107
2354.88	28.9725
2358.45	32.358
2362.03	46.8855
2365.59	17.6723
2369.16	24.7649
2372.73	24.4923
2376.29	51.9291
2379.85	33.1404
2383.41	18.1348
2386.97	33.5578
2390.53	33.3678
2394.09	24.0584
2397.64	31.3526
2401.2	33.233
2404.75	27.019
2408.3	25.4201
2411.85	42.2791
2415.39	27.1013
2418.94	36.7716
2422.48	30.8641
2426.03	25.0045
2429.57	10.8837
2433.11	23.5834
2436.64	25.2685
2440.18	29.7726
2443.72	29.6589
2447.25	28.6136
2450.78	1.40985
2454.31	23.8418
2457.84	17.0444
2461.37	33.532
2464.89	28.3429
2468.42	24.7955
2471.94	37.5111
2475.46	28.9973
2478.98	27.9899
2482.5	28.9103
2486.01	35.3727
2489.53	12.4917
2493.04	25.5002
2496.55	27.0652
2500.06	25.9069
2503.57	34.9463
2507.08	16.8246
2510.58	34.1223
2514.09	17.879
2517.59	25.9005
2521.09	21.8828
2524.59	5.65633
2528.09	24.8619
2531.59	30.2379
2535.08	24.5634
2538.58	43.8849
2542.07	21.74
2545.56	34.786
2549.05	17.4827
2552.54	19.571
2556.02	30.0577
2559.51	24.0191
2562.99	5.89247
2566.47	45.4736
2569.95	18.1868
2573.43	4.84836
2576.91	34.5983
2580.38	23.2002
2583.85	11.7429
2587.33	43.7212
2590.8	32.1703
2594.27	31.8177
2597.74	22.8347
2601.2	19.6142
2604.67	29.7514
2608.13	21.5408
2611.59	16.9156
2615.06	17.8576
2618.51	23.6972
2621.97	40.9521
2625.43	31.2411
2628.88	21.4511
2632.33	33.7017
2635.79	37.2262
2639.24	25.3168
2642.69	26.7801
2646.13	32.0028
2649.58	32.4109
2653.02	33.6986
2656.47	30.1446
2659.91	28.4382
2663.35	15.3365
2666.79	45.7235
2670.22	23.1682
2673.66	19.5041
2677.09	28.0892
2680.52	30.1176
2683.95	-0.514008
2687.39	15.6907
2690.81	6.85133
2694.24	29.7879
2697.66	12.5941
2701.09	24.3239
2704.51	15.5807
2707.93	4.05933
2711.35	23.405
2714.77	16.7617
2718.18	23.1947
2721.6	31.5494
2725.01	30.6214
2728.42	9.16046
2731.84	12.908
2735.24	15.7071
2738.65	6.32376
2742.06	7.22189
2745.46	9.00351
2748.86	36.1157
2752.27	13.427
2755.67	13.2611
2759.07	18.7081
2762.46	20.3926
2765.86	9.75023
2769.25	16.0191
2772.65	12.814
2776.04	29.3665
2779.43	10.0638
2782.82	18.9774
2786.2	22.2096
2789.59	9.43405
2792.98	10.7567
2796.36	-10.4811
2799.74	-1.65729
2803.12	12.7345
2806.5	17.7284
2809.88	8.65381
2813.25	4.25232
2816.63	17.6007
2820	-0.843872
2823.37	23.7112
2826.74	2.56293
2830.11	27.1328
2833.48	3.2601
2836.84	-0.0568237
2840.21	19.9562
2843.57	23.2536
2846.93	17.2987
2850.29	16.0999
2853.65	21.497
2857.01	10.0487
2860.36	14.5141
2863.72	4.04031
2867.07	16.0484
2870.42	8.37723
2873.77	20.3971
2877.12	1.39661
2880.47	2.11743
2883.81	20.733
2887.16	5.40329
2890.5	14.5831
2893.84	16.2021
2897.18	6.40729
2900.52	-2.49338
2903.86	12.2071
2907.19	8.89911
2910.53	21.651
2913.86	13.5624
2917.19	21.5384
2920.52	18.114
2923.85	22.24
2927.18	12.1539
2930.51	21.8764
2933.83	16.4426
2937.15	11.9145
2940.48	53.5903
2943.8	26.429
2947.11	15.3218
2950.43	27.7568
2953.75	7.26187
2957.06	-0.982574
2960.38	15.2385
2963.69	10.8258
2967	19.5673
2970.31	6.82568
2973.62	13.8352
2976.92	13.3546
2980.23	8.23291
2983.53	13.3994
2986.84	16.7113
2990.14	7.83847
2993.44	30.9072
2996.73	7.03165
3000.03	15.1157
3003.33	15.682
3006.62	22.8383
3009.91	40.3832
3013.2	21.2382
3016.49	21.8702
3019.78	14.9561
3023.07	25.0127
3026.35	21.872
3029.64	-0.150604
3032.92	18.4297
3036.2	4.87735
3039.48	6.43973
3042.76	27.8793
3046.04	2.96649
3049.32	-0.180756
3052.59	21.3092
3055.86	6.80972
3059.14	15.9997
3062.41	14.6654
3065.68	8.63779
3068.94	-5.96719
3072.21	19.2264
3075.48	20.421
3078.74	-1.76221
3082	35.6925
3085.26	27.9214
3088.52	17.2825
3091.78	37.1229
3095.04	5.67834
3098.29	29.912
3101.55	21.0842
3104.8	28.3636
3108.05	22.4889
3111.3	21.3277
3114.55	31.4919
3117.8	38.839
3121.04	18.5878
3124.29	21.1953
3127.53	46.6707
3130.77	31.178
3134.02	22.3636
3137.25	33.561
3140.49	43.7969
3143.73	35.9232
3146.96	40.4528
3150.2	27.8486
3153.43	40.0529
3156.66	51.2998
3159.89	41.5784
3163.12	56.6586
3166.35	45.0314
3169.57	67.7331
3172.8	58.9239
3176.02	45.3369
3179.24	76.5725
3182.46	73.4603
3185.68	92.3011
3188.9	92.979
3192.12	92.7005
3195.33	74.3238
3198.55	102.639
3201.76	76.6539
3204.97	85.9348
3208.18	96.1842
3211.39	114.069
3214.6	118.664
3217.8	110.93
3221.01	121.279
3224.21	121.188
3227.41	115.441
3230.61	131.592
3233.81	134.468
3237.01	132.565
3240.21	133.623
3243.4	135.668
3246.59	151.083
3249.79	176.051
3252.98	175.354
3256.17	165.136
3259.36	169.224
3262.54	181.85
3265.73	203.018
3268.92	224.129
3272.1	198.388
3275.28	215.611
3278.46	227.1
3281.64	248.03
3284.82	235.446
3288	289.674
3291.17	275.153
3294.35	281.67
3297.52	296.738
3300.69	315.62
3303.86	342.254
3307.03	346.823
3310.2	373.202
3313.36	379.492
3316.53	407.575
3319.69	427.064
3322.85	447.447
3326.02	468.757
3329.18	498.558
3332.33	512.263
3335.49	533.569
3338.65	555.869
3341.8	588.587
3344.95	635.442
3348.11	684.383
3351.26	705.273
3354.41	744.061
3357.56	782.971
3360.7	818.178
3363.85	862.964
3366.99	900.256
3370.13	944.24
3373.28	976.986
3376.42	1021.24
3379.56	1136.43
3382.69	1163.93
3385.83	1243.39
3388.97	1328.75
3392.1	1344.19
3395.23	1464.69
3398.36	1511.9
3401.49	1600
3404.62	1756.75
3407.75	1856.06
3410.88	1958.55
3414	2099.27
3417.13	2268.26
3420.25	2467.86
3423.37	2623.58
3426.49	2830.41
3429.61	3051.15
3432.73	3291.56
3435.84	3598.08
3438.96	3832.96
3442.07	4202.79
3445.18	4762.22
3448.29	5380.36
3451.4	6644.15
3454.51	8319.13
3457.62	10796.4
3460.72	12309.7
3463.83	11748.9
3466.93	9800.42
3470.03	7931.8
3473.13	6775.67
3476.23	6030.33
3479.33	5574.23
3482.43	5374.41
3485.53	5243.07
3488.62	5130.24
3491.71	5149.57
3494.81	5216.6
3497.9	5159.81
3500.99	5227.17
3504.07	5283.31
3507.16	5384.67
3510.25	5513.2
3513.33	5768.7
3516.41	5910.26
3519.5	6304.24
3522.58	6583.88
3525.66	7096.22
3528.73	7506.84
3531.81	8074.88
3534.89	8545.11
3537.96	9026.16
3541.03	9147.35
3544.11	8939.32
3547.18	8358.67
3550.25	7437.8
3553.32	6403.15
3556.38	5390.53
3559.45	4436.44
3562.51	3681.94
3565.58	3084.97
3568.64	2674.7
3571.7	2247.95
3574.76	1960.02
3577.82	1712.89
3580.87	1554.7
3583.93	1388.74
3586.98	1281.44
3590.04	1153.28
3593.09	1065.73
3596.14	965.867
3599.19	932.256
3602.24	897.71
3605.29	834.651
3608.33	797.104
3611.38	776.596
3614.42	705.954
3617.46	675.014
3620.5	654.525
3623.54	656.729
3626.58	621.234
3629.62	599.952
3632.65	588.045
3635.69	548.792
3638.72	538.001
3641.76	498.145
3644.79	435.796
3647.82	440.424
3650.84	418.489
3653.87	383.465
3656.9	372.047
3659.92	333.863
3662.95	329.427
3665.97	284.336
3668.99	294.528
3672.01	284.106
3675.03	272.744
3678.05	237.789
3681.07	222.643
3684.08	206.49
3687.1	226.246
3690.11	201.554
3693.12	179.671
3696.13	180.49
3699.14	184.994
3702.15	168.725
3705.16	176.151
3708.16	163.62
3711.17	159.559
3714.17	132.623
3717.17	115.11
3720.17	125.199
3723.17	120.949
3726.17	123.313
3729.17	96.1069
3732.16	95.5207
3735.16	91.0737
3738.15	93.2358
3741.14	76.3129
3744.13	76.4703
3747.13	64.2194
3750.11	60.4886
3753.1	48.1738
3756.09	70.9863
3759.07	69.1003
3762.06	49.1814
3765.04	35.883
3768.02	42.4869
3771	17.8758
3773.98	29.2535
3776.96	26.4598
3779.94	39.7458
3782.91	27.5355
3785.89	20.0551
3788.86	27.6988
3791.83	12.7055
3794.8	21.3615
3797.77	12.1103
3800.74	22.7013
3803.71	13.5139
3806.68	-6.99393
3809.64	11.2342
3812.61	-4.52615
3815.57	-9.88596
3818.53	4.62814
3821.49	11.6041
3824.45	-5.06879
3827.41	-21.7284
3830.36	-13.747
3833.32	-19.9753
3836.27	-7.18655
3839.23	-30.4453
3842.18	-8.09604
3845.13	-14.2393
3848.08	-27.0317
3851.03	-18.8526
3853.98	-2.99411
3856.92	-20.4843
3859.87	-7.41183
3862.81	-11.499
3865.75	-18.4579
3868.7	-28.2757
3871.64	-30.4395
3874.57	-16.2812
3877.51	-12.6438
3880.45	-9.96652
3883.39	-25.5407
3886.32	-6.53149
3889.25	0.00482178
3892.18	-20.3523
3895.12	-23.3823
3898.05	-25.4486
3900.97	-21.7357
3903.9	-17.9858
3906.83	-23.8403
3909.75	-27.682
3912.68	-25.7328
3915.6	-14.1521
3918.52	-20.7885
3921.44	-24.425
3924.36	-24.2194
3927.28	-18.2281
3930.2	-24.67
3933.11	-8.05121
3936.03	-15.2421
3938.94	-46.2263
3941.86	-26.3235
3944.77	-17.8606
3947.68	-23.6589
3950.59	-14.9778
3953.49	-23.4198
3956.4	-32.7166
3959.31	-21.7784
3962.21	-6.88904
3965.12	-10.0872
3968.02	-0.700348
3970.92	-26.6807
3973.82	3.1069
3976.72	-0.585175
3979.61	-7.06647
3982.51	-5.76425
3985.41	14.8837
3988.3	-7.61893
3991.19	27.6998
3994.09	11.1818
3996.98	8.32422
3999.87	30.6286