File: Data/3-Raman/processed/bu19(2)w-a-ff1-fi07-v_1800 (450-850nm)_532nm_edge_100%_x100_vis_lwd_h100um_30sx2_01.txt
#Acq. time (s)=	30
#Accumulations=	2
#Range (cm-¹)=	1200...2365
#Windows=	3
#Auto scanning=	Off
#Autofocus=	Off
#Macrospot=	Off
#AutoExposure=	Off
#Spike filter=	Multiple accum.
#Delay time (s)=	2
#Binning=	1
#Readout mode=	Signal
#DeNoise=	Off
#ICS correction=	On
#Dark correction=	Off
#Inst. Process=	Off
#Detector Gain=	Best Dynamic
#Detector ADC=	50 kHz HS
#Detector temperature (°C)=	-60.28
#Instrument=	LabRAM HR Evol
#Detector=	SIN-EM FIVIS
#Objective=	x100_VIS_LWD
#Grating=	1800 (450-850nm)
#ND Filter=	100%
#Laser=	532nm_Edge
#Hole=	100.021
#Temperature=	0
#Range=	Visible
#StageXY=	75x50mm Scan+
#StageZ=	Z motor
#X (µm)=	0
#Y (µm)=	0
#Z (µm)=	-66.9
#Full time(mm:ss)=	3:24
#Project=	21_11_26
#Sample=	BU19(2)w
#Site=
#Title=	BU19(2)w-A-FF1-FI07-V_1800 (450-850nm)_532nm_Edge_100%_x100_VIS_LWD_H100um_30sX2
#Remark=
#Date=	26.11.2021 16:46
#Acquired=	26.11.2021 16:46:02
#Base:Fit=	16.12.2021 16:00:56
#Base:Fit=	16.12.2021 16:08:03
#Base:Sub=	16.12.2021 16:08:04
1202.72	2.96459
1203.84	16.543
1204.95	5.24846
1206.06	1.40273
1207.17	1.79489
1208.28	6.51432
1209.39	6.92544
1210.5	0.951134
1211.61	4.48602
1212.72	2.67451
1213.83	-3.37565
1214.94	5.52786
1216.05	0.56543
1217.16	0.807831
1218.27	1.05907
1219.38	2.39298
1220.49	4.78546
1221.6	-3.43432
1222.71	-1.13873
1223.81	-3.13192
1224.92	-1.91299
1226.03	0.436699
1227.14	1.69841
1228.25	3.83875
1229.35	-7.71073
1230.46	0.033844
1231.57	4.20122
1232.67	1.21528
1233.78	0.30513
1234.89	-3.72212
1235.99	4.85929
1237.1	3.92107
1238.2	9.19299
1239.31	6.0646
1240.41	3.00113
1241.52	1.01488
1242.62	2.1311
1243.73	-12.4299
1244.83	0.233772
1245.94	15.9557
1247.04	8.65479
1248.14	11.846
1249.25	-0.684937
1250.35	12.9739
1251.45	4.59756
1252.56	9.81998
1253.66	9.81724
1254.76	7.82796
1255.87	7.89063
1256.97	13.1786
1258.07	22.6023
1259.17	23.6417
1260.27	23.7476
1261.37	53.9373
1262.48	82.4834
1263.58	125.905
1264.68	89.9665
1265.78	38.6421
1266.88	28.2333
1267.98	18.9569
1269.08	32.7365
1270.18	21.2554
1271.28	14.9302
1272.38	21.2614
1273.47	25.6071
1274.57	21.5496
1275.67	23.7039
1276.77	32.2222
1277.87	44.9642
1278.97	52.4819
1280.07	88.3199
1281.16	229.328
1282.26	745.362
1283.36	1846.64
1284.45	1385.85
1285.55	300.497
1286.65	86.7412
1287.75	49.8984
1288.84	40.4615
1289.94	24.8011
1291.03	25.9517
1292.13	20.7482
1293.22	10.2876
1294.32	23.1183
1295.42	17.9481
1296.51	10.8208
1297.61	13.0086
1298.7	19.3863
1299.79	8.87367
1300.89	7.93583
1301.98	6.98759
1303.08	6.05121
1304.17	-1.26754
1305.26	7.27664
1306.35	9.42706
1307.45	3.19372
1308.54	-1.96211
1309.63	-3.93636
1310.73	-4.86311
1311.82	8.98833
1312.91	3.86981
1314	-1.30497
1315.09	-3.2811
1316.18	-1.00308
1317.28	-0.88018
1318.37	-1.77824
1319.46	-2.69202
1320.55	-5.7185
1321.64	1.77252
1322.73	-3.41752
1323.82	3.03545
1324.91	-2.0808
1326	1.19151
1327.09	4.39146
1328.18	4.67335
1329.27	2.81106
1330.35	0.855804
1331.44	-2.19735
1332.53	2.08831
1333.62	6.37283
1334.71	1.21407
1335.79	1.33286
1336.88	-0.628822
1337.97	4.76411
1339.06	0.701035
1340.14	1.9283
1341.23	7.35473
1342.32	5.41975
1343.4	2.40881
1344.49	3.63829
1345.58	-1.42893
1346.66	-1.32372
1347.75	4.00876
1348.83	5.21562
1349.92	6.40583
1351	9.67244
1352.09	-0.579643
1353.17	3.82362
1354.25	0.96936
1355.34	4.14339
1356.42	2.26389
1357.51	9.70849
1358.59	11.9467
1359.67	5.88106
1360.76	6.02649
1361.84	10.3593
1362.92	10.5439
1364	19.0664
1365.09	29.6326
1366.17	23.5604
1367.25	17.4814
1368.33	26.9967
1369.41	104.781
1370.5	32.597
1371.58	26.5396
1372.66	25.6008
1373.74	23.6991
1374.82	36.254
1375.9	40.5898
1376.98	33.5548
1378.06	36.8285
1379.14	49.5727
1380.22	48.7061
1381.3	53.8482
1382.38	83.7424
1383.46	111.456
1384.54	217.18
1385.61	596.326
1386.69	2899.75
1387.77	3328.57
1388.85	505.91
1389.93	161.207
1391	97.5252
1392.08	57.6619
1393.16	56.7665
1394.23	50.7993
1395.31	39.7524
1396.39	33.8548
1397.46	34.0237
1398.54	29.1039
1399.62	34.4681
1400.69	31.6394
1401.77	30.866
1402.84	32.2297
1403.92	36.6257
1404.99	37.7979
1406.07	62.5542
1407.14	104.752
1408.22	192.152
1409.29	188.327
1410.37	80.8752
1411.44	35.8546
1412.51	24.7693
1413.59	14.9037
1414.66	15.0253
1415.73	14.2267
1416.81	15.4713
1417.88	15.6977
1418.95	12.8211
1420.02	12.999
1421.1	14.1678
1422.17	13.3356
1423.24	15.7133
1424.31	16.7135
1425.38	13.826
1426.45	17.1057
1427.52	10.0503
1428.59	7.10534
1429.67	7.30181
1430.74	9.57858
1431.81	8.8031
1432.87	7.9217
1433.95	6.98951
1435.01	5.13132
1436.08	5.30209
1437.15	2.3821
1438.22	8.68143
1439.29	3.74426
1440.36	0.86969
1441.43	6.17273
1442.49	2.22617
1443.56	6.48422
1444.63	7.65612
1445.7	2.72378
1446.77	4.91325
1447.83	-0.0796089
1448.9	0.0845909
1449.97	-0.799221
1451.03	6.50121
1452.1	1.50513
1453.17	-0.403088
1454.23	0.770206
1455.3	2.95604
1456.36	1.05509
1457.43	-0.876503
1458.49	2.32373
1459.56	-1.63409
1460.62	-0.485332
1461.69	3.72033
1462.75	2.79132
1463.82	-0.19186
1464.88	6.12002
1465.94	-5.12865
1467.01	-1.96052
1468.07	3.25097
1469.13	-1.73944
1470.2	1.40615
1471.26	-0.541893
1472.32	6.67408
1473.39	3.72004
1474.45	1.76924
1475.51	-5.24324
1476.57	1.96928
1477.63	-2.01897
1478.69	3.14899
1479.76	1.1856
1480.82	-4.85376
1481.88	-4.77306
1482.94	1.43689
1484	3.5666
1485.06	1.5364
1486.12	-2.44146
1487.18	5.75431
1488.24	0.750332
1489.3	-2.23718
1490.36	-1.15575
1491.42	-3.12062
1492.48	0.996708
1493.53	-6.00975
1494.59	-0.882698
1495.65	-2.84809
1496.71	1.22389
1497.77	-0.737556
1498.82	0.336582
1499.88	-0.598232
1500.94	-0.531242
1502	3.55198
1503.05	2.5874
1504.11	-1.40794
1505.17	-0.338089
1506.22	4.72027
1507.28	1.75583
1508.34	2.81674
1509.39	0.853668
1510.45	-0.0977707
1511.5	5.95708
1512.56	-0.113781
1513.61	0.892509
1514.67	-0.0420952
1515.72	-2.04044
1516.78	1.97832
1517.83	1.00945
1518.88	0.0606308
1519.94	0.109024
1520.99	0.140312
1522.05	2.18929
1523.1	1.20251
1524.15	4.19514
1525.2	6.21069
1526.26	3.254
1527.31	2.30277
1528.36	-4.6991
1529.41	2.32627
1530.47	1.33833
1531.52	-4.62343
1532.57	-0.598026
1533.62	6.4848
1534.67	-1.512
1535.72	-3.51478
1536.77	1.46203
1537.82	3.43719
1538.87	1.42902
1539.92	-2.50041
1540.97	-1.42362
1542.02	4.57964
1543.07	-0.455704
1544.12	0.51289
1545.17	-2.45393
1546.22	-0.405689
1547.27	-0.388279
1548.32	-0.399437
1549.37	3.58912
1550.42	-1.39507
1551.46	4.74326
1552.51	3.74577
1553.56	-2.30081
1554.61	2.68926
1555.65	1.65407
1556.7	1.65289
1557.75	4.66597
1558.79	0.628082
1559.84	0.583992
1560.89	1.5632
1561.93	-2.42882
1562.98	1.58918
1564.02	-0.420578
1565.07	3.60976
1566.11	4.3486
1567.16	-4.46708
1568.2	-0.446697
1569.25	-4.44212
1570.29	1.53173
1571.34	1.5247
1572.38	2.49886
1573.43	2.46701
1574.47	-0.539116
1575.51	3.48656
1576.56	-4.50995
1577.6	1.43032
1578.64	-1.61543
1579.69	4.35445
1580.73	-0.628448
1581.77	0.341545
1582.81	-0.686584
1583.85	-0.704254
1584.9	1.27923
1585.94	-0.725727
1586.98	-1.76083
1588.02	-1.78606
1589.06	5.18213
1590.1	0.208851
1591.14	1.20406
1592.18	0.188
1593.22	4.11878
1594.26	3.05151
1595.3	1.05964
1596.34	-0.95303
1597.38	1.02525
1598.42	5.98151
1599.46	-2.0109
1600.5	3.90242
1601.54	0.870831
1602.58	-3.14104
1603.62	-5.16298
1604.66	-0.239716
1605.69	0.739899
1606.73	-6.17985
1607.77	0.71344
1608.81	-1.86027
1609.84	4.12945
1610.88	2.32608
1611.92	0.00165176
1612.95	2.0487
1613.99	0.443001
1615.03	-1.30505
1616.06	0.592094
1617.1	0.614384
1618.13	-0.0418358
1619.17	2.07924
1620.2	-0.567757
1621.24	-2.11455
1622.27	1.1444
1623.31	2.01756
1624.34	0.454212
1625.38	-0.124565
1626.41	-1.53452
1627.45	0.284595
1628.48	0.435505
1629.51	0.610397
1630.55	2.37887
1631.53	-3.32981
1632.57	3.57381
1633.62	-0.381828
1634.66	-2.35423
1635.71	5.51754
1636.75	0.563354
1637.8	1.51664
1638.84	-3.42607
1639.89	2.4711
1640.93	2.46949
1641.98	-0.492401
1643.02	0.476131
1644.06	2.43053
1645.11	-6.44822
1646.15	0.442844
1647.19	-0.562584
1648.24	1.38567
1649.28	0.431244
1650.32	6.33027
1651.37	-1.51618
1652.41	0.456749
1653.45	-3.49796
1654.49	0.446957
1655.53	-1.512
1656.57	0.496609
1657.62	0.494106
1658.66	-0.509392
1659.7	2.42434
1660.74	-2.51408
1661.78	1.4567
1662.82	0.512356
1663.86	2.49186
1664.9	2.4638
1665.94	-0.548054
1666.98	-1.48743
1668.02	-2.49415
1669.06	-1.49936
1670.1	2.47955
1671.14	-2.43152
1672.18	-0.459637
1673.21	-0.453529
1674.25	3.51305
1675.29	2.5505
1676.33	3.55291
1677.37	-2.37797
1678.4	0.576244
1679.44	3.52063
1680.48	-0.443241
1681.52	0.536484
1682.55	0.540703
1683.59	2.5194
1684.63	-3.41074
1685.66	3.50086
1686.7	3.51165
1687.73	-3.38603
1688.77	3.51778
1689.81	-2.42448
1690.84	2.50647
1691.88	0.555969
1692.91	-2.40036
1693.95	0.530491
1694.98	3.46552
1696.01	-1.44478
1697.05	0.546329
1698.08	3.4795
1699.12	3.46121
1700.15	-7.35399
1701.18	-4.39993
1702.22	-2.43948
1703.25	0.497787
1704.28	-1.46513
1705.32	-0.463257
1706.35	-3.40673
1707.38	0.498981
1708.41	0.4688
1709.44	-3.48221
1710.48	-1.51873
1711.51	-0.513283
1712.54	-4.41484
1713.57	0.437923
1714.6	1.38881
1715.63	2.37994
1716.66	4.34746
1717.69	-2.52045
1718.72	4.25475
1719.75	0.359463
1720.78	6.21465
1721.81	1.32845
1722.84	4.22103
1723.87	1.29275
1724.9	-0.644833
1725.93	2.22839
1726.96	4.16817
1727.99	4.17257
1729.02	6.04007
1730.05	6.97871
1731.07	-1.71798
1732.1	-0.692001
1733.13	6.07224
1734.16	3.13755
1735.18	4.06738
1736.21	1.15736
1737.24	5.00582
1738.26	3.07578
1739.29	3.05852
1740.32	3.01445
1741.34	-1.80493
1742.37	4.8909
1743.4	4.89628
1744.42	9.67688
1745.45	1.07698
1746.47	0.12476
1747.5	7.74413
1748.52	0.0992241
1749.55	1.08135
1750.57	-1.73552
1751.6	5.94674
1752.62	6.87971
1753.64	4.9523
1754.67	3.03134
1755.69	5.88772
1756.71	9.67683
1757.74	4.89029
1758.76	-1.73791
1759.78	2.09077
1760.81	5.90424
1761.83	1.14097
1762.85	6.86105
1763.87	1.17996
1764.89	4.08193
1765.92	6.97497
1766.94	10.798
1767.96	4.14003
1768.98	7.94588
1770	6.93287
1771.02	6.97428
1772.04	16.5374
1773.06	7.0719
1774.08	8.06087
1775.1	6.18877
1776.12	12.9203
1777.14	8.17168
1778.16	7.20778
1779.18	2.4291
1780.2	6.24587
1781.22	8.18102
1782.24	6.30642
1783.26	6.35175
1784.28	12.1111
1785.29	5.48172
1786.31	6.44064
1787.33	3.61407
1788.35	6.57468
1789.37	4.73839
1790.38	4.7905
1791.4	2.88351
1792.42	3.82532
1793.43	6.72662
1794.45	6.75023
1795.47	4.88485
1796.48	3.98512
1797.5	-0.774349
1798.51	0.218548
1799.53	3.11269
1800.55	2.13833
1801.56	-0.741821
1802.58	3.12074
1803.59	3.16136
1804.61	3.19135
1805.62	2.27403
1806.64	6.17051
1807.65	5.22961
1808.66	-4.39553
1809.68	3.33193
1810.69	-0.508995
1811.7	5.28074
1812.72	0.476128
1813.73	-0.45969
1814.74	2.47925
1815.76	6.38372
1816.77	-0.364506
1817.78	5.41923
1818.79	-0.36322
1819.8	3.52172
1820.82	0.646687
1821.83	3.57508
1822.84	3.59895
1823.85	3.60582
1824.86	0.709843
1825.87	1.69793
1826.88	6.54863
1827.89	3.66038
1828.9	0.757996
1829.91	0.751404
1830.92	0.74152
1831.93	1.72856
1832.94	0.785919
1833.95	0.799805
1834.96	0.778606
1835.97	3.62762
1836.98	4.74662
1837.99	3.65332
1839	3.65234
1840	2.73941
1841.01	3.63243
1842.02	-2.23118
1843.03	0.634476
1844.04	1.59949
1845.04	0.636131
1846.05	2.5766
1847.06	4.5456
1848.07	0.556011
1849.07	-4.2523
1850.08	1.49448
1851.09	-3.35755
1852.09	1.42048
1853.1	2.37612
1854.1	1.39829
1855.11	0.397499
1856.11	3.23323
1857.12	-0.607494
1858.12	0.33279
1859.13	0.298916
1860.13	3.13707
1861.14	1.2361
1862.14	-0.66267
1863.15	-0.691147
1864.15	-2.63886
1865.15	1.14956
1866.16	1.09618
1867.16	2.9313
1868.16	-1.87842
1869.17	-0.938778
1870.17	1.89899
1871.17	0.934517
1872.17	-0.0373001
1873.18	2.78096
1874.18	-0.0905037
1875.18	1.76425
1876.18	2.64673
1877.18	-0.241043
1878.18	-1.24632
1879.19	2.58558
1880.19	-3.07476
1881.19	1.64474
1882.19	-0.3116
1883.19	-0.397224
1884.19	2.3807
1885.19	-4.21097
1886.19	-2.29368
1887.19	5.24209
1888.19	1.41818
1889.19	-1.46983
1890.19	3.20481
1891.19	3.21671
1892.18	-0.571323
1893.18	3.16518
1894.18	2.15216
1895.18	-0.697113
1896.18	0.240597
1897.18	-2.57027
1898.17	1.18744
1899.17	-1.6687
1900.17	2.99097
1901.16	1.09657
1902.16	1.11097
1903.16	2.05109
1904.16	2.96207
1905.15	1.06032
1906.15	0.0907707
1907.14	7.56272
1908.14	1.91769
1909.14	-0.900108
1910.13	5.70041
1911.13	-0.855858
1912.12	-1.80337
1913.12	2.88432
1914.11	0.0602455
1915.11	1.96624
1916.1	-1.80994
1917.1	-0.900078
1918.09	3.77988
1919.08	0.959919
1920.08	0.995682
1921.07	-0.903553
1922.06	-4.67387
1923.06	1.92385
1924.05	2.83641
1925.04	-0.978214
1926.04	-0.970493
1927.03	-3.7866
1928.02	-0.941559
1929.01	0.951874
1930	0.017704
1931	0.989544
1931.99	2.86744
1932.98	0.930672
1933.97	-0.977531
1934.96	1.96373
1935.95	-0.82983
1936.94	1.97789
1937.93	5.73592
1938.92	1.90905
1939.91	-1.89591
1940.9	5.73801
1941.89	4.80636
1942.88	-1.8743
1943.87	-1.91094
1944.86	0.00721359
1945.85	-3.79608
1946.84	0.0354614
1947.83	0.0138588
1948.82	0.949535
1949.8	-4.78258
1950.79	0.0371704
1951.78	-1.84075
1952.77	-1.82763
1953.76	-0.878281
1954.74	1.90589
1955.73	4.74487
1956.72	-3.8367
1957.7	-0.938313
1958.69	0.987637
1959.68	-1.92176
1960.66	3.80843
1961.65	-1.03267
1962.63	1.83354
1963.62	1.82599
1964.61	-0.095829
1965.59	0.846596
1966.58	-0.106972
1967.56	2.78112
1968.55	2.77542
1969.53	6.58478
1970.52	1.72483
1971.5	9.36407
1972.48	2.63664
1973.47	7.41179
1974.45	3.53812
1975.44	9.28185
1976.42	3.54013
1977.4	7.3692
1978.39	7.33619
1979.37	1.56098
1980.35	4.4301
1981.33	4.39793
1982.31	1.5
1983.3	10.0819
1984.28	9.08377
1985.26	10.0098
1986.24	11.8977
1987.22	3.30107
1988.21	13.7741
1989.19	9.85177
1990.17	10.6776
1991.15	11.8394
1992.13	12.8735
1993.11	14.9483
1994.09	12.978
1995.07	10.3658
1996.05	13.7146
1997.03	14.5828
1998.01	16.8152
1998.99	18.0065
1999.97	17.0463
2000.95	13.163
2001.92	17.2989
2002.9	19.1078
2003.88	18.564
2004.86	15.5699
2005.84	18.2232
2006.81	15.009
2007.79	16.8852
2008.77	18.6299
2009.75	14.1044
2010.73	17.3073
2011.7	14.0971
2012.68	19.251
2013.67	13.5472
2014.66	17.2247
2015.64	13.451
2016.63	17.2327
2017.62	16.333
2018.61	14.3895
2019.6	18.0661
2020.58	12.4278
2021.57	9.62479
2022.56	12.4269
2023.55	12.3875
2024.54	12.3524
2025.52	10.4277
2026.51	7.59826
2027.5	13.3329
2028.48	13.2832
2029.47	8.69246
2030.45	9.49678
2031.44	6.72687
2032.43	6.74387
2033.41	9.61288
2034.4	6.8247
2035.38	6.76921
2036.37	5.00229
2037.35	10.6118
2038.34	9.67551
2039.32	7.79056
2040.31	3.09833
2041.29	8.66733
2042.27	7.72792
2043.26	8.65484
2044.24	5.92309
2045.23	5.91254
2046.21	6.94844
2047.19	3.18992
2048.17	5.95187
2049.16	6.91096
2050.14	2.30792
2051.12	6.09072
2052.11	4.21593
2053.09	6.11474
2054.07	3.37305
2055.05	0.597633
2056.03	-1.27172
2057.01	1.53979
2058	0.632744
2058.98	6.29463
2059.96	7.27072
2060.94	3.53141
2061.92	3.56775
2062.9	4.53399
2063.88	0.831619
2064.86	1.80462
2065.84	-3.76832
2066.82	3.78546
2067.8	3.82496
2068.78	0.106159
2069.76	1.99849
2070.73	2.95742
2071.71	3.00582
2072.69	0.258839
2073.67	-2.54824
2074.65	4.07593
2075.63	-1.50796
2076.6	1.38589
2077.58	4.2228
2078.56	0.464993
2079.54	1.45419
2080.51	-3.20748
2081.49	4.37597
2082.47	-1.26728
2083.45	0.653492
2084.42	0.677422
2085.4	2.59562
2086.37	5.47091
2087.35	0.799084
2088.32	-2.00256
2089.3	0.870274
2090.28	0.922634
2091.25	0.0146561
2092.23	0.0695839
2093.2	0.142094
2094.18	1.15469
2095.15	1.19029
2096.13	4.04893
2097.1	0.26754
2098.07	-0.674641
2099.05	3.14244
2100.02	0.319
2101	-1.54321
2101.97	-1.49289
2102.94	2.33307
2103.92	-0.50388
2104.89	-1.41675
2105.86	3.38692
2106.83	-1.31881
2107.8	-3.18819
2108.78	-0.340099
2109.75	2.53954
2110.72	2.57787
2111.69	1.65541
2112.66	-2.12377
2113.63	4.57635
2114.61	-0.138847
2115.58	-3.90993
2116.55	-1.9932
2117.52	-2.92446
2118.49	-1.00743
2119.46	1.83488
2120.43	-1.00408
2121.4	-0.965626
2122.37	-0.905132
2123.34	1.99288
2124.31	2.02109
2125.28	0.108746
2126.25	0.0921555
2127.21	2.92944
2128.18	1.054
2129.15	1.07884
2130.12	-5.51435
2131.09	1.12149
2132.06	-0.756603
2133.02	2.08516
2133.99	1.17056
2134.96	3.09024
2135.93	3.11257
2136.89	0.280396
2137.86	1.26035
2138.83	-1.5501
2139.79	0.372814
2140.76	1.31609
2141.73	-1.48872
2142.69	3.23062
2143.66	-1.42211
2144.62	1.36442
2145.59	3.27557
2146.55	3.29768
2147.52	0.492435
2148.48	0.504612
2149.45	0.512375
2150.42	2.37652
2151.38	2.3959
2152.34	3.37914
2153.31	3.39462
2154.27	-0.344925
2155.24	2.4433
2156.2	1.4888
2157.16	0.568851
2158.13	-0.325558
2159.09	-0.294106
2160.05	-0.286781
2161.01	-1.22391
2161.98	0.656567
2162.94	0.680355
2163.9	-2.10634
2164.86	0.692631
2165.83	0.71722
2166.79	0.735203
2167.75	-2.05775
2168.71	0.713001
2169.67	1.67943
2170.63	0.814625
2171.59	-0.101791
2172.56	0.796764
2173.51	-1.05025
2174.48	0.840046
2175.44	-3.7833
2176.4	0.878635
2177.36	-0.038353
2178.32	1.8433
2179.28	1.84448
2180.23	-1.84607
2181.19	0.95488
2182.15	3.74897
2183.11	3.7559
2184.07	0.962055
2185.03	0.971348
2185.99	0.0765228
2186.95	0.122089
2187.9	5.74944
2188.86	-2.60296
2189.82	4.8033
2190.78	2.95172
2191.73	2.97774
2192.69	0.22493
2193.65	-0.666424
2194.6	1.25577
2195.56	1.26947
2196.52	-2.46137
2197.47	0.310467
2198.43	-1.52897
2199.38	4.09383
2200.34	8.81184
2201.3	-1.35177
2202.25	1.34795
2203.21	3.28053
2204.16	7.15649
2205.12	4.30377
2206.07	1.44203
2207.03	0.523232
2207.98	-0.373972
2208.93	1.52685
2209.89	1.55042
2210.84	3.43563
2211.8	2.53868
2212.75	1.64067
2213.7	-2.09144
2214.66	0.733593
2215.61	-0.16745
2216.56	-2.02156
2217.51	-1.08044
2218.47	1.73338
2219.42	-1.04294
2220.37	1.78727
2221.32	-1.94728
2222.27	6.43773
2223.23	-0.085886
2224.18	1.81938
2225.13	0.928764
2226.08	1.90603
2227.03	1.00441
2227.98	1.03078
2228.93	-2.71891
2229.88	-0.833714
2230.83	0.139822
2231.78	-0.76326
2232.73	0.208891
2233.68	-0.700958
2234.63	2.14215
2235.58	1.1841
2236.53	0.246275
2237.48	0.265522
2238.43	-0.625521
2239.38	-3.41172
2240.33	0.3545
2241.27	2.26195
2242.22	-1.49743
2243.17	0.407089
2244.12	1.34408
2245.07	2.30896
2246.01	0.46484
2246.96	-5.18363
2247.91	-0.43401
2248.85	-3.27334
2249.8	-0.428352
2250.75	1.46288
2251.69	3.33371
2252.64	-5.164
2253.59	1.50875
2254.53	-0.352135
2255.48	-2.24019
2256.42	-2.22782
2257.37	-2.20277
2258.32	-1.2342
2259.26	-2.16891
2260.2	1.65052
2261.15	-2.13321
2262.1	-1.15837
2263.04	0.766157
2263.98	-1.09863
2264.93	-1.05122
2265.87	1.83905
2266.81	-1.9917
2267.76	3.71417
2268.7	0.836996
2269.65	0.862534
2270.59	1.86278
2271.53	-6.71341
2272.47	-0.95525
2273.42	0.968576
2274.36	-1.89106
2275.3	0.0348644
2276.24	4.83493
2277.18	-2.79514
2278.13	2.04619
2279.07	-1.76863
2280.01	-0.825764
2280.95	-0.85121
2281.89	-5.65279
2282.83	-1.79886
2283.77	-0.80015
2284.71	1.17776
2285.65	-1.68327
2286.59	-1.69609
2287.54	-2.62165
2288.47	2.21323
2289.41	1.22916
2290.35	5.03827
2291.29	5.04581
2292.23	0.274597
2293.17	3.19551
2294.11	-3.52946
2295.05	-0.649689
2295.99	-1.62508
2296.93	1.24144
2297.86	1.26678
2298.8	-1.58764
2299.74	3.26475
2300.68	5.20067
2301.61	7.1548
2302.55	1.36694
2303.49	-0.563177
2304.43	-2.48168
2305.36	2.36934
2306.3	1.4192
2307.24	-0.504814
2308.17	0.454645
2309.11	2.38577
2310.04	-0.482742
2310.98	-3.37281
2311.92	-1.48212
2312.85	1.38716
2313.79	-0.532808
2314.72	1.44111
2315.66	-0.472046
2316.59	-3.40846
2317.52	0.443071
2318.46	1.41372
2319.39	1.39255
2320.33	2.34552
2321.26	7.17875
2322.2	7.20951
2323.13	8.19765
2324.06	12.0719
2325	12.0548
2325.93	21.6588
2326.86	68.8861
2327.79	257.756
2328.73	161.301
2329.66	38.8382
2330.59	17.634
2331.52	6.06036
2332.46	1.24322
2333.39	4.09958
2334.32	0.220562
2335.25	3.06995
2336.18	1.13181
2337.11	3.03024
2338.04	0.121092
2338.97	0.0957928
2339.91	2.95962
2340.84	2.91886
2341.77	5.73248
2342.7	-1.03344
2343.63	4.68587
2344.56	0.822762
2345.49	4.62106
2346.41	-1.18618
2347.34	2.60151
2348.27	-0.307489
2349.2	3.48795
2350.13	0.525644
2351.06	3.18482
2351.99	0.413744
2352.91	2.22568
2353.84	5.93682
2354.77	-0.782974
2355.7	4.88008
2356.63	-1.8685
2357.55	3.73897
2358.48	-0.146509
2359.41	-0.228346
2360.33	-0.316607
2361.26	1.47728
2362.19	1.36638
2363.11	-4.42725
2364.04	-0.742535
2364.97	0.0973358