File: Data/3-Raman/processed/bu19w-e-ff11-fi06-v_150 (500nm)_633nm_edge_100%_x100_vis_h50um_60sx2_01_0.txt
#Acq. time (s)=	60
#Accumulations=	2
#Range (cm-¹)=	100...4000
#Windows=	1
#Auto scanning=	Off
#Autofocus=	Off
#Macrospot=	Off
#AutoExposure=	Off
#Spike filter=	Multiple accum.
#Delay time (s)=	2
#Binning=	1
#Readout mode=	Signal
#DeNoise=	Off
#ICS correction=	On
#Dark correction=	Off
#Inst. Process=	Off
#Detector Gain=	Best Dynamic
#Detector ADC=	50 kHz HS
#Detector temperature (°C)=	-60.09
#Instrument=	LabRAM HR Evol
#Detector=	SIN-EM FIVIS
#Objective=	x100_VIS
#Grating=	150 (500nm)
#ND Filter=	100%
#Laser=	633nm_Edge
#Hole=	49.98
#Temperature=	0
#Range=	Visible
#StageXY=	75x50mm Scan+
#StageZ=	Z motor
#X (µm)=	0
#Y (µm)=	0
#Z (µm)=	-272.4
#Full time(mm:ss)=	2:04
#Project=	21_11_04
#Sample=	BU19w
#Site=
#Title=	BU19w-E-FF11-FI06-V_150 (500nm)_633nm_Edge_100%_x100_VIS_H50um_60sX2
#Remark=
#Date=	04.11.2021 15:52
#Acquired=	04.11.2021 15:52:12
#Base:Fit=	16.12.2021 17:39:50
#Base:Edit=	16.12.2021 17:53:02
#Base:Edit=	16.12.2021 17:53:03
#Base:Edit=	16.12.2021 17:53:03
#Base:Edit=	16.12.2021 17:53:04
#Base:Edit=	16.12.2021 17:53:04
#Base:Edit=	16.12.2021 17:53:04
#Base:Edit=	16.12.2021 17:53:05
#Base:Edit=	16.12.2021 17:53:06
#Base:Edit=	16.12.2021 17:53:06
#Base:Sub=	16.12.2021 17:53:08
102.881	125.997
109.397	108.122
115.908	86.7011
122.414	91.3063
128.914	89.4891
135.409	108.94
141.898	96.0529
148.383	92.0514
154.861	129.492
161.335	151.893
167.801	70.9955
174.264	31.404
180.721	15.8989
187.173	10.0894
193.62	7.28049
200.061	4.68593
206.496	6.1833
212.926	14.4764
219.352	43.8868
225.772	146.723
232.185	210.276
238.595	99.9753
244.999	57.505
251.397	41.7924
257.791	48.0043
264.178	47.7039
270.561	49.4249
276.939	80.6629
283.31	61.6796
289.678	39.8955
296.039	28.5839
302.396	54.2543
308.746	91.2647
315.093	264.262
321.433	416.391
327.768	261.059
334.099	120.994
340.423	76.2573
346.743	76.8107
353.058	94.3269
359.367	85.4334
365.671	55.8778
371.971	26.4175
378.265	12.0518
384.553	6.21191
390.837	16.4894
397.116	18.4592
403.389	26.2052
409.657	33.9711
415.92	53.0342
422.178	74.9516
428.431	114.473
434.678	125.297
440.921	95.5966
447.158	89.4647
453.391	111.399
459.618	73.6092
465.84	33.3404
472.057	22.0967
478.27	14.6844
484.477	20.3097
490.679	34.3205
496.876	40.8876
503.068	61.4609
509.255	84.8631
515.436	89.6602
521.613	86.1495
527.785	91.1391
533.952	84.0401
540.113	60.8729
546.27	33.7055
552.423	34.6631
558.568	28.9445
564.711	19.2754
570.848	18.9498
576.979	20.4114
583.107	32.1544
589.228	56.9584
595.345	88.3318
601.458	68.6357
607.565	62.1366
613.667	69.7
619.764	72.7108
625.856	41.9084
631.944	43.7671
638.026	39.7524
644.104	48.7402
650.177	51.0936
656.244	41.1225
662.308	25.557
668.365	15.6783
674.418	9.70113
680.467	12.1497
686.511	3.44989
692.549	-0.540184
698.582	-0.797657
704.611	11.1228
710.635	7.03064
716.655	4.66084
722.669	3.22897
728.679	5.48673
734.683	1.14503
740.683	-1.32323
746.678	4.62048
752.669	12.441
758.654	5.38188
764.635	9.63342
770.611	13.9495
776.582	6.05959
782.549	9.3614
788.511	15.4421
794.466	13.9376
800.419	13.3044
806.366	8.83868
812.309	9.04828
818.247	12.0193
824.18	11.2008
830.108	8.5191
836.033	16.2357
841.952	16.5855
847.865	16.0098
853.776	25.7908
859.681	28.1003
865.58	36.0887
871.476	45.0338
877.366	43.4585
883.253	45.6092
889.134	54.3238
895.012	57.2745
900.883	49.6703
906.751	49.5774
912.614	54.1657
918.473	54.0872
924.326	58.8439
930.174	63.7507
936.019	91.3752
941.859	121.274
947.693	147.653
953.525	164.714
959.35	162.642
965.171	174.739
970.988	248.141
976.801	304.08
982.608	374.779
988.411	345.457
994.209	232.02
1000	196.323
1005.79	185.637
1011.58	206.712
1017.36	241.362
1023.13	224.614
1028.9	162.077
1034.67	129.064
1040.43	104.592
1046.19	106.069
1051.94	91.9333
1057.69	74.7292
1063.44	70.9594
1069.17	77.7293
1074.91	84.4863
1080.64	113.478
1086.37	160.813
1092.09	212.025
1097.8	236.056
1103.52	159.492
1109.22	117.01
1114.93	95.0549
1120.63	92.5857
1126.32	82.1639
1132.01	103.015
1137.7	129.841
1143.38	175.444
1149.06	255.461
1154.73	165.081
1160.4	90.1564
1166.06	58.4404
1171.72	44.4899
1177.38	41.3365
1183.03	27.4912
1188.67	23.5369
1194.31	22.5791
1199.95	14.8407
1205.58	10.1034
1211.21	11.2786
1216.84	14.4757
1222.46	7.78235
1228.07	7.0211
1233.68	11.2363
1239.29	6.36861
1244.89	3.41904
1250.49	6.4593
1256.08	11.4793
1261.67	8.3435
1267.26	4.19128
1272.84	34.2296
1278.42	31.9928
1283.99	8.73808
1289.56	2.60218
1295.12	5.51136
1300.68	7.45515
1306.23	11.4625
1311.78	8.55119
1317.33	1.64447
1322.87	5.8143
1328.41	-2.12338
1333.94	2.07774
1339.47	3.21888
1345	1.2433
1350.52	0.259861
1356.04	4.38482
1361.55	0.260777
1367.06	4.31344
1372.56	8.34137
1378.06	79.1193
1383.56	19.4584
1389.05	8.07377
1394.53	6.991
1400.02	14.205
1405.5	4.96873
1410.97	7.06172
1416.44	4.01707
1421.91	3.03798
1427.37	5.18016
1432.83	-0.992401
1438.28	2.19069
1443.73	6.43285
1449.17	4.37965
1454.62	0.166718
1460.05	0.109276
1465.48	6.32315
1470.91	4.12398
1476.34	-6.45922
1481.76	5.02464
1487.17	-0.273941
1492.59	7.06863
1497.99	0.759789
1503.4	2.8936
1508.8	5.0579
1514.19	3.00579
1519.59	3.09172
1524.97	4.2574
1530.36	0.067028
1535.74	1.24166
1541.11	4.53174
1546.48	8.84521
1551.85	5.49877
1557.21	7.47873
1562.57	7.30899
1567.93	4.98007
1573.28	3.72952
1578.62	6.81801
1583.97	5.63252
1589.3	-0.921791
1594.64	10.8628
1599.97	2.195
1605.3	6.50346
1610.62	1.11851
1615.94	5.53751
1621.25	3.45867
1626.56	3.55091
1631.87	12.4382
1637.17	3.67297
1642.47	3.6132
1647.76	7.99315
1653.05	4.60325
1658.34	6.71783
1663.62	4.37661
1668.9	4.23744
1674.18	5.2012
1679.45	5.0422
1684.71	7.06437
1689.98	3.53779
1695.23	1.15751
1700.49	2.18158
1705.74	9.00256
1710.99	8.93257
1716.23	4.33362
1721.47	6.58423
1726.7	5.40107
1731.94	6.48903
1737.16	5.3217
1742.39	1.88935
1747.61	6.34074
1752.82	13.0348
1758.03	6.12754
1763.24	8.23431
1768.44	9.21851
1773.64	4.54471
1778.84	5.56242
1784.03	2.06718
1789.22	11.1111
1794.41	13.3631
1799.59	9.92545
1804.76	6.48354
1809.94	8.74852
1815.11	9.85199
1820.27	5.18465
1825.43	10.9209
1830.59	8.567
1835.74	6.21078
1840.89	11.9709
1846.04	3.7175
1851.18	3.61385
1856.32	4.65593
1861.45	11.6034
1866.58	5.66273
1871.71	9.10077
1876.83	1.90189
1881.95	11.2057
1887.07	11.0552
1892.18	2.57182
1897.29	4.71954
1902.39	10.4818
1907.49	5.65372
1912.59	10.378
1917.68	9.19739
1922.77	5.4631
1927.86	11.3507
1932.94	10.0617
1938.02	6.34588
1943.09	-1.01443
1948.16	4.83099
1953.23	4.63051
1958.29	9.23057
1963.35	5.38128
1968.41	9.94411
1973.46	7.24355
1978.51	3.34079
1983.55	12.6733
1988.59	-3.24961
1993.63	3.68864
1998.66	-1.38201
2003.69	9.19524
2008.72	13.7937
2013.74	5.17525
2018.76	-1.05807
2023.77	10.7948
2028.78	11.8469
2033.79	4.47463
2038.79	12.8382
2043.79	4.24334
2048.79	11.4459
2053.78	8.88695
2058.77	10.0074
2063.76	2.57534
2068.74	7.38105
2073.72	12.1989
2078.69	5.93531
2083.66	9.50434
2088.63	13.0499
2093.59	5.50002
2098.55	11.6121
2103.51	11.5466
2108.46	10.2546
2113.41	8.9797
2118.36	10.2191
2123.3	8.94178
2128.24	13.9562
2133.17	3.78523
2138.11	13.8426
2143.03	6.12967
2147.96	9.82443
2152.88	14.7662
2157.79	9.47406
2162.71	13.0881
2167.62	3.8839
2172.52	3.64513
2177.43	8.53773
2182.32	8.2641
2187.22	9.24595
2192.11	3.8688
2197	7.48666
2201.89	7.31199
2206.77	9.74323
2211.64	1.91543
2216.52	8.27357
2221.39	8.21304
2226.26	2.96374
2231.12	8.09428
2235.98	9.33876
2240.84	7.97263
2245.69	7.91687
2250.54	5.23124
2255.39	7.79371
2260.23	6.42177
2265.07	8.98367
2269.9	7.53629
2274.74	7.37591
2279.57	-0.790359
2284.39	1.6272
2289.21	6.6822
2294.03	6.41352
2298.84	3.51173
2303.66	8.64218
2308.46	13.8471
2313.27	8.41616
2318.07	12.3862
2322.87	12.3469
2327.66	4.24066
2332.45	4.21857
2337.24	5.57336
2342.02	15.1154
2346.8	5.64718
2351.58	-1.16043
2356.35	0.194946
2361.12	9.75404
2365.89	11.0619
2370.65	13.7587
2375.41	12.2955
2380.17	2.4729
2384.92	10.6398
2389.67	11.8269
2394.42	21.3218
2399.16	4.33351
2403.9	-0.135231
2408.64	-3.19516
2413.37	6.43814
2418.1	5.23099
2422.83	5.26698
2427.55	12.1843
2432.27	5.12197
2436.99	13.6316
2441.7	6.57624
2446.41	2.32609
2451.11	6.6265
2455.82	-0.520126
2460.51	-0.521202
2465.21	11.0018
2469.9	19.6797
2474.59	2.31571
2479.28	0.849655
2483.96	2.2672
2488.64	-0.717735
2493.32	-3.7207
2497.99	2.06119
2502.66	1.97621
2507.32	13.6336
2511.99	3.21748
2516.65	14.8649
2521.3	7.3884
2525.96	8.76092
2530.61	14.5791
2535.25	18.9661
2539.89	15.9608
2544.53	8.4851
2549.17	3.98272
2553.8	8.43416
2558.43	-0.625015
2563.06	8.3388
2567.68	5.33488
2572.3	6.86356
2576.92	9.89671
2581.53	5.31463
2586.14	6.72041
2590.75	11.1072
2595.35	10.9792
2599.96	9.37668
2604.55	1.62993
2609.15	9.13013
2613.74	13.5438
2618.33	17.9785
2622.91	11.7025
2627.49	6.97591
2632.07	14.6075
2636.64	3.87689
2641.22	7.05831
2645.78	11.8264
2650.35	21.268
2654.91	10.4479
2659.47	4.15553
2664.03	19.706
2668.58	8.66864
2673.13	8.66145
2677.67	-0.613251
2682.22	4.42328
2686.76	9.46074
2691.29	8.11009
2695.83	16.1738
2700.36	16.1914
2704.89	8.15976
2709.41	19.4057
2713.93	19.3909
2718.45	-3.20831
2722.96	24.2916
2727.47	11.2546
2731.98	17.621
2736.49	2.85847
2740.99	7.59306
2745.49	12.3933
2749.98	18.9004
2754.47	7.59876
2758.96	27.2636
2763.45	23.9544
2767.93	27.2857
2772.41	12.4768
2776.89	15.8597
2781.36	17.6806
2785.84	12.9023
2790.3	16.4255
2794.77	6.55581
2799.23	18.3952
2803.69	15.1111
2808.14	25.2574
2812.59	6.71044
2817.04	4.9709
2821.49	15.094
2825.93	8.30279
2830.37	13.3712
2834.81	11.6282
2839.24	16.6981
2843.67	8.1388
2848.1	14.9785
2852.53	21.8872
2856.95	8.27308
2861.37	11.8202
2865.78	5.08372
2870.19	17.3792
2874.6	8.88844
2879.01	7.33855
2883.41	14.5602
2887.81	11.3108
2892.21	4.4875
2896.6	15.3149
2901	24.4756
2905.38	6.91302
2909.77	12.4316
2914.15	17.8944
2918.53	9.03014
2922.91	9.1432
2927.28	16.5121
2931.65	13.095
2936.02	4.15668
2940.38	16.9096
2944.74	9.67596
2949.1	-1.28349
2953.46	4.16403
2957.81	15.1023
2962.16	-1.37141
2966.5	18.7924
2970.85	18.8482
2975.19	18.9149
2979.52	26.3561
2983.86	8.01045
2988.19	17.4098
2992.52	4.60448
2996.85	17.8187
3001.17	21.8104
3005.49	14.6117
3009.8	29.9337
3014.12	18.9024
3018.43	23.0152
3022.74	25.2497
3027.04	27.4096
3031.34	27.6081
3035.64	25.8227
3039.94	18.2578
3044.23	16.4324
3048.52	14.5702
3052.81	30.0576
3057.09	32.0962
3061.38	32.1947
3065.65	53.6295
3069.93	28.5072
3074.2	36.3925
3078.47	32.6212
3082.74	28.834
3087	42.7194
3091.27	43.0126
3095.52	39.4411
3099.78	31.9125
3104.03	50.1461
3108.28	50.6483
3112.53	51.193
3116.77	69.7845
3121.01	54.314
3125.25	65.0615
3129.49	57.6707
3133.72	48.2205
3137.95	71.4867
3142.18	57.7937
3146.4	48.0531
3150.62	63.1082
3154.84	73.9684
3159.06	61.876
3163.27	70.6833
3167.48	73.1785
3171.69	69.3727
3175.89	80.2555
3180.09	86.8155
3184.29	76.3742
3188.49	76.4397
3192.68	65.9864
3196.87	102.42
3201.06	94.4948
3205.24	78.0216
3209.42	63.666
3213.6	72.9836
3217.78	69.4014
3221.95	74.4346
3226.12	59.8277
3230.29	56.0602
3234.45	58.8449
3238.61	48.3516
3242.77	60.0706
3246.93	45.1507
3251.08	50.1117
3255.23	28.0295
3259.38	55.3511
3263.53	42.3378
3267.67	38.5881
3271.81	30.066
3275.95	34.9494
3280.08	37.4778
3284.21	33.1315
3288.34	37.9546
3292.47	35.8672
3296.59	42.9793
3300.71	29.372
3304.83	27.2756
3308.95	41.4134
3313.06	20.7007
3317.17	39.5225
3321.27	37.4616
3325.38	37.7961
3329.48	14.7161
3333.58	24.5771
3337.67	27.422
3341.77	34.8637
3345.86	18.523
3349.95	18.7048
3354.03	26.0388
3358.11	31.0995
3362.19	38.5837
3366.27	41.2801
3370.34	15.1693
3374.42	20.1941
3378.48	30.0021
3382.55	22.9261
3386.61	3.73415
3390.68	-10.684
3394.73	30.5785
3398.79	8.94359
3402.84	18.7747
3406.89	9.14995
3410.94	14.0899
3414.98	16.5963
3419.03	16.6761
3423.06	11.8633
3427.1	26.5909
3431.14	12.0858
3435.17	19.6034
3439.2	12.488
3443.22	25.0175
3447.25	8.15443
3451.27	6.02727
3455.28	21.2676
3459.3	14.3389
3463.31	12.3663
3467.32	5.38272
3471.33	10.8688
3475.34	23.8309
3479.34	21.7935
3483.34	-0.514664
3487.33	10.0245
3491.33	23.1534
3495.32	13.3557
3499.31	11.1368
3503.3	8.8562
3507.28	11.6554
3511.26	6.65718
3515.24	9.33464
3519.22	19.7207
3523.19	9.54352
3527.16	12.2557
3531.13	20.1158
3535.1	10.0972
3539.06	23.4078
3543.02	3.03502
3546.98	5.90337
3550.93	21.7205
3554.89	-4.17758
3558.84	9.02365
3562.78	11.88
3566.73	14.8041
3570.67	25.6637
3574.61	18.2038
3578.55	16.0318
3582.48	24.4508
3586.41	6.48944
3590.35	14.9372
3594.27	2.15137
3598.2	2.62479
3602.12	11.0823
3606.04	-15.2869
3609.95	14.6069
3613.87	1.55327
3617.78	-0.78833
3621.69	4.90508
3625.6	5.10289
3629.5	-8.23578
3633.4	5.44016
3637.3	5.65526
3641.2	8.68622
3645.09	3.64714
3648.98	6.68846
3652.87	-9.3846
3656.76	-0.965729
3660.64	4.73331
3664.53	-11.4174
3668.4	-8.42124
3672.28	2.78236
3676.16	5.86644
3680.03	6.28069
3683.9	-12.5032
3687.76	23.8658
3691.63	5.09529
3695.49	0.0525665
3699.35	14.4872
3703.2	3.87585
3707.06	4.4268
3710.91	7.78371
3714.76	-0.113358
3718.6	0.357483
3722.45	-4.84297
3726.29	6.88351
3730.13	4.48166
3733.97	10.6167
3737.8	-0.29776
3741.63	5.8241
3745.46	-10.8796
3749.29	0.923218
3753.11	1.27287
3756.93	7.31409
3760.75	-0.988449
3764.57	-6.44051
3768.39	2.45653
3772.2	-2.94165
3776.01	11.7645
3779.81	9.28314
3783.62	3.96931
3787.42	4.41977
3791.22	-3.81396
3795.02	14.0121
3798.81	-2.83759
3802.61	12.214
3806.4	4.0663
3810.18	-4.11662
3813.97	5.18478
3817.75	14.5183
3821.53	12.1337
3825.31	6.76682
3829.09	19.0609
3832.86	13.7344
3836.63	5.41727
3840.4	5.93201
3844.17	15.3965
3847.93	21.767
3851.69	-10.4898
3855.45	7.72164
3859.21	14.0053
3862.96	2.49279
3866.71	0.0698166
3870.46	15.6332
3874.21	16.0568
3877.95	-7.41414
3881.69	10.9674
3885.44	14.4361
3889.17	5.95274
3892.91	24.4933
3896.64	-10.9299
3900.37	1.66821
3904.1	11.2833
3907.82	36.0167
3911.55	21.5475
3915.27	13.1146
3918.99	10.7701
3922.7	17.5933
3926.42	12.228
3930.13	6.8172
3933.84	22.7682
3937.54	8.08279
3941.25	11.8221
3944.95	-2.84637
3948.65	22.4912
3952.35	13.9044
3956.04	17.6419
3959.73	18.253
3963.42	15.7477
3967.11	3.91515
3970.8	29.2422
3974.48	26.7023
3978.16	14.8513
3981.84	24.6742
3985.52	18.9965
3989.19	22.6315
3992.86	20.1216
3996.53	30.0809
3998.37	18.0053