File: Data/3-Raman/processed/bu19(2)w-a-ff1-fi09-v_150 (500nm)_532nm_edge_100%_x100_vis_lwd_h50um_30sx2_01.txt
#Acq. time (s)=	30
#Accumulations=	2
#Range (cm-¹)=	99...4000
#Windows=	1
#Auto scanning=	Off
#Autofocus=	Off
#Macrospot=	Off
#AutoExposure=	Off
#Spike filter=	Multiple accum.
#Delay time (s)=	2
#Binning=	1
#Readout mode=	Signal
#DeNoise=	Off
#ICS correction=	On
#Dark correction=	Off
#Inst. Process=	Off
#Detector Gain=	Best Dynamic
#Detector ADC=	50 kHz HS
#Detector temperature (°C)=	-60.09
#Instrument=	LabRAM HR Evol
#Detector=	SIN-EM FIVIS
#Objective=	x100_VIS_LWD
#Grating=	150 (500nm)
#ND Filter=	100%
#Laser=	532nm_Edge
#Hole=	49.98
#Temperature=	0
#Range=	Visible
#StageXY=	75x50mm Scan+
#StageZ=	Z motor
#X (µm)=	0
#Y (µm)=	0
#Z (µm)=	-56
#Full time(mm:ss)=	1:04
#Project=	21_11_26
#Sample=	BU19(2)w
#Site=
#Title=	BU19(2)w-A-FF1-FI09-V_150 (500nm)_532nm_Edge_100%_x100_VIS_LWD_H50um_30sX2
#Remark=
#Date=	26.11.2021 16:25
#Acquired=	26.11.2021 16:25:41
#Base:Fit=	16.12.2021 16:00:56
#Base:Edit=	16.12.2021 16:08:33
#Base:Sub=	16.12.2021 16:08:38
102.91	7647.06
107.534	6758.82
112.156	6484.42
116.775	5619.61
121.392	4355.58
126.005	3173.96
130.617	2677.38
135.227	2633.01
139.835	3364.29
144.439	4970.72
149.042	6992.91
153.643	6621.43
158.242	4336.86
162.839	2358.88
167.431	1308.97
172.023	793.612
176.613	475.53
181.198	214.867
185.783	152.155
190.366	-0.165039
194.947	49.0457
199.524	94.2755
204.1	337.386
208.674	1148.94
213.243	2036.02
217.813	1253.5
222.38	423.249
226.945	335.174
231.506	795.647
236.066	1973.96
240.625	2241.14
245.179	1003.21
249.732	330.462
254.284	125.418
258.831	47.4602
263.378	0.258667
267.923	16.5374
272.464	35.4651
277.004	48.6175
281.54	191.809
286.076	250.709
290.61	139.495
295.139	100.28
299.669	102.682
304.196	106.665
308.718	146.204
313.241	179.185
317.759	266.042
322.278	349.076
326.794	501.382
331.305	725.86
335.817	1055.16
340.324	1085.97
344.832	909.688
349.334	1073.25
353.837	1571.73
358.338	1520.07
362.834	994.122
367.33	662.78
371.822	595.675
376.314	621.415
380.802	706.347
385.289	920.781
389.772	1483.19
394.255	2415.97
398.734	2911.25
403.213	2618.03
407.688	2229.45
412.162	1855.14
416.632	1560.76
421.102	1450.93
425.568	1611.81
430.033	1799.37
434.495	1926.35
438.956	1858.61
443.413	1765.55
447.87	1824.19
452.323	2007.46
456.776	1975.73
461.224	1640.52
465.673	1225.69
470.117	901.555
474.561	727.55
479.001	704.403
483.438	727.07
487.876	848.525
492.309	1025.67
496.742	1378.42
501.172	1924.61
505.601	2676.25
510.025	3443.01
514.448	3870.41
518.871	3620.17
523.289	3111.11
527.707	2641.93
532.121	2326.66
536.533	2249.87
540.945	2270.25
545.353	2400.57
549.758	2401.18
554.164	2417.61
558.565	2209.6
562.965	1931.47
567.364	1608.86
571.759	1286.73
576.151	1001.85
580.544	933.712
584.933	874.362
589.319	899.037
593.706	1010.03
598.088	1167.07
602.468	1457.74
606.848	1824.98
611.224	2486.18
615.598	3955.41
619.972	6722.38
624.341	8485.19
628.709	6564.68
633.074	3674.65
637.44	2101.55
641.801	1384.97
646.16	978.422
650.517	698.337
654.874	560.807
659.227	430.023
663.578	348.072
667.927	264.029
672.275	247.024
676.62	201.77
680.962	161.27
685.302	164.614
689.643	146.687
693.979	189.784
698.313	217.511
702.645	303.072
706.975	384.527
711.305	341.114
715.631	261.426
719.955	187.699
724.276	156.367
728.596	150.745
732.913	120.128
737.231	67.311
741.544	23.9127
745.856	29.8847
750.165	-0.423462
754.472	7.22986
758.778	4.97272
763.081	12.8699
767.384	3.75867
771.683	-6.88159
775.98	14.2775
780.275	14.6577
784.568	17.4323
788.859	24.9828
793.147	19.446
797.434	50.0751
801.719	39.0726
806.004	50.4653
810.284	75.2771
814.563	80.434
818.839	119.836
823.114	162.617
827.386	256.294
831.657	370.033
835.925	540.212
840.192	685.222
844.456	897.622
848.719	1007.09
852.979	909.494
857.237	792.217
861.493	614.5
865.748	510.639
870	433.105
874.25	427.012
878.499	498.633
882.745	581.904
886.989	526.844
891.231	326.67
895.471	201.263
899.71	114.461
903.946	63.7162
908.18	22.0865
912.412	-21.0351
916.642	-21.547
920.87	-46.9227
925.096	-31.3586
929.321	-23.5673
933.543	-63.5625
937.763	-45.5274
941.981	-28.6732
946.197	-47.1558
950.412	-21.7791
954.622	-43.2076
958.832	-21.9058
963.04	-32.441
967.246	-34.3598
971.451	-25.5593
975.653	-4.97311
979.853	-4.43832
984.052	17.4166
988.248	41.41
992.442	102.516
996.633	177.838
1000.82	236.76
1005.01	301.314
1009.2	273.758
1013.38	200.441
1017.57	147.049
1021.75	143.692
1025.92	123.161
1030.1	129.13
1034.27	175.551
1038.45	255.497
1042.62	379.636
1046.78	544.914
1050.95	640.304
1055.12	594.112
1059.28	592.273
1063.44	568.015
1067.6	654.058
1071.75	741.577
1075.91	970.605
1080.06	1285.65
1084.21	1742.38
1088.36	2644.18
1092.51	3945.02
1096.65	5190.3
1100.8	5302.79
1104.94	3811.52
1109.08	2201.65
1113.21	1322.7
1117.35	869.304
1121.48	653.639
1125.61	576.542
1129.74	590.583
1133.87	651.077
1137.99	827.401
1142.12	1150.09
1146.24	1504.02
1150.36	1582.35
1154.48	1323.43
1158.59	968.537
1162.71	649.223
1166.82	443.07
1170.93	298.712
1175.04	206.862
1179.14	116.098
1183.25	62.5469
1187.35	48.0413
1191.45	17.9498
1195.55	19.604
1199.65	-9.50183
1203.74	10.3435
1207.83	0.618011
1211.92	4.1499
1216.01	46.086
1220.1	88.8726
1224.19	112.442
1228.27	131.02
1232.35	188.769
1236.43	219.82
1240.51	317.144
1244.58	506.077
1248.66	1161.34
1252.73	1322.16
1256.8	842.19
1260.87	777.716
1264.93	1547.56
1269	11049.9
1273.06	11660
1277.12	2883.66
1281.18	822.552
1285.23	616.288
1289.29	520.192
1293.34	384.593
1297.39	370.623
1301.44	318.279
1305.49	308.11
1309.53	304.95
1313.58	324.899
1317.62	287.162
1321.66	292.628
1325.7	295.837
1329.73	293.929
1333.77	304.007
1337.8	319.858
1341.83	358.557
1345.86	416.022
1349.88	492.204
1353.91	730.321
1357.93	1010.35
1361.95	906.565
1365.97	1106.24
1369.99	3707.08
1374	23578.8
1378.02	15035.6
1382.03	2895.35
1386.04	1056.44
1390.05	948.58
1394.05	1788.96
1398.06	1977.72
1402.06	830.75
1406.06	397.347
1410.06	298.85
1414.05	257.516
1418.05	167.788
1422.04	149.035
1426.03	106.493
1430.02	45.9498
1434.01	49.6216
1438	13.7854
1441.98	10.5298
1445.96	-11.5348
1449.94	-33.6136
1453.92	-20.2201
1457.9	-54.1957
1461.87	-59.6087
1465.85	-53.2843
1469.82	-68.6211
1473.78	-50.5117
1477.75	-72.6977
1481.72	-70.3726
1485.68	-62.2033
1489.65	-67.758
1493.61	-71.3374
1497.56	-73.9353
1501.52	-74.5659
1505.47	-70.3046
1509.43	-65.0312
1513.38	-69.4718
1517.33	-66.1402
1521.27	-68.6215
1525.22	-77.8868
1529.16	-47.3895
1533.11	-77.9638
1537.05	-58.1339
1540.98	-58.6669
1544.92	-55.3346
1548.86	-59.7658
1552.79	-58.3961
1556.72	-65.7797
1560.65	-45.1237
1564.58	-61.2916
1568.5	-50.3945
1572.43	-41.4714
1576.35	-56.718
1580.27	-62.312
1584.19	-45.7365
1588.1	-48.4828
1592.02	-43.5401
1595.93	-39.5828
1599.84	-47.1733
1603.75	-47.0664
1607.66	-37.3471
1611.57	-54.4956
1615.47	-37.1224
1619.37	-38.9099
1623.27	-27.3151
1627.17	-20.496
1631.07	-20.3647
1634.97	-33.5801
1638.86	-34.3774
1642.75	-31.3083
1646.64	-49.2897
1650.53	-15.5139
1654.42	-26.7938
1658.3	-20.8388
1662.18	-24.507
1666.07	-16.6987
1669.94	-9.88356
1673.82	-22.3734
1677.7	-27.1975
1681.57	-31.1731
1685.44	-23.6852
1689.31	-26.7876
1693.18	-19.3986
1697.05	-7.285
1700.92	-20.0838
1704.78	-12.8704
1708.64	-4.78432
1712.5	-2.48219
1716.36	-15.3605
1720.21	-0.761246
1724.07	-6.04605
1727.92	-0.0345612
1731.77	-0.670868
1735.62	4.32848
1739.47	3.65865
1743.32	6.68938
1747.16	19.0184
1751.01	19.3401
1754.85	20.6593
1758.69	23.0191
1762.52	25.7378
1766.36	19.9311
1770.19	15.1187
1774.02	37.3542
1777.85	7.50681
1781.68	9.33252
1785.51	9.31735
1789.33	1.82997
1793.16	-0.0666656
1796.98	10.2192
1800.8	-1.10129
1804.62	5.28737
1808.43	8.83401
1812.25	11.4083
1816.06	17.7114
1819.87	-0.616379
1823.68	-1.08224
1827.49	11.6126
1831.3	-6.8837
1835.1	-2.80249
1838.9	3.11343
1842.71	15.5604
1846.51	-4.01074
1850.3	-1.0072
1854.1	3.76457
1857.89	14.0692
1861.69	2.80804
1865.48	3.66412
1869.27	3.59921
1873.05	-0.158997
1876.84	17.3966
1880.62	10.8948
1884.4	11.8628
1888.19	12.8286
1891.96	14.9308
1895.74	5.06807
1899.52	9.00049
1903.29	24.0521
1907.06	16.129
1910.83	15.579
1914.6	4.02724
1918.37	10.9189
1922.13	16.0954
1925.9	16.6693
1929.66	8.91946
1933.42	4.86736
1937.18	27.8068
1940.94	13.4771
1944.69	18.722
1948.44	30.5396
1952.2	15.9438
1955.95	29.405
1959.69	27.734
1963.44	41.9523
1967.19	40.1838
1970.93	37.4017
1974.67	62.6703
1978.41	71.9093
1982.15	67.9786
1985.89	80.8272
1989.62	93.6024
1993.35	102.561
1997.09	112.356
2000.82	88.6537
2004.55	108.569
2008.27	100.65
2012	73.3369
2015.72	72.8227
2019.44	58.6596
2023.16	62.9966
2026.88	50.9793
2030.6	56.378
2034.31	52.7271
2038.03	45.4922
2041.74	36.3989
2045.45	33.6925
2049.16	39.227
2052.86	27.4016
2056.57	29.3201
2060.27	27.6768
2063.98	26.1554
2067.67	26.5153
2071.37	21.3617
2075.07	18.0351
2078.77	18.4066
2082.46	20.6439
2086.15	11.7218
2089.84	9.98036
2093.53	7.21846
2097.22	23.1324
2100.9	-2.82381
2104.59	19.5079
2108.27	8.32185
2111.95	1.75679
2115.63	3.55388
2119.31	8.1123
2122.98	3.30344
2126.66	26.2918
2130.33	13.986
2134	9.09329
2137.67	9.74445
2141.34	13.1286
2145	2.65021
2148.67	13.3491
2152.33	12.0693
2155.99	18.1342
2159.65	15.9484
2163.31	24.7588
2166.96	17.1482
2170.62	7.76768
2174.27	12.1452
2177.92	7.45572
2181.57	18.2659
2185.22	7.22676
2188.87	11.7052
2192.51	8.98059
2196.15	3.60057
2199.8	10.0974
2203.44	2.03647
2207.07	8.59569
2210.71	6.97537
2214.35	19.1103
2217.98	12.9536
2221.61	4.02824
2225.24	13.4815
2228.87	-0.0788727
2232.5	3.85394
2236.12	5.9678
2239.75	9.00908
2243.37	14.8376
2246.99	3.03525
2250.61	12.5956
2254.23	0.782776
2257.85	18.8108
2261.46	5.11183
2265.07	6.32822
2268.68	21.6415
2272.29	2.27835
2275.9	18.5772
2279.51	22.614
2283.11	9.53906
2286.72	11.5525
2290.32	16.4034
2293.92	7.9946
2297.52	12.8315
2301.11	17.6834
2304.71	27.2461
2308.3	49.0947
2311.9	148.65
2315.49	1267.17
2319.08	1762.57
2322.66	428.857
2326.25	56.3047
2329.84	44.696
2333.42	34.0318
2337	27.1404
2340.58	23.0665
2344.16	8.64664
2347.73	29.9067
2351.31	17.3609
2354.88	28.2235
2358.45	19.4401
2362.03	22.7846
2365.59	16.821
2369.16	25.7357
2372.73	24.4848
2376.29	24.1486
2379.85	19.2065
2383.41	8.78021
2386.97	37.0416
2390.53	27.5967
2394.09	19.1362
2397.64	18.0887
2401.2	15.2785
2404.75	14.4114
2408.3	4.40392
2411.85	13.7295
2415.39	8.42905
2418.94	12.3553
2422.48	18.1626
2426.03	6.52525
2429.57	12.4384
2433.11	11.0134
2436.64	9.62555
2440.18	21.2592
2443.72	4.09337
2447.25	15.7903
2450.78	3.25223
2454.31	16.0198
2457.84	13.6746
2461.37	8.32851
2464.89	11.4382
2468.42	10.6203
2471.94	21.286
2475.46	19.3602
2478.98	-0.512451
2482.5	-9.96227
2486.01	12.5579
2489.53	5.75737
2493.04	22.5587
2496.55	2.62822
2500.06	5.29919
2503.57	15.3861
2507.08	-4.47264
2510.58	15.7794
2514.09	-4.96382
2517.59	4.12941
2521.09	3.02492
2524.59	7.35347
2528.09	2.60785
2531.59	3.46094
2535.08	7.1091
2538.58	2.50322
2542.07	12.7042
2545.56	9.15457
2549.05	7.52892
2552.54	7.75816
2556.02	9.88843
2559.51	1.92076
2562.99	5.99745
2566.47	4.58801
2569.95	19.0777
2573.43	4.71217
2576.91	7.175
2580.38	15.3267
2583.85	-2.86751
2587.33	-0.365082
2590.8	11.5916
2594.27	12.0998
2597.74	6.86003
2601.2	2.60368
2604.67	0.223999
2608.13	3.48488
2611.59	5.64162
2615.06	2.87299
2618.51	2.08926
2621.97	1.22858
2625.43	13.7839
2628.88	23.4005
2632.33	7.05031
2635.79	17.5384
2639.24	8.77872
2642.69	22.9802
2646.13	10.3339
2649.58	12.9838
2653.02	-1.5759
2656.47	2.89427
2659.91	20.5955
2663.35	4.1012
2666.79	7.50414
2670.22	18.4248
2673.66	13.2949
2677.09	12.9077
2680.52	18.1648
2683.95	25.3096
2687.39	22.2346
2690.81	14.6303
2694.24	-1.28535
2697.66	18.1602
2701.09	9.70403
2704.51	17.0723
2707.93	3.98204
2711.35	8.68709
2714.77	17.1525
2718.18	10.7634
2721.6	5.32834
2725.01	10.1651
2728.42	5.68288
2731.84	3.06721
2735.24	17.2816
2738.65	5.28238
2742.06	6.37862
2745.46	13.0704
2748.86	11.2847
2752.27	7.61346
2755.67	10.5033
2759.07	14.3123
2762.46	11.5303
2765.86	21.8827
2769.25	2.99028
2772.65	4.7925
2776.04	14.1111
2779.43	4.54924
2782.82	16.6185
2786.2	7.01259
2789.59	4.92886
2792.98	5.65483
2796.36	1.6716
2799.74	14.5852
2803.12	6.80669
2806.5	6.53476
2809.88	10.9355
2813.25	7.8259
2816.63	14.0535
2820	9.05093
2823.37	10.6125
2826.74	16.8547
2830.11	10.0468
2833.48	13.5141
2836.84	21.6657
2840.21	12.1438
2843.57	8.24179
2846.93	5.30782
2850.29	7.09355
2853.65	-7.88477
2857.01	6.04716
2860.36	9.73534
2863.72	7.8298
2867.07	16.2319
2870.42	2.12556
2873.77	26.4865
2877.12	10.4468
2880.47	4.71745
2883.81	16.8676
2887.16	12.0401
2890.5	10.0244
2893.84	12.7113
2897.18	16.2928
2900.52	-0.0193634
2903.86	12.0024
2907.19	15.4819
2910.53	0.95787
2913.86	18.585
2917.19	22.9418
2920.52	26.3122
2923.85	17.367
2927.18	19.7454
2930.51	32.4777
2933.83	23.4425
2937.15	28.5335
2940.48	29.8365
2943.8	20.7665
2947.11	25.8291
2950.43	23.3566
2953.75	27.451
2957.06	22.1447
2960.38	12.1774
2963.69	16.3048
2967	21.371
2970.31	32.1174
2973.62	17.5713
2976.92	13.3409
2980.23	23.2096
2983.53	29.2957
2986.84	17.5549
2990.14	27.4089
2993.44	25.0582
2996.73	12.3745
3000.03	34.4646
3003.33	29.2909
3006.62	21.2838
3009.91	17.0445
3013.2	27.873
3016.49	6.67256
3019.78	14.6637
3023.07	16.049
3026.35	6.1039
3029.64	-1.0233
3032.92	21.1209
3036.2	12.0747
3039.48	6.78957
3042.76	12.8478
3046.04	-0.0228882
3049.32	6.97725
3052.59	20.6096
3055.86	3.91852
3059.14	8.06148
3062.41	8.33701
3065.68	18.1266
3068.94	12.7008
3072.21	21.4546
3075.48	-0.34877
3078.74	12.2073
3082	18.0463
3085.26	6.05397
3088.52	5.41994
3091.78	-5.61038
3095.04	4.26694
3098.29	19.5671
3101.55	1.73151
3104.8	15.2222
3108.05	2.18359
3111.3	27.1692
3114.55	10.198
3117.8	9.42216
3121.04	23.8844
3124.29	7.86565
3127.53	30.8926
3130.77	11.9886
3134.02	32.1512
3137.25	35.1506
3140.49	16.2056
3143.73	18.2231
3146.96	27.8656
3150.2	29.8932
3153.43	46.2292
3156.66	38.7062
3159.89	37.8628
3163.12	37.9597
3166.35	33.2823
3169.57	51.479
3172.8	50.5655
3176.02	42.9562
3179.24	41.0462
3182.46	42.9446
3185.68	40.0761
3188.9	55.2888
3192.12	58.0899
3195.33	43.7323
3198.55	54.1442
3201.76	67.3961
3204.97	59.7064
3208.18	62.4976
3211.39	66.2515
3214.6	64.3147
3217.8	74.7651
3221.01	61.4314
3224.21	69.0358
3227.41	77.6226
3230.61	80.5088
3233.81	72.002
3237.01	86.3102
3240.21	88.3235
3243.4	75.1227
3246.59	87.6505
3249.79	77.3176
3252.98	94.6628
3256.17	105.359
3259.36	113.197
3262.54	113.351
3265.73	121.095
3268.92	107.773
3272.1	135.492
3275.28	131.664
3278.46	139.294
3281.64	151.614
3284.82	160.033
3288	170.363
3291.17	174.927
3294.35	170.947
3297.52	180.294
3300.69	198.211
3303.86	194.332
3307.03	210.319
3310.2	202.472
3313.36	224.971
3316.53	244.56
3319.69	256.519
3322.85	262.755
3326.02	286.982
3329.18	308.337
3332.33	318.331
3335.49	356.697
3338.65	382.797
3341.8	401.368
3344.95	399.198
3348.11	427.371
3351.26	467.027
3354.41	494.421
3357.56	508.714
3360.7	560.766
3363.85	590.314
3366.99	630.279
3370.13	662.776
3373.28	695.344
3376.42	745.055
3379.56	779.757
3382.69	823.061
3385.83	854.078
3388.97	902.264
3392.1	972.304
3395.23	1051.84
3398.36	1083.75
3401.49	1177.16
3404.62	1262.33
3407.75	1364.93
3410.88	1390.83
3414	1529.07
3417.13	1666.19
3420.25	1783.39
3423.37	1954.95
3426.49	2133.88
3429.61	2320.16
3432.73	2469.86
3435.84	2687.77
3438.96	2923.05
3442.07	3185.35
3445.18	3599.18
3448.29	4083.49
3451.4	4939.08
3454.51	6340.86
3457.62	7989.31
3460.72	8994.03
3463.83	8507.29
3466.93	7104.2
3470.03	5790.8
3473.13	4865.88
3476.23	4430.27
3479.33	4137.59
3482.43	4008.24
3485.53	3847.07
3488.62	3872.47
3491.71	3940.04
3494.81	3862.46
3497.9	3918.76
3500.99	3925.71
3504.07	4027.07
3507.16	4088.09
3510.25	4152.79
3513.33	4214.16
3516.41	4399.58
3519.5	4660.27
3522.58	4954.55
3525.66	5250.39
3528.73	5661.09
3531.81	6056.36
3534.89	6366.46
3537.96	6742.26
3541.03	6858.11
3544.11	6709.88
3547.18	6325.39
3550.25	5689.23
3553.32	4862.61
3556.38	4103.78
3559.45	3363.83
3562.51	2812.4
3565.58	2273.02
3568.64	1958.44
3571.7	1667.1
3574.76	1437.21
3577.82	1233.92
3580.87	1094.04
3583.93	960.696
3586.98	876.589
3590.04	783.033
3593.09	725.421
3596.14	632.768
3599.19	621.591
3602.24	548.884
3605.29	545.275
3608.33	503.782
3611.38	484.101
3614.42	441.742
3617.46	426.82
3620.5	411.974
3623.54	387.769
3626.58	396.634
3629.62	399.904
3632.65	376.779
3635.69	324.488
3638.72	307.24
3641.76	272.23
3644.79	268.365
3647.82	243.025
3650.84	224.141
3653.87	191.238
3656.9	188.796
3659.92	162.041
3662.95	171.932
3665.97	164.813
3668.99	132.992
3672.01	120.127
3675.03	112.006
3678.05	112.414
3681.07	99.6412
3684.08	92.5202
3687.1	88.2519
3690.11	84.9541
3693.12	85.4682
3696.13	68.001
3699.14	54.2549
3702.15	84.2193
3705.16	59.1819
3708.16	33.1721
3711.17	60.3361
3714.17	43.7754
3717.17	51.9096
3720.17	37.2488
3723.17	32.0722
3726.17	25.9302
3729.17	19.7746
3732.16	24.0867
3735.16	36.0023
3738.15	21.2367
3741.14	17.8878
3744.13	12.6173
3747.13	8.29306
3750.11	20.1187
3753.1	26.2218
3756.09	30.4261
3759.07	11.8724
3762.06	5.67061
3765.04	7.04587
3768.02	3.70036
3771	6.06383
3773.98	13.1843
3776.96	8.97847
3779.94	14.2451
3782.91	14.8051
3785.89	-9.18015
3788.86	-2.92598
3791.83	5.228
3794.8	6.81035
3797.77	11.2421
3800.74	-3.19292
3803.71	13.5516
3806.68	0.0890503
3809.64	14.9616
3812.61	5.27763
3815.57	14.4935
3818.53	8.57758
3821.49	7.38638
3824.45	7.13426
3827.41	9.72612
3830.36	11.3599
3833.32	7.2868
3836.27	13.6534
3839.23	23.8197
3842.18	21.6228
3845.13	8.93478
3848.08	26.6729
3851.03	22.5103
3853.98	25.9556
3856.92	24.6115
3859.87	32.7906
3862.81	27.5702
3865.75	28.0365
3868.7	27.5116
3871.64	33.6409
3874.57	33.0223
3877.51	45.7907
3880.45	26.8191
3883.39	30.8213
3886.32	18.4197
3889.25	37.6737
3892.18	53.9966
3895.12	40.4548
3898.05	38.3722
3900.97	43.9062
3903.9	36.8793
3906.83	39.3862
3909.75	42.8222
3912.68	55.7865
3915.6	39.8384
3918.52	38.2292
3921.44	38.5134
3924.36	18.5304
3927.28	33.9679
3930.2	41.6253
3933.11	30.9842
3936.03	42.355
3938.94	25.9152
3941.86	41.9899
3944.77	48.3825
3947.68	28.8493
3950.59	37.9705
3953.49	39.3563
3956.4	39.6986
3959.31	43.795
3962.21	30.5551
3965.12	28.7168
3968.02	34.4557
3970.92	23.7914
3973.82	28.3703
3976.72	19.3896
3979.61	36.2095
3982.51	37.5295
3985.41	31.0313
3988.3	19.5846
3991.19	22.4212
3994.09	18.3657
3996.98	31.5331
3999.87	0.288635