File: Data/3-Raman/processed/bu19w-e-ff11b-fi10-v_150 (500nm)_633nm_edge_100%_x100_vis_h50um_60sx2_01_0.txt
#Acq. time (s)=	60
#Accumulations=	2
#Range (cm-¹)=	100...4000
#Windows=	1
#Auto scanning=	Off
#Autofocus=	Off
#Macrospot=	Off
#AutoExposure=	Off
#Spike filter=	Multiple accum.
#Delay time (s)=	2
#Binning=	1
#Readout mode=	Signal
#DeNoise=	Off
#ICS correction=	On
#Dark correction=	Off
#Inst. Process=	Off
#Detector Gain=	Best Dynamic
#Detector ADC=	50 kHz HS
#Detector temperature (°C)=	-60.09
#Instrument=	LabRAM HR Evol
#Detector=	SIN-EM FIVIS
#Objective=	x100_VIS
#Grating=	150 (500nm)
#ND Filter=	100%
#Laser=	633nm_Edge
#Hole=	49.98
#Temperature=	0
#Range=	Visible
#StageXY=	75x50mm Scan+
#StageZ=	Z motor
#X (µm)=	0
#Y (µm)=	0
#Z (µm)=	-271.2
#Full time(mm:ss)=	2:04
#Project=	21_11_04
#Sample=	BU19w
#Site=
#Title=	BU19w-E-FF11b-FI10-V_150 (500nm)_633nm_Edge_100%_x100_VIS_H50um_60sX2
#Remark=
#Date=	04.11.2021 17:04
#Acquired=	04.11.2021 17:04:15
#Base:Fit=	16.12.2021 17:39:50
#Base:Edit=	16.12.2021 17:48:42
#Base:Edit=	16.12.2021 17:48:43
#Base:Edit=	16.12.2021 17:48:44
#Base:Sub=	16.12.2021 17:48:47
102.881	9.82065
109.397	60.4902
115.908	341.864
122.414	99.1706
128.914	26.8306
135.409	26.5836
141.898	12.4003
148.383	20.7853
154.861	26.8859
161.335	33.5746
167.801	39.8734
174.264	88.8661
180.721	184.306
187.173	324.017
193.62	447.533
200.061	370.232
206.496	241.773
212.926	125.421
219.352	78.5291
225.772	55.2057
232.185	42.0428
238.595	24.9718
244.999	33.4437
251.397	83.5111
257.791	41.263
264.178	12.2034
270.561	10.529
276.939	10.6213
283.31	5.79968
289.678	-0.134506
296.039	-0.538979
302.396	10.2914
308.746	9.63755
315.093	7.00586
321.433	8.08154
327.768	4.38255
334.099	12.8762
340.423	52.3971
346.743	63.5184
353.058	10.466
359.367	12.9273
365.671	11.5487
371.971	12.9392
378.265	18.9607
384.553	35.2718
390.837	54.5206
397.116	17.5333
403.389	17.19
409.657	14.9009
415.92	19.1221
422.178	34.648
428.431	43.2645
434.678	78.9976
440.921	163.442
447.158	579.52
453.391	1488
459.618	692.041
465.84	231.623
472.057	115.076
478.27	86.3432
484.477	55.7304
490.679	47.4717
496.876	42.9492
503.068	41.2418
509.255	25.5545
515.436	25.7502
521.613	21.3433
527.785	16.0475
533.952	16.4339
540.113	12.1112
546.27	17.1247
552.423	13.5526
558.568	4.2663
564.711	10.8741
570.848	7.02099
576.979	11.5539
583.107	2.98851
589.228	12.2632
595.345	5.78489
601.458	-0.543304
607.565	14.704
613.667	1.07427
619.764	8.09438
625.856	2.97581
631.944	9.96375
638.026	11.1389
644.104	13.1033
650.177	7.53658
656.244	3.78802
662.308	10.3371
668.365	5.68378
674.418	6.82233
680.467	10.8188
686.511	26.1064
692.549	6.96523
698.582	6.51817
704.611	7.93064
710.635	2.70607
716.655	6.70155
722.669	5.07333
728.679	-2.24826
734.683	7.27892
740.683	11.1694
746.678	1.07984
752.669	8.78403
758.654	10.9643
764.635	3.99628
770.611	11.1222
776.582	13.5868
782.549	26.338
788.511	37.1697
794.466	43.2416
800.419	34.1238
806.366	29.6373
812.309	17.586
818.247	10.2038
824.18	11.257
830.108	2.97597
836.033	11.6932
841.952	10.2797
847.865	8.88515
853.776	10.3437
859.681	17.4864
865.58	22.7848
871.476	14.8245
877.366	15.2557
883.253	10.8848
889.134	14.9837
895.012	12.3869
900.883	4.01125
906.751	11.6687
912.614	12.6729
918.473	13.7192
924.326	17.697
930.174	13.3403
936.019	7.1697
941.859	10.5475
947.693	8.28133
953.525	15.5151
959.35	9.36107
965.171	10.759
970.988	11.1446
976.801	6.6277
982.608	1.98424
988.411	6.88007
994.209	5.04434
1000	9.90615
1005.79	4.30717
1011.58	1.65886
1017.36	7.64435
1023.13	4.11568
1028.9	3.51193
1034.67	8.6855
1040.43	8.1284
1046.19	5.62854
1051.94	11.776
1057.69	21.7721
1063.44	19.0702
1069.17	26.9434
1074.91	31.8885
1080.64	11.5555
1086.37	13.5353
1092.09	9.72498
1097.8	6.87647
1103.52	8.87311
1109.22	7.0687
1114.93	5.37525
1120.63	17.3616
1126.32	17.6234
1132.01	2.26241
1137.7	9.3569
1143.38	18.4374
1149.06	31.4077
1154.73	19.7107
1160.4	10.8497
1166.06	14.6692
1171.72	11.6067
1177.38	4.62193
1183.03	1.59922
1188.67	17.2218
1194.31	11.4239
1199.95	10.5835
1205.58	13.775
1211.21	13.0845
1216.84	14.4078
1222.46	21.7419
1228.07	9.15438
1233.68	7.44367
1239.29	12.7033
1244.89	5.77567
1250.49	10.8614
1256.08	14.8792
1261.67	9.70502
1267.26	14.5981
1272.84	74.7638
1278.42	16.1831
1283.99	7.94421
1289.56	6.77542
1295.12	10.6554
1300.68	3.58854
1306.23	4.59148
1311.78	5.69727
1317.33	3.84519
1322.87	4.02411
1328.41	8.28693
1333.94	9.51757
1339.47	4.59039
1345	1.60903
1350.52	11.9097
1356.04	20.1569
1361.55	16.0315
1367.06	14.9173
1372.56	36.3699
1378.06	108.128
1383.56	8.38046
1389.05	7.22147
1394.53	10.2142
1400.02	6.12221
1405.5	11.2764
1410.97	10.2867
1416.44	9.32139
1421.91	3.18526
1427.37	5.34123
1432.83	15.8402
1438.28	5.51273
1443.73	17.101
1449.17	12.9813
1454.62	8.77067
1460.05	1.34724
1465.48	3.33356
1470.91	12.6516
1476.34	2.04325
1481.76	9.31506
1487.17	19.774
1492.59	11.3619
1497.99	10.3436
1503.4	7.23685
1508.8	9.44115
1514.19	2.12912
1519.59	16.1083
1524.97	8.81743
1530.36	3.62359
1535.74	4.87105
1541.11	12.5355
1546.48	10.3969
1551.85	9.21318
1557.21	12.2467
1562.57	8.81902
1567.93	14.0211
1573.28	4.13315
1578.62	8.29798
1583.97	14.6611
1589.3	12.4387
1594.64	9.17446
1599.97	8.10128
1605.3	22.2057
1610.62	10.4251
1615.94	23.6655
1621.25	16.2907
1626.56	7.75699
1631.87	15.6554
1637.17	10.2945
1642.47	18.0356
1647.76	8.11588
1653.05	-0.753426
1658.34	13.6056
1663.62	7.98949
1668.9	14.5531
1674.18	11.1301
1679.45	17.6714
1684.71	9.753
1689.98	15.1227
1695.23	10.5805
1700.49	2.83092
1705.74	6.46099
1710.99	13.167
1716.23	8.64267
1721.47	3.18931
1726.7	12.185
1731.94	5.53291
1737.16	5.59641
1742.39	9.03763
1747.61	7.96185
1752.82	10.2356
1758.03	-1.10567
1763.24	14.6753
1768.44	-0.103706
1773.64	-3.55238
1778.84	5.506
1784.03	7.80857
1789.22	-0.0941696
1794.41	13.6751
1799.59	11.5175
1804.76	-0.959549
1809.94	4.87321
1815.11	8.40594
1820.27	7.3345
1825.43	14.3693
1830.59	8.68092
1835.74	1.81328
1840.89	14.6945
1846.04	6.57829
1851.18	11.2893
1856.32	10.1254
1861.45	19.5646
1866.58	12.6044
1871.71	7.946
1876.83	9.13186
1881.95	6.7648
1887.07	12.6461
1892.18	4.27937
1897.29	6.54287
1902.39	1.78239
1907.49	6.56548
1912.59	12.6338
1917.68	16.3911
1922.77	11.6003
1927.86	5.67251
1932.94	10.5083
1938.02	18.9409
1943.09	4.5134
1948.16	14.1047
1953.23	15.2372
1958.29	4.29411
1963.35	7.79263
1968.41	10.0578
1973.46	8.66936
1978.51	3.66946
1983.55	7.0929
1988.59	10.5217
1993.63	7.94668
1998.66	7.79476
2003.69	5.2615
2008.72	19.5986
2013.74	9.89973
2018.76	14.6294
2023.77	9.73084
2028.78	14.5251
2033.79	13.331
2038.79	9.71833
2043.79	8.52879
2048.79	13.4329
2053.78	9.77855
2058.77	15.9098
2063.76	8.61332
2068.74	12.3262
2073.72	9.89446
2078.69	17.2964
2083.66	7.41913
2088.63	6.12434
2093.59	8.57722
2098.55	9.8445
2103.51	13.6193
2108.46	16.1881
2113.41	22.5516
2118.36	5.12061
2123.3	11.4919
2128.24	12.8337
2133.17	15.4215
2138.11	12.9179
2143.03	14.2001
2147.96	10.3583
2152.88	25.5926
2157.79	11.4543
2162.71	12.591
2167.62	8.57255
2172.52	14.8046
2177.43	13.3765
2182.32	10.6087
2187.22	7.81177
2192.11	15.3032
2197	8.74276
2201.89	11.2035
2206.77	7.28391
2211.64	13.6881
2216.52	22.7252
2221.39	11.1237
2226.26	13.7348
2231.12	15.0567
2235.98	16.3833
2240.84	9.86778
2245.69	8.56724
2250.54	4.6283
2255.39	16.4667
2260.23	8.56993
2265.07	15.1595
2269.9	7.13985
2274.74	0.381714
2279.57	16.1747
2284.39	13.3146
2289.21	11.7501
2294.03	19.4949
2298.84	19.2917
2303.66	15.1383
2308.46	11.0419
2313.27	16.3414
2318.07	15.0026
2322.87	20.3816
2327.66	13.6795
2332.45	25.8859
2337.24	20.5617
2342.02	15.2209
2346.8	18.0773
2351.58	11.346
2356.35	12.7681
2361.12	18.2455
2365.89	14.0702
2370.65	19.5594
2375.41	26.4421
2380.17	9.71618
2384.92	2.60823
2389.67	19.1004
2394.42	20.2488
2399.16	11.6107
2403.9	5.74708
2408.64	12.4285
2413.37	6.76015
2418.1	20.9927
2422.83	9.85226
2427.55	-1.51859
2432.27	13.9773
2436.99	14.0327
2441.7	15.5106
2446.41	24.1162
2451.11	22.7808
2455.82	7.09618
2460.51	8.56453
2465.21	-0.04879
2469.9	4.27355
2474.59	17.2939
2479.28	21.6842
2483.96	10.0565
2488.64	5.63264
2493.32	9.95438
2497.99	15.7685
2502.66	12.7764
2507.32	15.6325
2511.99	14.0518
2516.65	27.1849
2521.3	18.2516
2525.96	13.727
2530.61	4.74484
2535.25	19.5017
2539.89	19.4749
2544.53	19.4597
2549.17	13.496
2553.8	16.4794
2558.43	16.4336
2563.06	19.4337
2567.68	16.4682
2572.3	13.5094
2576.92	19.5983
2581.53	13.5294
2586.14	14.9527
2590.75	1.1089
2595.35	4.01883
2599.96	13.0846
2604.55	12.982
2609.15	11.3363
2613.74	11.1712
2618.33	9.49091
2622.91	27.7248
2627.49	0.0268021
2632.07	6.12778
2636.64	3.10091
2641.22	-1.41558
2645.78	11.1071
2650.35	9.69371
2654.91	12.9045
2659.47	9.7651
2664.03	11.2704
2668.58	9.6441
2673.13	6.53069
2677.67	6.74316
2682.22	3.95365
2686.76	15.4022
2691.29	15.7237
2695.83	15.8426
2700.36	19.1077
2704.89	11.1219
2709.41	12.7491
2713.93	11.1501
2718.45	24.1549
2722.96	17.7278
2727.47	1.48013
2731.98	12.7506
2736.49	20.7791
2740.99	20.6931
2745.49	12.5297
2749.98	17.4587
2754.47	9.48781
2758.96	9.53916
2763.45	7.90122
2767.93	24.4233
2772.41	21.2091
2776.89	18.0703
2781.36	13.3395
2785.84	15.274
2790.3	15.5436
2794.77	15.7899
2799.23	17.6594
2803.69	16.1302
2808.14	16.2393
2812.59	16.3255
2817.04	28.2032
2821.49	13.0317
2825.93	-2.16836
2830.37	8.06037
2834.81	13.1963
2839.24	18.3491
2843.67	3.04782
2848.1	4.83446
2852.53	13.5234
2856.95	18.8741
2861.37	12.2089
2865.78	19.3884
2870.19	12.7667
2874.6	23.4791
2879.01	25.5641
2883.41	15.4544
2887.81	12.3122
2892.21	19.6918
2896.6	-2.91628
2901	15.1572
2905.38	15.4735
2909.77	17.552
2914.15	12.3929
2918.53	3.62073
2922.91	11.0192
2927.28	0.46917
2931.65	13.3909
2936.02	11.8141
2940.38	10.1559
2944.74	24.8565
2949.1	17.6694
2953.46	14.1265
2957.81	32.4971
2962.16	21.6485
2966.5	14.4589
2970.85	16.4537
2975.19	14.7862
2979.52	27.8613
2983.86	9.6306
2988.19	9.88477
2992.52	26.8922
2996.85	17.9291
3001.17	22.0347
3005.49	39.3269
3009.8	19.0989
3014.12	11.9209
3018.43	27.4859
3022.74	16.5439
3027.04	20.696
3031.34	15.2548
3035.64	25.0439
3039.94	25.2618
3044.23	21.6362
3048.52	16.0391
3052.81	18.132
3057.09	16.3899
3061.38	35.928
3065.65	38.079
3069.93	38.2922
3074.2	20.995
3078.47	34.8479
3082.74	25.3054
3087	25.5765
3091.27	21.9948
3095.52	16.4848
3099.78	28.7379
3104.03	27.2258
3108.28	51.6189
3112.53	36.2724
3116.77	24.8042
3121.01	31.3948
3125.25	27.9677
3129.49	34.7145
3133.72	39.5283
3137.95	29.9987
3142.18	38.8724
3146.4	39.479
3150.62	25.4937
3154.84	36.312
3159.06	47.1699
3163.27	41.3303
3167.48	37.5092
3171.69	48.425
3175.89	36.0862
3180.09	53.2157
3184.29	27.9577
3188.49	55.6108
3192.68	53.6816
3196.87	43.3168
3201.06	50.1978
3205.24	59.3284
3209.42	60.0011
3213.6	67.1815
3217.78	59.2697
3221.95	79.5461
3226.12	51.8663
3230.29	59.0758
3234.45	59.6938
3238.61	62.5
3242.77	58.7483
3246.93	61.6827
3251.08	62.2396
3255.23	58.1552
3259.38	72.0713
3263.53	56.8647
3267.67	78.1496
3271.81	56.117
3275.95	49.6469
3280.08	61.3619
3284.21	68.53
3288.34	91.8044
3292.47	101.322
3296.59	69.3231
3300.71	55.7541
3304.83	60.6385
3308.95	63.2179
3313.06	61.1136
3317.17	63.6827
3321.27	61.6412
3325.38	76.0352
3329.48	60.0547
3333.58	91.215
3337.67	80.0752
3341.77	68.6593
3345.86	83.1881
3349.95	85.805
3354.03	83.676
3358.11	93.5794
3362.19	77.2246
3366.27	99.1139
3370.34	85.07
3374.42	85.3402
3378.48	90.3527
3382.55	90.5245
3386.61	88.2552
3390.68	73.8507
3394.73	105.44
3398.79	91.1069
3402.84	81.518
3406.89	86.4458
3410.94	93.7894
3414.98	86.5228
3419.03	101.179
3423.06	108.513
3427.1	118.336
3431.14	94.0567
3435.17	89.3466
3439.2	77.3349
3443.22	75.1374
3447.25	80.4275
3451.27	90.6964
3455.28	86.26
3459.3	114.186
3463.31	90.011
3467.32	103.176
3471.33	91.2948
3475.34	56.5406
3479.34	99.8846
3483.34	90.3228
3487.33	67.9884
3491.33	83.6796
3495.32	78.9934
3499.31	66.5474
3503.3	69.3451
3507.28	87.4806
3511.26	82.3952
3515.24	69.5553
3519.22	51.547
3523.19	74.6704
3527.16	69.5558
3531.13	69.5725
3535.1	72.3856
3539.06	54.6508
3543.02	65.2837
3546.98	68.098
3550.93	52.6444
3554.89	52.5974
3558.84	39.6685
3562.78	47.6195
3566.73	40.0026
3570.67	66.4611
3574.61	27.4618
3578.55	48.8189
3582.48	43.9951
3586.41	47.0952
3590.35	39.5946
3594.27	34.7077
3598.2	35.1219
3602.12	24.7885
3606.04	27.7893
3609.95	25.3828
3613.87	33.7372
3617.78	23.2132
3621.69	26.0865
3625.6	20.7365
3629.5	12.6608
3633.4	15.3645
3637.3	23.5583
3641.2	23.7574
3645.09	24.0404
3648.98	10.6418
3652.87	24.3931
3656.76	10.8879
3660.64	2.81119
3664.53	24.752
3668.4	24.9163
3672.28	5.91685
3676.16	17.0991
3680.03	11.9215
3683.9	4.04483
3687.76	12.7503
3691.63	7.68135
3695.49	16.4132
3699.35	0.185333
3703.2	-2.19371
3707.06	6.63789
3710.91	15.5197
3714.76	13.1776
3718.6	2.31427
3722.45	-2.9705
3726.29	17.1594
3730.13	-5.1461
3733.97	12.2497
3737.8	18.3316
3741.63	21.5618
3745.46	4.81183
3749.29	-3.43959
3753.11	5.4193
3756.93	5.66896
3760.75	5.8925
3764.57	-5.35265
3768.39	14.9557
3772.2	12.3853
3776.01	9.82138
3779.81	-7.08258
3783.62	7.70358
3787.42	2.36095
3791.22	2.76033
3795.02	6.11142
3798.81	9.52364
3802.61	-1.55208
3806.4	1.91135
3810.18	14.1505
3813.97	8.86992
3817.75	18.2149
3821.53	4.10182
3825.31	7.54929
3829.09	8.07504
3832.86	5.69482
3836.63	21.0289
3840.4	9.74524
3844.17	-4.48763
3847.93	-1.08586
3851.69	11.2225
3855.45	20.5451
3859.21	11.9832
3862.96	-2.48232
3866.71	7.03867
3870.46	-16.1469
3874.21	8.18626
3877.95	11.6433
3881.69	6.14276
3885.44	3.65677
3889.17	4.19119
3892.91	1.77003
3896.64	-6.59332
3900.37	9.06824
3904.1	0.650269
3907.82	16.3557
3911.55	4.92471
3915.27	8.62573
3918.99	0.249268
3922.7	19.2695
3926.42	7.85491
3930.13	5.53377
3933.84	21.518
3937.54	19.1236
3941.25	13.6986
3944.95	8.29514
3948.65	18.2603
3952.35	37.4714
3956.04	19.6038
3959.73	23.3092
3963.42	5.31081
3967.11	33.7382
3970.8	15.6473
3974.48	16.1663
3978.16	13.5708
3981.84	-1.47592
3985.52	-1.01806
3989.19	21.1456
3992.86	27.8562
3996.53	12.894
3998.37	28.7128