File: Data/3-Raman/processed/bu19w-e-ff11b-fi10-v_1800 (450-850nm)_532nm_edge_100%_x100_vis_h50um_30sx2_01.txt
#Acq. time (s)=	30
#Accumulations=	2
#Range (cm-¹)=	1200...2400
#Windows=	4
#Auto scanning=	Off
#Autofocus=	Off
#Macrospot=	Off
#AutoExposure=	Off
#Spike filter=	Multiple accum.
#Delay time (s)=	2
#Binning=	1
#Readout mode=	Signal
#DeNoise=	Off
#ICS correction=	On
#Dark correction=	Off
#Inst. Process=	Off
#Detector Gain=	Best Dynamic
#Detector ADC=	50 kHz HS
#Detector temperature (°C)=	-60.09
#Instrument=	LabRAM HR Evol
#Detector=	SIN-EM FIVIS
#Objective=	x100_VIS
#Grating=	1800 (450-850nm)
#ND Filter=	100%
#Laser=	532nm_Edge
#Hole=	49.98
#Temperature=	0
#Range=	Visible
#StageXY=	75x50mm Scan+
#StageZ=	Z motor
#X (µm)=	0
#Y (µm)=	0
#Z (µm)=	-270.7
#Full time(mm:ss)=	4:20
#Project=	21_11_04
#Sample=	BU19w
#Site=
#Title=	BU19w-E-FF11b-FI10-V_1800 (450-850nm)_532nm_Edge_100%_x100_VIS_H50um_30sX2
#Remark=
#Date=	04.11.2021 17:12
#Acquired=	04.11.2021 17:12:18
#Base:Fit=	16.12.2021 17:39:50
#Base:Fit=	16.12.2021 17:48:30
#Base:Sub=	16.12.2021 17:48:31
1200.19	3.17387
1201.3	4.97059
1202.41	3.66165
1203.52	0.0896854
1204.63	3.02734
1205.74	-0.505974
1206.85	0.267067
1207.97	-0.00347519
1209.08	0.803438
1210.19	0.547174
1211.3	0.286806
1212.41	0.0356827
1213.52	0.872515
1214.63	1.73557
1215.74	0.460402
1216.85	-1.89154
1217.95	1.08672
1219.06	-0.16111
1220.17	0.722639
1221.28	1.60421
1222.39	-0.716986
1223.5	1.20342
1224.61	-1.0736
1225.71	-0.14649
1226.82	6.03463
1227.93	-0.499691
1229.03	2.59411
1230.14	3.50339
1231.25	4.37135
1232.35	0.0566139
1233.46	1.00461
1234.57	1.97445
1235.67	6.09973
1236.78	4.9401
1237.88	-2.53375
1238.99	1.56032
1240.1	-0.613985
1241.2	0.363461
1242.3	0.294739
1243.41	0.241789
1244.51	0.179249
1245.62	7.41908
1246.72	-4.14999
1247.82	4.15452
1248.93	2.02017
1250.03	4.05961
1251.13	0.862299
1252.24	0.807262
1253.34	2.8539
1254.44	4.93415
1255.54	0.734844
1256.65	-1.36684
1257.75	8.00163
1258.85	-0.377781
1259.95	2.74954
1261.05	13.1385
1262.15	25.7715
1263.25	31.9605
1264.35	15.3015
1265.45	6.92461
1266.55	4.85259
1267.66	5.94241
1268.75	2.84263
1269.85	3.87713
1270.95	8.05112
1272.05	8.08603
1273.15	7.09287
1274.25	1.88533
1275.35	7.15798
1276.45	5.10387
1277.54	13.5622
1278.64	10.463
1279.74	18.8919
1280.84	48.4061
1281.94	167.431
1283.03	522.362
1284.13	234.018
1285.23	50.6578
1286.32	21.214
1287.42	11.7511
1288.52	5.47241
1289.61	4.47878
1290.71	4.51049
1291.8	3.49231
1292.9	3.52888
1293.99	0.441921
1295.09	1.55731
1296.18	1.64471
1297.28	1.66803
1298.37	-0.416063
1299.47	-0.384605
1300.56	-0.337116
1301.65	3.9416
1302.75	3.98372
1303.84	-1.26039
1304.94	4.05118
1306.03	0.905262
1307.12	-0.102207
1308.21	0.998251
1309.31	-5.27169
1310.4	2.16147
1311.49	-3.06086
1312.58	1.21515
1313.67	3.36549
1314.76	-0.799314
1315.86	-0.743519
1316.95	-1.75252
1318.04	-0.639187
1319.13	1.52106
1320.22	-2.65632
1321.31	-1.57557
1322.4	2.67381
1323.49	-0.443182
1324.58	5.934
1325.67	1.72078
1326.76	3.87222
1327.85	2.91825
1328.93	-1.23385
1330.02	4.08304
1331.11	-3.27848
1332.2	2.00141
1333.29	-3.23961
1334.37	2.03422
1335.46	-2.13226
1336.55	4.19454
1337.64	1.08275
1338.72	1.1177
1339.81	-4.06512
1340.9	-2.96834
1341.98	2.29959
1343.07	2.33023
1344.16	3.42509
1345.24	4.49348
1346.33	2.41259
1347.41	1.39054
1348.5	0.385057
1349.58	-0.626814
1350.67	1.4809
1351.75	0.478394
1352.84	2.63693
1353.92	3.68452
1355.01	2.66646
1356.09	2.71925
1357.17	4.83134
1358.26	-1.36773
1359.34	3.84824
1360.42	-2.35023
1361.5	1.83547
1362.59	4.97925
1363.67	5.04099
1364.75	7.14356
1365.83	3.02159
1366.92	7.17343
1368	8.25997
1369.08	21.754
1370.16	2.13601
1371.24	5.24976
1372.32	10.4091
1373.4	9.40501
1374.48	15.6185
1375.56	9.4845
1376.64	6.40642
1377.72	11.6215
1378.8	15.8225
1379.88	19.9355
1380.96	26.094
1382.04	21.9433
1383.12	32.1813
1384.2	53.7522
1385.28	156.543
1386.36	910.631
1387.43	452.227
1388.51	72.473
1389.59	27.3405
1390.67	18.082
1391.74	18.0919
1392.82	10.941
1393.9	17.1078
1394.97	8.96838
1396.05	6.95847
1397.13	11.0686
1398.2	12.1346
1399.28	10.14
1400.35	6.09797
1401.43	10.2401
1402.5	6.23842
1403.58	9.35172
1404.65	12.4497
1405.73	13.4863
1406.8	30.9489
1407.88	56.6323
1408.95	43.3594
1410.03	14.6676
1411.1	8.51876
1412.17	7.54327
1413.25	7.60371
1414.32	6.63155
1415.39	-0.519695
1416.47	2.60413
1417.54	4.70198
1418.61	0.628042
1419.68	4.75578
1420.75	2.71357
1421.83	6.87266
1422.9	2.86765
1423.97	6.84732
1425.04	5.88413
1426.11	0.796967
1427.18	2.84507
1428.25	0.819061
1429.32	0.860617
1430.39	-0.108879
1431.46	1.99223
1432.53	0.972263
1433.6	3.01745
1434.67	5.11418
1435.74	2.06534
1436.81	1.06168
1437.88	2.11318
1438.95	3.17472
1440.01	2.19751
1441.08	-1.87635
1442.15	2.25606
1443.22	2.27521
1444.29	-0.76544
1445.35	4.39717
1446.42	0.313713
1447.49	2.38218
1448.56	-0.656324
1449.62	-1.66486
1450.69	0.403555
1451.75	-3.67631
1452.82	-2.62184
1453.89	-1.57246
1454.95	-2.5736
1456.02	3.60716
1457.08	-1.50238
1458.15	-2.50228
1459.21	-1.45002
1460.28	-0.406658
1461.34	-0.393631
1462.41	2.68273
1463.47	0.647787
1464.53	1.73647
1465.6	1.67576
1466.66	-3.41151
1467.72	2.72935
1468.79	0.707672
1469.85	0.714005
1470.91	-1.31089
1471.97	-0.277317
1473.04	1.77447
1474.1	-1.26213
1475.16	-0.219213
1476.22	0.811552
1477.29	0.824608
1478.34	-2.2142
1479.41	0.84053
1480.47	0.839705
1481.53	3.90803
1482.59	3.94336
1483.65	-0.0966606
1484.71	0.863457
1485.77	2.9496
1486.83	-0.0756187
1487.89	-0.071558
1488.95	-0.0657101
1490.01	-0.0485992
1491.07	-0.0403042
1492.12	0.99074
1493.18	3.02975
1494.24	-3.01218
1495.3	2.041
1496.36	-0.982622
1497.42	-1.97482
1498.47	-0.943941
1499.53	1.10127
1500.59	-1.90877
1501.64	0.122063
1502.7	4.16434
1503.76	3.17167
1504.81	-3.87026
1505.87	-0.842598
1506.93	0.189316
1507.98	1.21421
1509.04	0.227064
1510.09	-0.762558
1511.15	-1.77455
1512.21	0.217098
1513.26	-2.7894
1514.31	2.26155
1515.37	1.25154
1516.42	-0.748564
1517.48	2.28033
1518.53	1.30393
1519.58	0.322443
1520.64	3.35228
1521.69	-1.64712
1522.75	-0.636822
1523.8	0.360209
1524.85	1.37797
1525.9	1.41185
1526.95	-0.57366
1528.01	-1.56473
1529.06	-0.549826
1530.11	1.46947
1531.16	0.496485
1532.21	-2.49056
1533.27	0.555412
1534.32	1.57353
1535.37	-1.43611
1536.42	-0.44194
1537.47	1.56326
1538.52	0.568413
1539.57	0.631519
1540.62	1.67191
1541.67	1.66909
1542.72	0.664343
1543.77	1.66517
1544.81	-1.29998
1545.86	0.733873
1546.91	-0.244551
1547.96	2.76179
1549.01	3.73851
1550.06	3.83678
1551.1	2.87766
1552.15	2.90209
1553.2	1.886
1554.25	3.88389
1555.3	1.8875
1556.34	0.901058
1557.39	-1.08517
1558.43	2.91118
1559.48	2.90633
1560.53	0.916029
1561.57	0.946119
1562.62	2.96416
1563.66	1.98829
1564.71	2.98621
1565.76	2.99467
1566.8	3.02747
1567.84	0.0390949
1568.89	3.04557
1569.93	2.06157
1570.98	4.07143
1572.02	4.07481
1573.07	5.07314
1574.11	2.1039
1575.15	5.13669
1576.2	2.14793
1577.24	6.1227
1578.28	1.13344
1579.32	0.153854
1580.37	-1.82293
1581.41	-0.823116
1582.45	4.16534
1583.49	2.18368
1584.53	5.19149
1585.58	3.20813
1586.62	3.2055
1587.66	0.231421
1588.7	0.255941
1589.74	3.26232
1590.78	0.294863
1591.82	3.28531
1592.86	2.28029
1593.9	3.26383
1594.94	3.29002
1595.98	1.30577
1597.02	4.30541
1598.06	2.32526
1599.1	3.31315
1600.14	2.31907
1601.17	5.27703
1602.21	4.25065
1603.25	1.35262
1604.29	2.08127
1605.33	2.20926
1606.37	-0.196163
1607.4	3.69377
1608.44	3.6494
1609.48	3.29564
1610.51	5.62185
1611.55	3.61811
1612.59	2.32174
1613.62	2.25345
1614.66	3.5015
1615.7	4.67599
1616.73	3.41339
1617.77	3.45674
1618.8	2.1644
1619.84	1.46347
1620.87	1.25306
1621.91	2.71217
1622.94	3.39167
1623.98	2.68136
1625.01	2.19911
1626.04	3.32882
1627.08	2.35347
1628.11	1.95477
1629.07	-0.410065
1630.12	2.55316
1631.16	-1.37242
1632.21	6.53964
1633.25	4.56606
1634.3	2.61559
1635.34	0.651957
1636.39	-1.31612
1637.43	3.61053
1638.48	1.64856
1639.52	0.67532
1640.57	-0.290154
1641.61	-0.283167
1642.65	0.709616
1643.7	0.715874
1644.74	2.69232
1645.78	3.68849
1646.83	0.739817
1647.87	0.748632
1648.91	0.780506
1649.95	2.76637
1651	1.80691
1652.04	0.834412
1653.08	0.839705
1654.12	-0.129509
1655.16	0.882738
1656.21	2.88349
1657.25	1.90249
1658.29	3.87731
1659.33	0.915768
1660.37	-2.02683
1661.41	0.955915
1662.45	6.93692
1663.49	1.95061
1664.53	4.96086
1665.57	2.02307
1666.61	0.977251
1667.65	-0.962551
1668.69	1.04081
1669.72	-0.92597
1670.76	1.07545
1671.8	1.08618
1672.84	1.0968
1673.88	1.11421
1674.92	3.11485
1675.95	-1.82183
1676.99	4.12492
1678.03	0.162039
1679.07	1.15002
1680.1	2.13916
1681.14	2.14311
1682.18	1.16432
1683.21	0.183502
1684.25	2.16068
1685.29	4.14219
1686.32	-1.76801
1687.36	3.17656
1688.39	0.212217
1689.43	1.1922
1690.46	2.19044
1691.5	1.21845
1692.53	1.21719
1693.57	0.219454
1694.6	-0.767748
1695.64	1.21532
1696.67	3.19536
1697.7	2.19765
1698.74	-0.757475
1699.77	0.234688
1700.81	1.21959
1701.84	3.17957
1702.87	1.212
1703.9	1.21769
1704.94	2.20775
1705.97	-0.740795
1707	1.21104
1708.03	1.19261
1709.06	-1.75759
1710.1	2.16518
1711.13	-1.73675
1712.16	0.220474
1713.19	3.12809
1714.22	-0.787317
1715.25	0.202497
1716.28	0.198849
1717.31	-1.77605
1718.34	-1.79186
1719.37	5.02608
1720.4	-2.7595
1721.43	3.06645
1722.46	1.10745
1723.49	0.133308
1724.52	1.09731
1725.55	-1.83108
1726.58	0.10729
1727.6	0.109713
1728.63	0.0464706
1729.66	-2.82782
1730.69	1.04827
1731.72	-0.879694
1732.74	-0.885374
1733.77	1.98736
1734.8	-3.81289
1735.82	0.0320683
1736.85	2.91315
1737.88	1.94246
1738.91	-2.8747
1739.93	-0.978207
1740.96	-0.99053
1741.98	-0.0368977
1743.01	-0.0370178
1744.03	-2.91418
1745.06	-2.90965
1746.09	0.907307
1747.11	0.891819
1748.13	-1.97326
1749.16	0.903553
1750.18	0.92557
1751.21	-1.93734
1752.23	-0.0405979
1753.26	-1.00515
1754.28	0.892673
1755.3	4.69735
1756.33	0.869118
1757.35	-1.04374
1758.37	-1.98264
1759.39	2.78036
1760.42	-2.93119
1761.44	2.76657
1762.46	0.873373
1763.48	0.879482
1764.5	-1.00299
1765.53	-0.0414143
1766.55	-0.0406761
1767.57	2.81028
1768.59	-1.95695
1769.61	-0.0743313
1770.63	-4.81018
1771.65	-0.0402565
1772.67	-0.975586
1773.69	2.84318
1774.71	0.949705
1775.73	3.83372
1776.75	0.0175476
1777.77	0.00896072
1778.79	1.89812
1779.81	-0.948299
1780.83	-1.8916
1781.85	2.88261
1782.86	0.993143
1783.88	1.96279
1784.9	0.0671711
1785.92	0.0667248
1786.94	-2.77865
1787.95	-1.78152
1788.97	3.03237
1789.99	0.172874
1791	-2.71392
1792.02	0.161036
1793.04	2.08585
1794.05	2.09231
1795.07	1.1685
1796.09	-1.69404
1797.1	1.20569
1798.12	-1.66793
1799.13	-0.709372
1800.15	-1.67774
1801.16	0.24408
1802.18	2.17619
1803.19	3.15718
1804.21	1.24689
1805.22	-0.657379
1806.24	2.24912
1807.25	0.327293
1808.26	0.332497
1809.28	-0.625141
1810.29	0.342661
1811.3	0.34445
1812.32	0.354494
1813.33	0.368004
1814.34	0.392445
1815.36	1.37102
1816.37	1.37873
1817.38	0.396645
1818.39	-0.554256
1819.4	-0.545374
1820.42	2.36775
1821.43	-0.520437
1822.44	-0.511215
1823.45	1.42448
1824.46	0.465244
1825.47	0.474077
1826.48	1.44746
1827.49	1.45856
1828.5	2.42423
1829.51	1.45483
1830.52	-1.45224
1831.53	-1.43984
1832.54	0.51263
1833.55	1.48877
1834.56	0.497883
1835.57	-2.41826
1836.58	-0.442635
1837.58	-2.42267
1838.59	0.51812
1839.6	0.536715
1840.61	-2.41263
1841.62	-0.505751
1842.62	-0.511501
1843.63	0.456255
1844.64	-2.43402
1845.65	0.48167
1846.65	2.38893
1847.66	-1.48221
1848.67	-0.522898
1849.67	-0.539602
1850.68	1.36562
1851.68	-0.560009
1852.69	-1.5173
1853.69	-1.52534
1854.7	-0.57815
1855.71	2.28362
1856.71	-1.54562
1857.72	-2.50767
1858.72	-0.605658
1859.72	-0.609062
1860.73	1.31891
1861.73	-0.585014
1862.74	0.35961
1863.74	0.348276
1864.74	2.24566
1865.75	2.21957
1866.75	-0.665464
1867.75	-0.677479
1868.76	-0.673317
1869.76	-2.57422
1870.76	0.279078
1871.76	-1.62581
1872.77	1.21585
1873.77	-1.63581
1874.77	4.039
1875.77	-1.67053
1876.77	0.203682
1877.77	2.16494
1878.78	2.14242
1879.78	1.19265
1880.78	-1.64596
1881.78	5.88325
1882.78	1.13754
1883.78	-0.762712
1884.78	-1.68601
1885.78	2.11247
1886.78	0.21616
1887.78	1.14409
1888.77	-0.760256
1889.77	2.06715
1890.77	1.13884
1891.77	-1.68548
1892.77	0.187037
1893.77	1.11353
1894.76	1.10851
1895.76	-2.63777
1896.76	0.19891
1897.76	0.20455
1898.75	2.07441
1899.75	-1.68871
1900.75	2.08012
1901.75	-0.718893
1902.74	-0.714495
1903.74	2.10585
1904.74	-1.65252
1905.73	0.21945
1906.73	1.15595
1907.72	1.16924
1908.72	4.00196
1909.71	-1.61344
1910.71	-1.59152
1911.7	0.297977
1912.7	-0.639904
1913.69	0.322807
1914.69	-0.599842
1915.68	1.29352
1916.68	-0.598574
1917.67	0.345255
1918.66	-1.5188
1919.66	-1.49248
1920.65	0.407949
1921.64	0.424801
1922.64	-2.41331
1923.63	0.420763
1924.62	-1.46816
1925.61	-0.501024
1926.61	-0.477003
1927.6	-1.40936
1928.59	2.39431
1929.58	-0.425964
1930.57	0.54435
1931.57	3.3912
1932.56	0.540953
1933.55	0.561352
1934.54	1.57849
1935.53	-0.310755
1936.52	-5.07575
1937.51	-1.27329
1938.5	0.641809
1939.49	-1.24632
1940.48	-0.265381
1941.47	-1.21778
1942.46	0.716267
1943.45	0.70051
1944.44	0.730959
1945.42	2.66667
1946.41	0.769798
1947.4	1.72756
1948.39	-0.179428
1949.38	1.75605
1950.37	3.70894
1951.35	-0.0930328
1952.34	-1.0392
1953.33	0.881577
1954.32	-0.110369
1955.3	0.859226
1956.29	1.8575
1957.28	-0.0421982
1958.26	3.81471
1959.25	0.929262
1960.23	-0.997049
1961.22	-1.00099
1962.21	-0.0321484
1963.19	-0.983315
1964.18	1.90768
1965.16	3.83319
1966.15	0.0117531
1967.13	0.983593
1968.12	-1.8919
1969.1	-1.89967
1970.09	-0.948257
1971.07	-0.951242
1972.05	0.0168591
1973.04	-0.945251
1974.02	0.970739
1975.01	2.89945
1975.99	0.0370712
1976.97	1.00097
1977.95	1.95484
1978.94	4.83399
1979.92	1.0049
1980.9	2.91586
1981.88	0.0437889
1982.87	3.86153
1983.85	2.90107
1984.83	-0.929558
1985.81	-0.920597
1986.79	-0.898472
1987.77	2.71125
1988.75	0.211874
1989.73	1.32116
1990.72	0.730497
1991.7	1.89932
1992.68	1.03116
1993.66	0.254875
1994.63	-0.970938
1995.61	1.2431
1996.59	0.590647
1997.57	-0.0972633
1998.55	-2.15927
1999.53	-0.85899
2000.51	-0.334345
2001.49	0.19319
2002.47	-2.54138
2003.45	0.887888
2004.42	-1.00886
2005.4	-0.177067
2006.38	-0.344269
2007.36	2.18336
2008.31	-0.0686054
2009.3	0.859539
2010.29	-1.03378
2011.28	-0.0886421
2012.27	-1.02978
2013.26	0.832941
2014.24	1.74363
2015.23	0.815653
2016.22	2.71958
2017.21	0.83746
2018.2	1.753
2019.18	-0.140482
2020.17	-0.140469
2021.16	-0.133877
2022.15	-2.01026
2023.14	-2.02055
2024.12	-2.03114
2025.11	-0.180052
2026.1	-0.175297
2027.08	-0.123457
2028.07	1.67646
2029.06	-1.9779
2030.04	-0.169031
2031.03	0.778032
2032.01	-1.07156
2033	-0.113293
2033.98	3.6086
2034.97	-1.99359
2035.95	-1.96506
2036.94	0.842287
2037.92	1.77306
2038.91	0.830469
2039.89	-3.8489
2040.87	0.804811
2041.86	-1.06223
2042.84	1.73442
2043.83	1.76219
2044.81	-2.92562
2045.79	-1.91241
2046.78	1.78196
2047.76	2.6936
2048.74	0.842087
2049.72	0.867069
2050.71	-1.92532
2051.69	1.80651
2052.67	-1.91746
2053.65	2.77993
2054.63	1.84915
2055.62	-1.8966
2056.6	2.77628
2057.58	0.917822
2058.56	1.87265
2059.54	0.944283
2060.52	0.943348
2061.5	-1.85711
2062.48	-0.911518
2063.46	-0.898977
2064.44	0.0488663
2065.42	0.07057
2066.4	0.0817699
2067.38	1.03289
2068.36	0.104004
2069.34	-1.78907
2070.31	-0.830441
2071.29	0.138308
2072.27	-0.801676
2073.25	-0.800833
2074.23	1.09241
2075.21	1.12476
2076.18	3.02482
2077.16	-0.766191
2078.14	2.07188
2079.12	-1.68472
2080.09	2.10721
2081.07	-1.67409
2082.05	2.10924
2083.02	3.05587
2084	1.16706
2084.98	1.16965
2085.95	-0.707111
2086.93	-0.695679
2087.9	1.20061
2088.88	-0.685432
2089.85	-0.674816
2090.83	0.280729
2091.8	-1.59751
2092.78	1.27182
2093.75	-0.612226
2094.73	2.23875
2095.7	2.22784
2096.68	-2.52632
2097.65	1.26392
2098.62	-0.637775
2099.6	1.25915
2100.57	1.26836
2101.54	1.27531
2102.52	0.32106
2103.49	-3.48203
2104.46	1.27247
2105.44	2.23679
2106.41	0.341621
2107.38	0.337681
2108.35	0.319878
2109.32	-0.622179
2110.3	2.22779
2111.27	0.323391
2112.24	0.322815
2113.21	-0.615824
2114.18	-1.56811
2115.15	0.330669
2116.12	0.320065
2117.09	-0.631989
2118.06	1.2528
2119.03	3.13077
2120	-0.671473
2120.97	-1.61101
2121.94	0.299463
2122.91	0.306982
2123.88	3.14664
2124.85	0.270332
2125.82	0.248356
2126.79	2.12374
2127.76	0.22603
2128.72	-0.721991
2129.69	-1.67222
2130.66	1.15463
2131.63	1.1434
2132.6	3.96188
2133.56	1.13125
2134.53	0.186411
2135.5	0.178232
2136.47	-0.777727
2137.43	3.94319
2138.4	2.99073
2139.37	1.09598
2140.33	0.142206
2141.3	1.07542
2142.26	2.01446
2143.23	0.0874691
2144.19	2.93102
2145.16	0.102329
2146.13	2.91472
2147.09	0.0846539
2148.06	2.89186
2149.02	1.93574
2149.98	0.975266
2150.95	-0.898943
2151.91	0.044096
2152.88	-1.84389
2153.84	-0.919081
2154.8	-0.948111
2155.77	2.76958
2156.73	-0.0380707
2157.69	1.83881
2158.66	-1.90413
2159.62	1.81715
2160.58	0.867161
2161.54	-1.93905
2162.51	-1.01056
2163.47	1.77674
2164.43	-2.89876
2165.39	0.828943
2166.35	-1.97516
2167.32	2.66166
2168.28	-1.08108
2169.24	0.78896
2170.2	-3.85153
2171.16	1.71745
2172.12	-0.169868
2173.08	0.753824
2174.04	-2.03076
2175	-1.10533
2175.96	-1.11193
2176.92	-0.188206
2177.88	-0.192451
2178.84	3.51181
2179.8	0.724073
2180.76	-0.210176
2181.72	-0.21892
2182.68	0.697094
2183.63	-1.17494
2184.59	3.45558
2185.55	2.53583
2186.51	2.55272
2187.47	0.709183
2188.43	2.55014
2189.38	-0.255863
2190.34	-3.03988
2191.3	1.59747
2192.25	0.674381
2193.21	-1.17086
2194.17	-3.00945
2195.12	0.698601
2196.08	0.674839
2197.04	2.51426
2197.99	1.59307
2198.95	-1.1732
2199.9	3.50628
2200.86	2.60162
2201.81	-0.285994
2202.77	2.55396
2203.72	-0.191776
2204.68	0.710394
2205.63	-0.245905
2206.59	-3.03771
2207.54	-0.2369
2208.49	-0.225775
2209.45	0.706211
2210.4	-0.217997
2211.36	-0.207064
2212.31	-0.202675
2213.26	-0.213169
2214.22	-4.86248
2215.17	-2.0591
2216.12	0.74032
2217.07	1.67215
2218.03	0.738916
2218.98	2.6179
2219.93	-2.05015
2220.88	0.744589
2221.83	0.729481
2222.78	-2.06606
2223.74	3.55824
2224.69	-0.164843
2225.64	1.72493
2226.59	-0.135313
2227.54	-1.06819
2228.49	-0.13546
2229.44	0.809454
2230.39	-0.114401
2231.34	-1.03859
2232.29	2.73567
2233.24	2.75098
2234.19	1.81189
2235.14	-1.02666
2236.09	2.73914
2237.04	-0.0720081
2237.98	-0.988441
2238.93	-0.971754
2239.88	3.73008
2240.83	-1.91355
2241.78	-0.0203915
2242.73	-0.0158978
2243.67	1.86568
2244.62	-1.8933
2245.57	-0.931087
2246.52	-1.86559
2247.46	0.979263
2248.41	-0.91608
2249.36	0.0354977
2250.3	-2.81072
2251.25	0.0183411
2252.2	0.0295353
2253.14	0.0588379
2254.09	-1.82252
2255.03	0.0753479
2255.98	0.0857315
2256.92	-0.849445
2257.87	1.05825
2258.81	-1.78087
2259.76	2.98069
2260.7	1.09529
2261.65	-0.79797
2262.59	-0.783661
2263.54	-1.71182
2264.48	1.17545
2265.42	0.231606
2266.37	-0.73377
2267.31	0.211876
2268.26	-0.744934
2269.2	-3.58922
2270.14	1.20815
2271.08	0.268127
2272.03	1.23676
2272.97	-1.62587
2273.91	0.295813
2274.85	0.30435
2275.79	-0.641335
2276.74	0.337135
2277.68	-0.591505
2278.62	0.376648
2279.56	-1.55558
2280.5	0.353449
2281.44	-0.603653
2282.38	2.29023
2283.32	-0.558598
2284.26	-1.49379
2285.2	0.444742
2286.14	-1.48309
2287.08	1.43033
2288.02	0.475477
2288.96	1.42507
2289.9	0.451149
2290.84	-0.49634
2291.78	-1.43791
2292.72	-4.30923
2293.66	-1.40895
2294.6	2.44035
2295.54	1.4733
2296.47	-2.38017
2297.41	3.41729
2298.35	4.40655
2299.29	0.570608
2300.23	-0.385571
2301.16	-1.33602
2302.1	-1.33187
2303.04	-1.32615
2303.97	-1.3118
2304.91	-2.26193
2305.85	2.58352
2306.78	2.591
2307.72	0.658144
2308.65	2.6006
2309.59	2.62709
2310.53	0.699413
2311.46	2.60518
2312.4	2.59909
2313.33	-1.23959
2314.27	-0.244305
2315.2	-1.20454
2316.14	-0.252062
2317.07	-0.244923
2318	-0.238325
2318.94	-0.240946
2319.87	-1.20041
2320.81	0.744925
2321.74	6.56943
2322.67	1.752
2323.61	3.69838
2324.54	8.5242
2325.47	6.57618
2326.41	16.2099
2327.34	83.6653
2328.27	55.7199
2329.2	16.1829
2330.13	5.5945
2331.07	0.788713
2332	0.795044
2332.93	1.75585
2333.86	-3.05691
2334.79	2.71327
2335.72	1.75976
2336.66	1.76277
2337.59	0.804556
2338.52	-0.150379
2339.45	2.73884
2340.38	3.69305
2341.31	3.6741
2342.24	2.71037
2343.17	1.75698
2344.1	-1.11012
2345.02	-0.150606
2345.95	2.71766
2346.88	-1.11031
2347.81	2.66109
2348.74	2.63721
2349.67	2.50545
2350.6	1.2921
2351.53	1.55523
2352.45	3.15388
2353.38	1.06772
2354.31	0.86853
2355.24	-0.5858
2356.17	0.052824
2357.09	1.40311
2358.02	-0.646471
2358.95	-0.796743
2359.87	-0.752377
2360.8	3.1989
2361.73	-1.06442
2362.65	0.978201
2363.58	-1.7858
2364.5	1.11559
2365.43	0.0962391
2366.36	-2.10936
2367.28	-1.12585
2368.2	1.03442
2368.98	-1.21659
2369.92	-0.286295
2370.86	-1.23911
2371.79	2.52103
2372.73	1.5704
2373.67	1.56258
2374.6	-0.329269
2375.54	-1.27789
2376.48	2.46993
2377.41	-0.353912
2378.35	1.5087
2379.28	1.48678
2380.22	2.41272
2381.15	-0.399139
2382.09	1.46984
2383.02	-0.408506
2383.96	-1.34792
2384.89	3.32106
2385.83	-3.24248
2386.76	-0.461491
2387.69	1.38892
2388.63	5.11188
2389.56	1.37168
2390.5	0.434687
2391.43	0.430492
2392.36	2.28198
2393.3	0.383699
2394.23	2.22248
2395.16	-0.570805
2396.09	0.400061
2397.02	0.380774
2397.96	-1.49485
2398.89	0.358315
2399.82	-1.51695