File: Data/3-Raman/processed/bu19w-e-ff11-fi03-v_150 (500nm)_633nm_edge_100%_x100_vis_h50um_60sx2_01_0.txt
#Acq. time (s)=	60
#Accumulations=	2
#Range (cm-¹)=	100...4000
#Windows=	1
#Auto scanning=	Off
#Autofocus=	Off
#Macrospot=	Off
#AutoExposure=	Off
#Spike filter=	Multiple accum.
#Delay time (s)=	2
#Binning=	1
#Readout mode=	Signal
#DeNoise=	Off
#ICS correction=	On
#Dark correction=	Off
#Inst. Process=	Off
#Detector Gain=	Best Dynamic
#Detector ADC=	50 kHz HS
#Detector temperature (°C)=	-60.09
#Instrument=	LabRAM HR Evol
#Detector=	SIN-EM FIVIS
#Objective=	x100_VIS
#Grating=	150 (500nm)
#ND Filter=	100%
#Laser=	633nm_Edge
#Hole=	49.98
#Temperature=	0
#Range=	Visible
#StageXY=	75x50mm Scan+
#StageZ=	Z motor
#X (µm)=	0
#Y (µm)=	0
#Z (µm)=	-257.1
#Full time(mm:ss)=	2:04
#Project=	21_11_04
#Sample=	BU19w
#Site=
#Title=	BU19w-E-FF11-FI03-V_150 (500nm)_633nm_Edge_100%_x100_VIS_H50um_60sX2
#Remark=
#Date=	04.11.2021 16:50
#Acquired=	04.11.2021 16:50:57
#Base:Fit=	16.12.2021 17:39:50
#Base:Edit=	16.12.2021 17:49:34
#Base:Edit=	16.12.2021 17:49:36
#Base:Edit=	16.12.2021 17:49:37
#Base:Sub=	16.12.2021 17:49:39
102.881	303.618
109.397	256.425
115.908	225.493
122.414	218.372
128.914	247.565
135.409	250.792
141.898	235.608
148.383	252.891
154.861	390.743
161.335	365.719
167.801	152.513
174.264	62.409
180.721	37.9737
187.173	1.55507
193.62	-1.82027
200.061	11.6431
206.496	11.5099
212.926	41.3587
219.352	124.083
225.772	384.261
232.185	498.27
238.595	221.993
244.999	107.248
251.397	120.226
257.791	149.581
264.178	126.16
270.561	112.581
276.939	143.897
283.31	97.6077
289.678	65.6924
296.039	68.9675
302.396	112.159
308.746	269.762
315.093	692.628
321.433	943.496
327.768	527.676
334.099	235.845
340.423	173.36
346.743	171.29
353.058	223.885
359.367	218.928
365.671	137.831
371.971	55.0981
378.265	22.3117
384.553	20.6494
390.837	1.50821
397.116	9.79474
403.389	15.4921
409.657	47.6027
415.92	73.0709
422.178	112.725
428.431	159.298
434.678	158.096
440.921	172.855
447.158	240.93
453.391	265.492
459.618	179.113
465.84	102.739
472.057	81.6084
478.27	88.6415
484.477	76.0779
490.679	87.7124
496.876	126.375
503.068	185.59
509.255	221.543
515.436	211.857
521.613	219.163
527.785	221.032
533.952	188.35
540.113	147.896
546.27	107.919
552.423	114.736
558.568	75.1185
564.711	74.7466
570.848	93.8891
576.979	73.2975
583.107	115.474
589.228	140.769
595.345	143.88
601.458	151.076
607.565	180.999
613.667	178.414
619.764	172.272
625.856	119.125
631.944	91.6877
638.026	88.274
644.104	104.255
650.177	94.7365
656.244	83.1394
662.308	50.0096
668.365	39.4458
674.418	12.3971
680.467	13.3786
686.511	4.16644
692.549	18.4031
698.582	19.5739
704.611	18.8002
710.635	25.419
716.655	17.6222
722.669	11.6987
728.679	7.52845
734.683	13.5927
740.683	17.7381
746.678	9.74648
752.669	24.1961
758.654	31.2551
764.635	8.68919
770.611	23.5612
776.582	17.8148
782.549	11.9088
788.511	31.3209
794.466	18.6032
800.419	23.6661
806.366	11.642
812.309	24.0337
818.247	34.395
824.18	20.2977
830.108	37.1081
836.033	26.1147
841.952	37.7697
847.865	36.3663
853.776	40.6495
859.681	61.9423
865.58	89.0217
871.476	101.03
877.366	125.156
883.253	120.716
889.134	122.739
895.012	115.137
900.883	110.129
906.751	121.986
912.614	132.785
918.473	115.464
924.326	149.205
930.174	177.662
936.019	242.242
941.859	320.982
947.693	377.683
953.525	383.412
959.35	386.946
965.171	413.072
970.988	503.256
976.801	673.576
982.608	754.37
988.411	650.601
994.209	491.556
1000	417.156
1005.79	439.522
1011.58	500.677
1017.36	570.946
1023.13	507.886
1028.9	368.53
1034.67	294.898
1040.43	264.347
1046.19	240.378
1051.94	188.898
1057.69	178.752
1063.44	155.68
1069.17	162.408
1074.91	207.954
1080.64	268.816
1086.37	396.404
1092.09	612.113
1097.8	593.297
1103.52	430.469
1109.22	334.956
1114.93	271.916
1120.63	248.811
1126.32	281.809
1132.01	322.901
1137.7	426.903
1143.38	592.272
1149.06	764.559
1154.73	482.656
1160.4	247.198
1166.06	155.245
1171.72	132.27
1177.38	98.5786
1183.03	81.7144
1188.67	75.8655
1194.31	53.5667
1199.95	46.0616
1205.58	30.8791
1211.21	25.5205
1216.84	19.199
1222.46	5.91044
1228.07	17.4815
1233.68	12.025
1239.29	17.5109
1244.89	16.8202
1250.49	8.92367
1256.08	16.0891
1261.67	20.0761
1267.26	26.0385
1272.84	146.608
1278.42	45.7656
1283.99	10.4824
1289.56	19.3975
1295.12	15.3836
1300.68	13.4492
1306.23	10.634
1311.78	10.9729
1317.33	6.36768
1322.87	-0.24942
1328.41	3.25912
1333.94	3.72571
1339.47	1.07845
1345	0.363098
1350.52	8.82487
1356.04	1.86662
1361.55	14.3498
1367.06	9.28165
1372.56	37.0449
1378.06	265.048
1383.56	15.4992
1389.05	16.5287
1394.53	17.6283
1400.02	29.1596
1405.5	14.9855
1410.97	-1.26191
1416.44	5.19114
1421.91	-1.77728
1427.37	7.85126
1432.83	11.286
1438.28	5.33292
1443.73	5.61971
1449.17	9.00817
1454.62	1.80793
1460.05	8.17326
1465.48	1.88226
1470.91	1.8679
1476.34	10.271
1481.76	11.3728
1487.17	-3.2545
1492.59	8.43813
1497.99	0.188919
1503.4	-1.7253
1508.8	10.1508
1514.19	1.94852
1519.59	4.38294
1524.97	11.1261
1530.36	3.96711
1535.74	16.1583
1541.11	4.56165
1546.48	4.68111
1551.85	6.80503
1557.21	0.143227
1562.57	12.9414
1567.93	6.30097
1573.28	8.28271
1578.62	3.85953
1583.97	7.02808
1589.3	5.91825
1594.64	3.7718
1599.97	16.7762
1605.3	16.9001
1610.62	14.9396
1615.94	9.7929
1621.25	12.2922
1626.56	8.22021
1631.87	4.10022
1637.17	9.79995
1642.47	6.50285
1647.76	9.85871
1653.05	6.52971
1658.34	16.4397
1663.62	14.119
1668.9	16.2043
1674.18	7.18684
1679.45	14.779
1684.71	10.1094
1689.98	3.215
1695.23	0.815987
1700.49	1.88126
1705.74	13.359
1710.99	3.29946
1716.23	13.2021
1721.47	11.1058
1726.7	18.9436
1731.94	2.15701
1737.16	13.4197
1742.39	13.4408
1747.61	15.7013
1752.82	16.7776
1758.03	5.3501
1763.24	14.2299
1768.44	11.8032
1773.64	3.72036
1778.84	12.6877
1784.03	9.23094
1789.22	18.334
1794.41	8.10319
1799.59	12.7295
1804.76	11.6665
1809.94	24.3544
1815.11	16.317
1820.27	4.7795
1825.43	11.7223
1830.59	16.387
1835.74	8.29318
1840.89	2.43821
1846.04	2.36789
1851.18	19.8262
1856.32	13.8637
1861.45	6.77401
1866.58	13.7936
1871.71	14.9142
1876.83	14.8035
1881.95	13.4922
1887.07	7.42058
1892.18	17.8053
1897.29	13.9917
1902.39	13.8347
1907.49	6.67079
1912.59	18.6029
1917.68	10.3794
1922.77	5.44494
1927.86	10.167
1932.94	12.5023
1938.02	5.2053
1943.09	2.65746
1948.16	13.3125
1953.23	8.26897
1958.29	12.8295
1963.35	12.5482
1968.41	11.0224
1973.46	2.21837
1978.51	10.2765
1983.55	15.9151
1988.59	7.13181
1993.63	23.6165
1998.66	12.4765
2003.69	13.3945
2008.72	7.14285
2013.74	10.5461
2018.76	11.5267
2023.77	17.3491
2028.78	9.97058
2033.79	12.3071
2038.79	-4.72167
2043.79	13.4118
2048.79	9.73847
2053.78	9.65239
2058.77	5.94012
2063.76	27.9468
2068.74	19.3721
2073.72	16.8945
2078.69	13.1572
2083.66	18.0155
2088.63	24.0684
2093.59	21.5362
2098.55	10.3802
2103.51	32.7843
2108.46	16.6713
2113.41	39.2932
2118.36	28.1895
2123.3	30.8536
2128.24	22.1471
2133.17	15.8873
2138.11	20.9781
2143.03	15.8974
2147.96	24.7653
2152.88	29.7655
2157.79	25.79
2162.71	28.1455
2167.62	13.8213
2172.52	25.1014
2177.43	13.3765
2182.32	27.1682
2187.22	14.0363
2192.11	16.3376
2197	21.2575
2201.89	8.30864
2206.77	19.7972
2211.64	18.5075
2216.52	5.63016
2221.39	14.7232
2226.26	16.0798
2231.12	13.5412
2235.98	22.7262
2240.84	3.19189
2245.69	21.5781
2250.54	13.7747
2255.39	12.5056
2260.23	19.1768
2265.07	8.62119
2269.9	15.1982
2274.74	12.4423
2279.57	14.9503
2284.39	10.7351
2289.21	10.4654
2294.03	12.8519
2298.84	9.9619
2303.66	11.1295
2308.46	16.3979
2313.27	16.4043
2318.07	21.835
2322.87	21.9202
2327.66	13.9503
2332.45	19.4827
2337.24	11.5211
2342.02	8.97377
2346.8	13.2913
2351.58	16.2481
2356.35	4.03642
2361.12	10.935
2365.89	19.227
2370.65	5.41869
2375.41	23.4161
2380.17	2.56361
2384.92	12.1504
2389.67	18.914
2394.42	18.6557
2399.16	15.5549
2403.9	8.26512
2408.64	6.56883
2413.37	2.32736
2418.1	11.1051
2422.83	2.8481
2427.55	-1.45905
2432.27	1.41121
2436.99	17.0936
2441.7	15.8334
2446.41	18.8344
2451.11	11.8611
2455.82	0.528046
2460.51	10.6831
2465.21	19.4489
2469.9	16.6728
2474.59	18.2028
2479.28	11.0471
2483.96	-0.547821
2488.64	31.5193
2493.32	15.4669
2497.99	9.61374
2502.66	15.4448
2507.32	22.7352
2511.99	18.2272
2516.65	12.1997
2521.3	18.014
2525.96	13.4946
2530.61	17.8423
2535.25	14.833
2539.89	23.7342
2544.53	20.7683
2549.17	13.3396
2553.8	8.86273
2558.43	7.30688
2563.06	26.8251
2567.68	2.82254
2572.3	28.5454
2576.92	15.0167
2581.53	15.0058
2586.14	34.6251
2590.75	11.6181
2595.35	20.5813
2599.96	20.4984
2604.55	21.8846
2609.15	21.7215
2613.74	9.25644
2618.33	22.8049
2622.91	11.8725
2627.49	33.1599
2632.07	23.9211
2636.64	20.9308
2641.22	27.3018
2645.78	27.5374
2650.35	26.1829
2654.91	32.5446
2659.47	30.9442
2664.03	21.456
2668.58	22.8965
2673.13	35.4557
2677.67	31.0671
2682.22	36.3923
2686.76	33.7312
2691.29	38.9565
2695.83	18.2804
2700.36	18.2755
2704.89	27.9005
2709.41	29.4745
2713.93	18.1342
2718.45	14.9113
2722.96	16.4778
2727.47	35.8037
2731.98	40.4702
2736.49	38.6222
2740.99	27.0158
2745.49	31.7601
2749.98	15.4048
2754.47	30.2866
2758.96	31.9109
2763.45	20.3274
2767.93	31.8347
2772.41	30.169
2776.89	17.0531
2781.36	20.5504
2785.84	34.1091
2790.3	17.7067
2794.77	31.291
2799.23	28.0845
2803.69	38.2541
2808.14	29.8617
2812.59	14.6457
2817.04	22.9897
2821.49	12.7456
2825.93	16.069
2830.37	24.4807
2834.81	19.2735
2839.24	24.2784
2843.67	24.1926
2848.1	22.4595
2852.53	15.6435
2856.95	20.8996
2861.37	34.8085
2865.78	24.7123
2870.19	12.8442
2874.6	28.7036
2879.01	1.10455
2883.41	17.1122
2887.81	19.2068
2892.21	7.18008
2896.6	26.9228
2901	14.9111
2905.38	-0.853531
2909.77	20.75
2914.15	24.4433
2918.53	24.5639
2922.91	-0.441803
2927.28	3.3326
2931.65	28.865
2936.02	23.6167
2940.38	20.0504
2944.74	18.2702
2949.1	20.0424
2953.46	30.9678
2957.81	14.498
2962.16	18.1347
2966.5	16.321
2970.85	25.5608
2975.19	20.1319
2979.52	23.9032
2983.86	31.4585
2988.19	31.72
2992.52	48.7587
2996.85	19.346
3001.17	51.4884
3005.49	31.3971
3009.8	37.5013
3014.12	39.8281
3018.43	51.7491
3022.74	35.2361
3027.04	45.1746
3031.34	68.4532
3035.64	47.6782
3039.94	59.4178
3044.23	51.9834
3048.52	61.8071
3052.81	73.5851
3057.09	71.9221
3061.38	85.727
3065.65	86.0087
3069.93	74.6348
3074.2	84.6474
3078.47	86.9249
3082.74	95.0724
3087	79.8796
3091.27	98.1243
3095.52	122.513
3099.78	113.501
3104.03	122.345
3108.28	119.402
3112.53	150.477
3116.77	135.637
3121.01	163.031
3125.25	148.274
3129.49	166.002
3133.72	141.117
3137.95	161.09
3142.18	166.694
3146.4	159.797
3150.62	179.742
3154.84	180.82
3159.06	198.573
3163.27	226.936
3167.48	211.206
3171.69	237.56
3175.89	208.955
3180.09	211.722
3184.29	216.491
3188.49	238.098
3192.68	223.862
3196.87	216.165
3201.06	200.407
3205.24	221.113
3209.42	203.428
3213.6	187.81
3217.78	185.156
3221.95	175.816
3226.12	179.537
3230.29	170.067
3234.45	173.691
3238.61	159.596
3242.77	134.448
3246.93	142.6
3251.08	92.3484
3255.23	122.348
3259.38	94.0528
3263.53	115.46
3267.67	96.7273
3271.81	100.304
3275.95	96.6166
3280.08	76.7381
3284.21	82.006
3288.34	96.48
3292.47	92.5552
3296.59	67.8254
3300.71	84.6905
3304.83	73.8105
3308.95	76.8117
3313.06	68.1471
3317.17	75.7896
3321.27	69.5308
3325.38	77.3789
3329.48	52.4909
3333.58	72.3833
3337.67	61.7096
3341.77	81.5137
3345.86	70.4224
3349.95	61.5733
3354.03	57.4694
3358.11	77.3422
3362.19	63.8318
3366.27	50.2227
3370.34	60.5861
3374.42	49.2565
3378.48	61.9084
3382.55	48.0212
3386.61	34.0747
3390.68	44.2556
3394.73	49.6306
3398.79	42.9726
3402.84	36.224
3406.89	48.8608
3410.94	15.2737
3414.98	20.576
3419.03	30.7669
3423.06	36.0723
3427.1	38.9812
3431.14	27.3113
3435.17	37.6862
3439.2	35.9055
3443.22	29.2446
3447.25	34.9759
3451.27	38.285
3455.28	39.221
3459.3	30.3412
3463.31	16.4408
3467.32	32.4484
3471.33	23.4319
3475.34	31.8212
3479.34	20.1548
3483.34	28.6414
3487.33	19.3832
3491.33	27.8622
3495.32	26.1299
3499.31	31.9916
3503.3	30.1114
3507.28	20.461
3511.26	18.3481
3515.24	26.4694
3519.22	32.0152
3523.19	16.9866
3527.16	19.9938
3531.13	30.7162
3535.1	21.0333
3539.06	39.8786
3543.02	32.8138
3546.98	20.453
3550.93	23.5668
3554.89	42.1049
3558.84	32.1816
3562.78	37.9346
3566.73	54.2254
3570.67	28.8141
3574.61	53.0967
3578.55	40.772
3582.48	65.3635
3586.41	53.0896
3590.35	53.9822
3594.27	33.5858
3598.2	34.395
3602.12	29.7873
3606.04	25.1225
3609.95	-1.12251
3613.87	39.8182
3617.78	18.8362
3621.69	35.5047
3625.6	22.3139
3629.5	11.7829
3633.4	28.2455
3637.3	20.4349
3641.2	15.4493
3645.09	21.397
3648.98	8.21556
3652.87	22.1623
3656.76	19.7437
3660.64	33.6749
3664.53	6.63681
3668.4	28.8042
3672.28	31.8375
3676.16	29.4963
3680.03	10.7553
3683.9	30.5417
3687.76	14.6228
3691.63	6.92305
3695.49	24.0875
3699.35	2.41928
3703.2	22.4499
3707.06	25.8375
3710.91	9.59657
3714.76	7.29169
3718.6	13.3558
3722.45	22.2258
3726.29	33.907
3730.13	14.4471
3733.97	11.9809
3737.8	6.64699
3741.63	15.5042
3745.46	12.9489
3749.29	18.9153
3753.11	16.2514
3756.93	16.3885
3760.75	16.4805
3764.57	19.4206
3768.39	2.30946
3772.2	11.0529
3776.01	8.3248
3779.81	14.2603
3783.62	17.3982
3787.42	17.6737
3791.22	15.0285
3795.02	6.65611
3798.81	24.3951
3802.61	18.9908
3806.4	10.6866
3810.18	11.1014
3813.97	11.4812
3817.75	20.6457
3821.53	21.0238
3825.31	15.478
3829.09	1.09306
3832.86	10.3129
3836.63	28.4193
3840.4	11.0304
3844.17	-0.413834
3847.93	8.71539
3851.69	8.93425
3855.45	9.12421
3859.21	3.31268
3862.96	12.4286
3866.71	15.8731
3870.46	13.4968
3874.21	10.7975
3877.95	2.15295
3881.69	-9.46689
3885.44	2.89287
3889.17	9.33464
3892.91	3.86435
3896.64	10.5192
3900.37	11.1523
3904.1	-3.27426
3907.82	21.524
3911.55	1.1048
3915.27	4.90919
3918.99	8.8208
3922.7	15.8894
3926.42	1.64441
3930.13	24.0167
3933.84	0.51326
3937.54	10.6629
3941.25	8.65967
3944.95	22.1313
3948.65	7.91803
3952.35	18.348
3956.04	28.8249
3959.73	26.935
3963.42	28.1587
3967.11	10.8012
3970.8	30.6401
3974.48	22.6714
3978.16	20.9521
3981.84	44.0577
3985.52	39.3207
3989.19	12.9534
3992.86	17.7379
3996.53	38.1868
3998.37	14.3134