File: Data/3-Raman/processed/bu19w-b-ff1-host_150 (500nm)_532nm_edge_100%_x100_vis_h50um_10sx2_01.txt
#Acq. time (s)=	10
#Accumulations=	2
#Range (cm-¹)=	50...5000
#Windows=	1
#Auto scanning=	Off
#Autofocus=	Off
#Macrospot=	Off
#AutoExposure=	Off
#Spike filter=	Multiple accum.
#Delay time (s)=	2
#Binning=	1
#Readout mode=	Signal
#DeNoise=	Off
#ICS correction=	On
#Dark correction=	Off
#Inst. Process=	Off
#Detector Gain=	Best Dynamic
#Detector ADC=	50 kHz HS
#Detector temperature (°C)=	-60.09
#Instrument=	LabRAM HR Evol
#Detector=	SIN-EM FIVIS
#Objective=	x100_VIS
#Grating=	150 (500nm)
#ND Filter=	100%
#Laser=	532nm_Edge
#Hole=	49.98
#Temperature=	0
#Range=	Visible
#StageXY=	75x50mm Scan+
#StageZ=	Z motor
#X (µm)=	0
#Y (µm)=	0
#Z (µm)=	-136.5
#Full time(s)=	25
#Project=	21_05_14
#Sample=	BU19w
#Site=
#Title=	BU19w-FF1-host_150 (500nm)_532nm_Edge_100%_x100_VIS_H50um_10sX2
#Remark=
#Date=	14.05.2021 11:13
#Acquired=	14.05.2021 11:13:10
#Base:Fit=	22.12.2021 12:22:35
#Base:Sub=	22.12.2021 12:26:44
#Data Range:Extract=	22.12.2021 12:27:19
103.953	88.5887
108.572	1.31055
113.192	-1.68567
117.809	40.115
122.424	159.961
127.037	270.461
131.645	101.678
136.253	0.391724
140.859	62.3281
145.463	102.387
150.062	67.9459
154.661	188.763
159.258	294.108
163.852	66.7911
168.442	169.473
173.032	607.951
177.62	2594.42
182.203	3836.14
186.787	1966.39
191.368	857.985
195.946	960.92
200.521	2782.78
205.095	10602.9
209.667	13325.6
214.234	5331.32
218.802	1414.22
223.367	543.821
227.928	319.043
232.488	428.023
237.047	351.381
241.601	262.477
246.155	287.198
250.707	635.868
255.254	936.659
259.802	1243.15
264.344	2471.25
268.887	2669.53
273.428	2135.62
277.964	1514.98
282.5	1000.66
287.034	1505.22
291.564	3490.04
296.093	8705.18
300.619	10685.9
305.144	6034.34
309.667	2889.92
314.185	2388.59
318.703	4309.78
323.218	6634.74
327.732	4543.96
332.241	2096.23
336.751	1347.24
341.258	1424.49
345.761	2421.12
350.264	3078.25
354.763	1960.52
359.262	1032.41
363.756	979.736
368.25	1432.12
372.74	1254.76
377.23	720.292
381.716	355.957
386.201	342.596
390.682	571.699
395.163	466.741
399.64	737.991
404.117	1420.12
408.59	1969.62
413.062	2255.8
417.53	2040.16
421.998	1470.59
426.462	965.026
430.926	1174.73
435.385	2045.67
439.844	1957.88
444.299	733.009
448.755	189.295
453.205	142.574
457.654	181.529
462.102	301.679
466.547	771.067
470.991	2353.67
475.431	4310.23
479.871	2953.32
484.307	1078.25
488.74	447.631
493.174	325.714
497.603	415.845
502.032	530.05
506.457	792.132
510.88	1122.15
515.303	1291.4
519.721	1174.75
524.138	1010.41
528.554	704.12
532.966	546.146
537.378	454.053
541.786	434.751
546.192	482.741
550.598	528.273
554.999	607.523
559.399	719.074
563.798	693.223
568.193	778.291
572.586	729.04
576.979	732.274
581.368	850.675
585.755	679.281
590.139	452.93
594.524	462.561
598.904	718.329
603.282	1763.55
607.66	3769.15
612.034	3517.25
616.406	1756.76
620.776	1197.18
625.146	1603.29
629.511	2633.52
633.875	2770.36
638.236	1601.56
642.598	661.031
646.955	430.607
651.31	346.786
655.663	582.941
660.016	708.844
664.365	572.523
668.712	395.82
673.057	363.714
677.399	403.67
681.742	717.42
686.08	822.128
690.417	931.103
694.751	1229.77
699.083	1288.6
703.415	927.93
707.743	518.719
712.069	250.547
716.393	159.675
720.715	104.179
725.035	26.5344
729.355	40.8563
733.67	43.5077
737.984	-1.98401
742.296	1.93274
746.605	12.4595
750.913	91.2572
755.218	63.8278
759.521	151.314
763.825	111.362
768.124	220.038
772.421	348.374
776.716	456.758
781.009	739.976
785.3	1207.35
789.589	2168.04
793.876	3836.09
798.161	4828.08
802.444	3979.17
806.725	2347.84
811.005	1266.94
815.282	779.089
819.557	517.492
823.83	357.551
828.1	272.482
832.369	198.35
836.636	206.677
840.9	165.156
845.163	144.014
849.423	108.509
853.682	133.644
857.938	103.61
862.193	77.7255
866.445	85.3966
870.695	93.7798
874.944	44.6423
879.19	68.672
883.435	37.2845
887.677	46.5732
891.917	51.5906
896.156	43.7867
900.392	48.7468
904.627	48.3829
908.859	51.0421
913.087	49.4071
917.316	27.9207
921.542	83.7115
925.766	113.124
929.989	49.0649
934.209	86.9292
938.427	111.309
942.644	153.558
946.858	158.129
951.07	190.864
955.281	227.925
959.487	366.107
963.694	556.202
967.898	747.178
972.101	868.339
976.301	814.744
980.5	955.512
984.696	1238
988.891	1248.29
993.081	923.955
997.272	604.049
1001.46	438.79
1005.65	405.096
1009.83	341.668
1014.01	292.41
1018.19	299.511
1022.37	297.75
1026.55	309.062
1030.72	330.621
1034.9	369.415
1039.07	410.986
1043.23	479.014
1047.4	569.448
1051.57	663.268
1055.73	977.056
1059.89	1419.35
1064.05	2411.49
1068.21	4586.47
1072.36	6135.45
1076.51	4847.56
1080.66	3059.13
1084.81	1993.36
1088.96	1520.25
1093.1	1517.99
1097.25	1914.1
1101.39	3032.46
1105.53	4675.67
1109.67	5737.67
1113.8	5050.76
1117.93	3953.17
1122.06	3639.87
1126.19	4366.67
1130.32	4761.39
1134.45	4397.96
1138.57	3815.82
1142.69	3791.76
1146.81	4089.77
1150.93	4393.37
1155.05	3977.52
1159.16	2916.13
1163.27	2256.51
1167.38	2168.84
1171.49	2796.44
1175.6	3699.24
1179.7	3659.53
1183.8	2585.57
1187.91	1855.9
1192	1448.49
1196.1	1005.13
1200.2	811.816
1204.29	714.804
1208.38	670.039
1212.47	755.962
1216.56	731.766
1220.64	724.141
1224.72	581.59
1228.81	483.515
1232.88	526.128
1236.96	735.176
1241.04	1017.24
1245.11	965.449
1249.18	863.28
1253.25	1141.19
1257.32	1584.78
1261.39	1620.37
1265.45	1092.01
1269.51	665.282
1273.57	397.147
1277.63	320.202
1281.69	293.096
1285.75	253.468
1289.8	170.307
1293.85	106.884
1297.9	143.026
1301.95	151.639
1305.99	113.712
1310.04	194.594
1314.08	98.4427
1318.12	146.963
1322.15	99.2607
1326.19	105.498
1330.22	144.799
1334.26	107.173
1338.29	76.3358
1342.32	78.3695
1346.34	110.237
1350.37	92.2725
1354.39	69.4742
1358.41	63.5076
1362.43	91.4391
1366.45	61.3074
1370.46	29.6426
1374.48	103.89
1378.49	43.3105
1382.5	75.1283
1386.51	60.126
1390.51	75.0752
1394.52	78.9796
1398.52	65.152
1402.52	56.1029
1406.52	52.177
1410.52	100.69
1414.51	40.7766
1418.5	62.717
1422.5	82.5071
1426.49	43.2144
1430.47	46.3547
1434.46	36.7611
1438.44	36.009
1442.43	20.2716
1446.4	8.32288
1450.38	7.00391
1454.36	12.3702
1458.34	22.3939
1462.31	24.964
1466.28	35.2202
1470.25	46.6779
1474.22	4.97461
1478.18	54.2345
1482.15	-2.43262
1486.11	85.5658
1490.07	32.892
1494.03	19.418
1497.98	21.7152
1501.94	30.1602
1505.89	59.4832
1509.84	66.6296
1513.79	82.5868
1517.74	-3.14355
1521.69	34.5194
1525.63	43.208
1529.57	20.1318
1533.51	36.8864
1537.45	34.3064
1541.39	31.7577
1545.32	29.2242
1549.25	67.392
1553.19	66.6211
1557.11	50.0846
1561.04	13.0394
1564.97	17.4504
1568.89	57.4822
1572.82	70.3846
1576.74	19.5197
1580.65	45.8296
1584.57	71.0179
1588.49	45.0861
1592.4	35.5309
1596.31	41.3737
1600.22	78.0765
1604.13	44.9669
1608.04	32.1306
1611.94	43.3876
1615.84	56.8101
1619.74	33.782
1623.64	31.1039
1627.54	14.3552
1631.43	60.3655
1635.33	20.2571
1639.22	48.5009
1643.11	11.1099
1647	1.67834
1650.88	16.3302
1654.77	69.2905
1658.65	42.4985
1662.53	32.675
1666.41	85.1093
1670.29	66.8585
1674.17	79.191
1678.04	57.0216
1681.91	66.9457
1685.78	107.38
1689.65	20.9324
1693.52	42.5172
1697.39	10.2577
1701.25	26.3625
1705.11	29.6495
1708.97	62.9382
1712.83	29.7122
1716.69	49.686
1720.54	10.1669
1724.39	-2.00037
1728.25	41.9974
1732.1	11.8146
1735.94	25.5962
1739.79	32.5426
1743.63	36.7379
1747.48	43.8043
1751.32	53.4746
1755.16	21.4756
1758.99	51.734
1762.83	72.9126
1766.66	48.9401
1770.5	55.6801
1774.33	61.6569
1778.16	70.0781
1781.98	89.1775
1785.81	78.645
1789.63	116.896
1793.45	126.254
1797.27	69.795
1801.09	91.1218
1804.91	52.8635
1808.72	92.6024
1812.54	79.2504
1816.35	44.3523
1820.16	106.101
1823.97	8.99329
1827.77	60.4559
1831.58	56.7135
1835.38	78.0719
1839.18	84.0516
1842.98	86.7693
1846.78	31.4856
1850.57	66.4827
1854.37	63.4075
1858.16	46.7129
1861.95	0.987793
1865.74	84.71
1869.53	59.8689
1873.31	67.8778
1877.1	67.728
1880.88	107.036
1884.66	71.8491
1888.44	83.7778
1892.22	114.447
1895.99	117.478
1899.77	80.7963
1903.54	86.8906
1907.31	37.9312
1911.08	86.3657
1914.85	105.573
1918.61	86.2144
1922.37	113.422
1926.14	120.637
1929.9	112.284
1933.66	144.869
1937.41	54.3038
1941.17	108.304
1944.92	135.448
1948.67	100.082
1952.42	90.1697
1956.17	88.6648
1959.92	99.5786
1963.67	85.0171
1967.41	96.2449
1971.15	98.2322
1974.89	61.4196
1978.63	55.2316
1982.37	49.682
1986.1	125.081
1989.84	56.5146
1993.57	58.4553
1997.3	99.0146
2001.03	52.3743
2004.75	93.6295
2008.48	142.47
2012.2	112.938
2015.92	90.7979
2019.64	58.845
2023.36	84.8418
2027.08	48.8936
2030.79	92.2754
2034.51	80.8092
2038.22	75.4811
2041.93	141.492
2045.64	104.92
2049.34	116.366
2053.05	113.323
2056.75	118.456
2060.46	122.18
2064.16	93.3464
2067.85	121.71
2071.55	98.5359
2075.25	124.402
2078.94	147.757
2082.63	118.092
2086.32	105.822
2090.01	116.363
2093.7	85.1233
2097.39	78.8091
2101.07	106.169
2104.75	116.459
2108.43	112.487
2112.11	115.868
2115.79	114.404
2119.46	140.073
2123.14	86.3239
2126.81	61.1577
2130.48	125.61
2134.15	152.819
2137.82	130.714
2141.48	153.514
2145.15	119.973
2148.81	113.145
2152.47	121.078
2156.13	124.498
2159.79	143.66
2163.45	114.724
2167.1	108.083
2170.76	121.337
2174.41	114.177
2178.06	146.394
2181.7	108.528
2185.35	138.384
2189	169.971
2192.64	159.607
2196.28	164.331
2199.92	138.281
2203.56	200.131
2207.2	127.193
2210.83	166.941
2214.47	176.683
2218.1	197.522
2221.73	155.075
2225.36	157.532
2228.99	172.912
2232.61	158.037
2236.24	146.784
2239.86	193.831
2243.48	169.472
2247.1	184.157
2250.72	184.212
2254.33	120.07
2257.95	190.295
2261.56	174.386
2265.17	174.509
2268.78	117.76
2272.39	171.5
2276	120.124
2279.6	169.392
2283.2	137.23
2286.81	151.426
2290.41	163.457
2294.01	156.605
2297.6	152.677
2301.2	151.298
2304.79	137.167
2308.39	143.591
2311.98	131.717
2315.57	98.6616
2319.15	92.6781
2322.74	183.115
2326.32	73.4958
2329.91	108.453
2333.49	122.287
2337.07	142.428
2340.65	166.989
2344.22	152.751
2347.8	129.035
2351.37	96.8973
2354.94	115.161
2358.52	104.355
2362.08	118.648
2365.65	103.315
2369.22	132.928
2372.78	124.485
2376.34	94.8319
2379.9	116.2
2383.46	134.945
2387.02	96.0691
2390.58	60.434
2394.13	151.951
2397.69	167.949
2401.24	123.577
2404.79	85.0699
2408.34	159.117
2411.89	132.866
2415.43	135.491
2418.98	113.621
2422.52	87.5142
2426.06	131.96
2429.6	119.629
2433.14	121.567
2436.67	188.764
2440.21	142.828
2443.74	98.5996
2447.27	172.396
2450.8	150.304
2454.33	114.785
2457.86	101.929
2461.39	131.1
2464.91	110.818
2468.43	177.507
2471.95	119.96
2475.47	105.91
2478.99	116.806
2482.51	137.425
2486.02	151.18
2489.54	123.407
2493.05	119.363
2496.56	54.7936
2500.07	107.903
2503.57	123.995
2507.08	124.736
2510.58	138.56
2514.09	100.769
2517.59	81.0736
2521.09	130.49
2524.59	138.204
2528.08	118.724
2531.58	117.981
2535.07	138.139
2538.56	102.407
2542.05	130.331
2545.54	83.4803
2549.03	103.169
2552.52	106.673
2556	98.275
2559.48	102.77
2562.97	116.515
2566.45	125.326
2569.93	163.664
2573.4	101.368
2576.88	121.804
2580.35	144.369
2583.82	125.476
2587.3	149.677
2590.76	138.717
2594.23	128.206
2597.7	129.726
2601.17	144.579
2604.63	109.504
2608.09	124.63
2611.55	140.06
2615.01	68.0464
2618.47	135.43
2621.92	77.557
2625.38	96.9833
2628.83	95.9354
2632.29	158.742
2635.73	147.023
2639.18	96.6967
2642.63	108.241
2646.08	115.848
2649.52	106.795
2652.96	93.4807
2656.41	108.29
2659.85	115.261
2663.28	109.706
2666.72	90.0262
2670.16	107.906
2673.59	71.595
2677.02	119.985
2680.45	91.0217
2683.88	72.0842
2687.31	138.298
2690.74	79.4829
2694.16	109.635
2697.59	99.2484
2701.01	113.204
2704.43	85.1743
2707.85	87.4031
2711.27	142.132
2714.68	95.8105
2718.1	117.821
2721.51	121.476
2724.92	85.1252
2728.34	84.3651
2731.74	81.6122
2735.15	128.517
2738.56	90.1063
2741.96	110.41
2745.37	151.111
2748.77	96.9373
2752.17	122.543
2755.57	91.4143
2758.96	122.542
2762.36	126.782
2765.76	130.751
2769.15	129.666
2772.54	94.5243
2775.93	44.007
2779.32	110.962
2782.71	102.422
2786.09	88.1818
2789.48	57.9271
2792.86	96.1974
2796.24	55.6218
2799.62	126.406
2803	82.7466
2806.38	82.2117
2809.75	121.817
2813.13	114.506
2816.5	68.837
2819.87	94.4633
2823.24	133.386
2826.61	86.6338
2829.98	125.891
2833.34	130.076
2836.71	89.8652
2840.07	73.3011
2843.43	104.674
2846.79	76.0979
2850.15	68.5525
2853.51	130.788
2856.87	114.827
2860.22	86.9097
2863.57	111.486
2866.92	108.006
2870.27	56.4816
2873.62	48.0436
2876.97	61.1903
2880.32	102.58
2883.66	95.8007
2887.01	88.9413
2890.35	85.809
2893.69	102.061
2897.03	94.4312
2900.36	79.892
2903.7	74.5753
2907.03	88.0372
2910.37	85.2654
2913.7	60.64
2917.03	61.2834
2920.36	63.7166
2923.68	97.2192
2927.01	100.173
2930.34	57.619
2933.66	76.1624
2936.98	123.91
2940.3	104.698
2943.62	67.6815
2946.94	43.0259
2950.26	82.2722
2953.57	101.763
2956.88	109.322
2960.2	88.9214
2963.51	79.865
2966.82	62.8765
2970.12	78.2028
2973.43	58.7941
2976.74	96.0729
2980.04	17.6858
2983.34	74.5415
2986.64	94.922
2989.94	111.619
2993.24	103.995
2996.54	98.3501
2999.83	55.0798
3003.13	60.6744
3006.42	78.6591
3009.71	71.3309
3013	81.0088
3016.29	80.2822
3019.58	110.655
3022.86	67.4495
3026.15	97.8846
3029.43	65.0262
3032.71	90.6583
3035.99	107.744
3039.27	82.2886
3042.55	82.3971
3045.82	67.3839
3049.1	70.3423
3052.37	68.6283
3055.65	57.3657
3058.92	0.0506592
3062.19	71.9529
3065.45	66.8395
3068.72	89.9475
3071.98	57.2234
3075.25	88.0385
3078.51	51.7896
3081.77	59.7711
3085.03	49.6211
3088.29	58.9252
3091.55	93.3187
3094.8	66.3037
3098.06	52.8523
3101.31	53.2421
3104.56	83.052
3107.81	74.6221
3111.06	56.0551
3114.31	48.1139
3117.56	45.938
3120.8	61.8638
3124.04	46.3354
3127.28	58.3763
3130.53	78.0841
3133.77	41.5179
3137	14.3827
3140.24	52.0508
3143.48	50.6356
3146.71	53.1547
3149.94	28.0638
3153.17	62.0266
3156.4	80.7961
3159.63	85.1957
3162.86	43.816
3166.09	53.8107
3169.31	53.1848
3172.53	39.1434
3175.76	49.7649
3178.98	49.8641
3182.2	61.4725
3185.41	77.6401
3188.63	72.7813
3191.84	48.8691
3195.06	58.2961
3198.27	63.8649
3201.48	69.5083
3204.69	74.2577
3207.9	76.2291
3211.11	79.2679
3214.31	61.509
3217.52	40.9022
3220.72	70.7621
3223.92	85.5867
3227.13	23.3811
3230.32	84.0624
3233.52	64.6621
3236.72	90.3879
3239.91	87.6613
3243.11	79.3147
3246.3	72.8591
3249.49	81.83
3252.68	43.1613
3255.87	82.7151
3259.06	88.6467
3262.24	62.8296
3265.43	79.7571
3268.61	72.6379
3271.79	61.59
3274.98	44.8264
3278.16	88.855
3281.33	84.791
3284.51	105.603
3287.69	101.43
3290.86	91.7073
3294.03	131.473
3297.2	110.234
3300.37	107.582
3303.55	117.795
3306.71	114.541
3309.88	110.072
3313.04	108.356
3316.21	113.256
3319.37	135.144
3322.53	142.813
3325.69	175.087
3328.85	205.454
3332.01	93.2396
3335.16	164.494
3338.32	190.512
3341.47	175.959
3344.62	203.318
3347.77	209.469
3350.92	146.766
3354.07	249.225
3357.22	248.085
3360.36	192.499
3363.51	165.216
3366.65	154.055
3369.79	141.059
3372.93	193.398
3376.07	167.47
3379.21	188.87
3382.35	173.316
3385.48	196.689
3388.62	175.62
3391.75	187.681
3394.88	231.341
3398.01	291.283
3401.14	402.723
3404.27	471.825
3407.4	509.808
3410.52	492.661
3413.64	613.104
3416.77	792.705
3419.89	1124.07
3423.01	1623.25
3426.13	2720.85
3429.24	5631.65
3432.36	13232.4
3435.47	24195.8
3438.59	21264.7
3441.7	10223.4
3444.81	4317.38
3447.92	2206.81
3451.03	1310.68
3454.14	935.514
3457.24	652.78
3460.35	533.027
3463.45	456.122
3466.55	369.626
3469.65	361.55
3472.75	338.962
3475.85	308.942
3478.95	315.942
3482.04	335.262
3485.14	359.402
3488.23	412.07
3491.33	461.5
3494.42	479.729
3497.5	648.682
3500.59	803.519
3503.68	994.553
3506.77	1385.23
3509.85	1926.03
3512.93	2610.27
3516.02	3328.81
3519.1	3690.04
3522.18	3285.29
3525.25	2599.77
3528.33	1903.7
3531.41	1406.77
3534.48	982.949
3537.56	755.674
3540.63	608.925
3543.7	452.976
3546.77	399.574
3549.84	335.232
3552.9	284.792
3555.97	255.421
3559.03	225.135
3562.1	190.652
3565.16	217.499
3568.22	158.592
3571.28	192.796
3574.34	168.26
3577.4	164.465
3580.45	133.04
3583.51	162.164
3586.56	133.435
3589.61	148.131
3592.66	115.395
3595.71	122.329
3598.76	95.1732
3601.81	68.8296
3604.85	142.693
3607.9	80.2891
3610.94	77.4242
3613.98	64.1101
3617.02	105.626
3620.07	53.7705
3623.1	55.7603
3626.14	83.3004
3629.18	87.1892
3632.21	79.6689
3635.25	69.6991
3638.28	76.8768
3641.31	50.3284
3644.34	24.2124
3647.37	63.5143
3650.4	93.8246
3653.42	55.0679
3656.45	85.5406
3659.47	67.9613
3662.49	53.8992
3665.52	81.4888
3668.54	66.0768
3671.55	31.853
3674.57	62.801
3677.59	77.8239
3680.61	46.4694
3683.62	77.5012
3686.63	48.0575
3689.64	60.2759
3692.65	42.239
3695.66	19.1046
3698.67	49.3893
3701.68	36.9974
3704.68	47.3835
3707.69	30.0486
3710.69	35.4207
3713.69	33.9353
3716.7	84.915
3719.7	29.1313
3722.69	20.8119
3725.69	54.264
3728.69	8.58826
3731.68	44.6786
3734.68	53.9459
3737.67	25.0208
3740.66	22.5895
3743.65	14.3463
3746.64	40.2032
3749.63	20.3202
3752.61	66.9001
3755.6	40.4047
3758.58	14.8646
3761.57	2.50293
3764.55	41.3191
3767.53	47.0673
3770.51	31.1852
3773.49	57.0166
3776.46	36.6024
3779.44	76.7551
3782.41	40.4063
3785.39	23.9838
3788.36	9.52527
3791.33	40.5896
3794.3	38.7312
3797.27	31.2776
3800.24	39.114
3803.2	27.1913
3806.17	37.024
3809.13	70.5781
3812.09	11.5306
3815.06	30.9724
3818.02	58.0581
3820.98	48.2693
3823.93	16.78
3826.89	55.4171
3829.85	41.9077
3832.8	33.2546
3835.75	47.4561
3838.71	55.9745
3841.66	53.0735
3844.61	45.4321
3847.56	48.3074
3850.5	46.4961
3853.45	54.2483
3856.39	41.9673
3859.34	29.6841
3862.28	-3.75891
3865.22	21.1621
3868.16	33.55
3871.1	8.51477
3874.04	51.5331
3876.98	32.0399
3879.91	42.1743
3882.85	-8.38635
3885.78	31.2838
3888.71	32.4606
3891.64	23.9679
3894.57	45.1271
3897.5	27.6595
3900.43	38.0653
3903.36	34.814
3906.28	50.0049
3909.21	24.7072
3912.13	40.621
3915.05	41.0311
3917.97	23.4725
3920.89	6.62988
3923.81	41.4702
3926.73	45.4755
3929.64	47.464
3932.56	27.7245
3935.47	4.41248
3938.38	45.5199
3941.3	3.18738
3944.21	29.8536
3947.12	33.6652
3950.02	17.4614
3952.93	19.4913
3955.84	37.9194
3958.74	39.1648
3961.64	36.6309
3964.55	25.532
3967.45	33.6711
3970.35	42.8156
3973.25	60.5861
3976.14	36.9802
3979.04	19.0322
3981.94	42.3915
3984.83	18.5773
3987.72	35.1298
3990.62	50.5317
3993.51	8.46094
3996.4	46.2172
3999.29	65.7678