File: Data/3-Raman/processed/bu19(2)w-a-ff2b-fi03-v_1800 (450-850nm)_532nm_edge_100%_x100_vis_lwd_h100um_30sx2_01.txt
#Acq. time (s)=	30
#Accumulations=	2
#Range (cm-¹)=	1200...2365
#Windows=	3
#Auto scanning=	Off
#Autofocus=	Off
#Macrospot=	Off
#AutoExposure=	Off
#Spike filter=	Multiple accum.
#Delay time (s)=	2
#Binning=	1
#Readout mode=	Signal
#DeNoise=	Off
#ICS correction=	On
#Dark correction=	Off
#Inst. Process=	Off
#Detector Gain=	Best Dynamic
#Detector ADC=	50 kHz HS
#Detector temperature (°C)=	-60.09
#Instrument=	LabRAM HR Evol
#Detector=	SIN-EM FIVIS
#Objective=	x50_VIS_LWD
#Grating=	1800 (450-850nm)
#ND Filter=	100%
#Laser=	532nm_Edge
#Hole=	100.021
#Temperature=	0
#Range=	Visible
#StageXY=	75x50mm Scan+
#StageZ=	Z motor
#X (µm)=	0
#Y (µm)=	0
#Z (µm)=	-10.1
#Full time(mm:ss)=	3:23
#Project=	21_11_26
#Sample=	BU19(2)w
#Site=
#Title=	BU19(2)w-A-FF2b-FI03-V_1800 (450-850nm)_532nm_Edge_100%_x50_VIS_LWD_H100um_30sX2
#Remark=
#Date=	26.11.2021 14:57
#Acquired=	26.11.2021 14:57:04
#Base:Fit=	16.12.2021 16:00:56
#Base:Fit=	16.12.2021 16:09:50
#Base:Sub=	16.12.2021 16:09:51
1202.72	5.92043
1203.84	13.2561
1204.95	1.09203
1206.06	4.96445
1207.17	5.54158
1208.28	6.16368
1209.39	-2.86467
1210.5	2.03345
1211.61	3.60664
1212.72	0.900398
1213.83	-1.78799
1214.94	-3.36906
1216.05	-11.3658
1217.16	0.739021
1218.27	5.38647
1219.38	7.92356
1220.49	-0.152115
1221.6	-7.17337
1222.71	-4.73975
1223.81	-0.254944
1224.92	-3.1366
1226.03	4.61278
1227.14	0.712791
1228.25	-1.2418
1229.35	2.04359
1230.46	-7.99421
1231.57	-0.545876
1232.67	0.769821
1233.78	-2.14519
1234.89	-3.9801
1235.99	-2.67025
1237.1	3.83711
1238.2	8.14445
1239.31	8.24467
1240.41	3.16117
1241.52	3.34452
1242.62	1.38735
1243.73	-2.62457
1244.83	6.95882
1245.94	8.07636
1247.04	7.12069
1248.14	6.18326
1249.25	3.12385
1250.35	8.46664
1251.45	6.41509
1252.56	14.817
1253.66	15.9
1254.76	13.9538
1255.87	8.83454
1256.97	28.7816
1258.07	21.5288
1259.17	20.5151
1260.27	27.9577
1261.37	52.958
1262.48	75.2478
1263.58	79.0974
1264.68	49.2973
1265.78	30.4319
1266.88	17.9509
1267.98	25.4152
1269.08	20.3585
1270.18	19.3651
1271.28	20.3816
1272.38	23.5825
1273.47	19.5516
1274.57	20.7357
1275.67	20.7961
1276.77	18.8144
1277.87	29.4428
1278.97	62.1834
1280.07	106.436
1281.16	293.725
1282.26	1044.53
1283.36	1290.28
1284.45	413.554
1285.55	124.818
1286.65	59.5584
1287.75	43.7713
1288.84	33.2736
1289.94	20.754
1291.03	21.8896
1292.13	21.9387
1293.22	19.8882
1294.32	22.1666
1295.42	13.8147
1296.51	12.9954
1297.61	4.59754
1298.7	18.3553
1299.79	9.93594
1300.89	2.64121
1301.98	12.2305
1303.08	9.15967
1304.17	2.87385
1305.26	5.05937
1306.35	4.02531
1307.45	-3.286
1308.54	6.29893
1309.63	-4.14049
1310.73	-2.98371
1311.82	9.78513
1312.91	-0.64151
1314	0.491684
1315.09	3.76559
1316.18	4.96082
1317.28	0.829842
1318.37	7.29671
1319.46	2.12767
1320.55	1.18401
1321.64	4.41882
1322.73	0.252892
1323.82	1.4026
1324.91	-5.85394
1326	-1.55505
1327.09	1.62199
1328.18	2.91703
1329.27	7.34827
1330.35	3.25085
1331.44	3.32775
1332.53	1.26142
1333.62	-0.789112
1334.71	6.62999
1335.79	-1.67907
1336.88	1.57231
1337.97	-0.403519
1339.06	0.742748
1340.14	-4.34546
1341.23	3.14237
1342.32	4.31797
1343.4	3.36929
1344.49	-1.70855
1345.58	3.64906
1346.66	0.586071
1347.75	-5.58265
1348.83	3.93499
1349.92	11.3442
1351	-1.03253
1352.09	6.37056
1353.17	5.54326
1354.25	2.65786
1355.34	10.9965
1356.42	5.96868
1357.51	-2.19583
1358.59	4.1719
1359.67	13.6395
1360.76	6.49615
1361.84	3.54903
1362.92	11.9907
1364	16.341
1365.09	16.5215
1366.17	8.36341
1367.25	12.611
1368.33	35.5359
1369.41	52.2923
1370.5	19.3745
1371.58	20.5314
1372.66	19.5763
1373.74	21.7753
1374.82	26.063
1375.9	25.2224
1376.98	32.5856
1378.06	27.6
1379.14	37.2097
1380.22	45.5999
1381.3	54.8399
1382.38	69.3007
1383.46	112.401
1384.54	228.353
1385.61	803.493
1386.69	3149.17
1387.77	1090.18
1388.85	234.142
1389.93	106.566
1391	75.7582
1392.08	46.138
1393.16	38.0659
1394.23	34.1332
1395.31	31.2544
1396.39	40.6894
1397.46	26.5134
1398.54	21.5773
1399.62	26.9205
1400.69	30.2136
1401.77	30.4466
1402.84	25.6382
1403.92	34.1181
1404.99	45.5361
1406.07	63.0956
1407.14	98.104
1408.22	156.78
1409.29	110.881
1410.37	52.6368
1411.44	30.1771
1412.51	23.1786
1413.59	22.5416
1414.66	16.4855
1415.73	8.48909
1416.81	6.63942
1417.88	14.0431
1418.95	7.04502
1420.02	4.13197
1421.1	13.5115
1422.17	2.40284
1423.24	12.9789
1424.31	9.87874
1425.38	8.00829
1426.45	6.14944
1427.52	5.24666
1428.59	7.41884
1429.67	4.53621
1430.74	3.72892
1431.81	0.887009
1432.87	2.05619
1433.95	6.24945
1435.01	8.48485
1436.08	-0.570839
1437.15	-1.4443
1438.22	6.9006
1439.29	5.03281
1440.36	0.105545
1441.43	5.40565
1442.49	1.45689
1443.56	2.63695
1444.63	2.78284
1445.7	5.02695
1446.77	5.16351
1447.83	6.32167
1448.9	0.333858
1449.97	0.475479
1451.03	6.75075
1452.1	-2.34323
1453.17	4.97089
1454.23	8.19577
1455.3	6.28387
1456.36	-0.739269
1457.43	-2.668
1458.49	3.60807
1459.56	2.72677
1460.62	-3.29312
1461.69	0.917053
1462.75	-1.02975
1463.82	4.17365
1464.88	1.28217
1465.94	1.27891
1467.01	-2.69226
1468.07	-5.63676
1469.13	6.71863
1470.2	-3.38712
1471.26	-1.25188
1472.32	-2.17604
1473.39	-1.05023
1474.45	-2.99253
1475.51	0.178703
1476.57	3.32607
1477.63	2.39505
1478.69	5.53522
1479.76	-2.51826
1480.82	-0.426697
1481.88	-3.38359
1482.94	0.804207
1484	-3.15124
1485.06	0.921463
1486.12	-3.0479
1487.18	4.14289
1488.24	0.161171
1489.3	4.26666
1490.36	-1.72631
1491.42	1.37401
1492.48	0.444862
1493.53	-2.50851
1494.59	1.61696
1495.65	-1.35023
1496.71	0.711334
1497.77	3.80629
1498.82	3.88089
1499.88	-6.12841
1500.94	-2.01363
1502	-0.946934
1503.05	-0.890579
1504.11	-3.86527
1505.17	3.26517
1506.22	0.271244
1507.28	6.38552
1508.34	7.45719
1509.39	3.48969
1510.45	4.56506
1511.5	4.58572
1512.56	0.539684
1513.61	-3.46252
1514.67	0.633453
1515.72	1.6573
1516.78	-0.332199
1517.83	2.72112
1518.88	0.78091
1519.94	-5.17924
1520.99	2.88951
1522.05	1.94009
1523.1	-6.05567
1524.15	3.97016
1525.2	1.99176
1526.26	0.0461769
1527.31	-4.90529
1528.36	2.13527
1529.41	2.15828
1530.47	1.182
1531.52	1.24309
1532.57	1.27156
1533.62	-0.659679
1534.67	1.38451
1535.72	3.40268
1536.77	4.37743
1537.82	-1.64019
1538.87	1.36458
1539.92	-0.552956
1540.97	2.54203
1542.02	-0.464619
1543.07	8.533
1544.12	-2.49683
1545.17	-1.45261
1546.22	-1.39679
1547.27	2.63831
1548.32	2.63688
1549.37	3.63264
1550.42	1.66202
1551.46	4.80463
1552.51	1.80946
1553.56	4.80524
1554.61	-2.22984
1555.65	6.76759
1556.7	0.766342
1557.75	2.78735
1558.79	0.763783
1559.84	0.730652
1560.89	2.71948
1561.93	-2.26247
1562.98	-4.23608
1564.02	-4.23526
1565.07	3.8033
1566.11	3.56255
1567.16	-4.25332
1568.2	1.77458
1569.25	0.787907
1570.29	3.77047
1571.34	-4.22275
1572.38	5.75324
1573.43	1.73543
1574.47	-4.25677
1575.51	-6.22259
1576.56	-1.22176
1577.6	1.72974
1578.64	-1.30708
1579.69	0.682858
1580.73	0.692142
1581.77	-0.323986
1582.81	-1.34373
1583.85	-6.33406
1584.9	3.62479
1585.94	-0.365414
1586.98	1.59283
1588.02	3.56328
1589.06	-1.40381
1590.1	-2.39123
1591.14	-5.37464
1592.18	-1.40449
1593.22	1.54012
1594.26	4.45776
1595.3	4.45858
1596.34	0.464241
1597.38	4.43447
1598.42	2.44228
1599.46	-2.56326
1600.5	-1.60302
1601.54	3.30381
1602.58	2.26488
1603.62	-1.73399
1604.66	1.21561
1605.69	2.19929
1606.73	5.17623
1607.77	2.188
1608.81	2.12577
1609.84	1.89928
1610.88	-0.239368
1611.92	-1.19221
1612.95	-1.30591
1613.99	-0.281437
1615.03	-2.88377
1616.06	-0.164501
1617.1	0.149483
1618.13	0.589279
1619.17	1.5023
1620.2	1.6747
1621.24	2.01626
1622.27	1.16317
1623.31	2.35054
1624.34	1.52253
1625.38	2.12345
1626.41	1.27621
1627.45	2.29819
1628.48	-0.582088
1629.51	-2.12111
1630.55	0.7411
1631.53	6.0706
1632.57	1.15335
1633.62	-3.78483
1634.66	-3.78576
1635.71	-0.839481
1636.75	-0.861305
1637.8	0.0970802
1638.84	4.01668
1639.89	-0.912453
1640.93	0.0702858
1641.98	-2.89055
1643.02	3.00209
1644.06	3.97345
1645.11	-2.93579
1646.15	-1.94904
1647.19	-3.93514
1648.24	-1.00072
1649.28	2.96019
1650.32	6.89061
1651.37	0.025528
1652.41	1.01209
1653.45	-4.91262
1654.49	-3.92606
1655.53	1.01167
1656.57	2.03033
1657.62	3.0138
1658.66	-0.950134
1659.7	0.999126
1660.74	-0.981884
1661.78	4.95863
1662.82	3.02366
1663.86	-3.8909
1664.9	-0.951515
1665.94	-1.98283
1666.98	-3.91943
1668.02	0.00949097
1669.06	-0.972542
1670.1	-1.93801
1671.14	1.04993
1672.18	2.03094
1673.21	-1.92002
1674.25	1.05336
1675.29	-2.88443
1676.33	2.07085
1677.37	0.095047
1678.4	-0.910141
1679.44	1.04614
1680.48	-3.907
1681.52	-3.91613
1682.55	-3.91551
1683.59	0.0356178
1684.63	2.992
1685.66	-0.962727
1686.7	-1.9446
1687.73	-4.89768
1688.77	1.01706
1689.81	-0.977749
1690.84	4.93604
1691.88	0.0197487
1692.91	0.0196838
1693.95	-2.96679
1694.98	0.954548
1696.01	-1.99125
1697.05	-0.991947
1698.08	3.91051
1699.12	-2.01425
1700.15	0.941971
1701.18	-2.01261
1702.22	-0.056282
1703.25	-0.0709496
1704.28	2.87417
1705.32	-1.0424
1706.35	-1.0429
1707.38	-3.02963
1708.41	2.82586
1709.44	-0.14904
1710.48	-0.148811
1711.51	-1.10865
1712.54	-0.119236
1713.57	-4.07316
1714.6	1.76562
1715.63	2.75098
1716.66	-1.14838
1717.69	4.67337
1718.72	6.56792
1719.75	4.61477
1720.78	1.70173
1721.81	2.65373
1722.84	3.59973
1723.87	2.61124
1724.9	2.61013
1725.93	1.60112
1726.96	5.4748
1727.99	3.53649
1729.02	0.573555
1730.05	5.37939
1731.07	2.47176
1732.1	3.49171
1733.13	4.45365
1734.16	2.48544
1735.18	-5.25637
1736.21	4.35437
1737.24	4.34865
1738.26	0.49221
1739.29	5.27858
1740.32	-0.524078
1741.34	5.1991
1742.37	6.1421
1743.4	3.27082
1744.42	4.22154
1745.45	1.35674
1746.47	7.09315
1747.5	2.28692
1748.52	4.18742
1749.55	6.1185
1750.57	-0.525711
1751.6	4.28139
1752.62	-2.42683
1753.64	6.14876
1754.67	5.1779
1755.69	5.17049
1756.71	5.14946
1757.74	4.1712
1758.76	-0.561115
1759.78	8.97153
1760.81	5.16778
1761.83	8.95906
1762.85	10.8707
1763.87	6.13519
1764.89	9.98423
1765.92	3.35273
1766.94	4.3152
1767.96	4.317
1768.98	10.9733
1770	4.25974
1771.02	9.0429
1772.04	10.0416
1773.06	11.031
1774.08	11.0633
1775.1	9.1862
1776.12	10.1931
1777.14	11.159
1778.16	10.1912
1779.18	7.31245
1780.2	3.51165
1781.22	5.44014
1782.24	3.55925
1783.26	5.50168
1784.28	3.62682
1785.29	2.70942
1786.31	5.57385
1787.33	4.64976
1788.35	7.60105
1789.37	7.67204
1790.38	5.8026
1791.4	0.0586967
1792.42	9.62141
1793.43	4.85598
1794.45	2.00033
1795.47	1.08292
1796.48	4.01206
1797.5	2.12941
1798.51	7.92633
1799.53	1.20314
1800.55	3.1122
1801.56	0.23019
1802.58	5.05025
1803.59	3.1641
1804.61	2.22797
1805.62	1.30412
1806.64	0.376812
1807.65	2.32237
1808.66	-1.5221
1809.68	1.38313
1810.69	0.432003
1811.7	2.36412
1812.72	2.37778
1813.73	4.33358
1814.74	1.47802
1815.76	4.41087
1816.77	3.4599
1817.78	1.51377
1818.79	-0.406124
1819.8	6.37631
1820.82	-1.33528
1821.83	6.42702
1822.84	2.57787
1823.85	-0.319902
1824.86	2.59146
1825.87	4.54683
1826.88	-1.25631
1827.89	1.66441
1828.9	2.63717
1829.91	-3.17977
1830.92	0.68589
1831.93	3.60859
1832.94	0.726839
1833.95	4.61757
1834.96	1.6906
1835.97	6.47921
1836.98	3.71177
1837.99	4.57025
1839	-1.23617
1840	2.68525
1841.01	5.5214
1842.02	3.5243
1843.03	2.53113
1844.04	-0.360987
1845.04	-1.32311
1846.05	3.51208
1847.06	2.58207
1848.07	-0.423174
1849.07	2.4719
1850.08	2.446
1851.09	0.48229
1852.09	0.461102
1853.1	4.29994
1854.1	-4.35363
1855.11	3.28777
1856.11	-0.578634
1857.12	1.33123
1858.12	1.31752
1859.13	-1.58124
1860.13	2.21985
1861.14	0.319782
1862.14	-0.621574
1863.15	-0.644361
1864.15	-0.674379
1865.15	0.254389
1866.16	-0.743074
1867.16	-1.75075
1868.16	3.91283
1869.17	2.95459
1870.17	-0.857641
1871.17	-1.81714
1872.17	1.01766
1873.18	0.0438232
1874.18	0.975552
1875.18	0.940672
1876.18	0.88759
1877.18	1.79361
1878.18	0.795534
1879.19	-0.101553
1880.19	-3.86896
1881.19	0.855778
1882.19	0.801884
1883.19	4.50063
1884.19	0.685862
1885.19	0.696365
1886.19	-1.15643
1887.19	-0.223078
1888.19	1.62578
1889.19	2.51544
1890.19	2.48895
1891.19	-0.322411
1892.18	0.605165
1893.18	0.583256
1894.18	4.28526
1895.18	2.38198
1896.18	-0.433905
1897.18	-5.12294
1898.17	-1.36119
1899.17	-0.447113
1900.17	5.15996
1901.16	0.453196
1902.16	0.470007
1903.16	-1.40736
1904.16	4.21386
1905.15	-0.501488
1906.15	3.23618
1907.14	0.385092
1908.14	0.38026
1909.14	2.26467
1910.13	1.34657
1911.13	1.37825
1912.12	-0.505215
1913.12	1.36399
1914.11	0.428436
1915.11	4.2239
1916.1	3.28461
1917.1	1.37131
1918.09	3.23082
1919.08	-0.528822
1920.08	0.450521
1921.07	2.33682
1922.06	4.24674
1923.06	0.449709
1924.05	-1.46397
1925.04	-0.543884
1926.04	7.03147
1927.03	1.38733
1928.02	-0.495409
1929.01	0.455957
1930	3.31822
1931	2.39749
1931.99	1.43499
1932.98	-3.33765
1933.97	-0.495604
1934.96	0.538464
1935.95	-0.352896
1936.94	1.51277
1937.93	4.33005
1938.92	-0.441412
1939.91	0.520008
1940.9	3.39342
1941.89	2.46281
1942.88	-0.395145
1943.87	3.39339
1944.86	-6.13769
1945.85	0.568741
1946.84	-2.28708
1947.83	1.52447
1948.82	-0.400723
1949.8	0.568047
1950.79	0.605728
1951.78	-3.1902
1952.77	0.667051
1953.76	-1.25836
1954.74	0.58453
1955.73	0.559345
1956.72	-1.31186
1957.7	2.55244
1958.69	1.60155
1959.68	4.46554
1960.66	1.55841
1961.65	-0.391901
1962.63	1.52138
1963.62	3.43986
1964.61	2.48431
1965.59	1.51349
1966.58	4.40755
1967.56	-1.34822
1968.55	4.41951
1969.53	2.47187
1970.52	0.507605
1971.5	2.40111
1972.48	2.39536
1973.47	4.30077
1974.45	6.18954
1975.44	7.14655
1976.42	0.448593
1977.4	6.20189
1978.39	9.05439
1979.37	5.20336
1980.35	9.03729
1981.33	5.17906
1982.31	8.03522
1983.3	11.8362
1984.28	12.7592
1985.26	9.86726
1986.24	7.9393
1987.22	10.8197
1988.21	13.6525
1989.19	14.4467
1990.17	8.89484
1991.15	14.5976
1992.13	15.7058
1993.11	13.8052
1994.09	8.42457
1995.07	12.8356
1996.05	13.7491
1997.03	17.2279
1998.01	14.507
1998.99	17.4879
1999.97	13.0255
2000.95	19.706
2001.92	19.3955
2002.9	18.6696
2003.88	17.3925
2004.86	17.0798
2005.84	16.9852
2006.81	15.2812
2007.79	18.1364
2008.77	19.7157
2009.75	18.2723
2010.73	15.553
2011.7	14.998
2012.68	20.2363
2013.67	12.6636
2014.66	17.2978
2015.64	23.858
2016.63	11.6847
2017.62	16.422
2018.61	13.5542
2019.6	13.4991
2020.58	8.80813
2021.57	14.4408
2022.56	16.313
2023.55	16.2814
2024.54	15.319
2025.52	15.2709
2026.51	11.5153
2027.5	12.5746
2028.48	10.6699
2029.47	11.6848
2030.45	9.70492
2031.44	10.6705
2032.43	12.5591
2033.41	7.02187
2034.4	6.10699
2035.38	7.93307
2036.37	6.16073
2037.35	8.03608
2038.34	7.10673
2039.32	7.09996
2040.31	7.08487
2041.29	11.7275
2042.27	6.13324
2043.26	7.06735
2044.24	3.39784
2045.23	8.98979
2046.21	3.48392
2047.19	8.13819
2048.17	7.17623
2049.16	10.0024
2050.14	2.59905
2051.12	-0.159035
2052.11	5.4461
2053.09	5.47826
2054.07	6.47269
2055.05	1.82833
2056.03	2.769
2057.01	-0.0244503
2058	4.67891
2058.98	6.59896
2059.96	-0.851023
2060.94	3.83964
2061.92	-3.61428
2062.9	2.03323
2063.88	2.0758
2064.86	5.86127
2065.84	1.22671
2066.82	-3.42591
2067.8	1.30649
2068.78	-0.535101
2069.76	-2.39846
2070.73	4.20037
2071.71	2.36627
2072.69	-1.33074
2073.67	2.45475
2074.65	2.48751
2075.63	1.60947
2076.6	0.724838
2077.58	-3.03916
2078.56	-1.13345
2079.54	0.795658
2080.51	-0.0930882
2081.49	1.82159
2082.47	-1.93189
2083.45	3.76795
2084.42	-1.87772
2085.4	0.984852
2086.37	4.80264
2087.35	-0.820877
2088.32	0.160334
2089.3	0.192245
2090.28	1.18656
2091.25	1.22353
2092.23	-0.622719
2093.2	2.28904
2094.18	0.445446
2095.15	3.33074
2096.13	-1.41098
2097.1	3.35878
2098.07	1.46774
2099.05	0.538734
2100.02	2.46003
2101	0.595518
2101.97	-0.308044
2102.94	2.5668
2103.92	-1.21832
2104.89	0.714008
2105.86	1.7124
2106.83	-2.04831
2107.8	2.73462
2108.78	3.6811
2109.75	-1.98934
2110.72	-1.95571
2111.69	1.86977
2112.66	-0.0108414
2113.63	0.033186
2114.61	0.0654583
2115.58	0.0931683
2116.55	1.05812
2117.52	-2.72359
2118.49	3.93893
2119.46	-0.806931
2120.43	-0.799757
2121.4	-0.765728
2122.37	1.18383
2123.34	-0.66993
2124.31	-2.54283
2125.28	3.13903
2126.25	-4.45012
2127.21	-0.660994
2128.18	1.24567
2129.15	0.322653
2130.12	0.342869
2131.09	-0.583208
2132.06	-1.51637
2133.02	-3.39285
2133.99	0.407511
2134.96	-3.33952
2135.93	-0.487818
2136.89	3.28374
2137.86	-0.455301
2138.83	-0.439302
2139.79	-1.34994
2140.76	1.47968
2141.73	1.49761
2142.69	-1.31609
2143.66	2.49734
2144.62	0.582607
2145.59	3.42944
2146.55	1.56821
2147.52	2.52054
2148.48	-0.287466
2149.45	2.53606
2150.42	0.64996
2151.38	-0.270571
2152.34	-0.233814
2153.31	0.717934
2154.27	1.6636
2155.24	1.64558
2156.2	-3.0425
2157.16	1.64169
2158.13	0.740911
2159.09	0.767143
2160.05	-2.96384
2161.01	0.768684
2161.98	4.5119
2162.94	-0.133257
2163.9	-1.05661
2164.86	3.60486
2165.83	-0.102425
2166.79	3.63898
2167.75	-1.01839
2168.71	0.82468
2169.67	-3.79576
2170.63	-0.0231037
2171.59	4.64351
2172.56	3.68033
2173.51	0.900736
2174.48	1.85612
2175.44	-1.84249
2176.4	-0.900993
2177.36	-1.82021
2178.32	1.91447
2179.28	-1.79921
2180.23	1.93321
2181.19	1.01664
2182.15	-4.54444
2183.11	0.101912
2184.07	1.94668
2185.03	-0.826595
2185.99	2.90612
2186.95	-0.765688
2187.9	-1.65114
2188.86	0.20973
2189.82	2.97786
2190.78	1.1253
2191.73	-1.63622
2192.69	1.16858
2193.65	2.12661
2194.6	2.18165
2195.56	-4.31423
2196.52	-0.609774
2197.47	0.306347
2198.43	-2.46459
2199.38	-1.49677
2200.34	7.85163
2201.3	-0.463566
2202.25	1.31938
2203.21	2.30836
2204.16	4.28972
2205.12	-1.34699
2206.07	6.97111
2207.03	0.471098
2207.98	0.497288
2208.93	2.39093
2209.89	3.34102
2210.84	1.49557
2211.8	-0.341682
2212.75	1.55011
2213.7	0.614733
2214.66	2.50246
2215.61	-4.00544
2216.56	0.672499
2217.51	-3.05668
2218.47	-0.246183
2219.42	4.44414
2220.37	-3.009
2221.32	-0.202955
2222.27	-3.02016
2223.23	-0.210533
2224.18	-2.05042
2225.13	-2.0179
2226.08	0.821745
2227.03	0.849947
2227.98	-0.0665779
2228.93	-1.94153
2229.88	3.69208
2230.83	-1.90637
2231.78	0.939447
2232.73	1.907
2233.68	1.93369
2234.63	-0.873203
2235.58	2.87642
2236.53	1.93786
2237.48	-2.74981
2238.43	2.94144
2239.38	0.152004
2240.33	-0.796734
2241.27	-0.779991
2242.22	0.176044
2243.17	3.96676
2244.12	3.96033
2245.07	-0.741455
2246.01	-3.54167
2246.96	0.263056
2247.91	0.280317
2248.85	1.22708
2249.8	0.286774
2250.75	1.23298
2251.69	2.16298
2252.64	-0.66168
2253.59	-3.46106
2254.53	-2.48702
2255.48	-2.47896
2256.42	-3.41572
2257.37	2.30024
2258.32	3.26946
2259.26	-2.41417
2260.2	3.30475
2261.15	-5.23372
2262.1	2.3976
2263.04	-1.38946
2263.98	1.50445
2264.93	0.595108
2265.87	-0.336042
2266.81	-0.341921
2267.76	-3.2172
2268.7	2.49672
2269.65	-0.340145
2270.59	1.60959
2271.53	0.680557
2272.47	-0.253687
2273.42	-2.15514
2274.36	-0.228241
2275.3	-0.214567
2276.24	1.71473
2277.18	0.789558
2278.13	1.7929
2279.07	-1.06156
2280.01	1.80836
2280.95	-0.127787
2281.89	-0.130751
2282.83	-2.98504
2283.77	-0.0694332
2284.71	0.943556
2285.65	-1.91648
2286.59	0.964529
2287.54	2.92965
2288.47	-0.900419
2289.41	2.9409
2290.35	0.0306091
2291.29	1.00452
2292.23	-0.88306
2293.17	3.00162
2294.11	1.09926
2295.05	3.98608
2295.99	2.0551
2296.93	1.08181
2297.86	1.11037
2298.8	0.184669
2299.74	0.218355
2300.68	3.12574
2301.61	3.15297
2302.55	-2.62686
2303.49	1.2426
2304.43	2.22741
2305.36	1.29049
2306.3	-4.48549
2307.24	1.32965
2308.17	4.232
2309.11	0.375685
2310.04	1.37786
2310.98	-1.50373
2311.92	-0.562967
2312.85	2.32094
2313.79	0.409948
2314.72	-0.511597
2315.66	-1.45169
2316.59	4.32547
2317.52	1.42821
2318.46	2.40955
2319.39	0.472696
2320.33	0.474905
2321.26	0.492193
2322.2	3.4226
2323.13	5.38393
2324.06	5.40109
2325	9.26765
2325.93	21.7916
2326.86	67.1079
2327.79	189.478
2328.73	47.7514
2329.66	19.7774
2330.59	11.1113
2331.52	2.44392
2332.46	2.45637
2333.39	0.517691
2334.32	0.508722
2335.25	3.37858
2336.18	1.45716
2337.11	-1.43334
2338.04	-1.43884
2338.97	0.477453
2339.91	2.39812
2340.84	1.41891
2341.77	-1.49639
2342.7	1.35527
2343.63	-0.573925
2344.56	4.21057
2345.49	1.32047
2346.41	2.24572
2347.34	1.26805
2348.27	4.12568
2349.2	4.11264
2350.13	-0.730682
2351.06	1.98794
2351.99	3.98674
2352.91	-1.80519
2353.84	4.80341
2354.77	-0.939262
2355.7	-0.967834
2356.63	-1.0174
2357.55	-0.131203
2358.48	-2.08332
2359.41	0.715925
2360.33	-2.1896
2361.26	-3.20509
2362.19	-1.38047
2363.11	1.3848
2364.04	-5.30766
2364.97	1.24297