File: Data/3-Raman/processed/bu19w-a-ff07b-fi04-s_150 (500nm)_532nm_edge_100%_x100_vis_lwd_h50um_15sx2_01_0.txt
#Acq. time (s)=	15
#Accumulations=	2
#Range (cm-¹)=	50...5000
#Windows=	1
#Auto scanning=	Off
#Autofocus=	Off
#Macrospot=	Off
#AutoExposure=	Off
#Spike filter=	Multiple accum.
#Delay time (s)=	2
#Binning=	1
#Readout mode=	Signal
#DeNoise=	Off
#ICS correction=	On
#Dark correction=	Off
#Inst. Process=	Off
#Detector Gain=	Best Dynamic
#Detector ADC=	50 kHz HS
#Detector temperature (°C)=	-60.09
#Instrument=	LabRAM HR Evol
#Detector=	SIN-EM FIVIS
#Objective=	x100_VIS_LWD
#Grating=	150 (500nm)
#ND Filter=	100%
#Laser=	532nm_Edge
#Hole=	49.98
#Temperature=	0
#Range=	Visible
#StageXY=	75x50mm Scan+
#StageZ=	Z motor
#X (µm)=	0
#Y (µm)=	0
#Z (µm)=	-40
#Full time(s)=	34
#Project=	21_05_28
#Sample=	BU19w
#Site=
#Title=	BU19w-FF07b-FI04-S_150 (500nm)_532nm_Edge_100%_x100_VIS_LWD_H50um_15sX2
#Remark=
#Date=	28.05.2021 16:13
#Acquired=	28.05.2021 16:13:37
#Base:Fit=	16.12.2021 17:39:50
#Base:Edit=	16.12.2021 17:59:07
#Base:Sub=	16.12.2021 17:59:10
51.5961	3987.57
56.2453	3192.84
60.8921	2577.26
65.5367	5385.77
70.1768	8543.93
74.8167	3879.02
79.4543	1177.47
84.0897	671.396
88.7227	467.402
93.3513	275.323
97.9798	227.283
102.606	169.064
107.23	134.413
111.851	236.96
116.469	197.206
121.086	165.635
125.7	114.194
130.313	432.772
134.921	914.829
139.529	442.754
144.134	203.162
148.738	57.2413
153.337	-0.0847168
157.936	172.175
162.532	874.794
167.126	2351.66
171.716	2272.87
176.306	909.908
180.894	448.085
185.477	501.294
190.06	1474.25
194.64	4926.58
199.219	4847.25
203.793	1613.9
208.367	450.014
212.939	105.553
217.506	66.6711
222.073	226.914
226.638	194.727
231.199	87.3623
235.759	93.3556
240.318	453.016
244.872	604.216
249.425	862.068
253.977	1720.67
258.524	1571.26
263.071	1122.95
267.616	1169.62
272.156	2215.9
276.697	2385.11
281.233	2945.04
285.769	5993.99
290.303	8036.72
294.832	7109.39
299.361	4056.93
303.886	2627.1
308.411	3250.21
312.934	3301.37
317.452	2195.56
321.97	1295.17
326.484	844.123
330.998	1037.68
335.507	1646.59
340.017	1942.1
344.524	1152.24
349.027	705.003
353.53	999.887
358.028	1455.29
362.527	1292.54
367.021	707.234
371.515	457.274
376.004	599.871
380.494	670.574
384.979	561.178
389.465	616.5
393.946	935.472
398.427	1141.64
402.903	1301.4
407.38	1118.81
411.852	765.33
416.324	579.559
420.792	931.367
425.26	1543.26
429.723	896.622
434.187	248.18
438.646	110.033
443.105	80.4099
447.56	53.8002
452.015	162.775
456.466	398.437
460.914	1143.92
465.362	1755.57
469.807	1292.93
474.251	1116.34
478.69	1390.56
483.13	1359.54
487.566	1313.61
491.999	1326.82
496.432	1329.21
500.861	1223.28
505.29	1110.72
509.715	904.197
514.138	653.756
518.56	372.159
522.979	296.789
527.395	249.419
531.811	207.997
536.223	210.697
540.635	264.331
545.042	264.557
549.448	297.247
553.853	325.056
558.255	371.688
562.654	348.556
567.053	368.537
571.448	375.163
575.841	283.303
580.232	235.48
584.622	334.413
589.009	710.272
593.393	1872.35
597.777	3190.72
602.157	2465.13
606.535	1159.45
610.913	896.374
615.287	1176.75
619.659	1841.29
624.029	2028.3
628.398	1372.37
632.763	906.304
637.127	1347.68
641.488	2425.93
645.849	2212.77
650.206	1162.74
654.561	585.39
658.914	391.581
663.267	387.176
667.615	560.23
671.962	734.278
676.307	773.7
680.649	877.938
684.991	1025.86
689.33	924.799
693.666	516.777
698	237.555
702.332	139.041
706.662	57.0919
710.992	35.1482
715.318	13.8755
719.641	-32.0984
723.963	-19.0013
728.283	-15.2419
732.6	-8.63184
736.918	30.5991
741.231	11.2015
745.542	33.4801
749.852	15.5148
754.159	73.9377
758.464	125.887
762.767	221.246
767.068	287.281
771.369	437.615
775.666	788.309
779.961	1408.01
784.254	2249.09
788.545	2875.55
792.834	2660.77
797.12	2025.7
801.405	1336.77
805.688	845.447
809.968	539.815
814.247	355.393
818.524	186.526
822.798	150.684
827.071	82.1125
831.341	44.3995
835.612	90.4181
839.878	30.5177
844.142	-0.893555
848.405	42.3087
852.665	24.1776
856.923	12.6733
861.18	58.4326
865.434	110.522
869.686	150.029
873.936	221.019
878.185	144.529
882.431	87.7146
886.675	63.4014
890.915	51.6077
895.155	61.1608
899.393	31.4407
903.63	49.679
907.864	14.3158
912.096	14.5474
916.326	20.8268
920.554	-4.44958
924.78	35.6769
929.004	28.8054
933.227	41.5229
937.447	71.2528
941.665	95.223
945.881	153.172
950.095	251.439
954.305	346.551
958.516	460.714
962.724	480.177
966.93	434.982
971.134	564.069
975.337	689.028
979.537	703.854
983.735	621.577
987.93	667.422
992.124	812.87
996.316	1223.3
1000.51	2008.78
1004.7	3265.66
1008.88	4222.61
1013.06	3243.74
1017.25	1910.76
1021.43	1227.35
1025.61	963.649
1029.78	1083.31
1033.96	1517.46
1038.13	2494.09
1042.3	3433.31
1046.47	3276.57
1050.63	3601.17
1054.8	5066.14
1058.96	5615.39
1063.12	4413.18
1067.28	2837.51
1071.44	1754.13
1075.59	1169.46
1079.74	983.197
1083.89	1019.7
1088.04	1305.48
1092.19	2047.78
1096.33	3139.46
1100.48	3981.85
1104.62	4042.91
1108.76	3410.19
1112.89	2798.99
1117.03	2813.84
1121.16	2639.51
1125.29	2261.52
1129.42	2004.29
1133.55	2078.81
1137.68	2286.04
1141.8	2304.7
1145.92	1960.81
1150.04	1397.44
1154.16	1146.94
1158.27	1236.77
1162.39	1649.18
1166.5	2011.23
1170.61	1795.6
1174.72	1328.71
1178.82	1136.12
1182.93	1118.73
1187.03	988.667
1191.13	763.45
1195.23	611.245
1199.33	508.2
1203.42	438.88
1207.51	423.637
1211.6	368.024
1215.69	291.574
1219.78	294.233
1223.86	307.12
1227.95	472.651
1232.03	594.044
1236.11	475.426
1240.18	464.781
1244.26	628.568
1248.33	846.747
1252.41	777.374
1256.48	511.579
1260.54	298.737
1264.61	196.834
1268.67	176.104
1272.74	166.545
1276.8	122.841
1280.86	114.154
1284.91	85.1381
1288.97	66.9399
1293.02	67.7063
1297.07	64.2726
1301.12	77.8563
1305.17	82.1565
1309.21	72.2656
1313.25	57.1986
1317.3	57.855
1321.34	40.1453
1325.37	72.3478
1329.41	47.0558
1333.44	43.775
1337.48	26.1063
1341.5	58.3276
1345.53	62.3452
1349.56	35.4165
1353.59	85.2219
1357.61	65.3679
1361.63	39.5385
1365.65	38.7347
1369.66	91.4666
1373.68	178.862
1377.69	205.11
1381.7	213.793
1385.72	143.279
1389.72	90.7626
1393.73	48.4155
1397.73	49.834
1401.74	41.3071
1405.74	6.1283
1409.73	53.8273
1413.73	11.9233
1417.73	-4.35986
1421.72	19.7959
1425.71	-3.58301
1429.7	0.143677
1433.69	39.5054
1437.67	12.6761
1441.66	63.8571
1445.64	47.7207
1449.62	18.692
1453.6	31.9049
1457.57	26.2588
1461.55	45.0437
1465.52	-1.51294
1469.49	28.6315
1473.46	46.0911
1477.43	11.364
1481.39	15.7629
1485.36	21.0465
1489.32	17.4344
1493.28	33.4219
1497.24	44.5096
1501.19	23.552
1505.15	9.62634
1509.1	4.76001
1513.05	-0.0332031
1517	24.3502
1520.95	10.9783
1524.9	19.9868
1528.84	43.6069
1532.78	30.5082
1536.72	38.7545
1540.66	20.858
1544.6	21.3708
1548.53	3.47192
1552.46	61.1284
1556.4	42.1057
1560.32	61.6422
1564.25	98.4436
1568.18	75.1201
1572.1	86.521
1576.02	109.465
1579.94	101.437
1583.86	132.914
1587.78	76.5664
1591.69	104.983
1595.61	124.661
1599.52	94.3315
1603.43	100.621
1607.34	121.464
1611.24	60.7943
1615.15	139.228
1619.05	98.9579
1622.95	115.134
1626.85	96.0565
1630.74	104.886
1634.64	95.8978
1638.53	82.0502
1642.42	101.05
1646.31	81.016
1650.2	99.4147
1654.09	81.4248
1657.97	80.5839
1661.86	100.821
1665.74	73.7461
1669.62	104.2
1673.49	74.6775
1677.37	104.679
1681.24	56.1969
1685.12	64.1182
1688.99	45.0653
1692.86	50.7106
1696.72	30.3411
1700.59	70.9546
1704.45	85.4388
1708.31	91.9955
1712.17	64.0787
1716.03	91.24
1719.89	61.5815
1723.74	49.9911
1727.6	30.8014
1731.45	49.085
1735.3	61.7433
1739.14	62.0331
1742.99	46.2998
1746.83	29.7601
1750.68	67.8636
1754.52	57.0621
1758.36	15.3965
1762.19	69.3062
1766.03	50.0054
1769.86	62.7054
1773.69	47.1536
1777.53	37.1802
1781.35	13.5791
1785.18	52.631
1789	55.4608
1792.83	47.108
1796.65	42.4989
1800.47	66.9525
1804.29	72.8342
1808.1	56.9641
1811.92	31.494
1815.73	62.3724
1819.54	44.6353
1823.35	67.1587
1827.16	16.8112
1830.97	60.4681
1834.77	50.0508
1838.58	63.9218
1842.38	40.8984
1846.18	33.6078
1849.97	67.7419
1853.77	45.9598
1857.56	68.8112
1861.36	56.6688
1865.15	53.7397
1868.93	83.4274
1872.72	47.3221
1876.51	44.8793
1880.29	47.1321
1884.07	24.9785
1887.86	54.4686
1891.63	67.776
1895.41	43.3743
1899.19	34.6139
1902.96	50.2827
1906.73	24.7539
1910.5	51.8191
1914.27	32.3318
1918.04	66.4193
1921.8	52.3661
1925.57	32.8173
1929.33	39.3846
1933.09	62.8223
1936.85	26.6849
1940.6	72.5195
1944.36	49.275
1948.11	61.5477
1951.87	50.3781
1955.61	0.194458
1959.36	-6.49634
1963.11	52.1699
1966.86	20.5977
1970.6	26.2095
1974.34	28.5569
1978.08	29.7128
1981.82	65.2739
1985.56	30.4409
1989.29	72.0638
1993.02	46.2828
1996.75	52.8792
2000.49	42.5048
2004.21	66.48
2007.94	34.77
2011.67	25.9431
2015.39	44.7733
2019.11	45.75
2022.83	68.4435
2026.55	68.9449
2030.27	60.3345
2033.98	49.5825
2037.69	22.7711
2041.41	63.5925
2045.12	47.549
2048.82	57.1669
2052.53	55.1252
2056.24	33.9141
2059.94	43.5698
2063.64	47.5861
2067.34	16.9675
2071.04	33.3333
2074.74	39.6217
2078.43	70.9967
2082.13	29.387
2085.82	59.864
2089.51	6.25378
2093.2	28.2322
2096.88	64.762
2100.57	53.6718
2104.25	41.2173
2107.94	73.1838
2111.62	34.272
2115.3	71.5686
2118.97	49.1989
2122.65	59.7782
2126.32	31.0992
2129.99	51.392
2133.66	52.0778
2137.33	76.7019
2141	27.201
2144.67	50.4447
2148.33	66.1606
2151.99	97.406
2155.66	30.5052
2159.31	58.1351
2162.97	59.3308
2166.63	72.589
2170.28	55.9603
2173.94	38.0757
2177.59	57.8219
2181.24	55.8838
2184.89	75.7212
2188.53	80.4406
2192.18	75.6671
2195.82	58.6936
2199.46	66.5854
2203.1	77.3828
2206.74	80.2006
2210.38	77.7708
2214.01	75.5265
2217.65	99.943
2221.28	87.7389
2224.91	77.4156
2228.54	92.767
2232.16	83.2949
2235.79	70.2201
2239.41	66.324
2243.04	118.944
2246.66	112.254
2250.28	116.777
2253.89	79.5505
2257.51	128.186
2261.12	89.0857
2264.74	38.4553
2268.35	87.2421
2271.96	87.6472
2275.57	73.5618
2279.17	100.558
2282.78	69.1377
2286.38	70.7096
2289.98	36.3525
2293.58	68.9244
2297.18	88.3367
2300.78	71.845
2304.37	57.0018
2307.97	90.2054
2311.56	36.026
2315.15	64.1112
2318.74	47.42
2322.33	77.8087
2325.91	86.5001
2329.5	100.714
2333.08	54.2903
2336.66	84.1864
2340.24	53.5587
2343.82	55.7854
2347.4	87.8546
2350.97	84.1219
2354.54	61.6387
2358.12	104.468
2361.69	39.0206
2365.26	90.9069
2368.82	77.756
2372.39	60.3656
2375.95	66.037
2379.52	21.8992
2383.08	89.5504
2386.64	35.7104
2390.19	52.9918
2393.75	61.3341
2397.31	86.5829
2400.86	41.7152
2404.41	64.5229
2407.96	41.683
2411.51	50.5974
2415.06	47.0105
2418.6	39.1621
2422.15	43.4806
2425.69	48.1473
2429.23	73.4963
2432.77	38.1813
2436.31	3.0321
2439.84	36.6257
2443.38	53.7305
2446.91	43.8879
2450.44	38.9751
2453.97	42.728
2457.5	39.9662
2461.03	36.9497
2464.55	0.810791
2468.08	46.4948
2471.6	61.2811
2475.12	19.9633
2478.64	51.1193
2482.16	42.8816
2485.67	26.6116
2489.19	28.3462
2492.7	29.895
2496.21	28.797
2499.72	66.6029
2503.23	50.5251
2506.74	66.0216
2510.25	47.6022
2513.75	20.0549
2517.25	35.6669
2520.75	34.7825
2524.25	33.8777
2527.75	44.5345
2531.25	33.3638
2534.74	54.7328
2538.24	55.2798
2541.73	36.7909
2545.22	37.4373
2548.71	39.6166
2552.2	53.8951
2555.68	24.1809
2559.17	35.8494
2562.65	15.1013
2566.13	24.6594
2569.61	45.892
2573.09	53.5844
2576.57	51.2944
2580.04	86.8751
2583.51	16.2054
2586.99	34.9702
2590.46	36.42
2593.93	49.5206
2597.4	60.5477
2600.86	33.8501
2604.33	4.99036
2607.79	41.4044
2611.25	0.902954
2614.71	39.1246
2618.17	32.7563
2621.63	10.4321
2625.09	20.5133
2628.54	3.32947
2631.99	58.9161
2635.45	57.4845
2638.9	28.8029
2642.34	44.936
2645.79	30.1644
2649.24	50.6709
2652.68	70.7919
2656.12	78.1067
2659.56	46.1848
2663.01	57.8174
2666.44	45.6473
2669.88	59.9009
2673.32	27.9432
2676.75	44.2197
2680.18	82.1777
2683.61	49.2985
2687.04	40.3719
2690.47	33.3247
2693.9	21.2028
2697.32	19.9893
2700.75	18.176
2704.17	43.3982
2707.59	56.5809
2711.01	41.0146
2714.43	66.687
2717.84	30.2992
2721.26	20.234
2724.67	30.8682
2728.08	50.9912
2731.49	56.2914
2734.9	17.5352
2738.31	16.1923
2741.71	60.76
2745.12	11.2422
2748.52	37.5739
2751.92	20.7153
2755.32	54.5345
2758.72	44.9382
2762.12	44.787
2765.52	55.5754
2768.91	36.0006
2772.3	26.5649
2775.7	71.6677
2779.09	11.958
2782.47	47.2029
2785.86	23.0325
2789.25	43.9945
2792.63	6.61243
2796.01	48.1511
2799.4	-10.8031
2802.78	18.2919
2806.15	36.12
2809.53	71.6909
2812.91	37.8861
2816.28	61.0974
2819.65	65.5696
2823.03	19.8701
2826.4	60.2462
2829.76	59.6776
2833.13	62.1106
2836.5	14.5139
2839.86	50.0852
2843.22	68.2478
2846.59	61.6117
2849.95	54.5636
2853.3	26.3713
2856.66	54.9666
2860.02	53.8889
2863.37	59.5454
2866.72	50.2834
2870.08	59.7871
2873.43	71.1053
2876.77	26.922
2880.12	95.589
2883.47	54.0961
2886.81	35.0537
2890.15	67.8761
2893.5	57.2164
2896.84	49.9872
2900.17	81.3337
2903.51	65.1826
2906.85	58.319
2910.18	78.7809
2913.52	54.6731
2916.85	82.5175
2920.18	57.1708
2923.51	45.9563
2926.83	114.986
2930.16	88.3174
2933.48	100.235
2936.81	115.701
2940.13	117.011
2943.45	80.6497
2946.77	76.4065
2950.09	123.963
2953.4	148.843
2956.72	144.628
2960.03	122.839
2963.34	111.534
2966.65	99.4015
2969.96	107.419
2973.27	122.271
2976.58	111.867
2979.88	85.7546
2983.19	127.042
2986.49	121.511
2989.79	129.217
2993.09	146.378
2996.39	120.42
2999.68	135.886
3002.98	125.963
3006.27	109.459
3009.57	127.891
3012.86	157.727
3016.15	140.521
3019.43	132.692
3022.72	88.0477
3026.01	157.573
3029.29	131.823
3032.57	162.714
3035.86	192.623
3039.14	131.733
3042.41	145.552
3045.69	135.757
3048.97	163.852
3052.24	167.344
3055.52	193.64
3058.79	172.48
3062.06	172.65
3065.33	219.547
3068.6	221.675
3071.86	210.188
3075.13	228.68
3078.39	222.186
3081.65	243.643
3084.91	248.43
3088.17	275.929
3091.43	277.312
3094.69	294.012
3097.95	313.428
3101.2	293.006
3104.45	347.401
3107.7	367.409
3110.95	338.657
3114.2	364.581
3117.45	364.005
3120.7	399.67
3123.94	382.012
3127.18	394.811
3130.43	441.872
3133.67	441.329
3136.91	440.74
3140.14	498.213
3143.38	431.739
3146.61	472.057
3149.85	463.872
3153.08	532.027
3156.31	569.604
3159.54	558.593
3162.77	548.475
3166	602.301
3169.22	566.259
3172.45	621.699
3175.67	603.583
3178.89	684.54
3182.11	680.553
3185.33	722.392
3188.55	723.939
3191.77	778.815
3194.98	745.991
3198.2	760.791
3201.41	819.348
3204.62	846.549
3207.83	832.887
3211.04	866.914
3214.25	880.15
3217.45	921.125
3220.66	940.224
3223.86	895.672
3227.06	947.42
3230.26	919.316
3233.46	987.474
3236.66	986.039
3239.85	968.92
3243.05	1040.48
3246.24	1009.33
3249.44	1046.78
3252.63	1035.87
3255.82	1071.77
3259.01	1022.69
3262.19	1082.11
3265.38	1037.13
3268.56	1065.36
3271.75	1080.95
3274.93	1118.37
3278.11	1087.93
3281.29	1116.23
3284.47	1110.68
3287.64	1141.43
3290.82	1068.03
3293.99	1147.39
3297.17	1117.98
3300.34	1134.35
3303.51	1163.64
3306.68	1124.72
3309.84	1207.34
3313.01	1193.51
3316.18	1234.62
3319.34	1284.14
3322.5	1208.38
3325.66	1300.41
3328.82	1386.62
3331.98	1424.53
3335.14	1482.42
3338.29	1532.91
3341.45	1633.55
3344.6	1748.3
3347.75	1925.9
3350.9	2159.83
3354.05	2461.53
3357.2	2969.12
3360.35	3668.34
3363.49	4531.45
3366.64	5601.59
3369.78	6961.27
3372.92	8679.75
3376.06	10352.6
3379.2	9987.38
3382.34	7919.53
3385.48	5739.5
3388.61	4440.34
3391.75	3613.02
3394.88	3233.42
3398.01	3012.48
3401.14	2838.21
3404.27	2748.44
3407.4	2688.31
3410.52	2748.09
3413.65	2952.58
3416.77	3369.87
3419.89	4332.87
3423.01	6649.59
3426.13	12102.7
3429.25	14381.9
3432.37	9142.97
3435.49	4849.8
3438.6	3127.4
3441.72	2524.85
3444.83	2198.19
3447.94	1970.24
3451.05	1884.44
3454.16	1812.58
3457.26	1849.27
3460.37	1777.02
3463.47	1726.7
3466.58	1686.75
3469.68	1722.36
3472.78	1679.67
3475.88	1708.98
3478.98	1729.88
3482.07	1823.69
3485.17	1831.46
3488.26	1963.14
3491.36	2106.48
3494.45	2261.93
3497.54	2536.06
3500.63	2945.6
3503.72	3527.53
3506.81	4241.13
3509.89	4771.29
3512.98	4550.65
3516.06	3998.41
3519.14	3203.08
3522.22	2642.52
3525.3	2175.9
3528.38	1934.89
3531.45	1695.91
3534.53	1514.71
3537.61	1379.44
3540.68	1316.22
3543.75	1259.71
3546.82	1126.31
3549.89	1106.84
3552.96	1070.72
3556.03	1024.9
3559.09	980.343
3562.16	941.422
3565.22	900.131
3568.28	858.502
3571.34	851.606
3574.4	772.629
3577.46	792.356
3580.52	781.578
3583.57	727.014
3586.63	756.688
3589.68	674.448
3592.73	666.906
3595.78	641.315
3598.83	630.739
3601.88	663.739
3604.93	590.495
3607.97	559.773
3611.02	571.623
3614.06	477.525
3617.1	519.484
3620.14	498.227
3623.18	445.938
3626.22	455.983
3629.26	477.427
3632.3	453.547
3635.33	436.205
3638.36	437.141
3641.4	425.113
3644.43	359.636
3647.46	329.344
3650.49	354.167
3653.51	309.562
3656.54	302.702
3659.57	303.627
3662.59	276.165
3665.61	229.557
3668.63	203.031
3671.65	208.844
3674.67	227.935
3677.69	181.044
3680.71	196.506
3683.72	153.316
3686.74	135.623
3689.75	125.516
3692.76	101.225
3695.77	110.073
3698.78	116.803
3701.79	111.463
3704.79	89.9755
3707.8	83.642
3710.81	61.9539
3713.81	71.5358
3716.81	54.3485
3719.81	54.3545
3722.81	58.0273
3725.81	32.0911
3728.81	57.4686
3731.8	47.5364
3734.8	86.0607
3737.79	55.897
3740.78	51.3499
3743.77	15.2715
3746.76	50.4686
3749.75	34.1915
3752.74	3.60364
3755.73	24.3083
3758.71	5.16553
3761.7	18.2578
3764.68	13.2432
3767.66	33.828
3770.64	45.9539
3773.62	17.5022
3776.6	22.2435
3779.58	1.53125
3782.55	18.6868
3785.53	18.85
3788.5	-7.35962
3791.47	20.3091
3794.44	18.8784
3797.41	15.6456
3800.38	53.0672
3803.35	4.72247
3806.32	4.57324
3809.28	3.50873
3812.24	52.5993
3815.21	28.9481
3818.17	26.1135
3821.13	17.6398
3824.09	28.1216
3827.04	7.42249
3830	41.6917
3832.96	7.69922
3835.91	17.4222
3838.86	31.0095
3841.82	1.83911
3844.77	21.131
3847.72	27.1445
3850.67	-2.04218
3853.61	12.6413
3856.56	31.1855
3859.5	-3.71948
3862.45	31.1138
3865.39	41.0658
3868.33	6.97754
3871.27	42.713
3874.21	23.8017
3877.15	56.6428
3880.09	34.6685
3883.02	17.3666
3885.96	28.7603
3888.89	16.0527
3891.82	47.5271
3894.75	39.5337
3897.68	26.5999
3900.61	43.3634
3903.54	24.5186
3906.47	50.7399
3909.39	32.8582
3912.31	35.069
3915.24	-10.8528
3918.16	23.8666
3921.08	47.2195
3924	25.2492
3926.92	47.3176
3929.83	56.804
3932.75	15.4546
3935.67	22.2699
3938.58	62.7989
3941.49	21.1532
3944.4	54.1035
3947.31	27.7462
3950.22	38.8287
3953.13	17.4275
3956.04	22.8776
3958.94	15.9637
3961.85	28.2559
3964.75	24.3057
3967.65	14.6535
3970.55	10.7971
3973.45	10.8027
3976.35	37.6749
3979.25	9.74359
3982.15	26.8979
3985.04	43.0834
3987.94	27.4971
3990.83	40.7251
3993.72	39.4141
3996.61	45.0167
3999.5	79.48
4002.39	36.9895
4005.28	56.1262
4008.16	54.1282
4011.05	18.402
4013.93	18.312
4016.81	34.6295
4019.7	33.587
4022.58	43.1581
4025.46	39.2189
4028.33	37.2279
4031.21	3.33917
4034.09	41.9785
4036.96	70.987
4039.84	36.1729
4042.71	15.8232
4045.58	4.99005
4048.45	43.6243
4051.32	16.4056
4054.19	3.76166
4057.05	18.3693
4059.92	56.2625
4062.78	30.0301
4065.65	34.8826
4068.51	38.7601
4071.37	30.949
4074.23	31.8865
4077.09	37.6726
4079.95	40.5302
4082.81	36.5626
4085.66	43.326
4088.52	22.7282
4091.37	58.7211
4094.22	61.6103
4097.07	36.0983
4099.92	25.2756
4102.77	40.8168
4105.62	31.8877
4108.47	19.9073
4111.31	34.3539
4114.16	55.5505
4117	31.6357
4119.84	59.4621
4122.69	56.9622
4125.53	34.0223
4128.36	26.7609
4131.2	28.5469
4134.04	41.2383
4136.88	-5.57764
4139.71	23.9344
4142.54	30.1202
4145.38	48.1731
4148.21	14.715
4151.04	48.8623
4153.87	54.4235
4156.69	50.8475
4159.52	69.4045
4162.35	23.7087
4165.17	45.6368
4168	31.3583
4170.82	26.9043
4173.64	48.9039
4176.46	68.9705
4179.28	26.4496
4182.1	65.1717
4184.91	37.4188
4187.73	42.9694
4190.54	47.5649
4193.36	43.4882
4196.17	49.2919
4198.98	61.1054
4201.79	60.1512
4204.6	92.5908
4207.41	113.248
4210.22	103.499
4213.02	106.477
4215.83	79.9493
4218.63	86.3907
4221.44	63.2196
4224.24	88.2563
4227.04	68.7838
4229.84	55.3542
4232.64	64.6794
4235.43	47.384
4238.23	61.8338
4241.02	61.4376
4243.82	65.0367
4246.61	37.8207
4249.4	69.3101
4252.19	53.8663
4254.98	43.3536
4257.77	47.7438
4260.56	61.1459
4263.35	63.58
4266.13	71.0674
4268.92	58.5206
4271.7	32.837
4274.48	55.4391
4277.26	47.6494
4280.04	12.4582
4282.82	51.9312
4285.6	44.8533
4288.38	37.6586
4291.15	36.4382
4293.93	43.28
4296.7	21.8702
4299.47	48.147
4302.25	21.6248
4305.02	41.7471
4307.79	58.8391
4310.55	45.5069
4313.32	54.5992
4316.09	60.5123
4318.85	61.2628
4321.62	49.7393
4324.38	24.904
4327.14	33.621
4329.9	30.1456
4332.66	54.0823
4335.42	12.8682
4338.18	68.3592
4340.94	73.0663
4343.69	19.6666
4346.45	40.7592
4349.2	44.5929
4351.95	53.5345
4354.7	46.3561
4357.45	45.2056
4360.2	52.2333
4362.95	38.7479
4365.7	22.2466
4368.44	59.9647
4371.19	46.5356
4373.93	45.2549
4376.68	29.5812
4379.42	39.4955
4382.16	80.2132
4384.9	37.7697
4387.64	38.6392
4390.37	28.483
4393.11	44.186
4395.85	53.3016
4398.58	21.5283
4401.31	46.5824
4404.05	47.7684
4406.78	37.5769
4409.51	56.4811
4412.24	49.3269
4414.96	21.2172
4417.69	30.5331
4420.42	46.8447
4423.14	51.8447
4425.87	63.1558
4428.59	34.7797
4431.31	42.9528
4434.03	28.0953
4436.75	35.1658
4439.47	29.6298
4442.19	66.9905
4444.91	69.7936
4447.62	28.4714
4450.34	79.4963
4453.05	55.9198
4455.76	47.0205
4458.47	44.3459
4461.19	31.1227
4463.89	60.048
4466.6	55.306
4469.31	43.2335
4472.02	24.861
4474.72	53.9365
4477.43	40.9403
4480.13	33.2523
4482.83	32.9808
4485.53	43.2661
4488.23	13.3242
4490.93	40.4412
4493.63	32.4766
4496.33	46.6209
4499.02	70.4377
4501.72	25.3566
4504.41	18.3393
4507.11	18.8026
4509.8	36.2537
4512.49	30.372
4515.18	48.9149
4517.87	44.123
4520.56	28.7253
4523.24	8.06049
4525.93	-13.7025
4528.61	44.3402
4531.3	32.1595
4533.98	17.843
4536.66	34.46
4539.34	34.0393
4542.02	40.0665
4544.7	48.2267
4547.38	23.2449
4550.05	30.3543
4552.73	32.1771
4555.4	31.9668
4558.08	52.2681
4560.75	15.782
4563.42	63.3784
4566.09	43.3063
4568.76	64.468
4571.43	24.5272
4574.1	35.8603
4576.77	32.8069
4579.43	35.5002
4582.1	34.1241
4584.76	43.7469
4587.42	44.2816
4590.08	40.4088
4592.74	27.7279
4595.4	30.3589
4598.06	28.6938
4600.72	52.1017
4603.38	25.3362
4606.03	36.8928
4608.69	40.7983
4611.34	24.9673
4613.99	46.4146
4616.64	23.9232
4619.29	20.1214
4621.94	37.2652
4624.59	4.80859
4627.24	32.9173
4629.89	34.5405
4632.53	31.717
4635.18	27.6853
4637.82	22.4949
4640.46	20.6061
4643.1	5.43036
4645.74	15.8685
4648.38	2.06671
4651.02	33.9359
4653.66	22.7201
4656.3	17.8773
4658.93	38.0066
4661.57	34.0708
4664.2	35.8137
4666.83	43.0579
4669.46	38.9738
4672.09	21.4973
4674.72	31.9915
4677.35	4.36041
4679.98	4.7301
4682.61	39.8997
4685.23	0.935303
4687.86	12.5274
4690.48	12.8866
4693.1	16.6315
4695.73	10.1813
4698.34	22.8875
4700.96	26.5924
4703.58	39.3151
4706.2	40.6945
4708.82	8.13141
4711.43	16.239
4714.05	35.6637
4716.66	24.5052
4719.28	35.9646
4721.89	5.48145
4724.5	35.0276
4727.11	4.57483
4729.72	-6.5835
4732.33	20.847
4734.93	36.9507
4737.54	22.3641
4740.14	7.72992
4742.75	43.1016
4745.35	21.5706
4747.95	-0.0130005
4750.55	2.21472
4753.15	30.6376
4755.75	26.0495
4758.35	21.46
4760.95	26.0344
4763.54	-5.78601
4766.14	3.42017
4768.73	13.9028
4771.33	21.0242
4773.92	33.7411
4776.51	52.1909
4779.1	12.4233
4781.69	22.8842
4784.28	37.9353
4786.87	27.8531
4789.45	22.3449
4792.04	4.26605
4794.63	13.681
4797.21	26.569
4799.79	-1.74414
4802.37	26.1708
4804.95	22.0233
4807.53	29.4408
4810.11	20.8082
4812.69	25.9811
4815.27	19.6686
4817.84	-5.08813
4820.42	1.35431
4822.99	26.3349
4825.57	13.1494
4828.14	4.56696
4830.71	12.2437
4833.28	2.54962
4835.85	18.4878
4838.42	-3.96024
4840.98	13.3109
4843.55	44.6677
4846.12	26.7934
4848.68	4.12326
4851.24	15.3219
4853.81	5.03937
4856.37	21.8987
4858.93	14.5873
4861.49	36.7115
4864.05	39.8583
4866.61	33.3813
4869.16	38.7671
4871.72	6.41217
4874.27	28.3883
4876.83	15.9675
4879.38	-0.0191956
4881.93	-0.609039
4884.49	8.28821
4887.04	17.2073
4889.58	38.0594
4892.13	26.8216
4894.68	50.1004
4897.23	22.1715
4899.77	8.52063
4902.32	38.9919
4904.86	-5.66833
4907.4	14.0898
4909.95	11.1785
4912.49	21.3143
4915.03	49.3551
4917.57	9.28204
4920.1	14.6792
4922.64	26.0727
4925.18	47.0577
4927.71	47.7932
4930.25	28.1688
4932.78	34.9984
4935.31	28.7955
4937.84	30.9325
4940.38	21.1184
4942.9	26.6768
4945.43	44.4205
4947.96	29.941
4950.49	27.4431
4953.01	5.82666
4955.54	54.9406
4958.06	44.2094
4960.59	50.3503
4963.11	12.1
4965.63	50.9489
4968.15	52.6594
4970.67	32.5529
4973.19	23.2832
4975.71	69.5891
4978.22	49.4957
4980.74	48.7878
4983.25	45.6942
4985.77	52.3466
4988.28	57.8445
4990.79	54.8953
4993.3	62.9011
4995.81	57.5581
4998.32	77.9077