File: Data/3-Raman/processed/bu19w-d-ff2-fi03-v_150 (500nm)_532nm_edge_100%_x100_vis_h50um_15sx2_03_0.txt
#Acq. time (s)=	15
#Accumulations=	2
#Range (cm-¹)=	100...5000
#Windows=	1
#Auto scanning=	Off
#Autofocus=	Off
#Macrospot=	Off
#AutoExposure=	Off
#Spike filter=	Multiple accum.
#Delay time (s)=	2
#Binning=	1
#Readout mode=	Signal
#DeNoise=	Off
#ICS correction=	On
#Dark correction=	Off
#Inst. Process=	Off
#Detector Gain=	Best Dynamic
#Detector ADC=	50 kHz HS
#Detector temperature (°C)=	-60.09
#Instrument=	LabRAM HR Evol
#Detector=	SIN-EM FIVIS
#Objective=	x100_VIS
#Grating=	150 (500nm)
#ND Filter=	100%
#Laser=	532nm_Edge
#Hole=	49.98
#Temperature=	0
#Range=	Visible
#StageXY=	75x50mm Scan+
#StageZ=	Z motor
#X (µm)=	0
#Y (µm)=	0
#Z (µm)=	-214.6
#Full time(s)=	38
#Project=	21_05_14
#Sample=	BU19w
#Site=
#Title=	BU19w-FF2-FI03-V_150 (500nm)_532nm_Edge_100%_x100_VIS_H50um_15sX2
#Remark=
#Date=	14.05.2021 17:30
#Acquired=	14.05.2021 17:30:18
#Base:Fit=	16.12.2021 17:39:50
#Base:Sub=	16.12.2021 18:02:23
102.699	821.838
107.322	750.782
111.942	654.618
116.56	587.873
121.173	535.422
125.787	490.489
130.398	434.569
135.006	409.082
139.613	289.806
144.215	296.792
148.817	347.282
153.417	557.926
158.014	901.382
162.607	663.392
167.2	275.741
171.79	152.205
176.379	165.175
180.963	337.746
185.547	663.703
190.128	591.388
194.705	307.879
199.282	81.0531
203.857	33.1248
208.43	27.1736
212.998	41.1655
217.566	11.4761
222.132	0.444763
226.693	128.911
231.254	298.938
235.813	338.445
240.368	582.847
244.923	863.701
249.475	488.615
254.023	204.582
258.571	107.302
263.117	124.685
267.658	333.976
272.199	1054.98
276.738	1993.31
281.273	1587.44
285.807	701.93
290.34	365.081
294.868	228.021
299.396	291.702
303.919	345.631
308.443	219.633
312.964	162.995
317.481	209.185
321.998	456.584
326.51	707.946
331.023	596.044
335.533	410.24
340.039	471.662
344.544	811.003
349.046	980.476
353.547	746.597
358.045	400.579
362.542	337.351
367.036	425.418
371.527	367.236
376.017	167.379
380.503	156.469
384.99	173.052
389.471	281.943
393.953	307.855
398.43	206.326
402.908	105.08
407.381	103.177
411.854	299.826
416.323	515.603
420.791	320.947
425.256	103.859
429.72	24.417
434.18	21.4777
438.64	-2.30939
443.095	20.9095
447.551	38.1705
452.003	108.802
456.454	98.4217
460.901	110.273
465.348	79.362
469.791	92.1279
474.231	86.0009
478.672	164.087
483.108	262.874
487.544	382.976
491.976	419.875
496.408	457.154
500.836	334.139
505.261	227.139
509.687	191.663
514.108	134.3
518.529	123.17
522.946	86.9857
527.361	73.8893
531.776	88.741
536.187	100.135
540.595	119.588
545.003	163.337
549.408	152.573
553.812	162.283
558.212	167.276
562.61	153.422
567.007	123.554
571.401	124.938
575.792	167.892
580.184	247.526
584.571	450.254
588.956	661.412
593.341	491.022
597.722	262.724
602.101	299.022
606.48	398.495
610.854	475.393
615.227	309.18
619.597	165.457
623.967	107.753
628.334	95.4549
632.698	132.267
637.06	167.219
641.422	185.023
645.779	164.601
650.135	172.428
654.491	230.265
658.842	346.423
663.192	451.872
667.539	492.022
671.884	505.548
676.23	531.233
680.571	416.359
684.91	229.317
689.247	129.596
693.583	66.6932
697.916	32.701
702.247	5.79321
706.576	4.62018
710.902	-3.99902
715.229	-0.752502
719.551	39.8761
723.872	10.166
728.19	6.78998
732.506	7.27441
736.82	36.3198
741.134	19.6409
745.444	23.8763
749.752	43.7806
754.058	57.0025
758.362	129.565
762.664	158.122
766.964	242.921
771.264	432.684
775.559	645.294
779.853	586.071
784.144	410.892
788.434	272.206
792.722	196.017
797.007	160.944
801.29	146.389
805.572	114.654
809.851	94.0444
814.13	58.2042
818.406	34.3857
822.679	59.1677
826.95	37.8129
831.219	59.4413
835.486	74.4283
839.752	110.326
844.015	154.911
848.276	202.177
852.535	143.477
856.792	68.3072
861.047	57.0118
865.3	33.3655
869.551	38.1829
873.8	-1.11285
878.047	4.50482
882.292	-6.57111
886.534	9.35547
890.775	7.14801
895.014	9.92621
899.251	8.49335
903.486	-1.0473
907.719	31.3579
911.95	30.6625
916.179	23.3291
920.406	12.8074
924.63	36.8488
928.853	27.5071
933.074	98.7716
937.293	95.6439
941.51	156.623
945.723	237.525
949.936	282.202
954.147	268.305
958.356	208.85
962.563	185.777
966.768	163.887
970.971	170.903
975.172	128.178
979.371	114.324
983.568	113.252
987.761	119.454
991.954	95.514
996.145	95.5228
1000.33	124.408
1004.52	105.691
1008.71	100.949
1012.89	121.466
1017.07	135.634
1021.25	140.207
1025.43	169.947
1029.6	177.316
1033.77	178.449
1037.95	230.942
1042.11	363.271
1046.28	626.581
1050.45	966.114
1054.61	936.363
1058.77	682.516
1062.93	423.148
1067.09	316.406
1071.24	331.423
1075.4	357.008
1079.55	469.194
1083.7	726.705
1087.85	1034.4
1091.99	1066.83
1096.14	915.224
1100.28	796.336
1104.42	905.995
1108.55	1086.37
1112.69	968.892
1116.82	812.222
1120.96	750.517
1125.09	773.774
1129.21	814.404
1133.34	859.969
1137.46	684.432
1141.59	525.344
1145.71	413.959
1149.83	477.96
1153.94	608.434
1158.06	617.08
1162.17	476.552
1166.28	445.244
1170.39	354.733
1174.5	249.669
1178.6	160.188
1182.7	105.826
1186.8	118.755
1190.9	82.2153
1195	72.1656
1199.1	100.641
1203.19	53.6354
1207.28	74.8274
1211.37	64.6367
1215.46	134.186
1219.54	177.41
1223.63	202.454
1227.71	164.705
1231.79	127.437
1235.87	155.288
1239.95	208.719
1244.02	178.38
1248.09	69.8487
1252.16	79.3205
1256.23	93.9521
1260.3	71.7363
1264.36	36.6106
1268.43	155.908
1272.49	298.573
1276.55	143.277
1280.6	27.8096
1284.66	24.5924
1288.71	0.212463
1292.76	17.9417
1296.81	-7.66895
1300.86	7.90479
1304.91	4.20612
1308.95	27.7594
1312.99	12.7557
1317.03	26.7277
1321.07	0.33551
1325.11	9.78796
1329.14	24.3963
1333.18	34.6558
1337.21	17.6904
1341.24	14.6889
1345.26	6.66168
1349.29	41.4979
1353.31	23.558
1357.33	21.5576
1361.35	10.6331
1365.37	19.7386
1369.39	53.5817
1373.4	296.66
1377.41	435.852
1381.43	151.8
1385.43	54.4202
1389.44	60.5076
1393.45	27.5536
1397.45	42.9811
1401.45	24.7531
1405.45	11.5313
1409.45	57.5189
1413.44	62.1635
1417.44	46.0576
1421.43	41.7354
1425.42	99.3669
1429.41	131.04
1433.39	177.738
1437.38	185.777
1441.36	198.772
1445.34	183.928
1449.32	168.071
1453.3	116.534
1457.27	103.415
1461.24	87.1115
1465.22	36.2415
1469.19	65.1247
1473.15	34.0986
1477.12	34.3351
1481.09	25.7062
1485.05	51.2501
1489.01	36.6824
1492.97	36.8329
1496.93	33.0974
1500.88	32.4064
1504.83	17.2894
1508.79	12.0474
1512.74	32.0429
1516.68	32.6726
1520.63	28.5057
1524.57	49.5836
1528.52	3.82471
1532.46	40.5203
1536.4	40.3623
1540.33	1.45044
1544.27	32.2877
1548.2	54.3874
1552.14	22.173
1556.07	48.9034
1559.99	60.012
1563.92	41.9956
1567.84	63.5474
1571.77	23.1989
1575.69	52.3723
1579.61	32.2606
1583.52	60.3132
1587.44	52.6225
1591.35	19.9066
1595.27	61.2292
1599.18	55.439
1603.09	25.7455
1606.99	69.0347
1610.9	63.3832
1614.8	48.2324
1618.7	52.26
1622.6	39.0405
1626.5	36.4839
1630.39	39.8044
1634.29	45.1489
1638.18	72.5194
1642.07	30.2054
1645.96	26.2507
1649.85	49.1779
1653.73	50.9754
1657.62	43.0836
1661.5	61.0242
1665.38	25.9454
1669.26	27.2144
1673.13	40.7913
1677.01	30.1127
1680.88	39.2236
1684.75	31.9097
1688.62	18.7227
1692.49	53.2445
1696.35	39.7535
1700.22	33.7527
1704.08	59.9573
1707.94	64.9548
1711.8	101.123
1715.66	89.8361
1719.51	105.034
1723.37	99.373
1727.22	105.811
1731.07	114.973
1734.92	118.45
1738.76	72.2423
1742.61	86.7748
1746.45	104.316
1750.29	73.0033
1754.13	78.2726
1757.97	92.853
1761.81	66.0352
1765.64	37.9066
1769.47	60.4104
1773.31	48.6699
1777.14	45.3925
1780.96	34.8477
1784.79	38.35
1788.61	36.2858
1792.43	20.1477
1796.25	51.8264
1800.07	32.4688
1803.89	26.8586
1807.71	76.7877
1811.52	46.467
1815.33	44.1219
1819.14	18.8081
1822.95	29.1627
1826.76	42.1238
1830.56	16.1763
1834.37	36.2157
1838.17	28.7805
1841.97	56.869
1845.77	38.8461
1849.56	67.5383
1853.36	31.2209
1857.15	24.6598
1860.94	66.3475
1864.73	30.7115
1868.52	52.7785
1872.31	43.3969
1876.09	62.7658
1879.87	42.61
1883.66	54.9073
1887.43	41.0269
1891.21	29.4579
1894.99	32.5258
1898.76	4.50745
1902.53	22.7437
1906.31	49.3643
1910.08	48.5673
1913.84	17.4818
1917.61	21.7417
1921.37	10.5655
1925.14	73.6135
1928.9	23.6461
1932.66	13.5135
1936.41	12.623
1940.17	26.6446
1943.92	17.4658
1947.68	27.1799
1951.43	28.1117
1955.18	6.07184
1958.92	59.6376
1962.67	31.3846
1966.41	49.9598
1970.16	36.1237
1973.9	20.2377
1977.64	32.2559
1981.37	2.95026
1985.11	24.8755
1988.84	16.8104
1992.57	62.4712
1996.31	40.9278
2000.03	59.1511
2003.76	28.3961
2007.49	28.7643
2011.21	24.4504
2014.93	30.4623
2018.65	36.1394
2022.37	28.4498
2026.09	32.242
2029.81	10.2037
2033.52	25.656
2037.23	16.1116
2040.94	-16.2891
2044.65	36.3028
2048.36	5.76025
2052.07	-1.78845
2055.77	34.7921
2059.47	25.4186
2063.17	-2.04565
2066.87	11.0099
2070.57	1.99927
2074.27	19.7694
2077.96	55.3034
2081.65	53.8269
2085.34	35.9346
2089.03	19.4748
2092.72	26.7305
2096.41	3.49725
2100.09	40.1896
2103.77	22.7656
2107.46	31.187
2111.14	14.3937
2114.81	32.8835
2118.49	47.3127
2122.16	30.6676
2125.84	13.9572
2129.51	16.5159
2133.18	14.3994
2136.85	37.9811
2140.51	13.3281
2144.18	30.9696
2147.84	44.8229
2151.5	50.3612
2155.16	39.4319
2158.82	48.6989
2162.48	12.4554
2166.13	1.0697
2169.79	10.9508
2173.44	19.4149
2177.09	38.8585
2180.74	18.3425
2184.38	20.5778
2188.03	11.4905
2191.67	23.7003
2195.32	29.9482
2198.96	8.95874
2202.6	23.6794
2206.23	9.38318
2209.87	46.4658
2213.5	19.6167
2217.14	33.0957
2220.77	33.7972
2224.4	43.722
2228.03	156.877
2231.65	174.47
2235.28	318.9
2238.9	430.362
2242.52	395.534
2246.14	283.433
2249.76	175.788
2253.38	128.538
2256.99	60.6139
2260.6	54.1176
2264.21	40.0715
2267.82	20.623
2271.44	4.86694
2275.04	29.1233
2278.65	29.3936
2282.25	6.41724
2285.85	40.3611
2289.45	35.3715
2293.05	10.4659
2296.65	41.4718
2300.25	20.3257
2303.84	9.30298
2307.43	16.0847
2311.02	17.9667
2314.62	27.224
2318.2	98.7695
2321.79	82.5782
2325.38	29.8972
2328.96	17.9998
2332.54	42.6635
2336.12	48.2817
2339.7	20.785
2343.28	23.2836
2346.85	17.1864
2350.43	26.947
2354	35.652
2357.57	33.0469
2361.14	55.4952
2364.71	33.338
2368.27	30.9265
2371.84	45.3132
2375.4	49.3505
2378.96	84.873
2382.52	61.528
2386.08	59.5549
2389.64	45.92
2393.19	-4.03723
2396.75	42.756
2400.3	45.207
2403.85	37.1677
2407.4	32.1322
2410.95	70.7928
2414.49	58.3389
2418.04	16.7443
2421.58	39.7657
2425.12	14.3438
2428.66	30.7399
2432.2	93.8121
2435.74	55.3003
2439.27	3.703
2442.81	65.7526
2446.34	27.3002
2449.87	37.7322
2453.4	84.5189
2456.93	24.803
2460.45	56.6775
2463.98	67.351
2467.5	83.5498
2471.02	26.7863
2474.54	63.5007
2478.06	60.1615
2481.58	67.8738
2485.09	58.7682
2488.61	46.8505
2492.12	82.0596
2495.63	51.1852
2499.14	53.3926
2502.65	96.1479
2506.15	59.2773
2509.66	64.3096
2513.16	75.2046
2516.66	67.8269
2520.16	61.6282
2523.66	109.888
2527.16	75.6246
2530.66	78.5585
2534.15	65.3286
2537.64	64.4093
2541.13	58.5991
2544.62	48.0548
2548.11	64.4529
2551.6	105.17
2555.08	76.5099
2558.57	86.7523
2562.05	48.3976
2565.53	70.9757
2569.01	94.1293
2572.49	39.0895
2575.96	70.4961
2579.44	76.8303
2582.91	37.9431
2586.38	65.9384
2589.85	103.76
2593.32	73.6139
2596.79	92.4683
2600.25	69.4795
2603.72	63.9247
2607.18	58.1967
2610.64	105.557
2614.1	97.9551
2617.56	125.343
2621.02	71.7079
2624.47	51.266
2627.92	70.927
2631.38	109.452
2634.83	104.249
2638.28	51.8461
2641.72	84.3286
2645.17	92.7863
2648.61	88.5061
2652.06	92.3989
2655.5	100.631
2658.94	85.9015
2662.38	89.9387
2665.82	108.12
2669.25	89.3141
2672.69	77.4178
2676.12	117.323
2679.55	79.8053
2682.98	86.7035
2686.41	119.781
2689.84	43.9015
2693.26	65.4506
2696.69	74.2837
2700.11	84.3241
2703.53	120.002
2706.95	112.379
2710.37	117.321
2713.79	140.313
2717.2	149.745
2720.62	178.145
2724.03	119.935
2727.44	87.0435
2730.85	106.398
2734.26	118.311
2737.66	145.298
2741.07	116.673
2744.47	105.514
2747.87	111.305
2751.28	130.26
2754.67	112.179
2758.07	120.713
2761.47	98.6179
2764.86	108.337
2768.26	104.52
2771.65	128.894
2775.04	124.724
2778.43	122.178
2781.82	128.904
2785.2	91.3453
2788.59	119.639
2791.97	126.146
2795.35	86.8295
2798.73	114.75
2802.11	124.842
2805.49	154.604
2808.87	97.1733
2812.24	116.476
2815.62	78.5995
2818.99	114.796
2822.36	87.8187
2825.73	120.679
2829.1	152.774
2832.46	155.399
2835.83	126.665
2839.19	129.032
2842.55	124.333
2845.91	109.93
2849.27	125.283
2852.63	145.89
2855.99	132.166
2859.34	142.13
2862.69	231.846
2866.05	214.016
2869.4	232.639
2872.75	216.478
2876.09	228.473
2879.44	205.64
2882.78	138.313
2886.13	250.054
2889.47	208.188
2892.81	247.949
2896.15	243.07
2899.49	188.712
2902.82	253.28
2906.16	273.274
2909.49	281.713
2912.82	328.963
2916.16	389.089
2919.49	459.454
2922.81	519.339
2926.14	590.096
2929.46	664.465
2932.79	624.002
2936.11	744.884
2939.43	720.471
2942.75	657.533
2946.07	574.161
2949.39	577.357
2952.7	525.039
2956.02	451.574
2959.33	480.85
2962.64	468.773
2965.95	444.084
2969.26	472.802
2972.57	485.203
2975.87	469.395
2979.17	464.39
2982.48	445.435
2985.78	417.264
2989.08	426.721
2992.38	347.042
2995.68	327.618
2998.97	283.779
3002.27	278.381
3005.56	229.897
3008.85	186.186
3012.14	210.373
3015.43	178.933
3018.72	176.673
3022	156.484
3025.29	183.542
3028.57	199.301
3031.85	147.9
3035.14	125.682
3038.41	139.426
3041.69	130.492
3044.97	98.9135
3048.24	112.72
3051.52	102.015
3054.79	118.769
3058.06	60.3885
3061.33	39.5137
3064.6	99.4701
3067.87	65.2491
3071.13	79.9457
3074.4	71.874
3077.66	124.502
3080.92	68.1492
3084.18	59.5564
3087.44	77.8762
3090.7	82.379
3093.95	42.3298
3097.21	22.483
3100.46	73.0194
3103.71	101.319
3106.96	97.392
3110.21	101.507
3113.46	103.683
3116.71	104.051
3119.95	50.1556
3123.2	77.2054
3126.44	106.127
3129.68	70.2772
3132.92	63.9473
3136.16	79.4636
3139.4	87.3206
3142.63	57.0435
3145.87	31.6278
3149.1	98.7915
3152.33	34.2971
3155.56	85.2516
3158.79	28.3756
3162.02	44.0194
3165.25	39.5171
3168.47	36.7914
3171.69	28.2703
3174.92	46.3397
3178.14	75.7944
3181.36	18.4967
3184.58	85.046
3187.79	11.3369
3191.01	61.5577
3194.22	84.1085
3197.43	-1.01587
3200.65	43.4536
3203.86	31.8083
3207.07	80.1997
3210.27	73.5028
3213.48	42.2137
3216.69	33.7974
3219.89	79.6409
3223.09	27.6737
3226.29	37.6008
3229.49	40.0686
3232.69	36.7177
3235.89	55.5499
3239.08	46.9569
3242.28	58.4686
3245.47	55.707
3248.66	61.6726
3251.85	59.1481
3255.04	68.0913
3258.23	31.9703
3261.42	89.1848
3264.6	64.973
3267.79	64.444
3270.97	59.9586
3274.15	108.014
3277.33	70.7787
3280.51	68.5063
3283.68	64.3195
3286.86	78.1069
3290.04	51.0037
3293.21	46.7771
3296.38	40.5801
3299.55	52.9238
3302.72	57.348
3305.89	54.9001
3309.06	75.0006
3312.22	113.913
3315.39	54.0242
3318.55	69.0676
3321.71	41.4592
3324.87	96.2554
3328.03	51.6857
3331.19	89.5027
3334.34	82.0834
3337.5	45.5789
3340.65	78.9146
3343.81	54.1014
3346.96	91.0844
3350.11	31.0054
3353.25	72.901
3356.4	43.2491
3359.55	59.0575
3362.69	32.5022
3365.84	51.2983
3368.98	43.7367
3372.12	26.9313
3375.26	79.1337
3378.4	78.6044
3381.53	65.6862
3384.67	123.816
3387.8	114.855
3390.94	118.284
3394.07	111.527
3397.2	123.653
3400.33	107.65
3403.46	200.995
3406.58	194.843
3409.71	398.109
3412.83	688.916
3415.96	1509.94
3419.08	3440.39
3422.2	4040.87
3425.32	2346.64
3428.44	965.142
3431.55	444.226
3434.67	279.815
3437.78	234.939
3440.89	145.334
3444	123.095
3447.12	191.417
3450.22	153.59
3453.33	131.974
3456.44	118.677
3459.54	127.207
3462.65	95.7423
3465.75	157.217
3468.85	199.028
3471.95	205.292
3475.05	219.292
3478.15	246.609
3481.24	309.839
3484.34	394.813
3487.43	545.935
3490.53	735.397
3493.62	995.613
3496.71	1387.44
3499.79	1775.52
3502.88	2122.06
3505.97	2039.89
3509.05	1571.49
3512.14	1203.18
3515.22	816.043
3518.3	602.672
3521.38	466.634
3524.46	348.445
3527.54	245.893
3530.61	265.744
3533.69	193.912
3536.76	127.426
3539.83	113.165
3542.9	117.895
3545.97	145.945
3549.04	108.544
3552.11	107.631
3555.18	138.212
3558.24	73.3964
3561.3	61.1509
3564.37	72.4365
3567.43	73.3827
3570.49	90.1492
3573.55	53.6062
3576.61	53.9683
3579.66	71.2601
3582.72	104.506
3585.77	64.6693
3588.82	18.0406
3591.87	68.9707
3594.92	6.97351
3597.97	41.5939
3601.02	55.2222
3604.07	78.1422
3607.11	36.6692
3610.16	36.7594
3613.2	40.5416
3616.24	60.3942
3619.28	79.3525
3622.32	26.6724
3625.36	37.2921
3628.39	89.3129
3631.43	48.8756
3634.46	51.1044
3637.5	-0.0179443
3640.53	61.9532
3643.56	77.2996
3646.59	77.3199
3649.62	2.27441
3652.64	70.2595
3655.67	68.0731
3658.69	26.408
3661.72	3.27478
3664.74	54.7872
3667.76	34.7587
3670.78	49.7776
3673.79	54.5193
3676.81	46.1515
3679.83	49.0581
3682.84	45.3306
3685.86	52.99
3688.87	70.1702
3691.88	42.9012
3694.89	35.2079
3697.9	-3.60156
3700.91	24.0667
3703.91	25.1753
3706.92	39.4288
3709.92	13.6206
3712.92	61.7566
3715.92	75.7267
3718.92	17.2325
3721.92	22.3303
3724.92	43.4598
3727.92	3.51685
3730.91	37.6967
3733.91	28.8302
3736.9	34.0887
3739.89	59.1294
3742.88	63.0594
3745.87	37.3416
3748.86	56.1595
3751.85	30.2573
3754.83	45.2238
3757.82	74.3778
3760.8	44.5928
3763.78	25.2477
3766.76	61.8657
3769.74	31.4318
3772.72	45.5973
3775.7	9.76257
3778.67	61.9236
3781.65	70.6423
3784.62	22.7847
3787.6	27.8921
3790.57	10.5792
3793.54	43.463
3796.51	28.3033
3799.47	27.5063
3802.44	31.5538
3805.41	38.4873
3808.37	31.3457
3811.33	49.7793
3814.3	28.5409
3817.26	6.40222
3820.22	29.7206
3823.18	43.7012
3826.13	35.9464
3829.09	30.9999
3832.04	47.9983
3835	40.4446
3837.95	59.5115
3840.9	34.8405
3843.85	9.20093
3846.8	51.2037
3849.75	51.4285
3852.69	45.9795
3855.64	25.2622
3858.58	38.9496
3861.53	52.5701
3864.47	37.4839
3867.41	61.5356
3870.35	37.608
3873.29	-2.71936
3876.22	23.9408
3879.16	22.5964
3882.1	67.1678
3885.03	50.0933
3887.96	21.3867
3890.89	68.573
3893.82	52.1099
3896.75	-1.12866
3899.68	20.6008
3902.61	23.811
3905.53	69.4802
3908.46	40.0863
3911.38	53.7874
3914.3	-10.5306
3917.23	97.3859
3920.15	51.4244
3923.06	69.5554
3925.98	82.7031
3928.9	64.0289
3931.81	75.3893
3934.73	4.74561
3937.64	59.9653
3940.55	68.1589
3943.46	59.1453
3946.37	51.2542
3949.28	55.96
3952.19	56.9036
3955.09	26.3911
3958	36.202
3960.9	40.349
3963.8	49.3906
3966.71	36.4713
3969.61	59.1243
3972.51	70.2677
3975.4	61.1563
3978.3	49.9834
3981.2	50.3066
3984.09	23.6162
3986.99	62.3112
3989.88	48.7815
3992.77	58.6339
3995.66	44.4464
3998.55	55.3632
4001.43	51.8677
4004.32	45.5713
4007.21	38.3534
4010.09	6.04016
4012.98	33.5172
4015.86	34.007
4018.74	27.7332
4021.62	43.6669
4024.5	60.6249
4027.37	71.8052
4030.25	126.566
4033.13	44.9801
4036	59.225
4038.87	35.7463
4041.75	65.2501
4044.62	41.453
4047.49	61.3806
4050.35	46.5024
4053.22	67.657
4056.09	18.9789
4058.95	11.9277
4061.82	42.7667
4064.68	87.2589
4067.54	30.5961
4070.4	73.1483
4073.26	23.2133
4076.12	69.6554
4078.98	45.9641
4081.83	89.5433
4084.69	78.4972
4087.54	82.0308
4090.4	44.6541
4093.25	60.9601
4096.1	61.6113
4098.95	3.67688
4101.8	94.2673
4104.64	46.8584
4107.49	10.095
4110.33	16.3138
4113.18	46.7914
4116.02	74.1394
4118.86	53.4309
4121.7	65.1893
4124.54	36.9592
4127.38	108.834
4130.22	65.6201
4133.05	64.8817
4135.89	16.1536
4138.72	20.2347
4141.56	72.9532
4144.39	80.4193
4147.22	59.6404
4150.05	106.266
4152.88	27.9454
4155.7	66.4423
4158.53	43.3046
4161.36	65.7299
4164.18	37.3032
4167	15.7654
4169.82	74.5353
4172.65	42.431
4175.46	76.8521
4178.28	46.8175
4181.1	93.1897
4183.92	18.354
4186.73	54.1393
4189.55	53.9048
4192.36	65.6744
4195.17	62.9813
4197.98	38.8081
4200.79	40.1013
4203.6	52.2155
4206.41	72.1814
4209.21	77.4354
4212.02	91.5038
4214.83	87.5098
4217.63	65.2817
4220.43	54.5814
4223.23	22.9642
4226.03	60.5211
4228.83	79.5873
4231.63	36.4404
4234.42	50.8785
4237.22	67.4006
4240.01	26.3606
4242.81	24.1223
4245.6	14.899
4248.39	58.4001
4251.18	53.9563
4253.97	63.4115
4256.76	77.8101
4259.55	38.1644
4262.33	60.7463
4265.12	37.2584
4267.9	68.0985
4270.68	49.6027
4273.47	46.9863
4276.25	52.1367
4279.03	74.3215
4281.8	17.5402
4284.58	19.1615
4287.36	33.7537
4290.13	17.8756
4292.91	43.644
4295.68	29.1113
4298.45	58.1309
4301.22	43.4611
4303.99	37.9264
4306.76	64.9459
4309.53	83.0015
4312.3	51.1622
4315.06	108.589
4317.83	10.2289
4320.59	56.2509
4323.35	49.2463
4326.11	41.2379
4328.87	50.4794
4331.63	40.3418
4334.39	63.8015
4337.15	57.8259
4339.9	16.3623
4342.66	47.3605
4345.41	41.8519
4348.17	54.7855
4350.92	58.8217
4353.67	32.322
4356.42	70.0946
4359.17	51.6071
4361.91	27.0098
4364.66	5.46606
4367.41	34.1587
4370.15	41.2673
4372.89	69.7605
4375.63	63.3029
4378.38	48.5377
4381.12	24.5835
4383.86	65.6656
4386.59	21.9779
4389.33	27.0717
4392.07	41.3018
4394.8	47.1655
4397.53	75.0928
4400.27	33.6366
4403	39.7744
4405.73	46.0349
4408.46	87.5782
4411.19	33.2131
4413.92	28.6168
4416.64	34.0101
4419.37	75.8083
4422.09	63.6565
4424.82	38.9833
4427.54	16.3763
4430.26	93.1038
4432.98	61.0106
4435.7	43.4609
4438.42	43.5853
4441.13	38.431
4443.85	40.5914
4446.57	47.9598
4449.28	62.6141
4451.99	28.88
4454.71	33.9205
4457.42	66.1904
4460.13	33.4073
4462.83	13.3073
4465.54	26.9036
4468.25	34.2964
4470.95	39.7118
4473.66	53.7264
4476.36	1.45959
4479.07	35.781
4481.77	38.5055
4484.47	46.439
4487.17	56.4706
4489.87	84.2369
4492.56	38.3612
4495.26	76.5614
4497.96	48.0763
4500.65	65.9097
4503.34	27.7793
4506.04	70.3011
4508.73	64.0629
4511.42	51.4808
4514.11	57.0199
4516.8	39.1859
4519.48	102.372
4522.17	17.8119
4524.85	58.6772
4527.54	32.5673
4530.22	24.5653
4532.9	56.103
4535.58	53.5287
4538.27	55.4209
4540.94	33.7289
4543.62	40.9786
4546.3	33.2565
4548.98	58.7943
4551.65	55.7975
4554.33	24.9446
4557	60.1868
4559.67	6.39197
4562.34	7.74719
4565.01	25.14
4567.68	43.2003
4570.35	20.3679
4573.02	30.7771
4575.68	32.3534
4578.35	-1.51697
4581.01	20.0713
4583.67	65.4496
4586.34	10.5447
4589	48.105
4591.66	-8.25574
4594.31	39.5773
4596.97	53.1655
4599.63	16.8291
4602.29	65.9937
4604.94	16.6143
4607.59	18.7631
4610.25	52.6948
4612.9	54.7733
4615.55	47.0022
4618.2	14.045
4620.85	18.4594
4623.5	30.4857
4626.14	79.9357
4628.79	21.245
4631.43	14.1799
4634.08	36.795
4636.72	24.0564
4639.36	44.3955
4642	46.2452
4644.64	71.8168
4647.28	28.9364
4649.92	25.2999
4652.56	43.5823
4655.19	16.2407
4657.83	37.2023
4660.46	67.5055
4663.1	-0.456787
4665.73	44.9031
4668.36	55.8507
4670.99	17.4756
4673.62	46.2968
4676.24	44.844
4678.87	11.8896
4681.5	109.228
4684.12	53.7902
4686.75	41.0002
4689.37	55.3409
4691.99	24.4465
4694.61	61.1227
4697.23	73.054
4699.85	60.179
4702.47	19.9725
4705.09	55.4397
4707.7	27.5228
4710.32	64.0577
4712.93	104.001
4715.55	60.0175
4718.16	23.9792
4720.77	70.4166
4723.38	63.8325
4725.99	13.1335
4728.6	61.1332
4731.21	22.8872
4733.81	77.7566
4736.42	77.9536
4739.02	92.9628
4741.63	4.26099
4744.23	85.0657
4746.83	48.3325
4749.43	54.8986
4752.03	33.0127
4754.63	45.1854
4757.23	85.9409
4759.82	57.4152
4762.42	26.5978
4765.01	25.6251
4767.61	59.2965
4770.2	79.9734
4772.79	37.9148
4775.38	63.2147
4777.97	69.0768
4780.56	48.658
4783.15	65.9744
4785.74	77.5767
4788.32	23.9829
4790.91	28.8228
4793.49	46.2499
4796.07	48.9612
4798.66	51.7644
4801.24	50.0674
4803.82	58.8601
4806.4	77.08
4808.98	75.6687
4811.55	29.3892
4814.13	90.3779
4816.71	60.4027
4819.28	38.4133
4821.85	70.8389
4824.43	46.5133
4827	46.4065
4829.57	65.1343
4832.14	54.767
4834.71	41.0527
4837.28	27.4277
4839.84	74.6586
4842.41	52.595
4844.97	52.5953
4847.54	41.8365
4850.1	56.0212
4852.66	54.0891
4855.22	33.051
4857.78	30.8035
4860.34	25.9053
4862.9	53.5001
4865.46	69.0431
4868.01	69.9072
4870.57	34.8654
4873.12	37.4336
4875.68	40.0222
4878.23	42.5399
4880.78	39.0016
4883.33	36.6119
4885.88	72.2827
4888.43	71.1559
4890.98	16.3685
4893.53	59.1719
4896.07	44.7305
4898.62	45.7721
4901.16	47.9248
4903.7	74.0215
4906.25	42.6051
4908.79	27.7667
4911.33	79.6064
4913.87	77.5874
4916.41	82.7677
4918.94	41.4231
4921.48	78.922
4924.02	31.6467
4926.55	38.0721
4929.08	41.0459
4931.62	29.99
4934.15	52.416
4936.68	53.2173
4939.21	39.2875
4941.74	50.5344
4944.27	56.1841
4946.79	31.9056
4949.32	54.3982
4951.85	51.6713
4954.37	46.6064
4956.9	33.3125
4959.42	32.1202
4961.94	36.0076
4964.46	0.461914
4966.98	67.1636
4969.5	4.65674
4972.02	20.5151
4974.53	26.6956
4977.05	14.7665
4979.57	44.0236
4982.08	64.8778
4984.59	25.1498
4987.1	-4.91479
4989.62	43.952
4992.13	10.1273
4994.64	37.2563
4997.15	14.5913
4999.65	27.2955