File: Data/3-Raman/processed/bu19(2)w-a-ff1-fi08-v_1800 (450-850nm)_532nm_edge_100%_x100_vis_lwd_h100um_30sx2_01.txt
#Acq. time (s)=	30
#Accumulations=	2
#Range (cm-¹)=	1200...2365
#Windows=	3
#Auto scanning=	Off
#Autofocus=	Off
#Macrospot=	Off
#AutoExposure=	Off
#Spike filter=	Multiple accum.
#Delay time (s)=	2
#Binning=	1
#Readout mode=	Signal
#DeNoise=	Off
#ICS correction=	On
#Dark correction=	Off
#Inst. Process=	Off
#Detector Gain=	Best Dynamic
#Detector ADC=	50 kHz HS
#Detector temperature (°C)=	-60.09
#Instrument=	LabRAM HR Evol
#Detector=	SIN-EM FIVIS
#Objective=	x100_VIS_LWD
#Grating=	1800 (450-850nm)
#ND Filter=	100%
#Laser=	532nm_Edge
#Hole=	100.021
#Temperature=	0
#Range=	Visible
#StageXY=	75x50mm Scan+
#StageZ=	Z motor
#X (µm)=	0
#Y (µm)=	0
#Z (µm)=	-63.9
#Full time(mm:ss)=	3:23
#Project=	21_11_26
#Sample=	BU19(2)w
#Site=
#Title=	BU19(2)w-A-FF1-FI08-V_1800 (450-850nm)_532nm_Edge_100%_x100_VIS_LWD_H100um_30sX2
#Remark=
#Date=	26.11.2021 16:41
#Acquired=	26.11.2021 16:41:21
#Base:Fit=	16.12.2021 16:00:56
#Base:Fit=	16.12.2021 16:08:27
#Base:Sub=	16.12.2021 16:08:29
1202.72	16.3835
1203.84	24.1209
1204.95	10.2226
1206.06	5.93569
1207.17	3.75512
1208.28	11.2703
1209.39	12.3422
1210.5	-0.441811
1211.61	-4.7568
1212.72	-1.59841
1213.83	4.77007
1214.94	1.60635
1216.05	-1.57094
1217.16	2.5927
1218.27	4.64005
1219.38	-0.710976
1220.49	-2.86701
1221.6	-0.7798
1222.71	-3.01366
1223.81	-7.3999
1224.92	1.99541
1226.03	-7.53299
1227.14	-0.192833
1228.25	0.645714
1229.35	8.82265
1230.46	1.63485
1231.57	4.51396
1232.67	2.36019
1233.78	1.23776
1234.89	-1.9414
1235.99	1.18845
1237.1	-2.04291
1238.2	-2.2016
1239.31	1.84083
1240.41	2.79842
1241.52	3.79231
1242.62	1.60252
1243.73	-0.531647
1244.83	0.453468
1245.94	1.36631
1247.04	8.58803
1248.14	5.36795
1249.25	7.35415
1250.35	7.29544
1251.45	5.07312
1252.56	14.3571
1253.66	9.02345
1254.76	13.2004
1255.87	21.5223
1256.97	22.5444
1258.07	37.0978
1259.17	31.7807
1260.27	37.0386
1261.37	66.0878
1262.48	99.831
1263.58	143.121
1264.68	91.5043
1265.78	61.0132
1266.88	47.4133
1267.98	22.4181
1269.08	26.7348
1270.18	30.9203
1271.28	31.8624
1272.38	25.5968
1273.47	28.8719
1274.57	37.3778
1275.67	34.2594
1276.77	34.3649
1277.87	52.3434
1278.97	74.5757
1280.07	117.763
1281.16	337.646
1282.26	1096.9
1283.36	2272.7
1284.45	1442.56
1285.55	306.756
1286.65	115.109
1287.75	75.091
1288.84	49.8591
1289.94	42.6341
1291.03	27.9956
1292.13	31.2217
1293.22	16.5549
1294.32	19.9217
1295.42	17.9274
1296.51	15.0556
1297.61	17.256
1298.7	13.0817
1299.79	5.75255
1300.89	15.3938
1301.98	10.2439
1303.08	9.33214
1304.17	2.03252
1305.26	2.15366
1306.35	6.43783
1307.45	9.72308
1308.54	3.54167
1309.63	6.87608
1310.73	10.2037
1311.82	0.87072
1312.91	0.00797272
1314	8.58855
1315.09	1.37003
1316.18	3.68948
1317.28	1.73464
1318.37	-1.236
1319.46	-2.11145
1320.55	1.23966
1321.64	2.42633
1322.73	-5.89445
1323.82	-3.61964
1324.91	3.9591
1326	-4.32606
1327.09	-2.13708
1328.18	-0.758011
1329.27	-0.465012
1330.35	-6.59601
1331.44	4.09914
1332.53	6.30694
1333.62	0.111885
1334.71	0.249161
1335.79	2.50832
1336.88	-1.50789
1337.97	4.97818
1339.06	2.00501
1340.14	2.23257
1341.23	5.61311
1342.32	7.91229
1343.4	5.98864
1344.49	7.26597
1345.58	0.152596
1346.66	1.34062
1347.75	6.71237
1348.83	-4.54133
1349.92	8.15715
1351	7.30522
1352.09	8.53884
1353.17	6.75794
1354.25	15.4187
1355.34	13.4012
1356.42	8.45293
1357.51	8.67227
1358.59	13.0334
1359.67	12.1989
1360.76	24.8168
1361.84	20.9055
1362.92	22.1693
1364	26.6039
1365.09	32.0404
1366.17	17.733
1367.25	24.1087
1368.33	44.0093
1369.41	125.984
1370.5	35.2365
1371.58	29.2219
1372.66	37.6028
1373.74	39.8605
1374.82	43.185
1375.9	42.4175
1376.98	54.9926
1378.06	54.1874
1379.14	61.8588
1380.22	68.2446
1381.3	88.8109
1382.38	111.52
1383.46	143.338
1384.54	277.794
1385.61	796.613
1386.69	3823.3
1387.77	3485.55
1388.85	529.787
1389.93	194.428
1391	121.508
1392.08	93.9611
1393.16	68.509
1394.23	53.3698
1395.31	56.6926
1396.39	53.9157
1397.46	42.8616
1398.54	50.2568
1399.62	40.3242
1400.69	44.7065
1401.77	52.1758
1402.84	41.31
1403.92	46.7856
1404.99	53.1192
1406.07	79.955
1407.14	132.437
1408.22	232.19
1409.29	231.493
1410.37	105.627
1411.44	49.3454
1412.51	37.2713
1413.59	24.4038
1414.66	21.4704
1415.73	22.7672
1416.81	16.8638
1417.88	20.2117
1418.95	20.4563
1420.02	22.723
1421.1	22.8918
1422.17	17.9893
1423.24	19.3886
1424.31	13.2254
1425.38	20.6279
1426.45	16.764
1427.52	9.74065
1428.59	15.0185
1429.67	14.2273
1430.74	8.34465
1431.81	9.65601
1432.87	10.857
1433.95	4.82787
1435.01	7.10013
1436.08	6.27771
1437.15	6.46103
1438.22	7.66901
1439.29	10.9585
1440.36	7.09559
1441.43	4.22663
1442.49	4.41119
1443.56	9.7236
1444.63	8.87302
1445.7	7.04951
1446.77	2.0857
1447.83	-5.95475
1448.9	4.49173
1449.97	6.71065
1451.03	6.85889
1452.1	8.0365
1453.17	4.10508
1454.23	4.28065
1455.3	2.39307
1456.36	3.59261
1457.43	4.75807
1458.49	1.83569
1459.56	-4.1466
1460.62	2.14861
1461.69	0.232464
1462.75	2.3983
1463.82	-1.58487
1464.88	2.70292
1465.94	-3.41421
1467.01	-3.28542
1468.07	-4.17244
1469.13	1.05958
1470.2	0.146801
1471.26	0.257687
1472.32	0.36557
1473.39	-0.530674
1474.45	-1.44193
1475.51	2.76154
1476.57	-0.18399
1477.63	2.96687
1478.69	-0.997673
1479.76	4.17189
1480.82	-3.88273
1481.88	-0.74049
1482.94	1.43028
1484	1.54734
1485.06	-0.463017
1486.12	-0.370533
1487.18	-1.27625
1488.24	1.84175
1489.3	-3.15441
1490.36	-1.04472
1491.42	-0.971519
1492.48	3.16163
1493.53	3.24719
1494.59	-0.708534
1495.65	1.38307
1496.71	0.417667
1497.77	0.489697
1498.82	-4.47693
1499.88	-1.36038
1500.94	0.739975
1502	-2.22771
1503.05	-0.150257
1504.11	2.92706
1505.17	5.01923
1506.22	3.03276
1507.28	0.0811615
1508.34	2.16241
1509.39	-0.795792
1510.45	1.28836
1511.5	-0.701855
1512.56	1.29073
1513.61	4.31435
1514.67	2.38924
1515.72	-0.604053
1516.78	-1.58993
1517.83	2.46575
1518.88	0.525402
1519.94	3.59452
1520.99	-1.38026
1522.05	1.68206
1523.1	1.70819
1524.15	-0.299706
1525.2	4.73138
1526.26	-2.22369
1527.31	-0.161198
1528.36	-0.139202
1529.41	1.885
1530.47	1.90715
1531.52	3.9708
1532.57	1.99199
1533.62	4.07149
1534.67	-1.9114
1535.72	1.10693
1536.77	-1.92566
1537.82	-1.94027
1538.87	2.05975
1539.92	0.141239
1540.97	0.227245
1542.02	-0.778683
1543.07	6.21143
1544.12	-5.82169
1545.17	-1.78119
1546.22	-1.72894
1547.27	2.30173
1548.32	4.29773
1549.37	-7.7229
1550.42	-0.691895
1551.46	3.44687
1552.51	-0.557365
1553.56	0.427433
1554.61	0.407516
1555.65	5.38938
1556.7	6.39436
1557.75	0.396786
1558.79	-4.63434
1559.84	-2.66863
1560.89	4.31271
1561.93	4.32372
1562.98	-2.65166
1564.02	-2.65692
1565.07	2.37634
1566.11	-1.84908
1567.16	-1.69598
1568.2	-2.66805
1569.25	-2.66118
1570.29	-1.68204
1571.34	-4.68401
1572.38	-1.70641
1573.43	-2.73135
1574.47	1.25311
1575.51	-1.71081
1576.56	-2.71051
1577.6	-4.75528
1578.64	1.18096
1579.69	2.16811
1580.73	-0.818943
1581.77	1.14972
1582.81	2.11526
1583.85	0.106609
1584.9	-1.89265
1585.94	1.08417
1586.98	4.03007
1588.02	-0.970749
1589.06	-0.967915
1590.1	-3.95114
1591.14	-1.96023
1592.18	-1.97915
1593.22	-2.025
1594.26	-3.08316
1595.3	-4.08205
1596.34	4.83281
1597.38	-2.12791
1598.42	-0.151733
1599.46	-1.19122
1600.5	2.73775
1601.54	3.6703
1602.58	-1.33449
1603.62	7.52005
1604.66	-0.413395
1605.69	4.52109
1606.73	0.570427
1607.77	1.47981
1608.81	4.20839
1609.84	1.03611
1610.88	2.22472
1611.92	1.97332
1612.95	-1.40565
1613.99	-0.764095
1615.03	1.85859
1616.06	-1.88564
1617.1	2.31439
1618.13	-3.85309
1619.17	2.33004
1620.2	-0.946751
1621.24	0.969219
1622.27	1.33156
1623.31	-0.406288
1624.34	-2.39398
1625.38	-0.153473
1626.41	0.594994
1627.45	1.087
1628.48	0.430233
1629.51	2.23458
1630.55	-0.486481
1631.53	-3.31309
1632.57	-2.32412
1633.62	1.60211
1634.66	-1.35736
1635.71	-1.3724
1636.75	-5.34056
1637.8	2.50628
1638.84	3.46706
1639.89	2.47163
1640.93	-0.48592
1641.98	2.45698
1643.02	1.45374
1644.06	-0.531345
1645.11	2.39386
1646.15	2.3964
1647.19	-2.54742
1648.24	1.36544
1649.28	0.408115
1650.32	6.30418
1651.37	-0.560047
1652.41	0.424541
1653.45	4.34859
1654.49	3.36478
1655.53	6.33352
1656.57	2.42537
1657.62	5.38062
1658.66	5.35862
1659.7	-0.589588
1660.74	-2.57327
1661.78	-0.579552
1662.82	0.445827
1663.86	-0.542442
1664.9	-0.572342
1665.94	2.33215
1666.98	-0.581955
1668.02	-1.59319
1669.06	1.37188
1670.1	2.38558
1671.14	2.41315
1672.18	-0.561924
1673.21	-0.560055
1674.25	-1.54163
1675.29	0.456619
1676.33	3.43338
1677.37	-1.51221
1678.4	-0.541477
1679.44	-1.55544
1680.48	0.407467
1681.52	2.37016
1682.55	4.34555
1683.59	-1.58365
1684.63	-2.57942
1685.66	-0.610077
1686.7	-0.604591
1687.73	3.358
1688.77	-5.54468
1689.81	2.32839
1690.84	-3.59808
1691.88	3.3258
1692.91	1.35085
1693.95	-6.5709
1694.98	0.304321
1696.01	2.28475
1697.05	-0.65567
1698.08	-1.66582
1699.12	-1.68602
1700.15	-0.698269
1701.18	2.2487
1702.22	-4.6491
1703.25	-2.69869
1704.28	2.21059
1705.32	1.24257
1706.35	1.24043
1707.38	-1.73445
1708.41	0.192783
1709.44	4.06952
1710.48	1.13093
1711.51	1.15252
1712.54	2.14241
1713.57	4.04533
1714.6	2.05581
1715.63	1.08747
1716.66	4.02613
1717.69	4.95737
1718.72	-4.8441
1719.75	3.91531
1720.78	1.00218
1721.81	2.9236
1722.84	-2.93763
1723.87	1.90177
1724.9	3.84106
1725.93	-0.0842438
1726.96	3.78845
1727.99	1.84937
1729.02	1.78118
1730.05	4.64951
1731.07	6.56606
1732.1	-0.134983
1733.13	1.79267
1734.16	3.68093
1735.18	6.53062
1736.21	5.53701
1737.24	1.68004
1738.26	3.59206
1739.29	-0.275043
1740.32	3.51641
1741.34	4.43878
1742.37	1.54916
1743.4	-1.32217
1744.42	4.41203
1745.45	3.45921
1746.47	10.1492
1747.5	-0.396172
1748.52	1.50304
1749.55	-3.24908
1750.57	5.39195
1751.6	3.51146
1752.62	3.48517
1753.64	4.41716
1754.67	4.39737
1755.69	8.19985
1756.71	6.26727
1757.74	6.23381
1758.76	5.30951
1759.78	3.42336
1760.81	6.27909
1761.83	4.36161
1762.85	6.2728
1763.87	2.48754
1764.89	6.33676
1765.92	2.56119
1766.94	12.0905
1767.96	8.28124
1768.98	4.46908
1770	6.3042
1771.02	9.19013
1772.04	10.1921
1773.06	3.57187
1774.08	10.2653
1775.1	-1.13367
1776.12	6.53882
1777.14	9.41004
1778.16	12.2498
1779.18	7.4608
1780.2	12.2228
1781.22	4.6352
1782.24	7.51566
1783.26	11.3687
1784.28	12.3586
1785.29	2.86218
1786.31	-1.90696
1787.33	5.75534
1788.35	7.7601
1789.37	6.87918
1790.38	7.88734
1791.4	4.05797
1792.42	3.07788
1793.43	4.05816
1794.45	4.07636
1795.47	1.24518
1796.48	2.25766
1797.5	1.3365
1798.51	-1.51987
1799.53	1.36959
1800.55	6.1558
1801.56	3.26959
1802.58	4.24645
1803.59	4.28391
1804.61	1.42462
1805.62	-2.3862
1806.64	1.50265
1807.65	1.52002
1808.66	-0.398708
1809.68	-0.386982
1810.69	0.588264
1811.7	-1.33886
1812.72	-2.29174
1813.73	-1.30322
1814.74	3.563
1815.76	-0.266365
1816.77	0.71331
1817.78	5.52595
1818.79	2.63863
1819.8	1.68819
1820.82	4.6112
1821.83	2.70074
1822.84	2.72101
1823.85	5.62831
1824.86	5.63316
1825.87	4.68323
1826.88	-0.154102
1827.89	3.73413
1828.9	2.76604
1829.91	1.78691
1830.92	2.74128
1831.93	0.820904
1832.94	0.844376
1833.95	1.825
1834.96	5.67468
1835.97	3.67564
1836.98	1.88285
1837.99	0.792999
1839	4.66054
1840	1.80956
1841.01	-0.201538
1842.02	1.66127
1843.03	-1.26725
1844.04	1.62473
1845.04	3.5532
1846.05	1.63285
1847.06	-0.263966
1848.07	1.53339
1849.07	2.50038
1850.08	-0.419262
1851.09	1.45438
1852.09	1.42555
1853.1	0.459015
1854.1	0.439827
1855.11	-1.52135
1856.11	1.31384
1857.12	4.17654
1858.12	4.15596
1859.13	-0.666462
1860.13	-0.697533
1861.14	3.13778
1862.14	3.15357
1863.15	-0.704411
1864.15	3.07932
1865.15	2.08788
1866.16	2.03134
1867.16	0.0545807
1868.16	0.951511
1869.17	-1.91261
1870.17	-1.92693
1871.17	2.81106
1872.17	-2.91235
1873.18	-3.89107
1874.18	-2.96403
1875.18	-1.10762
1876.18	3.56503
1877.18	1.62117
1878.18	-1.27702
1879.19	-2.17372
1880.19	0.684807
1881.19	-4.06334
1882.19	-1.28549
1883.19	-4.20075
1884.19	-5.18874
1885.19	-3.29735
1886.19	0.511314
1887.19	0.495529
1888.19	-4.26699
1889.19	0.386868
1890.19	5.06096
1891.19	0.366245
1892.18	0.346611
1893.18	-1.56429
1894.18	1.18923
1895.18	-0.719215
1896.18	1.16004
1897.18	-0.707642
1898.17	-1.65086
1899.17	-0.74374
1900.17	2.97692
1901.16	-2.67361
1902.16	4.86225
1903.16	3.92498
1904.16	-1.7448
1905.15	1.99676
1906.15	-1.79059
1907.14	-2.76761
1908.14	3.79831
1909.14	0.984154
1910.13	0.0654984
1911.13	0.0977783
1912.12	1.97938
1913.12	-3.69129
1914.11	4.7923
1915.11	2.9337
1916.1	1.99197
1917.1	-3.69971
1918.09	0.0413895
1919.08	-2.77745
1920.08	-2.7426
1921.07	3.86477
1922.06	-0.843266
1923.06	0.0837936
1924.05	1.94527
1925.04	0.968273
1926.04	1.92688
1927.03	5.74408
1928.02	2.91684
1929.01	-2.76413
1930	-3.69698
1931	7.71846
1931.99	0.106781
1932.98	0.0724564
1933.97	6.70854
1934.96	0.161797
1935.95	-2.62981
1936.94	-1.72286
1937.93	-1.76653
1938.92	-0.828709
1939.91	-0.82008
1940.9	-1.76004
1941.89	2.07735
1942.88	2.08251
1943.87	-3.67673
1944.86	-0.799973
1945.85	0.179901
1946.84	-3.63162
1947.83	4.00182
1948.82	1.11715
1949.8	2.08789
1950.79	0.216385
1951.78	-3.57442
1952.77	-3.55719
1953.76	-0.681885
1954.74	-1.72893
1955.73	-1.75767
1956.72	5.01141
1957.7	-0.721581
1958.69	0.248905
1959.68	-0.733585
1960.66	3.08015
1961.65	3.04301
1962.63	-2.72324
1963.62	1.11367
1964.61	-3.68357
1965.59	1.10528
1966.58	4.00058
1967.56	4.01297
1968.55	-1.75512
1969.53	2.0618
1970.52	5.85015
1971.5	1.98079
1972.48	1.01474
1973.47	1.00019
1974.45	1.92836
1975.44	2.88461
1976.42	5.77778
1977.4	1.93909
1978.39	6.70801
1979.37	4.77253
1980.35	6.68932
1981.33	6.66154
1982.31	7.59952
1983.3	1.82547
1984.28	5.62114
1985.26	10.3789
1986.24	10.3608
1987.22	10.3755
1988.21	14.1605
1989.19	12.0916
1990.17	10.8874
1991.15	8.57152
1992.13	11.3666
1993.11	12.1621
1994.09	16.4749
1995.07	15.1639
1996.05	13.4031
1997.03	12.3733
1998.01	14.7643
1998.99	17.321
1999.97	16.8878
2000.95	17.8249
2001.92	16.6949
2002.9	15.4868
2003.88	17.219
2004.86	18.8416
2005.84	19.276
2006.81	17.3863
2007.79	19.5828
2008.77	19.1804
2009.75	14.9082
2010.73	14.3169
2011.7	11.9268
2012.68	12.7003
2013.67	12.6522
2014.66	18.2138
2015.64	10.6909
2016.63	14.4778
2017.62	17.3416
2018.61	21.9707
2019.6	15.3334
2020.58	9.70185
2021.57	12.5246
2022.56	9.71333
2023.55	11.5526
2024.54	13.3928
2025.52	7.73762
2026.51	10.5118
2027.5	7.84544
2028.48	13.4117
2029.47	11.6352
2030.45	15.232
2031.44	9.67131
2032.43	9.69472
2033.41	5.0976
2034.4	13.5312
2035.38	6.93684
2036.37	7.98354
2037.35	7.98719
2038.34	7.05693
2039.32	7.04707
2040.31	4.22715
2041.29	7.00221
2042.27	7.0007
2043.26	6.06956
2044.24	4.2737
2045.23	6.13351
2046.21	8.11086
2047.19	5.28917
2048.17	3.39177
2049.16	6.22034
2050.14	7.22348
2051.12	6.34446
2052.11	5.40783
2053.09	6.37818
2054.07	2.70732
2055.05	5.54939
2056.03	2.74719
2057.01	2.75787
2058	1.85601
2058.98	1.90979
2059.96	0.0800285
2060.94	5.70612
2061.92	4.81192
2062.9	2.03711
2063.88	3.02344
2064.86	2.12696
2065.84	1.25139
2066.82	4.11787
2067.8	3.22252
2068.78	-0.492157
2069.76	-0.475151
2070.73	-0.451683
2071.71	0.539036
2072.69	-1.26515
2073.67	2.52209
2074.65	-0.265697
2075.63	1.69278
2076.6	1.76258
2077.58	0.828465
2078.56	-1.03848
2079.54	1.8414
2080.51	0.0187225
2081.49	2.88126
2082.47	1.02076
2083.45	0.110199
2084.42	-1.7526
2085.4	-0.776405
2086.37	-3.5711
2087.35	-0.677937
2088.32	-0.637753
2089.3	1.29174
2090.28	-0.546913
2091.25	0.442688
2092.23	-2.34394
2093.2	3.42611
2094.18	-2.20852
2095.15	-3.12175
2096.13	-0.258545
2097.1	2.61293
2098.07	0.721951
2099.05	-1.15395
2100.02	-0.178719
2101	-2.03882
2101.97	1.81281
2102.94	4.69073
2103.92	-0.99358
2104.89	1.89334
2105.86	0.0503349
2106.83	0.0980606
2107.8	-1.76953
2108.78	-2.72073
2109.75	1.11015
2110.72	-0.750252
2111.69	0.228695
2112.66	4.04823
2113.63	-1.59904
2114.61	-0.611866
2115.58	3.22109
2116.55	-0.564137
2117.52	-3.39428
2118.49	2.32061
2119.46	-1.47796
2120.43	-2.41885
2121.4	-0.484257
2122.37	-0.422199
2123.34	-3.21859
2124.31	-0.341896
2125.28	-0.355312
2126.25	1.52184
2127.21	0.574608
2128.18	-5.08141
2129.15	0.616192
2130.12	-1.25151
2131.09	-3.12
2132.06	-3.10734
2133.02	-2.15183
2133.99	4.48309
2134.96	1.68419
2135.93	0.763012
2136.89	2.64582
2137.86	2.68327
2138.83	4.58467
2139.79	3.68049
2140.76	0.852131
2141.73	-0.0695686
2142.69	3.70699
2143.66	2.82264
2144.62	0.898296
2145.59	-5.65333
2146.55	1.89011
2147.52	2.84326
2148.48	-2.78221
2149.45	0.0424385
2150.42	0.968102
2151.38	-2.7627
2152.34	2.90636
2153.31	-3.64193
2154.27	3.86547
2155.24	-1.77561
2156.2	1.01163
2157.16	1.02462
2158.13	0.129368
2159.09	1.09437
2160.05	2.03344
2161.01	-1.70745
2161.98	2.03754
2162.94	0.194012
2163.9	2.06841
2164.86	1.1352
2165.83	1.15828
2166.79	-2.55211
2167.75	0.241291
2168.71	3.00654
2169.67	-0.677769
2170.63	3.10949
2171.59	-2.46418
2172.56	-0.634792
2173.51	-3.41228
2174.48	-1.52427
2175.44	0.356289
2176.4	-1.48891
2177.36	2.23746
2178.32	-2.3854
2179.28	0.401455
2180.23	-3.29101
2181.19	0.4366
2182.15	4.15688
2183.11	1.37843
2184.07	0.438148
2185.03	4.15186
2185.99	-0.451176
2186.95	2.37561
2187.9	1.50291
2188.86	-2.208
2189.82	0.558418
2190.78	0.56049
2191.73	-1.27029
2192.69	-1.24368
2193.65	1.575
2194.6	0.710915
2195.56	-0.206707
2196.52	-1.15299
2197.47	-1.16768
2198.43	3.48458
2199.38	3.53963
2200.34	6.3956
2201.3	1.81721
2202.25	2.6455
2203.21	0.858582
2204.16	1.92505
2205.12	4.67072
2206.07	1.80503
2207.03	2.74373
2207.98	-1.87429
2208.93	1.8861
2209.89	0.0457191
2210.84	3.79224
2211.8	1.96213
2212.75	-0.803133
2213.7	-1.73857
2214.66	2.01842
2215.61	0.183613
2216.56	1.12915
2217.51	-5.40001
2218.47	-0.720541
2219.42	-1.63084
2220.37	1.19811
2221.32	-0.668751
2222.27	1.1782
2223.23	1.18883
2224.18	-1.57783
2225.13	-3.40806
2226.08	0.373859
2227.03	0.407784
2227.98	-1.44226
2228.93	0.433025
2229.88	-0.495161
2230.83	-1.39848
2231.78	-1.36372
2232.73	-0.392179
2233.68	-0.361717
2234.63	0.598801
2235.58	2.46272
2236.53	0.583847
2237.48	1.54404
2238.43	-5.93996
2239.38	1.64491
2240.33	0.693768
2241.27	0.714756
2242.22	-4.93231
2243.17	-1.14063
2244.12	2.628
2245.07	-0.182644
2246.01	4.58853
2246.96	0.835835
2247.91	2.74968
2248.85	1.80285
2249.8	0.863274
2250.75	-2.92227
2251.69	0.843071
2252.64	0.857222
2253.59	-0.0363922
2254.53	-0.00116158
2255.48	2.85272
2256.42	0.022543
2257.37	-0.89827
2258.32	-0.877069
2259.26	1.03982
2260.2	2.01122
2261.15	-0.819674
2262.1	-1.74502
2263.04	-3.62701
2263.98	-0.728718
2264.93	-0.678118
2265.87	1.25949
2266.81	2.20456
2267.76	-4.49373
2268.7	-0.689913
2269.65	1.24544
2270.59	5.11527
2271.53	-1.54353
2272.47	1.35054
2273.42	0.406942
2274.36	-1.49303
2275.3	-2.43617
2276.24	-5.29452
2277.18	-0.470512
2278.13	-0.421335
2279.07	2.48871
2280.01	0.551859
2280.95	-3.30774
2281.89	-4.27159
2282.83	-6.1671
2283.77	2.51114
2284.71	1.61375
2285.65	1.6439
2286.59	-3.17664
2287.54	-1.21102
2288.47	1.70171
2289.41	3.60925
2290.35	0.688513
2291.29	1.66102
2292.23	-3.10931
2293.17	6.55646
2294.11	1.76522
2295.05	0.792604
2295.99	1.74591
2296.93	-5.00715
2297.86	0.794744
2298.8	5.65407
2299.74	-0.0924644
2300.68	0.882853
2301.61	-1.98675
2302.55	-3.90953
2303.49	-3.90464
2304.43	-0.0274048
2305.36	4.8299
2306.3	2.919
2307.24	-0.933292
2308.17	3.89575
2309.11	-0.932236
2310.04	2.00342
2310.98	1.05362
2311.92	1.00956
2312.85	0.985649
2313.79	-1.89514
2314.72	3.9483
2315.66	2.04149
2316.59	2.00386
2317.52	0.0638313
2318.46	5.86792
2319.39	3.91771
2320.33	2.94425
2321.26	1.02559
2322.2	2.98756
2323.13	4.94403
2324.06	11.7225
2325	12.6761
2325.93	25.1799
2326.86	76.2672
2327.79	269.955
2328.73	160.971
2329.66	45.2547
2330.59	21.164
2331.52	6.7041
2332.46	3.8173
2333.39	1.86121
2334.32	3.76022
2335.25	2.76318
2336.18	-0.133881
2337.11	-1.11708
2338.04	-1.139
2338.97	4.60509
2339.91	0.743017
2340.84	4.54798
2341.77	-1.27456
2342.7	3.47166
2343.63	-3.27034
2344.56	3.41254
2345.49	3.37751
2346.41	2.36043
2347.34	1.36029
2348.27	1.32405
2349.2	2.24698
2350.13	1.19822
2351.06	-0.905603
2351.99	6.81709
2352.91	-1.87621
2353.84	0.886471
2354.77	-0.119167
2355.7	1.731
2356.63	2.59872
2357.55	-0.360504
2358.48	0.505035
2359.41	-7.18027
2360.33	2.22569
2361.26	1.16715
2362.19	-1.79111
2363.11	0.933212
2364.04	-0.12141
2364.97	-2.12481