File: Data/3-Raman/processed/bu19(2)w-a-ff1b-fi01-v_1800 (450-850nm)_532nm_edge_100%_x100_vis_lwd_h100um_30sx2_02.txt
#Acq. time (s)=	30
#Accumulations=	2
#Range (cm-¹)=	1200...2365
#Windows=	3
#Auto scanning=	Off
#Autofocus=	Off
#Macrospot=	Off
#AutoExposure=	Off
#Spike filter=	Multiple accum.
#Delay time (s)=	2
#Binning=	1
#Readout mode=	Signal
#DeNoise=	Off
#ICS correction=	On
#Dark correction=	Off
#Inst. Process=	Off
#Detector Gain=	Best Dynamic
#Detector ADC=	50 kHz HS
#Detector temperature (°C)=	-60.09
#Instrument=	LabRAM HR Evol
#Detector=	SIN-EM FIVIS
#Objective=	x100_VIS_LWD
#Grating=	1800 (450-850nm)
#ND Filter=	100%
#Laser=	532nm_Edge
#Hole=	100.021
#Temperature=	0
#Range=	Visible
#StageXY=	75x50mm Scan+
#StageZ=	Z motor
#X (µm)=	0
#Y (µm)=	0
#Z (µm)=	-1.6
#Full time(mm:ss)=	3:11
#Project=	21_11_26
#Sample=	BU19(2)w
#Site=
#Title=	BU19(2)w-A-FF1b-FI01-V_1800 (450-850nm)_532nm_Edge_100%_x100_VIS_LWD_H100um_30sX2
#Remark=
#Date=	26.11.2021 14:10
#Acquired=	26.11.2021 14:10:41
#Base:Fit=	16.12.2021 16:00:56
#Base:Sub=	16.12.2021 16:02:24
1202.72	6.8654
1203.84	14.3502
1204.95	7.77694
1206.06	5.46072
1207.17	8.47688
1208.28	9.38188
1209.39	12.4153
1210.5	11.1962
1211.61	9.90855
1212.72	10.7581
1213.83	9.49506
1214.94	7.20838
1216.05	10.2355
1217.16	11.0514
1218.27	0.199615
1219.38	8.48595
1220.49	6.16359
1221.6	2.78381
1222.71	13.1195
1223.81	10.7017
1224.92	8.32972
1226.03	9.19553
1227.14	13.2104
1228.25	7.60175
1229.35	8.31415
1230.46	5.11168
1231.57	5.80081
1232.67	6.64682
1233.78	4.32788
1234.89	8.34645
1235.99	11.3213
1237.1	8.99767
1238.2	17.1102
1239.31	14.7242
1240.41	5.06039
1241.52	13.2472
1242.62	15.1129
1243.73	10.7372
1244.83	12.6303
1245.94	23.888
1247.04	19.4576
1248.14	25.5206
1249.25	25.2791
1250.35	24.0371
1251.45	22.7292
1252.56	22.4832
1253.66	19.1108
1254.76	20.0119
1255.87	25.0628
1256.97	39.5237
1258.07	64.3862
1259.17	45.3639
1260.27	49.4368
1261.37	74.1904
1262.48	116.132
1263.58	189.544
1264.68	158.792
1265.78	79.0065
1266.88	57.9577
1267.98	35.9565
1269.08	46.4141
1270.18	50.467
1271.28	49.1854
1272.38	51.1601
1273.47	48.0207
1274.57	50.0991
1275.67	60.4853
1276.77	56.2637
1277.87	69.9089
1278.97	84.6453
1280.07	114.025
1281.16	251.73
1282.26	785.519
1283.36	2407.45
1284.45	2368.77
1285.55	460.316
1286.65	154.791
1287.75	98.8458
1288.84	70.3266
1289.94	60.8675
1291.03	55.58
1292.13	48.1453
1293.22	37.5634
1294.32	49.2406
1295.42	24.9741
1296.51	28.2927
1297.61	33.5379
1298.7	28.183
1299.79	32.3419
1300.89	26.0227
1301.98	33.4201
1303.08	24.9918
1304.17	24.9616
1305.26	19.6807
1306.35	21.7333
1307.45	18.5694
1308.54	17.5407
1309.63	19.6993
1310.73	13.4097
1311.82	12.3994
1312.91	19.8639
1314	17.7704
1315.09	14.6578
1316.18	15.8039
1317.28	15.8473
1318.37	15.9312
1319.46	17.0558
1320.55	5.50452
1321.64	12.9224
1322.73	17.1534
1323.82	15.0987
1324.91	13.0791
1326	12.067
1327.09	5.73167
1328.18	17.531
1329.27	13.5031
1330.35	13.5985
1331.44	16.8088
1332.53	11.5507
1333.62	11.5749
1334.71	17.9166
1335.79	9.58444
1336.88	9.66994
1337.97	11.8698
1339.06	11.9497
1340.14	15.226
1341.23	11.1837
1342.32	13.3956
1343.4	20.8034
1344.49	14.6717
1345.58	15.8373
1346.66	19.0248
1347.75	13.8809
1348.83	11.9269
1349.92	11.003
1351	24.6477
1352.09	22.6799
1353.17	21.8627
1354.25	18.9926
1355.34	23.1569
1356.42	22.2918
1357.51	16.2078
1358.59	24.6532
1359.67	19.6019
1360.76	24.9043
1361.84	32.3246
1362.92	33.5242
1364	35.8237
1365.09	46.3771
1366.17	37.1817
1367.25	42.4571
1368.33	58.1655
1369.41	166.967
1370.5	61.6863
1371.58	50.4426
1372.66	58.7588
1373.74	61.9909
1374.82	68.3544
1375.9	67.5397
1376.98	73.8847
1378.06	88.4736
1379.14	97.1702
1380.22	122.052
1381.3	131.18
1382.38	145.6
1383.46	187.608
1384.54	294.329
1385.61	714.603
1386.69	3598.42
1387.77	4884.87
1388.85	661.999
1389.93	238.546
1391	136.84
1392.08	118.486
1393.16	90.9534
1394.23	75.7885
1395.31	71.9274
1396.39	67.0859
1397.46	52.9444
1398.54	60.3241
1399.62	60.6099
1400.69	55.7695
1401.77	49.9136
1402.84	55.4286
1403.92	59.8718
1404.99	69.2745
1406.07	90.9748
1407.14	137.303
1408.22	286.264
1409.29	301.988
1410.37	108.431
1411.44	65.4803
1412.51	47.2598
1413.59	35.4204
1414.66	32.4919
1415.73	34.8215
1416.81	30.9798
1417.88	25.0904
1418.95	20.2054
1420.02	29.6779
1421.1	26.7823
1422.17	27.0263
1423.24	27.4072
1424.31	20.2445
1425.38	29.715
1426.45	19.7138
1427.52	20.9164
1428.59	14.9521
1429.67	15.2034
1430.74	11.3846
1431.81	20.9202
1432.87	15.9911
1433.95	13.0697
1435.01	13.3184
1436.08	15.5979
1437.15	12.7375
1438.22	15.0007
1439.29	20.3685
1440.36	14.4854
1441.43	13.6989
1442.49	11.8664
1443.56	9.0106
1444.63	10.248
1445.7	12.5565
1446.77	4.5547
1447.83	8.85873
1448.9	10.1144
1449.97	8.27179
1451.03	13.5899
1452.1	4.56387
1453.17	1.69918
1454.23	6.01375
1455.3	9.29335
1456.36	8.48549
1457.43	7.649
1458.49	1.69992
1459.56	0.883904
1460.62	5.17738
1461.69	8.43197
1462.75	5.53136
1463.82	4.67141
1464.88	2.85959
1465.94	6.01215
1467.01	3.13044
1468.07	4.33455
1469.13	7.57742
1470.2	1.62255
1471.26	5.86549
1472.32	0.937309
1473.39	2.13118
1474.45	0.259357
1475.51	2.47782
1476.57	6.71212
1477.63	6.86816
1478.69	6.01032
1479.76	2.0937
1480.82	6.28817
1481.88	3.39843
1482.94	1.55614
1484	6.80265
1485.06	-0.203463
1486.12	4.00026
1487.18	9.22807
1488.24	4.30087
1489.3	2.40476
1490.36	4.57205
1491.42	5.71604
1492.48	4.85021
1493.53	3.98175
1494.59	1.09289
1495.65	2.23438
1496.71	4.36565
1497.77	6.51456
1498.82	8.66834
1499.88	10.8306
1500.94	6.92889
1502	7.04701
1503.05	11.199
1504.11	7.2747
1505.17	2.36176
1506.22	8.5052
1507.28	-0.438431
1508.34	8.75035
1509.39	9.87667
1510.45	3.95154
1511.5	7.06026
1512.56	7.10976
1513.61	8.18852
1514.67	8.31824
1515.72	5.38518
1516.78	6.46525
1517.83	5.56061
1518.88	9.6854
1519.94	5.78097
1520.99	9.88719
1522.05	8.98578
1523.1	8.06233
1524.15	6.11419
1525.2	6.19117
1526.26	10.2993
1527.31	8.39916
1528.36	10.4757
1529.41	10.5458
1530.47	8.61429
1531.52	8.71451
1532.57	7.78517
1533.62	8.89671
1534.67	9.97875
1535.72	10.0354
1536.77	12.0627
1537.82	10.0932
1538.87	11.1396
1539.92	10.2541
1540.97	5.35838
1542.02	9.41097
1543.07	12.4427
1544.12	6.461
1545.17	10.5384
1546.22	5.61736
1547.27	10.686
1548.32	10.7208
1549.37	11.7525
1550.42	7.80855
1551.46	12.9636
1552.51	11.0021
1553.56	13.028
1554.61	11.0393
1555.65	15.0575
1556.7	16.0951
1557.75	9.12611
1558.79	13.1411
1559.84	15.1357
1560.89	9.15378
1561.93	9.19116
1562.98	11.2382
1564.02	9.26085
1565.07	12.3152
1566.11	14.1257
1567.16	9.30528
1568.2	15.3503
1569.25	9.38166
1570.29	12.3848
1571.34	9.40486
1572.38	14.4028
1573.43	14.3973
1574.47	10.4159
1575.51	14.4574
1576.56	11.4772
1577.6	10.4515
1578.64	13.4157
1579.69	12.4253
1580.73	12.443
1581.77	9.44396
1582.81	18.3979
1583.85	18.3944
1584.9	16.4073
1585.94	14.4152
1586.98	13.3935
1588.02	17.3598
1589.06	14.3862
1590.1	15.393
1591.14	22.3716
1592.18	14.3923
1593.22	13.3586
1594.26	17.2754
1595.3	16.2815
1596.34	18.2466
1597.38	17.2484
1598.42	21.2136
1599.46	19.1796
1600.5	14.1807
1601.54	15.1196
1602.58	16.0588
1603.62	11.0665
1604.66	14.0099
1605.69	20.9188
1606.73	22.8997
1607.77	15.1624
1608.81	23.5387
1609.84	17.4186
1610.88	18.745
1611.92	19.3384
1612.95	16.081
1613.99	20.9556
1615.03	22.4132
1616.06	20.7483
1617.1	19.1157
1618.13	21.9562
1619.17	23.9925
1620.2	21.347
1621.24	22.6516
1622.27	19.7742
1623.31	24.3251
1624.34	23.4956
1625.38	21.28
1626.41	24.2222
1627.45	26.7183
1628.48	22.3516
1629.51	21.8075
1630.55	23.739
1631.53	25.4896
1632.57	24.4932
1633.62	19.5293
1634.66	21.4771
1635.71	19.4686
1636.75	18.4318
1637.8	22.3132
1638.84	23.2496
1639.89	26.1674
1640.93	25.1556
1641.98	23.1507
1643.02	18.1836
1644.06	19.1249
1645.11	19.0708
1646.15	25.9348
1647.19	22.9281
1648.24	22.8763
1649.28	17.9577
1650.32	32.6835
1651.37	21.858
1652.41	26.7557
1653.45	26.7062
1654.49	23.722
1655.53	25.6754
1656.57	23.7128
1657.62	22.6881
1658.66	21.6466
1659.7	21.5823
1660.74	21.5365
1661.78	20.5425
1662.82	20.552
1663.86	25.4581
1664.9	20.4504
1665.94	23.3135
1666.98	26.2949
1668.02	24.2555
1669.06	16.3297
1670.1	22.2455
1671.14	20.2628
1672.18	23.1812
1673.21	19.1933
1674.25	16.1981
1675.29	19.1497
1676.33	17.1417
1677.37	18.0966
1678.4	21.9954
1679.44	18.9617
1680.48	15.9433
1681.52	15.8917
1682.55	16.8407
1683.59	14.8244
1684.63	15.7649
1685.66	15.7198
1686.7	14.6988
1687.73	9.73167
1688.77	13.6299
1689.81	17.514
1690.84	12.5346
1691.88	10.5376
1692.91	10.4974
1693.95	9.44238
1694.98	8.39698
1696.01	13.2922
1697.05	9.32532
1698.08	11.2336
1699.12	11.175
1700.15	8.18715
1701.18	12.0797
1702.22	15.9607
1703.25	9.02386
1704.28	4.07016
1705.32	11.9035
1706.35	10.8804
1707.38	11.7968
1708.41	5.84271
1709.44	8.71206
1710.48	12.5892
1711.51	9.63278
1712.54	4.70705
1713.57	12.4566
1714.6	8.48093
1715.63	7.47409
1716.66	10.3745
1717.69	5.42392
1718.72	7.29508
1719.75	9.20201
1720.78	9.17239
1721.81	9.11597
1722.84	12.9431
1723.87	8.03346
1724.9	7.02607
1725.93	8.89556
1726.96	8.85755
1727.99	4.94735
1729.02	8.73203
1730.05	14.4692
1731.07	6.69995
1732.1	5.74614
1733.13	6.67621
1734.16	11.4358
1735.18	4.62345
1736.21	7.46124
1737.24	6.46243
1738.26	4.49984
1739.29	8.29672
1740.32	6.3074
1741.34	8.1679
1742.37	4.29551
1743.4	6.1816
1744.42	9.97397
1745.45	6.1222
1746.47	8.00473
1747.5	6.04184
1748.52	6.96065
1749.55	6.95108
1750.57	7.91587
1751.6	9.82596
1752.62	5.00211
1753.64	5.91595
1754.67	7.78458
1755.69	8.70581
1756.71	2.94879
1757.74	3.85728
1758.76	4.80487
1759.78	9.55311
1760.81	3.82311
1761.83	4.74315
1762.85	10.4337
1763.87	5.67259
1764.89	8.53947
1765.92	5.68807
1766.94	6.62779
1767.96	2.80181
1768.98	5.63464
1770	9.36863
1771.02	5.57813
1772.04	6.54605
1773.06	3.70213
1774.08	5.61104
1775.1	6.56621
1776.12	6.59014
1777.14	12.3029
1778.16	9.41562
1779.18	5.57421
1780.2	4.61218
1781.22	6.52114
1782.24	4.62137
1783.26	7.49575
1784.28	8.46225
1785.29	2.75676
1786.31	6.56192
1787.33	5.61988
1788.35	5.67536
1789.37	6.67585
1790.38	9.57782
1791.4	5.73833
1792.42	7.62862
1793.43	1.88995
1794.45	1.89496
1795.47	0.959347
1796.48	4.82911
1797.5	1.00871
1798.51	1.02224
1799.53	3.90491
1800.55	5.80816
1801.56	5.80042
1802.58	1.00475
1803.59	4.87082
1804.61	5.84836
1805.62	0.10058
1806.64	4.9407
1807.65	3.98791
1808.66	3.9928
1809.68	3.03632
1810.69	0.151096
1811.7	2.07965
1812.72	4.98055
1813.73	5.96527
1814.74	3.10097
1815.76	1.1942
1816.77	3.13813
1817.78	3.12659
1818.79	6.03521
1819.8	7.01655
1820.82	4.13588
1821.83	3.18865
1822.84	9.01426
1823.85	4.18061
1824.86	4.18814
1825.87	6.1421
1826.88	7.11917
1827.89	3.26015
1828.9	3.26611
1829.91	5.20136
1830.92	7.13299
1831.93	3.27861
1832.94	3.30264
1833.95	5.2567
1834.96	3.30686
1835.97	7.14123
1836.98	3.38219
1837.99	6.20567
1839	4.27576
1840	0.446987
1841.01	1.37344
1842.02	2.29987
1843.03	3.24964
1844.04	4.22252
1845.04	0.373074
1846.05	1.3537
1847.06	6.21701
1848.07	3.23266
1849.07	2.28358
1850.08	3.23372
1851.09	2.24751
1852.09	2.23864
1853.1	1.2854
1854.1	1.28372
1855.11	2.22436
1856.11	1.2495
1857.12	-0.661402
1858.12	2.21066
1859.13	-1.62926
1860.13	1.23139
1861.14	1.25084
1862.14	2.23029
1863.15	1.26503
1864.15	3.16205
1865.15	3.14995
1866.16	2.16981
1867.16	2.1336
1868.16	-0.743759
1869.17	3.06451
1870.17	2.11707
1871.17	4.02146
1872.17	2.11876
1873.18	4.95902
1874.18	4.00594
1875.18	3.98776
1876.18	3.9541
1877.18	2.04012
1878.18	1.0655
1879.19	-0.777643
1880.19	3.03559
1881.19	2.09274
1882.19	0.170656
1883.19	1.07003
1884.19	1.04982
1885.19	-0.81641
1886.19	3.94028
1887.19	4.88702
1888.19	2.03619
1889.19	2.94903
1890.19	4.8224
1891.19	2.02051
1892.18	5.78743
1893.18	3.89718
1894.18	4.79976
1895.18	6.67065
1896.18	1.98692
1897.18	0.128168
1898.17	3.902
1899.17	6.71074
1900.17	4.81525
1901.16	2.93973
1902.16	2.96469
1903.16	5.8006
1904.16	4.85284
1905.15	4.85156
1906.15	3.90383
1907.14	4.82649
1908.14	2.95471
1909.14	2.96921
1910.13	2.99645
1911.13	7.74014
1912.12	4.92566
1913.12	2.09749
1914.11	5.88103
1915.11	3.08205
1916.1	1.2064
1917.1	4.02474
1918.09	4.95485
1919.08	3.08795
1920.08	5.01562
1921.07	4.07659
1922.06	4.09958
1923.06	5.98672
1924.05	4.08373
1925.04	1.23555
1926.04	3.14295
1927.03	3.17255
1928.02	2.24135
1929.01	2.25115
1930	5.11609
1931	3.2468
1931.99	3.24203
1932.98	1.32687
1933.97	1.32875
1934.96	7.10899
1935.95	2.40508
1936.94	8.09426
1937.93	3.30283
1938.92	2.34591
1939.91	6.16757
1940.9	5.23128
1941.89	0.482941
1942.88	0.489029
1943.87	1.42432
1944.86	1.43758
1945.85	4.32429
1946.84	1.46895
1947.83	3.37213
1948.82	8.14384
1949.8	6.24516
1950.79	6.28134
1951.78	8.24097
1952.77	6.33998
1953.76	4.41581
1954.74	4.34896
1955.73	3.36911
1956.72	6.28729
1957.7	2.4659
1958.69	3.43277
1959.68	6.29851
1960.66	2.43364
1961.65	1.44727
1962.63	6.23829
1963.62	5.27458
1964.61	7.19562
1965.59	6.22285
1966.58	8.1514
1967.56	3.35144
1968.55	6.2309
1969.53	7.16573
1970.52	6.16144
1971.5	5.17431
1972.48	7.08238
1973.47	6.10614
1974.45	4.15948
1975.44	7.9855
1976.42	7.99128
1977.4	7.98265
1978.39	4.12023
1979.37	10.8093
1980.35	9.84243
1981.33	5.9803
1982.31	10.7464
1983.3	8.79899
1984.28	8.76422
1985.26	10.6491
1986.24	7.75804
1987.22	8.71297
1988.21	8.67641
1989.19	10.4933
1990.17	8.63543
1991.15	9.59437
1992.13	8.11288
1993.11	11.8981
1994.09	10.7422
1995.07	9.61444
1996.05	12.1803
1997.03	11.7954
1998.01	5.88999
1998.99	10.3898
1999.97	10.756
2000.95	12.5303
2001.92	12.7433
2002.9	12.607
2003.88	12.4531
2004.86	14.305
2005.84	9.91881
2006.81	12.759
2007.79	12.1477
2008.77	12.6622
2009.75	8.25988
2010.73	14.0547
2011.7	15.7821
2012.68	11.6024
2013.67	10.6088
2014.66	9.6005
2015.64	11.451
2016.63	11.454
2017.62	16.1637
2018.61	11.4046
2019.6	8.52759
2020.58	13.1838
2021.57	10.3624
2022.56	9.40382
2023.55	9.35988
2024.54	12.1228
2025.52	9.26164
2026.51	8.28888
2027.5	10.2328
2028.48	8.31223
2029.47	6.48064
2030.45	11.9711
2031.44	6.37626
2032.43	7.30298
2033.41	2.65893
2034.4	8.2587
2035.38	9.13015
2036.37	9.19091
2037.35	7.2994
2038.34	9.14861
2039.32	7.24796
2040.31	3.47601
2041.29	9.03237
2042.27	6.20987
2043.26	5.25457
2044.24	5.27889
2045.23	8.97991
2046.21	5.30207
2047.19	8.06424
2048.17	7.08056
2049.16	5.21407
2050.14	5.23793
2051.12	7.11975
2052.11	3.35737
2053.09	3.35762
2054.07	6.18456
2055.05	4.3152
2056.03	2.4228
2057.01	8.94877
2058	3.33914
2058.98	5.22445
2059.96	4.29501
2060.94	8.02035
2061.92	6.15408
2062.9	4.28135
2063.88	0.544271
2064.86	5.23507
2065.84	5.25766
2066.82	8.08746
2067.8	6.21728
2068.78	8.10626
2069.76	9.03186
2070.73	6.20485
2071.71	4.33981
2072.69	2.49308
2073.67	5.30845
2074.65	5.31197
2075.63	4.40293
2076.6	-0.288322
2077.58	4.41398
2078.56	5.34746
2079.54	6.30573
2080.51	0.665758
2081.49	3.49757
2082.47	6.33047
2083.45	3.49841
2084.42	1.60557
2085.4	6.33106
2086.37	10.1223
2087.35	6.36508
2088.32	3.53519
2089.3	4.48725
2090.28	3.56105
2091.25	4.51916
2092.23	3.59498
2093.2	3.63274
2094.18	3.66229
2095.15	4.62121
2096.13	5.55762
2097.1	5.55278
2098.07	0.790882
2099.05	3.63587
2100.02	3.63596
2101	2.69695
2101.97	4.61887
2102.94	5.57172
2103.92	2.71422
2104.89	2.7258
2105.86	4.65155
2106.83	1.81991
2107.8	1.82862
2108.78	3.70918
2109.75	3.71721
2110.72	5.63156
2111.69	2.78805
2112.66	3.73826
2113.63	5.66413
2114.61	4.7282
2115.58	3.78778
2116.55	4.73536
2117.52	4.73506
2118.49	1.88727
2119.46	6.61377
2120.43	3.75969
2121.4	6.62209
2122.37	4.76551
2123.34	8.59294
2124.31	1.0104
2125.28	4.78277
2126.25	2.86305
2127.21	5.6903
2128.18	7.58361
2129.15	0.976749
2130.12	4.76654
2131.09	2.88457
2132.06	2.88531
2133.02	1.94205
2133.99	2.90189
2134.96	1.97709
2135.93	1.98925
2136.89	5.75368
2137.86	3.8927
2138.83	4.84389
2139.79	3.92718
2140.76	3.9231
2141.73	4.87748
2142.69	4.8826
2143.66	1.15727
2144.62	0.187963
2145.59	4.91142
2146.55	3.98747
2147.52	4.93754
2148.48	4.94559
2149.45	4.9503
2150.42	2.12656
2151.38	8.70473
2152.34	2.1793
2153.31	2.19415
2154.27	5.0157
2155.24	4.06326
2156.2	3.11614
2157.16	4.06504
2158.13	0.36306
2159.09	2.2613
2160.05	5.07409
2161.01	4.14013
2161.98	4.15623
2162.94	6.97968
2163.9	0.465305
2164.86	0.474955
2165.83	4.229
2166.79	3.31894
2167.75	3.32668
2168.71	3.31702
2169.67	5.21485
2170.63	2.48489
2171.59	2.50616
2172.56	1.56204
2173.51	5.2981
2174.48	2.54688
2175.44	1.64731
2176.4	6.31695
2177.36	1.69273
2178.32	4.5106
2179.28	8.23755
2180.23	5.48386
2181.19	5.50899
2182.15	3.6736
2183.11	0.910521
2184.07	2.7723
2185.03	5.57413
2185.99	6.54227
2186.95	6.59675
2187.9	4.80251
2188.86	2.96486
2189.82	2.96822
2190.78	2.98794
2191.73	4.87908
2192.69	3.0644
2193.65	6.82323
2194.6	3.17944
2195.56	2.27845
2196.52	4.14143
2197.47	9.71348
2198.43	5.10606
2199.38	3.31097
2200.34	9.88964
2201.3	6.24912
2202.25	4.32788
2203.21	6.26521
2204.16	9.20006
2205.12	3.58167
2206.07	7.26915
2207.03	7.29712
2207.98	3.62457
2208.93	4.60688
2209.89	3.71424
2210.84	2.81987
2211.8	2.86588
2212.75	2.91203
2213.7	6.66091
2214.66	4.83854
2215.61	5.8188
2216.56	9.58429
2217.51	4.00826
2218.47	3.10508
2219.42	3.14506
2220.37	3.18638
2221.32	-0.528543
2222.27	6.01486
2223.23	5.11046
2224.18	5.16058
2225.13	0.538553
2226.08	4.33268
2227.03	-0.306351
2227.98	6.29562
2228.93	2.56447
2229.88	5.40428
2230.83	5.45316
2231.78	1.74471
2232.73	4.60788
2233.68	5.59212
2234.63	5.62643
2235.58	0.927132
2236.53	3.76845
2237.48	-0.903461
2238.43	1.03152
2239.38	1.08024
2240.33	1.0919
2241.27	3.95308
2242.22	3.98048
2243.17	5.89738
2244.12	1.18771
2245.07	4.0494
2246.01	3.15319
2246.96	-3.43398
2247.91	5.10978
2248.85	3.22948
2249.8	2.30043
2250.75	7.04273
2251.69	7.03687
2252.64	0.439054
2253.59	7.11459
2254.53	5.25856
2255.48	3.37872
2256.42	4.34653
2257.37	2.47846
2258.32	4.40105
2259.26	3.47139
2260.2	4.44359
2261.15	7.31811
2262.1	2.58842
2263.04	5.46596
2263.98	4.55168
2264.93	4.59568
2265.87	4.61994
2266.81	2.70465
2267.76	5.55451
2268.7	1.73005
2269.65	3.6579
2270.59	-0.128544
2271.53	2.75818
2272.47	4.68788
2273.42	2.78137
2274.36	7.57371
2275.3	3.75224
2276.24	3.75876
2277.18	3.78125
2278.13	4.77308
2279.07	1.90761
2280.01	-0.0304832
2280.95	-0.0536232
2281.89	1.85036
2282.83	3.77649
2283.77	0.920214
2284.71	1.91245
2285.65	5.77119
2286.59	6.71106
2287.54	2.88322
2288.47	4.81363
2289.41	2.86026
2290.35	5.7057
2291.29	5.69858
2292.23	0.903109
2293.17	6.69095
2294.11	2.83861
2295.05	4.74113
2295.99	5.67761
2296.93	2.75717
2297.86	3.72207
2298.8	2.76938
2299.74	2.77567
2300.68	5.65661
2301.61	7.5863
2302.55	4.67458
2303.49	2.72541
2304.43	3.68091
2305.36	1.74723
2306.3	3.67133
2307.24	4.62466
2308.17	2.66572
2309.11	3.61036
2310.04	0.712542
2310.98	-0.267136
2311.92	6.44205
2312.85	4.46659
2313.79	3.48847
2314.72	5.43337
2315.66	5.42963
2316.59	4.409
2317.52	1.48099
2318.46	5.32685
2319.39	7.21937
2320.33	8.15362
2321.26	5.2446
2322.2	5.24609
2323.13	6.20815
2324.06	11.9954
2325	16.7972
2325.93	25.4244
2326.86	54.3089
2327.79	194.016
2328.73	143.828
2329.66	35.8183
2330.59	19.4191
2331.52	6.87286
2332.46	5.89734
2333.39	3.93479
2334.32	7.75248
2335.25	1.94295
2336.18	4.8098
2337.11	3.82344
2338.04	4.7615
2338.97	-0.0665264
2339.91	4.72339
2340.84	5.65368
2341.77	1.76721
2342.7	2.6928
2343.63	2.67472
2344.56	1.70323
2345.49	1.6875
2346.41	2.61551
2347.34	2.59909
2348.27	2.58999
2349.2	0.669701
2350.13	3.49715
2351.06	2.41936
2351.99	1.55796
2352.91	4.38177
2353.84	5.29501
2354.77	3.39102
2355.7	2.44167
2356.63	5.28422
2357.55	5.25592
2358.48	3.347
2359.41	5.244
2360.33	3.34054
2361.26	1.43266
2362.19	2.37157
2363.11	2.36485
2364.04	2.37036
2364.97	0.486914