File: Data/3-Raman/processed/bu19w-e-ff11b-fi01-v_150 (500nm)_532nm_edge_100%_x100_vis_h50um_30sx2_01_0.txt
#Acq. time (s)=	30
#Accumulations=	2
#Range (cm-¹)=	100...5000
#Windows=	1
#Auto scanning=	Off
#Autofocus=	Off
#Macrospot=	Off
#AutoExposure=	Off
#Spike filter=	Multiple accum.
#Delay time (s)=	2
#Binning=	1
#Readout mode=	Signal
#DeNoise=	Off
#ICS correction=	On
#Dark correction=	Off
#Inst. Process=	Off
#Detector Gain=	Best Dynamic
#Detector ADC=	50 kHz HS
#Detector temperature (°C)=	-60.09
#Instrument=	LabRAM HR Evol
#Detector=	SIN-EM FIVIS
#Objective=	x100_VIS
#Grating=	150 (500nm)
#ND Filter=	100%
#Laser=	532nm_Edge
#Hole=	49.98
#Temperature=	0
#Range=	Visible
#StageXY=	75x50mm Scan+
#StageZ=	Z motor
#X (µm)=	0
#Y (µm)=	0
#Z (µm)=	-244.6
#Full time(mm:ss)=	1:05
#Project=	21_11_04
#Sample=	BU19w
#Site=
#Title=	BU19w-E-FF11b-FI01-V_150 (500nm)_532nm_Edge_100%_x100_VIS_H50um_30sX2
#Remark=
#Date=	04.11.2021 18:35
#Acquired=	04.11.2021 18:35:33
#Base:Fit=	16.12.2021 17:39:50
#Base:Edit=	16.12.2021 17:46:16
#Base:Edit=	16.12.2021 17:46:18
#Base:Edit=	16.12.2021 17:46:20
#Base:Sub=	16.12.2021 17:46:23
101.869	8895.06
106.493	8458.15
111.113	9020.31
115.732	10786.5
120.349	9621.56
124.964	6863.74
129.577	5693.68
134.185	5164.11
138.793	4834.54
143.399	4412.9
148.003	4160.23
152.602	3926.48
157.201	3803.01
161.798	3812.51
166.392	3898.07
170.982	4190.53
175.572	4724.29
180.16	5852.78
184.745	7460.72
189.326	9116.21
193.907	9981.39
198.486	9235.24
203.06	7466.97
207.634	5621.97
212.206	4209.82
216.776	3215.68
221.341	2455.97
225.906	2084.42
230.469	1688.62
235.028	1454.82
239.586	1301.06
244.142	1344.13
248.694	1696
253.246	2103.59
257.795	1383.04
262.341	691.146
266.886	468.717
271.428	374.642
275.967	303.171
280.505	213.189
285.041	165.541
289.573	117.972
294.105	75.1462
298.632	47.4003
303.159	23.7747
307.685	19.6949
312.205	-0.334778
316.726	-5.95245
321.242	-12.0868
325.758	-27.3104
330.272	14.1661
334.782	90.2471
339.292	700.096
343.797	1153.25
348.302	590.013
352.803	186.949
357.304	70.1974
361.802	22.0304
366.297	17.3669
370.791	-5.8335
375.281	51.3269
379.77	199.516
384.256	339.497
388.741	393.486
393.223	409.468
397.704	187.198
402.18	72.7239
406.657	111.875
411.13	162.284
415.602	191.647
420.07	235.951
424.538	346.445
429.002	638.982
433.465	1109.2
437.925	2287.46
442.384	4877.42
446.839	11993.5
451.294	23256.4
455.745	24215.8
460.196	13614.8
464.642	6117.35
469.089	3273.97
473.531	2114.9
477.971	1570.85
482.411	1093.7
486.846	840.659
491.282	742.352
495.713	716.992
500.144	595.291
504.572	507.361
508.997	450.131
513.421	334.004
517.842	308.201
522.263	259.713
526.679	232.459
531.093	176.531
535.507	155.569
539.917	135.828
544.327	105.63
548.733	92.8581
553.137	92.7774
557.54	73.6431
561.94	56.0495
566.337	56.2891
570.734	71.7212
575.127	68.6629
579.518	54.3464
583.909	40.4038
588.295	71.5767
592.68	42.03
597.064	35.9575
601.445	29.8222
605.823	25.1136
610.201	25.7469
614.575	29.7797
618.947	10.8333
623.317	40.2796
627.686	42.4578
632.052	27.8491
636.415	24.1813
640.777	43.7261
645.138	35.638
649.495	51.2322
653.85	5.88208
658.205	44.6653
662.556	29.1412
666.905	41.7847
671.252	70.0784
675.597	85.552
679.941	151.504
684.282	221.361
688.62	212.479
692.957	134.547
697.293	68.7164
701.625	66.3752
705.955	31.5377
710.283	57.5703
714.609	39.7335
718.933	39.2001
723.257	57.2151
727.577	38.4465
731.894	45.8151
736.21	32.404
740.524	50.5753
744.835	41.6783
749.147	54.8495
753.454	78.5351
757.759	80.0324
762.063	69.2713
766.364	71.4301
770.663	122.781
774.96	161.573
779.257	241.857
783.55	422.642
787.841	550.489
792.13	723.669
796.417	896.541
800.702	704.218
804.985	375.692
809.266	222.493
813.545	166.125
817.821	162.61
822.096	162.309
826.371	130.219
830.641	113.51
834.91	156.254
839.176	126.155
843.441	116.866
847.703	121.672
851.964	128.254
856.222	194.307
860.479	250.313
864.733	340.215
868.986	277.87
873.236	184.717
877.485	135.487
881.731	136.623
885.975	114.541
890.218	102.047
894.458	108.86
898.696	94.7238
902.933	110.016
907.167	113.746
911.399	116.689
915.63	108.041
919.858	94.9334
924.084	91.3983
928.308	64.8835
932.531	64.7854
936.749	68.8989
940.967	68.542
945.184	73.4355
949.398	64.3604
953.61	48.9962
957.821	70.9293
962.029	60.9228
966.236	73.2416
970.44	61.134
974.642	43.7872
978.843	52.9472
983.041	48.3634
987.236	31.0281
991.43	39.0661
995.623	46.2548
999.813	62.1234
1004	78.0554
1008.19	54.7195
1012.37	53.631
1016.55	53.4431
1020.73	55.3292
1024.91	75.2458
1029.09	65.0818
1033.27	75.0674
1037.44	66.4734
1041.61	69.3305
1045.78	114.71
1049.94	152.325
1054.11	258.575
1058.27	292.229
1062.43	320.239
1066.59	434.121
1070.75	587.057
1074.9	422.159
1079.05	235.354
1083.2	149.27
1087.35	88.6236
1091.5	84.1258
1095.65	73.5705
1099.79	100.116
1103.93	81.5025
1108.07	75.3127
1112.21	62.1662
1116.34	71.4646
1120.48	75.0623
1124.61	82.052
1128.74	70.741
1132.86	94.2765
1136.99	128.017
1141.11	150.48
1145.23	266.704
1149.35	392.407
1153.47	394.229
1157.59	247.143
1161.7	146.26
1165.82	96.7984
1169.92	91.608
1174.03	66.687
1178.14	81.8887
1182.24	83.642
1186.35	99.6725
1190.45	87.7209
1194.55	81.836
1198.64	107.512
1202.74	118.677
1206.83	138.865
1210.92	159.942
1215.01	212.22
1219.1	222.925
1223.18	244.679
1227.27	256.371
1231.35	250.162
1235.43	266.273
1239.5	301.674
1243.58	359.843
1247.65	482.009
1251.72	734.333
1255.8	749.289
1259.86	618.483
1263.93	627.633
1267.99	1944.46
1272.06	4639.49
1276.12	4134.69
1280.18	1417.65
1284.23	533.807
1288.29	398.924
1292.34	360.43
1296.39	326.813
1300.44	304.188
1304.49	303.608
1308.53	294.899
1312.58	279.074
1316.62	270.115
1320.66	266.066
1324.7	268.897
1328.73	283.661
1332.77	296.348
1336.8	300.791
1340.83	303.111
1344.86	336.314
1348.88	363.384
1352.91	452.055
1356.93	581.155
1360.95	657.172
1364.97	822.119
1368.99	1451.27
1373.01	4992
1377.02	8155.4
1381.03	4686.91
1385.04	1298.46
1389.05	578.569
1393.06	666.189
1397.06	967.874
1401.06	794.978
1405.06	422.853
1409.06	289.068
1413.06	270.588
1417.05	239.267
1421.05	201.975
1425.04	170.52
1429.03	177.381
1433.01	142.763
1437	119.018
1440.99	107.111
1444.97	102.075
1448.95	78.2568
1452.93	74.1375
1456.9	67.0244
1460.88	63.8119
1464.85	71.3397
1468.82	73.9051
1472.79	54.8932
1476.76	58.4543
1480.73	60.0042
1484.69	72.2934
1488.65	60.0942
1492.61	47.9415
1496.57	64.0948
1500.53	53.9439
1504.48	49.6956
1508.43	65.9347
1512.39	62.7521
1516.33	60.555
1520.28	58.3894
1524.23	61.0939
1528.17	70.6038
1532.11	73.3575
1536.05	72.2437
1539.99	67.2612
1543.93	75.8485
1547.86	68.933
1551.8	81.3949
1555.73	89.9467
1559.66	99.4148
1563.58	116.58
1567.51	97.9124
1571.44	124.667
1575.36	109.852
1579.28	126.893
1583.2	123.65
1587.11	144.477
1591.03	164.295
1594.94	157.144
1598.85	166.344
1602.76	185.161
1606.67	194.417
1610.58	192.174
1614.48	210.088
1618.38	203.138
1622.29	215.331
1626.18	238.103
1630.08	237.963
1633.98	198.718
1637.87	235.092
1641.76	234.235
1645.65	230.612
1649.54	227.035
1653.43	184.141
1657.31	177.646
1661.2	179.774
1665.08	149.161
1668.96	161.746
1672.83	152.117
1676.71	121.311
1680.58	104.778
1684.46	84.3352
1688.33	62.9484
1692.2	57.8402
1696.06	51.7497
1699.93	38.9502
1703.79	58.5641
1707.66	43.7887
1711.52	35.6704
1715.37	19.0573
1719.23	25.2291
1723.08	23.8355
1726.94	6.42049
1730.79	11.6065
1734.64	10.223
1738.49	-0.52652
1742.33	-0.981674
1746.18	-6.07683
1750.02	-20.323
1753.86	-15.8757
1757.7	-29.8738
1761.54	-3.66411
1765.37	-13.7302
1769.21	-5.17897
1773.04	-28.1119
1776.87	-7.33165
1780.7	-26.5082
1784.53	-16.7639
1788.35	-24.7264
1792.17	-24.2722
1796	-24.7455
1799.82	-17.7052
1803.64	-34.2791
1807.45	-24.539
1811.27	-18.5659
1815.08	-10.7272
1818.89	-11.4529
1822.7	-27.3282
1826.51	-30.967
1830.32	-18.6174
1834.12	-20.4629
1837.92	-28.9242
1841.72	-14.8223
1845.52	-25.2138
1849.32	-18.6715
1853.12	-35.6368
1856.91	-23.6086
1860.7	-20.0772
1864.5	-25.8884
1868.28	-25.1516
1872.07	-21.6124
1875.86	-21.7439
1879.64	-25.5461
1883.42	-20.9617
1887.21	-21.8932
1890.98	-13.4179
1894.76	-19.637
1898.54	-21.2524
1902.31	-18.1868
1906.08	-22.4384
1909.85	-15.6163
1913.62	-14.2458
1917.39	-17.4652
1921.16	-4.86076
1924.92	-4.2195
1928.68	-9.10803
1932.44	-10.2739
1936.2	-24.4888
1939.96	5.1091
1943.71	-18.4929
1947.47	-11.2519
1951.22	-9.77296
1954.97	1.96248
1958.72	-0.482224
1962.46	-12.3922
1966.21	-4.58786
1969.95	-0.594238
1973.7	8.9435
1977.43	8.11818
1981.17	6.32483
1984.91	11.9801
1988.65	13.8627
1992.38	18.5062
1996.11	12.8634
1999.84	20.1968
2003.57	11.7652
2007.3	22.764
2011.02	22.5955
2014.75	4.96188
2018.47	18.7064
2022.19	16.9492
2025.91	25.3994
2029.62	33.8742
2033.34	16.7962
2037.05	15.3866
2040.76	29.5145
2044.47	25.323
2048.18	22.9611
2051.89	17.8976
2055.59	34.8349
2059.3	26.2245
2063	42.5318
2066.7	12.9717
2070.4	43.2093
2074.1	20.953
2077.79	26.3678
2081.49	27.1879
2085.18	37.2674
2088.87	22.9785
2092.56	29.9054
2096.25	42.5238
2099.93	36.5334
2103.61	28.594
2107.3	15.9663
2110.98	37.7149
2114.66	49.2188
2118.33	46.7504
2122.01	50.6968
2125.68	29.5283
2129.36	33.3954
2133.03	19.6441
2136.7	21.6308
2140.36	39.2699
2144.03	24.5668
2147.7	20.9374
2151.36	39.3584
2155.02	19.219
2158.68	33.0233
2162.34	40.4118
2165.99	35.0386
2169.65	37.0105
2173.3	12.6487
2176.95	19.3252
2180.6	30.5704
2184.25	28.1578
2187.9	22.1532
2191.54	24.4182
2195.18	30.4074
2198.83	29.1694
2202.47	20.6551
2206.11	23.1078
2209.74	26.5131
2213.38	10.7309
2217.01	13.2483
2220.64	22.2027
2224.27	18.3172
2227.9	19.0119
2231.53	18.7846
2235.16	13.0279
2238.78	27.6072
2242.4	15.3413
2246.02	28.095
2249.64	26.0146
2253.26	23.0149
2256.88	8.82233
2260.49	20.7485
2264.11	29.881
2267.72	24.0484
2271.33	18.2357
2274.93	18.0051
2278.54	22.4269
2282.15	22.0191
2285.75	24.4186
2289.35	29.6607
2292.95	15.9635
2296.55	19.2835
2300.15	15.9845
2303.74	32.5472
2307.34	37.7043
2310.93	75.0591
2314.52	319.025
2318.11	960.922
2321.7	735.356
2325.28	219.005
2328.87	47.7925
2332.45	36.5389
2336.03	24.34
2339.61	14.0328
2343.19	20.6564
2346.77	21.6025
2350.34	20.6551
2353.92	24.375
2357.49	15.0032
2361.06	26.1432
2364.63	11.2083
2368.2	24.1702
2371.76	16.7524
2375.33	15.8225
2378.89	15.8163
2382.45	25.9655
2386.01	16.7803
2389.57	18.6727
2393.13	8.66426
2396.68	7.89153
2400.23	20.0043
2403.79	11.1248
2407.34	15.1033
2410.88	9.97511
2414.43	7.63696
2417.98	16.3557
2421.52	10.3993
2425.06	15.5179
2428.61	17.0009
2432.14	7.42256
2435.68	9.88495
2439.22	17.0171
2442.75	-0.949722
2446.29	12.7323
2449.82	9.66539
2453.35	12.2373
2456.88	7.19606
2460.4	9.52223
2463.93	9.93655
2467.45	8.33713
2470.98	9.66551
2474.5	2.27208
2478.02	8.02444
2481.54	12.857
2485.05	-5.92136
2488.57	4.40263
2492.08	1.61391
2495.59	-4.98886
2499.1	-1.23824
2502.61	4.33466
2506.12	7.05144
2509.63	8.79045
2513.13	4.01292
2516.63	-2.5724
2520.13	7.5836
2523.63	-1.85022
2527.13	15.7069
2530.63	9.25171
2534.12	5.59357
2537.62	9.36679
2541.11	9.47784
2544.6	11.5076
2548.09	9.91803
2551.58	6.47935
2555.06	3.06781
2558.55	5.28743
2562.03	14.9304
2565.51	1.42896
2568.99	0.0306396
2572.47	11.7448
2575.95	-0.817413
2579.43	1.61229
2582.9	-2.5383
2586.37	5.57704
2589.84	7.06117
2593.31	-0.0924225
2596.78	7.92754
2600.25	4.57002
2603.71	-13.1745
2607.18	7.28481
2610.64	15.1896
2614.1	2.80206
2617.56	-5.68626
2621.02	6.89066
2624.47	13.6714
2627.93	-0.733871
2631.38	8.84946
2634.83	-0.810883
2638.28	-0.918518
2641.73	-2.9707
2645.18	4.50905
2648.62	1.45316
2652.07	10.7603
2655.51	8.57193
2658.95	4.45584
2662.39	16.4399
2665.83	4.72325
2669.27	7.19728
2672.7	2.12016
2676.14	5.53358
2679.57	-4.15817
2683	6.77762
2686.43	5.59244
2689.86	7.30423
2693.29	9.07719
2696.71	11.7353
2700.13	1.39555
2703.56	-3.34633
2706.98	18.8704
2710.4	7.72383
2713.82	2.18169
2717.23	4.10916
2720.65	2.33914
2724.06	0.583389
2727.47	4.43616
2730.88	5.50075
2734.29	10.2993
2737.7	1.98598
2741.11	11.4706
2744.51	14.3666
2747.91	15.359
2751.32	13.5317
2754.72	-0.5448
2758.11	6.99062
2761.51	11.7141
2764.91	16.3934
2768.3	23.8743
2771.7	20.9561
2775.09	16.1378
2778.48	16.9414
2781.87	20.542
2785.25	20.3585
2788.64	15.4634
2792.03	35.9457
2795.41	17.8763
2798.79	19.5461
2802.17	19.3037
2805.55	22.8107
2808.93	28.1794
2812.3	30.7186
2815.68	31.3707
2819.05	41.3531
2822.42	24.278
2825.79	23.1074
2829.16	32.2031
2832.53	33.8565
2835.89	35.5414
2839.26	36.3241
2842.62	41.7997
2845.98	43.5933
2849.34	46.388
2852.7	48.3089
2856.06	50.2021
2859.41	53.9944
2862.77	57.8199
2866.12	48.5389
2869.47	64.574
2872.82	72.1739
2876.17	67.5561
2879.52	70.4516
2882.87	76.1715
2886.21	74.3369
2889.55	78.1533
2892.89	81.0228
2896.23	82.8896
2899.57	74.3196
2902.91	78.9502
2906.25	76.9277
2909.58	78.6687
2912.91	99.3148
2916.25	91.557
2919.58	101.735
2922.91	89.1934
2926.23	102.165
2929.56	117.919
2932.88	101.516
2936.21	110.57
2939.53	113.951
2942.85	134.284
2946.17	119.759
2949.49	129.725
2952.8	146.245
2956.12	143.018
2959.43	133.272
2962.74	150.778
2966.06	152.336
2969.37	170.862
2972.67	162.261
2975.98	171.479
2979.28	178.892
2982.59	179.693
2985.89	195.532
2989.19	214.218
2992.49	207.568
2995.79	225.361
2999.09	242.25
3002.38	254.448
3005.68	248.779
3008.97	282.669
3012.26	273.298
3015.55	277.12
3018.84	294.133
3022.13	308.327
3025.41	326.313
3028.7	331.105
3031.98	340.618
3035.26	341.609
3038.54	352.041
3041.82	379.517
3045.1	412.708
3048.38	395.746
3051.65	419.505
3054.92	441.411
3058.2	453.832
3061.47	507.802
3064.73	498.324
3068	512.486
3071.27	563.563
3074.54	567.386
3077.8	595.738
3081.06	588.688
3084.32	650.637
3087.58	642.361
3090.84	689.398
3094.1	683.428
3097.35	743.725
3100.61	784.697
3103.86	795.022
3107.11	832.488
3110.36	860.348
3113.61	861.207
3116.86	908.816
3120.11	957.428
3123.35	996.538
3126.59	1010.88
3129.84	1027.08
3133.08	1097.65
3136.32	1071.92
3139.55	1192.93
3142.79	1218.61
3146.03	1256.68
3149.26	1290.1
3152.49	1385.56
3155.72	1390.36
3158.95	1413.33
3162.18	1480.15
3165.41	1529.82
3168.64	1580.3
3171.86	1599.15
3175.08	1679.01
3178.31	1718.61
3181.53	1757.22
3184.75	1820.67
3187.96	1812.34
3191.18	1863.06
3194.4	1881.34
3197.61	2003.42
3200.82	2007.28
3204.03	2037.89
3207.24	2048.57
3210.45	2086.94
3213.66	2172.08
3216.86	2196.48
3220.07	2254.18
3223.27	2232.99
3226.48	2268.18
3229.68	2276.78
3232.87	2335.09
3236.07	2334.18
3239.27	2390.98
3242.47	2415.58
3245.66	2406.05
3248.85	2442.25
3252.04	2405.34
3255.23	2517.29
3258.42	2463.25
3261.61	2522.42
3264.8	2516.29
3267.98	2561.36
3271.16	2609.98
3274.35	2566.7
3277.53	2653.35
3280.71	2705
3283.89	2676.81
3287.06	2723.17
3290.24	2682.41
3293.41	2761.11
3296.58	2765.31
3299.76	2789.47
3302.93	2808.72
3306.1	2841.41
3309.26	2895.67
3312.43	2924.65
3315.59	2969.53
3318.76	2982.96
3321.92	3038.89
3325.08	2974.49
3328.24	3114.61
3331.4	3146.77
3334.56	3161.17
3337.71	3188.11
3340.87	3220.01
3344.02	3264.16
3347.17	3349.64
3350.33	3312.56
3353.47	3380.96
3356.62	3431.88
3359.77	3472.6
3362.92	3600.55
3366.06	3602.26
3369.2	3665.5
3372.34	3727.98
3375.49	3729.63
3378.62	3739.95
3381.76	3738.23
3384.9	3807.18
3388.04	3841.58
3391.17	3848.6
3394.3	3870.75
3397.43	3937.98
3400.56	3982.15
3403.69	3994.5
3406.82	4079.48
3409.95	4065.03
3413.07	4101.92
3416.2	4066.35
3419.32	4128.63
3422.44	4069.49
3425.56	4103.88
3428.68	4147.05
3431.8	4090.36
3434.91	4105.39
3438.03	4097.34
3441.14	4058.36
3444.25	4103.35
3447.36	4022.42
3450.47	4029.2
3453.58	4022.93
3456.69	4031.84
3459.79	3974.45
3462.9	3913.27
3466	3936.53
3469.11	3887.08
3472.21	3790.37
3475.31	3792.72
3478.4	3667.51
3481.5	3638.21
3484.6	3626.99
3487.69	3502.71
3490.79	3475.37
3493.88	3431.2
3496.97	3285.06
3500.06	3295.28
3503.15	3232.13
3506.23	3162.72
3509.32	3083.12
3512.4	3024.17
3515.49	2945.93
3518.57	2868.54
3521.65	2872.31
3524.73	2790.94
3527.81	2686.17
3530.89	2593.06
3533.96	2568.31
3537.03	2541.21
3540.11	2478.35
3543.18	2341.37
3546.25	2297.1
3549.32	2289.74
3552.39	2248.66
3555.46	2135.37
3558.52	2059.29
3561.59	2007.8
3564.65	1971.88
3567.71	1909.05
3570.77	1824.13
3573.83	1794.1
3576.89	1751.83
3579.95	1701.81
3583	1638.36
3586.06	1584.22
3589.11	1528.2
3592.16	1453.01
3595.21	1487.78
3598.27	1420.03
3601.31	1394.97
3604.36	1320.53
3607.41	1286.73
3610.45	1254.85
3613.5	1192.69
3616.54	1165.49
3619.58	1116.68
3622.62	1083.08
3625.66	1053.33
3628.69	984.118
3631.73	960.122
3634.77	906.885
3637.8	877.505
3640.83	808.77
3643.86	771.203
3646.89	713.216
3649.92	706.69
3652.95	661.824
3655.98	611.017
3659	555.524
3662.02	508.331
3665.05	432.686
3668.07	443.36
3671.09	397.624
3674.11	333.004
3677.13	341.969
3680.14	292.42
3683.16	307.049
3686.17	282.93
3689.19	233.25
3692.2	233.702
3695.21	187.741
3698.22	166.291
3701.23	166.715
3704.23	147.207
3707.24	140.971
3710.24	131.838
3713.25	126.48
3716.25	111.564
3719.25	107.13
3722.25	72.1968
3725.25	85.7857
3728.25	80.3118
3731.24	83.3922
3734.24	66.4514
3737.23	62.8184
3740.22	59.1689
3743.21	57.3979
3746.21	51.8069
3749.19	46.2009
3752.18	39.6361
3755.17	31.1786
3758.15	34.1253
3761.14	24.7381
3764.12	28.6134
3767.1	30.5951
3770.08	25.0204
3773.06	27.9836
3776.04	20.5613
3779.02	23.552
3781.99	13.33
3784.97	19.1716
3787.94	18.4131
3790.91	4.45219
3793.88	14.1193
3796.85	21.9148
3799.82	8.01137
3802.79	10.1796
3805.76	13.3034
3808.72	18.3244
3811.69	3.51385
3814.65	7.60672
3817.61	3.19456
3820.57	10.1427
3823.53	13.3148
3826.49	6.08281
3829.45	6.42897
3832.4	0.134125
3835.36	-2.35565
3838.31	16.0567
3841.26	5.98067
3844.21	4.44968
3847.16	17.1992
3850.11	10.9222
3853.06	14.1803
3856	14.5849
3858.95	2.57536
3861.89	4.88739
3864.84	13.8907
3867.78	0.884888
3870.72	12.7616
3873.66	21.774
3876.6	5.84021
3879.53	4.27144
3882.47	21.8985
3885.4	9.72623
3888.34	12.9144
3891.27	14.1744
3894.2	13.5044
3897.13	19.545
3900.06	14.9863
3902.99	12.3488
3905.91	19.3015
3908.84	11.8576
3911.76	17.8547
3914.69	9.42195
3917.61	19.2277
3920.53	11.7804
3923.45	24.4606
3926.37	20.8006
3929.28	7.54053
3932.2	25.9063
3935.11	17.4781
3938.03	11.9624
3940.94	14.1422
3943.85	6.72963
3946.76	17.5173
3949.67	22.5773
3952.58	19.991
3955.49	19.3256
3958.39	16.7596
3961.3	12.2835
3964.2	21.2319
3967.1	11.0172
3970	19.0301
3972.9	18.417
3975.8	17.7995
3978.7	22.9344
3981.6	14.6062
3984.49	24.5351
3987.39	25.8058
3990.28	19.3788
3993.17	13.8865
3996.06	18.0464
3998.95	18.3543
4001.84	21.5593
4004.73	3.57924
4007.61	12.5713
4010.5	24.4641
4013.38	33.4703
4016.27	16.4385
4019.15	16.7635
4022.03	19.9834
4024.91	16.4447
4027.79	19.6702
4030.66	16.1312
4033.54	22.2643
4036.42	16.7927
4039.29	8.41827
4042.16	21.3396
4045.03	26.4908
4047.9	19.0527
4050.77	14.5257
4053.64	19.7026
4056.51	23.9284
4059.38	22.3269
4062.24	5.1705
4065.1	19.1029
4067.97	16.5138
4070.83	12.9459
4073.69	19.1075
4076.55	19.427
4079.41	7.07736
4082.26	7.3876
4085.12	-2.05406
4087.97	8.97653
4090.83	15.1338
4093.68	4.70654
4096.53	10.8654
4099.38	1.39906
4102.23	6.58606
4105.08	3.94696
4107.93	7.15874
4110.77	11.3498
4113.62	9.65431
4116.46	6.96317
4119.3	15.0167
4122.14	6.4323
4124.98	14.5
4127.82	3.97768
4130.66	6.21176
4133.5	4.55133
4136.33	2.92783
4139.17	5.06894
4142	16.8608
4144.83	7.27475
4147.67	7.54576
4150.5	7.82686
4153.33	4.16103
4156.15	11.2159
4158.98	-0.388428
4161.81	17.4045
4164.63	14.672
4167.45	10.9592
4170.28	-2.5274
4173.1	-0.359192
4175.92	-6.98972
4178.74	9.8493
4181.56	9.09515
4184.37	2.47629
4187.19	-0.225235
4190	-0.968224
4192.82	11.0305
4195.63	8.36429
4198.44	9.63254
4201.25	12.8587
4204.06	7.2628
4206.87	19.3233
4209.68	-5.92461
4212.48	4.17184
4215.29	5.42698
4218.1	13.6462
4220.9	17.9401
4223.7	7.42946
4226.5	10.7027
4229.3	5.106
4232.1	3.46025
4234.9	13.7112
4237.69	10.1095
4240.49	9.47948
4243.28	5.86623
4246.07	9.21995
4248.87	2.60278
4251.66	11.9285
4254.45	12.2743
4257.24	-0.40181
4260.03	13.9377
4262.81	2.23795
4265.6	15.6166
4268.38	1.89114
4271.17	9.26719
4273.95	1.538
4276.73	10.9165
4279.51	-2.93271
4282.29	5.41591
4285.07	13.7621
4287.84	5.91123
4290.62	19.2936
4293.39	-1.75087
4296.17	9.62081
4298.94	0.739731
4301.71	6.03738
4304.48	-1.85664
4307.25	4.45486
4310.02	0.61779
4312.79	7.96888
4315.55	8.18836
4318.32	2.28825
4321.08	-4.64413
4323.85	12.8432
4326.61	7.92706
4329.37	12.1782
4332.13	15.3978
4334.89	2.32201
4337.65	5.53346
4340.4	1.6319
4343.16	-2.27028
4345.91	-0.0461502
4348.67	13.4131
4351.42	10.5528
4354.17	7.72048
4356.92	0.783646
4359.67	4.06327
4362.42	11.4326
4365.17	10.6281
4367.91	1.6142
4370.66	1.82665
4373.4	11.2521
4376.14	17.6014
4378.89	-2.75391
4381.63	-0.530647
4384.37	10.9496
4387.11	1.90179
4389.84	13.4717
4392.58	14.7836
4395.32	0.7052
4398.05	10.2877
4400.78	17.8074
4403.52	-0.58065
4406.25	11.0854
4408.98	10.3166
4411.71	7.45068
4414.44	11.8469
4417.16	5.82316
4419.89	4.95425
4422.62	6.18808
4425.34	4.29964
4428.06	2.40844
4430.78	-0.5326
4433.51	5.93582
4436.22	2.98275
4438.94	6.30509
4441.66	10.6666
4444.38	8.74075
4447.1	0.508705
4449.81	4.86546
4452.52	5.01392
4455.24	11.4633
4457.95	3.19064
4460.66	10.6759
4463.37	1.35377
4466.08	3.59458
4468.78	10.0522
4471.49	-1.37899
4474.2	15.6309
4476.9	7.37253
4479.6	4.38618
4482.31	4.56882
4485.01	16.3729
4487.71	0.69429
4490.41	13.5544
4493.11	14.7552
4495.8	1.10858
4498.5	5.48079
4501.19	18.3264
4503.89	3.61149
4506.58	7.98218
4509.27	3.8745
4511.96	6.1296
4514.66	2.01926
4517.34	4.28036
4520.03	-7.26715
4522.72	2.44949
4525.41	-1.65388
4528.09	7.00951
4530.77	12.4912
4533.46	5.19029
4536.14	5.35033
4538.82	12.9858
4541.5	3.5477
4544.18	5.85299
4546.86	0.675522
4549.53	5.12855
4552.21	4.23913
4554.88	6.5881
4557.56	-2.86189
4560.23	10.294
4562.9	8.42146
4565.57	7.65668
4568.24	2.59509
4570.91	7.20992
4573.58	-3.49413
4576.24	4.19272
4578.91	8.685
4581.58	5.61955
4584.24	3.66753
4586.9	-1.6297
4589.56	10.5065
4592.22	5.18691
4594.88	9.69154
4597.54	-1.07482
4600.2	9.99326
4602.86	1.40717
4605.51	3.7652
4608.17	9.41608
4610.82	10.6912
4613.47	8.66938
4616.13	13.2361
4618.78	3.51567
4621.43	2.59262
4624.07	3.86781
4626.72	-1.48319
4629.37	-1.32874
4632.01	6.55769
4634.66	4.48653
4637.3	3.51009
4639.94	3.63835
4642.59	8.19674
4645.23	6.1374
4647.87	8.54299
4650.5	5.42718
4653.14	10.1335
4655.78	9.24861
4658.42	3.75327
4661.05	13.9594
4663.68	4.10409
4666.31	0.923248
4668.95	3.30114
4671.58	11.2919
4674.21	6.96597
4676.84	9.3606
4679.46	14.0009
4682.09	9.6593
4684.72	-0.308403
4687.34	6.58081
4689.97	2.22512
4692.59	3.49782
4695.21	5.88896
4697.83	6.02518
4700.45	9.55025
4703.07	2.91137
4705.69	7.55476
4708.3	0.89241
4710.92	10.0567
4713.54	11.3052
4716.15	3.49156
4718.76	8.12552
4721.37	4.82777
4723.99	7.18767
4726.59	0.493225
4729.2	2.8762
4731.81	6.39741
4734.42	7.65102
4737.03	6.6291
4739.63	12.4188
4742.23	13.6609
4744.84	-1.03294
4747.44	12.7046
4750.04	3.66883
4752.64	4.87714
4755.24	0.392937
4757.84	3.87385
4760.44	9.64275
4763.03	10.868
4765.63	-4.9867
4768.22	13.3581
4770.82	10.0704
4773.41	5.61107
4776	4.5739
4778.59	4.67843
4781.18	-5.50111
4783.77	2.5979
4786.36	3.84448
4788.94	8.524
4791.53	10.9226
4794.11	4.16695
4796.7	1.98996
4799.28	6.70081
4801.86	7.98293
4804.44	11.5724
4807.02	4.83646
4809.6	6.15135
4812.18	8.61803
4814.76	4.17693
4817.33	2.04112
4819.91	10.3122
4822.48	16.2875
4825.06	3.7377
4827.63	6.23746
4830.2	-0.551109
4832.77	5.45019
4835.34	6.81041
4837.91	4.68762
4840.48	7.24182
4843.04	16.8229
4845.61	8.82726
4848.17	5.491
4850.74	11.514
4853.3	9.24007
4855.86	4.61649
4858.42	18.9401
4860.98	6.1753
4863.54	13.4163
4866.1	2.90478
4868.66	8.93207
4871.21	5.52968
4873.77	2.09256
4876.32	4.56314
4878.88	11.7815
4881.43	11.8776
4883.98	8.40079
4886.53	4.91702
4889.08	4.9979
4891.63	9.83865
4894.18	2.77055
4896.72	9.98672
4899.27	4.092
4901.81	-4.19776
4904.36	-0.567543
4906.9	-1.71403
4909.44	-5.25753
4911.98	1.92434
4914.52	5.51305
4917.06	-1.66138
4919.6	-0.46637
4922.14	1.92178
4924.67	10.2834
4927.21	0.726059
4929.74	4.29845
4932.28	5.50481
4934.81	1.94675
4937.34	7.94545
4939.87	9.1548
4942.4	9.11702
4944.93	10.3096
4947.46	1.93757
4949.99	3.13969
4952.51	1.94989
4955.04	-0.455978
4957.56	-0.449844
4960.08	-0.437592
4962.61	5.59095
4965.13	-0.37603
4967.65	0.888817
4970.17	0.918747
4972.69	5.76577
4975.2	0.95034
4977.72	4.58353
4980.24	2.17339
4982.75	3.38994
4985.27	4.60818
4987.78	-1.45424
4990.29	-3.88646
4992.8	4.61143
4995.31	3.38125
4997.82	3.37975