File: Data/3-Raman/processed/bu19w-e-ff11b-fi06-l_150 (500nm)_532nm_edge_100%_x100_vis_h50um_30sx2_01_0.txt
#Acq. time (s)=	30
#Accumulations=	2
#Range (cm-¹)=	100...5000
#Windows=	1
#Auto scanning=	Off
#Autofocus=	Off
#Macrospot=	Off
#AutoExposure=	Off
#Spike filter=	Multiple accum.
#Delay time (s)=	2
#Binning=	1
#Readout mode=	Signal
#DeNoise=	Off
#ICS correction=	On
#Dark correction=	Off
#Inst. Process=	Off
#Detector Gain=	Best Dynamic
#Detector ADC=	50 kHz HS
#Detector temperature (°C)=	-60.09
#Instrument=	LabRAM HR Evol
#Detector=	SIN-EM FIVIS
#Objective=	x100_VIS
#Grating=	150 (500nm)
#ND Filter=	100%
#Laser=	532nm_Edge
#Hole=	49.98
#Temperature=	0
#Range=	Visible
#StageXY=	75x50mm Scan+
#StageZ=	Z motor
#X (µm)=	0
#Y (µm)=	0
#Z (µm)=	-245.5
#Full time(mm:ss)=	1:05
#Project=	21_11_04
#Sample=	BU19w
#Site=
#Title=	BU19w-E-FF11b-FI06-L_150 (500nm)_532nm_Edge_100%_x100_VIS_H50um_30sX2
#Remark=
#Date=	04.11.2021 18:16
#Acquired=	04.11.2021 18:16:11
#Base:Fit=	16.12.2021 17:39:50
#Base:Sub=	16.12.2021 17:47:23
101.869	7507.33
106.493	7665.94
111.113	9299.21
115.732	14401.1
120.349	19129.8
124.964	15474.2
129.577	9361.19
134.185	7334.7
138.793	6742.78
143.399	6298.51
148.003	5852.57
152.602	5623.76
157.201	5644.34
161.798	5942.73
166.392	6391.9
170.982	7220.56
175.572	8596.69
180.16	11150.2
184.745	14906.4
189.326	20418
193.907	25081.1
198.486	26831.6
203.06	24289.9
207.634	19027.2
212.206	13938.8
216.776	9977.17
221.341	7369.43
225.906	5681.75
230.469	4528.26
235.028	3648.33
239.586	3170.14
244.142	2936.38
248.694	3254.45
253.246	4732.82
257.795	5022.75
262.341	3044.4
266.886	1453.06
271.428	886.951
275.967	624.505
280.505	443.455
285.041	330.707
289.573	229.505
294.105	121.31
298.632	76.8068
303.159	0
307.685	18.0769
312.205	1.1283
316.726	-18.6829
321.242	-42.9963
325.758	-53.1042
330.272	-38.8138
334.782	30.0005
339.292	805.566
343.797	2834.65
348.302	3087.01
352.803	1436.43
357.304	461.132
361.802	200.974
366.297	135.193
370.791	54.4888
375.281	98.7821
379.77	287.136
384.256	705.46
388.741	1117.81
393.223	1318.51
397.704	1072.92
402.18	560.63
406.657	298.362
411.13	356.012
415.602	448.6
420.07	637.839
424.538	865.335
429.002	1300.2
433.465	2109.7
437.925	4067.17
442.384	8277.71
446.839	19293.8
451.294	36598.3
455.745	36635.9
460.196	36702.4
464.642	33998.3
469.089	15610.4
473.531	8704.68
477.971	5915.32
482.411	4240.08
486.846	3104.86
491.282	2427.28
495.713	2168.45
500.144	2010.85
504.572	1797.14
508.997	1507.63
513.421	1274.94
517.842	1048.35
522.263	904.711
526.679	790.779
531.093	617.106
535.507	552.597
539.917	465.001
544.327	392.351
548.733	322.048
553.137	235.304
557.54	204.588
561.94	198.459
566.337	196.538
570.734	139.981
575.127	174.234
579.518	191.991
583.909	189.256
588.295	184.353
592.68	150.347
597.064	118.419
601.445	44.4718
605.823	70.097
610.201	38.8195
614.575	10.3842
618.947	49.8086
623.317	12.0908
627.686	25.7526
632.052	2.82776
636.415	40.8856
640.777	21.2499
645.138	-32.9855
649.495	-27.0846
653.85	-47.9969
658.205	-56.2264
662.556	-52.3801
666.905	-64.767
671.252	15.5018
675.597	35.2092
679.941	150.352
684.282	341.854
688.62	548.653
692.957	494.539
697.293	261.214
701.625	94.5333
705.955	24.3525
710.283	7.6109
714.609	-3.90808
718.933	-25.3775
723.257	-16.2275
727.577	-12.67
731.894	-22.3114
736.21	-51.2703
740.524	-70.6755
744.835	-39.5547
749.147	-64.6857
753.454	-18.6166
757.759	14.6057
762.063	27.5884
766.364	72.0793
770.663	104.872
774.96	179.142
779.257	277.336
783.55	582.276
787.841	1057.38
792.13	1405.17
796.417	2058.81
800.702	2398.19
804.985	1563.93
809.266	748.645
813.545	413.014
817.821	255.642
822.096	230.112
826.371	208.104
830.641	186.095
834.91	156.3
839.176	186.982
843.441	184.429
847.703	158.333
851.964	149.251
856.222	196.346
860.479	266.457
864.733	449.666
868.986	533.122
873.236	398.587
877.485	272.866
881.731	200.963
885.975	183.561
890.218	159.206
894.458	124.745
898.696	94.8917
902.933	80.9848
907.167	123.545
911.399	134.55
915.63	123.302
919.858	111.856
924.084	62.4795
928.308	63.2729
932.531	41.2736
936.749	47.1144
940.967	23.7826
945.184	42.1033
949.398	13.3017
953.61	20.9478
957.821	9.42334
962.029	-13.7451
966.236	0.31488
970.44	2.68115
974.642	-23.5228
978.843	-3.07535
983.041	-22.8467
987.236	-39.4931
991.43	-31.8355
995.623	-22.8504
999.813	-29.5044
1004	-23.42
1008.19	-16.2739
1012.37	-13.4111
1016.55	-12.8873
1020.73	-7.11328
1024.91	3.8494
1029.09	24.1749
1033.27	38.9885
1037.44	63.9068
1041.61	67.0439
1045.78	97.7898
1049.94	165.386
1054.11	336.445
1058.27	557.254
1062.43	694.349
1066.59	889.189
1070.75	1359.53
1074.9	1532.92
1079.05	980.987
1083.2	463.367
1087.35	244.289
1091.5	167.042
1095.65	115.093
1099.79	111.804
1103.93	92.1656
1108.07	75.7903
1112.21	69.8852
1116.34	61.9476
1120.48	77.9916
1124.61	79.168
1128.74	98.8188
1132.86	111.464
1136.99	176.264
1141.11	247.299
1145.23	458.576
1149.35	809.379
1153.47	1050.96
1157.59	928.983
1161.7	483.531
1165.82	232.736
1169.92	132.493
1174.03	115.659
1178.14	92.5406
1182.24	97.1864
1186.35	88.3146
1190.45	96.6316
1194.55	100.663
1198.64	110.639
1202.74	114.303
1206.83	116.86
1210.92	158.886
1215.01	202.695
1219.1	276.504
1223.18	307.779
1227.27	280.823
1231.35	243.145
1235.43	220.894
1239.5	183.003
1243.58	170.963
1247.65	175.014
1251.72	180.272
1255.8	203.572
1259.86	211.94
1263.93	264.354
1267.99	235.821
1272.06	219.295
1276.12	172.589
1280.18	158.868
1284.23	140.997
1288.29	132.031
1292.34	113.915
1296.39	97.6938
1300.44	82.4008
1304.49	82.1199
1308.53	92.8626
1312.58	91.448
1316.62	88.8773
1320.66	79.15
1324.7	79.3693
1328.73	96.5757
1332.77	103.662
1336.8	80.517
1340.83	114.399
1344.86	108.147
1348.88	111.85
1352.91	120.499
1356.93	146.986
1360.95	228.858
1364.97	299.589
1368.99	569.822
1373.01	762.442
1377.02	673.735
1381.03	425.744
1385.04	255.16
1389.05	177.325
1393.06	151.748
1397.06	125.303
1401.06	99.7923
1405.06	88.9966
1409.06	80.1719
1413.06	81.2044
1417.05	80.2476
1421.05	85.1851
1425.04	91.0589
1429.03	90.851
1433.01	87.6594
1437	96.3077
1440.99	91.1058
1444.97	91.7754
1448.95	96.3468
1452.93	100.855
1456.9	85.5865
1460.88	78.1573
1464.85	80.4807
1468.82	82.757
1472.79	78.1747
1476.76	77.4836
1480.73	80.6589
1484.69	52.4783
1488.65	71.2493
1492.61	82.1638
1496.57	66.7279
1500.53	79.5737
1504.48	82.6986
1508.43	77.1297
1512.39	81.2951
1516.33	91.2791
1520.28	88.6565
1524.23	95.7429
1528.17	96.0457
1532.11	94.4321
1536.05	100.572
1539.99	113.49
1543.93	116.707
1547.86	132.508
1551.8	138.608
1555.73	146.598
1559.66	163.236
1563.58	170.133
1567.51	176.012
1571.44	217.604
1575.36	198.28
1579.28	220.458
1583.2	231.976
1587.11	238.621
1591.03	245.234
1594.94	289.331
1598.85	292.984
1602.76	319.703
1606.67	330.139
1610.58	359.756
1614.48	359.655
1618.38	362.496
1622.29	387.332
1626.18	381.584
1630.08	396.97
1633.98	408.693
1637.87	425.199
1641.76	411.193
1645.65	404.972
1649.54	392.087
1653.43	372.495
1657.31	361.471
1661.2	346.561
1665.08	312.319
1668.96	288.564
1672.83	271.394
1676.71	236.877
1680.58	213.712
1684.46	188.54
1688.33	182.559
1692.2	156.404
1696.06	140.783
1699.93	123.243
1703.79	107.6
1707.66	89.097
1711.52	77.2597
1715.37	73.0504
1719.23	63.1938
1723.08	59.0469
1726.94	57.7247
1730.79	43.2132
1734.64	46.5962
1738.49	43.3946
1742.33	40.1798
1746.18	27.6772
1750.02	32.0708
1753.86	29.1063
1757.7	16.9836
1761.54	12.5836
1765.37	22.0181
1769.21	16.641
1773.04	12.2837
1776.87	17.2372
1780.7	8.28069
1784.53	-8.13437
1788.35	7.20523
1792.17	0.128845
1796	-1.33788
1799.82	6.58246
1803.64	-4.39641
1807.45	-5.06163
1811.27	-0.0877228
1815.08	-4.56805
1818.89	-0.628357
1822.7	-4.28238
1826.51	-1.36172
1830.32	-2.25804
1834.12	-4.13799
1837.92	4.31374
1841.72	2.37929
1845.52	4.16879
1849.32	4.09584
1853.12	-2.60173
1856.91	5.636
1860.7	1.66267
1864.5	-0.45163
1868.28	1.17548
1872.07	0.963577
1875.86	-1.06093
1879.64	8.94049
1883.42	6.99747
1887.21	-0.446899
1890.98	-1.25912
1894.76	12.6786
1898.54	4.5305
1902.31	2.89503
1906.08	8.66399
1909.85	11.6958
1913.62	6.49774
1917.39	6.84666
1921.16	10.0744
1924.92	2.22833
1928.68	10.1561
1932.44	16.2753
1936.2	27.0759
1939.96	8.97559
1943.71	18.8606
1947.47	13.798
1951.22	20.7742
1954.97	26.7526
1958.72	36.3988
1962.46	33.7646
1966.21	28.3037
1969.95	31.2436
1973.7	30.3527
1977.43	40.6696
1981.17	48.1222
1984.91	54.588
1988.65	43.2818
1992.38	52.4772
1996.11	53.2299
1999.84	47.4477
2003.57	50.0279
2007.3	60.9039
2011.02	61.5343
2014.75	50.213
2018.47	56.4758
2022.19	64.6775
2025.91	61.0856
2029.62	66.6888
2033.34	61.3834
2037.05	53.4396
2040.76	52.7912
2044.47	51.2181
2048.18	74.3651
2051.89	64.5976
2055.59	63.0877
2059.3	67.1772
2063	73.2626
2066.7	67.4735
2070.4	68.1338
2074.1	76.1835
2077.79	71.3335
2081.49	77.6001
2085.18	69.9429
2088.87	74.0994
2092.56	73.4688
2096.25	85.9639
2099.93	65.8999
2103.61	77.3644
2107.3	76.6996
2110.98	85.2976
2114.66	83.6563
2118.33	70.8388
2122.01	94.1684
2125.68	81.2148
2129.36	81.2302
2133.03	83.0712
2136.7	72.8786
2140.36	73.754
2144.03	58.9258
2147.7	76.3301
2151.36	71.6312
2155.02	60.5389
2158.68	57.7312
2162.34	47.6449
2165.99	54.9621
2169.65	55.0038
2173.3	63.3242
2176.95	44.377
2180.6	55.5033
2184.25	42.056
2187.9	58.6714
2191.54	45.3512
2195.18	36.6484
2198.83	41.6443
2202.47	35.726
2206.11	43.517
2209.74	37.646
2213.38	40.9385
2217.01	41.5005
2220.64	39.3118
2224.27	27.9272
2227.9	26.6278
2231.53	24.4009
2235.16	34.1931
2238.78	34.756
2242.4	31.6051
2246.02	38.6486
2249.64	28.0503
2253.26	33.269
2256.88	27.3223
2260.49	33.5024
2264.11	32.1897
2267.72	29.9451
2271.33	28.6688
2274.93	19.815
2278.54	25.0243
2282.15	15.042
2285.75	25.8004
2289.35	26.1815
2292.95	18.9706
2296.55	20.2679
2300.15	26.3062
2303.74	33.2715
2307.34	24.0909
2310.93	22.4625
2314.52	40.7135
2318.11	30.4959
2321.7	38.2446
2325.28	43.9863
2328.87	26.0474
2332.45	22.2971
2336.03	19.474
2339.61	27.9351
2343.19	29.7694
2346.77	22.1907
2350.34	18.3706
2353.92	20.1644
2357.49	21.0064
2361.06	22.7639
2364.63	22.6496
2368.2	24.3983
2371.76	15.9882
2375.33	21.4657
2378.89	8.46431
2382.45	13.9493
2386.01	22.1895
2389.57	12.0541
2393.13	14.8183
2396.68	23.1189
2400.23	17.7117
2403.79	11.4676
2407.34	11.661
2410.88	10.9881
2414.43	16.7764
2417.98	15.2547
2421.52	19.2713
2425.06	10.429
2428.61	11.7441
2432.14	17.7133
2435.68	13.5401
2439.22	16.7918
2442.75	8.89182
2446.29	5.62068
2449.82	11.7122
2453.35	0.966843
2456.88	13.5975
2460.4	12.0149
2463.93	15.1135
2467.45	6.78505
2470.98	4.19096
2474.5	12.7316
2478.02	10.828
2481.54	11.7798
2485.05	9.85272
2488.57	14.4229
2492.08	7.76721
2495.59	6.69379
2499.1	-1.8452
2502.61	10.1857
2506.12	0.664337
2509.63	13.5177
2513.13	5.85469
2516.63	-1.75418
2520.13	4.5936
2523.63	2.48924
2527.13	8.84106
2530.63	-1.41544
2534.12	12.359
2537.62	-0.603775
2541.11	5.83926
2544.6	4.96021
2548.09	3.21582
2551.58	14.4091
2555.06	6.22246
2558.55	2.7178
2562.03	18.6845
2565.51	2.22151
2568.99	7.16373
2572.47	0.013092
2575.95	4.09029
2579.43	4.45337
2582.9	1.05116
2586.37	3.29897
2589.84	-1.11433
2593.31	3.88138
2596.78	0.290848
2600.25	-4.2337
2603.71	-4.00464
2607.18	4.77998
2610.64	-0.92598
2614.1	-0.989304
2617.56	9.57072
2621.02	-9.71671
2624.47	-4.05126
2627.93	0.611069
2631.38	7.16449
2634.83	-0.721161
2638.28	11.4918
2641.73	4.49803
2645.18	-2.51228
2648.62	8.62625
2652.07	1.58177
2655.51	11.6467
2658.95	-2.09937
2662.39	2.19196
2665.83	-2.06113
2669.27	3.12601
2672.7	8.27229
2676.14	3.09117
2679.57	6.37376
2683	2.19209
2686.43	-8.46792
2689.86	5.21404
2693.29	2.15924
2696.71	2.793
2700.13	7.1763
2703.56	7.83919
2706.98	-6.38652
2710.4	6.45493
2713.82	6.3047
2717.23	1.52275
2720.65	1.41629
2724.06	7.8549
2727.47	1.23953
2730.88	0.225403
2734.29	8.55722
2737.7	12.2182
2741.11	3.68303
2744.51	-4.90038
2747.91	0.571548
2751.32	6.04977
2754.72	10.5806
2758.11	8.50204
2761.51	10.1931
2764.91	10.8975
2768.3	9.69115
2771.7	4.68436
2775.09	18.5075
2778.48	11.5703
2781.87	4.61195
2785.25	23.9941
2788.64	4.78285
2792.03	2.50461
2795.41	17.1274
2798.79	17.6495
2802.17	19.0754
2805.55	19.5597
2808.93	20.0358
2812.3	19.5615
2815.68	20.0099
2819.05	17.6446
2822.42	27.438
2825.79	23.2471
2829.16	33.9854
2832.53	23.3005
2835.89	35.0089
2839.26	42.0835
2842.62	36.1495
2845.98	31.1842
2849.34	43.9923
2852.7	35.4036
2856.06	47.324
2859.41	44.3266
2862.77	37.6011
2866.12	46.7994
2869.47	50.3897
2872.82	49.2751
2876.17	57.553
2879.52	63.9575
2882.87	65.6549
2886.21	56.0179
2889.55	71.8416
2892.89	63.1194
2896.23	79.8515
2899.57	75.7589
2902.91	77.301
2906.25	93.0044
2909.58	90.7091
2912.91	92.1761
2916.25	91.7341
2919.58	112.063
2922.91	103.991
2926.23	114.809
2929.56	113.288
2932.88	123.071
2936.21	112.974
2939.53	131.177
2942.85	137.101
2946.17	120.427
2949.49	148.001
2952.8	148.26
2956.12	151.34
2959.43	166.669
2962.74	167
2966.06	179.537
2969.37	177.157
2972.67	185.17
2975.98	172.545
2979.28	203.147
2982.59	208.372
2985.89	224.885
2989.19	227.345
2992.49	240.15
2995.79	262.381
2999.09	259.273
3002.38	273.085
3005.68	278.438
3008.97	265.008
3012.26	327.866
3015.55	315.426
3018.84	343.499
3022.13	366.876
3025.41	370.46
3028.7	366.501
3031.98	403.156
3035.26	437.929
3038.54	416.918
3041.82	466.852
3045.1	461.942
3048.38	479.765
3051.65	496.653
3054.92	540.123
3058.2	529.549
3061.47	567.121
3064.73	605.771
3068	628.21
3071.27	660.023
3074.54	704.22
3077.8	702.909
3081.06	714.498
3084.32	772.453
3087.58	798.134
3090.84	827.928
3094.1	861.766
3097.35	896.982
3100.61	944.372
3103.86	981.993
3107.11	999.306
3110.36	1052.66
3113.61	1117.03
3116.86	1126.31
3120.11	1218.49
3123.35	1246.9
3126.59	1254.33
3129.84	1344.61
3133.08	1349.19
3136.32	1420.44
3139.55	1500.21
3142.79	1581.87
3146.03	1620.65
3149.26	1644.3
3152.49	1716.64
3155.72	1768.89
3158.95	1847.93
3162.18	1913.56
3165.41	1960.14
3168.64	2031.35
3171.86	2090.93
3175.08	2202.91
3178.31	2236.41
3181.53	2332.82
3184.75	2339.63
3187.96	2446.24
3191.18	2528.88
3194.4	2607.67
3197.61	2632.06
3200.82	2678.26
3204.03	2778.83
3207.24	2860.41
3210.45	2887.85
3213.66	2996.36
3216.86	3067.03
3220.07	3099.64
3223.27	3147.57
3226.48	3264.35
3229.68	3262.29
3232.87	3315.73
3236.07	3409.78
3239.27	3378.11
3242.47	3482.79
3245.66	3537.27
3248.85	3509.83
3252.04	3525.65
3255.23	3618.89
3258.42	3682.59
3261.61	3734.34
3264.8	3819
3267.98	3829.55
3271.16	3845.43
3274.35	3860.08
3277.53	3899.57
3280.71	3986.9
3283.89	4017.97
3287.06	4104.49
3290.24	4121.84
3293.41	4145.29
3296.58	4202.85
3299.76	4259.37
3302.93	4263.75
3306.1	4407.73
3309.26	4468.41
3312.43	4465.53
3315.59	4566.8
3318.76	4677.29
3321.92	4687.87
3325.08	4778.98
3328.24	4852
3331.4	4882.44
3334.56	4959.49
3337.71	5032.15
3340.87	5167.42
3344.02	5156.42
3347.17	5320.19
3350.33	5397.72
3353.47	5510.92
3356.62	5577.68
3359.77	5658.85
3362.92	5695.54
3366.06	5862.52
3369.2	5882.77
3372.34	5985.35
3375.49	6133.14
3378.62	6179.34
3381.76	6256.21
3384.9	6328.05
3388.04	6417.6
3391.17	6542.33
3394.3	6548.78
3397.43	6665.68
3400.56	6791.58
3403.69	6744.67
3406.82	6868.37
3409.95	6909.07
3413.07	7021.19
3416.2	7071.66
3419.32	7037.83
3422.44	7129.28
3425.56	7108.57
3428.68	7137.11
3431.8	7142.7
3434.91	7029.41
3438.03	7168.17
3441.14	7213.35
3444.25	7234.63
3447.36	7145.51
3450.47	7141.21
3453.58	7090.97
3456.69	7025.46
3459.79	7037.91
3462.9	6918.06
3466	6911.09
3469.11	6909.83
3472.21	6823.54
3475.31	6683.88
3478.4	6639.46
3481.5	6574.64
3484.6	6483.61
3487.69	6367.67
3490.79	6269.75
3493.88	6157.79
3496.97	5961.74
3500.06	5856.78
3503.15	5757.85
3506.23	5591.9
3509.32	5561.92
3512.4	5391.67
3515.49	5253.37
3518.57	5095.41
3521.65	5010.02
3524.73	4914.65
3527.81	4760.79
3530.89	4668.44
3533.96	4555.31
3537.03	4386.87
3540.11	4274.35
3543.18	4204.8
3546.25	4009.36
3549.32	3963.62
3552.39	3782.51
3555.46	3737.9
3558.52	3593.62
3561.59	3506.11
3564.65	3323.89
3567.71	3299.21
3570.77	3193.25
3573.83	3077.92
3576.89	2985.49
3579.95	2861.47
3583	2790.32
3586.06	2698.02
3589.11	2623.76
3592.16	2546.31
3595.21	2458.41
3598.27	2390.21
3601.31	2295.56
3604.36	2263.19
3607.41	2121.85
3610.45	2045.91
3613.5	1965.2
3616.54	1944
3619.58	1802.12
3622.62	1732.19
3625.66	1695.4
3628.69	1619.2
3631.73	1560.88
3634.77	1488.37
3637.8	1396.6
3640.83	1316.41
3643.86	1257.1
3646.89	1176.59
3649.92	1064.57
3652.95	1044.19
3655.98	934.466
3659	886.829
3662.02	827.7
3665.05	748.521
3668.07	717.773
3671.09	650.47
3674.11	600.127
3677.13	546.004
3680.14	482.425
3683.16	442.354
3686.17	401.302
3689.19	361.17
3692.2	339.944
3695.21	294.074
3698.22	287.849
3701.23	273.203
3704.23	245.25
3707.24	192.564
3710.24	186.336
3713.25	177.222
3716.25	169
3719.25	155.098
3722.25	129.717
3725.25	128.101
3728.25	115.029
3731.24	108.601
3734.24	99.2867
3737.23	82.3244
3740.22	85.3371
3743.21	71.1853
3746.21	55.1225
3749.19	57.1135
3752.18	61.934
3755.17	50.6069
3758.15	32.6638
3761.14	30.8609
3764.12	36.6217
3767.1	13.9772
3770.08	38.6976
3773.06	32.2068
3776.04	9.6745
3779.02	33.4802
3781.99	7.22394
3784.97	11.2091
3787.94	18.0406
3790.91	10.7269
3793.88	8.17441
3796.85	13.1948
3799.82	13.5116
3802.79	1.58902
3805.76	-2.77003
3808.72	-2.39935
3811.69	0.82338
3814.65	2.1656
3817.61	-2.15881
3820.57	4.88094
3823.53	-3.21471
3826.49	0.0678406
3829.45	3.35959
3832.4	5.70575
3835.36	1.43456
3838.31	3.8201
3841.26	-4.24435
3844.21	-12.3207
3847.16	-2.31609
3850.11	3.90355
3853.06	-5.1078
3856	-8.40271
3858.95	-3.10292
3861.89	1.25517
3864.84	-2.04561
3867.78	-7.26453
3870.72	-7.71587
3873.66	3.33652
3876.6	-4.79605
3879.53	3.36377
3882.47	-0.0163422
3885.4	0.421204
3888.34	0.844681
3891.27	3.18462
3894.2	-0.251877
3897.13	-1.79001
3900.06	10.1118
3902.99	5.66342
3905.91	9.83984
3908.84	3.4722
3911.76	11.5039
3914.69	10.8668
3917.61	3.49001
3920.53	-2.87813
3923.45	6.07602
3926.37	15.0004
3929.28	6.63837
3932.2	19.3544
3935.11	3.37813
3938.03	13.3087
3940.94	6.04591
3943.85	21.7425
3946.76	13.5142
3949.67	17.7554
3952.58	13.3968
3955.49	6.17271
3958.39	22.9141
3961.3	15.7199
3964.2	17.159
3967.1	4.22749
3970	29.6714
3972.9	24.4316
3975.8	23.024
3978.7	14.8764
3981.6	17.2798
3984.49	6.22333
3987.39	18.2284
3990.28	10.9993
3993.17	18.1671
3996.06	22.494
3998.95	10.4564
4001.84	9.97621
4004.73	22.0188
4007.61	16.7384
4010.5	9.52905
4013.38	10.0249
4016.27	23.0635
4019.15	21.6369
4022.03	21.173
4024.91	16.8457
4027.79	7.68846
4030.66	11.0899
4033.54	20.3027
4036.42	15.0117
4039.29	9.72441
4042.16	23.7985
4045.03	4.90637
4047.9	9.26955
4050.77	14.6158
4053.64	6.39627
4056.51	16.6264
4059.38	6.46846
4062.24	18.6379
4065.1	-1.2592
4067.97	5.08116
4070.83	13.3701
4073.69	9.00964
4076.55	7.56215
4079.41	6.1102
4082.26	6.60521
4085.12	14.9023
4087.97	5.63611
4090.83	12.9516
4093.68	1.73331
4096.53	4.16762
4099.38	18.3371
4102.23	2.20821
4105.08	1.70694
4107.93	9.01041
4110.77	8.48851
4113.62	0.11702
4116.46	1.51152
4119.3	-11.7991
4122.14	-1.62215
4124.98	3.67961
4127.82	3.11464
4130.66	2.59169
4133.5	3.07433
4136.33	-0.314682
4139.17	0.0234985
4142	12.9223
4144.83	2.51944
4147.67	18.6275
4150.5	-1.46733
4153.33	5.81125
4156.15	2.25613
4158.98	-1.36806
4161.81	9.73322
4164.63	8.14133
4167.45	3.61201
4170.28	2.02361
4173.1	-0.534714
4175.92	7.66766
4178.74	10.0011
4181.56	8.43462
4184.37	3.93829
4187.19	4.33954
4190	-1.12694
4192.82	5.17093
4195.63	3.65666
4198.44	2.16162
4201.25	8.50252
4204.06	-8.69038
4206.87	4.51884
4209.68	3.99304
4212.48	2.47649
4215.29	2.92067
4218.1	8.37358
4220.9	2.01015
4223.7	3.50566
4226.5	3.00592
4229.3	8.45657
4232.1	-0.916672
4234.9	5.55345
4237.69	2.12918
4240.49	13.5939
4243.28	0.229111
4246.07	4.75897
4248.87	4.30424
4251.66	0.835022
4254.45	2.34673
4257.24	-1.15834
4260.03	-1.67192
4262.81	-7.19746
4265.6	1.32411
4268.38	7.86316
4271.17	-8.73773
4273.95	-6.23868
4276.73	2.28854
4279.51	5.75708
4282.29	7.19582
4285.07	3.56148
4287.84	3.94731
4290.62	5.32594
4293.39	3.65755
4296.17	11.1232
4298.94	-3.69478
4301.71	1.74205
4304.48	-3.9846
4307.25	4.49512
4310.02	-0.219421
4312.79	-1.87854
4315.55	-3.56352
4318.32	-5.26747
4321.08	-1.89606
4323.85	-0.573502
4326.61	-0.278961
4329.37	6.1286
4332.13	-2.75899
4334.89	5.67494
4337.65	-2.20747
4340.4	-10.0708
4343.16	-1.62669
4345.91	-8.46344
4348.67	0.00874329
4351.42	6.44635
4354.17	2.71161
4356.92	-0.0209656
4359.67	4.39806
4362.42	6.76492
4365.17	-1.09637
4367.91	5.36548
4370.66	5.69324
4373.4	12.1503
4376.14	1.1557
4378.89	17.8624
4381.63	-2.40605
4384.37	10.201
4387.11	1.25623
4389.84	0.583771
4392.58	6.11668
4395.32	1.44519
4398.05	-4.36862
4400.78	-6.075
4403.52	1.52805
4406.25	-3.30095
4408.98	0.173706
4411.71	6.7587
4414.44	7.08641
4417.16	5.32039
4419.89	11.8327
4422.62	8.98373
4425.34	6.13922
4428.06	4.33415
4430.78	1.47783
4433.51	-2.43423
4436.22	8.29773
4438.94	6.46138
4441.66	8.79939
4444.38	0.651474
4447.1	2.97842
4449.81	-4.14426
4452.52	8.66882
4455.24	5.7263
4457.95	0.664658
4460.66	18.7192
4463.37	5.25201
4466.08	2.29117
4468.78	10.9099
4471.49	4.80025
4474.2	8.17537
4476.9	4.18652
4479.6	3.3658
4482.31	8.88432
4485.01	2.78758
4487.71	-0.159286
4490.41	1.11449
4493.11	5.53105
4495.8	15.2129
4498.5	0.570602
4501.19	7.09843
4503.89	8.31526
4506.58	0.00402832
4509.27	-0.886688
4511.96	1.40364
4514.66	2.63567
4517.34	3.871
4520.03	-4.45319
4522.72	11.6819
4525.41	12.9399
4528.09	-1.77509
4530.77	5.86534
4533.46	10.3192
4536.14	1.9818
4538.82	6.44476
4541.5	6.64964
4544.18	-2.77237
4546.86	2.77534
4549.53	2.97678
4552.21	8.54861
4554.88	-6.23392
4557.56	4.75154
4560.23	0.742096
4562.9	9.67754
4565.57	5.72408
4568.24	7.20982
4570.91	-7.64921
4573.58	6.62135
4576.24	14.3176
4578.91	-0.720032
4581.58	-5.94566
4584.24	14.9844
4586.9	-2.27542
4589.56	1.1512
4592.22	1.2933
4594.88	10.1743
4597.54	7.07034
4600.2	-0.429901
4602.86	-7.91588
4605.51	-0.0752106
4608.17	8.87561
4610.82	1.38849
4613.47	4.86264
4616.13	13.8354
4618.78	7.42929
4621.43	-0.082428
4624.07	1.20358
4626.72	6.89351
4629.37	3.75256
4632.01	1.70728
4634.66	8.48439
4637.3	5.30145
4639.94	5.43422
4642.59	-9.93985
4645.23	5.72978
4647.87	4.81898
4650.5	11.7162
4653.14	1.98959
4655.78	3.34186
4658.42	14.5593
4661.05	4.7023
4663.68	4.9021
4666.31	10.6769
4668.95	2.99797
4671.58	5.39746
4674.21	8.91808
4676.84	2.34967
4679.46	1.37996
4682.09	1.52806
4684.72	0.552612
4687.34	0.700836
4689.97	-2.52613
4692.59	8.88946
4695.21	-3.36299
4697.83	2.4138
4700.45	5.94408
4703.07	13.9938
4705.69	-5.08314
4708.3	4.08397
4710.92	7.59908
4713.54	-6.99323
4716.15	1.04346
4718.76	6.81454
4721.37	-1.01096
4723.99	5.88601
4726.59	-5.33662
4729.2	-6.34975
4731.81	8.52985
4734.42	-2.69621
4737.03	4.24356
4739.63	10.0444
4742.23	7.88637
4744.84	9.12805
4747.44	2.39855
4750.04	9.30192
4752.64	-0.858711
4755.24	7.18785
4757.84	8.4053
4760.44	-1.7477
4763.03	1.77052
4765.63	12.1329
4768.22	15.6973
4770.82	-5.80566
4773.41	6.86913
4776	9.28551
4778.59	2.57088
4781.18	2.70385
4783.77	0.553116
4786.36	0.690224
4788.94	11.1248
4791.53	8.98532
4794.11	10.2864
4796.7	5.86501
4799.28	1.45309
4801.86	5.07694
4804.44	5.27275
4807.02	10.0846
4809.6	-0.0403748
4812.18	-2.12424
4814.76	-0.744476
4817.33	-5.12514
4819.91	-1.41317
4822.48	9.25252
4825.06	2.56608
4827.63	-0.657463
4830.2	5.40634
4832.77	14.992
4835.34	3.63999
4837.91	5.10623
4840.48	8.9275
4843.04	5.73528
4845.61	-5.69432
4848.17	0.4384
4850.74	-2.84748
4853.3	0.835106
4855.86	9.23035
4858.42	0.121361
4860.98	3.95145
4863.54	5.39718
4866.1	4.43746
4868.66	8.21011
4871.21	6.10741
4873.77	6.34005
4876.32	0.629646
4878.88	3.2173
4881.43	-2.50873
4883.98	3.63102
4886.53	3.83459
4889.08	6.42099
4891.63	7.82281
4894.18	4.45869
4896.72	-1.29483
4899.27	10.823
4901.81	-0.900803
4904.36	0.487808
4906.9	7.84368
4909.44	-0.324715
4911.98	1.03398
4914.52	5.96691
4917.06	-2.25052
4919.6	5.07409
4922.14	-3.12995
4924.67	10.1741
4927.21	12.7359
4929.74	2.13648
4932.28	2.32347
4934.81	8.51649
4937.34	-6.83636
4939.87	2.93562
4942.4	13.8577
4944.93	2.07439
4947.46	9.47268
4949.99	12.0804
4952.51	0.311577
4955.04	8.91221
4957.56	7.93992
4960.08	0.972603
4962.61	6.02657
4965.13	11.1228
4967.65	3.00366
4970.17	2.06978
4972.69	4.74683
4975.2	9.84115
4977.72	16.1498
4980.24	7.95356
4982.75	3.37733
4985.27	4.85794
4987.78	14.8385
4990.29	10.2635
4992.8	0.809998
4995.31	5.93907
4997.82	0.131386