File: Data/3-Raman/processed/bu19w-d-ff2-fi08-v_150 (500nm)_532nm_edge_100%_x100_vis_lwd_h50um_30sx2_01_0.txt
#Acq. time (s)=	30
#Accumulations=	2
#Range (cm-¹)=	100...4000
#Windows=	1
#Auto scanning=	Off
#Autofocus=	Off
#Macrospot=	Off
#AutoExposure=	Off
#Spike filter=	Multiple accum.
#Delay time (s)=	2
#Binning=	1
#Readout mode=	Signal
#DeNoise=	Off
#ICS correction=	On
#Dark correction=	Off
#Inst. Process=	Off
#Detector Gain=	Best Dynamic
#Detector ADC=	50 kHz HS
#Detector temperature (°C)=	-60.09
#Instrument=	LabRAM HR Evol
#Detector=	SIN-EM FIVIS
#Objective=	x100_VIS_LWD
#Grating=	150 (500nm)
#ND Filter=	100%
#Laser=	532nm_Edge
#Hole=	49.98
#Temperature=	0
#Range=	Visible
#StageXY=	75x50mm Scan+
#StageZ=	Z motor
#X (µm)=	0
#Y (µm)=	0
#Z (µm)=	12.2
#Full time(mm:ss)=	1:09
#Project=	21_11_22
#Sample=	BU19w
#Site=
#Title=	BU19w-D-FF2-FI08-V_150 (500nm)_532nm_Edge_100%_x100_VIS_LWD_H50um_30sX2
#Remark=
#Date=	22.11.2021 13:49
#Acquired=	22.11.2021 13:49:31
#Base:Fit=	16.12.2021 17:39:50
#Base:Edit=	16.12.2021 17:43:00
#Base:Edit=	16.12.2021 17:43:03
#Base:Edit=	16.12.2021 17:43:07
#Base:Edit=	16.12.2021 17:43:09
#Base:Edit=	16.12.2021 17:43:11
#Base:Edit=	16.12.2021 17:43:15
#Base:Edit=	16.12.2021 17:43:20
#Base:Sub=	16.12.2021 17:43:24
103.97	1511.96
108.592	1285.07
113.209	1061.31
117.826	933.172
122.441	864.353
127.054	816.692
131.664	765.268
136.27	664.216
140.876	553.034
145.48	542.093
150.081	802.85
154.678	1345.76
159.275	1486.57
163.869	799.899
168.461	394.606
173.049	288.527
177.637	564.429
182.222	1444.74
186.806	1785.63
191.384	1141.87
195.963	505.371
200.54	233.252
205.112	105.266
209.684	39.4695
214.253	-0.881042
218.821	1.28107
223.384	83.7524
227.947	326.97
232.507	554.787
237.064	850.193
241.62	1633.65
246.174	1747.11
250.724	1190.91
255.273	642.481
259.82	392.29
264.363	412.802
268.906	1254.13
273.447	2997.96
277.983	3668.17
282.519	2164.48
287.051	906.241
291.583	589.061
296.112	864.701
300.637	1116.01
305.162	826.659
309.685	430.166
314.204	267.445
318.722	410.747
323.236	732.51
327.75	959.349
332.262	637.612
336.77	388.276
341.277	660.953
345.78	1105.65
350.283	1119.57
354.782	683.982
359.28	366.153
363.775	393.271
368.269	522.308
372.761	312.59
377.249	140.423
381.736	216.037
386.22	408.468
390.703	728.862
395.182	827.796
399.661	567.984
404.136	529.383
408.61	1249.15
413.08	2834.48
417.551	2895.63
422.017	1318.81
426.482	389.229
430.944	76.717
435.406	11.1569
439.863	4.52936
444.32	62.2625
448.773	239.057
453.226	424.591
457.674	310.011
462.121	127.739
466.567	62.3332
471.009	55.9013
475.452	129.95
479.889	220.438
484.327	367.121
488.761	586.058
493.194	675.252
497.623	622.303
502.051	472.484
506.478	315.725
510.9	186.663
515.323	114.226
519.742	85.7653
524.158	75.8473
528.574	68.2082
532.987	82.546
537.397	86.3869
541.807	119.077
546.212	157.51
550.618	173.778
555.019	208.217
559.419	222.71
563.818	188.674
568.213	150.675
572.606	150.534
576.999	275.466
581.388	633.978
585.775	1133.72
590.161	1046.25
594.544	611.345
598.924	500.859
603.304	794.834
607.68	1307.71
612.055	1214.55
616.426	714.032
620.798	346.526
625.166	222.223
629.532	190.74
633.897	241.092
638.258	307.642
642.618	288.243
646.975	230.787
651.332	321.545
655.685	510.881
660.036	753.109
664.385	912.104
668.734	978.393
673.079	1021.22
677.421	998.505
681.762	691.05
686.1	389.885
690.439	192.523
694.773	111.618
699.105	39.1726
703.435	32.0404
707.763	12.7166
712.091	-7.96347
716.415	-6.53055
720.737	-7.64536
725.057	-5.87921
729.375	-1.63828
733.692	5.15985
738.006	3.47125
742.317	2.39313
746.627	19.0232
750.934	47.7007
755.24	71.9312
759.543	145.416
763.846	226.899
768.146	428.288
772.443	707.342
776.738	882.546
781.031	735.305
785.322	454.64
789.611	285.299
793.898	180.982
798.183	133.272
802.466	81.5503
806.748	49.7744
811.027	40.0222
815.304	20.411
819.579	10.6614
823.851	-15.5379
828.122	-5.40707
832.391	4.73209
836.657	-14.9246
840.922	-45.6711
845.184	-45.6195
849.445	-36.9013
853.703	-37.016
857.96	-27.2227
862.214	-11.9793
866.467	-11.1525
870.717	-36.7465
874.965	-37.1063
879.212	-39.7014
883.456	-33.6413
887.699	-41.9021
891.939	-32.8663
896.177	-51.6873
900.414	-39.5297
904.648	-39.5941
908.88	-35.6653
913.111	-36.9748
917.339	-24.2913
921.565	1.23776
925.79	17.8399
930.012	64.8612
934.232	138.578
938.451	217.336
942.667	421.972
946.881	575.703
951.094	551.206
955.302	426.822
959.511	324.128
963.717	278.04
967.921	266.08
972.124	171.583
976.324	99.5335
980.523	73.2015
984.719	55.3804
988.914	34.4247
993.104	26.4123
997.295	15.4325
1001.48	37.4004
1005.67	31.8669
1009.85	47.6409
1014.04	58.0583
1018.22	106.904
1022.4	118.45
1026.57	152.298
1030.75	210.669
1034.92	312.312
1039.09	527.401
1043.26	952.629
1047.42	1691.61
1051.59	2187.7
1055.75	1699.25
1059.91	1054.43
1064.07	736.775
1068.23	645.366
1072.38	806.357
1076.54	1182.07
1080.69	1933.8
1084.84	2954.78
1088.98	3605.59
1093.13	2994.77
1097.27	2123.82
1101.41	1934.98
1105.55	2245.25
1109.69	2419.3
1113.83	2000.07
1117.96	1624.28
1122.09	1450.08
1126.22	1536.56
1130.35	1596.38
1134.47	1373.91
1138.6	1032.41
1142.72	825.915
1146.84	900.821
1150.96	1226.91
1155.07	1581.7
1159.19	1531.78
1163.3	1191.25
1167.41	1032.11
1171.52	814.969
1175.62	512.48
1179.73	290.8
1183.83	216.467
1187.93	147.23
1192.03	144.721
1196.13	139.057
1200.22	122.134
1204.31	124.59
1208.4	97.6864
1212.49	143.704
1216.58	305.395
1220.67	454.307
1224.75	402.093
1228.83	263.265
1232.91	284.16
1236.99	348.37
1241.06	329.484
1245.14	234.94
1249.21	215.56
1253.28	130.348
1257.35	73.0949
1261.41	63.8189
1265.48	233.787
1269.54	962.45
1273.6	499.714
1277.66	67.0662
1281.72	27.6335
1285.77	12.2388
1289.82	17.9459
1293.88	18.5885
1297.92	17.1986
1301.97	6.69986
1306.02	5.25117
1310.06	3.78848
1314.1	8.3056
1318.14	14.7881
1322.18	-1.94113
1326.22	5.44508
1330.25	0.76416
1334.28	-0.957291
1338.31	5.30269
1342.34	5.5294
1346.37	12.7304
1350.39	23.8907
1354.42	47.9346
1358.44	52.0464
1362.46	75.9695
1366.47	144.339
1370.49	738.72
1374.5	1674.98
1378.51	428.574
1382.52	82.1954
1386.53	42.2672
1390.54	64.3979
1394.54	133.882
1398.55	65.5027
1402.55	3.94743
1406.55	3.46852
1410.54	2.99088
1414.54	-6.37572
1418.53	-12.8045
1422.52	-11.3666
1426.51	-13.9501
1430.5	-14.5714
1434.49	-7.3006
1438.47	-20.7799
1442.45	-5.65392
1446.43	-14.2446
1450.41	-23.8445
1454.39	-7.8278
1458.36	-5.65577
1462.34	-13.38
1466.31	-12.2626
1470.28	-10.1633
1474.24	-20.8459
1478.21	-11.9343
1482.17	-7.95768
1486.14	-10.8541
1490.1	-8.86954
1494.05	-3.00031
1498.01	-1.04321
1501.97	2.86024
1505.92	0.941673
1509.87	10.6782
1513.82	0.977219
1517.77	-7.74755
1521.71	7.77415
1525.66	-12.5992
1529.6	5.8091
1533.54	0.935875
1537.48	13.4928
1541.41	12.4636
1545.35	10.448
1549.28	11.3212
1553.21	12.1636
1557.14	24.5881
1561.07	16.6477
1565	17.3902
1568.92	19.0713
1572.84	18.7982
1576.76	24.2938
1580.68	26.867
1584.6	25.5556
1588.51	28.0751
1592.43	30.5704
1596.34	33.0434
1600.25	35.5038
1604.16	37.9616
1608.06	27.9378
1611.97	34.2075
1615.87	34.7219
1619.77	35.2131
1623.67	37.6153
1627.57	40.9736
1631.46	46.2657
1635.36	43.8824
1639.25	41.5066
1643.14	35.3076
1647.03	31.0122
1650.91	45.8875
1654.8	47.3136
1658.68	43.9128
1662.56	42.3897
1666.44	37.9472
1670.32	31.5276
1674.2	33.7308
1678.07	27.2129
1681.94	34.0914
1685.81	32.2991
1689.68	24.7243
1693.55	31.4841
1697.41	24.8171
1701.28	27.6685
1705.14	29.5183
1709	32.2712
1712.86	25.5167
1716.72	32.9679
1720.57	31.8805
1724.42	22.2959
1728.28	27.7589
1732.13	15.3702
1735.97	17.9842
1739.82	20.5581
1743.66	26.8338
1747.51	16.3973
1751.35	26.4411
1755.19	18.8849
1759.02	15.1847
1762.86	14.2104
1766.69	22.5284
1770.53	20.6733
1774.36	19.7397
1778.18	20.6856
1782.01	19.7756
1785.84	23.5368
1789.66	17.0029
1793.48	16.0667
1797.3	12.293
1801.12	17.8508
1804.94	17.7434
1808.75	11.0171
1812.57	10.8562
1816.38	16.3072
1820.19	19.8342
1824	10.1236
1827.8	13.5857
1831.61	5.7009
1835.41	7.21765
1839.21	7.76757
1843.01	11.1031
1846.81	5.98697
1850.6	9.26888
1854.4	16.2423
1858.19	7.28887
1861.98	6.73011
1865.77	17.3167
1869.56	14.8884
1873.34	14.332
1877.13	8.24039
1880.91	6.80894
1884.69	12.7482
1888.47	11.4151
1892.25	10.0939
1896.02	9.68694
1899.8	9.31542
1903.57	-0.244308
1907.34	7.69564
1911.11	10.1463
1914.88	11.6868
1918.64	8.66827
1922.41	7.50663
1926.17	8.21162
1929.93	-1.29794
1933.69	4.05805
1937.44	-0.836464
1941.2	6.40623
1944.95	-1.31232
1948.7	-1.62621
1952.46	-2.91805
1956.2	0.43708
1959.95	-0.001091
1963.7	-3.26294
1967.44	-4.67102
1971.18	-1.42648
1974.92	-1.9555
1978.66	-12.7941
1982.4	-3.0613
1986.13	4.7648
1989.87	-5.14771
1993.6	-2.02843
1997.33	-12.8577
2001.06	-6.97393
2004.78	4.42538
2008.51	-11.9103
2012.23	0.343887
2015.96	-5.7667
2019.67	-2.63156
2023.39	-6.77052
2027.11	-7.22233
2030.83	-7.63868
2034.54	-8.00183
2038.25	-8.37423
2041.96	-13.3248
2045.67	-9.11655
2049.38	-9.46147
2053.08	-10.7098
2056.79	-4.57711
2060.49	-3.86359
2064.19	-17.8267
2067.89	-14.3197
2071.58	-6.17715
2075.28	-5.38788
2078.97	-7.35894
2082.67	-6.55699
2086.36	-5.85554
2090.05	-3.35892
2093.73	-7.30691
2097.42	-8.4716
2101.1	-6.87933
2104.78	-10.8784
2108.47	-13.9562
2112.14	-6.8035
2115.82	-0.58844
2119.5	-8.34558
2123.17	-3.12084
2126.84	-3.47562
2130.52	-7.53771
2134.18	-12.5125
2137.85	-7.32994
2141.52	-5.85978
2145.18	-8.07493
2148.84	-8.44051
2152.51	-9.71078
2156.17	-9.13385
2159.82	-3.96947
2163.48	-4.27022
2167.14	-10.9242
2170.79	-2.03059
2174.44	6.89053
2178.09	1.26537
2181.74	-0.70916
2185.38	8.26416
2189.03	6.38114
2192.67	9.10579
2196.32	2.76551
2199.96	6.46645
2203.59	6.55153
2207.23	8.49502
2210.87	13.217
2214.5	8.80182
2218.13	19.9945
2221.76	11.0048
2225.39	2.91016
2229.02	4.9469
2232.65	5.1618
2236.27	1.68157
2239.89	-4.5862
2243.51	-12.7261
2247.13	-3.21181
2250.75	-9.48065
2254.37	-11.0876
2257.98	-4.28013
2261.59	-3.07246
2265.2	-0.906662
2268.81	-2.45811
2272.42	-3.09032
2276.03	-9.40997
2279.64	-14.8575
2283.24	-14.6531
2286.84	-13.4917
2290.44	-20.848
2294.04	-13.0638
2297.64	-10.9393
2301.23	-16.4005
2304.83	-4.82138
2308.42	2.01417
2312.01	44.861
2315.6	199.515
2319.19	104.859
2322.77	13.0515
2326.36	-7.67533
2329.94	-10.415
2333.52	-9.38427
2337.1	-13.0709
2340.68	-3.59008
2344.26	-9.16246
2347.83	0.270325
2351.41	-1.55035
2354.98	-7.09734
2358.55	-7.96684
2362.12	-2.32279
2365.69	-8.74831
2369.25	6.17879
2372.82	-2.05576
2376.38	-0.105194
2379.94	-2.74898
2383.5	0.151535
2387.06	-3.36497
2390.61	-7.76442
2394.17	-2.95225
2397.72	0.060318
2401.27	-6.03262
2404.82	0.728119
2408.37	-1.63486
2411.92	1.53876
2415.47	-1.68736
2419.01	1.53902
2422.55	2.03562
2426.09	-0.206581
2429.63	2.18924
2433.17	-0.0156708
2436.71	-5.00508
2440.24	3.02503
2443.78	0.828926
2447.31	4.2551
2450.84	-4.48046
2454.37	-2.9725
2457.89	-4.37341
2461.42	1.74562
2464.94	-3.5211
2468.47	1.64759
2471.99	0.076088
2475.51	-0.594749
2479.03	10.0673
2482.54	8.43379
2486.06	5.79712
2489.57	7.90719
2493.08	11.844
2496.59	-0.135284
2500.1	0.992462
2503.61	3.96128
2507.12	1.30435
2510.62	4.24174
2514.12	5.33311
2517.62	3.65488
2521.12	7.46386
2524.62	7.66296
2528.12	10.6584
2531.61	9.96658
2535.11	10.227
2538.6	8.66013
2542.09	3.44647
2545.58	2.8868
2549.07	12.4914
2552.55	8.25419
2556.04	12.3962
2559.52	12.8288
2563	4.00494
2566.48	8.2158
2569.96	12.4672
2573.44	10.1935
2576.91	10.7391
2580.39	1.85812
2583.86	14.6662
2587.33	8.54956
2590.8	13.7454
2594.27	14.1687
2597.74	11.7543
2601.2	13.1434
2604.67	8.71712
2608.13	8.02796
2611.59	10.1271
2615.05	13.2273
2618.51	8.58729
2621.96	14.4892
2625.42	11.7047
2628.87	7.93655
2632.32	11.8167
2635.77	7.98016
2639.22	16.5728
2642.67	13.6365
2646.11	9.73851
2649.56	15.3519
2653	9.4909
2656.44	10.267
2659.88	19.5433
2663.32	11.7444
2666.76	12.455
2670.19	15.9641
2673.63	11.9563
2677.06	12.6508
2680.49	14.2875
2683.92	19.6725
2687.35	14.8481
2690.78	9.13245
2694.2	15.4904
2697.63	18.1305
2701.05	11.461
2704.47	13.1474
2707.89	17.6895
2711.31	16.6622
2714.72	11.918
2718.14	15.5618
2721.55	8.01989
2724.96	8.86243
2728.37	10.6368
2731.78	15.2044
2735.19	22.5806
2738.6	12.133
2742	1.63177
2745.41	11.7567
2748.81	13.4226
2752.21	12.2477
2755.61	11.9843
2759	13.5977
2762.4	8.57317
2765.8	12.9414
2769.19	14.4501
2772.58	14.0522
2775.97	21.1572
2779.36	-2.84534
2782.75	18.3247
2786.13	11.2373
2789.52	8.84021
2792.9	4.54751
2796.28	13.3926
2799.66	4.36652
2803.04	11.2766
2806.42	5.983
2809.79	4.42026
2813.17	8.45004
2816.54	0.309959
2819.91	8.05202
2823.28	3.65861
2826.65	8.58588
2830.02	11.6448
2833.38	11.9147
2836.75	5.66986
2840.11	4.09103
2843.47	4.38754
2846.83	4.71013
2850.19	7.85383
2853.55	8.17146
2856.91	3.81726
2860.26	-0.542648
2863.61	-0.233208
2866.96	-2.74731
2870.31	-0.589127
2873.66	4.37989
2877.01	1.81426
2880.36	4.88251
2883.7	0.390488
2887.05	0.595367
2890.39	-1.10301
2893.73	-0.00862122
2897.07	-1.77828
2900.4	6.82755
2903.74	-4.46088
2907.07	4.09856
2910.41	-3.45
2913.74	2.23096
2917.07	4.09467
2920.4	-2.57344
2923.73	9.64993
2927.05	3.87583
2930.38	3.74917
2933.7	8.30649
2937.02	5.30159
2940.34	16.422
2943.66	10.5719
2946.98	-6.56436
2950.3	-2.07028
2953.61	-6.98483
2956.92	-0.617294
2960.24	-0.820953
2963.55	-1.96684
2966.86	-4.02036
2970.16	-1.3611
2973.47	-1.52533
2976.78	3.0248
2980.08	5.67215
2983.38	-2.94186
2986.68	2.52643
2989.98	3.29945
2993.28	-0.623184
2996.58	-13.0062
2999.87	-0.956726
3003.17	0.74762
3006.46	-3.18607
3009.75	0.413605
3013.04	9.67041
3016.33	1.01611
3019.62	-1.05125
3022.91	8.20125
3026.19	0.466141
3029.47	6.88832
3032.75	8.57953
3036.03	7.42659
3039.31	8.16342
3042.59	3.22278
3045.87	-1.72261
3049.14	11.326
3052.42	1.64102
3055.69	21.3403
3058.96	17.276
3062.23	21.7741
3065.49	17.71
3068.76	20.2584
3072.03	35.8732
3075.29	30.8511
3078.55	32.3763
3081.81	44.5347
3085.07	32.0143
3088.33	35.6884
3091.59	37.5138
3094.85	46.6214
3098.1	46.3899
3101.35	58.4614
3104.61	49.7408
3107.85	49.5521
3111.1	73.0775
3114.35	60.4573
3117.6	76.4129
3120.84	86.6637
3124.09	93.108
3127.33	93.8309
3130.57	91.7052
3133.81	101.014
3137.05	109.36
3140.28	114.848
3143.52	112.714
3146.75	132.54
3149.99	122.822
3153.22	143.614
3156.45	142.489
3159.68	150.898
3162.9	157.413
3166.13	181.079
3169.35	173.232
3172.58	168.24
3175.8	199.479
3179.02	195.412
3182.24	214.261
3185.46	216.846
3188.67	213.706
3191.89	202.953
3195.1	232.221
3198.32	230.039
3201.53	242.17
3204.74	238.14
3207.95	258.883
3211.15	262.537
3214.36	244.357
3217.56	271.853
3220.77	249.908
3223.97	278.445
3227.17	285.126
3230.37	281.402
3233.57	271.933
3236.76	289.246
3239.96	282.808
3243.15	298.32
3246.35	306.232
3249.54	298.015
3252.73	313.671
3255.92	309.31
3259.1	302.971
3262.29	320.446
3265.47	338.817
3268.66	322.756
3271.84	304.763
3275.02	329.772
3278.2	352.761
3281.38	300.224
3284.55	339.359
3287.73	343.13
3290.9	341.252
3294.08	366.996
3297.25	360.35
3300.42	352.944
3303.59	361.571
3306.76	366.347
3309.92	394.79
3313.09	369.991
3316.25	386.982
3319.41	403.935
3322.58	410.467
3325.74	412.277
3328.9	414.117
3332.05	421.688
3335.21	411.387
3338.36	433.253
3341.52	445.688
3344.67	453.589
3347.82	462.643
3350.97	461.329
3354.12	471.434
3357.26	493.847
3360.41	496.586
3363.55	495.59
3366.7	524.842
3369.84	524.91
3372.98	557.192
3376.12	555.559
3379.26	544.546
3382.39	586.435
3385.53	601.037
3388.66	612.846
3391.8	661.62
3394.93	664.667
3398.06	731.816
3401.19	789.702
3404.31	881.069
3407.44	1064.95
3410.56	1471.99
3413.69	2533.87
3416.81	5338.16
3419.93	8312
3423.05	6765.11
3426.17	3415.16
3429.29	1734.37
3432.41	1170.22
3435.52	957.179
3438.63	863.721
3441.75	798.942
3444.86	723.494
3447.97	736.781
3451.08	749.915
3454.18	711.624
3457.29	717.026
3460.39	711.014
3463.5	731.585
3466.6	728.286
3469.7	761.754
3472.8	802.146
3475.9	843.496
3479	921.738
3482.09	1053.78
3485.19	1218.8
3488.28	1435.76
3491.37	1837.11
3494.46	2418.44
3497.55	3082.22
3500.64	3745.8
3503.73	3928.41
3506.81	3487.39
3509.9	2719.03
3512.98	2039.59
3516.06	1542.19
3519.14	1226.79
3522.22	1000.63
3525.3	842.214
3528.38	690.604
3531.46	615.229
3534.53	569.639
3537.6	534.487
3540.67	518.651
3543.75	449.731
3546.82	421.014
3549.88	393.049
3552.95	381.073
3556.02	358.796
3559.08	341.259
3562.14	311.272
3565.21	296.352
3568.27	312.896
3571.33	289.374
3574.39	283.899
3577.44	258.475
3580.5	251.992
3583.55	242.629
3586.61	248.452
3589.66	221.987
3592.71	202.172
3595.76	218.342
3598.81	192.84
3601.85	190.992
3604.9	184.391
3607.95	175.914
3610.99	151.367
3614.03	152.345
3617.07	143.907
3620.11	152.485
3623.15	123.356
3626.19	128.216
3629.22	131.174
3632.26	108.692
3635.29	118.315
3638.33	114.808
3641.36	72.7656
3644.39	80.6791
3647.42	85.6819
3650.44	58.7744
3653.47	67.2049
3656.5	64.9817
3659.52	45.7818
3662.54	44.4127
3665.56	39.1471
3668.58	24.5065
3671.6	31.5564
3674.62	17.8589
3677.64	17.3777
3680.65	14.9902
3683.67	6.92361
3686.68	6.41844
3689.69	9.70085
3692.7	0.669846
3695.71	-2.73157
3698.72	-7.05093
3701.73	-3.78966
3704.73	-10.03
3707.74	-8.7037
3710.74	-11.1991
3713.74	-8.97148
3716.75	-11.4952
3719.75	-19.7614
3722.74	-9.01137
3725.74	-7.80449
3728.74	-10.4271
3731.73	-12.1222
3734.73	-12.8929
3737.72	-2.26334
3740.71	-0.234467
3743.7	-14.4012
3746.69	-14.3201
3749.68	-1.91165
3752.66	-3.77426
3755.65	-3.74503
3758.63	-4.67989
3761.62	7.62538
3764.6	0.019165
3767.58	4.72197
3770.56	2.79945
3773.54	2.76617
3776.51	2.72678
3779.49	1.73692
3782.46	0.733063
3785.44	-8.7751
3788.41	6.25227
3791.38	2.40611
3794.35	-2.3893
3797.32	-4.36504
3800.29	12.5424
3803.25	4.89148
3806.22	1.94376
3809.18	-0.0719147
3812.14	6.40331
3815.11	-0.3759
3818.07	0.394257
3821.03	12.5089
3823.98	7.57339
3826.94	0.716446
3829.9	7.10638
3832.85	3.05582
3835.8	3.73399
3838.76	-2.26271
3841.71	10.7322
3844.66	16.1113
3847.61	-4.24017
3850.55	8.73183
3853.5	7.39163
3856.45	5.07278
3859.39	10.3774
3862.33	7.04817
3865.27	19.9712
3868.21	12.7544
3871.15	1.66441
3874.09	14.5242
3877.03	5.27642
3879.96	8.47276
3882.9	15.4777
3885.83	11.8806
3888.77	14.0242
3891.7	15.1804
3894.63	11.4901
3897.56	16.4177
3900.48	16.5151
3903.41	10.8042
3906.34	1.25044
3909.26	15.6948
3912.18	24.3366
3915.1	5.08984
3918.02	17.5517
3920.94	3.08514
3923.86	15.4632
3926.78	18.2112
3929.7	5.60003
3932.61	6.42893
3935.52	0.567619
3938.44	15.7879
3941.35	15.6602
3944.26	10.7418
3947.17	11.5722
3950.08	15.2767
3952.98	16.1062
3955.89	15.0263
3958.79	13.9463
3961.7	1.36439
3964.6	5.07854
3967.5	14.5563
3970.4	10.608
3973.3	5.69234
3976.2	5.56816
3979.09	11.2027
3981.99	7.2289
3984.88	6.13498
3987.78	9.85376
3990.67	3.94116
3993.56	0.949448
3996.45	6.62601
3999.34	2.69809