File: Data/3-Raman/processed/bu19w-e-ff11b-fi01-v_1800 (450-850nm)_532nm_edge_100%_x100_vis_h50um_30sx2_01.txt
#Acq. time (s)=	30
#Accumulations=	2
#Range (cm-¹)=	1200...2365
#Windows=	3
#Auto scanning=	Off
#Autofocus=	Off
#Macrospot=	Off
#AutoExposure=	Off
#Spike filter=	Multiple accum.
#Delay time (s)=	2
#Binning=	1
#Readout mode=	Signal
#DeNoise=	Off
#ICS correction=	On
#Dark correction=	Off
#Inst. Process=	Off
#Detector Gain=	Best Dynamic
#Detector ADC=	50 kHz HS
#Detector temperature (°C)=	-60.09
#Instrument=	LabRAM HR Evol
#Detector=	SIN-EM FIVIS
#Objective=	x100_VIS
#Grating=	1800 (450-850nm)
#ND Filter=	100%
#Laser=	532nm_Edge
#Hole=	49.98
#Temperature=	0
#Range=	Visible
#StageXY=	75x50mm Scan+
#StageZ=	Z motor
#X (µm)=	0
#Y (µm)=	0
#Z (µm)=	-245.6
#Full time(mm:ss)=	3:23
#Project=	21_11_04
#Sample=	BU19w
#Site=
#Title=	BU19w-E-FF11b-FI01-V_1800 (450-850nm)_532nm_Edge_100%_x100_VIS_H50um_30sX2
#Remark=
#Date=	04.11.2021 18:28
#Acquired=	04.11.2021 18:28:15
#Base:Fit=	16.12.2021 17:39:50
#Base:Fit=	16.12.2021 17:46:27
#Base:Sub=	16.12.2021 17:46:29
1202.73	3.22269
1203.85	5.20501
1204.96	2.93925
1206.07	0.63348
1207.18	-2.72138
1208.29	3.57561
1209.4	1.32439
1210.51	1.19161
1211.62	-4.27693
1212.73	-3.33169
1213.84	-1.29893
1214.95	2.8735
1216.06	-0.434433
1217.17	2.62696
1218.28	0.394474
1219.39	-0.759464
1220.5	3.40135
1221.61	1.17365
1222.72	-1.07863
1223.82	3.02609
1224.93	5.05308
1226.04	3.93819
1227.15	5.9263
1228.25	2.59027
1229.36	4.76998
1230.47	2.5317
1231.57	2.39477
1232.68	4.42774
1233.79	-1.92694
1234.89	2.23899
1236	0.0898399
1237.1	-4.19577
1238.21	-0.0922165
1239.31	-0.158337
1240.42	-2.3008
1241.52	3.93322
1242.63	0.75774
1243.74	-2.42482
1244.84	2.75699
1245.94	0.590107
1247.05	-0.498039
1248.15	1.53547
1249.25	2.54976
1250.36	0.406002
1251.46	0.350693
1252.56	1.33959
1253.66	1.31675
1254.77	1.30746
1255.87	1.28686
1256.97	1.26855
1258.07	6.45592
1259.18	5.38581
1260.28	1.18657
1261.38	9.52323
1262.48	9.51046
1263.58	14.7756
1264.68	4.31936
1265.78	8.48046
1266.88	10.5959
1267.98	12.7494
1269.08	5.43726
1270.18	22.1442
1271.28	12.6984
1272.38	14.8446
1273.48	12.7994
1274.58	15.9608
1275.68	11.7953
1276.78	5.5325
1277.87	15.0348
1278.97	10.8663
1280.07	18.2261
1281.17	21.4347
1282.26	38.2972
1283.36	132.76
1284.46	68.9576
1285.55	17.291
1286.65	4.66304
1287.75	9.92062
1288.84	0.478912
1289.94	2.6277
1291.04	3.69059
1292.13	0.551739
1293.23	1.6435
1294.32	-1.47357
1295.42	3.87885
1296.51	-0.29388
1297.61	-0.297504
1298.7	1.82831
1299.79	6.07843
1300.89	-3.39679
1301.98	1.92676
1303.08	-0.166801
1304.17	0.915455
1305.26	0.922398
1306.36	-1.17804
1307.45	-1.1431
1308.54	-0.0508423
1309.63	-2.11347
1310.73	0.0309219
1311.82	3.24723
1312.91	2.22244
1314	2.25323
1315.09	-0.862209
1316.18	2.34491
1317.28	2.38823
1318.37	-2.84985
1319.46	2.46883
1320.55	-0.670818
1321.64	-1.72088
1322.73	1.46068
1323.82	0.450264
1324.91	1.54293
1325.99	2.56419
1327.08	0.536575
1328.17	2.73892
1329.26	3.84287
1330.35	-1.40685
1331.44	-0.357471
1332.53	-0.355419
1333.62	0.698555
1334.7	2.80964
1335.79	-0.31723
1336.88	2.85717
1337.96	1.82907
1339.05	0.814995
1340.14	-3.32299
1341.23	4.04659
1342.31	3.01484
1343.4	0.9562
1344.48	3.08803
1345.57	2.05183
1346.66	1.00469
1347.74	-1.05942
1348.83	2.09439
1349.91	-1.00712
1351	3.17161
1352.08	2.17983
1353.17	4.38213
1354.25	1.19753
1355.33	4.3511
1356.42	4.39542
1357.5	4.42327
1358.58	4.44252
1359.67	3.42414
1360.75	10.6977
1361.83	2.44781
1362.92	6.63594
1364	8.76514
1365.08	3.60843
1366.16	13.9627
1367.24	10.878
1368.33	15.0726
1369.41	15.1179
1370.49	14.1
1371.57	13.0539
1372.65	18.2077
1373.73	26.4754
1374.81	19.2941
1375.89	28.6112
1376.97	48.1461
1378.05	57.591
1379.13	64.8609
1380.21	81.1991
1381.29	82.1668
1382.37	77.9104
1383.45	72.7184
1384.53	69.7263
1385.61	82.199
1386.68	276.393
1387.76	111.469
1388.84	40.2205
1389.92	26.8339
1390.99	24.805
1392.07	18.6526
1393.15	15.5996
1394.23	10.5111
1395.3	9.54515
1396.38	5.47912
1397.46	8.56771
1398.53	6.57174
1399.61	9.69548
1400.68	10.7773
1401.76	12.8965
1402.83	4.79534
1403.91	10.967
1404.99	5.85812
1406.06	3.8239
1407.13	8.9932
1408.21	16.2166
1409.28	12.1637
1410.36	6.02065
1411.43	7.05431
1412.5	6.12998
1413.58	4.07682
1414.65	6.20728
1415.72	-1.96824
1416.8	4.24015
1417.87	-1.88496
1418.94	2.25942
1420.01	0.212568
1421.08	3.30501
1422.16	3.37819
1423.23	2.28216
1424.3	1.29748
1425.37	0.328857
1426.44	0.336525
1427.51	1.35088
1428.58	3.42677
1429.65	2.45176
1430.72	0.468252
1431.79	-1.55854
1432.86	-0.540449
1433.93	2.53661
1435	-0.496056
1436.07	2.59502
1437.14	-2.51173
1438.21	2.63805
1439.28	6.77394
1440.35	2.7157
1441.41	0.680138
1442.48	0.71183
1443.55	2.76877
1444.62	-2.31441
1445.69	-1.27369
1446.75	-0.237207
1447.82	1.82779
1448.89	-2.24597
1449.95	-0.191851
1451.02	2.89098
1452.09	1.87634
1453.15	1.90266
1454.22	-2.18325
1455.28	0.908638
1456.35	0.923988
1457.41	-1.12136
1458.48	-0.0783081
1459.54	-0.0635967
1460.61	0.964327
1461.67	0.960482
1462.74	0.948095
1463.8	-2.09933
1464.86	2.99067
1465.93	-3.15296
1466.99	2.96285
1468.05	-2.13139
1469.12	0.928413
1470.18	1.93626
1471.24	3.96652
1472.31	3.97006
1473.37	-2.14198
1474.43	1.93902
1475.49	-2.12804
1476.55	0.918232
1477.62	-4.1658
1478.68	1.92317
1479.74	0.88768
1480.8	0.870222
1481.86	-2.15378
1482.92	-2.13684
1483.98	-2.15049
1485.04	2.81292
1486.1	-3.19564
1487.16	2.88326
1488.22	2.86399
1489.28	-3.2183
1490.34	1.83548
1491.4	-2.21772
1492.46	-3.22691
1493.52	0.816545
1494.57	-0.190325
1495.63	4.82861
1496.69	-1.24057
1497.75	-0.231777
1498.81	2.80198
1499.86	-2.23686
1500.92	4.82077
1501.98	2.79634
1503.03	0.757553
1504.09	-3.27259
1505.15	-2.27509
1506.2	-0.277267
1507.26	-1.27646
1508.32	1.74335
1509.37	-1.27926
1510.43	-0.282871
1511.48	-0.3304
1512.54	1.634
1513.59	-0.371071
1514.65	0.621981
1515.7	-4.42687
1516.76	-0.426046
1517.81	-2.42535
1518.86	-0.413664
1519.92	-2.42452
1520.97	-0.413937
1522.02	-1.42824
1523.08	-1.45446
1524.13	-0.480803
1525.18	-0.477589
1526.24	-3.46623
1527.29	-2.47382
1528.34	0.517441
1529.39	2.50894
1530.44	2.51514
1531.5	-0.487989
1532.55	5.53644
1533.6	-0.463415
1534.65	2.53281
1535.7	-1.51444
1536.75	-1.55184
1537.8	1.42441
1538.85	0.428907
1539.9	1.49063
1540.95	-0.514881
1542	-1.54827
1543.05	4.42346
1544.1	1.40936
1545.15	3.4428
1546.2	-0.559708
1547.25	1.44841
1548.29	1.43595
1549.34	1.37197
1550.39	5.53329
1551.44	3.4847
1552.49	2.49833
1553.53	4.45823
1554.58	2.41142
1555.63	2.40713
1556.68	2.39993
1557.72	4.38488
1558.77	3.34154
1559.82	-1.68308
1560.86	5.30318
1561.91	1.32621
1562.95	0.317623
1564	3.3368
1565.04	3.20867
1566.09	3.29593
1567.13	-1.68726
1568.18	5.29402
1569.22	4.26811
1570.27	0.270483
1571.31	7.24726
1572.36	3.23155
1573.4	4.20963
1574.44	4.23361
1575.49	4.24742
1576.53	-3.76833
1577.57	3.17507
1578.62	6.15086
1579.66	4.16261
1580.7	4.15268
1581.74	4.12843
1582.79	10.0938
1583.83	6.10413
1584.87	5.10892
1585.91	0.110914
1586.95	2.08244
1587.99	9.04827
1589.03	4.08806
1590.07	6.08506
1591.12	8.07761
1592.16	7.05047
1593.2	9.98534
1594.24	10.959
1595.28	7.98042
1596.32	6.98255
1597.35	7.98488
1598.39	8.95076
1599.43	9.91554
1600.47	8.89134
1601.51	10.8271
1602.55	9.80375
1603.59	4.84147
1604.63	8.79969
1605.66	13.7585
1606.7	10.808
1607.74	12.0958
1608.78	10.628
1609.81	9.65291
1610.85	15.9429
1611.89	13.9501
1612.92	13.7589
1613.96	11.3573
1615	17.0024
1616.03	17.8772
1617.07	14.5274
1618.1	17.5939
1619.14	21.2453
1620.17	18.8542
1621.21	19.115
1622.24	23.2616
1623.28	18.1892
1624.31	21.3719
1625.35	21.2482
1626.38	23.6812
1627.41	25.3942
1628.45	24.834
1629.48	25.6694
1630.51	25.1601
1631.3	20.5893
1632.34	28.5291
1633.39	27.5064
1634.43	27.5296
1635.48	29.4937
1636.52	26.5163
1637.57	22.5639
1638.61	27.4855
1639.66	24.5383
1640.7	29.4936
1641.75	17.6725
1642.79	28.5027
1643.83	29.4775
1644.88	24.5684
1645.92	25.558
1646.96	21.6134
1648.01	23.5949
1649.05	29.5575
1650.09	22.6987
1651.13	33.5813
1652.18	31.6221
1653.22	24.7278
1654.26	26.7268
1655.3	29.7521
1656.34	26.8396
1657.38	27.8249
1658.42	28.7991
1659.47	26.8034
1660.51	25.8587
1661.55	23.9379
1662.59	21.0632
1663.63	24.9513
1664.67	24.0451
1665.71	21.1323
1666.75	25.9984
1667.79	22.0306
1668.83	21.1175
1669.86	15.2026
1670.9	25.1364
1671.94	20.2168
1672.98	18.2595
1674.02	19.286
1675.06	21.3104
1676.1	19.3532
1677.13	12.4386
1678.17	20.3378
1679.21	13.4141
1680.25	18.3566
1681.28	12.4391
1682.32	15.4213
1683.35	16.4249
1684.39	10.5031
1685.43	10.5199
1686.46	12.5311
1687.5	14.5154
1688.54	10.563
1689.57	12.5257
1690.6	12.5599
1691.64	12.5913
1692.68	12.5878
1693.71	10.5975
1694.74	10.604
1695.78	7.68093
1696.81	14.5943
1697.85	11.6231
1698.88	11.6274
1699.92	8.6946
1700.95	7.72322
1701.98	11.6507
1703.01	6.74552
1704.05	6.76901
1705.08	11.7021
1706.11	10.72
1707.14	5.79929
1708.18	3.81771
1709.21	7.7297
1710.24	9.71369
1711.27	3.87633
1712.3	7.79204
1713.33	3.84873
1714.36	6.78653
1715.4	9.75427
1716.43	3.89363
1717.46	3.86292
1718.49	7.74597
1719.52	2.89969
1720.55	2.91045
1721.58	6.79603
1722.61	5.81497
1723.64	4.8547
1724.66	2.9118
1725.69	6.77679
1726.72	3.87951
1727.75	8.74521
1728.78	2.84125
1729.81	3.85907
1730.83	0.0404625
1731.86	-1.87107
1732.89	3.92849
1733.92	1.97932
1734.95	3.89258
1735.97	2.93698
1737	2.94499
1738.03	7.75441
1739.05	1.98037
1740.08	0.999458
1741.1	0.998558
1742.13	3.88362
1743.16	1.98552
1744.18	1.99215
1745.21	2.01646
1746.23	2.97231
1747.26	2.01252
1748.28	-3.69407
1749.31	1.11866
1750.33	4.98952
1751.36	0.229431
1752.38	5.95553
1753.4	2.13928
1754.43	2.1424
1755.45	3.10206
1756.47	1.18907
1757.5	3.10061
1758.52	-0.667492
1759.54	4.11472
1760.57	3.17449
1761.59	-0.621361
1762.61	1.31163
1763.63	1.33984
1764.66	3.29284
1765.68	4.27593
1766.7	4.29423
1767.72	1.44926
1768.74	2.39319
1769.76	-1.40382
1770.78	0.536148
1771.8	2.48264
1772.82	1.57256
1773.84	-1.25009
1774.86	0.688883
1775.88	-1.16944
1776.9	0.748461
1777.92	-0.200321
1778.94	1.70079
1779.96	-3.02465
1780.98	-0.139917
1782	-0.101667
1783.02	1.84085
1784.04	2.83679
1785.05	0.00357056
1786.07	-0.932518
1787.09	1.97833
1788.11	1.11044
1789.12	-0.755802
1790.14	1.19386
1791.16	0.230579
1792.18	0.250319
1793.19	0.277361
1794.21	2.21507
1795.23	-0.592516
1796.24	0.406586
1797.26	4.29021
1798.27	0.472788
1799.29	1.44022
1800.3	-1.43785
1801.32	1.46066
1802.33	0.530657
1803.35	-0.393728
1804.36	3.48724
1805.38	-0.319622
1806.39	3.5681
1807.41	0.696306
1808.42	2.64433
1809.43	0.737757
1810.45	2.68164
1811.46	0.76856
1812.47	0.796976
1813.49	1.79294
1814.5	-2.02557
1815.51	1.8646
1816.53	2.85052
1817.54	-1.0242
1818.55	-1.9617
1819.56	2.89594
1820.57	0.988783
1821.58	0.0499268
1822.6	2.00681
1823.61	2.98138
1824.62	1.068
1825.63	2.05495
1826.64	2.07067
1827.65	-0.814613
1828.66	-1.7807
1829.67	2.09842
1830.68	9.85117
1831.69	4.06857
1832.7	1.18716
1833.71	0.233686
1834.72	3.10466
1835.73	5.99157
1836.74	1.22145
1837.75	1.15198
1838.75	-1.67836
1839.76	2.2011
1840.77	2.143
1841.78	1.14224
1842.79	5.00222
1843.79	1.14797
1844.8	-5.59684
1845.81	2.15909
1846.81	3.05464
1847.82	0.180635
1848.83	-0.799093
1849.83	0.136286
1850.84	-3.72636
1851.85	2.03209
1852.85	0.113604
1853.86	1.05445
1854.86	1.99295
1855.87	-0.897148
1856.87	-0.897488
1857.88	1.96199
1858.88	0.981529
1859.89	0.0219212
1860.89	-2.82943
1861.9	-0.913113
1862.9	1.93291
1863.9	1.91189
1864.91	-0.0219936
1865.91	-1.0146
1866.92	1.79858
1867.92	4.6303
1868.92	-2.97615
1869.92	-1.08208
1870.93	0.81288
1871.93	1.74701
1872.93	-2.06892
1873.93	1.70884
1874.93	-0.218786
1875.94	6.36122
1876.94	-2.19297
1877.94	-1.2001
1878.94	-1.1949
1879.94	1.62424
1880.94	0.661299
1881.94	-2.2325
1882.94	-0.257233
1883.94	3.3756
1884.94	0.554972
1885.94	-1.31481
1886.94	1.48616
1887.94	-2.32313
1888.94	-1.41792
1889.94	-0.480385
1890.94	4.22507
1891.94	-0.496984
1892.94	0.403799
1893.93	-0.568399
1894.93	-2.46277
1895.93	2.23829
1896.93	1.30397
1897.93	2.2306
1898.92	1.25546
1899.92	-0.646191
1900.92	-1.58611
1901.91	-2.51831
1902.91	2.16472
1903.91	1.20467
1904.9	1.18737
1905.9	-3.54456
1906.9	0.190489
1907.89	0.188374
1908.89	4.88647
1909.88	2.08552
1910.88	-0.732025
1911.87	2.07588
1912.87	1.11823
1913.86	-2.64285
1914.86	2.07665
1915.85	-2.6597
1916.85	1.07962
1917.84	3.88969
1918.84	4.84875
1919.83	2.97392
1920.82	2.9684
1921.82	-0.82052
1922.81	1.03997
1923.8	2.898
1924.79	-3.73653
1925.79	0.0507793
1926.78	-0.890322
1927.77	-2.79224
1928.76	3.83333
1929.75	0.99872
1930.75	0.0466537
1931.74	1.91201
1932.73	-0.968126
1933.72	-0.00509834
1934.71	4.81952
1935.7	-0.915705
1936.69	2.85714
1937.68	0.907782
1938.67	2.80507
1939.66	4.70344
1940.65	0.909838
1941.64	-2.95202
1942.63	1.83564
1943.62	1.79323
1944.61	-0.113142
1945.6	4.66752
1946.59	-0.128031
1947.58	3.6668
1948.57	-0.179544
1949.55	4.60643
1950.54	-2.07962
1951.53	-1.11183
1952.52	0.795986
1953.5	0.745663
1954.49	1.62997
1955.48	-1.25172
1956.47	0.681995
1957.45	1.63881
1958.44	6.42382
1959.43	1.57866
1960.41	4.41395
1961.4	0.535513
1962.38	-1.40555
1963.37	2.41208
1964.36	2.3901
1965.34	-0.515108
1966.33	1.40131
1967.31	0.418997
1968.3	1.35336
1969.28	3.21786
1970.26	0.287769
1971.25	2.16619
1972.23	-1.69247
1973.22	3.0576
1974.2	-1.77072
1975.18	-1.78854
1976.17	0.111525
1977.15	1.99719
1978.13	-0.922718
1979.12	1.92409
1980.1	-2.90091
1981.08	-1.02572
1982.06	-2.01864
1983.05	-4.93994
1984.03	1.71828
1985.01	-2.15147
1985.99	2.60984
1986.97	2.58257
1987.95	3.46705
1988.93	1.45881
1989.91	-1.45289
1990.89	4.79089
1991.88	2.22441
1992.86	0.407099
1993.84	3.324
1994.82	1.41604
1995.8	0.908974
1996.78	2.39178
1997.76	-0.243887
1998.73	0.468786
1999.71	-0.193926
2000.69	-0.512751
2001.67	3.23402
2002.65	0.586914
2003.63	0.0375652
2004.6	-0.151237
2005.58	0.0301476
2006.56	1.29363
2007.54	-0.0768394
2008.52	-2.99804
2009.49	1.1494
2010.47	-1.47637
2011.45	-2.64057
2012.42	-0.478876
2013.41	0.393507
2014.4	0.319736
2015.39	2.18498
2016.38	-0.627953
2017.37	-2.5517
2018.35	2.07206
2019.34	0.138355
2020.33	0.107136
2021.32	1.95795
2022.31	2.84973
2023.29	3.73047
2024.28	-1.93339
2025.27	1.74125
2026.25	0.802132
2027.24	-0.0924549
2028.23	-0.177444
2029.21	3.58543
2030.2	0.656437
2031.19	-2.12988
2032.17	1.60938
2033.16	5.3607
2034.14	1.53982
2035.13	0.610247
2036.11	-3.12527
2037.1	0.598621
2038.08	1.49708
2039.07	-0.411816
2040.05	0.471123
2041.03	-0.503336
2042.02	-3.33268
2043	-4.27967
2043.99	-0.542225
2044.97	2.21628
2045.95	-1.44641
2046.94	0.342173
2047.92	0.294775
2048.9	0.295519
2049.88	-4.35597
2050.87	-3.43823
2051.85	1.20955
2052.83	1.20927
2053.81	-1.57969
2054.79	4.9504
2055.78	3.98281
2056.76	-0.711184
2057.74	-1.64704
2058.72	3.04357
2059.7	-0.71307
2060.68	0.208599
2061.66	0.20207
2062.64	3.01417
2063.62	-1.66743
2064.6	-1.66415
2065.58	2.1092
2066.56	-0.706106
2067.54	1.17773
2068.52	3.99911
2069.5	-2.62001
2070.48	0.231251
2071.46	2.14332
2072.43	3.0689
2073.41	-0.705545
2074.39	-0.696335
2075.37	5.95106
2076.35	-0.655613
2077.32	2.13691
2078.3	3.08985
2079.28	-1.6039
2080.26	-0.649382
2081.23	-3.49527
2082.21	3.11922
2083.19	4.05772
2084.16	-2.56022
2085.14	3.10803
2086.12	-2.54145
2087.09	4.09444
2088.07	4.09556
2089.04	4.1081
2090.02	2.22944
2090.99	0.346725
2091.97	-0.567188
2092.94	0.416553
2093.92	3.29177
2094.89	1.38351
2095.87	-0.53157
2096.84	3.25756
2097.81	-0.550343
2098.79	1.34371
2099.76	2.29491
2100.74	0.418386
2101.71	-2.42114
2102.68	1.37055
2103.65	3.26758
2104.63	2.34062
2105.6	4.27057
2106.57	2.38568
2107.54	0.477171
2108.52	3.30626
2109.49	-0.468769
2110.46	5.23953
2111.43	1.43876
2112.4	-0.448044
2113.38	2.4328
2114.35	1.48868
2115.32	-0.406542
2116.29	2.43674
2117.26	2.44367
2118.23	-0.418224
2119.2	-0.431385
2120.17	4.30771
2121.14	2.4483
2122.11	0.589331
2123.08	3.46365
2124.05	1.56174
2125.02	1.52498
2125.98	2.45273
2126.95	2.4446
2127.92	1.50632
2128.89	-2.26072
2129.86	4.36508
2130.83	0.58983
2131.79	1.53659
2132.76	-0.348417
2133.73	1.56155
2134.7	2.52349
2135.67	-2.19099
2136.63	4.41707
2137.6	2.56185
2138.57	0.694246
2139.53	-4.96069
2140.5	-0.241495
2141.46	0.708326
2142.43	2.62038
2143.4	0.695267
2144.36	2.6342
2145.33	-1.11792
2146.29	0.77673
2147.26	4.54424
2148.22	1.73613
2149.19	-1.08317
2150.15	-0.144424
2151.12	3.64062
2152.08	-0.0760593
2153.05	0.870855
2154.01	0.874025
2154.97	6.46343
2155.94	-2.88268
2156.9	1.8157
2157.86	-1.87814
2158.83	-1.85605
2159.79	2.81837
2160.75	0.0290146
2161.72	0.0515442
2162.68	1.00788
2163.64	1.02489
2164.6	2.89944
2165.56	-2.65584
2166.53	1.08653
2167.49	2.94527
2168.45	1.09654
2169.41	-1.63604
2170.37	0.277288
2171.33	1.20248
2172.29	2.13575
2173.25	3.09713
2174.21	1.28061
2175.17	1.30955
2176.13	-1.45332
2177.09	-0.491482
2178.05	-4.18097
2179.01	2.3477
2179.97	5.16698
2180.93	2.4097
2181.89	3.35964
2182.85	2.44907
2183.81	0.605215
2184.76	2.49799
2185.72	0.695454
2186.68	-0.167635
2187.64	4.52645
2188.6	-4.74361
2189.55	-0.0962524
2190.51	0.870905
2191.47	1.84072
2192.42	-2.74962
2193.38	-3.61841
2194.34	2.02132
2195.3	0.182629
2196.25	3.8982
2197.21	-0.71965
2198.16	2.11778
2199.12	-1.52523
2200.07	1.35133
2201.03	3.27202
2201.99	0.397842
2202.94	0.49678
2203.9	-3.1209
2204.85	-3.13236
2205.8	1.53997
2206.76	0.64432
2207.71	0.704287
2208.67	-1.10269
2209.62	-0.1322
2210.58	-0.0790539
2211.53	-0.0215225
2212.48	-0.914383
2213.44	2.84131
2214.39	2.9116
2215.34	0.154819
2216.29	0.189964
2217.25	0.227674
2218.2	-0.666151
2219.15	0.321228
2220.1	-0.572062
2221.06	-4.28738
2222.01	3.20333
2222.96	1.38682
2223.91	-2.28608
2224.86	0.580315
2225.81	-0.295149
2226.76	1.63476
2227.72	1.67388
2228.67	1.70229
2229.62	1.75518
2230.57	-0.0653305
2231.52	0.932074
2232.47	-2.77427
2233.42	2.92344
2234.37	0.131615
2235.31	-0.795364
2236.26	-0.756598
2237.21	3.06346
2238.16	1.25089
2239.11	4.13353
2240.06	0.372557
2241.01	0.429014
2241.96	-0.473745
2242.9	3.33462
2243.85	-0.415886
2244.8	-0.354645
2245.75	2.5357
2246.69	-1.20199
2247.64	5.45638
2248.59	3.58718
2249.53	-2.05449
2250.48	0.79553
2251.43	2.70572
2252.37	1.8096
2253.32	1.87865
2254.26	0.974403
2255.21	1.95047
2256.16	1.99352
2257.1	-3.65762
2258.05	0.174479
2258.99	2.1139
2259.94	-0.700434
2260.88	3.14977
2261.83	1.2805
2262.77	2.27984
2263.71	-0.517975
2264.66	3.35384
2265.6	3.38426
2266.55	3.38253
2267.49	-0.428488
2268.43	1.49909
2269.38	-0.359993
2270.32	3.50956
2271.26	3.55054
2272.2	2.62625
2273.15	2.65355
2274.09	1.72288
2275.03	-0.164829
2275.97	-0.13076
2276.92	-1.04642
2277.86	-0.0340996
2278.8	-0.0147896
2279.74	0.933954
2280.68	-0.98287
2281.62	2.86732
2282.56	2.90652
2283.5	0.0832806
2284.44	-0.834394
2285.38	-0.812916
2286.32	1.11965
2287.26	3.09063
2288.2	-1.71046
2289.14	0.202026
2290.08	3.08253
2291.02	1.19273
2291.96	-0.699398
2292.9	0.296829
2293.84	-1.61711
2294.78	2.2338
2295.72	4.15597
2296.65	1.27171
2297.59	-2.54319
2298.53	4.23511
2299.47	-2.49135
2300.41	0.42
2301.34	2.37013
2302.28	1.4111
2303.22	2.38434
2304.15	-2.41935
2305.09	-1.43233
2306.03	0.519121
2306.97	1.49282
2307.9	-1.40654
2308.84	3.44267
2309.77	-1.36012
2310.71	-0.390711
2311.64	0.538996
2312.58	-1.39445
2313.51	3.46835
2314.45	1.57926
2315.39	-5.19265
2316.32	1.55098
2317.25	-5.19452
2318.19	-1.33167
2319.12	0.593071
2320.06	-0.365038
2320.99	-2.27408
2321.92	-0.309021
2322.86	3.57161
2323.79	-0.283707
2324.72	2.60154
2325.66	4.51815
2326.59	2.57359
2327.52	6.42025
2328.46	14.1368
2329.39	4.49139
2330.32	4.49859
2331.25	0.664619
2332.18	5.48258
2333.12	1.6284
2334.05	-2.2242
2334.98	0.664574
2335.91	0.676666
2336.84	-0.276714
2337.77	2.61482
2338.7	-1.21638
2339.63	-0.245502
2340.56	-0.249474
2341.49	-0.26149
2342.42	1.66062
2343.35	1.67582
2344.28	-1.17928
2345.21	1.70162
2346.14	-2.12218
2347.07	2.6806
2348	-3.99367
2348.93	0.802666
2349.85	0.772419
2350.78	3.68985
2351.71	2.71853
2352.64	0.788658
2353.57	1.76738
2354.5	-1.05018
2355.42	-0.0741005
2356.35	0.878546
2357.28	-2.90683
2358.21	-0.0318928
2359.13	1.89692
2360.06	-0.932568
2360.99	-2.80975
2361.91	1.94625
2362.84	-0.868454
2363.77	-1.77954
2364.69	1.09158
2364.92	2.04511