File: Data/3-Raman/processed/bu19w-e-ff11b-fi08-v_1800 (450-850nm)_532nm_edge_100%_x100_vis_h50um_30sx2_01.txt
#Acq. time (s)=	30
#Accumulations=	2
#Range (cm-¹)=	1200...2400
#Windows=	4
#Auto scanning=	Off
#Autofocus=	Off
#Macrospot=	Off
#AutoExposure=	Off
#Spike filter=	Multiple accum.
#Delay time (s)=	2
#Binning=	1
#Readout mode=	Signal
#DeNoise=	Off
#ICS correction=	On
#Dark correction=	Off
#Inst. Process=	Off
#Detector Gain=	Best Dynamic
#Detector ADC=	50 kHz HS
#Detector temperature (°C)=	-60.09
#Instrument=	LabRAM HR Evol
#Detector=	SIN-EM FIVIS
#Objective=	x100_VIS
#Grating=	1800 (450-850nm)
#ND Filter=	100%
#Laser=	532nm_Edge
#Hole=	49.98
#Temperature=	0
#Range=	Visible
#StageXY=	75x50mm Scan+
#StageZ=	Z motor
#X (µm)=	0
#Y (µm)=	0
#Z (µm)=	-249
#Full time(mm:ss)=	4:28
#Project=	21_11_04
#Sample=	BU19w
#Site=
#Title=	BU19w-E-FF11b-FI08-V_1800 (450-850nm)_532nm_Edge_100%_x100_VIS_H50um_30sX2
#Remark=
#Date=	04.11.2021 17:37
#Acquired=	04.11.2021 17:37:20
#Base:Fit=	16.12.2021 17:39:50
#Base:Fit=	16.12.2021 17:48:07
#Base:Sub=	16.12.2021 17:48:07
1200.19	1.19642
1201.3	-0.383377
1202.41	1.38504
1203.52	1.96775
1204.63	-0.614836
1205.74	5.36691
1206.85	10.2689
1207.97	3.42869
1209.08	1.95568
1210.19	-2.71152
1211.3	3.29633
1212.41	3.97179
1213.52	2.54613
1214.63	2.21861
1215.74	0.816605
1216.85	0.461052
1217.95	1.18959
1219.06	-3.36152
1220.17	-0.473537
1221.28	-2.88884
1222.39	-0.0322571
1223.5	1.76833
1224.61	3.60013
1225.71	1.25529
1226.82	-0.0601425
1227.93	0.670326
1229.03	4.7287
1230.14	-1.84228
1231.25	-2.12374
1232.35	1.86983
1233.46	-0.429428
1234.57	2.5514
1235.67	2.38146
1236.78	1.13044
1237.88	-0.139126
1238.99	-0.332256
1240.1	1.60057
1241.2	0.398022
1242.3	3.39078
1243.41	0.115604
1244.51	1.02161
1245.62	6.08203
1246.72	1.76369
1247.82	1.61819
1248.93	2.54963
1250.03	-0.712238
1251.13	2.28795
1252.24	-3.06047
1253.34	1.00606
1254.44	3.02486
1255.54	3.98392
1256.65	6.00177
1257.75	3.81909
1258.85	4.77362
1259.95	9.93539
1261.05	19.2113
1262.15	40.184
1263.25	38.9836
1264.35	18.1083
1265.45	20.1257
1266.55	11.7428
1267.66	3.38296
1268.75	11.7678
1269.85	12.747
1270.95	17.9133
1272.05	9.54066
1273.15	17.9518
1274.25	7.4717
1275.35	11.661
1276.45	9.57961
1277.54	11.7071
1278.64	26.461
1279.74	49.576
1280.84	138.008
1281.94	501.291
1283.03	662.23
1284.13	175.094
1285.23	55.9655
1286.32	26.4964
1287.42	22.2642
1288.52	17.0158
1289.61	10.7479
1290.71	13.9162
1291.8	8.66411
1292.9	6.57459
1293.99	9.81018
1295.09	-0.686775
1296.18	3.62233
1297.28	8.90651
1298.37	-0.590576
1299.47	4.70253
1300.56	-1.59459
1301.65	-1.54938
1302.75	-1.51785
1303.84	2.73127
1304.94	4.86275
1306.03	-1.46264
1307.12	-4.58583
1308.21	-2.4364
1309.31	0.789387
1310.4	-1.27923
1311.49	-0.169609
1312.58	3.05095
1313.67	-2.19167
1314.76	1.0353
1315.86	1.0944
1316.95	1.14219
1318.04	1.20473
1319.13	-1.91471
1320.22	2.36208
1321.31	0.268028
1322.4	1.35137
1323.49	-1.76047
1324.58	1.46016
1325.67	-2.75217
1326.76	-3.75115
1327.85	0.577457
1328.93	2.76884
1330.02	-0.345181
1331.11	-2.43346
1332.2	3.89791
1333.29	3.90917
1334.37	1.83229
1335.46	0.819893
1336.55	1.91337
1337.64	0.908005
1338.72	4.09524
1339.81	2.07159
1340.9	0.0433731
1341.98	1.13533
1343.07	-1.95851
1344.16	3.33814
1345.24	0.238602
1346.33	-0.785095
1347.41	0.292587
1348.5	3.47223
1349.58	-0.650398
1350.67	1.47197
1351.75	1.52816
1352.84	4.76033
1353.92	5.81651
1355.01	-0.380383
1356.09	3.8524
1357.17	9.1
1358.26	3.95508
1359.34	0.892204
1360.42	7.14492
1361.5	10.3182
1362.59	8.30639
1363.67	14.6165
1364.75	7.41928
1365.83	8.49002
1366.92	8.52299
1368	13.7751
1369.08	33.5048
1370.16	14.9369
1371.24	9.80117
1372.32	12.9123
1373.4	15.0246
1374.48	22.2945
1375.56	19.2832
1376.64	26.5113
1377.72	27.6577
1378.8	36.0365
1379.88	37.0593
1380.96	44.2483
1382.04	54.4613
1383.12	72.8858
1384.2	114.994
1385.28	344.169
1386.36	1646.91
1387.43	434.646
1388.51	114.417
1389.59	54.943
1390.67	34.3948
1391.74	30.3258
1392.82	28.3158
1393.9	26.3231
1394.97	25.3869
1396.05	20.3405
1397.13	23.45
1398.2	14.3236
1399.28	9.29747
1400.35	17.5812
1401.43	18.6909
1402.5	17.8334
1403.58	16.8764
1404.65	21.029
1405.73	28.2415
1406.8	50.8655
1407.88	79.6677
1408.95	49.0033
1410.03	23.4218
1411.1	15.2454
1412.17	15.3372
1413.25	13.3939
1414.32	5.27932
1415.39	8.43183
1416.47	9.54348
1417.54	3.46189
1418.61	5.59099
1419.68	5.63977
1420.75	6.70714
1421.83	5.77374
1422.9	4.90852
1423.97	1.7084
1425.04	11.034
1426.11	1.88406
1427.18	7.03129
1428.25	4.0136
1429.32	2.0462
1430.39	5.22198
1431.46	6.34123
1432.53	7.39748
1433.6	4.3414
1434.67	2.37931
1435.74	2.43878
1436.81	-0.580515
1437.88	4.60251
1438.95	5.70156
1440.01	4.76523
1441.08	-4.40116
1442.15	5.91906
1443.22	0.84346
1444.29	6.04268
1445.35	-0.0415936
1446.42	-3.06607
1447.49	0.0604
1448.56	2.18517
1449.62	2.23157
1450.69	3.30503
1451.75	2.32905
1452.82	0.344467
1453.89	2.45085
1454.95	1.48131
1456.02	-0.50231
1457.08	1.59091
1458.15	3.69608
1459.21	-2.39035
1460.28	1.75644
1461.34	0.773294
1462.41	0.807076
1463.47	-2.22113
1464.53	-1.09813
1465.6	-1.1355
1466.66	-3.13265
1467.72	-1.04276
1468.79	-4.05459
1469.85	-1.98043
1470.91	2.13484
1471.97	-1.89658
1473.04	-0.834709
1474.1	0.227541
1475.16	2.31755
1476.22	1.33893
1477.29	0.361023
1478.34	1.41366
1479.41	2.45864
1480.47	2.47906
1481.53	-4.57276
1482.59	0.563837
1483.65	2.64218
1484.71	-6.51417
1485.77	-4.40696
1486.83	-4.36566
1487.89	4.77643
1488.95	2.77764
1490.01	1.80691
1491.07	-2.20762
1492.12	0.86985
1493.18	-1.11085
1494.24	2.98108
1495.3	4.00836
1496.36	3.02285
1497.42	-0.975061
1498.47	1.08839
1499.53	3.15798
1500.59	5.21739
1501.64	3.22968
1502.7	2.24706
1503.76	1.27561
1504.81	1.31247
1505.87	3.34635
1506.93	-0.637556
1507.98	2.42264
1509.04	2.46354
1510.09	2.50101
1511.15	2.50649
1512.21	2.49355
1513.26	2.51367
1514.31	0.557646
1515.37	6.58697
1516.42	1.59158
1517.48	3.63616
1518.53	1.67601
1519.58	3.72221
1520.64	3.75962
1521.69	2.78975
1522.75	4.81485
1523.8	2.81333
1524.85	-1.16094
1525.9	2.89808
1526.95	7.94364
1528.01	4.9597
1529.06	2.98218
1530.11	2.01087
1531.16	5.06228
1532.21	2.08977
1533.27	5.15764
1534.32	2.17631
1535.37	-3.83004
1536.42	7.18387
1537.47	4.19397
1538.52	3.20811
1539.57	1.29257
1540.62	4.35397
1541.67	-4.65882
1542.72	4.35912
1543.77	0.365154
1544.81	-1.58637
1545.86	2.46344
1546.91	3.50078
1547.96	2.50695
1549.01	2.48869
1550.06	5.61184
1551.1	4.66764
1552.15	2.69384
1553.2	0.679495
1554.25	1.68164
1555.3	7.70688
1556.34	6.72783
1557.39	2.74614
1558.43	1.73908
1559.48	5.73823
1560.53	4.75213
1561.57	2.79347
1562.62	0.818151
1563.66	9.85286
1564.71	5.84997
1565.76	1.86503
1566.8	9.9048
1567.84	6.91957
1568.89	6.92902
1569.93	8.9479
1570.98	3.96586
1572.02	4.97075
1573.07	5.97066
1574.11	7.99947
1575.15	6.04679
1576.2	5.05852
1577.24	1.04661
1578.28	5.03425
1579.32	7.04924
1580.37	6.07327
1581.41	7.06836
1582.45	6.07805
1583.49	6.08919
1584.53	4.11946
1585.58	4.12884
1586.62	2.13431
1587.66	7.12059
1588.7	8.14622
1589.74	8.16889
1590.78	4.20798
1591.82	7.19526
1592.86	6.18288
1593.9	8.15212
1594.94	5.2009
1595.98	10.1662
1597.02	4.22701
1598.06	7.21072
1599.1	9.18339
1600.14	11.1566
1601.17	4.19505
1602.21	11.0816
1603.25	6.97004
1604.29	6.05387
1605.33	8.54265
1606.37	6.25261
1607.4	7.20953
1608.44	7.90463
1609.48	4.41854
1610.51	6.86205
1611.55	6.41452
1612.59	7.21797
1613.62	6.87283
1614.66	8.84301
1615.7	10.4952
1616.73	8.16334
1617.77	6.77895
1618.8	6.61406
1619.84	7.16735
1620.87	7.40537
1621.91	7.73243
1622.94	7.11204
1623.98	8.07424
1625.01	7.76644
1626.04	4.17163
1627.08	5.62638
1628.11	6.13378
1629.07	4.32072
1630.12	5.30688
1631.16	8.27341
1632.21	9.28776
1633.25	10.2614
1634.3	11.2657
1635.34	4.36657
1636.39	9.28438
1637.43	9.27635
1638.48	4.35352
1639.52	8.29578
1640.57	7.32833
1641.61	7.32664
1642.65	7.32724
1643.7	10.2769
1644.74	5.35781
1645.78	10.2837
1646.83	4.37391
1647.87	5.35885
1648.91	7.36121
1649.95	8.35831
1651	6.41273
1652.04	9.37634
1653.08	3.46008
1654.12	1.5001
1655.16	7.44092
1656.21	7.46831
1657.25	3.51795
1658.29	5.48372
1659.33	6.45565
1660.37	4.49459
1661.41	2.54265
1662.45	5.55957
1663.49	7.46521
1664.53	6.5314
1665.57	6.55637
1666.61	7.4481
1667.65	6.49922
1668.69	1.59253
1669.72	7.51896
1670.76	5.56904
1671.8	-0.358093
1672.84	2.61085
1673.88	8.55648
1674.92	9.56672
1675.95	6.60306
1676.99	5.61449
1678.03	6.58566
1679.07	7.5613
1680.1	3.59847
1681.14	5.56962
1682.18	0.631718
1683.21	5.57035
1684.25	4.57445
1685.29	5.56049
1686.32	3.59581
1687.36	4.58103
1688.39	2.59401
1689.43	5.53495
1690.46	3.56723
1691.5	1.60247
1692.53	4.55157
1693.57	0.582977
1694.6	6.4816
1695.64	3.53372
1696.67	5.50692
1697.7	-0.425898
1698.74	-3.38881
1699.77	4.48416
1700.81	-0.442789
1701.84	1.50872
1702.87	0.515749
1703.9	4.44431
1704.94	1.49717
1705.97	-0.477533
1707	3.42591
1708.03	2.41316
1709.06	0.430155
1710.1	1.40906
1711.13	7.29586
1712.16	2.38776
1713.19	-0.585426
1714.22	2.32974
1715.25	-0.593092
1716.28	3.30147
1717.31	2.28381
1718.34	3.22517
1719.37	-0.674063
1720.4	2.24137
1721.43	4.163
1722.46	0.249836
1723.49	-0.731853
1724.52	3.13536
1725.55	0.193008
1726.58	2.12359
1727.6	-1.75568
1728.63	3.95893
1729.66	0.120237
1730.69	0.127028
1731.72	4.95777
1732.74	0.111567
1733.77	1.04294
1734.8	-0.914043
1735.82	0.0333405
1736.85	0.0209866
1737.88	-5.76242
1738.91	0.943598
1739.93	-1.01309
1740.96	1.83931
1741.98	-0.0877018
1743.01	4.6919
1744.03	-2.97859
1745.06	-3.93555
1746.09	-1.08132
1747.11	2.71589
1748.13	0.798929
1749.16	-0.145952
1750.18	3.69742
1751.21	-0.125799
1752.23	1.76055
1753.26	-1.12113
1754.28	0.769522
1755.3	0.75643
1756.33	-1.17233
1757.35	-2.13964
1758.37	-1.17807
1759.39	-1.17678
1760.42	-1.18479
1761.44	-0.247641
1762.46	-2.14437
1763.48	3.56375
1764.5	0.731764
1765.53	-0.212509
1766.55	-0.215868
1767.57	0.727133
1768.59	-2.14343
1769.61	-1.2183
1770.63	0.695606
1771.65	-0.235453
1772.67	0.731972
1773.69	0.742136
1774.71	-3.05822
1775.73	-0.177027
1776.75	-2.08998
1777.77	-3.05487
1778.79	0.733736
1779.81	2.64412
1780.83	-0.203428
1781.85	2.66626
1782.86	1.72986
1783.88	0.792915
1784.9	0.804579
1785.92	0.800999
1786.94	0.821581
1787.95	-0.079319
1788.97	0.907156
1789.99	-0.035717
1791	-1.96994
1792.02	-1.01268
1793.04	-1.00476
1794.05	0.916521
1795.07	1.91504
1796.09	0.0152073
1797.1	-1.88801
1798.12	0.0451679
1799.13	0.0391254
1800.15	4.83036
1801.16	-3.81613
1802.18	-0.924335
1803.19	1.01791
1804.21	0.0696011
1805.22	2.0191
1806.24	0.110865
1807.25	2.04359
1808.26	2.04856
1809.28	5.91154
1810.29	-1.79812
1811.3	-3.72528
1812.32	-2.75151
1813.33	-1.77316
1814.34	4.04905
1815.36	0.19833
1816.37	0.206221
1817.38	0.186604
1818.39	-1.72856
1819.4	-1.71911
1820.42	5.06374
1821.43	0.243685
1822.44	-1.68178
1823.45	3.1568
1824.46	-1.67352
1825.47	3.17798
1826.48	-1.65931
1827.49	2.22779
1828.5	1.2547
1829.51	-0.683699
1830.52	-0.686895
1831.53	-0.671803
1832.54	3.22238
1833.55	0.322073
1834.56	1.26392
1835.57	2.2126
1836.58	2.26816
1837.58	0.269402
1838.59	2.25541
1839.6	1.30964
1840.61	-3.58619
1841.62	1.21125
1842.62	-1.6907
1843.63	-2.65165
1844.64	-3.61253
1845.65	0.271917
1846.65	1.21033
1847.66	0.226179
1848.67	2.14635
1849.67	2.12246
1850.68	1.13876
1851.68	-1.74833
1852.69	1.13555
1853.69	0.163818
1854.7	1.10635
1855.71	-0.825596
1856.71	0.134394
1857.72	2.04181
1858.72	2.98005
1859.72	2.01807
1860.73	-2.74558
1861.73	0.135601
1862.74	0.120527
1863.74	2.01725
1864.74	-0.862253
1865.75	1.97018
1866.75	-0.920721
1867.75	-1.88636
1868.76	-0.930967
1869.76	-5.6837
1870.76	0.0211143
1871.76	0.0146866
1872.77	-2.84273
1873.77	-0.000606537
1874.77	1.87714
1875.77	4.68305
1876.77	0.873156
1877.77	-2.83995
1878.78	2.82192
1879.78	-1.91636
1880.78	-2.86145
1881.78	-2.89576
1882.78	0.856636
1883.78	2.72304
1884.78	2.75022
1885.78	-1.94166
1886.78	2.76841
1887.78	0.861359
1888.77	0.835131
1889.77	2.72081
1890.77	1.7947
1891.77	-4.79713
1892.77	0.838148
1893.77	0.820091
1894.76	-0.126314
1895.76	3.64795
1896.76	4.6104
1897.76	1.7946
1898.75	0.840288
1899.75	-0.106354
1900.75	0.845078
1901.75	0.869797
1902.74	-2.88814
1903.74	-0.0686722
1904.74	-1.94753
1905.73	-1.01804
1906.73	-0.0831203
1907.72	3.68864
1908.72	1.8245
1909.71	-0.0257339
1910.71	1.88514
1911.7	-0.935236
1912.7	3.77715
1913.69	0.975775
1914.69	3.83027
1915.68	-0.881344
1916.68	-1.83241
1917.67	2.88091
1918.66	-2.75236
1919.66	-0.833597
1920.65	3.90271
1921.64	-0.805632
1922.64	1.08106
1923.63	-2.70428
1924.62	-0.815529
1925.61	-0.79077
1926.61	-0.76404
1927.6	2.09321
1928.59	3.05595
1929.58	1.18748
1930.57	1.21184
1931.57	1.20819
1932.56	-0.695822
1933.55	0.274664
1934.54	1.30221
1935.53	2.27258
1936.52	3.21907
1937.51	4.15378
1938.5	2.26119
1939.49	-1.53084
1940.48	1.36096
1941.47	1.3589
1942.46	2.34345
1943.45	-2.44984
1944.44	-0.510309
1945.42	4.29378
1946.41	-0.471861
1947.4	-1.42958
1948.39	1.44205
1949.38	1.46599
1950.37	-1.37044
1951.35	-2.29657
1952.34	-0.363197
1953.33	-0.366856
1954.32	-0.409548
1955.3	4.39199
1956.29	0.600451
1957.28	1.58277
1958.26	2.55522
1959.25	-0.334408
1960.23	3.49564
1961.22	0.604664
1962.21	-0.348209
1963.19	5.41806
1964.18	4.4676
1965.16	2.54872
1966.15	4.49188
1967.13	0.656593
1968.12	3.54641
1969.1	1.60585
1970.09	2.54693
1971.07	3.49556
1972.05	-2.25396
1973.04	0.61478
1974.02	4.44173
1975.01	0.616297
1975.99	2.54706
1976.97	1.58842
1977.95	6.37019
1978.94	-1.29919
1979.92	4.45261
1980.9	2.52346
1981.88	0.604206
1982.87	3.4568
1983.85	-1.33533
1984.83	-1.34671
1985.81	1.48589
1986.79	-1.2441
1987.77	4.96443
1988.75	2.46673
1989.73	0.291931
1990.72	1.23116
1991.7	-0.174702
1992.68	-0.0488777
1993.66	3.19151
1994.63	-0.499557
1995.61	1.85579
1996.59	1.57965
1997.57	-0.595919
1998.55	0.427467
1999.53	-0.748943
2000.51	1.03845
2001.49	1.62206
2002.47	1.5302
2003.45	1.34263
2004.42	-0.485437
2005.4	-0.589861
2006.38	-1.26891
2007.36	-0.775158
2008.31	-0.643579
2009.3	-1.60986
2010.29	-1.62587
2011.28	-0.686079
2012.27	-0.691669
2013.26	-0.720858
2014.24	1.11833
2015.23	-1.69112
2016.22	-1.66982
2017.21	0.200754
2018.2	-0.770374
2019.18	-3.60809
2020.17	2.00597
2021.16	-1.73839
2022.15	1.99586
2023.14	-0.833448
2024.12	-0.854607
2025.11	1.91739
2026.1	0.0508823
2027.08	-0.825224
2028.07	0.0228462
2029.06	-0.81535
2030.04	0.966494
2031.03	-0.887432
2032.01	1.92879
2033	2.89085
2033.98	0.996845
2034.97	0.991432
2035.95	2.8972
2036.94	1.95831
2037.92	0.0778236
2038.91	3.79868
2039.89	0.973433
2040.87	1.88498
2041.86	0.942938
2042.84	0.00656891
2043.83	2.83204
2044.81	-0.00827599
2045.79	-2.70582
2046.78	0.0400753
2047.76	-0.920918
2048.74	0.95433
2049.72	0.0464439
2050.71	0.987602
2051.69	0.0428734
2052.67	0.987129
2053.65	1.94736
2054.63	1.01247
2055.62	1.00037
2056.6	0.0588436
2057.58	-0.867924
2058.56	-1.78673
2059.54	-0.846647
2060.52	0.0837212
2061.5	0.0892067
2062.48	1.03344
2063.46	1.98321
2064.44	2.93062
2065.42	-0.798042
2066.4	1.0896
2067.38	-2.65842
2068.36	3.93045
2069.34	-3.60975
2070.31	2.98943
2071.29	-0.740589
2072.27	2.08226
2073.25	1.13765
2074.23	0.204676
2075.21	-1.64701
2076.18	-2.58118
2077.16	3.05645
2078.14	1.17745
2079.12	2.14345
2080.09	-0.676836
2081.07	3.09726
2082.05	-0.680511
2083.02	0.263458
2084	0.261908
2084.98	-1.62781
2085.95	1.22289
2086.93	0.289749
2087.9	0.291677
2088.88	3.13854
2089.85	2.20467
2090.83	2.21361
2091.8	-0.608368
2092.78	1.31611
2093.75	3.23735
2094.73	-1.51913
2095.7	1.31793
2096.68	2.25972
2097.65	2.24653
2098.62	-0.606846
2099.6	2.23739
2100.57	-1.54975
2101.54	0.356409
2102.52	-1.54942
2103.49	1.29016
2104.46	4.14877
2105.44	3.21732
2106.41	-0.578022
2107.38	0.367126
2108.35	-3.45399
2109.32	2.25377
2110.3	-1.54628
2111.27	-2.50131
2112.24	0.347281
2113.21	-2.48888
2114.18	-1.54062
2115.15	-1.54253
2116.12	-0.604717
2117.09	-2.50639
2118.06	1.27466
2119.03	-1.59147
2120	-0.655397
2120.97	0.304684
2121.94	2.22184
2122.91	-1.56386
2123.88	0.326836
2124.85	0.291155
2125.82	-2.57429
2126.79	-1.6447
2127.76	2.1306
2128.72	-1.65209
2129.69	0.23349
2130.66	1.17036
2131.63	-0.729837
2132.6	2.08893
2133.56	-0.739374
2134.53	3.98033
2135.5	1.14111
2136.47	0.183756
2137.43	-1.69252
2138.4	-0.756516
2139.37	-2.64902
2140.33	1.10891
2141.3	0.159737
2142.26	-0.781504
2143.23	0.10774
2144.19	2.02027
2145.16	0.133961
2146.13	-1.7518
2147.09	1.99836
2148.06	-0.828754
2149.02	0.0947189
2149.98	1.00955
2150.95	1.95245
2151.91	1.96467
2152.88	0.0764008
2153.84	-2.74608
2154.8	1.90063
2155.77	0.943218
2156.73	1.87597
2157.69	0.02211
2158.66	-0.913074
2159.62	0.00674057
2160.58	-0.00769424
2161.54	0.92131
2162.51	-0.944868
2163.47	-0.0197411
2164.43	-0.965883
2165.39	-0.0276604
2166.35	-0.0337982
2167.32	3.67143
2168.28	0.857391
2169.24	0.8766
2170.2	0.902517
2171.16	-0.975256
2172.12	0.857038
2173.08	0.856071
2174.04	1.79606
2175	-0.0617542
2175.96	-2.85154
2176.92	-0.993797
2177.88	-2.85057
2178.84	0.858538
2179.8	0.861979
2180.76	-0.06744
2181.72	0.855883
2182.68	-0.0802784
2183.63	-1.02313
2184.59	-0.0935955
2185.55	1.7743
2186.51	2.72872
2187.47	-0.962664
2188.43	0.882238
2189.38	-6.5565
2190.34	-0.0635185
2191.3	1.79955
2192.25	3.66712
2193.21	2.76196
2194.17	0.0115986
2195.12	-0.924109
2196.08	-0.0169964
2197.04	5.53569
2197.99	-0.943604
2198.95	2.80165
2199.9	-0.874235
2200.86	0.0910339
2201.81	-0.946011
2202.77	0.0512638
2203.72	0.113846
2204.68	-0.84733
2205.63	0.0579948
2206.59	-0.868685
2207.54	1.94311
2208.49	0.102657
2209.45	0.10981
2210.4	1.05682
2211.36	2.94248
2212.31	-0.77599
2213.26	1.08184
2214.22	-1.68907
2215.17	-0.745066
2216.12	0.192556
2217.07	-0.737507
2218.03	1.13591
2218.98	-2.58267
2219.93	-1.6382
2220.88	-3.51128
2221.83	-1.65435
2222.78	-2.57648
2223.74	-3.48707
2224.69	-1.59353
2225.64	1.24052
2226.59	0.325441
2227.54	1.27419
2228.49	0.33478
2229.44	-2.46553
2230.39	-1.50682
2231.34	2.27367
2232.29	0.416153
2233.24	1.37801
2234.19	-1.43915
2235.14	-0.51347
2236.09	-0.504992
2237.04	0.452406
2237.98	1.43148
2238.93	-1.37218
2239.88	2.38738
2240.83	2.4102
2241.78	0.533884
2242.73	3.37443
2243.67	0.537561
2244.62	0.562344
2245.57	-3.19404
2246.52	-1.28643
2247.46	1.56202
2248.41	2.50653
2249.36	-0.324104
2250.3	1.55925
2251.25	-0.34211
2252.2	-3.16517
2253.14	-0.290672
2254.09	0.676577
2255.03	-0.2691
2255.98	-1.20462
2256.92	-2.1371
2257.87	0.721907
2258.81	0.735456
2259.76	-3.05474
2260.7	-2.08778
2261.65	-0.174286
2262.59	4.60459
2263.54	-2.9861
2264.48	-1.05058
2265.42	0.871485
2266.37	-0.0985298
2267.31	-1.06494
2268.26	-3.93111
2269.2	-2.00373
2270.14	0.887648
2271.08	0.904694
2272.03	4.7437
2272.97	-2.90374
2273.91	0.930601
2274.85	-0.97683
2275.79	-0.00811386
2276.74	1.93079
2277.68	1.00811
2278.62	-1.86739
2279.56	0.99259
2280.5	0.016613
2281.44	-1.90332
2282.38	2.90719
2283.32	-3.78107
2284.26	2.01376
2285.2	2.02757
2286.14	-0.869507
2287.08	-2.77016
2288.02	2.04958
2288.96	2.02622
2289.9	6.81068
2290.84	-1.83122
2291.78	1.07539
2292.72	1.09504
2293.66	0.137007
2294.6	3.97721
2295.54	-1.81225
2296.47	1.06289
2297.41	3.00904
2298.35	3.03176
2299.29	-0.808296
2300.23	1.12379
2301.16	-0.795523
2302.1	-3.69401
2303.04	-2.73002
2303.97	1.14112
2304.91	-3.67631
2305.85	-0.769596
2306.78	-3.66867
2307.72	2.1216
2308.65	2.12523
2309.59	-1.72075
2310.53	1.18081
2311.46	1.13959
2312.4	-1.77028
2313.33	2.10953
2314.27	-0.760138
2315.2	2.14012
2316.14	-0.787378
2317.07	1.14395
2318	2.10881
2318.94	4.02526
2319.87	4.02273
2320.81	1.13848
2321.74	5.9948
2322.67	2.13882
2323.61	6.01378
2324.54	5.03048
2325.47	10.7986
2326.41	31.9942
2327.34	146.659
2328.27	81.116
2329.2	11.6926
2330.13	4.95113
2331.07	2.06701
2332	2.06789
2332.93	1.09554
2333.86	3.01155
2334.79	1.07856
2335.72	0.121222
2336.66	-3.72596
2337.59	1.08027
2338.52	2.04449
2339.45	0.125071
2340.38	2.99672
2341.31	3.93041
2342.24	2.0039
2343.17	0.0907326
2344.1	0.0995636
2345.02	0.0988464
2345.95	-0.866125
2346.88	3.92354
2347.81	2.00414
2348.74	0.886406
2349.67	1.69703
2350.6	-0.961773
2351.53	-1.29684
2352.45	-0.329372
2353.38	1.5844
2354.31	0.100924
2355.24	-0.250889
2356.17	1.33209
2357.09	1.73885
2358.02	0.695951
2358.95	0.833796
2359.87	-1.93566
2360.8	-1.37009
2361.73	-1.76785
2362.65	1.01164
2363.58	0.203363
2364.5	-1.7671
2365.43	0.555323
2366.36	0.159758
2367.28	-2.96517
2368.2	1.38687
2368.98	1.11089
2369.92	0.173441
2370.86	0.184784
2371.79	1.14428
2372.73	-1.6614
2373.67	2.12288
2374.6	2.13931
2375.54	0.280743
2376.48	1.24409
2377.41	0.33259
2378.35	1.29239
2379.28	0.369801
2380.22	-1.47202
2381.15	-2.36764
2382.09	2.35516
2383.02	-1.34781
2383.96	-1.30158
2384.89	-0.323206
2385.83	-2.15956
2386.76	2.53971
2387.69	-2.08536
2388.63	2.63162
2389.56	-0.112667
2390.5	-0.0507584
2391.43	2.81204
2392.36	-1.79363
2393.3	0.107149
2394.23	-2.63054
2395.16	0.237865
2396.09	0.368471
2397.02	0.432768
2397.96	-1.35459
2398.89	1.52212
2399.82	-3.05638