File: Data/3-Raman/processed/bu19(2)w-a-ff1-fi01-l_150 (500nm)_532nm_edge_10%_x100_vis_lwd_h50um_30sx2_01.txt
#Acq. time (s)=	30
#Accumulations=	2
#Range (cm-¹)=	99...4000
#Windows=	1
#Auto scanning=	Off
#Autofocus=	Off
#Macrospot=	Off
#AutoExposure=	Off
#Spike filter=	Multiple accum.
#Delay time (s)=	2
#Binning=	1
#Readout mode=	Signal
#DeNoise=	Off
#ICS correction=	On
#Dark correction=	Off
#Inst. Process=	Off
#Detector Gain=	Best Dynamic
#Detector ADC=	50 kHz HS
#Detector temperature (°C)=	-60.09
#Instrument=	LabRAM HR Evol
#Detector=	SIN-EM FIVIS
#Objective=	x100_VIS_LWD
#Grating=	150 (500nm)
#ND Filter=	10%
#Laser=	532nm_Edge
#Hole=	49.98
#Temperature=	0
#Range=	Visible
#StageXY=	75x50mm Scan+
#StageZ=	Z motor
#X (µm)=	0
#Y (µm)=	0
#Z (µm)=	-47.8
#Full time(mm:ss)=	1:05
#Project=	21_11_26
#Sample=	BU19(2)w
#Site=
#Title=	BU19(2)w-A-FF1-FI01-L_150 (500nm)_532nm_Edge_10%_x100_VIS_LWD_H50um_30sX2
#Remark=
#Date=	26.11.2021 11:48
#Acquired=	26.11.2021 11:48:55
#Base:Fit=	16.12.2021 16:00:56
#Base:Edit=	16.12.2021 16:02:29
#Base:Edit=	16.12.2021 16:02:33
#Peaks:Remove=	16.12.2021 16:02:34
#Peaks:Remove=	16.12.2021 16:02:39
#Peaks:Remove=	16.12.2021 16:02:41
#Base:Edit=	16.12.2021 16:02:42
#Base:Sub=	16.12.2021 16:02:50
102.91	11.6461
107.534	0.0249939
112.156	26.4742
116.775	50.9846
121.392	105.932
126.005	103.385
130.617	59.9216
135.227	44.7035
139.835	39.0709
144.439	89.7287
149.042	198.908
153.643	354.185
158.242	479.556
162.839	403.617
167.431	257.744
172.023	130.149
176.613	84.4038
181.198	50.6735
185.783	38.7233
190.366	26.5237
194.947	11.6311
199.524	13.6181
204.1	5.57832
208.674	8.3089
213.243	53.6256
217.813	120.742
222.38	159.517
226.945	77.0013
231.506	30.9582
236.066	32.4052
240.625	83.7165
245.179	159.151
249.732	88.0018
254.284	54.5601
258.831	22.2462
263.378	16.5931
267.923	3.52706
272.464	9.76482
277.004	8.59617
281.54	3.69336
286.076	9.62453
290.61	15.5158
295.139	28.641
299.669	8.88013
304.196	-0.0889206
308.718	5.40415
313.241	14.2777
317.759	13.303
322.278	9.91327
326.794	24.4436
331.305	25.3515
335.817	39.5306
340.324	63.3828
344.832	80.6432
349.334	69.3184
353.837	75.2673
358.338	87.9719
362.834	105.651
367.33	82.4612
371.822	56.6612
376.314	45.723
380.802	46.6115
385.289	54.4802
389.772	63.61
394.255	108.511
398.734	169.416
403.213	243.293
407.688	223.826
412.162	215.949
416.632	172.638
421.102	150.988
425.568	140.236
430.033	135.308
434.495	137.467
438.956	159.755
443.413	158.599
447.87	155.008
452.323	142.331
456.776	155.444
461.224	173.566
465.673	158.5
470.117	124.057
474.561	99.1456
479.001	62.4768
483.438	62.0689
487.876	54.8353
492.309	69.7766
496.742	58.9738
501.172	93.356
505.601	127.824
510.025	176.281
514.448	248.979
518.871	298.515
523.289	314.641
527.707	277.691
532.121	238.466
536.533	195.783
540.945	162.313
545.353	161.24
549.758	181.056
554.164	162.563
558.565	165.983
562.965	157.274
567.364	148.803
571.759	122.702
576.151	102.147
580.544	80.894
584.933	78.2063
589.319	64.2741
593.706	70.721
598.088	85.4546
602.468	92.1261
606.848	115.684
611.224	130.611
615.598	165.16
619.972	232.817
624.341	378.057
628.709	607.2
633.074	622.348
637.44	405.279
641.801	232.902
646.16	151.797
650.517	106.061
654.874	65.9972
659.227	46.3179
663.578	43.8615
667.927	24.3823
672.275	18.5621
676.62	20.6455
680.962	14.8545
685.302	14.6907
689.643	18.9921
693.979	10.0435
698.313	13.7365
702.645	17.2212
706.975	18.3822
711.305	32.1739
715.631	19.0687
719.955	17.0913
724.276	24.085
728.596	15.4627
732.913	23.5595
737.231	12.5189
741.544	9.2523
745.856	4.78638
750.165	0.495388
754.472	8.54557
758.778	6.26855
763.081	4.01373
767.384	6.21344
771.683	2.93803
775.98	7.37508
780.275	1.87809
784.568	5.28323
788.859	2.10508
793.147	0.0605621
797.434	3.49748
801.719	4.75829
806.004	6.06893
810.284	14.0042
814.563	3.25971
818.839	4.62464
823.114	8.19316
827.386	12.8862
831.657	26.4059
835.925	28.9243
840.192	33.6471
844.456	39.47
848.719	65.1252
852.979	79.6709
857.237	80.9767
861.493	74.5678
865.748	54.9346
870	57.297
874.25	42.0585
878.499	33.4202
882.745	35.7398
886.989	42.3842
891.231	50.0311
895.471	41.3062
899.71	25.1964
903.946	19.0335
908.18	12.7721
912.412	4.28344
916.642	7.74841
920.87	12.2723
925.096	9.21503
929.321	6.13769
933.543	-0.0818367
937.763	7.65213
941.981	-0.714867
946.197	4.83748
950.412	9.30206
954.622	3.1105
958.832	5.45647
963.04	3.55098
967.246	5.90267
971.451	6.13404
975.653	6.37514
979.853	9.80014
984.052	8.99537
988.248	11.3647
992.442	10.5611
996.633	14.031
1000.82	19.6608
1005.01	25.3146
1009.2	35.2411
1013.38	33.4912
1017.57	33.8441
1021.75	16.0643
1025.92	21.7152
1030.1	18.8039
1034.27	20.1407
1038.45	22.4774
1042.62	29.0304
1046.78	40.8797
1050.95	47.3491
1055.12	55.8906
1059.28	61.1912
1063.44	56.9394
1067.6	57.9394
1071.75	53.6774
1075.91	73.4685
1080.06	81.6676
1084.21	100.153
1088.36	123.697
1092.51	175.995
1096.65	258.907
1100.8	347.652
1104.94	449.319
1109.08	383.221
1113.21	252.257
1117.35	164.488
1121.48	98.4913
1125.61	70.2874
1129.74	62.4801
1133.87	61.839
1137.99	72.4462
1142.12	79.9943
1146.24	97.8773
1150.36	126.079
1154.48	151.153
1158.59	143.158
1162.71	127.888
1166.82	89.854
1170.93	71.4045
1175.04	50.8734
1179.14	29.3269
1183.25	30.4535
1187.35	28.4714
1191.45	16.1976
1195.55	23.4045
1199.65	11.1548
1203.74	8.11966
1207.83	8.14226
1211.92	11.2024
1216.01	7.17613
1220.1	11.232
1224.19	8.23763
1228.27	14.2883
1232.35	13.3243
1236.43	7.39787
1240.51	17.4902
1244.58	10.5815
1248.66	4.69254
1252.73	14.7972
1256.8	9.93312
1260.87	16.0631
1264.93	12.2035
1269	21.3598
1273.06	18.5125
1277.12	12.6458
1281.18	7.76634
1285.23	7.89553
1289.29	11.0341
1293.34	13.1625
1297.39	5.21059
1301.44	9.33889
1305.49	6.40413
1309.53	7.49579
1313.58	10.597
1317.62	6.62657
1321.66	7.68498
1325.7	5.70721
1329.73	9.75644
1333.77	6.76406
1337.8	7.77445
1341.83	4.77123
1345.86	11.7598
1349.88	8.75194
1353.91	8.73957
1357.93	15.6804
1361.95	8.71084
1365.97	9.68953
1369.99	18.5765
1374	35.3452
1378.02	44.1957
1382.03	29.3991
1386.04	15.6335
1390.05	11.729
1394.05	13.7414
1398.06	10.8485
1402.06	3.02376
1406.06	3.07412
1410.06	2.14096
1414.05	0.222666
1418.05	2.24863
1422.04	4.2751
1426.03	7.28535
1430.02	2.3768
1434.01	4.38277
1438	3.4249
1441.98	5.42855
1445.96	6.43835
1449.94	7.44463
1453.92	4.49753
1457.9	0.563305
1461.87	2.53872
1465.85	4.49975
1469.82	3.50469
1473.78	-0.430422
1477.75	0.543032
1481.72	7.38844
1485.68	6.38548
1489.65	7.33645
1493.61	-0.495911
1497.56	2.41333
1501.52	2.39786
1505.47	3.36018
1509.43	2.38588
1513.38	6.27132
1517.33	2.38793
1521.27	3.36316
1525.22	1.42982
1529.16	3.37834
1533.11	4.36037
1537.05	6.31198
1540.98	0.511053
1544.92	3.43251
1548.86	6.35328
1552.79	9.27318
1556.72	4.43925
1560.65	2.50763
1564.58	5.41236
1568.5	6.37627
1572.43	6.36992
1576.35	10.2258
1580.27	8.28471
1584.19	3.45296
1588.1	12.1145
1592.02	9.20925
1595.93	13.0406
1599.84	9.1785
1603.75	13.9671
1607.66	9.16077
1611.57	10.1151
1615.47	15.863
1619.37	12.9903
1623.27	13.9479
1627.17	15.8689
1631.07	16.8381
1634.97	13.0362
1638.86	15.9327
1642.75	13.0966
1646.64	13.1415
1650.53	12.232
1654.42	17.0807
1658.3	13.2912
1662.18	12.3777
1666.07	10.4945
1669.94	12.4516
1673.82	10.5513
1677.7	13.4555
1681.57	11.5322
1685.44	12.4814
1689.31	8.63114
1693.18	0.950794
1697.05	5.72044
1700.92	7.60617
1704.78	4.71136
1708.64	6.57869
1712.5	4.6331
1716.36	2.69641
1720.21	1.71528
1724.07	5.45843
1727.92	6.35829
1731.77	4.43003
1735.62	2.51347
1739.47	6.2154
1743.32	8.96296
1747.16	4.25171
1751.01	4.22689
1754.85	0.501745
1758.69	4.22061
1762.52	2.4239
1766.36	8.03121
1770.19	1.58107
1774.02	1.64415
1777.85	2.63939
1781.68	6.4438
1785.51	1.8637
1789.33	5.68803
1793.16	3.90703
1796.98	3.99744
1800.8	5.02687
1804.62	5.09758
1808.43	3.28218
1812.25	5.23084
1816.06	4.34694
1819.87	-0.325659
1823.68	-1.2319
1827.49	-0.25577
1831.3	1.65549
1835.1	1.67282
1838.9	4.5097
1842.71	1.69427
1846.51	4.51381
1850.3	1.70245
1854.1	1.69548
1857.89	-2.0574
1861.69	0.726166
1865.48	3.49437
1869.27	0.682947
1873.05	5.29875
1876.84	4.35478
1880.62	0.647758
1884.4	1.57327
1888.19	0.656708
1891.96	-1.14746
1895.74	8.09241
1899.52	0.768616
1903.29	7.2604
1907.06	1.79423
1910.83	1.85277
1914.6	0.999685
1918.37	3.83914
1922.13	3.93165
1925.9	2.17488
1929.66	2.2725
1933.42	4.23282
1937.18	2.47292
1940.94	2.57209
1944.69	6.41251
1948.44	6.5185
1952.2	1.90709
1955.95	6.66623
1959.69	2.02008
1963.44	8.63435
1967.19	4.91529
1970.93	10.5749
1974.67	9.64891
1978.41	4.03339
1982.15	9.65351
1985.89	9.64658
1989.62	9.63556
1993.35	7.75612
1997.09	12.384
2000.82	15.131
2004.55	13.2396
2008.27	7.65618
2012	13.1499
2015.72	10.3434
2019.44	10.3191
2023.16	13.9804
2026.88	10.3298
2030.6	8.51644
2034.31	12.212
2038.03	8.5969
2041.74	7.72399
2045.45	5.93253
2049.16	5.05695
2052.86	7.85006
2056.57	10.6463
2060.27	9.7961
2063.98	9.88332
2067.67	6.29984
2071.37	5.47009
2075.07	9.25238
2078.77	4.72781
2082.46	8.52646
2086.15	7.69342
2089.84	5.89106
2093.53	5.93074
2097.22	6.91413
2100.9	7.89267
2104.59	9.79045
2108.27	8.89174
2111.95	7.05784
2115.63	4.29372
2119.31	8.0323
2122.98	8.03906
2126.66	7.11076
2130.33	8.95896
2134	5.24644
2137.67	4.31377
2141.34	5.22423
2145	8.89108
2148.67	5.18453
2152.33	6.99917
2155.99	1.47472
2159.65	6.0365
2163.31	7.84571
2166.96	6.00385
2170.62	8.72921
2174.27	4.17533
2177.92	7.82665
2181.57	6.01806
2185.22	4.20917
2188.87	6.95579
2192.51	4.25569
2196.15	7.02597
2199.8	10.7178
2203.44	5.2999
2207.07	5.35265
2210.71	7.23828
2214.35	2.72398
2217.98	9.20025
2221.61	3.758
2225.24	3.8184
2228.87	8.48245
2232.5	9.47046
2236.12	5.84318
2239.75	3.12819
2243.37	6.89293
2246.99	6.025
2250.61	3.29505
2254.23	8.94282
2257.85	5.27987
2261.46	6.27725
2265.07	0.71834
2268.68	8.27642
2272.29	2.70909
2275.9	7.4715
2279.51	5.63869
2283.11	2.83833
2286.72	7.58827
2290.32	1.9474
2293.92	3.86092
2297.52	6.72346
2301.11	4.85526
2304.71	5.82195
2308.3	1.09611
2311.9	8.68693
2315.49	3.00282
2319.08	6.79204
2322.66	7.72967
2326.25	5.80742
2329.84	6.72175
2333.42	4.79712
2337	5.70187
2340.58	6.59954
2344.16	6.55085
2347.73	-2.88482
2351.31	3.63275
2354.88	5.45033
2358.45	1.66053
2362.03	1.60803
2365.59	5.27207
2369.16	5.21293
2372.73	5.16043
2376.29	6.02971
2379.85	1.3597
2383.41	4.07792
2386.97	4.9501
2390.53	3.98675
2394.09	3.03073
2397.64	3.91768
2401.2	7.56139
2404.75	2.9717
2408.3	6.63357
2411.85	2.97282
2415.39	2.98457
2418.94	6.67826
2422.48	4.86391
2426.03	3.05083
2429.57	4.00757
2433.11	5.89785
2436.64	0.386105
2440.18	4.14274
2443.72	1.3995
2447.25	6.11161
2450.78	4.30131
2454.31	9.05555
2457.84	2.52477
2461.37	4.42458
2464.89	0.66881
2468.42	10.0909
2471.94	3.50165
2475.46	9.1318
2478.98	6.2618
2482.5	5.28491
2486.01	1.47308
2489.53	3.29621
2493.04	7.94697
2496.55	4.12679
2500.06	1.26303
2503.57	4.0106
2507.08	3.00906
2510.58	5.73286
2514.09	3.79648
2517.59	4.65944
2521.09	3.66926
2524.59	4.51432
2528.09	7.2336
2531.59	6.26002
2535.08	5.29197
2538.58	3.41043
2542.07	4.30385
2545.56	2.44189
2549.05	2.43625
2552.54	2.43156
2556.02	6.13511
2559.51	2.44861
2562.99	-0.321108
2566.47	1.56007
2569.95	3.45726
2573.43	4.43606
2576.91	6.36284
2580.38	2.66532
2583.85	4.60514
2587.33	4.66459
2590.8	6.61401
2594.27	3.80296
2597.74	4.7858
2601.2	4.82634
2604.67	0.0772514
2608.13	7.76222
2611.59	5.84076
2615.06	2.93565
2618.51	3.88119
2621.97	1.93241
2625.43	2.8605
2628.88	1.85926
2632.33	3.73462
2635.79	3.68136
2639.24	3.6194
2642.69	3.55195
2646.13	2.5226
2649.58	-0.415527
2653.02	2.36793
2656.47	2.28001
2659.91	5.03388
2663.35	3.98361
2666.79	1.99005
2670.22	1.88984
2673.66	-0.092474
2677.09	0.752516
2680.52	9.08691
2683.95	-0.359407
2687.39	6.09624
2690.81	2.30184
2694.24	2.24905
2697.66	1.25906
2701.09	3.99845
2704.51	3.94524
2707.93	4.82262
2711.35	2.93057
2714.77	1.04264
2718.18	5.67578
2721.6	1.9338
2725.01	3.78582
2728.42	0.973799
2731.84	0.0268288
2735.24	1.88433
2738.65	6.55714
2742.06	3.73289
2745.46	2.77494
2748.86	2.75068
2752.27	-1.03504
2755.67	2.69911
2759.07	2.66821
2762.46	1.69541
2765.86	1.65619
2769.25	2.55454
2772.65	6.27465
2776.04	0.568697
2779.43	4.2793
2782.82	0.450239
2786.2	1.32736
2789.59	3.14249
2792.98	2.13402
2796.36	4.88273
2799.74	4.81106
2803.12	0.0435009
2806.5	0.906952
2809.88	5.514
2813.25	6.36787
2816.63	1.60813
2820	0.592047
2823.37	6.11452
2826.74	-1.42496
2830.11	8.75751
2833.48	3.09364
2836.84	4.89107
2840.21	2.03528
2843.57	5.70584
2846.93	2.86178
2850.29	0.0249577
2853.65	4.65755
2857.01	6.49108
2860.36	1.78527
2863.72	3.62662
2867.07	3.5981
2870.42	7.3229
2873.77	6.35583
2877.12	0.682718
2880.47	1.58629
2883.81	8.14407
2887.16	4.33548
2890.5	4.29475
2893.84	4.25138
2897.18	5.14469
2900.52	4.14176
2903.86	0.294014
2907.19	10.6334
2910.53	4.88409
2913.86	4.80876
2917.19	5.67642
2920.52	8.42972
2923.85	2.6671
2927.18	6.35819
2930.51	7.20523
2933.83	8.04602
2937.15	5.10476
2940.48	16.3093
2943.8	9.59584
2947.11	12.3066
2950.43	11.2508
2953.75	10.1939
2957.06	12.8961
2960.38	16.5396
2963.69	7.0455
2967	8.81656
2970.31	12.4732
2973.62	8.6329
2976.92	6.66846
2980.23	14.0916
2983.53	10.2501
2986.84	17.6729
2990.14	17.5897
2993.44	7.17526
2996.73	11.7884
3000.03	16.4066
3003.33	15.3847
3006.62	14.361
3009.91	18.9866
3013.2	16.0846
3016.49	21.6601
3019.78	16.8685
3023.07	17.7297
3026.35	21.4227
3029.64	25.1194
3032.92	18.4246
3036.2	29.6802
3039.48	24.8662
3042.76	20.9933
3046.04	19.0101
3049.32	26.495
3052.59	27.3534
3055.86	29.1613
3059.14	30.0188
3062.41	29.907
3065.68	29.8034
3068.94	34.436
3072.21	33.3594
3075.48	36.9652
3078.74	35.8972
3082	43.338
3085.26	35.6686
3088.52	46.0199
3091.78	46.9072
3095.04	42.0949
3098.29	48.5876
3101.55	50.3779
3104.8	50.2498
3108.05	55.869
3111.3	56.7204
3114.55	55.6379
3117.8	65.0353
3121.04	58.2486
3124.29	72.4135
3127.53	69.4324
3130.77	71.2102
3134.02	72.0362
3137.25	80.4838
3140.49	72.7201
3143.73	80.2064
3146.96	84.8333
3150.2	85.6537
3153.43	86.4759
3156.66	86.338
3159.89	97.6511
3163.12	98.4659
3166.35	105.96
3169.57	96.2637
3172.8	115.185
3176.02	116.921
3179.24	113.872
3182.46	123.222
3185.68	128.756
3188.9	115.197
3192.12	125.471
3195.33	145.266
3198.55	147.898
3201.76	135.287
3204.97	138.874
3208.18	151.031
3211.39	142.255
3214.6	151.571
3217.8	169.46
3221.01	145.489
3224.21	156.723
3227.41	161.317
3230.61	170.672
3233.81	178.141
3237.01	172.275
3240.21	176.924
3243.4	171.113
3246.59	187.218
3249.79	170.934
3252.98	180.401
3256.17	192.746
3259.36	189.826
3262.54	191.644
3265.73	199.16
3268.92	196.136
3272.1	194.043
3275.28	205.309
3278.46	198.421
3281.64	198.169
3284.82	179.738
3288	201.397
3291.17	203.943
3294.35	208.414
3297.52	227.159
3300.69	200.186
3303.86	210.414
3307.03	222.471
3310.2	226.881
3313.36	227.442
3316.53	215.642
3319.69	233.264
3322.85	235.679
3326.02	230.517
3329.18	242.397
3332.33	252.374
3335.49	245.351
3338.65	242.139
3341.8	253.105
3344.95	261.238
3348.11	274.155
3351.26	271.12
3354.41	269.025
3357.56	284.875
3360.7	288.492
3363.85	293.093
3366.99	304.306
3370.13	307.998
3373.28	293.78
3376.42	320.186
3379.56	319.243
3382.69	334.383
3385.83	327.777
3388.97	329.71
3392.1	338.278
3395.23	359.15
3398.36	355.306
3401.49	390.558
3404.62	368.025
3407.75	386.337
3410.88	380.939
3414	402.173
3417.13	403.332
3420.25	423.533
3423.37	418.914
3426.49	436.147
3429.61	438.029
3432.73	472.312
3435.84	472.117
3438.96	488.985
3442.07	513.548
3445.18	524.731
3448.29	539.606
3451.4	563.986
3454.51	614.93
3457.62	705.788
3460.72	759.31
3463.83	897.349
3466.93	904.029
3470.03	852.667
3473.13	733.007
3476.23	654.556
3479.33	631.162
3482.43	593.651
3485.53	581.73
3488.62	545.318
3491.71	557.182
3494.81	539.951
3497.9	537.805
3500.99	559.202
3504.07	515.546
3507.16	528.378
3510.25	524.241
3513.33	549.11
3516.41	521.387
3519.5	550.598
3522.58	567.874
3525.66	591.292
3528.73	589.899
3531.81	615.587
3534.89	611.875
3537.96	654.102
3541.03	716.203
3544.11	738.047
3547.18	705.013
3550.25	708.398
3553.32	624.624
3556.38	574.761
3559.45	494.67
3562.51	457.1
3565.58	390.018
3568.64	325.668
3571.7	290.785
3574.76	280.369
3577.82	245.311
3580.87	229.195
3583.93	199.78
3586.98	209.233
3590.04	194.03
3593.09	184.493
3596.14	161.691
3599.19	162.573
3602.24	147.359
3605.29	135.925
3608.33	139.632
3611.38	130.098
3614.42	128.13
3617.46	111.995
3620.5	128.928
3623.54	117.554
3626.58	109.031
3629.62	104.301
3632.65	91.0941
3635.69	90.1363
3638.72	82.633
3641.76	86.4478
3644.79	84.6377
3647.82	68.7533
3650.84	71.6557
3653.87	61.4068
3656.9	61.3641
3659.92	55.9407
3662.95	43.9095
3665.97	38.4405
3668.99	31.0426
3672.01	36.8651
3675.03	28.5512
3678.05	31.5651
3681.07	23.2573
3684.08	18.7198
3687.1	20.8021
3690.11	15.3235
3693.12	10.7911
3696.13	10.0477
3699.14	8.34713
3702.15	5.71379
3705.16	6.87804
3708.16	6.14738
3711.17	5.41294
3714.17	-0.0773544
3717.17	0.132759
3720.17	4.15756
3723.17	-3.24138
3726.17	-3.02708
3729.17	-7.57452
3732.16	-8.31279
3735.16	-0.481007
3738.15	-5.03031
3741.14	-7.67431
3744.13	-6.51205
3747.13	-4.39951
3750.11	-7.04301
3753.1	-4.9331
3756.09	-4.72166
3759.07	-7.35219
3762.06	-10.9255
3765.04	-5.96644
3768.02	-10.4784
3771	-9.30099
3773.98	-7.17252
3776.96	-5.98574
3779.94	-13.2992
3782.91	-7.37824
3785.89	-6.17981
3788.86	-8.75372
3791.83	-5.65903
3794.8	-8.21989
3797.77	-8.88845
3800.74	-6.72161
3803.71	-11.1572
3806.68	-8.03665
3809.64	-6.80214
3812.61	-2.72858
3815.57	-8.10601
3818.53	-12.5412
3821.49	-2.78338
3824.45	-6.27178
3827.41	-5.97233
3830.36	-10.4132
3833.32	-6.32377
3836.27	-5.07465
3839.23	-8.57323
3842.18	-1.62264
3845.13	-5.12859
3848.08	-1.02564
3851.03	-3.58669
3853.98	-4.24594
3856.92	-2.04597
3859.87	-0.800697
3862.81	0.443001
3865.75	-5.01612
3868.7	0.0452843
3871.64	-1.6024
3874.57	2.49561
3877.51	-0.126366
3880.45	-2.76198
3883.39	-7.3318
3886.32	2.50003
3889.25	1.75355
3892.18	-5.7328
3895.12	-0.729553
3898.05	-2.46996
3900.97	-0.376099
3903.9	-0.215549
3906.83	-1.03002
3909.75	3.91771
3912.68	-3.64321
3915.6	0.314644
3918.52	1.37548
3921.44	-0.449623
3924.36	3.46618
3927.28	5.44293
3930.2	4.52434
3933.11	-0.240818
3936.03	-5.00634
3938.94	-1.159
3941.86	-2.109
3944.77	5.53933
3947.68	3.59854
3950.59	0.687527
3953.49	-0.323513
3956.4	1.52186
3959.31	3.35287
3962.21	1.33454
3965.12	-2.62029
3968.02	-0.842567
3970.92	-1.96089
3973.82	-0.221237
3976.72	-5.22558
3979.61	-1.61291
3982.51	0.0541191
3985.41	1.69696
3988.3	-0.532749
3991.19	-3.75289
3994.09	-2.1954
3996.98	-0.657787
3999.87	-0.110905