File: Data/3-Raman/processed/bu19w-a-ff07b-fi07-v_150 (500nm)_532nm_edge_100%_x100_vis_lwd_h50um_15sx2_01_0.txt
#Acq. time (s)=	15
#Accumulations=	2
#Range (cm-¹)=	50...5000
#Windows=	1
#Auto scanning=	Off
#Autofocus=	Off
#Macrospot=	Off
#AutoExposure=	Off
#Spike filter=	Multiple accum.
#Delay time (s)=	2
#Binning=	1
#Readout mode=	Signal
#DeNoise=	Off
#ICS correction=	On
#Dark correction=	Off
#Inst. Process=	Off
#Detector Gain=	Best Dynamic
#Detector ADC=	50 kHz HS
#Detector temperature (°C)=	-60.09
#Instrument=	LabRAM HR Evol
#Detector=	SIN-EM FIVIS
#Objective=	x100_VIS_LWD
#Grating=	150 (500nm)
#ND Filter=	100%
#Laser=	532nm_Edge
#Hole=	49.98
#Temperature=	0
#Range=	Visible
#StageXY=	75x50mm Scan+
#StageZ=	Z motor
#X (µm)=	0
#Y (µm)=	0
#Z (µm)=	-15.6
#Full time(s)=	35
#Project=	21_05_28
#Sample=	BU19w
#Site=
#Title=	BU19w-FF07b-FI07-V_150 (500nm)_532nm_Edge_100%_x100_VIS_LWD_H50um_15sX2
#Remark=
#Date=	28.05.2021 16:41
#Acquired=	28.05.2021 16:41:28
#Base:Fit=	16.12.2021 17:39:50
#Base:Sub=	16.12.2021 17:58:32
51.5961	34444.9
56.2453	27961.3
60.8921	20711.5
65.5367	19277.6
70.1768	15677.1
74.8167	8619.74
79.4543	5165.57
84.0897	3603.58
88.7227	2444.89
93.3513	1635.34
97.9798	1173.44
102.606	786.719
107.23	502.358
111.851	379.497
116.469	169.948
121.086	52.6534
125.7	-87.5415
130.313	-94.2932
134.921	-143.608
139.529	-141.994
144.134	-253.198
148.738	-307.515
153.337	-279.272
157.936	-172.173
162.532	365.182
167.126	1285.47
171.716	868.781
176.306	118.976
180.894	-6.17407
185.477	344.867
190.06	2028.31
194.64	4781.22
199.219	3220.08
203.793	879.847
208.367	127.721
212.939	-17.2877
217.506	-27.3823
222.073	26.5159
226.638	0.0010376
231.199	34.8231
235.759	157.963
240.318	444.936
244.872	590.254
249.425	1018.55
253.977	1534.15
258.524	1214.67
263.071	895.175
267.616	602.387
272.156	597.094
276.697	1127.17
281.233	2859.58
285.769	4840.4
290.303	4035.02
294.832	2142.38
299.361	1372.66
303.886	1488.87
308.411	2397.31
312.934	2382.56
317.452	1391.92
321.97	902.502
326.484	882.269
330.998	1214.86
335.507	1748.88
340.017	1650.7
344.524	1070.45
349.027	920.153
353.53	1209.77
358.028	1381.28
362.527	1059.86
367.021	766.499
371.515	649.811
376.004	730.845
380.494	708.747
384.979	619.288
389.465	809.645
393.946	1089.33
398.427	1265.48
402.903	1250.87
407.38	1030.32
411.852	712.647
416.324	649.687
420.792	914.924
425.26	1006.68
429.723	660.48
434.187	471.945
438.646	365.555
443.105	356.772
447.56	413.196
452.015	542.228
456.466	846.076
460.914	1706.42
465.362	1690.41
469.807	954.226
474.251	619.618
478.69	517.16
483.13	527.456
487.566	572.678
491.999	708.731
496.432	844.138
500.861	944.874
505.29	981.113
509.715	893.456
514.138	725.942
518.56	603.462
522.979	524.001
527.395	478.16
531.811	475.15
536.223	510.41
540.635	510.902
545.042	547.181
549.448	560.265
553.853	575.461
558.255	547.056
562.654	583.49
567.053	621.852
571.448	614.174
575.841	480.429
580.232	407.453
584.622	510.27
589.009	798.635
593.393	1547.44
597.777	2074.14
602.157	1538.34
606.535	956.112
610.913	906.581
615.287	1142.58
619.659	1335.81
624.029	1086.02
628.398	647.287
632.763	408.551
637.127	396.761
641.488	434.475
645.849	555.363
650.206	548.961
654.561	471.185
658.914	412.208
663.267	441.572
667.615	626.9
671.962	686.656
676.307	740.026
680.649	848.051
684.991	890.127
689.33	766.592
693.666	518.8
698	315.716
702.332	236.999
706.662	172.047
710.992	124.038
715.318	156.481
719.641	122.129
723.963	140.35
728.283	136.151
732.6	133.631
736.918	141.892
741.231	118.386
745.542	141.618
749.852	163.105
754.159	180.278
758.464	245.126
762.767	286.016
767.068	358.583
771.369	501.323
775.666	812.922
779.961	1403.29
784.254	1940.71
788.545	1973.44
792.834	1339.26
797.12	796.026
801.405	476.196
805.688	363.347
809.968	291.618
814.247	220.055
818.524	172.826
822.798	158.605
827.071	106.078
831.341	118.575
835.612	85.9412
839.878	90.7481
844.142	65.7237
848.405	68.0632
852.665	83.2833
856.923	68.7568
861.18	80.6982
865.434	44.0896
869.686	49.1547
873.936	32.1275
878.185	38.0432
882.431	55.8614
886.675	38.4042
890.915	-0.0172729
895.155	19.1213
899.393	32.7925
903.63	50.0465
907.864	32.7999
912.096	22.4275
916.326	43.8496
920.554	25.1592
924.78	34.3248
929.004	43.1229
933.227	84.9304
937.447	72.9648
941.665	101.558
945.881	140.681
950.095	235.171
954.305	365.86
958.516	385.634
962.724	380.006
966.93	372.404
971.134	455.156
975.337	476.531
979.537	429.18
983.735	318.571
987.93	288.517
992.124	240.613
996.316	202.905
1000.51	212.333
1004.7	195.466
1008.88	193.586
1013.06	244.954
1017.25	319.689
1021.43	389.275
1025.61	370.201
1029.78	360.367
1033.96	403.627
1038.13	505.576
1042.3	623.671
1046.47	714.765
1050.63	1018.64
1054.8	1641.09
1058.96	2518.16
1063.12	2414.24
1067.28	1643.29
1071.44	1054.92
1075.59	722.984
1079.74	658.739
1083.89	785.542
1088.04	1122.68
1092.19	1732.32
1096.33	2371.05
1100.48	2374.66
1104.62	1963.04
1108.76	1710.56
1112.89	1839.52
1117.03	2086.93
1121.16	2034.31
1125.29	1692.51
1129.42	1615.34
1133.55	1739.27
1137.68	1890.68
1141.8	1863.68
1145.92	1449.13
1150.04	1055.29
1154.16	964.847
1158.27	1115.11
1162.39	1483.89
1166.5	1648.71
1170.61	1299.1
1174.72	911.068
1178.82	703.635
1182.93	500.661
1187.03	394.381
1191.13	306.303
1195.23	312.466
1199.33	342.798
1203.42	327.91
1207.51	292.721
1211.6	268.912
1215.69	237.209
1219.78	235.991
1223.86	288.174
1227.95	442.603
1232.03	537.776
1236.11	437.658
1240.18	499.206
1244.26	667.284
1248.33	842.701
1252.41	638.503
1256.48	539.348
1260.54	511.26
1264.61	339.274
1268.67	254.303
1272.74	304.62
1276.8	1668.64
1280.86	2962.25
1284.91	943.669
1288.97	261.799
1293.02	203.157
1297.07	169.51
1301.12	177.074
1305.17	165.335
1309.21	165.636
1313.25	151.73
1317.3	137.54
1321.34	134.276
1325.37	139.774
1329.41	160.236
1333.44	143.421
1337.48	135.409
1341.5	133.291
1345.53	141.079
1349.56	112.935
1353.59	173.467
1357.61	194.089
1361.63	194.736
1365.65	252.938
1369.66	253.775
1373.68	255.808
1377.69	603.055
1381.7	4145.24
1385.72	3453.97
1389.72	769.876
1393.73	270.056
1397.73	232.231
1401.74	424.798
1405.74	530.74
1409.73	279.053
1413.73	158.389
1417.73	157.99
1421.72	119.072
1425.71	123.467
1429.7	107.718
1433.69	101.909
1437.67	82.2535
1441.66	95.1877
1445.64	111.945
1449.62	73.3823
1453.6	85.0214
1457.57	113.33
1461.55	88.2609
1465.52	73.821
1469.49	58.3779
1473.46	73.5027
1477.43	73.7762
1481.39	86.6865
1485.36	82.8716
1489.32	77.0521
1493.28	65.4398
1497.24	97.7241
1501.19	69.6425
1505.15	45.6278
1509.1	106.393
1513.05	95.2477
1517	74.4414
1520.95	70.2223
1524.9	70.8948
1528.84	80.3401
1532.78	63.6898
1536.72	78.0693
1540.66	93.4279
1544.6	75.83
1548.53	72.7645
1552.46	76.4708
1556.4	95.5747
1560.32	85.5004
1564.25	89.8589
1568.18	104.766
1572.1	76.1007
1576.02	61.9391
1579.94	69.9531
1583.86	58.6417
1587.78	67.5154
1591.69	58.0573
1595.61	78.4055
1599.52	85.2574
1603.43	65.2651
1607.34	54.9963
1611.24	84.0622
1615.15	91.095
1619.05	64.6856
1622.95	62.183
1626.85	47.3409
1630.74	60.3419
1634.64	46.7604
1638.53	59.9335
1642.42	77.1206
1646.31	41.7652
1650.2	55.325
1654.09	49.738
1657.97	61.3558
1661.86	39.3245
1665.74	43.0768
1669.62	41.9393
1673.49	58.8391
1677.37	52.6147
1681.24	66.1778
1685.12	44.9736
1688.99	12.2306
1692.86	52.1991
1696.72	43.1733
1700.59	36.9092
1704.45	26.6931
1708.31	40.1477
1712.17	16.3543
1716.03	53.305
1719.89	39.9978
1723.74	39.9636
1727.6	29.4971
1731.45	21.7702
1735.3	52.5656
1739.14	55.0625
1742.99	61.1796
1746.83	49.6069
1750.68	51.5157
1754.52	39.7427
1758.36	58.9909
1762.19	26.5226
1766.03	45.4988
1769.86	23.8846
1773.69	28.5969
1777.53	29.609
1781.35	56.9512
1785.18	59.2816
1789	30.835
1792.83	24.7994
1796.65	48.7795
1800.47	54.0036
1804.29	23.9528
1808.1	35.2214
1811.92	27.5671
1815.73	2.78796
1819.54	40.9
1823.35	42.0291
1827.16	49.6203
1830.97	45.683
1834.77	50.0339
1838.58	50.4823
1842.38	29.18
1846.18	33.1062
1849.97	54.926
1853.77	51.0445
1857.56	30.1552
1861.36	22.1707
1865.15	49.49
1868.93	46.114
1872.72	15.9516
1876.51	41.527
1880.29	16.2836
1884.07	27.36
1887.86	42.1079
1891.63	26.374
1895.41	27.2216
1899.19	46.4641
1902.96	24.612
1906.73	24.9757
1910.5	35.54
1914.27	42.6985
1918.04	34.2254
1921.8	61.3322
1925.57	36.7324
1929.33	7.52832
1933.09	39.6457
1936.85	28.0771
1940.6	29.5057
1944.36	34.6605
1948.11	29.5195
1951.87	28.4727
1955.61	47.7839
1959.36	31.0242
1963.11	42.1896
1966.86	15.7433
1970.6	42.5792
1974.34	25.958
1978.08	-13.2708
1981.82	23.2531
1985.56	38.9895
1989.29	2.34363
1993.02	18.7776
1996.75	46.1555
2000.49	2.76654
2004.21	69.7571
2007.94	19.9658
2011.67	34.7294
2015.39	11.7415
2019.11	36.0086
2022.83	44.0958
2026.55	38.8914
2030.27	11.7499
2033.98	2.3764
2037.69	24.3774
2041.41	14.2711
2045.12	1.35522
2048.82	40.6439
2052.53	29.7245
2056.24	8.76514
2059.94	31.2605
2063.64	20.3098
2067.34	35.2632
2071.04	44.8053
2074.74	10.0884
2078.43	28.014
2082.13	17.3425
2085.82	18.6013
2089.51	22.676
2093.2	8.75989
2096.88	24.0103
2100.57	3.79901
2104.25	7.50507
2107.94	27.8199
2111.62	14.5342
2115.3	18.8939
2118.97	-1.0108
2122.65	29.8798
2126.32	31.7888
2129.99	7.62421
2133.66	42.6725
2137.33	28.5906
2141	31.9467
2144.67	25.9542
2148.33	36.4823
2151.99	38.6944
2155.66	37.2614
2159.31	28.5394
2162.97	42.7858
2166.63	40.6915
2170.28	29.6284
2173.94	22.5599
2177.59	32.9738
2181.24	49.8577
2184.89	42.1317
2188.53	1.88843
2192.18	55.6448
2195.82	53.3547
2199.46	24.826
2203.1	44.6755
2206.74	30.9195
2210.38	17.2717
2214.01	38.4938
2217.65	20.3992
2221.28	51.8651
2224.91	14.4947
2228.54	23.9393
2232.16	51.892
2235.79	48.5917
2239.41	46.1859
2243.04	71.572
2246.66	58.0101
2250.28	54.6831
2253.89	44.9224
2257.51	18.41
2261.12	21.7089
2264.74	38.975
2268.35	27.311
2271.96	22.3759
2275.57	41.6879
2279.17	33.4883
2282.78	14.3448
2286.38	45.2213
2289.98	24.152
2293.58	35.1033
2297.18	26.2262
2300.78	18.3203
2304.37	24.4821
2307.97	5.83795
2311.56	27.8356
2315.15	42.1324
2318.74	49.6517
2322.33	264.448
2325.91	427.182
2329.5	130.022
2333.08	18.4999
2336.66	39.1639
2340.24	20.1155
2343.82	12.3219
2347.4	25.0919
2350.97	52.7433
2354.54	5.46643
2358.12	45.0903
2361.69	37.9455
2365.26	8.51379
2368.82	60.8753
2372.39	27.1517
2375.95	2.72296
2379.52	39.3039
2383.08	16.9132
2386.64	13.9952
2390.19	36.0341
2393.75	18.7374
2397.31	20.9856
2400.86	22.6042
2404.41	10.9446
2407.96	3.05811
2411.51	41.3841
2415.06	11.1304
2418.6	8.59723
2422.15	25.5198
2425.69	1.22998
2429.23	26.0059
2432.77	15.903
2436.31	37.4703
2439.84	6.27039
2443.38	14.1138
2446.91	11.7537
2450.44	24.5421
2453.97	11.2732
2457.5	20.9095
2461.03	39.2596
2464.55	8.55334
2468.08	41.2304
2471.6	34.0757
2475.12	23.5883
2478.64	17.7081
2482.16	28.9444
2485.67	19.1287
2489.19	39.8404
2492.7	9.3219
2496.21	13.1101
2499.72	5.95276
2503.23	28.4691
2506.74	59.1776
2510.25	24.3393
2513.75	31.562
2517.25	5.53857
2520.75	41.8887
2524.25	9.93835
2527.75	11.306
2531.25	43.3794
2534.74	34.9219
2538.24	1.82477
2541.73	17.8502
2545.22	36.1463
2548.71	36.3755
2552.2	-14.1838
2555.68	18.6784
2559.17	14.9835
2562.65	57.7126
2566.13	24.731
2569.61	29.1787
2573.09	51.6436
2576.57	2.23566
2580.04	30.7429
2583.51	23.6481
2586.99	62.8638
2590.46	36.6257
2593.93	37.3723
2597.4	22.7347
2600.86	17.8467
2604.33	27.222
2607.79	62.0278
2611.25	73.1234
2614.71	29.8342
2618.17	19.5103
2621.63	13.6239
2625.09	38.321
2628.54	21.4692
2631.99	24.6558
2635.45	46.8179
2638.9	5.4176
2642.34	27.1453
2645.79	61.0785
2649.24	52.8521
2652.68	40.6338
2656.12	43.4511
2659.56	17.6014
2663.01	43.8601
2666.44	44.407
2669.88	38.3368
2673.32	55.7596
2676.75	48.8635
2680.18	37.456
2683.61	36.5763
2687.04	50.0183
2690.47	54.6993
2693.9	57.8375
2697.32	20.7513
2700.75	51.8527
2704.17	49.4744
2707.59	50.8616
2711.01	24.9896
2714.43	47.6765
2717.84	56.6099
2721.26	62.013
2724.67	37.6973
2728.08	50.77
2731.49	45.2288
2734.9	55.5443
2738.31	45.272
2741.71	45.2595
2745.12	36.6235
2748.52	52.2852
2751.92	36.0146
2755.32	70.4615
2758.72	34.2424
2762.12	63.9439
2765.52	53.8568
2768.91	55.8802
2772.3	59.642
2775.7	44.4851
2779.09	43.3135
2782.47	63.6779
2785.86	58.5513
2789.25	54.3447
2792.63	70.7928
2796.01	80.6232
2799.4	72.6083
2802.78	91.6634
2806.15	64.7768
2809.53	60.393
2812.91	46.613
2816.28	70.2057
2819.65	39.5695
2823.03	53.9295
2826.4	67.4666
2829.76	58.691
2833.13	59.372
2836.5	42.5279
2839.86	65.9039
2843.22	81.0831
2846.59	55.493
2849.95	61.9192
2853.3	60.1711
2856.66	48.9729
2860.02	67.8098
2863.37	73.6946
2866.72	81.5093
2870.08	61.1992
2873.43	80.2445
2876.77	65.4476
2880.12	68.4873
2883.47	50.7723
2886.81	41.443
2890.15	80.2267
2893.5	53.8328
2896.84	61.2198
2900.17	93.0784
2903.51	101.165
2906.85	39.1216
2910.18	64.0486
2913.52	71.8821
2916.85	104.255
2920.18	74.9904
2923.51	102.439
2926.83	88.1899
2930.16	70.988
2933.48	85.8083
2936.81	106.134
2940.13	94.3765
2943.45	121.27
2946.77	118.034
2950.09	133.651
2953.4	119.133
2956.72	77.4342
2960.03	121.375
2963.34	102.49
2966.65	80.8723
2969.96	88.6234
2973.27	76.8477
2976.58	89.5011
2979.88	86.364
2983.19	83.1207
2986.49	92.1403
2989.79	121.88
2993.09	105.651
2996.39	91.3449
2999.68	71.4401
3002.98	84.4237
3006.27	114.359
3009.57	88.8673
3012.86	79.4108
3016.15	80.3318
3019.43	76.5187
3022.72	100.989
3026.01	88.6835
3029.29	110.377
3032.57	76.3326
3035.86	72.4603
3039.14	113.01
3042.41	89.2685
3045.69	71.2059
3048.97	74.9176
3052.24	101.376
3055.52	71.9558
3058.79	92.7394
3062.06	76.2458
3065.33	121.561
3068.6	75.6736
3071.86	93.1694
3075.13	71.9262
3078.39	93.3392
3081.65	90.7544
3084.91	107.93
3088.17	88.0626
3091.43	95.971
3094.69	100.147
3097.95	98.394
3101.2	114.35
3104.45	136.793
3107.7	105.469
3110.95	106.347
3114.2	106.929
3117.45	118.068
3120.7	95.9081
3123.94	105.174
3127.18	115.382
3130.43	112.227
3133.67	85.2616
3136.91	121.173
3140.14	103.66
3143.38	122.362
3146.61	116.285
3149.85	108.362
3153.08	115.717
3156.31	137.345
3159.54	111.304
3162.77	107.173
3166	119.267
3169.22	116.963
3172.45	141.314
3175.67	123.638
3178.89	129.741
3182.11	123.432
3185.33	164.832
3188.55	146.987
3191.77	111.97
3194.98	155.113
3198.2	147.728
3201.41	134.615
3204.62	163.442
3207.83	178.011
3211.04	142.19
3214.25	168.29
3217.45	183.989
3220.66	213.006
3223.86	201.156
3227.06	195.114
3230.26	187.194
3233.46	230.728
3236.66	224.723
3239.85	251.308
3243.05	301.777
3246.24	279.942
3249.44	246.657
3252.63	307.846
3255.82	296.621
3259.01	273.908
3262.19	300.676
3265.38	299.605
3268.56	305.067
3271.75	305.643
3274.93	301.378
3278.11	274.174
3281.29	271.585
3284.47	266.896
3287.64	265.098
3290.82	198.375
3293.99	249.029
3297.17	234.818
3300.34	236.828
3303.51	234.312
3306.68	210.6
3309.84	220.101
3313.01	246.538
3316.18	231.097
3319.34	257.399
3322.5	224.853
3325.66	238.78
3328.82	202.542
3331.98	218.389
3335.14	247.51
3338.29	230.42
3341.45	238.902
3344.6	215.341
3347.75	218.447
3350.9	277.41
3354.05	232.673
3357.2	255.919
3360.35	217.953
3363.49	217.809
3366.64	241.264
3369.78	234.601
3372.92	254.399
3376.06	243.182
3379.2	245.222
3382.34	283.222
3385.48	295.684
3388.61	322.441
3391.75	313.275
3394.88	379.808
3398.01	375.057
3401.14	423.086
3404.27	475.1
3407.4	535.883
3410.52	666.286
3413.65	947.333
3416.77	1400.94
3419.89	2621.68
3423.01	5626.98
3426.13	10468.8
3429.25	10060.9
3432.37	5338.15
3435.49	2425.19
3438.6	1268.91
3441.72	876.915
3444.83	666.317
3447.94	510.878
3451.05	408.922
3454.16	442.191
3457.26	356.369
3460.37	374.216
3463.47	325.463
3466.58	346.076
3469.68	300.057
3472.78	319.356
3475.88	356.945
3478.98	387.91
3482.07	430.227
3485.17	486.689
3488.26	547.885
3491.36	693.22
3494.45	809.591
3497.54	1073.03
3500.63	1457.86
3503.72	1849.1
3506.81	2334.81
3509.89	2628.82
3512.98	2347.25
3516.06	1944.37
3519.14	1401.75
3522.22	1057.34
3525.3	804.017
3528.38	630.481
3531.45	527.83
3534.53	432.392
3537.61	357.162
3540.68	289.626
3543.75	281.061
3546.82	240.224
3549.89	246.349
3552.96	211.583
3556.03	184.264
3559.09	196.821
3562.16	180.041
3565.22	161.156
3568.28	163.915
3571.34	144.209
3574.4	179.064
3577.46	133.353
3580.52	138.779
3583.57	126.113
3586.63	156.993
3589.68	141.395
3592.73	110.522
3595.78	162.103
3598.83	208.831
3601.88	239.427
3604.93	285.985
3607.97	357.019
3611.02	264.373
3614.06	275.736
3617.1	219.048
3620.14	205.892
3623.18	191.852
3626.22	121.286
3629.26	113.986
3632.3	87.8063
3635.33	96.4454
3638.36	93.0484
3641.4	86.9425
3644.43	69.6425
3647.46	84.5403
3650.49	45.5821
3653.51	59.4286
3656.54	60.0441
3659.57	73.6854
3662.59	51.4919
3665.61	64.9227
3668.63	78.9442
3671.65	61.1042
3674.67	39.512
3677.69	50.978
3680.71	30.3864
3683.72	63.5984
3686.74	42.0103
3689.75	45.9695
3692.76	52.7957
3695.77	36.8968
3698.78	49.2714
3701.79	2.06171
3704.79	29.7799
3707.8	18.5799
3710.81	50.0488
3713.81	51.0624
3716.81	34.8594
3719.81	35.8259
3722.81	32.8915
3725.81	42.2715
3728.81	5.87714
3731.8	38.9462
3734.8	1.47302
3737.79	53.429
3740.78	-3.21796
3743.77	20.015
3746.76	37.4625
3749.75	26.3027
3752.74	-1.04785
3755.73	2.95782
3758.71	13.6187
3761.7	30.8849
3764.68	16.8004
3767.66	24.5325
3770.64	24.7421
3773.62	39.2067
3776.6	16.847
3779.58	26.6771
3782.55	45.9944
3785.53	15.2634
3788.5	10.0818
3791.47	13.4437
3794.44	27.3004
3797.41	52.5438
3800.38	33.4709
3803.35	15.4337
3806.32	22.9252
3809.28	37.0568
3812.24	32.3414
3815.21	41.8238
3818.17	28.6306
3821.13	25.8658
3824.09	7.96771
3827.04	18.5233
3830	10.139
3832.96	34.9404
3835.91	23.7738
3838.86	5.97906
3841.82	45.1932
3844.77	1.69843
3847.72	39.0734
3850.67	35.569
3853.61	22.5648
3856.56	34.366
3859.5	14.6744
3862.45	33.1973
3865.39	15.3486
3868.33	18.5376
3871.27	-1.32794
3874.21	19.0396
3877.15	57.6397
3880.09	33.7861
3883.02	24.2441
3885.96	19.4158
3888.89	5.88177
3891.82	48.0814
3894.75	6.59723
3897.68	39.0695
3900.61	40.6886
3903.54	35.5574
3906.47	46.6848
3909.39	38.6706
3912.31	41.1641
3915.24	23.4143
3918.16	26.7615
3921.08	43.6734
3924	25.8834
3926.92	40.6502
3929.83	22.7378
3932.75	20.1498
3935.67	20.6029
3938.58	30.7742
3941.49	23.8337
3944.4	-11.8923
3947.31	13.6987
3950.22	13.508
3953.13	26.7733
3956.04	26.6647
3958.94	17.9972
3961.85	21.815
3964.75	20.8755
3967.65	1.75433
3970.55	14.3119
3973.45	16.3423
3976.35	27.0027
3979.25	21.2957
3982.15	40.5281
3985.04	8.80902
3987.94	29.9288
3990.83	34.6859
3993.72	-0.0747681
3996.61	39.363
3999.5	23.9504
4002.39	2.78619
4005.28	49.0392
4008.16	23.0979
4011.05	17.3868
4013.93	-8.58807
4016.81	39.7045
4019.7	25.3059
4022.58	12.8237
4025.46	43.7995
4028.33	39.0641
4031.21	46.8962
4034.09	20.9048
4036.96	16.184
4039.84	29.8818
4042.71	35.8256
4045.58	26.1599
4048.45	13.6146
4051.32	14.6698
4054.19	31.2827
4057.05	14.9777
4059.92	28.7344
4062.78	22.0769
4065.65	0.835022
4068.51	23.335
4071.37	26.3861
4074.23	25.5436
4077.09	41.2432
4079.95	30.6426
4082.81	39.5273
4085.66	26.9711
4088.52	20.2245
4091.37	9.56934
4094.22	11.6442
4097.07	7.81012
4099.92	22.5775
4102.77	13.8784
4105.62	20.8004
4108.47	23.7363
4111.31	13.9632
4114.16	22.7075
4117	25.5179
4119.84	17.472
4122.69	7.48175
4125.53	28.884
4128.36	19.9664
4131.2	33.735
4134.04	28.0208
4136.88	31.3186
4139.71	8.33917
4142.54	30.8521
4145.38	15.9824
4148.21	15.0619
4151.04	36.7121
4153.87	46.4769
4156.69	29.5708
4159.52	21.2197
4162.35	12.1253
4165.17	35.3956
4168	16.5956
4170.82	7.61035
4173.64	8.44122
4176.46	16.1351
4179.28	30.6763
4182.1	19.8437
4184.91	37.3968
4187.73	33.47
4190.54	2.16058
4193.36	49.2352
4196.17	55.2866
4198.98	56.5388
4201.79	54.8266
4204.6	33.5204
4207.41	76.9508
4210.22	67.4063
4213.02	62.74
4215.83	62.9797
4218.63	55.7297
4221.44	54.3351
4224.24	41.0402
4227.04	26.6483
4229.84	36.0568
4232.64	27.6948
4235.43	19.3899
4238.23	34.9053
4241.02	52.4598
4243.82	29.3
4246.61	24.0396
4249.4	35.6786
4252.19	64.2615
4254.98	59.9055
4257.77	47.4719
4260.56	22.9799
4263.35	29.5521
4266.13	48.2105
4268.92	41.821
4271.7	30.3707
4274.48	39.03
4277.26	43.5481
4280.04	36.8783
4282.82	34.1962
4285.6	39.536
4288.38	35.6984
4291.15	36.8521
4293.93	36.9676
4296.7	19.9426
4299.47	47.5535
4302.25	44.7059
4305.02	31.6983
4307.79	52.1843
4310.55	13.7946
4313.32	21.1617
4316.09	18.2698
4318.85	13.2861
4321.62	13.3484
4324.38	21.5084
4327.14	18.4418
4329.9	38.8212
4332.66	38.7681
4335.42	26.5256
4338.18	43.769
4340.94	32.5961
4343.69	43.847
4346.45	24.572
4349.2	20.6373
4351.95	33.0337
4354.7	30.2787
4357.45	9.05243
4360.2	45.0795
4362.95	29.9401
4365.7	11.7653
4368.44	42.7053
4371.19	35.8018
4373.93	23.6534
4376.68	18.665
4379.42	32.1066
4382.16	30.1353
4384.9	11.7559
4387.64	34.613
4390.37	34.0544
4393.11	24.3058
4395.85	37.6783
4398.58	35.1538
4401.31	50.1961
4404.05	25.8218
4406.78	43.9675
4409.51	56.9842
4412.24	21.0714
4414.96	22.4839
4417.69	21.7889
4420.42	27.1182
4423.14	44.038
4425.87	28.647
4428.59	38.3117
4431.31	-5.33881
4434.03	16.8558
4436.75	46.3835
4439.47	30.8657
4442.19	19.467
4444.91	31.1439
4447.62	22.8579
4450.34	28.2115
4453.05	33.5199
4455.76	17.8092
4458.47	29.3622
4461.19	40.8976
4463.89	24.1162
4466.6	37.8165
4469.31	29.4571
4472.02	24.2717
4474.72	25.4475
4477.43	19.2914
4480.13	42.704
4482.83	25.0077
4485.53	-0.116852
4488.23	33.8883
4490.93	34.0593
4493.63	43.6223
4496.33	34.0463
4499.02	59.5138
4501.72	33.0507
4504.41	33.0217
4507.11	35.164
4509.8	40.5046
4512.49	39.4828
4515.18	29.9785
4517.87	13.0431
4520.56	51.3695
4523.24	24.9309
4525.93	30.3747
4528.61	2.80984
4531.3	24.2285
4533.98	38.2232
4536.66	8.51343
4539.34	53.5062
4542.02	31.2891
4544.7	27.2045
4547.38	20.9884
4550.05	39.3986
4552.73	11.792
4555.4	59.3358
4558.08	44.7435
4560.75	31.3362
4563.42	14.7342
4566.09	7.94226
4568.76	30.4813
4571.43	24.5929
4574.1	23.5671
4576.77	33.1902
4579.43	34.3716
4582.1	46.6406
4584.76	14.3783
4587.42	13.3776
4590.08	7.98145
4592.74	31.9858
4595.4	44.042
4598.06	35.4117
4600.72	36.5566
4603.38	34.5132
4606.03	39.0673
4608.69	17.3238
4611.34	24.0712
4613.99	23.1221
4616.64	41.9474
4619.29	26.7251
4621.94	17.0027
4624.59	29.2852
4627.24	19.4835
4629.89	17.3701
4632.53	40.6481
4635.18	35.1349
4637.82	-2.50595
4640.46	26.2213
4643.1	2.9274
4645.74	15.1773
4648.38	28.6761
4651.02	46.7661
4653.66	18.3389
4656.3	14.1375
4658.93	22.816
4661.57	17.3361
4664.2	13.0362
4666.83	16.4866
4669.46	16.4769
4672.09	29.9404
4674.72	31.085
4677.35	42.3163
4679.98	12.0248
4682.61	13.1222
4685.23	11.9709
4687.86	22.063
4690.48	-7.22375
4693.1	15.268
4695.73	53.5319
4698.34	16.2592
4700.96	42.1565
4703.58	7.0744
4706.2	13.7241
4708.82	4.53387
4711.43	19.0731
4714.05	25.6946
4716.66	32.3004
4719.28	28.6926
4721.89	14.8644
4724.5	35.01
4727.11	34.8187
4729.72	5.15326
4732.33	24.2714
4734.93	10.4713
4737.54	-1.09061
4740.14	3.22522
4742.75	23.4479
4745.35	24.3078
4747.95	22.8583
4750.55	36.1369
4753.15	23.2553
4755.75	33.1235
4758.35	9.98013
4760.95	36.9617
4763.54	7.04727
4766.14	-1.21683
4768.73	35.0533
4771.33	4.11224
4773.92	19.8293
4776.51	28.7176
4779.1	28.4789
4781.69	27.089
4784.28	7.41269
4786.87	26.6003
4789.45	18.3494
4792.04	-7.06448
4794.63	16.7545
4797.21	25.7173
4799.79	26.707
4802.37	25.4289
4804.95	24.1819
4807.53	22.9849
4810.11	10.3064
4812.69	21.7872
4815.27	3.3287
4817.84	12.5648
4820.42	38.0368
4822.99	12.6383
4825.57	18.473
4828.14	5.74518
4830.71	19.7121
4833.28	38.4086
4835.85	2.41403
4838.42	36.3705
4840.98	9.69525
4843.55	7.49646
4846.12	39.2144
4848.68	20.4967
4851.24	16.8814
4853.81	8.29083
4856.37	24.4574
4858.93	10.434
4861.49	21.1068
4864.05	-3.72858
4866.61	7.88428
4869.16	24.2715
4871.72	20.6535
4874.27	21.6708
4876.83	4.85834
4879.38	16.4959
4881.93	28.1245
4884.49	8.85388
4887.04	18.0859
4889.58	13.0654
4892.13	11.6109
4894.68	32.7649
4897.23	20.5681
4899.77	20.2673
4902.32	29.4993
4904.86	20.8376
4907.4	0.212555
4909.95	2.24948
4912.49	0.621094
4915.03	12.1056
4917.57	-8.69681
4920.1	3.99097
4922.64	33.4082
4925.18	16.2372
4927.71	11.0414
4930.25	3.40665
4932.78	30.5428
4935.31	38.6397
4937.84	6.01218
4940.38	15.2549
4942.9	1.58997
4945.43	6.02231
4947.96	0.936218
4950.49	19.8044
4953.01	26.7349
4955.54	4.83337
4958.06	3.3869
4960.59	4.37283
4963.11	18.6198
4965.63	17.3565
4968.15	-5.52368
4970.67	17.2716
4973.19	38.8877
4975.71	0.129486
4978.22	21.7555
4980.74	26.4985
4983.25	20.355
4985.77	-10.032
4988.28	25.0699
4990.79	8.01437
4993.3	29.8257
4995.81	2.98712
4998.32	0.526672