File: Data/3-Raman/processed/bu19w-b-ff1-fi02-l_150 (500nm)_532nm_edge_100%_x100_vis_h50um_15sx2_01.txt
#Acq. time (s)=	15
#Accumulations=	2
#Range (cm-¹)=	100...5000
#Windows=	1
#Auto scanning=	Off
#Autofocus=	Off
#Macrospot=	Off
#AutoExposure=	Off
#Spike filter=	Multiple accum.
#Delay time (s)=	2
#Binning=	1
#Readout mode=	Signal
#DeNoise=	Off
#ICS correction=	On
#Dark correction=	Off
#Inst. Process=	Off
#Detector Gain=	Best Dynamic
#Detector ADC=	50 kHz HS
#Detector temperature (°C)=	-60.09
#Instrument=	LabRAM HR Evol
#Detector=	SIN-EM FIVIS
#Objective=	x100_VIS
#Grating=	150 (500nm)
#ND Filter=	100%
#Laser=	532nm_Edge
#Hole=	49.98
#Temperature=	0
#Range=	Visible
#StageXY=	75x50mm Scan+
#StageZ=	Z motor
#X (µm)=	0
#Y (µm)=	0
#Z (µm)=	-135.8
#Full time(s)=	34
#Project=	21_05_14
#Sample=	BU19w
#Site=
#Title=	BU19w-FF1-FI02-L_150 (500nm)_532nm_Edge_100%_x100_VIS_H50um_15sX2
#Remark=
#Date=	14.05.2021 12:03
#Acquired=	14.05.2021 12:03:39
#Base:Fit=	22.12.2021 12:22:35
#Base:Sub=	22.12.2021 12:23:43
#Data Range:Extract=	22.12.2021 12:27:19
102.699	5218.61
107.322	4677.96
111.942	4275.49
116.56	3970.03
121.173	3691.2
125.787	3376.81
130.398	3021.06
135.006	2803.38
139.613	2708.26
144.215	2398.36
148.817	2287.82
153.417	2188.69
158.014	2094.48
162.607	1895.71
167.2	1835.84
171.79	2232.09
176.379	3173.38
180.963	2910.08
185.547	1861.69
190.128	1425.14
194.705	1607.47
199.282	3661.42
203.857	7521.06
208.43	5693.95
212.998	1900.47
217.566	709.805
222.132	362.88
226.693	275.547
231.254	202.21
235.813	56.9036
240.368	7.12549
244.923	0.000488281
249.475	75.1135
254.023	109.941
258.571	294.04
263.117	682.059
267.658	717.145
272.199	480.763
276.738	158.895
281.273	171.895
285.807	597.305
290.34	2277.48
294.868	4510.96
299.396	3716.32
303.919	1503.2
308.443	637.817
312.964	908.795
317.481	2184.19
321.998	2504.56
326.51	1074.47
331.023	199.798
335.533	80.1975
340.039	326.559
344.544	735.915
349.046	747.35
353.547	263.746
358.045	-10.1772
362.542	74.1177
367.036	56.783
371.527	-50.8623
376.017	-190.837
380.503	-207.228
384.99	-155.527
389.471	-92.7473
393.953	-80.2427
398.43	253.731
402.908	592.799
407.381	756.097
411.854	823.628
416.323	650.31
420.791	386.847
425.256	319.89
429.72	612.735
434.18	922.873
438.64	496.556
443.095	80.2507
447.551	-52.1433
452.003	-57.5176
456.454	-10.0696
460.901	113.364
465.348	573.36
469.791	1658.24
474.231	2040.42
478.672	954.614
483.108	281.464
487.544	138.636
491.976	75.4197
496.408	117.875
500.836	274.838
505.261	425.556
509.687	542.05
514.108	546.53
518.529	545.199
522.946	383.337
527.361	328.882
531.776	244.935
536.187	236.137
540.595	254.939
545.003	275.844
549.408	332.674
553.812	365.14
558.212	366.126
562.61	398.632
567.007	340.136
571.401	427.879
575.792	459.019
580.184	459.709
584.571	357.494
588.956	236.669
593.341	285.216
597.722	497.916
602.101	1254.09
606.48	1794.1
610.854	1247.78
615.227	662.593
619.597	696.37
623.967	1086.58
628.334	1554.95
632.698	1183.3
637.06	632.757
641.422	281.837
645.779	224.441
650.135	266.76
654.491	387.642
658.842	376.834
663.192	264.165
667.539	203.607
671.884	240.71
676.23	300.958
680.571	346.921
684.91	431.07
689.247	473.253
693.583	675.05
697.916	555.163
702.247	399.672
706.576	259.73
710.902	174.31
715.229	172.457
719.551	105.929
723.872	97.1227
728.19	84.0983
732.506	106.352
736.82	60.4546
741.134	51.8864
745.444	81.941
749.752	38.1345
754.058	157.703
758.362	124.614
762.664	146.342
766.964	151.973
771.264	259.089
775.559	356.923
779.853	436.149
784.144	860.391
788.434	1433.21
792.722	2124.45
797.007	2306.9
801.29	1556.28
805.572	871.688
809.851	524.078
814.13	345.149
818.406	263.813
822.679	163.117
826.95	159.417
831.219	127.092
835.486	160.69
839.752	89.2859
844.015	94.5996
848.276	57.6234
852.535	97.6299
856.792	60.4004
861.047	37.2664
865.3	57.4574
869.551	100.218
873.8	96.1758
878.047	218.828
882.292	258.187
886.534	161.157
890.775	81.2983
895.014	69.708
899.251	1.28174
903.486	-1.3092
907.719	29.2513
911.95	38.2856
916.179	37.1127
920.406	30.5573
924.63	24.6779
928.853	31.14
933.074	7.72766
937.293	-12.0105
941.51	35.4449
945.723	79.13
949.936	88.0132
954.147	111.944
958.356	183.88
962.563	274.972
966.768	305.48
970.971	361.882
975.172	364.272
979.371	512.28
983.568	648.623
987.761	548.378
991.954	355.478
996.145	237.186
1000.33	212.508
1004.52	182.656
1008.71	159.516
1012.89	172.824
1017.07	188.225
1021.25	135.236
1025.43	199.556
1029.6	173.141
1033.77	154.28
1037.95	217.69
1042.11	242.773
1046.28	277.548
1050.45	421.027
1054.61	514.441
1058.77	824.316
1062.93	1566.15
1067.09	2644.5
1071.24	2784.8
1075.4	1878.95
1079.55	1137.16
1083.7	793.217
1087.85	712.222
1091.99	826.882
1096.14	1175.34
1100.28	1773.46
1104.42	2529.44
1108.55	2631.88
1112.69	2121.65
1116.82	1732.93
1120.96	1811.13
1125.09	2184.47
1129.21	2217.64
1133.34	1927.07
1137.46	1691.75
1141.59	1764.52
1145.71	2074.99
1149.83	2099.37
1153.94	1749
1158.06	1227.56
1162.17	1060.73
1166.28	1180.27
1170.39	1544.98
1174.5	1840.25
1178.6	1498.58
1182.7	1060.77
1186.8	717.412
1190.9	583.547
1195	418.805
1199.1	321.362
1203.19	320.711
1207.28	341.341
1211.37	356.953
1215.46	373.527
1219.54	293.889
1223.63	305.112
1227.71	279.137
1231.79	276.05
1235.87	390.59
1239.95	461.105
1244.02	442.029
1248.09	448.584
1252.16	660.464
1256.23	788.061
1260.3	782.228
1264.36	515.593
1268.43	433.366
1272.49	373.079
1276.55	378.844
1280.6	358.345
1284.66	283.828
1288.71	229.271
1292.76	196.309
1296.81	174.307
1300.86	149.908
1304.91	145.292
1308.95	143.784
1312.99	140.557
1317.03	148.718
1321.07	114.351
1325.11	116.118
1329.14	122.321
1333.18	163.773
1337.21	108.529
1341.24	82.2118
1345.26	95.7428
1349.29	116.242
1353.31	100.946
1357.33	83.7196
1361.35	141.763
1365.37	141.887
1369.39	201.474
1373.4	239.812
1377.41	435.924
1381.43	721.138
1385.43	927.43
1389.44	838.682
1393.45	472.534
1397.45	296.695
1401.45	214.825
1405.45	95.7343
1409.45	107.871
1413.44	78.7295
1417.44	105.773
1421.43	39.9048
1425.42	44.4376
1429.41	27.5715
1433.39	47.7831
1437.38	19.298
1441.36	81.7161
1445.34	45.9799
1449.32	29.9426
1453.3	40.1233
1457.27	14.6669
1461.24	60.5366
1465.22	35.0754
1469.19	13.8201
1473.15	9.36023
1477.12	16.2465
1481.09	22.0266
1485.05	7.11377
1489.01	67.4198
1492.97	57.5454
1496.93	0.0408936
1500.88	42.2555
1504.83	48.8866
1508.79	51.0814
1512.74	94.0646
1516.68	29.5125
1520.63	46.6968
1524.57	49.455
1528.52	37.9015
1532.46	45.9235
1536.4	40.3882
1540.33	78.5348
1544.27	36.2468
1548.2	88.9366
1552.14	75.6245
1556.07	67.8003
1559.99	120.699
1563.92	94.024
1567.84	94.269
1571.77	106.027
1575.69	95.5371
1579.61	111.023
1583.52	92.6674
1587.44	137.766
1591.35	183.742
1595.27	169.063
1599.18	191.019
1603.09	201.722
1606.99	169.483
1610.9	237.029
1614.8	234.856
1618.7	278.763
1622.6	239.387
1626.5	258.876
1630.39	273.103
1634.29	322.203
1638.18	367.58
1642.07	314.13
1645.96	301.164
1649.85	333.435
1653.73	313.865
1657.62	329.626
1661.5	326.904
1665.38	305.505
1669.26	284.613
1673.13	296.867
1677.01	271.999
1680.88	247.027
1684.75	200.78
1688.62	165.803
1692.49	163.03
1696.35	103.575
1700.22	198.437
1704.08	129.645
1707.94	139.547
1711.8	71.4446
1715.66	110.696
1719.51	66.7411
1723.37	99.2413
1727.22	64.5286
1731.07	119.98
1734.92	52.5535
1738.76	53.3032
1742.61	55.8796
1746.45	58.3206
1750.29	90.677
1754.13	21.8528
1757.97	24.2559
1761.81	61.9961
1765.64	35.769
1769.47	-5.87866
1773.31	49.5767
1777.14	60.7969
1780.96	40.0105
1784.79	35.2813
1788.61	45.6863
1792.43	35.5654
1796.25	25.3843
1800.07	20.0137
1803.89	13.8376
1807.71	67.8984
1811.52	69.8262
1815.33	52.1919
1819.14	64.9275
1822.95	60.2666
1826.76	19.2781
1830.56	54.1047
1834.37	85.6252
1838.17	19.8684
1841.97	44.0378
1845.77	36.175
1849.56	67.3042
1853.36	49.7781
1857.15	1.88916
1860.94	33.8708
1864.73	39.7524
1868.52	45.8633
1872.31	49.5244
1876.09	45.1558
1879.87	-1.97144
1883.66	10.4592
1887.43	40.8088
1891.21	61.3159
1894.99	30.1433
1898.76	69.4783
1902.53	68.1055
1906.31	55.9453
1910.08	77.5088
1913.84	48.8213
1917.61	67.1003
1921.37	42.7073
1925.14	91.7229
1928.9	60.3875
1932.66	65.2798
1936.41	79.4446
1940.17	58.085
1943.92	76.4211
1947.68	115.448
1951.43	93.6365
1955.18	67.0298
1958.92	67.4924
1962.67	125.995
1966.41	80.0149
1970.16	99.5818
1973.9	130.884
1977.64	83.0352
1981.37	121.002
1985.11	122.06
1988.84	112.696
1992.57	85.1448
1996.31	78.7097
2000.03	148.905
2003.76	113.731
2007.49	136.015
2011.21	105.639
2014.93	126.478
2018.65	101.073
2022.37	118.844
2026.09	130.466
2029.81	153.553
2033.52	129.358
2037.23	156.713
2040.94	152.164
2044.65	149.115
2048.36	99.8552
2052.07	149.795
2055.77	120.438
2059.47	78.1533
2063.17	143.108
2066.87	165.267
2070.57	148.837
2074.27	162.897
2077.96	180.042
2081.65	161.926
2085.34	211.12
2089.03	220.184
2092.72	166.324
2096.41	141.686
2100.09	129.846
2103.77	173.453
2107.46	144.114
2111.14	148.058
2114.81	128.698
2118.49	163.487
2122.16	134.239
2125.84	154.012
2129.51	189.988
2133.18	113.008
2136.85	144.893
2140.51	138.463
2144.18	161.288
2147.84	164.68
2151.5	151.577
2155.16	149.632
2158.82	127.722
2162.48	137.314
2166.13	139.021
2169.79	168.71
2173.44	145.565
2177.09	156.286
2180.74	151.744
2184.38	158.14
2188.03	190.166
2191.67	194.803
2195.32	162.952
2198.96	150.396
2202.6	146.361
2206.23	173.769
2209.87	197.034
2213.5	161.928
2217.14	200.185
2220.77	164.193
2224.4	182.427
2228.03	157.22
2231.65	132.168
2235.28	134.845
2238.9	135.547
2242.52	149.214
2246.14	142.443
2249.76	164.757
2253.38	166.857
2256.99	148.484
2260.6	190.667
2264.21	168.23
2267.82	141.54
2271.44	172.142
2275.04	167.983
2278.65	170.468
2282.25	134.064
2285.85	170.848
2289.45	96.6436
2293.05	125.394
2296.65	124.979
2300.25	142.396
2303.84	131.818
2307.43	72.5178
2311.02	119.076
2314.62	111.231
2318.2	128.531
2321.79	88.0605
2325.38	60.8723
2328.96	115.07
2332.54	113.969
2336.12	111.704
2339.7	128.895
2343.28	94.1604
2346.85	74.2942
2350.43	107.722
2354	139.961
2357.57	167.27
2361.14	95.7939
2364.71	64.5884
2368.27	70.9219
2371.84	141.306
2375.4	65.3325
2378.96	121.707
2382.52	96.2405
2386.08	117.085
2389.64	85.9983
2393.19	102.301
2396.75	107.41
2400.3	119.913
2403.85	127.747
2407.4	121.33
2410.95	62.6062
2414.49	91.4282
2418.04	86.7686
2421.58	42.8752
2425.12	72.3049
2428.66	128.197
2432.2	106.032
2435.74	87.8455
2439.27	132.995
2442.81	108.521
2446.34	67.3337
2449.87	95.7925
2453.4	89.9487
2456.93	102.837
2460.45	44.0674
2463.98	140.005
2467.5	79.1494
2471.02	69.7102
2474.54	104.591
2478.06	110.069
2481.58	72.7371
2485.09	83.1833
2488.61	108.606
2492.12	78.8525
2495.63	50.4668
2499.14	44.0349
2502.65	46.1384
2506.15	110.435
2509.66	73.7637
2513.16	54.4016
2516.66	83.8181
2520.16	79.6833
2523.66	89.6748
2527.16	50.8169
2530.66	122.184
2534.15	79.6733
2537.64	32.0901
2541.13	50.0049
2544.62	72.7661
2548.11	54.1833
2551.6	104.332
2555.08	58.6162
2558.57	83.27
2562.05	105.142
2565.53	57.9939
2569.01	81.2781
2572.49	54.5525
2575.96	83.5454
2579.44	90.3018
2582.91	92.4595
2586.38	71.5857
2589.85	93.1628
2593.32	65.4849
2596.79	86.9595
2600.25	107.756
2603.72	113.266
2607.18	42.3062
2610.64	74.5725
2614.1	34.7993
2617.56	43.2249
2621.02	48.3376
2624.47	41.2957
2627.92	87.6829
2631.38	48.1472
2634.83	80.8491
2638.28	71.908
2641.72	49.0637
2645.17	65.3569
2648.61	46.8367
2652.06	40.2004
2655.5	40.6624
2658.94	14.3384
2662.38	32.2961
2665.82	-2.65405
2669.25	19.7131
2672.69	70.4529
2676.12	37.8708
2679.55	54.4812
2682.98	31.4167
2686.41	51.689
2689.84	31.3391
2693.26	2.94922
2696.69	47.6172
2700.11	44.2139
2703.53	69.1172
2706.95	43.6414
2710.37	43.8499
2713.79	59.3767
2717.2	54.8789
2720.62	4.08618
2724.03	70.05
2727.44	14.8867
2730.85	87.665
2734.26	21.0029
2737.66	56.4417
2741.07	49.3298
2744.47	43.6372
2747.87	53.947
2751.28	65.166
2754.67	52.4045
2758.07	77.6042
2761.47	31.5288
2764.86	29.4263
2768.26	69.2793
2771.65	43.9927
2775.04	40.021
2778.43	56.4275
2781.82	46.2683
2785.2	35.0823
2788.59	37.988
2791.97	49.1538
2795.35	77.4294
2798.73	67.6438
2802.11	71.9561
2805.49	47.2141
2808.87	31.7471
2812.24	54.5662
2815.62	38.8354
2818.99	78.5095
2822.36	59.7271
2825.73	58.8281
2829.1	65.6135
2832.46	92.3784
2835.83	71.9849
2839.19	70.6384
2842.55	121.919
2845.91	39.6582
2849.27	69.3242
2852.63	69.6069
2855.99	88.8337
2859.34	120.628
2862.69	44.8254
2866.05	100.294
2869.4	89.0376
2872.75	77.6875
2876.09	116.119
2879.44	97.1465
2882.78	81.7314
2886.13	100.099
2889.47	104.495
2892.81	122.427
2896.15	111.715
2899.49	168.763
2902.82	105.34
2906.16	113.663
2909.49	81.9998
2912.82	120.36
2916.16	111.944
2919.49	159.178
2922.81	123.123
2926.14	147.147
2929.46	115.316
2932.79	157.584
2936.11	143.205
2939.43	156.182
2942.75	188.942
2946.07	153.122
2949.39	214.135
2952.7	224.233
2956.02	187.748
2959.33	180.768
2962.64	214.068
2965.95	266.626
2969.26	244.151
2972.57	270.969
2975.87	279.017
2979.17	287.506
2982.48	280.171
2985.78	273.018
2989.08	306.317
2992.38	316.259
2995.68	337.664
2998.97	400.503
3002.27	309.002
3005.56	385.171
3008.85	356.09
3012.14	438.277
3015.43	384.75
3018.72	450.899
3022	496.344
3025.29	531.52
3028.57	501.545
3031.85	503.563
3035.14	526.257
3038.41	527.247
3041.69	568.952
3044.97	564.411
3048.24	614.714
3051.52	631.101
3054.79	615.203
3058.06	710.916
3061.33	714.926
3064.6	759.054
3067.87	782.88
3071.13	847.161
3074.4	848.435
3077.66	875.327
3080.92	863.066
3084.18	928.247
3087.44	962.72
3090.7	1005.54
3093.95	1026.33
3097.21	1087.46
3100.46	1091.58
3103.71	1164.24
3106.96	1190.49
3110.21	1275.78
3113.46	1306.75
3116.71	1395.03
3119.95	1411.95
3123.2	1504.11
3126.44	1548.55
3129.68	1612.1
3132.92	1674.67
3136.16	1689.42
3139.4	1806.09
3142.63	1858.89
3145.87	1930.02
3149.1	1936.48
3152.33	2092.58
3155.56	2163.89
3158.79	2262.8
3162.02	2288.27
3165.25	2317.29
3168.47	2432.8
3171.69	2510.89
3174.92	2593.38
3178.14	2631.81
3181.36	2770.5
3184.58	2779.99
3187.79	2895.04
3191.01	3002.37
3194.22	3039.09
3197.43	3114.71
3200.65	3213.27
3203.86	3258.67
3207.07	3307.12
3210.27	3341.62
3213.48	3486.88
3216.69	3513.3
3219.89	3626.4
3223.09	3664.87
3226.29	3737.78
3229.49	3754.11
3232.69	3840.49
3235.89	3866.95
3239.08	3911.14
3242.28	3950.96
3245.47	4040.39
3248.66	4118.02
3251.85	4060.57
3255.04	4193.99
3258.23	4268.6
3261.42	4261.2
3264.6	4295.88
3267.79	4338.46
3270.97	4380.54
3274.15	4408.3
3277.33	4484.69
3280.51	4508.08
3283.68	4427.41
3286.86	4515.07
3290.04	4495.33
3293.21	4575.59
3296.38	4590.75
3299.55	4610.45
3302.72	4749.86
3305.89	4707.61
3309.06	4853.53
3312.22	4843.83
3315.39	4913.68
3318.55	4955.64
3321.71	4953.95
3324.87	5052.65
3328.03	4999.02
3331.19	5215.21
3334.34	5245.65
3337.5	5321.06
3340.65	5400.17
3343.81	5466.46
3346.96	5550
3350.11	5586.52
3353.25	5687.89
3356.4	5702
3359.55	5767.04
3362.69	5818.25
3365.84	5918.94
3368.98	6021.82
3372.12	6129.47
3375.26	6169.67
3378.4	6173.64
3381.53	6328.4
3384.67	6377.08
3387.8	6378.65
3390.94	6577.62
3394.07	6693.79
3397.2	6790.66
3400.33	6939.49
3403.46	6973.65
3406.58	6984.71
3409.71	7174.1
3412.83	7254.1
3415.96	7307.58
3419.08	7571.36
3422.2	7936.73
3425.32	8971.64
3428.44	11498.9
3431.55	16712.5
3434.67	19309
3437.78	14469.3
3440.89	10137.1
3444	8517.41
3447.12	7851.3
3450.22	7581.63
3453.33	7357.88
3456.44	7364.29
3459.54	7258.16
3462.65	7227.87
3465.75	7218.69
3468.85	7108.08
3471.95	7055.3
3475.05	7011.04
3478.15	6890.71
3481.24	6784.92
3484.34	6758.18
3487.43	6668.04
3490.53	6668.55
3493.62	6552.37
3496.71	6621.14
3499.79	6467.12
3502.88	6496.2
3505.97	6581.47
3509.05	6752.35
3512.14	6907.91
3515.22	6958.25
3518.3	6773.23
3521.38	6371.5
3524.46	6124.66
3527.54	5746.31
3530.61	5427.97
3533.69	5290.67
3536.76	5079.41
3539.83	4886.24
3542.9	4782.4
3545.97	4600.4
3549.04	4553.33
3552.11	4386.74
3555.18	4267.33
3558.24	4097.33
3561.3	3944.72
3564.37	3892.89
3567.43	3733.24
3570.49	3723.3
3573.55	3555.3
3576.61	3463.86
3579.66	3426.05
3582.72	3234.11
3585.77	3206.13
3588.82	3120.8
3591.87	3002.08
3594.92	2909.6
3597.97	2846.44
3601.02	2771.63
3604.07	2644.44
3607.11	2656.3
3610.16	2563.05
3613.2	2443.26
3616.24	2347.31
3619.28	2235.63
3622.32	2171.37
3625.36	2132.86
3628.39	2060.4
3631.43	1994.35
3634.46	1915.81
3637.5	1759.85
3640.53	1782.17
3643.56	1672.7
3646.59	1583.4
3649.62	1509.58
3652.64	1442.59
3655.67	1298.11
3658.69	1244.66
3661.72	1226.5
3664.74	1132.59
3667.76	1083.99
3670.78	977.162
3673.79	887.355
3676.81	859.943
3679.83	753.051
3682.84	674.377
3685.86	657.166
3688.87	612.552
3691.88	593.535
3694.89	526.707
3697.9	446.789
3700.91	420.995
3703.91	318.239
3706.92	342.501
3709.92	323.834
3712.92	312.497
3715.92	268.866
3718.92	274.551
3721.92	239.115
3724.92	211.105
3727.92	201.996
3730.91	167.006
3733.91	172.76
3736.9	145.977
3739.89	150.403
3742.88	106.146
3745.87	155.888
3748.86	97.0946
3751.85	99.0901
3754.83	70.7578
3757.82	74.696
3760.8	76.6003
3763.78	91.7509
3766.76	70.0846
3769.74	98.7402
3772.72	77.4069
3775.7	45.8093
3778.67	34.1989
3781.65	69.8591
3784.62	51.7676
3787.6	57.3743
3790.57	0.932007
3793.54	34.3375
3796.51	47.0804
3799.47	42.1007
3802.44	25.9146
3805.41	28.6665
3808.37	39.0793
3811.33	33.4872
3814.3	29.8209
3817.26	44.199
3820.22	16.0276
3823.18	11.6183
3826.13	42.3207
3829.09	39.8414
3832.04	36.5359
3835	34.2892
3837.95	28.2605
3840.9	-3.4718
3843.85	10.451
3846.8	-3.17102
3849.75	-8.14343
3852.69	47.0299
3855.64	22.1046
3858.58	-0.921631
3861.53	28.5371
3864.47	26.4432
3867.41	5.06531
3870.35	55.4991
3873.29	12.8793
3876.22	68.9312
3879.16	54.7476
3882.1	8.63733
3885.03	12.3337
3887.96	8.26123
3890.89	75.2881
3893.82	60.408
3896.75	23.1888
3899.68	3.2439
3902.61	15.7621
3905.53	24.5887
3908.46	48.7131
3911.38	-2.2627
3914.3	36.8873
3917.23	50.3876
3920.15	30.0757
3923.06	19.1631
3925.98	3.3158
3928.9	24.7034
3931.81	27.2048
3934.73	32.9047
3937.64	37.0665
3940.55	51.6665
3943.46	38.5244
3946.37	41.8088
3949.28	40.4443
3952.19	16.156
3955.09	66.7095
3958	13.8977
3960.9	28.2157
3963.8	36.8773
3966.71	36.996
3969.61	57.3326
3972.51	8.54126
3975.4	78.7372
3978.3	54.6888
3981.2	78.6534
3984.09	43.8925
3986.99	40.8468
3989.88	25.9878
3992.77	36.3978
3995.66	52.5978
3998.55	58.288
4001.43	45.702