File: Data/3-Raman/processed/bu19w-a-ff07a-fi02-v_150 (500nm)_532nm_edge_10%_x100_vis_lwd_h50um_20sx2_01_0.txt
#Acq. time (s)=	20
#Accumulations=	2
#Range (cm-¹)=	50...5000
#Windows=	1
#Auto scanning=	Off
#Autofocus=	Off
#Macrospot=	Off
#AutoExposure=	Off
#Spike filter=	Multiple accum.
#Delay time (s)=	2
#Binning=	1
#Readout mode=	Signal
#DeNoise=	Off
#ICS correction=	On
#Dark correction=	Off
#Inst. Process=	Off
#Detector Gain=	Best Dynamic
#Detector ADC=	50 kHz HS
#Detector temperature (°C)=	-60.09
#Instrument=	LabRAM HR Evol
#Detector=	SIN-EM FIVIS
#Objective=	x100_VIS_LWD
#Grating=	150 (500nm)
#ND Filter=	10%
#Laser=	532nm_Edge
#Hole=	49.98
#Temperature=	0
#Range=	Visible
#StageXY=	75x50mm Scan+
#StageZ=	Z motor
#X (µm)=	0
#Y (µm)=	0
#Z (µm)=	-12.5
#Full time(s)=	45
#Project=	21_05_28
#Sample=	BU19w
#Site=
#Title=	BU19w-FF07a-FI02-V_150 (500nm)_532nm_Edge_10%_x100_VIS_LWD_H50um_20sX2
#Remark=
#Date=	28.05.2021 17:41
#Acquired=	28.05.2021 17:41:38
#Base:Fit=	16.12.2021 17:39:50
#Base:Sub=	16.12.2021 17:57:42
51.5961	3094.5
56.2453	2297.21
60.8921	2164.26
65.5367	1741.46
70.1768	948.172
74.8167	597.557
79.4543	413.213
84.0897	304.739
88.7227	217.701
93.3513	176.467
97.9798	145.744
102.606	99.1977
107.23	93.6077
111.851	75.4249
116.469	53.3444
121.086	26.2946
125.7	16.6261
130.313	13.2188
134.921	14.7749
139.529	10.1545
144.134	3.07304
148.738	2.10466
153.337	-0.116791
157.936	70.0051
162.532	178.003
167.126	151.17
171.716	42.3617
176.306	15.6145
180.894	34.1329
185.477	179.845
190.06	464.971
194.64	336.619
199.219	127.495
203.793	36.9778
208.367	0.239471
212.939	0.166321
217.506	1.28366
222.073	2.36819
226.638	-0.267868
231.199	6.80347
235.759	40.6998
240.318	52.5279
244.872	97.211
249.425	167.37
253.977	153.317
258.524	84.5126
263.071	52.2801
267.616	48.0189
272.156	97.133
276.697	250.422
281.233	484.762
285.769	378.786
290.303	222.215
294.832	121.373
299.361	144.272
303.886	223.212
308.411	253.438
312.934	157.42
317.452	81.0212
321.97	69.3928
326.484	94.8461
330.998	141.482
335.507	129.008
340.017	80.9142
344.524	62.3157
349.027	100.466
353.53	110.841
358.028	71.4939
362.527	52.8672
367.021	38.8297
371.515	61.6216
376.004	61.4685
380.494	47.8869
384.979	77.2403
389.465	108.007
393.946	134.497
398.427	138.367
402.903	131.795
407.38	84.7907
411.852	109.082
416.324	187.779
420.792	257.953
425.26	189.014
429.723	82.5071
434.187	29.3426
438.646	22.2814
443.105	14.1095
447.56	31.6826
452.015	89.4259
456.466	143.687
460.914	156.136
465.362	98.7719
469.807	59.6248
474.251	35.9056
478.69	27.3414
483.13	48.9978
487.566	55.6818
491.999	76.3795
496.432	74.696
500.861	100.759
505.29	81.9754
509.715	57.6317
514.138	54.1025
518.56	45.945
522.979	36.697
527.395	34.4251
531.811	36.8118
536.223	42.7079
540.635	46.2978
545.042	44.0812
549.448	52.3063
553.853	54.705
558.255	58.1398
562.654	56.4227
567.053	63.0112
571.448	35.7277
575.841	41.5088
580.232	33.8268
584.622	49.2277
589.009	142.031
593.393	183.166
597.777	147.991
602.157	87.61
606.535	78.1676
610.913	129.362
615.287	151.551
619.659	119.075
624.029	78.3112
628.398	40.892
632.763	37.4362
637.127	33.9071
641.488	56.7512
645.849	37.2329
650.206	37.0766
654.561	26.5359
658.914	39.5705
663.267	71.9821
667.615	73.553
671.962	87.5043
676.307	85.5145
680.649	114.985
684.991	101.652
689.33	54.8989
693.666	42.172
698	27.023
702.332	21.3361
706.662	18.8053
710.992	14.6804
715.318	17.2248
719.641	18.5004
723.963	12.9454
728.283	2.03278
732.6	4.22092
736.918	-0.230637
741.231	17.6309
745.542	16.0569
749.852	22.8241
754.159	36.1165
758.464	39.8671
762.767	36.8637
767.068	57.2412
771.369	84.5383
775.666	125.779
779.961	213.6
784.254	207.121
788.545	136.893
792.834	93.402
797.12	61.9925
801.405	38.4841
805.688	34.9597
809.968	24.9131
814.247	35.7912
818.524	11.5061
822.798	16.9149
827.071	19.0749
831.341	15.7469
835.612	25.6452
839.878	18.9985
844.142	26.6681
848.405	13.3068
852.665	5.36337
856.923	17.2701
861.18	18.1427
865.434	0.265793
869.686	23.0571
873.936	15.0017
878.185	4.73047
882.431	27.295
886.675	20.1986
890.915	5.40414
895.155	9.08978
899.393	15.2304
903.63	25.0104
907.864	7.41861
912.096	5.90169
916.326	9.8972
920.554	17.0849
924.78	14.4794
929.004	19.3133
933.227	23.2773
937.447	16.4869
941.665	28.9405
945.881	31.7066
950.095	50.466
954.305	74.5533
958.516	44.3191
962.724	56.712
966.93	48.9241
971.134	71.9476
975.337	57.8757
979.537	37.4947
983.735	40.4744
987.93	31.8026
992.124	31.6227
996.316	25.2356
1000.51	25.3191
1004.7	10.5892
1008.88	21.3485
1013.06	23.6313
1017.25	30.1327
1021.43	36.6461
1025.61	34.5883
1029.78	33.5224
1033.96	50.549
1038.13	57.7361
1042.3	70.0999
1046.47	95.1843
1050.63	188.083
1054.8	300.675
1058.96	296.298
1063.12	188.435
1067.28	124.19
1071.44	92.7925
1075.59	102.324
1079.74	113.863
1083.89	143.922
1088.04	246.222
1092.19	348.972
1096.33	338.171
1100.48	254.783
1104.62	238.358
1108.76	281.423
1112.89	328.636
1117.03	299.426
1121.16	235.238
1125.29	214.218
1129.42	200.438
1133.55	214.364
1137.68	238.488
1141.8	159.938
1145.92	132.643
1150.04	115.475
1154.16	123.885
1158.27	172.433
1162.39	187.904
1166.5	161.98
1170.61	116.38
1174.72	100.629
1178.82	77.6439
1182.93	38.2279
1187.03	33.7749
1191.13	40.5034
1195.23	38.9515
1199.33	38.3584
1203.42	35.6764
1207.51	54.3174
1211.6	42.4817
1215.69	25.6711
1219.78	42.2112
1223.86	65.7325
1227.95	72.1515
1232.03	58.6189
1236.11	63.2993
1240.18	94.0866
1244.26	86.8358
1248.33	80.6915
1252.41	61.7037
1256.48	57.7392
1260.54	55.8085
1264.61	42.9068
1268.67	39.0376
1272.74	155.479
1276.8	279.206
1280.86	134.964
1284.91	37.6405
1288.97	21.6262
1293.02	28.7249
1297.07	28.7502
1301.12	40.8491
1305.17	15.6222
1309.21	25.6559
1313.25	27.6039
1317.3	26.4564
1321.34	30.3034
1325.37	18.9771
1329.41	22.7244
1333.44	21.4225
1337.48	30.0821
1341.5	33.6762
1345.53	27.2484
1349.56	21.8364
1353.59	20.4287
1357.61	29.9608
1361.63	27.5446
1365.65	35.0708
1369.66	27.7817
1373.68	67.9378
1377.69	342.691
1381.7	353.975
1385.72	106.543
1389.72	30.6188
1393.73	24.6564
1397.73	40.4386
1401.74	54.2457
1405.74	35.5386
1409.73	13.8827
1413.73	32.6611
1417.73	11.9924
1421.72	25.8539
1425.71	32.7878
1429.7	5.05772
1433.69	18.8211
1437.67	18.7557
1441.66	15.732
1445.64	7.74451
1449.62	9.61885
1453.6	21.3242
1457.57	13.2822
1461.55	12.1125
1465.52	10.8858
1469.49	27.3447
1473.46	16.3008
1477.43	15.0637
1481.39	12.8256
1485.36	16.4516
1489.32	20.0543
1493.28	8.04816
1497.24	11.6716
1501.19	-0.270065
1505.15	19.9395
1509.1	12.9572
1513.05	14.7394
1517	14.5891
1520.95	11.5495
1524.9	9.49521
1528.84	9.39638
1532.78	22.893
1536.72	12.1592
1540.66	19.8483
1544.6	11.0636
1548.53	17.7846
1552.46	8.03548
1556.4	5.04774
1560.32	8.81177
1564.25	14.4876
1568.18	13.3692
1572.1	9.33932
1576.02	19.7979
1579.94	9.96925
1583.86	32.9349
1587.78	5.75032
1591.69	11.3359
1595.61	20.7554
1599.52	3.2551
1603.43	29.9638
1607.34	9.65202
1611.24	11.4254
1615.15	21.836
1619.05	16.9376
1622.95	15.8621
1626.85	0.460159
1630.74	22.4145
1634.64	13.8028
1638.53	24.3255
1642.42	20.542
1646.31	17.7548
1650.2	21.6958
1654.09	12.2192
1657.97	16.156
1661.86	13.3655
1665.74	13.4192
1669.62	22.1052
1673.49	17.2729
1677.37	20.1205
1681.24	17.0967
1685.12	10.1895
1688.99	27.2518
1692.86	28.9117
1696.72	6.62575
1700.59	17.7999
1704.45	15.5494
1708.31	12.3149
1712.17	-0.442184
1716.03	16.2338
1719.89	16.7721
1723.74	8.81958
1727.6	1.82605
1731.45	17.3864
1735.3	26.3312
1739.14	21.1803
1742.99	12.2968
1746.83	6.25989
1750.68	1.28925
1754.52	12.1772
1758.36	5.52939
1762.19	20.5332
1766.03	10.344
1769.86	8.58064
1773.69	9.69426
1777.53	16.4011
1781.35	16.6661
1785.18	15.0974
1789	7.93477
1792.83	19.4915
1796.65	6.69626
1800.47	9.82803
1804.29	16.6126
1808.1	7.38448
1811.92	24.5138
1815.73	30.3141
1819.54	5.83525
1823.35	20.9334
1827.16	12.4081
1830.97	9.49474
1834.77	11.2482
1838.58	8.26146
1842.38	10.8947
1846.18	0.329987
1849.97	7.63693
1853.77	11.0916
1857.56	18.2256
1861.36	25.269
1865.15	14.5793
1868.93	16.9565
1872.72	5.44778
1876.51	18.0657
1880.29	10.345
1884.07	27.6166
1887.86	9.87039
1891.63	21.8172
1895.41	14.4416
1899.19	18.1099
1902.96	20.9441
1906.73	-0.119781
1910.5	11.0568
1914.27	21.3984
1918.04	4.08241
1921.8	21.0473
1925.57	7.52377
1929.33	19.968
1933.09	14.8118
1936.85	9.62971
1940.6	9.08917
1944.36	17.8965
1948.11	8.92918
1951.87	30.7546
1955.61	31.8786
1959.36	12.2313
1963.11	13.1821
1966.86	12.2447
1970.6	11.2486
1974.34	9.24794
1978.08	7.21404
1981.82	19.189
1985.56	15.2152
1989.29	18.6951
1993.02	16.5447
1996.75	14.3644
2000.49	12.1568
2004.21	23.8559
2007.94	25.3219
2011.67	11.987
2015.39	22.6296
2019.11	21.3931
2022.83	30.3488
2026.55	14.6805
2030.27	24.6736
2033.98	9.12834
2037.69	15.6181
2041.41	18.431
2045.12	3.83319
2048.82	12.1299
2052.53	15.8875
2056.24	24.2395
2059.94	15.2846
2063.64	17.4464
2067.34	17.8228
2071.04	26.5089
2074.74	9.38431
2078.43	6.0824
2082.13	4.63435
2085.82	38.4303
2089.51	18.1847
2093.2	10.8426
2096.88	25.8935
2100.57	17.6753
2104.25	12.1783
2107.94	26.1799
2111.62	22.4799
2115.3	10.4097
2118.97	16.9094
2122.65	22.3977
2126.32	16.7029
2129.99	16.5506
2133.66	14.5306
2137.33	12.5039
2141	20.6034
2144.67	23.1202
2148.33	17.3378
2151.99	17.082
2155.66	24.1691
2159.31	12.0215
2162.97	13.6433
2166.63	7.07738
2170.28	3.2952
2173.94	2.32689
2177.59	18.6972
2181.24	15.058
2184.89	20.5106
2188.53	20.5558
2192.18	18.8572
2195.82	10.8647
2199.46	15.6563
2203.1	18.6549
2206.74	19.8645
2210.38	26.5956
2214.01	15.0622
2217.65	21.8436
2221.28	21.3039
2224.91	24.4524
2228.54	17.4639
2232.16	24.2986
2235.79	26.5515
2239.41	15.8468
2243.04	19.9372
2246.66	7.31917
2250.28	12.3407
2253.89	15.536
2257.51	21.5596
2261.12	15.4458
2264.74	17.717
2268.35	18.1396
2271.96	22.3669
2275.57	20.9067
2279.17	14.6738
2282.78	16.7978
2286.38	16.089
2289.98	8.76021
2293.58	25.0415
2297.18	15.7976
2300.78	34.959
2304.37	8.62886
2307.97	13.5165
2311.56	16.4848
2315.15	18.4779
2318.74	31.8116
2322.33	61.1973
2325.91	31.7249
2329.5	10.8045
2333.08	13.5145
2336.66	17.1373
2340.24	7.54492
2343.82	9.24385
2347.4	18.4208
2350.97	6.94794
2354.54	19.8145
2358.12	17.6929
2361.69	30.4668
2365.26	19.9545
2368.82	10.424
2372.39	21.3437
2375.95	16.4979
2379.52	23.67
2383.08	21.6304
2386.64	21.4562
2390.19	13.966
2393.75	12.0371
2397.31	10.1664
2400.86	23.0212
2404.41	14.8966
2407.96	2.20938
2411.51	18.9351
2415.06	17.3699
2418.6	17.6843
2422.15	17.108
2425.69	-0.0142975
2429.23	9.62155
2432.77	24.8778
2436.31	16.1372
2439.84	15.7374
2443.38	20.006
2446.91	28.0329
2450.44	4.31688
2453.97	20.86
2457.5	27.9562
2461.03	11.3637
2464.55	19.2289
2468.08	26.007
2471.6	11.2336
2475.12	14.0892
2478.64	12.1998
2482.16	16.9396
2485.67	8.42125
2489.19	23.324
2492.7	18.5661
2496.21	22.159
2499.72	16.4405
2503.23	20.0314
2506.74	22.6469
2510.25	28.9405
2513.75	18.4794
2517.25	22.0311
2520.75	12.6193
2524.25	17.0036
2527.75	18.7802
2531.25	15.0574
2534.74	26.1371
2538.24	22.4962
2541.73	28.1272
2545.22	15.3925
2548.71	28.5815
2552.2	22.3889
2555.68	11.6081
2559.17	18.4919
2562.65	21.6871
2566.13	20.3233
2569.61	23.6715
2573.09	13.0621
2576.57	29.6121
2580.04	24.6689
2583.51	20.6491
2586.99	1.46684
2590.46	19.1253
2593.93	5.40309
2597.4	7.78976
2600.86	37.9359
2604.33	18.422
2607.79	17.9056
2611.25	22.0373
2614.71	18.3676
2618.17	31.094
2621.63	11.0787
2625.09	18.893
2628.54	23.7749
2631.99	18.0612
2635.45	19.027
2638.9	17.0632
2642.34	29.4329
2645.79	24.5247
2649.24	34.8933
2652.68	23.2641
2656.12	14.4839
2659.56	28.4847
2663.01	20.6219
2666.44	14.6683
2669.88	17.2222
2673.32	26.3371
2676.75	11.9857
2680.18	23.9359
2683.61	19.0592
2687.04	17.994
2690.47	26.367
2693.9	15.2262
2697.32	31.9962
2700.75	18.0782
2704.17	12.5513
2707.59	11.6855
2711.01	15.5876
2714.43	19.5286
2717.84	16.0594
2721.26	26.5981
2724.67	18.5207
2728.08	18.8463
2731.49	22.9225
2734.9	23.253
2738.31	20.7726
2741.71	9.8344
2745.12	12.927
2748.52	26.337
2751.92	21.9017
2755.32	18.3857
2758.72	21.4363
2762.12	4.71173
2765.52	24.6784
2768.91	23.8933
2772.3	19.3093
2775.7	9.99995
2779.09	23.2725
2782.47	27.0957
2785.86	14.9043
2789.25	16.8277
2792.63	20.6224
2796.01	23.468
2799.4	15.9832
2802.78	19.7385
2806.15	15.054
2809.53	14.1193
2812.91	9.43384
2816.28	22.5105
2819.65	17.8133
2823.03	9.41733
2826.4	15.046
2829.76	26.2738
2833.13	23.5378
2836.5	9.65709
2839.86	6.05476
2843.22	14.594
2846.59	19.449
2849.95	25.3031
2853.3	22.8053
2856.66	15.6106
2860.02	23.3888
2863.37	9.6694
2866.72	9.04805
2870.08	14.0565
2873.43	32.2173
2876.77	15.6139
2880.12	15.9167
2883.47	18.0985
2886.81	18.384
2890.15	22.442
2893.5	25.5516
2896.84	21.0601
2900.17	15.5936
2903.51	10.0974
2906.85	18.7722
2910.18	-0.00787354
2913.52	25.675
2916.85	25.7958
2920.18	26.8366
2923.51	17.4644
2926.83	11.8646
2930.16	18.5305
2933.48	35.5566
2936.81	22.3377
2940.13	14.7963
2943.45	11.9777
2946.77	18.5824
2950.09	30.8267
2953.4	18.6067
2956.72	18.6214
2960.03	24.296
2963.34	24.3497
2966.65	23.476
2969.96	18.9021
2973.27	24.6749
2976.58	12.6327
2979.88	26.8841
2983.19	29.86
2986.49	13.1353
2989.79	22.702
2993.09	16.3125
2996.39	17.4441
2999.68	19.5249
3002.98	19.7243
3006.27	19.9244
3009.57	30.4912
3012.86	28.835
3016.15	31.892
3019.43	17.0338
3022.72	32.3432
3026.01	28.7928
3029.29	17.6862
3032.57	23.5713
3035.86	24.7274
3039.14	16.4223
3042.41	12.8415
3045.69	29.1391
3048.97	16.0943
3052.24	13.4593
3055.52	12.7218
3058.79	28.1007
3062.06	28.2568
3065.33	20.8473
3068.6	24.8026
3071.86	24.9263
3075.13	34.388
3078.39	10.8307
3081.65	13.7724
3084.91	23.4874
3088.17	24.6629
3091.43	23.0351
3094.69	32.8245
3097.95	14.8337
3101.2	24.5166
3104.45	25.614
3107.7	17.2742
3110.95	24.1334
3114.2	33.7996
3117.45	23.489
3120.7	19.8449
3123.94	32.3921
3127.18	36.367
3130.43	20.3274
3133.67	28.1109
3136.91	22.5472
3140.14	36.9925
3143.38	33.324
3146.61	22.9816
3149.85	11.6935
3153.08	25.2026
3156.31	17.7231
3159.54	27.4185
3162.77	31.3861
3166	24.8577
3169.22	11.633
3172.45	32.7521
3175.67	34.7773
3178.89	40.6038
3182.11	29.256
3185.33	38.8978
3188.55	37.0734
3191.77	36.1986
3194.98	35.324
3198.2	30.6369
3201.41	41.186
3204.62	33.648
3207.83	36.5895
3211.04	35.7315
3214.25	33.9342
3217.45	35.003
3220.66	40.8284
3223.86	30.4886
3227.06	38.2394
3230.26	33.6276
3233.46	46.1545
3236.66	48.2051
3239.85	46.489
3243.05	29.5457
3246.24	29.7451
3249.44	36.6168
3252.63	36.8367
3255.82	37.0614
3259.01	43.0102
3262.19	47.9841
3265.38	32.8765
3268.56	24.4272
3271.75	46.5304
3274.93	46.6516
3278.11	62.0526
3281.29	40.1672
3284.47	41.1737
3287.64	44.0912
3290.82	48.8982
3293.99	47.9971
3297.17	51.8531
3300.34	48.0915
3303.51	61.5088
3306.68	45.3705
3309.84	47.3004
3313.01	41.5987
3316.18	39.6935
3319.34	39.685
3322.5	58.627
3325.66	56.7043
3328.82	45.3244
3331.98	56.6584
3335.14	45.315
3338.29	58.5493
3341.45	69.8937
3344.6	63.3139
3347.75	59.6164
3350.9	50.3108
3354.05	54.2001
3357.2	46.7996
3360.35	61.0883
3363.49	54.6619
3366.64	60.4966
3369.78	66.3445
3372.92	70.3174
3376.06	54.4924
3379.2	66.0507
3382.34	66.2902
3385.48	64.6303
3388.61	70.5528
3391.75	67.9662
3394.88	76.7315
3398.01	81.6634
3401.14	63.0152
3404.27	75.6665
3407.4	110.21
3410.52	114.409
3413.65	162.4
3416.77	261.859
3419.89	533.069
3423.01	1071.74
3426.13	1178.36
3429.25	680.464
3432.37	306.395
3435.49	181.422
3438.6	116.562
3441.72	101.389
3444.83	89.0783
3447.94	75.7787
3451.05	68.2051
3454.16	67.2808
3457.26	64.4485
3460.37	66.3513
3463.47	71.0998
3466.58	68.2314
3469.68	69.1357
3472.78	75.6922
3475.88	68.091
3478.98	72.8155
3482.07	73.7596
3485.17	77.5429
3488.26	100.223
3491.36	108.753
3494.45	127.722
3497.54	153.276
3500.63	187.286
3503.72	241.083
3506.81	271.22
3509.89	240.097
3512.98	194.782
3516.06	163.701
3519.14	121.572
3522.22	103.995
3525.3	84.6584
3528.38	65.1717
3531.45	66.3431
3534.53	54.2549
3537.61	58.1319
3540.68	58.2494
3543.75	38.6189
3546.82	52.9447
3549.89	43.7842
3552.96	47.8062
3556.03	36.6845
3559.09	23.6847
3562.16	40.0264
3565.22	33.6146
3568.28	43.2853
3571.34	31.2077
3574.4	27.5842
3577.46	33.4513
3580.52	26.9768
3583.57	29.9754
3586.63	24.4244
3589.68	25.5122
3592.73	19.9452
3595.78	25.7516
3598.83	28.6993
3601.88	30.6982
3604.93	32.6798
3607.97	28.0255
3611.02	27.1579
3614.06	23.4489
3617.1	24.4618
3620.14	18.8733
3623.18	12.3547
3626.22	20.9331
3629.26	20.0882
3632.3	12.6433
3635.33	30.6176
3638.36	20.3806
3641.4	20.5176
3644.43	27.2565
3647.46	17.0953
3650.49	17.2466
3653.51	22.1219
3656.54	17.4192
3659.57	0.781601
3662.59	2.93261
3665.61	18.2565
3668.63	16.5694
3671.65	22.4552
3674.67	16.0898
3677.69	21.9964
3680.71	19.4171
3683.72	1.7055
3686.74	6.67088
3689.75	5.96883
3692.76	14.7383
3695.77	20.6782
3698.78	-0.892494
3701.79	15.4814
3704.79	10.0443
3707.8	16.9476
3710.81	2.93406
3713.81	6.96474
3716.81	12.8868
3719.81	1.6925
3722.81	18.0826
3725.81	6.85812
3728.81	11.808
3731.8	9.13181
3734.8	9.3009
3737.79	10.4091
3740.78	1.03581
3743.77	13.5407
3746.76	12.7099
3749.75	14.7201
3752.74	2.46923
3755.73	5.42302
3758.71	18.8132
3761.7	0.893486
3764.68	6.67705
3767.66	2.04074
3770.64	9.72072
3773.62	7.94617
3776.6	3.34668
3779.58	7.26242
3782.55	-0.151901
3785.53	9.43807
3788.5	14.3094
3791.47	0.30925
3794.44	3.31886
3797.41	5.39402
3800.38	12.1966
3803.35	6.74312
3806.32	9.79321
3809.28	10.9593
3812.24	1.73701
3815.21	7.63892
3818.17	14.4949
3821.13	8.11256
3824.09	-0.166634
3827.04	10.5015
3830	-2.51633
3832.96	2.47243
3835.91	6.52872
3838.86	11.5464
3841.82	14.6704
3844.77	3.52901
3847.72	2.84539
3850.67	8.83443
3853.61	4.35075
3856.56	12.2684
3859.5	9.69392
3862.45	3.29153
3865.39	1.65612
3868.33	0.975433
3871.27	6.03537
3874.21	0.54969
3877.15	6.56858
3880.09	18.3442
3883.02	9.94422
3885.96	14.9787
3888.89	14.2398
3891.82	3.88103
3894.75	6.97643
3897.68	11.9822
3900.61	13.1288
3903.54	14.2721
3906.47	11.5559
3909.39	5.0093
3912.31	12.8702
3915.24	13.9916
3918.16	10.3034
3921.08	9.5174
3924	10.6303
3926.92	11.7301
3929.83	11.8599
3932.75	11.9851
3935.67	15.0102
3938.58	14.2268
3941.49	7.71857
3944.4	13.6484
3947.31	-0.521759
3950.22	4.46704
3953.13	11.3793
3956.04	2.97468
3958.94	5.11328
3961.85	8.21614
3964.75	6.533
3967.65	0.0595627
3970.55	5.0985
3973.45	6.3054
3976.35	7.51101
3979.25	11.593
3982.15	12.7877
3985.04	9.17424
3987.94	10.3617
3990.83	8.66059
3993.72	10.7945
3996.61	10.0621
3999.5	4.51485
4002.39	6.67166
4005.28	3.05255
4008.16	8.10726
4011.05	2.56399
4013.93	16.3008
4016.81	13.6497
4019.7	11.9613
4022.58	6.40891
4025.46	11.4769
4028.33	12.686
4031.21	11.9632
4034.09	0.603821
4036.96	14.3919
4039.84	9.80452
4042.71	4.24076
4045.58	12.2202
4048.45	9.54884
4051.32	10.759
4054.19	7.12515
4057.05	12.2324
4059.92	10.5428
4062.78	10.7907
4065.65	1.31795
4068.51	3.50594
4071.37	8.61345
4074.23	14.6985
4077.09	7.15131
4079.95	13.2373
4082.81	9.58002
4085.66	4.94481
4088.52	10.0566
4091.37	1.50822
4094.22	17.3696
4097.07	-0.953041
4099.92	12.9632
4102.77	6.35761
4105.62	11.4796
4108.47	18.5492
4111.31	12.9026
4114.16	7.24166
4117	11.3573
4119.84	13.5012
4122.69	10.7532
4125.53	12.9098
4128.36	8.21788
4131.2	11.3812
4134.04	10.6429
4136.88	6.99155
4139.71	7.14335
4142.54	16.9997
4145.38	5.44403
4148.21	12.5171
4151.04	14.707
4153.87	18.8338
4156.69	7.25714
4159.52	11.308
4162.35	1.69318
4165.17	17.5252
4168	13.7905
4170.82	12.0167
4173.64	19.0496
4176.46	10.4376
4179.28	13.5605
4182.1	8.86707
4184.91	15.9129
4187.73	11.2263
4190.54	7.51834
4193.36	16.5466
4196.17	3.06789
4198.98	10.1642
4201.79	14.3234
4204.6	12.6047
4207.41	14.8059
4210.22	6.20648
4213.02	17.2488
4215.83	15.5187
4218.63	13.8411
4221.44	9.19638
4224.24	9.46558
4227.04	7.74782
4229.84	13.9482
4232.64	5.32191
4235.43	10.5548
4238.23	14.8131
4241.02	6.17166
4243.82	10.4376
4246.61	9.73987
4249.4	18.0087
4252.19	15.3058
4254.98	11.5929
4257.77	12.8657
4260.56	6.12444
4263.35	7.39481
4266.13	16.7036
4268.92	9.95359
4271.7	12.2444
4274.48	17.5607
4277.26	10.7618
4280.04	13.0249
4282.82	9.22108
4285.6	19.5595
4288.38	11.6849
4291.15	10.878
4293.93	5.00249
4296.7	14.33
4299.47	17.5915
4302.25	20.8471
4305.02	9.89533
4307.79	9.08547
4310.55	15.3897
4313.32	7.47619
4316.09	10.7279
4318.85	13.9737
4321.62	8.05404
4324.38	13.3228
4327.14	17.5704
4329.9	19.785
4332.66	14.8587
4335.42	12.9919
4338.18	18.2475
4340.94	17.4065
4343.69	13.506
4346.45	8.59119
4349.2	7.75993
4351.95	11.0105
4354.7	11.2219
4357.45	11.423
4360.2	12.6462
4362.95	9.77099
4365.7	9.97161
4368.44	11.189
4371.19	7.28807
4373.93	9.52306
4376.68	7.6516
4379.42	10.9051
4382.16	9.02192
4384.9	12.28
4387.64	4.2467
4390.37	3.43386
4393.11	21.1829
4395.85	9.10691
4398.58	12.4434
4401.31	14.7478
4404.05	21.1939
4406.78	3.78973
4409.51	12.3217
4412.24	2.13956
4414.96	8.58353
4417.69	15.0349
4420.42	4.77797
4423.14	19.5616
4425.87	13.4889
4428.59	15.7655
4431.31	13.8617
4434.03	15.0914
4436.75	18.412
4439.47	18.5882
4442.19	8.27193
4444.91	11.581
4447.62	4.39349
4450.34	11.8967
4453.05	15.1972
4455.76	7.99094
4458.47	14.435
4461.19	19.8268
4463.89	14.7157
4466.6	10.6498
4469.31	15.0042
4472.02	14.1003
4474.72	8.98746
4477.43	9.14521
4480.13	5.08816
4482.83	10.5301
4485.53	7.5265
4488.23	8.74078
4490.93	13.1267
4493.63	11.1464
4496.33	9.15173
4499.02	11.4052
4501.72	13.6551
4504.41	11.6599
4507.11	10.7302
4509.8	14.044
4512.49	-2.80176
4515.18	6.87873
4517.87	11.2586
4520.56	6.08115
4523.24	3.03081
4525.93	10.6155
4528.61	1.17286
4531.3	18.3528
4533.98	5.70725
4536.66	10.1143
4539.34	9.19157
4542.02	7.20268
4544.7	12.6936
4547.38	14.9848
4550.05	11.9246
4552.73	5.6493
4555.4	7.95771
4558.08	7.05746
4560.75	6.17414
4563.42	8.53331
4566.09	13.0836
4568.76	10.0923
4571.43	10.298
4574.1	7.16757
4576.77	11.6051
4579.43	5.21719
4582.1	6.45844
4584.76	12.0699
4587.42	8.93199
4590.08	11.2372
4592.74	9.17268
4595.4	18.0277
4598.06	2.86686
4600.72	10.6367
4603.38	0.924328
4606.03	3.24532
4608.69	7.76286
4611.34	13.3864
4613.99	9.1335
4616.64	9.26823
4619.29	10.5064
4621.94	16.1553
4624.59	1.97056
4627.24	10.9227
4629.89	2.21988
4632.53	1.23544
4635.18	6.87475
4637.82	9.19691
4640.46	5.98532
4643.1	3.87856
4645.74	5.10903
4648.38	7.4679
4651.02	6.51497
4653.66	6.69632
4656.3	0.161606
4658.93	0.242626
4661.57	11.5243
4664.2	0.500832
4666.83	2.86286
4669.46	10.8087
4672.09	6.45522
4674.72	7.69652
4677.35	13.425
4679.98	9.05957
4682.61	14.7944
4685.23	1.42999
4687.86	0.419029
4690.48	10.6642
4693.1	5.1547
4695.73	9.77744
4698.34	9.89347
4700.96	11.1403
4703.58	6.73893
4706.2	10.238
4708.82	8.08524
4711.43	7.05952
4714.05	13.9554
4716.66	7.26665
4719.28	0.569908
4721.89	13.1309
4724.5	3.0266
4727.11	11.0683
4729.72	-0.166039
4732.33	5.6172
4734.93	12.5432
4737.54	1.29266
4740.14	5.9446
4742.75	3.77536
4745.35	14.114
4747.95	1.69717
4750.55	10.8898
4753.15	5.29265
4755.75	7.66127
4758.35	0.925045
4760.95	7.85517
4763.54	11.3778
4766.14	8.07304
4768.73	0.222149
4771.33	0.351013
4773.92	9.5973
4776.51	5.1567
4779.1	8.70772
4781.69	-0.304794
4784.28	6.67846
4786.87	5.66572
4789.45	9.23007
4792.04	5.93427
4794.63	0.348774
4797.21	-2.94753
4799.79	4.07914
4802.37	6.53128
4804.95	10.1427
4807.53	5.72333
4810.11	2.45217
4812.69	4.93556
4815.27	2.81636
4817.84	7.62593
4820.42	7.82961
4822.99	6.87801
4825.57	7.08619
4828.14	0.333492
4830.71	5.18533
4833.28	10.058
4835.85	3.29828
4838.42	2.36207
4840.98	4.93632
4843.55	1.66566
4846.12	7.75623
4848.68	2.12148
4851.24	-0.0154533
4853.81	1.33942
4856.37	7.4115
4858.93	2.95656
4861.49	10.2809
4864.05	2.2612
4866.61	11.9344
4869.16	5.0747
4871.72	2.95256
4874.27	2.00174
4876.83	2.23263
4879.38	6.02666
4881.93	11.0133
4884.49	7.69001
4887.04	12.6869
4889.58	8.17971
4892.13	10.812
4894.68	7.49474
4897.23	5.3675
4899.77	10.393
4902.32	13.0411
4904.86	1.37649
4907.4	4.02828
4909.95	10.2677
4912.49	2.16946
4915.03	9.59896
4917.57	8.66688
4920.1	11.3298
4922.64	12.8032
4925.18	7.11341
4927.71	16.9674
4930.25	-0.668404
4932.78	17.5736
4935.31	13.1204
4937.84	5.07173
4940.38	14.9785
4942.9	10.5033
4945.43	12.0401
4947.96	7.60277
4950.49	11.5549
4953.01	5.92807
4955.54	7.49372
4958.06	12.6772
4960.59	16.6764
4963.11	12.2783
4965.63	9.09631
4968.15	11.9464
4970.67	8.76368
4973.19	10.4073
4975.71	12.0589
4978.22	23.3916
4980.74	21.4415
4983.25	17.0724
4985.77	10.2791
4988.28	16.8305
4990.79	19.7583
4993.3	16.6164
4995.81	11.04
4998.32	18.8702