File: Data/3-Raman/processed/bu19w-e-ff11b-fi10-l_150 (500nm)_532nm_edge_100%_x100_vis_h50um_30sx2_01_0.txt
#Acq. time (s)=	30
#Accumulations=	2
#Range (cm-¹)=	100...5000
#Windows=	1
#Auto scanning=	Off
#Autofocus=	Off
#Macrospot=	Off
#AutoExposure=	Off
#Spike filter=	Multiple accum.
#Delay time (s)=	2
#Binning=	1
#Readout mode=	Signal
#DeNoise=	Off
#ICS correction=	On
#Dark correction=	Off
#Inst. Process=	Off
#Detector Gain=	Best Dynamic
#Detector ADC=	50 kHz HS
#Detector temperature (°C)=	-60.28
#Instrument=	LabRAM HR Evol
#Detector=	SIN-EM FIVIS
#Objective=	x100_VIS
#Grating=	150 (500nm)
#ND Filter=	100%
#Laser=	532nm_Edge
#Hole=	49.98
#Temperature=	0
#Range=	Visible
#StageXY=	75x50mm Scan+
#StageZ=	Z motor
#X (µm)=	0
#Y (µm)=	0
#Z (µm)=	-270.7
#Full time(mm:ss)=	1:05
#Project=	21_11_04
#Sample=	BU19w
#Site=
#Title=	BU19w-E-FF11b-FI10-L_150 (500nm)_532nm_Edge_100%_x100_VIS_H50um_30sX2
#Remark=
#Date=	04.11.2021 17:18
#Acquired=	04.11.2021 17:18:52
#Base:Fit=	16.12.2021 17:39:50
#Base:Sub=	16.12.2021 17:48:26
101.869	2921.41
106.493	5898.58
111.113	9709.09
115.732	8460.05
120.349	4477.33
124.964	2882.52
129.577	2563.55
134.185	2335.58
138.793	2058.2
143.399	2018.23
148.003	2093.97
152.602	2245.92
157.201	2563.89
161.798	3071.98
166.392	3887.32
170.982	5127.14
175.572	7331.28
180.16	10357.8
184.745	13434.9
189.326	15245.2
193.907	14310
198.486	11430.1
203.06	8234.37
207.634	5870.2
212.206	4323.63
216.776	3248.31
221.341	2475.33
225.906	2041.07
230.469	1730.01
235.028	1568.14
239.586	1629.84
244.142	2292.62
248.694	2784.82
253.246	1919.14
257.795	904.35
262.341	498.18
266.886	371.047
271.428	277.031
275.967	206.397
280.505	117.989
285.041	117.376
289.573	66.5222
294.105	79.2759
298.632	19.3337
303.159	53.1088
307.685	35.6534
312.205	0.0159912
316.726	7.90442
321.242	2.31366
325.758	37.8163
330.272	282.29
334.782	1229.83
339.292	2081.11
343.797	1350.91
348.302	468.027
352.803	196.942
357.304	108.852
361.802	86.3721
366.297	93.9866
370.791	180.22
375.281	416.755
379.77	722.349
384.256	878.902
388.741	831.378
393.223	436.981
397.704	255.805
402.18	180.599
406.657	276.291
411.13	368.772
415.602	464.594
420.07	704.77
424.538	1086.94
429.002	1959.64
433.465	3859.71
437.925	8338.05
442.384	20651.4
446.839	37432.3
451.294	37450.1
455.745	24974.6
460.196	11622.7
464.642	6120.42
469.089	3931.89
473.531	2754.05
477.971	2012.94
482.411	1597.6
486.846	1332.8
491.282	1229.8
495.713	1146.08
500.144	954.599
504.572	807.601
508.997	732.986
513.421	601.747
517.842	509.945
522.263	423.151
526.679	359.823
531.093	339.446
535.507	267.219
539.917	232.019
544.327	200.234
548.733	162.653
553.137	145.86
557.54	147.238
561.94	138.881
566.337	122.794
570.734	146.351
575.127	135.671
579.518	123.831
583.909	157.645
588.295	116.878
592.68	65.6891
597.064	88.6531
601.445	61.673
605.823	57.8506
610.201	54.4421
614.575	17.8516
618.947	39.0112
623.317	35.8782
627.686	30.5106
632.052	3.98499
636.415	29.6711
640.777	11.0778
645.138	6.06061
649.495	-1.46289
653.85	-0.100159
658.205	-0.995605
662.556	59.8362
666.905	38.5465
671.252	148.461
675.597	210.171
679.941	417.615
684.282	380.483
688.62	241.885
692.957	106.144
697.293	56.4894
701.625	36.1826
705.955	27.2377
710.283	7.07086
714.609	13.6116
718.933	17.4804
723.257	9.66263
727.577	16.5976
731.894	12.9042
736.21	24.5109
740.524	49.8609
744.835	32.5043
749.147	35.8555
753.454	62.3029
757.759	92.7479
762.063	80.4677
766.364	127.026
770.663	241.473
774.96	375.194
779.257	557.756
783.55	777.378
787.841	1030.36
792.13	1314.23
796.417	1061.74
800.702	565.343
804.985	312.563
809.266	220.767
813.545	174.152
817.821	166.128
822.096	159.161
826.371	151.253
830.641	161
834.91	123.365
839.176	140.767
843.441	159.215
847.703	125.604
851.964	124.722
856.222	162.413
860.479	222.078
864.733	209.988
868.986	147.104
873.236	162.226
877.485	101.469
881.731	129.481
885.975	118.918
890.218	107.027
894.458	90.5815
898.696	117.256
902.933	122.402
907.167	134.451
911.399	121.888
915.63	99.9802
919.858	59.6465
924.084	68.8966
928.308	46.5605
932.531	73.1901
936.749	73.9662
940.967	58.5289
945.184	31.3146
949.398	54.3191
953.61	42.1852
957.821	12.0201
962.029	25.5577
966.236	30.5971
970.44	40.961
974.642	17.4514
978.843	3.53439
983.041	34.1719
987.236	-1.93121
991.43	-2.03333
995.623	0.204773
999.813	5.8302
1004	9.39752
1008.19	11.935
1012.37	18.7353
1016.55	10.5146
1020.73	17.1756
1024.91	42.9768
1029.09	44.0787
1033.27	58.9574
1037.44	68.0835
1041.61	127.003
1045.78	209.147
1049.94	328.01
1054.11	398.544
1058.27	418.826
1062.43	619.186
1066.59	839.157
1070.75	671.761
1074.9	362.056
1079.05	190.813
1083.2	111.906
1087.35	108.079
1091.5	76.5024
1095.65	66.8297
1099.79	77.8644
1103.93	72.4959
1108.07	56.0217
1112.21	54.0734
1116.34	41.955
1120.48	45.5746
1124.61	73.0059
1128.74	109.807
1132.86	127.4
1136.99	244.398
1141.11	447.957
1145.23	632.786
1149.35	668.534
1153.47	378.896
1157.59	185.547
1161.7	104.448
1165.82	66.5353
1169.92	56.3969
1174.03	43.0457
1178.14	53.3306
1182.24	64.5961
1186.35	55.1821
1190.45	57.9017
1194.55	46.1678
1198.64	57.8667
1202.74	87.7399
1206.83	110.295
1210.92	150.957
1215.01	207.571
1219.1	188.344
1223.18	156.205
1227.27	132.305
1231.35	71.6022
1235.43	93.2699
1239.5	68.1631
1243.58	71.9487
1247.65	59.8499
1251.72	83.8541
1255.8	94.9472
1259.86	94.0986
1263.93	79.2785
1267.99	66.4798
1272.06	63.7122
1276.12	59.9192
1280.18	53.0754
1284.23	44.1481
1288.29	37.1451
1292.34	37.1369
1296.39	33.0379
1300.44	28.898
1304.49	33.7626
1308.53	12.3824
1312.58	46.4056
1316.62	21.8615
1320.66	19.4225
1324.7	31.9877
1328.73	37.423
1332.77	33.7884
1336.8	46.0991
1340.83	34.2948
1344.86	53.4552
1348.88	59.5652
1352.91	67.6394
1356.93	81.6467
1360.95	135.236
1364.97	219.362
1368.99	244.974
1373.01	188.669
1377.02	117.773
1381.03	69.7233
1385.04	51.3933
1389.05	42.9748
1393.06	35.5944
1397.06	34.2145
1401.06	33.8023
1405.06	41.2423
1409.06	38.847
1413.06	36.4626
1417.05	42.9513
1421.05	48.4444
1425.04	33.1621
1429.03	22.6869
1433.01	28.0018
1437	35.2906
1440.99	41.576
1444.97	36.9633
1448.95	44.163
1452.93	29.6112
1456.9	33.7668
1460.88	48.7073
1464.85	14.3237
1468.82	32.0878
1472.79	42.9642
1476.76	38.0883
1480.73	40.0388
1484.69	48.8105
1488.65	53.6239
1492.61	34.0329
1496.57	35.9385
1500.53	42.7221
1504.48	32.02
1508.43	37.916
1512.39	52.5638
1516.33	38.0755
1520.28	47.88
1524.23	43.1388
1528.17	46.1697
1532.11	50.1927
1536.05	40.648
1539.99	60.1796
1543.93	73.8885
1547.86	62.3979
1551.8	62.5294
1555.73	66.5005
1559.66	73.3261
1563.58	83.9791
1567.51	82.981
1571.44	73.259
1575.36	88.6487
1579.28	76.9797
1583.2	103.887
1587.11	106.637
1591.03	120.92
1594.94	109.199
1598.85	105.182
1602.76	116.553
1606.67	132.749
1610.58	115.371
1614.48	153.616
1618.38	138.221
1622.29	138.143
1626.18	139.062
1630.08	133.327
1633.98	131.517
1637.87	123.001
1641.76	119.335
1645.65	120.528
1649.54	125.587
1653.43	111.478
1657.31	92.5229
1661.2	94.6612
1665.08	82.3309
1668.96	68.0312
1672.83	81.5261
1676.71	61.3465
1680.58	65.0701
1684.46	71.5853
1688.33	66.5544
1692.2	47.1121
1696.06	38.1999
1699.93	32.137
1703.79	34.6249
1707.66	19.9193
1711.52	34.668
1715.37	25.6549
1719.23	33.7131
1723.08	33.2477
1726.94	27.1128
1730.79	22.8464
1734.64	28.9258
1738.49	16.243
1742.33	23.1912
1746.18	19.871
1750.02	11.1095
1753.86	17.3109
1757.7	19.9054
1761.54	19.1301
1765.37	23.8204
1769.21	-3.01773
1773.04	18.5516
1776.87	10.3964
1780.7	-1.44351
1784.53	7.25465
1788.35	1.04356
1792.17	21.0459
1796	9.22316
1799.82	9.56834
1803.64	-3.38196
1807.45	17.5166
1811.27	-0.215881
1815.08	4.62688
1818.89	11.2762
1822.7	14.0934
1826.51	8.3793
1830.32	19.5862
1834.12	5.28085
1837.92	1.31831
1841.72	-0.78685
1845.52	15.8515
1849.32	-2.24113
1853.12	5.86105
1856.91	3.59253
1860.7	7.80046
1864.5	17.5458
1868.28	-2.44791
1872.07	4.53859
1875.86	18.9367
1879.64	8.37526
1883.42	17.2889
1887.21	7.78389
1890.98	8.63628
1894.76	-1.52344
1898.54	12.2392
1902.31	9.52396
1906.08	8.69554
1909.85	8.81
1913.62	4.38771
1917.39	11.9769
1921.16	19.7121
1924.92	16.3944
1928.68	9.38838
1932.44	16.3234
1936.2	10.2404
1939.96	4.12593
1943.71	18.5598
1947.47	6.81863
1951.22	22.084
1954.97	26.0227
1958.72	17.6401
1962.46	12.9328
1966.21	4.45813
1969.95	18.4609
1973.7	14.54
1977.43	29.3221
1981.17	10.3437
1984.91	12.8727
1988.65	23.7651
1992.38	31.7972
1996.11	19.2986
1999.84	17.9435
2003.57	23.0792
2007.3	19.8652
2011.02	17.5293
2014.75	30.8443
2018.47	13.9129
2022.19	26.4933
2025.91	14.4458
2029.62	29.9125
2033.34	20.7336
2037.05	28.1398
2040.76	7.13745
2044.47	23.6621
2048.18	13.6333
2051.89	29.2892
2055.59	27.5658
2059.3	15.8587
2063	24.468
2066.7	7.41495
2070.4	12.4322
2074.1	24.8549
2077.79	27.1676
2081.49	18.391
2085.18	19.767
2088.87	32.9885
2092.56	20.0647
2096.25	16.5346
2099.93	20.4195
2103.61	32.5966
2107.3	32.6448
2110.98	29.8674
2114.66	25.2231
2118.33	25.2048
2122.01	34.3893
2125.68	37.9339
2129.36	34.0252
2133.03	17.1427
2136.7	32.6437
2140.36	30.5283
2144.03	16.4039
2147.7	34.5092
2151.36	31.4272
2155.02	26.5308
2158.68	24.4068
2162.34	36.0248
2165.99	16.6163
2169.65	25.5557
2173.3	22.7236
2176.95	16.3127
2180.6	17.2152
2184.25	21.7534
2187.9	13.6036
2191.54	21.0052
2195.18	18.4885
2198.83	20.5786
2202.47	17.2253
2206.11	5.68269
2209.74	6.94476
2213.38	13.7328
2217.01	21.4713
2220.64	12.7102
2224.27	21.4071
2227.9	8.9341
2231.53	13.952
2235.16	28.2457
2238.78	8.33708
2242.4	0.409393
2246.02	14.7323
2249.64	1.21069
2253.26	-3.01886
2256.88	5.8192
2260.49	7.20782
2264.11	15.1324
2267.72	10.9057
2271.33	10.4698
2274.93	2.45461
2278.54	-1.87541
2282.15	-2.55807
2285.75	0.513214
2289.35	6.43105
2292.95	15.1648
2296.55	6.87939
2300.15	14.6902
2303.74	12.0567
2307.34	8.42842
2310.93	20.8828
2314.52	13.4013
2318.11	18.2063
2321.7	27.6987
2325.28	8.65736
2328.87	17.0379
2332.45	5.55
2336.03	12.9221
2339.61	23.0712
2343.19	0.264236
2346.77	31.9364
2350.34	0.719772
2353.92	20.0957
2357.49	14.1902
2361.06	1.77487
2364.63	27.5124
2368.2	26.2599
2371.76	18.5798
2375.33	3.52242
2378.89	12.5113
2382.45	6.75409
2386.01	28.6343
2389.57	12.8195
2393.13	5.34433
2396.68	23.6149
2400.23	12.607
2403.79	27.3732
2407.34	6.4319
2410.88	7.5601
2414.43	3.23701
2417.98	0.78717
2421.52	6.6443
2425.06	14.4041
2428.61	13.9332
2432.14	8.87701
2435.68	13.1106
2439.22	8.09546
2442.75	17.0381
2446.29	7.36096
2449.82	-2.32869
2453.35	4.85306
2456.88	4.43303
2460.4	8.54778
2463.93	2.26776
2467.45	23.1846
2470.98	7.44199
2474.5	2.74486
2478.02	-6.73923
2481.54	10.2184
2485.05	21.4338
2488.57	3.3418
2492.08	20.1357
2495.59	9.59575
2499.1	6.62279
2502.61	18.5798
2506.12	0.568848
2509.63	2.15814
2513.13	19.5656
2516.63	7.23486
2520.13	-6.87875
2523.63	2.99727
2527.13	9.33224
2530.63	14.7836
2534.12	13.7897
2537.62	-0.983917
2541.11	-4.63831
2544.6	3.79057
2548.09	14.1644
2551.58	9.77171
2555.06	12.8186
2558.55	-1.6257
2562.03	4.2971
2565.51	16.8362
2568.99	7.12131
2572.47	3.0161
2575.95	12.0439
2579.43	11.7623
2582.9	3.94676
2586.37	-0.134171
2589.84	2.35521
2593.31	5.70389
2596.78	11.8812
2600.25	10.5082
2603.71	19.6469
2607.18	-4.85968
2610.64	14.5721
2614.1	7.93672
2617.56	9.07011
2621.02	9.15471
2624.47	13.045
2627.93	14.9551
2631.38	11.0687
2634.83	3.2999
2638.28	10.8218
2641.73	-1.81624
2645.18	4.66045
2648.62	13.9717
2652.07	3.18936
2655.51	16.1788
2658.95	3.43796
2662.39	6.83331
2665.83	12.0808
2669.27	12.586
2672.7	20.5955
2676.14	14.5258
2679.57	-3.66261
2683	21.2505
2686.43	6.95314
2689.86	15.1895
2693.29	2.99939
2696.71	12.1902
2700.13	22.3456
2703.56	-8.42706
2706.98	-0.129425
2710.4	4.58482
2713.82	-2.75533
2717.23	-2.6199
2720.65	12.462
2724.06	13.6046
2727.47	17.5655
2730.88	4.71826
2734.29	16.1658
2737.7	-0.475754
2741.11	-0.275299
2744.51	-4.80719
2747.91	13.1739
2751.32	1.09352
2754.72	15.327
2758.11	12.6022
2761.51	10.8256
2764.91	8.04851
2768.3	6.18224
2771.7	0.510406
2775.09	20.2637
2778.48	7.00322
2781.87	7.84616
2785.25	12.4357
2788.64	9.48724
2792.03	15.9344
2795.41	13.9084
2798.79	4.37781
2802.17	11.7101
2805.55	8.72098
2808.93	12.2877
2812.3	16.7714
2815.68	19.3646
2819.05	20.0757
2822.42	17.0826
2825.79	15.0547
2829.16	22.3649
2832.53	10.1252
2835.89	21.219
2839.26	11.8502
2842.62	26.7403
2845.98	33.2983
2849.34	26.8825
2852.7	17.7151
2856.06	32.7911
2859.41	17.9965
2862.77	20.0487
2866.12	8.05328
2869.47	32.6284
2872.82	33.7576
2876.17	34.8808
2879.52	29.4095
2882.87	28.6308
2886.21	28.775
2889.55	35.5186
2892.89	38.4867
2896.23	25.3296
2899.57	43.3379
2902.91	33.8867
2906.25	34.8097
2909.58	42.337
2912.91	47.0062
2916.25	45.0371
2919.58	50.5987
2922.91	56.1427
2926.23	54.0994
2929.56	55.7988
2932.88	57.4699
2936.21	53.435
2939.53	57.8909
2942.85	51.0337
2946.17	67.7281
2949.49	68.4141
2952.8	57.808
2956.12	57.5541
2959.43	60.1564
2962.74	67.4728
2966.06	61.6609
2969.37	77.4942
2972.67	77.4407
2975.98	88.6415
2979.28	95.2128
2982.59	94.2396
2985.89	89.5276
2989.19	92.3415
2992.49	97.0442
2995.79	114.918
2999.09	116.844
3002.38	103.722
3005.68	115.046
3008.97	109.463
3012.26	122.725
3015.55	133.182
3018.84	137.985
3022.13	138.07
3025.41	158.92
3028.7	166.577
3031.98	166.676
3035.26	163.923
3038.54	174.394
3041.82	177.308
3045.1	199.162
3048.38	195.473
3051.65	206.936
3054.92	227.903
3058.2	241.287
3061.47	237.468
3064.73	247.943
3068	246.032
3071.27	249.749
3074.54	245.424
3077.8	271.94
3081.06	281.191
3084.32	296.576
3087.58	312.891
3090.84	308.472
3094.1	338.368
3097.35	346.611
3100.61	345.729
3103.86	395.109
3107.11	402.009
3110.36	411.696
3113.61	435.453
3116.86	449.755
3120.11	451.701
3123.35	472.698
3126.59	495.599
3129.84	503.238
3133.08	515.659
3136.32	545.221
3139.55	563.31
3142.79	569.951
3146.03	583.268
3149.26	626.202
3152.49	652.004
3155.72	683.496
3158.95	693.083
3162.18	706.455
3165.41	715.07
3168.64	755.093
3171.86	799.817
3175.08	785.336
3178.31	838.51
3181.53	843.954
3184.75	860.875
3187.96	896.729
3191.18	909.653
3194.4	962.592
3197.61	944.986
3200.82	936.885
3204.03	972.631
3207.24	1032.19
3210.45	1022.32
3213.66	1034.41
3216.86	1073.23
3220.07	1106.34
3223.27	1090.96
3226.48	1109.98
3229.68	1134.72
3232.87	1123.44
3236.07	1153.9
3239.27	1168.5
3242.47	1147.97
3245.66	1175.12
3248.85	1219.44
3252.04	1234.4
3255.23	1252.27
3258.42	1255.83
3261.61	1281.15
3264.8	1257.57
3267.98	1251.91
3271.16	1275.72
3274.35	1317.58
3277.53	1318.37
3280.71	1289.24
3283.89	1308.51
3287.06	1311.6
3290.24	1330.74
3293.41	1402.43
3296.58	1377.77
3299.76	1423.58
3302.93	1434.58
3306.1	1435.61
3309.26	1458.37
3312.43	1482.72
3315.59	1466.11
3318.76	1529.17
3321.92	1514.33
3325.08	1545
3328.24	1581.3
3331.4	1579.76
3334.56	1610.47
3337.71	1619.57
3340.87	1646.74
3344.02	1691.81
3347.17	1699.59
3350.33	1722.02
3353.47	1746.28
3356.62	1745.33
3359.77	1820.82
3362.92	1832.48
3366.06	1797.98
3369.2	1839.04
3372.34	1878.31
3375.49	1925.42
3378.62	1932.06
3381.76	1969.06
3384.9	1992.74
3388.04	1992.06
3391.17	2017.89
3394.3	2038.06
3397.43	2062.22
3400.56	2075.45
3403.69	2079.41
3406.82	2079.8
3409.95	2104.09
3413.07	2154.12
3416.2	2168.4
3419.32	2186.36
3422.44	2191.74
3425.56	2152.72
3428.68	2179.12
3431.8	2135.5
3434.91	2138.2
3438.03	2121.21
3441.14	2176.1
3444.25	2158.45
3447.36	2100.22
3450.47	2126.87
3453.58	2121.67
3456.69	2094.55
3459.79	2056.65
3462.9	2069.16
3466	2034.99
3469.11	2022.41
3472.21	1985.66
3475.31	1950.65
3478.4	1935.69
3481.5	1919.91
3484.6	1855.06
3487.69	1855.61
3490.79	1817.74
3493.88	1805.03
3496.97	1794.16
3500.06	1740.69
3503.15	1687.35
3506.23	1671.39
3509.32	1643.26
3512.4	1557.12
3515.49	1557.86
3518.57	1477.32
3521.65	1479.28
3524.73	1444.93
3527.81	1379.46
3530.89	1367.88
3533.96	1356.01
3537.03	1283.87
3540.11	1233.52
3543.18	1201.86
3546.25	1179.23
3549.32	1135.97
3552.39	1109.33
3555.46	1078.73
3558.52	1048.32
3561.59	1047.27
3564.65	1001.41
3567.71	974.279
3570.77	943.74
3573.83	905.024
3576.89	874.887
3579.95	870.267
3583	837.108
3586.06	820.921
3589.11	786.722
3592.16	778.003
3595.21	742.73
3598.27	686.543
3601.31	707.124
3604.36	693.508
3607.41	639.148
3610.45	660.497
3613.5	604.278
3616.54	602.875
3619.58	563.755
3622.62	532.264
3625.66	536.659
3628.69	491.154
3631.73	464.496
3634.77	466.06
3637.8	416.977
3640.83	397.174
3643.86	380.261
3646.89	373.874
3649.92	326.844
3652.95	300.661
3655.98	282.193
3659	278.993
3662.02	239.964
3665.05	222.474
3668.07	211.347
3671.09	191.83
3674.11	180.804
3677.13	145.247
3680.14	146.507
3683.16	138.298
3686.17	122.519
3689.19	124.711
3692.2	108.925
3695.21	90.2864
3698.22	87.676
3701.23	85.1305
3704.23	68.3437
3707.24	66.7323
3710.24	57.4845
3713.25	58.6698
3716.25	48.4062
3719.25	42.9153
3722.25	34.5347
3725.25	41.366
3728.25	36.7516
3731.24	32.1217
3734.24	31.2797
3737.23	23.7482
3740.22	14.2985
3743.21	21.0063
3746.21	34.3502
3749.19	12.4859
3752.18	18.1829
3755.17	21.0219
3758.15	23.865
3761.14	20.0631
3764.12	3.93013
3767.1	9.60371
3770.08	23.8028
3773.06	7.74304
3776.04	4.95038
3779.02	5.95255
3781.99	12.6367
3784.97	-0.51062
3787.94	13.7402
3790.91	9.11942
3793.88	3.59023
3796.85	11.2929
3799.82	1.07365
3802.79	11.6513
3805.76	11.8573
3808.72	-0.212021
3811.69	1.9005
3814.65	-3.54366
3817.61	7.09367
3820.57	8.28642
3823.53	2.85768
3826.49	3.12297
3829.45	15.7154
3832.4	0.813858
3835.36	4.89615
3838.31	-0.502563
3841.26	-7.8094
3844.21	1.99387
3847.16	5.15268
3850.11	-1.20184
3853.06	9.608
3856	6.12633
3858.95	-3.08963
3861.89	3.93375
3864.84	1.38904
3867.78	15.1211
3870.72	9.69083
3873.66	2.32918
3876.6	-3.13046
3879.53	-0.935913
3882.47	13.7309
3885.4	10.1257
3888.34	10.3485
3891.27	1.91023
3894.2	6.9241
3897.13	3.25938
3900.06	0.533478
3902.99	14.1518
3905.91	1.78113
3908.84	10.5879
3911.76	13.6075
3914.69	2.19626
3917.61	7.10254
3920.53	19.7287
3923.45	13.1094
3926.37	3.59552
3929.28	14.2096
3932.2	-2.03136
3935.11	17.2277
3938.03	10.6621
3940.94	3.18102
3943.85	-1.44635
3946.76	13.0851
3949.67	20.9348
3952.58	7.73564
3955.49	11.7791
3958.39	10.095
3961.3	13.2106
3964.2	14.4207
3967.1	14.6841
3970	13.0393
3972.9	0.840973
3975.8	19.3575
3978.7	16.7414
3981.6	9.30411
3984.49	8.58847
3987.39	20.3629
3990.28	5.2083
3993.17	12.145
3996.06	7.57748
3998.95	13.5901
4001.84	10.9518
4004.73	4.46143
4007.61	9.53822
4010.5	8.83841
4013.38	8.13486
4016.27	8.39691
4019.15	13.4846
4022.03	14.7131
4024.91	4.35295
4027.79	12.3473
4030.66	14.5485
4033.54	7.08649
4036.42	-5.2193
4039.29	6.67207
4042.16	7.91811
4045.03	8.16284
4047.9	2.60043
4050.77	7.70903
4053.64	4.10138
4056.51	9.2422
4059.38	8.55652
4062.24	0.0892487
4065.1	15.9155
4067.97	13.2775
4070.83	5.76851
4073.69	7.98573
4076.55	4.35718
4079.41	-0.251511
4082.26	6.83212
4085.12	5.14584
4087.97	-3.37973
4090.83	-2.15408
4093.68	3.966
4096.53	8.12521
4099.38	4.47729
4102.23	-4.06488
4105.08	5.96159
4107.93	11.0821
4110.77	-1.40849
4113.62	9.5657
4116.46	-3.94638
4119.3	15.7925
4122.14	5.19182
4124.98	-1.47379
4127.82	12.4178
4130.66	9.71753
4133.5	15.8594
4136.33	5.39946
4139.17	6.49345
4142	1.54448
4144.83	-6.14096
4147.67	4.85316
4150.5	10.973
4153.33	15.1
4156.15	6.43068
4158.98	3.56458
4161.81	16.4053
4164.63	-4.96529
4167.45	3.98666
4170.28	4.14189
4173.1	11.152
4175.92	8.3873
4178.74	-3.17911
4181.56	8.73811
4184.37	9.90457
4187.19	-5.55038
4190	14.2186
4192.82	-0.234756
4195.63	6.86278
4198.44	7.13254
4201.25	-4.36732
4204.06	13.555
4206.87	-4.82758
4209.68	12.1287
4212.48	0.598404
4215.29	18.5511
4218.1	11.041
4220.9	15.3388
4223.7	9.76109
4226.5	-3.74956
4229.3	11.3992
4232.1	16.694
4234.9	2.20923
4237.69	8.5278
4240.49	-4.00363
4243.28	2.32938
4246.07	-5.25293
4248.87	-3.89107
4251.66	9.43803
4254.45	7.79887
4257.24	22.1501
4260.03	8.4785
4262.81	6.81781
4265.6	5.15869
4268.38	5.51668
4271.17	9.89928
4273.95	8.23882
4276.73	4.52309
4279.51	4.81253
4282.29	8.12033
4285.07	13.4366
4287.84	9.62988
4290.62	20.9825
4293.39	2.96815
4296.17	-0.858093
4298.94	2.42134
4301.71	3.6609
4304.48	18.0907
4307.25	13.2415
4310.02	-0.749405
4312.79	11.6889
4315.55	5.80704
4318.32	-4.1684
4321.08	5.17606
4323.85	18.5836
4326.61	-0.599136
4329.37	2.6218
4332.13	16.0133
4334.89	7.0018
4337.65	1.02908
4340.4	5.2728
4343.16	6.46332
4345.91	6.64986
4348.67	8.8922
4351.42	10.117
4354.17	3.21332
4356.92	4.46307
4359.67	-2.47139
4362.42	14.1151
4365.17	12.3024
4367.91	9.4493
4370.66	3.53015
4373.4	9.88789
4376.14	11.1124
4378.89	-4.10608
4381.63	4.28433
4384.37	2.41417
4387.11	10.8592
4389.84	3.94217
4392.58	11.4676
4395.32	11.9127
4398.05	7.07967
4400.78	9.46092
4403.52	3.53986
4406.25	13.1761
4408.98	3.10255
4411.71	22.1098
4414.44	10.9371
4417.16	10.1543
4419.89	-3.20764
4422.62	15.7783
4425.34	11.8347
4428.06	15.1997
4430.78	-2.34302
4433.51	4.15056
4436.22	6.45638
4438.94	-0.673157
4441.66	14.1867
4444.38	7.03905
4447.1	-4.32347
4449.81	9.49838
4452.52	-0.83873
4455.24	17.181
4457.95	4.71765
4460.66	11.162
4463.37	12.3718
4466.08	14.6317
4468.78	1.11531
4471.49	13.9171
4474.2	11.9968
4476.9	9.03508
4479.6	17.6857
4482.31	5.24506
4485.01	-1.9326
4487.71	7.78296
4490.41	15.3892
4493.11	18.7294
4495.8	11.4492
4498.5	2.08003
4501.19	16.0049
4503.89	10.8447
4506.58	8.87885
4509.27	17.5231
4511.96	10.2582
4514.66	17.8526
4517.34	7.40329
4520.03	16.0763
4522.72	7.76555
4525.41	5.8279
4528.09	9.20651
4530.77	-6.58058
4533.46	5.33061
4536.14	14.0634
4538.82	5.73293
4541.5	15.5634
4544.18	-0.255035
4546.86	4.23871
4549.53	20.5217
4552.21	-3.88672
4554.88	7.09677
4557.56	11.6799
4560.23	8.79333
4562.9	14.5496
4565.57	9.57437
4568.24	3.54642
4570.91	9.33659
4573.58	7.36018
4576.24	4.21411
4578.91	3.31784
4581.58	6.83156
4584.24	1.68622
4586.9	18.2286
4589.56	8.61342
4592.22	3.33327
4594.88	16.6131
4597.54	9.17915
4600.2	12.6457
4602.86	1.92685
4605.51	12.0078
4608.17	0.186203
4610.82	4.8029
4613.47	11.6182
4616.13	10.7498
4618.78	-0.0131531
4621.43	6.83142
4624.07	5.96812
4626.72	15.0196
4629.37	1.99583
4632.01	3.31175
4634.66	1.28957
4637.3	10.3168
4639.94	8.28342
4642.59	-7.04337
4645.23	17.5475
4647.87	10.0484
4650.5	11.4597
4653.14	-2.64871
4655.78	9.908
4658.42	14.4785
4661.05	2.44679
4663.68	-0.645691
4666.31	8.53674
4668.95	2.02913
4671.58	1.1252
4674.21	10.3018
4676.84	4.91245
4679.46	6.24579
4682.09	9.82303
4684.72	-0.0813293
4687.34	2.37286
4689.97	3.70686
4692.59	7.30006
4695.21	7.50249
4697.83	-6.96088
4700.45	14.6798
4703.07	-4.31604
4705.69	7.16478
4708.3	0.562393
4710.92	-0.39595
4713.54	11.0931
4716.15	7.86693
4718.76	6.89537
4721.37	16.1183
4723.99	11.7347
4726.59	0.566589
4729.2	-2.65955
4731.81	17.9509
4734.42	-2.30327
4737.03	6.96144
4739.63	0.309509
4742.23	-4.07693
4744.84	6.30936
4747.44	6.45245
4750.04	13.3991
4752.64	5.55827
4755.24	10.2335
4757.84	12.6312
4760.44	9.35277
4763.03	4.94669
4765.63	7.38091
4768.22	5.29218
4770.82	3.2196
4773.41	3.39275
4776	11.5592
4778.59	6.03143
4781.18	5.06639
4783.77	0.673126
4786.36	8.85638
4788.94	3.31985
4791.53	1.21735
4794.11	4.84546
4796.7	-9.85118
4799.28	6.40695
4801.86	0.896408
4804.44	11.4669
4807.02	1.3842
4809.6	-12.1581
4812.18	6.52292
4814.76	7.95473
4817.33	-7.91844
4819.91	9.70459
4822.48	11.1666
4825.06	9.15891
4827.63	0.181442
4830.2	12.0931
4832.77	14.7468
4835.34	-1.22733
4837.91	8.43759
4840.48	1.78584
4843.04	11.495
4845.61	4.79486
4848.17	3.92848
4850.74	8.89323
4853.3	7.88838
4855.86	4.53728
4858.42	8.40025
4860.98	-1.8849
4863.54	14.9186
4866.1	11.6125
4868.66	4.75642
4871.21	8.57954
4873.77	-0.659225
4876.32	-2.81715
4878.88	2.13979
4881.43	1.15794
4883.98	0.164917
4886.53	11.0551
4889.08	10.0669
4891.63	12.6485
4894.18	-1.44536
4896.72	10.6516
4899.27	8.45038
4901.81	-4.49031
4904.36	-1.93568
4906.9	1.8098
4909.44	4.35538
4911.98	4.48337
4914.52	11.7646
4917.06	2.30768
4919.6	8.39256
4922.14	-3.44319
4924.67	8.61603
4927.21	2.76064
4929.74	1.66643
4932.28	4.19078
4934.81	-2.82532
4937.34	11.6768
4939.87	-0.151627
4942.4	3.51822
4944.93	1.24474
4947.46	7.37906
4949.99	13.5126
4952.51	14.8651
4955.04	13.8001
4957.56	5.55463
4960.08	-2.69044
4962.61	1.08278
4965.13	7.3038
4967.65	3.92662
4970.17	-7.93956
4972.69	1.88615
4975.2	5.68245
4977.72	4.64253
4980.24	8.44472
4982.75	-5.91615
4985.27	-2.11694
4987.78	7.75711
4990.29	9.1467
4992.8	-1.62967
4995.31	4.6048
4997.82	4.77856