File: Data/3-Raman/processed/bu19w-e-ff11b-fi05-v_1800 (450-850nm)_532nm_edge_100%_x100_vis_h50um_30sx2_01.txt
#Acq. time (s)=	30
#Accumulations=	2
#Range (cm-¹)=	1200...2365
#Windows=	3
#Auto scanning=	Off
#Autofocus=	Off
#Macrospot=	Off
#AutoExposure=	Off
#Spike filter=	Multiple accum.
#Delay time (s)=	2
#Binning=	1
#Readout mode=	Signal
#DeNoise=	Off
#ICS correction=	On
#Dark correction=	Off
#Inst. Process=	Off
#Detector Gain=	Best Dynamic
#Detector ADC=	50 kHz HS
#Detector temperature (°C)=	-60.28
#Instrument=	LabRAM HR Evol
#Detector=	SIN-EM FIVIS
#Objective=	x100_VIS
#Grating=	1800 (450-850nm)
#ND Filter=	100%
#Laser=	532nm_Edge
#Hole=	49.98
#Temperature=	0
#Range=	Visible
#StageXY=	75x50mm Scan+
#StageZ=	Z motor
#X (µm)=	0
#Y (µm)=	0
#Z (µm)=	-263.7
#Full time(mm:ss)=	3:18
#Project=	21_11_04
#Sample=	BU19w
#Site=
#Title=	BU19w-E-FF11b-FI05-V_1800 (450-850nm)_532nm_Edge_100%_x100_VIS_H50um_30sX2
#Remark=
#Date=	04.11.2021 18:58
#Acquired=	04.11.2021 18:58:56
#Base:Fit=	16.12.2021 17:39:50
#Base:Fit=	16.12.2021 17:44:46
#Base:Sub=	16.12.2021 17:44:47
1202.73	1.03671
1203.85	0.891083
1204.96	0.778585
1206.07	-1.50297
1207.18	-0.55472
1208.29	0.404545
1209.4	-2.90377
1210.51	0.191566
1211.62	-0.987507
1212.73	3.17003
1213.84	-2.23893
1214.95	-1.24966
1216.06	-0.276873
1217.17	-0.373985
1218.28	0.602976
1219.39	-2.65312
1220.5	-0.596451
1221.61	0.38488
1222.72	3.46054
1223.82	2.31306
1224.93	0.140215
1226.04	2.207
1227.15	3.17918
1228.25	4.1108
1229.36	-0.0586414
1230.47	7.23139
1231.57	1.87604
1232.68	2.88225
1233.79	1.79931
1234.89	2.82816
1236	-0.353691
1237.1	2.7459
1238.21	0.584713
1239.31	-2.59915
1240.42	-1.57615
1241.52	2.58599
1242.63	0.475086
1243.74	1.50514
1244.84	-0.622559
1245.94	-1.70752
1247.05	1.4129
1248.15	-0.710093
1249.25	-1.76869
1250.36	0.297636
1251.46	1.31479
1252.56	0.24354
1253.66	-2.89392
1254.77	-1.84845
1255.87	0.235727
1256.97	2.32185
1258.07	3.35359
1259.18	0.214729
1260.28	7.51449
1261.38	10.6472
1262.48	14.8237
1263.58	22.1843
1264.68	8.60568
1265.78	5.46753
1266.88	0.264145
1267.98	2.3963
1269.08	8.70369
1270.18	3.44723
1271.28	0.304182
1272.38	2.43247
1273.48	4.5647
1274.58	5.63112
1275.68	6.70776
1276.78	6.74108
1277.87	9.93254
1278.97	8.9146
1280.07	15.2318
1281.17	51.0634
1282.26	156.365
1283.36	418.789
1284.46	117.588
1285.55	17.4579
1286.65	10.0987
1287.75	6.94308
1288.84	8.02425
1289.94	-0.364447
1291.04	0.702396
1292.13	2.82894
1293.23	1.80704
1294.32	3.95244
1295.42	2.95532
1296.51	0.882706
1297.61	2.99771
1298.7	4.06721
1299.79	4.08976
1300.89	0.944788
1301.98	0.977791
1303.08	-0.0615616
1304.17	1.01571
1305.26	2.07963
1306.36	-0.0206032
1307.45	2.11508
1308.54	1.08816
1309.63	1.12269
1310.73	1.14751
1311.82	4.34958
1312.91	0.14925
1314	0.171833
1315.09	3.37537
1316.18	-1.87782
1317.28	-1.84862
1318.37	0.293888
1319.46	2.43179
1320.55	-2.82898
1321.64	0.343554
1322.73	1.41031
1323.82	-0.66934
1324.91	2.51925
1325.99	-0.658747
1327.08	0.442863
1328.17	-3.7173
1329.26	0.533381
1330.35	-2.61417
1331.44	0.545467
1332.53	3.70109
1333.62	-0.502575
1334.7	-0.49383
1335.79	0.568405
1336.88	0.586693
1337.96	1.64694
1339.05	0.620081
1340.14	2.74631
1341.23	0.675858
1342.31	1.7321
1343.4	3.84386
1344.48	1.77665
1345.57	-1.35251
1346.66	0.733942
1347.74	-0.296583
1348.83	3.88696
1349.91	0.774515
1351	2.86383
1352.08	1.85286
1353.17	0.884363
1354.25	0.846319
1355.33	3.98454
1356.42	4.01087
1357.5	5.06439
1358.58	1.96129
1359.67	6.11796
1360.75	0.948853
1361.83	3.04171
1362.92	5.1401
1364	5.17498
1365.08	5.1856
1366.16	4.155
1367.24	3.13294
1368.33	16.6071
1369.41	11.465
1370.49	8.37239
1371.57	3.2036
1372.65	6.2995
1373.73	6.31585
1374.81	10.4559
1375.89	9.45344
1376.97	14.5954
1378.05	16.7373
1379.13	17.7988
1380.21	20.8462
1381.29	22.891
1382.37	26.9492
1383.45	32.055
1384.53	50.5636
1385.61	150.261
1386.68	898.047
1387.76	160.86
1388.84	35.3356
1389.92	20.9311
1390.99	11.7187
1392.07	7.62057
1393.15	8.65674
1394.23	8.67422
1395.3	6.66413
1396.38	5.65789
1397.46	4.64682
1398.53	6.72477
1399.61	1.64207
1400.68	4.74887
1401.76	5.81655
1402.83	5.88346
1403.91	5.89268
1404.99	4.88038
1406.06	11.0405
1407.13	18.2473
1408.21	44.9421
1409.28	15.2388
1410.36	3.96402
1411.43	4.99595
1412.5	6.08938
1413.58	0.961044
1414.65	2.03633
1415.72	3.08991
1416.8	2.09499
1417.87	1.09528
1418.94	0.0917339
1420.01	5.23471
1421.08	2.16423
1422.16	1.18583
1423.23	5.24558
1424.3	-1.89905
1425.37	-0.836006
1426.44	3.27426
1427.51	2.24445
1428.58	3.2901
1429.65	2.30163
1430.72	1.32402
1431.79	0.318396
1432.86	1.34228
1433.93	3.39718
1435	-0.669727
1436.07	2.42005
1437.14	0.385687
1438.21	-0.615473
1439.28	4.53624
1440.35	3.544
1441.41	3.55886
1442.48	0.509096
1443.55	-1.53069
1444.62	0.553982
1445.69	4.6725
1446.75	0.58267
1447.82	-0.426889
1448.89	-0.402512
1449.95	-0.393442
1451.02	1.66876
1452.09	0.657839
1453.15	-0.343214
1454.22	-1.35199
1455.28	1.74111
1456.35	-0.29092
1457.41	1.76838
1458.48	0.763968
1459.54	-1.26755
1460.61	0.792049
1461.67	-1.24896
1462.74	-1.24633
1463.8	-2.24757
1464.86	-1.2275
1465.93	1.83578
1466.99	-1.22141
1468.05	0.832253
1469.12	-0.178194
1470.18	0.844046
1471.24	3.90514
1472.31	2.89869
1473.37	0.86956
1474.43	0.885773
1475.49	-2.15476
1476.55	2.93846
1477.62	-3.15281
1478.68	0.917801
1479.74	-2.12982
1480.8	0.91588
1481.86	-2.10531
1482.92	-4.11523
1483.98	1.97761
1485.04	-0.101627
1486.1	1.97492
1487.16	6.0381
1488.22	2.9978
1489.28	-0.0339756
1490.34	-0.0251007
1491.4	0.99225
1492.46	1.00475
1493.52	-2.01633
1494.57	-0.99143
1495.63	-2.00658
1496.69	0.0178566
1497.75	0.0294209
1498.81	0.0448685
1499.86	1.07158
1500.92	-2.9587
1501.98	-1.94015
1503.03	-0.930504
1504.09	0.092186
1505.15	0.0971603
1506.2	-1.91663
1507.26	1.12338
1508.32	1.13366
1509.37	-0.869123
1510.43	0.14395
1511.48	2.13849
1512.54	0.112551
1513.59	-1.88171
1514.65	2.14074
1515.7	-0.878141
1516.76	2.1358
1517.81	0.14706
1518.86	-1.84335
1519.92	2.17908
1520.97	2.19467
1522.02	0.193474
1523.08	0.189316
1524.13	4.18971
1525.18	0.198641
1526.24	1.2248
1527.29	-0.773689
1528.34	-0.769936
1529.39	-1.76564
1530.44	1.25471
1531.5	-0.735376
1532.55	0.284786
1533.6	-0.69684
1534.65	3.31958
1535.7	-0.701202
1536.75	0.289005
1537.8	1.28628
1538.85	0.30102
1539.9	1.35054
1540.95	3.36701
1542	1.35355
1543.05	3.34566
1544.1	0.348587
1545.15	1.37918
1546.2	0.39143
1547.25	-0.596352
1548.29	2.41343
1549.34	-0.615227
1550.39	1.48243
1551.44	2.47483
1552.49	1.49259
1553.53	0.473715
1554.58	2.46557
1555.63	0.47039
1556.68	2.48067
1557.72	3.48201
1558.77	3.46648
1559.82	4.45974
1560.86	0.46674
1561.91	2.48915
1562.95	2.4943
1564	2.51613
1565.04	-0.541269
1566.09	3.51179
1567.13	0.532658
1568.18	-0.468836
1569.22	0.5271
1570.27	1.53596
1571.31	0.536592
1572.36	3.53076
1573.4	2.52976
1574.44	4.55062
1575.49	2.57017
1576.53	1.56506
1577.57	3.54173
1578.62	2.54433
1579.66	-0.435255
1580.7	2.55908
1581.74	2.55342
1582.79	1.55925
1583.83	2.56051
1584.87	4.56116
1585.91	1.56996
1586.95	4.5513
1587.99	6.54959
1589.03	-0.400986
1590.07	2.59635
1591.12	0.612438
1592.16	4.58459
1593.2	3.57053
1594.24	1.58062
1595.28	1.58802
1596.32	1.59237
1597.35	1.60337
1598.39	6.5604
1599.43	2.58172
1600.47	2.57158
1601.51	1.56505
1602.55	2.54461
1603.59	4.51861
1604.63	5.51485
1605.66	5.5281
1606.7	0.59535
1607.74	6.50811
1608.78	4.62313
1609.81	5.08299
1610.85	3.53603
1611.89	2.62098
1612.92	3.5506
1613.96	3.67401
1615	3.8979
1616.03	2.70477
1617.07	5.10711
1618.1	5.00858
1619.14	2.79329
1620.17	4.99381
1621.21	2.37952
1622.24	4.18268
1623.28	4.49308
1624.31	5.04567
1625.35	3.33758
1626.38	4.41691
1627.41	6.79093
1628.45	3.32041
1629.48	2.87794
1630.51	3.5434
1631.3	2.63269
1632.34	3.64143
1633.39	6.58786
1634.43	5.61437
1635.48	2.65819
1636.52	3.63882
1637.57	6.58999
1638.61	3.63881
1639.66	5.61214
1640.7	0.703682
1641.75	3.65771
1642.79	1.69206
1643.83	3.6598
1644.88	2.68189
1645.92	3.66993
1646.96	4.6515
1648.01	2.6916
1649.05	2.71377
1650.09	3.71219
1651.13	4.71567
1652.18	1.76515
1653.22	5.70928
1654.26	2.76484
1655.3	3.77555
1656.34	3.79384
1657.38	2.80752
1658.42	6.75045
1659.47	0.826496
1660.51	4.78609
1661.55	3.82019
1662.59	4.84374
1663.63	4.81808
1664.67	3.86237
1665.71	-0.0724468
1666.75	3.85458
1667.79	0.887173
1668.83	0.913176
1669.86	3.88027
1670.9	2.91349
1671.94	3.91034
1672.98	3.91776
1674.02	4.92175
1675.06	2.96108
1676.1	5.93821
1677.13	1.98363
1678.17	2.96539
1679.21	0.985794
1680.25	0.985308
1681.28	2.96421
1682.32	0.994547
1683.35	3.96309
1684.39	2.97471
1685.43	1.00491
1686.46	1.01828
1687.5	2.00772
1688.54	0.0297165
1689.57	1.99617
1690.6	2.99546
1691.64	4.98096
1692.68	0.0429764
1693.71	3.97506
1694.74	1.01884
1695.78	1.03058
1696.81	1.03477
1697.85	1.02531
1698.88	-0.943555
1699.92	3.98124
1700.95	1.03161
1701.98	-0.940283
1703.01	1.02585
1704.05	0.0503807
1705.08	1.03848
1706.11	2.01731
1707.14	-0.937131
1708.18	0.0290833
1709.21	1.00107
1710.24	1.98812
1711.27	1.02312
1712.3	3.95391
1713.33	-0.957925
1714.36	1.97136
1715.4	1.00767
1716.43	-0.950193
1717.46	-0.969474
1718.49	1.94133
1719.52	-0.00025177
1720.55	-0.000457764
1721.58	2.9087
1722.61	0.954119
1723.64	-0.016964
1724.66	0.946796
1725.69	1.90286
1726.72	1.9014
1727.75	1.90726
1728.78	-0.0843782
1729.81	-1.0289
1730.83	-1.01133
1731.86	1.8925
1732.89	1.88625
1733.92	-0.0612125
1734.95	-1.0376
1735.97	-0.0768661
1737	0.883116
1738.03	0.87804
1739.05	1.82701
1740.08	-2.02924
1741.1	0.838305
1742.13	-0.119214
1743.16	-0.116751
1744.18	-2.03269
1745.21	-0.113063
1746.23	1.79187
1747.26	0.826525
1748.28	0.831285
1749.31	-2.97332
1750.33	-1.04428
1751.36	-1.0403
1752.38	1.81619
1753.4	0.855803
1754.43	-0.102876
1755.45	-2.01089
1756.47	-0.116402
1757.5	-0.117921
1758.52	1.79937
1759.54	0.854818
1760.57	-1.04769
1761.59	-1.04944
1762.61	0.863276
1763.63	-1.98024
1764.66	-1.00898
1765.68	2.80979
1766.7	-0.0422373
1767.72	-0.0425224
1768.74	0.898025
1769.76	0.892599
1770.78	-0.0402708
1771.8	-0.972196
1772.82	-0.955886
1773.84	1.91256
1774.86	0.974838
1775.88	-0.909227
1776.9	0.997328
1777.92	3.84933
1778.94	0.0327187
1779.96	0.997612
1780.98	-0.894928
1782	0.0737371
1783.02	-0.863902
1784.04	-0.846322
1785.05	0.118427
1786.07	0.123173
1787.09	-0.809379
1788.11	-0.766681
1789.12	2.13085
1790.14	-0.73033
1791.16	-0.73771
1792.18	0.226479
1793.19	-2.63667
1794.21	0.245053
1795.23	-0.678892
1796.24	-0.661099
1797.26	3.20145
1798.27	2.25254
1799.29	-0.632667
1800.3	-0.634226
1801.32	0.33192
1802.33	0.345824
1803.35	1.32558
1804.36	-1.54517
1805.38	-1.52532
1806.39	1.38077
1807.41	1.38865
1808.42	1.39712
1809.43	1.40646
1810.45	-0.515813
1811.46	-3.40226
1812.47	0.467746
1813.49	-2.41206
1814.5	1.47328
1815.51	-0.447147
1816.53	-1.40529
1817.54	-3.34361
1818.55	0.535047
1819.56	0.547671
1820.57	0.561239
1821.58	-2.3269
1822.6	-0.380987
1823.61	2.5251
1824.62	-0.367166
1825.63	-1.32633
1826.64	-0.350132
1827.65	0.629789
1828.66	0.629658
1829.67	0.63164
1830.68	6.4443
1831.69	2.58678
1832.7	0.663531
1833.71	3.58114
1834.72	-0.316241
1835.73	-1.29045
1836.74	1.65205
1837.75	0.641258
1838.75	-0.281737
1839.76	-3.18452
1840.77	-0.309284
1841.78	0.637012
1842.79	-0.325938
1843.79	0.642099
1844.8	1.61189
1845.81	-0.294166
1846.81	-3.21872
1847.82	-0.318698
1848.83	2.56109
1849.83	-0.341119
1850.84	0.609405
1851.85	2.52922
1852.85	1.57226
1853.86	-0.356494
1854.86	3.46881
1855.87	-0.371452
1856.87	-1.32662
1857.88	2.49816
1858.88	-0.383322
1859.89	-1.33813
1860.89	-0.367675
1861.9	-1.31929
1862.9	2.49575
1863.9	0.575447
1864.91	-0.389573
1865.91	1.49697
1866.92	1.4733
1867.92	0.514596
1868.92	0.518373
1869.92	1.46886
1870.93	-1.38107
1871.93	-0.434792
1872.93	0.509241
1873.93	3.34933
1874.93	0.489736
1875.94	3.3068
1876.94	0.448464
1877.94	-4.24934
1878.94	2.38971
1879.94	-0.45918
1880.94	-0.462347
1881.94	0.453969
1882.94	1.46229
1883.94	-2.39416
1884.94	2.33319
1885.94	0.46452
1886.94	0.452557
1887.94	-0.50576
1888.94	-0.521145
1889.94	-0.516171
1890.94	1.37271
1891.94	0.430563
1892.94	1.3543
1893.93	0.402151
1894.93	-0.538699
1895.93	1.35042
1896.93	-0.518908
1897.93	-2.39982
1898.92	-0.529783
1899.92	-0.534363
1900.92	1.35373
1901.91	0.428807
1902.91	2.30672
1903.91	-0.516865
1904.9	1.36225
1905.9	2.28933
1906.9	-1.47128
1907.89	-1.46396
1908.89	-1.45635
1909.88	-1.43897
1910.88	-1.42677
1911.87	0.456373
1912.87	1.39881
1913.86	2.35823
1914.86	0.48521
1915.85	-0.459181
1916.85	0.47431
1917.84	0.473758
1918.84	2.37879
1919.83	-1.38223
1920.82	2.40508
1921.82	-0.424743
1922.81	-0.431717
1923.8	0.505913
1924.79	0.504922
1925.79	1.46671
1926.78	2.42924
1927.77	0.542918
1928.76	5.28883
1929.75	-0.382689
1930.75	0.575816
1931.74	1.51694
1932.73	0.559638
1933.72	3.42991
1934.71	-2.23056
1935.7	-0.323508
1936.69	0.61898
1937.68	1.55673
1938.67	1.56477
1939.66	-2.23898
1940.65	4.45846
1941.64	2.53206
1942.63	-0.306429
1943.62	-1.27225
1944.61	3.51563
1945.6	2.57495
1946.59	0.666333
1947.58	0.660954
1948.57	-0.295531
1949.55	1.63068
1950.54	-1.22072
1951.53	-0.24419
1952.52	-1.20003
1953.5	1.66401
1954.49	-1.24195
1955.48	-1.23454
1956.47	-1.21561
1957.45	-0.246121
1958.44	1.6764
1959.43	1.66588
1960.41	-0.268014
1961.4	-0.277141
1962.38	-2.19684
1963.37	2.60258
1964.36	0.682194
1965.34	-0.279693
1966.33	-0.270723
1967.31	1.65194
1968.3	2.61028
1969.28	1.62866
1970.26	-0.307045
1971.25	1.6012
1972.23	-1.27657
1973.22	-0.330005
1974.2	1.57952
1975.18	0.623738
1976.17	1.58532
1977.15	3.49705
1978.13	-0.351198
1979.12	1.56172
1980.1	-1.32004
1981.08	1.54268
1982.06	0.576689
1983.05	-0.398204
1984.03	1.50517
1985.01	0.534882
1985.99	-0.419662
1986.97	4.35749
1987.95	0.5068
1988.93	1.40055
1989.91	1.35816
1990.89	2.28656
1991.88	-1.42011
1992.86	1.87499
1993.84	3.01785
1994.82	0.619539
1995.8	0.179245
1996.78	-0.443701
1997.76	-1.62281
1998.73	-0.354369
1999.71	0.548035
2000.69	0.444399
2001.67	0.460032
2002.65	1.13275
2003.63	0.73941
2004.6	0.518243
2005.58	0.971011
2006.56	0.499007
2007.54	-0.496904
2008.52	-0.56045
2009.49	0.644094
2010.47	-0.509707
2011.45	0.238416
2012.42	1.11956
2013.41	1.09064
2014.4	-0.81795
2015.39	2.00114
2016.38	2.01529
2017.37	-0.819086
2018.35	-0.845876
2019.34	-0.866935
2020.33	-0.874397
2021.32	1.93238
2022.31	0.980896
2023.29	-1.84447
2024.28	1.87317
2025.27	-0.0186129
2026.25	-0.0135946
2027.24	0.951643
2028.23	1.8457
2029.21	0.934083
2030.2	-0.989891
2031.19	-0.0435114
2032.17	-1.90062
2033.16	1.85022
2034.14	-2.8534
2035.13	-0.978587
2036.11	2.76911
2037.1	0.898644
2038.08	-0.982847
2039.07	-0.996543
2040.05	-1.01553
2041.03	2.69877
2042.02	-0.109508
2043	0.82138
2043.99	-0.0988503
2044.97	-1.97776
2045.95	-1.00442
2046.94	-1.03934
2047.92	0.80709
2048.9	2.67946
2049.88	-2.90587
2050.87	0.827183
2051.85	0.820649
2052.83	-1.04284
2053.81	-0.0949163
2054.79	-1.03453
2055.78	-1.98006
2056.76	0.818798
2057.74	1.75891
2058.72	-1.03689
2059.7	0.833056
2060.68	-1.04259
2061.66	-1.04224
2062.64	0.835631
2063.62	-0.0957003
2064.6	-3.84111
2065.58	1.80177
2066.56	2.74598
2067.54	-0.0660601
2068.52	-1.94292
2069.5	-1.02054
2070.48	0.879591
2071.46	0.898384
2072.43	0.892496
2073.41	-0.0510683
2074.39	-0.043766
2075.37	-0.963035
2076.35	-0.0175571
2077.32	-0.978437
2078.3	-0.0293903
2079.28	0.930033
2080.26	0.937375
2081.23	-0.957393
2082.21	-0.956429
2083.19	-0.958796
2084.16	1.87504
2085.14	-0.0151987
2086.12	-0.948494
2087.09	1.8971
2088.07	2.84427
2089.04	-1.88316
2090.02	0.965149
2090.99	-2.81957
2091.97	-0.907283
2092.94	-0.890764
2093.92	-4.68317
2094.89	0.0661945
2095.87	-0.892506
2096.84	1.95044
2097.81	-0.90456
2098.79	-0.908096
2099.76	0.040451
2100.74	-0.899682
2101.71	-0.896658
2102.68	0.996727
2103.65	1.94286
2104.63	-0.89664
2105.6	0.0650492
2106.57	0.070426
2107.54	0.063899
2108.52	-0.89869
2109.49	1.00985
2110.46	1.96095
2111.43	1.00696
2112.4	0.0603342
2113.38	2.92379
2114.35	-1.8289
2115.32	-0.879577
2116.29	1.01286
2117.26	-1.83649
2118.23	1.9483
2119.2	-0.90904
2120.17	0.0346451
2121.14	0.995965
2122.11	0.0623474
2123.08	1.96965
2124.05	-2.78237
2125.02	-1.85423
2125.98	0.0255709
2126.95	1.90736
2127.92	0.959629
2128.89	1.9059
2129.86	0.0148449
2130.83	2.84467
2131.79	2.83821
2132.76	0.000790596
2133.73	0.949682
2134.7	-0.93502
2135.67	0.946134
2136.63	-0.000213623
2137.6	-0.934948
2138.57	-0.932536
2139.53	2.82933
2140.5	-0.943291
2141.46	-0.00501919
2142.43	0.943808
2143.4	0.911817
2144.36	-0.946404
2145.33	0.931343
2146.29	1.87
2147.26	-0.013341
2148.22	0.922701
2149.19	-0.965322
2150.15	1.83846
2151.12	-0.964478
2152.08	1.85755
2153.05	-0.0226641
2154.01	-0.0303402
2154.97	-0.985772
2155.94	-0.0597897
2156.9	-0.989342
2157.86	2.76255
2158.83	1.8287
2159.79	-0.982181
2160.75	0.88038
2161.72	0.881611
2162.68	-0.0493793
2163.64	1.81371
2164.6	-0.0556326
2165.56	0.884242
2166.53	0.880782
2167.49	-0.99274
2168.45	2.72198
2169.41	1.81396
2170.37	-0.0306711
2171.33	-1.90516
2172.29	2.73317
2173.25	1.80948
2174.21	3.6792
2175.17	1.82368
2176.13	-0.0339632
2177.09	-0.028554
2178.05	0.901165
2179.01	-0.953242
2179.97	-0.0190563
2180.93	-0.0163279
2181.89	-0.944694
2182.85	0.907695
2183.81	-0.953353
2184.76	1.83495
2185.72	-1.85858
2186.68	0.946212
2187.64	-0.896465
2188.6	0.0258589
2189.55	0.015954
2190.51	0.951355
2191.47	-0.893774
2192.42	0.0460253
2193.38	1.92399
2194.34	0.0890417
2195.3	-0.843019
2196.25	1.00156
2197.21	1.92612
2198.16	1.0146
2199.12	1.04118
2200.07	0.145852
2201.03	-0.768901
2201.99	0.10356
2202.94	-1.71565
2203.9	-0.740831
2204.85	0.165878
2205.8	-0.767568
2206.76	2.02603
2207.71	2.04601
2208.67	1.1319
2209.62	2.07007
2210.58	-4.43719
2211.53	1.17216
2212.48	-1.61885
2213.44	0.245546
2214.39	-1.59853
2215.34	-0.65632
2216.29	-1.58568
2217.25	-2.51375
2218.2	1.22792
2219.15	-1.55981
2220.1	0.316648
2221.06	1.2461
2222.01	1.24103
2222.96	-1.5477
2223.91	-0.592779
2224.86	0.361456
2225.81	-3.36668
2226.76	-2.41611
2227.72	1.34055
2228.67	-0.534329
2229.62	-0.520977
2230.57	-0.505328
2231.52	2.33058
2232.47	1.40752
2233.42	0.481778
2234.37	0.483798
2235.31	-2.34616
2236.26	-0.45919
2237.21	-1.38504
2238.16	1.46484
2239.11	-1.35041
2240.06	-0.415583
2241.01	0.544174
2241.96	2.4399
2242.9	1.4989
2243.85	1.497
2244.8	-0.370771
2245.75	1.53561
2246.69	-1.29147
2247.64	1.55119
2248.59	-2.23585
2249.53	1.55473
2250.48	1.54399
2251.43	3.42975
2252.37	-1.28612
2253.32	-2.2123
2254.26	-1.25597
2255.21	1.58916
2256.16	1.59914
2257.1	1.61055
2258.05	-2.18311
2258.99	-1.22658
2259.94	0.680215
2260.88	0.692175
2261.83	-2.15849
2262.77	2.61398
2263.71	1.68474
2264.66	1.70278
2265.6	2.66074
2266.55	1.68929
2267.49	-0.231009
2268.43	-0.234073
2269.38	-0.220109
2270.32	-0.206808
2271.26	-1.15502
2272.2	1.71841
2273.15	2.677
2274.09	-0.193085
2275.03	-4.02151
2275.97	-1.14377
2276.92	-1.13306
2277.86	-0.156201
2278.8	3.68263
2279.74	-1.13902
2280.68	-3.0693
2281.62	-1.15657
2282.56	1.72905
2283.5	0.790554
2284.44	-1.11932
2285.38	0.804333
2286.32	0.795372
2287.26	2.73563
2288.2	-0.158446
2289.14	2.70583
2290.08	-0.195715
2291.02	1.73475
2291.96	-0.182608
2292.9	-0.175359
2293.84	3.67466
2294.78	-2.12083
2295.72	1.71666
2296.65	0.743426
2297.59	2.68113
2298.53	-1.16583
2299.47	-3.09342
2300.41	-0.201151
2301.34	-1.16665
2302.28	-1.17464
2303.22	-1.18151
2304.15	0.751596
2305.09	3.65246
2306.03	0.754478
2306.97	-0.219186
2307.9	0.735134
2308.84	1.70136
2309.77	1.71101
2310.71	0.733392
2311.64	0.697887
2312.58	-1.24545
2313.51	0.696
2314.45	1.67911
2315.39	-2.20194
2316.32	2.60415
2317.25	-0.293577
2318.19	0.660764
2319.12	0.646182
2320.06	-0.324736
2320.99	-1.28652
2321.92	2.59023
2322.86	0.655717
2323.79	1.62051
2324.72	1.6007
2325.66	6.40845
2326.59	16.9947
2327.52	69.0153
2328.46	39.129
2329.39	10.1979
2330.32	6.34026
2331.25	-0.398957
2332.18	2.48298
2333.12	2.47185
2334.05	-1.38903
2334.98	-1.39556
2335.91	-1.39673
2336.84	0.522774
2337.77	-2.3648
2338.7	-1.40356
2339.63	-0.444793
2340.56	2.42489
2341.49	0.487244
2342.42	-1.43577
2343.35	2.39984
2344.28	-0.471006
2345.21	-1.43354
2346.14	-0.478765
2347.07	0.480221
2348	1.44819
2348.93	-1.42692
2349.85	1.41432
2350.78	-0.472859
2351.71	-1.44212
2352.64	1.3974
2353.57	-0.49893
2354.5	-0.48134
2355.42	-0.474538
2356.35	0.469776
2357.28	-0.478061
2358.21	0.478808
2359.13	0.489153
2360.06	1.4417
2360.99	2.3917
2361.91	0.497666
2362.84	1.4519
2363.77	-1.37287
2364.69	-1.35872
2364.92	0.535278