File: Data/3-Raman/processed/bu19w-b-ff1-fi09-v_150 (500nm)_532nm_edge_100%_x100_vis_h50um_15sx2_01.txt
#Acq. time (s)=	15
#Accumulations=	2
#Range (cm-¹)=	100...5000
#Windows=	1
#Auto scanning=	Off
#Autofocus=	Off
#Macrospot=	Off
#AutoExposure=	Off
#Spike filter=	Multiple accum.
#Delay time (s)=	2
#Binning=	1
#Readout mode=	Signal
#DeNoise=	Off
#ICS correction=	On
#Dark correction=	Off
#Inst. Process=	Off
#Detector Gain=	Best Dynamic
#Detector ADC=	50 kHz HS
#Detector temperature (°C)=	-60.09
#Instrument=	LabRAM HR Evol
#Detector=	SIN-EM FIVIS
#Objective=	x100_VIS
#Grating=	150 (500nm)
#ND Filter=	100%
#Laser=	532nm_Edge
#Hole=	49.98
#Temperature=	0
#Range=	Visible
#StageXY=	75x50mm Scan+
#StageZ=	Z motor
#X (µm)=	0
#Y (µm)=	0
#Z (µm)=	-142.1
#Full time(s)=	34
#Project=	21_05_14
#Sample=	BU19w
#Site=
#Title=	BU19w-FF1-FI09-V_150 (500nm)_532nm_Edge_100%_x100_VIS_H50um_15sX2
#Remark=
#Date=	14.05.2021 16:17
#Acquired=	14.05.2021 16:17:53
#Base:Fit=	22.12.2021 12:22:35
#Base:Edit=	22.12.2021 12:26:11
#Base:Edit=	22.12.2021 12:26:12
#Base:Edit=	22.12.2021 12:26:12
#Base:Edit=	22.12.2021 12:26:15
#Base:Sub=	22.12.2021 12:26:17
#Data Range:Extract=	22.12.2021 12:27:19
102.699	986.253
107.322	786.098
111.942	618.055
116.56	471.434
121.173	421.509
125.787	413.308
130.398	295.021
135.006	355.793
139.613	229.835
144.215	115.271
148.817	176.471
153.417	661.051
158.014	1652.59
162.607	1414.82
167.2	553.273
171.79	281.419
176.379	506.702
180.963	2052.06
185.547	5372.28
190.128	4379.58
194.705	1418.65
199.282	345.187
203.857	71.5537
208.43	25.4694
212.998	72.3551
217.566	16.5045
222.132	-1.47449
226.693	184.362
231.254	479.695
235.813	514.654
240.368	1029.78
244.923	1630.65
249.475	1317.48
254.023	879.605
258.571	519.039
263.117	447.193
267.658	866.954
272.199	2514.68
276.738	5035.04
281.273	4450.86
285.807	2139.33
290.34	1157.43
294.868	1138.96
299.396	2163.7
303.919	2525.04
308.443	1455.3
312.964	760.494
317.481	667.006
321.998	924.652
326.51	1585.04
331.023	1569.37
335.533	872.816
340.039	627.213
344.544	858.933
349.046	1136.65
353.547	799.448
358.045	397.42
362.542	230.961
367.036	344.771
371.527	321.515
376.017	255.148
380.503	431.071
384.99	776.748
389.471	1050.4
393.953	1078.58
398.43	817.938
402.908	543.591
407.381	425.961
411.854	568.645
416.323	876.489
420.791	533.742
425.256	130.54
429.72	4.98987
434.18	42.7145
438.64	26.9086
443.095	134.42
447.551	449.234
452.003	1266.49
456.454	1545.64
460.901	815.746
465.348	335.599
469.791	202.621
474.231	194.202
478.672	232.667
483.108	330.704
487.544	528.394
491.976	715.938
496.408	700.957
500.836	609.786
505.261	515.527
509.687	285.678
514.108	243.373
518.529	209.205
522.946	187.402
527.361	169.098
531.776	221.826
536.187	260.807
540.595	255.745
545.003	315.524
549.408	344.076
553.812	371.882
558.212	364.7
562.61	345.284
567.007	260.495
571.401	192.263
575.792	254.801
580.184	499.147
584.571	1305.62
588.956	2000.35
593.341	1330.42
597.722	661.88
602.101	615.053
606.48	1021.22
610.854	1336.89
615.227	1034.1
619.597	518.525
623.967	270.177
628.334	206.059
632.698	201.216
637.06	341.305
641.422	318.015
645.779	281.189
650.135	219.782
654.491	278.093
658.842	460.248
663.192	612.195
667.539	698.444
671.884	740.558
676.23	836.213
680.571	742.49
684.91	422.004
689.247	259.177
693.583	94.6097
697.916	60.3826
702.247	39.0048
706.576	29.3169
710.902	17.1771
715.229	7.39746
719.551	-0.89624
723.872	25.9777
728.19	27.6748
732.506	11.2222
736.82	13.309
741.134	63.9862
745.444	93.4578
749.752	162.194
754.058	170.795
758.362	313.912
762.664	496.393
766.964	736.525
771.264	1302.51
775.559	2077.64
779.853	2233.47
784.144	1540.58
788.434	925.465
792.722	558.234
797.007	338.915
801.29	228.155
805.572	182.102
809.851	115.439
814.13	73.3237
818.406	81.6733
822.679	112.462
826.95	100.537
831.219	68.8392
835.486	35.896
839.752	51.3284
844.015	36.6495
848.276	50.6329
852.535	29.1818
856.792	36.3983
861.047	35.7272
865.3	37.8081
869.551	-16.4967
873.8	15.5944
878.047	53.8832
882.292	52.0563
886.534	21.1729
890.775	3.17834
895.014	14.8304
899.251	20.5621
903.486	27.3489
907.719	68.9412
911.95	48.8038
916.179	80.2117
920.406	60.8744
924.63	96.4465
928.853	92.3448
933.074	104.55
937.293	151.514
941.51	261.238
945.723	361.69
949.936	484.772
954.147	447.995
958.356	451.982
962.563	495.505
966.768	534.825
970.971	515.218
975.172	314.577
979.371	235.381
983.568	216.711
987.761	130.014
991.954	147.099
996.145	88.2451
1000.33	146.388
1004.52	131.603
1008.71	134.178
1012.89	128.688
1017.07	199.911
1021.25	255.21
1025.43	264.73
1029.6	359.768
1033.77	427.22
1037.95	558.644
1042.11	829.424
1046.28	1586.31
1050.45	2760.96
1054.61	2800.82
1058.77	1885.96
1062.93	1249.35
1067.09	858.789
1071.24	779.667
1075.4	872.576
1079.55	1196.43
1083.7	1928.28
1087.85	2692.02
1091.99	2889.02
1096.14	2256.63
1100.28	1821.4
1104.42	2030.16
1108.55	2346.01
1112.69	2329.03
1116.82	1996.58
1120.96	1807.88
1125.09	1899.31
1129.21	2021.82
1133.34	2126.53
1137.46	1704.68
1141.59	1261.16
1145.71	1025.85
1149.83	1188.47
1153.94	1652
1158.06	1889.51
1162.17	1579.62
1166.28	1175.34
1170.39	894.05
1174.5	669.194
1178.6	461.065
1182.7	406.487
1186.8	351.539
1190.9	377.127
1195	319.155
1199.1	399.424
1203.19	331.564
1207.28	310.71
1211.37	283.033
1215.46	309.989
1219.54	457.879
1223.63	591.178
1227.71	488.509
1231.79	482.996
1235.87	641.1
1239.95	835.023
1244.02	732.595
1248.09	520.135
1252.16	463.924
1256.23	310.122
1260.3	233.428
1264.36	246
1268.43	856.233
1272.49	1901.25
1276.55	580.557
1280.6	181.73
1284.66	143.8
1288.71	156.099
1292.76	124.672
1296.81	137.474
1300.86	118.718
1304.91	144.989
1308.95	163.279
1312.99	108.354
1317.03	102.208
1321.07	120.013
1325.11	87.5022
1329.14	89.5852
1333.18	128.023
1337.21	91.8499
1341.24	141.523
1345.26	152.972
1349.29	122.604
1353.31	114.263
1357.33	243.851
1361.35	126.326
1365.37	185.751
1369.39	344.934
1373.4	2162.33
1377.41	2471.6
1381.43	520.042
1385.43	163.019
1389.44	158.714
1393.45	232.035
1397.45	322.552
1401.45	134.858
1405.45	82.314
1409.45	88.0667
1413.44	88.033
1417.44	54.3945
1421.43	70.9839
1425.42	51.4086
1429.41	21.3547
1433.39	40.174
1437.38	75.4846
1441.36	41.7491
1445.34	-12.0941
1449.32	54.4059
1453.3	59.3234
1457.27	24.6759
1461.24	34.833
1465.22	17.0408
1469.19	26.9874
1473.15	41.8779
1477.12	5.3645
1481.09	48.1326
1485.05	34.9207
1489.01	45.1708
1492.97	11.6735
1496.93	44.5397
1500.88	16.3607
1504.83	45.9985
1508.79	45.863
1512.74	47.6757
1516.68	82.6797
1520.63	15.9764
1524.57	53.1934
1528.52	61.5109
1532.46	39.9423
1536.4	46.4924
1540.33	3.68225
1544.27	11.2557
1548.2	44.0336
1552.14	52.473
1556.07	75.1285
1559.99	12.3564
1563.92	38.4556
1567.84	49.8583
1571.77	83.3851
1575.69	27.0632
1579.61	40.1904
1583.52	41.649
1587.44	83.4265
1591.35	9.67468
1595.27	33.1099
1599.18	44.1125
1603.09	54.3879
1606.99	57.1699
1610.9	39.8651
1614.8	85.0948
1618.7	79.615
1622.6	105.759
1626.5	75.8093
1630.39	79.7717
1634.29	27.5979
1638.18	56.8561
1642.07	12.9871
1645.96	57.4836
1649.85	70.5226
1653.73	44.1776
1657.62	88.724
1661.5	120.623
1665.38	68.5643
1669.26	65.1404
1673.13	32.4553
1677.01	82.8894
1680.88	67.9962
1684.75	86.5125
1688.62	61.5828
1692.49	55.4761
1696.35	50.0645
1700.22	64.3135
1704.08	83.8013
1707.94	79.9833
1711.8	76.943
1715.66	92.0055
1719.51	88.1735
1723.37	56.0065
1727.22	83.8834
1731.07	87.1637
1734.92	76.3956
1738.76	103.664
1742.61	59.9449
1746.45	56.2224
1750.29	72.1411
1754.13	7.25549
1757.97	75.5714
1761.81	73.399
1765.64	38.8442
1769.47	47.3286
1773.31	-19.1322
1777.14	63.6239
1780.96	68.8173
1784.79	35.937
1788.61	60.2119
1792.43	13.3669
1796.25	61.2139
1800.07	-0.672974
1803.89	88.1469
1807.71	46.0757
1811.52	70.5654
1815.33	-6.52747
1819.14	31.7054
1822.95	62.9454
1826.76	75.7831
1830.56	65.4354
1834.37	71.6425
1838.17	42.7235
1841.97	74.537
1845.77	64.9148
1849.56	77.4335
1853.36	83.4854
1857.15	89.9006
1860.94	59.5404
1864.73	123.217
1868.52	49.6399
1872.31	55.3488
1876.09	77.9407
1879.87	45.6703
1883.66	84.8713
1887.43	55.4034
1891.21	51.9774
1894.99	71.4139
1898.76	80.3615
1902.53	41.1932
1906.31	59.3462
1910.08	17.2164
1913.84	47.4131
1917.61	66.4698
1921.37	47.4539
1925.14	78.6769
1928.9	34.1155
1932.66	83.4608
1936.41	64.829
1940.17	25.5076
1943.92	80.1248
1947.68	74.9655
1951.43	99.0576
1955.18	50.8274
1958.92	29.713
1962.67	80.7427
1966.41	64.8633
1970.16	100.479
1973.9	26.9192
1977.64	71.053
1981.37	97.952
1985.11	79.5908
1988.84	119.843
1992.57	58.9629
1996.31	38.8378
2000.03	59.2831
2003.76	79.0215
2007.49	108.052
2011.21	72.4323
2014.93	37.5132
2018.65	82.0724
2022.37	48.6703
2026.09	54.9052
2029.81	90.0294
2033.52	67.6748
2037.23	59.3763
2040.94	80.5085
2044.65	29.9211
2048.36	52.1265
2052.07	44.3982
2055.77	29.7026
2059.47	17.588
2063.17	60.375
2066.87	42.7867
2070.57	24.2902
2074.27	127.766
2077.96	68.9261
2081.65	107.202
2085.34	70.9291
2089.03	10.4745
2092.72	84.8702
2096.41	77.027
2100.09	56.0199
2103.77	62.5824
2107.46	91.0933
2111.14	79.4312
2114.81	88.167
2118.49	71.1738
2122.16	109.997
2125.84	76.2731
2129.51	79.2725
2133.18	38.7592
2136.85	109.805
2140.51	89.8887
2144.18	69.8318
2147.84	44.2788
2151.5	101.395
2155.16	95.2583
2158.82	57.2832
2162.48	123.886
2166.13	33.8096
2169.79	115.825
2173.44	103.921
2177.09	53.9707
2180.74	81.6035
2184.38	71.0447
2188.03	47.864
2191.67	44.5298
2195.32	140.344
2198.96	76.0903
2202.6	91.4316
2206.23	78.8596
2209.87	119.676
2213.5	80.1787
2217.14	80.0779
2220.77	82.8323
2224.4	98.5105
2228.03	89.2
2231.65	30.22
2235.28	101.552
2238.9	52.5437
2242.52	65.5403
2246.14	80.4153
2249.76	36.9285
2253.38	83.0525
2256.99	42.5283
2260.6	41.9124
2264.21	107.804
2267.82	116.208
2271.44	96.406
2275.04	45.4927
2278.65	58.7283
2282.25	90.7644
2285.85	91.1929
2289.45	62.8708
2293.05	53.3667
2296.65	77.1384
2300.25	49.6313
2303.84	44.3499
2307.43	57.6748
2311.02	91.5774
2314.62	129.859
2318.2	362.88
2321.79	138.265
2325.38	52.1125
2328.96	72.0508
2332.54	66.9836
2336.12	57.0098
2339.7	51.4871
2343.28	113.369
2346.85	34.2168
2350.43	133.938
2354	94.0442
2357.57	106.354
2361.14	88.7698
2364.71	43.4939
2368.27	83.9907
2371.84	105.182
2375.4	34.6753
2378.96	61.4729
2382.52	73.71
2386.08	41.1636
2389.64	41.2688
2393.19	60.2605
2396.75	-22.6948
2400.3	72.2065
2403.85	33.1904
2407.4	44.9866
2410.95	82.4756
2414.49	2.8418
2418.04	81.6995
2421.58	19.3137
2425.12	10.8196
2428.66	24.948
2432.2	36.7915
2435.74	9.12476
2439.27	17.769
2442.81	48.0266
2446.34	39.3994
2449.87	45.2688
2453.4	34.6038
2456.93	71.906
2460.45	40.4734
2463.98	38.3767
2467.5	-18.7019
2471.02	51.2007
2474.54	39.0413
2478.06	93.6858
2481.58	45.1814
2485.09	39.8064
2488.61	25.0291
2492.12	66.855
2495.63	82.7002
2499.14	43.6426
2502.65	64.6226
2506.15	87.1152
2509.66	45.1123
2513.16	38.0959
2516.66	81.6772
2520.16	44.4419
2523.66	62.1194
2527.16	-37.4623
2530.66	26.8315
2534.15	78.7495
2537.64	54.4858
2541.13	63.4304
2544.62	43.9792
2548.11	52.4316
2551.6	50.1235
2555.08	36.0823
2558.57	54.4778
2562.05	44.9641
2565.53	26.8279
2569.01	19.488
2572.49	72.4614
2575.96	78.3044
2579.44	26.9207
2582.91	68.8564
2586.38	-8.65601
2589.85	26.3401
2593.32	-14.4771
2596.79	34.813
2600.25	61.5547
2603.72	83.6201
2607.18	36.9937
2610.64	51.427
2614.1	60.0754
2617.56	60.281
2621.02	37.9607
2624.47	46.7412
2627.92	66.6958
2631.38	39.1631
2634.83	68.5266
2638.28	56.2688
2641.72	90.3979
2645.17	81.3672
2648.61	71.9424
2652.06	47.7253
2655.5	30.6904
2658.94	58.0454
2662.38	52.8511
2665.82	25.0542
2669.25	63.0198
2672.69	29.7695
2676.12	93.4514
2679.55	52.595
2682.98	33.8806
2686.41	27.7085
2689.84	6.08813
2693.26	56.5447
2696.69	54.3113
2700.11	44.9902
2703.53	50.0503
2706.95	-24.1276
2710.37	44.5508
2713.79	33.6615
2717.2	75.3726
2720.62	36.3671
2724.03	30.1193
2727.44	53.0673
2730.85	75.9403
2734.26	14.537
2737.66	57.1255
2741.07	49.6792
2744.47	43.6649
2747.87	14.1714
2751.28	29.7516
2754.67	59.028
2758.07	29.3005
2761.47	50.7596
2764.86	10.6914
2768.26	38.9767
2771.65	82.2261
2775.04	60.1064
2778.43	68.7443
2781.82	72.48
2785.2	7.45081
2788.59	84.4404
2791.97	46.5244
2795.35	32.3494
2798.73	51.5081
2802.11	25.6569
2805.49	42.9402
2808.87	30.124
2812.24	67.7548
2815.62	77.0951
2818.99	46.5748
2822.36	51.916
2825.73	35.9507
2829.1	79.8666
2832.46	38.454
2835.83	72.8531
2839.19	68.5295
2842.55	41.3457
2845.91	14.7656
2849.27	-9.0343
2852.63	43.2637
2855.99	55.6876
2859.34	42.277
2862.69	31.7261
2866.05	43.7761
2869.4	50.9938
2872.75	21.4979
2876.09	48.3375
2879.44	27.1713
2882.78	75.5743
2886.13	58.7906
2889.47	87.4735
2892.81	56.978
2896.15	42.2506
2899.49	33.8147
2902.82	57.2402
2906.16	-0.849121
2909.49	31.678
2912.82	32.978
2916.16	35.7931
2919.49	28.058
2922.81	33.5175
2926.14	33.8503
2929.46	82.2648
2932.79	96.1621
2936.11	53.4589
2939.43	67.3696
2942.75	51.1565
2946.07	54.8715
2949.39	32.1956
2952.7	47.0605
2956.02	75.3843
2959.33	90.8781
2962.64	60.3352
2965.95	28.4091
2969.26	66.7065
2972.57	82.1343
2975.87	35.5128
2979.17	55.0668
2982.48	42.8263
2985.78	99.2753
2989.08	87.2639
2992.38	65.9421
2995.68	62.6112
2998.97	57.4337
3002.27	128.337
3005.56	92.2253
3008.85	94.7898
3012.14	94.6393
3015.43	87.8342
3018.72	37.598
3022	27.8733
3025.29	53.1233
3028.57	147.356
3031.85	84.7018
3035.14	98.4762
3038.41	72.5555
3041.69	85.4279
3044.97	60.5222
3048.24	85.7249
3051.52	87.3746
3054.79	122.171
3058.06	91.2941
3061.33	97.8636
3064.6	93.2367
3067.87	113.008
3071.13	144.455
3074.4	93.5225
3077.66	131.741
3080.92	119.892
3084.18	102.746
3087.44	112.537
3090.7	86.6744
3093.95	94.9082
3097.21	161.403
3100.46	123.339
3103.71	103.965
3106.96	138.928
3110.21	141.899
3113.46	148.626
3116.71	101.178
3119.95	122.307
3123.2	140.568
3126.44	128.286
3129.68	139.839
3132.92	154.23
3136.16	203.797
3139.4	165.615
3142.63	179.859
3145.87	164.655
3149.1	210.566
3152.33	213.505
3155.56	215.523
3158.79	217.5
3162.02	190.855
3165.25	216.557
3168.47	187.698
3171.69	199.785
3174.92	276.591
3178.14	277.935
3181.36	246.907
3184.58	234.784
3187.79	295.009
3191.01	230.341
3194.22	256.203
3197.43	309.615
3200.65	296.409
3203.86	331.835
3207.07	278.837
3210.27	297.353
3213.48	295.102
3216.69	257.692
3219.89	288.819
3223.09	329.659
3226.29	294.47
3229.49	290.853
3232.69	322.302
3235.89	325.57
3239.08	283.349
3242.28	368.859
3245.47	303.89
3248.66	324.842
3251.85	319.211
3255.04	365.13
3258.23	357.375
3261.42	354.083
3264.6	349.521
3267.79	381.97
3270.97	350.245
3274.15	380.615
3277.33	333.274
3280.51	368.548
3283.68	400.919
3286.86	351.054
3290.04	367.147
3293.21	360.34
3296.38	389.64
3299.55	394.73
3302.72	403.247
3305.89	393.421
3309.06	413.689
3312.22	375.803
3315.39	378.727
3318.55	417.589
3321.71	443.128
3324.87	402.388
3328.03	425.111
3331.19	479.114
3334.34	459.572
3337.5	486.503
3340.65	467.194
3343.81	486.989
3346.96	420.716
3350.11	498.705
3353.25	387.466
3356.4	488.414
3359.55	447.311
3362.69	509.999
3365.84	488.893
3368.98	481.049
3372.12	500.833
3375.26	514.145
3378.4	581.485
3381.53	559.909
3384.67	586.717
3387.8	661.86
3390.94	656.73
3394.07	652.532
3397.2	749.979
3400.33	792.995
3403.46	933.202
3406.58	1100.49
3409.71	1490.94
3412.83	2204.29
3415.96	4094.67
3419.08	8539.1
3422.2	11855.1
3425.32	8257.48
3428.44	3891.8
3431.55	1988.84
3434.67	1330.06
3437.78	1052.65
3440.89	900.509
3444	763.13
3447.12	740.232
3450.22	677.889
3453.33	675.596
3456.44	654.868
3459.54	617.927
3462.65	665.525
3465.75	605.57
3468.85	622.781
3471.95	649.166
3475.05	729.688
3478.15	752.518
3481.24	801.833
3484.34	902.232
3487.43	1066.93
3490.53	1272.96
3493.62	1611.1
3496.71	2116.58
3499.79	2565.52
3502.88	2956.69
3505.97	2858.88
3509.05	2430.13
3512.14	1881.19
3515.22	1464.72
3518.3	1157.26
3521.38	934.146
3524.46	820.977
3527.54	664.655
3530.61	616.474
3533.69	559.498
3536.76	471.933
3539.83	401.908
3542.9	428.141
3545.97	375.963
3549.04	401.87
3552.11	348.912
3555.18	339.739
3558.24	323.199
3561.3	303.347
3564.37	324.065
3567.43	264.313
3570.49	305.662
3573.55	303.178
3576.61	295.872
3579.66	259.955
3582.72	263.699
3585.77	235.149
3588.82	234.877
3591.87	218.396
3594.92	244.428
3597.97	219.252
3601.02	194.906
3604.07	199.762
3607.11	231.049
3610.16	201.733
3613.2	188.428
3616.24	183.675
3619.28	205.43
3622.32	185.733
3625.36	156.74
3628.39	168.252
3631.43	134.436
3634.46	133.88
3637.5	123.27
3640.53	162.717
3643.56	125.444
3646.59	123.66
3649.62	127.742
3652.64	112.102
3655.67	145.739
3658.69	130.533
3661.72	105.646
3664.74	121.472
3667.76	65.7355
3670.78	62.9341
3673.79	51.7244
3676.81	75.5476
3679.83	53.0503
3682.84	52.2589
3685.86	60.967
3688.87	46.0664
3691.88	79.5104
3694.89	11.2991
3697.9	61.7406
3700.91	26.9291
3703.91	53.7987
3706.92	89.1077
3709.92	53.0117
3712.92	52.8212
3715.92	45.0686
3718.92	39.0959
3721.92	65.3431
3724.92	12.4191
3727.92	6.98621
3730.91	65.2209
3733.91	16.6287
3736.9	16.4655
3739.89	28.4988
3742.88	33.725
3745.87	6.47314
3748.86	54.1891
3751.85	52.4148
3754.83	1.33057
3757.82	53.6761
3760.8	30.0145
3763.78	30.0532
3766.76	8.42212
3769.74	40.8726
3772.72	34.6541
3775.7	0.186401
3778.67	0.805786
3781.65	36.4043
3784.62	52.228
3787.6	27.5354
3790.57	-6.3728
3793.54	-2.36853
3796.51	62.1346
3799.47	30.5457
3802.44	41.5516
3805.41	25.2163
3808.37	27.8574
3811.33	50.4052
3814.3	55.9813
3817.26	29.4521
3820.22	7.66406
3823.18	19.104
3826.13	41.025
3829.09	18.3763
3832.04	20.4825
3835	33.1371
3837.95	8.7666
3840.9	30.9448
3843.85	4.63403
3846.8	42.1471
3849.75	22.6091
3852.69	-7.41492
3855.64	42.7373
3858.58	21.3234
3861.53	62.928
3864.47	44.2792
3867.41	40.8236
3870.35	73.7356
3873.29	41.3994
3876.22	49.1978
3879.16	39.5593
3882.1	8.59241
3885.03	41.8765
3887.96	22.2269
3890.89	21.7483
3893.82	4.76489
3896.75	83.7574
3899.68	21.3511
3902.61	24.1302
3905.53	53.0037
3908.46	27.9774
3911.38	11.4832
3914.3	16.9193
3917.23	36.0599
3920.15	-11.2283
3923.06	36.33
3925.98	15.6168
3928.9	-4.25488
3931.81	4.89001
3934.73	37.2974
3937.64	35.5602
3940.55	49.0601
3943.46	8.00818
3946.37	49.4274
3949.28	40.2272
3952.19	46.4009
3955.09	23.0067
3958	53.3344
3960.9	66.4918
3963.8	3.9895
3966.71	24.0046
3969.61	46.974
3972.51	40.1876
3975.4	49.6498
3978.3	25.3766
3981.2	36.6243
3984.09	29.5349
3986.99	26.2853
3989.88	28.5688
3992.77	29.1597
3995.66	35.5347
3998.55	3.46741
4001.43	33.0281