File: Data/3-Raman/processed/bu19(2)w-a-ff2-fi01-v_1800 (450-850nm)_532nm_edge_100%_x100_vis_lwd_h100um_30sx2_01.txt
#Acq. time (s)=	30
#Accumulations=	2
#Range (cm-¹)=	1200...2365
#Windows=	3
#Auto scanning=	Off
#Autofocus=	Off
#Macrospot=	Off
#AutoExposure=	Off
#Spike filter=	Multiple accum.
#Delay time (s)=	2
#Binning=	1
#Readout mode=	Signal
#DeNoise=	Off
#ICS correction=	On
#Dark correction=	Off
#Inst. Process=	Off
#Detector Gain=	Best Dynamic
#Detector ADC=	50 kHz HS
#Detector temperature (°C)=	-60.09
#Instrument=	LabRAM HR Evol
#Detector=	SIN-EM FIVIS
#Objective=	x100_VIS_LWD
#Grating=	1800 (450-850nm)
#ND Filter=	100%
#Laser=	532nm_Edge
#Hole=	100.021
#Temperature=	0
#Range=	Visible
#StageXY=	75x50mm Scan+
#StageZ=	Z motor
#X (µm)=	0
#Y (µm)=	0
#Z (µm)=	12.5
#Full time(mm:ss)=	3:23
#Project=	21_11_26
#Sample=	BU19(2)w
#Site=
#Title=	BU19(2)w-A-FF2-FI01-V_1800 (450-850nm)_532nm_Edge_100%_x100_VIS_LWD_H100um_30sX2
#Remark=
#Date=	26.11.2021 14:18
#Acquired=	26.11.2021 14:18:21
#Base:Fit=	16.12.2021 16:00:56
#Base:Fit=	16.12.2021 16:10:48
#Base:Sub=	16.12.2021 16:10:49
1202.72	-4.49313
1203.84	-0.676079
1204.95	-4.54476
1206.06	7.58506
1207.17	8.87126
1208.28	2.71293
1209.39	-2.39959
1210.5	1.06538
1211.61	5.45029
1212.72	-1.91778
1213.83	4.58323
1214.94	3.67667
1216.05	-2.58849
1217.16	-1.55124
1218.27	-5.82079
1219.38	5.85307
1220.49	-1.58153
1221.6	-9.02451
1222.71	-4.91666
1223.81	-6.17672
1224.92	1.05706
1226.03	-1.11916
1227.14	-12.838
1228.25	5.82356
1229.35	-5.05001
1230.46	-2.82709
1231.57	0.959
1232.67	-1.30434
1233.78	6.90444
1234.89	1.50535
1235.99	-4.95264
1237.1	3.22987
1238.2	4.98454
1239.31	3.59134
1240.41	1.22989
1241.52	2.05343
1242.62	5.96521
1243.73	7.84854
1244.83	9.69319
1245.94	14.5734
1247.04	20.5312
1248.14	20.2414
1249.25	14.6806
1250.35	12.3221
1251.45	15.0893
1252.56	21.0041
1253.66	21.6956
1254.76	28.8091
1255.87	35.8754
1256.97	48.1765
1258.07	78.1621
1259.17	63.1976
1260.27	73.4933
1261.37	154.416
1262.48	255.1
1263.58	273.705
1264.68	152.281
1265.78	81.7757
1266.88	61.6886
1267.98	46.9778
1269.08	63.7178
1270.18	53.0257
1271.28	44.2918
1272.38	57.7073
1273.47	61.8943
1274.57	68.1559
1275.67	67.9896
1276.77	71.0922
1277.87	106.79
1278.97	173.073
1280.07	319.177
1281.16	919.659
1282.26	3180.15
1283.36	4964.02
1284.45	1791.37
1285.55	428.568
1286.65	184.079
1287.75	114.38
1288.84	95.2819
1289.94	81.6248
1291.03	64.7439
1292.13	56.2266
1293.22	39.3038
1294.32	38.376
1295.42	42.583
1296.51	34.4104
1297.61	33.3038
1298.7	40.5946
1299.79	32.0576
1300.89	25.7616
1301.98	17.3376
1303.08	20.5539
1304.17	8.91119
1305.26	9.98557
1306.35	12.0315
1307.45	11.0011
1308.54	10.011
1309.63	4.83611
1310.73	0.705887
1311.82	-3.41775
1312.91	3.05792
1314	2.06453
1315.09	-0.986382
1316.18	5.52066
1317.28	-3.88103
1318.37	-2.66172
1319.46	-3.57531
1320.55	2.91034
1321.64	7.20918
1322.73	-0.117516
1323.82	3.1758
1324.91	-4.02328
1326	-6.016
1327.09	17.1526
1328.18	4.91667
1329.27	10.5309
1330.35	0.177788
1331.44	1.36055
1332.53	1.43117
1333.62	3.62368
1334.71	7.93948
1335.79	11.2376
1336.88	11.417
1337.97	4.29167
1339.06	14.9424
1340.14	1.59383
1341.23	6.06699
1342.32	-2.06882
1343.4	0.22139
1344.49	0.503891
1345.58	10.1611
1346.66	8.21828
1347.75	6.30782
1348.83	7.61237
1349.92	13.0595
1351	11.2116
1352.09	9.37556
1353.17	12.8978
1354.25	18.5554
1355.34	15.503
1356.42	18.952
1357.51	21.3193
1358.59	23.6711
1359.67	32.2381
1360.76	17.9674
1361.84	24.5089
1362.92	36.2187
1364	55.2765
1365.09	54.6058
1366.17	48.6432
1367.25	45.7631
1368.33	116.428
1369.41	179.938
1370.5	43.8088
1371.58	56.4744
1372.66	58.7093
1373.74	64.1507
1374.82	75.829
1375.9	76.2206
1376.98	94.0479
1378.06	93.3524
1379.14	117.767
1380.22	143.826
1381.3	177.685
1382.38	233.285
1383.46	348.121
1384.54	714.294
1385.61	2469.25
1386.69	10850.5
1387.77	4336.95
1388.85	823.201
1389.93	343.854
1391	219.548
1392.08	144.923
1393.16	126.728
1394.23	104.545
1395.31	87.5507
1396.39	83.9226
1397.46	84.2483
1398.54	74.3955
1399.62	74.8736
1400.69	80.4571
1401.77	89.1365
1402.84	79.5497
1403.92	96.5364
1404.99	123.494
1406.07	192.463
1407.14	328.088
1408.22	563.4
1409.29	388.619
1410.37	161.398
1411.44	93.9212
1412.51	53.304
1413.59	40.707
1414.66	44.0415
1415.73	27.0381
1416.81	21.3021
1417.88	29.9589
1418.95	33.4506
1420.02	28.6739
1421.1	24.87
1422.17	18.0722
1423.24	34.0806
1424.31	33.0767
1425.38	27.3045
1426.45	15.397
1427.52	15.6804
1428.59	16.9895
1429.67	15.3342
1430.74	10.649
1431.81	18.3014
1432.87	13.4813
1433.95	0.395935
1435.01	13.0699
1436.08	-1.94965
1437.15	18.8643
1438.22	7.92068
1439.29	10.3388
1440.36	0.483994
1441.43	5.96656
1442.49	4.2404
1443.56	-0.560173
1444.63	13.0799
1445.7	3.20713
1446.77	-4.70066
1447.83	-0.305538
1448.9	2.07998
1449.97	-2.7471
1451.03	7.77958
1452.1	2.93473
1453.17	1.18279
1454.23	-3.63289
1455.3	0.755558
1456.36	5.16136
1457.43	-0.727303
1458.49	-5.57588
1459.56	8.03398
1460.62	7.27581
1461.69	1.37418
1462.75	-3.5172
1463.82	-3.30362
1464.88	3.16553
1465.94	-4.93093
1467.01	-6.7343
1468.07	-0.370625
1469.13	-2.17067
1470.2	-2.98337
1471.26	-9.9038
1472.32	0.489613
1473.39	-8.44974
1474.45	-4.17387
1475.51	4.20512
1476.57	0.33609
1477.63	-3.54162
1478.69	-0.296169
1479.76	-7.23375
1480.82	-5.05038
1481.88	0.208218
1482.94	2.48233
1484	-3.40046
1485.06	1.74827
1486.12	-0.104103
1487.18	4.14339
1488.24	-7.85696
1489.3	-6.70438
1490.36	-4.51743
1491.42	-6.39405
1492.48	0.848701
1493.53	-2.0243
1494.59	-1.86227
1495.65	3.3279
1496.71	0.398216
1497.77	-1.48258
1498.82	-1.3355
1499.88	-2.1859
1500.94	0.990486
1502	-1.91938
1503.05	-8.86444
1504.11	1.32868
1505.17	-6.60262
1506.22	5.57129
1507.28	2.67755
1508.34	-0.224316
1509.39	0.901703
1510.45	-0.990902
1511.5	2.09333
1512.56	6.11215
1513.61	2.13531
1514.67	-1.74508
1515.72	2.32374
1516.78	5.37715
1517.83	3.45581
1518.88	6.577
1519.94	4.67451
1520.99	2.74537
1522.05	-1.17589
1523.1	2.8927
1524.15	-1.10162
1525.2	2.95519
1526.26	-1.95987
1527.31	-2.86697
1528.36	3.19183
1529.41	-3.77744
1530.47	2.27702
1531.52	6.37889
1532.57	2.41784
1533.62	0.522942
1534.67	-1.42452
1535.72	1.60767
1536.77	2.58033
1537.82	0.564144
1538.87	3.57175
1539.92	3.69314
1540.97	-3.19776
1542.02	-3.19426
1543.07	1.79519
1544.12	3.76379
1545.17	-4.17913
1546.22	-0.100662
1547.27	-2.06955
1548.32	0.930424
1549.37	-1.08211
1550.42	8.96439
1551.46	4.13792
1552.51	5.15767
1553.56	4.12436
1554.61	7.10137
1555.65	3.05082
1556.7	3.05292
1557.75	1.06286
1558.79	2.02452
1559.84	10.9642
1560.89	6.93508
1561.93	1.94661
1562.98	-1.02786
1564.02	-1.04203
1565.07	11.0012
1566.11	4.64791
1567.16	3.87569
1568.2	3.90872
1569.25	-1.0888
1570.29	3.87006
1571.34	-2.14159
1572.38	-3.1786
1573.43	2.76493
1574.47	3.73982
1575.51	0.777534
1576.56	8.75949
1577.6	5.67274
1578.64	2.59342
1579.69	-1.42101
1580.73	0.564529
1581.77	-2.47428
1582.81	-0.535477
1583.85	-4.55622
1584.9	0.399185
1585.94	3.35635
1586.98	7.26633
1588.02	4.22933
1589.06	1.23278
1590.1	-2.76061
1591.14	1.2055
1592.18	-1.82529
1593.22	-3.89515
1594.26	-2.01209
1595.3	8.89219
1596.34	-1.09583
1597.38	3.84147
1598.42	4.80217
1599.46	1.73776
1600.5	-0.319302
1601.54	7.51312
1602.58	-1.49262
1603.62	-1.57488
1604.66	2.33089
1605.69	-2.646
1606.73	3.27437
1607.77	-4.45248
1608.81	-0.506424
1609.84	2.54163
1610.88	6.19046
1611.92	-2.88895
1612.95	-2.89635
1613.99	1.9133
1615.03	5.46372
1616.06	0.458588
1617.1	1.77202
1618.13	1.85844
1619.17	2.49207
1620.2	2.58847
1621.24	0.398369
1622.27	2.91074
1623.31	1.17664
1624.34	2.46573
1625.38	-0.432438
1626.41	-2.52319
1627.45	-0.919334
1628.48	1.36221
1629.51	-0.603462
1630.55	0.755497
1631.53	-0.89513
1632.57	3.03011
1633.62	1.01753
1634.66	-0.979412
1635.71	-2.99132
1636.75	1.87928
1637.8	1.81548
1638.84	-0.203629
1639.89	4.68264
1640.93	2.6874
1641.98	1.6682
1643.02	3.59257
1644.06	1.58215
1645.11	-0.439606
1646.15	0.525692
1647.19	2.44224
1648.24	0.427483
1649.28	-2.51368
1650.32	5.32861
1651.37	1.40551
1652.41	-1.57125
1653.45	3.31494
1654.49	0.340748
1655.53	-0.652504
1656.57	1.34267
1657.62	-3.61845
1658.66	2.25946
1659.7	-0.753716
1660.74	1.18564
1661.78	2.18305
1662.82	-3.71177
1663.86	2.19807
1664.9	-1.80746
1665.94	-4.84771
1666.98	1.10927
1668.02	1.06161
1669.06	-2.897
1670.1	-1.89624
1671.14	-1.8812
1672.18	-3.88476
1673.21	0.0562439
1674.25	3.01701
1675.29	0.0617638
1676.33	0.0573235
1677.37	-5.89162
1678.4	-0.98011
1679.44	-0.0362434
1680.48	4.87434
1681.52	-1.08392
1682.55	0.878922
1683.59	4.81601
1684.63	-3.10876
1685.66	-0.164967
1686.7	-1.15693
1687.73	0.82169
1688.77	-0.194984
1689.81	-5.1696
1690.84	-4.20081
1691.88	-4.19068
1692.91	-2.22765
1693.95	-2.2775
1694.98	-4.28612
1696.01	0.643013
1697.05	1.63963
1698.08	0.612988
1699.12	-2.37407
1700.15	-3.36087
1701.18	4.49726
1702.22	-0.445553
1703.25	-1.45684
1704.28	0.497684
1705.32	1.49214
1706.35	0.501328
1707.38	4.38465
1708.41	-6.45417
1709.44	-1.60501
1710.48	-4.54718
1711.51	1.34933
1712.54	3.31729
1713.57	-0.665356
1714.6	-0.707695
1715.63	0.276707
1716.66	-0.69289
1717.69	1.20732
1718.72	-1.78593
1719.75	-1.79373
1720.78	1.13514
1721.81	3.04897
1722.84	0.0946045
1723.87	-0.900257
1724.9	0.0679779
1725.93	0.0142479
1726.96	-3.86663
1727.99	2.91536
1729.02	3.7956
1730.05	-0.105545
1731.07	-2.04943
1732.1	-0.047451
1733.13	-1.98392
1734.16	4.72471
1735.18	-3.99681
1736.21	-0.171642
1737.24	0.785507
1738.26	4.62103
1739.29	6.5148
1740.32	5.49051
1741.34	5.44738
1742.37	1.59926
1743.4	2.56037
1744.42	3.51106
1745.45	1.60699
1746.47	2.56435
1747.5	4.44093
1748.52	1.56639
1749.55	3.50796
1750.57	5.48149
1751.6	1.70146
1752.62	3.58651
1753.64	-0.252651
1754.67	2.59327
1755.69	1.6353
1756.71	1.61357
1757.74	0.63308
1758.76	3.52549
1759.78	4.50459
1760.81	-0.243889
1761.83	5.45261
1762.85	1.66883
1763.87	10.2551
1764.89	6.51513
1765.92	6.56236
1766.94	0.869724
1767.96	11.3467
1768.98	6.58863
1770	9.36298
1771.02	7.5161
1772.04	11.388
1773.06	8.5907
1774.08	8.63832
1775.1	8.67967
1776.12	7.80368
1777.14	6.87335
1778.16	0.19416
1779.18	4.93662
1780.2	3.999
1781.22	-0.72118
1782.24	3.124
1783.26	1.27402
1784.28	0.367764
1785.29	9.00889
1786.31	7.10889
1787.33	1.43056
1788.35	3.45588
1789.37	1.63577
1790.38	6.49287
1791.4	2.67385
1792.42	-0.216373
1793.43	6.52502
1794.45	-3.02524
1795.47	4.70655
1796.48	-1.93722
1797.5	-0.921509
1798.51	3.92854
1799.53	-2.78647
1800.55	4.88964
1801.56	3.93293
1802.58	3.00113
1803.59	-1.75228
1804.61	-1.71407
1805.62	-3.58401
1806.64	1.28501
1807.65	-3.50391
1808.66	-5.4123
1809.68	0.394192
1810.69	-7.2968
1811.7	0.426239
1812.72	1.41324
1813.73	1.45338
1814.74	-2.35108
1815.76	-4.23607
1816.77	2.55379
1817.78	2.53867
1818.79	0.627445
1819.8	2.58753
1820.82	1.65556
1821.83	-1.21105
1822.84	-1.18048
1823.85	5.60686
1824.86	-1.15628
1825.87	1.77592
1826.88	4.6945
1827.89	-0.124912
1828.9	3.75795
1829.91	-0.122635
1830.92	-2.06846
1831.93	-0.106644
1832.94	-1.04111
1833.95	0.917114
1834.96	1.86138
1835.97	-0.139282
1836.98	1.97506
1837.99	0.862968
1839	7.63837
1840	3.8395
1841.01	0.845013
1842.02	3.66012
1843.03	1.69143
1844.04	-3.12941
1845.04	1.69711
1846.05	-1.1825
1847.06	-0.172333
1848.07	-2.25213
1849.07	-5.13246
1850.08	3.49479
1851.09	-3.29247
1852.09	-1.40099
1853.1	0.514904
1854.1	-2.38547
1855.11	3.31977
1856.11	-1.52012
1857.12	-0.572796
1858.12	1.32096
1859.13	0.321144
1860.13	-7.3644
1861.14	3.16693
1862.14	1.27346
1863.15	-4.502
1864.15	-1.67863
1865.15	1.14547
1866.16	2.98529
1867.16	-3.76894
1868.16	3.77603
1869.17	1.85953
1870.17	-3.86235
1871.17	1.8226
1872.17	3.69417
1873.18	1.75392
1874.18	-1.12424
1875.18	-0.228989
1876.18	0.638744
1877.18	2.46839
1878.18	1.44152
1879.19	-3.22484
1880.19	-0.364765
1881.19	-2.27834
1882.19	-3.3023
1883.19	2.25367
1884.19	-1.58315
1885.19	2.19464
1886.19	4.12739
1887.19	0.327869
1888.19	4.03848
1889.19	-6.4064
1890.19	-1.74038
1891.19	2.97788
1892.18	-4.58523
1893.18	0.0836372
1894.18	-3.76566
1895.18	2.77103
1896.18	-1.93232
1897.18	2.77799
1898.17	0.88871
1899.17	2.72044
1900.17	-2.03188
1901.16	-0.176128
1902.16	2.65784
1903.16	-0.16795
1904.16	-0.208084
1905.15	-0.238888
1906.15	4.41843
1907.14	-2.21436
1908.14	5.28119
1909.14	4.33985
1910.13	1.54021
1911.13	-3.13472
1912.12	2.50483
1913.12	5.29746
1914.11	0.585464
1915.11	1.54903
1916.1	-4.12029
1917.1	3.37843
1918.09	6.1564
1919.08	1.44806
1920.08	4.32258
1921.07	6.19548
1922.06	2.42912
1923.06	0.50433
1924.05	2.34824
1925.04	-0.536591
1926.04	-0.532112
1927.03	-1.45398
1928.02	-7.13565
1929.01	-2.4088
1930	-2.39997
1931	-1.43082
1931.99	-0.513905
1932.98	-1.51673
1933.97	0.361019
1934.96	-6.19269
1935.95	-2.31681
1936.94	2.37729
1937.93	-4.35792
1938.92	1.32423
1939.91	-5.34445
1940.9	2.2827
1941.89	1.34571
1942.88	-2.47976
1943.87	1.28286
1944.86	3.19913
1945.85	-0.602619
1946.84	1.31369
1947.83	-1.58993
1948.82	-0.666927
1949.8	-3.53479
1950.79	1.28947
1951.78	-0.582287
1952.77	-3.45266
1953.76	2.2889
1954.74	-0.718243
1955.73	0.188957
1956.72	-3.59598
1957.7	4.10401
1958.69	1.22057
1959.68	-6.5081
1960.66	-1.75283
1961.65	0.109272
1962.63	-0.874802
1963.62	2.94717
1964.61	-3.78376
1965.59	-1.8934
1966.58	1.94935
1967.56	1.94854
1968.55	9.62434
1969.53	4.76532
1970.52	-2.99493
1971.5	6.5483
1972.48	1.72827
1973.47	0.735649
1974.45	-3.15152
1975.44	6.416
1976.42	3.54477
1977.4	11.2008
1978.39	3.47982
1979.37	4.40115
1980.35	6.30243
1981.33	6.25318
1982.31	7.17144
1983.3	9.99015
1984.28	7.06142
1985.26	14.6663
1986.24	11.7601
1987.22	9.8505
1988.21	5.96862
1989.19	16.209
1990.17	13.2926
1991.15	7.95885
1992.13	12.305
1993.11	11.4615
1994.09	13.8393
1995.07	15.7345
1996.05	13.4507
1997.03	15.1301
1998.01	17.779
1998.99	15.6473
1999.97	16.4881
2000.95	13.6214
2001.92	15.6177
2002.9	18.5193
2003.88	16.3823
2004.86	17.249
2005.84	18.7234
2006.81	17.9909
2007.79	15.3992
2008.77	20.7172
2009.75	18.25
2010.73	18.0232
2011.7	15.671
2012.68	19.1049
2013.67	21.858
2014.66	17.0591
2015.64	17.9764
2016.63	16.1305
2017.62	18.0557
2018.61	17.9778
2019.6	16.9539
2020.58	15.9976
2021.57	14.1336
2022.56	15.9981
2023.55	8.4662
2024.54	12.1691
2025.52	14.9043
2026.51	1.80777
2027.5	10.3558
2028.48	6.56723
2029.47	9.46617
2030.45	10.2479
2031.44	10.2849
2032.43	12.1743
2033.41	8.52217
2034.4	4.80409
2035.38	7.54387
2036.37	11.4116
2037.35	10.4761
2038.34	8.60748
2039.32	3.92052
2040.31	13.2313
2041.29	1.07028
2042.27	3.86438
2043.26	2.93169
2044.24	3.93896
2045.23	6.7276
2046.21	4.98427
2047.19	5.89335
2048.17	-0.673546
2049.16	0.292042
2050.14	5.03166
2051.12	1.35506
2052.11	0.419083
2053.09	7.9304
2054.07	0.53064
2055.05	6.18293
2056.03	0.574669
2057.01	1.52126
2058	2.49361
2058.98	-1.18642
2059.96	4.47837
2060.94	3.55288
2061.92	3.60053
2062.9	0.830875
2063.88	-4.73498
2064.86	2.80972
2065.84	0.0690155
2066.82	4.82166
2067.8	-3.58139
2068.78	1.16817
2069.76	1.18796
2070.73	2.15549
2071.71	-0.603176
2072.69	-0.510502
2073.67	0.456688
2074.65	3.32629
2075.63	-0.353634
2076.6	2.55959
2077.58	-4.03326
2078.56	1.65235
2079.54	3.6004
2080.51	-1.98623
2081.49	1.8279
2082.47	1.86414
2083.45	0.961834
2084.42	-2.78405
2085.4	0.0898514
2086.37	1.08665
2087.35	0.212128
2088.32	-4.46962
2089.3	-4.42487
2090.28	-3.41314
2091.25	1.37619
2092.23	-0.447899
2093.2	-2.25499
2094.18	-1.22672
2095.15	-1.17911
2096.13	-2.1128
2097.1	1.71607
2098.07	-2.0683
2099.05	-5.83448
2100.02	-1.05457
2101	-1.9552
2101.97	0.960064
2102.94	4.79656
2103.92	1.96604
2104.89	1.06641
2105.86	-1.71331
2106.83	-1.65386
2107.8	-1.61021
2108.78	0.290737
2109.75	3.18164
2110.72	-0.567093
2111.69	0.421101
2112.66	-1.44944
2113.63	0.51519
2114.61	-0.387108
2115.58	-4.1472
2116.55	0.627308
2117.52	0.652943
2118.49	0.678371
2119.46	-1.21851
2120.43	-1.2069
2121.4	-4.9474
2122.37	-3.92503
2123.34	0.884331
2124.31	2.82106
2125.28	-0.986839
2126.25	0.892227
2127.21	-0.0503349
2128.18	0.919029
2129.15	-2.82823
2130.12	-2.79677
2131.09	-1.82253
2132.06	-0.860291
2133.02	-4.61874
2133.99	-2.69281
2134.96	-1.70732
2135.93	-3.56324
2136.89	-4.50091
2137.86	-0.682827
2138.83	-1.60093
2139.79	4.10364
2140.76	-0.605236
2141.73	-2.46096
2142.69	-4.32529
2143.66	-2.37621
2144.62	-0.533035
2145.59	-0.494164
2146.55	-1.40487
2147.52	3.31431
2148.48	4.26868
2149.45	3.33878
2150.42	-5.11432
2151.38	0.5364
2152.34	0.590954
2153.31	1.54937
2154.27	-3.1232
2155.24	-4.07694
2156.2	3.38493
2157.16	0.599545
2158.13	3.45166
2159.09	-4.92178
2160.05	-3.97606
2161.01	2.55562
2161.98	1.63859
2162.94	0.733883
2163.9	1.67896
2164.86	0.74765
2165.83	-1.0873
2166.79	1.72873
2167.75	0.796051
2168.71	3.55736
2169.67	-1.97956
2170.63	2.7496
2171.59	-0.958992
2172.56	1.79175
2173.51	3.66098
2174.48	2.76878
2175.44	-4.64029
2176.4	5.59752
2177.36	3.74998
2178.32	-0.869091
2179.28	-2.72573
2180.23	-2.70108
2181.19	-5.47037
2182.15	-1.74761
2183.11	1.04254
2184.07	1.02603
2185.03	-1.74647
2185.99	4.7754
2186.95	-1.66422
2187.9	-5.31987
2188.86	-5.3159
2189.82	-2.55162
2190.78	0.230854
2191.73	2.11068
2192.69	-1.56941
2193.65	1.25266
2194.6	-1.46239
2195.56	0.407513
2196.52	4.09656
2197.47	0.3601
2198.43	-1.48224
2199.38	3.21622
2200.34	6.07885
2201.3	0.576744
2202.25	0.458992
2203.21	3.32766
2204.16	3.48873
2205.12	1.55853
2206.07	2.4022
2207.03	4.26712
2207.98	-0.3494
2208.93	-2.17212
2209.89	5.29775
2210.84	1.5911
2211.8	3.48842
2212.75	5.38841
2213.7	1.64627
2214.66	2.60468
2215.61	-1.09758
2216.56	1.7108
2217.51	-1.08975
2218.47	0.784462
2219.42	-2.92992
2220.37	-0.103962
2221.32	0.825909
2222.27	3.59383
2223.23	-2.93665
2224.18	0.833633
2225.13	0.877316
2226.08	-3.7651
2227.03	0.949917
2227.98	0.0346069
2228.93	0.0261726
2229.88	0.0290451
2230.83	1.93998
2231.78	0.0974121
2232.73	2.00782
2233.68	-1.72617
2234.63	0.169926
2235.58	-0.799667
2236.53	-1.74624
2237.48	1.08929
2238.43	-0.74144
2239.38	1.18914
2240.33	-2.60147
2241.27	-0.700527
2242.22	0.251503
2243.17	-0.681324
2244.12	2.13267
2245.07	0.260414
2246.01	-2.53142
2246.96	-3.45533
2247.91	-0.602711
2248.85	-4.39755
2249.8	-2.50672
2250.75	0.321823
2251.69	-1.60143
2252.64	-2.54064
2253.59	-4.38584
2254.53	-1.51338
2255.48	0.384354
2256.42	1.34035
2257.37	-2.43087
2258.32	-2.41576
2259.26	0.444401
2260.2	-1.44117
2261.15	-0.475555
2262.1	-3.30779
2263.04	2.42097
2263.98	1.51306
2264.93	0.613472
2265.87	-2.2277
2266.81	-0.337105
2267.76	-1.32183
2268.7	0.561729
2269.65	3.44885
2270.59	-3.18666
2271.53	-3.16168
2272.47	0.684708
2273.42	-0.264706
2274.36	4.5294
2275.3	-2.16123
2276.24	0.721142
2277.18	-1.15886
2278.13	-3.02765
2279.07	-0.12096
2280.01	-2.06639
2280.95	0.776569
2281.89	-2.11427
2282.83	-3.05127
2283.77	-1.08738
2284.71	3.78541
2285.65	-3.88199
2286.59	-5.82206
2287.54	-0.00463867
2288.47	8.68821
2289.41	8.65645
2290.35	-1.97368
2291.29	-2.92704
2292.23	-1.92324
2293.17	4.85642
2294.11	-3.79014
2295.05	1.97804
2295.99	5.81375
2296.93	-2.87358
2297.86	1.0073
2298.8	1.05392
2299.74	-1.79813
2300.68	4.0002
2301.61	2.10088
2302.55	-0.787163
2303.49	2.11223
2304.43	-0.763821
2305.36	2.16599
2306.3	-0.708675
2307.24	3.17347
2308.17	4.13578
2309.11	-1.65725
2310.04	-0.648251
2310.98	1.30781
2311.92	-3.57354
2312.85	-0.70129
2313.79	-2.61217
2314.72	2.27574
2315.66	-0.591507
2316.59	-0.630123
2317.52	2.26063
2318.46	6.13904
2319.39	3.22402
2320.33	6.1132
2321.26	9.99352
2322.2	11.9743
2323.13	12.9795
2324.06	14.9326
2325	30.3893
2325.93	72.8072
2326.86	267.616
2327.79	722.414
2328.73	198.879
2329.66	60.0224
2330.59	25.3414
2331.52	9.92339
2332.46	8.00919
2333.39	3.16469
2334.32	3.14183
2335.25	5.0323
2336.18	2.14182
2337.11	3.08584
2338.04	4.02921
2338.97	4.97152
2339.91	0.154396
2340.84	3.00129
2341.77	2.93562
2342.7	2.885
2343.63	3.81593
2344.56	-0.0411453
2345.49	-1.03067
2346.41	0.82798
2347.34	2.70276
2348.27	-0.202648
2349.2	3.59647
2350.13	-0.330051
2351.06	2.30313
2351.99	-1.3998
2352.91	3.26649
2353.84	2.20205
2354.77	1.19601
2355.7	-1.7185
2356.63	0.0970078
2357.55	3.78635
2358.48	-0.109856
2359.41	0.746861
2360.33	0.644608
2361.26	-5.16813
2362.19	2.28909
2363.11	4.04726
2364.04	-0.807835
2364.97	2.84757