File: Data/3-Raman/processed/bu19w-e-ff11b-fi04-l_150 (500nm)_532nm_edge_100%_x100_vis_h50um_30sx2_01_0.txt
#Acq. time (s)=	30
#Accumulations=	2
#Range (cm-¹)=	100...5000
#Windows=	1
#Auto scanning=	Off
#Autofocus=	Off
#Macrospot=	Off
#AutoExposure=	Off
#Spike filter=	Multiple accum.
#Delay time (s)=	2
#Binning=	1
#Readout mode=	Signal
#DeNoise=	Off
#ICS correction=	On
#Dark correction=	Off
#Inst. Process=	Off
#Detector Gain=	Best Dynamic
#Detector ADC=	50 kHz HS
#Detector temperature (°C)=	-60.09
#Instrument=	LabRAM HR Evol
#Detector=	SIN-EM FIVIS
#Objective=	x100_VIS
#Grating=	150 (500nm)
#ND Filter=	100%
#Laser=	532nm_Edge
#Hole=	49.98
#Temperature=	0
#Range=	Visible
#StageXY=	75x50mm Scan+
#StageZ=	Z motor
#X (µm)=	0
#Y (µm)=	0
#Z (µm)=	-246.8
#Full time(mm:ss)=	1:04
#Project=	21_11_04
#Sample=	BU19w
#Site=
#Title=	BU19w-E-FF11b-FI04-L_150 (500nm)_532nm_Edge_100%_x100_VIS_H50um_30sX2
#Remark=
#Date=	04.11.2021 18:53
#Acquired=	04.11.2021 18:53:25
#Base:Fit=	16.12.2021 17:39:50
#Base:Sub=	16.12.2021 17:45:21
101.869	4346.85
106.493	7438.13
111.113	18551.1
115.732	26771.9
120.349	16004.4
124.964	7089.64
129.577	5335.17
134.185	4777.02
138.793	4259.06
143.399	3781.28
148.003	3704.86
152.602	3955.11
157.201	4545.59
161.798	5361.46
166.392	6601.75
170.982	8649.17
175.572	12244.4
180.16	17836.2
184.745	25217.9
189.326	32081.2
193.907	33791.8
198.486	29317.7
203.06	22286.1
207.634	15653.1
212.206	11167.6
216.776	8056.1
221.341	6020.95
225.906	4686
230.469	3867.21
235.028	3300.05
239.586	3052.86
244.142	3637.03
248.694	6421.42
253.246	6636.18
257.795	3041.92
262.341	1339.69
266.886	756.71
271.428	570.24
275.967	373.167
280.505	221.422
285.041	190.3
289.573	93.3379
294.105	45.4177
298.632	42.3002
303.159	19.6161
307.685	62.0883
312.205	20.6958
316.726	11.3625
321.242	-0.00012207
325.758	60.0703
330.272	199.772
334.782	1022.89
339.292	3960.29
343.797	4087.55
348.302	1638.63
352.803	613.697
357.304	333.378
361.802	335.832
366.297	332.337
370.791	380.969
375.281	662.448
379.77	1616.86
384.256	2613.95
388.741	2802.1
393.223	1480.32
397.704	699.208
402.18	679.298
406.657	707.776
411.13	870.074
415.602	1037.75
420.07	1402.89
424.538	1961.07
429.002	3185.39
433.465	5888.05
437.925	11568.3
442.384	25132.3
446.839	37200.8
451.294	37224.2
455.745	37263.6
460.196	37331.6
464.642	18772.7
469.089	11072
473.531	7785.67
477.971	5524.77
482.411	4298.95
486.846	3492.2
491.282	3173.04
495.713	2979.48
500.144	2571.49
504.572	2206.39
508.997	1930.64
513.421	1643.28
517.842	1417.34
522.263	1317.97
526.679	1196.05
531.093	1085.87
535.507	1009.49
539.917	893.604
544.327	751.901
548.733	655.197
553.137	616.177
557.54	601.85
561.94	582.252
566.337	519.264
570.734	556.583
575.127	585.608
579.518	563.532
583.909	581.131
588.295	523.424
592.68	486.757
597.064	424.335
601.445	445.68
605.823	385.35
610.201	394.411
614.575	400.422
618.947	354.883
623.317	361.977
627.686	348.562
632.052	323.784
636.415	331.479
640.777	308.731
645.138	298.256
649.495	253.053
653.85	253.101
658.205	277.486
662.556	299.98
666.905	326.54
671.252	418.359
675.597	588.169
679.941	1022.13
684.282	1472.03
688.62	1089.1
692.957	616.804
697.293	425.694
701.625	352.561
705.955	304.646
710.283	279.341
714.609	235.686
718.933	256.338
723.257	248.167
727.577	231.745
731.894	257.917
736.21	225.101
740.524	234.85
744.835	217.283
749.147	262.919
753.454	286.121
757.759	320.352
762.063	352.254
766.364	419.999
770.663	558.449
774.96	784.27
779.257	1349.33
783.55	2150.08
787.841	2414.32
792.13	3018.98
796.417	3137.98
800.702	1772.95
804.985	1001.58
809.266	702.954
813.545	539.754
817.821	477.873
822.096	473.102
826.371	469.691
830.641	460.834
834.91	437.635
839.176	428.642
843.441	407.377
847.703	396.813
851.964	396.674
856.222	420.768
860.479	496.581
864.733	582.025
868.986	468.964
873.236	410.866
877.485	411.899
881.731	396.306
885.975	366.19
890.218	310.687
894.458	280.048
898.696	352.638
902.933	312.212
907.167	315.195
911.399	304.036
915.63	280.463
919.858	242.721
924.084	207.055
928.308	195.726
932.531	176.702
936.749	174.825
940.967	160.97
945.184	163.11
949.398	124.622
953.61	120.515
957.821	119.659
962.029	76.3406
966.236	67.1494
970.44	56.9603
974.642	73.3873
978.843	38.9753
983.041	19.5116
987.236	39.2168
991.43	40.9135
995.623	39.7496
999.813	29.3385
1004	32.7751
1008.19	43.7002
1012.37	52.542
1016.55	55.9263
1020.73	63.5587
1024.91	70.0351
1029.09	73.1026
1033.27	130.521
1037.44	133.976
1041.61	180.745
1045.78	297.607
1049.94	643.32
1054.11	1071.22
1058.27	1105.41
1062.43	1106.28
1066.59	1668.36
1070.75	1850.36
1074.9	974.09
1079.05	399.313
1083.2	249.665
1087.35	168.366
1091.5	139.294
1095.65	104.394
1099.79	100.653
1103.93	82.6455
1108.07	77.1242
1112.21	67.7984
1116.34	64.6407
1120.48	89.5991
1124.61	111.002
1128.74	174.509
1132.86	235.345
1136.99	418.26
1141.11	745.437
1145.23	1422.75
1149.35	1933.82
1153.47	1589.71
1157.59	781.959
1161.7	340.824
1165.82	201.761
1169.92	145.151
1174.03	89.446
1178.14	82.1486
1182.24	83.0716
1186.35	69.4863
1190.45	63.8907
1194.55	89.9284
1198.64	73.8268
1202.74	87.227
1206.83	127.936
1210.92	156.275
1215.01	259.24
1219.1	285.129
1223.18	264.748
1227.27	225.521
1231.35	182.662
1235.43	130.285
1239.5	137.276
1243.58	144.133
1247.65	119.19
1251.72	138.432
1255.8	151.791
1259.86	150.244
1263.93	173.761
1267.99	130.327
1272.06	87.8734
1276.12	73.4115
1280.18	55.8785
1284.23	52.3226
1288.29	20.5029
1292.34	10.7473
1296.39	7.96829
1300.44	21.2752
1304.49	11.3377
1308.53	11.4407
1312.58	-3.6102
1316.62	20.5276
1320.66	20.3885
1324.7	0.0168457
1328.73	18.8104
1332.77	31.5201
1336.8	20.0196
1340.83	20.5015
1344.86	33.9272
1348.88	39.3141
1352.91	67.5755
1356.93	114.622
1360.95	172.378
1364.97	346.797
1368.99	500.02
1373.01	373.618
1377.02	207.213
1381.03	119.048
1385.04	84.3495
1389.05	50.7489
1393.06	44.7941
1397.06	35.0334
1401.06	26.2378
1405.06	3.61218
1409.06	19.4377
1413.06	18.535
1417.05	36.3793
1421.05	20.6654
1425.04	35.511
1429.03	23.5442
1433.01	28.3593
1437	28.2444
1440.99	24.1677
1444.97	30.9107
1448.95	31.697
1452.93	27.502
1456.9	41.0151
1460.88	27.8576
1464.85	23.4822
1468.82	39.7296
1472.79	19.6426
1476.76	24.0914
1480.73	37.3022
1484.69	27.9486
1488.65	10.7774
1492.61	32.7051
1496.57	24.3669
1500.53	23.861
1504.48	36.0479
1508.43	26.9078
1512.39	24.6049
1516.33	41.7287
1520.28	35.5765
1524.23	44.9659
1528.17	43.7011
1532.11	56.0415
1536.05	57.7232
1539.99	58.4389
1543.93	68.8432
1547.86	83.1167
1551.8	104.164
1555.73	95.136
1559.66	122.846
1563.58	104.036
1567.51	120.022
1571.44	145.62
1575.36	163.444
1579.28	160.958
1583.2	193.175
1587.11	184.84
1591.03	190.941
1594.94	177.785
1598.85	223.267
1602.76	229.337
1606.67	231.628
1610.58	260.782
1614.48	245.844
1618.38	256.85
1622.29	250.587
1626.18	279.806
1630.08	275.585
1633.98	266.728
1637.87	272.223
1641.76	247.183
1645.65	233.725
1649.54	217.419
1653.43	228.933
1657.31	204.901
1661.2	197.144
1665.08	182.571
1668.96	171.776
1672.83	155.089
1676.71	138.363
1680.58	110.899
1684.46	107.364
1688.33	79.8292
1692.2	84.8567
1696.06	53.4695
1699.93	55.5532
1703.79	64.244
1707.66	47.1407
1711.52	52.8416
1715.37	47.1398
1719.23	28.2304
1723.08	27.3382
1726.94	34.9066
1730.79	34.8805
1734.64	17.9879
1738.49	24.5386
1742.33	13.2905
1746.18	14.2099
1750.02	19.9039
1753.86	5.25256
1757.7	13.0128
1761.54	8.13904
1765.37	18.9313
1769.21	20.491
1773.04	8.22615
1776.87	10.8378
1780.7	7.92793
1784.53	12.5148
1788.35	7.78654
1792.17	-6.31734
1796	-0.767654
1799.82	3.8474
1803.64	10.2235
1807.45	-4.14392
1811.27	11.6007
1815.08	8.4599
1818.89	10.8816
1822.7	-1.85942
1826.51	0.452988
1830.32	21.5631
1834.12	9.60464
1837.92	12.6872
1841.72	13.8456
1845.52	2.73755
1849.32	1.99304
1853.12	10.5284
1856.91	14.2951
1860.7	1.18616
1864.5	23.4711
1868.28	3.88777
1872.07	11.2823
1875.86	30.7111
1879.64	11.3131
1883.42	-4.25217
1887.21	16.1434
1890.98	27.5295
1894.76	11.3342
1898.54	19.0591
1902.31	19.5079
1906.08	25.5267
1909.85	22.3594
1913.62	24.7936
1917.39	23.5584
1921.16	0.260727
1924.92	22.2896
1928.68	15.6657
1932.44	18.3305
1936.2	31.2454
1939.96	34.8632
1943.71	25.3898
1947.47	23.3797
1951.22	46.514
1954.97	41.4206
1958.72	48.407
1962.46	34.6376
1966.21	37.7569
1969.95	52.0708
1973.7	47.5071
1977.43	43.837
1981.17	63.5236
1984.91	51.3414
1988.65	51.2896
1992.38	60.5148
1996.11	60.3542
1999.84	50.8665
2003.57	74.7525
2007.3	56.0168
2011.02	63.107
2014.75	66.488
2018.47	70.8835
2022.19	58.9095
2025.91	49.8498
2029.62	64.6381
2033.34	48.379
2037.05	56.9491
2040.76	45.3436
2044.47	55.6957
2048.18	59.6324
2051.89	62.7017
2055.59	74.9487
2059.3	64.4036
2063	55.8362
2066.7	65.695
2070.4	69.1578
2074.1	79.0929
2077.79	73.3591
2081.49	73.1782
2085.18	77.6041
2088.87	63.1791
2092.56	67.157
2096.25	70.3291
2099.93	80.9151
2103.61	70.9421
2107.3	91.6129
2110.98	87.1241
2114.66	77.0447
2118.33	92.9608
2122.01	80.8918
2125.68	87.3285
2129.36	91.857
2133.03	81.532
2136.7	86.929
2140.36	62.728
2144.03	69.89
2147.7	79.7667
2151.36	62.9695
2155.02	74.6565
2158.68	66.1758
2162.34	72.37
2165.99	63.0693
2169.65	55.655
2173.3	67.4747
2176.95	60.2226
2180.6	54.824
2184.25	65.7979
2187.9	64.082
2191.54	56.0953
2195.18	49.1044
2198.83	54.0019
2202.47	56.195
2206.11	41.9936
2209.74	56.1303
2213.38	44.7039
2217.01	35.0882
2220.64	46.5638
2224.27	50.7262
2227.9	37.3845
2231.53	39.6824
2235.16	53.0928
2238.78	46.1771
2242.4	42.9369
2246.02	35.0331
2249.64	36.4078
2253.26	42.4648
2256.88	45.761
2260.49	51.8674
2264.11	53.2827
2267.72	37.8328
2271.33	41.169
2274.93	38.8169
2278.54	40.1591
2282.15	37.5932
2285.75	45.3834
2289.35	38.0674
2292.95	25.0323
2296.55	41.3174
2300.15	42.4791
2303.74	39.8159
2307.34	51.3165
2310.93	36.2446
2314.52	32.5104
2318.11	58.1183
2321.7	69.4464
2325.28	41.8094
2328.87	55.7875
2332.45	42.325
2336.03	36.4064
2339.61	52.1298
2343.19	27.3553
2346.77	40.1712
2350.34	36.9976
2353.92	31.0174
2357.49	32.5097
2361.06	42.3614
2364.63	28.9301
2368.2	35.9696
2371.76	16.1737
2375.33	36.1879
2378.89	28.4438
2382.45	23.5132
2386.01	24.1356
2389.57	23.8675
2393.13	30.0619
2396.68	28.0496
2400.23	24.2741
2403.79	24.2704
2407.34	23.3832
2410.88	23.4852
2414.43	24.5587
2417.98	29.3536
2421.52	31.4322
2425.06	24.3466
2428.61	6.21094
2432.14	37.0598
2435.68	23.5913
2439.22	19.3728
2442.75	20.7341
2446.29	17.4387
2449.82	19.7756
2453.35	7.14438
2456.88	20.6736
2460.4	19.0069
2463.93	14.4723
2467.45	11.6709
2470.98	14.6454
2474.5	15.47
2478.02	20.9308
2481.54	23.5953
2485.05	29.0114
2488.57	6.07462
2492.08	10.5153
2495.59	21.4292
2499.1	26.7345
2502.61	19.8141
2506.12	6.33345
2509.63	18.0291
2513.13	3.6337
2516.63	-2.3112
2520.13	1.06807
2523.63	18.1923
2527.13	15.1128
2530.63	24.0995
2534.12	21.0951
2537.62	0.620331
2541.11	10.6404
2544.6	17.0582
2548.09	18.9553
2551.58	8.84502
2555.06	3.38551
2558.55	17.4701
2562.03	12.1011
2565.51	17.028
2568.99	2.46196
2572.47	26.188
2575.95	13.5308
2579.43	13.0569
2582.9	14.4766
2586.37	7.39323
2589.84	13.5018
2593.31	23.3382
2596.78	9.35484
2600.25	-5.58778
2603.71	11.9342
2607.18	4.48515
2610.64	13.1805
2614.1	5.40273
2617.56	11.1533
2621.02	8.17253
2624.47	10.9195
2627.93	-10.407
2631.38	6.66173
2634.83	0.63443
2638.28	6.06201
2641.73	9.52742
2645.18	4.33513
2648.62	0.100082
2652.07	-2.25957
2655.51	12.4641
2658.95	8.09633
2662.39	16.9852
2665.83	-6.31978
2669.27	20.4456
2672.7	20.732
2676.14	-0.53244
2679.57	5.4738
2683	-2.52307
2686.43	14.7587
2689.86	9.75156
2693.29	9.49208
2696.71	10.1127
2700.13	14.4998
2703.56	1.21967
2706.98	3.74832
2710.4	-2.88275
2713.82	10.9896
2717.23	8.15582
2720.65	9.08295
2724.06	4.44025
2727.47	7.27316
2730.88	26.0211
2734.29	6.41919
2737.7	7.38899
2741.11	16.7966
2744.51	14.9144
2747.91	15.8147
2751.32	12.9577
2754.72	13.8449
2758.11	9.99677
2761.51	5.21222
2764.91	6.96375
2768.3	0.20459
2771.7	5.65996
2775.09	21.4627
2778.48	7.07884
2781.87	-1.67496
2785.25	21.5595
2788.64	16.5438
2792.03	21.8661
2795.41	18.7164
2798.79	18.3911
2802.17	17.0888
2805.55	23.2891
2808.93	9.80522
2812.3	28.1486
2815.68	24.0071
2819.05	28.2707
2822.42	21.3596
2825.79	19.1521
2829.16	21.623
2832.53	6.4137
2835.89	26.6514
2839.26	38.5357
2842.62	28.1064
2845.98	39.1578
2849.34	42.841
2852.7	41.93
2856.06	30.7057
2859.41	32.5833
2862.77	38.2393
2866.12	45.7915
2869.47	39.2895
2872.82	46.8472
2876.17	49.7111
2879.52	39.3952
2882.87	49.7813
2886.21	63.9396
2889.55	63.9547
2892.89	59.2375
2896.23	62.011
2899.57	59.0759
2902.91	66.5044
2906.25	58.7627
2909.58	83.1707
2912.91	78.2227
2916.25	66.6355
2919.58	73.9295
2922.91	86.8783
2926.23	88.4509
2929.56	84.3074
2932.88	95.2484
2936.21	104.237
2939.53	96.2395
2942.85	113.692
2946.17	121.712
2949.49	114.68
2952.8	111.406
2956.12	116.597
2959.43	127.466
2962.74	126.159
2966.06	138.937
2969.37	127.42
2972.67	164.752
2975.98	153.311
2979.28	163.522
2982.59	169.934
2985.89	171.678
2989.19	182.835
2992.49	194.952
2995.79	185.487
2999.09	222.097
3002.38	220.179
3005.68	232.368
3008.97	229.546
3012.26	239.928
3015.55	267.296
3018.84	243.771
3022.13	286.244
3025.41	290.069
3028.7	294.851
3031.98	317.581
3035.26	333.692
3038.54	331.833
3041.82	363.092
3045.1	346.114
3048.38	367.958
3051.65	421.086
3054.92	425.941
3058.2	454.488
3061.47	465.769
3064.73	468.618
3068	502.704
3071.27	529.097
3074.54	546.177
3077.8	552.714
3081.06	588.317
3084.32	609.496
3087.58	639.18
3090.84	670.096
3094.1	676.506
3097.35	694.008
3100.61	734.021
3103.86	765.26
3107.11	820.804
3110.36	842.011
3113.61	849.531
3116.86	923.8
3120.11	940.994
3123.35	946.766
3126.59	1011.59
3129.84	1056.39
3133.08	1106.95
3136.32	1106.01
3139.55	1199.38
3142.79	1204.08
3146.03	1247.88
3149.26	1300.37
3152.49	1353.87
3155.72	1428.29
3158.95	1429.34
3162.18	1465.62
3165.41	1540.11
3168.64	1589.63
3171.86	1656.19
3175.08	1707.41
3178.31	1726.96
3181.53	1774.14
3184.75	1850.93
3187.96	1937.93
3191.18	1924.73
3194.4	1966.8
3197.61	2055.49
3200.82	2059.31
3204.03	2108.93
3207.24	2202.38
3210.45	2198.84
3213.66	2272.53
3216.86	2309.28
3220.07	2318.44
3223.27	2357.17
3226.48	2396.18
3229.68	2434.28
3232.87	2483.1
3236.07	2534.54
3239.27	2583.78
3242.47	2598.94
3245.66	2599.98
3248.85	2622.93
3252.04	2674.8
3255.23	2684.84
3258.42	2753.09
3261.61	2802.83
3264.8	2771.94
3267.98	2819.9
3271.16	2852.27
3274.35	2891.12
3277.53	2879.35
3280.71	2940.47
3283.89	2951.28
3287.06	2975.54
3290.24	3001.37
3293.41	3016.99
3296.58	3102.01
3299.76	3112.65
3302.93	3159.41
3306.1	3223.3
3309.26	3210.73
3312.43	3287.89
3315.59	3339.08
3318.76	3373.97
3321.92	3437.1
3325.08	3520.99
3328.24	3520.55
3331.4	3601.49
3334.56	3607.94
3337.71	3662.86
3340.87	3754.82
3344.02	3823.14
3347.17	3901.8
3350.33	3928.76
3353.47	3982
3356.62	4048.94
3359.77	4147.19
3362.92	4159.3
3366.06	4233.74
3369.2	4316.01
3372.34	4315.47
3375.49	4422.16
3378.62	4500.81
3381.76	4536.35
3384.9	4631.21
3388.04	4663.25
3391.17	4692.52
3394.3	4732.21
3397.43	4808.15
3400.56	4837.9
3403.69	4889.01
3406.82	4897.98
3409.95	4963.37
3413.07	5010.77
3416.2	4999.77
3419.32	5026.54
3422.44	5097.75
3425.56	5107.8
3428.68	5080.59
3431.8	5075.56
3434.91	5147.8
3438.03	5087.84
3441.14	5092.55
3444.25	5095.32
3447.36	5083.55
3450.47	5045.99
3453.58	5021.91
3456.69	4960.66
3459.79	4956.75
3462.9	4924.23
3466	4891.5
3469.11	4889.48
3472.21	4711.87
3475.31	4681.17
3478.4	4654.58
3481.5	4552.6
3484.6	4505.7
3487.69	4456.35
3490.79	4385.99
3493.88	4292.51
3496.97	4222.54
3500.06	4135.26
3503.15	4008.66
3506.23	3885.13
3509.32	3837.18
3512.4	3770.06
3515.49	3704.44
3518.57	3637.54
3521.65	3466.66
3524.73	3415.4
3527.81	3340.48
3530.89	3270.29
3533.96	3155.98
3537.03	3080.55
3540.11	3026.96
3543.18	2931.65
3546.25	2827.88
3549.32	2746.32
3552.39	2646.88
3555.46	2599.02
3558.52	2550.67
3561.59	2409.54
3564.65	2350.09
3567.71	2293.98
3570.77	2251.96
3573.83	2170.75
3576.89	2105.76
3579.95	2068.07
3583	1989.42
3586.06	1897.27
3589.11	1876.28
3592.16	1826.57
3595.21	1789.16
3598.27	1694.73
3601.31	1666.69
3604.36	1629.95
3607.41	1560.92
3610.45	1500.48
3613.5	1437.17
3616.54	1361.59
3619.58	1318.28
3622.62	1271.31
3625.66	1231.04
3628.69	1193.75
3631.73	1124.38
3634.77	1059.7
3637.8	1029.3
3640.83	957.678
3643.86	903.138
3646.89	841.405
3649.92	785.913
3652.95	734.461
3655.98	698.505
3659	622.432
3662.02	575.323
3665.05	531.78
3668.07	488.751
3671.09	470.384
3674.11	412.414
3677.13	364.802
3680.14	364.398
3683.16	323.321
3686.17	300.172
3689.19	269.443
3692.2	243.424
3695.21	231.599
3698.22	204.491
3701.23	176.505
3704.23	191.197
3707.24	159.365
3710.24	140.756
3713.25	128.759
3716.25	130.974
3719.25	121.803
3722.25	90.6897
3725.25	84.2917
3728.25	78.818
3731.24	72.3731
3734.24	79.234
3737.23	81.3014
3740.22	59.5473
3743.21	62.5152
3746.21	55.9488
3749.19	53.1665
3752.18	54.1687
3755.17	39.0271
3758.15	38.1467
3761.14	33.4711
3764.12	46.7848
3767.1	26.947
3770.08	27.0278
3773.06	13.8928
3776.04	25.3686
3779.02	23.6212
3781.99	18.1151
3784.97	15.4503
3787.94	21.299
3790.91	4.50687
3793.88	16.0712
3796.85	0.28421
3799.82	9.05162
3802.79	8.4127
3805.76	1.17542
3808.72	12.8366
3811.69	20.7415
3814.65	5.96793
3817.61	-3.13579
3820.57	17.1003
3823.53	8.95734
3826.49	-0.12384
3829.45	3.11221
3832.4	-1.23753
3835.36	-3.67265
3838.31	5.29945
3841.26	17.138
3844.21	18.5294
3847.16	11.3615
3850.11	4.19273
3853.06	12.2819
3856	10.8475
3858.95	5.59364
3861.89	2.24683
3864.84	6.53653
3867.78	10.8356
3870.72	3.62381
3873.66	8.86411
3876.6	13.145
3879.53	9.72554
3882.47	16.8494
3885.4	12.421
3888.34	6.05188
3891.27	16.9792
3894.2	10.5928
3897.13	-6.39948
3900.06	19.8598
3902.99	6.68898
3905.91	6.95227
3908.84	18.7798
3911.76	20.9739
3914.69	12.5796
3917.61	6.09398
3920.53	17.9001
3923.45	6.62054
3926.37	16.4351
3929.28	18.55
3932.2	8.19308
3935.11	15.1382
3938.03	17.3354
3940.94	22.4499
3943.85	12.2225
3946.76	14.455
3949.67	15.7527
3952.58	23.7707
3955.49	7.85727
3958.39	14.9478
3961.3	23.0114
3964.2	22.4641
3967.1	9.46291
3970	28.1216
3972.9	22.8094
3975.8	26.131
3978.7	17.9135
3981.6	28.8961
3984.49	16.8111
3987.39	24.902
3990.28	11.8331
3993.17	6.42598
3996.06	25.1125
3998.95	5.30606
4001.84	30.75
4004.73	16.7262
4007.61	18.1193
4010.5	17.5892
4013.38	15.1272
4016.27	17.4885
4019.15	23.7126
4022.03	13.5279
4024.91	21.6866
4027.79	18.2625
4030.66	14.836
4033.54	19.1495
4036.42	26.3711
4039.29	10.3766
4042.16	23.4185
4045.03	5.43143
4047.9	31.0536
4050.77	21.8027
4053.64	18.3747
4056.51	16.9033
4059.38	17.3668
4062.24	10.0496
4065.1	13.4183
4067.97	9.00874
4070.83	6.53784
4073.69	9.90413
4076.55	0.608429
4079.41	0.0711365
4082.26	3.43181
4085.12	5.821
4087.97	9.17912
4090.83	16.442
4093.68	-3.61575
4096.53	13.4158
4099.38	2.12964
4102.23	11.3611
4105.08	5.92285
4107.93	5.35129
4110.77	12.6074
4113.62	3.20914
4116.46	-0.338058
4119.3	15.6638
4122.14	0.348328
4124.98	8.54007
4127.82	2.0582
4130.66	1.49106
4133.5	-3.94637
4136.33	9.28183
4139.17	9.5737
4142	2.8437
4144.83	7.07805
4147.67	18.2549
4150.5	-12.6485
4153.33	-6.38908
4156.15	7.6449
4158.98	8.87253
4161.81	5.25992
4164.63	4.61159
4167.45	8.85091
4170.28	18.9642
4173.1	7.57147
4175.92	1.07326
4178.74	12.1775
4181.56	-2.13269
4184.37	2.14418
4187.19	2.51743
4190	16.5936
4192.82	5.2532
4195.63	-6.07814
4198.44	7.09589
4201.25	7.53476
4204.06	3.07346
4206.87	7.43451
4209.68	-3.91335
4212.48	12.2362
4215.29	-2.08168
4218.1	4.33452
4220.9	11.7485
4223.7	17.1855
4226.5	8.78543
4229.3	1.3812
4232.1	1.88297
4234.9	0.421524
4237.69	5.90819
4240.49	0.486481
4243.28	8.97458
4246.07	5.54373
4248.87	14.0586
4251.66	11.5946
4254.45	1.12001
4257.24	3.61366
4260.03	4.10384
4262.81	3.59711
4265.6	-8.95602
4268.38	-4.44095
4271.17	8.13452
4273.95	17.7096
4276.73	10.1208
4279.51	17.6363
4282.29	0.896896
4285.07	-4.76208
4287.84	6.75111
4290.62	-1.98862
4293.39	11.533
4296.17	-1.25644
4298.94	7.24074
4301.71	5.5887
4304.48	7.98917
4307.25	5.3127
4310.02	-1.42557
4312.79	8.10573
4315.55	10.503
4318.32	7.79611
4321.08	7.10968
4323.85	7.42598
4326.61	-4.48759
4329.37	-4.1815
4332.13	11.3882
4334.89	5.57249
4337.65	-2.29819
4340.4	6.15793
4343.16	-3.73019
4345.91	-2.39507
4348.67	2.01363
4351.42	10.5091
4354.17	-0.356827
4356.92	10.2137
4359.67	9.5421
4362.42	9.88237
4365.17	15.3544
4367.91	0.325043
4370.66	4.76964
4373.4	5.08896
4376.14	10.5327
4378.89	4.6711
4381.63	1.87959
4384.37	6.28645
4387.11	-2.64066
4389.84	1.85143
4392.58	5.34685
4395.32	9.9926
4398.05	-0.957245
4400.78	2.53986
4403.52	-0.189545
4406.25	13.6807
4408.98	-0.463013
4411.71	1.98383
4414.44	2.32956
4417.16	5.79189
4419.89	10.2408
4422.62	14.7155
4425.34	0.413101
4428.06	-5.55331
4430.78	8.33447
4433.51	3.40309
4436.22	9.97266
4438.94	-1.27039
4441.66	1.08488
4444.38	1.34474
4447.1	-7.84987
4449.81	15.4892
4452.52	2.07347
4455.24	-1.90196
4457.95	9.87003
4460.66	13.2288
4463.37	8.19243
4466.08	11.564
4468.78	11.7864
4471.49	-0.621246
4474.2	10.1443
4476.9	4.06735
4479.6	11.7045
4482.31	0.356644
4485.01	10.1195
4487.71	0.851791
4490.41	4.25938
4493.11	17.1609
4495.8	9.92236
4498.5	13.298
4501.19	10.3101
4503.89	11.542
4506.58	4.30623
4509.27	11.9162
4511.96	7.85834
4514.66	13.3521
4517.34	14.6047
4520.03	8.42293
4522.72	13.9444
4525.41	14.1506
4528.09	12.2217
4530.77	13.4889
4533.46	-2.29709
4536.14	11.7666
4538.82	6.63692
4541.5	5.7809
4544.18	-4.70439
4546.86	10.4785
4549.53	-4.30202
4552.21	11.9876
4554.88	-0.64035
4557.56	7.13257
4560.23	2.05449
4562.9	13.1517
4565.57	17.8504
4568.24	6.37462
4570.91	13.2099
4573.58	7.95464
4576.24	-0.636612
4578.91	8.21202
4581.58	16.0425
4584.24	17.3975
4586.9	11.0311
4589.56	4.64606
4592.22	-0.672653
4594.88	1.64871
4597.54	7.26981
4600.2	10.6919
4602.86	14.1459
4605.51	3.37897
4608.17	10.129
4610.82	3.7276
4613.47	9.38657
4616.13	-3.63216
4618.78	8.63182
4621.43	18.7243
4624.07	10.0916
4626.72	9.1526
4629.37	19.2442
4632.01	5.03702
4634.66	10.69
4637.3	16.3375
4639.94	10.9193
4642.59	7.70869
4645.23	1.19939
4647.87	3.58913
4650.5	3.79427
4653.14	4.04745
4655.78	6.49207
4658.42	-3.4978
4661.05	6.68346
4663.68	0.156036
4666.31	3.66132
4668.95	2.65985
4671.58	3.90866
4674.21	7.3967
4676.84	-2.56932
4679.46	9.89212
4682.09	4.39743
4684.72	6.76192
4687.34	-0.993179
4689.97	-2.00526
4692.59	1.48997
4695.21	6.10478
4697.83	3.95526
4700.45	11.9645
4703.07	1.90874
4705.69	-2.52164
4708.3	-3.56841
4710.92	5.5602
4713.54	7.90483
4716.15	5.7173
4718.76	1.25497
4721.37	3.58546
4723.99	7.04231
4726.59	-3.0864
4729.2	11.7452
4731.81	14.1069
4734.42	-1.69971
4737.03	4.06371
4739.63	10.9606
4742.23	3.07619
4744.84	0.862961
4747.44	6.60675
4750.04	5.50388
4752.64	13.5108
4755.24	-3.52104
4757.84	-1.20628
4760.44	9.09192
4763.03	2.32585
4765.63	6.9554
4768.22	2.50308
4770.82	-0.796188
4773.41	5.0002
4776	-10.8811
4778.59	6.34285
4781.18	-2.69424
4783.77	-2.59257
4786.36	7.80438
4788.94	5.62959
4791.53	3.46002
4794.11	4.73238
4796.7	7.1586
4799.28	7.31183
4801.86	0.592331
4804.44	1.91451
4807.02	3.2585
4809.6	-5.73668
4812.18	-0.926788
4814.76	-5.32129
4817.33	1.83067
4819.91	2.07878
4822.48	-2.29967
4825.06	11.8587
4827.63	-8.75518
4830.2	1.95055
4832.77	-3.5835
4835.34	2.52409
4837.91	4.00333
4840.48	7.84096
4843.04	-0.0138855
4845.61	12.0149
4848.17	2.9392
4850.74	2.03415
4853.3	-3.65499
4855.86	-2.2834
4858.42	2.76249
4860.98	-0.433723
4863.54	2.23558
4866.1	7.23158
4868.66	-10.2231
4871.21	-3.9988
4873.77	9.32203
4876.32	-2.24592
4878.88	6.34534
4881.43	1.88671
4883.98	3.36021
4886.53	-12.9893
4889.08	11.0895
4891.63	6.64317
4894.18	1.00188
4896.72	6.08037
4899.27	6.39846
4901.81	11.4925
4904.36	1.08455
4906.9	1.41439
4909.44	-3.03125
4911.98	10.4201
4914.52	5.95383
4917.06	7.45575
4919.6	8.97916
4922.14	-0.240356
4924.67	6.08146
4927.21	-3.11366
4929.74	8.00239
4932.28	-2.35678
4934.81	10.0356
4937.34	2.09296
4939.87	9.71288
4942.4	5.3207
4944.93	14.1485
4947.46	3.85023
4949.99	3.13718
4952.51	-4.75159
4955.04	1.74558
4957.56	11.8801
4960.08	12.4409
4962.61	7.01519
4965.13	11.2496
4967.65	10.7101
4970.17	16.1765
4972.69	7.17202
4975.2	16.2803
4977.72	22.9945
4980.24	10.3765
4982.75	19.5515
4985.27	20.2734
4987.78	11.3036
4990.29	20.5527
4992.8	15.2361
4995.31	11.1358
4997.82	21.6793