File: Data/3-Raman/processed/bu19w-b-ff1-fi02-s_150 (500nm)_532nm_edge_100%_x100_vis_h50um_15sx2_01.txt
#Acq. time (s)=	15
#Accumulations=	2
#Range (cm-¹)=	100...5000
#Windows=	1
#Auto scanning=	Off
#Autofocus=	Off
#Macrospot=	Off
#AutoExposure=	Off
#Spike filter=	Multiple accum.
#Delay time (s)=	2
#Binning=	1
#Readout mode=	Signal
#DeNoise=	Off
#ICS correction=	On
#Dark correction=	Off
#Inst. Process=	Off
#Detector Gain=	Best Dynamic
#Detector ADC=	50 kHz HS
#Detector temperature (°C)=	-60.09
#Instrument=	LabRAM HR Evol
#Detector=	SIN-EM FIVIS
#Objective=	x100_VIS
#Grating=	150 (500nm)
#ND Filter=	100%
#Laser=	532nm_Edge
#Hole=	49.98
#Temperature=	0
#Range=	Visible
#StageXY=	75x50mm Scan+
#StageZ=	Z motor
#X (µm)=	0
#Y (µm)=	0
#Z (µm)=	-134.5
#Full time(s)=	34
#Project=	21_05_14
#Sample=	BU19w
#Site=
#Title=	BU19w-FF1-FI02-S_150 (500nm)_532nm_Edge_100%_x100_VIS_H50um_15sX2
#Remark=
#Date=	14.05.2021 12:05
#Acquired=	14.05.2021 12:05:43
#Base:Fit=	22.12.2021 12:22:35
#Base:Edit=	22.12.2021 12:23:48
#Base:Edit=	22.12.2021 12:23:50
#Base:Sub=	22.12.2021 12:23:53
#Data Range:Extract=	22.12.2021 12:27:19
102.699	447.605
107.322	236.179
111.942	333.103
116.56	275.346
121.173	393.956
125.787	438.99
130.398	520.968
135.006	1450.81
139.613	3548.79
144.215	5711.29
148.817	5928.3
153.417	3513.48
158.014	1532.31
162.607	655.986
167.2	563.752
171.79	1409
176.379	2969.66
180.963	2414.88
185.547	1101.49
190.128	858.196
194.705	1557.53
199.282	4846.24
203.857	10682.6
208.43	7181.97
212.998	1922.89
217.566	452.88
222.132	181.145
226.693	256.979
231.254	284.374
235.813	159.075
240.368	31.7295
244.923	0.890625
249.475	257.156
254.023	285.48
258.571	727.129
263.117	1300.74
267.658	1405.98
272.199	1282.36
276.738	1458.73
281.273	1944.71
285.807	2256.4
290.34	4903.99
294.868	10567.9
299.396	14127.3
303.919	9433.77
308.443	5234.87
312.964	5497.28
317.481	6589.41
321.998	5717.77
326.51	3634.87
331.023	2221.84
335.533	1532.66
340.039	1530.65
344.544	2088.99
349.046	1988.36
353.547	1280.98
358.045	938.148
362.542	1076.41
367.036	1221.68
371.527	1071.17
376.017	995.492
380.503	1148.32
384.99	1587.94
389.471	1981.52
393.953	2361.91
398.43	2873.47
402.908	3027.71
407.381	2895.66
411.854	2724.98
416.323	2400.2
420.791	1776.98
425.256	1527.21
429.72	2335.44
434.18	2603.91
438.64	1431.93
443.095	741.058
447.551	511.218
452.003	528.001
456.454	504.563
460.901	693.437
465.348	1352.52
469.791	2884.7
474.231	3360.78
478.672	2029.26
483.108	1364.77
487.544	1243.29
491.976	1280.57
496.408	1454.99
500.836	1601.44
505.261	1832.28
509.687	1999.7
514.108	2123.33
518.529	2112.8
522.946	1838.29
527.361	1487.26
531.776	1220.06
536.187	1015.03
540.595	962.449
545.003	954.768
549.408	1068.87
553.812	1035.46
558.212	944.651
562.61	863.323
567.007	779.423
571.401	827.62
575.792	888.202
580.184	884.14
584.571	767.055
588.956	705.251
593.341	958.836
597.722	2049.27
602.101	4288.84
606.48	4861.61
610.854	2972.51
615.227	1765.57
619.597	1795.72
623.967	2806.47
628.334	4541.43
632.698	4027.23
637.06	2677.4
641.422	2588.95
645.779	4419.88
650.135	4891.07
654.491	2795.41
658.842	1591.55
663.192	931.962
667.539	695.024
671.884	530.724
676.23	539.314
680.571	619.206
684.91	627.578
689.247	684.804
693.583	780.486
697.916	745.462
702.247	441.308
706.576	262.17
710.902	141.925
715.229	81.6855
719.551	-1.40039
723.872	22.4839
728.19	14.5732
732.506	36.3082
736.82	-26.7875
741.134	0.993286
745.444	23.1125
749.752	31.3752
754.058	20.6479
758.362	98.4996
762.664	110.858
766.964	227.691
771.264	317.48
775.559	500.281
779.853	721.724
784.144	1302.27
788.434	2286.4
792.722	3727.93
797.007	4196.52
801.29	3565.86
805.572	2426.06
809.851	1522.53
814.13	1003.46
818.406	621.495
822.679	398.487
826.95	285.7
831.219	143.167
835.486	170.172
839.752	120.957
844.015	123.19
848.276	97.5417
852.535	76.1942
856.792	64.825
861.047	183.248
865.3	260.091
869.551	437.447
873.8	714.663
878.047	855.864
882.292	714.563
886.534	450.64
890.775	252.475
895.014	276.407
899.251	221.538
903.486	149.949
907.719	146.005
911.95	104.614
916.179	60.7688
920.406	23.6106
924.63	36.7769
928.853	-12.8425
933.074	68.8441
937.293	55.3934
941.51	86.7155
945.723	104.77
949.936	172.438
954.147	282.759
958.356	300.577
962.563	493.932
966.768	611.715
970.971	680.102
975.172	864.102
979.371	1115.33
983.568	1383.51
987.761	1557.75
991.954	1610.33
996.145	2037.57
1000.33	2884.67
1004.52	4628.59
1008.71	7937.06
1012.89	11840.8
1017.07	10937.1
1021.25	6566.61
1025.43	3750.63
1029.6	2428.47
1033.77	2004.21
1037.95	2051.44
1042.11	2774.12
1046.28	4133.71
1050.45	4639.42
1054.61	5234.04
1058.77	7832.37
1062.93	8557.47
1067.09	7212.01
1071.24	5486.43
1075.4	3419.56
1079.55	2151.41
1083.7	1412.27
1087.85	1190.8
1091.99	1336.9
1096.14	1895.57
1100.28	2978.59
1104.42	4506.56
1108.55	5524.24
1112.69	4772.82
1116.82	3404.4
1120.96	3081.79
1125.09	3286.46
1129.21	3138.77
1133.34	2699.27
1137.46	2416.95
1141.59	2525.12
1145.71	2798.9
1149.83	2830.45
1153.94	2230.98
1158.06	1701.71
1162.17	1336.95
1166.28	1570.23
1170.39	2181.48
1174.5	2415.75
1178.6	2055.37
1182.7	1450.79
1186.8	1084.6
1190.9	910.487
1195	715.826
1199.1	522.288
1203.19	503.319
1207.28	404.38
1211.37	437.573
1215.46	488.788
1219.54	328.974
1223.63	300.55
1227.71	238.077
1231.79	294.567
1235.87	390.525
1239.95	554.377
1244.02	473.791
1248.09	509.666
1252.16	789.812
1256.23	1054.69
1260.3	923.326
1264.36	481.918
1268.43	392.852
1272.49	276.539
1276.55	260.29
1280.6	227.778
1284.66	254.96
1288.71	176.399
1292.76	111.372
1296.81	127.802
1300.86	97.5294
1304.91	84.0294
1308.95	126.032
1312.99	86.7252
1317.03	77.0165
1321.07	83.1898
1325.11	72.2189
1329.14	72.6903
1333.18	57.3475
1337.21	59.6549
1341.24	40.7339
1345.26	36.6998
1349.29	63.5754
1353.31	55.6091
1357.33	25.8287
1361.35	52.5399
1365.37	74.7439
1369.39	117.798
1373.4	90.2417
1377.41	155.522
1381.43	298.14
1385.43	416.838
1389.44	418.582
1393.45	246.027
1397.45	140.702
1401.45	101.858
1405.45	99.6766
1409.45	29.6016
1413.44	40.4565
1417.44	-10.9299
1421.43	44.1624
1425.42	43.3442
1429.41	24.1257
1433.39	43.8845
1437.38	52.4692
1441.36	67.0187
1445.34	-5.6936
1449.32	37.9834
1453.3	12.1942
1457.27	12.8842
1461.24	1.21033
1465.22	36.3627
1469.19	22.496
1473.15	4.77039
1477.12	18.0455
1481.09	21.3754
1485.05	28.4518
1489.01	21.8181
1492.97	9.49011
1496.93	43.0023
1500.88	52.4156
1504.83	30.1262
1508.79	0.454956
1512.74	74.6938
1516.68	36.4607
1520.63	68.2548
1524.57	75.8772
1528.52	70.1085
1532.46	40.2522
1536.4	34.6206
1540.33	64.8856
1544.27	72.8281
1548.2	30.3903
1552.14	62.4193
1556.07	72.8125
1559.99	117.785
1563.92	115.109
1567.84	150.916
1571.77	130.554
1575.69	105.343
1579.61	150.482
1583.52	112.567
1587.44	129.462
1591.35	169.388
1595.27	166.912
1599.18	157.798
1603.09	129.746
1606.99	136.435
1610.9	159.44
1614.8	191.276
1618.7	158.991
1622.6	186.098
1626.5	211.652
1630.39	170.608
1634.29	177.75
1638.18	181.117
1642.07	178.396
1645.96	171.1
1649.85	215.718
1653.73	210.418
1657.62	179.963
1661.5	224.208
1665.38	196.021
1669.26	174.152
1673.13	238.355
1677.01	172.255
1680.88	104.318
1684.75	145.656
1688.62	138.701
1692.49	110.323
1696.35	99.8928
1700.22	102.455
1704.08	112.2
1707.94	115.785
1711.8	110.628
1715.66	71.5171
1719.51	67.556
1723.37	64.4735
1727.22	94.9797
1731.07	137.467
1734.92	93.6295
1738.76	104.795
1742.61	92.5658
1746.45	89.4762
1750.29	22.4135
1754.13	41.6565
1757.97	45.5039
1761.81	18.6636
1765.64	73.6885
1769.47	39.8265
1773.31	63.9574
1777.14	43.7347
1780.96	-17.9913
1784.79	34.2946
1788.61	37.2856
1792.43	41.2773
1796.25	39.6157
1800.07	62.6155
1803.89	19.9678
1807.71	74.2412
1811.52	59.4323
1815.33	14.7295
1819.14	49.5328
1822.95	62.2577
1826.76	53.7771
1830.56	14.6202
1834.37	40.1115
1838.17	49.2699
1841.97	44.8632
1845.77	65.7363
1849.56	51.5215
1853.36	34.7144
1857.15	16.5295
1860.94	41.7981
1864.73	42.8407
1868.52	23.7036
1872.31	43.8148
1876.09	29.9352
1879.87	69.1705
1883.66	45.188
1887.43	45.5212
1891.21	47.8779
1894.99	52.858
1898.76	44.5538
1902.53	37.7874
1906.31	77.3043
1910.08	55.6201
1913.84	37.0774
1917.61	46.0386
1921.37	55.7244
1925.14	101.829
1928.9	49.8918
1932.66	60.1696
1936.41	22.8408
1940.17	50.7526
1943.92	32.338
1947.68	35.6375
1951.43	43.8501
1955.18	56.8176
1958.92	35.9241
1962.67	32.7146
1966.41	63.0938
1970.16	47.4119
1973.9	52.9468
1977.64	80.5408
1981.37	35.8002
1985.11	30.0439
1988.84	2.72656
1992.57	37.3608
1996.31	23.281
2000.03	41.4272
2003.76	28.3464
2007.49	6.3114
2011.21	82.7673
2014.93	62.9729
2018.65	18.9222
2022.37	5.1521
2026.09	22.6672
2029.81	21.5011
2033.52	54.2413
2037.23	58.983
2040.94	56.5286
2044.65	25.4071
2048.36	56.0686
2052.07	46.7123
2055.77	32.2035
2059.47	61.4814
2063.17	44.6538
2066.87	75.8866
2070.57	22.4431
2074.27	92.6934
2077.96	94.0034
2081.65	77.6361
2085.34	29.3635
2089.03	102.001
2092.72	84.6553
2096.41	78.8643
2100.09	57.1819
2103.77	51.9299
2107.46	45.4058
2111.14	47.0869
2114.81	89.6152
2118.49	51.6187
2122.16	55.6094
2125.84	20.5146
2129.51	68.4772
2133.18	90.391
2136.85	49.1891
2140.51	38.1721
2144.18	61.0626
2147.84	58.106
2151.5	73.5375
2155.16	52.4099
2158.82	59.8311
2162.48	94.0718
2166.13	53.7717
2169.79	60.616
2173.44	32.7706
2177.09	30.5964
2180.74	95.9486
2184.38	72.1536
2188.03	75.7091
2191.67	84.5367
2195.32	48.5958
2198.96	70.2203
2202.6	104.975
2206.23	80.7784
2209.87	119.989
2213.5	104.533
2217.14	87.2454
2220.77	125.157
2224.4	116.258
2228.03	97.9823
2231.65	84.4921
2235.28	85.8251
2238.9	73.1584
2242.52	65.0793
2246.14	107.151
2249.76	82.5603
2253.38	27.3252
2256.99	109.322
2260.6	34.1807
2264.21	61.865
2267.82	38.4604
2271.44	84.6108
2275.04	38.6724
2278.65	56.9552
2282.25	90.3422
2285.85	62.8043
2289.45	46.2225
2293.05	42.8058
2296.65	62.2523
2300.25	45.5873
2303.84	33.1897
2307.43	74.4952
2311.02	67.2081
2314.62	77.6039
2318.2	86.6586
2321.79	66.4545
2325.38	62.4269
2328.96	72.6718
2332.54	67.4028
2336.12	30.8735
2339.7	56.2727
2343.28	35.3916
2346.85	47.1759
2350.43	28.9069
2354	58.2222
2357.57	67.7393
2361.14	63.197
2364.71	68.9663
2368.27	76.9172
2371.84	22.1913
2375.4	25.6329
2378.96	30.2468
2382.52	22.1959
2386.08	43.8458
2389.64	32.8047
2393.19	17.7106
2396.75	35.3929
2400.3	46.6196
2403.85	10.9364
2407.4	-6.0564
2410.95	22.7145
2414.49	44.5453
2418.04	34.6809
2421.58	49.0914
2425.12	42.868
2428.66	25.0485
2432.2	26.088
2435.74	40.4573
2439.27	63.407
2442.81	6.36304
2446.34	79.2306
2449.87	-13.0297
2453.4	109.89
2456.93	34.745
2460.45	25.4275
2463.98	-49.7021
2467.5	51.3303
2471.02	52.9418
2474.54	-0.844116
2478.06	-26.4923
2481.58	49.2943
2485.09	24.1078
2488.61	2.73071
2492.12	-15.541
2495.63	11.6588
2499.14	44.7246
2502.65	20.8883
2506.15	38.8585
2509.66	15.6456
2513.16	-20.083
2516.66	8.7489
2520.16	-10.6476
2523.66	13.5898
2527.16	50.7361
2530.66	11.4503
2534.15	10.6224
2537.64	40.6302
2541.13	29.0143
2544.62	20.2653
2548.11	36.6438
2551.6	36.6949
2555.08	35.0919
2558.57	22.3608
2562.05	5.69287
2565.53	3.58057
2569.01	32.8221
2572.49	30.7648
2575.96	47.8905
2579.44	36.094
2582.91	41.3085
2586.38	51.9799
2589.85	64.5436
2593.32	16.4763
2596.79	34.5771
2600.25	75.8793
2603.72	32.126
2607.18	19.4615
2610.64	67.1698
2614.1	9.1377
2617.56	29.1685
2621.02	-8.83008
2624.47	-2.20557
2627.92	53.0896
2631.38	16.7548
2634.83	31.6484
2638.28	12.6549
2641.72	10.4722
2645.17	6.31494
2648.61	34.2311
2652.06	34.9138
2655.5	60.7831
2658.94	35.1476
2662.38	21.6788
2665.82	66.7786
2669.25	54.9725
2672.69	84.8257
2676.12	40.7985
2679.55	22.5942
2682.98	37.5923
2686.41	41.6003
2689.84	45.863
2693.26	23.5029
2696.69	45.2968
2700.11	35.7511
2703.53	36.92
2706.95	51.6663
2710.37	21.3496
2713.79	40.7096
2717.2	80.0568
2720.62	47.9714
2724.03	43.0364
2727.44	53.2517
2730.85	49.3359
2734.26	85.6753
2737.66	70.5352
2741.07	41.8831
2744.47	70.0958
2747.87	52.3098
2751.28	42.9238
2754.67	109.366
2758.07	52.7722
2761.47	56.8142
2764.86	86.9847
2768.26	72.4666
2771.65	88.942
2775.04	105.091
2778.43	56.8887
2781.82	53.7375
2785.2	50.5068
2788.59	59.4819
2791.97	87.0691
2795.35	107.307
2798.73	69.8494
2802.11	116.849
2805.49	58.8451
2808.87	73.8387
2812.24	88.7324
2815.62	129.585
2818.99	39.0032
2822.36	55.2295
2825.73	83.6808
2829.1	92.7296
2832.46	59.2843
2835.83	69.0055
2839.19	55.7914
2842.55	96.0638
2845.91	113.628
2849.27	119.974
2852.63	99.7477
2855.99	134.854
2859.34	132.908
2862.69	89.7986
2866.05	135.801
2869.4	93.4742
2872.75	150.641
2876.09	146.688
2879.44	144.589
2882.78	155.525
2886.13	109.706
2889.47	120.616
2892.81	112.074
2896.15	106.104
2899.49	97.9403
2902.82	165.183
2906.16	121.593
2909.49	126.045
2912.82	127.653
2916.16	146.881
2919.49	123.397
2922.81	142.426
2926.14	142.162
2929.46	142.754
2932.79	141.962
2936.11	188.325
2939.43	197.865
2942.75	174.456
2946.07	219.901
2949.39	177.775
2952.7	217.375
2956.02	187.754
2959.33	211.032
2962.64	180.76
2965.95	198.775
2969.26	238.196
2972.57	219.113
2975.87	218.612
2979.17	212.997
2982.48	216.866
2985.78	261.254
2989.08	213.688
2992.38	240.388
2995.68	257.847
2998.97	249.964
3002.27	268.302
3005.56	277.435
3008.85	249.954
3012.14	279.066
3015.43	281.756
3018.72	332.506
3022	294.587
3025.29	335.038
3028.57	321.674
3031.85	343.171
3035.14	332.429
3038.41	366.157
3041.69	392.351
3044.97	363.731
3048.24	370.049
3051.52	407.766
3054.79	438.828
3058.06	464.914
3061.33	430.713
3064.6	515.314
3067.87	506.624
3071.13	498.126
3074.4	505.949
3077.66	542.219
3080.92	564.547
3084.18	522.806
3087.44	506.094
3090.7	638.135
3093.95	661.518
3097.21	637.667
3100.46	675.63
3103.71	749.537
3106.96	753.205
3110.21	738.071
3113.46	746.664
3116.71	782.987
3119.95	827.914
3123.2	835.676
3126.44	850.984
3129.68	877.744
3132.92	956.898
3136.16	917.737
3139.4	972.88
3142.63	994.648
3145.87	1095.7
3149.1	1132.03
3152.33	1179.72
3155.56	1192.17
3158.79	1205.51
3162.02	1212.18
3165.25	1300.73
3168.47	1296.47
3171.69	1331.2
3174.92	1368.55
3178.14	1455.39
3181.36	1473.59
3184.58	1512.5
3187.79	1601.74
3191.01	1593.69
3194.22	1646.59
3197.43	1706.98
3200.65	1718.87
3203.86	1774.64
3207.07	1789.61
3210.27	1826.67
3213.48	1831.63
3216.69	1913.69
3219.89	1907.35
3223.09	1945.08
3226.29	1987.69
3229.49	2039.17
3232.69	2094.22
3235.89	2079.47
3239.08	2105.05
3242.28	2165.16
3245.47	2272.97
3248.66	2218.17
3251.85	2228.36
3255.04	2209.95
3258.23	2344.81
3261.42	2281.5
3264.6	2323.64
3267.79	2302.28
3270.97	2357.99
3274.15	2354.46
3277.33	2376.1
3280.51	2366.3
3283.68	2381.3
3286.86	2428.36
3290.04	2396.5
3293.21	2477.05
3296.38	2539.26
3299.55	2509.18
3302.72	2527.89
3305.89	2502.34
3309.06	2618.75
3312.22	2608.31
3315.39	2683.18
3318.55	2707.49
3321.71	2782.91
3324.87	2833.62
3328.03	2888.09
3331.19	2913.43
3334.34	2926.82
3337.5	2883.04
3340.65	3002.47
3343.81	3136.8
3346.96	3304.48
3350.11	3393.02
3353.25	3491.48
3356.4	3619.42
3359.55	3863.04
3362.69	4052.25
3365.84	4451.25
3368.98	4920.45
3372.12	5509.65
3375.26	6581.33
3378.4	7957.94
3381.53	9575.49
3384.67	9828.9
3387.8	8266.84
3390.94	6649.44
3394.07	5660.06
3397.2	5198.39
3400.33	4869.95
3403.46	4768.48
3406.58	4683.38
3409.71	4638.3
3412.83	4584.06
3415.96	4696.88
3419.08	4931.56
3422.2	5315.14
3425.32	6392.71
3428.44	9540.8
3431.55	15937.1
3434.67	19260.1
3437.78	13132.7
3440.89	7522.79
3444	5379.27
3447.12	4699.94
3450.22	4379.52
3453.33	4244.17
3456.44	4005.34
3459.54	3979.69
3462.65	3970.03
3465.75	3864.03
3468.85	3802.1
3471.95	3819.53
3475.05	3797.68
3478.15	3776.15
3481.24	3684.82
3484.34	3660.97
3487.43	3605.51
3490.53	3656.52
3493.62	3676.55
3496.71	3648.83
3499.79	3760.19
3502.88	3805.33
3505.97	3897
3509.05	4087.52
3512.14	4325.11
3515.22	4532.86
3518.3	4490.33
3521.38	4135.29
3524.46	3836.08
3527.54	3467.24
3530.61	3203.16
3533.69	3007.3
3536.76	2887.14
3539.83	2816.3
3542.9	2677.38
3545.97	2592.16
3549.04	2566.72
3552.11	2418.48
3555.18	2370.05
3558.24	2275.59
3561.3	2171.64
3564.37	2158.27
3567.43	2084.39
3570.49	2065.81
3573.55	1961.46
3576.61	1936.62
3579.66	1909.61
3582.72	1830.12
3585.77	1741.07
3588.82	1758.89
3591.87	1625.82
3594.92	1650.84
3597.97	1547.9
3601.02	1542.34
3604.07	1494.88
3607.11	1454.97
3610.16	1404.58
3613.2	1379.63
3616.24	1286.8
3619.28	1307.42
3622.32	1252.68
3625.36	1245.29
3628.39	1165.31
3631.43	1118.18
3634.46	1088.47
3637.5	1030.98
3640.53	1034.93
3643.56	1006.56
3646.59	902.549
3649.62	897.634
3652.64	833.802
3655.67	801.212
3658.69	800.933
3661.72	717.452
3664.74	684.794
3667.76	635.234
3670.78	585.837
3673.79	579.911
3676.81	547.666
3679.83	443.513
3682.84	452.68
3685.86	418.388
3688.87	408.72
3691.88	361.207
3694.89	315.234
3697.9	289.324
3700.91	301.445
3703.91	251.851
3706.92	249.559
3709.92	231.917
3712.92	245.441
3715.92	182.907
3718.92	150.671
3721.92	193.489
3724.92	180.002
3727.92	189.255
3730.91	135.521
3733.91	175.896
3736.9	139.963
3739.89	107.685
3742.88	128.572
3745.87	122.678
3748.86	116.666
3751.85	107.766
3754.83	77.0847
3757.82	66.3507
3760.8	73.5317
3763.78	81.6421
3766.76	88.8884
3769.74	89.6393
3772.72	80.1112
3775.7	79.1893
3778.67	66.09
3781.65	44.5365
3784.62	31.563
3787.6	40.3802
3790.57	72.0454
3793.54	44.3967
3796.51	47.9785
3799.47	22.467
3802.44	52.7662
3805.41	57.6232
3808.37	39.8864
3811.33	25.0219
3814.3	35.7148
3817.26	34.1743
3820.22	42.1326
3823.18	27.4589
3826.13	52.6173
3829.09	55.9749
3832.04	46.1564
3835	70.6064
3837.95	1.03052
3840.9	30.248
3843.85	68.0923
3846.8	37.4656
3849.75	59.2982
3852.69	26.8276
3855.64	8.64185
3858.58	54.4891
3861.53	-0.0959473
3864.47	26.6018
3867.41	16.8411
3870.35	0.299927
3873.29	23.9966
3876.22	43.7543
3879.16	40.3427
3882.1	64.6346
3885.03	16.7321
3887.96	38.9279
3890.89	50.5094
3893.82	21.5608
3896.75	21.2896
3899.68	23.8744
3902.61	14.7367
3905.53	55.7178
3908.46	31.2716
3911.38	38.4308
3914.3	15.6545
3917.23	66.1155
3920.15	33.8263
3923.06	8.10999
3925.98	18.7424
3928.9	11.0264
3931.81	43.7897
3934.73	21.259
3937.64	19.1521
3940.55	51.4431
3943.46	6.20227
3946.37	47.2537
3949.28	12.7819
3952.19	34.8545
3955.09	20.6514
3958	27.5936
3960.9	19.2646
3963.8	41.6857
3966.71	21.9885
3969.61	81.0259
3972.51	57.5354
3975.4	18.5864
3978.3	26.5984
3981.2	8.63831
3984.09	33.8717
3986.99	26.4176
3989.88	4.31909
3992.77	30.5289
3995.66	24.043
3998.55	0.283569
4001.43	68.9758