File: Data/3-Raman/processed/bu19w-d-ff2-fi09-v_1800 (450-850nm)_532nm_edge_100%_x100_vis_lwd_h50um_30sx2_01.txt
#Acq. time (s)=	30
#Accumulations=	2
#Range (cm-¹)=	1200...2365
#Windows=	3
#Auto scanning=	Off
#Autofocus=	Off
#Macrospot=	Off
#AutoExposure=	Off
#Spike filter=	Multiple accum.
#Delay time (s)=	2
#Binning=	1
#Readout mode=	Signal
#DeNoise=	Off
#ICS correction=	On
#Dark correction=	Off
#Inst. Process=	Off
#Detector Gain=	Best Dynamic
#Detector ADC=	50 kHz HS
#Detector temperature (°C)=	-60.09
#Instrument=	LabRAM HR Evol
#Detector=	SIN-EM FIVIS
#Objective=	x100_VIS_LWD
#Grating=	1800 (450-850nm)
#ND Filter=	100%
#Laser=	532nm_Edge
#Hole=	49.98
#Temperature=	0
#Range=	Visible
#StageXY=	75x50mm Scan+
#StageZ=	Z motor
#X (µm)=	0
#Y (µm)=	0
#Z (µm)=	70.2
#Full time(mm:ss)=	3:18
#Project=	21_11_22
#Sample=	BU19w
#Site=
#Title=	BU19w-D-FF2-FI09-V_1800 (450-850nm)_532nm_Edge_100%_x100_VIS_LWD_H50um_30sX2
#Remark=
#Date=	22.11.2021 13:31
#Acquired=	22.11.2021 13:31:07
#Base:Fit=	16.12.2021 17:39:50
#Base:Fit=	16.12.2021 17:43:51
#Base:Sub=	16.12.2021 17:43:52
1202.84	7.31549
1203.95	9.12299
1205.06	14.1874
1206.17	7.49313
1207.29	1.91552
1208.39	6.98785
1209.51	7.79794
1210.62	7.57347
1211.72	-1.11824
1212.84	0.846886
1213.94	-0.425068
1215.05	-2.73362
1216.16	1.35714
1217.27	-0.902378
1218.38	-6.32611
1219.49	1.99915
1220.6	-1.34756
1221.71	-0.422531
1222.81	-3.66298
1223.92	-0.567593
1225.03	0.334339
1226.14	4.38145
1227.24	1.31281
1228.35	10.6101
1229.46	22.1362
1230.56	36.8091
1231.67	32.6236
1232.78	47.3733
1233.88	46.3077
1234.99	49.3541
1236.09	30.3834
1237.2	24.0894
1238.3	23.0761
1239.41	11.5577
1240.51	11.6164
1241.62	13.7584
1242.72	7.47592
1243.83	10.6419
1244.93	15.9254
1246.03	19.0958
1247.14	22.3055
1248.24	28.5966
1249.34	29.6718
1250.45	39.0996
1251.55	35.0579
1252.65	34.1245
1253.75	37.3742
1254.86	24.9302
1255.96	19.7855
1257.06	22.0287
1258.16	24.1597
1259.26	13.954
1260.36	11.8481
1261.46	22.6207
1262.56	27.9101
1263.66	56.2572
1264.76	32.4282
1265.86	9.62271
1266.96	3.48289
1268.06	4.63254
1269.16	4.78294
1270.26	2.89182
1271.36	4.13578
1272.46	8.49291
1273.56	3.43839
1274.66	0.481575
1275.76	6.99053
1276.85	4.0095
1277.95	12.5888
1279.05	18.056
1280.15	19.2593
1281.24	58.2471
1282.34	176.594
1283.44	738.053
1284.53	604.216
1285.63	83.2785
1286.73	22.4526
1287.82	20.544
1288.92	12.2919
1290.01	7.20452
1291.11	6.38435
1292.21	1.30523
1293.3	-1.60024
1294.4	0.694595
1295.49	4.02466
1296.58	1.02396
1297.68	1.22081
1298.77	-0.699837
1299.87	-3.67142
1300.96	-1.3846
1302.05	-1.19992
1303.15	-1.04109
1304.24	2.30322
1305.33	-4.88891
1306.42	2.69287
1307.52	-0.278065
1308.61	0.970184
1309.7	-1.99252
1310.79	-1.81466
1311.88	3.65329
1312.98	-5.64611
1314.07	-0.183201
1315.16	-5.2687
1316.25	-2.96819
1317.34	-2.78207
1318.43	-0.50543
1319.52	1.75899
1320.61	-4.39632
1321.7	-2.10228
1322.79	2.27722
1323.88	1.34832
1324.97	0.531412
1326.06	6.02791
1327.15	3.03703
1328.23	0.0255508
1329.32	-1.94674
1330.41	2.39692
1331.5	0.435635
1332.59	6.87956
1333.67	3.88468
1334.76	-2.24423
1335.85	1.04789
1336.94	1.21648
1338.02	2.43614
1339.11	-0.547932
1340.2	2.73204
1341.28	2.89458
1342.37	3.04535
1343.45	3.16537
1344.54	6.41669
1345.63	-0.734314
1346.71	2.53028
1347.8	4.74622
1348.88	1.75874
1349.96	5.05347
1351.05	3.16265
1352.13	11.5544
1353.22	4.42832
1354.3	4.56214
1355.39	5.72884
1356.47	4.81581
1357.55	3.89574
1358.63	2.99365
1359.72	9.33803
1360.8	5.3474
1361.88	7.55753
1362.97	12.8415
1364.05	16.0376
1365.13	13.0686
1366.21	14.2465
1367.29	13.3346
1368.37	19.63
1369.45	45.4769
1370.54	16.6982
1371.62	12.6893
1372.7	18.9933
1373.78	23.2162
1374.86	14.0532
1375.94	21.4533
1377.02	30.8237
1378.09	35.9655
1379.18	34.9939
1380.25	51.4356
1381.33	46.3753
1382.41	66.0473
1383.49	69.3119
1384.57	95.828
1385.65	196.374
1386.72	1068.81
1387.8	1120.64
1388.88	131.079
1389.96	60.4172
1391.03	34.8983
1392.11	29.873
1393.19	27.9372
1394.26	22.8892
1395.34	20.9236
1396.42	16.9375
1397.49	18.0629
1398.57	14.0715
1399.64	16.261
1400.72	17.409
1401.79	11.3078
1402.87	20.5945
1403.94	13.4854
1405.02	13.573
1406.09	22.8892
1407.17	35.2848
1408.24	90.6412
1409.31	80.4427
1410.39	24.2861
1411.46	17.1139
1412.53	10.0139
1413.61	13.1702
1414.68	6.05812
1415.75	8.1815
1416.82	10.2912
1417.9	11.3534
1418.97	8.33269
1420.04	11.5354
1421.11	8.41417
1422.18	4.36275
1423.26	5.45213
1424.33	10.6032
1425.4	6.52853
1426.47	6.58551
1427.54	6.65703
1428.61	3.65939
1429.68	5.74396
1430.75	3.70176
1431.82	1.70316
1432.89	8.91788
1433.96	2.80372
1435.02	3.86135
1436.09	3.90787
1437.16	6.01272
1438.23	-0.0966778
1439.3	8.13918
1440.37	3.04528
1441.43	3.07271
1442.5	2.09689
1443.57	-0.956627
1444.64	-0.93405
1445.7	6.27907
1446.77	2.20111
1447.84	0.166971
1448.9	2.23466
1449.97	1.23323
1451.04	0.235474
1452.1	5.38003
1453.17	2.33239
1454.23	2.34427
1455.3	2.3602
1456.36	1.35813
1457.43	2.39757
1458.49	1.38099
1459.56	1.38286
1460.62	1.37956
1461.69	-0.630716
1462.75	0.349607
1463.81	-0.664312
1464.88	4.44467
1465.94	2.41269
1467	1.38997
1468.07	3.42649
1469.13	-3.70484
1470.19	5.46402
1471.25	2.40657
1472.32	0.381367
1473.38	0.38069
1474.44	3.42748
1475.5	1.39087
1476.56	-1.66637
1477.62	-1.68159
1478.68	2.37275
1479.75	-0.655455
1480.81	0.365499
1481.87	2.35439
1482.93	-0.692707
1483.99	1.33665
1485.05	2.33883
1486.11	2.32042
1487.17	6.35971
1488.22	-0.733608
1489.28	-0.737881
1490.34	4.31176
1491.4	-1.75781
1492.46	3.28435
1493.52	-1.78957
1494.58	-0.789755
1495.63	-1.80492
1496.69	-2.81571
1497.75	2.22777
1498.81	-3.84169
1499.86	-2.84494
1500.92	0.164711
1501.98	-1.85695
1503.03	-3.89494
1504.09	-2.89367
1505.15	0.121519
1506.2	1.12127
1507.26	-1.90724
1508.31	0.0824242
1509.37	-1.97411
1510.42	0.00514603
1511.48	0.00808334
1512.53	-1.02172
1513.59	3.96559
1514.64	-2.06387
1515.7	-1.06433
1516.75	2.94373
1517.8	-0.0789738
1518.86	1.92093
1519.91	2.90425
1520.96	-2.14077
1522.02	-0.156485
1523.07	0.842426
1524.12	0.842422
1525.17	-2.18232
1526.23	-2.19992
1527.28	-0.213495
1528.33	-1.21409
1529.38	-1.22819
1530.43	0.785725
1531.48	-0.225349
1532.53	1.75995
1533.59	-1.28469
1534.64	-0.315722
1535.69	-0.338684
1536.74	0.679201
1537.79	-2.30673
1538.84	0.677855
1539.89	2.64896
1540.94	-1.3878
1541.98	-0.387009
1543.03	8.63516
1544.08	0.615732
1545.13	-0.406805
1546.18	-0.428051
1547.23	0.567503
1548.28	-2.39494
1549.33	-1.40103
1550.37	-0.421169
1551.42	-0.445498
1552.47	0.52891
1553.52	2.52052
1554.56	1.51239
1555.61	4.48881
1556.65	-2.54745
1557.7	3.43074
1558.75	-0.572569
1559.79	-0.571127
1560.84	-1.58371
1561.88	-0.576761
1562.93	-0.703016
1563.98	2.36655
1565.02	2.37597
1566.07	1.37374
1567.11	-1.6428
1568.15	1.34735
1569.2	-0.66745
1570.24	5.30364
1571.29	-3.68974
1572.33	0.316027
1573.37	5.3091
1574.42	-2.7116
1575.46	3.24454
1576.5	2.24033
1577.55	2.24151
1578.59	-0.763845
1579.63	4.20155
1580.67	-3.77604
1581.72	3.19296
1582.76	-0.796448
1583.8	1.17575
1584.84	-2.81555
1585.88	1.16814
1586.92	1.17314
1587.96	5.16011
1589	3.16099
1590.04	4.13207
1591.08	-0.871527
1592.12	0.123804
1593.16	0.115528
1594.2	0.116673
1595.24	2.1037
1596.28	0.0985985
1597.32	2.06843
1598.36	4.0261
1599.4	4.00236
1600.44	2.99314
1601.48	-0.965977
1602.51	2.00355
1603.55	3.00439
1604.59	1.03193
1605.63	1.03215
1606.66	1.01572
1607.7	1.0648
1608.74	1.96386
1609.77	5.60043
1610.81	3.22103
1611.85	0.967901
1612.88	1.7407
1613.92	4.27224
1614.95	3.66527
1615.99	3.351
1617.03	5.26464
1618.06	1.01233
1619.1	3.70841
1620.13	6.60649
1621.17	4.37421
1622.2	4.78663
1623.23	6.7683
1624.27	2.33664
1625.3	4.56017
1626.34	5.76783
1627.37	4.11461
1628.4	4.64581
1629.44	3.91278
1630.47	7.62337
1631.29	3.92507
1632.33	5.9062
1633.38	5.90707
1634.42	3.93356
1635.47	5.90591
1636.51	7.88442
1637.56	0.0212994
1638.6	4.95992
1639.65	2.99696
1640.69	4.97466
1641.73	2.02452
1642.78	4.0112
1643.82	5.98347
1644.86	5.9875
1645.91	6.99604
1646.95	3.08254
1647.99	4.09886
1649.03	3.13488
1650.08	6.1006
1651.12	6.11884
1652.16	3.18411
1653.2	2.2359
1654.24	9.1649
1655.28	4.23711
1656.33	10.1576
1657.37	4.24795
1658.41	6.25235
1659.45	7.25276
1660.49	3.36255
1661.53	5.33066
1662.57	3.35419
1663.61	4.41383
1664.65	3.39939
1665.69	3.41051
1666.72	2.46401
1667.76	5.45975
1668.8	3.4993
1669.84	4.50951
1670.88	4.53161
1671.92	4.56165
1672.96	6.56876
1674	1.64154
1675.03	2.64307
1676.07	3.636
1677.11	4.63494
1678.15	1.68229
1679.18	1.70064
1680.22	1.71939
1681.25	3.71189
1682.29	1.75066
1683.33	5.72125
1684.36	0.810822
1685.4	4.77344
1686.43	3.79224
1687.47	3.80132
1688.51	-0.115938
1689.54	-2.06707
1690.58	1.88393
1691.61	0.902443
1692.64	-1.04656
1693.68	4.89358
1694.71	3.91568
1695.75	2.936
1696.78	0.00259209
1697.81	-0.963753
1698.85	0.034586
1699.88	1.02611
1700.91	3.00802
1701.95	4.01636
1702.98	1.08747
1704.01	2.07457
1705.04	1.0951
1706.08	-1.84501
1707.11	-2.80821
1708.14	0.155695
1709.17	0.181561
1710.2	1.15845
1711.23	2.13473
1712.27	-2.7317
1713.3	0.224943
1714.33	2.18037
1715.36	-1.72804
1716.39	-1.71494
1717.42	-1.69252
1718.45	1.23601
1719.48	0.268543
1720.51	1.24705
1721.54	1.26467
1722.56	-1.64517
1723.59	-0.662834
1724.62	2.25577
1725.65	2.26355
1726.68	0.307833
1727.71	-0.638254
1728.74	-0.598001
1729.76	1.35085
1730.79	-0.5783
1731.82	0.385857
1732.85	-0.573839
1733.87	-0.559792
1734.9	-0.547108
1735.93	-0.538897
1736.95	3.29801
1737.98	0.418653
1739.01	0.426498
1740.03	-0.515232
1741.06	0.455776
1742.08	-1.4417
1743.11	3.35773
1744.13	1.44811
1745.16	-1.40948
1746.18	1.47734
1747.21	-0.399523
1748.23	-0.369293
1749.26	1.54909
1750.28	-0.355011
1751.31	-0.346653
1752.33	-1.28923
1753.35	0.623745
1754.38	0.62418
1755.4	-2.20736
1756.42	-1.23416
1757.44	-1.21707
1758.47	-1.20648
1759.49	1.66
1760.51	0.732368
1761.53	0.760572
1762.56	-1.11328
1763.58	1.76223
1764.6	-2.9825
1765.62	-1.0669
1766.64	-1.07425
1767.66	-2.95089
1768.68	2.78266
1769.7	-1.94595
1770.72	0.934092
1771.74	-2.85178
1772.76	0.0371399
1773.78	0.0586014
1774.8	2.92444
1775.82	-0.88074
1776.84	-1.82364
1777.86	-0.848182
1778.88	0.12479
1779.9	0.152349
1780.92	-0.77652
1781.94	2.1128
1782.95	-0.735217
1783.97	1.19306
1784.99	2.19169
1786.01	0.323868
1787.03	-2.52031
1788.04	1.33205
1789.06	1.32998
1790.08	-0.566288
1791.09	-1.50611
1792.11	0.431477
1793.13	1.43039
1794.14	0.49719
1795.16	-0.440898
1796.17	0.535352
1797.19	0.538547
1798.21	0.546138
1799.22	0.56139
1800.24	-0.376355
1801.25	1.56771
1802.27	1.59409
1803.28	-1.26857
1804.29	-2.21453
1805.31	-1.23771
1806.32	0.704463
1807.34	0.718951
1808.35	-0.235085
1809.36	-0.222495
1810.38	0.762105
1811.39	0.785639
1812.4	1.77794
1813.41	-0.140531
1814.43	0.833521
1815.44	0.838276
1816.45	-0.111156
1817.46	1.83991
1818.47	-0.0766001
1819.49	-1.02719
1820.5	1.8881
1821.51	0.928326
1822.52	-0.0244188
1823.53	-0.0139294
1824.54	-0.00147724
1825.55	-0.959507
1826.56	0.0123901
1827.57	0.983724
1828.58	3.90073
1829.59	-2.86356
1830.6	2.96457
1831.61	-0.90771
1832.62	1.01032
1833.63	-0.851423
1834.64	0.0682783
1835.65	1.01353
1836.65	-0.874541
1837.66	0.0790281
1838.67	-2.84109
1839.68	0.0429993
1840.69	-0.913195
1841.7	1.02246
1842.7	0.0639105
1843.71	0.0944271
1844.72	1.00484
1845.72	-1.87256
1846.73	1.0099
1847.74	-0.927464
1848.74	0.0270348
1849.75	0.990239
1850.75	-0.92929
1851.76	-0.940346
1852.76	0.966682
1853.77	0.967008
1854.78	-0.948926
1855.78	0.00120258
1856.79	-0.964081
1857.79	-0.955864
1858.79	0.0132895
1859.8	1.92239
1860.8	1.91005
1861.81	-0.00914955
1862.81	-0.97738
1863.81	-0.0457134
1864.82	1.83698
1865.82	-0.0660009
1866.82	1.83578
1867.83	0.884284
1868.83	-0.0680265
1869.83	0.874493
1870.83	-1.02907
1871.84	1.80591
1872.84	-1.05505
1873.84	0.81917
1874.84	0.784406
1875.84	3.66334
1876.84	-0.106804
1877.84	-0.107907
1878.84	-2.0179
1879.84	-0.159202
1880.84	-0.152342
1881.84	-1.11556
1882.85	0.789041
1883.85	0.796623
1884.84	1.72323
1885.84	-1.12446
1886.84	-0.193654
1887.84	-1.12745
1888.84	3.57915
1889.84	-0.19329
1890.84	0.721507
1891.84	0.714301
1892.83	-0.222823
1893.83	-0.214355
1894.83	-0.209584
1895.83	-0.216906
1896.83	1.65028
1897.82	-0.232865
1898.82	-1.16366
1899.82	-3.0385
1900.81	-2.10425
1901.81	-3.04803
1902.81	-3.05177
1903.8	0.692713
1904.8	0.690211
1905.79	-0.243644
1906.79	0.70649
1907.79	1.66629
1908.78	0.729623
1909.78	2.60861
1910.77	0.727158
1911.77	-0.201684
1912.76	-3.02676
1913.76	0.739538
1914.75	-0.214657
1915.74	-0.210467
1916.74	-1.13697
1917.73	0.75355
1918.72	0.764258
1919.72	-0.182692
1920.71	2.64364
1921.7	0.742154
1922.7	2.6371
1923.69	-1.13071
1924.68	-1.12301
1925.67	-0.172682
1926.66	0.783037
1927.66	-0.151576
1928.65	4.59476
1929.64	0.785732
1930.63	-1.1168
1931.62	-1.08458
1932.61	-2.0062
1933.61	-0.111897
1934.6	0.825125
1935.59	-1.08839
1936.58	0.82383
1937.57	-0.122627
1938.56	2.75422
1939.55	-0.116874
1940.54	0.840207
1941.52	-1.06761
1942.51	-2.0132
1943.5	0.862302
1944.49	-1.05374
1945.48	-2.01506
1946.47	-1.0558
1947.46	-1.04184
1948.44	2.81463
1949.43	1.8681
1950.42	-1.01052
1951.41	2.79424
1952.39	-1.05744
1953.38	-1.03856
1954.37	0.892928
1955.36	-0.0619726
1956.34	0.892413
1957.33	-0.0788145
1958.31	1.82725
1959.3	-2.97639
1960.29	-1.05793
1961.27	0.863003
1962.26	-1.06109
1963.24	-0.0985918
1964.23	-0.0923986
1965.21	2.79027
1966.2	0.858932
1967.18	1.79742
1968.17	-0.135349
1969.15	1.77796
1970.14	-1.10367
1971.12	-2.07526
1972.1	1.75538
1973.09	-0.157261
1974.07	2.71962
1975.05	3.66772
1976.04	-1.1357
1977.02	-0.178965
1978	-0.189524
1978.98	2.67492
1979.97	-1.16573
1980.95	-1.1801
1981.93	1.68016
1982.91	1.66878
1983.89	2.6292
1984.88	-3.11802
1985.86	-0.284149
1986.84	1.58689
1987.82	-1.2654
1988.8	0.661044
1989.78	-0.324729
1990.76	-1.22378
1991.74	0.551031
1992.72	0.215484
1993.7	0.426188
1994.68	-1.35465
1995.66	-1.83505
1996.64	1.60926
1997.62	0.783064
1998.6	-0.681213
1999.57	-1.58286
2000.55	-0.16159
2001.53	-1.62484
2002.51	-1.30828
2003.49	-2.52056
2004.47	-0.8485
2005.44	1.31533
2006.42	1.14416
2007.4	-0.184458
2008.38	-0.0643435
2009.35	-0.911003
2010.33	-0.475003
2011.3	-0.650204
2012.18	-0.0302172
2013.17	-0.964957
2014.16	-0.0123777
2015.15	-0.968143
2016.14	0.883646
2017.13	1.80567
2018.11	1.80291
2019.1	-1.94557
2020.09	-0.0864105
2021.08	-0.101017
2022.06	-0.120101
2023.05	-1.07249
2024.04	-1.05059
2025.02	-0.10602
2026.01	-1.94964
2027	-1.06065
2027.98	-0.150864
2028.97	-2.9439
2029.96	0.807189
2030.94	2.69184
2031.93	0.778657
2032.91	1.74367
2033.9	-2.93192
2034.88	1.74269
2035.87	-2.94071
2036.85	-0.149895
2037.83	-0.167444
2038.82	-0.177398
2039.8	-0.187557
2040.79	0.753138
2041.77	-2.04127
2042.75	0.757425
2043.74	-0.157849
2044.72	0.746108
2045.7	-2.05568
2046.69	0.752209
2047.67	1.70142
2048.65	0.757921
2049.63	0.75826
2050.62	0.767022
2051.6	1.71377
2052.58	-0.164955
2053.56	0.761912
2054.54	-2.97932
2055.52	0.76788
2056.5	0.775953
2057.48	0.770733
2058.46	-0.164558
2059.45	-2.03752
2060.43	-0.158768
2061.4	1.71937
2062.39	0.7914
2063.37	1.74134
2064.34	-2.01302
2065.32	-0.129313
2066.3	-2.01073
2067.28	0.792961
2068.26	0.812085
2069.24	-0.114429
2070.22	-0.120875
2071.2	1.76009
2072.18	0.8289
2073.15	-1.03814
2074.13	0.842987
2075.11	-0.115262
2076.09	-1.99827
2077.06	2.73535
2078.04	-0.0991535
2079.02	-0.105601
2080	-1.99609
2080.97	-0.111681
2081.95	-0.115137
2082.93	1.77159
2083.9	0.836824
2084.88	-1.05397
2085.85	1.78298
2086.83	-1.05263
2087.8	0.842259
2088.78	1.79453
2089.75	1.81122
2090.73	0.873522
2091.7	0.876143
2092.68	1.81417
2093.65	-0.0974493
2094.63	0.838272
2095.6	0.827394
2096.57	-2.02709
2097.55	-2.0318
2098.52	-0.129324
2099.5	-1.08404
2100.47	-0.148141
2101.44	1.74461
2102.41	0.799057
2103.39	-0.147339
2104.36	-0.149993
2105.33	-1.11853
2106.3	-1.13273
2107.27	-1.13244
2108.25	3.61076
2109.22	0.74836
2110.19	-0.203609
2111.16	-1.15321
2112.13	-0.210477
2113.1	-0.2219
2114.07	1.66213
2115.04	3.54957
2116.01	-1.218
2116.99	-0.289057
2117.96	-1.24481
2118.92	0.655404
2119.9	0.658731
2120.86	0.653862
2121.83	-0.316792
2122.8	-0.348315
2123.77	0.575027
2124.74	0.557734
2125.71	-0.399405
2126.68	-0.410331
2127.65	-1.36695
2128.61	0.506189
2129.58	0.489097
2130.55	0.476078
2131.52	1.41325
2132.48	-1.42866
2133.45	1.37908
2134.42	1.36903
2135.39	2.30271
2136.35	-1.4708
2137.32	-1.49622
2138.28	-1.51094
2139.25	-2.46848
2140.22	0.363137
2141.18	0.312121
2142.15	-1.57169
2143.12	2.17858
2144.08	1.2231
2145.05	0.265715
2146.01	-0.690935
2146.98	1.1591
2147.94	-0.73557
2148.9	0.199885
2149.87	0.189077
2150.83	-4.51524
2151.8	-0.793438
2152.76	-0.82509
2153.72	0.0900326
2154.69	0.0827198
2155.65	1.94832
2156.61	-0.871954
2157.58	-1.82901
2158.54	0.0205898
2159.5	2.807
2160.47	-0.0072279
2161.43	-1.88989
2162.39	1.82297
2163.35	-1.91544
2164.31	-1.00274
2165.27	-2.8937
2166.24	-1.0446
2167.2	-1.03723
2168.16	1.74719
2169.12	-0.149228
2170.08	-0.167885
2171.04	-1.10471
2172	1.67574
2172.96	0.733373
2173.92	0.71752
2174.88	-0.22097
2175.84	-1.16737
2176.8	0.680435
2177.76	-3.97305
2178.72	0.654938
2179.68	0.638787
2180.64	0.616227
2181.59	1.52379
2182.55	-1.2612
2183.51	2.44847
2184.47	0.60366
2185.43	-1.26216
2186.38	-1.28453
2187.34	1.47576
2188.3	3.32463
2189.26	0.539703
2190.21	-0.388389
2191.17	-2.23531
2192.13	1.47941
2193.08	1.45838
2194.04	-0.424644
2195	1.41802
2195.95	1.42558
2196.91	-0.418669
2197.86	0.534632
2198.82	0.514111
2199.78	1.41497
2200.73	0.494413
2201.69	2.39199
2202.64	1.40156
2203.59	0.467896
2204.55	-1.39854
2205.5	-1.39224
2206.46	0.471935
2207.41	2.33158
2208.37	-0.458475
2209.32	-0.451884
2210.27	-1.3921
2211.23	0.466919
2212.18	-0.454379
2213.13	1.41111
2214.09	2.33866
2215.04	-1.39807
2215.99	1.40417
2216.94	0.477093
2217.9	0.474422
2218.85	1.39217
2219.8	0.451401
2220.75	0.460892
2221.7	0.478048
2222.65	1.42894
2223.6	0.505135
2224.55	1.45356
2225.5	2.38908
2226.46	-1.36421
2227.41	0.524975
2228.36	0.53949
2229.31	1.49418
2230.26	3.39002
2231.21	-2.2438
2232.16	-1.30682
2233.11	-0.372348
2234.05	0.574125
2235	-0.34417
2235.95	0.621538
2236.9	0.629059
2237.85	-0.314038
2238.8	3.47476
2239.75	-0.288911
2240.69	2.54313
2241.64	1.60624
2242.59	-0.254981
2243.54	-0.236193
2244.48	1.6715
2245.43	-0.215264
2246.38	0.735196
2247.32	1.69242
2248.27	1.68647
2249.22	-0.196791
2250.16	1.72493
2251.11	0.806664
2252.06	-2.02309
2253	-0.114194
2253.95	0.856703
2254.89	0.878273
2255.84	-1.00501
2256.78	0.914935
2257.73	-1.91743
2258.67	0.960307
2259.62	0.0283604
2260.56	2.91684
2261.51	-1.81226
2262.45	0.125897
2263.39	-1.77203
2264.34	0.140001
2265.28	-0.808336
2266.22	0.166895
2267.17	-1.70702
2268.11	0.234299
2269.05	1.21909
2270	-1.62891
2270.94	-0.649926
2271.88	-2.54206
2272.82	-0.605441
2273.77	0.385815
2274.71	-0.535057
2275.65	-1.45866
2276.59	-1.44093
2277.53	2.39939
2278.47	1.453
2279.41	0.520658
2280.36	-1.36061
2281.3	1.57162
2282.24	0.6475
2283.18	1.62573
2284.12	-4.11349
2285.06	-0.224625
2286	-0.207758
2286.94	-0.203935
2287.88	-1.14286
2288.82	1.78392
2289.75	0.860478
2290.69	0.897845
2291.63	-1.00679
2292.57	-0.0252447
2293.51	-0.011301
2294.45	0.0217628
2295.39	-0.897699
2296.32	0.106386
2297.26	0.13891
2298.2	-0.791607
2299.14	1.17012
2300.07	0.23147
2301.01	-0.703948
2301.95	-0.666472
2302.89	-2.56343
2303.82	3.2692
2304.76	-1.53766
2305.69	-1.51153
2306.63	1.4263
2307.57	-1.43567
2308.5	-0.451935
2309.44	-1.40745
2310.37	-3.31072
2311.31	-0.368215
2312.24	0.645355
2313.18	-0.306961
2314.11	-1.25767
2315.05	-0.255493
2315.98	-0.238232
2316.92	2.67775
2317.85	2.70789
2318.78	3.71375
2319.72	2.79177
2320.65	1.85425
2321.58	1.88101
2322.52	5.75204
2323.45	5.76149
2324.38	9.62602
2325.32	12.5332
2326.25	23.1464
2327.18	84.8088
2328.11	201.329
2329.05	42.491
2329.98	14.5454
2330.91	1.0781
2331.84	4.9341
2332.77	0.141729
2333.7	1.11924
2334.63	1.13348
2335.56	-0.776746
2336.5	1.16083
2337.43	0.207537
2338.36	-0.753887
2339.29	1.16188
2340.22	2.12532
2341.15	0.215874
2342.08	1.18181
2343.01	0.21898
2343.93	5.00594
2344.86	0.218522
2345.79	1.18089
2346.72	1.1635
2347.65	2.0678
2348.58	2.12636
2349.51	0.16401
2350.44	0.128418
2351.36	1.06635
2352.29	1.05992
2353.22	-0.866435
2354.15	-0.90102
2355.07	3.82418
2356	-2.85627
2356.93	-0.0360937
2357.86	-1.02416
2358.78	-0.118254
2359.71	-3.00519
2360.63	-0.20848
2361.56	3.52954
2362.49	0.641881
2363.41	1.51683
2364.34	0.541848
2364.8	0.522299