File: Data/3-Raman/processed/bu19w-e-ff11-fi07-v_150 (500nm)_633nm_edge_100%_x100_vis_h50um_60sx2_01_0.txt
#Acq. time (s)=	60
#Accumulations=	2
#Range (cm-¹)=	100...4000
#Windows=	1
#Auto scanning=	Off
#Autofocus=	Off
#Macrospot=	Off
#AutoExposure=	Off
#Spike filter=	Multiple accum.
#Delay time (s)=	2
#Binning=	1
#Readout mode=	Signal
#DeNoise=	Off
#ICS correction=	On
#Dark correction=	Off
#Inst. Process=	Off
#Detector Gain=	Best Dynamic
#Detector ADC=	50 kHz HS
#Detector temperature (°C)=	-60.09
#Instrument=	LabRAM HR Evol
#Detector=	SIN-EM FIVIS
#Objective=	x100_VIS
#Grating=	150 (500nm)
#ND Filter=	100%
#Laser=	633nm_Edge
#Hole=	49.98
#Temperature=	0
#Range=	Visible
#StageXY=	75x50mm Scan+
#StageZ=	Z motor
#X (µm)=	0
#Y (µm)=	0
#Z (µm)=	-271
#Full time(mm:ss)=	2:04
#Project=	21_11_04
#Sample=	BU19w
#Site=
#Title=	BU19w-E-FF11-FI07-V_150 (500nm)_633nm_Edge_100%_x100_VIS_H50um_60sX2
#Remark=
#Date=	04.11.2021 16:01
#Acquired=	04.11.2021 16:01:34
#Base:Fit=	16.12.2021 17:39:50
#Base:Edit=	16.12.2021 17:52:23
#Base:Edit=	16.12.2021 17:52:23
#Base:Edit=	16.12.2021 17:52:23
#Base:Edit=	16.12.2021 17:52:24
#Base:Edit=	16.12.2021 17:52:24
#Base:Edit=	16.12.2021 17:52:25
#Base:Edit=	16.12.2021 17:52:25
#Base:Edit=	16.12.2021 17:52:26
#Base:Edit=	16.12.2021 17:52:26
#Base:Edit=	16.12.2021 17:52:26
#Base:Edit=	16.12.2021 17:52:27
#Base:Edit=	16.12.2021 17:52:28
#Base:Edit=	16.12.2021 17:52:28
#Base:Edit=	16.12.2021 17:52:29
#Base:Sub=	16.12.2021 17:52:47
102.881	268.074
109.397	203.187
115.908	167.258
122.414	156.464
128.914	138.366
135.409	135.86
141.898	103.959
148.383	115.481
154.861	143.642
161.335	147.249
167.801	81.1581
174.264	34.3922
180.721	16.5634
187.173	9.44445
193.62	6.33568
200.061	9.2171
206.496	0.96711
212.926	9.09927
219.352	37.4336
225.772	122.079
232.185	185.607
238.595	88.6091
244.999	35.6943
251.397	39.9572
257.791	50.0123
264.178	46.9322
270.561	44.9455
276.939	61.1119
283.31	62.1599
289.678	31.0263
296.039	30.2737
302.396	38.1148
308.746	84.7445
315.093	208.807
321.433	369.628
327.768	218.254
334.099	100.062
340.423	65.8768
346.743	54.3536
353.058	72.0555
359.367	77.4723
365.671	59.3776
371.971	12.2319
378.265	10.2429
384.553	-0.124939
390.837	9.3661
397.116	14.2942
403.389	15.5836
409.657	40.45
415.92	45.4781
422.178	75.0794
428.431	100.538
434.678	100.186
440.921	87.5833
447.158	87.1969
453.391	96.1269
459.618	62.1845
465.84	31.3213
472.057	22.9343
478.27	19.3002
484.477	24.9692
490.679	25.9696
496.876	35.3572
503.068	58.7433
509.255	73.7571
515.436	85.0819
521.613	85.2968
527.785	80.9004
533.952	72.8108
540.113	52.4073
546.27	43.1082
552.423	29.8676
558.568	26.9281
564.711	19.0898
570.848	18.7005
576.979	24.782
583.107	32.6946
589.228	52.7492
595.345	73.7879
601.458	72.6314
607.565	81.9034
613.667	75.3701
619.764	67.9669
625.856	49.2667
631.944	46.3035
638.026	40.277
644.104	42.5413
650.177	43.8297
656.244	41.2413
662.308	30.2097
668.365	16.4413
674.418	5.65421
680.467	2.35873
686.511	2.83392
692.549	4.3036
698.582	8.59235
704.611	-4.04009
710.635	2.03713
716.655	-0.489845
722.669	5.43411
728.679	4.71069
734.683	-0.731884
740.683	3.17911
746.678	5.21719
752.669	8.21092
758.654	4.72021
764.635	2.27749
770.611	5.4863
776.582	9.63717
782.549	4.3243
788.511	6.47733
794.466	3.87123
800.419	6.85732
806.366	1.29944
812.309	4.18546
818.247	7.94742
824.18	15.4102
830.108	14.4333
836.033	7.99217
841.952	16.6205
847.865	17.7938
853.776	17.1249
859.681	14.5872
865.58	23.3725
871.476	28.3895
877.366	38.0583
883.253	34.3991
889.134	42.0511
895.012	36.3599
900.883	40.0337
906.751	37.0116
912.614	46.2245
918.473	38.533
924.326	46.0211
930.174	68.6948
936.019	74.5995
941.859	106.275
947.693	133.497
953.525	141.889
959.35	138.743
965.171	161.271
970.988	216.373
976.801	291.442
982.608	344.83
988.411	303.046
994.209	227.859
1000	193.071
1005.79	184.25
1011.58	206.248
1017.36	212.245
1023.13	198.311
1028.9	138.584
1034.67	116.081
1040.43	92.5462
1046.19	82.4017
1051.94	75.008
1057.69	63.6126
1063.44	63.73
1069.17	52.0543
1074.91	70.4788
1080.64	99.4899
1086.37	123.592
1092.09	195.18
1097.8	186.335
1103.52	130.136
1109.22	94.4505
1114.93	66.6796
1120.63	71.969
1126.32	73.2638
1132.01	85.3586
1137.7	110.249
1143.38	150.964
1149.06	219.203
1154.73	148.552
1160.4	68.7714
1166.06	46.967
1171.72	34.0701
1177.38	25.1207
1183.03	23.0826
1188.67	21.1542
1194.31	14.412
1199.95	9.68692
1205.58	5.03627
1211.21	8.27286
1216.84	2.66222
1222.46	7.96796
1228.07	1.33233
1233.68	4.63877
1239.29	8.92677
1244.89	6.09034
1250.49	14.2855
1256.08	25.467
1261.67	16.3532
1267.26	13.2902
1272.84	136.961
1278.42	114.513
1283.99	19.056
1289.56	12.0012
1295.12	7.00933
1300.68	7.06095
1306.23	5.17937
1311.78	2.37469
1317.33	6.63946
1322.87	8.93656
1328.41	1.14219
1333.94	3.45128
1339.47	4.72493
1345	9.01612
1350.52	10.2196
1356.04	11.3987
1361.55	13.5634
1367.06	12.5915
1372.56	21.8652
1378.06	341.28
1383.56	78.3613
1389.05	14.7327
1394.53	10.686
1400.02	29.3285
1405.5	14.0562
1410.97	4.94183
1416.44	3.04437
1421.91	4.25266
1427.37	8.59269
1432.83	4.6285
1438.28	-1.45054
1443.73	7.08277
1449.17	1.99903
1454.62	1.04232
1460.05	1.09281
1465.48	1.11222
1470.91	1.11811
1476.34	-0.964195
1481.76	-3.02515
1487.17	4.38348
1492.59	3.41749
1497.99	0.366699
1503.4	0.488785
1508.8	3.80673
1514.19	-1.33504
1519.59	3.09711
1524.97	-4.19265
1530.36	4.55732
1535.74	5.84307
1541.11	4.91853
1546.48	4.99584
1551.85	6.06266
1557.21	4.88602
1562.57	8.04013
1567.93	10.1051
1573.28	1.39143
1578.62	6.71347
1583.97	6.68271
1589.3	1.28249
1594.64	8.83234
1599.97	7.79081
1605.3	2.44886
1610.62	6.88089
1615.94	5.94764
1621.25	6.12033
1626.56	5.19016
1631.87	2.04166
1637.17	4.34231
1642.47	7.65814
1647.76	4.35584
1653.05	-2.30529
1658.34	2.07749
1663.62	9.76932
1668.9	11.9013
1674.18	6.2618
1679.45	11.6965
1684.71	3.78985
1689.98	9.17041
1695.23	6.83381
1700.49	5.68972
1705.74	-0.802895
1710.99	10.3053
1716.23	6.86035
1721.47	6.91287
1726.7	10.2461
1731.94	9.12843
1737.16	9.12069
1742.39	13.6156
1747.61	-4.47571
1752.82	9.01549
1758.03	8.92091
1763.24	7.65579
1768.44	0.732201
1773.64	7.40919
1778.84	1.63988
1784.03	6.1104
1789.22	2.64992
1794.41	16.3084
1799.59	7.16726
1804.76	10.6107
1809.94	17.4941
1815.11	2.48653
1820.27	2.42947
1825.43	2.37514
1830.59	-2.31694
1835.74	8.09801
1840.89	15.0288
1846.04	10.2847
1851.18	2.00342
1856.32	12.4121
1861.45	5.29099
1866.58	11.0902
1871.71	13.3552
1876.83	8.51578
1881.95	13.0984
1887.07	8.21556
1892.18	10.366
1897.29	6.59614
1902.39	6.43301
1907.49	14.6309
1912.59	8.66283
1917.68	8.65418
1922.77	8.49029
1927.86	5.99137
1932.94	11.8715
1938.02	6.94202
1943.09	4.37777
1948.16	7.80521
1953.23	17.2284
1958.29	10.9714
1963.35	13.1329
1968.41	16.4737
1973.46	13.7539
1978.51	5.01617
1983.55	7.11234
1988.59	6.8083
1993.63	2.90561
1998.66	3.82688
2003.69	3.5647
2008.72	4.53055
2013.74	9.1274
2018.76	8.8997
2023.77	12.2985
2028.78	7.29306
2033.79	1.09869
2038.79	8.22014
2043.79	10.5209
2048.79	10.4107
2053.78	16.3603
2058.77	11.3633
2063.76	10.0318
2068.74	9.92085
2073.72	11.0303
2078.69	4.7401
2083.66	3.3456
2088.63	11.8037
2093.59	15.3718
2098.55	0.384148
2103.51	8.97553
2108.46	5.1572
2113.41	13.8518
2118.36	5.04127
2123.3	10.0184
2128.24	4.91196
2133.17	13.6812
2138.11	2.16975
2143.03	7.12453
2147.96	9.52551
2152.88	10.6187
2157.79	6.57891
2162.71	2.50293
2167.62	9.8961
2172.52	1.96686
2177.43	6.83963
2182.32	11.6689
2187.22	4.95273
2192.11	8.52048
2197	3.15447
2201.89	2.95708
2206.77	10.505
2211.64	-5.06562
2216.52	-0.0310593
2221.39	3.75357
2226.26	8.8569
2231.12	4.8818
2235.98	4.79932
2240.84	15.1737
2245.69	9.87994
2250.54	7.18616
2255.39	7.10637
2260.23	4.39986
2265.07	2.97488
2269.9	0.18013
2274.74	6.63933
2279.57	5.1101
2284.39	8.85298
2289.21	1.92859
2294.03	5.64433
2298.84	6.73021
2303.66	9.19225
2308.46	-0.292175
2313.27	6.28164
2318.07	10.2414
2322.87	20.9472
2327.66	-3.3158
2332.45	7.45202
2337.24	10.17
2342.02	7.47994
2346.8	7.54012
2351.58	0.737762
2356.35	-7.52225
2361.12	-2.11261
2365.89	0.551323
2370.65	0.460724
2375.41	5.90409
2380.17	5.79376
2384.92	4.23669
2389.67	2.64082
2394.42	10.7463
2399.16	9.07519
2403.9	4.61317
2408.64	4.34503
2413.37	7.02739
2418.1	11.433
2422.83	4.46918
2427.55	-4.09103
2432.27	1.51615
2436.99	10.0244
2441.7	1.54825
2446.41	-2.70642
2451.11	7.30348
2455.82	0.170418
2460.51	-2.69003
2465.21	-1.24673
2469.9	3.07748
2474.59	-2.72742
2479.28	-1.28802
2483.96	1.59512
2488.64	3.00102
2493.32	-1.43983
2497.99	4.36363
2502.66	10.1708
2507.32	1.27911
2511.99	-0.302834
2516.65	3.98949
2521.3	11.279
2525.96	8.24188
2530.61	8.15646
2535.25	-5.24957
2539.89	-2.33604
2544.53	11.0255
2549.17	8.04334
2553.8	6.54123
2558.43	6.49487
2563.06	10.9906
2567.68	1.99296
2572.3	8.06548
2576.92	8.09828
2581.53	6.5705
2586.14	4.96638
2590.75	13.9388
2595.35	3.18848
2599.96	10.7456
2604.55	4.55432
2609.15	-3.19302
2613.74	7.35656
2618.33	10.2848
2622.91	8.62674
2627.49	10.0601
2632.07	13.1174
2636.64	5.49137
2641.22	-3.65512
2645.78	5.75556
2650.35	13.6514
2654.91	16.8716
2659.47	12.1832
2664.03	4.31498
2668.58	8.95133
2673.13	7.40619
2677.67	9.18262
2682.22	12.7107
2686.76	14.6322
2691.29	3.74895
2695.83	16.6362
2700.36	7.06001
2704.89	10.2974
2709.41	13.5273
2713.93	2.24094
2718.45	21.6825
2722.96	7.1396
2727.47	20.0725
2731.98	-12.4884
2736.49	5.26543
2740.99	8.4132
2745.49	11.6227
2749.98	14.9013
2754.47	11.8027
2758.96	2.00048
2763.45	6.90025
2767.93	5.29723
2772.41	18.5066
2776.89	3.76243
2781.36	7.23772
2785.84	12.4362
2790.3	9.31686
2794.77	6.15457
2799.23	-2.11043
2803.69	11.4162
2808.14	9.79411
2812.59	9.8328
2817.04	6.44686
2821.49	16.6124
2825.93	8.16698
2830.37	11.5763
2834.81	6.46854
2839.24	13.2768
2843.67	1.34042
2848.1	6.49895
2852.53	3.14942
2856.95	8.42131
2861.37	12.0074
2865.78	22.5817
2870.19	-8.3489
2874.6	19.6175
2879.01	12.9082
2883.41	6.18738
2887.81	9.96795
2892.21	-3.87071
2896.6	-3.64466
2901	1.93213
2905.38	14.6014
2909.77	0.541496
2914.15	14.9673
2918.53	7.93261
2922.91	15.2776
2927.28	13.6884
2931.65	12.1118
2936.02	23.1578
2940.38	-5.78928
2944.74	16.1009
2949.1	-2.09088
2953.46	16.1797
2957.81	-11.197
2962.16	16.2682
2966.5	14.5092
2970.85	9.09527
2975.19	3.67117
2979.52	22.1939
2983.86	22.3628
2988.19	7.76353
2992.52	9.83631
2996.85	-1.10735
3001.17	21.5555
3005.49	10.6481
3009.8	10.9489
3014.12	24.4366
3018.43	21.0353
3022.74	15.7025
3027.04	14.068
3031.34	20.0149
3035.64	10.6053
3039.94	1.14456
3044.23	22.4098
3048.52	24.4647
3052.81	14.9451
3057.09	32.4727
3061.38	28.7555
3065.65	26.9659
3069.93	32.941
3074.2	42.8376
3078.47	52.7855
3082.74	27.6027
3087	21.9596
3091.27	37.9558
3095.52	36.3878
3099.78	42.731
3104.03	47.17
3108.28	31.7847
3112.53	44.2895
3116.77	48.8578
3121.01	35.3618
3125.25	42.0247
3129.49	44.7302
3133.72	51.5944
3137.95	64.6571
3142.18	69.5281
3146.4	49.534
3150.62	70.8759
3154.84	67.2285
3159.06	61.4421
3163.27	68.208
3167.48	68.6533
3171.69	54.356
3175.89	75.8284
3180.09	63.4038
3184.29	65.7153
3188.49	80.6927
3192.68	49.0728
3196.87	79.1542
3201.06	77.6169
3205.24	65.4234
3209.42	66.1291
3213.6	51.7399
3217.78	67.6424
3221.95	61.8263
3226.12	58.1559
3230.29	58.8255
3234.45	50.6532
3238.61	51.2457
3242.77	45.2583
3246.93	43.708
3251.08	46.4832
3255.23	44.6514
3259.38	40.5828
3263.53	45.6375
3267.67	46.4834
3271.81	24.3732
3275.95	40.7298
3280.08	36.4741
3284.21	34.4914
3288.34	39.3897
3292.47	21.2605
3296.59	33.0359
3300.71	24.1032
3304.83	22.0699
3308.95	20.0287
3313.06	27.2471
3317.17	34.5125
3321.27	37.1798
3325.38	30.5635
3329.48	23.9474
3333.58	43.3108
3337.67	22.6558
3341.77	30.1509
3345.86	47.0944
3349.95	30.7611
3354.03	31.0476
3358.11	24.2559
3362.19	31.7925
3366.27	36.9412
3370.34	30.1072
3374.42	28.0124
3378.48	18.6278
3382.55	23.6812
3386.61	19.0679
3390.68	7.16644
3394.73	33.9975
3398.79	14.868
3402.84	32.0698
3406.89	22.5387
3410.94	12.9755
3414.98	15.5633
3419.03	30.3432
3423.06	35.3754
3427.1	16.0383
3431.14	21.1407
3435.17	26.2951
3439.2	21.7075
3443.22	26.9507
3447.25	10.1462
3451.27	15.4782
3455.28	18.4182
3459.3	28.8974
3463.31	19.5349
3467.32	0.106468
3471.33	25.68
3475.34	3.5069
3479.34	11.5364
3483.34	14.5405
3487.33	30.2345
3491.33	2.73911
3495.32	8.23597
3499.31	16.2749
3503.3	19.1729
3507.28	22.0375
3511.26	19.6743
3515.24	7.006
3519.22	14.88
3523.19	17.6189
3527.16	2.37273
3531.13	2.55149
3535.1	23.5017
3539.06	11.0038
3543.02	3.59116
3546.98	14.279
3550.93	14.5472
3554.89	14.696
3558.84	27.9523
3562.78	12.6173
3566.73	15.5623
3570.67	29.0504
3574.61	29.4739
3578.55	16.8144
3582.48	33.1378
3586.41	25.7688
3590.35	34.2598
3594.27	16.1949
3598.2	11.3563
3602.12	19.8219
3606.04	-1.17894
3609.95	9.92702
3613.87	15.6943
3617.78	13.366
3621.69	16.3699
3625.6	16.5769
3629.5	8.65499
3633.4	19.6327
3637.3	19.8505
3641.2	17.4557
3645.09	4.24831
3648.98	15.4251
3652.87	10.2325
3656.76	5.01122
3660.64	7.95895
3664.53	16.3603
3668.4	13.8809
3672.28	8.64857
3676.16	6.20961
3680.03	17.5463
3683.9	6.97395
3687.76	-11.8849
3691.63	24.5131
3695.49	16.66
3699.35	11.5724
3703.2	17.5983
3707.06	18.0884
3710.91	10.1611
3714.76	27.4778
3718.6	13.8174
3722.45	5.71979
3726.29	20.1942
3730.13	14.8787
3733.97	23.7637
3737.8	7.07201
3741.63	10.2438
3745.46	13.4109
3749.29	7.98378
3753.11	16.8099
3756.93	2.70767
3760.75	20.0713
3764.57	23.1106
3768.39	6.0948
3772.2	12.05
3776.01	12.2732
3779.81	9.65132
3783.62	12.8274
3787.42	24.6735
3791.22	16.3112
3795.02	5.07637
3798.81	11.227
3802.61	5.79624
3806.4	9.0964
3810.18	12.4104
3813.97	4.01354
3817.75	7.29477
3821.53	16.4461
3825.31	13.8341
3829.09	11.2185
3832.86	14.5262
3836.63	-2.86182
3840.4	6.31607
3844.17	-5.19612
3847.93	24.7045
3851.69	21.9538
3855.45	4.30781
3859.21	16.3319
3862.96	10.5565
3866.71	10.8968
3870.46	11.3189
3874.21	5.54361
3877.95	17.7082
3881.69	11.9489
3885.44	9.19729
3889.17	15.4528
3892.91	15.7599
3896.64	19.1451
3900.37	19.4972
3904.1	7.78214
3907.82	11.1233
3911.55	2.40501
3915.27	2.76579
3918.99	6.20582
3922.7	24.921
3926.42	-5.09606
3930.13	13.6388
3933.84	20.1502
3937.54	14.3921
3941.25	2.51762
3944.95	12.1777
3948.65	12.607
3952.35	16.0871
3956.04	7.19122
3959.73	22.9994
3963.42	7.84258
3967.11	20.5321
3970.8	17.703
3974.48	11.7947
3978.16	2.77843
3981.84	12.341
3985.52	-2.89951
3989.19	9.78072
3992.86	13.2121
3996.53	7.38731
3998.37	4.48973