File: Data/3-Raman/processed/bu19w-e-ff11b-fi03-v_1800 (450-850nm)_532nm_edge_100%_x100_vis_h50um_30sx2_01.txt
#Acq. time (s)=	30
#Accumulations=	2
#Range (cm-¹)=	1200...2365
#Windows=	3
#Auto scanning=	Off
#Autofocus=	Off
#Macrospot=	Off
#AutoExposure=	Off
#Spike filter=	Multiple accum.
#Delay time (s)=	2
#Binning=	1
#Readout mode=	Signal
#DeNoise=	Off
#ICS correction=	On
#Dark correction=	Off
#Inst. Process=	Off
#Detector Gain=	Best Dynamic
#Detector ADC=	50 kHz HS
#Detector temperature (°C)=	-60.09
#Instrument=	LabRAM HR Evol
#Detector=	SIN-EM FIVIS
#Objective=	x100_VIS
#Grating=	1800 (450-850nm)
#ND Filter=	100%
#Laser=	532nm_Edge
#Hole=	49.98
#Temperature=	0
#Range=	Visible
#StageXY=	75x50mm Scan+
#StageZ=	Z motor
#X (µm)=	0
#Y (µm)=	0
#Z (µm)=	-250.4
#Full time(mm:ss)=	3:18
#Project=	21_11_04
#Sample=	BU19w
#Site=
#Title=	BU19w-E-FF11b-FI03-V_1800 (450-850nm)_532nm_Edge_100%_x100_VIS_H50um_30sX2
#Remark=
#Date=	04.11.2021 18:43
#Acquired=	04.11.2021 18:43:09
#Base:Fit=	16.12.2021 17:39:50
#Base:Fit=	16.12.2021 17:45:42
#Base:Sub=	16.12.2021 17:45:44
1202.73	3.29329
1203.85	4.00112
1204.96	0.447273
1206.07	1.17484
1207.18	-1.29824
1208.29	1.59911
1209.4	3.43677
1210.51	-1.14269
1211.62	1.75663
1212.73	0.401585
1213.84	-1.99425
1214.95	-0.117983
1216.06	-1.44567
1217.17	0.41489
1218.28	-0.895557
1219.39	-4.31155
1220.5	-1.35078
1221.61	2.6575
1222.72	1.34974
1223.82	-0.995466
1224.93	-0.141226
1226.04	6.01177
1227.15	1.57287
1228.25	1.3268
1229.36	6.51875
1230.47	-0.0167675
1231.57	-3.3758
1232.68	1.7184
1233.79	-0.526966
1234.89	-1.7093
1236	-3.9451
1237.1	0.105259
1238.21	0.993702
1239.31	-1.23798
1240.42	-3.45161
1241.52	0.621944
1242.63	-3.67111
1243.74	0.421236
1244.84	1.35682
1245.94	-0.855425
1247.05	1.1442
1248.15	3.13245
1249.25	2.00613
1250.36	2.95821
1251.46	-2.35783
1252.56	3.81781
1253.66	5.8428
1254.77	1.61745
1255.87	0.517214
1256.97	3.5986
1258.07	9.80207
1259.18	4.52923
1260.28	9.69816
1261.38	15.9226
1262.48	38.8493
1263.58	44.1168
1264.68	15.8766
1265.78	6.43589
1266.88	3.29818
1267.98	6.45992
1269.08	5.41229
1270.18	7.46098
1271.28	5.34027
1272.38	2.22152
1273.48	5.38877
1274.58	4.34353
1275.68	6.45775
1276.78	7.53234
1277.87	15.9742
1278.97	16.0065
1280.07	30.7291
1281.17	98.1488
1282.26	408.742
1283.36	887.197
1284.46	222.691
1285.55	50.8712
1286.65	26.6635
1287.75	16.1359
1288.84	8.8055
1289.94	13.0683
1291.04	3.60728
1292.13	7.85016
1293.23	3.68188
1294.32	2.67938
1295.42	1.69861
1296.51	4.92694
1297.61	7.05142
1298.7	4.96778
1299.79	2.8964
1300.89	5.04925
1301.98	1.93632
1303.08	-0.13961
1304.17	0.958952
1305.26	3.09848
1306.36	-1.09023
1307.45	2.12455
1308.54	2.17804
1309.63	0.129549
1310.73	2.2917
1311.82	3.41129
1312.91	-1.81686
1314	1.401
1315.09	-1.70034
1316.18	-0.586956
1317.28	1.58625
1318.37	0.591787
1319.46	0.648577
1320.55	-0.355591
1321.64	-1.37564
1322.73	2.88688
1323.82	-0.212791
1324.91	-3.31616
1325.99	1.96486
1327.08	3.10719
1328.17	-3.11917
1329.26	-1.99695
1330.35	-0.890133
1331.44	0.194239
1332.53	0.229467
1333.62	2.36667
1334.7	0.309494
1335.79	-0.68984
1336.88	1.4626
1337.96	1.5116
1339.05	-0.524374
1340.14	-0.453619
1341.23	2.75055
1342.31	1.75005
1343.4	-1.32871
1344.48	-1.26463
1345.57	0.869837
1346.66	1.94691
1347.74	-0.0885086
1348.83	1.00863
1349.91	2.10071
1351	2.14717
1352.08	-0.903913
1353.17	2.3343
1354.25	-1.82933
1355.33	1.3492
1356.42	2.45424
1357.5	6.66204
1358.58	3.59656
1359.67	5.71763
1360.75	5.76685
1361.83	5.82654
1362.92	7.96453
1364	10.1118
1365.08	4.98202
1366.16	10.1948
1367.24	9.20714
1368.33	30.9932
1369.41	11.4165
1370.49	5.26258
1371.57	10.453
1372.65	8.42522
1373.73	13.6302
1374.81	11.6257
1375.89	13.7514
1376.97	13.7806
1378.05	18.0212
1379.13	22.2125
1380.21	23.2299
1381.29	23.2526
1382.37	36.5818
1383.45	50.9407
1384.53	110.519
1385.61	384.866
1386.68	2095.13
1387.76	344.464
1388.84	78.0388
1389.92	35.9278
1390.99	25.7196
1392.07	25.7387
1393.15	15.542
1394.23	14.5679
1395.3	11.5701
1396.38	8.5486
1397.46	10.637
1398.53	11.726
1399.61	9.74796
1400.68	13.9146
1401.76	11.9463
1402.83	14.1079
1403.91	12.0911
1404.99	18.2854
1406.06	26.518
1407.13	54.2619
1408.21	100.479
1409.28	44.1526
1410.36	18.5366
1411.43	16.5138
1412.5	10.4717
1413.58	11.5191
1414.65	6.47517
1415.72	2.42237
1416.8	7.61765
1417.87	3.56296
1418.94	5.66875
1420.01	5.69907
1421.08	6.75947
1422.16	7.86691
1423.23	3.73595
1424.3	6.86467
1425.37	7.95937
1426.44	5.93645
1427.51	3.90348
1428.58	0.876171
1429.65	2.98242
1430.72	3.05321
1431.79	2.06961
1432.86	4.13888
1433.93	6.21373
1435	2.16891
1436.07	3.22993
1437.14	1.21591
1438.21	3.30794
1439.28	8.4807
1440.35	3.40785
1441.41	5.49241
1442.48	1.43614
1443.55	0.439884
1444.62	-1.56028
1445.69	6.67955
1446.75	-0.469475
1447.82	3.66483
1448.89	0.630182
1449.95	1.68085
1451.02	-1.36486
1452.09	-2.35894
1453.15	0.753681
1454.22	-0.239794
1455.28	3.8931
1456.35	-0.173773
1457.41	2.9247
1458.48	1.93442
1459.54	2.99033
1460.61	0.965723
1461.67	-0.0378342
1462.74	1.0005
1463.8	1.03532
1464.86	-2.02188
1465.93	0.0346394
1466.99	0.0519657
1468.05	0.0771828
1469.12	0.0985546
1470.18	0.113701
1471.24	0.131538
1472.31	3.2095
1473.37	2.20896
1474.43	-0.818088
1475.49	0.222307
1476.55	0.238981
1477.62	0.259447
1478.68	0.27298
1479.74	-1.74856
1480.8	1.30668
1481.86	-2.72155
1482.92	-0.66226
1483.98	-2.68048
1485.04	-0.685703
1486.1	-0.631849
1487.16	4.45228
1488.22	0.40925
1489.28	-0.590042
1490.34	-1.5852
1491.4	1.46203
1492.46	-0.540854
1493.52	-0.522854
1494.57	0.508108
1495.63	-0.50115
1496.69	0.519716
1497.75	-1.4815
1498.81	-0.451777
1499.86	0.579624
1500.92	1.60139
1501.98	1.61511
1503.03	0.611336
1504.09	0.630123
1505.15	0.639925
1506.2	-0.361573
1507.26	2.68255
1508.32	-0.326084
1509.37	-1.31749
1510.43	-0.300012
1511.48	1.70133
1512.54	-0.318188
1513.59	-0.300794
1514.65	-0.291274
1515.7	-2.2998
1516.76	-1.28724
1517.81	-0.265918
1518.86	0.755454
1519.92	-1.2385
1520.97	0.785134
1522.02	0.793415
1523.08	1.79464
1524.13	-2.21375
1525.18	-0.194959
1526.24	-3.17781
1527.29	-1.16444
1528.34	-0.156363
1529.39	-0.148601
1530.44	0.869807
1531.5	0.884878
1532.55	-6.11336
1533.6	-0.0768394
1534.65	0.932593
1535.7	-1.07888
1536.75	-0.0850649
1537.8	-2.0848
1538.85	0.930085
1539.9	1.97846
1540.95	-2.01887
1542	3.98712
1543.05	4.9786
1544.1	0.982079
1545.15	3.01368
1546.2	2.02663
1547.25	1.03951
1548.29	0.0429163
1549.34	1.02183
1550.39	3.12002
1551.44	2.10576
1552.49	3.13115
1553.53	1.10974
1554.58	-0.904153
1555.63	-1.89719
1556.68	0.11375
1557.72	3.11976
1558.77	-0.893953
1559.82	0.103738
1560.86	1.10867
1561.91	1.1302
1562.95	1.13597
1564	3.15731
1565.04	2.09777
1566.09	0.155338
1567.13	2.1751
1568.18	2.17371
1569.22	-1.82732
1570.27	1.18003
1571.31	3.17859
1572.36	3.17691
1573.4	1.17903
1574.44	1.19991
1575.49	3.21434
1576.53	0.212769
1577.57	2.1936
1578.62	2.19435
1579.66	0.21155
1580.7	1.21229
1581.74	0.212373
1582.79	0.215425
1583.83	5.20103
1584.87	2.22153
1585.91	2.21925
1586.95	6.19632
1587.99	3.21945
1589.03	1.2444
1590.07	2.25038
1591.12	1.2624
1592.16	2.25054
1593.2	2.23548
1594.24	3.22714
1595.28	2.24145
1596.32	2.24619
1597.35	4.24422
1598.39	1.25859
1599.43	0.261419
1600.47	2.23745
1601.51	5.19389
1602.55	3.20446
1603.59	0.235743
1604.63	3.2096
1605.66	3.222
1606.7	4.22506
1607.74	-0.661782
1608.78	2.96865
1609.81	1.46534
1610.85	3.05321
1611.89	0.802353
1612.92	1.6419
1613.96	0.223599
1615	0.914001
1616.03	2.04529
1617.07	4.00947
1618.1	3.06249
1619.14	3.47544
1620.17	2.25393
1621.21	1.13236
1622.24	3.50629
1623.28	2.57759
1624.31	1.15268
1625.35	2.76727
1626.38	3.01065
1627.41	5.49817
1628.45	2.19375
1629.48	2.44392
1630.51	2.23307
1631.3	4.29922
1632.34	3.33649
1633.39	1.35826
1634.43	4.32652
1635.48	2.35745
1636.52	2.35513
1637.57	2.35488
1638.61	3.34307
1639.66	-0.588349
1640.7	2.3786
1641.75	3.36475
1642.79	1.40038
1643.83	1.40184
1644.88	0.424884
1645.92	2.39819
1646.96	0.431344
1648.01	1.42285
1649.05	1.44354
1650.09	3.42665
1651.13	1.47368
1652.18	2.46596
1653.22	2.47017
1654.26	3.46765
1655.3	1.51894
1656.34	4.49724
1657.38	1.5385
1658.42	2.52455
1659.47	3.50601
1660.51	1.54949
1661.55	-3.36684
1662.59	2.587
1663.63	2.56826
1664.67	0.620461
1665.71	0.63871
1666.75	2.59399
1667.79	1.60275
1668.83	1.62863
1669.86	0.646352
1670.9	3.6303
1671.94	3.63952
1672.98	0.682038
1674.02	2.67382
1675.06	1.70138
1676.1	0.720324
1677.13	-0.26382
1678.17	-0.267196
1679.21	1.71016
1680.25	-0.265229
1681.28	3.69087
1682.32	0.734139
1683.35	-0.247769
1684.39	3.70427
1685.43	0.747847
1686.46	-0.226716
1687.5	2.73947
1688.54	1.74981
1689.57	-1.21471
1690.6	1.75689
1691.64	-0.205623
1692.68	-0.207051
1693.71	2.74213
1694.74	2.74275
1695.78	0.784266
1696.81	1.77448
1697.85	1.7664
1698.88	-0.201597
1699.92	0.788142
1700.95	0.791057
1701.98	-1.17907
1703.01	-0.194487
1704.05	-0.187174
1705.08	1.78386
1706.11	-2.14664
1707.14	3.73441
1708.18	1.75758
1709.21	1.75073
1710.24	1.75872
1711.27	0.792896
1712.3	0.788722
1713.33	0.770753
1714.36	-0.206936
1715.4	-1.17222
1716.43	-0.198313
1717.46	-1.19089
1718.49	2.69551
1719.52	-0.219925
1720.55	1.72678
1721.58	1.71858
1722.61	-1.20495
1723.64	0.738023
1724.66	2.67226
1725.69	-2.18663
1726.72	-1.21741
1727.75	1.69378
1728.78	0.673735
1729.81	-1.23814
1730.83	0.710124
1731.86	0.714185
1732.89	-0.25644
1733.92	-1.23503
1734.95	-3.1717
1735.97	2.60238
1737	-2.21065
1738.03	1.63144
1739.05	-1.26047
1740.08	-1.27566
1741.1	-0.324044
1742.13	0.63306
1743.16	0.634425
1744.18	0.63066
1745.21	1.59232
1746.23	0.628721
1747.26	-0.335346
1748.28	0.622768
1749.31	1.591
1750.33	-2.2146
1751.36	-1.25613
1752.38	-1.26377
1753.4	4.45567
1754.43	-1.27287
1755.45	0.629788
1756.47	-0.333744
1757.5	-1.28743
1758.52	2.52957
1759.54	-1.27184
1760.57	-1.27262
1761.59	-0.324918
1762.61	-1.26732
1763.63	0.64118
1764.66	0.659045
1765.68	-1.23707
1766.7	-2.18678
1767.72	0.666524
1768.74	0.655052
1769.76	0.648397
1770.78	-1.2387
1771.8	-0.273437
1772.82	-0.260515
1773.84	0.700709
1774.86	3.56862
1775.88	-2.13083
1776.9	-0.226025
1777.92	1.67271
1778.94	-0.240664
1779.96	1.67215
1780.98	-3.07989
1782	-0.211514
1783.02	-0.200266
1784.04	-1.14048
1785.05	2.68274
1786.07	-0.177852
1787.09	-1.11566
1788.11	-0.123786
1789.12	-0.105489
1790.14	1.82154
1791.16	-1.06361
1792.18	-1.0607
1793.19	-2.97018
1794.21	-0.0922022
1795.23	-1.02334
1796.24	0.910449
1797.26	-0.0370359
1798.27	0.931899
1799.29	0.927629
1800.3	-2.92011
1801.32	0.92404
1802.33	-0.988328
1803.35	-0.0145655
1804.36	-1.92863
1805.38	0.97487
1806.39	-0.941069
1807.41	0.0262957
1808.42	0.0303984
1809.43	-0.92892
1810.45	1.0012
1811.46	-0.925249
1812.47	1.0121
1813.49	-1.87236
1814.5	-0.890658
1815.51	0.0828514
1816.53	1.05376
1817.54	-0.88961
1818.55	2.01909
1819.56	1.06077
1820.57	2.03691
1821.58	0.112369
1822.6	0.118206
1823.61	-0.851152
1824.62	-0.844763
1825.63	1.09673
1826.64	0.131684
1827.65	1.10704
1828.66	-0.834113
1829.67	1.101
1830.68	4.97313
1831.69	-0.827702
1832.7	1.11929
1833.71	-0.815044
1834.72	3.03618
1835.73	3.02326
1836.74	1.12196
1837.75	1.07898
1838.75	0.149351
1839.76	1.11711
1840.77	1.08227
1841.78	0.094799
1842.79	2.02198
1843.79	2.0213
1844.8	0.0933704
1845.81	-1.82027
1846.81	0.074585
1847.82	-0.882756
1848.83	-2.81874
1849.83	-1.87054
1850.84	0.999934
1851.85	0.995683
1852.85	0.995183
1853.86	-0.935781
1854.86	0.970376
1855.87	-1.91315
1856.87	0.00135136
1857.88	-0.00622654
1858.88	-1.93153
1859.89	-0.0212746
1860.89	-0.967924
1861.9	-2.88012
1862.9	-0.977926
1863.9	-1.94283
1864.91	-0.0448093
1865.91	-0.0659542
1866.92	0.862976
1867.92	-0.0977383
1868.92	0.853375
1869.92	0.850364
1870.93	-1.05217
1871.93	-1.05842
1872.93	2.73155
1873.93	0.824292
1874.93	-0.138798
1875.94	1.73207
1876.94	-2.06994
1877.94	-0.150093
1878.94	0.803192
1879.94	1.74047
1880.94	-1.10486
1881.94	-0.187166
1882.94	-2.03211
1883.94	-0.208537
1884.94	0.74303
1885.94	1.7025
1886.94	1.68827
1887.94	-0.214742
1888.94	0.710256
1889.94	-0.228396
1890.94	-1.16708
1891.94	0.71436
1892.94	-0.243663
1893.93	-0.255443
1894.93	-1.19763
1895.93	0.688901
1896.93	-0.242547
1897.93	0.696736
1898.92	0.684326
1899.92	2.55713
1900.92	-0.254153
1901.91	-0.242083
1902.91	1.63524
1903.91	-2.1291
1904.9	-0.25052
1905.9	3.49592
1906.9	-0.265436
1907.89	-1.19827
1908.89	-0.251753
1909.88	1.64739
1910.88	-0.223075
1911.87	-0.22398
1912.87	-0.223683
1913.86	0.732794
1914.86	-0.19898
1915.85	-1.14322
1916.85	-3.97996
1917.84	0.734194
1918.84	-0.193255
1919.83	-0.178243
1920.82	-0.171865
1921.82	-1.11126
1922.81	0.773982
1923.8	-2.06727
1924.79	-0.177535
1925.79	-2.05445
1926.78	1.74489
1927.77	-1.08859
1928.76	5.55267
1929.75	-0.118558
1930.75	1.79017
1931.74	-0.114328
1932.73	4.62291
1933.72	1.7993
1934.71	-1.00963
1935.7	0.899308
1936.69	2.79628
1937.68	2.7836
1938.67	0.88922
1939.66	-1.00768
1940.65	0.920897
1941.64	-0.998672
1942.63	-0.0226564
1943.62	-0.0309629
1944.61	-2.88191
1945.6	-0.0025444
1946.59	1.91611
1947.58	-1.91115
1948.57	-2.865
1949.55	1.93255
1950.54	1.00049
1951.53	1.02161
1952.52	1.0298
1953.5	0.0578117
1954.49	-0.923435
1955.48	-0.912946
1956.47	1.98888
1957.45	1.04195
1958.44	0.0850792
1959.43	-1.84139
1960.41	0.0723391
1961.4	-0.891762
1962.38	1.03199
1963.37	1.9961
1964.36	-1.84045
1965.34	1.04309
1966.33	-0.865346
1967.31	-0.860854
1968.3	0.102315
1969.28	-0.870434
1970.26	-0.878918
1971.25	-0.882947
1972.23	1.04042
1973.22	1.03294
1974.2	1.03085
1975.18	-0.879109
1976.17	-0.872309
1977.15	0.0865879
1978.13	-0.877666
1979.12	-1.8345
1980.1	0.082181
1981.08	0.0772133
1982.06	0.0755911
1983.05	0.0652113
1984.03	2.93144
1985.01	-0.900002
1985.99	-1.84931
1986.97	-0.890495
1987.95	2.91299
1988.93	-0.91752
1989.91	-2.77243
1990.89	1.68267
1991.88	-1.50069
1992.86	0.662573
1993.84	-1.08937
1994.82	-1.17605
1995.8	-1.44594
1996.78	-1.52018
1997.76	0.865388
1998.73	0.314472
1999.71	0.906419
2000.69	-0.47899
2001.67	0.80847
2002.65	0.626599
2003.63	0.00594521
2004.6	0.698763
2005.58	1.46858
2006.56	-0.826568
2007.54	-1.18132
2008.52	-0.215626
2009.49	0.278982
2010.47	-1.32117
2011.45	-3.53776
2012.42	-0.0771961
2013.41	-1.0343
2014.4	2.70163
2015.39	-1.04295
2016.38	-0.086257
2017.37	-1.97105
2018.35	1.76538
2019.34	1.75098
2020.33	0.814544
2021.32	-1.99067
2022.31	-1.99479
2023.29	1.73802
2024.28	-1.07755
2025.27	-2.0228
2026.25	0.788365
2027.24	1.75931
2028.23	-1.07128
2029.21	-1.98266
2030.2	1.70857
2031.19	-1.0684
2032.17	1.74933
2033.16	-2.90514
2034.14	1.74361
2035.13	0.826483
2036.11	0.842518
2037.1	-1.0211
2038.08	1.77964
2039.07	-1.96281
2040.05	1.76049
2041.03	0.82025
2042.02	-1.04691
2043	0.822878
2043.99	0.841094
2044.97	-0.0975199
2045.95	0.883131
2046.94	1.78868
2047.92	-1.01993
2048.9	-0.0756092
2049.88	-0.0555201
2050.87	-1.91961
2051.85	0.883336
2052.83	-1.90858
2053.81	-1.89226
2054.79	-1.88948
2055.78	-0.0221796
2056.76	-0.0208597
2057.74	1.8597
2058.72	-1.86729
2059.7	-0.927135
2060.68	0.94808
2061.66	-0.917853
2062.64	-0.908229
2063.62	0.0391493
2064.6	0.0500374
2065.58	-0.870865
2066.56	-2.74056
2067.54	-2.73157
2068.52	0.0960655
2069.5	0.0849514
2070.48	1.04871
2071.46	3.89574
2072.43	1.07038
2073.41	2.01513
2074.39	-2.68306
2075.37	2.05707
2076.35	-0.768174
2077.32	-1.72135
2078.3	1.11793
2079.28	0.191919
2080.26	0.202171
2081.23	0.201997
2082.21	1.15202
2083.19	1.15376
2084.16	0.211748
2085.14	-0.729856
2086.12	2.12152
2087.09	1.18578
2088.07	-0.703254
2089.04	0.251433
2090.02	2.1556
2090.99	1.21687
2091.97	-0.661265
2092.94	0.305861
2093.92	1.26911
2094.89	2.21803
2095.87	1.26172
2096.84	0.308317
2097.81	0.304726
2098.79	-1.59476
2099.76	3.1518
2100.74	-1.58454
2101.71	1.26881
2102.68	-2.53306
2103.65	0.313909
2104.63	-0.62708
2105.6	0.334104
2106.57	-0.611119
2107.54	-0.615771
2108.52	2.22245
2109.49	1.28183
2110.46	-0.616957
2111.43	2.22922
2112.4	1.28225
2113.38	-0.607749
2114.35	0.341902
2115.32	-0.609936
2116.29	0.33302
2117.26	-0.617885
2118.23	1.26902
2119.2	2.20445
2120.17	1.25112
2121.14	2.21005
2122.11	1.27378
2123.08	0.330475
2124.05	2.22036
2125.02	4.08863
2125.98	2.1768
2126.95	1.21928
2127.92	0.269458
2128.89	0.267753
2129.86	-0.680752
2130.83	0.257752
2131.79	1.1942
2132.76	3.07298
2133.73	1.18691
2134.7	1.18559
2135.67	0.232999
2136.63	1.16895
2137.6	1.17241
2138.57	0.227064
2139.53	3.04242
2140.5	1.14933
2141.46	1.14093
2142.43	2.08414
2143.4	-0.770111
2144.36	-0.757121
2145.33	1.1156
2146.29	0.168932
2147.26	1.09963
2148.22	1.09069
2149.19	0.136074
2150.15	1.05934
2151.12	0.123872
2152.08	0.125059
2153.05	1.98911
2154.01	0.100995
2154.97	1.01123
2155.94	-0.873037
2156.9	-0.876122
2157.86	0.99737
2158.83	0.99085
2159.79	0.975277
2160.75	0.0300703
2161.72	2.82224
2162.68	0.949914
2163.64	-0.92459
2164.6	-0.00466824
2165.56	0.925864
2166.53	-0.948467
2167.49	-0.0361042
2168.45	0.880719
2169.41	-0.0403271
2170.37	-0.966021
2171.33	1.80354
2172.29	-1.93204
2173.25	0.850867
2174.21	1.78023
2175.17	-1.94353
2176.13	0.835217
2177.09	-0.0987215
2178.05	0.821055
2179.01	0.813412
2179.97	1.73691
2180.93	-0.127761
2181.89	0.789599
2182.85	-0.151109
2183.81	0.758926
2184.76	-0.170826
2185.72	-2.02311
2186.68	-0.159766
2187.64	-0.157823
2188.6	0.753852
2189.55	2.5875
2190.51	-0.197145
2191.47	-1.1271
2192.42	-2.05526
2193.38	0.736131
2194.34	0.745787
2195.3	-0.197498
2196.25	0.708394
2197.21	-0.232859
2198.16	0.697615
2199.12	3.49775
2200.07	-0.20069
2201.03	-0.197067
2201.99	1.59511
2202.94	-2.09567
2203.9	-0.205524
2204.85	1.62161
2205.8	0.676229
2206.76	0.668421
2207.71	0.674139
2208.67	-0.253758
2209.62	-0.259059
2210.58	3.47029
2211.53	-1.18586
2212.48	0.67451
2213.44	1.59442
2214.39	-0.261383
2215.34	1.60281
2216.29	1.59538
2217.25	0.655817
2218.2	0.651111
2219.15	1.58826
2220.1	1.58454
2221.06	-0.29936
2222.01	2.48636
2222.96	1.55441
2223.91	2.50038
2224.86	0.637626
2225.81	0.645059
2226.76	-2.16325
2227.72	0.644861
2228.67	2.50976
2229.62	4.39006
2230.57	-1.23478
2231.52	0.649457
2232.47	-2.16692
2233.42	-0.282616
2234.37	-3.11357
2235.31	-0.307483
2236.26	1.57011
2237.21	-0.305742
2238.16	1.59216
2239.11	-1.23295
2240.06	0.636277
2241.01	0.643648
2241.96	0.64257
2242.9	-1.25099
2243.85	-1.26032
2244.8	-0.306231
2245.75	0.645612
2246.69	-0.297839
2247.64	-0.302057
2248.59	-0.311026
2249.53	0.633156
2250.48	1.56254
2251.43	0.605445
2252.37	-0.335225
2253.32	-0.32022
2254.26	-2.21411
2255.21	-1.27141
2256.16	1.57682
2257.1	0.632583
2258.05	0.631813
2258.99	-1.26642
2259.94	-0.315581
2260.88	-1.2612
2261.83	-2.21391
2262.77	-1.25643
2263.71	1.61888
2264.66	-0.277914
2265.6	-1.23461
2266.55	0.657932
2267.49	0.643272
2268.43	-2.22355
2269.38	-2.21527
2270.32	1.61531
2271.26	0.665627
2272.2	0.667402
2273.15	1.62385
2274.09	0.666258
2275.03	-1.24845
2275.97	1.6295
2276.92	0.682425
2277.86	-1.22089
2278.8	1.65721
2279.74	-1.24255
2280.68	1.62124
2281.62	-1.25875
2282.56	-1.25141
2283.5	-0.273273
2284.44	2.6258
2285.38	-1.22202
2286.32	1.65733
2287.26	0.709993
2288.2	-1.219
2289.14	0.687604
2290.08	-0.286856
2291.02	1.64543
2291.96	0.692897
2292.9	1.66673
2293.84	1.66511
2294.78	0.69022
2295.72	-0.282803
2296.65	0.673028
2297.59	0.686888
2298.53	1.66192
2299.47	1.66867
2300.41	0.70658
2301.34	0.710643
2302.28	1.67205
2303.22	-1.22568
2304.15	-1.21979
2305.09	-1.21423
2306.03	-0.243688
2306.97	0.720541
2307.9	2.64582
2308.84	2.65083
2309.77	1.69803
2310.71	2.65982
2311.64	-1.23387
2312.58	-0.276302
2313.51	1.67003
2314.45	1.69072
2315.39	0.715323
2316.32	1.6613
2317.25	-2.19835
2318.19	-0.27286
2319.12	0.683034
2320.06	2.61126
2320.99	-0.27636
2321.92	2.63768
2322.86	4.5739
2323.79	3.60868
2324.72	8.4217
2325.66	13.2275
2326.59	41.1716
2327.52	154.863
2328.46	85.459
2329.39	19.9023
2330.32	8.34077
2331.25	4.49287
2332.18	1.59567
2333.12	-0.339644
2334.05	3.4972
2334.98	1.56502
2335.91	1.56229
2336.84	1.55642
2337.77	1.54977
2338.7	-0.376004
2339.63	0.578726
2340.56	0.562976
2341.49	-0.417639
2342.42	0.529914
2343.35	0.524243
2344.28	-1.39617
2345.21	1.46604
2346.14	-1.42034
2347.07	0.485851
2348	2.39957
2348.93	-1.44532
2349.85	0.429319
2350.78	1.39315
2351.71	1.36075
2352.64	-0.583477
2353.57	-2.49807
2354.5	0.357101
2355.42	0.342715
2356.35	1.26448
2357.28	1.24329
2358.21	-0.67628
2359.13	-0.69235
2360.06	2.13117
2360.99	-1.68975
2361.91	-2.66368
2362.84	-2.68677
2363.77	0.130703
2364.69	0.106787
2364.92	-0.844703