File: Data/3-Raman/processed/bu19w-e-ff11-fi07-l_150 (500nm)_633nm_edge_100%_x100_vis_h50um_60sx2_01_0.txt
#Acq. time (s)=	60
#Accumulations=	2
#Range (cm-¹)=	100...4000
#Windows=	1
#Auto scanning=	Off
#Autofocus=	Off
#Macrospot=	Off
#AutoExposure=	Off
#Spike filter=	Multiple accum.
#Delay time (s)=	2
#Binning=	1
#Readout mode=	Signal
#DeNoise=	Off
#ICS correction=	On
#Dark correction=	Off
#Inst. Process=	Off
#Detector Gain=	Best Dynamic
#Detector ADC=	50 kHz HS
#Detector temperature (°C)=	-60.09
#Instrument=	LabRAM HR Evol
#Detector=	SIN-EM FIVIS
#Objective=	x100_VIS
#Grating=	150 (500nm)
#ND Filter=	100%
#Laser=	633nm_Edge
#Hole=	49.98
#Temperature=	0
#Range=	Visible
#StageXY=	75x50mm Scan+
#StageZ=	Z motor
#X (µm)=	0
#Y (µm)=	0
#Z (µm)=	-268.8
#Full time(mm:ss)=	2:05
#Project=	21_11_04
#Sample=	BU19w
#Site=
#Title=	BU19w-E-FF11-FI07-L_150 (500nm)_633nm_Edge_100%_x100_VIS_H50um_60sX2
#Remark=
#Date=	04.11.2021 16:06
#Acquired=	04.11.2021 16:06:32
#Base:Fit=	16.12.2021 17:39:50
#Base:Edit=	16.12.2021 17:52:14
#Base:Edit=	16.12.2021 17:52:14
#Base:Edit=	16.12.2021 17:52:15
#Base:Sub=	16.12.2021 17:52:18
102.881	270.843
109.397	237.742
115.908	219.785
122.414	193.925
128.914	195.569
135.409	198.807
141.898	200.705
148.383	204.283
154.861	258.36
161.335	312.179
167.801	168.169
174.264	78.1306
180.721	55.5326
187.173	33.2523
193.62	23.7753
200.061	19.5897
206.496	7.4353
212.926	20.389
219.352	55.6055
225.772	204.404
232.185	383.336
238.595	230.605
244.999	103.256
251.397	75.0586
257.791	114.445
264.178	127.504
270.561	94.3345
276.939	126.836
283.31	121.482
289.678	60.271
296.039	46.5374
302.396	62.2727
308.746	148.937
315.093	363.997
321.433	673.324
327.768	484.615
334.099	211.266
340.423	128.54
346.743	136.362
353.058	143.217
359.367	165.053
365.671	111.604
371.971	63.9305
378.265	24.8013
384.553	-0.122604
390.837	8.0181
397.116	11.6279
403.389	18.2101
409.657	42.6901
415.92	51.9905
422.178	71.636
428.431	140.879
434.678	153.838
440.921	133.75
447.158	168.09
453.391	194.658
459.618	161.522
465.84	81.2548
472.057	60.8443
478.27	61.0735
484.477	63.1189
490.679	63.2589
496.876	94.1308
503.068	120.35
509.255	153.106
515.436	169.124
521.613	163.799
527.785	162.305
533.952	142.145
540.113	115.218
546.27	97.3675
552.423	89.593
558.568	72.2199
564.711	58.2934
570.848	46.0988
576.979	63.8093
583.107	83.265
589.228	104.571
595.345	129.72
601.458	132.77
607.565	146.344
613.667	156.314
619.764	143.05
625.856	100.596
631.944	77.385
638.026	80.1769
644.104	83.5849
650.177	78.4655
656.244	87.2402
662.308	56.613
668.365	29.8772
674.418	16.4809
680.467	12.449
686.511	17.8028
692.549	5.49236
698.582	18.4306
704.611	14.4631
710.635	11.3231
716.655	6.06828
722.669	11.14
728.679	1.08862
734.683	4.11943
740.683	5.24956
746.678	8.24851
752.669	8.48055
758.654	11.5678
764.635	11.1022
770.611	8.82612
776.582	12.1515
782.549	8.80505
788.511	7.25088
794.466	10.3436
800.419	6.74245
806.366	15.3088
812.309	20.9764
818.247	11.519
824.18	19.8601
830.108	14.154
836.033	18.9257
841.952	20.1279
847.865	25.107
853.776	35.7916
859.681	35.2589
865.58	54.5668
871.476	67.308
877.366	72.3299
883.253	98.1403
889.134	103.907
895.012	88.6969
900.883	83.7331
906.751	79.6204
912.614	71.725
918.473	87.4529
924.326	91.1622
930.174	117.679
936.019	146.344
941.859	193.511
947.693	240.175
953.525	279.595
959.35	268.426
965.171	305.744
970.988	386.148
976.801	515.152
982.608	606.723
988.411	566.474
994.209	438.267
1000	345.921
1005.79	350.342
1011.58	344.807
1017.36	418.806
1023.13	376.614
1028.9	290.635
1034.67	238.924
1040.43	207.267
1046.19	178.322
1051.94	165.506
1057.69	130.149
1063.44	115.875
1069.17	117.882
1074.91	142.212
1080.64	188.719
1086.37	271.948
1092.09	405.543
1097.8	453.779
1103.52	347.263
1109.22	250.855
1114.93	202.263
1120.63	185.806
1126.32	179.736
1132.01	211.845
1137.7	283.305
1143.38	385.534
1149.06	510.381
1154.73	387.918
1160.4	203.829
1166.06	131.781
1171.72	96.2828
1177.38	75.5678
1183.03	65.7491
1188.67	48.3245
1194.31	24.169
1199.95	29.429
1205.58	21.1203
1211.21	4.92008
1216.84	7.4412
1222.46	8.03044
1228.07	6.62518
1233.68	9.17065
1239.29	5.62106
1244.89	11.0284
1250.49	6.25208
1256.08	10.4995
1261.67	7.57185
1267.26	2.61349
1272.84	10.7117
1278.42	4.69101
1283.99	-0.294174
1289.56	-0.220657
1295.12	4.89924
1300.68	6.0672
1306.23	-1.68481
1311.78	5.67477
1317.33	5.08389
1322.87	-2.55305
1328.41	4.97973
1333.94	4.41554
1339.47	0.740349
1345	-2.00834
1350.52	4.42178
1356.04	-0.457573
1361.55	6.93228
1367.06	13.2345
1372.56	14.3592
1378.06	13.4245
1383.56	5.29177
1389.05	9.47227
1394.53	5.48721
1400.02	5.70213
1405.5	1.79111
1410.97	8.19569
1416.44	4.31517
1421.91	7.67238
1427.37	2.75011
1432.83	6.12801
1438.28	0.117371
1443.73	5.5756
1449.17	6.82843
1454.62	1.70953
1460.05	1.77591
1465.48	4.94853
1470.91	-1.34886
1476.34	7.06036
1481.76	1.85031
1487.17	5.05763
1492.59	4.09446
1497.99	12.6444
1503.4	9.62997
1508.8	12.9789
1514.19	8.93491
1519.59	4.88837
1524.97	1.89149
1530.36	9.59657
1535.74	6.60016
1541.11	4.58613
1546.48	4.62829
1551.85	9.95962
1557.21	6.5313
1562.57	8.51826
1567.93	6.17985
1573.28	7.06807
1578.62	7.99236
1583.97	15.4138
1589.3	9.93478
1594.64	10.9461
1599.97	17.389
1605.3	11.9959
1610.62	15.3094
1615.94	18.7086
1621.25	4.68784
1626.56	21.2449
1631.87	11.5007
1637.17	21.4853
1642.47	16.9898
1647.76	15.8184
1653.05	15.7119
1658.34	16.6632
1663.62	16.4718
1668.9	15.146
1674.18	10.481
1679.45	14.6658
1684.71	19.9019
1689.98	8.50534
1695.23	13.7707
1700.49	12.5133
1705.74	9.34295
1710.99	2.49687
1716.23	16.7594
1721.47	10.03
1726.7	9.88471
1731.94	6.40743
1737.16	6.27863
1742.39	-0.62439
1747.61	10.5047
1752.82	14.8366
1758.03	6.68321
1763.24	5.26579
1768.44	1.59068
1773.64	11.5228
1778.84	11.2943
1784.03	6.56052
1789.22	7.53811
1794.41	13.1063
1799.59	13.0059
1804.76	11.7762
1809.94	8.20378
1815.11	13.8116
1820.27	9.04779
1825.43	-0.361443
1830.59	2.95872
1835.74	3.97974
1840.89	1.46649
1846.04	7.09383
1851.18	4.53912
1856.32	10.1424
1861.45	6.42726
1866.58	-3.15807
1871.71	6.04084
1876.83	9.33106
1881.95	-1.55459
1887.07	8.79183
1892.18	7.257
1897.29	4.52998
1902.39	8.98395
1907.49	6.42174
1912.59	2.74149
1917.68	5.0453
1922.77	4.77171
1927.86	6.97044
1932.94	6.77544
1938.02	4.15422
1943.09	9.91341
1948.16	10.8416
1953.23	2.09053
1958.29	-9.10237
1963.35	13.433
1968.41	5.8093
1973.46	5.37736
1978.51	7.35397
1983.55	3.31034
1988.59	1.68817
1993.63	2.48457
1998.66	5.70714
2003.69	13.7688
2008.72	1.42713
2013.74	7.15478
2018.76	15.2875
2023.77	12.5969
2028.78	12.3722
2033.79	10.9919
2038.79	7.1981
2043.79	8.26109
2048.79	6.91489
2053.78	9.1773
2058.77	9.03991
2063.76	8.92274
2068.74	11.2611
2073.72	9.91111
2078.69	9.77589
2083.66	7.14789
2088.63	19.3022
2093.59	14.2139
2098.55	17.8544
2103.51	11.5814
2108.46	0.316849
2113.41	19.0485
2118.36	19.0882
2123.3	16.6034
2128.24	15.35
2133.17	25.4538
2138.11	20.3498
2143.03	22.8349
2147.96	24.0178
2152.88	17.4922
2157.79	10.9136
2162.71	11.953
2167.62	7.83339
2172.52	12.6936
2177.43	8.61829
2182.32	10.8777
2187.22	7.98599
2192.11	14.1159
2197	13.892
2201.89	9.8893
2206.77	2.06922
2211.64	18.735
2216.52	7.10722
2221.39	7.09973
2226.26	9.69043
2231.12	8.39384
2235.98	1.87569
2240.84	12.3186
2245.69	12.3391
2250.54	9.73045
2255.39	8.41667
2260.23	1.8337
2265.07	4.44678
2269.9	5.69316
2274.74	-3.72568
2279.57	8.06775
2284.39	2.52724
2289.21	15.5752
2294.03	6.00323
2298.84	11.1098
2303.66	2.95274
2308.46	9.53477
2313.27	5.49747
2318.07	6.85468
2322.87	23.0116
2327.66	6.92979
2332.45	7.00451
2337.24	5.75102
2342.02	8.59072
2346.8	4.6709
2351.58	10.298
2356.35	13.1557
2361.12	7.66288
2365.89	6.27269
2370.65	22.86
2375.41	7.61573
2380.17	10.3382
2384.92	10.2108
2389.67	7.24973
2394.42	1.44545
2399.16	1.16178
2403.9	-0.524513
2408.64	-7.75735
2413.37	17.2537
2418.1	9.22659
2422.83	9.3634
2427.55	6.47442
2432.27	7.93339
2436.99	9.45023
2441.7	1.03836
2446.41	8.23848
2451.11	12.6302
2455.82	24.1923
2460.51	24.3302
2465.21	5.73006
2469.9	21.6739
2474.59	15.9523
2479.28	7.31299
2483.96	13.1569
2488.64	-2.90301
2493.32	18.9669
2497.99	7.24562
2502.66	5.72186
2507.32	10.0464
2511.99	15.8209
2516.65	11.2632
2521.3	15.5914
2525.96	6.62331
2530.61	15.3937
2535.25	9.39659
2539.89	12.3199
2544.53	7.8172
2549.17	6.30264
2553.8	16.7434
2558.43	7.68573
2563.06	19.6645
2567.68	1.62981
2572.3	18.2483
2576.92	6.16779
2581.53	18.2399
2586.14	21.1383
2590.75	8.75259
2595.35	16.174
2599.96	17.5812
2604.55	15.89
2609.15	17.2282
2613.74	20.0375
2618.33	22.8662
2622.91	24.1695
2627.49	19.3773
2632.07	13.1443
2636.64	16.2294
2641.22	3.97285
2645.78	22.6566
2650.35	21.2132
2654.91	21.258
2659.47	19.5893
2664.03	20.9907
2668.58	27.0862
2673.13	22.3291
2677.67	19.3731
2682.22	27.6824
2686.76	26.4553
2691.29	29.9432
2695.83	29.981
2700.36	31.5364
2704.89	23.4343
2709.41	39.4305
2713.93	31.2688
2718.45	18.2952
2722.96	24.6571
2727.47	22.8414
2731.98	37.1845
2736.49	25.529
2740.99	20.3621
2745.49	23.4023
2749.98	20.006
2754.47	28.2508
2758.96	24.8685
2763.45	11.5549
2767.93	29.536
2772.41	14.5911
2776.89	22.8166
2781.36	21.2434
2785.84	16.3865
2790.3	18.1577
2794.77	16.5589
2799.23	14.8786
2803.69	24.9099
2808.14	34.9294
2812.59	26.3774
2817.04	26.1887
2821.49	27.709
2825.93	3.80974
2830.37	30.7945
2834.81	11.8837
2839.24	15.0741
2843.67	4.6319
2848.1	9.59328
2852.53	26.6206
2856.95	19.7545
2861.37	23.1995
2865.78	26.7482
2870.19	0.883316
2874.6	11.3502
2879.01	30.6288
2883.41	9.84358
2887.81	25.8064
2892.21	-0.444336
2896.6	8.50909
2901	1.59419
2905.38	12.3425
2909.77	17.7693
2914.15	23.1102
2918.53	26.6799
2922.91	14.1266
2927.28	17.7953
2931.65	12.4745
2936.02	5.22997
2940.38	23.2945
2944.74	15.9289
2949.1	10.2839
2953.46	17.4181
2957.81	24.5632
2962.16	20.7654
2966.5	11.4913
2970.85	18.7508
2975.19	9.49237
2979.52	29.6996
2983.86	33.4297
2988.19	29.8429
2992.52	18.8602
2996.85	24.6018
3001.17	22.9637
3005.49	25.1139
3009.8	27.2721
3014.12	27.5208
3018.43	35.4435
3022.74	49.1188
3027.04	45.5984
3031.34	51.5289
3035.64	43.9824
3039.94	49.8183
3044.23	42.2251
3048.52	28.7841
3052.81	57.7335
3057.09	52.0382
3061.38	55.9911
3065.65	67.7218
3069.93	77.5531
3074.2	81.596
3078.47	68.131
3082.74	74.1543
3087	97.9349
3091.27	96.4474
3095.52	97.0424
3099.78	107.555
3104.03	96.3941
3108.28	91.2045
3112.53	106.021
3116.77	124.952
3121.01	99.7738
3125.25	125.039
3129.49	130.3
3133.72	127.536
3137.95	149.332
3142.18	160.908
3146.4	153.833
3150.62	152.834
3154.84	162.026
3159.06	160.779
3163.27	149.067
3167.48	191.846
3171.69	161.113
3175.89	176.568
3180.09	155.888
3184.29	194.374
3188.49	150.098
3192.68	180.233
3196.87	180.851
3201.06	203.291
3205.24	200.305
3209.42	171.646
3213.6	177.37
3217.78	176.708
3221.95	149.778
3226.12	168.58
3230.29	167.728
3234.45	157.998
3238.61	157.003
3242.77	158.378
3246.93	133.054
3251.08	131.898
3255.23	119.267
3259.38	124.615
3263.53	116.672
3267.67	136.403
3271.81	142.312
3275.95	118.083
3280.08	125.635
3284.21	119.451
3288.34	124.727
3292.47	136.896
3296.59	112.169
3300.71	103.625
3304.83	122.815
3308.95	111.919
3313.06	124.166
3317.17	96.9163
3321.27	127.97
3325.38	119.518
3329.48	115.783
3333.58	121.701
3337.67	146.559
3341.77	119.155
3345.86	155.545
3349.95	111.133
3354.03	128.495
3358.11	146.087
3362.19	115.938
3366.27	131.155
3370.34	115.221
3374.42	118.388
3378.48	133.515
3382.55	122.103
3386.61	127.549
3390.68	116.031
3394.73	138.414
3398.79	114.879
3402.84	127.616
3406.89	116.01
3410.94	126.249
3414.98	124.316
3419.03	146.756
3423.06	120.429
3427.1	125.835
3431.14	133.795
3435.17	124.731
3439.2	123.081
3443.22	116.566
3447.25	107.718
3451.27	118.59
3455.28	112.311
3459.3	143.379
3463.31	119.883
3467.32	133.731
3471.33	97.4329
3475.34	103.487
3479.34	94.5434
3483.34	118.417
3487.33	99.2472
3491.33	107.931
3495.32	88.5315
3499.31	91.9666
3503.3	92.7548
3507.28	80.6349
3511.26	106.821
3515.24	76.4724
3519.22	87.1991
3523.19	100.506
3527.16	80.4214
3531.13	83.4699
3535.1	89.3622
3539.06	95.4325
3543.02	96.2544
3546.98	68.4273
3550.93	69.0096
3554.89	90.1803
3558.84	75.1109
3562.78	75.716
3566.73	102.519
3570.67	71.9797
3574.61	101.598
3578.55	99.9077
3582.48	103.568
3586.41	75.5305
3590.35	71.174
3594.27	74.7572
3598.2	59.6675
3602.12	63.1388
3606.04	55.8657
3609.95	45.7988
3613.87	51.8333
3617.78	55.1444
3621.69	42.1492
3625.6	50.592
3629.5	56.3103
3633.4	48.4408
3637.3	29.8137
3641.2	38.3925
3645.09	36.2191
3648.98	39.3747
3652.87	7.0374
3656.76	37.3139
3660.64	23.961
3664.53	35.1377
3668.4	21.78
3672.28	22.0534
3676.16	30.6364
3680.03	42.0717
3683.9	12.355
3687.76	26.7038
3691.63	27.2977
3695.49	22.2715
3699.35	22.8094
3703.2	34.4756
3707.06	15.4657
3710.91	21.5809
3714.76	10.8143
3718.6	30.9234
3722.45	11.532
3726.29	6.16385
3730.13	20.6044
3733.97	32.2838
3737.8	9.85359
3741.63	-4.14763
3745.46	27.4462
3749.29	27.6461
3753.11	30.6428
3756.93	7.81447
3760.75	7.82938
3764.57	10.6906
3768.39	10.7005
3772.2	5.01605
3776.01	10.8113
3779.81	22.4065
3783.62	8.17679
3787.42	11.2177
3791.22	2.68077
3795.02	5.74638
3798.81	-8.52234
3802.61	14.9299
3806.4	6.4881
3810.18	-10.7473
3813.97	15.7709
3817.75	-1.5625
3821.53	10.3756
3825.31	16.4314
3829.09	4.84712
3832.86	8.02139
3836.63	25.9694
3840.4	11.3804
3844.17	5.7067
3847.93	-9.06923
3851.69	2.85777
3855.45	8.82391
3859.21	-6.0723
3862.96	2.86769
3866.71	32.9188
3870.46	9.49268
3874.21	6.60561
3877.95	12.7137
3881.69	-8.06612
3885.44	-1.89066
3889.17	10.3364
3892.91	1.65936
3896.64	26.1316
3900.37	20.5522
3904.1	11.9503
3907.82	9.37605
3911.55	6.85498
3915.27	-1.67685
3918.99	8.05849
3922.7	-6.41306
3926.42	-17.8987
3930.13	4.19089
3933.84	1.83984
3937.54	2.5477
3941.25	3.35184
3944.95	7.32816
3948.65	-7.1671
3952.35	12.247
3956.04	13.1817
3959.73	1.73112
3963.42	5.76967
3967.11	-2.56776
3970.8	10.8017
3974.48	5.65782
3978.16	3.66338
3981.84	10.9903
3985.52	12.1835
3989.19	28.957
3992.86	14.859
3996.53	10.1967
3998.37	14.1247