File: Data/3-Raman/processed/bu19w-e-ff11-fi01-v_150 (500nm)_633nm_edge_100%_x100_vis_h50um_60sx2_01_0.txt
#Acq. time (s)=	60
#Accumulations=	2
#Range (cm-¹)=	100...4000
#Windows=	1
#Auto scanning=	Off
#Autofocus=	Off
#Macrospot=	Off
#AutoExposure=	Off
#Spike filter=	Multiple accum.
#Delay time (s)=	2
#Binning=	1
#Readout mode=	Signal
#DeNoise=	Off
#ICS correction=	On
#Dark correction=	Off
#Inst. Process=	Off
#Detector Gain=	Best Dynamic
#Detector ADC=	50 kHz HS
#Detector temperature (°C)=	-60.28
#Instrument=	LabRAM HR Evol
#Detector=	SIN-EM FIVIS
#Objective=	x100_VIS
#Grating=	150 (500nm)
#ND Filter=	100%
#Laser=	633nm_Edge
#Hole=	49.98
#Temperature=	0
#Range=	Visible
#StageXY=	75x50mm Scan+
#StageZ=	Z motor
#X (µm)=	0
#Y (µm)=	0
#Z (µm)=	-289.1
#Full time(mm:ss)=	2:04
#Project=	21_11_04
#Sample=	BU19w
#Site=
#Title=	BU19w-E-FF11-FI01-V_150 (500nm)_633nm_Edge_100%_x100_VIS_H50um_60sX2
#Remark=
#Date=	04.11.2021 16:41
#Acquired=	04.11.2021 16:41:53
#Base:Fit=	16.12.2021 17:39:50
#Base:Fit=	16.12.2021 17:50:25
#Base:Edit=	16.12.2021 17:50:28
#Base:Edit=	16.12.2021 17:50:29
#Base:Edit=	16.12.2021 17:50:30
#Peaks:Remove=	16.12.2021 17:50:32
#Peaks:Remove=	16.12.2021 17:50:33
#Peaks:Remove=	16.12.2021 17:50:34
#Base:Edit=	16.12.2021 17:50:36
#Base:Edit=	16.12.2021 17:50:37
#Base:Edit=	16.12.2021 17:50:38
#Base:Edit=	16.12.2021 17:50:40
#Base:Edit=	16.12.2021 17:50:40
#Base:Sub=	16.12.2021 17:50:42
102.881	137.933
109.397	105.104
115.908	74.1533
122.414	67.0249
128.914	59.8969
135.409	62.3035
141.898	54.1476
148.383	46.038
154.861	76.2741
161.335	70.1726
167.801	32.4364
174.264	21.4741
180.721	-0.0880356
187.173	5.12055
193.62	-0.238419
200.061	-2.66825
206.496	3.60661
212.926	7.94608
219.352	22.7785
225.772	74.7201
232.185	98.8359
238.595	53.5865
244.999	18.9258
251.397	18.4964
257.791	37.0286
264.178	31.8557
270.561	26.7094
276.939	35.8096
283.31	39.1839
289.678	18.8214
296.039	16.4375
302.396	22.5674
308.746	50.4046
315.093	150.909
321.433	192.811
327.768	108.348
334.099	50.3565
340.423	31.0341
346.743	35.2654
353.058	51.7098
359.367	47.3692
365.671	33.6081
371.971	17.0527
378.265	12.716
384.553	7.47211
390.837	6.10064
397.116	1.04532
403.389	14.8707
409.657	14.5718
415.92	15.1455
422.178	29.874
428.431	36.7879
434.678	37.8479
440.921	41.7026
447.158	45.4985
453.391	57.6568
459.618	43.6933
465.84	22.4515
472.057	13.411
478.27	10.9742
484.477	14.1177
490.679	18.1876
496.876	28.7863
503.068	40.3354
509.255	40.7078
515.436	44.8408
521.613	44.3771
527.785	38.3515
533.952	38.0024
540.113	21.6293
546.27	20.1898
552.423	17.6966
558.568	14.2035
564.711	11.5005
570.848	12.4812
576.979	18.0636
583.107	18.0096
589.228	28.278
595.345	37.6912
601.458	31.4125
607.565	36.4559
613.667	37.832
619.764	30.8633
625.856	19.1906
631.944	12.0269
638.026	13.1732
644.104	14.1706
650.177	17.0323
656.244	14.1651
662.308	15.0324
668.365	0.982323
674.418	-0.760101
680.467	0.336159
686.511	0.560097
692.549	4.60545
698.582	-2.56198
704.611	-0.388527
710.635	6.44124
716.655	-3.80993
722.669	-6.52709
728.679	-3.66919
734.683	-3.65972
740.683	2.8903
746.678	3.83913
752.669	-3.56177
758.654	0.287216
764.635	-2.25037
770.611	3.68997
776.582	4.02076
782.549	7.10997
788.511	-4.92934
794.466	0.887428
800.419	2.87066
806.366	4.79065
812.309	6.66956
818.247	0.974411
824.18	-1.90952
830.108	9.2476
836.033	10.26
841.952	8.60464
847.865	6.96593
853.776	4.41875
859.681	14.1277
865.58	15.3955
871.476	25.1682
877.366	23.4839
883.253	23.6352
889.134	18.971
895.012	23.7395
900.883	21.7581
906.751	20.6653
912.614	15.7896
918.473	18.5045
924.326	33.544
930.174	33.692
936.019	42.4165
941.859	64.6089
947.693	72.7826
953.525	70.5472
959.35	71.067
965.171	79.1314
970.988	107.28
976.801	122.806
982.608	155.282
988.411	132.961
994.209	97.2812
1000	83.7068
1005.79	91.224
1011.58	97.9784
1017.36	103.91
1023.13	96.5545
1028.9	64.4199
1034.67	63.8642
1040.43	46.9696
1046.19	44.47
1051.94	37.0276
1057.69	29.4813
1063.44	27.6473
1069.17	34.4396
1074.91	38.3084
1080.64	47.9394
1086.37	74.0156
1092.09	111.724
1097.8	107.756
1103.52	74.7955
1109.22	56.4946
1114.93	44.1688
1120.63	45.5111
1126.32	44.7985
1132.01	56.8236
1137.7	76.7407
1143.38	108.527
1149.06	143.23
1154.73	99.0749
1160.4	38.951
1166.06	31.865
1171.72	13.0387
1177.38	18.7276
1183.03	13.6901
1188.67	9.74468
1194.31	11.7317
1199.95	9.89003
1205.58	1.27819
1211.21	5.45644
1216.84	-1.18222
1222.46	-5.86449
1228.07	3.39849
1233.68	4.67009
1239.29	-0.154976
1244.89	10.0385
1250.49	14.109
1256.08	14.0761
1261.67	14.945
1267.26	10.7479
1272.84	169.496
1278.42	41.4316
1283.99	8.08464
1289.56	3.90416
1295.12	7.77789
1300.68	1.70434
1306.23	10.7048
1311.78	3.80438
1317.33	-0.062561
1322.87	6.16322
1328.41	7.39875
1333.94	3.5426
1339.47	1.65977
1345	2.76291
1350.52	5.88512
1356.04	0.768738
1361.55	6.89484
1367.06	12.962
1372.56	28.2364
1378.06	311.54
1383.56	24.8561
1389.05	17.5139
1394.53	17.4109
1400.02	30.7846
1405.5	11.2553
1410.97	-0.0638046
1416.44	5.12875
1421.91	-3.10926
1427.37	-4.10623
1432.83	-4.06573
1438.28	6.40314
1443.73	4.3644
1449.17	-0.862022
1454.62	4.32084
1460.05	4.20419
1465.48	-2.25557
1470.91	2.81628
1476.34	4.7532
1481.76	1.47397
1487.17	1.36585
1492.59	3.3986
1497.99	8.63622
1503.4	-1.92326
1508.8	1.2606
1514.19	1.3013
1519.59	0.303604
1524.97	0.38166
1530.36	-1.68553
1535.74	-3.75231
1541.11	3.81766
1546.48	-0.576149
1551.85	0.315079
1557.21	4.34353
1562.57	-3.49118
1567.93	1.62235
1573.28	-1.89508
1578.62	-2.13728
1583.97	1.96758
1589.3	3.94277
1594.64	1.64365
1599.97	-2.78326
1605.3	0.381973
1610.62	-1.80129
1615.94	3.68018
1621.25	1.5883
1626.56	8.24394
1631.87	-0.467049
1637.17	-4.88408
1642.47	7.13221
1647.76	2.60307
1653.05	-0.863739
1658.34	0.0556793
1663.62	7.60187
1668.9	4.03951
1674.18	2.68708
1679.45	4.64351
1684.71	6.54995
1689.98	-3.73813
1695.23	1.5284
1700.49	5.81089
1705.74	4.8811
1710.99	1.39628
1716.23	-4.40871
1721.47	1.14955
1726.7	1.0229
1731.94	-3.55638
1737.16	1.96348
1742.39	2.98867
1747.61	-0.513382
1752.82	2.71809
1758.03	-3.13775
1763.24	4.5425
1768.44	0.913284
1773.64	1.82632
1778.84	0.507904
1784.03	1.50092
1789.22	3.67337
1794.41	8.16157
1799.59	3.54556
1804.76	3.51427
1809.94	3.44878
1815.11	3.35919
1820.27	-1.34979
1825.43	7.82063
1830.59	7.76013
1835.74	3.05991
1840.89	4.12343
1846.04	-1.84202
1851.18	0.348045
1856.32	1.34028
1861.45	1.21233
1866.58	2.28335
1871.71	0.975609
1876.83	-1.55621
1881.95	-1.74605
1887.07	-7.86729
1892.18	-2.23643
1897.29	1.02302
1902.39	-0.363831
1907.49	-2.85787
1912.59	3.0411
1917.68	-2.91288
1922.77	-0.725487
1927.86	6.33498
1932.94	-2.1706
1938.02	0.0802917
1943.09	4.71153
1948.16	0.896507
1953.23	1.85188
1958.29	-3.24271
1963.35	-7.15134
1968.41	4.57866
1973.46	-10.2401
1978.51	12.2749
1983.55	-1.3325
1988.59	1.9213
1993.63	1.57844
1998.66	-3.55075
2003.69	5.77435
2008.72	-1.69665
2013.74	4.09131
2018.76	1.43944
2023.77	-2.40838
2028.78	1.02973
2033.79	3.31853
2038.79	-5.27796
2043.79	3.10409
2048.79	9.10598
2053.78	2.89172
2058.77	0.351021
2063.76	2.71516
2068.74	1.40821
2073.72	-3.60437
2078.69	1.20763
2083.66	-1.39291
2088.63	4.60877
2093.59	4.48595
2098.55	0.696304
2103.51	3.12705
2108.46	4.35019
2113.41	23.1287
2118.36	-5.65213
2123.3	1.88995
2128.24	3.14764
2133.17	0.586929
2138.11	4.32863
2143.03	10.6133
2147.96	6.69473
2152.88	6.5369
2157.79	1.23407
2162.71	16.332
2167.62	-6.95875
2172.52	8.12932
2177.43	-1.06789
2182.32	-1.37252
2187.22	3.41276
2192.11	-1.98889
2197	1.61403
2201.89	0.155907
2206.77	5.16572
2211.64	-5.21505
2216.52	3.7485
2221.39	-2.74686
2226.26	7.59347
2231.12	-5.42709
2235.98	1.04716
2240.84	-4.21494
2245.69	4.9218
2250.54	3.59072
2255.39	2.24256
2260.23	-4.37662
2265.07	-1.80022
2269.9	8.69176
2274.74	5.88852
2279.57	0.380173
2284.39	1.45219
2289.21	-5.49261
2294.03	0.862473
2298.84	-3.39098
2303.66	-10.2657
2308.46	5.60493
2313.27	9.55219
2318.07	16.2507
2322.87	22.9871
2327.66	-1.21592
2332.45	6.91377
2337.24	12.4079
2342.02	-1.08904
2346.8	-6.44048
2351.58	-3.62451
2356.35	3.28
2361.12	10.1246
2365.89	7.32088
2370.65	0.354202
2375.41	-5.27107
2380.17	-6.77762
2384.92	9.71529
2389.67	1.14377
2394.42	3.64213
2399.16	6.09414
2403.9	7.14259
2408.64	-0.136726
2413.37	6.72329
2418.1	-1.37729
2422.83	-12.5487
2427.55	-8.47216
2432.27	1.38441
2436.99	1.43674
2441.7	5.75136
2446.41	0.120758
2451.11	10.1751
2455.82	-2.64973
2460.51	-1.17847
2465.21	0.296051
2469.9	0.309067
2474.59	4.64839
2479.28	-4.0429
2483.96	1.75148
2488.64	1.6922
2493.32	10.394
2497.99	0.099884
2502.66	4.41351
2507.32	-3.04385
2511.99	11.526
2516.65	-6.32204
2521.3	-0.560089
2525.96	-5.13098
2530.61	6.57111
2535.25	4.99995
2539.89	10.8816
2544.53	-1.0755
2549.17	7.83937
2553.8	-8.64643
2558.43	3.23442
2563.06	3.19102
2567.68	-1.32367
2572.3	13.7884
2576.92	4.73619
2581.53	0.13382
2586.14	-0.0207062
2590.75	-0.255112
2595.35	2.6031
2599.96	10.1028
2604.55	5.36726
2609.15	-2.45511
2613.74	3.41617
2618.33	4.72169
2622.91	-0.094162
2627.49	11.9818
2632.07	5.76917
2636.64	13.4962
2641.22	9.00206
2645.78	2.94923
2650.35	4.60458
2654.91	12.4498
2659.47	-6.36855
2664.03	4.42711
2668.58	-0.415985
2673.13	7.38106
2677.67	10.7375
2682.22	-1.50247
2686.76	5.16414
2691.29	10.2348
2695.83	-12.127
2700.36	-0.965347
2704.89	5.40617
2709.41	6.94305
2713.93	-1.20442
2718.45	1.998
2722.96	0.305054
2727.47	-1.4682
2731.98	-1.68668
2736.49	6.20509
2740.99	2.72748
2745.49	-5.57274
2749.98	-4.03894
2754.47	4.22798
2758.96	-0.748688
2763.45	5.69341
2767.93	12.2399
2772.41	2.30316
2776.89	0.682602
2781.36	2.4595
2785.84	-0.692322
2790.3	-2.20842
2794.77	-2.08975
2799.23	11.3907
2803.69	1.33405
2808.14	-2.07248
2812.59	7.9894
2817.04	4.49771
2821.49	1.01035
2825.93	4.32132
2830.37	4.2267
2834.81	-0.998093
2839.24	-4.53238
2843.67	2.17471
2848.1	-1.30467
2852.53	-9.88719
2856.95	15.906
2861.37	-16.7073
2865.78	2.38266
2870.19	6.01428
2874.6	-14.6714
2879.01	15.102
2883.41	-3.87074
2887.81	8.64767
2892.21	-8.73512
2896.6	-3.23111
2901	2.34863
2905.38	4.31245
2909.77	-6.2406
2914.15	9.89503
2918.53	-0.803558
2922.91	-0.727264
2927.28	-4.20302
2931.65	-4.05418
2936.02	-7.60579
2940.38	-0.359116
2944.74	19.6368
2949.1	10.4565
2953.46	-2.38206
2957.81	-9.78406
2962.16	-13.532
2966.5	8.40361
2970.85	19.4281
2975.19	4.74599
2979.52	-4.45975
2983.86	8.52515
2988.19	8.66895
2992.52	3.28685
2996.85	9.06844
3001.17	-7.48683
3005.49	9.64058
3009.8	6.18042
3014.12	-2.998
3018.43	2.99307
3022.74	-4.28474
3027.04	7.35562
3031.34	7.52165
3035.64	11.4381
3039.94	11.5149
3044.23	-1.8629
3048.52	5.86029
3052.81	3.95706
3057.09	2.07774
3061.38	13.7337
3065.65	9.91705
3069.93	15.8018
3074.2	2.25372
3078.47	23.775
3082.74	12.1635
3087	6.45847
3091.27	10.6322
3095.52	18.8515
3099.78	9.36188
3104.03	17.6972
3108.28	28.1395
3112.53	22.7229
3116.77	11.2343
3121.01	46.0129
3125.25	20.4589
3129.49	31.3162
3133.72	34.1707
3137.95	37.0253
3142.18	46.0141
3146.4	30.163
3150.62	24.5105
3154.84	33.2705
3159.06	25.3362
3163.27	36.233
3167.48	55.5406
3171.69	41.2441
3175.89	43.6891
3180.09	33.3071
3184.29	50.3749
3188.49	41.9495
3192.68	42.1129
3196.87	31.7431
3201.06	53.6228
3205.24	30.7308
3209.42	46.4894
3213.6	32.1591
3217.78	30.7718
3221.95	44.5527
3226.12	38.767
3230.29	52.6732
3234.45	33.5869
3238.61	29.818
3242.77	43.8869
3246.93	22.4218
3251.08	29.72
3255.23	27.9191
3259.38	28.3893
3263.53	13.212
3267.67	9.58549
3271.81	8.00415
3275.95	19.8365
3280.08	36.198
3284.21	38.8613
3288.34	36.9318
3292.47	32.6673
3296.59	21.4446
3300.71	21.8032
3304.83	29.0952
3308.95	13.2141
3313.06	13.5057
3317.17	18.4855
3321.27	42.2063
3325.38	26.3563
3329.48	38.6188
3333.58	18.2017
3337.67	37.7971
3341.77	28.8828
3345.86	36.4318
3349.95	39.1777
3354.03	34.8027
3358.11	28.1388
3362.19	23.8496
3366.27	26.7024
3370.34	43.9902
3374.42	8.33601
3378.48	23.1115
3382.55	16.1877
3386.61	28.5601
3390.68	26.4195
3394.73	24.2897
3398.79	36.7805
3402.84	29.8101
3406.89	27.6449
3410.94	20.5907
3414.98	20.8212
3419.03	28.3712
3423.06	31.0351
3427.1	19.0989
3431.14	12.0951
3435.17	24.7008
3439.2	27.6078
3443.22	15.8322
3447.25	28.7297
3451.27	24.4393
3455.28	12.7847
3459.3	25.9879
3463.31	26.8527
3467.32	27.7292
3471.33	33.5902
3475.34	11.6649
3479.34	27.5423
3483.34	3.0071
3487.33	26.5282
3491.33	29.8027
3495.32	25.395
3499.31	-12.3334
3503.3	31.6925
3507.28	9.10483
3511.26	6.8746
3515.24	14.8863
3519.22	15.1879
3523.19	5.20372
3527.16	28.7105
3531.13	18.7548
3535.1	16.723
3539.06	-8.47133
3543.02	5.04405
3546.98	13.3554
3550.93	16.4177
3554.89	16.7148
3558.84	17.1476
3562.78	25.4658
3566.73	2.55687
3570.67	-2.03848
3574.61	11.6917
3578.55	22.9349
3582.48	0.0341339
3586.41	0.815842
3590.35	14.8527
3594.27	15.6663
3598.2	16.4754
3602.12	6.53165
3606.04	7.23848
3609.95	10.5807
3613.87	-12.9851
3617.78	28.0596
3621.69	-11.8888
3625.6	-3.3848
3629.5	-5.70583
3633.4	13.5751
3637.3	0.464874
3641.2	3.72125
3645.09	7.0732
3648.98	10.349
3652.87	-0.0589752
3656.76	-2.33144
3660.64	17.2128
3664.53	1.2679
3668.4	9.94997
3672.28	-8.72987
3676.16	13.7369
3680.03	6.15878
3683.9	-4.12486
3687.76	-6.11778
3691.63	5.72682
3695.49	12.0241
3699.35	-17.7833
3703.2	10.8098
3707.06	8.82143
3710.91	1.20454
3714.76	7.57597
3718.6	5.45238
3722.45	-2.36584
3726.29	-13.0834
3730.13	-6.83887
3733.97	-17.5811
3737.8	-14.1496
3741.63	14.9098
3745.46	21.2089
3749.29	4.61888
3753.11	5.10052
3756.93	-5.92099
3760.75	-14.1301
3764.57	12.0298
3768.39	0.954636
3772.2	4.25929
3776.01	-21.1534
3779.81	2.30042
3783.62	17.2318
3787.42	6.25807
3791.22	-1.89319
3795.02	4.44884
3798.81	-3.63596
3802.61	-0.121628
3806.4	3.43112
3810.18	12.8306
3813.97	-4.09007
3817.75	2.34567
3821.53	8.78365
3825.31	6.37399
3829.09	-16.6576
3832.86	4.51918
3836.63	13.9237
3840.4	-3.3241
3844.17	0.179901
3847.93	12.42
3851.69	-5.05795
3855.45	-4.76402
3859.21	-1.5631
3862.96	13.5699
3866.71	8.1127
3870.46	-0.252716
3874.21	-2.9597
3877.95	-2.673
3881.69	-2.38681
3885.44	21.8673
3889.17	4.23862
3892.91	10.6106
3896.64	17.0856
3900.37	8.47462
3904.1	-0.183609
3907.82	0.172241
3911.55	9.6228
3915.27	-14.1982
3918.99	16.5696
3922.7	-13.33
3926.42	5.39293
3930.13	-6.40598
3933.84	-6.07431
3937.54	9.54311
3941.25	0.685425
3944.95	-5.09132
3948.65	1.40358
3952.35	-4.49539
3956.04	-10.4486
3959.73	-1.00032
3963.42	-13.2561
3967.11	2.31551
3970.8	-0.753357
3974.48	-0.713898
3978.16	8.60724
3981.84	-13.1459
3985.52	-10.0983
3989.19	11.5462
3992.86	5.3315
3996.53	-3.94556
3998.37	5.40207