File: Data/3-Raman/processed/bu19w-e-ff11-fi02-v_150 (500nm)_633nm_edge_100%_x100_vis_h50um_60sx2_01_0.txt
#Acq. time (s)=	60
#Accumulations=	2
#Range (cm-¹)=	100...4000
#Windows=	1
#Auto scanning=	Off
#Autofocus=	Off
#Macrospot=	Off
#AutoExposure=	Off
#Spike filter=	Multiple accum.
#Delay time (s)=	2
#Binning=	1
#Readout mode=	Signal
#DeNoise=	Off
#ICS correction=	On
#Dark correction=	Off
#Inst. Process=	Off
#Detector Gain=	Best Dynamic
#Detector ADC=	50 kHz HS
#Detector temperature (°C)=	-60.09
#Instrument=	LabRAM HR Evol
#Detector=	SIN-EM FIVIS
#Objective=	x100_VIS
#Grating=	150 (500nm)
#ND Filter=	100%
#Laser=	633nm_Edge
#Hole=	49.98
#Temperature=	0
#Range=	Visible
#StageXY=	75x50mm Scan+
#StageZ=	Z motor
#X (µm)=	0
#Y (µm)=	0
#Z (µm)=	-280.8
#Full time(mm:ss)=	2:04
#Project=	21_11_04
#Sample=	BU19w
#Site=
#Title=	BU19w-E-FF11-FI02-V_150 (500nm)_633nm_Edge_100%_x100_VIS_H50um_60sX2
#Remark=
#Date=	04.11.2021 16:26
#Acquired=	04.11.2021 16:26:08
#Base:Fit=	16.12.2021 17:39:50
#Base:Sub=	16.12.2021 17:51:16
102.881	144.076
109.397	123.763
115.908	88.6391
122.414	88.3068
128.914	77.8922
135.409	78.3735
141.898	83.9848
148.383	72.7781
154.861	104.088
161.335	83.0993
167.801	37.4753
174.264	21.7817
180.721	15.881
187.173	2.50616
193.62	6.55772
200.061	4.18817
206.496	3.10806
212.926	6.01196
219.352	23.4055
225.772	81.8826
232.185	98.3912
238.595	46.6535
244.999	12.3034
251.397	30.3535
257.791	31.3971
264.178	22.1443
270.561	13.0214
276.939	39.1023
283.31	34.8813
289.678	17.4271
296.039	20.8536
302.396	30.9556
308.746	58.0871
315.093	155.109
321.433	214.344
327.768	111.401
334.099	60.4431
340.423	37.8079
346.743	41.58
353.058	50.9901
359.367	53.7601
365.671	23.6012
371.971	17.9356
378.265	4.76846
384.553	14.1577
390.837	0.231987
397.116	7.96397
403.389	14.8573
409.657	17.0232
415.92	25.7265
422.178	39.13
428.431	43.7324
434.678	50.9503
440.921	57.1576
447.158	57.6474
453.391	62.7592
459.618	46.443
465.84	23.7781
472.057	18.89
478.27	21.5214
484.477	33.4413
490.679	36.9512
496.876	35.7859
503.068	47.665
509.255	51.1458
515.436	54.6371
521.613	62.8631
527.785	55.2383
533.952	58.9052
540.113	50.3115
546.27	34.0031
552.423	36.3946
558.568	19.8214
564.711	24.773
570.848	23.0018
576.979	27.6969
583.107	39.8339
589.228	40.7654
595.345	40.8665
601.458	52.2942
607.565	62.9453
613.667	50.3035
619.764	60.1928
625.856	31.5989
631.944	26.2549
638.026	25.417
644.104	37.5877
650.177	40.2892
656.244	23.1608
662.308	22.9215
668.365	10.5584
674.418	12.3653
680.467	11.4093
686.511	11.4441
692.549	9.69016
698.582	9.81404
704.611	3.33393
710.635	8.05537
716.655	7.90327
722.669	7.75304
728.679	9.40308
734.683	5.38835
740.683	13.5309
746.678	4.86649
752.669	12.1149
758.654	13.8275
764.635	2.63864
770.611	8.32273
776.582	5.57738
782.549	2.74924
788.511	9.27978
794.466	9.17245
800.419	9.93428
806.366	13.4531
812.309	15.0407
818.247	4.35349
824.18	12.4205
830.108	12.0546
836.033	8.1296
841.952	4.34621
847.865	4.32677
853.776	13.7464
859.681	14.7687
865.58	24.312
871.476	23.4675
877.366	24.4006
883.253	38.5626
889.134	40.3181
895.012	32.5257
900.883	33.1459
906.751	33.6922
912.614	25.7392
918.473	27.2873
924.326	28.0434
930.174	39.2973
936.019	46.9362
941.859	64.2891
947.693	79.9304
953.525	76.6596
959.35	84.7336
965.171	86.9772
970.988	119.831
976.801	160.215
982.608	182.948
988.411	160.469
994.209	117.941
1000	90.8745
1005.79	89.719
1011.58	92.5941
1017.36	110.879
1023.13	112.099
1028.9	70.4018
1034.67	60.2482
1040.43	60.6931
1046.19	62.1159
1051.94	44.0696
1057.69	29.7539
1063.44	35.7033
1069.17	33.7584
1074.91	40.553
1080.64	64.7466
1086.37	99.5499
1092.09	133.402
1097.8	130.427
1103.52	77.187
1109.22	63.7904
1114.93	54.477
1120.63	56.928
1126.32	56.3402
1132.01	68.5025
1137.7	96.4025
1143.38	121.477
1149.06	160.249
1154.73	106.372
1160.4	50.2864
1166.06	33.4542
1171.72	39.2385
1177.38	22.4758
1183.03	13.6398
1188.67	16.6615
1194.31	8.04661
1199.95	8.31235
1205.58	4.77738
1211.21	6.19103
1216.84	3.70206
1222.46	2.21992
1228.07	3.72167
1233.68	7.19485
1239.29	1.55994
1244.89	0.837502
1250.49	10.1244
1256.08	12.2824
1261.67	4.23501
1267.26	14.3263
1272.84	105.829
1278.42	43.3132
1283.99	6.12015
1289.56	11.1141
1295.12	7.16119
1300.68	13.259
1306.23	9.45206
1311.78	4.74723
1317.33	5.10367
1322.87	4.47947
1328.41	3.88043
1333.94	2.24316
1339.47	7.69621
1345	1.83949
1350.52	5.14568
1356.04	7.39877
1361.55	11.6542
1367.06	14.8134
1372.56	23.068
1378.06	248.006
1383.56	26.1909
1389.05	4.65106
1394.53	12.9227
1400.02	33.6522
1405.5	-1.14524
1410.97	0.050354
1416.44	8.5053
1421.91	8.72037
1427.37	11.0257
1432.83	8.13705
1438.28	14.6134
1443.73	10.6506
1449.17	10.8237
1454.62	5.66413
1460.05	9.88485
1465.48	5.65756
1470.91	6.6581
1476.34	2.42367
1481.76	-1.78319
1487.17	7.68379
1492.59	10.8931
1497.99	10.9866
1503.4	4.76606
1508.8	8.07169
1514.19	9.29486
1519.59	9.48538
1524.97	16.1025
1530.36	5.59606
1535.74	13.3323
1541.11	14.5521
1546.48	11.335
1551.85	9.05802
1557.21	13.1493
1562.57	12.9297
1567.93	12.7019
1573.28	17.8506
1578.62	9.04521
1583.97	8.89799
1589.3	16.3096
1594.64	10.8316
1599.97	15.0915
1605.3	10.755
1610.62	16.218
1615.94	8.73057
1621.25	8.86229
1626.56	12.2727
1631.87	7.99048
1637.17	23.472
1642.47	11.2253
1647.76	1.17493
1653.05	9.89626
1658.34	6.38842
1663.62	15.0431
1668.9	10.3669
1674.18	13.4422
1679.45	10.9497
1684.71	13.946
1689.98	13.5995
1695.23	19.9484
1700.49	12.0357
1705.74	12.2144
1710.99	2.01468
1716.23	11.797
1721.47	-0.542908
1726.7	12.7354
1731.94	21.6131
1737.16	6.87957
1742.39	6.73714
1747.61	2.06055
1752.82	10.8967
1758.03	8.38872
1763.24	14.884
1768.44	5.53688
1773.64	6.39183
1778.84	11.8233
1784.03	17.3141
1789.22	1.22944
1794.41	17.0555
1799.59	10.1019
1804.76	11.1627
1809.94	14.4916
1815.11	8.58695
1820.27	3.81248
1825.43	15.232
1830.59	5.82629
1835.74	13.8383
1840.89	14.843
1846.04	4.14376
1851.18	7.43108
1856.32	11.863
1861.45	12.844
1866.58	13.8552
1871.71	14.8394
1876.83	6.34431
1881.95	9.62134
1887.07	-1.30228
1892.18	14.8844
1897.29	10.9655
1902.39	10.687
1907.49	14.0592
1912.59	4.46128
1917.68	13.9397
1922.77	7.69985
1927.86	9.90609
1932.94	18.112
1938.02	4.69942
1943.09	5.64613
1948.16	10.1774
1953.23	13.4654
1958.29	5.88272
1963.35	4.30478
1968.41	13.5418
1973.46	5.86391
1978.51	9.02911
1983.55	7.37563
1988.59	10.5477
1993.63	11.3278
1998.66	7.325
2003.69	5.75832
2008.72	5.43465
2013.74	14.7718
2018.76	2.4211
2023.77	20.2128
2028.78	11.544
2033.79	2.90582
2038.79	11.2172
2043.79	6.21921
2048.79	10.9575
2053.78	10.7896
2058.77	19.2104
2063.76	5.65143
2068.74	5.53243
2073.72	21.3906
2078.69	26.2098
2083.66	16.2054
2088.63	8.59363
2093.59	20.823
2098.55	5.86781
2103.51	12.0129
2108.46	16.9746
2113.41	14.4964
2118.36	14.5334
2123.3	18.3402
2128.24	0.689415
2133.17	15.8265
2138.11	13.2442
2143.03	10.6332
2147.96	9.24918
2152.88	20.5634
2157.79	16.5408
2162.71	11.1904
2167.62	14.7347
2172.52	0.406776
2177.43	14.2404
2182.32	19.054
2187.22	7.19196
2192.11	6.91401
2197	5.40141
2201.89	11.6548
2206.77	15.4106
2211.64	7.6422
2216.52	15.3629
2221.39	20.5658
2226.26	3.74198
2231.12	15.4515
2235.98	18.0937
2240.84	5.05924
2245.69	18.183
2250.54	18.2326
2255.39	6.4166
2260.23	14.3726
2265.07	10.4101
2269.9	6.37473
2274.74	18.2128
2279.57	16.7438
2284.39	12.5424
2289.21	0.317139
2294.03	9.37489
2298.84	10.4946
2303.66	10.3431
2308.46	11.6119
2313.27	11.6105
2318.07	39.8252
2322.87	14.4116
2327.66	18.5515
2332.45	14.6308
2337.24	9.36161
2342.02	19.0462
2346.8	13.8329
2351.58	11.3043
2356.35	12.8217
2361.12	15.6191
2365.89	19.7936
2370.65	6.00146
2375.41	29.5623
2380.17	17.0741
2384.92	14.1957
2389.67	1.51766
2394.42	16.6067
2399.16	6.59505
2403.9	21.6245
2408.64	14.4108
2413.37	17.1818
2418.1	9.20634
2422.83	7.97923
2427.55	14.9734
2432.27	24.9616
2436.99	12.415
2441.7	16.8337
2446.41	14.1554
2451.11	-1.38879
2455.82	20.2048
2460.51	14.6289
2465.21	11.8957
2469.9	17.7875
2474.59	12.1003
2479.28	13.662
2483.96	16.6546
2488.64	23.9862
2493.32	24.0273
2497.99	21.1501
2502.66	12.3584
2507.32	7.91682
2511.99	35.8133
2516.65	21.0037
2521.3	16.533
2525.96	34.2258
2530.61	7.54266
2535.25	14.9305
2539.89	17.9138
2544.53	11.9832
2549.17	25.4583
2553.8	25.5198
2558.43	31.5172
2563.06	21.068
2567.68	18.1501
2572.3	31.8489
2576.92	22.8848
2581.53	18.3616
2586.14	13.7162
2590.75	36.3316
2595.35	21.0079
2599.96	20.9508
2604.55	37.6284
2609.15	11.5393
2613.74	23.567
2618.33	14.2048
2622.91	24.7404
2627.49	16.9329
2632.07	33.7947
2636.64	40.0719
2641.22	31.043
2645.78	23.5268
2650.35	23.7032
2654.91	25.3739
2659.47	33.1388
2664.03	25.2284
2668.58	45.4798
2673.13	21.9825
2677.67	22.2402
2682.22	13.2195
2686.76	24.7178
2691.29	20.2793
2695.83	20.35
2700.36	23.5449
2704.89	12.2655
2709.41	25.0731
2713.93	18.552
2718.45	26.6272
2722.96	23.336
2727.47	24.8126
2731.98	22.9659
2736.49	25.9712
2740.99	14.3439
2745.49	20.6804
2749.98	12.4329
2754.47	33.799
2758.96	20.6377
2763.45	13.9305
2767.93	17.1549
2772.41	20.3639
2776.89	22.0403
2781.36	10.5673
2785.84	30.6697
2790.3	22.5229
2794.77	22.6564
2799.23	17.678
2803.69	27.7556
2808.14	14.2202
2812.59	12.4202
2817.04	8.86154
2821.49	44.2624
2825.93	18.7259
2830.37	37.267
2834.81	9.88402
2839.24	13.0977
2843.67	19.7448
2848.1	23.0481
2852.53	12.714
2856.95	10.9903
2861.37	17.8798
2865.78	12.7988
2870.19	19.8334
2874.6	16.4741
2879.01	16.6077
2883.41	20.2878
2887.81	25.7684
2892.21	13.627
2896.6	10.2654
2901	26.4392
2905.38	15.9101
2909.77	26.7089
2914.15	-0.142014
2918.53	8.75438
2922.91	21.3284
2927.28	21.4075
2931.65	19.7098
2936.02	23.3533
2940.38	10.5577
2944.74	10.4335
2949.1	22.9863
2953.46	22.8179
2957.81	8.01523
2962.16	16.9804
2966.5	7.67323
2970.85	27.7543
2975.19	11.1219
2979.52	31.2995
2983.86	9.1322
2988.19	20.2679
2992.52	24.083
2996.85	-0.00428772
3001.17	3.8472
3005.49	19.0181
3009.8	24.8761
3014.12	19.4097
3018.43	8.31706
3022.74	18.0464
3027.04	31.5376
3031.34	-0.847382
3035.64	33.5669
3039.94	25.8856
3044.23	23.9457
3048.52	23.8835
3052.81	14.1675
3057.09	21.8459
3061.38	17.923
3065.65	41.1436
3069.93	25.5874
3074.2	33.3454
3078.47	21.6535
3082.74	35.3163
3087	31.5067
3091.27	21.895
3095.52	33.9841
3099.78	40.2495
3104.03	42.6441
3108.28	37.1619
3112.53	49.6738
3116.77	36.1939
3121.01	32.717
3125.25	63.6651
3129.49	56.3539
3133.72	36.7933
3137.95	56.0052
3142.18	56.7603
3146.4	45.0175
3150.62	58.0416
3154.84	64.7414
3159.06	52.6406
3163.27	48.8698
3167.48	57.6255
3171.69	55.9058
3175.89	58.309
3180.09	66.9163
3184.29	37.3303
3188.49	60.6261
3192.68	45.8715
3196.87	48.2128
3201.06	59.4174
3205.24	45.074
3209.42	56.55
3213.6	65.9951
3217.78	38.6882
3221.95	45.937
3226.12	42.3195
3230.29	45.2368
3234.45	45.9379
3238.61	57.6778
3242.77	47.4155
3246.93	57.1846
3251.08	28.778
3255.23	29.1977
3259.38	54.405
3263.53	39.3127
3267.67	35.8391
3271.81	38.9318
3275.95	25.7108
3280.08	32.9193
3284.21	37.8638
3288.34	10.6469
3292.47	17.8449
3296.59	27.3561
3300.71	36.9788
3304.83	32.7298
3308.95	40.0708
3313.06	33.4477
3317.17	19.8523
3321.27	27.2647
3325.38	34.8009
3329.48	21.3227
3333.58	31.4938
3337.67	13.3969
3341.77	16.3053
3345.86	28.6158
3349.95	43.2735
3354.03	22.2807
3358.11	22.8009
3362.19	28.1234
3366.27	-0.118347
3370.34	31.585
3374.42	32.0656
3378.48	10.7825
3382.55	23.2085
3386.61	40.4834
3390.68	33.5797
3394.73	24.2576
3398.79	10.1393
3402.84	29.9205
3406.89	13.242
3410.94	15.9787
3414.98	38.191
3419.03	38.5219
3423.06	26.6409
3427.1	51.3874
3431.14	24.9641
3435.17	0.982422
3439.2	38.2586
3443.22	24.1506
3447.25	37.1792
3451.27	3.41431
3455.28	26.4632
3459.3	5.07877
3463.31	23.4424
3467.32	11.9365
3471.33	27.9119
3475.34	21.1904
3479.34	6.94972
3483.34	25.5065
3487.33	16.2312
3491.33	24.6989
3495.32	25.5113
3499.31	21.1492
3503.3	32.0637
3507.28	19.8616
3511.26	28.0279
3515.24	23.3248
3519.22	28.8896
3523.19	8.7429
3527.16	22.0767
3531.13	30.2678
3535.1	18.0648
3539.06	13.7005
3543.02	24.8021
3546.98	15.1053
3550.93	23.4949
3554.89	31.7144
3558.84	8.86179
3562.78	-0.949326
3566.73	28.4462
3570.67	42.3592
3574.61	19.6031
3578.55	44.1467
3582.48	31.991
3586.41	11.8482
3590.35	23.4001
3594.27	35.0124
3598.2	14.6682
3602.12	42.2903
3606.04	16.4016
3609.95	3.76743
3613.87	7.23097
3617.78	29.5521
3621.69	32.9406
3625.6	11.8497
3629.5	9.64378
3633.4	23.6212
3637.3	40.4086
3641.2	22.1355
3645.09	31.0647
3648.98	29.0357
3652.87	18.7456
3656.76	24.7652
3660.64	25.3232
3664.53	17.6672
3668.4	20.9882
3672.28	32.5066
3676.16	24.9761
3680.03	20.2525
3683.9	21.0987
3687.76	24.7823
3691.63	28.4957
3695.49	21.0561
3699.35	24.7393
3703.2	17.2539
3707.06	23.7488
3710.91	27.464
3714.76	28.3463
3718.6	26.3315
3722.45	4.49425
3726.29	27.7934
3730.13	11.4909
3733.97	32.0697
3737.8	27.1094
3741.63	13.5407
3745.46	31.2973
3749.29	9.04503
3753.11	21.0118
3756.93	27.2145
3760.75	19.0533
3764.57	28.0603
3768.39	25.6231
3772.2	23.2346
3776.01	17.9698
3779.81	35.7393
3783.62	30.5847
3787.42	22.5383
3791.22	31.7587
3795.02	29.5001
3798.81	15.6891
3802.61	39.5997
3806.4	14.1491
3810.18	17.7577
3813.97	38.8808
3817.75	36.6323
3821.53	31.413
3825.31	23.1791
3829.09	23.7563
3832.86	30.2794
3836.63	42.7091
3840.4	34.4132
3844.17	17.2536
3847.93	23.5962
3851.69	21.0084
3855.45	36.2058
3859.21	39.4415
3862.96	15.97
3866.71	37.3694
3870.46	20.1685
3874.21	11.5488
3877.95	41.7913
3881.69	27.2141
3885.44	36.5943
3889.17	13.0637
3892.91	37.5332
3896.64	23.1105
3900.37	17.6203
3904.1	42.2486
3907.82	42.7824
3911.55	25.2147
3915.27	7.6192
3918.99	32.5134
3922.7	30.2041
3926.42	27.8527
3930.13	16.289
3933.84	44.4122
3937.54	11.2654
3941.25	36.4241
3944.95	27.8907
3948.65	16.212
3952.35	47.6699
3956.04	51.3606
3959.73	30.239
3963.42	33.8329
3967.11	21.8993
3970.8	31.6163
3974.48	22.7713
3978.16	32.5294
3981.84	29.8401
3985.52	17.8624
3989.19	24.5113
3992.86	46.7582
3996.53	13.2425
3998.37	32.2099