File: Data/3-Raman/processed/bu19w-b-ff1-fi07-l_150 (500nm)_532nm_edge_100%_x100_vis_h50um_15sx2_01.txt
#Acq. time (s)=	15
#Accumulations=	2
#Range (cm-¹)=	100...5000
#Windows=	1
#Auto scanning=	Off
#Autofocus=	Off
#Macrospot=	Off
#AutoExposure=	Off
#Spike filter=	Multiple accum.
#Delay time (s)=	2
#Binning=	1
#Readout mode=	Signal
#DeNoise=	Off
#ICS correction=	On
#Dark correction=	Off
#Inst. Process=	Off
#Detector Gain=	Best Dynamic
#Detector ADC=	50 kHz HS
#Detector temperature (°C)=	-60.09
#Instrument=	LabRAM HR Evol
#Detector=	SIN-EM FIVIS
#Objective=	x100_VIS
#Grating=	150 (500nm)
#ND Filter=	100%
#Laser=	532nm_Edge
#Hole=	49.98
#Temperature=	0
#Range=	Visible
#StageXY=	75x50mm Scan+
#StageZ=	Z motor
#X (µm)=	0
#Y (µm)=	0
#Z (µm)=	-166.4
#Full time(s)=	34
#Project=	21_05_14
#Sample=	BU19w
#Site=
#Title=	BU19w-FF1-FI07-L_150 (500nm)_532nm_Edge_100%_x100_VIS_H50um_15sX2
#Remark=
#Date=	14.05.2021 15:54
#Acquired=	14.05.2021 15:54:14
#Base:Fit=	22.12.2021 12:22:35
#Base:Sub=	22.12.2021 12:25:28
#Data Range:Extract=	22.12.2021 12:27:19
102.699	197.073
107.322	190.232
111.942	70.9746
116.56	0.0871582
121.173	50.1975
125.787	33.8358
130.398	30.411
135.006	136.525
139.613	62.9382
144.215	20.0841
148.817	82.674
153.417	635.89
158.014	2037.68
162.607	1959.62
167.2	798.457
171.79	320.122
176.379	577.439
180.963	2312.47
185.547	6518.21
190.128	5733.23
194.705	1952.34
199.282	500.362
203.857	142.873
208.43	100.879
212.998	108.919
217.566	74.0337
222.132	-0.141479
226.693	145.312
231.254	464.972
235.813	615.728
240.368	1109.72
244.923	1940.6
249.475	1672.96
254.023	1116.15
258.571	605.17
263.117	556.843
267.658	1038.85
272.199	2960.87
276.738	6187.7
281.273	5766.94
285.807	2858.39
290.34	1441.64
294.868	1436.69
299.396	2667.2
303.919	3192.07
308.443	2010.16
312.964	965.176
317.481	753.407
321.998	1092.17
326.51	1750.86
331.023	1864.96
335.533	1079.8
340.039	724.263
344.544	979.749
349.046	1352.62
353.547	981.314
358.045	570.304
362.542	295.368
367.036	387.294
371.527	372.766
376.017	293.018
380.503	528.369
384.99	911.662
389.471	1259.26
393.953	1425.99
398.43	1086.07
402.908	729.576
407.381	444.526
411.854	647.515
416.323	1049.54
420.791	709.578
425.256	214.853
429.72	78.2012
434.18	24.7947
438.64	45.8505
443.095	125.629
447.551	514.763
452.003	1512.93
456.454	1993.28
460.901	1214.85
465.348	455.922
469.791	209.489
474.231	208.766
478.672	271.585
483.108	445.085
487.544	660.644
491.976	874.297
496.408	887.676
500.836	845.522
505.261	559.578
509.687	429.53
514.108	263.875
518.529	284.366
522.946	226.96
527.361	251.647
531.776	328.835
536.187	352.92
540.595	390.883
545.003	443.885
549.408	492.333
553.812	491.353
558.212	528.7
562.61	471.761
567.007	386.309
571.401	273.352
575.792	276.662
580.184	656.598
584.571	1541.03
588.956	2492.83
593.341	1920.36
597.722	976.728
602.101	758.107
606.48	1225.71
610.854	1661.78
615.227	1361.58
619.597	641.146
623.967	339.172
628.334	278.455
632.698	280.816
637.06	411.955
641.422	499.757
645.779	364.917
650.135	268.493
654.491	357.326
658.842	507.464
663.192	719.438
667.539	866.597
671.884	950.175
676.23	1136.56
680.571	946.892
684.91	580.312
689.247	298.082
693.583	137.42
697.916	59.4611
702.247	22.1403
706.576	11.9325
710.902	0.109863
715.229	30.2434
719.551	19.6677
723.872	27.5071
728.19	30.293
732.506	65.5342
736.82	64.3644
741.134	86.6118
745.444	117.255
749.752	174.796
754.058	207.18
758.362	359.394
762.664	518.913
766.964	890.606
771.264	1622.32
775.559	2552.09
779.853	2775.46
784.144	2044.95
788.434	1213.52
792.722	686.841
797.007	454.882
801.29	322.456
805.572	294.161
809.851	169.313
814.13	141.488
818.406	150.946
822.679	122.193
826.95	100.147
831.219	69.2966
835.486	92.3464
839.752	107.586
844.015	67.4015
848.276	78.242
852.535	80.1363
856.792	69.8898
861.047	76.0369
865.3	85.0643
869.551	79.5281
873.8	50.6295
878.047	72.0045
882.292	57.8688
886.534	83.6404
890.775	49.5301
895.014	49.1009
899.251	82.5344
903.486	117.338
907.719	96.7005
911.95	119.111
916.179	83.9393
920.406	99.5798
924.63	87.7716
928.853	142.09
933.074	189.97
937.293	219.069
941.51	292.84
945.723	502.772
949.936	611.166
954.147	587.375
958.356	552.141
962.563	622.338
966.768	685.051
970.971	665.359
975.172	493.206
979.371	317.377
983.568	251.875
987.761	214.759
991.954	217.605
996.145	208.73
1000.33	185.317
1004.52	208.693
1008.71	239.842
1012.89	252.491
1017.07	236.344
1021.25	309.732
1025.43	354.706
1029.6	366.619
1033.77	508.441
1037.95	764.654
1042.11	1101.25
1046.28	1995.07
1050.45	3402.71
1054.61	3798.38
1058.77	2798.26
1062.93	1749.28
1067.09	1195.44
1071.24	1090.12
1075.4	1108.95
1079.55	1477.85
1083.7	2295.86
1087.85	3335.08
1091.99	3621.61
1096.14	3016.75
1100.28	2451.17
1104.42	2594.57
1108.55	3097.4
1112.69	3236.19
1116.82	2665.42
1120.96	2419.87
1125.09	2437.97
1129.21	2795.91
1133.34	2811.89
1137.46	2313.29
1141.59	1672.44
1145.71	1400.85
1149.83	1512.76
1153.94	2016.42
1158.06	2370.48
1162.17	2003.8
1166.28	1465.39
1170.39	1095.53
1174.5	881.245
1178.6	612.649
1182.7	479.21
1186.8	488.68
1190.9	481.237
1195	528.51
1199.1	513.812
1203.19	492.859
1207.28	388.884
1211.37	348.252
1215.46	417.755
1219.54	617.927
1223.63	771.1
1227.71	629.954
1231.79	623.912
1235.87	851.884
1239.95	1152.7
1244.02	981.291
1248.09	664.679
1252.16	416.251
1256.23	280.767
1260.3	267.304
1264.36	200.984
1268.43	202.968
1272.49	141.785
1276.55	168.778
1280.6	154.527
1284.66	151.946
1288.71	108.041
1292.76	121.202
1296.81	96.0221
1300.86	84.7147
1304.91	129.627
1308.95	112.09
1312.99	110.248
1317.03	121.075
1321.07	112.608
1325.11	143.679
1329.14	151.831
1333.18	110.297
1337.21	106.653
1341.24	93.8679
1345.26	85.0192
1349.29	74.2288
1353.31	120.152
1357.33	128.199
1361.35	142.112
1365.37	137.556
1369.39	215.093
1373.4	178.386
1377.41	139.901
1381.43	100.924
1385.43	108.746
1389.44	65.514
1393.45	49.3793
1397.45	61.0425
1401.45	94.1207
1405.45	49.5132
1409.45	51.3118
1413.44	46.2821
1417.44	72.7976
1421.43	51.8632
1425.42	49.2681
1429.41	57.1267
1433.39	48.5188
1437.38	86.114
1441.36	53.6481
1445.34	45.6051
1449.32	61.2021
1453.3	41.0215
1457.27	51.3129
1461.24	56.2975
1465.22	49.1995
1469.19	18.6643
1473.15	62.8087
1477.12	55.6079
1481.09	22.8934
1485.05	0.919678
1489.01	52.2202
1492.97	65.4586
1496.93	60.191
1500.88	61.9574
1504.83	69.8289
1508.79	48.8008
1512.74	65.6632
1516.68	59.3468
1520.63	28.8983
1524.57	63.5131
1528.52	45.8917
1532.46	43.8921
1536.4	62.2457
1540.33	41.8712
1544.27	64.1229
1548.2	58.2825
1552.14	54.3009
1556.07	23.0022
1559.99	45.7666
1563.92	57.739
1567.84	86.0129
1571.77	49.4733
1575.69	75.7006
1579.61	46.8539
1583.52	53.6504
1587.44	45.9073
1591.35	61.2545
1595.27	40.0315
1599.18	65.0015
1603.09	56.5111
1606.99	70.2188
1610.9	60.9335
1614.8	57.5682
1618.7	67.6697
1622.6	74.9071
1626.5	31.6736
1630.39	66.2407
1634.29	73.282
1638.18	59.3065
1642.07	53.4016
1645.96	64.9005
1649.85	60.2006
1653.73	46.8232
1657.62	47.7327
1661.5	72.5308
1665.38	66.3522
1669.26	34.9189
1673.13	46.4601
1677.01	25.9418
1680.88	22.1124
1684.75	33.5094
1688.62	46.6061
1692.49	98.6514
1696.35	30.9061
1700.22	46.1042
1704.08	43.8169
1707.94	60.261
1711.8	61.3326
1715.66	81.3982
1719.51	69.3042
1723.37	80.769
1727.22	61.889
1731.07	56.1748
1734.92	28.0187
1738.76	62.3638
1742.61	35.0149
1746.45	-1.01282
1750.29	37.1357
1754.13	18.2572
1757.97	-4.57751
1761.81	29.8151
1765.64	48.839
1769.47	33.4325
1773.31	33.1576
1777.14	16.3387
1780.96	25.0527
1784.79	-0.630127
1788.61	18.6445
1792.43	11.7744
1796.25	38.6842
1800.07	46.3428
1803.89	33.7251
1807.71	44.6023
1811.52	26.0336
1815.33	30.5897
1819.14	53.5303
1822.95	62.9897
1826.76	73.0614
1830.56	33.7283
1834.37	31.84
1838.17	53.2628
1841.97	42.4076
1845.77	36.2234
1849.56	54.1611
1853.36	69.6073
1857.15	73.4098
1860.94	52.683
1864.73	17.2174
1868.52	56.2399
1872.31	46.2866
1876.09	45.7986
1879.87	22.6283
1883.66	57.8612
1887.43	44.2588
1891.21	56.325
1894.99	71.9685
1898.76	28.1875
1902.53	54.8015
1906.31	13.4595
1910.08	12.0605
1913.84	0.807373
1917.61	41.8141
1921.37	27.9271
1925.14	47.5355
1928.9	7.02258
1932.66	3.62268
1936.41	16.0258
1940.17	53.6848
1943.92	63.6948
1947.68	3.06128
1951.43	65.7037
1955.18	63.8861
1958.92	28.4514
1962.67	11.6852
1966.41	49.2235
1970.16	68.1573
1973.9	32.4213
1977.64	53.5699
1981.37	42.67
1985.11	53.0066
1988.84	49.2194
1992.57	39.4994
1996.31	50.9376
2000.03	66.7609
2003.76	46.6689
2007.49	56.5648
2011.21	38.7349
2014.93	43.3977
2018.65	46.2875
2022.37	33.3273
2026.09	44.0682
2029.81	74.6547
2033.52	55.4063
2037.23	50.3851
2040.94	17.9867
2044.65	50.38
2048.36	51.053
2052.07	65.6672
2055.77	47.5663
2059.47	28.8105
2063.17	49.1088
2066.87	46.634
2070.57	33.1367
2074.27	55.6718
2077.96	76.6149
2081.65	63.2706
2085.34	35.9739
2089.03	42.9208
2092.72	64.5782
2096.41	93.0797
2100.09	91.0653
2103.77	85.0864
2107.46	46.2877
2111.14	72.4539
2114.81	34.4307
2118.49	72.1609
2122.16	89.7495
2125.84	83.0812
2129.51	43.7358
2133.18	49.7635
2136.85	66.6489
2140.51	47.2393
2144.18	56.2758
2147.84	63.4016
2151.5	58.5946
2155.16	54.8024
2158.82	59.3472
2162.48	64.1476
2166.13	28.1362
2169.79	89.2145
2173.44	92.5695
2177.09	78.7469
2180.74	42.338
2184.38	67.8171
2188.03	69.4674
2191.67	67.1162
2195.32	77.178
2198.96	70.0845
2202.6	60.4738
2206.23	36.4897
2209.87	81.3174
2213.5	109.932
2217.14	80.8461
2220.77	80.2375
2224.4	81.486
2228.03	90.0114
2231.65	59.02
2235.28	117.709
2238.9	83.8428
2242.52	91.6158
2246.14	81.7358
2249.76	72.9341
2253.38	53.0757
2256.99	61.2354
2260.6	70.2146
2264.21	68.869
2267.82	21.8607
2271.44	65.0176
2275.04	53.0146
2278.65	58.2981
2282.25	56.2072
2285.85	70.5183
2289.45	96.8596
2293.05	77.7637
2296.65	85.2631
2300.25	46.2355
2303.84	36.1835
2307.43	18.2848
2311.02	56.1039
2314.62	81.3342
2318.2	52.228
2321.79	98.2314
2325.38	68.7097
2328.96	50.6561
2332.54	82.3229
2336.12	73.2319
2339.7	71.4741
2343.28	57.3497
2346.85	48.7167
2350.43	40.0419
2354	54.647
2357.57	93.318
2361.14	56.4351
2364.71	57.8063
2368.27	0.1427
2371.84	79.7472
2375.4	107.203
2378.96	42.594
2382.52	51.0776
2386.08	62.4982
2389.64	69.623
2393.19	58.7977
2396.75	35.7028
2400.3	43.5737
2403.85	57.5435
2407.4	51.6509
2410.95	32.6595
2414.49	57.0942
2418.04	34.1176
2421.58	59.2582
2425.12	23.1025
2428.66	47.251
2432.2	39.4094
2435.74	24.3755
2439.27	33.5784
2442.81	42.9158
2446.34	86.1431
2449.87	89.65
2453.4	65.4634
2456.93	64.207
2460.45	67.8611
2463.98	84.1187
2467.5	98.319
2471.02	49.8844
2474.54	36.1373
2478.06	91.8254
2481.58	72.7134
2485.09	91.2899
2488.61	53.4182
2492.12	12.0773
2495.63	17.2762
2499.14	50.7982
2502.65	64.9043
2506.15	83.4025
2509.66	83.0688
2513.16	60.7755
2516.66	32.4077
2520.16	103.399
2523.66	57.5931
2527.16	40.4185
2530.66	92.7373
2534.15	53.1943
2537.64	74.9004
2541.13	54.86
2544.62	62.4556
2548.11	32.3357
2551.6	51.4302
2555.08	-9.06042
2558.57	63.8599
2562.05	48.4554
2565.53	35.4181
2569.01	68.5508
2572.49	48.8214
2575.96	34.0353
2579.44	47.5764
2582.91	52.7686
2586.38	42.6107
2589.85	71.4457
2593.32	52.2065
2596.79	22.8534
2600.25	73.8549
2603.72	18.8855
2607.18	24.9365
2610.64	43.6716
2614.1	50.6519
2617.56	38.7861
2621.02	65.985
2624.47	36.0101
2627.92	80.6901
2631.38	71.2269
2634.83	45.8867
2638.28	54.7855
2641.72	84.296
2645.17	64.9391
2648.61	19.554
2652.06	55.767
2655.5	49.6257
2658.94	63.2233
2662.38	29.2522
2665.82	53.9337
2669.25	38.7646
2672.69	61.4672
2676.12	59.9298
2679.55	14.7946
2682.98	75.7019
2686.41	38.6503
2689.84	55.8256
2693.26	36.1749
2696.69	41.0845
2700.11	75.1071
2703.53	28.7173
2706.95	56.198
2710.37	38.5664
2713.79	4.49329
2717.2	50.8423
2720.62	28.5342
2724.03	64.1945
2727.44	42.1731
2730.85	31.2295
2734.26	40.861
2737.66	10.2091
2741.07	46.795
2744.47	55.8511
2747.87	46.1444
2751.28	43.9163
2754.67	29.0918
2758.07	39.918
2761.47	29.5367
2764.86	2.90186
2768.26	58.8428
2771.65	46.8425
2775.04	71.3035
2778.43	12.608
2781.82	60.1715
2785.2	40.8196
2788.59	64.7197
2791.97	36.7621
2795.35	101.038
2798.73	25.9644
2802.11	45.7175
2805.49	57.0054
2808.87	68.1753
2812.24	57.7473
2815.62	57.457
2818.99	55.5397
2822.36	60.4532
2825.73	54.2889
2829.1	55.7688
2832.46	33.361
2835.83	50.3647
2839.19	21.1198
2842.55	35.0773
2845.91	38.3733
2849.27	56.4723
2852.63	54.61
2855.99	85.6638
2859.34	75.8938
2862.69	18.3861
2866.05	57.4622
2869.4	57.0515
2872.75	36.8467
2876.09	65.4824
2879.44	-0.0372314
2882.78	40.7327
2886.13	72.0131
2889.47	68.5334
2892.81	55.0853
2896.15	68.8206
2899.49	70.0013
2902.82	69.0328
2906.16	39.5573
2909.49	79.9161
2912.82	37.0038
2916.16	28.7897
2919.49	70.5879
2922.81	65.0444
2926.14	87.5182
2929.46	114.612
2932.79	103.508
2936.11	85.8231
2939.43	136.02
2942.75	104.242
2946.07	65.1093
2949.39	85.2185
2952.7	103.352
2956.02	61.6608
2959.33	85.0576
2962.64	83.057
2965.95	80.525
2969.26	80.5801
2972.57	76.5729
2975.87	80.7623
2979.17	110.859
2982.48	70.6703
2985.78	93.5065
2989.08	58.1871
2992.38	70.8384
2995.68	73.2928
2998.97	62.621
3002.27	94.1816
3005.56	96.7747
3008.85	88.1682
3012.14	108.855
3015.43	108.783
3018.72	63.41
3022	89.7001
3025.29	97.1843
3028.57	89.5605
3031.85	98.8693
3035.14	82.5707
3038.41	98.4473
3041.69	97.3175
3044.97	113.311
3048.24	95.1498
3051.52	50.5402
3054.79	108.268
3058.06	107.02
3061.33	127.167
3064.6	169.32
3067.87	111.584
3071.13	116.988
3074.4	166.005
3077.66	119.266
3080.92	138.009
3084.18	174.219
3087.44	148.139
3090.7	127.18
3093.95	131.973
3097.21	146.516
3100.46	162.986
3103.71	143.896
3106.96	151.537
3110.21	178.642
3113.46	219.042
3116.71	168.136
3119.95	157.236
3123.2	209.193
3126.44	256.356
3129.68	211.114
3132.92	227.791
3136.16	213.882
3139.4	216.135
3142.63	242.224
3145.87	255.073
3149.1	285.175
3152.33	280.893
3155.56	283.323
3158.79	270.453
3162.02	324.388
3165.25	347.669
3168.47	342.167
3171.69	366.163
3174.92	348.976
3178.14	355.576
3181.36	392.755
3184.58	403.048
3187.79	415.139
3191.01	412.919
3194.22	401.16
3197.43	379.836
3200.65	393.817
3203.86	454.512
3207.07	462.932
3210.27	454.361
3213.48	463.085
3216.69	468.998
3219.89	464.493
3223.09	469.706
3226.29	463.581
3229.49	506.165
3232.69	476.304
3235.89	502.951
3239.08	490.794
3242.28	520.673
3245.47	488.653
3248.66	466.322
3251.85	458.385
3255.04	508.682
3258.23	552.105
3261.42	520.758
3264.6	514.879
3267.79	520.223
3270.97	538.776
3274.15	555.425
3277.33	572.68
3280.51	577.036
3283.68	592.832
3286.86	575.999
3290.04	561.234
3293.21	567.429
3296.38	632.575
3299.55	592.586
3302.72	635.991
3305.89	570.653
3309.06	639.079
3312.22	622.684
3315.39	619.546
3318.55	599.259
3321.71	654.801
3324.87	666.732
3328.03	663.548
3331.19	710.597
3334.34	677.509
3337.5	656.951
3340.65	719.425
3343.81	703.102
3346.96	732.73
3350.11	722.81
3353.25	781.001
3356.4	746.948
3359.55	733.932
3362.69	755.895
3365.84	776.115
3368.98	753.022
3372.12	774.56
3375.26	813.248
3378.4	828.536
3381.53	863.558
3384.67	890.296
3387.8	972.003
3390.94	1002.82
3394.07	1009.88
3397.2	1051.43
3400.33	1109.65
3403.46	1343.94
3406.58	1502.86
3409.71	2015.32
3412.83	2997.5
3415.96	5530.76
3419.08	12104.1
3422.2	17534.8
3425.32	12880.1
3428.44	6017.29
3431.55	2938.84
3434.67	2012.44
3437.78	1508.64
3440.89	1268.58
3444	1135.8
3447.12	1107.96
3450.22	1090.2
3453.33	972.43
3456.44	1000.04
3459.54	985.687
3462.65	941.803
3465.75	971.837
3468.85	990.581
3471.95	950.37
3475.05	1042.05
3478.15	1071.32
3481.24	1165.81
3484.34	1273.57
3487.43	1437.14
3490.53	1669.52
3493.62	2117.99
3496.71	2664.83
3499.79	3327.72
3502.88	3760.06
3505.97	3749.61
3509.05	3191.32
3512.14	2491.31
3515.22	1862.28
3518.3	1527.68
3521.38	1279.58
3524.46	1072.4
3527.54	970.969
3530.61	849.273
3533.69	747.007
3536.76	709.48
3539.83	683.005
3542.9	654.531
3545.97	607.274
3549.04	542.621
3552.11	537.062
3555.18	511.965
3558.24	496.541
3561.3	490.101
3564.37	438.949
3567.43	464.649
3570.49	457.783
3573.55	404.214
3576.61	445.404
3579.66	383.054
3582.72	390.713
3585.77	386.941
3588.82	351.703
3591.87	372.31
3594.92	312.219
3597.97	289.076
3601.02	291.38
3604.07	274.596
3607.11	305.075
3610.16	272.118
3613.2	263.68
3616.24	276.063
3619.28	260.215
3622.32	235.021
3625.36	218.447
3628.39	243.311
3631.43	228.481
3634.46	226.198
3637.5	211.991
3640.53	212.098
3643.56	159.956
3646.59	184.705
3649.62	124.99
3652.64	129.324
3655.67	163.149
3658.69	136.828
3661.72	123.423
3664.74	105.522
3667.76	83.9111
3670.78	95.4604
3673.79	94.8452
3676.81	112.281
3679.83	81.5015
3682.84	79.9849
3685.86	80.4019
3688.87	73.2953
3691.88	46.3403
3694.89	56.9988
3697.9	32.7637
3700.91	53.1975
3703.91	13.8287
3706.92	52.193
3709.92	40.0807
3712.92	57.2445
3715.92	59.25
3718.92	24.0198
3721.92	69.5538
3724.92	46.4032
3727.92	35.5157
3730.91	48.2997
3733.91	30.4426
3736.9	12.4553
3739.89	31.4214
3742.88	68.3101
3745.87	3.28345
3748.86	32.2732
3751.85	60.2271
3754.83	39.7826
3757.82	44.9607
3760.8	-4.00537
3763.78	36.1122
3766.76	69.6471
3769.74	10.5875
3772.72	43.4225
3775.7	51.7535
3778.67	27.1224
3781.65	56.3766
3784.62	52.6431
3787.6	20.6743
3790.57	38.0089
3793.54	12.0854
3796.51	-4.31323
3799.47	19.119
3802.44	13.3995
3805.41	1.11157
3808.37	66.3933
3811.33	60.8739
3814.3	77.1388
3817.26	-5.87402
3820.22	64.4341
3823.18	26.9332
3826.13	27.345
3829.09	64.72
3832.04	40.5735
3835	44.9852
3837.95	69.3812
3840.9	31.9811
3843.85	57.3577
3846.8	37.1062
3849.75	18.8138
3852.69	22.4778
3855.64	38.5789
3858.58	16.5067
3861.53	8.66663
3864.47	33.3582
3867.41	29.2396
3870.35	7.79321
3873.29	54.3961
3876.22	48.105
3879.16	7.07056
3882.1	51.3467
3885.03	75.3317
3887.96	30.9928
3890.89	46.2014
3893.82	38.173
3896.75	61.6826
3899.68	4.37952
3902.61	33.4098
3905.53	52.9607
3908.46	47.4462
3911.38	32.1943
3914.3	39.8264
3917.23	37.1624
3920.15	33.3539
3923.06	25.5173
3925.98	37.689
3928.9	74.6136
3931.81	42.8049
3934.73	40.0471
3937.64	61.574
3940.55	28.4343
3943.46	36.4913
3946.37	16.9175
3949.28	42.4678
3952.19	38.3915
3955.09	53.5968
3958	53.5597
3960.9	14.2902
3963.8	18.2181
3966.71	48.1244
3969.61	51.2443
3972.51	35.1512
3975.4	21.8477
3978.3	22.8372
3981.2	66.0927
3984.09	44.873
3986.99	66.9175
3989.88	59.8629
3992.77	43.4268
3995.66	41.4265
3998.55	66.4447
4001.43	68.3832