File: Data/3-Raman/processed/bu19w-a-ff07a-fi06-v_150 (500nm)_532nm_edge_100%_x100_vis_lwd_h50um_30sx2_01_0.txt
#Acq. time (s)=	30
#Accumulations=	2
#Range (cm-¹)=	50...5000
#Windows=	1
#Auto scanning=	Off
#Autofocus=	Off
#Macrospot=	Off
#AutoExposure=	Off
#Spike filter=	Multiple accum.
#Delay time (s)=	2
#Binning=	1
#Readout mode=	Signal
#DeNoise=	Off
#ICS correction=	On
#Dark correction=	Off
#Inst. Process=	Off
#Detector Gain=	Best Dynamic
#Detector ADC=	50 kHz HS
#Detector temperature (°C)=	-60.09
#Instrument=	LabRAM HR Evol
#Detector=	SIN-EM FIVIS
#Objective=	x100_VIS_LWD
#Grating=	150 (500nm)
#ND Filter=	100%
#Laser=	532nm_Edge
#Hole=	49.98
#Temperature=	0
#Range=	Visible
#StageXY=	75x50mm Scan+
#StageZ=	Z motor
#X (µm)=	0
#Y (µm)=	0
#Z (µm)=	-21.4
#Full time(mm:ss)=	1:04
#Project=	21_05_28
#Sample=	BU19w
#Site=
#Title=	BU19w-FF07a-FI06-V_150 (500nm)_532nm_Edge_100%_x100_VIS_LWD_H50um_30sX2
#Remark=
#Date=	28.05.2021 19:32
#Acquired=	28.05.2021 19:32:09
#Base:Fit=	16.12.2021 17:39:50
#Base:Sub=	16.12.2021 17:56:45
51.5961	45218.4
56.2453	35798.2
60.8921	24051
65.5367	14198
70.1768	9078.28
74.8167	6565.62
79.4543	4910.11
84.0897	3686.01
88.7227	2766.78
93.3513	2139.11
97.9798	1667.96
102.606	1490.74
107.23	1031.45
111.851	700.338
116.469	518.832
121.086	418.392
125.7	300.232
130.313	247.12
134.921	158.422
139.529	10.3899
144.134	-19.678
148.738	346.269
153.337	1477.71
157.936	2079.84
162.532	1131.13
167.126	289.705
171.716	307.834
176.306	1273.86
180.894	4009.35
185.477	5809.37
190.06	3477.97
194.64	1079.98
199.219	169.934
203.793	-4.53577
208.367	-0.00158691
212.939	-3.47815
217.506	-21.083
222.073	41.3668
226.638	398.839
231.199	806.289
235.759	1183.23
240.318	2196.15
244.872	2513.42
249.425	1705.36
253.977	1151.21
258.524	843.3
263.071	966.986
267.616	2399.16
272.156	5262.53
276.697	7058.91
281.233	4866.78
285.769	2419.44
290.303	1685.1
294.832	2278.64
299.361	3091.29
303.886	2615.45
308.411	1561.28
312.934	1107.89
317.452	1298.2
321.97	2051.53
326.484	2606.42
330.998	2057.28
335.507	1326.71
340.017	1486.58
344.524	1945.6
349.027	2015.98
353.53	1414.33
358.028	889.886
362.527	827.427
367.021	990.211
371.515	805.285
376.004	793.995
380.494	1103.96
384.979	1520.13
389.465	1766.45
393.946	1622.97
398.427	1202.26
402.903	848.249
407.38	892.848
411.852	1214.64
416.324	1167.4
420.792	761.452
425.26	451.074
429.723	417.578
434.187	329.139
438.646	380.812
443.105	723.84
447.56	1335.25
452.015	1955.03
456.466	1684.96
460.914	980.38
465.362	634.815
469.807	563.189
474.251	602.386
478.69	746.345
483.13	958.633
487.566	1196.2
491.999	1408.14
496.432	1392.28
500.861	1185.85
505.29	906.081
509.715	683.897
514.138	614.26
518.56	567.609
522.979	529.537
527.395	543.785
531.811	611.484
536.223	628.584
540.635	642.168
545.042	752.909
549.448	706.015
553.853	770.09
558.255	788.795
562.654	734.115
567.053	638.722
571.448	570.019
575.841	797.005
580.232	1411.95
584.622	2570.95
589.009	2784.27
593.393	1826.37
597.777	1256.79
602.157	1456.97
606.535	1771.92
610.913	1909.42
615.287	1411.59
619.659	811.41
624.029	587.328
628.398	515.914
632.763	663.782
637.127	775.526
641.488	762.431
645.849	660.557
650.206	673.376
654.561	846.142
658.914	1113.97
663.267	1353.53
667.615	1434.55
671.962	1566.56
676.307	1557.05
680.649	1128.32
684.991	761.098
689.33	478.671
693.666	332.218
698	272.836
702.332	191.675
706.662	145.714
710.992	197
715.318	190.87
719.641	167.604
723.963	177.386
728.283	196.803
732.6	217.834
736.918	204.107
741.231	282.374
745.542	263.721
749.852	368.87
754.159	480.665
758.464	649.26
762.767	959.243
767.068	1541.83
771.369	2467.02
775.666	3148.06
779.961	2640.97
784.254	1631.13
788.545	950.95
792.834	643.834
797.12	425.536
801.405	359.493
805.688	314.703
809.968	235.408
814.247	214.678
818.524	190.922
822.798	155.054
827.071	78.8815
831.341	92.0027
835.612	137.15
839.878	122.696
844.142	92.6167
848.405	107.208
852.665	104.354
856.923	127.975
861.18	96.4591
865.434	105.441
869.686	95.2102
873.936	95.6545
878.185	85.8401
882.431	46.1571
886.675	84.6414
890.915	0.0229492
895.155	98.8297
899.393	87.2174
903.63	63.8529
907.864	49.191
912.096	97.6787
916.326	110.231
920.554	128.907
924.78	151.209
929.004	118.773
933.227	210.843
937.447	315.4
941.665	483.418
945.881	685.927
950.095	711.592
954.305	656.796
958.516	632.208
962.724	698.348
966.93	736.986
971.134	552.006
975.337	378.386
979.537	290.026
983.735	224.379
987.93	219.112
992.124	193.932
996.316	199.685
1000.51	185.382
1004.7	186.295
1008.88	237.441
1013.06	177.085
1017.25	229.072
1021.43	351.561
1025.61	379.965
1029.78	469.67
1033.96	643.176
1038.13	962.686
1042.3	1692.42
1046.47	3054.11
1050.63	3840.37
1054.8	3257.98
1058.96	2103.54
1063.12	1462.16
1067.28	1114.79
1071.44	1126.67
1075.59	1449.67
1079.74	2203.8
1083.89	3218.49
1088.04	3984.59
1092.19	3769.25
1096.33	3024.42
1100.48	2822.79
1104.62	3327.74
1108.76	3474.09
1112.89	3171.46
1117.03	2721.99
1121.16	2605.2
1125.29	2789.43
1129.42	2948.26
1133.55	2613.39
1137.68	2034.11
1141.8	1554.46
1145.92	1528.69
1150.04	1911.03
1154.16	2462.38
1158.27	2391.61
1162.39	1954.46
1166.5	1437.7
1170.61	1029.75
1174.72	770.834
1178.82	533.542
1182.93	515.798
1187.03	461.451
1191.13	505.593
1195.23	519.229
1199.33	505.546
1203.42	427.218
1207.51	391.803
1211.6	380.969
1215.69	606.631
1219.78	815.206
1223.86	807.031
1227.95	742.289
1232.03	818.816
1236.11	1073.99
1240.18	1178.43
1244.26	947.636
1248.33	928.722
1252.41	678.56
1256.48	533.643
1260.54	440.922
1264.61	1062.6
1268.67	3842.59
1272.74	3600.1
1276.8	1001.83
1280.86	372.752
1284.91	290.084
1288.97	293.481
1293.02	225.161
1297.07	254.202
1301.12	214.562
1305.17	168.5
1309.21	213.024
1313.25	205.929
1317.3	200.181
1321.34	204.115
1325.37	191.24
1329.41	215.34
1333.44	173.926
1337.48	233.238
1341.5	174.97
1345.53	279.479
1349.56	277.896
1353.59	367.898
1357.61	385.159
1361.63	371.447
1365.65	566.985
1369.66	2759.58
1373.68	7090.97
1377.69	3873.98
1381.7	826.061
1385.72	368.003
1389.72	434.327
1393.73	680.354
1397.73	648.804
1401.74	272.276
1405.74	194.977
1409.73	154.282
1413.73	155.145
1417.73	124.455
1421.72	142.078
1425.71	117
1429.7	128.519
1433.69	100.697
1437.67	74.8036
1441.66	101.262
1445.64	94.8518
1449.62	92.2803
1453.6	45.9917
1457.57	62.6616
1461.55	110.505
1465.52	50.4105
1469.49	35.5446
1473.46	50.4039
1477.43	82.6394
1481.39	90.0643
1485.36	43.5164
1489.32	79.0336
1493.28	75.542
1497.24	49.668
1501.19	96.071
1505.15	83.3502
1509.1	57.5328
1513.05	-0.187866
1517	105.324
1520.95	62.4641
1524.9	53.6923
1528.84	86.7434
1532.78	40.5038
1536.72	42.7728
1540.66	48.9618
1544.6	44.4829
1548.53	61.318
1552.46	52.9458
1556.4	75.3394
1560.32	91.6215
1564.25	87.3518
1568.18	65.4818
1572.1	75.3805
1576.02	88.1172
1579.94	59.2505
1583.86	118.109
1587.78	57.2489
1591.69	111.941
1595.61	79.9315
1599.52	98.8929
1603.43	63.2317
1607.34	88.3319
1611.24	81.7882
1615.15	83.0356
1619.05	77.8167
1622.95	118.434
1626.85	86.5526
1630.74	103.723
1634.64	101.379
1638.53	97.0092
1642.42	73.9607
1646.31	66.5908
1650.2	91.0214
1654.09	81.9807
1657.97	82.3571
1661.86	88.4092
1665.74	103.704
1669.62	53.4165
1673.49	78.4734
1677.37	105.325
1681.24	103.266
1685.12	65.1997
1688.99	130.585
1692.86	81.4407
1696.72	52.2153
1700.59	59.0339
1704.45	63.5107
1708.31	90.3923
1712.17	32.2288
1716.03	99.3926
1719.89	94.4597
1723.74	107.502
1727.6	119.359
1731.45	69.7452
1735.3	98.3077
1739.14	76.9106
1742.99	94.5498
1746.83	66.567
1750.68	48.1873
1754.52	94.5566
1758.36	78.8356
1762.19	66.2518
1766.03	27.2045
1769.86	25.9869
1773.69	81.4412
1777.53	78.4181
1781.35	50.8613
1785.18	80.4713
1789	38.3787
1792.83	34.6295
1796.65	111.601
1800.47	62.7865
1804.29	63.4089
1808.1	26.1971
1811.92	66.9296
1815.73	16.8093
1819.54	6.3811
1823.35	50.1798
1827.16	67.1865
1830.97	49.6892
1834.77	88.231
1838.58	85.8881
1842.38	62.5413
1846.18	96.9949
1849.97	55.613
1853.77	57.4348
1857.56	92.3838
1861.36	47.2614
1865.15	80.2603
1868.93	64.0851
1872.72	86.1469
1876.51	76.1415
1880.29	81.0615
1884.07	48.0752
1887.86	39.1702
1891.63	25.1311
1895.41	68.1879
1899.19	42.2159
1902.96	32.7288
1906.73	60.4337
1910.5	62.5596
1914.27	34.9872
1918.04	57.334
1921.8	19.0653
1925.57	15.1194
1929.33	54.1892
1933.09	46.1696
1936.85	66.9495
1940.6	18.6514
1944.36	69.2695
1948.11	25.4073
1951.87	59.6101
1955.61	44.2279
1959.36	38.1151
1963.11	54.8118
1966.86	42.2704
1970.6	85.4063
1974.34	55.5061
1978.08	49.5938
1981.82	81.6978
1985.56	34.8551
1989.29	76.5314
1993.02	57.1804
1996.75	101.619
2000.49	31.3539
2004.21	67.9302
2007.94	57.9031
2011.67	96.2565
2015.39	4.82788
2019.11	96.4674
2022.83	70.6669
2026.55	53.5026
2030.27	21.7854
2033.98	10.2954
2037.69	27.8761
2041.41	63.5858
2045.12	30.4589
2048.82	-7.2052
2052.53	26.0366
2056.24	51.1677
2059.94	69.158
2063.64	3.10535
2067.34	52.3152
2071.04	59.4889
2074.74	-0.65979
2078.43	57.5004
2082.13	17.8259
2085.82	56.6376
2089.51	20.589
2093.2	39.3147
2096.88	76.7258
2100.57	62.6409
2104.25	45.0356
2107.94	64.2581
2111.62	102.67
2115.3	25.7202
2118.97	26.603
2122.65	89.7844
2126.32	51.2654
2129.99	60.6697
2133.66	60.5867
2137.33	50.1833
2141	80.9648
2144.67	30.2229
2148.33	88.0325
2151.99	46.4287
2155.66	85.7124
2159.31	47.1472
2162.97	75.6704
2166.63	104.456
2170.28	67.9248
2173.94	92.4893
2177.59	45.593
2181.24	54.5464
2184.89	95.2332
2188.53	102.847
2192.18	33.0996
2195.82	67.9714
2199.46	37.7947
2203.1	79.8694
2206.74	49.355
2210.38	67.6047
2214.01	96.3005
2217.65	50.9421
2221.28	52.3474
2224.91	61.2495
2228.54	67.2727
2232.16	94.6055
2235.79	81.575
2239.41	96.2144
2243.04	121.059
2246.66	78.1182
2250.28	38.8872
2253.89	86.426
2257.51	27.0247
2261.12	26.2769
2264.74	47.749
2268.35	62.0415
2271.96	79.7383
2275.57	67.696
2279.17	85.177
2282.78	91.7471
2286.38	45.4104
2289.98	69.8704
2293.58	23.1316
2297.18	82.4099
2300.78	31.0637
2304.37	66.4495
2307.97	67.2703
2311.56	179.628
2315.15	624.36
2318.74	564.332
2322.33	177.826
2325.91	42.1343
2329.5	57.7668
2333.08	66.46
2336.66	79.5466
2340.24	49.9167
2343.82	88.7561
2347.4	53.0391
2350.97	81.907
2354.54	75.9651
2358.12	75.498
2361.69	70.2214
2365.26	63.0703
2368.82	73.7246
2372.39	28.4377
2375.95	92.1982
2379.52	78.2917
2383.08	51.8347
2386.64	38.5737
2390.19	78.1152
2393.75	115.29
2397.31	51.3545
2400.86	70.7844
2404.41	9.95288
2407.96	81.4045
2411.51	84.2341
2415.06	71.1331
2418.6	42.9756
2422.15	25.2607
2425.69	51.3872
2429.23	35.7498
2432.77	61.2434
2436.31	2.10547
2439.84	-3.15186
2443.38	1.08301
2446.91	49.2913
2450.44	28.999
2453.97	60.6428
2457.5	55.1567
2461.03	89.9702
2464.55	99.2085
2468.08	42.2834
2471.6	25.0073
2475.12	21.7285
2478.64	40.752
2482.16	68.6328
2485.67	55.0898
2489.19	32.5801
2492.7	54.6543
2496.21	101.589
2499.72	87.4475
2503.23	62.249
2506.74	106.773
2510.25	69.5142
2513.75	80.0247
2517.25	113.396
2520.75	96.0916
2524.25	114.182
2527.75	41.323
2531.25	69.9263
2534.74	70.2432
2538.24	77.7573
2541.73	40.6501
2545.22	33.3298
2548.71	141.585
2552.2	60.6599
2555.68	15.4351
2559.17	50.0544
2562.65	29.1519
2566.13	28.793
2569.61	27.3467
2573.09	27.4771
2576.57	67.4719
2580.04	61.1746
2583.51	34.2651
2586.99	54.4949
2590.46	122.613
2593.93	34.8071
2597.4	86.293
2600.86	76.6838
2604.33	72.563
2607.79	84.2727
2611.25	94.895
2614.71	66.3901
2618.17	107.015
2621.63	99.5515
2625.09	81.04
2628.54	77.2507
2631.99	73.0715
2635.45	87.4905
2638.9	86.7825
2642.34	136.378
2645.79	116.523
2649.24	106.113
2652.68	83.7273
2656.12	89.322
2659.56	106.729
2663.01	153.15
2666.44	122.595
2669.88	98.7339
2673.32	152.909
2676.75	124.708
2680.18	67.0649
2683.61	138.238
2687.04	75.7402
2690.47	123.168
2693.9	44.7285
2697.32	45.9634
2700.75	98.0356
2704.17	111.094
2707.59	83.356
2711.01	64.8447
2714.43	32.9028
2717.84	51.7205
2721.26	27.2649
2724.67	102
2728.08	48.2292
2731.49	37.5144
2734.9	112.78
2738.31	70.1523
2741.71	124.9
2745.12	69.4072
2748.52	49.2004
2751.92	52.5229
2755.32	90.4692
2758.72	87.7163
2762.12	91.6184
2765.52	91.1021
2768.91	71.3647
2772.3	99.2856
2775.7	33.7219
2779.09	99.6479
2782.47	66.333
2785.86	105.338
2789.25	100.97
2792.63	86.1902
2796.01	92.9763
2799.4	84.7478
2802.78	105.222
2806.15	107.902
2809.53	105.853
2812.91	108.361
2816.28	118.213
2819.65	62.6362
2823.03	138.226
2826.4	92.8284
2829.76	92.4424
2833.13	92.4209
2836.5	82.6409
2839.86	102.194
2843.22	95.2495
2846.59	49.7854
2849.95	61.1482
2853.3	73.1262
2856.66	102.599
2860.02	107.237
2863.37	100.976
2866.72	92.0085
2870.08	62.4087
2873.43	88.9619
2876.77	77.8867
2880.12	83.6863
2883.47	79.9998
2886.81	44.9927
2890.15	89.1819
2893.5	130.479
2896.84	135.307
2900.17	143.572
2903.51	141.049
2906.85	153.365
2910.18	130.462
2913.52	145.24
2916.85	116.326
2920.18	155.168
2923.51	181.576
2926.83	145.349
2930.16	139.037
2933.48	170.22
2936.81	200.99
2940.13	219.473
2943.45	175.775
2946.77	151.072
2950.09	158.488
2953.4	150.773
2956.72	204.23
2960.03	180.149
2963.34	149.771
2966.65	149.612
2969.96	109.917
2973.27	139.159
2976.58	160.086
2979.88	151.431
2983.19	110.581
2986.49	171.265
2989.79	146.704
2993.09	99.686
2996.39	124.2
2999.68	144.181
3002.98	132.188
3006.27	85.3994
3009.57	72.6667
3012.86	91.1438
3016.15	137.978
3019.43	114.1
3022.72	127.903
3026.01	137.97
3029.29	132.988
3032.57	113.792
3035.86	123.769
3039.14	115.728
3042.41	120.959
3045.69	147.085
3048.97	96.5549
3052.24	170.113
3055.52	183.155
3058.79	185.681
3062.06	130.481
3065.33	200.898
3068.6	160.002
3071.86	180.25
3075.13	158.46
3078.39	195.21
3081.65	152.456
3084.91	177.309
3088.17	161.258
3091.43	200.991
3094.69	188.661
3097.95	207.305
3101.2	181.964
3104.45	166.606
3107.7	177.163
3110.95	229.261
3114.2	243.444
3117.45	258.822
3120.7	215.246
3123.94	239.29
3127.18	252.831
3130.43	274.884
3133.67	244.577
3136.91	317.141
3140.14	280.915
3143.38	308.534
3146.61	272.302
3149.85	276.294
3153.08	330.899
3156.31	341.539
3159.54	319.826
3162.77	320.928
3166	335.407
3169.22	329.611
3172.45	388.524
3175.67	313.736
3178.89	424.797
3182.11	366.003
3185.33	407.435
3188.55	396.103
3191.77	403.777
3194.98	473.39
3198.2	469.576
3201.41	462.859
3204.62	501.02
3207.83	524.99
3211.04	461.549
3214.25	485.86
3217.45	505.609
3220.66	491.125
3223.86	523.362
3227.06	501.664
3230.26	501.918
3233.46	530.931
3236.66	583.566
3239.85	542.622
3243.05	531.336
3246.24	527.81
3249.44	493.804
3252.63	575.422
3255.82	558.941
3259.01	554.8
3262.19	586.538
3265.38	608.344
3268.56	595.367
3271.75	525.748
3274.93	540.032
3278.11	569.561
3281.29	602.315
3284.47	603.039
3287.64	632.45
3290.82	617.735
3293.99	620.435
3297.17	677.325
3300.34	652.334
3303.51	580.431
3306.68	675.317
3309.84	709.917
3313.01	617.642
3316.18	684.853
3319.34	718.69
3322.5	706.871
3325.66	706.476
3328.82	731.657
3331.98	684.077
3335.14	770.937
3338.29	773.916
3341.45	759.187
3344.6	720.046
3347.75	777.833
3350.9	782.6
3354.05	690.254
3357.2	787.701
3360.35	739.216
3363.49	785.354
3366.64	788.207
3369.78	827.069
3372.92	837.783
3376.06	844.141
3379.2	894.09
3382.34	918.722
3385.48	1027.38
3388.61	1012.51
3391.75	1014.7
3394.88	1048.93
3398.01	1144.91
3401.14	1315.84
3404.27	1590.82
3407.4	1956.94
3410.52	2874.67
3413.65	5365.89
3416.77	11372.7
3419.89	17307.9
3423.01	14068.5
3426.13	7132.1
3429.25	3528.8
3432.37	2132.87
3435.49	1656.42
3438.6	1400.74
3441.72	1242.96
3444.83	1127.15
3447.94	1095.62
3451.05	1083.1
3454.16	1086.32
3457.26	1045.66
3460.37	1027.45
3463.47	1022.51
3466.58	992.722
3469.68	1056.47
3472.78	1157.45
3475.88	1263.02
3478.98	1367.67
3482.07	1542.29
3485.17	1738.5
3488.26	2108.47
3491.36	2656.13
3494.45	3287.74
3497.54	4254.72
3500.63	5112.26
3503.72	5248.15
3506.81	4612.79
3509.89	3548.42
3512.98	2707.64
3516.06	2090.94
3519.14	1666.99
3522.22	1369.57
3525.3	1187.16
3528.38	1034.73
3531.45	940.136
3534.53	818.379
3537.61	761.32
3540.68	725.327
3543.75	642.386
3546.82	685.483
3549.89	593.564
3552.96	562.305
3556.03	590.367
3559.09	548.871
3562.16	556.576
3565.22	513.527
3568.28	456.787
3571.34	442.52
3574.4	474.45
3577.46	470.463
3580.52	434.017
3583.57	413.49
3586.63	393.681
3589.68	374.808
3592.73	375.542
3595.78	335.461
3598.83	388.036
3601.88	371.436
3604.93	337.55
3607.97	345.148
3611.02	346.098
3614.06	298.721
3617.1	292.87
3620.14	280.524
3623.18	243.772
3626.22	248.616
3629.26	235.692
3632.3	234.895
3635.33	209.51
3638.36	201.638
3641.4	240.173
3644.43	198.985
3647.46	218.583
3650.49	152.88
3653.51	150.527
3656.54	139.804
3659.57	124.403
3662.59	76.741
3665.61	113.413
3668.63	105.789
3671.65	88.2744
3674.67	87.8235
3677.69	49.7294
3680.71	120.324
3683.72	143.626
3686.74	97.9445
3689.75	37.1289
3692.76	28.3658
3695.77	74.5613
3698.78	60.6825
3701.79	45.3234
3704.79	17.5967
3707.8	111.395
3710.81	54.8842
3713.81	42.8488
3716.81	26.7462
3719.81	65.0104
3722.81	24.0338
3725.81	41.9009
3728.81	4.35767
3731.8	25.7124
3734.8	77.3425
3737.79	88.7455
3740.78	32.3798
3743.77	73.8175
3746.76	111.249
3749.75	2.04956
3752.74	76.1812
3755.73	78.0391
3758.71	39.146
3761.7	51.4498
3764.68	31.3575
3767.66	34.0674
3770.64	69.0968
3773.62	8.75305
3776.6	93.2422
3779.58	60.6066
3782.55	26.2338
3785.53	33.4603
3788.5	17.1918
3791.47	-7.44287
3794.44	24.8568
3797.41	30.8838
3800.38	7.76489
3803.35	22.6581
3806.32	42.3782
3809.28	54.6067
3812.24	25.375
3815.21	33.9858
3818.17	17.1089
3821.13	56.1295
3824.09	59.2546
3827.04	17.9888
3830	85.709
3832.96	74.7655
3835.91	53.5499
3838.86	65.6451
3841.82	59.6931
3844.77	22.3203
3847.72	61.0886
3850.67	2.81458
3853.61	45.6228
3856.56	-7.85437
3859.5	28.3833
3862.45	66.6097
3865.39	62.6818
3868.33	69.2731
3871.27	36.4164
3874.21	81.1389
3877.15	59.6121
3880.09	97.375
3883.02	63.8754
3885.96	66.6362
3888.89	52.9121
3891.82	17.9492
3894.75	6.91968
3897.68	84.1279
3900.61	79.3763
3903.54	29.3781
3906.47	36.8472
3909.39	86.8259
3912.31	62.61
3915.24	18.0503
3918.16	40.6285
3921.08	74.0826
3924	67.793
3926.92	93.9154
3929.83	46.9645
3932.75	42.1505
3935.67	67.4728
3938.58	60.6077
3941.49	49.2904
3944.4	88.5468
3947.31	64.7129
3950.22	29.5767
3953.13	65.4254
3956.04	38.1526
3958.94	23.4852
3961.85	46.2654
3964.75	31.7606
3967.65	72.0095
3970.55	42.3468
3973.45	71.2596
3976.35	25.2474
3979.25	41.5228
3982.15	53.8444
3985.04	46.9111
3987.94	51.4235
3990.83	72.2269
3993.72	78.3912
3996.61	82.9725
3999.5	39.399
4002.39	94.0951
4005.28	74.6937
4008.16	76.5668
4011.05	54.3635
4013.93	22.4718
4016.81	34.9456
4019.7	70.589
4022.58	34.8049
4025.46	69.5081
4028.33	22.1434
4031.21	48.2155
4034.09	52.113
4036.96	32.8102
4039.84	47.4478
4042.71	56.2347
4045.58	44.3818
4048.45	51.9937
4051.32	77.1599
4054.19	22.8978
4057.05	20.1919
4059.92	27.1232
4062.78	32.0514
4065.65	47.6853
4068.51	57.4869
4071.37	72.1344
4074.23	72.184
4077.09	50.7656
4079.95	64.3873
4082.81	43.8967
4085.66	44.8577
4088.52	65.2401
4091.37	66.1178
4094.22	50.52
4097.07	27.9327
4099.92	65.0372
4102.77	63.0237
4105.62	35.5209
4108.47	-4.92578
4111.31	57.3794
4114.16	59.8064
4117	60.1035
4119.84	54.2823
4122.69	21.0906
4125.53	58.5657
4128.36	31.496
4131.2	38.1609
4134.04	48.9988
4136.88	47.6305
4139.71	55.8915
4142.54	54.8173
4145.38	73.5084
4148.21	38.083
4151.04	16.4761
4153.87	67.928
4156.69	52.1836
4159.52	73.9071
4162.35	38.5138
4165.17	72.8049
4168	33.7104
4170.82	29.9141
4173.64	56.5306
4176.46	65.5911
4179.28	57.0525
4182.1	65.2817
4184.91	33.4689
4187.73	41.8546
4190.54	53.223
4193.36	125.547
4196.17	102.144
4198.98	126.979
4201.79	150.797
4204.6	123.708
4207.41	86.6969
4210.22	73.2527
4213.02	29.2639
4215.83	47.1625
4218.63	40.4674
4221.44	51.3921
4224.24	71.0669
4227.04	6.62769
4229.84	47.113
4232.64	34.3063
4235.43	69.2245
4238.23	44.8098
4241.02	32.2852
4243.82	48.6083
4246.61	37.1866
4249.4	100.423
4252.19	65.8124
4254.98	89.0465
4257.77	58.1346
4260.56	71.2144
4263.35	80.3844
4266.13	57.5002
4268.92	78.9109
4271.7	65.1119
4274.48	90.5341
4277.26	47.0729
4280.04	45.7118
4282.82	29.077
4285.6	58.7701
4288.38	54.9069
4291.15	48.8417
4293.93	44.729
4296.7	70.2179
4299.47	33.0077
4302.25	62.5549
4305.02	49.4879
4307.79	36.405
4310.55	44.7205
4313.32	48.1132
4316.09	52.2698
4318.85	90.8817
4321.62	62.2317
4324.38	25.2922
4327.14	68.7101
4329.9	-7.98291
4332.66	64.8768
4335.42	48.1992
4338.18	5.88794
4340.94	52.5249
4343.69	34.9679
4346.45	39.9989
4349.2	9.4635
4351.95	68.7389
4354.7	48.8279
4357.45	35.8682
4360.2	78.1287
4362.95	84.5248
4365.7	70.601
4368.44	42.176
4371.19	63.0928
4373.93	67.3385
4376.68	28.4434
4379.42	21.2184
4382.16	29.3629
4384.9	48.9186
4387.64	35.9244
4390.37	53.3488
4393.11	20.5426
4395.85	52.8032
4398.58	49.9188
4401.31	45.9197
4404.05	15.84
4406.78	85.392
4409.51	10.75
4412.24	47.0583
4414.96	70.7281
4417.69	51.6486
4420.42	42.3506
4423.14	9.33655
4425.87	27.5178
4428.59	35.2869
4431.31	36.792
4434.03	58.1473
4436.75	41.7649
4439.47	55.672
4442.19	62.1108
4444.91	26.6398
4447.62	33.0162
4450.34	35.2006
4453.05	33.0579
4455.76	28.7932
4458.47	42.2572
4461.19	38.8501
4463.89	67.1781
4466.6	36.5763
4469.31	31.2963
4472.02	50.2924
4474.72	12.5439
4477.43	61.3176
4480.13	59.6301
4482.83	55.9135
4485.53	18.3721
4488.23	29.2979
4490.93	24.3112
4493.63	32.7369
4496.33	33.5348
4499.02	11.2926
4501.72	75.8342
4504.41	40.6803
4507.11	65.0133
4509.8	16.2214
4512.49	16.2045
4515.18	57.6232
4517.87	21.5834
4520.56	52.5131
4523.24	61.2915
4525.93	40.2805
4528.61	52.2228
4531.3	59.9585
4533.98	2.7085
4536.66	51.0319
4539.34	24.7421
4542.02	29.4778
4544.7	32.061
4547.38	62.5167
4550.05	54.4768
4552.73	9.03064
4555.4	31.3226
4558.08	10.8762
4560.75	-6.02368
4563.42	49.4714
4566.09	4.03271
4568.76	13.9496
4571.43	50.2244
4574.1	25.4213
4576.77	40.2307
4579.43	61.114
4582.1	47.7858
4584.76	15.0502
4587.42	-4.3125
4590.08	32.9236
4592.74	18.7853
4595.4	59.3066
4598.06	20.2721
4600.72	16.0388
4603.38	41.5781
4606.03	39.8632
4608.69	31.5756
4611.34	58.3971
4613.99	19.3232
4616.64	35.118
4619.29	38.8995
4621.94	69.181
4624.59	16.7927
4627.24	37.0193
4629.89	21.8859
4632.53	6.67542
4635.18	48.7589
4637.82	26.6333
4640.46	49.8467
4643.1	1.10645
4645.74	-4.19324
4648.38	34.0764
4651.02	4.94897
4653.66	51.8578
4656.3	31.4771
4658.93	4.19434
4661.57	31.2949
4664.2	18.4348
4666.83	56.8038
4669.46	5.43628
4672.09	32.4675
4674.72	58.3878
4677.35	33.8594
4679.98	48.5442
4682.61	26.1472
4685.23	22.8203
4687.86	45.3521
4690.48	19.5249
4693.1	-19.8497
4695.73	13.8861
4698.34	44.2582
4700.96	75.8209
4703.58	-2.18848
4706.2	31.4856
4708.82	58.368
4711.43	10.5598
4714.05	32.8578
4716.66	26.8107
4719.28	19.5658
4721.89	20.1997
4724.5	44.5771
4727.11	27.1666
4729.72	66.5333
4732.33	70.7495
4734.93	55.6605
4737.54	33.6812
4740.14	33.2068
4742.75	23.585
4745.35	41.1606
4747.95	33.6239
4750.55	32.7451
4753.15	53.5186
4755.75	31.0159
4758.35	6.22144
4760.95	57.7941
4763.54	55.9415
4766.14	82.6288
4768.73	9.29578
4771.33	21.4896
4773.92	31.1777
4776.51	38.6046
4779.1	48.3198
4781.69	68.3004
4784.28	71.1561
4786.87	33.9952
4789.45	36.8381
4792.04	60.3177
4794.63	5.98364
4797.21	21.5164
4799.79	39.4619
4802.37	60.9352
4804.95	40.0277
4807.53	15.7604
4810.11	37.5416
4812.69	25.9371
4815.27	48.9515
4817.84	43.215
4820.42	12.1003
4822.99	30.6601
4825.57	55.067
4828.14	45.8476
4830.71	51.7119
4833.28	23.9453
4835.85	59.0419
4838.42	38.3491
4840.98	23.5121
4843.55	23.7833
4846.12	23.86
4848.68	57.8474
4851.24	48.097
4853.81	29.4011
4856.37	44.9637
4858.93	9.73242
4861.49	0.260498
4864.05	28.2507
4866.61	0.396484
4869.16	47.05
4871.72	14.6887
4874.27	29.4068
4876.83	0.15033
4879.38	34.9061
4881.93	19.7671
4884.49	5.72223
4887.04	35.6214
4889.58	75.0825
4892.13	26.512
4894.68	58.8071
4897.23	35.0925
4899.77	36.3428
4902.32	66.183
4904.86	33.9791
4907.4	31.5294
4909.95	31.4216
4912.49	44.2184
4915.03	13.9293
4917.57	37.2845
4920.1	12.9553
4922.64	18.4739
4925.18	15.6284
4927.71	10.4476
4930.25	54.1321
4932.78	47.8747
4935.31	31.0195
4937.84	5.64679
4940.38	1.77472
4942.9	27.3997
4945.43	19.8486
4947.96	7.63965
4950.49	4.95789
4953.01	28.7224
4955.54	24.7819
4958.06	-4.20709
4960.59	50.9077
4963.11	-0.80542
4965.63	18.6239
4968.15	-7.52576
4970.67	31.1068
4973.19	4.57227
4975.71	3.32037
4978.22	2.03076
4980.74	-4.07135
4983.25	41.8947
4985.77	37.0425
4988.28	29.76
4990.79	18.8231
4993.3	32.13
4995.81	19.8626
4998.32	16.2401