File: Data/3-Raman/processed/bu19(2)w-a-ff2-fi03-v_150 (500nm)_532nm_edge_100%_x100_vis_lwd_h50um_30sx2_01.txt
#Acq. time (s)=	30
#Accumulations=	2
#Range (cm-¹)=	99...4000
#Windows=	1
#Auto scanning=	Off
#Autofocus=	Off
#Macrospot=	Off
#AutoExposure=	Off
#Spike filter=	Multiple accum.
#Delay time (s)=	2
#Binning=	1
#Readout mode=	Signal
#DeNoise=	Off
#ICS correction=	On
#Dark correction=	Off
#Inst. Process=	Off
#Detector Gain=	Best Dynamic
#Detector ADC=	50 kHz HS
#Detector temperature (°C)=	-60.09
#Instrument=	LabRAM HR Evol
#Detector=	SIN-EM FIVIS
#Objective=	x100_VIS_LWD
#Grating=	150 (500nm)
#ND Filter=	100%
#Laser=	532nm_Edge
#Hole=	49.98
#Temperature=	0
#Range=	Visible
#StageXY=	75x50mm Scan+
#StageZ=	Z motor
#X (µm)=	0
#Y (µm)=	0
#Z (µm)=	-43.7
#Full time(mm:ss)=	1:05
#Project=	21_11_26
#Sample=	BU19(2)w
#Site=
#Title=	BU19(2)w-A-FF2-FI03-V_150 (500nm)_532nm_Edge_100%_x100_VIS_LWD_H50um_30sX2
#Remark=
#Date=	26.11.2021 15:21
#Acquired=	26.11.2021 15:21:18
#Base:Fit=	16.12.2021 16:00:56
#Base:Edit=	16.12.2021 16:11:10
#Base:Edit=	16.12.2021 16:11:13
#Base:Sub=	16.12.2021 16:11:14
102.91	1798.46
107.534	2781.24
112.156	2889.55
116.775	2005.43
121.392	1214.12
126.005	1043.39
130.617	1193.26
135.227	2110.25
139.835	4409.64
144.439	7380.05
149.042	7795.86
153.643	5303.48
158.242	2743.44
162.839	1234.94
167.431	540.785
172.023	223.675
176.613	54.415
181.198	61.9663
185.783	0.0961914
190.366	104.715
194.947	296.228
199.524	780.034
204.1	1792
208.674	3298.75
213.243	2691.76
217.813	1326.54
222.38	982.477
226.945	1498.61
231.506	2781.84
236.066	3457.26
240.625	1935.68
245.179	833.42
249.732	415.062
254.284	266.084
258.831	156.155
263.378	64.5618
267.923	13.1523
272.464	49.0901
277.004	149.314
281.54	314.374
286.076	176.964
290.61	77.2832
295.139	-0.192383
299.669	42.6353
304.196	62.2385
308.718	172.854
313.241	171.288
317.759	349.111
322.278	603.771
326.794	906.56
331.305	1355.25
335.817	1555.56
340.324	1503.71
344.832	1472.77
349.334	2026.98
353.837	2292.84
358.338	1712.27
362.834	1367.97
367.33	1298.91
371.822	1477.36
376.314	1744.3
380.802	2168.87
385.289	3015.16
389.772	4377.29
394.255	5637.07
398.734	5782.07
403.213	5791.3
407.688	5670.96
412.162	5550.43
416.632	5579.06
421.102	5834.04
425.568	6238.04
430.033	6229.54
434.495	5944.25
438.956	5257.15
443.413	4818.93
447.87	4607.31
452.323	4342.95
456.776	3768.82
461.224	2974.33
465.673	2403.21
470.117	2062.63
474.561	1916.61
479.001	1850.58
483.438	1995.26
487.876	2177.02
492.309	2577.59
496.742	3131.4
501.172	4089.84
505.601	5071.32
510.025	5676.23
514.448	5507.08
518.871	5011.87
523.289	4438.19
527.707	4104.05
532.121	3941.92
536.533	4071.21
540.945	4234.28
545.353	4486.23
549.758	4604.05
554.164	4679.06
558.565	4515.34
562.965	4263.82
567.364	4129.03
571.759	4045.34
576.151	4183.22
580.544	4451.55
584.933	4826.52
589.319	5397.39
593.706	5949.61
598.088	6369
602.468	6762.66
606.848	7380.14
611.224	8529.48
615.598	11518.8
619.972	14174.3
624.341	11873.1
628.709	7872.18
633.074	5379.94
637.44	4083.26
641.801	3368.09
646.16	2798.06
650.517	2459.29
654.874	2175.45
659.227	1934.99
663.578	1733.37
667.927	1580.07
672.275	1478.78
676.62	1357.68
680.962	1241.6
685.302	1209.49
689.643	1081.21
693.979	1125.7
698.313	1136.96
702.645	1210.49
706.975	1118.17
711.305	1011.14
715.631	852.045
719.955	815.689
724.276	753.009
728.596	700.557
732.913	653.294
737.231	516.508
741.544	512.974
745.856	478.298
750.165	484.392
754.472	500.812
758.778	521.338
763.081	489.005
767.384	518.071
771.683	493.83
775.98	567.453
780.275	525.324
784.568	572.638
788.859	620.485
793.147	597.11
797.434	639.446
801.719	647.535
806.004	672.749
810.284	738.358
814.563	787.787
818.839	896.964
823.114	899.357
827.386	1112.65
831.657	1231.64
835.925	1413.57
840.192	1643.92
844.456	1609.23
848.719	1466.2
852.979	1270.56
857.237	1047.51
861.493	880.745
865.748	711.46
870	658.208
874.25	725.335
878.499	867.28
882.745	792.487
886.989	544.341
891.231	321.162
895.471	165.808
899.71	117.229
903.946	87.6241
908.18	17.6604
912.412	35.6857
916.642	11.3638
920.87	9.39624
925.096	49.9023
929.321	-15.014
933.543	-8.03723
937.763	19.1039
941.981	-22.8571
946.197	44.1284
950.412	7.2655
954.622	16.7318
958.832	47.598
963.04	38.1659
967.246	6.58923
971.451	24.0455
975.653	78.8617
979.853	33.1161
984.052	115.837
988.248	135.958
992.442	260.938
996.633	333.18
1000.82	421.488
1005.01	470.038
1009.2	338.338
1013.38	290.335
1017.57	224.652
1021.75	201.403
1025.92	225.724
1030.1	295.333
1034.27	353.702
1038.45	540.343
1042.62	739.158
1046.78	938.315
1050.95	851.297
1055.12	847.793
1059.28	839.373
1063.44	858.756
1067.6	1036.14
1071.75	1303.34
1075.91	1609.34
1080.06	2186.18
1084.21	3156.64
1088.36	4743.65
1092.51	6603.11
1096.65	7280.89
1100.8	5761
1104.94	3648.22
1109.08	2229.84
1113.21	1509.54
1117.35	1176.88
1121.48	985.757
1125.61	1020.21
1129.74	1066.88
1133.87	1250.6
1137.99	1591.11
1142.12	2032.11
1146.24	2121.23
1150.36	1772.58
1154.48	1426.38
1158.59	995.999
1162.71	700.984
1166.82	501.219
1170.93	322.707
1175.04	292.241
1179.14	216.184
1183.25	135.046
1187.35	103.964
1191.45	94.6917
1195.55	63.5057
1199.65	25.8586
1203.74	46.0797
1207.83	10.2124
1211.92	67.7565
1216.01	43.2435
1220.1	59.2802
1224.19	61.3625
1228.27	62.7305
1232.35	85.6206
1236.43	58.5309
1240.51	112.218
1244.58	211.444
1248.66	368.041
1252.73	301.865
1256.8	175.054
1260.87	244.244
1264.93	957.917
1269	3461.48
1273.06	1690.89
1277.12	327.729
1281.18	142.856
1285.23	97.114
1289.29	115.424
1293.34	104.368
1297.39	90.0436
1301.44	67.4945
1305.49	90.0088
1309.53	63.0229
1313.58	79.2059
1317.62	69.6841
1321.66	81.012
1325.7	95.8243
1329.73	95.3313
1333.77	76.6128
1337.8	94.5654
1341.83	90.1987
1345.86	155.594
1349.88	99.089
1353.91	233.857
1357.93	215.234
1361.95	229.263
1365.97	429.573
1369.99	2999.44
1374	5536.51
1378.02	1580.1
1382.03	334.177
1386.04	240.669
1390.05	287.281
1394.05	563.62
1398.06	340.592
1402.06	121.198
1406.06	90.7729
1410.06	84.101
1414.05	58.7939
1418.05	40.3663
1422.04	41.6271
1426.03	57.5151
1430.02	54.9639
1434.01	26.828
1438	9.51611
1441.98	39.594
1445.96	54.6471
1449.94	-26.1239
1453.92	28.0754
1457.9	11.0973
1461.87	17.5471
1465.85	-3.979
1469.82	31.4617
1473.78	41.4559
1477.75	10.0448
1481.72	36.3392
1485.68	26.2616
1489.65	20.0146
1493.61	19.7172
1497.56	25.2811
1501.52	68.9135
1505.47	50.4144
1509.43	19.6464
1513.38	47.27
1517.33	-8.57019
1521.27	23.0874
1525.22	46.0538
1529.16	40.9653
1533.11	36.0183
1537.05	55.3182
1540.98	64.9435
1544.92	32.8872
1548.86	56.0536
1552.79	37.5392
1556.72	85.694
1560.65	38.7305
1564.58	43.9078
1568.5	40.2354
1572.43	24.8627
1576.35	86.7303
1580.27	57.7327
1584.19	51.8717
1588.1	73.8492
1592.02	57.2378
1595.93	80.0476
1599.84	89.3525
1603.75	101.61
1607.66	77.5723
1611.57	84.2673
1615.47	84.321
1619.37	95.0726
1623.27	98.0634
1627.17	79.2184
1631.07	101.687
1634.97	62.3313
1638.86	95.6445
1642.75	53.6338
1646.64	69.3164
1650.53	69.7848
1654.42	59.743
1658.3	60.1283
1662.18	41.2327
1666.07	87.423
1669.94	70.041
1673.82	66.6727
1677.7	48.7948
1681.57	34.1075
1685.44	61.3508
1689.31	78.8347
1693.18	79.7289
1697.05	74.6881
1700.92	35.0558
1704.78	47.7242
1708.64	46.7521
1712.5	20.8274
1716.36	49.9714
1720.21	52.5536
1724.07	54.1997
1727.92	54.7803
1731.77	88.0361
1735.62	75.2888
1739.47	56.8312
1743.32	76.5593
1747.16	34.802
1751.01	45.9767
1754.85	84.4604
1758.69	89.2438
1762.52	57.0948
1766.36	38.897
1770.19	49.916
1774.02	35.4954
1777.85	41.5493
1781.68	19.1173
1785.51	14.5411
1789.33	30.6398
1793.16	-12.1725
1796.98	25.5787
1800.8	9.81812
1804.62	24.306
1808.43	27.4111
1812.25	44.5143
1816.06	48.2122
1819.87	19.2947
1823.68	27.7955
1827.49	39.8381
1831.3	57.1925
1835.1	18.6094
1838.9	38.249
1842.71	26.6234
1846.51	32.5798
1850.3	53.6699
1854.1	35.7328
1857.89	57.7349
1861.69	33.5531
1865.48	33.5308
1869.27	29.9075
1873.05	37.5375
1876.84	53.7
1880.62	24.6538
1884.4	0.802979
1888.19	50.7035
1891.96	34.7173
1895.74	15.0917
1899.52	36.869
1903.29	45.3584
1907.06	12.6531
1910.83	27.0098
1914.6	34.4445
1918.37	19.8206
1922.13	17.9286
1925.9	33.7406
1929.66	71.1609
1933.42	59.5544
1937.18	39.4781
1940.94	41.6826
1944.69	29.8282
1948.44	54.4741
1952.2	60.402
1955.95	33.9144
1959.69	50.9231
1963.44	91.9436
1967.19	88.7446
1970.93	106.739
1974.67	146.744
1978.41	113.331
1982.15	142.463
1985.89	132.045
1989.62	170.016
1993.35	158.286
1997.09	153.766
2000.82	133.24
2004.55	128.594
2008.27	134.91
2012	133.504
2015.72	99.0464
2019.44	91.0374
2023.16	69.057
2026.88	92.7549
2030.6	79.8651
2034.31	93.2057
2038.03	67.6287
2041.74	41.0145
2045.45	69.2382
2049.16	8.6759
2052.86	69.2213
2056.57	33.6829
2060.27	58.3202
2063.98	35.1169
2067.67	22.2535
2071.37	48.1429
2075.07	19.6848
2078.77	47.6219
2082.46	28.5027
2086.15	27.7219
2089.84	6.02429
2093.53	72.0198
2097.22	54.0778
2100.9	36.8333
2104.59	40.5626
2108.27	63.6135
2111.95	36.2574
2115.63	42.3468
2119.31	48.2797
2122.98	37.9393
2126.66	58.8999
2130.33	49.0475
2134	41.8828
2137.67	48.5231
2141.34	48.4792
2145	68.5208
2148.67	40.585
2152.33	43.9457
2155.99	24.4291
2159.65	17.8394
2163.31	40.6642
2166.96	36.2406
2170.62	47.5431
2174.27	56.6003
2177.92	31.3322
2181.57	69.0464
2185.22	21.1738
2188.87	38.2271
2192.51	23.0079
2196.15	18.2867
2199.8	59.3829
2203.44	19.5353
2207.07	-26.5945
2210.71	27.0127
2214.35	12.2749
2217.98	5.81433
2221.61	70.9976
2225.24	15.9642
2228.87	36.2195
2232.5	0.290405
2236.12	10.5616
2239.75	15.2806
2243.37	25.5538
2246.99	0.532104
2250.61	34.0826
2254.23	-3.85254
2257.85	0.187134
2261.46	32.2681
2265.07	3.44604
2268.68	48.7654
2272.29	25.9153
2275.9	24.3154
2279.51	26.1536
2283.11	7.39075
2286.72	33.9122
2290.32	12.2596
2293.92	66.0814
2297.52	-14.3708
2301.11	16.8661
2304.71	28.9928
2308.3	33.2983
2311.9	91.47
2315.49	294.494
2319.08	173.108
2322.66	42.0223
2326.25	30.5823
2329.84	12.4326
2333.42	47.9979
2337	53.1448
2340.58	43.0532
2344.16	25.353
2347.73	27.2667
2351.31	27.2189
2354.88	50.4861
2358.45	20.4124
2362.03	48.1149
2365.59	57.1056
2369.16	39.2469
2372.73	48.606
2376.29	46.7517
2379.85	27.406
2383.41	17.4923
2386.97	46.3649
2390.53	39.5376
2394.09	54.0786
2397.64	35.9535
2401.2	9.09668
2404.75	19.5566
2408.3	32.0055
2411.85	2.7793
2415.39	19.694
2418.94	26.8188
2422.48	20.3458
2426.03	-8.90076
2429.57	49.7491
2433.11	21.9116
2436.64	30.371
2440.18	55.7124
2443.72	46.8074
2447.25	-7.85645
2450.78	27.2969
2454.31	20.6044
2457.84	40.3872
2461.37	29.9979
2464.89	26.0697
2468.42	32.4586
2471.94	41.704
2475.46	23.5007
2478.98	35.3086
2482.5	17.1359
2486.01	39.0475
2489.53	53.5869
2493.04	21.7758
2496.55	30.6605
2500.06	32.4386
2503.57	44.11
2507.08	52.7418
2510.58	57.3492
2514.09	34.1141
2517.59	44.6829
2521.09	40.5867
2524.59	82.8878
2528.09	-2.23328
2531.59	48.9006
2535.08	35.5101
2538.58	43.7064
2542.07	41.1031
2545.56	28.9164
2549.05	40.3123
2552.54	49.0065
2556.02	8.99487
2559.51	56.5563
2562.99	25.3794
2566.47	32.7363
2569.95	43.2852
2573.43	25.2119
2576.91	32.5671
2580.38	24.1971
2583.85	33.7577
2587.33	61.3347
2590.8	34.6853
2594.27	24.3893
2597.74	59.5793
2601.2	51.3386
2604.67	60.176
2608.13	49.162
2611.59	26.5483
2615.06	37.6622
2618.51	15.5956
2621.97	46.8312
2625.43	36.5123
2628.88	40.281
2632.33	51.5276
2635.79	15.4442
2639.24	50.9645
2642.69	30.6525
2646.13	47.4424
2649.58	15.4077
2653.02	50.8671
2656.47	43.0754
2659.91	47.4022
2663.35	41.1532
2666.79	47.0935
2670.22	68.9935
2673.66	54.9825
2677.09	53.4188
2680.52	32.3715
2683.95	8.85278
2687.39	16.6003
2690.81	22.2697
2694.24	44.1725
2697.66	15.5134
2701.09	36.4653
2704.51	24.8717
2707.93	23.5507
2711.35	38.8459
2714.77	24.61
2718.18	22.6835
2721.6	31.2206
2725.01	52.0436
2728.42	1.07703
2731.84	22.988
2735.24	29.8929
2738.65	56.4825
2742.06	49.2883
2745.46	39.9557
2748.86	26.6713
2752.27	37.819
2755.67	28.1676
2759.07	16.4788
2762.46	47.1759
2765.86	40.8236
2769.25	31.4464
2772.65	33.1686
2776.04	3.68335
2779.43	51.2393
2782.82	48.6809
2786.2	57.3143
2789.59	56.4784
2792.98	31.1464
2796.36	36.7941
2799.74	44.2974
2803.12	44.08
2806.5	24.1785
2809.88	67.9526
2813.25	33.9037
2816.63	28.813
2820	53.5837
2823.37	33.6842
2826.74	22.3534
2830.11	-1.00867
2833.48	51.2675
2836.84	42.2313
2840.21	23.1404
2843.57	10.7834
2846.93	19.1852
2850.29	60.6432
2853.65	19.3518
2857.01	32.0242
2860.36	28.9661
2863.72	34.4559
2867.07	41.8672
2870.42	25.8284
2873.77	-20.4001
2877.12	25.3839
2880.47	54.2734
2883.81	23.7966
2887.16	9.18665
2890.5	16.2217
2893.84	12.7939
2897.18	27.0276
2900.52	34.4722
2903.86	43.6143
2907.19	3.39478
2910.53	23.6123
2913.86	60.7633
2917.19	24.0068
2920.52	16.3954
2923.85	23.8413
2927.18	28.3225
2930.51	25.0544
2933.83	21.636
2937.15	33.1272
2940.48	37.984
2943.8	3.25317
2947.11	-13.517
2950.43	7.38538
2953.75	16.9174
2957.06	19.8837
2960.38	1.43323
2963.69	-18.7871
2967	12.6547
2970.31	25.6635
2973.62	-13.6526
2976.92	19.2855
2980.23	24.2689
2983.53	6.57788
2986.84	34.9359
2990.14	18.2969
2993.44	28.9136
2996.73	-14.9061
3000.03	-3.25146
3003.33	24.3723
3006.62	17.2021
3009.91	-0.244385
3013.2	-5.41553
3016.49	32.7675
3019.78	1.18164
3023.07	43.1105
3026.35	19.9556
3029.64	-3.21838
3032.92	57.64
3036.2	11.6696
3039.48	-2.23328
3042.76	16.9648
3046.04	-5.45459
3049.32	-3.27222
3052.59	-5.83569
3055.86	7.73767
3059.14	16.5226
3062.41	43.8882
3065.68	44.8729
3068.94	4.8855
3072.21	24.4124
3075.48	11.5615
3078.74	21.7472
3082	39.1122
3085.26	45.2056
3088.52	41.7438
3091.78	19.6147
3095.04	39.3555
3098.29	19.4886
3101.55	40.3365
3104.8	18.1587
3108.05	62.1841
3111.3	36.58
3114.55	17.2209
3117.8	30.3312
3121.04	44.4287
3124.29	60.4313
3127.53	72.6034
3130.77	73.3019
3134.02	57.8145
3137.25	71.83
3140.49	92.4485
3143.73	86.3551
3146.96	62.1505
3150.2	80.9336
3153.43	88.3019
3156.66	87.9829
3159.89	100.102
3163.12	123.627
3166.35	74.6353
3169.57	117.128
3172.8	142.346
3176.02	102.614
3179.24	176.313
3182.46	174.61
3185.68	163.401
3188.9	145.358
3192.12	178.762
3195.33	172.12
3198.55	149.268
3201.76	174.016
3204.97	168.349
3208.18	186.53
3211.39	189.549
3214.6	180.302
3217.8	163.549
3221.01	185.809
3224.21	223.343
3227.41	177.319
3230.61	236.929
3233.81	252.902
3237.01	268.788
3240.21	200.306
3243.4	218.526
3246.59	215.885
3249.79	281.879
3252.98	251.791
3256.17	292.324
3259.36	296.605
3262.54	266.297
3265.73	304.534
3268.92	298.628
3272.1	327.922
3275.28	349.487
3278.46	321.368
3281.64	339.726
3284.82	370.196
3288	377.789
3291.17	398.596
3294.35	382.365
3297.52	408.965
3300.69	423.205
3303.86	423.563
3307.03	432.055
3310.2	461.305
3313.36	519.714
3316.53	523.821
3319.69	544.969
3322.85	536.647
3326.02	563.414
3329.18	598.68
3332.33	638.679
3335.49	666.491
3338.65	698.229
3341.8	752.735
3344.95	794.997
3348.11	829.282
3351.26	821.68
3354.41	941.315
3357.56	908.53
3360.7	990.885
3363.85	1011.34
3366.99	1029.99
3370.13	1114.84
3373.28	1137.59
3376.42	1270.18
3379.56	1291.59
3382.69	1317.89
3385.83	1374.38
3388.97	1498.35
3392.1	1549.66
3395.23	1583.86
3398.36	1668.54
3401.49	1753.11
3404.62	1806.82
3407.75	1992.05
3410.88	2097.06
3414	2235.53
3417.13	2388.69
3420.25	2441.76
3423.37	2674.9
3426.49	2809.18
3429.61	3087.01
3432.73	3354.83
3435.84	3679.01
3438.96	3972.36
3442.07	4410.37
3445.18	5044.63
3448.29	6094.98
3451.4	7639.01
3454.51	9850.92
3457.62	11716.2
3460.72	11933.9
3463.83	10188.9
3466.93	8403.3
3470.03	7152.84
3473.13	6338.68
3476.23	5904.53
3479.33	5585.08
3482.43	5555.83
3485.53	5346.36
3488.62	5441.77
3491.71	5482.46
3494.81	5391
3497.9	5384.3
3500.99	5454.53
3504.07	5346.72
3507.16	5577.22
3510.25	5603.08
3513.33	5826.34
3516.41	6083.65
3519.5	6254.69
3522.58	6632.73
3525.66	7089.86
3528.73	7367.29
3531.81	7798.78
3534.89	8255.02
3537.96	8376.28
3541.03	8369.16
3544.11	7848.89
3547.18	7227.86
3550.25	6341.18
3553.32	5498.74
3556.38	4542.35
3559.45	3781.86
3562.51	3188.11
3565.58	2684.74
3568.64	2307.45
3571.7	1970.85
3574.76	1713.1
3577.82	1495.29
3580.87	1293.38
3583.93	1200.37
3586.98	1099.59
3590.04	914.469
3593.09	920.685
3596.14	807.463
3599.19	760.489
3602.24	701.281
3605.29	598.408
3608.33	627.056
3611.38	629.222
3614.42	533.99
3617.46	512.518
3620.5	492.143
3623.54	467.2
3626.58	444.267
3629.62	426.22
3632.65	410.963
3635.69	348.616
3638.72	348.872
3641.76	323.043
3644.79	291.796
3647.82	242.159
3650.84	246.721
3653.87	181.895
3656.9	173.669
3659.92	155.41
3662.95	150.192
3665.97	85.3821
3668.99	86.858
3672.01	60.3892
3675.03	67.0078
3678.05	35.9834
3681.07	54.1406
3684.08	1.39624
3687.1	-8.80701
3690.11	1.86096
3693.12	12.6066
3696.13	-18.285
3699.14	-7.70264
3702.15	-15.7972
3705.16	-2.04578
3708.16	-21.5129
3711.17	-4.99646
3714.17	-8.49878
3717.17	-55.8816
3720.17	-48.0011
3723.17	-42.1373
3726.17	-50.6233
3729.17	-39.1897
3732.16	-42.0961
3735.16	-86.0378
3738.15	-58.6554
3741.14	-65.6261
3744.13	-61.2825
3747.13	-62.715
3750.11	-55.6769
3753.1	-100.006
3756.09	-76.8672
3759.07	-84.0734
3762.06	-62.838
3765.04	-58.7565
3768.02	-76.4158
3771	-54.2172
3773.98	-48.9559
3776.96	-60.629
3779.94	-78.8375
3782.91	-61.0667
3785.89	-72.5601
3788.86	-66.0472
3791.83	-59.4735
3794.8	-101.823
3797.77	-93.1275
3800.74	-76.8247
3803.71	-77.3893
3806.68	-81.691
3809.64	-65.1938
3812.61	-37.2972
3815.57	-34.8989
3818.53	-64.6539
3821.49	-66.9705
3824.45	-25.729
3827.41	-60.1904
3830.36	-76.6973
3833.32	-66.6973
3836.27	4.12549
3839.23	-62.668
3842.18	-58.3011
3845.13	-56.8268
3848.08	-33.4732
3851.03	-23.4226
3853.98	-66.7435
3856.92	-37.6342
3859.87	-33.347
3862.81	4.36749
3865.75	1.84711
3868.7	-12.2271
3871.64	-10.1683
3874.57	-42.7206
3877.51	38.7869
3880.45	-3.65802
3883.39	-16.5305
3886.32	23.2639
3889.25	-0.505798
3892.18	10.2153
3895.12	-1.29877
3898.05	-19.7443
3900.97	41.4435
3903.9	27.5108
3906.83	-1.03735
3909.75	18.5078
3912.68	-0.573608
3915.6	13.7981
3918.52	44.3323
3921.44	14.4283
3924.36	11.1306
3927.28	3.78961
3930.2	10.6426
3933.11	12.5469
3936.03	24.1344
3938.94	5.14789
3941.86	-4.21576
3944.77	-13.7887
3947.68	17.7294
3950.59	24.3146
3953.49	-5.55511
3956.4	-17.3384
3959.31	4.33881
3962.21	-21.9897
3965.12	-1.4726
3968.02	22.7922
3970.92	-4.84277
3973.82	-20.1619
3976.72	9.4527
3979.61	8.1181
3982.51	-9.79034
3985.41	-13.4866
3988.3	26.8229
3991.19	0.566223
3994.09	-1.95007
3996.98	8.97711
3999.87	-4.36786