File: Data/3-Raman/processed/bu19(2)w-a-ff1-fi01-v_1800 (450-850nm)_532nm_edge_100%_x100_vis_lwd_h100um_30sx2_01.txt
#Acq. time (s)=	30
#Accumulations=	2
#Range (cm-¹)=	1200...2365
#Windows=	3
#Auto scanning=	Off
#Autofocus=	Off
#Macrospot=	Off
#AutoExposure=	Off
#Spike filter=	Multiple accum.
#Delay time (s)=	2
#Binning=	1
#Readout mode=	Signal
#DeNoise=	Off
#ICS correction=	On
#Dark correction=	Off
#Inst. Process=	Off
#Detector Gain=	Best Dynamic
#Detector ADC=	50 kHz HS
#Detector temperature (°C)=	-60.09
#Instrument=	LabRAM HR Evol
#Detector=	SIN-EM FIVIS
#Objective=	x100_VIS_LWD
#Grating=	1800 (450-850nm)
#ND Filter=	100%
#Laser=	532nm_Edge
#Hole=	100.021
#Temperature=	0
#Range=	Visible
#StageXY=	75x50mm Scan+
#StageZ=	Z motor
#X (µm)=	0
#Y (µm)=	0
#Z (µm)=	-47.2
#Full time(mm:ss)=	3:22
#Project=	21_11_26
#Sample=	BU19(2)w
#Site=
#Title=	BU19(2)w-A-FF1-FI01-V_1800 (450-850nm)_532nm_Edge_100%_x100_VIS_LWD_H100um_30sX2
#Remark=
#Date=	26.11.2021 11:36
#Acquired=	26.11.2021 11:36:17
#Base:Fit=	16.12.2021 16:00:56
#Base:Sub=	16.12.2021 16:04:20
1202.72	4.7682
1203.84	4.1189
1204.95	18.434
1206.06	3.66098
1207.17	1.75439
1208.28	10.5935
1209.39	8.709
1210.5	10.0583
1211.61	4.91888
1212.72	5.12036
1213.83	10.6605
1214.94	1.33187
1216.05	3.69978
1217.16	12.3564
1218.27	2.95343
1219.38	4.19614
1220.49	7.56055
1221.6	7.7383
1222.71	6.78706
1223.81	5.79843
1224.92	6.95867
1226.03	9.23847
1227.14	10.4388
1228.25	4.12479
1229.35	11.4864
1230.46	7.58237
1231.57	8.59257
1232.67	13.9692
1233.78	16.1733
1234.89	12.1081
1235.99	9.08953
1237.1	13.3815
1238.2	13.3941
1239.31	15.5056
1240.41	10.3287
1241.52	16.7083
1242.62	13.6184
1243.73	17.9079
1244.83	16.9312
1245.94	14.8424
1247.04	18.0117
1248.14	21.1975
1249.25	28.5387
1250.35	25.4572
1251.45	18.1292
1252.56	28.5747
1253.66	24.3968
1254.76	26.5772
1255.87	27.6815
1256.97	35.0564
1258.07	44.4788
1259.17	47.6047
1260.27	47.711
1261.37	63.2921
1262.48	93.9011
1263.58	134.222
1264.68	137.989
1265.78	84.5478
1266.88	55.3263
1267.98	52.3295
1269.08	52.5044
1270.18	43.115
1271.28	52.484
1272.38	52.5326
1273.47	51.6449
1274.57	52.83
1275.67	61.2729
1276.77	52.9982
1277.87	77.2886
1278.97	75.3415
1280.07	104.858
1281.16	199.572
1282.26	585.035
1283.36	1650.6
1284.45	2115.16
1285.55	710.857
1286.65	194.806
1287.75	116.856
1288.84	85.2881
1289.94	68.5676
1291.03	62.3291
1292.13	62.3664
1293.22	51.8801
1294.32	44.6756
1295.42	48.97
1296.51	46.0615
1297.61	38.7069
1298.7	36.6019
1299.79	31.3367
1300.89	33.5328
1301.98	29.3817
1303.08	27.3525
1304.17	32.6666
1305.26	41.1701
1306.35	32.7197
1307.45	26.4437
1308.54	26.5183
1309.63	27.6667
1310.73	24.5849
1311.82	33.1129
1312.91	31.1147
1314	20.6097
1315.09	25.972
1316.18	29.2577
1317.28	26.1567
1318.37	24.1488
1319.46	27.4044
1320.55	31.7153
1321.64	21.1882
1322.73	29.6507
1323.82	23.3849
1324.91	25.5871
1326	21.4143
1327.09	20.3411
1328.18	32.1416
1329.27	22.8353
1330.35	28.1961
1331.44	16.635
1332.53	28.2194
1333.62	25.066
1334.71	24.0357
1335.79	16.7347
1336.88	22.0402
1337.97	20.0202
1339.06	17.9785
1340.14	25.4117
1341.23	27.6184
1342.32	29.7915
1343.4	19.3745
1344.49	26.7986
1345.58	24.784
1346.66	31.0603
1347.75	16.4832
1348.83	25.9467
1349.92	23.9267
1351	17.7436
1352.09	19.8918
1353.17	27.3315
1354.25	28.5617
1355.34	28.5093
1356.42	25.5022
1357.51	35.9712
1358.59	35.0016
1359.67	29.88
1360.76	39.2548
1361.84	38.3133
1362.92	41.5097
1364	45.8024
1365.09	41.7768
1366.17	48.0349
1367.25	47.0246
1368.33	47.1441
1369.41	110.361
1370.5	89.7701
1371.58	48.4712
1372.66	54.6508
1373.74	49.5555
1374.82	58.923
1375.9	59.0441
1376.98	77.6576
1378.06	64.3577
1379.14	79.0883
1380.22	85.3343
1381.3	98.5671
1382.38	118.064
1383.46	143.606
1384.54	223.595
1385.61	434.341
1386.69	1628.3
1387.77	4942.95
1388.85	1513.2
1389.93	336.579
1391	163.874
1392.08	123.877
1393.16	97.2552
1394.23	82.999
1395.31	64.6956
1396.39	73.0398
1397.46	64.9197
1398.54	56.8362
1399.62	58.0215
1400.69	63.2943
1401.77	58.3418
1402.84	71.9438
1403.92	62.9274
1404.99	77.3389
1406.07	77.383
1407.14	110.267
1408.22	186.299
1409.29	269.554
1410.37	169.212
1411.44	74.8396
1412.51	46.2448
1413.59	48.6444
1414.66	41.4732
1415.73	37.516
1416.81	39.7065
1417.88	32.6621
1418.95	30.7308
1420.02	34.9345
1421.1	28.8277
1422.17	36.1279
1423.24	29.1866
1424.31	36.2561
1425.38	26.1105
1426.45	29.3112
1427.52	26.2768
1428.59	25.298
1429.67	29.5158
1430.74	20.4495
1431.81	16.5178
1432.87	19.6668
1433.95	21.7331
1435.01	18.7777
1436.08	20.9247
1437.15	17.9312
1438.22	15.965
1439.29	24.2736
1440.36	14.159
1441.43	15.2911
1442.49	13.3269
1443.56	12.39
1444.63	15.5459
1445.7	18.7524
1446.77	13.6949
1447.83	10.6882
1448.9	12.8393
1449.97	11.8916
1451.03	12.9784
1452.1	7.92162
1453.17	12.0998
1454.23	14.2376
1455.3	11.2399
1456.36	13.3792
1457.43	19.5849
1458.49	8.38461
1459.56	11.5412
1460.62	4.43813
1461.69	8.5907
1462.75	13.7505
1463.82	6.623
1464.88	12.8786
1465.94	13.8335
1467.01	8.78519
1468.07	7.8251
1469.13	6.86534
1470.2	6.90438
1471.26	7.96642
1472.32	13.0986
1473.39	13.1525
1474.45	10.1378
1475.51	9.18667
1476.57	13.3003
1477.63	8.25004
1478.69	8.2912
1479.76	12.3838
1480.82	10.3601
1481.88	3.29566
1482.94	-0.688234
1484	10.5389
1485.06	5.43364
1486.12	5.47143
1487.18	10.5898
1488.24	11.6274
1489.3	13.6618
1490.36	7.62417
1491.42	8.65794
1492.48	10.7187
1493.53	3.67872
1494.59	7.76203
1495.65	4.754
1496.71	6.77639
1497.77	7.81271
1498.82	2.8013
1499.88	7.89229
1500.94	5.91122
1502	0.884445
1503.05	7.9666
1504.11	9.99544
1505.17	10.0307
1506.22	11.0314
1507.28	9.04906
1508.34	7.06236
1509.39	7.09036
1510.45	15.1854
1511.5	8.12096
1512.56	9.0742
1513.61	13.0692
1514.67	10.1067
1515.72	2.06373
1516.78	10.077
1517.83	9.08832
1518.88	4.10814
1519.94	8.14988
1520.99	3.14699
1522.05	8.18738
1523.1	10.193
1524.15	7.15668
1525.2	13.1637
1526.26	13.1962
1527.31	9.2235
1528.36	6.21506
1529.41	12.2232
1530.47	5.21231
1531.52	9.25451
1532.57	6.25259
1533.62	8.3068
1534.67	13.3369
1535.72	6.30559
1536.77	5.26025
1537.82	10.229
1538.87	6.2112
1539.92	10.2756
1540.97	10.3476
1542.02	3.31087
1543.07	7.28509
1544.12	2.24423
1545.17	8.27067
1546.22	9.31158
1547.27	7.31748
1548.32	9.30098
1549.37	6.27537
1550.42	11.2931
1551.46	10.4108
1552.51	14.4265
1553.56	9.37445
1554.61	12.3501
1555.65	8.30189
1556.7	6.29162
1557.75	7.295
1558.79	10.2627
1559.84	12.2109
1560.89	7.18683
1561.93	9.18708
1562.98	2.20146
1564.02	5.18819
1565.07	8.21202
1566.11	8.96463
1567.16	5.12712
1568.2	11.1446
1569.25	9.14627
1570.29	1.12245
1571.34	11.1059
1572.38	2.08698
1573.43	5.05183
1574.47	2.04333
1575.51	5.0623
1576.56	9.05381
1577.6	10.992
1578.64	6.94453
1579.69	13.9089
1580.73	8.92429
1581.77	9.89119
1582.81	4.87491
1583.85	3.85951
1584.9	9.82518
1585.94	9.81028
1586.98	0.808725
1588.02	7.74791
1589.06	8.74341
1590.1	10.7363
1591.14	8.74283
1592.18	5.73362
1593.22	9.66451
1594.26	4.62486
1595.3	9.58512
1596.34	2.60433
1597.38	13.5205
1598.42	9.53483
1599.46	8.49178
1600.5	4.4829
1601.54	2.44782
1602.58	7.34828
1603.62	6.31095
1604.66	5.29913
1605.69	13.1985
1606.73	5.28982
1607.77	9.18298
1608.81	9.95233
1609.84	13.3902
1610.88	7.14511
1611.92	7.34081
1612.95	8.5746
1613.99	7.79141
1615.03	8.42502
1616.06	10.0259
1617.1	6.45094
1618.13	9.2299
1619.17	7.00654
1620.2	7.02799
1621.24	9.14468
1622.27	7.07562
1623.31	8.95508
1624.34	8.78247
1625.38	6.56343
1626.41	6.54576
1627.45	10.4739
1628.48	8.43684
1629.51	8.93746
1630.55	7.45544
1631.53	8.97781
1632.57	6.02419
1633.62	11.9203
1634.66	2.05967
1635.71	8.9431
1636.75	8.91476
1637.8	12.8201
1638.84	7.87378
1639.89	4.90812
1640.93	5.88552
1641.98	8.82681
1643.02	5.85424
1644.06	9.77371
1645.11	9.74628
1646.15	9.74578
1647.19	8.73649
1648.24	9.69721
1649.28	6.76648
1650.32	11.6763
1651.37	13.6716
1652.41	4.80006
1653.45	10.6939
1654.49	9.70663
1655.53	9.71296
1656.57	4.80687
1657.62	5.78523
1658.66	8.72448
1659.7	7.70875
1660.74	7.69472
1661.78	6.72476
1662.82	7.74267
1663.86	5.76292
1664.9	8.69536
1665.94	9.62728
1666.98	6.70485
1668.02	9.63983
1669.06	5.69236
1670.1	5.70968
1671.14	7.70483
1672.18	7.69244
1673.21	6.70188
1674.25	12.6371
1675.29	10.6759
1676.33	9.69022
1677.37	7.70947
1678.4	9.66654
1679.44	7.66069
1680.48	6.65551
1681.52	8.61581
1682.55	6.63544
1683.59	4.65401
1684.63	7.60573
1685.66	5.62115
1686.7	2.65899
1687.73	6.61507
1688.77	9.56028
1689.81	4.59877
1690.84	3.60231
1691.88	6.57261
1692.91	5.58059
1693.95	10.4761
1694.98	6.50675
1696.01	6.51117
1697.05	-0.378176
1698.08	3.53907
1699.12	8.43822
1700.15	8.43707
1701.18	4.49323
1702.22	6.4443
1703.25	6.42437
1704.28	8.38182
1705.32	10.3556
1706.35	7.40148
1707.38	8.35209
1708.41	6.35375
1709.44	9.25223
1710.48	6.30972
1711.51	6.32394
1712.54	7.30818
1713.57	3.34751
1714.6	2.342
1715.63	6.25269
1716.66	6.25558
1717.69	11.0952
1718.72	4.21861
1719.75	10.0526
1720.78	5.18723
1721.81	5.16385
1722.84	2.22142
1723.87	3.17568
1724.9	6.08353
1725.93	8.95109
1726.96	6.03597
1727.99	6.03179
1729.02	2.10474
1730.05	8.84215
1731.07	8.82703
1732.1	5.9762
1733.13	9.83291
1734.16	7.86104
1735.18	7.82376
1736.21	5.87193
1737.24	6.82571
1738.26	6.81304
1739.29	8.71236
1740.32	11.5428
1741.34	5.75674
1742.37	9.57146
1743.4	5.73918
1744.42	10.514
1745.45	7.64461
1746.47	7.63951
1747.5	6.65545
1748.52	6.6435
1749.55	9.52397
1750.57	9.56208
1751.6	8.63042
1752.62	3.82991
1753.64	5.72112
1754.67	8.56546
1755.69	9.50844
1756.71	7.58058
1757.74	8.50465
1758.76	8.52526
1759.78	11.3928
1760.81	9.48892
1761.83	14.2283
1762.85	11.3827
1763.87	13.2984
1764.89	9.53191
1765.92	9.55778
1766.94	11.4686
1767.96	11.4666
1768.98	8.60611
1770	6.65257
1771.02	9.53012
1772.04	10.5206
1773.06	14.3577
1774.08	11.5299
1775.1	5.8388
1776.12	11.599
1777.14	6.84273
1778.16	12.5467
1779.18	7.76475
1780.2	12.5268
1781.22	7.78979
1782.24	13.5232
1783.26	3.07761
1784.28	8.82318
1785.29	8.85679
1786.31	12.6727
1787.33	4.11197
1788.35	13.7415
1789.37	8.06447
1790.38	9.06326
1791.4	6.19296
1792.42	6.17692
1793.43	9.07045
1794.45	6.21257
1795.47	8.169
1796.48	4.37614
1797.5	4.40924
1798.51	5.3952
1799.53	4.43977
1800.55	8.27098
1801.56	7.30899
1802.58	7.32452
1803.59	5.43441
1804.61	5.45731
1805.62	5.49269
1806.64	8.41698
1807.65	5.54331
1808.66	6.51725
1809.68	8.45811
1810.69	8.47072
1811.7	8.47399
1812.72	5.59455
1813.73	9.47792
1814.74	9.51814
1815.76	8.58662
1816.77	7.63506
1817.78	9.55434
1818.79	9.56734
1819.8	10.5517
1820.82	5.74043
1821.83	10.6008
1822.84	-0.024683
1823.85	8.69364
1824.86	7.73342
1825.87	2.91
1826.88	8.72879
1827.89	7.77618
1828.9	5.84331
1829.91	7.77595
1830.92	7.76814
1831.93	9.72363
1832.94	9.7502
1833.95	3.94887
1834.96	5.87128
1835.97	7.76216
1836.98	5.94883
1837.99	7.7887
1839	7.79035
1840	7.8408
1841.01	9.71312
1842.02	2.89387
1843.03	10.5896
1844.04	7.69916
1845.04	5.77415
1846.05	5.78654
1847.06	6.78633
1848.07	9.56525
1849.07	6.68615
1850.08	3.77742
1851.09	4.7043
1852.09	5.64666
1853.1	6.60692
1854.1	6.59569
1855.11	6.56338
1856.11	2.70192
1857.12	7.48785
1858.12	9.39134
1859.13	6.49333
1860.13	9.33942
1861.14	7.44215
1862.14	4.58978
1863.15	3.61368
1864.15	4.54332
1865.15	7.38493
1866.16	11.1568
1867.16	7.28602
1868.16	3.44049
1869.17	10.0912
1870.17	2.47919
1871.17	4.37394
1872.17	4.3612
1873.18	3.39172
1874.18	9.07273
1875.18	8.09053
1876.18	3.30448
1877.18	7.0547
1878.18	7.94963
1879.19	5.16463
1880.19	7.08023
1881.19	5.17986
1882.19	4.18602
1883.19	7.89337
1884.19	3.14188
1885.19	9.75317
1886.19	8.85076
1887.19	6.01031
1888.19	6.91866
1889.19	6.87032
1890.19	6.84742
1891.19	5.92119
1892.18	4.02613
1893.18	4.00792
1894.18	6.77679
1895.18	2.99874
1896.18	8.64119
1897.18	4.8968
1898.17	4.89927
1899.17	8.63598
1900.17	3.90895
1901.16	10.4782
1902.16	6.73926
1903.16	6.74517
1904.16	2.96521
1905.15	5.77387
1906.15	8.57372
1907.14	7.60335
1908.14	9.47892
1909.14	9.48705
1910.13	8.57152
1911.13	9.54768
1912.12	6.72436
1913.12	3.88569
1914.11	5.77661
1915.11	6.74273
1916.1	3.91597
1917.1	5.77925
1918.09	6.69803
1919.08	8.59766
1920.08	10.5266
1921.07	4.85545
1922.06	10.5457
1923.06	5.80378
1924.05	7.67177
1925.04	7.64627
1926.04	4.82391
1927.03	5.7957
1928.02	4.85903
1929.01	4.86252
1930	7.72316
1931	8.69894
1931.99	7.73619
1932.98	3.91194
1933.97	5.80477
1934.96	8.74162
1935.95	6.89997
1936.94	6.85813
1937.93	8.7232
1938.92	5.85482
1939.91	6.81504
1940.9	7.78055
1941.89	6.84671
1942.88	8.75933
1943.87	3.00386
1944.86	8.7423
1945.85	6.85384
1946.84	3.03951
1947.83	5.89266
1948.82	8.74598
1949.8	3.01664
1950.79	7.83686
1951.78	4.03957
1952.77	7.89463
1953.76	8.84789
1954.74	3.96955
1955.73	7.77463
1956.72	6.86116
1957.7	6.88098
1958.69	12.6532
1959.68	8.78563
1960.66	9.7167
1961.65	2.00225
1962.63	8.70967
1963.62	3.9039
1964.61	6.78259
1965.59	6.76704
1966.58	12.5375
1967.56	8.69959
1968.55	7.73278
1969.53	7.70263
1970.52	7.65312
1971.5	12.4178
1972.48	10.4872
1973.47	10.4675
1974.45	8.51548
1975.44	10.4239
1976.42	7.55387
1977.4	14.2593
1978.39	10.3921
1979.37	11.3273
1980.35	10.3605
1981.33	7.45489
1982.31	15.093
1983.3	5.48433
1984.28	13.103
1985.26	8.2926
1986.24	10.1814
1987.22	12.0951
1988.21	8.23345
1989.19	11.0294
1990.17	10.7368
1991.15	9.42667
1992.13	13.1919
1993.11	7.72953
1994.09	13.576
1995.07	14.8821
1996.05	11.4558
1997.03	11.8295
1998.01	15.0025
1998.99	14.4986
1999.97	11.8593
2000.95	15.0174
2001.92	13.8769
2002.9	13.6778
2003.88	17.6823
2004.86	13.0754
2005.84	12.0867
2006.81	16.0335
2007.79	15.7517
2008.77	17.9835
2009.75	13.9285
2010.73	12.2541
2011.7	10.242
2012.68	7.93473
2013.67	10.7167
2014.66	8.77873
2015.64	15.332
2016.63	13.468
2017.62	12.5504
2018.61	8.74442
2019.6	8.69228
2020.58	11.4849
2021.57	8.67323
2022.56	13.3433
2023.55	12.3702
2024.54	13.2712
2025.52	10.4187
2026.51	10.3879
2027.5	8.60605
2028.48	12.3024
2029.47	9.55126
2030.45	12.2449
2031.44	10.3929
2032.43	12.2638
2033.41	15.1127
2034.4	9.5077
2035.38	4.78817
2036.37	8.5901
2037.35	10.4492
2038.34	8.56851
2039.32	7.61271
2040.31	10.3848
2041.29	9.41715
2042.27	8.46878
2043.26	9.38603
2044.24	6.62626
2045.23	7.53974
2046.21	6.67045
2047.19	5.70798
2048.17	8.46623
2049.16	5.67712
2050.14	8.51103
2051.12	5.7332
2052.11	2.91493
2053.09	4.79219
2054.07	7.62932
2055.05	6.70476
2056.03	6.6904
2057.01	2.94219
2058	6.6891
2058.98	8.58524
2059.96	9.53802
2060.94	5.78317
2061.92	9.5414
2062.9	9.5504
2063.88	3.01291
2064.86	3.96222
2065.84	10.5595
2066.82	4.94839
2067.8	4.96263
2068.78	5.91777
2069.76	5.91126
2070.73	3.0912
2071.71	5.93143
2072.69	10.6837
2073.67	7.8551
2074.65	5.98155
2075.63	7.90696
2076.6	5.11237
2077.58	4.15634
2078.56	6.03836
2079.54	6.05751
2080.51	6.09022
2081.49	7.03656
2082.47	5.14924
2083.45	5.15569
2084.42	8.93604
2085.4	4.21507
2086.37	12.735
2087.35	9.92815
2088.32	6.15518
2089.3	4.27005
2090.28	6.18681
2091.25	7.14717
2092.23	8.12247
2093.2	6.26702
2094.18	5.34864
2095.15	8.20958
2096.13	4.39359
2097.1	4.389
2098.07	5.32381
2099.05	4.37052
2100.02	6.26739
2101	7.22565
2101.97	3.44926
2102.94	6.29953
2103.92	4.38875
2104.89	6.29661
2105.86	4.42048
2106.83	10.1404
2107.8	4.44154
2108.78	7.26563
2109.75	4.41973
2110.72	7.27902
2111.69	5.37995
2112.66	7.27344
2113.63	4.44384
2114.61	6.35211
2115.58	5.40477
2116.55	5.39468
2117.52	8.23547
2118.49	5.37852
2119.46	9.14542
2120.43	4.38593
2121.4	4.39562
2122.37	8.21889
2123.34	3.4946
2124.31	4.44487
2125.28	6.30673
2126.25	6.26773
2127.21	4.35179
2128.18	5.28839
2129.15	6.23166
2130.12	7.17235
2131.09	2.4422
2132.06	7.1511
2133.02	7.13519
2133.99	6.19306
2134.96	5.25355
2135.93	4.30625
2136.89	3.33977
2137.86	0.519112
2138.83	7.11048
2139.79	6.17727
2140.76	8.98031
2141.73	2.38148
2142.69	4.25245
2143.66	3.33393
2144.62	6.10257
2145.59	-0.475863
2146.55	7.04203
2147.52	7.97075
2148.48	6.07837
2149.45	6.06148
2150.42	2.27764
2151.38	3.20983
2152.34	1.34857
2153.31	0.403578
2154.27	-0.545082
2155.24	2.22998
2156.2	7.80296
2157.16	4.05536
2158.13	4.06701
2159.09	5.94095
2160.05	1.25324
2161.01	4.96352
2161.98	4.02037
2162.94	6.8175
2163.9	3.07396
2164.86	6.78199
2165.83	3.05388
2166.79	3.04794
2167.75	2.09663
2168.71	2.05988
2169.67	6.71879
2170.63	6.75577
2171.59	5.81549
2172.56	2.04722
2173.51	5.75301
2174.48	7.61855
2175.44	3.90044
2176.4	8.53867
2177.36	6.66923
2178.32	2.02422
2179.28	6.64899
2180.23	3.86332
2181.19	3.85641
2182.15	2.9169
2183.11	3.83206
2184.07	4.73063
2185.03	6.57188
2185.99	6.58039
2186.95	5.67438
2187.9	3.84636
2188.86	1.97474
2189.82	0.0891781
2190.78	2.85633
2191.73	6.56763
2192.69	3.79173
2193.65	8.445
2194.6	3.84087
2195.56	4.76355
2196.52	2.87356
2197.47	3.77202
2198.43	1.91207
2199.38	0.079319
2200.34	7.54971
2201.3	2.94019
2202.25	7.48964
2203.21	5.67829
2204.16	3.91248
2205.12	6.65241
2206.07	5.64428
2207.03	2.84741
2207.98	4.71843
2208.93	3.80515
2209.89	2.87691
2210.84	4.74172
2211.8	3.82209
2212.75	3.83434
2213.7	0.0865307
2214.66	9.42153
2215.61	-0.832388
2216.56	1.96356
2217.51	6.62193
2218.47	3.8166
2219.42	0.0863552
2220.37	1.9614
2221.32	4.75257
2222.27	3.78578
2223.23	5.64791
2224.18	2.86267
2225.13	3.81973
2226.08	1.96681
2227.03	2.91753
2227.98	2.92491
2228.93	1.97349
2229.88	4.78058
2230.83	3.86002
2231.78	5.75631
2232.73	6.71254
2233.68	3.90528
2234.63	5.7911
2235.58	3.88046
2236.53	7.63087
2237.48	4.81307
2238.43	4.84583
2239.38	1.09969
2240.33	4.85296
2241.27	3.91479
2242.22	4.85842
2243.17	4.8607
2244.12	2.0103
2245.07	7.67929
2246.01	2.0381
2246.96	2.04833
2247.91	2.05245
2248.85	5.82502
2249.8	7.71078
2250.75	2.01955
2251.69	0.100763
2252.64	2.93632
2253.59	3.91519
2254.53	1.08937
2255.48	5.82536
2256.42	2.03209
2257.37	6.78858
2258.32	-0.800322
2259.26	4.90035
2260.2	3.95592
2261.15	1.10909
2262.1	3.02134
2263.04	2.07671
2263.98	2.10017
2264.93	3.08535
2265.87	3.09686
2266.81	6.89594
2267.76	1.14092
2268.7	3.02596
2269.65	4.94582
2270.59	2.11037
2271.53	4.99162
2272.47	3.0891
2273.42	0.217861
2274.36	5.0029
2275.3	2.13221
2276.24	2.13322
2277.18	2.15226
2278.13	1.22262
2279.07	6.03714
2280.01	2.17108
2280.95	6.93442
2281.89	3.08179
2282.83	7.88685
2283.77	6.96003
2284.71	6.04586
2285.65	4.13745
2286.59	4.11693
2287.54	4.14509
2288.47	6.08195
2289.41	7.01765
2290.35	6.97476
2291.29	5.05147
2292.23	3.15371
2293.17	8.95445
2294.11	3.18615
2295.05	6.05947
2295.99	5.07787
2296.93	5.05224
2297.86	5.06995
2298.8	1.24347
2299.74	6.08729
2300.68	4.15947
2301.61	9.96541
2302.55	3.20815
2303.49	3.20474
2304.43	0.31642
2305.36	2.2638
2306.3	-0.624678
2307.24	5.17962
2308.17	1.30591
2309.11	4.20216
2310.04	3.26206
2310.98	0.370197
2311.92	3.23092
2312.85	5.13708
2313.79	5.14747
2314.72	7.12125
2315.66	4.24194
2316.59	6.14016
2317.52	9.02777
2318.46	6.13895
2319.39	5.15776
2320.33	2.25659
2321.26	8.0584
2322.2	7.124
2323.13	7.14776
2324.06	12.9613
2325	14.8875
2325.93	27.4016
2326.86	50.5187
2327.79	183.504
2328.73	323.224
2329.66	89.9015
2330.59	35.9592
2331.52	19.5832
2332.46	6.1133
2333.39	8.02462
2334.32	8.97629
2335.25	8.95805
2336.18	4.15461
2337.11	7.99813
2338.04	3.18909
2338.97	7.03272
2339.91	3.19323
2340.84	2.22174
2341.77	0.274731
2342.7	1.21796
2343.63	7.92741
2344.56	4.09656
2345.49	3.13693
2346.41	3.11831
2347.34	5.9865
2348.27	3.11651
2349.2	2.16432
2350.13	5.95074
2351.06	5.80887
2351.99	7.84237
2352.91	5.88685
2353.84	1.08062
2354.77	2.03446
2355.7	4.89401
2356.63	3.92067
2357.55	2.93382
2358.48	4.81763
2359.41	2.90182
2360.33	3.83286
2361.26	4.75157
2362.19	4.718
2363.11	1.84453
2364.04	5.60856
2364.97	-0.0887623