File: Data/3-Raman/processed/bu19w-e-ff11-fi10-v_150 (500nm)_633nm_edge_100%_x100_vis_h50um_30sx2_01_0.txt
#Acq. time (s)=	30
#Accumulations=	2
#Range (cm-¹)=	100...4000
#Windows=	1
#Auto scanning=	Off
#Autofocus=	Off
#Macrospot=	Off
#AutoExposure=	Off
#Spike filter=	Multiple accum.
#Delay time (s)=	2
#Binning=	1
#Readout mode=	Signal
#DeNoise=	Off
#ICS correction=	On
#Dark correction=	Off
#Inst. Process=	Off
#Detector Gain=	Best Dynamic
#Detector ADC=	50 kHz HS
#Detector temperature (°C)=	-60.09
#Instrument=	LabRAM HR Evol
#Detector=	SIN-EM FIVIS
#Objective=	x100_VIS
#Grating=	150 (500nm)
#ND Filter=	100%
#Laser=	633nm_Edge
#Hole=	49.98
#Temperature=	0
#Range=	Visible
#StageXY=	75x50mm Scan+
#StageZ=	Z motor
#X (µm)=	0
#Y (µm)=	0
#Z (µm)=	-270.9
#Full time(mm:ss)=	1:04
#Project=	21_11_04
#Sample=	BU19w
#Site=
#Title=	BU19w-E-FF11-FI10-V_150 (500nm)_633nm_Edge_100%_x100_VIS_H50um_30sX2
#Remark=
#Date=	04.11.2021 11:51
#Acquired=	04.11.2021 11:51:31
#Base:Fit=	16.12.2021 17:39:50
#Base:Edit=	16.12.2021 17:54:49
#Base:Edit=	16.12.2021 17:54:49
#Base:Edit=	16.12.2021 17:54:49
#Base:Edit=	16.12.2021 17:54:50
#Base:Edit=	16.12.2021 17:54:50
#Base:Edit=	16.12.2021 17:54:50
#Base:Edit=	16.12.2021 17:54:50
#Base:Edit=	16.12.2021 17:54:51
#Base:Edit=	16.12.2021 17:54:52
#Base:Edit=	16.12.2021 17:54:52
#Base:Edit=	16.12.2021 17:54:52
#Base:Edit=	16.12.2021 17:54:53
#Base:Edit=	16.12.2021 17:54:53
#Base:Edit=	16.12.2021 17:54:54
#Peaks:Remove=	16.12.2021 17:54:56
#Peaks:Remove=	16.12.2021 17:54:59
#Base:Sub=	16.12.2021 17:55:05
102.881	46.6759
109.397	38.9623
115.908	30.2022
122.414	21.3211
128.914	13.305
135.409	12.84
141.898	19.934
148.383	22.2019
154.861	16.7744
161.335	28.5425
167.801	29.7197
174.264	26.0094
180.721	7.82013
187.173	4.87183
193.62	-0.0575333
200.061	0.743698
206.496	0.6269
212.926	1.40694
219.352	4.05998
225.772	9.51173
232.185	30.0886
238.595	50.6263
244.999	34.1032
251.397	15.6797
257.791	12.4214
264.178	16.7475
270.561	14.4245
276.939	13.0419
283.31	24.8939
289.678	29.109
296.039	12.4414
302.396	13.7584
308.746	14.1026
315.093	18.216
321.433	36.4824
327.768	78.333
334.099	65.4635
340.423	28.0596
346.743	17.9905
353.058	21.0949
359.367	24.1585
365.671	16.8518
371.971	17.0678
378.265	8.82433
384.553	5.29606
390.837	10.2875
397.116	6.88752
403.389	1.63948
409.657	4.84143
415.92	0.450485
422.178	7.37879
428.431	13.222
434.678	21.7772
440.921	18.989
447.158	22.7605
453.391	26.4902
459.618	19.0452
465.84	28.4826
472.057	8.13572
478.27	3.69102
484.477	10.4224
490.679	7.83576
496.876	10.8449
503.068	8.27044
509.255	18.7605
515.436	16.2108
521.613	24.916
527.785	20.5761
533.952	29.4111
540.113	18.5111
546.27	20.7116
552.423	11.5155
558.568	11.7208
564.711	13.708
570.848	13.745
576.979	6.22294
583.107	9.04077
589.228	10.0189
595.345	7.33435
601.458	14.0561
607.565	15.2706
613.667	23.0712
619.764	28.1567
625.856	13.5457
631.944	16.6805
638.026	11.2133
644.104	16.0146
650.177	5.75004
656.244	9.54496
662.308	1.14817
668.365	6.80177
674.418	4.1512
680.467	6.19528
686.511	-0.113403
692.549	4.83467
698.582	2.31828
704.611	1.65644
710.635	0.957615
716.655	3.91685
722.669	-0.6357
728.679	7.91327
734.683	2.36802
740.683	0.580898
746.678	3.47874
752.669	-0.127811
758.654	4.697
764.635	4.96124
770.611	11.8269
776.582	6.51353
782.549	0.187592
788.511	5.11666
794.466	8.13911
800.419	4.5149
806.366	2.73834
812.309	7.52858
818.247	6.63119
824.18	-0.83527
830.108	2.95287
836.033	9.6272
841.952	7.0431
847.865	6.33812
853.776	0.955788
859.681	11.5725
865.58	6.1923
871.476	9.29072
877.366	14.2323
883.253	11.5558
889.134	14.5282
895.012	18.4119
900.883	19.3726
906.751	16.508
912.614	11.7596
918.473	13.6423
924.326	11.8382
930.174	13.8686
936.019	15.9571
941.859	20.0439
947.693	24.1797
953.525	33.1075
959.35	39.1808
965.171	36.599
970.988	43.5476
976.801	43.6894
982.608	69.5885
988.411	91.524
994.209	76.0733
1000	67.3785
1005.79	46.3707
1011.58	48.37
1017.36	49.4815
1023.13	50.6353
1028.9	49.0052
1034.67	37.7857
1040.43	31.3449
1046.19	26.7957
1051.94	28.9534
1057.69	27.1881
1063.44	25.3503
1069.17	14.6927
1074.91	20.5422
1080.64	23.4432
1086.37	34.0841
1092.09	37.9544
1097.8	46.6519
1103.52	65.9913
1109.22	51.5597
1114.93	39.1777
1120.63	33.6177
1126.32	27.9548
1132.01	26.1933
1137.7	33.2378
1143.38	34.4126
1149.06	40.4434
1154.73	62.1782
1160.4	55.2479
1166.06	24.6285
1171.72	20.5938
1177.38	9.71199
1183.03	18.4287
1188.67	11.5783
1194.31	12.5887
1199.95	6.80205
1205.58	11.8556
1211.21	7.11322
1216.84	9.28627
1222.46	5.53086
1228.07	-0.260712
1233.68	1.89904
1239.29	4.03867
1244.89	12.1863
1250.49	5.14617
1256.08	2.1029
1261.67	9.09988
1267.26	3.97169
1272.84	4.87334
1278.42	10.7715
1283.99	52.7114
1289.56	7.53338
1295.12	2.46818
1300.68	-0.566475
1306.23	6.44077
1311.78	5.51509
1317.33	5.62417
1322.87	2.72169
1328.41	5.89574
1333.94	3.99957
1339.47	4.1076
1345	4.17171
1350.52	2.16415
1356.04	8.34528
1361.55	-0.907402
1367.06	4.18742
1372.56	10.2888
1378.06	6.11524
1383.56	33.7614
1389.05	32.6507
1394.53	7.98387
1400.02	4.92308
1405.5	9.05485
1410.97	8.06071
1416.44	-0.152809
1421.91	2.99525
1427.37	8.24453
1432.83	-0.00984192
1438.28	7.34391
1443.73	8.45485
1449.17	3.26011
1454.62	5.35353
1460.05	3.21636
1465.48	4.20452
1470.91	3.08315
1476.34	1.9725
1481.76	1.93122
1487.17	6.10736
1492.59	4.00351
1497.99	6.13216
1503.4	8.2854
1508.8	5.17365
1514.19	3.124
1519.59	1.07864
1524.97	3.30454
1530.36	3.40114
1535.74	4.58577
1541.11	6.81422
1546.48	-1.82385
1551.85	7.85008
1557.21	3.40284
1562.57	1.13498
1567.93	5.33881
1573.28	6.30155
1578.62	5.13798
1583.97	1.84923
1589.3	6.11137
1594.64	6.08942
1599.97	10.4083
1605.3	8.28012
1610.62	4.01313
1615.94	4.11124
1621.25	6.41326
1626.56	4.34404
1631.87	0.0528336
1637.17	2.32054
1642.47	6.73314
1647.76	8.95753
1653.05	7.84378
1658.34	5.59308
1663.62	9.9779
1668.9	11.0254
1674.18	6.52376
1679.45	6.44843
1684.71	6.34586
1689.98	6.23708
1695.23	6.15975
1700.49	6.15473
1705.74	-1.45786
1710.99	8.57084
1716.23	6.29224
1721.47	7.48785
1726.7	9.7447
1731.94	3.05132
1737.16	4.20226
1742.39	5.35443
1747.61	7.63311
1752.82	7.6314
1758.03	4.21095
1763.24	5.28938
1768.44	6.37616
1773.64	8.60528
1778.84	9.72612
1784.03	5.19402
1789.22	8.63865
1794.41	1.8401
1799.59	0.744007
1804.76	5.38895
1809.94	5.438
1815.11	11.2369
1820.27	12.441
1825.43	9.02431
1830.59	7.91833
1835.74	4.48771
1840.89	10.3432
1846.04	8.03029
1851.18	9.21079
1856.32	1.00473
1861.45	4.53191
1866.58	3.38253
1871.71	5.74722
1876.83	2.19873
1881.95	2.17608
1887.07	10.4154
1892.18	2.06993
1897.29	6.72292
1902.39	5.51106
1907.49	4.34196
1912.59	6.77975
1917.68	3.28951
1922.77	2.06437
1927.86	9.25427
1932.94	3.27817
1938.02	-0.330585
1943.09	5.65489
1948.16	4.41426
1953.23	0.738766
1958.29	4.2769
1963.35	10.2173
1968.41	7.70323
1973.46	3.96227
1978.51	7.44731
1983.55	3.70713
1988.59	4.78635
1993.63	7.07278
1998.66	6.96542
2003.69	10.4799
2008.72	1.98792
2013.74	5.53634
2018.76	7.87643
2023.77	5.40348
2028.78	6.57406
2033.79	6.56476
2038.79	7.77309
2043.79	4.13436
2048.79	6.57346
2053.78	2.90053
2058.77	2.89355
2063.76	11.4655
2068.74	9.02976
2073.72	4.11638
2078.69	11.4967
2083.66	11.4826
2088.63	8.96953
2093.59	8.94997
2098.55	6.4779
2103.51	6.49054
2108.46	6.51627
2113.41	17.818
2118.36	16.6465
2123.3	9.16664
2128.24	7.94415
2133.17	0.369186
2138.11	5.42897
2143.03	6.6868
2147.96	10.4776
2152.88	15.5257
2157.79	2.68417
2162.71	8.96921
2167.62	12.6773
2172.52	4.89063
2177.43	4.78128
2182.32	3.35757
2187.22	8.31701
2192.11	6.904
2197	6.79189
2201.89	6.71254
2206.77	2.80074
2211.64	2.75877
2216.52	9.18378
2221.39	4.00612
2226.26	7.88388
2231.12	9.17865
2235.98	5.26226
2240.84	9.16723
2245.69	7.85245
2250.54	2.58628
2255.39	5.19094
2260.23	7.81717
2265.07	10.4331
2269.9	5.07213
2274.74	6.30785
2279.57	-0.450928
2284.39	0.729267
2289.21	7.21397
2294.03	5.7138
2298.84	14.8834
2303.66	5.43898
2308.46	5.35373
2313.27	9.3094
2318.07	9.28582
2322.87	3.88593
2327.66	6.55811
2332.45	5.20096
2337.24	13.3415
2342.02	-2.94473
2346.8	-0.206192
2351.58	1.17285
2356.35	10.7792
2361.12	-0.281033
2365.89	-0.354103
2370.65	6.48849
2375.41	-3.28391
2380.17	-8.94064
2384.92	-2.13317
2389.67	0.490009
2394.42	5.8721
2399.16	11.2306
2403.9	1.2724
2408.64	-1.71595
2413.37	5.15056
2418.1	-3.14311
2422.83	5.2697
2427.55	5.16745
2432.27	-0.514084
2436.99	0.874966
2441.7	3.69326
2446.41	-4.86575
2451.11	9.38145
2455.82	6.51292
2460.51	10.8132
2465.21	5.04904
2469.9	0.684235
2474.59	-2.26437
2479.28	2.04098
2483.96	6.35361
2488.64	0.45005
2493.32	0.364815
2497.99	6.14387
2502.66	4.59341
2507.32	-4.32614
2511.99	-7.40018
2516.65	-3.12359
2521.3	14.4717
2525.96	5.50669
2530.61	2.43658
2535.25	2.34347
2539.89	2.26379
2544.53	2.19014
2549.17	2.12897
2553.8	6.55389
2558.43	-8.51542
2563.06	-10.1053
2567.68	4.88211
2572.3	0.331764
2576.92	0.288208
2581.53	-1.30036
2586.14	-1.42081
2590.75	-1.58022
2595.35	7.41631
2599.96	2.7543
2604.55	2.63497
2609.15	-3.60516
2613.74	5.40839
2618.33	0.672691
2622.91	0.526619
2627.49	0.398613
2632.07	-8.89381
2636.64	3.38226
2641.22	-1.21933
2645.78	-1.18913
2650.35	-5.83563
2654.91	1.9397
2659.47	3.43304
2664.03	1.77969
2668.58	0.119881
2673.13	0.0768814
2677.67	4.87843
2682.22	8.24468
2686.76	-1.11354
2691.29	-5.78868
2695.83	0.605461
2700.36	2.18023
2704.89	0.540825
2709.41	-7.55948
2713.93	-2.7823
2718.45	11.7494
2722.96	-7.70911
2727.47	0.316887
2731.98	-1.41377
2736.49	0.0969849
2740.99	9.74647
2745.49	3.17197
2749.98	-3.38194
2754.47	1.58024
2758.96	-0.0747223
2763.45	6.44669
2767.93	-3.41642
2772.41	1.50824
2776.89	-13.3235
2781.36	-1.67632
2785.84	5.08289
2790.3	-1.46632
2794.77	-1.37526
2799.23	-4.67117
2803.69	5.45163
2808.14	-2.94678
2812.59	-8.01197
2817.04	-1.27885
2821.49	5.48412
2825.93	0.406998
2830.37	-1.29481
2834.81	-3.01157
2839.24	5.49464
2843.67	-3.03324
2848.1	-6.43345
2852.53	-2.96749
2856.95	-2.8867
2861.37	0.646736
2865.78	-6.12382
2870.19	-0.796753
2874.6	4.562
2879.01	-0.492058
2883.41	-2.05731
2887.81	5.15685
2892.21	0.0714798
2896.6	7.34069
2901	2.2613
2905.38	11.3431
2909.77	0.824547
2914.15	6.30635
2918.53	-0.742126
2922.91	2.98497
2927.28	10.3681
2931.65	-5.70047
2936.02	7.11886
2940.38	-0.0346527
2944.74	5.51752
2949.1	-5.35104
2953.46	2.01055
2957.81	0.251778
2962.16	-6.99372
2966.5	4.08746
2970.85	0.531425
2975.19	8.01152
2979.52	6.30363
2983.86	-0.922356
2988.19	4.81487
2992.52	6.89162
2996.85	8.99007
3001.17	1.78584
3005.49	0.181107
3009.8	-5.1997
3014.12	6.35597
3018.43	8.56213
3022.74	6.97971
3027.04	-0.383446
3031.34	-2.08549
3035.64	7.66003
3039.94	11.6806
3044.23	8.02931
3048.52	6.27279
3052.81	12.2245
3057.09	-14.6422
3061.38	0.986427
3065.65	3.09543
3069.93	3.26984
3074.2	11.2362
3078.47	15.3415
3082.74	13.6015
3087	9.93766
3091.27	8.26493
3095.52	18.44
3099.78	18.8118
3104.03	21.1918
3108.28	15.6571
3112.53	8.10314
3116.77	14.5266
3121.01	19.003
3125.25	13.4301
3129.49	11.8997
3133.72	12.4241
3137.95	33.4612
3142.18	19.6107
3146.4	26.3001
3150.62	20.5436
3154.84	18.8463
3159.06	23.3943
3163.27	19.5905
3167.48	34.6529
3171.69	13.9736
3175.89	33.2889
3180.09	39.913
3184.29	27.4482
3188.49	21.2787
3192.68	30.0153
3196.87	28.1927
3201.06	37.1757
3205.24	37.6877
3209.42	25.3441
3213.6	38.8387
3217.78	30.771
3221.95	44.3828
3226.12	36.2325
3230.29	38.9811
3234.45	37.3213
3238.61	31.2078
3242.77	25.096
3246.93	30.1003
3251.08	28.3361
3255.23	33.2052
3259.38	26.8643
3263.53	22.8164
3267.67	32.5201
3271.81	28.5228
3275.95	38.0433
3280.08	31.5213
3284.21	38.7311
3288.34	27.5767
3292.47	27.8777
3296.59	30.4724
3300.71	33.1093
3304.83	19.5341
3308.95	29.1076
3313.06	31.7182
3317.17	34.3514
3321.27	30.0207
3325.38	28.0479
3329.48	37.8131
3333.58	35.9684
3337.67	41.1936
3341.77	29.7566
3345.86	37.1935
3349.95	35.1061
3354.03	40.1578
3358.11	28.5818
3362.19	43.267
3366.27	43.6132
3370.34	41.56
3374.42	32.2401
3378.48	46.9497
3382.55	32.7234
3386.61	47.4433
3390.68	35.5671
3394.73	43.0432
3398.79	45.7252
3402.84	41.0874
3406.89	41.2737
3410.94	56.0412
3414.98	31.8683
3419.03	44.2062
3423.06	46.7927
3427.1	46.9593
3431.14	39.834
3435.17	37.6107
3439.2	42.763
3443.22	47.9507
3447.25	50.7625
3451.27	48.6603
3455.28	39.1671
3459.3	37.1172
3463.31	52.5054
3467.32	42.9952
3471.33	40.9187
3475.34	28.6816
3479.34	41.6441
3483.34	47.0777
3487.33	39.8347
3491.33	42.7143
3495.32	35.3736
3499.31	40.7436
3503.3	40.9662
3507.28	38.5845
3511.26	30.9797
3515.24	38.755
3519.22	25.9648
3523.19	38.876
3527.16	44.1023
3531.13	28.7175
3535.1	31.4605
3539.06	31.6898
3543.02	21.5149
3546.98	26.8402
3550.93	21.7395
3554.89	26.9413
3558.84	27.0103
3562.78	40.1405
3566.73	37.6855
3570.67	30.0364
3574.61	32.8319
3578.55	33.0514
3582.48	28.0332
3586.41	22.9906
3590.35	15.2556
3594.27	28.7491
3598.2	44.9791
3602.12	37.1857
3606.04	26.654
3609.95	10.6671
3613.87	32.2991
3617.78	21.6255
3621.69	16.2693
3625.6	21.6425
3629.5	16.1895
3633.4	10.7037
3637.3	26.9088
3641.2	21.5263
3645.09	10.7349
3648.98	21.6296
3652.87	21.6135
3656.76	2.49511
3660.64	10.6233
3664.53	21.4839
3668.4	10.5203
3672.28	13.207
3676.16	10.4645
3680.03	5.00451
3683.9	-0.443039
3687.76	7.91029
3691.63	16.315
3695.49	8.08196
3699.35	8.16807
3703.2	11.0317
3707.06	5.53647
3710.91	5.61726
3714.76	14.1194
3718.6	11.3513
3722.45	8.55222
3726.29	11.3793
3730.13	0.0448532
3733.97	5.71988
3737.8	14.2574
3741.63	14.259
3745.46	11.3963
3749.29	5.64719
3753.11	2.71934
3756.93	-0.237267
3760.75	-3.21516
3764.57	10.9946
3768.39	5.15729
3772.2	5.07899
3776.01	7.87729
3779.81	2.07822
3783.62	-0.82235
3787.42	7.81367
3791.22	-3.75532
3795.02	4.92332
3798.81	4.96709
3802.61	7.92975
3806.4	5.10256
3810.18	5.18512
3813.97	8.17745
3817.75	-6.39792
3821.53	-0.484314
3825.31	8.37412
3829.09	2.54636
3832.86	2.62772
3836.63	-3.20657
3840.4	5.73448
3844.17	5.84727
3847.93	2.90041
3851.69	-5.99574
3855.45	-0.0504227
3859.21	-0.0707932
3862.96	8.86216
3866.71	0.0809555
3870.46	3.27166
3874.21	0.348175
3877.95	9.39692
3881.69	3.51785
3885.44	-8.32931
3889.17	-17.1754
3892.91	-5.00678
3896.64	1.2454
3900.37	-4.53235
3904.1	-10.3192
3907.82	-1.01653
3911.55	-0.7257
3915.27	5.65419
3918.99	-0.0354309
3922.7	0.382088
3926.42	6.904
3930.13	10.3987
3933.84	1.64131
3937.54	11.2514
3941.25	8.65858
3944.95	6.10401
3948.65	0.460884
3952.35	-2.12
3956.04	1.4841
3959.73	8.1872
3963.42	2.52071
3967.11	-0.0495453
3970.8	25.2792
3974.48	13.4555
3978.16	-1.45616
3981.84	11.5468
3985.52	15.2749
3989.19	3.53003
3992.86	7.35505
3996.53	-1.17025
3998.37	11.6659