File: Data/3-Raman/processed/bu19w-e-ff11b-fi06-v_150 (500nm)_532nm_edge_100%_x100_vis_h50um_30sx2_01_0.txt
#Acq. time (s)=	30
#Accumulations=	2
#Range (cm-¹)=	100...5000
#Windows=	1
#Auto scanning=	Off
#Autofocus=	Off
#Macrospot=	Off
#AutoExposure=	Off
#Spike filter=	Multiple accum.
#Delay time (s)=	2
#Binning=	1
#Readout mode=	Signal
#DeNoise=	Off
#ICS correction=	On
#Dark correction=	Off
#Inst. Process=	Off
#Detector Gain=	Best Dynamic
#Detector ADC=	50 kHz HS
#Detector temperature (°C)=	-60.09
#Instrument=	LabRAM HR Evol
#Detector=	SIN-EM FIVIS
#Objective=	x100_VIS
#Grating=	150 (500nm)
#ND Filter=	100%
#Laser=	532nm_Edge
#Hole=	49.98
#Temperature=	0
#Range=	Visible
#StageXY=	75x50mm Scan+
#StageZ=	Z motor
#X (µm)=	0
#Y (µm)=	0
#Z (µm)=	-245.5
#Full time(mm:ss)=	1:05
#Project=	21_11_04
#Sample=	BU19w
#Site=
#Title=	BU19w-E-FF11b-FI06-V_150 (500nm)_532nm_Edge_100%_x100_VIS_H50um_30sX2
#Remark=
#Date=	04.11.2021 18:14
#Acquired=	04.11.2021 18:14:36
#Base:Fit=	16.12.2021 17:39:50
#Base:Sub=	16.12.2021 17:47:27
101.869	5775.56
106.493	5321.64
111.113	5810.03
115.732	7938.16
120.349	9280.76
124.964	6840.08
129.577	4698.83
134.185	3866.14
138.793	3609.31
143.399	3275.58
148.003	2956.7
152.602	2849.11
157.201	2751.58
161.798	2777.82
166.392	2967.79
170.982	3315.13
175.572	3749.03
180.16	4764.97
184.745	6223.25
189.326	8503.04
193.907	10422.8
198.486	11033
203.06	9938.32
207.634	7637.42
212.206	5613.87
216.776	4102.34
221.341	3050.06
225.906	2386.97
230.469	1919.58
235.028	1601.81
239.586	1394.52
244.142	1238.76
248.694	1432.19
253.246	2071.23
257.795	2116.89
262.341	1207.35
266.886	632.703
271.428	455.045
275.967	335.118
280.505	246.213
285.041	218.732
289.573	146.147
294.105	96.1391
298.632	109.647
303.159	67.6052
307.685	62.0993
312.205	20.3161
316.726	21.0319
321.242	-0.00012207
325.758	11.7474
330.272	33.2799
334.782	20.5195
339.292	252.359
343.797	1099.73
348.302	1331.63
352.803	586.027
357.304	188.269
361.802	68.3907
366.297	33.7747
370.791	36.1501
375.281	25.4116
379.77	149.69
384.256	355.523
388.741	531.846
393.223	517.606
397.704	356.937
402.18	145.617
406.657	100.097
411.13	105.988
415.602	171.577
420.07	202.03
424.538	292.487
429.002	483.84
433.465	828.563
437.925	1652.09
442.384	3278.33
446.839	7527.69
451.294	19110.5
455.745	31464.7
460.196	25542.5
464.642	12438.5
469.089	5881.73
473.531	3330.87
477.971	2234.66
482.411	1624.69
486.846	1188.58
491.282	923.007
495.713	799.543
500.144	755.152
504.572	644.68
508.997	554.466
513.421	431.976
517.842	348.974
522.263	319.549
526.679	284.749
531.093	181.94
535.507	155.685
539.917	166.567
544.327	90.5676
548.733	50.5079
553.137	39.4022
557.54	17.513
561.94	6.96442
566.337	36.1203
570.734	1.0036
575.127	1.20361
579.518	12.6505
583.909	13.7426
588.295	19.9613
592.68	-8.20325
597.064	-46.2054
601.445	-34.3141
605.823	-30.9615
610.201	-35.1934
614.575	-57.8807
618.947	-43.2273
623.317	-43.731
627.686	-54.4441
632.052	-31.4272
636.415	-49.8568
640.777	-64.5764
645.138	-70.2686
649.495	-48.7182
653.85	-68.5533
658.205	-63.1472
662.556	-66.5219
666.905	-64.3591
671.252	-22.6799
675.597	-34.3826
679.941	14.7036
684.282	114.928
688.62	207.719
692.957	119.381
697.293	46.9581
701.625	-1.82898
705.955	-22.437
710.283	-38.7501
714.609	-50.7929
718.933	-43.0571
723.257	-54.8416
727.577	-47.5191
731.894	-24.6665
736.21	-35.1688
740.524	-38.6371
744.835	-41.7069
749.147	-29.949
753.454	-14.2153
757.759	-20.1069
762.063	-0.0608521
766.364	22.7949
770.663	32.0101
774.96	37.0029
779.257	140.058
783.55	289.269
787.841	435.224
792.13	562.414
796.417	749.112
800.702	952.279
804.985	606.33
809.266	292.864
813.545	152.139
817.821	108.251
822.096	93.9994
826.371	88.6674
830.641	69.0269
834.91	80.2054
839.176	72.5822
843.441	70.3883
847.703	73.5318
851.964	82.9673
856.222	70.3239
860.479	110.546
864.733	175.938
868.986	231.108
873.236	150.896
877.485	110.235
881.731	82.7312
885.975	55.1364
890.218	59.0376
894.458	57.2532
898.696	51.752
902.933	61.3192
907.167	57.3232
911.399	51.6705
915.63	51.6865
919.858	53.7489
924.084	41.6712
928.308	35.7916
932.531	31.4506
936.749	22.7774
940.967	18.2904
945.184	5.20065
949.398	16.6595
953.61	14.2908
957.821	19.3873
962.029	0.0322571
966.236	-1.21988
970.44	-1.40457
974.642	-3.67838
978.843	17.3601
983.041	-6.07602
987.236	-10.4717
991.43	-4.30655
995.623	-2.2276
999.813	-1.07317
1004	2.21962
1008.19	-12.5469
1012.37	-1.84688
1016.55	3.4408
1020.73	11.8956
1024.91	0.000930786
1029.09	16.7859
1033.27	18.5299
1037.44	10.3758
1041.61	32.9554
1045.78	45.8605
1049.94	101.1
1054.11	172.993
1058.27	261.353
1062.43	262.602
1066.59	309.953
1070.75	482.781
1074.9	620.97
1079.05	365.426
1083.2	193.397
1087.35	90.8724
1091.5	53.0197
1095.65	56.6004
1099.79	51.0073
1103.93	40.3263
1108.07	39.9614
1112.21	43.7856
1116.34	33.3275
1120.48	36.4014
1124.61	54.988
1128.74	54.2521
1132.86	73.0114
1136.99	86.6045
1141.11	114.549
1145.23	209.497
1149.35	390.145
1153.47	472.881
1157.59	362.45
1161.7	181.61
1165.82	117.214
1169.92	75.4469
1174.03	56.2942
1178.14	70.0648
1182.24	37.464
1186.35	50.085
1190.45	53.2857
1194.55	69.6997
1198.64	60.4117
1202.74	85.7236
1206.83	77.3348
1210.92	105.445
1215.01	124.303
1219.1	168.251
1223.18	202.959
1227.27	177.38
1231.35	180.032
1235.43	177.872
1239.5	157.93
1243.58	182.848
1247.65	205.824
1251.72	313.832
1255.8	455.948
1259.86	369.408
1263.93	290.802
1267.99	383.315
1272.06	1379.14
1276.12	3168.88
1280.18	1409.49
1284.23	409.419
1288.29	247.704
1292.34	218.607
1296.39	186.375
1300.44	175.228
1304.49	146.863
1308.53	152.716
1312.58	139.373
1316.62	160.182
1320.66	147.653
1324.7	150.13
1328.73	163.58
1332.77	148.862
1336.8	164.144
1340.83	173.305
1344.86	176.392
1348.88	178.444
1352.91	203.368
1356.93	263.961
1360.95	334.211
1364.97	384.461
1368.99	493.929
1373.01	889.467
1377.02	3505.74
1381.03	4629.7
1385.04	1422.87
1389.05	424.77
1393.06	306.052
1397.06	393.244
1401.06	561.247
1405.06	349.955
1409.06	176.006
1413.06	156.744
1417.05	148.308
1421.05	119.113
1425.04	121.455
1429.03	99.9785
1433.01	96.265
1437	90.5722
1440.99	73.0152
1444.97	83.0692
1448.95	69.4053
1452.93	64.5922
1456.9	56.7939
1460.88	53.8948
1464.85	52.9091
1468.82	61.731
1472.79	59.742
1476.76	48.9009
1480.73	48.831
1484.69	51.677
1488.65	52.5399
1492.61	53.4
1496.57	45.4811
1500.53	58.031
1504.48	51.1193
1508.43	54.9424
1512.39	58.7672
1516.33	53.8489
1520.28	40.2115
1524.23	58.5952
1528.17	51.7596
1532.11	59.4797
1536.05	66.2261
1539.99	66.1835
1543.93	62.2593
1547.86	65.1117
1551.8	77.6443
1555.73	78.5242
1559.66	71.6243
1563.58	96.6376
1567.51	88.7164
1571.44	92.3819
1575.36	108.587
1579.28	105.455
1583.2	106.173
1587.11	107.834
1591.03	119.106
1594.94	138.044
1598.85	140.608
1602.76	156.624
1606.67	152.499
1610.58	150.305
1614.48	167.292
1618.38	178.548
1622.29	166.798
1626.18	169.446
1630.08	155.859
1633.98	179.677
1637.87	179.564
1641.76	181.424
1645.65	174.725
1649.54	169.962
1653.43	154.651
1657.31	158.499
1661.2	132.557
1665.08	144.026
1668.96	119.902
1672.83	112.047
1676.71	99.3643
1680.58	86.5911
1684.46	85.2957
1688.33	74.3947
1692.2	71.1434
1696.06	58.3054
1699.93	53.1167
1703.79	50.7708
1707.66	40.7842
1711.52	42.2032
1715.37	42.6654
1719.23	40.2935
1723.08	35.1026
1726.94	26.1534
1730.79	34.1384
1734.64	31.7796
1738.49	9.76954
1742.33	23.3159
1746.18	17.2474
1750.02	17.7799
1753.86	16.5039
1757.7	12.5155
1761.54	7.7871
1765.37	17.855
1769.21	4.73811
1773.04	9.32607
1776.87	6.48701
1780.7	6.47306
1784.53	7.41611
1788.35	11.1817
1792.17	2.79276
1796	8.45267
1799.82	1.91174
1803.64	-0.00667572
1807.45	11.2423
1811.27	2.70689
1815.08	2.62978
1818.89	-0.322769
1822.7	4.24343
1826.51	5.01569
1830.32	-0.841911
1834.12	-2.0081
1837.92	-5.07236
1841.72	-4.38339
1845.52	7.55212
1849.32	-3.04365
1853.12	-3.34915
1856.91	3.79601
1860.7	4.34909
1864.5	-5.35095
1868.28	0.790016
1872.07	0.432251
1875.86	1.02495
1879.64	7.16644
1883.42	1.35268
1887.21	5.69332
1890.98	3.70998
1894.76	-1.01366
1898.54	4.38589
1902.31	2.47327
1906.08	-1.25362
1909.85	-4.96982
1913.62	7.94601
1917.39	4.28781
1921.16	9.0126
1924.92	0.809555
1928.68	1.87666
1932.44	8.54158
1936.2	4.05479
1939.96	7.95044
1943.71	11.8614
1947.47	11.11
1951.22	10.2585
1954.97	4.66377
1958.72	18.7313
1962.46	5.5181
1966.21	11.0852
1969.95	1.59926
1973.7	9.90183
1977.43	11.6088
1981.17	22.6499
1984.91	16.8221
1988.65	15.6625
1992.38	21.9426
1996.11	24.456
1999.84	22.2977
2003.57	13.6709
2007.3	20.7835
2011.02	25.9874
2014.75	29.3332
2018.47	24.469
2022.19	17.8682
2025.91	20.5204
2029.62	20.4456
2033.34	21.3352
2037.05	17.715
2040.76	24.1505
2044.47	19.5957
2048.18	25.1137
2051.89	26.0851
2055.59	12.413
2059.3	26.2891
2063	20.0937
2066.7	30.4703
2070.4	22.4735
2074.1	25.5278
2077.79	28.6049
2081.49	29.8549
2085.18	19.0308
2088.87	31.2603
2092.56	24.8326
2096.25	30.5538
2099.93	25.11
2103.61	24.2638
2107.3	28.0468
2110.98	20.6504
2114.66	16.9728
2118.33	23.5085
2122.01	37.4173
2125.68	27.1458
2129.36	28.926
2133.03	29.7631
2136.7	21.3489
2140.36	28.6296
2144.03	23.8882
2147.7	34.794
2151.36	23.6217
2155.02	20.7459
2158.68	18.803
2162.34	16.8834
2165.99	20.469
2169.65	14.9545
2173.3	14.9681
2176.95	25.0321
2180.6	7.80354
2184.25	4.23488
2187.9	5.24277
2191.54	5.39037
2195.18	19.2402
2198.83	14.9246
2202.47	4.23315
2206.11	17.2752
2209.74	12.0896
2213.38	10.5707
2217.01	5.38885
2220.64	6.62266
2224.27	6.0282
2227.9	1.74236
2231.53	6.67028
2235.16	6.0815
2238.78	5.48942
2242.4	12.3088
2246.02	12.6473
2249.64	3.69299
2253.26	1.24277
2256.88	-3.07122
2260.49	13.1649
2264.11	3.22488
2267.72	-0.173889
2271.33	7.71846
2274.93	13.7325
2278.54	5.58547
2282.15	17.1698
2285.75	8.9259
2289.35	7.29009
2292.95	10.3647
2296.55	8.71415
2300.15	10.855
2303.74	8.24392
2307.34	12.2407
2310.93	11.4831
2314.52	31.5626
2318.11	175.771
2321.7	503.632
2325.28	216.44
2328.87	47.9696
2332.45	13.0213
2336.03	13.0366
2339.61	7.38831
2343.19	15.8465
2346.77	13.0017
2350.34	5.47488
2353.92	2.64592
2357.49	7.28734
2361.06	9.11023
2364.63	11.8537
2368.2	3.46217
2371.76	-1.16935
2375.33	6.22987
2378.89	9.91241
2382.45	12.676
2386.01	5.32337
2389.57	7.19695
2393.13	8.1705
2396.68	4.58972
2400.23	1.96629
2403.79	6.73032
2407.34	6.01434
2410.88	7.17175
2414.43	8.36031
2417.98	-4.20871
2421.52	3.45041
2425.06	7.46713
2428.61	4.13885
2432.14	4.51768
2435.68	2.13882
2439.22	4.40411
2442.75	2.9619
2446.29	4.31445
2449.82	1.01253
2453.35	-0.41404
2456.88	2.79607
2460.4	-6.31495
2463.93	4.33296
2467.45	-6.77281
2470.98	3.87568
2474.5	4.95405
2478.02	5.99005
2481.54	-3.32329
2485.05	0.529022
2488.57	0.550667
2492.08	1.55297
2495.59	2.51062
2499.1	4.424
2502.61	-2.11128
2506.12	-7.71275
2509.63	-6.78785
2513.13	-0.280983
2516.63	-2.13535
2520.13	5.30839
2523.63	2.47247
2527.13	-0.25795
2530.63	-4.80602
2534.12	1.7417
2537.62	2.77376
2541.11	-6.32413
2544.6	-0.616333
2548.09	4.21636
2551.58	2.58835
2555.06	4.67944
2558.55	2.19438
2562.03	-3.08746
2565.51	4.67049
2568.99	3.16949
2572.47	0.749817
2575.95	-2.60441
2579.43	1.55714
2582.9	4.80438
2586.37	0.503731
2589.84	-1.00116
2593.31	11.6941
2596.78	2.50873
2600.25	3.81419
2603.71	0.33242
2607.18	-2.25986
2610.64	4.66434
2614.1	4.7945
2617.56	-1.7579
2621.02	1.2513
2624.47	9.04632
2627.93	4.3203
2631.38	1.50087
2634.83	0.579735
2638.28	-5.16331
2641.73	4.40905
2645.18	8.19759
2648.62	11.0136
2652.07	5.21672
2655.51	3.21918
2658.95	3.10613
2662.39	2.98164
2665.83	1.90089
2669.27	2.70776
2672.7	4.44213
2676.14	3.36746
2679.57	4.18167
2683	6.88047
2686.43	11.4658
2689.86	-4.40604
2693.29	8.66489
2696.71	6.79459
2700.13	-2.49797
2703.56	-1.5454
2706.98	10.5577
2710.4	5.06042
2713.82	7.95112
2717.23	9.93113
2720.65	8.20384
2724.06	13.0146
2727.47	4.76609
2730.88	9.59371
2734.29	10.6795
2737.7	17.3878
2741.11	4.40477
2744.51	12.032
2747.91	8.37764
2751.32	8.47849
2754.72	1.98361
2758.11	12.4113
2761.51	17.202
2764.91	13.4845
2768.3	10.6902
2771.7	16.3564
2775.09	18.2424
2778.48	15.3969
2781.87	14.4192
2785.25	12.4909
2788.64	14.3207
2792.03	19.9029
2795.41	17.9558
2798.79	19.7669
2802.17	15.9248
2805.55	17.7119
2808.93	15.7455
2812.3	19.3888
2815.68	14.6026
2819.05	21.9624
2822.42	22.7908
2825.79	18.9681
2829.16	29.1391
2832.53	23.4721
2835.89	21.5541
2839.26	31.763
2842.62	39.1988
2845.98	34.5506
2849.34	39.2643
2852.7	35.619
2856.06	31.9467
2859.41	35.7632
2862.77	29.3036
2866.12	33.1422
2869.47	40.7429
2872.82	38.0164
2876.17	45.6218
2879.52	36.2932
2882.87	47.6699
2886.21	42.0786
2889.55	39.3026
2892.89	49.7425
2896.23	38.4172
2899.57	50.7041
2902.91	49.7313
2906.25	54.4151
2909.58	54.3545
2912.91	45.7636
2916.25	54.1955
2919.58	56.9241
2922.91	59.6408
2926.23	65.1781
2929.56	65.0148
2932.88	69.5552
2936.21	64.6244
2939.53	73.8423
2942.85	71.7384
2946.17	65.8747
2949.49	74.1349
2952.8	75.7946
2956.12	79.3317
2959.43	88.5233
2962.74	76.1393
2966.06	82.5315
2969.37	98.3471
2972.67	86.0646
2975.98	105.67
2979.28	101.866
2982.59	101.786
2985.89	101.715
2989.19	114.8
2992.49	122.263
2995.79	123.164
2999.09	126.896
3002.38	126.867
3005.68	134.361
3008.97	139.056
3012.26	152.241
3015.55	152.255
3018.84	145.662
3022.13	169.241
3025.41	174.913
3028.7	173.04
3031.98	175.882
3035.26	188.166
3038.54	204.234
3041.82	195.718
3045.1	201.396
3048.38	216.554
3051.65	231.722
3054.92	247.864
3058.2	234.605
3061.47	232.616
3064.73	276.219
3068	272.345
3071.27	279.802
3074.54	309.621
3077.8	312.371
3081.06	321.583
3084.32	343.517
3087.58	362.594
3090.84	359.029
3094.1	379.312
3097.35	378.013
3100.61	402.723
3103.86	426.367
3107.11	442.683
3110.36	457.995
3113.61	492.157
3116.86	479.729
3120.11	511.118
3123.35	522.518
3126.59	567.258
3129.84	573.874
3133.08	587.177
3136.32	611.903
3139.55	634.688
3142.79	658.419
3146.03	676.433
3149.26	687.829
3152.49	724.046
3155.72	747.833
3158.95	802.184
3162.18	844.111
3165.41	842.161
3168.64	862.072
3171.86	888.59
3175.08	911.25
3178.31	948.125
3181.53	986.877
3184.75	1038.05
3187.96	1082.39
3191.18	1077.09
3194.4	1103.25
3197.61	1136.04
3200.82	1184.97
3204.03	1224.4
3207.24	1237.2
3210.45	1260.52
3213.66	1282.03
3216.86	1302.68
3220.07	1345.21
3223.27	1343.06
3226.48	1415.28
3229.68	1409.51
3232.87	1418.15
3236.07	1452.35
3239.27	1469.79
3242.47	1494
3245.66	1514.51
3248.85	1568.38
3252.04	1538.57
3255.23	1544.07
3258.42	1587.74
3261.61	1582.51
3264.8	1627.66
3267.98	1659.21
3271.16	1681.02
3274.35	1644.45
3277.53	1716.77
3280.71	1716.12
3283.89	1717.01
3287.06	1763.76
3290.24	1794.06
3293.41	1803.54
3296.58	1825.32
3299.76	1825.16
3302.93	1872.18
3306.1	1877.7
3309.26	1940.1
3312.43	1941.27
3315.59	1935.66
3318.76	1972.7
3321.92	2008.65
3325.08	2079.6
3328.24	2101.23
3331.4	2152.19
3334.56	2187.16
3337.71	2192.06
3340.87	2238.66
3344.02	2269.2
3347.17	2288.03
3350.33	2311.27
3353.47	2391.94
3356.62	2419.19
3359.77	2422.99
3362.92	2479.91
3366.06	2539.74
3369.2	2608.24
3372.34	2644.79
3375.49	2642.07
3378.62	2710.3
3381.76	2741.91
3384.9	2822.54
3388.04	2823.13
3391.17	2869.18
3394.3	2876.43
3397.43	2946.14
3400.56	2980.79
3403.69	2955.99
3406.82	3043.53
3409.95	3078.19
3413.07	3065.29
3416.2	3042.04
3419.32	3101.49
3422.44	3099.7
3425.56	3121.09
3428.68	3170.55
3431.8	3180.43
3434.91	3167.71
3438.03	3195.18
3441.14	3207.8
3444.25	3151.7
3447.36	3180.75
3450.47	3143
3453.58	3115.24
3456.69	3124.61
3459.79	3096.38
3462.9	3069.07
3466	3049.25
3469.11	3035.7
3472.21	3001.54
3475.31	2969.44
3478.4	2909.17
3481.5	2887.9
3484.6	2876.19
3487.69	2799.54
3490.79	2762.07
3493.88	2658.48
3496.97	2667.14
3500.06	2627.46
3503.15	2555.89
3506.23	2458.42
3509.32	2422.34
3512.4	2376.05
3515.49	2335.76
3518.57	2241.16
3521.65	2250.03
3524.73	2194.88
3527.81	2132.77
3530.89	2072.29
3533.96	2003.82
3537.03	1920.1
3540.11	1903.5
3543.18	1830.39
3546.25	1816.17
3549.32	1754.37
3552.39	1725.1
3555.46	1656.81
3558.52	1600.12
3561.59	1556.67
3564.65	1506.17
3567.71	1460.11
3570.77	1395.59
3573.83	1392.86
3576.89	1359.85
3579.95	1311.54
3583	1258.37
3586.06	1214.56
3589.11	1191.62
3592.16	1116.37
3595.21	1120.76
3598.27	1060.59
3601.31	1023.21
3604.36	1009.4
3607.41	961.448
3610.45	938.135
3613.5	918.572
3616.54	883.877
3619.58	843.609
3622.62	789.285
3625.66	780.304
3628.69	744.068
3631.73	704.053
3634.77	680.967
3637.8	642.111
3640.83	600.56
3643.86	575.089
3646.89	521.597
3649.92	494.24
3652.95	459.524
3655.98	441.808
3659	416.034
3662.02	376.981
3665.05	350.978
3668.07	316.225
3671.09	274.016
3674.11	258.2
3677.13	242.391
3680.14	223.754
3683.16	197.514
3686.17	175.977
3689.19	176.189
3692.2	156.527
3695.21	138.743
3698.22	141.736
3701.23	120.131
3704.23	111.788
3707.24	110.084
3710.24	90.293
3713.25	97.0932
3716.25	82.9435
3719.25	76.4149
3722.25	62.2427
3725.25	68.9969
3728.25	49.0744
3731.24	50.0897
3734.24	41.5675
3737.23	46.3605
3740.22	44.4762
3743.21	34.962
3746.21	34.9563
3749.19	37.7889
3752.18	27.3073
3755.17	23.4841
3758.15	21.5693
3761.14	22.5003
3764.12	25.314
3767.1	13.9256
3770.08	16.7581
3773.06	12.0357
3776.04	11.1108
3779.02	16.8104
3781.99	16.849
3784.97	15.9466
3787.94	4.66928
3790.91	8.50771
3793.88	5.76043
3796.85	8.68829
3799.82	12.569
3802.79	7.02885
3805.76	14.7162
3808.72	2.57345
3811.69	8.38873
3814.65	4.75809
3817.61	2.07471
3820.57	6.02005
3823.53	4.29232
3826.49	-1.21637
3829.45	5.59488
3832.4	-0.86525
3835.36	5.9671
3838.31	3.31879
3841.26	-0.282494
3844.21	3.72087
3847.16	-4.64122
3850.11	0.327118
3853.06	6.26521
3856	4.58266
3858.95	6.72037
3861.89	-4.51937
3864.84	8.13596
3867.78	-4.08397
3870.72	7.62685
3873.66	7.84417
3876.6	-1.53879
3879.53	14.9814
3882.47	2.68572
3885.4	4.78235
3888.34	3.02711
3891.27	10.8823
3894.2	14.8898
3897.13	11.1894
3900.06	3.62856
3902.99	14.3376
3905.91	6.76086
3908.84	-6.56329
3911.76	3.17236
3914.69	6.16845
3917.61	8.19261
3920.53	1.59979
3923.45	1.70764
3926.37	15.2348
3929.28	-0.0273972
3932.2	12.51
3935.11	14.5294
3938.03	-3.53501
3940.94	4.28158
3943.85	3.46899
3946.76	16.067
3949.67	15.2745
3952.58	15.4498
3955.49	16.5884
3958.39	3.37073
3961.3	5.4837
3964.2	12.3971
3967.1	7.8157
3970	9.95277
3972.9	13.0564
3975.8	17.1214
3978.7	10.6145
3981.6	11.7833
3984.49	15.8357
3987.39	15.0764
3990.28	14.3149
3993.17	11.6119
3996.06	10.857
3998.95	10.0994
4001.84	11.2737
4004.73	17.2664
4007.61	9.78138
4010.5	6.14808
4013.38	6.36757
4016.27	8.51787
4019.15	10.6704
4022.03	9.92795
4024.91	16.9121
4027.79	9.41172
4030.66	9.6386
4033.54	14.705
4036.42	0.426003
4039.29	7.43524
4042.16	18.3239
4045.03	-3.74056
4047.9	5.1984
4050.77	5.42428
4053.64	9.53646
4056.51	-1.86578
4059.38	6.13891
4062.24	7.34619
4065.1	4.66666
4067.97	3.92907
4070.83	-3.62202
4073.69	2.44783
4076.55	2.67758
4079.41	5.82925
4082.26	6.05908
4085.12	8.24007
4087.97	7.49104
4090.83	0.884644
4093.68	5.99648
4096.53	0.360573
4099.38	3.51913
4102.23	3.74583
4105.08	11.7929
4107.93	0.266899
4110.77	3.41259
4113.62	-0.302002
4116.46	7.7168
4119.3	2.99779
4122.14	12.9584
4124.98	8.25188
4127.82	5.50574
4130.66	0.826248
4133.5	4.97395
4136.33	6.21571
4139.17	8.32093
4142	3.47215
4144.83	10.4829
4147.67	5.80484
4150.5	-3.76452
4153.33	3.28935
4156.15	3.45327
4158.98	1.61786
4161.81	-0.187134
4164.63	5.84968
4167.45	7.97108
4170.28	3.25035
4173.1	-7.33229
4175.92	-0.309525
4178.74	8.6688
4181.56	4.94124
4184.37	5.12878
4187.19	4.34303
4190	3.5593
4192.82	-0.147789
4195.63	7.90349
4198.44	-4.6004
4201.25	4.44776
4204.06	5.66099
4206.87	2.94522
4209.68	10.0488
4212.48	2.41526
4215.29	0.671021
4218.1	-4.96338
4220.9	0.228874
4223.7	2.46206
4226.5	4.6862
4229.3	1.98631
4232.1	-0.715553
4234.9	9.46355
4237.69	-6.11446
4240.49	3.09663
4243.28	4.37752
4246.07	-0.308525
4248.87	7.94955
4251.66	8.23122
4254.45	2.51147
4257.24	-1.22969
4260.03	-1.97684
4262.81	2.29156
4265.6	4.56396
4268.38	-7.22786
4271.17	4.10065
4273.95	-0.672516
4276.73	-2.44784
4279.51	4.84658
4282.29	3.05022
4285.07	7.30782
4287.84	0.427666
4290.62	5.67637
4293.39	-1.22794
4296.17	-3.06275
4298.94	8.28614
4301.71	4.42362
4304.48	1.5689
4307.25	5.81751
4310.02	-1.1018
4312.79	4.17677
4315.55	2.32707
4318.32	-0.552185
4321.08	4.70202
4323.85	0.787521
4326.61	1.95707
4329.37	3.12856
4332.13	3.27181
4334.89	0.36161
4337.65	7.63095
4340.4	1.66835
4343.16	1.82005
4345.91	-0.0606537
4348.67	-4.99686
4351.42	-4.83413
4354.17	0.455414
4356.92	6.76604
4359.67	2.85388
4362.42	4.04808
4365.17	0.129486
4367.91	1.3221
4370.66	-0.553825
4373.4	-0.395088
4376.14	-0.240677
4378.89	12.2281
4381.63	10.3209
4384.37	6.36155
4387.11	1.3876
4389.84	5.70152
4392.58	4.88676
4395.32	2.06774
4398.05	4.35394
4400.78	2.4928
4403.52	-4.56423
4406.25	2.89188
4408.98	-0.0210648
4411.71	0.169044
4414.44	4.51019
4417.16	3.64338
4419.89	11.0803
4422.62	9.1496
4425.34	3.04568
4428.06	-3.06781
4430.78	5.44621
4433.51	1.41363
4436.22	10.9817
4438.94	0.649643
4441.66	10.2134
4444.38	7.20154
4447.1	-2.11593
4449.81	5.35372
4452.52	10.7209
4455.24	4.53152
4457.95	8.83895
4460.66	6.83567
4463.37	5.89225
4466.08	5.99778
4468.78	0.84465
4471.49	5.16602
4474.2	-3.14401
4476.9	0.137794
4479.6	7.64876
4482.31	10.9522
4485.01	15.3162
4487.71	0.647064
4490.41	1.8232
4493.11	5.09695
4495.8	8.35403
4498.5	3.15762
4501.19	12.7851
4503.89	8.63095
4506.58	4.48222
4509.27	6.69586
4511.96	4.66603
4514.66	2.63531
4517.34	2.72823
4520.03	6.0109
4522.72	0.799667
4525.41	15.7961
4528.09	7.38622
4530.77	4.29417
4533.46	10.7928
4536.14	6.63532
4538.82	12.0808
4541.5	3.65157
4544.18	1.62151
4546.86	4.94089
4549.53	11.4783
4552.21	8.38646
4554.88	4.23029
4557.56	7.59578
4560.23	9.92034
4562.9	-0.669121
4565.57	3.8467
4568.24	9.49097
4570.91	-4.41751
4573.58	7.60533
4576.24	4.39385
4578.91	9.91206
4581.58	8.94928
4584.24	8.00777
4586.9	1.56039
4589.56	9.27464
4592.22	-4.83318
4594.88	6.15453
4597.54	2.9667
4600.2	0.856094
4602.86	5.32226
4605.51	-1.14922
4608.17	2.2321
4610.82	4.52361
4613.47	2.42301
4616.13	-9.57476
4618.78	7.01035
4621.43	7.11452
4624.07	10.5218
4626.72	-1.51714
4629.37	6.29264
4632.01	-4.67255
4634.66	7.55454
4637.3	-0.124809
4639.94	1.04164
4642.59	8.85434
4645.23	1.17867
4647.87	7.93475
4650.5	11.3942
4653.14	2.65284
4655.78	9.46535
4658.42	-1.65872
4661.05	11.8102
4663.68	9.6856
4666.31	6.42822
4668.95	-2.45202
4671.58	-6.85991
4674.21	-0.0710678
4676.84	-0.00146484
4679.46	5.67783
4682.09	6.87028
4684.72	4.69243
4687.34	4.76083
4689.97	-0.798134
4692.59	-1.85789
4695.21	2.70959
4697.83	1.64166
4700.45	5.08892
4703.07	7.40895
4705.69	1.81247
4708.3	2.99177
4710.92	6.43142
4713.54	12.1367
4716.15	3.1235
4718.76	6.55861
4721.37	11.1273
4723.99	5.49141
4726.59	4.39915
4729.2	1.04228
4731.81	1.08807
4734.42	-0.00149536
4737.03	1.17773
4739.63	-7.87833
4742.23	1.25185
4744.84	3.55589
4747.44	-2.10821
4750.04	-0.958725
4752.64	3.60775
4755.24	13.8648
4757.84	1.35751
4760.44	8.20831
4763.03	-4.28963
4765.63	4.85217
4768.22	0.343651
4770.82	9.52483
4773.41	0.441124
4776	6.18983
4778.59	2.80923
4781.18	-2.86034
4783.77	6.32429
4786.36	2.94048
4788.94	-3.8779
4791.53	5.32406
4794.11	1.94271
4796.7	6.58121
4799.28	-0.231392
4801.86	-0.163292
4804.44	4.50526
4807.02	5.74426
4809.6	12.7473
4812.18	1.33263
4814.76	1.43076
4817.33	0.380066
4819.91	5.11379
4822.48	-1.71481
4825.06	4.18885
4827.63	1.98425
4830.2	3.26003
4832.77	6.87553
4835.34	2.34918
4837.91	-2.17974
4840.48	1.46496
4843.04	5.1196
4845.61	-2.95095
4848.17	0.685677
4850.74	4.3093
4853.3	5.53355
4855.86	4.41125
4858.42	-0.157654
4860.98	4.69009
4863.54	13.0705
4866.1	1.34938
4868.66	4.98389
4871.21	0.361603
4873.77	1.63589
4876.32	-3.02544
4878.88	-0.574181
4881.43	-0.498138
4883.98	5.51337
4886.53	5.58839
4889.08	2.09775
4891.63	6.93497
4894.18	2.24859
4896.72	-1.25343
4899.27	4.77509
4901.81	9.61615
4904.36	0.142418
4906.9	-0.985649
4909.44	-2.11822
4911.98	0.317154
4914.52	1.55246
4917.06	0.391876
4919.6	-4.34453
4922.14	-6.69138
4924.67	4.10624
4927.21	0.571785
4929.74	-0.581711
4932.28	-1.71657
4934.81	7.92861
4937.34	-0.374847
4939.87	-6.29211
4942.4	0.927376
4944.93	5.77895
4947.46	-0.131828
4949.99	-1.25574
4952.51	8.41769
4955.04	-3.50214
4957.56	-2.21796
4960.08	5.08048
4962.61	6.38719
4965.13	6.51559
4967.65	-0.567566
4970.17	5.57874
4972.69	2.07549
4975.2	-0.227745
4977.72	1.09061
4980.24	6.04546
4982.75	-5.94679
4985.27	5.07648
4987.78	-0.866882
4990.29	-1.96117
4992.8	7.88288
4995.31	1.92149
4997.82	0.833946