File: Data/3-Raman/processed/bu19w-d-ff2-fi08-v_1800 (450-850nm)_532nm_edge_100%_x100_vis_lwd_h50um_30sx2_01.txt
#Acq. time (s)=	30
#Accumulations=	2
#Range (cm-¹)=	1200...2365
#Windows=	3
#Auto scanning=	Off
#Autofocus=	Off
#Macrospot=	Off
#AutoExposure=	Off
#Spike filter=	Multiple accum.
#Delay time (s)=	2
#Binning=	1
#Readout mode=	Signal
#DeNoise=	Off
#ICS correction=	On
#Dark correction=	Off
#Inst. Process=	Off
#Detector Gain=	Best Dynamic
#Detector ADC=	50 kHz HS
#Detector temperature (°C)=	-60.09
#Instrument=	LabRAM HR Evol
#Detector=	SIN-EM FIVIS
#Objective=	x100_VIS_LWD
#Grating=	1800 (450-850nm)
#ND Filter=	100%
#Laser=	532nm_Edge
#Hole=	49.98
#Temperature=	0
#Range=	Visible
#StageXY=	75x50mm Scan+
#StageZ=	Z motor
#X (µm)=	0
#Y (µm)=	0
#Z (µm)=	12.2
#Full time(mm:ss)=	3:18
#Project=	21_11_22
#Sample=	BU19w
#Site=
#Title=	BU19w-D-FF2-FI08-V_1800 (450-850nm)_532nm_Edge_100%_x100_VIS_LWD_H50um_30sX2
#Remark=
#Date=	22.11.2021 13:45
#Acquired=	22.11.2021 13:45:11
#Base:Fit=	16.12.2021 17:39:50
#Base:Fit=	16.12.2021 17:43:29
#Base:Sub=	16.12.2021 17:43:30
1202.84	8.29484
1203.95	3.7575
1205.06	4.61953
1206.17	4.42365
1207.29	3.18618
1208.39	3.00143
1209.51	2.83044
1210.62	4.8117
1211.72	0.436287
1212.84	2.45841
1213.94	0.200294
1215.05	4.33512
1216.16	-3.18671
1217.27	3.10083
1218.38	-1.20724
1219.49	-0.228527
1220.6	-0.317389
1221.71	-0.380627
1222.81	-2.51889
1223.92	-2.5424
1225.03	4.76775
1226.14	1.53568
1227.24	3.71799
1228.35	4.69337
1229.46	7.85452
1230.56	14.1675
1231.67	19.4593
1232.78	24.7654
1233.88	19.5341
1234.99	19.5169
1236.09	18.4578
1237.2	12.2006
1238.3	3.86996
1239.41	6.01089
1240.51	9.22637
1241.62	3.00043
1242.72	6.18591
1243.83	5.19127
1244.93	9.44537
1246.03	1.13577
1247.14	5.39957
1248.24	7.54718
1249.34	10.7432
1250.45	12.8943
1251.55	14.0489
1252.65	14.1497
1253.75	5.89736
1254.86	8.07709
1255.96	6.07288
1257.06	6.19438
1258.16	4.17768
1259.26	0.154366
1260.36	3.32766
1261.46	2.48017
1262.56	7.78804
1263.66	9.98674
1264.76	5.94513
1265.86	-1.23641
1266.96	0.972803
1268.06	-1.02899
1269.16	-0.913429
1270.26	-1.8208
1271.36	-2.73443
1272.46	1.5801
1273.56	3.81394
1274.66	-0.251219
1275.76	-1.16613
1276.85	2.11119
1277.95	2.22756
1279.05	3.41398
1280.15	1.41865
1281.24	9.91643
1282.34	33.2719
1283.44	138.693
1284.53	88.2147
1285.63	10.4231
1286.73	6.34445
1287.82	1.20161
1288.92	1.31386
1290.01	-0.679398
1291.11	0.511328
1292.21	1.68422
1293.3	1.84235
1294.4	-0.161257
1295.49	-1.11845
1296.58	0.0385456
1297.68	-1.95812
1298.77	1.32086
1299.87	2.49109
1300.96	0.477943
1302.05	-3.64095
1303.15	-0.383907
1304.24	-4.50267
1305.33	5.09495
1306.42	-0.0717678
1307.52	1.08805
1308.61	-0.919882
1309.7	-1.86825
1310.79	3.50281
1311.88	-0.621595
1312.98	-0.516777
1314.07	-0.424772
1315.16	1.78671
1316.25	-3.40207
1317.34	-2.25419
1318.43	-2.17436
1319.52	1.06467
1320.61	2.19971
1321.7	1.2329
1322.79	2.36059
1323.88	3.46306
1324.97	1.4727
1326.06	-1.58785
1327.15	-2.56485
1328.23	1.71886
1329.32	1.76997
1330.41	0.771095
1331.5	1.87683
1332.59	1.93551
1333.67	0.948259
1334.76	3.10901
1335.85	3.16425
1336.94	2.18477
1338.02	3.30141
1339.11	3.36075
1340.2	-3.91272
1341.28	6.60849
1342.37	5.61593
1343.45	2.51635
1344.54	2.55429
1345.63	2.60461
1346.71	1.60824
1347.8	-1.47026
1348.88	0.654255
1349.96	0.718164
1351.05	2.87343
1352.13	2.88123
1353.22	0.851956
1354.3	5.04738
1355.39	0.931752
1356.47	3.042
1357.55	3.07121
1358.63	3.11012
1359.72	3.1474
1360.8	2.16016
1361.88	3.23709
1362.97	1.19282
1364.05	2.24897
1365.13	1.25257
1366.21	2.32834
1367.29	4.42777
1368.37	6.51308
1369.45	10.6423
1370.54	3.44387
1371.62	4.50077
1372.7	2.47107
1373.78	1.46459
1374.86	5.60485
1375.94	7.72858
1377.02	6.71509
1378.09	4.64068
1379.18	3.62065
1380.25	7.72322
1381.33	8.75934
1382.41	9.83005
1383.49	7.81865
1384.57	14.9577
1385.65	35.4776
1386.72	212.236
1387.8	149.374
1388.88	27.3324
1389.96	7.86591
1391.03	8.89779
1392.11	3.79576
1393.19	3.81717
1394.26	4.84623
1395.34	1.78719
1396.42	1.80705
1397.49	3.8726
1398.57	4.9171
1399.64	1.8795
1400.72	4.98594
1401.79	2.93112
1402.87	2.92992
1403.94	3.95871
1405.02	3.97231
1406.09	5.01092
1407.17	9.12634
1408.24	17.3087
1409.31	15.259
1410.39	10.2084
1411.46	4.02631
1412.53	5.06685
1413.61	1.99598
1414.68	3.03464
1415.75	4.06887
1416.82	0.985332
1417.9	4.05603
1418.97	3.03171
1420.04	-0.0186987
1421.11	3.01607
1422.18	5.06514
1423.26	0.970005
1424.33	-4.16845
1425.4	0.941313
1426.47	1.96899
1427.54	0.95666
1428.61	2.00069
1429.68	0.964921
1430.75	2.99022
1431.82	1.9687
1432.89	1.96635
1433.96	1.95893
1435.02	0.927732
1436.09	0.929574
1437.16	-0.0884752
1438.23	2.98841
1439.3	5.03344
1440.37	-0.0981255
1441.43	-2.15587
1442.5	1.95301
1443.57	0.917591
1444.64	-1.14321
1445.7	3.9835
1446.77	0.899562
1447.84	1.91212
1448.9	1.90118
1449.97	0.870152
1451.04	-1.18252
1452.1	1.88487
1453.17	-0.1673
1454.23	0.845771
1455.3	0.83716
1456.36	2.88263
1457.43	-0.199184
1458.49	1.83647
1459.56	0.79599
1460.62	-1.26841
1461.69	-1.26132
1462.75	1.75758
1463.81	0.72559
1464.88	0.716186
1465.94	1.72752
1467	0.691524
1468.07	1.696
1469.13	0.662581
1470.19	0.653472
1471.25	1.65727
1472.32	-2.41814
1473.38	2.65856
1474.44	-0.407298
1475.5	-0.418867
1476.56	-0.43437
1477.62	-0.455462
1478.68	1.56181
1479.75	3.59678
1480.81	0.547407
1481.87	2.53871
1482.93	0.499636
1483.99	-2.54422
1485.05	-3.56896
1486.11	2.48787
1487.17	3.48883
1488.22	1.45126
1489.28	0.432637
1490.34	0.424986
1491.4	0.418597
1492.46	-2.62432
1493.52	-1.63173
1494.58	-1.64083
1495.63	-1.64701
1496.69	3.39774
1497.75	-1.65379
1498.81	-0.654747
1499.86	1.35283
1500.92	0.331563
1501.98	-2.69693
1503.03	-1.70444
1504.09	-0.70045
1505.15	-0.704835
1506.2	1.30622
1507.26	-0.711176
1508.31	-1.7343
1509.37	-0.757467
1510.42	3.23923
1511.48	-0.771756
1512.53	1.22047
1513.59	-2.80845
1514.64	0.194163
1515.7	-0.806722
1516.75	-1.80951
1517.8	2.19858
1518.86	1.19537
1519.91	-0.819857
1520.96	2.16801
1522.02	0.155384
1523.07	-0.842908
1524.12	1.16682
1525.17	-0.845095
1526.23	3.15453
1527.28	2.14622
1528.33	0.151187
1529.38	1.14927
1530.43	-0.841835
1531.48	0.162138
1532.53	2.15981
1533.59	-0.867719
1534.64	0.117033
1535.69	-1.89171
1536.74	0.127797
1537.79	0.150971
1538.84	-1.86247
1539.89	1.12851
1540.94	-1.88931
1541.98	-0.881136
1543.03	2.13673
1544.08	-0.864998
1545.13	0.129849
1546.18	1.12331
1547.23	-0.874116
1548.28	1.17419
1549.33	2.17936
1550.37	2.16862
1551.42	-0.850036
1552.47	1.14266
1553.52	1.14268
1554.56	0.144702
1555.61	0.134804
1556.65	-3.8794
1557.7	-2.88352
1558.75	-1.88005
1559.79	1.12895
1560.84	2.12792
1561.88	0.141978
1562.93	2.04607
1563.98	1.11843
1565.02	3.13227
1566.07	1.13945
1567.11	1.13445
1568.15	0.137553
1569.2	-3.8617
1570.24	1.12654
1571.29	1.12796
1572.33	-0.852321
1573.37	2.15083
1574.42	-1.8574
1575.46	3.11683
1576.5	-1.86545
1577.55	1.13354
1578.59	0.133718
1579.63	0.129507
1580.67	-0.865361
1581.72	1.13147
1582.76	2.13084
1583.8	1.12742
1584.84	1.12588
1585.88	1.1355
1586.92	1.1457
1587.96	0.15864
1589	0.160235
1590.04	-2.83281
1591.08	-0.857678
1592.12	3.12368
1593.16	1.13617
1594.2	-0.843921
1595.24	-0.838269
1596.28	1.14003
1597.32	-0.848912
1598.36	0.132621
1599.4	-0.86627
1600.44	-0.872554
1601.48	0.118524
1602.51	1.11403
1603.55	2.11562
1604.59	1.13487
1605.63	-0.839786
1606.66	-0.846084
1607.7	-2.73795
1608.74	1.15464
1609.77	2.87568
1610.81	2.56369
1611.85	0.368667
1612.88	0.982473
1613.92	1.03562
1614.95	0.56365
1615.99	1.27329
1617.03	0.803631
1618.06	0.474827
1619.1	1.58422
1620.13	0.866455
1621.17	1.5525
1622.2	1.78388
1623.23	0.227215
1624.27	2.22672
1625.3	0.102158
1626.34	1.69482
1627.37	1.85176
1628.4	-0.0964003
1629.44	0.125372
1630.47	1.61264
1631.29	0.867694
1632.33	-1.09885
1633.38	0.871669
1634.42	0.867799
1635.47	-0.116403
1636.51	0.872056
1637.56	3.83035
1638.6	2.8544
1639.65	2.855
1640.69	-2.06364
1641.73	-0.0967131
1642.78	0.896073
1643.82	-0.0880928
1644.86	2.86188
1645.91	2.87431
1646.95	2.8856
1647.99	1.91864
1649.03	2.91397
1650.08	-0.0403805
1651.12	2.92266
1652.16	-1.01039
1653.2	0.981819
1654.24	1.97656
1655.28	0.989151
1656.33	2.9582
1657.37	-0.000715256
1658.41	4.94583
1659.45	1.98927
1660.49	2.02217
1661.53	-0.951635
1662.57	1.01473
1663.61	0.0665569
1664.65	2.01805
1665.69	2.01799
1666.72	2.03952
1667.76	3.04202
1668.8	2.05686
1669.84	1.07533
1670.88	5.03686
1671.92	-0.884521
1672.96	2.09377
1674	3.08953
1675.03	1.10921
1676.07	2.09163
1677.11	0.112985
1678.15	-0.875719
1679.18	5.05514
1680.22	2.09481
1681.25	-0.866551
1682.29	1.1088
1683.33	1.11321
1684.36	0.134761
1685.4	3.09563
1686.43	0.128201
1687.47	0.124903
1688.51	2.10803
1689.54	2.11359
1690.58	2.10362
1691.61	0.12344
1692.64	1.11256
1693.68	-0.849576
1694.71	1.11599
1695.75	0.124179
1696.78	1.11
1697.81	0.126547
1698.85	0.12475
1699.88	-0.864212
1700.91	-1.84631
1701.95	-2.8233
1702.98	0.126204
1704.01	1.09936
1705.04	0.106749
1706.08	-0.886765
1707.11	0.090538
1708.14	2.05629
1709.17	0.104061
1710.2	3.02383
1711.23	0.0759649
1712.27	0.0756674
1713.3	0.0822477
1714.33	0.0710802
1715.36	2.97347
1716.39	0.0460987
1717.42	0.0494184
1718.45	0.0417299
1719.48	0.0318356
1720.51	-0.947728
1721.54	1.96485
1722.56	1.94861
1723.59	-0.964708
1724.62	-0.000263214
1725.65	1.92841
1726.68	-0.0369272
1727.71	-0.0362473
1728.74	-0.984989
1729.76	-0.986329
1730.79	-0.0327835
1731.82	-0.0476208
1732.85	0.90322
1733.87	2.82363
1734.9	1.85559
1735.93	-3.91995
1736.95	-0.0923967
1737.98	2.76792
1739.01	0.842586
1740.03	-1.07422
1741.06	-2.99076
1742.08	1.7907
1743.11	0.833628
1744.13	0.821867
1745.16	-0.141974
1746.18	-1.09266
1747.21	-0.126019
1748.23	-0.115902
1749.26	1.78649
1750.28	2.73
1751.31	0.812839
1752.33	0.806562
1753.35	0.7976
1754.38	-1.11904
1755.4	-1.11482
1756.42	1.74364
1757.44	3.6461
1758.47	-0.165416
1759.49	0.783149
1760.51	1.73901
1761.53	0.797717
1762.56	0.80889
1763.58	0.811379
1764.6	0.809751
1765.62	0.805545
1766.64	0.783319
1767.66	-2.06015
1768.68	-1.09859
1769.7	0.812452
1770.72	1.77281
1771.74	0.82681
1772.76	0.841805
1773.78	-0.106134
1774.8	2.74593
1775.82	-0.120424
1776.84	-0.126023
1777.86	-0.117981
1778.88	0.839526
1779.9	1.80381
1780.92	-0.0935335
1781.94	2.77991
1782.95	-0.082202
1783.97	1.83138
1784.99	0.901366
1786.01	-0.029686
1787.03	-0.97355
1788.04	-0.0108414
1789.06	-1.93772
1790.08	-0.0170965
1791.09	0.945928
1792.11	0.953453
1793.13	0.976575
1794.14	0.989369
1795.16	0.0377636
1796.17	-1.88281
1797.19	0.0332241
1798.21	-0.930532
1799.22	0.0331678
1800.24	1.96581
1801.25	0.0514498
1802.27	-2.82413
1803.28	2.00346
1804.29	2.01086
1805.31	-0.878269
1806.32	-0.87489
1807.34	1.05696
1808.35	0.0929832
1809.36	1.05962
1810.38	-0.860218
1811.39	-0.849312
1812.4	1.09629
1813.41	-1.79871
1814.43	1.09982
1815.44	2.06243
1816.45	0.137376
1817.46	3.04592
1818.47	3.05543
1819.49	1.12921
1820.5	0.164305
1821.51	0.164931
1822.52	1.14009
1823.53	1.14299
1824.54	1.14789
1825.55	-1.75515
1826.56	0.179344
1827.57	0.176352
1828.58	0.180815
1829.59	0.189526
1830.6	4.07311
1831.61	-1.74339
1832.62	0.173726
1833.63	0.236598
1834.64	0.186331
1835.65	2.09615
1836.65	1.1692
1837.66	0.182474
1838.67	2.08972
1839.68	1.10746
1840.69	2.07574
1841.7	-3.7103
1842.7	1.11479
1843.71	-0.793049
1844.72	1.08712
1845.72	-0.831903
1846.73	1.0853
1847.74	2.03005
1848.74	-2.78156
1849.75	0.0994053
1850.75	0.0975227
1851.76	0.0846052
1852.76	1.03173
1853.77	0.0720387
1854.78	0.0695438
1855.78	2.9317
1856.79	-1.86064
1857.79	-0.899156
1858.79	1.02379
1859.8	-0.894521
1860.8	0.0514765
1861.81	-0.911549
1862.81	0.983697
1863.81	-0.942734
1864.82	-1.90972
1865.82	-2.86175
1866.82	-0.00982571
1867.83	1.8898
1868.83	0.937064
1869.83	-0.019618
1870.83	-0.973201
1871.84	1.86305
1872.84	0.898676
1873.84	-0.0649996
1874.84	-0.0932589
1875.84	1.83243
1876.84	-0.994008
1877.84	0.899375
1878.84	1.82807
1879.84	1.79589
1880.84	-2.9165
1881.84	-0.101832
1882.85	-2.91658
1883.85	-1.02241
1884.84	-0.0908508
1885.84	-1.99061
1886.84	-0.115273
1887.84	-1.04899
1888.84	2.71734
1889.84	-0.111403
1890.84	-1.0718
1891.84	-1.07599
1892.83	0.806645
1893.83	-2.00479
1894.83	-1.99986
1895.83	-0.123328
1896.83	-1.07173
1897.82	-2.01277
1898.82	2.69616
1899.82	-1.05695
1900.81	0.819576
1901.81	2.6981
1902.81	-1.06413
1903.8	-0.134979
1904.8	-0.135207
1905.79	0.810893
1906.79	-2.93918
1907.79	-1.04293
1908.78	3.67252
1909.78	-0.0973644
1910.77	-0.0935946
1911.77	0.86316
1912.76	0.870905
1913.76	1.80902
1914.75	-0.0849361
1915.74	-0.0791645
1916.74	0.883171
1917.73	-0.0581179
1918.72	-0.992926
1919.72	-0.992064
1920.71	-0.0524273
1921.7	0.885305
1922.7	-0.0537205
1923.69	-0.985619
1924.68	0.917167
1925.67	-0.0248556
1926.66	1.88011
1927.66	-0.00226021
1928.65	4.74622
1929.64	0.940694
1930.63	0.938309
1931.62	0.972974
1932.61	0.0537806
1933.61	0.997529
1934.6	0.985505
1935.59	0.0269728
1936.58	1.94082
1937.57	0.996072
1938.56	-0.897214
1939.55	3.86742
1940.54	-0.898508
1941.52	-0.896029
1942.51	1.0254
1943.5	1.99117
1944.49	-0.879076
1945.48	0.074296
1946.47	1.99223
1947.46	3.9251
1948.44	0.112982
1949.43	-0.836322
1950.42	-1.79363
1951.41	0.100842
1952.39	-1.82871
1953.38	1.06589
1954.37	1.07804
1955.36	0.12359
1956.34	0.119036
1957.33	1.0716
1958.31	-0.859521
1959.3	1.05692
1960.29	-2.78246
1961.27	2.01929
1962.26	2.01688
1963.24	-1.82193
1964.23	1.06653
1965.21	-0.856586
1966.2	1.05913
1967.18	0.080862
1968.17	0.0701265
1969.15	-0.893225
1970.14	-1.85548
1971.12	-0.907234
1972.1	1.00698
1973.09	1.01157
1974.07	1.01109
1975.05	0.0435543
1976.04	0.993706
1977.02	-0.924918
1978	2.89869
1978.98	-0.941369
1979.97	0.00746059
1980.95	-0.00603008
1981.93	-0.970354
1982.91	0.932128
1983.89	2.84742
1984.88	0.923972
1985.86	0.892438
1986.84	0.861339
1987.82	0.864423
1988.8	-0.0734177
1989.78	-0.042098
1990.76	0.715445
1991.74	-0.901593
1992.72	1.75913
1993.7	0.300253
1994.68	-0.726706
1995.66	0.888322
1996.64	-0.347864
1997.62	-0.00822353
1998.6	1.60691
1999.57	-0.73738
2000.55	1.12325
2001.53	0.655506
2002.51	0.621018
2003.49	0.0948029
2004.47	0.987617
2005.44	0.30017
2006.42	-0.429748
2007.4	0.112864
2008.38	-0.281082
2009.35	0.12187
2010.33	-1.6106
2011.3	0.0843029
2012.18	0.428408
2013.17	0.429544
2014.16	-0.500849
2015.15	-0.517109
2016.14	0.397863
2017.13	-0.553411
2018.11	-1.49486
2019.1	-0.56289
2020.09	-0.576934
2021.08	0.34337
2022.06	-2.47745
2023.05	0.304012
2024.04	-0.612583
2025.02	0.327825
2026.01	1.28889
2027	-0.629875
2027.98	-0.652393
2028.97	-0.650503
2029.96	1.22929
2030.94	1.23876
2031.93	1.19836
2032.91	4.02628
2033.9	0.282748
2034.88	0.280147
2035.87	-0.666253
2036.85	-1.61306
2037.83	1.16885
2038.82	-0.707739
2039.8	1.14435
2040.79	1.14931
2041.77	-0.715763
2042.75	-0.718597
2043.74	-0.707466
2044.72	-0.73354
2045.7	1.12432
2046.69	2.99729
2047.67	0.207187
2048.65	0.196593
2049.63	-0.74002
2050.62	-0.736465
2051.6	0.204493
2052.58	0.194953
2053.56	0.18536
2054.54	2.0506
2055.52	0.184657
2056.5	-0.747593
2057.48	-1.69039
2058.46	-0.756557
2059.45	1.11339
2060.43	0.179817
2061.4	-1.69433
2062.39	3.00002
2063.37	0.192179
2064.34	-0.747375
2065.32	1.13408
2066.3	-2.62909
2067.28	0.17537
2068.26	-0.751688
2069.24	-3.56757
2070.22	-1.69122
2071.2	0.188121
2072.18	0.194786
2073.15	1.15403
2074.13	0.202806
2075.11	2.07496
2076.09	-1.69614
2077.06	2.08994
2078.04	-0.745921
2079.02	-0.752485
2080	1.13591
2080.97	-0.759861
2081.95	0.181246
2082.93	-0.767515
2083.9	-0.760856
2084.88	-2.65318
2085.85	2.07641
2086.83	2.08125
2087.8	0.187056
2088.78	0.190158
2089.75	0.202518
2090.73	0.211811
2091.7	-0.736859
2092.68	2.10453
2093.65	-0.755207
2094.63	1.13281
2095.6	-0.774276
2096.57	1.11825
2097.55	1.11528
2098.52	-1.72854
2099.5	-0.78198
2100.47	0.15699
2101.44	1.10258
2102.41	-1.74232
2103.39	1.11282
2104.36	0.161723
2105.33	0.147509
2106.3	0.136713
2107.27	1.08953
2108.25	-0.813989
2109.22	-0.821774
2110.19	2.02829
2111.16	-0.81862
2112.13	0.127935
2113.1	-0.829197
2114.07	1.0604
2115.04	-0.844916
2116.01	1.98616
2116.99	1.97108
2117.96	0.0722466
2118.92	0.0795279
2119.9	-0.863403
2120.86	0.0853672
2121.83	1.01944
2122.8	0.994769
2123.77	0.0325022
2124.74	0.0224848
2125.71	0.962302
2126.68	-0.932742
2127.65	-0.937779
2128.61	0.942559
2129.58	0.93284
2130.55	-0.960446
2131.52	0.926597
2132.48	0.922781
2133.45	0.908896
2134.42	-0.0367117
2135.39	-0.0386534
2136.35	0.909109
2137.32	1.83329
2138.28	-1.94136
2139.25	0.875445
2140.22	-0.995796
2141.18	0.850866
2142.15	-1.02561
2143.12	-1.02769
2144.08	-1.97293
2145.05	-0.100957
2146.01	-0.10873
2146.98	0.814133
2147.94	1.74181
2148.9	0.810578
2149.87	-0.12888
2150.83	-1.07375
2151.8	-1.08839
2152.76	1.69759
2153.72	-0.180434
2154.69	-0.178826
2155.65	0.760407
2156.61	-1.11442
2157.58	1.67469
2158.54	-0.198585
2159.5	1.66509
2160.47	1.65981
2161.43	1.6518
2162.39	-1.14844
2163.35	0.714159
2164.31	0.70574
2165.27	2.54569
2166.24	0.685558
2167.2	-2.09094
2168.16	1.6344
2169.12	-0.247391
2170.08	-0.254236
2171.04	0.677252
2172	-0.249791
2172.96	2.53595
2173.92	1.60179
2174.88	1.60249
2175.84	1.59531
2176.8	0.667846
2177.76	0.666963
2178.72	2.52014
2179.68	1.5867
2180.64	1.57573
2181.59	-0.285178
2182.55	-1.20787
2183.51	0.655094
2184.47	0.671692
2185.43	-0.255836
2186.38	1.58866
2187.34	-0.276218
2188.3	1.58126
2189.26	1.58666
2190.21	0.666944
2191.17	0.685181
2192.13	2.54997
2193.08	-0.247231
2194.04	-0.260581
2195	3.44669
2195.95	1.60522
2196.91	1.62492
2197.86	0.721883
2198.82	1.64235
2199.78	2.55354
2200.73	2.56925
2201.69	2.60688
2202.64	1.63206
2203.59	2.56506
2204.55	-0.22447
2205.5	-0.213103
2206.46	-1.13737
2207.41	0.727773
2208.37	2.60093
2209.32	1.68046
2210.27	-0.186772
2211.23	1.67758
2212.18	2.62629
2213.13	1.69539
2214.09	2.62756
2215.04	-0.171759
2215.99	-0.168113
2216.94	0.774306
2217.9	-1.09444
2218.85	2.63117
2219.8	-1.10729
2220.75	0.7693
2221.7	-0.150425
2222.65	-0.138175
2223.6	1.74611
2224.55	-3.87012
2225.5	-0.120866
2226.46	3.62637
2227.41	0.825112
2228.36	0.83617
2229.31	0.847076
2230.26	2.73813
2231.21	-1.01786
2232.16	-0.0828362
2233.11	-1.0313
2234.05	-0.0892982
2235	1.80903
2235.95	0.882995
2236.9	1.82806
2237.85	3.70903
2238.8	-0.0566597
2239.75	-0.0533495
2240.69	0.884961
2241.64	-0.0597944
2242.59	0.900128
2243.54	1.85483
2244.48	0.913817
2245.43	0.910506
2246.38	1.85132
2247.32	0.904914
2248.27	1.83654
2249.22	0.887347
2250.16	0.901091
2251.11	0.913581
2252.06	2.8103
2253	-0.0355959
2253.95	0.918896
2254.89	0.923739
2255.84	-0.0260248
2256.78	1.87693
2257.73	-0.0221729
2258.67	1.88622
2259.62	-0.967875
2260.56	-1.91296
2261.51	3.82442
2262.45	0.970007
2263.39	-1.90257
2264.34	1.89969
2265.28	-0.976209
2266.22	0.930202
2267.17	1.89678
2268.11	-0.0074482
2269.05	-0.00452328
2270	2.86324
2270.94	-0.966904
2271.88	2.85876
2272.82	-0.0168066
2273.77	0.946609
2274.71	-0.962503
2275.65	-1.91644
2276.59	1.91512
2277.53	-0.0281258
2278.47	-0.0421228
2279.41	-1.00461
2280.36	1.87914
2281.3	-0.0241776
2282.24	0.942245
2283.18	-0.995259
2284.12	1.8932
2285.06	-0.026783
2286	0.921667
2286.94	1.85559
2287.88	2.80624
2288.82	1.85207
2289.75	0.893166
2290.69	-1.03263
2291.63	-2.00729
2292.57	-1.05892
2293.51	0.846629
2294.45	-0.118596
2295.39	0.851266
2296.32	-1.07366
2297.26	-1.07814
2298.2	-0.116068
2299.14	2.7743
2300.07	-2.06146
2301.01	-0.138285
2301.95	-0.13814
2302.89	0.826324
2303.82	0.823372
2304.76	-1.1204
2305.69	-1.13081
2306.63	-2.09728
2307.57	1.77262
2308.5	-1.14796
2309.44	0.758463
2310.37	-2.14612
2311.31	-0.205719
2312.24	-0.196335
2313.18	-1.18198
2314.11	1.69666
2315.05	0.733268
2315.98	-0.248821
2316.92	-0.260593
2317.85	-0.263935
2318.78	-0.259076
2319.72	-0.250766
2320.65	0.713894
2321.58	0.710427
2322.52	-1.2407
2323.45	-1.25358
2324.38	2.59005
2325.32	3.54572
2326.25	4.50148
2327.18	12.2016
2328.11	39.1581
2329.05	8.3556
2329.98	4.48791
2330.91	-0.331745
2331.84	-2.26317
2332.77	0.622267
2333.7	-1.29982
2334.63	-0.33701
2335.56	0.625155
2336.5	-3.21427
2337.43	-0.330207
2338.36	-0.336693
2339.29	2.53415
2340.22	0.619788
2341.15	-0.330475
2342.08	0.638301
2343.01	0.639333
2343.93	-0.3113
2344.86	0.657064
2345.79	2.59023
2346.72	0.674471
2347.65	0.646991
2348.58	0.719786
2349.51	1.6519
2350.44	-2.16824
2351.36	-0.24542
2352.29	-0.217607
2353.22	-2.10439
2354.15	-0.191899
2355.07	-1.12338
2356	3.6493
2356.93	-2.97496
2357.86	-1.05477
2358.78	-1.03302
2359.71	-0.0632658
2360.63	-0.98094
2361.56	-1.89415
2362.49	-0.915353
2363.41	0.994561
2364.34	0.109355
2364.8	0.137052