File: Data/3-Raman/processed/bu19(2)w-a-ff2b-fi01-v_1800 (450-850nm)_532nm_edge_100%_x100_vis_lwd_h100um_30sx2_01.txt
#Acq. time (s)=	30
#Accumulations=	2
#Range (cm-¹)=	1200...2365
#Windows=	3
#Auto scanning=	Off
#Autofocus=	Off
#Macrospot=	Off
#AutoExposure=	Off
#Spike filter=	Multiple accum.
#Delay time (s)=	2
#Binning=	1
#Readout mode=	Signal
#DeNoise=	Off
#ICS correction=	On
#Dark correction=	Off
#Inst. Process=	Off
#Detector Gain=	Best Dynamic
#Detector ADC=	50 kHz HS
#Detector temperature (°C)=	-60.09
#Instrument=	LabRAM HR Evol
#Detector=	SIN-EM FIVIS
#Objective=	x100_VIS_LWD
#Grating=	1800 (450-850nm)
#ND Filter=	100%
#Laser=	532nm_Edge
#Hole=	100.021
#Temperature=	0
#Range=	Visible
#StageXY=	75x50mm Scan+
#StageZ=	Z motor
#X (µm)=	0
#Y (µm)=	0
#Z (µm)=	-56.4
#Full time(mm:ss)=	3:17
#Project=	21_11_26
#Sample=	BU19(2)w
#Site=
#Title=	BU19(2)w-A-FF2b-FI01-V_1800 (450-850nm)_532nm_Edge_100%_x100_VIS_LWD_H100um_30sX2
#Remark=
#Date=	26.11.2021 16:06
#Acquired=	26.11.2021 16:06:58
#Base:Fit=	16.12.2021 16:00:56
#Base:Fit=	16.12.2021 16:09:03
#Base:Sub=	16.12.2021 16:09:05
1202.72	8.14634
1203.84	3.36349
1204.95	3.82567
1206.06	11.7067
1207.17	6.63186
1208.28	6.96885
1209.39	-2.34532
1210.5	2.26681
1211.61	-3.9156
1212.72	-6.89618
1213.83	1.85057
1214.94	-4.2746
1216.05	6.60573
1217.16	3.52082
1218.27	1.51247
1219.38	-4.71705
1220.49	1.78309
1221.6	-4.45543
1222.71	9.34588
1223.81	8.24404
1224.92	1.91218
1226.03	-0.108521
1227.14	-3.21833
1228.25	-3.32745
1229.35	-2.40636
1230.46	-1.1155
1231.57	4.99744
1232.67	2.90883
1233.78	0.793564
1234.89	-2.33569
1235.99	-7.57378
1237.1	3.94915
1238.2	9.06286
1239.31	-6.80548
1240.41	-1.63381
1241.52	0.420166
1242.62	-1.76113
1243.73	5.53947
1244.83	1.28004
1245.94	9.51601
1247.04	8.34735
1248.14	11.3896
1249.25	17.5355
1250.35	10.1306
1251.45	12.0576
1252.56	15.0396
1253.66	8.62691
1254.76	15.8968
1255.87	16.8675
1256.97	22.0218
1258.07	46.9708
1259.17	19.6809
1260.27	38.4557
1261.37	54.9304
1262.48	89.6375
1263.58	152.709
1264.68	107.338
1265.78	59.0042
1266.88	36.9801
1267.98	29.6934
1269.08	27.6685
1270.18	26.549
1271.28	15.9145
1272.38	23.184
1273.47	25.3382
1274.57	26.4274
1275.67	33.726
1276.77	28.5097
1277.87	41.1573
1278.97	58.0479
1280.07	92.7433
1281.16	214.726
1282.26	702.247
1283.36	2174.85
1284.45	1684.3
1285.55	332.94
1286.65	118.047
1287.75	66.3737
1288.84	38.9646
1289.94	41.1369
1291.03	29.5845
1292.13	25.3646
1293.22	17.9967
1294.32	30.7843
1295.42	10.7916
1296.51	13.1215
1297.61	18.4209
1298.7	12.062
1299.79	5.71806
1300.89	8.95536
1301.98	13.2406
1303.08	3.81187
1304.17	11.2293
1305.26	-2.44262
1306.35	1.7779
1307.45	4.99882
1308.54	-0.191849
1309.63	12.5752
1310.73	-8.42906
1311.82	7.50452
1312.91	3.41824
1314	-0.729797
1315.09	-9.06303
1316.18	6.9262
1317.28	0.689514
1318.37	2.94582
1319.46	-3.26611
1320.55	-8.42028
1321.64	-4.11473
1322.73	-0.881905
1323.82	-3.93279
1324.91	2.54192
1326	-1.57838
1327.09	-1.5516
1328.18	0.841637
1329.27	4.26029
1330.35	-1.91669
1331.44	-9.19122
1332.53	-2.8026
1333.62	-1.67463
1334.71	-3.68064
1335.79	0.636734
1336.88	-10.7591
1337.97	0.931145
1339.06	2.1096
1340.14	2.30074
1341.23	5.64616
1342.32	7.90928
1343.4	-9.74099
1344.49	-0.128464
1345.58	0.0452652
1346.66	4.32817
1347.75	-1.80824
1348.83	8.79626
1349.92	4.79067
1351	5.99142
1352.09	8.23559
1353.17	9.55257
1354.25	7.77979
1355.34	1.58832
1356.42	10.1241
1357.51	13.4326
1358.59	13.6138
1359.67	11.7167
1360.76	20.1649
1361.84	12.0898
1362.92	16.4415
1364	16.7134
1365.09	33.5242
1366.17	26.437
1367.25	23.4773
1368.33	27.856
1369.41	139.795
1370.5	34.5555
1371.58	27.4891
1372.66	30.6942
1373.74	37.0612
1374.82	39.3407
1375.9	47.8315
1376.98	36.7047
1378.06	55.4495
1379.14	62.0874
1380.22	77.733
1381.3	86.9458
1382.38	103.476
1383.46	140.417
1384.54	235.902
1385.61	569.958
1386.69	2968.92
1387.77	4016.28
1388.85	555.508
1389.93	198.638
1391	107.237
1392.08	76.6157
1393.16	67.5444
1394.23	48.3016
1395.31	48.546
1396.39	41.6653
1397.46	42.8839
1398.54	45.1555
1399.62	49.5413
1400.69	38.5657
1401.77	37.8336
1402.84	34.126
1403.92	41.6452
1404.99	44.8933
1406.07	68.6476
1407.14	124.199
1408.22	237.272
1409.29	254.006
1410.37	100.441
1411.44	44.1515
1412.51	35.1435
1413.59	27.4136
1414.66	19.3318
1415.73	19.5953
1416.81	20.8736
1417.88	13.9429
1418.95	15.2067
1420.02	16.4377
1421.1	20.7053
1422.17	12.7143
1423.24	20.2779
1424.31	17.1622
1425.38	13.2753
1426.45	7.34985
1427.52	10.5694
1428.59	0.473961
1429.67	12.9845
1430.74	7.0955
1431.81	2.24375
1432.87	7.53877
1433.95	0.47179
1435.01	7.85702
1436.08	5.99895
1437.15	2.07206
1438.22	3.26835
1439.29	7.57097
1440.36	5.74812
1441.43	4.91917
1442.49	3.03989
1443.56	16.5423
1444.63	9.52545
1445.7	9.74554
1446.77	4.76571
1447.83	4.91085
1448.9	6.11807
1449.97	6.27079
1451.03	9.47703
1452.1	1.41543
1453.17	2.59193
1454.23	2.75283
1455.3	4.94817
1456.36	1.00903
1457.43	2.15712
1458.49	-2.83098
1459.56	-4.73157
1460.62	2.57038
1461.69	-1.41372
1462.75	-2.33813
1463.82	-6.34008
1464.88	1.00131
1465.94	-0.0431671
1467.01	-1.97643
1468.07	0.176758
1469.13	-1.75164
1470.2	-2.68587
1471.26	1.479
1472.32	2.58134
1473.39	4.71786
1474.45	5.81602
1475.51	-6.28432
1476.57	2.95987
1477.63	4.05096
1478.69	4.12876
1479.76	0.125446
1480.82	-1.86397
1481.88	1.25301
1482.94	-1.66946
1484	-0.559204
1485.06	-5.6411
1486.12	0.506489
1487.18	1.60456
1488.24	-1.38216
1489.3	-4.38086
1490.36	1.74995
1491.42	1.79403
1492.48	0.8465
1493.53	-2.12598
1494.59	-1.05218
1495.65	-1.00917
1496.71	-0.994225
1497.77	-3.97693
1498.82	0.113705
1499.88	4.21647
1500.94	0.234486
1502	-1.75254
1503.05	1.30477
1504.11	-1.69813
1505.17	4.40127
1506.22	2.38274
1507.28	-6.64086
1508.34	-5.59423
1509.39	-1.52601
1510.45	4.56315
1511.5	-0.484039
1512.56	0.462624
1513.61	-0.563431
1514.67	-0.505726
1515.72	0.484669
1516.78	2.47223
1517.83	-1.52262
1518.88	0.522427
1519.94	5.57221
1520.99	-4.44748
1522.05	-2.41575
1523.1	3.5989
1524.15	-5.45997
1525.2	-2.46059
1526.26	0.574757
1527.31	-2.39738
1528.36	-1.40322
1529.41	-2.41414
1530.47	3.58736
1531.52	-1.38525
1532.57	2.61901
1533.62	1.67023
1534.67	1.6789
1535.72	-0.348808
1536.77	-0.413403
1537.82	3.53574
1538.87	0.50293
1539.92	4.57235
1540.97	3.64774
1542.02	-1.40079
1543.07	-0.451614
1544.12	3.48757
1545.17	4.50954
1546.22	2.54517
1547.27	1.5425
1548.32	-0.497009
1549.37	5.4679
1550.42	-0.534599
1551.46	0.589127
1552.51	1.5792
1553.56	5.54081
1554.61	4.48318
1555.65	5.42216
1556.7	-4.61686
1557.75	0.379662
1558.79	-4.68278
1559.84	1.24878
1560.89	-1.79426
1561.93	0.191917
1562.98	-4.80523
1564.02	1.16401
1565.07	7.18382
1566.11	-1.12132
1567.16	-0.95454
1568.2	-1.94266
1569.25	2.04313
1570.29	5.99162
1571.34	2.96708
1572.38	0.921066
1573.43	-1.13042
1574.47	5.82629
1575.51	0.855412
1576.56	-1.16279
1577.6	-2.24153
1578.64	1.66809
1579.69	-0.356045
1580.73	1.62521
1581.77	-5.40125
1582.81	-0.470829
1583.85	3.47699
1584.9	1.46004
1585.94	4.41831
1586.98	0.370609
1588.02	2.31508
1589.06	3.30034
1590.1	4.2879
1591.14	2.28371
1592.18	-2.73232
1593.22	0.183342
1594.26	5.05469
1595.3	0.0698242
1596.34	-1.95958
1597.38	-3.9675
1598.42	1.96885
1599.46	2.8915
1600.5	-0.14407
1601.54	-10.1291
1602.58	-2.27375
1603.62	1.6174
1604.66	2.5705
1605.69	0.573284
1606.73	4.52843
1607.77	-4.22733
1608.81	-1.08026
1609.84	2.92201
1610.88	3.22282
1611.92	-4.04387
1612.95	2.98913
1613.99	-2.05858
1615.03	-2.43295
1616.06	1.38058
1617.1	0.738998
1618.13	4.69271
1619.17	6.30287
1620.2	2.96371
1621.24	3.03843
1622.27	3.73075
1623.31	3.80001
1624.34	1.16425
1625.38	0.959934
1626.41	1.31292
1627.45	2.81045
1628.48	2.17114
1629.51	3.7395
1630.55	4.1348
1631.53	6.86799
1632.57	-0.0197105
1633.62	5.87617
1634.66	6.86209
1635.71	5.86073
1636.75	6.81339
1637.8	-1.10311
1638.84	5.7644
1639.89	5.75546
1640.93	6.74028
1641.98	-0.159203
1643.02	4.7461
1644.06	7.68415
1645.11	0.769417
1646.15	3.73032
1647.19	3.70699
1648.24	-0.246136
1649.28	3.72853
1650.32	4.70898
1651.37	3.76742
1652.41	4.76122
1653.45	2.77872
1654.49	-0.167152
1655.53	9.71251
1656.57	3.84953
1657.62	6.81394
1658.66	3.83839
1659.7	3.81363
1660.74	2.8244
1661.78	-0.0961304
1662.82	4.89959
1663.86	2.93593
1664.9	4.88567
1665.94	5.81433
1666.98	3.91277
1668.02	1.92141
1669.06	-2.00769
1670.1	1.98491
1671.14	3.01923
1672.18	-1.91983
1673.21	1.06248
1674.25	3.06394
1675.29	1.12621
1676.33	1.15114
1677.37	2.16004
1678.4	-2.79363
1679.44	-3.79397
1680.48	4.11362
1681.52	3.12607
1682.55	4.1306
1683.59	-5.73296
1684.63	-2.76094
1685.66	0.212799
1686.7	1.22496
1687.73	-2.69447
1688.77	-1.70419
1689.81	1.24745
1690.84	0.271477
1691.88	-1.66289
1692.91	2.30248
1693.95	2.28026
1694.98	-1.67072
1696.01	2.3014
1697.05	-1.60186
1698.08	-0.6255
1699.12	1.33896
1700.15	1.36395
1701.18	-3.53944
1702.22	4.33365
1703.25	4.33177
1704.28	3.36573
1705.32	-2.4914
1706.35	1.4584
1707.38	1.44524
1708.41	4.36602
1709.44	3.35797
1710.48	3.3786
1711.51	-4.40793
1712.54	0.52322
1713.57	-1.46758
1714.6	-3.43311
1715.63	0.507034
1716.66	-0.437546
1717.69	2.46806
1718.72	-7.31376
1719.75	2.44281
1720.78	1.50147
1721.81	-1.42109
1722.84	4.403
1723.87	2.46061
1724.9	0.540169
1725.93	-0.45443
1726.96	0.534557
1727.99	-5.25481
1729.02	1.47404
1730.05	2.43123
1731.07	3.40627
1732.1	2.53182
1733.13	2.54973
1734.16	2.52638
1735.18	-2.31142
1736.21	1.53735
1737.24	1.55426
1738.26	1.56598
1739.29	-0.356445
1740.32	4.41255
1741.34	2.47947
1742.37	3.44345
1743.4	1.55301
1744.42	4.43889
1745.45	3.51075
1746.47	2.57528
1747.5	-0.300461
1748.52	1.62142
1749.55	-4.05883
1750.57	3.65526
1751.6	5.62553
1752.62	5.61821
1753.64	10.3869
1754.67	3.70922
1755.69	3.72255
1756.71	3.71933
1757.74	0.855198
1758.76	3.76144
1759.78	3.80362
1760.81	0.0230103
1761.83	-1.86871
1762.85	3.86977
1763.87	2.96157
1764.89	2.08075
1765.92	2.13726
1766.94	0.266605
1767.96	6.95189
1768.98	4.1134
1770	7.86408
1771.02	2.22583
1772.04	9.90465
1773.06	1.40676
1774.08	5.26816
1775.1	5.3182
1776.12	6.35141
1777.14	9.24495
1778.16	3.53112
1779.18	7.33413
1780.2	12.1173
1781.22	5.50446
1782.24	8.40773
1783.26	4.66173
1784.28	3.76406
1785.29	-0.944378
1786.31	-2.83139
1787.33	3.89823
1788.35	2.1019
1789.37	5.0685
1790.38	-1.57025
1791.4	2.28777
1792.42	3.24065
1793.43	6.1571
1794.45	0.4459
1795.47	6.26501
1796.48	-1.33632
1797.5	0.643391
1798.51	-0.270859
1799.53	0.712727
1800.55	0.710228
1801.56	2.64388
1802.58	1.71652
1803.59	-0.151882
1804.61	3.73756
1805.62	2.8357
1806.64	0.00255585
1807.65	-1.89193
1808.66	4.87905
1809.68	4.90679
1810.69	-3.74405
1811.7	0.1273
1812.72	1.11743
1813.73	2.1231
1814.74	0.249207
1815.76	6.09693
1816.77	3.22486
1817.78	4.18198
1818.79	3.23947
1819.8	1.33535
1820.82	5.23812
1821.83	-4.39962
1822.84	7.2453
1823.85	0.483238
1824.86	5.33829
1825.87	0.525597
1826.88	0.540127
1827.89	-4.28048
1828.9	3.47938
1829.91	0.570606
1830.92	-1.37193
1831.93	2.52625
1832.94	2.56027
1833.95	1.61078
1834.96	5.46545
1835.97	3.46856
1836.98	2.66374
1837.99	3.5032
1839	0.601723
1840	0.662018
1841.01	3.48815
1842.02	5.34325
1843.03	4.34253
1844.04	4.34473
1845.04	0.489136
1846.05	3.397
1847.06	-1.38975
1848.07	6.17938
1849.07	-0.552132
1850.08	-1.54553
1851.09	0.327522
1852.09	0.298901
1853.1	4.13456
1854.1	-2.60544
1855.11	-5.52499
1856.11	1.14308
1857.12	-0.783813
1858.12	-0.804138
1859.13	1.071
1860.13	1.99156
1861.14	0.0893784
1862.14	0.103485
1863.15	-2.80013
1864.15	0.980457
1865.15	1.89534
1866.16	0.878647
1867.16	1.75148
1868.16	0.737301
1869.17	0.721218
1870.17	-2.14984
1871.17	0.68251
1872.17	1.60442
1873.18	2.51509
1874.18	4.38221
1875.18	-1.36237
1876.18	2.35342
1877.18	-0.544399
1878.18	-5.33932
1879.19	-1.5139
1880.19	0.393917
1881.19	-0.574757
1882.19	3.13128
1883.19	2.07916
1884.19	-2.69644
1885.19	-1.75322
1886.19	2.05302
1887.19	0.139885
1888.19	0.0810623
1889.19	-0.935459
1890.19	-1.91978
1891.19	-0.0333786
1892.18	1.81979
1893.18	0.83786
1894.18	-3.94669
1895.18	-3.04672
1896.18	3.52069
1897.18	5.40723
1898.17	1.63322
1899.17	-0.295452
1900.17	-0.347187
1901.16	-5.07032
1902.16	3.39421
1903.16	5.26699
1904.16	-4.17825
1905.15	0.490368
1906.15	0.448193
1907.14	-4.30243
1908.14	1.31105
1909.14	0.362946
1910.13	1.31413
1911.13	2.2799
1912.12	-3.38685
1913.12	0.346832
1914.11	1.28112
1915.11	0.351051
1916.1	2.22569
1917.1	4.06254
1918.09	-3.52957
1919.08	0.23978
1920.08	-3.51027
1921.07	-1.64239
1922.06	-4.47639
1923.06	3.99925
1924.05	3.95131
1925.04	1.06606
1926.04	-0.825138
1927.03	2.97678
1928.02	5.81626
1929.01	-1.77341
1930	-2.71896
1931	1.08999
1931.99	3.90369
1932.98	-0.895576
1933.97	5.72395
1934.96	2.02339
1935.95	1.13473
1936.94	2.97008
1937.93	1.9496
1938.92	-0.938496
1939.91	-3.80298
1940.9	0.00657654
1941.89	-2.84759
1942.88	0.95787
1943.87	-1.95854
1944.86	-1.00492
1945.85	-2.90625
1946.84	-0.0403481
1947.83	-5.81329
1948.82	-2.97843
1949.8	-2.98241
1950.79	0.875557
1951.78	2.83201
1952.77	-3.88298
1953.76	0.895962
1954.74	-1.13973
1955.73	1.68532
1956.72	6.53008
1957.7	5.58785
1958.69	2.70131
1959.68	-1.1838
1960.66	-0.271049
1961.65	4.4719
1962.63	5.40643
1963.62	-5.17157
1964.61	-1.34485
1965.59	-1.37538
1966.58	-0.418221
1967.56	-2.34595
1968.55	-2.36381
1969.53	0.472584
1970.52	1.3607
1971.5	3.22956
1972.48	9.92052
1973.47	-1.6234
1974.45	7.913
1975.44	5.01857
1976.42	5.9799
1977.4	2.12456
1978.39	7.83289
1979.37	6.83727
1980.35	10.6551
1981.33	6.7738
1982.31	4.82022
1983.3	11.4721
1984.28	6.63266
1985.26	16.1523
1986.24	12.2913
1987.22	14.2047
1988.21	7.45696
1989.19	9.21772
1990.17	11.7202
1991.15	14.4104
1992.13	11.7973
1993.11	16.416
1994.09	12.124
1995.07	16.9939
1996.05	10.2933
1997.03	13.3594
1998.01	18.8784
1998.99	13.8167
1999.97	15.4981
2000.95	15.9596
2001.92	17.6275
2002.9	16.2432
2003.88	16.9341
2004.86	17.8143
2005.84	16.5734
2006.81	17.8988
2007.79	14.1625
2008.77	17.893
2009.75	18.8092
2010.73	19.9489
2011.7	13.2805
2012.68	19.6101
2013.67	10.1363
2014.66	13.81
2015.64	12.8497
2016.63	17.5702
2017.62	19.491
2018.61	15.659
2019.6	12.7666
2020.58	15.5569
2021.57	14.6264
2022.56	17.4252
2023.55	8.9566
2024.54	10.7895
2025.52	13.5281
2026.51	14.4231
2027.5	6.1596
2028.48	9.84979
2029.47	7.13211
2030.45	7.92826
2031.44	7.95986
2032.43	9.84544
2033.41	10.8561
2034.4	5.26566
2035.38	5.20716
2036.37	7.18918
2037.35	9.05824
2038.34	7.18819
2039.32	6.23829
2040.31	9.94664
2041.29	8.97937
2042.27	4.31201
2043.26	0.582687
2044.24	4.379
2045.23	-1.22388
2046.21	5.41469
2047.19	-1.14328
2048.17	4.41864
2049.16	6.31453
2050.14	8.25417
2051.12	2.70642
2052.11	3.63631
2053.09	2.73846
2054.07	1.87238
2055.05	3.77962
2056.03	0.976379
2057.01	5.66006
2058	0.0853348
2058.98	3.88386
2059.96	2.99369
2060.94	-0.740303
2061.92	1.174
2062.9	0.273304
2063.88	-4.36049
2064.86	3.18043
2065.84	1.37275
2066.82	0.487339
2067.8	3.35191
2068.78	6.22085
2069.76	0.59935
2070.73	2.50421
2071.71	4.44234
2072.69	0.768635
2073.67	-0.149414
2074.65	2.71658
2075.63	2.80096
2076.6	0.991558
2077.58	-1.8274
2078.56	4.79914
2079.54	1.08133
2080.51	1.15536
2081.49	4.02205
2082.47	-0.668617
2083.45	-1.57441
2084.42	-1.54277
2085.4	2.27344
2086.37	2.32196
2087.35	-0.448887
2088.32	-2.29521
2089.3	3.4262
2090.28	-5.03378
2091.25	-2.14387
2092.23	-2.07916
2093.2	0.852825
2094.18	-0.0225182
2095.15	1.92352
2096.13	-1.8633
2097.1	1.96371
2098.07	0.0771904
2099.05	3.90166
2100.02	2.03511
2101	3.97949
2101.97	-2.60415
2102.94	-5.4181
2103.92	-4.44741
2104.89	-1.55373
2105.86	-1.48958
2106.83	0.46719
2107.8	4.31098
2108.78	-0.441673
2109.75	0.547092
2110.72	3.44437
2111.69	-0.319633
2112.66	-0.292301
2113.63	0.718487
2114.61	-2.08752
2115.58	4.60384
2116.55	1.77378
2117.52	-4.84949
2118.49	1.82129
2119.46	-1.97273
2120.43	1.82954
2121.4	0.930019
2122.37	-2.79087
2123.34	0.116352
2124.31	-3.64441
2125.28	-0.806492
2126.25	-0.819183
2127.21	2.02333
2128.18	-2.6818
2129.15	1.13176
2130.12	3.05078
2131.09	2.13231
2132.06	0.258915
2133.02	1.21778
2133.99	-3.46442
2134.96	-1.53772
2135.93	-3.39532
2136.89	5.09425
2137.86	-3.34607
2138.83	3.27615
2139.79	1.43657
2140.76	3.32438
2141.73	3.34987
2142.69	0.540657
2143.66	1.54707
2144.62	1.50594
2145.59	-2.21824
2146.55	-2.19008
2147.52	2.52858
2148.48	-6.84897
2149.45	-3.0789
2150.42	-2.14714
2151.38	3.50167
2152.34	4.49218
2153.31	0.76075
2154.27	-1.10056
2155.24	-0.183331
2156.2	3.53762
2157.16	3.55392
2158.13	0.797169
2159.09	1.76789
2160.05	2.7098
2161.01	-1.96294
2161.98	0.852867
2162.94	1.8126
2163.9	1.82444
2164.86	-1.90192
2165.83	0.920902
2166.79	1.87236
2167.75	0.940327
2168.71	-4.66294
2169.67	-3.6952
2170.63	-0.83564
2171.59	1.97301
2172.56	-2.71272
2173.51	1.94518
2174.48	2.9092
2175.44	8.5104
2176.4	-2.62652
2177.36	2.03067
2178.32	0.197243
2179.28	-0.730797
2180.23	2.0784
2181.19	1.16469
2182.15	1.17318
2183.11	2.10711
2184.07	2.09158
2185.03	-1.60762
2185.99	5.83944
2186.95	2.18081
2187.9	0.383152
2188.86	-0.542923
2189.82	6.85584
2190.78	2.21918
2191.73	-6.10103
2192.69	-0.509937
2193.65	-1.40181
2194.6	3.31066
2195.56	3.32134
2196.52	2.3677
2197.47	3.27365
2198.43	-2.27938
2199.38	4.27221
2200.34	12.7127
2201.3	2.55857
2202.25	6.15849
2203.21	-3.06095
2204.16	6.40276
2205.12	1.67701
2206.07	5.31679
2207.03	8.11171
2207.98	1.63573
2208.93	6.32969
2209.89	1.69482
2210.84	3.57634
2211.8	1.74474
2212.75	-0.089241
2213.7	-1.9623
2214.66	0.859394
2215.61	-1.91164
2216.56	-0.970066
2217.51	1.83221
2218.47	2.7737
2219.42	-0.00606155
2220.37	1.8863
2221.32	0.948521
2222.27	3.72008
2223.23	0.925251
2224.18	-3.71294
2225.13	1.00143
2226.08	0.103352
2227.03	-0.80294
2227.98	0.156021
2228.93	-3.6006
2229.88	2.96671
2230.83	6.75617
2231.78	-0.719257
2232.73	2.12983
2233.68	0.277061
2234.63	-3.47301
2235.58	3.08846
2236.53	-3.49919
2237.48	2.1588
2238.43	-0.614933
2239.38	1.31408
2240.33	3.18453
2241.27	-0.571758
2242.22	-2.44965
2243.17	2.28194
2244.12	1.32325
2245.07	-3.3811
2246.01	0.43845
2246.96	-2.37519
2247.91	1.42532
2248.85	2.36455
2249.8	0.472561
2250.75	3.30356
2251.69	2.32829
2252.64	-0.499588
2253.59	1.44493
2254.53	1.47861
2255.48	-0.413612
2256.42	-2.30127
2257.37	1.51836
2258.32	-2.26167
2259.26	-1.29969
2260.2	-0.333393
2261.15	-0.316666
2262.1	0.658218
2263.04	-0.273823
2263.98	-3.09179
2264.93	2.68251
2265.87	-1.11142
2266.81	-1.12631
2267.76	-2.10492
2268.7	-2.12283
2269.65	-2.09872
2270.59	0.811646
2271.53	3.70895
2272.47	-0.0921249
2273.42	-2.95258
2274.36	3.7578
2275.3	-4.84491
2276.24	-1.96048
2277.18	1.90864
2278.13	1.96312
2279.07	0.0725708
2280.01	2.93188
2280.95	0.0237122
2281.89	1.93059
2282.83	-3.79675
2283.77	0.0867805
2284.71	1.1136
2285.65	3.06991
2286.59	0.169987
2287.54	-0.745399
2288.47	-3.61068
2289.41	-1.70104
2290.35	0.188702
2291.29	2.12425
2292.23	3.13456
2293.17	1.25035
2294.11	1.27955
2295.05	1.27132
2295.99	-1.62592
2296.93	-3.56548
2297.86	0.317776
2298.8	3.25655
2299.74	-0.55579
2300.68	-0.540249
2301.61	1.42207
2302.55	3.36527
2303.49	2.40972
2304.43	-1.427
2305.36	0.540024
2306.3	-0.398087
2307.24	3.48934
2308.17	1.5597
2309.11	-0.361938
2310.04	-1.28262
2310.98	-0.288906
2311.92	0.639042
2312.85	1.58699
2313.79	5.47438
2314.72	-3.15657
2315.66	0.748016
2316.59	0.719006
2317.52	0.720943
2318.46	2.67434
2319.39	-0.228893
2320.33	2.67023
2321.26	1.73059
2322.2	4.67538
2323.13	6.64874
2324.06	12.4756
2325	12.4759
2325.93	32.7164
2326.86	93.4585
2327.79	344.026
2328.73	172.39
2329.66	49.938
2330.59	20.0841
2331.52	7.56697
2332.46	-0.118366
2333.39	0.831936
2334.32	1.78545
2335.25	0.805763
2336.18	-3.03471
2337.11	2.73123
2338.04	4.64938
2338.97	2.7218
2339.91	5.60732
2340.84	3.6636
2341.77	1.6965
2342.7	6.45805
2343.63	-1.22354
2344.56	5.47953
2345.49	-1.2453
2346.41	0.632641
2347.34	-2.26225
2348.27	-1.32047
2349.2	-1.33458
2350.13	3.37555
2351.06	0.317986
2351.99	0.433079
2352.91	-0.601891
2353.84	0.270477
2354.77	-5.47812
2355.7	3.06123
2356.63	1.09014
2357.55	0.0514221
2358.48	4.73663
2359.41	-1.98237
2360.33	2.69133
2361.26	4.4946
2362.19	-1.29371
2363.11	-2.34081
2364.04	-0.538792
2364.97	0.310837