File: Data/3-Raman/processed/bu19(2)w-a-ff1-fi01-v_150 (500nm)_532nm_edge_100%_x100_vis_lwd_h50um_30sx2_01.txt
#Acq. time (s)=	30
#Accumulations=	2
#Range (cm-¹)=	99...4000
#Windows=	1
#Auto scanning=	Off
#Autofocus=	Off
#Macrospot=	Off
#AutoExposure=	Off
#Spike filter=	Multiple accum.
#Delay time (s)=	2
#Binning=	1
#Readout mode=	Signal
#DeNoise=	Off
#ICS correction=	On
#Dark correction=	Off
#Inst. Process=	Off
#Detector Gain=	Best Dynamic
#Detector ADC=	50 kHz HS
#Detector temperature (°C)=	-60.09
#Instrument=	LabRAM HR Evol
#Detector=	SIN-EM FIVIS
#Objective=	x100_VIS_LWD
#Grating=	150 (500nm)
#ND Filter=	100%
#Laser=	532nm_Edge
#Hole=	49.98
#Temperature=	0
#Range=	Visible
#StageXY=	75x50mm Scan+
#StageZ=	Z motor
#X (µm)=	0
#Y (µm)=	0
#Z (µm)=	-47.2
#Full time(mm:ss)=	1:05
#Project=	21_11_26
#Sample=	BU19(2)w
#Site=
#Title=	BU19(2)w-A-FF1-FI01-V_150 (500nm)_532nm_Edge_100%_x100_VIS_LWD_H50um_30sX2
#Remark=
#Date=	26.11.2021 11:42
#Acquired=	26.11.2021 11:42:58
#Base:Fit=	16.12.2021 16:00:56
#Base:Edit=	16.12.2021 16:04:12
#Base:Sub=	16.12.2021 16:04:16
102.91	4529.53
107.534	3601.54
112.156	3046.67
116.775	2870.38
121.392	2950.16
126.005	2435.64
130.617	1738.09
135.227	1265.36
139.835	1154.79
144.439	1345.94
149.042	2049.98
153.643	3521.92
158.242	4570.18
162.839	3797.06
167.431	2220.85
172.023	1155.78
176.613	666.922
181.198	352.205
185.783	162.464
190.366	68.2444
194.947	46.2963
199.524	-0.0239258
204.1	0.255188
208.674	71.5936
213.243	336.354
217.813	1022.04
222.38	1256.62
226.945	547.272
231.506	189.141
236.066	235.977
240.625	665.202
245.179	1267.26
249.732	1010.45
254.284	386.64
258.831	105.125
263.378	-0.325928
267.923	10.3029
272.464	16.5791
277.004	10.0788
281.54	13.917
286.076	74.2268
290.61	169.388
295.139	147.813
299.669	79.4142
304.196	54.0374
308.718	69.3027
313.241	68.7435
317.759	79.7924
322.278	118.667
326.794	158.568
331.305	202.005
335.817	313.812
340.324	543.476
344.832	696.156
349.334	642.28
353.837	579.428
358.338	727.166
362.834	909.438
367.33	735.169
371.822	481.891
376.314	380.667
380.802	367.086
385.289	395.546
389.772	485.612
394.255	731.616
398.734	1280.53
403.213	1883.28
407.688	1949.04
412.162	1664.21
416.632	1353.27
421.102	1117.06
425.568	972.57
430.033	988.104
434.495	1101.15
438.956	1245.42
443.413	1198.5
447.87	1183.88
452.323	1165.14
456.776	1237.75
461.224	1362.76
465.673	1275.6
470.117	996.659
474.561	709.343
479.001	534.741
483.438	457.218
487.876	434.391
492.309	460.63
496.742	581.258
501.172	761.241
505.601	1048.14
510.025	1503.24
514.448	2048.14
518.871	2575.28
523.289	2677.83
527.707	2408.83
532.121	1990.87
536.533	1674.64
540.945	1495.81
545.353	1466.11
549.758	1467.72
554.164	1505.05
558.565	1527.47
562.965	1467.06
567.364	1341.27
571.759	1095.74
576.151	903.382
580.544	757.768
584.933	608.659
589.319	540.348
593.706	559.085
598.088	557.021
602.468	667.694
606.848	824.086
611.224	1020.3
615.598	1306.24
619.972	1860.59
624.341	3170.39
628.709	5083.28
633.074	5381.57
637.44	3642.74
641.801	2038.51
646.16	1232.94
650.517	788.131
654.874	564.852
659.227	411.415
663.578	317.114
667.927	258.237
672.275	195.072
676.62	158.08
680.962	130.304
685.302	117.21
689.643	88.5601
693.979	83.9848
698.313	104.375
702.645	130.62
706.975	166.519
711.305	239.819
715.631	242.686
719.955	228.326
724.276	154.065
728.596	117.538
732.913	87.9036
737.231	98.1605
741.544	81.8299
745.856	27.9441
750.165	27.9105
754.472	17.4019
758.778	14.1997
763.081	23.3974
767.384	12.2911
771.683	1.70248
775.98	-1.36964
780.275	11.3654
784.568	15.3197
788.859	10.6717
793.147	2.84024
797.434	29.0608
801.719	30.0748
806.004	39.0387
810.284	36.0541
814.563	48.5543
818.839	60.0515
823.114	81.4959
827.386	98.6892
831.657	142.414
835.925	179.63
840.192	278.66
844.456	410.869
848.719	516.461
852.979	642.539
857.237	682.548
861.493	583.716
865.748	497.002
870	409.131
874.25	346.618
878.499	317.061
882.745	307.213
886.989	350.722
891.231	387.156
895.471	323.253
899.71	207.565
903.946	129.91
908.18	76.6783
912.412	61.0864
916.642	20.904
920.87	21.8285
925.096	18.3671
929.321	-1.33121
933.543	9.45226
937.763	13.7795
941.981	-6.58142
946.197	-5.49648
950.412	-0.124756
954.622	6.39459
958.832	15.083
963.04	13.1834
967.246	16.6548
971.451	30.7914
975.653	19.5455
979.853	26.3867
984.052	43.8921
988.248	35.9946
992.442	52.4921
996.633	84.053
1000.82	118.01
1005.01	160.63
1009.2	196.004
1013.38	195.333
1017.57	176.454
1021.75	129.814
1025.92	139.586
1030.1	119.344
1034.27	121.419
1038.45	137.015
1042.62	164.088
1046.78	208.106
1050.95	301.775
1055.12	425.712
1059.28	462.201
1063.44	449.793
1067.6	425.703
1071.75	449.92
1075.91	503.198
1080.06	586.331
1084.21	773.517
1088.36	1006.08
1092.51	1422
1096.65	2063.3
1100.8	3087.87
1104.94	3724.12
1109.08	3310.18
1113.21	2218.92
1117.35	1295.08
1121.48	836.984
1125.61	598.674
1129.74	492.853
1133.87	470.834
1137.99	494.699
1142.12	542.218
1146.24	723.819
1150.36	990.228
1154.48	1157.53
1158.59	1138.74
1162.71	912.172
1166.82	654.249
1170.93	464.318
1175.04	347.559
1179.14	254.58
1183.25	185.425
1187.35	146.109
1191.45	118.003
1195.55	76.6084
1199.65	66.9749
1203.74	70.5657
1207.83	72.0883
1211.92	51.3363
1216.01	65.0538
1220.1	62.6087
1224.19	71.2692
1228.27	84.9608
1232.35	109.708
1236.43	125.609
1240.51	158.65
1244.58	167.609
1248.66	222.607
1252.73	348.702
1256.8	707.735
1260.87	706.469
1264.93	456.257
1269	439.019
1273.06	1214.7
1277.12	6592.14
1281.18	5431.31
1285.23	1304.97
1289.29	440.819
1293.34	336.609
1297.39	298.685
1301.44	250.599
1305.49	219.532
1309.53	208.581
1313.58	204.634
1317.62	207.603
1321.66	205.446
1325.7	199.126
1329.73	202.813
1333.77	212.469
1337.8	195.912
1341.83	211.357
1345.86	230.696
1349.88	236.99
1353.91	241.274
1357.93	338.92
1361.95	469.877
1365.97	537.129
1369.99	500.498
1374	707.912
1378.02	3375.89
1382.03	12707.7
1386.04	6355.02
1390.05	1177.76
1394.05	526.073
1398.06	535.116
1402.06	1070.11
1406.06	980.693
1410.06	395.493
1414.05	245.713
1418.05	214.18
1422.04	168.777
1426.03	139.085
1430.02	113.186
1434.01	82.3631
1438	75.2261
1441.98	55.2462
1445.96	49.0516
1449.94	34.9437
1453.92	29.6844
1457.9	42.1489
1461.87	21.0627
1465.85	15.7022
1469.82	9.3512
1473.78	7.93258
1477.75	7.47054
1481.72	4.04324
1485.68	4.52023
1489.65	-4.79426
1493.61	2.50534
1497.56	-0.941956
1501.52	-6.32517
1505.47	2.90192
1509.43	-2.44128
1513.38	0.962448
1517.33	-5.34898
1521.27	6.78339
1525.22	10.1744
1529.16	0.957512
1533.11	-0.495255
1537.05	0.952675
1540.98	-3.42133
1544.92	0.916924
1548.86	12.9951
1552.79	0.841217
1556.72	4.1642
1560.65	-2.22383
1564.58	-2.82225
1568.5	2.36184
1572.43	5.58835
1576.35	1.07353
1580.27	5.23624
1584.19	1.66662
1588.1	8.68285
1592.02	16.6377
1595.93	7.2564
1599.84	6.5313
1603.75	16.369
1607.66	5.09452
1611.57	18.7596
1615.47	20.9089
1619.37	26.8974
1623.27	20.4164
1627.17	20.6524
1631.07	16.1115
1634.97	22.1305
1638.86	22.3929
1642.75	18.8497
1646.64	34.4845
1650.53	26.1739
1654.42	20.7285
1658.3	26.7785
1662.18	16.4908
1666.07	23.4616
1669.94	19.8406
1673.82	20.9798
1677.7	29.7941
1681.57	17.3897
1685.44	22.2431
1689.31	19.399
1693.18	17.4874
1697.05	5.03526
1700.92	22.202
1704.78	12.5846
1708.64	26.7632
1712.5	12.3628
1716.36	17.9192
1720.21	20.615
1724.07	18.5787
1727.92	24.0698
1731.77	21.9938
1735.62	28.3708
1739.47	24.4091
1743.32	16.7127
1747.16	13.71
1751.01	29.373
1754.85	18.1137
1758.69	30.1274
1762.52	17.2918
1766.36	37.7764
1770.19	34.1723
1774.02	30.6242
1777.85	31.7227
1781.68	31.0005
1785.51	19.0919
1789.33	18.3752
1793.16	12.9746
1796.98	16.9378
1800.8	16.2062
1804.62	7.86694
1808.43	18.3358
1812.25	17.495
1816.06	11.9123
1819.87	17.5952
1823.68	10.0362
1827.49	12.8328
1831.3	12.7652
1835.1	4.18594
1838.9	15.3696
1842.71	7.70389
1846.51	15.9939
1850.3	10.2054
1854.1	1.57038
1857.89	10.6972
1861.69	7.62514
1865.48	9.2055
1869.27	5.21762
1873.05	4.03625
1876.84	8.42822
1880.62	14.6566
1884.4	8.008
1888.19	15.1891
1891.96	13.2873
1895.74	4.02787
1899.52	9.49144
1903.29	14.0827
1907.06	17.7788
1910.83	11.3564
1914.6	8.65404
1918.37	9.64621
1922.13	7.93813
1925.9	12.7186
1929.66	9.1846
1933.42	10.2965
1937.18	14.2054
1940.94	12.5245
1944.69	3.35052
1948.44	19.4474
1952.2	15.7935
1955.95	11.1464
1959.69	18.6475
1963.44	21.4138
1967.19	13.8436
1970.93	19.3829
1974.67	23.933
1978.41	31.2599
1982.15	39.4837
1985.89	45.7933
1989.62	54.8669
1993.35	47.1226
1997.09	55.1801
2000.82	54.8277
2004.55	58.1884
2008.27	57.8231
2012	58.3431
2015.72	53.3503
2019.44	42.9472
2023.16	48.2388
2026.88	41.7043
2030.6	33.3562
2034.31	32.4031
2038.03	33.3303
2041.74	36.0778
2045.45	27.8296
2049.16	20.5009
2052.86	21.4388
2056.57	20.5541
2060.27	16.066
2063.98	17.1526
2067.67	20.1131
2071.37	12.9606
2075.07	11.3242
2078.77	13.3909
2082.46	8.06349
2086.15	10.1292
2089.84	-7.4357
2093.53	4.67023
2097.22	14.0506
2100.9	4.82306
2104.59	7.64697
2108.27	18.8243
2111.95	14.1742
2115.63	1.15793
2119.31	6.72434
2122.98	6.67177
2126.66	-4.53419
2130.33	1.87608
2134	3.63605
2137.67	14.6292
2141.34	4.34755
2145	12.5112
2148.67	4.08536
2152.33	7.62565
2155.99	-0.756866
2159.65	3.7074
2163.31	-1.87952
2166.96	0.780945
2170.62	0.720299
2174.27	-1.11764
2177.92	1.62344
2181.57	4.37777
2185.22	2.57905
2188.87	-0.0985565
2192.51	2.72323
2196.15	6.50236
2199.8	1.20202
2203.44	5.02508
2207.07	-2.08159
2210.71	-4.61618
2214.35	4.75926
2217.98	1.33259
2221.61	-1.18231
2225.24	0.90078
2228.87	4.82697
2232.5	4.15591
2236.12	5.3414
2239.75	-2.72761
2243.37	12.3539
2246.99	-2.2337
2250.61	5.45887
2254.23	2.01018
2257.85	-1.44048
2261.46	2.5748
2265.07	13.148
2268.68	4.06861
2272.29	2.49958
2275.9	3.72257
2279.51	3.03548
2283.11	3.22408
2286.72	13.8008
2290.32	0.763229
2293.92	4.71885
2297.52	-2.67308
2301.11	-1.54742
2304.71	11.8811
2308.3	14.8723
2311.9	16.9015
2315.49	18.9142
2319.08	93.8827
2322.66	662.335
2326.25	607.738
2329.84	149.53
2333.42	22.8273
2337	13.355
2340.58	15.1928
2344.16	22.6533
2347.73	16.938
2351.31	22.4742
2354.88	13.962
2358.45	11.0738
2362.03	8.19011
2365.59	20.1856
2369.16	12.6639
2372.73	16.3077
2376.29	14.3844
2379.85	13.3933
2383.41	14.2617
2386.97	16.9779
2390.53	17.868
2394.09	16.0254
2397.64	8.71826
2401.2	14.285
2404.75	9.82731
2408.3	19.1307
2411.85	9.22707
2415.39	18.6109
2418.94	7.8207
2422.48	14.5029
2426.03	17.5418
2429.57	14.155
2433.11	8.92554
2436.64	11.111
2440.18	18.8896
2443.72	6.22251
2447.25	14.9664
2450.78	18.1586
2454.31	16.692
2457.84	8.56027
2461.37	6.90256
2464.89	4.28634
2468.42	6.29827
2471.94	3.66983
2475.46	6.54136
2478.98	14.1068
2482.5	9.42506
2486.01	9.41871
2489.53	4.64605
2493.04	7.45045
2496.55	11.1282
2500.06	15.7665
2503.57	4.45281
2507.08	14.6344
2510.58	8.90912
2514.09	7.86143
2517.59	-0.591927
2521.09	8.6164
2524.59	5.68809
2528.09	4.71234
2531.59	9.30301
2535.08	10.2059
2538.58	12.0575
2542.07	16.697
2545.56	8.46507
2549.05	11.3474
2552.54	7.76537
2556.02	6.97604
2559.51	6.22904
2562.99	10.1189
2566.47	1.97191
2569.95	13.3932
2573.43	14.6123
2576.91	16.7918
2580.38	3.01741
2583.85	2.36391
2587.33	21.567
2590.8	11.443
2594.27	15.4716
2597.74	13.779
2601.2	13.0605
2604.67	-0.120926
2608.13	10.5635
2611.59	9.66733
2615.06	13.4972
2618.51	4.8755
2621.97	10.6163
2625.43	10.5682
2628.88	7.60619
2632.33	10.3868
2635.79	12.1749
2639.24	9.13192
2642.69	13.7316
2646.13	7.77717
2649.58	7.55602
2653.02	13.9791
2656.47	10.834
2659.91	9.57371
2663.35	10.1964
2666.79	7.02187
2670.22	10.4525
2673.66	7.27351
2677.09	11.6254
2680.52	6.60654
2683.95	9.09947
2687.39	8.81532
2690.81	2.06667
2694.24	-0.917343
2697.66	0.733223
2701.09	1.46727
2704.51	13.361
2707.93	8.50648
2711.35	6.50937
2714.77	9.17928
2718.18	1.62477
2721.6	8.98417
2725.01	5.17046
2728.42	7.8898
2731.84	2.20045
2735.24	3.04066
2738.65	2.94062
2742.06	6.58331
2745.46	5.51293
2748.86	10.0593
2752.27	6.14522
2755.67	4.09368
2759.07	0.140282
2762.46	4.65681
2765.86	2.54911
2769.25	12.6704
2772.65	-1.73199
2776.04	8.35143
2779.43	-4.19958
2782.82	-0.754555
2786.2	0.791878
2789.59	2.32717
2792.98	7.61088
2796.36	9.12146
2799.74	-1.58003
2803.12	7.41022
2806.5	4.19664
2809.88	-5.57642
2813.25	4.30619
2816.63	6.67963
2820	6.23811
2823.37	-1.65828
2826.74	2.58955
2830.11	4.03773
2833.48	-0.0976257
2836.84	-1.42212
2840.21	9.37518
2843.57	-7.75864
2846.93	6.80379
2850.29	0.899239
2853.65	-4.06184
2857.01	4.96619
2860.36	1.86288
2863.72	7.18816
2867.07	-0.597511
2870.42	-1.83559
2873.77	2.54882
2877.12	1.29183
2880.47	10.3804
2883.81	-5.02222
2887.16	-2.5463
2890.5	-1.96102
2893.84	-1.38545
2897.18	6.72285
2900.52	2.52257
2903.86	-7.37981
2907.19	6.35086
2910.53	3.98264
2913.86	2.54694
2917.19	-0.79422
2920.52	-0.372528
2923.85	2.87487
2927.18	-0.51358
2930.51	-0.141281
2933.83	9.65453
2937.15	4.31519
2940.48	10.2924
2943.8	3.06612
2947.11	2.43896
2950.43	8.39604
2953.75	15.2743
2957.06	8.05191
2960.38	8.36518
2963.69	-0.698868
2967	12.759
2970.31	2.79939
2973.62	-0.575699
2976.92	10.12
2980.23	-1.68166
2983.53	4.32435
2986.84	6.5823
2990.14	4.15084
2993.44	1.71881
2996.73	-3.53001
3000.03	8.14064
3003.33	7.59077
3006.62	6.097
3009.91	7.43359
3013.2	13.4848
3016.49	11.0624
3019.78	20.8879
3023.07	4.30547
3026.35	12.2432
3029.64	4.13521
3032.92	8.29636
3036.2	1.10896
3039.48	9.98579
3042.76	16.031
3046.04	11.6701
3049.32	3.5161
3052.59	4.82712
3055.86	9.93356
3059.14	12.1915
3062.41	18.1951
3065.68	15.6827
3068.94	12.1988
3072.21	21.9654
3075.48	5.97833
3078.74	25.2368
3082	31.1642
3085.26	29.6533
3088.52	17.6893
3091.78	27.6026
3095.04	27.0844
3098.29	29.1948
3101.55	29.515
3104.8	36.4574
3108.05	22.5577
3111.3	39.0786
3114.55	53.6433
3117.8	36.8091
3121.04	40.9242
3124.29	47.8979
3127.53	52.0124
3130.77	59.9338
3134.02	62.1423
3137.25	54.8134
3140.49	66.5368
3143.73	57.285
3146.96	72.8233
3150.2	69.3082
3153.43	85.8263
3156.66	79.4456
3159.89	82.6109
3163.12	78.1359
3166.35	103.245
3169.57	100.658
3172.8	96.1442
3176.02	108.797
3179.24	110.93
3182.46	119.736
3185.68	118.055
3188.9	128.738
3192.12	127.97
3195.33	119.579
3198.55	121.669
3201.76	132.323
3204.97	133.464
3208.18	143.183
3211.39	154.816
3214.6	151.247
3217.8	166.73
3221.01	158.432
3224.21	172.978
3227.41	161.877
3230.61	169.812
3233.81	175.875
3237.01	185.725
3240.21	168.057
3243.4	181.825
3246.59	190.862
3249.79	176.085
3252.98	202.337
3256.17	221.952
3259.36	223.448
3262.54	203.882
3265.73	217.684
3268.92	217.11
3272.1	246.113
3275.28	245.481
3278.46	234.34
3281.64	237.444
3284.82	253.834
3288	260.683
3291.17	263.677
3294.35	264.804
3297.52	253.532
3300.69	286.083
3303.86	285.406
3307.03	306.495
3310.2	318.96
3313.36	290.474
3316.53	316.127
3319.69	343.627
3322.85	326.518
3326.02	371.004
3329.18	374.736
3332.33	375.644
3335.49	394.546
3338.65	410.646
3341.8	431.492
3344.95	456.108
3348.11	476.158
3351.26	495.428
3354.41	509.98
3357.56	539.699
3360.7	571.353
3363.85	608.773
3366.99	590.595
3370.13	640.376
3373.28	649.656
3376.42	693.979
3379.56	705.335
3382.69	757.386
3385.83	758.402
3388.97	787.887
3392.1	832.573
3395.23	860.22
3398.36	912.26
3401.49	964.988
3404.62	1032.16
3407.75	1060.63
3410.88	1100.66
3414	1185.49
3417.13	1223.46
3420.25	1294.78
3423.37	1407.09
3426.49	1505.84
3429.61	1609.13
3432.73	1677.84
3435.84	1776.73
3438.96	1965.81
3442.07	2110.23
3445.18	2250.72
3448.29	2460.25
3451.4	2724.83
3454.51	3165.93
3457.62	3827.32
3460.72	4879.24
3463.83	6018.82
3466.93	6154.09
3470.03	5504.31
3473.13	4473.85
3476.23	3770.81
3479.33	3369.13
3482.43	3085.5
3485.53	2950.74
3488.62	2861.72
3491.71	2819.54
3494.81	2797.1
3497.9	2790.61
3500.99	2770.72
3504.07	2791.47
3507.16	2774.98
3510.25	2820.65
3513.33	2877.57
3516.41	2984.88
3519.5	3090.99
3522.58	3232.59
3525.66	3379.79
3528.73	3526.43
3531.81	3786.72
3534.89	4018.93
3537.96	4346.33
3541.03	4508.86
3544.11	4697.98
3547.18	4725.87
3550.25	4667.52
3553.32	4287.4
3556.38	3798.7
3559.45	3216.46
3562.51	2745.27
3565.58	2280.56
3568.64	1911.82
3571.7	1600.35
3574.76	1359.87
3577.82	1198.14
3580.87	1038.16
3583.93	910.33
3586.98	795.7
3590.04	732.306
3593.09	662.19
3596.14	614.846
3599.19	557.044
3602.24	543.81
3605.29	504.009
3608.33	446.228
3611.38	423.503
3614.42	411.177
3617.46	384.686
3620.5	335.613
3623.54	376.249
3626.58	352.757
3629.62	324.62
3632.65	307.794
3635.69	305.092
3638.72	285.589
3641.76	268.994
3644.79	235.533
3647.82	217.247
3650.84	220.492
3653.87	192.754
3656.9	197.454
3659.92	169.173
3662.95	153.992
3665.97	138.73
3668.99	119.535
3672.01	107.954
3675.03	101.1
3678.05	94.2646
3681.07	77.9993
3684.08	72.1023
3687.1	70.938
3690.11	44.2382
3693.12	52.5533
3696.13	58.0461
3699.14	45.4911
3702.15	36.7744
3705.16	42.291
3708.16	34.5193
3711.17	29.5693
3714.17	17.9465
3717.17	19.6119
3720.17	17.4927
3723.17	20.1113
3726.17	5.58061
3729.17	8.17439
3732.16	0.284546
3735.16	-1.90472
3738.15	-8.86906
3741.14	-1.5625
3744.13	-10.4536
3747.13	-7.93311
3750.11	0.275818
3753.1	-11.4835
3756.09	-12.7824
3759.07	-16.9174
3762.06	-8.7215
3765.04	-16.6543
3768.02	-3.73793
3771	-18.2627
3773.98	-12.8923
3776.96	-26.4189
3779.94	-22.9144
3782.91	-26.0132
3785.89	-22.4961
3788.86	-19.9151
3791.83	-20.1568
3794.8	-19.4306
3797.77	-19.6363
3800.74	-24.5533
3803.71	-24.7329
3806.68	-20.1843
3809.64	-23.189
3812.61	-28.0798
3815.57	-16.8997
3818.53	-25.5747
3821.49	-18.1667
3824.45	-25.9019
3827.41	-21.3236
3830.36	-17.6916
3833.32	-23.5468
3836.27	-16.1133
3839.23	-21.967
3842.18	-17.3796
3845.13	-14.6966
3848.08	-25.3419
3851.03	-25.526
3853.98	-15.2226
3856.92	-17.3148
3859.87	-17.5081
3862.81	-11.9742
3865.75	-21.7597
3868.7	-16.25
3871.64	-25.1302
3874.57	-11.0208
3877.51	-4.58826
3880.45	-9.70036
3883.39	-19.6492
3886.32	-9.4532
3889.25	-9.84964
3892.18	-9.30508
3895.12	-13.5902
3898.05	-5.40665
3900.97	-4.94818
3903.9	-16.0487
3906.83	-9.87451
3909.75	-5.62622
3912.68	-7.17665
3915.6	-13.5618
3918.52	-11.3267
3921.44	-8.12939
3924.36	0.777817
3927.28	-8.58742
3930.2	-13.183
3933.11	-0.554245
3936.03	-4.20953
3938.94	-0.197449
3941.86	-10.5486
3944.77	-16.1487
3947.68	-11.2355
3950.59	-7.29333
3953.49	-9.11359
3956.4	-6.16832
3959.31	-7.07042
3962.21	-7.99643
3965.12	-11.8228
3968.02	-8.96297
3970.92	2.50906
3973.82	-11.9539
3976.72	-6.29994
3979.61	0.276398
3982.51	-6.64168
3985.41	-0.143814
3988.3	-2.34026
3991.19	-8.42766
3994.09	-10.7237
3996.98	3.32251
3999.87	-2.87833