File: Data/3-Raman/processed/bu19w-e-ff11-fi10-l_150 (500nm)_633nm_edge_100%_x100_vis_h50um_60sx2_01_0.txt
#Acq. time (s)=	60
#Accumulations=	2
#Range (cm-¹)=	100...4000
#Windows=	1
#Auto scanning=	Off
#Autofocus=	Off
#Macrospot=	Off
#AutoExposure=	Off
#Spike filter=	Multiple accum.
#Delay time (s)=	2
#Binning=	1
#Readout mode=	Signal
#DeNoise=	Off
#ICS correction=	On
#Dark correction=	Off
#Inst. Process=	Off
#Detector Gain=	Best Dynamic
#Detector ADC=	50 kHz HS
#Detector temperature (°C)=	-60.09
#Instrument=	LabRAM HR Evol
#Detector=	SIN-EM FIVIS
#Objective=	x100_VIS
#Grating=	150 (500nm)
#ND Filter=	100%
#Laser=	633nm_Edge
#Hole=	49.98
#Temperature=	0
#Range=	Visible
#StageXY=	75x50mm Scan+
#StageZ=	Z motor
#X (µm)=	0
#Y (µm)=	0
#Z (µm)=	-266.5
#Full time(mm:ss)=	2:04
#Project=	21_11_04
#Sample=	BU19w
#Site=
#Title=	BU19w-E-FF11-FI10-L_150 (500nm)_633nm_Edge_100%_x100_VIS_H50um_60sX2
#Remark=
#Date=	04.11.2021 12:03
#Acquired=	04.11.2021 12:03:28
#Base:Fit=	16.12.2021 17:39:50
#Base:Edit=	16.12.2021 17:53:12
#Base:Edit=	16.12.2021 17:53:13
#Base:Edit=	16.12.2021 17:53:15
#Base:Edit=	16.12.2021 17:53:15
#Base:Edit=	16.12.2021 17:53:16
#Base:Edit=	16.12.2021 17:53:17
#Base:Sub=	16.12.2021 17:53:19
102.881	294.382
109.397	262.457
115.908	223.543
122.414	187.023
128.914	183.658
135.409	159.811
141.898	182.456
148.383	159.072
154.861	148.043
161.335	179.996
167.801	210.82
174.264	131.016
180.721	78.5951
187.173	55.4905
193.62	27.3559
200.061	21.27
206.496	12.5636
212.926	5.55136
219.352	7.96802
225.772	13.0233
232.185	84.3351
238.595	202.109
244.999	106.06
251.397	30.9372
257.791	14.5897
264.178	18.1534
270.561	34.9622
276.939	28.0274
283.31	56.9664
289.678	46.8522
296.039	6.28152
302.396	-6.85699
308.746	-2.11359
315.093	33.7452
321.433	141.274
327.768	338.387
334.099	251.521
340.423	107.07
346.743	51.2066
353.058	50.8704
359.367	73.9195
365.671	83.668
371.971	43.5703
378.265	4.42834
384.553	-5.55
390.837	3.48543
397.116	6.12224
403.389	8.91551
409.657	4.07135
415.92	16.9786
422.178	42.1048
428.431	55.3007
434.678	87.8604
440.921	87.2708
447.158	89.395
453.391	81.1224
459.618	93.5686
465.84	90.4134
472.057	38.9546
478.27	34.2863
484.477	24.9224
490.679	36.9606
496.876	43.4044
503.068	39.6054
509.255	55.3932
515.436	63.7685
521.613	79.7654
527.785	80.0043
533.952	94.4707
540.113	77.8884
546.27	63.8254
552.423	53.2304
558.568	49.0956
564.711	36.0881
570.848	42.6675
576.979	22.7478
583.107	36.6238
589.228	33.7592
595.345	57.204
601.458	69.7491
607.565	76.994
613.667	91.8542
619.764	87.279
625.856	79.0032
631.944	67.4773
638.026	51.7196
644.104	50.6908
650.177	44.9252
656.244	72.7438
662.308	47.0393
668.365	31.7616
674.418	22.4674
680.467	21.6578
686.511	14.4435
692.549	0.827744
698.582	5.91965
704.611	3.46236
710.635	4.63496
716.655	-0.162781
722.669	11.0176
728.679	13.5895
734.683	2.96748
740.683	9.19458
746.678	5.16632
752.669	-6.23622
758.654	16.0331
764.635	2.21237
770.611	-3.13806
776.582	1.78934
782.549	-7.51575
788.511	4.71655
794.466	0.843994
800.419	5.32394
806.366	10.6163
812.309	7.35057
818.247	7.74031
824.18	5.26372
830.108	5.61487
836.033	3.42551
841.952	5.19298
847.865	3.2426
853.776	16.3686
859.681	7.92738
865.58	18.3313
871.476	38.2068
877.366	41.8271
883.253	43.4416
889.134	45.8684
895.012	55.7696
900.883	44.5974
906.751	38.0691
912.614	41.8896
918.473	26.9814
924.326	32.977
930.174	54.2252
936.019	57.8007
941.859	68.3098
947.693	91.2818
953.525	119.186
959.35	139.477
965.171	128.05
970.988	158.618
976.801	200.439
982.608	286.803
988.411	372.701
994.209	343.48
1000	259.102
1005.79	196.118
1011.58	195.545
1017.36	199.971
1023.13	221.75
1028.9	215.191
1034.67	182.757
1040.43	129.997
1046.19	111.703
1051.94	99.9182
1057.69	93.7563
1063.44	73.7665
1069.17	79.7644
1074.91	66.3276
1080.64	80.944
1086.37	113.925
1092.09	145.964
1097.8	192.46
1103.52	238.942
1109.22	170.598
1114.93	124.841
1120.63	109.236
1126.32	108.93
1132.01	87.1737
1137.7	113.315
1143.38	148.398
1149.06	172.556
1154.73	245.777
1160.4	199.48
1166.06	116.522
1171.72	64.265
1177.38	58.159
1183.03	39.4537
1188.67	28.79
1194.31	37.7926
1199.95	23.4745
1205.58	17.1348
1211.21	5.88736
1216.84	18.3673
1222.46	11.1193
1228.07	14.7917
1233.68	12.3952
1239.29	7.85895
1244.89	2.13084
1250.49	3.32299
1256.08	10.4869
1261.67	6.38837
1267.26	7.30537
1272.84	17.215
1278.42	15.9913
1283.99	7.77312
1289.56	6.65
1295.12	8.60735
1300.68	11.6395
1306.23	16.8033
1311.78	4.11301
1317.33	14.5721
1322.87	11.0126
1328.41	0.379684
1333.94	11.0095
1339.47	10.4212
1345	3.56914
1350.52	5.86007
1356.04	11.188
1361.55	11.3076
1367.06	16.4675
1372.56	24.6543
1378.06	46.1839
1383.56	26.6178
1389.05	14.2471
1394.53	5.03529
1400.02	8.29228
1405.5	-5.94589
1410.97	9.70245
1416.44	8.92165
1421.91	11.261
1427.37	-1.93838
1432.83	11.8643
1438.28	1.72151
1443.73	7.21465
1449.17	0.103043
1454.62	3.35947
1460.05	10.7391
1465.48	8.60653
1470.91	0.150558
1476.34	6.41682
1481.76	8.53676
1487.17	-1.91367
1492.59	5.55588
1497.99	7.83393
1503.4	-2.51576
1508.8	7.246
1514.19	8.6051
1519.59	-2.77
1524.97	6.11066
1530.36	1.10648
1535.74	10.0885
1541.11	10.3761
1546.48	12.6776
1551.85	8.30537
1557.21	10.263
1562.57	9.00626
1567.93	6.66905
1573.28	15.1011
1578.62	13.9028
1583.97	7.392
1589.3	11.6822
1594.64	12.7976
1599.97	8.57578
1605.3	15.2132
1610.62	14.385
1615.94	25.6213
1621.25	22.7937
1626.56	35.2806
1631.87	26.9341
1637.17	26.1468
1642.47	31.7604
1647.76	37.4237
1653.05	24.2083
1658.34	33.07
1663.62	35.2377
1668.9	26.2815
1674.18	22.8579
1679.45	24.9512
1684.71	13.67
1689.98	5.71009
1695.23	15.541
1700.49	27.7808
1705.74	13.8889
1710.99	11.7159
1716.23	8.30128
1721.47	15.2418
1726.7	15.3272
1731.94	26.7043
1737.16	15.6026
1742.39	19.1046
1747.61	5.6565
1752.82	9.0718
1758.03	2.25193
1763.24	3.28672
1768.44	2.07255
1773.64	21.2766
1778.84	9.93041
1784.03	11.1152
1789.22	14.6333
1794.41	19.3402
1799.59	10.3769
1804.76	7.12809
1809.94	8.41574
1815.11	8.52276
1820.27	13.251
1825.43	19.1673
1830.59	11.198
1835.74	3.20644
1840.89	16.1039
1846.04	14.9982
1851.18	16.2083
1856.32	10.3451
1861.45	10.3979
1866.58	12.8334
1871.71	21.1278
1876.83	8.15617
1881.95	6.93987
1887.07	17.5102
1892.18	14.9863
1897.29	12.4475
1902.39	6.47093
1907.49	11.2597
1912.59	16.1834
1917.68	16.4215
1922.77	11.5928
1927.86	9.25118
1932.94	12.888
1938.02	9.29626
1943.09	20.0815
1948.16	6.77037
1953.23	13.8603
1958.29	12.4851
1963.35	14.7
1968.41	19.2821
1973.46	17.779
1978.51	15.0723
1983.55	14.7693
1988.59	12.0763
1993.63	13.0075
1998.66	18.7751
2003.69	16.1657
2008.72	6.38631
2013.74	13.4814
2018.76	18.1567
2023.77	12.0046
2028.78	16.7732
2033.79	8.318
2038.79	5.90577
2043.79	16.8559
2048.79	-1.33347
2053.78	20.583
2058.77	3.53196
2063.76	18.2637
2068.74	22.0148
2073.72	19.6167
2078.69	19.6532
2083.66	24.5921
2088.63	10.9427
2093.59	24.5509
2098.55	23.3987
2103.51	2.35918
2108.46	29.8932
2113.41	21.3437
2118.36	20.2926
2123.3	28.0346
2128.24	25.6969
2133.17	14.4449
2138.11	27.2042
2143.03	12.0219
2147.96	12.0197
2152.88	14.5019
2157.79	22.0524
2162.71	15.5049
2167.62	16.5609
2172.52	33.0026
2177.43	21.3264
2182.32	17.2357
2187.22	16.9436
2192.11	16.7242
2197	15.2776
2201.89	15.1944
2206.77	29.3089
2211.64	20.3562
2216.52	8.8195
2221.39	12.7899
2226.26	12.8896
2231.12	27.298
2235.98	9.17693
2240.84	2.72615
2245.69	18.5338
2250.54	12.0803
2255.39	1.62926
2260.23	21.5226
2265.07	0.424698
2269.9	18.9613
2274.74	8.28131
2279.57	14.8098
2284.39	18.6098
2289.21	10.3933
2294.03	10.1521
2298.84	20.6107
2303.66	21.8263
2308.46	15.1377
2313.27	13.8462
2318.07	-2.14149
2322.87	30.1936
2327.66	16.9002
2332.45	14.3771
2337.24	21.3653
2342.02	9.37625
2346.8	12.3816
2351.58	11.2766
2356.35	4.59824
2361.12	14.3021
2365.89	10.2266
2370.65	14.4335
2375.41	22.7964
2380.17	22.8233
2384.92	15.8006
2389.67	11.4856
2394.42	11.274
2399.16	11.0062
2403.9	5.15891
2408.64	-3.44481
2413.37	17.4518
2418.1	19.366
2422.83	22.4448
2427.55	14.0081
2432.27	2.87038
2436.99	10.1317
2441.7	1.82085
2446.41	17.6681
2451.11	16.4774
2455.82	9.5289
2460.51	-0.329376
2465.21	18.5671
2469.9	11.5315
2474.59	14.5752
2479.28	8.94197
2483.96	16.3478
2488.64	25.191
2493.32	20.903
2497.99	18.0756
2502.66	22.541
2507.32	13.7596
2511.99	9.32692
2516.65	22.5402
2521.3	22.5568
2525.96	9.26582
2530.61	15.1826
2535.25	21.166
2539.89	18.2861
2544.53	16.8982
2549.17	22.9979
2553.8	23.1334
2558.43	18.7097
2563.06	12.8217
2567.68	22.0199
2572.3	19.2151
2576.92	11.8269
2581.53	22.5367
2586.14	16.4591
2590.75	5.71049
2595.35	16.3029
2599.96	13.2801
2604.55	10.1954
2609.15	16.2484
2613.74	11.5438
2618.33	12.9715
2622.91	15.9373
2627.49	25.0837
2632.07	20.5611
2636.64	33.0862
2641.22	16.4418
2645.78	9.01324
2650.35	15.499
2654.91	14.1602
2659.47	12.6533
2664.03	26.7278
2668.58	25.1707
2673.13	8.03873
2677.67	22.5766
2682.22	24.8126
2686.76	26.99
2691.29	22.7258
2695.83	18.1442
2700.36	31.1016
2704.89	3.89983
2709.41	34.5492
2713.93	16.8898
2718.45	25.1081
2722.96	8.99695
2727.47	28.4386
2731.98	16.9868
2736.49	15.2462
2740.99	20.0114
2745.49	19.9835
2749.98	15.1476
2754.47	20.323
2758.96	17.1261
2763.45	13.847
2767.93	33.6803
2772.41	15.646
2776.89	22.4305
2781.36	21.0734
2785.84	21.4265
2790.3	16.7588
2794.77	10.3494
2799.23	7.1821
2803.69	17.3973
2808.14	14.1132
2812.59	19.2245
2817.04	19.2112
2821.49	32.7627
2825.93	12.4513
2830.37	36.2337
2834.81	2.19345
2839.24	19.1803
2843.67	20.8669
2848.1	8.93677
2852.53	3.86757
2856.95	26.3261
2861.37	12.7465
2865.78	14.7182
2870.19	32.3135
2874.6	22.197
2879.01	19.0177
2883.41	17.6134
2887.81	14.4595
2892.21	11.2412
2896.6	9.78976
2901	-4.05782
2905.38	19.2854
2909.77	14.164
2914.15	23.2091
2918.53	23.3201
2922.91	9.08646
2927.28	14.6691
2931.65	13.0779
2936.02	20.4514
2940.38	24.1137
2944.74	27.764
2949.1	29.5101
2953.46	22.1523
2957.81	0.13591
2962.16	21.9969
2966.5	23.7906
2970.85	16.4404
2975.19	23.7952
2979.52	40.3921
2983.86	31.2591
2988.19	29.5632
2992.52	29.765
2996.85	39.2981
3001.17	32.1304
3005.49	34.3376
3009.8	34.6639
3014.12	42.4946
3018.43	20.1741
3022.74	26.1925
3027.04	30.2168
3031.34	49.4621
3035.64	41.8755
3039.94	38.0689
3044.23	36.1687
3048.52	45.767
3052.81	51.5255
3057.09	70.8688
3061.38	49.601
3065.65	39.8936
3069.93	57.3484
3074.2	45.6767
3078.47	43.7308
3082.74	61.3088
3087	86.8926
3091.27	65.6122
3095.52	65.9783
3099.78	78.228
3104.03	84.6676
3108.28	79.2861
3112.53	93.902
3116.77	106.606
3121.01	89.2433
3125.25	106.199
3129.49	101.037
3133.72	89.7813
3137.95	92.7396
3142.18	110.049
3146.4	121.181
3150.62	126.068
3154.84	134.936
3159.06	127.09
3163.27	140.174
3167.48	165.846
3171.69	149.52
3175.89	141.42
3180.09	141.535
3184.29	166.968
3188.49	173.239
3192.68	162.713
3196.87	167.222
3201.06	180.76
3205.24	177.377
3209.42	167.677
3213.6	170.906
3217.78	159.047
3221.95	177.465
3226.12	196.042
3230.29	179.582
3234.45	182.768
3238.61	190.35
3242.77	200.389
3246.93	194.959
3251.08	164.538
3255.23	174.027
3259.38	188.118
3263.53	207.093
3267.67	215.585
3271.81	191.813
3275.95	183.279
3280.08	215.703
3284.21	186.318
3288.34	198.169
3292.47	177.779
3296.59	210.323
3300.71	178.405
3304.83	185.696
3308.95	209.258
3313.06	239.79
3317.17	191.321
3321.27	203.435
3325.38	208.745
3329.48	193.068
3333.58	229.433
3337.67	230.626
3341.77	229.032
3345.86	250.936
3349.95	241.854
3354.03	211.335
3358.11	238.192
3362.19	250.845
3366.27	253.895
3370.34	264.184
3374.42	259.932
3378.48	286.835
3382.55	277.559
3386.61	285.128
3390.68	270.874
3394.73	280.842
3398.79	312.838
3402.84	288.901
3406.89	318.289
3410.94	311.185
3414.98	294.308
3419.03	309.101
3423.06	353.121
3427.1	328.977
3431.14	356.278
3435.17	312.857
3439.2	362.596
3443.22	314.405
3447.25	308.146
3451.27	294.508
3455.28	310.698
3459.3	304.92
3463.31	329.078
3467.32	303.413
3471.33	330.162
3475.34	306.378
3479.34	320.526
3483.34	276.512
3487.33	293.098
3491.33	271.56
3495.32	300.828
3499.31	276.389
3503.3	254.239
3507.28	234.443
3511.26	278.48
3515.24	227.444
3519.22	214.889
3523.19	181.753
3527.16	213.019
3531.13	179.918
3535.1	196.19
3539.06	186.934
3543.02	182.697
3546.98	178.314
3550.93	173.77
3554.89	153.278
3558.84	161.657
3562.78	172.798
3566.73	147.582
3570.67	148.62
3574.61	133.913
3578.55	124.55
3582.48	102.088
3586.41	124.491
3590.35	125.796
3594.27	100.509
3598.2	91.0776
3602.12	89.5322
3606.04	98.673
3609.95	78.2193
3613.87	65.7659
3617.78	66.7054
3621.69	45.9171
3625.6	54.6367
3629.5	52.5323
3633.4	58.4868
3637.3	56.4557
3641.2	41.0688
3645.09	25.7633
3648.98	34.7891
3652.87	21.9583
3656.76	28.167
3660.64	34.3835
3664.53	13.2878
3668.4	11.3699
3672.28	12.1774
3676.16	-6.06778
3680.03	-5.05199
3683.9	15.3383
3687.76	2.81181
3691.63	-9.76294
3695.49	-8.59125
3699.35	12.1084
3703.2	-3.36674
3707.06	-7.6871
3710.91	-9.22594
3714.76	-7.9894
3718.6	-32.1833
3722.45	-8.49867
3726.29	-1.73912
3730.13	-9.12263
3733.97	-5.13455
3737.8	-21.0488
3741.63	-22.8009
3745.46	-1.7411
3749.29	-14.9546
3753.11	-16.8079
3756.93	-10.1231
3760.75	-12.0616
3764.57	-5.41508
3768.39	-15.9431
3772.2	16.6186
3776.01	-16.8232
3779.81	10.1003
3783.62	-6.03102
3787.42	0.874191
3791.22	-0.901474
3795.02	-19.9763
3798.81	-15.8866
3802.61	-5.95663
3806.4	6.9536
3810.18	11.16
3813.97	-5.13588
3817.75	-21.517
3821.53	-5.69817
3825.31	-7.52122
3829.09	2.42647
3832.86	0.641815
3836.63	4.72656
3840.4	8.77682
3844.17	-13.8045
3847.93	-1.01804
3851.69	14.7209
3855.45	21.5013
3859.21	22.2466
3862.96	23.0291
3866.71	12.1509
3870.46	10.2829
3874.21	-0.908447
3877.95	-15.1084
3881.69	-2.42567
3885.44	10.2796
3889.17	11.0265
3892.91	2.79704
3896.64	-11.406
3900.37	7.38269
3904.1	5.07623
3907.82	-6.34029
3911.55	-5.70023
3915.27	13.1051
3918.99	22.8996
3922.7	11.464
3926.42	-6.20116
3930.13	15.7122
3933.84	10.0338
3937.54	4.24899
3941.25	29.163
3944.95	32.6375
3948.65	5.20303
3952.35	2.26338
3956.04	11.5951
3959.73	8.44891
3963.42	2.10545
3967.11	1.84479
3970.8	10.7697
3974.48	10.3532
3978.16	3.64935
3981.84	6.12093
3985.52	2.31442
3989.19	4.63565
3992.86	-14.7686
3996.53	-6.27716
3998.37	-6.6944