File: Data/3-Raman/processed/bu19(2)w-a-ff1-fi03-v_1800 (450-850nm)_532nm_edge_100%_x100_vis_lwd_h100um_30sx2_01.txt
#Acq. time (s)=	30
#Accumulations=	2
#Range (cm-¹)=	1200...2365
#Windows=	3
#Auto scanning=	Off
#Autofocus=	Off
#Macrospot=	Off
#AutoExposure=	Off
#Spike filter=	Multiple accum.
#Delay time (s)=	2
#Binning=	1
#Readout mode=	Signal
#DeNoise=	Off
#ICS correction=	On
#Dark correction=	Off
#Inst. Process=	Off
#Detector Gain=	Best Dynamic
#Detector ADC=	50 kHz HS
#Detector temperature (°C)=	-60.09
#Instrument=	LabRAM HR Evol
#Detector=	SIN-EM FIVIS
#Objective=	x100_VIS_LWD
#Grating=	1800 (450-850nm)
#ND Filter=	100%
#Laser=	532nm_Edge
#Hole=	100.021
#Temperature=	0
#Range=	Visible
#StageXY=	75x50mm Scan+
#StageZ=	Z motor
#X (µm)=	0
#Y (µm)=	0
#Z (µm)=	-10.9
#Full time(mm:ss)=	3:18
#Project=	21_11_26
#Sample=	BU19(2)w
#Site=
#Title=	BU19(2)w-A-FF1-FI03-L_1800 (450-850nm)_532nm_Edge_100%_x100_VIS_LWD_H100um_30sX2
#Remark=
#Date=	26.11.2021 12:23
#Acquired=	26.11.2021 12:23:13
#Base:Fit=	16.12.2021 16:00:56
#Base:Fit=	16.12.2021 16:05:25
#Base:Sub=	16.12.2021 16:05:26
1202.72	-11.865
1203.84	-19.6525
1204.95	32.077
1206.06	-13.0729
1207.17	-5.20679
1208.28	10.371
1209.39	21.6331
1210.5	39.1425
1211.61	-18.7625
1212.72	29.2441
1213.83	-5.22229
1214.94	-38.4012
1216.05	3.89673
1217.16	31.3455
1218.27	-19.3354
1219.38	-22.4747
1220.49	37.2561
1221.6	33.4701
1222.71	4.77832
1223.81	-0.376831
1224.92	-6.52087
1226.03	14.5906
1227.14	6.77917
1228.25	-25.4061
1229.35	-9.3031
1230.46	12.7808
1231.57	9.15247
1232.67	25.8135
1233.78	-35.6172
1234.89	28.9232
1235.99	-34.6356
1237.1	-29.9122
1238.2	3.57312
1239.31	11.9628
1240.41	-27.5837
1241.52	23.7482
1242.62	-6.41821
1243.73	12.7448
1244.83	17.7543
1245.94	-8.06165
1247.04	-12.3262
1248.14	11.1266
1249.25	26.7094
1250.35	24.3452
1251.45	23.6708
1252.56	17.0135
1253.66	5.18567
1254.76	5.85718
1255.87	44.5
1256.97	-18.0615
1258.07	61.6992
1259.17	71.0052
1260.27	76.0258
1261.37	82.2098
1262.48	160.967
1263.58	197.6
1264.68	148.804
1265.78	78.8832
1266.88	62.9694
1267.98	69.6027
1269.08	28.6768
1270.18	28.4254
1271.28	15.0829
1272.38	49.5341
1273.47	50.2489
1274.57	35.8929
1275.67	58.9182
1276.77	78.8669
1277.87	91.6035
1278.97	123.447
1280.07	186.652
1281.16	496.743
1282.26	1662.14
1283.36	3227.04
1284.45	1667.21
1285.55	432.119
1286.65	190.492
1287.75	103.191
1288.84	103.548
1289.94	43.2935
1291.03	81.4579
1292.13	70.5056
1293.22	61.7642
1294.32	24.6603
1295.42	57.5477
1296.51	20.8386
1297.61	6.66003
1298.7	18.1777
1299.79	-2.97656
1300.89	30.0763
1301.98	14.2952
1303.08	11.3977
1304.17	26.4142
1305.26	2.83862
1306.35	-14.6091
1307.45	16.5439
1308.54	2.79077
1309.63	5.25867
1310.73	25.4265
1311.82	12.8754
1312.91	14.6093
1314	-9.29565
1315.09	28.7355
1316.18	15.7698
1317.28	26.9789
1318.37	7.3291
1319.46	11.5259
1320.55	-12.8577
1321.64	8.0332
1322.73	-2.05237
1323.82	-9.07898
1324.91	-19.6183
1326	-12.3901
1327.09	-7.89526
1328.18	1.25916
1329.27	27.5105
1330.35	-6.54236
1331.44	17.2656
1332.53	19.9835
1333.62	2.9259
1334.71	-15.8489
1335.79	14.1783
1336.88	-28.8691
1337.97	14.4474
1339.06	-16.2593
1340.14	10.884
1341.23	29.8564
1342.32	17.6659
1343.4	11.9545
1344.49	0.290527
1345.58	8.88635
1346.66	-0.835083
1347.75	-28.9624
1348.83	-19.3121
1349.92	7.60547
1351	1.07739
1352.09	39.3379
1353.17	22.7998
1354.25	-3.51318
1355.34	7.06848
1356.42	0.70105
1357.51	9.2522
1358.59	16.5139
1359.67	20.5354
1360.76	5.45874
1361.84	35.0245
1362.92	36.5154
1364	52.7305
1365.09	67.2286
1366.17	15.0667
1367.25	46.3365
1368.33	70.1486
1369.41	188.625
1370.5	53.8405
1371.58	54.5054
1372.66	47.8906
1373.74	28.2401
1374.82	73.1404
1375.9	78.375
1376.98	56.0516
1378.06	26.7329
1379.14	136.999
1380.22	119.705
1381.3	153.024
1382.38	141.945
1383.46	258.38
1384.54	394.789
1385.61	917.289
1386.69	4315.15
1387.77	5843.05
1388.85	1085.36
1389.93	366.4
1391	200.363
1392.08	151.862
1393.16	110.653
1394.23	32.3837
1395.31	102.09
1396.39	71.1677
1397.46	56.1405
1398.54	60.0769
1399.62	47.7836
1400.69	88.5818
1401.77	67.1626
1402.84	62.0094
1403.92	39.3475
1404.99	65.0253
1406.07	128.7
1407.14	169.427
1408.22	265.618
1409.29	314.701
1410.37	162.627
1411.44	69.7705
1412.51	80.994
1413.59	79.1858
1414.66	12.6486
1415.73	21.9869
1416.81	21.8455
1417.88	-2.68445
1418.95	22.6257
1420.02	60.5245
1421.1	40.9185
1422.17	19.8115
1423.24	45.5162
1424.31	34.7225
1425.38	46.4175
1426.45	49.3199
1427.52	38.6364
1428.59	13.7109
1429.67	-16.1421
1430.74	14.4512
1431.81	22.2461
1432.87	7.25208
1433.95	-7.33398
1435.01	3.89697
1436.08	-17.2612
1437.15	19.4484
1438.22	7.06409
1439.29	21.3785
1440.36	-39.4473
1441.43	11.6702
1442.49	7.75977
1443.56	18.2996
1444.63	35.7509
1445.7	-18.8484
1446.77	17.8945
1447.83	-4.93347
1448.9	5.24622
1449.97	-3.85706
1451.03	17.2128
1452.1	11.8584
1453.17	-14.453
1454.23	22.1095
1455.3	33.6633
1456.36	15.0323
1457.43	7.54211
1458.49	-28.1938
1459.56	-13.1245
1460.62	20.8468
1461.69	-22.5454
1462.75	-28.4648
1463.82	-22.4668
1464.88	-3.69678
1465.94	-35.073
1467.01	32.1263
1468.07	-12.6414
1469.13	31.3983
1470.2	32.6803
1471.26	8.73071
1472.32	-14.2244
1473.39	-28.3511
1474.45	8.86816
1475.51	4.51721
1476.57	-8.91748
1477.63	-35.8151
1478.69	12.7578
1479.76	-39.8134
1480.82	34.8358
1481.88	5.16882
1482.94	4.85608
1484	10.7117
1485.06	20.5608
1486.12	-8.92822
1487.18	-4.23608
1488.24	-2.70569
1489.3	-8.80334
1490.36	11.3693
1491.42	1.72925
1492.48	30.2892
1493.53	-28.1362
1494.59	14.701
1495.65	26.5104
1496.71	25.1552
1497.77	-5.20667
1498.82	28.4385
1499.88	4.06165
1500.94	38.9641
1502	9.39661
1503.05	31.3308
1504.11	3.61243
1505.17	8.26611
1506.22	31.2399
1507.28	20.751
1508.34	-6.0105
1509.39	45.8411
1510.45	-2.81628
1511.5	31.2222
1512.56	-13.1655
1513.61	24.4103
1514.67	18.99
1515.72	-0.246216
1516.78	-9.51111
1517.83	14.6954
1518.88	16.8279
1519.94	-5.3114
1520.99	16.9565
1522.05	-3.3457
1523.1	12.3511
1524.15	33.7344
1525.2	22.3428
1526.26	1.50488
1527.31	14.9315
1528.36	2.64148
1529.41	28.4331
1530.47	26.3147
1531.52	0.905762
1532.57	-11.9695
1533.62	62.6001
1534.67	24.2053
1535.72	6.72107
1536.77	26.6364
1537.82	15.0532
1538.87	4.34717
1539.92	41.5414
1540.97	38.0386
1542.02	46.3049
1543.07	18.8394
1544.12	24.1409
1545.17	12.7068
1546.22	47.9783
1547.27	22.7566
1548.32	44.2472
1549.37	25.5604
1550.42	18.6196
1551.46	51.5988
1552.51	11.9169
1553.56	36.048
1554.61	57.1414
1555.65	58.877
1556.7	19.0665
1557.75	-14.2916
1558.79	16.6736
1559.84	12.9708
1560.89	27.4318
1561.93	0.20105
1562.98	11.6057
1564.02	11.6608
1565.07	23.5682
1566.11	55.462
1567.16	24.8706
1568.2	35.7306
1569.25	24.5902
1570.29	-4.91968
1571.34	37.4097
1572.38	-5.00647
1573.43	-1.74048
1574.47	4.45959
1575.51	-3.32312
1576.56	33.3184
1577.6	45.4666
1578.64	-18.1392
1579.69	40.9537
1580.73	30.9495
1581.77	46.4498
1582.81	3.93738
1583.85	68.7195
1584.9	47.304
1585.94	9.75842
1586.98	2.76477
1588.02	23.3517
1589.06	46.3081
1590.1	-8.32043
1591.14	14.5261
1592.18	35.4446
1593.22	3.23181
1594.26	57.5555
1595.3	22.5428
1596.34	8.38623
1597.38	18.9326
1598.42	48.2408
1599.46	48.9265
1600.5	61.9097
1601.54	24.537
1602.58	-7.65137
1603.62	11.8877
1604.66	44.498
1605.69	44.0955
1606.73	28.559
1607.77	28.738
1608.81	60.147
1609.84	0.750122
1610.88	-3.95789
1611.92	42.6995
1612.95	0.585327
1613.99	-6.41858
1615.03	14.5287
1616.06	22.1923
1617.1	8.93127
1618.13	7.48572
1619.17	0.0761719
1620.2	28.8514
1621.24	-29.7847
1622.27	29.4426
1623.31	22.8878
1624.34	17.4736
1625.38	-8.94263
1626.41	24.9606
1627.45	9.16443
1628.48	32.8361
1629.51	23.1582
1630.55	-8.88477
1631.53	53.6874
1632.57	29.4065
1633.62	4.01343
1634.66	17.7113
1635.71	-11.6205
1636.75	41.1392
1637.8	28.5797
1638.84	25.4272
1639.89	-4.67969
1640.93	-1.9635
1641.98	-6.47742
1643.02	26.006
1644.06	19.2009
1645.11	8.9165
1646.15	30.6034
1647.19	-3.20886
1648.24	2.46863
1649.28	22.4209
1650.32	26.7245
1651.37	-1.54114
1652.41	8.14465
1653.45	-1.74304
1654.49	14.8888
1655.53	-12.3861
1656.57	20.724
1657.62	30.0935
1658.66	-22.4801
1659.7	31.052
1660.74	19.3533
1661.78	7.45532
1662.82	6.23523
1663.86	13.8522
1664.9	38.6365
1665.94	30.5145
1666.98	38.5115
1668.02	-2.59949
1669.06	19.988
1670.1	-3.74487
1671.14	-10.6777
1672.18	5.24939
1673.21	-5.91492
1674.25	28.6674
1675.29	16.4717
1676.33	8.53235
1677.37	49.7954
1678.4	14.6688
1679.44	26.6812
1680.48	-13.1
1681.52	34.1293
1682.55	20.7496
1683.59	13.2159
1684.63	-6.53772
1685.66	5.43176
1686.7	-51.1328
1687.73	6.16895
1688.77	10.738
1689.81	29.5598
1690.84	-6.94409
1691.88	23.9259
1692.91	-11.3096
1693.95	-30.5038
1694.98	-35.4102
1696.01	-7.98022
1697.05	11.8517
1698.08	-7.94421
1699.12	-9.7699
1700.15	43.8286
1701.18	-0.434814
1702.22	8.91565
1703.25	27.858
1704.28	23.9623
1705.32	20.0123
1706.35	52.5333
1707.38	36.4105
1708.41	12.1279
1709.44	-45.6238
1710.48	1.49524
1711.51	25.2953
1712.54	6.40796
1713.57	12.7123
1714.6	11.1582
1715.63	-3.89905
1716.66	-0.426147
1717.69	-26.7913
1718.72	22.1461
1719.75	30.7201
1720.78	0.0617676
1721.81	-12.7672
1722.84	2.36914
1723.87	-1.44434
1724.9	-7.2981
1725.93	10.8699
1726.96	55.3021
1727.99	8.80322
1729.02	1.51953
1730.05	9.74622
1731.07	31.3691
1732.1	47.9574
1733.13	3.28198
1734.16	10.8669
1735.18	1.22498
1736.21	27.8306
1737.24	22.704
1738.26	-1.88696
1739.29	11.4095
1740.32	-17.9296
1741.34	8.18066
1742.37	4.54749
1743.4	22.7677
1744.42	18.5687
1745.45	25.5068
1746.47	24.4426
1747.5	13.3616
1748.52	-17.7351
1749.55	34.976
1750.57	13.4606
1751.6	25.5594
1752.62	50.0974
1753.64	43.301
1754.67	10.9325
1755.69	27.7009
1756.71	-5.80029
1757.74	7.04919
1758.76	13.1948
1759.78	1.75208
1760.81	13.3438
1761.83	-21.4905
1762.85	-18.993
1763.87	24.7797
1764.89	-2.41553
1765.92	45.9045
1766.94	40.7997
1767.96	22.8452
1768.98	57.9326
1770	20.7126
1771.02	-16.3719
1772.04	32.6709
1773.06	2.30383
1774.08	79.1875
1775.1	38.776
1776.12	50.1714
1777.14	26.1837
1778.16	-2.89697
1779.18	26.666
1780.2	26.1775
1781.22	21.0253
1782.24	5.31531
1783.26	10.3718
1784.28	16.084
1785.29	-1.72009
1786.31	-23.345
1787.33	11.8733
1788.35	33.8328
1789.37	24.3365
1790.38	37.5869
1791.4	26.6975
1792.42	10.6421
1793.43	15.0381
1794.45	1.02588
1795.47	-26.9578
1796.48	30.9287
1797.5	21.9187
1798.51	27.7095
1799.53	37.0828
1800.55	29.8722
1801.56	-3.44263
1802.58	-8.83289
1803.59	35.851
1804.61	-4.59827
1805.62	5.76831
1806.64	36.2877
1807.65	44.5452
1808.66	-1.60535
1809.68	-10.9598
1810.69	18.2302
1811.7	-46.6349
1812.72	13.464
1813.73	-16.3196
1814.74	8.71765
1815.76	-5.1571
1816.77	28.1832
1817.78	-7.79565
1818.79	6.09705
1819.8	26.0787
1820.82	-5.80225
1821.83	-26.9938
1822.84	1.00769
1823.85	23.33
1824.86	13.7952
1825.87	-27.0308
1826.88	-19.0907
1827.89	-18.4274
1828.9	-1.94922
1829.91	6.21155
1830.92	4.5238
1831.93	5.40137
1832.94	39.658
1833.95	-14.9247
1834.96	9.01709
1835.97	-46.2126
1836.98	-8.72681
1837.99	-10.1245
1839	0.47876
1840	25.6766
1841.01	-14.9722
1842.02	-12.7202
1843.03	-13.3572
1844.04	35.0049
1845.04	7.23291
1846.05	14.7275
1847.06	11.074
1848.07	25.4352
1849.07	-3.87
1850.08	8.20959
1851.09	-19.1016
1852.09	0.879028
1853.1	28.7755
1854.1	18.5308
1855.11	57.8068
1856.11	10.969
1857.12	-32.2532
1858.12	1.65759
1859.13	16.4569
1860.13	-15.3682
1861.14	-8.57007
1862.14	0.392456
1863.15	-18.8927
1864.15	37.847
1865.15	34.6167
1866.16	12.1986
1867.16	-16.7031
1868.16	-25.6492
1869.17	-9.48499
1870.17	2.73755
1871.17	36.8495
1872.17	24.9219
1873.18	6.83057
1874.18	5.31165
1875.18	10.3441
1876.18	-16.9902
1877.18	17.0918
1878.18	34.2748
1879.19	7.65894
1880.19	15.226
1881.19	-4.62231
1882.19	-5.39404
1883.19	0.110229
1884.19	19.9117
1885.19	12.7567
1886.19	40.1835
1887.19	29.8271
1888.19	21.562
1889.19	2.17712
1890.19	-4.30017
1891.19	22.6868
1892.18	7.49438
1893.18	-10.0275
1894.18	-20.2828
1895.18	-36.8467
1896.18	10.1665
1897.18	5.24451
1898.17	-10.8169
1899.17	9.98022
1900.17	10.8217
1901.16	-14.26
1902.16	45.9241
1903.16	-6.56165
1904.16	11.8398
1905.15	-2.24512
1906.15	21.7571
1907.14	-14.9918
1908.14	-9.67737
1909.14	1.89417
1910.13	3.15918
1911.13	-40.1674
1912.12	28.6017
1913.12	4.16565
1914.11	9.2804
1915.11	-0.633057
1916.1	-12.7004
1917.1	33.8739
1918.09	33.2787
1919.08	11.4301
1920.08	37.3083
1921.07	-0.643311
1922.06	13.683
1923.06	16.6469
1924.05	-30.0892
1925.04	25.1161
1926.04	4.23621
1927.03	-10.1261
1928.02	15.2216
1929.01	49.6678
1930	-30.7239
1931	12.6344
1931.99	-23.209
1932.98	-38.1239
1933.97	30.0242
1934.96	-15.0975
1935.95	14.4607
1936.94	-3.20129
1937.93	3.14063
1938.92	-23.1635
1939.91	-5.39539
1940.9	5.01709
1941.89	22.5659
1942.88	-5.6991
1943.87	-5.42639
1944.86	19.3688
1945.85	1.7135
1946.84	-28.9976
1947.83	6.56311
1948.82	43.1298
1949.8	-6.75427
1950.79	-17.8857
1951.78	7.69312
1952.77	-29.5774
1953.76	5.72375
1954.74	19.2777
1955.73	-33.9587
1956.72	-28.2517
1957.7	2.90527
1958.69	8.255
1959.68	3.30957
1960.66	26.8252
1961.65	23.0665
1962.63	-23.4033
1963.62	-3.38171
1964.61	-4.16455
1965.59	10.5249
1966.58	19.7932
1967.56	-0.848511
1968.55	-21.1263
1969.53	15.8198
1970.52	25.667
1971.5	-13.3486
1972.48	-5.16553
1973.47	9.32544
1974.45	8.61316
1975.44	28.4799
1976.42	2.23083
1977.4	-5.7196
1978.39	8.21375
1979.37	29.218
1980.35	0.224487
1981.33	12.1725
1982.31	-8.11023
1983.3	-18.3167
1984.28	-14.3251
1985.26	-24.2335
1986.24	2.45276
1987.22	2.73181
1988.21	-13.4314
1989.19	29.0063
1990.17	8.24951
1991.15	23.5111
1992.13	-14.0537
1993.11	29.5635
1994.09	-12.1632
1995.07	14.5355
1996.05	28.6896
1997.03	-16.4155
1998.01	14.8522
1998.99	10.3782
1999.97	-1.94385
2000.95	22.4034
2001.92	24.3208
2002.9	14.3185
2003.88	26.5006
2004.86	11.8154
2005.84	34.774
2006.81	6.29431
2007.79	30.0908
2008.77	7.99915
2009.75	16.3723
2010.73	45.1959
2011.7	42.1262
2012.68	47.6226
2013.67	30.8406
2014.66	30.0149
2015.64	35.3656
2016.63	-9.21008
2017.62	24.6133
2018.61	-24.4257
2019.6	16.3258
2020.58	27.2643
2021.57	28.8279
2022.56	61.6133
2023.55	29.4164
2024.54	2.10742
2025.52	43.009
2026.51	17.6758
2027.5	44.9843
2028.48	18.941
2029.47	-4.46301
2030.45	19.0623
2031.44	35.4606
2032.43	8.39075
2033.41	22.7252
2034.4	-9.15881
2035.38	15.499
2036.37	25.0228
2037.35	2.58533
2038.34	9.16467
2039.32	22.5436
2040.31	-15.891
2041.29	12.6252
2042.27	3.93115
2043.26	35.3877
2044.24	23.4055
2045.23	-12.5879
2046.21	12.5875
2047.19	40.2974
2048.17	22.5197
2049.16	33.8978
2050.14	18.0764
2051.12	4.31531
2052.11	-26.0718
2053.09	21.8944
2054.07	5.96887
2055.05	22.2047
2056.03	25.6215
2057.01	-10.8414
2058	-0.397949
2058.98	-0.124268
2059.96	33.2719
2060.94	8.84387
2061.92	42.1101
2062.9	10.4323
2063.88	1.98071
2064.86	31.5084
2065.84	15.2828
2066.82	-10.0894
2067.8	31.8013
2068.78	14.575
2069.76	-13.5011
2070.73	-15.8591
2071.71	0.146973
2072.69	4.46997
2073.67	44.316
2074.65	-9.16272
2075.63	36.3254
2076.6	27.8252
2077.58	-1.75562
2078.56	19.1853
2079.54	2.05872
2080.51	-8.56091
2081.49	13.7711
2082.47	-13.9193
2083.45	11.5717
2084.42	-1.12878
2085.4	4.34326
2086.37	-0.0300293
2087.35	-13.0056
2088.32	13.7643
2089.3	27.0742
2090.28	-10.6963
2091.25	12.3965
2092.23	37.321
2093.2	42.3763
2094.18	36.3887
2095.15	18.4382
2096.13	8.50977
2097.1	23.8679
2098.07	43.2782
2099.05	24.49
2100.02	39.1171
2101	36.3864
2101.97	6.00989
2102.94	50.2338
2103.92	7.20325
2104.89	5.42957
2105.86	37.8555
2106.83	5.21692
2107.8	19.3328
2108.78	-7.54578
2109.75	41.5956
2110.72	23.7151
2111.69	10.9611
2112.66	14.8701
2113.63	3.36206
2114.61	1.50818
2115.58	-4.45105
2116.55	-2.70593
2117.52	0.126587
2118.49	18.1353
2119.46	-3.94226
2120.43	15.2476
2121.4	9.77686
2122.37	-13.4006
2123.34	26.4012
2124.31	14.646
2125.28	19.4996
2126.25	17.559
2127.21	36.4139
2128.18	-4.31165
2129.15	20.6813
2130.12	6.77979
2131.09	-18.545
2132.06	16.9957
2133.02	17.5323
2133.99	21.9797
2134.96	50.1953
2135.93	15.611
2136.89	25.8918
2137.86	7.23816
2138.83	28.9755
2139.79	9.43726
2140.76	-30.9688
2141.73	12.6257
2142.69	39.691
2143.66	44.7534
2144.62	12.5475
2145.59	3.99341
2146.55	42.0071
2147.52	19.4312
2148.48	6.12231
2149.45	5.73108
2150.42	7.11243
2151.38	-4.76746
2152.34	22.245
2153.31	13.9392
2154.27	23.1042
2155.24	1.53748
2156.2	-9.52734
2157.16	-18.7826
2158.13	-3.24646
2159.09	-21.8145
2160.05	30.2009
2161.01	60.9677
2161.98	-8.90955
2162.94	30.0209
2163.9	1.07166
2164.86	-18.1034
2165.83	23.666
2166.79	-8.53235
2167.75	20.6908
2168.71	10.4973
2169.67	-44.7423
2170.63	1.14978
2171.59	-6.92957
2172.56	-31.5244
2173.51	23.4452
2174.48	-14.2529
2175.44	20.0736
2176.4	-8.33081
2177.36	-32.2295
2178.32	-15.5123
2179.28	13.9236
2180.23	12.0801
2181.19	27.4457
2182.15	-8.53577
2183.11	-21.3883
2184.07	-30.5968
2185.03	5.78967
2185.99	-14.0006
2186.95	32.8527
2187.9	26.4822
2188.86	3.32825
2189.82	-5.21045
2190.78	6.89441
2191.73	-0.182617
2192.69	14.2877
2193.65	-6.95374
2194.6	-0.62439
2195.56	25.1497
2196.52	16.7078
2197.47	39.0377
2198.43	-7.42114
2199.38	3.88354
2200.34	7.39758
2201.3	37.5046
2202.25	8.04395
2203.21	10.23
2204.16	7.47375
2205.12	38.5557
2206.07	21.9523
2207.03	13.3807
2207.98	-15.3158
2208.93	-11.0875
2209.89	60.2302
2210.84	12.2773
2211.8	14.3612
2212.75	17.4041
2213.7	5.40234
2214.66	-0.262573
2215.61	44.7687
2216.56	2.84668
2217.51	-16.9899
2218.47	22.3276
2219.42	39.0376
2220.37	-11.4104
2221.32	-1.51807
2222.27	9.87805
2223.23	7.17944
2224.18	33.0148
2225.13	-8.06311
2226.08	10.5439
2227.03	-36.746
2227.98	-28.2866
2228.93	-39.0328
2229.88	42.6461
2230.83	-15.7921
2231.78	-16.0682
2232.73	-7.13232
2233.68	-32.1465
2234.63	-11.6868
2235.58	-35.5662
2236.53	-26.3912
2237.48	-0.289429
2238.43	-5.30469
2239.38	17.627
2240.33	11.2009
2241.27	-8.73132
2242.22	-24.2705
2243.17	31.1125
2244.12	20.9707
2245.07	-12.1787
2246.01	9.83838
2246.96	-23.9047
2247.91	27.0803
2248.85	34.3347
2249.8	25.8872
2250.75	-17.0348
2251.69	-21.2023
2252.64	-21.6776
2253.59	31.0964
2254.53	11.9326
2255.48	-27.6636
2256.42	1.27771
2257.37	-14.5327
2258.32	-24.0815
2259.26	14.5671
2260.2	24.9133
2261.15	-18.916
2262.1	27.921
2263.04	1.2981
2263.98	-23.312
2264.93	18.3392
2265.87	26.2528
2266.81	-2.27087
2267.76	-10.2806
2268.7	-1.76831
2269.65	-8.20422
2270.59	11.2382
2271.53	-2.73303
2272.47	25.0972
2273.42	-4.18542
2274.36	5.81567
2275.3	-40.6372
2276.24	0.0467529
2277.18	-3.08643
2278.13	-34.2998
2279.07	19.7292
2280.01	-12.2228
2280.95	-16.7643
2281.89	-12.7197
2282.83	12.2305
2283.77	59.4447
2284.71	15.3376
2285.65	6.92798
2286.59	2.10059
2287.54	3.12805
2288.47	4.96594
2289.41	45.0503
2290.35	3.41943
2291.29	24.7675
2292.23	4.47156
2293.17	20.4369
2294.11	4.99976
2295.05	-21.8787
2295.99	-0.626465
2296.93	4.76099
2297.86	-23.8948
2298.8	-5.74646
2299.74	10.2732
2300.68	3.71155
2301.61	11.4692
2302.55	-15.5277
2303.49	17.1534
2304.43	29.2972
2305.36	35.2788
2306.3	-23.8915
2307.24	25.7837
2308.17	12.7388
2309.11	2.93335
2310.04	24.8623
2310.98	23.5638
2311.92	-21.5594
2312.85	-1.8186
2313.79	-2.21704
2314.72	4.92017
2315.66	4.15149
2316.59	14.6243
2317.52	19.8287
2318.46	15.3817
2319.39	-9.72986
2320.33	20.6914
2321.26	-16.3849
2322.2	-22.5565
2323.13	-29.1224
2324.06	-16.9955
2325	21.2678
2325.93	32.0327
2326.86	46.1266
2327.79	284.874
2328.73	77.3105
2329.66	15.6093
2330.59	17.5193
2331.52	3.91345
2332.46	-17.6417
2333.39	25.7388
2334.32	-7.66284
2335.25	-16.3792
2336.18	6.86609
2337.11	-19.3754
2338.04	-0.370117
2338.97	-7.28308
2339.91	-37.8496
2340.84	-3.05676
2341.77	-6.85168
2342.7	50.4625
2343.63	-44.5941
2344.56	-30.0583
2345.49	-0.448975
2346.41	16.5797
2347.34	-13.3781
2348.27	4.01453
2349.2	9.16113
2350.13	11.5635
2351.06	1.86096
2351.99	21.1965
2352.91	-19.3243
2353.84	-2.45837
2354.77	-2.19019
2355.7	-35.226
2356.63	2.88049
2357.55	-6.55298
2358.48	10.8132
2359.41	-30.5757
2360.33	-6.57043
2361.26	20.5972
2362.19	-16.8436
2363.11	19.6887
2364.04	19.9604
2364.97	-10.0197