File: Data/3-Raman/processed/bu19w-e-ff11b-fi02-v_1800 (450-850nm)_532nm_edge_100%_x100_vis_h50um_30sx2_01.txt
#Acq. time (s)=	30
#Accumulations=	2
#Range (cm-¹)=	1200...2365
#Windows=	3
#Auto scanning=	Off
#Autofocus=	Off
#Macrospot=	Off
#AutoExposure=	Off
#Spike filter=	Multiple accum.
#Delay time (s)=	2
#Binning=	1
#Readout mode=	Signal
#DeNoise=	Off
#ICS correction=	On
#Dark correction=	Off
#Inst. Process=	Off
#Detector Gain=	Best Dynamic
#Detector ADC=	50 kHz HS
#Detector temperature (°C)=	-60.09
#Instrument=	LabRAM HR Evol
#Detector=	SIN-EM FIVIS
#Objective=	x100_VIS
#Grating=	1800 (450-850nm)
#ND Filter=	100%
#Laser=	532nm_Edge
#Hole=	49.98
#Temperature=	0
#Range=	Visible
#StageXY=	75x50mm Scan+
#StageZ=	Z motor
#X (µm)=	0
#Y (µm)=	0
#Z (µm)=	-251.2
#Full time(mm:ss)=	3:17
#Project=	21_11_04
#Sample=	BU19w
#Site=
#Title=	BU19w-E-FF11b-FI02-V_1800 (450-850nm)_532nm_Edge_100%_x100_VIS_H50um_30sX2
#Remark=
#Date=	04.11.2021 18:23
#Acquired=	04.11.2021 18:23:01
#Base:Fit=	16.12.2021 17:39:50
#Base:Fit=	16.12.2021 17:46:34
#Base:Sub=	16.12.2021 17:46:35
1202.73	5.97152
1203.85	5.42861
1204.96	4.94571
1206.07	0.143879
1207.18	-0.337404
1208.29	3.48803
1209.4	1.98481
1210.51	3.67824
1211.62	-3.15883
1212.73	1.75571
1213.84	-1.81864
1214.95	4.21004
1216.06	0.638124
1217.17	-0.804586
1218.28	-0.0964432
1219.39	-0.42754
1220.5	1.38182
1221.61	-0.00684357
1222.72	-0.357254
1223.82	-2.79785
1224.93	-0.969208
1226.04	-0.167168
1227.15	-2.57856
1228.25	3.38757
1229.36	-0.929153
1230.47	4.04408
1231.57	-1.51574
1232.68	-1.73955
1233.79	2.26089
1234.89	-0.0225906
1236	0.84222
1237.1	0.619461
1238.21	1.43567
1239.31	0.193447
1240.42	-2.07029
1241.52	-0.145622
1242.63	-1.33756
1243.74	1.66156
1244.84	-0.599625
1245.94	0.273094
1247.05	-1.95934
1248.15	-3.15838
1249.25	-4.326
1250.36	5.98829
1251.46	-2.51358
1252.56	1.52492
1253.66	1.42476
1254.77	0.298
1255.87	-1.88321
1256.97	5.33981
1258.07	11.5012
1259.18	4.10154
1260.28	6.10118
1261.38	17.5095
1262.48	31.0077
1263.58	39.3829
1264.68	26.7861
1265.78	9.99114
1266.88	7.87815
1267.98	2.6556
1269.08	9.9627
1270.18	8.81933
1271.28	1.42598
1272.38	5.61771
1273.48	6.67276
1274.58	7.69614
1275.68	12.9359
1276.78	9.79148
1277.87	11.907
1278.97	22.4323
1280.07	25.5473
1281.17	67.6785
1282.26	282.434
1283.36	838.819
1284.46	313.292
1285.55	60.2725
1286.65	22.3394
1287.75	15.9814
1288.84	11.7799
1289.94	11.8063
1291.04	7.57314
1292.13	3.35543
1293.23	2.31836
1294.32	3.39879
1295.42	4.51809
1296.51	3.49747
1297.61	6.63093
1298.7	2.39477
1299.79	2.39889
1300.89	4.51527
1301.98	0.316097
1303.08	0.311504
1304.17	-0.74033
1305.26	2.40827
1306.36	-1.82713
1307.45	3.46105
1308.54	3.47934
1309.63	-2.82096
1310.73	1.4138
1311.82	6.72475
1312.91	2.51185
1314	-3.81134
1315.09	1.50184
1316.18	1.52163
1317.28	-1.62248
1318.37	1.57225
1319.46	-3.69294
1320.55	2.65337
1321.64	-4.75565
1322.73	3.67658
1323.82	0.539391
1324.91	-1.55018
1325.99	-1.6062
1327.08	-2.59688
1328.17	2.75627
1329.26	3.84302
1330.35	-4.59179
1331.44	0.646671
1332.53	2.72472
1333.62	0.598164
1334.7	4.78428
1335.79	-2.56081
1336.88	2.6904
1337.96	3.73523
1339.05	-0.440498
1340.14	-1.45315
1341.23	5.89769
1342.31	-1.43543
1343.4	1.71734
1344.48	4.87681
1345.57	-0.363205
1346.66	2.73937
1347.74	2.73703
1348.83	-1.42316
1349.91	1.70262
1351	-1.42308
1352.08	-5.55079
1353.17	6.01365
1354.25	6.94384
1355.33	-1.34697
1356.42	1.79819
1357.5	3.88535
1358.58	1.81071
1359.67	2.84784
1360.75	3.88812
1361.83	4.94434
1362.92	7.04765
1364	10.2014
1365.08	8.13154
1366.16	6.05224
1367.24	7.08972
1368.33	15.4083
1369.41	29.915
1370.49	8.20865
1371.57	9.21358
1372.65	9.19957
1373.73	13.3361
1374.81	10.2665
1375.89	10.3028
1376.97	12.3461
1378.05	16.5835
1379.13	19.7175
1380.21	21.7088
1381.29	24.773
1382.37	29.8316
1383.45	46.2033
1384.53	72.9405
1385.61	253.806
1386.68	1517.23
1387.76	568.637
1388.84	92.7015
1389.92	43.3445
1390.99	33.1048
1392.07	18.7436
1393.15	18.7548
1394.23	11.6146
1395.3	11.6739
1396.38	16.8137
1397.46	12.7321
1398.53	7.66973
1399.61	11.8204
1400.68	12.9074
1401.76	11.9604
1402.83	12.084
1403.91	13.1197
1404.99	18.265
1406.06	23.398
1407.13	50.1063
1408.21	89.1356
1409.28	60.4954
1410.36	20.4936
1411.43	15.3722
1412.5	11.4039
1413.58	10.3716
1414.65	4.3142
1415.72	8.47071
1416.8	4.42314
1417.87	6.53058
1418.94	6.5763
1420.01	7.61328
1421.08	2.4987
1422.16	2.59243
1423.23	10.7124
1424.3	2.57219
1425.37	2.65151
1426.44	2.66807
1427.51	5.73477
1428.58	1.68329
1429.65	2.7783
1430.72	-1.23025
1431.79	0.865444
1432.86	0.867119
1433.93	0.885586
1435	4.02426
1436.07	2.01133
1437.14	3.0697
1438.21	-2.00005
1439.28	9.33352
1440.35	-1.87381
1441.41	1.24054
1442.48	-1.77716
1443.55	3.37875
1444.62	3.45725
1445.69	3.49683
1446.75	3.53199
1447.82	3.57296
1448.89	2.6075
1449.95	4.68517
1451.02	-2.45303
1452.09	2.70998
1453.15	5.84432
1454.22	-4.35904
1455.28	0.815304
1456.35	-2.2104
1457.41	0.898796
1458.48	1.97752
1459.54	-1.04605
1460.61	2.06418
1461.67	3.11624
1462.74	0.0657806
1463.8	3.19566
1464.86	1.15797
1465.93	3.21635
1466.99	-2.8789
1468.05	2.26732
1469.12	4.34436
1470.18	-4.80259
1471.24	0.325195
1472.31	1.3889
1473.37	1.42501
1474.43	-3.61032
1475.49	-1.52752
1476.55	-0.473938
1477.62	3.63816
1478.68	-0.398006
1479.74	-1.38996
1480.8	2.69499
1481.86	-3.32341
1482.92	2.83559
1483.98	1.84823
1485.04	4.80537
1486.1	-0.126339
1487.16	4.98819
1488.22	1.97731
1489.28	-0.00951004
1490.34	-6.03237
1491.4	1.08834
1492.46	4.17454
1493.52	-0.82819
1494.57	2.26154
1495.63	2.27731
1496.69	-2.72969
1497.75	-2.6761
1498.81	2.43137
1499.86	1.48695
1500.92	2.54184
1501.98	2.59095
1503.03	3.63052
1504.09	3.69158
1505.15	-2.31474
1506.2	4.77485
1507.26	3.83609
1508.32	-0.140293
1509.37	1.93378
1510.43	1.97888
1511.48	3.99188
1512.54	2.99104
1513.59	0.0420074
1514.65	4.10567
1515.7	3.12088
1516.76	0.16032
1517.81	1.23169
1518.86	5.31261
1519.92	-0.650364
1520.97	-0.584097
1522.02	-1.5377
1523.08	0.49976
1524.13	1.53095
1525.18	4.60218
1526.24	2.68443
1527.29	4.73922
1528.34	2.78054
1529.39	1.82908
1530.44	6.90792
1531.5	5.9734
1532.55	5.0479
1533.6	2.12219
1534.65	6.18329
1535.7	1.19099
1536.75	4.21279
1537.8	1.24823
1538.85	0.31711
1539.9	6.45858
1540.95	5.52032
1542	5.54473
1543.05	8.57009
1544.1	4.61822
1545.15	2.71587
1546.2	4.78774
1547.25	3.85611
1548.29	9.9172
1549.34	5.89854
1550.39	11.1576
1551.44	7.15825
1552.49	3.2265
1553.53	4.24461
1554.58	2.26039
1555.63	4.32357
1556.68	6.38325
1557.72	-0.582449
1558.77	4.44349
1559.82	4.47831
1560.86	4.53127
1561.91	4.61798
1562.95	4.67183
1564	-0.24847
1565.04	6.67601
1566.09	3.83782
1567.13	5.92095
1568.18	7.96056
1569.22	3.99683
1570.27	7.05687
1571.31	4.10237
1572.36	7.13905
1573.4	2.18837
1574.44	6.26698
1575.49	3.3445
1576.53	3.37909
1577.57	7.38139
1578.62	4.43425
1579.66	6.4939
1580.7	0.561285
1581.74	2.59143
1582.79	9.61234
1583.83	1.69744
1584.87	5.74048
1585.91	5.77837
1586.95	10.7898
1587.99	6.86789
1589.03	5.94553
1590.07	8.99527
1591.12	5.06933
1592.16	5.0966
1593.2	4.11586
1594.24	3.16162
1595.28	9.17778
1596.32	9.22784
1597.35	5.31725
1598.39	2.36878
1599.43	5.37694
1600.47	5.40208
1601.51	10.3666
1602.55	2.47288
1603.59	-0.455639
1604.63	4.5425
1605.66	6.58332
1606.7	6.64847
1607.74	5.59875
1608.78	5.73985
1609.81	6.63271
1610.85	4.94549
1611.89	4.05478
1612.92	8.07301
1613.96	5.0463
1615	2.39165
1616.03	6.28409
1617.07	4.91531
1618.1	6.389
1619.14	3.81242
1620.17	4.25307
1621.21	3.43252
1622.24	4.43811
1623.28	4.35337
1624.31	2.37787
1625.35	4.08222
1626.38	4.79296
1627.41	3.69532
1628.45	4.61917
1629.48	2.09648
1630.51	8.4071
1631.3	1.7589
1632.34	-0.142574
1633.39	-1.10202
1634.43	2.89356
1635.48	1.94629
1636.52	4.93158
1637.57	2.01046
1638.61	3.03477
1639.66	5.0463
1640.7	1.16462
1641.75	0.216097
1642.79	9.11458
1643.83	5.21049
1644.88	4.26987
1645.92	2.3421
1646.96	5.32428
1648.01	3.4013
1649.05	1.49892
1650.09	0.566471
1651.13	2.59427
1652.18	0.664162
1653.22	2.67118
1654.26	6.6619
1655.3	2.78634
1656.34	-0.118128
1657.38	3.86196
1658.42	5.86073
1659.47	1.936
1660.51	1.00159
1661.55	-1.90259
1662.59	3.11073
1663.63	5.08015
1664.67	-2.75056
1665.71	3.23611
1666.75	3.22446
1667.79	4.22824
1668.83	-0.640701
1669.86	2.35522
1670.9	1.42302
1671.94	-2.49298
1672.98	-0.479721
1674.02	0.554256
1675.06	-3.35542
1676.1	0.639215
1677.13	0.670019
1678.17	1.67369
1679.21	1.69442
1680.25	-0.259315
1681.28	3.72012
1682.32	-0.199755
1683.35	1.80574
1684.39	-1.13478
1685.43	-2.09273
1686.46	-3.04089
1687.5	1.92201
1688.54	0.950382
1689.57	-1.99831
1690.6	0.998663
1691.64	3.99542
1692.68	1.04853
1693.71	2.03768
1694.74	-1.88409
1695.78	1.10672
1696.81	2.11625
1697.85	4.08809
1698.88	1.15109
1699.92	-0.791849
1700.95	2.17935
1701.98	-0.762442
1703.01	0.237457
1704.05	2.22895
1705.08	-0.695259
1706.11	-1.66559
1707.14	4.22356
1708.18	2.25123
1709.21	-0.683483
1710.24	1.30006
1711.27	-2.5837
1712.3	-3.55445
1713.33	-1.60983
1714.36	-2.57505
1715.4	0.386179
1716.43	-1.56117
1717.46	4.27127
1718.49	3.28782
1719.52	-1.56082
1720.55	2.34329
1721.58	1.36806
1722.61	-0.578814
1723.64	2.34488
1724.66	-1.53745
1725.69	-0.574459
1726.72	3.30867
1727.75	4.2947
1728.78	1.31282
1729.81	-2.50956
1730.83	4.28844
1731.86	-4.39413
1732.89	1.40323
1733.92	-0.543594
1734.95	0.407555
1735.97	2.33567
1737	-2.47143
1738.03	1.37505
1739.05	0.404524
1740.08	-0.576168
1741.1	-1.53889
1742.13	0.382092
1743.16	-1.52361
1744.18	-0.565704
1745.21	-0.551489
1746.23	1.35526
1747.26	-2.47365
1748.28	-0.553171
1749.31	-1.48263
1750.33	-0.495977
1751.36	-2.39853
1752.38	-1.45105
1753.4	2.36167
1754.43	4.26229
1755.45	-4.31625
1756.47	0.433044
1757.5	-2.42086
1758.52	5.21289
1759.54	-0.484737
1760.57	2.37057
1761.59	2.36696
1762.61	-5.22178
1763.63	-1.40428
1764.66	0.529482
1765.68	-1.35853
1766.7	-1.35193
1767.72	-0.400127
1768.74	-3.26539
1769.76	-1.37055
1770.78	0.553337
1771.8	-0.37007
1772.82	0.605192
1773.84	-0.328993
1774.86	4.45219
1775.88	3.53332
1776.9	-2.18658
1777.92	-2.19234
1778.94	-2.20269
1779.96	-2.18623
1780.98	-4.0764
1782	-3.10418
1783.02	-3.08552
1784.04	2.6595
1785.05	-1.14266
1786.07	-1.13797
1787.09	-0.154476
1788.11	1.82167
1789.12	3.77164
1790.14	-4.83746
1791.16	-1.97408
1792.18	-2.92546
1793.19	-0.997562
1794.21	-2.90578
1795.23	0.976372
1796.24	0.0397797
1797.26	0.0625095
1798.27	-0.885616
1799.29	1.0324
1800.3	-0.895668
1801.32	1.02991
1802.33	1.04666
1803.35	0.107855
1804.36	-2.76052
1805.38	-1.77291
1806.39	0.172567
1807.41	-3.67536
1808.42	2.1159
1809.43	-0.76685
1810.45	1.16594
1811.46	1.17013
1812.47	1.18632
1813.49	-1.69032
1814.5	-1.66225
1815.51	1.25003
1816.53	-1.64142
1817.54	-0.68997
1818.55	-1.63881
1819.56	0.307903
1820.57	1.29047
1821.58	1.30875
1822.6	-0.615973
1823.61	1.31925
1824.62	0.364059
1825.63	3.27899
1826.64	-0.587608
1827.65	0.393225
1828.66	2.32629
1829.67	0.388123
1830.68	1.35731
1831.69	1.37438
1832.7	3.33002
1833.71	1.40093
1834.72	-3.47374
1835.73	0.382971
1836.74	4.31175
1837.75	-3.49297
1838.75	-2.47232
1839.76	-1.50243
1840.77	-1.5482
1841.78	-0.612207
1842.79	-2.54213
1843.79	-1.57565
1844.8	-2.53591
1845.81	-0.576569
1846.81	4.18507
1847.82	-6.3995
1848.83	1.29204
1849.83	1.26619
1850.84	2.2075
1851.85	1.24313
1852.85	-1.6352
1853.86	1.22884
1854.86	0.253609
1855.87	1.19925
1856.87	1.20044
1857.88	3.10509
1858.88	3.08483
1859.89	0.215746
1860.89	5.97586
1861.9	-1.67235
1862.9	-2.6431
1863.9	2.12177
1864.91	-1.71391
1865.91	2.06982
1866.92	2.98539
1867.92	-1.78139
1868.92	2.97638
1869.92	2.02455
1870.93	-2.72635
1871.93	2.01736
1872.93	-0.840406
1873.93	1.04857
1874.93	-1.8149
1875.94	1.94214
1876.94	1.91161
1877.94	-3.71313
1878.94	0.088541
1879.94	0.0784473
1880.94	-1.81879
1881.94	2.86505
1882.94	3.91035
1883.94	-2.8227
1884.94	0.967173
1885.94	-1.83792
1886.94	-1.85188
1887.94	0.0142994
1888.94	-0.0075779
1889.94	0.943121
1890.94	0.953121
1891.94	1.89617
1892.94	-0.949358
1893.93	-0.962776
1894.93	-0.962002
1895.93	-0.946245
1896.93	-0.927984
1897.93	0.956127
1898.92	0.941542
1899.92	-1.88076
1900.92	-0.925833
1901.91	1.91995
1902.91	1.91895
1903.91	-0.901979
1904.9	-1.83964
1905.9	-0.911152
1906.9	-1.85129
1907.89	-1.83615
1908.89	-3.70038
1909.88	1.03328
1910.88	-1.76729
1911.87	-1.76328
1912.87	-0.815599
1913.86	3.92504
1914.86	-0.766504
1915.85	-0.762245
1916.85	0.172602
1917.84	1.12042
1918.84	2.09578
1919.83	3.07249
1920.82	3.08953
1921.82	-1.6223
1922.81	1.21049
1923.8	0.260714
1924.79	-0.678865
1925.79	1.24139
1926.78	1.27034
1927.77	-0.606262
1928.76	1.30604
1929.75	-0.560108
1930.75	1.35946
1931.74	-3.38982
1932.73	0.402348
1933.72	-0.510475
1934.71	1.4687
1935.7	0.525942
1936.69	1.47163
1937.68	2.41107
1938.67	2.43133
1939.66	1.4981
1940.65	0.585409
1941.64	1.52459
1942.63	-2.25151
1943.62	4.42179
1944.61	2.54405
1945.6	0.661087
1946.59	-0.280859
1947.58	3.54607
1948.57	1.64317
1949.55	2.62901
1950.54	0.75773
1951.53	-0.16535
1952.52	0.812115
1953.5	1.75806
1954.49	-1.15055
1955.48	3.66435
1956.47	2.75022
1957.45	2.77659
1958.44	2.78816
1959.43	2.78357
1960.41	1.81428
1961.4	0.851442
1962.38	-0.0972309
1963.37	4.71341
1964.36	2.80425
1965.34	1.85297
1966.33	-0.0433292
1967.31	3.81328
1968.3	3.82039
1969.28	-0.0400295
1970.26	-0.0503712
1971.25	1.86493
1972.23	1.87678
1973.22	-0.0487919
1974.2	0.910587
1975.18	-0.991611
1976.17	-0.0180206
1977.15	0.944054
1978.13	1.89668
1979.12	0.944059
1980.1	-0.0117054
1981.08	3.81528
1982.06	4.77249
1983.05	-0.985292
1984.03	2.83907
1985.01	-0.0372524
1985.99	0.9328
1986.97	-0.972464
1987.95	0.914688
1988.93	-1.03622
1989.91	4.47121
1990.89	0.908894
1991.88	-1.69181
1992.86	4.2288
1993.84	1.63546
1994.82	-2.0064
1995.8	2.45157
1996.78	0.267921
1997.76	-1.29187
1998.73	1.93519
1999.71	0.0153923
2000.69	1.93661
2001.67	0.0355549
2002.65	0.368372
2003.63	-0.29491
2004.6	1.17164
2005.58	0.362312
2006.56	0.557669
2007.54	-1.4631
2008.52	-0.961439
2009.49	0.0228367
2010.47	0.818577
2011.45	-0.863703
2012.42	-2.07944
2013.41	1.65713
2014.4	-0.25272
2015.39	2.57904
2016.38	-0.209959
2017.37	-1.15906
2018.35	-2.12295
2019.34	-4.95028
2020.33	-1.20278
2021.32	1.61362
2022.31	0.667597
2023.29	0.651278
2024.28	-1.23608
2025.27	-1.2566
2026.25	-2.17362
2027.24	0.679668
2028.23	0.636536
2029.21	0.67593
2030.2	1.53685
2031.19	-1.23058
2032.17	0.660851
2033.16	-0.246067
2034.14	-0.283024
2035.13	-1.19521
2036.11	-3.044
2037.1	5.37825
2038.08	-0.239244
2039.07	-1.18395
2040.05	2.53027
2041.03	0.651024
2042.02	-3.08399
2043	1.58212
2043.99	-0.257763
2044.97	-1.20167
2045.95	-0.201714
2046.94	1.62192
2047.92	-2.12751
2048.9	-0.247421
2049.88	2.58253
2050.87	2.58552
2051.85	-0.218485
2052.83	0.729019
2053.81	-1.11582
2054.79	-1.11527
2055.78	-3.9285
2056.76	1.67878
2057.74	1.69153
2058.72	1.71337
2059.7	1.71588
2060.68	-0.155792
2061.66	-1.08627
2062.64	-2.01213
2063.62	0.81082
2064.6	-1.98962
2065.58	5.54232
2066.56	0.858332
2067.54	1.81029
2068.52	0.879211
2069.5	-0.0829029
2070.48	-0.0516624
2071.46	2.80066
2072.43	-0.0293903
2073.41	1.85367
2074.39	-0.0169525
2075.37	0.962463
2076.35	2.85511
2077.32	-0.942274
2078.3	2.84112
2079.28	1.9215
2080.26	2.87814
2081.23	3.81672
2082.21	-1.85017
2083.19	-0.907789
2084.16	0.981142
2085.14	3.81605
2086.12	1.94481
2087.09	0.0624218
2088.07	-0.883785
2089.04	-1.82396
2090.02	1.0261
2090.99	0.0857983
2091.97	0.108852
2092.94	1.08138
2093.92	1.09575
2094.89	2.03814
2095.87	0.123091
2096.84	2.01131
2097.81	-0.84865
2098.79	1.04173
2099.76	1.03795
2100.74	1.99777
2101.71	0.0994511
2102.68	1.0372
2103.65	1.02911
2104.63	2.93687
2105.6	2.95089
2106.57	-3.70067
2107.54	2.93953
2108.52	2.91412
2109.49	1.02286
2110.46	-2.78101
2111.43	1.95764
2112.4	1.95623
2113.38	1.01737
2114.35	-1.84081
2115.32	1.95225
2116.29	0.984623
2117.26	0.976845
2118.23	-0.944674
2119.2	-0.967428
2120.17	-1.92788
2121.14	0.925594
2122.11	0.938391
2123.08	-0.00708961
2124.05	-0.973331
2125.02	-2.90735
2125.98	2.7444
2126.95	2.72076
2127.92	1.76301
2128.89	3.64557
2129.86	1.74441
2130.83	-2.9941
2131.79	5.48749
2132.76	1.69317
2133.73	4.52152
2134.7	0.740011
2135.67	1.66435
2136.63	-2.1225
2137.6	0.706694
2138.57	0.698862
2139.53	0.676067
2140.5	1.60095
2141.46	-1.2405
2142.43	2.52403
2143.4	-1.29297
2144.36	3.42745
2145.33	-2.23202
2146.29	5.27458
2147.26	-1.32151
2148.22	1.47955
2149.19	2.38846
2150.15	-0.450756
2151.12	-0.450882
2152.08	-2.32762
2153.05	2.34088
2154.01	-3.30433
2154.97	-2.40574
2155.94	3.17548
2156.9	-1.50263
2157.86	0.371229
2158.83	3.1627
2159.79	0.333557
2160.75	0.313356
2161.72	0.301262
2162.68	-3.44111
2163.64	-1.59136
2164.6	-0.679543
2165.56	0.249121
2166.53	0.2304
2167.49	-0.731314
2168.45	-0.752028
2169.41	0.191404
2170.37	1.13149
2171.33	1.095
2172.29	3.85374
2173.25	-0.798969
2174.21	-2.65818
2175.17	-2.66753
2176.13	-1.75121
2177.09	-2.68727
2178.05	0.0862484
2179.01	1.00385
2179.97	1.9256
2180.93	-1.79893
2181.89	0.0422153
2182.85	0.950676
2183.81	0.925032
2184.76	-0.00455093
2185.72	2.78309
2186.68	-0.910116
2187.64	1.88134
2188.6	-1.85577
2189.55	3.67972
2190.51	-0.958246
2191.47	1.82273
2192.42	2.75471
2193.38	1.84394
2194.34	0.934029
2195.3	-0.0138264
2196.25	-0.0456238
2197.21	-1.9179
2198.16	0.873426
2199.12	0.897181
2200.07	-1.85916
2201.03	0.94516
2201.99	-3.79488
2202.94	-0.0394955
2203.9	0.947607
2204.85	-0.964527
2205.8	-0.0517311
2206.76	-0.058466
2207.71	0.886049
2208.67	0.897129
2209.62	-0.967777
2210.58	-2.82284
2211.53	-0.0141468
2212.48	-0.0155411
2213.44	-0.0282669
2214.39	1.85992
2215.34	1.86244
2216.29	1.85771
2217.25	-3.74646
2218.2	-3.74727
2219.15	0.933374
2220.1	0.934746
2221.06	-2.81786
2222.01	0.901926
2222.96	-0.956478
2223.91	-0.934958
2224.86	0.954832
2225.81	-1.83565
2226.76	0.990211
2227.72	0.991539
2228.67	2.85926
2229.62	0.0595074
2230.57	-2.74062
2231.52	-3.66445
2232.47	3.87261
2233.42	0.12566
2234.37	2.00494
2235.31	1.04499
2236.26	2.93038
2237.21	0.127117
2238.16	0.157398
2239.11	-3.60015
2240.06	3.92694
2241.01	0.177002
2241.96	2.07281
2242.9	1.13007
2243.85	3.95598
2244.8	-2.62613
2245.75	2.12043
2246.69	1.18964
2247.64	-2.59202
2248.59	3.08219
2249.53	1.19711
2250.48	-2.60139
2251.43	-2.60712
2252.37	-2.59057
2253.32	1.23098
2254.26	-0.649719
2255.21	-0.647495
2256.16	-1.58161
2257.1	-0.616037
2258.05	-0.606886
2258.99	-1.54364
2259.94	0.369049
2260.88	1.34098
2261.83	2.30307
2262.77	1.37416
2263.71	2.36513
2264.66	1.44138
2265.6	1.45046
2266.55	0.47891
2267.49	-0.486286
2268.43	-0.484425
2269.38	1.45182
2270.32	1.48008
2271.26	1.50051
2272.2	-1.35589
2273.15	-1.34649
2274.09	1.53426
2275.03	0.587952
2275.97	1.56412
2276.92	-0.325775
2277.86	0.670019
2278.8	0.675892
2279.74	-0.304577
2280.68	2.56195
2281.62	2.56578
2282.56	-2.20584
2283.5	1.67404
2284.44	1.70665
2285.38	-1.16883
2286.32	1.71674
2287.26	-2.10258
2288.2	0.792303
2289.14	4.62028
2290.08	-0.199488
2291.02	-0.177328
2291.96	1.77143
2292.9	2.7606
2293.84	2.76732
2294.78	1.79512
2295.72	0.825121
2296.65	2.74828
2297.59	-1.0731
2298.53	-0.0854931
2299.47	-1.0327
2300.41	-1.02102
2301.34	-1.00736
2302.28	1.89079
2303.22	-0.0351219
2304.15	-0.0172195
2305.09	-0.96616
2306.03	1.94753
2306.97	-2.88096
2307.9	1.94785
2308.84	-1.90397
2309.77	0.0544739
2310.71	3.9224
2311.64	-0.946512
2312.58	-1.91632
2313.51	1.0083
2314.45	1.04399
2315.39	-1.86256
2316.32	0.0485249
2317.25	2.95747
2318.19	-1.87541
2319.12	1.97719
2320.06	1.98006
2320.99	0.0667648
2321.92	2.99389
2322.86	1.06902
2323.79	2.0426
2324.72	6.85449
2325.66	9.72878
2326.59	24.171
2327.52	105.103
2328.46	106.058
2329.39	18.3353
2330.32	10.6285
2331.25	5.82329
2332.18	0.999912
2333.12	0.988899
2334.05	0.974756
2334.98	1.92788
2335.91	0.00384903
2336.84	2.88298
2337.77	3.83717
2338.7	-0.00967598
2339.63	1.90574
2340.56	0.92379
2341.49	-0.0650444
2342.42	-0.079237
2343.35	1.83211
2344.28	1.83022
2345.21	-0.103804
2346.14	-2.03559
2347.07	-2.04595
2348	-0.131227
2348.93	3.67717
2349.85	3.61357
2350.78	1.71929
2351.71	3.58264
2352.64	4.47589
2353.57	0.65382
2354.5	1.60636
2355.42	1.58732
2356.35	1.54448
2357.28	4.36792
2358.21	0.540329
2359.13	2.41872
2360.06	3.33304
2360.99	1.39768
2361.91	-0.537075
2362.84	0.376102
2363.77	0.347845
2364.69	-2.51967
2364.92	1.25347