File: Data/3-Raman/processed/bu19(2)w-a-ff1-fi01-s_1800 (450-850nm)_532nm_edge_10%_x100_vis_lwd_h50um_30sx2_01.txt
#Acq. time (s)=	30
#Accumulations=	2
#Range (cm-¹)=	99...1000
#Windows=	2
#Auto scanning=	Off
#Autofocus=	Off
#Macrospot=	Off
#AutoExposure=	Off
#Spike filter=	Multiple accum.
#Delay time (s)=	2
#Binning=	1
#Readout mode=	Signal
#DeNoise=	Off
#ICS correction=	On
#Dark correction=	Off
#Inst. Process=	Off
#Detector Gain=	Best Dynamic
#Detector ADC=	50 kHz HS
#Detector temperature (°C)=	-60.09
#Instrument=	LabRAM HR Evol
#Detector=	SIN-EM FIVIS
#Objective=	x100_VIS_LWD
#Grating=	1800 (450-850nm)
#ND Filter=	10%
#Laser=	532nm_Edge
#Hole=	49.98
#Temperature=	0
#Range=	Visible
#StageXY=	75x50mm Scan+
#StageZ=	Z motor
#X (µm)=	0
#Y (µm)=	0
#Z (µm)=	-45.7
#Full time(mm:ss)=	2:09
#Project=	21_11_26
#Sample=	BU19(2)w
#Site=
#Title=	BU19(2)w-A-FF1-FI01-S_1800 (450-850nm)_532nm_Edge_10%_x100_VIS_LWD_H50um_30sX2
#Remark=
#Date=	26.11.2021 11:52
#Acquired=	26.11.2021 11:52:27
#Base:Fit=	16.12.2021 16:00:56
#Base:Edit=	16.12.2021 16:03:35
#Base:Clear=	16.12.2021 16:03:37
#Base:Edit=	16.12.2021 16:03:39
#Base:Edit=	16.12.2021 16:03:39
#Base:Edit=	16.12.2021 16:03:40
#Base:Edit=	16.12.2021 16:03:40
#Base:Edit=	16.12.2021 16:03:41
#Base:Edit=	16.12.2021 16:03:41
#Base:Edit=	16.12.2021 16:03:43
#Base:Edit=	16.12.2021 16:03:44
#Base:Edit=	16.12.2021 16:03:45
#Base:Edit=	16.12.2021 16:03:45
#Base:Edit=	16.12.2021 16:03:46
#Base:Edit=	16.12.2021 16:03:47
#Base:Edit=	16.12.2021 16:03:47
#Base:Edit=	16.12.2021 16:03:48
#Base:Edit=	16.12.2021 16:03:49
#Base:Edit=	16.12.2021 16:03:50
#Base:Edit=	16.12.2021 16:03:50
#Base:Edit=	16.12.2021 16:03:51
#Base:Edit=	16.12.2021 16:03:53
#Base:Edit=	16.12.2021 16:03:53
#Base:Edit=	16.12.2021 16:03:54
#Base:Edit=	16.12.2021 16:03:55
#Base:Edit=	16.12.2021 16:03:55
#Base:Edit=	16.12.2021 16:03:56
#Peaks:Remove=	16.12.2021 16:03:57
#Base:Sub=	16.12.2021 16:04:00
102.198	-12.668
102.842	-5.28122
103.486	6.3632
104.128	3.67387
104.772	3.86024
105.415	1.23451
106.057	8.52579
106.701	5.92282
107.344	-13.824
107.986	7.69055
108.629	0.58432
109.271	9.18886
109.914	9.30278
110.558	-3.33006
111.199	-3.11771
111.843	-2.94229
112.484	9.95575
113.127	-6.95848
113.768	-11.1148
114.411	18.6425
115.052	1.68053
115.695	-1.07742
116.336	7.41844
116.979	-6.6384
117.62	8.84154
118.263	-9.38705
118.904	3.33043
119.547	2.03096
120.187	14.7687
120.83	7.95871
121.471	-4.45102
122.113	-4.26997
122.754	11.3054
123.397	5.84123
124.037	1.77592
124.677	0.567749
125.32	20.2946
125.96	7.82968
126.602	-7.45633
127.243	9.36299
127.883	9.45447
128.525	1.26868
129.165	16.8501
129.805	5.95558
130.447	-2.17494
131.087	2.19101
131.727	6.52434
132.369	1.13565
133.009	5.49472
133.648	11.2819
134.29	8.67957
134.93	0.471588
135.57	2.05083
136.209	0.875229
136.851	12.2128
137.49	15.2156
138.13	1.47627
138.769	15.5245
139.411	14.3761
140.05	13.3237
140.689	13.7317
141.328	14.0631
141.968	12.9803
142.609	18.6939
143.248	8.98663
143.887	22.9474
144.526	3.56161
145.165	-4.54516
145.804	2.64729
146.445	7.15434
147.084	-13.6048
147.722	1.90758
148.361	-4.92919
149	6.33369
149.638	-6.13638
150.277	-4.65208
150.916	2.41295
151.554	2.53343
152.195	-11.2095
152.833	-4.08418
153.472	-4.00169
154.11	-10.912
154.748	-5.31472
155.387	-12.1839
156.025	-5.08416
156.663	-3.48293
157.301	7.76877
157.939	-11.5508
158.577	-14.2126
159.215	-0.222946
159.853	-2.94305
160.491	-5.6369
161.129	-5.52625
161.767	5.62032
162.404	-5.38188
163.042	0.219635
163.678	-5.27333
164.315	4.43529
164.953	-3.79751
165.591	-5.07917
166.228	-2.21123
166.866	-0.741508
167.503	-10.3454
168.14	2.14522
168.778	-3.32103
169.413	-4.65181
170.05	-7.4751
170.687	-1.94322
171.325	-3.20085
171.962	-3.06541
172.599	-7.01917
173.234	-9.68239
173.871	-10.9923
174.508	-9.54453
175.145	-3.9639
175.781	-2.54026
176.416	-2.46266
177.053	-10.6364
177.69	-3.6281
178.326	4.72032
178.961	-0.816063
179.597	-6.34488
180.234	-3.60606
180.868	3.26379
181.505	-4.99337
182.141	3.34418
182.778	3.5517
183.412	8.03152
184.048	2.57478
184.684	1.15339
185.318	-1.73296
185.955	12.1809
186.591	13.6361
187.225	6.79192
187.861	8.21478
188.495	-5.50592
189.131	2.79987
189.767	5.45939
190.4	16.4606
191.036	16.6683
191.67	7.4054
192.305	19.8582
192.939	3.40152
193.575	14.4661
194.21	3.37852
194.844	8.89077
195.479	13.0172
196.113	12.9977
196.748	4.72534
197.381	8.91303
198.017	18.6201
198.65	11.7603
199.285	15.8963
199.918	9.00024
200.553	17.2371
201.186	17.1792
201.819	21.2522
202.454	30.8231
203.087	25.2064
203.722	20.9603
204.355	16.7873
204.99	7.12862
205.623	30.5523
206.255	20.979
206.89	19.671
207.523	32.1287
208.157	29.3625
208.79	19.6404
209.422	16.7828
210.057	20.8193
210.689	12.4791
211.321	28.9066
211.956	20.6335
212.588	27.4709
213.22	20.5065
213.852	23.1735
214.487	20.3578
215.119	29.8528
215.751	28.3581
216.385	32.3275
217.017	15.8306
217.649	12.9922
218.281	41.5864
218.914	18.2652
219.546	28.272
220.178	26.7378
220.81	21.2225
221.441	32.0879
222.075	40.1823
222.706	34.6177
223.338	33.1715
223.969	30.4378
224.601	33.2118
225.232	49.7017
225.866	42.9167
226.497	37.4632
227.128	27.8139
227.759	29.0659
228.391	27.5881
229.022	30.2443
229.653	43.8249
230.284	35.5675
230.915	36.8996
231.546	38.2563
232.179	36.786
232.81	46.1197
233.44	44.598
234.071	40.422
234.702	47.3067
235.333	36.5359
235.963	32.4663
236.594	35.2492
237.224	36.6797
237.855	43.5593
238.485	39.4289
239.116	32.6055
239.746	28.516
240.377	39.5214
241.005	36.7768
241.635	42.2162
242.265	28.3494
242.896	43.2957
243.526	50.0463
244.156	23.8935
244.786	29.2985
245.416	33.3526
246.046	25.1342
246.676	41.5558
247.306	45.711
247.933	47.0198
248.563	35.934
249.193	46.7206
249.823	35.6422
250.452	38.2928
251.082	25.847
251.709	46.2793
252.339	49.0812
252.968	35.3958
253.598	31.246
254.225	38.0304
254.854	37.9012
255.484	36.3831
256.113	29.4582
256.742	32.1596
257.369	30.8949
257.999	30.9001
258.628	24.0041
259.255	38.942
259.884	33.2628
260.513	24.9206
261.14	23.4538
261.768	31.5237
262.397	30.071
263.026	21.7409
263.653	38.0973
264.281	29.8025
264.908	28.4218
265.537	28.5354
266.165	31.5178
266.792	33.9019
267.42	19.5688
268.047	19.4329
268.675	16.7362
269.303	26.2576
269.93	20.6268
270.558	19.2113
271.184	19.1322
271.812	16.3146
272.438	9.38666
273.067	5.13902
273.693	26.7025
274.321	23.8184
274.949	12.7934
275.575	13.9648
276.2	17.8821
276.828	16.4187
277.454	14.9957
278.082	20.3289
278.707	16.1502
279.335	6.62845
279.961	24.2104
280.588	20.0973
281.214	10.5388
281.841	10.4365
282.467	11.6671
283.092	7.49725
283.719	14.1638
284.345	16.7624
284.97	19.3761
285.597	8.52408
286.222	19.2827
286.85	3.02097
287.475	4.33026
288.1	5.62363
288.727	6.93529
289.352	10.9882
289.977	13.6925
290.601	6.87019
291.228	17.651
291.853	8.16203
292.478	12.2049
293.105	4.07225
293.729	6.73083
294.354	4.07512
294.978	-6.75143
295.605	14.8788
296.229	-0.138702
296.854	7.89456
297.478	18.6864
298.103	10.5182
298.729	10.4505
299.353	-7.16106
299.978	13.1336
300.602	11.7676
301.226	2.25523
301.85	3.54697
302.476	12.9398
303.1	12.9067
303.724	7.46292
304.348	16.8898
304.972	11.4399
305.596	4.64989
306.219	-2.12677
306.843	1.97443
307.467	14.2343
308.093	10.1907
308.716	14.2216
309.34	7.39635
309.963	19.6627
310.587	-2.11029
311.21	1.93613
311.834	5.95195
312.457	9.99312
313.081	7.24799
313.704	12.6057
314.327	5.69322
314.95	8.26526
315.573	17.7277
316.197	-2.73087
316.82	-6.84385
317.443	10.8432
318.064	2.72131
318.687	9.61949
319.309	9.68936
319.932	6.94115
320.555	-4.02022
321.178	-8.2083
321.801	-2.88589
322.423	5.14938
323.046	-20.8541
323.669	-8.74011
324.289	-7.52233
324.912	5.92462
325.534	-5.07828
326.157	-3.862
326.779	-5.36446
327.401	6.70776
328.022	-0.15332
328.644	-1.62195
329.266	-5.80566
329.888	-1.8969
330.509	-4.74887
331.131	-0.867569
331.753	8.40277
332.375	2.83202
332.995	9.47849
333.617	10.8065
334.238	4.06641
334.86	-1.30521
335.48	-10.7202
336.102	2.608
336.724	-4.48457
337.343	1.74493
337.965	0.0983582
338.587	12.1643
339.206	9.50314
339.828	4.08867
340.449	-1.32356
341.068	1.27483
341.69	-0.239319
342.309	10.3344
342.93	-8.48859
343.552	3.45297
344.171	3.3907
344.792	1.9397
345.411	-0.907272
346.032	-5.09789
346.653	8.02475
347.272	6.46481
347.893	7.60448
348.512	-5.86069
349.133	1.96663
349.752	0.55188
350.373	-3.49153
350.991	4.36612
351.612	5.55258
352.231	14.6808
352.851	7.93694
353.47	-2.7608
354.088	-4.1806
354.709	3.75478
355.327	-8.13976
355.948	3.73267
356.566	-1.61522
357.186	8.90654
357.805	8.882
358.423	7.5302
359.043	11.4352
359.661	-0.569504
360.281	4.64893
360.899	7.27177
361.517	1.98518
362.137	8.57315
362.755	5.90732
363.373	5.89726
363.993	3.20204
364.611	3.03162
365.229	15.9881
365.846	0.141312
366.466	8.12428
367.084	-2.41969
367.701	-2.43962
368.321	10.8841
368.938	21.4291
369.556	4.11475
370.173	5.38629
370.793	1.37616
371.41	-7.87437
372.027	18.7012
372.645	18.7843
373.262	16.0994
373.881	18.6482
374.498	11.8049
375.115	11.9
375.732	9.98285
376.349	9.81978
376.966	5.59642
377.583	22.5957
378.202	17.5404
378.819	8.13683
379.436	25.2931
380.053	10.6271
380.669	2.64508
381.286	15.9576
381.903	15.9101
382.519	10.5978
383.136	18.6227
383.752	15.9528
384.369	21.27
384.985	-0.0744781
385.602	18.5669
386.218	22.553
386.834	13.1257
387.45	18.4432
388.067	21.1185
388.683	37.1513
389.299	26.4982
389.915	26.5146
390.531	31.8347
391.147	33.064
391.763	19.6338
392.379	35.5808
392.995	31.5874
393.611	27.5859
394.227	27.5998
394.842	26.2293
395.458	38.1568
396.072	27.3574
396.687	37.9676
397.303	44.5819
397.918	39.1275
398.534	45.689
399.149	34.8619
399.765	28.0445
400.378	53.2243
400.994	57.0589
401.609	52.8764
402.224	60.7107
402.839	55.2311
403.453	47.1621
404.068	43.0543
404.683	66.9211
405.298	54.9481
405.911	66.9205
406.526	66.8794
407.141	72.1201
407.754	73.2979
408.368	63.7725
408.983	70.1536
409.598	71.2392
410.211	71.0007
410.825	86.6542
411.44	87.8181
412.053	89.096
412.667	79.7518
413.282	86.253
413.894	83.5003
414.509	85.9831
415.121	87.1778
415.735	89.5904
416.35	102.51
416.962	90.4509
417.576	95.5967
418.188	91.4454
418.802	109.529
419.414	107.938
420.029	101.033
420.643	125.493
421.254	91.2202
421.868	97.6246
422.48	105.52
423.094	116.137
423.706	105.721
424.32	106.955
424.931	125.055
425.545	118.248
426.157	130.934
426.768	120.113
427.382	109.454
427.993	130.114
428.607	119.517
429.218	140.183
429.832	125.796
430.443	129.576
431.054	129.459
431.668	126.627
432.279	132.904
432.89	123.699
433.503	133.978
434.114	118.259
434.727	120.748
435.338	124.609
435.949	119.357
436.56	136.098
437.173	132.069
437.784	126.763
438.395	135.76
439.008	140.889
439.618	147.2
440.229	125.02
440.84	133.939
441.452	122.194
442.063	129.841
442.673	106.552
443.284	138.828
443.896	118.252
444.507	136.432
445.117	122.187
445.727	113.136
446.338	111.81
446.95	119.491
447.56	120.653
448.17	102.439
448.78	121.768
449.39	112.555
450	93.0956
450.61	99.4546
451.22	98.3561
451.832	100.18
452.442	104.381
453.052	78.2383
453.662	88.0041
454.272	100.885
454.881	90.5344
455.491	89.2103
456.101	68.5374
456.71	85.3647
457.32	75.1308
457.929	76.5474
458.539	68.9463
459.148	67.8245
459.757	67.9225
460.367	69.2426
460.976	56.0953
461.585	59.7812
462.194	58.3907
462.804	63.6127
463.413	45.506
464.022	63.7279
464.631	45.6761
465.24	58.6373
465.847	35.2966
466.456	61.309
467.065	30.3957
467.674	51.2717
468.282	42.1994
468.891	39.332
469.5	44.4054
470.108	50.8544
470.715	28.7838
471.324	42.9868
471.932	35.2039
472.541	39.0956
473.149	23.6573
473.756	32.8688
474.364	31.6651
474.972	32.9941
475.581	42.0221
476.187	22.4748
476.795	26.2466
477.403	18.3661
478.012	18.2283
478.618	22.0169
479.226	22.0089
479.834	20.7207
480.44	28.4543
481.048	19.4007
481.656	13.0027
482.261	20.7921
482.869	20.6577
483.477	9.02789
484.083	24.5424
484.691	12.9102
485.298	15.4448
485.904	7.61978
486.511	19.047
487.119	0.89003
487.724	20.1019
488.332	-8.34851
488.937	12.0798
489.545	13.1983
490.15	0.291916
490.757	16.9105
491.363	20.7322
491.97	11.8279
492.575	8.06693
493.182	1.77553
493.787	10.8256
494.394	5.6196
494.999	14.4715
495.606	2.80057
496.211	0.126419
496.818	6.36716
497.423	-2.73257
498.03	13.6754
498.634	0.83577
499.241	-0.330429
499.846	1.21402
500.451	-6.89607
501.057	0.887497
501.662	2.01117
502.268	-7.05753
502.873	-7.14514
503.477	12.0181
504.084	6.03816
504.688	-5.44197
505.292	-5.42543
505.899	-6.67989
506.503	-1.66415
507.107	-5.49005
507.713	-11.8856
508.317	4.56747
508.921	9.61092
509.525	-3.07634
510.131	-8.11923
510.735	2.04713
511.339	4.59315
511.943	5.83008
512.549	-3.06396
513.153	-8.15082
513.757	-9.45509
514.36	0.655396
514.966	-6.86641
515.57	-0.450562
516.173	-2.82635
516.777	12.4369
517.38	9.95117
517.984	12.5004
518.589	2.24025
519.193	2.2711
519.796	-11.5304
520.399	-2.53607
521.003	0.155792
521.606	-2.21991
522.209	-0.894867
522.812	-2.22906
523.415	1.52927
524.018	5.29268
524.621	-1.11191
525.224	9.02881
525.829	2.88303
526.432	10.6708
527.035	2.00551
527.638	12.2476
528.241	-4.16884
528.844	10.9513
529.446	-4.19818
530.049	-1.6517
530.652	12.3203
531.252	4.93137
531.855	-5.05843
532.457	2.66246
533.06	-0.996094
533.662	-3.44617
534.264	-2.15289
534.867	13.0835
535.469	-18.5115
536.071	1.81737
536.674	-3.14053
537.276	7.12654
537.876	11.0811
538.478	-0.152313
539.08	0.0872498
539.682	4.03682
540.284	0.29895
540.886	5.40991
541.486	-4.69194
542.088	0.409485
542.69	-3.32715
543.292	4.38463
543.893	3.22456
544.493	3.3391
545.095	9.83774
545.696	6.15718
546.298	6.20683
546.898	3.69484
547.499	5.06465
548.101	12.8139
548.7	0.351288
549.301	9.40973
549.903	4.45943
550.502	18.5475
551.103	7.15622
551.705	0.817841
552.304	8.47571
552.905	4.75682
553.506	4.83765
554.105	12.5232
554.706	6.18312
555.307	15.295
555.906	8.97485
556.507	16.6627
557.106	2.81042
557.707	13.0589
558.305	28.3803
558.906	24.6178
559.507	19.6051
560.106	20.9685
560.706	17.2539
561.305	31.2842
561.906	22.5018
562.504	18.814
563.104	36.7257
563.703	31.8249
564.303	36.9781
564.902	31.9405
565.5	29.4896
566.1	34.6325
566.699	37.2684
567.299	30.9834
567.897	36.1475
568.497	39.9769
569.095	41.0024
569.693	27.4875
570.293	45.9002
570.891	30.2229
571.491	40.0034
572.089	51.6044
572.687	43.4659
573.287	44.1754
573.884	51.9492
574.482	58.9011
575.082	63.1245
575.679	65.5173
576.277	60.3422
576.875	62.3104
577.474	57.0221
578.072	66.6568
578.669	74.2498
579.266	71.0909
579.866	61.7036
580.463	78.638
581.06	72.9479
581.658	72.1936
582.257	74.987
582.854	79.4107
583.451	74.233
584.048	73.6677
584.645	74.4147
585.242	89.0927
585.841	89.9374
586.438	88.6205
587.035	91.7724
587.632	96.2417
588.229	98.6463
588.826	99.7222
589.422	102.875
590.019	104.869
590.616	91.3944
591.214	107.509
591.811	116.553
592.408	104.422
593.004	121.662
593.601	116.178
594.197	124.943
594.793	124.783
595.39	135.764
595.986	130.802
596.582	133.132
597.179	134.586
597.492	134.035
598.094	155.211
598.698	141.529
599.3	146.04
599.903	151.344
600.507	164.19
601.109	152.018
601.711	169.448
602.315	158.298
602.917	170.596
603.518	159.505
604.12	170.673
604.724	164.616
605.326	162.397
605.928	173.708
606.529	162.823
607.133	177.805
607.734	166.9
608.336	199.21
608.938	190.625
609.541	177.055
610.143	185.691
610.744	186.944
611.345	200.533
611.947	199.4
612.548	198.357
613.151	194.933
613.752	207.41
614.353	195.229
614.955	202.757
615.556	189.399
616.157	199.482
616.758	213.299
617.359	191.315
617.962	196.705
618.563	200.801
619.163	206.192
619.764	186.856
620.365	192.102
620.966	211.992
621.566	176.298
622.167	213.392
622.768	182.639
623.368	185.29
623.969	186.733
624.569	194.422
625.17	180.007
625.77	194.032
626.37	162.095
626.971	178.319
627.571	158.755
628.171	181.499
628.771	177.855
629.372	173.184
629.972	163.599
630.57	161.43
631.17	172.869
631.77	160.605
632.37	137.19
632.97	142.407
633.57	147.636
634.169	152.81
634.769	145.517
635.369	143.211
635.967	155.801
636.566	147.276
637.166	143.709
637.766	117.906
638.365	121.92
638.963	129.577
639.562	124.744
640.162	124.896
640.761	117.633
641.361	122.869
641.958	120.698
642.557	122.272
643.156	106.499
643.756	103.116
644.353	110.864
644.952	107.271
645.551	111.079
646.148	104.976
646.747	90.2346
647.346	94.1414
647.945	95.5659
648.542	100.735
649.141	94.7011
649.74	92.3493
650.336	80.0678
650.935	93.8561
651.532	95.2466
652.13	84.2259
652.729	81.9258
653.326	82.1368
653.924	66.2325
654.523	86.3457
655.119	95.2411
655.718	76.7831
656.314	69.5064
656.912	78.3613
657.509	80.9462
658.107	84.7222
658.703	78.6556
659.301	70.1672
659.897	52.9604
660.496	67.9648
661.092	63.1929
661.69	65.9297
662.286	59.9141
662.884	68.6162
663.479	64.9289
664.077	45.2352
664.673	66.5285
665.271	46.905
665.867	54.4457
666.464	57.0398
667.06	41.1151
667.656	54.8034
668.253	38.8915
668.849	56.2461
669.446	50.169
670.042	50.2683
670.637	61.4624
671.235	45.6049
671.83	47.0258
672.425	54.5588
673.023	53.4577
673.618	49.8796
674.213	51.1728
674.81	46.352
675.405	47.7021
676.001	44.1665
676.598	44.3242
677.193	42.0192
677.788	43.3782
678.383	36.1783
678.979	52.0945
679.574	35.0827
680.169	37.6719
680.764	40.2402
681.361	35.5791
681.955	39.1583
682.55	33.1485
683.145	36.9315
683.739	29.8119
684.336	26.3722
684.93	32.6778
685.525	40.2044
686.119	29.4682
686.713	40.5698
687.308	26.1529
687.904	20.2216
688.498	24.0138
689.093	30.2332
689.687	24.3021
690.281	31.7427
690.875	16.1433
691.469	15.0633
692.063	28.4724
692.657	25.0157
693.251	16.6813
693.845	20.5648
694.439	27.0592
695.033	23.561
695.626	24.8943
696.22	25.0155
696.814	20.2835
697.408	16.7818
698.001	27.7374
698.595	20.559
699.188	23.0787
699.782	30.4798
700.375	21.0832
700.969	20.1146
701.562	24.01
702.156	14.5888
702.749	28.069
703.342	23.424
703.936	27.2248
704.529	16.5095
705.122	20.2412
705.715	13.1189
706.306	24.1728
706.899	16.0008
707.492	17.4778
708.085	15.373
708.678	11.9503
709.271	12.1507
709.864	15.9742
710.455	16.1726
711.048	13.9438
711.64	16.5387
712.233	9.44157
712.824	12.025
713.416	8.59402
714.009	20.8855
714.601	4.10603
715.194	12.7311
715.784	5.60379
716.377	9.39771
716.969	21.6907
717.56	14.7265
718.152	10.1321
718.744	15.2687
719.336	16.7755
719.927	15.8349
720.519	6.3452
721.111	15.0704
721.701	9.20576
722.293	6.98021
722.883	3.53127
723.475	2.49017
724.067	1.41811
724.657	10.0683
725.249	7.77681
725.841	5.51672
726.43	8.18003
727.022	1.17282
727.612	-1.0089
728.203	4.14212
728.793	1.91703
729.385	6.97839
729.976	7.14478
730.566	4.83711
731.157	6.18846
731.747	2.66467
732.338	8.89803
732.927	6.6654
733.519	9.31384
734.108	5.87171
734.699	4.8778
735.288	-3.46661
735.878	1.62609
736.469	-0.610809
737.058	-1.60986
737.649	-0.191605
738.238	7.32577
738.829	1.38455
739.418	2.76334
740.007	9.01735
740.598	4.27452
741.186	-6.59878
741.777	6.97045
742.366	7.13006
742.955	-1.22729
743.545	-3.47855
744.134	2.82195
744.722	0.571693
745.313	5.65497
745.901	0.929428
746.49	-5.01981
747.08	-4.87598
747.669	-4.71725
748.257	-5.76584
748.845	6.58997
749.436	6.71712
750.024	-4.13202
750.612	-2.77641
751.2	-3.85808
751.79	-1.3137
752.379	-4.79929
752.967	-2.15188
753.555	1.73958
754.143	0.742027
754.733	3.35854
755.32	-1.40112
755.908	-2.61242
756.496	-0.145485
757.084	4.81104
757.672	2.61896
758.261	-5.7562
758.849	0.457489
759.437	-4.32949
760.024	0.631104
760.612	1.9948
761.199	-3.89556
761.787	-3.75174
762.374	1.32346
762.962	-4.6137
763.549	2.73433
764.136	2.87989
764.724	1.80836
765.311	-0.480072
765.9	-2.77608
766.487	2.19466
767.074	2.32126
767.661	2.44332
768.249	1.37205
768.836	3.91954
769.421	6.50299
770.008	3.00718
770.594	-2.94331
771.181	-1.6544
771.768	5.66402
772.355	-5.06802
772.942	2.25938
773.528	2.40397
774.115	4.98368
774.702	5.14217
775.288	1.69717
775.875	-0.569603
776.461	-1.60701
777.046	2.03491
777.632	6.56577
778.219	4.38013
778.805	11.7129
779.391	8.33176
779.978	8.45161
780.562	1.42605
781.148	5.1699
781.734	8.87627
782.32	-1.78043
782.907	3.10358
783.491	5.60442
784.077	9.34942
784.663	9.47761
785.249	3.62916
785.833	6.13444
786.418	7.44355
787.004	0.404366
787.588	4.0885
788.174	5.3761
788.76	4.24706
789.345	5.4799
789.929	9.38904
790.515	0.0147858
791.1	3.76029
791.684	3.66226
792.269	8.53444
792.855	9.88136
793.438	7.61252
794.023	8.92432
794.607	6.76188
795.192	9.34048
795.777	9.55116
796.361	11.7553
796.946	7.56721
797.529	12.3534
798.114	14.3067
798.697	13.2778
799.282	13.478
799.865	10.1758
800.45	11.5179
801.033	15.1761
801.618	14.1197
802.201	11.8814
802.786	4.94765
803.369	13.375
803.953	6.44286
804.536	11.3296
805.121	9.14655
805.703	15.1897
806.288	21.2089
806.87	10.691
807.455	7.2721
808.037	19.261
808.62	11.1637
809.204	19.566
809.787	7.88937
810.371	11.5553
810.953	14.0447
811.536	17.7188
812.12	21.3976
812.702	16.8538
813.284	11.1175
813.868	17.2176
814.45	5.55425
815.032	15.1173
815.616	11.6683
816.198	17.665
816.78	18.9452
817.362	10.8077
817.946	16.8404
818.528	11.1572
819.11	19.5753
819.691	17.356
820.275	6.87155
820.857	12.8827
821.438	16.5454
822.02	14.3739
822.603	16.94
823.185	14.7567
823.766	10.177
824.348	13.8601
824.929	18.7314
825.511	16.4961
826.094	11.9
826.675	26.2125
827.256	19.2739
827.838	8.8016
828.419	18.413
829	17.4241
829.581	23.5266
830.162	13.0482
830.743	22.6498
831.324	14.5161
831.907	21.7747
832.488	23.103
833.069	18.5285
833.65	18.6895
834.23	17.6885
834.811	16.6901
835.392	19.2114
835.973	20.5247
836.553	23.024
837.134	25.5153
837.714	17.3435
838.295	17.4816
838.875	11.7115
839.456	21.3396
840.034	15.5843
840.615	18.1066
841.195	24.1447
841.775	19.5201
842.356	29.0999
842.936	20.9409
843.516	17.5419
844.096	11.7991
844.676	16.7
845.256	13.2943
845.835	14.6037
846.415	15.9207
846.995	20.8295
847.574	16.292
848.154	18.8531
848.732	17.8247
849.312	25.0173
849.892	15.6805
850.472	15.8233
851.051	11.2271
851.629	13.7381
852.209	18.6219
852.788	22.3341
853.368	15.3472
853.945	19.0069
854.525	14.3775
855.104	15.72
855.684	17.0583
856.261	10.0861
856.841	7.85775
857.42	20.9758
857.997	18.7006
858.576	8.19645
859.156	4.79112
859.733	6.10083
860.312	15.6551
860.889	11.0468
861.468	15.9413
862.047	7.82455
862.624	11.4915
863.203	10.4212
863.78	10.4899
864.359	11.8051
864.938	10.7572
865.514	12.0809
866.093	2.79969
866.67	1.78078
867.248	1.902
867.825	-0.349773
868.404	9.19715
868.98	6.95991
869.559	5.91395
870.135	14.2971
870.714	-4.42444
871.29	1.59451
871.869	8.7915
872.445	-0.50058
873.023	-0.38203
873.6	0.918781
874.176	1.04605
874.754	2.36076
875.33	4.83771
875.908	0.24913
876.484	1.53831
877.06	-6.56424
877.638	4.12288
878.214	-2.81155
878.792	3.17833
879.368	2.12966
879.944	2.26041
880.522	1.21254
881.098	-0.9837
881.674	2.6897
882.251	0.487904
882.827	-2.90895
883.403	4.24233
883.978	-0.362652
884.556	-2.6208
885.131	3.30597
885.707	-5.97955
886.282	-3.56341
886.86	-2.28717
887.435	3.72503
888.011	-0.785378
888.586	0.51844
889.163	0.640491
889.738	1.94888
890.314	-0.268818
890.889	4.52284
891.464	5.79234
892.039	-2.28477
892.616	-5.68464
893.191	-3.25808
893.766	-2.01583
894.341	-0.76786
894.916	0.496155
895.491	-1.72355
896.066	-1.60345
896.641	-1.46507
897.215	-0.142044
897.79	3.5096
898.367	-2.19053
898.941	-0.920547
899.516	-2.00092
900.091	-3.08353
900.665	-1.83367
901.24	-2.89093
901.814	-1.60818
902.389	-3.80507
902.963	-0.172432
903.537	-5.868
904.112	-4.58495
904.686	3.64101
905.26	2.52536
905.833	-4.36876
906.407	-3.12537
906.981	-4.17782
907.555	-1.71126
908.129	-0.401134
908.703	-2.59461
909.277	-2.48858
909.851	-3.5632
910.425	1.16025
910.999	-1.09707
911.571	-5.66953
912.145	-4.42667
912.718	0.293972
913.292	-4.24421
913.866	-3.00009
914.44	-1.75436
915.011	-2.81645
915.585	-1.5642
916.158	-1.45385
916.732	2.11723
917.303	2.21611
917.877	-3.4689
918.45	-3.38907
919.024	1.31523
919.595	-2.06777
920.168	1.465
920.742	0.392536
921.315	-0.663212
921.886	-4.03876
922.459	-3.95939
923.032	-2.72832
923.604	-2.65206
924.177	0.883095
924.75	-1.3379
925.321	-3.5648
925.894	-4.63749
926.466	-2.26088
927.037	-1.05188
927.61	3.60438
928.181	-5.53379
928.754	-2.01992
929.326	-3.08887
929.897	-1.844
930.47	-1.76865
931.041	-2.85085
931.613	1.80885
932.184	-5.03011
932.756	1.92211
933.327	-1.46531
933.899	0.889965
934.47	2.09688
935.042	-0.146767
935.612	-2.39347
936.185	-2.34692
936.755	-3.43464
937.327	-2.2222
937.897	3.58286
938.469	-0.910835
939.04	2.59096
939.612	0.314507
940.182	-4.20594
940.752	-1.85519
941.324	3.87723
941.894	2.70497
942.466	-1.76707
943.035	-4.04758
943.605	1.75418
944.177	-0.448227
944.747	-3.82887
945.317	-0.370975
945.888	-1.48608
946.458	-0.313152
947.028	0.867428
947.599	-3.64124
948.169	-3.58673
948.738	-5.82234
949.308	1.06581
949.879	-3.4618
950.448	2.25967
951.018	1.14249
951.587	-2.25188
952.158	-3.36414
952.728	0.0834694
953.297	-4.43027
953.866	-4.39186
954.435	-2.07935
955.006	0.241802
955.576	1.41746
956.145	3.72017
956.714	0.32962
957.283	-1.92606
957.852	-1.90488
958.42	-1.88981
958.991	-1.86771
959.56	1.56808
960.129	-2.94306
960.698	-0.654556
961.266	-1.7948
961.835	-0.644623
962.404	0.516697
962.972	-0.583977
963.541	-1.67471
964.109	-2.78941
964.678	-3.96103
965.246	0.551743
965.815	-1.68275
966.383	-1.47601
966.952	-2.66754
967.52	0.78405
968.088	-2.66879
968.657	2.9565
969.225	0.705303
969.793	-0.40731
970.361	1.87116
970.929	1.89663
971.497	-1.47622
972.065	0.80024
972.633	-2.57607
973.201	-3.69127
973.769	-2.55217
974.335	-0.272591
974.903	2.02813
975.471	-2.46617
976.039	0.938934
976.606	-1.30357
977.174	-8.05694
977.742	-1.27638
978.307	-4.64731
978.875	2.13956
979.443	-2.34753
980.01	-2.3222
980.576	-2.29217
981.143	0.00799179
981.711	-3.34538
982.278	-1.06312
982.845	-2.18096
983.411	-2.18479
983.978	-5.54554
984.545	-1.03027
985.111	1.21976
985.678	-3.26143
986.245	-2.11279
986.81	2.41812
987.377	2.43943
987.944	-4.27008
988.509	-3.11791
989.076	-4.20946
989.643	-0.805901
990.208	1.47884
990.775	1.5344
991.342	-6.25162
991.907	-1.6868
992.473	-1.63646
993.038	-0.469887
993.605	0.702705
994.169	-0.385418
994.736	0.776154
995.303	-5.86527
995.867	-4.64602
996.434	-2.28476
996.998	1.18932
997.565	1.26509
998.129	1.27066
998.695	-3.20392
999.26	-1.98401
999.826	-2.92889