File: Data/3-Raman/processed/bu19w-e-ff11b-fi08-v_150 (500nm)_532nm_edge_100%_x100_vis_h50um_30sx2_01_0.txt
#Acq. time (s)=	30
#Accumulations=	2
#Range (cm-¹)=	100...5000
#Windows=	1
#Auto scanning=	Off
#Autofocus=	Off
#Macrospot=	Off
#AutoExposure=	Off
#Spike filter=	Multiple accum.
#Delay time (s)=	2
#Binning=	1
#Readout mode=	Signal
#DeNoise=	Off
#ICS correction=	On
#Dark correction=	Off
#Inst. Process=	Off
#Detector Gain=	Best Dynamic
#Detector ADC=	50 kHz HS
#Detector temperature (°C)=	-60.28
#Instrument=	LabRAM HR Evol
#Detector=	SIN-EM FIVIS
#Objective=	x100_VIS
#Grating=	150 (500nm)
#ND Filter=	100%
#Laser=	532nm_Edge
#Hole=	49.98
#Temperature=	0
#Range=	Visible
#StageXY=	75x50mm Scan+
#StageZ=	Z motor
#X (µm)=	0
#Y (µm)=	0
#Z (µm)=	-249
#Full time(mm:ss)=	1:05
#Project=	21_11_04
#Sample=	BU19w
#Site=
#Title=	BU19w-E-FF11b-FI08-V_150 (500nm)_532nm_Edge_100%_x100_VIS_H50um_30sX2
#Remark=
#Date=	04.11.2021 17:43
#Acquired=	04.11.2021 17:43:11
#Base:Fit=	16.12.2021 17:39:50
#Base:Edit=	16.12.2021 17:47:59
#Base:Sub=	16.12.2021 17:48:03
101.869	7243.79
106.493	6563.27
111.113	6921.73
115.732	8410.59
120.349	8710.78
124.964	6161
129.577	4165.6
134.185	3455.02
138.793	3035.59
143.399	2705.79
148.003	2335.56
152.602	2209.94
157.201	2160.74
161.798	2237.79
166.392	2383.1
170.982	2619.83
175.572	3227.2
180.16	4216.06
184.745	5756.29
189.326	7581.17
193.907	9118.37
198.486	9115.12
203.06	7901.33
207.634	5946.56
212.206	4226.56
216.776	3087.32
221.341	2268.21
225.906	1729.82
230.469	1374.09
235.028	1104.8
239.586	986.681
244.142	896.079
248.694	1063.62
253.246	1522.66
257.795	1362.42
262.341	721.985
266.886	386.13
271.428	277.519
275.967	189.498
280.505	114.857
285.041	92.4927
289.573	74.04
294.105	52.1261
298.632	40.9108
303.159	16.0767
307.685	1.67535
312.205	27.3143
316.726	-0.00616455
321.242	2.64813
325.758	24.3462
330.272	59.0818
334.782	99.968
339.292	437.743
343.797	1124.9
348.302	1211.64
352.803	554.168
357.304	211.12
361.802	122.685
366.297	111.953
370.791	106.865
375.281	115.528
379.77	185.573
384.256	346.531
388.741	538.841
393.223	662.317
397.704	487.325
402.18	287.797
406.657	229.828
411.13	235.049
415.602	247.555
420.07	331.31
424.538	436.775
429.002	595.747
433.465	935.017
437.925	1694.08
442.384	3503.31
446.839	8253.05
451.294	19057.6
455.745	27056.4
460.196	20094.4
464.642	9880.19
469.089	4778.8
473.531	2892.8
477.971	2023.52
482.411	1487.73
486.846	1151.68
491.282	943.63
495.713	868.233
500.144	785.852
504.572	751.72
508.997	620.714
513.421	511.677
517.842	447.782
522.263	371.451
526.679	321.958
531.093	296.85
535.507	284.625
539.917	241.132
544.327	221.874
548.733	175.923
553.137	158.849
557.54	148.353
561.94	144.538
566.337	117.874
570.734	137.9
575.127	111.331
579.518	107.551
583.909	118.426
588.295	112.691
592.68	97.5535
597.064	80.3611
601.445	77.8679
605.823	69.1091
610.201	51.5307
614.575	78.9955
618.947	40.4126
623.317	49.2043
627.686	40.9489
632.052	41.3
636.415	56.1912
640.777	51.9309
645.138	24.6771
649.495	49.8112
653.85	38.1166
658.205	26.5318
662.556	34.6498
666.905	41.4279
671.252	48.1006
675.597	52.3117
679.941	109.33
684.282	178.212
688.62	262.186
692.957	179.535
697.293	96.021
701.625	42.8777
705.955	28.0042
710.283	23.0305
714.609	-2.28134
718.933	0.0336609
723.257	3.1069
727.577	1.7002
731.894	-1.15192
736.21	7.86932
740.524	-0.929077
744.835	9.87793
749.147	10.7304
753.454	15.5641
757.759	24.6933
762.063	23.7704
766.364	32.5099
770.663	51.1245
774.96	82.1371
779.257	127.945
783.55	225.73
787.841	329.251
792.13	446.096
796.417	669.955
800.702	757.23
804.985	476.923
809.266	246.64
813.545	126.444
817.821	108.625
822.096	79.7817
826.371	77.4975
830.641	57.6442
834.91	70.8523
839.176	67.5036
843.441	29.9037
847.703	68.2819
851.964	39.0581
856.222	53.9695
860.479	87.5965
864.733	123.311
868.986	174.185
873.236	120.478
877.485	79.9507
881.731	40.5615
885.975	41.5735
890.218	28.1855
894.458	11.3965
898.696	21.3685
902.933	28.0614
907.167	33.1185
911.399	50.5441
915.63	31.4724
919.858	-1.68005
924.084	21.2284
928.308	15.7678
932.531	-0.943604
936.749	-11.2028
940.967	-19.3971
945.184	-17.9808
949.398	-20.8606
953.61	-16.1637
957.821	-38.0489
962.029	-39.6308
966.236	-30.5498
970.44	-38.4232
974.642	-39.8498
978.843	-34.882
983.041	-36.2062
987.236	-61.8825
991.43	-42.0285
995.623	-41.0114
999.813	-36.6125
1004	-22.596
1008.19	-32.9428
1012.37	-34.7955
1016.55	-36.7545
1020.73	-33.4008
1024.91	-46.1177
1029.09	-19.4702
1033.27	-35.6183
1037.44	-24.3181
1041.61	-16.4586
1045.78	-2.24243
1049.94	29.872
1054.11	54.3578
1058.27	123.047
1062.43	148.008
1066.59	231.586
1070.75	411.078
1074.9	446.145
1079.05	247.58
1083.2	94.7937
1087.35	26.9195
1091.5	14.2342
1095.65	7.90237
1099.79	-3.40143
1103.93	-2.33853
1108.07	-7.31369
1112.21	-3.94531
1116.34	-15.8526
1120.48	-4.94531
1124.61	-24.3268
1128.74	-16.0991
1132.86	17.8334
1136.99	22.0442
1141.11	77.5645
1145.23	184.782
1149.35	305.6
1153.47	384.057
1157.59	246.643
1161.7	117.26
1165.82	41.373
1169.92	15.9804
1174.03	18.3347
1178.14	12.3742
1182.24	0.224823
1186.35	18.8566
1190.45	22.8809
1194.55	22.6961
1198.64	27.515
1202.74	31.1991
1206.83	60.2205
1210.92	75.9132
1215.01	99.612
1219.1	121.19
1223.18	156.779
1227.27	176.224
1231.35	185.735
1235.43	166.513
1239.5	239.545
1243.58	267.413
1247.65	417.193
1251.72	754.019
1255.8	788.619
1259.86	603.534
1263.93	586.341
1267.99	1553.4
1272.06	5880.41
1276.12	5821.2
1280.18	1941.47
1284.23	615.401
1288.29	401.777
1292.34	333.768
1296.39	298.809
1300.44	286.935
1304.49	264.859
1308.53	268.922
1312.58	245.71
1316.62	224.334
1320.66	234.072
1324.7	263.754
1328.73	256.067
1332.77	250.37
1336.8	246.512
1340.83	284.593
1344.86	297.499
1348.88	319.299
1352.91	393.763
1356.93	528.569
1360.95	632.088
1364.97	668.031
1368.99	1026.23
1373.01	4005.47
1377.02	11660
1381.03	7777.99
1385.04	2084.63
1389.05	752.889
1393.06	690.51
1397.06	1085.36
1401.06	1107.14
1405.06	569.17
1409.06	304.919
1413.06	237.703
1417.05	231.589
1421.05	195.83
1425.04	157.013
1429.03	132.809
1433.01	94.7711
1437	107.091
1440.99	80.8844
1444.97	92.1472
1448.95	64.8769
1452.93	68.1523
1456.9	58.5607
1460.88	48.926
1464.85	42.1675
1468.82	41.2859
1472.79	51.23
1476.76	41.4943
1480.73	32.7124
1484.69	41.5395
1488.65	24.9044
1492.61	26.8593
1496.57	50.2504
1500.53	36.5982
1504.48	34.6776
1508.43	33.7841
1512.39	35.8182
1516.33	56.2932
1520.28	38.9218
1524.23	50.6692
1528.17	39.1451
1532.11	46.0643
1536.05	30.6866
1539.99	52.1353
1543.93	57.0971
1547.86	53.328
1551.8	64.0811
1555.73	58.3266
1559.66	67.0482
1563.58	76.6891
1567.51	65.9733
1571.44	88.0994
1575.36	69.6183
1579.28	82.0256
1583.2	83.7897
1587.11	88.4128
1591.03	99.7481
1594.94	111.05
1598.85	117.519
1602.76	123.992
1606.67	121.86
1610.58	127.408
1614.48	130.087
1618.38	132.8
1622.29	134.534
1626.18	153.531
1630.08	149.593
1633.98	123.738
1637.87	144.776
1641.76	131.417
1645.65	111.409
1649.54	150.846
1653.43	134.702
1657.31	138.667
1661.2	112.833
1665.08	114.784
1668.96	112.846
1672.83	87.7394
1676.71	94.3244
1680.58	76.7404
1684.46	63.8923
1688.33	70.2184
1692.2	51.5691
1696.06	42.4879
1699.93	51.5363
1703.79	49.0555
1707.66	40.8145
1711.52	34.4503
1715.37	41.3748
1719.23	35.0349
1723.08	19.2837
1726.94	35.6031
1730.79	21.7346
1734.64	34.1944
1738.49	22.2467
1742.33	31.7899
1746.18	16.1513
1750.02	14.6402
1753.86	24.3565
1757.7	27.6798
1761.54	11.8713
1765.37	15.4401
1769.21	16.2707
1773.04	7.91788
1776.87	8.86797
1780.7	9.8838
1784.53	12.8098
1788.35	9.22386
1792.17	9.38316
1796	9.54794
1799.82	8.76469
1803.64	4.089
1807.45	8.79095
1811.27	-0.659317
1815.08	4.93166
1818.89	14.2144
1822.7	11.1712
1826.51	2.42719
1830.32	4.94832
1834.12	0.814804
1837.92	7.94849
1841.72	6.57098
1845.52	13.6004
1849.32	9.37567
1853.12	5.0742
1856.91	2.59584
1860.7	8.45801
1864.5	-2.48665
1868.28	-1.29167
1872.07	8.26062
1875.86	7.64487
1879.64	-1.25726
1883.42	9.31062
1887.21	-0.385101
1890.98	4.88142
1894.76	1.89671
1898.54	-0.168259
1902.31	7.97629
1906.08	-1.3157
1909.85	11.5163
1913.62	5.08403
1917.39	5.12456
1921.16	1.59827
1924.92	1.80014
1928.68	2.96825
1932.44	-1.41248
1936.2	10.9583
1939.96	2.83691
1943.71	4.96965
1947.47	8.05988
1951.22	19.429
1954.97	11.9497
1958.72	8.10811
1962.46	5.12582
1966.21	9.64639
1969.95	2.84227
1973.7	5.34196
1977.43	2.17476
1981.17	18.6298
1984.91	17.2515
1988.65	14.9172
1992.38	11.6289
1996.11	2.72913
1999.84	9.60059
2003.57	11.8201
2007.3	11.2482
2011.02	16.1524
2014.75	8.1656
2018.47	15.9191
2022.19	20.1151
2025.91	20.7778
2029.62	22.3941
2033.34	22.264
2037.05	23.1673
2040.76	18.5504
2044.47	9.34738
2048.18	14.7949
2051.89	12.0526
2055.59	13.9107
2059.3	13.1276
2063	15.2538
2066.7	12.8543
2070.4	26.1326
2074.1	7.16518
2077.79	17.7351
2081.49	8.91374
2085.18	25.0974
2088.87	8.56166
2092.56	5.80649
2096.25	22.6819
2099.93	6.07758
2103.61	16.3568
2107.3	16.3705
2110.98	2.40332
2114.66	30.2723
2118.33	16.2825
2122.01	30.0841
2125.68	22.4667
2129.36	13.9098
2133.03	21.086
2136.7	13.4454
2140.36	20.561
2144.03	25.7783
2147.7	4.28682
2151.36	18.6854
2155.02	22.9628
2158.68	17.1723
2162.34	3.20531
2165.99	17.6127
2169.65	8.32622
2173.3	5.52634
2176.95	4.61391
2180.6	9.19418
2184.25	3.76549
2187.9	14.7627
2191.54	13.1222
2195.18	9.75558
2198.83	-0.843094
2202.47	14.0999
2206.11	-1.92586
2209.74	5.81691
2213.38	4.46207
2217.01	17.7901
2220.64	2.70229
2224.27	9.65494
2227.9	11.0943
2231.53	-1.29491
2235.16	14.0206
2238.78	9.94878
2242.4	-3.40933
2246.02	12.8965
2249.64	6.94731
2253.26	9.38928
2256.88	15.5965
2260.49	2.19496
2264.11	5.58047
2267.72	19.3156
2271.33	-10.0775
2274.93	10.2804
2278.54	8.00934
2282.15	15.041
2285.75	21.1163
2289.35	0.747818
2292.95	15.3155
2296.55	20.4454
2300.15	15.1787
2303.74	13.6648
2307.34	32.0076
2310.93	44.6394
2314.52	201.321
2318.11	1039.34
2321.7	1150.94
2325.28	332.165
2328.87	66.1864
2332.45	33.0973
2336.03	14.2074
2339.61	19.8272
2343.19	16.9485
2346.77	16.871
2350.34	12.0964
2353.92	12.9424
2357.49	22.1744
2361.06	3.41991
2364.63	20.9883
2368.2	8.81984
2371.76	24.5304
2375.33	19.8438
2378.89	9.6398
2382.45	-0.499725
2386.01	9.65582
2389.57	3.28268
2393.13	6.1467
2396.68	-1.9348
2400.23	3.81131
2403.79	10.5811
2407.34	13.7251
2410.88	7.78128
2414.43	11.0677
2417.98	19.9232
2421.52	5.83545
2425.06	11.1065
2428.61	1.67967
2432.14	2.43228
2435.68	14.3533
2439.22	-0.588577
2442.75	4.90018
2446.29	16.9544
2449.82	7.58495
2453.35	10.4
2456.88	14.0508
2460.4	11.8816
2463.93	16.2724
2467.45	11.0826
2470.98	6.95665
2474.5	8.22047
2478.02	13.178
2481.54	16.2879
2485.05	6.1405
2488.57	14.7069
2492.08	5.49294
2495.59	14.9823
2499.1	5.75615
2502.61	7.73769
2506.12	-3.40163
2509.63	4.10616
2513.13	2.29108
2516.63	6.10239
2520.13	21.0705
2523.63	-0.257935
2527.13	7.33234
2530.63	14.9611
2534.12	16.1426
2537.62	12.7714
2541.11	5.7543
2544.6	3.44141
2548.09	14.1439
2551.58	0.838074
2555.06	8.83125
2558.55	18.8018
2562.03	2.80919
2565.51	11.0209
2568.99	11.87
2572.47	20.2484
2575.95	11.8391
2579.43	16.5759
2582.9	17.5791
2586.37	4.40068
2589.84	13.8616
2593.31	15.6596
2596.78	10.7515
2600.25	3.96822
2603.71	9.58499
2607.18	9.36299
2610.64	19.5458
2614.1	10.376
2617.56	18.5766
2621.02	16.126
2624.47	10.7551
2627.93	19.7423
2631.38	-1.07616
2634.83	26.0656
2638.28	17.6303
2641.73	13.9668
2645.18	24.6146
2648.62	18.9902
2652.07	19.0581
2655.51	13.3676
2658.95	34.2411
2662.39	19.9546
2665.83	22.7226
2669.27	12.277
2672.7	19.7356
2676.14	32.8208
2679.57	26.2144
2683	16.8729
2686.43	22.553
2689.86	16.2224
2693.29	22.0915
2696.71	29.7657
2700.13	28.1686
2703.56	27.5148
2706.98	22.2017
2710.4	25.3999
2713.82	24.9159
2717.23	30.9845
2720.65	22.1876
2724.06	12.4634
2727.47	18.6062
2730.88	32.2535
2734.29	32.8114
2737.7	24.9335
2741.11	32.0389
2744.51	37.2388
2747.91	25.4994
2751.32	27.8477
2754.72	33.9462
2758.11	34.373
2761.51	31.9821
2764.91	29.5322
2768.3	28.935
2771.7	33.0127
2775.09	38.0147
2778.48	38.2679
2781.87	40.373
2785.25	36.8114
2788.64	40.7685
2792.03	32.4922
2795.41	43.0027
2798.79	30.9708
2802.17	32.9905
2805.55	37.819
2808.93	37.014
2812.3	34.3248
2815.68	42.8472
2819.05	27.0576
2822.42	48.655
2825.79	34.8036
2829.16	32.1669
2832.53	40.7359
2835.89	58.6486
2839.26	33.7393
2842.62	40.5373
2845.98	47.3802
2849.34	49.6339
2852.7	51.9454
2856.06	52.3591
2859.41	52.797
2862.77	60.7488
2866.12	50.9146
2869.47	65.4546
2872.82	44.3118
2876.17	46.6227
2879.52	58.3426
2882.87	63.4801
2886.21	62.0041
2889.55	64.2903
2892.89	66.57
2896.23	56.5049
2899.57	70.0406
2902.91	67.4656
2906.25	61.073
2909.58	56.5504
2912.91	68.094
2916.25	69.2128
2919.58	85.4298
2922.91	76.0866
2926.23	81.855
2929.56	76.2402
2932.88	95.1584
2936.21	81.9239
2939.53	86.6213
2942.85	96.0194
2946.17	88.4611
2949.49	94.0903
2952.8	92.1789
2956.12	111.877
2959.43	95.9131
2962.74	105.324
2966.06	121.301
2969.37	114.833
2972.67	109.358
2975.98	132.02
2979.28	135.04
2982.59	140.835
2985.89	141.954
2989.19	141.209
2992.49	146.105
2995.79	148.198
2999.09	148.426
3002.38	176.86
3005.68	138.517
3008.97	171.693
3012.26	164.423
3015.55	191.071
3018.84	178.139
3022.13	197.256
3025.41	204.122
3028.7	208.165
3031.98	216.927
3035.26	225.677
3038.54	238.202
3041.82	232.763
3045.1	235.84
3048.38	255.022
3051.65	252.424
3054.92	262.158
3058.2	285.16
3061.47	277.683
3064.73	299.678
3068	300.747
3071.27	300.796
3074.54	335.47
3077.8	340.305
3081.06	342.089
3084.32	351.909
3087.58	382.581
3090.84	387.793
3094.1	389.304
3097.35	419.517
3100.61	427.305
3103.86	441.608
3107.11	460.975
3110.36	475.524
3113.61	500.33
3116.86	529.961
3120.11	511.053
3123.35	544.523
3126.59	565.608
3129.84	581.909
3133.08	603.945
3136.32	663.14
3139.55	665.104
3142.79	707.096
3146.03	697.607
3149.26	714.872
3152.49	727.392
3155.72	775.165
3158.95	788.635
3162.18	820.199
3165.41	840.328
3168.64	877.544
3171.86	903.229
3175.08	932.686
3178.31	952.497
3181.53	976.096
3184.75	1025.47
3187.96	1047.03
3191.18	1056.15
3194.4	1063.35
3197.61	1100.06
3200.82	1111.95
3204.03	1155.3
3207.24	1173.92
3210.45	1213.53
3213.66	1193.27
3216.86	1206.41
3220.07	1260.45
3223.27	1266.97
3226.48	1311.68
3229.68	1321.22
3232.87	1356.59
3236.07	1336.63
3239.27	1374.13
3242.47	1325.07
3245.66	1425.63
3248.85	1395.69
3252.04	1425.96
3255.23	1470.61
3258.42	1480.93
3261.61	1444.24
3264.8	1477.97
3267.98	1474.23
3271.16	1510.44
3274.35	1490.18
3277.53	1543.47
3280.71	1561.05
3283.89	1573.51
3287.06	1603.19
3290.24	1572.59
3293.41	1631.76
3296.58	1646.99
3299.76	1647.91
3302.93	1674.06
3306.1	1670.2
3309.26	1686.15
3312.43	1741.68
3315.59	1722.95
3318.76	1774.41
3321.92	1749.88
3325.08	1807.79
3328.24	1827.77
3331.4	1814.67
3334.56	1884.86
3337.71	1906.02
3340.87	1938.65
3344.02	1913.73
3347.17	1984.55
3350.33	1998.41
3353.47	2064.06
3356.62	2099.8
3359.77	2122.45
3362.92	2108.64
3366.06	2151.44
3369.2	2169.87
3372.34	2239.35
3375.49	2227.99
3378.62	2302.66
3381.76	2283.06
3384.9	2312.46
3388.04	2361.03
3391.17	2359.52
3394.3	2419.54
3397.43	2414.33
3400.56	2389.8
3403.69	2504.94
3406.82	2479.02
3409.95	2465.57
3413.07	2547.25
3416.2	2546.48
3419.32	2547.42
3422.44	2568.18
3425.56	2593.16
3428.68	2579.47
3431.8	2570.17
3434.91	2573.71
3438.03	2577.49
3441.14	2544.4
3444.25	2586.7
3447.36	2583.53
3450.47	2535.52
3453.58	2509.04
3456.69	2492.08
3459.79	2512.8
3462.9	2459.28
3466	2442.77
3469.11	2392.72
3472.21	2384.86
3475.31	2426.16
3478.4	2398.45
3481.5	2307.53
3484.6	2313.2
3487.69	2236.87
3490.79	2254.4
3493.88	2195.25
3496.97	2152.1
3500.06	2132.36
3503.15	2080.69
3506.23	2024.87
3509.32	1988.94
3512.4	1948.58
3515.49	1837.03
3518.57	1888.14
3521.65	1811.12
3524.73	1760.08
3527.81	1707.96
3530.89	1664.28
3533.96	1596.63
3537.03	1591.34
3540.11	1530.42
3543.18	1530.81
3546.25	1487.3
3549.32	1409.17
3552.39	1382.53
3555.46	1327.31
3558.52	1293.12
3561.59	1293.02
3564.65	1231.97
3567.71	1207.6
3570.77	1161.88
3573.83	1160.99
3576.89	1110.85
3579.95	1049.21
3583	1036.79
3586.06	1016.67
3589.11	997.501
3592.16	957.331
3595.21	908.629
3598.27	875.96
3601.31	858.479
3604.36	836.168
3607.41	806.23
3610.45	808.473
3613.5	768.133
3616.54	727.803
3619.58	715.882
3622.62	663.452
3625.66	644.105
3628.69	638.03
3631.73	609.311
3634.77	575.86
3637.8	556.748
3640.83	533.041
3643.86	492.479
3646.89	481.281
3649.92	436.947
3652.95	411.597
3655.98	373.175
3659	352.036
3662.02	334.575
3665.05	305.702
3668.07	277.504
3671.09	269.198
3674.11	240.152
3677.13	213.931
3680.14	202.817
3683.16	197.339
3686.17	165.383
3689.19	160.841
3692.2	139.261
3695.21	129.033
3698.22	124.416
3701.23	111.325
3704.23	106.76
3707.24	86.0426
3710.24	93.7838
3713.25	83.45
3716.25	77.8313
3719.25	60.8109
3722.25	59.9344
3725.25	65.7061
3728.25	66.6996
3731.24	40.0625
3734.24	53.4035
3737.23	51.4852
3740.22	40.9848
3743.21	34.2739
3746.21	34.2127
3749.19	33.1835
3752.18	33.0923
3755.17	33.9492
3758.15	30.0686
3761.14	37.5694
3764.12	20.4079
3767.1	25.0549
3770.08	24.9804
3773.06	14.5221
3776.04	18.2693
3779.02	22.9706
3781.99	17.2921
3784.97	16.343
3787.94	14.4628
3790.91	14.4828
3793.88	27.7469
3796.85	12.7125
3799.82	6.18323
3802.79	9.11876
3805.76	6.3999
3808.72	10.2993
3811.69	9.48869
3814.65	12.4657
3817.61	7.88385
3820.57	11.8243
3823.53	0.624847
3826.49	7.42766
3829.45	19.9303
3832.4	8.73441
3835.36	-0.558884
3838.31	6.29245
3841.26	16.0075
3844.21	8.61478
3847.16	-0.687408
3850.11	2.38916
3853.06	6.43561
3856	15.2658
3858.95	5.96704
3861.89	18.6445
3864.84	2.62962
3867.78	5.74287
3870.72	7.89029
3873.66	13.874
3876.6	3.54628
3879.53	-1.04968
3882.47	0.0993347
3885.4	-4.53445
3888.34	12.9282
3891.27	5.39529
3894.2	12.2789
3897.13	18.1826
3900.06	7.71873
3902.99	9.75566
3905.91	10.8082
3908.84	-8.30086
3911.76	8.14151
3914.69	9.19029
3917.61	15.9874
3920.53	13.2159
3923.45	0.814758
3926.37	14.3114
3929.28	6.68562
3932.2	4.80917
3935.11	12.5525
3938.03	16.496
3940.94	15.6873
3943.85	4.33029
3946.76	24.5791
3949.67	9.42197
3952.58	20.1302
3955.49	8.82202
3958.39	3.27327
3961.3	2.52136
3964.2	12.3219
3967.1	17.3456
3970	7.99252
3972.9	13.0352
3975.8	12.3184
3978.7	8.70941
3981.6	7.00951
3984.49	2.4232
3987.39	9.36621
3990.28	15.3489
3993.17	-0.813995
3996.06	5.17906
3998.95	9.24791
4001.84	8.51497
4004.73	16.4525
4007.61	19.5882
4010.5	6.34348
4013.38	2.72929
4016.27	2.97304
4019.15	0.322845
4022.03	-3.29507
4024.91	11.4361
4027.79	12.6568
4030.66	11.9461
4033.54	5.43793
4036.42	9.56841
4039.29	-0.809631
4042.16	3.3278
4045.03	11.3178
4047.9	13.5056
4050.77	5.0392
4053.64	3.3643
4056.51	4.61412
4059.38	1.00615
4062.24	4.1899
4065.1	9.32178
4067.97	2.78775
4070.83	14.7329
4073.69	9.16623
4076.55	6.51334
4079.41	-1.98943
4082.26	4.12192
4085.12	14.1407
4087.97	10.5027
4090.83	8.81284
4093.68	12.9907
4096.53	12.2779
4099.38	1.79916
4102.23	6.95171
4105.08	3.30118
4107.93	1.58829
4110.77	1.83191
4113.62	7.93303
4116.46	3.25348
4119.3	1.4901
4122.14	3.64183
4124.98	7.76758
4127.82	8.96295
4130.66	5.30144
4133.5	2.64015
4136.33	-0.963089
4139.17	2.13492
4142	9.98642
4144.83	1.35898
4147.67	-0.34581
4150.5	7.75029
4153.33	1.13135
4156.15	4.25348
4158.98	4.37772
4161.81	2.58783
4164.63	4.73477
4167.45	11.7696
4170.28	-3.68402
4173.1	8.25398
4175.92	-5.23058
4178.74	7.68922
4181.56	-9.69728
4184.37	3.23938
4187.19	2.49109
4190	-2.16765
4192.82	5.91487
4195.63	1.28906
4198.44	7.45552
4201.25	4.80164
4204.06	3.12987
4206.87	-0.512238
4209.68	6.64687
4212.48	2.99896
4215.29	2.2946
4218.1	11.5072
4220.9	5.95715
4223.7	12.2175
4226.5	8.59669
4229.3	3.0127
4232.1	6.32759
4234.9	2.7312
4237.69	8.06071
4240.49	4.46811
4243.28	21.7516
4246.07	1.24927
4248.87	10.5972
4251.66	1.98378
4254.45	9.33652
4257.24	6.68578
4260.03	1.01991
4262.81	0.360641
4265.6	2.71602
4268.38	5.08504
4271.17	-0.595276
4273.95	0.759659
4276.73	-2.95262
4279.51	1.38538
4282.29	6.73018
4285.07	4.98918
4287.84	8.28664
4290.62	13.5955
4293.39	7.76176
4296.17	-2.11356
4298.94	6.25838
4301.71	2.45537
4304.48	4.73384
4307.25	13.1055
4310.02	5.23612
4312.79	0.418587
4315.55	8.79819
4318.32	10.0476
4321.08	0.0906372
4323.85	18.6234
4326.61	-5.61324
4329.37	2.73558
4332.13	4.96153
4334.89	11.2685
4337.65	3.29905
4340.4	6.55877
4343.16	10.8415
4345.91	2.90115
4348.67	4.14787
4351.42	9.47928
4354.17	4.63467
4356.92	-0.228577
4359.67	-4.07817
4362.42	11.505
4365.17	8.68394
4367.91	2.77435
4370.66	-3.13293
4373.4	4.2691
4376.14	2.43445
4378.89	0.586906
4381.63	11.0596
4384.37	7.16057
4387.11	4.31241
4389.84	3.56631
4392.58	-1.28239
4395.32	5.30112
4398.05	4.58513
4400.78	1.78017
4403.52	5.17491
4406.25	2.35506
4408.98	7.84451
4411.71	5.01047
4414.44	3.19151
4417.16	1.36137
4419.89	3.64893
4422.62	16.3895
4425.34	7.23261
4428.06	3.28616
4430.78	-0.667763
4433.51	7.92511
4436.22	10.2401
4438.94	10.455
4441.66	6.46302
4444.38	6.66302
4447.1	4.75615
4449.81	10.1947
4452.52	6.1735
4455.24	5.29753
4457.95	-6.10139
4460.66	6.66601
4463.37	3.68082
4466.08	5.95084
4468.78	9.28061
4471.49	14.7242
4474.2	-2.99302
4476.9	8.79468
4479.6	7.94852
4482.31	8.16344
4485.01	3.09515
4487.71	7.52424
4490.41	13.0115
4493.11	12.1225
4495.8	-3.61604
4498.5	13.4902
4501.19	6.2347
4503.89	4.25984
4506.58	2.29563
4509.27	7.75761
4511.96	13.2236
4514.66	3.83443
4517.34	9.30852
4520.03	6.29048
4522.72	7.53545
4525.41	1.33338
4528.09	6.83051
4530.77	4.88081
4533.46	3.99651
4536.14	11.6486
4538.82	3.30161
4541.5	2.42847
4544.18	1.55083
4546.86	9.2365
4549.53	-2.34256
4552.21	10.7225
4554.88	9.8855
4557.56	15.5093
4560.23	6.12224
4562.9	5.34908
4565.57	12.1693
4568.24	-1.51296
4570.91	8.54652
4573.58	6.55064
4576.24	5.57554
4578.91	-0.771141
4581.58	4.87824
4584.24	-4.67139
4586.9	7.48448
4589.56	6.56445
4592.22	-2.00776
4594.88	12.3407
4597.54	-1.6779
4600.2	8.31943
4602.86	5.22607
4605.51	11.9918
4608.17	0.136559
4610.82	2.52412
4613.47	3.81306
4616.13	0.705933
4618.78	9.6991
4621.43	5.50293
4624.07	7.90729
4626.72	18.0284
4629.37	2.76537
4632.01	12.8888
4634.66	5.31654
4637.3	2.15102
4639.94	1.19476
4642.59	2.45232
4645.23	5.95509
4647.87	9.49551
4650.5	0.851746
4653.14	11.1431
4655.78	8.05753
4658.42	3.69951
4661.05	9.46859
4663.68	6.33627
4666.31	2.06596
4668.95	7.82675
4671.58	0.171623
4674.21	3.70748
4676.84	19.5837
4679.46	4.05725
4682.09	12.0899
4684.72	12.2669
4687.34	6.82067
4689.97	9.24696
4692.59	10.5537
4695.21	5.08766
4697.83	-2.64345
4700.45	5.42019
4703.07	-0.0620804
4705.69	4.60962
4708.3	12.6755
4710.92	4.90697
4713.54	-1.73868
4716.15	11.9877
4718.76	0.798065
4721.37	5.46219
4723.99	-1.21312
4726.59	10.2664
4729.2	14.9578
4731.81	10.5741
4734.42	14.1369
4737.03	4.06382
4739.63	13.2993
4742.23	20.2649
4744.84	-1.21481
4747.44	12.5607
4750.04	-2.12626
4752.64	-2.01751
4755.24	14.0242
4757.84	11.8555
4760.44	14.252
4763.03	12.1046
4765.63	3.12819
4768.22	8.98519
4770.82	8.02116
4773.41	10.4524
4776	4.89853
4778.59	11.9025
4781.18	8.62927
4783.77	13.3551
4786.36	3.22218
4788.94	10.2406
4791.53	12.6921
4794.11	7.13581
4796.7	5.01463
4799.28	13.2226
4801.86	4.23852
4804.44	4.43687
4807.02	1.20119
4809.6	8.32552
4812.18	5.09528
4814.76	1.86504
4817.33	-3.67443
4819.91	2.34135
4822.48	7.21396
4825.06	10.9424
4827.63	4.23543
4830.2	4.48251
4832.77	-5.72708
4835.34	5.00705
4837.91	2.95251
4840.48	5.576
4843.04	12.8866
4845.61	-4.41783
4848.17	14.6037
4850.74	3.08883
4853.3	7.94078
4855.86	5.74651
4858.42	20.1512
4860.98	1.5726
4863.54	6.52872
4866.1	-0.360878
4868.66	5.74767
4871.21	15.4483
4873.77	14.4753
4876.32	12.2998
4878.88	6.56104
4881.43	11.4926
4883.98	9.29447
4886.53	3.52614
4889.08	3.69952
4891.63	1.4933
4894.18	8.80563
4896.72	10.1648
4899.27	10.3285
4901.81	8.10431
4904.36	14.2272
4906.9	13.189
4909.44	3.78333
4911.98	-0.872681
4914.52	2.8216
4917.06	12.4776
4919.6	0.64122
4922.14	7.91788
4924.67	-1.53278
4927.21	4.55553
4929.74	15.4121
4932.28	9.56177
4934.81	0.138733
4937.34	14.6283
4939.87	8.77371
4942.4	12.4457
4944.93	12.5603
4947.46	-0.483673
4949.99	11.6238
4952.51	6.96159
4955.04	7.0789
4957.56	1.20995
4960.08	3.74812
4962.61	11.1049
4965.13	6.46948
4967.65	0.63681
4970.17	-1.62095
4972.69	14.2119
4975.2	3.48977
4977.72	-1.21149
4980.24	9.81184
4982.75	12.3742
4985.27	-3.24447
4987.78	11.4443
4990.29	3.07968
4992.8	10.4975
4995.31	10.6195
4997.82	-1.42879