File: Data/3-Raman/processed/bu19w-b-ff1-fi01-v_1800 (450-850nm)_532nm_edge_100%_x100_vis_h30um_30sx2_01.txt
#Acq. time (s)=	30
#Accumulations=	2
#Range (cm-¹)=	1230...2360
#Windows=	3
#Auto scanning=	Off
#Autofocus=	Off
#Macrospot=	Off
#AutoExposure=	Off
#Spike filter=	Multiple accum.
#Delay time (s)=	2
#Binning=	1
#Readout mode=	Signal
#DeNoise=	Off
#ICS correction=	On
#Dark correction=	Off
#Inst. Process=	Off
#Detector Gain=	Best Dynamic
#Detector ADC=	50 kHz HS
#Detector temperature (°C)=	-60.09
#Instrument=	LabRAM HR Evol
#Detector=	SIN-EM FIVIS
#Objective=	x100_VIS
#Grating=	1800 (450-850nm)
#ND Filter=	100%
#Laser=	532nm_Edge
#Hole=	30.0125
#Temperature=	0
#Range=	Visible
#StageXY=	75x50mm Scan+
#StageZ=	Z motor
#X (µm)=	0
#Y (µm)=	0
#Z (µm)=	-137.6
#Full time(mm:ss)=	3:18
#Project=	21_05_14
#Sample=	BU19w
#Site=
#Title=	BU19w-FF1-FI01-V_1800 (450-850nm)_532nm_Edge_100%_x100_VIS_H30um_30sX2
#Remark=
#Date=	14.05.2021 11:21
#Acquired=	14.05.2021 11:21:13
#Base:Fit=	22.12.2021 12:22:35
#Base:Sub=	22.12.2021 12:23:38
#Data Range:Extract=	22.12.2021 12:27:19
1231.3	4.99422
1232.13	-0.00634766
1232.96	9.69616
1233.79	17.2563
1234.62	22.6543
1235.45	15.424
1236.28	18.7136
1237.11	14.6897
1237.94	18.0184
1238.76	18.1839
1239.59	17.2954
1240.42	23.7701
1241.25	12.3999
1242.08	20.9152
1242.91	18.8943
1243.74	12.7252
1244.57	8.66444
1245.4	9.79778
1246.22	15.1498
1247.05	27.8121
1247.88	19.5117
1248.71	21.6645
1249.54	27.9875
1250.36	20.7331
1251.19	21.8849
1252.02	29.3086
1252.85	21.0392
1253.67	31.5743
1254.5	31.6423
1255.33	34.8179
1256.16	27.5368
1256.98	27.6455
1257.81	22.4255
1258.63	23.4717
1259.46	15.4124
1260.29	29.7678
1261.11	34.1921
1261.94	21.6965
1262.77	27.9742
1263.59	30.0992
1264.42	37.4944
1265.24	36.5544
1266.07	46.0754
1266.89	48.1808
1267.72	21.9412
1268.55	25.0532
1269.37	25.088
1270.2	17.8236
1271.02	19.9727
1271.85	19.9854
1272.67	19.9891
1273.5	16.8696
1274.32	24.2446
1275.14	13.7688
1275.97	17.9974
1276.79	27.4482
1277.62	22.1508
1278.44	19.0093
1279.26	28.4691
1280.09	23.1536
1280.91	29.311
1281.73	33.7056
1282.56	38.8628
1283.38	65.1763
1284.2	158.797
1285.03	324.929
1285.85	569.057
1286.67	488.238
1287.5	182.947
1288.32	73.3058
1289.14	41.6474
1289.96	39.4796
1290.78	32.1063
1291.61	20.5022
1292.43	22.5808
1293.25	18.4246
1294.07	23.6558
1294.89	19.3188
1295.72	23.4576
1296.54	21.2419
1297.36	16.9643
1298.18	22.1712
1299	11.5631
1299.82	7.27535
1300.64	24.0786
1301.46	17.6637
1302.28	11.2355
1303.11	19.5538
1303.92	19.4504
1304.75	9.88913
1305.57	7.70086
1306.39	13.9725
1307.21	12.8568
1308.03	13.8289
1308.85	11.6486
1309.66	9.48511
1310.48	11.5005
1311.3	16.6854
1312.12	8.1761
1312.94	18.681
1313.76	13.3104
1314.58	13.2329
1315.4	18.4486
1316.22	13.0849
1317.04	11.9438
1317.85	11.8516
1318.67	18.0464
1319.49	14.7522
1320.31	10.4162
1321.13	17.7267
1321.95	17.6392
1322.76	11.1948
1323.58	2.58208
1324.4	4.65501
1325.22	6.74909
1326.03	9.89299
1326.85	8.75016
1327.67	10.7541
1328.49	0.0758171
1329.3	8.35249
1330.12	11.3614
1330.94	16.4705
1331.75	6.88422
1332.57	12.0121
1333.39	8.7531
1334.2	13.8931
1335.02	9.59559
1335.83	13.6697
1336.65	11.4895
1337.47	9.32809
1338.28	11.3469
1339.1	11.2505
1339.91	13.2182
1340.73	7.89597
1341.54	8.87072
1342.36	11.9053
1343.17	8.63806
1343.99	4.31883
1344.8	7.32695
1345.62	4.11241
1346.43	10.2618
1347.25	3.91085
1348.06	12.1258
1348.88	14.1035
1349.69	7.81962
1350.5	4.71579
1351.32	10.8128
1352.13	7.56892
1352.95	8.52851
1353.76	11.5739
1354.57	15.6471
1355.39	14.5136
1356.2	10.2659
1357.01	12.248
1357.83	11.1008
1358.64	10.0018
1359.45	14.072
1360.26	9.87287
1361.08	3.63707
1361.89	8.75595
1362.7	12.8045
1363.51	19.9475
1364.32	6.40109
1365.14	9.46395
1365.95	8.39928
1366.76	11.4615
1367.57	15.5187
1368.38	9.23627
1369.19	13.2457
1370.01	7.99412
1370.82	13.0841
1371.63	33.6365
1372.44	11.9538
1373.25	20.1749
1374.06	12.869
1374.87	6.65675
1375.68	19.0953
1376.49	9.78911
1377.3	10.737
1378.11	15.7311
1378.92	15.6635
1379.73	20.6722
1380.54	24.672
1381.35	15.3974
1382.16	5.15979
1382.97	20.599
1383.78	23.6972
1384.59	35.7375
1385.4	26.404
1386.21	33.875
1387.02	77.9891
1387.83	138.308
1388.64	422.042
1389.44	1223.52
1390.25	879.043
1391.06	199.274
1391.87	62.1153
1392.68	45.7806
1393.49	34.5086
1394.3	29.3466
1395.1	29.3177
1395.91	27.293
1396.72	16.064
1397.53	13.0108
1398.33	16.1086
1399.14	23.3194
1399.95	15.2505
1400.76	15.2901
1401.56	12.1701
1402.37	14.1991
1403.18	17.2425
1403.98	24.416
1404.79	15.2174
1405.6	19.3433
1406.4	13.2212
1407.21	22.4749
1408.01	16.2724
1408.82	25.4669
1409.63	33.7202
1410.43	56.5646
1411.24	66.63
1412.04	52.4066
1412.85	33.9543
1413.65	16.5422
1414.46	16.5909
1415.27	12.5167
1416.07	18.7145
1416.87	4.33091
1417.68	15.6121
1418.48	8.41789
1419.29	8.49294
1420.09	15.8531
1420.9	13.5578
1421.7	6.35992
1422.51	7.47163
1423.31	8.54846
1424.11	0.328289
1424.92	0.298317
1425.72	9.53603
1426.52	8.56549
1427.33	11.7214
1428.13	11.8292
1428.93	14.9775
1429.74	14.9711
1430.54	7.74946
1431.34	6.71773
1432.15	9.8812
1432.95	12.9901
1433.75	-0.303562
1434.55	6.89597
1435.36	5.90847
1436.16	15.1894
1436.96	8.09439
1437.76	8.16794
1438.56	14.3628
1439.37	10.3059
1440.17	10.3567
1440.97	10.376
1441.77	12.5003
1442.57	7.44889
1443.37	10.5569
1444.18	6.48739
1444.98	3.44041
1445.78	11.7217
1446.58	10.7412
1447.38	7.68514
1448.18	2.59585
1448.98	0.580814
1449.78	3.70192
1450.58	5.82085
1451.38	6.89075
1452.18	12.065
1452.98	11.1068
1453.78	13.2071
1454.58	9.13652
1455.38	9.1863
1456.18	1.05493
1456.98	9.30708
1457.78	7.29928
1458.58	7.33095
1459.38	4.28356
1460.17	5.32191
1460.97	5.35465
1461.77	12.6544
1462.57	13.5564
1463.37	9.51086
1464.17	8.50498
1464.97	8.55567
1465.76	12.69
1466.56	5.58947
1467.36	12.7426
1468.16	12.7815
1468.95	5.67832
1469.75	7.76759
1470.55	10.8623
1471.35	3.77825
1472.15	11.9924
1472.94	6.95414
1473.74	11.064
1474.54	8.04701
1475.33	11.1446
1476.13	11.1719
1476.93	12.2083
1477.72	6.1208
1478.52	12.2458
1479.32	12.3404
1480.11	7.34872
1480.91	5.38871
1481.7	4.35183
1482.5	4.23803
1483.3	9.50788
1484.09	7.52548
1484.89	15.6586
1485.68	7.58143
1486.48	11.659
1487.27	11.7115
1488.07	12.7563
1488.86	11.7883
1489.66	11.8492
1490.45	11.904
1491.25	11.9621
1492.04	11.0151
1492.84	13.037
1493.63	9.0228
1494.42	22.1897
1495.22	8.1148
1496.01	10.199
1496.81	12.2932
1497.6	9.32911
1498.39	8.36358
1499.19	4.37389
1499.98	13.4859
1500.77	4.44219
1501.57	10.5624
1502.36	13.633
1503.15	4.57129
1503.95	1.61152
1504.74	9.74054
1505.53	15.8357
1506.33	10.8606
1507.12	10.9313
1507.91	15.9918
1508.7	10.944
1509.49	20.9465
1510.29	17.9325
1511.08	8.97102
1511.87	15.0586
1512.66	15.058
1513.45	8.04291
1514.24	14.1008
1515.04	15.1704
1515.83	16.2464
1516.62	15.3138
1517.41	15.3598
1518.2	17.4319
1518.99	16.4826
1519.78	9.49169
1520.57	12.5064
1521.36	10.5046
1522.15	11.5513
1522.94	8.61778
1523.73	11.7149
1524.52	-1.27273
1525.31	12.7918
1526.1	13.8252
1526.89	13.8624
1527.68	7.90786
1528.47	16.003
1529.26	10.0329
1530.05	13.1219
1530.84	20.2371
1531.63	14.2617
1532.42	12.2822
1533.21	19.274
1534	11.2405
1534.78	17.2562
1535.57	10.2633
1536.36	14.3357
1537.15	10.4914
1537.94	16.6188
1538.73	13.6128
1539.51	15.6085
1540.3	14.6028
1541.09	14.5942
1541.88	9.66589
1542.66	13.7679
1543.45	12.8264
1544.24	10.8774
1545.03	5.8828
1545.81	10.9465
1546.6	6.8442
1547.39	19.0633
1548.18	21.2595
1548.96	17.2426
1549.75	18.3387
1550.53	13.2764
1551.32	7.26403
1552.11	10.2518
1552.89	8.27866
1553.68	15.3184
1554.46	16.3661
1555.25	7.35618
1556.04	11.3391
1556.82	14.3262
1557.61	20.3315
1558.39	19.3582
1559.18	18.4431
1559.96	13.4721
1560.75	14.4939
1561.53	8.57566
1562.32	16.4977
1563.1	12.4287
1563.89	16.5472
1564.67	6.67293
1565.46	20.6622
1566.24	10.6767
1567.03	14.6841
1567.81	6.71848
1568.59	14.7233
1569.38	16.7234
1570.16	13.72
1570.94	11.7249
1571.73	19.7752
1572.51	9.85676
1573.29	14.8774
1574.08	18.8473
1574.86	12.8097
1575.64	11.7934
1576.43	15.8003
1577.21	16.8358
1577.99	14.8563
1578.77	17.8346
1579.56	15.8333
1580.34	15.8394
1581.12	18.8354
1581.9	16.875
1582.68	13.8992
1583.47	18.8589
1584.25	11.8776
1585.03	18.847
1585.81	18.8849
1586.59	17.9296
1587.38	15.9599
1588.16	11.0087
1588.94	11.0137
1589.72	19.9327
1590.5	18.891
1591.28	13.8731
1592.06	12.909
1592.84	23.83
1593.62	19.8642
1594.4	15.9136
1595.18	17.9122
1595.96	16.8818
1596.74	16.8546
1597.52	15.8363
1598.3	12.814
1599.08	21.6785
1599.86	13.7236
1600.64	26.549
1601.42	15.6703
1602.2	13.7033
1602.98	13.7233
1603.76	18.6998
1604.54	17.7243
1605.32	22.6715
1606.09	19.6863
1606.87	15.6772
1607.65	17.6008
1608.43	15.5901
1609.21	19.545
1609.99	14.6192
1610.77	11.6539
1611.54	17.5563
1612.32	14.5961
1613.1	19.518
1613.88	17.5644
1614.65	23.4791
1615.43	15.5782
1616.21	26.3955
1616.99	7.63473
1617.76	19.4485
1618.54	13.5483
1619.32	18.4872
1620.09	21.4697
1620.87	25.4524
1621.65	13.5581
1622.42	18.4455
1623.2	18.4327
1623.98	7.59987
1624.75	17.4493
1625.53	11.5405
1626.3	18.4295
1627.08	21.367
1627.86	21.3438
1628.63	16.4295
1629.41	20.3876
1630.18	14.4992
1630.96	11.5053
1631.73	16.4079
1632.51	9.48775
1633.28	11.1353
1634.06	18.0581
1634.83	13.1705
1635.61	16.8877
1636.38	10.3639
1637.16	17.3239
1637.93	15.5629
1638.7	8.09944
1639.48	16.3427
1640.25	15.0684
1641.03	16.9286
1641.8	11.3044
1642.58	11.3777
1643.35	8.60807
1644.12	10.4568
1644.9	12.7932
1645.67	9.9451
1646.44	12.2637
1647.21	10.7885
1647.99	7.73156
1648.76	14.4174
1649.53	10.5295
1650.31	8.2987
1651.08	10.9054
1651.85	6.25545
1652.62	10.5993
1653.39	13.6899
1654.17	9.56963
1654.94	8.82505
1655.71	7.38067
1656.48	8.96834
1657.25	3.51603
1658.03	9.48286
1658.75	5.35558
1659.53	2.40396
1660.31	1.46892
1661.09	4.33008
1661.87	11.2891
1662.65	4.24788
1663.43	13.3076
1664.22	10.2143
1665	11.1884
1665.77	8.21274
1666.55	2.33673
1667.34	5.27707
1668.12	8.28754
1668.89	4.31239
1669.67	9.25476
1670.45	4.30329
1671.23	8.26353
1672.01	7.28923
1672.79	10.2684
1673.57	14.2194
1674.35	5.30146
1675.13	-0.667248
1675.91	5.22482
1676.68	10.138
1677.46	12.0858
1678.24	8.10621
1679.02	7.10501
1679.8	7.09481
1680.58	-0.82217
1681.35	7.05882
1682.13	9.99811
1682.91	5.04855
1683.69	2.08973
1684.46	6.0391
1685.24	11.9352
1686.02	3.01255
1686.8	7.90565
1687.57	4.92534
1688.35	10.8543
1689.13	11.8458
1689.91	2.93458
1690.68	8.79778
1691.46	6.77813
1692.23	9.71265
1693.01	5.77427
1693.79	8.73729
1694.56	5.74462
1695.34	2.74253
1696.12	6.64717
1696.89	10.5761
1697.67	1.7006
1698.44	10.536
1699.22	7.54571
1699.99	3.57829
1700.77	4.54311
1701.54	6.50681
1702.32	3.55017
1703.09	4.51869
1703.87	6.43612
1704.65	2.46185
1705.42	9.26421
1706.19	2.34281
1706.97	8.19401
1707.74	5.25653
1708.52	15.0657
1709.29	4.29049
1710.07	3.24578
1710.84	2.19501
1711.61	15.8404
1712.39	5.09009
1713.16	7.05453
1713.93	5.06169
1714.71	9.86258
1715.48	6.85927
1716.25	8.77642
1717.03	6.82397
1717.8	10.7058
1718.57	8.71339
1719.35	7.69341
1720.12	13.4752
1720.89	9.56516
1721.66	4.69352
1722.44	9.48384
1723.21	3.61751
1723.98	9.422
1724.75	9.40619
1725.52	10.3445
1726.3	5.29813
1727.07	9.23876
1727.84	9.1827
1728.61	8.29287
1729.38	9.24981
1730.15	1.49614
1730.93	1.43574
1731.7	9.09679
1732.47	5.18711
1733.24	12.861
1734.01	5.14177
1734.78	6.08209
1735.55	8.93337
1736.32	6.97049
1737.09	9.77663
1737.86	7.80187
1738.63	4.89216
1739.4	12.5349
1740.17	3.90813
1740.94	4.85259
1741.71	13.4408
1742.48	7.70801
1743.25	10.561
1744.02	8.60477
1744.79	8.56478
1745.56	9.51532
1746.33	13.3542
1747.1	12.4443
1747.87	4.84154
1748.63	3.89581
1749.4	12.4532
1750.17	8.59944
1750.94	8.57487
1751.71	7.59284
1752.48	11.3906
1753.25	7.55014
1754.02	5.60118
1754.78	9.38206
1755.55	13.2256
1756.32	7.53018
1757.09	5.63619
1757.85	12.2891
1758.62	8.46154
1759.39	5.60453
1760.16	10.3901
1760.92	10.4051
1761.69	11.4126
1762.46	8.59521
1763.22	3.85512
1763.99	8.61725
1764.76	9.56897
1765.52	6.70501
1766.29	6.65932
1767.06	10.4192
1767.82	10.4665
1768.59	2.91924
1769.36	6.75871
1770.12	9.65825
1770.89	15.4054
1771.65	12.5783
1772.42	11.6677
1773.18	6.01998
1773.95	17.4679
1774.71	9.83057
1775.48	1.24319
1776.24	8.83202
1777.01	3.1447
1777.77	0.320919
1778.54	13.6766
1779.3	5.14917
1780.07	9.96236
1780.83	10.0049
1781.6	7.19942
1782.36	12.0044
1783.13	7.2375
1783.89	12.0438
1784.65	10.2103
1785.42	8.43652
1786.18	9.46625
1786.95	10.4936
1787.71	7.65614
1788.47	6.66599
1789.24	10.5079
1790	10.544
1790.76	11.5316
1791.53	11.5638
1792.29	10.6861
1793.05	10.7682
1793.81	8.90623
1794.58	14.7302
1795.34	9.96896
1796.1	5.18535
1796.86	10.9484
1797.63	7.10118
1798.39	7.11412
1799.15	12.9081
1799.91	8.15347
1800.67	8.21365
1801.44	5.36939
1802.2	15.0536
1802.96	8.38423
1803.72	14.22
1804.48	17.145
1805.24	9.46201
1806	12.385
1806.77	6.63383
1807.53	9.55695
1808.29	18.2522
1809.05	17.3126
1809.81	10.6096
1810.57	13.554
1811.33	12.6571
1812.09	12.7357
1812.85	12.7808
1813.61	11.8522
1814.37	8.96819
1815.13	7.98581
1815.89	11.9137
1816.65	10.018
1817.41	15.8669
1818.17	13.0154
1818.93	18.8777
1819.69	16.0204
1820.44	8.30834
1821.2	3.48442
1821.96	6.43066
1822.72	13.2533
1823.48	11.3463
1824.24	13.3187
1825	11.4286
1825.76	15.3215
1826.51	11.4577
1827.27	9.53448
1828.03	6.64644
1828.79	8.63425
1829.55	14.4997
1830.3	17.4581
1831.06	6.83387
1831.82	16.5023
1832.58	0.000656128
1833.33	12.5725
1834.09	15.6646
1834.85	17.5136
1835.6	12.596
1836.36	15.7116
1837.12	12.8648
1837.88	13.7112
1838.63	15.5798
1839.39	6.85236
1840.14	10.7268
1840.9	20.4058
1841.66	16.5773
1842.41	5.98739
1843.17	9.92973
1843.93	14.7986
1844.68	9.80383
1845.44	19.5202
1846.19	9.87106
1846.95	11.773
1847.7	21.3509
1848.46	13.648
1849.21	15.5783
1849.97	16.5649
1850.72	14.6563
1851.48	16.5467
1852.23	15.5767
1852.99	5.0145
1853.74	15.5704
1854.5	15.5856
1855.25	9.8411
1856.01	7.91337
1856.76	21.2859
1857.51	16.5383
1858.27	5.11921
1859.02	16.6489
1859.78	14.7298
1860.53	12.7976
1861.28	17.5626
1862.04	11.8204
1862.79	7.97261
1863.54	11.7355
1864.3	14.538
1865.05	12.6105
1865.8	10.7259
1866.56	17.4023
1867.31	15.5138
1868.06	17.4314
1868.81	17.4396
1869.57	17.4367
1870.32	9.83017
1871.07	18.3777
1871.82	17.4053
1872.57	17.372
1873.33	10.6835
1874.08	9.71783
1874.83	15.2736
1875.58	9.79546
1876.33	16.5005
1877.08	13.6561
1877.83	15.5779
1878.59	16.4926
1879.34	12.6312
1880.09	9.72284
1880.84	15.4585
1881.59	8.80009
1882.34	17.3428
1883.09	12.6943
1883.84	16.4952
1884.59	13.6296
1885.34	14.5381
1886.09	16.3733
1886.84	10.7154
1887.59	12.6404
1888.34	16.4332
1889.09	20.2069
1889.84	15.4979
1890.59	17.3141
1891.34	12.6038
1892.09	18.228
1892.84	14.5017
1893.59	10.7851
1894.34	16.4719
1895.09	15.5517
1895.84	21.1813
1896.58	20.2112
1897.33	7.99
1898.08	13.6507
1898.83	5.24123
1899.58	9.0502
1900.33	18.4526
1901.07	16.5683
1901.82	14.6932
1902.57	16.579
1903.32	18.4211
1904.06	8.08046
1904.81	15.6067
1905.56	12.8254
1906.31	15.6788
1907.05	11.9789
1907.8	16.7557
1908.55	12.082
1909.3	16.7935
1910.04	11.1483
1910.79	14.9422
1911.54	15.0028
1912.28	10.3329
1913.03	21.6679
1913.78	14.1039
1914.52	8.42252
1915.27	14.083
1916.02	14.1345
1916.76	19.8772
1917.51	22.7432
1918.25	11.4302
1919	18.0848
1919.74	17.1363
1920.49	16.1701
1921.24	16.1504
1921.98	18.0263
1922.73	18.0628
1923.47	17.1757
1924.22	16.2802
1924.96	15.3608
1925.7	14.4335
1926.45	14.464
1927.19	16.4146
1927.94	11.7155
1928.68	16.4565
1929.43	15.4801
1930.17	15.4581
1930.92	17.3874
1931.66	11.826
1932.4	11.9474
1933.15	9.07365
1933.89	15.7239
1934.63	23.2951
1935.38	23.2552
1936.12	21.3866
1936.86	19.5094
1937.61	18.5854
1938.35	12.9341
1939.09	13.8322
1939.84	16.7698
1940.58	14.82
1941.32	13.873
1942.06	18.6827
1942.81	18.7247
1943.55	12.0569
1944.29	18.7463
1945.03	17.7701
1945.77	15.8446
1946.52	13.9562
1947.26	12.085
1948	18.8605
1948.74	14.1287
1949.48	23.7581
1950.22	24.7342
1950.97	17.9369
1951.71	12.0668
1952.45	12.0363
1953.19	18.8093
1953.93	10.2237
1954.67	15.0519
1955.41	15.0622
1956.15	16.0023
1956.89	18.8505
1957.63	14.9629
1958.37	17.7939
1959.11	13.9339
1959.85	13.9269
1960.59	14.8784
1961.33	18.72
1962.07	12.9396
1962.81	13.8863
1963.55	18.7115
1964.29	13.9118
1965.03	13.9016
1965.77	14.8439
1966.51	18.6263
1967.25	23.3506
1967.99	16.5801
1968.73	13.6628
1969.47	17.4922
1970.2	16.5009
1970.94	19.3197
1971.68	13.5369
1972.42	16.4053
1973.16	19.2885
1973.9	13.5215
1974.63	17.3258
1975.37	14.3975
1976.11	18.1952
1976.85	20.0943
1977.59	11.4339
1978.32	17.1343
1979.06	11.3472
1979.8	16.0913
1980.53	18.8894
1981.27	16.9324
1982.01	16.8863
1982.75	13.9646
1983.48	15.8729
1984.22	17.7692
1984.95	19.611
1985.69	21.3971
1986.43	20.2833
1987.16	13.5411
1987.9	7.84599
1988.64	13.5889
1989.37	16.4503
1990.11	8.77296
1990.84	13.4523
1991.58	14.3009
1992.32	16.0892
1993.05	15.059
1993.79	14.0898
1994.52	16.9355
1995.26	10.2568
1995.99	13.055
1996.73	17.6407
1997.46	17.5489
1998.2	16.698
1998.93	25.2023
1999.67	10.8573
2000.4	10.7616
2001.14	15.4278
2001.87	15.3792
2002.6	12.5043
2003.34	11.5214
2004.07	9.61244
2004.81	16.1765
2005.54	17.0255
2006.27	21.6587
2007.01	15.9109
2007.74	12.0735
2008.48	9.2119
2009.21	9.14614
2009.94	15.4756
2010.67	10.5821
2011.41	13.5106
2012.14	16.833
2012.87	15.7116
2013.61	7.12834
2014.34	9.15264
2015.07	8.13226
2015.8	13.5679
2016.54	11.9536
2017.27	17.9077
2018	8.71905
2018.73	8.51094
2019.46	13.753
2020.2	12.3085
2020.93	9.73124
2021.66	11.5203
2022.39	12.216
2023.12	10.8907
2023.85	10.3254
2024.58	8.76408
2025.32	8.40057
2026.05	8.28475
2026.78	11.3208
2027.51	10.2118
2028.24	8.18757
2028.97	5.71762
2029.7	9.23701
2030.43	7.81529
2031.16	9.13362
2031.89	8.85669
2032.62	6.81379
2033.35	10.5548
2034.08	5.94977
2034.81	7.95751
2035.36	7.62125
2036.1	8.49715
2036.84	3.76552
2037.58	5.55561
2038.32	8.28595
2039.05	8.23983
2039.79	2.59375
2040.53	3.51356
2041.27	8.20704
2042.01	5.34212
2042.74	4.41415
2043.48	9.20037
2044.22	8.12086
2044.96	10.8128
2045.69	8.92877
2046.43	0.540253
2047.17	4.29756
2047.91	4.30116
2048.64	11.7157
2049.38	2.35726
2050.12	5.15202
2050.86	0.50375
2051.59	13.5968
2052.33	8.88724
2053.07	6.03166
2053.8	15.3377
2054.54	2.23327
2055.28	6.90831
2056.01	3.18309
2056.75	6.92078
2057.49	7.82047
2058.22	9.6773
2058.96	0.303665
2059.69	4.03848
2060.43	8.72983
2061.16	9.667
2061.9	3.10427
2062.63	4.0676
2063.37	3.14285
2064.11	4.07753
2064.84	10.6571
2065.58	7.83882
2066.31	6.88249
2067.05	10.5659
2067.78	7.79018
2068.51	10.6071
2069.25	1.2674
2069.98	5.00601
2070.72	7.81266
2071.45	6.86733
2072.19	5.9569
2072.92	6.02174
2073.65	9.79996
2074.39	7.86543
2075.12	4.04885
2075.85	8.77609
2076.59	5.98343
2077.32	12.6172
2078.06	9.77418
2078.79	9.75541
2079.52	7.8614
2080.25	11.6348
2080.99	5.00452
2081.72	9.72058
2082.45	9.71368
2083.19	6.88929
2083.92	7.86731
2084.65	0.312675
2085.38	7.87929
2086.12	5.98838
2086.85	3.17561
2087.58	4.13
2088.31	8.88131
2089.04	5.12439
2089.78	7.07727
2090.51	9.97138
2091.24	14.7626
2091.97	13.8101
2092.7	5.22619
2093.43	2.35453
2094.16	7.09024
2094.89	5.16113
2095.63	6.09525
2096.36	10.8357
2097.09	-0.55508
2097.82	5.15132
2098.55	5.18678
2099.28	10.8902
2100.01	5.18142
2100.74	4.21519
2101.47	11.8168
2102.2	9.00151
2102.93	13.7958
2103.66	7.16505
2104.39	10.0339
2105.12	16.6561
2105.85	0.467907
2106.58	4.28755
2107.31	4.30782
2108.04	2.41662
2108.77	6.21264
2109.5	10.9612
2110.22	4.34328
2110.95	11.9902
2111.68	11.0403
2112.41	3.45043
2113.14	7.2494
2113.87	6.28334
2114.6	10.093
2115.33	9.13017
2116.05	7.19841
2116.78	10.0193
2117.51	7.16901
2118.24	12.8909
2118.97	3.46971
2119.69	8.26367
2120.42	9.25159
2121.15	7.36145
2121.88	9.22547
2122.6	7.27235
2123.33	3.4553
2124.06	8.16855
2124.78	11.9513
2125.51	7.23209
2126.24	4.41658
2126.97	11.989
2127.69	8.22057
2128.42	6.33251
2129.15	8.22221
2129.87	3.49789
2130.6	9.18253
2131.32	8.27114
2132.05	4.52058
2132.78	2.64956
2133.5	9.23242
2134.23	13.9723
2134.95	8.36745
2135.68	7.41553
2136.4	7.49269
2137.13	12.1675
2137.85	9.34746
2138.58	1.83643
2139.31	7.48658
2140.03	8.48296
2140.76	13.0577
2141.48	11.2758
2142.21	7.53786
2142.93	11.3412
2143.65	8.53916
2144.38	13.2518
2145.1	6.68764
2145.83	5.76196
2146.55	8.57554
2147.28	16.0577
2148	14.2006
2148.72	1.13518
2149.45	18.0726
2150.17	10.5764
2150.89	8.71859
2151.62	7.77124
2152.34	3.05833
2153.06	7.72235
2153.79	10.5458
2154.51	11.525
2155.23	8.79132
2155.96	11.6337
2156.68	7.91188
2157.4	13.5122
2158.13	8.85545
2158.85	4.21728
2159.57	9.85531
2160.29	16.4101
2161.01	9.90381
2161.74	4.31752
2162.46	11.8165
2163.18	9.99802
2163.9	11.879
2164.62	14.6771
2165.35	7.20045
2166.07	13.7506
2166.79	11.978
2167.51	12.0805
2168.23	12.1103
2168.95	13.9342
2169.67	8.35991
2170.39	13.0412
2171.12	12.1707
2171.84	7.57697
2172.56	11.3333
2173.28	8.58151
2174	15.1124
2174.72	6.79983
2175.44	17.9832
2176.16	15.215
2176.88	5.05082
2177.6	6.02189
2178.32	10.7005
2179.04	18.1527
2179.76	7.97293
2180.48	11.6934
2181.2	12.6266
2181.92	4.32766
2182.64	8.09441
2183.35	11.877
2184.07	8.26062
2184.79	10.208
2185.51	14.8767
2186.23	13.022
2186.95	13.0134
2187.67	10.27
2188.39	7.54433
2189.1	11.3126
2189.82	6.7349
2190.54	15.1627
2191.26	15.2855
2191.98	13.4872
2192.7	15.3653
2193.41	8.85042
2194.13	11.6356
2194.85	7.95395
2195.57	9.87726
2196.28	12.7607
2197	11.0026
2197.72	12.0668
2198.44	15.8855
2199.15	10.0829
2199.87	11.1693
2200.59	13.9896
2201.3	16.075
2202.02	10.4703
2202.74	15.9684
2203.45	6.72287
2204.17	10.4616
2204.89	12.3934
2205.6	12.4685
2206.32	13.4601
2207.03	14.4274
2207.75	13.5546
2208.47	14.551
2209.18	13.6902
2209.9	6.26622
2210.61	12.8017
2211.33	17.5143
2212.04	14.8023
2212.76	18.579
2213.47	14.8744
2214.19	12.0964
2214.9	5.59594
2215.62	14.9637
2216.33	15.9553
2217.05	16.009
2217.76	16.0321
2218.48	7.61904
2219.19	9.47536
2219.91	7.63404
2220.62	9.55293
2221.33	14.3009
2222.05	23.7236
2222.76	17.2457
2223.48	20.117
2224.19	13.6115
2224.9	16.4604
2225.62	14.5889
2226.33	17.4076
2227.04	18.397
2227.76	18.4509
2228.47	20.3876
2229.18	16.6833
2229.9	15.7918
2230.61	16.7788
2231.32	19.6348
2232.03	13.0347
2232.75	14.8789
2233.46	18.6568
2234.17	9.27016
2234.88	13.0938
2235.6	23.5273
2236.31	10.3854
2237.02	12.2549
2237.73	14.1052
2238.44	20.7656
2239.16	13.2278
2239.87	12.3014
2240.58	12.2797
2241.29	16.0386
2242	14.1854
2242.71	0.0565834
2243.42	17.1015
2244.14	12.3872
2244.85	17.1213
2245.56	19.9372
2246.27	17.0735
2246.98	14.2379
2247.69	11.3556
2248.4	16.9755
2249.11	22.6273
2249.82	17.9173
2250.53	13.2427
2251.24	14.2087
2251.95	9.45747
2252.66	12.2774
2253.37	13.2201
2254.08	11.3261
2254.79	19.8702
2255.5	13.2048
2256.21	16.0452
2256.92	13.1816
2257.63	11.2655
2258.33	16.9762
2259.05	15.0526
2259.75	12.1832
2260.46	13.1426
2261.17	14.1238
2261.88	17.9602
2262.59	9.35485
2263.3	15.0325
2264	20.6683
2264.71	12.955
2265.42	17.6435
2266.13	11.8892
2266.84	16.661
2267.54	13.8024
2268.25	15.6946
2268.96	13.757
2269.67	11.8024
2270.38	16.5397
2271.08	9.79286
2271.79	14.5285
2272.5	10.6507
2273.2	16.3519
2273.91	14.4176
2274.62	15.3678
2275.32	7.68976
2276.03	12.4322
2276.74	18.09
2277.45	10.2887
2278.15	11.148
2278.86	13.9405
2279.56	15.81
2280.27	10.986
2280.98	15.7916
2281.68	14.8188
2282.39	16.704
2283.09	11.7872
2283.8	16.519
2284.5	21.3274
2285.21	12.6049
2285.92	10.5697
2286.62	13.3149
2287.33	13.1809
2288.03	15.0255
2288.74	12.1091
2289.44	12.0575
2290.15	8.15917
2290.85	9.05903
2291.56	11.8445
2292.26	10.7619
2292.97	9.68462
2293.67	-0.0719299
2294.37	9.48031
2295.08	10.4042
2295.78	14.2038
2296.48	4.51305
2297.19	11.1831
2297.89	15.9278
2298.6	10.0672
2299.3	14.797
2300	10.8377
2300.71	9.77327
2301.41	9.7056
2302.11	10.6049
2302.82	8.59562
2303.52	14.3206
2304.22	10.3608
2304.93	11.2146
2305.63	7.24453
2306.33	5.23698
2307.03	6.15819
2307.74	8.00937
2308.44	8.84071
2309.14	6.72647
2309.84	12.3958
2310.54	18.1137
2311.25	14.2327
2311.95	15.1828
2312.65	8.30822
2313.35	12.9933
2314.05	8.03696
2314.75	10.8669
2315.46	8.8354
2316.16	8.7235
2316.86	6.6879
2317.56	10.4666
2318.26	12.3412
2318.96	5.54493
2319.66	3.57867
2320.36	1.57339
2321.06	14.0797
2321.76	11.0888
2322.46	8.05897
2323.17	9.88262
2323.86	13.632
2324.57	12.5608
2325.27	8.62395
2325.97	18.1953
2326.67	10.3877
2327.36	14.1877
2328.06	10.2668
2328.76	16.0202
2329.46	33.2992
2330.16	72.693
2330.86	107.259
2331.56	37.8718
2332.26	11.8406
2332.96	7.96523
2333.66	6.00322
2334.36	7.89408
2335.06	10.7455
2335.75	4.95385
2336.45	11.6738
2337.15	3.96336
2337.85	11.6108
2338.55	2.91026
2339.25	13.4241
2339.94	0.948322
2340.64	3.83605
2341.34	14.4023
2342.04	5.79794
2342.74	1.96514
2343.43	7.71927
2344.13	15.4091
2344.83	6.83323
2345.53	7.86085
2346.22	5.99079
2346.92	10.7562
2347.62	3.02976
2348.31	7.06536
2349.01	9.91718
2349.71	5.21121
2350.4	8.07776
2351.1	9.123
2351.8	7.36145
2352.49	11.2839
2353.19	7.5799
2353.89	7.64413
2354.58	5.85469
2355.28	9.78618
2355.97	7.07468
2356.67	8.18197
2357.36	10.2237
2358.06	13.2151
2358.76	15.2611
2359.45	10.6796
2359.92	7.95751