File: Data/3-Raman/processed/bu19w-d-ff2-fi06-v_1800 (450-850nm)_532nm_edge_100%_x100_vis_lwd_h50um_30sx2_01.txt
#Acq. time (s)=	30
#Accumulations=	2
#Range (cm-¹)=	1200...2365
#Windows=	3
#Auto scanning=	Off
#Autofocus=	Off
#Macrospot=	Off
#AutoExposure=	Off
#Spike filter=	Multiple accum.
#Delay time (s)=	2
#Binning=	1
#Readout mode=	Signal
#DeNoise=	Off
#ICS correction=	On
#Dark correction=	Off
#Inst. Process=	Off
#Detector Gain=	Best Dynamic
#Detector ADC=	50 kHz HS
#Detector temperature (°C)=	-60.09
#Instrument=	LabRAM HR Evol
#Detector=	SIN-EM FIVIS
#Objective=	x100_VIS_LWD
#Grating=	1800 (450-850nm)
#ND Filter=	100%
#Laser=	532nm_Edge
#Hole=	49.98
#Temperature=	0
#Range=	Visible
#StageXY=	75x50mm Scan+
#StageZ=	Z motor
#X (µm)=	0
#Y (µm)=	0
#Z (µm)=	58.8
#Full time(mm:ss)=	3:12
#Project=	21_11_22
#Sample=	BU19w
#Site=
#Title=	BU19w-D-FF2-FI06-V_1800 (450-850nm)_532nm_Edge_100%_x100_VIS_LWD_H50um_30sX2
#Remark=
#Date=	22.11.2021 13:14
#Acquired=	22.11.2021 13:14:09
#Base:Fit=	16.12.2021 17:39:50
#Base:Fit=	16.12.2021 17:44:22
#Base:Sub=	16.12.2021 17:44:24
1202.84	2.91257
1203.95	2.71543
1205.06	6.83512
1206.17	4.53787
1207.29	3.33953
1208.39	7.44585
1209.51	3.0234
1210.62	5.02138
1211.72	0.666012
1212.84	3.76763
1213.94	-1.68435
1215.05	2.44825
1216.16	3.41303
1217.27	5.44957
1218.38	-0.987663
1219.49	-0.030571
1220.6	0.906189
1221.71	-1.29668
1222.81	2.88247
1223.92	-0.330666
1225.03	-1.49786
1226.14	3.64061
1227.24	0.562244
1228.35	11.995
1229.46	8.81918
1230.56	19.2984
1231.67	23.5105
1232.78	25.6335
1233.88	24.5674
1234.99	23.4424
1236.09	16.0347
1237.2	16.0234
1238.3	5.55681
1239.41	6.6034
1240.51	10.829
1241.62	8.75362
1242.72	7.69231
1243.83	10.834
1244.93	9.80918
1246.03	12.9547
1247.14	14.0379
1248.24	21.3507
1249.34	26.5749
1250.45	23.4475
1251.55	31.8806
1252.65	21.5034
1253.75	22.6149
1254.86	23.7046
1255.96	8.07904
1257.06	12.3493
1258.16	14.4485
1259.26	11.4762
1260.36	12.4695
1261.46	14.7976
1262.56	12.7316
1263.66	24.3029
1264.76	12.9327
1265.86	6.79399
1266.96	5.83294
1268.06	3.78785
1269.16	4.92464
1270.26	10.3006
1271.36	5.19129
1272.46	9.48609
1273.56	10.6643
1274.66	10.7978
1275.76	8.8344
1276.85	5.78897
1277.95	10.0972
1279.05	13.3891
1280.15	9.27011
1281.24	26.1412
1282.34	82.1996
1283.44	309.767
1284.53	93.9351
1285.63	17.1861
1286.73	7.85025
1287.82	4.81668
1288.92	2.82066
1290.01	6.09369
1291.11	3.09208
1292.21	0.0547409
1293.3	0.241175
1294.4	3.52792
1295.49	5.73829
1296.58	4.78545
1297.68	1.74969
1298.77	-3.40397
1299.87	2.00865
1300.96	0.00749969
1302.05	0.128746
1303.15	-1.88303
1304.24	0.344725
1305.33	-2.6916
1306.42	-3.61341
1307.52	4.9596
1308.61	-0.186155
1309.7	-0.0449905
1310.79	-3.09418
1311.88	3.36864
1312.98	0.344292
1314.07	-0.589092
1315.16	0.603298
1316.25	3.9017
1317.34	-0.196262
1318.43	-0.0881672
1319.52	2.12194
1320.61	-0.925737
1321.7	3.42101
1322.79	-0.686983
1323.88	4.65184
1324.97	-1.48856
1326.06	1.83698
1327.15	-0.151375
1328.23	-0.0484257
1329.32	-1.01594
1330.41	0.125074
1331.5	3.36843
1332.59	3.46689
1333.67	0.425882
1334.76	0.538258
1335.85	1.68694
1336.94	-0.286983
1338.02	-3.30454
1339.11	0.995546
1340.2	3.1839
1341.28	5.39245
1342.37	3.40707
1343.45	0.353344
1344.54	3.56694
1345.63	1.58579
1346.71	6.89038
1347.8	6.98112
1348.88	3.95195
1349.96	0.962744
1351.05	4.23252
1352.13	2.1953
1353.22	3.34355
1354.3	5.51729
1355.39	4.57081
1356.47	2.58533
1357.55	4.74071
1358.63	6.91013
1359.72	4.9346
1360.8	7.12136
1361.88	4.11836
1362.97	11.4424
1364.05	7.37238
1365.13	9.53951
1366.21	10.6838
1367.29	5.60695
1368.37	17.0428
1369.45	13.9884
1370.54	14.0593
1371.62	14.1433
1372.7	15.2673
1373.78	17.4045
1374.86	19.5393
1375.94	20.7327
1377.02	26.9857
1378.09	26.9704
1379.18	37.2839
1380.25	45.4919
1381.33	46.5627
1382.41	52.8691
1383.49	44.8005
1384.57	60.0865
1385.65	109.369
1386.72	556.446
1387.8	150.64
1388.88	39.9215
1389.96	25.6179
1391.03	20.5596
1392.11	17.5621
1393.19	19.6969
1394.26	13.6112
1395.34	13.6751
1396.42	11.7141
1397.49	9.74843
1398.57	6.75949
1399.64	4.81743
1400.72	9.01659
1401.79	12.139
1402.87	7.05586
1403.94	12.2354
1405.02	9.23154
1406.09	10.3269
1407.17	22.7048
1408.24	32.9686
1409.31	21.7442
1410.39	10.6169
1411.46	9.60679
1412.53	9.6767
1413.61	6.65847
1414.68	6.72344
1415.75	6.77985
1416.82	7.85127
1417.9	3.77159
1418.97	3.82
1420.04	1.85816
1421.11	5.93759
1422.18	4.95299
1423.26	5.00696
1424.33	5.02548
1425.4	2.99534
1426.47	4.06652
1427.54	5.15188
1428.61	4.19604
1429.68	3.19508
1430.75	5.24685
1431.82	2.2163
1432.89	4.30027
1433.96	2.27795
1435.02	3.32889
1436.09	0.294903
1437.16	0.339844
1438.23	3.45186
1439.3	7.57963
1440.37	1.4544
1441.43	2.50163
1442.5	3.5713
1443.57	4.61462
1444.64	-0.496361
1445.7	8.76281
1446.77	1.60322
1447.84	2.63966
1448.9	6.75123
1449.97	1.64673
1451.04	0.644556
1452.1	-0.363386
1453.17	-0.341805
1454.23	6.83905
1455.3	-0.320274
1456.36	-0.302143
1457.43	2.78272
1458.49	2.78654
1459.56	-1.30904
1460.62	-1.31307
1461.69	1.78763
1462.75	-0.302929
1463.81	0.720913
1464.88	1.74619
1465.94	0.731586
1467	-1.31214
1468.07	1.7419
1469.13	-3.35456
1470.19	0.720877
1471.25	-0.301527
1472.32	4.79492
1473.38	-0.297142
1474.44	0.713604
1475.5	-0.307781
1476.56	-0.318192
1477.62	-0.336887
1478.68	0.671038
1479.75	-1.34568
1480.81	0.688221
1481.87	2.67482
1482.93	1.65159
1483.99	1.65254
1485.05	-1.39849
1486.11	0.607971
1487.17	2.62225
1488.22	1.59567
1489.28	-1.44414
1490.34	0.570604
1491.4	0.564383
1492.46	-1.47008
1493.52	-0.484034
1494.58	-0.495977
1495.63	0.505093
1496.69	-3.53584
1497.75	0.49577
1498.81	-2.54768
1499.86	-1.55356
1500.92	0.445005
1501.98	-2.58737
1503.03	1.41837
1504.09	-2.62034
1505.15	0.392471
1506.2	1.38983
1507.26	2.39019
1508.31	1.35305
1509.37	3.31219
1510.42	2.27166
1511.48	0.264238
1512.53	2.24296
1513.59	0.205385
1514.64	-0.812904
1515.7	-2.82473
1516.75	-1.82985
1517.8	-0.841988
1518.86	0.151552
1519.91	-2.87899
1520.96	0.0945892
1522.02	0.0722466
1523.07	-0.935478
1524.12	1.06519
1525.17	3.04747
1526.23	-0.981647
1527.28	-1.00138
1528.33	1.00026
1529.38	2.98641
1530.43	1.99246
1531.48	0.978237
1532.53	0.954407
1533.59	-1.09098
1534.64	-0.125475
1535.69	-1.15158
1536.74	-1.13979
1537.79	0.881054
1538.84	0.853792
1539.89	-3.18577
1540.94	-2.21933
1541.98	0.778347
1543.03	2.78638
1544.08	-0.229109
1545.13	1.74891
1546.18	-0.278969
1547.23	-1.28957
1548.28	-0.245945
1549.33	2.75194
1550.37	-0.28846
1551.42	2.6908
1552.47	3.65832
1553.52	0.637194
1554.56	1.62801
1555.61	-0.405008
1556.65	2.55881
1557.7	2.5337
1558.75	0.524837
1559.79	2.52247
1560.84	0.504805
1561.88	2.50946
1562.93	0.371059
1563.98	1.44238
1565.02	-0.552984
1566.07	1.43889
1567.11	2.41505
1568.15	4.40089
1569.2	-1.61577
1570.24	1.35609
1571.29	0.343742
1572.33	3.34919
1573.37	-1.65527
1574.42	1.3066
1575.46	1.27109
1576.5	2.25578
1577.55	4.24625
1578.59	3.22842
1579.63	4.20149
1580.67	0.202831
1581.72	-0.801905
1582.76	1.17983
1583.8	2.14996
1584.84	3.12756
1585.88	1.13642
1586.92	4.12297
1587.96	2.12992
1589	6.10031
1590.04	5.07364
1591.08	5.03011
1592.12	3.0404
1593.16	5.01211
1594.2	6.00167
1595.24	1.02987
1596.28	4.97525
1597.32	-0.00668716
1598.36	2.9384
1599.4	5.87955
1600.44	5.85208
1601.48	4.85299
1602.51	7.81757
1603.55	4.85847
1604.59	5.84932
1605.63	6.83299
1606.66	5.81728
1607.7	3.86562
1608.74	6.71116
1609.77	3.21835
1610.81	5.7409
1611.85	2.48841
1612.88	6.51523
1613.92	5.32593
1614.95	7.24194
1615.99	10.5678
1617.03	9.14692
1618.06	6.11963
1619.1	8.21877
1620.13	6.68007
1621.17	6.97408
1622.2	6.95292
1623.23	10.2344
1624.27	8.10365
1625.3	9.88109
1626.34	10.2144
1627.37	9.74311
1628.4	8.19008
1629.44	5.43095
1630.47	10.1256
1631.29	7.02938
1632.33	9.99312
1633.38	8.01933
1634.42	5.05757
1635.47	9.98011
1636.51	13.9243
1637.56	9.01161
1638.6	12.9646
1639.65	9.02837
1640.69	9.03417
1641.73	9.03129
1642.78	11.0171
1643.82	9.04955
1644.86	9.05021
1645.91	13.0087
1646.95	11.0632
1647.99	13.0679
1649.03	7.17692
1650.08	12.1101
1651.12	9.17052
1652.16	14.1201
1653.2	8.2464
1654.24	10.2387
1655.28	10.2425
1656.33	10.2408
1657.37	11.2304
1658.41	7.31751
1659.45	7.32939
1660.49	10.3535
1661.53	6.38981
1662.57	5.39783
1663.61	10.4137
1664.65	10.3745
1665.69	8.40889
1666.72	7.46514
1667.76	10.4618
1668.8	9.48777
1669.84	8.5203
1670.88	4.58669
1671.92	7.58239
1672.96	8.5993
1674	6.64013
1675.03	4.67076
1676.07	5.66174
1677.11	5.67079
1678.15	8.64478
1679.18	6.68594
1680.22	1.76414
1681.25	4.74354
1682.29	6.73127
1683.33	4.77612
1684.36	5.79148
1685.4	3.82679
1686.43	3.83304
1687.47	5.81465
1688.51	5.8443
1689.54	5.86701
1690.58	3.89537
1691.61	4.88285
1692.64	3.91873
1693.68	0.990318
1694.71	4.93979
1695.75	1.99166
1696.78	2.9944
1697.81	5.96274
1698.85	4.0085
1699.88	4.01522
1700.91	4.03182
1701.95	1.10964
1702.98	4.07666
1704.01	2.11728
1705.04	1.13916
1706.08	2.11799
1707.11	0.175104
1708.14	-1.75616
1709.17	3.16693
1710.2	3.16359
1711.23	1.20841
1712.27	1.22667
1713.3	2.23089
1714.33	-1.66952
1715.36	2.22515
1716.39	-3.60445
1717.42	1.2872
1718.45	3.24223
1719.48	2.27484
1720.51	1.31131
1721.54	0.359362
1722.56	0.362173
1723.59	3.28341
1724.62	2.3273
1725.65	1.36922
1726.68	1.35057
1727.71	0.405867
1728.74	-0.518919
1729.76	1.43171
1730.79	-1.45985
1731.82	-0.491585
1732.85	0.477819
1733.87	1.45575
1734.9	2.43129
1735.93	1.47869
1736.95	4.35641
1737.98	-1.39607
1739.01	1.48849
1740.03	1.50583
1741.06	0.564693
1742.08	-0.374051
1743.11	0.602097
1744.13	-1.3017
1745.16	0.61867
1746.18	-2.22052
1747.21	0.678174
1748.23	1.66652
1749.26	-1.19004
1750.28	0.729058
1751.31	-0.214116
1752.33	0.752358
1753.35	0.762035
1754.38	-0.185455
1755.4	-2.06363
1756.42	0.814911
1757.44	-1.06873
1758.47	-0.104376
1759.49	-1.98849
1760.51	0.888377
1761.53	1.86976
1762.56	-0.00170898
1763.58	0.972169
1764.6	-1.86611
1765.62	1.00329
1766.64	1.94643
1767.66	1.02297
1768.68	0.105497
1769.7	0.134025
1770.72	1.11335
1771.74	-0.766113
1772.76	-0.732879
1773.78	-0.709438
1774.8	2.16002
1775.82	1.21469
1776.84	-0.677685
1777.86	-0.651657
1778.88	-2.533
1779.9	0.352875
1780.92	-1.52737
1781.94	0.40892
1782.95	0.425529
1783.97	-1.46057
1784.99	-2.37728
1786.01	-0.423035
1787.03	1.52546
1788.04	-0.370999
1789.06	-2.28311
1790.08	-0.346615
1791.09	-2.24251
1792.11	0.655181
1793.13	-0.265243
1794.14	-1.19847
1795.16	-1.17457
1796.17	-0.196192
1797.19	0.77136
1798.21	-1.13951
1799.22	-0.161813
1800.24	-0.137399
1801.25	0.846533
1802.27	-2.0142
1803.28	-0.0620365
1804.29	1.88541
1805.31	0.936716
1806.32	-1.93899
1807.34	-0.959048
1808.35	0.981314
1809.36	0.99577
1810.38	1.9822
1811.39	0.0766277
1812.4	0.102495
1813.41	-0.848351
1814.43	2.06056
1815.44	-0.83125
1816.45	2.08559
1817.46	0.170876
1818.47	1.1567
1819.49	-1.7283
1820.5	-0.747927
1821.51	1.19785
1822.52	1.21441
1823.53	-1.67929
1824.54	-0.697629
1825.55	0.282931
1826.56	-2.61814
1827.57	1.26012
1828.58	3.20947
1829.59	-1.61705
1830.6	4.21196
1831.61	0.340504
1832.62	-0.643109
1833.63	0.398257
1834.64	0.350409
1835.65	-0.634728
1836.65	1.3459
1837.66	1.33091
1838.67	-0.62311
1839.68	-1.59779
1840.69	-0.62494
1841.7	1.31088
1842.7	-0.612254
1843.71	0.381405
1844.72	1.29553
1845.72	-0.619353
1846.73	0.338404
1847.74	0.325397
1848.74	0.31928
1849.75	-0.638234
1850.75	0.32252
1851.76	1.26992
1852.76	-0.656687
1853.77	-0.656347
1854.78	-0.657073
1855.78	-0.663853
1856.79	0.28366
1857.79	1.24728
1858.79	3.17301
1859.8	1.25405
1860.8	1.24228
1861.81	2.18808
1862.81	1.21744
1863.81	2.14611
1864.82	1.17326
1865.82	0.21983
1866.82	0.218903
1867.83	2.11743
1868.83	-1.68719
1869.83	-2.64407
1870.83	1.14763
1871.84	-1.71062
1872.84	1.11551
1873.84	-1.74341
1874.84	1.05949
1875.84	2.04135
1876.84	-1.73389
1877.84	0.15666
1878.84	1.08234
1879.84	0.10343
1880.84	0.107089
1881.84	-0.857648
1882.85	-0.844742
1883.85	1.04694
1884.84	0.0849447
1885.84	0.063798
1886.84	0.99133
1887.84	0.0541792
1888.84	0.0485811
1889.84	0.981378
1890.84	-1.8669
1891.84	-0.93676
1892.83	0.00109959
1893.83	1.8857
1894.83	-1.87578
1895.83	1.87518
1896.83	1.85841
1897.82	-0.0287304
1898.82	-0.964476
1899.82	-0.0222521
1900.81	-1.91401
1901.81	0.898433
1902.81	0.889629
1903.8	-0.0687857
1904.8	1.80228
1905.79	-1.95511
1906.79	0.868528
1907.79	-2.88571
1908.78	0.879991
1909.78	0.870324
1910.77	0.867089
1911.77	-0.0680285
1912.76	0.875621
1913.76	-0.0810432
1914.75	0.845856
1915.74	1.78767
1916.74	1.80136
1917.73	2.74191
1918.72	-1.98023
1919.72	2.7406
1920.71	-1.05651
1921.7	1.7622
1922.7	1.76071
1923.69	-1.06913
1924.68	1.7727
1925.67	-2.01955
1926.66	-2.02033
1927.66	-0.118059
1928.65	4.62166
1929.64	1.75546
1930.63	2.69254
1931.62	0.823112
1932.61	1.80441
1933.61	1.78414
1934.6	-2.04744
1935.59	-0.158998
1936.58	-0.158761
1937.57	-0.160279
1938.56	1.75415
1939.55	-0.169452
1940.54	3.64312
1941.52	-1.13521
1942.51	-1.1334
1943.5	-1.13409
1944.49	0.767751
1945.48	-3.06964
1946.47	-1.16207
1947.46	-1.15677
1948.44	3.65003
1949.43	1.73561
1950.42	1.73122
1951.41	-0.2286
1952.39	-0.252473
1953.38	-1.20084
1954.37	2.64296
1955.36	-0.241317
1956.34	-0.255463
1957.33	2.60825
1958.31	0.665846
1959.3	2.57273
1960.29	-2.23535
1961.27	0.637282
1962.26	-0.334568
1963.24	0.61994
1964.23	0.61812
1965.21	1.57006
1966.2	0.592326
1967.18	0.563879
1968.17	-4.25383
1969.15	-0.429595
1970.14	-0.44158
1971.12	-0.462734
1972.1	-0.474474
1973.09	0.480429
1974.07	3.34917
1975.05	-0.505155
1976.04	1.39448
1977.02	-2.4496
1978	-1.50883
1978.98	-0.56738
1979.97	-0.585077
1980.95	2.2622
1981.93	-1.58047
1982.91	-1.59818
1983.89	1.26486
1984.88	3.15628
1985.86	1.20155
1986.84	-0.744963
1987.82	2.10743
1988.8	0.193891
1989.78	0.145282
1990.76	0.977493
1991.74	1.7666
1992.72	1.81559
1993.7	0.416614
1994.68	-1.3389
1995.66	1.02429
1996.64	-1.77547
1997.62	-1.37494
1998.6	0.759868
1999.57	-1.27868
2000.55	0.56953
2001.53	0.143222
2002.51	0.413139
2003.49	1.01067
2004.47	0.0153637
2005.44	-0.331509
2006.42	1.44897
2007.4	-0.705884
2008.38	0.985681
2009.35	-0.557719
2010.33	-1.24725
2011.3	0.346088
2012.18	1.88217
2013.17	-1.87489
2014.16	-0.929784
2015.15	-0.952091
2016.14	-0.0440531
2017.13	0.872484
2018.11	-1.94612
2019.1	1.79172
2020.09	-1.97286
2021.08	1.74793
2022.06	-2.01454
2023.05	-0.172482
2024.04	-2.02326
2025.02	-1.08515
2026.01	-1.06211
2027	-2.04977
2027.98	-2.07649
2028.97	-0.210649
2029.96	0.736058
2030.94	1.68029
2031.93	0.697323
2032.91	1.65737
2033.9	3.52034
2034.88	-0.223107
2035.87	0.696239
2036.85	-0.255093
2037.83	-0.277111
2038.82	0.640776
2039.8	1.55753
2040.79	-1.23408
2041.77	-0.302326
2042.75	-0.305955
2043.74	1.57619
2044.72	0.608064
2045.7	-4.06201
2046.69	-0.326091
2047.67	-2.18388
2048.65	2.47364
2049.63	-0.330654
2050.62	0.609008
2051.6	-0.318072
2052.58	0.606443
2053.56	-0.339258
2054.54	1.52585
2055.52	-0.33895
2056.5	-0.333825
2057.48	-1.27705
2058.46	0.593779
2059.45	0.591842
2060.43	0.596625
2061.4	1.53615
2062.39	1.5448
2063.37	-0.322743
2064.34	-0.321726
2065.32	1.56193
2066.3	-0.320217
2067.28	-0.336555
2068.26	3.44279
2069.24	2.5191
2070.22	0.628633
2071.2	1.56779
2072.18	0.636456
2073.15	-0.286635
2074.13	0.650675
2075.11	-0.307296
2076.09	-0.302632
2077.06	-0.289741
2078.04	0.655434
2079.02	-1.23985
2080	2.54054
2080.97	-1.24394
2081.95	0.643834
2082.93	2.53208
2083.9	0.653831
2084.88	0.657523
2085.85	-1.23594
2086.83	-0.282843
2087.8	0.667106
2088.78	-0.274327
2089.75	-0.257651
2090.73	0.705806
2091.7	1.66196
2092.68	-2.14916
2093.65	1.64356
2094.63	0.682563
2095.6	-1.22318
2096.57	-0.277877
2097.55	-2.17694
2098.52	2.5786
2099.5	1.62806
2100.47	-0.281364
2101.44	1.61565
2102.41	1.62444
2103.39	-2.16844
2104.36	0.685542
2105.33	2.57117
2106.3	-0.288637
2107.27	0.667264
2108.25	-1.23412
2109.22	-0.290811
2110.19	3.51221
2111.16	1.61993
2112.13	1.618
2113.1	1.61205
2114.07	0.652331
2115.04	0.647473
2116.01	2.52856
2116.99	0.617801
2117.96	1.56415
2118.92	1.57655
2119.9	-3.15816
2120.86	3.48863
2121.83	-1.27121
2122.8	-1.29384
2123.77	1.53
2124.74	-0.371145
2125.71	2.46077
2126.68	1.51216
2127.65	-0.381742
2128.61	-2.27855
2129.58	-2.28583
2130.55	-0.402394
2131.52	2.43072
2132.48	1.48465
2133.45	3.35587
2134.42	0.526238
2135.39	-1.35946
2136.35	-0.409437
2137.32	1.45755
2138.28	0.509243
2139.25	-1.3811
2140.22	2.40345
2141.18	0.477391
2142.15	0.483755
2143.12	1.4233
2144.08	-2.34143
2145.05	0.470582
2146.01	-1.41481
2146.98	1.38434
2147.94	-1.43729
2148.9	0.445847
2149.87	-0.492179
2150.83	-2.37376
2151.8	2.29265
2152.76	-1.47139
2153.72	-0.544888
2154.69	-0.541472
2155.65	-0.534745
2156.61	-2.40851
2157.58	-2.41928
2158.54	1.30802
2159.5	-1.49201
2160.47	-1.49557
2161.43	1.29466
2162.39	1.29073
2163.35	-0.572643
2164.31	1.28218
2165.27	2.18962
2166.24	1.26069
2167.2	-0.58002
2168.16	-0.577145
2169.12	2.19054
2170.08	-0.604722
2171.04	0.328531
2172	0.332673
2172.96	-1.52682
2173.92	0.327935
2174.88	2.18808
2175.84	2.181
2176.8	0.326751
2177.76	0.327304
2178.72	1.25345
2179.68	0.321321
2180.64	0.311332
2181.59	2.15781
2182.55	2.16508
2183.51	0.32385
2184.47	-1.5125
2185.43	2.20473
2186.38	4.04697
2187.34	2.18043
2188.3	2.18666
2189.26	0.340238
2190.21	2.20715
2191.17	-1.48414
2192.13	-0.546482
2193.08	3.16139
2194.04	1.28877
2195	3.14254
2195.95	1.30548
2196.91	-1.45839
2197.86	1.36533
2198.82	1.35592
2199.78	0.408911
2200.73	1.35822
2201.69	4.19927
2202.64	-0.502533
2203.59	1.36406
2204.55	-0.491757
2205.5	2.3175
2206.46	0.46833
2207.41	0.475253
2208.37	0.489748
2209.32	0.506429
2210.27	1.44144
2211.23	-1.35257
2212.18	2.40055
2213.13	-2.25971
2214.09	0.544964
2215.04	1.48562
2215.99	1.49583
2216.94	2.44627
2217.9	2.45257
2218.85	-0.356797
2219.8	-1.28817
2220.75	0.596208
2221.7	0.620604
2222.65	0.642481
2223.6	0.662136
2224.55	0.680026
2225.5	3.49861
2226.46	2.56525
2227.41	-0.227289
2228.36	0.731844
2229.31	0.752735
2230.26	2.65387
2231.21	-0.150759
2232.16	-0.148689
2233.11	-0.148444
2234.05	0.803786
2235	-1.05175
2235.95	0.86016
2236.9	0.872795
2237.85	3.70719
2238.8	1.84088
2239.75	1.8569
2240.69	0.918051
2241.64	3.76064
2242.59	1.90472
2243.54	0.0362844
2244.48	1.00063
2245.43	-1.82906
2246.38	0.0712357
2247.32	-0.861763
2248.27	0.0835609
2249.22	-1.79722
2250.16	-0.823613
2251.11	-0.796527
2252.06	0.166957
2253	-2.66389
2253.95	-0.745667
2254.89	1.17406
2255.84	2.14058
2256.78	-0.689654
2257.73	0.279698
2258.67	-0.647812
2259.62	-1.58133
2260.56	0.350674
2261.51	-1.52237
2262.45	-0.541528
2263.39	1.37938
2264.34	-1.48289
2265.28	-1.47779
2266.22	-2.41324
2267.17	-2.38436
2268.11	0.5083
2269.05	-0.42375
2270	0.551251
2270.94	0.56979
2271.88	-1.32628
2272.82	-1.30872
2273.77	-2.24021
2274.71	-1.25149
2275.65	1.65956
2276.59	1.67154
2277.53	0.708769
2278.47	0.716631
2279.41	-0.222282
2280.36	-1.1521
2281.3	-2.07391
2282.24	-0.12233
2283.18	-2.03586
2284.12	1.83922
2285.06	-1.01898
2286	1.87979
2286.94	-1.97216
2287.88	-0.0348148
2288.82	-0.966042
2289.75	1.95098
2290.69	0.0516338
2291.63	-0.89833
2292.57	-0.888779
2293.51	-1.84508
2294.45	0.101791
2295.39	1.09809
2296.32	-0.800584
2297.26	1.14996
2298.2	0.208534
2299.14	1.19391
2300.07	2.17433
2301.01	1.22748
2301.95	0.288095
2302.89	0.311754
2303.82	0.333594
2304.76	0.347161
2305.69	0.360725
2306.63	1.35319
2307.57	1.38012
2308.5	0.416255
2309.44	-0.552176
2310.37	-1.5035
2311.31	1.42713
2312.24	-0.473755
2313.18	-0.471019
2314.11	1.4625
2315.05	-0.446125
2315.98	-3.33784
2316.92	0.53127
2317.85	0.547294
2318.78	-0.394314
2319.72	2.53211
2320.65	2.54754
2321.58	-0.340206
2322.52	1.58869
2323.45	2.55332
2324.38	3.51487
2325.32	7.37474
2326.25	13.1587
2327.18	39.1696
2328.11	68.0548
2329.05	14.1526
2329.98	10.2882
2330.91	3.54732
2331.84	1.61823
2332.77	0.66021
2333.7	0.663535
2334.63	2.58828
2335.56	-0.29557
2336.5	1.62998
2337.43	1.62575
2338.36	0.651867
2339.29	1.59653
2340.22	-1.28535
2341.15	1.58753
2342.08	0.62606
2343.01	-0.346012
2343.93	3.4742
2344.86	0.592756
2345.79	3.46176
2346.72	2.47734
2347.65	-0.44362
2348.58	2.46843
2349.51	-2.36454
2350.44	-2.40078
2351.36	1.38955
2352.29	-1.48049
2353.22	0.399441
2354.15	-1.54251
2355.07	-0.621924
2356	0.297527
2356.93	-0.683847
2357.86	-0.723417
2358.78	0.182129
2359.71	-0.810637
2360.63	1.98611
2361.56	0.0506277
2362.49	0.00388241
2363.41	-1.00285
2364.34	-0.0868368
2364.8	-0.10394