File: Data/3-Raman/processed/bu19w-d-ore2-fi13-v_1800 (450-850nm)_532nm_edge_100%_x100_vis_lwd_h50um_30sx2_01.txt
#Acq. time (s)=	30
#Accumulations=	2
#Range (cm-¹)=	1200...2365
#Windows=	3
#Auto scanning=	Off
#Autofocus=	Off
#Macrospot=	Off
#AutoExposure=	Off
#Spike filter=	Multiple accum.
#Delay time (s)=	2
#Binning=	1
#Readout mode=	Signal
#DeNoise=	Off
#ICS correction=	On
#Dark correction=	Off
#Inst. Process=	Off
#Detector Gain=	Best Dynamic
#Detector ADC=	50 kHz HS
#Detector temperature (°C)=	-60.09
#Instrument=	LabRAM HR Evol
#Detector=	SIN-EM FIVIS
#Objective=	x100_VIS_LWD
#Grating=	1800 (450-850nm)
#ND Filter=	100%
#Laser=	532nm_Edge
#Hole=	49.98
#Temperature=	0
#Range=	Visible
#StageXY=	75x50mm Scan+
#StageZ=	Z motor
#X (µm)=	0
#Y (µm)=	0
#Z (µm)=	14.4
#Full time(mm:ss)=	3:22
#Project=	21_11_22
#Sample=	BU19w
#Site=
#Title=	BU19w-D-FFore2-FI13-V_1800 (450-850nm)_532nm_Edge_100%_x100_VIS_LWD_H50um_30sX2
#Remark=
#Date=	22.11.2021 14:06
#Acquired=	22.11.2021 14:06:00
#Base:Fit=	16.12.2021 17:39:50
#Base:Fit=	16.12.2021 17:40:55
#Base:Sub=	16.12.2021 17:40:56
1202.84	4.06729
1203.95	2.85957
1205.06	0.612425
1206.17	3.7217
1207.29	-0.635088
1208.39	0.327827
1209.51	1.29387
1210.62	1.20847
1211.72	0.0846653
1212.84	5.35047
1213.94	-0.0620308
1215.05	-1.20266
1216.16	1.91879
1217.27	-0.257998
1218.38	-7.72833
1219.49	2.79815
1220.6	-0.466064
1221.71	1.58081
1222.81	2.60722
1223.92	0.463457
1225.03	-1.73265
1226.14	1.33066
1227.24	3.50062
1228.35	6.54333
1229.46	0.21874
1230.56	1.24743
1231.67	3.34653
1232.78	0.195908
1233.88	0.180702
1234.99	0.136532
1236.09	-3.05039
1237.2	-0.968037
1238.3	1.12836
1239.41	0.0674572
1240.51	0.0772629
1241.62	1.12686
1242.72	4.2459
1243.83	1.08997
1244.93	1.08952
1246.03	0.0332127
1247.14	3.17907
1248.24	-1.0187
1249.34	0.0165806
1250.45	0.00857735
1251.55	-3.09528
1252.65	1.10112
1253.75	3.21174
1254.86	-1.99989
1255.96	-0.952234
1257.06	0.129469
1258.16	-4.05618
1259.26	-1.89805
1260.36	0.139769
1261.46	6.53728
1262.56	1.29876
1263.66	2.36644
1264.76	4.51275
1265.86	3.53502
1266.96	-0.627207
1268.06	4.60612
1269.16	2.54208
1270.26	5.75033
1271.36	-1.53012
1272.46	3.74754
1273.56	2.7516
1274.66	0.705738
1275.76	1.81464
1276.85	3.9565
1277.95	0.831648
1279.05	2.98917
1280.15	1.95946
1281.24	8.26223
1282.34	38.918
1283.44	72.6424
1284.53	22.1056
1285.63	7.39189
1286.73	3.23431
1287.82	3.27847
1288.92	1.20322
1290.01	-1.92292
1291.11	1.30527
1292.21	4.51167
1293.3	2.50133
1294.4	1.47745
1295.49	0.439068
1296.58	2.57243
1297.68	3.67261
1298.77	-1.56772
1299.87	-0.467993
1300.96	1.66953
1302.05	2.7587
1303.15	0.65921
1304.24	-1.42053
1305.33	2.83667
1306.42	-0.284555
1307.52	0.81119
1308.61	-2.31543
1309.7	1.95575
1310.79	1.98237
1311.88	2.0196
1312.98	-2.15523
1314.07	-6.34824
1315.16	3.20022
1316.25	4.29304
1317.34	0.10203
1318.43	2.22996
1319.52	2.23728
1320.61	1.20582
1321.7	1.24125
1322.79	-0.850096
1323.88	0.190695
1324.97	6.59126
1326.06	1.39025
1327.15	5.63814
1328.23	0.37351
1329.32	-1.7386
1330.41	4.56746
1331.5	-2.78633
1332.59	0.372145
1333.67	1.43441
1334.76	0.405458
1335.85	0.414577
1336.94	3.58386
1338.02	0.473783
1339.11	0.492737
1340.2	1.54365
1341.28	1.56871
1342.37	2.62943
1343.45	-1.55834
1344.54	0.523882
1345.63	-0.504663
1346.71	1.5864
1347.8	4.71278
1348.88	0.555338
1349.96	1.63653
1351.05	-0.390312
1352.13	2.68943
1353.22	2.71003
1354.3	2.71863
1355.39	5.83722
1356.47	5.83728
1357.55	1.68499
1358.63	4.80469
1359.72	1.70822
1360.8	2.77318
1361.88	3.82818
1362.97	8.99721
1364.05	3.81082
1365.13	4.86108
1366.21	1.78599
1367.29	-0.270247
1368.37	2.82487
1369.45	8.98902
1370.54	8.9814
1371.62	6.92604
1372.7	6.94051
1373.78	3.85278
1374.86	5.91408
1375.94	9.07333
1377.02	15.2539
1378.09	16.2101
1379.18	16.1825
1380.25	21.2646
1381.33	18.173
1382.41	17.1988
1383.49	14.1648
1384.57	22.2749
1385.65	31.5161
1386.72	156.934
1387.8	44.9065
1388.88	14.1203
1389.96	10.003
1391.03	7.9512
1392.11	2.84022
1393.19	6.95168
1394.26	5.91988
1395.34	4.89642
1396.42	-1.22462
1397.49	5.95532
1398.57	0.854765
1399.64	3.97532
1400.72	6.06229
1401.79	5.01915
1402.87	1.92806
1403.94	3.97336
1405.02	7.06091
1406.09	1.94528
1407.17	6.058
1408.24	16.2772
1409.31	9.09785
1410.39	4.0572
1411.46	1.96898
1412.53	4.03688
1413.61	8.15425
1414.68	3.03242
1415.75	3.03746
1416.82	0.97547
1417.9	3.00717
1418.97	5.05965
1420.04	-0.024601
1421.11	5.02291
1422.18	6.04135
1423.26	-2.15522
1424.33	0.894089
1425.4	4.96129
1426.47	2.91774
1427.54	1.91301
1428.61	-0.109324
1429.68	2.95035
1430.75	3.92907
1431.82	4.95782
1432.89	-0.170782
1433.96	2.88922
1435.02	-2.24459
1436.09	0.830435
1437.16	2.89305
1438.23	5.97109
1439.3	11.0877
1440.37	5.95247
1441.43	6.96308
1442.5	5.95544
1443.57	2.86056
1444.64	0.79166
1445.7	4.89335
1446.77	1.80436
1447.84	3.83254
1448.9	1.76421
1449.97	-1.32021
1451.04	3.79836
1452.1	0.7127
1453.17	0.708897
1454.23	3.76231
1455.3	1.69855
1456.36	-0.356226
1457.43	-0.370028
1458.49	1.65648
1459.56	3.67395
1460.62	2.61489
1461.69	3.65732
1462.75	4.58381
1463.81	3.54249
1464.88	-2.5951
1465.94	3.51007
1467	0.421959
1468.07	0.39662
1469.13	2.40736
1470.19	0.354452
1471.25	1.34734
1472.32	-0.696167
1473.38	2.33531
1474.44	2.30916
1475.5	4.31988
1476.56	2.25588
1477.62	2.21363
1478.68	2.19012
1479.75	-0.84911
1480.81	2.18923
1481.87	-0.919546
1482.93	4.12299
1483.99	3.10107
1485.05	0.0355301
1486.11	-3.03428
1487.17	-1.03049
1488.22	1.9767
1489.28	2.97161
1490.34	0.932999
1491.4	-0.0922947
1492.46	-1.12605
1493.52	2.87472
1494.58	-3.20234
1495.63	-0.189327
1496.69	4.85036
1497.75	0.80139
1498.81	-3.25909
1499.86	0.75448
1500.92	2.74404
1501.98	-1.29975
1503.03	1.68765
1504.09	-0.33856
1505.15	-5.38967
1506.2	2.65857
1507.26	-3.39682
1508.31	1.60475
1509.37	1.53867
1510.42	2.49902
1511.48	-0.50963
1512.53	-0.544199
1513.59	0.422434
1514.64	0.405455
1515.7	5.41785
1516.75	1.40072
1517.8	-0.621601
1518.86	-2.63601
1519.91	-2.65826
1520.96	-0.692976
1522.02	-3.72063
1523.07	0.283859
1524.12	4.29563
1525.17	2.26845
1526.23	2.24621
1527.28	2.22629
1528.33	1.23129
1529.38	2.2176
1530.43	1.23321
1531.48	-1.78277
1532.53	-0.802074
1533.59	2.15604
1534.64	-1.88637
1535.69	2.0869
1536.74	-1.88691
1537.79	-1.85725
1538.84	2.12621
1539.89	1.08709
1540.94	-0.954132
1541.98	0.052124
1543.03	5.07588
1544.08	1.06577
1545.13	0.0411491
1546.18	-2.98475
1547.23	-3.98871
1548.28	2.09232
1549.33	2.0841
1550.37	-3.96465
1551.42	0.0209846
1552.47	2.99442
1553.52	-8.03421
1554.56	-0.024992
1555.61	6.95337
1556.65	0.908752
1557.7	-0.111895
1558.75	1.88461
1559.79	0.892675
1560.84	3.88006
1561.88	3.89787
1562.93	-0.271658
1563.98	-0.167578
1565.02	1.84608
1566.07	-1.15258
1567.11	4.82513
1568.15	-0.178059
1569.2	-0.195522
1570.24	2.7782
1571.29	-1.22292
1572.33	4.79144
1573.37	-0.205187
1574.42	3.75224
1575.46	-0.27487
1576.5	-2.27469
1577.55	0.720217
1578.59	2.69802
1579.63	-1.3068
1580.67	2.66918
1581.72	2.66748
1582.76	0.671057
1583.8	5.62431
1584.84	-1.35476
1585.88	-0.353088
1586.92	1.64601
1587.96	6.63175
1589	5.62754
1590.04	2.61194
1591.08	-1.40469
1592.12	6.54718
1593.16	0.575745
1594.2	0.578098
1595.24	6.53939
1596.28	8.49509
1597.32	-1.44704
1598.36	3.47991
1599.4	4.44011
1600.44	2.43594
1601.48	4.40779
1602.51	2.43407
1603.55	0.469921
1604.59	7.40315
1605.63	0.476048
1606.66	5.39638
1607.7	-3.36836
1608.74	5.03004
1609.77	4.6595
1610.81	0.576254
1611.85	4.3899
1612.88	4.66834
1613.92	2.0611
1614.95	1.35907
1615.99	4.80135
1617.03	3.1763
1618.06	0.547659
1619.1	2.1084
1620.13	2.64128
1621.17	1.52824
1622.2	2.48685
1623.23	2.2207
1624.27	5.75685
1625.3	4.98222
1626.34	1.91932
1627.37	1.76802
1628.4	3.37556
1629.44	4.14425
1630.47	5.1539
1631.29	3.4794
1632.33	-0.456194
1633.38	5.45438
1634.42	1.50663
1635.47	4.45985
1636.51	5.45065
1637.56	1.52172
1638.6	1.53494
1639.65	3.50592
1640.69	4.49525
1641.73	-2.3952
1642.78	2.53966
1643.82	0.572315
1644.86	0.573065
1645.91	3.54434
1646.95	2.57953
1647.99	2.60899
1649.03	4.59773
1650.08	2.6318
1651.12	5.60186
1652.16	4.63509
1653.2	3.68784
1654.24	5.67777
1655.28	1.73196
1656.33	2.71594
1657.37	4.68978
1658.41	2.74571
1659.45	0.781643
1660.49	2.81069
1661.53	2.79593
1662.57	6.73171
1663.61	-1.09652
1664.65	2.82226
1665.69	3.81374
1666.72	0.890686
1667.76	1.90536
1668.8	2.90429
1669.84	1.93237
1670.88	4.91499
1671.92	2.96293
1672.96	0.016901
1674	3.00149
1675.03	1.02716
1676.07	2.0127
1677.11	0.0399189
1678.15	4.98526
1679.18	3.02135
1680.22	0.0701637
1681.25	4.03172
1682.29	5.02557
1683.33	6.02766
1684.36	5.06407
1685.4	2.10472
1686.43	5.06391
1687.47	1.1187
1688.51	3.11604
1689.54	-2.78821
1690.58	-1.80432
1691.61	0.163099
1692.64	1.16313
1693.68	-0.785242
1694.71	1.18625
1695.75	2.1675
1696.78	-0.772865
1697.81	1.20494
1698.85	-0.755892
1699.88	3.17495
1700.91	1.21895
1701.95	0.255714
1702.98	0.267756
1704.01	3.2089
1705.04	0.256279
1706.08	0.243595
1707.11	-1.70754
1708.14	-2.66578
1709.17	0.292078
1710.2	2.23517
1711.23	0.267839
1712.27	-1.67565
1713.3	-0.678303
1714.33	1.26731
1715.36	1.24393
1716.39	0.272776
1717.42	1.26243
1718.45	0.287254
1719.48	2.22623
1720.51	-1.66254
1721.54	4.17366
1722.56	1.24869
1723.59	0.282299
1724.62	-0.682703
1725.65	-2.61791
1726.68	-0.715845
1727.71	-0.70351
1728.74	0.301224
1729.76	-1.62255
1730.79	0.300898
1731.82	1.25224
1732.85	1.24356
1733.87	-0.67594
1734.9	-0.671698
1735.93	0.287941
1736.95	-0.686043
1737.98	3.13647
1739.01	5.04786
1740.03	1.22541
1741.06	-2.59627
1742.08	-0.674177
1743.11	1.24929
1744.13	0.287033
1745.16	-2.57893
1746.18	-2.56177
1747.21	0.332546
1748.23	0.359838
1749.26	-2.50775
1750.28	2.2633
1751.31	-1.55398
1752.33	2.26168
1753.35	-0.599035
1754.38	0.343674
1755.4	0.361595
1756.42	3.23336
1757.44	-0.562243
1758.47	2.29263
1759.49	-2.45338
1760.51	0.416794
1761.53	3.29572
1762.56	0.469057
1763.58	-0.468538
1764.6	-2.36365
1765.62	-0.455328
1766.64	1.4233
1767.66	-3.30625
1768.68	1.47452
1769.7	0.547886
1770.72	0.570742
1771.74	1.54161
1772.76	-0.331251
1773.78	-0.313637
1774.8	4.4505
1775.82	-1.26778
1776.84	2.53959
1777.86	-1.24487
1778.88	-4.08411
1779.9	3.56164
1780.92	-1.18116
1781.94	2.66059
1782.95	0.761496
1783.97	-0.175665
1784.99	-0.132484
1786.01	-5.8311
1787.03	-1.01395
1788.04	0.918106
1789.06	0.907965
1790.08	0.924551
1791.09	-0.976093
1792.11	0.000905991
1793.13	-1.87849
1794.14	1.98943
1795.16	1.05084
1796.17	0.100603
1797.19	2.98005
1798.21	-0.860695
1799.22	3.95435
1800.24	2.0567
1801.25	1.11524
1802.27	2.10366
1803.28	-0.758303
1804.29	3.11302
1805.31	2.1592
1806.32	-0.720921
1807.34	2.18309
1808.35	-0.703085
1809.36	-0.693586
1810.38	3.18398
1811.39	2.24402
1812.4	1.30577
1813.41	0.351551
1814.43	4.22065
1815.44	2.28737
1816.45	0.370785
1817.46	-1.54676
1818.47	0.403847
1819.49	0.42058
1820.5	0.429379
1821.51	1.40236
1822.52	-3.42492
1823.53	-0.511871
1824.54	4.34217
1825.55	2.41366
1826.56	1.44284
1827.57	0.472942
1828.58	0.482729
1829.59	1.46778
1830.6	6.32702
1831.61	3.41967
1832.62	1.44998
1833.63	2.52428
1834.64	-1.43037
1835.65	-0.493275
1836.65	4.40688
1837.66	-0.462009
1838.67	3.36751
1839.68	1.41296
1840.69	0.455027
1841.7	0.458889
1842.7	2.39185
1843.71	0.498398
1844.72	-1.50017
1845.72	0.435425
1846.73	0.423515
1847.74	0.400768
1848.74	-0.572409
1849.75	2.30822
1850.75	-1.53537
1851.76	-3.47117
1852.76	-1.56859
1853.77	-3.48699
1854.78	-0.617861
1855.78	1.28289
1856.79	-1.602
1857.79	-2.55144
1858.79	2.24477
1859.8	0.321989
1860.8	0.304352
1861.81	-5.43945
1862.81	-1.63996
1863.81	-0.717371
1864.82	1.15706
1865.82	-0.749537
1866.82	-0.752037
1867.83	0.194166
1868.83	-1.71206
1869.83	-0.774033
1870.83	-0.783232
1871.84	-0.800289
1872.84	0.122435
1873.84	-2.74364
1874.84	4.76658
1875.84	4.82572
1876.84	-1.78319
1877.84	2.00009
1878.84	2.91549
1879.84	0.97562
1880.84	-0.905972
1881.84	1.89287
1882.85	-0.915243
1883.85	0.979094
1884.84	-0.932198
1885.84	2.80864
1886.84	-0.035368
1887.84	-0.0278091
1888.84	2.79133
1889.84	-3.80997
1890.84	0.859396
1891.84	-3.85051
1892.83	-0.0926018
1893.83	-1.02482
1894.83	2.74068
1895.83	-1.03443
1896.83	-0.113136
1897.82	-1.06096
1898.82	0.827698
1899.82	2.71563
1900.81	4.58254
1901.81	0.812838
1902.81	-1.07609
1903.8	0.780504
1904.8	1.71308
1905.79	-2.98018
1906.79	0.788563
1907.79	-0.13258
1908.78	-1.07197
1909.78	-2.02301
1910.77	-0.140091
1911.77	2.70343
1912.76	2.7094
1913.76	-1.07878
1914.75	3.61765
1915.74	2.67826
1916.74	-0.130972
1917.73	0.811913
1918.72	-1.06889
1919.72	2.70828
1920.71	-2.03521
1921.7	1.72722
1922.7	-2.99608
1923.69	0.800695
1924.68	0.808857
1925.67	1.75731
1926.66	0.816839
1927.66	-1.06642
1928.65	6.52383
1929.64	-2.03789
1930.63	0.798046
1931.62	2.74472
1932.61	0.886335
1933.61	1.81765
1934.6	1.79199
1935.59	4.62997
1936.58	-2.02779
1937.57	3.6937
1938.56	-2.01293
1939.55	-2.02749
1940.54	0.834131
1941.52	-0.122946
1942.51	-0.11282
1943.5	-4.888
1944.49	2.75354
1945.48	0.8295
1946.47	-0.126474
1947.46	0.846985
1948.44	-1.04774
1949.43	1.84234
1950.42	-0.0791893
1951.41	-1.08572
1952.39	0.80393
1953.38	-1.09122
1954.37	-0.121225
1955.36	-0.118504
1956.34	-0.131853
1957.33	0.810225
1958.31	0.786825
1959.3	0.775702
1960.29	0.769901
1961.27	0.766376
1962.26	-1.16378
1963.24	-0.205437
1964.23	-0.202169
1965.21	0.752419
1966.2	-0.224913
1967.18	1.66306
1968.17	-0.278858
1969.15	-1.24997
1970.14	-0.300934
1971.12	-3.19979
1972.1	-1.29249
1973.09	0.626001
1974.07	-2.2578
1975.05	0.601784
1976.04	0.583679
1977.02	-0.382198
1978	0.556833
1978.98	-2.3337
1979.97	-0.436493
1980.95	0.494965
1981.93	0.477783
1982.91	-1.45326
1983.89	-2.41067
1984.88	1.39303
1985.86	-0.56756
1986.84	1.28778
1987.82	4.14577
1988.8	-0.601967
1989.78	1.27645
1990.76	-0.475718
1991.74	3.63442
1992.72	0.373207
1993.7	-2.17742
1994.68	-0.690882
1995.66	0.197433
1996.64	1.07314
1997.62	1.00338
1998.6	-0.555695
1999.57	0.675735
2000.55	1.27355
2001.53	1.13131
2002.51	0.17128
2003.49	0.441879
2004.47	0.922539
2005.44	-0.478003
2006.42	-0.934103
2007.4	1.25793
2008.38	-0.119982
2009.35	0.16716
2010.33	0.909626
2011.3	-0.301956
2012.18	-3.36583
2013.17	-1.48528
2014.16	3.22849
2015.15	0.386976
2016.14	1.29292
2017.13	-3.40898
2018.11	3.14341
2019.1	0.330391
2020.09	2.184
2021.08	3.09858
2022.06	-1.59808
2023.05	-2.55343
2024.04	-2.52881
2025.02	-1.58317
2026.01	-0.611496
2027	-0.672789
2027.98	1.16352
2028.97	-1.62711
2029.96	-0.672722
2030.94	1.21387
2031.93	-0.704155
2032.91	0.26494
2033.9	-0.67124
2034.88	1.19988
2035.87	-0.681503
2036.85	2.10587
2037.83	0.217531
2038.82	-1.65813
2039.8	-0.736773
2040.79	-0.72546
2041.77	0.212866
2042.75	-0.717876
2043.74	2.10741
2044.72	0.205143
2045.7	1.13374
2046.69	-0.716806
2047.67	0.236248
2048.65	1.1613
2049.63	2.09822
2050.62	1.17788
2051.6	0.25927
2052.58	0.252443
2053.56	-0.689154
2054.54	0.246395
2055.52	-2.54745
2056.5	-0.664297
2057.48	1.20511
2058.46	1.21004
2059.45	-0.658808
2060.43	1.22619
2061.4	1.23514
2062.39	1.25121
2063.37	0.330378
2064.34	0.337957
2065.32	2.22893
2066.3	4.11239
2067.28	-0.601078
2068.26	0.365833
2069.24	-0.552679
2070.22	2.26964
2071.2	1.33121
2072.18	-1.47729
2073.15	1.38214
2074.13	2.32375
2075.11	-1.46171
2076.09	-1.45078
2077.06	2.34817
2078.04	3.3
2079.02	-2.37002
2080	-1.41897
2080.97	0.471487
2081.95	1.41981
2082.93	0.478376
2083.9	2.39017
2084.88	0.508369
2085.85	4.2997
2086.83	0.527889
2087.8	-1.35793
2088.78	-1.34551
2089.75	-0.371826
2090.73	1.55022
2091.7	0.612061
2092.68	2.50735
2093.65	3.45257
2094.63	-0.354128
2095.6	-0.356979
2096.57	-0.355846
2097.55	1.54699
2098.52	-2.23533
2099.5	-2.2309
2100.47	-0.337315
2101.44	2.51435
2102.41	-0.318949
2103.39	-0.303658
2104.36	0.655195
2105.33	1.59374
2106.3	0.637146
2107.27	-1.24972
2108.25	-1.24588
2109.22	0.651308
2110.19	0.661001
2111.16	-0.275604
2112.13	-0.272335
2113.1	1.62694
2114.07	-0.278736
2115.04	-0.278866
2116.01	-0.291399
2116.99	0.646202
2117.96	-0.297773
2118.92	2.56592
2119.9	-0.262678
2120.86	1.64369
2121.83	0.681957
2122.8	1.60379
2123.77	3.48106
2124.74	2.52767
2125.71	1.58226
2126.68	3.47361
2127.65	-0.306168
2128.61	2.52253
2129.58	0.628269
2130.55	0.627741
2131.52	3.46623
2132.48	-1.25014
2133.45	3.45438
2134.42	0.62932
2135.39	1.57668
2136.35	3.47747
2137.32	-3.13807
2138.28	-0.313963
2139.25	-1.25942
2140.22	-3.12134
2141.18	0.603573
2142.15	-0.324755
2143.12	2.49934
2144.08	0.61727
2145.05	1.55195
2146.01	3.42434
2146.98	1.5301
2147.94	-1.28922
2148.9	0.599365
2149.87	0.602837
2150.83	-2.2141
2151.8	-1.29171
2152.76	2.42724
2153.72	0.550869
2154.69	1.49288
2155.65	1.505
2156.61	-1.30161
2157.58	0.554455
2158.54	-1.31588
2159.5	-1.31401
2160.47	-0.382847
2161.43	2.40837
2162.39	-0.389332
2163.35	-0.386448
2164.31	1.46935
2165.27	-0.414272
2166.24	-0.410913
2167.2	0.544769
2168.16	0.550266
2169.12	0.525414
2170.08	-0.410152
2171.04	2.38397
2172	2.39065
2172.96	-1.32651
2173.92	0.528769
2174.88	2.39038
2175.84	-1.33075
2176.8	0.530117
2177.76	1.45981
2178.72	-1.32691
2179.68	-1.33053
2180.64	-0.413643
2181.59	0.505619
2182.55	1.4402
2183.51	0.527695
2184.47	-1.30541
2185.43	1.48311
2186.38	-1.31532
2187.34	1.45465
2188.3	-0.393806
2189.26	-0.386215
2190.21	0.55262
2191.17	1.50715
2192.13	1.51593
2193.08	3.36104
2194.04	1.48347
2195	1.47932
2195.95	-0.359127
2196.91	1.5239
2197.86	-0.301304
2198.82	-3.10628
2199.78	-3.12446
2200.73	1.54213
2201.69	2.52124
2202.64	-0.327303
2203.59	0.605856
2204.55	-1.25409
2205.5	1.55243
2206.46	0.63097
2207.41	-0.297935
2208.37	-0.287285
2209.32	0.658339
2210.27	1.58739
2211.23	0.652485
2212.18	-3.99719
2213.13	-1.19498
2214.09	-1.19791
2215.04	0.669744
2215.99	0.673479
2216.94	2.55234
2217.9	2.55119
2218.85	-1.202
2219.8	-0.274866
2220.75	1.60388
2221.7	1.62407
2222.65	-0.231632
2223.6	1.65452
2224.55	-0.209696
2225.5	-0.213808
2226.46	-1.15698
2227.41	3.54582
2228.36	-0.195423
2229.31	-0.183697
2230.26	-0.173517
2231.21	-1.10693
2232.16	0.764532
2233.11	-0.189581
2234.05	0.751078
2235	0.770245
2235.95	-0.153734
2236.9	-0.153719
2237.85	-0.162245
2238.8	-0.15556
2239.75	-1.09717
2240.69	1.72484
2241.64	-0.166122
2242.59	0.797239
2243.54	-2.97661
2244.48	-1.08129
2245.43	1.75145
2246.38	3.63445
2247.32	1.74004
2248.27	-0.172607
2249.22	-0.179214
2250.16	-0.163675
2251.11	2.69382
2252.06	-0.15093
2253	-0.154589
2253.95	-1.09735
2254.89	-0.143948
2255.84	-1.09535
2256.78	-2.99438
2257.73	1.75889
2258.67	-1.0875
2259.62	0.815722
2260.56	-2.03062
2261.51	-0.105587
2262.45	-2.00636
2263.39	-2.01669
2264.34	0.825001
2265.28	0.804853
2266.22	0.803617
2267.17	1.77395
2268.11	0.827806
2269.05	0.832611
2270	0.829584
2270.94	-0.130598
2271.88	1.78018
2272.82	0.818525
2273.77	-2.04764
2274.71	-1.07781
2275.65	1.81389
2276.59	0.841043
2277.53	-1.10813
2278.47	0.791723
2279.41	1.74723
2280.36	0.798855
2281.3	-0.136889
2282.24	-2.05369
2283.18	0.816538
2284.12	-0.140722
2285.06	2.75899
2286	1.77734
2286.94	-3.06638
2287.88	-2.11566
2288.82	-1.14496
2289.75	1.7505
2290.69	2.72053
2291.63	1.74419
2292.57	3.65109
2293.51	1.70052
2294.45	0.73847
2295.39	-1.1748
2296.32	-3.09602
2297.26	-2.1336
2298.2	-2.13344
2299.14	-2.13659
2300.07	0.750439
2301.01	-1.18469
2301.95	0.751478
2302.89	-1.17787
2303.82	1.72223
2304.76	-0.220476
2305.69	-0.229633
2306.63	1.71059
2307.57	-1.1825
2308.5	1.69726
2309.44	-1.22985
2310.37	3.58827
2311.31	-6.04925
2312.24	2.66957
2313.18	-1.21957
2314.11	-2.20427
2315.05	-1.23102
2315.98	-0.280695
2316.92	2.60397
2317.85	-1.25437
2318.78	-0.276625
2319.72	2.64097
2320.65	1.67744
2321.58	-2.18907
2322.52	0.691235
2323.45	-0.287542
2324.38	-2.22953
2325.32	5.4778
2326.25	6.43595
2327.18	12.2126
2328.11	18.9494
2329.05	5.48715
2329.98	3.54868
2330.91	1.61955
2331.84	-0.311817
2332.77	-2.23079
2333.7	0.659426
2334.63	2.5873
2335.56	-0.292307
2336.5	0.679153
2337.43	-1.23979
2338.36	-0.285709
2339.29	2.58468
2340.22	-0.285583
2341.15	1.64378
2342.08	1.65816
2343.01	-4.08841
2343.93	3.5827
2344.86	2.63843
2345.79	1.70369
2346.72	0.743362
2347.65	-0.249956
2348.58	1.75555
2349.51	-0.190834
2350.44	-2.10919
2351.36	2.67119
2352.29	2.70347
2353.22	-1.09064
2354.15	2.71675
2355.07	-0.120192
2356	0.849379
2356.93	-4.82672
2357.86	1.83357
2358.78	0.898415
2359.71	0.912281
2360.63	-2.85059
2361.56	0.0144749
2362.49	3.82061
2363.41	-1.8386
2364.34	-1.78241
2364.8	0.133339