File: Data/3-Raman/processed/bu19(2)w-a-ff1-fi05-l_150 (500nm)_532nm_edge_100%_x100_vis_lwd_h50um_30sx2_01.txt
#Acq. time (s)=	30
#Accumulations=	2
#Range (cm-¹)=	99...4000
#Windows=	1
#Auto scanning=	Off
#Autofocus=	Off
#Macrospot=	Off
#AutoExposure=	Off
#Spike filter=	Multiple accum.
#Delay time (s)=	2
#Binning=	1
#Readout mode=	Signal
#DeNoise=	Off
#ICS correction=	On
#Dark correction=	Off
#Inst. Process=	Off
#Detector Gain=	Best Dynamic
#Detector ADC=	50 kHz HS
#Detector temperature (°C)=	-60.09
#Instrument=	LabRAM HR Evol
#Detector=	SIN-EM FIVIS
#Objective=	x100_VIS_LWD
#Grating=	150 (500nm)
#ND Filter=	100%
#Laser=	532nm_Edge
#Hole=	49.98
#Temperature=	0
#Range=	Visible
#StageXY=	75x50mm Scan+
#StageZ=	Z motor
#X (µm)=	0
#Y (µm)=	0
#Z (µm)=	-9.8
#Full time(mm:ss)=	1:05
#Project=	21_11_26
#Sample=	BU19(2)w
#Site=
#Title=	BU19(2)w-A-FF1-FI05-L_150 (500nm)_532nm_Edge_100%_x100_VIS_LWD_H50um_30sX2
#Remark=
#Date=	26.11.2021 13:38
#Acquired=	26.11.2021 13:38:16
#Base:Fit=	16.12.2021 16:00:56
#Base:Edit=	16.12.2021 16:06:23
#Base:Sub=	16.12.2021 16:06:27
102.91	1209.59
107.534	4447.29
112.156	4949.84
116.775	2936.09
121.392	1086.72
126.005	1242.2
130.617	3071.99
135.227	6973.74
139.835	14854.6
144.439	22993.7
149.042	21768.3
153.643	13715.6
158.242	7181.7
162.839	3734.64
167.431	1990.73
172.023	990.922
176.613	375.639
181.198	108.628
185.783	0.0151367
190.366	-5.37646
194.947	345.745
199.524	1501.13
204.1	4488.36
208.674	7228.66
213.243	4111.2
217.813	1310.99
222.38	1116.08
226.945	2612.14
231.506	5981.57
236.066	6119.07
240.625	2747.18
245.179	846.297
249.732	247.557
254.284	33.2582
258.831	22.5724
263.378	-0.0274658
267.923	34.8058
272.464	219.187
277.004	733.638
281.54	870.399
286.076	429.706
290.61	211.451
295.139	205.505
299.669	257.6
304.196	381.281
308.718	522.619
313.241	676.331
317.759	946.343
322.278	1480
326.794	2514.03
331.305	3576.4
335.817	3684.06
340.324	3104.54
344.832	3320.09
349.334	4417.74
353.837	4118.69
358.338	2674.84
362.834	2058.7
367.33	1995.16
371.822	2026.99
376.314	2425.2
380.802	3384.75
385.289	5945.93
389.772	9836.57
394.255	11270.2
398.734	9650.67
403.213	7907.02
407.688	6571.72
412.162	5609.5
416.632	5461.96
421.102	5950.68
425.568	6711.94
430.033	6975.75
434.495	6715.12
438.956	6426.36
443.413	6662.03
447.87	7382.19
452.323	7290.74
456.776	6014.51
461.224	4325.37
465.673	3136.65
470.117	2531.2
474.561	2345.79
479.001	2564.69
483.438	3013.5
487.876	3927.45
492.309	5385.82
496.742	7687.78
501.172	10758.9
505.601	13659.7
510.025	14989
514.448	13991.2
518.871	11692.3
523.289	9801.28
527.707	8487.91
532.121	7817.11
536.533	7861.27
540.945	7978.62
545.353	8231.16
549.758	8009.9
554.164	7332.03
558.565	6449.3
562.965	5303.67
567.364	4377.16
571.759	3498.61
576.151	3023.94
580.544	2890.39
584.933	2984.87
589.319	3509.34
593.706	4275.48
598.088	5267.74
602.468	6588.83
606.848	9119.12
611.224	14536.6
615.598	24617.9
619.972	30199.4
624.341	22600.7
628.709	13013
633.074	7360.1
637.44	4842.66
641.801	3277.75
646.16	2440.12
650.517	1758.05
654.874	1348.37
659.227	1064.32
663.578	860.333
667.927	648.886
672.275	514.109
676.62	453.024
680.962	424.964
685.302	433.88
689.643	532.018
693.979	845.084
698.313	1130.63
702.645	1365.28
706.975	1268.79
711.305	962.241
715.631	703.163
719.955	581.209
724.276	578.854
728.596	446.358
732.913	292.817
737.231	118.892
741.544	95.6055
745.856	61.0897
750.165	0.0681152
754.472	-6.79163
758.778	-9.2049
763.081	-15.898
767.384	-6.19708
771.683	24.2208
775.98	8.67609
780.275	39.8253
784.568	48.1453
788.859	107.169
793.147	131.241
797.434	192.157
801.719	204.145
806.004	291.995
810.284	359.577
814.563	527.63
818.839	717.071
823.114	998.082
827.386	1387.92
831.657	1975.78
835.925	2717.81
840.192	3371.27
844.456	3674.18
848.719	3572.92
852.979	2978.34
857.237	2455.08
861.493	2067.95
865.748	1737.04
870	1667.69
874.25	1896.79
878.499	2186.06
882.745	1899.08
886.989	1294.29
891.231	793.674
895.471	550.609
899.71	367.872
903.946	255.657
908.18	211.224
912.412	160.142
916.642	164.098
920.87	127.976
925.096	136.936
929.321	135.671
933.543	160.57
937.763	155.375
941.981	161.766
946.197	214.069
950.412	207.556
954.622	187.623
958.832	228.639
963.04	200.702
967.246	243.132
971.451	296.328
975.653	296.762
979.853	368.418
984.052	511.29
988.248	681.606
992.442	871.048
996.633	1105.26
1000.82	1167.33
1005.01	1105.9
1009.2	943.701
1013.38	804.554
1017.57	764.777
1021.75	715.318
1025.92	835.159
1030.1	981.281
1034.27	1235.91
1038.45	1694.27
1042.62	2295.03
1046.78	2627.86
1050.95	2463.44
1055.12	2410.23
1059.28	2458.93
1063.44	2794.37
1067.6	3338.3
1071.75	4105.98
1075.91	5304.24
1080.06	7408.23
1084.21	10927.1
1088.36	15945.8
1092.51	20560.9
1096.65	19717.8
1100.8	14132.1
1104.94	8544.61
1109.08	5310.68
1113.21	3803.17
1117.35	3107.56
1121.48	2812.47
1125.61	2904.22
1129.74	3273.5
1133.87	4056.87
1137.99	5365.74
1142.12	6628.01
1146.24	6852.43
1150.36	5800.45
1154.48	4319.24
1158.59	3112.61
1162.71	2220.09
1166.82	1639.2
1170.93	1265.34
1175.04	961.296
1179.14	780.004
1183.25	650.426
1187.35	503.243
1191.45	393.797
1195.55	364.31
1199.65	284.588
1203.74	244.75
1207.83	232.476
1211.92	198.018
1216.01	191.053
1220.1	190.241
1224.19	168.435
1228.27	172.954
1232.35	169.717
1236.43	184.038
1240.51	174.769
1244.58	178.295
1248.66	188.061
1252.73	215.164
1256.8	221.435
1260.87	197.812
1264.93	170.216
1269	132.653
1273.06	91.0509
1277.12	96.4658
1281.18	87.7474
1285.23	57.7414
1289.29	70.7958
1293.34	64.6161
1297.39	56.2741
1301.44	46.815
1305.49	56.3444
1309.53	41.5988
1313.58	48.9165
1317.62	36.8486
1321.66	51.824
1325.7	45.4106
1329.73	54.9768
1333.77	64.4265
1337.8	62.61
1341.83	68.676
1345.86	85.6106
1349.88	101.437
1353.91	159.97
1357.93	248.08
1361.95	416.086
1365.97	590.543
1369.99	469.072
1374	234.595
1378.02	132.856
1382.03	79.6467
1386.04	58.1952
1390.05	15.1541
1394.05	15.5001
1398.06	-8.64383
1402.06	-4.32144
1406.06	-9.91821
1410.06	-0.745209
1414.05	-12.2876
1418.05	-3.16876
1422.04	-7.91992
1426.03	5.98825
1430.02	-3.06015
1434.01	15.5237
1438	6.40524
1441.98	1.19272
1445.96	3.77386
1449.94	15.1665
1453.92	-6.11176
1457.9	1.13922
1461.87	14.1836
1465.85	5.39178
1469.82	10.3163
1473.78	-22.0772
1477.75	4.37061
1481.72	5.19547
1485.68	2.0405
1489.65	-8.0097
1493.61	2.44684
1497.56	26.4912
1501.52	21.2713
1505.47	14.1425
1509.43	8.05563
1513.38	22.3595
1517.33	21.0946
1521.27	43.1172
1525.22	25.3417
1529.16	32.7756
1533.11	40.212
1537.05	36.9545
1540.98	32.7018
1544.92	53.6076
1548.86	55.0946
1552.79	55.5748
1556.72	45.3199
1560.65	68.8654
1564.58	80.7003
1568.5	73.108
1572.43	78.0255
1576.35	90.6224
1580.27	91.5728
1584.19	138.763
1588.1	120.299
1592.02	137.44
1595.93	148.743
1599.84	164.802
1603.75	190.443
1607.66	170.039
1611.57	212.931
1615.47	213.614
1619.37	224.878
1623.27	234.157
1627.17	227.213
1631.07	235.627
1634.97	219.297
1638.86	227.802
1642.75	218.225
1646.64	202.013
1650.53	205.94
1654.42	178.207
1658.3	177.255
1662.18	177.22
1666.07	160.733
1669.94	147.047
1673.82	114.934
1677.7	126.997
1681.57	122.479
1685.44	106.325
1689.31	100.697
1693.18	89.2366
1697.05	98.7767
1700.92	87.1967
1704.78	88.9079
1708.64	95.2763
1712.5	87.2803
1716.36	69.8293
1720.21	90.2802
1724.07	80.4416
1727.92	89.4356
1731.77	88.9202
1735.62	102.489
1739.47	108.457
1743.32	107.805
1747.16	124.856
1751.01	124.412
1754.85	161.232
1758.69	165.752
1762.52	164.498
1766.36	139.711
1770.19	129.915
1774.02	97.9778
1777.85	82.7311
1781.68	75.9481
1785.51	50.525
1789.33	34.3981
1793.16	51.0084
1796.98	37.6496
1800.8	51.4817
1804.62	35.9668
1808.43	26.9813
1812.25	38.6776
1816.06	21.0876
1819.87	28.8235
1823.68	1.56641
1827.49	28.9751
1831.3	7.24741
1835.1	24.1006
1838.9	9.80914
1842.71	-0.739044
1846.51	14.967
1850.3	3.46594
1854.1	11.5337
1857.89	-2.00003
1861.69	4.95367
1865.48	9.05298
1869.27	13.1628
1873.05	4.31567
1876.84	26.0781
1880.62	27.4761
1884.4	28.0764
1888.19	35.1339
1891.96	28.7293
1895.74	26.0204
1899.52	35.2755
1903.29	27.1824
1907.06	31.1147
1910.83	38.7694
1914.6	37.3325
1918.37	31.3029
1922.13	36.5504
1925.9	29.8088
1929.66	19.3869
1933.42	30.3422
1937.18	36.6787
1940.94	26.2287
1944.69	49.4103
1948.44	56.7521
1952.2	65.7388
1955.95	75.5504
1959.69	99.2867
1963.44	103.184
1967.19	142.75
1970.93	171.842
1974.67	211.991
1978.41	233.237
1982.15	250.611
1985.89	264.119
1989.62	298.99
1993.35	280.578
1997.09	291.876
2000.82	263.139
2004.55	271.585
2008.27	240.22
2012	225.469
2015.72	220.009
2019.44	175.348
2023.16	152.155
2026.88	170.493
2030.6	154.049
2034.31	145.149
2038.03	121.756
2041.74	106.568
2045.45	110.584
2049.16	85.3175
2052.86	77.5223
2056.57	76.1646
2060.27	74.9883
2063.98	68.5195
2067.67	52.9211
2071.37	59.4146
2075.07	37.3293
2078.77	60.5043
2082.46	37.4712
2086.15	54.2327
2089.84	36.3051
2093.53	52.6061
2097.22	41.1916
2100.9	27.8597
2104.59	46.9842
2108.27	35.3729
2111.95	47.9045
2115.63	21.3845
2119.31	12.5107
2122.98	36.9781
2126.66	29.8079
2130.33	43.9297
2134	31.1605
2137.67	23.0357
2141.34	33.3539
2145	38.0768
2148.67	28.9771
2152.33	39.1964
2155.99	28.3177
2159.65	12.919
2163.31	32.3367
2166.96	12.5104
2170.62	0.0812073
2174.27	9.64796
2177.92	6.52322
2181.57	12.5431
2185.22	4.00017
2188.87	10.088
2192.51	10.8242
2196.15	9.85123
2199.8	1.65002
2203.44	11.7064
2207.07	7.22064
2210.71	0.0282898
2214.35	-8.06226
2217.98	4.92871
2221.61	-13.2549
2225.24	-13.0835
2228.87	-3.71266
2232.5	-19.2154
2236.12	-20.8839
2239.75	-0.346848
2243.37	-8.48755
2246.99	-29.6597
2250.61	-9.96663
2254.23	-18.1306
2257.85	-9.50368
2261.46	-10.1992
2265.07	-6.24019
2268.68	-12.5637
2272.29	-20.7414
2275.9	-13.9398
2279.51	-10.9476
2283.11	-23.19
2286.72	-15.6205
2290.32	-21.2736
2293.92	-24.1237
2297.52	-22.2386
2301.11	-17.5019
2304.71	-20.3736
2308.3	-13.8115
2311.9	-12.0142
2315.49	6.8147
2319.08	2.85684
2322.66	-3.04201
2326.25	-20.4174
2329.84	-22.6484
2333.42	-6.95789
2337	-13.0195
2340.58	-18.1476
2344.16	-7.29985
2347.73	-15.2787
2351.31	-11.0665
2354.88	-1.26958
2358.45	-0.851669
2362.03	-11.6224
2365.59	-7.48363
2369.16	0.362427
2372.73	-3.80708
2376.29	-14.4485
2379.85	-4.74857
2383.41	-5.19118
2386.97	-19.4124
2390.53	-25.2966
2394.09	-6.35791
2397.64	-7.57231
2401.2	-11.4737
2404.75	-9.7771
2408.3	-8.06195
2411.85	-10.8583
2415.39	-9.94919
2418.94	-7.16344
2422.48	1.17052
2426.03	0.349899
2429.57	6.95105
2433.11	9.90651
2436.64	-0.99707
2440.18	6.64072
2443.72	-8.03337
2447.25	0.55278
2450.78	-3.89417
2454.31	-7.408
2457.84	-10.1282
2461.37	2.98683
2464.89	1.96141
2468.42	6.42471
2471.94	-9.73529
2475.46	4.9398
2478.98	2.58141
2482.5	12.499
2486.01	-5.93178
2489.53	-8.45189
2493.04	16.3584
2496.55	12.8486
2500.06	6.59377
2503.57	0.283295
2507.08	10.76
2510.58	5.30128
2514.09	9.16727
2517.59	19.5547
2521.09	21.5845
2524.59	6.79716
2528.09	7.94356
2531.59	8.19679
2535.08	12.1543
2538.58	14.3022
2542.07	7.25121
2545.56	16.8824
2549.05	14.5827
2552.54	19.6662
2556.02	15.5403
2559.51	14.2582
2562.99	14.813
2566.47	24.7346
2569.95	13.299
2573.43	11.1827
2576.91	2.50854
2580.38	18.2414
2583.85	6.71225
2587.33	7.38817
2590.8	8.00177
2594.27	8.50441
2597.74	15.6283
2601.2	19.9532
2604.67	21.3884
2608.13	15.9833
2611.59	2.70584
2615.06	3.67499
2618.51	7.57106
2621.97	34.4357
2625.43	19.9232
2628.88	13.9868
2632.33	1.28064
2635.79	6.75423
2639.24	12.1425
2642.69	12.6745
2646.13	10.2767
2649.58	7.84868
2653.02	12.0333
2656.47	8.51953
2659.91	15.3979
2663.35	24.0927
2666.79	14.7506
2670.22	13.9039
2673.66	16.7849
2677.09	10.2738
2680.52	10.3448
2683.95	6.6904
2687.39	5.88388
2690.81	-2.28812
2694.24	5.42519
2697.66	-2.76506
2701.09	2.09561
2704.51	15.3017
2707.93	9.87964
2711.35	3.6337
2714.77	-1.67514
2718.18	7.91754
2721.6	1.69066
2725.01	2.91318
2728.42	7.86259
2731.84	0.651062
2735.24	3.68338
2738.65	11.3812
2742.06	3.1098
2745.46	-1.48677
2748.86	-14.6023
2752.27	-2.37422
2755.67	-5.22893
2759.07	6.92645
2762.46	3.05556
2765.86	2.86867
2769.25	3.5631
2772.65	-4.28758
2776.04	0.0632172
2779.43	-4.13057
2782.82	-3.67343
2786.2	-11.7335
2789.59	-5.71753
2792.98	3.0714
2796.36	-4.15935
2799.74	-9.53726
2803.12	-14.9748
2806.5	-1.68907
2809.88	-4.38522
2813.25	-1.50906
2816.63	-7.09999
2820	-0.578354
2823.37	-2.46803
2826.74	-7.15817
2830.11	-3.47116
2833.48	-9.11006
2836.84	-3.55989
2840.21	1.99313
2843.57	11.2866
2846.93	1.97197
2850.29	-3.56796
2853.65	-13.7604
2857.01	4.00247
2860.36	-8.12616
2863.72	-3.42749
2867.07	8.76126
2870.42	-4.38527
2873.77	4.94109
2877.12	15.1911
2880.47	8.48141
2883.81	9.259
2887.16	6.21481
2890.5	-10.0868
2893.84	0.939819
2897.18	-7.96497
2900.52	3.86087
2903.86	4.26852
2907.19	6.50259
2910.53	6.78781
2913.86	11.7508
2917.19	28.9609
2920.52	12.0295
2923.85	30.9945
2927.18	14.9043
2930.51	36.5453
2933.83	27.8696
2937.15	42.7101
2940.48	43.3484
2943.8	54.3129
2947.11	52.0565
2950.43	52.6004
2953.75	45.5739
2957.06	46.0482
2960.38	32.4647
2963.69	53.6106
2967	52.2163
2970.31	47.1526
2973.62	71.2039
2976.92	80.2353
2980.23	83.6793
2983.53	79.5387
2986.84	93.2289
2990.14	118.191
2993.44	114.979
2996.73	109.884
3000.03	117.004
3003.33	109.99
3006.62	136.815
3009.91	134.5
3013.2	154.786
3016.49	160.006
3019.78	150.109
3023.07	190.164
3026.35	191.544
3029.64	196.688
3032.92	217.866
3036.2	229.559
3039.48	223.253
3042.76	261.392
3046.04	272.107
3049.32	280.923
3052.59	250.875
3055.86	325.077
3059.14	357.566
3062.41	330.044
3065.68	361.43
3068.94	387.965
3072.21	417.15
3075.48	449.331
3078.74	462.452
3082	461.982
3085.26	510.657
3088.52	522.305
3091.78	543.726
3095.04	601.371
3098.29	574.015
3101.55	633.836
3104.8	675.387
3108.05	696.557
3111.3	742.312
3114.55	791.49
3117.8	812.215
3121.04	824.399
3124.29	869.911
3127.53	909.687
3130.77	974.198
3134.02	1006.33
3137.25	1043.19
3140.49	1110.47
3143.73	1142.44
3146.96	1148.68
3150.2	1191.26
3153.43	1261.53
3156.66	1321.25
3159.89	1353.35
3163.12	1410.21
3166.35	1515.74
3169.57	1519.93
3172.8	1585.04
3176.02	1674.84
3179.24	1687.16
3182.46	1741.4
3185.68	1759.42
3188.9	1849.62
3192.12	1815.77
3195.33	1911.53
3198.55	2002.43
3201.76	1974.16
3204.97	2050.75
3208.18	2104.53
3211.39	2179.36
3214.6	2218.19
3217.8	2230.57
3221.01	2318.11
3224.21	2291.59
3227.41	2319.6
3230.61	2400.96
3233.81	2397.88
3237.01	2463.13
3240.21	2522.44
3243.4	2543.88
3246.59	2594.1
3249.79	2570.05
3252.98	2671.22
3256.17	2683.88
3259.36	2760.45
3262.54	2827.07
3265.73	2824.46
3268.92	2890.15
3272.1	2916.33
3275.28	2949.96
3278.46	2996.9
3281.64	3060.26
3284.82	3070.41
3288	3144.56
3291.17	3218.32
3294.35	3236.12
3297.52	3300.44
3300.69	3320.04
3303.86	3411.97
3307.03	3549.39
3310.2	3542.67
3313.36	3712.05
3316.53	3810.66
3319.69	3848.31
3322.85	3931.23
3326.02	3963.89
3329.18	4219.84
3332.33	4357.34
3335.49	4387.31
3338.65	4485.68
3341.8	4606.99
3344.95	4801.88
3348.11	4898.1
3351.26	5106.94
3354.41	5250.66
3357.56	5364.01
3360.7	5539.94
3363.85	5646.97
3366.99	5889.08
3370.13	5924.19
3373.28	6163.49
3376.42	6332.08
3379.56	6509.7
3382.69	6735.14
3385.83	6981.31
3388.97	7155.62
3392.1	7379.51
3395.23	7589.1
3398.36	7867.82
3401.49	8184.96
3404.62	8549.06
3407.75	8948.07
3410.88	9258.18
3414	9773.37
3417.13	10188.9
3420.25	10692.1
3423.37	11270.4
3426.49	11847.8
3429.61	12534.1
3432.73	13264.7
3435.84	14025.8
3438.96	14847.3
3442.07	16203.9
3445.18	18011.8
3448.29	20861
3451.4	25611
3454.51	30031.7
3457.62	30010.6
3460.72	29985.3
3463.83	29803.1
3466.93	24842
3470.03	21472.7
3473.13	19449
3476.23	18144
3479.33	17497.2
3482.43	17122.7
3485.53	16901.4
3488.62	16783.7
3491.71	16770
3494.81	16752.7
3497.9	16847.1
3500.99	16998.7
3504.07	17008.5
3507.16	17427.2
3510.25	17866.2
3513.33	18310.1
3516.41	18926.6
3519.5	19765.1
3522.58	21020.5
3525.66	22169.9
3528.73	23596
3531.81	24850.4
3534.89	26037.6
3537.96	26518.1
3541.03	26076.1
3544.11	24404.4
3547.18	22056.7
3550.25	19185.7
3553.32	16284.3
3556.38	13811.7
3559.45	11622
3562.51	9954.38
3565.58	8595.44
3568.64	7476.82
3571.7	6613.18
3574.76	5844.03
3577.82	5362.46
3580.87	4824.4
3583.93	4411.14
3586.98	4133.13
3590.04	3784.13
3593.09	3505.84
3596.14	3361.32
3599.19	3146.49
3602.24	2949.89
3605.29	2830.77
3608.33	2672.78
3611.38	2566.09
3614.42	2408.4
3617.46	2328.32
3620.5	2216.49
3623.54	2114.46
3626.58	2018.4
3629.62	1918.93
3632.65	1790.3
3635.69	1620.35
3638.72	1541.62
3641.76	1441.72
3644.79	1299.86
3647.82	1166.18
3650.84	1097.86
3653.87	960.293
3656.9	876.099
3659.92	774.254
3662.95	721.098
3665.97	607.344
3668.99	551.321
3672.01	481.535
3675.03	403.339
3678.05	385.629
3681.07	300.043
3684.08	283.362
3687.1	221.368
3690.11	178.337
3693.12	161.872
3696.13	97.1507
3699.14	89.1316
3702.15	68.0983
3705.16	30.0215
3708.16	-1.39392
3711.17	-2.45178
3714.17	-15.8623
3717.17	-74.0164
3720.17	-81.6521
3723.17	-89.3127
3726.17	-119.815
3729.17	-136.029
3732.16	-143.652
3735.16	-160.788
3738.15	-140.782
3741.14	-195.019
3744.13	-168.338
3747.13	-171.14
3750.11	-193.892
3753.1	-208.99
3756.09	-222.111
3759.07	-235.137
3762.06	-249.05
3765.04	-230.705
3768.02	-235.987
3771	-226.032
3773.98	-243.416
3776.96	-229.51
3779.94	-257.121
3782.91	-235.524
3785.89	-258.277
3788.86	-232.808
3791.83	-233.723
3794.8	-215.669
3797.77	-242.863
3800.74	-238.866
3803.71	-238.578
3806.68	-218.423
3809.64	-219.023
3812.61	-221.486
3815.57	-225.833
3818.53	-233.016
3821.49	-222.216
3824.45	-217.089
3827.41	-189.209
3830.36	-195.44
3833.32	-189.372
3836.27	-188.983
3839.23	-189.562
3842.18	-171.167
3845.13	-175.62
3848.08	-178.214
3851.03	-144.643
3853.98	-139.66
3856.92	-149.991
3859.87	-121.237
3862.81	-124.049
3865.75	-117.391
3868.7	-126.124
3871.64	-103.355
3874.57	-95.0355
3877.51	-95.4497
3880.45	-66.2305
3883.39	-69.7849
3886.32	-66.7619
3889.25	-59.0655
3892.18	-63.996
3895.12	-54.6371
3898.05	-47.3684
3900.97	-59.5008
3903.9	-46.7756
3906.83	-32.3126
3909.75	-49.6796
3912.68	-41.2778
3915.6	-32.1105
3918.52	-28.8977
3921.44	-16.2003
3924.36	-43.1081
3927.28	-11.6937
3930.2	-16.9711
3933.11	-18.6229
3936.03	-26.1494
3938.94	-8.92758
3941.86	-10.0683
3944.77	-7.6441
3947.68	-6.40182
3950.59	6.11185
3953.49	-4.58981
3956.4	7.43695
3959.31	4.85236
3962.21	-21.9607
3965.12	14.1962
3968.02	1.18732
3970.92	19.5324
3973.82	3.02652
3976.72	10.1747
3979.61	40.9846
3982.51	-2.55865
3985.41	23.6824
3988.3	7.24161
3991.19	5.78891
3994.09	8.71442
3996.98	5.53174
3999.87	-0.958984