File: Data/3-Raman/processed/bu19w-e-ff11b-fi02-v_150 (500nm)_532nm_edge_100%_x100_vis_h50um_30sx2_01_0.txt
#Acq. time (s)=	30
#Accumulations=	2
#Range (cm-¹)=	100...5000
#Windows=	1
#Auto scanning=	Off
#Autofocus=	Off
#Macrospot=	Off
#AutoExposure=	Off
#Spike filter=	Multiple accum.
#Delay time (s)=	2
#Binning=	1
#Readout mode=	Signal
#DeNoise=	Off
#ICS correction=	On
#Dark correction=	Off
#Inst. Process=	Off
#Detector Gain=	Best Dynamic
#Detector ADC=	50 kHz HS
#Detector temperature (°C)=	-60.09
#Instrument=	LabRAM HR Evol
#Detector=	SIN-EM FIVIS
#Objective=	x100_VIS
#Grating=	150 (500nm)
#ND Filter=	100%
#Laser=	532nm_Edge
#Hole=	49.98
#Temperature=	0
#Range=	Visible
#StageXY=	75x50mm Scan+
#StageZ=	Z motor
#X (µm)=	0
#Y (µm)=	0
#Z (µm)=	-251.2
#Full time(mm:ss)=	1:04
#Project=	21_11_04
#Sample=	BU19w
#Site=
#Title=	BU19w-E-FF11b-FI02-V_150 (500nm)_532nm_Edge_100%_x100_VIS_H50um_30sX2
#Remark=
#Date=	04.11.2021 18:20
#Acquired=	04.11.2021 18:20:45
#Base:Fit=	16.12.2021 17:39:50
#Base:Edit=	16.12.2021 17:46:41
#Base:Edit=	16.12.2021 17:46:42
#Base:Edit=	16.12.2021 17:46:54
#Base:Edit=	16.12.2021 17:46:56
#Base:Edit=	16.12.2021 17:46:57
#Base:Edit=	16.12.2021 17:46:58
#Base:Edit=	16.12.2021 17:46:58
#Base:Edit=	16.12.2021 17:46:59
#Base:Edit=	16.12.2021 17:47:00
#Base:Edit=	16.12.2021 17:47:00
#Base:Edit=	16.12.2021 17:47:04
#Base:Sub=	16.12.2021 17:47:09
101.869	6344.22
106.493	5845.46
111.113	5939.58
115.732	7291.46
120.349	7821.31
124.964	6040.56
129.577	4261.5
134.185	3622.44
138.793	3310.53
143.399	3029.36
148.003	2794.29
152.602	2601.56
157.201	2510.07
161.798	2504.69
166.392	2602.23
170.982	2785.37
175.572	3230.34
180.16	3989.64
184.745	5249.04
189.326	6738.15
193.907	7993.35
198.486	8123.98
203.06	7126.01
207.634	5552.12
212.206	4134.41
216.776	3111.24
221.341	2362.6
225.906	1845.37
230.469	1573.99
235.028	1386.02
239.586	1160.49
244.142	1047.41
248.694	1230.81
253.246	1579.44
257.795	1585.55
262.341	969.263
266.886	550.871
271.428	397.71
275.967	340.567
280.505	261.725
285.041	203.733
289.573	190.894
294.105	143.078
298.632	115.684
303.159	62.4636
307.685	79.312
312.205	71.6321
316.726	33.9927
321.242	-0.680969
325.758	16.3982
330.272	10.0085
334.782	4.79211
339.292	272.042
343.797	899.803
348.302	973.599
352.803	452.561
357.304	128.581
361.802	9.6192
366.297	-10.605
370.791	-12.4388
375.281	-7.28027
379.77	0.954956
384.256	135.641
388.741	233.356
393.223	355.955
397.704	258.029
402.18	67.2365
406.657	19.478
411.13	33.0685
415.602	74.41
420.07	109.177
424.538	150.805
429.002	296.032
433.465	589.051
437.925	1219.88
442.384	2551.48
446.839	6220.67
451.294	14643
455.745	21636.1
460.196	17463.5
464.642	8567.42
469.089	4003.27
473.531	2338.23
477.971	1520.9
482.411	1092.26
486.846	816.041
491.282	635.026
495.713	613.648
500.144	578.252
504.572	492.588
508.997	496.249
513.421	347.339
517.842	245.992
522.263	184.273
526.679	162.145
531.093	121.671
535.507	104.502
539.917	114.004
544.327	71.3483
548.733	64.6207
553.137	67.1102
557.54	33.2681
561.94	42.1936
566.337	43.2475
570.734	40.1613
575.127	30.949
579.518	38.6157
583.909	33.4797
588.295	64.0562
592.68	39.6879
597.064	37.0214
601.445	4.78638
605.823	9.36505
610.201	11.7816
614.575	34.2203
618.947	48.5854
623.317	36.3148
627.686	37.692
632.052	3.04953
636.415	45.7172
640.777	13.1509
645.138	47.8307
649.495	39.9262
653.85	37.4163
658.205	54.2896
662.556	71.3361
666.905	63.1022
671.252	53.6302
675.597	75.5334
679.941	134.321
684.282	176.872
688.62	245.774
692.957	198.132
697.293	147.312
701.625	95.4937
705.955	77.3351
710.283	72.4238
714.609	82.9957
718.933	79.5847
723.257	115.053
727.577	88.6664
731.894	74.0304
736.21	109.671
740.524	114.852
744.835	105.51
749.147	121.339
753.454	100.316
757.759	122.839
762.063	158.707
766.364	157.968
770.663	178.405
774.96	186.521
779.257	238.38
783.55	318.886
787.841	448.234
792.13	522.367
796.417	716.728
800.702	811.92
804.985	541.65
809.266	340.02
813.545	252.803
817.821	197.514
822.096	202.614
826.371	203.427
830.641	189.914
834.91	187.354
839.176	170.344
843.441	180.775
847.703	147.921
851.964	157.67
856.222	146.405
860.479	143.897
864.733	154.454
868.986	159.244
873.236	124.302
877.485	157.26
881.731	162.567
885.975	165.375
890.218	147.1
894.458	155.722
898.696	138.032
902.933	150.999
907.167	128.479
911.399	157.149
915.63	113.64
919.858	146.736
924.084	126.719
928.308	83.7291
932.531	101.665
936.749	84.0841
940.967	89.9235
945.184	96.7125
949.398	72.4471
953.61	64.3525
957.821	75.4589
962.029	46.1707
966.236	29.7151
970.44	39.8413
974.642	45.7838
978.843	27.3748
983.041	32.3577
987.236	25.667
991.43	20.0286
995.623	15.7523
999.813	9.63547
1004	21.6241
1008.19	3.9483
1012.37	5.39465
1016.55	12.0329
1020.73	42.1292
1024.91	2.81216
1029.09	10.234
1033.27	1.51813
1037.44	35.0388
1041.61	16.979
1045.78	26.6273
1049.94	46.6925
1054.11	99.4255
1058.27	149.635
1062.43	174.092
1066.59	249.741
1070.75	412.936
1074.9	502.861
1079.05	297.32
1083.2	136.489
1087.35	65.8077
1091.5	49.3363
1095.65	33.1299
1099.79	23.3676
1103.93	16.7734
1108.07	4.24225
1112.21	6.31821
1116.34	10.4702
1120.48	6.12674
1124.61	8.43857
1128.74	-1.32605
1132.86	12.6088
1136.99	37.7591
1141.11	48.563
1145.23	121.279
1149.35	238.401
1153.47	265.666
1157.59	187.402
1161.7	89.3457
1165.82	29.2792
1169.92	-13.3289
1174.03	2.72141
1178.14	-2.96545
1182.24	-4.52866
1186.35	-2.08484
1190.45	-24.5539
1194.55	-13.2748
1198.64	-7.29517
1202.74	5.66302
1206.83	15.4699
1210.92	29.3047
1215.01	46.1422
1219.1	92.1693
1223.18	91.8407
1227.27	124.738
1231.35	103.707
1235.43	100.175
1239.5	152.064
1243.58	155.815
1247.65	197.739
1251.72	395.84
1255.8	515.389
1259.86	418.381
1263.93	324.407
1267.99	533.81
1272.06	2311.43
1276.12	4085.06
1280.18	2360.76
1284.23	649.65
1288.29	292.814
1292.34	239.496
1296.39	235.378
1300.44	167.735
1304.49	175.544
1308.53	182.311
1312.58	154.776
1316.62	158.275
1320.66	151.566
1324.7	145.685
1328.73	165.829
1332.77	170.865
1336.8	168.66
1340.83	173.367
1344.86	210.967
1348.88	187.618
1352.91	222.114
1356.93	274.426
1360.95	368.17
1364.97	395.406
1368.99	437.577
1373.01	1249.81
1377.02	5106.28
1381.03	6166.94
1385.04	2504.93
1389.05	590.775
1393.06	371.446
1397.06	566.979
1401.06	773.498
1405.06	507.138
1409.06	274.24
1413.06	201.981
1417.05	195.799
1421.05	186.661
1425.04	132.028
1429.03	106.725
1433.01	103.171
1437	103.615
1440.99	106.043
1444.97	46.2352
1448.95	59.4528
1452.93	67.6708
1456.9	55.1288
1460.88	48.4471
1464.85	66.2298
1468.82	54.4501
1472.79	69.3096
1476.76	67.425
1480.73	75.281
1484.69	55.6996
1488.65	50.8098
1492.61	72.3391
1496.57	71.4352
1500.53	51.1331
1504.48	56.2802
1508.43	99.4919
1512.39	49.4772
1516.33	82.0801
1520.28	63.3039
1524.23	54.3015
1528.17	86.0865
1532.11	86.9214
1536.05	97.4867
1539.99	72.2221
1543.93	88.6521
1547.86	62.4639
1551.8	70.2038
1555.73	70.1468
1559.66	86.477
1563.58	87.2587
1567.51	94.7663
1571.44	89.6695
1575.36	85.5469
1579.28	88.1785
1583.2	94.6597
1587.11	74.1261
1591.03	104.642
1594.94	83.171
1598.85	76.1641
1602.76	82.6642
1606.67	87.33
1610.58	92.9827
1614.48	69.922
1618.38	89.1187
1622.29	42.2151
1626.18	48.0696
1630.08	39.648
1633.98	16.0694
1637.87	52.7998
1641.76	38.9088
1645.65	8.83743
1649.54	3.70941
1653.43	12.0348
1657.31	14.5798
1661.2	0.776489
1665.08	2.25943
1668.96	-14.5755
1672.83	4.03201
1676.71	-11.0454
1680.58	-19.5935
1684.46	-33.0533
1688.33	-20.6284
1692.2	-28.4224
1696.06	-28.6035
1699.93	-46.0403
1703.79	-19.6339
1707.66	-32.4299
1711.52	-38.6059
1715.37	-39.0688
1719.23	-33.8319
1723.08	-38.041
1726.94	-30.0125
1730.79	-35.2362
1734.64	-27.2812
1738.49	-31.5575
1742.33	-41.462
1746.18	-51.3001
1750.02	-53.4498
1753.86	-46.1622
1757.7	-51.6724
1761.54	-41.7601
1765.37	-26.4505
1769.21	-44.4869
1773.04	-34.4724
1776.87	-32.7957
1780.7	-44.9878
1784.53	-30.085
1788.35	-41.2813
1792.17	-35.6481
1796	-40.3166
1799.82	-31.869
1803.64	-23.6282
1807.45	-42.7469
1811.27	-38.3807
1815.08	-18.9893
1818.89	-22.3909
1822.7	-25.9077
1826.51	-12.521
1830.32	-31.3129
1834.12	-15.3223
1837.92	-19.1998
1841.72	-7.14706
1845.52	-19.6372
1849.32	-11.4302
1853.12	-12.7733
1856.91	-20.769
1860.7	-16.7237
1864.5	-18.3347
1868.28	-15.2687
1872.07	-0.134766
1875.86	-13.6621
1879.64	-16.036
1883.42	-9.04776
1887.21	-5.73886
1890.98	-2.0545
1894.76	-13.9721
1898.54	-3.82025
1902.31	-18.3772
1906.08	1.18826
1909.85	2.37634
1913.62	-0.00485229
1917.39	-2.3681
1921.16	-2.68472
1924.92	10.0036
1928.68	-9.69269
1932.44	-8.991
1936.2	5.66577
1939.96	13.8162
1943.71	-9.82809
1947.47	17.0391
1951.22	8.01285
1954.97	6.31772
1958.72	14.7509
1962.46	14.5803
1966.21	11.5558
1969.95	30.9464
1973.7	9.81607
1977.43	25.1779
1981.17	28.2605
1984.91	9.76605
1988.65	22.0569
1992.38	40.7632
1996.11	13.7516
1999.84	21.097
2003.57	23.7758
2007.3	27.3343
2011.02	24.311
2014.75	32.3347
2018.47	26.7117
2022.19	25.8915
2025.91	34.437
2029.62	27.4517
2033.34	37.9776
2037.05	22.1255
2040.76	31.8413
2044.47	39.6947
2048.18	30.1333
2051.89	38.9485
2055.59	34.0418
2059.3	40.2864
2063	33.0148
2066.7	34.0818
2070.4	23.1952
2074.1	37.1787
2077.79	27.1833
2081.49	39.3979
2085.18	36.752
2088.87	48.543
2092.56	41.5039
2096.25	45.7874
2099.93	59.3229
2103.61	38.2906
2107.3	32.989
2110.98	27.6163
2114.66	39.8813
2118.33	53.9439
2122.01	42.7566
2125.68	63.9513
2129.36	44.2581
2133.03	28.2584
2136.7	49.24
2140.36	71.9348
2144.03	44.7209
2147.7	45.1554
2151.36	41.8962
2155.02	38.6495
2158.68	39.0792
2162.34	40.4522
2165.99	40.9588
2169.65	36.0483
2173.3	47.6782
2176.95	26.6074
2180.6	41.0822
2184.25	21.8701
2187.9	48.2114
2191.54	45.5886
2195.18	44.0164
2198.83	33.4175
2202.47	22.8296
2206.11	37.8277
2209.74	21.8357
2213.38	30.5586
2217.01	54.9066
2220.64	31.5797
2224.27	17.3864
2227.9	27.0692
2231.53	51.5349
2235.16	36.3717
2238.78	48.9087
2242.4	33.6555
2246.02	31.3311
2249.64	47.6021
2253.26	39.7423
2256.88	24.417
2260.49	52.9617
2264.11	55.3332
2267.72	40.8509
2271.33	53.6505
2274.93	32.5094
2278.54	45.1251
2282.15	41.4866
2285.75	36.8462
2289.35	45.4367
2292.95	42.6278
2296.55	42.6545
2300.15	32.2751
2303.74	41.7176
2307.34	61.5045
2310.93	64.1731
2314.52	96.1616
2318.11	398.173
2321.7	742.482
2325.28	412.757
2328.87	148.818
2332.45	46.9155
2336.03	53.6545
2339.61	33.9545
2343.19	42.4693
2346.77	54.6561
2350.34	26.4844
2353.92	25.506
2357.49	37.5681
2361.06	37.4457
2364.63	25.2277
2368.2	32.5557
2371.76	27.9003
2375.33	39.8829
2378.89	30.5936
2382.45	38.8849
2386.01	23.2664
2389.57	39.9048
2393.13	26.2929
2396.68	31.1522
2400.23	31.5483
2403.79	36.725
2407.34	32.803
2410.88	33.6055
2414.43	18.9092
2417.98	27.2414
2421.52	31.9765
2425.06	10.0888
2428.61	26.0677
2432.14	13.5128
2435.68	24.1568
2439.22	21.8866
2442.75	26.1534
2446.29	-7.81491
2449.82	38.5908
2453.35	16.8163
2456.88	11.6501
2460.4	23.0979
2463.93	34.512
2467.45	-0.559235
2470.98	11.7458
2474.5	25.4507
2478.02	-4.38998
2481.54	26.2062
2485.05	14.2529
2488.57	0.223022
2492.08	10.8072
2495.59	5.26541
2499.1	24.1789
2502.61	13.0188
2506.12	34.5038
2509.63	0.836853
2513.13	22.2061
2516.63	24.0848
2520.13	13.9709
2523.63	10.1145
2527.13	2.94052
2530.63	6.04358
2534.12	33.1953
2537.62	12.4547
2541.11	0.113037
2544.6	11.0175
2548.09	11.9529
2551.58	-5.57776
2555.06	20.4349
2558.55	-0.533539
2562.03	-3.00961
2565.51	11.4127
2568.99	10.1744
2572.47	-0.31073
2575.95	11.7147
2579.43	2.27069
2582.9	13.5412
2586.37	26.7814
2589.84	16.3058
2593.31	7.47766
2596.78	-10.0396
2600.25	1.13184
2603.71	6.60141
2607.18	-12.0846
2610.64	5.37277
2614.1	13.9125
2617.56	18.7964
2621.02	-1.46484
2624.47	6.0751
2627.93	-5.6991
2631.38	8.40991
2634.83	16.6624
2638.28	18.0785
2641.73	22.3021
2645.18	5.40204
2648.62	-5.73532
2652.07	9.77515
2655.51	5.1586
2658.95	21.3714
2662.39	21.3748
2665.83	-3.22662
2669.27	8.11368
2672.7	-6.01511
2676.14	10.0157
2679.57	-0.180603
2683	-7.4454
2686.43	12.4988
2689.86	12.1378
2693.29	10.083
2696.71	20.9775
2700.13	17.0668
2703.56	16.9137
2706.98	-9.28381
2710.4	11.3035
2713.82	-7.08795
2717.23	-7.73016
2720.65	8.48062
2724.06	20.1163
2727.47	7.53207
2730.88	5.23926
2734.29	-3.62717
2737.7	0.613281
2741.11	2.98233
2744.51	2.47391
2747.91	0.0343323
2751.32	-0.514587
2754.72	20.558
2758.11	8.65927
2761.51	-11.7021
2764.91	2.68939
2768.3	17.0402
2771.7	7.77319
2775.09	-8.10901
2778.48	13.639
2781.87	14.6105
2785.25	20.2641
2788.64	12.738
2792.03	9.91623
2795.41	12.725
2798.79	8.03696
2802.17	5.17227
2805.55	23.8842
2808.93	5.10223
2812.3	8.79761
2815.68	22.7588
2819.05	13.3358
2822.42	-1.6055
2825.79	9.65195
2829.16	6.94745
2832.53	8.0282
2835.89	12.9115
2839.26	16.9327
2842.62	13.5822
2845.98	24.3029
2849.34	35.1757
2852.7	22.8482
2856.06	35.6746
2859.41	13.9812
2862.77	7.27759
2866.12	44.631
2869.47	22.028
2872.82	18.1414
2876.17	40.5704
2879.52	12.2087
2882.87	39.3787
2886.21	22.2466
2889.55	38.1156
2892.89	34.1653
2896.23	21.6084
2899.57	30.7438
2902.91	29.4254
2906.25	36.5788
2909.58	48.439
2912.91	37.563
2916.25	32.3492
2919.58	55.4631
2922.91	32.2064
2926.23	31.6306
2929.56	31.0024
2932.88	52.0623
2936.21	51.3294
2939.53	16.6607
2942.85	57.424
2946.17	27.5358
2949.49	41.9273
2952.8	36.5489
2956.12	50.9181
2959.43	30.603
2962.74	52.5808
2966.06	37.9803
2969.37	28.1916
2972.67	39.1266
2975.98	66.013
2979.28	48.8989
2982.59	60.8206
2985.89	47.4315
2989.19	62.232
2992.49	35.7325
2995.79	57.1566
2999.09	40.085
3002.38	61.5551
3005.68	69.8723
3008.97	60.3515
3012.26	57.437
3015.55	66.7824
3018.84	81.7873
3022.13	84.541
3025.41	77.8639
3028.7	70.2446
3031.98	84.3435
3035.26	76.6979
3038.54	81.3278
3041.82	43.3923
3045.1	63.1711
3048.38	81.0827
3051.65	88.5873
3054.92	80.0001
3058.2	78.9778
3061.47	94.9036
3064.73	72.9461
3068	94.5876
3071.27	94.3439
3074.54	114.537
3077.8	102.963
3081.06	117.759
3084.32	110.201
3087.58	111.143
3090.84	100.808
3094.1	130.469
3097.35	121.487
3100.61	147.048
3103.86	136.372
3107.11	127.824
3110.36	137.296
3113.61	137.097
3116.86	144.555
3120.11	142.508
3123.35	144.269
3126.59	157.457
3129.84	156.341
3133.08	176.199
3136.32	186.519
3139.55	178.701
3142.79	197.568
3146.03	193.555
3149.26	197.204
3152.49	210.404
3155.72	207.365
3158.95	214.836
3162.18	237.555
3165.41	214.478
3168.64	261.968
3171.86	238.797
3175.08	250.913
3178.31	268.7
3181.53	267.392
3184.75	271.825
3187.96	279.998
3191.18	285.288
3194.4	274.373
3197.61	284.413
3200.82	302.999
3204.03	313.982
3207.24	332.592
3210.45	313.156
3213.66	312.794
3216.86	312.475
3220.07	348.302
3223.27	340.384
3226.48	362.972
3229.68	355.126
3232.87	352.091
3236.07	347.09
3239.27	374.595
3242.47	372.633
3245.66	365.939
3248.85	362.091
3252.04	402.165
3255.23	375.514
3258.42	403.232
3261.61	377.397
3264.8	396.341
3267.98	390.352
3271.16	392.887
3274.35	406.836
3277.53	414.094
3280.71	394.463
3283.89	426.251
3287.06	420.82
3290.24	405.785
3293.41	433.714
3296.58	414.905
3299.76	420.86
3302.93	440.324
3306.1	439.591
3309.26	455.908
3312.43	443.573
3315.59	474.884
3318.76	459.635
3321.92	447.221
3325.08	464.191
3328.24	471.669
3331.4	485.763
3334.56	497.992
3337.71	496.103
3340.87	511.255
3344.02	514.133
3347.17	503.052
3350.33	514.798
3353.47	520.862
3356.62	521.359
3359.77	553.935
3362.92	547.963
3366.06	563.688
3369.2	572.857
3372.34	582.999
3375.49	597.966
3378.62	592.199
3381.76	560.955
3384.9	592.966
3388.04	606.162
3391.17	627.893
3394.3	592.812
3397.43	604.772
3400.56	617.255
3403.69	616.543
3406.82	642.503
3409.95	656.2
3413.07	664.2
3416.2	629.102
3419.32	647.272
3422.44	654.89
3425.56	646.092
3428.68	648.571
3431.8	656.65
3434.91	661.681
3438.03	643.553
3441.14	660.856
3444.25	653.332
3447.36	670.402
3450.47	674.091
3453.58	668.092
3456.69	644.942
3459.79	659.739
3462.9	664.031
3466	646.414
3469.11	631.55
3472.21	617.457
3475.31	661.449
3478.4	608.878
3481.5	611.271
3484.6	610.839
3487.69	591.571
3490.79	591.309
3493.88	582.797
3496.97	557.276
3500.06	538.297
3503.15	559.905
3506.23	550.237
3509.32	567.91
3512.4	530.687
3515.49	514.295
3518.57	495.741
3521.65	500.048
3524.73	454.066
3527.81	474.614
3530.89	463.667
3533.96	479.96
3537.03	435.454
3540.11	425.906
3543.18	430.865
3546.25	424.298
3549.32	401.252
3552.39	385.563
3555.46	380.183
3558.52	388.148
3561.59	388.56
3564.65	377.454
3567.71	352.965
3570.77	356.152
3573.83	362.827
3576.89	324
3579.95	338.227
3583	314.461
3586.06	334.26
3589.11	302.841
3592.16	288.417
3595.21	299.573
3598.27	275.605
3601.31	264.911
3604.36	267.416
3607.41	283.116
3610.45	281.767
3613.5	243.525
3616.54	229.859
3619.58	234.158
3622.62	230.921
3625.66	224.866
3628.69	232.981
3631.73	229.751
3634.77	220.834
3637.8	213.922
3640.83	194.839
3643.86	211.552
3646.89	161.589
3649.92	154.763
3652.95	174.392
3655.98	154.8
3659	151.231
3662.02	156.086
3665.05	145.802
3668.07	132.47
3671.09	142.791
3674.11	122.948
3677.13	107.82
3680.14	119.139
3683.16	111.542
3686.17	95.4246
3689.19	109.574
3692.2	93.4472
3695.21	87.727
3698.22	99.9276
3701.23	97.0433
3704.23	86.5567
3707.24	97.8977
3710.24	90.1967
3713.25	80.5571
3716.25	81.3209
3719.25	89.7235
3722.25	77.1411
3725.25	74.0417
3728.25	71.8585
3731.24	71.5535
3734.24	67.403
3737.23	64.1641
3740.22	73.2705
3743.21	73.762
3746.21	68.5146
3749.19	56.5816
3752.18	54.1339
3755.17	63.0731
3758.15	69.1601
3761.14	47.73
3764.12	49.9858
3767.1	66.4447
3770.08	50.7299
3773.06	56.8129
3776.04	69.5285
3779.02	46.3419
3781.99	53.4194
3784.97	59.5489
3787.94	53.4186
3790.91	76.567
3793.88	43.1338
3796.85	40.8727
3799.82	41.4586
3802.79	42.0864
3805.76	44.6188
3808.72	53.7736
3811.69	43.1071
3814.65	63.6412
3817.61	44.4712
3820.57	42.3315
3823.53	47.7709
3826.49	32.3975
3829.45	39.7607
3832.4	60.4073
3835.36	63.0791
3838.31	42.0276
3841.26	42.8083
3844.21	20.7582
3847.16	41.5193
3850.11	45.1775
3853.06	41.234
3856	35.3827
3858.95	32.3913
3861.89	28.4446
3864.84	24.4727
3867.78	43.48
3870.72	40.4492
3873.66	38.3654
3876.6	43.9456
3879.53	25.4911
3882.47	23.3195
3885.4	31.6818
3888.34	30.4137
3891.27	39.7104
3894.2	28.8036
3897.13	38.0527
3900.06	25.1465
3902.99	40.1244
3905.91	35.8257
3908.84	28.69
3911.76	22.4899
3914.69	24.9132
3917.61	26.3488
3920.53	30.731
3923.45	15.8521
3926.37	28.7763
3929.28	21.5242
3932.2	43.008
3935.11	21.4511
3938.03	30.6151
3940.94	25.4821
3943.85	26.0649
3946.76	45.8151
3949.67	26.3474
3952.58	27.0132
3955.49	21.9485
3958.39	24.5784
3961.3	30.1034
3964.2	26.0656
3967.1	23.965
3970	27.6398
3972.9	26.5337
3975.8	36.9485
3978.7	22.3774
3981.6	8.73935
3984.49	25.8553
3987.39	23.7372
3990.28	13.9226
3993.17	17.5309
3996.06	3.88895
3998.95	12.3745
4001.84	4.51935
4004.73	7.26218
4007.61	21.5909
4010.5	0.276733
4013.38	29.089
4016.27	18.3815
4019.15	20.217
4022.03	5.6452
4024.91	21.0095
4027.79	6.44644
4030.66	25.7108
4033.54	9.22516
4036.42	6.27811
4039.29	37.2307
4042.16	14.9458
4045.03	10.0331
4047.9	6.10562
4050.77	29.347
4053.64	9.95096
4056.51	5.12946
4059.38	4.1853
4062.24	7.12088
4065.1	9.09457
4067.97	-0.595001
4070.83	32.521
4073.69	8.23831
4076.55	6.33368
4079.41	9.30261
4082.26	-4.29092
4085.12	-13.9866
4087.97	1.66882
4090.83	-3.15387
4093.68	9.62186
4096.53	3.83606
4099.38	2.95132
4102.23	-2.81909
4105.08	4.1167
4107.93	-5.60104
4110.77	-0.638214
4113.62	9.19659
4116.46	3.34845
4119.3	7.25259
4122.14	9.2066
4124.98	-0.5401
4127.82	-5.37674
4130.66	1.61292
4133.5	2.78745
4136.33	14.8409
4139.17	6.95905
4142	20.3396
4144.83	30.1442
4147.67	16.6359
4150.5	-5.66177
4153.33	4.29282
4156.15	6.3143
4158.98	-3.52789
4161.81	4.34262
4164.63	2.48535
4167.45	0.632355
4170.28	11.5137
4173.1	8.7276
4175.92	9.86987
4178.74	12.9761
4181.56	-4.42438
4184.37	-5.18127
4187.19	-0.0453186
4190	-11.5257
4192.82	6.40076
4195.63	3.81824
4198.44	-10.4766
4201.25	1.68433
4204.06	0.142426
4206.87	25.0996
4209.68	13.7567
4212.48	-5.4642
4215.29	-7.00378
4218.1	8.35172
4220.9	-1.8746
4223.7	13.5019
4226.5	15.052
4229.3	7.76212
4232.1	7.40424
4234.9	3.12408
4237.69	15.7206
4240.49	5.52097
4243.28	4.25797
4246.07	1.02313
4248.87	-5.22107
4251.66	14.4547
4254.45	3.18695
4257.24	0.878693
4260.03	13.5916
4262.81	-4.7388
4265.6	13.0518
4268.38	20.8578
4271.17	15.5997
4273.95	21.4097
4276.73	7.00275
4279.51	9.69464
4282.29	-0.762695
4285.07	8.9646
4287.84	15.6363
4290.62	1.02954
4293.39	-2.4595
4296.17	-4.89792
4298.94	-4.26849
4301.71	13.5867
4304.48	12.1768
4307.25	2.64612
4310.02	17.5047
4312.79	18.1811
4315.55	10.6822
4318.32	15.3611
4321.08	7.81253
4323.85	11.4393
4326.61	2.8367
4329.37	0.35379
4332.13	10.0706
4334.89	23.8824
4337.65	37.6748
4340.4	19.9343
4343.16	14.4275
4345.91	20.1658
4348.67	13.6961
4351.42	35.8082
4354.17	23.2951
4356.92	24.031
4359.67	14.5378
4362.42	-2.14426
4365.17	22.1418
4367.91	24.9203
4370.66	9.27194
4373.4	5.87262
4376.14	9.64618
4378.89	17.5099
4381.63	16.1268
4384.37	21.9554
4387.11	10.3708
4389.84	20.4906
4392.58	21.4092
4395.32	29.7682
4398.05	19.3554
4400.78	28.5533
4403.52	36.7095
4406.25	40.7445
4408.98	21.9458
4411.71	22.8333
4414.44	23.6801
4417.16	34.9329
4419.89	29.4037
4422.62	24.9539
4425.34	32.0019
4428.06	28.6138
4430.78	19.9901
4433.51	30.181
4436.22	50.8407
4438.94	21.2201
4441.66	34.5151
4444.38	27.8988
4447.1	16.0108
4449.81	36.653
4452.52	25.7785
4455.24	22.2419
4457.95	29.1855
4460.66	28.7583
4463.37	23.103
4466.08	33.2169
4468.78	39.1403
4471.49	35.603
4474.2	33.1354
4476.9	31.741
4479.6	28.2524
4482.31	35.3279
4485.01	41.3536
4487.71	34.6738
4490.41	34.3172
4493.11	44.4748
4495.8	34.4605
4498.5	38.2604
4501.19	36.7476
4503.89	52.1572
4506.58	40.0369
4509.27	50.1845
4511.96	52.9077
4514.66	24.8484
4517.34	39.2483
4520.03	34.5383
4522.72	24.531
4525.41	57.0632
4528.09	39.5846
4530.77	46.5883
4533.46	49.3363
4536.14	31.8235
4538.82	38.8385
4541.5	36.2613
4544.18	29.3902
4546.86	37.4921
4549.53	28.4658
4552.21	51.5972
4554.88	34.0395
4557.56	39.0312
4560.23	38.7308
4562.9	44.9358
4565.57	42.5942
4568.24	47.9003
4570.91	45.4682
4573.58	45.9669
4576.24	37.6304
4578.91	30.5003
4581.58	36.5013
4584.24	32.7803
4586.9	33.2377
4589.56	24.9482
4592.22	54.7983
4594.88	37.7431
4597.54	30.5289
4600.2	37.4727
4602.86	54.3166
4605.51	38.3481
4608.17	23.4382
4610.82	45.7981
4613.47	33.0393
4616.13	21.3429
4618.78	32.7283
4621.43	36.4334
4624.07	32.4104
4626.72	37.1747
4629.37	26.4656
4632.01	46.6617
4634.66	39.1934
4637.3	52.7057
4639.94	48.5093
4642.59	38.7594
4645.23	35.6976
4647.87	42.6753
4650.5	35.28
4653.14	54.6565
4655.78	33.8824
4658.42	41.7196
4661.05	31.9112
4663.68	36.6398
4666.31	48.0466
4668.95	49.3196
4671.58	36.0552
4674.21	41.8032
4676.84	39.6974
4679.46	33.0839
4682.09	30.9356
4684.72	38.89
4687.34	34.4747
4689.97	51.4322
4692.59	43.6308
4695.21	31.2747
4697.83	32.424
4700.45	38.0866
4703.07	24.5396
4705.69	31.2852
4708.3	28.9763
4710.92	30.0398
4713.54	34.4875
4716.15	26.4658
4718.76	41.0703
4721.37	36.4072
4723.99	11.3123
4726.59	28.1833
4729.2	24.6577
4731.81	32.4748
4734.42	24.3939
4737.03	17.4255
4739.63	29.7525
4742.23	40.9389
4744.84	25.9389
4747.44	34.8046
4750.04	23.1425
4752.64	11.481
4755.24	30.5385
4757.84	35.9316
4760.44	21.9934
4763.03	36.5331
4765.63	38.5613
4768.22	31.5297
4770.82	15.3953
4773.41	11.7343
4776	26.335
4778.59	30.6722
4781.18	20.1556
4783.77	6.20206
4786.36	28.8294
4788.94	12.5825
4791.53	22.6539
4794.11	-2.75214
4796.7	23.3844
4799.28	7.15814
4801.86	13.8768
4804.44	-2.33977
4807.02	18.2327
4809.6	4.35097
4812.18	12.3268
4814.76	15.7271
4817.33	20.3115
4819.91	2.97231
4822.48	6.42831
4825.06	11.0643
4827.63	7.59369
4830.2	0.638626
4832.77	-7.46124
4835.34	15.8873
4837.91	3.1787
4840.48	2.15054
4843.04	4.63597
4845.61	4.75232
4848.17	2.50806
4850.74	6.07857
4853.3	5.97833
4855.86	-19.9636
4858.42	4.93338
4860.98	11.039
4863.54	6.48482
4866.1	-8.78302
4868.66	5.51128
4871.21	18.7362
4873.77	-1.22931
4876.32	-5.82153
4878.88	1.46709
4881.43	2.83862
4883.98	-11.2228
4886.53	-6.2588
4889.08	3.50061
4891.63	-3.35925
4894.18	-17.3534
4896.72	-5.12846
4899.27	-3.59656
4901.81	-7.99832
4904.36	-4.02345
4906.9	8.33829
4909.44	-3.15144
4911.98	4.45107
4914.52	-3.45659
4917.06	6.56929
4919.6	-6.03711
4922.14	-3.07085
4924.67	16.6694
4927.21	14.965
4929.74	1.32451
4932.28	9.30354
4934.81	13.7978
4937.34	18.3211
4939.87	1.34418
4942.4	-2.51663
4944.93	-6.25139
4947.46	3.2858
4949.99	-6.29495
4952.51	23.7614
4955.04	25.0858
4957.56	8.50903
4960.08	0.403122
4962.61	22.4202
4965.13	3.69662
4967.65	29.6152
4970.17	47.15
4972.69	79.2523
4975.2	104.227
4977.72	91.8269
4980.24	14.1476
4982.75	26.0378
4985.27	22.2748
4987.78	22.2297
4990.29	33.2032
4992.8	56.43
4995.31	38.3979
4997.82	22.8893