File: Data/3-Raman/processed/bu19w-e-ff11b-fi06-v_1800 (450-850nm)_532nm_edge_100%_x100_vis_h50um_30sx2_01.txt
#Acq. time (s)=	30
#Accumulations=	2
#Range (cm-¹)=	1200...2400
#Windows=	4
#Auto scanning=	Off
#Autofocus=	Off
#Macrospot=	Off
#AutoExposure=	Off
#Spike filter=	Multiple accum.
#Delay time (s)=	2
#Binning=	1
#Readout mode=	Signal
#DeNoise=	Off
#ICS correction=	On
#Dark correction=	Off
#Inst. Process=	Off
#Detector Gain=	Best Dynamic
#Detector ADC=	50 kHz HS
#Detector temperature (°C)=	-60.09
#Instrument=	LabRAM HR Evol
#Detector=	SIN-EM FIVIS
#Objective=	x100_VIS
#Grating=	1800 (450-850nm)
#ND Filter=	100%
#Laser=	532nm_Edge
#Hole=	49.98
#Temperature=	0
#Range=	Visible
#StageXY=	75x50mm Scan+
#StageZ=	Z motor
#X (µm)=	0
#Y (µm)=	0
#Z (µm)=	-245.5
#Full time(mm:ss)=	4:27
#Project=	21_11_04
#Sample=	BU19w
#Site=
#Title=	BU19w-E-FF11b-FI06-V_1800 (450-850nm)_532nm_Edge_100%_x100_VIS_H50um_30sX2
#Remark=
#Date=	04.11.2021 18:08
#Acquired=	04.11.2021 18:08:13
#Base:Fit=	16.12.2021 17:39:50
#Base:Fit=	16.12.2021 17:47:31
#Base:Sub=	16.12.2021 17:47:32
1200.19	3.2349
1201.3	-1.25542
1202.41	-1.31966
1203.52	3.87361
1204.63	0.514574
1205.74	1.41903
1206.85	4.46707
1207.97	-2.09253
1209.08	2.05288
1210.19	-1.28497
1211.3	2.84097
1212.41	1.63376
1213.52	-2.74341
1214.63	-2.83702
1215.74	-0.815754
1216.85	0.11586
1217.95	-2.12329
1219.06	0.963793
1220.17	4.05465
1221.28	0.776123
1222.39	3.82191
1223.5	1.58103
1224.61	-0.625273
1225.71	5.65273
1226.82	1.34288
1227.93	7.50553
1229.03	1.19244
1230.14	3.21267
1231.25	3.08096
1232.35	0.920862
1233.46	0.86936
1234.57	2.94024
1235.67	2.90775
1236.78	2.84437
1237.88	0.659519
1238.99	0.596701
1240.1	-1.53857
1241.2	1.57252
1242.3	1.53928
1243.41	0.473204
1244.51	-2.70121
1245.62	6.66507
1246.72	-3.82734
1247.82	4.50463
1248.93	-2.83182
1250.03	2.37217
1251.13	-1.8443
1252.24	3.3457
1253.34	1.24027
1254.44	1.25492
1255.54	2.29863
1256.65	-0.825512
1257.75	2.29781
1258.85	0.20225
1259.95	1.26123
1261.05	9.58269
1262.15	10.7294
1263.25	7.55655
1264.35	7.61292
1265.45	8.65878
1266.55	6.60457
1267.66	4.57425
1268.75	10.9197
1269.85	7.7753
1270.95	9.86819
1272.05	3.63741
1273.15	6.84844
1274.25	3.75387
1275.35	9.04183
1276.45	11.2047
1277.54	8.12228
1278.64	6.08548
1279.74	10.322
1280.84	15.6433
1281.94	43.0757
1283.03	107.103
1284.13	91.6817
1285.23	23.1989
1286.32	6.40132
1287.42	7.4826
1288.52	2.27002
1289.61	6.55532
1290.71	5.54754
1291.8	0.330551
1292.9	2.48771
1293.99	4.68752
1295.09	1.60003
1296.18	2.76054
1297.28	0.684406
1298.37	3.89486
1299.47	0.7724
1300.56	0.835165
1301.65	-2.26401
1302.75	0.962021
1303.84	-1.09853
1304.94	3.17243
1306.03	-5.23138
1307.12	-0.949965
1308.21	-2.99806
1309.31	-2.92208
1310.4	-3.91538
1311.49	2.48824
1312.58	-1.66481
1313.67	0.502323
1314.76	-0.479284
1315.86	1.70555
1316.95	1.76898
1318.04	-3.4385
1319.13	0.851274
1320.22	0.91597
1321.31	-2.21188
1322.4	0.999762
1323.49	1.06314
1324.58	1.13045
1325.67	1.1521
1326.76	2.26787
1327.85	2.38362
1328.93	-0.696392
1330.02	-1.69114
1331.11	0.451921
1332.2	2.58715
1333.29	-1.58746
1334.37	1.60196
1335.46	0.599079
1336.55	0.651367
1337.64	-0.346231
1338.72	0.753248
1339.81	3.96495
1340.9	0.889593
1341.98	-0.107672
1343.07	-0.0590649
1344.16	2.0982
1345.24	4.22882
1346.33	5.29459
1347.41	2.20074
1348.5	3.29473
1349.58	-0.827053
1350.67	4.4173
1351.75	1.3494
1352.84	1.44253
1353.92	0.427801
1355.01	3.58199
1356.09	3.64989
1357.17	5.77626
1358.26	4.77907
1359.34	8.9684
1360.42	5.88642
1361.5	5.94176
1362.59	7.02708
1363.67	10.211
1364.75	8.18259
1365.83	7.17606
1366.92	8.23605
1368	10.3689
1369.08	16.6377
1370.16	11.5012
1371.24	18.7463
1372.32	16.6828
1373.4	17.7475
1374.48	16.7582
1375.56	32.2692
1376.64	38.4421
1377.72	36.4799
1378.8	37.6209
1379.88	53.0443
1380.96	57.1145
1382.04	66.2681
1383.12	59.0261
1384.2	50.8659
1385.28	63.3203
1386.36	150.727
1387.43	247.001
1388.51	49.0802
1389.59	26.5363
1390.67	23.4338
1391.74	13.2032
1392.82	13.2249
1393.9	13.2556
1394.97	12.2835
1396.05	9.25326
1397.13	11.3192
1398.2	13.4108
1399.28	8.34826
1400.35	9.4267
1401.43	6.40107
1402.5	10.6023
1403.58	4.47987
1404.65	7.58009
1405.73	9.64469
1406.8	6.60437
1407.88	14.8489
1408.95	15.9201
1410.03	10.818
1411.1	6.71952
1412.17	4.7149
1413.25	2.71732
1414.32	3.79108
1415.39	1.76892
1416.47	0.780163
1417.54	2.87202
1418.61	2.90302
1419.68	7.02357
1420.75	-1.18503
1421.83	3.99132
1422.9	4.09032
1423.97	2.93564
1425.04	5.03566
1426.11	1.99065
1427.18	1.97991
1428.25	-0.0552273
1429.32	5.09797
1430.39	0.0205784
1431.46	4.1637
1432.53	-0.970837
1433.6	3.11359
1434.67	2.12419
1435.74	-0.936552
1436.81	2.14513
1437.88	3.18346
1438.95	3.20727
1440.01	0.165409
1441.08	-5.97349
1442.15	1.22028
1443.22	0.199518
1444.29	3.29604
1445.35	2.28898
1446.42	2.29218
1447.49	-6.93351
1448.56	2.3147
1449.62	0.262434
1450.69	2.31258
1451.75	3.33683
1452.82	4.37459
1453.89	-0.743156
1454.95	1.31061
1456.02	2.34874
1457.08	3.36684
1458.15	2.34706
1459.21	0.306177
1460.28	2.35287
1461.34	-1.75156
1462.41	-0.741461
1463.47	-2.79596
1464.53	1.33847
1465.6	4.3178
1466.66	-1.81303
1467.72	-0.795153
1468.79	3.28024
1469.85	1.22329
1470.91	1.21206
1471.97	-3.88828
1473.04	1.19469
1474.1	0.169645
1475.16	0.170994
1476.22	-1.87494
1477.29	-0.868507
1478.34	0.134413
1479.41	2.14645
1480.47	-1.9401
1481.53	0.088131
1482.59	4.15782
1483.65	-3.96886
1484.71	0.0115871
1485.77	-4.0094
1486.83	0.0341644
1487.89	-3.02604
1488.95	2.01403
1490.01	-4.06529
1491.07	-1.04853
1492.12	-2.0659
1493.18	0.957684
1494.24	0.954929
1495.3	-3.11374
1496.36	-0.105236
1497.42	0.893826
1498.47	1.89805
1499.53	-1.13036
1500.59	0.880175
1501.64	-1.15402
1502.7	-0.164516
1503.76	-2.19222
1504.81	2.83851
1505.87	0.795317
1506.93	0.793137
1507.98	-1.232
1509.04	-0.231031
1510.09	-2.25535
1511.15	2.74374
1512.21	1.68371
1513.26	3.66751
1514.31	1.66525
1515.37	0.627296
1516.42	0.605207
1517.48	1.60209
1518.53	0.59938
1519.58	-1.41174
1520.64	-0.415009
1521.69	-1.42761
1522.75	-0.444695
1523.8	-2.48075
1524.85	-1.4889
1525.9	4.53146
1526.95	0.515944
1528.01	0.50005
1529.06	-1.51632
1530.11	-0.523951
1531.16	1.48394
1532.21	-1.5279
1533.27	-3.51923
1534.32	2.48943
1535.37	-0.547487
1536.42	1.41949
1537.47	-1.6028
1538.52	0.377909
1539.57	0.421642
1540.62	-0.564915
1541.67	1.41262
1542.72	1.38384
1543.77	2.35964
1544.81	-1.6263
1545.86	1.38832
1546.91	1.3908
1547.96	1.36863
1549.01	2.32215
1550.06	1.39953
1551.1	6.44389
1552.15	0.423132
1553.2	4.40233
1554.25	0.362267
1555.3	-0.651888
1556.34	2.34882
1557.39	4.3503
1558.43	2.31516
1559.48	0.290546
1560.53	5.27713
1561.57	0.29389
1562.62	3.29445
1563.66	6.30389
1564.71	3.2808
1565.76	4.27088
1566.8	3.29018
1567.84	3.28458
1568.89	2.27543
1569.93	2.27548
1570.98	7.26744
1572.02	3.25836
1573.07	3.24309
1574.11	3.25588
1575.15	8.2773
1576.2	7.27191
1577.24	6.23432
1578.28	2.22732
1579.32	2.23318
1580.37	3.23674
1581.41	7.20969
1582.45	6.20639
1583.49	6.20512
1584.53	5.21973
1585.58	10.197
1586.62	5.20202
1587.66	8.18787
1588.7	3.23202
1589.74	7.22735
1590.78	8.23744
1591.82	10.2197
1592.86	10.1914
1593.9	4.20402
1594.94	3.23244
1595.98	6.20712
1597.02	7.21652
1598.06	8.20895
1599.1	6.20816
1600.14	9.17221
1601.17	6.1723
1602.21	14.069
1603.25	11.1349
1604.29	11.0207
1605.33	13.3031
1606.37	11.352
1607.4	13.4886
1608.44	13.2703
1609.48	14.2655
1610.51	11.6336
1611.55	11.4596
1612.59	12.6044
1613.62	15.7941
1614.66	16.6412
1615.7	16.4592
1616.73	12.55
1617.77	14.3301
1618.8	16.0653
1619.84	15.7292
1620.87	17.176
1621.91	18.0166
1622.94	18.8692
1623.98	14.3887
1625.01	17.6852
1626.04	17.5453
1627.08	16.4452
1628.11	12.4151
1629.07	11.3667
1630.12	17.29
1631.16	14.3608
1632.21	22.2949
1633.25	17.3641
1634.3	21.3435
1635.34	18.4002
1636.39	18.4026
1637.43	15.4539
1638.48	18.422
1639.52	16.4758
1640.57	16.5144
1641.61	19.4828
1642.65	14.5794
1643.7	21.4833
1644.74	16.583
1645.78	16.6102
1646.83	20.555
1647.87	21.5598
1648.91	16.7091
1649.95	18.7158
1651	18.7706
1652.04	15.8456
1653.08	20.7893
1654.12	18.8582
1655.16	17.9327
1656.21	24.9026
1657.25	19.9872
1658.29	18.0263
1659.33	20.989
1660.37	17.0859
1661.41	11.2216
1662.45	14.2807
1663.49	19.1533
1664.53	13.326
1665.57	12.3951
1666.61	18.2266
1667.65	15.3449
1668.69	17.3891
1669.72	12.4806
1670.76	12.5407
1671.8	14.5521
1672.84	15.5753
1673.88	15.6228
1674.92	5.78255
1675.95	6.80834
1676.99	15.748
1678.03	9.82212
1679.07	10.8289
1680.1	7.88587
1681.14	12.8527
1682.18	9.92374
1683.21	7.97984
1684.25	8.99203
1685.29	12.9737
1686.32	7.09373
1687.36	10.0881
1688.39	10.1076
1689.43	11.1056
1690.46	6.2132
1691.5	6.25742
1692.53	10.2266
1693.57	9.24578
1694.6	4.34071
1695.64	2.41241
1696.67	9.34779
1697.7	2.4643
1698.74	4.45649
1699.77	3.50958
1700.81	3.53806
1701.84	6.50741
1702.87	2.6016
1703.9	3.61883
1704.94	3.65573
1705.97	2.69965
1707	1.73276
1708.03	3.70147
1709.06	1.75613
1710.1	5.70879
1711.13	3.79781
1712.16	5.78213
1713.19	1.86681
1714.22	4.81889
1715.25	1.93298
1716.28	0.00495911
1717.31	1.95881
1718.34	2.9409
1719.37	-1.89447
1720.4	3.0054
1721.43	0.103418
1722.46	3.03443
1723.49	4.03167
1724.52	2.11189
1725.55	-0.788511
1726.58	5.05531
1727.6	2.18134
1728.63	0.207888
1729.66	2.19561
1730.69	-1.62701
1731.72	-0.625248
1732.74	3.26211
1733.77	2.30093
1734.8	-0.580656
1735.82	-0.55784
1736.85	1.39165
1737.88	-0.509346
1738.91	3.3492
1739.93	2.38838
1740.96	-2.38694
1741.98	-1.40277
1743.01	-1.37265
1744.03	1.51987
1745.06	-2.27191
1746.09	3.48577
1747.11	-2.23221
1748.13	1.61503
1749.16	-3.11701
1750.18	0.754232
1751.21	0.788029
1752.23	0.80105
1753.26	-1.08947
1754.28	-1.06971
1755.3	-0.0938873
1756.33	-0.0812416
1757.35	-0.0629292
1758.37	-0.0217094
1759.39	0.962978
1760.42	0.0361156
1761.44	1.95719
1762.46	1.04205
1763.48	-1.77737
1764.5	0.171762
1765.53	1.16056
1766.55	0.235909
1767.57	-0.692745
1768.59	2.17541
1769.61	0.281076
1770.63	4.12262
1771.65	-0.584318
1772.67	1.35994
1773.69	1.3967
1774.71	0.479841
1775.73	-1.37902
1776.75	-2.30975
1777.77	-2.29226
1778.79	-1.32792
1779.81	-2.24811
1780.83	-3.16848
1781.85	1.62797
1782.86	-4.05198
1783.88	-1.15597
1784.9	-2.07674
1785.92	0.807276
1786.94	2.75731
1787.95	0.916376
1788.97	3.83773
1789.99	-1.87679
1791	1.00663
1792.02	1.02858
1793.04	0.0994835
1794.05	0.125322
1795.07	0.176172
1796.09	0.212669
1797.1	0.248541
1798.12	-1.64568
1799.13	1.25397
1800.15	-0.657652
1801.16	-1.5997
1802.18	-1.57311
1803.19	-0.578909
1804.21	0.411415
1805.22	4.29979
1806.24	-0.484491
1807.25	1.4641
1808.26	-1.40711
1809.28	1.50609
1810.29	2.4886
1811.3	2.50462
1812.32	0.600203
1813.33	-1.30307
1814.34	3.56151
1815.36	0.687975
1816.37	1.67453
1817.38	1.67137
1818.39	-0.234053
1819.4	-1.18069
1820.42	2.70982
1821.43	1.7673
1822.44	2.75534
1823.45	-2.07436
1824.46	-0.12085
1825.47	0.865179
1826.48	0.878914
1827.49	1.86676
1828.5	-1.03351
1829.51	0.911192
1830.52	-1.98781
1831.53	0.936649
1832.54	1.92722
1833.55	1.94029
1834.56	0.956669
1835.57	-0.018362
1836.58	0.0259209
1837.58	0.953342
1838.59	-0.94024
1839.6	-0.919844
1840.61	1.94247
1841.62	-0.97717
1842.62	-0.0143795
1843.63	-0.973001
1844.64	0.961599
1845.65	0.984699
1846.65	-0.9621
1847.66	-0.9742
1848.67	0.949112
1849.67	-0.0288792
1850.68	-1.00451
1851.68	-0.0480614
1852.69	-1.9662
1853.69	0.904642
1854.7	0.890886
1855.71	-0.0805073
1856.71	-1.99603
1857.72	-0.0877914
1858.72	1.81047
1859.72	1.80345
1860.73	-1.05466
1861.73	-1.04991
1862.74	0.84815
1863.74	-2.03304
1864.74	-2.04656
1865.75	2.69601
1866.75	-1.1447
1867.75	-0.210394
1868.76	0.738035
1869.76	-0.219152
1870.76	2.62693
1871.76	-1.18572
1872.77	0.699404
1873.77	1.63606
1874.77	2.56082
1875.77	0.632725
1876.77	-0.33919
1877.77	2.55479
1878.78	3.47083
1879.78	-0.329451
1880.78	-0.3381
1881.78	2.45652
1882.78	-2.29389
1883.78	-0.430616
1884.78	0.520327
1885.78	-3.24708
1886.78	0.511024
1887.78	-2.3437
1888.77	-1.43017
1889.77	-0.498703
1890.77	3.26702
1891.77	0.428709
1892.77	0.404602
1893.77	3.19754
1894.76	1.29843
1895.76	-2.46323
1896.76	1.29816
1897.76	1.28829
1898.75	-1.55685
1899.75	0.302607
1900.75	1.23643
1901.75	3.12172
1902.74	2.16878
1903.74	0.270493
1904.74	1.19559
1905.73	1.16987
1906.73	-3.54558
1907.72	-0.734478
1908.72	0.199106
1909.71	0.205284
1910.71	-0.732407
1911.7	1.13815
1912.7	1.12296
1913.69	0.181774
1914.69	0.182232
1915.68	0.168728
1916.68	1.08669
1917.67	1.06733
1918.66	-1.76079
1919.66	0.133551
1920.65	1.0683
1921.64	2.01
1922.64	-0.849619
1923.63	1.01777
1924.62	2.88651
1925.61	1.9443
1926.61	1.94852
1927.6	0.995256
1928.59	1.93472
1929.58	1.93703
1930.57	0.987762
1931.57	0.0155621
1932.56	-0.0095253
1933.55	-2.86114
1934.54	2.88346
1935.53	1.92479
1936.52	-0.958797
1937.51	-1.94218
1938.5	4.71014
1939.49	1.84817
1940.48	0.901161
1941.47	-1.02889
1942.46	2.79108
1943.45	1.79551
1944.44	0.848255
1945.42	0.848068
1946.41	0.839014
1947.4	2.72884
1948.39	0.797646
1949.38	-1.11856
1950.37	-3.02851
1951.35	-1.10512
1952.34	1.76553
1953.33	-0.179558
1954.32	-1.19395
1955.3	-1.20755
1956.29	1.68292
1957.28	-0.241335
1958.26	5.51338
1959.25	2.60256
1960.23	-0.30975
1961.22	-0.338848
1962.21	-0.354301
1963.19	1.54992
1964.18	5.37734
1965.16	-0.403553
1966.15	-0.408678
1967.13	0.538626
1968.12	0.522717
1969.1	0.488003
1970.09	0.452738
1971.07	2.34278
1972.05	2.32785
1973.04	1.33998
1974.02	-0.603354
1975.01	2.25966
1975.99	0.332409
1976.97	-2.56443
1977.95	0.28434
1978.94	2.18117
1979.92	3.12076
1980.9	-1.6992
1981.88	1.15229
1982.87	2.07419
1983.85	1.09073
1984.83	2.97248
1985.81	-0.892416
1986.79	1.00948
1987.77	0.89337
1988.75	0.069582
1989.73	0.0430069
1990.72	1.17102
1991.7	1.32545
1992.68	0.924809
1993.66	-0.976673
1994.63	-0.0980644
1995.61	1.36046
1996.59	0.333241
1997.57	0.800072
1998.55	0.694555
1999.53	-0.3606
2000.51	0.948544
2001.49	-0.32115
2002.47	-0.00423431
2003.45	0.30401
2004.42	1.98098
2005.4	-0.014328
2006.38	-1.93767
2007.36	1.95642
2008.31	4.19837
2009.3	2.27252
2010.29	-0.584431
2011.28	-2.48413
2012.27	2.20502
2013.26	0.281479
2014.24	-0.705212
2015.23	1.16455
2016.22	-2.58659
2017.21	2.09082
2018.2	-2.64371
2019.18	1.06982
2020.17	-0.821342
2021.16	-0.831669
2022.15	1.9556
2023.14	1.92333
2024.12	-0.912125
2025.11	-0.0138149
2026.1	-0.0248127
2027.08	-0.919085
2028.07	-1.00214
2029.06	0.941498
2030.04	-0.0802898
2031.03	-1.94576
2032.01	1.79222
2033	1.8072
2033.98	0.842257
2034.97	-1.03838
2035.95	-0.0833321
2036.94	-0.0943718
2037.92	-0.111174
2038.91	0.80208
2039.89	1.70766
2040.87	-0.18292
2041.86	-1.12974
2042.84	-0.20805
2043.83	-0.191055
2044.81	3.49201
2045.79	0.793728
2046.78	1.66499
2047.76	-0.232
2048.74	1.63759
2049.72	0.723087
2050.71	-1.1431
2051.69	0.711615
2052.67	0.71707
2053.65	-2.07051
2054.63	2.60338
2055.62	2.58893
2056.6	2.57982
2057.58	0.715666
2058.56	0.729992
2059.54	1.66835
2060.52	2.59726
2061.5	2.60155
2062.48	-2.07514
2063.46	-0.192209
2064.44	0.752615
2065.42	-0.16527
2066.4	0.78236
2067.38	0.791912
2068.36	3.62137
2069.34	0.780857
2070.31	-1.0786
2071.29	0.832516
2072.27	1.77385
2073.25	2.71441
2074.23	-0.10074
2075.21	-1.95471
2076.18	-0.0556984
2077.16	-1.95983
2078.14	0.878683
2079.12	3.73398
2080.09	1.86169
2081.07	-0.974108
2082.05	0.92103
2083.02	1.86932
2084	0.927402
2084.98	-0.0126286
2085.95	-0.94042
2086.93	0.0213566
2087.9	0.0283585
2088.88	-0.907103
2089.85	1.95034
2090.83	0.0688286
2091.8	1.04305
2092.78	1.07327
2093.75	2.04802
2094.73	1.10137
2095.7	2.99558
2096.68	1.09575
2097.65	0.14279
2098.62	2.99281
2099.6	0.150898
2100.57	0.16757
2101.54	0.18215
2102.52	-1.71433
2103.49	1.13504
2104.46	2.10203
2105.44	1.17614
2106.41	1.19131
2107.38	1.1957
2108.35	-0.714792
2109.32	1.20296
2110.3	3.11276
2111.27	-0.681822
2112.24	0.277609
2113.21	0.301237
2114.18	1.26014
2115.15	-0.631489
2116.12	2.21784
2117.09	3.17622
2118.06	-0.625109
2119.03	-1.57929
2120	-0.630116
2120.97	-0.608038
2121.94	1.31763
2122.91	-0.559278
2123.88	-0.553879
2124.85	6.06121
2125.82	0.36557
2126.79	1.3076
2127.76	-0.576384
2128.72	-3.40072
2129.69	3.22373
2130.66	1.33952
2131.63	2.28626
2132.6	1.34367
2133.56	2.30295
2134.53	3.26103
2135.5	2.32331
2136.47	-1.44761
2137.43	0.460222
2138.4	4.23855
2139.37	-0.468275
2140.33	2.362
2141.3	-1.39732
2142.26	1.44159
2143.23	1.4078
2144.19	4.27231
2145.16	1.46006
2146.13	0.52903
2147.09	0.535574
2148.06	-0.396883
2149.02	-0.395365
2149.98	1.47527
2150.95	1.49451
2151.91	0.581514
2152.88	1.52274
2153.84	0.589472
2154.8	2.44491
2155.77	0.5707
2156.73	-0.349777
2157.69	-1.25759
2158.66	0.626112
2159.62	1.56197
2160.58	1.56357
2161.54	1.57481
2162.51	0.656425
2163.47	-0.267727
2164.43	3.46204
2165.39	-0.244192
2166.35	0.697287
2167.32	-3.02557
2168.28	-0.235985
2169.24	-0.205555
2170.2	3.55543
2171.16	2.6236
2172.12	-0.175659
2173.08	2.62597
2174.04	-1.06709
2175	1.7368
2175.96	-0.108889
2176.92	1.7635
2177.88	-2.8653
2178.84	1.78829
2179.8	-0.0509071
2180.76	-1.89342
2181.72	3.68627
2182.68	0.90987
2183.63	-0.0162315
2184.59	0.000921249
2185.55	0.02701
2186.51	0.0621319
2187.47	-0.834105
2188.43	0.0993614
2189.38	1.02381
2190.34	1.96812
2191.3	1.99009
2192.25	-1.69575
2193.21	0.190899
2194.17	3.02323
2195.12	-2.54464
2196.08	-1.61728
2197.04	4.88062
2197.99	-1.58719
2198.95	1.2369
2199.9	-0.573927
2200.86	1.33147
2201.81	-4.31338
2202.77	3.18432
2203.72	-0.472178
2204.68	0.44908
2205.63	2.30105
2206.59	2.31724
2207.54	1.41949
2208.49	0.519617
2209.45	0.539106
2210.4	-2.23005
2211.36	-0.337107
2212.31	-0.314344
2213.26	1.55805
2214.22	0.662304
2215.17	2.55189
2216.12	1.63472
2217.07	-1.15009
2218.03	-1.13217
2218.98	0.763191
2219.93	2.65423
2220.88	-1.07502
2221.83	-2.00492
2222.78	1.75242
2223.74	-0.080946
2224.69	1.82368
2225.64	-0.951429
2226.59	1.88991
2227.54	0.974094
2228.49	-1.82736
2229.44	-1.805
2230.39	2.91714
2231.34	-0.80728
2232.29	1.10208
2233.24	0.190512
2234.19	0.207785
2235.14	2.08785
2236.09	-0.714203
2237.04	-0.689266
2237.98	1.2353
2238.93	1.26865
2239.88	3.15547
2240.83	1.29958
2241.78	-0.567272
2242.73	-2.43688
2243.67	3.23451
2244.62	1.37952
2245.57	1.41279
2246.52	-3.29166
2247.46	0.512535
2248.41	0.523188
2249.36	1.48812
2250.3	-0.399681
2251.25	-2.286
2252.2	-0.371832
2253.14	-1.27895
2254.09	1.59149
2255.03	-2.18744
2255.98	1.62814
2256.92	0.705551
2257.87	0.726089
2258.81	-1.15174
2259.76	0.769697
2260.7	-1.10643
2261.65	-1.08642
2262.59	2.74744
2263.54	0.880533
2264.48	-0.0382442
2265.42	-0.972327
2266.37	-0.0166702
2267.31	-0.0145283
2268.26	2.85339
2269.2	2.88523
2270.14	-1.8563
2271.08	2.94823
2272.03	1.05747
2272.97	1.07493
2273.91	1.09228
2274.85	1.11019
2275.79	3.04726
2276.74	0.202604
2277.68	-1.67874
2278.62	-1.66251
2279.56	-0.704665
2280.5	2.17178
2281.44	1.22309
2282.38	1.2485
2283.32	2.24767
2284.26	-0.600406
2285.2	1.34632
2286.14	1.35039
2287.08	1.385
2288.02	0.437927
2288.96	0.434095
2289.9	6.19914
2290.84	-0.509125
2291.78	-0.481241
2292.72	1.47271
2293.66	0.526579
2294.6	1.49312
2295.54	3.4226
2296.47	1.50024
2297.41	1.52943
2298.35	2.52324
2299.29	1.58624
2300.23	-0.327556
2301.16	-1.27138
2302.1	-1.26
2303.04	1.64801
2303.97	-0.260739
2304.91	-2.16998
2305.85	-2.15046
2306.78	2.69648
2307.72	-0.195249
2308.65	-0.178827
2309.59	1.78539
2310.53	4.70106
2311.46	1.78088
2312.4	-0.146726
2313.33	0.846804
2314.27	-0.0836306
2315.2	-0.0698776
2316.14	1.85533
2317.07	-0.061882
2318	-0.0481596
2318.94	-0.0430918
2319.87	-0.0303373
2320.81	-0.00858498
2321.74	0.989159
2322.67	1.01027
2323.61	3.93048
2324.54	3.93248
2325.47	1.99751
2326.41	2.96212
2327.34	8.74662
2328.27	34.787
2329.2	7.79553
2330.13	4.92034
2331.07	1.08541
2332	2.0629
2332.93	0.143733
2333.86	3.03792
2334.79	0.158738
2335.72	-0.786641
2336.66	-0.774362
2337.59	1.16052
2338.52	-1.70818
2339.45	-2.6545
2340.38	0.233969
2341.31	0.229954
2342.24	1.19534
2343.17	0.251282
2344.1	1.22771
2345.02	-0.678816
2345.95	-1.63047
2346.88	1.25438
2347.81	-2.52529
2348.74	3.90265
2349.67	-1.34631
2350.6	-1.4743
2351.53	0.549135
2352.45	0.295585
2353.38	0.85869
2354.31	-0.046834
2355.24	0.782137
2356.17	-0.20446
2357.09	2.11228
2358.02	-0.225084
2358.95	-0.111599
2359.87	-0.418672
2360.8	0.808499
2361.73	0.403424
2362.65	-0.765289
2363.58	1.82213
2364.5	-2.24986
2365.43	-0.674713
2366.36	2.16825
2367.28	-0.0213366
2368.2	0.0789785
2368.98	0.447489
2369.92	2.3326
2370.86	-1.43526
2371.79	0.454727
2372.73	-0.481588
2373.67	2.34638
2374.6	-1.41249
2375.54	0.470842
2376.48	4.23084
2377.41	0.480683
2378.35	-0.457043
2379.28	-0.462472
2380.22	-0.458728
2381.15	-0.449795
2382.09	0.495294
2383.02	1.43686
2383.96	1.44498
2384.89	-2.29319
2385.83	-0.427379
2386.76	-0.436393
2387.69	0.493761
2388.63	2.36299
2389.56	-2.29763
2390.5	-0.426521
2391.43	-1.35311
2392.36	2.37482
2393.3	-2.30318
2394.23	0.47937
2395.16	-0.444607
2396.09	2.39655
2397.02	0.520987
2397.96	0.519285
2398.89	-2.28202
2399.82	-2.28453