File: Data/3-Raman/processed/bu19w-e-ff11b-fi03-l_150 (500nm)_532nm_edge_100%_x100_vis_h50um_30sx2_01_0.txt
#Acq. time (s)=	30
#Accumulations=	2
#Range (cm-¹)=	100...5000
#Windows=	1
#Auto scanning=	Off
#Autofocus=	Off
#Macrospot=	Off
#AutoExposure=	Off
#Spike filter=	Multiple accum.
#Delay time (s)=	2
#Binning=	1
#Readout mode=	Signal
#DeNoise=	Off
#ICS correction=	On
#Dark correction=	Off
#Inst. Process=	Off
#Detector Gain=	Best Dynamic
#Detector ADC=	50 kHz HS
#Detector temperature (°C)=	-60.09
#Instrument=	LabRAM HR Evol
#Detector=	SIN-EM FIVIS
#Objective=	x100_VIS
#Grating=	150 (500nm)
#ND Filter=	100%
#Laser=	532nm_Edge
#Hole=	49.98
#Temperature=	0
#Range=	Visible
#StageXY=	75x50mm Scan+
#StageZ=	Z motor
#X (µm)=	0
#Y (µm)=	0
#Z (µm)=	-250.5
#Full time(mm:ss)=	1:05
#Project=	21_11_04
#Sample=	BU19w
#Site=
#Title=	BU19w-E-FF11b-FI03-L_150 (500nm)_532nm_Edge_100%_x100_VIS_H50um_30sX2
#Remark=
#Date=	04.11.2021 18:39
#Acquired=	04.11.2021 18:39:02
#Base:Fit=	16.12.2021 17:39:50
#Base:Edit=	16.12.2021 17:46:00
#Base:Sub=	16.12.2021 17:46:03
101.869	4625.07
106.493	6004.4
111.113	11150.5
115.732	17833.9
120.349	14194.1
124.964	7097.57
129.577	5081.05
134.185	4686.91
138.793	4267.15
143.399	3883.56
148.003	3606.18
152.602	3773.64
157.201	3961.37
161.798	4476.67
166.392	5295.38
170.982	6588.56
175.572	8635.62
180.16	12174.2
184.745	17021.8
189.326	22109.3
193.907	24462.1
198.486	22343.9
203.06	17713.5
207.634	12711.3
212.206	9024.55
216.776	6577.07
221.341	4834.07
225.906	3775.38
230.469	3121.63
235.028	2596.02
239.586	2307.31
244.142	2474.34
248.694	3670.78
253.246	4661.01
257.795	2909.05
262.341	1267.18
266.886	665.498
271.428	438.5
275.967	277.343
280.505	178.43
285.041	132.295
289.573	26.4368
294.105	0.0020752
298.632	-3.43506
303.159	16.1749
307.685	-14.7512
312.205	-17.6754
316.726	-19.0897
321.242	-47.8859
325.758	-38.2292
330.272	80.2616
334.782	453.234
339.292	2041.61
343.797	3431.71
348.302	2072.79
352.803	724.125
357.304	336.77
361.802	249.199
366.297	216.706
370.791	238.663
375.281	337.743
379.77	662.475
384.256	1137.78
388.741	1664.71
393.223	1686.57
397.704	871.437
402.18	527.306
406.657	499.518
411.13	591.662
415.602	682.55
420.07	920.484
424.538	1226.67
429.002	1879.76
433.465	3376.43
437.925	6578.69
442.384	14133.7
446.839	35438.6
451.294	37026.1
455.745	37064.5
460.196	36027.7
464.642	16294.1
469.089	8956.1
473.531	6040.39
477.971	4437.97
482.411	3271.39
486.846	2547.1
491.282	2218.83
495.713	2149.43
500.144	1932.38
504.572	1765.03
508.997	1550.03
513.421	1328.07
517.842	1130.51
522.263	934.732
526.679	800.734
531.093	723.573
535.507	674.456
539.917	599.807
544.327	530.731
548.733	459.232
553.137	367.715
557.54	368.23
561.94	391.321
566.337	363.96
570.734	384.819
575.127	385.972
579.518	342.048
583.909	407.45
588.295	349.64
592.68	309.472
597.064	268.617
601.445	243.516
605.823	227.41
610.201	225.306
614.575	209.982
618.947	230.697
623.317	199.353
627.686	189.667
632.052	180.028
636.415	216.567
640.777	170.163
645.138	142.885
649.495	140.324
653.85	121.267
658.205	116.225
662.556	172.012
666.905	192.021
671.252	192.525
675.597	267.069
679.941	501.854
684.282	799.859
688.62	735.033
692.957	449.689
697.293	261.57
701.625	172.322
705.955	150.725
710.283	127.367
714.609	109.253
718.933	88.0245
723.257	103.147
727.577	102.366
731.894	92.0558
736.21	108.749
740.524	72.9135
744.835	104.649
749.147	92.4705
753.454	82.6635
757.759	123.44
762.063	165.237
766.364	199.231
770.663	221.534
774.96	357.685
779.257	575.066
783.55	986.511
787.841	1278.55
792.13	1740.62
796.417	2342.86
800.702	1765.22
804.985	905.737
809.266	477.322
813.545	328.396
817.821	280.799
822.096	246.323
826.371	267.12
830.641	229.634
834.91	214.149
839.176	204.071
843.441	199.386
847.703	184.466
851.964	176.7
856.222	211.923
860.479	309.883
864.733	411.953
868.986	374.891
873.236	224.549
877.485	198.321
881.731	162.146
885.975	121.402
890.218	154.528
894.458	100.145
898.696	127.403
902.933	115.305
907.167	122.823
911.399	105.424
915.63	87.5
919.858	99.6808
924.084	65.2791
928.308	39.0837
932.531	29.9467
936.749	8.97614
940.967	14.65
945.184	26.6397
949.398	3.31122
953.61	-15.5175
957.821	-21.4674
962.029	-29.4628
966.236	-33.1404
970.44	-72.8325
974.642	-56.168
978.843	-58.5541
983.041	-69.3166
987.236	-80.0875
991.43	-54.871
995.623	-40.9615
999.813	-56.3827
1004	-51.5966
1008.19	-43.5671
1012.37	-38.6955
1016.55	-19.0692
1020.73	-45.2815
1024.91	-37.5045
1029.09	-33.1438
1033.27	-8.62286
1037.44	-16.6784
1041.61	53.8024
1045.78	78.2955
1049.94	221.486
1054.11	415.905
1058.27	540.432
1062.43	589.127
1066.59	1008.51
1070.75	1487.08
1074.9	1111.5
1079.05	479.889
1083.2	173.003
1087.35	81.4688
1091.5	82.4622
1095.65	41.4638
1099.79	35.7753
1103.93	13.7857
1108.07	-4.88657
1112.21	-6.90958
1116.34	-6.86035
1120.48	-18.4169
1124.61	12.3079
1128.74	37.1212
1132.86	66.2676
1136.99	154.832
1141.11	358.612
1145.23	720.657
1149.35	1090.76
1153.47	847.139
1157.59	388.987
1161.7	149.129
1165.82	58.6621
1169.92	16.5895
1174.03	11.5046
1178.14	-3.97256
1182.24	-10.1911
1186.35	3.01718
1190.45	-3.5766
1194.55	-26.6589
1198.64	-11.9793
1202.74	22.8781
1206.83	40.2313
1210.92	48.38
1215.01	79.739
1219.1	128.094
1223.18	129.041
1227.27	80.9412
1231.35	68.2466
1235.43	62.8952
1239.5	67.8581
1243.58	43.7233
1247.65	64.6656
1251.72	103.817
1255.8	128.106
1259.86	151.488
1263.93	155.957
1267.99	131.483
1272.06	90.9871
1276.12	66.437
1280.18	44.8074
1284.23	17.0215
1288.29	20.2831
1292.34	7.38229
1296.39	13.5247
1300.44	-13.6304
1304.49	17.574
1308.53	-6.70206
1312.58	14.3339
1316.62	2.97238
1320.66	13.6775
1324.7	17.1949
1328.73	18.6025
1332.77	30.019
1336.8	0.168823
1340.83	38.3847
1344.86	38.4601
1348.88	54.4648
1352.91	71.4068
1356.93	123.064
1360.95	210.194
1364.97	385.181
1368.99	658.572
1373.01	612.551
1377.02	408.053
1381.03	218.857
1385.04	120.739
1389.05	85.7879
1393.06	65.6948
1397.06	42.7879
1401.06	34.6167
1405.06	21.4717
1409.06	25.0948
1413.06	19.8626
1417.05	-0.183502
1421.05	13.2938
1425.04	21.7931
1429.03	23.2138
1433.01	28.5697
1437	18.1273
1440.99	21.4869
1444.97	27.7571
1448.95	32.0086
1452.93	8.57764
1456.9	10.7526
1460.88	10.8952
1464.85	25.6937
1468.82	15.8431
1472.79	20.7756
1476.76	11.9223
1480.73	27.5315
1484.69	15.6702
1488.65	30.1954
1492.61	34.9311
1496.57	35.7576
1500.53	26.8648
1504.48	43.3242
1508.43	37.4766
1512.39	43.314
1516.33	24.8787
1520.28	31.7128
1524.23	51.1615
1528.17	68.6695
1532.11	56.1474
1536.05	51.3848
1539.99	71.8178
1543.93	94.1759
1547.86	102.954
1551.8	88.4682
1555.73	97.1835
1559.66	132.935
1563.58	119.249
1567.51	137.443
1571.44	140.111
1575.36	165.934
1579.28	180.115
1583.2	184.61
1587.11	197.729
1591.03	208.876
1594.94	219.025
1598.85	244.523
1602.76	254.644
1606.67	257.141
1610.58	263.482
1614.48	275.59
1618.38	285.833
1622.29	275.929
1626.18	307.251
1630.08	297.475
1633.98	301.254
1637.87	301.193
1641.76	281.13
1645.65	268.826
1649.54	265.178
1653.43	274.015
1657.31	241.532
1661.2	229.149
1665.08	207.05
1668.96	201.214
1672.83	195.241
1676.71	163.265
1680.58	158.971
1684.46	135.358
1688.33	137.641
1692.2	101.526
1696.06	83.6166
1699.93	89.5793
1703.79	76.3781
1707.66	81.2367
1711.52	48.9626
1715.37	55.6755
1719.23	52.9096
1723.08	44.4937
1726.94	55.868
1730.79	43.6468
1734.64	35.2418
1738.49	18.4251
1742.33	40.8535
1746.18	28.7273
1750.02	18.6475
1753.86	16.1169
1757.7	22.9903
1761.54	8.89227
1765.37	18.8021
1769.21	24.1199
1773.04	12.8293
1776.87	17.3453
1780.7	18.2079
1784.53	9.77596
1788.35	15.3583
1792.17	12.5342
1796	5.00688
1799.82	4.01518
1803.64	6.64662
1807.45	-2.05754
1811.27	21.2433
1815.08	18.1197
1818.89	25.2695
1822.7	9.70247
1826.51	3.52446
1830.32	1.05904
1834.12	14.5535
1837.92	19.509
1841.72	15.01
1845.52	7.64722
1849.32	7.82309
1853.12	4.15878
1856.91	-4.23235
1860.7	19.0594
1864.5	31.0448
1868.28	12.3505
1872.07	18.7764
1875.86	6.72075
1879.64	24.2661
1883.42	12.3421
1887.21	5.98863
1890.98	28.3933
1894.76	26.8916
1898.54	10.6616
1902.31	19.3595
1906.08	22.5839
1909.85	15.697
1913.62	21.7798
1917.39	32.5061
1921.16	26.7537
1924.92	46.0162
1928.68	12.4938
1932.44	38.3606
1936.2	35.441
1939.96	39.0295
1943.71	46.3616
1947.47	42.4801
1951.22	49.6441
1954.97	36.9975
1958.72	44.8768
1962.46	43.2706
1966.21	52.9143
1969.95	61.5408
1973.7	43.7884
1977.43	64.4297
1981.17	63.452
1984.91	60.5607
1988.65	60.4404
1992.38	70.5266
1996.11	54.485
1999.84	53.3025
2003.57	74.3479
2007.3	69.4151
2011.02	77.336
2014.75	64.9893
2018.47	71.165
2022.19	74.7184
2025.91	79.3325
2029.62	77.5696
2033.34	83.22
2037.05	75.2674
2040.76	75.5135
2044.47	82.1518
2048.18	86.9523
2051.89	78.0705
2055.59	58.2077
2059.3	87.022
2063	85.7846
2066.7	77.2561
2070.4	60.4272
2074.1	73.071
2077.79	82.0761
2081.49	93.9124
2085.18	88.1239
2088.87	71.8017
2092.56	81.3044
2096.25	89.0852
2099.93	75.4538
2103.61	92.4042
2107.3	76.752
2110.98	75.006
2114.66	96.4883
2118.33	94.6906
2122.01	82.5691
2125.68	80.6025
2129.36	84.1596
2133.03	86.7493
2136.7	88.3897
2140.36	83.5167
2144.03	105.336
2147.7	81.0616
2151.36	77.9849
2155.02	63.9234
2158.68	64.562
2162.34	58.8269
2165.99	67.7495
2169.65	62.1054
2173.3	58.3893
2176.95	57.472
2180.6	64.7736
2184.25	57.508
2187.9	69.3967
2191.54	54.0968
2195.18	59.8142
2198.83	49.2015
2202.47	59.5666
2206.11	53.5564
2209.74	55.797
2213.38	66.315
2217.01	60.3743
2220.64	44.3176
2224.27	50.2927
2227.9	44.2964
2231.53	53.0407
2235.16	46.1235
2238.78	41.9529
2242.4	52.5912
2246.02	33.542
2249.64	30.2465
2253.26	32.5501
2256.88	43.2781
2260.49	42.8212
2264.11	44.2064
2267.72	40.921
2271.33	44.2516
2274.93	43.7756
2278.54	35.682
2282.15	51.0262
2285.75	37.0875
2289.35	42.9808
2292.95	32.7694
2296.55	43.3656
2300.15	35.0441
2303.74	34.2567
2307.34	41.0008
2310.93	34.4418
2314.52	49.649
2318.11	43.013
2321.7	54.3287
2325.28	41.8284
2328.87	27.4223
2332.45	49.8538
2336.03	42.0164
2339.61	43.5855
2343.19	39.4822
2346.77	34.4242
2350.34	30.301
2353.92	25.245
2357.49	42.5891
2361.06	27.2523
2364.63	43.5712
2368.2	39.4287
2371.76	45.5374
2375.33	19.2579
2378.89	24.4443
2382.45	46.2221
2386.01	29.3142
2389.57	33.6179
2393.13	33.3643
2396.68	24.92
2400.23	25.7204
2403.79	33.0445
2407.34	25.7402
2410.88	14.8382
2414.43	34.2662
2417.98	23.4545
2421.52	32.8928
2425.06	22.132
2428.61	22.4637
2432.14	15.4381
2435.68	9.35164
2439.22	33.9132
2442.75	9.25301
2446.29	28.3475
2449.82	21.373
2453.35	19.0882
2456.88	37.362
2460.4	16.894
2463.93	8.59543
2467.45	20.8866
2470.98	21.9914
2474.5	31.3077
2478.02	17.8924
2481.54	22.4429
2485.05	21.2645
2488.57	24.6632
2492.08	19.6866
2495.59	10.8819
2499.1	-0.668274
2502.61	14.8972
2506.12	21.0296
2509.63	13.1134
2513.13	20.1188
2516.63	27.146
2520.13	27.6952
2523.63	14.2063
2527.13	9.27878
2530.63	11.8023
2534.12	23.5772
2537.62	9.56274
2541.11	6.66768
2544.6	7.55362
2548.09	16.8417
2551.58	0.269577
2555.06	5.91553
2558.55	14.459
2562.03	7.24393
2565.51	14.0389
2568.99	2.28224
2572.47	17.6185
2575.95	9.64603
2579.43	-0.215088
2582.9	6.84549
2586.37	12.0579
2589.84	11.5635
2593.31	12.8584
2596.78	18.8765
2600.25	18.3012
2603.71	12.9249
2607.18	12.2057
2610.64	-7.8806
2614.1	9.3049
2617.56	17.9467
2621.02	15.9315
2624.47	7.14932
2627.93	7.91859
2631.38	10.5742
2634.83	12.2174
2638.28	4.20703
2641.73	8.62488
2645.18	1.51256
2648.62	5.86517
2652.07	7.29736
2655.51	9.62134
2658.95	14.7378
2662.39	22.6483
2665.83	-0.687302
2669.27	4.36394
2672.7	18.7777
2676.14	19.0814
2679.57	-7.74298
2683	5.76419
2686.43	15.5538
2689.86	4.0098
2693.29	21.4496
2696.71	-1.22667
2700.13	9.67175
2703.56	9.40834
2706.98	12.8532
2710.4	9.00978
2713.82	4.27379
2717.23	10.7436
2720.65	4.21503
2724.06	20.0895
2727.47	14.5324
2730.88	10.8465
2734.29	9.01024
2737.7	-1.26543
2741.11	23.1387
2744.51	13.7448
2747.91	14.6371
2751.32	2.36841
2754.72	7.9445
2758.11	11.6143
2761.51	21.8916
2764.91	16.0973
2768.3	19.691
2771.7	18.5331
2775.09	23.9525
2778.48	9.54877
2781.87	30.9026
2785.25	23.0433
2788.64	30.2311
2792.03	28.002
2795.41	31.3996
2798.79	16.9592
2802.17	28.7646
2805.55	24.6174
2808.93	18.5974
2812.3	39.7116
2815.68	29.9195
2819.05	46.2896
2822.42	28.1334
2825.79	45.4792
2829.16	23.6669
2832.53	35.4492
2835.89	31.4292
2839.26	51.6678
2842.62	41.2122
2845.98	49.4454
2849.34	33.5268
2852.7	54.9871
2856.06	49.3543
2859.41	36.2624
2862.77	47.5153
2866.12	40.057
2869.47	56.9823
2872.82	46.6847
2876.17	57.0442
2879.52	71.1827
2882.87	49.5342
2886.21	71.2074
2889.55	73.0858
2892.89	69.2893
2896.23	84.3237
2899.57	63.3927
2902.91	83.0831
2906.25	97.0668
2909.58	86.4243
2912.91	89.9503
2916.25	90.6196
2919.58	107.323
2922.91	117.378
2926.23	102.82
2929.56	117.518
2932.88	108.555
2936.21	125.972
2939.53	128.275
2942.85	129.631
2946.17	142.29
2949.49	138.01
2952.8	137.482
2956.12	152.93
2959.43	173.109
2962.74	183.924
2966.06	158.163
2969.37	196.296
2972.67	216.697
2975.98	194.889
2979.28	204.121
2982.59	223.623
2985.89	222.508
2989.19	243.014
2992.49	237.249
2995.79	240.9
2999.09	268.078
3002.38	267.064
3005.68	302.735
3008.97	309.303
3012.26	306.488
3015.55	336.664
3018.84	348.946
3022.13	333.876
3025.41	376.363
3028.7	379.244
3031.98	382.119
3035.26	427.504
3038.54	424.68
3041.82	447.403
3045.1	467.32
3048.38	480.637
3051.65	509.12
3054.92	528.177
3058.2	539.637
3061.47	568.886
3064.73	608.705
3068	624.716
3071.27	635.857
3074.54	673.608
3077.8	687.677
3081.06	715.581
3084.32	751.004
3087.58	766.463
3090.84	845.868
3094.1	821.967
3097.35	875.45
3100.61	876.463
3103.86	904.781
3107.11	974.607
3110.36	1005.33
3113.61	1069.9
3116.86	1075.59
3120.11	1153.68
3123.35	1163.24
3126.59	1218.5
3129.84	1249.92
3133.08	1329.02
3136.32	1375.7
3139.55	1408.01
3142.79	1446.01
3146.03	1498.33
3149.26	1539.34
3152.49	1637.63
3155.72	1651.91
3158.95	1719.7
3162.18	1771.2
3165.41	1845.65
3168.64	1917.05
3171.86	1974.93
3175.08	1991.68
3178.31	2077.89
3181.53	2143.99
3184.75	2188.22
3187.96	2195.89
3191.18	2260.69
3194.4	2328.3
3197.61	2449.18
3200.82	2419.44
3204.03	2463.15
3207.24	2535.47
3210.45	2564.12
3213.66	2646.22
3216.86	2678.11
3220.07	2723.3
3223.27	2759.07
3226.48	2815.13
3229.68	2802.75
3232.87	2894.37
3236.07	2869.62
3239.27	2946.49
3242.47	2999.79
3245.66	2996.15
3248.85	3042.05
3252.04	3033.04
3255.23	3125.24
3258.42	3122.05
3261.61	3139.39
3264.8	3172.5
3267.98	3236.65
3271.16	3232.63
3274.35	3215.01
3277.53	3270.95
3280.71	3323.27
3283.89	3297.54
3287.06	3412.19
3290.24	3488.22
3293.41	3428.23
3296.58	3447.22
3299.76	3509.01
3302.93	3455.64
3306.1	3527.84
3309.26	3585.37
3312.43	3681.16
3315.59	3672.1
3318.76	3796.74
3321.92	3801.58
3325.08	3822.55
3328.24	3956.11
3331.4	3995.93
3334.56	4078.5
3337.71	4114.12
3340.87	4065.12
3344.02	4179.36
3347.17	4264.41
3350.33	4275.23
3353.47	4390.55
3356.62	4451.76
3359.77	4482.08
3362.92	4527.17
3366.06	4615.75
3369.2	4665.97
3372.34	4688.1
3375.49	4823.19
3378.62	4841.52
3381.76	4867.72
3384.9	4965.49
3388.04	4974.94
3391.17	5082.88
3394.3	5077.25
3397.43	5077.42
3400.56	5124.38
3403.69	5304.75
3406.82	5237.13
3409.95	5235.31
3413.07	5283.89
3416.2	5339.74
3419.32	5394.34
3422.44	5398.94
3425.56	5371.82
3428.68	5348.43
3431.8	5432.16
3434.91	5381.13
3438.03	5428.86
3441.14	5362.8
3444.25	5344.44
3447.36	5384.93
3450.47	5295.67
3453.58	5324.71
3456.69	5180.34
3459.79	5233.26
3462.9	5193.77
3466	5095.17
3469.11	5032.12
3472.21	5011.6
3475.31	4920.88
3478.4	4886.43
3481.5	4822.96
3484.6	4737.96
3487.69	4669.49
3490.79	4620.63
3493.88	4498.71
3496.97	4429.55
3500.06	4341.18
3503.15	4248.39
3506.23	4177.43
3509.32	4065.21
3512.4	3964.88
3515.49	3925.38
3518.57	3772.84
3521.65	3720.6
3524.73	3624.41
3527.81	3499.62
3530.89	3438.88
3533.96	3386.87
3537.03	3299.02
3540.11	3201.89
3543.18	3082.97
3546.25	3012.17
3549.32	2946.77
3552.39	2827.53
3555.46	2780.65
3558.52	2720.05
3561.59	2622.54
3564.65	2545.13
3567.71	2441.62
3570.77	2381.63
3573.83	2323.13
3576.89	2254.31
3579.95	2187.17
3583	2155.87
3586.06	2108.22
3589.11	2018.85
3592.16	1906.47
3595.21	1892.67
3598.27	1800.03
3601.31	1783.25
3604.36	1737.86
3607.41	1640.32
3610.45	1642.17
3613.5	1590.99
3616.54	1519.96
3619.58	1474.59
3622.62	1413.32
3625.66	1363.47
3628.69	1312.85
3631.73	1251.84
3634.77	1200.2
3637.8	1160.27
3640.83	1073.51
3643.86	1008.56
3646.89	936.448
3649.92	894.062
3652.95	836.934
3655.98	752.822
3659	723.812
3662.02	635.34
3665.05	594.638
3668.07	552.521
3671.09	472.862
3674.11	455.423
3677.13	416.299
3680.14	407.397
3683.16	345.522
3686.17	323.301
3689.19	304.859
3692.2	277.889
3695.21	261.323
3698.22	231.353
3701.23	220.434
3704.23	198.112
3707.24	188.108
3710.24	172.339
3713.25	137.508
3716.25	142.548
3719.25	126.692
3722.25	115.538
3725.25	108.16
3728.25	92.1787
3731.24	81.8883
3734.24	74.4255
3737.23	74.5477
3740.22	71.79
3743.21	56.6273
3746.21	69.9894
3749.19	75.7048
3752.18	48.1397
3755.17	44.3429
3758.15	57.6409
3761.14	39.6265
3764.12	47.1974
3767.1	11.2104
3770.08	29.2305
3773.06	27.3967
3776.04	27.4783
3779.02	23.798
3781.99	22.9751
3784.97	28.7685
3787.94	5.31035
3790.91	9.25165
3793.88	6.62801
3796.85	6.85892
3799.82	9.93759
3802.79	23.4403
3805.76	19.0213
3808.72	12.7194
3811.69	4.54114
3814.65	15.2747
3817.61	-5.18993
3820.57	-2.00189
3823.53	11.6118
3826.49	9.15509
3829.45	2.90909
3832.4	26.0576
3835.36	0.856735
3838.31	4.1302
3841.26	15.0148
3844.21	9.74367
3847.16	20.6544
3850.11	6.82426
3853.06	8.24336
3856	16.3517
3858.95	18.7477
3861.89	4.90099
3864.84	5.36868
3867.78	0.0940704
3870.72	4.37576
3873.66	1.94522
3876.6	2.38272
3879.53	-6.80711
3882.47	19.5176
3885.4	24.6917
3888.34	9.66379
3891.27	24.4265
3894.2	18.029
3897.13	-1.8638
3900.06	14.7598
3902.99	12.1472
3905.91	15.2701
3908.84	29.0001
3911.76	20.5993
3914.69	17.9457
3917.61	10.4713
3920.53	12.6544
3923.45	23.4275
3926.37	14.9769
3929.28	18.0201
3932.2	13.3794
3935.11	20.2963
3938.03	8.10886
3940.94	12.2518
3943.85	19.243
3946.76	23.3748
3949.67	20.8309
3952.58	14.4764
3955.49	12.9186
3958.39	24.7946
3961.3	39.5646
3964.2	29.4346
3967.1	14.5174
3970	21.6664
3972.9	14.433
3975.8	14.8711
3978.7	31.627
3981.6	28.1964
3984.49	14.1858
3987.39	10.7328
3990.28	14.9688
3993.17	32.6392
3996.06	16.6912
3998.95	26.7158
4001.84	25.2068
4004.73	34.2946
4007.61	17.3884
4010.5	31.3172
4013.38	25.0038
4016.27	15.7936
4019.15	24.9128
4022.03	23.4182
4024.91	23.8548
4027.79	22.3655
4030.66	1.54227
4033.54	13.5889
4036.42	23.7131
4039.29	5.78511
4042.16	13.017
4045.03	24.0899
4047.9	22.5813
4050.77	8.48009
4053.64	21.5392
4056.51	5.51614
4059.38	20.5448
4062.24	17.119
4065.1	10.7739
4067.97	18.0369
4070.83	15.5731
4073.69	13.1053
4076.55	19.3956
4079.41	18.8681
4082.26	-1.15617
4085.12	11.9597
4087.97	15.3204
4090.83	1.11414
4093.68	15.2257
4096.53	0.029953
4099.38	21.9644
4102.23	5.78616
4105.08	7.19102
4107.93	-1.21056
4110.77	15.8248
4113.62	12.2919
4116.46	0.904617
4119.3	15.9129
4122.14	23.09
4124.98	2.89093
4127.82	13.0356
4130.66	3.65744
4133.5	-0.798355
4136.33	13.4221
4139.17	14.6689
4142	14.731
4144.83	16.9871
4147.67	12.5031
4150.5	17.8231
4153.33	17.2251
4156.15	-1.07574
4158.98	9.91151
4161.81	11.1674
4164.63	14.4132
4167.45	9.83017
4170.28	18.948
4173.1	17.3188
4175.92	2.98189
4178.74	8.20322
4181.56	18.3298
4184.37	25.5313
4187.19	19.0499
4190	5.72171
4192.82	23.7365
4195.63	8.49391
4198.44	12.8593
4201.25	8.3999
4204.06	9.82678
4206.87	4.37601
4209.68	23.475
4212.48	-5.56696
4215.29	7.63652
4218.1	3.25046
4220.9	12.6493
4223.7	11.1938
4226.5	9.70766
4229.3	13.1883
4232.1	6.7906
4234.9	9.31439
4237.69	15.8231
4240.49	6.46121
4243.28	13.983
4246.07	12.5726
4248.87	5.16292
4251.66	8.69547
4254.45	9.22871
4257.24	20.7509
4260.03	4.24231
4262.81	22.8049
4265.6	12.2976
4268.38	2.78114
4271.17	12.3623
4273.95	12.8876
4276.73	17.4096
4279.51	5.75169
4282.29	14.2684
4285.07	4.57303
4287.84	10.0161
4290.62	16.4531
4293.39	14.7826
4296.17	17.1865
4298.94	0.346527
4301.71	-9.43011
4304.48	16.2976
4307.25	5.49522
4310.02	-3.2807
4312.79	9.29614
4315.55	7.61789
4318.32	16.0918
4321.08	6.23424
4323.85	17.7337
4326.61	9.8779
4329.37	9.15199
4332.13	7.38644
4334.89	9.70218
4337.65	-0.227249
4340.4	13.309
4343.16	10.5435
4345.91	5.75227
4348.67	10.155
4351.42	6.39548
4354.17	3.69702
4356.92	0.977448
4359.67	17.6833
4362.42	1.64705
4365.17	8.1339
4367.91	5.39073
4370.66	-0.418793
4373.4	-4.21439
4376.14	11.4796
4378.89	16.9017
4381.63	15.1288
4384.37	20.5579
4387.11	12.664
4389.84	8.94429
4392.58	-6.09021
4395.32	-2.46317
4398.05	20.7113
4400.78	26.3185
4403.52	8.07916
4406.25	13.6694
4408.98	10.9676
4411.71	14.4774
4414.44	11.7175
4417.16	17.2765
4419.89	9.2124
4422.62	12.6398
4425.34	18.1715
4428.06	20.5765
4430.78	12.5262
4433.51	22.2459
4436.22	14.1673
4438.94	17.5912
4441.66	18.9016
4444.38	4.48148
4447.1	15.2186
4449.81	11.2648
4452.52	3.08871
4455.24	13.8128
4457.95	20.3212
4460.66	1.59166
4463.37	7.05685
4466.08	13.5733
4468.78	19.0498
4471.49	15.0616
4474.2	5.81532
4476.9	21.8716
4479.6	8.42531
4482.31	11.8589
4485.01	17.4088
4487.71	13.4346
4490.41	24.2575
4493.11	20.2267
4495.8	16.1524
4498.5	17.407
4501.19	17.5924
4503.89	9.27855
4506.58	9.45738
4509.27	17.0649
4511.96	7.69955
4514.66	8.94388
4517.34	19.7513
4520.03	19.9476
4522.72	10.5939
4525.41	12.9299
4528.09	18.4562
4530.77	18.6671
4533.46	3.95676
4536.14	3.09831
4538.82	19.3216
4541.5	9.94075
4544.18	13.3701
4546.86	5.03937
4549.53	5.26212
4552.21	11.9302
4554.88	1.47224
4557.56	12.4998
4560.23	-0.0640717
4562.9	7.84067
4565.57	0.701431
4568.24	24.9832
4570.91	22.1382
4573.58	3.87613
4576.24	19.1642
4578.91	11.7442
4581.58	2.20538
4584.24	17.7345
4586.9	12.4745
4589.56	11.5579
4592.22	6.25513
4594.88	18.4201
4597.54	14.2408
4600.2	-3.08769
4602.86	9.13077
4605.51	-8.18535
4608.17	8.44566
4610.82	17.4302
4613.47	13.2458
4616.13	20.0408
4618.78	9.25452
4621.43	5.06438
4624.07	9.6767
4626.72	7.66342
4629.37	15.5738
4632.01	6.91643
4634.66	18.1227
4637.3	1.66919
4639.94	13.976
4642.59	-1.39413
4645.23	6.52992
4647.87	15.6228
4650.5	0.336212
4653.14	0.643906
4655.78	14.2811
4658.42	8.76204
4661.05	10.066
4663.68	18.1057
4666.31	14.961
4668.95	5.04947
4671.58	0.737656
4674.21	-0.223419
4676.84	10.0267
4679.46	4.57664
4682.09	8.09837
4684.72	3.7578
4687.34	-5.0878
4689.97	8.5672
4692.59	-4.78781
4695.21	0.986069
4697.83	10.1489
4700.45	12.5559
4703.07	9.31433
4705.69	12.8332
4708.3	3.91325
4710.92	5.15941
4713.54	3.00935
4716.15	15.5719
4718.76	12.2769
4721.37	13.5085
4723.99	20.3973
4726.59	12.5758
4729.2	8.16356
4731.81	13.9655
4734.42	7.28185
4737.03	7.40445
4739.63	-0.440903
4742.23	14.4484
4744.84	4.30701
4747.44	7.80566
4750.04	9.0036
4752.64	7.93272
4755.24	6.8604
4757.84	5.7869
4760.44	-0.961563
4763.03	5.96623
4765.63	11.7693
4768.22	21.0364
4770.82	4.10835
4773.41	3.09848
4776	6.65849
4778.59	1.08977
4781.18	4.655
4783.77	4.79796
4786.36	2.65862
4788.94	1.66396
4791.53	7.54396
4794.11	10.0047
4796.7	-4.71196
4799.28	0.0646362
4801.86	3.714
4804.44	5.08801
4807.02	1.88986
4809.6	-5.9005
4812.18	3.57156
4814.76	8.46364
4817.33	1.83519
4819.91	5.61137
4822.48	-3.3327
4825.06	6.24873
4827.63	-1.55014
4830.2	4.57599
4832.77	16.5568
4835.34	4.11496
4837.91	6.82843
4840.48	1.38892
4843.04	26.3634
4845.61	-6.05292
4848.17	13.0714
4850.74	12.2223
4853.3	3.03511
4855.86	4.43394
4858.42	4.83633
4860.98	15.8476
4863.54	7.95515
4866.1	10.625
4868.66	-7.97752
4871.21	12.4934
4873.77	4.53242
4876.32	-3.45721
4878.88	14.6485
4881.43	9.02817
4883.98	4.58272
4886.53	-6.99667
4889.08	-3.11986
4891.63	1.95836
4894.18	15.3764
4896.72	12.1293
4899.27	6.49396
4901.81	5.62607
4904.36	4.75955
4906.9	6.28038
4909.44	-7.72502
4911.98	-2.65205
4914.52	9.582
4917.06	15.8349
4919.6	11.3596
4922.14	17.6434
4924.67	7.20778
4927.21	5.15199
4929.74	9.05952
4932.28	14.2097
4934.81	-6.91164
4937.34	4.24942
4939.87	19.0133
4942.4	0.200119
4944.93	7.77998
4947.46	5.81802
4949.99	6.25357
4952.51	7.90767
4955.04	7.1534
4957.56	5.23068
4960.08	3.32678
4962.61	6.24931
4965.13	14.0385
4967.65	0.198685
4970.17	9.20834
4972.69	12.1966
4975.2	10.3613
4977.72	13.3623
4980.24	6.70248
4982.75	15.7861
4985.27	21.2624
4987.78	2.4895
4990.29	7.98576
4992.8	14.7103
4995.31	12.9314
4997.82	14.8363