File: Data/3-Raman/processed/bu19(2)w-a-ff1-fi06-v_1800 (450-850nm)_532nm_edge_100%_x100_vis_lwd_h100um_30sx2_01.txt
#Acq. time (s)=	30
#Accumulations=	2
#Range (cm-¹)=	1200...2365
#Windows=	3
#Auto scanning=	Off
#Autofocus=	Off
#Macrospot=	Off
#AutoExposure=	Off
#Spike filter=	Multiple accum.
#Delay time (s)=	2
#Binning=	1
#Readout mode=	Signal
#DeNoise=	Off
#ICS correction=	On
#Dark correction=	Off
#Inst. Process=	Off
#Detector Gain=	Best Dynamic
#Detector ADC=	50 kHz HS
#Detector temperature (°C)=	-60.09
#Instrument=	LabRAM HR Evol
#Detector=	SIN-EM FIVIS
#Objective=	x100_VIS_LWD
#Grating=	1800 (450-850nm)
#ND Filter=	100%
#Laser=	532nm_Edge
#Hole=	100.021
#Temperature=	0
#Range=	Visible
#StageXY=	75x50mm Scan+
#StageZ=	Z motor
#X (µm)=	0
#Y (µm)=	0
#Z (µm)=	-16.9
#Full time(mm:ss)=	3:18
#Project=	21_11_26
#Sample=	BU19(2)w
#Site=
#Title=	BU19(2)w-A-FF1-FI06-V_1800 (450-850nm)_532nm_Edge_100%_x100_VIS_LWD_H100um_30sX2
#Remark=
#Date=	26.11.2021 13:46
#Acquired=	26.11.2021 13:46:13
#Base:Fit=	16.12.2021 16:00:56
#Base:Fit=	16.12.2021 16:07:48
#Base:Sub=	16.12.2021 16:07:50
1202.72	6.9111
1203.84	3.36761
1204.95	1.70964
1206.06	-3.35168
1207.17	4.33153
1208.28	-0.76799
1209.39	3.71414
1210.5	5.02246
1211.61	-4.57268
1212.72	-2.44505
1213.83	-6.69231
1214.94	-1.27965
1216.05	0.876541
1217.16	-0.404099
1218.27	2.57346
1219.38	-2.91095
1220.49	-0.979187
1221.6	-7.55836
1222.71	8.98788
1223.81	-0.00657654
1224.92	-4.68106
1226.03	-6.0473
1227.14	5.18188
1228.25	5.50365
1229.35	-1.58081
1230.46	9.94508
1231.57	13.2298
1232.67	6.41333
1233.78	13.1927
1234.89	5.32642
1235.99	4.79468
1237.1	15.6994
1238.2	7.50053
1239.31	4.55495
1240.41	6.95406
1241.52	10.4449
1242.62	4.40977
1243.73	12.0816
1244.83	1.86534
1245.94	11.409
1247.04	7.36864
1248.14	24.2896
1249.25	4.52167
1250.35	9.92731
1251.45	15.1825
1252.56	12.0878
1253.66	11.0746
1254.76	12.3243
1255.87	17.6776
1256.97	7.36234
1258.07	24.1195
1259.17	14.7158
1260.27	16.9657
1261.37	24.1492
1262.48	44.4093
1263.58	72.1104
1264.68	30.9626
1265.78	33.9521
1266.88	27.6943
1267.98	16.3513
1269.08	19.6949
1270.18	14.448
1271.28	17.4293
1272.38	14.2841
1273.47	15.4861
1274.57	16.651
1275.67	14.5359
1276.77	19.8617
1277.87	20.9992
1278.97	29.511
1280.07	33.701
1281.16	79.9347
1282.26	272.654
1283.36	738.509
1284.45	518.075
1285.55	105.253
1286.65	47.2443
1287.75	29.2114
1288.84	17.5275
1289.94	12.2903
1291.03	18.5866
1292.13	6.91873
1293.22	15.2704
1294.32	14.3393
1295.42	9.0377
1296.51	12.4559
1297.61	12.371
1298.7	7.99789
1299.79	8.91351
1300.89	5.73029
1301.98	5.69176
1303.08	7.7851
1304.17	14.0082
1305.26	3.37975
1306.35	7.42346
1307.45	-2.14839
1308.54	2.03104
1309.63	0.97139
1310.73	2.00359
1311.82	5.14824
1312.91	0.952957
1314	2.98083
1315.09	6.12498
1316.18	-3.33972
1317.28	3.9986
1318.37	7.18382
1319.46	-4.45624
1320.55	5.02988
1321.64	2.79659
1322.73	-3.67941
1323.82	12.0723
1324.91	0.468781
1326	3.5269
1327.09	4.33585
1328.18	5.631
1329.27	-5.80244
1330.35	0.510117
1331.44	7.77426
1332.53	3.35828
1333.62	4.22964
1334.71	-5.36966
1335.79	-6.51508
1336.88	2.85617
1337.97	-8.70859
1339.06	-2.50462
1340.14	6.94067
1341.23	1.74457
1342.32	2.76895
1343.4	1.63264
1344.49	1.65611
1345.58	5.81001
1346.66	11.9124
1347.75	0.305664
1348.83	6.54053
1349.92	-9.1358
1351	-1.90108
1352.09	4.29016
1353.17	1.31506
1354.25	3.59779
1355.34	8.52388
1356.42	-2.85782
1357.51	4.41039
1358.59	6.46321
1359.67	2.28259
1360.76	-2.96068
1361.84	-3.96529
1362.92	12.6268
1364	9.64748
1365.09	-5.81618
1366.17	5.53462
1367.25	4.42796
1368.33	11.7431
1369.41	36.6846
1370.5	9.85051
1371.58	1.5535
1372.66	9.69292
1373.74	9.68474
1374.82	13.8533
1375.9	7.76268
1376.98	8.82262
1378.06	8.86847
1379.14	17.4522
1380.22	24.6872
1381.3	24.4558
1382.38	35.6898
1383.46	39.6488
1384.54	80.6628
1385.61	221.563
1386.69	1136.05
1387.77	1046.76
1388.85	145.561
1389.93	56.9054
1391	30.0645
1392.08	21.8444
1393.16	26.9504
1394.23	5.50868
1395.31	15.845
1396.39	14.9802
1397.46	9.8999
1398.54	0.775131
1399.62	16.2944
1400.69	8.26981
1401.77	22.7869
1402.84	5.70222
1403.92	14.1596
1404.99	13.1429
1406.07	17.2617
1407.14	37.8306
1408.22	66.7006
1409.29	72
1410.37	19.8432
1411.44	4.42947
1412.51	5.54015
1413.59	13.2238
1414.66	2.8998
1415.73	10.259
1416.81	1.17165
1417.88	5.45369
1418.95	9.69868
1420.02	-5.63912
1421.1	6.68784
1422.17	10.9109
1423.24	8.23001
1424.31	7.8745
1425.38	3.88307
1426.45	2.9991
1427.52	-5.22933
1428.59	13.183
1429.67	2.0607
1430.74	6.37737
1431.81	-0.531174
1432.87	-1.53047
1433.95	5.5453
1435.01	5.68916
1436.08	-0.363937
1437.15	3.78806
1438.22	-3.32248
1439.29	5.00949
1440.36	0.0739899
1441.43	4.30182
1442.49	-0.751282
1443.56	6.50641
1444.63	11.6906
1445.7	0.600998
1446.77	-0.383575
1447.83	2.72655
1448.9	2.84807
1449.97	3.93272
1451.03	10.0967
1452.1	1.92752
1453.17	6.09531
1454.23	6.1911
1455.3	4.2047
1456.36	6.35706
1457.43	14.5681
1458.49	9.4908
1459.56	3.43427
1460.62	5.52942
1461.69	-3.68209
1462.75	7.55016
1463.82	7.48958
1464.88	-0.488953
1465.94	-3.86797
1467.01	2.27002
1468.07	1.28267
1469.13	0.297913
1470.2	-9.92698
1471.26	3.30672
1472.32	0.229309
1473.39	4.32704
1474.45	-3.83312
1475.51	-6.82185
1476.57	3.35237
1477.63	1.29427
1478.69	-1.76445
1479.76	21.5584
1480.82	0.121109
1481.88	-9.02246
1482.94	-7.89028
1484	-2.75894
1485.06	1.06645
1486.12	-0.969589
1487.18	-1.94169
1488.24	3.0825
1489.3	-5.09543
1490.36	-5.10687
1491.42	-3.12941
1492.48	4.96553
1493.53	-6.15334
1494.59	8.01177
1495.65	2.91833
1496.71	4.82406
1497.77	-4.28471
1498.82	-0.243935
1499.88	-2.22482
1500.94	-0.188454
1502	-3.26042
1503.05	-6.32935
1504.11	-9.4119
1505.17	3.71114
1506.22	6.61668
1507.28	4.61216
1508.34	-2.44276
1509.39	7.632
1510.45	-5.45347
1511.5	1.47908
1512.56	6.24563
1513.61	-1.94221
1514.67	3.15038
1515.72	4.0296
1516.78	8.91078
1517.83	11.8835
1518.88	-2.12084
1519.94	0.907333
1520.99	7.89594
1522.05	3.88884
1523.1	8.82796
1524.15	1.64012
1525.2	3.56543
1526.26	1.59354
1527.31	9.65683
1528.36	1.56422
1529.41	-10.5295
1530.47	-0.577141
1531.52	-0.522125
1532.57	-5.57993
1533.62	-12.5014
1534.67	0.525848
1535.72	7.45261
1536.77	3.22849
1537.82	5.05417
1538.87	-0.059967
1539.92	2.09605
1540.97	-8.75695
1542.02	1.15204
1543.07	7.99467
1544.12	-3.19962
1545.17	6.84422
1546.22	5.93263
1547.27	2.91444
1548.32	2.80495
1549.37	-0.31601
1550.42	5.69147
1551.46	4.03081
1552.51	9.01016
1553.56	16.8898
1554.61	-0.307037
1555.65	-8.48126
1556.7	11.4938
1557.75	-1.55609
1558.79	2.29663
1559.84	5.0986
1560.89	9.97815
1561.93	-0.0423431
1562.98	3.97626
1564.02	-8.09944
1565.07	-0.0489502
1566.11	-0.876587
1567.16	3.6004
1568.2	2.65038
1569.25	-4.3709
1570.29	-0.489395
1571.34	-2.5459
1572.38	0.338028
1573.43	1.20209
1574.47	7.12236
1575.51	0.204788
1576.56	3.16508
1577.6	9.93953
1578.64	2.74356
1579.69	-0.313095
1580.73	-0.331665
1581.77	-0.446899
1582.81	-4.56177
1583.85	12.2891
1584.9	0.28566
1585.94	1.2173
1586.98	0.0645447
1588.02	1.94716
1589.06	7.90677
1590.1	-2.05537
1591.14	12.862
1592.18	3.81245
1593.22	3.62897
1594.26	2.384
1595.3	2.35008
1596.34	12.1781
1597.38	0.215851
1598.42	4.13783
1599.46	2.96756
1600.5	3.81033
1601.54	6.57794
1602.58	2.42273
1603.62	2.24828
1604.66	-2.78293
1605.69	-3.81723
1606.73	3.10826
1607.77	7.86234
1608.81	4.85191
1609.84	-4.01346
1610.88	4.95486
1611.92	4.50368
1612.95	-0.230637
1613.99	2.15512
1615.03	-3.17516
1616.06	-1.78006
1617.1	1.37206
1618.13	-2.09503
1619.17	0.142166
1620.2	5.02718
1621.24	0.66185
1622.27	2.80986
1623.31	-1.56012
1624.34	6.18362
1625.38	3.85651
1626.41	1.43675
1627.45	-2.70685
1628.48	2.53745
1629.51	0.999619
1630.55	-5.50232
1631.53	2.34377
1632.57	-4.54518
1633.62	3.27371
1634.66	6.21111
1635.71	-3.70908
1636.75	6.03468
1637.8	3.93407
1638.84	0.887924
1639.89	9.69566
1640.93	7.7002
1641.98	-1.21143
1643.02	-5.22693
1644.06	0.606979
1645.11	3.45068
1646.15	1.47473
1647.19	-0.594543
1648.24	8.16408
1649.28	7.26118
1650.32	2.28748
1651.37	3.35037
1652.41	2.34436
1653.45	-1.6756
1654.49	-2.67903
1655.53	-0.69577
1656.57	10.2554
1657.62	3.30382
1658.66	-2.71098
1659.7	7.02814
1660.74	4.00356
1661.78	-0.873245
1662.82	-2.74066
1663.86	-5.73228
1664.9	1.0493
1665.94	3.78633
1666.98	-2.00261
1668.02	4.78973
1669.06	-1.14606
1670.1	1.87364
1671.14	-1.03108
1672.18	5.82198
1673.21	6.78513
1674.25	-0.142334
1675.29	-10.9877
1676.33	8.79404
1677.37	1.84019
1678.4	6.6805
1679.44	-9.27053
1680.48	10.4092
1681.52	6.36832
1682.55	12.254
1683.59	13.194
1684.63	-3.67105
1685.66	-6.69685
1686.7	0.191559
1687.73	11.054
1688.77	-2.87137
1689.81	1.93098
1690.84	1.85872
1691.88	-0.100494
1692.91	2.80743
1693.95	2.63376
1694.98	-1.44725
1696.01	0.507492
1697.05	-0.474762
1698.08	-3.57343
1699.12	5.15596
1700.15	5.11497
1701.18	4.05891
1702.22	0.0189209
1703.25	6.77745
1704.28	8.67107
1705.32	3.75221
1706.35	-0.243713
1707.38	2.53687
1708.41	2.34662
1709.44	-3.73439
1710.48	5.01219
1711.51	-2.80725
1712.54	2.06355
1713.57	4.75218
1714.6	2.61557
1715.63	-3.28053
1716.66	7.4278
1717.69	11.1129
1718.72	6.93933
1719.75	11.7183
1720.78	-2.92702
1721.81	11.5136
1722.84	3.55817
1723.87	12.1589
1724.9	5.28223
1725.93	12.8051
1726.96	15.6221
1727.99	6.82347
1729.02	7.46962
1730.05	3.42482
1731.07	14.8902
1732.1	11.1697
1733.13	1.41193
1734.16	7.94548
1735.18	11.5807
1736.21	18.1401
1737.24	19.9563
1738.26	6.36626
1739.29	7.16573
1740.32	11.7035
1741.34	6.70331
1742.37	11.3537
1743.4	4.57086
1744.42	12.1158
1745.45	11.0912
1746.47	9.08517
1747.5	4.1144
1748.52	21.1732
1749.55	2.07703
1750.57	10.7536
1751.6	9.82425
1752.62	10.6008
1753.64	19.0242
1754.67	5.51378
1755.69	11.1159
1756.71	6.18208
1757.74	16.4533
1758.76	16.4643
1759.78	12.6331
1760.81	14.4543
1761.83	14.3134
1762.85	14.2616
1763.87	9.48465
1764.89	15.2645
1765.92	17.1963
1766.94	12.383
1767.96	8.48743
1768.98	14.0894
1770	21.3643
1771.02	11.9056
1772.04	26.2499
1773.06	18.69
1774.08	9.19588
1775.1	22.5303
1776.12	16.9234
1777.14	14.9706
1778.16	18.6366
1779.18	16.5538
1780.2	7.91545
1781.22	12.6772
1782.24	8.86502
1783.26	20.3512
1784.28	16.572
1785.29	12.8124
1786.31	17.4925
1787.33	8.92885
1788.35	10.1169
1789.37	13.1597
1790.38	20.9131
1791.4	6.4649
1792.42	15.8754
1793.43	11.0816
1794.45	4.35283
1795.47	10.1825
1796.48	16.0587
1797.5	10.3606
1798.51	11.343
1799.53	12.235
1800.55	0.546707
1801.56	2.36911
1802.58	2.34094
1803.59	-0.498611
1804.61	7.20172
1805.62	15.9333
1806.64	13.1092
1807.65	1.526
1808.66	21.716
1809.68	17.823
1810.69	6.21318
1811.7	10.9523
1812.72	9.95004
1813.73	19.6145
1814.74	4.24841
1815.76	12.9942
1816.77	11.0313
1817.78	3.14771
1818.79	7.93782
1819.8	5.01755
1820.82	8.8878
1821.83	5.0266
1822.84	21.4773
1823.85	9.79466
1824.86	12.6375
1825.87	14.5628
1826.88	-3.89746
1827.89	4.7928
1828.9	1.8119
1829.91	4.60216
1830.92	10.2824
1831.93	16.0814
1832.94	15.1351
1833.95	10.2598
1834.96	9.11676
1835.97	8.81375
1836.98	10.2656
1837.99	8.74446
1839	7.69038
1840	9.75998
1841.01	-2.21977
1842.02	11.9303
1843.03	17.5089
1844.04	1.03317
1845.04	9.64241
1846.05	12.5043
1847.06	16.4419
1848.07	11.0052
1849.07	10.9553
1850.08	2.09944
1851.09	1.84172
1852.09	5.50783
1853.1	-4.18396
1854.1	7.19771
1855.11	0.24707
1856.11	0.0274658
1857.12	3.75493
1858.12	5.53188
1859.13	-0.413101
1860.13	3.22717
1861.14	8.94513
1862.14	0.332047
1863.15	9.71698
1864.15	0.897507
1865.15	5.47833
1866.16	10.9247
1867.16	-5.60623
1868.16	-5.86652
1869.17	9.24283
1870.17	1.52373
1871.17	2.3627
1872.17	5.07089
1873.18	-2.70369
1874.18	5.69322
1875.18	11.1567
1876.18	5.15851
1877.18	5.85692
1878.18	-4.8374
1879.19	1.92827
1880.19	-7.51163
1881.19	5.63733
1882.19	-1.29054
1883.19	3.97797
1884.19	3.72784
1885.19	1.82887
1886.19	4.75969
1887.19	-1.01404
1888.19	8.18744
1889.19	6.00601
1890.19	2.0645
1891.19	9.60112
1892.18	1.94315
1893.18	13.0821
1894.18	2.40907
1895.18	6.94666
1896.18	-4.37186
1897.18	2.21365
1898.17	5.92482
1899.17	3.86458
1900.17	0.851807
1901.16	3.57472
1902.16	6.42082
1903.16	7.32854
1904.16	4.35812
1905.15	8.94176
1906.15	0.331207
1907.14	-2.68135
1908.14	3.8205
1909.14	-9.36002
1910.13	-4.62198
1911.13	1.11148
1912.12	3.88976
1913.12	4.71614
1914.11	1.87181
1915.11	-2.78859
1916.1	10.3863
1917.1	-5.81593
1918.09	6.27968
1919.08	0.631256
1920.08	1.69414
1921.07	0.687729
1922.06	7.33965
1923.06	6.28261
1924.05	6.12886
1925.04	-6.3166
1926.04	6.92822
1927.03	5.12277
1928.02	-3.39264
1929.01	3.214
1930	-0.541504
1931	1.42914
1931.99	2.27542
1932.98	6.84544
1933.97	1.09174
1934.96	2.39207
1935.95	-2.13036
1936.94	-4.26332
1937.93	5.99701
1938.92	4.95175
1939.91	-2.66582
1940.9	-1.69495
1941.89	7.89828
1942.88	-1.66364
1943.87	-2.78781
1944.86	2.00807
1945.85	-2.70538
1946.84	0.180573
1947.83	-9.48701
1948.82	-4.80583
1949.8	3.81769
1950.79	2.99489
1951.78	6.03052
1952.77	-6.40692
1953.76	2.17538
1954.74	-0.145264
1955.73	4.48776
1956.72	-8.7625
1957.7	3.78258
1958.69	-13.5166
1959.68	3.65649
1960.66	9.26381
1961.65	-3.40025
1962.63	9.96469
1963.62	-2.56367
1964.61	-2.59088
1965.59	6.91942
1966.58	3.08859
1967.56	9.81776
1968.55	-1.7623
1969.53	1.9279
1970.52	7.4446
1971.5	7.27977
1972.48	8.16713
1973.47	3.26701
1974.45	-5.52733
1975.44	9.75359
1976.42	9.76959
1977.4	13.5509
1978.39	7.64743
1979.37	1.77943
1980.35	17.0646
1981.33	16.9084
1982.31	11.9934
1983.3	18.5296
1984.28	4.95596
1985.26	12.469
1986.24	-1.02911
1987.22	11.3924
1988.21	13.1219
1989.19	4.26381
1990.17	17.6203
1991.15	17.243
1992.13	21.5349
1993.11	23.3507
1994.09	17.3999
1995.07	15.1848
1996.05	14.0131
1997.03	18.1783
1998.01	20.3046
1998.99	18.9404
1999.97	22.0544
2000.95	18.1609
2001.92	16.959
2002.9	20.9132
2003.88	23.8459
2004.86	26.5332
2005.84	20.1205
2006.81	20.8719
2007.79	24.1864
2008.77	18.9629
2009.75	21.5986
2010.73	23.3241
2011.7	22.0362
2012.68	21.4919
2013.67	19.365
2014.66	18.0965
2015.64	9.53197
2016.63	22.7072
2017.62	15.266
2018.61	13.1172
2019.6	13.7596
2020.58	14.5812
2021.57	20.1656
2022.56	3.22159
2023.55	20.8087
2024.54	15.9453
2025.52	14.7459
2026.51	7.10603
2027.5	7.49849
2028.48	11.0089
2029.47	9.36739
2030.45	14.4247
2031.44	8.86742
2032.43	6.99553
2033.41	5.30302
2034.4	3.42075
2035.38	12.4765
2036.37	15.6147
2037.35	7.11751
2038.34	21.0627
2039.32	15.317
2040.31	8.60696
2041.29	15.8751
2042.27	7.37915
2043.26	9.14638
2044.24	7.44838
2045.23	3.59584
2046.21	12.3093
2047.19	12.1265
2048.17	-4.89255
2049.16	10.9736
2050.14	12.0722
2051.12	8.44099
2052.11	7.3896
2053.09	0.884003
2054.07	3.8398
2055.05	5.74254
2056.03	-1.83638
2057.01	2.76686
2058	3.7204
2058.98	5.69745
2059.96	7.6291
2060.94	-4.61609
2061.92	-1.76338
2062.9	-3.61806
2063.88	3.01987
2064.86	4.94069
2065.84	-4.30414
2066.82	4.22589
2067.8	-0.416382
2068.78	4.34142
2069.76	-3.23529
2070.73	1.43301
2071.71	-6.94064
2072.69	5.49753
2073.67	7.33751
2074.65	9.24779
2075.63	-0.930176
2076.6	1.11665
2077.58	-2.75014
2078.56	1.91608
2079.54	-6.50232
2080.51	9.69951
2081.49	2.12357
2082.47	7.78027
2083.45	3.06583
2084.42	-6.40646
2085.4	6.81856
2086.37	5.91574
2087.35	-8.16032
2088.32	0.388885
2089.3	1.3517
2090.28	-0.444534
2091.25	-3.24664
2092.23	4.448
2093.2	1.79352
2094.18	9.54015
2095.15	1.00653
2096.13	5.65691
2097.1	6.55275
2098.07	-1.15404
2099.05	11.1356
2100.02	12.9984
2101	-4.06401
2101.97	-6.82706
2102.94	-5.89941
2103.92	0.658066
2104.89	-6.91631
2105.86	-8.72279
2106.83	-2.01096
2107.8	11.2975
2108.78	-4.07733
2109.75	-1.23793
2110.72	11.135
2111.69	-1.23787
2112.66	-5.09509
2113.63	-4.06923
2114.61	-0.255157
2115.58	0.683243
2116.55	-1.29935
2117.52	0.529236
2118.49	0.456787
2119.46	-1.60963
2120.43	-5.52823
2121.4	3.02585
2122.37	-3.4823
2123.34	-0.555679
2124.31	-5.32506
2125.28	0.151306
2126.25	3.70622
2127.21	0.710297
2128.18	-6.93141
2129.15	-7.91487
2130.12	5.26689
2131.09	8.04094
2132.06	-0.56604
2133.02	1.2133
2133.99	-9.18681
2134.96	11.5695
2135.93	5.85742
2136.89	-10.3354
2137.86	8.53819
2138.83	1.86453
2139.79	-0.941696
2140.76	-0.147247
2141.73	6.38843
2142.69	10.0518
2143.66	3.57002
2144.62	-3.34784
2145.59	5.10414
2146.55	1.2961
2147.52	13.4291
2148.48	8.63153
2149.45	-1.81468
2150.42	6.4225
2151.38	-4.88533
2152.34	-3.89185
2153.31	-1.15121
2154.27	-1.25264
2155.24	2.24733
2156.2	0.14418
2157.16	-0.869858
2158.13	3.84386
2159.09	-4.56606
2160.05	-0.94136
2161.01	-4.84172
2161.98	-6.78558
2162.94	4.37737
2163.9	-7.84
2164.86	6.00677
2165.83	-3.33803
2166.79	1.26413
2167.75	-5.3949
2168.71	-10.2814
2169.67	12.9987
2170.63	2.01131
2171.59	1.94176
2172.56	3.50642
2173.51	2.49295
2174.48	-8.64137
2175.44	-6.8053
2176.4	4.28426
2177.36	-5.08226
2178.32	-0.456253
2179.28	-4.29237
2180.23	-4.31087
2181.19	0.276428
2182.15	-3.51668
2183.11	5.67316
2184.07	3.6376
2185.03	4.48273
2185.99	5.44101
2186.95	2.76132
2187.9	1.98114
2188.86	8.382
2189.82	-1.09988
2190.78	-3.05237
2191.73	7.1517
2192.69	-0.242218
2193.65	0.749832
2194.6	0.952881
2195.56	-6.52898
2196.52	-2.99956
2197.47	-3.17593
2198.43	6.06808
2199.38	4.36749
2200.34	3.64136
2201.3	1.09338
2202.25	8.88884
2203.21	3.56592
2204.16	-2.41393
2205.12	0.996445
2206.07	0.581482
2207.03	-0.393265
2207.98	-0.328506
2208.93	-9.53989
2209.89	9.10292
2210.84	1.66649
2211.8	12.9263
2212.75	-2.84892
2213.7	2.6488
2214.66	0.832031
2215.61	-9.36345
2216.56	-0.981293
2217.51	-6.63074
2218.47	1.75305
2219.42	-2.87231
2220.37	2.78844
2221.32	4.595
2222.27	6.28297
2223.23	-4.00551
2224.18	-5.77016
2225.13	-5.63379
2226.08	5.72668
2227.03	0.208511
2227.98	6.83331
2228.93	-0.733887
2229.88	-0.750305
2230.83	8.74889
2231.78	6.05717
2232.73	1.46318
2233.68	-2.20511
2234.63	-4.9912
2235.58	1.4554
2236.53	1.41049
2237.48	-0.430786
2238.43	0.712814
2239.38	-0.0572205
2240.33	2.68173
2241.27	-1.98274
2242.22	5.59044
2243.17	14.1253
2244.12	-6.72408
2245.07	-6.67278
2246.01	8.62044
2246.96	6.82822
2247.91	-13.9341
2248.85	-7.35316
2249.8	-1.68643
2250.75	3.94382
2251.69	5.69492
2252.64	-7.51642
2253.59	13.5297
2254.53	3.25002
2255.48	-3.37976
2256.42	-9.98781
2257.37	4.34459
2258.32	-2.23021
2259.26	0.667786
2260.2	0.733688
2261.15	1.75243
2262.1	-1.95439
2263.04	-0.923218
2263.98	8.7888
2264.93	2.34479
2265.87	-3.28004
2266.81	-7.17717
2267.76	-3.48087
2268.7	4.05202
2269.65	-1.56363
2270.59	8.19162
2271.53	5.44855
2272.47	12.2434
2273.42	1.75528
2274.36	16.1526
2275.3	1.84038
2276.24	0.92952
2277.18	0.127213
2278.13	-1.56982
2279.07	-3.3743
2280.01	5.15968
2280.95	0.213257
2281.89	-9.43332
2282.83	6.00276
2283.77	2.36835
2284.71	0.726044
2285.65	1.80949
2286.59	8.46199
2287.54	-2.88922
2288.47	0.0916748
2289.41	3.83444
2290.35	-5.00885
2291.29	1.75255
2292.23	-4.80194
2293.17	0.164444
2294.11	-0.697891
2295.05	-5.57886
2295.99	11.6872
2296.93	0.0245056
2297.86	-1.77513
2298.8	5.15111
2299.74	2.4229
2300.68	-1.40076
2301.61	8.36011
2302.55	-0.306519
2303.49	-4.16161
2304.43	11.3518
2305.36	-4.94014
2306.3	3.84047
2307.24	4.86089
2308.17	2.89964
2309.11	2.90286
2310.04	5.97362
2310.98	2.18047
2311.92	2.91772
2312.85	6.64944
2313.79	13.4757
2314.72	5.02292
2315.66	4.18028
2316.59	4.95895
2317.52	9.7417
2318.46	3.99387
2319.39	-5.74284
2320.33	1.94283
2321.26	10.6888
2322.2	4.08763
2323.13	-6.42937
2324.06	20.6953
2325	9.05077
2325.93	26.2547
2326.86	39.6131
2327.79	135.863
2328.73	66.4017
2329.66	17.132
2330.59	20.0056
2331.52	2.64005
2332.46	11.3489
2333.39	1.60559
2334.32	-4.25743
2335.25	5.23711
2336.18	13.8767
2337.11	-2.5341
2338.04	6.05792
2338.97	5.03516
2339.91	-0.760666
2340.84	3.91849
2341.77	1.76036
2342.7	0.627731
2343.63	2.46541
2344.56	-1.42474
2345.49	6.15707
2346.41	0.213272
2347.34	1.05754
2348.27	-4.76541
2349.2	-4.83095
2350.13	-0.374939
2351.06	5.43205
2351.99	1.22101
2352.91	2.77693
2353.84	10.0464
2354.77	0.404572
2355.7	-1.6203
2356.63	2.89091
2357.55	3.49545
2358.48	-4.35252
2359.41	3.0128
2360.33	-5.79523
2361.26	-4.22253
2362.19	7.74908
2363.11	-5.8689
2364.04	3.29617
2364.97	12.4405