File: Data/3-Raman/processed/bu19(2)w-a-ff1-fi04-v_1800 (450-850nm)_532nm_edge_100%_x100_vis_lwd_h100um_30sx2_01.txt
#Acq. time (s)=	30
#Accumulations=	2
#Range (cm-¹)=	1200...2365
#Windows=	3
#Auto scanning=	Off
#Autofocus=	Off
#Macrospot=	Off
#AutoExposure=	Off
#Spike filter=	Multiple accum.
#Delay time (s)=	2
#Binning=	1
#Readout mode=	Signal
#DeNoise=	Off
#ICS correction=	On
#Dark correction=	Off
#Inst. Process=	Off
#Detector Gain=	Best Dynamic
#Detector ADC=	50 kHz HS
#Detector temperature (°C)=	-60.09
#Instrument=	LabRAM HR Evol
#Detector=	SIN-EM FIVIS
#Objective=	x100_VIS_LWD
#Grating=	1800 (450-850nm)
#ND Filter=	100%
#Laser=	532nm_Edge
#Hole=	100.021
#Temperature=	0
#Range=	Visible
#StageXY=	75x50mm Scan+
#StageZ=	Z motor
#X (µm)=	0
#Y (µm)=	0
#Z (µm)=	-14.5
#Full time(mm:ss)=	3:20
#Project=	21_11_26
#Sample=	BU19(2)w
#Site=
#Title=	BU19(2)w-A-FF1-FI04-V_1800 (450-850nm)_532nm_Edge_100%_x100_VIS_LWD_H100um_30sX2
#Remark=
#Date=	26.11.2021 13:26
#Acquired=	26.11.2021 13:26:35
#Base:Fit=	16.12.2021 16:00:56
#Base:Fit=	16.12.2021 16:06:18
#Base:Sub=	16.12.2021 16:06:18
1202.72	12.3732
1203.84	-11.7014
1204.95	2.47223
1206.06	25.9532
1207.17	-14.0769
1208.28	-15.1605
1209.39	13.677
1210.5	-13.964
1211.61	-2.49078
1212.72	0.462555
1213.83	-4.95932
1214.94	-16.474
1216.05	-2.48367
1217.16	8.84595
1218.27	-5.22412
1219.38	-11.6698
1220.49	-10.6294
1221.6	12.6958
1222.71	12.2721
1223.81	15.8472
1224.92	1.7352
1226.03	6.04581
1227.14	-9.81589
1228.25	5.15775
1229.35	8.44516
1230.46	9.53583
1231.57	-3.14612
1232.67	11.5511
1233.78	-2.21356
1234.89	-5.25082
1235.99	10.6503
1237.1	-1.0556
1238.2	-0.567169
1239.31	24.0663
1240.41	8.11987
1241.52	1.785
1242.62	-0.552917
1243.73	4.71033
1244.83	1.45392
1245.94	-3.21112
1247.04	11.1071
1248.14	11.9317
1249.25	2.16168
1250.35	6.20169
1251.45	4.66016
1252.56	17.8046
1253.66	-7.67215
1254.76	3.87872
1255.87	2.74225
1256.97	7.89267
1258.07	31.6532
1259.17	31.2718
1260.27	14.6705
1261.37	54.7371
1262.48	74.3625
1263.58	115.693
1264.68	97.2706
1265.78	46.4601
1266.88	17.0303
1267.98	25.6254
1269.08	6.10663
1270.18	1.74243
1271.28	16.8925
1272.38	13.6188
1273.47	30.6945
1274.57	20.4384
1275.67	37.0965
1276.77	27.8023
1277.87	35.3314
1278.97	40.809
1280.07	70.1711
1281.16	135.223
1282.26	452.246
1283.36	1402.82
1284.45	1610.56
1285.55	297.398
1286.65	102.333
1287.75	59.859
1288.84	41.6844
1289.94	39.6756
1291.03	26.9953
1292.13	22.5753
1293.22	10.8103
1294.32	15.373
1295.42	18.4818
1296.51	20.2669
1297.61	15.8315
1298.7	2.77512
1299.79	17.1939
1300.89	-1.82825
1301.98	11.8165
1303.08	-3.00061
1304.17	-2.23181
1305.26	2.87296
1306.35	-6.04459
1307.45	14.8444
1308.54	-11.6228
1309.63	9.47217
1310.73	-16.9671
1311.82	10.4122
1312.91	-5.3475
1314	-7.69998
1315.09	-5.66504
1316.18	4.99054
1317.28	2.70203
1318.37	0.60907
1319.46	1.58078
1320.55	-12.2499
1321.64	-24.2334
1322.73	10.1353
1323.82	9.89349
1324.91	-7.04819
1326	-2.13168
1327.09	8.69504
1328.18	9.30881
1329.27	10.7719
1330.35	-12.5744
1331.44	-1.38745
1332.53	17.9557
1333.62	-3.69864
1334.71	26.2287
1335.79	9.01611
1336.88	-3.89087
1337.97	6.36224
1339.06	8.06964
1340.14	1.70578
1341.23	2.72144
1342.32	14.0211
1343.4	-0.000488281
1344.49	5.133
1345.58	2.79233
1346.66	8.43405
1347.75	4.75818
1348.83	11.8114
1349.92	-10.4061
1351	3.80728
1352.09	9.69601
1353.17	6.78622
1354.25	-1.18066
1355.34	14.469
1356.42	1.91254
1357.51	6.86371
1358.59	9.67685
1359.67	10.384
1360.76	-2.48322
1361.84	15.9969
1362.92	18.9093
1364	27.2992
1365.09	15.8483
1366.17	10.28
1367.25	18.0664
1368.33	24.219
1369.41	105.983
1370.5	22.0872
1371.58	32.0244
1372.66	23.1119
1373.74	38.2483
1374.82	40.1389
1375.9	37.005
1376.98	38.8329
1378.06	44.8227
1379.14	52.7372
1380.22	71.0253
1381.3	68.9915
1382.38	65.3871
1383.46	103.667
1384.54	121.806
1385.61	412.691
1386.69	1933.39
1387.77	3449.4
1388.85	404.328
1389.93	138.96
1391	85.8218
1392.08	52.6159
1393.16	54.2808
1394.23	19.2859
1395.31	23.3286
1396.39	52.0963
1397.46	16.0285
1398.54	34.3231
1399.62	38.5729
1400.69	26.414
1401.77	32.73
1402.84	8.74869
1403.92	38.8785
1404.99	27.2555
1406.07	40.2759
1407.14	66.7678
1408.22	169.401
1409.29	212.613
1410.37	62.9547
1411.44	38.8853
1412.51	14.18
1413.59	14.263
1414.66	20.9194
1415.73	31.3453
1416.81	16.0437
1417.88	34.6985
1418.95	3.91211
1420.02	-5.4715
1421.1	16.7617
1422.17	1.35074
1423.24	17.5901
1424.31	23.3447
1425.38	7.93814
1426.45	13.1396
1427.52	20.8846
1428.59	5.08145
1429.67	25.6389
1430.74	0.339783
1431.81	17.2325
1432.87	-3.56244
1433.95	3.99091
1435.01	-1.0401
1436.08	1.98178
1437.15	15.1239
1438.22	6.77029
1439.29	3.78558
1440.36	-4.17035
1441.43	-3.08942
1442.49	7.06537
1443.56	17.2388
1444.63	-3.40781
1445.7	5.05545
1446.77	0.76004
1447.83	2.59985
1448.9	19.0722
1449.97	-4.64114
1451.03	-11.0468
1452.1	-5.10266
1453.17	7.10843
1454.23	-7.23938
1455.3	-3.23734
1456.36	4.98688
1457.43	6.79968
1458.49	-6.65695
1459.56	9.73257
1460.62	-1.66891
1461.69	-14.2099
1462.75	-3.29861
1463.82	6.49054
1464.88	3.79712
1465.94	-4.62219
1467.01	8.43372
1468.07	-5.99823
1469.13	-5.1153
1470.2	-1.37936
1471.26	-4.72772
1472.32	0.0618591
1473.39	-11.2921
1474.45	-8.51801
1475.51	-1.41431
1476.57	-4.69855
1477.63	6.20029
1478.69	5.95636
1479.76	-17.7721
1480.82	5.06042
1481.88	-12.4322
1482.94	-12.2488
1484	-13.2859
1485.06	8.10095
1486.12	-8.32935
1487.18	-14.4624
1488.24	5.49097
1489.3	14.1629
1490.36	-6.28696
1491.42	7.55292
1492.48	-15.8461
1493.53	-10.9436
1494.59	-12.0716
1495.65	12.923
1496.71	0.294434
1497.77	-4.97369
1498.82	5.99899
1499.88	2.957
1500.94	13.9849
1502	-3.44818
1503.05	-2.70367
1504.11	8.07272
1505.17	-13.1737
1506.22	10.5396
1507.28	6.43201
1508.34	3.29733
1509.39	4.19644
1510.45	16.2391
1511.5	5.6723
1512.56	-0.276093
1513.61	7.18576
1514.67	3.31549
1515.72	-4.18588
1516.78	8.36111
1517.83	2.16074
1518.88	-2.81747
1519.94	-6.83887
1520.99	8.03741
1522.05	17.0238
1523.1	8.69711
1524.15	4.09445
1525.2	6.79858
1526.26	1.84152
1527.31	-6.08185
1528.36	14.6858
1529.41	11.401
1530.47	3.14395
1531.52	-0.716583
1532.57	2.10333
1533.62	8.43427
1534.67	-9.67975
1535.72	-4.97791
1536.77	16.3665
1537.82	-3.22238
1538.87	5.39993
1539.92	3.89096
1540.97	0.438141
1542.02	8.07135
1543.07	-4.48166
1544.12	-20.0724
1545.17	-1.94379
1546.22	-18.6993
1547.27	7.30682
1548.32	5.96405
1549.37	-9.41547
1550.42	1.61105
1551.46	-5.33432
1552.51	6.60101
1553.56	-9.88751
1554.61	0.718872
1555.65	1.22803
1556.7	-7.94745
1557.75	5.01276
1558.79	7.55237
1559.84	20.9476
1560.89	-5.38132
1561.93	-4.43146
1562.98	5.66437
1564.02	-7.5394
1565.07	11.6749
1566.11	-9.91379
1567.16	-2.35599
1568.2	11.8345
1569.25	5.81332
1570.29	2.48248
1571.34	0.349335
1572.38	-5.95755
1573.43	6.64755
1574.47	6.48135
1575.51	17.7591
1576.56	-0.288422
1577.6	5.08954
1578.64	6.47772
1579.69	9.31897
1580.73	4.33905
1581.77	7.02109
1582.81	-16.249
1583.85	18.4163
1584.9	13.34
1585.94	22.165
1586.98	9.77155
1588.02	5.51419
1589.06	-3.41119
1590.1	-3.36926
1591.14	-4.36057
1592.18	12.3661
1593.22	7.87244
1594.26	-10.7347
1595.3	-7.79117
1596.34	-2.08475
1597.38	-11.0887
1598.42	-6.21072
1599.46	-14.6256
1600.5	-3.1066
1601.54	-13.5749
1602.58	2.73749
1603.62	10.1746
1604.66	8.98474
1605.69	-2.94513
1606.73	-6.8161
1607.77	-18.7088
1608.81	-3.13113
1609.84	-11.9852
1610.88	5.22891
1611.92	1.40167
1612.95	-8.936
1613.99	12.1811
1615.03	-7.64191
1616.06	6.90652
1617.1	1.20801
1618.13	0.547607
1619.17	-1.88428
1620.2	4.16327
1621.24	1.89545
1622.27	2.12994
1623.31	0.348206
1624.34	4.25769
1625.38	-2.56122
1626.41	0.403992
1627.45	2.87045
1628.48	-0.297668
1629.51	3.31525
1630.55	4.75134
1631.53	-2.67484
1632.57	1.42432
1633.62	-8.50616
1634.66	-3.51422
1635.71	-2.60211
1636.75	10.9707
1637.8	6.74615
1638.84	1.65787
1639.89	9.49847
1640.93	-16.0576
1641.98	-4.27625
1643.02	5.44684
1644.06	9.28152
1645.11	13.9819
1646.15	6.21457
1647.19	-6.77145
1648.24	3.88174
1649.28	-3.62454
1650.32	15.0394
1651.37	2.61499
1652.41	-3.23737
1653.45	12.4039
1654.49	4.59409
1655.53	2.79184
1656.57	-0.722778
1657.62	-3.69376
1658.66	0.0820007
1659.7	17.5637
1660.74	0.716125
1661.78	21.7347
1662.82	-7.40198
1663.86	-4.40063
1664.9	8.13681
1665.94	-14.1424
1666.98	5.13754
1668.02	0.940979
1669.06	16.8112
1670.1	2.31305
1671.14	6.58185
1672.18	15.3904
1673.21	-8.29181
1674.25	11.5797
1675.29	1.93567
1676.33	-10.8311
1677.37	3.06183
1678.4	-0.118805
1679.44	-12.2686
1680.48	-14.4004
1681.52	1.26172
1682.55	-2.70059
1683.59	17.0291
1684.63	-5.79718
1685.66	3.99698
1686.7	-9.78235
1687.73	15.0204
1688.77	3.96759
1689.81	-7.18918
1690.84	-7.29306
1691.88	-13.052
1692.91	5.65381
1693.95	1.28659
1694.98	21.6541
1696.01	-7.82532
1697.05	16.9414
1698.08	7.72964
1699.12	9.40604
1700.15	7.43082
1701.18	11.2623
1702.22	-5.66736
1703.25	-8.86761
1704.28	-1.10287
1705.32	17.6659
1706.35	5.78995
1707.38	7.35394
1708.41	1.97745
1709.44	13.2095
1710.48	0.400299
1711.51	4.48376
1712.54	10.4034
1713.57	6.81848
1714.6	8.3313
1715.63	-6.30569
1716.66	5.42593
1717.69	1.96585
1718.72	11.016
1719.75	11.8409
1720.78	-5.68491
1721.81	5.64078
1722.84	4.2597
1723.87	0.0745544
1724.9	-1.0097
1725.93	10.0502
1726.96	7.00204
1727.99	-2.79163
1729.02	0.252197
1730.05	-13.6813
1731.07	-5.21558
1732.1	7.87341
1733.13	21.2394
1734.16	-4.4183
1735.18	20.1224
1736.21	1.42648
1737.24	1.25137
1738.26	6.79556
1739.29	4.52066
1740.32	7.71835
1741.34	12.0294
1742.37	25.154
1743.4	1.11188
1744.42	8.57584
1745.45	-2.00891
1746.47	14.1118
1747.5	-5.43799
1748.52	-2.80054
1749.55	2.10168
1750.57	6.30508
1751.6	17.9962
1752.62	1.36603
1753.64	10.573
1754.67	-2.13287
1755.69	14.824
1756.71	-6.48953
1757.74	11.1697
1758.76	10.3936
1759.78	-1.90231
1760.81	11.3325
1761.83	7.27344
1762.85	8.22571
1763.87	15.9175
1764.89	13.4314
1765.92	-0.616302
1766.94	32.7043
1767.96	10.708
1768.98	9.60303
1770	5.04202
1771.02	11.0066
1772.04	21.8638
1773.06	11.6926
1774.08	11.9199
1775.1	6.38437
1776.12	24.9511
1777.14	13.5453
1778.16	13.2988
1779.18	5.3486
1780.2	2.45398
1781.22	15.008
1782.24	6.60248
1783.26	5.97498
1784.28	10.0485
1785.29	16.1046
1786.31	15.0698
1787.33	5.77356
1788.35	4.71899
1789.37	8.26276
1790.38	4.85208
1791.4	10.583
1792.42	13.1494
1793.43	-3.92181
1794.45	7.70093
1795.47	11.9599
1796.48	-0.954468
1797.5	1.33578
1798.51	0.624908
1799.53	4.46561
1800.55	-0.594849
1801.56	6.99646
1802.58	23.4509
1803.59	13.2329
1804.61	6.73376
1805.62	12.9129
1806.64	11.372
1807.65	-0.0404358
1808.66	6.7666
1809.68	7.82718
1810.69	27.2021
1811.7	-8.49438
1812.72	7.99667
1813.73	-6.21222
1814.74	25.1065
1815.76	5.19226
1816.77	14.9883
1817.78	-1.66382
1818.79	9.0683
1819.8	0.533569
1820.82	9.46832
1821.83	2.94733
1822.84	5.09796
1823.85	18.6842
1824.86	-3.52844
1825.87	-2.3717
1826.88	-0.375031
1827.89	-0.216919
1828.9	5.61493
1829.91	1.63931
1830.92	-0.432129
1831.93	1.70239
1832.94	5.86609
1833.95	7.95755
1834.96	7.70148
1835.97	8.04413
1836.98	7.72333
1837.99	3.49454
1839	19.9453
1840	13.8048
1841.01	15.8819
1842.02	-6.12759
1843.03	-2.59631
1844.04	1.29321
1845.04	14.8438
1846.05	1.495
1847.06	3.87436
1848.07	26.5095
1849.07	2.55627
1850.08	-0.624329
1851.09	0.811371
1852.09	2.48633
1853.1	1.53259
1854.1	1.39465
1855.11	1.94196
1856.11	9.22958
1857.12	-24.3269
1858.12	11.9385
1859.13	-0.822388
1860.13	-5.86655
1861.14	1.03894
1862.14	1.30301
1863.15	-1.81143
1864.15	3.58405
1865.15	9.02704
1866.16	-0.0715942
1867.16	-0.750366
1868.16	9.21106
1869.17	7.29297
1870.17	-19.3685
1871.17	-5.14789
1872.17	-3.37094
1873.18	15.3961
1874.18	-6.5769
1875.18	7.29837
1876.18	-3.71298
1877.18	8.17331
1878.18	17.9801
1879.19	5.4967
1880.19	9.65958
1881.19	-14.0259
1882.19	9.99197
1883.19	6.2919
1884.19	3.04129
1885.19	3.29419
1886.19	12.3692
1887.19	-15.0273
1888.19	4.42313
1889.19	-4.58951
1890.19	4.62509
1891.19	-5.43451
1892.18	2.04669
1893.18	14.1334
1894.18	-6.23074
1895.18	-10.1415
1896.18	4.12613
1897.18	-3.07806
1898.17	1.77576
1899.17	7.21017
1900.17	14.4738
1901.16	13.5621
1902.16	-19.9088
1903.16	14.1452
1904.16	0.858856
1905.15	-10.4517
1906.15	-5.87253
1907.14	-10.8171
1908.14	5.24478
1909.14	-1.1044
1910.13	14.3712
1911.13	5.52768
1912.12	10.406
1913.12	6.61423
1914.11	6.86456
1915.11	15.8166
1916.1	5.64798
1917.1	-3.94547
1918.09	0.613342
1919.08	6.59805
1920.08	-4.09503
1921.07	3.59167
1922.06	1.14896
1923.06	-6.42419
1924.05	0.0717468
1925.04	-6.69214
1926.04	-3.51999
1927.03	14.9843
1928.02	-9.31412
1929.01	17.4449
1930	0.789246
1931	2.24377
1931.99	1.30728
1932.98	4.91992
1933.97	-4.43942
1934.96	6.32861
1935.95	14.9453
1936.94	11.7332
1937.93	21.8929
1938.92	7.65118
1939.91	9.86023
1940.9	-5.03326
1941.89	10.6738
1942.88	-12.9433
1943.87	1.1976
1944.86	3.4711
1945.85	5.85681
1946.84	-8.13797
1947.83	14.8175
1948.82	9.09601
1949.8	-17.3506
1950.79	1.48154
1951.78	16.591
1952.77	-7.95529
1953.76	13.2979
1954.74	2.87808
1955.73	7.52496
1956.72	-1.27927
1957.7	6.87344
1958.69	-0.524261
1959.68	-8.26852
1960.66	-9.35651
1961.65	0.998138
1962.63	-0.830902
1963.62	5.07626
1964.61	3.37115
1965.59	-3.31573
1966.58	-6.85358
1967.56	14.5713
1968.55	-3.53235
1969.53	6.90186
1970.52	19.9605
1971.5	-8.98489
1972.48	-5.06256
1973.47	13.1618
1974.45	6.27423
1975.44	0.648895
1976.42	-0.961975
1977.4	3.95868
1978.39	1.92554
1979.37	9.55801
1980.35	4.90033
1981.33	-4.8067
1982.31	-0.0672913
1983.3	-5.96075
1984.28	6.29422
1985.26	7.15891
1986.24	0.434418
1987.22	-6.01135
1988.21	23.4175
1989.19	27.1847
1990.17	8.2092
1991.15	10.1127
1992.13	21.5569
1993.11	15.958
1994.09	6.21735
1995.07	21.5421
1996.05	9.88275
1997.03	14.7241
1998.01	24.0589
1998.99	8.27213
1999.97	10.4465
2000.95	18.4492
2001.92	12.9444
2002.9	20.774
2003.88	12.7268
2004.86	8.77652
2005.84	22.5482
2006.81	14.1468
2007.79	16.433
2008.77	10.1068
2009.75	8.77838
2010.73	1.11005
2011.7	19.1417
2012.68	20.6133
2013.67	21.1411
2014.66	-2.03348
2015.64	14.7863
2016.63	5.70032
2017.62	7.04376
2018.61	-0.947968
2019.6	3.19748
2020.58	4.99158
2021.57	6.99124
2022.56	12.6008
2023.55	12.2988
2024.54	13.9027
2025.52	3.15771
2026.51	-1.74765
2027.5	8.86325
2028.48	23.4162
2029.47	14.9096
2030.45	3.40527
2031.44	11.1909
2032.43	-1.67258
2033.41	-5.66296
2034.4	-4.54721
2035.38	0.524323
2036.37	-1.21667
2037.35	-2.14749
2038.34	16.5594
2039.32	8.93964
2040.31	-0.636566
2041.29	23.3179
2042.27	-1.9194
2043.26	-11.2777
2044.24	2.41611
2045.23	-10.7513
2046.21	-5.06711
2047.19	10.5467
2048.17	-0.125305
2049.16	-11.0571
2050.14	-10.4372
2051.12	18.0606
2052.11	3.9465
2053.09	-6.03125
2054.07	9.54681
2055.05	-2.31473
2056.03	1.37408
2057.01	-2.34784
2058	11.9365
2058.98	10.5675
2059.96	10.9385
2060.94	7.1933
2061.92	9.40594
2062.9	19.0358
2063.88	-9.57086
2064.86	8.57065
2065.84	-2.10324
2066.82	12.4143
2067.8	4.32114
2068.78	-4.70615
2069.76	-6.53104
2070.73	2.99506
2071.71	-9.716
2072.69	-5.18842
2073.67	12.7975
2074.65	-5.75388
2075.63	25.1205
2076.6	4.08334
2077.58	-1.61749
2078.56	-11.9192
2079.54	11.1442
2080.51	9.875
2081.49	-11.6893
2082.47	6.44281
2083.45	10.4633
2084.42	4.94647
2085.4	4.20361
2086.37	15.8729
2087.35	9.77771
2088.32	-5.05365
2089.3	12.2439
2090.28	-0.52951
2091.25	-1.15002
2092.23	-5.37708
2093.2	11.4844
2094.18	10.1927
2095.15	-5.69229
2096.13	13.2656
2097.1	1.94186
2098.07	10.416
2099.05	1.01147
2100.02	3.04089
2101	-2.37582
2101.97	4.73337
2102.94	7.74594
2103.92	0.130737
2104.89	4.21133
2105.86	-21.9
2106.83	0.345459
2107.8	5.3237
2108.78	-0.599518
2109.75	11.9502
2110.72	-5.8042
2111.69	7.66397
2112.66	-22.6525
2113.63	-7.97116
2114.61	8.45224
2115.58	-4.6506
2116.55	-6.53265
2117.52	-15.0301
2118.49	-2.63959
2119.46	-8.5387
2120.43	-4.84744
2121.4	5.88315
2122.37	-1.11655
2123.34	-14.9011
2124.31	13.7565
2125.28	-17.8796
2126.25	-7.80939
2127.21	-11.7509
2128.18	-5.08871
2129.15	-10.6162
2130.12	-8.61017
2131.09	-9.45923
2132.06	4.68549
2133.02	2.76089
2133.99	0.129883
2134.96	9.80527
2135.93	-0.449219
2136.89	14.4641
2137.86	6.284
2138.83	16.716
2139.79	5.72125
2140.76	0.876556
2141.73	0.045105
2142.69	1.93079
2143.66	-3.18481
2144.62	-8.47723
2145.59	18.0867
2146.55	11.6454
2147.52	-3.34357
2148.48	7.94824
2149.45	20.1136
2150.42	3.89151
2151.38	9.63379
2152.34	7.24692
2153.31	11.0767
2154.27	-0.16571
2155.24	-8.01169
2156.2	-9.25998
2157.16	-3.58286
2158.13	-7.87302
2159.09	-3.85336
2160.05	-6.67078
2161.01	-3.08612
2161.98	9.11838
2162.94	-0.0129089
2163.9	-3.6998
2164.86	2.75754
2165.83	-3.54883
2166.79	14.2926
2167.75	6.75729
2168.71	-1.03363
2169.67	3.98871
2170.63	-5.52307
2171.59	10.4175
2172.56	-2.13693
2173.51	5.37427
2174.48	15.0053
2175.44	5.01822
2176.4	-1.35321
2177.36	-3.11047
2178.32	-1.93463
2179.28	-6.5925
2180.23	1.08459
2181.19	12.3809
2182.15	2.26044
2183.11	13.4647
2184.07	15.1561
2185.03	-12.5507
2185.99	11.9198
2186.95	2.27545
2187.9	-5.41208
2188.86	-1.64044
2189.82	4.65125
2190.78	-1.78763
2191.73	-10.7443
2192.69	-6.67493
2193.65	-8.99887
2194.6	11.3192
2195.56	4.06955
2196.52	2.0321
2197.47	-2.7536
2198.43	-1.60294
2199.38	1.8613
2200.34	12.895
2201.3	7.30307
2202.25	3.40103
2203.21	-0.331696
2204.16	4.12851
2205.12	7.35089
2206.07	-4.54745
2207.03	-5.28424
2207.98	-0.169189
2208.93	10.6225
2209.89	0.735229
2210.84	1.07364
2211.8	-0.306244
2212.75	15.108
2213.7	5.83722
2214.66	-2.13443
2215.61	-18.4556
2216.56	-6.99976
2217.51	13.7231
2218.47	-0.957855
2219.42	0.386871
2220.37	-8.52325
2221.32	19.6601
2222.27	1.77255
2223.23	-0.774292
2224.18	8.19968
2225.13	-3.30487
2226.08	14.1613
2227.03	23.1517
2227.98	19.8573
2228.93	4.05026
2229.88	-6.00931
2230.83	1.12961
2231.78	0.772705
2232.73	-5.26718
2233.68	7.47995
2234.63	9.74936
2235.58	4.04434
2236.53	-16.4669
2237.48	-4.79987
2238.43	7.2764
2239.38	-0.501556
2240.33	10.8794
2241.27	2.80069
2242.22	-0.633881
2243.17	-9.70731
2244.12	9.24985
2245.07	1.16605
2246.01	-0.966766
2246.96	0.47937
2247.91	9.40787
2248.85	1.9978
2249.8	15.491
2250.75	-8.01053
2251.69	1.38828
2252.64	17.7982
2253.59	-6.00693
2254.53	4.05716
2255.48	0.543243
2256.42	21.7457
2257.37	-0.512207
2258.32	-16.2303
2259.26	-14.9141
2260.2	-5.00644
2261.15	3.96301
2262.1	-12.6768
2263.04	32.5026
2263.98	9.39172
2264.93	-15.5854
2265.87	4.95715
2266.81	16.4652
2267.76	2.08472
2268.7	13.5339
2269.65	-3.14096
2270.59	10.9495
2271.53	-14.3397
2272.47	-15.8033
2273.42	10.3412
2274.36	-5.60101
2275.3	10.0455
2276.24	16.1293
2277.18	10.9851
2278.13	-13.206
2279.07	7.45337
2280.01	-4.1004
2280.95	-4.22522
2281.89	11.1819
2282.83	-1.79105
2283.77	6.57004
2284.71	5.52231
2285.65	-3.60266
2286.59	2.19431
2287.54	-9.65628
2288.47	9.06705
2289.41	1.31256
2290.35	0.119354
2291.29	-1.52637
2292.23	-4.75018
2293.17	6.40469
2294.11	8.77435
2295.05	9.78256
2295.99	-0.773041
2296.93	-1.78931
2297.86	-13.8138
2298.8	11.8506
2299.74	-6.85733
2300.68	4.03058
2301.61	1.58966
2302.55	19.2055
2303.49	3.97034
2304.43	-5.32593
2305.36	-14.508
2306.3	-6.3887
2307.24	1.66223
2308.17	10.4921
2309.11	-2.82983
2310.04	0.653778
2310.98	16.5037
2311.92	-14.7526
2312.85	10.2611
2313.79	7.7254
2314.72	3.6347
2315.66	-5.54996
2316.59	-0.927216
2317.52	3.04324
2318.46	9.15317
2319.39	15.9272
2320.33	-9.03302
2321.26	-6.75327
2322.2	3.47049
2323.13	-4.74271
2324.06	13.9722
2325	17.0089
2325.93	25.5286
2326.86	35.0988
2327.79	129.502
2328.73	107.471
2329.66	12.056
2330.59	27.6852
2331.52	16.3196
2332.46	-6.44733
2333.39	1.27936
2334.32	-3.46051
2335.25	-0.579193
2336.18	0.631348
2337.11	-1.14001
2338.04	-3.86206
2338.97	18.4134
2339.91	7.12766
2340.84	12.9261
2341.77	1.19388
2342.7	-7.48938
2343.63	-19.7839
2344.56	-6.13452
2345.49	7.45447
2346.41	-4.10556
2347.34	-9.72067
2348.27	-17.1621
2349.2	14.6953
2350.13	-1.9122
2351.06	-17.6702
2351.99	-1.75104
2352.91	-2.0817
2353.84	-9.05978
2354.77	1.6377
2355.7	-5.76028
2356.63	13.2327
2357.55	4.41409
2358.48	-10.8002
2359.41	2.52838
2360.33	-7.93182
2361.26	-17.559
2362.19	-0.663757
2363.11	3.89856
2364.04	1.97556
2364.97	0.996765