File: Data/3-Raman/processed/bu19w-c-ore1-fi06-v_150 (500nm)_532nm_edge_100%_x100_vis_h50um_15sx2_01_0.txt
#Acq. time (s)=	15
#Accumulations=	2
#Range (cm-¹)=	100...5000
#Windows=	1
#Auto scanning=	Off
#Autofocus=	Off
#Macrospot=	Off
#AutoExposure=	Off
#Spike filter=	Multiple accum.
#Delay time (s)=	2
#Binning=	1
#Readout mode=	Signal
#DeNoise=	Off
#ICS correction=	On
#Dark correction=	Off
#Inst. Process=	Off
#Detector Gain=	Best Dynamic
#Detector ADC=	50 kHz HS
#Detector temperature (°C)=	-60.09
#Instrument=	LabRAM HR Evol
#Detector=	SIN-EM FIVIS
#Objective=	x100_VIS
#Grating=	150 (500nm)
#ND Filter=	100%
#Laser=	532nm_Edge
#Hole=	49.98
#Temperature=	0
#Range=	Visible
#StageXY=	75x50mm Scan+
#StageZ=	Z motor
#X (µm)=	0
#Y (µm)=	0
#Z (µm)=	-3.2
#Full time(s)=	35
#Project=	21_05_14
#Sample=	BU19w
#Site=
#Title=	BU19w-FF-ore1-FI06-V_150 (500nm)_532nm_Edge_100%_x100_VIS_H50um_15sX2
#Remark=
#Date=	14.05.2021 18:47
#Acquired=	14.05.2021 18:47:31
#Base:Fit=	16.12.2021 17:39:50
#Base:Sub=	16.12.2021 18:01:27
102.699	1045.07
107.322	907.904
111.942	739.5
116.56	653.29
121.173	595.458
125.787	492.756
130.398	453.966
135.006	412.865
139.613	358.617
144.215	336.423
148.817	484.822
153.417	950.85
158.014	1045.12
162.607	429.132
167.2	181.124
171.79	157.413
176.379	218.257
180.963	687.727
185.547	834.219
190.128	533.035
194.705	214.662
199.282	44.257
203.857	19.2606
208.43	61.4913
212.998	2.16003
217.566	-2.18335
222.132	131.579
226.693	377.461
231.254	532.431
235.813	654.267
240.368	1330.69
244.923	996.333
249.475	380.769
254.023	152.177
258.571	114.824
263.117	302.314
267.658	965.157
272.199	2336.41
276.738	2653.83
281.273	1350.34
285.807	523.01
290.34	320.494
294.868	337.325
299.396	410.355
303.919	301.659
308.443	244.178
312.964	294.597
317.481	502.624
321.998	1013.18
326.51	1196.74
331.023	740.13
335.533	594.424
340.039	990.133
344.544	1471.13
349.046	1304.95
353.547	740.759
358.045	508.412
362.542	543.593
367.036	635.825
371.527	370.595
376.017	260.526
380.503	345.415
384.99	452.265
389.471	571.533
393.953	395.36
398.43	162.52
402.908	119.216
407.381	130.919
411.854	231.889
416.323	191.699
420.791	104.292
425.256	22.2171
429.72	16.194
434.18	-0.578003
438.64	0.511597
443.095	14.5298
447.551	85.8994
452.003	126.146
456.454	110.003
460.901	78.2877
465.348	104.042
469.791	113.378
474.231	153.071
478.672	267.36
483.108	339.206
487.544	461.663
491.976	522.932
496.408	502.134
500.836	380.318
505.261	234.06
509.687	138.55
514.108	95.158
518.529	57.552
522.946	72.2929
527.361	82.411
531.776	63.8027
536.187	92.6493
540.595	104.098
545.003	210.588
549.408	162.863
553.812	161.137
558.212	132.739
562.61	92.7007
567.007	109.375
571.401	81.4171
575.792	222.177
580.184	539.131
584.571	905.443
588.956	757.34
593.341	348.031
597.722	322.978
602.101	471.698
606.48	604.43
610.854	424.42
615.227	221.993
619.597	113.828
623.967	108.954
628.334	163.359
632.698	220.076
637.06	254.407
641.422	185.852
645.779	202.558
650.135	268.078
654.491	410.774
658.842	597.693
663.192	687.358
667.539	787.609
671.884	805.541
676.23	696.117
680.571	408.852
684.91	228.266
689.247	111.561
693.583	72.6417
697.916	43.7844
702.247	50.0482
706.576	33.933
710.902	37.2221
715.229	46.8275
719.551	44.3414
723.872	34.4379
728.19	25.0546
732.506	29.6785
736.82	45.9494
741.134	57.2877
745.444	67.986
749.752	110.182
754.058	182.806
758.362	251.533
762.664	362.359
766.964	690.012
771.264	1039.52
775.559	1117.23
779.853	849.807
784.144	475.158
788.434	283.249
792.722	208.026
797.007	129.888
801.29	100.876
805.572	60.1345
809.851	55.7896
814.13	51.5893
818.406	23.1246
822.679	41.0298
826.95	7.26855
831.219	37.4031
835.486	39.9581
839.752	29.2149
844.015	16.1131
848.276	11.3726
852.535	29.7269
856.792	77.8075
861.047	57.4752
865.3	25.9306
869.551	38.2657
873.8	6.48663
878.047	23.9878
882.292	21.4933
886.534	2.36322
890.775	15.3824
895.014	-1.4729
899.251	40.0854
903.486	12.8406
907.719	1.72852
911.95	-2.42163
916.179	8.42206
920.406	23.5645
924.63	37.7719
928.853	41.049
933.074	59.4211
937.293	75.3677
941.51	174.623
945.723	176.207
949.936	160.962
954.147	87.2758
958.356	93.6344
962.563	125.558
966.768	81.052
970.971	71.7947
975.172	29.7476
979.371	76.8816
983.568	35.0778
987.761	79.9702
991.954	69.1965
996.145	50.485
1000.33	36.1603
1004.52	35.679
1008.71	47.0408
1012.89	66.7101
1017.07	82.1481
1021.25	80.5143
1025.43	120.132
1029.6	168.355
1033.77	221.127
1037.95	344.405
1042.11	644.211
1046.28	1181.76
1050.45	1303.19
1054.61	966.197
1058.77	643.097
1062.93	411.757
1067.09	332.87
1071.24	348.379
1075.4	409.882
1079.55	679.376
1083.7	1029.9
1087.85	1233.85
1091.99	1059.25
1096.14	900.844
1100.28	982.079
1104.42	1204.06
1108.55	1219.91
1112.69	1048.43
1116.82	885.686
1120.96	943.273
1125.09	1029.96
1129.21	1098.49
1133.34	927.009
1137.46	653.842
1141.59	532.494
1145.71	548.606
1149.83	662.051
1153.94	795.563
1158.06	696.787
1162.17	483.894
1166.28	382.311
1170.39	278.359
1174.5	185.669
1178.6	162.068
1182.7	148.77
1186.8	128.776
1190.9	194.695
1195	170.122
1199.1	173.945
1203.19	155.277
1207.28	107.321
1211.37	183.025
1215.46	259.352
1219.54	356.586
1223.63	317.977
1227.71	266.917
1231.79	362.352
1235.87	468.832
1239.95	423.931
1244.02	296.397
1248.09	278.404
1252.16	213.694
1256.23	148.078
1260.3	127.498
1264.36	290.164
1268.43	1459.34
1272.49	629.022
1276.55	127.18
1280.6	104.728
1284.66	66.9361
1288.71	66.3195
1292.76	75.6167
1296.81	93.9628
1300.86	55.7583
1304.91	67.8206
1308.95	56.7319
1312.99	55.4906
1317.03	55.0298
1321.07	71.6045
1325.11	60.6225
1329.14	59.8544
1333.18	73.8547
1337.21	45.6152
1341.24	61.3677
1345.26	83.0032
1349.29	119.515
1353.31	112.192
1357.33	115.811
1361.35	166.937
1365.37	248.786
1369.39	1132.29
1373.4	2181.75
1377.41	489.034
1381.43	123.95
1385.43	117.838
1389.44	127.561
1393.45	213.423
1397.45	161.624
1401.45	73.1678
1405.45	48.8102
1409.45	42.2428
1413.44	32.7571
1417.44	15.3506
1421.43	10.7309
1425.42	23.6738
1429.41	5.79285
1433.39	27.5844
1437.38	27.5518
1441.36	21.6213
1445.34	29.3766
1449.32	-0.379456
1453.3	9.20233
1457.27	17.7416
1461.24	15.2513
1465.22	45.0841
1469.19	29.738
1473.15	32.1121
1477.12	0.034729
1481.09	12.0574
1485.05	6.40601
1489.01	34.9435
1492.97	8.86145
1496.93	19.8751
1500.88	20.2772
1504.83	4.30042
1508.79	15.6823
1512.74	21.2288
1516.68	21.9885
1520.63	20.8697
1524.57	25.6115
1528.52	22.6685
1532.46	56.618
1536.4	21.7512
1540.33	35.3684
1544.27	33.4774
1548.2	30.6259
1552.14	33.5485
1556.07	44.1118
1559.99	22.6461
1563.92	45.635
1567.84	31.8073
1571.77	40.1907
1575.69	44.6911
1579.61	53.9813
1583.52	32.39
1587.44	36.7932
1591.35	47.9206
1595.27	55.1777
1599.18	62.4572
1603.09	55.4218
1606.99	64.7694
1610.9	52.0771
1614.8	69.1849
1618.7	56.6212
1622.6	52.694
1626.5	75.7021
1630.39	47.1673
1634.29	67.5652
1638.18	46.8231
1642.07	65.554
1645.96	57.5472
1649.85	69.7209
1653.73	69.4152
1657.62	46.0017
1661.5	50.3608
1665.38	50.7607
1669.26	41.4178
1673.13	52.1191
1677.01	37.6574
1680.88	30.5839
1684.75	33.0533
1688.62	35.4238
1692.49	32.8799
1696.35	19.7401
1700.22	12.2389
1704.08	40.8178
1707.94	38.7368
1711.8	29.0182
1715.66	46.8235
1719.51	32.4639
1723.37	35.1068
1727.22	16.9568
1731.07	54.2286
1734.92	42.6539
1738.76	27.2964
1742.61	33.4333
1746.45	28.6295
1750.29	5.61426
1754.13	8.89856
1757.97	25.9165
1761.81	3.32538
1765.64	25.0377
1769.47	35.0942
1773.31	1.56866
1777.14	23.9588
1780.96	13.9365
1784.79	21.7041
1788.61	25.8013
1792.43	-1.95459
1796.25	27.4835
1800.07	26.6636
1803.89	23.713
1807.71	29.215
1811.52	17.6416
1815.33	17.1702
1819.14	24.0202
1822.95	-2.27606
1826.76	16.5668
1830.56	32.391
1834.37	30.1682
1838.17	51.3698
1841.97	25.4109
1845.77	29.5228
1849.56	35.3796
1853.36	23.1889
1857.15	55.6812
1860.94	19.9111
1864.73	56.7949
1868.52	29.6205
1872.31	32.2722
1876.09	45.161
1879.87	40.6572
1883.66	21.578
1887.43	30.558
1891.21	52.7787
1894.99	26.1797
1898.76	2.51086
1902.53	53.5896
1906.31	32.9525
1910.08	5.07526
1913.84	36.3284
1917.61	15.2348
1921.37	62.791
1925.14	1.15918
1928.9	29.5039
1932.66	23.5197
1936.41	51.0717
1940.17	44.1235
1943.92	52.2635
1947.68	54.229
1951.43	38.1075
1955.18	27.3008
1958.92	58.4332
1962.67	42.5438
1966.41	55.6917
1970.16	67.5495
1973.9	59.5762
1977.64	17.7844
1981.37	38.6417
1985.11	24.7858
1988.84	23.971
1992.57	56.4928
1996.31	52.577
2000.03	37.4702
2003.76	54.8781
2007.49	70.1241
2011.21	39.2532
2014.93	60.1112
2018.65	54.7501
2022.37	49.6888
2026.09	43.1536
2029.81	13.6226
2033.52	43.2755
2037.23	47.1224
2040.94	56.5008
2044.65	56.6246
2048.36	37.6592
2052.07	59.9874
2055.77	54.0362
2059.47	45.8497
2063.17	27.7444
2066.87	47.3986
2070.57	73.5975
2074.27	50.9264
2077.96	77.3121
2081.65	36.0547
2085.34	50.9396
2089.03	67.7755
2092.72	60.7969
2096.41	81.8376
2100.09	50.4664
2103.77	55.2573
2107.46	67.369
2111.14	57.1017
2114.81	66.3369
2118.49	48.4233
2122.16	32.1421
2125.84	69.6112
2129.51	94.8333
2133.18	54.3204
2136.85	71.0763
2140.51	34.1833
2144.18	45.2079
2147.84	61.6895
2151.5	69.8657
2155.16	64.3138
2158.82	81.678
2162.48	60.7606
2166.13	71.0031
2169.79	64.1057
2173.44	48.3811
2177.09	65.4838
2180.74	84.4525
2184.38	60.6655
2188.03	61.7516
2191.67	86.727
2195.32	77.3737
2198.96	70.7982
2202.6	41.4896
2206.23	85.3204
2209.87	69.8944
2213.5	73.7278
2217.14	90.4327
2220.77	64.0094
2224.4	64.2064
2228.03	64.3566
2231.65	86.7396
2235.28	62.9553
2238.9	67.7779
2242.52	61.4689
2246.14	44.9045
2249.76	57.2158
2253.38	47.249
2256.99	44.7407
2260.6	55.2637
2264.21	56.4251
2267.82	62.4348
2271.44	64.6971
2275.04	59.1558
2278.65	72.2143
2282.25	46.2539
2285.85	27.0059
2289.45	40.7109
2293.05	49.6779
2296.65	35.9747
2300.25	52.5206
2303.84	42.3945
2307.43	64.3828
2311.02	108.089
2314.62	300.48
2318.2	155.295
2321.79	56.3392
2325.38	39.559
2328.96	49.2913
2332.54	30.5686
2336.12	51.3964
2339.7	41.9785
2343.28	77.5912
2346.85	53.9611
2350.43	48.1606
2354	48.8791
2357.57	34.6428
2361.14	44.615
2364.71	48.9999
2368.27	47.9156
2371.84	72.8065
2375.4	25.5248
2378.96	51.3023
2382.52	43.0158
2386.08	36.6727
2389.64	45.1591
2393.19	51.9521
2396.75	44.2863
2400.3	49.7369
2403.85	39.8441
2407.4	27.3103
2410.95	25.113
2414.49	49.6598
2418.04	52.3275
2421.58	31.1669
2425.12	19.3326
2428.66	30.6965
2432.2	31.1157
2435.74	46.4908
2439.27	21.036
2442.81	54.2543
2446.34	12.8986
2449.87	33.3412
2453.4	28.338
2456.93	18.0571
2460.45	51.7662
2463.98	54.1742
2467.5	50.8467
2471.02	47.3846
2474.54	36.4882
2478.06	23.01
2481.58	45.2334
2485.09	36.9496
2488.61	38.0748
2492.12	39.2704
2495.63	44.0433
2499.14	39.5464
2502.65	46.0333
2506.15	33.759
2509.66	53.1273
2513.16	36.3147
2516.66	44.7443
2520.16	54.6987
2523.66	28.8917
2527.16	38.5601
2530.66	26.1345
2534.15	44.3593
2537.64	18.4089
2541.13	33.3187
2544.62	38.4118
2548.11	41.7236
2551.6	35.8851
2555.08	19.2773
2558.57	22.1019
2562.05	20.5267
2565.53	9.83728
2569.01	28.217
2572.49	22.4694
2575.96	41.2371
2579.44	31.9138
2582.91	19.7223
2586.38	42.441
2589.85	26.0004
2593.32	44.4885
2596.79	31.7436
2600.25	18.9863
2603.72	48.0761
2607.18	24.967
2610.64	25.177
2614.1	32.3763
2617.56	45.1249
2621.02	40.4537
2624.47	31.7584
2627.92	25.8474
2631.38	32.293
2634.83	18.3909
2638.28	38.8925
2641.72	24.7552
2645.17	24.0051
2648.61	47.9326
2652.06	26.874
2655.5	22.8471
2658.94	49.0994
2662.38	27.8682
2665.82	20.8899
2669.25	28.9291
2672.69	10.7318
2676.12	40.4761
2679.55	37.4998
2682.98	11.3506
2686.41	32.264
2689.84	27.4367
2693.26	-5.49884
2696.69	25.9482
2700.11	21.1807
2703.53	12.5526
2706.95	25.789
2710.37	32.6863
2713.79	23.8878
2717.2	17.9989
2720.62	33.6467
2724.03	13.8963
2727.44	22.2095
2730.85	13.6611
2734.26	18.2043
2737.66	27.4543
2741.07	30.045
2744.47	5.26996
2747.87	32.173
2751.28	24.2939
2754.67	12.5111
2758.07	45.066
2761.47	19.0553
2764.86	17.4496
2768.26	42.1036
2771.65	36.5691
2775.04	15.86
2778.43	8.2533
2781.82	24.1306
2785.2	1.39661
2788.59	36.9726
2791.97	24.5336
2795.35	28.1365
2798.73	12.8319
2802.11	23.8094
2805.49	30.0852
2808.87	33.5079
2812.24	1.3623
2815.62	43.9691
2818.99	32.4415
2822.36	26.636
2825.73	2.23285
2829.1	31.037
2832.46	32.9217
2835.83	12.5515
2839.19	34.2166
2842.55	46.6986
2845.91	26.75
2849.27	25.7196
2852.63	21.7509
2855.99	29.063
2859.34	18.7092
2862.69	16.7886
2866.05	25.2153
2869.4	27.9794
2872.75	48.5926
2876.09	28.7634
2879.44	13.599
2882.78	28.5313
2886.13	30.2333
2889.47	14.0374
2892.81	35.4503
2896.15	29.3824
2899.49	35.514
2902.82	16.0117
2906.16	21.0668
2909.49	37.413
2912.82	29.1566
2916.16	40.6584
2919.49	25.6282
2922.81	20.9943
2926.14	25.6993
2929.46	65.3218
2932.79	50.0043
2936.11	25.2822
2939.43	51.488
2942.75	18.3408
2946.07	35.1553
2949.39	41.586
2952.7	27.3155
2956.02	38.5157
2959.33	38.543
2962.64	42.3065
2965.95	51.8361
2969.26	19.4085
2972.57	48.7769
2975.87	46.4982
2979.17	43.1497
2982.48	62.3608
2985.78	35.6281
2989.08	46.4652
2992.38	38.5487
2995.68	64.5069
2998.97	74.5154
3002.27	65.687
3005.56	64.4434
3008.85	56.6417
3012.14	68.6501
3015.43	75.943
3018.72	51.1657
3022	57.5
3025.29	64.8025
3028.57	59.8316
3031.85	63.3359
3035.14	100.854
3038.41	74.0865
3041.69	116.39
3044.97	83.9579
3048.24	84.6284
3051.52	108.087
3054.79	79.3979
3058.06	80.0178
3061.33	124.129
3064.6	101.89
3067.87	115.621
3071.13	131.664
3074.4	116.767
3077.66	143.595
3080.92	140.47
3084.18	151.717
3087.44	115.625
3090.7	139.511
3093.95	144.665
3097.21	131.849
3100.46	163.728
3103.71	175.874
3106.96	172.844
3110.21	181.021
3113.46	209.178
3116.71	182.152
3119.95	204.651
3123.2	204.29
3126.44	221.059
3129.68	228.311
3132.92	214.587
3136.16	217.983
3139.4	237.569
3142.63	254.297
3145.87	259.629
3149.1	292.654
3152.33	259.85
3155.56	276.657
3158.79	306.813
3162.02	303.58
3165.25	323.196
3168.47	344.654
3171.69	316.452
3174.92	324.447
3178.14	405.864
3181.36	371.87
3184.58	374.049
3187.79	388.574
3191.01	405.944
3194.22	442.351
3197.43	431.091
3200.65	417.962
3203.86	426.771
3207.07	457.506
3210.27	435.961
3213.48	465.873
3216.69	459.65
3219.89	479.132
3223.09	488.246
3226.29	485.03
3229.49	507.591
3232.69	482.511
3235.89	507.088
3239.08	489.889
3242.28	497.505
3245.47	522.285
3248.66	530.969
3251.85	530.176
3255.04	526.529
3258.23	552.358
3261.42	537.942
3264.6	550.112
3267.79	566.941
3270.97	555.027
3274.15	532.61
3277.33	594.072
3280.51	541.656
3283.68	557.981
3286.86	565.615
3290.04	551.388
3293.21	582.898
3296.38	628.619
3299.55	607.958
3302.72	623.282
3305.89	608.017
3309.06	623.014
3312.22	649.288
3315.39	657.459
3318.55	672.207
3321.71	641.462
3324.87	653.372
3328.03	660.552
3331.19	691.415
3334.34	679.841
3337.5	713.691
3340.65	698.46
3343.81	716.475
3346.96	729.189
3350.11	757.003
3353.25	738.76
3356.4	780.906
3359.55	771.372
3362.69	800.545
3365.84	825.087
3368.98	816.66
3372.12	827.261
3375.26	869.105
3378.4	879.913
3381.53	850.953
3384.67	901.511
3387.8	917.14
3390.94	953.694
3394.07	961.283
3397.2	969.606
3400.33	1048.4
3403.46	1124.65
3406.58	1194.51
3409.71	1416.86
3412.83	2140.19
3415.96	3832.91
3419.08	5985.71
3422.2	5129.82
3425.32	2822.9
3428.44	1710.8
3431.55	1289.44
3434.67	1152.11
3437.78	1078.93
3440.89	1018.27
3444	1009.77
3447.12	978.363
3450.22	982.962
3453.33	979.923
3456.44	969.054
3459.54	979.074
3462.65	968.118
3465.75	970.351
3468.85	1044.19
3471.95	1084.22
3475.05	1069.43
3478.15	1137.05
3481.24	1227.28
3484.34	1379.82
3487.43	1556.88
3490.53	1899.62
3493.62	2369.66
3496.71	2878.73
3499.79	3274.64
3502.88	3164.26
3505.97	2690.56
3509.05	2149.48
3512.14	1638.11
3515.22	1330.35
3518.3	1138.78
3521.38	1017.32
3524.46	922.451
3527.54	832.282
3530.61	787.182
3533.69	712.12
3536.76	680.289
3539.83	648.324
3542.9	579.961
3545.97	560.681
3549.04	561.073
3552.11	505.469
3555.18	511.466
3558.24	470.239
3561.3	465.691
3564.37	436.424
3567.43	446.996
3570.49	426.127
3573.55	431.702
3576.61	416.375
3579.66	407.615
3582.72	399.723
3585.77	369.998
3588.82	359.167
3591.87	322.706
3594.92	345.905
3597.97	311.289
3601.02	306.942
3604.07	312.941
3607.11	290.539
3610.16	269.08
3613.2	266.506
3616.24	258.286
3619.28	250.11
3622.32	241.967
3625.36	248.014
3628.39	225.78
3631.43	205.405
3634.46	244.452
3637.5	197.027
3640.53	184.5
3643.56	182.483
3646.59	152.141
3649.62	155.75
3652.64	145.54
3655.67	102.268
3658.69	127.973
3661.72	123.498
3664.74	111.235
3667.76	80.1313
3670.78	68.8597
3673.79	67.9849
3676.81	80.3629
3679.83	67.2274
3682.84	63.5267
3685.86	71.1862
3688.87	55.2029
3691.88	52.4763
3694.89	54.4012
3697.9	56.3845
3700.91	51.7556
3703.91	71.8118
3706.92	39.5814
3709.92	42.4534
3712.92	43.3644
3715.92	56.6604
3718.92	9.01105
3721.92	52.6926
3724.92	21.1205
3727.92	30.4574
3730.91	30.2307
3733.91	30.9059
3736.9	22.9715
3739.89	19.7482
3742.88	34.5613
3745.87	11.2856
3748.86	15.5548
3751.85	32.1485
3754.83	24.0573
3757.82	22.6116
3760.8	29.6635
3763.78	27.2315
3766.76	29.5632
3769.74	23.4196
3772.72	29.6093
3775.7	15.9751
3778.67	12.7734
3781.65	14.3057
3784.62	12.0807
3787.6	12.7101
3790.57	40.7705
3793.54	10.3567
3796.51	21.4971
3799.47	10.0341
3802.44	17.4839
3805.41	7.94653
3808.37	40.0069
3811.33	32.3995
3814.3	-0.741882
3817.26	2.06003
3820.22	1.08578
3823.18	27.6063
3826.13	26.6825
3829.09	13.4216
3832.04	25.7962
3835	17.3235
3837.95	24.9985
3840.9	29.8261
3843.85	34.6644
3846.8	11.9021
3849.75	8.19034
3852.69	14.0236
3855.64	17.0055
3858.58	17.1321
3861.53	13.4089
3864.47	12.5483
3867.41	9.73947
3870.35	26.0848
3873.29	20.37
3876.22	23.246
3879.16	28.0017
3882.1	16.373
3885.03	18.1556
3887.96	19.9179
3890.89	34.1659
3893.82	17.5965
3896.75	11.5496
3899.68	28.5708
3902.61	27.26
3905.53	13.493
3908.46	14.1261
3911.38	21.4486
3914.3	23.914
3917.23	35.0951
3920.15	36.6166
3923.06	27.526
3925.98	15.5279
3928.9	24.5868
3931.81	16.4678
3934.73	7.47769
3937.64	14.8596
3940.55	25.089
3943.46	29.5774
3946.37	21.6559
3949.28	-4.42609
3952.19	10.6777
3955.09	27.7353
3958	-0.210571
3960.9	32.2254
3963.8	11.9695
3966.71	4.1861
3969.61	25.2016
3972.51	26.0686
3975.4	10.5833
3978.3	22.9225
3981.2	21.8029
3984.09	42.7753
3986.99	20.4766
3989.88	25.0342
3992.77	28.6957
3995.66	14.0751
3998.55	20.6411
4001.43	26.2513
4004.32	18.3966
4007.21	3.79694
4010.09	26.781
4012.98	14.0955
4015.86	30.3474
4018.74	25.371
4021.62	21.3541
4024.5	23.1375
4027.37	17.1892
4030.25	40.2543
4033.13	15.9359
4036	19.6793
4038.87	12.7773
4041.75	29.0573
4044.62	27.8974
4047.49	14.1566
4050.35	6.2399
4053.22	0.282654
4056.09	12.775
4058.95	20.3999
4061.82	42.6068
4064.68	21.0754
4067.54	29.6758
4070.4	12.9711
4073.26	36.1702
4076.12	20.4119
4078.98	27.0539
4081.83	25.9
4084.69	20.8325
4087.54	30.3857
4090.4	30.1995
4093.25	13.4055
4096.1	14.1745
4098.95	5.17929
4101.8	-0.907288
4104.64	28.1883
4107.49	29.8815
4110.33	19.8146
4113.18	38.0811
4116.02	24.0058
4118.86	33.3954
4121.7	29.1172
4124.54	5.29025
4127.38	49.0488
4130.22	20.4536
4133.05	19.3392
4135.89	30.7725
4138.72	5.52927
4141.56	5.90518
4144.39	19.3332
4147.22	46.501
4150.05	11.9551
4152.88	31.143
4155.7	11.025
4158.53	27.1287
4161.36	8.11694
4164.18	17.4745
4167	19.0103
4169.82	36.2123
4172.65	-0.360443
4175.46	23.7006
4178.28	30.1733
4181.1	20.041
4183.92	19.7002
4186.73	24.2648
4189.55	26.9054
4192.36	36.4489
4195.17	22.5306
4197.98	25.274
4200.79	45.6707
4203.6	58.241
4206.41	17.7885
4209.21	22.4848
4212.02	42.905
4214.83	17.2258
4217.63	19.1661
4220.43	8.23651
4223.23	23.9017
4226.03	21.8213
4228.83	25.7101
4231.63	31.6083
4234.42	26.6462
4237.22	32.599
4240.01	33.6021
4242.81	16.7037
4245.6	24.6733
4248.39	20.6538
4251.18	30.5918
4253.97	29.5259
4256.76	18.4217
4259.55	26.3493
4262.33	35.3108
4265.12	22.1999
4267.9	25.1609
4270.68	18.0414
4273.47	18.9291
4276.25	42.9753
4279.03	23.5856
4281.8	15.2569
4284.58	16.9925
4287.36	22.7389
4290.13	20.3658
4292.91	1.80243
4295.68	16.7026
4298.45	26.5374
4301.22	25.2004
4303.99	34.0127
4306.76	42.8407
4309.53	27.311
4312.3	29.032
4315.06	17.4798
4317.83	15.055
4320.59	12.6028
4323.35	11.1462
4326.11	27.0022
4328.87	10.2523
4331.63	13.8648
4334.39	21.5458
4337.15	20.074
4339.9	22.7101
4342.66	35.5576
4345.41	2.54163
4348.17	22.5779
4350.92	17.1512
4353.67	11.7348
4356.42	21.6256
4359.17	27.4268
4361.91	33.2415
4364.66	15.4971
4367.41	20.2859
4370.15	9.67563
4372.89	0.0457458
4375.63	10.9274
4378.38	16.6638
4381.12	13.1656
4383.86	27.1897
4386.59	38.2493
4389.33	27.7784
4392.07	19.4979
4394.8	24.5982
4397.53	29.5775
4400.27	19.0176
4403	9.46146
4405.73	26.901
4408.46	31.8849
4411.19	26.4236
4413.92	16.7569
4416.64	21.5896
4419.37	14.9319
4422.09	3.0896
4424.82	29.881
4427.54	32.6678
4430.26	19.7603
4432.98	28.8052
4435.7	11.6561
4438.42	5.99136
4441.13	34.9175
4443.85	28.1926
4446.57	22.4995
4449.28	12.5846
4451.99	25.7586
4454.71	33.6687
4457.42	20.537
4460.13	21.0859
4462.83	34.2694
4465.54	8.53146
4468.25	23.8444
4470.95	10.7513
4473.66	10.3154
4476.36	19.3921
4479.07	27.444
4481.77	29.1744
4484.47	6.57718
4487.17	25.1945
4489.87	27.9088
4492.56	11.4599
4495.26	15.1943
4497.96	16.8147
4500.65	28.981
4503.34	21.0473
4506.04	4.63486
4508.73	18.9759
4511.42	11.0414
4514.11	23.2872
4516.8	24.9169
4519.48	11.7051
4522.17	13.3736
4524.85	3.32072
4527.54	35.8688
4530.22	3.44769
4532.9	29.6539
4535.58	8.93373
4538.27	30.9379
4540.94	28.3758
4543.62	5.49644
4546.3	18.9824
4548.98	11.0651
4551.65	26.7944
4554.33	-1.46581
4557	9.01012
4559.67	12.0203
4562.34	25.8826
4565.01	19.4002
4567.68	20.3905
4570.35	14.5477
4573.02	14.9595
4575.68	17.7002
4578.35	29.211
4581.01	11.5535
4583.67	23.0484
4586.34	2.93259
4589	12.2123
4591.66	17.1184
4594.31	11.1922
4596.97	27.0442
4599.63	17.8227
4602.29	19.5606
4604.94	12.5319
4607.59	12.0809
4610.25	18.2046
4612.9	-9.73267
4615.55	13.9745
4618.2	26.7413
4620.85	15.2838
4623.5	23.6362
4626.14	26.4602
4628.79	3.88531
4631.43	7.76768
4634.08	12.7306
4636.72	19.9178
4639.36	9.37164
4642	22.1355
4644.64	26.1183
4647.28	21.2833
4649.92	0.935226
4652.56	12.9563
4655.19	18.8816
4657.83	10.564
4660.46	2.28989
4663.1	11.8863
4665.73	23.6267
4668.36	11.9134
4670.99	25.9407
4673.62	20.9259
4676.24	23.7531
4678.87	20.9593
4681.5	23.7778
4684.12	25.478
4686.75	9.16875
4689.37	22.1358
4691.99	-6.60782
4694.61	0.689514
4697.23	2.35857
4699.85	8.55002
4702.47	23.7571
4705.09	8.45035
4707.7	25.9176
4710.32	4.91997
4712.93	28.0546
4715.55	24.0009
4718.16	26.7505
4720.77	18.1265
4723.38	25.4095
4725.99	11.1677
4728.6	12.8021
4731.21	13.304
4733.81	9.25995
4736.42	29.0554
4739.02	21.5816
4741.63	11.7926
4744.23	29.3096
4746.83	4.66972
4749.43	21.0034
4752.03	16.8545
4754.63	11.5529
4757.23	0.578186
4759.82	27.199
4762.42	7.13686
4765.01	9.88852
4767.61	18.4161
4770.2	5.19911
4772.79	7.95178
4775.38	17.5627
4777.97	8.89912
4780.56	19.6556
4783.15	8.70303
4785.74	0.0268555
4788.32	22.2448
4790.91	14.7316
4793.49	3.77054
4796.07	18.043
4798.66	9.40598
4801.24	20.2885
4803.82	5.93292
4806.4	27.2441
4808.98	12.886
4811.55	10.0413
4814.13	2.5806
4816.71	19.3961
4819.28	8.48015
4821.85	33.4526
4824.43	19.0526
4827	25.503
4829.57	21.5436
4832.14	1.26575
4834.71	18.2765
4837.28	14.337
4839.84	-0.135223
4842.41	30.9987
4844.97	11.7407
4847.54	19.4225
4850.1	2.28833
4852.66	7.34911
4855.22	23.3339
4857.78	25.2201
4860.34	22.3427
4862.9	13.4566
4865.46	9.2426
4868.01	13.4103
4870.57	17.529
4873.12	5.01642
4875.68	15.0277
4878.23	9.61024
4880.78	10.1066
4883.33	14.1642
4885.88	19.4181
4888.43	18.7371
4890.98	8.51819
4893.53	14.9614
4896.07	5.9052
4898.62	13.5346
4901.16	5.64977
4903.7	14.4795
4906.25	12.5367
4908.79	6.99104
4911.33	16.9401
4913.87	19.7068
4916.41	12.9229
4918.94	-2.21382
4921.48	8.9326
4924.02	14.1172
4926.55	28.8544
4929.08	12.5386
4931.62	20.1826
4934.15	18.2604
4936.68	25.8974
4939.21	16.7186
4941.74	9.9389
4944.27	12.7976
4946.79	18.0602
4949.32	7.74786
4951.85	-0.182541
4954.37	11.0909
4956.9	14
4959.42	10.921
4961.94	16.2994
4964.46	22.9418
4966.98	11.4907
4969.5	12.0495
4972.02	19.8518
4974.53	10.7392
4977.05	7.66435
4979.57	11.8552
4982.08	14.8459
4984.59	-1.56316
4987.1	1.43015
4989.62	10.5036
4992.13	18.3702
4994.64	8.00208
4997.15	8.60695
4999.65	21.4236