File: Data/3-Raman/processed/bu19w-d-ff2-fi07-v_1800 (450-850nm)_532nm_edge_100%_x100_vis_lwd_h50um_30sx2_01.txt
#Acq. time (s)=	30
#Accumulations=	2
#Range (cm-¹)=	1200...2365
#Windows=	3
#Auto scanning=	Off
#Autofocus=	Off
#Macrospot=	Off
#AutoExposure=	Off
#Spike filter=	Multiple accum.
#Delay time (s)=	2
#Binning=	1
#Readout mode=	Signal
#DeNoise=	Off
#ICS correction=	On
#Dark correction=	Off
#Inst. Process=	Off
#Detector Gain=	Best Dynamic
#Detector ADC=	50 kHz HS
#Detector temperature (°C)=	-60.09
#Instrument=	LabRAM HR Evol
#Detector=	SIN-EM FIVIS
#Objective=	x100_VIS_LWD
#Grating=	1800 (450-850nm)
#ND Filter=	100%
#Laser=	532nm_Edge
#Hole=	49.98
#Temperature=	0
#Range=	Visible
#StageXY=	75x50mm Scan+
#StageZ=	Z motor
#X (µm)=	0
#Y (µm)=	0
#Z (µm)=	58.6
#Full time(mm:ss)=	3:23
#Project=	21_11_22
#Sample=	BU19w
#Site=
#Title=	BU19w-D-FF2-FI07-V_1800 (450-850nm)_532nm_Edge_100%_x100_VIS_LWD_H50um_30sX2
#Remark=
#Date=	22.11.2021 13:19
#Acquired=	22.11.2021 13:19:23
#Base:Fit=	16.12.2021 17:39:50
#Base:Fit=	16.12.2021 17:44:18
#Base:Sub=	16.12.2021 17:44:19
1202.84	12.5977
1203.95	5.39817
1205.06	6.842
1206.17	11.5176
1207.29	10.8934
1208.39	11.3125
1209.51	11.7577
1210.62	4.79379
1211.72	6.41261
1212.84	0.600533
1213.94	3.27152
1215.05	2.78399
1216.16	-1.90588
1217.27	-1.25877
1218.38	0.473915
1219.49	2.18193
1220.6	-2.46704
1221.71	-3.88693
1222.81	-2.07304
1223.92	3.97408
1225.03	-0.607616
1226.14	2.19256
1227.24	4.20234
1228.35	11.2079
1229.46	21.5131
1230.56	29.7218
1231.67	34.8383
1232.78	49.4442
1233.88	54.5466
1234.99	48.001
1236.09	37.2941
1237.2	21.4464
1238.3	20.3237
1239.41	9.75012
1240.51	9.71259
1241.62	2.32989
1242.72	1.20719
1243.83	10.5771
1244.93	4.27578
1246.03	19.9347
1247.14	23.0826
1248.24	25.1336
1249.34	37.6439
1250.45	44.93
1251.55	41.8954
1252.65	36.7496
1253.75	29.5228
1254.86	28.538
1255.96	18.1464
1257.06	19.3261
1258.16	19.3528
1259.26	17.4945
1260.36	13.2753
1261.46	14.6445
1262.56	26.2064
1263.66	53.5091
1264.76	23.4087
1265.86	7.93541
1266.96	8.09079
1268.06	-0.17379
1269.16	-1.05473
1270.26	1.26099
1271.36	3.57622
1272.46	1.66243
1273.56	-5.46905
1274.66	3.15437
1275.76	6.54355
1276.85	4.64641
1277.95	3.7921
1279.05	14.5537
1280.15	24.2118
1281.24	48.514
1282.34	171.101
1283.44	754.717
1284.53	450.379
1285.63	64.2345
1286.73	26.6109
1287.82	15.2717
1288.92	6.01464
1290.01	7.29526
1291.11	5.47453
1292.21	9.93855
1293.3	0.768505
1294.4	2.05895
1295.49	4.38386
1296.58	2.49156
1297.68	-1.4789
1298.77	-0.175838
1299.87	-0.977608
1300.96	1.36389
1302.05	0.549519
1303.15	-2.40233
1304.24	-1.10966
1305.33	1.24965
1306.42	1.50685
1307.52	2.81617
1308.61	-0.0973511
1309.7	1.22358
1310.79	1.45933
1311.88	4.87588
1312.98	-3.30589
1314.07	-3.0642
1315.16	0.360794
1316.25	-2.56075
1317.34	2.96746
1318.43	-1.0357
1319.52	1.28727
1320.61	0.462914
1321.7	4.92554
1322.79	-0.125347
1323.88	-3.09757
1324.97	1.40774
1326.06	2.74492
1327.15	0.867455
1328.23	3.18512
1329.32	-2.94603
1330.41	-0.647484
1331.5	3.75052
1332.59	0.805368
1333.67	-1.08168
1334.76	3.32744
1335.85	3.52836
1336.94	-2.5314
1338.02	2.93161
1339.11	1.04808
1340.2	3.33393
1341.28	-0.633926
1342.37	5.84331
1343.45	3.9233
1344.54	5.13967
1345.63	1.16698
1346.71	6.56369
1347.8	1.54208
1348.88	7.96531
1349.96	5.07005
1351.05	7.39462
1352.13	3.35442
1353.22	4.58914
1354.3	6.84696
1355.39	5.98305
1356.47	7.19015
1357.55	10.4581
1358.63	8.56277
1359.72	11.8431
1360.8	5.82529
1361.88	8.07849
1362.97	14.4398
1364.05	7.33941
1365.13	15.7825
1366.21	14.934
1367.29	16.1296
1368.37	20.3973
1369.45	24.6257
1370.54	10.329
1371.62	15.6327
1372.7	18.8833
1373.78	11.8161
1374.86	19.1639
1375.94	21.4513
1377.02	17.4605
1378.09	18.5539
1379.18	28.9355
1380.25	29.0072
1381.33	29.1204
1382.41	36.4936
1383.49	49.0078
1384.57	76.6327
1385.65	178.231
1386.72	1238.58
1387.8	610.34
1388.88	95.6106
1389.96	53.6716
1391.03	37.3945
1392.11	27.2806
1393.19	27.418
1394.26	23.421
1395.34	23.5279
1396.42	21.6147
1397.49	17.6483
1398.57	16.7534
1399.64	13.8408
1400.72	24.2488
1401.79	19.1936
1402.87	25.4238
1403.94	21.4115
1405.02	20.498
1406.09	26.7609
1407.17	46.3595
1408.24	106.852
1409.31	66.9578
1410.39	26.1905
1411.46	12.8814
1412.53	18.1179
1413.61	9.99848
1414.68	10.0952
1415.75	13.2652
1416.82	10.2552
1417.9	10.3101
1418.97	13.4668
1420.04	12.578
1421.11	12.5534
1422.18	10.569
1423.26	13.7279
1424.33	12.7399
1425.4	10.7286
1426.47	7.72892
1427.54	8.83961
1428.61	12.0148
1429.68	6.92987
1430.75	6.95199
1431.82	5.9923
1432.89	8.09731
1433.96	7.11934
1435.02	4.09314
1436.09	6.2008
1437.16	2.1671
1438.23	3.24691
1439.3	11.4949
1440.37	7.43836
1441.43	6.452
1442.5	2.41068
1443.57	4.49748
1444.64	3.50489
1445.7	3.55049
1446.77	5.63681
1447.84	1.56289
1448.9	3.64142
1449.97	5.72412
1451.04	1.6626
1452.1	0.669016
1453.17	1.72931
1454.23	0.727541
1455.3	1.77809
1456.36	1.80947
1457.43	4.90733
1458.49	1.85193
1459.56	3.91085
1460.62	-2.21805
1461.69	2.93853
1462.75	2.90404
1463.81	0.878424
1464.88	2.93573
1465.94	0.912674
1467	1.9395
1468.07	3.98527
1469.13	-0.0819798
1470.19	-1.08661
1471.25	-0.0611153
1472.32	0.974171
1473.38	-0.0354919
1474.44	-2.06448
1475.5	0.992653
1476.56	-2.05502
1477.62	-0.0296211
1478.68	0.988955
1479.75	-3.04992
1480.81	1.02382
1481.87	0.997152
1482.93	0.998144
1483.99	-1.01832
1485.05	1.00629
1486.11	-0.0136318
1487.17	2.01084
1488.22	-0.0159893
1489.28	0.998068
1490.34	-2.03259
1491.4	2.0142
1492.46	-1.02119
1493.52	-1.03355
1494.58	-1.03547
1495.63	0.984144
1496.69	-3.04808
1497.75	2.00206
1498.81	0.986496
1499.86	-1.03699
1500.92	-0.0365238
1501.98	-1.04323
1503.03	1.96506
1504.09	0.958233
1505.15	-0.0502262
1506.2	0.956324
1507.26	-0.0501862
1508.31	-2.08055
1509.37	-1.10556
1510.42	0.882753
1511.48	-3.12691
1512.53	0.873716
1513.59	-2.15355
1514.64	-2.15893
1515.7	-2.1567
1516.75	0.853807
1517.8	-3.16462
1518.86	-0.155626
1519.91	-1.16929
1520.96	-1.19041
1522.02	-0.199791
1523.07	-1.19892
1524.12	1.81239
1525.17	-0.202705
1526.23	-1.21471
1527.28	-1.22354
1528.33	-0.215805
1529.38	-1.22458
1530.43	0.793083
1531.48	2.79773
1532.53	0.779287
1533.59	3.75483
1534.64	0.72765
1535.69	-3.28578
1536.74	-1.26856
1537.79	-1.24758
1538.84	-0.259142
1539.89	-1.28071
1540.94	-1.30252
1541.98	-0.296652
1543.03	2.71988
1544.08	-0.285458
1545.13	-0.297758
1546.18	-2.3121
1547.23	-0.309933
1548.28	0.738768
1549.33	-2.27655
1550.37	0.719635
1551.42	3.7114
1552.47	3.69005
1553.52	3.68522
1554.56	2.68359
1555.61	-2.33971
1556.65	-1.35886
1557.7	-3.36802
1558.75	-0.369387
1559.79	3.63759
1560.84	-1.36813
1561.88	2.64524
1562.93	3.52032
1563.98	2.60529
1565.02	4.61823
1566.07	-0.377172
1567.11	-0.386538
1568.15	1.61082
1569.2	-1.39503
1570.24	-1.40493
1571.29	1.58755
1572.33	1.60501
1573.37	1.60766
1574.42	1.58647
1575.46	2.56273
1576.5	-1.42576
1577.55	0.573992
1578.59	1.56409
1579.63	-1.43368
1580.67	2.54892
1581.72	1.55538
1582.76	1.55629
1583.8	-1.44134
1584.84	-0.449972
1585.88	-1.43714
1586.92	1.55823
1587.96	-0.425486
1589	-2.41717
1590.04	1.55207
1591.08	2.52275
1592.12	-0.450737
1593.16	2.52734
1594.2	0.546997
1595.24	1.5457
1596.28	1.53425
1597.32	0.534929
1598.36	1.51214
1599.4	0.509405
1600.44	-0.488987
1601.48	1.49059
1602.51	-1.46826
1603.55	-2.44449
1604.59	0.533171
1605.63	0.538193
1606.66	1.51814
1607.7	-0.424913
1608.74	-0.424004
1609.77	-2.9831
1610.81	0.620777
1611.85	-1.17933
1612.88	1.87088
1613.92	3.02119
1614.95	-0.177944
1615.99	0.146929
1617.03	0.972105
1618.06	0.305124
1619.1	-1.7107
1620.13	0.419907
1621.17	1.43543
1622.2	-1.10003
1623.23	-0.466448
1624.27	-0.253952
1625.3	-0.836472
1626.34	0.829302
1627.37	1.58069
1628.4	3.56294
1629.44	0.886824
1630.47	1.5066
1631.29	1.25523
1632.33	0.280039
1633.38	2.25492
1634.42	2.2547
1635.47	-1.67773
1636.51	-1.66737
1637.56	-0.671412
1638.6	0.327986
1639.65	2.30406
1640.69	-0.639446
1641.73	-2.60253
1642.78	1.3497
1643.82	-1.59573
1644.86	-0.605498
1645.91	1.38175
1646.95	0.416836
1647.99	1.42791
1649.03	-0.524492
1650.08	-0.514813
1651.12	3.44216
1652.16	1.48991
1653.2	-0.451382
1654.24	2.52629
1655.28	0.559763
1656.33	1.55025
1657.37	-0.414284
1658.41	-0.390202
1659.45	1.59494
1660.49	0.652348
1661.53	1.63576
1662.57	1.63438
1663.61	-1.27462
1664.65	0.684413
1665.69	-2.26624
1666.72	0.726017
1667.76	0.750543
1668.8	0.763579
1669.84	-0.207854
1670.88	-1.17956
1671.92	-1.15772
1672.96	0.841909
1674	-1.12126
1675.03	0.867013
1676.07	-0.119087
1677.11	-0.110723
1678.15	0.886213
1679.18	2.87569
1680.22	-1.062
1681.25	0.926066
1682.29	-1.03897
1683.33	-1.02392
1684.36	0.971984
1685.4	-0.00761509
1686.43	-0.00312138
1687.47	0.00329971
1688.51	1.99809
1689.54	2.0147
1690.58	-1.93022
1691.61	1.02782
1692.64	-0.927601
1693.68	-0.907817
1694.71	-1.88733
1695.75	-0.899256
1696.78	2.06534
1697.81	2.0759
1698.85	-1.85022
1699.88	0.119757
1700.91	0.130248
1701.95	0.147574
1702.98	-0.822889
1704.01	-1.80314
1705.04	0.157906
1706.08	1.13123
1707.11	-0.819103
1708.14	0.178404
1709.17	-1.76317
1710.2	-1.76726
1711.23	-1.77004
1712.27	1.17035
1713.3	0.211267
1714.33	0.208478
1715.36	0.195231
1716.39	2.14702
1717.42	2.1608
1718.45	-0.758435
1719.48	1.18488
1720.51	0.212987
1721.54	1.19317
1722.56	-1.72331
1723.59	-1.71816
1724.62	-0.744348
1725.65	1.19344
1726.68	-0.764513
1727.71	0.211055
1728.74	0.240655
1729.76	-0.718227
1730.79	0.242555
1731.82	1.19829
1732.85	0.229878
1733.87	0.234557
1734.9	1.19962
1735.93	1.19788
1736.95	0.227038
1737.98	2.13542
1739.01	2.13318
1740.03	-1.69034
1741.06	0.22854
1742.08	-0.722047
1743.11	0.242086
1744.13	0.237661
1745.16	-0.718771
1746.18	-0.706537
1747.21	0.269554
1748.23	2.20079
1749.26	1.24216
1750.28	-0.670768
1751.31	1.23592
1752.33	-2.57661
1753.35	0.280449
1754.38	4.07761
1755.4	1.23584
1756.42	-0.656098
1757.44	1.25341
1758.47	-1.59986
1759.49	-3.49638
1760.51	0.317813
1761.53	-1.56837
1762.56	-0.599537
1763.58	-3.44689
1764.6	-2.48993
1765.62	-2.48733
1766.64	0.348763
1767.66	0.361537
1768.68	1.33184
1769.7	0.396425
1770.72	1.36264
1771.74	-0.529917
1772.76	-1.4628
1773.78	0.45387
1774.8	-1.45381
1775.82	-0.505298
1776.84	0.444666
1777.86	0.4582
1778.88	1.42069
1779.9	-0.467901
1780.92	-0.454847
1781.94	-0.438792
1782.95	-0.43488
1783.97	2.43702
1784.99	-0.397681
1786.01	-2.2826
1787.03	-3.22393
1788.04	0.617873
1789.06	-1.30769
1790.08	-1.29924
1791.09	-0.333183
1792.11	0.635859
1793.13	-3.17705
1794.14	-0.281307
1795.16	0.692536
1796.17	0.69756
1797.19	0.691717
1798.21	0.690034
1799.22	-0.265018
1800.24	-0.252236
1801.25	-1.20338
1802.27	-0.226917
1803.28	-1.17461
1804.29	-0.202553
1805.31	-1.1625
1806.32	-2.12154
1807.34	0.775821
1808.35	-1.15108
1809.36	-2.11158
1810.38	-1.13739
1811.39	-1.12476
1812.4	-1.11011
1813.41	-2.07138
1814.43	0.827657
1815.44	0.824471
1816.45	0.832897
1817.46	0.841969
1818.47	-0.116087
1819.49	-0.107174
1820.5	2.8003
1821.51	-3.0071
1822.52	0.872442
1823.53	-0.0930643
1824.54	-0.0882635
1825.55	2.82171
1826.56	3.78536
1827.57	1.84404
1828.58	-0.0880222
1829.59	-1.04816
1830.6	6.71219
1831.61	0.894444
1832.62	0.869315
1833.63	-1.97544
1834.64	0.881981
1835.65	-2.04453
1836.65	1.8649
1837.66	-1.06072
1838.67	-1.0858
1839.68	-1.10207
1840.69	0.82968
1841.7	-1.09876
1842.7	0.831307
1843.71	0.856577
1844.72	-0.163303
1845.72	-2.08349
1846.73	0.794785
1847.74	-2.10716
1848.74	-0.195489
1849.75	-1.15714
1850.75	-1.16031
1851.76	-1.17454
1852.76	1.68734
1853.77	-2.1476
1854.78	0.721458
1855.78	0.71034
1856.79	1.6535
1857.79	0.702607
1858.79	-1.20182
1859.8	-1.20803
1860.8	-0.264278
1861.81	-0.274405
1862.81	0.663419
1863.81	-1.26597
1864.82	-0.333902
1865.82	0.613431
1866.82	-2.23992
1867.83	-0.341427
1868.83	1.55529
1869.83	-0.353392
1870.83	0.589775
1871.84	-0.371188
1872.84	-1.33559
1873.84	-0.407278
1874.84	2.39243
1875.84	2.4343
1876.84	1.50262
1877.84	-0.393165
1878.84	-1.35683
1879.84	-0.442138
1880.84	-1.37999
1881.84	0.487163
1882.85	0.505295
1883.85	0.512501
1884.84	0.497084
1885.84	-1.40579
1886.84	-3.29775
1887.84	0.476213
1888.84	-0.467056
1889.84	-1.41273
1890.84	-0.493772
1891.84	0.440427
1892.83	0.444061
1893.83	1.39424
1894.83	-1.42109
1895.83	-1.42595
1896.83	0.444421
1897.82	1.38177
1898.82	-0.486372
1899.82	0.462913
1900.81	-0.482183
1901.81	-0.483535
1902.81	1.39491
1903.8	-0.49614
1904.8	1.38246
1905.79	-0.488043
1906.79	0.464374
1907.79	-1.39858
1908.78	2.37629
1909.78	0.491163
1910.77	-0.445468
1911.77	-0.429567
1912.76	-0.420471
1913.76	-2.31079
1914.75	-0.430579
1915.74	0.520443
1916.74	1.48716
1917.73	-0.396559
1918.72	1.5081
1919.72	-2.27132
1920.71	1.50615
1921.7	0.555133
1922.7	1.50926
1923.69	-1.3095
1924.68	-0.350479
1925.67	-0.342446
1926.66	0.617815
1927.66	2.53502
1928.65	3.4897
1929.64	-1.26163
1930.63	0.636701
1931.62	-0.274114
1932.61	2.62443
1933.61	-1.19572
1934.6	-0.251201
1935.59	-0.254259
1936.58	1.66408
1937.57	2.6301
1938.56	0.744169
1939.55	-0.21172
1940.54	1.70574
1941.52	-1.1502
1942.51	0.776555
1943.5	-0.165037
1944.49	-1.11806
1945.48	0.796117
1946.47	-2.06346
1947.46	0.828565
1948.44	0.85597
1949.43	0.874004
1950.42	0.883878
1951.41	1.81732
1952.39	-0.109426
1953.38	-0.0832796
1954.37	-0.0655088
1955.36	-1.01424
1956.34	0.908845
1957.33	0.90597
1958.31	-1.01979
1959.3	2.82218
1960.29	-0.0505505
1961.27	-0.0424376
1962.26	0.921728
1963.24	1.89228
1964.23	-0.0156174
1965.21	0.951946
1966.2	0.951373
1967.18	-0.0211754
1968.17	2.85243
1969.15	1.89562
1970.14	-2.8966
1971.12	-1.94123
1972.1	-0.019824
1973.09	-0.967043
1974.07	-0.00111103
1975.05	0.956474
1976.04	-0.00360489
1977.02	0.96104
1978	-0.957838
1978.98	2.87299
1979.97	-0.959322
1980.95	-0.965019
1981.93	-1.92151
1982.91	-2.87851
1983.89	0.955886
1984.88	0.952376
1985.86	-0.980623
1986.84	0.902044
1987.82	-0.0386229
1988.8	-0.959754
1989.78	-0.91665
1990.76	1.88714
1991.74	-1.76286
1992.72	-1.53973
1993.7	0.80332
1994.68	-0.448353
1995.66	-1.39723
1996.64	0.870012
1997.62	0.213061
1998.6	-0.94226
1999.57	-1.31216
2000.55	0.669551
2001.53	1.09457
2002.51	1.17832
2003.49	0.432298
2004.47	-0.0400906
2005.44	-0.203224
2006.42	-0.621707
2007.4	0.0544386
2008.38	-1.08415
2009.35	0.291734
2010.33	-0.411649
2011.3	1.62241
2012.18	2.27438
2013.17	-0.531851
2014.16	-1.4542
2015.15	1.35415
2016.14	4.1475
2017.13	0.390347
2018.11	1.32979
2019.1	2.26943
2020.09	0.388506
2021.08	0.379922
2022.06	-2.43438
2023.05	-0.579165
2024.04	0.38032
2025.02	3.19985
2026.01	2.30233
2027	0.384451
2027.98	-0.566289
2028.97	2.24237
2029.96	1.33129
2030.94	0.413367
2031.93	0.379792
2032.91	-0.524605
2033.9	1.34709
2034.88	0.416373
2035.87	-0.524158
2036.85	3.20329
2037.83	-2.40916
2038.82	0.382912
2039.8	0.376492
2040.79	-0.545126
2041.77	-1.47216
2042.75	-2.40236
2043.74	-0.518766
2044.72	-0.541288
2045.7	-1.47547
2046.69	0.400852
2047.67	-0.518184
2048.65	1.34341
2049.63	-2.3902
2050.62	2.29011
2051.6	-0.50326
2052.58	-1.44393
2053.56	-0.514586
2054.54	1.3543
2055.52	2.29821
2056.5	-0.501038
2057.48	-2.37686
2058.46	-0.503913
2059.45	-3.31297
2060.43	-1.43546
2061.4	0.441782
2062.39	-2.3645
2063.37	1.39819
2064.34	-3.29628
2065.32	0.465344
2066.3	1.40342
2067.28	0.448218
2068.26	-0.476611
2069.24	-1.40731
2070.22	0.468909
2071.2	-0.476115
2072.18	-0.469482
2073.15	-0.45446
2074.13	-0.462219
2075.11	1.40921
2076.09	-3.30648
2077.06	-0.467343
2078.04	2.36438
2079.02	2.35555
2080	1.40794
2080.97	0.45484
2081.95	1.39364
2082.93	-2.39287
2083.9	-0.498101
2084.88	1.39228
2085.85	0.440047
2086.83	-0.506537
2087.8	-0.510451
2088.78	-0.511569
2089.75	-0.503685
2090.73	-0.499138
2091.7	1.39944
2092.68	1.38331
2093.65	-1.48197
2094.63	-1.49864
2095.6	-0.563799
2096.57	0.373276
2097.55	0.363685
2098.52	1.31198
2099.5	0.352026
2100.47	-1.56535
2101.44	3.16982
2102.41	1.26871
2103.39	0.315908
2104.36	0.307119
2105.33	-1.61669
2106.3	1.21251
2107.27	0.257017
2108.25	-1.65608
2109.22	-0.724061
2110.19	0.216303
2111.16	-0.740592
2112.13	1.14569
2113.1	-0.773035
2114.07	0.15525
2115.04	2.03612
2116.01	-1.78762
2116.99	1.03084
2117.96	1.0152
2118.92	-1.83385
2119.9	0.0572309
2120.86	0.993408
2121.83	0.015583
2122.8	-0.969505
2123.77	-0.0525255
2124.74	2.75938
2125.71	-1.04219
2126.68	-0.116206
2127.65	0.808562
2128.61	-0.160717
2129.58	-0.185575
2130.55	2.62397
2131.52	-1.16655
2132.48	-0.242406
2133.45	2.55621
2134.42	0.651381
2135.39	0.632984
2136.35	-4.09454
2137.32	-3.18278
2138.28	0.561253
2139.25	0.535001
2140.22	0.532048
2141.18	-0.465957
2142.15	0.460372
2143.12	-0.49999
2144.08	-0.524166
2145.05	-0.550662
2146.01	2.23925
2146.98	-1.54989
2147.94	-1.5777
2148.9	2.16004
2149.87	-1.6118
2150.83	0.235831
2151.8	-1.67369
2152.76	-2.64747
2153.72	2.93
2154.69	0.109786
2155.65	0.0953274
2156.61	-0.865381
2157.58	-0.898355
2158.54	-2.79125
2159.5	-0.0146103
2160.47	-0.972653
2161.43	-1.9325
2162.39	1.77037
2163.35	-1.97826
2164.31	-1.07526
2165.27	1.67416
2166.24	0.723435
2167.2	-0.209232
2168.16	-0.228204
2169.12	-0.271204
2170.08	1.5587
2171.04	-0.317305
2172	0.594248
2172.96	0.571417
2173.92	-0.382998
2174.88	0.526397
2175.84	-0.42988
2176.8	-0.448946
2177.76	0.458512
2178.72	2.29125
2179.68	2.26508
2180.64	-1.47612
2181.59	-1.50303
2182.55	1.26233
2183.51	0.326738
2184.47	0.326366
2185.43	2.16556
2186.38	0.276084
2187.34	1.17264
2188.3	3.93953
2189.26	1.14576
2190.21	0.208913
2191.17	1.14089
2192.13	0.200479
2193.08	-4.47185
2194.04	1.06653
2195	2.90073
2195.95	2.90103
2196.91	2.9093
2197.86	1.06591
2198.82	0.107006
2199.78	-0.857383
2200.73	2.86368
2201.69	2.89323
2202.64	0.965775
2203.59	3.74499
2204.55	0.941658
2205.5	-0.918783
2206.46	1.87013
2207.41	0.929149
2208.37	2.79189
2209.32	2.79456
2210.27	2.78059
2211.23	2.76845
2212.18	1.84348
2213.13	-0.964478
2214.09	-0.0418749
2215.04	3.68534
2215.99	1.81439
2216.94	-0.0519047
2217.9	0.875419
2218.85	1.78884
2219.8	-0.0896025
2220.75	0.849472
2221.7	0.862874
2222.65	0.873975
2223.6	-0.0539761
2224.55	0.890613
2225.5	1.82326
2226.46	0.879795
2227.41	1.82979
2228.36	0.903665
2229.31	2.79616
2230.26	0.928155
2231.21	0.938508
2232.16	1.87286
2233.11	0.923742
2234.05	0.928761
2235	1.89327
2235.95	1.91774
2236.9	0.98186
2237.85	2.86769
2238.8	-1.83443
2239.75	1.00809
2240.69	0.0652533
2241.64	1.96043
2242.59	0.100164
2243.54	3.90375
2244.48	4.86847
2245.43	2.03682
2246.38	1.09641
2247.32	2.05572
2248.27	-0.784737
2249.22	-1.7198
2250.16	-0.744391
2251.11	3.07622
2252.06	-0.697893
2253	-0.681923
2253.95	0.291941
2254.89	-2.53183
2255.84	3.18642
2256.78	0.361106
2257.73	-0.565692
2258.67	-1.48829
2259.62	-0.51275
2260.56	0.474294
2261.51	1.47182
2262.45	0.552794
2263.39	-0.384338
2264.34	-1.32966
2265.28	-1.31695
2266.22	-0.335638
2267.17	-1.24908
2268.11	0.699036
2269.05	-0.222258
2270	1.72034
2270.94	-3.03473
2271.88	0.823474
2272.82	0.853498
2273.77	1.8535
2274.71	-0.977011
2275.65	-0.932994
2276.59	1.01354
2277.53	1.02387
2278.47	-0.8713
2279.41	-2.75432
2280.36	1.1278
2281.3	1.18828
2282.24	-0.689754
2283.18	-1.62496
2284.12	0.342615
2285.06	-1.53587
2286	2.34339
2286.94	0.431115
2287.88	1.42476
2288.82	0.514039
2289.75	0.562148
2290.69	2.53648
2291.63	-0.321835
2292.57	1.63284
2293.51	0.69402
2294.45	-0.225159
2295.39	-2.09899
2296.32	-1.08627
2297.26	-0.0793905
2298.2	-0.0349817
2299.14	1.93698
2300.07	0.0434484
2301.01	1.04855
2301.95	-1.80061
2302.89	1.14283
2303.82	4.08676
2304.76	1.22253
2305.69	-0.674176
2306.63	3.24014
2307.57	0.388479
2308.5	-0.552217
2309.44	-1.49704
2310.37	2.39911
2311.31	3.42447
2312.24	2.51554
2313.18	2.53747
2314.11	1.59331
2315.05	1.63872
2315.98	-1.23293
2316.92	1.69172
2317.85	-0.201053
2318.78	2.74065
2319.72	1.82365
2320.65	3.79306
2321.58	2.85915
2322.52	4.80442
2323.45	5.78599
2324.38	6.76384
2325.32	13.5326
2326.25	23.1865
2327.18	71.3674
2328.11	160.93
2329.05	36.7594
2329.98	13.6358
2330.91	4.02114
2331.84	2.10635
2332.77	2.1236
2333.7	2.13964
2334.63	1.19207
2335.56	-0.718968
2336.5	3.13929
2337.43	2.18325
2338.36	3.13758
2339.29	5.04666
2340.22	1.21163
2341.15	3.13118
2342.08	3.1325
2343.01	0.246281
2343.93	4.06828
2344.86	0.229932
2345.79	5.01324
2346.72	1.15573
2347.65	-0.809169
2348.58	0.179154
2349.51	0.121104
2350.44	1.97842
2351.36	0.0432739
2352.29	0.0195017
2353.22	0.933449
2354.15	-0.0723553
2355.07	2.73182
2356	1.73117
2356.93	1.6784
2357.86	0.665661
2358.78	-1.29798
2359.71	-0.421921
2360.63	-2.38555
2361.56	1.32471
2362.49	-3.48215
2363.41	-2.63146
2364.34	0.133205
2364.8	2.93077