File: Data/3-Raman/processed/bu19w-a-ff07b-fi03-v_150 (500nm)_532nm_edge_100%_x100_vis_lwd_h50um_15sx2_01_0.txt
#Acq. time (s)=	15
#Accumulations=	2
#Range (cm-¹)=	50...5000
#Windows=	1
#Auto scanning=	Off
#Autofocus=	Off
#Macrospot=	Off
#AutoExposure=	Off
#Spike filter=	Multiple accum.
#Delay time (s)=	2
#Binning=	1
#Readout mode=	Signal
#DeNoise=	Off
#ICS correction=	On
#Dark correction=	Off
#Inst. Process=	Off
#Detector Gain=	Best Dynamic
#Detector ADC=	50 kHz HS
#Detector temperature (°C)=	-60.09
#Instrument=	LabRAM HR Evol
#Detector=	SIN-EM FIVIS
#Objective=	x100_VIS_LWD
#Grating=	150 (500nm)
#ND Filter=	100%
#Laser=	532nm_Edge
#Hole=	49.98
#Temperature=	0
#Range=	Visible
#StageXY=	75x50mm Scan+
#StageZ=	Z motor
#X (µm)=	0
#Y (µm)=	0
#Z (µm)=	-48.6
#Full time(s)=	34
#Project=	21_05_28
#Sample=	BU19w
#Site=
#Title=	BU19w-FF07b-FI03-V_150 (500nm)_532nm_Edge_100%_x100_VIS_LWD_H50um_15sX2
#Remark=
#Date=	28.05.2021 15:47
#Acquired=	28.05.2021 15:47:30
#Base:Fit=	16.12.2021 17:39:50
#Base:Sub=	16.12.2021 17:59:24
51.5961	13926.5
56.2453	12077.5
60.8921	9668.14
65.5367	8330.33
70.1768	11147.4
74.8167	9807.55
79.4543	4503.38
84.0897	2647.17
88.7227	1916.36
93.3513	1451.75
97.9798	1152.16
102.606	921.236
107.23	772.713
111.851	691.92
116.469	691.815
121.086	559.485
125.7	388.878
130.313	312.927
134.921	271.702
139.529	248.723
144.134	215.652
148.738	211.578
153.337	94.1731
157.936	79.7061
162.532	155.566
167.126	681.478
171.716	1522.21
176.306	1037.06
180.894	298.572
185.477	252.079
190.06	613.531
194.64	2570.67
199.219	5585.31
203.793	3380.56
208.367	980.49
212.939	233.61
217.506	21.7213
222.073	43.8445
226.638	24.6234
231.199	37.24
235.759	-0.0128174
240.318	174.177
244.872	455.537
249.425	541.558
253.977	1018.48
258.524	1519.14
263.071	1176.78
267.616	771.009
272.156	460.911
276.697	442.68
281.233	1072.24
285.769	2930.2
290.303	5003.84
294.832	3778.49
299.361	1702.37
303.886	971.951
308.411	1273.58
312.934	2272.28
317.452	2150.19
321.97	1121.33
326.484	553.538
330.998	522.843
335.507	943.843
340.017	1555.86
344.524	1329.76
349.027	697.387
353.53	575.726
358.028	856.923
362.527	1082.15
367.021	708.201
371.515	344.157
376.004	226.569
380.494	352.246
384.979	312.916
389.465	230.086
393.946	434.408
398.427	711.113
402.903	891.756
407.38	819.489
411.852	554.518
416.324	329.978
420.792	209.663
425.26	460.819
429.723	645.536
434.187	291.808
438.646	21.743
443.105	1.38489
447.56	-1.83728
452.015	0.659302
456.466	103.975
460.914	577.979
465.362	1359.44
469.807	1339.65
474.251	582.226
478.69	193.731
483.13	141.996
487.566	123.091
491.999	197.896
496.432	336.889
500.861	488.683
505.29	663.503
509.715	636.316
514.138	566.319
518.56	358.787
522.979	258.217
527.395	188.063
531.811	172.512
536.223	141.026
540.635	159.314
545.042	197.201
549.448	239.813
553.853	254.342
558.255	270.17
562.654	255.212
567.053	274.317
571.448	313.102
575.841	275.51
580.232	215.693
584.622	164.173
589.009	235.714
593.393	544.872
597.777	1409.94
602.157	1846.79
606.535	1168.22
610.913	645.516
615.287	619.966
619.659	1036.49
624.029	1380.9
628.398	971.878
632.763	488.226
637.127	241.292
641.488	190.404
645.849	257.814
650.206	311.977
654.561	311.428
658.914	258.23
663.267	235.874
667.615	300.295
671.962	467.996
676.307	654.347
680.649	641.666
684.991	700.247
689.33	867.577
693.666	563.301
698	370.907
702.332	190.325
706.662	110.795
710.992	92.8054
715.318	66.4081
719.641	37.4097
723.963	51.5651
728.283	23.304
732.6	56.587
736.918	-1.54663
741.231	37.0161
745.542	69.2266
749.852	96.082
754.159	65.475
758.464	126.81
762.767	154.069
767.068	192.503
771.369	314.72
775.666	460.345
779.961	780.915
784.254	1352.94
788.545	2128.39
792.834	1981.58
797.12	1287.77
801.405	734.822
805.688	473.648
809.968	308.976
814.247	238.042
818.524	160.737
822.798	126.268
827.071	102.099
831.341	89.0424
835.612	98.02
839.878	39.5925
844.142	97.8639
848.405	76.1088
852.665	72.1736
856.923	122.237
861.18	42.1816
865.434	68.7074
869.686	59.4584
873.936	78.421
878.185	64.0057
882.431	52.541
886.675	46.9937
890.915	64.4916
895.155	1.9823
899.393	38.8964
903.63	66.1171
907.864	33.6532
912.096	49.1823
916.326	55.8573
920.554	74.0439
924.78	50.5763
929.004	75.7842
933.227	69.5261
937.447	85.6245
941.665	104.418
945.881	91.9147
950.095	186.111
954.305	293.251
958.516	369.419
962.724	453.08
966.93	421.004
971.134	465.631
975.337	534.969
979.537	592.819
983.735	476.282
987.93	304.745
992.124	295.425
996.316	220.764
1000.51	145.006
1004.7	164.934
1008.88	173.495
1013.06	181.065
1017.25	186.077
1021.43	192.139
1025.61	182.876
1029.78	184.706
1033.96	221.201
1038.13	273.964
1042.3	313.751
1046.47	404.39
1050.63	552.482
1054.8	886.05
1058.96	1664.74
1063.12	2614.64
1067.28	2411.7
1071.44	1580.4
1075.59	1036.15
1079.74	795.205
1083.89	771.046
1088.04	967.633
1092.19	1327.45
1096.33	2061.5
1100.48	2744.89
1104.62	2588.26
1108.76	2005
1112.89	1654.89
1117.03	1768.01
1121.16	2093.74
1125.29	1964.54
1129.42	1763.76
1133.55	1691.27
1137.68	1866.84
1141.8	2104.38
1145.92	1900.96
1150.04	1574.2
1154.16	1113.79
1158.27	1070.63
1162.39	1296.19
1166.5	1756.13
1170.61	1926.11
1174.72	1449.32
1178.82	1057.2
1182.93	794.325
1187.03	546.663
1191.13	439.042
1195.23	343.484
1199.33	288.542
1203.42	323.997
1207.51	324.557
1211.6	343.413
1215.69	285.504
1219.78	312.71
1223.86	274.741
1227.95	356.699
1232.03	467.109
1236.11	550.878
1240.18	476.915
1244.26	494.449
1248.33	644.591
1252.41	810.959
1256.48	626.397
1260.54	446.037
1264.61	374.793
1268.67	249.785
1272.74	203.016
1276.8	203.314
1280.86	729.96
1284.91	1050.12
1288.97	214.147
1293.02	100.755
1297.07	123.977
1301.12	112.786
1305.17	126.445
1309.21	103.701
1313.25	79.7408
1317.3	117.617
1321.34	68.4678
1325.37	97.1899
1329.41	8.04688
1333.44	100.588
1337.48	75.0164
1341.5	122.249
1345.53	65.248
1349.56	76.1974
1353.59	64.2612
1357.61	94.1658
1361.63	29.6228
1365.65	106.17
1369.66	131.375
1373.68	81.9359
1377.69	92.0608
1381.7	256.158
1385.72	1544.31
1389.72	1057.48
1393.73	211.32
1397.73	68.7112
1401.74	90.3508
1405.74	201.612
1409.73	185.998
1413.73	92.6504
1417.73	83.1107
1421.72	75.515
1425.71	52.8557
1429.7	-1.34082
1433.69	59.1759
1437.67	87.0609
1441.66	32.0425
1445.64	74.4786
1449.62	64.4869
1453.6	90.679
1457.57	73.2831
1461.55	37.8385
1465.52	52.0636
1469.49	83.8359
1473.46	85.3596
1477.43	61.1161
1481.39	88.6156
1485.36	26.8683
1489.32	16.9382
1493.28	41.3232
1497.24	11.101
1501.19	20.0813
1505.15	43.9446
1509.1	58.5613
1513.05	20.8405
1517	21.1212
1520.95	38.0959
1524.9	29.9587
1528.84	3.54504
1532.78	53.9553
1536.72	36.5442
1540.66	64.7433
1544.6	72.5896
1548.53	51.3765
1552.46	59.2253
1556.4	65.8707
1560.32	-4.2605
1564.25	38.6775
1568.18	59.1322
1572.1	58.1533
1576.02	36.86
1579.94	33.8484
1583.86	50.071
1587.78	17.9437
1591.69	57.0499
1595.61	57.5762
1599.52	31.1959
1603.43	70.2932
1607.34	35.7435
1611.24	77.0308
1615.15	41.7349
1619.05	65.1664
1622.95	66.4305
1626.85	78.5209
1630.74	54.4862
1634.64	71.2668
1638.53	73.587
1642.42	62.0494
1646.31	71.0198
1650.2	89.7775
1654.09	53.0011
1657.97	94.7371
1661.86	56.702
1665.74	55.7334
1669.62	93.9652
1673.49	76.7872
1677.37	68.1415
1681.24	97.8328
1685.12	49.2234
1688.99	50.3895
1692.86	55.9314
1696.72	89.8644
1700.59	48.8606
1704.45	39.0292
1708.31	51.6478
1712.17	87.5353
1716.03	39.8816
1719.89	35.9941
1723.74	124.648
1727.6	54.5219
1731.45	35.1077
1735.3	67.4967
1739.14	86.394
1742.99	85.3418
1746.83	100.218
1750.68	42.8213
1754.52	69.8258
1758.36	21.8459
1762.19	42.0443
1766.03	93.3275
1769.86	50.6743
1773.69	109.323
1777.53	72.2799
1781.35	93.6108
1785.18	63.0582
1789	43.8461
1792.83	84.6106
1796.65	52.3698
1800.47	65.0411
1804.29	67.0452
1808.1	75.4844
1811.92	51.6473
1815.73	84.0111
1819.54	81.5389
1823.35	27.582
1827.16	70.4287
1830.97	57.9917
1834.77	81.783
1838.58	41.174
1842.38	48.2821
1846.18	53.944
1849.97	44.8256
1853.77	60.999
1857.56	89.6699
1861.36	63.4583
1865.15	78.9902
1868.93	25.9467
1872.72	103.031
1876.51	73.88
1880.29	86.5059
1884.07	109.176
1887.86	67.4185
1891.63	87.8938
1895.41	88.1654
1899.19	87.5111
1902.96	52.7875
1906.73	69.9926
1910.5	54.2509
1914.27	40.1656
1918.04	56.6514
1921.8	20.8798
1925.57	47.2365
1929.33	32.292
1933.09	75.1318
1936.85	55.6602
1940.6	61.2479
1944.36	42.4812
1948.11	53.6248
1951.87	56.5961
1955.61	89.7203
1959.36	65.4138
1963.11	79.8523
1966.86	57.5397
1970.6	43.0193
1974.34	48.3767
1978.08	39.238
1981.82	108.351
1985.56	35.8087
1989.29	75.1805
1993.02	46.0767
1996.75	54.762
2000.49	41.6569
2004.21	62.0294
2007.94	50.6466
2011.67	36.0291
2015.39	26.1353
2019.11	65.0117
2022.83	85.6328
2026.55	58.9705
2030.27	41.5764
2033.98	117.663
2037.69	68.1699
2041.41	51.4285
2045.12	96.7712
2048.82	65.2539
2052.53	9.4248
2056.24	19.6472
2059.94	45.6467
2063.64	89.5613
2067.34	86.3235
2071.04	56.5381
2074.74	57.1401
2078.43	36.6438
2082.13	15.303
2085.82	48.3762
2089.51	39.0356
2093.2	-4.71802
2096.88	18.5032
2100.57	19.0461
2104.25	44.9119
2107.94	67.6094
2111.62	102.982
2115.3	45.3059
2118.97	57.0813
2122.65	41.0442
2126.32	95.9963
2129.99	46.6992
2133.66	75.9741
2137.33	43.0964
2141	69.9216
2144.67	100.923
2148.33	48.8809
2151.99	46.5579
2155.66	66.3257
2159.31	22.9575
2162.97	56.7505
2166.63	67.0684
2170.28	30.3508
2173.94	72.9468
2177.59	115.076
2181.24	50.092
2184.89	77.8494
2188.53	88.009
2192.18	40.8281
2195.82	54.6079
2199.46	79.842
2203.1	62.5283
2206.74	109.454
2210.38	94.7283
2214.01	85.7856
2217.65	62.2778
2221.28	51.6216
2224.91	53.9436
2228.54	41.3884
2232.16	64.8469
2235.79	55.321
2239.41	96.616
2243.04	99.0637
2246.66	83.7961
2250.28	82.5559
2253.89	73.1914
2257.51	88.281
2261.12	72.5315
2264.74	45.2271
2268.35	65.927
2271.96	58.0964
2275.57	12.8992
2279.17	48.9971
2282.78	75.1855
2286.38	54.165
2289.98	71.843
2293.58	-5.33301
2297.18	13.0598
2300.78	91.2339
2304.37	49.7292
2307.97	63.6394
2311.56	33.6357
2315.15	8.98193
2318.74	69.2527
2322.33	46.5566
2325.91	149.316
2329.5	210.982
2333.08	71.0876
2336.66	105.692
2340.24	55.1528
2343.82	75.9714
2347.4	10.1023
2350.97	38.9031
2354.54	15.1382
2358.12	70.6333
2361.69	14.9512
2365.26	86.7749
2368.82	36.0439
2372.39	79.5916
2375.95	71.0471
2379.52	61.678
2383.08	44.3496
2386.64	-13.1621
2390.19	99.833
2393.75	68.0559
2397.31	54.4778
2400.86	41.72
2404.41	59.5847
2407.96	36.5103
2411.51	62.115
2415.06	8.4707
2418.6	90.3887
2422.15	66.1506
2425.69	32.2886
2429.23	84.7769
2432.77	64.8801
2436.31	-7.39795
2439.84	34.5317
2443.38	80.5837
2446.91	29.8423
2450.44	56.1038
2453.97	-2.48291
2457.5	60.3708
2461.03	63.0066
2464.55	16.4219
2468.08	59.3074
2471.6	39.0542
2475.12	60.1946
2478.64	30.0496
2482.16	71.0256
2485.67	21.6042
2489.19	31.0488
2492.7	53.0413
2496.21	43.645
2499.72	20.1348
2503.23	44.5603
2506.74	88.1375
2510.25	40.6313
2513.75	56.748
2517.25	88.2622
2520.75	81.157
2524.25	69.6545
2527.75	67.0645
2531.25	76.1914
2534.74	29.3635
2538.24	53.4314
2541.73	96.5144
2545.22	11.5815
2548.71	61.5066
2552.2	35.8489
2555.68	67.2563
2559.17	78.6157
2562.65	41.8037
2566.13	71.9644
2569.61	73.1953
2573.09	86.2925
2576.57	54.9578
2580.04	64.3362
2583.51	47.5315
2586.99	59.9509
2590.46	21.5645
2593.93	46.4275
2597.4	79.5952
2600.86	41.0544
2604.33	101.694
2607.79	12.5269
2611.25	48.8311
2614.71	28.8296
2618.17	12.5955
2621.63	66.4902
2625.09	88.2278
2628.54	31.5112
2631.99	56.0811
2635.45	24.3975
2638.9	69.728
2642.34	59.0083
2645.79	104.271
2649.24	86.2468
2652.68	13.4087
2656.12	86.7266
2659.56	44.4111
2663.01	91.0557
2666.44	52.2375
2669.88	15.448
2673.32	100.963
2676.75	73.9182
2680.18	6.17554
2683.61	46.7031
2687.04	53.4402
2690.47	18.8499
2693.9	102.559
2697.32	39.4983
2700.75	71.0713
2704.17	112.018
2707.59	87.0359
2711.01	0.534424
2714.43	5.66797
2717.84	82.0671
2721.26	33.2532
2724.67	70.509
2728.08	58.5581
2731.49	54.2175
2734.9	65.665
2738.31	92.1545
2741.71	95.1477
2745.12	85.4773
2748.52	87.686
2751.92	51.3909
2755.32	53.4365
2758.72	23.2283
2762.12	85.3621
2765.52	72.4856
2768.91	60.1917
2772.3	70.1326
2775.7	94.0164
2779.09	64.7422
2782.47	28.5862
2785.86	73.2339
2789.25	17.1377
2792.63	87.9287
2796.01	35.5247
2799.4	32.9563
2802.78	50.668
2806.15	70.2732
2809.53	98.2388
2812.91	100.777
2816.28	68.595
2819.65	83.1511
2823.03	104.61
2826.4	26.5896
2829.76	93.3518
2833.13	112.874
2836.5	78.8228
2839.86	89.9255
2843.22	56.8027
2846.59	51.2764
2849.95	78.3264
2853.3	92.9211
2856.66	59.6226
2860.02	100.486
2863.37	85.5654
2866.72	105.405
2870.08	101.859
2873.43	59.6433
2876.77	56.7712
2880.12	50.0813
2883.47	88.54
2886.81	59.9238
2890.15	119.013
2893.5	39.1846
2896.84	65.5205
2900.17	31.0293
2903.51	102.124
2906.85	66.9941
2910.18	58.1626
2913.52	79.4565
2916.85	85.4578
2920.18	91.1189
2923.51	80.5898
2926.83	78.374
2930.16	55.9954
2933.48	113.65
2936.81	125.594
2940.13	104.537
2943.45	126.874
2946.77	127.62
2950.09	98.3557
2953.4	92.5623
2956.72	84.0562
2960.03	75.9661
2963.34	66.2305
2966.65	93.2466
2969.96	84.3989
2973.27	129.447
2976.58	140.847
2979.88	87.9114
2983.19	111.648
2986.49	102.701
2989.79	71.3665
2993.09	109.608
2996.39	92.5825
2999.68	54.999
3002.98	98.2402
3006.27	55.9265
3009.57	55.1846
3012.86	55.5151
3016.15	66.272
3019.43	61.9063
3022.72	116.939
3026.01	84.2754
3029.29	20.457
3032.57	64.2485
3035.86	40.8643
3039.14	42.9382
3042.41	26.1191
3045.69	63.2974
3048.97	44.6611
3052.24	34.5417
3055.52	67.1458
3058.79	41.8384
3062.06	29.084
3065.33	48.9314
3068.6	100.786
3071.86	72.4429
3075.13	84.8445
3078.39	43.6072
3081.65	32.0027
3084.91	53.6055
3088.17	76.0779
3091.43	57.4109
3094.69	44.5564
3097.95	62.1421
3101.2	30.7729
3104.45	58.8928
3107.7	-7.06641
3110.95	33.2156
3114.2	67.1101
3117.45	39.3301
3120.7	61.1296
3123.94	57.2249
3127.18	72.3445
3130.43	71.2092
3133.67	53.9131
3136.91	36.5537
3140.14	59.1182
3143.38	72.1311
3146.61	59.4229
3149.85	42.0955
3153.08	70.592
3156.31	33.1919
3159.54	58.8135
3162.77	50.9797
3166	25.9771
3169.22	37.043
3172.45	35.5522
3175.67	61.6504
3178.89	100.923
3182.11	45.7256
3185.33	51.6357
3188.55	33.4636
3191.77	73.3945
3194.98	53.2705
3198.2	56.9482
3201.41	86.2957
3204.62	60.5098
3207.83	66.2275
3211.04	94.8875
3214.25	13.3298
3217.45	47.0522
3220.66	76.0234
3223.86	35.634
3227.06	73.4639
3230.26	54.2722
3233.46	82.813
3236.66	26.5305
3239.85	19.2375
3243.05	110.142
3246.24	44.041
3249.44	59.8604
3252.63	105.463
3255.82	108.241
3259.01	89.978
3262.19	72.343
3265.38	56.3064
3268.56	90.5979
3271.75	104.622
3274.93	86.0413
3278.11	80.8048
3281.29	55.0791
3284.47	80.5372
3287.64	57.3667
3290.82	48.3481
3293.99	91.9353
3297.17	57.2854
3300.34	85.5546
3303.51	92.392
3306.68	79.6509
3309.84	147.554
3313.01	77.2531
3316.18	124.671
3319.34	132.123
3322.5	90.199
3325.66	116.559
3328.82	80.4449
3331.98	69.9713
3335.14	89.8972
3338.29	89.2084
3341.45	125.471
3344.6	156.094
3347.75	146.692
3350.9	117.075
3354.05	129.851
3357.2	128.728
3360.35	159.766
3363.49	131.669
3366.64	96.0642
3369.78	116.205
3372.92	179.853
3376.06	163.556
3379.2	170.948
3382.34	162.381
3385.48	148.976
3388.61	140.463
3391.75	182.129
3394.88	236.992
3398.01	262.927
3401.14	241.763
3404.27	292.869
3407.4	296.781
3410.52	395.917
3413.65	573.244
3416.77	818.896
3419.89	1361.26
3423.01	2664.47
3426.13	6204.55
3429.25	10724.3
3432.37	9339.11
3435.49	4507.58
3438.6	1977.77
3441.72	1115.94
3444.83	696.125
3447.94	464.885
3451.05	415.859
3454.16	337.962
3457.26	338.176
3460.37	257.206
3463.47	204.837
3466.58	280.678
3469.68	231.742
3472.78	213.82
3475.88	225.94
3478.98	263.705
3482.07	291.107
3485.17	331.756
3488.26	383.836
3491.36	496.613
3494.45	603.343
3497.54	787.293
3500.63	1060.56
3503.72	1447.8
3506.81	1967.1
3509.89	2452.91
3512.98	2775.81
3516.06	2376.72
3519.14	1888.04
3522.22	1413.79
3525.3	991.787
3528.38	720.243
3531.45	628.415
3534.53	448.172
3537.61	344.253
3540.68	327.421
3543.75	219.933
3546.82	235.75
3549.89	171.775
3552.96	214.984
3556.03	170.09
3559.09	130.207
3562.16	154.672
3565.22	132.324
3568.28	107.762
3571.34	159.64
3574.4	87.322
3577.46	88.0968
3580.52	100.093
3583.57	80.632
3586.63	97.0287
3589.68	105.82
3592.73	80.2322
3595.78	93.467
3598.83	73.3567
3601.88	75.042
3604.93	105.868
3607.97	48.5248
3611.02	81.0597
3614.06	78.4862
3617.1	91.8979
3620.14	61.0127
3623.18	106.655
3626.22	50.476
3629.26	76.4536
3632.3	79.6903
3635.33	54.5863
3638.36	119.353
3641.4	49.7888
3644.43	35.9546
3647.46	108.206
3650.49	99.0234
3653.51	61.8688
3656.54	2.72058
3659.57	34.9331
3662.59	29.3563
3665.61	62.0642
3668.63	89.2516
3671.65	85.7631
3674.67	37.0719
3677.69	47.8909
3680.71	49.3711
3683.72	22.392
3686.74	84.2902
3689.75	18.5686
3692.76	23.8209
3695.77	65.0947
3698.78	20.7422
3701.79	45.0067
3704.79	63.6008
3707.8	10.9475
3710.81	69.2202
3713.81	45.632
3716.81	49.387
3719.81	38.9862
3722.81	38.8252
3725.81	30.896
3728.81	42.7992
3731.8	65.0536
3734.8	99.5088
3737.79	47.1102
3740.78	81.1992
3743.77	0.864746
3746.76	44.0979
3749.75	46.2401
3752.74	18.7976
3755.73	23.6445
3758.71	79.7599
3761.7	19.1285
3764.68	50.3444
3767.66	35.1631
3770.64	42.8413
3773.62	73.3662
3776.6	3.78711
3779.58	91.2194
3782.55	51.1782
3785.53	21.5732
3788.5	38.338
3791.47	58.0316
3794.44	67.6057
3797.41	-3.85657
3800.38	71.0845
3803.35	37.6931
3806.32	53.4801
3809.28	64.5989
3812.24	55.0337
3815.21	63.4637
3818.17	70.0477
3821.13	75.7571
3824.09	22.8059
3827.04	53.2843
3830	62.9551
3832.96	38.4757
3835.91	27.4086
3838.86	17.3553
3841.82	31.047
3844.77	73.2781
3847.72	90.8524
3850.67	65.6476
3853.61	30.0031
3856.56	78.3094
3859.5	42.6566
3862.45	27.9834
3865.39	52.4152
3868.33	24.2073
3871.27	33.1919
3874.21	56.5247
3877.15	48.1404
3880.09	63.5618
3883.02	42.3132
3885.96	51.601
3888.89	81.9177
3891.82	65.0648
3894.75	76.0092
3897.68	54.0439
3900.61	55.9333
3903.54	51.0439
3906.47	33.4587
3909.39	27.6031
3912.31	29.2854
3915.24	85.5742
3918.16	43.7616
3921.08	80.9906
3924	50.687
3926.92	95.0571
3929.83	74.9862
3932.75	42.4147
3935.67	64.8508
3938.58	65.5831
3941.49	33.0913
3944.4	63.6475
3947.31	50.2479
3950.22	53.2859
3953.13	54.5244
3956.04	96.0548
3958.94	34.2888
3961.85	26.2238
3964.75	71.9078
3967.65	25.6545
3970.55	51.396
3973.45	40.7291
3976.35	31.9344
3979.25	41.2825
3982.15	31.3115
3985.04	34.7632
3987.94	51.6029
3990.83	71.2832
3993.72	24.4091
3996.61	87.4938
3999.5	48.5623
4002.39	77.0822
4005.28	35.3362
4008.16	19.6517
4011.05	62.7719
4013.93	37.4376
4016.81	87.3431
4019.7	45.6042
4022.58	23.1327
4025.46	39.2849
4028.33	21.6628
4031.21	72.6689
4034.09	65.734
4036.96	70.42
4039.84	53.8813
4042.71	35.3434
4045.58	41.7253
4048.45	39.4662
4051.32	60.5582
4054.19	27.4275
4057.05	52.6466
4059.92	67.1495
4062.78	47.6023
4065.65	49.4297
4068.51	16.236
4071.37	1.47498
4074.23	49.9716
4077.09	50.7552
4079.95	39.8324
4082.81	55.2153
4085.66	72.5759
4088.52	77.1888
4091.37	22.27
4094.22	50.4064
4097.07	77.4719
4099.92	68.4894
4102.77	25.2445
4105.62	41.5769
4108.47	111.547
4111.31	70.0238
4114.16	50.8177
4117	77.4624
4119.84	22.6643
4122.69	37.3804
4125.53	7.25818
4128.36	13.3822
4131.2	31.6464
4134.04	53.0784
4136.88	63.2257
4139.71	74.4724
4142.54	28.6289
4145.38	29.673
4148.21	84.1455
4151.04	25.198
4153.87	50.1144
4156.69	80.3862
4159.52	21.948
4162.35	43.3182
4165.17	40.4169
4168	70.752
4170.82	55.1896
4173.64	24.0673
4176.46	63.3981
4179.28	44.0574
4182.1	76.6718
4184.91	52.6139
4187.73	39.3955
4190.54	70.2434
4193.36	56.3077
4196.17	66.0172
4198.98	62.2261
4201.79	68.1825
4204.6	84.0231
4207.41	58.5928
4210.22	96.0273
4213.02	66.6222
4215.83	110.923
4218.63	80.3635
4221.44	85.1228
4224.24	35.5015
4227.04	45.8319
4229.84	50.493
4232.64	62.1366
4235.43	63.0848
4238.23	32.3757
4241.02	97.9578
4243.82	54.3496
4246.61	47.5536
4249.4	70.5679
4252.19	66.5481
4254.98	21.4902
4257.77	52.2557
4260.56	59.0262
4263.35	54.8407
4266.13	59.7313
4268.92	68.7504
4271.7	76.7603
4274.48	73.6571
4277.26	53.114
4280.04	67.6792
4282.82	108.445
4285.6	43.9521
4288.38	43.965
4291.15	66.1014
4293.93	66.9324
4296.7	52.7572
4299.47	33.6044
4302.25	-6.99792
4305.02	17.2949
4307.79	47.703
4310.55	29.4414
4313.32	62.1154
4316.09	55.9548
4318.85	47.6301
4321.62	55.4951
4324.38	56.1292
4327.14	-0.326294
4329.9	48.1525
4332.66	62.887
4335.42	10.4661
4338.18	78.1351
4340.94	43.149
4343.69	45.8694
4346.45	29.3521
4349.2	40.4861
4351.95	86.3441
4354.7	75.4122
4357.45	46.9341
4360.2	62.4034
4362.95	21.5206
4365.7	71.8604
4368.44	43.2401
4371.19	34.1969
4373.93	40.3002
4376.68	50.4867
4379.42	37.979
4382.16	58.3038
4384.9	53.0365
4387.64	69.6418
4390.37	45.5996
4393.11	16.5435
4395.85	49.2759
4398.58	66.6936
4401.31	10.5778
4404.05	17.4298
4406.78	68.9817
4409.51	43.8199
4412.24	1.80493
4414.96	44.8992
4417.69	47.3737
4420.42	58.7167
4423.14	61.9702
4425.87	46.5048
4428.59	43.5596
4431.31	55.2448
4434.03	61.6841
4436.75	42.9388
4439.47	61.8235
4442.19	64.88
4444.91	37.5513
4447.62	22.7074
4450.34	38.2944
4453.05	48.5341
4455.76	59.8134
4458.47	66.7772
4461.19	62.1285
4463.89	48.168
4466.6	39.4244
4469.31	27.5852
4472.02	36.8434
4474.72	23.0345
4477.43	48.3138
4480.13	73.7146
4482.83	37.9872
4485.53	31.7778
4488.23	65.6379
4490.93	64.5768
4493.63	70.6262
4496.33	30.9615
4499.02	40.2028
4501.72	54.6775
4504.41	46.8082
4507.11	60.2491
4509.8	42.9724
4512.49	50.0864
4515.18	73.1548
4517.87	81.4027
4520.56	39.759
4523.24	73.6779
4525.93	81.0278
4528.61	58.551
4531.3	39.271
4533.98	39.1765
4536.66	68.9814
4539.34	56.1617
4542.02	0.650513
4544.7	30.5699
4547.38	55.2189
4550.05	42.4271
4552.73	59.7313
4555.4	47.2032
4558.08	48.7715
4560.75	49.5834
4563.42	36.5625
4566.09	45.4307
4568.76	50.2809
4571.43	31.682
4574.1	47.6644
4576.77	49.0892
4579.43	51.0346
4582.1	41.4698
4584.76	14.6395
4587.42	50.3582
4590.08	47.8846
4592.74	31.1035
4595.4	32.9311
4598.06	54.5404
4600.72	23.5881
4603.38	19.0408
4606.03	67.1128
4608.69	41.8308
4611.34	35.1617
4613.99	2.07501
4616.64	55.7401
4619.29	13.8353
4621.94	39.0706
4624.59	47.7695
4627.24	24.3972
4629.89	59.4507
4632.53	77.936
4635.18	75.2729
4637.82	30.4827
4640.46	36.5398
4643.1	23.7828
4645.74	45.5987
4648.38	24.4289
4651.02	23.4459
4653.66	43.9659
4656.3	37.3365
4658.93	25.1579
4661.57	62.7723
4664.2	41.4246
4666.83	36.6526
4669.46	69.6716
4672.09	65.8677
4674.72	42.9741
4677.35	49.182
4679.98	12.7193
4682.61	52.5427
4685.23	58.6962
4687.86	58.0997
4690.48	22.6122
4693.1	29.8826
4695.73	37.0689
4698.34	48.7523
4700.96	37.8891
4703.58	8.89526
4706.2	36.2812
4708.82	0.334656
4711.43	22.0051
4714.05	22.1691
4716.66	42.6662
4719.28	76.7203
4721.89	26.8986
4724.5	41.6023
4727.11	32.6256
4729.72	42.9786
4732.33	37.4471
4734.93	47.8071
4737.54	51.3102
4740.14	32.0156
4742.75	31.996
4745.35	40.9938
4747.95	32.8533
4750.55	17.743
4753.15	33.3794
4755.75	38.7495
4758.35	50.9396
4760.95	46.1387
4763.54	47.0891
4766.14	-10.0044
4768.73	20.8043
4771.33	26.6239
4773.92	66.482
4776.51	47.0305
4779.1	45.8319
4781.69	40.0419
4784.28	27.3914
4786.87	23.8806
4789.45	31.8055
4792.04	63.8019
4794.63	-3.77008
4797.21	39.7584
4799.79	23.8015
4802.37	2.1344
4804.95	31.0313
4807.53	29.0479
4810.11	55.8889
4812.69	5.58545
4815.27	61.3159
4817.84	28.3245
4820.42	28.8391
4822.99	46.7054
4825.57	40.2892
4828.14	53.5584
4830.71	22.7194
4833.28	22.1287
4835.85	21.5649
4838.42	39.7679
4840.98	34.725
4843.55	26.1097
4846.12	52.4811
4848.68	29.5234
4851.24	5.06927
4853.81	43.4992
4856.37	45.6628
4858.93	28.6461
4861.49	43.3608
4864.05	-8.24744
4866.61	-5.88232
4869.16	30.834
4871.72	44.1289
4874.27	3.92828
4876.83	11.0015
4879.38	-0.902283
4881.93	25.1237
4884.49	21.4328
4887.04	41.5076
4889.58	34.2733
4892.13	47.2699
4894.68	34.0538
4897.23	33.9073
4899.77	32.5483
4902.32	40.7167
4904.86	33.3777
4907.4	20.0314
4909.95	9.04431
4912.49	57.6019
4915.03	47.5874
4917.57	37.5011
4920.1	35.8789
4922.64	-1.57874
4925.18	36.2549
4927.71	15.6087
4930.25	35.5043
4932.78	20.9662
4935.31	30.5019
4937.84	22.0177
4940.38	35.0773
4942.9	46.605
4945.43	26.1229
4947.96	47.6979
4950.49	45.3073
4953.01	4.62769
4955.54	29.8121
4958.06	65.9882
4960.59	37.4319
4963.11	20.9478
4965.63	23.9183
4968.15	37.9014
4970.67	39.6463
4973.19	32.9305
4975.71	3.24976
4978.22	15.843
4980.74	45.4615
4983.25	37.6139
4985.77	49.2034
4988.28	39.0129
4990.79	11.8364
4993.3	-10.5333
4995.81	7.22858
4998.32	41.0162