File: Data/3-Raman/processed/bu19w-a-ff07b-fi09-v_150 (500nm)_532nm_edge_100%_x100_vis_lwd_h50um_15sx2_01_0.txt
#Acq. time (s)=	15
#Accumulations=	2
#Range (cm-¹)=	50...5000
#Windows=	1
#Auto scanning=	Off
#Autofocus=	Off
#Macrospot=	Off
#AutoExposure=	Off
#Spike filter=	Multiple accum.
#Delay time (s)=	2
#Binning=	1
#Readout mode=	Signal
#DeNoise=	Off
#ICS correction=	On
#Dark correction=	Off
#Inst. Process=	Off
#Detector Gain=	Best Dynamic
#Detector ADC=	50 kHz HS
#Detector temperature (°C)=	-60.09
#Instrument=	LabRAM HR Evol
#Detector=	SIN-EM FIVIS
#Objective=	x100_VIS_LWD
#Grating=	150 (500nm)
#ND Filter=	100%
#Laser=	532nm_Edge
#Hole=	49.98
#Temperature=	0
#Range=	Visible
#StageXY=	75x50mm Scan+
#StageZ=	Z motor
#X (µm)=	0
#Y (µm)=	0
#Z (µm)=	-17.5
#Full time(s)=	34
#Project=	21_05_28
#Sample=	BU19w
#Site=
#Title=	BU19w-FF07b-FI09-V_150 (500nm)_532nm_Edge_100%_x100_VIS_LWD_H50um_15sX2
#Remark=
#Date=	28.05.2021 16:51
#Acquired=	28.05.2021 16:51:51
#Base:Fit=	16.12.2021 17:39:50
#Base:Sub=	16.12.2021 17:58:00
51.5961	51825.5
56.2453	40356.7
60.8921	31425.3
65.5367	29242.7
70.1768	21676.2
74.8167	13711.1
79.4543	9834.47
84.0897	7581.71
88.7227	6154.8
93.3513	4821.31
97.9798	3863.87
102.606	3225.61
107.23	2746.81
111.851	2440.69
116.469	1995.59
121.086	1587.37
125.7	1340.06
130.313	1220.13
134.921	1037.92
139.529	922.557
144.134	760.612
148.738	623.217
153.337	520.201
157.936	686.977
162.532	1685.22
167.126	2492.23
171.716	1418.41
176.306	564.332
180.894	490.85
185.477	980.925
190.06	3860.72
194.64	6585.96
199.219	3569.99
203.793	1139.22
208.367	356.764
212.939	78.959
217.506	92.8715
222.073	76.7816
226.638	0.00604248
231.199	28.7148
235.759	318.048
240.318	709.987
244.872	822.2
249.425	1768.32
253.977	2295.26
258.524	1500.33
263.071	965.029
267.616	564.759
272.156	555.134
276.697	1520.77
281.233	4453.88
285.769	6779.89
290.303	4503.98
294.832	2017.06
299.361	1239.6
303.886	1667.92
308.411	2771.68
312.934	2367.19
317.452	1145.23
321.97	643.369
326.484	697.168
330.998	1327.18
335.507	2084.28
340.017	1552.99
344.524	777.633
349.027	742.974
353.53	1284.1
358.028	1477.98
362.527	847.701
367.021	353.348
371.515	285.018
376.004	396.593
380.494	321.408
384.979	165.716
389.465	485.509
393.946	822.375
398.427	1081.43
402.903	1033.99
407.38	616.655
411.852	239.16
416.324	275.978
420.792	696.422
425.26	793.562
429.723	249.273
434.187	-97.4381
438.646	-198.081
443.105	-175.008
447.56	-128.687
452.015	15.1442
456.466	575.97
460.914	1532.19
465.362	1254.19
469.807	419.685
474.251	77.6959
478.69	-14.2869
483.13	41.7181
487.566	172.275
491.999	356.388
496.432	594.306
500.861	785.604
505.29	773.9
509.715	617.932
514.138	373.042
518.56	134.079
522.979	95.4609
527.395	39.7287
531.811	60.4706
536.223	70.9921
540.635	116.299
545.042	165.078
549.448	191.914
553.853	179.157
558.255	218.028
562.654	214.977
567.053	274.235
571.448	206.704
575.841	112.402
580.232	88.8726
584.622	219.313
589.009	705.83
593.393	1945.53
597.777	2359.44
602.157	1305.68
606.535	724.999
610.913	754.295
615.287	1296.83
619.659	1493.77
624.029	955.455
628.398	395.205
632.763	174.052
637.127	148.97
641.488	231.67
645.849	364.373
650.206	327.441
654.561	232.842
658.914	242.537
663.267	395.954
667.615	687.677
671.962	878.083
676.307	940.622
680.649	1081.34
684.991	1135.64
689.33	813.264
693.666	409.215
698	180.636
702.332	60.5295
706.662	4.45758
710.992	-31.4378
715.318	-49.7985
719.641	-49.7056
723.963	-63.4478
728.283	-32.2151
732.6	-48.8516
736.918	-22.0578
741.231	-13.4086
745.542	-21.3276
749.852	42.223
754.159	55.1546
758.464	114.718
762.767	207.529
767.068	352.868
771.369	553.51
775.666	1048.07
779.961	1887.03
784.254	2677.53
788.545	2334.51
792.834	1429.26
797.12	819.361
801.405	512.228
805.688	333.95
809.968	217.634
814.247	150.881
818.524	118.27
822.798	98.7891
827.071	93.7357
831.341	55.6385
835.612	42.8041
839.878	36.4718
844.142	33.3227
848.405	23.2828
852.665	20.5822
856.923	13.4309
861.18	34.8709
865.434	16.4989
869.686	-6.46674
873.936	24.2782
878.185	-0.0791016
882.431	7.22693
886.675	19.6972
890.915	14.3116
895.155	21.7401
899.393	32.2446
903.63	65.6272
907.864	36.3292
912.096	31.2825
916.326	35.1993
920.554	36.7921
924.78	67.2211
929.004	84.2653
933.227	96.576
937.447	128.063
941.665	177.448
945.881	260.76
950.095	405.634
954.305	604.621
958.516	629.664
962.724	583.536
966.93	566.269
971.134	650.998
975.337	660.518
979.537	500.623
983.735	368.595
987.93	282.147
992.124	236.025
996.316	191.471
1000.51	181.176
1004.7	182.642
1008.88	172.498
1013.06	194.231
1017.25	182.788
1021.43	207.537
1025.61	246.024
1029.78	289.604
1033.96	337.198
1038.13	421.23
1042.3	582.29
1046.47	804.516
1050.63	1316.6
1054.8	2529.06
1058.96	3671.77
1063.12	3120.89
1067.28	2038.85
1071.44	1336.19
1075.59	1030.67
1079.74	992.615
1083.89	1242.92
1088.04	1808.22
1092.19	2842.61
1096.33	3734.18
1100.48	3472.68
1104.62	2655.01
1108.76	2381.45
1112.89	2735.46
1117.03	3114.74
1121.16	2814.94
1125.29	2437.41
1129.42	2333.8
1133.55	2600.28
1137.68	2713.99
1141.8	2611.09
1145.92	1977.44
1150.04	1470.82
1154.16	1387.83
1158.27	1747.69
1162.39	2323.98
1166.5	2354.5
1170.61	1873.58
1174.72	1389.26
1178.82	1055.74
1182.93	737.172
1187.03	512.418
1191.13	456.006
1195.23	419.987
1199.33	449.171
1203.42	459.611
1207.51	462.794
1211.6	413.323
1215.69	349.009
1219.78	383.829
1223.86	521.09
1227.95	750.173
1232.03	777.624
1236.11	667.017
1240.18	698.136
1244.26	1018.53
1248.33	1149.53
1252.41	902.976
1256.48	847.361
1260.54	676.967
1264.61	471.5
1268.67	385.018
1272.74	730.513
1276.8	3387.85
1280.86	3194.85
1284.91	852.044
1288.97	328.454
1293.02	244.054
1297.07	238.02
1301.12	226.868
1305.17	177.268
1309.21	194.133
1313.25	226.035
1317.3	165.966
1321.34	194.426
1325.37	177.302
1329.41	185.248
1333.44	186.069
1337.48	196.677
1341.5	151.099
1345.53	155.54
1349.56	202.81
1353.59	209.127
1357.61	198.566
1361.63	294.065
1365.65	304.251
1369.66	325.404
1373.68	371.37
1377.69	1662.61
1381.7	6540.06
1385.72	3672.27
1389.72	695.269
1393.73	321.875
1397.73	310.061
1401.74	559.204
1405.74	560.17
1409.73	262.57
1413.73	151.173
1417.73	137.36
1421.72	129.449
1425.71	117.495
1429.7	72.6315
1433.69	92.0137
1437.67	59.0507
1441.66	36.9633
1445.64	37.4992
1449.62	63.6613
1453.6	45.318
1457.57	52.5702
1461.55	47.8887
1465.52	31.2266
1469.49	32.2613
1473.46	36.319
1477.43	29.5027
1481.39	22.6324
1485.36	3.02228
1489.32	14.6964
1493.28	35.164
1497.24	10.7583
1501.19	-4.76849
1505.15	10.9519
1509.1	35.5438
1513.05	17.4085
1517	31.3604
1520.95	25.9555
1524.9	1.19562
1528.84	10.4313
1532.78	21.6709
1536.72	9.65985
1540.66	24.8065
1544.6	12.8209
1548.53	6.65656
1552.46	49.9006
1556.4	28.1702
1560.32	30.5737
1564.25	26.1411
1568.18	39.0653
1572.1	11.3439
1576.02	22.2811
1579.94	21.601
1583.86	3.55261
1587.78	6.68805
1591.69	9.80597
1595.61	43.684
1599.52	28.5006
1603.43	3.78882
1607.34	9.89941
1611.24	16.0172
1615.15	9.71008
1619.05	18.813
1622.95	11.5974
1626.85	12.1322
1630.74	29.0093
1634.64	2.99518
1638.53	23.8548
1642.42	-3.00952
1646.31	11.4147
1650.2	13.4472
1654.09	19.3484
1657.97	32.8922
1661.86	20.4912
1665.74	17.5818
1669.62	3.07422
1673.49	-12.5671
1677.37	15.0198
1681.24	40.3689
1685.12	3.1449
1688.99	-20.6328
1692.86	3.42151
1696.72	1.5119
1700.59	-11.945
1704.45	3.13293
1708.31	-19.0743
1712.17	7.12939
1716.03	14.2736
1719.89	0.604431
1723.74	26.6424
1727.6	5.43195
1731.45	10.5339
1735.3	2.53113
1739.14	4.78809
1742.99	28.4292
1746.83	14.747
1750.68	5.17542
1754.52	6.03833
1758.36	28.541
1762.19	2.7948
1766.03	17.4739
1769.86	-6.63336
1773.69	1.09363
1777.53	36.7756
1781.35	22.4092
1785.18	35.1654
1789	17.168
1792.83	34.7305
1796.65	1.69537
1800.47	19.2773
1804.29	5.49237
1808.1	0.111389
1811.92	6.91052
1815.73	-5.24683
1819.54	22.9189
1823.35	-0.00964355
1827.16	16.5846
1830.97	26.4102
1834.77	19.1127
1838.58	2.31726
1842.38	-6.0697
1846.18	9.84888
1849.97	1.40704
1853.77	-9.14471
1857.56	20.3924
1861.36	2.99152
1865.15	16.3091
1868.93	7.3396
1872.72	43.8605
1876.51	31.3449
1880.29	12.4526
1884.07	27.9618
1887.86	-0.736511
1891.63	16.3347
1895.41	10.4072
1899.19	-0.12085
1902.96	12.5958
1906.73	10.6975
1910.5	8.85071
1914.27	21.9612
1918.04	32.3654
1921.8	17.2838
1925.57	23.5061
1929.33	39.1316
1933.09	24.1841
1936.85	13.8172
1940.6	19.2587
1944.36	0.381775
1948.11	11.4193
1951.87	21.1017
1955.61	26.8098
1959.36	20.9446
1963.11	11.127
1966.86	27.57
1970.6	19.4094
1974.34	0.727173
1978.08	21.3084
1981.82	9.927
1985.56	6.88013
1989.29	19.6325
1993.02	13.617
1996.75	21.448
2000.49	15.2153
2004.21	16.4392
2007.94	9.27081
2011.67	22.2685
2015.39	39.8178
2019.11	22.704
2022.83	16.0325
2026.55	16.1365
2030.27	14.4286
2033.98	40.4588
2037.69	17.2598
2041.41	16.8875
2045.12	-0.015686
2048.82	14.2209
2052.53	5.67773
2056.24	24.6434
2059.94	12.7623
2063.64	17.7398
2067.34	31.1513
2071.04	20.7004
2074.74	31.4475
2078.43	19.1583
2082.13	7.78906
2085.82	4.65314
2089.51	34.2589
2093.2	25.525
2096.88	25.434
2100.57	18.7214
2104.25	22.9626
2107.94	15.9351
2111.62	15.3238
2115.3	-2.9718
2118.97	1.8985
2122.65	15.8153
2126.32	33.2869
2129.99	22.8231
2133.66	40.0869
2137.33	10.1241
2141	26.2838
2144.67	37.6879
2148.33	24.1724
2151.99	18.952
2155.66	27.5187
2159.31	33.3299
2162.97	35.5385
2166.63	23.2328
2170.28	34.7614
2173.94	50.1645
2177.59	48.3882
2181.24	46.6956
2184.89	63.1662
2188.53	64.3375
2192.18	39.3768
2195.82	69.2693
2199.46	56.5292
2203.1	46.5739
2206.74	42.1748
2210.38	55.2414
2214.01	25.4025
2217.65	43.1876
2221.28	48.1846
2224.91	44.0331
2228.54	54.5628
2232.16	37.4615
2235.79	59.1744
2239.41	70.7548
2243.04	52.6885
2246.66	66.1091
2250.28	61.0033
2253.89	32.662
2257.51	52.8092
2261.12	39.3549
2264.74	36.0786
2268.35	36.6102
2271.96	57.9691
2275.57	18.0183
2279.17	45.6673
2282.78	49.3542
2286.38	28.4789
2289.98	21.7398
2293.58	22.4719
2297.18	17.5457
2300.78	31.5755
2304.37	62.567
2307.97	28.9934
2311.56	49.3447
2315.15	41.1616
2318.74	92.575
2322.33	468.74
2325.91	434.87
2329.5	142.894
2333.08	39.3948
2336.66	22.8217
2340.24	36.3333
2343.82	36.5743
2347.4	62.9993
2350.97	46.197
2354.54	18.2029
2358.12	18.2628
2361.69	21.071
2365.26	29.4306
2368.82	19.2465
2372.39	33.3276
2375.95	36.2146
2379.52	39.1063
2383.08	27.3282
2386.64	24.8475
2390.19	33.5052
2393.75	48.6948
2397.31	17.2949
2400.86	32.8884
2404.41	12.1752
2407.96	34.6185
2411.51	17.9193
2415.06	27.9723
2418.6	35.4468
2422.15	43.0439
2425.69	19.4904
2429.23	-3.9751
2432.77	16.9976
2436.31	24.2966
2439.84	28.9094
2443.38	4.72729
2446.91	29.9254
2450.44	-4.5119
2453.97	21.9821
2457.5	24.6686
2461.03	42.8068
2464.55	4.35815
2468.08	24.7363
2471.6	32.4627
2475.12	-4.32166
2478.64	38.0646
2482.16	19.2417
2485.67	32.2204
2489.19	34.4123
2492.7	32.269
2496.21	33.5069
2499.72	22.8
2503.23	27.8036
2506.74	23.3426
2510.25	23.4109
2513.75	-1.59174
2517.25	16.3724
2520.75	33.4688
2524.25	15.7945
2527.75	13.6249
2531.25	24.5606
2534.74	33.733
2538.24	8.95428
2541.73	17.5588
2545.22	20.0248
2548.71	23.7053
2552.2	8.01599
2555.68	26.7174
2559.17	28.1891
2562.65	3.69012
2566.13	39.8521
2569.61	12.0615
2573.09	41.3282
2576.57	19.337
2580.04	3.92926
2583.51	38.4559
2586.99	6.03125
2590.46	30.1691
2593.93	18.9015
2597.4	21.7691
2600.86	0.0185547
2604.33	3.95776
2607.79	8.49664
2611.25	34.5744
2614.71	22.7688
2618.17	24.6592
2621.63	20.5056
2625.09	23.9092
2628.54	22.3295
2631.99	5.27979
2635.45	48.5392
2638.9	12.919
2642.34	19.3835
2645.79	51.5156
2649.24	-0.501526
2652.68	40.8962
2656.12	26.7935
2659.56	25.8983
2663.01	20.1977
2666.44	14.4608
2669.88	33.2436
2673.32	20.8721
2676.75	34.941
2680.18	44.3735
2683.61	7.20514
2687.04	30.1172
2690.47	4.01764
2693.9	33.1658
2697.32	24.8945
2700.75	22.3786
2704.17	47.7987
2707.59	10.0034
2711.01	20.1237
2714.43	33.1914
2717.84	15.6898
2721.26	6.68567
2724.67	26.6797
2728.08	58.9205
2731.49	26.7598
2734.9	62.8306
2738.31	-0.352661
2741.71	18.8592
2745.12	21.0768
2748.52	-1.22424
2751.92	1.84521
2755.32	8.63043
2758.72	1.23218
2762.12	16.4507
2765.52	22.0836
2768.91	-0.653809
2772.3	33.9832
2775.7	37.4659
2779.09	-1.55579
2782.47	31.8606
2785.86	22.8512
2789.25	10.0709
2792.63	19.8436
2796.01	-0.470581
2799.4	22.4283
2802.78	6.72925
2806.15	21.0616
2809.53	35.3598
2812.91	14.0415
2816.28	-10.0789
2819.65	18.1446
2823.03	15.6331
2826.4	13.2244
2829.76	20.1981
2833.13	-1.62085
2836.5	28.8721
2839.86	20.3586
2843.22	16.6443
2846.59	30.8059
2849.95	12.5996
2853.3	7.59576
2856.66	8.11456
2860.02	-0.620178
2863.37	20.6752
2866.72	6.43268
2870.08	26.8899
2873.43	11.6533
2876.77	28.3422
2880.12	8.33862
2883.47	25.0275
2886.81	19.0602
2890.15	15.9043
2893.5	28.77
2896.84	28.2552
2900.17	19.1334
2903.51	19.3635
2906.85	18.5682
2910.18	27.1813
2913.52	12.0931
2916.85	24.4036
2920.18	40.3964
2923.51	34.5972
2926.83	53.3225
2930.16	27.5232
2933.48	57.3909
2936.81	34.2749
2940.13	47.9706
2943.45	39.9851
2946.77	32.9821
2950.09	40.1276
2953.4	47.242
2956.72	49.6796
2960.03	48.4832
2963.34	40.7888
2966.65	19.0819
2969.96	37.9281
2973.27	14.6978
2976.58	38.4
2979.88	43.4658
2983.19	52.2108
2986.49	48.8066
2989.79	35.1203
2993.09	32.726
2996.39	57.6227
2999.68	33.7027
3002.98	21.9843
3006.27	3.67871
3009.57	7.06433
3012.86	18.9702
3016.15	39.3903
3019.43	2.3078
3022.72	22.7227
3026.01	22.4037
3029.29	21.1552
3032.57	11.3934
3035.86	22.39
3039.14	19.1967
3042.41	18.8495
3045.69	-7.03729
3048.97	18.2026
3052.24	47.2618
3055.52	3.37775
3058.79	15.3865
3062.06	35.7284
3065.33	5.89807
3068.6	14.8871
3071.86	14.2463
3075.13	11.1334
3078.39	-16.8969
3081.65	18.3936
3084.91	10.6436
3088.17	5.70251
3091.43	4.74121
3094.69	22.8399
3097.95	21.0791
3101.2	3.59167
3104.45	24.0149
3107.7	4.81152
3110.95	17.8626
3114.2	20.2388
3117.45	20.7753
3120.7	50.8577
3123.94	20.9473
3127.18	22.4576
3130.43	15.3765
3133.67	17.8383
3136.91	-4.49768
3140.14	28.4218
3143.38	11.7672
3146.61	18.0011
3149.85	14.7487
3153.08	20.0963
3156.31	11.1132
3159.54	9.78204
3162.77	20.837
3166	39.5349
3169.22	-0.99176
3172.45	18.5598
3175.67	13.2758
3178.89	31.7936
3182.11	36.9465
3185.33	46.8843
3188.55	32.9052
3191.77	13.2006
3194.98	25.9098
3198.2	29.0789
3201.41	13.1902
3204.62	25.9042
3207.83	60.5287
3211.04	32.3714
3214.25	23.3026
3217.45	32.3605
3220.66	56.6428
3223.86	42.9018
3227.06	22.5724
3230.26	26.9949
3233.46	48.598
3236.66	27.3432
3239.85	42.4009
3243.05	40.3694
3246.24	54.5684
3249.44	37.335
3252.63	62.1097
3255.82	67.8512
3259.01	82.1785
3262.19	36.2566
3265.38	61.8525
3268.56	66.3464
3271.75	57.4006
3274.93	60.8353
3278.11	67.1274
3281.29	75.1854
3284.47	59.2531
3287.64	71.0194
3290.82	84.6257
3293.99	92.5624
3297.17	69.9823
3300.34	81.7182
3303.51	98.3689
3306.68	99.6003
3309.84	90.3036
3313.01	95.1656
3316.18	96.1825
3319.34	70.6218
3322.5	111.43
3325.66	118.086
3328.82	107.708
3331.98	136.13
3335.14	129.61
3338.29	110.893
3341.45	131.883
3344.6	120.81
3347.75	116.532
3350.9	114.32
3354.05	133.78
3357.2	110.91
3360.35	123.898
3363.49	131.323
3366.64	137.827
3369.78	133.056
3372.92	139.639
3376.06	171.805
3379.2	155.868
3382.34	170.191
3385.48	198.675
3388.61	237.664
3391.75	276.71
3394.88	295.87
3398.01	302.506
3401.14	362.746
3404.27	429.82
3407.4	545.57
3410.52	731.999
3413.65	1056.82
3416.77	1826.78
3419.89	3588.42
3423.01	8411.85
3426.13	14530.1
3429.25	11710.7
3432.37	5470
3435.49	2449.24
3438.6	1314.11
3441.72	843.036
3444.83	605.869
3447.94	500.224
3451.05	369.854
3454.16	372.865
3457.26	319.67
3460.37	316.849
3463.47	301.656
3466.58	320.638
3469.68	304.34
3472.78	318.254
3475.88	342.838
3478.98	377.843
3482.07	472.415
3485.17	586.723
3488.26	694.347
3491.36	849.242
3494.45	1179.94
3497.54	1564.2
3500.63	2183.87
3503.72	2907.88
3506.81	3627.95
3509.89	3917.78
3512.98	3393.54
3516.06	2555.66
3519.14	1884.34
3522.22	1309.56
3525.3	977.251
3528.38	767.957
3531.45	543.607
3534.53	486.955
3537.61	366.551
3540.68	311.417
3543.75	240.609
3546.82	254.615
3549.89	209.689
3552.96	196.651
3556.03	192.044
3559.09	154.435
3562.16	134.774
3565.22	162.315
3568.28	149.014
3571.34	112.223
3574.4	121.548
3577.46	104.349
3580.52	95.6272
3583.57	96.3364
3586.63	101.724
3589.68	113.745
3592.73	77.3243
3595.78	99.6694
3598.83	56.5657
3601.88	66.5313
3604.93	91.5674
3607.97	77.7368
3611.02	81.8824
3614.06	76.538
3617.1	57.0095
3620.14	56.4099
3623.18	69.9886
3626.22	70.3718
3629.26	69.8511
3632.3	58.9337
3635.33	64.9418
3638.36	62.6263
3641.4	74.5076
3644.43	71.403
3647.46	52.4593
3650.49	54.9873
3653.51	35.9568
3656.54	35.0067
3659.57	26.869
3662.59	44.0789
3665.61	54.609
3668.63	32.8279
3671.65	29.079
3674.67	22.5229
3677.69	23.5418
3680.71	34.9819
3683.72	49.2371
3686.74	31.3615
3689.75	14.4268
3692.76	28.731
3695.77	23.1591
3698.78	30.7413
3701.79	13.7878
3704.79	14.8448
3707.8	14.9449
3710.81	3.57196
3713.81	34.9354
3716.81	29.1541
3719.81	11.9854
3722.81	7.10974
3725.81	28.8453
3728.81	37.2039
3731.8	16.9532
3734.8	32.8334
3737.79	19.1309
3740.78	25.3745
3743.77	20.1279
3746.76	15.7903
3749.75	34.2172
3752.74	27.8796
3755.73	32.9346
3758.71	15.225
3761.7	6.05597
3764.68	8.22473
3767.66	5.66888
3770.64	20.1884
3773.62	4.47766
3776.6	23.7964
3779.58	34.6251
3782.55	10.5306
3785.53	28.9523
3788.5	0.190491
3791.47	-0.210297
3794.44	-5.25012
3797.41	11.4595
3800.38	27.2584
3803.35	27.0819
3806.32	41.0988
3809.28	13.5684
3812.24	21.0199
3815.21	15.2512
3818.17	12.327
3821.13	25.5087
3824.09	14.0966
3827.04	-2.02966
3830	4.58017
3832.96	23.5241
3835.91	37.7948
3838.86	-3.93152
3841.82	29.3746
3844.77	25.6235
3847.72	13.3086
3850.67	5.75815
3853.61	20.1537
3856.56	36.4909
3859.5	14.6523
3862.45	39.6251
3865.39	28.2455
3868.33	13.0132
3871.27	25.5052
3874.21	3.47153
3877.15	25.5304
3880.09	17.7865
3883.02	13.8216
3885.96	14.5954
3888.89	29.7495
3891.82	32.3886
3894.75	17.6909
3897.68	25.0426
3900.61	35.2189
3903.54	17.4929
3906.47	15.0902
3909.39	-6.4769
3912.31	9.39536
3915.24	13.6822
3918.16	36.18
3921.08	34.7522
3924	3.46716
3926.92	18.2019
3929.83	10.8207
3932.75	-11.9036
3935.67	24.889
3938.58	35.9097
3941.49	41.2756
3944.4	-5.11145
3947.31	19.3824
3950.22	18.075
3953.13	16.8026
3956.04	8.84607
3958.94	20.0887
3961.85	-3.13733
3964.75	11.0283
3967.65	39.6166
3970.55	20.2831
3973.45	15.3429
3976.35	25.7507
3979.25	26.5258
3982.15	12.8513
3985.04	18.3848
3987.94	-2.06714
3990.83	5.34714
3993.72	8.8587
3996.61	-1.01102
3999.5	28.5669
4002.39	15.8233
4005.28	17.5251
4008.16	22.1425
4011.05	14.2377
4013.93	27.5332
4016.81	-3.53311
4019.7	16.5239
4022.58	19.215
4025.46	13.2172
4028.33	13.0212
4031.21	19.5938
4034.09	11.6775
4036.96	30.8505
4039.84	12.3083
4042.71	24.7263
4045.58	24.4758
4048.45	11.6496
4051.32	35.6837
4054.19	10.2917
4057.05	25.6851
4059.92	38.1616
4062.78	19.5394
4065.65	5.76099
4068.51	7.52661
4071.37	24.8547
4074.23	14.9382
4077.09	35.1935
4079.95	22.3326
4082.81	16.282
4085.66	2.42786
4088.52	13.9036
4091.37	18.5558
4094.22	26.1744
4097.07	32.784
4099.92	18.9043
4102.77	4.02307
4105.62	-5.01752
4108.47	21.0996
4111.31	12.0099
4114.16	21.4568
4117	2.47449
4119.84	3.00153
4122.69	24.0861
4125.53	5.10352
4128.36	24.2993
4131.2	-2.38324
4134.04	7.21887
4136.88	13.0514
4139.71	24.1906
4142.54	11.4149
4145.38	25.651
4148.21	19.5247
4151.04	12.4523
4153.87	24.8584
4156.69	16.5344
4159.52	18.7889
4162.35	2.62097
4165.17	25.6446
4168	24.2048
4170.82	32.5679
4173.64	12.5973
4176.46	37.6251
4179.28	16.6909
4182.1	9.48569
4184.91	0.338623
4187.73	41.1081
4190.54	5.5827
4193.36	24.922
4196.17	35.5126
4198.98	40.3032
4201.79	55.8668
4204.6	56.7553
4207.41	82.1653
4210.22	72.2562
4213.02	84.9209
4215.83	60.229
4218.63	28.8947
4221.44	14.2147
4224.24	35.9648
4227.04	17.2105
4229.84	19.2544
4232.64	14.3912
4235.43	40.2831
4238.23	33.533
4241.02	39.6872
4243.82	28.9624
4246.61	39.1496
4249.4	48.3379
4252.19	22.559
4254.98	29.692
4257.77	26.7907
4260.56	39.9068
4263.35	22.9836
4266.13	11.0579
4268.92	33.3179
4271.7	37.5055
4274.48	-0.643066
4277.26	7.44897
4280.04	23.5734
4282.82	17.4608
4285.6	25.4514
4288.38	37.4433
4291.15	7.8952
4293.93	4.63382
4296.7	1.42877
4299.47	11.4337
4302.25	9.23761
4305.02	17.1834
4307.79	-4.31006
4310.55	34.1367
4313.32	11.6745
4316.09	12.5119
4318.85	8.22357
4321.62	31.3867
4324.38	-3.50558
4327.14	11.4655
4329.9	22.3848
4332.66	13.9063
4335.42	19.7162
4338.18	27.5226
4340.94	17.071
4343.69	14.7718
4346.45	16.5954
4349.2	3.15457
4351.95	8.07819
4354.7	18.2278
4357.45	3.81009
4360.2	15.9695
4362.95	24.025
4365.7	19.8431
4368.44	8.44595
4371.19	23.7384
4373.93	19.4788
4376.68	33.6829
4379.42	12.9488
4382.16	-17.0554
4384.9	11.5211
4387.64	-0.915466
4390.37	18.6949
4393.11	22.954
4395.85	6.89212
4398.58	25.64
4401.31	18.5297
4404.05	12.3965
4406.78	1.08154
4409.51	-4.00946
4412.24	30.368
4414.96	25.1904
4417.69	4.35376
4420.42	16.6885
4423.14	18.6845
4425.87	1.91364
4428.59	26.9147
4431.31	13.2645
4434.03	12.1421
4436.75	25.6584
4439.47	11.9303
4442.19	21.2102
4444.91	4.28873
4447.62	24.0542
4450.34	21.7916
4453.05	6.88785
4455.76	19.2863
4458.47	10.6352
4461.19	18.7844
4463.89	2.80237
4466.6	29.9327
4469.31	-0.776978
4472.02	1.14465
4474.72	-4.27313
4477.43	7.20245
4480.13	21.8877
4482.83	29.2279
4485.53	18.6156
4488.23	3.72656
4490.93	13.1365
4493.63	17.1704
4496.33	16.9107
4499.02	12.4863
4501.72	13.3341
4504.41	13.0925
4507.11	8.64725
4509.8	24.3628
4512.49	10.381
4515.18	20.8132
4517.87	21.7063
4520.56	17.3033
4523.24	21.4409
4525.93	12.8136
4528.61	16.9445
4531.3	24.2876
4533.98	25.253
4536.66	11.2963
4539.34	30.4268
4542.02	-4.87918
4544.7	15.3548
4547.38	12.0904
4550.05	33.4574
4552.73	10.9453
4555.4	13.1317
4558.08	25.0471
4560.75	9.12103
4563.42	28.781
4566.09	3.25549
4568.76	24.2716
4571.43	7.17609
4574.1	5.93451
4576.77	25.1747
4579.43	33.7442
4582.1	-6.45587
4584.76	34.9799
4587.42	13.0771
4590.08	17.2933
4592.74	16.0208
4595.4	19.1381
4598.06	-1.73712
4600.72	21.0549
4603.38	5.65121
4606.03	17.6207
4608.69	12.0752
4611.34	28.4667
4613.99	25.1057
4616.64	12.9403
4619.29	20.5714
4621.94	1.80475
4624.59	17.1573
4627.24	18.1663
4629.89	14.7431
4632.53	-0.856018
4635.18	14.434
4637.82	-7.89917
4640.46	20.658
4643.1	13.8074
4645.74	8.13278
4648.38	13.6276
4651.02	18.1046
4653.66	10.4736
4656.3	8.24316
4658.93	21.265
4661.57	23.3894
4664.2	-11.2875
4666.83	12.0577
4669.46	-2.6778
4672.09	24.0198
4674.72	22.7341
4677.35	0.131439
4679.98	17.89
4682.61	17.6929
4685.23	23.1136
4687.86	20.6659
4690.48	-0.918976
4693.1	20.273
4695.73	20.0458
4698.34	18.6828
4700.96	3.7775
4703.58	8.04083
4706.2	29.2312
4708.82	11.9856
4711.43	15.0719
4714.05	14.7586
4716.66	30.2819
4719.28	27.6752
4721.89	19.3862
4724.5	15.608
4727.11	5.064
4729.72	19.4877
4732.33	15.7625
4734.93	14.3038
4737.54	-4.21722
4740.14	29.518
4742.75	-3.83136
4745.35	-5.37762
4747.95	29.4622
4750.55	23.2989
4753.15	27.3844
4755.75	26.9091
4758.35	11.6324
4760.95	16.8704
4763.54	13.02
4766.14	13.74
4768.73	16.8063
4771.33	1.65039
4773.92	14.9386
4776.51	9.97794
4779.1	31.2771
4781.69	26.3105
4784.28	22.4825
4786.87	24.3689
4789.45	15.9595
4792.04	4.11621
4794.63	25.481
4797.21	-0.103607
4799.79	6.41217
4802.37	25.5754
4804.95	2.29654
4807.53	0.850922
4810.11	23.5864
4812.69	14.1062
4815.27	4.61819
4817.84	13.5984
4820.42	5.27786
4822.99	9.66327
4825.57	22.1735
4828.14	24.2613
4830.71	17.0604
4833.28	4.04865
4835.85	13.144
4838.42	17.6296
4840.98	22.151
4843.55	2.08667
4846.12	6.5271
4848.68	22.6822
4851.24	19.98
4853.81	15.9027
4856.37	13.0461
4858.93	-0.144745
4861.49	9.01059
4864.05	-4.3252
4866.61	11.7577
4869.16	19.6038
4871.72	5.03156
4874.27	5.76569
4876.83	-3.01855
4879.38	21.4026
4881.93	3.09335
4884.49	4.93744
4887.04	12.7217
4889.58	14.5717
4892.13	14.0417
4894.68	14.6877
4897.23	9.36496
4899.77	20.7144
4902.32	-0.135803
4904.86	19.5578
4907.4	-1.33405
4909.95	-0.75824
4912.49	15.2845
4915.03	-2.13817
4917.57	10.2731
4920.1	2.4048
4922.64	2.89487
4925.18	10.5553
4927.71	3.89354
4930.25	23.4882
4932.78	21.6436
4935.31	-2.87996
4937.84	20.4097
4940.38	13.7829
4942.9	1.04742
4945.43	0.376862
4947.96	6.93314
4950.49	-9.28862
4953.01	-14.7141
4955.54	5.01595
4958.06	-0.395584
4960.59	-5.79523
4963.11	12.8603
4965.63	2.74144
4968.15	19.1512
4970.67	22.2505
4973.19	-3.62729
4975.71	15.1404
4978.22	0.0780792
4980.74	14.0456
4983.25	9.87027
4985.77	3.27068
4988.28	-2.12308
4990.79	-1.44884
4993.3	10.1595
4995.81	16.9139
4998.32	3.01237