File: Data/3-Raman/processed/bu19w-e-ff11b-fi07-v_1800 (450-850nm)_532nm_edge_100%_x100_vis_h50um_30sx2_01.txt
#Acq. time (s)=	30
#Accumulations=	2
#Range (cm-¹)=	1200...2400
#Windows=	4
#Auto scanning=	Off
#Autofocus=	Off
#Macrospot=	Off
#AutoExposure=	Off
#Spike filter=	Multiple accum.
#Delay time (s)=	2
#Binning=	1
#Readout mode=	Signal
#DeNoise=	Off
#ICS correction=	On
#Dark correction=	Off
#Inst. Process=	Off
#Detector Gain=	Best Dynamic
#Detector ADC=	50 kHz HS
#Detector temperature (°C)=	-60.09
#Instrument=	LabRAM HR Evol
#Detector=	SIN-EM FIVIS
#Objective=	x100_VIS
#Grating=	1800 (450-850nm)
#ND Filter=	100%
#Laser=	532nm_Edge
#Hole=	49.98
#Temperature=	0
#Range=	Visible
#StageXY=	75x50mm Scan+
#StageZ=	Z motor
#X (µm)=	0
#Y (µm)=	0
#Z (µm)=	-274.1
#Full time(mm:ss)=	4:21
#Project=	21_11_04
#Sample=	BU19w
#Site=
#Title=	BU19w-E-FF11b-FI07-V_1800 (450-850nm)_532nm_Edge_100%_x100_VIS_H50um_30sX2
#Remark=
#Date=	04.11.2021 17:55
#Acquired=	04.11.2021 17:55:30
#Base:Fit=	16.12.2021 17:39:50
#Base:Fit=	16.12.2021 17:47:37
#Base:Sub=	16.12.2021 17:47:38
1200.19	2.54496
1201.3	3.32944
1202.41	2.06158
1203.52	2.85566
1204.63	0.471104
1205.74	-1.92747
1206.85	2.11689
1207.97	-3.45403
1209.08	-2.59356
1210.19	0.40765
1211.3	3.39851
1212.41	-0.00289154
1213.52	5.13849
1214.63	-0.343939
1215.74	1.61808
1216.85	0.373854
1217.95	-1.91318
1219.06	0.0638943
1220.17	-3.25555
1221.28	-0.211794
1222.39	0.688835
1223.5	0.537125
1224.61	-3.8122
1225.71	-0.741911
1226.82	3.3654
1227.93	1.09333
1229.03	4.21256
1230.14	0.942516
1231.25	0.806898
1232.35	3.87764
1233.46	0.652237
1234.57	0.59635
1235.67	2.64384
1236.78	0.465618
1237.88	0.375927
1238.99	1.35202
1240.1	-1.845
1241.2	-1.89132
1242.3	3.3043
1243.41	-1.96797
1244.51	0.0892029
1245.62	4.21636
1246.72	-1.05031
1247.82	-1.09168
1248.93	-0.0683918
1250.03	-0.0979233
1251.13	2.99945
1252.24	0.877024
1253.34	1.89961
1254.44	1.9049
1255.54	-2.27821
1256.65	2.94552
1257.75	6.06513
1258.85	3.96603
1259.95	5.01954
1261.05	9.16742
1262.15	19.7019
1263.25	29.0509
1264.35	14.4858
1265.45	4.03386
1266.55	5.10566
1267.66	4.10752
1268.75	3.10617
1269.85	3.10736
1270.95	7.29542
1272.05	3.14763
1273.15	8.44155
1274.25	3.24027
1275.35	3.27368
1276.45	4.37059
1277.54	6.52479
1278.64	9.7339
1279.74	20.2744
1280.84	47.6883
1281.94	199.352
1283.03	464.91
1284.13	211.184
1285.23	47.8543
1286.32	20.5204
1287.42	11.0649
1288.52	10.0524
1289.61	3.79525
1290.71	6.99077
1291.8	0.709827
1292.9	6.01541
1293.99	3.98176
1295.09	6.15322
1296.18	0.955963
1297.28	3.09738
1298.37	5.24047
1299.47	-2.11613
1300.56	-2.0692
1301.65	1.15098
1302.75	5.41863
1303.84	-0.880238
1304.94	3.37771
1306.03	0.23667
1307.12	-0.771849
1308.21	2.4372
1309.31	2.49569
1310.4	2.54046
1311.49	0.481794
1312.58	-1.57937
1313.67	1.62685
1314.76	-1.48689
1315.86	-0.379179
1316.95	-2.44672
1318.04	0.774591
1319.13	-2.34999
1320.22	-2.30494
1321.31	1.94334
1322.4	-1.19151
1323.49	-4.3114
1324.58	-3.21089
1325.67	3.12289
1326.76	0.00697517
1327.85	-3.07582
1328.93	1.20046
1330.02	-0.869976
1331.11	3.36406
1332.2	-1.88372
1333.29	2.3385
1334.37	-0.790438
1335.46	-2.85891
1336.55	0.320286
1337.64	1.39869
1338.72	-0.664057
1339.81	1.47622
1340.9	0.471945
1341.98	-0.544933
1343.07	2.62185
1344.16	3.70971
1345.24	-0.449213
1346.33	0.607561
1347.41	1.67015
1348.5	5.86909
1349.58	1.72593
1350.67	3.82839
1351.75	3.859
1352.84	0.802254
1353.92	3.93083
1355.01	1.87063
1356.09	-0.163679
1357.17	5.05824
1358.26	4.04202
1359.34	6.13835
1360.42	5.11356
1361.5	2.03984
1362.59	5.17613
1363.67	5.226
1364.75	2.14446
1365.83	8.36742
1366.92	3.2083
1368	10.4855
1369.08	27.071
1370.16	9.50986
1371.24	6.41796
1372.32	8.47983
1373.4	7.46928
1374.48	7.49423
1375.56	10.6207
1376.64	10.624
1377.72	15.8279
1378.8	17.9557
1379.88	14.8538
1380.96	24.0996
1382.04	23.0306
1383.12	33.2631
1384.2	54.8234
1385.28	141.173
1386.36	730.891
1387.43	578.994
1388.51	91.9731
1389.59	33.4851
1390.67	19.0895
1391.74	20.1153
1392.82	7.83701
1393.9	16.0418
1394.97	10.96
1396.05	10.9859
1397.13	13.0395
1398.2	11.0245
1399.28	5.94547
1400.35	4.9593
1401.43	4.99109
1402.5	8.14167
1403.58	9.19107
1404.65	11.254
1405.73	16.3833
1406.8	22.558
1407.88	47.2009
1408.95	42.1171
1410.03	14.4401
1411.1	5.21045
1412.17	4.21914
1413.25	2.20879
1414.32	4.29777
1415.39	8.42813
1416.47	6.40591
1417.54	5.40876
1418.61	4.40539
1419.68	2.35872
1420.75	5.44192
1421.83	3.42476
1422.9	5.5649
1423.97	2.37511
1425.04	4.46605
1426.11	3.46701
1427.18	3.45723
1428.25	0.396606
1429.32	2.47248
1430.39	2.51312
1431.46	1.52147
1432.53	2.5451
1433.6	1.51031
1434.67	3.59069
1435.74	3.60444
1436.81	3.61401
1437.88	2.60511
1438.95	0.579437
1440.01	3.68621
1441.08	2.67652
1442.15	1.66934
1443.22	2.70336
1444.29	4.77706
1445.35	-0.330475
1446.42	0.704596
1447.49	0.712294
1448.56	3.81294
1449.62	0.742077
1450.69	1.77447
1451.75	-1.29169
1452.82	-0.249491
1453.89	3.8623
1454.95	0.800051
1456.02	0.819155
1457.08	-1.22541
1458.15	0.836349
1459.21	1.87676
1460.28	-1.18856
1461.34	0.863064
1462.41	-0.161869
1463.47	-0.159487
1464.53	1.93288
1465.6	2.89566
1466.66	-2.20186
1467.72	-0.152205
1468.79	-1.16395
1469.85	0.873676
1470.91	-0.142054
1471.97	-0.136932
1473.04	-3.1848
1474.1	-0.124275
1475.16	-2.14632
1476.22	-1.12422
1477.29	1.93102
1478.34	1.932
1479.41	0.91287
1480.47	-1.1243
1481.53	0.917681
1482.59	-2.10762
1483.65	-1.08188
1484.71	2.9201
1485.77	-1.08931
1486.83	-0.0699654
1487.89	-1.08594
1488.95	0.936342
1490.01	-1.07986
1491.07	2.96487
1492.12	1.96342
1493.18	-2.07271
1494.24	2.99452
1495.3	-2.06502
1496.36	-1.05612
1497.42	-0.0395584
1498.47	-1.03764
1499.53	-0.0133686
1500.59	1.00479
1501.64	1.00765
1502.7	-2.01847
1503.76	1.01409
1504.81	2.02923
1505.87	1.01559
1506.93	-0.985832
1507.98	0.0297661
1509.04	0.0402641
1510.09	0.0487766
1511.15	0.0371456
1512.21	-0.990494
1513.26	2.01977
1514.31	2.03991
1515.37	2.02814
1516.42	2.02588
1517.48	1.03429
1518.53	1.05007
1519.58	0.0588512
1520.64	-2.94058
1521.69	1.08088
1522.75	-0.925362
1523.8	0.067194
1524.85	2.07793
1525.9	1.09871
1526.95	0.106518
1528.01	0.109663
1529.06	-0.88682
1530.11	0.122696
1531.16	0.140722
1532.21	1.15331
1533.27	0.178438
1534.32	0.185698
1535.37	-1.82548
1536.42	0.166239
1537.47	2.16513
1538.52	2.16349
1539.57	1.21256
1540.62	0.236748
1541.67	0.230474
1542.72	2.22513
1543.77	-0.78067
1544.81	0.244957
1545.86	2.26976
1546.91	1.28311
1547.96	-2.72576
1549.01	-1.7413
1550.06	2.33134
1551.1	1.3591
1552.15	1.37458
1553.2	1.36069
1554.25	5.35973
1555.3	3.35698
1556.34	2.3636
1557.39	-0.631405
1558.43	0.359753
1559.48	-0.646219
1560.53	3.35496
1561.57	0.377756
1562.62	0.38868
1563.66	0.404438
1564.71	2.39935
1565.76	0.404011
1566.8	1.42607
1567.84	2.43155
1568.89	-1.56391
1569.93	2.44301
1570.98	2.4488
1572.02	-0.54759
1573.07	2.44586
1574.11	2.46358
1575.15	4.48849
1576.2	-0.503244
1577.24	2.47637
1578.28	4.46513
1579.32	1.48575
1580.37	2.49452
1581.41	1.49507
1582.45	-1.49068
1583.49	2.49954
1584.53	1.51682
1585.58	0.525761
1586.62	-0.472834
1587.66	0.528833
1588.7	1.54215
1589.74	1.55596
1590.78	1.56991
1591.82	1.57017
1592.86	2.55417
1593.9	5.52249
1594.94	2.5621
1595.98	0.575111
1597.02	2.57561
1598.06	0.592436
1599.1	0.587517
1600.14	2.56784
1601.17	0.573017
1602.21	2.53201
1603.25	5.44351
1604.29	4.32072
1605.33	3.05133
1606.37	3.3684
1607.4	3.65458
1608.44	-0.244219
1609.48	4.02574
1610.51	2.06113
1611.55	1.01745
1612.59	3.50054
1613.62	2.86193
1614.66	3.22231
1615.7	1.69903
1616.73	3.24215
1617.77	5.7961
1618.8	4.50475
1619.84	3.44301
1620.87	5.80733
1621.91	2.232
1622.94	3.61204
1623.98	3.98323
1625.01	3.24767
1626.04	2.12813
1627.08	3.73701
1628.11	3.66059
1629.07	2.70579
1630.12	1.72547
1631.16	0.751835
1632.21	1.75878
1633.25	3.72799
1634.3	2.75873
1635.34	0.792707
1636.39	5.71813
1637.43	4.73273
1638.48	-0.18474
1639.52	0.807976
1640.57	3.77736
1641.61	5.75028
1642.65	3.78696
1643.7	5.75864
1644.74	3.7965
1645.78	3.80601
1646.83	1.83951
1647.87	8.73026
1648.91	3.84232
1649.95	7.79522
1651	4.86383
1652.04	2.90343
1653.08	6.84764
1654.12	3.90586
1655.16	3.93029
1656.21	0.993284
1657.25	4.94555
1658.29	0.999161
1659.33	2.96856
1660.37	2.98209
1661.41	3.99036
1662.45	4.03681
1663.49	3.00832
1664.53	6.01316
1665.57	2.08311
1666.61	3.01608
1667.65	5.01982
1668.69	4.06129
1669.72	-0.870203
1670.76	1.1269
1671.8	6.07804
1672.84	4.10986
1673.88	2.14756
1674.92	-0.802568
1675.95	1.18592
1676.99	5.15162
1678.03	2.17736
1679.07	1.18711
1680.1	-2.76494
1681.14	0.202869
1682.18	2.18614
1683.21	2.19173
1684.25	1.20502
1685.29	2.19784
1686.32	1.22337
1687.36	1.22795
1688.39	2.21334
1689.43	1.21964
1690.46	1.22923
1691.5	2.22838
1692.53	2.22655
1693.57	-2.71285
1694.6	1.22673
1695.64	1.23753
1696.67	1.24515
1697.7	0.250663
1698.74	0.248508
1699.77	0.255211
1700.81	-0.727692
1701.84	3.20026
1702.87	3.19783
1703.9	-0.727924
1704.94	1.24326
1705.97	0.259371
1707	0.249374
1708.03	2.19451
1709.06	2.18194
1710.1	0.229408
1711.13	0.241774
1712.16	-0.738896
1713.19	-1.73583
1714.22	-1.74023
1715.25	3.15533
1716.28	1.19723
1717.31	3.12422
1718.34	1.15717
1719.37	1.15893
1720.4	3.1071
1721.43	-0.795588
1722.46	1.13695
1723.49	2.10497
1724.52	0.157045
1725.55	1.10911
1726.58	1.10854
1727.6	-2.76467
1728.63	0.0874281
1729.66	1.0734
1730.69	2.04932
1731.72	0.120144
1732.74	0.114378
1733.77	1.05984
1734.8	-1.84731
1735.82	1.03452
1736.85	-1.85653
1737.88	-1.86205
1738.91	-0.911573
1739.93	0.026371
1740.96	0.0145893
1741.98	-0.946997
1743.01	-1.9046
1744.03	-0.953835
1745.06	0.962385
1746.09	-0.00190163
1747.11	0.940029
1748.13	0.938161
1749.16	-0.00637341
1750.18	0.966672
1751.21	0.969881
1752.23	0.000631332
1753.26	-2.87127
1754.28	-0.971297
1755.3	1.88177
1756.33	0.913697
1757.35	0.903728
1758.37	0.91444
1759.39	0.917937
1760.42	-1.93959
1761.44	0.905987
1762.46	1.86275
1763.48	0.916171
1764.5	-0.0186014
1765.53	-1.91541
1766.55	-1.91545
1767.57	-0.0157099
1768.59	-0.0261755
1769.61	-1.9424
1770.63	1.86876
1771.65	-0.0165367
1772.67	-0.955479
1773.69	-0.947521
1774.71	0.0119228
1775.73	0.0302629
1776.75	0.979623
1777.77	-2.83895
1778.79	2.85969
1779.81	1.91445
1780.83	2.87335
1781.85	0.979321
1782.86	-1.868
1783.88	0.0498056
1784.9	1.96662
1785.92	0.0566511
1786.94	1.02582
1787.95	-2.76143
1788.97	0.129747
1789.99	2.05814
1791	0.128044
1792.02	1.08554
1793.04	0.133739
1794.05	1.09558
1795.07	-1.75571
1796.09	2.09822
1797.1	1.15187
1798.12	1.1597
1799.13	0.193672
1800.15	1.14563
1801.16	-1.73724
1802.18	-0.770032
1803.19	1.16588
1804.21	1.17519
1805.22	0.228988
1806.24	0.240856
1807.25	-0.72005
1808.26	-3.60929
1809.28	1.21407
1810.29	2.17952
1811.3	2.17904
1812.32	-0.706839
1813.33	3.1619
1814.34	-0.680167
1815.36	0.294156
1816.37	2.23196
1817.38	-1.64797
1818.39	2.22747
1819.4	4.16728
1820.42	0.308654
1821.43	-1.61709
1822.44	2.26046
1823.45	1.28997
1824.46	2.26363
1825.47	1.30113
1826.48	2.27173
1827.49	-0.627319
1828.5	2.27444
1829.51	-1.60232
1830.52	1.29847
1831.53	0.339512
1832.54	-0.619164
1833.55	-0.615914
1834.56	3.23772
1835.57	-0.64848
1836.58	2.29166
1837.58	1.27545
1838.59	-2.5645
1839.6	2.29324
1840.61	0.31039
1841.62	-1.64567
1842.62	1.24126
1843.63	-0.687426
1844.64	2.20652
1845.65	1.25931
1846.65	-2.61913
1847.66	2.18372
1848.67	1.21406
1849.67	-0.727954
1850.68	0.216804
1851.68	3.09104
1852.69	-0.749896
1853.69	4.03804
1854.7	-1.7311
1855.71	0.173091
1856.71	1.13002
1857.72	-1.74966
1858.72	-1.76179
1859.72	-1.76675
1860.73	2.06896
1861.73	-1.75252
1862.74	1.10446
1863.74	-4.64038
1864.74	0.123783
1865.75	-1.80478
1866.75	1.02744
1867.75	0.0624218
1868.76	1.01407
1869.76	0.0606747
1870.76	1.01001
1871.76	0.0527649
1872.77	-0.905525
1873.77	0.986249
1874.77	3.81404
1875.77	-2.84071
1876.77	2.81604
1877.77	0.0321894
1878.78	0.0126152
1879.78	-0.938748
1880.78	0.00671577
1881.78	0.921183
1882.78	0.899864
1883.78	0.884271
1884.78	0.900242
1885.78	-0.970684
1886.78	-0.979119
1887.78	-0.0505333
1888.77	-1.01164
1889.77	-1.01159
1890.77	-1.94573
1891.77	-1.00557
1892.77	-1.95741
1893.77	3.67018
1894.76	-1.03556
1895.76	1.79212
1896.76	-1.0165
1897.76	-1.01436
1898.75	-1.96436
1899.75	-0.0911922
1900.75	-2.9037
1901.75	-1.95058
1902.74	-0.0684166
1903.74	0.868786
1904.74	1.80804
1905.73	0.857864
1906.73	1.79185
1907.72	3.67992
1908.72	-3.82879
1909.71	-0.991061
1910.71	-2.85805
1911.7	-2.85576
1912.7	-0.0291367
1913.69	-0.956596
1914.69	0.00125027
1915.68	0.0042038
1916.68	-0.945909
1917.67	-0.00460911
1918.66	0.95644
1919.66	0.97959
1920.65	0.986493
1921.64	0.999003
1922.64	-1.84152
1923.63	-0.899869
1924.62	-0.90139
1925.61	1.00651
1926.61	-0.867016
1927.6	0.0904589
1928.59	-0.847707
1929.58	-1.77946
1930.57	1.08335
1931.57	1.08039
1932.56	-0.822045
1933.55	-0.807715
1934.54	1.1468
1935.53	1.15904
1936.52	-0.750515
1937.51	0.191776
1938.5	2.10365
1939.49	2.11758
1940.48	-0.719185
1941.47	1.18757
1942.46	0.254204
1943.45	-2.62237
1944.44	-0.692321
1945.42	1.23687
1946.41	2.20461
1947.4	0.291137
1948.39	0.29388
1949.38	1.26788
1950.37	-0.620462
1951.35	-1.55525
1952.34	0.375343
1953.33	-0.586595
1954.32	-2.53113
1955.3	0.35117
1956.29	-0.578238
1957.28	1.35894
1958.26	-2.47656
1959.25	3.28621
1960.23	-1.52319
1961.22	1.35102
1962.21	0.397762
1963.19	-4.39613
1964.18	-1.50905
1965.16	0.414306
1966.15	0.429927
1967.13	-1.48472
1968.12	-0.51777
1969.1	0.43356
1970.09	2.34243
1971.07	-1.50002
1972.05	1.38412
1973.04	-0.538531
1974.02	-1.49936
1975.01	-0.532907
1975.99	-0.522378
1976.97	2.35795
1977.95	1.39311
1978.94	1.39503
1979.92	1.39813
1980.9	-0.523494
1981.88	-0.523016
1982.87	2.33848
1983.85	1.3779
1984.83	0.415417
1985.81	0.421579
1986.79	2.20219
1987.77	0.598262
1988.75	2.12881
1989.73	0.95263
1990.72	0.110432
1991.7	0.477834
1992.68	1.05056
1993.66	0.6369
1994.63	-0.424073
1995.61	-0.471876
1996.59	0.557464
1997.57	2.27507
1998.55	0.978702
1999.53	0.820558
2000.51	1.60356
2001.49	1.55656
2002.47	-1.56244
2003.45	-0.48176
2004.42	1.26584
2005.4	0.10726
2006.38	0.68486
2007.36	0.057332
2008.31	-1.57682
2009.3	0.297155
2010.29	-1.59492
2011.28	0.291308
2012.27	-3.47482
2013.26	0.273914
2014.24	0.250244
2015.23	3.07552
2016.22	2.15921
2017.21	-0.661982
2018.2	-0.67961
2019.18	-2.56779
2020.17	1.17905
2021.16	-0.688427
2022.15	0.244522
2023.14	1.1689
2024.12	1.15682
2025.11	-0.72641
2026.1	0.210968
2027.08	-1.6142
2028.07	-0.731899
2029.06	0.273346
2030.04	1.14931
2031.03	-1.63668
2032.01	0.244899
2033	-0.667889
2033.98	1.18889
2034.97	-0.677845
2035.95	1.21934
2036.94	0.286212
2037.92	0.28342
2038.91	-0.656827
2039.89	2.13232
2040.87	1.18888
2041.86	-0.677472
2042.84	0.255869
2043.83	0.278978
2044.81	2.11694
2045.79	1.27246
2046.78	-1.56954
2047.76	2.14601
2048.74	-0.639509
2049.72	-0.618754
2050.71	1.25856
2051.69	0.321363
2052.67	-0.601488
2053.65	0.35386
2054.63	1.29383
2055.62	0.354576
2056.6	-1.51519
2057.58	-1.50587
2058.56	-0.554727
2059.54	0.388509
2060.52	-0.547389
2061.5	-2.41224
2062.48	-0.530621
2063.46	1.35577
2064.44	1.36649
2065.42	2.32642
2066.4	1.39902
2067.38	2.35025
2068.36	-0.458723
2069.34	0.469204
2070.31	0.488295
2071.29	2.39791
2072.27	3.3418
2073.25	-2.30596
2074.23	1.47021
2075.21	0.556648
2076.18	-0.376204
2077.16	2.44082
2078.14	-1.32399
2079.12	2.46949
2080.09	1.5385
2081.07	0.592989
2082.05	-0.347613
2083.02	2.4897
2084	2.49166
2084.98	-1.28505
2085.95	0.618428
2086.93	-1.26246
2087.9	1.58071
2088.88	1.58841
2089.85	-0.294725
2090.83	0.660907
2091.8	-0.269726
2092.78	1.64948
2093.75	0.715324
2094.73	-0.235189
2095.7	-1.19246
2096.68	-1.19516
2097.65	1.64716
2098.62	-2.15144
2099.6	1.64473
2100.57	1.65392
2101.54	4.51051
2102.52	-0.241381
2103.49	-1.19489
2104.46	-2.13746
2105.44	-1.17658
2106.41	3.58204
2107.38	-2.12411
2108.35	0.712257
2109.32	1.67008
2110.3	1.67091
2111.27	0.717747
2112.24	3.56726
2113.21	-1.17161
2114.18	0.728128
2115.15	0.727128
2116.12	0.718341
2117.09	0.71684
2118.06	2.60304
2119.03	1.63844
2120	0.681546
2120.97	1.63826
2121.94	-0.245388
2122.91	0.710714
2123.88	1.65361
2124.85	0.678947
2125.82	1.60613
2126.79	-0.299523
2127.76	1.5859
2128.72	0.638422
2129.69	0.633864
2130.66	1.57181
2131.63	2.50612
2132.6	-0.336125
2133.56	0.607727
2134.53	2.49427
2135.5	-2.23049
2136.47	1.53062
2137.43	-0.350272
2138.4	2.47105
2139.37	1.51997
2140.33	-0.374596
2141.3	3.38438
2142.26	1.49884
2143.23	1.45715
2144.19	-0.403422
2145.16	2.41109
2146.13	1.46338
2147.09	0.513957
2148.06	0.504427
2149.02	1.42844
2149.98	-1.40407
2150.95	2.34577
2151.91	2.35085
2152.88	1.39977
2153.84	-0.486878
2154.8	-0.513429
2155.77	3.20559
2156.73	-1.47078
2157.69	-0.531453
2158.66	3.20201
2159.62	1.31711
2160.58	-0.564848
2161.54	1.29361
2162.51	0.355372
2163.47	3.14204
2164.43	1.26117
2165.39	-0.603112
2166.35	0.318997
2167.32	-0.629441
2168.28	1.21043
2169.24	1.21836
2170.2	2.16227
2171.16	-0.648028
2172.12	-0.672096
2173.08	1.17945
2174.04	1.18068
2175	-2.54239
2175.96	0.23733
2176.92	-2.55654
2177.88	-0.704629
2178.84	1.14172
2179.8	-0.719748
2180.76	1.12945
2181.72	-2.59326
2182.68	1.10536
2183.63	-0.76747
2184.59	-0.772825
2185.55	-0.771132
2186.51	1.09373
2187.47	0.173161
2188.43	3.86956
2189.38	0.134597
2190.34	2.91025
2191.3	1.98153
2192.25	0.126983
2193.21	-1.7236
2194.17	0.14934
2195.12	1.99507
2196.08	1.96898
2197.04	3.80557
2197.99	1.02454
2198.95	1.96738
2199.9	0.130076
2200.86	1.07766
2201.81	1.91403
2202.77	1.03015
2203.72	1.0677
2204.68	1.03615
2205.63	0.0781164
2206.59	1.93063
2207.54	0.0769758
2208.49	-0.848958
2209.45	2.87191
2210.4	-1.78406
2211.36	-1.78062
2212.31	-0.849596
2213.26	1.00105
2214.22	1.01239
2215.17	1.01097
2216.12	1.00432
2217.07	1.93093
2218.03	2.85959
2218.98	-1.807
2219.93	0.994193
2220.88	0.0461617
2221.83	1.89448
2222.78	1.89434
2223.74	-0.898686
2224.69	-0.891167
2225.64	0.989804
2226.59	0.996095
2227.54	0.0567474
2228.49	-2.76661
2229.44	0.0457783
2230.39	-0.886867
2231.34	1.93818
2232.29	2.88562
2233.24	1.95177
2234.19	-0.876714
2235.14	-0.896876
2236.09	-1.84103
2237.04	3.80675
2237.98	1.00109
2238.93	-0.876221
2239.88	0.0488214
2240.83	-1.8326
2241.78	-1.83503
2242.73	-0.894773
2243.67	0.0366745
2244.62	-0.899713
2245.57	-1.83721
2246.52	-4.67361
2247.46	0.0550308
2248.41	-1.84754
2249.36	0.0419579
2250.3	-0.919224
2251.25	1.90182
2252.2	-0.932891
2253.14	-0.916228
2254.09	0.0365953
2255.03	-0.918286
2255.98	-1.86622
2256.92	-1.86309
2257.87	1.93443
2258.81	3.83704
2259.76	0.987444
2260.7	0.0419722
2261.65	0.993806
2262.59	0.0471821
2263.54	1.01624
2264.48	0.0767536
2265.42	-0.877161
2266.37	-1.84909
2267.31	0.997418
2268.26	-2.82849
2269.2	0.0413742
2270.14	1.00985
2271.08	1.01581
2272.03	-2.80836
2272.97	-0.896774
2273.91	-0.898567
2274.85	-0.899797
2275.79	0.0598717
2276.74	-0.889052
2277.68	0.0892963
2278.62	2.00865
2279.56	1.98638
2280.5	-2.82611
2281.44	0.0427847
2282.38	0.0493793
2283.32	0.0678148
2284.26	1.04609
2285.2	1.05146
2286.14	2.00088
2287.08	2.01854
2288.02	-1.83501
2288.96	-0.890382
2289.9	3.89858
2290.84	0.0578527
2291.78	-1.85604
2292.72	0.0800123
2293.66	-0.882725
2294.6	-0.894251
2295.54	1.98354
2296.47	1.97084
2297.41	0.0583401
2298.35	1.03484
2299.29	1.04561
2300.23	2.0107
2301.16	-2.80832
2302.1	1.04875
2303.04	0.0814877
2303.97	0.0880709
2304.91	0.0963869
2305.85	-0.864342
2306.78	0.102078
2307.72	1.06188
2308.65	2.03066
2309.59	2.04818
2310.53	1.08087
2311.46	-2.81156
2312.4	0.0748816
2313.33	0.0892487
2314.27	1.07821
2315.2	-0.855148
2316.14	0.0925846
2317.07	1.05961
2318	0.094923
2318.94	0.087429
2319.87	2.0177
2320.81	0.0972843
2321.74	1.08297
2322.67	-0.841347
2323.61	4.00062
2324.54	3.0247
2325.47	6.87185
2326.41	13.6089
2327.34	52.1468
2328.27	85.8874
2329.2	15.5043
2330.13	6.83959
2331.07	0.104914
2332	2.99877
2332.93	-1.81872
2333.86	0.104646
2334.79	2.02592
2335.72	1.07143
2336.66	-0.84863
2337.59	2.0388
2338.52	-0.838421
2339.45	1.09029
2340.38	-0.834062
2341.31	-0.844545
2342.24	-0.844664
2343.17	1.08003
2344.1	1.09103
2345.02	0.136278
2345.95	-0.822294
2346.88	0.141556
2347.81	1.10243
2348.74	1.0513
2349.67	0.0187054
2350.6	1.84188
2351.53	-0.321779
2352.45	0.940572
2353.38	0.97438
2354.31	-1.416
2355.24	2.7364
2356.17	-1.38129
2357.09	0.398671
2358.02	0.663765
2358.95	0.347988
2359.87	0.019249
2360.8	0.84762
2361.73	-0.0227547
2362.65	0.471122
2363.58	1.90349
2364.5	-2.2471
2365.43	2.08418
2366.36	-1.08764
2367.28	-1.25225
2368.2	2.62362
2368.98	-0.673831
2369.92	0.27492
2370.86	-1.60099
2371.79	0.295936
2372.73	0.308355
2373.67	1.26306
2374.6	0.333787
2375.54	0.347201
2376.48	0.362455
2377.41	-1.49759
2378.35	-0.545997
2379.28	-1.47478
2380.22	-1.45638
2381.15	2.31204
2382.09	-0.471018
2383.02	0.48784
2383.96	-0.421615
2384.89	-0.398521
2385.83	2.42032
2386.76	-3.17151
2387.69	2.44715
2388.63	-0.323862
2389.56	2.50079
2390.5	0.667998
2391.43	2.56676
2392.36	-0.204495
2393.3	-2.98652
2394.23	-1.1022
2395.16	-0.13322
2396.09	1.80884
2397.02	-0.0306568
2397.96	0.937409
2398.89	0.972382
2399.82	0.0777092