File: Data/3-Raman/processed/bu19w-e-ff11-fi02-l_150 (500nm)_633nm_edge_100%_x100_vis_h50um_60sx2_01_0.txt
#Acq. time (s)=	60
#Accumulations=	2
#Range (cm-¹)=	100...4000
#Windows=	1
#Auto scanning=	Off
#Autofocus=	Off
#Macrospot=	Off
#AutoExposure=	Off
#Spike filter=	Multiple accum.
#Delay time (s)=	2
#Binning=	1
#Readout mode=	Signal
#DeNoise=	Off
#ICS correction=	On
#Dark correction=	Off
#Inst. Process=	Off
#Detector Gain=	Best Dynamic
#Detector ADC=	50 kHz HS
#Detector temperature (°C)=	-60.09
#Instrument=	LabRAM HR Evol
#Detector=	SIN-EM FIVIS
#Objective=	x100_VIS
#Grating=	150 (500nm)
#ND Filter=	100%
#Laser=	633nm_Edge
#Hole=	49.98
#Temperature=	0
#Range=	Visible
#StageXY=	75x50mm Scan+
#StageZ=	Z motor
#X (µm)=	0
#Y (µm)=	0
#Z (µm)=	-281.7
#Full time(mm:ss)=	2:04
#Project=	21_11_04
#Sample=	BU19w
#Site=
#Title=	BU19w-E-FF11-FI02-L_150 (500nm)_633nm_Edge_100%_x100_VIS_H50um_60sX2
#Remark=
#Date=	04.11.2021 16:29
#Acquired=	04.11.2021 16:29:18
#Base:Fit=	16.12.2021 17:39:50
#Base:Edit=	16.12.2021 17:51:01
#Base:Edit=	16.12.2021 17:51:01
#Base:Edit=	16.12.2021 17:51:02
#Base:Edit=	16.12.2021 17:51:03
#Base:Edit=	16.12.2021 17:51:04
#Base:Sub=	16.12.2021 17:51:05
102.881	88.3278
109.397	72.3492
115.908	68.9594
122.414	72.3835
128.914	75.9723
135.409	95.9328
141.898	110.233
148.383	107.509
154.861	186.373
161.335	185.019
167.801	77.3751
174.264	29.1239
180.721	5.80682
187.173	0.702393
193.62	8.05974
200.061	-0.66481
206.496	9.01294
212.926	12.9995
219.352	69.5111
225.772	204.097
232.185	273.507
238.595	123.413
244.999	63.989
251.397	73.0726
257.791	88.8065
264.178	92.2959
270.561	70.2702
276.939	78.68
283.31	80.4335
289.678	46.1416
296.039	55.4214
302.396	73.2289
308.746	137.313
315.093	364.691
321.433	520.16
327.768	306.857
334.099	136.18
340.423	97.5849
346.743	119.32
353.058	140.996
359.367	123.965
365.671	91.8926
371.971	40.1707
378.265	26.083
384.553	3.6344
390.837	14.2134
397.116	14.6136
403.389	15.139
409.657	22.2328
415.92	41.5341
422.178	59.8816
428.431	96.7226
434.678	85.9772
440.921	99.7119
447.158	131.141
453.391	145.49
459.618	102.982
465.84	62.7267
472.057	44.067
478.27	37.6649
484.477	43.3584
490.679	52.7702
496.876	61.2582
503.068	90.2818
509.255	123.076
515.436	129.82
521.613	128.298
527.785	128.761
533.952	117.155
540.113	85.6828
546.27	60.5016
552.423	65.2766
558.568	47.2937
564.711	43.2065
570.848	35.2163
576.979	44.0178
583.107	57.4506
589.228	69.9791
595.345	74.2607
601.458	93.695
607.565	104.065
613.667	108.956
619.764	92.4571
625.856	47.6949
631.944	55.2685
638.026	33.3253
644.104	49.7955
650.177	61.4869
656.244	46.7089
662.308	23.5486
668.365	20.1185
674.418	11.3162
680.467	3.50251
686.511	2.2867
692.549	9.57918
698.582	3.7945
704.611	1.70515
710.635	7.05463
716.655	3.73125
722.669	-0.524841
728.679	4.52133
734.683	4.82191
740.683	6.98222
746.678	12.8874
752.669	7.64254
758.654	9.93176
764.635	4.00777
770.611	13.1139
776.582	7.2239
782.549	6.86217
788.511	9.24929
794.466	6.86159
800.419	10.9842
806.366	8.4221
812.309	15.2233
818.247	19.106
824.18	15.4394
830.108	19.2761
836.033	19.5671
841.952	25.6426
847.865	35.5118
853.776	28.5628
859.681	46.0995
865.58	60.9032
871.476	66.2705
877.366	67.6804
883.253	78.484
889.134	73.0393
895.012	70.3471
900.883	65.5833
906.751	67.3446
912.614	64.3502
918.473	72.7277
924.326	88.8038
930.174	99.4779
936.019	131.067
941.859	161.293
947.693	212.689
953.525	209.255
959.35	232.35
965.171	239.028
970.988	297.333
976.801	405.245
982.608	424.114
988.411	398.585
994.209	290.819
1000	268.427
1005.79	241.515
1011.58	283.668
1017.36	322.32
1023.13	261.846
1028.9	198.59
1034.67	174.482
1040.43	159.958
1046.19	140.508
1051.94	124.664
1057.69	102.79
1063.44	102.055
1069.17	108.877
1074.91	116.654
1080.64	167.002
1086.37	244.369
1092.09	344.007
1097.8	332.19
1103.52	250.793
1109.22	191.98
1114.93	152.846
1120.63	151.679
1126.32	146.381
1132.01	198.802
1137.7	251.466
1143.38	329.894
1149.06	411.213
1154.73	284.58
1160.4	147.62
1166.06	106.943
1171.72	84.063
1177.38	63.1936
1183.03	51.2549
1188.67	53.1742
1194.31	31.7566
1199.95	20.1865
1205.58	29.3194
1211.21	21.812
1216.84	17.264
1222.46	14.7009
1228.07	20.1054
1233.68	18.4713
1239.29	16.7413
1244.89	12.8586
1250.49	18.9584
1256.08	13.8743
1261.67	14.7322
1267.26	13.5442
1272.84	0.240974
1278.42	9.0404
1283.99	11.798
1289.56	13.5917
1295.12	13.4421
1300.68	14.349
1306.23	11.35
1311.78	13.4769
1317.33	8.64035
1322.87	0.77137
1328.41	8.07556
1333.94	9.31598
1339.47	4.3916
1345	-1.66876
1350.52	6.55962
1356.04	8.61581
1361.55	7.5324
1367.06	15.6253
1372.56	18.5363
1378.06	16.3063
1383.56	15.091
1389.05	8.74047
1394.53	13.7316
1400.02	13.7132
1405.5	5.45259
1410.97	14.7177
1416.44	13.7178
1421.91	8.58206
1427.37	0.322792
1432.83	3.47329
1438.28	4.54211
1443.73	12.9333
1449.17	2.45061
1454.62	19.1421
1460.05	3.23289
1465.48	8.26957
1470.91	5.93425
1476.34	1.51776
1481.76	13.9353
1487.17	6.4295
1492.59	6.31664
1497.99	6.24492
1503.4	1.97553
1508.8	12.5417
1514.19	3.01965
1519.59	6.25412
1524.97	2.04227
1530.36	4.23756
1535.74	7.54378
1541.11	11.8632
1546.48	0.937851
1551.85	11.494
1557.21	12.1846
1562.57	13.9728
1567.93	11.4388
1573.28	2.44203
1578.62	12.8824
1583.97	15.8372
1589.3	12.3601
1594.64	14.3107
1599.97	5.5179
1605.3	8.63756
1610.62	18.3484
1615.94	4.27011
1621.25	8.69112
1626.56	12.0412
1631.87	6.59999
1637.17	7.66727
1642.47	10.7883
1647.76	15.0483
1653.05	12.6293
1658.34	9.04235
1663.62	9.85302
1668.9	0.65799
1674.18	0.3255
1679.45	-1.13611
1684.71	7.32439
1689.98	2.47095
1695.23	8.74921
1700.49	0.771477
1705.74	4.23756
1710.99	12.9436
1716.23	4.82259
1721.47	11.4662
1726.7	11.281
1731.94	6.65376
1737.16	0.869453
1742.39	9.71294
1747.61	11.7963
1752.82	17.2255
1758.03	3.37294
1763.24	13.2272
1768.44	16.3083
1773.64	11.4742
1778.84	6.67803
1784.03	9.87627
1789.22	7.43847
1794.41	22.139
1799.59	11.7734
1804.76	9.40922
1809.94	13.8928
1815.11	4.53547
1820.27	10.1565
1825.43	5.39296
1830.59	21.5078
1835.74	5.14522
1840.89	7.30928
1846.04	7.11532
1851.18	6.90575
1856.32	6.65531
1861.45	14.6786
1866.58	2.77701
1871.71	3.7545
1876.83	12.9432
1881.95	3.24478
1887.07	2.95588
1892.18	8.49594
1897.29	10.4801
1902.39	10.2066
1907.49	7.66714
1912.59	11.1654
1917.68	-0.772118
1922.77	3.72954
1927.86	10.7355
1932.94	11.7678
1938.02	6.76834
1943.09	7.72871
1948.16	7.4528
1953.23	9.53447
1958.29	4.35658
1963.35	1.56623
1968.41	11.9971
1973.46	9.11984
1978.51	8.65346
1983.55	14.1997
1988.59	14.9457
1993.63	-1.12287
1998.66	12.8933
2003.69	1.69905
2008.72	14.6011
2013.74	4.67991
2018.76	11.5947
2023.77	4.06861
2028.78	9.87059
2033.79	9.70609
2038.79	-1.34889
2043.79	11.8546
2048.79	9.31647
2053.78	3.0556
2058.77	9.0266
2063.76	12.5981
2068.74	8.82317
2073.72	11.1683
2078.69	2.41732
2083.66	5.94939
2088.63	16.857
2093.59	11.7641
2098.55	19.1323
2103.51	14.1193
2108.46	19.0958
2113.41	15.3852
2118.36	21.7138
2123.3	16.7415
2128.24	24.3439
2133.17	7.90038
2138.11	10.3719
2143.03	20.464
2147.96	17.8121
2152.88	22.739
2157.79	9.75227
2162.71	1.80734
2167.62	10.4214
2172.52	1.16924
2177.43	13.686
2182.32	15.8917
2187.22	19.3379
2192.11	12.6155
2197	14.9099
2201.89	13.4436
2206.77	9.46289
2211.64	2.94743
2216.52	-0.980484
2221.39	-4.89517
2226.26	13.2301
2231.12	14.5391
2235.98	14.5513
2240.84	15.8679
2245.69	14.5812
2250.54	11.9718
2255.39	17.2408
2260.23	9.35445
2265.07	5.35196
2269.9	15.857
2274.74	21.0243
2279.57	10.2021
2284.39	21.8978
2289.21	13.6002
2294.03	13.2784
2298.84	9.0119
2303.66	12.802
2308.46	22.0399
2313.27	3.29503
2318.07	-0.725815
2322.87	16.749
2327.66	15.4765
2332.45	6.11569
2337.24	14.3611
2342.02	2.27669
2346.8	20.2047
2351.58	14.9451
2356.35	-0.0400238
2361.12	10.958
2365.89	-0.0995941
2370.65	23.3802
2375.41	10.8959
2380.17	26.1036
2384.92	6.49802
2389.67	11.8403
2394.42	7.37694
2399.16	23.7345
2403.9	16.4167
2408.64	4.95306
2413.37	14.6373
2418.1	16.4736
2422.83	12.447
2427.55	9.55173
2432.27	8.21181
2436.99	9.75713
2441.7	12.7348
2446.41	2.91086
2451.11	11.6051
2455.82	0.274658
2460.51	11.8705
2465.21	12.0002
2469.9	3.43114
2474.59	13.6243
2479.28	16.6303
2483.96	23.9822
2488.64	9.42599
2493.32	2.10779
2497.99	9.42006
2502.66	15.2608
2507.32	16.6806
2511.99	10.7016
2516.65	13.5188
2521.3	25.2534
2525.96	4.4948
2530.61	13.2868
2535.25	20.6722
2539.89	10.2815
2544.53	14.758
2549.17	22.2691
2553.8	11.8529
2558.43	8.82825
2563.06	20.8669
2567.68	16.4564
2572.3	6.01266
2576.92	9.11047
2581.53	21.2527
2586.14	7.49675
2590.75	17.9347
2595.35	31.5007
2599.96	25.372
2604.55	29.8497
2609.15	20.5614
2613.74	26.4762
2618.33	21.7088
2622.91	29.1911
2627.49	25.9998
2632.07	16.7901
2636.64	19.9896
2641.22	26.409
2645.78	4.993
2650.35	19.1706
2654.91	28.683
2659.47	44.3034
2664.03	30.1883
2668.58	14.4582
2673.13	27.0509
2677.67	33.7188
2682.22	31.2088
2686.76	31.7706
2691.29	14.6938
2695.83	27.636
2700.36	26.101
2704.89	8.46429
2709.41	18.1105
2713.93	19.7131
2718.45	23.0189
2722.96	35.9972
2727.47	26.2009
2731.98	24.4147
2736.49	20.9798
2740.99	30.5555
2745.49	30.4724
2749.98	40.2754
2754.47	29.1109
2758.96	22.5924
2763.45	20.9019
2767.93	37.4036
2772.41	25.9144
2776.89	19.4568
2781.36	27.9953
2785.84	21.6834
2790.3	23.6563
2794.77	15.5598
2799.23	32.5083
2803.69	17.5117
2808.14	25.9874
2812.59	36.1471
2817.04	5.67731
2821.49	24.2513
2825.93	20.858
2830.37	29.3264
2834.81	20.7705
2839.24	25.8244
2843.67	15.5469
2848.1	17.2643
2852.53	-1.50983
2856.95	19.209
2861.37	15.9385
2865.78	35.1954
2870.19	28.6034
2874.6	30.6506
2879.01	27.5119
2883.41	38.4045
2887.81	16.0322
2892.21	32.2246
2896.6	32.6432
2901	38.4361
2905.38	29.8994
2909.77	15.9142
2914.15	32.1507
2918.53	17.9644
2922.91	10.9478
2927.28	25.5965
2931.65	31.3218
2936.02	18.8451
2940.38	20.7337
2944.74	20.7865
2949.1	22.5704
2953.46	20.73
2957.81	22.5265
2962.16	33.4983
2966.5	29.8765
2970.85	24.4455
2975.19	37.412
2979.52	37.5219
2983.86	32.1653
2988.19	28.7143
2992.52	29.0152
2996.85	38.6525
3001.17	24.121
3005.49	30.171
3009.8	41.8947
3014.12	44.2115
3018.43	46.6531
3022.74	35.7962
3027.04	34.2659
3031.34	47.9245
3035.64	48.1313
3039.94	42.5579
3044.23	60.0364
3048.52	60.1931
3052.81	64.1971
3057.09	58.5944
3061.38	76.1877
3065.65	78.3286
3069.93	76.5895
3074.2	70.9646
3078.47	57.5438
3082.74	85.098
3087	75.6799
3091.27	93.835
3095.52	90.5556
3099.78	71.4779
3104.03	88.0235
3108.28	110.74
3112.53	99.7294
3116.77	108.673
3121.01	99.6097
3125.25	124.942
3129.49	93.6905
3133.72	107.156
3137.95	108.397
3142.18	123.968
3146.4	127.134
3150.62	132.3
3154.84	143.53
3159.06	123.43
3163.27	149.344
3167.48	141.679
3171.69	140.31
3175.89	155.699
3180.09	153.996
3184.29	154.294
3188.49	156.59
3192.68	148.447
3196.87	168.116
3201.06	134.97
3205.24	142.434
3209.42	150.106
3213.6	125.475
3217.78	141.931
3221.95	112.656
3226.12	131.278
3230.29	117.068
3234.45	115.923
3238.61	112.514
3242.77	102.56
3246.93	110.414
3251.08	102.404
3255.23	100.833
3259.38	106.046
3263.53	100.226
3267.67	85.7935
3271.81	73.2039
3275.95	80.6785
3280.08	74.3049
3284.21	86.2508
3288.34	91.3396
3292.47	77.9916
3296.59	80.7108
3300.71	76.5974
3304.83	86.3398
3308.95	79.8784
3313.06	94.2533
3317.17	80.7789
3321.27	74.3257
3325.38	74.968
3329.48	89.7493
3333.58	83.6977
3337.67	84.6903
3341.77	71.2018
3345.86	85.9875
3349.95	76.9546
3354.03	67.906
3358.11	56.5775
3362.19	57.1722
3366.27	62.5244
3370.34	65.5088
3374.42	70.8312
3378.48	49.5659
3382.55	83.7216
3386.61	62.3619
3390.68	65.107
3394.73	72.7209
3398.79	73.1744
3402.84	63.8292
3406.89	20.3811
3410.94	64.4122
3414.98	42.7679
3419.03	67.3948
3423.06	70.0859
3427.1	48.4251
3431.14	51.2389
3435.17	54.1302
3439.2	37.5041
3443.22	62.6044
3447.25	46.1174
3451.27	59.1828
3455.28	57.5752
3459.3	63.541
3463.31	19.75
3467.32	50.6706
3471.33	51.6493
3475.34	75.0947
3479.34	53.3691
3483.34	44.1441
3487.33	60.2155
3491.33	25.4555
3495.32	31.2812
3499.31	49.8468
3503.3	32.537
3507.28	51.0133
3511.26	66.792
3515.24	51.7183
3519.22	46.8965
3523.19	54.9309
3527.16	37.2919
3531.13	45.3722
3535.1	30.5063
3539.06	44.1747
3543.02	44.8658
3546.98	40.2837
3550.93	40.7913
3554.89	38.488
3558.84	49.3609
3562.78	47.3098
3566.73	71.4581
3570.67	27.7943
3574.61	38.9951
3578.55	60.8624
3582.48	32.8442
3586.41	41.7057
3590.35	53.2563
3594.27	62.2069
3598.2	47.1876
3602.12	37.3593
3606.04	24.7704
3609.95	55.0422
3613.87	28.9048
3617.78	18.8025
3621.69	5.8649
3625.6	25.189
3629.5	22.8772
3633.4	15.0963
3637.3	31.7688
3641.2	16.0999
3645.09	22.215
3648.98	11.9181
3652.87	1.51317
3656.76	18.3259
3660.64	29.6976
3664.53	16.487
3668.4	36.1206
3672.28	17.4644
3676.16	18.0561
3680.03	21.4898
3683.9	19.5305
3687.76	1.08325
3691.63	10.222
3695.49	33.213
3699.35	9.06548
3703.2	1.49957
3707.06	7.91699
3710.91	31.1919
3714.76	6.74146
3718.6	30.0084
3722.45	10.9646
3726.29	17.2611
3730.13	15.0726
3733.97	4.39293
3737.8	13.5747
3741.63	5.65144
3745.46	6.24046
3749.29	21.0755
3753.11	27.2971
3756.93	7.69711
3760.75	28.131
3764.57	14.1737
3768.39	20.2951
3772.2	12.1336
3776.01	18.323
3779.81	10.1931
3783.62	10.7505
3787.42	-8.87021
3791.22	29.1801
3795.02	15.3448
3798.81	10.2092
3802.61	-0.73996
3806.4	-8.79778
3810.18	6.44781
3813.97	1.24385
3817.75	7.72299
3821.53	11.2669
3825.31	5.94705
3829.09	0.613083
3832.86	13.0061
3836.63	16.5473
3840.4	14.1369
3844.17	2.88289
3847.93	12.1715
3851.69	15.5028
3855.45	21.7601
3859.21	-1.78783
3862.96	22.2753
3866.71	10.9204
3870.46	-15.2898
3874.21	17.8616
3877.95	21.175
3881.69	3.55861
3885.44	9.89084
3889.17	25.2522
3892.91	22.7001
3896.64	29.2628
3900.37	8.69072
3904.1	9.14011
3907.82	9.57304
3911.55	10.0386
3915.27	4.47224
3918.99	5.01413
3922.7	17.7905
3926.42	3.13663
3930.13	0.60257
3933.84	10.2247
3937.54	25.9586
3941.25	26.448
3944.95	20.8405
3948.65	2.83481
3952.35	9.40184
3956.04	15.9476
3959.73	16.2471
3963.42	13.4073
3967.11	1.21289
3970.8	10.6514
3974.48	23.2155
3978.16	-1.45186
3981.84	23.437
3985.52	17.306
3989.19	23.578
3992.86	8.21045
3996.53	11.5171
3998.37	17.8542