File: Data/3-Raman/processed/bu19w-c-ore1-fi04-v_150 (500nm)_532nm_edge_100%_x100_vis_h50um_15sx2_01_0.txt
#Acq. time (s)=	15
#Accumulations=	2
#Range (cm-¹)=	100...5000
#Windows=	1
#Auto scanning=	Off
#Autofocus=	Off
#Macrospot=	Off
#AutoExposure=	Off
#Spike filter=	Multiple accum.
#Delay time (s)=	2
#Binning=	1
#Readout mode=	Signal
#DeNoise=	Off
#ICS correction=	On
#Dark correction=	Off
#Inst. Process=	Off
#Detector Gain=	Best Dynamic
#Detector ADC=	50 kHz HS
#Detector temperature (°C)=	-60.09
#Instrument=	LabRAM HR Evol
#Detector=	SIN-EM FIVIS
#Objective=	x100_VIS
#Grating=	150 (500nm)
#ND Filter=	100%
#Laser=	532nm_Edge
#Hole=	49.98
#Temperature=	0
#Range=	Visible
#StageXY=	75x50mm Scan+
#StageZ=	Z motor
#X (µm)=	0
#Y (µm)=	0
#Z (µm)=	-4.5
#Full time(s)=	35
#Project=	21_05_14
#Sample=	BU19w
#Site=
#Title=	BU19w-FF-ore1-FI04-V_150 (500nm)_532nm_Edge_100%_x100_VIS_H50um_15sX2
#Remark=
#Date=	14.05.2021 18:39
#Acquired=	14.05.2021 18:39:22
#Base:Fit=	16.12.2021 17:39:50
#Base:Sub=	16.12.2021 18:01:37
102.699	1726.95
107.322	1455.23
111.942	1186.86
116.56	976.068
121.173	862.062
125.787	731.812
130.398	679.124
135.006	542.775
139.613	419.281
144.215	367.232
148.817	561.856
153.417	1262.8
158.014	1435.93
162.607	669.635
167.2	396.289
171.79	405.956
176.379	941.773
180.963	2617.62
185.547	2789.92
190.128	1005.11
194.705	236.672
199.282	85.8755
203.857	47.4061
208.43	46.7624
212.998	65.5955
217.566	-0.0543823
222.132	22.2305
226.693	101.654
231.254	158.742
235.813	133.892
240.368	246.578
244.923	217.547
249.475	166.371
254.023	117.681
258.571	85.9856
263.117	260.872
267.658	731.48
272.199	1784.66
276.738	1937.15
281.273	1006.45
285.807	463.248
290.34	523.409
294.868	1039.27
299.396	1398.72
303.919	899.611
308.443	337.241
312.964	192.262
317.481	256.086
321.998	409.041
326.51	485.261
331.023	295.825
335.533	140.625
340.039	186.724
344.544	211.082
349.046	169.083
353.547	122.87
358.045	47.1924
362.542	108.406
367.036	129.343
371.527	122.664
376.017	196.279
380.503	420.125
384.99	501.403
389.471	533.379
393.953	538.114
398.43	398.364
402.908	250.267
407.381	310.734
411.854	431.76
416.323	299.224
420.791	122.503
425.256	15.1144
429.72	0.290161
434.18	27.6909
438.64	62.3727
443.095	214.394
447.551	687.447
452.003	1132.56
456.454	693.404
460.901	280.44
465.348	92.5175
469.791	97.9634
474.231	90.4058
478.672	152.969
483.108	145.42
487.544	229.342
491.976	237.29
496.408	235.403
500.836	210.977
505.261	187.215
509.687	136.683
514.108	144.054
518.529	110.988
522.946	124.593
527.361	189.109
531.776	256.287
536.187	250.65
540.595	261.189
545.003	234.575
549.408	255.515
553.812	251.646
558.212	295.062
562.61	207.007
567.007	168.144
571.401	137.152
575.792	182.433
580.184	396.818
584.571	767.976
588.956	624.713
593.341	306.379
597.722	223.835
602.101	323.008
606.48	379.047
610.854	301.311
615.227	159.56
619.597	82.6595
623.967	80.6058
628.334	93.2761
632.698	134.437
637.06	210.398
641.422	132.07
645.779	95.5381
650.135	66.7266
654.491	64.1364
658.842	87.2388
663.192	84.2227
667.539	159.14
671.884	214.128
676.23	220.329
680.571	143.347
684.91	75.5953
689.247	59.8611
693.583	21.8009
697.916	21.6697
702.247	8.35797
706.576	-1.28143
710.902	26.5479
715.229	7.90112
719.551	0.604919
723.872	29.0123
728.19	13.7117
732.506	45.3177
736.82	20.5532
741.134	55.0493
745.444	93.7287
749.752	105.16
754.058	186.151
758.362	240.721
762.664	367.55
766.964	719.233
771.264	1174.73
775.559	1381.28
779.853	1016.36
784.144	589.063
788.434	337.093
792.722	231.596
797.007	149.732
801.29	118.237
805.572	133.38
809.851	36.5084
814.13	66.2815
818.406	48.6995
822.679	46.7303
826.95	47.0629
831.219	36.415
835.486	12.4692
839.752	17.1154
844.015	17.1876
848.276	31.0362
852.535	10.6237
856.792	33.2066
861.047	68.8929
865.3	36.0192
869.551	20.6271
873.8	13.8322
878.047	18.9724
882.292	-1.35333
886.534	18.4235
890.775	4.76935
895.014	7.05377
899.251	47.5992
903.486	-0.297852
907.719	4.54333
911.95	2.34235
916.179	18.3406
920.406	12.7418
924.63	38.3863
928.853	22.1112
933.074	34.9463
937.293	45.3316
941.51	72.7025
945.723	93.4103
949.936	102.576
954.147	133.104
958.356	151.968
962.563	221.891
966.768	194.094
970.971	159.165
975.172	96.7997
979.371	100.389
983.568	34.1447
987.761	69.4095
991.954	52.2726
996.145	42.1221
1000.33	52.3211
1004.52	31.8416
1008.71	61.4667
1012.89	70.6403
1017.07	117.129
1021.25	109.255
1025.43	141.456
1029.6	144.862
1033.77	215.696
1037.95	339.8
1042.11	661.74
1046.28	1150.06
1050.45	1385.82
1054.61	1002.75
1058.77	633.742
1062.93	429.33
1067.09	319.471
1071.24	314.623
1075.4	393.468
1079.55	531.489
1083.7	788.747
1087.85	861.835
1091.99	826.798
1096.14	742.464
1100.28	904.579
1104.42	1214.22
1108.55	1266.54
1112.69	1056.95
1116.82	869.611
1120.96	839.541
1125.09	922.098
1129.21	941.479
1133.34	806.768
1137.46	553.029
1141.59	429.587
1145.71	440.498
1149.83	465.171
1153.94	584.086
1158.06	498.573
1162.17	366.053
1166.28	241.626
1170.39	168.466
1174.5	136.39
1178.6	148.577
1182.7	128.828
1186.8	158.764
1190.9	157.572
1195	186.753
1199.1	143.079
1203.19	124.931
1207.28	117.022
1211.37	147.638
1215.46	172.06
1219.54	237.776
1223.63	259.109
1227.71	256.747
1231.79	335.767
1235.87	451.996
1239.95	452.731
1244.02	448.654
1248.09	486.385
1252.16	294.753
1256.23	280.001
1260.3	298.389
1264.36	1354.85
1268.43	3598.24
1272.49	1203.44
1276.55	311.515
1280.6	201.703
1284.66	198.043
1288.71	132.939
1292.76	163.228
1296.81	150.175
1300.86	149.044
1304.91	146.74
1308.95	128.343
1312.99	131.807
1317.03	132.945
1321.07	132.966
1325.11	133.487
1329.14	100.053
1333.18	129.518
1337.21	156.69
1341.24	118.699
1345.26	150.606
1349.29	231.205
1353.31	304.587
1357.33	248.732
1361.35	248.507
1365.37	489.862
1369.39	3477.71
1373.4	5112.87
1377.41	1124.79
1381.43	332.476
1385.43	267.845
1389.44	365.754
1393.45	556.719
1397.45	288.117
1401.45	172.781
1405.45	113.672
1409.45	111.783
1413.44	97.1271
1417.44	64.6669
1421.43	71.6268
1425.42	48.673
1429.41	60.9891
1433.39	59.7075
1437.38	40.5192
1441.36	19.3896
1445.34	14.8762
1449.32	59.6707
1453.3	13.5308
1457.27	31.4358
1461.24	-1.13904
1465.22	11.4205
1469.19	17.163
1473.15	36.6599
1477.12	26.5288
1481.09	17.3553
1485.05	24.7652
1489.01	21.4144
1492.97	25.9453
1496.93	28.5426
1500.88	4.03705
1504.83	32.251
1508.79	22.7086
1512.74	13.181
1516.68	-0.130432
1520.63	2.16541
1524.57	13.2366
1528.52	32.1465
1532.46	25.9202
1536.4	41.9894
1540.33	27.0735
1544.27	0.530212
1548.2	21.4727
1552.14	23.9562
1556.07	16.6241
1559.99	9.19629
1563.92	33.6172
1567.84	55.0362
1571.77	22.3002
1575.69	23.3807
1579.61	7.06543
1583.52	59.1656
1587.44	28.3177
1591.35	26.3808
1595.27	35.9732
1599.18	67.6796
1603.09	38.0329
1606.99	52.6291
1610.9	46.1415
1614.8	34.0203
1618.7	42.0598
1622.6	46.2766
1626.5	67.8879
1630.39	44.6933
1634.29	54.1909
1638.18	27.3383
1642.07	38.0916
1645.96	76.7571
1649.85	39.755
1653.73	41.0784
1657.62	43.2975
1661.5	54.0801
1665.38	63.7599
1669.26	36.7454
1673.13	50.8846
1677.01	32.1245
1680.88	6.27008
1684.75	28.3464
1688.62	41.6342
1692.49	22.1932
1696.35	21.8013
1700.22	39.3747
1704.08	25.2799
1707.94	12.967
1711.8	-4.11072
1715.66	52.7498
1719.51	10.2332
1723.37	20.6451
1727.22	4.56372
1731.07	21.3683
1734.92	16.5711
1738.76	1.39667
1742.61	-4.40021
1746.45	24.5419
1750.29	38.0444
1754.13	28.6913
1757.97	27.7762
1761.81	28.182
1765.64	24.5364
1769.47	4.68677
1773.31	11.9456
1777.14	10.9725
1780.96	13.0325
1784.79	10.5172
1788.61	30.5266
1792.43	6.55658
1796.25	2.21936
1800.07	12.6075
1803.89	25.531
1807.71	29.9703
1811.52	2.21191
1815.33	25.107
1819.14	34.5044
1822.95	36.1896
1826.76	21.6459
1830.56	46.4753
1834.37	40.0197
1838.17	49.4407
1841.97	19.206
1845.77	35.0016
1849.56	24.3629
1853.36	23.7169
1857.15	36.8544
1860.94	43.2416
1864.73	28.2546
1868.52	40.3229
1872.31	42.304
1876.09	20.3823
1879.87	20.8909
1883.66	25.274
1887.43	26.5177
1891.21	19.9611
1894.99	17.9494
1898.76	1.43878
1902.53	33.0527
1906.31	34.4065
1910.08	27.6849
1913.84	31.2796
1917.61	42.6046
1921.37	11.6929
1925.14	35.4744
1928.9	16.7207
1932.66	23.978
1936.41	20.0389
1940.17	35.6926
1943.92	42.2151
1947.68	27.3799
1951.43	4.68329
1955.18	28.5455
1958.92	28.5083
1962.67	22.7651
1966.41	28.1994
1970.16	20.0666
1973.9	34.2848
1977.64	27.7078
1981.37	32.2465
1985.11	34.7553
1988.84	45.5817
1992.57	21.7414
1996.31	29.4285
2000.03	31.4138
2003.76	20.5699
2007.49	24.2289
2011.21	16.7921
2014.93	33.481
2018.65	36.9332
2022.37	62.7404
2026.09	12.0649
2029.81	41.8232
2033.52	30.2807
2037.23	13.0057
2040.94	36.0665
2044.65	39.7778
2048.36	25.3625
2052.07	31.205
2055.77	26.2037
2059.47	27.3814
2063.17	35.2823
2066.87	38.7048
2070.57	48.6246
2074.27	37.347
2077.96	46.4924
2081.65	70.4873
2085.34	30.8654
2089.03	48.6061
2092.72	48.2114
2096.41	50.7797
2100.09	79.8897
2103.77	44.6874
2107.46	20.4991
2111.14	31.5787
2114.81	25.8987
2118.49	40.409
2122.16	26.7292
2125.84	29.7014
2129.51	22.3293
2133.18	32.5274
2136.85	45.3562
2140.51	76.4279
2144.18	30.9213
2147.84	36.0838
2151.5	52.2476
2155.16	60.166
2158.82	53.4869
2162.48	49.7206
2166.13	47.9227
2169.79	81.9108
2173.44	24.2475
2177.09	67.7318
2180.74	47.577
2184.38	51.093
2188.03	43.1904
2191.67	88.3638
2195.32	37.3824
2198.96	35.6178
2202.6	68.6545
2206.23	49.833
2209.87	47.5685
2213.5	77.4521
2217.14	53.2914
2220.77	26.3339
2224.4	34.2854
2228.03	65.2571
2231.65	32.6882
2235.28	48.1409
2238.9	19.1191
2242.52	42.8932
2246.14	53.7178
2249.76	47.9126
2253.38	28.1836
2256.99	44.8521
2260.6	54.0104
2264.21	29.4225
2267.82	34.0569
2271.44	19.8817
2275.04	25.1158
2278.65	61.1787
2282.25	16.6235
2285.85	36.4368
2289.45	55.1836
2293.05	32.2935
2296.65	37.8333
2300.25	43.3187
2303.84	56.1938
2307.43	71.7777
2311.02	124.218
2314.62	414.403
2318.2	151.821
2321.79	63.3309
2325.38	33.2608
2328.96	69.4182
2332.54	65.6921
2336.12	43.9935
2339.7	73.0344
2343.28	57.7656
2346.85	39.6444
2350.43	39.3274
2354	54.8373
2357.57	49.7335
2361.14	67.8657
2364.71	39.5504
2368.27	43.9102
2371.84	65.0027
2375.4	66.5464
2378.96	49.76
2382.52	30.3624
2386.08	26.7542
2389.64	46.2714
2393.19	64.125
2396.75	19
2400.3	40.2519
2403.85	60.8998
2407.4	11.1133
2410.95	20.335
2414.49	17.775
2418.04	23.6659
2421.58	36.1616
2425.12	40.6138
2428.66	23.08
2432.2	33.4278
2435.74	36.528
2439.27	13.6427
2442.81	9.3454
2446.34	67.762
2449.87	55.4131
2453.4	33.3656
2456.93	39.6824
2460.45	23.9633
2463.98	34.3212
2467.5	54.0338
2471.02	29.2228
2474.54	62.7846
2478.06	43.8185
2481.58	19.072
2485.09	42.8507
2488.61	44.0076
2492.12	57.4606
2495.63	40.6664
2499.14	44.6439
2502.65	41.7527
2506.15	50.8878
2509.66	31.9916
2513.16	46.7899
2516.66	45.0167
2520.16	28.0425
2523.66	31.9047
2527.16	44.4731
2530.66	46.0496
2534.15	34.0226
2537.64	57.2261
2541.13	61.4005
2544.62	40.1682
2548.11	72.5792
2551.6	50.6008
2555.08	-0.593933
2558.57	38.9708
2562.05	41.8099
2565.53	50.5271
2569.01	57.6536
2572.49	36.8895
2575.96	48.1102
2579.44	51.9352
2582.91	55.8141
2586.38	49.1771
2589.85	60.1236
2593.32	46.0626
2596.79	20.7147
2600.25	21.1359
2603.72	28.8685
2607.18	41.7988
2610.64	51.0085
2614.1	40.4081
2617.56	43.9193
2621.02	50.1509
2624.47	27.3214
2627.92	41.829
2631.38	47.5165
2634.83	28.958
2638.28	57.231
2641.72	22.101
2645.17	78.737
2648.61	49.2043
2652.06	28.1316
2655.5	66.7938
2658.94	45.4831
2662.38	55.3685
2665.82	29.3627
2669.25	49.4998
2672.69	54.6397
2676.12	62.6773
2679.55	59.6311
2682.98	39.9955
2686.41	24.6401
2689.84	37.7616
2693.26	50.6376
2696.69	29.2211
2700.11	69.3612
2703.53	31.1552
2706.95	27.0696
2710.37	57.6171
2713.79	34.3638
2717.2	45.7144
2720.62	40.4266
2724.03	19.3156
2727.44	49.6516
2730.85	61.2908
2734.26	32.6656
2737.66	42.4365
2741.07	39.8822
2744.47	70.0366
2747.87	31.6182
2751.28	35.4614
2754.67	50.4346
2758.07	33.5143
2761.47	34.2481
2764.86	24.5075
2768.26	24.9666
2771.65	66.8435
2775.04	49.2198
2778.43	40.8965
2781.82	63.5682
2785.2	56.0776
2788.59	51.407
2791.97	51.3677
2795.35	50.4721
2798.73	40.0142
2802.11	39.8931
2805.49	37.8968
2808.87	35.8578
2812.24	57.1724
2815.62	44.7373
2818.99	47.3718
2822.36	47.3412
2825.73	5.40814
2829.1	40.9477
2832.46	42.1423
2835.83	30.4245
2839.19	33.7599
2842.55	41.9155
2845.91	36.3292
2849.27	70.2949
2852.63	60.2415
2855.99	51.1954
2859.34	51.6205
2862.69	47.3905
2866.05	47.8824
2869.4	50.1896
2872.75	51.5352
2876.09	63.2081
2879.44	45.6938
2882.78	54.4822
2886.13	36.8014
2889.47	49.3731
2892.81	16.361
2896.15	21.0378
2899.49	64.3862
2902.82	50.8666
2906.16	32.5563
2909.49	76.6133
2912.82	55.3759
2916.16	54.8096
2919.49	85.399
2922.81	73.4009
2926.14	55.5836
2929.46	63.2519
2932.79	48.076
2936.11	44.242
2939.43	63.032
2942.75	85.5693
2946.07	62.0235
2949.39	45.0698
2952.7	40.3263
2956.02	78.9059
2959.33	78.1583
2962.64	52.9987
2965.95	55.2327
2969.26	66.2219
2972.57	34.8639
2975.87	70.4103
2979.17	70.1454
2982.48	72.7389
2985.78	85.7227
2989.08	91.2251
2992.38	72.3405
2995.68	75.1157
2998.97	76.0266
3002.27	115.461
3005.56	74.0793
3008.85	83.5414
3012.14	80.808
3015.43	88.4183
3018.72	73.3853
3022	68.711
3025.29	90.488
3028.57	67.8858
3031.85	84.9218
3035.14	96.2595
3038.41	107.617
3041.69	85.8635
3044.97	96.3177
3048.24	107.698
3051.52	108.71
3054.79	120.135
3058.06	116.293
3061.33	127.43
3064.6	111.127
3067.87	105.146
3071.13	134.579
3074.4	101.843
3077.66	144.97
3080.92	99.4233
3084.18	154.584
3087.44	132.099
3090.7	138.28
3093.95	162.641
3097.21	145.285
3100.46	155.507
3103.71	138.415
3106.96	177.503
3110.21	164.004
3113.46	176.185
3116.71	155.083
3119.95	173.983
3123.2	213.841
3126.44	196.519
3129.68	184.914
3132.92	188.544
3136.16	210.244
3139.4	201.42
3142.63	206.893
3145.87	233.391
3149.1	281.871
3152.33	261.657
3155.56	261.487
3158.79	252.71
3162.02	271.607
3165.25	263.723
3168.47	274.849
3171.69	284.978
3174.92	314.113
3178.14	338.434
3181.36	307.453
3184.58	340.289
3187.79	340.643
3191.01	327.648
3194.22	348.95
3197.43	334.973
3200.65	325.795
3203.86	355.685
3207.07	356.104
3210.27	362.296
3213.48	363.811
3216.69	373.905
3219.89	355.482
3223.09	394.231
3226.29	384.503
3229.49	429.096
3232.69	380.375
3235.89	424.137
3239.08	406.144
3242.28	416.777
3245.47	418.847
3248.66	433.403
3251.85	407.01
3255.04	411.139
3258.23	446.658
3261.42	428.561
3264.6	453.284
3267.79	435.853
3270.97	455.59
3274.15	454.313
3277.33	449.04
3280.51	501.758
3283.68	458.054
3286.86	478.191
3290.04	484.082
3293.21	509.013
3296.38	494.827
3299.55	499.991
3302.72	537.31
3305.89	482.187
3309.06	538.166
3312.22	529.376
3315.39	535.752
3318.55	557.24
3321.71	542.696
3324.87	555.634
3328.03	518.446
3331.19	573.995
3334.34	577.626
3337.5	573.816
3340.65	603.023
3343.81	588.131
3346.96	603.775
3350.11	596.816
3353.25	619.203
3356.4	646.368
3359.55	634.105
3362.69	680.347
3365.84	665.375
3368.98	674.962
3372.12	677.159
3375.26	684.149
3378.4	693.131
3381.53	669.909
3384.67	716.747
3387.8	773.127
3390.94	760.523
3394.07	753.033
3397.2	838.159
3400.33	900.911
3403.46	1019.96
3406.58	1201.16
3409.71	1638.81
3412.83	2619.7
3415.96	5220.42
3419.08	7151.17
3422.2	5001.89
3425.32	2495.53
3428.44	1522.88
3431.55	1135.01
3434.67	924.268
3437.78	919.902
3440.89	761.992
3444	770.786
3447.12	727.106
3450.22	739.472
3453.33	695.62
3456.44	740.136
3459.54	717.02
3462.65	712.895
3465.75	715.311
3468.85	689.809
3471.95	688.43
3475.05	663.512
3478.15	657.621
3481.24	734.944
3484.34	714.002
3487.43	720.58
3490.53	771.002
3493.62	824.279
3496.71	888.686
3499.79	973.932
3502.88	919.284
3505.97	895.891
3509.05	778.815
3512.14	686.228
3515.22	635.313
3518.3	595.112
3521.38	557.011
3524.46	511.84
3527.54	498.045
3530.61	513.361
3533.69	455.376
3536.76	437.805
3539.83	447.395
3542.9	407.414
3545.97	404.211
3549.04	381.006
3552.11	383.115
3555.18	399.574
3558.24	360.3
3561.3	352.969
3564.37	360.714
3567.43	323.954
3570.49	331.582
3573.55	325.829
3576.61	336.16
3579.66	295.199
3582.72	300.631
3585.77	264.31
3588.82	259.209
3591.87	280.607
3594.92	252.654
3597.97	284.377
3601.02	237.423
3604.07	256.685
3607.11	230.505
3610.16	264.818
3613.2	238.592
3616.24	207.695
3619.28	210.839
3622.32	188.546
3625.36	186.115
3628.39	178.961
3631.43	174.587
3634.46	160.929
3637.5	154.934
3640.53	180.068
3643.56	147.993
3646.59	133.68
3649.62	142.042
3652.64	125.177
3655.67	106.427
3658.69	97.4589
3661.72	103.456
3664.74	114.823
3667.76	73.4355
3670.78	79.2353
3673.79	94.5135
3676.81	94.7427
3679.83	49.5959
3682.84	66.791
3685.86	49.9637
3688.87	53.9591
3691.88	43.769
3694.89	64.7399
3697.9	56.4058
3700.91	50.9437
3703.91	48.3218
3706.92	62.7447
3709.92	47.6572
3712.92	35.3309
3715.92	41.0917
3718.92	10.6412
3721.92	51.5256
3724.92	66.66
3727.92	19.8516
3730.91	58.6956
3733.91	40.3356
3736.9	46.6793
3739.89	45.3372
3742.88	31.5754
3745.87	48.1956
3748.86	34.3393
3751.85	45.1694
3754.83	38.9166
3757.82	27.9246
3760.8	47.2303
3763.78	65.5569
3766.76	40.3602
3769.74	16.1929
3772.72	57.3319
3775.7	17.1966
3778.67	51.7632
3781.65	54.21
3784.62	48.1859
3787.6	36.5308
3790.57	25.9037
3793.54	34.2128
3796.51	37.8354
3799.47	39.6406
3802.44	21.6566
3805.41	23.5166
3808.37	1.78363
3811.33	28.2666
3814.3	30.1921
3817.26	42.5499
3820.22	20.8497
3823.18	46.5239
3826.13	31.4879
3829.09	43.9265
3832.04	13.7189
3835	22.4403
3837.95	26.4289
3840.9	52.2899
3843.85	24.8976
3846.8	6.05328
3849.75	37.7301
3852.69	25.5881
3855.64	15.3395
3858.58	45.2246
3861.53	27.3008
3864.47	19.874
3867.41	35.3908
3870.35	17.3465
3873.29	49.1531
3876.22	19.4971
3879.16	13.7656
3882.1	19.4943
3885.03	18.4488
3887.96	21.2212
3890.89	20.1274
3893.82	55.5193
3896.75	56.2159
3899.68	30.9348
3902.61	13.2729
3905.53	16.8152
3908.46	30.9019
3911.38	34.3644
3914.3	47.3625
3917.23	38.3687
3920.15	56.1883
3923.06	6.75238
3925.98	34.0351
3928.9	20.0204
3931.81	36.7698
3934.73	22.9731
3937.64	24.6255
3940.55	23.3733
3943.46	25.0009
3946.37	14.2299
3949.28	28.3969
3952.19	32.0519
3955.09	30.0064
3958	49.0674
3960.9	45.1601
3963.8	21.1432
3966.71	33.5849
3969.61	21.1054
3972.51	34.534
3975.4	43.1421
3978.3	45.9482
3981.2	26.6351
3984.09	17.858
3986.99	38.889
3989.88	51.1786
3992.77	17.3804
3995.66	46.1217
3998.55	36.3953
4001.43	28.5936
4004.32	11.1775
4007.21	40.0205
4010.09	50.5582
4012.98	25.4175
4015.86	47.5388
4018.74	26.2333
4021.62	40.6402
4024.5	44.442
4027.37	26.0163
4030.25	9.52191
4033.13	32.6761
4036	30.7098
4038.87	20.0313
4041.75	19.9167
4044.62	13.0093
4047.49	33.2722
4050.35	13.8101
4053.22	22.5083
4056.09	19.5764
4058.95	19.5252
4061.82	17.5247
4064.68	24.273
4067.54	59.2338
4070.4	36.793
4073.26	15.2974
4076.12	21.0499
4078.98	33.6272
4081.83	10.1372
4084.69	24.6583
4087.54	30.3917
4090.4	22.4837
4093.25	25.3085
4096.1	25.1911
4098.95	11.4034
4101.8	18.1175
4104.64	41.4259
4107.49	-4.7518
4110.33	22.4284
4113.18	30.958
4116.02	33.5577
4118.86	17.5322
4121.7	16.2317
4124.54	13.9858
4127.38	12.7878
4130.22	39.1175
4133.05	18.5418
4135.89	31.9955
4138.72	21.3491
4141.56	19.7207
4144.39	23.4504
4147.22	25.2593
4150.05	26.0448
4152.88	40.3788
4155.7	42.7637
4158.53	15.804
4161.36	23.2423
4164.18	32.6359
4167	21.4967
4169.82	36.7914
4172.65	11.03
4175.46	25.3677
4178.28	33.8588
4181.1	20.8636
4183.92	14.7301
4186.73	18.3981
4189.55	12.3236
4192.36	19.0364
4195.17	37.5665
4197.98	29.6707
4200.79	60.994
4203.6	48.1921
4206.41	52.0602
4209.21	38.243
4212.02	36.193
4214.83	25.4434
4217.63	23.6616
4220.43	32.652
4223.23	16.9333
4226.03	19.9721
4228.83	23.0715
4231.63	49.9727
4234.42	33.36
4237.22	16.7169
4240.01	14.9498
4242.81	21.1602
4245.6	25.3887
4248.39	13.6161
4251.18	41.7562
4253.97	22.9149
4256.76	37.0531
4259.55	21.1574
4262.33	10.262
4265.12	16.4472
4267.9	22.6559
4270.68	20.804
4273.47	42.0853
4276.25	17.8962
4279.03	26.9635
4281.8	15.7843
4284.58	25.7799
4287.36	15.4907
4290.13	34.5247
4292.91	35.3718
4295.68	2.82373
4298.45	5.7207
4301.22	29.9049
4303.99	30.7632
4306.76	36.7119
4309.53	15.2606
4312.3	27.3202
4315.06	26.1017
4317.83	9.58447
4320.59	16.4388
4323.35	20.2138
4326.11	22.9729
4328.87	20.6207
4331.63	27.4273
4334.39	12.8297
4337.15	9.46185
4339.9	8.17465
4342.66	17.1027
4345.41	18.9418
4348.17	39.1699
4350.92	6.38242
4353.67	34.897
4356.42	10.2374
4359.17	21.352
4361.91	22.2518
4364.66	1.63687
4367.41	35.3356
4370.15	20.8393
4372.89	13.4647
4375.63	15.3051
4378.38	16.0964
4381.12	17.93
4383.86	3.38397
4386.59	6.44379
4389.33	6.52451
4392.07	13.0028
4394.8	28.7678
4397.53	22.658
4400.27	23.7775
4403	25.9263
4405.73	26.027
4408.46	-3.00986
4411.19	7.38397
4413.92	3.17883
4416.64	25.9663
4419.37	20.5901
4422.09	21.5325
4424.82	23.5257
4427.54	11.9327
4430.26	5.54675
4432.98	22.1673
4435.7	4.21973
4438.42	17.6632
4441.13	11.1855
4443.85	2.59445
4446.57	14.9771
4449.28	13.6994
4451.99	12.401
4454.71	17.3849
4457.42	21.293
4460.13	16.8187
4462.83	12.359
4465.54	4.74631
4468.25	15.0461
4470.95	5.37
4473.66	6.2583
4476.36	25.1084
4479.07	18.6812
4481.77	21.7579
4484.47	3.67645
4487.17	19.4106
4489.87	23.4562
4492.56	27.3564
4495.26	-0.403809
4497.96	2.53998
4500.65	41.4485
4503.34	1.98486
4506.04	26.1393
4508.73	11.0585
4511.42	34.1819
4514.11	8.4949
4516.8	11.4672
4519.48	8.11908
4522.17	11.1569
4524.85	13.1158
4527.54	30.0045
4530.22	3.22189
4532.9	42.5467
4535.58	17.888
4538.27	-0.354248
4540.94	2.73672
4543.62	-1.63715
4546.3	1.47687
4548.98	23.8962
4551.65	4.60782
4554.33	16.4388
4557	17.6751
4559.67	-6.88068
4562.34	16.0353
4565.01	13.2869
4567.68	-4.77393
4570.35	3.8364
4573.02	2.35135
4575.68	1.07425
4578.35	10.7584
4581.01	1.12637
4583.67	0.981049
4586.34	31.3528
4589	9.35239
4591.66	1.49445
4594.31	15.5851
4596.97	17.5733
4599.63	8.71045
4602.29	10.8179
4604.94	1.9679
4607.59	20.5367
4610.25	2.89709
4612.9	15.9805
4615.55	1.60208
4618.2	14.7495
4620.85	21.3037
4623.5	4.68027
4626.14	8.97202
4628.79	17.6991
4631.43	5.37714
4634.08	-0.363556
4636.72	18.2465
4639.36	24.6655
4642	10.1119
4644.64	12.2657
4647.28	14.5003
4649.92	17.9501
4652.56	9.3237
4655.19	11.0931
4657.83	23.2353
4660.46	14.2708
4663.1	29.8845
4665.73	12.9318
4668.36	11.6752
4670.99	-1.91785
4673.62	20.3423
4676.24	6.72485
4678.87	-2.43466
4681.5	9.74026
4684.12	17.4379
4686.75	9.38373
4689.37	13.7315
4691.99	15.7925
4694.61	21.227
4697.23	9.74762
4699.85	7.29105
4702.47	13.8281
4705.09	9.05966
4707.7	39.3338
4710.32	11.9153
4712.93	11.638
4715.55	18.125
4718.16	26.8932
4720.77	10.6774
4723.38	1.30408
4725.99	16.9061
4728.6	26.8492
4731.21	6.14325
4733.81	34.2678
4736.42	14.6414
4739.02	6.37527
4741.63	15.1199
4744.23	15.9103
4746.83	22.3117
4749.43	31.003
4752.03	15.7943
4754.63	16.4986
4757.23	27.4734
4759.82	-2.50485
4762.42	18.7532
4765.01	16.1495
4767.61	13.6371
4770.2	24.7061
4772.79	15.2438
4775.38	20.6212
4777.97	13.4276
4780.56	32.5097
4783.15	34.4629
4785.74	10.1051
4788.32	5.18201
4790.91	10.5763
4793.49	9.09619
4796.07	13.3787
4798.66	19.978
4801.24	27.7519
4803.82	14.8843
4806.4	8.93427
4808.98	25.9818
4811.55	17.7201
4814.13	15.2159
4816.71	24.2952
4819.28	18.3444
4821.85	11.222
4824.43	20.3168
4827	13.149
4829.57	14.1472
4832.14	9.31445
4834.71	2.16873
4837.28	19.5525
4839.84	14.7713
4842.41	11.0785
4844.97	20.2423
4847.54	19.9875
4850.1	14.8344
4852.66	28.3032
4855.22	3.39862
4857.78	10.2405
4860.34	21.7581
4862.9	29.6265
4865.46	23.257
4868.01	14.6465
4870.57	21.3352
4873.12	7.8205
4875.68	4.95978
4878.23	22.2538
4880.78	12.2194
4883.33	27.1169
4885.88	8.73114
4888.43	37.9217
4890.98	14.7362
4893.53	15.3361
4896.07	8.76147
4898.62	21.2515
4901.16	20.6052
4903.7	21.1587
4906.25	13.3004
4908.79	20.9303
4911.33	23.7321
4913.87	27.6969
4916.41	18.5195
4918.94	26.0717
4921.48	9.71762
4924.02	18.4583
4926.55	9.24936
4929.08	10.8134
4931.62	1.6701
4934.15	2.07813
4936.68	16.8203
4939.21	3.94946
4941.74	30.582
4944.27	3.40146
4946.79	10.9423
4949.32	23.2816
4951.85	11.6196
4954.37	5.94788
4956.9	-5.71077
4959.42	27.0861
4961.94	2.24583
4964.46	13.5284
4966.98	22.3801
4969.5	22.741
4972.02	9.79768
4974.53	4.06256
4977.05	7.98683
4979.57	14.3324
4982.08	12.1959
4984.59	22.1797
4987.1	18.8141
4989.62	-0.382187
4992.13	22.9446
4994.64	15.8777
4997.15	10.0277
4999.65	10.2548