File: Data/3-Raman/processed/bu19w-e-ff11b-fi09-v_150 (500nm)_532nm_edge_100%_x100_vis_h50um_30sx2_01_0.txt
#Acq. time (s)=	30
#Accumulations=	2
#Range (cm-¹)=	100...5000
#Windows=	1
#Auto scanning=	Off
#Autofocus=	Off
#Macrospot=	Off
#AutoExposure=	Off
#Spike filter=	Multiple accum.
#Delay time (s)=	2
#Binning=	1
#Readout mode=	Signal
#DeNoise=	Off
#ICS correction=	On
#Dark correction=	Off
#Inst. Process=	Off
#Detector Gain=	Best Dynamic
#Detector ADC=	50 kHz HS
#Detector temperature (°C)=	-60.09
#Instrument=	LabRAM HR Evol
#Detector=	SIN-EM FIVIS
#Objective=	x100_VIS
#Grating=	150 (500nm)
#ND Filter=	100%
#Laser=	532nm_Edge
#Hole=	49.98
#Temperature=	0
#Range=	Visible
#StageXY=	75x50mm Scan+
#StageZ=	Z motor
#X (µm)=	0
#Y (µm)=	0
#Z (µm)=	-293.2
#Full time(mm:ss)=	1:04
#Project=	21_11_04
#Sample=	BU19w
#Site=
#Title=	BU19w-E-FF11b-FI09-V_150 (500nm)_532nm_Edge_100%_x100_VIS_H50um_30sX2
#Remark=
#Date=	04.11.2021 17:29
#Acquired=	04.11.2021 17:29:00
#Base:Fit=	16.12.2021 17:39:50
#Base:Sub=	16.12.2021 17:48:19
101.869	2269.68
106.493	2572.04
111.113	4051.79
115.732	5532.88
120.349	4082.9
124.964	2233.28
129.577	1535.49
134.185	1343.78
138.793	1149.25
143.399	999.899
148.003	896.526
152.602	922.48
157.201	941.48
161.798	1064.99
166.392	1317.24
170.982	1689.51
175.572	2261.43
180.16	3319.3
184.745	4730.93
189.326	6152.58
193.907	6950.74
198.486	6479.37
203.06	5203.07
207.634	3652.63
212.206	2549.03
216.776	1870.11
221.341	1402.97
225.906	1036.15
230.469	853.883
235.028	732.844
239.586	673.003
244.142	666.82
248.694	966.668
253.246	1156.33
257.795	765.337
262.341	344.777
266.886	200.805
271.428	132.419
275.967	83.6708
280.505	63.0421
285.041	64.5297
289.573	62.7743
294.105	24.9572
298.632	26.0562
303.159	27.2596
307.685	10.1205
312.205	8.1976
316.726	0.0193787
321.242	4.64008
325.758	14.536
330.272	29.7628
334.782	166.991
339.292	693.277
343.797	1036.93
348.302	593.744
352.803	200.457
357.304	75.7024
361.802	25.7426
366.297	42.8874
370.791	30.5178
375.281	71.5446
379.77	158.641
384.256	331.43
388.741	474.046
393.223	444.959
397.704	186.701
402.18	88.5146
406.657	91.6466
411.13	128.524
415.602	135.717
420.07	208.201
424.538	275.082
429.002	493.518
433.465	936.772
437.925	1853.43
442.384	4188.64
446.839	10433.6
451.294	19758.6
455.745	18820.6
460.196	10390.5
464.642	4767.65
469.089	2639.86
473.531	1738.17
477.971	1248.41
482.411	900.836
486.846	690.583
491.282	585.381
495.713	559.661
500.144	547.726
504.572	471.067
508.997	357.272
513.421	311.723
517.842	252.353
522.263	257.893
526.679	201.207
531.093	163.082
535.507	137.766
539.917	128.651
544.327	100.956
548.733	103.393
553.137	80.2513
557.54	94.0048
561.94	60.4412
566.337	53.7655
570.734	63.9718
575.127	55.829
579.518	63.1426
583.909	75.5879
588.295	64.4219
592.68	32.6503
597.064	36.9131
601.445	35.4659
605.823	26.8328
610.201	36.0609
614.575	35.6167
618.947	24.8233
623.317	34.2564
627.686	39.175
632.052	40.3092
636.415	22.9328
640.777	29.7169
645.138	-0.177246
649.495	14.3735
653.85	24.1704
658.205	21.8221
662.556	32.1886
666.905	10.6284
671.252	43.3998
675.597	53.3042
679.941	167.66
684.282	215.097
688.62	192.916
692.957	120.244
697.293	74.5159
701.625	43.0686
705.955	55.7061
710.283	20.5992
714.609	37.9895
718.933	30.4075
723.257	29.2702
727.577	30.0722
731.894	60.3224
736.21	43.5292
740.524	40.7604
744.835	62.257
749.147	54.2691
753.454	36.8149
757.759	64.6018
762.063	90.0296
766.364	80.2738
770.663	105.928
774.96	144.076
779.257	219.035
783.55	308.174
787.841	365.447
792.13	496.784
796.417	643.703
800.702	523.246
804.985	325.572
809.266	197.529
813.545	142.137
817.821	137.403
822.096	121.638
826.371	131.297
830.641	106.856
834.91	118.759
839.176	100.862
843.441	100.551
847.703	86.8626
851.964	98.2934
856.222	105.298
860.479	99.0622
864.733	77.3504
868.986	96.2384
873.236	98.5196
877.485	101.783
881.731	78.6744
885.975	82.8102
890.218	84.5391
894.458	81.7047
898.696	115.236
902.933	91.1584
907.167	99.1089
911.399	107.562
915.63	80.5797
919.858	74.0911
924.084	66.446
928.308	52.0979
932.531	64.0222
936.749	64.0892
940.967	62.9763
945.184	45.7814
949.398	41.4248
953.61	48.8953
957.821	45.7322
962.029	25.606
966.236	18.3003
970.44	35.443
974.642	28.2366
978.843	0.938934
983.041	30.9165
987.236	24.8694
991.43	2.95755
995.623	5.58975
999.813	10.5291
1004	1.74533
1008.19	4.65869
1012.37	23.5547
1016.55	-2.32706
1020.73	20.7757
1024.91	12.9149
1029.09	23.0751
1033.27	11.8019
1037.44	33.3312
1041.61	25.8194
1045.78	54.5113
1049.94	87.2433
1054.11	128.248
1058.27	145.679
1062.43	181.891
1066.59	301.905
1070.75	416.938
1074.9	330.459
1079.05	144.495
1083.2	80.0766
1087.35	66.838
1091.5	47.5674
1095.65	36.7446
1099.79	18.919
1103.93	12.4677
1108.07	32.6993
1112.21	19.3684
1116.34	4.05737
1120.48	17.6691
1124.61	26.5047
1128.74	24.2196
1132.86	34.312
1136.99	67.9441
1141.11	144.777
1145.23	238.419
1149.35	325.017
1153.47	259.857
1157.59	137.62
1161.7	65.784
1165.82	34.0728
1169.92	15.7149
1174.03	13.7729
1178.14	3.53827
1182.24	4.63
1186.35	10.7905
1190.45	5.48158
1194.55	8.30367
1198.64	10.0042
1202.74	16.7135
1206.83	11.1707
1210.92	41.1189
1215.01	58.798
1219.1	64.3174
1223.18	111.067
1227.27	81.4522
1231.35	91.1245
1235.43	82.0087
1239.5	73.1474
1243.58	100.161
1247.65	178.171
1251.72	274.387
1255.8	245.927
1259.86	157.553
1263.93	234.154
1267.99	1006.78
1272.06	2238.27
1276.12	1536.95
1280.18	470.374
1284.23	147.567
1288.29	117.944
1292.34	116.432
1296.39	92.6943
1300.44	94.0978
1304.49	89.3885
1308.53	68.5175
1312.58	65.7606
1316.62	85.0595
1320.66	65.9907
1324.7	79.0454
1328.73	69.8904
1332.77	106.919
1336.8	70.5549
1340.83	87.2815
1344.86	100.915
1348.88	122.463
1352.91	118.066
1356.93	182.244
1360.95	212.449
1364.97	200.044
1368.99	459.571
1373.01	2390.7
1377.02	3669.86
1381.03	1924.75
1385.04	486.375
1389.05	220.65
1393.06	275.007
1397.06	425.113
1401.06	303.454
1405.06	159.995
1409.06	83.5061
1413.06	68.1217
1417.05	69.5017
1421.05	67.9147
1425.04	54.4377
1429.03	48.716
1433.01	49.9053
1437	44.1933
1440.99	23.6649
1444.97	16.9298
1448.95	39.7782
1452.93	16.2079
1456.9	18.2605
1460.88	10.4167
1464.85	19.2382
1468.82	16.2184
1472.79	-0.511505
1476.76	15.1434
1480.73	4.26756
1484.69	6.12386
1488.65	15.7746
1492.61	12.726
1496.57	7.7438
1500.53	17.399
1504.48	13.4599
1508.43	16.3972
1512.39	20.3263
1516.33	14.5532
1520.28	-0.890594
1524.23	18.6119
1528.17	-0.666306
1532.11	21.7778
1536.05	19.0215
1539.99	5.61081
1543.93	17.3985
1547.86	22.4003
1551.8	32.2435
1555.73	26.5563
1559.66	20.8309
1563.58	11.2093
1567.51	46.0581
1571.44	27.6857
1575.36	26.7153
1579.28	25.7354
1583.2	41.1408
1587.11	33.3776
1591.03	38.1317
1594.94	28.4451
1598.85	41.8365
1602.76	24.4997
1606.67	14.9017
1610.58	36.9693
1614.48	34.1081
1618.38	34.1586
1622.29	38.0276
1626.18	46.7124
1630.08	29.5912
1633.98	39.3482
1637.87	41.4467
1641.76	25.4083
1645.65	26.6597
1649.54	21.2259
1653.43	26.3501
1657.31	33.3807
1661.2	37.5232
1665.08	35.8547
1668.96	23.5754
1672.83	32.3674
1676.71	16.1395
1680.58	10.3708
1684.46	16.0551
1688.33	22.6647
1692.2	20.5893
1696.06	2.21658
1699.93	25.8848
1703.79	7.46544
1707.66	30.9391
1711.52	21.9701
1715.37	15.8777
1719.23	12.6579
1723.08	27.3912
1726.94	10.0162
1730.79	17.1133
1734.64	17.6271
1738.49	25.6003
1742.33	29.7681
1746.18	9.71417
1750.02	40.0695
1753.86	17.5237
1757.7	14.6358
1761.54	2.84268
1765.37	15.0658
1769.21	20.8466
1773.04	0.729568
1776.87	17.8127
1780.7	7.04967
1784.53	20.5667
1788.35	25.7377
1792.17	10.3325
1796	8.01262
1799.82	21.6502
1803.64	15.4199
1807.45	8.19775
1811.27	28.2732
1815.08	22.8644
1818.89	18.2888
1822.7	24.9641
1826.51	15.5518
1830.32	17.395
1834.12	17.2859
1837.92	31.2542
1841.72	15.0601
1845.52	15.753
1849.32	24.9076
1853.12	18.0109
1856.91	25.0893
1860.7	21.7999
1864.5	28.7279
1868.28	33.7881
1872.07	30.5136
1875.86	33.7749
1879.64	18.5818
1883.42	22.8901
1887.21	23.5227
1890.98	29.0133
1894.76	6.01001
1898.54	20.7313
1902.31	17.1447
1906.08	21.894
1909.85	17.4599
1913.62	20.478
1917.39	21.6784
1921.16	23.9499
1924.92	30.8956
1928.68	23.9876
1932.44	21.7248
1936.2	12.9251
1939.96	11.5476
1943.71	11.0921
1947.47	24.6998
1951.22	22.1969
1954.97	28.9794
1958.72	27.1848
1962.46	23.4168
1966.21	27.1454
1969.95	36.4332
1973.7	27.7844
1977.43	33.1531
1981.17	33.7836
1984.91	13.8097
1988.65	18.1204
1992.38	27.97
1996.11	16.3461
1999.84	14.9283
2003.57	41.2962
2007.3	27.8052
2011.02	29.0547
2014.75	29.382
2018.47	19.7198
2022.19	38.6434
2025.91	21.9517
2029.62	25.4586
2033.34	16.2329
2037.05	21.7683
2040.76	19.0321
2044.47	24.5225
2048.18	22.6839
2051.89	27.3045
2055.59	9.95901
2059.3	24.7858
2063	22.3655
2066.7	15.4036
2070.4	22.2567
2074.1	18.9854
2077.79	18.4907
2081.49	31.9086
2085.18	14.7203
2088.87	23.2388
2092.56	21.3883
2096.25	18.7259
2099.93	19.7551
2103.61	23.4831
2107.3	26.2377
2110.98	29.8806
2114.66	25.1433
2118.33	29.6742
2122.01	22.0308
2125.68	21.7595
2129.36	27.0136
2133.03	24.8216
2136.7	24.4685
2140.36	31.4589
2144.03	17.1911
2147.7	28.71
2151.36	31.0005
2155.02	-0.631439
2158.68	39.2456
2162.34	16.8778
2165.99	25.6449
2169.65	31.6975
2173.3	21.4411
2176.95	27.6506
2180.6	28.4242
2184.25	19.1863
2187.9	22.7393
2191.54	17.2959
2195.18	22.8677
2198.83	23.9552
2202.47	23.2479
2206.11	24.4036
2209.74	15.5491
2213.38	26.8447
2217.01	25.3536
2220.64	20.1905
2224.27	5.82687
2227.9	14.4334
2231.53	12.9199
2235.16	21.5877
2238.78	17.3213
2242.4	12.1067
2246.02	28.2213
2249.64	24.8675
2253.26	14.0783
2256.88	15.4049
2260.49	22.3424
2264.11	17.1021
2267.72	43.7555
2271.33	28.2749
2274.93	15.5054
2278.54	27.137
2282.15	-1.93835
2285.75	28.4122
2289.35	22.9017
2292.95	19.2388
2296.55	23.1463
2300.15	30.8579
2303.74	37.5926
2307.34	31.9552
2310.93	43.3395
2314.52	173.174
2318.11	426.128
2321.7	286.582
2325.28	101.498
2328.87	46.2662
2332.45	33.6301
2336.03	37.0194
2339.61	26.2421
2343.19	29.5712
2346.77	33.796
2350.34	20.1879
2353.92	20.6421
2357.49	35.0773
2361.06	29.8816
2364.63	14.4773
2368.2	42.7481
2371.76	16.34
2375.33	24.2191
2378.89	29.3023
2382.45	26.109
2386.01	51.4713
2389.57	15.2511
2393.13	36.0673
2396.68	33.9963
2400.23	21.0198
2403.79	25.594
2407.34	25.6315
2410.88	18.4269
2414.43	25.9682
2417.98	6.9333
2421.52	26.5382
2425.06	14.9255
2428.61	10.7223
2432.14	14.8764
2435.68	23.7347
2439.22	28.9458
2442.75	19.3031
2446.29	16.1562
2449.82	15.8472
2453.35	23.0881
2456.88	32.1024
2460.4	21.1468
2463.93	13.8941
2467.45	30.9732
2470.98	25.5786
2474.5	30.2199
2478.02	8.34943
2481.54	14.8338
2485.05	16.5204
2488.57	27.4601
2492.08	5.60313
2495.59	9.96947
2499.1	19.9989
2502.61	14.042
2506.12	12.7234
2509.63	41.1912
2513.13	26.7639
2516.63	7.80214
2520.13	22.3363
2523.63	25.539
2527.13	29.9072
2530.63	21.4036
2534.12	20.3323
2537.62	24.8759
2541.11	6.40605
2544.6	22.1928
2548.09	24.2605
2551.58	1.38588
2555.06	19.2353
2558.55	12.2451
2562.03	19.1495
2565.51	28.0502
2568.99	8.17438
2572.47	8.82407
2575.95	18.8948
2579.43	11.2138
2582.9	17.6445
2586.37	25.0632
2589.84	6.86093
2593.31	7.45261
2596.78	7.99632
2600.25	9.57254
2603.71	12.1028
2607.18	11.6331
2610.64	17.6889
2614.1	12.0325
2617.56	19.9321
2621.02	13.3163
2624.47	11.4607
2627.93	5.69734
2631.38	19.1071
2634.83	7.49609
2638.28	9.25455
2641.73	16.7143
2645.18	26.9731
2648.62	18.0951
2652.07	18.7224
2655.51	18.3336
2658.95	11.2498
2662.39	21.2225
2665.83	18.8398
2669.27	15.5241
2672.7	8.4453
2676.14	16.4534
2679.57	13.2263
2683	17.5421
2686.43	8.85939
2689.86	23.6573
2693.29	20.8374
2696.71	16.0978
2700.13	15.1444
2703.56	20.721
2706.98	24.4231
2710.4	12.5011
2713.82	7.1342
2717.23	12.9817
2720.65	20.7501
2724.06	28.5676
2727.47	21.4793
2730.88	-1.5016
2734.29	19.4469
2737.7	9.51848
2741.11	26.7669
2744.51	4.56601
2747.91	23.6372
2751.32	3.24883
2754.72	6.33971
2758.11	3.75476
2761.51	8.71597
2764.91	14.5601
2768.3	26.0271
2771.7	11.0667
2775.09	10.2253
2778.48	19.7067
2781.87	11.2584
2785.25	21.6221
2788.64	25.3835
2792.03	16.9141
2795.41	14.0817
2798.79	18.7706
2802.17	7.46342
2805.55	21.487
2808.93	8.32312
2812.3	26.987
2815.68	11.9466
2819.05	23.0816
2822.42	7.16837
2825.79	17.4292
2829.16	11.8483
2832.53	32.3948
2835.89	17.5754
2839.26	23.2952
2842.62	16.9525
2845.98	27.4371
2849.34	33.3562
2852.7	23.488
2856.06	18.2388
2859.41	4.59543
2862.77	-0.620529
2866.12	11.0316
2869.47	11.4546
2872.82	6.22672
2876.17	18.8479
2879.52	9.83841
2882.87	15.8808
2886.21	10.5985
2889.55	21.347
2892.89	-0.960068
2896.23	6.89749
2899.57	30.8104
2902.91	21.5915
2906.25	16.1232
2909.58	21.9903
2912.91	20.269
2916.25	27.9974
2919.58	20.5499
2922.91	15.9305
2926.23	20.7509
2929.56	12.3023
2932.88	20.8392
2936.21	17.059
2939.53	25.5427
2942.85	23.6512
2946.17	14.2387
2949.49	10.4941
2952.8	35.889
2956.12	34.0105
2959.43	34.0532
2962.74	35.0606
2966.06	28.5745
2969.37	16.5344
2972.67	17.678
2975.98	18.8211
2979.28	20.9518
2982.59	22.1136
2985.89	23.2903
2989.19	18.849
2992.49	22.8661
2995.79	13.7443
2999.09	9.32813
3002.38	34.0584
3005.68	35.2884
3008.97	29.9517
3012.26	15.2049
3015.55	28.716
3018.84	24.323
3022.13	26.5242
3025.41	22.1221
3028.7	20.552
3031.98	18.9763
3035.26	29.6764
3038.54	21.4648
3041.82	33.1163
3045.1	33.424
3048.38	30.8943
3051.65	24.57
3054.92	24.8831
3058.2	25.1875
3061.47	41.5446
3064.73	23.787
3068	41.1072
3071.27	24.2272
3074.54	28.9359
3077.8	37.6971
3081.06	38.771
3084.32	35.328
3087.58	46.099
3090.84	43.6564
3094.1	47.91
3097.35	30.894
3100.61	63.489
3103.86	43.7319
3107.11	51.6799
3110.36	48.1817
3113.61	56.016
3116.86	59.1156
3120.11	60.3193
3123.35	55.8082
3126.59	64.629
3129.84	54.3861
3133.08	48.9094
3136.32	34.8449
3139.55	70.3341
3142.79	62.9241
3146.03	75.5351
3149.26	52.8846
3152.49	64.5683
3155.72	74.3344
3158.95	72.6636
3162.18	70.9814
3165.41	93.1587
3168.64	82.8646
3171.86	81.1375
3175.08	69.8572
3178.31	78.5909
3181.53	78.7312
3184.75	84.6028
3187.96	84.7157
3191.18	75.2876
3194.4	90.6407
3197.61	85.0217
3200.82	99.3971
3204.03	87.1191
3207.24	93.8928
3210.45	109.24
3213.66	105.573
3216.86	113.345
3220.07	89.7239
3223.27	93.6989
3226.48	104.363
3229.68	122.644
3232.87	101.945
3236.07	115.471
3239.27	113.843
3242.47	102.709
3245.66	119.208
3248.85	114.751
3252.04	100.787
3255.23	109.713
3258.42	126.28
3261.61	139.952
3264.8	134.48
3267.98	128.003
3271.16	127.223
3274.35	135.019
3277.53	114.157
3280.71	147.668
3283.89	144.816
3287.06	146.747
3290.24	134.339
3293.41	137.222
3296.58	131.514
3299.76	146.757
3302.93	142.089
3306.1	145.895
3309.26	131.598
3312.43	130.57
3315.59	147.563
3318.76	143.648
3321.92	147.309
3325.08	180.325
3328.24	173.543
3331.4	158.27
3334.56	171.388
3337.71	159.97
3340.87	168.408
3344.02	160.808
3347.17	163.668
3350.33	192.073
3353.47	185.588
3356.62	188.573
3359.77	188.747
3362.92	185.198
3366.06	195.799
3369.2	199.822
3372.34	179.328
3375.49	201.342
3378.62	176.17
3381.76	188.79
3384.9	207.072
3388.04	195.138
3391.17	198.337
3394.3	198.693
3397.43	189.446
3400.56	215.491
3403.69	214.097
3406.82	214.638
3409.95	219.005
3413.07	209.098
3416.2	227.652
3419.32	234.763
3422.44	231.354
3425.56	220.217
3428.68	213.769
3431.8	218.721
3434.91	228.368
3438.03	231.219
3441.14	222.671
3444.25	213.169
3447.36	239.825
3450.47	219.738
3453.58	204.369
3456.69	204.248
3459.79	224.049
3462.9	209.583
3466	206.519
3469.11	201.51
3472.21	212.537
3475.31	198.1
3478.4	212.098
3481.5	194.884
3484.6	197.549
3487.69	200.234
3490.79	199.192
3493.88	182.22
3496.97	199.21
3500.06	196.35
3503.15	201.053
3506.23	173.636
3509.32	187.702
3512.4	167.739
3515.49	132.793
3518.57	172.465
3521.65	180.296
3524.73	175.245
3527.81	160.562
3530.89	158.904
3533.96	133.575
3537.03	150.565
3540.11	126.971
3543.18	139.413
3546.25	130.053
3549.32	129.438
3552.39	121.179
3555.46	120.442
3558.52	112.184
3561.59	121.917
3564.65	119.275
3567.71	125.109
3570.77	95.9707
3573.83	120.724
3576.89	108.508
3579.95	107.647
3583	97.2761
3586.06	97.3098
3589.11	102.084
3592.16	97.3372
3595.21	99.2204
3598.27	95.3889
3601.31	87.7728
3604.36	96.226
3607.41	96.1314
3610.45	90.3603
3613.5	78.9093
3616.54	77.8491
3619.58	64.5301
3622.62	75.7647
3625.66	69.0788
3628.69	75.6104
3631.73	54.8037
3634.77	67.8916
3637.8	65.0319
3640.83	61.2656
3643.86	37.7668
3646.89	54.7936
3649.92	54.809
3652.95	47.3596
3655.98	49.9015
3659	59.5765
3662.02	35.351
3665.05	30.8367
3668.07	38.4595
3671.09	51.7983
3674.11	38.7464
3677.13	41.7383
3680.14	34.3578
3683.16	43.0204
3686.17	39.4016
3689.19	42.4081
3692.2	34.0616
3695.21	34.2367
3698.22	49.5287
3701.23	27.896
3704.23	27.1159
3707.24	26.333
3710.24	25.523
3713.25	15.1878
3716.25	41.9132
3719.25	24.9025
3722.25	17.3712
3725.25	27.9094
3728.25	15.5768
3731.24	30.8454
3734.24	32.7608
3737.23	29.89
3740.22	31.7615
3743.21	24.0891
3746.21	16.4054
3749.19	43.8822
3752.18	34.2571
3755.17	18.9432
3758.15	16.9373
3761.14	25.3595
3764.12	26.1703
3767.1	27.9307
3770.08	20.2411
3773.06	10.6875
3776.04	-0.733353
3779.02	27.5529
3781.99	18.9919
3784.97	17.9928
3787.94	10.3968
3790.91	26.4113
3793.88	25.4662
3796.85	23.5941
3799.82	20.7885
3802.79	9.51204
3805.76	20.9063
3808.72	13.4175
3811.69	23.893
3814.65	13.5803
3817.61	28.8031
3820.57	28.9065
3823.53	6.29001
3826.49	13.9796
3829.45	24.5243
3832.4	10.4172
3835.36	30.4801
3838.31	-0.70842
3841.26	10.8313
3844.21	31.8978
3847.16	17.7782
3850.11	11.2663
3853.06	29.5457
3856	20.1856
3858.95	23.2283
3861.89	15.7632
3864.84	7.31557
3867.78	11.3037
3870.72	21.0315
3873.66	10.628
3876.6	25.1545
3879.53	20.4706
3882.47	12.879
3885.4	26.3999
3888.34	14.9196
3891.27	19.771
3894.2	14.999
3897.13	11.1628
3900.06	14.0346
3902.99	19.7875
3905.91	26.4705
3908.84	12.0327
3911.76	6.23019
3914.69	22.5104
3917.61	5.14801
3920.53	9.91888
3923.45	20.4075
3926.37	24.1486
3929.28	16.3608
3932.2	17.1932
3935.11	17.1148
3938.03	23.7796
3940.94	12.2914
3943.85	6.52922
3946.76	15.139
3949.67	10.3647
3952.58	20.9254
3955.49	16.1736
3958.39	19.1021
3961.3	5.75195
3964.2	18.2838
3967.1	15.4933
3970	0.238739
3972.9	24.3308
3975.8	10.9895
3978.7	17.7995
3981.6	20.7569
3984.49	20.8294
3987.39	16.0837
3990.28	11.3324
3993.17	12.3229
3996.06	23.9378
3998.95	22.0804
4001.84	19.2705
4004.73	24.1666
4007.61	11.7348
4010.5	24.3576
4013.38	15.7736
4016.27	9.11444
4019.15	19.8217
4022.03	21.8478
4024.91	25.8084
4027.79	10.453
4030.66	7.65195
4033.54	15.4929
4036.42	25.278
4039.29	3.13759
4042.16	24.5559
4045.03	18.8288
4047.9	26.6753
4050.77	17.0878
4053.64	18.1734
4056.51	21.2208
4059.38	18.44
4062.24	2.04652
4065.1	11.8839
4067.97	12.0053
4070.83	3.36746
4073.69	20.0316
4076.55	8.46397
4079.41	7.60251
4082.26	10.6396
4085.12	13.6814
4087.97	4.03491
4090.83	17.8036
4093.68	17.9283
4096.53	6.31926
4099.38	13.2764
4102.23	16.3272
4105.08	3.72621
4107.93	11.6405
4110.77	0.96817
4113.62	10.8259
4116.46	13.8153
4119.3	10.9068
4122.14	22.6786
4124.98	15.8803
4127.82	27.6839
4130.66	11.1535
4133.5	16.1899
4136.33	5.60667
4139.17	6.57211
4142	13.2338
4144.83	3.46468
4147.67	8.46939
4150.5	6.63971
4153.33	8.68948
4156.15	5.77771
4158.98	12.5781
4161.81	5.73393
4164.63	2.83665
4167.45	20.4781
4170.28	3.8961
4173.1	24.4892
4175.92	22.5961
4178.74	14.8367
4181.56	15.8947
4184.37	-1.62289
4187.19	17.0619
4190	13.2552
4192.82	8.49617
4195.63	4.7346
4198.44	10.7941
4201.25	11.9554
4204.06	16.0687
4206.87	13.3104
4209.68	14.4812
4212.48	19.5795
4215.29	0.0995636
4218.1	18.0916
4220.9	12.473
4223.7	20.6343
4226.5	12.0019
4229.3	14.2538
4232.1	17.5104
4234.9	10.8919
4237.69	9.22984
4240.49	12.5344
4243.28	8.89224
4246.07	17.2016
4248.87	9.57031
4251.66	15.8796
4254.45	15.2014
4257.24	17.5074
4260.03	10.7995
4262.81	-2.93495
4265.6	10.4167
4268.38	17.7821
4271.17	13.0857
4273.95	14.4192
4276.73	16.7295
4279.51	9.92841
4282.29	7.14513
4285.07	7.37343
4287.84	21.7446
4290.62	9.79112
4293.39	17.0595
4296.17	19.294
4298.94	9.38336
4301.71	10.6044
4304.48	6.74957
4307.25	22.1833
4310.02	12.2444
4312.79	6.37822
4315.55	20.8222
4318.32	10.8396
4321.08	12.0339
4323.85	2.01518
4326.61	11.3315
4329.37	22.695
4332.13	6.54018
4334.89	3.63445
4337.65	15.9969
4340.4	16.1662
4343.16	15.3212
4345.91	18.5733
4348.67	28.9891
4351.42	17.9814
4354.17	14.1594
4356.92	-3.99315
4359.67	9.53717
4362.42	14.8874
4365.17	8.99557
4367.91	17.4299
4370.66	-0.768875
4373.4	22.0214
4376.14	16.0874
4378.89	9.1069
4381.63	25.7423
4384.37	12.6014
4387.11	13.8825
4389.84	13.1784
4392.58	8.38359
4395.32	25.391
4398.05	17.5139
4400.78	11.6654
4403.52	10.9697
4406.25	24.8074
4408.98	28.298
4411.71	29.6953
4414.44	13.3678
4417.16	4.29504
4419.89	21.2056
4422.62	12.0836
4425.34	17.579
4428.06	5.323
4430.78	15.0057
4433.51	13.1896
4436.22	27.0681
4438.94	36.7644
4441.66	13.9557
4444.38	11.0537
4447.1	11.2868
4449.81	29.3672
4452.52	12.7878
4455.24	14.0538
4457.95	8.9985
4460.66	18.65
4463.37	15.7101
4466.08	23.2859
4468.78	11.9339
4471.49	15.3214
4474.2	5.03233
4476.9	10.5591
4479.6	24.5464
4482.31	19.563
4485.01	26.194
4487.71	23.3043
4490.41	9.82379
4493.11	19.573
4495.8	20.8215
4498.5	18.9316
4501.19	18.0912
4503.89	18.2914
4506.58	14.27
4509.27	10.2512
4511.96	25.3292
4514.66	31.9319
4517.34	13.0561
4520.03	33.4848
4522.72	12.4904
4525.41	8.49275
4528.09	33.2299
4530.77	12.1967
4533.46	15.6576
4536.14	28.73
4538.82	13.0031
4541.5	5.81143
4544.18	8.22748
4546.86	20.2846
4549.53	4.517
4552.21	2.67116
4554.88	10.5094
4557.56	21.6114
4560.23	20.9621
4562.9	20.3417
4565.57	8.96893
4568.24	24.669
4570.91	14.2956
4573.58	17.8107
4576.24	20.151
4578.91	16.0661
4581.58	9.86781
4584.24	28.7466
4586.9	34.4693
4589.56	19.4699
4592.22	13.1604
4594.88	22.1348
4597.54	14.7607
4600.2	13.9119
4602.86	19.6602
4605.51	18.8603
4608.17	23.5396
4610.82	26.0364
4613.47	20.8432
4616.13	29.9247
4618.78	8.22849
4621.43	9.62447
4624.07	22.0384
4626.72	19.0151
4629.37	19.2889
4632.01	19.5573
4634.66	28.6444
4637.3	20.0259
4639.94	15.8231
4642.59	20.4749
4645.23	21.8475
4647.87	6.62354
4650.5	9.17967
4653.14	2.89731
4655.78	12.1543
4658.42	14.5236
4661.05	20.3736
4663.68	7.27898
4666.31	1.96362
4668.95	12.2589
4671.58	22.585
4674.21	30.681
4676.84	27.5722
4679.46	31.1875
4682.09	7.8466
4684.72	17.0649
4687.34	13.9235
4689.97	22.0339
4692.59	6.50414
4695.21	11.2258
4697.83	10.3099
4700.45	12.7815
4703.07	14.1214
4705.69	9.79492
4708.3	26.9416
4710.92	13.5528
4713.54	26.1794
4716.15	17.2954
4718.76	19.7212
4721.37	18.7439
4723.99	13.2192
4726.59	28.1248
4729.2	24.9023
4731.81	22.8119
4734.42	9.3614
4737.03	23.1618
4739.63	14.2261
4742.23	15.5124
4744.84	11.0956
4747.44	12.355
4750.04	3.3463
4752.64	18.2388
4755.24	10.3675
4757.84	2.49144
4760.44	21.9496
4763.03	2.71152
4765.63	30.1724
4768.22	12.107
4770.82	20.2692
4773.41	-3.54622
4776	-1.12764
4778.59	4.71938
4781.18	20.85
4783.77	9.56442
4786.36	39.4348
4788.94	9.84448
4791.53	19.1458
4794.11	13.5762
4796.7	6.85861
4799.28	19.6409
4801.86	18.6822
4804.44	10.844
4807.02	20.2541
4809.6	19.3407
4812.18	24.1809
4814.76	-3.24815
4817.33	18.914
4819.91	7.62042
4822.48	21.7594
4825.06	20.8716
4827.63	7.21458
4830.2	16.7581
4832.77	5.40501
4835.34	2.17902
4837.91	11.7964
4840.48	9.77222
4843.04	18.2709
4845.61	20.9033
4848.17	18.8292
4850.74	15.5279
4853.3	15.6386
4855.86	20.4594
4858.42	7.80704
4860.98	19.8725
4863.54	17.7567
4866.1	0.216949
4868.66	8.66679
4871.21	10.0724
4873.77	19.7357
4876.32	13.9797
4878.88	14.1479
4881.43	8.37042
4883.98	22.7712
4886.53	12.2258
4889.08	0.482391
4891.63	12.5288
4894.18	15.057
4896.72	14.0093
4899.27	3.41916
4901.81	20.247
4904.36	14.418
4906.9	14.5483
4909.44	14.6709
4911.98	11.1785
4914.52	2.89426
4917.06	13.7083
4919.6	9.0103
4922.14	15.0665
4924.67	15.1525
4927.21	14.056
4929.74	4.57562
4932.28	19.0414
4934.81	13.2194
4937.34	8.57484
4939.87	6.31889
4942.4	13.5767
4944.93	14.9023
4947.46	6.67747
4949.99	11.6266
4952.51	7.00211
4955.04	10.7559
4957.56	7.33997
4960.08	1.53441
4962.61	0.545166
4965.13	10.4258
4967.65	3.49614
4970.17	1.33821
4972.69	20.8952
4975.2	-3.00336
4977.72	20.21
4980.24	9.59126
4982.75	12.2827
4985.27	2.86424
4987.78	11.6386
4990.29	5.86029
4992.8	7.3644
4995.31	14.9565
4997.82	10.4098