File: Data/3-Raman/processed/bu19w-b-ff1-fi05-s_150 (500nm)_532nm_edge_100%_x100_vis_h50um_15sx2_01.txt
#Acq. time (s)=	15
#Accumulations=	2
#Range (cm-¹)=	100...5000
#Windows=	1
#Auto scanning=	Off
#Autofocus=	Off
#Macrospot=	Off
#AutoExposure=	Off
#Spike filter=	Multiple accum.
#Delay time (s)=	2
#Binning=	1
#Readout mode=	Signal
#DeNoise=	Off
#ICS correction=	On
#Dark correction=	Off
#Inst. Process=	Off
#Detector Gain=	Best Dynamic
#Detector ADC=	50 kHz HS
#Detector temperature (°C)=	-60.09
#Instrument=	LabRAM HR Evol
#Detector=	SIN-EM FIVIS
#Objective=	x100_VIS
#Grating=	150 (500nm)
#ND Filter=	100%
#Laser=	532nm_Edge
#Hole=	49.98
#Temperature=	0
#Range=	Visible
#StageXY=	75x50mm Scan+
#StageZ=	Z motor
#X (µm)=	0
#Y (µm)=	0
#Z (µm)=	-135.8
#Full time(s)=	34
#Project=	21_05_14
#Sample=	BU19w
#Site=
#Title=	BU19w-FF1-FI05-S_150 (500nm)_532nm_Edge_100%_x100_VIS_H50um_15sX2
#Remark=
#Date=	14.05.2021 14:32
#Acquired=	14.05.2021 14:32:31
#Base:Fit=	22.12.2021 12:22:35
#Base:Sub=	22.12.2021 12:25:06
#Data Range:Extract=	22.12.2021 12:27:19
102.699	1103.61
107.322	995.23
111.942	802.706
116.56	724.768
121.173	699.773
125.787	938.77
130.398	891.965
135.006	603.287
139.613	691.885
144.215	534.964
148.817	539.553
153.417	864.311
158.014	2019.38
162.607	3554.85
167.2	2802.98
171.79	1316.62
176.379	1069.08
180.963	1640.85
185.547	4651.14
190.128	9521.52
194.705	6440.12
199.282	1737.18
203.857	490.073
208.43	206.315
212.998	162.891
217.566	168.983
222.132	108.332
226.693	-0.000976563
231.254	51.979
235.813	273.168
240.368	321.829
244.923	634.467
249.475	1045.4
254.023	1225.13
258.571	1199.58
263.117	1560.17
267.658	2134.29
272.199	2073.08
276.738	4034.38
281.273	7439.17
285.807	8049.51
290.34	4480.12
294.868	2345.94
299.396	2711.59
303.919	4398.11
308.443	4176.46
312.964	2317.4
317.481	1222.42
321.998	883.633
326.51	1113.33
331.023	1646.86
335.533	1454.09
340.039	808.95
344.544	495.025
349.046	528.585
353.547	527.06
358.045	329.413
362.542	197.318
367.036	155.314
371.527	232.206
376.017	255.625
380.503	415.599
384.99	840.02
389.471	1308.3
393.953	1645.92
398.43	1676.33
402.908	1550.9
407.381	1216.7
411.854	1215.98
416.323	2347.68
420.791	2616.41
425.256	1356.16
429.72	537.606
434.18	324.996
438.64	292.887
443.095	358.17
447.551	499.258
452.003	1178.39
456.454	2753.1
460.901	3161.92
465.348	1939.01
469.791	1520.45
474.231	1459.25
478.672	1349.42
483.108	1313.05
487.544	1332.5
491.976	1271.1
496.408	1218.82
500.836	1125.57
505.261	951.809
509.687	762.495
514.108	653.158
518.529	531.093
522.946	482.792
527.361	494.537
531.776	509.114
536.187	604.757
540.595	677.176
545.003	643.942
549.408	651.206
553.812	701.52
558.212	688.248
562.61	777.545
567.007	726.777
571.401	528.983
575.792	444.097
580.184	581.473
584.571	1129.14
588.956	2422.12
593.341	2988.58
597.722	1951.61
602.101	1204.08
606.48	1198.75
610.854	1698.34
615.227	2323.35
619.597	1895.94
623.967	1102.06
628.334	768.5
632.698	1170.49
637.06	1487.16
641.422	971.663
645.779	675.297
650.135	493.724
654.491	274.277
658.842	259.51
663.192	307.389
667.539	381.794
671.884	376.105
676.23	515.372
680.571	721.798
684.91	574.305
689.247	362.833
693.583	212.85
697.916	148.302
702.247	78.4469
706.576	38.2981
710.902	0.0123291
715.229	40.3888
719.551	64.3119
723.872	50.2814
728.19	44.7177
732.506	40.2006
736.82	106.242
741.134	158.458
745.444	179.482
749.752	208.104
754.058	298.284
758.362	371.983
762.664	521.297
766.964	790.978
771.264	1315.12
775.559	2140.74
779.853	3179.17
784.144	3400.27
788.434	2589.58
792.722	1610.63
797.007	1057.95
801.29	808.631
805.572	603.503
809.851	484.508
814.13	453.911
818.406	370.341
822.679	329.017
826.95	270.244
831.219	210.371
835.486	201.029
839.752	230.146
844.015	252.311
848.276	258.908
852.535	316.061
856.792	389.68
861.047	409.057
865.3	462.96
869.551	388.872
873.8	254.116
878.047	163.305
882.292	171.698
886.534	188.069
890.775	207.23
895.014	276.52
899.251	306.654
903.486	312.778
907.719	303.555
911.95	273.96
916.179	201.942
920.406	200.29
924.63	127.61
928.853	144.477
933.074	185.108
937.293	275.451
941.51	373.871
945.723	476.952
949.936	604.789
954.147	683.501
958.356	726.123
962.563	809.275
966.768	1049.47
970.971	1237.89
975.172	1142.23
979.371	941.394
983.568	879.575
987.761	924.289
991.954	1081.6
996.145	1431.73
1000.33	1917
1004.52	1887.78
1008.71	1297.65
1012.89	946.64
1017.07	842.089
1021.25	900.482
1025.43	1146.68
1029.6	1641.07
1033.77	2569.2
1037.95	2828.32
1042.11	2746.41
1046.28	3811.16
1050.45	4730.89
1054.61	4893.18
1058.77	4239.08
1062.93	2799.73
1067.09	1755.95
1071.24	1201.17
1075.4	1088.48
1079.55	1275.66
1083.7	1702.98
1087.85	2653.51
1091.99	3883.19
1096.14	4297.75
1100.28	3719.51
1104.42	2827.38
1108.55	2845.01
1112.69	3264.26
1116.82	3112.42
1120.96	2652.94
1125.09	2393.37
1129.21	2464.68
1133.34	2744.49
1137.46	2697.32
1141.59	2175.39
1145.71	1585.21
1149.83	1332
1153.94	1563.79
1158.06	2014.26
1162.17	2324.1
1166.28	1983.13
1170.39	1506.03
1174.5	1285.46
1178.6	1129.97
1182.7	897.559
1186.8	706.173
1190.9	589.67
1195	491.45
1199.1	507.257
1203.19	486.125
1207.28	438.759
1211.37	337.195
1215.46	265.454
1219.54	279.891
1223.63	427.843
1227.71	549.867
1231.79	478.204
1235.87	505.906
1239.95	684.616
1244.02	957.214
1248.09	772.11
1252.16	433.646
1256.23	275.044
1260.3	240.478
1264.36	216.113
1268.43	203.091
1272.49	186.057
1276.55	116.7
1280.6	86.2994
1284.66	51.3925
1288.71	81.8203
1292.76	28.3479
1296.81	14.0546
1300.86	84.1666
1304.91	90.5381
1308.95	-3.84265
1312.99	58.536
1317.03	92.1765
1321.07	64.1989
1325.11	80.7262
1329.14	50.3069
1333.18	44.4575
1337.21	26.3021
1341.24	30.025
1345.26	47.5959
1349.29	43.2257
1353.31	55.804
1357.33	85.1969
1361.35	111.469
1365.37	166.755
1369.39	351.387
1373.4	481.774
1377.41	384.435
1381.43	199.229
1385.43	129.993
1389.44	117.041
1393.45	41.7107
1397.45	42.4314
1401.45	14.2723
1405.45	22.7267
1409.45	5.6626
1413.44	1.48914
1417.44	20.9563
1421.43	20.6044
1425.42	40.5221
1429.41	35.2819
1433.39	31.3922
1437.38	13.4514
1441.36	33.0663
1445.34	7.96375
1449.32	39.063
1453.3	4.75415
1457.27	15.7023
1461.24	38.0374
1465.22	36.4207
1469.19	27.0887
1473.15	1.12756
1477.12	-1.55066
1481.09	51.4933
1485.05	32.9163
1489.01	13.4021
1492.97	58.4072
1496.93	7.89099
1500.88	41.3871
1504.83	43.0449
1508.79	14.8646
1512.74	27.4923
1516.68	48.9781
1520.63	13.3337
1524.57	56.3359
1528.52	103.336
1532.46	27.3331
1536.4	47.295
1540.33	52.7527
1544.27	64.0046
1548.2	78.1644
1552.14	60.2596
1556.07	137.019
1559.99	107.06
1563.92	95.3578
1567.84	78.7015
1571.77	101.606
1575.69	164.983
1579.61	137.531
1583.52	131.251
1587.44	117.177
1591.35	147.363
1595.27	146.713
1599.18	132.684
1603.09	146.696
1606.99	143.567
1610.9	133.76
1614.8	185.46
1618.7	158.644
1622.6	217.064
1626.5	188.654
1630.39	177.791
1634.29	167.186
1638.18	178.641
1642.07	199.205
1645.96	181.625
1649.85	207.287
1653.73	181.102
1657.62	187.409
1661.5	154.153
1665.38	143.666
1669.26	172.295
1673.13	139.063
1677.01	125.629
1680.88	122.061
1684.75	144.249
1688.62	85.6764
1692.49	96.818
1696.35	110.584
1700.22	63.9004
1704.08	76.1082
1707.94	62.2988
1711.8	118.588
1715.66	83.8616
1719.51	57.814
1723.37	84.5977
1727.22	71.5551
1731.07	49.1278
1734.92	17.4408
1738.76	26.7789
1742.61	58.4049
1746.45	51.3665
1750.29	66.4617
1754.13	54.3065
1757.97	39.2267
1761.81	43.3564
1765.64	76.6288
1769.47	57.8724
1773.31	40.2919
1777.14	40.5966
1780.96	33.839
1784.79	36.554
1788.61	38.4492
1792.43	39.4506
1796.25	62.9758
1800.07	70.0251
1803.89	30.3993
1807.71	50.0192
1811.52	26.0464
1815.33	9.13257
1819.14	68.1379
1822.95	30.6213
1826.76	43.719
1830.56	37.5618
1834.37	3.8136
1838.17	32.0018
1841.97	51.3821
1845.77	47.2029
1849.56	59.635
1853.36	51.8066
1857.15	56.6915
1860.94	22.1399
1864.73	67.6873
1868.52	70.5531
1872.31	49.5824
1876.09	48.282
1879.87	46.4417
1883.66	63.3506
1887.43	45.2802
1891.21	71.2958
1894.99	53.9546
1898.76	28.7177
1902.53	35.222
1906.31	44.6687
1910.08	51.7307
1913.84	4.6676
1917.61	63.3721
1921.37	40.4001
1925.14	-3.8291
1928.9	76.478
1932.66	47.2638
1936.41	17.8793
1940.17	16.3834
1943.92	66.6932
1947.68	30.5422
1951.43	69.8218
1955.18	51.1787
1958.92	63.7255
1962.67	56.4215
1966.41	93.085
1970.16	51.0841
1973.9	113.848
1977.64	46.052
1981.37	60.4844
1985.11	97.9487
1988.84	38.2589
1992.57	75.1637
1996.31	32.7787
2000.03	93.2103
2003.76	98.1329
2007.49	105.251
2011.21	45.0867
2014.93	36.9929
2018.65	100.522
2022.37	87.6077
2026.09	37.0615
2029.81	61.3411
2033.52	67.7971
2037.23	93.985
2040.94	85.4773
2044.65	95.9773
2048.36	75.675
2052.07	88.5394
2055.77	51.274
2059.47	81.2045
2063.17	85.9969
2066.87	85.4572
2070.57	96.9594
2074.27	91.9084
2077.96	75.9003
2081.65	104.312
2085.34	83.6024
2089.03	100.844
2092.72	88.2073
2096.41	100.97
2100.09	56.2466
2103.77	103.364
2107.46	108.361
2111.14	122.521
2114.81	98.5255
2118.49	72.2389
2122.16	107.596
2125.84	96.4178
2129.51	147.023
2133.18	80.9558
2136.85	41.6437
2140.51	134.939
2144.18	118.256
2147.84	119.05
2151.5	101.518
2155.16	90.543
2158.82	129.077
2162.48	132.165
2166.13	106.309
2169.79	84.6028
2173.44	109.989
2177.09	101.794
2180.74	135.607
2184.38	92.1068
2188.03	98.4572
2191.67	78.0482
2195.32	133.766
2198.96	89.4504
2202.6	79.9542
2206.23	115.472
2209.87	104.666
2213.5	96.7244
2217.14	108.986
2220.77	110.323
2224.4	134.699
2228.03	100.956
2231.65	118.993
2235.28	119.558
2238.9	130.234
2242.52	121.44
2246.14	86.5782
2249.76	129.049
2253.38	61.7742
2256.99	106.437
2260.6	75.3032
2264.21	79.6501
2267.82	83.4255
2271.44	77.8009
2275.04	69.6638
2278.65	90.1771
2282.25	88.2676
2285.85	111.254
2289.45	37.5564
2293.05	86.7175
2296.65	150.25
2300.25	85.8606
2303.84	58.0215
2307.43	115.234
2311.02	75.5715
2314.62	90.6393
2318.2	98.7737
2321.79	99.6365
2325.38	100.77
2328.96	76.465
2332.54	58.5272
2336.12	79.1167
2339.7	104.151
2343.28	118.624
2346.85	89.7711
2350.43	97.4449
2354	58.324
2357.57	95.6766
2361.14	40.7552
2364.71	108.627
2368.27	83.8574
2371.84	116.701
2375.4	86.4961
2378.96	90.6976
2382.52	46.2837
2386.08	57.3408
2389.64	87.9512
2393.19	80.3638
2396.75	51.3051
2400.3	99.9064
2403.85	60.1742
2407.4	63.796
2410.95	52.4457
2414.49	23.8868
2418.04	43.4158
2421.58	48.5205
2425.12	77.103
2428.66	52.5101
2432.2	84.6227
2435.74	50.2852
2439.27	63.348
2442.81	86.8153
2446.34	18.9275
2449.87	77.5833
2453.4	59.9988
2456.93	73.9852
2460.45	81.6813
2463.98	52.9999
2467.5	61.8608
2471.02	77.0444
2474.54	53.4917
2478.06	76.7144
2481.58	99.6387
2485.09	42.6469
2488.61	62.8384
2492.12	60.6349
2495.63	100.222
2499.14	36.0641
2502.65	60.3125
2506.15	90.8156
2509.66	71.7449
2513.16	60.4905
2516.66	70.9362
2520.16	52.8702
2523.66	68.0197
2527.16	36.734
2530.66	64.7902
2534.15	80.3247
2537.64	96.1461
2541.13	45.2401
2544.62	43.0779
2548.11	62.3079
2551.6	59.593
2555.08	41.9712
2558.57	65.12
2562.05	0.626343
2565.53	78.8639
2569.01	67.3163
2572.49	26.0354
2575.96	49.6261
2579.44	52.7664
2582.91	72.0469
2586.38	78.9257
2589.85	105.973
2593.32	63.0997
2596.79	57.6621
2600.25	54.2278
2603.72	48.2094
2607.18	67.0336
2610.64	85.3064
2614.1	80.2203
2617.56	52.5023
2621.02	75.4186
2624.47	71.9696
2627.92	90.3732
2631.38	73.903
2634.83	69.4528
2638.28	99.2395
2641.72	108.506
2645.17	90.9446
2648.61	81.7299
2652.06	115.01
2655.5	44.2542
2658.94	81.6974
2662.38	72.4471
2665.82	97.2119
2669.25	57.6903
2672.69	65.5188
2676.12	46.3389
2679.55	60.2594
2682.98	105.286
2686.41	56.9283
2689.84	99.9485
2693.26	59.6102
2696.69	70.8058
2700.11	88.7424
2703.53	86.7826
2706.95	79.4648
2710.37	70.6757
2713.79	67.7476
2717.2	62.3199
2720.62	72.9659
2724.03	46.3971
2727.44	98.4401
2730.85	114.016
2734.26	92.1411
2737.66	75.8604
2741.07	107.166
2744.47	107.216
2747.87	106.346
2751.28	91.3308
2754.67	75.0447
2758.07	68.3591
2761.47	89.5145
2764.86	119.905
2768.26	105.699
2771.65	120.624
2775.04	100.44
2778.43	116.762
2781.82	87.7573
2785.2	117.982
2788.59	104.909
2791.97	81.3861
2795.35	137.857
2798.73	77.5664
2802.11	156.144
2805.49	109.058
2808.87	134.039
2812.24	101.869
2815.62	140.632
2818.99	95.5133
2822.36	123.479
2825.73	113.28
2829.1	119.089
2832.46	70.2103
2835.83	138.02
2839.19	114.814
2842.55	128.239
2845.91	143.979
2849.27	112.839
2852.63	152.3
2855.99	134.031
2859.34	146.851
2862.69	137.264
2866.05	171.82
2869.4	118.994
2872.75	134.631
2876.09	154.953
2879.44	149.865
2882.78	165.387
2886.13	139.297
2889.47	209.615
2892.81	153.872
2896.15	195.27
2899.49	154.16
2902.82	179.982
2906.16	186.778
2909.49	174.478
2912.82	164.067
2916.16	183.653
2919.49	201.226
2922.81	179.981
2926.14	186.807
2929.46	194.499
2932.79	211.269
2936.11	187.459
2939.43	248.497
2942.75	241.661
2946.07	216.12
2949.39	207.492
2952.7	243.913
2956.02	253.304
2959.33	236.658
2962.64	258.441
2965.95	266.495
2969.26	257.356
2972.57	240.43
2975.87	241.928
2979.17	280.628
2982.48	320.362
2985.78	242.88
2989.08	292.179
2992.38	277.693
2995.68	287.742
2998.97	326.972
3002.27	309.706
3005.56	345.279
3008.85	355.546
3012.14	309.378
3015.43	359.259
3018.72	364.829
3022	360.01
3025.29	381.658
3028.57	400.486
3031.85	430.596
3035.14	456.86
3038.41	410.32
3041.69	425.262
3044.97	411.877
3048.24	481.775
3051.52	487.386
3054.79	448.385
3058.06	528.672
3061.33	515.573
3064.6	559.572
3067.87	556.822
3071.13	575.401
3074.4	577.866
3077.66	582.233
3080.92	637.89
3084.18	612.364
3087.44	639.376
3090.7	702.031
3093.95	674.359
3097.21	701.128
3100.46	760.244
3103.71	775.311
3106.96	819.047
3110.21	877.421
3113.46	864.351
3116.71	897.081
3119.95	902.219
3123.2	925.432
3126.44	932.386
3129.68	987.002
3132.92	1018.72
3136.16	1091.33
3139.4	1073.32
3142.63	1162.08
3145.87	1129.87
3149.1	1184.53
3152.33	1227.68
3155.56	1303.32
3158.79	1349.34
3162.02	1353.38
3165.25	1395.42
3168.47	1446.78
3171.69	1457.94
3174.92	1520.41
3178.14	1556.04
3181.36	1585.05
3184.58	1601.4
3187.79	1696.71
3191.01	1695.69
3194.22	1770.85
3197.43	1751.59
3200.65	1836.2
3203.86	1804.74
3207.07	1857.17
3210.27	1897.39
3213.48	1983.5
3216.69	1982.13
3219.89	2022.68
3223.09	1992.17
3226.29	2040.73
3229.49	2106.69
3232.69	2083
3235.89	2153.12
3239.08	2214.09
3242.28	2180.05
3245.47	2169.82
3248.66	2236.12
3251.85	2270.22
3255.04	2315.84
3258.23	2262.74
3261.42	2340.92
3264.6	2362.25
3267.79	2364.06
3270.97	2382.78
3274.15	2349.92
3277.33	2428.22
3280.51	2463.68
3283.68	2523.88
3286.86	2469.26
3290.04	2524.54
3293.21	2529.22
3296.38	2561.36
3299.55	2619.19
3302.72	2579.25
3305.89	2641.61
3309.06	2702.34
3312.22	2704.7
3315.39	2733.51
3318.55	2770.64
3321.71	2891.07
3324.87	2902.46
3328.03	2881.74
3331.19	2958.61
3334.34	3085.76
3337.5	3122.54
3340.65	3190.39
3343.81	3311.8
3346.96	3396.77
3350.11	3555.32
3353.25	3834.97
3356.4	4097.91
3359.55	4523.73
3362.69	5142.27
3365.84	5901.98
3368.98	6917.05
3372.12	7822.4
3375.26	7904.65
3378.4	6759.4
3381.53	5786.46
3384.67	5047.59
3387.8	4783.05
3390.94	4633.07
3394.07	4521.36
3397.2	4322.33
3400.33	4417.07
3403.46	4486.91
3406.58	4639.98
3409.71	5013.42
3412.83	5387.1
3415.96	6795.91
3419.08	10469.9
3422.2	17962.6
3425.32	20927.9
3428.44	14124.5
3431.55	7944.46
3434.67	5609.39
3437.78	4777.29
3440.89	4323.71
3444	4161.02
3447.12	4037.45
3450.22	3933.15
3453.33	3857.49
3456.44	3849.69
3459.54	3767.54
3462.65	3726.19
3465.75	3669.31
3468.85	3679.29
3471.95	3559
3475.05	3594.6
3478.15	3514.06
3481.24	3535.81
3484.34	3590.86
3487.43	3582.07
3490.53	3588.04
3493.62	3642.31
3496.71	3828.06
3499.79	3902.86
3502.88	4195.2
3505.97	4331.3
3509.05	4202.73
3512.14	3934.54
3515.22	3551.6
3518.3	3247.13
3521.38	3121.02
3524.46	2907.36
3527.54	2800.5
3530.61	2733.6
3533.69	2630.58
3536.76	2555.21
3539.83	2406.92
3542.9	2324.9
3545.97	2324.38
3549.04	2182.51
3552.11	2140.06
3555.18	2100.94
3558.24	2027.09
3561.3	1992.21
3564.37	1918.19
3567.43	1885.97
3570.49	1869.34
3573.55	1772.68
3576.61	1733.73
3579.66	1709.73
3582.72	1612.42
3585.77	1559.64
3588.82	1565.39
3591.87	1487.59
3594.92	1457.95
3597.97	1443.44
3601.02	1378.56
3604.07	1335.28
3607.11	1217.27
3610.16	1288.34
3613.2	1191.07
3616.24	1160.04
3619.28	1151.81
3622.32	1054.08
3625.36	1061.21
3628.39	992.915
3631.43	1006.46
3634.46	938.47
3637.5	843.592
3640.53	892.915
3643.56	795.961
3646.59	754.214
3649.62	714.593
3652.64	678.625
3655.67	644.162
3658.69	598.463
3661.72	610.852
3664.74	565.022
3667.76	526.774
3670.78	467.913
3673.79	453.435
3676.81	385.218
3679.83	411.367
3682.84	345.826
3685.86	325.656
3688.87	290.36
3691.88	296.748
3694.89	233.712
3697.9	220.081
3700.91	217.904
3703.91	222.375
3706.92	219.127
3709.92	215.766
3712.92	180.845
3715.92	197.323
3718.92	184.211
3721.92	147.168
3724.92	117.615
3727.92	112.728
3730.91	142.016
3733.91	122.603
3736.9	115.463
3739.89	116.753
3742.88	120.786
3745.87	90.4729
3748.86	113.305
3751.85	99.0349
3754.83	117.079
3757.82	103.797
3760.8	79.0693
3763.78	100.777
3766.76	59.1234
3769.74	88.5736
3772.72	51.9143
3775.7	70.1768
3778.67	57.3359
3781.65	81.3673
3784.62	84.6737
3787.6	75.7728
3790.57	22.6857
3793.54	63.1669
3796.51	61.2471
3799.47	15.1012
3802.44	46.4607
3805.41	50.4834
3808.37	30.9548
3811.33	60.6151
3814.3	44.9323
3817.26	56.7274
3820.22	79.9252
3823.18	15.1371
3826.13	45.0909
3829.09	39.0302
3832.04	64.3669
3835	42.3402
3837.95	42.1594
3840.9	41.0204
3843.85	54.174
3846.8	40.7222
3849.75	41.6172
3852.69	-5.1521
3855.64	41.5966
3858.58	39.7109
3861.53	30.114
3864.47	51.1376
3867.41	59.6631
3870.35	73.911
3873.29	52.646
3876.22	48.5264
3879.16	53.8949
3882.1	40.8765
3885.03	71.0074
3887.96	75.1437
3890.89	24.4323
3893.82	23.6007
3896.75	29.359
3899.68	59.1345
3902.61	23.3693
3905.53	51.1722
3908.46	39.5135
3911.38	51.7872
3914.3	48.5543
3917.23	62.8215
3920.15	73.1025
3923.06	24.6992
3925.98	54.8821
3928.9	30.2944
3931.81	27.0165
3934.73	35.4622
3937.64	35.5536
3940.55	55.6934
3943.46	35.6418
3946.37	31.0188
3949.28	62.8813
3952.19	48.8323
3955.09	-0.560913
3958	20.988
3960.9	7.14099
3963.8	29.7847
3966.71	26.6101
3969.61	54.1942
3972.51	59.7175
3975.4	25.8068
3978.3	29.2686
3981.2	50.9801
3984.09	36.1135
3986.99	44.3245
3989.88	36.005
3992.77	70.2036
3995.66	59.2014
3998.55	27.0691
4001.43	50.7893