File: Data/3-Raman/processed/bu19w-e-ff11-fi04-v_150 (500nm)_633nm_edge_100%_x100_vis_h50um_60sx2_01_0.txt
#Acq. time (s)=	60
#Accumulations=	2
#Range (cm-¹)=	100...4000
#Windows=	1
#Auto scanning=	Off
#Autofocus=	Off
#Macrospot=	Off
#AutoExposure=	Off
#Spike filter=	Multiple accum.
#Delay time (s)=	2
#Binning=	1
#Readout mode=	Signal
#DeNoise=	Off
#ICS correction=	On
#Dark correction=	Off
#Inst. Process=	Off
#Detector Gain=	Best Dynamic
#Detector ADC=	50 kHz HS
#Detector temperature (°C)=	-60.28
#Instrument=	LabRAM HR Evol
#Detector=	SIN-EM FIVIS
#Objective=	x100_VIS
#Grating=	150 (500nm)
#ND Filter=	100%
#Laser=	633nm_Edge
#Hole=	49.98
#Temperature=	0
#Range=	Visible
#StageXY=	75x50mm Scan+
#StageZ=	Z motor
#X (µm)=	0
#Y (µm)=	0
#Z (µm)=	-244.4
#Full time(mm:ss)=	2:04
#Project=	21_11_04
#Sample=	BU19w
#Site=
#Title=	BU19w-E-FF11-FI04-V_150 (500nm)_633nm_Edge_100%_x100_VIS_H50um_60sX2
#Remark=
#Date=	04.11.2021 16:32
#Acquired=	04.11.2021 16:32:58
#Base:Fit=	16.12.2021 17:39:50
#Base:Edit=	16.12.2021 17:50:49
#Base:Edit=	16.12.2021 17:50:50
#Base:Edit=	16.12.2021 17:50:51
#Base:Edit=	16.12.2021 17:50:52
#Base:Edit=	16.12.2021 17:50:52
#Base:Edit=	16.12.2021 17:50:53
#Base:Edit=	16.12.2021 17:50:53
#Base:Edit=	16.12.2021 17:50:53
#Base:Edit=	16.12.2021 17:50:54
#Base:Sub=	16.12.2021 17:50:55
102.881	256.109
109.397	224.427
115.908	178.56
122.414	168.047
128.914	128.961
135.409	139.636
141.898	89.0817
148.383	107.631
154.861	142.679
161.335	267.031
167.801	106.905
174.264	51.1157
180.721	74.784
187.173	146.116
193.62	102.468
200.061	24.802
206.496	15.3553
212.926	5.89246
219.352	6.98103
225.772	7.07468
232.185	81.2379
238.595	80.2962
244.999	203.975
251.397	95.8919
257.791	19.208
264.178	10.021
270.561	110.908
276.939	428.066
283.31	310.735
289.678	74.8833
296.039	33.3568
302.396	65.6797
308.746	54.4266
315.093	29.9929
321.433	93.399
327.768	181.353
334.099	125.932
340.423	89.3435
346.743	204.475
353.058	220.472
359.367	96.0286
365.671	72.3682
371.971	92.8847
378.265	34.4849
384.553	61.5554
390.837	92.6779
397.116	75.2317
403.389	27.7769
409.657	5.50069
415.92	68.9791
422.178	47.3567
428.431	20.4638
434.678	5.60678
440.921	10.5219
447.158	-0.618347
453.391	30.3321
459.618	31.3446
465.84	28.8147
472.057	19.8446
478.27	34.3045
484.477	40.3423
490.679	64.0532
496.876	98.0135
503.068	71.3965
509.255	55.0111
515.436	29.2916
521.613	26.0379
527.785	7.85196
533.952	17.8331
540.113	24.9934
546.27	20.6816
552.423	39.746
558.568	34.1525
564.711	25.3966
570.848	16.4764
576.979	18.6878
583.107	53.6139
589.228	111.795
595.345	70.3429
601.458	48.8011
607.565	99.3218
613.667	70.6324
619.764	40.0845
625.856	18.8213
631.944	25.4669
638.026	44.0524
644.104	49.1015
650.177	26.829
656.244	64.4963
662.308	98.1671
668.365	104.642
674.418	114.356
680.467	113.943
686.511	48.4003
692.549	25.8877
698.582	5.18437
704.611	1.24863
710.635	5.65285
716.655	-2.47307
722.669	18.537
728.679	13.1009
734.683	8.5477
740.683	4.93785
746.678	18.1714
752.669	13.7448
758.654	28.0865
764.635	44.6518
770.611	83.9309
776.582	176.961
782.549	151.561
788.511	81.5706
794.466	43.3815
800.419	24.815
806.366	15.5585
812.309	27.8897
818.247	8.13976
824.18	12.7825
830.108	8.08157
836.033	7.41133
841.952	6.04356
847.865	8.45924
853.776	3.43776
859.681	1.25958
865.58	27.4184
871.476	17.6878
877.366	10.5834
883.253	7.17215
889.134	11.246
895.012	9.5446
900.883	1.05527
906.751	-2.76571
912.614	5.64967
918.473	17.8649
924.326	11.4671
930.174	9.97096
936.019	13.3176
941.859	20.7081
947.693	20.6166
953.525	31.0016
959.35	33.7115
965.171	28.639
970.988	35.9167
976.801	36.2981
982.608	35.4617
988.411	45.0659
994.209	20.1871
1000	15.4669
1005.79	12.7453
1011.58	19.7337
1017.36	24.931
1023.13	32.1229
1028.9	17.4588
1034.67	30.6248
1040.43	48.7421
1046.19	86.3088
1051.94	188.859
1057.69	180.964
1063.44	94.0587
1069.17	56.3956
1074.91	53.7033
1080.64	71.3004
1086.37	136.334
1092.09	186.837
1097.8	154.993
1103.52	142.573
1109.22	222.366
1114.93	196.24
1120.63	146.938
1126.32	150.748
1132.01	162.476
1137.7	117.399
1143.38	89.7617
1149.06	69.7006
1154.73	120.342
1160.4	103.773
1166.06	65.3321
1171.72	62.3311
1177.38	42.6727
1183.03	16.3245
1188.67	23.4035
1194.31	29.6365
1199.95	36.0351
1205.58	27.9544
1211.21	15.949
1216.84	29.6535
1222.46	51.4985
1228.07	40.5682
1233.68	30.4445
1239.29	54.3564
1244.89	55.9753
1250.49	32.1481
1256.08	31.4145
1261.67	29.4877
1267.26	27.5258
1272.84	68.7593
1278.42	39.49
1283.99	14.3682
1289.56	10.41
1295.12	17.5385
1300.68	7.75603
1306.23	9.09369
1311.78	11.6059
1317.33	3.15656
1322.87	2.76347
1328.41	7.47768
1333.94	-1.02175
1339.47	5.66792
1345	15.3466
1350.52	10.6501
1356.04	18.2034
1361.55	17.4634
1367.06	36.1438
1372.56	49.618
1378.06	185.289
1383.56	34.4191
1389.05	18.0914
1394.53	10.0543
1400.02	21.6848
1405.5	7.6073
1410.97	-0.296356
1416.44	3.16886
1421.91	18.054
1427.37	10.1911
1432.83	16.8625
1438.28	7.89716
1443.73	12.4773
1449.17	12.831
1454.62	-0.577415
1460.05	2.71303
1465.48	9.09196
1470.91	1.79396
1476.34	9.21451
1481.76	14.5861
1487.17	8.4398
1492.59	5.4923
1497.99	6.80296
1503.4	10.2648
1508.8	9.54743
1514.19	2.49087
1519.59	6.08038
1524.97	9.71093
1530.36	13.3634
1535.74	18.1411
1541.11	13.1096
1546.48	12.2298
1551.85	11.1645
1557.21	2.38028
1562.57	7.6673
1567.93	10.78
1573.28	16.0325
1578.62	28.878
1583.97	11.6489
1589.3	17.0596
1594.64	20.3729
1599.97	7.55901
1605.3	22.8738
1610.62	6.909
1615.94	27.9275
1621.25	32.7663
1626.56	15.701
1631.87	28.1977
1637.17	10.8713
1642.47	13.1662
1647.76	27.667
1653.05	22.2085
1658.34	25.5395
1663.62	17.7378
1668.9	16.5562
1674.18	17.5805
1679.45	13.0329
1684.71	9.5293
1689.98	12.6565
1695.23	16.9593
1700.49	12.5763
1705.74	4.15907
1710.99	12.0087
1716.23	9.71154
1721.47	5.4556
1726.7	13.365
1731.94	11.2523
1737.16	2.3624
1742.39	10.3407
1747.61	11.5524
1752.82	7.05283
1758.03	9.28262
1763.24	6.92147
1768.44	5.70695
1773.64	11.3079
1778.84	6.75521
1784.03	-7.98283
1789.22	9.15448
1794.41	12.6987
1799.59	4.8527
1804.76	2.72554
1809.94	2.84443
1815.11	6.39135
1820.27	5.33403
1825.43	8.91213
1830.59	0.914162
1835.74	8.01651
1840.89	5.76823
1846.04	8.14939
1851.18	4.67313
1856.32	19.8832
1861.45	7.05209
1866.58	-1.09566
1871.71	9.53786
1876.83	1.28021
1881.95	11.8782
1887.07	2.37656
1892.18	12.8762
1897.29	11.544
1902.39	12.6901
1907.49	17.51
1912.59	12.9535
1917.68	6.03828
1922.77	-11.9126
1927.86	7.2691
1932.94	3.73611
1938.02	8.56901
1943.09	-5.86764
1948.16	9.7287
1953.23	8.43169
1958.29	13.1277
1963.35	16.5988
1968.41	4.36356
1973.46	8.95023
1978.51	12.329
1983.55	6.07603
1988.59	8.26299
1993.63	11.6673
1998.66	0.674133
2003.69	1.73737
2008.72	2.84628
2013.74	12.4165
2018.76	8.73076
2023.77	8.67481
2028.78	7.47603
2033.79	3.91562
2038.79	11.2647
2043.79	16.2301
2048.79	4.20179
2053.78	1.82671
2058.77	-1.74184
2063.76	11.8372
2068.74	9.52379
2073.72	5.95795
2078.69	13.4521
2083.66	-3.74335
2088.63	17.2788
2093.59	13.6623
2098.55	7.61838
2103.51	0.323372
2108.46	4.24828
2113.41	8.23165
2118.36	16.0233
2123.3	8.74619
2128.24	7.71884
2133.17	15.5142
2138.11	1.74284
2143.03	9.50715
2147.96	23.6321
2152.88	12.2222
2157.79	-3.08846
2162.71	10.9279
2167.62	5.72958
2172.52	8.23301
2177.43	23.5595
2182.32	-2.1492
2187.22	20.7525
2192.11	-3.64897
2197	5.28528
2201.89	18.1595
2206.77	22.133
2211.64	8.14669
2216.52	13.4945
2221.39	17.6061
2226.26	13.9555
2231.12	12.8879
2235.98	14.4224
2240.84	9.42406
2245.69	17.5163
2250.54	11.1924
2255.39	10.0936
2260.23	5.04781
2265.07	9.19891
2269.9	5.35069
2274.74	4.09463
2279.57	4.12382
2284.39	12.0672
2289.21	15.9861
2294.03	6.5947
2298.84	7.89038
2303.66	9.2466
2308.46	21.3711
2313.27	20.2298
2318.07	12.4351
2322.87	12.6717
2327.66	16.9813
2332.45	9.1737
2337.24	16.2645
2342.02	9.8162
2346.8	14.2971
2351.58	9.19752
2356.35	1.25382
2361.12	6.94405
2365.89	2.97996
2370.65	19.748
2375.41	4.68377
2380.17	13.1397
2384.92	6.24355
2389.67	6.23857
2394.42	21.4854
2399.16	8.84537
2403.9	5.93661
2408.64	30.8879
2413.37	3.16422
2418.1	7.87599
2422.83	23.6568
2427.55	28.0087
2432.27	11.3589
2436.99	7.4085
2441.7	9.11443
2446.41	25.0674
2451.11	-0.30323
2455.82	19.9996
2460.51	8.81371
2465.21	29.2545
2469.9	26.6604
2474.59	0.853622
2479.28	-1.83704
2483.96	12.8979
2488.64	17.4383
2493.32	8.82919
2497.99	4.58778
2502.66	-4.10271
2507.32	15.0815
2511.99	22.5104
2516.65	13.7132
2521.3	9.36224
2525.96	18.3027
2530.61	21.3422
2535.25	5.14627
2539.89	14.1824
2544.53	18.796
2549.17	11.5097
2553.8	11.6639
2558.43	16.2617
2563.06	22.4251
2567.68	9.08952
2572.3	25.9022
2576.92	10.9878
2581.53	15.6607
2586.14	8.09839
2590.75	3.47676
2595.35	6.50114
2599.96	18.7365
2604.55	14.1687
2609.15	4.9841
2613.74	9.4883
2618.33	14.0132
2622.91	10.8883
2627.49	12.3894
2632.07	17.0703
2636.64	9.55495
2641.22	17.5318
2645.78	14.7267
2650.35	10.3172
2654.91	15.1788
2659.47	10.5472
2664.03	12.1081
2668.58	12.0982
2673.13	27.884
2677.67	14.0839
2682.22	6.69185
2686.76	11.8883
2691.29	15.4738
2695.83	14.0377
2700.36	2.88995
2704.89	19.0135
2709.41	2.95418
2713.93	22.3254
2718.45	4.64487
2722.96	17.627
2727.47	11.1021
2731.98	4.49393
2736.49	7.60803
2740.99	4.2218
2745.49	10.6639
2749.98	13.9327
2754.47	19.0388
2758.96	19.0769
2763.45	-5.57855
2767.93	15.8147
2772.41	10.8908
2776.89	17.6051
2781.36	17.8181
2785.84	9.76419
2790.3	19.9968
2794.77	13.5228
2799.23	5.26408
2803.69	-1.40446
2808.14	8.70761
2812.59	3.63086
2817.04	18.777
2821.49	18.7377
2825.93	18.7197
2830.37	5.0864
2834.81	23.7207
2839.24	11.7315
2843.67	21.904
2848.1	8.22295
2852.53	6.5294
2856.95	10.042
2861.37	10.1382
2865.78	18.9425
2870.19	12.2231
2874.6	15.8811
2879.01	21.3296
2883.41	19.8584
2887.81	14.8806
2892.21	11.5942
2896.6	29.5222
2901	6.80002
2905.38	-1.92671
2909.77	17.8331
2914.15	23.2708
2918.53	3.61716
2922.91	5.48093
2927.28	20.0273
2931.65	12.9821
2936.02	14.8855
2940.38	0.355225
2944.74	9.41176
2949.1	7.49039
2953.46	9.22893
2957.81	14.6167
2962.16	1.73041
2966.5	5.33118
2970.85	3.46318
2975.19	29.2022
2979.52	12.6343
2983.86	12.684
2988.19	7.23615
2992.52	7.37308
2996.85	5.66295
3001.17	9.59648
3005.49	17.3452
3009.8	21.3747
3014.12	8.40967
3018.43	21.9509
3022.74	20.375
3027.04	24.4026
3031.34	9.26733
3035.64	16.9671
3039.94	5.49203
3044.23	11.2776
3048.52	28.6048
3052.81	17.0454
3057.09	17.0716
3061.38	32.5753
3065.65	26.8006
3069.93	15.1763
3074.2	21.0381
3078.47	28.8892
3082.74	36.7687
3087	27.1423
3091.27	31.3052
3095.52	19.8202
3099.78	20.1391
3104.03	38.3484
3108.28	30.8732
3112.53	27.3809
3116.77	31.8748
3121.01	36.4378
3125.25	43.1194
3129.49	41.7941
3133.72	40.518
3137.95	49.4634
3142.18	52.2323
3146.4	61.1544
3150.62	59.69
3154.84	51.8137
3159.06	43.8609
3163.27	52.6434
3167.48	61.4164
3171.69	59.711
3175.89	72.6963
3180.09	64.4222
3184.29	73.0032
3188.49	51.8245
3192.68	58.3209
3196.87	54.3084
3201.06	82.5921
3205.24	85.4413
3209.42	62.6053
3213.6	74.1831
3217.78	94.5899
3221.95	88.9357
3226.12	89.8079
3230.29	95.0486
3234.45	84.8585
3238.61	81.1976
3242.77	106.499
3246.93	100.827
3251.08	106.08
3255.23	106.657
3259.38	84.7765
3263.53	92.2963
3267.67	88.9825
3271.81	103.595
3275.95	101.906
3280.08	102.357
3284.21	100.512
3288.34	123.932
3292.47	101.355
3296.59	80.9736
3300.71	116.069
3304.83	107.28
3308.95	105.42
3313.06	122.089
3317.17	138.861
3321.27	95.1087
3325.38	107.401
3329.48	117.475
3333.58	87.8528
3337.67	126.522
3341.77	131.987
3345.86	127.831
3349.95	97.4041
3354.03	138.323
3358.11	131.837
3362.19	137.297
3366.27	137.941
3370.34	116.98
3374.42	151.2
3378.48	132.401
3382.55	152.129
3386.61	152.547
3390.68	140.825
3394.73	170.27
3398.79	163.528
3402.84	154.234
3406.89	195.899
3410.94	169.484
3414.98	240.395
3419.03	455.191
3423.06	750.698
3427.1	422.085
3431.14	246.929
3435.17	191.315
3439.2	177.3
3443.22	148.565
3447.25	159.263
3451.27	162.641
3455.28	171.117
3459.3	172.372
3463.31	153.747
3467.32	157.501
3471.33	153.69
3475.34	179.813
3479.34	175.948
3483.34	172.028
3487.33	178.195
3491.33	232.711
3495.32	259.359
3499.31	306.452
3503.3	394.544
3507.28	328.838
3511.26	298.577
3515.24	229.65
3519.22	186.323
3523.19	160.95
3527.16	127.891
3531.13	107.644
3535.1	100.538
3539.06	122.02
3543.02	96.8522
3546.98	102.65
3550.93	97.9605
3554.89	85.2268
3558.84	77.8553
3562.78	83.5785
3566.73	84.1943
3570.67	84.9323
3574.61	69.9208
3578.55	91.7428
3582.48	63.6785
3586.41	59.2699
3590.35	54.8199
3594.27	52.9969
3598.2	53.8195
3602.12	41.2051
3606.04	60.6703
3609.95	47.9167
3613.87	37.7999
3617.78	49.1812
3621.69	33.4876
3625.6	33.8319
3629.5	17.9268
3633.4	29.0172
3637.3	37.4962
3641.2	27.157
3645.09	22.3081
3648.98	33.6773
3652.87	17.7562
3656.76	18.1374
3660.64	23.9655
3664.53	21.5915
3668.4	11.067
3672.28	14.189
3676.16	6.44994
3680.03	1.5065
3683.9	21.3877
3687.76	11.0839
3691.63	0.732864
3695.49	1.36874
3699.35	10.3853
3703.2	-0.099884
3707.06	-21.7979
3710.91	-4.35149
3714.76	-3.71381
3718.6	-14.4089
3722.45	3.06111
3726.29	12.0707
3730.13	-10.0646
3733.97	1.8196
3737.8	-3.32721
3741.63	-14.221
3745.46	-5.18779
3749.29	-7.5939
3753.11	9.97514
3756.93	-6.83005
3760.75	4.95648
3764.57	5.27875
3768.39	2.75323
3772.2	-5.46687
3776.01	9.28406
3779.81	-1.77443
3783.62	-7.04298
3787.42	2.10556
3791.22	-6.07507
3795.02	0.240387
3798.81	0.829163
3802.61	1.43958
3806.4	2.08215
3810.18	8.56546
3813.97	-2.50197
3817.75	6.8889
3821.53	1.6246
3825.31	-12.5164
3829.09	-3.13367
3832.86	3.37411
3836.63	6.93402
3840.4	19.3619
3844.17	8.16815
3847.93	-3.22844
3851.69	-11.6849
3855.45	-11.2604
3859.21	-7.91092
3862.96	1.43427
3866.71	11.0168
3870.46	-0.148743
3874.21	-8.62527
3877.95	0.845245
3881.69	-1.62064
3885.44	7.91945
3889.17	5.5287
3892.91	0.186981
3896.64	6.94377
3900.37	-13.4019
3904.1	2.37044
3907.82	18.1908
3911.55	12.9363
3915.27	-7.44286
3918.99	-3.55414
3922.7	3.45981
3926.42	-10.8548
3930.13	17.5452
3933.84	6.20364
3937.54	-2.12462
3941.25	26.4376
3944.95	-0.21608
3948.65	13.0989
3952.35	14.0741
3956.04	-0.414185
3959.73	3.60898
3963.42	1.44122
3967.11	20.9526
3970.8	15.6641
3974.48	10.4196
3978.16	8.29024
3981.84	15.45
3985.52	4.03259
3989.19	17.4592
3992.86	12.3677
3996.53	22.8784
3998.37	-1.33235