File: Data/3-Raman/processed/bu19w-e-ff11-fi10-s2_150 (500nm)_633nm_edge_100%_x100_vis_h50um_60sx2_01_0.txt
#Acq. time (s)=	60
#Accumulations=	2
#Range (cm-¹)=	100...4000
#Windows=	1
#Auto scanning=	Off
#Autofocus=	Off
#Macrospot=	Off
#AutoExposure=	Off
#Spike filter=	Multiple accum.
#Delay time (s)=	2
#Binning=	1
#Readout mode=	Signal
#DeNoise=	Off
#ICS correction=	On
#Dark correction=	Off
#Inst. Process=	Off
#Detector Gain=	Best Dynamic
#Detector ADC=	50 kHz HS
#Detector temperature (°C)=	-60.09
#Instrument=	LabRAM HR Evol
#Detector=	SIN-EM FIVIS
#Objective=	x100_VIS
#Grating=	150 (500nm)
#ND Filter=	100%
#Laser=	633nm_Edge
#Hole=	49.98
#Temperature=	0
#Range=	Visible
#StageXY=	75x50mm Scan+
#StageZ=	Z motor
#X (µm)=	0
#Y (µm)=	0
#Z (µm)=	-266.9
#Full time(mm:ss)=	2:04
#Project=	21_11_04
#Sample=	BU19w
#Site=
#Title=	BU19w-E-FF11-FI10-S2_150 (500nm)_633nm_Edge_100%_x100_VIS_H50um_60sX2
#Remark=
#Date=	04.11.2021 12:00
#Acquired=	04.11.2021 12:00:45
#Base:Fit=	16.12.2021 17:39:50
#Base:Edit=	16.12.2021 17:53:23
#Base:Edit=	16.12.2021 17:53:24
#Base:Edit=	16.12.2021 17:53:24
#Base:Edit=	16.12.2021 17:53:26
#Base:Edit=	16.12.2021 17:53:26
#Base:Edit=	16.12.2021 17:53:27
#Base:Sub=	16.12.2021 17:53:29
102.881	255.952
109.397	229.459
115.908	189.998
122.414	172.762
128.914	145.349
135.409	152.618
141.898	175.418
148.383	193.854
154.861	178.248
161.335	230.049
167.801	297.504
174.264	166.592
180.721	84.5964
187.173	34.3072
193.62	36.7945
200.061	13.8346
206.496	-0.0188293
212.926	11.9992
219.352	12.7433
225.772	65.9643
232.185	215.089
238.595	431.675
244.999	272.14
251.397	113.886
257.791	90.6112
264.178	112.119
270.561	120.499
276.939	114.799
283.31	134.689
289.678	141.25
296.039	84.3082
302.396	47.3859
308.746	72.9215
315.093	139.092
321.433	372.32
327.768	709.328
334.099	521.908
340.423	234.572
346.743	158.513
353.058	140.877
359.367	178.695
365.671	193.825
371.971	131.91
378.265	62.5912
384.553	26.2965
390.837	14.7073
397.116	14.5565
403.389	30.5809
409.657	17.348
415.92	38.8717
422.178	63.194
428.431	83.1581
434.678	133.782
440.921	171.877
447.158	139.296
453.391	191
459.618	226.766
465.84	176.126
472.057	108.052
478.27	59.8034
484.477	55.2951
490.679	69.3907
496.876	64.8397
503.068	85.4651
509.255	114.5
515.436	153.882
521.613	165.457
527.785	186.577
533.952	175.102
540.113	165.387
546.27	132.688
552.423	102.406
558.568	80.4276
564.711	62.7695
570.848	62.8168
576.979	68.2775
583.107	59.6807
589.228	86.6928
595.345	116.636
601.458	160.878
607.565	153.28
613.667	183.192
619.764	180.656
625.856	148.102
631.944	113.975
638.026	111.353
644.104	86.6421
650.177	91.1029
656.244	101.873
662.308	81.6452
668.365	60.6115
674.418	39.9881
680.467	14.7887
686.511	19.5311
692.549	13.2045
698.582	1.23724
704.611	11.7009
710.635	12.6735
716.655	0.175667
722.669	10.2316
728.679	-1.43964
734.683	-0.0351181
740.683	4.15028
746.678	18.606
752.669	7.91982
758.654	8.5207
764.635	14.0385
770.611	3.75462
776.582	4.65948
782.549	15.7979
788.511	6.12331
794.466	5.7738
800.419	2.47241
806.366	12.2542
812.309	4.06551
818.247	7.07329
824.18	22.193
830.108	20.4345
836.033	18.9422
841.952	24.2163
847.865	29.537
853.776	28.3642
859.681	34.7569
865.58	44.9672
871.476	71.2772
877.366	87.0275
883.253	87.4972
889.134	98.2484
895.012	103.174
900.883	100.254
906.751	93.4177
912.614	91.2751
918.473	70.4564
924.326	94.0861
930.174	97.3256
936.019	113.015
941.859	150.9
947.693	187.254
953.525	239.128
959.35	288.272
965.171	314.372
970.988	330.713
976.801	418.566
982.608	589.944
988.411	710.679
994.209	655.885
1000	494.559
1005.79	375.931
1011.58	373.372
1017.36	396.939
1023.13	426.529
1028.9	415.55
1034.67	307.65
1040.43	260.943
1046.19	234.248
1051.94	218.786
1057.69	194.301
1063.44	152.945
1069.17	143.318
1074.91	150.19
1080.64	181.179
1086.37	238.253
1092.09	314.734
1097.8	428.84
1103.52	486.787
1109.22	400.147
1114.93	287.916
1120.63	252.348
1126.32	223.069
1132.01	235.785
1137.7	244.624
1143.38	309.467
1149.06	392.888
1154.73	502.7
1160.4	451.359
1166.06	264.815
1171.72	149.562
1177.38	121.789
1183.03	89.3395
1188.67	77.7094
1194.31	56.4678
1199.95	47.0871
1205.58	28.0562
1211.21	32.6177
1216.84	16.4984
1222.46	16.1955
1228.07	17.8861
1233.68	25.5384
1239.29	6.95664
1244.89	9.32107
1250.49	9.54297
1256.08	13.7183
1261.67	10.6793
1267.26	13.6633
1272.84	10.5456
1278.42	10.4068
1283.99	11.2814
1289.56	10.2138
1295.12	-0.770241
1300.68	10.3055
1306.23	8.50308
1311.78	10.8569
1317.33	5.25828
1322.87	2.68604
1328.41	5.20169
1333.94	11.7869
1339.47	11.212
1345	2.33478
1350.52	5.67171
1356.04	9.99881
1361.55	5.01086
1367.06	0.959641
1372.56	10.2209
1378.06	12.2832
1383.56	13.3027
1389.05	10.211
1394.53	-8.20675
1400.02	3.26697
1405.5	1.3856
1410.97	10.8689
1416.44	4.92673
1421.91	3.1129
1427.37	1.30854
1432.83	14.0703
1438.28	6.01076
1443.73	12.5494
1449.17	1.24588
1454.62	10.7996
1460.05	5.58521
1465.48	6.60983
1470.91	6.55852
1476.34	6.52848
1481.76	3.39266
1487.17	5.537
1492.59	2.47492
1497.99	11.0445
1503.4	11.2309
1508.8	12.516
1514.19	3.22448
1519.59	13.0874
1524.97	14.4819
1530.36	5.15559
1535.74	20.5488
1541.11	5.69
1546.48	14.4262
1551.85	2.44884
1557.21	18.4344
1562.57	11.7457
1567.93	14.7659
1573.28	5.92595
1578.62	6.8441
1583.97	13.2021
1589.3	18.5172
1594.64	10.9537
1599.97	8.81966
1605.3	21.87
1610.62	18.8053
1615.94	13.6416
1621.25	18.3111
1626.56	20.8112
1631.87	14.5083
1637.17	19.1044
1642.47	19.0997
1647.76	15.8017
1653.05	19.0929
1658.34	22.3242
1663.62	3.33567
1668.9	23.1288
1674.18	32.9299
1679.45	18.3044
1684.71	12.4873
1689.98	21.0542
1695.23	18.617
1700.49	17.4582
1705.74	11.1756
1710.99	11.1232
1716.23	8.72449
1721.47	25.6158
1726.7	11.0359
1731.94	3.19411
1737.16	21.1874
1742.39	9.92541
1747.61	14.4155
1752.82	10.9421
1758.03	16.463
1763.24	15.1291
1768.44	9.27853
1773.64	5.70347
1778.84	-5.77552
1784.03	8.90284
1789.22	10.0154
1794.41	20.2928
1799.59	16.9251
1804.76	13.5647
1809.94	8.98956
1815.11	12.4298
1820.27	10.1097
1825.43	4.31506
1830.59	14.7509
1835.74	8.96704
1840.89	14.7567
1846.04	15.8609
1851.18	15.7804
1856.32	-0.744209
1861.45	12.072
1866.58	9.68417
1871.71	6.07265
1876.83	14.191
1881.95	14.0446
1887.07	11.5033
1892.18	8.86515
1897.29	2.66634
1902.39	2.48229
1907.49	5.95863
1912.59	0.0422363
1917.68	7.26402
1922.77	14.2566
1927.86	8.21395
1932.94	3.34017
1938.02	6.82629
1943.09	15.0919
1948.16	18.5219
1953.23	12.2607
1958.29	-1.27084
1963.35	21.328
1968.41	11.3458
1973.46	16.974
1978.51	4.53819
1983.55	7.7524
1988.59	10.9778
1993.63	8.20569
1998.66	7.86663
2003.69	9.96799
2008.72	10.916
2013.74	8.28706
2018.76	16.4789
2023.77	16.2609
2028.78	16.1121
2033.79	14.82
2038.79	17.1757
2043.79	19.5571
2048.79	20.7561
2053.78	1.17109
2058.77	14.535
2063.76	10.8383
2068.74	13.2604
2073.72	2.15137
2078.69	18.0893
2083.66	15.5379
2088.63	20.3372
2093.59	20.2625
2098.55	16.5403
2103.51	27.7535
2108.46	22.8461
2113.41	30.4658
2118.36	18.0736
2123.3	16.924
2128.24	24.5828
2133.17	20.8524
2138.11	18.3321
2143.03	20.864
2147.96	23.3589
2152.88	19.4121
2157.79	17.9628
2162.71	17.7378
2167.62	16.1737
2172.52	28.7145
2177.43	13.133
2182.32	21.7817
2187.22	7.34695
2192.11	13.4665
2197	17.084
2201.89	18.2279
2206.77	16.8672
2211.64	19.4237
2216.52	16.8658
2221.39	15.6254
2226.26	16.9759
2231.12	4.02528
2235.98	-2.47086
2240.84	9.29976
2245.69	11.9657
2250.54	21.2128
2255.39	14.6852
2260.23	5.50719
2265.07	13.4437
2269.9	20.0187
2274.74	19.9126
2279.57	3.80345
2284.39	3.55524
2289.21	8.58699
2294.03	5.63174
2298.84	5.38457
2303.66	11.8657
2308.46	10.4516
2313.27	15.7907
2318.07	10.4886
2322.87	10.5431
2327.66	7.93384
2332.45	6.69049
2337.24	13.6091
2342.02	12.4334
2346.8	12.6745
2351.58	7.41492
2356.35	6.17635
2361.12	17.2132
2365.89	3.43231
2370.65	11.7261
2375.41	4.78651
2380.17	6.11986
2384.92	-0.97467
2389.67	1.60056
2394.42	22.2086
2399.16	10.7493
2403.9	10.4118
2408.64	1.75157
2413.37	15.6337
2418.1	14.6945
2422.83	3.65543
2427.55	4.98892
2432.27	13.537
2436.99	0.961624
2441.7	16.7115
2446.41	8.34282
2451.11	8.50198
2455.82	12.9397
2460.51	14.534
2465.21	14.69
2469.9	3.25693
2474.59	9.12268
2479.28	7.77814
2483.96	9.30331
2488.64	0.569504
2493.32	13.7158
2497.99	18.1404
2502.66	-0.933731
2507.32	18.1171
2511.99	1.85236
2516.65	12.0463
2521.3	14.9384
2525.96	14.882
2530.61	2.97557
2535.25	5.90968
2539.89	19.2912
2544.53	20.8252
2549.17	13.4393
2553.8	4.51807
2558.43	10.4918
2563.06	0.0209045
2567.68	13.6476
2572.3	10.7644
2576.92	18.4339
2581.53	13.9315
2586.14	15.3731
2590.75	12.1578
2595.35	13.5635
2599.96	28.766
2604.55	14.9555
2609.15	27.0626
2613.74	11.5979
2618.33	19.0835
2622.91	18.928
2627.49	15.7487
2632.07	37.2694
2636.64	23.6028
2641.22	17.6974
2645.78	22.6292
2650.35	24.4472
2654.91	30.8815
2659.47	18.4192
2664.03	16.8077
2668.58	23.016
2673.13	30.9465
2677.67	32.931
2682.22	17.7797
2686.76	26.2611
2691.29	26.7584
2695.83	15.7464
2700.36	27.0559
2704.89	36.7875
2709.41	30.4135
2713.93	27.2334
2718.45	12.8039
2722.96	27.421
2727.47	25.7641
2731.98	25.6422
2736.49	14.1243
2740.99	26.9902
2745.49	44.861
2749.98	4.15616
2754.47	24.0186
2758.96	24.0942
2763.45	22.4535
2767.93	37.3608
2772.41	14.3822
2776.89	4.64037
2781.36	26.4433
2785.84	28.492
2790.3	22.1957
2794.77	12.4738
2799.23	12.6866
2803.69	29.6619
2808.14	19.6796
2812.59	26.511
2817.04	16.3834
2821.49	21.4877
2825.93	16.4579
2830.37	11.3912
2834.81	14.7905
2839.24	7.97656
2843.67	16.5176
2848.1	14.889
2852.53	4.7493
2856.95	8.37996
2861.37	25.8207
2865.78	10.6356
2870.19	7.50735
2874.6	11.3044
2879.01	34.3361
2883.41	19.0847
2887.81	37.111
2892.21	21.7412
2896.6	18.6696
2901	15.6204
2905.38	12.4397
2909.77	18.1328
2914.15	12.9921
2918.53	16.7941
2922.91	18.8611
2927.28	15.5955
2931.65	8.72769
2936.02	18.0522
2940.38	27.3102
2944.74	23.8418
2949.1	27.5629
2953.46	31.317
2957.81	18.6208
2962.16	0.41629
2966.5	18.8565
2970.85	30.0524
2975.19	17.3852
2979.52	21.2644
2983.86	25.2297
2988.19	42.2559
2992.52	46.4286
2996.85	32.0184
3001.17	41.8794
3005.49	42.4836
3009.8	43.0813
3014.12	39.864
3018.43	36.7301
3022.74	43.068
3027.04	41.6884
3031.34	47.8549
3035.64	44.3701
3039.94	44.6865
3044.23	52.6985
3048.52	56.8397
3052.81	62.9144
3057.09	70.9859
3061.38	67.4528
3065.65	67.7895
3069.93	75.8989
3074.2	91.8366
3078.47	63.0079
3082.74	108.31
3087	91.2646
3091.27	91.9402
3095.52	104.557
3099.78	95.551
3104.03	118.273
3108.28	113.38
3112.53	112.511
3116.77	109.61
3121.01	136.946
3125.25	154.485
3129.49	133.667
3133.72	139.291
3137.95	142.872
3142.18	148.427
3146.4	155.974
3150.62	163.472
3154.84	154.114
3159.06	176
3163.27	154.016
3167.48	165.44
3171.69	166.403
3175.89	182.018
3180.09	182.65
3184.29	181.047
3188.49	200.523
3192.68	203.245
3196.87	210.421
3201.06	181.835
3205.24	187.469
3209.42	184.702
3213.6	214.365
3217.78	203.129
3221.95	191.664
3226.12	180.117
3230.29	196.978
3234.45	187.452
3238.61	164.532
3242.77	141.593
3246.93	169.812
3251.08	173.332
3255.23	163.121
3259.38	146.152
3263.53	158.665
3267.67	155.98
3271.81	164.302
3275.95	137.892
3280.08	138.656
3284.21	150.884
3288.34	135.566
3292.47	143.175
3296.59	136.933
3300.71	126.143
3304.83	150.021
3308.95	153.105
3313.06	128.236
3317.17	142.907
3321.27	134.381
3325.38	135.292
3329.48	131.586
3333.58	149.313
3337.67	141.18
3341.77	146.89
3345.86	107.368
3349.95	148.409
3354.03	141.982
3358.11	152.4
3362.19	129.392
3366.27	156.568
3370.34	138.229
3374.42	141.376
3378.48	158.879
3382.55	161.911
3386.61	169.746
3390.68	148.518
3394.73	158.745
3398.79	152.132
3402.84	145.393
3406.89	131.277
3410.94	126.831
3414.98	161.314
3419.03	169.057
3423.06	171.893
3427.1	157.705
3431.14	143.599
3435.17	141.771
3439.2	142.482
3443.22	135.882
3447.25	131.883
3451.27	155.03
3455.28	146.258
3459.3	140.075
3463.31	146.343
3467.32	152.657
3471.33	123.82
3475.34	112.2
3479.34	128.381
3483.34	121.85
3487.33	97.4759
3491.33	126.373
3495.32	134.938
3499.31	112.76
3503.3	108.313
3507.28	129.411
3511.26	116.965
3515.24	122.428
3519.22	91.8872
3523.19	94.7433
3527.16	97.6565
3531.13	116.007
3535.1	75.353
3539.06	109.689
3543.02	97.4277
3546.98	98.0003
3550.93	49.0752
3554.89	85.6707
3558.84	86.0525
3562.78	89.1212
3566.73	89.6847
3570.67	100.838
3574.61	112.015
3578.55	78.6608
3582.48	108.491
3586.41	101.492
3590.35	89.123
3594.27	97.9485
3598.2	69.4589
3602.12	72.826
3606.04	76.1715
3609.95	74.0779
3613.87	53.1235
3617.78	40.127
3621.69	48.5911
3625.6	46.0907
3629.5	57.0827
3633.4	27.4338
3637.3	27.6206
3641.2	44.2197
3645.09	33.8041
3648.98	20.5247
3652.87	31.6454
3656.76	23.6693
3660.64	48.4082
3664.53	32.1963
3668.4	26.9474
3672.28	18.9306
3676.16	16.4728
3680.03	30.5638
3683.9	36.5486
3687.76	17.8042
3691.63	10.0349
3695.49	7.70633
3699.35	30.4378
3703.2	0.25943
3707.06	9.11368
3710.91	18.0086
3714.76	12.8527
3718.6	4.77742
3722.45	2.27664
3726.29	28.0126
3730.13	11.3243
3733.97	0.285843
3737.8	14.7988
3741.63	12.2288
3745.46	9.62837
3749.29	24.1261
3753.11	4.26506
3756.93	18.6735
3760.75	13.0037
3764.57	15.9113
3768.39	15.9763
3772.2	13.2291
3776.01	19.1012
3779.81	10.6559
3783.62	8.01964
3787.42	14.0433
3791.22	5.61258
3795.02	14.5831
3798.81	3.35504
3802.61	18.2494
3806.4	15.7786
3810.18	1.62883
3813.97	22.4733
3817.75	-3.4825
3821.53	11.5457
3825.31	-2.81749
3829.09	-11.3223
3832.86	12.6509
3836.63	16.0061
3840.4	-1.37825
3844.17	-12.8189
3847.93	17.1029
3851.69	-15.3309
3855.45	8.64607
3859.21	11.7699
3862.96	11.9881
3866.71	6.52457
3870.46	4.15842
3874.21	13.4227
3877.95	-13.1348
3881.69	32.0831
3885.44	-0.406799
3889.17	18.0352
3892.91	-2.40819
3896.64	7.25935
3900.37	-13.1718
3904.1	17.5995
3907.82	24.319
3911.55	3.90829
3915.27	4.68933
3918.99	5.56355
3922.7	12.6202
3926.42	7.507
3930.13	14.5927
3933.84	24.7222
3937.54	-14.1798
3941.25	-0.910461
3944.95	9.41904
3948.65	1.29393
3952.35	5.47293
3956.04	12.7653
3959.73	23.1514
3963.42	5.68896
3967.11	19.1966
3970.8	7.91566
3974.48	-3.29874
3978.16	1.02759
3981.84	17.7651
3985.52	19.0514
3989.19	20.3991
3992.86	15.6719
3996.53	1.7511
3998.37	11.9081