File: Data/3-Raman/processed/bu19w-e-ff11b-fi04-v_1800 (450-850nm)_532nm_edge_100%_x100_vis_h50um_30sx2_01.txt
#Acq. time (s)=	30
#Accumulations=	2
#Range (cm-¹)=	1200...2365
#Windows=	3
#Auto scanning=	Off
#Autofocus=	Off
#Macrospot=	Off
#AutoExposure=	Off
#Spike filter=	Multiple accum.
#Delay time (s)=	2
#Binning=	1
#Readout mode=	Signal
#DeNoise=	Off
#ICS correction=	On
#Dark correction=	Off
#Inst. Process=	Off
#Detector Gain=	Best Dynamic
#Detector ADC=	50 kHz HS
#Detector temperature (°C)=	-60.09
#Instrument=	LabRAM HR Evol
#Detector=	SIN-EM FIVIS
#Objective=	x100_VIS
#Grating=	1800 (450-850nm)
#ND Filter=	100%
#Laser=	532nm_Edge
#Hole=	49.98
#Temperature=	0
#Range=	Visible
#StageXY=	75x50mm Scan+
#StageZ=	Z motor
#X (µm)=	0
#Y (µm)=	0
#Z (µm)=	-244.7
#Full time(mm:ss)=	3:22
#Project=	21_11_04
#Sample=	BU19w
#Site=
#Title=	BU19w-E-FF11b-FI04-V_1800 (450-850nm)_532nm_Edge_100%_x100_VIS_H50um_30sX2
#Remark=
#Date=	04.11.2021 18:47
#Acquired=	04.11.2021 18:47:44
#Base:Fit=	16.12.2021 17:39:50
#Base:Fit=	16.12.2021 17:45:36
#Base:Sub=	16.12.2021 17:45:37
1202.73	0.738043
1203.85	0.420357
1204.96	-2.00216
1206.07	-0.153461
1207.18	-1.50664
1208.29	1.44177
1209.4	3.33284
1210.51	-0.131001
1211.62	1.74678
1212.73	-1.69041
1213.84	-0.838198
1214.95	3.22231
1216.06	-0.187746
1217.17	7.02665
1218.28	-0.60881
1219.39	0.268337
1220.5	-2.0224
1221.61	-2.20567
1222.72	0.765312
1223.82	3.74244
1224.93	1.47635
1226.04	2.40271
1227.15	5.38955
1228.25	2.00812
1229.36	4.11102
1230.47	2.88147
1231.57	2.70267
1232.68	6.79025
1233.79	2.4921
1234.89	-2.8439
1236	-0.827688
1237.1	3.2587
1238.21	1.03201
1239.31	-0.110767
1240.42	-2.2808
1241.52	-1.31023
1242.63	-1.36647
1243.74	-3.52154
1244.84	-0.450304
1245.94	-2.62588
1247.05	-0.586727
1248.15	1.43814
1249.25	-1.74084
1250.36	-0.751535
1251.46	3.36913
1252.56	-0.863697
1253.66	2.24185
1254.77	3.27473
1255.87	4.29914
1256.97	4.2831
1258.07	8.43064
1259.18	5.27848
1260.28	8.39212
1261.38	18.8243
1262.48	35.5208
1263.58	31.4174
1264.68	10.5229
1265.78	7.38182
1266.88	5.32419
1267.98	5.38412
1269.08	7.51097
1270.18	6.44022
1271.28	7.48409
1272.38	7.54279
1273.48	7.60149
1274.58	7.63297
1275.68	5.57914
1276.78	7.73185
1277.87	3.5871
1278.97	17.3136
1280.07	32.0577
1281.17	72.1375
1282.26	281.684
1283.36	638.473
1284.46	145.08
1285.55	30.2002
1286.65	14.4372
1287.75	8.14175
1288.84	9.25056
1289.94	5.10724
1291.04	4.09018
1292.13	-0.0759258
1293.23	4.20094
1294.32	3.21795
1295.42	4.37261
1296.51	-0.83386
1297.61	0.249655
1298.7	2.40365
1299.79	2.4573
1300.89	1.45553
1301.98	0.468035
1303.08	0.515154
1304.17	-3.6551
1305.26	-2.55997
1306.36	-1.46463
1307.45	0.70578
1308.54	-1.34056
1309.63	0.841768
1310.73	0.901739
1311.82	0.974922
1312.91	-0.0230923
1314	-1.02114
1315.09	1.16535
1316.18	-2.99507
1317.28	-1.87198
1318.37	1.36499
1319.46	-0.68639
1320.55	-1.68692
1321.64	3.624
1322.73	1.55797
1323.82	0.570782
1324.91	-0.421373
1325.99	0.638205
1327.08	-1.37402
1328.17	-2.32444
1329.26	-0.144947
1330.35	3.06833
1331.44	0.98217
1332.53	2.06262
1333.62	2.09126
1334.7	-1.01979
1335.79	-0.973589
1336.88	0.127504
1337.96	0.172659
1339.05	3.36909
1340.14	2.39168
1341.23	3.4977
1342.31	2.48983
1343.4	-0.594103
1344.48	4.69386
1345.57	-0.4986
1346.66	0.569714
1347.74	1.65419
1348.83	4.82639
1349.91	0.702536
1351	4.90093
1352.08	0.804369
1353.17	5.09153
1354.25	-1.17891
1355.33	-0.085783
1356.42	2.05086
1357.5	-1.0173
1358.58	1.09885
1359.67	3.21071
1360.75	4.28652
1361.83	5.37282
1362.92	6.46688
1364	11.714
1365.08	12.7821
1366.16	4.52994
1367.24	7.66774
1368.33	25.31
1369.41	8.82513
1370.49	9.89196
1371.57	12.9966
1372.65	7.85906
1373.73	19.234
1374.81	20.3062
1375.89	21.3915
1376.97	22.4261
1378.05	20.4925
1379.13	26.7349
1380.21	34.9273
1381.29	35.9512
1382.37	48.2124
1383.45	47.1645
1384.53	88.2696
1385.61	276.338
1386.68	1430.91
1387.76	248.609
1388.84	62.909
1389.92	33.1022
1390.99	23.9053
1392.07	10.5973
1393.15	15.7444
1394.23	12.7093
1395.3	12.7705
1396.38	11.7804
1397.46	5.66866
1398.53	6.74408
1399.61	12.9405
1400.68	7.88117
1401.76	11.0224
1402.83	10.0974
1403.91	7.0401
1404.99	16.2969
1406.06	19.389
1407.13	32.7656
1408.21	69.7352
1409.28	32.8761
1410.36	12.3754
1411.43	7.26568
1412.5	14.544
1413.58	9.41603
1414.65	10.5216
1415.72	4.40242
1416.8	8.55914
1417.87	3.46398
1418.94	8.63879
1420.01	3.51393
1421.08	5.58447
1422.16	4.62731
1423.23	4.57405
1424.3	6.66548
1425.37	3.6467
1426.44	4.68427
1427.51	5.70372
1428.58	2.66211
1429.65	1.6847
1430.72	0.720388
1431.79	5.87864
1432.86	3.82348
1433.93	4.8562
1435	1.82397
1436.07	2.86957
1437.14	-0.184364
1438.21	2.91858
1439.28	6.0297
1440.35	1.96999
1441.41	4.03962
1442.48	2.02192
1443.55	-0.0162811
1444.62	0.0256805
1445.69	3.12163
1446.75	3.13633
1447.82	3.15435
1448.89	1.13334
1449.95	0.117064
1451.02	0.130856
1452.09	-0.878279
1453.15	2.22321
1454.22	0.190964
1455.28	2.26147
1456.35	0.231035
1457.41	2.28977
1458.48	1.28728
1459.54	-1.76767
1460.61	-1.75698
1461.67	2.34298
1462.74	1.31647
1463.8	-1.72837
1464.86	-0.714098
1465.93	2.34435
1466.99	1.32407
1468.05	3.37627
1469.12	3.38238
1470.18	1.34134
1471.24	3.38056
1472.31	1.35424
1473.37	1.35826
1474.43	1.37349
1475.49	-3.70442
1476.55	-0.648369
1477.62	1.39371
1478.68	-0.640564
1479.74	-3.69257
1480.8	-1.66568
1481.86	-2.65771
1482.92	-1.62167
1483.98	-1.62426
1485.04	1.34587
1486.1	-1.63294
1487.16	2.4278
1488.22	-0.615623
1489.28	0.396433
1490.34	-2.6328
1491.4	-0.607822
1492.46	-3.63089
1493.52	-0.589611
1494.57	2.45465
1495.63	2.43752
1496.69	0.417915
1497.75	-1.59208
1498.81	1.44906
1499.86	-1.5639
1500.92	2.47659
1501.98	-0.546051
1503.03	-0.551891
1504.09	1.477
1505.15	1.47664
1506.2	0.463619
1507.26	0.479858
1508.32	0.486973
1509.37	1.50455
1510.43	-0.509562
1511.48	-1.54128
1512.54	-0.558882
1513.59	1.46226
1514.65	-0.544682
1515.7	-1.56248
1516.76	2.45028
1517.81	0.460569
1518.86	-0.527643
1519.92	1.48565
1520.97	1.49985
1522.02	0.498291
1523.08	2.49219
1524.13	0.475924
1525.18	1.49096
1526.24	1.5173
1527.29	1.51987
1528.34	1.519
1529.39	-0.481834
1530.44	-1.4685
1531.5	1.55024
1532.55	2.57215
1533.6	-4.42522
1534.65	2.59813
1535.7	-0.426821
1536.75	3.55774
1537.8	-1.45064
1538.85	-3.43647
1539.9	0.621218
1540.95	0.632504
1542	-1.38358
1543.05	-0.394537
1544.1	0.608641
1545.15	1.64464
1546.2	2.66137
1547.25	-3.3344
1548.29	-1.32692
1549.34	0.641588
1550.39	1.76381
1551.44	-0.259542
1552.49	4.78573
1553.53	2.75395
1554.58	1.73298
1555.63	-0.261335
1556.68	0.747791
1557.72	2.75029
1558.77	-0.269238
1559.82	3.72315
1560.86	3.72828
1561.91	0.758043
1562.95	4.76456
1564	1.79108
1565.04	1.71121
1566.09	1.78711
1567.13	4.81516
1568.18	1.81151
1569.22	2.80539
1570.27	2.81833
1571.31	-0.178722
1572.36	4.81342
1573.4	2.8145
1574.44	4.84269
1575.49	3.8675
1576.53	3.86035
1577.57	-0.152515
1578.62	1.84427
1579.66	2.85834
1580.7	0.870214
1581.74	4.85212
1582.79	1.86838
1583.83	3.86969
1584.87	1.89118
1585.91	-0.10075
1586.95	6.8638
1587.99	4.88736
1589.03	4.91244
1590.07	1.94251
1591.12	2.95183
1592.16	4.93376
1593.2	4.91299
1594.24	3.91938
1595.28	4.92652
1596.32	0.963156
1597.35	4.9554
1598.39	4.94922
1599.43	6.92739
1600.47	4.93388
1601.51	7.8863
1602.55	8.86334
1603.59	6.88409
1604.63	6.89917
1605.66	4.94343
1606.7	5.95651
1607.74	4.94036
1608.78	5.83755
1609.81	4.74561
1610.85	7.84653
1611.89	6.55745
1612.92	0.795862
1613.96	7.60689
1615	6.52353
1616.03	6.49662
1617.07	7.33535
1618.1	7.28097
1619.14	6.30578
1620.17	4.984
1621.21	8.17978
1622.24	5.7122
1623.28	5.68933
1624.31	5.63245
1625.35	4.07274
1626.38	6.98764
1627.41	6.85171
1628.45	8.79996
1629.48	7.56844
1630.51	8.17636
1631.3	7.17726
1632.34	6.23162
1633.39	7.21223
1634.43	7.23622
1635.48	7.24535
1636.52	6.26209
1637.57	6.26759
1638.61	6.27957
1639.66	7.27908
1640.7	7.30763
1641.75	6.33175
1642.79	7.32908
1643.83	8.32077
1644.88	6.3702
1645.92	5.40104
1646.96	4.42463
1648.01	7.39439
1649.05	7.43558
1650.09	7.46428
1651.13	9.46955
1652.18	7.51608
1653.22	7.52923
1654.26	6.56942
1655.3	7.59944
1656.34	6.64731
1657.38	6.6579
1658.42	4.69065
1659.47	6.66365
1660.51	8.6676
1661.55	6.73241
1662.59	6.7896
1663.63	6.7672
1664.67	8.7956
1665.71	4.87949
1666.75	4.85456
1667.79	4.85574
1668.83	7.86629
1669.86	3.93117
1670.9	2.97969
1671.94	2.01224
1672.98	6.97497
1674.02	4.03821
1675.06	5.06036
1676.1	6.07099
1677.13	3.11791
1678.17	2.13059
1679.21	5.10418
1680.25	6.10107
1681.28	5.12697
1682.32	3.16958
1683.35	2.19857
1684.39	5.17179
1685.43	4.20136
1686.46	4.22982
1687.5	-0.696062
1688.54	4.24716
1689.57	1.28806
1690.6	3.28716
1691.64	1.33801
1692.68	2.3304
1693.71	4.29788
1694.74	6.27757
1695.78	5.3187
1696.81	5.33384
1697.85	3.36031
1698.88	1.40078
1699.92	4.36922
1700.95	2.41398
1701.98	3.39901
1703.01	-0.521475
1704.05	-2.4679
1705.08	1.4794
1706.11	0.503479
1707.14	-0.479332
1708.18	1.47285
1709.21	1.47313
1710.24	4.42985
1711.27	0.540201
1712.3	1.52248
1713.33	-0.448277
1714.36	4.44352
1715.4	-0.415411
1716.43	2.51839
1717.46	2.49819
1718.49	0.54372
1719.52	-4.30821
1720.55	1.54178
1721.58	1.54002
1722.61	1.53667
1723.64	1.54533
1724.66	0.57494
1725.69	1.53774
1726.72	-3.29812
1727.75	-0.376476
1728.78	2.46236
1729.81	-1.36435
1730.83	1.56429
1731.86	0.611731
1732.89	0.613554
1733.92	-0.363089
1734.95	4.44404
1735.97	-1.328
1737	-0.359983
1738.03	-0.357405
1739.05	0.598396
1740.08	2.49971
1741.1	-0.37764
1742.13	1.54473
1743.16	-2.27405
1744.18	-1.3127
1745.21	-1.29783
1746.23	1.56934
1747.26	0.609203
1748.28	-0.333054
1749.31	-0.308386
1750.33	-0.278749
1751.36	1.64344
1752.38	-2.18138
1753.4	0.682404
1754.43	3.54212
1755.45	-0.268238
1756.47	-3.13032
1757.5	-2.17377
1758.52	0.702335
1759.54	1.66762
1760.57	1.67235
1761.59	-1.17805
1762.61	0.741793
1763.63	-3.04605
1764.66	-0.163256
1765.68	-0.14587
1766.7	-1.08821
1767.72	1.77077
1768.74	-1.08989
1769.76	0.80896
1770.78	-0.116703
1771.8	4.66529
1772.82	0.885509
1773.84	-0.999352
1774.86	2.83007
1775.88	2.86197
1776.9	2.86453
1777.92	0.956423
1778.94	-0.952955
1779.96	0.0170231
1780.98	0.0332909
1782	0.0557938
1783.02	0.0768452
1784.04	-1.80663
1785.05	0.116444
1786.07	-0.829531
1787.09	1.10801
1788.11	-0.748762
1789.12	1.19689
1790.14	-0.701574
1791.16	-0.708652
1792.18	-0.699366
1793.19	1.23086
1794.21	-0.674667
1795.23	1.28703
1796.24	-0.610241
1797.26	1.33423
1798.27	1.34945
1799.29	-0.573435
1800.3	0.38604
1801.32	1.35385
1802.33	-1.51161
1803.35	-0.529463
1804.36	0.450792
1805.38	-0.48642
1806.39	2.42338
1807.41	-1.42242
1808.42	1.47901
1809.43	-2.36653
1810.45	0.532606
1811.46	-2.35314
1812.47	0.554922
1813.49	0.572628
1814.5	-2.29805
1815.51	0.61418
1816.53	0.623682
1817.54	-1.31882
1818.55	0.630133
1819.56	-0.322746
1820.57	-0.308292
1821.58	-1.25985
1822.6	3.59122
1823.61	-1.2474
1824.62	-1.23577
1825.63	-0.258083
1826.64	-1.21909
1827.65	-2.17697
1828.66	-4.11498
1829.67	2.66506
1830.68	5.5715
1831.69	0.745312
1832.7	0.760096
1833.71	1.73823
1834.72	2.67756
1835.73	0.730139
1836.74	1.74323
1837.75	-1.21014
1838.75	-2.13218
1839.76	2.71249
1840.77	-1.19905
1841.78	-0.257496
1842.79	0.706608
1843.79	-3.15017
1844.8	0.711336
1845.81	-0.228603
1846.81	-0.273455
1847.82	1.66324
1848.83	-1.23941
1849.83	-1.25816
1850.84	-2.23283
1851.85	0.644932
1852.85	-0.314434
1853.86	-0.327728
1854.86	0.617146
1855.87	1.56348
1856.87	-1.31015
1857.88	-1.3182
1858.88	-3.24513
1859.89	2.48988
1860.89	-0.36458
1861.9	-2.27547
1862.9	0.579132
1863.9	-1.34468
1864.91	1.50398
1865.91	1.47459
1866.92	2.39469
1867.92	-0.470839
1868.92	1.4314
1869.92	2.37813
1870.93	-1.4256
1871.93	0.466146
1872.93	1.405
1873.93	0.444836
1874.93	-1.47002
1875.94	4.18128
1876.94	-0.575338
1877.94	3.25063
1878.94	0.417377
1879.94	-2.43519
1880.94	0.397333
1881.94	-0.586142
1882.94	-3.36552
1883.94	0.328344
1884.94	-1.54844
1885.94	0.356678
1886.94	-1.54812
1887.94	-2.51059
1888.94	0.293982
1889.94	1.23825
1890.94	-0.641968
1891.94	-0.645609
1892.94	0.272869
1893.93	-3.50303
1894.93	0.250998
1895.93	0.259058
1896.93	-1.61201
1897.93	1.20663
1898.92	2.12845
1899.92	0.240044
1900.92	-0.692276
1901.91	-1.61917
1902.91	1.19613
1903.91	-0.69046
1904.9	1.18556
1905.9	1.1684
1906.9	0.221653
1907.89	-0.71085
1908.89	-2.58384
1909.88	-0.684422
1910.88	2.15431
1911.87	2.15078
1912.87	1.20711
1913.86	0.281334
1914.86	-0.649706
1915.85	-1.59651
1916.85	1.21931
1917.84	0.273582
1918.84	1.23571
1919.83	0.309435
1920.82	1.26076
1921.82	0.321344
1922.81	-0.634611
1923.8	-0.645088
1924.79	0.296923
1925.79	-0.631809
1926.78	0.329947
1927.77	1.28438
1928.76	4.13504
1929.75	2.25933
1930.75	0.371861
1931.74	2.25937
1932.73	-2.49544
1933.72	-0.576357
1934.71	1.3822
1935.7	-1.47607
1936.69	-2.44079
1937.68	3.25468
1938.67	2.31221
1939.66	0.415285
1940.65	-1.46766
1941.64	1.37467
1942.63	-0.506586
1943.62	1.38785
1944.61	2.36015
1945.6	-0.491375
1946.59	0.468916
1947.58	1.41887
1948.57	-0.4937
1949.55	2.3923
1950.54	-0.452927
1951.53	-0.431313
1952.52	2.45651
1953.5	-1.40315
1954.49	0.481129
1955.48	-0.466393
1956.47	1.47923
1957.45	2.45382
1958.44	-2.34994
1959.43	0.522703
1960.41	-1.41173
1961.4	1.45814
1962.38	-1.41961
1963.37	0.501341
1964.36	-0.457664
1965.34	-0.457981
1966.33	-1.40656
1967.31	0.517794
1968.3	1.4775
1969.28	1.45568
1970.26	-0.480799
1971.25	2.38688
1972.23	-1.44775
1973.22	0.457508
1974.2	0.450832
1975.18	1.41545
1976.17	-0.497271
1977.15	-1.46089
1978.13	-0.513214
1979.12	-1.47374
1980.1	1.39689
1981.08	0.427586
1982.06	1.37872
1983.05	1.3596
1984.03	0.394638
1985.01	1.33735
1985.99	2.29911
1986.97	-0.569904
1987.95	-1.55063
1988.93	1.25838
1989.91	0.200062
1990.89	1.04702
1991.88	-1.69103
1992.86	0.949347
1993.84	-1.20487
1994.82	1.07812
1995.8	-0.5487
1996.78	-0.547091
1997.76	1.51438
1998.73	0.534632
1999.71	-2.58048
2000.69	-0.723715
2001.67	1.42206
2002.65	-1.05704
2003.63	0.246758
2004.6	1.17462
2005.58	2.5313
2006.56	0.403343
2007.54	1.65213
2008.52	0.145437
2009.49	1.00276
2010.47	0.14933
2011.45	-1.52304
2012.42	1.96652
2013.41	-0.883413
2014.4	1.90327
2015.39	0.974142
2016.38	-3.70446
2017.37	-0.896671
2018.35	-2.79858
2019.34	-2.81586
2020.33	0.927523
2021.32	1.86642
2022.31	-0.0178986
2023.29	0.900539
2024.28	0.880665
2025.27	-1.00835
2026.25	-0.0635204
2027.24	2.78428
2028.23	-2.86176
2029.21	-1.90095
2030.2	-0.0920124
2031.19	-0.0688705
2032.17	-0.0499897
2033.16	-0.0286903
2034.14	-0.0627441
2035.13	-0.979744
2036.11	0.906109
2037.1	2.7813
2038.08	1.8374
2039.07	-1.9103
2040.05	-0.992809
2041.03	-0.0719547
2042.02	0.852497
2043	-1.93842
2043.99	1.81152
2044.97	0.867233
2045.95	-0.942188
2046.94	0.888739
2047.92	-2.85759
2048.9	-0.980335
2049.88	0.910702
2050.87	-0.0207291
2051.85	2.77948
2052.83	0.923946
2053.81	1.88246
2054.79	0.0126648
2055.78	0.940439
2056.76	-2.79939
2057.74	0.016058
2058.72	-0.901447
2059.7	-1.83433
2060.68	2.84797
2061.66	0.0462132
2062.64	0.994442
2063.62	0.0698509
2064.6	1.0203
2065.58	0.104656
2066.56	-1.76333
2067.54	-0.812265
2068.52	-1.74323
2069.5	-0.818768
2070.48	2.97157
2071.46	3.00136
2072.43	1.11628
2073.41	-2.64705
2074.39	1.13356
2075.37	1.16923
2076.35	2.12056
2077.32	0.216505
2078.3	0.228598
2079.28	2.14011
2080.26	1.20899
2081.23	2.15253
2082.21	-1.62111
2083.19	0.270596
2084.16	-1.61603
2085.14	-1.6121
2086.12	2.18887
2087.09	3.14877
2088.07	-1.57846
2089.04	1.27216
2090.02	-2.50428
2090.99	4.13991
2091.97	2.27156
2092.94	1.34834
2093.92	0.415291
2094.89	0.413715
2095.87	2.30692
2096.84	-0.546896
2097.81	0.398409
2098.79	0.397142
2099.76	2.29767
2100.74	-0.535843
2101.71	-0.529375
2102.68	-0.533165
2103.65	0.415476
2104.63	0.428347
2105.6	-1.456
2106.57	0.453581
2107.54	1.3984
2108.52	-0.514771
2109.49	-2.40248
2110.46	-2.39932
2111.43	2.34743
2112.4	-0.496492
2113.38	-2.38237
2114.35	0.469938
2115.32	2.37028
2116.29	-0.487467
2117.26	-0.4869
2118.23	-1.44782
2119.2	0.436424
2120.17	-0.515388
2121.14	-0.499977
2122.11	4.26202
2123.08	0.476488
2124.05	2.36658
2125.02	-0.506479
2125.98	2.31587
2126.95	0.412365
2127.92	-1.48065
2128.89	2.30129
2129.86	-0.535313
2130.83	1.34909
2131.79	-0.546194
2132.76	3.22179
2133.73	0.396177
2134.7	-1.48904
2135.67	0.390455
2136.63	4.15651
2137.6	2.28003
2138.57	-1.49087
2139.53	0.384007
2140.5	2.26143
2141.46	1.31305
2142.43	-1.50506
2143.4	0.340719
2144.36	0.364563
2145.33	-1.52195
2146.29	3.17477
2147.26	0.348343
2148.22	3.15929
2149.19	0.326599
2150.15	2.1878
2151.12	0.321209
2152.08	2.20417
2153.05	0.31999
2154.01	0.307673
2154.97	1.21528
2155.94	-1.60234
2156.9	1.20223
2157.86	-2.52378
2158.83	-0.656286
2159.79	0.26474
2160.75	0.25577
2161.72	-0.679422
2162.68	2.11714
2163.64	-0.68659
2164.6	0.235909
2165.56	1.17292
2166.53	1.16453
2167.49	-0.715607
2168.45	-0.725107
2169.41	-1.63762
2170.37	0.238398
2171.33	-1.64346
2172.29	1.13013
2173.25	1.13171
2174.21	3.92752
2175.17	0.209108
2176.13	0.205162
2177.09	0.206482
2178.05	2.05994
2179.01	0.200687
2179.97	-0.72628
2180.93	0.200178
2181.89	0.194366
2182.85	1.113
2183.81	2.0251
2184.76	0.176285
2185.72	-1.66653
2186.68	1.13686
2187.64	-0.708641
2188.6	-4.43285
2189.55	2.04398
2190.51	1.12138
2191.47	1.12726
2192.42	3.92019
2193.38	3.01405
2194.34	2.10838
2195.3	1.16929
2196.25	2.07593
2197.21	-2.57087
2198.16	1.15257
2199.12	-0.680124
2200.07	2.14591
2201.03	0.298641
2201.99	-0.704268
2202.94	-0.663778
2203.9	1.24942
2204.85	1.21211
2205.8	1.20234
2206.76	-1.58742
2207.71	3.08085
2208.67	2.1654
2209.62	-2.48781
2210.58	1.2508
2211.53	0.334721
2212.48	-1.52696
2213.44	0.332769
2214.39	-2.44498
2215.34	-0.572001
2216.29	-0.571182
2217.25	0.365023
2218.2	-0.564545
2219.15	-1.4859
2220.1	2.25731
2221.06	-1.48889
2222.01	2.23718
2222.96	-1.4861
2223.91	1.3396
2224.86	-0.511814
2225.81	-2.36668
2226.76	-1.41537
2227.72	-0.473255
2228.67	-1.41273
2229.62	1.41442
2230.57	-0.445408
2231.52	0.512156
2232.47	-0.411463
2233.42	-0.396515
2234.37	0.545422
2235.31	0.533472
2236.26	2.42099
2237.21	-1.32465
2238.16	-0.356583
2239.11	-0.341198
2240.06	1.53338
2241.01	-2.22009
2241.96	-1.26797
2242.9	0.62328
2243.85	1.56529
2244.8	0.646643
2245.75	-0.279696
2246.69	0.680168
2247.64	-0.260828
2248.59	0.684618
2249.53	2.58553
2250.48	-3.10077
2251.43	1.62421
2252.37	-3.08858
2253.32	0.727327
2254.26	0.74161
2255.21	-0.203051
2256.16	-1.13813
2257.1	1.72486
2258.05	1.73452
2258.99	-1.10258
2259.94	0.809418
2260.88	1.7792
2261.83	-2.01755
2262.77	-0.0955315
2263.71	-0.066103
2264.66	-2.90689
2265.6	0.921429
2266.55	-0.0454617
2267.49	1.85409
2268.43	-0.0508499
2269.38	-0.982454
2270.32	0.950354
2271.26	0.967556
2272.2	0.0226936
2273.15	0.988333
2274.09	-0.917337
2275.03	1.00669
2275.97	0.0643101
2276.92	2.00439
2277.86	0.116125
2278.8	0.121443
2279.74	-1.81314
2280.68	2.97408
2281.62	-0.856758
2282.56	0.121078
2283.5	1.11466
2284.44	-3.669
2285.38	-0.774029
2286.32	0.187946
2287.26	1.17668
2288.2	2.14454
2289.14	1.16486
2290.08	1.15638
2291.02	0.213366
2291.96	2.1581
2292.9	2.17941
2293.84	-1.66984
2294.78	-0.711605
2295.72	2.1714
2296.65	0.245293
2297.59	-1.65777
2298.53	-4.53189
2299.47	0.302849
2300.41	-3.54714
2301.34	-0.64146
2302.28	-1.60458
2303.22	3.22425
2304.15	3.2403
2305.09	3.25564
2306.03	-0.597818
2306.97	-2.52782
2307.9	-1.5634
2308.84	3.27869
2309.77	-0.567629
2310.71	-1.53551
2311.64	-1.56143
2312.58	0.36414
2313.51	-2.51061
2314.45	-1.51979
2315.39	1.37606
2316.32	2.32109
2317.25	1.36409
2318.19	-1.53722
2319.12	0.385872
2320.06	2.31712
2320.99	1.36523
2321.92	5.25393
2322.86	1.39311
2323.79	6.23203
2324.72	6.21148
2325.66	11.0184
2326.59	23.5322
2327.52	113.14
2328.46	74.5792
2329.39	19.6228
2330.32	9.02488
2331.25	3.25207
2332.18	1.31763
2333.12	1.30609
2334.05	0.329849
2334.98	0.320478
2335.91	-2.56783
2336.84	-0.651621
2337.77	-1.62096
2338.7	0.296564
2339.63	1.24869
2340.56	2.18795
2341.49	2.15834
2342.42	1.18309
2343.35	1.17409
2344.28	2.12668
2345.21	2.10721
2346.14	-1.74274
2347.07	0.158493
2348	1.11074
2348.93	0.130993
2349.85	1.98972
2350.78	0.0848694
2351.71	1.95229
2352.64	0.94664
2353.57	1.88219
2354.5	-0.0308056
2355.42	-0.05373
2356.35	0.856283
2357.28	1.77541
2358.21	-0.154961
2359.13	2.66796
2360.06	-0.217777
2360.99	-1.20526
2361.91	-0.299419
2362.84	3.44773
2363.77	2.46556
2364.69	-0.409649
2364.92	1.47108