File: Data/3-Raman/processed/bu19w-b-ff1-fi02-v_150 (500nm)_532nm_edge_100%_x100_vis_h50um_15sx2_01.txt
#Acq. time (s)=	15
#Accumulations=	2
#Range (cm-¹)=	100...5000
#Windows=	1
#Auto scanning=	Off
#Autofocus=	Off
#Macrospot=	Off
#AutoExposure=	Off
#Spike filter=	Multiple accum.
#Delay time (s)=	2
#Binning=	1
#Readout mode=	Signal
#DeNoise=	Off
#ICS correction=	On
#Dark correction=	Off
#Inst. Process=	Off
#Detector Gain=	Best Dynamic
#Detector ADC=	50 kHz HS
#Detector temperature (°C)=	-60.09
#Instrument=	LabRAM HR Evol
#Detector=	SIN-EM FIVIS
#Objective=	x100_VIS
#Grating=	150 (500nm)
#ND Filter=	100%
#Laser=	532nm_Edge
#Hole=	49.98
#Temperature=	0
#Range=	Visible
#StageXY=	75x50mm Scan+
#StageZ=	Z motor
#X (µm)=	0
#Y (µm)=	0
#Z (µm)=	-136.1
#Full time(s)=	34
#Project=	21_05_14
#Sample=	BU19w
#Site=
#Title=	BU19w-FF1-FI02-V_150 (500nm)_532nm_Edge_100%_x100_VIS_H50um_15sX2
#Remark=
#Date=	14.05.2021 11:59
#Acquired=	14.05.2021 11:59:42
#Base:Fit=	22.12.2021 12:22:35
#Base:Edit=	22.12.2021 12:23:58
#Base:Sub=	22.12.2021 12:24:00
#Data Range:Extract=	22.12.2021 12:27:19
102.699	10565.2
107.322	8580.23
111.942	6907.09
116.56	5706.43
121.173	4692.02
125.787	3866.83
130.398	3126.84
135.006	2602.09
139.613	2155.68
144.215	1782.67
148.817	1485.11
153.417	1332.2
158.014	1037.77
162.607	839.399
167.2	740.41
171.79	1021.06
176.379	1744.65
180.963	1462.68
185.547	755.019
190.128	473.029
194.705	704.648
199.282	2286.66
203.857	4824.56
208.43	3629.1
212.998	1137.32
217.566	341.925
222.132	102.858
226.693	127.452
231.254	101.504
235.813	80.3871
240.368	0.140625
244.923	83.2855
249.475	207.33
254.023	204.502
258.571	430.087
263.117	717.239
267.658	677.177
272.199	570.564
276.738	344.197
281.273	348.973
285.807	656.354
290.34	1953.7
294.868	3424.36
299.396	3001.94
303.919	1489.21
308.443	774.615
312.964	1035.48
317.481	2024.41
321.998	2109.91
326.51	1115.47
331.023	505.207
335.533	408.307
340.039	517.357
344.544	891.307
349.046	770.682
353.547	463.816
358.045	237.04
362.542	347.223
367.036	364.172
371.527	223.763
376.017	153.275
380.503	109.235
384.99	142.077
389.471	134.713
393.953	189.733
398.43	374.647
402.908	613.396
407.381	712.095
411.854	771.864
416.323	634.277
420.791	433.474
425.256	348.421
429.72	532.499
434.18	773.804
438.64	391.056
443.095	133.218
447.551	58.4227
452.003	84.1991
456.454	90.1969
460.901	212.211
465.348	584.368
469.791	1317.34
474.231	1552.92
478.672	729.996
483.108	229.377
487.544	235.699
491.976	166.566
496.408	181.543
500.836	254.049
505.261	347.906
509.687	426.328
514.108	450.55
518.529	381.192
522.946	289.619
527.361	240.82
531.776	175.106
536.187	192.751
540.595	231.223
545.003	218.63
549.408	248.985
553.812	328.542
558.212	330.18
562.61	329.95
567.007	307.031
571.401	295.291
575.792	356.664
580.184	302.638
584.571	267.169
588.956	187.802
593.341	234.61
597.722	387.08
602.101	910.939
606.48	1343.92
610.854	881.284
615.227	473.552
619.597	444.567
623.967	679.737
628.334	959.784
632.698	822.978
637.06	432.604
641.422	256.93
645.779	115.704
650.135	161.403
654.491	247.855
658.842	225.957
663.192	179.395
667.539	162.144
671.884	159.049
676.23	213.181
680.571	245.359
684.91	289.173
689.247	367.964
693.583	427.006
697.916	360.581
702.247	246.818
706.576	135.64
710.902	117.053
715.229	83.822
719.551	70.9392
723.872	46.2228
728.19	68.1407
732.506	-3.72693
736.82	23.1018
741.134	33.8804
745.444	51.939
749.752	39.2163
754.058	25.2235
758.362	81.8557
762.664	86.88
766.964	112.03
771.264	157.902
775.559	235.707
779.853	356.897
784.144	601.708
788.434	1037.22
792.722	1588.74
797.007	1624.13
801.29	1187.96
805.572	718.369
809.851	429.582
814.13	266.59
818.406	173.8
822.679	149.68
826.95	129.074
831.219	69.9722
835.486	88.9852
839.752	46.1075
844.015	90.0339
848.276	34.537
852.535	96.9194
856.792	72.1906
861.047	49.5134
865.3	36.1825
869.551	31.3131
873.8	79.7476
878.047	42.2837
882.292	48.0269
886.534	59.5237
890.775	78.0709
895.014	38.4331
899.251	53.1722
903.486	2.66785
907.719	39.9218
911.95	56.6531
916.179	62.1569
920.406	4.05554
924.63	48.2437
928.853	33.532
933.074	28.7328
937.293	23.36
941.51	74.4958
945.723	53.5679
949.936	66.2875
954.147	112.174
958.356	113.51
962.563	174.556
966.768	227.113
970.971	218.564
975.172	261.033
979.371	364.327
983.568	441.2
987.761	384.288
991.954	245.155
996.145	196.447
1000.33	143.941
1004.52	95.7788
1008.71	100.017
1012.89	118.52
1017.07	57.0944
1021.25	109.652
1025.43	108.953
1029.6	114.708
1033.77	112.185
1037.95	117.416
1042.11	202.699
1046.28	255.044
1050.45	277.093
1054.61	351.308
1058.77	626.321
1062.93	1089.37
1067.09	1879.11
1071.24	2044.61
1075.4	1422.34
1079.55	798.338
1083.7	550.645
1087.85	537.343
1091.99	578.221
1096.14	793.609
1100.28	1198.83
1104.42	1702.49
1108.55	1890.48
1112.69	1457.77
1116.82	1220.85
1120.96	1306.37
1125.09	1551.12
1129.21	1625.79
1133.34	1379.09
1137.46	1216.76
1141.59	1326.58
1145.71	1467.27
1149.83	1478.57
1153.94	1203.2
1158.06	831.249
1162.17	670.681
1166.28	788.337
1170.39	1049.25
1174.5	1230.73
1178.6	1090.53
1182.7	697.516
1186.8	494.622
1190.9	393.214
1195	286.425
1199.1	232.444
1203.19	230.316
1207.28	228.2
1211.37	292.972
1215.46	294.93
1219.54	179.618
1223.63	247.651
1227.71	209.118
1231.79	260.483
1235.87	356.369
1239.95	428.261
1244.02	443.505
1248.09	508.321
1252.16	632.702
1256.23	769.651
1260.3	771.187
1264.36	1006.36
1268.43	1026.27
1272.49	680.184
1276.55	629.47
1280.6	1002.71
1284.66	5739.76
1288.71	7298.25
1292.76	1916.96
1296.81	656.813
1300.86	448.588
1304.91	413.25
1308.95	350.79
1312.99	330.902
1317.03	313.296
1321.07	323.639
1325.11	233.206
1329.14	269.964
1333.18	290.702
1337.21	248.824
1341.24	276.787
1345.26	276.562
1349.29	294.315
1353.31	291.2
1357.33	339.688
1361.35	337.434
1365.37	360.58
1369.39	482.646
1373.4	674.126
1377.41	631.922
1381.43	741.326
1385.43	2016.25
1389.44	12195.3
1393.45	9712.25
1397.45	1895.14
1401.45	720.679
1405.45	664.459
1409.45	998.898
1413.44	1312.17
1417.44	601.125
1421.43	335.611
1425.42	276.578
1429.41	251.369
1433.39	176.409
1437.38	138.634
1441.36	143.395
1445.34	94.4226
1449.32	90.8065
1453.3	67.0402
1457.27	68.7698
1461.24	104.354
1465.22	64.6841
1469.19	63.6365
1473.15	70.5114
1477.12	65.1664
1481.09	48.9514
1485.05	35.5601
1489.01	29.0381
1492.97	12.9613
1496.93	33.0242
1500.88	27.1309
1504.83	18.7919
1508.79	7.00293
1512.74	55.4358
1516.68	36.1101
1520.63	30.5774
1524.57	-15.5479
1528.52	16.1342
1532.46	104.205
1536.4	66.2712
1540.33	35.2043
1544.27	27.3916
1548.2	40.9182
1552.14	16.545
1556.07	82.8794
1559.99	8.56482
1563.92	24.0875
1567.84	51.015
1571.77	63.337
1575.69	19.6256
1579.61	28.9452
1583.52	19.853
1587.44	50.129
1591.35	26.4694
1595.27	17.2498
1599.18	51.3678
1603.09	40.6074
1606.99	49.2573
1610.9	21.5269
1614.8	-10.6993
1618.7	52.0103
1622.6	28.5455
1626.5	80.1663
1630.39	40.3441
1634.29	49.7069
1638.18	66.8105
1642.07	65.4468
1645.96	58.5874
1649.85	60.5063
1653.73	82.5405
1657.62	37.2024
1661.5	15.6248
1665.38	25.3906
1669.26	31.8799
1673.13	51.3774
1677.01	30.9216
1680.88	17.178
1684.75	36.834
1688.62	32.1912
1692.49	0.36499
1696.35	40.0061
1700.22	55.2554
1704.08	32.8538
1707.94	-5.11035
1711.8	24.228
1715.66	42.207
1719.51	30.8984
1723.37	69.5173
1727.22	29.6084
1731.07	37.658
1734.92	39.134
1738.76	-4.55591
1742.61	39.5173
1746.45	22.8298
1750.29	29.6221
1754.13	67.9368
1757.97	3.06006
1761.81	35.6746
1765.64	49.8157
1769.47	41.1785
1773.31	16.2146
1777.14	9.24707
1780.96	56.0566
1784.79	45.3171
1788.61	107.737
1792.43	34.4722
1796.25	52.0479
1800.07	35.929
1803.89	57.561
1807.71	39.5867
1811.52	21.2278
1815.33	5.93018
1819.14	47.4253
1822.95	68.6863
1826.76	19.6436
1830.56	24.7351
1834.37	41.6284
1838.17	67.5728
1841.97	56.3772
1845.77	31.0642
1849.56	38.2219
1853.36	64.1401
1857.15	32.4397
1860.94	91.6968
1864.73	46.6824
1868.52	5.83643
1872.31	21.0315
1876.09	68.7966
1879.87	40.4475
1883.66	52.2839
1887.43	53.5732
1891.21	54.2852
1894.99	64.0481
1898.76	48.6416
1902.53	43.1443
1906.31	17.6523
1910.08	-1.78101
1913.84	96.3962
1917.61	52.4661
1921.37	59.1765
1925.14	95.8347
1928.9	34.4514
1932.66	1.73071
1936.41	57.4392
1940.17	103.966
1943.92	32.1714
1947.68	62.3552
1951.43	72.9944
1955.18	42.2346
1958.92	54.4949
1962.67	75.958
1966.41	62.4314
1970.16	88.1306
1973.9	52.4458
1977.64	55.709
1981.37	54.9116
1985.11	10.7837
1988.84	59.8296
1992.57	33.7427
1996.31	31.5518
2000.03	11.4761
2003.76	67.6204
2007.49	1.86523
2011.21	83.5725
2014.93	43.3582
2018.65	23.1362
2022.37	-4.31128
2026.09	89.4185
2029.81	46.2695
2033.52	81.2446
2037.23	36.874
2040.94	38.4172
2044.65	29.5696
2048.36	70.6575
2052.07	69.9338
2055.77	54.0288
2059.47	67.4426
2063.17	70.6343
2066.87	31.7471
2070.57	68.4399
2074.27	58.1963
2077.96	75.0225
2081.65	39.8967
2085.34	96.2139
2089.03	39.0947
2092.72	99.2527
2096.41	96.7117
2100.09	48.3835
2103.77	51.7834
2107.46	55.7229
2111.14	-38.1501
2114.81	22.2612
2118.49	45.7341
2122.16	102.651
2125.84	55.4578
2129.51	106.109
2133.18	54.8699
2136.85	51.4871
2140.51	88.2686
2144.18	111.83
2147.84	31.4307
2151.5	35.7251
2155.16	39.22
2158.82	66.6235
2162.48	74.2625
2166.13	114.154
2169.79	26.1772
2173.44	72.1853
2177.09	49.1521
2180.74	73.666
2184.38	42.7109
2188.03	45.5696
2191.67	94.7192
2195.32	80.1133
2198.96	78.4592
2202.6	-8.64404
2206.23	132.87
2209.87	54.6047
2213.5	110.126
2217.14	48.3831
2220.77	131.792
2224.4	116.971
2228.03	74.2896
2231.65	88.9788
2235.28	134.31
2238.9	99.9751
2242.52	52.5171
2246.14	101.551
2249.76	147.275
2253.38	60.9587
2256.99	77.1953
2260.6	52.0957
2264.21	26.8489
2267.82	87.5063
2271.44	106.038
2275.04	60.5522
2278.65	66.915
2282.25	53.3
2285.85	87.3989
2289.45	90.8875
2293.05	67.8125
2296.65	111.139
2300.25	91.832
2303.84	58.7122
2307.43	80.1824
2311.02	61.5483
2314.62	70.0322
2318.2	94.1799
2321.79	92.7327
2325.38	109.195
2328.96	461.996
2332.54	871.875
2336.12	322.335
2339.7	98.5916
2343.28	65.0068
2346.85	86.5886
2350.43	50.9358
2354	64.7788
2357.57	52.3391
2361.14	51.9521
2364.71	14.5261
2368.27	86.9426
2371.84	78.908
2375.4	71.5996
2378.96	5.61475
2382.52	44.095
2386.08	65.2942
2389.64	41.9172
2393.19	70.5134
2396.75	29.2578
2400.3	32.0916
2403.85	46.7549
2407.4	70.0994
2410.95	89.8262
2414.49	100.809
2418.04	63.5771
2421.58	92.0376
2425.12	55.6953
2428.66	78.8723
2432.2	60.9209
2435.74	46.9741
2439.27	48.0042
2442.81	57.5542
2446.34	90.7727
2449.87	75.9102
2453.4	74.4497
2456.93	88.8804
2460.45	66.5139
2463.98	33.8481
2467.5	-4.77783
2471.02	61.8623
2474.54	55.7644
2478.06	51.4443
2481.58	40.1331
2485.09	43.614
2488.61	72.4336
2492.12	57.3416
2495.63	45.4531
2499.14	55.4893
2502.65	0.181396
2506.15	28.7266
2509.66	28.1274
2513.16	64.2363
2516.66	31.116
2520.16	37.8372
2523.66	40.1621
2527.16	60.1956
2530.66	59.2559
2534.15	40.5122
2537.64	40.6748
2541.13	64.8335
2544.62	71.7202
2548.11	74.2122
2551.6	82.5918
2555.08	83.0198
2558.57	47.2778
2562.05	68.967
2565.53	52.3799
2569.01	85.8379
2572.49	70.2869
2575.96	62.6335
2579.44	73.9753
2582.91	77.9136
2586.38	107.165
2589.85	39.4434
2593.32	84.8721
2596.79	64.3245
2600.25	46.7236
2603.72	68.321
2607.18	38.4695
2610.64	58.1204
2614.1	67.2122
2617.56	73.6021
2621.02	50.7263
2624.47	83.9094
2627.92	3.38696
2631.38	37.6829
2634.83	18.4885
2638.28	45.8923
2641.72	85.1392
2645.17	89.8054
2648.61	23.4517
2652.06	18.6545
2655.5	26.6572
2658.94	88.4148
2662.38	56.937
2665.82	-0.794434
2669.25	61.0188
2672.69	4.56323
2676.12	41.3994
2679.55	52.3491
2682.98	62.8594
2686.41	72.8208
2689.84	49.657
2693.26	85.5068
2696.69	99.4143
2700.11	58.7813
2703.53	57.6509
2706.95	45.2109
2710.37	32.4177
2713.79	47.032
2717.2	24.8494
2720.62	79.4436
2724.03	51.2234
2727.44	62.4351
2730.85	55.7603
2734.26	65.9146
2737.66	52.6711
2741.07	60.6123
2744.47	102.877
2747.87	27.7219
2751.28	35.2019
2754.67	28.1187
2758.07	74.0693
2761.47	56.3091
2764.86	42.0149
2768.26	49.887
2771.65	71.7788
2775.04	51.8528
2778.43	37.2515
2781.82	74.2395
2785.2	19.8479
2788.59	89.5984
2791.97	24.7161
2795.35	41.8269
2798.73	47.1802
2802.11	72.2366
2805.49	56.9673
2808.87	80.9155
2812.24	46.7554
2815.62	78.8022
2818.99	73.7513
2822.36	78.4109
2825.73	67.3616
2829.1	73.326
2832.46	48.0292
2835.83	33.338
2839.19	111.272
2842.55	78.7972
2845.91	6.85107
2849.27	56.1471
2852.63	122.808
2855.99	66.4248
2859.34	97.3174
2862.69	57.1492
2866.05	68.5939
2869.4	77.0764
2872.75	44.1438
2876.09	49.6548
2879.44	83.4178
2882.78	88.7863
2886.13	48.7028
2889.47	20.0376
2892.81	40.8129
2896.15	91.5959
2899.49	115.602
2902.82	102.397
2906.16	57.8121
2909.49	65.0367
2912.82	76.9911
2916.16	81.9288
2919.49	34.6915
2922.81	43.2191
2926.14	64.5658
2929.46	94.2965
2932.79	74.4241
2936.11	71.5626
2939.43	73.4233
2942.75	27.287
2946.07	100.862
2949.39	49.2157
2952.7	56.7599
2956.02	117.213
2959.33	87.8521
2962.64	103.487
2965.95	53.0077
2969.26	-4.14185
2972.57	100.608
2975.87	91.7476
2979.17	75.8665
2982.48	62.9081
2985.78	102.68
2989.08	76.7974
2992.38	32.1997
2995.68	76.0619
2998.97	85.2074
3002.27	98.0125
3005.56	102.564
3008.85	81.8041
3012.14	51.7072
3015.43	58.2825
3018.72	102.551
3022	52.4865
3025.29	86.4497
3028.57	134.612
3031.85	69.314
3035.14	67.2025
3038.41	100.114
3041.69	107.513
3044.97	62.9246
3048.24	87.3706
3051.52	76.8881
3054.79	53.0704
3058.06	126.705
3061.33	93.6073
3064.6	127.117
3067.87	72.0879
3071.13	107.518
3074.4	70.983
3077.66	89.4617
3080.92	92.944
3084.18	102.527
3087.44	87.8008
3090.7	94.4126
3093.95	108.51
3097.21	88.6506
3100.46	89.7228
3103.71	77.1545
3106.96	120.831
3110.21	166.791
3113.46	104.176
3116.71	75.9166
3119.95	109.574
3123.2	93.6859
3126.44	136.808
3129.68	78.9402
3132.92	97.2783
3136.16	143.169
3139.4	95.589
3142.63	119.501
3145.87	88.2159
3149.1	109.455
3152.33	126.822
3155.56	181.431
3158.79	148.233
3162.02	115.029
3165.25	131.311
3168.47	156.975
3171.69	112.886
3174.92	130.67
3178.14	176.995
3181.36	168.038
3184.58	147.468
3187.79	191.626
3191.01	168.081
3194.22	141.673
3197.43	161.899
3200.65	212.637
3203.86	185.37
3207.07	182.947
3210.27	163.526
3213.48	156.634
3216.69	147.875
3219.89	197.183
3223.09	194.36
3226.29	168.774
3229.49	185.216
3232.69	211.043
3235.89	201.053
3239.08	237.908
3242.28	187.283
3245.47	211.904
3248.66	228.134
3251.85	230.17
3255.04	199.774
3258.23	210.173
3261.42	190.683
3264.6	258.775
3267.79	194.813
3270.97	221.441
3274.15	227.054
3277.33	212.284
3280.51	236.221
3283.68	233.408
3286.86	253.311
3290.04	218.988
3293.21	242.799
3296.38	222.696
3299.55	277.392
3302.72	275.545
3305.89	186.896
3309.06	266.286
3312.22	277.949
3315.39	250.632
3318.55	305.765
3321.71	203.554
3324.87	233.097
3328.03	221.009
3331.19	239.299
3334.34	302.112
3337.5	247.068
3340.65	290.184
3343.81	311.967
3346.96	303.247
3350.11	275.712
3353.25	325.676
3356.4	274.889
3359.55	309.194
3362.69	284.181
3365.84	299.822
3368.98	317.416
3372.12	314.499
3375.26	355.125
3378.4	336.419
3381.53	313.792
3384.67	350.879
3387.8	316.123
3390.94	287.113
3394.07	339.661
3397.2	410.349
3400.33	400.888
3403.46	427.705
3406.58	462.325
3409.71	460.936
3412.83	544.747
3415.96	622.744
3419.08	757.937
3422.2	1026.43
3425.32	1722.31
3428.44	3583.93
3431.55	7453.14
3434.67	9008.31
3437.78	5386.98
3440.89	2408.63
3444	1252.87
3447.12	816.876
3450.22	633.426
3453.33	549.209
3456.44	422.888
3459.54	407.946
3462.65	444.259
3465.75	392.989
3468.85	356.348
3471.95	410.388
3475.05	375.555
3478.15	369.267
3481.24	324.278
3484.34	383.372
3487.43	368.939
3490.53	410.874
3493.62	408.515
3496.71	490.815
3499.79	512.904
3502.88	614.63
3505.97	733.404
3509.05	875.725
3512.14	1073.05
3515.22	1241.61
3518.3	1222.92
3521.38	1094.06
3524.46	830.019
3527.54	682.105
3530.61	572.455
3533.69	457.792
3536.76	408.853
3539.83	373.634
3542.9	313.862
3545.97	306.835
3549.04	324.085
3552.11	288.948
3555.18	235.155
3558.24	233.577
3561.3	262.822
3564.37	212.329
3567.43	181.793
3570.49	225.835
3573.55	220.362
3576.61	194.89
3579.66	201.514
3582.72	180.461
3585.77	195.395
3588.82	213.944
3591.87	180.253
3594.92	177.714
3597.97	171.346
3601.02	183.784
3604.07	153.464
3607.11	120.292
3610.16	163.651
3613.2	151.139
3616.24	206.649
3619.28	136.688
3622.32	142.305
3625.36	148.021
3628.39	120.724
3631.43	135.702
3634.46	116.128
3637.5	90.2731
3640.53	139.877
3643.56	134.399
3646.59	133.356
3649.62	149.472
3652.64	141.112
3655.67	127.536
3658.69	171.417
3661.72	75.7079
3664.74	127.123
3667.76	101.344
3670.78	125.7
3673.79	74.6726
3676.81	95.46
3679.83	105.827
3682.84	68.9153
3685.86	97.2759
3688.87	57.5579
3691.88	88.8859
3694.89	33.7136
3697.9	82.9854
3700.91	92.557
3703.91	88.8417
3706.92	53.6071
3709.92	70.4878
3712.92	75.7576
3715.92	66.808
3718.92	67.2466
3721.92	94.189
3724.92	87.6609
3727.92	68.6294
3730.91	74.2098
3733.91	92.9398
3736.9	64.8661
3739.89	55.6547
3742.88	77.6956
3745.87	57.7257
3748.86	95.6021
3751.85	56.4568
3754.83	50.6096
3757.82	29.5815
3760.8	60.5851
3763.78	85.849
3766.76	76.1599
3769.74	50.5469
3772.72	43.0519
3775.7	64.9557
3778.67	52.9424
3781.65	73.0823
3784.62	57.407
3787.6	45.5945
3790.57	69.8701
3793.54	79.2065
3796.51	32.9424
3799.47	74.6563
3802.44	61.7321
3805.41	23.3408
3808.37	45.4912
3811.33	33.6748
3814.3	47.4177
3817.26	53.6633
3820.22	53.3203
3823.18	39.816
3826.13	48.1375
3829.09	53.5975
3832.04	64.8708
3835	39.2266
3837.95	55.3781
3840.9	62.9755
3843.85	77.2617
3846.8	29.71
3849.75	33.6412
3852.69	97.728
3855.64	32.073
3858.58	25.5865
3861.53	50.5736
3864.47	28.6809
3867.41	44.0105
3870.35	63.1321
3873.29	30.4165
3876.22	38.7908
3879.16	49.8966
3882.1	69.4734
3885.03	33.1725
3887.96	35.2346
3890.89	35.318
3893.82	49.6632
3896.75	55.1516
3899.68	31.7534
3902.61	68.7129
3905.53	88.5045
3908.46	39.0164
3911.38	57.6356
3914.3	54.9283
3917.23	43.8573
3920.15	48.9209
3923.06	6.76587
3925.98	35.4785
3928.9	28.5466
3931.81	51.5865
3934.73	7.88025
3937.64	31.5581
3940.55	37.9111
3943.46	27.0515
3946.37	52.7096
3949.28	-0.97644
3952.19	69.8726
3955.09	26.8895
3958	27.0803
3960.9	15.8331
3963.8	34.3805
3966.71	65.4896
3969.61	78.452
3972.51	69.3295
3975.4	56.2753
3978.3	55.588
3981.2	49.1014
3984.09	21.3781
3986.99	16.7178
3989.88	24.3148
3992.77	45.6233
3995.66	36.1556
3998.55	36.3734
4001.43	40.4596