File: Data/3-Raman/processed/bu19w-e-ff11b-fi09-v_1800 (450-850nm)_532nm_edge_100%_x100_vis_h50um_30sx2_01.txt
#Acq. time (s)=	30
#Accumulations=	2
#Range (cm-¹)=	1200...2400
#Windows=	4
#Auto scanning=	Off
#Autofocus=	Off
#Macrospot=	Off
#AutoExposure=	Off
#Spike filter=	Multiple accum.
#Delay time (s)=	2
#Binning=	1
#Readout mode=	Signal
#DeNoise=	Off
#ICS correction=	On
#Dark correction=	Off
#Inst. Process=	Off
#Detector Gain=	Best Dynamic
#Detector ADC=	50 kHz HS
#Detector temperature (°C)=	-60.09
#Instrument=	LabRAM HR Evol
#Detector=	SIN-EM FIVIS
#Objective=	x100_VIS
#Grating=	1800 (450-850nm)
#ND Filter=	100%
#Laser=	532nm_Edge
#Hole=	49.98
#Temperature=	0
#Range=	Visible
#StageXY=	75x50mm Scan+
#StageZ=	Z motor
#X (µm)=	0
#Y (µm)=	0
#Z (µm)=	-293.2
#Full time(mm:ss)=	4:21
#Project=	21_11_04
#Sample=	BU19w
#Site=
#Title=	BU19w-E-FF11b-FI09-V_1800 (450-850nm)_532nm_Edge_100%_x100_VIS_H50um_30sX2
#Remark=
#Date=	04.11.2021 17:31
#Acquired=	04.11.2021 17:31:01
#Base:Fit=	16.12.2021 17:39:50
#Base:Fit=	16.12.2021 17:48:11
#Base:Sub=	16.12.2021 17:48:11
1200.19	0.241238
1201.3	4.26514
1202.41	2.99816
1203.52	2.72144
1204.63	3.56299
1205.74	4.38041
1206.85	3.06065
1207.97	1.76793
1209.08	0.48317
1210.19	0.273525
1211.3	3.26096
1212.41	0.920193
1213.52	3.92466
1214.63	-1.56745
1215.74	3.57799
1216.85	0.197353
1217.95	0.0229683
1219.06	-3.31799
1220.17	-0.286079
1221.28	3.80211
1222.39	-1.66555
1223.5	4.51166
1224.61	0.143444
1225.71	5.30841
1226.82	3.06285
1227.93	1.8297
1229.03	2.81843
1230.14	3.74393
1231.25	0.432201
1232.35	1.38043
1233.46	0.234129
1234.57	0.154444
1235.67	3.22933
1236.78	2.07878
1237.88	-3.28131
1238.99	-1.27708
1240.1	1.79064
1241.2	-1.42562
1242.3	-0.447706
1243.41	-0.506098
1244.51	-2.66781
1245.62	6.67179
1246.72	-0.715475
1247.82	-1.82943
1248.93	3.35011
1250.03	-0.89035
1251.13	0.0912628
1252.24	0.0315514
1253.34	1.02639
1254.44	-2.13071
1255.54	3.05528
1256.65	3.02864
1257.75	6.11963
1258.85	3.99179
1259.95	8.14795
1261.05	6.00628
1262.15	15.4565
1263.25	24.7828
1264.35	14.3634
1265.45	5.97214
1266.55	2.83354
1267.66	2.84885
1268.75	2.86356
1269.85	2.83599
1270.95	6.99539
1272.05	5.95889
1273.15	4.93623
1274.25	3.89896
1275.35	4.95256
1276.45	8.12153
1277.54	8.14764
1278.64	10.277
1279.74	19.7371
1280.84	49.2266
1281.94	198.757
1283.03	440.116
1284.13	166.281
1285.23	38.7528
1286.32	21.9192
1287.42	11.3834
1288.52	10.3437
1289.61	4.05946
1290.71	5.12167
1291.8	-0.132656
1292.9	4.0933
1293.99	-0.0781078
1295.09	9.45134
1296.18	1.06253
1297.28	2.12208
1298.37	-1.03947
1299.47	2.13732
1300.56	2.16048
1301.65	-0.979509
1302.75	-0.960754
1303.84	2.2217
1304.94	0.121651
1306.03	4.34266
1307.12	0.147259
1308.21	-0.885248
1309.31	-1.90613
1310.4	3.39313
1311.49	0.257431
1312.58	-0.769314
1313.67	-0.751005
1314.76	1.39315
1315.86	0.368933
1316.95	-1.71878
1318.04	-0.629808
1319.13	1.50815
1320.22	-1.63513
1321.31	0.482693
1322.4	-0.560715
1323.49	0.51899
1324.58	2.65629
1325.67	-3.67118
1326.76	-0.487215
1327.85	-1.47798
1328.93	0.673117
1330.02	3.86031
1331.11	-4.56925
1332.2	1.75019
1333.29	0.698317
1334.37	-1.39455
1335.46	-2.42848
1336.55	0.736206
1337.64	0.752689
1338.72	-2.3704
1339.81	-0.243166
1340.9	-3.35438
1341.98	1.89775
1343.07	-0.178684
1344.16	-0.148146
1345.24	1.95405
1346.33	2.99561
1347.41	4.04458
1348.5	0.938381
1349.58	0.953188
1350.67	0.965612
1351.75	-0.0519238
1352.84	4.16613
1353.92	0.00376129
1355.01	-4.13877
1356.09	4.20574
1357.17	1.11155
1358.26	0.0903416
1359.34	1.14499
1360.42	0.117981
1361.5	3.25315
1362.59	3.27684
1363.67	4.35663
1364.75	6.44715
1365.83	1.28114
1366.92	5.42496
1368	7.52999
1369.08	19.9753
1370.16	3.44783
1371.24	3.4547
1372.32	2.42347
1373.4	8.62586
1374.48	6.58758
1375.56	7.65151
1376.64	6.62582
1377.72	8.73623
1378.8	11.8879
1379.88	13.9398
1380.96	11.8718
1382.04	14.9284
1383.12	27.2207
1384.2	48.7815
1385.28	146.418
1386.36	791.608
1387.43	438.057
1388.51	81.8234
1389.59	31.549
1390.67	22.2811
1391.74	14.0884
1392.82	13.0749
1393.9	10.0243
1394.97	5.96759
1396.05	7.02004
1397.13	7.03302
1398.2	10.1359
1399.28	7.10749
1400.35	4.07831
1401.43	8.21129
1402.5	7.26921
1403.58	7.29698
1404.65	10.3909
1405.73	13.475
1406.8	20.68
1407.88	48.4041
1408.95	34.0953
1410.03	14.6296
1411.1	5.40492
1412.17	4.42027
1413.25	3.44311
1414.32	2.46007
1415.39	4.54355
1416.47	0.472622
1417.54	0.508095
1418.61	2.59444
1419.68	1.58286
1420.75	-0.458359
1421.83	2.6641
1422.9	1.72219
1423.97	1.63027
1425.04	2.70413
1426.11	2.73854
1427.18	-0.335548
1428.25	-2.36274
1429.32	3.8184
1430.39	1.81903
1431.46	-0.190067
1432.53	1.86895
1433.6	0.843287
1434.67	2.93293
1435.74	-0.117756
1436.81	1.95078
1437.88	0.951508
1438.95	2.00889
1440.01	1.02547
1441.08	2.07639
1442.15	0.0536213
1443.22	0.0728226
1444.29	-1.94631
1445.35	4.23889
1446.42	1.1805
1447.49	4.27367
1448.56	1.23267
1449.62	0.223587
1450.69	0.241629
1451.75	-1.78909
1452.82	-1.76101
1453.89	0.312077
1454.95	0.334673
1456.02	0.364553
1457.08	-0.644739
1458.15	3.47671
1459.21	-0.594461
1460.28	0.448965
1461.34	1.48668
1462.41	2.51796
1463.47	-1.56012
1464.53	-1.50701
1465.6	-0.522396
1466.66	-1.52672
1467.72	-1.5063
1468.79	-1.48689
1469.85	-1.47638
1470.91	2.61302
1471.97	0.591619
1473.04	2.64416
1474.1	-0.391811
1475.16	-3.42055
1476.22	1.68249
1477.29	-0.337215
1478.34	1.70869
1479.41	-1.33082
1480.47	-2.34028
1481.53	-2.31697
1482.59	-1.27166
1483.65	0.780285
1484.71	5.79823
1485.77	1.80471
1486.83	1.82078
1487.89	1.82649
1488.95	-0.189758
1490.01	-0.171862
1491.07	1.86091
1492.12	-0.140896
1493.18	-0.122753
1494.24	-3.13263
1495.3	-1.10572
1496.36	2.94101
1497.42	0.939667
1498.47	-0.0480309
1499.53	-0.0227966
1500.59	-0.00396347
1501.64	-3.01798
1502.7	-1.99756
1503.76	1.04498
1504.81	0.0535107
1505.87	1.06623
1506.93	1.08994
1507.98	2.11503
1509.04	-1.89526
1510.09	1.14562
1511.15	1.14224
1512.21	-0.882374
1513.26	-1.87816
1514.31	0.157774
1515.37	0.157324
1516.42	-0.837393
1517.48	2.19081
1518.53	3.2189
1519.58	0.230225
1520.64	-0.753889
1521.69	0.266266
1522.75	4.28525
1523.8	-0.728859
1524.85	0.288774
1525.9	0.318556
1526.95	0.336634
1528.01	2.35149
1529.06	-2.64405
1530.11	1.37802
1531.16	1.40425
1532.21	3.42657
1533.27	-2.55433
1534.32	0.469629
1535.37	1.47187
1536.42	3.46701
1537.47	-0.530024
1538.52	0.476593
1539.57	2.53347
1540.62	1.56532
1541.67	1.56476
1542.72	-0.438452
1543.77	1.56487
1544.81	1.5976
1545.86	2.62754
1546.91	2.64893
1547.96	-0.353432
1549.01	0.633451
1550.06	3.71549
1551.1	1.7459
1552.15	0.762444
1553.2	-1.25113
1554.25	2.75619
1555.3	0.759716
1556.34	4.77985
1557.39	0.788074
1558.43	-0.218294
1559.48	3.77957
1560.53	1.78798
1561.57	2.81374
1562.62	0.829
1563.66	0.848909
1564.71	1.84825
1565.76	-0.142866
1566.8	0.882277
1567.84	1.89163
1568.89	2.89722
1569.93	-0.088356
1570.98	3.9182
1572.02	2.92192
1573.07	2.92231
1574.11	0.94598
1575.15	0.973309
1576.2	-1.01736
1577.24	1.96624
1578.28	-0.0294952
1579.32	2.9752
1580.37	0.994894
1581.41	0.995363
1582.45	1.00039
1583.49	0.0124607
1584.53	4.01156
1585.58	3.02165
1586.62	3.01824
1587.66	4.02082
1588.7	1.05519
1589.74	2.06563
1590.78	2.08067
1591.82	4.07269
1592.86	2.07247
1593.9	1.06968
1594.94	3.07611
1595.98	2.08288
1597.02	4.08404
1598.06	2.10085
1599.1	4.0799
1600.14	1.10026
1601.17	4.05973
1602.21	0.0981636
1603.25	3.85157
1604.29	1.1552
1605.33	1.10044
1606.37	2.82408
1607.4	2.70099
1608.44	1.42893
1609.48	0.837278
1610.51	4.49176
1611.55	3.60473
1612.59	1.26759
1613.62	2.52547
1614.66	4.60666
1615.7	2.59283
1616.73	2.57558
1617.77	-0.515601
1618.8	2.00617
1619.84	1.38666
1620.87	0.834427
1621.91	2.16209
1622.94	1.04088
1623.98	0.77985
1625.01	1.89581
1626.04	1.68031
1627.08	-1.14929
1628.11	1.61432
1629.07	1.21307
1630.12	-1.73968
1631.16	0.239014
1632.21	1.24241
1633.25	1.23857
1634.3	1.25088
1635.34	3.22411
1636.39	1.25037
1637.43	0.263874
1638.48	-0.718466
1639.52	1.25518
1640.57	1.267
1641.61	2.25259
1642.65	-1.68235
1643.7	0.287132
1644.74	2.2577
1645.78	2.26328
1646.83	2.2608
1647.87	1.27986
1648.91	1.30215
1649.95	0.326431
1651	1.32719
1652.04	-1.62337
1653.08	3.30313
1654.12	1.34144
1655.16	1.35911
1656.21	-1.5847
1657.25	1.37676
1658.29	0.386913
1659.33	1.3664
1660.37	-1.58384
1661.41	-0.583721
1662.45	0.437328
1663.49	-1.5725
1664.53	0.431038
1665.57	4.40156
1666.61	1.38109
1667.65	0.417536
1668.69	0.436641
1669.72	-0.549276
1670.76	0.454292
1671.8	0.457776
1672.84	0.461143
1673.88	2.44785
1674.92	-1.49708
1675.95	1.47569
1676.99	2.46709
1678.03	1.46749
1679.07	0.472358
1680.1	1.45596
1681.14	0.465811
1682.18	-1.50812
1683.21	0.468024
1684.25	1.45156
1685.29	-1.51097
1686.32	-0.516772
1687.36	1.45787
1688.39	0.463284
1689.43	-1.52097
1690.46	0.455763
1691.5	-2.49889
1692.53	0.455435
1693.57	2.41113
1694.6	-0.552723
1695.64	1.42248
1696.67	2.40981
1697.7	1.40872
1698.74	1.40037
1699.77	1.40143
1700.81	0.41251
1701.84	0.401966
1702.87	2.36033
1703.9	-0.588518
1704.94	-0.588172
1705.97	-0.594771
1707	1.35287
1708.03	1.33113
1709.06	-0.644144
1710.1	1.31363
1711.13	-0.638115
1712.16	1.31299
1713.19	2.26202
1714.22	3.22609
1715.25	0.300933
1716.28	-1.66127
1717.31	-4.61006
1718.34	0.243459
1719.37	1.21337
1720.4	4.12933
1721.43	-1.72476
1722.46	1.17469
1723.49	2.13719
1724.52	-0.786673
1725.55	3.06858
1726.58	1.12429
1727.6	2.08901
1728.63	0.09231
1729.66	-2.79149
1730.69	1.07703
1731.72	-0.85747
1732.74	0.0978088
1733.77	2.00235
1734.8	-1.87446
1735.82	-0.922839
1736.85	-0.932155
1737.88	-2.86618
1738.91	-0.95952
1739.93	-0.0266981
1740.96	1.87219
1741.98	-0.052803
1743.01	0.898634
1744.03	-1.02707
1745.06	2.79722
1746.09	0.870826
1747.11	-0.102833
1748.13	-1.06382
1749.16	2.76094
1750.18	1.82009
1751.21	-0.0931358
1752.23	-0.111221
1753.26	-0.125477
1754.28	1.76773
1755.3	-0.149624
1756.33	0.783468
1757.35	-1.13317
1758.37	-1.12782
1759.39	0.774373
1760.42	0.7662
1761.44	-0.196882
1762.46	0.755412
1763.48	-2.09735
1764.5	-1.13527
1765.53	1.72381
1766.55	0.767127
1767.57	-0.192884
1768.59	-1.1581
1769.61	-2.12751
1770.63	0.729581
1771.65	-0.209394
1772.67	0.751072
1773.69	-2.09992
1774.71	1.71246
1775.73	0.775823
1776.75	1.72125
1777.77	-0.196752
1778.79	-0.21316
1779.81	2.64431
1780.83	-0.207928
1781.85	0.750716
1782.86	1.71238
1783.88	0.768346
1784.9	-2.08816
1785.92	0.769096
1786.94	-3.03756
1787.95	2.73261
1788.97	1.79535
1789.99	0.845965
1791	0.829494
1792.02	-0.131386
1793.04	-2.04426
1794.05	0.830904
1795.07	1.81568
1796.09	0.867839
1797.1	4.7241
1798.12	1.84626
1799.13	-0.0837746
1800.15	0.865791
1801.16	-2.97993
1802.18	2.78901
1803.19	-2.0057
1804.21	-1.03789
1805.22	1.86403
1806.24	-0.0522051
1807.25	0.912485
1808.26	-1.01459
1809.28	-0.0489607
1810.29	-3.90597
1811.3	-1.97975
1812.32	0.91761
1813.33	-3.89868
1814.34	0.944196
1815.36	0.951363
1816.37	-0.978992
1817.38	-1.96027
1818.39	-0.0190573
1819.4	1.91875
1820.42	-0.00778484
1821.43	0.968346
1822.44	-0.96262
1823.45	-0.965884
1824.46	2.91055
1825.47	-1.92651
1826.48	2.91694
1827.49	-0.951612
1828.5	-0.956629
1829.51	1.9453
1830.52	0.00343418
1831.53	0.0118418
1832.54	0.021719
1833.55	-1.91443
1834.56	0.971656
1835.57	-0.0114574
1836.58	1.96086
1837.58	0.944176
1838.59	0.00944519
1839.6	0.0224762
1840.61	1.91121
1841.62	0.916662
1842.62	1.87282
1843.63	1.87296
1844.64	-1.02037
1845.65	-1.0051
1846.65	1.86842
1847.66	0.88696
1848.67	-2.00789
1849.67	-0.0997162
1850.68	1.80474
1851.68	0.837337
1852.69	-0.122746
1853.69	0.826612
1854.7	0.812362
1855.71	3.67222
1856.71	0.798112
1857.72	0.790653
1858.72	0.776321
1859.72	0.770667
1860.73	0.782202
1861.73	-1.12521
1862.74	-0.180668
1863.74	0.763116
1864.74	0.750527
1865.75	1.68066
1866.75	1.65259
1867.75	-1.21391
1868.76	1.6399
1869.76	0.687111
1870.76	2.58757
1871.76	0.680352
1872.77	-1.22695
1873.77	-2.18091
1874.77	2.54659
1875.77	-0.319897
1876.77	1.55327
1877.77	-1.23262
1878.78	0.644391
1879.78	-1.25299
1880.78	-0.306394
1881.78	0.609236
1882.78	-0.354387
1883.78	-0.367818
1884.78	2.47873
1885.78	-1.27773
1886.78	1.54634
1887.78	-2.2405
1888.77	1.50973
1889.77	-0.371941
1890.77	-0.362437
1891.77	0.578743
1892.77	-3.19589
1893.77	1.4941
1894.76	-1.33029
1895.76	-0.38097
1896.76	-2.24883
1897.76	3.39834
1898.75	-0.373425
1899.75	-2.25716
1900.75	-1.31003
1901.75	4.34881
1902.74	0.589514
1903.74	-0.352386
1904.74	-0.35147
1905.73	1.51951
1906.73	-4.11841
1907.72	1.52656
1908.72	-2.22198
1909.71	-2.20317
1910.71	-0.301995
1911.7	-0.297923
1912.7	-0.295343
1913.69	0.664204
1914.69	-2.14853
1915.68	-2.144
1916.68	2.56659
1917.67	0.680418
1918.66	-0.243282
1919.66	-3.99923
1920.65	1.67908
1921.64	-0.197653
1922.64	3.58176
1923.63	2.6328
1924.62	0.742467
1925.61	1.70822
1926.61	0.784144
1927.6	-3.93902
1928.59	-0.138876
1929.58	1.77784
1930.57	2.74682
1931.57	0.846692
1932.56	1.79209
1933.55	0.860945
1934.54	-1.93929
1935.53	-1.92702
1936.52	2.83496
1937.51	-1.93551
1938.5	2.83399
1939.49	-0.00817394
1940.48	0.970315
1941.47	-0.936861
1942.46	0.0389795
1943.45	1.93282
1944.44	2.91582
1945.42	1.02652
1946.41	1.03942
1947.4	0.0839825
1948.39	1.04452
1949.38	1.06388
1950.37	-0.82291
1951.35	0.163772
1952.34	-1.74487
1953.33	-0.784447
1954.32	0.146799
1955.3	0.156307
1956.29	2.10854
1957.28	0.206163
1958.26	1.17773
1959.25	0.214756
1960.23	0.209573
1961.22	1.16477
1962.21	1.17272
1963.19	0.220342
1964.18	2.14979
1965.16	-1.68698
1966.15	1.21134
1967.13	-0.701754
1968.12	1.22797
1969.1	2.17891
1970.09	1.20824
1971.07	0.245071
1972.05	-3.58479
1973.04	2.16716
1974.02	0.247827
1975.01	-0.701569
1975.99	1.22849
1976.97	-0.685987
1977.95	4.10355
1978.94	-0.686366
1979.92	2.19326
1980.9	0.272087
1981.88	-2.59984
1982.87	1.22117
1983.85	0.261941
1984.83	2.16853
1985.81	-1.64068
1986.79	1.20465
1987.77	-1.56769
1988.75	-1.49206
1989.73	2.08168
1990.72	-0.496571
1991.7	0.940291
1992.68	0.868729
1993.66	0.283009
1994.63	0.451542
1995.61	0.611343
1996.59	1.63441
1997.57	-0.206674
1998.55	-0.00622368
1999.53	0.424529
2000.51	-0.123405
2001.49	0.63347
2002.47	-0.184733
2003.45	0.136071
2004.42	0.215074
2005.4	-0.47287
2006.38	2.89746
2007.36	1.74026
2008.31	1.11009
2009.3	0.153292
2010.29	1.08711
2011.28	-1.73558
2012.27	1.08963
2013.26	-0.809232
2014.24	0.107481
2015.23	-3.63879
2016.22	-2.68231
2017.21	-0.804386
2018.2	1.0541
2019.18	-0.83645
2020.17	-0.836332
2021.16	1.97926
2022.15	-1.77014
2023.14	1.96182
2024.12	-1.78865
2025.11	-1.80209
2026.1	0.0683117
2027.08	0.114417
2028.07	0.0571289
2029.06	1.06637
2030.04	2.87098
2031.03	-1.7803
2032.01	-2.70021
2033	-0.812057
2033.98	1.04442
2034.97	1.9784
2035.95	1.07419
2036.94	-0.794353
2037.92	0.137512
2038.91	-1.73717
2039.89	-1.74691
2040.87	-0.822945
2041.86	1.03877
2042.84	1.03952
2043.83	-0.802668
2044.81	0.105216
2045.79	-0.7493
2046.78	0.146982
2047.76	-1.73381
2048.74	1.07445
2049.72	1.0968
2050.71	-1.69669
2051.69	1.10176
2052.67	0.178724
2053.65	-2.60681
2054.63	-0.732351
2055.62	0.198456
2056.6	1.13212
2057.58	-1.66345
2058.56	-2.58494
2059.54	-0.706767
2060.52	-0.707252
2061.5	1.17225
2062.48	0.244596
2063.46	4.00521
2064.44	3.07874
2065.42	-1.5923
2066.4	1.23428
2067.38	-0.634345
2068.36	1.25507
2069.34	0.301886
2070.31	-3.44067
2071.29	0.345592
2072.27	0.34705
2073.25	-0.593763
2074.23	0.356501
2075.21	0.383986
2076.18	0.394257
2077.16	-1.506
2078.14	2.27432
2079.12	-3.37304
2080.09	2.30624
2081.07	-1.47483
2082.05	2.30812
2083.02	2.30966
2084	-1.46911
2084.98	1.36811
2085.95	-1.45582
2086.93	2.33896
2087.9	1.39603
2088.88	0.45603
2089.85	1.41336
2090.83	-0.474264
2091.8	-0.458105
2092.78	1.46019
2093.75	-2.32699
2094.73	0.524323
2095.7	-0.434408
2096.68	2.41104
2097.65	-0.445214
2098.62	0.501193
2099.6	1.44921
2100.57	2.407
2101.54	-0.435821
2102.52	-3.28818
2103.49	0.504653
2104.46	1.46143
2105.44	0.523615
2106.41	-0.422036
2107.38	-0.4253
2108.35	1.45887
2109.32	4.31629
2110.3	1.46648
2111.27	-2.33671
2112.24	0.512103
2113.21	-0.427778
2114.18	-0.429484
2115.15	0.519182
2116.12	0.50974
2117.09	-3.29097
2118.06	-1.40257
2119.03	2.37603
2120	0.470502
2120.97	0.478579
2121.94	2.38914
2122.91	1.44739
2123.88	2.38945
2124.85	0.465282
2125.82	4.23113
2126.79	1.37709
2127.76	0.425611
2128.72	0.423047
2129.69	1.36312
2130.66	0.411057
2131.63	3.23387
2132.6	0.390769
2133.56	0.390744
2134.53	0.389595
2135.5	-0.561208
2136.47	-0.572521
2137.43	1.3182
2138.4	-0.575283
2139.37	-0.582932
2140.33	0.349151
2141.3	2.22461
2142.26	-1.54398
2143.23	-0.639616
2144.19	-0.62164
2145.16	-0.627917
2146.13	4.06527
2147.09	1.23555
2148.06	2.16486
2149.02	-0.66599
2149.98	2.12802
2150.95	1.19106
2151.91	0.258026
2152.88	-2.56631
2153.84	0.23363
2154.8	-0.729335
2155.77	2.0558
2156.73	-1.68585
2157.69	-2.61544
2158.66	1.11873
2159.62	1.10352
2160.58	1.08847
2161.54	-2.65049
2162.51	0.143576
2163.47	-0.798658
2164.43	1.05073
2165.39	1.98277
2166.35	-1.75295
2167.32	0.0930738
2168.28	1.00312
2169.24	1.01192
2170.2	-0.837175
2171.16	0.0778666
2172.12	0.0534849
2173.08	0.976801
2174.04	-0.879733
2175	0.974363
2175.96	0.96699
2176.92	0.0320129
2177.88	-0.901762
2178.84	1.87428
2179.8	1.87107
2180.76	1.86437
2181.72	0.926632
2182.68	-2.7955
2183.63	-0.03018
2184.59	-0.0341482
2185.55	-0.957702
2186.51	0.908628
2187.47	-2.79684
2188.43	-2.80951
2189.38	1.80832
2190.34	0.877137
2191.3	0.876932
2192.25	-0.0486441
2193.21	1.81595
2194.17	0.906816
2195.12	-0.963205
2196.08	-1.9124
2197.04	3.63868
2197.99	1.7874
2198.95	0.875143
2199.9	1.8301
2200.86	-0.945673
2201.81	-0.097683
2202.77	0.87468
2203.72	0.914235
2204.68	-0.0463085
2205.63	-0.0712814
2206.59	-0.0761242
2207.54	-3.79006
2208.49	-3.78553
2209.45	-0.994224
2210.4	0.872463
2211.36	-0.0523109
2212.31	-0.0512075
2213.26	3.6658
2214.22	-0.984201
2215.17	-0.0503206
2216.12	1.81258
2217.07	0.874244
2218.03	1.80513
2218.98	-0.991101
2219.93	-3.79484
2220.88	-0.0675268
2221.83	0.849695
2222.78	-0.0822544
2223.74	-0.0703592
2224.69	-0.0594912
2225.64	-0.048542
2226.59	-0.0405636
2227.54	-0.0400181
2228.49	-1.9234
2229.44	-0.0460634
2230.39	-0.0375195
2231.34	-0.0278587
2232.29	-1.90045
2233.24	-0.0122747
2234.19	-0.0149813
2235.14	-0.0335045
2236.09	0.906102
2237.04	0.911507
2237.98	-0.0108795
2238.93	-1.88664
2239.88	1.86982
2240.83	0.935906
2241.78	-0.950748
2242.73	1.88026
2243.67	2.81313
2244.62	-0.00725555
2245.57	0.00422096
2246.52	0.0100336
2247.46	0.95665
2248.41	-0.943707
2249.36	-0.944552
2250.3	0.935074
2251.25	-1.91513
2252.2	1.87204
2253.14	-0.946818
2254.09	1.90467
2255.03	0.952067
2255.98	-2.83856
2256.92	-0.935255
2257.87	-1.88344
2258.81	0.0194845
2259.76	1.92312
2260.7	0.0292568
2261.65	-0.920017
2262.59	1.94325
2263.54	0.0561981
2264.48	1.98196
2265.42	1.03093
2266.37	0.059473
2267.31	1.95275
2268.26	-1.87162
2269.2	1.001
2270.14	1.97241
2271.08	-0.88787
2272.03	-0.884507
2272.97	1.98613
2273.91	0.0723858
2274.85	0.0730104
2275.79	1.03467
2276.74	-0.870585
2277.68	-0.851011
2278.62	-0.85131
2279.56	1.04958
2280.5	-0.884711
2281.44	-1.84907
2282.38	-0.883405
2283.32	1.05597
2284.26	0.112905
2285.2	1.08114
2286.14	0.107738
2287.08	-0.839073
2288.02	-0.839379
2288.96	0.105067
2289.9	5.85517
2290.84	0.0924368
2291.78	0.104561
2292.72	2.0428
2293.66	-0.846542
2294.6	1.06876
2295.54	1.05774
2296.47	-1.84063
2297.41	-0.867311
2298.35	3.00016
2299.29	-0.846138
2300.23	0.118689
2301.16	0.124872
2302.1	1.08601
2303.04	1.08358
2303.97	-1.80629
2304.91	0.132707
2305.85	0.138015
2306.78	0.137389
2307.72	-0.835785
2308.65	0.131984
2309.59	2.0814
2310.53	0.145958
2311.46	1.08199
2312.4	0.105305
2313.33	-0.84713
2314.27	1.10637
2315.2	-1.79519
2316.14	2.04959
2317.07	0.118094
2318	2.04891
2318.94	-0.856529
2319.87	-0.857718
2320.81	1.08041
2321.74	3.99808
2322.67	3.0397
2323.61	2.07869
2324.54	3.03472
2325.47	6.87975
2326.41	12.6499
2327.34	64.6808
2328.27	69.5023
2329.2	10.6871
2330.13	6.8357
2331.07	2.98814
2332	2.98963
2332.93	0.0947313
2333.86	0.0899687
2334.79	1.04669
2335.72	1.05093
2336.66	1.05079
2337.59	-0.871555
2338.52	2.01538
2339.45	0.0962076
2340.38	2.97147
2341.31	-0.884148
2342.24	1.02965
2343.17	-1.84214
2344.1	-0.876281
2345.02	1.99935
2345.95	-1.83713
2346.88	0.0806942
2347.81	0.109169
2348.74	3.71586
2349.67	0.734172
2350.6	0.810399
2351.53	-0.291187
2352.45	-1.11788
2353.38	0.0883799
2354.31	0.695302
2355.24	0.480975
2356.17	-0.854053
2357.09	-0.295093
2358.02	-0.0702305
2358.95	0.465025
2359.87	-2.03745
2360.8	-1.24232
2361.73	-0.230648
2362.65	-2.30043
2363.58	-1.46568
2364.5	-0.705748
2365.43	-1.38282
2366.36	0.00714397
2367.28	1.20515
2368.2	-0.199959
2368.98	1.05751
2369.92	-1.77094
2370.86	2.00336
2371.79	0.127964
2372.73	1.07762
2373.67	0.146907
2374.6	0.154533
2375.54	2.04304
2376.48	1.11492
2377.41	-0.748971
2378.35	-0.739179
2379.28	1.13873
2380.22	1.15259
2381.15	0.237345
2382.09	1.19553
2383.02	-1.59188
2383.96	1.23897
2384.89	1.25901
2385.83	0.335654
2386.76	-1.52225
2387.69	-1.50391
2388.63	-0.545278
2389.56	-1.45216
2390.5	1.37621
2391.43	-0.456762
2392.36	1.43374
2393.3	0.509998
2394.23	-1.32976
2395.16	0.569522
2396.09	1.58117
2397.02	1.6073
2397.96	1.64337
2398.89	2.61177
2399.82	0.785886