File: Data/3-Raman/processed/bu19(2)w-a-ff2b-fi02-v_1800 (450-850nm)_532nm_edge_100%_x100_vis_lwd_h100um_30sx2_01.txt
#Acq. time (s)=	30
#Accumulations=	2
#Range (cm-¹)=	1200...2365
#Windows=	3
#Auto scanning=	Off
#Autofocus=	Off
#Macrospot=	Off
#AutoExposure=	Off
#Spike filter=	Multiple accum.
#Delay time (s)=	2
#Binning=	1
#Readout mode=	Signal
#DeNoise=	Off
#ICS correction=	On
#Dark correction=	Off
#Inst. Process=	Off
#Detector Gain=	Best Dynamic
#Detector ADC=	50 kHz HS
#Detector temperature (°C)=	-60.09
#Instrument=	LabRAM HR Evol
#Detector=	SIN-EM FIVIS
#Objective=	x100_VIS_LWD
#Grating=	1800 (450-850nm)
#ND Filter=	100%
#Laser=	532nm_Edge
#Hole=	100.021
#Temperature=	0
#Range=	Visible
#StageXY=	75x50mm Scan+
#StageZ=	Z motor
#X (µm)=	0
#Y (µm)=	0
#Z (µm)=	-48.5
#Full time(mm:ss)=	3:23
#Project=	21_11_26
#Sample=	BU19(2)w
#Site=
#Title=	BU19(2)w-A-FF2b-FI02-V_1800 (450-850nm)_532nm_Edge_100%_x100_VIS_LWD_H100um_30sX2
#Remark=
#Date=	26.11.2021 16:13
#Acquired=	26.11.2021 16:13:37
#Base:Fit=	16.12.2021 16:00:56
#Base:Fit=	16.12.2021 16:09:28
#Base:Sub=	16.12.2021 16:09:29
1202.72	7.46678
1203.84	8.0837
1204.95	4.2671
1206.06	0.367767
1207.17	4.9919
1208.28	3.22849
1209.39	13.2087
1210.5	-1.37766
1211.61	4.23547
1212.72	-1.89891
1213.83	0.512718
1214.94	-0.227127
1216.05	1.13708
1217.16	-5.06116
1218.27	-2.74226
1219.38	-6.77369
1220.49	0.863739
1221.6	0.00512695
1222.71	2.23323
1223.81	1.22736
1224.92	-6.06745
1226.03	-0.611992
1227.14	1.6441
1228.25	-2.59828
1229.35	-3.68827
1230.46	-0.204033
1231.57	-0.301956
1232.67	-8.60048
1233.78	0.936806
1234.89	4.20822
1235.99	5.37711
1237.1	5.43262
1238.2	2.246
1239.31	2.21392
1240.41	2.24088
1241.52	5.4423
1242.62	3.35912
1243.73	1.32577
1244.83	4.50348
1245.94	-8.10828
1247.04	9.67448
1248.14	7.58361
1249.25	6.51068
1250.35	12.8011
1251.45	6.46664
1252.56	7.46405
1253.66	8.46056
1254.76	9.561
1255.87	8.5379
1256.97	15.8744
1258.07	34.6551
1259.17	23.1234
1260.27	20.0593
1261.37	40.824
1262.48	89.1764
1263.58	140.88
1264.68	99.734
1265.78	49.41
1266.88	33.7445
1267.98	25.4919
1269.08	23.5422
1270.18	23.5553
1271.28	23.4772
1272.38	21.4104
1273.47	26.7827
1274.57	30.0475
1275.67	36.3766
1276.77	36.4864
1277.87	33.4533
1278.97	45.1503
1280.07	79.917
1281.16	213.544
1282.26	744.289
1283.36	2187.49
1284.45	1562.42
1285.55	300.435
1286.65	92.9859
1287.75	51.9173
1288.84	29.8401
1289.94	37.3322
1291.03	25.8393
1292.13	29.0534
1293.22	14.3733
1294.32	10.3371
1295.42	20.98
1296.51	9.63492
1297.61	17.1034
1298.7	11.8578
1299.79	11.9022
1300.89	13.0781
1301.98	8.96393
1303.08	10.1434
1304.17	2.82443
1305.26	1.869
1306.35	4.0255
1307.45	2.01645
1308.54	4.25009
1309.63	-0.879951
1310.73	-3.90887
1311.82	5.72968
1312.91	-4.65964
1314	-1.37837
1315.09	0.87886
1316.18	2.11542
1317.28	3.30496
1318.37	-3.9168
1319.46	-6.93047
1320.55	-10.9999
1321.64	4.9526
1322.73	-7.61176
1323.82	5.18333
1324.91	-7.29787
1326	5.47611
1327.09	6.57693
1328.18	4.77769
1329.27	5.04736
1330.35	3.10995
1331.44	1.12541
1332.53	-0.893745
1333.62	-1.84504
1334.71	4.57212
1335.79	-0.539078
1336.88	-1.43177
1337.97	0.8377
1339.06	0.986275
1340.14	1.18848
1341.23	8.73222
1342.32	-1.55637
1343.4	-3.49444
1344.49	5.07983
1345.58	2.12521
1346.66	0.157936
1347.75	6.55241
1348.83	-0.555977
1349.92	-0.380119
1351	3.95535
1352.09	-0.0301361
1353.17	6.48142
1354.25	10.9486
1355.34	7.88475
1356.42	10.1865
1357.51	10.3825
1358.59	6.41772
1359.67	19.0486
1360.76	17.1333
1361.84	16.3093
1362.92	20.6589
1364	16.7829
1365.09	29.447
1366.17	21.33
1367.25	28.7156
1368.33	32.0551
1369.41	126.41
1370.5	29.4394
1371.58	32.7043
1372.66	36.9366
1373.74	32.991
1374.82	30.115
1375.9	39.6284
1376.98	48.0652
1378.06	43.1243
1379.14	59.0009
1380.22	81.8559
1381.3	81.8101
1382.38	98.3438
1383.46	137.344
1384.54	238.976
1385.61	591.489
1386.69	3177.37
1387.77	3554.27
1388.85	474.506
1389.93	158.52
1391	92.814
1392.08	81.6646
1393.16	61.3221
1394.23	50.2596
1395.31	48.4459
1396.39	39.504
1397.46	36.623
1398.54	34.7939
1399.62	39.1605
1400.69	24.0721
1401.77	36.6319
1402.84	37.0025
1403.92	39.3726
1404.99	51.8484
1406.07	60.2115
1407.14	115.755
1408.22	226.761
1409.29	227.068
1410.37	80.6647
1411.44	42.8361
1412.51	28.6947
1413.59	25.0263
1414.66	16.9436
1415.73	17.1914
1416.81	13.3201
1417.88	13.5636
1418.95	19.9532
1420.02	11.9266
1421.1	11.0588
1422.17	13.3227
1423.24	5.43005
1424.31	16.7308
1425.38	20.0117
1426.45	13.0501
1427.52	13.186
1428.59	9.22741
1429.67	7.39023
1430.74	8.65622
1431.81	6.86744
1432.87	7.02509
1433.95	10.2025
1435.01	6.30838
1436.08	6.49077
1437.15	7.67891
1438.22	-0.350033
1439.29	13.161
1440.36	8.25365
1441.43	2.28812
1442.49	1.42754
1443.56	4.6693
1444.63	4.82494
1445.7	4.0032
1446.77	3.12306
1447.83	9.41627
1448.9	4.46292
1449.97	5.63618
1451.03	1.6651
1452.1	3.84898
1453.17	5.02023
1454.23	-3.02282
1455.3	8.39061
1456.36	6.49592
1457.43	1.49269
1458.49	-0.425385
1459.56	0.742989
1460.62	3.94359
1461.69	-4.1378
1462.75	-3.01268
1463.82	-4.9666
1464.88	-0.704281
1465.94	1.33406
1467.01	-1.62024
1468.07	-2.52851
1469.13	0.6423
1470.2	-0.290981
1471.26	-3.25725
1472.32	2.94128
1473.39	-2.04907
1474.45	-0.945347
1475.51	-1.85235
1476.57	2.30489
1477.63	-1.68558
1478.69	-2.61982
1479.76	-1.53434
1480.82	-3.5145
1481.88	-1.4083
1482.94	-3.32084
1484	0.835583
1485.06	-0.180798
1486.12	0.903244
1487.18	6.05554
1488.24	-6.04259
1489.3	2.1012
1490.36	1.15296
1491.42	5.2481
1492.48	-4.79556
1493.53	-2.70879
1494.59	-2.64234
1495.65	4.48104
1496.71	3.49119
1497.77	-1.50554
1498.82	-5.48438
1499.88	0.638809
1500.94	-1.32041
1502	-1.28132
1503.05	3.80068
1504.11	-0.203506
1505.17	-1.1583
1506.22	-2.15331
1507.28	1.9266
1508.34	-1.05157
1509.39	-0.000511169
1510.45	-1.96867
1511.5	-0.956635
1512.56	-3.00517
1513.61	-1.00216
1514.67	3.07579
1515.72	-4.95777
1516.78	3.06416
1517.83	3.08771
1518.88	2.12999
1519.94	0.162445
1520.99	1.18652
1522.05	-2.79476
1523.1	-1.78447
1524.15	-1.80573
1525.2	2.20407
1526.26	2.24087
1527.31	-1.72837
1528.36	4.28605
1529.41	-1.72467
1530.47	-0.720142
1531.52	1.3225
1532.57	-3.68128
1533.62	-0.623596
1534.67	3.4045
1535.72	1.38762
1536.77	-2.66675
1537.82	0.300343
1538.87	-2.71777
1539.92	-4.66091
1540.97	-1.59184
1542.02	-2.61563
1543.07	1.35367
1544.12	3.30734
1545.17	-0.669266
1546.22	-0.632954
1547.27	1.37674
1548.32	-0.650181
1549.37	1.32473
1550.42	2.33529
1551.46	-4.5755
1552.51	-0.564602
1553.56	1.40605
1554.61	0.365501
1555.65	0.321507
1556.7	3.31388
1557.75	0.305328
1558.79	3.26558
1559.84	0.206169
1560.89	1.17374
1561.93	1.16911
1562.98	0.178226
1564.02	-2.84239
1565.07	-5.82869
1566.11	-2.06881
1567.16	-1.92587
1568.2	-0.911949
1569.25	2.08141
1570.29	2.04463
1571.34	-1.9702
1572.38	-0.00645828
1573.43	-1.04615
1574.47	-2.06569
1575.51	-4.04486
1576.56	-0.060463
1577.6	1.87062
1578.64	-5.17493
1579.69	-1.20821
1580.73	-3.20991
1581.77	1.73847
1582.81	0.699657
1583.85	-1.31955
1584.9	1.6513
1585.94	-3.35046
1586.98	-1.40741
1588.02	-0.446789
1589.06	-1.44783
1590.1	3.52536
1591.14	-1.46136
1592.18	0.50222
1593.22	-1.54512
1594.26	0.366039
1595.3	5.32169
1596.34	-3.65257
1597.38	5.27207
1598.42	1.28152
1599.46	-1.75222
1600.5	-0.805809
1601.54	6.06749
1602.58	8.97141
1603.62	-0.979836
1604.66	0.970333
1605.69	-2.99931
1606.73	1.94616
1607.77	2.94717
1608.81	0.92194
1609.84	-0.419689
1610.88	5.8839
1611.92	-0.50655
1612.95	0.220337
1613.99	3.20441
1615.03	0.0944748
1616.06	-1.66884
1617.1	5.43623
1618.13	1.71758
1619.17	4.17617
1620.2	3.54326
1621.24	4.09513
1622.27	3.3001
1623.31	3.10186
1624.34	2.88624
1625.38	3.80193
1626.41	3.54575
1627.45	3.53373
1628.48	1.61108
1629.51	1.57504
1630.55	4.18148
1631.53	-0.447018
1632.57	9.41523
1633.62	5.45958
1634.66	-0.45298
1635.71	2.49154
1636.75	7.39112
1637.8	4.40286
1638.84	4.38226
1639.89	-2.5151
1640.93	0.438194
1641.98	1.41673
1643.02	4.35587
1644.06	5.32805
1645.11	0.385693
1646.15	8.26654
1647.19	3.32624
1648.24	1.34294
1649.28	8.26793
1650.32	4.3277
1651.37	5.35183
1652.41	-1.5382
1653.45	0.423466
1654.49	6.3454
1655.53	5.3807
1656.57	1.48126
1657.62	-1.47665
1658.66	0.486027
1659.7	1.45241
1660.74	3.422
1661.78	2.47086
1662.82	4.49909
1663.86	5.49812
1664.9	2.51244
1665.94	1.47866
1666.98	1.538
1668.02	0.536831
1669.06	1.54037
1670.1	4.54258
1671.14	1.61919
1672.18	5.57551
1673.21	0.64859
1674.25	0.669483
1675.29	2.68291
1676.33	1.71557
1677.37	-0.247017
1678.4	0.736885
1679.44	-3.22988
1680.48	4.67752
1681.52	-2.23799
1682.55	-2.22338
1683.59	2.72957
1684.63	1.74809
1685.66	-4.16741
1686.7	3.75423
1687.73	-0.168446
1688.77	-0.166817
1689.81	-0.175102
1690.84	0.820946
1691.88	1.84255
1692.91	-1.10192
1693.95	2.82498
1694.98	-3.0952
1696.01	-0.112339
1697.05	-4.02095
1698.08	3.85175
1699.12	-2.05846
1700.15	-1.05229
1701.18	3.88084
1702.22	3.88365
1703.25	1.91692
1704.28	-3.9625
1705.32	-0.981979
1706.35	5.91265
1707.38	2.95266
1708.41	-0.988163
1709.44	-7.86117
1710.48	-5.88246
1711.51	0.0326576
1712.54	2.02216
1713.57	1.98971
1714.6	0.0228004
1715.63	3.95948
1716.66	2.0346
1717.69	1.03802
1718.72	-7.76195
1719.75	0.0460854
1720.78	2.02234
1721.81	-0.899467
1722.84	3.9542
1723.87	-0.900513
1724.9	-1.85095
1725.93	-0.89933
1726.96	0.0883636
1727.99	0.109871
1729.02	-0.899303
1730.05	2.95989
1731.07	5.86496
1732.1	4.01721
1733.13	0.169212
1734.16	-1.77659
1735.18	0.139282
1736.21	2.0624
1737.24	0.154018
1738.26	1.12807
1739.29	-0.792446
1740.32	3.98236
1741.34	-3.69595
1742.37	-2.72698
1743.4	0.169003
1744.42	1.14189
1745.45	-1.70045
1746.47	-1.67868
1747.5	4.04924
1748.52	2.15073
1749.55	0.285759
1750.57	-5.38187
1751.6	3.27148
1752.62	4.224
1753.64	1.36151
1754.67	4.22811
1755.69	0.429409
1756.71	2.33598
1757.74	2.33026
1758.76	5.23303
1759.78	4.32105
1760.81	5.29658
1761.83	2.45215
1762.85	5.3367
1763.87	4.42617
1764.89	7.34695
1765.92	4.54573
1766.94	3.62564
1767.96	4.59988
1768.98	3.66574
1770	3.62735
1771.02	8.43335
1772.04	6.60299
1773.06	6.66196
1774.08	5.76288
1775.1	4.85814
1776.12	6.83797
1777.14	5.91799
1778.16	5.92441
1779.18	8.77747
1780.2	1.18952
1781.22	1.23438
1782.24	7.94345
1783.26	2.28743
1784.28	4.24589
1785.29	9.07525
1786.31	3.37163
1787.33	1.51271
1788.35	0.658039
1789.37	6.48789
1790.38	8.47291
1791.4	2.74671
1792.42	3.70398
1793.43	0.871609
1794.45	5.69931
1795.47	2.88748
1796.48	6.7998
1797.5	-0.826862
1798.51	-1.74336
1799.53	1.16499
1800.55	4.04952
1801.56	-4.58016
1802.58	2.1771
1803.59	-3.53875
1804.61	1.31038
1805.62	2.32923
1806.64	-0.506584
1807.65	3.38226
1808.66	0.51685
1809.68	0.545467
1810.69	0.573246
1811.7	2.51924
1812.72	3.5116
1813.73	4.51853
1814.74	1.67919
1815.76	4.62762
1816.77	-0.17622
1817.78	1.75534
1818.79	-1.11774
1819.8	2.77793
1820.82	-2.988
1821.83	-1.01864
1822.84	0.949459
1823.85	-0.00101471
1824.86	0.98547
1825.87	4.88887
1826.88	0.0649986
1827.89	5.90362
1828.9	-1.83276
1829.91	3.01403
1830.92	6.88586
1831.93	2.07325
1832.94	5.98486
1833.95	2.13143
1834.96	-0.787075
1835.97	4.977
1836.98	-1.66245
1837.99	8.89106
1839	-1.74717
1840	3.15319
1841.01	6.9577
1842.02	-2.76342
1843.03	5.8992
1844.04	3.0132
1845.04	8.8098
1846.05	1.10979
1847.06	5.01469
1848.07	-1.85265
1849.07	0.0845032
1850.08	0.0630302
1851.09	-2.85742
1852.09	0.00673676
1853.1	0.968403
1854.1	-1.92229
1855.11	-0.994831
1856.11	-1.02481
1857.12	0.887321
1858.12	-0.0822868
1859.13	4.67364
1860.13	-1.08968
1861.14	-2.98871
1862.14	-1.05845
1863.15	-2.03791
1864.15	-0.157032
1865.15	0.770023
1866.16	4.53712
1867.16	0.660477
1868.16	1.56367
1869.17	2.50621
1870.17	-0.356697
1871.17	-4.16899
1872.17	-1.3356
1873.18	2.43629
1874.18	-0.432186
1875.18	-5.21128
1876.18	-3.36754
1877.18	-1.51634
1878.18	1.26199
1879.19	-2.47175
1880.19	4.17281
1881.19	3.21227
1882.19	4.09293
1883.19	-2.60159
1884.19	-0.761452
1885.19	1.1307
1886.19	-4.49969
1887.19	1.14864
1888.19	2.98859
1889.19	0.100349
1890.19	-1.81452
1891.19	-0.865471
1892.18	0.997211
1893.18	-1.85628
1894.18	-0.040657
1895.18	-1.01052
1896.18	0.864994
1897.18	1.81361
1898.17	-1.95483
1899.17	5.53135
1900.17	3.60884
1901.16	-0.16658
1902.16	1.72383
1903.16	3.60183
1904.16	-2.07145
1905.15	1.66582
1906.15	4.45284
1907.14	-2.16652
1908.14	-1.24159
1909.14	-3.12505
1910.13	1.58758
1911.13	0.671047
1912.12	-0.280041
1913.12	1.57839
1914.11	-0.308601
1915.11	3.47806
1916.1	3.47228
1917.1	1.54662
1918.09	-0.377258
1919.08	3.39803
1920.08	1.54116
1921.07	0.581944
1922.06	0.589554
1923.06	2.45409
1924.05	-0.418709
1925.04	-0.457283
1926.04	0.489933
1927.03	-3.27799
1928.02	0.508087
1929.01	0.50095
1930	6.19778
1931	5.27035
1931.99	4.29435
1932.98	-2.39207
1933.97	1.38636
1934.96	3.3726
1935.95	1.52663
1936.94	-0.437286
1937.93	2.36556
1938.92	-2.41964
1939.91	-1.47145
1940.9	-0.517811
1941.89	-0.509087
1942.88	-6.24489
1943.87	4.20963
1944.86	-1.51375
1945.85	1.36316
1946.84	0.408455
1947.83	-2.48884
1948.82	2.26466
1949.8	-4.43143
1950.79	-0.57843
1951.78	1.37188
1952.77	-0.541634
1953.76	3.28199
1954.74	-6.4085
1955.73	1.21812
1956.72	-0.661228
1957.7	2.23141
1958.69	1.26731
1959.68	-1.64949
1960.66	1.19231
1961.65	2.10448
1962.63	-1.75544
1963.62	2.06814
1964.61	4.93955
1965.59	1.07285
1966.58	0.110867
1967.56	6.83536
1968.55	2.0154
1969.53	5.81783
1970.52	4.79136
1971.5	-0.0492325
1972.48	2.80828
1973.47	5.65743
1974.45	7.52868
1975.44	5.59574
1976.42	5.59829
1977.4	4.62334
1978.39	0.749149
1979.37	3.59455
1980.35	7.41437
1981.33	6.41518
1982.31	8.29777
1983.3	8.25362
1984.28	0.553581
1985.26	13.9057
1986.24	13.8732
1987.22	7.18137
1988.21	6.17839
1989.19	7.12879
1990.17	8.04294
1991.15	14.4309
1992.13	10.9622
1993.11	14.372
1994.09	9.54841
1995.07	18.6602
1996.05	16.2946
1997.03	13.8515
1998.01	13.5173
1998.99	10.4748
1999.97	16.28
2000.95	16.7084
2001.92	18.8472
2002.9	14.115
2003.88	15.5103
2004.86	14.1045
2005.84	13.0095
2006.81	18.2449
2007.79	17.9546
2008.77	19.4743
2009.75	14.5631
2010.73	18.9385
2011.7	19.8515
2012.68	15.4758
2013.67	17.2957
2014.66	17.2067
2015.64	18.1207
2016.63	18.1422
2017.62	18.1766
2018.61	19.0416
2019.6	11.463
2020.58	11.4422
2021.57	5.82381
2022.56	15.1768
2023.55	8.5819
2024.54	4.80682
2025.52	13.1566
2026.51	10.3208
2027.5	11.3797
2028.48	9.46039
2029.47	10.4713
2030.45	9.40276
2031.44	7.56125
2032.43	11.3074
2033.41	8.56968
2034.4	7.64661
2035.38	7.58717
2036.37	11.4284
2037.35	9.55207
2038.34	5.80825
2039.32	7.65956
2040.31	5.76498
2041.29	4.80132
2042.27	2.92873
2043.26	5.71826
2044.24	7.64315
2045.23	8.56148
2046.21	5.8616
2047.19	1.16881
2048.17	-0.729095
2049.16	3.9553
2050.14	3.07975
2051.12	3.12336
2052.11	-2.48628
2053.09	3.14419
2054.07	0.396496
2055.05	2.29527
2056.03	1.35892
2057.01	5.10312
2058	6.0654
2058.98	-0.434391
2059.96	2.4092
2060.94	0.542633
2061.92	2.44904
2062.9	2.4776
2063.88	0.647018
2064.86	1.61917
2065.84	0.737099
2066.82	1.71984
2067.8	-1.06049
2068.78	-2.90217
2069.76	5.56918
2070.73	2.76966
2071.71	3.7581
2072.69	0.0700188
2073.67	4.79554
2074.65	2.00499
2075.63	3.01892
2076.6	-0.689953
2077.58	2.14949
2078.56	4.99688
2079.54	4.10192
2080.51	-0.556271
2081.49	0.414867
2082.47	2.3322
2083.45	-0.469742
2084.42	0.501251
2085.4	2.4215
2086.37	0.571995
2087.35	-5.04811
2088.32	1.61462
2089.3	0.704296
2090.28	0.758698
2091.25	-1.09435
2092.23	-1.98632
2093.2	-1.91443
2094.18	1.95005
2095.15	2.93965
2096.13	-0.850067
2097.1	-0.826744
2098.07	0.134583
2099.05	-1.73936
2100.02	-1.71118
2101	-0.72242
2101.97	0.281788
2102.94	-0.636929
2103.92	-0.619835
2104.89	-1.52853
2105.86	-1.47188
2106.83	-2.37325
2107.8	1.46608
2108.78	2.41569
2109.75	-0.398304
2110.72	-5.10578
2111.69	-3.17282
2112.66	-1.24728
2113.63	-0.243065
2114.61	-0.202061
2115.58	-2.06696
2116.55	-0.145081
2117.52	-1.07106
2118.49	-0.0978813
2119.46	0.853699
2120.43	1.81234
2121.4	1.85727
2122.37	0.0282097
2123.34	1.03384
2124.31	2.0176
2125.28	0.112801
2126.25	0.103909
2127.21	0.111107
2128.18	-6.48337
2129.15	0.16629
2130.12	-3.58463
2131.09	0.223286
2132.06	4.01863
2133.02	4.03393
2133.99	-4.42324
2134.96	-0.609543
2135.93	1.3079
2136.89	-0.571854
2137.86	0.414833
2138.83	-0.502613
2139.79	2.37037
2140.76	-1.38992
2141.73	-1.36109
2142.69	0.542225
2143.66	2.48832
2144.62	-0.364334
2145.59	-0.326294
2146.55	0.644272
2147.52	4.42602
2148.48	-0.251759
2149.45	2.58086
2150.42	-0.236286
2151.38	2.6038
2152.34	0.780777
2153.31	-2.0073
2154.27	-0.113358
2155.24	4.55549
2156.2	0.804165
2157.16	3.62931
2158.13	-4.73265
2159.09	-0.0208035
2160.05	2.79738
2161.01	1.86646
2161.98	-0.910547
2162.94	-4.61033
2163.9	-0.858715
2164.86	3.81189
2165.83	-6.40587
2166.79	-1.72
2167.75	1.0836
2168.71	-4.50743
2169.67	-0.745483
2170.63	-0.675859
2171.59	3.07121
2172.56	-1.60191
2173.51	-1.58158
2174.48	1.24538
2175.44	0.347418
2176.4	1.29979
2177.36	3.17764
2178.32	2.28023
2179.28	-2.35247
2180.23	1.39233
2181.19	5.12904
2182.15	3.28957
2183.11	0.521635
2184.07	-3.18719
2185.03	4.244
2185.99	2.43048
2186.95	-1.22654
2187.9	0.690079
2188.86	0.703098
2189.82	0.695629
2190.78	-4.85429
2191.73	-0.187162
2192.69	-0.151773
2193.65	3.60352
2194.6	2.74842
2195.56	-0.948578
2196.52	1.83082
2197.47	3.67937
2198.43	2.77448
2199.38	2.83494
2200.34	4.76533
2201.3	-0.74275
2202.25	3.82392
2203.21	0.183243
2204.16	3.11506
2205.12	3.07479
2206.07	2.08553
2207.03	3.96199
2207.98	3.07218
2208.93	2.18771
2209.89	0.354393
2210.84	-1.48162
2211.8	0.419664
2212.75	3.25638
2213.7	0.462521
2214.66	-4.1699
2215.61	1.46535
2216.56	3.35142
2217.51	0.563364
2218.47	2.44892
2219.42	0.611557
2220.37	-0.291494
2221.32	2.52092
2222.27	3.43963
2223.23	-3.0794
2224.18	1.63017
2225.13	0.742302
2226.08	1.72242
2227.03	-1.98782
2227.98	-1.02179
2228.93	3.67191
2229.88	-1.93925
2230.83	1.85152
2231.78	-3.74415
2232.73	-1.83157
2233.68	1.96402
2234.63	-0.835991
2235.58	5.73779
2236.53	-1.77979
2237.48	-1.75838
2238.43	2.05984
2239.38	3.05187
2240.33	-4.49619
2241.27	-0.701605
2242.22	4.03436
2243.17	5.94352
2244.12	-1.61113
2245.07	1.24289
2246.01	1.28893
2246.96	-1.51925
2247.91	-0.551716
2248.85	3.23622
2249.8	-2.43305
2250.75	2.30006
2251.69	0.392294
2252.64	-0.538372
2253.59	1.40536
2254.53	1.44111
2255.48	-3.28911
2256.42	0.5184
2257.37	-4.19926
2258.32	-0.38171
2259.26	-0.364746
2260.2	-3.19624
2261.15	-1.27596
2262.1	6.36077
2263.04	-1.23014
2263.98	-0.238111
2264.93	-0.190329
2265.87	1.74578
2266.81	-1.12763
2267.76	-4.00578
2268.7	-2.10834
2269.65	0.777916
2270.59	-2.99956
2271.53	-0.106333
2272.47	-1.04037
2273.42	1.84136
2274.36	-1.01707
2275.3	-1.00462
2276.24	-2.90698
2277.18	-0.959848
2278.13	1.96329
2279.07	0.0694332
2280.01	3.89303
2280.95	1.94847
2281.89	-2.85214
2282.83	-1.87317
2283.77	-0.875311
2284.71	-0.822584
2285.65	0.164623
2286.59	-4.65576
2287.54	-1.7337
2288.47	-0.751257
2289.41	5.97101
2290.35	0.163832
2291.29	-1.75068
2292.23	-0.754089
2293.17	3.12943
2294.11	1.2245
2295.05	1.21456
2295.99	-0.721752
2296.93	-1.70073
2297.86	1.21158
2298.8	-1.64268
2299.74	1.28113
2300.68	0.325109
2301.61	-2.54804
2302.55	-1.57716
2303.49	-3.50421
2304.43	2.30147
2305.36	3.29322
2306.3	1.37924
2307.24	1.39102
2308.17	0.421106
2309.11	1.38958
2310.04	0.455948
2310.98	0.471298
2311.92	-1.50084
2312.85	-0.555941
2313.79	-0.542431
2314.72	-2.43318
2315.66	2.42472
2316.59	1.42364
2317.52	3.34754
2318.46	1.42585
2319.39	0.445734
2320.33	1.4049
2321.26	0.451563
2322.2	2.41246
2323.13	10.169
2324.06	11.1485
2325	20.8054
2325.93	36.2024
2326.86	93.0746
2327.79	400.514
2328.73	216.325
2329.66	53.3799
2330.59	20.6243
2331.52	7.13257
2332.46	2.32354
2333.39	3.26361
2334.32	1.31956
2335.25	5.14055
2336.18	-2.55842
2337.11	4.15878
2338.04	-2.58529
2338.97	1.24535
2339.91	-0.685984
2340.84	0.248146
2341.77	0.200445
2342.7	0.163746
2343.63	3.97816
2344.56	2.0448
2345.49	-0.853222
2346.41	1.0206
2347.34	-0.922979
2348.27	1.92693
2349.2	1.90635
2350.13	2.78921
2351.06	-0.245993
2351.99	1.75263
2352.91	0.719952
2353.84	3.5004
2354.77	-1.29748
2355.7	-0.381107
2356.63	0.509945
2357.55	-5.27543
2358.48	1.31822
2359.41	-1.59406
2360.33	4.03581
2361.26	1.10509
2362.19	2.91262
2363.11	1.87422
2364.04	-1.04497
2364.97	-4.90991