File: Data/3-Raman/processed/bu19w-d-ff2-fi10-v_150 (500nm)_532nm_edge_100%_x100_vis_lwd_h50um_30sx2_01_0.txt
#Acq. time (s)=	30
#Accumulations=	2
#Range (cm-¹)=	100...4000
#Windows=	1
#Auto scanning=	Off
#Autofocus=	Off
#Macrospot=	Off
#AutoExposure=	Off
#Spike filter=	Multiple accum.
#Delay time (s)=	2
#Binning=	1
#Readout mode=	Signal
#DeNoise=	Off
#ICS correction=	On
#Dark correction=	Off
#Inst. Process=	Off
#Detector Gain=	Best Dynamic
#Detector ADC=	50 kHz HS
#Detector temperature (°C)=	-60.09
#Instrument=	LabRAM HR Evol
#Detector=	SIN-EM FIVIS
#Objective=	x100_VIS_LWD
#Grating=	150 (500nm)
#ND Filter=	100%
#Laser=	532nm_Edge
#Hole=	49.98
#Temperature=	0
#Range=	Visible
#StageXY=	75x50mm Scan+
#StageZ=	Z motor
#X (µm)=	0
#Y (µm)=	0
#Z (µm)=	63.2
#Full time(mm:ss)=	1:06
#Project=	21_11_22
#Sample=	BU19w
#Site=
#Title=	BU19w-D-FF2-FI10-V_150 (500nm)_532nm_Edge_100%_x100_VIS_LWD_H50um_30sX2
#Remark=
#Date=	22.11.2021 13:55
#Acquired=	22.11.2021 13:55:25
#Base:Fit=	16.12.2021 17:39:50
#Base:Edit=	16.12.2021 17:41:06
#Base:Edit=	16.12.2021 17:41:07
#Base:Edit=	16.12.2021 17:41:08
#Base:Edit=	16.12.2021 17:41:10
#Base:Edit=	16.12.2021 17:42:39
#Peaks:Remove=	16.12.2021 17:42:51
#Base:Sub=	16.12.2021 17:42:54
103.97	5418.83
108.592	4963.55
113.209	4356.72
117.826	4005.17
122.441	3701.4
127.054	3433.7
131.664	3191.32
136.27	2961.78
140.876	2581.41
145.48	2451.62
150.081	2554.41
154.678	3241.63
159.275	3447.01
163.869	2420.6
168.461	1637.76
173.049	1340.25
177.637	1587.16
182.222	2582.28
186.806	2832.99
191.384	1958.82
195.963	1022.47
200.54	613.359
205.112	419.365
209.684	250.977
214.253	164.349
218.821	4.02625
223.384	42.4521
227.947	275.442
232.507	518.358
237.064	725.935
241.62	1670.04
246.174	1655.76
250.724	921.605
255.273	375.214
259.82	11.0972
264.363	142.106
268.906	1032.52
273.447	3097.64
277.983	4011.99
282.519	2238.65
287.051	788.44
291.583	346.862
296.112	606.471
300.637	1034.46
305.162	688.256
309.685	71.4976
314.204	-66.8674
318.722	102.344
323.236	420.495
327.75	688.477
332.262	402.489
336.77	120.567
341.277	382.015
345.78	886.566
350.283	948.079
354.782	498.092
359.28	118.97
363.775	246.639
368.269	409.773
372.761	231.001
377.249	9.61426
381.736	97.3788
386.22	412.56
390.703	807.748
395.182	947.986
399.661	641.256
404.136	577.441
408.61	1287.2
413.08	2999.23
417.551	3108.88
422.017	1346.61
426.482	360.37
430.944	70.0525
435.406	-13.6727
439.863	-11.2793
444.32	48.1276
448.773	339.951
453.226	529.366
457.674	424.942
462.121	243.084
466.567	139.983
471.009	92.4973
475.452	169.546
479.889	334.476
484.327	500.077
488.761	730.2
493.194	878.236
497.623	853.317
502.051	719.648
506.478	468.822
510.9	335.673
515.323	226.614
519.742	208.919
524.158	208.648
528.574	185.135
532.987	233.299
537.397	262.721
541.807	334.687
546.212	349.614
550.618	449.998
555.019	441.409
559.419	474.762
563.818	397.148
568.213	341.331
572.606	329.412
576.999	426.332
581.388	793.235
585.775	1363.09
590.161	1247.29
594.544	770.689
598.924	738.532
603.304	1123.26
607.68	1579.05
612.055	1393.16
616.426	840.127
620.798	526.455
625.166	387.487
629.532	382.792
633.897	427.352
638.258	500.827
642.618	482.313
646.975	450.452
651.332	512.602
655.685	727.756
660.036	1015.25
664.385	1201.88
668.734	1213.98
673.079	1353.61
677.421	1298.82
681.762	934.577
686.1	628.113
690.439	393.855
694.773	279.575
699.105	226.418
703.435	178.122
707.763	178.139
712.091	139.6
716.415	166.356
720.737	112.307
725.057	133.366
729.375	135.833
733.692	125.614
738.006	141.951
742.317	149.881
746.627	157.901
750.934	179.475
755.24	183.653
759.543	208.049
763.846	381.068
768.146	626.634
772.443	979.553
776.738	1147.89
781.031	946.395
785.322	647.496
789.611	389.541
793.898	287.826
798.183	164.78
802.466	141.553
806.748	121.914
811.027	95.739
815.304	79.5533
819.579	68.7626
823.851	31.7257
828.122	16.6996
832.391	39.1031
836.657	25.0391
840.922	-13.4306
845.184	-8.05029
849.445	12.2557
853.703	74.3996
857.96	143.047
862.214	248.876
866.467	173.781
870.717	31.6403
874.965	7.02362
879.212	-28.6313
883.456	-32.779
887.699	-38.3988
891.939	-31.375
896.177	-44.9689
900.414	-36.1031
904.648	-66.1238
908.88	-68.9429
913.111	-45.3011
917.339	-37.0032
921.565	-52.6152
925.79	-5.30481
930.012	32.1339
934.232	85.537
938.451	195.318
942.667	362.391
946.881	596.075
951.094	543.78
955.302	387.481
959.511	305.12
963.717	303.815
967.921	287.813
972.124	160.787
976.324	89.171
980.523	40.098
984.719	-2.54321
988.914	10.9897
993.104	-20.3859
997.295	-30.0471
1001.48	-9.80939
1005.67	-19.1092
1009.85	9.97681
1014.04	5.93579
1018.22	33.9141
1022.4	93.8779
1026.57	149.338
1030.75	213.222
1034.92	304.917
1039.09	528.928
1043.26	1045.03
1047.42	2017.83
1051.59	2638.52
1055.75	2069.69
1059.91	1234.93
1064.07	783.946
1068.23	694.198
1072.38	761.656
1076.54	1144.5
1080.69	1900.04
1084.84	3043.89
1088.98	3688.99
1093.13	3206.44
1097.27	2380.32
1101.41	2296.6
1105.55	2858.98
1109.69	3045.26
1113.83	2546.62
1117.96	2004.41
1122.09	1739.12
1126.22	1859.23
1130.35	1862.02
1134.47	1614.94
1138.6	1126.46
1142.72	859.116
1146.84	913.032
1150.96	1286.89
1155.07	1633.55
1159.19	1489.73
1163.3	1157.31
1167.41	1008.25
1171.52	832.984
1175.62	491.871
1179.73	271.776
1183.83	177.336
1187.93	140.096
1192.03	130.414
1196.13	144.018
1200.22	160.394
1204.31	111.626
1208.4	73.325
1212.49	152.51
1216.58	317.031
1220.67	505.05
1224.75	457.796
1228.83	310.142
1232.91	364.646
1236.99	440.898
1241.06	440.883
1245.14	354.441
1249.21	385.495
1253.28	324.957
1257.35	291.546
1261.41	260.263
1265.48	636.604
1269.54	1754.66
1273.6	1603.94
1277.66	503.573
1281.72	110.64
1285.77	89.1757
1289.82	59.5567
1293.88	83.1717
1297.92	78.534
1301.97	62.67
1306.02	66.8959
1310.06	44.8643
1314.1	39.7093
1318.14	52.5148
1322.18	50.9865
1326.22	78.4418
1330.25	78.7145
1334.28	47.6514
1338.31	97.612
1342.34	118.352
1346.37	99.1178
1350.39	143.672
1354.42	254.666
1358.44	324.552
1362.46	491.338
1366.47	888.119
1370.49	2208.07
1374.5	3401.14
1378.51	2047.87
1382.52	512.657
1386.53	220.177
1390.54	222.287
1394.54	346.862
1398.55	284.354
1402.55	132.054
1406.55	83.2203
1410.54	35.3832
1414.54	42.7555
1418.53	59.9802
1422.52	12.928
1426.51	29.7249
1430.5	-24.5995
1434.49	42.542
1438.47	21.7703
1442.45	14.7346
1446.43	3.67303
1450.41	0.404358
1454.39	-3.94525
1458.36	14.2533
1462.34	16.4534
1466.31	11.6855
1470.28	13.8688
1474.24	-3.65375
1478.21	20.8864
1482.17	-6.56311
1486.14	23.6545
1490.1	31.3605
1494.05	38.0754
1498.01	24.3643
1501.97	27.3068
1505.92	27.4755
1509.87	28.658
1513.82	40.5201
1517.77	54.3555
1521.71	46.8624
1525.66	57.8187
1529.6	91.1193
1533.54	76.9146
1537.48	50.1039
1541.41	65.9144
1545.35	110.76
1549.28	57.7231
1553.21	97.5854
1557.14	115.021
1561.07	92.6551
1565	98.2631
1568.92	143.405
1572.84	148.845
1576.76	128.166
1580.68	124.826
1584.6	162.844
1588.51	164.163
1592.43	180.828
1596.34	190.708
1600.25	215.962
1604.16	231.675
1608.06	222.442
1611.97	229.533
1615.87	230.951
1619.77	273.484
1623.67	269.156
1627.57	248.655
1631.46	250.386
1635.36	262.62
1639.25	259.683
1643.14	249.245
1647.03	242.685
1650.91	258.199
1654.8	253.485
1658.68	218.914
1662.56	211.053
1666.44	165.568
1670.32	179.438
1674.2	167.252
1678.07	147.977
1681.94	150.56
1685.81	137.705
1689.68	111.308
1693.55	94.4116
1697.41	97.4906
1701.28	90.8617
1705.14	109.792
1709	100.937
1712.86	57.0162
1716.72	90.8467
1720.57	72.6168
1724.42	63.8129
1728.28	74.6634
1732.13	63.9098
1735.97	76.5209
1739.82	59.1
1743.66	61.3212
1747.51	42.4815
1751.35	20.2156
1755.19	63.2189
1759.02	31.9947
1762.86	33.8857
1766.69	47.9512
1770.53	9.3479
1774.36	56.3151
1778.18	15.0304
1782.01	42.7964
1785.84	35.1775
1789.66	29.4259
1793.48	11.4598
1797.3	17.8322
1801.12	33.2795
1804.94	26.9951
1808.75	-1.04932
1812.57	30.1785
1816.38	30.0439
1820.19	-1.40735
1824	20.804
1827.8	29.6351
1831.61	26.9828
1835.41	20.4567
1839.21	5.38141
1843.01	45.6172
1846.81	22.0093
1850.6	17.8932
1854.4	22.9636
1858.19	34.3559
1861.98	6.52155
1865.77	18.7881
1869.56	48.6702
1873.34	20.2844
1877.13	20.6732
1880.91	-11.8969
1884.69	-1.98004
1888.47	27.838
1892.25	-2.07263
1896.02	41.6234
1899.8	21.1506
1903.57	-3.80139
1907.34	4.44922
1911.11	26.7474
1914.88	14.083
1918.64	-2.88605
1922.41	-11.4783
1926.17	-8.86993
1929.93	5.90149
1933.69	-0.695496
1937.44	9.47156
1941.2	1.90057
1944.95	8.39349
1948.7	12.5621
1952.46	-5.08563
1956.2	22.0521
1959.95	21.7411
1963.7	4.49982
1967.44	10.5894
1971.18	10.8162
1974.92	16.5568
1978.66	36.2261
1982.4	12.7672
1986.13	21.0354
1989.87	8.71118
1993.6	20.4934
1997.33	8.93561
2001.06	50.2238
2004.78	26.6404
2008.51	10.386
2012.23	41.1384
2015.96	27.9833
2019.67	21.6532
2023.39	45.0121
2027.11	18.1071
2030.83	46.3522
2034.54	43.801
2038.25	2.72845
2041.96	18.4089
2045.67	39.5919
2049.38	13.3043
2053.08	35.6207
2056.79	23.4134
2060.49	35.4745
2064.19	23.8491
2067.89	38.0514
2071.58	20.0348
2075.28	37.1439
2078.97	21.9645
2082.67	28.0297
2086.36	20.488
2090.05	20.9235
2093.73	20.7451
2097.42	34.4844
2101.1	38.7203
2104.78	19.62
2108.47	43.2255
2112.14	34.2771
2115.82	23.4334
2119.5	30.9719
2123.17	41.1483
2126.84	11.393
2130.52	13.1326
2134.18	40.7409
2137.85	34.0458
2141.52	42.0412
2145.18	55.5089
2148.84	44.1467
2152.51	22.7828
2156.17	53.7146
2159.82	35.2885
2163.48	40.7693
2167.14	32.6907
2170.79	44.0134
2174.44	39.1207
2178.09	49.7998
2181.74	48.66
2185.38	48.5795
2189.03	43.3133
2192.67	21.0114
2196.32	47.1299
2199.96	46.025
2203.59	45.944
2207.23	20.3896
2210.87	34.2291
2214.5	42.6629
2218.13	41.0522
2221.76	39.4832
2225.39	46.1856
2229.02	19.7143
2232.65	17.2508
2236.27	25.8903
2239.89	10.4523
2243.51	29.3123
2247.13	21.2988
2250.75	26.3741
2254.37	24.0674
2257.98	5.86743
2261.59	25.9449
2265.2	18.0029
2268.81	9.22858
2272.42	29.5054
2276.03	14.7949
2279.64	11.0582
2283.24	38.4214
2286.84	14.8234
2290.44	3.41846
2294.04	9.05231
2297.64	-1.37
2301.23	31.711
2304.83	37.2254
2308.42	29.3997
2312.01	109.659
2315.6	390.732
2319.19	381.562
2322.77	100.266
2326.36	22.7213
2329.94	22.754
2333.52	37.8078
2337.1	-1.849
2340.68	34.7166
2344.26	34.5075
2347.83	54.8749
2351.41	20.9231
2354.98	5.74255
2358.55	40.8907
2362.12	14.5522
2365.69	22.6808
2369.25	6.82764
2372.82	9.5105
2376.38	5.72913
2379.94	5.71429
2383.5	30.5957
2387.06	18.7436
2390.61	35.4743
2394.17	16.5632
2397.72	17.0917
2401.27	13.2957
2404.82	31.5851
2408.37	42.7322
2411.92	5.38348
2415.47	21.3601
2419.01	40.208
2422.55	17.7468
2426.09	23.9388
2429.63	53.3601
2433.17	28.3166
2436.71	45.933
2440.24	28.2695
2443.78	35.7181
2447.31	47.0197
2450.84	19.0425
2454.37	41.422
2457.89	21.9973
2461.42	25.0489
2464.94	22.083
2468.47	46.7529
2471.99	41.5207
2475.51	61.536
2479.03	50.5121
2482.54	52.5121
2486.06	30.6863
2489.57	37.2765
2493.08	49.2745
2496.59	43.5221
2500.1	39.5379
2503.61	75.606
2507.12	27.5316
2510.62	48.4884
2514.12	62.0346
2517.62	48.7086
2521.12	49.8912
2524.62	49.6697
2528.12	41.2403
2531.61	61.478
2535.11	50.441
2538.6	57.0131
2542.09	52.7094
2545.58	40.2826
2549.07	57.4001
2552.55	67.2256
2556.04	59.7012
2559.52	53.0332
2563	70.6971
2566.48	77.367
2569.96	57.063
2573.44	42.3226
2576.91	51.9878
2580.39	41.9032
2583.86	68.6033
2587.33	44.1027
2590.8	59.1176
2594.27	57.8601
2597.74	43.3368
2601.2	55.4854
2604.67	32.8654
2608.13	58.7451
2611.59	50.6276
2615.05	47.4807
2618.51	59.4655
2621.96	64.6012
2625.42	66.6816
2628.87	56.1628
2632.32	50.305
2635.77	66.3242
2639.22	53.4605
2642.67	33.7957
2646.11	69.5014
2649.56	53.4713
2653	50.6566
2656.44	63.8493
2659.88	48.4722
2663.32	64.2563
2666.76	48.8035
2670.19	48.3893
2673.63	63.9563
2677.06	38.2744
2680.49	66.0137
2683.92	52.7017
2687.35	46.1948
2690.78	40.7776
2694.2	33.3404
2697.63	40.8572
2701.05	51.1414
2704.47	44.6037
2707.89	58.8214
2711.31	41.4623
2714.72	31.5728
2718.14	30.0951
2721.55	18.3655
2724.96	41.1514
2728.37	35.925
2731.78	30.6113
2735.19	19.615
2738.6	38.5533
2742	34.8576
2745.41	25.3967
2748.81	38.4485
2752.21	41.0882
2755.61	24.7864
2759	22.5741
2762.4	30.5489
2765.8	17.6772
2769.19	27.2896
2772.58	27.3929
2775.97	17.9455
2779.36	13.0943
2782.75	22.2766
2786.13	21.9741
2789.52	23.4848
2792.9	-9.84073
2796.28	24.4317
2799.66	13.4884
2803.04	6.26407
2806.42	16.7848
2809.79	2.8743
2813.17	-10.1542
2816.54	-17.6255
2819.91	-6.40298
2823.28	7.61499
2826.65	-15.6923
2830.02	11.349
2833.38	2.07971
2836.75	-3.43002
2840.11	-15.4177
2843.47	-22.6918
2846.83	-22.3997
2850.19	-8.94864
2853.55	-3.05878
2856.91	-21.4506
2860.26	-21.135
2863.61	-9.59286
2866.96	-14.9442
2870.31	-36.3496
2873.66	-6.13492
2877.01	-12.621
2880.36	-34.2495
2883.7	-21.1012
2887.05	0.512146
2890.39	-26.0716
2893.73	-19.7719
2897.07	-19.2501
2900.4	-37.7676
2903.74	-40.3122
2907.07	-11.7111
2910.41	0.721924
2913.74	-16.2483
2917.07	-32.3923
2920.4	-24.9548
2923.73	-26.1118
2927.05	-4.7135
2930.38	-18.3782
2933.7	-17.0597
2937.02	-9.18524
2940.34	-22.0898
2943.66	-5.8158
2946.98	-26.2717
2950.3	4.94592
2953.61	1.33441
2956.92	22.1956
2960.24	6.46838
2963.55	20.7616
2966.86	13.6227
2970.16	15.0417
2973.47	22.0544
2976.78	42.3201
2980.08	36.2007
2983.38	29.1559
2986.68	33.3962
2989.98	56.4218
2993.28	53.1716
2996.58	42.4199
2999.87	97.4625
3003.17	99.8445
3006.46	111.689
3009.75	104.738
3013.04	114.748
3016.33	129.45
3019.62	159.234
3022.91	138.077
3026.19	144.287
3029.47	165.596
3032.75	181.206
3036.03	208.14
3039.31	200.093
3042.59	243.165
3045.87	251.246
3049.14	274.482
3052.42	266.489
3055.69	278.368
3058.96	315.548
3062.23	364.273
3065.49	369.24
3068.76	374.989
3072.03	418.441
3075.29	432.826
3078.55	435.327
3081.81	521.477
3085.07	498.488
3088.33	564.182
3091.59	596.997
3094.85	621.176
3098.1	644.477
3101.35	701.66
3104.61	688.314
3107.85	795.672
3111.1	818.755
3114.35	815.352
3117.6	870.103
3120.84	940.134
3124.09	989.226
3127.33	1023.04
3130.57	1052.16
3133.81	1136.54
3137.05	1188.44
3140.28	1218.41
3143.52	1256.04
3146.75	1323.4
3149.99	1367.03
3153.22	1447.79
3156.45	1489.56
3159.68	1562.76
3162.9	1586.43
3166.13	1640.43
3169.35	1703.81
3172.58	1819.6
3175.8	1861.69
3179.02	1900.88
3182.24	1988.83
3185.46	2028.75
3188.67	2078.12
3191.89	2099.85
3195.1	2192.06
3198.32	2215.6
3201.53	2255.48
3204.74	2329.75
3207.95	2372.77
3211.15	2403.67
3214.36	2455.79
3217.56	2506.05
3220.77	2565
3223.97	2588.24
3227.17	2592.55
3230.37	2586.78
3233.57	2618.79
3236.76	2694.54
3239.96	2712.51
3243.15	2746.01
3246.35	2738.59
3249.54	2788.83
3252.73	2808.76
3255.92	2848.79
3259.1	2869.27
3262.29	2947.53
3265.47	2930.74
3268.66	2985.26
3271.84	2974.61
3275.02	3041.41
3278.2	3026.24
3281.38	3057.09
3284.55	3133.92
3287.73	3155
3290.9	3153.64
3294.08	3136.95
3297.25	3162.18
3300.42	3291.45
3303.59	3305.31
3306.76	3349.28
3309.92	3350.73
3313.09	3380.44
3316.25	3456.58
3319.41	3538.15
3322.58	3606.44
3325.74	3583.87
3328.9	3670.24
3332.05	3686.96
3335.21	3758.9
3338.36	3804.79
3341.52	3894.12
3344.67	3938.45
3347.82	3943.67
3350.97	4005.39
3354.12	4109.27
3357.26	4175.77
3360.41	4203.46
3363.55	4222.86
3366.7	4379.43
3369.84	4276.88
3372.98	4362.86
3376.12	4469.06
3379.26	4585.24
3382.39	4587.84
3385.53	4654.42
3388.66	4789.37
3391.8	4838.36
3394.93	4848.48
3398.06	4957.08
3401.19	5106.33
3404.31	5180.58
3407.44	5456.07
3410.56	5937.81
3413.69	7217.11
3416.81	10810.9
3419.93	14927.9
3423.05	13573.3
3426.17	8977.61
3429.29	6631.27
3432.41	5855.91
3435.52	5492.4
3438.63	5263.63
3441.75	5263.08
3444.86	5133.38
3447.97	5076.28
3451.08	5080.26
3454.18	4989.04
3457.29	4973.24
3460.39	4981.21
3463.5	4953.8
3466.6	4925.77
3469.7	4908.81
3472.8	4848.51
3475.9	4873.88
3479	4855.15
3482.09	4942.51
3485.19	5148.29
3488.28	5290.56
3491.37	5673.46
3494.46	6064.59
3497.55	6842.6
3500.64	7398.14
3503.73	7405.1
3506.81	6842.49
3509.9	6049.27
3512.98	5232.62
3516.06	4722.95
3519.14	4246.19
3522.22	4003
3525.3	3678.48
3528.38	3465.48
3531.46	3299.79
3534.53	3174.47
3537.6	3159.79
3540.67	2941.62
3543.75	2840.31
3546.82	2748.69
3549.88	2642.84
3552.95	2560.16
3556.02	2423.2
3559.08	2422.61
3562.14	2305.76
3565.21	2195.97
3568.27	2174.4
3571.33	2047.09
3574.39	1998.65
3577.44	2004.09
3580.5	1869.95
3583.55	1805.79
3586.61	1751.19
3589.66	1692.53
3592.71	1589.37
3595.76	1577.99
3598.81	1488.1
3601.85	1444.47
3604.9	1425.36
3607.95	1322.15
3610.99	1338.09
3614.03	1256.68
3617.07	1201.02
3620.11	1144.62
3623.15	1040.31
3626.19	984.358
3629.22	937.827
3632.26	896.915
3635.29	848.05
3638.33	775.955
3641.36	703.138
3644.39	691.966
3647.42	587.204
3650.44	572.264
3653.47	513.927
3656.5	423.875
3659.52	394.761
3662.54	337.168
3665.56	295.946
3668.58	256.858
3671.6	206.469
3674.62	162.701
3677.64	105.719
3680.65	74.1475
3683.67	40.6586
3686.68	35.5425
3689.69	28.5515
3692.7	-31.4911
3695.71	-25.3914
3698.72	-42.8585
3701.73	-83.1387
3704.73	-87.3847
3707.74	-95.518
3710.74	-91.3452
3713.74	-111.984
3716.75	-105.965
3719.75	-126.672
3722.74	-130.308
3725.74	-130.195
3728.74	-150.128
3731.73	-139.646
3734.73	-136.853
3737.72	-140.78
3740.71	-144.775
3743.7	-133.604
3746.69	-130.113
3749.68	-120.033
3752.66	-119.488
3755.65	-134.145
3758.63	-137.443
3761.62	-130.379
3764.6	-134.71
3767.58	-133.37
3770.56	-120.689
3773.54	-119.38
3776.51	-126.599
3779.49	-109.28
3782.46	-106.187
3785.44	-86.1361
3788.41	-97.2805
3791.38	-97.1008
3794.35	-93.1786
3797.32	-92.1407
3800.29	-92.0712
3803.25	-91.1146
3806.22	-84.5576
3809.18	-70.4943
3812.14	-91.4786
3815.11	-66.2069
3818.07	-59.9155
3821.03	-37.6059
3823.98	-70.2872
3826.94	-61.3892
3829.9	-50.6869
3832.85	-58.0735
3835.8	-39.912
3838.76	-45.5922
3841.71	-26.6605
3844.66	-30.6502
3847.61	-43.32
3850.55	-17.0142
3853.5	-22.2659
3856.45	-11.4045
3859.39	-20.7163
3862.33	-15.8349
3865.27	-6.27994
3868.21	-8.3634
3871.15	5.71738
3874.09	1.44266
3877.03	-11.646
3879.96	0.0675659
3882.9	4.89331
3885.83	18.2153
3888.77	15.0504
3891.7	28.0821
3894.63	7.27786
3897.56	10.3385
3900.48	10.3688
3903.41	31.3613
3906.34	27.2552
3909.26	16.247
3912.18	36.775
3915.1	31.1803
3918.02	22.6245
3920.94	26.338
3923.86	31.7794
3926.78	36.073
3929.7	38.2669
3932.61	24.0955
3935.52	21.3258
3938.44	13.6713
3941.35	7.74057
3944.26	24.6408
3947.17	5.98346
3950.08	27.398
3952.98	23.7646
3955.89	17.1188
3958.79	17.0255
3961.7	19.655
3964.6	5.83447
3967.5	11.9972
3970.4	15.1293
3973.3	-3.99741
3976.2	12.2191
3979.09	-7.30072
3981.99	8.56415
3984.88	6.9429
3987.78	-16.9753
3990.67	-18.0274
3993.56	-22.0782
3996.45	-33.044
3999.34	-19.1353