File: Data/3-Raman/processed/bu19w-a-ff07a-fi04-v_150 (500nm)_532nm_edge_100%_x100_vis_lwd_h50um_30sx2_01_0.txt
#Acq. time (s)=	30
#Accumulations=	2
#Range (cm-¹)=	50...5000
#Windows=	1
#Auto scanning=	Off
#Autofocus=	Off
#Macrospot=	Off
#AutoExposure=	Off
#Spike filter=	Multiple accum.
#Delay time (s)=	2
#Binning=	1
#Readout mode=	Signal
#DeNoise=	Off
#ICS correction=	On
#Dark correction=	Off
#Inst. Process=	Off
#Detector Gain=	Best Dynamic
#Detector ADC=	50 kHz HS
#Detector temperature (°C)=	-60.09
#Instrument=	LabRAM HR Evol
#Detector=	SIN-EM FIVIS
#Objective=	x100_VIS_LWD
#Grating=	150 (500nm)
#ND Filter=	100%
#Laser=	532nm_Edge
#Hole=	49.98
#Temperature=	0
#Range=	Visible
#StageXY=	75x50mm Scan+
#StageZ=	Z motor
#X (µm)=	0
#Y (µm)=	0
#Z (µm)=	-1.5
#Full time(mm:ss)=	1:04
#Project=	21_05_28
#Sample=	BU19w
#Site=
#Title=	BU19w-FF07a-FI04-V_150 (500nm)_532nm_Edge_100%_x100_VIS_LWD_H50um_30sX2
#Remark=
#Date=	28.05.2021 19:24
#Acquired=	28.05.2021 19:24:00
#Base:Fit=	16.12.2021 17:39:50
#Base:Edit=	16.12.2021 17:57:14
#Base:Edit=	16.12.2021 17:57:15
#Base:Edit=	16.12.2021 17:57:19
#Base:Edit=	16.12.2021 17:57:20
#Base:Sub=	16.12.2021 17:57:22
51.5961	56554.9
56.2453	49291.4
60.8921	36317.9
65.5367	20301.5
70.1768	13228.8
74.8167	9959.64
79.4543	7589.88
84.0897	6000.37
88.7227	4779.95
93.3513	3874.62
97.9798	3251.04
102.606	2836.18
107.23	2396.19
111.851	1869.15
116.469	1549.38
121.086	1316.44
125.7	1225.05
130.313	1112.9
134.921	941.321
139.529	750.528
144.134	599.604
148.738	930.151
153.337	2029.18
157.936	3097.24
162.532	1929.43
167.126	963.968
171.716	825.625
176.306	2150.89
180.894	6603.91
185.477	10707.6
190.06	5931.74
194.64	1794.35
199.219	443.154
203.793	126.376
208.367	80.7111
212.939	115.472
217.506	-5.40027
222.073	-0.607422
226.638	240.874
231.199	563.314
235.759	751.813
240.318	1330.22
244.872	1825.26
249.425	1496.11
253.977	1153.62
258.524	725.123
263.071	958.47
267.616	2306.08
272.156	5522.14
276.697	8228.61
281.233	5785.12
285.769	2697.25
290.303	1891.25
294.832	2890.55
299.361	4645.28
303.886	3982.36
308.411	1951.94
312.934	1069.11
317.452	1003.77
321.97	1571.16
326.484	2423.1
330.998	1856.28
335.507	937.233
340.017	683.136
344.524	848.737
349.027	885.49
353.53	583.408
358.028	259.932
362.527	164.508
367.021	322.381
371.515	337.696
376.004	385.843
380.494	873.778
384.979	1342.32
389.465	1461.73
393.946	1392.73
398.427	953.906
402.903	623.925
407.38	668.733
411.852	1141.86
416.324	1072.11
420.792	457.324
425.26	92.4689
429.723	-51.6172
434.187	-37.4146
438.646	84.9369
443.105	492.798
447.56	1505.66
452.015	2981.74
456.466	2539.29
460.914	1018.72
465.362	351.606
469.807	214.073
474.251	219.353
478.69	325.086
483.13	491.501
487.566	762.429
491.999	964.584
496.432	867.347
500.861	677.405
505.29	494.688
509.715	355.457
514.138	206.975
518.56	202.963
522.979	242.216
527.395	285.315
531.811	390.049
536.223	429.246
540.635	470.822
545.042	465.924
549.448	429.728
553.853	495.31
558.255	521.456
562.654	416.636
567.053	286.241
571.448	214.285
575.841	466.108
580.232	1244.77
584.622	2720.22
589.009	3279.64
593.393	2005.91
597.777	1098.3
602.157	1140.92
606.535	1690.49
610.913	1934.65
615.287	1462.23
619.659	631.344
624.029	239.674
628.398	206.867
632.763	249.743
637.127	402.861
641.488	399.05
645.849	256.281
650.206	158.629
654.561	236.153
658.914	354.477
663.267	538.068
667.615	623.777
671.962	761.775
676.307	852.07
680.649	694.524
684.991	327
689.33	81.1903
693.666	-13.8473
698	-76.9904
702.332	-112.825
706.662	-119.845
710.992	-148.157
715.318	-130.921
719.641	-154.061
723.963	-115.857
728.283	-120.461
732.6	-101.159
736.918	-70.5488
741.231	-57.0072
745.542	35.1921
749.852	84.3329
754.159	199.286
758.464	407.912
762.767	678.056
767.068	1433.65
771.369	2556.23
775.666	3404.68
779.961	3047.54
784.254	1909.44
788.545	1017.66
792.834	497.255
797.12	251.478
801.405	132.599
805.688	24.8977
809.968	-42.6671
814.247	-31.9509
818.524	-123.326
822.798	-109.131
827.071	-114.417
831.341	-148.244
835.612	-169.971
839.878	-165.344
844.142	-104.574
848.405	-134.691
852.665	-92.673
856.923	-124.548
861.18	-69.384
865.434	-98.1792
869.686	-148.199
873.936	-155.509
878.185	-130.178
882.431	-138.024
886.675	-152.859
890.915	-153.018
895.155	-134.051
899.393	-114.272
903.63	-138.696
907.864	-166.841
912.096	-134.512
916.326	-103.769
920.554	-77.6602
924.78	-101.66
929.004	-72.4178
933.227	15.0491
937.447	102.178
941.665	188.69
945.881	330.332
950.095	349.778
954.305	372.789
958.516	474.679
962.724	681.789
966.93	772.886
971.134	595.647
975.337	372.432
979.537	144.425
983.735	111.788
987.93	83.381
992.124	55.1204
996.316	9.78345
1000.51	58.4041
1004.7	71.3186
1008.88	91.8903
1013.06	83.8138
1017.25	179.772
1021.43	218.328
1025.61	283.321
1029.78	390.579
1033.96	624.499
1038.13	925.774
1042.3	1654.6
1046.47	3063.27
1050.63	4418.05
1054.8	3998.01
1058.96	2628.6
1063.12	1668.85
1067.28	1132.2
1071.44	1098.56
1075.59	1428.61
1079.74	2076.22
1083.89	3244.78
1088.04	4227.79
1092.19	4036.08
1096.33	3233.44
1100.48	2824.43
1104.62	3080.97
1108.76	3384.19
1112.89	3174.4
1117.03	2857.15
1121.16	2826.13
1125.29	3065.39
1129.42	3330.41
1133.55	3043.67
1137.68	2417.28
1141.8	1759.88
1145.92	1629.77
1150.04	2046.64
1154.16	2693.61
1158.27	2835.25
1162.39	2161.67
1166.5	1491.06
1170.61	1036.72
1174.72	783.152
1178.82	563.619
1182.93	523.469
1187.03	504.453
1191.13	591.24
1195.23	597.305
1199.33	584.383
1203.42	470.252
1207.51	416.527
1211.6	425.939
1215.69	468.701
1219.78	651.408
1223.86	799.275
1227.95	765.39
1232.03	933.498
1236.11	1365.63
1240.18	1561.67
1244.26	1262.61
1248.33	1060.59
1252.41	863.744
1256.48	596.266
1260.54	530.677
1264.61	776.313
1268.67	2967.16
1272.74	4114.73
1276.8	1608.09
1280.86	465.042
1284.91	290.746
1288.97	243.695
1293.02	260.837
1297.07	229.423
1301.12	247.218
1305.17	217.378
1309.21	179.361
1313.25	215.766
1317.3	180.13
1321.34	208.694
1325.37	202.503
1329.41	205.191
1333.44	188.642
1337.48	221.813
1341.5	259.639
1345.53	240.246
1349.56	251.781
1353.59	358.811
1357.61	447.63
1361.63	447.75
1365.65	632.227
1369.66	2047.78
1373.68	6130.05
1377.69	5221.8
1381.7	1325.97
1385.72	411.996
1389.72	414.369
1393.73	627.771
1397.73	676.529
1401.74	400.103
1405.74	227.876
1409.73	195.612
1413.73	165.393
1417.73	139.089
1421.72	94.951
1425.71	117.757
1429.7	113.29
1433.69	99.0374
1437.67	62.0304
1441.66	78.3419
1445.64	77.6722
1449.62	62.1156
1453.6	107.512
1457.57	51.1892
1461.55	47.9148
1465.52	86.5913
1469.49	50.3878
1473.46	14.3971
1477.43	43.0602
1481.39	52.8815
1485.36	44.9702
1489.32	64.3423
1493.28	55.4286
1497.24	58.2389
1501.19	43.6188
1505.15	37.9559
1509.1	69.521
1513.05	70.9961
1517	85.1321
1520.95	1.36304
1524.9	84.5376
1528.84	85.3083
1532.78	35.7949
1536.72	81.2919
1540.66	53.1406
1544.6	71.4926
1548.53	88.8586
1552.46	87.7941
1556.4	53.6437
1560.32	75.479
1564.25	114.568
1568.18	80.9492
1572.1	84.9589
1576.02	115.965
1579.94	71.5918
1583.86	71.592
1587.78	122.547
1591.69	107.913
1595.61	119.231
1599.52	95.9219
1603.43	118.813
1607.34	176.375
1611.24	122.648
1615.15	129.427
1619.05	137.305
1622.95	127.85
1626.85	174.09
1630.74	138.146
1634.64	176.276
1638.53	115.733
1642.42	123.447
1646.31	122.773
1650.2	147.128
1654.09	162.924
1657.97	111.411
1661.86	121.256
1665.74	109.721
1669.62	111.494
1673.49	104.232
1677.37	104.576
1681.24	116.763
1685.12	119.979
1688.99	105.809
1692.86	89.4946
1696.72	78.777
1700.59	107.039
1704.45	89.1782
1708.31	92.0549
1712.17	107.954
1716.03	103.879
1719.89	89.4491
1723.74	61.876
1727.6	106.82
1731.45	86.5188
1735.3	57.9489
1739.14	126.644
1742.99	59.5337
1746.83	44.926
1750.68	108.184
1754.52	72.3435
1758.36	73.3892
1762.19	72.6139
1766.03	82.1317
1769.86	54.9373
1773.69	72.8673
1777.53	38.7344
1781.35	56.1515
1785.18	59.7944
1789	39.2529
1792.83	58.0273
1796.65	70.3156
1800.47	57.2047
1804.29	83.7732
1808.1	28.3505
1811.92	13.2207
1815.73	45.0272
1819.54	48.0476
1823.35	49.8197
1827.16	34.3885
1830.97	53.5338
1834.77	32.7729
1838.58	49.5012
1842.38	88.5754
1846.18	39.9238
1849.97	75.0078
1853.77	81.3351
1857.56	73.3049
1861.36	65.8519
1865.15	79.6873
1868.93	54.5759
1872.72	59.3279
1876.51	48.568
1880.29	78.5314
1884.07	71.1005
1887.86	23.2225
1891.63	65.0623
1895.41	58.1403
1899.19	49.3732
1902.96	36.5045
1906.73	89.2162
1910.5	75.7657
1914.27	72.8761
1918.04	59.9039
1921.8	29.1616
1925.57	50.2897
1929.33	67.0602
1933.09	44.0181
1936.85	84.2114
1940.6	46.0953
1944.36	33.9893
1948.11	43.3859
1951.87	64.0814
1955.61	35.4973
1959.36	50.4196
1963.11	35.8309
1966.86	55.9203
1970.6	79.3671
1974.34	69.5048
1978.08	46.2931
1981.82	61.2867
1985.56	76.0219
1989.29	72.8417
1993.02	36.8657
1996.75	65.8472
2000.49	46.2317
2004.21	41.5625
2007.94	58.0138
2011.67	48.2849
2015.39	65.3003
2019.11	57.1301
2022.83	76.2041
2026.55	47.4398
2030.27	25.1659
2033.98	83.114
2037.69	36.2124
2041.41	36.7982
2045.12	54.6825
2048.82	55.1987
2052.53	75.1898
2056.24	28.3882
2059.94	58.2578
2063.64	33.8695
2067.34	62.1274
2071.04	60.1831
2074.74	51.791
2078.43	48.0892
2082.13	33.3473
2085.82	35.1042
2089.51	22.4205
2093.2	56.5645
2096.88	14.1799
2100.57	48.7225
2104.25	58.6869
2107.94	22.8613
2111.62	12.896
2115.3	89.3564
2118.97	39.2211
2122.65	65.7253
2126.32	108.61
2129.99	49.2722
2133.66	62.1432
2137.33	23.1376
2141	79.0884
2144.67	36.0789
2148.33	44.6362
2151.99	34.7773
2155.66	79.0854
2159.31	72.9587
2162.97	73.4047
2166.63	37.5491
2170.28	38.4669
2173.94	33.5278
2177.59	51.6349
2181.24	40.7782
2184.89	72.6317
2188.53	74.8046
2192.18	60.1991
2195.82	48.847
2199.46	88.7864
2203.1	87.0062
2206.74	15.1348
2210.38	87.7532
2214.01	74.7036
2217.65	62.6102
2221.28	95.5193
2224.91	79.8629
2228.54	55.7842
2232.16	69.5017
2235.79	56.5859
2239.41	35.2664
2243.04	30.5464
2246.66	54.5544
2250.28	29.4198
2253.89	18.3252
2257.51	53.9807
2261.12	61.6954
2264.74	26.2098
2268.35	48.9125
2271.96	15.6022
2275.57	19.4974
2279.17	22.1216
2282.78	13.537
2286.38	6.81665
2289.98	-15.0466
2293.58	14.9181
2297.18	33.6132
2300.78	44.8132
2304.37	-2.9314
2307.97	40.0164
2311.56	87.5469
2315.15	480.874
2318.74	625.532
2322.33	191.804
2325.91	98.5116
2329.5	37.4342
2333.08	47.1512
2336.66	67.993
2340.24	56.5909
2343.82	30.0552
2347.4	-7.81311
2350.97	15.245
2354.54	37.2251
2358.12	2.13135
2361.69	32.2773
2365.26	0.0239258
2368.82	9.72424
2372.39	48.4154
2375.95	21.2477
2379.52	26.5105
2383.08	31.9257
2386.64	2.50488
2390.19	24.8362
2393.75	8.84229
2397.31	31.7825
2400.86	30.401
2404.41	14.1683
2407.96	6.35156
2411.51	11.9265
2415.06	-11.546
2418.6	2.01379
2422.15	-7.18628
2425.69	23.5303
2429.23	28.8396
2432.77	17.7925
2436.31	22.7572
2439.84	-17.6387
2443.38	1.49207
2446.91	43.1606
2450.44	20.7455
2453.97	23.785
2457.5	-5.04651
2461.03	-1.17908
2464.55	27.1053
2468.08	30.7509
2471.6	4.3313
2475.12	9.7251
2478.64	-5.81689
2482.16	26.005
2485.67	0.795654
2489.19	9.64648
2492.7	10.7435
2496.21	-21.714
2499.72	35.3716
2503.23	9.55444
2506.74	20.9642
2510.25	8.74951
2513.75	25.5228
2517.25	6.34363
2520.75	-9.7616
2524.25	41.8046
2527.75	-8.07629
2531.25	19.1521
2534.74	-15.3079
2538.24	17.0986
2541.73	13.8232
2545.22	-0.808472
2548.71	-32.4366
2552.2	45.0327
2555.68	-23.1788
2559.17	14.7142
2562.65	6.34741
2566.13	15.2782
2569.61	10.6853
2573.09	26.0486
2576.57	2.3938
2580.04	0.479248
2583.51	8.07288
2586.99	-19.2872
2590.46	-9.18579
2593.93	-20.6129
2597.4	3.91174
2600.86	26.0771
2604.33	29.0853
2607.79	19.8341
2611.25	4.65405
2614.71	-0.865723
2618.17	21.0055
2621.63	15.4432
2625.09	23.083
2628.54	39.9792
2631.99	8.64246
2635.45	60.5051
2638.9	26.5756
2642.34	48.017
2645.79	44.2899
2649.24	28.08
2652.68	-3.62744
2656.12	79.5493
2659.56	11.1914
2663.01	26.3369
2666.44	48.8534
2669.88	54.2743
2673.32	19.1732
2676.75	2.28711
2680.18	12.8271
2683.61	23.6257
2687.04	45.1313
2690.47	27.3799
2693.9	-7.57385
2697.32	31.7437
2700.75	22.9344
2704.17	64.4188
2707.59	40.8467
2711.01	47.0582
2714.43	31.2317
2717.84	26.8346
2721.26	32.0162
2724.67	28.0596
2728.08	4.59705
2731.49	47.5563
2734.9	17.5264
2738.31	16.4921
2741.71	36.0392
2745.12	2.78589
2748.52	9.71106
2751.92	16.6696
2755.32	29.1775
2758.72	52.8588
2762.12	53.0481
2765.52	26.5049
2768.91	38.3907
2772.3	21.7942
2775.7	28.6501
2779.09	40.9347
2782.47	18.1978
2785.86	67.8507
2789.25	48.7555
2792.63	65.3575
2796.01	52.7865
2799.4	67.4613
2802.78	63.1443
2806.15	22.3024
2809.53	4.91528
2812.91	40.8311
2816.28	73.8082
2819.65	75.8848
2823.03	63.2445
2826.4	67.6034
2829.76	72.0679
2833.13	24.5398
2836.5	42.5028
2839.86	93.2981
2843.22	59.5957
2846.59	83.9862
2849.95	64.1356
2853.3	59.504
2856.66	36.0243
2860.02	55.7072
2863.37	82.1521
2866.72	46.8505
2870.08	77.1715
2873.43	68.0184
2876.77	86.0784
2880.12	72.1371
2883.47	85.4518
2886.81	102.458
2890.15	102.476
2893.5	80.6847
2896.84	62.322
2900.17	74.0197
2903.51	121.471
2906.85	112.95
2910.18	104.312
2913.52	89.901
2916.85	105.679
2920.18	118.414
2923.51	136.749
2926.83	125.641
2930.16	154.98
2933.48	125.577
2936.81	108.282
2940.13	130.617
2943.45	124.665
2946.77	161.134
2950.09	163.735
2953.4	124.924
2956.72	143.521
2960.03	160.453
2963.34	147.47
2966.65	114.894
2969.96	133.397
2973.27	142.771
2976.58	161.59
2979.88	171.266
2983.19	147.939
2986.49	146.282
2989.79	203.865
2993.09	178.88
2996.39	167.114
2999.68	165.756
3002.98	157.798
3006.27	169.599
3009.57	176.82
3012.86	203.902
3016.15	163.202
3019.43	180.877
3022.72	174.024
3026.01	205.868
3029.29	192.442
3032.57	187.479
3035.86	249.558
3039.14	229.376
3042.41	255.55
3045.69	250.544
3048.97	256.91
3052.24	260.44
3055.52	289.614
3058.79	246.67
3062.06	267.733
3065.33	302.315
3068.6	296.866
3071.86	296.783
3075.13	315.3
3078.39	335.359
3081.65	358.71
3084.91	404.289
3088.17	374.857
3091.43	367.67
3094.69	379.583
3097.95	376.167
3101.2	404.195
3104.45	434.783
3107.7	490.897
3110.95	447.831
3114.2	481.321
3117.45	497.831
3120.7	507.73
3123.94	521.442
3127.18	557.997
3130.43	559.255
3133.67	589.133
3136.91	618.969
3140.14	615.35
3143.38	629.82
3146.61	633.816
3149.85	691.335
3153.08	704.084
3156.31	747.281
3159.54	737.117
3162.77	732.61
3166	781.547
3169.22	774.958
3172.45	798.766
3175.67	790.997
3178.89	867.022
3182.11	869.546
3185.33	868.295
3188.55	915.436
3191.77	921.505
3194.98	931.377
3198.2	994.557
3201.41	978.61
3204.62	997.991
3207.83	1052.65
3211.04	1048.4
3214.25	1013.85
3217.45	1073.64
3220.66	1058.28
3223.86	1080.11
3227.06	1080.27
3230.26	1139.47
3233.46	1150.33
3236.66	1139.15
3239.85	1124.67
3243.05	1186.49
3246.24	1139.87
3249.44	1229.51
3252.63	1152.59
3255.82	1206.36
3259.01	1212.41
3262.19	1241.04
3265.38	1246.42
3268.56	1259.1
3271.75	1210.41
3274.93	1236.08
3278.11	1241.65
3281.29	1318.34
3284.47	1311.48
3287.64	1333.3
3290.82	1316.75
3293.99	1363.32
3297.17	1375.46
3300.34	1382.86
3303.51	1450.82
3306.68	1412.43
3309.84	1430.89
3313.01	1470.78
3316.18	1457.29
3319.34	1508.26
3322.5	1513.55
3325.66	1520.75
3328.82	1499.57
3331.98	1573.98
3335.14	1602.17
3338.29	1608.85
3341.45	1643.08
3344.6	1667.91
3347.75	1639.69
3350.9	1653.63
3354.05	1671.3
3357.2	1647.82
3360.35	1675.38
3363.49	1729.69
3366.64	1792.57
3369.78	1805.64
3372.92	1883.96
3376.06	1892.83
3379.2	1871.61
3382.34	1928.01
3385.48	1991.88
3388.61	2080.68
3391.75	2088.22
3394.88	2175.16
3398.01	2197.87
3401.14	2449.99
3404.27	2770.25
3407.4	3273.88
3410.52	4396.95
3413.65	7457.59
3416.77	14517.7
3419.89	21367.5
3423.01	17026.8
3426.13	8909.17
3429.25	4863.64
3432.37	3319.37
3435.49	2747.06
3438.6	2414.61
3441.72	2259.32
3444.83	2214.68
3447.94	2056.85
3451.05	2063.98
3454.16	2007.77
3457.26	1982.01
3460.37	1978.69
3463.47	1985.76
3466.58	1969.86
3469.68	1978.2
3472.78	1966.08
3475.88	1977.66
3478.98	2049
3482.07	2169.55
3485.17	2299.45
3488.26	2422.81
3491.36	2779.71
3494.45	3144.02
3497.54	3744.8
3500.63	4194.01
3503.72	4291.38
3506.81	3990.1
3509.89	3363.13
3512.98	2731.79
3516.06	2287.37
3519.14	2002.97
3522.22	1808.22
3525.3	1641.54
3528.38	1534.42
3531.45	1464.65
3534.53	1376.34
3537.61	1300.07
3540.68	1255.21
3543.75	1243.45
3546.82	1190.7
3549.89	1119.67
3552.96	1120.8
3556.03	1045.11
3559.09	972.546
3562.16	1000.28
3565.22	951.812
3568.28	921.955
3571.34	910.725
3574.4	854.907
3577.46	826.667
3580.52	852.329
3583.57	805.75
3586.63	780.812
3589.68	773.885
3592.73	732.595
3595.78	760.47
3598.83	710.469
3601.88	670.923
3604.93	612.289
3607.97	651.985
3611.02	589.496
3614.06	612.989
3617.1	548.556
3620.14	605.092
3623.18	549.381
3626.22	499.438
3629.26	513.727
3632.3	445.965
3635.33	486.46
3638.36	449.193
3641.4	426.263
3644.43	382.811
3647.46	353.841
3650.49	338.59
3653.51	345.178
3656.54	357.5
3659.57	285.45
3662.59	312.936
3665.61	254.467
3668.63	246.233
3671.65	210.008
3674.67	193.621
3677.69	163.128
3680.71	186.506
3683.72	192.83
3686.74	164.188
3689.75	118.516
3692.76	137.207
3695.77	102.871
3698.78	98.6072
3701.79	122.095
3704.79	110.49
3707.8	119.754
3710.81	103.229
3713.81	77.0903
3716.81	77.4266
3719.81	111.15
3722.81	105.724
3725.81	109.722
3728.81	64.1005
3731.8	85.0571
3734.8	81.145
3737.79	19.0311
3740.78	33.9556
3743.77	41.1312
3746.76	25.3872
3749.75	49.4819
3752.74	79.1693
3755.73	36.6537
3758.71	49.2501
3761.7	47.5808
3764.68	61.9343
3767.66	29.903
3770.64	27.3312
3773.62	29.5917
3776.6	13.9699
3779.58	49.4503
3782.55	33.968
3785.53	34.567
3788.5	43.7247
3791.47	47.285
3794.44	18.9241
3797.41	28.4048
3800.38	15.2974
3803.35	2.3244
3806.32	15.8443
3809.28	23.7361
3812.24	22.2479
3815.21	-10.4171
3818.17	27.8638
3821.13	19.8503
3824.09	40.2641
3827.04	39.9327
3830	10.2258
3832.96	10.8334
3835.91	31.4733
3838.86	24.6504
3841.82	51.0894
3844.77	44.2654
3847.72	31.7441
3850.67	33.5395
3853.61	45.8871
3856.56	10.5591
3859.5	14.3467
3862.45	36.317
3865.39	41.0421
3868.33	1.72137
3871.27	13.0522
3874.21	39.7179
3877.15	25.1079
3880.09	20.9296
3883.02	32.9748
3885.96	25.6882
3888.89	54.8536
3891.82	10.9189
3894.75	-0.382996
3897.68	32.4285
3900.61	34.3548
3903.54	7.40912
3906.47	23.6141
3909.39	35.1293
3912.31	6.18604
3915.24	14.6351
3918.16	42.2263
3921.08	16.2141
3924	49.5344
3926.92	8.84576
3929.83	21.8038
3932.75	4.04681
3935.67	8.57245
3938.58	5.63959
3941.49	16.2913
3944.4	29.7263
3947.31	14.4958
3950.22	12.772
3953.13	12.0794
3956.04	-9.63867
3958.94	14.7055
3961.85	44.8616
3964.75	-1.59979
3967.65	20.0494
3970.55	37.9321
3973.45	46.2635
3976.35	19.0492
3979.25	38.8263
3982.15	8.58038
3985.04	27.329
3987.94	6.61804
3990.83	24.3411
3993.72	2.51965
3996.61	23.2053
3999.5	43.8895
4002.39	-12.3861
4005.28	25.7062
4008.16	23.4104
4011.05	6.66815
4013.93	21.7237
4016.81	28.1206
4019.7	25.8391
4022.58	36.1045
4025.46	12.5807
4028.33	13.217
4031.21	-4.50525
4034.09	12.601
4036.96	20.0601
4039.84	40.1561
4042.71	13.7557
4045.58	25.933
4048.45	22.6623
4051.32	41.7441
4054.19	44.4059
4057.05	46.1971
4059.92	-18.0839
4062.78	7.8985
4065.65	-0.109985
4068.51	22.0203
4071.37	31.5101
4074.23	8.88116
4077.09	35.8842
4079.95	18.0829
4082.81	13.9128
4085.66	14.6256
4088.52	56.2692
4091.37	21.8198
4094.22	31.3489
4097.07	27.1388
4099.92	10.2767
4102.77	16.8438
4105.62	-9.86536
4108.47	47.4354
4111.31	10.8427
4114.16	-9.23181
4117	14.6475
4119.84	22.7407
4122.69	14.2142
4125.53	17.5435
4128.36	45.3662
4131.2	12.7556
4134.04	27.2682
4136.88	22.4753
4139.71	21.4505
4142.54	22.5775
4145.38	13.1025
4148.21	27.4739
4151.04	12.5562
4153.87	5.26404
4156.69	12.3452
4159.52	21.009
4162.35	17.2737
4165.17	9.74567
4168	45.2436
4170.82	18.1907
4173.64	29.3334
4176.46	13.1202
4179.28	0.822266
4182.1	36.5205
4184.91	14.5493
4187.73	49.3658
4190.54	34.3171
4193.36	60.5119
4196.17	71.1581
4198.98	74.1108
4201.79	68.2086
4204.6	87.85
4207.41	70.1732
4210.22	65.2651
4213.02	71.1282
4215.83	46.5074
4218.63	38.1238
4221.44	35.5779
4224.24	12.2286
4227.04	37.1025
4229.84	57.2336
4232.64	29.942
4235.43	14.584
4238.23	44.8655
4241.02	39.487
4243.82	47.0442
4246.61	45.71
4249.4	40.3268
4252.19	20.8672
4254.98	53.3146
4257.77	35.7139
4260.56	53.1267
4263.35	54.5688
4266.13	23.9107
4268.92	17.3654
4271.7	23.8743
4274.48	24.3228
4277.26	21.5732
4280.04	63.1272
4282.82	25.8614
4285.6	22.8341
4288.38	37.9086
4291.15	32.6593
4293.93	14.2036
4296.7	19.1484
4299.47	28.2193
4302.25	-8.42712
4305.02	20.8452
4307.79	1.40466
4310.55	40.9077
4313.32	50.0379
4316.09	35.6432
4318.85	39.4728
4321.62	24.9243
4324.38	29.6433
4327.14	7.84662
4329.9	52.2742
4332.66	-11.356
4335.42	36.0961
4338.18	43.7368
4340.94	36.2512
4343.69	36.9183
4346.45	22.3728
4349.2	31.3532
4351.95	50.5518
4354.7	40.3709
4357.45	33.1454
4360.2	35.1143
4362.95	17.5877
4365.7	44.1529
4368.44	17.389
4371.19	48.0942
4373.93	31.4886
4376.68	34.3491
4379.42	-0.854736
4382.16	28.6109
4384.9	19.0967
4387.64	6.65741
4390.37	34.6428
4393.11	33.9515
4395.85	8.04388
4398.58	22.8417
4401.31	44.8826
4404.05	22.3149
4406.78	17.3731
4409.51	38.4234
4412.24	33.4191
4414.96	29.3262
4417.69	34.5655
4420.42	53.0369
4423.14	36.2105
4425.87	37.1497
4428.59	5.70032
4431.31	55.7579
4434.03	15.8765
4436.75	52.3364
4439.47	51.0798
4442.19	43.4491
4444.91	21.1413
4447.62	55.4249
4450.34	31.9932
4453.05	60.9841
4455.76	20.6351
4458.47	33.7851
4461.19	44.8039
4463.89	13.8585
4466.6	60.7174
4469.31	37.139
4472.02	29.3629
4474.72	25.8536
4477.43	27.6718
4480.13	7.39008
4482.83	50.4612
4485.53	37.5908
4488.23	32.0359
4490.93	19.0317
4493.63	44.9918
4496.33	28.4957
4499.02	39.6579
4501.72	12.6376
4504.41	43.8278
4507.11	54.9623
4509.8	59.7593
4512.49	39.0898
4515.18	21.5995
4517.87	61.4612
4520.56	36.5662
4523.24	57.4359
4525.93	50.658
4528.61	73.6627
4531.3	41.3158
4533.98	41.9856
4536.66	36.2722
4539.34	28.4349
4542.02	63.3604
4544.7	30.9608
4547.38	23.1404
4550.05	23.8758
4552.73	50.4031
4555.4	67.4413
4558.08	25.5201
4560.75	54.7104
4563.42	38.832
4566.09	19.8646
4568.76	31.3057
4571.43	43.4409
4574.1	32.024
4576.77	30.0762
4579.43	38.2312
4582.1	39.0743
4584.76	16.0773
4587.42	39.505
4590.08	28.02
4592.74	27.3539
4595.4	55.1151
4598.06	33.8232
4600.72	16.8006
4603.38	38.1692
4606.03	21.2831
4608.69	6.55823
4611.34	13.7529
4613.99	27.5175
4616.64	21.5082
4619.29	45.2194
4621.94	-8.07996
4624.59	36.5884
4627.24	34.9415
4629.89	40.9843
4632.53	2.80304
4635.18	23.0718
4637.82	24.506
4640.46	0.464966
4643.1	21.8149
4645.74	3.43347
4648.38	58.4165
4651.02	13.685
4653.66	21.3641
4656.3	35.4593
4658.93	12.0806
4661.57	8.10114
4664.2	18.7343
4666.83	10.2866
4669.46	3.91028
4672.09	22.207
4674.72	15.8593
4677.35	21.8255
4679.98	25.5377
4682.61	18.0016
4685.23	39.6744
4687.86	29.8792
4690.48	29.08
4693.1	28.2841
4695.73	22.9177
4698.34	7.37805
4700.96	24.563
4703.58	21.4133
4706.2	-1.01276
4708.82	37.5756
4711.43	36.5798
4714.05	11.802
4716.66	8.48712
4719.28	22.1303
4721.89	36.8917
4724.5	49.363
4727.11	5.22888
4729.72	34.8378
4732.33	9.99005
4734.93	6.69781
4737.54	5.64795
4740.14	30.7067
4742.75	9.13495
4745.35	51.2036
4747.95	13.5991
4750.55	31.6555
4753.15	9.90344
4755.75	-2.75958
4758.35	18.7209
4760.95	23.1888
4763.54	35.6743
4766.14	23.1459
4768.73	5.04669
4771.33	12.0649
4773.92	18.9685
4776.51	20.1846
4779.1	-9.42548
4781.69	-12.7911
4784.28	14.709
4786.87	15.943
4789.45	9.17639
4792.04	11.5854
4794.63	6.00867
4797.21	18.785
4799.79	12.1491
4802.37	2.10284
4804.95	19.6563
4807.53	6.2818
4810.11	9.0387
4812.69	7.19238
4815.27	9.99231
4817.84	-10.2481
4820.42	28.4689
4822.99	7.09589
4825.57	16.9777
4828.14	-9.09314
4830.71	20.555
4833.28	25.9142
4835.85	8.01788
4838.42	14.6492
4840.98	4.9975
4843.55	-12.8962
4846.12	38.2337
4848.68	29.584
4851.24	32.4943
4853.81	0.951599
4856.37	30.6409
4858.93	5.60919
4861.49	4.06537
4864.05	10.64
4866.61	18.2313
4869.16	29.4336
4871.72	1.7301
4874.27	21.2526
4876.83	18.2302
4879.38	6.91138
4881.93	40.678
4884.49	16.2561
4887.04	0.139954
4889.58	25.6656
4892.13	11.969
4894.68	13.735
4897.23	-5.94067
4899.77	2.97809
4902.32	-11.9375
4904.86	25.6508
4907.4	22.683
4909.95	24.4962
4912.49	17.8525
4915.03	23.1382
4917.57	24.815
4920.1	9.85477
4922.64	33.1495
4925.18	21.8321
4927.71	11.773
4930.25	18.407
4932.78	19.2366
4935.31	30.9616
4937.84	40.2736
4940.38	29.265
4942.9	39.5995
4945.43	26.2217
4947.96	29.7233
4950.49	26.0512
4953.01	17.6587
4955.54	36.8219
4958.06	60.9391
4960.59	40.7249
4963.11	38.5986
4965.63	49.8854
4968.15	45.6713
4970.67	14.8023
4973.19	75.6288
4975.71	54.438
4978.22	45.3319
4980.74	42.328
4983.25	33.3091
4985.77	26.7599
4988.28	36.0307
4990.79	62.3825
4993.3	12.2024
4995.81	49.5946
4998.32	49.4207