File: Data/3-Raman/processed/bu19w-e-ff11-fi10-v_150 (500nm)_633nm_edge_100%_x100_vis_h50um_60sx2_01_0.txt
#Acq. time (s)=	60
#Accumulations=	2
#Range (cm-¹)=	100...4000
#Windows=	1
#Auto scanning=	Off
#Autofocus=	Off
#Macrospot=	Off
#AutoExposure=	Off
#Spike filter=	Multiple accum.
#Delay time (s)=	2
#Binning=	1
#Readout mode=	Signal
#DeNoise=	Off
#ICS correction=	On
#Dark correction=	Off
#Inst. Process=	Off
#Detector Gain=	Best Dynamic
#Detector ADC=	50 kHz HS
#Detector temperature (°C)=	-60.09
#Instrument=	LabRAM HR Evol
#Detector=	SIN-EM FIVIS
#Objective=	x100_VIS
#Grating=	150 (500nm)
#ND Filter=	100%
#Laser=	633nm_Edge
#Hole=	49.98
#Temperature=	0
#Range=	Visible
#StageXY=	75x50mm Scan+
#StageZ=	Z motor
#X (µm)=	0
#Y (µm)=	0
#Z (µm)=	-270.9
#Full time(mm:ss)=	2:05
#Project=	21_11_04
#Sample=	BU19w
#Site=
#Title=	BU19w-E-FF11-FI10-V_150 (500nm)_633nm_Edge_100%_x100_VIS_H50um_60sX2
#Remark=
#Date=	04.11.2021 11:53
#Acquired=	04.11.2021 11:53:51
#Base:Fit=	16.12.2021 17:39:50
#Base:Edit=	16.12.2021 17:54:28
#Base:Edit=	16.12.2021 17:54:29
#Base:Edit=	16.12.2021 17:54:29
#Base:Edit=	16.12.2021 17:54:29
#Base:Edit=	16.12.2021 17:54:30
#Base:Edit=	16.12.2021 17:54:30
#Base:Edit=	16.12.2021 17:54:31
#Base:Edit=	16.12.2021 17:54:31
#Base:Edit=	16.12.2021 17:54:32
#Base:Edit=	16.12.2021 17:54:32
#Base:Sub=	16.12.2021 17:54:45
102.881	150.15
109.397	115.077
115.908	83.8662
122.414	77.5016
128.914	76.9468
135.409	76.4241
141.898	65.3941
148.383	57.3475
154.861	60.9013
161.335	61.6813
167.801	91.2799
174.264	53.7688
180.721	30.6047
187.173	18.9158
193.62	14.894
200.061	20.536
206.496	3.46673
212.926	4.54401
219.352	11.39
225.772	26.8044
232.185	47.8295
238.595	108.833
244.999	68.223
251.397	30.5535
257.791	25.1982
264.178	24.6516
270.561	34.592
276.939	20.8727
283.31	43.1761
289.678	47.4302
296.039	26.0838
302.396	1.00819
308.746	24.1797
315.093	36.0087
321.433	89.3908
327.768	172.988
334.099	138.695
340.423	61.0287
346.743	38.0667
353.058	33.9478
359.367	56.1505
365.671	48.2035
371.971	47.796
378.265	16.4159
384.553	14.1997
390.837	9.33051
397.116	10.1927
403.389	8.33008
409.657	13.9805
415.92	12.0146
422.178	14.7356
428.431	26.6547
434.678	34.586
440.921	53.7502
447.158	44.6266
453.391	42.0673
459.618	58.2682
465.84	54.9986
472.057	22.9363
478.27	18.9407
484.477	17.7299
490.679	23.0356
496.876	19.9591
503.068	23.4189
509.255	27.8208
515.436	28.5175
521.613	45.1747
527.785	40.4063
533.952	47.9002
540.113	49.7631
546.27	31.7015
552.423	33.2859
558.568	23.4714
564.711	23.8485
570.848	11.8801
576.979	11.1382
583.107	16.9526
589.228	20.0005
595.345	31.5341
601.458	46.0133
607.565	41.0735
613.667	45.5265
619.764	53.8512
625.856	46.2825
631.944	43.1882
638.026	29.4746
644.104	30.6571
650.177	25.2338
656.244	43.1724
662.308	24.5041
668.365	20.8768
674.418	15.5824
680.467	18.7319
686.511	8.89247
692.549	6.59633
698.582	15.5515
704.611	16.9996
710.635	14.6162
716.655	11.0901
722.669	5.6941
728.679	13.3633
734.683	9.72852
740.683	7.0349
746.678	8.10031
752.669	13.8697
758.654	1.98616
764.635	9.84921
770.611	9.3856
776.582	11.7253
782.549	10.2292
788.511	19.0269
794.466	7.97565
800.419	7.213
806.366	16.7429
812.309	3.62356
818.247	16.7762
824.18	14.8505
830.108	15.7469
836.033	16.8155
841.952	8.6786
847.865	19.2804
853.776	11.1771
859.681	11.5337
865.58	21.3414
871.476	19.8074
877.366	27.6329
883.253	32.5615
889.134	27.9221
895.012	31.7573
900.883	31.6693
906.751	32.4507
912.614	28.4918
918.473	31.1853
924.326	32.1327
930.174	28.5259
936.019	40.0721
941.859	41.4763
947.693	51.4639
953.525	71.051
959.35	77.3051
965.171	76.7621
970.988	87.6308
976.801	96.4126
982.608	156.71
988.411	181.286
994.209	169.393
1000	137.549
1005.79	99.2285
1011.58	84.0324
1017.36	91.8391
1023.13	102.606
1028.9	105.916
1034.67	91.0445
1040.43	67.47
1046.19	65.9824
1051.94	55.6637
1057.69	52.0096
1063.44	40.4517
1069.17	45.2669
1074.91	38.4222
1080.64	41.2314
1086.37	59.5294
1092.09	73.9718
1097.8	100.968
1103.52	124.087
1109.22	94.1694
1114.93	69.293
1120.63	59.0194
1126.32	57.3401
1132.01	48.8458
1137.7	64.8031
1143.38	75.9111
1149.06	89.8813
1154.73	129.358
1160.4	94.7793
1166.06	50.2326
1171.72	42.1278
1177.38	24.2465
1183.03	21.128
1188.67	20.0898
1194.31	22.0673
1199.95	15.3371
1205.58	7.71915
1211.21	6.99065
1216.84	3.32934
1222.46	5.63498
1228.07	2.96544
1233.68	6.2473
1239.29	4.45213
1244.89	8.60091
1250.49	3.57729
1256.08	15.6627
1261.67	15.5148
1267.26	7.28049
1272.84	6.07496
1278.42	17.8919
1283.99	90.7736
1289.56	8.45255
1295.12	6.33099
1300.68	0.266602
1306.23	3.27817
1311.78	1.39459
1317.33	6.59856
1322.87	3.79111
1328.41	9.1029
1333.94	1.2164
1339.47	6.5047
1345	1.51093
1350.52	5.68758
1356.04	7.79051
1361.55	2.64967
1367.06	8.74734
1372.56	14.8083
1378.06	13.6752
1383.56	56.6733
1389.05	63.7164
1394.53	5.1682
1400.02	12.403
1405.5	10.391
1410.97	12.524
1416.44	4.36389
1421.91	4.46428
1427.37	1.46701
1432.83	3.66281
1438.28	2.73133
1443.73	3.88367
1449.17	6.05714
1454.62	2.91222
1460.05	1.80584
1465.48	6.95737
1470.91	0.542465
1476.34	3.5936
1481.76	0.380928
1487.17	7.69707
1492.59	6.65304
1497.99	9.86246
1503.4	1.49415
1508.8	5.82354
1514.19	2.7714
1519.59	0.794754
1524.97	3.09581
1530.36	6.48646
1535.74	4.53567
1541.11	7.89452
1546.48	1.42847
1551.85	-0.841461
1557.21	9.75328
1562.57	10.6313
1567.93	5.03545
1573.28	2.67833
1578.62	8.98108
1583.97	12.1005
1589.3	7.709
1594.64	10.8949
1599.97	11.9705
1605.3	7.68761
1610.62	5.61839
1615.94	9.04518
1621.25	10.3465
1626.56	11.6502
1631.87	15.1522
1637.17	2.04925
1642.47	2.01784
1647.76	11.9654
1653.05	11.9317
1658.34	7.41569
1663.62	6.19271
1668.9	12.7122
1674.18	5.91569
1679.45	6.86428
1684.71	11.0878
1689.98	8.64912
1695.23	7.37402
1700.49	9.54779
1705.74	0.934792
1710.99	10.9293
1716.23	7.46181
1721.47	14.2705
1726.7	4.1779
1731.94	0.826981
1737.16	4.20348
1742.39	1.94901
1747.61	7.57951
1752.82	12.0518
1758.03	15.3594
1763.24	7.29505
1768.44	1.50211
1773.64	9.31671
1778.84	3.56546
1784.03	5.79606
1789.22	3.51634
1794.41	16.0865
1799.59	12.7263
1804.76	4.77839
1809.94	10.5572
1815.11	3.65772
1820.27	2.50458
1825.43	3.66833
1830.59	3.68552
1835.74	7.20475
1840.89	14.1926
1846.04	3.66117
1851.18	15.305
1856.32	7.03469
1861.45	7.00171
1866.58	6.99152
1871.71	15.1978
1876.83	5.6927
1881.95	5.59544
1887.07	7.83929
1892.18	12.3784
1897.29	-0.827438
1902.39	9.70116
1907.49	6.11581
1912.59	8.54148
1917.68	3.86425
1922.77	6.13564
1927.86	3.70554
1932.94	10.8532
1938.02	8.39135
1943.09	8.29372
1948.16	9.36976
1953.23	5.58463
1958.29	10.2056
1963.35	8.78345
1968.41	9.73965
1973.46	11.8566
1978.51	10.3584
1983.55	12.4669
1988.59	9.77394
1993.63	2.28577
1998.66	6.84113
2003.69	7.81678
2008.72	8.82919
2013.74	0.236092
2018.76	15.712
2023.77	8.31448
2028.78	6.9885
2033.79	6.91562
2038.79	4.43013
2043.79	9.23148
2048.79	6.76785
2053.78	9.12594
2058.77	10.302
2063.76	6.60262
2068.74	11.4754
2073.72	-4.54889
2078.69	1.52818
2083.66	12.5418
2088.63	7.47533
2093.59	9.86709
2098.55	9.84083
2103.51	8.58718
2108.46	12.3424
2113.41	13.6475
2118.36	14.9756
2123.3	10.008
2128.24	15.0932
2133.17	12.5815
2138.11	3.68254
2143.03	15.0714
2147.96	8.63421
2152.88	12.3302
2157.79	4.50513
2162.71	-2.09326
2167.62	11.7152
2172.52	8.93312
2177.43	1.04212
2182.32	3.32787
2187.22	8.14375
2192.11	13.0143
2197	8.96183
2201.89	3.68082
2206.77	3.56833
2211.64	11.2239
2216.52	17.6497
2221.39	9.8989
2226.26	15.0843
2231.12	11.1904
2235.98	0.755623
2240.84	3.33831
2245.69	-3.23354
2250.54	8.55515
2255.39	3.26794
2260.23	9.8571
2265.07	4.52512
2269.9	4.42528
2274.74	12.2479
2279.57	10.7457
2284.39	5.18864
2289.21	0.923843
2294.03	15.2831
2298.84	13.7158
2303.66	4.20352
2308.46	12.0932
2313.27	6.69096
2318.07	5.33369
2322.87	-2.74817
2327.66	18.8068
2332.45	2.65371
2337.24	12.1947
2342.02	1.40837
2346.8	12.4384
2351.58	7.08743
2356.35	12.643
2361.12	7.11172
2365.89	5.68378
2370.65	8.39956
2375.41	9.72502
2380.17	1.30825
2384.92	3.92023
2389.67	10.6659
2394.42	7.62131
2399.16	3.13917
2403.9	13.9567
2408.64	10.8791
2413.37	10.7972
2418.1	12.5043
2422.83	4.18587
2427.55	1.26429
2432.27	9.73945
2436.99	-1.50668
2441.7	1.38154
2446.41	14.2548
2451.11	7.21444
2455.82	13.0103
2460.51	8.78675
2465.21	0.211678
2469.9	4.56945
2474.59	7.48442
2479.28	6.07491
2483.96	13.366
2488.64	1.68139
2493.32	4.55885
2497.99	10.3887
2502.66	-1.39527
2507.32	10.2781
2511.99	5.76208
2516.65	10.0543
2521.3	21.7819
2525.96	15.8034
2530.61	9.80503
2535.25	-2.10854
2539.89	5.2813
2544.53	17.1818
2549.17	3.78036
2553.8	18.7427
2558.43	11.2316
2563.06	8.24247
2567.68	6.79125
2572.3	-3.70316
2576.92	2.37925
2581.53	6.92065
2586.14	6.83335
2590.75	-0.929497
2595.35	3.5134
2599.96	8.02664
2604.55	-1.22413
2609.15	12.4058
2613.74	3.07339
2618.33	9.04591
2622.91	8.90678
2627.49	8.80197
2632.07	7.2621
2636.64	4.27463
2641.22	10.624
2645.78	-0.01651
2650.35	20.3499
2654.91	3.35986
2659.47	4.91153
2664.03	6.42642
2668.58	0.110001
2673.13	6.42168
2677.67	11.4143
2682.22	13.4748
2686.76	4.36148
2691.29	22.2673
2695.83	11.2305
2700.36	16.1172
2704.89	12.9737
2709.41	8.18323
2713.93	-6.312
2718.45	11.5336
2722.96	9.9653
2727.47	0.209488
2731.98	13.1078
2736.49	4.88794
2740.99	19.431
2745.49	16.1632
2749.98	9.69754
2754.47	6.65353
2758.96	10.0003
2763.45	0.168076
2767.93	1.89058
2772.41	3.60054
2776.89	5.40739
2781.36	5.65268
2785.84	7.60899
2790.3	14.5742
2794.77	11.513
2799.23	15.0847
2803.69	20.308
2808.14	10.3364
2812.59	3.67821
2817.04	3.71422
2821.49	10.5403
2825.93	8.92867
2830.37	12.395
2834.81	7.34131
2839.24	14.2051
2843.67	14.2747
2848.1	0.715744
2852.53	11.1376
2856.95	-2.37637
2861.37	18.4945
2865.78	1.55663
2870.19	10.5217
2874.6	12.5847
2879.01	7.71072
2883.41	2.84406
2887.81	-2.04102
2892.21	5.34537
2896.6	14.571
2901	-4.49622
2905.38	15.3941
2909.77	12.1661
2914.15	7.03404
2918.53	25.1951
2922.91	20.1045
2927.28	11.4341
2931.65	20.8259
2936.02	6.6228
2940.38	8.62581
2944.74	5.16109
2949.1	5.26642
2953.46	9.03827
2957.81	5.50195
2962.16	12.9518
2966.5	9.45346
2970.85	20.6657
2975.19	19.0515
2979.52	19.2757
2983.86	17.7086
2988.19	31.0108
2992.52	-2.01001
2996.85	-1.67253
3001.17	41.691
3005.49	14.1283
3009.8	7.06728
3014.12	22.5777
3018.43	25.0116
3022.74	23.6535
3027.04	22.188
3031.34	22.5584
3035.64	28.6006
3039.94	21.2179
3044.23	19.5763
3048.52	33.3021
3052.81	21.9879
3057.09	22.2579
3061.38	12.8369
3065.65	40.2359
3069.93	5.55579
3074.2	40.8318
3078.47	37.2529
3082.74	35.6127
3087	37.9573
3091.27	30.5845
3095.52	39
3099.78	51.441
3104.03	36.2472
3108.28	42.8875
3112.53	47.6207
3116.77	34.3235
3121.01	43.1041
3125.25	60.1007
3129.49	32.5974
3133.72	47.7691
3137.95	34.3313
3142.18	53.6826
3146.4	52.4285
3150.62	42.7919
3154.84	49.6325
3159.06	60.6658
3163.27	69.6785
3167.48	59.7652
3171.69	64.5583
3175.89	54.5046
3180.09	63.3281
3184.29	72.1126
3188.49	74.4773
3192.68	55.7118
3196.87	56.1332
3201.06	54.6738
3205.24	48.986
3209.42	67.0057
3213.6	76.5544
3217.78	79.7162
3221.95	67.5758
3226.12	70.6535
3230.29	84.7066
3234.45	70.1732
3238.61	73.1989
3242.77	54.1323
3246.93	66.1622
3251.08	55.7276
3255.23	60.7763
3259.38	83.8773
3263.53	75.673
3267.67	60.9581
3271.81	61.8401
3275.95	60.1363
3280.08	69.7614
3284.21	77.1254
3288.34	70.7177
3292.47	73.4675
3296.59	57.7466
3300.71	74.386
3304.83	67.9121
3308.95	54.4493
3313.06	64.1362
3317.17	57.5837
3321.27	62.7211
3325.38	56.261
3329.48	84.9906
3333.58	71.7267
3337.67	63.0897
3341.77	77.8804
3345.86	85.5053
3349.95	69.3033
3354.03	64.9592
3358.11	84.5665
3362.19	87.5272
3366.27	71.2863
3370.34	69.3936
3374.42	67.4263
3378.48	99.1188
3382.55	87.43
3386.61	63.6027
3390.68	71.1358
3394.73	61.7429
3398.79	76.6465
3402.84	74.5191
3406.89	79.6318
3410.94	72.5639
3414.98	89.8169
3419.03	92.4823
3423.06	78.0549
3427.1	88.0412
3431.14	98.1207
3435.17	81.3742
3439.2	79.3435
3443.22	67.5195
3447.25	75.4455
3451.27	71.0891
3455.28	89.0595
3459.3	67.5289
3463.31	55.8396
3467.32	76.5748
3471.33	79.8449
3475.34	77.9442
3479.34	66.0243
3483.34	54.0105
3487.33	74.8922
3491.33	60.2382
3495.32	78.6235
3499.31	74.0132
3503.3	79.5487
3507.28	77.3364
3511.26	64.6951
3515.24	67.4099
3519.22	34.1254
3523.19	57.3845
3527.16	67.8438
3531.13	42.2402
3535.1	58.0457
3539.06	66.2763
3543.02	20.0493
3546.98	54.0661
3550.93	56.9118
3554.89	59.5848
3558.84	49.3811
3562.78	49.637
3566.73	39.5197
3570.67	45.1458
3574.61	48.1579
3578.55	46
3582.48	51.8043
3586.41	47.0788
3590.35	42.3103
3594.27	48.1462
3598.2	46.001
3602.12	43.7834
3606.04	41.5279
3609.95	41.8916
3613.87	39.5614
3617.78	39.8818
3621.69	42.8181
3625.6	29.4042
3629.5	43.0006
3633.4	26.7971
3637.3	21.4773
3641.2	35.2433
3645.09	24.6847
3648.98	33.0549
3652.87	14.1353
3656.76	19.6939
3660.64	36.1661
3664.53	30.7983
3668.4	14.5354
3672.28	42.0087
3676.16	25.7961
3680.03	15.0941
3683.9	20.9307
3687.76	24.101
3691.63	27.2995
3695.49	2.70848
3699.35	30.88
3703.2	8.96704
3707.06	9.34517
3710.91	26.5506
3714.76	10.071
3718.6	27.2742
3722.45	19.0981
3726.29	13.6823
3730.13	13.9135
3733.97	17.014
3737.8	5.89543
3741.63	8.95787
3745.46	14.8683
3749.29	15.0461
3753.11	20.899
3756.93	29.5794
3760.75	9.58659
3764.57	3.89313
3768.39	-1.78816
3772.2	12.6557
3776.01	15.6407
3779.81	18.672
3783.62	7.37366
3787.42	7.591
3791.22	7.78476
3795.02	19.6081
3798.81	8.33517
3802.61	2.84583
3806.4	-5.55028
3810.18	12.2818
3813.97	15.5398
3817.75	7.08566
3821.53	19.1351
3825.31	16.4875
3829.09	-0.882675
3832.86	25.9864
3836.63	23.379
3840.4	20.7367
3844.17	18.1483
3847.93	0.53746
3851.69	-5.22902
3855.45	12.7507
3859.21	-10.9283
3862.96	13.0025
3866.71	1.46204
3870.46	13.8602
3874.21	2.12032
3877.95	14.3015
3881.69	5.57635
3885.44	8.84721
3889.17	3.17058
3892.91	9.53381
3896.64	9.99826
3900.37	19.4644
3904.1	-4.20659
3907.82	8.28596
3911.55	-6.35837
3915.27	12.303
3918.99	15.9243
3922.7	16.5874
3926.42	8.08813
3930.13	14.8173
3933.84	9.27591
3937.54	12.8943
3941.25	10.4464
3944.95	11.1267
3948.65	17.9627
3952.35	0.0807953
3956.04	-5.49278
3959.73	10.5575
3963.42	20.4312
3967.11	17.9007
3970.8	2.94655
3974.48	-2.6759
3978.16	13.4192
3981.84	10.8848
3985.52	23.8788
3989.19	-0.315765
3992.86	6.57864
3996.53	1.13834
3998.37	1.54724