File: Data/3-Raman/processed/bu19w-b-ff1-fi04-v_150 (500nm)_532nm_edge_100%_x100_vis_h50um_15sx2_01.txt
#Acq. time (s)=	15
#Accumulations=	2
#Range (cm-¹)=	100...5000
#Windows=	1
#Auto scanning=	Off
#Autofocus=	Off
#Macrospot=	Off
#AutoExposure=	Off
#Spike filter=	Multiple accum.
#Delay time (s)=	2
#Binning=	1
#Readout mode=	Signal
#DeNoise=	Off
#ICS correction=	On
#Dark correction=	Off
#Inst. Process=	Off
#Detector Gain=	Best Dynamic
#Detector ADC=	50 kHz HS
#Detector temperature (°C)=	-60.09
#Instrument=	LabRAM HR Evol
#Detector=	SIN-EM FIVIS
#Objective=	x100_VIS
#Grating=	150 (500nm)
#ND Filter=	100%
#Laser=	532nm_Edge
#Hole=	49.98
#Temperature=	0
#Range=	Visible
#StageXY=	75x50mm Scan+
#StageZ=	Z motor
#X (µm)=	0
#Y (µm)=	0
#Z (µm)=	-139.1
#Full time(s)=	34
#Project=	21_05_14
#Sample=	BU19w
#Site=
#Title=	BU19w-FF1-FI04-V_150 (500nm)_532nm_Edge_100%_x100_VIS_H50um_15sX2
#Remark=
#Date=	14.05.2021 14:14
#Acquired=	14.05.2021 14:14:23
#Base:Fit=	22.12.2021 12:22:35
#Base:Edit=	22.12.2021 12:24:53
#Base:Edit=	22.12.2021 12:24:55
#Base:Sub=	22.12.2021 12:24:57
#Data Range:Extract=	22.12.2021 12:27:19
102.699	5970.99
107.322	5087.99
111.942	4148.55
116.56	3445.31
121.173	2838.2
125.787	2366.4
130.398	2002.99
135.006	1680.44
139.613	1442.07
144.215	1161.51
148.817	983.63
153.417	843.692
158.014	985.258
162.607	1392.9
167.2	1247.19
171.79	676.445
176.379	511.461
180.963	505.919
185.547	1296.94
190.128	2962.85
194.705	2688.86
199.282	955.675
203.857	256.063
208.43	102.201
212.998	31.6626
217.566	37.0682
222.132	9.52344
226.693	-8.4574
231.254	6.39539
235.813	73.8759
240.368	107.96
244.923	220.09
249.475	448.766
254.023	410.589
258.571	295.849
263.117	202.149
267.658	151.081
272.199	328.273
276.738	1036.14
281.273	2112.79
285.807	2031.66
290.34	1043.59
294.868	473.474
299.396	576.268
303.919	1113.71
308.443	1390.28
312.964	787.2
317.481	307.153
321.998	177.972
326.51	293.431
331.023	545.877
335.533	599.257
340.039	281.29
344.544	137.364
349.046	120.085
353.547	221.684
358.045	130.464
362.542	17.6947
367.036	10.6804
371.527	38.8638
376.017	50.7415
380.503	11.92
384.99	166.67
389.471	340.573
393.953	454.366
398.43	477.112
402.908	429.474
407.381	314.019
411.854	232.191
416.323	309.766
420.791	464.308
425.256	351.541
429.72	124.769
434.18	35.8982
438.64	-0.688354
443.095	42.6365
447.551	37.7037
452.003	261.359
456.454	714.434
460.901	900.159
465.348	506.005
469.791	176.882
474.231	65.5548
478.672	29.8307
483.108	108.822
487.544	167.08
491.976	220.737
496.408	270.956
500.836	299.908
505.261	287.881
509.687	220.015
514.108	141.918
518.529	90.4399
522.946	106.727
527.361	90.6698
531.776	154.86
536.187	123.077
540.595	137.527
545.003	176.243
549.408	153.508
553.812	202.014
558.212	178.623
562.61	224.29
567.007	249.158
571.401	183.019
575.792	95.5752
580.184	142.873
584.571	235.382
588.956	526.445
593.341	822.189
597.722	661.084
602.101	355.703
606.48	311.808
610.854	439.345
615.227	637.028
619.597	570.663
623.967	323.151
628.334	117.004
632.698	74.0361
637.06	149.637
641.422	139.548
645.779	168.584
650.135	123.876
654.491	64.3522
658.842	86.0717
663.192	161.161
667.539	155.159
671.884	177.913
676.23	275.719
680.571	294.09
684.91	270.528
689.247	175.383
693.583	131.896
697.916	63.6385
702.247	41.5813
706.576	-4.39514
710.902	-19.313
715.229	-11.6581
719.551	-37.4017
723.872	19.4376
728.19	16.05
732.506	-9.97949
736.82	-13.0166
741.134	55.0203
745.444	31.9506
749.752	61.67
754.058	73.1069
758.362	129.173
762.664	160.442
766.964	246.382
771.264	402.604
775.559	636.81
779.853	948.032
784.144	1079.75
788.434	735.95
792.722	388.107
797.007	233.221
801.29	201.045
805.572	121.391
809.851	72.8264
814.13	56.5332
818.406	43.4136
822.679	20.8275
826.95	23.7609
831.219	26.7878
835.486	14.2839
839.752	-1.66956
844.015	11.8297
848.276	9.80835
852.535	3.23914
856.792	-11.0328
861.047	-0.129639
865.3	0.282959
869.551	-11.7422
873.8	-6.64063
878.047	22.2589
882.292	-23.9375
886.534	1.3197
890.775	-25.0839
895.014	8.66162
899.251	28.1935
903.486	-8.80798
907.719	20.2965
911.95	16.99
916.179	5.76074
920.406	22.6624
924.63	2.75452
928.853	14.3837
933.074	-19.9391
937.293	24.5551
941.51	40.8932
945.723	32.2828
949.936	130.852
954.147	121.797
958.356	167.25
962.563	146.965
966.768	207.514
970.971	223.912
975.172	192.748
979.371	156.813
983.568	78.6847
987.761	50.0599
991.954	53.2931
996.145	-14.056
1000.33	48.3367
1004.52	18.7256
1008.71	13.9097
1012.89	16.9841
1017.07	68.0282
1021.25	61.4991
1025.43	75.3247
1029.6	28.3218
1033.77	110.88
1037.95	112.52
1042.11	218.726
1046.28	420.55
1050.45	705.019
1054.61	1208.72
1058.77	1356.63
1062.93	942.322
1067.09	625.824
1071.24	333.662
1075.4	344.164
1079.55	356.631
1083.7	527.575
1087.85	803.114
1091.99	1146.54
1096.14	1276.06
1100.28	1047.88
1104.42	837.249
1108.55	866.869
1112.69	1023.64
1116.82	1063.75
1120.96	891.939
1125.09	853.09
1129.21	843.368
1133.34	947.833
1137.46	918.247
1141.59	776.515
1145.71	539.183
1149.83	424.621
1153.94	390.092
1158.06	620.553
1162.17	857.298
1166.28	691.091
1170.39	398.232
1174.5	310.29
1178.6	266.648
1182.7	141.789
1186.8	92.7842
1190.9	124.327
1195	111.158
1199.1	128.986
1203.19	140.352
1207.28	170.926
1211.37	169.138
1215.46	114.985
1219.54	150.013
1223.63	205.118
1227.71	314.941
1231.79	257.235
1235.87	369.225
1239.95	412.256
1244.02	527.453
1248.09	591.426
1252.16	724.986
1256.23	999.055
1260.3	678.945
1264.36	515.891
1268.43	694.775
1272.49	3693.85
1276.55	8112.35
1280.6	3073.31
1284.66	714.88
1288.71	404.614
1292.76	343.238
1296.81	338.147
1300.86	213.743
1304.91	213.919
1308.95	261.574
1312.99	202.663
1317.03	226.691
1321.07	275.61
1325.11	241.8
1329.14	280.833
1333.18	242.665
1337.21	195.14
1341.24	234.475
1345.26	246.588
1349.29	278.63
1353.31	382.19
1357.33	392.129
1361.35	609.943
1365.37	608.277
1369.39	656.264
1373.4	1343.02
1377.41	9026.41
1381.43	12350.3
1385.43	3032.35
1389.44	769.059
1393.45	587.939
1397.45	843.532
1401.45	1260.28
1405.45	715.798
1409.45	330.835
1413.44	269.242
1417.44	239.124
1421.43	189.109
1425.42	166
1429.41	94.7975
1433.39	126.862
1437.38	81.5851
1441.36	90.6935
1445.34	52.9865
1449.32	35.9672
1453.3	88.5511
1457.27	104.46
1461.24	18.3298
1465.22	5.70728
1469.19	4.13708
1473.15	19.3226
1477.12	19.3417
1481.09	-10.1193
1485.05	-17.1632
1489.01	26.5813
1492.97	-3.71631
1496.93	35.2739
1500.88	44.3739
1504.83	5.31458
1508.79	-23.5529
1512.74	-12.5674
1516.68	-11.0819
1520.63	16.7822
1524.57	18.5717
1528.52	23.4943
1532.46	-7.26843
1536.4	19.1685
1540.33	47.6061
1544.27	53.7422
1548.2	15.335
1552.14	-24.1493
1556.07	8.69067
1559.99	29.6371
1563.92	26.1808
1567.84	28.3514
1571.77	12.0861
1575.69	5.46252
1579.61	27.7012
1583.52	49.8165
1587.44	43.8422
1591.35	46.525
1595.27	47.2588
1599.18	57.698
1603.09	54.9615
1606.99	49.5623
1610.9	47.0957
1614.8	35.3146
1618.7	65.776
1622.6	57.9512
1626.5	-15.4933
1630.39	69.4227
1634.29	19.7474
1638.18	18.9557
1642.07	44.684
1645.96	42.8916
1649.85	66.1848
1653.73	5.94629
1657.62	54.9644
1661.5	38.4706
1665.38	73.5052
1669.26	51.4257
1673.13	24.0836
1677.01	70.2083
1680.88	73.9834
1684.75	69.8712
1688.62	57.791
1692.49	18.5391
1696.35	28.7905
1700.22	72.9395
1704.08	54.5732
1707.94	123.267
1711.8	43.5242
1715.66	65.4971
1719.51	46.8279
1723.37	9.3064
1727.22	29.9556
1731.07	77.647
1734.92	64.2795
1738.76	65.5884
1742.61	51.009
1746.45	60.5427
1750.29	84.1829
1754.13	13.1538
1757.97	58.8164
1761.81	96.2341
1765.64	72.4441
1769.47	97.3943
1773.31	60.4929
1777.14	82.5471
1780.96	40.9089
1784.79	75.0691
1788.61	33.6899
1792.43	68.1902
1796.25	99.9622
1800.07	87.7205
1803.89	81.21
1807.71	47.2849
1811.52	54.4431
1815.33	46.7568
1819.14	45.8457
1822.95	33.1946
1826.76	76.6389
1830.56	64.781
1834.37	71.3335
1838.17	55.9063
1841.97	80.478
1845.77	118.053
1849.56	56.7236
1853.36	71.4319
1857.15	96.7024
1860.94	36.6587
1864.73	89.3721
1868.52	103.171
1872.31	38.6201
1876.09	51.2708
1879.87	58.9187
1883.66	62.4353
1887.43	83.0176
1891.21	59.7534
1894.99	51.9841
1898.76	65.0415
1902.53	77.8892
1906.31	52.3345
1910.08	58.6475
1913.84	68.2019
1917.61	71.2419
1921.37	53.7903
1925.14	70.8284
1928.9	63.1475
1932.66	77.8245
1936.41	95.2817
1940.17	62.27
1943.92	8.95874
1947.68	67.1064
1951.43	8.12891
1955.18	67.3784
1958.92	98.2935
1962.67	68.9077
1966.41	48.6792
1970.16	80.8315
1973.9	66.5854
1977.64	109.024
1981.37	95.8789
1985.11	101.038
1988.84	94.8291
1992.57	68.5537
1996.31	120.017
2000.03	41.2622
2003.76	50.0598
2007.49	70.0081
2011.21	79.6404
2014.93	59.4993
2018.65	83.116
2022.37	31.6228
2026.09	111.42
2029.81	58.0105
2033.52	90.0422
2037.23	66.531
2040.94	33.999
2044.65	72.5608
2048.36	61.2529
2052.07	54.8191
2055.77	74.4324
2059.47	50.0171
2063.17	109.928
2066.87	81.9165
2070.57	46.5051
2074.27	66.4702
2077.96	21.9546
2081.65	59.7627
2085.34	55.489
2089.03	67.8127
2092.72	86.8665
2096.41	88.7327
2100.09	115.514
2103.77	101.948
2107.46	81.4773
2111.14	94.2932
2114.81	93.1001
2118.49	71.7251
2122.16	78.2905
2125.84	71.699
2129.51	119.341
2133.18	77.1211
2136.85	47.6418
2140.51	101.739
2144.18	62.4841
2147.84	89.4648
2151.5	99.875
2155.16	70.0903
2158.82	103.638
2162.48	97.3203
2166.13	75.8745
2169.79	51.4939
2173.44	69.9539
2177.09	98.5833
2180.74	80.1006
2184.38	73.4834
2188.03	53.386
2191.67	128.709
2195.32	45.5977
2198.96	50.0703
2202.6	95.9575
2206.23	72.9021
2209.87	51.0647
2213.5	26.6309
2217.14	62.751
2220.77	51.2822
2224.4	127.272
2228.03	55.8101
2231.65	121.982
2235.28	66.3245
2238.9	49.2834
2242.52	86.9243
2246.14	37.29
2249.76	95.7461
2253.38	48.3188
2256.99	45.6558
2260.6	14.7004
2264.21	11.7092
2267.82	55.2495
2271.44	97.071
2275.04	41.0322
2278.65	20.7871
2282.25	70.2434
2285.85	95.6946
2289.45	-14.4321
2293.05	26.6174
2296.65	73.5576
2300.25	78.7175
2303.84	52.0898
2307.43	82.9055
2311.02	40.4458
2314.62	101.886
2318.2	422.478
2321.79	1160.14
2325.38	598.352
2328.96	133.408
2332.54	90.8357
2336.12	83.0171
2339.7	92.7986
2343.28	23.4612
2346.85	51.5979
2350.43	62.7063
2354	52.1799
2357.57	91.8821
2361.14	123.903
2364.71	34.3018
2368.27	62.158
2371.84	5.09473
2375.4	56.0417
2378.96	41.6638
2382.52	63.488
2386.08	71.7639
2389.64	46.5188
2393.19	65.0024
2396.75	52.1479
2400.3	28.3914
2403.85	21.9663
2407.4	21.4587
2410.95	6.27588
2414.49	28.2075
2418.04	35.0488
2421.58	39.5415
2425.12	51.1089
2428.66	42.8796
2432.2	45.2644
2435.74	-0.241943
2439.27	29.5681
2442.81	52.1824
2446.34	51.7803
2449.87	5.93042
2453.4	51.3611
2456.93	24.4082
2460.45	31.2673
2463.98	-13.5974
2467.5	95.0618
2471.02	55.1589
2474.54	27.4827
2478.06	54.4028
2481.58	17.7754
2485.09	16.71
2488.61	72.949
2492.12	69.2593
2495.63	48.1304
2499.14	32.1106
2502.65	4.09985
2506.15	22.5466
2509.66	36.0981
2513.16	37.0586
2516.66	67.2668
2520.16	44.4741
2523.66	69.1858
2527.16	44.1157
2530.66	59.093
2534.15	18.4121
2537.64	18.7983
2541.13	43.1753
2544.62	29.0337
2548.11	37.2671
2551.6	50.4714
2555.08	88.1387
2558.57	45.2246
2562.05	50.4248
2565.53	20.0708
2569.01	9.80737
2572.49	24.2673
2575.96	14.8569
2579.44	79.0684
2582.91	39.8213
2586.38	50.2773
2589.85	27.3523
2593.32	41.6287
2596.79	-14.0376
2600.25	67.96
2603.72	19.9309
2607.18	22.9719
2610.64	17.998
2614.1	22.5999
2617.56	39.896
2621.02	85.603
2624.47	44.2068
2627.92	77.3984
2631.38	95.7166
2634.83	60.5603
2638.28	57.6682
2641.72	79.1362
2645.17	4.94604
2648.61	9.72827
2652.06	55.8459
2655.5	30.9712
2658.94	65.6873
2662.38	75.3882
2665.82	61.4802
2669.25	83.1531
2672.69	74.0745
2676.12	79.3918
2679.55	53.3535
2682.98	56.8831
2686.41	53.3474
2689.84	23.2114
2693.26	61.4299
2696.69	52.5688
2700.11	22.677
2703.53	35.0862
2706.95	43.5872
2710.37	88.9595
2713.79	15.6545
2717.2	63.8066
2720.62	69.4939
2724.03	68.823
2727.44	27.2627
2730.85	64.0854
2734.26	82.2393
2737.66	67.6375
2741.07	51.6934
2744.47	72.8628
2747.87	46.1516
2751.28	62.6368
2754.67	65.5151
2758.07	31.025
2761.47	75.0388
2764.86	58.4771
2768.26	75.3961
2771.65	83.7236
2775.04	126.551
2778.43	53.1849
2781.82	68.1732
2785.2	77.4146
2788.59	33.9795
2791.97	62.7628
2795.35	78.5885
2798.73	89.2305
2802.11	43.6281
2805.49	61.8036
2808.87	-5.34729
2812.24	99.6268
2815.62	62.1993
2818.99	74.6145
2822.36	81.7839
2825.73	55.5271
2829.1	126.441
2832.46	53.3219
2835.83	69.0707
2839.19	86.1514
2842.55	105.537
2845.91	91.0846
2849.27	94.3909
2852.63	43.0601
2855.99	51.7058
2859.34	83.1705
2862.69	96.0439
2866.05	79.0403
2869.4	94.6987
2872.75	90.5809
2876.09	43.095
2879.44	82.1586
2882.78	73.9844
2886.13	82.6254
2889.47	121.663
2892.81	76.959
2896.15	90.5621
2899.49	81.1505
2902.82	68.5874
2906.16	115.495
2909.49	96.8846
2912.82	108.554
2916.16	80.0995
2919.49	89.3458
2922.81	155.271
2926.14	123.386
2929.46	77.2732
2932.79	124.195
2936.11	133.325
2939.43	91.5615
2942.75	178.893
2946.07	97.8149
2949.39	77.9114
2952.7	108.697
2956.02	52.4553
2959.33	119.546
2962.64	84.2675
2965.95	162.954
2969.26	84.8983
2972.57	125.59
2975.87	138.952
2979.17	137.802
2982.48	117.99
2985.78	124.613
2989.08	152.902
2992.38	123.05
2995.68	181.67
2998.97	136.004
3002.27	128.755
3005.56	100.994
3008.85	135.451
3012.14	144.612
3015.43	148.068
3018.72	136.394
3022	106.762
3025.29	164.952
3028.57	170.294
3031.85	179.328
3035.14	173.132
3038.41	141.409
3041.69	132.38
3044.97	141.414
3048.24	174.058
3051.52	147.134
3054.79	117.288
3058.06	177.298
3061.33	166.631
3064.6	120.082
3067.87	155.814
3071.13	179.524
3074.4	161.609
3077.66	137.075
3080.92	185.711
3084.18	205.376
3087.44	143.76
3090.7	203.205
3093.95	172.254
3097.21	183.393
3100.46	222.123
3103.71	212.996
3106.96	248.694
3110.21	257.147
3113.46	210.324
3116.71	216.904
3119.95	221.597
3123.2	221.503
3126.44	204.194
3129.68	264.08
3132.92	249.608
3136.16	220.73
3139.4	235.644
3142.63	246.735
3145.87	242.673
3149.1	226.288
3152.33	253.706
3155.56	297.377
3158.79	255.142
3162.02	265.378
3165.25	302.197
3168.47	286.358
3171.69	278.06
3174.92	307.764
3178.14	267.742
3181.36	279.287
3184.58	285.881
3187.79	344.79
3191.01	272.13
3194.22	261.417
3197.43	325.895
3200.65	303.744
3203.86	351.161
3207.07	354.865
3210.27	346.323
3213.48	348.406
3216.69	355.275
3219.89	314.618
3223.09	388.3
3226.29	352.651
3229.49	363.787
3232.69	361.458
3235.89	333.774
3239.08	394.813
3242.28	333.144
3245.47	333.365
3248.66	344.235
3251.85	389.549
3255.04	318.483
3258.23	397.016
3261.42	375.016
3264.6	383.267
3267.79	424.711
3270.97	390.516
3274.15	374.47
3277.33	390.562
3280.51	382.319
3283.68	412.233
3286.86	384.711
3290.04	402.142
3293.21	429.059
3296.38	417.766
3299.55	375.598
3302.72	461.574
3305.89	452.088
3309.06	418.52
3312.22	438.949
3315.39	445.05
3318.55	409.331
3321.71	454.194
3324.87	466.81
3328.03	473.755
3331.19	441.123
3334.34	475.752
3337.5	436.915
3340.65	477.349
3343.81	506.83
3346.96	490.735
3350.11	502.006
3353.25	469.188
3356.4	447.779
3359.55	485.07
3362.69	557.336
3365.84	526.937
3368.98	503.179
3372.12	491.917
3375.26	513.8
3378.4	500.893
3381.53	510.531
3384.67	553.432
3387.8	520.708
3390.94	613.985
3394.07	577.634
3397.2	576.446
3400.33	640.137
3403.46	649.088
3406.58	732.347
3409.71	750.202
3412.83	933.258
3415.96	1380.39
3419.08	2232.43
3422.2	4377.95
3425.32	6245.33
3428.44	4624.46
3431.55	2309.95
3434.67	1274.98
3437.78	901.195
3440.89	768.147
3444	652.762
3447.12	676.628
3450.22	663.886
3453.33	591.128
3456.44	601.883
3459.54	588.768
3462.65	525.224
3465.75	560.34
3468.85	570.062
3471.95	570.913
3475.05	569.12
3478.15	520.148
3481.24	580.93
3484.34	572.792
3487.43	579.951
3490.53	600.067
3493.62	711.767
3496.71	789.191
3499.79	895.058
3502.88	1041.8
3505.97	1142.44
3509.05	1102.72
3512.14	1021.38
3515.22	859.583
3518.3	718.216
3521.38	612.838
3524.46	556.506
3527.54	545.115
3530.61	513.592
3533.69	443.179
3536.76	402.623
3539.83	416.285
3542.9	395.999
3545.97	376.482
3549.04	375.556
3552.11	378.03
3555.18	385.529
3558.24	397.031
3561.3	347.473
3564.37	335.617
3567.43	343.744
3570.49	342.071
3573.55	304.138
3576.61	319.23
3579.66	283.9
3582.72	330.913
3585.77	298.2
3588.82	273.856
3591.87	295.871
3594.92	280.778
3597.97	282.701
3601.02	240.929
3604.07	264.336
3607.11	227.134
3610.16	267.412
3613.2	238.593
3616.24	208.898
3619.28	226.489
3622.32	247.887
3625.36	215.638
3628.39	217.299
3631.43	205.653
3634.46	236.645
3637.5	235.915
3640.53	183.624
3643.56	174.088
3646.59	179.346
3649.62	182.932
3652.64	163.083
3655.67	184.916
3658.69	132.436
3661.72	141.813
3664.74	147.677
3667.76	143.241
3670.78	136.13
3673.79	138.533
3676.81	136.318
3679.83	100.031
3682.84	173.359
3685.86	105.851
3688.87	124.446
3691.88	104.273
3694.89	97.074
3697.9	101.423
3700.91	115.358
3703.91	95.1182
3706.92	111.766
3709.92	93.1215
3712.92	87.5737
3715.92	89.6794
3718.92	75.488
3721.92	116.364
3724.92	99.9761
3727.92	61.5665
3730.91	108.725
3733.91	92.8606
3736.9	48.3015
3739.89	125.409
3742.88	109.089
3745.87	66.0151
3748.86	74.1704
3751.85	113.599
3754.83	69.4974
3757.82	64.3226
3760.8	14.4954
3763.78	74.5852
3766.76	53.292
3769.74	69.048
3772.72	81.1268
3775.7	53.5948
3778.67	41.3011
3781.65	66.8257
3784.62	62.1919
3787.6	55.7476
3790.57	73.1075
3793.54	80.2388
3796.51	55.3625
3799.47	37.2677
3802.44	68.379
3805.41	78.7711
3808.37	91.1455
3811.33	45.9105
3814.3	77.2802
3817.26	51.9625
3820.22	29.4929
3823.18	35.511
3826.13	59.5851
3829.09	40.9896
3832.04	29.1206
3835	34.4249
3837.95	24.5509
3840.9	42.2275
3843.85	29.4917
3846.8	46.3109
3849.75	40.3606
3852.69	40.1667
3855.64	15.1611
3858.58	76.1589
3861.53	46.3099
3864.47	99.6982
3867.41	63.0028
3870.35	51.1218
3873.29	68.9247
3876.22	49.1642
3879.16	37.8798
3882.1	68.6956
3885.03	67.6832
3887.96	30.0667
3890.89	46.2349
3893.82	29.5585
3896.75	46.3553
3899.68	17.9232
3902.61	25.8347
3905.53	45.416
3908.46	56.2762
3911.38	36.2615
3914.3	60.2744
3917.23	70.1335
3920.15	60.6097
3923.06	42.2734
3925.98	41.087
3928.9	57.0133
3931.81	60.731
3934.73	51.3302
3937.64	56.6289
3940.55	31.2084
3943.46	41.2405
3946.37	19.809
3949.28	34.8811
3952.19	56.7153
3955.09	27.9144
3958	49.9592
3960.9	60.5811
3963.8	54.0313
3966.71	3.42603
3969.61	46.8856
3972.51	58.693
3975.4	49.3064
3978.3	53.2623
3981.2	-6.24707
3984.09	50.4845
3986.99	60.1195
3989.88	34.8976
3992.77	36.8364
3995.66	33.9772
3998.55	34.0687
4001.43	16.8458