File: Data/3-Raman/processed/bu19w-a-ff07b-fi10-v_150 (500nm)_532nm_edge_100%_x100_vis_lwd_h50um_15sx2_01_0.txt
#Acq. time (s)=	15
#Accumulations=	2
#Range (cm-¹)=	50...5000
#Windows=	1
#Auto scanning=	Off
#Autofocus=	Off
#Macrospot=	Off
#AutoExposure=	Off
#Spike filter=	Multiple accum.
#Delay time (s)=	2
#Binning=	1
#Readout mode=	Signal
#DeNoise=	Off
#ICS correction=	On
#Dark correction=	Off
#Inst. Process=	Off
#Detector Gain=	Best Dynamic
#Detector ADC=	50 kHz HS
#Detector temperature (°C)=	-60.09
#Instrument=	LabRAM HR Evol
#Detector=	SIN-EM FIVIS
#Objective=	x100_VIS_LWD
#Grating=	150 (500nm)
#ND Filter=	100%
#Laser=	532nm_Edge
#Hole=	49.98
#Temperature=	0
#Range=	Visible
#StageXY=	75x50mm Scan+
#StageZ=	Z motor
#X (µm)=	0
#Y (µm)=	0
#Z (µm)=	-31.5
#Full time(s)=	34
#Project=	21_05_28
#Sample=	BU19w
#Site=
#Title=	BU19w-FF07b-FI10-V_150 (500nm)_532nm_Edge_100%_x100_VIS_LWD_H50um_15sX2
#Remark=
#Date=	28.05.2021 16:54
#Acquired=	28.05.2021 16:54:34
#Base:Fit=	16.12.2021 17:39:50
#Base:Sub=	16.12.2021 17:57:54
51.5961	23321.6
56.2453	17456.5
60.8921	12989.7
65.5367	11860.3
70.1768	9273.69
74.8167	5415.93
79.4543	3641.57
84.0897	2695.16
88.7227	1950.6
93.3513	1496.51
97.9798	1187.97
102.606	835.015
107.23	764.932
111.851	683.839
116.469	474.594
121.086	293.933
125.7	215.063
130.313	209.637
134.921	182.124
139.529	104.018
144.134	91.1062
148.738	17.6356
153.337	-6.87927
157.936	86.2622
162.532	502.553
167.126	973.213
171.716	540.002
176.306	132.742
180.894	81.4628
185.477	325.937
190.06	1562.13
194.64	3141.76
199.219	2021.34
203.793	571.377
208.367	138.767
212.939	38.5592
217.506	18.7396
222.073	29.1591
226.638	-0.00421143
231.199	42.3972
235.759	227.293
240.318	442.06
244.872	562.03
249.425	1067.8
253.977	1365.17
258.524	1029
263.071	727.245
267.616	408.794
272.156	434.046
276.697	880.982
281.233	2315
285.769	3754.23
290.303	2700
294.832	1298.22
299.361	837.314
303.886	973.788
308.411	1629.97
312.934	1529.86
317.452	865.352
321.97	550.883
326.484	564.929
330.998	927.05
335.507	1337.52
340.017	1131.94
344.524	683.104
349.027	671.659
353.53	961.425
358.028	1132.01
362.527	817.078
367.021	508.819
371.515	450.302
376.004	508.66
380.494	486.713
384.979	390.224
389.465	489.342
393.946	627.347
398.427	798.685
402.903	775.623
407.38	580.121
411.852	411.284
416.324	406.17
420.792	621.518
425.26	695.569
429.723	426.019
434.187	207.002
438.646	197.167
443.105	201.62
447.56	202.105
452.015	287.18
456.466	527.122
460.914	1077.56
465.362	994.96
469.807	567.078
474.251	337.948
478.69	312.495
483.13	326.939
487.566	368.354
491.999	484.411
496.432	626.547
500.861	711.998
505.29	701.948
509.715	582.02
514.138	478.237
518.56	370.946
522.979	310.199
527.395	275.041
531.811	304.75
536.223	274.437
540.635	304.27
545.042	279.531
549.448	319.691
553.853	326.022
558.255	356.044
562.654	349.731
567.053	387.233
571.448	308.246
575.841	357.132
580.232	294.114
584.622	371.807
589.009	596.643
593.393	1300.24
597.777	1608.49
602.157	1029.03
606.535	626.368
610.913	664.541
615.287	977.284
619.659	1101.8
624.029	893.607
628.398	454.345
632.763	339.476
637.127	277.827
641.488	310.317
645.849	398.465
650.206	377.55
654.561	301.182
658.914	332.151
663.267	339.766
667.615	523.771
671.962	620.597
676.307	654.379
680.649	742.914
684.991	752.13
689.33	586.994
693.666	383.817
698	245.227
702.332	151.115
706.662	160.998
710.992	128.552
715.318	90.0693
719.641	122.619
723.963	78.2712
728.283	108.813
732.6	92.9371
736.918	48.4391
741.231	68.9667
745.542	74.858
749.852	111.227
754.159	132.758
758.464	158.521
762.767	174.017
767.068	240.239
771.369	357.991
775.666	583.366
779.961	983.885
784.254	1431.84
788.545	1273.62
792.834	849.359
797.12	494.629
801.405	294.524
805.688	235.298
809.968	160.032
814.247	134.433
818.524	90.302
822.798	91.2671
827.071	98.0207
831.341	53.1171
835.612	59.9947
839.878	54.6948
844.142	51.5032
848.405	38.0447
852.665	17.4425
856.923	22.2306
861.18	24.7994
865.434	49.2242
869.686	-0.376404
873.936	0.473572
878.185	8.77649
882.431	15.7578
886.675	36.5276
890.915	3.26587
895.155	26.3074
899.393	-15.2178
903.63	26.6547
907.864	13.0065
912.096	14.5134
916.326	-0.701294
920.554	-11.7369
924.78	15.712
929.004	23.1879
933.227	48.9916
937.447	67.1387
941.665	84.9655
945.881	114.373
950.095	214.102
954.305	299.993
958.516	343.227
962.724	283.423
966.93	269.569
971.134	380.053
975.337	342.223
979.537	272.845
983.735	205.921
987.93	135.873
992.124	82.9372
996.316	90.0727
1000.51	36.4478
1004.7	78.4338
1008.88	38.9026
1013.06	34.4262
1017.25	48.8786
1021.43	64.4384
1025.61	112.911
1029.78	121.562
1033.96	136.283
1038.13	168.012
1042.3	227.766
1046.47	369.236
1050.63	636.21
1054.8	1206.01
1058.96	1775.82
1063.12	1623.65
1067.28	1071.96
1071.44	678.498
1075.59	475.454
1079.74	497.599
1083.89	663.439
1088.04	984.526
1092.19	1649.42
1096.33	2074.77
1100.48	1979.99
1104.62	1473.51
1108.76	1230.71
1112.89	1341.71
1117.03	1550.8
1121.16	1401.54
1125.29	1214.72
1129.42	1180.5
1133.55	1277.89
1137.68	1401.66
1141.8	1299.7
1145.92	964.269
1150.04	754.961
1154.16	667.912
1158.27	864.898
1162.39	1216.41
1166.5	1266.93
1170.61	1000.12
1174.72	705.093
1178.82	543.11
1182.93	394.757
1187.03	227.793
1191.13	211.44
1195.23	173.288
1199.33	169.645
1203.42	246.166
1207.51	189.136
1211.6	171.974
1215.69	123.665
1219.78	149.272
1223.86	215.123
1227.95	357.155
1232.03	304.983
1236.11	292.999
1240.18	341.754
1244.26	446.088
1248.33	522.952
1252.41	466.864
1256.48	320.187
1260.54	311.526
1264.61	150.025
1268.67	157.704
1272.74	237.767
1276.8	1392.77
1280.86	1504.47
1284.91	359.071
1288.97	105.098
1293.02	101.362
1297.07	70.2616
1301.12	88.4154
1305.17	43.8828
1309.21	64.7922
1313.25	46.2711
1317.3	43.4941
1321.34	33.4482
1325.37	19.9994
1329.41	71.7721
1333.44	78.1366
1337.48	57.0602
1341.5	49.8733
1345.53	25.6177
1349.56	28.3447
1353.59	40.045
1357.61	76.5876
1361.63	105.969
1365.65	114.67
1369.66	108.705
1373.68	115.862
1377.69	599.397
1381.7	2887.8
1385.72	1580.14
1389.72	272.026
1393.73	134.954
1397.73	95.8083
1401.74	223.998
1405.74	231.033
1409.73	117.947
1413.73	29.527
1417.73	60.4291
1421.72	40.0121
1425.71	48.0731
1429.7	30.8949
1433.69	11.8431
1437.67	-13.1559
1441.66	25.0521
1445.64	34.4565
1449.62	2.34631
1453.6	35.1769
1457.57	-1.14185
1461.55	17.5603
1465.52	8.33301
1469.49	16.7521
1473.46	-6.1239
1477.43	12.1029
1481.39	-14.9213
1485.36	19.6932
1489.32	1.36804
1493.28	10.493
1497.24	47.8789
1501.19	14.22
1505.15	36.2521
1509.1	34.2502
1513.05	41.0667
1517	-5.45825
1520.95	-4.27991
1524.9	12.481
1528.84	35.1259
1532.78	2.63696
1536.72	4.10413
1540.66	19.1676
1544.6	5.15588
1548.53	27.9657
1552.46	15.8884
1556.4	33.7036
1560.32	23.2601
1564.25	24.3118
1568.18	45.5544
1572.1	51.2186
1576.02	14.3601
1579.94	22.8573
1583.86	27.4497
1587.78	30.9797
1591.69	6.55542
1595.61	31.1942
1599.52	27.9199
1603.43	3.61133
1607.34	35.1443
1611.24	20.6318
1615.15	37.8333
1619.05	38.879
1622.95	57.084
1626.85	25.6692
1630.74	41.301
1634.64	43.8818
1638.53	29.1667
1642.42	54.9474
1646.31	5.28149
1650.2	21.8119
1654.09	38.4114
1657.97	50.1301
1661.86	34.9104
1665.74	42.5201
1669.62	36.5466
1673.49	31.1777
1677.37	30.5426
1681.24	37.9515
1685.12	23.9423
1688.99	39.5806
1692.86	33.8744
1696.72	27.0566
1700.59	23.8824
1704.45	10.9407
1708.31	9.2229
1712.17	74.698
1716.03	17.6498
1719.89	34.6375
1723.74	34.5841
1727.6	11.8192
1731.45	43.464
1735.3	36.608
1739.14	7.18689
1742.99	34.6832
1746.83	49.9963
1750.68	17.5964
1754.52	17.2391
1758.36	35.1216
1762.19	2.87354
1766.03	64.4871
1769.86	14.1877
1773.69	21.0527
1777.53	33.5426
1781.35	51.0977
1785.18	28.744
1789	23.2666
1792.83	0.956543
1796.65	31.135
1800.47	28.4611
1804.29	6.23108
1808.1	-1.06787
1811.92	9.39526
1815.73	4.57593
1819.54	63.4233
1823.35	-5.40454
1827.16	46.3218
1830.97	26.9703
1834.77	49.7394
1838.58	32.7332
1842.38	15.5748
1846.18	20.7196
1849.97	24.1072
1853.77	16.6438
1857.56	2.36633
1861.36	38.1448
1865.15	14.9998
1868.93	33.8433
1872.72	14.7291
1876.51	17.1801
1880.29	52.9208
1884.07	11.6056
1887.86	35.7939
1891.63	-5.92834
1895.41	61.8889
1899.19	29.3927
1902.96	25.9158
1906.73	56.7198
1910.5	26.8635
1914.27	41.6444
1918.04	40.8367
1921.8	35.2244
1925.57	7.46973
1929.33	60.5472
1933.09	46.0573
1936.85	42.6555
1940.6	53.2006
1944.36	33.8177
1948.11	52.7788
1951.87	14.5575
1955.61	13.3582
1959.36	48.188
1963.11	-3.78235
1966.86	20.2546
1970.6	55.1655
1974.34	31.4398
1978.08	33.7438
1981.82	33.0273
1985.56	23.689
1989.29	35.6934
1993.02	32.5548
1996.75	44.9878
2000.49	34.8677
2004.21	22.9886
2007.94	74.7584
2011.67	29.2166
2015.39	59.3198
2019.11	43.9854
2022.83	14.6581
2026.55	15.4098
2030.27	26.2712
2033.98	20.3041
2037.69	44.9496
2041.41	48.4333
2045.12	33.5055
2048.82	62.5511
2052.53	5.75684
2056.24	50.686
2059.94	16.5295
2063.64	-2.27905
2067.34	4.89087
2071.04	0.204712
2074.74	25.9785
2078.43	31.5941
2082.13	23.4211
2085.82	35.4834
2089.51	25.7021
2093.2	10.7274
2096.88	24.1971
2100.57	53.2729
2104.25	22.4207
2107.94	19.2551
2111.62	33.5708
2115.3	47.8418
2118.97	33.1344
2122.65	44.8851
2126.32	1.61511
2129.99	28.6696
2133.66	28.7034
2137.33	34.1967
2141	36.6932
2144.67	53.7302
2148.33	39.3478
2151.99	46.109
2155.66	28.1416
2159.31	11.1918
2162.97	36.4772
2166.63	28.1187
2170.28	48.2549
2173.94	57.0306
2177.59	5.07922
2181.24	54.3542
2184.89	39.8575
2188.53	44.8073
2192.18	18.406
2195.82	36.188
2199.46	43.3439
2203.1	27.8624
2206.74	43.5927
2210.38	38.5541
2214.01	57.4878
2217.65	35.2893
2221.28	35.1
2224.91	31.3057
2228.54	19.1272
2232.16	79.8378
2235.79	33.6613
2239.41	65.9811
2243.04	65.9318
2246.66	46.3373
2250.28	36.0507
2253.89	27.7395
2257.51	38.1868
2261.12	72.9584
2264.74	14.0481
2268.35	47.9532
2271.96	45.6238
2275.57	-19.2095
2279.17	38.0149
2282.78	45.4495
2286.38	31.1578
2289.98	29.1196
2293.58	38.261
2297.18	-4.58936
2300.78	38.7343
2304.37	61.9979
2307.97	-2.18408
2311.56	40.5481
2315.15	46.1293
2318.74	-2.5282
2322.33	300.98
2325.91	316.357
2329.5	78.2047
2333.08	17.0028
2336.66	54.7988
2340.24	35.8253
2343.82	33.6991
2347.4	63.3167
2350.97	23.4312
2354.54	14.4803
2358.12	42.8076
2361.69	56.9727
2365.26	58.9822
2368.82	62.9288
2372.39	0.522705
2375.95	12.1813
2379.52	45.9824
2383.08	26.4078
2386.64	53.0205
2390.19	31.0995
2393.75	-1.51147
2397.31	66.2673
2400.86	21.698
2404.41	8.10986
2407.96	5.68579
2411.51	24.9089
2415.06	29.7935
2418.6	35.9321
2422.15	13.7755
2425.69	-15.4963
2429.23	48.7063
2432.77	19.0754
2436.31	24.845
2439.84	64.2311
2443.38	43.3818
2446.91	20.608
2450.44	28.8915
2453.97	13.9894
2457.5	42.3826
2461.03	4.74463
2464.55	10.2794
2468.08	41.1448
2471.6	49.5439
2475.12	57.6191
2478.64	55.1212
2482.16	43.4263
2485.67	41.6172
2489.19	23.9519
2492.7	49.3304
2496.21	-6.76172
2499.72	53.9243
2503.23	44.7872
2506.74	27.9943
2510.25	51.9855
2513.75	21.1036
2517.25	34.3099
2520.75	44.0049
2524.25	24.057
2527.75	40.6318
2531.25	53.8297
2534.74	31.2136
2538.24	33.9396
2541.73	21.3019
2545.22	41.6105
2548.71	2.49207
2552.2	65.067
2555.68	46.7133
2559.17	36.3906
2562.65	28.8552
2566.13	17.2383
2569.61	33.0314
2573.09	30.5642
2576.57	53.6632
2580.04	81.8623
2583.51	44.313
2586.99	22.6156
2590.46	46.941
2593.93	65.9453
2597.4	40.9839
2600.86	57.3873
2604.33	16.3082
2607.79	10.7502
2611.25	29.0392
2614.71	62.7701
2618.17	43.2468
2621.63	46.2167
2625.09	24.9089
2628.54	39.7638
2631.99	47.6757
2635.45	34.146
2638.9	17.3781
2642.34	51.1586
2645.79	53.046
2649.24	32.8879
2652.68	34.4136
2656.12	54.6196
2659.56	70.6761
2663.01	49.5852
2666.44	52.0918
2669.88	39.4834
2673.32	49.4401
2676.75	28.6234
2680.18	58.6608
2683.61	30.0215
2687.04	48.6165
2690.47	49.4095
2693.9	52.5529
2697.32	74.9747
2700.75	48.3726
2704.17	70.2231
2707.59	20.5278
2711.01	44.3251
2714.43	70.2948
2717.84	23.9473
2721.26	34.6478
2724.67	42.7551
2728.08	71.5485
2731.49	33.1694
2734.9	77.0177
2738.31	25.3835
2741.71	62.7091
2745.12	35.9965
2748.52	45.7107
2751.92	47.9426
2755.32	73.5947
2758.72	56.7689
2762.12	73.8708
2765.52	82.1519
2768.91	47.8257
2772.3	56.6299
2775.7	50.2505
2779.09	88.8638
2782.47	-1.71985
2785.86	59.2006
2789.25	58.8876
2792.63	68.8735
2796.01	49.6969
2799.4	31.4912
2802.78	106.912
2806.15	39.7705
2809.53	63.5596
2812.91	7.70447
2816.28	73.4199
2819.65	69.8815
2823.03	71.2384
2826.4	65.3287
2829.76	85.6417
2833.13	87.4965
2836.5	73.7789
2839.86	68.6937
2843.22	78.7906
2846.59	61.2706
2849.95	50.756
2853.3	53.6105
2856.66	70.3352
2860.02	78.8654
2863.37	75.4153
2866.72	31.7136
2870.08	42.3567
2873.43	72.6724
2876.77	95.4915
2880.12	30.7787
2883.47	44.1101
2886.81	96.981
2890.15	63.0709
2893.5	63.9891
2896.84	71.2092
2900.17	67.8475
2903.51	62.3892
2906.85	84.2117
2910.18	103.09
2913.52	102.006
2916.85	115.973
2920.18	80.5446
2923.51	59.2565
2926.83	63.3934
2930.16	92.8563
2933.48	95.6942
2936.81	103.052
2940.13	85.8936
2943.45	161.099
2946.77	86.566
2950.09	127.899
2953.4	112.729
2956.72	73.2151
2960.03	76.2251
2963.34	115.954
2966.65	78.8291
2969.96	97.469
2973.27	63.8318
2976.58	120.303
2979.88	95.3945
2983.19	56.2469
2986.49	115.734
2989.79	73.9326
2993.09	91.329
2996.39	92.8445
2999.68	87.8579
3002.98	68.7498
3006.27	90.0905
3009.57	98.3853
3012.86	70.9773
3016.15	80.3223
3019.43	82.1057
3022.72	81.9882
3026.01	108.308
3029.29	113.906
3032.57	104.371
3035.86	121.232
3039.14	69.9832
3042.41	120.887
3045.69	128.328
3048.97	88.4368
3052.24	87.3586
3055.52	95.801
3058.79	93.7666
3062.06	87.5175
3065.33	93.8029
3068.6	80.9508
3071.86	122.862
3075.13	127.548
3078.39	117.479
3081.65	87.0775
3084.91	113.751
3088.17	145.139
3091.43	105.698
3094.69	138.535
3097.95	138.309
3101.2	121.834
3104.45	135.535
3107.7	150.826
3110.95	166.893
3114.2	146.358
3117.45	146.887
3120.7	174.122
3123.94	147.075
3127.18	174.304
3130.43	170.059
3133.67	184.897
3136.91	167.294
3140.14	172.496
3143.38	194.843
3146.61	208.625
3149.85	166.242
3153.08	210.668
3156.31	192.094
3159.54	198.359
3162.77	184.545
3166	221.31
3169.22	216.918
3172.45	218.153
3175.67	214.561
3178.89	260.466
3182.11	249.107
3185.33	245.413
3188.55	274.931
3191.77	253.876
3194.98	290.007
3198.2	271.798
3201.41	280.237
3204.62	314.44
3207.83	316.318
3211.04	298.285
3214.25	283.216
3217.45	268.251
3220.66	276.124
3223.86	340.172
3227.06	278.802
3230.26	307.838
3233.46	342.699
3236.66	347.021
3239.85	333.59
3243.05	305.95
3246.24	320.278
3249.44	319.378
3252.63	309.084
3255.82	332.211
3259.01	378.242
3262.19	336.239
3265.38	320.744
3268.56	377.638
3271.75	372.294
3274.93	385.965
3278.11	337.526
3281.29	364.233
3284.47	369.652
3287.64	356.974
3290.82	386.137
3293.99	383.948
3297.17	372.174
3300.34	407.098
3303.51	409.98
3306.68	362.987
3309.84	401.484
3313.01	410.239
3316.18	424.585
3319.34	408.516
3322.5	446.444
3325.66	419.928
3328.82	447.404
3331.98	420.038
3335.14	455.177
3338.29	459.247
3341.45	427.573
3344.6	413.895
3347.75	472.254
3350.9	461.22
3354.05	493.525
3357.2	442.121
3360.35	434.154
3363.49	502.736
3366.64	507.257
3369.78	521.299
3372.92	524.095
3376.06	510.089
3379.2	473.472
3382.34	549.341
3385.48	551.465
3388.61	606.703
3391.75	571.159
3394.88	597.049
3398.01	608.322
3401.14	626.238
3404.27	669.006
3407.4	731.017
3410.52	855.069
3413.65	983.128
3416.77	1320.53
3419.89	2220.84
3423.01	4621.89
3426.13	7805.18
3429.25	6768.16
3432.37	3496.19
3435.49	1796.63
3438.6	1156.57
3441.72	924.606
3444.83	764.234
3447.94	689.425
3451.05	645.137
3454.16	667.336
3457.26	657.088
3460.37	631.39
3463.47	632.315
3466.58	600.851
3469.68	608.103
3472.78	612.203
3475.88	633.857
3478.98	664.082
3482.07	710.414
3485.17	736.88
3488.26	821.985
3491.36	927.103
3494.45	1090.25
3497.54	1306.06
3500.63	1687.59
3503.72	2074.6
3506.81	2550.34
3509.89	2655.41
3512.98	2436.34
3516.06	1952.03
3519.14	1469.38
3522.22	1169.14
3525.3	917.935
3528.38	801.988
3531.45	693.532
3534.53	552.526
3537.61	529.711
3540.68	487.236
3543.75	480.335
3546.82	454.298
3549.89	404.718
3552.96	411.434
3556.03	396.273
3559.09	347.261
3562.16	358.798
3565.22	323.633
3568.28	348.885
3571.34	271.237
3574.4	296.276
3577.46	298.616
3580.52	318.867
3583.57	303.914
3586.63	281.248
3589.68	281.335
3592.73	243.334
3595.78	254.604
3598.83	234.483
3601.88	218.164
3604.93	242.43
3607.97	210.752
3611.02	215.03
3614.06	171.983
3617.1	214.887
3620.14	170.955
3623.18	171.463
3626.22	213.49
3629.26	184.87
3632.3	217.432
3635.33	186.823
3638.36	158.416
3641.4	184.748
3644.43	140.645
3647.46	157.991
3650.49	155.258
3653.51	123.514
3656.54	142.082
3659.57	93.5266
3662.59	142.691
3665.61	108.802
3668.63	96.9917
3671.65	111.824
3674.67	123.892
3677.69	74.6768
3680.71	83.0754
3683.72	106.543
3686.74	90.3299
3689.75	65.6116
3692.76	63.6125
3695.77	82.4623
3698.78	66.9963
3701.79	65.9625
3704.79	15.5606
3707.8	57.2178
3710.81	91.1967
3713.81	53.8076
3716.81	42.8926
3719.81	46.3117
3722.81	50.5555
3725.81	38.5272
3728.81	58.7784
3731.8	50.3898
3734.8	61.8964
3737.79	58.051
3740.78	43.6455
3743.77	33.8838
3746.76	48.7753
3749.75	33.1331
3752.74	47.8336
3755.73	13.1337
3758.71	47.7624
3761.7	42.4958
3764.68	47.5754
3767.66	16.6932
3770.64	17.1518
3773.62	48.9086
3776.6	66.528
3779.58	28.441
3782.55	28.2287
3785.53	37.4731
3788.5	58.0962
3791.47	41.9618
3794.44	64.6827
3797.41	13.8622
3800.38	27.282
3803.35	39.8896
3806.32	40.2746
3809.28	31.2393
3812.24	49.6655
3815.21	-9.40521
3818.17	39.3344
3821.13	34.2119
3824.09	29.108
3827.04	25.0128
3830	19.9727
3832.96	36.7363
3835.91	19.4409
3838.86	-8.28107
3841.82	31.4456
3844.77	54.0978
3847.72	41.5798
3850.67	20.5067
3853.61	48.0817
3856.56	41.3637
3859.5	31.778
3862.45	48.952
3865.39	44.0885
3868.33	27.721
3871.27	16.0392
3874.21	59.939
3877.15	53.9487
3880.09	25.7533
3883.02	51.2292
3885.96	17.9851
3888.89	43.29
3891.82	46.4534
3894.75	5.33319
3897.68	36.2155
3900.61	36.2177
3903.54	56.3853
3906.47	46.6284
3909.39	30.2588
3912.31	33.9877
3915.24	45.3117
3918.16	19.1138
3921.08	51.6639
3924	48.496
3926.92	25.0798
3929.83	35.1602
3932.75	14.5286
3935.67	44.8971
3938.58	16.0721
3941.49	25.7189
3944.4	54.429
3947.31	11.3828
3950.22	28.7474
3953.13	29.9033
3956.04	13.8599
3958.94	27.5884
3961.85	35.6181
3964.75	30.2767
3967.65	32.6557
3970.55	45.6371
3973.45	52.8978
3976.35	34.2143
3979.25	20.2586
3982.15	24.4938
3985.04	16.2177
3987.94	27.1263
3990.83	26.4686
3993.72	17.0483
3996.61	52.0515
3999.5	38.9349
4002.39	48.9644
4005.28	12.7847
4008.16	-0.252075
4011.05	29.1245
4013.93	49.8336
4016.81	30.0511
4019.7	27.6243
4022.58	24.226
4025.46	22.7621
4028.33	41.6079
4031.21	16.975
4034.09	31.9966
4036.96	24.7882
4039.84	46.6548
4042.71	7.49878
4045.58	29.2053
4048.45	27.7115
4051.32	23.3562
4054.19	31.6558
4057.05	26.4626
4059.92	14.4312
4062.78	-6.38861
4065.65	35.963
4068.51	22.9146
4071.37	25.4096
4074.23	38.6127
4077.09	33.304
4079.95	23.1111
4082.81	28.5046
4085.66	52.441
4088.52	47.0837
4091.37	35.8674
4094.22	13.9633
4097.07	31.0475
4099.92	27.6745
4102.77	42.8541
4105.62	25.743
4108.47	30.0408
4111.31	35.3341
4114.16	29.7642
4117	18.2366
4119.84	25.1859
4122.69	36.064
4125.53	18.6674
4128.36	7.16431
4131.2	38.9592
4134.04	38.5845
4136.88	19.8477
4139.71	30.4365
4142.54	36.3557
4145.38	26.7073
4148.21	17.3938
4151.04	17.9335
4153.87	24.1625
4156.69	17.3652
4159.52	37.6288
4162.35	14.1598
4165.17	13.3071
4168	21.2476
4170.82	37.0526
4173.64	35.303
4176.46	17.9316
4179.28	25.0121
4182.1	-0.110291
4184.91	21.7424
4187.73	27.9982
4190.54	34.2797
4193.36	28.9491
4196.17	58.9583
4198.98	7.79132
4201.79	44.7774
4204.6	47.5092
4207.41	53.1549
4210.22	45.0756
4213.02	78.2339
4215.83	35.707
4218.63	49.7076
4221.44	17.3667
4224.24	11.5218
4227.04	11.4847
4229.84	47.1682
4232.64	34.4711
4235.43	26.8005
4238.23	23.1261
4241.02	44.29
4243.82	26.7438
4246.61	24.1366
4249.4	31.4445
4252.19	57.6651
4254.98	8.95142
4257.77	21.0971
4260.56	23.2411
4263.35	32.4468
4266.13	30.6566
4268.92	38.9717
4271.7	9.03979
4274.48	0.17572
4277.26	15.3522
4280.04	39.5344
4282.82	33.3835
4285.6	27.1411
4288.38	30.9108
4291.15	32.5751
4293.93	13.9545
4296.7	-3.56232
4299.47	11.4039
4302.25	15.1576
4305.02	22.9658
4307.79	-0.696472
4310.55	12.228
4313.32	13.041
4316.09	38.1432
4318.85	11.3011
4321.62	41.3901
4324.38	44.9619
4327.14	31.1864
4329.9	34.7497
4332.66	17.8568
4335.42	23.4213
4338.18	25.8544
4340.94	8.05188
4343.69	-4.65961
4346.45	18.3922
4349.2	50.7145
4351.95	20.8022
4354.7	36.0046
4357.45	15.3629
4360.2	27.4273
4362.95	23.0854
4365.7	11.6422
4368.44	42.1346
4371.19	23.5211
4373.93	51.9456
4376.68	28.031
4379.42	48.1869
4382.16	13.8961
4384.9	5.31781
4387.64	11.2858
4390.37	23.7213
4393.11	32.1752
4395.85	4.0412
4398.58	44.5735
4401.31	52.037
4404.05	19.0123
4406.78	31.6093
4409.51	19.3295
4412.24	22.5366
4414.96	32.9315
4417.69	22.4703
4420.42	13.7818
4423.14	1.04767
4425.87	38.4494
4428.59	21.5779
4431.31	24.5461
4434.03	24.3618
4436.75	17.8591
4439.47	42.7434
4442.19	21.4579
4444.91	9.60626
4447.62	29.1791
4450.34	28.8219
4453.05	47.3063
4455.76	26.9175
4458.47	48.4879
4461.19	35.3473
4463.89	33.8574
4466.6	19.723
4469.31	39.2962
4472.02	26.2749
4474.72	17.5138
4477.43	66.7808
4480.13	24.3884
4482.83	49.54
4485.53	24.0087
4488.23	18.4711
4490.93	30.8824
4493.63	2.91614
4496.33	15.0555
4499.02	20.9706
4501.72	39.5637
4504.41	28.4369
4507.11	31.1503
4509.8	24.3378
4512.49	35.5587
4515.18	31.9409
4517.87	25.1495
4520.56	21.5649
4523.24	31.8652
4525.93	45.3642
4528.61	51.4124
4531.3	28.7216
4533.98	32.6653
4536.66	29.1644
4539.34	40.6246
4542.02	31.8406
4544.7	42.2764
4547.38	15.2934
4550.05	45.0332
4552.73	32.005
4555.4	51.2527
4558.08	26.5821
4560.75	36.4648
4563.42	-3.10895
4566.09	38.3791
4568.76	35.8131
4571.43	42.597
4574.1	36.7376
4576.77	40.376
4579.43	24.7691
4582.1	12.6557
4584.76	-5.91779
4587.42	8.91296
4590.08	7.36511
4592.74	18.8407
4595.4	22.7272
4598.06	16.8517
4600.72	18.5559
4603.38	13.8088
4606.03	13.4689
4608.69	35.0519
4611.34	22.6667
4613.99	16.8189
4616.64	24.1385
4619.29	6.19379
4621.94	30.0876
4624.59	24.2362
4627.24	28.2498
4629.89	16.7795
4632.53	19.6279
4635.18	26.8111
4637.82	28.4253
4640.46	11.2081
4643.1	11.6986
4645.74	13.4284
4648.38	25.2921
4651.02	32.8787
4653.66	16.2134
4656.3	31.5564
4658.93	21.7613
4661.57	38.0357
4664.2	42.1501
4666.83	10.4052
4669.46	19.8669
4672.09	9.2312
4674.72	22.0933
4677.35	20.3832
4679.98	7.42908
4682.61	27.0071
4685.23	28.6249
4687.86	22.3653
4690.48	-0.785706
4693.1	27.8499
4695.73	18.1436
4698.34	29.8422
4700.96	6.57159
4703.58	9.22424
4706.2	31.0383
4708.82	39.2836
4711.43	12.4394
4714.05	27.435
4716.66	35.6207
4719.28	26.7898
4721.89	33.7913
4724.5	22.6288
4727.11	35.3437
4729.72	25.408
4732.33	20.0013
4734.93	37.3022
4737.54	14.8199
4740.14	24.1108
4742.75	19.7372
4745.35	24.4128
4747.95	21.0818
4750.55	39.2889
4753.15	18.8193
4755.75	6.29709
4758.35	29.0522
4760.95	32.507
4763.54	46.2466
4766.14	19.0161
4768.73	22.6508
4771.33	12.6422
4773.92	28.7516
4776.51	18.6276
4779.1	19.913
4781.69	44.0367
4784.28	21.3207
4786.87	13.4512
4789.45	20.4455
4792.04	17.1604
4794.63	35.6488
4797.21	40.4227
4799.79	16.5872
4802.37	7.66412
4804.95	10.2492
4807.53	17.4977
4810.11	20.1906
4812.69	-1.31265
4815.27	3.68604
4817.84	36.4366
4820.42	27.6844
4822.99	21.218
4825.57	-2.6434
4828.14	37.2416
4830.71	23.7862
4833.28	-1.29199
4835.85	26.0033
4838.42	-2.57169
4840.98	-3.14877
4843.55	11.4646
4846.12	2.5871
4848.68	20.6255
4851.24	27.9731
4853.81	36.1696
4856.37	9.18671
4858.93	32.0767
4861.49	32.5894
4864.05	17.6103
4866.61	1.25052
4869.16	13.2756
4871.72	11.2225
4874.27	-1.61328
4876.83	24.6052
4879.38	57.9778
4881.93	-0.0583801
4884.49	3.58072
4887.04	15.5417
4889.58	18.0139
4892.13	1.44974
4894.68	32.4818
4897.23	13.4922
4899.77	21.8877
4902.32	5.23715
4904.86	16.0119
4907.4	-1.87314
4909.95	29.1784
4912.49	32.6707
4915.03	9.85229
4917.57	20.4375
4920.1	0.0209656
4922.64	17.8357
4925.18	34.4701
4927.71	8.12485
4930.25	16.3803
4932.78	2.05386
4935.31	9.33731
4937.84	20.1712
4940.38	19.0416
4942.9	9.33438
4945.43	14.17
4947.96	17.8925
4950.49	18.0128
4953.01	38.5667
4955.54	13.501
4958.06	14.9106
4960.59	24.7751
4963.11	20.281
4965.63	-2.13647
4968.15	22.4721
4970.67	15.6556
4973.19	26.922
4975.71	29.7495
4978.22	12.0276
4980.74	-10.5329
4983.25	29.8686
4985.77	13.3884
4988.28	13.8898
4990.79	21.7029
4993.3	44.1174
4995.81	25.1932
4998.32	39.2175