File: Data/3-Raman/processed/bu19(2)w-a-ff2-fi05-v_1800 (450-850nm)_532nm_edge_100%_x100_vis_lwd_h100um_30sx2_01.txt
#Acq. time (s)=	30
#Accumulations=	2
#Range (cm-¹)=	1200...2365
#Windows=	3
#Auto scanning=	Off
#Autofocus=	Off
#Macrospot=	Off
#AutoExposure=	Off
#Spike filter=	Multiple accum.
#Delay time (s)=	2
#Binning=	1
#Readout mode=	Signal
#DeNoise=	Off
#ICS correction=	On
#Dark correction=	Off
#Inst. Process=	Off
#Detector Gain=	Best Dynamic
#Detector ADC=	50 kHz HS
#Detector temperature (°C)=	-60.09
#Instrument=	LabRAM HR Evol
#Detector=	SIN-EM FIVIS
#Objective=	x100_VIS_LWD
#Grating=	1800 (450-850nm)
#ND Filter=	100%
#Laser=	532nm_Edge
#Hole=	100.021
#Temperature=	0
#Range=	Visible
#StageXY=	75x50mm Scan+
#StageZ=	Z motor
#X (µm)=	0
#Y (µm)=	0
#Z (µm)=	-51.2
#Full time(mm:ss)=	3:17
#Project=	21_11_26
#Sample=	BU19(2)w
#Site=
#Title=	BU19(2)w-A-FF2-FI05-V_1800 (450-850nm)_532nm_Edge_100%_x100_VIS_LWD_H100um_30sX2
#Remark=
#Date=	26.11.2021 15:09
#Acquired=	26.11.2021 15:09:56
#Base:Fit=	16.12.2021 16:00:56
#Base:Fit=	16.12.2021 16:11:37
#Base:Sub=	16.12.2021 16:11:38
1202.72	11.625
1203.84	1.89182
1204.95	-2.70374
1206.06	15.0938
1207.17	-0.494431
1208.28	8.73671
1209.39	1.89775
1210.5	-5.89404
1211.61	4.25433
1212.72	-6.91928
1213.83	-0.956512
1214.94	20.056
1216.05	13.3641
1217.16	12.7822
1218.27	-7.90984
1219.38	7.60078
1220.49	0.855896
1221.6	4.73347
1222.71	6.2778
1223.81	-2.86813
1224.92	1.87375
1226.03	-8.98216
1227.14	-0.887558
1228.25	5.71222
1229.35	4.89954
1230.46	5.14885
1231.57	1.09021
1232.67	-5.53134
1233.78	7.76428
1234.89	-1.92863
1235.99	-7.40874
1237.1	2.74229
1238.2	4.26016
1239.31	-0.494766
1240.41	-4.02121
1241.52	-10.5968
1242.62	7.88683
1243.73	-0.732925
1244.83	14.6907
1245.94	11.0484
1247.04	2.26077
1248.14	-2.26309
1249.25	-0.570953
1250.35	12.7426
1251.45	9.13387
1252.56	1.39647
1253.66	2.02777
1254.76	7.10902
1255.87	-3.55341
1256.97	23.3997
1258.07	35.6308
1259.17	38.3971
1260.27	17.4392
1261.37	41.9962
1262.48	88.3331
1263.58	112.34
1264.68	71.3279
1265.78	43.6804
1266.88	28.8583
1267.98	36.2291
1269.08	40.5699
1270.18	32.0158
1271.28	32.6631
1272.38	28.34
1273.47	30.569
1274.57	44.2915
1275.67	33.6902
1276.77	50.5418
1277.87	32.7704
1278.97	74.9414
1280.07	114.853
1281.16	252.548
1282.26	908.535
1283.36	2054.76
1284.45	1023.73
1285.55	232.756
1286.65	109.421
1287.75	62.9055
1288.84	32.2524
1289.94	41.8221
1291.03	30.2591
1292.13	35.4563
1293.22	32.2486
1294.32	9.32785
1295.42	22.0161
1296.51	15.1057
1297.61	24.5753
1298.7	15.9875
1299.79	16.9237
1300.89	12.7817
1301.98	-1.95311
1303.08	3.40874
1304.17	9.6895
1305.26	12.869
1306.35	0.0538025
1307.45	-5.21446
1308.54	2.23645
1309.63	2.36058
1310.73	3.51399
1311.82	2.56128
1312.91	22.8032
1314	2.75117
1315.09	2.85672
1316.18	-0.108917
1317.28	6.28694
1318.37	7.51323
1319.46	-7.16098
1320.55	1.40335
1321.64	-11.3012
1322.73	0.236465
1323.82	-3.93372
1324.91	-9.06602
1326	-0.639359
1327.09	3.3544
1328.18	9.13585
1329.27	-1.00238
1330.35	8.61259
1331.44	3.30824
1332.53	-2.10982
1333.62	-6.43312
1334.71	1.89841
1335.79	5.03505
1336.88	9.26471
1337.97	-1.13023
1339.06	-7.40178
1340.14	19.9972
1341.23	6.58441
1342.32	5.6403
1343.4	17.1448
1344.49	3.71878
1345.58	12.1742
1346.66	4.75128
1347.75	6.77617
1348.83	-2.50352
1349.92	-4.53157
1351	12.1634
1352.09	11.1658
1353.17	-4.0938
1354.25	29.6526
1355.34	26.1937
1356.42	2.48546
1357.51	14.021
1358.59	18.2488
1359.67	16.234
1360.76	18.312
1361.84	14.3186
1362.92	28.9532
1364	31.3266
1365.09	35.6809
1366.17	29.4887
1367.25	34.6257
1368.33	49.3139
1369.41	110.612
1370.5	34.2632
1371.58	39.4521
1372.66	42.4181
1373.74	39.3847
1374.82	33.3542
1375.9	47.9981
1376.98	63.5566
1378.06	60.6011
1379.14	77.7543
1380.22	89.1739
1381.3	91.8836
1382.38	127.757
1383.46	154.18
1384.54	269.031
1385.61	722.259
1386.69	3488.09
1387.77	2335.42
1388.85	412.183
1389.93	160.016
1391	117.654
1392.08	84.8338
1393.16	58.214
1394.23	56.2881
1395.31	69.7955
1396.39	67.0266
1397.46	54.8293
1398.54	43.7383
1399.62	45.078
1400.69	47.4222
1401.77	52.8687
1402.84	41.1532
1403.92	67.2524
1404.99	64.1958
1406.07	109.343
1407.14	125.858
1408.22	237.909
1409.29	179.779
1410.37	79.5349
1411.44	41.5366
1412.51	46.8101
1413.59	26.095
1414.66	21.9178
1415.73	26.3131
1416.81	18.3549
1417.88	27.8874
1418.95	21.9453
1420.02	31.3198
1421.1	26.1861
1422.17	13.0301
1423.24	22.8994
1424.31	34.6614
1425.38	22.5344
1426.45	13.5301
1427.52	1.19211
1428.59	18.5758
1429.67	1.3875
1430.74	17.0913
1431.81	18.5438
1432.87	13.4514
1433.95	11.2476
1435.01	17.6152
1436.08	14.6867
1437.15	12.7184
1438.22	15.8786
1439.29	5.84503
1440.36	8.17781
1441.43	4.26506
1442.49	10.5276
1443.56	11.6706
1444.63	10.7305
1445.7	1.77963
1446.77	-1.239
1447.83	7.01149
1448.9	7.18857
1449.97	1.119
1451.03	2.16275
1452.1	12.4495
1453.17	9.47249
1454.23	-3.71375
1455.3	9.69475
1456.36	-14.7586
1457.43	3.70717
1458.49	-4.42691
1459.56	13.1136
1460.62	-1.16959
1461.69	2.92822
1462.75	3.90128
1463.82	-6.41531
1464.88	-1.01683
1465.94	-2.515
1467.01	0.558792
1468.07	-2.46315
1469.13	7.77855
1470.2	6.69714
1471.26	-1.49155
1472.32	12.7233
1473.39	-0.488495
1474.45	-7.64838
1475.51	-16.7252
1476.57	18.8763
1477.63	9.66911
1478.69	-7.64143
1479.76	4.47534
1480.82	4.30872
1481.88	-2.82535
1482.94	5.46487
1484	-8.68074
1485.06	-8.00754
1486.12	5.13908
1487.18	11.2681
1488.24	4.10133
1489.3	-21.3305
1490.36	-0.11084
1491.42	8.90739
1492.48	-6.26163
1493.53	-1.21507
1494.59	6.87875
1495.65	4.7878
1496.71	2.58925
1497.77	0.523285
1498.82	-10.5838
1499.88	3.59174
1500.94	-6.48833
1502	-9.58972
1503.05	5.47069
1504.11	-4.71495
1505.17	2.35533
1506.22	-1.85483
1507.28	7.21909
1508.34	17.2839
1509.39	0.142822
1510.45	0.156189
1511.5	7.0174
1512.56	7.62241
1513.61	4.37274
1514.67	-7.58125
1515.72	16.3261
1516.78	-9.95921
1517.83	-11.0172
1518.88	0.0549774
1519.94	-0.926468
1520.99	-1.98497
1522.05	-2.98689
1523.1	11.944
1524.15	2.66486
1525.2	13.5612
1526.26	13.6078
1527.31	4.65427
1528.36	-4.47699
1529.41	23.4594
1530.47	-1.67935
1531.52	15.4338
1532.57	7.34293
1533.62	8.50763
1534.67	11.5009
1535.72	9.35411
1536.77	17.0421
1537.82	-6.235
1538.87	11.5954
1539.92	-12.1853
1540.97	-9.94106
1542.02	-1.08833
1543.07	14.6899
1544.12	3.40169
1545.17	17.4741
1546.22	9.60486
1547.27	0.573547
1548.32	7.42677
1549.37	-2.75385
1550.42	0.254959
1551.46	11.7953
1552.51	6.7207
1553.56	0.49437
1554.61	2.29782
1555.65	5.07018
1556.7	12.0024
1557.75	8.96503
1558.79	3.73561
1559.84	4.45139
1560.89	-3.70659
1561.93	9.25764
1562.98	13.3002
1564.02	-8.80215
1565.07	4.28706
1566.11	-11.8737
1567.16	8.78482
1568.2	10.8726
1569.25	12.8541
1570.29	1.69321
1571.34	-0.377197
1572.38	8.45883
1573.43	-2.71111
1574.47	-0.80101
1575.51	-10.6746
1576.56	-5.71915
1577.6	7.96915
1578.64	5.67889
1579.69	12.5774
1580.73	-11.3617
1581.77	-4.53136
1582.81	-5.69876
1583.85	-0.820297
1584.9	8.08873
1585.94	5.02527
1586.98	-5.14209
1588.02	2.6819
1589.06	-16.2242
1590.1	0.704529
1591.14	-1.29529
1592.18	3.58014
1593.22	3.33447
1594.26	4.97646
1595.3	11.9059
1596.34	-6.104
1597.38	-6.14388
1598.42	5.72597
1599.46	10.4527
1600.5	-1.64685
1601.54	11.9569
1602.58	17.6319
1603.62	13.4347
1604.66	14.3206
1605.69	-8.45886
1606.73	10.3663
1607.77	7.41789
1608.81	2.31929
1609.84	6.86267
1610.88	10.1685
1611.92	7.40491
1612.95	1.71458
1613.99	-0.330902
1615.03	-2.5307
1616.06	7.04922
1617.1	0.496918
1618.13	8.9881
1619.17	-0.812729
1620.2	-1.42035
1621.24	4.85519
1622.27	6.40088
1623.31	6.34978
1624.34	-1.2711
1625.38	8.39415
1626.41	8.68944
1627.45	4.974
1628.48	5.58937
1629.51	-3.10234
1630.55	4.62608
1631.53	3.77348
1632.57	3.79872
1633.62	3.71832
1634.66	13.5594
1635.71	-7.21686
1636.75	10.3769
1637.8	1.34142
1638.84	5.16193
1639.89	3.13538
1640.93	1.14236
1641.98	2.07079
1643.02	18.7094
1644.06	0.905685
1645.11	4.7054
1646.15	2.7444
1647.19	1.63434
1648.24	8.40585
1649.28	8.53859
1650.32	-2.34258
1651.37	4.68027
1652.41	-4.19661
1653.45	-4.28523
1654.49	7.53691
1655.53	17.4407
1656.57	4.78738
1657.62	5.73802
1658.66	-8.18571
1659.7	18.2936
1660.74	-3.46777
1661.78	0.579163
1662.82	-1.21364
1663.86	-1.2251
1664.9	-3.36084
1665.94	1.29036
1666.98	17.3035
1668.02	0.382553
1669.06	7.30124
1670.1	10.3821
1671.14	8.52873
1672.18	11.4309
1673.21	2.53105
1674.25	-4.3678
1675.29	17.4826
1676.33	7.61375
1677.37	15.5294
1678.4	-1.40941
1679.44	-8.47562
1680.48	4.28523
1681.52	-11.6075
1682.55	0.22583
1683.59	-3.75458
1684.63	3.09622
1685.66	7.98132
1686.7	3.05035
1687.73	-7.78029
1688.77	8.91295
1689.81	-5.05444
1690.84	-7.08582
1691.88	13.6974
1692.91	-10.0171
1693.95	-13.1623
1694.98	5.41122
1696.01	-3.43166
1697.05	0.559052
1698.08	0.399826
1699.12	-1.70459
1700.15	-4.6673
1701.18	-2.75107
1702.22	-6.78252
1703.25	-0.0201111
1704.28	6.80798
1705.32	4.88345
1706.35	-2.03633
1707.38	2.69289
1708.41	-2.42416
1709.44	-0.696609
1710.48	15.9073
1711.51	3.25394
1712.54	-14.3575
1713.57	6.89238
1714.6	-6.98596
1715.63	15.4885
1716.66	1.81618
1717.69	2.5542
1718.72	2.24345
1719.75	0.231598
1720.78	-4.63539
1721.81	0.0764771
1722.84	-8.84828
1723.87	-6.05934
1724.9	1.66057
1725.93	-4.41206
1726.96	-3.49954
1727.99	17.7716
1729.02	9.6344
1730.05	6.54735
1731.07	-3.20764
1732.1	2.82964
1733.13	9.52625
1734.16	5.41583
1735.18	13.8552
1736.21	11.7492
1737.24	-0.836182
1738.26	5.80116
1739.29	-6.84265
1740.32	-4.23041
1741.34	7.06862
1742.37	-2.62558
1743.4	8.82181
1744.42	-0.82695
1745.45	-3.71631
1746.47	7.70633
1747.5	-7.76949
1748.52	0.7314
1749.55	-2.06714
1750.57	3.84218
1751.6	3.94861
1752.62	-6.72121
1753.64	4.59467
1754.67	-5.07076
1755.69	-2.28946
1756.71	6.13358
1757.74	-9.27129
1758.76	6.03499
1759.78	7.02902
1760.81	12.7059
1761.83	10.6936
1762.85	-1.65678
1763.87	-1.61089
1764.89	9.97429
1765.92	5.32828
1766.94	-0.374695
1767.96	-2.31323
1768.98	15.7037
1770	2.05669
1771.02	1.23253
1772.04	-3.33958
1773.06	4.40363
1774.08	14.9833
1775.1	9.36031
1776.12	8.62486
1777.14	3.88074
1778.16	5.68443
1779.18	1.73459
1780.2	-1.13109
1781.22	8.47404
1782.24	-2.87254
1783.26	-5.58383
1784.28	16.4629
1785.29	-1.50313
1786.31	-7.25468
1787.33	-9.05472
1788.35	13.3035
1789.37	18.4128
1790.38	3.28348
1791.4	-6.30536
1792.42	0.274216
1793.43	3.22736
1794.45	16.7024
1795.47	-8.03035
1796.48	-2.04584
1797.5	-3.80214
1798.51	-10.4209
1799.53	3.03952
1800.55	12.5337
1801.56	-4.7991
1802.58	5.82243
1803.59	0.21051
1804.61	0.312378
1805.62	-4.32413
1806.64	3.54732
1807.65	5.54179
1808.66	-2.14349
1809.68	-1.13899
1810.69	9.50479
1811.7	4.67039
1812.72	-11.6787
1813.73	-3.85551
1814.74	4.05107
1815.76	13.8751
1816.77	-9.26886
1817.78	10.921
1818.79	-0.631821
1819.8	-5.39899
1820.82	-5.30521
1821.83	-2.30235
1822.84	6.49591
1823.85	-1.2408
1824.86	11.3579
1825.87	-8.89896
1826.88	10.4873
1827.89	6.67577
1828.9	-5.92068
1829.91	-6.94328
1830.92	-5.07623
1831.93	6.61977
1832.94	7.70792
1833.95	-4.83797
1834.96	-11.742
1835.97	-7.17598
1836.98	-7.47806
1837.99	-4.17984
1839	4.5137
1840	-2.00565
1841.01	-11.0802
1842.02	-7.547
1843.03	6.76164
1844.04	0.00416565
1845.04	-7.71269
1846.05	1.01926
1847.06	12.7901
1848.07	9.20337
1849.07	-2.32056
1850.08	-0.54805
1851.09	-4.6319
1852.09	-3.80206
1853.1	6.73921
1854.1	2.81065
1855.11	-1.23688
1856.11	-11.0088
1857.12	-4.3437
1858.12	2.27585
1859.13	-14.1585
1860.13	-7.60373
1861.14	2.02336
1862.14	-2.67236
1863.15	-4.72345
1864.15	-5.85808
1865.15	0.671234
1866.16	-9.12445
1867.16	2.92955
1868.16	-6.8394
1869.17	8.33124
1870.17	-1.23076
1871.17	-3.18416
1872.17	-5.17545
1873.18	4.18484
1874.18	11.6768
1875.18	-0.85817
1876.18	6.41626
1877.18	-8.00342
1878.18	3.98991
1879.19	7.12302
1880.19	13.8822
1881.19	10.0448
1882.19	-4.45464
1883.19	7.39374
1884.19	9.98178
1885.19	6.28427
1886.19	1.78516
1887.19	5.50659
1888.19	-5.08496
1889.19	9.7054
1890.19	-5.49881
1891.19	0.235474
1892.18	2.98773
1893.18	9.45895
1894.18	-16.2549
1895.18	12.7545
1896.18	-10.7076
1897.18	8.1842
1898.17	11.9652
1899.17	0.531189
1900.17	9.76051
1901.16	2.20308
1902.16	13.5985
1903.16	3.29263
1904.16	13.5252
1905.15	-7.22884
1906.15	3.93796
1907.14	-4.68875
1908.14	4.68845
1909.14	2.85492
1910.13	7.69498
1911.13	1.30464
1912.12	2.26218
1913.12	5.95795
1914.11	2.24229
1915.11	-8.92961
1916.1	9.02618
1917.1	-9.97685
1918.09	4.03392
1919.08	-0.597015
1920.08	9.07256
1921.07	-9.83017
1922.06	-2.16064
1923.06	11.0073
1924.05	-7.07819
1925.04	0.347168
1926.04	-3.34679
1927.03	6.28531
1928.02	-7.84161
1929.01	-5.91321
1930	0.832535
1931	4.79083
1931.99	4.72572
1932.98	2.67155
1933.97	1.71048
1934.96	-6.34409
1935.95	6.41324
1936.94	-2.39697
1937.93	-1.65489
1938.92	-0.758392
1939.91	8.83008
1940.9	-11.0961
1941.89	5.24336
1942.88	0.508728
1943.87	-0.602936
1944.86	-1.46791
1945.85	-5.15285
1946.84	-6.98698
1947.83	0.588425
1948.82	-4.26248
1949.8	11.1199
1950.79	1.77557
1951.78	2.9868
1952.77	-14.1886
1953.76	-0.766327
1954.74	-10.8018
1955.73	7.26108
1956.72	6.59259
1957.7	4.81281
1958.69	-1.8613
1959.68	1.87428
1960.66	5.57199
1961.65	-6.12749
1962.63	6.30849
1963.62	-5.22458
1964.61	0.550827
1965.59	-9.11861
1966.58	-10.0262
1967.56	7.31671
1968.55	7.30768
1969.53	3.3119
1970.52	3.05093
1971.5	7.68832
1972.48	5.72375
1973.47	1.80055
1974.45	3.55151
1975.44	14.0689
1976.42	2.62309
1977.4	-1.24234
1978.39	2.45338
1979.37	-2.4431
1980.35	4.24181
1981.33	6.96864
1982.31	4.93916
1983.3	8.60687
1984.28	3.64412
1985.26	-1.26796
1986.24	4.36417
1987.22	0.567902
1988.21	16.6305
1989.19	-5.5648
1990.17	4.84763
1991.15	17.1931
1992.13	4.59128
1993.11	4.65442
1994.09	6.34267
1995.07	7.48787
1996.05	4.1602
1997.03	4.72023
1998.01	17.3329
1998.99	13.0357
1999.97	7.44862
2000.95	10.6895
2001.92	8.9765
2002.9	13.9777
2003.88	12.2944
2004.86	14.4039
2005.84	12.0464
2006.81	12.3916
2007.79	5.87263
2008.77	11.384
2009.75	11.7375
2010.73	14.6578
2011.7	19.0388
2012.68	13.5671
2013.67	21.8056
2014.66	24.2875
2015.64	11.9934
2016.63	11.132
2017.62	16.8922
2018.61	10.054
2019.6	7.89117
2020.58	9.67854
2021.57	10.6173
2022.56	18.9889
2023.55	-2.71587
2024.54	13.9559
2025.52	7.16351
2026.51	10.7395
2027.5	17.7874
2028.48	4.48103
2029.47	7.58136
2030.45	-4.1806
2031.44	2.43211
2032.43	5.26662
2033.41	-5.70718
2034.4	-1.0083
2035.38	6.18846
2036.37	-1.82384
2037.35	7.47998
2038.34	-8.45828
2039.32	10.1264
2040.31	-3.09613
2041.29	4.1976
2042.27	7.85045
2043.26	-11.7842
2044.24	2.41501
2045.23	1.38586
2046.21	-3.83392
2047.19	-8.65242
2048.17	-6.99294
2049.16	7.98386
2050.14	11.0096
2051.12	2.76184
2052.11	8.27475
2053.09	-1.92085
2054.07	-5.45068
2055.05	16.1391
2056.03	16.0631
2057.01	-4.54471
2058	1.12622
2058.98	-2.45625
2059.96	2.32999
2060.94	2.28416
2061.92	-11.6638
2062.9	-2.23778
2063.88	8.20361
2064.86	0.800842
2065.84	3.81361
2066.82	-6.37724
2067.8	-7.21562
2068.78	1.35025
2069.76	-2.43127
2070.73	-8.99887
2071.71	-6.98029
2072.69	-0.118698
2073.67	-2.94655
2074.65	10.3099
2075.63	1.14658
2076.6	7.03906
2077.58	6.0327
2078.56	-10.0175
2079.54	-5.17235
2080.51	-3.07578
2081.49	-11.5523
2082.47	2.65292
2083.45	-3.90405
2084.42	-8.60701
2085.4	-0.0603027
2086.37	-0.912247
2087.35	2.09917
2088.32	0.294113
2089.3	-2.47845
2090.28	12.8352
2091.25	-8.85907
2092.23	3.63716
2093.2	3.90544
2094.18	7.92122
2095.15	-1.51013
2096.13	-3.47185
2097.1	-6.32909
2098.07	-7.34508
2099.05	5.94064
2100.02	1.20897
2101	6.98026
2101.97	4.28902
2102.94	3.36684
2103.92	-2.37886
2104.89	-0.402176
2105.86	-10.6883
2106.83	8.44342
2107.8	-14.3186
2108.78	-4.94044
2109.75	4.60194
2110.72	5.63574
2111.69	-2.8833
2112.66	-0.99263
2113.63	-0.847137
2114.61	2.07666
2115.58	0.220734
2116.55	-12.1627
2117.52	-0.78418
2118.49	-2.70418
2119.46	4.75418
2120.43	-9.54845
2121.4	5.70294
2122.37	0.222839
2123.34	-3.422
2124.31	8.00426
2125.28	-12.0966
2126.25	-11.3302
2127.21	1.80995
2128.18	-2.94225
2129.15	6.53058
2130.12	-1.96947
2131.09	-1.9706
2132.06	6.47702
2133.02	2.64226
2133.99	7.4041
2134.96	1.80156
2135.93	-0.0738373
2136.89	8.29619
2137.86	1.78458
2138.83	0.827393
2139.79	5.6333
2140.76	7.41504
2141.73	3.65067
2142.69	-3.92293
2143.66	11.332
2144.62	-3.09088
2145.59	-9.61436
2146.55	0.745575
2147.52	-4.91461
2148.48	9.14114
2149.45	8.13922
2150.42	3.28709
2151.38	9.85458
2152.34	2.49271
2153.31	0.607346
2154.27	15.5587
2155.24	2.23747
2156.2	-10.0975
2157.16	4.83656
2158.13	1.21913
2159.09	-5.24847
2160.05	-11.8378
2161.01	9.52614
2161.98	-2.61993
2162.94	1.14996
2163.9	12.3111
2164.86	4.77109
2165.83	1.08899
2166.79	2.96396
2167.75	7.53563
2168.71	1.7511
2169.67	10.2334
2170.63	5.85312
2171.59	5.85074
2172.56	-1.83911
2173.51	0.932419
2174.48	7.53236
2175.44	-8.21617
2176.4	1.0844
2177.36	4.79175
2178.32	-3.51387
2179.28	5.71356
2180.23	2.05531
2181.19	2.99818
2182.15	3.91223
2183.11	14.0939
2184.07	3.76726
2185.03	-3.65927
2185.99	1.0815
2186.95	5.90387
2187.9	-4.07211
2188.86	7.96724
2189.82	4.10649
2190.78	-5.19876
2191.73	-5.11992
2192.69	1.47122
2193.65	10.897
2194.6	3.77072
2195.56	-6.43051
2196.52	5.51175
2197.47	3.52956
2198.43	10.9881
2199.38	7.52104
2200.34	2.23817
2201.3	-3.94679
2202.25	12.247
2203.21	1.44019
2204.16	11.4409
2205.12	3.68623
2206.07	-3.20753
2207.03	6.10985
2207.98	-16.072
2208.93	5.50334
2209.89	-0.924408
2210.84	-2.70531
2211.8	0.235031
2212.75	1.3154
2213.7	5.00505
2214.66	-9.80212
2215.61	5.27313
2216.56	-9.62166
2217.51	-3.07332
2218.47	-7.69807
2219.42	2.68431
2220.37	6.5457
2221.32	5.60548
2222.27	-4.7964
2223.23	-2.88863
2224.18	-12.9946
2225.13	0.301224
2226.08	0.498444
2227.03	-10.582
2227.98	-6.7149
2228.93	-1.10133
2229.88	10.1885
2230.83	1.92986
2231.78	3.05219
2232.73	-7.12407
2233.68	0.550873
2234.63	6.29192
2235.58	8.06876
2236.53	2.42764
2237.48	-1.24249
2238.43	-5.69031
2239.38	14.3459
2240.33	-0.797012
2241.27	3.07755
2242.22	-4.40016
2243.17	-1.48648
2244.12	0.357056
2245.07	-5.2068
2246.01	-6.87399
2246.96	2.72202
2247.91	-4.74799
2248.85	7.54523
2249.8	1.89378
2250.75	-0.0119781
2251.69	5.55099
2252.64	5.61699
2253.59	4.94733
2254.53	0.389999
2255.48	-5.25917
2256.42	1.4438
2257.37	2.53403
2258.32	0.740448
2259.26	3.67123
2260.2	-1.93214
2261.15	5.77248
2262.1	-1.70581
2263.04	-7.30899
2263.98	-5.19461
2264.93	11.2875
2265.87	2.83168
2266.81	-8.69069
2267.76	17.9158
2268.7	-6.01604
2269.65	2.69817
2270.59	1.02452
2271.53	8.81654
2272.47	-1.58499
2273.42	2.29318
2274.36	4.26463
2275.3	-0.462158
2276.24	-7.10448
2277.18	-1.18445
2278.13	4.81894
2279.07	9.75867
2280.01	5.80791
2280.95	-2.01727
2281.89	-1.11722
2282.83	3.78708
2283.77	10.7288
2284.71	7.19879
2285.65	1.56155
2286.59	-3.3291
2287.54	-1.19849
2288.47	3.71771
2289.41	17.0788
2290.35	2.4397
2291.29	2.47345
2292.23	-7.9193
2293.17	10.5402
2294.11	3.90541
2295.05	6.7235
2295.99	3.75746
2296.93	-2.13535
2297.86	3.77065
2298.8	5.89278
2299.74	3.17241
2300.68	-2.58121
2301.61	2.35692
2302.55	4.30539
2303.49	9.1328
2304.43	6.30954
2305.36	-5.15099
2306.3	13.2958
2307.24	4.65324
2308.17	-0.210632
2309.11	-6.00574
2310.04	-0.0330963
2310.98	2.94708
2311.92	-0.19487
2312.85	4.49704
2313.79	8.43175
2314.72	8.68733
2315.66	3.9882
2316.59	6.69115
2317.52	1.81854
2318.46	3.80392
2319.39	7.58192
2320.33	6.58475
2321.26	-2.02885
2322.2	6.83562
2323.13	3.10641
2324.06	4.14262
2325	7.0161
2325.93	20.3666
2326.86	97.4204
2327.79	272.69
2328.73	85.6307
2329.66	33.4785
2330.59	16.1509
2331.52	4.59297
2332.46	0.813828
2333.39	10.3618
2334.32	5.4903
2335.25	5.39526
2336.18	3.49937
2337.11	-5.17268
2338.04	4.42879
2338.97	7.30205
2339.91	-2.28175
2340.84	-5.23227
2341.77	-3.48874
2342.7	4.07201
2343.63	-5.52428
2344.56	7.9164
2345.49	4.07368
2346.41	-1.79115
2347.34	-0.859512
2348.27	2.98628
2349.2	-0.808884
2350.13	-9.65402
2351.06	3.87961
2351.99	-7.83324
2352.91	-2.33963
2353.84	9.81519
2354.77	1.25858
2355.7	3.18369
2356.63	2.11888
2357.55	-8.54425
2358.48	7.5287
2359.41	-1.09853
2360.33	-4.03897
2361.26	-0.397018
2362.19	-6.25253
2363.11	-3.57346
2364.04	-12.1863
2364.97	-7.5526