File: Data/3-Raman/processed/bu19w-b-ff1-fi01-l_150 (500nm)_532nm_edge_100%_x100_vis_h50um_15sx2_01.txt
#Acq. time (s)=	15
#Accumulations=	2
#Range (cm-¹)=	100...5000
#Windows=	1
#Auto scanning=	Off
#Autofocus=	Off
#Macrospot=	Off
#AutoExposure=	Off
#Spike filter=	Multiple accum.
#Delay time (s)=	2
#Binning=	1
#Readout mode=	Signal
#DeNoise=	Off
#ICS correction=	On
#Dark correction=	Off
#Inst. Process=	Off
#Detector Gain=	Best Dynamic
#Detector ADC=	50 kHz HS
#Detector temperature (°C)=	-60.28
#Instrument=	LabRAM HR Evol
#Detector=	SIN-EM FIVIS
#Objective=	x100_VIS
#Grating=	150 (500nm)
#ND Filter=	100%
#Laser=	532nm_Edge
#Hole=	49.98
#Temperature=	0
#Range=	Visible
#StageXY=	75x50mm Scan+
#StageZ=	Z motor
#X (µm)=	0
#Y (µm)=	0
#Z (µm)=	-137.5
#Full time(s)=	35
#Project=	21_05_14
#Sample=	BU19w
#Site=
#Title=	BU19w-FF1-FI01-L_150 (500nm)_532nm_Edge_100%_x100_VIS_H50um_15sX2
#Remark=
#Date=	14.05.2021 11:29
#Acquired=	14.05.2021 11:29:41
#Base:Fit=	22.12.2021 12:22:35
#Base:Sub=	22.12.2021 12:23:11
#Data Range:Extract=	22.12.2021 12:27:19
102.699	3518.54
107.322	3086.27
111.942	2906.01
116.56	2648.89
121.173	2597.18
125.787	2349.3
130.398	2069.29
135.006	1822.68
139.613	1790.93
144.215	1634.26
148.817	1587.3
153.417	1540.59
158.014	1466.92
162.607	1238.61
167.2	1247.35
171.79	1897.01
176.379	3732.78
180.963	3623.91
185.547	1954.67
190.128	1353.81
194.705	1565.35
199.282	4119.72
203.857	10652.3
208.43	9205.98
212.998	3281.38
217.566	950.651
222.132	388.515
226.693	208.573
231.254	276.339
235.813	73.1157
240.368	-0.0776367
244.923	35.4468
249.475	304.406
254.023	362.494
258.571	863.015
263.117	1836.77
267.658	1659.22
272.199	1146.52
276.738	622.889
281.273	407.973
285.807	1056.47
290.34	3290.56
294.868	7473.02
299.396	7123.58
303.919	3392.37
308.443	1612.04
312.964	1788.4
317.481	3733.25
321.998	4593.95
326.51	2437.4
331.023	994.009
335.533	584.573
340.039	875.168
344.544	1708.5
349.046	1769.68
353.547	865.26
358.045	322.613
362.542	506.725
367.036	677.229
371.527	395.536
376.017	7.33667
380.503	-50.9741
384.99	-7.21729
389.471	90.939
393.953	45.8628
398.43	480.57
402.908	1038.76
407.381	1404.78
411.854	1517.31
416.323	1297.88
420.791	874.789
425.256	574.781
429.72	978.654
434.18	1654.84
438.64	1091.95
443.095	257.774
447.551	-59.8313
452.003	-83.8511
456.454	10.8481
460.901	157.004
465.348	718.516
469.791	2377.94
474.231	3195.66
478.672	1672.1
483.108	537.149
487.544	201.438
491.976	156.25
496.408	224.767
500.836	401.991
505.261	669.189
509.687	905.571
514.108	934.02
518.529	845.771
522.946	634.177
527.361	473.351
531.776	380.215
536.187	322.893
540.595	332.542
545.003	279.376
549.408	370.002
553.812	480.431
558.212	559.178
562.61	538.162
567.007	617.186
571.401	568.122
575.792	628.574
580.184	645.077
584.571	547.398
588.956	332.372
593.341	400.437
597.722	664.811
602.101	1861.6
606.48	3072.8
610.854	2195.15
615.227	1172.5
619.597	952.467
623.967	1550.3
628.334	2243.94
632.698	1997.38
637.06	1039.84
641.422	439.44
645.779	253.611
650.135	333.274
654.491	470.767
658.842	524.225
663.192	421.078
667.539	298.679
671.884	276.522
676.23	415.117
680.571	654.426
684.91	717.146
689.247	838.454
693.583	1103.68
697.916	989.817
702.247	622.5
706.576	336.38
710.902	192.818
715.229	112.296
719.551	83.9586
723.872	83.0408
728.19	85.8292
732.506	30.0702
736.82	45.2808
741.134	2.85242
745.444	-0.939941
749.752	60.3619
754.058	46.9359
758.362	80.4537
762.664	107.948
766.964	188.519
771.264	307.78
775.559	405.541
779.853	606.485
784.144	1131.12
788.434	2248.08
792.722	3474.83
797.007	3676.36
801.29	2559.86
805.572	1467.35
809.851	799.968
814.13	482.744
818.406	376.36
822.679	288.068
826.95	215.317
831.219	125.988
835.486	123.467
839.752	112.994
844.015	106.452
848.276	103.933
852.535	80.2427
856.792	80.766
861.047	21.5604
865.3	48.6487
869.551	32.3633
873.8	90.1497
878.047	93.6918
882.292	181.69
886.534	140.746
890.775	105.785
895.014	17.4501
899.251	1.41565
903.486	17.6156
907.719	-4.61487
911.95	61.0392
916.179	30.9988
920.406	23.7072
924.63	23.5415
928.853	19.604
933.074	63.0851
937.293	76.827
941.51	96.6713
945.723	116.031
949.936	183.859
954.147	265.517
958.356	336.56
962.563	540.456
966.768	624.118
970.971	644.589
975.172	657.751
979.371	817.656
983.568	956.379
987.761	888.085
991.954	644.801
996.145	415.938
1000.33	287.932
1004.52	304.235
1008.71	233.816
1012.89	259.314
1017.07	237.893
1021.25	257.916
1025.43	260.754
1029.6	216.593
1033.77	323.03
1037.95	378.03
1042.11	381.966
1046.28	478.517
1050.45	618.784
1054.61	796.792
1058.77	1336.5
1062.93	2395.12
1067.09	4217.65
1071.24	4831.33
1075.4	3495.11
1079.55	2175.27
1083.7	1444.83
1087.85	1251.58
1091.99	1316.59
1096.14	1873.63
1100.28	2836.16
1104.42	4186.92
1108.55	4673.46
1112.69	3852.37
1116.82	3039.65
1120.96	3178.84
1125.09	3773.96
1129.21	3935.47
1133.34	3396.05
1137.46	3106.66
1141.59	3092.81
1145.71	3524.25
1149.83	3613.41
1153.94	2959.7
1158.06	2189.22
1162.17	1775.94
1166.28	1897.67
1170.39	2523.11
1174.5	3063.02
1178.6	2632.98
1182.7	1786.07
1186.8	1418.11
1190.9	1010.56
1195	799.085
1199.1	619.329
1203.19	557.101
1207.28	556.029
1211.37	600.619
1215.46	582.495
1219.54	530.731
1223.63	450.305
1227.71	422.256
1231.79	405.151
1235.87	605.795
1239.95	835.143
1244.02	803.046
1248.09	727.949
1252.16	1035.97
1256.23	1355.78
1260.3	1183.49
1264.36	779.225
1268.43	519.065
1272.49	399.808
1276.55	363.535
1280.6	314.976
1284.66	314.969
1288.71	303.815
1292.76	233.712
1296.81	182.587
1300.86	112.913
1304.91	143.645
1308.95	145.226
1312.99	145.083
1317.03	183.518
1321.07	168.304
1325.11	150.957
1329.14	169.218
1333.18	152.481
1337.21	108.305
1341.24	126.988
1345.26	104.551
1349.29	161.891
1353.31	140.559
1357.33	129.216
1361.35	115.869
1365.37	104.149
1369.39	172.652
1373.4	184.355
1377.41	271.11
1381.43	448.068
1385.43	657.321
1389.44	634.483
1393.45	402.082
1397.45	251.72
1401.45	171.707
1405.45	138.234
1409.45	100.969
1413.44	64.7894
1417.44	90.7041
1421.43	89.8621
1425.42	87.3417
1429.41	61.4299
1433.39	20.2639
1437.38	34.0704
1441.36	42.0183
1445.34	76.1864
1449.32	71.7927
1453.3	62.0394
1457.27	49.1826
1461.24	60.3608
1465.22	56.327
1469.19	70.1997
1473.15	71.3488
1477.12	58.3267
1481.09	29.5535
1485.05	40.7843
1489.01	-0.744385
1492.97	22.3623
1496.93	33.7833
1500.88	61.0947
1504.83	45.0692
1508.79	6.17163
1512.74	30.4364
1516.68	70.4164
1520.63	57.1996
1524.57	53.8156
1528.52	52.597
1532.46	24.4178
1536.4	47.6187
1540.33	73.7878
1544.27	80.5597
1548.2	67.9736
1552.14	94.9794
1556.07	68.3771
1559.99	84.1187
1563.92	67.7179
1567.84	94.6528
1571.77	117.602
1575.69	120.211
1579.61	62.9287
1583.52	87.561
1587.44	113.945
1591.35	102.75
1595.27	142.494
1599.18	164.989
1603.09	134.955
1606.99	132.993
1610.9	199.141
1614.8	167.778
1618.7	138.457
1622.6	188.648
1626.5	157.896
1630.39	146.753
1634.29	199.172
1638.18	222.965
1642.07	236.959
1645.96	241.657
1649.85	208.152
1653.73	240.783
1657.62	271.355
1661.5	212.349
1665.38	220.187
1669.26	212.213
1673.13	239.316
1677.01	232.18
1680.88	158.677
1684.75	157.035
1688.62	134.95
1692.49	116.327
1696.35	145.228
1700.22	136.391
1704.08	103.301
1707.94	100.294
1711.8	89.511
1715.66	77.9473
1719.51	76.8838
1723.37	82.3447
1727.22	45.1543
1731.07	53.092
1734.92	71.3074
1738.76	58.2847
1742.61	66.7166
1746.45	45.2358
1750.29	49.1111
1754.13	51.1226
1757.97	50.1384
1761.81	91.9377
1765.64	39.1045
1769.47	41.4749
1773.31	59.1704
1777.14	57.7017
1780.96	69.9148
1784.79	78.6714
1788.61	9.00073
1792.43	83.5723
1796.25	-1.31689
1800.07	40.6567
1803.89	47.0759
1807.71	29.8804
1811.52	54.7434
1815.33	29.8726
1819.14	75.9368
1822.95	15.9082
1826.76	14.833
1830.56	45.2258
1834.37	50.6533
1838.17	28.4634
1841.97	1.19336
1845.77	-2.61768
1849.56	38.1724
1853.36	3.14355
1857.15	38.6277
1860.94	47.4338
1864.73	53.4724
1868.52	29.1477
1872.31	34.8872
1876.09	54.7583
1879.87	53.0117
1883.66	59.1396
1887.43	-7.85327
1891.21	56.1848
1894.99	64.8486
1898.76	43.7397
1902.53	70.2759
1906.31	53.8223
1910.08	96.9109
1913.84	87.0369
1917.61	40.1267
1921.37	58.6511
1925.14	66.3608
1928.9	46.5332
1932.66	30.3958
1936.41	41.1765
1940.17	73.4463
1943.92	59.4648
1947.68	71.6597
1951.43	93.3726
1955.18	76.5112
1958.92	18.1252
1962.67	104.192
1966.41	99.845
1970.16	52.1406
1973.9	57.5259
1977.64	70.8774
1981.37	119.403
1985.11	45.1038
1988.84	73.386
1992.57	31.2529
1996.31	74.3518
2000.03	59.5352
2003.76	82.0874
2007.49	71.4353
2011.21	45.0906
2014.93	91.0674
2018.65	80.6484
2022.37	93.2373
2026.09	107.954
2029.81	110.332
2033.52	52.647
2037.23	51.9993
2040.94	86.2852
2044.65	119.33
2048.36	43.9131
2052.07	129.979
2055.77	132.209
2059.47	50.0671
2063.17	57.605
2066.87	106.868
2070.57	127.792
2074.27	79.5457
2077.96	79.5254
2081.65	89.6409
2085.34	97.4968
2089.03	87.5168
2092.72	102.863
2096.41	126.134
2100.09	119.432
2103.77	106.788
2107.46	82.5847
2111.14	106.543
2114.81	119.273
2118.49	83.9282
2122.16	78.3887
2125.84	111.628
2129.51	115.669
2133.18	53.9985
2136.85	73.4524
2140.51	97.0403
2144.18	108.368
2147.84	103.064
2151.5	117.988
2155.16	94.5356
2158.82	101.481
2162.48	94.2075
2166.13	114.67
2169.79	86.5691
2173.44	84.946
2177.09	107.165
2180.74	98.6558
2184.38	94.7273
2188.03	97.3474
2191.67	119.889
2195.32	140.588
2198.96	122.344
2202.6	142.744
2206.23	129.787
2209.87	119.916
2213.5	52.5029
2217.14	119.857
2220.77	113.061
2224.4	132.968
2228.03	122.355
2231.65	123.039
2235.28	104.366
2238.9	130.909
2242.52	91.623
2246.14	74.4966
2249.76	89.2246
2253.38	117.3
2256.99	144.626
2260.6	157.791
2264.21	143.747
2267.82	103.897
2271.44	137.297
2275.04	36.019
2278.65	86.4685
2282.25	108.501
2285.85	100.828
2289.45	122.048
2293.05	46.7102
2296.65	73.6851
2300.25	95.7947
2303.84	70.0093
2307.43	109.24
2311.02	87.5093
2314.62	96.6799
2318.2	46.6511
2321.79	25.0854
2325.38	77.2837
2328.96	71.8381
2332.54	64.0669
2336.12	54.2107
2339.7	76.0632
2343.28	57.2456
2346.85	54.1785
2350.43	39.8037
2354	81.3787
2357.57	17.3535
2361.14	38.1233
2364.71	61.6807
2368.27	16.0486
2371.84	46.6836
2375.4	47.4424
2378.96	78.9087
2382.52	74.645
2386.08	69.7756
2389.64	69.0549
2393.19	73.4995
2396.75	47.5508
2400.3	104.187
2403.85	48.9529
2407.4	62.8816
2410.95	45.6577
2414.49	64.6328
2418.04	60.2434
2421.58	55.3228
2425.12	30.7007
2428.66	59.1709
2432.2	5.78247
2435.74	41.6475
2439.27	22.9331
2442.81	28.5037
2446.34	-3.99023
2449.87	81.0364
2453.4	70.9443
2456.93	56.9165
2460.45	79.5278
2463.98	79.646
2467.5	84.2207
2471.02	63.7944
2474.54	46.0901
2478.06	72.6113
2481.58	30.8586
2485.09	44.4021
2488.61	95.4724
2492.12	109.151
2495.63	110.939
2499.14	55.0759
2502.65	35.8962
2506.15	27.6843
2509.66	62.1414
2513.16	7.73145
2516.66	12.4341
2520.16	31.834
2523.66	43.1108
2527.16	48.0674
2530.66	9.91919
2534.15	80.4451
2537.64	12.9771
2541.13	28.5752
2544.62	73.9861
2548.11	66.0859
2551.6	30.7634
2555.08	44.8066
2558.57	29.2148
2562.05	41.3896
2565.53	17.116
2569.01	52.1917
2572.49	80.407
2575.96	39.7693
2579.44	65.9751
2582.91	61.2483
2586.38	72.3025
2589.85	44.2385
2593.32	74.27
2596.79	35.4033
2600.25	52.0134
2603.72	28.3923
2607.18	3.08325
2610.64	21.5181
2614.1	55.3315
2617.56	35.5286
2621.02	68.1311
2624.47	50.1238
2627.92	53.853
2631.38	15.8508
2634.83	23.2288
2638.28	47.4482
2641.72	34.7222
2645.17	37.2295
2648.61	38.3433
2652.06	56.9771
2655.5	37.9497
2658.94	26.3423
2662.38	76.9136
2665.82	82.9224
2669.25	48.1694
2672.69	57.1033
2676.12	42.8752
2679.55	48.7971
2682.98	14.1694
2686.41	27.6038
2689.84	18.1592
2693.26	36.9744
2696.69	75.7537
2700.11	47.877
2703.53	40.884
2706.95	73.7563
2710.37	-9.9707
2713.79	57.45
2717.2	76.9829
2720.62	58.6721
2724.03	81.571
2727.44	57.0969
2730.85	47.4033
2734.26	81.6992
2737.66	96.4038
2741.07	57.2354
2744.47	39.1506
2747.87	71.8362
2751.28	46.1948
2754.67	86.8838
2758.07	76.1313
2761.47	33.6299
2764.86	68.0811
2768.26	76.6306
2771.65	20.0427
2775.04	47.8965
2778.43	101.753
2781.82	44.2961
2785.2	70.5254
2788.59	72.259
2791.97	42.7893
2795.35	107.484
2798.73	64.6235
2802.11	41.54
2805.49	72.8262
2808.87	56.196
2812.24	116.198
2815.62	39.4729
2818.99	81.749
2822.36	66.5051
2825.73	37.4443
2829.1	68.2866
2832.46	83.6953
2835.83	83.6248
2839.19	40.1938
2842.55	134.168
2845.91	116.089
2849.27	60.761
2852.63	83.3027
2855.99	79.9548
2859.34	83.5137
2862.69	118.082
2866.05	112.511
2869.4	129.287
2872.75	106.542
2876.09	70.4995
2879.44	95.5935
2882.78	119.615
2886.13	110.478
2889.47	127.939
2892.81	153.272
2896.15	117.808
2899.49	124.539
2902.82	157.432
2906.16	113.528
2909.49	107.225
2912.82	126.47
2916.16	126.375
2919.49	97.7439
2922.81	166.467
2926.14	144.91
2929.46	145.941
2932.79	157.784
2936.11	164.896
2939.43	198.387
2942.75	146.169
2946.07	159.108
2949.39	174.782
2952.7	140.552
2956.02	219.404
2959.33	184.987
2962.64	224.645
2965.95	186.96
2969.26	230.854
2972.57	249.954
2975.87	243.699
2979.17	257.591
2982.48	227.499
2985.78	275.495
2989.08	282.266
2992.38	244.99
2995.68	299.959
2998.97	281.674
3002.27	314.043
3005.56	274.209
3008.85	319.197
3012.14	326.672
3015.43	345.401
3018.72	365.045
3022	319.581
3025.29	329.833
3028.57	383.541
3031.85	365.365
3035.14	385.817
3038.41	424.288
3041.69	434.413
3044.97	492.943
3048.24	400.801
3051.52	485.007
3054.79	430.785
3058.06	475.83
3061.33	489.927
3064.6	553.609
3067.87	496.421
3071.13	517.916
3074.4	593.832
3077.66	592.942
3080.92	616.262
3084.18	584.14
3087.44	648.366
3090.7	675.274
3093.95	701.415
3097.21	695.588
3100.46	731.62
3103.71	775.186
3106.96	811.324
3110.21	831.421
3113.46	855.259
3116.71	943.994
3119.95	915.641
3123.2	942.499
3126.44	990.24
3129.68	1038.97
3132.92	1059.08
3136.16	1105.74
3139.4	1146.6
3142.63	1185.56
3145.87	1243.75
3149.1	1167.62
3152.33	1266.87
3155.56	1349.99
3158.79	1360.54
3162.02	1461.75
3165.25	1495.95
3168.47	1567.1
3171.69	1566.5
3174.92	1595.21
3178.14	1686.75
3181.36	1733.51
3184.58	1789.48
3187.79	1817.57
3191.01	1818.93
3194.22	1926.96
3197.43	1925.29
3200.65	1969.43
3203.86	2030.82
3207.07	2108.53
3210.27	2163.62
3213.48	2096.28
3216.69	2177.43
3219.89	2320.47
3223.09	2294.59
3226.29	2422
3229.49	2359.52
3232.69	2369.05
3235.89	2432.6
3239.08	2476.62
3242.28	2504.75
3245.47	2606.28
3248.66	2572.91
3251.85	2618.89
3255.04	2633.46
3258.23	2649.43
3261.42	2728.75
3264.6	2724.33
3267.79	2722.24
3270.97	2756.09
3274.15	2773.69
3277.33	2835.43
3280.51	2873.17
3283.68	2808.76
3286.86	2888.96
3290.04	2906.46
3293.21	3007.75
3296.38	2936.36
3299.55	3001.47
3302.72	3056.17
3305.89	3025.56
3309.06	3071.21
3312.22	3115.42
3315.39	3190.72
3318.55	3199.32
3321.71	3213.6
3324.87	3256.28
3328.03	3196.82
3331.19	3355.1
3334.34	3348.32
3337.5	3452.45
3340.65	3438.56
3343.81	3450.22
3346.96	3606.73
3350.11	3659.61
3353.25	3669.69
3356.4	3709.27
3359.55	3733.53
3362.69	3800.43
3365.84	3816.74
3368.98	3865.3
3372.12	3979.69
3375.26	3891.47
3378.4	4080.4
3381.53	4158.59
3384.67	4149.35
3387.8	4168.6
3390.94	4262.04
3394.07	4392.9
3397.2	4448.3
3400.33	4526.71
3403.46	4592.62
3406.58	4641.98
3409.71	4753.56
3412.83	4880.94
3415.96	5106.98
3419.08	5444.53
3422.2	5987.24
3425.32	7368.04
3428.44	10743.9
3431.55	19352.9
3434.67	26384.6
3437.78	19884.7
3440.89	11126.8
3444	7332.87
3447.12	6091.31
3450.22	5519.57
3453.33	5172.23
3456.44	4941.34
3459.54	4827.53
3462.65	4825.76
3465.75	4763.63
3468.85	4735.6
3471.95	4594.93
3475.05	4555.45
3478.15	4649.75
3481.24	4521.91
3484.34	4500.41
3487.43	4420.02
3490.53	4486.14
3493.62	4526.03
3496.71	4536.89
3499.79	4613.36
3502.88	4827.93
3505.97	5080.5
3509.05	5567.76
3512.14	6059.1
3515.22	6489.31
3518.3	6545.81
3521.38	6006.87
3524.46	5184.82
3527.54	4665.15
3530.61	4258.41
3533.69	3801.09
3536.76	3644.02
3539.83	3355.77
3542.9	3208.54
3545.97	3140.35
3549.04	3027.86
3552.11	2895.39
3555.18	2897.88
3558.24	2722.9
3561.3	2599.72
3564.37	2490.29
3567.43	2519.4
3570.49	2444.43
3573.55	2280.75
3576.61	2281.9
3579.66	2214.43
3582.72	2086.85
3585.77	2099.53
3588.82	1963.93
3591.87	1903.09
3594.92	1868.54
3597.97	1838.67
3601.02	1768.79
3604.07	1731.78
3607.11	1703.23
3610.16	1662.29
3613.2	1563.62
3616.24	1490.62
3619.28	1461.27
3622.32	1431.12
3625.36	1469.05
3628.39	1372.17
3631.43	1287.41
3634.46	1220.18
3637.5	1193.95
3640.53	1139.84
3643.56	1101.49
3646.59	1045.78
3649.62	1040.29
3652.64	944.364
3655.67	888.726
3658.69	828.891
3661.72	790.27
3664.74	727.911
3667.76	681.639
3670.78	674.241
3673.79	599.016
3676.81	561.626
3679.83	486.329
3682.84	513.037
3685.86	480.232
3688.87	430.41
3691.88	418.485
3694.89	373.011
3697.9	340.055
3700.91	297.688
3703.91	294.199
3706.92	259.165
3709.92	243.897
3712.92	239.781
3715.92	222.403
3718.92	219.149
3721.92	183.344
3724.92	189.255
3727.92	181.7
3730.91	157.792
3733.91	165.109
3736.9	143.699
3739.89	143.033
3742.88	167.889
3745.87	129.797
3748.86	119.152
3751.85	172.085
3754.83	90.2356
3757.82	117.544
3760.8	96.3464
3763.78	103.581
3766.76	129.846
3769.74	74.8975
3772.72	31.4956
3775.7	100.7
3778.67	89.6752
3781.65	62.6464
3784.62	37.6061
3787.6	55.1436
3790.57	62.535
3793.54	25.7451
3796.51	108.93
3799.47	76.2271
3802.44	90.8574
3805.41	38.4803
3808.37	80.6683
3811.33	51.0986
3814.3	59.3761
3817.26	80.032
3820.22	65.7194
3823.18	69.5028
3826.13	48.6985
3829.09	49.6577
3832.04	30.8158
3835	32.0034
3837.95	60.7762
3840.9	44.8773
3843.85	61.3346
3846.8	43.5859
3849.75	2.07288
3852.69	38.7721
3855.64	43.0883
3858.58	57.0033
3861.53	42.1581
3864.47	65.5775
3867.41	27.5969
3870.35	55.652
3873.29	75.0616
3876.22	33.8461
3879.16	34.6831
3882.1	44.9341
3885.03	53.1244
3887.96	81.4305
3890.89	42.3766
3893.82	33.9128
3896.75	75.2429
3899.68	36.7183
3902.61	55.658
3905.53	51.6827
3908.46	71.6603
3911.38	21.3452
3914.3	74.6033
3917.23	53.235
3920.15	55.6743
3923.06	33.913
3925.98	50.3838
3928.9	55.174
3931.81	31.5226
3934.73	58.9692
3937.64	85.8333
3940.55	8.23462
3943.46	34.0767
3946.37	74.428
3949.28	45.985
3952.19	86.5486
3955.09	65.0092
3958	19.5957
3960.9	59.5295
3963.8	67.9408
3966.71	38.0747
3969.61	52.3949
3972.51	81.1213
3975.4	20.4528
3978.3	56.6748
3981.2	37.1377
3984.09	55.0067
3986.99	77.6924
3989.88	21.2415
3992.77	61.2422
3995.66	-0.736328
3998.55	21.0736
4001.43	23.6573