File: Data/3-Raman/processed/bu19w-d-ore2-fi11-v_150 (500nm)_532nm_edge_100%_x100_vis_lwd_h50um_30sx2_01_0.txt
#Acq. time (s)=	30
#Accumulations=	2
#Range (cm-¹)=	100...4000
#Windows=	1
#Auto scanning=	Off
#Autofocus=	Off
#Macrospot=	Off
#AutoExposure=	Off
#Spike filter=	Multiple accum.
#Delay time (s)=	2
#Binning=	1
#Readout mode=	Signal
#DeNoise=	Off
#ICS correction=	On
#Dark correction=	Off
#Inst. Process=	Off
#Detector Gain=	Best Dynamic
#Detector ADC=	50 kHz HS
#Detector temperature (°C)=	-60.28
#Instrument=	LabRAM HR Evol
#Detector=	SIN-EM FIVIS
#Objective=	x100_VIS_LWD
#Grating=	150 (500nm)
#ND Filter=	100%
#Laser=	532nm_Edge
#Hole=	49.98
#Temperature=	0
#Range=	Visible
#StageXY=	75x50mm Scan+
#StageZ=	Z motor
#X (µm)=	0
#Y (µm)=	0
#Z (µm)=	37.7
#Full time(mm:ss)=	1:05
#Project=	21_11_22
#Sample=	BU19w
#Site=
#Title=	BU19w-D-FFore2-FI11-V_150 (500nm)_532nm_Edge_100%_x100_VIS_LWD_H50um_30sX2
#Remark=
#Date=	22.11.2021 14:15
#Acquired=	22.11.2021 14:15:07
#Base:Fit=	16.12.2021 17:39:50
#Base:Edit=	16.12.2021 17:40:18
#Base:Edit=	16.12.2021 17:40:19
#Base:Edit=	16.12.2021 17:40:24
#Base:Edit=	16.12.2021 17:40:33
#Base:Edit=	16.12.2021 17:40:35
#Base:Sub=	16.12.2021 17:40:38
103.97	1912.3
108.592	8026.93
113.209	12523.9
117.826	6097.5
122.441	1608.11
127.054	529.865
131.664	289.453
136.27	133.302
140.876	3.66284
145.48	12.8979
150.081	186.607
154.678	433.005
159.275	861.103
163.869	1415.39
168.461	2196.26
173.049	3629.87
177.637	5850.92
182.222	8870.37
186.806	11581.3
191.384	12665.4
195.963	11108.5
200.54	8468.51
205.112	5757.11
209.684	3903.78
214.253	2589.16
218.821	1934.25
223.384	1383.56
227.947	1054.41
232.507	843.305
237.064	730.765
241.62	905.673
246.174	1522.55
250.724	1634.96
255.273	772.592
259.82	305.822
264.363	95.1945
268.906	101.24
273.447	15.5457
277.983	21.4338
282.519	18.522
287.051	-9.99689
291.583	21.9407
296.112	36.3774
300.637	52.751
305.162	74.5134
309.685	84.8928
314.204	141.895
318.722	186.431
323.236	154.964
327.75	284.351
332.262	623.25
336.77	1842.33
341.277	2505.56
345.78	1272.21
350.283	485.877
354.782	317.271
359.28	294.561
363.775	324.936
368.269	389.826
372.761	603.828
377.249	1282.8
381.736	1370.71
386.22	1785.46
390.703	1491.24
395.182	793.428
399.661	541.905
404.136	559.606
408.61	601.255
413.08	688.66
417.551	778.01
422.017	1025.77
426.482	1400.28
430.944	2340.49
435.406	4155.39
439.863	8836.38
444.32	23440.7
448.773	37746.7
453.226	37779.5
457.674	19051.7
462.121	9042.71
466.567	5337.95
471.009	3618.43
475.452	2682.6
479.889	2140.6
484.327	1719.45
488.761	1422.18
493.194	1360.73
497.623	1300.1
502.051	1252.08
506.478	1161.91
510.9	979.133
515.323	807.97
519.742	721.481
524.158	666.489
528.574	632.407
532.987	559.148
537.397	513.599
541.807	464.449
546.212	421.048
550.618	405.363
555.019	383.421
559.419	359.788
563.818	374.659
568.213	357.511
572.606	361.307
576.999	361.538
581.388	341.401
585.775	314.035
590.161	285.263
594.544	300.107
598.924	263.996
603.304	245.3
607.68	238.565
612.055	210.192
616.426	240.821
620.798	206.161
625.166	202.369
629.532	226.588
633.897	186.471
638.258	154.752
642.618	146.964
646.975	163.015
651.332	112.57
655.685	129.508
660.036	164.993
664.385	184.286
668.734	184.224
673.079	266.306
677.421	536.778
681.762	755.004
686.1	602.113
690.439	321.137
694.773	173.174
699.105	146.799
703.435	101.516
707.763	94.6299
712.091	68.5909
716.415	81.4257
720.737	49.971
725.057	45.8542
729.375	55.8875
733.692	61.0599
738.006	29.0779
742.317	25.6997
746.627	44.2869
750.934	54.4323
755.24	93.4059
759.543	41.4332
763.846	72.1015
768.146	96.0601
772.443	164.488
776.738	287.6
781.031	427.034
785.322	524.819
789.611	788.413
793.898	984.301
798.183	722.634
802.466	328.318
806.748	194.135
811.027	108.508
815.304	112.128
819.579	115.779
823.851	72.3353
828.122	110.459
832.391	112.327
836.657	67.8797
840.922	75.2315
845.184	101.211
849.445	87.131
853.703	96.2596
857.96	170.415
862.214	199.273
866.467	165.193
870.717	114.616
874.965	73.9303
879.212	76.0009
883.456	89.8869
887.699	53.3139
891.939	24.2948
896.177	35.2433
900.414	32.3149
904.648	50.4503
908.88	62.3928
913.111	48.7466
917.339	28.5538
921.565	-7.84604
925.79	-4.66229
930.012	7.72693
934.232	-12.1118
938.451	3.32846
942.667	1.56799
946.881	-21.5605
951.094	-11.4419
955.302	-24.7172
959.511	-18.7599
963.717	-17.0139
967.921	-40.6866
972.124	-30.3052
976.324	-42.1473
980.523	-43.307
984.719	-20.1226
988.914	-23.4135
993.104	-43.3682
997.295	-31.3191
1001.48	-35.0879
1005.67	-25.0213
1009.85	-22.3618
1014.04	-28.3496
1018.22	-17.3154
1022.4	-10.6176
1026.57	-17.9773
1030.75	3.39084
1034.92	-3.43555
1039.09	26.7677
1043.26	47.2859
1047.42	129.189
1051.59	212.766
1055.75	201.636
1059.91	211.477
1064.07	278.91
1068.23	424.506
1072.38	298.319
1076.54	155.211
1080.69	62.6955
1084.84	51.5611
1088.98	36.4486
1093.13	24.6305
1097.27	21.228
1101.41	32.1955
1105.55	16.6624
1109.69	28.9363
1113.83	23.8568
1117.96	34.5797
1122.09	72.2546
1126.22	72.3385
1130.35	103.26
1134.47	225.406
1138.6	429.998
1142.72	899.85
1146.84	1262.68
1150.96	875.572
1155.07	398.605
1159.19	202.883
1163.3	107.019
1167.41	61.6123
1171.52	72.7846
1175.62	48.8067
1179.73	51.5857
1183.83	25.4541
1187.93	55.5828
1192.03	48.5896
1196.13	60.8845
1200.22	59.7375
1204.31	83.9301
1208.4	84.6787
1212.49	114.721
1216.58	167.789
1220.67	197.527
1224.75	142.963
1228.83	130.822
1232.91	134.002
1236.99	141.491
1241.06	154.813
1245.14	187.221
1249.21	342.702
1253.28	301.637
1257.35	238.625
1261.41	250.602
1265.48	706.193
1269.54	2202.24
1273.6	1467.06
1277.66	406.718
1281.72	158.495
1285.77	145.181
1289.82	125.739
1293.88	120.28
1297.92	103.674
1301.97	82.9282
1306.02	86.3095
1310.06	80.5688
1314.1	95.8298
1318.14	72.689
1322.18	101.764
1326.22	92.4734
1330.25	83.1748
1334.28	94.7947
1338.31	111.289
1342.34	120.671
1346.37	126.001
1350.39	146.236
1354.42	240.91
1358.44	280.657
1362.46	381.704
1366.47	606.1
1370.49	2081.73
1374.5	3709.05
1378.51	1565.64
1382.52	395.99
1386.53	229.475
1390.54	253.096
1394.54	383.299
1398.55	282.106
1402.55	145.319
1406.55	102.121
1410.54	85.5424
1414.54	64.0179
1418.53	82.9333
1422.52	54.4099
1426.51	67.175
1430.5	36.481
1434.49	50.2351
1438.47	43.2401
1442.45	37.1909
1446.43	33.0807
1450.41	37.8001
1454.39	15.8481
1458.36	14.5587
1462.34	6.27661
1466.31	29.4373
1470.28	22.1484
1474.24	5.03052
1478.21	26.1183
1482.17	21.686
1486.14	20.1729
1490.1	14.7794
1494.05	4.53943
1498.01	20.6413
1501.97	12.4528
1505.92	4.36813
1509.87	38.098
1513.82	17.4416
1517.77	24.0155
1521.71	38.3711
1525.66	21.7187
1529.6	28.3862
1533.54	48.6387
1537.48	29.1646
1541.41	42.6499
1545.35	32.8845
1549.28	47.346
1553.21	42.3981
1557.14	59.6707
1561.07	44.9571
1565	66.9787
1568.92	59.9552
1572.84	56.8024
1576.76	79.7034
1580.68	81.3501
1584.6	99.353
1588.51	67.2603
1592.43	103.512
1596.34	95.5045
1600.25	124.034
1604.16	125.729
1608.06	126.491
1611.97	147.412
1615.87	148.267
1619.77	151.028
1623.67	139.495
1627.57	106.988
1631.46	138.747
1635.36	138.934
1639.25	152.63
1643.14	141.546
1647.03	131.462
1650.91	112.763
1654.8	99.7761
1658.68	87.7213
1662.56	84.2429
1666.44	93.2177
1670.32	83.8222
1674.2	72.4746
1678.07	74.4113
1681.94	43.5978
1685.81	43.5053
1689.68	49.1009
1693.55	24.0238
1697.41	34.3142
1701.28	29.2514
1705.14	9.86578
1709	35.1414
1712.86	17.663
1716.72	11.6327
1720.57	12.2531
1724.42	9.08865
1728.28	21.8747
1732.13	9.31085
1735.97	14.5628
1739.82	1.0892
1743.66	-1.12421
1747.51	8.00616
1751.35	2.3924
1755.19	1.60425
1759.02	-7.97794
1762.86	-10.265
1766.69	0.513367
1770.53	-6.19034
1774.36	4.8027
1778.18	0.0774841
1782.01	-3.66309
1785.84	-12.9871
1789.66	6.71173
1793.48	-8.22244
1797.3	5.91876
1801.12	-8.30154
1804.94	12.2544
1808.75	4.54425
1812.57	2.43216
1816.38	7.74615
1820.19	-4.94867
1824	-12.0311
1827.8	1.56488
1831.61	14.1287
1835.41	3.08707
1839.21	18.3578
1843.01	-2.16479
1846.81	11.1664
1850.6	-1.88257
1854.4	20.5585
1858.19	2.70624
1861.98	14.6806
1865.77	6.20325
1869.56	7.0672
1873.34	14.4655
1877.13	5.25027
1880.91	11.8556
1884.69	10.187
1888.47	12.5146
1892.25	26.8546
1896.02	11.7442
1899.8	5.03564
1903.57	14.9618
1907.34	22.1661
1911.11	14.7345
1914.88	-2.83395
1918.64	16.6931
1922.41	19.6628
1926.17	5.98785
1929.93	38.7727
1933.69	-0.0529175
1937.44	8.55972
1941.2	22.8062
1944.95	37.1196
1948.7	34.3272
1952.46	18.2544
1956.2	22.6752
1959.95	21.3453
1963.7	29.3855
1967.44	42.0294
1971.18	62.9675
1974.92	27.582
1978.66	49.3014
1982.4	41.0051
1986.13	35.4886
1989.87	46.7107
1993.6	32.7197
1997.33	44.7056
2001.06	53.8643
2004.78	48.1815
2008.51	38.747
2012.23	50.513
2015.96	48.5953
2019.67	42.2783
2023.39	59.0497
2027.11	57.5373
2030.83	52.4652
2034.54	50.293
2038.25	27.9284
2041.96	65.0549
2045.67	56.391
2049.38	52.3635
2053.08	74.0021
2056.79	49.9663
2060.49	81.1652
2064.19	65.6458
2067.89	58.3843
2071.58	49.2485
2075.28	57.657
2078.97	54.0714
2082.67	64.351
2086.36	57.5873
2090.05	61.7459
2093.73	74.4225
2097.42	60.1062
2101.1	56.8121
2104.78	72.9861
2108.47	66.7779
2112.14	67.987
2115.82	71.0115
2119.5	73.901
2123.17	82.2589
2126.84	72.9369
2130.52	61.7394
2134.18	57.0151
2137.85	60.5517
2141.52	75.0761
2145.18	48.1218
2148.84	70.8378
2152.51	63.2236
2156.17	52.8941
2159.82	70.9552
2163.48	57.064
2167.14	56.0161
2170.79	66.0126
2174.44	50.5809
2178.09	67.9538
2181.74	61.6479
2185.38	63.5876
2189.03	51.0929
2192.67	54.1744
2196.32	53.6857
2199.96	53.2202
2203.59	55.5307
2207.23	76.1723
2210.87	53.8826
2214.5	56.2909
2218.13	63.295
2221.76	48.2552
2225.39	46.039
2229.02	29.9692
2232.65	43.4333
2236.27	58.7775
2239.89	53.7581
2243.51	53.3454
2247.13	50.1429
2250.75	60.9257
2254.37	53.1033
2257.98	57.3935
2261.59	36.3718
2265.2	67.8188
2268.81	48.6942
2272.42	52.9644
2276.03	38.287
2279.64	51.7047
2283.24	53.7623
2286.84	50.1562
2290.44	34.1981
2294.04	45.6593
2297.64	55.2466
2301.23	42.0531
2304.83	60.0523
2308.42	58.0999
2312.01	121.499
2315.6	391.427
2319.19	317.155
2322.77	114.876
2326.36	64.2099
2329.94	58.0077
2333.52	47.9962
2337.1	48.3242
2340.68	51.4303
2344.26	55.4193
2347.83	44.3739
2351.41	37.0867
2354.98	51.2651
2358.55	43.94
2362.12	40.3481
2365.69	42.3464
2369.25	53.6592
2372.82	42.7287
2376.38	35.5196
2379.94	35.7361
2383.5	47.0152
2387.06	35.3357
2390.61	35.6683
2394.17	28.7439
2397.72	47.5808
2401.27	33.5707
2404.82	31.5232
2408.37	10.3157
2411.92	39.6366
2415.47	9.34744
2419.01	22.2738
2422.55	28.845
2426.09	22.5856
2429.63	21.9069
2433.17	22.2106
2436.71	14.1858
2440.24	27.5579
2443.78	37.2671
2447.31	23.6842
2450.84	7.26373
2454.37	29.1655
2457.89	45.2377
2461.42	16.0403
2464.94	21.4878
2468.47	26.1652
2471.99	26.6884
2475.51	19.5395
2479.03	17.1704
2482.54	10.0013
2486.06	9.26285
2489.57	14.2734
2493.08	8.83917
2496.59	6.28455
2500.1	3.67587
2503.61	9.4198
2507.12	5.76401
2510.62	15.1559
2514.12	9.71603
2517.62	8.98019
2521.12	14.5328
2524.62	26.8185
2528.12	20.683
2531.61	2.5925
2535.11	5.83093
2538.6	9.12515
2542.09	7.01569
2545.58	0.419128
2549.07	-8.94955
2552.55	4.85791
2556.04	-4.31168
2559.52	-2.37939
2563	6.1944
2566.48	-0.950378
2569.96	-17.3996
2573.44	13.9077
2576.91	-4.35934
2580.39	7.45386
2583.86	-2.40625
2587.33	-5.74277
2590.8	-10.1902
2594.27	16.723
2597.74	-9.62183
2601.2	-13.1284
2604.67	-0.490906
2608.13	-15.8777
2611.59	4.02664
2615.05	0.0640564
2618.51	-4.02347
2621.96	-13.925
2625.42	21.2548
2628.87	-3.17044
2632.32	4.03558
2635.77	-3.23581
2639.22	-5.74948
2642.67	-9.27036
2646.11	-1.3345
2649.56	-0.157776
2653	-2.86154
2656.44	-0.866486
2659.88	-15.0114
2663.32	-13.0534
2666.76	-6.39166
2670.19	-11.0677
2673.63	-2.53775
2677.06	-8.04816
2680.49	-6.93274
2683.92	-17.8605
2687.35	-4.34778
2690.78	-9.36481
2694.2	0.453796
2697.63	1.0238
2701.05	-17.9183
2704.47	-8.96133
2707.89	-4.44437
2711.31	-14.7496
2714.72	-8.24924
2718.14	-16.5913
2721.55	-32.3716
2724.96	-14.541
2728.37	-26.5664
2731.78	-17.1026
2735.19	-8.55145
2738.6	-8.42935
2742	-26.1974
2745.41	-9.2674
2748.81	-21.4536
2752.21	-8.2674
2755.61	-18.6378
2759	-10.1614
2762.4	-17.7709
2765.8	-5.63077
2769.19	-13.3267
2772.58	-24.8083
2775.97	-25.9671
2779.36	-18.6867
2782.75	-18.9607
2786.13	-1.37189
2789.52	-3.54968
2792.9	-17.0096
2796.28	-3.2168
2799.66	2.06329
2803.04	-23.5927
2806.42	-1.44388
2809.79	-3.67859
2813.17	-4.98846
2816.54	2.10114
2819.91	-31.8439
2823.28	-1.34116
2826.65	5.84067
2830.02	-11.1732
2833.38	-20.6695
2836.75	3.41763
2840.11	-13.4273
2843.47	-0.394073
2846.83	-19.8864
2850.19	11.076
2853.55	-20.5457
2856.91	-11.9767
2860.26	10.6896
2863.61	-8.75864
2866.96	-1.03473
2870.31	-17.7381
2873.66	16.2925
2877.01	11.7899
2880.36	7.26819
2883.7	4.59842
2887.05	-2.80823
2890.39	15.2716
2893.73	20.0627
2897.07	2.11432
2900.4	10.5934
2903.74	15.2498
2907.07	7.57742
2910.41	21.6413
2913.74	26.2218
2917.07	28.8552
2920.4	32.4108
2923.73	27.4267
2927.05	16.7232
2930.38	39.0487
2933.7	39.5794
2937.02	50.4762
2940.34	47.2198
2943.66	42.0899
2946.98	36.9757
2950.3	63.8134
2953.61	53.0374
2956.92	69.5524
2960.24	57.9313
2963.55	66.0266
2966.86	51.7053
2970.16	83.4185
2973.47	74.7913
2976.78	80.3094
2980.08	67.94
2983.38	95.0049
2986.68	104.261
2989.98	95.6841
2993.28	93.6909
2996.58	92.651
2999.87	115.109
3003.17	111.233
3006.46	120.557
3009.75	125.196
3013.04	145.862
3016.33	139.19
3019.62	146.644
3022.91	172.03
3026.19	163.447
3029.47	162.397
3032.75	183.999
3036.03	184.791
3039.31	207.339
3042.59	216.654
3045.87	221.241
3049.14	222.974
3052.42	227.561
3055.69	272.904
3058.96	271.607
3062.23	274.171
3065.49	293.742
3068.76	307.523
3072.03	322.545
3075.29	306.005
3078.55	323.325
3081.81	343.122
3085.07	363.829
3088.33	400.892
3091.59	385.854
3094.85	423.013
3098.1	440.717
3101.35	462.978
3104.61	485.642
3107.85	523.448
3111.1	551.444
3114.35	570.946
3117.6	576.185
3120.84	580.46
3124.09	624.725
3127.33	637.513
3130.57	650.312
3133.81	680.232
3137.05	745.361
3140.28	753.271
3143.52	790.725
3146.75	786.292
3149.99	836.238
3153.22	870.865
3156.45	888.356
3159.68	934.416
3162.9	927.048
3166.13	962.492
3169.35	1007.37
3172.58	1021.64
3175.8	1048.17
3179.02	1099.46
3182.24	1146
3185.46	1171.34
3188.67	1181.36
3191.89	1252.34
3195.1	1282.28
3198.32	1256.91
3201.53	1322.05
3204.74	1383.38
3207.95	1367.68
3211.15	1416.77
3214.36	1406.99
3217.56	1467.59
3220.77	1445.47
3223.97	1485.36
3227.17	1486.26
3230.37	1506.35
3233.57	1562.42
3236.76	1558.97
3239.96	1599.42
3243.15	1659.06
3246.35	1609.12
3249.54	1713.8
3252.73	1674.58
3255.92	1651.52
3259.1	1706.44
3262.29	1688.5
3265.47	1742.85
3268.66	1743.48
3271.84	1754.47
3275.02	1798.88
3278.2	1783.61
3281.38	1787
3284.55	1815.25
3287.73	1831.8
3290.9	1853.29
3294.08	1885.15
3297.25	1882.65
3300.42	1934.09
3303.59	1981.04
3306.76	1993.48
3309.92	1995.06
3313.09	2027.8
3316.25	2035.76
3319.41	2079.62
3322.58	2057.12
3325.74	2090.5
3328.9	2121.97
3332.05	2206.47
3335.21	2189.09
3338.36	2222.89
3341.52	2251.95
3344.67	2308.01
3347.82	2330.85
3350.97	2378.11
3354.12	2397.42
3357.26	2439.49
3360.41	2464.96
3363.55	2512.19
3366.7	2547.35
3369.84	2596.79
3372.98	2617.37
3376.12	2683.44
3379.26	2724.24
3382.39	2703.46
3385.53	2710.37
3388.66	2739.1
3391.8	2729.97
3394.93	2796.47
3398.06	2851.72
3401.19	2828.61
3404.31	2845.66
3407.44	2936.17
3410.56	2882.18
3413.69	2921.56
3416.81	2944.58
3419.93	2925.39
3423.05	2997.12
3426.17	2967.07
3429.29	2969.03
3432.41	2977.98
3435.52	2965.97
3438.63	2923.9
3441.75	2959.13
3444.86	2920.15
3447.97	2915.5
3451.08	2929.38
3454.18	2944.17
3457.29	2918.47
3460.39	2815.75
3463.5	2801.4
3466.6	2805.65
3469.7	2749.42
3472.8	2670.71
3475.9	2619.76
3479	2564.33
3482.09	2605.46
3485.19	2536.27
3488.28	2520.43
3491.37	2442.3
3494.46	2440.57
3497.55	2375.43
3500.64	2294.48
3503.73	2247
3506.81	2167.66
3509.9	2112.03
3512.98	2022.91
3516.06	2029.18
3519.14	1994.07
3522.22	1904.44
3525.3	1902.14
3528.38	1816.54
3531.46	1750.34
3534.53	1674.54
3537.6	1622.44
3540.67	1582.85
3543.75	1575.7
3546.82	1487.11
3549.88	1451.83
3552.95	1400.23
3556.02	1323.4
3559.08	1296.77
3562.14	1282.06
3565.21	1205.51
3568.27	1167.42
3571.33	1106.74
3574.39	1122.97
3577.44	1017.72
3580.5	1003.43
3583.55	997.581
3586.61	952.895
3589.66	909.978
3592.71	845.298
3595.76	851.637
3598.81	797.41
3601.85	769.644
3604.9	739.014
3607.95	695.22
3610.99	660.912
3614.03	651.202
3617.07	620.839
3620.11	579.293
3623.15	557.674
3626.19	507.929
3629.22	483.664
3632.26	454.699
3635.29	414.757
3638.33	401.358
3641.36	330.714
3644.39	333.76
3647.42	261.326
3650.44	239.032
3653.47	210.062
3656.5	173.377
3659.52	156.387
3662.54	105.406
3665.56	105.967
3668.58	68.0677
3671.6	38.7003
3674.62	15.0478
3677.64	-8.54919
3680.65	-15.136
3683.67	-31.1286
3686.68	-37.6111
3689.69	-63.9192
3692.7	-38.0857
3695.71	-76.7217
3698.72	-82.0631
3701.73	-103.496
3704.73	-104.958
3707.74	-117.816
3710.74	-128.754
3713.74	-127.325
3716.75	-124.866
3719.75	-132.861
3722.74	-152.258
3725.74	-135.45
3728.74	-134.794
3731.73	-129.351
3734.73	-149.598
3737.72	-144.105
3740.71	-150.966
3743.7	-144.475
3746.69	-138.916
3749.68	-128.583
3752.66	-132.456
3755.65	-132.473
3758.63	-145.722
3761.62	-127.658
3764.6	-156.909
3767.58	-131.176
3770.56	-139.451
3773.54	-126.861
3776.51	-148.243
3779.49	-130.826
3782.46	-143.598
3785.44	-130.823
3788.41	-126.503
3791.38	-128.722
3794.35	-119.563
3797.32	-107.534
3800.29	-105.829
3803.25	-120.143
3806.22	-111.766
3809.18	-102.405
3812.14	-95.8527
3815.11	-105.355
3818.07	-95.9199
3821.03	-101.612
3823.98	-86.4462
3826.94	-81.6841
3829.9	-96.8381
3832.85	-84.4681
3835.8	-85.3725
3838.76	-82.4843
3841.71	-82.4596
3844.66	-85.3007
3847.61	-64.3394
3850.55	-63.3748
3853.5	-62.4288
3856.45	-59.5962
3859.39	-53.9189
3862.33	-51.1507
3865.27	-49.3722
3868.21	-42.859
3871.15	-25.8374
3874.09	-36.6796
3877.03	-41.8502
3879.96	-21.1634
3882.9	-23.6098
3885.83	-38.6331
3888.77	-9.50856
3891.7	-17.9568
3894.63	-11.1202
3897.56	-6.31183
3900.48	-23.7052
3903.41	-21.0214
3906.34	-3.98401
3909.26	3.31958
3912.18	-1.99103
3915.1	1.21895
3918.02	-1.4019
3920.94	2.53717
3923.86	-9.98358
3926.78	5.16739
3929.7	19.1909
3932.61	26.4071
3935.52	10.5337
3938.44	0.296875
3941.35	2.32477
3944.26	29.0856
3947.17	23.1392
3950.08	8.40773
3952.98	21.2625
3955.89	7.1223
3958.79	8.11034
3961.7	9.85454
3964.6	5.63768
3967.5	21.3469
3970.4	0.368088
3973.3	6.01015
3976.2	16.196
3979.09	15.5425
3981.99	5.00389
3984.88	-8.71548
3987.78	4.19943
3990.67	-7.25633
3993.56	-5.51108
3996.45	-12.7462
3999.34	-18.3713