File: Data/3-Raman/processed/bu19w-d-ff2-fi02-v_150 (500nm)_532nm_edge_100%_x100_vis_h50um_15sx2_02_0.txt
#Acq. time (s)=	15
#Accumulations=	2
#Range (cm-¹)=	100...5000
#Windows=	1
#Auto scanning=	Off
#Autofocus=	Off
#Macrospot=	Off
#AutoExposure=	Off
#Spike filter=	Multiple accum.
#Delay time (s)=	2
#Binning=	1
#Readout mode=	Signal
#DeNoise=	Off
#ICS correction=	On
#Dark correction=	Off
#Inst. Process=	Off
#Detector Gain=	Best Dynamic
#Detector ADC=	50 kHz HS
#Detector temperature (°C)=	-60.09
#Instrument=	LabRAM HR Evol
#Detector=	SIN-EM FIVIS
#Objective=	x100_VIS
#Grating=	150 (500nm)
#ND Filter=	100%
#Laser=	532nm_Edge
#Hole=	49.98
#Temperature=	0
#Range=	Visible
#StageXY=	75x50mm Scan+
#StageZ=	Z motor
#X (µm)=	0
#Y (µm)=	0
#Z (µm)=	-183.9
#Full time(s)=	34
#Project=	21_05_14
#Sample=	BU19w
#Site=
#Title=	BU19w-FF2-FI02-V_150 (500nm)_532nm_Edge_100%_x100_VIS_H50um_15sX2
#Remark=
#Date=	14.05.2021 17:17
#Acquired=	14.05.2021 17:17:14
#Base:Fit=	16.12.2021 17:39:50
#Base:Sub=	16.12.2021 18:02:55
102.699	452.321
107.322	407.149
111.942	281.716
116.56	213.882
121.173	220.56
125.787	216.706
130.398	133.387
135.006	188.52
139.613	117.223
144.215	104.061
148.817	126.682
153.417	366.738
158.014	856.802
162.607	715.866
167.2	259.562
171.79	32.8357
176.379	74.4543
180.963	190.927
185.547	645.18
190.128	667.824
194.705	339.525
199.282	94.5352
203.857	47.7281
208.43	24.2865
212.998	52.3333
217.566	3.43213
222.132	-3.81244
226.693	145.309
231.254	377.285
235.813	424.737
240.368	620.69
244.923	998.085
249.475	749.609
254.023	308.196
258.571	191.055
263.117	154.447
267.658	347.313
272.199	994.777
276.738	2158.87
281.273	1999.11
285.807	1043.57
290.34	477.902
294.868	330.027
299.396	385.231
303.919	424.42
308.443	316.325
312.964	246.573
317.481	254.547
321.998	497.448
326.51	814.099
331.023	798.312
335.533	536.395
340.039	467.847
344.544	776.86
349.046	1062.74
353.547	910.245
358.045	513.692
362.542	382.591
367.036	425.919
371.527	408.439
376.017	316.272
380.503	193.259
384.99	260.581
389.471	340.354
393.953	377.46
398.43	307.031
402.908	152.628
407.381	144.919
411.854	310.947
416.323	485.674
420.791	378.936
425.256	123.434
429.72	47.8884
434.18	19.7101
438.64	43.5552
443.095	1.74896
447.551	59.576
452.003	125.435
456.454	140.563
460.901	99.6613
465.348	76.3533
469.791	74.4205
474.231	109.916
478.672	141.476
483.108	209.202
487.544	296.288
491.976	423.343
496.408	447.09
500.836	385.918
505.261	298.301
509.687	174.65
514.108	97.4038
518.529	119.583
522.946	74.074
527.361	58.6204
531.776	57.3152
536.187	93.1021
540.595	47.7758
545.003	63.7865
549.408	86.7887
553.812	141.869
558.212	124.683
562.61	124.292
567.007	101.23
571.401	78.6535
575.792	83.1499
580.184	150.011
584.571	415.227
588.956	621.693
593.341	456.863
597.722	227.93
602.101	222.226
606.48	419.477
610.854	411.088
615.227	317.412
619.597	192.792
623.967	60.6077
628.334	21.6361
632.698	96.6354
637.06	157.368
641.422	168.989
645.779	155.997
650.135	182.613
654.491	209.762
658.842	363.496
663.192	467.807
667.539	539.606
671.884	583.378
676.23	604.242
680.571	522.658
684.91	302.679
689.247	159.254
693.583	101.333
697.916	48.4468
702.247	10.8199
706.576	20.0779
710.902	41.2429
715.229	27.0018
719.551	-4.29773
723.872	17.4658
728.19	50.3256
732.506	-1.97333
736.82	47.4171
741.134	31.1635
745.444	18.5363
749.752	59.9426
754.058	71.1639
758.362	101.267
762.664	139.919
766.964	228.656
771.264	404.111
775.559	674.817
779.853	701.188
784.144	494.453
788.434	279.302
792.722	177.332
797.007	138.638
801.29	113.008
805.572	74.7537
809.851	57.5812
814.13	79.15
818.406	21.4425
822.679	46.5259
826.95	18.9149
831.219	64.0585
835.486	30.9062
839.752	43.9712
844.015	40.2763
848.276	55.6707
852.535	35.6791
856.792	15.7118
861.047	52.9238
865.3	26.989
869.551	12.9736
873.8	18.4515
878.047	41.2575
882.292	6.71411
886.534	2.39539
890.775	26.494
895.014	-2.80426
899.251	24.4554
903.486	30.3584
907.719	20.0464
911.95	47.3116
916.179	40.7808
920.406	48.3264
924.63	29.6039
928.853	40.4641
933.074	97.5839
937.293	102.73
941.51	197.586
945.723	290.811
949.936	318.03
954.147	262.27
958.356	208.959
962.563	151.682
966.768	128.576
970.971	124.908
975.172	102.261
979.371	95.828
983.568	56.6555
987.761	58.5974
991.954	54.9224
996.145	74.4027
1000.33	50.7717
1004.52	47.3994
1008.71	64.4894
1012.89	52.4707
1017.07	54.2732
1021.25	60.3081
1025.43	115.91
1029.6	70.1079
1033.77	168.373
1037.95	209.75
1042.11	291.622
1046.28	584.228
1050.45	978.336
1054.61	1033.49
1058.77	717.252
1062.93	426.176
1067.09	309.92
1071.24	275.611
1075.4	323.156
1079.55	388.371
1083.7	640.668
1087.85	986.579
1091.99	1079.7
1096.14	892.127
1100.28	704.698
1104.42	881.037
1108.55	1069
1112.69	1030.25
1116.82	902.827
1120.96	726.26
1125.09	777.417
1129.21	858.549
1133.34	880.082
1137.46	758.309
1141.59	526.834
1145.71	403.531
1149.83	438.851
1153.94	531.099
1158.06	658.33
1162.17	583.594
1166.28	467.309
1170.39	406.185
1174.5	342.703
1178.6	196.895
1182.7	116.111
1186.8	115.713
1190.9	106.746
1195	126.041
1199.1	61.2111
1203.19	104.326
1207.28	75.2271
1211.37	87.8279
1215.46	149.794
1219.54	217.729
1223.63	283.442
1227.71	170.217
1231.79	156.872
1235.87	132.185
1239.95	197.881
1244.02	223.764
1248.09	124.836
1252.16	161.01
1256.23	82.5431
1260.3	69.1661
1264.36	55.9695
1268.43	201.351
1272.49	806.517
1276.55	382.654
1280.6	70.38
1284.66	67.035
1288.71	32.443
1292.76	78.1073
1296.81	37.1041
1300.86	50.2876
1304.91	18.9092
1308.95	58.1385
1312.99	57.6328
1317.03	73.8306
1321.07	28.4608
1325.11	61.9277
1329.14	38.332
1333.18	39.3655
1337.21	36.121
1341.24	34.7373
1345.26	78.1543
1349.29	36.8068
1353.31	82.1091
1357.33	61.7656
1361.35	51.3594
1365.37	90.7916
1369.39	91.7285
1373.4	709.478
1377.41	1162.51
1381.43	301.066
1385.43	70.0682
1389.44	61.7405
1393.45	70.6954
1397.45	187.266
1401.45	96.724
1405.45	89.0769
1409.45	57.8691
1413.44	5.99402
1417.44	71.491
1421.43	58.9608
1425.42	29.2029
1429.41	45.4382
1433.39	29.4185
1437.38	31.9542
1441.36	22.6815
1445.34	72.3608
1449.32	67.7024
1453.3	64.7418
1457.27	57.7377
1461.24	25.7477
1465.22	-13.3352
1469.19	25.397
1473.15	29.734
1477.12	45.5439
1481.09	74.9393
1485.05	62.1113
1489.01	16.1108
1492.97	35.6621
1496.93	11.3684
1500.88	18.4709
1504.83	17.0841
1508.79	45.0962
1512.74	31.3206
1516.68	28.3622
1520.63	26.4861
1524.57	46.0139
1528.52	35.6099
1532.46	12.7125
1536.4	16.954
1540.33	36.7317
1544.27	30.3275
1548.2	11.3335
1552.14	2.91467
1556.07	38.8302
1559.99	43.5734
1563.92	36.5668
1567.84	31.3788
1571.77	29.9991
1575.69	52.7197
1579.61	57.0157
1583.52	26.5426
1587.44	22.9893
1591.35	49.2458
1595.27	56.2065
1599.18	39.2001
1603.09	48.292
1606.99	45.0256
1610.9	35.074
1614.8	54.0295
1618.7	24.1752
1622.6	31.6879
1626.5	7.86023
1630.39	49.379
1634.29	25.0753
1638.18	39.0963
1642.07	62.1598
1645.96	29.8024
1649.85	19.5477
1653.73	41.8749
1657.62	5.5249
1661.5	44.9069
1665.38	1.40515
1669.26	33.5756
1673.13	46.2218
1677.01	63.3069
1680.88	8.66223
1684.75	48.9395
1688.62	35.2661
1692.49	30.9252
1696.35	30.2161
1700.22	35.9055
1704.08	29.8422
1707.94	50.1154
1711.8	47.4008
1715.66	72.2037
1719.51	36.483
1723.37	84.7296
1727.22	30.0441
1731.07	57.1721
1734.92	57.02
1738.76	90.265
1742.61	51.5593
1746.45	56.3069
1750.29	56.1926
1754.13	75.2213
1757.97	25.4052
1761.81	24.4539
1765.64	31.2983
1769.47	59.4596
1773.31	29.3331
1777.14	65.4969
1780.96	83.5005
1784.79	50.3135
1788.61	39.5874
1792.43	76.6863
1796.25	54.7074
1800.07	72.5597
1803.89	46.589
1807.71	65.7515
1811.52	52.6333
1815.33	53.1823
1819.14	29.6233
1822.95	38.8035
1826.76	49.5266
1830.56	-10.8453
1834.37	20.8673
1838.17	19.3712
1841.97	44.8306
1845.77	59.8448
1849.56	14.5658
1853.36	67.0757
1857.15	29.3711
1860.94	19.46
1864.73	33.7731
1868.52	70.428
1872.31	72.9182
1876.09	60.8085
1879.87	48.1901
1883.66	71.8441
1887.43	20.0177
1891.21	27.0153
1894.99	63.3439
1898.76	20.0001
1902.53	34.1641
1906.31	36.5378
1910.08	45.7357
1913.84	37.7234
1917.61	43.1915
1921.37	50.1255
1925.14	7.16687
1928.9	65.5238
1932.66	29.1694
1936.41	34.5999
1940.17	69.924
1943.92	19.5121
1947.68	39.8853
1951.43	58.8011
1955.18	32.8986
1958.92	22.1948
1962.67	71.4634
1966.41	49.1814
1970.16	68.3644
1973.9	60.038
1977.64	29.8805
1981.37	32.2949
1985.11	36.2892
1988.84	37.3512
1992.57	60.3522
1996.31	90.4392
2000.03	46.0642
2003.76	45.5328
2007.49	50.892
2011.21	45.0994
2014.93	37.8756
2018.65	41.7854
2022.37	50.9299
2026.09	28.8344
2029.81	18.3683
2033.52	73.4253
2037.23	42.005
2040.94	35.3905
2044.65	44.1119
2048.36	28.4429
2052.07	23.9607
2055.77	18.8236
2059.47	36.9408
2063.17	26.2262
2066.87	23.9425
2070.57	3.25818
2074.27	21.3514
2077.96	45.2473
2081.65	41.3583
2085.34	4.01038
2089.03	13.8422
2092.72	39.3341
2096.41	3.79834
2100.09	36.2858
2103.77	35.0463
2107.46	64.2158
2111.14	52.3223
2114.81	42.2468
2118.49	10.3358
2122.16	10.3496
2125.84	52.8846
2129.51	36.6914
2133.18	38.0673
2136.85	85.3892
2140.51	43.7507
2144.18	50.8683
2147.84	4.62183
2151.5	24.5874
2155.16	41.8214
2158.82	93.8419
2162.48	45.5616
2166.13	27.7467
2169.79	38.6771
2173.44	30.2181
2177.09	22.7977
2180.74	46.4681
2184.38	31.0303
2188.03	12.7223
2191.67	54.1184
2195.32	68.8531
2198.96	52.7775
2202.6	23.2301
2206.23	42.3269
2209.87	48.9302
2213.5	39.2201
2217.14	55.2207
2220.77	68.5908
2224.4	36.9108
2228.03	64.9666
2231.65	16.6366
2235.28	61.6382
2238.9	87.2413
2242.52	67.4413
2246.14	50.3541
2249.76	79.0259
2253.38	25.9047
2256.99	78.2435
2260.6	25.7877
2264.21	49.9937
2267.82	111.319
2271.44	53.3578
2275.04	31.2825
2278.65	53.8009
2282.25	31.1571
2285.85	57.985
2289.45	45.7874
2293.05	55.2836
2296.65	57.3398
2300.25	18.5455
2303.84	36.1936
2307.43	56.4218
2311.02	40.4127
2314.62	80.9951
2318.2	152.492
2321.79	113.325
2325.38	90.4708
2328.96	75.3005
2332.54	44.7275
2336.12	61.1677
2339.7	50.9956
2343.28	69.7874
2346.85	47.0847
2350.43	74.9043
2354	-16.0576
2357.57	82.3911
2361.14	37.1594
2364.71	56.212
2368.27	43.9852
2371.84	79.1754
2375.4	56.8212
2378.96	59.655
2382.52	44.2742
2386.08	52.1423
2389.64	72.2798
2393.19	57.9736
2396.75	45.2053
2400.3	92.7944
2403.85	14.574
2407.4	31.9987
2410.95	33.6603
2414.49	22.7839
2418.04	6.76038
2421.58	32.4557
2425.12	17.1943
2428.66	41.0935
2432.2	77.5005
2435.74	50.3207
2439.27	32.4565
2442.81	50.9944
2446.34	61.4176
2449.87	33.8624
2453.4	49.8727
2456.93	41.7976
2460.45	56.4742
2463.98	74.3019
2467.5	102.336
2471.02	30.9084
2474.54	37.4058
2478.06	20.9861
2481.58	34.4202
2485.09	51.5524
2488.61	39.4963
2492.12	92.4431
2495.63	70.7368
2499.14	39.0966
2502.65	39.5779
2506.15	72.4711
2509.66	92.0618
2513.16	61.7838
2516.66	61.6909
2520.16	48.7146
2523.66	78.3655
2527.16	62.6454
2530.66	76.7467
2534.15	85.8368
2537.64	26.0963
2541.13	76.931
2544.62	33.6801
2548.11	31.2097
2551.6	54.9113
2555.08	47.3096
2558.57	50.8361
2562.05	48.5887
2565.53	57.2113
2569.01	34.661
2572.49	51.6942
2575.96	35.4202
2579.44	43.7223
2582.91	52.1648
2586.38	76.5427
2589.85	42.1534
2593.32	23.1549
2596.79	51.3499
2600.25	78.8868
2603.72	94.2268
2607.18	95.7921
2610.64	28.2019
2614.1	74.6975
2617.56	78.3063
2621.02	69.064
2624.47	99.6527
2627.92	46.3715
2631.38	84.9185
2634.83	61.4427
2638.28	97.0859
2641.72	89.1479
2645.17	108.867
2648.61	47.0977
2652.06	85.0327
2655.5	42.575
2658.94	48.4413
2662.38	77.687
2665.82	66.2451
2669.25	57.4651
2672.69	41.4955
2676.12	73.6281
2679.55	48.979
2682.98	32.3436
2686.41	69.0988
2689.84	57.5746
2693.26	75.3461
2696.69	127.917
2700.11	61.6708
2703.53	90.8264
2706.95	120.53
2710.37	35.4159
2713.79	85.5698
2717.2	60.7323
2720.62	55.7428
2724.03	55.5635
2727.44	77.098
2730.85	45.2401
2734.26	39.5387
2737.66	37.6093
2741.07	72.9147
2744.47	91.9332
2747.87	41.4495
2751.28	74.5936
2754.67	59.3875
2758.07	66.0979
2761.47	89.2417
2764.86	72.5715
2768.26	94.1514
2771.65	80.7723
2775.04	94.413
2778.43	77.6205
2781.82	110.567
2785.2	84.1388
2788.59	65.2517
2791.97	61.2631
2795.35	33.0656
2798.73	61.7391
2802.11	119.459
2805.49	62.7999
2808.87	25.7904
2812.24	84.1754
2815.62	66.6071
2818.99	96.9497
2822.36	66.9448
2825.73	90.257
2829.1	83.0001
2832.46	75.1926
2835.83	90.9924
2839.19	80.1466
2842.55	65.0349
2845.91	79.3829
2849.27	88.1072
2852.63	68.4156
2855.99	38.627
2859.34	63.3738
2862.69	64.8306
2866.05	54.2057
2869.4	84.7383
2872.75	61.7002
2876.09	96.9076
2879.44	27.614
2882.78	90.054
2886.13	30.7321
2889.47	52.6847
2892.81	108.162
2896.15	75.5098
2899.49	68.0897
2902.82	64.1805
2906.16	56.3643
2909.49	84.3097
2912.82	93.3357
2916.16	112.424
2919.49	73.6792
2922.81	71.7947
2926.14	84.6755
2929.46	133.358
2932.79	131.52
2936.11	127.808
2939.43	131.652
2942.75	95.0331
2946.07	99.0665
2949.39	102.105
2952.7	91.9203
2956.02	105.537
2959.33	177.642
2962.64	125.806
2965.95	93.2087
2969.26	97.9559
2972.57	86.4308
2975.87	82.208
2979.17	98.2385
2982.48	87.1631
2985.78	76.2346
2989.08	96.3542
2992.38	50.8137
2995.68	73.0479
2998.97	62.4307
3002.27	76.171
3005.56	64.702
3008.85	74.0378
3012.14	69.3547
3015.43	33.5145
3018.72	61.741
3022	66.4006
3025.29	57.8992
3028.57	79.6176
3031.85	59.6975
3035.14	50.0728
3038.41	93.4424
3041.69	87.6533
3044.97	-4.22742
3048.24	60.0538
3051.52	90.3866
3054.79	64.7621
3058.06	59.7747
3061.33	51.5051
3064.6	33.9149
3067.87	46.4504
3071.13	86.9882
3074.4	35.533
3077.66	35.3077
3080.92	87.2875
3084.18	4.93188
3087.44	15.8585
3090.7	31.0035
3093.95	131.857
3097.21	45.6754
3100.46	89.761
3103.71	60.246
3106.96	56.4994
3110.21	47.4679
3113.46	41.2476
3116.71	83.6798
3119.95	69.9559
3123.2	30.4907
3126.44	41.4626
3129.68	85.8091
3132.92	80.5867
3136.16	26.6635
3139.4	65.1641
3142.63	34.0688
3145.87	69.8104
3149.1	85.6095
3152.33	60.3455
3155.56	73.2648
3158.79	44.1733
3162.02	53.2511
3165.25	69.8524
3168.47	81.5441
3171.69	79.7998
3174.92	67.4261
3178.14	74.0753
3181.36	54.0659
3184.58	75.8754
3187.79	67.0773
3191.01	83.0546
3194.22	108.536
3197.43	90.1475
3200.65	31.8361
3203.86	128.776
3207.07	81.1001
3210.27	58.2944
3213.48	66.0765
3216.69	80.5498
3219.89	91.2534
3223.09	65.9767
3226.29	70.2499
3229.49	68.9652
3232.69	103.725
3235.89	111.195
3239.08	72.1904
3242.28	72.3156
3245.47	121.047
3248.66	105.144
3251.85	59.7405
3255.04	101.154
3258.23	101.35
3261.42	85.0626
3264.6	115.322
3267.79	89.9812
3270.97	108.445
3274.15	61.957
3277.33	98.2931
3280.51	110.361
3283.68	89.0134
3286.86	56.0935
3290.04	82.4154
3293.21	82.0193
3296.38	72.9834
3299.55	50.1189
3302.72	58.3837
3305.89	80.7028
3309.06	120.79
3312.22	97.0331
3315.39	68.5248
3318.55	142.393
3321.71	92.0424
3324.87	118.458
3328.03	132.561
3331.19	112.729
3334.34	130.844
3337.5	92.4744
3340.65	88.1091
3343.81	96.3339
3346.96	146.54
3350.11	132.671
3353.25	111.442
3356.4	101.611
3359.55	112.733
3362.69	105.065
3365.84	155.963
3368.98	111.648
3372.12	114.698
3375.26	132.005
3378.4	163.625
3381.53	117.666
3384.67	154.07
3387.8	143.23
3390.94	169.395
3394.07	201.502
3397.2	202.306
3400.33	200.579
3403.46	240.808
3406.58	310.711
3409.71	425.563
3412.83	685.891
3415.96	1464.96
3419.08	3319.05
3422.2	4517.87
3425.32	2986.1
3428.44	1334.53
3431.55	678.074
3434.67	386.706
3437.78	302.745
3440.89	228.464
3444	248.25
3447.12	227.939
3450.22	194.965
3453.33	224.868
3456.44	188.792
3459.54	234.493
3462.65	183.132
3465.75	195.318
3468.85	242.96
3471.95	276.825
3475.05	290.928
3478.15	359.027
3481.24	397.762
3484.34	487.563
3487.43	643.509
3490.53	858.558
3493.62	1155.68
3496.71	1424.03
3499.79	1950.86
3502.88	2377.6
3505.97	2349.2
3509.05	1953.28
3512.14	1416.47
3515.22	1037.01
3518.3	770.169
3521.38	541.052
3524.46	477.691
3527.54	381.901
3530.61	309.368
3533.69	246.198
3536.76	226.133
3539.83	169.542
3542.9	141.404
3545.97	194.11
3549.04	104.847
3552.11	104.999
3555.18	125.277
3558.24	122.091
3561.3	118.518
3564.37	124.278
3567.43	115.901
3570.49	111.975
3573.55	128.722
3576.61	102.72
3579.66	54.7659
3582.72	121.424
3585.77	76.1199
3588.82	106.528
3591.87	82.8041
3594.92	69.3953
3597.97	146.893
3601.02	127.627
3604.07	70.3777
3607.11	123.806
3610.16	52.3324
3613.2	52.6644
3616.24	84.1798
3619.28	94.9724
3622.32	79.402
3625.36	56.4008
3628.39	62.5946
3631.43	67.7281
3634.46	81.584
3637.5	46.7711
3640.53	52.5941
3643.56	83.2687
3646.59	61.9486
3649.62	58.7053
3652.64	61.2896
3655.67	94.1517
3658.69	38.5569
3661.72	29.7539
3664.74	88.1345
3667.76	62.7214
3670.78	46.8723
3673.79	57.5128
3676.81	55.9875
3679.83	32.6794
3682.84	84.9668
3685.86	3.95996
3688.87	35.5457
3691.88	21.7488
3694.89	45.5878
3697.9	59.1954
3700.91	33.9991
3703.91	51.5013
3706.92	48.9269
3709.92	42.4171
3712.92	50.9221
3715.92	26.1768
3718.92	43.1804
3721.92	58.1451
3724.92	29.1715
3727.92	78.1694
3730.91	56.5605
3733.91	59.5417
3736.9	71.9025
3739.89	68.8518
3742.88	76.1265
3745.87	60.4275
3748.86	74.0703
3751.85	99.9865
3754.83	47.1351
3757.82	32.2726
3760.8	69.4392
3763.78	58.2399
3766.76	29.1666
3769.74	42.8276
3772.72	66.995
3775.7	67.6071
3778.67	83.4382
3781.65	53.962
3784.62	53.8423
3787.6	95.3306
3790.57	37.9183
3793.54	55.2285
3796.51	70.7378
3799.47	63.7773
3802.44	58.813
3805.41	53.8914
3808.37	12.1954
3811.33	63.1649
3814.3	25.304
3817.26	53.7037
3820.22	65.1224
3823.18	9.39722
3826.13	37.0546
3829.09	59.0304
3832.04	42.2361
3835	59.7039
3837.95	-0.710815
3840.9	67.1588
3843.85	22.8406
3846.8	41.366
3849.75	40.9387
3852.69	37.6903
3855.64	44.9563
3858.58	37.9266
3861.53	46.1119
3864.47	38.0277
3867.41	71.0265
3870.35	32.0983
3873.29	27.611
3876.22	44.0959
3879.16	34.5114
3882.1	69.9056
3885.03	67.7023
3887.96	61.5792
3890.89	56.361
3893.82	71.1787
3896.75	73.2986
3899.68	49.4193
3902.61	40.7197
3905.53	71.5753
3908.46	35.0751
3911.38	45.5439
3914.3	24.1359
3917.23	27.9705
3920.15	54.6614
3923.06	40.84
3925.98	47.9934
3928.9	53.0753
3931.81	50.7548
3934.73	27.6639
3937.64	29.8126
3940.55	61.5603
3943.46	56.9443
3946.37	62.0383
3949.28	23.2124
3952.19	40.9327
3955.09	6.10095
3958	67.1439
3960.9	34.3605
3963.8	68.7515
3966.71	-0.352661
3969.61	40.9061
3972.51	19.7819
3975.4	41.792
3978.3	39.687
3981.2	60.623
3984.09	49.7656
3986.99	32.1674
3989.88	44.142
3992.77	52.5103
3995.66	73.4049
3998.55	34.691
4001.43	41.2321
4004.32	59.411
4007.21	11.1393
4010.09	39.9429
4012.98	58.1685
4015.86	58.0791
4018.74	48.329
4021.62	72.3696
4024.5	61.6831
4027.37	32.6272
4030.25	71.2754
4033.13	45.146
4036	74.2289
4038.87	45.2573
4041.75	41.222
4044.62	92.4006
4047.49	30.2833
4050.35	74.8719
4053.22	95.3561
4056.09	16.8641
4058.95	56.728
4061.82	53.8564
4064.68	68.4885
4067.54	78.2532
4070.4	51.9987
4073.26	48.1011
4076.12	43.2008
4078.98	64.6089
4081.83	46.0619
4084.69	45.0269
4087.54	44.9255
4090.4	66.3679
4093.25	55.5913
4096.1	64.3156
4098.95	42.7919
4101.8	63.2406
4104.64	48.38
4107.49	71.5964
4110.33	47.7933
4113.18	-8.48584
4116.02	53.5067
4118.86	59.6293
4121.7	24.7811
4124.54	59.5146
4127.38	49.4355
4130.22	82.7537
4133.05	63.4861
4135.89	27.7865
4138.72	52.201
4141.56	55.601
4144.39	72.0703
4147.22	55.3689
4150.05	44.4097
4152.88	24.191
4155.7	71.9781
4158.53	41.4803
4161.36	53.481
4164.18	46.9019
4167	51.1067
4169.82	47.5706
4172.65	39.199
4175.46	53.3347
4178.28	49.9304
4181.1	44.6573
4183.92	63.8936
4186.73	46.0168
4189.55	68.3859
4192.36	68.4404
4195.17	58.8606
4197.98	50.3107
4200.79	51.5475
4203.6	79.2963
4206.41	58.938
4209.21	75.8909
4212.02	75.1301
4214.83	45.3007
4217.63	54.1837
4220.43	63.8728
4223.23	47.7823
4226.03	36.6483
4228.83	94.8872
4231.63	65.2155
4234.42	71.2965
4237.22	18.8585
4240.01	56.7717
4242.81	73.9425
4245.6	65.2341
4248.39	14.4647
4251.18	74.4111
4253.97	23.3774
4256.76	62.2913
4259.55	-0.933838
4262.33	55.1964
4265.12	46.2061
4267.9	42.2521
4270.68	20.1122
4273.47	18.9385
4276.25	66.9999
4279.03	42.2832
4281.8	50.7837
4284.58	59.1404
4287.36	26.8721
4290.13	37.0164
4292.91	56.3733
4295.68	57.6582
4298.45	75.1333
4301.22	27.613
4303.99	63.2952
4306.76	29.9747
4309.53	10.9468
4312.3	37.5955
4315.06	41.7109
4317.83	70.17
4320.59	50.7015
4323.35	57.6195
4326.11	55.3794
4328.87	65.3087
4331.63	57.8964
4334.39	39.2501
4337.15	58.3761
4339.9	69.4879
4342.66	68.4291
4345.41	71.5853
4348.17	14.5751
4350.92	77.1787
4353.67	29.5691
4356.42	72.8186
4359.17	53.6744
4361.91	34.5389
4364.66	23.5759
4367.41	23.8888
4370.15	56.9653
4372.89	41.7056
4375.63	62.3134
4378.38	24.3229
4381.12	44.9138
4383.86	40.0217
4386.59	45.813
4389.33	75.6288
4392.07	52.4927
4394.8	43.6389
4397.53	61.1472
4400.27	71.4164
4403	67.1565
4405.73	28.6827
4408.46	35.8011
4411.19	47.9634
4413.92	19.4178
4416.64	36.3872
4419.37	23.0454
4422.09	38.0464
4424.82	70.8409
4427.54	85.9141
4430.26	9.97632
4432.98	50.0861
4435.7	34.6664
4438.42	63.1555
4441.13	38.1599
4443.85	27.8021
4446.57	52.0371
4449.28	54.182
4451.99	7.9425
4454.71	50.9326
4457.42	50.767
4460.13	40.1641
4462.83	38.0192
4465.54	63.2518
4468.25	38.0371
4470.95	-3.97681
4473.66	77.3751
4476.36	50.2957
4479.07	60.1936
4481.77	45.8313
4484.47	56.7526
4487.17	31.6959
4489.87	55.1011
4492.56	24.1035
4495.26	46.333
4497.96	70.7108
4500.65	53.5651
4503.34	27.0051
4506.04	45.0157
4508.73	19.5404
4511.42	56.6809
4514.11	39.7439
4516.8	51.4667
4519.48	50.6075
4522.17	59.3406
4524.85	52.0599
4527.54	41.6199
4530.22	36.5035
4532.9	53.8317
4535.58	42.3579
4538.27	14.9731
4540.94	58.0417
4543.62	57.3717
4546.3	6.37354
4548.98	28.189
4551.65	28.8394
4554.33	32.7563
4557	44.5927
4559.67	21.0931
4562.34	47.3562
4565.01	34.3082
4567.68	33.8629
4570.35	29.9655
4573.02	16.3636
4575.68	28.3573
4578.35	51.5187
4581.01	22.1672
4583.67	32.1551
4586.34	29.0387
4589	27.962
4591.66	28.9955
4594.31	29.2772
4596.97	18.3334
4599.63	61.2133
4602.29	27.6406
4604.94	31.2514
4607.59	18.457
4610.25	7.78931
4612.9	8.05237
4615.55	14.9377
4618.2	51.6519
4620.85	48.7426
4623.5	58.976
4626.14	32.7056
4628.79	31.8254
4631.43	21.9272
4634.08	39.5453
4636.72	31.7475
4639.36	32.7073
4642	36.0977
4644.64	26.4632
4647.28	49.2403
4649.92	33.4406
4652.56	30.3533
4655.19	30.6093
4657.83	-8.2829
4660.46	14.3946
4663.1	28.1966
4665.73	13.6099
4668.36	19.2943
4670.99	43.9994
4673.62	44.0619
4676.24	4.83282
4678.87	21.6476
4681.5	38.4775
4684.12	42.9698
4686.75	74.4506
4689.37	15.9601
4691.99	55.3157
4694.61	47.3182
4697.23	47.2292
4699.85	5.36786
4702.47	19.8218
4705.09	54.6199
4707.7	24.9247
4710.32	12.1556
4712.93	37.8527
4715.55	10.2412
4718.16	0.766968
4720.77	52.3318
4723.38	12.2473
4725.99	-1.69806
4728.6	26.3394
4731.21	27.1564
4733.81	37.0555
4736.42	0.25293
4739.02	32.8013
4741.63	49.3102
4744.23	32.8513
4746.83	22.9755
4749.43	41.5884
4752.03	39.7189
4754.63	70.8008
4757.23	13.1803
4759.82	-6.78558
4762.42	50.6884
4765.01	1.25946
4767.61	39.8602
4770.2	39.3986
4772.79	28.6775
4775.38	-9.43561
4777.97	35.7804
4780.56	14.7539
4783.15	25.7388
4785.74	14.9955
4788.32	27.1467
4790.91	17.6193
4793.49	29.8376
4796.07	30.719
4798.66	31.6625
4801.24	-0.628052
4803.82	34.9264
4806.4	28.1242
4808.98	30.4645
4811.55	23.6513
4814.13	-0.459839
4816.71	30.953
4819.28	20.7711
4821.85	34.9103
4824.43	34.0118
4827	40.0115
4829.57	26.4144
4832.14	29.0646
4834.71	14.3527
4837.28	14.8699
4839.84	35.3231
4842.41	26.3516
4844.97	16.0787
4847.54	39.7311
4850.1	14.647
4852.66	21.9245
4855.22	61.1672
4857.78	9.76178
4860.34	25.3137
4862.9	33.4396
4865.46	27.2222
4868.01	3.68335
4870.57	24.8841
4873.12	-1.46155
4875.68	13.6921
4878.23	41.8857
4880.78	48.6652
4883.33	7.89984
4885.88	40.8306
4888.43	10.7759
4890.98	5.64594
4893.53	27.8999
4896.07	26.2988
4898.62	3.23944
4901.16	9.94202
4903.7	16.7064
4906.25	23.3496
4908.79	31.1238
4911.33	20.8593
4913.87	8.14728
4916.41	0.244873
4918.94	21.0695
4921.48	13.2311
4924.02	49.6602
4926.55	26.3086
4929.08	26.9579
4931.62	20.6526
4934.15	34.6902
4936.68	18.7672
4939.21	48.111
4941.74	24.8225
4944.27	36.5175
4946.79	41.0655
4949.32	1.29657
4951.85	16.6512
4954.37	15.2769
4956.9	24.8403
4959.42	30.8944
4961.94	34.7438
4964.46	1.47913
4966.98	30.7537
4969.5	44.2752
4972.02	37.2906
4974.53	61.7171
4977.05	41.4595
4979.57	-5.43188
4982.08	32.4697
4984.59	28.025
4987.1	12.6781
4989.62	13.1088
4992.13	45.1672
4994.64	26.2335
4997.15	46.3881
4999.65	33.6608