File: Data/3-Raman/processed/bu19w-d-ore2-fi09-v_150 (500nm)_532nm_edge_100%_x100_vis_lwd_h50um_15sx2_01_0.txt
#Acq. time (s)=	15
#Accumulations=	2
#Range (cm-¹)=	50...5000
#Windows=	1
#Auto scanning=	Off
#Autofocus=	Off
#Macrospot=	Off
#AutoExposure=	Off
#Spike filter=	Multiple accum.
#Delay time (s)=	2
#Binning=	1
#Readout mode=	Signal
#DeNoise=	Off
#ICS correction=	On
#Dark correction=	Off
#Inst. Process=	Off
#Detector Gain=	Best Dynamic
#Detector ADC=	50 kHz HS
#Detector temperature (°C)=	-60.09
#Instrument=	LabRAM HR Evol
#Detector=	SIN-EM FIVIS
#Objective=	x100_VIS_LWD
#Grating=	150 (500nm)
#ND Filter=	100%
#Laser=	532nm_Edge
#Hole=	49.98
#Temperature=	0
#Range=	Visible
#StageXY=	75x50mm Scan+
#StageZ=	Z motor
#X (µm)=	0
#Y (µm)=	0
#Z (µm)=	-6.6
#Full time(s)=	34
#Project=	21_05_28
#Sample=	BU19w
#Site=
#Title=	BU19w-FF-ore2-FI09-V_150 (500nm)_532nm_Edge_100%_x100_VIS_LWD_H50um_15sX2
#Remark=
#Date=	28.05.2021 15:13
#Acquired=	28.05.2021 15:13:44
#Base:Fit=	16.12.2021 17:39:50
#Base:Sub=	16.12.2021 18:00:30
51.5961	50263.5
56.2453	50796.8
60.8921	45421.9
65.5367	37741.5
70.1768	29833.2
74.8167	23815.5
79.4543	19385.2
84.0897	15853.9
88.7227	13144.5
93.3513	11017
97.9798	8915.11
102.606	7413.48
107.23	6210.57
111.851	5374.52
116.469	4788.97
121.086	4675.23
125.7	6578.68
130.313	7886.35
134.921	5017.99
139.529	3009.88
144.134	2556.56
148.738	2259.99
153.337	2062.25
157.936	1674.06
162.532	1578.27
167.126	1521.8
171.716	1603.74
176.306	1733.53
180.894	1957.61
185.477	2467.89
190.06	3277.75
194.64	4712.59
199.219	6585.24
203.793	8536.92
208.367	9265.7
212.939	8116.89
217.506	6149.93
222.073	4393.34
226.638	3103.47
231.199	2271.57
235.759	1694.06
240.318	1279.09
244.872	1081.31
249.425	900.6
253.977	807.593
258.524	882.503
263.071	1519.94
267.616	1783.28
272.156	896.975
276.697	368.591
281.233	255.486
285.769	171.894
290.303	148.236
294.832	60.55
299.361	74.713
303.886	82.708
308.411	46.4135
312.934	4.73914
317.452	-1.72803
321.97	13.165
326.484	4.30078
330.998	-3.35852
335.507	10.0972
340.017	10.1095
344.524	30.5656
349.027	127.664
353.53	833.774
358.028	1560.31
362.527	875.374
367.021	315.48
371.515	149.526
376.004	169.502
380.494	110.588
384.979	145.112
389.465	125.943
393.946	270.753
398.427	418.956
402.903	621.289
407.38	511.605
411.852	223.793
416.324	198.897
420.792	233.791
425.26	259.971
429.723	322.1
434.187	354.789
438.646	508.132
443.105	757.89
447.56	1330.45
452.015	2530.31
456.466	5167.45
460.914	14368.5
465.362	28561.2
469.807	24334.7
474.251	11151.3
478.69	5066.99
483.13	3002.97
487.566	2079.14
491.999	1561.84
496.432	1183.43
500.861	907.22
505.29	818.274
509.715	877.581
514.138	924.085
518.56	775.201
522.979	629.146
527.395	483.35
531.811	432.497
536.223	355.165
540.635	322.901
545.042	322.959
549.448	319.558
553.853	264.903
558.255	237.471
562.654	208.945
567.053	196.451
571.448	193.771
575.841	183.367
580.232	201.806
584.622	202.011
589.009	218.826
593.393	223.453
597.777	196.605
602.157	211.961
606.535	206.417
610.913	180.447
615.287	147.538
619.659	155.156
624.029	165.598
628.398	167.094
632.763	151.492
637.127	136.691
641.488	130.255
645.849	139.525
650.206	101.591
654.561	102.072
658.914	131.534
663.267	135.247
667.615	97.8176
671.962	119.192
676.307	86.0443
680.649	94.6212
684.991	133.185
689.33	139.03
693.666	228.827
698	316.742
702.332	248.579
706.662	164.823
710.992	119.04
715.318	113.205
719.641	113.325
723.963	113.061
728.283	69.222
732.6	128.131
736.918	109.866
741.231	104.625
745.542	84.8431
749.852	63.8002
754.159	95.8015
758.464	84.9965
762.767	85.4722
767.068	66.4597
771.369	93.5026
775.666	88.0211
779.961	102.234
784.254	142.131
788.545	174.887
792.834	296.097
797.12	425.112
801.405	503.731
805.688	689.865
809.968	984.219
814.247	720.222
818.524	378.282
822.798	221.006
827.071	190.487
831.341	184.261
835.612	140.57
839.878	141.976
844.142	174.17
848.405	122.161
852.665	120.367
856.923	92.1229
861.18	129.987
865.434	125.796
869.686	121.305
873.936	125.407
878.185	140.223
882.431	118.648
886.675	85.8406
890.915	125.639
895.155	131.171
899.393	98.2219
903.63	105.255
907.864	112.094
912.096	44.1901
916.326	49.4481
920.554	108.492
924.78	61.3667
929.004	73.0869
933.227	24.6327
937.447	83.4603
941.665	67.975
945.881	63.1104
950.095	55.0294
954.305	69.592
958.516	49.0897
962.724	45.7656
966.93	23.4294
971.134	25.6542
975.337	25.9322
979.537	0.893982
983.735	36.416
987.93	-0.0942993
992.124	1.60309
996.316	2.86072
1000.51	8.89801
1004.7	0.279846
1008.88	50.2122
1013.06	51.3693
1017.25	30.999
1021.43	0.974121
1025.61	24.0736
1029.78	22.3276
1033.96	32.0435
1038.13	25.9058
1042.3	50.1584
1046.47	42.3622
1050.63	70.4096
1054.8	58.9038
1058.96	65.1525
1063.12	154.407
1067.28	192.384
1071.44	224.75
1075.59	221.276
1079.74	459.437
1083.89	712.198
1088.04	524.725
1092.19	211.938
1096.33	119.407
1100.48	72.8699
1104.62	49.1629
1108.76	31.0477
1112.89	13.4146
1117.03	35.7703
1121.16	35.9537
1125.29	21.7505
1129.42	32.3792
1133.55	19.7647
1137.68	7.88513
1141.8	32.8991
1145.92	60.2374
1150.04	109.024
1154.16	161.469
1158.27	290.961
1162.39	349.046
1166.5	233.36
1170.61	122.6
1174.72	39.4495
1178.82	63.3856
1182.93	34.7639
1187.03	5.91125
1191.13	25.8759
1195.23	23.9823
1199.33	38.1305
1203.42	25.4796
1207.51	-5.461
1211.6	17.4745
1215.69	24.168
1219.78	28.8998
1223.86	46.8013
1227.95	63.825
1232.03	111.163
1236.11	103.163
1240.18	103.744
1244.26	111.1
1248.33	158.775
1252.41	167.082
1256.48	200.611
1260.54	353.308
1264.61	559.425
1268.67	376.714
1272.74	338.166
1276.8	441.028
1280.86	2106.21
1284.91	5075.36
1288.97	1448.33
1293.02	375.567
1297.07	291.678
1301.12	239.852
1305.17	198.867
1309.21	212.23
1313.25	175.064
1317.3	181.855
1321.34	160.211
1325.37	123.101
1329.41	127.139
1333.44	121.011
1337.48	151.637
1341.5	187.979
1345.53	165.148
1349.56	154.336
1353.59	165.477
1357.61	184.574
1361.63	228.294
1365.65	268.108
1369.66	387.046
1373.68	373.703
1377.69	442.431
1381.7	805.787
1385.72	5068.27
1389.72	7691.84
1393.73	1541.24
1397.73	471.107
1401.74	406.752
1405.74	474.348
1409.73	795.472
1413.73	456.286
1417.73	221.369
1421.72	167.851
1425.71	166.483
1429.7	118.145
1433.69	113.36
1437.67	105.59
1441.66	75.1324
1445.64	43.5384
1449.62	82.9549
1453.6	34.3785
1457.57	71.5226
1461.55	25.6844
1465.52	63.2656
1469.49	46.6384
1473.46	18.4019
1477.43	16.5778
1481.39	40.1077
1485.36	-0.0927734
1489.32	64.3001
1493.28	2.70831
1497.24	23.1661
1501.19	14.4729
1505.15	29.3098
1509.1	33.7075
1513.05	21.66
1517	1.91644
1520.95	18.2012
1524.9	42.2972
1528.84	17.9763
1532.78	-1.35944
1536.72	39.4296
1540.66	27.9084
1544.6	27.0538
1548.53	37.8333
1552.46	22.4543
1556.4	24.3953
1560.32	29.0899
1564.25	43.3468
1568.18	46.8491
1572.1	38.675
1576.02	71.0554
1579.94	27.114
1583.86	22.7469
1587.78	31.7977
1591.69	46.5845
1595.61	69.0202
1599.52	77.0068
1603.43	73.546
1607.34	66.4152
1611.24	65.0746
1615.15	72.4373
1619.05	108.68
1622.95	59.6068
1626.85	108.374
1630.74	81.6552
1634.64	75.3841
1638.53	86.2894
1642.42	92.6962
1646.31	85.9211
1650.2	67.74
1654.09	50.5472
1657.97	101.414
1661.86	48.5453
1665.74	84.8068
1669.62	66.1802
1673.49	31.8381
1677.37	67.6137
1681.24	73.9749
1685.12	49.3427
1688.99	40.0089
1692.86	41.0168
1696.72	52.3951
1700.59	41.598
1704.45	29.6621
1708.31	24.2113
1712.17	12.8697
1716.03	22.4323
1719.89	36.7251
1723.74	19.8394
1727.6	50.9658
1731.45	9.42792
1735.3	14.1016
1739.14	28.9228
1742.99	33.28
1746.83	34.8802
1750.68	18.5171
1754.52	10.9254
1758.36	32.6793
1762.19	17.1708
1766.03	44.5397
1769.86	-1.04419
1773.69	2.13922
1777.53	11.8777
1781.35	65.797
1785.18	-2.23663
1789	40.9001
1792.83	49.579
1796.65	39.5486
1800.47	34.1376
1804.29	22.3958
1808.1	7.72534
1811.92	14.5931
1815.73	18.4597
1819.54	26.5969
1823.35	35.4116
1827.16	0.636658
1830.97	28.7819
1834.77	10.454
1838.58	18.3445
1842.38	20.4174
1846.18	40.082
1849.97	38.2573
1853.77	33.1327
1857.56	32.4308
1861.36	11.8104
1865.15	20.0104
1868.93	53.3481
1872.72	8.83185
1876.51	-2.92987
1880.29	5.73145
1884.07	27.7075
1887.86	29.4144
1891.63	23.126
1895.41	66.5594
1899.19	45.5781
1902.96	4.81781
1906.73	30.5225
1910.5	34.2512
1914.27	36.5377
1918.04	49.9812
1921.8	33.6466
1925.57	32.1798
1929.33	31.826
1933.09	17.6224
1936.85	2.40405
1940.6	30.0394
1944.36	73.6606
1948.11	29.3444
1951.87	35.6642
1955.61	38.7483
1959.36	33.7644
1963.11	11.5212
1966.86	1.43494
1970.6	6.98303
1974.34	34.6476
1978.08	29.2538
1981.82	11.527
1985.56	17.0215
1989.29	3.72083
1993.02	11.7126
1996.75	20.3965
2000.49	19.5645
2004.21	24.3447
2007.94	38.2195
2011.67	42.5547
2015.39	36.792
2019.11	49.0159
2022.83	47.1136
2026.55	22.0656
2030.27	39.2043
2033.98	41.2976
2037.69	43.7673
2041.41	23.2527
2045.12	59.4175
2048.82	53.4943
2052.53	24.8934
2056.24	39.3993
2059.94	59.0735
2063.64	57.4463
2067.34	17.4569
2071.04	41.9152
2074.74	51.7098
2078.43	45.9053
2082.13	70.7367
2085.82	43.5361
2089.51	35.4036
2093.2	29.5652
2096.88	24.2434
2100.57	49.4122
2104.25	44.4618
2107.94	31.8788
2111.62	47.0294
2115.3	70.5087
2118.97	16.6975
2122.65	72.0955
2126.32	45.5203
2129.99	51.2611
2133.66	68.9156
2137.33	74.4354
2141	49.2922
2144.67	44.327
2148.33	73.3375
2151.99	57.2363
2155.66	54.9852
2159.31	37.2257
2162.97	54.3838
2166.63	65.2831
2170.28	26.2201
2173.94	55.0898
2177.59	46.847
2181.24	56.0542
2184.89	35.1873
2188.53	45.5544
2192.18	45.4386
2195.82	38.5012
2199.46	52.7551
2203.1	38.8953
2206.74	61.7047
2210.38	47.2822
2214.01	46.712
2217.65	39.7838
2221.28	66.8431
2224.91	49.9014
2228.54	25.4618
2232.16	51.7234
2235.79	12.5548
2239.41	0.0714111
2243.04	45.9336
2246.66	73.3267
2250.28	28.3229
2253.89	60.6177
2257.51	41.8007
2261.12	41.592
2264.74	14.0924
2268.35	61.6687
2271.96	53.2819
2275.57	85.0482
2279.17	22.2952
2282.78	25.686
2286.38	44.1787
2289.98	30.5491
2293.58	50.8007
2297.18	47.4568
2300.78	44.1528
2304.37	56.7635
2307.97	80.5214
2311.56	51.0454
2315.15	65.9492
2318.74	58.8594
2322.33	90.3616
2325.91	323.635
2329.5	1155.61
2333.08	431.271
2336.66	100.859
2340.24	58.3751
2343.82	61.964
2347.4	62.5801
2350.97	52.8115
2354.54	30.8712
2358.12	54.6647
2361.69	33.595
2365.26	60.9171
2368.82	61.3102
2372.39	42.5386
2375.95	80.1289
2379.52	49.338
2383.08	63.9347
2386.64	50.085
2390.19	17.177
2393.75	-7.16907
2397.31	54.1254
2400.86	33.2476
2404.41	33.1549
2407.96	54.2864
2411.51	41.9824
2415.06	32.686
2418.6	61.3229
2422.15	36.839
2425.69	28.2227
2429.23	66.0195
2432.77	61.6392
2436.31	91.7937
2439.84	46.9456
2443.38	65.3081
2446.91	52.0466
2450.44	24.9185
2453.97	60.7186
2457.5	31.9902
2461.03	58.7029
2464.55	55.2072
2468.08	12.0793
2471.6	49.099
2475.12	21.9768
2478.64	21.1337
2482.16	55.3472
2485.67	22.2278
2489.19	32.7014
2492.7	40.0045
2496.21	30.7157
2499.72	28.4063
2503.23	38.8297
2506.74	50.9038
2510.25	47.7736
2513.75	29.8542
2517.25	54.995
2520.75	39.4485
2524.25	92.6045
2527.75	41.3647
2531.25	62.5692
2534.74	26.678
2538.24	51.1371
2541.73	19.5712
2545.22	7.91516
2548.71	29.0442
2552.2	36.3986
2555.68	32.9713
2559.17	83.8335
2562.65	24.4163
2566.13	24.8027
2569.61	15.2842
2573.09	84.5231
2576.57	-4.04944
2580.04	57.4961
2583.51	57.244
2586.99	69.2817
2590.46	31.7644
2593.93	35.3135
2597.4	31.0697
2600.86	53.8811
2604.33	27.8693
2607.79	59.6134
2611.25	46.3246
2614.71	61.0568
2618.17	55.093
2621.63	63.0656
2625.09	67.9338
2628.54	62.8877
2631.99	24.054
2635.45	20.4976
2638.9	67.4272
2642.34	31.7115
2645.79	50.3689
2649.24	42.1682
2652.68	30.8768
2656.12	54.5356
2659.56	92.1047
2663.01	52.6718
2666.44	48.2731
2669.88	5.22632
2673.32	32.8521
2676.75	73.6692
2680.18	55.5031
2683.61	17.1058
2687.04	24.9507
2690.47	41.8846
2693.9	34.0359
2697.32	43.6604
2700.75	11.655
2704.17	54.1368
2707.59	80.8262
2711.01	26.4802
2714.43	53.2833
2717.84	62.6547
2721.26	61.0808
2724.67	67.1193
2728.08	34.9728
2731.49	73.8878
2734.9	65.0864
2738.31	72.2019
2741.71	15.4847
2745.12	32.6254
2748.52	25.2098
2751.92	36.6067
2755.32	25.3433
2758.72	42.1915
2762.12	67.5592
2765.52	36.1136
2768.91	28.0454
2772.3	37.701
2775.7	44.436
2779.09	44.3855
2782.47	63.9557
2785.86	8.14343
2789.25	63.3372
2792.63	39.4731
2796.01	49.4258
2799.4	47.1638
2802.78	56.9236
2806.15	31.0673
2809.53	53.9302
2812.91	47.688
2816.28	46.0698
2819.65	53.7787
2823.03	56.0536
2826.4	37.9634
2829.76	58.2034
2833.13	55.2859
2836.5	8.79871
2839.86	31.4463
2843.22	19.8446
2846.59	47.6434
2849.95	63.7542
2853.3	25.0765
2856.66	75.8994
2860.02	57.7643
2863.37	36.9218
2866.72	97.6295
2870.08	59.0126
2873.43	47.4823
2876.77	35.8929
2880.12	40.2579
2883.47	70.0383
2886.81	63.0011
2890.15	55.9283
2893.5	21.3804
2896.84	36.6301
2900.17	14.8558
2903.51	68.5864
2906.85	45.562
2910.18	58.3984
2913.52	54.1252
2916.85	51.67
2920.18	75.5416
2923.51	58.6783
2926.83	75.761
2930.16	36.9215
2933.48	26.3318
2936.81	64.6655
2940.13	73.7161
2943.45	50.7296
2946.77	82.4181
2950.09	96.2268
2953.4	43.2374
2956.72	83.3594
2960.03	73.8657
2963.34	59.7933
2966.65	72.0701
2969.96	54.671
2973.27	81.5562
2976.58	75.665
2979.88	84.0327
2983.19	78.1991
2986.49	107.168
2989.79	95.849
2993.09	111.803
2996.39	97.7677
2999.68	96.9448
3002.98	88.5869
3006.27	114.098
3009.57	101.137
3012.86	50.5542
3016.15	133.75
3019.43	124.614
3022.72	91.8696
3026.01	121.391
3029.29	106.581
3032.57	127.639
3035.86	124.086
3039.14	140.36
3042.41	128.276
3045.69	155.02
3048.97	89.9352
3052.24	129.018
3055.52	131.202
3058.79	165.59
3062.06	153.138
3065.33	175.97
3068.6	181.583
3071.86	185.99
3075.13	213.052
3078.39	185.403
3081.65	175.384
3084.91	129.393
3088.17	222.821
3091.43	216.028
3094.69	187.43
3097.95	207.659
3101.2	254.349
3104.45	215.237
3107.7	209.026
3110.95	244.519
3114.2	249.167
3117.45	272.021
3120.7	300.638
3123.94	292.12
3127.18	278.817
3130.43	329.315
3133.67	312.188
3136.91	315.99
3140.14	350.23
3143.38	375.881
3146.61	335.76
3149.85	368.194
3153.08	373.01
3156.31	396.85
3159.54	382.576
3162.77	382.568
3166	411.195
3169.22	432.064
3172.45	482.416
3175.67	492.625
3178.89	487.446
3182.11	476.529
3185.33	516.198
3188.55	516.586
3191.77	535.999
3194.98	540.154
3198.2	563.339
3201.41	594.097
3204.62	547.796
3207.83	561.539
3211.04	585.819
3214.25	633.036
3217.45	602.348
3220.66	624.942
3223.86	636.181
3227.06	655.195
3230.26	631.442
3233.46	641.109
3236.66	676.369
3239.85	658.705
3243.05	698.26
3246.24	718.88
3249.44	668.049
3252.63	707.921
3255.82	728.804
3259.01	739.175
3262.19	751.22
3265.38	740.104
3268.56	797.524
3271.75	762.114
3274.93	772.456
3278.11	746.477
3281.29	751.662
3284.47	753.672
3287.64	761.444
3290.82	800.532
3293.99	791.124
3297.17	792.137
3300.34	807.468
3303.51	786.07
3306.68	768.042
3309.84	809.778
3313.01	811.278
3316.18	816.47
3319.34	849.126
3322.5	899.672
3325.66	867.763
3328.82	858.635
3331.98	828.77
3335.14	894.5
3338.29	897.991
3341.45	903.502
3344.6	921.32
3347.75	924.511
3350.9	928.161
3354.05	978.916
3357.2	974.28
3360.35	974.462
3363.49	978.648
3366.64	1006.46
3369.78	1013.64
3372.92	1073.75
3376.06	1038.81
3379.2	1016.2
3382.34	1110.84
3385.48	1094.86
3388.61	1136.75
3391.75	1127.6
3394.88	1098.46
3398.01	1129.41
3401.14	1156.8
3404.27	1115.15
3407.4	1142.02
3410.52	1174.76
3413.65	1123.73
3416.77	1175.01
3419.89	1210.02
3423.01	1153.29
3426.13	1206.78
3429.25	1172.1
3432.37	1179.12
3435.49	1245.86
3438.6	1177.5
3441.72	1221.09
3444.83	1200.69
3447.94	1171.28
3451.05	1152.33
3454.16	1178.83
3457.26	1140.5
3460.37	1120.97
3463.47	1192.69
3466.58	1212.9
3469.68	1153.04
3472.78	1142.23
3475.88	1156.71
3478.98	1091.79
3482.07	1111.22
3485.17	1086.27
3488.26	1063.38
3491.36	1085.19
3494.45	1014.1
3497.54	1059.97
3500.63	1017.96
3503.72	982.638
3506.81	991.328
3509.89	979.273
3512.98	918.647
3516.06	948.764
3519.14	885.34
3522.22	886.691
3525.3	817.664
3528.38	824.983
3531.45	833.403
3534.53	789.518
3537.61	803.359
3540.68	732.414
3543.75	750.904
3546.82	725.701
3549.89	714.85
3552.96	701.693
3556.03	645.823
3559.09	682.898
3562.16	649.95
3565.22	620.437
3568.28	583.094
3571.34	595.494
3574.4	584.431
3577.46	551.62
3580.52	533.861
3583.57	558.67
3586.63	507.47
3589.68	508.43
3592.73	524.383
3595.78	460.681
3598.83	423.426
3601.88	470.493
3604.93	452.058
3607.97	443.95
3611.02	419.766
3614.06	402.157
3617.1	367.524
3620.14	375.466
3623.18	372.137
3626.22	377.337
3629.26	306.278
3632.3	333.182
3635.33	312.928
3638.36	320.277
3641.4	325.9
3644.43	283.677
3647.46	258.682
3650.49	254.076
3653.51	252.45
3656.54	242.843
3659.57	192.387
3662.59	184.101
3665.61	188.799
3668.63	155.323
3671.65	169.203
3674.67	156.732
3677.69	145.248
3680.71	141.362
3683.72	124.183
3686.74	81.463
3689.75	96.4418
3692.76	99.1554
3695.77	80.0869
3698.78	58.9207
3701.79	59.7405
3704.79	73.8499
3707.8	53.7697
3710.81	57.3189
3713.81	56.9993
3716.81	43.2512
3719.81	56.1991
3722.81	28.1113
3725.81	69.4444
3728.81	33.5755
3731.8	33.8284
3734.8	55.8988
3737.79	42.6385
3740.78	23.5969
3743.77	33.9631
3746.76	41.3975
3749.75	20.2233
3752.74	21.8118
3755.73	26.2366
3758.71	23.0875
3761.7	46.4696
3764.68	11.9527
3767.66	13.4865
3770.64	-6.68005
3773.62	23.3765
3776.6	8.09204
3779.58	17.4372
3782.55	7.93811
3785.53	31.5082
3788.5	6.96625
3791.47	14.5791
3794.44	2.49878
3797.41	14.0808
3800.38	0.22699
3803.35	1.58167
3806.32	-16.8562
3809.28	17.6248
3812.24	22.8802
3815.21	15.867
3818.17	-0.592163
3821.13	20.8214
3824.09	19.551
3827.04	14.5458
3830	30.3973
3832.96	19.7024
3835.91	21.409
3838.86	20.3081
3841.82	26.8086
3844.77	2.86938
3847.72	38.8853
3850.67	29.2581
3853.61	16.7985
3856.56	12.9204
3859.5	27.1922
3862.45	34.8018
3865.39	24.1938
3868.33	5.90308
3871.27	13.3929
3874.21	10.3193
3877.15	16.8019
3880.09	0.154541
3883.02	5.50415
3885.96	15.5685
3888.89	22.6958
3891.82	6.71729
3894.75	27.2363
3897.68	9.18982
3900.61	17.9816
3903.54	16.1724
3906.47	22.9203
3909.39	27.8351
3912.31	21.1419
3915.24	1.888
3918.16	8.52838
3921.08	16.259
3924	23.8337
3926.92	3.49396
3929.83	24.3324
3932.75	21.1584
3935.67	17.2131
3938.58	12.4695
3941.49	23.183
3944.4	28.0787
3947.31	13.8676
3950.22	28.4556
3953.13	15.3313
3956.04	7.02283
3958.94	28.4739
3961.85	11.6412
3964.75	31.258
3967.65	28.8754
3970.55	0.622864
3973.45	23.2373
3976.35	24.7262
3979.25	-6.50006
3982.15	35.2415
3985.04	30.849
3987.94	17.7611
3990.83	37.3424
3993.72	11.6283
3996.61	20.6782
3999.5	21.0563
4002.39	19.5449
4005.28	22.8583
4008.16	29.1002
4011.05	18.9677
4013.93	34.8508
4016.81	-1.34198
4019.7	14.5483
4022.58	26.5837
4025.46	23.177
4028.33	14.9494
4031.21	2.8504
4034.09	-6.341
4036.96	32.844
4039.84	27.5663
4042.71	19.354
4045.58	35.2327
4048.45	23.0508
4051.32	59.3774
4054.19	9.43878
4057.05	30.3712
4059.92	49.3528
4062.78	20.714
4065.65	13.4346
4068.51	16.8398
4071.37	15.3697
4074.23	7.07813
4077.09	46.4846
4079.95	34.2745
4082.81	24.9739
4085.66	29.3226
4088.52	41.4401
4091.37	5.74133
4094.22	28.6456
4097.07	60.302
4099.92	25.5721
4102.77	-2.36359
4105.62	43.9841
4108.47	11.0306
4111.31	34.8242
4114.16	23.309
4117	21.5073
4119.84	34.2845
4122.69	7.92633
4125.53	23.7308
4128.36	7.25647
4131.2	19.3489
4134.04	43.3049
4136.88	27.3162
4139.71	31.0279
4142.54	12.595
4145.38	46.8993
4148.21	15.9182
4151.04	39.7999
4153.87	27.2986
4156.69	41.9643
4159.52	25.0092
4162.35	32.7727
4165.17	34.7532
4168	15.2051
4170.82	16.2297
4173.64	30.0045
4176.46	-3.14502
4179.28	33.1387
4182.1	54.811
4184.91	20.757
4187.73	20.9711
4190.54	45.6633
4193.36	60.6871
4196.17	3.3277
4198.98	34.1895
4201.79	25.8412
4204.6	10.6437
4207.41	19.9391
4210.22	21.3998
4213.02	48.3875
4215.83	39.0142
4218.63	21.1632
4221.44	23.9236
4224.24	41.4244
4227.04	28.2554
4229.84	28.0231
4232.64	23.8517
4235.43	29.657
4238.23	29.561
4241.02	26.4966
4243.82	15.4817
4246.61	24.3904
4249.4	27.2958
4252.19	43.123
4254.98	27.9766
4257.77	23.7382
4260.56	16.4739
4263.35	3.20154
4266.13	12.0096
4268.92	17.8641
4271.7	19.6924
4274.48	39.6441
4277.26	29.2365
4280.04	20.7338
4282.82	47.5395
4285.6	30.8284
4288.38	46.3908
4291.15	38.6126
4293.93	16.6205
4296.7	52.4469
4299.47	17.397
4302.25	-2.53906
4305.02	8.95618
4307.79	24.5218
4310.55	29.9729
4313.32	16.173
4316.09	0.219238
4318.85	32.0181
4321.62	28.1688
4324.38	44.6263
4327.14	14.2153
4329.9	51.0366
4332.66	24.64
4335.42	25.7817
4338.18	45.1993
4340.94	52.5159
4343.69	28.2339
4346.45	21.3376
4349.2	13.4695
4351.95	24.9905
4354.7	26.4752
4357.45	5.40015
4360.2	8.84576
4362.95	19.4217
4365.7	40.3105
4368.44	10.9552
4371.19	51.353
4373.93	30.1224
4376.68	27.3323
4379.42	37.8346
4382.16	28.811
4384.9	6.45886
4387.64	9.92035
4390.37	13.6163
4393.11	40.0874
4395.85	42.3307
4398.58	30.6741
4401.31	31.3824
4404.05	32.0268
4406.78	36.853
4409.51	18.8561
4412.24	29.8695
4414.96	7.49854
4417.69	45.4999
4420.42	8.23053
4423.14	33.6274
4425.87	37.1678
4428.59	14.5944
4431.31	26.4908
4434.03	8.04419
4436.75	16.7672
4439.47	-5.96216
4442.19	20.4963
4444.91	44.8989
4447.62	10.5212
4450.34	23.3547
4453.05	32.9957
4455.76	16.3671
4458.47	16.4882
4461.19	10.2775
4463.89	-5.33008
4466.6	21.1175
4469.31	32.8836
4472.02	20.467
4474.72	11.2473
4477.43	33.6904
4480.13	16.1193
4482.83	43.9516
4485.53	10.5408
4488.23	8.75397
4490.93	17.5211
4493.63	25.1008
4496.33	-0.224854
4499.02	20.0748
4501.72	29.762
4504.41	18.213
4507.11	22.6132
4509.8	24.9116
4512.49	-0.376892
4515.18	28.4667
4517.87	19.1149
4520.56	36.343
4523.24	24.9382
4525.93	30.5393
4528.61	22.2957
4531.3	21.5144
4533.98	36.7348
4536.66	9.32101
4539.34	-1.03339
4542.02	27.0905
4544.7	16.7564
4547.38	39.5973
4550.05	42.1305
4552.73	23.2803
4555.4	38.824
4558.08	22.2466
4560.75	-3.91034
4563.42	21.6819
4566.09	20.5252
4568.76	18.4151
4571.43	36.5813
4574.1	7.517
4576.77	8.61584
4579.43	28.4298
4582.1	15.8726
4584.76	17.5313
4587.42	-14.8853
4590.08	9.328
4592.74	25.8783
4595.4	25.016
4598.06	16.5627
4600.72	14.6051
4603.38	2.89243
4606.03	37.1869
4608.69	-0.799377
4611.34	18.2032
4613.99	26.2372
4616.64	40.873
4619.29	26.9568
4621.94	0.925934
4624.59	-4.23352
4627.24	26.9647
4629.89	1.87912
4632.53	33.0894
4635.18	0.134125
4637.82	-0.810333
4640.46	8.19852
4643.1	29.4086
4645.74	8.6398
4648.38	17.9167
4651.02	1.77673
4653.66	-1.9957
4656.3	-8.2193
4658.93	30.7587
4661.57	4.31274
4664.2	28.1544
4666.83	34.0844
4669.46	7.45911
4672.09	31.2207
4674.72	22.5085
4677.35	35.0835
4679.98	29.7076
4682.61	27.6781
4685.23	20.0243
4687.86	32.6038
4690.48	28.3223
4693.1	13.9005
4695.73	3.92365
4698.34	7.46057
4700.96	11.011
4703.58	43.9156
4706.2	29.3467
4708.82	13.614
4711.43	35.1795
4714.05	26.1969
4716.66	23.9779
4719.28	30.7957
4721.89	17.2017
4724.5	33.0467
4727.11	7.008
4729.72	27.4894
4732.33	37.7758
4734.93	18.5427
4737.54	2.67767
4740.14	3.82211
4742.75	32.2425
4745.35	16.277
4747.95	30.9896
4750.55	36.535
4753.15	20.4717
4755.75	15.7753
4758.35	24.7334
4760.95	8.68896
4763.54	30.2456
4766.14	10.8325
4768.73	41.6486
4771.33	34.9005
4773.92	15.4957
4776.51	23.4752
4779.1	38.3135
4781.69	4.02902
4784.28	24.5786
4786.87	29.1396
4789.45	29.1281
4792.04	16.5396
4794.63	32.5836
4797.21	7.40674
4799.79	20.0785
4802.37	19.0223
4804.95	36.3723
4807.53	26.2166
4810.11	22.9731
4812.69	45.0582
4815.27	7.24115
4817.84	37.4848
4820.42	11.1845
4822.99	23.008
4825.57	31.3871
4828.14	36.2916
4830.71	12.164
4833.28	14.7682
4835.85	29.0413
4838.42	31.7348
4840.98	8.75696
4843.55	5.58081
4846.12	7.0069
4848.68	25.9922
4851.24	23.7346
4853.81	22.3649
4856.37	22.2405
4858.93	20.1595
4861.49	40.4446
4864.05	35.859
4866.61	2.75281
4869.16	19.2805
4871.72	18.1666
4874.27	-9.11938
4876.83	47.6861
4879.38	25.0678
4881.93	32.0694
4884.49	3.40726
4887.04	17.4951
4889.58	44.6867
4892.13	33.8223
4894.68	6.24994
4897.23	22.7123
4899.77	14.1391
4902.32	13.8906
4904.86	35.1086
4907.4	22.8944
4909.95	20.2042
4912.49	28.1654
4915.03	-3.32764
4917.57	14.1082
4920.1	23.2206
4922.64	21.5733
4925.18	21.1181
4927.71	21.8788
4930.25	11.8239
4932.78	19.7956
4935.31	12.29
4937.84	27.4617
4940.38	24.6739
4942.9	27.6857
4945.43	-2.68872
4947.96	23.2701
4950.49	26.4566
4953.01	-8.70154
4955.54	10.0367
4958.06	7.24832
4960.59	29.7014
4963.11	16.1524
4965.63	2.67538
4968.15	24.166
4970.67	11.8116
4973.19	16.3052
4975.71	19.5776
4978.22	13.1633
4980.74	16.4274
4983.25	5.15414
4985.77	29.0232
4988.28	39.5856
4990.79	33.158
4993.3	10.8813
4995.81	22.6202
4998.32	30.7808