File: Data/3-Raman/processed/bu19w-d-ore2-fi12-v_1800 (450-850nm)_532nm_edge_100%_x100_vis_lwd_h50um_30sx2_01.txt
#Acq. time (s)=	30
#Accumulations=	2
#Range (cm-¹)=	1200...2365
#Windows=	3
#Auto scanning=	Off
#Autofocus=	Off
#Macrospot=	Off
#AutoExposure=	Off
#Spike filter=	Multiple accum.
#Delay time (s)=	2
#Binning=	1
#Readout mode=	Signal
#DeNoise=	Off
#ICS correction=	On
#Dark correction=	Off
#Inst. Process=	Off
#Detector Gain=	Best Dynamic
#Detector ADC=	50 kHz HS
#Detector temperature (°C)=	-60.09
#Instrument=	LabRAM HR Evol
#Detector=	SIN-EM FIVIS
#Objective=	x100_VIS_LWD
#Grating=	1800 (450-850nm)
#ND Filter=	100%
#Laser=	532nm_Edge
#Hole=	49.98
#Temperature=	0
#Range=	Visible
#StageXY=	75x50mm Scan+
#StageZ=	Z motor
#X (µm)=	0
#Y (µm)=	0
#Z (µm)=	33.2
#Full time(mm:ss)=	3:22
#Project=	21_11_22
#Sample=	BU19w
#Site=
#Title=	BU19w-D-FFore2-FI12-V_1800 (450-850nm)_532nm_Edge_100%_x100_VIS_LWD_H50um_30sX2
#Remark=
#Date=	22.11.2021 14:29
#Acquired=	22.11.2021 14:29:18
#Base:Fit=	16.12.2021 17:39:50
#Base:Fit=	16.12.2021 17:40:01
#Base:Sub=	16.12.2021 17:40:04
1202.84	0.411493
1203.95	-0.876087
1205.06	0.00401688
1206.17	4.09699
1207.29	-1.41533
1208.39	-1.59779
1209.51	-2.83841
1210.62	3.39164
1211.72	-3.13424
1212.84	-0.0732861
1213.94	0.83123
1215.05	-2.50178
1216.16	2.67492
1217.27	-2.75048
1218.38	1.37856
1219.49	-0.873339
1220.6	3.21317
1221.71	0.976948
1222.81	7.22421
1223.92	0.801569
1225.03	5.93145
1226.14	8.93209
1227.24	5.79469
1228.35	7.7408
1229.46	6.62267
1230.56	7.60545
1231.67	12.8146
1232.78	6.47099
1233.88	6.41489
1234.99	8.42783
1236.09	4.14889
1237.2	4.09777
1238.3	1.96716
1239.41	1.9224
1240.51	2.94903
1241.62	1.87251
1242.72	1.82306
1243.83	-4.49663
1244.93	0.711763
1246.03	0.679058
1247.14	-2.47317
1248.24	5.85468
1249.34	-0.442986
1250.45	-1.51128
1251.55	0.585255
1252.65	-2.54457
1253.75	-1.49514
1254.86	-1.4981
1255.96	-3.59366
1257.06	3.73916
1258.16	7.88766
1259.26	4.82763
1260.36	8.93108
1261.46	5.92677
1262.56	25.767
1263.66	31.0084
1264.76	10.1616
1265.86	4.99439
1266.96	6.06684
1268.06	6.06145
1269.16	5.04282
1270.26	1.96365
1271.36	3.0687
1272.46	-0.0440922
1273.56	7.35591
1274.66	2.16279
1275.76	5.37779
1276.85	7.52447
1277.95	8.61233
1279.05	9.72699
1280.15	21.3298
1281.24	52.8438
1282.34	199.457
1283.44	510.14
1284.53	165.733
1285.63	35.2272
1286.73	14.247
1287.82	11.1452
1288.92	2.76215
1290.01	0.701691
1291.11	3.94294
1292.21	6.10832
1293.3	4.1099
1294.4	4.15753
1295.49	2.07821
1296.58	3.17217
1297.68	2.17615
1298.77	0.119972
1299.87	1.23648
1300.96	4.44784
1302.05	-1.8358
1303.15	1.36404
1304.24	0.358252
1305.33	0.415421
1306.42	0.477564
1307.52	-1.57288
1308.61	1.65257
1309.7	0.665337
1310.79	3.88108
1311.88	3.9396
1312.98	-1.27028
1314.07	-2.27277
1315.16	3.07278
1316.25	-0.0377522
1317.34	-4.20592
1318.43	3.22886
1319.52	-3.06716
1320.61	1.20018
1321.7	1.25936
1322.79	-0.805876
1323.88	1.31676
1324.97	-3.85307
1326.06	-3.77101
1327.15	2.6131
1328.23	4.75747
1329.32	0.564129
1330.41	2.69246
1331.5	-0.429604
1332.59	-0.391655
1333.67	2.79626
1334.76	-2.39779
1335.85	2.87885
1336.94	-1.25551
1338.02	1.944
1339.11	1.99051
1340.2	2.02424
1341.28	-0.0150604
1342.37	1.07515
1343.45	0.0536003
1344.54	-2.00504
1345.63	-0.918766
1346.71	4.32705
1347.8	1.23791
1348.88	4.3926
1349.96	-0.741375
1351.05	3.5024
1352.13	1.41415
1353.22	2.50218
1354.3	2.54079
1355.39	1.53843
1356.47	4.68368
1357.55	2.63654
1358.63	3.71362
1359.72	-0.388355
1360.8	1.73844
1361.88	4.89306
1362.97	3.88374
1364.05	7.00511
1365.13	6.01618
1366.21	4.00218
1367.29	8.17635
1368.37	15.4272
1369.45	14.3882
1370.54	8.22424
1371.62	6.19839
1372.7	11.392
1373.78	9.36178
1374.86	13.5091
1375.94	16.7011
1377.02	19.8163
1378.09	22.8568
1379.18	21.8274
1380.25	31.0389
1381.33	28.9969
1382.41	35.2389
1383.49	43.5409
1384.57	70.0591
1385.65	168.484
1386.72	1016.14
1387.8	317.377
1388.88	57.9161
1389.96	31.2723
1391.03	21.054
1392.11	15.969
1393.19	12.9443
1394.26	12.9616
1395.34	9.91827
1396.42	7.91664
1397.49	4.88766
1398.57	4.93094
1399.64	10.1272
1400.72	3.00119
1401.79	9.17101
1402.87	6.1062
1403.94	9.2023
1405.02	11.29
1406.09	11.3272
1407.17	23.6728
1408.24	48.2522
1409.31	33.92
1410.39	12.519
1411.46	8.39933
1412.53	4.33226
1413.61	7.44545
1414.68	7.48241
1415.75	2.37303
1416.82	4.44625
1417.9	1.37024
1418.97	1.39299
1420.04	3.51492
1421.11	0.387857
1422.18	2.45661
1423.26	4.53778
1424.33	5.55952
1425.4	2.48354
1426.47	3.53301
1427.54	4.59664
1428.61	-0.486151
1429.68	3.62499
1430.75	-2.53702
1431.82	-1.49005
1432.89	-0.448721
1433.96	2.63495
1435.02	3.66909
1436.09	3.69227
1437.16	1.67329
1438.23	1.69395
1439.3	8.88355
1440.37	0.69346
1441.43	0.702272
1442.5	-1.32061
1443.57	-1.31378
1444.64	1.76782
1445.7	3.83705
1446.77	3.84548
1447.84	1.79566
1448.9	1.7992
1449.97	2.83309
1451.04	-3.30157
1452.1	-0.218807
1453.17	-1.23001
1454.23	1.84568
1455.3	-2.24657
1456.36	-1.21066
1457.43	-0.180466
1458.49	-1.20482
1459.56	1.86052
1460.62	-0.195572
1461.69	-2.21548
1462.75	-0.21562
1463.81	0.804993
1464.88	-0.21274
1465.94	-1.22943
1467	3.86162
1468.07	2.83624
1469.13	0.793034
1470.19	-2.25981
1471.25	-0.228092
1472.32	2.83281
1473.38	3.84686
1474.44	0.788548
1475.5	-3.2815
1476.56	1.79166
1477.62	-1.27195
1478.68	3.79693
1479.75	-1.26069
1480.81	-1.25465
1481.87	-3.31448
1482.93	1.74687
1483.99	0.738695
1485.05	0.730818
1486.11	-0.295376
1487.17	3.74759
1488.22	0.703592
1489.28	2.72481
1490.34	0.701365
1491.4	-0.309467
1492.46	-1.32644
1493.52	-2.35263
1494.58	-3.36615
1495.63	-4.37597
1496.69	0.674757
1497.75	1.68602
1498.81	-1.34961
1499.86	0.661392
1500.92	-0.35725
1501.98	-1.36398
1503.03	-2.3876
1504.09	-0.371584
1505.15	0.635612
1506.2	2.65044
1507.26	-1.37809
1508.31	-2.40146
1509.37	0.580828
1510.42	-1.44966
1511.48	1.57393
1512.53	0.551708
1513.59	-1.47286
1514.64	-0.474209
1515.7	-2.47452
1516.75	0.538651
1517.8	-1.47144
1518.86	-1.46947
1519.91	-0.475197
1520.96	3.51029
1522.02	2.49765
1523.07	0.501455
1524.12	-2.49657
1525.17	0.501982
1526.23	-0.508196
1527.28	-0.51491
1528.33	0.497829
1529.38	-1.51018
1530.43	0.512714
1531.48	1.51776
1532.53	-1.50057
1533.59	1.47821
1534.64	0.454758
1535.69	3.44094
1536.74	1.47013
1537.79	0.499918
1538.84	1.4893
1539.89	1.46836
1540.94	-0.555807
1541.98	-1.54605
1543.03	5.48124
1544.08	0.476677
1545.13	-1.53644
1546.18	-1.54641
1547.23	-0.541197
1548.28	1.52067
1549.33	2.52479
1550.37	1.506
1551.42	0.488432
1552.47	1.47287
1553.52	1.4712
1554.56	2.47628
1555.61	4.46158
1556.65	3.43561
1557.7	1.42599
1558.75	-4.56727
1559.79	-1.55854
1560.84	2.43842
1561.88	0.455166
1562.93	3.32241
1563.98	0.420771
1565.02	0.437164
1566.07	4.44281
1567.11	3.43319
1568.15	3.43426
1569.2	4.42471
1570.24	1.41756
1571.29	6.40826
1572.33	0.439856
1573.37	2.44354
1574.42	5.41552
1575.46	1.40213
1576.5	-0.59046
1577.55	1.41223
1578.59	0.409464
1579.63	2.39422
1580.67	4.38551
1581.72	1.40182
1582.76	-0.587645
1583.8	3.38349
1584.84	3.379
1585.88	3.39076
1586.92	-0.579111
1587.96	0.426432
1589	2.41845
1590.04	2.4035
1591.08	2.3779
1592.12	6.36097
1593.16	5.3644
1594.2	1.39915
1595.24	4.38593
1596.28	5.36376
1597.32	4.36151
1598.36	2.36099
1599.4	-0.623318
1600.44	3.32312
1601.48	3.32481
1602.51	4.3225
1603.55	7.30776
1604.59	9.29911
1605.63	2.37819
1606.66	6.32089
1607.7	-0.464886
1608.74	6.92886
1609.77	4.88721
1610.81	3.62393
1611.85	3.85807
1612.88	3.1525
1613.92	6.34723
1614.95	3.44392
1615.99	3.2613
1617.03	8.90391
1618.06	3.75966
1619.1	5.47218
1620.13	4.33536
1621.17	6.9318
1622.2	6.75452
1623.23	3.61904
1624.27	3.066
1625.3	7.00905
1626.34	10.2551
1627.37	4.98423
1628.4	2.94163
1629.44	4.41141
1630.47	6.90398
1631.29	5.07732
1632.33	5.08776
1633.38	5.08949
1634.42	9.02506
1635.47	3.1211
1636.51	4.11554
1637.56	4.12741
1638.6	5.12845
1639.65	8.08724
1640.69	5.14284
1641.73	5.14377
1642.78	6.14683
1643.82	4.18287
1644.86	7.13721
1645.91	6.17778
1646.95	5.21593
1647.99	4.26281
1649.03	5.26877
1650.08	9.21832
1651.12	7.26508
1652.16	7.28673
1653.2	7.32857
1654.24	7.34764
1655.28	7.35286
1656.33	3.40797
1657.37	5.38616
1658.41	6.40301
1659.45	5.42872
1660.49	8.45121
1661.53	6.46312
1662.57	6.45662
1663.61	5.54396
1664.65	3.53854
1665.69	3.54751
1666.72	3.58657
1667.76	4.60388
1668.8	1.65285
1669.84	2.66032
1670.88	1.69094
1671.92	4.68455
1672.96	3.72022
1674	4.72858
1675.03	0.779373
1676.07	2.75975
1677.11	5.73298
1678.15	3.76517
1679.18	5.75644
1680.22	4.78433
1681.25	2.82255
1682.29	2.83361
1683.33	-0.111263
1684.36	2.87614
1685.4	2.88496
1686.43	2.88884
1687.47	2.89535
1688.51	2.92159
1689.54	0.967678
1690.58	0.968866
1691.61	0.9702
1692.64	4.92892
1693.68	1.99832
1694.71	0.0341263
1695.75	0.0384064
1696.78	3.00615
1697.81	3.01967
1698.85	2.04634
1699.88	-0.897671
1700.91	-0.883524
1701.95	0.120651
1702.98	0.136534
1704.01	0.139503
1705.04	2.10061
1706.08	2.09383
1707.11	-0.832144
1708.14	0.170521
1709.17	0.193026
1710.2	5.07922
1711.23	-0.791363
1712.27	1.17652
1713.3	1.19997
1714.33	-1.72862
1715.36	-0.762442
1716.39	0.220427
1717.42	-0.734077
1718.45	1.21747
1719.48	0.24671
1720.51	0.250799
1721.54	0.265381
1722.56	-3.61616
1723.59	0.271433
1724.62	0.280527
1725.65	0.286547
1726.68	2.19434
1727.71	-2.61655
1728.74	1.28417
1729.76	-1.60149
1730.79	-1.60031
1731.82	0.325813
1732.85	-1.59963
1733.87	0.336334
1734.9	-0.616232
1735.93	-1.57193
1736.95	-0.615261
1737.98	1.29897
1739.01	-0.611921
1740.03	-0.59898
1741.06	2.28281
1742.08	-1.53111
1743.11	-0.55969
1744.13	-3.42357
1745.16	-1.50714
1746.18	0.422289
1747.21	-0.502539
1748.23	-1.43096
1749.26	1.44084
1750.28	-4.28353
1751.31	-0.460009
1752.33	-1.40508
1753.35	-1.39935
1754.38	0.503416
1755.4	-1.37907
1756.42	2.44668
1757.44	-0.393495
1758.47	0.565094
1759.49	1.52755
1760.51	-0.353119
1761.53	0.623688
1762.56	-1.25233
1763.58	-0.283001
1764.6	-2.174
1765.62	-1.21226
1766.64	0.677784
1767.66	-0.250136
1768.68	1.68047
1769.7	-0.196536
1770.72	0.778889
1771.74	-3.00885
1772.76	-0.121774
1773.78	1.80443
1774.8	2.76194
1775.82	0.858955
1776.84	-2.94101
1777.86	-1.01581
1778.88	-0.0444841
1779.9	-0.971397
1780.92	-0.949014
1781.94	-0.923429
1782.95	1.95102
1783.97	1.01596
1784.99	0.101586
1786.01	-1.77111
1787.03	-0.784883
1788.04	-1.72671
1789.06	0.188087
1790.08	-1.7098
1791.09	0.223357
1792.11	-0.715321
1793.13	-0.679261
1794.14	-1.61526
1795.16	1.28999
1796.17	-0.619333
1797.19	-1.57757
1798.21	0.350574
1799.22	2.28594
1800.24	-1.53549
1801.25	0.406957
1802.27	-3.41875
1803.28	-1.46975
1804.29	-0.489207
1805.31	-0.477187
1806.32	-0.463922
1807.34	1.47769
1808.35	-1.40561
1809.36	-2.35826
1810.38	-2.34048
1811.39	3.4725
1812.4	-0.365281
1813.41	1.58117
1814.43	1.58745
1815.44	0.624821
1816.45	-0.325591
1817.46	0.657548
1818.47	-0.292991
1819.49	0.691293
1820.5	-2.20243
1821.51	1.67698
1822.52	0.723644
1823.53	0.733245
1824.54	1.71366
1825.55	-1.1828
1826.56	-1.18044
1827.57	1.72659
1828.58	-1.1677
1829.59	-0.184084
1830.6	3.70545
1831.61	0.801077
1832.62	-3.09013
1833.63	0.86095
1834.64	0.803693
1835.65	0.779624
1836.65	0.828436
1837.66	-1.12478
1838.67	0.784321
1839.68	1.73333
1840.69	-0.188406
1841.7	-0.183294
1842.7	0.786227
1843.71	-0.149252
1844.72	-0.202756
1845.72	1.73298
1846.73	-2.12471
1847.74	0.745477
1848.74	-2.14428
1849.75	-0.222127
1850.75	2.65705
1851.76	0.722336
1852.76	-0.248157
1853.77	1.6664
1854.78	0.706055
1855.78	-0.260605
1856.79	0.684378
1857.79	1.64783
1858.79	-2.16782
1859.8	0.696819
1860.8	-2.18351
1861.81	1.62783
1862.81	0.655402
1863.81	1.58183
1864.82	-2.24571
1865.82	-1.29794
1866.82	-1.29944
1867.83	-0.351862
1868.83	0.5941
1869.83	-0.365523
1870.83	-1.32189
1871.84	3.40741
1872.84	1.4888
1873.84	-1.37309
1874.84	1.42512
1875.84	2.41144
1876.84	2.4258
1877.84	0.527698
1878.84	-0.440725
1879.84	-0.476329
1880.84	0.471501
1881.84	0.446502
1882.85	-0.481067
1883.85	-1.42138
1884.84	1.39048
1885.84	-0.518512
1886.84	0.408207
1887.84	-2.41222
1888.84	-0.534272
1889.84	1.33959
1890.84	3.18746
1891.84	-0.582545
1892.83	-3.40303
1893.83	0.360936
1894.83	-2.45986
1895.83	0.350445
1896.83	-3.42462
1897.82	0.325423
1898.82	-3.42919
1899.82	2.21578
1900.81	3.14353
1901.81	0.314168
1902.81	0.305287
1903.8	0.285285
1904.8	0.278152
1905.79	0.279169
1906.79	2.16562
1907.79	-0.643241
1908.78	-0.643689
1909.78	-1.59507
1910.77	-0.656338
1911.77	2.18114
1912.76	0.296105
1913.76	2.1691
1914.75	-1.61979
1915.74	-0.678268
1916.74	-0.665762
1917.73	-1.61485
1918.72	0.279737
1919.72	-1.6186
1920.71	4.0381
1921.7	-2.59395
1922.7	-2.59666
1923.69	-1.6445
1924.68	0.251178
1925.67	1.1962
1926.66	-0.697254
1927.66	0.259159
1928.65	4.99934
1929.64	-1.66314
1930.63	-1.67445
1931.62	0.253577
1932.61	-0.669784
1933.61	-1.64231
1934.6	-0.711242
1935.59	-0.727524
1936.58	2.1311
1937.57	3.08522
1938.56	0.234035
1939.55	-2.64345
1940.54	1.16878
1941.52	-0.745887
1942.51	-2.6533
1943.5	-0.741349
1944.49	-1.7084
1945.48	-2.67707
1946.47	-0.768579
1947.46	0.196996
1948.44	-0.747946
1949.43	3.09682
1950.42	2.1329
1951.41	-0.789557
1952.39	-3.68831
1953.38	1.11744
1954.37	0.162531
1955.36	1.12202
1956.34	2.06816
1957.33	2.04865
1958.31	1.06536
1959.3	0.0927649
1960.29	-1.83577
1961.27	-4.72391
1962.26	-0.894816
1963.24	-0.900599
1964.23	2.94232
1965.21	-2.83472
1966.2	0.993565
1967.18	-0.95707
1968.17	1.89993
1969.15	-0.991527
1970.14	-0.0444288
1971.12	1.85012
1972.1	0.879669
1973.09	-1.04124
1974.07	-1.05037
1975.05	-2.98594
1976.04	0.830885
1977.02	1.77968
1978	-1.1149
1978.98	0.783491
1979.97	-0.192943
1980.95	-0.217099
1981.93	0.721708
1982.91	0.702065
1983.89	1.65426
1984.88	-0.278317
1985.86	-2.2293
1986.84	0.58734
1987.82	0.583958
1988.8	1.53657
1989.78	1.53652
1990.76	-1.14367
1991.74	2.9421
1992.72	1.21193
1993.7	1.23398
1994.68	-0.500687
1995.66	-0.653166
1996.64	-1.22337
1997.62	0.85202
1998.6	1.59518
1999.57	-1.51689
2000.55	-0.878286
2001.53	1.9294
2002.51	-0.826518
2003.49	-0.745108
2004.47	-0.315332
2005.44	0.261871
2006.42	-2.81135
2007.4	0.0384064
2008.38	0.405439
2009.35	0.714096
2010.33	0.119171
2011.3	0.105263
2012.18	2.41341
2013.17	0.533991
2014.16	0.54245
2015.15	0.516449
2016.14	-0.455464
2017.13	0.459595
2018.11	0.449982
2019.1	2.31398
2020.09	-1.45277
2021.08	-0.538987
2022.06	0.368193
2023.05	0.339821
2024.04	-0.573855
2025.02	-0.568877
2026.01	-0.542017
2027	-0.602423
2027.98	0.298782
2028.97	-1.56575
2029.96	2.18368
2030.94	2.1954
2031.93	0.274578
2032.91	-2.50253
2033.9	2.16472
2034.88	-2.51361
2035.87	1.20954
2036.85	-0.676698
2037.83	2.09866
2038.82	0.218119
2039.8	0.202969
2040.79	3.00596
2041.77	-4.45429
2042.75	1.13946
2043.74	0.223457
2044.72	0.188423
2045.7	-1.68414
2046.69	2.98886
2047.67	-0.731242
2048.65	-1.67673
2049.63	-0.744846
2050.62	-1.67274
2051.6	0.206776
2052.58	1.13175
2053.56	-1.68299
2054.54	-2.62107
2055.52	1.12634
2056.5	0.198736
2057.48	3.00062
2058.46	-4.48766
2059.45	-0.743127
2060.43	-1.67358
2061.4	0.204704
2062.39	-1.66103
2063.37	0.227615
2064.34	-1.64729
2065.32	-0.701376
2066.3	2.1185
2067.28	1.16211
2068.26	-0.695512
2069.24	-0.678435
2070.22	0.258568
2071.2	2.14204
2072.18	-1.61226
2073.15	1.24178
2074.13	-2.53745
2075.11	1.2244
2076.09	0.290085
2077.06	1.25292
2078.04	2.20206
2079.02	1.25444
2080	1.25916
2080.97	1.25795
2081.95	-3.46541
2082.93	0.31646
2083.9	1.27901
2084.88	0.341024
2085.85	-2.49484
2086.83	-1.53766
2087.8	1.31137
2088.78	1.32334
2089.75	-0.550427
2090.73	-0.53178
2091.7	0.428923
2092.68	1.37409
2093.65	-0.530074
2094.63	-1.48572
2095.6	0.410275
2096.57	0.411257
2097.55	1.36475
2098.52	-1.46921
2099.5	1.38462
2100.47	3.2773
2101.44	3.28124
2102.41	0.447645
2103.39	2.36382
2104.36	0.47101
2105.33	-0.488356
2106.3	4.25485
2107.27	2.36974
2108.25	0.474501
2109.22	-1.4259
2110.19	0.483559
2111.16	3.34892
2112.13	-1.39868
2113.1	0.502781
2114.07	1.449
2115.04	2.39984
2116.01	2.38807
2116.99	1.4312
2117.96	3.33223
2118.92	2.40554
2119.9	-1.3715
2120.86	1.4858
2121.83	-1.3689
2122.8	0.50828
2123.77	-1.39329
2124.74	-1.39482
2125.71	0.499479
2126.68	-0.441255
2127.65	-0.437375
2128.61	-1.38239
2129.58	-0.438872
2130.55	2.39542
2131.52	1.46204
2132.48	0.524094
2133.45	1.46065
2134.42	-0.417881
2135.39	2.41867
2136.35	0.549635
2137.32	0.538509
2138.28	1.48221
2139.25	1.48205
2140.22	-2.25944
2141.18	-0.407499
2142.15	0.547733
2143.12	0.555765
2144.08	0.559109
2145.05	-2.25818
2146.01	1.4995
2146.98	0.551945
2147.94	1.48831
2148.9	0.568985
2149.87	1.51528
2150.83	-0.358856
2151.8	-0.367413
2152.76	2.42345
2153.72	-0.380582
2154.69	0.566351
2155.65	-0.351875
2156.61	-0.348338
2157.58	-5.02008
2158.54	0.583208
2159.5	2.45679
2160.47	0.595436
2161.43	3.39317
2162.39	1.53369
2163.35	-0.320785
2164.31	0.611206
2165.27	2.45741
2166.24	0.607499
2167.2	-0.293404
2168.16	1.58052
2169.12	-1.22505
2170.08	-0.293648
2171.04	-0.280817
2172	-1.19744
2172.96	0.668801
2173.92	-0.255663
2174.88	-2.10283
2175.84	0.685806
2176.8	-1.16015
2177.76	-2.07968
2178.72	-2.07302
2179.68	-0.212518
2180.64	-0.214492
2181.59	0.713388
2182.55	-0.198593
2183.51	-2.0333
2184.47	0.778426
2185.43	-1.06809
2186.38	0.784133
2187.34	2.63504
2188.3	0.794338
2189.26	2.66456
2190.21	1.75602
2191.17	-0.999284
2192.13	-0.0545816
2193.08	-0.0562181
2194.04	-0.0637064
2195	-0.98605
2195.95	-1.89197
2196.91	-0.935107
2197.86	-0.898019
2198.82	2.82235
2199.78	-0.909981
2200.73	1.90443
2201.69	0.0897865
2202.64	-0.876636
2203.59	0.0646915
2204.55	0.0734558
2205.5	0.0954332
2206.46	1.04336
2207.41	-0.808499
2208.37	-0.790849
2209.32	-0.771348
2210.27	2.96501
2211.23	-1.69113
2212.18	-2.60267
2213.13	-5.39372
2214.09	2.08152
2215.04	0.223577
2215.99	2.10333
2216.94	0.252538
2217.9	-1.60883
2218.85	-0.678823
2219.8	0.257835
2220.75	-1.59256
2221.7	-0.63461
2222.65	-0.613488
2223.6	2.21636
2224.55	-0.57786
2225.5	1.30253
2226.46	-1.5064
2227.41	0.388079
2228.36	0.407432
2229.31	1.36649
2230.26	-1.43704
2231.21	-1.42263
2232.16	0.458982
2233.11	-0.484625
2234.05	0.464363
2235	1.43073
2235.95	-3.25871
2236.9	1.46506
2237.85	3.35173
2238.8	-3.23758
2239.75	-1.34054
2240.69	-0.396468
2241.64	-0.391297
2242.59	-1.31318
2243.54	-0.352574
2244.48	0.605097
2245.43	-0.338855
2246.38	0.607578
2247.32	-0.33288
2248.27	-0.341881
2249.22	-2.23093
2250.16	-1.26593
2251.11	1.59573
2252.06	0.654598
2253	4.45213
2253.95	1.62126
2254.89	-2.16466
2255.84	0.690163
2256.78	-0.250763
2257.73	1.65859
2258.67	-2.13324
2259.62	-1.17521
2260.56	-0.207108
2261.51	0.770286
2262.45	-0.169127
2263.39	-1.12632
2264.34	-4.95438
2265.28	-0.193168
2266.22	-1.14177
2267.17	-2.07965
2268.11	2.7113
2269.05	0.810026
2270	2.72742
2270.94	-0.13952
2271.88	-2.05094
2272.82	-2.04901
2273.77	0.836755
2274.71	-0.104918
2275.65	-2.97074
2276.59	3.74716
2277.53	2.76414
2278.47	-0.122028
2279.41	1.79826
2280.36	0.853997
2281.3	-2.0029
2282.24	-0.0680351
2283.18	-1.03792
2284.12	0.895663
2285.06	1.87327
2286	1.86316
2286.94	-2.00836
2287.88	-2.01217
2288.82	-0.0756483
2289.75	-0.0647745
2290.69	1.87198
2291.63	0.902865
2292.57	-1.9966
2293.51	-1.04707
2294.45	-0.0803022
2295.39	-0.0647564
2296.32	-0.0529499
2297.26	1.88001
2298.2	-1.00877
2299.14	-1.00653
2300.07	-0.0437613
2301.01	-0.0430956
2301.95	-1.96565
2302.89	-2.92588
2303.82	-0.0219164
2304.76	-0.0252781
2305.69	0.937801
2306.63	1.91545
2307.57	2.89537
2308.5	2.88
2309.44	1.89123
2310.37	0.924628
2311.31	0.947439
2312.24	-1.93332
2313.18	1.92241
2314.11	-0.988272
2315.05	-0.0110121
2315.98	-0.0194416
2316.92	-0.987941
2317.85	-0.0168829
2318.78	0.964495
2319.72	-0.948427
2320.65	2.9265
2321.58	2.93267
2322.52	1.95258
2323.45	3.87557
2324.38	2.90204
2325.32	1.93912
2326.25	9.64936
2327.18	38.5495
2328.11	47.2114
2329.05	11.607
2329.98	6.7829
2330.91	1.97163
2331.84	-2.83774
2332.77	0.0577869
2333.7	0.068923
2334.63	-0.88126
2335.56	-0.870211
2336.5	-2.77691
2337.43	1.07753
2338.36	-3.72092
2339.29	2.9978
2340.22	-0.824111
2341.15	0.152981
2342.08	-1.7437
2343.01	-1.73181
2343.93	2.11582
2344.86	0.221429
2345.79	1.20719
2346.72	0.257979
2347.65	2.14454
2348.58	2.23854
2349.51	0.308002
2350.44	-0.644486
2351.36	0.334435
2352.29	1.32508
2353.22	-1.50633
2354.15	0.412443
2355.07	-2.41245
2356	0.468697
2356.93	-1.39834
2357.86	2.42489
2358.78	0.55416
2359.71	-0.365186
2360.63	0.616335
2361.56	-1.23713
2362.49	0.69231
2363.41	3.54741
2364.34	0.783071
2364.8	0.814316