File: Data/3-Raman/processed/bu19(2)w-a-ff2b-fi05-v_1800 (450-850nm)_532nm_edge_100%_x100_vis_lwd_h100um_30sx2_01.txt
#Acq. time (s)=	30
#Accumulations=	2
#Range (cm-¹)=	1200...2365
#Windows=	3
#Auto scanning=	Off
#Autofocus=	Off
#Macrospot=	Off
#AutoExposure=	Off
#Spike filter=	Multiple accum.
#Delay time (s)=	2
#Binning=	1
#Readout mode=	Signal
#DeNoise=	Off
#ICS correction=	On
#Dark correction=	Off
#Inst. Process=	Off
#Detector Gain=	Best Dynamic
#Detector ADC=	50 kHz HS
#Detector temperature (°C)=	-60.09
#Instrument=	LabRAM HR Evol
#Detector=	SIN-EM FIVIS
#Objective=	x50_VIS_LWD
#Grating=	1800 (450-850nm)
#ND Filter=	100%
#Laser=	532nm_Edge
#Hole=	100.021
#Temperature=	0
#Range=	Visible
#StageXY=	75x50mm Scan+
#StageZ=	Z motor
#X (µm)=	0
#Y (µm)=	0
#Z (µm)=	2.5
#Full time(mm:ss)=	3:18
#Project=	21_11_26
#Sample=	BU19(2)w
#Site=
#Title=	BU19(2)w-A-FF2b-FI05-V_1800 (450-850nm)_532nm_Edge_100%_x50_VIS_LWD_H100um_30sX2
#Remark=
#Date=	26.11.2021 14:50
#Acquired=	26.11.2021 14:50:13
#Base:Fit=	16.12.2021 16:00:56
#Base:Fit=	16.12.2021 16:10:24
#Base:Sub=	16.12.2021 16:10:25
1202.72	6.86941
1203.84	1.35424
1204.95	3.21201
1206.06	6.02591
1207.17	1.24517
1208.28	-1.34519
1209.39	-2.89867
1210.5	-0.164223
1211.61	-0.76635
1212.72	6.0713
1213.83	-2.00696
1214.94	-5.7831
1216.05	2.11241
1217.16	0.287148
1218.27	3.77463
1219.38	-4.40128
1220.49	2.2683
1221.6	-1.68813
1222.71	-1.50839
1223.81	-0.339371
1224.92	0.862251
1226.03	2.14117
1227.14	-0.845406
1228.25	1.25298
1229.35	-2.99138
1230.46	-0.531174
1231.57	1.46251
1232.67	-4.7367
1233.78	3.73933
1234.89	-2.45902
1235.99	-5.51741
1237.1	2.92084
1238.2	8.09561
1239.31	-0.376389
1240.41	5.89561
1241.52	-1.43267
1242.62	2.71996
1243.73	6.92159
1244.83	5.84615
1245.94	2.58971
1247.04	6.68855
1248.14	10.8056
1249.25	15.9295
1250.35	11.6848
1251.45	9.44716
1252.56	8.26865
1253.66	10.2206
1254.76	15.4175
1255.87	22.6641
1256.97	46.6292
1258.07	52.7807
1259.17	41.1458
1260.27	66.2054
1261.37	120.203
1262.48	164.469
1263.58	148.081
1264.68	82.8279
1265.78	54.3652
1266.88	48.0113
1267.98	51.193
1269.08	38.7188
1270.18	47.0185
1271.28	33.2127
1272.38	37.3347
1273.47	37.4039
1274.57	47.9376
1275.67	64.6695
1276.77	71.0164
1277.87	81.5892
1278.97	136.368
1280.07	302.551
1281.16	1005.17
1282.26	2801.6
1283.36	2414.14
1284.45	730.096
1285.55	243.853
1286.65	112.153
1287.75	82.5764
1288.84	60.4145
1289.94	55.2216
1291.03	36.2924
1292.13	37.3293
1293.22	39.4313
1294.32	24.8287
1295.42	30.1413
1296.51	28.2874
1297.61	21.956
1298.7	24.0385
1299.79	17.6837
1300.89	13.533
1301.98	8.31451
1303.08	6.28008
1304.17	20.032
1305.26	8.47286
1306.35	11.6293
1307.45	5.35983
1308.54	6.50383
1309.63	1.34422
1310.73	2.50735
1311.82	6.84267
1312.91	1.71231
1314	1.79758
1315.09	-2.29951
1316.18	-1.07817
1317.28	3.26172
1318.37	-10.3093
1319.46	3.56847
1320.55	-0.510056
1321.64	4.8635
1322.73	0.72316
1323.82	1.91092
1324.91	-2.13414
1326	0.0943375
1327.09	3.29543
1328.18	4.67733
1329.27	-3.47151
1330.35	1.98713
1331.44	-1.04533
1332.53	3.25501
1333.62	2.30295
1334.71	-4.92512
1335.79	-2.67039
1336.88	4.8447
1337.97	-5.44154
1339.06	-9.45549
1340.14	1.25025
1341.23	-3.73847
1342.32	6.94697
1343.4	-2.29115
1344.49	4.23035
1345.58	-4.95879
1346.66	-1.66691
1347.75	0.592903
1348.83	6.03654
1349.92	2.08466
1351	6.46207
1352.09	11.8795
1353.17	11.1765
1354.25	18.8399
1355.34	10.5984
1356.42	11.9203
1357.51	18.404
1358.59	13.4542
1359.67	12.6565
1360.76	24.2751
1361.84	18.3356
1362.92	31.0344
1364	36.5585
1365.09	34.7945
1366.17	35.0183
1367.25	26.9499
1368.33	79.9818
1369.41	107.226
1370.5	46.5154
1371.58	37.4467
1372.66	35.5544
1373.74	48.1768
1374.82	54.6506
1375.9	59.0979
1376.98	57.3119
1378.06	74.0698
1379.14	85.9745
1380.22	98.597
1381.3	125.33
1382.38	184.022
1383.46	270.169
1384.54	614.799
1385.61	2236.16
1386.69	7044
1387.77	2057.52
1388.85	503.139
1389.93	221.213
1391	145.247
1392.08	113.658
1393.16	100.552
1394.23	79.3387
1395.31	69.4378
1396.39	61.6299
1397.46	60.8826
1398.54	64.2642
1399.62	57.4925
1400.69	65.0367
1401.77	54.1671
1402.84	61.8573
1403.92	78.7338
1404.99	91.2833
1406.07	140.734
1407.14	206.608
1408.22	286.989
1409.29	206.401
1410.37	94.9773
1411.44	55.1859
1412.51	44.2214
1413.59	33.5235
1414.66	25.5315
1415.73	24.8651
1416.81	19.0502
1417.88	18.3774
1418.95	27.9582
1420.02	20.0349
1421.1	23.3702
1422.17	10.3407
1423.24	14.9022
1424.31	22.1634
1425.38	4.01413
1426.45	7.41272
1427.52	11.7549
1428.59	13.0188
1429.67	9.24016
1430.74	10.6149
1431.81	9.96314
1432.87	5.09206
1433.95	7.34716
1435.01	6.62998
1436.08	5.89045
1437.15	6.15577
1438.22	1.30067
1439.29	4.66987
1440.36	2.93456
1441.43	0.145111
1442.49	6.56229
1443.56	0.675022
1444.63	2.98027
1445.7	9.43866
1446.77	5.57711
1447.83	4.78912
1448.9	5.05946
1449.97	0.175766
1451.03	1.4269
1452.1	2.68062
1453.17	-2.20163
1454.23	4.19448
1455.3	-5.81837
1456.36	0.575481
1457.43	-0.236206
1458.49	3.05861
1459.56	-1.82957
1460.62	-3.66161
1461.69	7.80458
1462.75	-1.22382
1463.82	2.01969
1464.88	2.28203
1465.94	-0.705769
1467.01	-3.57472
1468.07	-3.37849
1469.13	-4.20432
1470.2	-1.99403
1471.26	-1.82127
1472.32	0.384415
1473.39	-2.48929
1474.45	0.729267
1475.51	-4.17064
1476.57	-4.00492
1477.63	-0.796478
1478.69	0.378246
1479.76	-2.52669
1480.82	-5.44567
1481.88	-2.25074
1482.94	-7.13832
1484	-0.880615
1485.06	-3.84729
1486.12	-2.69223
1487.18	3.54138
1488.24	0.627567
1489.3	-4.32086
1490.36	0.869026
1491.42	-0.0254936
1492.48	-3.93802
1493.53	2.25578
1494.59	-3.6809
1495.65	0.473549
1496.71	-0.450054
1497.77	6.72579
1498.82	-4.25925
1499.88	-0.0974655
1500.94	1.02866
1502	-2.91296
1503.05	2.22557
1504.11	-1.72252
1505.17	2.41752
1506.22	0.466427
1507.28	-3.46318
1508.34	-2.36042
1509.39	3.77843
1510.45	2.86695
1511.5	0.90427
1512.56	2.92458
1513.61	-1.05309
1514.67	1.05894
1515.72	-1.90765
1516.78	-0.861874
1517.83	2.21306
1518.88	-2.71667
1519.94	0.3708
1520.99	-2.57771
1522.05	-1.50444
1523.1	3.5566
1524.15	-2.44068
1525.2	-2.39854
1526.26	1.67778
1527.31	-2.25885
1528.36	1.78683
1529.41	-1.18379
1530.47	0.855167
1531.52	0.923771
1532.57	-6.05269
1533.62	0.0371742
1534.67	-0.921841
1535.72	1.10357
1536.77	1.08707
1537.82	2.08017
1538.87	5.08677
1539.92	-3.83333
1540.97	-0.745014
1542.02	7.27552
1543.07	8.25809
1544.12	-0.770149
1545.17	3.27461
1546.22	-0.675232
1547.27	-0.650463
1548.32	-0.65284
1549.37	1.34244
1550.42	4.37125
1551.46	5.5034
1552.51	4.51031
1553.56	2.48225
1554.61	6.47144
1555.65	2.43272
1556.7	0.430286
1557.75	-0.563187
1558.79	1.41192
1559.84	-0.629665
1560.89	-3.64659
1561.93	-1.64378
1562.98	1.37135
1564.02	2.35965
1565.07	5.38647
1566.11	1.15406
1567.16	-4.69345
1568.2	0.319897
1569.25	-0.681263
1570.29	0.289841
1571.34	-0.722271
1572.38	5.24237
1573.43	0.212257
1574.47	-0.80415
1575.51	0.213566
1576.56	-0.796761
1577.6	2.13949
1578.64	2.07815
1579.69	-1.93058
1580.73	-1.93961
1581.77	1.01572
1582.81	-1.01788
1583.85	2.93849
1584.9	-2.0616
1585.94	-2.08553
1586.98	0.85186
1588.02	4.79434
1589.06	2.79428
1590.1	1.78915
1591.14	-2.20831
1592.18	2.73806
1593.22	3.67113
1594.26	-2.37233
1595.3	-0.405216
1596.34	-1.43732
1597.38	2.51306
1598.42	5.46809
1599.46	-3.52886
1600.5	0.388607
1601.54	4.28391
1602.58	3.22533
1603.62	-3.76008
1604.66	-0.829517
1605.69	5.07838
1606.73	-3.83475
1607.77	0.0479927
1608.81	0.000995636
1609.84	1.71218
1610.88	-4.05863
1611.92	0.752705
1612.95	0.987049
1613.99	-0.410236
1615.03	-3.17776
1616.06	0.639027
1617.1	-0.907913
1618.13	-0.124084
1619.17	0.353481
1620.2	-0.648262
1621.24	0.384083
1622.27	-1.65113
1623.31	0.793758
1624.34	0.981449
1625.38	-0.33651
1626.41	3.24807
1627.45	-0.573364
1628.48	1.35755
1629.51	3.59287
1630.55	1.6556
1631.53	2.86213
1632.57	-4.04577
1633.62	-1.11889
1634.66	1.81992
1635.71	0.805302
1636.75	0.764404
1637.8	-0.265713
1638.84	-2.2697
1639.89	-3.2786
1640.93	-3.29739
1641.98	0.61697
1643.02	-0.398087
1644.06	-0.426643
1645.11	1.50359
1646.15	0.50856
1647.19	4.40806
1648.24	4.37421
1649.28	-1.51639
1650.32	0.431091
1651.37	1.42928
1652.41	-0.55368
1653.45	-2.55093
1654.49	3.35072
1655.53	-1.57958
1656.57	4.36038
1657.62	-2.56449
1658.66	1.35442
1659.7	-3.61304
1660.74	-2.64708
1661.78	-1.65118
1662.82	-2.6148
1663.86	1.32778
1664.9	3.26511
1665.94	2.21621
1666.98	0.277935
1668.02	1.23403
1669.06	0.243828
1670.1	-0.727917
1671.14	-1.7001
1672.18	-6.65713
1673.21	3.22264
1674.25	1.24672
1675.29	3.2394
1676.33	-3.68538
1677.37	-1.70901
1678.4	1.23689
1679.44	0.219051
1680.48	-2.76327
1681.52	0.185337
1682.55	-0.806747
1683.59	-0.811787
1684.63	-4.77321
1685.66	0.156441
1686.7	0.158993
1687.73	-0.820564
1688.77	-3.79798
1689.81	-2.83315
1690.84	-2.8405
1691.88	0.133759
1692.91	-1.84174
1693.95	1.08505
1694.98	-0.90942
1696.01	1.06995
1697.05	-1.87182
1698.08	1.06014
1699.12	0.0562439
1700.15	-1.90742
1701.18	-2.89368
1702.22	2.01276
1703.25	1.99673
1704.28	1.99498
1705.32	-1.91977
1706.35	1.02862
1707.38	3.9477
1708.41	3.91333
1709.44	-2.97928
1710.48	-1.99704
1711.51	-0.0158386
1712.54	-3.91984
1713.57	-0.0440865
1714.6	-1.04575
1715.63	-0.0563965
1716.66	-4.9284
1717.69	2.85149
1718.72	2.80268
1719.75	0.855114
1720.78	-1.07921
1721.81	-0.121128
1722.84	3.74662
1723.87	-0.150875
1724.9	2.76641
1725.93	2.73006
1726.96	-1.14357
1727.99	-1.13662
1729.02	1.71374
1730.05	-0.237637
1731.07	9.4124
1732.1	1.75182
1733.13	5.619
1734.16	7.51316
1735.18	1.6972
1736.21	1.68111
1737.24	1.68348
1738.26	3.60491
1739.29	3.59119
1740.32	1.63358
1741.34	2.56964
1742.37	6.39394
1743.4	4.48757
1744.42	3.53181
1745.45	3.54483
1746.47	7.37605
1747.5	1.62125
1748.52	3.52987
1749.55	3.56038
1750.57	3.61332
1751.6	5.56384
1752.62	-0.183067
1753.64	1.71813
1754.67	4.57276
1755.69	4.57391
1756.71	1.70449
1757.74	6.44453
1758.76	6.48027
1759.78	6.50674
1760.81	9.37206
1761.83	5.5627
1762.85	4.63156
1763.87	4.65869
1764.89	11.3716
1765.92	10.4627
1766.94	9.52988
1767.96	10.4905
1768.98	13.3475
1770	7.58558
1771.02	12.3804
1772.04	10.5394
1773.06	9.63596
1774.08	13.4847
1775.1	12.5699
1776.12	8.82452
1777.14	11.7054
1778.16	11.6976
1779.18	8.82501
1780.2	7.88712
1781.22	7.92205
1782.24	6.05063
1783.26	9.90976
1784.28	7.09263
1785.29	5.23246
1786.31	5.2422
1787.33	8.1438
1788.35	2.50612
1789.37	5.45185
1790.38	8.38164
1791.4	3.60303
1792.42	1.67701
1793.43	1.70639
1794.45	6.52298
1795.47	5.61763
1796.48	4.7192
1797.5	1.88361
1798.51	0.956905
1799.53	3.85452
1800.55	0.96315
1801.56	1.92927
1802.58	4.83424
1803.59	0.0700531
1804.61	2.02402
1805.62	9.77069
1806.64	3.07524
1807.65	1.17155
1808.66	2.15109
1809.68	1.20546
1810.69	1.22292
1811.7	-1.66138
1812.72	2.21255
1813.73	4.17258
1814.74	3.25274
1815.76	4.25835
1816.77	-0.555901
1817.78	-2.49744
1818.79	0.416145
1819.8	5.26854
1820.82	1.42737
1821.83	3.3885
1822.84	-0.459667
1823.85	4.38807
1824.86	1.4929
1825.87	1.51263
1826.88	0.552799
1827.89	3.47517
1828.9	1.54206
1829.91	-0.40062
1830.92	-0.408833
1831.93	3.48222
1832.94	0.600693
1833.95	3.52171
1834.96	8.34396
1835.97	-2.3568
1836.98	-2.24171
1837.99	2.50184
1839	8.30677
1840	2.55002
1841.01	4.41482
1842.02	3.38069
1843.03	1.41939
1844.04	-1.47567
1845.04	-2.44096
1846.05	1.42586
1847.06	-0.474678
1848.07	0.373295
1849.07	1.33904
1850.08	2.27088
1851.09	3.18411
1852.09	-1.64576
1853.1	0.267628
1854.1	0.248638
1855.11	-3.62777
1856.11	-3.66264
1857.12	0.157158
1858.12	3.96708
1859.13	0.102119
1860.13	-0.885513
1861.14	2.94535
1862.14	-3.74283
1863.15	-5.68443
1864.15	0.0145149
1865.15	0.934105
1866.16	-1.02736
1867.16	-2.04484
1868.16	-0.194103
1869.17	-2.11138
1870.17	-4.0307
1871.17	2.60421
1872.17	0.677433
1873.18	-0.30645
1874.18	1.56435
1875.18	-1.32684
1876.18	0.505085
1877.18	-1.4377
1878.18	-3.38802
1879.19	-4.30054
1880.19	0.440575
1881.19	1.36666
1882.19	-0.591953
1883.19	-1.62152
1884.19	-0.730972
1885.19	0.210651
1886.19	-2.59696
1887.19	-1.67571
1888.19	-1.72528
1889.19	1.97993
1890.19	1.94031
1891.19	-1.82512
1892.18	-3.73559
1893.18	-0.00414276
1894.18	1.80348
1895.18	3.64504
1896.18	-0.123177
1897.18	1.75823
1898.17	2.68657
1899.17	1.70326
1900.17	6.35426
1901.16	3.51225
1902.16	0.697788
1903.16	3.50975
1904.16	-3.10923
1905.15	-1.25762
1906.15	4.34446
1907.14	3.35477
1908.14	2.39643
1909.14	8.02609
1910.13	-0.424355
1911.13	-4.17468
1912.12	4.28724
1913.12	-3.27835
1914.11	3.30774
1915.11	1.43286
1916.1	1.42124
1917.1	-3.33723
1918.09	0.393387
1919.08	-2.43929
1920.08	0.413628
1921.07	-2.43999
1922.06	6.07143
1923.06	2.25799
1924.05	-1.56353
1925.04	4.06337
1926.04	-0.662861
1927.03	4.08185
1928.02	2.18612
1929.01	-0.666538
1930	3.12881
1931	-1.60334
1931.99	0.266109
1932.98	4.01563
1933.97	0.200935
1934.96	1.22729
1935.95	1.28006
1936.94	-3.54408
1937.93	1.16388
1938.92	-0.767292
1939.91	1.13202
1940.9	-1.72806
1941.89	-2.67708
1942.88	-4.59742
1943.87	1.08469
1944.86	-1.77859
1945.85	-0.815327
1946.84	3.00873
1947.83	0.110172
1948.82	-2.78655
1949.8	-0.87616
1950.79	2.02219
1951.78	-0.823128
1952.77	3.02326
1953.76	-0.837418
1954.74	-3.80799
1955.73	-0.972561
1956.72	-3.81629
1957.7	4.83689
1958.69	1.95206
1959.68	-2.88573
1960.66	-3.88367
1961.65	1.83207
1962.63	-2.98653
1963.62	-1.08189
1964.61	0.829407
1965.59	3.68604
1966.58	-3.0374
1967.56	-3.04125
1968.55	0.791218
1969.53	3.63598
1970.52	1.6552
1971.5	5.45295
1972.48	0.638786
1973.47	6.36869
1974.45	2.49181
1975.44	5.35456
1976.42	3.44164
1977.4	6.30682
1978.39	6.27086
1979.37	6.24321
1980.35	10.0672
1981.33	10.9873
1982.31	9.04186
1983.3	9.00217
1984.28	13.742
1985.26	11.7952
1986.24	12.7244
1987.22	14.6427
1988.21	12.6847
1989.19	16.3467
1990.17	15.1219
1991.15	12.9257
1992.13	14.8521
1993.11	12.8807
1994.09	14.6249
1995.07	17.8606
1996.05	18.8983
1997.03	18.9702
1998.01	19.0236
1998.99	22.1517
1999.97	17.0384
2000.95	22.2869
2001.92	16.1614
2002.9	21.0048
2003.88	21.6512
2004.86	21.7055
2005.84	21.2002
2006.81	19.1907
2007.79	24.7842
2008.77	18.4518
2009.75	21.323
2010.73	21.8981
2011.7	18.9672
2012.68	16.7245
2013.67	21.376
2014.66	18.4755
2015.64	21.277
2016.63	16.6145
2017.62	18.537
2018.61	18.4756
2019.6	18.4067
2020.58	17.4579
2021.57	18.4075
2022.56	14.6592
2023.55	14.6262
2024.54	10.8588
2025.52	15.4802
2026.51	12.6556
2027.5	16.5346
2028.48	13.689
2029.47	10.9743
2030.45	11.7866
2031.44	13.6909
2032.43	9.98386
2033.41	10.0591
2034.4	13.8226
2035.38	11.9026
2036.37	12.9572
2037.35	9.22418
2038.34	9.23362
2039.32	4.55785
2040.31	4.54789
2041.29	9.19588
2042.27	-0.120586
2043.26	4.54837
2044.24	7.41696
2045.23	10.2153
2046.21	8.46408
2047.19	4.71837
2048.17	3.76492
2049.16	3.80265
2050.14	3.87333
2051.12	5.79971
2052.11	4.87323
2053.09	1.18024
2054.07	1.24892
2055.05	3.16271
2056.03	4.11221
2057.01	5.06749
2058	5.1099
2058.98	2.36636
2059.96	1.48141
2060.94	6.18261
2061.92	4.36149
2062.9	3.46951
2063.88	-0.21991
2064.86	3.57964
2065.84	0.836853
2066.82	3.71261
2067.8	0.00906372
2068.78	3.82284
2069.76	-4.60527
2070.73	-1.7497
2071.71	-1.68956
2072.69	1.21931
2073.67	-2.5118
2074.65	-2.46314
2075.63	0.444748
2076.6	4.29913
2077.58	3.37962
2078.56	1.52726
2079.54	0.64563
2080.51	-3.05693
2081.49	0.765476
2082.47	0.809734
2083.45	-0.0860977
2084.42	-0.0432816
2085.4	0.948471
2086.37	4.78638
2087.35	-0.81554
2088.32	0.186039
2089.3	-0.708363
2090.28	-1.58728
2091.25	0.364937
2092.23	-3.35623
2093.2	-1.37358
2094.18	0.604523
2095.15	1.60976
2096.13	-3.11155
2097.1	0.729105
2098.07	-3.03938
2099.05	-1.09918
2100.02	-1.05451
2101	-0.999147
2101.97	-5.67959
2102.94	-0.883152
2103.92	1.99924
2104.89	0.156982
2105.86	-1.67153
2106.83	-3.50911
2107.8	-0.605049
2108.78	2.2644
2109.75	3.26494
2110.72	0.473091
2111.69	-1.37847
2112.66	-0.387041
2113.63	-2.21937
2114.61	-3.11447
2115.58	0.737717
2116.55	-3.02522
2117.52	-0.136026
2118.49	-3.89367
2119.46	-1.97268
2120.43	-3.83819
2121.4	0.0100918
2122.37	-0.86054
2123.34	0.156725
2124.31	2.10377
2125.28	-1.67957
2126.25	-2.61495
2127.21	1.19396
2128.18	-2.55025
2129.15	-3.44979
2130.12	0.374195
2131.09	-2.41893
2132.06	-3.32906
2133.02	0.479687
2133.99	-1.35926
2134.96	1.52282
2135.93	0.621738
2136.89	2.52801
2137.86	-1.18818
2138.83	0.735165
2139.79	2.67612
2140.76	1.75531
2141.73	-0.0885811
2142.69	-0.056221
2143.66	0.955338
2144.62	-1.87765
2145.59	-3.71027
2146.55	-0.84853
2147.52	0.1257
2148.48	2.03573
2149.45	2.06218
2150.42	0.196072
2151.38	-1.64115
2152.34	3.10555
2153.31	2.20129
2154.27	4.10296
2155.24	-2.45021
2156.2	-1.50766
2157.16	0.392931
2158.13	-1.42273
2159.09	-0.442484
2160.05	-0.417673
2161.01	0.530609
2161.98	1.49346
2162.94	1.53154
2163.9	-3.10466
2164.86	0.64377
2165.83	1.61364
2166.79	2.5772
2167.75	2.59218
2168.71	0.727232
2169.67	2.63434
2170.63	-2.87903
2171.59	1.80452
2172.56	0.86064
2173.51	-1.90241
2174.48	-0.931913
2175.44	-1.82704
2176.4	0.0585289
2177.36	-1.77534
2178.32	-1.74201
2179.28	-0.797604
2180.23	3.8774
2181.19	-0.739395
2182.15	2.99385
2183.11	2.08385
2184.07	-3.47613
2185.03	3.95684
2185.99	-0.638544
2186.95	1.26542
2187.9	2.25215
2188.86	-0.519535
2189.82	3.18689
2190.78	2.27151
2191.73	1.37515
2192.69	1.40856
2193.65	0.520538
2194.6	2.44251
2195.56	5.24985
2196.52	0.596184
2197.47	0.591261
2198.43	-0.316381
2199.38	3.44852
2200.34	4.44157
2201.3	2.65048
2202.25	-1.14398
2203.21	-2.01242
2204.16	-1.90595
2205.12	0.860657
2206.07	-0.119667
2207.03	5.47106
2207.98	1.78452
2208.93	-0.0399628
2209.89	3.70743
2210.84	0.0027256
2211.8	2.82927
2212.75	2.86089
2213.7	2.85988
2214.66	0.0866222
2215.61	0.114542
2216.56	-1.74106
2217.51	1.06628
2218.47	1.07728
2219.42	-3.57186
2220.37	-0.747875
2221.32	0.188833
2222.27	1.10496
2223.23	0.179714
2224.18	0.208794
2225.13	-2.56335
2226.08	4.02069
2227.03	0.301266
2227.98	-1.5551
2228.93	0.318058
2229.88	2.19869
2230.83	4.10439
2231.78	-0.561831
2232.73	-1.47882
2233.68	2.30534
2234.63	-4.27019
2235.58	0.417711
2236.53	0.41523
2237.48	-2.39596
2238.43	-4.24608
2239.38	-1.38883
2240.33	2.37214
2241.27	-1.3889
2242.22	-0.438938
2243.17	-1.37486
2244.12	-0.442335
2245.07	-0.431883
2246.01	-0.401909
2246.96	-0.385696
2247.91	0.570641
2248.85	1.50966
2249.8	0.561621
2250.75	-1.33887
2251.69	0.529886
2252.64	-0.411907
2253.59	0.570162
2254.53	-2.2521
2255.48	2.48806
2256.42	0.595524
2257.37	1.56025
2258.32	-0.3286
2259.26	-1.27285
2260.2	-1.26503
2261.15	0.644693
2262.1	3.51318
2263.04	-1.2347
2263.98	-3.11545
2264.93	-1.17668
2265.87	-1.16336
2266.81	-4.04373
2267.76	2.61336
2268.7	3.54564
2269.65	-5.02508
2270.59	-0.224583
2271.53	3.61561
2272.47	-1.15342
2273.42	-2.10854
2274.36	1.72225
2275.3	-3.0605
2276.24	-2.09984
2277.18	-1.12128
2278.13	-0.129774
2279.07	-3.95587
2280.01	-1.09508
2280.95	-4.95749
2281.89	0.781366
2282.83	-0.164293
2283.77	-2.05494
2284.71	-1.05381
2285.65	-2.96234
2286.59	-0.0914459
2287.54	-0.0621796
2288.47	-0.0496559
2289.41	1.85505
2290.35	2.78069
2291.29	-0.100763
2292.23	-1.03539
2293.17	4.76737
2294.11	0.929495
2295.05	-1.97352
2295.99	0.903208
2296.93	0.883045
2297.86	2.82886
2298.8	2.86117
2299.74	-2.89751
2300.68	-1.92792
2301.61	0.984488
2302.55	0.0224876
2303.49	0.988478
2304.43	-3.82632
2305.36	-1.87591
2306.3	1.03733
2307.24	-0.885876
2308.17	0.0772114
2309.11	-0.8871
2310.04	-0.858627
2310.98	0.122538
2311.92	0.0866547
2312.85	1.03268
2313.79	2.01168
2314.72	0.121662
2315.66	2.0789
2316.59	-0.849333
2317.52	-1.81906
2318.46	3.02014
2319.39	0.112051
2320.33	5.89884
2321.26	3.01797
2322.2	5.94745
2323.13	8.87382
2324.06	8.88828
2325	21.4497
2325.93	40.7146
2326.86	183.459
2327.79	254.636
2328.73	56.0243
2329.66	27.0778
2330.59	10.7024
2331.52	2.99485
2332.46	2.04151
2333.39	3.95046
2334.32	2.01173
2335.25	-2.81678
2336.18	0.0674896
2337.11	-1.86429
2338.04	0.0498466
2338.97	-1.88176
2339.91	0.0360184
2340.84	0.0150928
2341.77	-0.0246105
2342.7	0.904194
2343.63	4.72333
2344.56	0.876987
2345.49	-2.97477
2346.41	-2.05089
2347.34	-0.159239
2348.27	1.73683
2349.2	0.761749
2350.13	2.60974
2351.06	-0.40889
2351.99	0.625336
2352.91	-0.399302
2353.84	1.43597
2354.77	-0.502581
2355.7	-0.537968
2356.63	-0.596331
2357.55	-3.52412
2358.48	-2.63262
2359.41	-0.792976
2360.33	1.98819
2361.26	-0.940243
2362.19	-4.81637
2363.11	0.778645
2364.04	3.5343
2364.97	-4.11925