File: Data/3-Raman/processed/bu19w-a-ff07b-fi04-v_150 (500nm)_532nm_edge_100%_x100_vis_lwd_h50um_15sx2_01_0.txt
#Acq. time (s)=	15
#Accumulations=	2
#Range (cm-¹)=	50...5000
#Windows=	1
#Auto scanning=	Off
#Autofocus=	Off
#Macrospot=	Off
#AutoExposure=	Off
#Spike filter=	Multiple accum.
#Delay time (s)=	2
#Binning=	1
#Readout mode=	Signal
#DeNoise=	Off
#ICS correction=	On
#Dark correction=	Off
#Inst. Process=	Off
#Detector Gain=	Best Dynamic
#Detector ADC=	50 kHz HS
#Detector temperature (°C)=	-60.09
#Instrument=	LabRAM HR Evol
#Detector=	SIN-EM FIVIS
#Objective=	x100_VIS_LWD
#Grating=	150 (500nm)
#ND Filter=	100%
#Laser=	532nm_Edge
#Hole=	49.98
#Temperature=	0
#Range=	Visible
#StageXY=	75x50mm Scan+
#StageZ=	Z motor
#X (µm)=	0
#Y (µm)=	0
#Z (µm)=	-40.8
#Full time(s)=	34
#Project=	21_05_28
#Sample=	BU19w
#Site=
#Title=	BU19w-FF07b-FI04-S_150 (500nm)_532nm_Edge_100%_x100_VIS_LWD_H50um_15sX2
#Remark=
#Date=	28.05.2021 16:11
#Acquired=	28.05.2021 16:11:57
#Base:Fit=	16.12.2021 17:39:50
#Base:Sub=	16.12.2021 17:59:13
51.5961	18393.9
56.2453	14927.2
60.8921	11221.2
65.5367	11454.5
70.1768	13108.4
74.8167	7190.53
79.4543	3684.11
84.0897	2555.01
88.7227	1913.99
93.3513	1386.86
97.9798	1040.54
102.606	849.506
107.23	686.593
111.851	655.54
116.469	575.275
121.086	388.601
125.7	231.349
130.313	265.592
134.921	236.238
139.529	143.298
144.134	183.778
148.738	85.5232
153.337	0.0256348
157.936	61.016
162.532	390.598
167.126	1400.89
171.716	1531.81
176.306	533.915
180.894	203.58
185.477	332.295
190.06	1366.4
194.64	5108.97
199.219	5241.97
203.793	1860.45
208.367	428.909
212.939	98.4686
217.506	88.6179
222.073	81.319
226.638	53.2013
231.199	42.0342
235.759	155.477
240.318	575.195
244.872	724.496
249.425	1066.08
253.977	2119.37
258.524	1865.24
263.071	1324.83
267.616	797.665
272.156	590.668
276.697	888.548
281.233	2392.22
285.769	5472.98
290.303	5438.71
294.832	2742.24
299.361	1329.04
303.886	1259.56
308.411	2180.97
312.934	2918.08
317.452	1754.04
321.97	882.472
326.484	640.358
330.998	961.469
335.507	1647.51
340.017	1964.24
344.524	1116
349.027	705.998
353.53	965.529
358.028	1501.22
362.527	1258.22
367.021	698.328
371.515	410.801
376.004	537.565
380.494	584.33
384.979	364.883
389.465	415.886
393.946	681.075
398.427	992.295
402.903	1165.21
407.38	933.642
411.852	517.775
416.324	434.729
420.792	726.65
425.26	1373.05
429.723	987.072
434.187	297.524
438.646	33.8572
443.105	-0.204346
447.56	39.2936
452.015	112.158
456.466	325.884
460.914	1117.45
465.362	1653.13
469.807	961.236
474.251	384.701
478.69	173.375
483.13	159.303
487.566	207.667
491.999	390.172
496.432	561.191
500.861	761.108
505.29	862.281
509.715	730.193
514.138	509.134
518.56	392.186
522.979	264.191
527.395	193.115
531.811	165.016
536.223	183.409
540.635	208.801
545.042	197.04
549.448	225.899
553.853	280.127
558.255	324.304
562.654	319.913
567.053	341.16
571.448	327.385
575.841	247.697
580.232	190.109
584.622	218.851
589.009	454.217
593.393	1184.1
597.777	2197.41
602.157	1884.34
606.535	952.236
610.913	733.384
615.287	1085.17
619.659	1745.25
624.029	1490.04
628.398	777.654
632.763	390.678
637.127	173.251
641.488	210.008
645.849	368.699
650.206	435.391
654.561	364.147
658.914	322.132
663.267	310.717
667.615	527.87
671.962	768.428
676.307	851.457
680.649	922.642
684.991	1023.18
689.33	897.382
693.666	584.964
698	304.318
702.332	176.396
706.662	94.1352
710.992	56.1439
715.318	0.7901
719.641	28.6429
723.963	21.1837
728.283	50.5974
732.6	38.8496
736.918	26.879
741.231	55.8672
745.542	49.6679
749.852	43.837
754.159	62.4996
758.464	140.267
762.767	161.442
767.068	267.859
771.369	337.776
775.666	660.953
779.961	1116.78
784.254	1984.89
788.545	2379.55
792.834	1805.39
797.12	1065.85
801.405	611.114
805.688	385.983
809.968	270.34
814.247	196.676
818.524	130.868
822.798	123.316
827.071	74.2239
831.341	84.6424
835.612	58.7031
839.878	70.131
844.142	49.43
848.405	54.7883
852.665	26.4135
856.923	67.4993
861.18	61.1237
865.434	40.228
869.686	-0.788757
873.936	28.3419
878.185	31.8851
882.431	18.7408
886.675	30.3163
890.915	52.0884
895.155	29.8652
899.393	49.6956
903.63	56.6308
907.864	70.7288
912.096	50.9904
916.326	57.8904
920.554	49.4169
924.78	96.575
929.004	70.8777
933.227	77.7172
937.447	115.515
941.665	157.155
945.881	218.802
950.095	316.474
954.305	472.803
958.516	582.022
962.724	571.041
966.93	525.199
971.134	622.87
975.337	704.798
979.537	641.674
983.735	452.905
987.93	298.127
992.124	262.108
996.316	185.735
1000.51	200.091
1004.7	191.388
1008.88	169.027
1013.06	164.714
1017.25	159.007
1021.43	212.979
1025.61	221.94
1029.78	299.864
1033.96	265.227
1038.13	345.603
1042.3	434.539
1046.47	571.008
1050.63	865.813
1054.8	1610.59
1058.96	2709.78
1063.12	3153.61
1067.28	2266.55
1071.44	1482.93
1075.59	1026.87
1079.74	915.265
1083.89	1013.48
1088.04	1452.6
1092.19	2253.41
1096.33	3284.02
1100.48	3629.7
1104.62	2926.16
1108.76	2225.19
1112.89	2226.84
1117.03	2608.25
1121.16	2655.12
1125.29	2266
1129.42	2069.16
1133.55	2123.4
1137.68	2319.49
1141.8	2417.37
1145.92	1997.6
1150.04	1483.81
1154.16	1202.48
1158.27	1337.8
1162.39	1857.62
1166.5	2384.8
1170.61	2074.15
1174.72	1503.99
1178.82	1121.73
1182.93	832.694
1187.03	597.12
1191.13	494.671
1195.23	440.25
1199.33	417.223
1203.42	393.911
1207.51	426.447
1211.6	450.745
1215.69	355.797
1219.78	303.792
1223.86	348.704
1227.95	569.179
1232.03	704.297
1236.11	624.454
1240.18	569.683
1244.26	670.391
1248.33	938.379
1252.41	902.896
1256.48	619.105
1260.54	489.221
1264.61	336.386
1268.67	256.661
1272.74	236.115
1276.8	490.479
1280.86	1475.68
1284.91	801.315
1288.97	273.411
1293.02	154.421
1297.07	171.103
1301.12	194.727
1305.17	131.436
1309.21	124.487
1313.25	149.648
1317.3	165.275
1321.34	137.313
1325.37	116.968
1329.41	130.674
1333.44	131.153
1337.48	104.158
1341.5	101.045
1345.53	151.729
1349.56	110.484
1353.59	143.041
1357.61	127.854
1361.63	114.594
1365.65	152.072
1369.66	192.588
1373.68	179.992
1377.69	185.371
1381.7	1110.98
1385.72	2120.96
1389.72	646.482
1393.73	199.509
1397.73	134.962
1401.74	158.914
1405.74	278.413
1409.73	200.006
1413.73	127.57
1417.73	90.5988
1421.72	63.443
1425.71	102.271
1429.7	74.3214
1433.69	59.3188
1437.67	51.1978
1441.66	95.4209
1445.64	83.1725
1449.62	84.6714
1453.6	63.2671
1457.57	83.1667
1461.55	89.0223
1465.52	42.3146
1469.49	60.507
1473.46	36.5969
1477.43	73.3903
1481.39	64.8666
1485.36	43.5542
1489.32	39.7949
1493.28	74.1888
1497.24	50.0361
1501.19	56.2432
1505.15	55.8342
1509.1	65.4774
1513.05	58.6792
1517	62.63
1520.95	71.559
1524.9	57.2804
1528.84	28.5586
1532.78	59.132
1536.72	0.551147
1540.66	61.2224
1544.6	48.2355
1548.53	44.9443
1552.46	69.743
1556.4	29.4885
1560.32	51.0342
1564.25	41.4568
1568.18	53.0381
1572.1	35.5172
1576.02	24.7561
1579.94	40.0104
1583.86	101.488
1587.78	55.8235
1591.69	54.4808
1595.61	58.8824
1599.52	28.6841
1603.43	41.8354
1607.34	64.7472
1611.24	42.5907
1615.15	91.463
1619.05	76.2805
1622.95	29.4316
1626.85	48.8569
1630.74	40.6783
1634.64	48.2112
1638.53	32.7041
1642.42	29.0035
1646.31	33.219
1650.2	26.0546
1654.09	63.077
1657.97	44.3528
1661.86	47.6499
1665.74	89.15
1669.62	68.047
1673.49	10.9669
1677.37	35.5266
1681.24	44.9851
1685.12	22.4327
1688.99	56.3854
1692.86	44.0248
1696.72	52.5514
1700.59	71.3406
1704.45	15.4203
1708.31	36.5154
1712.17	56.3052
1716.03	47.5861
1719.89	35.1655
1723.74	70.0089
1727.6	36.7783
1731.45	62.6769
1735.3	58.5571
1739.14	13.1335
1742.99	29.3534
1746.83	57.6621
1750.68	46.6699
1754.52	58.442
1758.36	20.8423
1762.19	50.2977
1766.03	33.3586
1769.86	46.6216
1773.69	40.0724
1777.53	49.3722
1781.35	71.2522
1785.18	35.5367
1789	27.9025
1792.83	36.2294
1796.65	25.85
1800.47	41.6968
1804.29	52.9924
1808.1	42.5464
1811.92	63.9813
1815.73	37.1034
1819.54	46.4312
1823.35	58.2527
1827.16	24.5448
1830.97	16.9052
1834.77	33.4366
1838.58	7.36133
1842.38	-0.0561523
1846.18	42.0118
1849.97	76.6322
1853.77	64.6318
1857.56	82.238
1861.36	34.9818
1865.15	15.6989
1868.93	33.7675
1872.72	31.5071
1876.51	45.2396
1880.29	50.7031
1884.07	65.9285
1887.86	37.897
1891.63	45.4744
1895.41	56.7642
1899.19	24.8083
1902.96	33.9146
1906.73	12.9012
1910.5	68.4609
1914.27	28.7094
1918.04	64.6638
1921.8	14.6801
1925.57	60.9817
1929.33	30.6715
1933.09	18.9652
1936.85	37.9297
1940.6	67.1974
1944.36	61.9359
1948.11	50.0898
1951.87	39.9552
1955.61	45.2236
1959.36	31.0079
1963.11	52.0364
1966.86	23.2131
1970.6	44.6683
1974.34	25.2683
1978.08	62.7754
1981.82	55.0479
1985.56	34.9497
1989.29	40.8743
1993.02	20.4744
1996.75	19.3981
2000.49	27.3394
2004.21	56.6069
2007.94	37.5475
2011.67	41.2821
2015.39	26.6504
2019.11	38.4335
2022.83	16.0681
2026.55	11.9739
2030.27	90.3274
2033.98	21.9491
2037.69	17.2048
2041.41	62.6959
2045.12	37.582
2048.82	30.8127
2052.53	27.9794
2056.24	41.717
2059.94	37.8568
2063.64	5.46936
2067.34	42.2957
2071.04	12.1088
2074.74	-3.39343
2078.43	64.3831
2082.13	25.0465
2085.82	-3.47375
2089.51	41.5688
2093.2	78.5906
2096.88	28.9563
2100.57	30.1683
2104.25	62.5378
2107.94	11.8865
2111.62	29.849
2115.3	38.467
2118.97	54.3347
2122.65	9.26257
2126.32	16.8514
2129.99	70.5376
2133.66	61.9548
2137.33	65.3125
2141	67.4926
2144.67	35.3513
2148.33	34.494
2151.99	35.4515
2155.66	30.0442
2159.31	40.2661
2162.97	22.3015
2166.63	31.0778
2170.28	56.4908
2173.94	39.6447
2177.59	77.7635
2181.24	55.0752
2184.89	72.3694
2188.53	30.0238
2192.18	65.5566
2195.82	73.5089
2199.46	54.4711
2203.1	51.0746
2206.74	70.7329
2210.38	81.5541
2214.01	61.4916
2217.65	89.1356
2221.28	84.7659
2224.91	79.5515
2228.54	79.7524
2232.16	35.7135
2235.79	42.4961
2239.41	58.5198
2243.04	83.8395
2246.66	106.401
2250.28	116.095
2253.89	81.2793
2257.51	106.216
2261.12	25.5658
2264.74	15.6469
2268.35	64.019
2271.96	66.856
2275.57	13.7455
2279.17	67.5839
2282.78	27.131
2286.38	43.2684
2289.98	36.7313
2293.58	47.0176
2297.18	28.0332
2300.78	26.131
2304.37	48.6199
2307.97	54.7107
2311.56	26.476
2315.15	53.9506
2318.74	87.8062
2322.33	72.9911
2325.91	219.116
2329.5	151.13
2333.08	62.3331
2336.66	54.6644
2340.24	35.5223
2343.82	64.2272
2347.4	61.6821
2350.97	60.9153
2354.54	57.2754
2358.12	76.8851
2361.69	33.9319
2365.26	62.6864
2368.82	42.2716
2372.39	49.1523
2375.95	44.8033
2379.52	101.413
2383.08	39.1912
2386.64	40.7849
2390.19	40.7946
2393.75	68.6375
2397.31	67.5486
2400.86	40.4038
2404.41	63.5852
2407.96	73.2183
2411.51	54.1638
2415.06	45.5483
2418.6	73.1282
2422.15	21.8864
2425.69	38.1371
2429.23	64.0583
2432.77	35.8146
2436.31	74.5354
2439.84	57.8467
2443.38	54.2465
2446.91	71.2118
2450.44	71.7438
2453.97	50.0222
2457.5	81.7701
2461.03	8.6991
2464.55	13.5834
2468.08	36.1021
2471.6	61.7721
2475.12	42.4648
2478.64	32.3983
2482.16	39.5588
2485.67	40.5049
2489.19	30.183
2492.7	26.3481
2496.21	66.7108
2499.72	79.4083
2503.23	48.5355
2506.74	53.9349
2510.25	109.314
2513.75	50.1783
2517.25	78.9304
2520.75	65.2043
2524.25	72.6908
2527.75	48.4127
2531.25	53.2141
2534.74	63.7797
2538.24	86.7914
2541.73	41.8894
2545.22	-0.437012
2548.71	83.4431
2552.2	19.6428
2555.68	68.1069
2559.17	41.459
2562.65	31.4722
2566.13	42.5831
2569.61	61.6844
2573.09	26.1364
2576.57	28.1914
2580.04	50.2924
2583.51	39.6217
2586.99	46.8572
2590.46	89.7985
2593.93	48.4833
2597.4	77.2483
2600.86	46.4359
2604.33	69.9137
2607.79	42.7285
2611.25	44.9197
2614.71	60.4851
2618.17	57.4292
2621.63	31.6372
2625.09	36.3021
2628.54	4.06384
2631.99	92.5986
2635.45	53.0382
2638.9	112.79
2642.34	50.5413
2645.79	58.9111
2649.24	53.7955
2652.68	32.1481
2656.12	51.0978
2659.56	40.2396
2663.01	53.8926
2666.44	50.3384
2669.88	67.5095
2673.32	65.7189
2676.75	38.8674
2680.18	62.9215
2683.61	44.2454
2687.04	44.8427
2690.47	74.3982
2693.9	72.7886
2697.32	110.906
2700.75	73.0381
2704.17	88.2898
2707.59	50.6041
2711.01	35.3934
2714.43	64.2317
2717.84	44.9984
2721.26	63.3196
2724.67	89.3491
2728.08	10.0278
2731.49	58.7295
2734.9	80.3163
2738.31	47.6057
2741.71	38.2136
2745.12	70.7683
2748.52	47.7274
2751.92	103.669
2755.32	85.2255
2758.72	88.2498
2762.12	80.9524
2765.52	97.7444
2768.91	81.3268
2772.3	40.1582
2775.7	64.83
2779.09	43.0818
2782.47	43.746
2785.86	70.6537
2789.25	79.6201
2792.63	62.209
2796.01	64.5093
2799.4	31.1404
2802.78	83.8865
2806.15	45.6588
2809.53	61.785
2812.91	64.7084
2816.28	90.9191
2819.65	58.2189
2823.03	68.7534
2826.4	100.012
2829.76	79.1595
2833.13	47.3655
2836.5	53.1444
2839.86	53.6023
2843.22	85.1104
2846.59	59.2306
2849.95	53.4646
2853.3	70.4512
2856.66	28.4324
2860.02	27.6971
2863.37	96.4335
2866.72	82.9069
2870.08	19.6292
2873.43	100.796
2876.77	58.8932
2880.12	87.4775
2883.47	85.9163
2886.81	43.6763
2890.15	82.5209
2893.5	69.3832
2896.84	29.3966
2900.17	76.178
2903.51	92.4893
2906.85	30.0901
2910.18	90.5726
2913.52	55.3818
2916.85	33.3428
2920.18	65.02
2923.51	87.1521
2926.83	57.1415
2930.16	67.5818
2933.48	94.8395
2936.81	58.6211
2940.13	71.4948
2943.45	58.9259
2946.77	111.389
2950.09	91.3982
2953.4	96.7687
2956.72	39.2584
2960.03	72.1968
2963.34	63.0172
2966.65	91.4668
2969.96	86.6058
2973.27	65.1396
2976.58	66.2523
2979.88	59.171
2983.19	74.4445
2986.49	80.4375
2989.79	84.6521
2993.09	79.5337
2996.39	82.9584
2999.68	33.8313
3002.98	65.5249
3006.27	66.2111
3009.57	37.844
3012.86	38.7247
3016.15	115.029
3019.43	58.446
3022.72	41.4043
3026.01	72.4922
3029.29	19.5946
3032.57	42.2052
3035.86	62.8818
3039.14	43.8212
3042.41	27.5989
3045.69	71.0332
3048.97	47.2841
3052.24	50.9946
3055.52	45.2751
3058.79	40.4424
3062.06	34.2024
3065.33	58.5448
3068.6	25.7808
3071.86	90.4589
3075.13	-11.177
3078.39	68.8389
3081.65	27.0336
3084.91	39.5498
3088.17	19.7411
3091.43	43.9955
3094.69	37.0035
3097.95	65.2766
3101.2	42.1833
3104.45	49.248
3107.7	33.2018
3110.95	46.4503
3114.2	34.5046
3117.45	54.1046
3120.7	19.4747
3123.94	58.1785
3127.18	8.27637
3130.43	35.5021
3133.67	22.7355
3136.91	19.4603
3140.14	6.58252
3143.38	20.3832
3146.61	16.0834
3149.85	10.9247
3153.08	59.2068
3156.31	-0.342163
3159.54	12.6407
3162.77	55.1658
3166	12.7766
3169.22	36.1078
3172.45	18.308
3175.67	4.27466
3178.89	40.701
3182.11	53.2555
3185.33	59.1624
3188.55	4.83948
3191.77	68.7128
3194.98	60.1282
3198.2	48.6746
3201.41	20.0627
3204.62	54.3655
3207.83	49.6799
3211.04	13.6656
3214.25	64.3405
3217.45	43.7538
3220.66	80.2538
3223.86	8.36426
3227.06	55.5209
3230.26	50.3955
3233.46	15.8768
3236.66	32.6522
3239.85	40.2172
3243.05	36.4398
3246.24	52.7358
3249.44	59.5248
3252.63	48.3395
3255.82	55.3088
3259.01	60.3505
3262.19	49.9205
3265.38	50.7546
3268.56	38.0254
3271.75	40.448
3274.93	57.1212
3278.11	79.5052
3281.29	54.8068
3284.47	42.2926
3287.64	51.7646
3290.82	43.9537
3293.99	83.9205
3297.17	53.3043
3300.34	76.0684
3303.51	68.6693
3306.68	74.2476
3309.84	74.937
3313.01	96.3224
3316.18	66.3257
3319.34	68.6046
3322.5	76.5206
3325.66	89.177
3328.82	41.2686
3331.98	92.7463
3335.14	83.7834
3338.29	65.5142
3341.45	87.9398
3344.6	107.552
3347.75	113.354
3350.9	70.4769
3354.05	81.3174
3357.2	63.0935
3360.35	124.121
3363.49	113.68
3366.64	95.7233
3369.78	123.11
3372.92	120.379
3376.06	117.809
3379.2	106.798
3382.34	126.079
3385.48	154.77
3388.61	143.881
3391.75	216.291
3394.88	215.79
3398.01	224.391
3401.14	288.811
3404.27	322.162
3407.4	354.775
3410.52	504.513
3413.65	696.399
3416.77	1041.57
3419.89	1920.11
3423.01	4515
3426.13	10163.1
3429.25	12249
3432.37	6822.89
3435.49	2907.23
3438.6	1390.82
3441.72	831.713
3444.83	586.682
3447.94	429.182
3451.05	321.344
3454.16	314.386
3457.26	251.219
3460.37	241.217
3463.47	281.59
3466.58	216.38
3469.68	221.301
3472.78	261.983
3475.88	255.685
3478.98	321.401
3482.07	378.578
3485.17	420.595
3488.26	523.111
3491.36	674.861
3494.45	856.266
3497.54	1109.21
3500.63	1552.38
3503.72	2093.39
3506.81	2852.1
3509.89	3333.12
3512.98	3346.23
3516.06	2678.18
3519.14	1950.48
3522.22	1394.9
3525.3	994.644
3528.38	744.287
3531.45	543.69
3534.53	480.454
3537.61	350.346
3540.68	307.278
3543.75	250.683
3546.82	224.989
3549.89	197.429
3552.96	173.269
3556.03	153.693
3559.09	150.407
3562.16	131.968
3565.22	106.606
3568.28	116.093
3571.34	102.289
3574.4	92.6062
3577.46	85.8226
3580.52	80.8311
3583.57	72.8927
3586.63	82.8572
3589.68	66.2596
3592.73	82.6937
3595.78	83.924
3598.83	70.8284
3601.88	103.204
3604.93	56.8444
3607.97	45.448
3611.02	45.4014
3614.06	56.6312
3617.1	42.302
3620.14	47.8654
3623.18	91.2102
3626.22	7.26343
3629.26	62.0054
3632.3	88.3668
3635.33	56.2727
3638.36	49.9104
3641.4	54.0609
3644.43	43.2919
3647.46	29.9989
3650.49	29.5548
3653.51	20.8038
3656.54	46.3225
3659.57	46.1937
3662.59	24.2876
3665.61	31.3392
3668.63	38.8064
3671.65	32.4028
3674.67	20.3871
3677.69	18.8041
3680.71	27.6702
3683.72	50.6564
3686.74	41.5286
3689.75	29.585
3692.76	47.955
3695.77	3.81934
3698.78	21.0328
3701.79	24.2755
3704.79	41.7582
3707.8	46.899
3710.81	11.9867
3713.81	25.4471
3716.81	44.4851
3719.81	40.7745
3722.81	27.3975
3725.81	43.4346
3728.81	30.8036
3731.8	19.9951
3734.8	22.4071
3737.79	40.8806
3740.78	39.257
3743.77	16.564
3746.76	45.1581
3749.75	37.4904
3752.74	48.7471
3755.73	34.3416
3758.71	43.7012
3761.7	16.9875
3764.68	17.6975
3767.66	4.23157
3770.64	30.608
3773.62	26.7936
3776.6	52.3678
3779.58	-10.8369
3782.55	23.3668
3785.53	13.1813
3788.5	34.2162
3791.47	40.2084
3794.44	64.3042
3797.41	41.2963
3800.38	12.6869
3803.35	15.3663
3806.32	38.8792
3809.28	42.5958
3812.24	34.0936
3815.21	23.7179
3818.17	32.2772
3821.13	45.6183
3824.09	1.23865
3827.04	44.046
3830	46.1481
3832.96	59.6265
3835.91	36.2057
3838.86	38.4506
3841.82	40.6956
3844.77	29.6141
3847.72	49.0001
3850.67	15.1049
3853.61	55.5869
3856.56	15.0344
3859.5	51.7928
3862.45	27.4338
3865.39	23.0615
3868.33	26.3376
3871.27	7.4856
3874.21	20.2229
3877.15	47.3248
3880.09	18.6403
3883.02	67.6331
3885.96	21.3892
3888.89	1.95483
3891.82	35.3508
3894.75	17.7377
3897.68	18.2609
3900.61	70.5949
3903.54	15.1962
3906.47	20.2533
3909.39	26.3895
3912.31	42.0361
3915.24	13.3814
3918.16	51.9065
3921.08	28.1818
3924	40.7419
3926.92	43.5813
3929.83	53.0313
3932.75	45.1782
3935.67	35.664
3938.58	30.1958
3941.49	31.6131
3944.4	56.8713
3947.31	35.2697
3950.22	49.1955
3953.13	57.4515
3956.04	42.7673
3958.94	12.84
3961.85	37.5615
3964.75	22.0845
3967.65	15.2818
3970.55	21.9534
3973.45	39.2162
3976.35	44.9459
3979.25	30.4367
3982.15	14.8879
3985.04	32.9568
3987.94	14.4448
3990.83	25.7062
3993.72	35.8922
3996.61	14.5113
3999.5	46.037
4002.39	39.1184
4005.28	20.6516
4008.16	35.9419
4011.05	25.2288
4013.93	-1.90204
4016.81	24.9755
4019.7	55.7328
4022.58	36.3033
4025.46	19.7592
4028.33	34.1405
4031.21	36.9379
4034.09	41.6964
4036.96	35.8248
4039.84	47.4141
4042.71	52.2043
4045.58	33.5782
4048.45	67.3242
4051.32	39.0941
4054.19	58.4225
4057.05	35.1588
4059.92	24.4537
4062.78	39.9338
4065.65	40.851
4068.51	54.4047
4071.37	61.1432
4074.23	29.915
4077.09	62.9155
4079.95	24.8046
4082.81	29.5471
4085.66	8.94464
4088.52	15.5923
4091.37	15.4119
4094.22	39.7064
4097.07	28.7791
4099.92	21.8044
4102.77	51.9504
4105.62	10.6909
4108.47	37.7726
4111.31	45.3109
4114.16	53.7188
4117	45.3935
4119.84	30.0827
4122.69	44.1466
4125.53	30.9216
4128.36	23.5902
4131.2	41.9575
4134.04	31.0911
4136.88	25.3928
4139.71	36.1875
4142.54	3.10217
4145.38	7.3855
4148.21	23.7702
4151.04	16.7394
4153.87	15.3751
4156.69	58.7294
4159.52	31.2009
4162.35	33.3739
4165.17	25.883
4168	16.425
4170.82	-2.7677
4173.64	16.231
4176.46	35.2529
4179.28	-0.488342
4182.1	36.213
4184.91	21.1116
4187.73	55.9502
4190.54	52.6637
4193.36	28.9611
4196.17	67.0289
4198.98	44.5159
4201.79	61.1597
4204.6	59.2235
4207.41	59.2081
4210.22	53.3179
4213.02	74.9037
4215.83	42.4214
4218.63	81.2914
4221.44	68.9392
4224.24	47.5966
4227.04	37.9409
4229.84	45.2211
4232.64	25.8286
4235.43	18.3865
4238.23	51.6432
4241.02	46.2671
4243.82	18.023
4246.61	66.4354
4249.4	57.0814
4252.19	32.6394
4254.98	96.0781
4257.77	47.4887
4260.56	22.8234
4263.35	39.2617
4266.13	59.7838
4268.92	28.1329
4271.7	36.6532
4274.48	17.9514
4277.26	17.1963
4280.04	40.5526
4282.82	60.8531
4285.6	40.6392
4288.38	28.3848
4291.15	11.9761
4293.93	8.68182
4296.7	54.1326
4299.47	34.8184
4302.25	29.6017
4305.02	45.6808
4307.79	27.2497
4310.55	43.3815
4313.32	10.8135
4316.09	31.9824
4318.85	32.7407
4321.62	23.2626
4324.38	4.54791
4327.14	12.2615
4329.9	3.71088
4332.66	13.4043
4335.42	37.4142
4338.18	12.4371
4340.94	46.7192
4343.69	12.7181
4346.45	38.9496
4349.2	32.6273
4351.95	37.5308
4354.7	22.2305
4357.45	16.0151
4360.2	25.1342
4362.95	36.2609
4365.7	30.0703
4368.44	23.799
4371.19	22.7274
4373.93	33.8196
4376.68	58.248
4379.42	8.68976
4382.16	41.2551
4384.9	17.3755
4387.64	33.7499
4390.37	7.22607
4393.11	31.2664
4395.85	40.5031
4398.58	-2.53741
4401.31	23.6487
4404.05	25.9711
4406.78	31.4507
4409.51	24.5066
4412.24	13.2903
4414.96	34.2124
4417.69	30.1263
4420.42	33.0067
4423.14	34.9997
4425.87	21.3779
4428.59	55.8026
4431.31	42.1768
4434.03	28.5115
4436.75	36.7772
4439.47	46.0602
4442.19	10.1976
4444.91	-5.75708
4447.62	43.2863
4450.34	32.532
4453.05	42.7054
4455.76	-2.81299
4458.47	29.343
4461.19	20.4846
4463.89	10.6651
4466.6	1.87091
4469.31	53.1024
4472.02	18.0704
4474.72	13.6187
4477.43	0.791687
4480.13	30.1982
4482.83	32.2416
4485.53	24.773
4488.23	24.6326
4490.93	15.9963
4493.63	61.1509
4496.33	6.69391
4499.02	23.2947
4501.72	37.7458
4504.41	47.9067
4507.11	39.0628
4509.8	33.4147
4512.49	7.60101
4515.18	50.7853
4517.87	18.6179
4520.56	36.3926
4523.24	28.7415
4525.93	13.6271
4528.61	42.1306
4531.3	53.644
4533.98	32.1414
4536.66	38.366
4539.34	11.5286
4542.02	26.3593
4544.7	37.993
4547.38	52.8784
4550.05	26.0226
4552.73	24.9139
4555.4	8.89215
4558.08	0.451599
4560.75	37.3823
4563.42	9.86255
4566.09	27.8201
4568.76	15.7099
4571.43	34.5874
4574.1	24.5195
4576.77	52.1579
4579.43	33.4448
4582.1	24.7727
4584.76	51.0437
4587.42	-11.3074
4590.08	3.63873
4592.74	38.1712
4595.4	26.9365
4598.06	17.9458
4600.72	17.6201
4603.38	29.4523
4606.03	12.8718
4608.69	9.41772
4611.34	20.2269
4613.99	29.9285
4616.64	-3.22906
4619.29	21.8895
4621.94	3.03839
4624.59	24.906
4627.24	22.4861
4629.89	18.9252
4632.53	15.3302
4635.18	35.9591
4637.82	4.56512
4640.46	18.5099
4643.1	20.2943
4645.74	32.2036
4648.38	30.9807
4651.02	4.35132
4653.66	17.936
4656.3	26.8186
4658.93	25.0003
4661.57	37.0266
4664.2	-2.20044
4666.83	10.9514
4669.46	19.5026
4672.09	10.2001
4674.72	28.8809
4677.35	2.71881
4679.98	16.9049
4682.61	32.2147
4685.23	17.1959
4687.86	25.7719
4690.48	16.3552
4693.1	30.5855
4695.73	13.2142
4698.34	5.95837
4700.96	30.309
4703.58	16.2622
4706.2	12.3124
4708.82	21.9047
4711.43	29.2178
4714.05	3.70172
4716.66	25.6923
4719.28	26.1464
4721.89	17.5096
4724.5	6.56805
4727.11	14.9733
4729.72	31.3613
4732.33	47.7659
4734.93	26.7057
4737.54	34.0035
4740.14	48.0893
4742.75	0.749268
4745.35	20.4447
4747.95	20.7617
4750.55	17.5788
4753.15	25.7911
4755.75	33.9897
4758.35	13.7278
4760.95	0.341797
4763.54	49.6179
4766.14	8.96527
4768.73	32.2265
4771.33	25.9056
4773.92	45.6959
4776.51	38.1162
4779.1	25.9613
4781.69	26.3502
4784.28	19.8833
4786.87	52.2916
4789.45	25.2394
4792.04	33.6606
4794.63	47.8365
4797.21	44.8572
4799.79	16.7026
4802.37	44.7675
4804.95	26.98
4807.53	11.5259
4810.11	32.9012
4812.69	24.3578
4815.27	28.507
4817.84	9.60657
4820.42	30.0012
4822.99	31.9176
4825.57	16.4592
4828.14	6.74683
4830.71	0.497925
4833.28	23.3643
4835.85	26.5035
4838.42	20.3772
4840.98	24.7911
4843.55	-9.44119
4846.12	31.1534
4848.68	36.5784
4851.24	21.8666
4853.81	34.9869
4856.37	1.17566
4858.93	14.8883
4861.49	54.544
4864.05	17.396
4866.61	17.8021
4869.16	12.3255
4871.72	29.4388
4874.27	44.0838
4876.83	25.4868
4879.38	16.3484
4881.93	16.6599
4884.49	34.7556
4887.04	18.392
4889.58	11.5323
4892.13	17.754
4894.68	40.6302
4897.23	24.1923
4899.77	29.1749
4902.32	11.4868
4904.86	12.8639
4907.4	2.27777
4909.95	20.3252
4912.49	22.7393
4915.03	21.5302
4917.57	15.4912
4920.1	17.8674
4922.64	-0.0713806
4925.18	22.6157
4927.71	29.8061
4930.25	14.2217
4932.78	28.6501
4935.31	15.6703
4937.84	27.7498
4940.38	42.2227
4942.9	37.3175
4945.43	34.9931
4947.96	37.538
4950.49	22.0852
4953.01	-0.537506
4955.54	39.1389
4958.06	15.3274
4960.59	25.1543
4963.11	15.8054
4965.63	35.4489
4968.15	20.2872
4970.67	26.656
4973.19	42.6682
4975.71	20.0336
4978.22	14.2748
4980.74	29.1004
4983.25	33.0533
4985.77	17.6298
4988.28	0.971741
4990.79	35.3114
4993.3	12.5437
4995.81	17.7129
4998.32	31.4986