File: Data/3-Raman/processed/bu19w-d-ore2-fi01-v_150 (500nm)_532nm_edge_100%_x100_vis_lwd_h50um_15sx2_01_0.txt
#Acq. time (s)=	15
#Accumulations=	2
#Range (cm-¹)=	50...5000
#Windows=	1
#Auto scanning=	Off
#Autofocus=	Off
#Macrospot=	Off
#AutoExposure=	Off
#Spike filter=	Multiple accum.
#Delay time (s)=	2
#Binning=	1
#Readout mode=	Signal
#DeNoise=	Off
#ICS correction=	On
#Dark correction=	Off
#Inst. Process=	Off
#Detector Gain=	Best Dynamic
#Detector ADC=	50 kHz HS
#Detector temperature (°C)=	-60.09
#Instrument=	LabRAM HR Evol
#Detector=	SIN-EM FIVIS
#Objective=	x100_VIS_LWD
#Grating=	150 (500nm)
#ND Filter=	100%
#Laser=	532nm_Edge
#Hole=	49.98
#Temperature=	0
#Range=	Visible
#StageXY=	75x50mm Scan+
#StageZ=	Z motor
#X (µm)=	0
#Y (µm)=	0
#Z (µm)=	-51.5
#Full time(s)=	34
#Project=	21_05_28
#Sample=
#Site=
#Title=	BU19w-FF-ore2-FI01-V_150 (500nm)_532nm_Edge_100%_x100_VIS_LWD_H50um_15sX2
#Remark=
#Date=	28.05.2021 14:40
#Acquired=	28.05.2021 14:40:49
#Base:Fit=	16.12.2021 17:39:50
#Base:Sub=	16.12.2021 18:01:18
51.5961	3441.22
56.2453	3621.74
60.8921	3516.21
65.5367	2872.73
70.1768	2076.32
74.8167	1486.86
79.4543	1026.04
84.0897	733.566
88.7227	537.521
93.3513	333.599
97.9798	237.651
102.606	110.436
107.23	59.3778
111.851	31.0968
116.469	1.64148
121.086	121.545
125.7	652.271
130.313	1365.18
134.921	930.838
139.529	262.291
144.134	84.5778
148.738	66.5022
153.337	23.5587
157.936	9.92969
162.532	-2.71051
167.126	34.5459
171.716	102.054
176.306	182.748
180.894	241.142
185.477	406.86
190.06	610.157
194.64	1040.64
199.219	1594.33
203.793	2172.01
208.367	2643.9
212.939	2573.6
217.506	1997.9
222.073	1384.01
226.638	949.433
231.199	669.583
235.759	460.396
240.318	318.131
244.872	238.998
249.425	216.915
253.977	216.428
258.524	185.251
263.071	338.647
267.616	455.099
272.156	298.105
276.697	133.933
281.233	34.2067
285.769	38.9202
290.303	17.376
294.832	27.5692
299.361	24.2997
303.886	1.33972
308.411	44.8348
312.934	23.1382
317.452	29.2318
321.97	39.6527
326.484	23.6545
330.998	23.2285
335.507	8.91296
340.017	51.082
344.524	54.3937
349.027	62.8201
353.53	222.831
358.028	490.364
362.527	416.218
367.021	179.304
371.515	111.176
376.004	73.2963
380.494	114.917
384.979	94.8982
389.465	63.2157
393.946	115.971
398.427	191.989
402.903	182.443
407.38	222.145
411.852	108.015
416.324	124.001
420.792	151.041
425.26	141.043
429.723	147.093
434.187	146.193
438.646	227.135
443.105	266
447.56	429.859
452.015	732.792
456.466	1364.67
460.914	3481.3
465.362	7744.31
469.807	8482.34
474.251	4666.88
478.69	2021.71
483.13	1145.18
487.566	785.05
491.999	598.809
496.432	468.634
500.861	374.674
505.29	313.986
509.715	321.381
514.138	361.085
518.56	340.613
522.979	259.261
527.395	260.206
531.811	189.633
536.223	180.504
540.635	174.842
545.042	169.089
549.448	162.19
553.853	152.789
558.255	131.157
562.654	125.682
567.053	131.587
571.448	114.773
575.841	125.711
580.232	128.889
584.622	124.291
589.009	107.962
593.393	115.83
597.777	121.87
602.157	126.941
606.535	111.092
610.913	129.423
615.287	120.698
619.659	146.882
624.029	80.0675
628.398	111.468
632.763	101.695
637.127	100.684
641.488	119.558
645.849	142.671
650.206	85.368
654.561	70.9808
658.914	110.34
663.267	81.9653
667.615	61.2972
671.962	68.7885
676.307	93.9207
680.649	62.658
684.991	81.7544
689.33	59.3176
693.666	93.3541
698	116.887
702.332	101.487
706.662	81.5546
710.992	74.4871
715.318	65.9994
719.641	45.3212
723.963	62.4397
728.283	53.3566
732.6	72.0039
736.918	54.3224
741.231	93.4377
745.542	40.8936
749.852	87.0341
754.159	39.1162
758.464	30.3816
762.767	38.5281
767.068	66.1414
771.369	68.5673
775.666	66.0696
779.961	49.11
784.254	98.9884
788.545	119.78
792.834	133.126
797.12	157.835
801.405	192.969
805.688	247.691
809.968	336.976
814.247	319.835
818.524	152.234
822.798	130.891
827.071	75.7548
831.341	76.8582
835.612	94.5353
839.878	85.6958
844.142	76.7303
848.405	67.3478
852.665	84.8815
856.923	60.526
861.18	54.9072
865.434	61.2046
869.686	61.6232
873.936	58.5002
878.185	46.3254
882.431	103.994
886.675	76.8246
890.915	44.7347
895.155	54.7294
899.393	51.5583
903.63	25.9762
907.864	53.0367
912.096	91.62
916.326	68.1158
920.554	32.5563
924.78	55.9358
929.004	39.8712
933.227	46.7585
937.447	18.1204
941.665	35.2913
945.881	37.2898
950.095	26.4404
954.305	19.1443
958.516	48.1907
962.724	52.8806
966.93	51.3263
971.134	26.6027
975.337	53.0591
979.537	21.3721
983.735	43.9742
987.93	30.5488
992.124	49.006
996.316	62.0132
1000.51	56.7581
1004.7	50.7061
1008.88	20.4041
1013.06	41.1389
1017.25	4.10583
1021.43	19.2395
1025.61	34.1492
1029.78	39.0361
1033.96	-5.60852
1038.13	40.3606
1042.3	40.7208
1046.47	29.3075
1050.63	31.3369
1054.8	15.047
1058.96	59.8052
1063.12	51.2126
1067.28	65.4357
1071.44	76.2588
1075.59	100.477
1079.74	161.964
1083.89	240.26
1088.04	212.631
1092.19	123.616
1096.33	70.5658
1100.48	58.2876
1104.62	72.8069
1108.76	71.4629
1112.89	67.6711
1117.03	26.4944
1121.16	20.771
1125.29	36.7136
1129.42	49.104
1133.55	20.9659
1137.68	24.1815
1141.8	56.1031
1145.92	35.9121
1150.04	67.8357
1154.16	77.4063
1158.27	104.008
1162.39	140.633
1166.5	89.097
1170.61	81.6029
1174.72	39.6401
1178.82	56.2225
1182.93	26.4213
1187.03	44.58
1191.13	45.5211
1195.23	58.3379
1199.33	30.8287
1203.42	36.7197
1207.51	51.6011
1211.6	61.3795
1215.69	46.9242
1219.78	44.7579
1223.86	37.76
1227.95	13.0339
1232.03	32.9229
1236.11	9.78162
1240.18	49.3667
1244.26	54.6689
1248.33	43.5203
1252.41	43.0742
1256.48	73.8962
1260.54	44.0144
1264.61	90.3193
1268.67	72.9077
1272.74	49.6641
1276.8	60.4904
1280.86	120.521
1284.91	373.494
1288.97	343.836
1293.02	117.597
1297.07	116.548
1301.12	59.9374
1305.17	53.4316
1309.21	18.608
1313.25	60.2344
1317.3	27.7914
1321.34	77.6702
1325.37	40.4191
1329.41	60.3524
1333.44	34.9103
1337.48	71.2208
1341.5	63.1451
1345.53	35.9624
1349.56	56.6892
1353.59	46.5193
1357.61	25.5167
1361.63	22.3153
1365.65	48.0651
1369.66	63.0743
1373.68	86.2616
1377.69	86.9388
1381.7	81.9547
1385.72	258.774
1389.72	686.765
1393.73	453.763
1397.73	96.3644
1401.74	46.8915
1405.74	68.2832
1409.73	131.237
1413.73	130.287
1417.73	44.4968
1421.72	55.35
1425.71	35.4069
1429.7	53.2607
1433.69	51.4891
1437.67	30.9225
1441.66	31.113
1445.64	52.7979
1449.62	28.994
1453.6	33.566
1457.57	58.6934
1461.55	59.8802
1465.52	64.5385
1469.49	54.3467
1473.46	15.8931
1477.43	27.3518
1481.39	34.6774
1485.36	36.0084
1489.32	52.8602
1493.28	42.4442
1497.24	67.1675
1501.19	66.6683
1505.15	79.0632
1509.1	33.5316
1513.05	52.2637
1517	83.6688
1520.95	81.2428
1524.9	81.8235
1528.84	60.215
1532.78	62.0667
1536.72	32.9351
1540.66	3.85596
1544.6	64.9017
1548.53	60.0553
1552.46	26.1427
1556.4	45.3317
1560.32	29.4297
1564.25	61.7582
1568.18	54.2476
1572.1	40.8328
1576.02	76.6581
1579.94	62.1857
1583.86	49.6198
1587.78	32.1359
1591.69	31.0051
1595.61	24.073
1599.52	38.2913
1603.43	66.0431
1607.34	67.118
1611.24	57.6787
1615.15	67.5225
1619.05	61.2797
1622.95	76.0112
1626.85	77.569
1630.74	68.7975
1634.64	58.6031
1638.53	53.1122
1642.42	62.3816
1646.31	101.681
1650.2	58.7252
1654.09	42.6512
1657.97	83.0739
1661.86	76.4088
1665.74	50.215
1669.62	77.6731
1673.49	15.2449
1677.37	36.3638
1681.24	76.8221
1685.12	45.7932
1688.99	38.6569
1692.86	46.5393
1696.72	54.1752
1700.59	46.2418
1704.45	58.024
1708.31	14.2291
1712.17	46.2567
1716.03	87.631
1719.89	22.0259
1723.74	36.9395
1727.6	26.2201
1731.45	26.5632
1735.3	20.4612
1739.14	29.1625
1742.99	60.02
1746.83	2.36194
1750.68	16.4896
1754.52	54.3219
1758.36	45.6665
1762.19	56.3114
1766.03	16.6216
1769.86	52.7363
1773.69	84.0934
1777.53	49.4816
1781.35	73.1133
1785.18	48.5404
1789	59.6013
1792.83	49.2366
1796.65	29.4939
1800.47	37.8142
1804.29	49.8512
1808.1	42.0117
1811.92	88.6512
1815.73	35.0791
1819.54	10.9589
1823.35	60.0266
1827.16	55.9574
1830.97	71.2478
1834.77	52.1759
1838.58	37.5724
1842.38	74.4672
1846.18	70.4993
1849.97	34.8503
1853.77	38.8167
1857.56	54.5057
1861.36	41.6274
1865.15	62.1151
1868.93	13.042
1872.72	-0.454346
1876.51	-8.95496
1880.29	26.9879
1884.07	28.4683
1887.86	45.6528
1891.63	47.191
1895.41	68.0967
1899.19	32.8748
1902.96	16.764
1906.73	89.3472
1910.5	52.546
1914.27	33.824
1918.04	60.412
1921.8	55.7831
1925.57	35.5571
1929.33	73.0897
1933.09	43.0487
1936.85	53.8488
1940.6	77.7125
1944.36	14.6348
1948.11	39.4148
1951.87	73.2979
1955.61	45.5284
1959.36	51.6252
1963.11	28.0571
1966.86	45.7233
1970.6	78.8068
1974.34	38.072
1978.08	58.9049
1981.82	27.0052
1985.56	39.7451
1989.29	14.005
1993.02	2.97559
1996.75	66.9559
2000.49	11.6075
2004.21	34.3346
2007.94	54.9209
2011.67	9.56445
2015.39	8.60962
2019.11	29.5674
2022.83	50.4265
2026.55	36.5559
2030.27	48.4042
2033.98	87.6141
2037.69	52.3597
2041.41	54.4849
2045.12	14.3604
2048.82	68.5851
2052.53	37.0835
2056.24	56.9712
2059.94	91.5339
2063.64	28.1077
2067.34	27.4459
2071.04	63.7847
2074.74	60.595
2078.43	39.0388
2082.13	52.7416
2085.82	48.6431
2089.51	31.3481
2093.2	35.5732
2096.88	79.672
2100.57	31.4373
2104.25	18.8749
2107.94	59.0308
2111.62	24.5225
2115.3	87.5948
2118.97	37.9579
2122.65	22.0513
2126.32	53.1182
2129.99	54.1959
2133.66	67.1392
2137.33	27.2499
2141	38.8602
2144.67	53.8524
2148.33	28.2041
2151.99	44.8534
2155.66	45.0155
2159.31	39.7529
2162.97	67.6211
2166.63	17.2095
2170.28	47.4489
2173.94	35.5536
2177.59	48.6476
2181.24	13.7404
2184.89	16.9956
2188.53	38.0033
2192.18	46.9644
2195.82	39.3765
2199.46	16.6865
2203.1	49.7952
2206.74	72.3086
2210.38	33.9406
2214.01	33.2614
2217.65	61.1096
2221.28	51.4447
2224.91	36.3389
2228.54	50.5514
2232.16	29.804
2235.79	47.9697
2239.41	48.5624
2243.04	66.7407
2246.66	73.7711
2250.28	33.4922
2253.89	87.3788
2257.51	54.8363
2261.12	60.4794
2264.74	79.9821
2268.35	44.4033
2271.96	74.9115
2275.57	29.7089
2279.17	36.6898
2282.78	53.8336
2286.38	78.5399
2289.98	55.061
2293.58	30.3672
2297.18	71.0078
2300.78	1.9259
2304.37	33.851
2307.97	43.6332
2311.56	60.755
2315.15	20.7379
2318.74	17.3916
2322.33	38.2838
2325.91	19.2491
2329.5	99.347
2333.08	96.8799
2336.66	65.8967
2340.24	70.5323
2343.82	56.17
2347.4	61.3268
2350.97	35.4313
2354.54	61.8949
2358.12	43.3628
2361.69	53.6525
2365.26	49.9359
2368.82	65.8363
2372.39	58.9894
2375.95	54.7982
2379.52	50.6749
2383.08	31.1396
2386.64	51.4049
2390.19	59.9886
2393.75	77.188
2397.31	47.2451
2400.86	55.5426
2404.41	60.2758
2407.96	64.3324
2411.51	67.3558
2415.06	35.9548
2418.6	66.5188
2422.15	75.3726
2425.69	57.9819
2429.23	35.4742
2432.77	56.733
2436.31	79.4264
2439.84	43.8875
2443.38	14.8571
2446.91	72.5608
2450.44	67.3098
2453.97	61.42
2457.5	55.2343
2461.03	28.5858
2464.55	88.4586
2468.08	29.8812
2471.6	53.928
2475.12	72.076
2478.64	56.9269
2482.16	35.507
2485.67	65.2318
2489.19	75.8694
2492.7	-3.59827
2496.21	3.35193
2499.72	26.8572
2503.23	74.0129
2506.74	33.8689
2510.25	51.2526
2513.75	77.0858
2517.25	44.7793
2520.75	77.8251
2524.25	28.0082
2527.75	63.4043
2531.25	53.9535
2534.74	65.1106
2538.24	61.1324
2541.73	78.8263
2545.22	91.9065
2548.71	110.448
2552.2	57.0228
2555.68	77.1229
2559.17	86.1575
2562.65	43.2817
2566.13	53.1677
2569.61	81.4063
2573.09	98.1342
2576.57	53.469
2580.04	116.085
2583.51	85.845
2586.99	85.6859
2590.46	41.4044
2593.93	54.8879
2597.4	71.937
2600.86	96.3173
2604.33	112.026
2607.79	87.3654
2611.25	83.1184
2614.71	36.285
2618.17	58.3278
2621.63	69.0397
2625.09	95.7253
2628.54	32.5571
2631.99	89.1632
2635.45	76.1569
2638.9	79.8735
2642.34	116.753
2645.79	88.1538
2649.24	45.193
2652.68	68.6576
2656.12	102.968
2659.56	68.4089
2663.01	76.4166
2666.44	53.0355
2669.88	86.2821
2673.32	65.6791
2676.75	52.0577
2680.18	80.9119
2683.61	52.1462
2687.04	79.2028
2690.47	72.9427
2693.9	82.2764
2697.32	98.6616
2700.75	99.6553
2704.17	70.0262
2707.59	34.0039
2711.01	75.5637
2714.43	96.1602
2717.84	137.66
2721.26	82.6842
2724.67	106.231
2728.08	99.1735
2731.49	70.7119
2734.9	134.765
2738.31	84.6371
2741.71	64.3379
2745.12	96.2195
2748.52	107.219
2751.92	71.2496
2755.32	88.7101
2758.72	96.5739
2762.12	107.315
2765.52	126.986
2768.91	74.7518
2772.3	99.4783
2775.7	102.373
2779.09	69.152
2782.47	63.007
2785.86	104.728
2789.25	79.5715
2792.63	66.6014
2796.01	108.083
2799.4	124.172
2802.78	88.344
2806.15	110.716
2809.53	135.826
2812.91	112.135
2816.28	130.453
2819.65	90.8013
2823.03	95.389
2826.4	118.895
2829.76	127.615
2833.13	81.6244
2836.5	113.345
2839.86	108.135
2843.22	95.859
2846.59	124.116
2849.95	99.0173
2853.3	127.537
2856.66	57.7815
2860.02	85.4261
2863.37	120.856
2866.72	92.7104
2870.08	109.565
2873.43	105.669
2876.77	99.8286
2880.12	115.586
2883.47	104.928
2886.81	108.249
2890.15	128.533
2893.5	127.013
2896.84	68.3102
2900.17	103.866
2903.51	115.507
2906.85	104.216
2910.18	98.4429
2913.52	166.349
2916.85	95.027
2920.18	105.754
2923.51	72.8789
2926.83	114.547
2930.16	140.795
2933.48	95.028
2936.81	132.087
2940.13	120.071
2943.45	120.335
2946.77	147.97
2950.09	203.855
2953.4	99.7935
2956.72	96.4648
2960.03	125.378
2963.34	80.3097
2966.65	103.878
2969.96	119.571
2973.27	128.106
2976.58	103.897
2979.88	140.046
2983.19	119.687
2986.49	130.421
2989.79	122.503
2993.09	153.159
2996.39	150.125
2999.68	111.476
3002.98	114.154
3006.27	126.257
3009.57	135.705
3012.86	142.445
3016.15	113.431
3019.43	62.6575
3022.72	113.685
3026.01	105.321
3029.29	86.5929
3032.57	92.3804
3035.86	88.6348
3039.14	90.5135
3042.41	98.0917
3045.69	120.867
3048.97	117.166
3052.24	88.8303
3055.52	105.081
3058.79	99.4591
3062.06	93.2468
3065.33	115.781
3068.6	90.6481
3071.86	129.653
3075.13	73.1411
3078.39	123.775
3081.65	95.1224
3084.91	79.416
3088.17	82.5873
3091.43	137.569
3094.69	122.401
3097.95	146.689
3101.2	122.741
3104.45	120.312
3107.7	113.992
3110.95	105.503
3114.2	138.315
3117.45	102.752
3120.7	79.6117
3123.94	113.617
3127.18	99.9756
3130.43	128.205
3133.67	150.76
3136.91	138.005
3140.14	107.992
3143.38	90.3496
3146.61	94.6495
3149.85	115.286
3153.08	100.68
3156.31	105.077
3159.54	148.646
3162.77	140.644
3166	155.553
3169.22	110.175
3172.45	116.202
3175.67	159.372
3178.89	156.586
3182.11	121.351
3185.33	187.266
3188.55	111.825
3191.77	167.924
3194.98	174.44
3198.2	174.261
3201.41	162.62
3204.62	201.529
3207.83	146.264
3211.04	181.514
3214.25	162.655
3217.45	143.932
3220.66	156.613
3223.86	195.047
3227.06	171.839
3230.26	169.606
3233.46	155.144
3236.66	168.159
3239.85	194.916
3243.05	156.095
3246.24	184.977
3249.44	162.431
3252.63	185.816
3255.82	170.163
3259.01	206.006
3262.19	204.37
3265.38	183.367
3268.56	184.071
3271.75	191.281
3274.93	232.772
3278.11	251.31
3281.29	174.913
3284.47	185.101
3287.64	212.495
3290.82	203.477
3293.99	211.782
3297.17	221.914
3300.34	201.607
3303.51	200.778
3306.68	210.895
3309.84	237.942
3313.01	215.255
3316.18	216.234
3319.34	220.018
3322.5	187.714
3325.66	198.106
3328.82	216.069
3331.98	217.979
3335.14	202.074
3338.29	209.957
3341.45	220.797
3344.6	216.593
3347.75	218.512
3350.9	219.94
3354.05	229.831
3357.2	197.521
3360.35	236.003
3363.49	194.582
3366.64	272.009
3369.78	238.271
3372.92	285.744
3376.06	254.181
3379.2	240.618
3382.34	262.094
3385.48	244.745
3388.61	266.319
3391.75	238.726
3394.88	261.205
3398.01	257.657
3401.14	220.061
3404.27	244.24
3407.4	261.991
3410.52	266.567
3413.65	271.093
3416.77	258.986
3419.89	247.689
3423.01	236.202
3426.13	267.275
3429.25	323.817
3432.37	307.547
3435.49	274.656
3438.6	238.493
3441.72	307.551
3444.83	307.837
3447.94	289.623
3451.05	288.535
3454.16	250.976
3457.26	267.689
3460.37	272.71
3463.47	283.392
3466.58	226.518
3469.68	241.606
3472.78	240.235
3475.88	266.891
3478.98	272.786
3482.07	256.061
3485.17	256.423
3488.26	300.355
3491.36	222.764
3494.45	267.446
3497.54	216.756
3500.63	206.535
3503.72	260.479
3506.81	210.424
3509.89	213.154
3512.98	213.455
3516.06	181.173
3519.14	215.22
3522.22	165.35
3525.3	236.332
3528.38	189.551
3531.45	195.722
3534.53	202.465
3537.61	164.955
3540.68	175.761
3543.75	197.682
3546.82	182.506
3549.89	191.202
3552.96	200.426
3556.03	149.919
3559.09	192.387
3562.16	155.366
3565.22	117.957
3568.28	135.236
3571.34	186.242
3574.4	158.704
3577.46	158.74
3580.52	150.103
3583.57	105.288
3586.63	121.973
3589.68	86.4883
3592.73	144.672
3595.78	97.5806
3598.83	112.905
3601.88	95.0721
3604.93	128.203
3607.97	96.84
3611.02	129.801
3614.06	99.3192
3617.1	96.205
3620.14	64.8513
3623.18	63.7932
3626.22	103.328
3629.26	99.5736
3632.3	140.945
3635.33	45.6908
3638.36	75.1212
3641.4	64.2891
3644.43	54.5771
3647.46	102.658
3650.49	78.796
3653.51	90.9097
3656.54	34.3037
3659.57	61.9303
3662.59	68.738
3665.61	104.477
3668.63	71.6674
3671.65	60.8773
3674.67	79.3962
3677.69	38.5526
3680.71	56.304
3683.72	67.3735
3686.74	63.3427
3689.75	1.63049
3692.76	51.6105
3695.77	32.4978
3698.78	55.7312
3701.79	63.1855
3704.79	32.6752
3707.8	50.5496
3710.81	76.8192
3713.81	20.2681
3716.81	45.2949
3719.81	90.4275
3722.81	36.3972
3725.81	46.9609
3728.81	48.8219
3731.8	34.389
3734.8	36.951
3737.79	54.5834
3740.78	33.0509
3743.77	55.1263
3746.76	24.7496
3749.75	37.9891
3752.74	7.40405
3755.73	17.6631
3758.71	49.7672
3761.7	-7.3374
3764.68	42.5865
3767.66	40.4011
3770.64	37.3851
3773.62	25.9965
3776.6	21.343
3779.58	54.574
3782.55	63.3159
3785.53	18.2484
3788.5	3.49768
3791.47	43.587
3794.44	17.8251
3797.41	26.1567
3800.38	36.4637
3803.35	26.1903
3806.32	18.8167
3809.28	73.8339
3812.24	11.7803
3815.21	45.2089
3818.17	35.1862
3821.13	20.4785
3824.09	6.73755
3827.04	39.502
3830	41.0331
3832.96	55.8351
3835.91	8.14343
3838.86	39.2925
3841.82	58.127
3844.77	38.9232
3847.72	17.8151
3850.67	25.3118
3853.61	67.2241
3856.56	73.9216
3859.5	41.4807
3862.45	54.8828
3865.39	73.9623
3868.33	15.4956
3871.27	43.0746
3874.21	51.469
3877.15	10.8628
3880.09	17.1022
3883.02	48.1802
3885.96	85.8397
3888.89	46.5099
3891.82	37.871
3894.75	29.158
3897.68	27.9607
3900.61	47.7632
3903.54	34.8298
3906.47	84.2177
3909.39	26.1001
3912.31	28.4154
3915.24	45.9705
3918.16	54.782
3921.08	55.1896
3924	30.3695
3926.92	78.3286
3929.83	64.7427
3932.75	37.6998
3935.67	15.797
3938.58	47.8048
3941.49	70.4744
3944.4	58.5432
3947.31	46.6892
3950.22	46.4606
3953.13	23.347
3956.04	47.2108
3958.94	57.7932
3961.85	75.1516
3964.75	55.1996
3967.65	16.1282
3970.55	39.4504
3973.45	75.3093
3976.35	79.4766
3979.25	23.9893
3982.15	74.0883
3985.04	47.2837
3987.94	26.1664
3990.83	57.8936
3993.72	9.63086
3996.61	20.2815
3999.5	53.0516
4002.39	24.287
4005.28	58.1262
4008.16	25.5725
4011.05	47.9501
4013.93	0.894165
4016.81	90.7974
4019.7	85.2268
4022.58	86.4006
4025.46	71.1606
4028.33	48.2042
4031.21	68.7344
4034.09	14.8475
4036.96	16.0746
4039.84	43.4955
4042.71	45.7206
4045.58	40.9442
4048.45	15.8754
4051.32	76.1797
4054.19	47.3605
4057.05	31.2545
4059.92	33.5288
4062.78	13.4076
4065.65	45.7643
4068.51	39.2393
4071.37	64.7965
4074.23	41.6943
4077.09	25.3577
4079.95	37.2487
4082.81	38.4214
4085.66	36.6786
4088.52	37.7931
4091.37	37.9304
4094.22	20.5796
4097.07	46.0933
4099.92	27.7231
4102.77	55.2544
4105.62	59.2904
4108.47	51.4321
4111.31	76.8586
4114.16	54.1854
4117	81.2955
4119.84	68.0933
4122.69	62.7418
4125.53	62.4371
4128.36	40.6324
4131.2	51.4641
4134.04	17.431
4136.88	45.486
4139.71	46.5109
4142.54	53.291
4145.38	3.91528
4148.21	13.7323
4151.04	36.3821
4153.87	2.94153
4156.69	50.3385
4159.52	66.8407
4162.35	62.2617
4165.17	-2.79932
4168	60.2631
4170.82	65.6716
4173.64	56.4818
4176.46	31.6787
4179.28	56.7516
4182.1	47.6991
4184.91	74.8776
4187.73	31.6984
4190.54	59.9641
4193.36	51.2405
4196.17	53.4111
4198.98	28.322
4201.79	61.0045
4204.6	30.9912
4207.41	48.9904
4210.22	14.9775
4213.02	62.4507
4215.83	67.6819
4218.63	53.9589
4221.44	40.1252
4224.24	35.0295
4227.04	30.7498
4229.84	49.3993
4232.64	58.2318
4235.43	26.6169
4238.23	51.5305
4241.02	45.7424
4243.82	55.8795
4246.61	42.2123
4249.4	55.356
4252.19	27.48
4254.98	48.4814
4257.77	23.381
4260.56	61.3245
4263.35	13.1483
4266.13	29.1664
4268.92	46.3079
4271.7	32.2626
4274.48	8.06458
4277.26	58.2393
4280.04	33.6124
4282.82	29.0728
4285.6	64.8538
4288.38	12.4985
4291.15	16.6534
4293.93	60.256
4296.7	30.0994
4299.47	97.328
4302.25	46.8494
4305.02	44.0032
4307.79	62.4746
4310.55	41.3989
4313.32	48.873
4316.09	30.736
4318.85	26.7223
4321.62	25.6808
4324.38	36.7631
4327.14	69.1787
4329.9	41.5565
4332.66	59.6382
4335.42	44.1755
4338.18	48.9709
4340.94	52.9705
4343.69	30.4701
4346.45	51.9266
4349.2	40.8551
4351.95	61.4232
4354.7	59.8535
4357.45	40.7711
4360.2	60.5338
4362.95	32.1476
4365.7	73.4778
4368.44	47.1233
4371.19	59.8177
4373.93	44.6173
4376.68	42.7212
4379.42	17.1083
4382.16	53.0854
4384.9	14.1436
4387.64	29.9039
4390.37	47.1505
4393.11	71.8253
4395.85	53.0457
4398.58	34.4043
4401.31	16.6986
4404.05	14.3861
4406.78	37.0295
4409.51	52.4994
4412.24	16.9034
4414.96	28.9696
4417.69	39.9672
4420.42	19.2484
4423.14	54.0106
4425.87	33.5493
4428.59	50.6789
4431.31	51.1022
4434.03	48.3618
4436.75	12.0569
4439.47	50.0416
4442.19	43.933
4444.91	20.0148
4447.62	31.6838
4450.34	57.0138
4453.05	22.4012
4455.76	43.4359
4458.47	33.9031
4461.19	42.1941
4463.89	33.8029
4466.6	-5.1297
4469.31	35.9561
4472.02	22.3716
4474.72	-0.61676
4477.43	46.034
4480.13	31.6423
4482.83	67.9675
4485.53	11.364
4488.23	43.4085
4490.93	43.7132
4493.63	40.5855
4496.33	3.41193
4499.02	18.2987
4501.72	46.9127
4504.41	11.8727
4507.11	39.4628
4509.8	48.0145
4512.49	0.336609
4515.18	18.4614
4517.87	32.3821
4520.56	36.7961
4523.24	13.6741
4525.93	58.6143
4528.61	21.6133
4531.3	57.0382
4533.98	27.5062
4536.66	40.636
4539.34	-8.09827
4542.02	21.1465
4544.7	0.167603
4547.38	16.6428
4550.05	24.5859
4552.73	34.7822
4555.4	48.3855
4558.08	34.2286
4560.75	10.6313
4563.42	29.1664
4566.09	23.2256
4568.76	16.4243
4571.43	23.1027
4574.1	25.4771
4576.77	15.5126
4579.43	58.1454
4582.1	13.1754
4584.76	17.2674
4587.42	7.74939
4590.08	49.4127
4592.74	41.9238
4595.4	23.5771
4598.06	46.8301
4600.72	31.7537
4603.38	34.3416
4606.03	23.8533
4608.69	41.8529
4611.34	11.623
4613.99	-3.32587
4616.64	38.8412
4619.29	21.7234
4621.94	39.86
4624.59	28.23
4627.24	37.4639
4629.89	1.39862
4632.53	8.33472
4635.18	1.87701
4637.82	1.98712
4640.46	31.9711
4643.1	11.0519
4645.74	15.808
4648.38	3.04608
4651.02	48.252
4653.66	0.433044
4656.3	17.8341
4658.93	55.4842
4661.57	32.4858
4664.2	29.6954
4666.83	26.7692
4669.46	48.2409
4672.09	14.9532
4674.72	30.8976
4677.35	27.7874
4679.98	23.5283
4682.61	32.7142
4685.23	27.2996
4687.86	1.62695
4690.48	32.2087
4693.1	6.52002
4695.73	24.6796
4698.34	58.6389
4700.96	6.87323
4703.58	32.9426
4706.2	45.3997
4708.82	45.4007
4711.43	9.16302
4714.05	24.9406
4716.66	31.6334
4719.28	17.898
4721.89	21.1159
4724.5	42.4285
4727.11	20.7804
4729.72	49.0834
4732.33	16.1168
4734.93	38.77
4737.54	3.45221
4740.14	63.5414
4742.75	57.6826
4745.35	35.8193
4747.95	37.7736
4750.55	32.7759
4753.15	38.0435
4755.75	14.8369
4758.35	10.9695
4760.95	17.4213
4763.54	15.9589
4766.14	17.9596
4768.73	9.88519
4771.33	32.6536
4773.92	55.2676
4776.51	44.8105
4779.1	32.0598
4781.69	70.691
4784.28	45.3525
4786.87	64.5909
4789.45	35.7967
4792.04	37.9034
4794.63	34.3145
4797.21	13.5563
4799.79	38.7139
4802.37	20.3466
4804.95	28.4236
4807.53	32.0115
4810.11	21.8477
4812.69	34.686
4815.27	21.0621
4817.84	35.1637
4820.42	53.9752
4822.99	12.6298
4825.57	36.086
4828.14	31.7247
4830.71	11.089
4833.28	21.8781
4835.85	29.2219
4838.42	58.8419
4840.98	34.8537
4843.55	4.88806
4846.12	50.8848
4848.68	21.7844
4851.24	34.665
4853.81	42.3347
4856.37	34.8557
4858.93	18.6808
4861.49	46.0294
4864.05	14.1821
4866.61	22.1757
4869.16	17.2128
4871.72	20.6802
4874.27	53.5828
4876.83	27.1523
4879.38	46.9427
4881.93	53.64
4884.49	42.465
4887.04	11.0506
4889.58	53.3481
4892.13	-6.66473
4894.68	54.6746
4897.23	52.8964
4899.77	16.5092
4902.32	28.9557
4904.86	-0.370605
4907.4	31.1102
4909.95	32.7245
4912.49	37.7422
4915.03	6.85663
4917.57	30.8327
4920.1	42.9348
4922.64	14.4007
4925.18	2.58374
4927.71	36.2141
4930.25	27.9103
4932.78	38.9153
4935.31	38.0929
4937.84	3.66156
4940.38	30.2307
4942.9	40.9066
4945.43	-2.03864
4947.96	5.39447
4950.49	6.79779
4953.01	19.0391
4955.54	1.1925
4958.06	-4.5564
4960.59	1.73645
4963.11	-2.7334
4965.63	9.8075
4968.15	30.9222
4970.67	16.8793
4973.19	13.6223
4975.71	23.6094
4978.22	2.14063
4980.74	18.1648
4983.25	23.3021
4985.77	19.9667
4988.28	9.33795
4990.79	14.4742
4993.3	12.2731
4995.81	1.508
4998.32	17.6204