File: Data/3-Raman/processed/bu19w-d-ore2-fi04-v_150 (500nm)_532nm_edge_100%_x100_vis_lwd_h50um_15sx2_01_0.txt
#Acq. time (s)=	15
#Accumulations=	2
#Range (cm-¹)=	50...5000
#Windows=	1
#Auto scanning=	Off
#Autofocus=	Off
#Macrospot=	Off
#AutoExposure=	Off
#Spike filter=	Multiple accum.
#Delay time (s)=	2
#Binning=	1
#Readout mode=	Signal
#DeNoise=	Off
#ICS correction=	On
#Dark correction=	Off
#Inst. Process=	Off
#Detector Gain=	Best Dynamic
#Detector ADC=	50 kHz HS
#Detector temperature (°C)=	-60.09
#Instrument=	LabRAM HR Evol
#Detector=	SIN-EM FIVIS
#Objective=	x100_VIS_LWD
#Grating=	150 (500nm)
#ND Filter=	100%
#Laser=	532nm_Edge
#Hole=	49.98
#Temperature=	0
#Range=	Visible
#StageXY=	75x50mm Scan+
#StageZ=	Z motor
#X (µm)=	0
#Y (µm)=	0
#Z (µm)=	-25.9
#Full time(s)=	35
#Project=	21_05_28
#Sample=	BU19w
#Site=
#Title=	BU19w-FF-ore2-FI04-V_150 (500nm)_532nm_Edge_100%_x100_VIS_LWD_H50um_15sX2
#Remark=
#Date=	28.05.2021 14:54
#Acquired=	28.05.2021 14:54:25
#Base:Fit=	16.12.2021 17:39:50
#Base:Edit=	16.12.2021 18:01:02
#Base:Sub=	16.12.2021 18:01:05
51.5961	14529.3
56.2453	16187.2
60.8921	16813.4
65.5367	14037.7
70.1768	11144.6
74.8167	8903.8
79.4543	7119.46
84.0897	5913.7
88.7227	4939.18
93.3513	4198.74
97.9798	3522.45
102.606	3118.87
107.23	2671.43
111.851	2418.94
116.469	2228.56
121.086	2108.56
125.7	2635.29
130.313	3747.06
134.921	3068.44
139.529	1937.19
144.134	1633.7
148.738	1595.68
153.337	1430.96
157.936	1328.92
162.532	1193.69
167.126	1207.61
171.716	1265.21
176.306	1271.08
180.894	1471.13
185.477	1680.48
190.06	2066.67
194.64	2901.24
199.219	3885.7
203.793	5178.82
208.367	5846.98
212.939	5647.28
217.506	4440.46
222.073	3290.53
226.638	2466.15
231.199	1766.65
235.759	1334.32
240.318	1061.37
244.872	875.517
249.425	767.023
253.977	671.167
258.524	662.267
263.071	967.384
267.616	1235.92
272.156	872.217
276.697	453.825
281.233	285.119
285.769	199.863
290.303	190.982
294.832	109.054
299.361	102.785
303.886	78.6294
308.411	95.7772
312.934	52.5188
317.452	-0.141846
321.97	-7.56287
326.484	-18.4192
330.998	-11.3452
335.507	-28.4396
340.017	15.3879
344.524	-20.9269
349.027	-0.765869
353.53	317.358
358.028	984.013
362.527	719.33
367.021	187.427
371.515	80.4045
376.004	24.8163
380.494	11.4182
384.979	-30.2662
389.465	34.993
393.946	72.0339
398.427	41.5116
402.903	108.561
407.38	128.201
411.852	24.8031
416.324	37.5596
420.792	54.7755
425.26	61.5426
429.723	74.9341
434.187	108.677
438.646	161.408
443.105	288.646
447.56	566.593
452.015	1075.13
456.466	2376.81
460.914	6450.95
465.362	15194.3
469.807	17069
474.251	9274.52
478.69	3847.54
483.13	1998.94
487.566	1300.69
491.999	923.369
496.432	646.2
500.861	490.486
505.29	341.576
509.715	379.426
514.138	488.977
518.56	330.392
522.979	245.314
527.395	168.78
531.811	100.664
536.223	54.8268
540.635	85.4829
545.042	95.2937
549.448	36.801
553.853	38.431
558.255	68.2802
562.654	-18.953
567.053	3.10388
571.448	20.057
575.841	-44.2286
580.232	-38.4386
584.622	-19.3602
589.009	-26.5278
593.393	0.375732
597.777	9.63464
602.157	-44.798
606.535	-30.7543
610.913	-15.5
615.287	-56.317
619.659	-19.2045
624.029	-12.5781
628.398	-38.7499
632.763	-43.8406
637.127	-0.303467
641.488	-12.0938
645.849	-35.798
650.206	-65.738
654.561	-1.59253
658.914	-56.9758
663.267	-70.2563
667.615	-52.2285
671.962	-1.80603
676.307	-42.3461
680.649	-36.649
684.991	-33.5618
689.33	-29.5308
693.666	8.24597
698	53.4282
702.332	51.5608
706.662	-11.2736
710.992	-58.4916
715.318	-60.3036
719.641	-34.1776
723.963	-18.7681
728.283	-69.3695
732.6	5.89795
736.918	-8.95215
741.231	-25.6309
745.542	-49.6962
749.852	-14.6331
754.159	12.6536
758.464	-24.9181
762.767	-63.3921
767.068	-26.4733
771.369	10.4642
775.666	-18.4698
779.961	-51.2991
784.254	-4.90576
788.545	26.0098
792.834	95.9033
797.12	140.306
801.405	190.915
805.688	294.478
809.968	552.638
814.247	514.232
818.524	264.957
822.798	104.656
827.071	73.5021
831.341	36.9568
835.612	11.4104
839.878	51.8741
844.142	3.90576
848.405	70.0483
852.665	59.0433
856.923	103.155
861.18	9.44727
865.434	31.1268
869.686	77.4868
873.936	47.552
878.185	45.7544
882.431	108.133
886.675	50.4292
890.915	51.8666
895.155	43.8988
899.393	3.2124
903.63	5.2804
907.864	44.0122
912.096	36.1543
916.326	50.9683
920.554	38.3655
924.78	61.7375
929.004	-3.06482
933.227	9.57361
937.447	21.9827
941.665	15.6389
945.881	-4.83557
950.095	28.0436
954.305	11.1838
958.516	1.99341
962.724	6.8606
966.93	-4.04041
971.134	33.0377
975.337	23.7576
979.537	18.9429
983.735	-15.1805
987.93	-1.68713
992.124	15.1279
996.316	55.4729
1000.51	-13.1823
1004.7	17.0577
1008.88	13.6526
1013.06	44.3372
1017.25	5.38867
1021.43	32.4415
1025.61	-1.70422
1029.78	4.02588
1033.96	14.4948
1038.13	4.93469
1042.3	-0.389893
1046.47	86.7677
1050.63	41.2639
1054.8	39.9976
1058.96	36.0428
1063.12	58.9338
1067.28	113.719
1071.44	118.619
1075.59	125.369
1079.74	194.439
1083.89	410.832
1088.04	384.883
1092.19	216.222
1096.33	83.2098
1100.48	54.1952
1104.62	75.6442
1108.76	49.7883
1112.89	40.2063
1117.03	56.5569
1121.16	53.2122
1125.29	38.5492
1129.42	56.2637
1133.55	60.2856
1137.68	66.8591
1141.8	40.4692
1145.92	57.6018
1150.04	57.7111
1154.16	117.52
1158.27	128.095
1162.39	193.929
1166.5	167.238
1170.61	75.0222
1174.72	7.98633
1178.82	55.0331
1182.93	1.0708
1187.03	10.3215
1191.13	16.3647
1195.23	20.7446
1199.33	4.01331
1203.42	14.3308
1207.51	48.7787
1211.6	72.9673
1215.69	44.5887
1219.78	32.662
1223.86	81.3599
1227.95	93.1776
1232.03	111.719
1236.11	123.831
1240.18	104.154
1244.26	185.904
1248.33	141.651
1252.41	63.6125
1256.48	122.844
1260.54	145.526
1264.61	216.591
1268.67	246.188
1272.74	156.931
1276.8	170.846
1280.86	343.451
1284.91	1403.88
1288.97	1251.93
1293.02	370.398
1297.07	145.359
1301.12	120.467
1305.17	104.229
1309.21	85.8326
1313.25	97.4343
1317.3	111.281
1321.34	104.521
1325.37	68.782
1329.41	38.8796
1333.44	114.198
1337.48	81.3521
1341.5	136.279
1345.53	77.9141
1349.56	110.422
1353.59	98.0823
1357.61	108.73
1361.63	112.213
1365.65	103.211
1369.66	169.694
1373.68	209.879
1377.69	179.352
1381.7	278.337
1385.72	859.716
1389.72	2865.51
1393.73	1246.04
1397.73	297.904
1401.74	142.798
1405.74	148.137
1409.73	293.702
1413.73	246.35
1417.73	152.619
1421.72	41.0076
1425.71	102.838
1429.7	120.103
1433.69	71.4258
1437.67	111.575
1441.66	100.43
1445.64	102.763
1449.62	70.4373
1453.6	28.8787
1457.57	79.8228
1461.55	40.6531
1465.52	85.4854
1469.49	-22.2781
1473.46	33.5139
1477.43	98.7039
1481.39	62.5381
1485.36	45.8831
1489.32	23.2517
1493.28	76.9731
1497.24	27.3003
1501.19	59.7683
1505.15	67.2844
1509.1	105.563
1513.05	46.8398
1517	49.4792
1520.95	79.5466
1524.9	67.0774
1528.84	102.316
1532.78	25.3967
1536.72	54.2197
1540.66	66.647
1544.6	45.1765
1548.53	72.1821
1552.46	76.9102
1556.4	86.2092
1560.32	65.1479
1564.25	39.022
1568.18	92.9685
1572.1	73.2356
1576.02	95.9927
1579.94	64.5916
1583.86	54.4006
1587.78	79.7012
1591.69	98.1736
1595.61	28.1013
1599.52	88.8474
1603.43	69.0486
1607.34	88.9919
1611.24	84.0518
1615.15	101.344
1619.05	128.547
1622.95	116.332
1626.85	138.024
1630.74	76.7776
1634.64	76.6206
1638.53	109.86
1642.42	115.041
1646.31	124.581
1650.2	78.7808
1654.09	89.6633
1657.97	76.3684
1661.86	92.7593
1665.74	127.937
1669.62	70.5962
1673.49	99.9861
1677.37	77.3364
1681.24	78.395
1685.12	87.4895
1688.99	65.6843
1692.86	18.5361
1696.72	30.4788
1700.59	80.2004
1704.45	84.4456
1708.31	39.6294
1712.17	70.47
1716.03	43.4021
1719.89	59.1096
1723.74	67.2695
1727.6	107.212
1731.45	31.0015
1735.3	56.5994
1739.14	38.769
1742.99	73.9233
1746.83	76.4675
1750.68	30.3123
1754.52	53.8564
1758.36	54.6345
1762.19	57.604
1766.03	56.0396
1769.86	72.1511
1773.69	75.5457
1777.53	62.2856
1781.35	-2.35229
1785.18	40.5884
1789	80.2158
1792.83	45.1792
1796.65	75.7813
1800.47	67.8557
1804.29	63.9851
1808.1	21.3132
1811.92	98.9607
1815.73	86.6807
1819.54	102.562
1823.35	97.9968
1827.16	73.1724
1830.97	51.4663
1834.77	96.0562
1838.58	55.4465
1842.38	92.5942
1846.18	76.4773
1849.97	41.0269
1853.77	48.5476
1857.56	47.0088
1861.36	28.8425
1865.15	-0.67627
1868.93	47.2566
1872.72	50.782
1876.51	12.2766
1880.29	61.7856
1884.07	96.5378
1887.86	59.5061
1891.63	45.6531
1895.41	121.143
1899.19	34.697
1902.96	66.2139
1906.73	78
1910.5	76.2458
1914.27	45.9304
1918.04	21.281
1921.8	62.8936
1925.57	90.0842
1929.33	47.3098
1933.09	46.458
1936.85	57.665
1940.6	30.5674
1944.36	24.8279
1948.11	74.3704
1951.87	42.323
1955.61	29.8782
1959.36	24.5945
1963.11	48.5547
1966.86	109.005
1970.6	61.613
1974.34	56.5059
1978.08	34.0444
1981.82	35.5461
1985.56	59.0396
1989.29	25.2776
1993.02	66.6646
1996.75	80.4509
2000.49	68.6538
2004.21	66.302
2007.94	95.0852
2011.67	33.7288
2015.39	42.6394
2019.11	26.1267
2022.83	65.0828
2026.55	24.9146
2030.27	82.8635
2033.98	72.4604
2037.69	70.2734
2041.41	0.118896
2045.12	40.5552
2048.82	18.8052
2052.53	122.112
2056.24	32.3408
2059.94	90.4893
2063.64	53.0549
2067.34	27.1716
2071.04	74.207
2074.74	54.0781
2078.43	73.8445
2082.13	34.5862
2085.82	78.4033
2089.51	70.0623
2093.2	53.1475
2096.88	74.6343
2100.57	61.283
2104.25	39.6335
2107.94	33.3606
2111.62	75.0657
2115.3	22.7937
2118.97	-0.95166
2122.65	71.8518
2126.32	79.9797
2129.99	69.1658
2133.66	64.6262
2137.33	45.1499
2141	68.6814
2144.67	33.7073
2148.33	41.0017
2151.99	95.9875
2155.66	96.8159
2159.31	30.0254
2162.97	44.1853
2166.63	40.4685
2170.28	18.9917
2173.94	27.7627
2177.59	82.6187
2181.24	98.6536
2184.89	32.7034
2188.53	36.6116
2192.18	56.074
2195.82	66.6101
2199.46	41.2996
2203.1	40.8713
2206.74	52.7278
2210.38	-13.5615
2214.01	59.491
2217.65	42.1323
2221.28	37.6521
2224.91	49.865
2228.54	81.2947
2232.16	79.6858
2235.79	68.1426
2239.41	40.7571
2243.04	28.0701
2246.66	53.3223
2250.28	31.3594
2253.89	126.997
2257.51	58.0295
2261.12	57.9517
2264.74	65.0667
2268.35	35.8989
2271.96	70.1909
2275.57	41.7627
2279.17	66.3032
2282.78	61.8352
2286.38	47.886
2289.98	39.5603
2293.58	68.7195
2297.18	44.0659
2300.78	22.3267
2304.37	38.9895
2307.97	11.5432
2311.56	32.0835
2315.15	50.3608
2318.74	17.0322
2322.33	23.9041
2325.91	67.0933
2329.5	271.605
2333.08	209.04
2336.66	98.2151
2340.24	34.4407
2343.82	68.3672
2347.4	67.1448
2350.97	3.00586
2354.54	9.10156
2358.12	44.8889
2361.69	71.0688
2365.26	19.9839
2368.82	30.4937
2372.39	37.8962
2375.95	11.8103
2379.52	46.7949
2383.08	38.6963
2386.64	-1.30908
2390.19	26.2969
2393.75	50.6848
2397.31	92.3059
2400.86	85.2708
2404.41	8.17993
2407.96	40.4724
2411.51	62.8696
2415.06	24.4153
2418.6	63.6992
2422.15	21.5894
2425.69	36.1831
2429.23	23.7744
2432.77	36.8013
2436.31	22.6338
2439.84	58.8337
2443.38	13.4509
2446.91	77.1382
2450.44	47.1511
2453.97	76.5654
2457.5	67.7754
2461.03	38.8533
2464.55	36.0388
2468.08	68.8359
2471.6	46.1675
2475.12	10.8123
2478.64	63.7939
2482.16	48.3262
2485.67	35.7183
2489.19	48.8738
2492.7	5.14673
2496.21	72.7021
2499.72	40.7476
2503.23	42.6638
2506.74	15.2246
2510.25	39.5422
2513.75	2.56372
2517.25	24.8389
2520.75	19.6653
2524.25	43.3604
2527.75	22.334
2531.25	-0.778076
2534.74	42.0635
2538.24	35.7766
2541.73	25.4761
2545.22	44.0637
2548.71	31.4238
2552.2	46.6265
2555.68	-1.30176
2559.17	59.3459
2562.65	76.6064
2566.13	58.7666
2569.61	2.47803
2573.09	74.6042
2576.57	20.1296
2580.04	46.655
2583.51	70.6621
2586.99	57.9063
2590.46	-8.69434
2593.93	62.8745
2597.4	44.7759
2600.86	28.282
2604.33	42.1157
2607.79	27.7231
2611.25	15.0696
2614.71	12.262
2618.17	92.032
2621.63	11.3057
2625.09	31.9539
2628.54	33.6926
2631.99	46.5608
2635.45	42.5059
2638.9	12.822
2642.34	52.6636
2645.79	-6.54272
2649.24	-3.677
2652.68	17.6973
2656.12	26.0129
2659.56	7.2312
2663.01	36.5793
2666.44	-10.0103
2669.88	57.6299
2673.32	53.3682
2676.75	38.2861
2680.18	3.98657
2683.61	-9.07397
2687.04	15.1602
2690.47	26.9209
2693.9	-0.539063
2697.32	46.0398
2700.75	-16.6863
2704.17	30.5027
2707.59	20.1147
2711.01	55.1321
2714.43	34.8608
2717.84	92.342
2721.26	9.66309
2724.67	11.1099
2728.08	54.7915
2731.49	22.0374
2734.9	41.5024
2738.31	-0.834473
2741.71	-19.9192
2745.12	47.8276
2748.52	18.5664
2751.92	39.1343
2755.32	26.5959
2758.72	33.5559
2762.12	-26.3069
2765.52	35.6619
2768.91	67.1384
2772.3	43.5701
2775.7	30.1729
2779.09	48.4063
2782.47	45.5923
2785.86	52.0215
2789.25	27.3367
2792.63	79.6758
2796.01	49.2261
2799.4	0.0449219
2802.78	40.6213
2806.15	58.677
2809.53	20.4644
2812.91	39.2764
2816.28	59.7974
2819.65	30.7454
2823.03	3.9856
2826.4	22.3611
2829.76	23.1924
2833.13	94.2332
2836.5	29.6721
2839.86	58.6909
2843.22	19.2427
2846.59	56.7576
2849.95	83.0444
2853.3	83.7888
2856.66	97.3384
2860.02	41.0955
2863.37	75.8411
2866.72	67.6428
2870.08	66.9507
2873.43	91.469
2876.77	38.8464
2880.12	22.7715
2883.47	30.1426
2886.81	17.5352
2890.15	34.1208
2893.5	60.9941
2896.84	33.46
2900.17	44.3511
2903.51	38.8113
2906.85	47.1848
2910.18	56.312
2913.52	56.7615
2916.85	-3.50293
2920.18	74.0378
2923.51	15.2375
2926.83	53.6497
2930.16	50.1309
2933.48	19.9167
2936.81	78.1128
2940.13	57.9727
2943.45	23.75
2946.77	79.0918
2950.09	79.8738
2953.4	114.417
2956.72	33.4624
2960.03	103.197
2963.34	32.3196
2966.65	27.3113
2969.96	107.396
2973.27	102.543
2976.58	45.2588
2979.88	99.9827
2983.19	46.5432
2986.49	44.8545
2989.79	66.7756
2993.09	41.8257
2996.39	90.2754
2999.68	12.926
3002.98	79.3672
3006.27	62.145
3009.57	58.2666
3012.86	73.3384
3016.15	58.3242
3019.43	44.1797
3022.72	87.5293
3026.01	139.431
3029.29	61.1052
3032.57	70.5234
3035.86	94.967
3039.14	79.6504
3042.41	88.9399
3045.69	117.219
3048.97	44.2063
3052.24	117.042
3055.52	132.186
3058.79	96.9824
3062.06	100.884
3065.33	69.0686
3068.6	89.1648
3071.86	107.838
3075.13	82.8533
3078.39	116.069
3081.65	30.0605
3084.91	89.095
3088.17	99.6814
3091.43	86.189
3094.69	90.8701
3097.95	112.727
3101.2	110.326
3104.45	139.842
3107.7	119.041
3110.95	148.353
3114.2	163.639
3117.45	119.144
3120.7	138.501
3123.94	175.011
3127.18	131.472
3130.43	126.919
3133.67	191.019
3136.91	131.16
3140.14	130.274
3143.38	175.123
3146.61	165.647
3149.85	150.595
3153.08	209.976
3156.31	188.2
3159.54	194.147
3162.77	160.901
3166	224.991
3169.22	161.958
3172.45	202.785
3175.67	210.117
3178.89	238.251
3182.11	233.918
3185.33	301.164
3188.55	240.349
3191.77	243.373
3194.98	262.593
3198.2	303.679
3201.41	319.932
3204.62	262.022
3207.83	284.173
3211.04	301.666
3214.25	328.828
3217.45	289.551
3220.66	338.755
3223.86	316.697
3227.06	369.068
3230.26	317.804
3233.46	330.45
3236.66	331.529
3239.85	327.405
3243.05	358.641
3246.24	317.615
3249.44	347.092
3252.63	378.728
3255.82	335.087
3259.01	419.264
3262.19	339.875
3265.38	396.698
3268.56	342.395
3271.75	362.37
3274.93	349.728
3278.11	402.958
3281.29	349.688
3284.47	406.761
3287.64	391.328
3290.82	387.157
3293.99	357.452
3297.17	377.222
3300.34	391.304
3303.51	418.281
3306.68	429.409
3309.84	457.417
3313.01	443.212
3316.18	430.79
3319.34	406.003
3322.5	455.106
3325.66	442.597
3328.82	449.999
3331.98	472.576
3335.14	428.214
3338.29	444.54
3341.45	431.767
3344.6	456.794
3347.75	480.499
3350.9	501
3354.05	504.502
3357.2	496.963
3360.35	524.425
3363.49	479.584
3366.64	553.598
3369.78	517.413
3372.92	536.035
3376.06	560.613
3379.2	520.151
3382.34	558.188
3385.48	561.167
3388.61	600.297
3391.75	613.945
3394.88	613.279
3398.01	606.305
3401.14	558.965
3404.27	575.326
3407.4	665.085
3410.52	608.716
3413.65	583.557
3416.77	636.846
3419.89	622.352
3423.01	630.499
3426.13	641.002
3429.25	669.209
3432.37	684.665
3435.49	601.26
3438.6	650.011
3441.72	662.778
3444.83	664.977
3447.94	614.219
3451.05	611.102
3454.16	626.693
3457.26	680.288
3460.37	628.807
3463.47	646.757
3466.58	591.406
3469.68	622.16
3472.78	626.835
3475.88	626.56
3478.98	633.987
3482.07	572.479
3485.17	514.905
3488.26	638.886
3491.36	555.441
3494.45	626.501
3497.54	545.547
3500.63	555.969
3503.72	577.754
3506.81	553.907
3509.89	539.481
3512.98	487.655
3516.06	520.993
3519.14	518.511
3522.22	514.216
3525.3	448.342
3528.38	467.067
3531.45	484.793
3534.53	430.28
3537.61	428.543
3540.68	408.137
3543.75	408.462
3546.82	448.087
3549.89	428.801
3552.96	397.604
3556.03	369.022
3559.09	377.664
3562.16	356.016
3565.22	350.964
3568.28	358.858
3571.34	335.169
3574.4	335.138
3577.46	316.226
3580.52	313.267
3583.57	332.906
3586.63	324.844
3589.68	242.803
3592.73	278.103
3595.78	225.188
3598.83	286.773
3601.88	250.759
3604.93	215.513
3607.97	216.112
3611.02	240.333
3614.06	252.135
3617.1	223.238
3620.14	184.078
3623.18	212.966
3626.22	205.109
3629.26	190.779
3632.3	192.368
3635.33	192.919
3638.36	223.096
3641.4	155.654
3644.43	167.462
3647.46	171.264
3650.49	181.146
3653.51	153.642
3656.54	146.46
3659.57	138.491
3662.59	85.1254
3665.61	124.631
3668.63	130.377
3671.65	112.014
3674.67	129.562
3677.69	53.7726
3680.71	103.604
3683.72	81.5656
3686.74	97.3431
3689.75	99.9409
3692.76	100.689
3695.77	37.9614
3698.78	109.451
3701.79	92.2117
3704.79	88.2312
3707.8	18.6741
3710.81	74.2932
3713.81	50.9109
3716.81	54.8879
3719.81	116.076
3722.81	42.8662
3725.81	94.2111
3728.81	71.1395
3731.8	54.6113
3734.8	20.7772
3737.79	64.8455
3740.78	23.0796
3743.77	52.5111
3746.76	69.4182
3749.75	50.0249
3752.74	4.8822
3755.73	31.9282
3758.71	28.6166
3761.7	42.3322
3764.68	43.5791
3767.66	19.299
3770.64	3.68665
3773.62	78.0792
3776.6	37.191
3779.58	60.6825
3782.55	49.3086
3785.53	51.1832
3788.5	24.8234
3791.47	38.2141
3794.44	62.2272
3797.41	40.1163
3800.38	38.8618
3803.35	2.87402
3806.32	58.5564
3809.28	42.5109
3812.24	47.3386
3815.21	40.8575
3818.17	54.2703
3821.13	44.0941
3824.09	15.0059
3827.04	40.9395
3830	75.4453
3832.96	16.0721
3835.91	37.4432
3838.86	11.4227
3841.82	67.108
3844.77	60.0723
3847.72	26.3987
3850.67	29.8871
3853.61	65.8813
3856.56	11.2959
3859.5	37.8198
3862.45	88.2999
3865.39	54.564
3868.33	34.1697
3871.27	19.3629
3874.21	28.463
3877.15	35.5842
3880.09	29.0953
3883.02	60.8676
3885.96	58.8417
3888.89	37.4725
3891.82	64.1042
3894.75	-16.0775
3897.68	39.139
3900.61	14.368
3903.54	37.634
3906.47	31.8708
3909.39	44.543
3912.31	47.4597
3915.24	28.1355
3918.16	32.7386
3921.08	47.1957
3924	66.153
3926.92	55.1859
3929.83	20.1228
3932.75	12.8268
3935.67	73.8778
3938.58	41.3545
3941.49	34.9498
3944.4	46.6017
3947.31	33.4377
3950.22	83.608
3953.13	41.965
3956.04	19.5231
3958.94	7.73376
3961.85	89.9098
3964.75	22.665
3967.65	59.0175
3970.55	26.3918
3973.45	31.2072
3976.35	56.1577
3979.25	24.3484
3982.15	14.5236
3985.04	35.4266
3987.94	47.6156
3990.83	-3.72131
3993.72	28.4498
3996.61	24.3243
3999.5	47.119
4002.39	31.483
4005.28	30.3026
4008.16	20.5156
4011.05	71.4617
4013.93	52.0299
4016.81	69.2506
4019.7	42.0869
4022.58	34.2
4025.46	82.3306
4028.33	-2.81812
4031.21	50.2012
4034.09	21.0948
4036.96	16.1626
4039.84	-7.11206
4042.71	29.5974
4045.58	42.8519
4048.45	35.8286
4051.32	27.9006
4054.19	36.5259
4057.05	31.7008
4059.92	30.6973
4062.78	9.23413
4065.65	-20.9961
4068.51	63.4973
4071.37	36.1471
4074.23	64.2511
4077.09	18.3271
4079.95	48.3468
4082.81	24.7716
4085.66	14.8375
4088.52	62.3846
4091.37	20.1743
4094.22	43.4393
4097.07	22.6584
4099.92	20.5006
4102.77	-21.7782
4105.62	-1.54199
4108.47	49.8545
4111.31	54.3256
4114.16	20.4706
4117	33.4568
4119.84	12.9801
4122.69	42.434
4125.53	23.1125
4128.36	35.1381
4131.2	21.0844
4134.04	3.28687
4136.88	37.8055
4139.71	16.8247
4142.54	25.1047
4145.38	67.2712
4148.21	48.3115
4151.04	47.0648
4153.87	29.8514
4156.69	40.574
4159.52	34.114
4162.35	18.3373
4165.17	34.0314
4168	65.3512
4170.82	33.1582
4173.64	21.5769
4176.46	27.6316
4179.28	43.4663
4182.1	35.9349
4184.91	57.7882
4187.73	16.1307
4190.54	25.37
4193.36	15.2286
4196.17	56.1313
4198.98	33.5643
4201.79	40.3352
4204.6	27.5465
4207.41	35.3016
4210.22	26.3921
4213.02	40.0273
4215.83	26.1313
4218.63	24.7463
4221.44	65.6545
4224.24	43.3911
4227.04	69.2979
4229.84	21.3387
4232.64	28.7247
4235.43	-17.2203
4238.23	11.1793
4241.02	34.7072
4243.82	16.553
4246.61	23.314
4249.4	76.8823
4252.19	46.5941
4254.98	73.1709
4257.77	42.6428
4260.56	23.0483
4263.35	11.4834
4266.13	42.1049
4268.92	11.5488
4271.7	38.2727
4274.48	15.6323
4277.26	17.9225
4280.04	63.4656
4282.82	19.0531
4285.6	32.0909
4288.38	18.6848
4291.15	31.4543
4293.93	20.89
4296.7	34.7935
4299.47	60.9707
4302.25	37.3564
4305.02	45.1616
4307.79	13.3691
4310.55	38.4906
4313.32	20.0355
4316.09	41.0366
4318.85	33.4539
4321.62	1.35461
4324.38	36.3391
4327.14	28.511
4329.9	54.3318
4332.66	52.5258
4335.42	38.5642
4338.18	23.4612
4340.94	22.8395
4343.69	34.4528
4346.45	48.2314
4349.2	56.0026
4351.95	10.7019
4354.7	36.1331
4357.45	23.6434
4360.2	42.8448
4362.95	33.3402
4365.7	27.0045
4368.44	29.7815
4371.19	74.7172
4373.93	32.2832
4376.68	36.9979
4379.42	38.5363
4382.16	44.1564
4384.9	24.1598
4387.64	34.2065
4390.37	43.6718
4393.11	45.0833
4395.85	17.4034
4398.58	59.1398
4401.31	51.2228
4404.05	19.3257
4406.78	4.01147
4409.51	11.5604
4412.24	55.4
4414.96	45.0223
4417.69	32.4884
4420.42	34.0792
4423.14	22.3192
4425.87	50.2753
4428.59	30.2131
4431.31	60.3068
4434.03	7.75073
4436.75	22.0812
4439.47	27.9909
4442.19	48.4749
4444.91	42.7833
4447.62	53.8047
4450.34	49.0856
4453.05	30.6097
4455.76	19.4572
4458.47	38.6743
4461.19	-13.6305
4463.89	58.2563
4466.6	64.9393
4469.31	51.6921
4472.02	45.8481
4474.72	42.195
4477.43	9.1098
4480.13	22.4713
4482.83	39.0771
4485.53	52.5294
4488.23	39.4788
4490.93	28.4808
4493.63	35.2094
4496.33	47.0685
4499.02	34.7661
4501.72	31.9268
4504.41	57.6166
4507.11	42.074
4509.8	15.9393
4512.49	38.5945
4515.18	33.6886
4517.87	12.8704
4520.56	33.5137
4523.24	43.6475
4525.93	26.1206
4528.61	-1.03119
4531.3	25.074
4533.98	30.9782
4536.66	44.3845
4539.34	50.3683
4542.02	51.0771
4544.7	38.9367
4547.38	40.7178
4550.05	23.228
4552.73	-0.636169
4555.4	34.6317
4558.08	44.3309
4560.75	15.5914
4563.42	31.1165
4566.09	46.9934
4568.76	31.781
4571.43	6.1452
4574.1	17.4111
4576.77	54.35
4579.43	17.911
4582.1	12.2463
4584.76	24.1486
4587.42	19.1898
4590.08	18.5236
4592.74	26.4825
4595.4	20.3196
4598.06	38.2847
4600.72	47.4294
4603.38	21.7485
4606.03	54.1208
4608.69	16.4003
4611.34	74.0719
4613.99	38.4615
4616.64	43.4389
4619.29	17.6621
4621.94	6.19366
4624.59	18.9103
4627.24	19.436
4629.89	11.0823
4632.53	-1.74597
4635.18	30.6086
4637.82	24.2114
4640.46	42.1414
4643.1	2.50372
4645.74	14.0001
4648.38	-15.3245
4651.02	56.6016
4653.66	9.97235
4656.3	19.6517
4658.93	31.7516
4661.57	44.5026
4664.2	42.9007
4666.83	27.746
4669.46	39.2072
4672.09	48.515
4674.72	1.77832
4677.35	26.7274
4679.98	39.343
4682.61	-16.5668
4685.23	22.9747
4687.86	8.57507
4690.48	42.5624
4693.1	54.0756
4695.73	27.1931
4698.34	35.2224
4700.96	53.4345
4703.58	56.9486
4706.2	30.9969
4708.82	34.3824
4711.43	-4.12653
4714.05	47.8575
4716.66	51.1536
4719.28	5.69507
4721.89	32.6903
4724.5	9.7804
4727.11	52.733
4729.72	8.40668
4732.33	40.0911
4734.93	52.4966
4737.54	28.5081
4740.14	24.9044
4742.75	64.4749
4745.35	20.9531
4747.95	26.2691
4750.55	21.2224
4753.15	26.4363
4755.75	23.6605
4758.35	39.0863
4760.95	30.6799
4763.54	45.0955
4766.14	19.6941
4768.73	25.2169
4771.33	43.3479
4773.92	16.8222
4776.51	16.5349
4779.1	47.0775
4781.69	-1.20349
4784.28	44.1968
4786.87	9.59399
4789.45	50.4614
4792.04	25.0034
4794.63	21.3029
4797.21	38.2443
4799.79	12.8535
4802.37	54.0241
4804.95	36.7442
4807.53	48.265
4810.11	0.015686
4812.69	21.9208
4815.27	24.2997
4817.84	24.4182
4820.42	25.7415
4822.99	38.6277
4825.57	63.1398
4828.14	28.5063
4830.71	29.8047
4833.28	13.7214
4835.85	20.9136
4838.42	29.3749
4840.98	6.3631
4843.55	21.8624
4846.12	26.7151
4848.68	45.5717
4851.24	21.9236
4853.81	-16.3628
4856.37	48.9169
4858.93	31.4493
4861.49	68.1171
4864.05	0.749695
4866.61	25.1571
4869.16	34.2705
4871.72	31.7177
4874.27	24.2332
4876.83	17.8301
4879.38	-8.76593
4881.93	3.73022
4884.49	51.8287
4887.04	35.7788
4889.58	-0.501526
4892.13	10.774
4894.68	30.3611
4897.23	30.8741
4899.77	24.2039
4902.32	34.1996
4904.86	53.7339
4907.4	7.58618
4909.95	1.97296
4912.49	3.35858
4915.03	23.7976
4917.57	11.9089
4920.1	34.7355
4922.64	3.79205
4925.18	39.7571
4927.71	7.6554
4930.25	19.6703
4932.78	47.4153
4935.31	13.1122
4937.84	30.1464
4940.38	13.6555
4942.9	-1.95935
4945.43	11.4065
4947.96	3.323
4950.49	10.7791
4953.01	8.70142
4955.54	11.3259
4958.06	-1.53143
4960.59	34.8889
4963.11	-4.30994
4965.63	5.9339
4968.15	13.9099
4970.67	18.0766
4973.19	-0.72168
4975.71	15.4554
4978.22	-3.42676
4980.74	34.5632
4983.25	12.0558
4985.77	24.6848
4988.28	8.21942
4990.79	13.5955
4993.3	26.2421
4995.81	9.67651
4998.32	-4.37946