File: Data/3-Raman/processed/bu19w-e-ff11-fi09-s_150 (500nm)_633nm_edge_100%_x100_vis_h50um_60sx2_01_0.txt
#Acq. time (s)=	60
#Accumulations=	2
#Range (cm-¹)=	100...4000
#Windows=	1
#Auto scanning=	Off
#Autofocus=	Off
#Macrospot=	Off
#AutoExposure=	Off
#Spike filter=	Multiple accum.
#Delay time (s)=	2
#Binning=	1
#Readout mode=	Signal
#DeNoise=	Off
#ICS correction=	On
#Dark correction=	Off
#Inst. Process=	Off
#Detector Gain=	Best Dynamic
#Detector ADC=	50 kHz HS
#Detector temperature (°C)=	-60.09
#Instrument=	LabRAM HR Evol
#Detector=	SIN-EM FIVIS
#Objective=	x100_VIS
#Grating=	150 (500nm)
#ND Filter=	100%
#Laser=	633nm_Edge
#Hole=	49.98
#Temperature=	0
#Range=	Visible
#StageXY=	75x50mm Scan+
#StageZ=	Z motor
#X (µm)=	0
#Y (µm)=	0
#Z (µm)=	-269.3
#Full time(mm:ss)=	2:04
#Project=	21_11_04
#Sample=	BU19w
#Site=
#Title=	BU19w-E-FF11-FI09-S_150 (500nm)_633nm_Edge_100%_x100_VIS_H50um_60sX2
#Remark=
#Date=	04.11.2021 16:13
#Acquired=	04.11.2021 16:13:38
#Base:Fit=	16.12.2021 17:39:50
#Base:Edit=	16.12.2021 17:51:44
#Base:Edit=	16.12.2021 17:51:45
#Base:Edit=	16.12.2021 17:51:46
#Base:Edit=	16.12.2021 17:51:47
#Base:Edit=	16.12.2021 17:51:47
#Base:Edit=	16.12.2021 17:51:47
#Base:Edit=	16.12.2021 17:51:48
#Base:Edit=	16.12.2021 17:51:49
#Base:Edit=	16.12.2021 17:51:49
#Base:Edit=	16.12.2021 17:51:50
#Base:Sub=	16.12.2021 17:51:55
102.881	188.752
109.397	156.827
115.908	142.021
122.414	119.416
128.914	136.82
135.409	147.311
141.898	144.111
148.383	132.092
154.861	183.03
161.335	192.54
167.801	90.4954
174.264	44.4575
180.721	14.1841
187.173	3.47824
193.62	0.831909
200.061	4.41682
206.496	8.58299
212.926	17.8566
219.352	75.168
225.772	225.107
232.185	298.646
238.595	134.854
244.999	72.4287
251.397	64.4739
257.791	89.9452
264.178	72.9837
270.561	77.1503
276.939	107.157
283.31	81.3238
289.678	48.0164
296.039	25.2506
302.396	57.5249
308.746	138.035
315.093	349.791
321.433	507.669
327.768	313.823
334.099	142.85
340.423	104.954
346.743	96.3249
353.058	118.799
359.367	125.195
365.671	74.2197
371.971	33.718
378.265	11.1414
384.553	-0.0769958
390.837	2.97884
397.116	12.7494
403.389	33.0377
409.657	29.7757
415.92	49.0649
422.178	95.7719
428.431	124.972
434.678	135.798
440.921	125.826
447.158	132.712
453.391	142.287
459.618	99.6755
465.84	40.6452
472.057	48.8531
478.27	34.8064
484.477	49.5979
490.679	52.2411
496.876	61.3851
503.068	93.8318
509.255	130.021
515.436	132.665
521.613	132.607
527.785	128.882
533.952	101.757
540.113	88.5537
546.27	65.6605
552.423	64.2106
558.568	45.639
564.711	34.3596
570.848	38.9549
576.979	38.6849
583.107	57.0986
589.228	103.464
595.345	120.026
601.458	129.377
607.565	134.311
613.667	129.988
619.764	105.147
625.856	92.4327
631.944	70.8666
638.026	78.176
644.104	73.8804
650.177	71.4291
656.244	74.441
662.308	39.9595
668.365	22.4489
674.418	18.2151
680.467	11.215
686.511	-0.409485
692.549	4.82594
698.582	7.26658
704.611	4.97524
710.635	8.2375
716.655	2.84301
722.669	6.83736
728.679	6.98199
734.683	-2.28986
740.683	4.34232
746.678	5.35917
752.669	4.54142
758.654	3.77466
764.635	5.95461
770.611	4.4541
776.582	1.98787
782.549	-5.27477
788.511	11.882
794.466	9.20675
800.419	6.44771
806.366	6.44457
812.309	11.1002
818.247	10.0387
824.18	15.5049
830.108	6.93777
836.033	20.0379
841.952	22.0839
847.865	22.2869
853.776	21.597
859.681	31.2945
865.58	41.9985
871.476	52.7274
877.366	57.6557
883.253	67.2579
889.134	70.1202
895.012	63.4145
900.883	52.7765
906.751	47.7639
912.614	43.6934
918.473	66.9692
924.326	60.3232
930.174	84.8908
936.019	114.389
941.859	153.823
947.693	189.837
953.525	204.241
959.35	237.675
965.171	272
970.988	367.655
976.801	497.58
982.608	526.816
988.411	461.788
994.209	347.147
1000	264.485
1005.79	257.543
1011.58	272.952
1017.36	305.825
1023.13	267.275
1028.9	201.128
1034.67	178.928
1040.43	161.513
1046.19	142.064
1051.94	123.326
1057.69	110.208
1063.44	104.656
1069.17	112.498
1074.91	145.572
1080.64	181.416
1086.37	246.251
1092.09	288.834
1097.8	308.119
1103.52	224.901
1109.22	156.502
1114.93	144.556
1120.63	133.739
1126.32	136.323
1132.01	173.202
1137.7	207.314
1143.38	275.952
1149.06	330.777
1154.73	247.572
1160.4	113.761
1166.06	79.234
1171.72	57.5853
1177.38	48.7181
1183.03	36.0348
1188.67	33.2807
1194.31	15.9627
1199.95	15.3341
1205.58	8.93254
1211.21	7.45583
1216.84	4.02738
1222.46	4.57584
1228.07	4.1284
1233.68	3.63147
1239.29	2.06201
1244.89	3.41956
1250.49	4.69891
1256.08	5.92304
1261.67	0.998795
1267.26	5.13795
1272.84	6.21101
1278.42	3.23529
1283.99	5.28745
1289.56	-0.631401
1295.12	1.50185
1300.68	9.67118
1306.23	2.91975
1311.78	2.25385
1317.33	2.6366
1322.87	0.0133591
1328.41	0.432556
1333.94	3.89179
1339.47	2.23086
1345	4.58316
1350.52	-3.34412
1356.04	9.20665
1361.55	0.152145
1367.06	1.31098
1372.56	7.57453
1378.06	8.69318
1383.56	5.69199
1389.05	4.73835
1394.53	1.76921
1400.02	7.09663
1405.5	2.13742
1410.97	4.39404
1416.44	1.51061
1421.91	-0.34708
1427.37	8.17559
1432.83	3.20573
1438.28	0.284569
1443.73	9.89352
1449.17	1.68727
1454.62	8.08199
1460.05	8.1294
1465.48	10.2328
1470.91	9.16428
1476.34	10.2051
1481.76	3.92151
1487.17	3.94995
1492.59	5.05723
1497.99	1.97776
1503.4	9.46326
1508.8	0.0613327
1514.19	0.181149
1519.59	8.84086
1524.97	5.80543
1530.36	2.74278
1535.74	6.12664
1541.11	2.98228
1546.48	6.22561
1551.85	7.19965
1557.21	5.91301
1562.57	11.1136
1567.93	11.9818
1573.28	9.60777
1578.62	10.5011
1583.97	13.5825
1589.3	5.91221
1594.64	2.56835
1599.97	8.95641
1605.3	9.98878
1610.62	8.90756
1615.94	11.1384
1621.25	11.2256
1626.56	13.4949
1631.87	10.2643
1637.17	8.05141
1642.47	3.49438
1647.76	4.46947
1653.05	15.3854
1658.34	10.7531
1663.62	1.64999
1668.9	4.72209
1674.18	11.111
1679.45	6.38969
1684.71	8.27567
1689.98	4.60805
1695.23	0.984177
1700.49	8.53443
1705.74	3.05141
1710.99	1.73047
1716.23	7.02942
1721.47	5.81599
1726.7	10.1037
1731.94	9.95054
1737.16	5.28293
1742.39	2.84435
1747.61	-4.13437
1752.82	13.711
1758.03	11.1805
1763.24	-2.72279
1768.44	11.6912
1773.64	6.86096
1778.84	2.05422
1784.03	10.9082
1789.22	7.30157
1794.41	12.8309
1799.59	1.24827
1804.76	2.24143
1809.94	3.2104
1815.11	12.2314
1820.27	5.12063
1825.43	-4.33012
1830.59	8.23214
1835.74	2.25423
1840.89	5.53781
1846.04	6.47532
1851.18	-4.2923
1856.32	0.107666
1861.45	12.778
1866.58	3.18309
1871.71	-2.93861
1876.83	7.39953
1881.95	7.12456
1887.07	5.6475
1892.18	1.74046
1897.29	0.189903
1902.39	4.63085
1907.49	-2.69525
1912.59	11.4232
1917.68	0.615028
1922.77	3.91656
1927.86	3.71375
1932.94	-1.28848
1938.02	0.879555
1943.09	5.4331
1948.16	1.54527
1953.23	12.0715
1958.29	-2.72225
1963.35	5.36422
1968.41	1.37352
1973.46	2.16875
1978.51	0.557526
1983.55	-1.05241
1988.59	-6.25586
1993.63	-9.03811
1998.66	1.42402
2003.69	1.0946
2008.72	-1.60453
2013.74	2.9425
2018.76	3.87177
2023.77	4.81842
2028.78	14.2706
2033.79	3.24422
2038.79	-4.17221
2043.79	2.96826
2048.79	0.422859
2053.78	2.70735
2058.77	7.47681
2063.76	-1.18089
2068.74	4.8521
2073.72	8.44536
2078.69	7.11512
2083.66	0.822403
2088.63	10.5432
2093.59	4.24723
2098.55	0.46299
2103.51	11.6098
2108.46	10.3698
2113.41	12.9108
2118.36	15.4865
2123.3	6.74336
2128.24	10.561
2133.17	14.3757
2138.11	1.68862
2143.03	5.46246
2147.96	11.7703
2152.88	5.29375
2157.79	2.60312
2162.71	6.26608
2167.62	-0.334267
2172.52	7.15731
2177.43	4.43627
2182.32	1.6577
2187.22	10.3747
2192.11	8.90704
2197	10.044
2201.89	7.39954
2206.77	-2.91708
2211.64	11.2388
2216.52	-1.62171
2221.39	-4.16511
2226.26	-0.230141
2231.12	11.5322
2235.98	-2.72496
2240.84	3.86301
2245.69	5.25133
2250.54	6.64671
2255.39	4.08963
2260.23	16.066
2265.07	0.26458
2269.9	-3.71124
2274.74	-1.09803
2279.57	4.14923
2284.39	6.69046
2289.21	14.5247
2294.03	18.3679
2298.84	3.61485
2303.66	-1.78204
2308.46	15.5682
2313.27	11.6357
2318.07	3.70947
2322.87	17.2583
2327.66	2.59579
2332.45	6.79873
2337.24	4.27141
2342.02	7.18762
2346.8	12.8981
2351.58	9.04115
2356.35	7.8556
2361.12	6.57546
2365.89	6.65695
2370.65	3.97113
2375.41	9.57664
2380.17	6.8456
2384.92	5.42821
2389.67	6.74657
2394.42	8.01573
2399.16	12.0261
2403.9	13.2418
2408.64	6.1273
2413.37	6.16168
2418.1	5.14384
2422.83	6.74948
2427.55	15.2148
2432.27	9.72264
2436.99	4.24419
2441.7	2.99272
2446.41	8.85057
2451.11	9.03342
2455.82	24.9583
2460.51	10.8052
2465.21	13.8532
2469.9	14.0023
2474.59	14.1316
2479.28	18.6314
2483.96	10.0211
2488.64	1.32839
2493.32	13.0541
2497.99	8.72196
2502.66	16.0857
2507.32	4.33781
2511.99	11.6596
2516.65	29.2923
2521.3	10.1064
2525.96	14.5152
2530.61	15.9702
2535.25	-0.33934
2539.89	26.4151
2544.53	20.5159
2549.17	11.6252
2553.8	10.1672
2558.43	14.6505
2563.06	17.6876
2567.68	10.238
2572.3	4.27667
2576.92	23.9917
2581.53	8.85103
2586.14	19.3898
2590.75	11.6298
2595.35	17.5923
2599.96	26.6732
2604.55	23.5213
2609.15	17.2827
2613.74	7.91819
2618.33	23.0342
2622.91	19.7947
2627.49	18.1107
2632.07	24.1974
2636.64	24.2476
2641.22	18.2011
2645.78	21.4304
2650.35	21.5392
2654.91	23.1492
2659.47	18.3794
2664.03	19.8017
2668.58	14.9522
2673.13	25.8722
2677.67	11.8781
2682.22	16.9342
2686.76	9.25191
2691.29	20.6125
2695.83	15.8073
2700.36	22.1376
2704.89	28.4767
2709.41	17.0906
2713.93	18.5599
2718.45	23.3259
2722.96	23.1989
2727.47	26.2368
2731.98	19.4669
2736.49	30.5425
2740.99	10.7311
2745.49	31.653
2749.98	20.0816
2754.47	31.5425
2758.96	31.4055
2763.45	26.2758
2767.93	19.5594
2772.41	22.6803
2776.89	32.5168
2781.36	20.9532
2785.84	21.0015
2790.3	22.7034
2794.77	32.7516
2799.23	27.6792
2803.69	15.7966
2808.14	8.86919
2812.59	5.26305
2817.04	20.1948
2821.49	13.1637
2825.93	23.0947
2830.37	10.9459
2834.81	12.3489
2839.24	22.2749
2843.67	11.7576
2848.1	1.24979
2852.53	16.4441
2856.95	9.44093
2861.37	19.6322
2865.78	14.4075
2870.19	14.3643
2874.6	7.36002
2879.01	7.3082
2883.41	2.04523
2887.81	23.0999
2892.21	12.5503
2896.6	9.02068
2901	5.49925
2905.38	10.7683
2909.77	8.89822
2914.15	8.70772
2918.53	17.4814
2922.91	13.746
2927.28	17.2562
2931.65	9.96297
2936.02	2.55495
2940.38	-8.60257
2944.74	2.02161
2949.1	12.6124
2953.46	6.82356
2957.81	21.1125
2962.16	-4.81003
2966.5	11.3808
2970.85	5.61836
2975.19	5.36809
2979.52	14.336
2983.86	-0.620895
2988.19	6.63643
2992.52	13.9758
2996.85	0.88298
3001.17	10.1853
3005.49	-4.7856
3009.8	12.1211
3014.12	8.34637
3018.43	12.2033
3022.74	12.2819
3027.04	16.0746
3031.34	15.9971
3035.64	21.5867
3039.94	17.5888
3044.23	23.1931
3048.52	23.0043
3052.81	34.3844
3057.09	28.4461
3061.38	32.157
3065.65	33.9464
3069.93	22.1436
3074.2	41.4548
3078.47	27.7088
3082.74	29.5432
3087	23.6398
3091.27	53.1468
3095.52	51.4134
3099.78	39.8176
3104.03	40.0925
3108.28	46.405
3112.53	52.8195
3116.77	53.2579
3121.01	47.699
3125.25	58.3433
3129.49	63.0595
3133.72	76.0647
3137.95	74.8037
3142.18	59.0198
3146.4	63.7173
3150.62	66.306
3154.84	58.3378
3159.06	64.9242
3163.27	94.6265
3167.48	67.6798
3171.69	89.0769
3175.89	76.6839
3180.09	83.1312
3184.29	95.8794
3188.49	85.2346
3192.68	98.0676
3196.87	98.3127
3201.06	79.697
3205.24	84.625
3209.42	81.1055
3213.6	81.9179
3217.78	87.1364
3221.95	57.4572
3226.12	77.8634
3230.29	67.6641
3234.45	63.9654
3238.61	60.214
3242.77	69.8765
3246.93	55.1298
3251.08	69.177
3255.23	62.921
3259.38	38.6723
3263.53	46.0467
3267.67	37.9924
3271.81	34.1978
3275.95	27.7791
3280.08	37.2517
3284.21	28.4153
3288.34	49.4211
3292.47	31.3416
3296.59	43.166
3300.71	27.3771
3304.83	25.4095
3308.95	39.6835
3313.06	28.4021
3317.17	33.4173
3321.27	47.8481
3325.38	25.0116
3329.48	32.6015
3333.58	26.3113
3337.67	53.0521
3341.77	37.1088
3345.86	11.4939
3349.95	49.8995
3354.03	12.2577
3358.11	27.0764
3362.19	34.8033
3366.27	30.5519
3370.34	35.905
3374.42	24.3737
3378.48	17.5589
3382.55	39.6695
3386.61	18.3265
3390.68	35.617
3394.73	21.4812
3398.79	29.2128
3402.84	27.1907
3406.89	20.2658
3410.94	3.58244
3414.98	28.2572
3419.03	28.618
3423.06	24.0852
3427.1	34.2263
3431.14	24.9194
3435.17	32.7742
3439.2	33.3701
3443.22	14.3669
3447.25	22.4663
3451.27	18.2899
3455.28	16.6461
3459.3	15.0945
3463.31	23.5269
3467.32	7.01997
3471.33	7.92778
3475.34	31.3524
3479.34	4.53258
3483.34	15.4971
3487.33	16.3529
3491.33	27.3747
3495.32	28.2056
3499.31	11.0816
3503.3	4.06837
3507.28	17.5015
3511.26	5.16075
3515.24	3.0484
3519.22	16.3495
3523.19	9.09131
3527.16	14.7342
3531.13	2.34398
3535.1	10.7487
3539.06	16.7149
3543.02	4.50433
3546.98	7.76318
3550.93	18.7575
3554.89	14.0017
3558.84	11.9685
3562.78	36.0538
3566.73	23.7377
3570.67	11.463
3574.61	27.9668
3578.55	23.5932
3582.48	13.9883
3586.41	12.2738
3590.35	13.1868
3594.27	19.4166
3598.2	25.6699
3602.12	-2.87366
3606.04	8.62915
3609.95	-9.42336
3613.87	2.05795
3617.78	-2.63443
3621.69	16.89
3625.6	17.3981
3629.5	-6.45882
3633.4	-3.32384
3637.3	5.29623
3641.2	5.91705
3645.09	-12.4038
3648.98	-25.4224
3652.87	5.05215
3656.76	-13.5171
3660.64	3.34262
3664.53	1.09253
3668.4	-1.11775
3672.28	-11.5594
3676.16	-13.7319
3680.03	-21.3429
3683.9	-1.40572
3687.76	-0.629181
3691.63	-5.37935
3695.49	0.886047
3699.35	9.99059
3703.2	-0.41069
3707.06	-2.44994
3710.91	-15.7312
3714.76	-6.6167
3718.6	-14.4332
3722.45	0.275269
3726.29	-16.1227
3730.13	-18.4156
3733.97	10.5366
3737.8	2.6041
3741.63	-2.54181
3745.46	0.835861
3749.29	1.32643
3753.11	-3.95563
3756.93	2.15804
3760.75	-0.353302
3764.57	-5.74892
3768.39	-5.40202
3772.2	-13.6245
3776.01	3.99164
3779.81	-9.95447
3783.62	-3.72853
3787.42	-9.01357
3791.22	0.0990601
3795.02	3.50533
3798.81	6.96716
3802.61	1.74409
3806.4	-9.2998
3810.18	0.0314484
3813.97	-2.32721
3817.75	1.15564
3821.53	4.63638
3825.31	5.14989
3829.09	11.5632
3832.86	-20.3166
3836.63	-2.07701
3840.4	16.1999
3844.17	-12.8587
3847.93	5.35999
3851.69	8.73836
3855.45	12.0913
3859.21	3.50186
3862.96	-13.9617
3866.71	-4.46295
3870.46	-6.7675
3874.21	2.62816
3877.95	0.104385
3881.69	-8.38623
3885.44	4.10226
3889.17	10.6609
3892.91	-6.70842
3896.64	12.0286
3900.37	3.70943
3904.1	1.40149
3907.82	11.1736
3911.55	21.0255
3915.27	3.6954
3918.99	10.6562
3922.7	-0.531876
3926.42	3.47668
3930.13	-4.7238
3933.84	-16.0432
3937.54	9.39343
3941.25	13.4925
3944.95	8.45284
3948.65	-2.76593
3952.35	-7.85655
3956.04	17.9727
3959.73	25.2814
3963.42	17.1293
3967.11	2.77679
3970.8	25.6198
3974.48	26.8416
3978.16	15.698
3981.84	16.9681
3985.52	15.1942
3989.19	19.6848
3992.86	24.2938
3996.53	22.8161
3998.37	32.9897