File: Data/3-Raman/processed/bu19w-b-ff1-fi10-v_150 (500nm)_532nm_edge_100%_x100_vis_h50um_15sx2_02.txt
#Acq. time (s)=	15
#Accumulations=	2
#Range (cm-¹)=	100...5000
#Windows=	1
#Auto scanning=	Off
#Autofocus=	Off
#Macrospot=	Off
#AutoExposure=	Off
#Spike filter=	Multiple accum.
#Delay time (s)=	2
#Binning=	1
#Readout mode=	Signal
#DeNoise=	Off
#ICS correction=	On
#Dark correction=	Off
#Inst. Process=	Off
#Detector Gain=	Best Dynamic
#Detector ADC=	50 kHz HS
#Detector temperature (°C)=	-60.09
#Instrument=	LabRAM HR Evol
#Detector=	SIN-EM FIVIS
#Objective=	x100_VIS
#Grating=	150 (500nm)
#ND Filter=	100%
#Laser=	532nm_Edge
#Hole=	49.98
#Temperature=	0
#Range=	Visible
#StageXY=	75x50mm Scan+
#StageZ=	Z motor
#X (µm)=	0
#Y (µm)=	0
#Z (µm)=	-186
#Full time(s)=	34
#Project=	21_05_14
#Sample=	BU19w
#Site=
#Title=	BU19w-FF1-FI10-V_150 (500nm)_532nm_Edge_100%_x100_VIS_H50um_15sX2
#Remark=
#Date=	14.05.2021 16:29
#Acquired=	14.05.2021 16:29:44
#Base:Fit=	22.12.2021 12:22:35
#Base:Edit=	22.12.2021 12:26:32
#Base:Edit=	22.12.2021 12:26:32
#Base:Edit=	22.12.2021 12:26:33
#Base:Edit=	22.12.2021 12:26:34
#Base:Edit=	22.12.2021 12:26:35
#Base:Edit=	22.12.2021 12:26:37
#Base:Sub=	22.12.2021 12:26:40
#Data Range:Extract=	22.12.2021 12:27:19
102.699	595.07
107.322	548.533
111.942	435.934
116.56	315.02
121.173	283.51
125.787	187.573
130.398	175.611
135.006	193.562
139.613	150.557
144.215	114.033
148.817	134.203
153.417	425.956
158.014	920.003
162.607	770.91
167.2	296.735
171.79	193.019
176.379	317.366
180.963	1245.74
185.547	2957.13
190.128	2188.11
194.705	651.02
199.282	181.967
203.857	-5.79126
208.43	39.0054
212.998	48.469
217.566	-3.10449
222.132	-20.3676
226.693	39.1149
231.254	189.958
235.813	267.517
240.368	465.295
244.923	764.026
249.475	569.72
254.023	391.743
258.571	268.776
263.117	191.185
267.658	475.41
272.199	1382.72
276.738	2643.96
281.273	2186.91
285.807	960.044
290.34	546.769
294.868	627.024
299.396	1127.81
303.919	1244.25
308.443	691.781
312.964	324.928
317.481	274.934
321.998	443.847
326.51	752.629
331.023	655.604
335.533	363.406
340.039	257.532
344.544	379.817
349.046	513.375
353.547	365.406
358.045	146.517
362.542	67.7656
367.036	134.663
371.527	116.466
376.017	160.323
380.503	217.317
384.99	387.498
389.471	534.797
393.953	579.373
398.43	424.981
402.908	290.754
407.381	262.285
411.854	379.672
416.323	463.736
420.791	257.087
425.256	57.8978
429.72	29.4794
434.18	1.30469
438.64	14.9111
443.095	87.3187
447.551	276.759
452.003	676.506
456.454	804.355
460.901	434.267
465.348	170.843
469.791	110.626
474.231	121.942
478.672	115.284
483.108	271.092
487.544	291.742
491.976	407.134
496.408	356.213
500.836	356.544
505.261	227.818
509.687	151.941
514.108	115.6
518.529	109.357
522.946	141.091
527.361	140.533
531.776	141.729
536.187	161.556
540.595	172.076
545.003	175.546
549.408	212.714
553.812	208.376
558.212	205.769
562.61	235.48
567.007	202.469
571.401	131.088
575.792	100.42
580.184	255.174
584.571	691.661
588.956	1065.51
593.341	703.715
597.722	375.573
602.101	309.27
606.48	574.076
610.854	687.975
615.227	567.076
619.597	300.232
623.967	90.1396
628.334	102.055
632.698	99.6099
637.06	244.628
641.422	191.982
645.779	70.7054
650.135	125.904
654.491	143.637
658.842	196.433
663.192	273.02
667.539	341.955
671.884	375.798
676.23	399.078
680.571	351.135
684.91	200.105
689.247	93.2445
693.583	121.967
697.916	17.04
702.247	31.9369
706.576	25.7836
710.902	3.00757
715.229	-51.5375
719.551	-46.866
723.872	18.1005
728.19	40.7358
732.506	17.4453
736.82	33.4532
741.134	0.646973
745.444	7.97632
749.752	39.787
754.058	109.273
758.362	108.408
762.664	240.262
766.964	441.97
771.264	705.563
775.559	1063.68
779.853	1126.61
784.144	737.536
788.434	494.869
792.722	303.887
797.007	202.013
801.29	197.847
805.572	109.068
809.851	58.073
814.13	92.2747
818.406	71.3281
822.679	36.6711
826.95	18.7905
831.219	79.2532
835.486	92.2454
839.752	28.9561
844.015	23.6533
848.276	22.2708
852.535	38.3411
856.792	43.3813
861.047	18.447
865.3	45.5825
869.551	27.1233
873.8	53.0649
878.047	31.4224
882.292	35.2161
886.534	37.9758
890.775	12.5483
895.014	31.5498
899.251	24.2014
903.486	7.62402
907.719	74.334
911.95	83.01
916.179	50.0984
920.406	35.6853
924.63	51.5371
928.853	84.6658
933.074	69.7244
937.293	115.096
941.51	169.663
945.723	191.531
949.936	241.795
954.147	252.795
958.356	243.893
962.563	243.823
966.768	293.81
970.971	266.96
975.172	196.894
979.371	104.241
983.568	120.882
987.761	85.2288
991.954	38.4548
996.145	78.2947
1000.33	65.8831
1004.52	73.9163
1008.71	70.8403
1012.89	84.9971
1017.07	74.646
1021.25	150.625
1025.43	189.037
1029.6	137.812
1033.77	244.236
1037.95	327.583
1042.11	484.466
1046.28	921.407
1050.45	1428.22
1054.61	1476.47
1058.77	1072.68
1062.93	694.861
1067.09	491.221
1071.24	394.765
1075.4	473.664
1079.55	715.82
1083.7	1020.62
1087.85	1448.93
1091.99	1501.89
1096.14	1239.32
1100.28	972.363
1104.42	1142.17
1108.55	1258.89
1112.69	1285
1116.82	1069.62
1120.96	935.756
1125.09	948.385
1129.21	1047.05
1133.34	1083.78
1137.46	814.532
1141.59	618.722
1145.71	545.444
1149.83	587.777
1153.94	825.462
1158.06	915.373
1162.17	751.016
1166.28	572.732
1170.39	383.081
1174.5	327.953
1178.6	189.368
1182.7	172.307
1186.8	158.409
1190.9	184.735
1195	181.455
1199.1	200.692
1203.19	189.961
1207.28	116.435
1211.37	146.62
1215.46	168.632
1219.54	268.499
1223.63	299.884
1227.71	216.163
1231.79	254.761
1235.87	354.774
1239.95	442.477
1244.02	379.788
1248.09	282.317
1252.16	223.484
1256.23	92.1658
1260.3	138.093
1264.36	156.523
1268.43	605.503
1272.49	811.836
1276.55	312.556
1280.6	73.4048
1284.66	124.786
1288.71	88.5881
1292.76	24.5295
1296.81	30.8372
1300.86	80.0269
1304.91	109.604
1308.95	79.8306
1312.99	47.1077
1317.03	89.0393
1321.07	48.0608
1325.11	36.8267
1329.14	96.4749
1333.18	55.5686
1337.21	78.2612
1341.24	114.532
1345.26	102.584
1349.29	101.694
1353.31	48.207
1357.33	71.2976
1361.35	101.154
1365.37	96.1343
1369.39	200.035
1373.4	1306.6
1377.41	1152.9
1381.43	283.959
1385.43	45.1011
1389.44	51.7217
1393.45	120.594
1397.45	183.19
1401.45	104.319
1405.45	7.03955
1409.45	110.088
1413.44	10.2026
1417.44	46.3613
1421.43	77.4597
1425.42	50.3406
1429.41	83.5083
1433.39	70.0369
1437.38	33.4033
1441.36	32.4143
1445.34	27.8743
1449.32	40.0215
1453.3	-5.6311
1457.27	41.1816
1461.24	53.6096
1465.22	36.877
1469.19	29.3201
1473.15	67.9888
1477.12	11.8425
1481.09	19.2998
1485.05	29.4478
1489.01	-12.1914
1492.97	48.8994
1496.93	8.63135
1500.88	10.7756
1504.83	-13.6724
1508.79	17.8694
1512.74	-11.7908
1516.68	8.37036
1520.63	48.1733
1524.57	-25.334
1528.52	10.0852
1532.46	31.197
1536.4	19.356
1540.33	17.2988
1544.27	5.53125
1548.2	40.29
1552.14	-4.56836
1556.07	43.0845
1559.99	8.05933
1563.92	76.2769
1567.84	22.3494
1571.77	14.7349
1575.69	72.7102
1579.61	60.0588
1583.52	3.92188
1587.44	65.1592
1591.35	66.6165
1595.27	68.9893
1599.18	23.478
1603.09	70.5442
1606.99	30.5642
1610.9	55.875
1614.8	30.7493
1618.7	59.4023
1622.6	70.8359
1626.5	15.8545
1630.39	41.8923
1634.29	13.887
1638.18	30.0117
1642.07	25.0579
1645.96	-13.1016
1649.85	65.9216
1653.73	19.2285
1657.62	-3.75293
1661.5	27.7029
1665.38	34.6187
1669.26	57.2983
1673.13	29.3276
1677.01	17.8774
1680.88	-5.55518
1684.75	3.36841
1688.62	35.781
1692.49	13.9351
1696.35	45.2251
1700.22	52.8987
1704.08	130.344
1707.94	115.573
1711.8	47.4497
1715.66	60.2109
1719.51	48.438
1723.37	79.0007
1727.22	92.0452
1731.07	26.0781
1734.92	110.211
1738.76	23.4592
1742.61	33.0234
1746.45	64.1533
1750.29	60.613
1754.13	74.1941
1757.97	38.6423
1761.81	-5.69873
1765.64	22.0396
1769.47	47.1228
1773.31	5.89282
1777.14	1.40601
1780.96	70.5703
1784.79	5.73242
1788.61	11.1353
1792.43	76.6707
1796.25	93.5447
1800.07	29.2896
1803.89	-38.1931
1807.71	34.5149
1811.52	64.3774
1815.33	-9.60693
1819.14	17.158
1822.95	87.6431
1826.76	18.7041
1830.56	69.6072
1834.37	76.4548
1838.17	48.9263
1841.97	88.4534
1845.77	61.1382
1849.56	28.606
1853.36	54.7625
1857.15	71.5469
1860.94	93.1604
1864.73	47.8477
1868.52	25.3521
1872.31	63.6033
1876.09	44.877
1879.87	98.0669
1883.66	33.9587
1887.43	85.2881
1891.21	26.1824
1894.99	28.5081
1898.76	54.7014
1902.53	15.677
1906.31	47.9314
1910.08	67.2422
1913.84	32.8442
1917.61	78.1748
1921.37	60.0427
1925.14	-26.4131
1928.9	-10.54
1932.66	46.4343
1936.41	-39.2153
1940.17	5.58838
1943.92	16.5847
1947.68	29.4766
1951.43	58.0596
1955.18	19.4036
1958.92	45.7512
1962.67	11.7041
1966.41	56.1687
1970.16	140.164
1973.9	92.1519
1977.64	66.0178
1981.37	80.5967
1985.11	62.783
1988.84	74.5864
1992.57	65.042
1996.31	82.8464
2000.03	80.6572
2003.76	71.5559
2007.49	75.0828
2011.21	24.1316
2014.93	8.23682
2018.65	59.7595
2022.37	16.45
2026.09	78.4844
2029.81	40.9739
2033.52	41.4895
2037.23	1.69775
2040.94	27.1133
2044.65	11.7534
2048.36	-30.345
2052.07	49.814
2055.77	40.8237
2059.47	-4.87231
2063.17	7.43604
2066.87	23.8701
2070.57	43.2563
2074.27	66.5039
2077.96	55.0569
2081.65	46.2498
2085.34	36.2942
2089.03	42.2883
2092.72	63.9858
2096.41	62.2349
2100.09	33.6377
2103.77	38.9106
2107.46	28.6997
2111.14	59.1028
2114.81	-11.916
2118.49	76.8093
2122.16	41.552
2125.84	69.1431
2129.51	96.0281
2133.18	115.368
2136.85	45.5293
2140.51	93.2578
2144.18	88.946
2147.84	0.942871
2151.5	98.5635
2155.16	87.9951
2158.82	86.8291
2162.48	60.7239
2166.13	45.2617
2169.79	61.8308
2173.44	67.072
2177.09	28.8906
2180.74	87.5168
2184.38	126.134
2188.03	70.9404
2191.67	89.7666
2195.32	66.2209
2198.96	77.6172
2202.6	64.9358
2206.23	22.6907
2209.87	19.3357
2213.5	30.979
2217.14	70.2776
2220.77	10.582
2224.4	58.4685
2228.03	64.7825
2231.65	58.5762
2235.28	58.9377
2238.9	41.5103
2242.52	84.3247
2246.14	49.1658
2249.76	59.9231
2253.38	21.668
2256.99	9.57813
2260.6	28.0149
2264.21	53.928
2267.82	5.63159
2271.44	96.4382
2275.04	-20.321
2278.65	48.0906
2282.25	-0.319092
2285.85	45.5261
2289.45	16.1111
2293.05	35.7466
2296.65	41.4604
2300.25	-8.96069
2303.84	25.0488
2307.43	-7.85449
2311.02	-52.6008
2314.62	4.44458
2318.2	147.947
2321.79	68.1936
2325.38	50.3484
2328.96	18.5317
2332.54	76.6404
2336.12	45.6829
2339.7	85.8171
2343.28	86.0203
2346.85	10.8457
2350.43	70.4983
2354	84.9065
2357.57	64.551
2361.14	13.4399
2364.71	67.5476
2368.27	66.4819
2371.84	46.4285
2375.4	24.2324
2378.96	26.5452
2382.52	25.5884
2386.08	75.6604
2389.64	-20.5217
2393.19	69.6694
2396.75	7.91187
2400.3	-15.5232
2403.85	6.3938
2407.4	5.17261
2410.95	28.4189
2414.49	1.84644
2418.04	66.1702
2421.58	14.3569
2425.12	41.7969
2428.66	-13.0286
2432.2	-21.9324
2435.74	6.87158
2439.27	-27.1987
2442.81	16.2017
2446.34	-7.09009
2449.87	35.0139
2453.4	27.4692
2456.93	22.3159
2460.45	55.0901
2463.98	68.6531
2467.5	89.3687
2471.02	3.62573
2474.54	39.5815
2478.06	12.752
2481.58	23.9231
2485.09	67.8486
2488.61	27.0601
2492.12	34.6812
2495.63	47.8755
2499.14	67.2637
2502.65	8.56348
2506.15	66.178
2509.66	31.113
2513.16	65.7212
2516.66	22.1506
2520.16	37.2131
2523.66	23.6838
2527.16	60.9727
2530.66	-25.947
2534.15	41.5195
2537.64	51.5564
2541.13	62.2461
2544.62	18.6052
2548.11	40.8796
2551.6	45.2615
2555.08	-14.8787
2558.57	52.8474
2562.05	-14.353
2565.53	41.4602
2569.01	-5.96899
2572.49	10.7756
2575.96	-1.63037
2579.44	11.679
2582.91	7.28271
2586.38	8.07104
2589.85	41.1665
2593.32	16.9167
2596.79	32.7371
2600.25	42.2544
2603.72	-3.52148
2607.18	36.1917
2610.64	32.7041
2614.1	3.93457
2617.56	55.5093
2621.02	43.9075
2624.47	82.1663
2627.92	29.5205
2631.38	-24.783
2634.83	73.2517
2638.28	68.9055
2641.72	29.2329
2645.17	55.4429
2648.61	42.7002
2652.06	46.1929
2655.5	64.9202
2658.94	86.947
2662.38	29.9031
2665.82	104.285
2669.25	127.046
2672.69	75.1611
2676.12	39.0081
2679.55	132.813
2682.98	3.18994
2686.41	118.641
2689.84	90.9163
2693.26	23.0425
2696.69	106.797
2700.11	36.6616
2703.53	17.782
2706.95	65.0767
2710.37	56.6746
2713.79	43.4314
2717.2	34.6873
2720.62	58.2456
2724.03	71.8799
2727.44	58.8655
2730.85	-9.60571
2734.26	-20.1643
2737.66	12.4512
2741.07	8.82593
2744.47	81.4739
2747.87	42.4211
2751.28	62.5146
2754.67	-21.6892
2758.07	82.907
2761.47	88.5354
2764.86	0.368164
2768.26	77.2761
2771.65	108.756
2775.04	62.3552
2778.43	85.0852
2781.82	12.4033
2785.2	115.553
2788.59	27.7083
2791.97	64.6091
2795.35	33.3137
2798.73	29.385
2802.11	28.3203
2805.49	91.9033
2808.87	103.692
2812.24	46.115
2815.62	41.5684
2818.99	34.7576
2822.36	34.2075
2825.73	87.9963
2829.1	64.7871
2832.46	62.8301
2835.83	82.9209
2839.19	89.7646
2842.55	38.6934
2845.91	94.99
2849.27	-16.7124
2852.63	46.1736
2855.99	73.1375
2859.34	53.052
2862.69	57.4321
2866.05	32.0142
2869.4	33.4868
2872.75	63.0562
2876.09	5.05444
2879.44	109.881
2882.78	43.0068
2886.13	55.0144
2889.47	44.6589
2892.81	37.929
2896.15	76.1023
2899.49	0.216553
2902.82	37.2954
2906.16	72.2458
2909.49	61.376
2912.82	55.2427
2916.16	53.1626
2919.49	144.463
2922.81	124.052
2926.14	94.4216
2929.46	120.389
2932.79	166.232
2936.11	147.888
2939.43	136.184
2942.75	61.467
2946.07	126.385
2949.39	91.438
2952.7	32.9224
2956.02	68.0476
2959.33	84.0371
2962.64	108.356
2965.95	101.631
2969.26	119.859
2972.57	147.748
2975.87	116.139
2979.17	60.2664
2982.48	114.395
2985.78	74.0227
2989.08	109.815
2992.38	82.8579
2995.68	148.262
2998.97	92.499
3002.27	133.387
3005.56	5.28955
3008.85	35.4407
3012.14	1.75684
3015.43	54.6653
3018.72	64.1824
3022	71.8044
3025.29	94.6394
3028.57	69.314
3031.85	45.699
3035.14	98.4734
3038.41	39.7158
3041.69	109.647
3044.97	80.3784
3048.24	108.734
3051.52	26.4385
3054.79	65.365
3058.06	45.0813
3061.33	116.903
3064.6	136.9
3067.87	23.532
3071.13	54.4668
3074.4	87.2715
3077.66	21.4939
3080.92	73.3857
3084.18	56.7761
3087.44	155.716
3090.7	89.2925
3093.95	80.9854
3097.21	86.4666
3100.46	72.0181
3103.71	82.4675
3106.96	133.093
3110.21	60.8379
3113.46	79.8669
3116.71	41.9446
3119.95	106.91
3123.2	68.9834
3126.44	126.224
3129.68	112.991
3132.92	51.0991
3136.16	100.554
3139.4	110.845
3142.63	159.267
3145.87	110.63
3149.1	121.255
3152.33	152.76
3155.56	164.299
3158.79	120.431
3162.02	118.549
3165.25	188.961
3168.47	140.754
3171.69	119.114
3174.92	158.269
3178.14	112.384
3181.36	240.205
3184.58	124.5
3187.79	180.268
3191.01	160.693
3194.22	144.911
3197.43	118.575
3200.65	186.618
3203.86	177.659
3207.07	177.426
3210.27	129.846
3213.48	163.424
3216.69	123.812
3219.89	154.669
3223.09	159.227
3226.29	157.247
3229.49	160.328
3232.69	173.643
3235.89	209.453
3239.08	149.472
3242.28	149.668
3245.47	202.29
3248.66	212.356
3251.85	183.498
3255.04	237.672
3258.23	173.088
3261.42	237.852
3264.6	181.759
3267.79	213.141
3270.97	199.345
3274.15	184.601
3277.33	230.416
3280.51	140.823
3283.68	191.553
3286.86	203.783
3290.04	197.161
3293.21	211.474
3296.38	206.583
3299.55	253.073
3302.72	202.796
3305.89	224.427
3309.06	235.031
3312.22	223.465
3315.39	194.743
3318.55	234.193
3321.71	256.531
3324.87	252.358
3328.03	201.905
3331.19	244.352
3334.34	260.592
3337.5	214.854
3340.65	303.107
3343.81	238.293
3346.96	199.071
3350.11	257.941
3353.25	265.326
3356.4	275.72
3359.55	292.219
3362.69	263.594
3365.84	287.964
3368.98	252.067
3372.12	283.572
3375.26	253.913
3378.4	269.827
3381.53	365.901
3384.67	329.937
3387.8	351.722
3390.94	361.407
3394.07	375.331
3397.2	337.043
3400.33	412.208
3403.46	498.322
3406.58	575.358
3409.71	761.189
3412.83	1254.09
3415.96	2521.34
3419.08	5161.79
3422.2	6358.93
3425.32	4192.81
3428.44	1961.55
3431.55	1097.32
3434.67	705.457
3437.78	465.862
3440.89	438.402
3444	444.478
3447.12	354.179
3450.22	425.385
3453.33	410.757
3456.44	327.081
3459.54	376.545
3462.65	330.774
3465.75	293.329
3468.85	303.235
3471.95	384.256
3475.05	392.591
3478.15	366.11
3481.24	427.647
3484.34	397.685
3487.43	525.724
3490.53	642.599
3493.62	756.721
3496.71	925.991
3499.79	1159.64
3502.88	1355.45
3505.97	1348.86
3509.05	1135.53
3512.14	868.432
3515.22	617.349
3518.3	471.789
3521.38	448.438
3524.46	394.626
3527.54	335.834
3530.61	352.998
3533.69	273.847
3536.76	307.339
3539.83	252.612
3542.9	185.908
3545.97	205.283
3549.04	194.888
3552.11	270.819
3555.18	197.861
3558.24	209.446
3561.3	177.646
3564.37	212.821
3567.43	168.551
3570.49	134.118
3573.55	161.889
3576.61	193.321
3579.66	175.167
3582.72	141.528
3585.77	129.615
3588.82	195.145
3591.87	131.558
3594.92	127.459
3597.97	116.66
3601.02	168.117
3604.07	205.985
3607.11	186.029
3610.16	136.66
3613.2	176.94
3616.24	157.757
3619.28	156.674
3622.32	156.644
3625.36	165.29
3628.39	94.7273
3631.43	117.23
3634.46	98.8213
3637.5	64.9692
3640.53	63.458
3643.56	145.531
3646.59	129.259
3649.62	102.1
3652.64	123.234
3655.67	120.358
3658.69	103.32
3661.72	96.177
3664.74	104.636
3667.76	80.2393
3670.78	124.989
3673.79	68.031
3676.81	37.6462
3679.83	124.3
3682.84	85.281
3685.86	68.9956
3688.87	42.363
3691.88	65.0525
3694.89	98.6116
3697.9	68.075
3700.91	81.3359
3703.91	73.7166
3706.92	89.5566
3709.92	85.1873
3712.92	42.3682
3715.92	112.841
3718.92	74.6216
3721.92	59.8904
3724.92	124.86
3727.92	111.525
3730.91	48.3906
3733.91	71.5774
3736.9	18.3198
3739.89	69.4292
3742.88	72.658
3745.87	39.4617
3748.86	75.4077
3751.85	58.0259
3754.83	37.8838
3757.82	92.666
3760.8	79.8489
3763.78	119.114
3766.76	58.1946
3769.74	49.6477
3772.72	112.263
3775.7	55.9358
3778.67	45.2068
3781.65	78.9419
3784.62	41.0452
3787.6	80.7219
3790.57	63.2373
3793.54	114.969
3796.51	49.8345
3799.47	69.075
3802.44	97.0471
3805.41	101.512
3808.37	33.3887
3811.33	108.068
3814.3	46.6807
3817.26	76.1973
3820.22	93.5017
3823.18	72.1858
3826.13	51.8792
3829.09	74.178
3832.04	-13.3528
3835	21.6946
3837.95	69.1865
3840.9	53.949
3843.85	33.0129
3846.8	74.0537
3849.75	98.1709
3852.69	38.4573
3855.64	70.3445
3858.58	58.3804
3861.53	61.5435
3864.47	6.29663
3867.41	128.011
3870.35	66.6414
3873.29	73.2173
3876.22	41.1038
3879.16	76.8523
3882.1	23.866
3885.03	-1.54126
3887.96	81.54
3890.89	97.2361
3893.82	72.2251
3896.75	97.791
3899.68	54.0483
3902.61	17.5911
3905.53	25.6455
3908.46	49.8989
3911.38	50.8247
3914.3	70.6094
3917.23	39.0681
3920.15	95.4946
3923.06	30.5916
3925.98	18.2256
3928.9	63.0867
3931.81	44.2539
3934.73	85.396
3937.64	-10.6743
3940.55	71.196
3943.46	51.614
3946.37	54.3242
3949.28	64.9443
3952.19	41.2026
3955.09	78.0483
3958	5.84546
3960.9	86.1235
3963.8	56.354
3966.71	101.536
3969.61	29.7937
3972.51	53.9819
3975.4	25.2078
3978.3	27.9067
3981.2	109.375
3984.09	47.4729
3986.99	59.5894
3989.88	84.6917
3992.77	28.5054
3995.66	65.6621
3998.55	77.9421
4001.43	72.9326