File: Data/3-Raman/processed/bu19w-b-ff1-fi04-s_150 (500nm)_532nm_edge_100%_x100_vis_h50um_15sx2_01.txt
#Acq. time (s)=	15
#Accumulations=	2
#Range (cm-¹)=	100...5000
#Windows=	1
#Auto scanning=	Off
#Autofocus=	Off
#Macrospot=	Off
#AutoExposure=	Off
#Spike filter=	Multiple accum.
#Delay time (s)=	2
#Binning=	1
#Readout mode=	Signal
#DeNoise=	Off
#ICS correction=	On
#Dark correction=	Off
#Inst. Process=	Off
#Detector Gain=	Best Dynamic
#Detector ADC=	50 kHz HS
#Detector temperature (°C)=	-60.09
#Instrument=	LabRAM HR Evol
#Detector=	SIN-EM FIVIS
#Objective=	x100_VIS
#Grating=	150 (500nm)
#ND Filter=	100%
#Laser=	532nm_Edge
#Hole=	49.98
#Temperature=	0
#Range=	Visible
#StageXY=	75x50mm Scan+
#StageZ=	Z motor
#X (µm)=	0
#Y (µm)=	0
#Z (µm)=	-143.1
#Full time(s)=	34
#Project=	21_05_14
#Sample=	BU19w
#Site=
#Title=	BU19w-FF1-FI04-S_150 (500nm)_532nm_Edge_100%_x100_VIS_H50um_15sX2
#Remark=
#Date=	14.05.2021 14:16
#Acquired=	14.05.2021 14:16:00
#Base:Fit=	22.12.2021 12:22:35
#Base:Edit=	22.12.2021 12:24:42
#Base:Edit=	22.12.2021 12:24:43
#Base:Edit=	22.12.2021 12:24:45
#Base:Sub=	22.12.2021 12:24:48
#Data Range:Extract=	22.12.2021 12:27:19
102.699	287.757
107.322	223.378
111.942	164.674
116.56	89.8618
121.173	0.12207
125.787	118.033
130.398	138.097
135.006	122.682
139.613	48.9353
144.215	29.6331
148.817	-48.4509
153.417	70.5222
158.014	533.026
162.607	1492.65
167.2	1229.99
171.79	449.505
176.379	205.875
180.963	448.358
185.547	1436.02
190.128	3024.6
194.705	2380.92
199.282	788.15
203.857	137.156
208.43	-4.76538
212.998	-53.5515
217.566	10.3232
222.132	30.2466
226.693	-28.4548
231.254	9.14819
235.813	200.794
240.368	342.804
244.923	512.743
249.475	836.771
254.023	551.857
258.571	311.248
263.117	202.586
267.658	385.442
272.199	563.462
276.738	1422.57
281.273	2875.05
285.807	3031.29
290.34	2029.02
294.868	953.955
299.396	790.425
303.919	1427.3
308.443	1515.08
312.964	784.699
317.481	395.015
321.998	320.843
326.51	469.567
331.023	807.198
335.533	883.236
340.039	513.529
344.544	314.281
349.046	511.703
353.547	610.082
358.045	422.788
362.542	173.845
367.036	111.884
371.527	270
376.017	287.126
380.503	92.8192
384.99	204.368
389.471	400.13
393.953	700.762
398.43	936.474
402.908	904.691
407.381	646.284
411.854	620.027
416.323	1024.02
420.791	1586.29
425.256	1186.51
429.72	653.9
434.18	448.584
438.64	398.305
443.095	286.16
447.551	317.075
452.003	417.516
456.454	982.361
460.901	1082.05
465.348	732.738
469.791	468.484
474.231	415.979
478.672	298.645
483.108	274.616
487.544	346.821
491.976	396.191
496.408	498.719
500.836	494.613
505.261	464.67
509.687	341.847
514.108	225.11
518.529	98.0964
522.946	83.0067
527.361	59.8823
531.776	70.8491
536.187	130.557
540.595	171.746
545.003	225.651
549.408	294.746
553.812	268.988
558.212	326.26
562.61	476.981
567.007	487.302
571.401	424.048
575.792	295.3
580.184	464.532
584.571	676.6
588.956	1283.34
593.341	1842.73
597.722	1528.88
602.101	1083.44
606.48	1106.86
610.854	1367.55
615.227	1515.87
619.597	1387.7
623.967	943.201
628.334	643.407
632.698	665.608
637.06	781.688
641.422	761.811
645.779	561.117
650.135	399.759
654.491	336.162
658.842	349.061
663.192	417.72
667.539	469.781
671.884	473.425
676.23	566.862
680.571	605.523
684.91	480.254
689.247	310.944
693.583	153.123
697.916	75.0453
702.247	30.6935
706.576	18.4442
710.902	-22.0811
715.229	20.4789
719.551	17.2362
723.872	1.94946
728.19	-19.6582
732.506	18.5555
736.82	-23.1665
741.134	41.3086
745.444	49.5704
749.752	51.8561
754.058	57.4657
758.362	154.927
762.664	184.84
766.964	295.033
771.264	572.208
775.559	914.471
779.853	1380.85
784.144	1520.36
788.434	1165.78
792.722	756.221
797.007	444.096
801.29	311.143
805.572	216.512
809.851	125.427
814.13	130.324
818.406	137.252
822.679	75.2195
826.95	120.084
831.219	115.44
835.486	51.092
839.752	39.4514
844.015	43.9954
848.276	51.839
852.535	29.7318
856.792	9.80481
861.047	75.5991
865.3	38.4053
869.551	55.8827
873.8	27.8711
878.047	34.7113
882.292	3.76184
886.534	2.82678
890.775	19.0687
895.014	-18.8525
899.251	32.2642
903.486	61.7345
907.719	9.19067
911.95	37.8096
916.179	53.0358
920.406	50.9598
924.63	41.5409
928.853	39.5391
933.074	120.305
937.293	24.5796
941.51	104.386
945.723	165.442
949.936	304.554
954.147	400.815
958.356	349.182
962.563	391.32
966.768	485.444
970.971	540.584
975.172	491.885
979.371	426.708
983.568	414.59
987.761	478.318
991.954	569.6
996.145	762.028
1000.33	1120.84
1004.52	1341.67
1008.71	1097.84
1012.89	780.017
1017.07	535.985
1021.25	517.52
1025.43	517.166
1029.6	681.333
1033.77	1046.34
1037.95	1498.87
1042.11	1753.39
1046.28	1999.46
1050.45	2599.35
1054.61	2948.74
1058.77	2578.45
1062.93	1742.09
1067.09	1066.85
1071.24	879.538
1075.4	785.599
1079.55	829.408
1083.7	1061.48
1087.85	1519.53
1091.99	2084.5
1096.14	2214.83
1100.28	2126.78
1104.42	1874.73
1108.55	2086.13
1112.69	2373.84
1116.82	2158.66
1120.96	1918.81
1125.09	1629
1129.21	1548.7
1133.34	1631.42
1137.46	1571.7
1141.59	1324.65
1145.71	1039.26
1149.83	854.798
1153.94	918.44
1158.06	1110.86
1162.17	1209.4
1166.28	1055.66
1170.39	899.033
1174.5	769.86
1178.6	632.527
1182.7	540.609
1186.8	470.108
1190.9	375.741
1195	388.544
1199.1	384.357
1203.19	402.298
1207.28	336.992
1211.37	306.516
1215.46	279.24
1219.54	297.654
1223.63	423.453
1227.71	459.288
1231.79	392.66
1235.87	353.259
1239.95	458.004
1244.02	565.846
1248.09	486.291
1252.16	326.242
1256.23	230.274
1260.3	209.4
1264.36	180.716
1268.43	164.345
1272.49	152.974
1276.55	205.772
1280.6	157.045
1284.66	160.089
1288.71	126.837
1292.76	98.2264
1296.81	119.893
1300.86	82.8475
1304.91	76.7695
1308.95	152.389
1312.99	116.608
1317.03	130.709
1321.07	99.3108
1325.11	138.536
1329.14	140.811
1333.18	129.424
1337.21	75.6895
1341.24	117.893
1345.26	95.9862
1349.29	115.006
1353.31	89.2642
1357.33	124.122
1361.35	102.355
1365.37	165.133
1369.39	169.618
1373.4	240.595
1377.41	192.338
1381.43	167.335
1385.43	147.894
1389.44	176.847
1393.45	118.853
1397.45	95.579
1401.45	100.537
1405.45	81.0449
1409.45	82.3672
1413.44	77.8668
1417.44	34.8268
1421.43	114.112
1425.42	55.6592
1429.41	112.256
1433.39	67.5374
1437.38	113.419
1441.36	91.2241
1445.34	101.294
1449.32	109.339
1453.3	72.6862
1457.27	116.767
1461.24	120.954
1465.22	79.571
1469.19	108.184
1473.15	120.102
1477.12	93.4377
1481.09	87.3119
1485.05	83.0446
1489.01	117.839
1492.97	142.926
1496.93	42.3622
1500.88	92.1069
1504.83	85.7153
1508.79	92.2748
1512.74	77.4738
1516.68	80.3187
1520.63	115.314
1524.57	85.4109
1528.52	73.144
1532.46	39.6917
1536.4	68.2847
1540.33	81.4185
1544.27	127.488
1548.2	97.9995
1552.14	100.398
1556.07	99.6503
1559.99	123.88
1563.92	83.1316
1567.84	139.935
1571.77	115.465
1575.69	132.515
1579.61	120.545
1583.52	91.1853
1587.44	117.633
1591.35	89.1951
1595.27	120.39
1599.18	101.675
1603.09	90.8761
1606.99	123.412
1610.9	113.778
1614.8	119.687
1618.7	103.642
1622.6	106.786
1626.5	97.8014
1630.39	126.475
1634.29	121.932
1638.18	115.536
1642.07	109.638
1645.96	99.1351
1649.85	89.6949
1653.73	145.488
1657.62	136.883
1661.5	123.306
1665.38	123.871
1669.26	102.032
1673.13	97.1682
1677.01	105.368
1680.88	66.7419
1684.75	76.9679
1688.62	103.249
1692.49	81.3314
1696.35	46.8423
1700.22	32.203
1704.08	89.6797
1707.94	107.652
1711.8	93.1698
1715.66	40.0417
1719.51	65.5782
1723.37	63.6316
1727.22	69.9504
1731.07	83.7024
1734.92	60.8989
1738.76	23.9656
1742.61	87.8278
1746.45	66.452
1750.29	41.3375
1754.13	44.78
1757.97	47.2659
1761.81	37.4777
1765.64	46.584
1769.47	55.7438
1773.31	52.2139
1777.14	26.5786
1780.96	37.7015
1784.79	1.37549
1788.61	63.3491
1792.43	11.1881
1796.25	33.986
1800.07	4.54993
1803.89	60.1729
1807.71	5.59888
1811.52	32.7483
1815.33	66.9976
1819.14	15.7992
1822.95	33.1954
1826.76	38.9259
1830.56	31.0536
1834.37	34.1979
1838.17	51.2291
1841.97	47.2542
1845.77	41.3724
1849.56	59.6016
1853.36	15.437
1857.15	68.1339
1860.94	24.3706
1864.73	44.0421
1868.52	-14.0627
1872.31	49.5413
1876.09	39.2339
1879.87	24.766
1883.66	35.5616
1887.43	46.4202
1891.21	32.3905
1894.99	86.3557
1898.76	68.9728
1902.53	61.2959
1906.31	18.8101
1910.08	45.7983
1913.84	50.0989
1917.61	-12.4379
1921.37	19.7783
1925.14	28.1718
1928.9	36.8138
1932.66	43.6643
1936.41	-0.819092
1940.17	49.8389
1943.92	22.3302
1947.68	43.1423
1951.43	49.3483
1955.18	34.1993
1958.92	39.8859
1962.67	61.4136
1966.41	28.3168
1970.16	74.2347
1973.9	62.6173
1977.64	56.338
1981.37	111.564
1985.11	57.1443
1988.84	43.7926
1992.57	58.0286
1996.31	60.837
2000.03	50.4663
2003.76	46.8414
2007.49	41.7606
2011.21	51.3711
2014.93	49.4039
2018.65	54.9124
2022.37	56.511
2026.09	33.306
2029.81	65.6736
2033.52	72.0522
2037.23	63.3579
2040.94	63.0042
2044.65	54.1902
2048.36	73.1884
2052.07	34.6995
2055.77	58.7704
2059.47	72.2061
2063.17	65.0706
2066.87	50.7268
2070.57	78.8174
2074.27	76.5557
2077.96	42.0562
2081.65	81.5906
2085.34	89.6665
2089.03	76.2063
2092.72	70.9725
2096.41	113.473
2100.09	63.1401
2103.77	85.1068
2107.46	39.8435
2111.14	90.2336
2114.81	59.6941
2118.49	61.2388
2122.16	68.6932
2125.84	62.1165
2129.51	86.76
2133.18	77.0984
2136.85	124.511
2140.51	114.333
2144.18	110.485
2147.84	109.371
2151.5	145.894
2155.16	119.205
2158.82	67.1069
2162.48	98.5256
2166.13	71.7466
2169.79	115.628
2173.44	92.7109
2177.09	106.343
2180.74	117.387
2184.38	109.342
2188.03	85.6686
2191.67	81.6335
2195.32	74.5172
2198.96	76.6461
2202.6	105.473
2206.23	81.6335
2209.87	129.349
2213.5	129.695
2217.14	98.8662
2220.77	73.521
2224.4	115.32
2228.03	77.8394
2231.65	88.4259
2235.28	87.985
2238.9	105.058
2242.52	83.1885
2246.14	137.445
2249.76	86.8416
2253.38	104.302
2256.99	79.83
2260.6	95.3704
2264.21	87.4767
2267.82	43.2693
2271.44	45.9388
2275.04	82.8844
2278.65	84.4175
2282.25	57.8223
2285.85	112.773
2289.45	62.5691
2293.05	89.8308
2296.65	121.015
2300.25	73.4935
2303.84	46.423
2307.43	60.7974
2311.02	95.83
2314.62	80.3713
2318.2	88.3087
2321.79	119.271
2325.38	68.1586
2328.96	94.6843
2332.54	83.1063
2336.12	77.0623
2339.7	77.4204
2343.28	79.5035
2346.85	133.896
2350.43	63.6077
2354	64.4576
2357.57	76.3928
2361.14	72.4103
2364.71	95.4144
2368.27	81.5271
2371.84	52.1382
2375.4	59.6337
2378.96	94.9441
2382.52	56.6836
2386.08	85.8184
2389.64	52.7565
2393.19	72.4081
2396.75	67.7817
2400.3	70.2273
2403.85	20.976
2407.4	54.4833
2410.95	51.0104
2414.49	42.2731
2418.04	41.1892
2421.58	96.5331
2425.12	58.3413
2428.66	17.5548
2432.2	65.8063
2435.74	58.8011
2439.27	48.1329
2442.81	46.8114
2446.34	71.8142
2449.87	41.9446
2453.4	69.79
2456.93	2.30127
2460.45	59.3383
2463.98	86.6986
2467.5	38.42
2471.02	57.7736
2474.54	51.6439
2478.06	45.1096
2481.58	82.5935
2485.09	49.5569
2488.61	95.5137
2492.12	68.325
2495.63	63.3107
2499.14	51.0558
2502.65	53.2363
2506.15	90.6586
2509.66	63.582
2513.16	56.4167
2516.66	94.1235
2520.16	55.9857
2523.66	61.2817
2527.16	35.8488
2530.66	62.3485
2534.15	73.5421
2537.64	49.9502
2541.13	64.7891
2544.62	25.916
2548.11	38.8635
2551.6	28.9138
2555.08	29.004
2558.57	69.9087
2562.05	32.5052
2565.53	63.4158
2569.01	43.5142
2572.49	61.2354
2575.96	47.4216
2579.44	29.8767
2582.91	29.2784
2586.38	33.2186
2589.85	39.2935
2593.32	52.4971
2596.79	32.7465
2600.25	55.0967
2603.72	53.896
2607.18	41.0946
2610.64	48.8716
2614.1	63.9819
2617.56	75.7076
2621.02	61.1996
2624.47	4.00574
2627.92	19.6069
2631.38	32.0253
2634.83	90.9586
2638.28	63.3062
2641.72	53.5475
2645.17	96.2924
2648.61	66.139
2652.06	43.3381
2655.5	60.1807
2658.94	79.632
2662.38	25.9926
2665.82	59.3992
2669.25	56.7128
2672.69	39.2209
2676.12	40.7262
2679.55	39.7001
2682.98	62.3478
2686.41	77.402
2689.84	27.1462
2693.26	28.7073
2696.69	60.3203
2700.11	23.2794
2703.53	61.2577
2706.95	11.0402
2710.37	29.9993
2713.79	70.6544
2717.2	1.71606
2720.62	20.5276
2724.03	49.7444
2727.44	68.8916
2730.85	29.0375
2734.26	33.1071
2737.66	34.3828
2741.07	41.047
2744.47	7.97681
2747.87	67.9419
2751.28	38.5854
2754.67	46.5465
2758.07	35.8678
2761.47	53.9832
2764.86	19.1416
2768.26	33.0077
2771.65	76.0055
2775.04	67.8792
2778.43	28.457
2781.82	50.1222
2785.2	30.3092
2788.59	42.4656
2791.97	20.6572
2795.35	51.5959
2798.73	81.2421
2802.11	74.286
2805.49	57.0289
2808.87	40.6521
2812.24	45.7568
2815.62	82.4894
2818.99	30.6614
2822.36	46.3116
2825.73	33.1278
2829.1	-2.26746
2832.46	25.9679
2835.83	22.7372
2839.19	25.3483
2842.55	20.7791
2845.91	26.8599
2849.27	5.57446
2852.63	19.4452
2855.99	48.4452
2859.34	19.6986
2862.69	-0.632813
2866.05	52.2249
2869.4	10.2417
2872.75	33.9287
2876.09	60.4406
2879.44	60.6143
2882.78	41.8159
2886.13	19.1036
2889.47	7.78186
2892.81	27.2426
2896.15	27.6318
2899.49	39.1635
2902.82	10.7585
2906.16	-13.017
2909.49	-1.92773
2912.82	25.245
2916.16	37.9723
2919.49	49.6493
2922.81	44.2648
2926.14	47.1249
2929.46	40.4733
2932.79	61.8363
2936.11	36.0126
2939.43	51.6936
2942.75	44.7675
2946.07	59.5851
2949.39	28.2672
2952.7	36.4052
2956.02	36.297
2959.33	69.2529
2962.64	62.7396
2965.95	82.7986
2969.26	40.5632
2972.57	12.1537
2975.87	12.3918
2979.17	8.59863
2982.48	13.3207
2985.78	61.333
2989.08	38.9778
2992.38	82.4285
2995.68	51.7627
2998.97	51.1824
3002.27	31.7183
3005.56	67.8898
3008.85	74.9789
3012.14	24.6768
3015.43	54.4065
3018.72	65.2795
3022	98.803
3025.29	55.9203
3028.57	73.4453
3031.85	71.0818
3035.14	66.7566
3038.41	49.1996
3041.69	78.0101
3044.97	76.6041
3048.24	108.302
3051.52	81.3462
3054.79	84.6779
3058.06	85.9547
3061.33	85.0082
3064.6	127.841
3067.87	136.331
3071.13	115.275
3074.4	125.307
3077.66	105.007
3080.92	113.914
3084.18	122.155
3087.44	123.062
3090.7	183.22
3093.95	148.837
3097.21	180.238
3100.46	148.904
3103.71	227.388
3106.96	165.169
3110.21	213.864
3113.46	177.807
3116.71	212.275
3119.95	209.627
3123.2	266.984
3126.44	210.933
3129.68	257.798
3132.92	251.285
3136.16	183.692
3139.4	257.146
3142.63	301.055
3145.87	291.657
3149.1	310.931
3152.33	308.227
3155.56	314.134
3158.79	347.684
3162.02	303.954
3165.25	367.001
3168.47	380.302
3171.69	359.18
3174.92	367.521
3178.14	433.996
3181.36	411.792
3184.58	382.785
3187.79	453.808
3191.01	444.729
3194.22	448.981
3197.43	475.096
3200.65	473.635
3203.86	474.145
3207.07	484.246
3210.27	531.56
3213.48	510.502
3216.69	529.436
3219.89	525.576
3223.09	506.663
3226.29	571.526
3229.49	558.538
3232.69	559.706
3235.89	601.149
3239.08	608.521
3242.28	603.629
3245.47	624.472
3248.66	617.842
3251.85	625.606
3255.04	626.715
3258.23	681.092
3261.42	640.691
3264.6	639.174
3267.79	689.038
3270.97	681.443
3274.15	649.02
3277.33	685.075
3280.51	704.475
3283.68	678.051
3286.86	710.623
3290.04	712.784
3293.21	706.354
3296.38	709.38
3299.55	729.083
3302.72	764.626
3305.89	729.519
3309.06	782.56
3312.22	736.585
3315.39	814.948
3318.55	791.655
3321.71	810.091
3324.87	779.298
3328.03	799.658
3331.19	833.337
3334.34	907.742
3337.5	936.947
3340.65	1019.89
3343.81	1001.35
3346.96	1048.51
3350.11	1138.11
3353.25	1221.35
3356.4	1370.7
3359.55	1590.16
3362.69	1841.88
3365.84	2166.5
3368.98	2436.69
3372.12	2665.02
3375.26	2743.61
3378.4	2496.61
3381.53	2129.11
3384.67	1771.88
3387.8	1534.5
3390.94	1472.15
3394.07	1431.43
3397.2	1438.4
3400.33	1428.76
3403.46	1436.46
3406.58	1527.06
3409.71	1614.14
3412.83	1737.9
3415.96	2295.29
3419.08	3753.75
3422.2	6780.15
3425.32	8871
3428.44	6468.93
3431.55	3453.05
3434.67	2143.4
3437.78	1675.5
3440.89	1435.99
3444	1375.38
3447.12	1259.47
3450.22	1223.33
3453.33	1177.69
3456.44	1124.16
3459.54	1112.48
3462.65	1178.66
3465.75	1109.72
3468.85	1124.64
3471.95	1095.66
3475.05	1059.37
3478.15	1090.42
3481.24	1144.17
3484.34	1187.58
3487.43	1216.99
3490.53	1276.39
3493.62	1392.47
3496.71	1609.13
3499.79	1796.68
3502.88	2064.55
3505.97	2296.63
3509.05	2275.94
3512.14	2008.44
3515.22	1696.88
3518.3	1401.11
3521.38	1207.27
3524.46	1098.08
3527.54	949.698
3530.61	915.165
3533.69	827.615
3536.76	782.223
3539.83	744.753
3542.9	726.25
3545.97	686.697
3549.04	671.408
3552.11	646.304
3555.18	619.558
3558.24	578.767
3561.3	557.443
3564.37	565.346
3567.43	487.068
3570.49	492.87
3573.55	469.098
3576.61	469.921
3579.66	468.726
3582.72	446.526
3585.77	437.569
3588.82	405.722
3591.87	394.67
3594.92	415.736
3597.97	386.556
3601.02	388.54
3604.07	344.028
3607.11	353.442
3610.16	340.107
3613.2	293.664
3616.24	333.22
3619.28	334.113
3622.32	284.133
3625.36	304.037
3628.39	230.632
3631.43	209.948
3634.46	232.785
3637.5	202.194
3640.53	201.859
3643.56	196.189
3646.59	220.442
3649.62	187.457
3652.64	151.304
3655.67	167.521
3658.69	120.444
3661.72	109.869
3664.74	146.859
3667.76	133.021
3670.78	125.889
3673.79	125.42
3676.81	81.5848
3679.83	31.0494
3682.84	45.684
3685.86	40.4955
3688.87	47.6385
3691.88	23.5632
3694.89	8.76178
3697.9	-21.1138
3700.91	6.92139
3703.91	23.5978
3706.92	12.6438
3709.92	27.264
3712.92	-6.74097
3715.92	19.2042
3718.92	8.92346
3721.92	-10.9771
3724.92	4.25812
3727.92	13.7114
3730.91	13.5543
3733.91	4.71918
3736.9	-9.91302
3739.89	2.95142
3742.88	-6.1601
3745.87	-9.64954
3748.86	-8.46509
3751.85	-3.51514
3754.83	-1.39575
3757.82	-22.0472
3760.8	4.64429
3763.78	4.77435
3766.76	-18.6945
3769.74	-0.429321
3772.72	-5.73999
3775.7	-10.9865
3778.67	-18.0518
3781.65	-0.53595
3784.62	6.62897
3787.6	-26.7496
3790.57	-20.3469
3793.54	12.5795
3796.51	14.4142
3799.47	-6.2934
3802.44	-28.8317
3805.41	-11.6799
3808.37	-8.64026
3811.33	-19.7496
3814.3	-36.5245
3817.26	2.54846
3820.22	-17.9657
3823.18	-15.7099
3826.13	-62.7131
3829.09	-9.26331
3832.04	-5.97736
3835	-27.3186
3837.95	-2.1156
3840.9	5.04193
3843.85	-8.72058
3846.8	28.9563
3849.75	-16.1896
3852.69	13.0286
3855.64	-6.39667
3858.58	-19.1522
3861.53	12.9783
3864.47	-14.2037
3867.41	-23.2925
3870.35	3.99994
3873.29	4.43274
3876.22	-5.78876
3879.16	13.6597
3882.1	-17.9189
3885.03	-8.26898
3887.96	-19.8121
3890.89	1.2995
3893.82	18.4708
3896.75	-9.67865
3899.68	14.0765
3902.61	-12.299
3905.53	1.78949
3908.46	7.17822
3911.38	-9.61591
3914.3	21.5162
3917.23	2.85895
3920.15	-1.50336
3923.06	-5.02075
3925.98	17.2724
3928.9	-10.3879
3931.81	-9.12494
3934.73	17.2069
3937.64	15.966
3940.55	-1.60724
3943.46	-6.72144
3946.37	7.38855
3949.28	-12.8996
3952.19	22.3791
3955.09	26.1329
3958	11.7277
3960.9	2.13977
3963.8	29.9824
3966.71	-15.0148
3969.61	-5.32001
3972.51	25.4967
3975.4	21.7078
3978.3	-1.37482
3981.2	59.1337
3984.09	19.6276
3986.99	5.09912
3989.88	15.4249
3992.77	28.778
3995.66	20.0042
3998.55	9.33313
4001.43	19.8459