File: Data/3-Raman/processed/bu19w-d-ff2-fi02-v_150 (500nm)_532nm_edge_100%_x100_vis_h50um_15sx2_01_0.txt
#Acq. time (s)=	15
#Accumulations=	2
#Range (cm-¹)=	100...5000
#Windows=	1
#Auto scanning=	Off
#Autofocus=	Off
#Macrospot=	Off
#AutoExposure=	Off
#Spike filter=	Multiple accum.
#Delay time (s)=	2
#Binning=	1
#Readout mode=	Signal
#DeNoise=	Off
#ICS correction=	On
#Dark correction=	Off
#Inst. Process=	Off
#Detector Gain=	Best Dynamic
#Detector ADC=	50 kHz HS
#Detector temperature (°C)=	-60.09
#Instrument=	LabRAM HR Evol
#Detector=	SIN-EM FIVIS
#Objective=	x100_VIS
#Grating=	150 (500nm)
#ND Filter=	100%
#Laser=	532nm_Edge
#Hole=	49.98
#Temperature=	0
#Range=	Visible
#StageXY=	75x50mm Scan+
#StageZ=	Z motor
#X (µm)=	0
#Y (µm)=	0
#Z (µm)=	-182.8
#Full time(s)=	34
#Project=	21_05_14
#Sample=	BU19w
#Site=
#Title=	BU19w-FF2-FI02-V_150 (500nm)_532nm_Edge_100%_x100_VIS_H50um_15sX2
#Remark=
#Date=	14.05.2021 17:15
#Acquired=	14.05.2021 17:15:47
#Base:Fit=	16.12.2021 17:39:50
#Base:Sub=	16.12.2021 18:02:58
102.699	405.054
107.322	407.617
111.942	276.063
116.56	201.959
121.173	147.765
125.787	165.927
130.398	105.668
135.006	124.537
139.613	125.209
144.215	62.0529
148.817	92.3572
153.417	359.59
158.014	903.638
162.607	740.576
167.2	225.34
171.79	48.5318
176.379	54.3074
180.963	205.794
185.547	665.598
190.128	685.131
194.705	391.543
199.282	166.492
203.857	75.908
208.43	37.9618
212.998	35.52
217.566	62.4482
222.132	0.0916748
226.693	120.923
231.254	374.645
235.813	457.187
240.368	664.901
244.923	1075.92
249.475	786.607
254.023	377.403
258.571	242.491
263.117	169.872
267.658	417.764
272.199	1076.46
276.738	2306.25
281.273	2189.16
285.807	1117.62
290.34	537.77
294.868	387.785
299.396	482.224
303.919	488.795
308.443	358.856
312.964	263.355
317.481	345.557
321.998	532.333
326.51	863.068
331.023	872.104
335.533	554.413
340.039	528.815
344.544	808.207
349.046	1138.38
353.547	979.6
358.045	545.547
362.542	411.931
367.036	475.015
371.527	464.493
376.017	287.111
380.503	243.062
384.99	298.144
389.471	420.902
393.953	502.803
398.43	294.677
402.908	189.927
407.381	165.866
411.854	347.714
416.323	585.477
420.791	437.755
425.256	193.309
429.72	88.6705
434.18	46.9055
438.64	-0.304077
443.095	46.4634
447.551	55.5663
452.003	131.507
456.454	158.972
460.901	160.142
465.348	98.356
469.791	116.804
474.231	137.426
478.672	159.883
483.108	245.383
487.544	346.891
491.976	462.588
496.408	486.562
500.836	411.798
505.261	325.836
509.687	215.381
514.108	146.711
518.529	93.1089
522.946	98.9911
527.361	54.0236
531.776	86.8416
536.187	54.9023
540.595	75.0223
545.003	91.6276
549.408	165.134
553.812	194.086
558.212	164.52
562.61	198.999
567.007	109.283
571.401	99.363
575.792	124.445
580.184	221.111
584.571	408.036
588.956	668.237
593.341	491.219
597.722	316.26
602.101	262.042
606.48	399.822
610.854	492.023
615.227	317.364
619.597	191.158
623.967	106.442
628.334	91.0502
632.698	141.436
637.06	173.064
641.422	194.442
645.779	172.856
650.135	183.993
654.491	218.368
658.842	367.861
663.192	558.741
667.539	601.201
671.884	596.562
676.23	649.165
680.571	543.034
684.91	346.693
689.247	193.393
693.583	106.249
697.916	47.3734
702.247	61.5717
706.576	9.07263
710.902	46.7991
715.229	1.91162
719.551	-2.83105
723.872	22.1619
728.19	45.5591
732.506	20.0569
736.82	39.5624
741.134	14.7119
745.444	55.8506
749.752	86.64
754.058	88.0046
758.362	110.539
762.664	150.483
766.964	289.88
771.264	428.681
775.559	667.494
779.853	703.127
784.144	545.486
788.434	348.502
792.722	211.621
797.007	144.761
801.29	94.421
805.572	87.6075
809.851	90.9001
814.13	60.3845
818.406	56.1764
822.679	41.2864
826.95	45.2607
831.219	62.5331
835.486	2.57373
839.752	25.2045
844.015	44.3088
848.276	64.7644
852.535	41.001
856.792	26.0841
861.047	13.2672
865.3	11.0695
869.551	9.7312
873.8	11.3625
878.047	29.2203
882.292	34.5288
886.534	18.562
890.775	0.523804
895.014	8.56482
899.251	38.8176
903.486	23.7468
907.719	32.3417
911.95	37.4491
916.179	23.9171
920.406	78.421
924.63	53.5413
928.853	58.4888
933.074	46.4165
937.293	114.325
941.51	205.406
945.723	284.167
949.936	343.923
954.147	248.217
958.356	229.526
962.563	150.505
966.768	146.038
970.971	133.443
975.172	99.7754
979.371	89.7814
983.568	38.5903
987.761	66.603
991.954	54.153
996.145	-1.77881
1000.33	22.0599
1004.52	12.1323
1008.71	40.7533
1012.89	55.1675
1017.07	39.7576
1021.25	81.8987
1025.43	94.5662
1029.6	127.583
1033.77	141.096
1037.95	219.342
1042.11	362.488
1046.28	560.895
1050.45	990.568
1054.61	1089.56
1058.77	739.822
1062.93	473.267
1067.09	299.504
1071.24	302.174
1075.4	330.174
1079.55	427.869
1083.7	674.101
1087.85	992.342
1091.99	1141.38
1096.14	909.918
1100.28	772.052
1104.42	838.303
1108.55	1097.33
1112.69	1125.3
1116.82	872.238
1120.96	843.415
1125.09	863.008
1129.21	887.024
1133.34	902.446
1137.46	758.066
1141.59	552.303
1145.71	426.966
1149.83	426.123
1153.94	604.86
1158.06	714.384
1162.17	570.248
1166.28	508.388
1170.39	455.168
1174.5	372.741
1178.6	205.957
1182.7	81.6077
1186.8	138.291
1190.9	70.3707
1195	119.864
1199.1	121.734
1203.19	129.502
1207.28	43.968
1211.37	104.583
1215.46	122.558
1219.54	187.989
1223.63	268.28
1227.71	200.669
1231.79	135.86
1235.87	173.908
1239.95	210.309
1244.02	176.018
1248.09	160.773
1252.16	114.938
1256.23	97.2993
1260.3	51.8578
1264.36	55.6107
1268.43	192.965
1272.49	805.138
1276.55	479.677
1280.6	103.154
1284.66	27.3483
1288.71	21.8671
1292.76	65.425
1296.81	19.2878
1300.86	52.5105
1304.91	30.0669
1308.95	29.8552
1312.99	41.2737
1317.03	-4.18457
1321.07	27.7657
1325.11	0.599121
1329.14	14.9454
1333.18	13.6665
1337.21	69.1614
1341.24	80.3262
1345.26	33.4938
1349.29	36.6488
1353.31	28.8992
1357.33	50.9391
1361.35	53.0537
1365.37	51.6161
1369.39	96.7367
1373.4	705.342
1377.41	1259.63
1381.43	426.48
1385.43	116.572
1389.44	10.6934
1393.45	107.217
1397.45	129.246
1401.45	90.8726
1405.45	16.1937
1409.45	37.218
1413.44	38.626
1417.44	12.3621
1421.43	13.6443
1425.42	20.3892
1429.41	21.7352
1433.39	46.1616
1437.38	26.9175
1441.36	55.1097
1445.34	33.6449
1449.32	1.29688
1453.3	0.237549
1457.27	35.5316
1461.24	20.1427
1465.22	0.549072
1469.19	11.5953
1473.15	36.399
1477.12	0.0644531
1481.09	10.7267
1485.05	38.8484
1489.01	55.1704
1492.97	58.8936
1496.93	3.23706
1500.88	15.0737
1504.83	48.5841
1508.79	19.1919
1512.74	32.5555
1516.68	49.9329
1520.63	29.5927
1524.57	20.0166
1528.52	36.7714
1532.46	16.8062
1536.4	23.0137
1540.33	40.8893
1544.27	17.0834
1548.2	1.04126
1552.14	27.5328
1556.07	46.9963
1559.99	62.3834
1563.92	27.3062
1567.84	28.8716
1571.77	25.5404
1575.69	35.6956
1579.61	56.3777
1583.52	48.0442
1587.44	51.1801
1591.35	46.5974
1595.27	37.1929
1599.18	44.1947
1603.09	26.4186
1606.99	40.4542
1610.9	42.9978
1614.8	31.345
1618.7	27.4218
1622.6	73.2946
1626.5	23.7186
1630.39	-0.66687
1634.29	42.1951
1638.18	-0.0980225
1642.07	62.4448
1645.96	40.8759
1649.85	25.1302
1653.73	45.7977
1657.62	71.1689
1661.5	60.8475
1665.38	58.8972
1669.26	23.0021
1673.13	40.613
1677.01	17.4626
1680.88	37.803
1684.75	-3.43762
1688.62	72.085
1692.49	34.205
1696.35	83.1682
1700.22	80.1448
1704.08	69.1707
1707.94	51.2526
1711.8	80.6757
1715.66	37.1753
1719.51	81.7224
1723.37	72.2946
1727.22	14.712
1731.07	85.873
1734.92	54.6606
1738.76	76.5851
1742.61	71.3412
1746.45	96.4495
1750.29	35.9395
1754.13	28.1733
1757.97	84.3772
1761.81	30.8735
1765.64	26.849
1769.47	55.371
1773.31	54.4785
1777.14	79.9147
1780.96	55.4846
1784.79	69.4575
1788.61	51.7681
1792.43	72.5071
1796.25	33.1713
1800.07	68.3723
1803.89	64.4476
1807.71	38.7825
1811.52	55.2504
1815.33	70.2794
1819.14	66.8146
1822.95	32.844
1826.76	45.6779
1830.56	91.052
1834.37	56.9213
1838.17	81.8706
1841.97	67.908
1845.77	52.0389
1849.56	49.0298
1853.36	52.8765
1857.15	68.4106
1860.94	75.152
1864.73	82.8209
1868.52	57.2551
1872.31	58.875
1876.09	70.8549
1879.87	57.386
1883.66	75.6212
1887.43	93.9469
1891.21	38.6456
1894.99	59.6079
1898.76	52.4648
1902.53	21.8911
1906.31	1.60535
1910.08	59.1169
1913.84	93.0771
1917.61	46.441
1921.37	93.7181
1925.14	47.6804
1928.9	55.5782
1932.66	51.4313
1936.41	68.6667
1940.17	71.9016
1943.92	66.1129
1947.68	74.828
1951.43	65.0975
1955.18	84.6532
1958.92	49.8289
1962.67	79.6646
1966.41	106.479
1970.16	89.2451
1973.9	42.6637
1977.64	90.3879
1981.37	72.3033
1985.11	62.3617
1988.84	90.5266
1992.57	97.703
1996.31	73.9359
2000.03	90.7941
2003.76	83.7734
2007.49	72.4653
2011.21	74.9263
2014.93	78.7144
2018.65	67.115
2022.37	59.0208
2026.09	55.4945
2029.81	80.0225
2033.52	86.0156
2037.23	79.6301
2040.94	130.11
2044.65	77.7876
2048.36	75.2737
2052.07	53.7455
2055.77	49.9032
2059.47	43.7437
2063.17	58.3561
2066.87	45.5907
2070.57	66.0454
2074.27	75.5272
2077.96	110.239
2081.65	83.8041
2085.34	85.0436
2089.03	78.4489
2092.72	75.5176
2096.41	53.4005
2100.09	76.9109
2103.77	105.73
2107.46	112.843
2111.14	98.4094
2114.81	77.4241
2118.49	84.7273
2122.16	104.332
2125.84	59.793
2129.51	94.6575
2133.18	103.497
2136.85	88.9822
2140.51	91.6921
2144.18	90.5343
2147.84	55.3307
2151.5	113.82
2155.16	76.0531
2158.82	80.5715
2162.48	72.5979
2166.13	66.7345
2169.79	97.8319
2173.44	64.96
2177.09	54.0934
2180.74	79.7908
2184.38	85.4771
2188.03	122.928
2191.67	62.7556
2195.32	86.0354
2198.96	86.7335
2202.6	101.391
2206.23	83.4979
2209.87	98.787
2213.5	116.128
2217.14	96.8492
2220.77	55.5293
2224.4	130.11
2228.03	97.8365
2231.65	121.997
2235.28	144.442
2238.9	103.851
2242.52	116.943
2246.14	97.5255
2249.76	79.1831
2253.38	25.5267
2256.99	104.425
2260.6	77.6705
2264.21	62.0288
2267.82	75.8719
2271.44	86.9426
2275.04	93.5463
2278.65	67.3751
2282.25	73.3196
2285.85	71.1622
2289.45	109.34
2293.05	50.9988
2296.65	91.1729
2300.25	73.4792
2303.84	80.9346
2307.43	124.112
2311.02	109.23
2314.62	100.674
2318.2	186.51
2321.79	183.384
2325.38	106.581
2328.96	88.5989
2332.54	75.9484
2336.12	73.509
2339.7	99.0432
2343.28	110.219
2346.85	78.0334
2350.43	85.1713
2354	101.51
2357.57	79.4572
2361.14	94.6116
2364.71	48.5125
2368.27	97.3944
2371.84	108.402
2375.4	90.5547
2378.96	66.5537
2382.52	112.787
2386.08	85.6055
2389.64	84.5771
2393.19	56.5123
2396.75	85.0297
2400.3	107.95
2403.85	77.5098
2407.4	108.843
2410.95	92.3804
2414.49	33.0564
2418.04	100.942
2421.58	89.2197
2425.12	60.4512
2428.66	64.3525
2432.2	72.3668
2435.74	74.239
2439.27	95.8008
2442.81	140.898
2446.34	91.0662
2449.87	82.6625
2453.4	90.6218
2456.93	74.337
2460.45	142.921
2463.98	99.621
2467.5	101.345
2471.02	113.074
2474.54	81.7122
2478.06	89.7582
2481.58	117.231
2485.09	71.1202
2488.61	109.674
2492.12	89.2396
2495.63	94.5911
2499.14	127.389
2502.65	99.5402
2506.15	79.9283
2509.66	142.15
2513.16	121.85
2516.66	115.031
2520.16	90.6462
2523.66	64.603
2527.16	112.558
2530.66	74.8263
2534.15	77.3953
2537.64	102.493
2541.13	75.8191
2544.62	117.557
2548.11	115.197
2551.6	94.6384
2555.08	65.9033
2558.57	94.6139
2562.05	68.4292
2565.53	76.3403
2569.01	132.483
2572.49	78.8356
2575.96	73.2102
2579.44	57.3798
2582.91	122.808
2586.38	68.0175
2589.85	88.8912
2593.32	89.1742
2596.79	83.3381
2600.25	75.7311
2603.72	111.323
2607.18	104.326
2610.64	74.127
2614.1	87.9795
2617.56	52.1466
2621.02	76.465
2624.47	112.715
2627.92	72.7534
2631.38	92.9054
2634.83	122.944
2638.28	104.682
2641.72	108.946
2645.17	94.975
2648.61	114.04
2652.06	84.9377
2655.5	101.07
2658.94	62.8889
2662.38	125.809
2665.82	102.599
2669.25	93.3813
2672.69	116.428
2676.12	118.093
2679.55	87.4408
2682.98	125.529
2686.41	65.9189
2689.84	97.1042
2693.26	80.1943
2696.69	49.7479
2700.11	121.071
2703.53	60.7397
2706.95	88.4692
2710.37	64.6599
2713.79	80.3217
2717.2	48.9115
2720.62	123.152
2724.03	91.276
2727.44	99.7512
2730.85	118.427
2734.26	102.477
2737.66	104.344
2741.07	58.9379
2744.47	75.0616
2747.87	76.2048
2751.28	114.949
2754.67	83.6692
2758.07	51.7
2761.47	109.589
2764.86	80.5461
2768.26	103.862
2771.65	84.673
2775.04	70.8191
2778.43	94.3364
2781.82	51.7758
2785.2	74.088
2788.59	74.7401
2791.97	72.4038
2795.35	50.5627
2798.73	67.7279
2802.11	71.7661
2805.49	101.098
2808.87	93.7664
2812.24	86.377
2815.62	121.803
2818.99	53.8337
2822.36	98.2632
2825.73	96.1621
2829.1	97.0792
2832.46	48.0863
2835.83	128.921
2839.19	69.4833
2842.55	66.3505
2845.91	61.9534
2849.27	86.4753
2852.63	79.7853
2855.99	88.276
2859.34	-4.89099
2862.69	78.9019
2866.05	62.6317
2869.4	70.5934
2872.75	66.2971
2876.09	64.7594
2879.44	75.4564
2882.78	80.366
2886.13	87.9747
2889.47	74.0291
2892.81	72.7185
2896.15	85.3379
2899.49	72.1251
2902.82	95.5197
2906.16	87.5635
2909.49	99.2666
2912.82	80.6954
2916.16	52.3069
2919.49	83.3864
2922.81	83.2047
2926.14	115.72
2929.46	94.2762
2932.79	141.31
2936.11	180.737
2939.43	79.7046
2942.75	124.812
2946.07	84.3751
2949.39	111.643
2952.7	62.6992
2956.02	54.5254
2959.33	57.0099
2962.64	89.4625
2965.95	60.4562
2969.26	48.192
2972.57	63.7262
2975.87	112.88
2979.17	31.2003
2982.48	85.7006
2985.78	101.896
2989.08	78.7244
2992.38	102.606
2995.68	76.8468
2998.97	75.5548
3002.27	60.9976
3005.56	59.8019
3008.85	65.3049
3012.14	57.7339
3015.43	45.3954
3018.72	44.3319
3022	59.3044
3025.29	50.7457
3028.57	86.578
3031.85	55.264
3035.14	38.9585
3038.41	5.64001
3041.69	27.2026
3044.97	60.2362
3048.24	35.4454
3051.52	50.5579
3054.79	42.8885
3058.06	63.4518
3061.33	15.2522
3064.6	45.0353
3067.87	45.1508
3071.13	34.3041
3074.4	41.5399
3077.66	45
3080.92	47.6252
3084.18	48.7424
3087.44	57.8121
3090.7	65.4307
3093.95	17.9078
3097.21	56.1998
3100.46	26.0632
3103.71	94.4824
3106.96	16.5077
3110.21	53.1179
3113.46	25.9099
3116.71	31.1655
3119.95	52.6394
3123.2	25.5242
3126.44	33.6046
3129.68	13.1168
3132.92	49.7928
3136.16	23.4786
3139.4	31.4396
3142.63	46.0753
3145.87	57.9576
3149.1	43.2206
3152.33	37.0115
3155.56	26.0649
3158.79	41.7993
3162.02	78.5409
3165.25	80.8143
3168.47	92.4841
3171.69	49.682
3174.92	49.6851
3178.14	48.673
3181.36	72.5155
3184.58	92.3788
3187.79	49.2186
3191.01	53.7285
3194.22	24.8785
3197.43	58.8647
3200.65	35.7611
3203.86	64.1442
3207.07	51.6786
3210.27	50.7562
3213.48	74.7188
3216.69	18.8069
3219.89	89.4581
3223.09	49.9421
3226.29	74.2286
3229.49	81.5568
3232.69	27.8674
3235.89	77.2631
3239.08	70.6993
3242.28	31.8613
3245.47	58.7532
3248.66	104.894
3251.85	68.1898
3255.04	45.7804
3258.23	47.9698
3261.42	75.6951
3264.6	80.2413
3267.79	53.0576
3270.97	68.7198
3274.15	69.1044
3277.33	49.1438
3280.51	76.5331
3283.68	44.7338
3286.86	52.8673
3290.04	54.4385
3293.21	76.9565
3296.38	89.858
3299.55	78.4786
3302.72	45.8572
3305.89	70.1213
3309.06	76.9705
3312.22	29.5195
3315.39	84.5867
3318.55	66.4856
3321.71	83.4731
3324.87	79.6267
3328.03	69.1969
3331.19	48.5022
3334.34	95.9802
3337.5	102.045
3340.65	65.6677
3343.81	71.1592
3346.96	70.5875
3350.11	36.1173
3353.25	134.733
3356.4	131.65
3359.55	120.318
3362.69	108.11
3365.84	86.5647
3368.98	98.0828
3372.12	39.9794
3375.26	122.62
3378.4	116.667
3381.53	47.2737
3384.67	114.133
3387.8	142.304
3390.94	94.8542
3394.07	171.659
3397.2	174.597
3400.33	177.869
3403.46	240.211
3406.58	283.801
3409.71	402.741
3412.83	688.101
3415.96	1524.64
3419.08	3422.93
3422.2	4672.64
3425.32	3179.35
3428.44	1403.9
3431.55	632.115
3434.67	415.394
3437.78	249.539
3440.89	217.449
3444	238.367
3447.12	176.282
3450.22	191.144
3453.33	189.78
3456.44	171.008
3459.54	145.545
3462.65	177.068
3465.75	189.396
3468.85	179.31
3471.95	276.847
3475.05	257.971
3478.15	342.335
3481.24	382.193
3484.34	464.621
3487.43	580.174
3490.53	800.18
3493.62	1120.18
3496.71	1559.49
3499.79	2002.59
3502.88	2349.4
3505.97	2358.92
3509.05	2011.19
3512.14	1425.59
3515.22	1095.32
3518.3	777.046
3521.38	589.818
3524.46	477.829
3527.54	329.5
3530.61	346.021
3533.69	251.944
3536.76	186.816
3539.83	170.174
3542.9	178.171
3545.97	145.3
3549.04	119.682
3552.11	123.003
3555.18	87.8092
3558.24	87.7941
3561.3	94.9592
3564.37	106.723
3567.43	67.3872
3570.49	96.957
3573.55	55.209
3576.61	78.8262
3579.66	73.8524
3582.72	52.5962
3585.77	72.0742
3588.82	60.098
3591.87	84.058
3594.92	42.4928
3597.97	25.5471
3601.02	30.2681
3604.07	43.3549
3607.11	64.8958
3610.16	70.2751
3613.2	28.3361
3616.24	39.3494
3619.28	62.6912
3622.32	21.9387
3625.36	56.7294
3628.39	76.3799
3631.43	30.9236
3634.46	80.8367
3637.5	51.9641
3640.53	31.748
3643.56	57.1028
3646.59	58.6808
3649.62	51.0593
3652.64	78.3229
3655.67	22.2018
3658.69	31.8907
3661.72	35.7194
3664.74	54.8748
3667.76	25.0909
3670.78	50.1471
3673.79	44.1725
3676.81	57.1808
3679.83	62.595
3682.84	29.2354
3685.86	53.5826
3688.87	29.7251
3691.88	21.042
3694.89	18.7084
3697.9	26.0367
3700.91	40.1102
3703.91	1.96484
3706.92	75.7562
3709.92	31.5956
3712.92	29.989
3715.92	18.9137
3718.92	22.9398
3721.92	30.6259
3724.92	19.1233
3727.92	45.5936
3730.91	5.25989
3733.91	25.6987
3736.9	27.8989
3739.89	88.9193
3742.88	27.0297
3745.87	28.749
3748.86	75.9397
3751.85	58.442
3754.83	68.5206
3757.82	31.1517
3760.8	24.9858
3763.78	40.5972
3766.76	20.3192
3769.74	8.71826
3772.72	34.1256
3775.7	24.6382
3778.67	20.9326
3781.65	65.4285
3784.62	-24.097
3787.6	23.3668
3790.57	15.3444
3793.54	35.7966
3796.51	18.5813
3799.47	49.6976
3802.44	72.4436
3805.41	9.28455
3808.37	25.5502
3811.33	48.4958
3814.3	53.5229
3817.26	40.6366
3820.22	28.7167
3823.18	42.4585
3826.13	10.7643
3829.09	43.4944
3832.04	44.1125
3835	28.6897
3837.95	9.46094
3840.9	59.611
3843.85	27.0499
3846.8	19.2524
3849.75	42.9833
3852.69	37.2203
3855.64	9.49878
3858.58	27.6324
3861.53	16.0601
3864.47	32.2234
3867.41	46.3862
3870.35	34.6143
3873.29	3.58521
3876.22	26.1309
3879.16	39.8973
3882.1	36.1915
3885.03	40.9956
3887.96	42.8412
3890.89	70.5939
3893.82	59.7174
3896.75	46.7117
3899.68	24.0529
3902.61	48.2913
3905.53	71.7064
3908.46	43.1404
3911.38	24.0594
3914.3	74.9231
3917.23	30.9725
3920.15	31.0125
3923.06	66.3557
3925.98	66.9928
3928.9	47.3481
3931.81	54.8215
3934.73	30.9954
3937.64	78.386
3940.55	44.2933
3943.46	46.6102
3946.37	12.683
3949.28	81.3312
3952.19	25.557
3955.09	40.7717
3958	36.912
3960.9	60.9105
3963.8	34.1893
3966.71	69.8751
3969.61	72.0638
3972.51	35.834
3975.4	8.1366
3978.3	20.6647
3981.2	66.8146
3984.09	32.1431
3986.99	84.9701
3989.88	41.3691
3992.77	55.7249
3995.66	54.6993
3998.55	38.3361
4001.43	79.76
4004.32	53.8516
4007.21	83.8577
4010.09	74.3333
4012.98	58.0568
4015.86	35.0149
4018.74	42.8356
4021.62	23.6183
4024.5	60.4523
4027.37	12.2638
4030.25	27.8938
4033.13	51.2791
4036	20.5516
4038.87	27.5787
4041.75	55.6903
4044.62	60.5396
4047.49	68.3938
4050.35	42.38
4053.22	55.2692
4056.09	3.15576
4058.95	87.8795
4061.82	62.8461
4064.68	48.4851
4067.54	25.3345
4070.4	47.8923
4073.26	92.85
4076.12	52.087
4078.98	49.2949
4081.83	100.132
4084.69	48.551
4087.54	41.7736
4090.4	92.6569
4093.25	43.9518
4096.1	54.7739
4098.95	41.2145
4101.8	37.3591
4104.64	39.2578
4107.49	10.7476
4110.33	39.9084
4113.18	41.4954
4116.02	79.132
4118.86	54.045
4121.7	46.7094
4124.54	24.795
4127.38	43.2153
4130.22	46.3004
4133.05	63.406
4135.89	22.9153
4138.72	37.5925
4141.56	64.549
4144.39	35.1383
4147.22	76.2998
4150.05	46.8492
4152.88	21.8254
4155.7	36.4054
4158.53	41.2133
4161.36	33.7329
4164.18	37.0194
4167	64.7786
4169.82	60.3468
4172.65	29.5662
4175.46	39.8729
4178.28	105.988
4181.1	20.6034
4183.92	45.7914
4186.73	27.0197
4189.55	44.58
4192.36	44.72
4195.17	72.4556
4197.98	18.9226
4200.79	113.422
4203.6	50.0328
4206.41	62.1617
4209.21	64.4738
4212.02	30.3739
4214.83	78.3511
4217.63	73.6017
4220.43	29.1835
4223.23	54.6262
4226.03	44.595
4228.83	40.6423
4231.63	36.7701
4234.42	38.9692
4237.22	24.335
4240.01	20.6259
4242.81	34.8838
4245.6	25.2476
4248.39	34.4255
4251.18	45.5479
4253.97	41.609
4256.76	87.6604
4259.55	57.6577
4262.33	29.6511
4265.12	47.8766
4267.9	76.2377
4270.68	15.9672
4273.47	55.2368
4276.25	36.8022
4279.03	35.3904
4281.8	26.787
4284.58	83.7703
4287.36	63.7365
4290.13	62.8322
4292.91	24.5371
4295.68	2.57275
4298.45	56.6094
4301.22	102.512
4303.99	74.353
4306.76	38.0721
4309.53	17.1017
4312.3	29.5989
4315.06	17.5093
4317.83	28.7321
4320.59	77.5323
4323.35	22.4113
4326.11	26.3441
4328.87	49.5789
4331.63	13.7065
4334.39	68.4828
4337.15	53.0364
4339.9	43.8356
4342.66	54.0642
4345.41	6.2915
4348.17	45.2773
4350.92	57.9529
4353.67	32.9131
4356.42	53.7629
4359.17	9.12268
4361.91	32.0382
4364.66	37.5667
4367.41	2.10803
4370.15	13.7305
4372.89	5.7312
4375.63	54.1421
4378.38	64.5186
4381.12	19.4613
4383.86	67.0963
4386.59	61.7153
4389.33	50.4736
4392.07	28.4862
4394.8	-6.09253
4397.53	40.4757
4400.27	1.12622
4403	48.7943
4405.73	22.9073
4408.46	72.7949
4411.19	21.6451
4413.92	11.9661
4416.64	43.6542
4419.37	36.703
4422.09	54.9823
4424.82	52.4128
4427.54	48.7969
4430.26	4.35864
4432.98	73.9194
4435.7	36.6598
4438.42	7.64551
4441.13	29.9534
4443.85	1.8988
4446.57	19.9679
4449.28	25.3948
4451.99	44.4255
4454.71	21.3652
4457.42	40.2583
4460.13	27.699
4462.83	59.3646
4465.54	30.0428
4468.25	50.2448
4470.95	27.3638
4473.66	1.4054
4476.36	37.7333
4479.07	50.9725
4481.77	49.4662
4484.47	52.1216
4487.17	49.4653
4489.87	54.0149
4492.56	60.2395
4495.26	54.0785
4497.96	21.4402
4500.65	34.1392
4503.34	35.3271
4506.04	20.662
4508.73	36.7545
4511.42	15.7267
4514.11	35.0839
4516.8	44.8896
4519.48	17.6669
4522.17	43.6211
4524.85	8.87903
4527.54	-0.296631
4530.22	26.7635
4532.9	51.7849
4535.58	-11.7491
4538.27	24.0859
4540.94	59.9238
4543.62	32.7592
4546.3	10.9025
4548.98	14.76
4551.65	21.0262
4554.33	16.6129
4557	-4.63464
4559.67	34.5692
4562.34	28.7756
4565.01	14.9238
4567.68	33.188
4570.35	24.1421
4573.02	34.6713
4575.68	39.3462
4578.35	20.4081
4581.01	21.8007
4583.67	32.0734
4586.34	33.6045
4589	5.54309
4591.66	37.411
4594.31	30.3511
4596.97	39.3728
4599.63	45.3801
4602.29	32.9009
4604.94	16.0044
4607.59	42.993
4610.25	27.1708
4612.9	37.6534
4615.55	1.99084
4618.2	44.5172
4620.85	16.5785
4623.5	17.1781
4626.14	29.8292
4628.79	44.7372
4631.43	28.5359
4634.08	27.6726
4636.72	27.9376
4639.36	36.9682
4642	31.8243
4644.64	26.9586
4647.28	50.079
4649.92	37.968
4652.56	69.8054
4655.19	2.3894
4657.83	55.2687
4660.46	35.9297
4663.1	12.0954
4665.73	54.8788
4668.36	18.3972
4670.99	9.83075
4673.62	29.2663
4676.24	54.3229
4678.87	15.3679
4681.5	23.5421
4684.12	30.611
4686.75	26.4099
4689.37	41.4261
4691.99	21.4036
4694.61	31.7635
4697.23	51.1843
4699.85	58.2206
4702.47	53.8267
4705.09	13.2255
4707.7	37.001
4710.32	9.8526
4712.93	22.2868
4715.55	19.9093
4718.16	69.6807
4720.77	66.0435
4723.38	77.3041
4725.99	55.7665
4728.6	0.15741
4731.21	6.94995
4733.81	33.0533
4736.42	60.2043
4739.02	68.0631
4741.63	63.2669
4744.23	66.448
4746.83	20.449
4749.43	12.0328
4752.03	30.9258
4754.63	24.7213
4757.23	22.007
4759.82	21.6686
4762.42	50.9393
4765.01	64.4402
4767.61	26.9454
4770.2	58.6692
4772.79	58.4713
4775.38	52.5798
4777.97	79.7771
4780.56	39.5671
4783.15	65.6446
4785.74	66.5692
4788.32	46.9062
4790.91	37.5869
4793.49	48.8597
4796.07	38.472
4798.66	36.1541
4801.24	45.3665
4803.82	79.9719
4806.4	23.8999
4808.98	18.3151
4811.55	51.9683
4814.13	32.6262
4816.71	37.6141
4819.28	10.1864
4821.85	54.5212
4824.43	63.0052
4827	36.59
4829.57	39.324
4832.14	38.5416
4834.71	37.8694
4837.28	38.4433
4839.84	37.8813
4842.41	41.7933
4844.97	50.2898
4847.54	24.608
4850.1	25.3162
4852.66	-2.74146
4855.22	22.2582
4857.78	68.5356
4860.34	48.6389
4862.9	35.3868
4865.46	31.3821
4868.01	44.3684
4870.57	51.205
4873.12	44.8234
4875.68	32.5027
4878.23	43.8461
4880.78	23.0436
4883.33	43.7786
4885.88	51.4534
4888.43	44.878
4890.98	40.6109
4893.53	37.4982
4896.07	-2.63037
4898.62	19.1945
4901.16	27.8511
4903.7	12.6771
4906.25	25.9946
4908.79	3.39594
4911.33	29.6157
4913.87	30.6689
4916.41	13.8104
4918.94	51.9355
4921.48	15.9692
4924.02	37.381
4926.55	20.4924
4929.08	13.2334
4931.62	4.96564
4934.15	18.2056
4936.68	79.2568
4939.21	22.7527
4941.74	-3.8255
4944.27	41.6752
4946.79	10.522
4949.32	30.8998
4951.85	33.2532
4954.37	20.0327
4956.9	26.1116
4959.42	16.6259
4961.94	12.0941
4964.46	10.1379
4966.98	16.4991
4969.5	17.882
4972.02	14.3994
4974.53	15.702
4977.05	4.90601
4979.57	40.1085
4982.08	37.7996
4984.59	8.79938
4987.1	28.3143
4989.62	0.420593
4992.13	-2.02777
4994.64	12.6272
4997.15	21.2861
4999.65	-3.00739