File: Data/3-Raman/processed/bu19w-b-ff1-fi08-s_150 (500nm)_532nm_edge_100%_x100_vis_h50um_15sx2_01.txt
#Acq. time (s)=	15
#Accumulations=	2
#Range (cm-¹)=	100...5000
#Windows=	1
#Auto scanning=	Off
#Autofocus=	Off
#Macrospot=	Off
#AutoExposure=	Off
#Spike filter=	Multiple accum.
#Delay time (s)=	2
#Binning=	1
#Readout mode=	Signal
#DeNoise=	Off
#ICS correction=	On
#Dark correction=	Off
#Inst. Process=	Off
#Detector Gain=	Best Dynamic
#Detector ADC=	50 kHz HS
#Detector temperature (°C)=	-60.09
#Instrument=	LabRAM HR Evol
#Detector=	SIN-EM FIVIS
#Objective=	x100_VIS
#Grating=	150 (500nm)
#ND Filter=	100%
#Laser=	532nm_Edge
#Hole=	49.98
#Temperature=	0
#Range=	Visible
#StageXY=	75x50mm Scan+
#StageZ=	Z motor
#X (µm)=	0
#Y (µm)=	0
#Z (µm)=	-197
#Full time(s)=	34
#Project=	21_05_14
#Sample=	BU19w
#Site=
#Title=	BU19w-FF1-FI08-S_150 (500nm)_532nm_Edge_100%_x100_VIS_H50um_15sX2
#Remark=
#Date=	14.05.2021 16:11
#Acquired=	14.05.2021 16:11:05
#Base:Fit=	22.12.2021 12:22:35
#Base:Sub=	22.12.2021 12:25:55
#Data Range:Extract=	22.12.2021 12:27:19
102.699	422.266
107.322	456.089
111.942	362.039
116.56	313.458
121.173	281.433
125.787	258.395
130.398	309.806
135.006	216.534
139.613	183.67
144.215	140.521
148.817	247.798
153.417	468.779
158.014	985.773
162.607	850.247
167.2	416.968
171.79	194.265
176.379	377.497
180.963	1125.38
185.547	2749.62
190.128	2184.93
194.705	681.252
199.282	170.092
203.857	77.5055
208.43	31.8489
212.998	35.5521
217.566	29.8584
222.132	0.0292969
226.693	30.0176
231.254	134.47
235.813	201.344
240.368	434.974
244.923	702.647
249.475	602.977
254.023	340.753
258.571	206.831
263.117	269.15
267.658	431.022
272.199	1277.02
276.738	2452.99
281.273	2248.99
285.807	1027.12
290.34	527.144
294.868	557.075
299.396	1042.87
303.919	1222.31
308.443	708.406
312.964	324.501
317.481	236.693
321.998	392.898
326.51	658.103
331.023	651.841
335.533	389.188
340.039	338.108
344.544	399.441
349.046	493.532
353.547	301.545
358.045	131.797
362.542	132.128
367.036	157.877
371.527	88.051
376.017	96.7681
380.503	208.474
384.99	384.865
389.471	524.544
393.953	588.162
398.43	443.805
402.908	317.188
407.381	229.874
411.854	431.372
416.323	536.451
420.791	337.013
425.256	142.847
429.72	106.148
434.18	-0.169678
438.64	27.1077
443.095	123.771
447.551	284.657
452.003	672.992
456.454	845.331
460.901	404.212
465.348	155.352
469.791	148.46
474.231	127.308
478.672	180.228
483.108	225.16
487.544	274.45
491.976	451.699
496.408	418.102
500.836	310.96
505.261	332.22
509.687	211.928
514.108	202.884
518.529	139.563
522.946	154.826
527.361	200.225
531.776	205.86
536.187	193.075
540.595	277.521
545.003	204.223
549.408	273.587
553.812	297.814
558.212	254.765
562.61	262.08
567.007	239.583
571.401	209.376
575.792	231.092
580.184	330.392
584.571	716.487
588.956	1035.62
593.341	789.316
597.722	416.512
602.101	405.331
606.48	598.011
610.854	753.748
615.227	641.883
619.597	280.086
623.967	177.811
628.334	190.321
632.698	177.606
637.06	229.106
641.422	246.357
645.779	214.216
650.135	144.631
654.491	239.251
658.842	309.179
663.192	377.872
667.539	378.868
671.884	486.051
676.23	487.678
680.571	393.458
684.91	270.101
689.247	118.445
693.583	133.19
697.916	55.1631
702.247	17.8831
706.576	29.8376
710.902	56.8499
715.229	0.359131
719.551	20.6116
723.872	55.8354
728.19	83.8625
732.506	66.2085
736.82	98.7266
741.134	106.379
745.444	81.6716
749.752	138.953
754.058	174.06
758.362	223.188
762.664	297.882
766.964	458.023
771.264	696.464
775.559	1096.34
779.853	1142.25
784.144	799.426
788.434	510.387
792.722	386.43
797.007	263.389
801.29	205.383
805.572	165.215
809.851	172.77
814.13	129.237
818.406	89.8892
822.679	124.948
826.95	79.9856
831.219	104.526
835.486	91.4429
839.752	54.9678
844.015	148.15
848.276	170.997
852.535	91.0508
856.792	70.6877
861.047	88.6089
865.3	126.477
869.551	76.8735
873.8	59.5659
878.047	56.0857
882.292	80.0139
886.534	86.281
890.775	86.8037
895.014	89.6772
899.251	25.1714
903.486	55.3091
907.719	115.894
911.95	111.157
916.179	39.9358
920.406	57.4385
924.63	127.163
928.853	79.1814
933.074	131.453
937.293	85.1318
941.51	177.692
945.723	270.456
949.936	314.733
954.147	281.47
958.356	303.976
962.563	383.093
966.768	351.879
970.971	364.968
975.172	266.991
979.371	198.466
983.568	177.831
987.761	163.066
991.954	133.218
996.145	204.136
1000.33	158.313
1004.52	159.456
1008.71	147.448
1012.89	196.149
1017.07	218.287
1021.25	228.627
1025.43	292.878
1029.6	314.541
1033.77	365.165
1037.95	375.269
1042.11	556.067
1046.28	922.063
1050.45	1462.09
1054.61	1490.36
1058.77	1117.26
1062.93	762.43
1067.09	542.772
1071.24	483.639
1075.4	561.124
1079.55	748.629
1083.7	1097.57
1087.85	1487.22
1091.99	1556.42
1096.14	1277.37
1100.28	1063.72
1104.42	1128.21
1108.55	1354.71
1112.69	1285.24
1116.82	1132.91
1120.96	996.518
1125.09	1016.94
1129.21	1086.86
1133.34	1114.13
1137.46	926.615
1141.59	658.741
1145.71	558.423
1149.83	599.193
1153.94	865.004
1158.06	976.825
1162.17	758.855
1166.28	556.829
1170.39	456.748
1174.5	293.112
1178.6	253.102
1182.7	200.726
1186.8	253.949
1190.9	177.949
1195	181.009
1199.1	225.785
1203.19	183.468
1207.28	145.438
1211.37	144.234
1215.46	140.076
1219.54	282.375
1223.63	311.875
1227.71	207.429
1231.79	266.521
1235.87	398.516
1239.95	457.053
1244.02	329.369
1248.09	266.032
1252.16	145.581
1256.23	118.528
1260.3	38.9333
1264.36	39.7893
1268.43	47.4099
1272.49	72.1973
1276.55	73.8394
1280.6	0.924072
1284.66	52.7505
1288.71	9.94482
1292.76	72.1421
1296.81	69.7813
1300.86	23.5413
1304.91	19.0796
1308.95	29.8721
1312.99	70.8411
1317.03	105.672
1321.07	36.4131
1325.11	89.208
1329.14	71.2417
1333.18	33.9731
1337.21	77.2205
1341.24	75.9609
1345.26	60.5037
1349.29	65.0869
1353.31	55.825
1357.33	66.4304
1361.35	82.8423
1365.37	64.5459
1369.39	85.1409
1373.4	106.58
1377.41	25.7993
1381.43	85.0754
1385.43	53.0796
1389.44	45.0688
1393.45	48.3052
1397.45	30.5164
1401.45	108.571
1405.45	-10.0149
1409.45	14.5554
1413.44	40.3545
1417.44	14.7734
1421.43	63.0479
1425.42	62.8411
1429.41	110.912
1433.39	90.7449
1437.38	145.079
1441.36	92.8979
1445.34	129.843
1449.32	113.382
1453.3	63.6802
1457.27	53.1919
1461.24	122.467
1465.22	6.97021
1469.19	47.2788
1473.15	18.9019
1477.12	87.8845
1481.09	102.647
1485.05	83.8616
1489.01	38.7432
1492.97	47.6467
1496.93	3.05029
1500.88	129.373
1504.83	59.8503
1508.79	88.2632
1512.74	40.9099
1516.68	37.624
1520.63	42.4014
1524.57	50.2793
1528.52	83.7156
1532.46	45.698
1536.4	89.1008
1540.33	86.0789
1544.27	45.238
1548.2	38.334
1552.14	49.6191
1556.07	97.1323
1559.99	76.4094
1563.92	67.929
1567.84	64.9424
1571.77	74.3611
1575.69	59.5596
1579.61	12.791
1583.52	41.0996
1587.44	92.2354
1591.35	141.318
1595.27	87.4084
1599.18	107.694
1603.09	142.785
1606.99	61.1614
1610.9	45.8391
1614.8	58.7375
1618.7	89.96
1622.6	117.36
1626.5	113.846
1630.39	70.8604
1634.29	64.842
1638.18	101.057
1642.07	79.0186
1645.96	33.3975
1649.85	116.49
1653.73	93.0474
1657.62	82.7253
1661.5	52.7876
1665.38	71.2129
1669.26	86.0657
1673.13	89.5522
1677.01	149.746
1680.88	58.3325
1684.75	85.6592
1688.62	119.09
1692.49	105.787
1696.35	106.317
1700.22	124.219
1704.08	84.1025
1707.94	137.436
1711.8	96.2861
1715.66	162.424
1719.51	93.3064
1723.37	176.057
1727.22	45.3447
1731.07	125.239
1734.92	153.273
1738.76	102.11
1742.61	92.0891
1746.45	148.564
1750.29	125.096
1754.13	56.8936
1757.97	107.244
1761.81	48.8833
1765.64	79.9807
1769.47	27.9373
1773.31	124.455
1777.14	104.423
1780.96	49.9495
1784.79	65.7935
1788.61	50.1514
1792.43	58.9438
1796.25	115.619
1800.07	76.0059
1803.89	34.8665
1807.71	92.4709
1811.52	133.498
1815.33	82.7407
1819.14	86.2617
1822.95	45.6292
1826.76	0.355957
1830.56	72.8523
1834.37	85.1218
1838.17	94.8865
1841.97	137.658
1845.77	107.914
1849.56	125.302
1853.36	82.1414
1857.15	37.1675
1860.94	82.8379
1864.73	140.447
1868.52	116.638
1872.31	109.258
1876.09	116.263
1879.87	113.179
1883.66	92.5471
1887.43	68.0327
1891.21	73.3384
1894.99	28.6687
1898.76	14.4595
1902.53	63.1414
1906.31	124.306
1910.08	110.05
1913.84	49.5344
1917.61	58.7559
1921.37	135.121
1925.14	44.3474
1928.9	104.294
1932.66	52.8259
1936.41	10.345
1940.17	58.269
1943.92	109.068
1947.68	80.5996
1951.43	58.0786
1955.18	72.2166
1958.92	168.865
1962.67	122.386
1966.41	122.408
1970.16	73.4539
1973.9	77.2341
1977.64	69.8748
1981.37	124.576
1985.11	44.885
1988.84	89.0686
1992.57	99.5193
1996.31	75.8413
2000.03	139.705
2003.76	67.9458
2007.49	137.975
2011.21	154.082
2014.93	143.601
2018.65	110.258
2022.37	87.9431
2026.09	93.4922
2029.81	26.8721
2033.52	71.2263
2037.23	108.044
2040.94	48.9717
2044.65	89.0901
2048.36	22.0488
2052.07	66.3516
2055.77	31.6733
2059.47	-6.17529
2063.17	17.9124
2066.87	72.947
2070.57	16.7153
2074.27	58.3445
2077.96	70.0569
2081.65	57.5718
2085.34	93.6548
2089.03	57.4314
2092.72	105.093
2096.41	113.674
2100.09	44.8037
2103.77	56.1794
2107.46	94.7104
2111.14	2.68994
2114.81	149.468
2118.49	80.2456
2122.16	147.763
2125.84	132.304
2129.51	128.116
2133.18	114.583
2136.85	129.12
2140.51	83.7935
2144.18	110.9
2147.84	67.0381
2151.5	117.839
2155.16	100.013
2158.82	98.9639
2162.48	95.0107
2166.13	170.146
2169.79	93.3315
2173.44	78.4873
2177.09	93.104
2180.74	88.0991
2184.38	46.7622
2188.03	46.5757
2191.67	30.6069
2195.32	62.6504
2198.96	113.397
2202.6	71.8198
2206.23	115.883
2209.87	40.9009
2213.5	77.0142
2217.14	43.5869
2220.77	55.3018
2224.4	18.312
2228.03	109.108
2231.65	143.409
2235.28	205.714
2238.9	178.109
2242.52	227.413
2246.14	108.595
2249.76	112.8
2253.38	113.765
2256.99	75.668
2260.6	30.4907
2264.21	147.249
2267.82	40.0493
2271.44	96.1987
2275.04	80.0615
2278.65	1.77881
2282.25	44.915
2285.85	82.4644
2289.45	77.6816
2293.05	50.0439
2296.65	17.0059
2300.25	120.037
2303.84	66.7075
2307.43	41.0571
2311.02	65.0615
2314.62	79.7964
2318.2	130.604
2321.79	102.762
2325.38	48.3774
2328.96	73.6523
2332.54	120.601
2336.12	18.1318
2339.7	177.766
2343.28	134.549
2346.85	108.778
2350.43	19.2866
2354	64.3203
2357.57	136.844
2361.14	94.498
2364.71	126.734
2368.27	116.077
2371.84	121.715
2375.4	108.398
2378.96	122.444
2382.52	123.168
2386.08	166.768
2389.64	28.5273
2393.19	83.4082
2396.75	112.274
2400.3	54.2974
2403.85	90.6211
2407.4	104.007
2410.95	94.5869
2414.49	31.7974
2418.04	87.6353
2421.58	2.62354
2425.12	-7.59473
2428.66	1.6665
2432.2	73.9829
2435.74	56.4336
2439.27	41.0132
2442.81	80.8354
2446.34	21.3462
2449.87	41.3569
2453.4	6.65723
2456.93	56.2769
2460.45	91.7012
2463.98	68.8916
2467.5	42.7036
2471.02	146.801
2474.54	36.2168
2478.06	34.0503
2481.58	118.664
2485.09	134.623
2488.61	106.33
2492.12	134.987
2495.63	57.356
2499.14	85.5386
2502.65	67.9287
2506.15	44.1694
2509.66	115.064
2513.16	130.939
2516.66	88.4072
2520.16	94.7471
2523.66	111.928
2527.16	35.3066
2530.66	24.084
2534.15	90.8628
2537.64	62.5957
2541.13	88.0156
2544.62	54.1284
2548.11	77.9619
2551.6	137.716
2555.08	43.8779
2558.57	34.2207
2562.05	56.1421
2565.53	103.092
2569.01	108.716
2572.49	24.5298
2575.96	52.6724
2579.44	52.2534
2582.91	105.923
2586.38	61.6924
2589.85	51.8306
2593.32	61.187
2596.79	12.7861
2600.25	39.1865
2603.72	51.1411
2607.18	123.038
2610.64	84.3672
2614.1	29.5103
2617.56	39.2285
2621.02	78.771
2624.47	21.8296
2627.92	44.833
2631.38	87.9673
2634.83	100.727
2638.28	67.606
2641.72	113.763
2645.17	-1.81689
2648.61	151.923
2652.06	72.5742
2655.5	52.2192
2658.94	87.3457
2662.38	81.9717
2665.82	83.2588
2669.25	83.9668
2672.69	78.8276
2676.12	100.597
2679.55	87.752
2682.98	119.088
2686.41	104.868
2689.84	73.2349
2693.26	57.0352
2696.69	93.0356
2700.11	76.7886
2703.53	104.967
2706.95	73.7573
2710.37	89.4492
2713.79	125.694
2717.2	40.0542
2720.62	74.4302
2724.03	38.3174
2727.44	42.8735
2730.85	96.7642
2734.26	44.9038
2737.66	72.7271
2741.07	135.451
2744.47	109.92
2747.87	113.587
2751.28	33.4507
2754.67	47.2803
2758.07	104.211
2761.47	14.6992
2764.86	69.6279
2768.26	105.661
2771.65	69.8315
2775.04	83.1494
2778.43	123.954
2781.82	88.0576
2785.2	-4.44238
2788.59	127.83
2791.97	49.9995
2795.35	104.247
2798.73	95.4077
2802.11	87.5825
2805.49	46.0522
2808.87	115.716
2812.24	99.978
2815.62	38.0503
2818.99	143.098
2822.36	131.315
2825.73	32.2578
2829.1	88.5337
2832.46	81.4561
2835.83	99.4204
2839.19	88.5317
2842.55	24.6265
2845.91	110.382
2849.27	67.9351
2852.63	57.9692
2855.99	36.4053
2859.34	43.6973
2862.69	100.868
2866.05	59.9595
2869.4	66.4849
2872.75	108.613
2876.09	145.041
2879.44	149.491
2882.78	112.08
2886.13	128.043
2889.47	48.0728
2892.81	167.891
2896.15	104.685
2899.49	63.3857
2902.82	186.935
2906.16	155.002
2909.49	118.749
2912.82	189.438
2916.16	97.4214
2919.49	242.514
2922.81	143.465
2926.14	227.832
2929.46	250.498
2932.79	279.541
2936.11	331.194
2939.43	231.075
2942.75	244.184
2946.07	221.882
2949.39	191.015
2952.7	223.906
2956.02	150.545
2959.33	144.719
2962.64	144.401
2965.95	152.73
2969.26	149.93
2972.57	236.305
2975.87	164.249
2979.17	219.68
2982.48	117.73
2985.78	277.132
2989.08	117.487
2992.38	90.4341
2995.68	145.499
2998.97	190.37
3002.27	155.079
3005.56	51.5576
3008.85	106.382
3012.14	156.828
3015.43	61.0991
3018.72	63.2759
3022	20.1445
3025.29	65.853
3028.57	138.06
3031.85	93.8896
3035.14	103.342
3038.41	63.6816
3041.69	34.4375
3044.97	114.275
3048.24	138.121
3051.52	98.7817
3054.79	40.3364
3058.06	4.05225
3061.33	86.1641
3064.6	118.467
3067.87	33.3911
3071.13	85.041
3074.4	58.5874
3077.66	82.4326
3080.92	97.5713
3084.18	70.9932
3087.44	86.0986
3090.7	72.8438
3093.95	135.613
3097.21	93.5054
3100.46	64.7534
3103.71	95.5112
3106.96	84.6855
3110.21	154.319
3113.46	142.937
3116.71	108.941
3119.95	152.136
3123.2	131.483
3126.44	133.561
3129.68	106.138
3132.92	121.545
3136.16	123.389
3139.4	190.905
3142.63	130.667
3145.87	172.706
3149.1	116.725
3152.33	179.821
3155.56	126.631
3158.79	182.109
3162.02	200.405
3165.25	106.737
3168.47	214.053
3171.69	116.946
3174.92	241.811
3178.14	185.218
3181.36	195.548
3184.58	205.47
3187.79	176.057
3191.01	166.65
3194.22	200.086
3197.43	156.243
3200.65	177.313
3203.86	202.364
3207.07	241.89
3210.27	233.185
3213.48	172.539
3216.69	198.563
3219.89	184.734
3223.09	185.628
3226.29	239.014
3229.49	241.446
3232.69	161.733
3235.89	172.261
3239.08	232.775
3242.28	209.808
3245.47	241.162
3248.66	230.048
3251.85	228.7
3255.04	310.428
3258.23	240.824
3261.42	163.813
3264.6	222.69
3267.79	121.512
3270.97	235.857
3274.15	213.61
3277.33	208.761
3280.51	241.071
3283.68	276.195
3286.86	243.164
3290.04	267.664
3293.21	271.139
3296.38	214.424
3299.55	303.694
3302.72	212.214
3305.89	220.126
3309.06	290.038
3312.22	222.673
3315.39	250.188
3318.55	352.371
3321.71	276.296
3324.87	326.277
3328.03	229.663
3331.19	258.227
3334.34	260.705
3337.5	307.975
3340.65	318.417
3343.81	358.055
3346.96	304.838
3350.11	282.82
3353.25	283.912
3356.4	320.122
3359.55	354.114
3362.69	289.29
3365.84	290.714
3368.98	290.391
3372.12	351.975
3375.26	290.167
3378.4	329.733
3381.53	356.781
3384.67	327.472
3387.8	354.997
3390.94	393.219
3394.07	344.306
3397.2	395.33
3400.33	454.868
3403.46	557.736
3406.58	587.004
3409.71	882.984
3412.83	1308.79
3415.96	2405.78
3419.08	5103.61
3422.2	6489.71
3425.32	4403.63
3428.44	2099.48
3431.55	1085.74
3434.67	803.714
3437.78	602.421
3440.89	550.344
3444	458.086
3447.12	355.325
3450.22	387.212
3453.33	375.206
3456.44	384.394
3459.54	355.368
3462.65	440.235
3465.75	352.724
3468.85	354.961
3471.95	361.423
3475.05	361.698
3478.15	432.228
3481.24	396.891
3484.34	513.956
3487.43	588.819
3490.53	694.489
3493.62	795.568
3496.71	1041.28
3499.79	1304.29
3502.88	1431.14
3505.97	1367.99
3509.05	1213.58
3512.14	865.954
3515.22	742.397
3518.3	524.348
3521.38	452.231
3524.46	402.944
3527.54	412.204
3530.61	283.903
3533.69	306.036
3536.76	248.95
3539.83	198.816
3542.9	209.828
3545.97	311.798
3549.04	239.309
3552.11	258.521
3555.18	229.263
3558.24	229.818
3561.3	185.763
3564.37	221.844
3567.43	218.356
3570.49	226.427
3573.55	175.184
3576.61	193.93
3579.66	127.902
3582.72	241.669
3585.77	220.626
3588.82	210.546
3591.87	243.838
3594.92	184.858
3597.97	147.608
3601.02	131.833
3604.07	232.083
3607.11	161.862
3610.16	163.383
3613.2	166.585
3616.24	129.275
3619.28	216.756
3622.32	127.004
3625.36	105.469
3628.39	224.242
3631.43	147.674
3634.46	118.954
3637.5	122.043
3640.53	143.478
3643.56	131.182
3646.59	147.386
3649.62	143.446
3652.64	85.9116
3655.67	116.84
3658.69	83.4756
3661.72	137.075
3664.74	73.9121
3667.76	133.441
3670.78	17.0757
3673.79	66.9141
3676.81	57.5908
3679.83	140.733
3682.84	67.9336
3685.86	94.4873
3688.87	128.77
3691.88	5.98096
3694.89	44.4072
3697.9	45.4233
3700.91	47.6387
3703.91	67.8965
3706.92	36.4763
3709.92	34.1465
3712.92	72.1753
3715.92	-10.4766
3718.92	35.002
3721.92	48.6958
3724.92	74.3931
3727.92	33.1282
3730.91	44.8186
3733.91	73.1887
3736.9	107.836
3739.89	75.3645
3742.88	33.0242
3745.87	101.572
3748.86	54.707
3751.85	4.90967
3754.83	49.2148
3757.82	86.7935
3760.8	72.8235
3763.78	72.1001
3766.76	122.743
3769.74	46.957
3772.72	87.8762
3775.7	-9.90527
3778.67	94.8403
3781.65	67.3967
3784.62	54.3286
3787.6	63.1887
3790.57	43.3677
3793.54	99.4861
3796.51	2.93335
3799.47	35.2529
3802.44	18.7849
3805.41	50.6125
3808.37	40.1736
3811.33	57.2827
3814.3	54.6375
3817.26	79.5964
3820.22	23.2559
3823.18	44.7988
3826.13	52.2681
3829.09	21.7517
3832.04	42.7437
3835	4.2124
3837.95	15.0989
3840.9	48.7859
3843.85	85.4268
3846.8	61.3054
3849.75	41.1912
3852.69	80.3159
3855.64	70.8562
3858.58	-1.61963
3861.53	34.6187
3864.47	84.3059
3867.41	139.535
3870.35	48.9319
3873.29	80.8928
3876.22	19.3647
3879.16	76.4673
3882.1	90.8479
3885.03	69.3101
3887.96	59.1028
3890.89	66.0566
3893.82	83.1589
3896.75	71.8394
3899.68	62.3499
3902.61	29.2153
3905.53	112.796
3908.46	111.584
3911.38	65.8184
3914.3	99.3193
3917.23	41.3638
3920.15	64.5347
3923.06	83.3252
3925.98	5.82056
3928.9	59.3083
3931.81	4.27319
3934.73	64.04
3937.64	50.0415
3940.55	112.416
3943.46	81.9785
3946.37	12.6653
3949.28	100.72
3952.19	10.8271
3955.09	61.0962
3958	25.3809
3960.9	132.637
3963.8	63.7693
3966.71	38.2263
3969.61	46.4155
3972.51	48.8274
3975.4	69.2878
3978.3	11.6289
3981.2	94.2012
3984.09	60.272
3986.99	134.04
3989.88	14.7832
3992.77	85.6763
3995.66	91.1975
3998.55	51.6594
4001.43	83.4119