File: Data/3-Raman/processed/bu19w-a-ff07a-fi03-v_150 (500nm)_532nm_edge_100%_x100_vis_lwd_h50um_30sx2_01_0.txt
#Acq. time (s)=	30
#Accumulations=	2
#Range (cm-¹)=	50...5000
#Windows=	1
#Auto scanning=	Off
#Autofocus=	Off
#Macrospot=	Off
#AutoExposure=	Off
#Spike filter=	Multiple accum.
#Delay time (s)=	2
#Binning=	1
#Readout mode=	Signal
#DeNoise=	Off
#ICS correction=	On
#Dark correction=	Off
#Inst. Process=	Off
#Detector Gain=	Best Dynamic
#Detector ADC=	50 kHz HS
#Detector temperature (°C)=	-60.09
#Instrument=	LabRAM HR Evol
#Detector=	SIN-EM FIVIS
#Objective=	x100_VIS_LWD
#Grating=	150 (500nm)
#ND Filter=	100%
#Laser=	532nm_Edge
#Hole=	49.98
#Temperature=	0
#Range=	Visible
#StageXY=	75x50mm Scan+
#StageZ=	Z motor
#X (µm)=	0
#Y (µm)=	0
#Z (µm)=	-4.8
#Full time(mm:ss)=	1:04
#Project=	21_05_28
#Sample=	BU19w
#Site=
#Title=	BU19w-FF07a-FI03-V_150 (500nm)_532nm_Edge_100%_x100_VIS_LWD_H50um_30sX2
#Remark=
#Date=	28.05.2021 18:17
#Acquired=	28.05.2021 18:17:52
#Base:Fit=	16.12.2021 17:39:50
#Base:Edit=	16.12.2021 17:57:27
#Base:Edit=	16.12.2021 17:57:28
#Base:Sub=	16.12.2021 17:57:32
51.5961	58527.6
56.2453	45395.5
60.8921	37351.3
65.5367	25607.9
70.1768	16982.9
74.8167	12756.6
79.4543	10119.3
84.0897	8087.29
88.7227	6739.54
93.3513	5621.27
97.9798	4706.85
102.606	4119.91
107.23	3654.55
111.851	3178.75
116.469	2662.1
121.086	2387.2
125.7	2102.33
130.313	1845.96
134.921	1686.31
139.529	1504.06
144.134	1234.08
148.738	1148.87
153.337	1385.44
157.936	2095.3
162.532	2302.17
167.126	1435.13
171.716	949.752
176.306	912.732
180.894	1750.5
185.477	4325.07
190.06	5289.56
194.64	2443.47
199.219	767.612
203.793	305.923
208.367	173.952
212.939	130.82
217.506	83.5328
222.073	-2.20215
226.638	65.4034
231.199	167.441
235.759	324.814
240.318	575.164
244.872	938.801
249.425	1013.27
253.977	735.946
258.524	350.128
263.071	249.962
267.616	429.801
272.156	1466.44
276.697	3451.22
281.233	4163.85
285.769	2334.87
290.303	1048.9
294.832	740.669
299.361	1517.79
303.886	2248.74
308.411	1582.66
312.934	556.195
317.452	249.478
321.97	363.634
326.484	777.79
330.998	1017.95
335.507	626.377
340.017	213.616
344.524	278.644
349.027	452.374
353.53	359.676
358.028	124.81
362.527	-1.80969
367.021	-0.344849
371.515	20.9467
376.004	-16.5425
380.494	117.732
384.979	377.478
389.465	557.139
393.946	742.672
398.427	667.559
402.903	398.302
407.38	299.525
411.852	614.092
416.324	1038.55
420.792	729.53
425.26	249.427
429.723	-27.0194
434.187	-57.5957
438.646	-62.1289
443.105	11.2831
447.56	220.167
452.015	880.882
456.466	1467.03
460.914	941.986
465.362	366.795
469.807	53.4763
474.251	-3.8064
478.69	30.58
483.13	118.36
487.566	240.37
491.999	461.447
496.432	504.539
500.861	397.624
505.29	293.495
509.715	181.527
514.138	71.8525
518.56	75.4166
522.979	29.6556
527.395	96.2537
531.811	101.79
536.223	139.916
540.635	200.058
545.042	216.055
549.448	223.919
553.853	240.777
558.255	262.513
562.654	270.242
567.053	246.925
571.448	148.347
575.841	188.739
580.232	371.189
584.622	885.93
589.009	1681.95
593.393	1685.21
597.777	948.558
602.157	697.634
606.535	920.556
610.913	1207.25
615.287	1236.39
619.659	707.898
624.029	365.459
628.398	169.476
632.763	171.416
637.127	260.781
641.488	298.087
645.849	263.97
650.206	210.972
654.561	234.923
658.914	286.758
663.267	407.297
667.615	494.943
671.962	554.614
676.307	657.298
680.649	642.349
684.991	428.843
689.33	213.198
693.666	146.667
698	41.9305
702.332	23.0121
706.662	26.3173
710.992	-2.46521
715.318	-16.0634
719.641	3.04565
723.963	-30.134
728.283	-19.9743
732.6	9.0083
736.918	-0.748596
741.231	62.1452
745.542	17.4883
749.852	70.1808
754.159	138.28
758.464	198.734
762.767	293.521
767.068	499.767
771.369	931.298
775.666	1499.86
779.961	1876.61
784.254	1596.62
788.545	936.333
792.834	528.602
797.12	351.238
801.405	203.576
805.688	121.862
809.968	51.5293
814.247	48.3778
818.524	59.6263
822.798	27.9004
827.071	6.26831
831.341	6.67017
835.612	5.9278
839.878	3.94849
844.142	-10.3391
848.405	-29.4548
852.665	1.57373
856.923	3.86108
861.18	35.8151
865.434	61.9905
869.686	73.4408
873.936	35.1678
878.185	-17.5504
882.431	-10.1448
886.675	-39.2536
890.915	-16.5166
895.155	-14.9488
899.393	-67.0773
903.63	-25.0626
907.864	3.70483
912.096	-68.3694
916.326	-37.0194
920.554	-32.9684
924.78	-31.4786
929.004	-14.4011
933.227	-9.17517
937.447	95.6557
941.665	125.977
945.881	234.074
950.095	290.509
954.305	351.337
958.516	312.066
962.724	367.653
966.93	463.586
971.134	441.725
975.337	319.45
979.537	231.387
983.735	136.215
987.93	89.7767
992.124	62.5056
996.316	99.4785
1000.51	40.7197
1004.7	22.3441
1008.88	82.6825
1013.06	52.7634
1017.25	64.0413
1021.43	126.507
1025.61	192.049
1029.78	175.019
1033.96	281.504
1038.13	390.907
1042.3	639.92
1046.47	1163.73
1050.63	2035.63
1054.8	2550.41
1058.96	2031.78
1063.12	1258.53
1067.28	837.046
1071.44	684.147
1075.59	715.973
1079.74	991.257
1083.89	1531.91
1088.04	2269.77
1092.19	2646.68
1096.33	2361.38
1100.48	1792.61
1104.62	1783.6
1108.76	2052.61
1112.89	2120.17
1117.03	1824.53
1121.16	1584.1
1125.29	1609.15
1129.42	1806.95
1133.55	1855.73
1137.68	1590.05
1141.8	1185.71
1145.92	916.282
1150.04	963.86
1154.16	1224.95
1158.27	1563.93
1162.39	1434.98
1166.5	1107.09
1170.61	703.507
1174.72	567.834
1178.82	372.368
1182.93	303.791
1187.03	244.213
1191.13	223.11
1195.23	263.151
1199.33	284.224
1203.42	269.218
1207.51	176.005
1211.6	174.505
1215.69	202.369
1219.78	345.049
1223.86	434.956
1227.95	417.484
1232.03	401.618
1236.11	563.838
1240.18	770.666
1244.26	760.198
1248.33	606.689
1252.41	663.736
1256.48	604.333
1260.54	356.239
1264.61	360.088
1268.67	851.835
1272.74	3710.52
1276.8	3483.85
1280.86	858.553
1284.91	224.646
1288.97	184.189
1293.02	157.641
1297.07	162.133
1301.12	153.432
1305.17	103.197
1309.21	132.519
1313.25	128.463
1317.3	107.897
1321.34	108.279
1325.37	74.054
1329.41	114.144
1333.44	100.832
1337.48	119.28
1341.5	132.487
1345.53	129.557
1349.56	136.593
1353.59	209.312
1357.61	270.912
1361.63	344.093
1365.65	382.626
1369.66	663.394
1373.68	2409.53
1377.69	7464.83
1381.7	3731.83
1385.72	690.47
1389.72	271.908
1393.73	292.812
1397.73	609.68
1401.74	553.343
1405.74	193.446
1409.73	97.5984
1413.73	84.6205
1417.73	62.773
1421.72	42.8718
1425.71	30.7256
1429.7	-4.63843
1433.69	9.47272
1437.67	2.83215
1441.66	-10.6939
1445.64	-12.5141
1449.62	-25.2367
1453.6	-23.3118
1457.57	-32.3193
1461.55	-1.08917
1465.52	-37.1363
1469.49	-41.7001
1473.46	-55.9357
1477.43	-42.7935
1481.39	-23.916
1485.36	-51.1344
1489.32	-25.5742
1493.28	-54.6534
1497.24	-50.494
1501.19	-57.9229
1505.15	-41.8288
1509.1	-17.7208
1513.05	-58.6476
1517	-17.9295
1520.95	-7.22223
1524.9	-33.312
1528.84	-3.07068
1532.78	2.07654
1536.72	-8.25934
1540.66	-20.4966
1544.6	1.18909
1548.53	11.2509
1552.46	-6.78271
1556.4	0.25708
1560.32	20.7001
1564.25	23.5993
1568.18	-11.3176
1572.1	-6.63806
1576.02	6.71155
1579.94	37.372
1583.86	26.4988
1587.78	23.2746
1591.69	38.3206
1595.61	37.9341
1599.52	57.7292
1603.43	47.8116
1607.34	40.9421
1611.24	42.7359
1615.15	50.3494
1619.05	77.2547
1622.95	52.3652
1626.85	85.0865
1630.74	57.6327
1634.64	75.4933
1638.53	106.704
1642.42	87.451
1646.31	74.1431
1650.2	61.8751
1654.09	62.109
1657.97	87.2144
1661.86	70.0325
1665.74	71.8516
1669.62	62.0187
1673.49	64.3571
1677.37	60.8629
1681.24	36.6461
1685.12	76.5181
1688.99	2.11456
1692.86	39.727
1696.72	17.7948
1700.59	31.0942
1704.45	13.6278
1708.31	24.5634
1712.17	-10.3372
1716.03	12.7194
1719.89	12.0723
1723.74	29.3786
1727.6	-5.27655
1731.45	15.4998
1735.3	19.3812
1739.14	17.512
1742.99	-15.2703
1746.83	4.28699
1750.68	-11.9099
1754.52	20.5359
1758.36	10.7947
1762.19	35.1172
1766.03	17.8964
1769.86	-5.47461
1773.69	7.82526
1777.53	1.62549
1781.35	10.6353
1785.18	6.74982
1789	31.934
1792.83	13.2155
1796.65	35.7305
1800.47	15.9697
1804.29	30.342
1808.1	20.1677
1811.92	16.4514
1815.73	24.8109
1819.54	32.744
1823.35	26.2634
1827.16	34.6887
1830.97	43.7731
1834.77	20.5457
1838.58	22.6037
1842.38	0.989685
1846.18	13.9409
1849.97	26.0327
1853.77	42.3097
1857.56	38.6396
1861.36	33.7302
1865.15	2.66992
1868.93	31.2567
1872.72	49.6219
1876.51	31.1195
1880.29	20.1294
1884.07	15.1032
1887.86	34.0522
1891.63	44.8769
1895.41	40.07
1899.19	15.0146
1902.96	47.422
1906.73	18.346
1910.5	28.9393
1914.27	22.3773
1918.04	16.7816
1921.8	36.7418
1925.57	28.1395
1929.33	46.579
1933.09	31.6951
1936.85	40.9405
1940.6	45.5104
1944.36	64.0932
1948.11	30.2452
1951.87	25.5421
1955.61	65.5043
1959.36	62.7026
1963.11	43.5907
1966.86	46.9563
1970.6	24.6531
1974.34	12.3292
1978.08	58.8428
1981.82	16.1816
1985.56	36.9891
1989.29	43.6194
1993.02	41.6739
1996.75	62.7688
2000.49	35.3361
2004.21	52.4945
2007.94	87.9327
2011.67	75.9472
2015.39	49.3304
2019.11	97.643
2022.83	53.7662
2026.55	41.7235
2030.27	79.161
2033.98	81.3629
2037.69	59.194
2041.41	70.796
2045.12	46.6016
2048.82	44.3965
2052.53	57.9494
2056.24	39.4974
2059.94	49.9554
2063.64	55.5434
2067.34	45.7522
2071.04	51.6658
2074.74	27.148
2078.43	66.4163
2082.13	61.4277
2085.82	83.2001
2089.51	87.0668
2093.2	15.2162
2096.88	40.4416
2100.57	56.2083
2104.25	40.012
2107.94	45.9547
2111.62	62.8934
2115.3	67.7025
2118.97	72.3696
2122.65	80.3293
2126.32	75.0579
2129.99	69.6291
2133.66	74.2899
2137.33	45.59
2141	70.3189
2144.67	81.9059
2148.33	89.6981
2151.99	55.2002
2155.66	96.0236
2159.31	95.5621
2162.97	77.864
2166.63	40.2997
2170.28	86.8658
2173.94	51.7984
2177.59	59.7875
2181.24	67.9046
2184.89	86.8818
2188.53	26.0933
2192.18	93.9551
2195.82	93.1319
2199.46	108.941
2203.1	52.8568
2206.74	58.9008
2210.38	67.8781
2214.01	53.2217
2217.65	55.0818
2221.28	74.4214
2224.91	77.3231
2228.54	57.1304
2232.16	30.4445
2235.79	57.3635
2239.41	76.9333
2243.04	67.8022
2246.66	53.9586
2250.28	56.8641
2253.89	52.4422
2257.51	53.7007
2261.12	44.6571
2264.74	40.1431
2268.35	66.6831
2271.96	57.8428
2275.57	23.2604
2279.17	46.7595
2282.78	23.3838
2286.38	60.405
2289.98	29.4158
2293.58	37.0249
2297.18	45.6254
2300.78	32.4973
2304.37	53.2913
2307.97	61.564
2311.56	76.3293
2315.15	134.542
2318.74	603.871
2322.33	551.525
2325.91	168.971
2329.5	54.6503
2333.08	44.3235
2336.66	31.0632
2340.24	20.5283
2343.82	41.8807
2347.4	45.2025
2350.97	12.8508
2354.54	36.6594
2358.12	42.5888
2361.69	51.222
2365.26	50.514
2368.82	28.5474
2372.39	13.3982
2375.95	38.8953
2379.52	18.1979
2383.08	35.473
2386.64	47.2822
2390.19	54.6478
2393.75	8.07373
2397.31	55.4196
2400.86	22.4222
2404.41	48.663
2407.96	1.71539
2411.51	0.108032
2415.06	-4.92566
2418.6	2.22711
2422.15	13.2431
2425.69	19.0107
2429.23	33.3726
2432.77	12.8541
2436.31	6.38824
2439.84	8.36621
2443.38	21.6169
2446.91	20.9601
2450.44	0.868164
2453.97	24.961
2457.5	36.2776
2461.03	4.35254
2464.55	7.15216
2468.08	28.913
2471.6	19.4577
2475.12	63.0298
2478.64	16.8083
2482.16	62.2458
2485.67	6.46362
2489.19	2.85242
2492.7	-5.82257
2496.21	23.4222
2499.72	15.4902
2503.23	60.5623
2506.74	21.2794
2510.25	8.01434
2513.75	29.3032
2517.25	13.6277
2520.75	32.5043
2524.25	-1.22766
2527.75	13.3178
2531.25	43.8109
2534.74	-2.19794
2538.24	2.90454
2541.73	-6.50946
2545.22	25.1779
2548.71	46.2713
2552.2	8.30151
2555.68	10.3398
2559.17	27.7188
2562.65	20.1182
2566.13	-26.1116
2569.61	14.4802
2573.09	-16.4275
2576.57	0.506592
2580.04	1.75488
2583.51	22.8861
2586.99	-3.14899
2590.46	48.1988
2593.93	20.351
2597.4	11.2732
2600.86	14.8817
2604.33	11.7189
2607.79	24.2655
2611.25	-2.41357
2614.71	4.76556
2618.17	9.45703
2621.63	28.1509
2625.09	22.6323
2628.54	55.2741
2631.99	52.2014
2635.45	39.2875
2638.9	40.4764
2642.34	36.6969
2645.79	24.13
2649.24	-12.3261
2652.68	34.9846
2656.12	18.1341
2659.56	43.8672
2663.01	20.1381
2666.44	30.446
2669.88	34.0959
2673.32	17.9398
2676.75	32.0612
2680.18	40.6711
2683.61	24.2607
2687.04	24.1453
2690.47	21.9092
2693.9	3.27679
2697.32	35.6815
2700.75	30.14
2704.17	38.6039
2707.59	47.1167
2711.01	21.959
2714.43	22.1307
2717.84	14.1358
2721.26	52.0041
2724.67	33.18
2728.08	48.9689
2731.49	30.2648
2734.9	16.1509
2738.31	6.70319
2741.71	-15.9382
2745.12	22.228
2748.52	45.2886
2751.92	36.4333
2755.32	17.1367
2758.72	54.2034
2762.12	32.9371
2765.52	62.2737
2768.91	49.064
2772.3	59.2501
2775.7	38.2628
2779.09	75.5184
2782.47	31.6413
2785.86	51.7307
2789.25	64.2513
2792.63	64.5099
2796.01	58.1729
2799.4	70.6291
2802.78	72.5922
2806.15	49.2684
2809.53	70.9236
2812.91	56.0012
2816.28	60.6893
2819.65	38.2747
2823.03	60.8661
2826.4	74.2507
2829.76	100.761
2833.13	71.494
2836.5	70.3966
2839.86	68.5563
2843.22	70.6555
2846.59	52.5092
2849.95	68.2937
2853.3	69.4139
2856.66	81.6336
2860.02	69.7074
2863.37	102.83
2866.72	86.3968
2870.08	106.537
2873.43	112.567
2876.77	100.712
2880.12	101.991
2883.47	92.875
2886.81	120.448
2890.15	97.0729
2893.5	127.457
2896.84	83.8914
2900.17	136.611
2903.51	130.551
2906.85	119.631
2910.18	118.087
2913.52	128.774
2916.85	106.275
2920.18	125.259
2923.51	138.509
2926.83	132.752
2930.16	159.926
2933.48	117.07
2936.81	189.242
2940.13	136.856
2943.45	171.236
2946.77	174.542
2950.09	160.953
2953.4	143.592
2956.72	163.872
2960.03	182.436
2963.34	156.045
2966.65	170.084
2969.96	183.514
2973.27	163.378
2976.58	189.253
2979.88	203.126
2983.19	197.171
2986.49	200.674
2989.79	206.128
2993.09	210.686
2996.39	227.528
2999.68	187.107
3002.98	195.541
3006.27	220.924
3009.57	244.541
3012.86	228.69
3016.15	229.81
3019.43	271.446
3022.72	285.753
3026.01	262.33
3029.29	273.841
3032.57	300.461
3035.86	273.168
3039.14	286.485
3042.41	307.393
3045.69	351.067
3048.97	344.597
3052.24	305.906
3055.52	372.44
3058.79	370.698
3062.06	348.635
3065.33	378.936
3068.6	369.236
3071.86	402.922
3075.13	410.825
3078.39	418.124
3081.65	452.502
3084.91	460.512
3088.17	439.039
3091.43	482.492
3094.69	558.432
3097.95	518.543
3101.2	546.095
3104.45	594.314
3107.7	560.463
3110.95	593.957
3114.2	646.044
3117.45	642.102
3120.7	664.863
3123.94	693.348
3127.18	721.817
3130.43	716.897
3133.67	757.744
3136.91	809.041
3140.14	789.719
3143.38	793.25
3146.61	830.161
3149.85	881.493
3153.08	864.202
3156.31	913.604
3159.54	945.894
3162.77	949.506
3166	976.023
3169.22	1005.24
3172.45	1045.77
3175.67	1050.91
3178.89	1149.39
3182.11	1118.08
3185.33	1191.73
3188.55	1180.25
3191.77	1222.1
3194.98	1205.79
3198.2	1237.09
3201.41	1299.75
3204.62	1278.67
3207.83	1310.98
3211.04	1331.96
3214.25	1355.92
3217.45	1370.51
3220.66	1410.78
3223.86	1426.39
3227.06	1481.22
3230.26	1423.85
3233.46	1514.11
3236.66	1514.78
3239.85	1506.44
3243.05	1489.65
3246.24	1503.44
3249.44	1529.64
3252.63	1499.82
3255.82	1528.22
3259.01	1563.29
3262.19	1574.16
3265.38	1562.73
3268.56	1617.84
3271.75	1580.99
3274.93	1598.45
3278.11	1621.59
3281.29	1659.5
3284.47	1678.8
3287.64	1692.41
3290.82	1693.39
3293.99	1682.19
3297.17	1711.85
3300.34	1745.33
3303.51	1769.84
3306.68	1738.48
3309.84	1808.66
3313.01	1773.81
3316.18	1813.87
3319.34	1818.7
3322.5	1910.61
3325.66	1887.8
3328.82	1860.32
3331.98	1918.97
3335.14	1924.8
3338.29	1976.18
3341.45	1932.38
3344.6	1944.34
3347.75	1990.89
3350.9	2015.45
3354.05	2051.29
3357.2	2128.9
3360.35	2069.99
3363.49	2144.32
3366.64	2178.2
3369.78	2187.72
3372.92	2238.89
3376.06	2189.42
3379.2	2259.03
3382.34	2338.3
3385.48	2315.39
3388.61	2454.47
3391.75	2462.18
3394.88	2451.73
3398.01	2491.62
3401.14	2605.4
3404.27	2730.1
3407.4	2922.8
3410.52	3318.67
3413.65	4005.58
3416.77	5965.51
3419.89	10081.9
3423.01	12997
3426.13	9646.23
3429.25	5606.62
3432.37	3811.35
3435.49	3115.94
3438.6	2835.12
3441.72	2699.94
3444.83	2571.38
3447.94	2558.59
3451.05	2486.6
3454.16	2499.01
3457.26	2435.14
3460.37	2414.67
3463.47	2334.27
3466.58	2394.41
3469.68	2360.97
3472.78	2318.52
3475.88	2391.69
3478.98	2405.27
3482.07	2354.66
3485.17	2496.02
3488.26	2597.75
3491.36	2671.55
3494.45	2929.27
3497.54	3214.1
3500.63	3545.65
3503.72	3837.48
3506.81	3783.42
3509.89	3463.73
3512.98	3045.24
3516.06	2651.56
3519.14	2351.99
3522.22	2147.68
3525.3	1975.14
3528.38	1925.4
3531.45	1728.98
3534.53	1700.93
3537.61	1678.33
3540.68	1626.71
3543.75	1580.78
3546.82	1528.8
3549.89	1461.32
3552.96	1419.68
3556.03	1382.54
3559.09	1298.37
3562.16	1331.53
3565.22	1285.66
3568.28	1252.72
3571.34	1224.15
3574.4	1160.5
3577.46	1170.88
3580.52	1147.91
3583.57	1079.25
3586.63	1041.73
3589.68	1015.57
3592.73	984.457
3595.78	956.157
3598.83	940.033
3601.88	892.66
3604.93	917.096
3607.97	908.263
3611.02	837.007
3614.06	876.316
3617.1	788.01
3620.14	798.979
3623.18	743.019
3626.22	706.014
3629.26	682.32
3632.3	685.88
3635.33	624.405
3638.36	636.704
3641.4	604.005
3644.43	592.153
3647.46	532.629
3650.49	546.149
3653.51	509.021
3656.54	485.468
3659.57	483.286
3662.59	426.368
3665.61	398.356
3668.63	378.3
3671.65	349.983
3674.67	320.738
3677.69	330.215
3680.71	272.689
3683.72	273.632
3686.74	267.962
3689.75	263.256
3692.76	232.051
3695.77	209.335
3698.78	215.803
3701.79	216.773
3704.79	203.498
3707.8	189.24
3710.81	211.926
3713.81	187.967
3716.81	160.073
3719.81	165.519
3722.81	138.493
3725.81	138.994
3728.81	149.893
3731.8	163.59
3734.8	152.442
3737.79	142.153
3740.78	143.217
3743.77	169.871
3746.76	129.853
3749.75	134.47
3752.74	135.22
3755.73	120.764
3758.71	117.728
3761.7	125.102
3764.68	103.025
3767.66	116.029
3770.64	117.718
3773.62	111.909
3776.6	139.246
3779.58	104.24
3782.55	83.4757
3785.53	104.283
3788.5	115.68
3791.47	113.904
3794.44	92.4283
3797.41	113.486
3800.38	94.0023
3803.35	71.7772
3806.32	66.577
3809.28	75.5656
3812.24	74.2079
3815.21	71.9204
3818.17	80.0539
3821.13	95.7953
3824.09	105.89
3827.04	67.7297
3830	79.7751
3832.96	86.1387
3835.91	92.5808
3838.86	84.8217
3841.82	90.3591
3844.77	99.7032
3847.72	71.9503
3850.67	76.5782
3853.61	70.7665
3856.56	46.826
3859.5	73.4788
3862.45	67.6795
3865.39	83.8361
3868.33	66.5001
3871.27	43.327
3874.21	56.5458
3877.15	64.9537
3880.09	90.5765
3883.02	57.5446
3885.96	75.3376
3888.89	55.598
3891.82	44.4751
3894.75	66.9731
3897.68	68.2285
3900.61	81.9055
3903.54	65.7536
3906.47	48.5604
3909.39	92.975
3912.31	64.2706
3915.24	59.533
3918.16	71.082
3921.08	85.6342
3924	72.2017
3926.92	7.85889
3929.83	60.4962
3932.75	81.4219
3935.67	66.1076
3938.58	61.4854
3941.49	61.7825
3944.4	85.9532
3947.31	44.1035
3950.22	60.7313
3953.13	23.7931
3956.04	44.3397
3958.94	50.5912
3961.85	68.3818
3964.75	45.9609
3967.65	56.1718
3970.55	65.4714
3973.45	44.0876
3976.35	50.5212
3979.25	39.6261
3982.15	60.3972
3985.04	34.0663
3987.94	41.3484
3990.83	45.7304
3993.72	31.7609
3996.61	47.7433
3999.5	65.6534
4002.39	48.9531
4005.28	22.6259
4008.16	61.8377
4011.05	54.826
4013.93	43.9467
4016.81	55.258
4019.7	49.2119
4022.58	44.1278
4025.46	31.3217
4028.33	49.4452
4031.21	41.4929
4034.09	34.5244
4036.96	44.011
4039.84	48.7025
4042.71	22.3902
4045.58	48.2709
4048.45	51.9175
4051.32	37.1876
4054.19	42.8574
4057.05	20.4572
4059.92	8.69427
4062.78	25.0786
4065.65	39.5441
4068.51	49.163
4071.37	24.7299
4074.23	9.03833
4077.09	4.03754
4079.95	38.9817
4082.81	16.4476
4085.66	29.0138
4088.52	5.46509
4091.37	29.7281
4094.22	15.9829
4097.07	16.8344
4099.92	17.7295
4102.77	12.7504
4105.62	20.467
4108.47	-5.14417
4111.31	24.0459
4114.16	35.5629
4117	17.6612
4119.84	28.0576
4122.69	10.0907
4125.53	-3.87848
4128.36	18.3849
4131.2	23.2131
4134.04	3.65796
4136.88	31.3274
4139.71	10.1965
4142.54	7.15948
4145.38	31.3306
4148.21	-11.7632
4151.04	18.6029
4153.87	11.6364
4156.69	5.43323
4159.52	4.85687
4162.35	27.0101
4165.17	20.8779
4168	22.5697
4170.82	18.4309
4173.64	10.4235
4176.46	-9.29517
4179.28	29.6703
4182.1	28.6001
4184.91	23.6458
4187.73	29.4944
4190.54	4.05634
4193.36	43.3084
4196.17	7.2608
4198.98	43.7806
4201.79	29.3415
4204.6	-5.68298
4207.41	61.3229
4210.22	17.4356
4213.02	14.7574
4215.83	25.8439
4218.63	-0.0901489
4221.44	16.2635
4224.24	14.8441
4227.04	23.2201
4229.84	12.9438
4232.64	26.4182
4235.43	18.2104
4238.23	4.07104
4241.02	17.7227
4243.82	8.55615
4246.61	-4.57898
4249.4	20.1127
4252.19	19.8536
4254.98	14.5822
4257.77	22.256
4260.56	-6.12292
4263.35	-0.433716
4266.13	23.3686
4268.92	28.1713
4271.7	13.8527
4274.48	-3.53967
4277.26	10.1945
4280.04	19.8361
4282.82	5.20227
4285.6	21.8398
4288.38	13.1319
4291.15	3.34418
4293.93	0.616577
4296.7	-5.07007
4299.47	19.7006
4302.25	-3.22754
4305.02	-6.8999
4307.79	23.9509
4310.55	14.2272
4313.32	18.7827
4316.09	17.1496
4318.85	-3.86835
4321.62	3.56494
4324.38	3.83319
4327.14	13.2427
4329.9	31.8471
4332.66	-9.70453
4335.42	9.89923
4338.18	-11.3024
4340.94	27.7271
4343.69	27.0233
4346.45	16.1835
4349.2	1.30627
4351.95	0.710999
4354.7	7.41479
4357.45	22.2442
4360.2	13.5682
4362.95	-1.29132
4365.7	-0.752991
4368.44	17.1606
4371.19	4.3905
4373.93	0.741943
4376.68	27.8732
4379.42	-16.9008
4382.16	23.5423
4384.9	-8.91193
4387.64	38.9279
4390.37	11.9193
4393.11	-5.79135
4395.85	-2.50537
4398.58	24.1878
4401.31	-7.06195
4404.05	29.9727
4406.78	13.1553
4409.51	17.0995
4412.24	-7.09735
4414.96	-11.6378
4417.69	28.5991
4420.42	5.06735
4423.14	13.9507
4425.87	4.08188
4428.59	10.9172
4431.31	9.39529
4434.03	21.4602
4436.75	17.8077
4439.47	3.64389
4442.19	12.4741
4444.91	15.0312
4447.62	23.852
4450.34	5.38162
4453.05	27.81
4455.76	-9.6449
4458.47	34.8053
4461.19	3.56326
4463.89	19.6882
4466.6	14.7683
4469.31	-19.5975
4472.02	18.6768
4474.72	16.997
4477.43	39.6019
4480.13	24.2955
4482.83	26.9401
4485.53	26.4114
4488.23	30.0649
4490.93	27.3499
4493.63	4.3924
4496.33	22.6272
4499.02	37.7854
4501.72	29.6112
4504.41	16.0874
4507.11	19.5614
4509.8	38.958
4512.49	19.105
4515.18	9.85709
4517.87	30.3473
4520.56	16.8676
4523.24	15.113
4525.93	19.7314
4528.61	16.8882
4531.3	11.9182
4533.98	25.0693
4536.66	27.5786
4539.34	23.6966
4542.02	19.8313
4544.7	20.2226
4547.38	4.57138
4550.05	22.0932
4552.73	19.3156
4555.4	40.2147
4558.08	20.3928
4560.75	16.7869
4563.42	24.0207
4566.09	23.8563
4568.76	29.2176
4571.43	10.4345
4574.1	29.0923
4576.77	17.1649
4579.43	20.6483
4582.1	14.5334
4584.76	18.2752
4587.42	14.1289
4590.08	20.8454
4592.74	16.6027
4595.4	20.0207
4598.06	26.7638
4600.72	25.8089
4603.38	29.3069
4606.03	25.1657
4608.69	1.28113
4611.34	23.4308
4613.99	21.4345
4616.64	26.0151
4619.29	15.2154
4621.94	12.1175
4624.59	4.5773
4627.24	9.11545
4629.89	13.6325
4632.53	9.29044
4635.18	23.6677
4637.82	25.8529
4640.46	8.09854
4643.1	15.7978
4645.74	13.622
4648.38	11.5422
4651.02	6.21832
4653.66	31.0767
4656.3	26.8252
4658.93	12.0606
4661.57	31.0501
4664.2	0.995056
4666.83	-4.5914
4669.46	17.6814
4672.09	17.6204
4674.72	15.2996
4677.35	26.4194
4679.98	36.4159
4682.61	11.5887
4685.23	15.9409
4687.86	28.1646
4690.48	13.3888
4693.1	19.9921
4695.73	11.9054
4698.34	21.8421
4700.96	26.1501
4703.58	19.1461
4706.2	4.17786
4708.82	10.658
4711.43	0.152618
4714.05	-3.58414
4716.66	23.2259
4719.28	9.25156
4721.89	15.6435
4724.5	26.5483
4727.11	19.3685
4729.72	20.144
4732.33	26.5936
4734.93	26.2321
4737.54	21.3023
4740.14	12.9287
4742.75	6.80377
4745.35	25.6655
4747.95	-1.00992
4750.55	7.52396
4753.15	-7.8302
4755.75	22.3284
4758.35	1.2666
4760.95	5.28015
4763.54	9.32129
4766.14	16.805
4768.73	19.826
4771.33	20.6007
4773.92	21.292
4776.51	6.01105
4779.1	11.2747
4781.69	1.68558
4784.28	16.0953
4786.87	4.22345
4789.45	12.937
4792.04	33.122
4794.63	2.95813
4797.21	20.9048
4799.79	-1.215
4802.37	15.6779
4804.95	-7.56314
4807.53	-3.20377
4810.11	1.19696
4812.69	13.6726
4815.27	-6.08878
4817.84	-7.38892
4820.42	10.9955
4822.99	6.28159
4825.57	3.88907
4828.14	1.49139
4830.71	-7.86792
4833.28	-13.7154
4835.85	9.57214
4838.42	13.149
4840.98	8.60126
4843.55	-6.50107
4846.12	4.09103
4848.68	-5.26938
4851.24	-12.3978
4853.81	6.10516
4856.37	-3.51462
4858.93	-19.856
4861.49	-3.22995
4864.05	-9.07581
4866.61	13.3235
4869.16	5.05786
4871.72	-6.67438
4874.27	-1.90289
4876.83	11.1591
4879.38	1.71838
4881.93	-7.7319
4884.49	-6.49741
4887.04	10.216
4889.58	-12.2648
4892.13	-1.41824
4894.68	1.1214
4897.23	6.06677
4899.77	5.07852
4902.32	1.7294
4904.86	5.56686
4907.4	1.07065
4909.95	9.73309
4912.49	-3.13934
4915.03	12.6681
4917.57	11.7608
4920.1	-27.2936
4922.64	1.7876
4925.18	20.1696
4927.71	8.74988
4930.25	9.28271
4932.78	20.715
4935.31	-0.0259399
4937.84	16.3238
4940.38	37.5213
4942.9	31.0876
4945.43	5.67935
4947.96	6.71494
4950.49	25.7738
4953.01	14.9596
4955.54	28.1464
4958.06	29.4666
4960.59	10.4579
4963.11	21.5657
4965.63	35.2531
4968.15	34.6411
4970.67	25.5546
4973.19	29.7822
4975.71	42.5347
4978.22	36.0278
4980.74	21.1266
4983.25	29.2897
4985.77	36.3431
4988.28	54.4176
4990.79	49.5315
4993.3	60.5113
4995.81	52.1111
4998.32	68.1989