File: Data/3-Raman/processed/bu19w-e-ff11b-fi07-l_150 (500nm)_532nm_edge_100%_x100_vis_h50um_30sx2_01_0.txt
#Acq. time (s)=	30
#Accumulations=	2
#Range (cm-¹)=	100...5000
#Windows=	1
#Auto scanning=	Off
#Autofocus=	Off
#Macrospot=	Off
#AutoExposure=	Off
#Spike filter=	Multiple accum.
#Delay time (s)=	2
#Binning=	1
#Readout mode=	Signal
#DeNoise=	Off
#ICS correction=	On
#Dark correction=	Off
#Inst. Process=	Off
#Detector Gain=	Best Dynamic
#Detector ADC=	50 kHz HS
#Detector temperature (°C)=	-60.09
#Instrument=	LabRAM HR Evol
#Detector=	SIN-EM FIVIS
#Objective=	x100_VIS
#Grating=	150 (500nm)
#ND Filter=	100%
#Laser=	532nm_Edge
#Hole=	49.98
#Temperature=	0
#Range=	Visible
#StageXY=	75x50mm Scan+
#StageZ=	Z motor
#X (µm)=	0
#Y (µm)=	0
#Z (µm)=	-273.9
#Full time(mm:ss)=	1:04
#Project=	21_11_04
#Sample=	BU19w
#Site=
#Title=	BU19w-E-FF11b-FI07-L_150 (500nm)_532nm_Edge_100%_x100_VIS_H50um_30sX2
#Remark=
#Date=	04.11.2021 17:49
#Acquired=	04.11.2021 17:49:21
#Base:Fit=	16.12.2021 17:39:50
#Base:Sub=	16.12.2021 17:47:49
101.869	2843.91
106.493	2957.64
111.113	3988.82
115.732	6762.34
120.349	8996.85
124.964	6674.94
129.577	3960.13
134.185	3044.39
138.793	2784.99
143.399	2724.46
148.003	2454.66
152.602	2331.18
157.201	2430.29
161.798	2629.93
166.392	2955.4
170.982	3489.79
175.572	4354.53
180.16	5893.31
184.745	8329.77
189.326	11514.6
193.907	14736
198.486	15552.3
203.06	13935.8
207.634	10863.6
212.206	7742.61
216.776	5512.07
221.341	3980.88
225.906	2869.75
230.469	2339.63
235.028	1894.7
239.586	1597.34
244.142	1437.3
248.694	1706.09
253.246	2632.66
257.795	2621.49
262.341	1524.44
266.886	675.758
271.428	398.635
275.967	252.747
280.505	148.297
285.041	106.082
289.573	72.9597
294.105	29.3458
298.632	0.00939941
303.159	-1.64124
307.685	9.40344
312.205	35.2126
316.726	-11.7427
321.242	30.3363
325.758	2.84106
330.272	67.6421
334.782	168.862
339.292	608.429
343.797	1922.97
348.302	2189.93
352.803	1150.8
357.304	530.655
361.802	351.495
366.297	267.935
370.791	217.592
375.281	256.313
379.77	345.777
384.256	569.297
388.741	785.092
393.223	948.566
397.704	790.891
402.18	513.24
406.657	458.142
411.13	467.594
415.602	607.737
420.07	631.985
424.538	751.981
429.002	1020.62
433.465	1525.49
437.925	2627.93
442.384	5043.36
446.839	11536.9
451.294	28313.9
455.745	37291.2
460.196	37358.2
464.642	20125.7
469.089	9385.95
473.531	5521.16
477.971	3831.02
482.411	2815.08
486.846	2253.78
491.282	1720.88
495.713	1656.2
500.144	1554.02
504.572	1423.93
508.997	1283.65
513.421	1070.43
517.842	991.356
522.263	865.336
526.679	708.503
531.093	677.792
535.507	666.976
539.917	600.524
544.327	576.722
548.733	494.846
553.137	431.225
557.54	417.919
561.94	395.105
566.337	375.089
570.734	427.665
575.127	389.576
579.518	405.832
583.909	446.458
588.295	419.538
592.68	380.686
597.064	358.974
601.445	356.394
605.823	320.948
610.201	312.834
614.575	328.793
618.947	316.045
623.317	286.525
627.686	283.213
632.052	291.468
636.415	300.239
640.777	261.425
645.138	265.761
649.495	278.823
653.85	214.835
658.205	202.776
662.556	236.727
666.905	219.15
671.252	213.933
675.597	291.842
679.941	288.317
684.282	395.508
688.62	520.787
692.957	430.677
697.293	336.371
701.625	237.579
705.955	237.88
710.283	219.33
714.609	175.753
718.933	203.266
723.257	190.739
727.577	169.93
731.894	169.17
736.21	177.233
740.524	137.435
744.835	180.025
749.147	166.046
753.454	157.91
757.759	189.285
762.063	170.093
766.364	158.163
770.663	213.642
774.96	251.857
779.257	323.969
783.55	488.94
787.841	711.628
792.13	946.431
796.417	1354.63
800.702	1643.64
804.985	1163.02
809.266	604.189
813.545	388.633
817.821	322.773
822.096	264.529
826.371	230.693
830.641	266.274
834.91	240.184
839.176	170.976
843.441	235.108
847.703	211.829
851.964	199.073
856.222	229.314
860.479	266.11
864.733	427.126
868.986	477.533
873.236	376.013
877.485	270.136
881.731	207.129
885.975	201.95
890.218	182.218
894.458	144.826
898.696	119.534
902.933	143.67
907.167	169.082
911.399	168.508
915.63	183.566
919.858	106.628
924.084	83.6536
928.308	91.4643
932.531	79.6644
936.749	85.0051
940.967	82.6458
945.184	89.838
949.398	72.4047
953.61	46.6652
957.821	40.2132
962.029	28.5309
966.236	49.8535
970.44	48.9104
974.642	56.5674
978.843	17.6501
983.041	7.47391
987.236	-1.64502
991.43	12.5302
995.623	-1.5181
999.813	5.93112
1004	-6.66187
1008.19	0.953491
1012.37	0.102783
1016.55	14.0065
1020.73	3.39685
1024.91	33.2241
1029.09	20.1512
1033.27	52.8688
1037.44	50.8537
1041.61	46.336
1045.78	51.3999
1049.94	99.8182
1054.11	203.049
1058.27	311.967
1062.43	345.208
1066.59	521.055
1070.75	840.452
1074.9	1037.47
1079.05	683.06
1083.2	310.882
1087.35	163.83
1091.5	131.347
1095.65	94.1135
1099.79	65.5104
1103.93	65.7605
1108.07	64.1404
1112.21	50.5842
1116.34	52.3858
1120.48	27.3705
1124.61	40.5888
1128.74	41.7355
1132.86	57.3828
1136.99	73.9616
1141.11	120.3
1145.23	226.59
1149.35	405.168
1153.47	516.623
1157.59	397.686
1161.7	224.804
1165.82	78.4925
1169.92	60.0431
1174.03	31.1212
1178.14	58.8008
1182.24	35.9764
1186.35	22.3271
1190.45	24.8548
1194.55	25.1841
1198.64	1.87003
1202.74	39.6687
1206.83	42.6783
1210.92	74.0448
1215.01	87.0822
1219.1	156.512
1223.18	182.458
1227.27	164.271
1231.35	120.351
1235.43	78.9277
1239.5	85.8842
1243.58	55.7487
1247.65	66.7226
1251.72	75.9629
1255.8	71.3277
1259.86	105.738
1263.93	86.2502
1267.99	104.857
1272.06	82.4858
1276.12	62.0622
1280.18	49.5999
1284.23	41.0582
1288.29	20.3276
1292.34	16.6324
1296.39	24.9406
1300.44	22.1264
1304.49	22.2463
1308.53	13.2476
1312.58	24.3655
1316.62	10.1318
1320.66	30.0476
1324.7	13.5706
1328.73	11.1022
1332.77	26.6857
1336.8	25.0384
1340.83	22.3152
1344.86	21.5486
1348.88	18.7722
1352.91	48.8508
1356.93	71.8806
1360.95	101.734
1364.97	176.087
1368.99	288.849
1373.01	395.504
1377.02	387.66
1381.03	218.393
1385.04	89.9883
1389.05	75.9705
1393.06	56.1514
1397.06	48.3143
1401.06	41.4395
1405.06	-1.93561
1409.06	24.6746
1413.06	6.95926
1417.05	21.7872
1421.05	-0.898376
1425.04	25.7237
1429.03	30.4366
1433.01	20.3289
1437	29.9778
1440.99	0.116974
1444.97	34.377
1448.95	17.2624
1452.93	17.8542
1456.9	19.3775
1460.88	30.6844
1464.85	30.0329
1468.82	22.4584
1472.79	36.5513
1476.76	15.2518
1480.73	37.0546
1484.69	26.477
1488.65	13.9396
1492.61	35.6117
1496.57	21.1705
1500.53	28.2119
1504.48	29.463
1508.43	24.0044
1512.39	38.9826
1516.33	27.7431
1520.28	29.1644
1524.23	55.8235
1528.17	31.0977
1532.11	44.2318
1536.05	47.6768
1539.99	44.3405
1543.93	59.4135
1547.86	66.7261
1551.8	85.6559
1555.73	75.4702
1559.66	101.042
1563.58	81.0533
1567.51	111.327
1571.44	98.9981
1575.36	120.472
1579.28	111.977
1583.2	146.869
1587.11	137.346
1591.03	150.921
1594.94	165.421
1598.85	174.124
1602.76	177.085
1606.67	186.83
1610.58	221.511
1614.48	225.512
1618.38	239.161
1622.29	255.644
1626.18	254.952
1630.08	260.085
1633.98	272.089
1637.87	248.669
1641.76	252.17
1645.65	253.888
1649.54	237.446
1653.43	242.114
1657.31	219.857
1661.2	205.226
1665.08	214.506
1668.96	205.455
1672.83	160.671
1676.71	158.136
1680.58	131.347
1684.46	128.45
1688.33	103.458
1692.2	91.8406
1696.06	75.4004
1699.93	76.1303
1703.79	61.5126
1707.66	54.4751
1711.52	61.6299
1715.37	34.6254
1719.23	44.6348
1723.08	46.1148
1726.94	42.8475
1730.79	41.4127
1734.64	9.05542
1738.49	33.8842
1742.33	16.5447
1746.18	22.5788
1750.02	19.4828
1753.86	18.386
1757.7	31.3844
1761.54	18.0121
1765.37	7.24866
1769.21	-4.38461
1773.04	23.1722
1776.87	19.1602
1780.7	24.556
1784.53	20.6945
1788.35	13.1136
1792.17	20.5053
1796	-0.220123
1799.82	11.8594
1803.64	4.01605
1807.45	6.46548
1811.27	17.367
1815.08	6.52679
1818.89	12.5223
1822.7	-0.447632
1826.51	5.38986
1830.32	7.36313
1834.12	0.765747
1837.92	4.47672
1841.72	10.0092
1845.52	2.30228
1849.32	20.9081
1853.12	13.0979
1856.91	13.6321
1860.7	-0.863312
1864.5	10.7207
1868.28	-2.79248
1872.07	13.4364
1875.86	36.1367
1879.64	4.31421
1883.42	6.8252
1887.21	22.2419
1890.98	14.0519
1894.76	0.388916
1898.54	26.2858
1902.31	25.6298
1906.08	36.0941
1909.85	27.2574
1913.62	23.1329
1917.39	34.7216
1921.16	15.1099
1924.92	14.001
1928.68	15.7207
1932.44	15.618
1936.2	28.5494
1939.96	21.9135
1943.71	33.9462
1947.47	21.6697
1951.22	28.7879
1954.97	46.1117
1958.72	34.1519
1962.46	42.7234
1966.21	40.9389
1969.95	40.935
1973.7	45.479
1977.43	27.4563
1981.17	40.2924
1984.91	56.7727
1988.65	33.0358
1992.38	43.7887
1996.11	50.7092
1999.84	41.7617
2003.57	35.6313
2007.3	56.301
2011.02	55.5775
2014.75	55.7828
2018.47	55.2268
2022.19	74.1272
2025.91	71.2211
2029.62	59.2186
2033.34	64.7401
2037.05	63.1134
2040.76	46.7873
2044.47	55.1608
2048.18	60.7817
2051.89	58.2348
2055.59	56.6283
2059.3	50.5965
2063	62.2302
2066.7	63.8795
2070.4	53.5896
2074.1	56.1874
2077.79	68.9872
2081.49	59.6298
2085.18	63.1882
2088.87	74.7214
2092.56	57.2249
2096.25	58.481
2099.93	69.0004
2103.61	56.1328
2107.3	56.2213
2110.98	65.5499
2114.66	64.6312
2118.33	80.3999
2122.01	70.0027
2125.68	56.7449
2129.36	53.6571
2133.03	56.0885
2136.7	52.946
2140.36	42.3689
2144.03	47.433
2147.7	48.7739
2151.36	45.5109
2155.02	54.1887
2158.68	42.7145
2162.34	51.4212
2165.99	58.3342
2169.65	45.2355
2173.3	40.4956
2176.95	63.1646
2180.6	43.0831
2184.25	41.206
2187.9	40.3123
2191.54	34.0992
2195.18	59.8733
2198.83	53.89
2202.47	36.079
2206.11	39.28
2209.74	25.1773
2213.38	14.7438
2217.01	38.2208
2220.64	36.9832
2224.27	24.7219
2227.9	34.5099
2231.53	29.5683
2235.16	39.4247
2238.78	36.3478
2242.4	40.6653
2246.02	18.9872
2249.64	25.1483
2253.26	27.6383
2256.88	38.5652
2260.49	8.39331
2264.11	25.8361
2267.72	25.5397
2271.33	22.4956
2274.93	23.1344
2278.54	20.8463
2282.15	30.6252
2285.75	15.8247
2289.35	31.2561
2292.95	14.5049
2296.55	13.8246
2300.15	21.6789
2303.74	18.1234
2307.34	30.607
2310.93	26.9324
2314.52	23.208
2318.11	18.4803
2321.7	31.6846
2325.28	46.574
2328.87	29.2282
2332.45	26.0557
2336.03	43.5883
2339.61	41.2533
2343.19	27.6071
2346.77	40.2401
2350.34	27.5096
2353.92	12.0038
2357.49	6.80167
2361.06	37.9202
2364.63	27.0814
2368.2	23.725
2371.76	19.5281
2375.33	12.5595
2378.89	12.9968
2382.45	18.078
2386.01	35.1346
2389.57	18.2024
2393.13	13.3053
2396.68	29.5969
2400.23	19.3996
2403.79	23.1212
2407.34	25.0664
2410.88	17.0444
2414.43	15.5233
2417.98	31.5296
2421.52	14.5052
2425.06	15.0112
2428.61	5.44421
2432.14	17.1739
2435.68	28.0918
2439.22	17.7281
2442.75	11.9948
2446.29	14.6426
2449.82	42.6268
2453.35	7.01141
2456.88	19.0043
2460.4	31.7021
2463.93	16.0918
2467.45	30.4026
2470.98	10.9479
2474.5	9.93573
2478.02	2.20123
2481.54	16.2169
2485.05	31.9907
2488.57	21.1955
2492.08	19.9575
2495.59	13.8984
2499.1	9.79761
2502.61	20.6041
2506.12	15.4316
2509.63	-2.83713
2513.13	14.3291
2516.63	13.8584
2520.13	24.5765
2523.63	-4.7717
2527.13	18.0428
2530.63	19.6484
2534.12	0.0587769
2537.62	3.65131
2541.11	12.8402
2544.6	15.7161
2548.09	15.9702
2551.58	-0.4021
2555.06	11.0222
2558.55	30.9827
2562.03	1.80496
2565.51	14.5064
2568.99	4.98849
2572.47	4.84818
2575.95	15.0723
2579.43	21.6564
2582.9	12.2705
2586.37	16.0683
2589.84	32.146
2593.31	21.5093
2596.78	15.5174
2600.25	14.371
2603.71	-3.07108
2607.18	-0.614655
2610.64	3.52545
2614.1	10.3042
2617.56	17.2284
2621.02	7.68176
2624.47	6.72382
2627.93	0.87616
2631.38	11.308
2634.83	14.9365
2638.28	13.6684
2641.73	17.1347
2645.18	26.2607
2648.62	6.69873
2652.07	26.2082
2655.51	5.60416
2658.95	5.90219
2662.39	13.7424
2665.83	30.0168
2669.27	32.0679
2672.7	30.3206
2676.14	8.93005
2679.57	10.1475
2683	4.88391
2686.43	18.3974
2689.86	6.9101
2693.29	5.81738
2696.71	-0.938965
2700.13	19.3706
2703.56	16.425
2706.98	6.0282
2710.4	14.4614
2713.82	20.1737
2717.23	-3.84164
2720.65	10.3728
2724.06	10.6616
2727.47	-6.77066
2730.88	17.8537
2734.29	20.048
2737.7	2.56693
2741.11	12.242
2744.51	23.752
2747.91	8.91946
2751.32	25.0992
2754.72	21.518
2758.11	15.0626
2761.51	28.397
2764.91	12.4415
2768.3	23.7606
2771.7	14.291
2775.09	28.3533
2778.48	26.3392
2781.87	18.6295
2785.25	18.4294
2788.64	21.0385
2792.03	36.7936
2795.41	18.6946
2798.79	35.3617
2802.17	24.7393
2805.55	24.4478
2808.93	22.2762
2812.3	11.6661
2815.68	31.9109
2819.05	37.1594
2822.42	29.3824
2825.79	27.2596
2829.16	30.7557
2832.53	37.0851
2835.89	22.9775
2839.26	30.3529
2842.62	16.365
2845.98	23.8772
2849.34	45.4975
2852.7	36.4458
2856.06	36.671
2859.41	31.329
2862.77	42.8704
2866.12	34.7673
2869.47	50.1094
2872.82	53.249
2876.17	42.2773
2879.52	57.6299
2882.87	46.6183
2886.21	30.8409
2889.55	55.614
2892.89	41.6822
2896.23	50.3311
2899.57	49.4812
2902.91	39.1147
2906.25	63.7084
2909.58	58.9422
2912.91	61.7161
2916.25	64.4686
2919.58	59.594
2922.91	71.7238
2926.23	80.9797
2929.56	86.3879
2932.88	59.6416
2936.21	90.4322
2939.53	103.259
2942.85	87.802
2946.17	109.094
2949.49	76.7478
2952.8	102.717
2956.12	107.988
2959.43	95.4817
2962.74	89.5972
2966.06	106.246
2969.37	142.697
2972.67	144.541
2975.98	137.003
2979.28	145.505
2982.59	145.503
2985.89	164.302
2989.19	148.397
2992.49	150.343
2995.79	172.985
2999.09	164.652
3002.38	183.579
3005.68	191.228
3008.97	190.454
3012.26	196.297
3015.55	218.179
3018.84	225.929
3022.13	230.849
3025.41	248.044
3028.7	250.157
3031.98	243.76
3035.26	277.031
3038.54	283.834
3041.82	296.325
3045.1	299.372
3048.38	292.013
3051.65	331.068
3054.92	351.224
3058.2	361.891
3061.47	365.713
3064.73	386.717
3068	394.36
3071.27	408.542
3074.54	424.828
3077.8	454.246
3081.06	468.172
3084.32	488.51
3087.58	483.185
3090.84	512.271
3094.1	529.198
3097.35	555.4
3100.61	581.258
3103.86	617.369
3107.11	635.897
3110.36	675.267
3113.61	686.707
3116.86	690.625
3120.11	728.857
3123.35	771.87
3126.59	811.072
3129.84	820.711
3133.08	873.263
3136.32	899.11
3139.55	945.869
3142.79	991.664
3146.03	1012.68
3149.26	1078.61
3152.49	1091.18
3155.72	1121.82
3158.95	1171.59
3162.18	1207.97
3165.41	1263.45
3168.64	1295.89
3171.86	1380.7
3175.08	1387.19
3178.31	1439.33
3181.53	1505.72
3184.75	1508.25
3187.96	1623.07
3191.18	1661.51
3194.4	1667.53
3197.61	1713.52
3200.82	1764.19
3204.03	1866.33
3207.24	1870.46
3210.45	1892.76
3213.66	1952.3
3216.86	2014.86
3220.07	2067.89
3223.27	2081.04
3226.48	2098.25
3229.68	2147.85
3232.87	2223.37
3236.07	2246.34
3239.27	2311.8
3242.47	2286.99
3245.66	2371.86
3248.85	2376.73
3252.04	2475.33
3255.23	2439.61
3258.42	2514.54
3261.61	2506.06
3264.8	2545.88
3267.98	2650.27
3271.16	2617.77
3274.35	2642.39
3277.53	2652.68
3280.71	2674.76
3283.89	2760.19
3287.06	2755
3290.24	2842.96
3293.41	2836.77
3296.58	2890.48
3299.76	2945.06
3302.93	2932.89
3306.1	2994.07
3309.26	3028.26
3312.43	3123.63
3315.59	3150.26
3318.76	3213.78
3321.92	3276.1
3325.08	3350.66
3328.24	3291.69
3331.4	3406.86
3334.56	3455.98
3337.71	3540.28
3340.87	3609.68
3344.02	3696.02
3347.17	3748.37
3350.33	3788.6
3353.47	3859.82
3356.62	3897.61
3359.77	3963.87
3362.92	4099.53
3366.06	4170.27
3369.2	4263.93
3372.34	4290.82
3375.49	4409.87
3378.62	4407.4
3381.76	4523.32
3384.9	4555.88
3388.04	4573.79
3391.17	4682.63
3394.3	4732.83
3397.43	4827.8
3400.56	4823.56
3403.69	4892.82
3406.82	4967.48
3409.95	5036.89
3413.07	5121.64
3416.2	5090.85
3419.32	5139.73
3422.44	5184.41
3425.56	5194.58
3428.68	5203.75
3431.8	5194.04
3434.91	5231.94
3438.03	5251.2
3441.14	5219.64
3444.25	5253.91
3447.36	5256.39
3450.47	5198.75
3453.58	5216.5
3456.69	5213.21
3459.79	5143.44
3462.9	5086.98
3466	5080.69
3469.11	5025.31
3472.21	4937.54
3475.31	4896.2
3478.4	4904.43
3481.5	4785.22
3484.6	4677.65
3487.69	4667.84
3490.79	4604.91
3493.88	4508.58
3496.97	4393.29
3500.06	4351.23
3503.15	4235.9
3506.23	4146.18
3509.32	4028.41
3512.4	3885.8
3515.49	3833.25
3518.57	3756.09
3521.65	3636.2
3524.73	3592.87
3527.81	3501.23
3530.89	3420.79
3533.96	3320.74
3537.03	3215.05
3540.11	3070.83
3543.18	3054.9
3546.25	2945.49
3549.32	2821.6
3552.39	2822.48
3555.46	2686.81
3558.52	2614.92
3561.59	2528.84
3564.65	2441.08
3567.71	2421.04
3570.77	2316.6
3573.83	2259.13
3576.89	2177.12
3579.95	2110.06
3583	2043.75
3586.06	1994.29
3589.11	1954.33
3592.16	1796.52
3595.21	1824.52
3598.27	1762.28
3601.31	1657.49
3604.36	1586.64
3607.41	1545.05
3610.45	1461.89
3613.5	1425.03
3616.54	1373.04
3619.58	1311.74
3622.62	1290.22
3625.66	1251.79
3628.69	1158.86
3631.73	1083.83
3634.77	1037.03
3637.8	984.023
3640.83	957.572
3643.86	856.933
3646.89	873.32
3649.92	785.833
3652.95	728.755
3655.98	719.953
3659	607.303
3662.02	613.927
3665.05	543.154
3668.07	487.899
3671.09	479.004
3674.11	429.575
3677.13	400.902
3680.14	374.13
3683.16	340.67
3686.17	295.832
3689.19	274.615
3692.2	260.017
3695.21	259.629
3698.22	222.144
3701.23	211.3
3704.23	215.629
3707.24	174.37
3710.24	162.465
3713.25	155.272
3716.25	148.009
3719.25	149.345
3722.25	129.684
3725.25	126.164
3728.25	97.8462
3731.24	113.305
3734.24	74.4446
3737.23	108.866
3740.22	81.3668
3743.21	85.2405
3746.21	76.7165
3749.19	59.6096
3752.18	62.4468
3755.17	57.6805
3758.15	69.0625
3761.14	29.2193
3764.12	53.8351
3767.1	47.1782
3770.08	37.7191
3773.06	34.9245
3776.04	51.066
3779.02	16.1883
3781.99	44.6492
3784.97	30.6026
3787.94	28.8577
3790.91	26.1891
3793.88	43.3956
3796.85	18.1576
3799.82	40.1328
3802.79	21.5634
3805.76	34.1693
3808.72	15.616
3811.69	22.5894
3814.65	24.8498
3817.61	26.175
3820.57	25.6236
3823.53	35.4951
3826.49	39.7188
3829.45	23.0981
3832.4	2.66061
3835.36	20.193
3838.31	18.7716
3841.26	17.3495
3844.21	13.0694
3847.16	27.8289
3850.11	14.0445
3853.06	18.3728
3856	37.9849
3858.95	-0.628998
3861.89	10.4066
3864.84	24.3134
3867.78	27.7118
3870.72	35.8807
3873.66	15.2821
3876.6	27.2731
3879.53	20.9992
3882.47	23.334
3885.4	35.2437
3888.34	34.6399
3891.27	19.6012
3894.2	19.9306
3897.13	45.2266
3900.06	38.7484
3902.99	21.6899
3905.91	41.1237
3908.84	19.2636
3911.76	27.174
3914.69	19.6808
3917.61	25.6114
3920.53	37.3652
3923.45	26.012
3926.37	21.3502
3929.28	16.666
3932.2	26.3412
3935.11	28.4193
3938.03	28.6447
3940.94	27.9767
3943.85	40.6815
3946.76	40.9555
3949.67	27.8588
3952.58	6.1662
3955.49	43.8569
3958.39	35.6121
3961.3	34.086
3964.2	22.0299
3967.1	31.0794
3970	37.2748
3972.9	25.2494
3975.8	31.4526
3978.7	17.4666
3981.6	31.3198
3984.49	27.8736
3987.39	25.3711
3990.28	21.9001
3993.17	37.6227
3996.06	38.9824
3998.95	39.3732
4001.84	32.0793
4004.73	19.0056
4007.61	26.1718
4010.5	26.6009
4013.38	43.4186
4016.27	23.595
4019.15	38.4982
4022.03	24.448
4024.91	19.0799
4027.79	26.2758
4030.66	14.1452
4033.54	17.4863
4036.42	40.1832
4039.29	10.6426
4042.16	22.7138
4045.03	26.9922
4047.9	37.1013
4050.77	17.1783
4053.64	5.98312
4056.51	12.2728
4059.38	14.6771
4062.24	21.9298
4065.1	20.4416
4067.97	25.7582
4070.83	27.1832
4073.69	35.422
4076.55	13.4704
4079.41	13.9057
4082.26	34.8106
4085.12	17.7025
4087.97	11.2984
4090.83	15.6226
4093.68	27.7804
4096.53	19.4161
4099.38	19.8514
4102.23	15.3947
4105.08	11.9023
4107.93	10.3323
4110.77	14.6328
4113.62	31.6292
4116.46	24.1292
4119.3	13.6537
4122.14	-3.66995
4124.98	21.1171
4127.82	8.72607
4130.66	37.5149
4133.5	15.442
4136.33	30.6695
4139.17	29.9003
4142	22.0095
4144.83	14.4395
4147.67	19.7316
4150.5	18.1951
4153.33	11.7045
4156.15	10.9922
4158.98	7.23276
4161.81	18.2291
4164.63	9.70241
4167.45	-1.76001
4170.28	25.9096
4173.1	5.67232
4175.92	8.91356
4178.74	4.33136
4181.56	17.3725
4184.37	9.88565
4187.19	21.9764
4190	14.5094
4192.82	4.1398
4195.63	9.45877
4198.44	15.799
4201.25	-4.33183
4204.06	1.02789
4206.87	4.42177
4209.68	12.7334
4212.48	-10.4025
4215.29	12.6469
4218.1	8.3147
4220.9	13.8263
4223.7	8.46999
4226.5	-1.8674
4229.3	-0.32872
4232.1	8.15042
4234.9	21.6303
4237.69	2.4295
4240.49	13.9711
4243.28	5.65932
4246.07	14.2673
4248.87	3.93839
4251.66	8.53294
4254.45	18.1261
4257.24	20.7119
4260.03	23.2964
4262.81	12.8593
4265.6	8.43098
4268.38	13.0558
4271.17	8.629
4273.95	-2.87325
4276.73	9.76411
4279.51	13.2981
4282.29	12.7755
4285.07	4.13477
4287.84	15.6862
4290.62	10.0113
4293.39	6.34344
4296.17	5.74237
4298.94	7.18898
4301.71	8.6151
4304.48	11.0514
4307.25	17.55
4310.02	-0.316925
4312.79	11.2977
4315.55	15.7681
4318.32	10.0401
4321.08	10.3962
4323.85	7.67665
4326.61	10.0334
4329.37	3.2307
4332.13	-10.7297
4334.89	7.91774
4337.65	25.5283
4340.4	6.49846
4343.16	4.79361
4345.91	18.4069
4348.67	19.8112
4351.42	17.1356
4354.17	0.218079
4356.92	9.83328
4359.67	12.2965
4362.42	9.63101
4365.17	5.95779
4367.91	13.5332
4370.66	11.91
4373.4	37.9443
4376.14	17.8033
4378.89	5.83813
4381.63	5.15474
4384.37	14.7615
4387.11	-1.27814
4389.84	17.7431
4392.58	3.87027
4395.32	2.51736
4398.05	3.07814
4400.78	17.0702
4403.52	12.4145
4406.25	11.9073
4408.98	21.7983
4411.71	26.4831
4414.44	18.6451
4417.16	9.73631
4419.89	12.1872
4422.62	13.6334
4425.34	5.70245
4428.06	8.20898
4430.78	13.8543
4433.51	13.224
4436.22	14.674
4438.94	6.68315
4441.66	15.4314
4444.38	16.8501
4447.1	29.7983
4449.81	6.01152
4452.52	10.5411
4455.24	12.967
4457.95	16.4231
4460.66	8.30495
4463.37	14.9322
4466.08	4.72803
4468.78	7.15671
4471.49	4.3333
4474.2	8.89981
4476.9	8.22174
4479.6	11.7798
4482.31	0.576553
4485.01	11.5425
4487.71	8.76074
4490.41	8.0815
4493.11	13.697
4495.8	12.9147
4498.5	14.2983
4501.19	25.2069
4503.89	-0.996323
4506.58	30.0572
4509.27	22.9598
4511.96	20.1008
4514.66	1.32065
4517.34	12.2675
4520.03	1.9799
4522.72	21.4777
4525.41	9.08044
4528.09	0.919785
4530.77	11.931
4533.46	11.2352
4536.14	18.0135
4538.82	17.3349
4541.5	-0.421906
4544.18	9.58754
4546.86	2.50031
4549.53	8.25407
4552.21	5.46127
4554.88	6.99591
4557.56	9.63748
4560.23	20.9651
4562.9	21.5908
4565.57	13.6464
4568.24	20.8993
4570.91	4.18286
4573.58	11.0554
4576.24	17.8161
4578.91	6.23349
4581.58	5.59338
4584.24	3.92374
4586.9	16.2793
4589.56	16.6438
4592.22	10.4368
4594.88	3.1411
4597.54	1.3317
4600.2	-3.78862
4602.86	17.3841
4605.51	12.3282
4608.17	8.36032
4610.82	13.1667
4613.47	-7.28326
4616.13	16.1893
4618.78	12.2131
4621.43	23.6595
4624.07	13.0749
4626.72	9.07184
4629.37	12.7791
4632.01	13.1711
4634.66	19.0586
4637.3	9.44667
4639.94	-1.28496
4642.59	16.7685
4645.23	0.536453
4647.87	2.0843
4650.5	8.13208
4653.14	13.1628
4655.78	21.4911
4658.42	13.9329
4661.05	19.9296
4663.68	21.5128
4666.31	7.42116
4668.95	12.2669
4671.58	21.6206
4674.21	8.57239
4676.84	17.9308
4679.46	-9.73674
4682.09	10.8431
4684.72	15.7183
4687.34	3.73006
4689.97	2.98251
4692.59	29.2748
4695.21	7.11247
4697.83	19.8845
4700.45	10.1043
4703.07	10.4713
4705.69	17.599
4708.3	15.6826
4710.92	8.09967
4713.54	5.0341
4716.15	17.8111
4718.76	3.40051
4721.37	22.9701
4723.99	14.2003
4726.59	14.5276
4729.2	-4.41698
4731.81	7.27068
4734.42	17.8362
4737.03	21.5877
4739.63	1.4558
4742.23	13.1449
4744.84	-3.61531
4747.44	1.2236
4750.04	21.9635
4752.64	29.0592
4755.24	15.667
4757.84	5.68513
4760.44	17.3518
4763.03	5.12808
4765.63	17.9693
4768.22	12.6347
4770.82	17.5847
4773.41	20.209
4776	-1.1292
4778.59	6.06502
4781.18	4.1239
4783.77	11.3272
4786.36	1.38904
4788.94	15.4672
4791.53	24.9894
4794.11	9.33868
4796.7	7.42793
4799.28	4.39072
4801.86	22.0185
4804.44	-0.502869
4807.02	17.1948
4809.6	21.1389
4812.18	12.4166
4814.76	12.9146
4817.33	-0.426453
4819.91	25.5206
4822.48	7.55043
4825.06	5.76425
4827.63	12.0928
4830.2	6.82097
4832.77	-3.09422
4835.34	10.2683
4837.91	12.0291
4840.48	23.1642
4843.04	8.57863
4845.61	10.3232
4848.17	12.0514
4850.74	19.6017
4853.3	17.6216
4855.86	10.9471
4858.42	23.3164
4860.98	7.40947
4863.54	5.57623
4866.1	7.2146
4868.66	13.5909
4871.21	25.9535
4873.77	9.85452
4876.32	11.4905
4878.88	7.19728
4881.43	20.6964
4883.98	12.8166
4886.53	10.8701
4889.08	2.97978
4891.63	1.03339
4894.18	-0.92215
4896.72	30.476
4899.27	15.4109
4901.81	13.4476
4904.36	23.4115
4906.9	9.50505
4909.44	15.879
4911.98	16.2453
4914.52	15.401
4917.06	15.7335
4919.6	23.2548
4922.14	18.8327
4924.67	20.3871
4927.21	20.7619
4929.74	25.8952
4932.28	13.1486
4934.81	18.374
4937.34	-0.347183
4939.87	19.2208
4942.4	14.7722
4944.93	19.9646
4947.46	24.001
4949.99	13.654
4952.51	18.9016
4955.04	6.13857
4957.56	22.2012
4960.08	20.2863
4962.61	25.5997
4965.13	39.4003
4967.65	25.566
4970.17	20.0893
4972.69	19.4176
4975.2	25.9882
4977.72	25.3111
4980.24	45.2148
4982.75	33.6655
4985.27	-0.933411
4987.78	22.6565
4990.29	13.4983
4992.8	21.3379
4995.31	14.5821
4997.82	28.5545