File: Data/3-Raman/processed/bu19w-d-ff2-fi09-v_150 (500nm)_532nm_edge_100%_x100_vis_lwd_h50um_30sx2_01_0.txt
#Acq. time (s)=	30
#Accumulations=	2
#Range (cm-¹)=	100...4000
#Windows=	1
#Auto scanning=	Off
#Autofocus=	Off
#Macrospot=	Off
#AutoExposure=	Off
#Spike filter=	Multiple accum.
#Delay time (s)=	2
#Binning=	1
#Readout mode=	Signal
#DeNoise=	Off
#ICS correction=	On
#Dark correction=	Off
#Inst. Process=	Off
#Detector Gain=	Best Dynamic
#Detector ADC=	50 kHz HS
#Detector temperature (°C)=	-60.09
#Instrument=	LabRAM HR Evol
#Detector=	SIN-EM FIVIS
#Objective=	x100_VIS_LWD
#Grating=	150 (500nm)
#ND Filter=	100%
#Laser=	532nm_Edge
#Hole=	49.98
#Temperature=	0
#Range=	Visible
#StageXY=	75x50mm Scan+
#StageZ=	Z motor
#X (µm)=	0
#Y (µm)=	0
#Z (µm)=	70.2
#Full time(mm:ss)=	1:05
#Project=	21_11_22
#Sample=	BU19w
#Site=
#Title=	BU19w-D-FF2-FI09-V_150 (500nm)_532nm_Edge_100%_x100_VIS_LWD_H50um_30sX2
#Remark=
#Date=	22.11.2021 13:35
#Acquired=	22.11.2021 13:35:55
#Base:Fit=	16.12.2021 17:39:50
#Base:Edit=	16.12.2021 17:43:33
#Base:Edit=	16.12.2021 17:43:36
#Base:Edit=	16.12.2021 17:43:38
#Base:Edit=	16.12.2021 17:43:41
#Base:Edit=	16.12.2021 17:43:44
#Base:Sub=	16.12.2021 17:43:46
103.97	5591.93
108.592	5034.27
113.209	4178.06
117.826	3752.04
122.441	3370.69
127.054	3073.78
131.664	2889.78
136.27	2609.01
140.876	2252.67
145.48	2080.72
150.081	2241.03
154.678	3163.51
159.275	3736.21
163.869	2431.54
168.461	1432.08
173.049	1104.21
177.637	1408.97
182.222	2907.35
186.806	3917.11
191.384	2685.36
195.963	1379.38
200.54	613.046
205.112	344.61
209.684	209.586
214.253	97.7732
218.821	2.92883
223.384	137.577
227.947	584.282
232.507	1026.22
237.064	1442.5
241.62	2735.4
246.174	3326.66
250.724	2255.49
255.273	1223.19
259.82	515.2
264.363	618.889
268.906	1863.18
273.447	5140.15
277.983	7240.87
282.519	4668.8
287.051	1982.29
291.583	1019.01
296.112	1263.76
300.637	1900.95
305.162	1488.99
309.685	682.625
314.204	339.062
318.722	532.295
323.236	1091.4
327.75	1647.79
332.262	1207.63
336.77	692.571
341.277	1050.01
345.78	2069.58
350.283	2406.04
354.782	1506.77
359.28	754.812
363.775	823.237
368.269	1174.01
372.761	874.989
377.249	286.28
381.736	254.404
386.22	578.621
390.703	1104.75
395.182	1347.61
399.661	1044.83
404.136	864.625
408.61	1782.11
413.08	4568.12
417.551	5651.44
422.017	2739.4
426.482	834.704
430.944	204.259
435.406	71.3514
439.863	-19.9879
444.32	80.7676
448.773	383.226
453.226	813.395
457.674	646.929
462.121	311.015
466.567	137.942
471.009	152.169
475.452	282.647
479.889	435.489
484.327	729.961
488.761	1062.95
493.194	1337.79
497.623	1327.8
502.051	1039.29
506.478	664.051
510.9	450.51
515.323	291.171
519.742	209.312
524.158	194.507
528.574	181.864
532.987	203.829
537.397	238.288
541.807	288.665
546.212	374.771
550.618	408.343
555.019	463.07
559.419	488.293
563.818	446.461
568.213	363.058
572.606	381.754
576.999	557.864
581.388	1128.56
585.775	2256.16
590.161	2208.78
594.544	1287
598.924	978.866
603.304	1469.65
607.68	2409.04
612.055	2504.75
616.426	1451.12
620.798	797.809
625.166	521.44
629.532	485.433
633.897	559.326
638.258	702.095
642.618	675.184
646.975	584.659
651.332	684.22
655.685	969.888
660.036	1448.03
664.385	1810.77
668.734	1919.96
673.079	2065.78
677.421	2056.48
681.762	1530.09
686.1	926.297
690.439	566.865
694.773	322.22
699.105	228.35
703.435	185.648
707.763	148.72
712.091	121.375
716.415	112.372
720.737	97.0519
725.057	111.087
729.375	98.4055
733.692	123.542
738.006	106.794
742.317	111.6
746.627	147.209
750.934	175.259
755.24	231.733
759.543	318.16
763.846	500.408
768.146	822.867
772.443	1386.92
776.738	1845.05
781.031	1628.95
785.322	1056.23
789.611	643.25
793.898	411.198
798.183	296.765
802.466	208.329
806.748	126.724
811.027	115.514
815.304	80.1425
819.579	75.4721
823.851	57.681
828.122	51.9795
832.391	53.9497
836.657	4.00635
840.922	3.57297
845.184	-1.45349
849.445	7.53772
853.703	27.5109
857.96	67.2575
862.214	123.362
866.467	94.463
870.717	25.9528
874.965	-8.50961
879.212	-29.8251
883.456	-31.5775
887.699	-36.8251
891.939	-32.5109
896.177	-30.8423
900.414	-15.0813
904.648	-29.1544
908.88	-29.7342
913.111	-18.1103
917.339	8.50488
921.565	15.5321
925.79	44.7329
930.012	108.884
934.232	206.116
938.451	437.853
942.667	733.99
946.881	1046.13
951.094	1039.04
955.302	792.651
959.511	591.739
963.717	553.928
967.921	465.415
972.124	334.887
976.324	183.473
980.523	110.771
984.719	61.4608
988.914	47.1632
993.104	27.9816
997.295	46.2391
1001.48	48.7833
1005.67	51.4529
1009.85	78.6901
1014.04	84.5866
1018.22	157.718
1022.4	211.732
1026.57	266.661
1030.75	368.521
1034.92	506.894
1039.09	809.55
1043.26	1542.44
1047.42	2881.07
1051.59	3972.09
1055.75	3369.84
1059.91	2123.84
1064.07	1376.28
1068.23	1160.55
1072.38	1322.33
1076.54	1885.39
1080.69	3128.22
1084.84	4953.71
1088.98	6353.67
1093.13	5594.62
1097.27	3980.25
1101.41	3349.67
1105.55	3879.64
1109.69	4323.79
1113.83	3842.95
1117.96	3064.09
1122.09	2762.63
1126.22	2881.44
1130.35	3061.31
1134.47	2784.58
1138.6	2122.44
1142.72	1625.46
1146.84	1619.93
1150.96	2125.83
1155.07	2933.66
1159.19	2937.38
1163.3	2316.6
1167.41	1894.6
1171.52	1551.64
1175.62	985.341
1179.73	536.356
1183.83	364.637
1187.93	307.914
1192.03	272.743
1196.13	270.243
1200.22	236.035
1204.31	202.005
1208.4	179.374
1212.49	273.125
1216.58	522.655
1220.67	834.434
1224.75	796.035
1228.83	576.12
1232.91	541.528
1236.99	720.57
1241.06	722.392
1245.14	587.849
1249.21	541.786
1253.28	529.89
1257.35	343.258
1261.41	323.534
1265.48	687.369
1269.54	2500.44
1273.6	3241.97
1277.66	1142.31
1281.72	243.687
1285.77	154.433
1289.82	126.433
1293.88	125.533
1297.92	104.45
1301.97	98.403
1306.02	82.2432
1310.06	71.1018
1314.1	68.899
1318.14	80.7136
1322.18	77.3018
1326.22	56.7314
1330.25	82.388
1334.28	76.7755
1338.31	89.1349
1342.34	96.4247
1346.37	108.673
1350.39	149.757
1354.42	242.383
1358.44	320.768
1362.46	372.237
1366.47	631.244
1370.49	2075.27
1374.5	5321.7
1378.51	4130.35
1382.52	970.516
1386.53	297.925
1390.54	246.748
1394.54	460.634
1398.55	503.268
1402.55	216.765
1406.55	85.8428
1410.54	69.2159
1414.54	58.4842
1418.53	21.0656
1422.52	8.25183
1426.51	-0.752655
1430.5	-6.81236
1434.49	-14.8535
1438.47	-15.0199
1442.45	-40.8929
1446.43	-32.2534
1450.41	-30.5715
1454.39	-33.8637
1458.36	-31.2907
1462.34	-42.5795
1466.31	-35.2
1470.28	-30.778
1474.24	-27.3832
1478.21	-27.9631
1482.17	-28.5724
1486.14	-12.6004
1490.1	-28.8888
1494.05	-22.7305
1498.01	-21.4611
1501.97	-10.4617
1505.92	-15.0082
1509.87	-17.6138
1513.82	1.12152
1517.77	-5.39937
1521.71	-1.26154
1525.66	0.917709
1529.6	5.99547
1533.54	12.9867
1537.48	20.9168
1541.41	20.0932
1545.35	22.1442
1549.28	46.4433
1553.21	30.9676
1557.14	33.8338
1561.07	54.0591
1565	40.3595
1568.92	47.8908
1572.84	65.9977
1576.76	58.9469
1580.68	79.8329
1584.6	68.8406
1588.51	88.6313
1592.43	96.8091
1596.34	87.6423
1600.25	90.9572
1604.16	114.419
1608.06	125.362
1611.97	124.772
1615.87	141.429
1619.77	145.579
1623.67	138.238
1627.57	139.519
1631.46	130.317
1635.36	154.582
1639.25	154.941
1643.14	148.624
1647.03	148.043
1650.91	135.926
1654.8	148.698
1658.68	126.852
1662.56	121.241
1666.44	119.405
1670.32	94.3913
1674.2	91.4327
1678.07	94.1058
1681.94	85.1567
1685.81	83.8449
1689.68	70.9701
1693.55	64.762
1697.41	68.0624
1701.28	49.3496
1705.14	48.7221
1709	50.8821
1712.86	42.5747
1716.72	49.4137
1720.57	49.5921
1724.42	42.1927
1728.28	46.0504
1732.13	20.7993
1735.97	33.0479
1739.82	33.0579
1743.66	40.4958
1747.51	27.5093
1751.35	30.3731
1755.19	39.7712
1759.02	25.2423
1762.86	31.9656
1766.69	25.6913
1770.53	27.8194
1774.36	27.1436
1778.18	10.638
1782.01	14.6175
1785.84	25.1437
1789.66	16.021
1793.48	19.0428
1797.3	9.82961
1801.12	8.96627
1804.94	20.3044
1808.75	23.1461
1812.57	12.7421
1816.38	10.749
1820.19	7.75773
1824	4.7253
1827.8	14.8467
1831.61	13.5974
1835.41	6.66163
1839.21	10.9889
1843.01	14.3215
1846.81	12.9494
1850.6	10.5782
1854.4	7.22889
1858.19	11.3032
1861.98	11.6042
1865.77	10.0423
1869.56	14.0464
1873.34	10.6465
1877.13	16.4889
1880.91	14.976
1884.69	5.18092
1888.47	12.0814
1892.25	16.229
1896.02	9.32356
1899.8	10.7413
1903.57	2.9744
1907.34	12.7086
1911.11	4.97675
1914.88	6.46733
1918.64	13.5773
1922.41	3.13297
1926.17	11.2243
1929.93	10.0615
1933.69	10.7533
1937.44	-0.69323
1941.2	1.84082
1944.95	10.0134
1948.7	8.72131
1952.46	1.73938
1956.2	8.77566
1959.95	-0.20327
1963.7	0.202911
1967.44	-2.23992
1971.18	-3.79123
1974.92	4.9426
1978.66	-6.01639
1982.4	7.33012
1986.13	1.02832
1989.87	-0.612549
1993.6	13.5341
1997.33	4.40491
2001.06	2.72491
2004.78	-1.72388
2008.51	0.269043
2012.23	-1.42014
2015.96	4.3026
2019.67	-1.82695
2023.39	3.13008
2027.11	3.53291
2030.83	9.47896
2034.54	-2.80435
2038.25	-6.86027
2041.96	10.1454
2045.67	3.35381
2049.38	5.75726
2053.08	5.43562
2056.79	-0.313751
2060.49	4.12674
2064.19	9.55104
2067.89	6.72931
2071.58	9.45061
2075.28	2.03423
2078.97	3.87888
2082.67	6.65736
2086.36	6.51793
2090.05	-0.206848
2093.73	11.7356
2097.42	9.74294
2101.1	6.77635
2104.78	9.37923
2108.47	3.60316
2112.14	0.627274
2115.82	19.0281
2119.5	9.50439
2123.17	9.25131
2126.84	5.28664
2130.52	4.10657
2134.18	5.71037
2137.85	9.14784
2141.52	-2.17792
2145.18	9.53885
2148.84	6.53514
2152.51	3.56306
2156.17	-1.2068
2159.82	16.0057
2163.48	11.3061
2167.14	25.8064
2170.79	20.3195
2174.44	27.6468
2178.09	28.6342
2181.74	36.0042
2185.38	31.5998
2189.03	35.4702
2192.67	28.5083
2196.32	35.2615
2199.96	37.5034
2203.59	44.359
2207.23	40.3098
2210.87	35.376
2214.5	35.0387
2218.13	34.7204
2221.76	33.5059
2225.39	40.5845
2229.02	33.863
2232.65	33.6192
2236.27	22.2805
2239.89	19.2583
2243.51	22.7349
2247.13	22.5232
2250.75	13.0274
2254.37	15.6569
2257.98	14.569
2261.59	17.2194
2265.2	6.77094
2268.81	7.60657
2272.42	14.0784
2276.03	5.4519
2279.64	1.45572
2283.24	10.6708
2286.84	0.0706558
2290.44	-2.03881
2294.04	11.0047
2297.64	3.25092
2301.23	1.16539
2304.83	14.2267
2308.42	31.0771
2312.01	112.378
2315.6	500.709
2319.19	655.644
2322.77	232.586
2326.36	31.5842
2329.94	4.79864
2333.52	0.707596
2337.1	-0.550156
2340.68	11.3556
2344.26	4.44958
2347.83	-1.49336
2351.41	9.42103
2354.98	4.434
2358.55	-1.46169
2362.12	-1.74874
2365.69	7.25912
2369.25	4.23187
2372.82	6.76756
2376.38	3.76573
2379.94	7.24596
2383.5	7.05538
2387.06	5.05354
2390.61	11.345
2394.17	2.07561
2397.72	5.69001
2401.27	10.2798
2404.82	4.81071
2408.37	2.12951
2411.92	14.161
2415.47	7.86246
2419.01	10.7665
2422.55	12.7797
2426.09	12.9783
2429.63	8.57188
2433.17	10.6526
2436.71	3.45988
2440.24	11.1326
2443.78	7.63755
2447.31	8.8151
2450.84	8.13209
2454.37	7.38208
2457.89	10.3047
2461.42	16.0382
2464.94	9.43751
2468.47	5.70948
2471.99	22.617
2475.51	13.9914
2479.03	16.7026
2482.54	13.7201
2486.06	11.6218
2489.57	16.1362
2493.08	14.9659
2496.59	12.8734
2500.1	18.2437
2503.61	17.0308
2507.12	25.1172
2510.62	22.9332
2514.12	20.7705
2517.62	15.8388
2521.12	22.8859
2524.62	17.049
2528.12	29.7124
2531.61	24.8152
2535.11	15.3245
2538.6	20.6047
2542.09	27.7578
2545.58	15.5518
2549.07	25.4954
2552.55	30.8341
2556.04	33.4405
2559.52	23.0387
2563	28.4288
2566.48	31.0533
2569.96	23.4145
2573.44	30.7222
2576.91	24.9088
2580.39	29.413
2583.86	34.867
2587.33	35.5659
2590.8	32.3887
2594.27	33.9154
2597.74	24.9502
2601.2	22.6134
2604.67	32.6626
2608.13	33.0407
2611.59	29.4771
2615.05	33.6128
2618.51	25.1934
2621.96	32.106
2625.42	36.0832
2628.87	35.215
2632.32	40.0567
2635.77	41.9571
2639.22	33.2759
2642.67	37.956
2646.11	37.816
2649.56	40.4857
2653	29.7717
2656.44	32.3436
2659.88	45.2839
2663.32	35.4434
2666.76	38.8159
2670.19	40.2524
2673.63	34.16
2677.06	33.6938
2680.49	34.1516
2683.92	23.4081
2687.35	31.3576
2690.78	33.7128
2694.2	23.9032
2697.63	35.4977
2701.05	34.9621
2704.47	38.1069
2707.89	33.8538
2711.31	31.446
2714.72	29.0211
2718.14	29.3742
2721.55	24.1111
2724.96	35.6214
2728.37	26.5628
2731.78	22.1254
2735.19	17.6449
2738.6	27.1911
2742	24.4979
2745.41	28.3285
2748.81	21.7899
2752.21	24.6112
2755.61	29.27
2759	27.3128
2762.4	20.5793
2765.8	32.6406
2769.19	21.0901
2772.58	27.4005
2775.97	15.7566
2779.36	15.3684
2782.75	18.7011
2786.13	23.8706
2789.52	13.0138
2792.9	7.76398
2796.28	18.4471
2799.66	17.8009
2803.04	15.2446
2806.42	18.2725
2809.79	11.8918
2813.17	14.8291
2816.54	3.70691
2819.91	5.64894
2823.28	4.76814
2826.65	15.0453
2830.02	17.8371
2833.38	9.43567
2836.75	5.67945
2840.11	4.70638
2843.47	6.52242
2846.83	14.8782
2850.19	-1.01575
2853.55	-4.83952
2856.91	8.1484
2860.26	0.555382
2863.61	4.16917
2866.96	8.70455
2870.31	2.87984
2873.66	-2.04877
2877.01	-3.25304
2880.36	-7.31757
2883.7	-14.2577
2887.05	11.7983
2890.39	-6.53558
2893.73	-1.32491
2897.07	3.84325
2900.4	-3.33516
2903.74	-4.88716
2907.07	7.71385
2910.41	1.34819
2913.74	2.51552
2917.07	4.57365
2920.4	7.5381
2923.73	-5.61378
2927.05	1.97954
2930.38	6.68408
2933.7	2.82913
2937.02	2.72197
2940.34	12.0076
2943.66	21.2553
2946.98	2.24689
2950.3	-3.60762
2953.61	14.0078
2956.92	2.50317
2960.24	7.89774
2963.55	17.9617
2966.86	11.1791
2970.16	17.5584
2973.47	26.7306
2976.78	12.4827
2980.08	13.1941
2983.38	21.4118
2986.68	25.8788
2989.98	22.8258
2993.28	32.9238
2996.58	45.8512
2999.87	19.2795
3003.17	47.235
3006.46	55.4629
3009.75	64.6479
3013.04	60.6495
3016.33	57.5724
3019.62	78.0603
3022.91	70.2496
3026.19	83.205
3029.47	70.6512
3032.75	102.49
3036.03	99.3496
3039.31	119.857
3042.59	112.938
3045.87	121.166
3049.14	142.66
3052.42	144.281
3055.69	157.269
3058.96	166.327
3062.23	179.247
3065.49	189.271
3068.76	190.681
3072.03	214.328
3075.29	231.904
3078.55	238.819
3081.81	243.409
3085.07	276.441
3088.33	296.398
3091.59	313.674
3094.85	322.423
3098.1	340.209
3101.35	354.031
3104.61	388.211
3107.85	425.204
3111.1	411.495
3114.35	427.38
3117.6	453.781
3120.84	495.445
3124.09	504.734
3127.33	534.97
3130.57	559.53
3133.81	625.076
3137.05	611.472
3140.28	655.07
3143.52	695.829
3146.75	707.129
3149.99	762.352
3153.22	772.72
3156.45	829.899
3159.68	806.917
3162.9	867.942
3166.13	892.614
3169.35	922.936
3172.58	975.173
3175.8	960.511
3179.02	1021.21
3182.24	1061.93
3185.46	1106.29
3188.67	1122.96
3191.89	1165.38
3195.1	1187.76
3198.32	1194.87
3201.53	1277.29
3204.74	1239.82
3207.95	1281.46
3211.15	1316.57
3214.36	1346.12
3217.56	1380.46
3220.77	1375.88
3223.97	1420.99
3227.17	1456.67
3230.37	1466.87
3233.57	1454.09
3236.76	1505.57
3239.96	1519.14
3243.15	1522.4
3246.35	1546.66
3249.54	1533.05
3252.73	1569.14
3255.92	1593.84
3259.1	1566.74
3262.29	1619.6
3265.47	1641.66
3268.66	1661.63
3271.84	1689.15
3275.02	1691.87
3278.2	1695.14
3281.38	1688.47
3284.55	1720.08
3287.73	1692.35
3290.9	1742.11
3294.08	1791.78
3297.25	1791.9
3300.42	1847.93
3303.59	1825.29
3306.76	1864.33
3309.92	1855.46
3313.09	1899.66
3316.25	1920.08
3319.41	1923.35
3322.58	2015.71
3325.74	2010.51
3328.9	2079.16
3332.05	2083.7
3335.21	2090.39
3338.36	2133.19
3341.52	2213.74
3344.67	2230.82
3347.82	2245.87
3350.97	2311.79
3354.12	2348.89
3357.26	2356.96
3360.41	2394.68
3363.55	2421.22
3366.7	2485.73
3369.84	2559.88
3372.98	2583.54
3376.12	2623.47
3379.26	2659.91
3382.39	2671.66
3385.53	2752.84
3388.66	2832.3
3391.8	2911.91
3394.93	2977.17
3398.06	3011.51
3401.19	3113.63
3404.31	3294.26
3407.44	3608.67
3410.56	4266.48
3413.69	5926.59
3416.81	10322.3
3419.93	16872
3423.05	15776.2
3426.17	9205.13
3429.29	5477.46
3432.41	4148.79
3435.52	3637.45
3438.63	3349.34
3441.75	3279.89
3444.86	3161.04
3447.97	3078.53
3451.08	3079.43
3454.18	3043.21
3457.29	3017.01
3460.39	3077.37
3463.5	3014.02
3466.6	3043.39
3469.7	3080.44
3472.8	3166.99
3475.9	3167.53
3479	3269.49
3482.09	3519.81
3485.19	3745.56
3488.28	4159.5
3491.37	4917.16
3494.46	5844.2
3497.55	7146.53
3500.64	8376.87
3503.73	8887.43
3506.81	8220.33
3509.9	6768.93
3512.98	5359.95
3516.06	4310.54
3519.14	3611.45
3522.22	3124.69
3525.3	2767.11
3528.38	2474.49
3531.46	2313.39
3534.53	2158.46
3537.6	2003.71
3540.67	1920.19
3543.75	1851.09
3546.82	1723.38
3549.88	1658.33
3552.95	1598.67
3556.02	1545.02
3559.08	1482.89
3562.14	1415.56
3565.21	1364.03
3568.27	1293.18
3571.33	1252.77
3574.39	1249.44
3577.44	1186.25
3580.5	1146.68
3583.55	1090.87
3586.61	1083.46
3589.66	1007.63
3592.71	997.24
3595.76	916.634
3598.81	929.893
3601.85	886.224
3604.9	795.215
3607.95	822.534
3610.99	781.736
3614.03	744.743
3617.07	716.366
3620.11	690.931
3623.15	658.977
3626.19	618.67
3629.22	576.484
3632.26	537.118
3635.29	533.801
3638.33	493.93
3641.36	450.408
3644.39	423.138
3647.42	400.327
3650.44	359.865
3653.47	329.617
3656.5	284.081
3659.52	258.172
3662.54	218.934
3665.56	196.333
3668.58	161.594
3671.6	131.557
3674.62	126.052
3677.64	97.8951
3680.65	69.6738
3683.67	66.9461
3686.68	51.9172
3689.69	32.1363
3692.7	22.748
3695.71	9.47241
3698.72	1.92871
3701.73	-13.2353
3704.73	-1.83875
3707.74	-18.0441
3710.74	-30.499
3713.74	-35.4064
3716.75	-29.8504
3719.75	-52.8976
3722.74	-48.3853
3725.74	-35.3424
3728.74	-52.8084
3731.73	-49.3657
3734.73	-43.1151
3737.72	-44.5233
3740.71	-44.0755
3743.7	-50.3283
3746.69	-53.7677
3749.68	-56.2938
3752.66	-48.4018
3755.65	-54.7778
3758.63	-45.0592
3761.62	-52.4566
3764.6	-44.7204
3767.58	-43.6407
3770.56	-50.1476
3773.54	-52.8918
3776.51	-42.4325
3779.49	-33.9004
3782.46	-44.2997
3785.44	-46.2298
3788.41	-37.8121
3791.38	-44.5188
3794.35	-29.55
3797.32	-28.7801
3800.29	-30.8711
3803.25	-32.0622
3806.22	-44.6393
3809.18	-32.6973
3812.14	-36.8703
3815.11	-35.4227
3818.07	-26.4543
3821.03	-15.6377
3823.98	-28.541
3826.94	-19.7137
3829.9	-20.4226
3832.85	-17.3827
3835.8	-7.74341
3838.76	-10.5081
3841.71	-11.4381
3844.66	-2.90981
3847.61	-9.66869
3850.55	-12.6801
3853.5	-14.8037
3856.45	-12.2181
3859.39	-5.86635
3862.33	2.33691
3865.27	1.87158
3868.21	-12.0877
3871.15	8.38963
3874.09	0.995117
3877.03	-0.726479
3879.96	2.2765
3882.9	3.28033
3885.83	4.21144
3888.77	6.03648
3891.7	2.98585
3894.63	9.4735
3897.56	3.38171
3900.48	8.76681
3903.41	5.41828
3906.34	7.79617
3909.26	8.17945
3912.18	6.57075
3915.1	15.4575
3918.02	3.18652
3920.94	10.0379
3923.86	-0.455559
3926.78	12.0083
3929.7	8.10517
3932.61	2.26962
3935.52	15.5629
3938.44	3.93565
3941.35	0.865433
3944.26	9.24417
3947.17	9.93172
3950.08	5.79829
3952.98	13.1194
3955.89	-3.53207
3958.79	-10.6422
3961.7	-2.45015
3964.6	7.63956
3967.5	-0.51474
3970.4	0.897629
3973.3	2.28242
3976.2	5.55801
3979.09	-4.64893
3981.99	-11.0372
3984.88	-3.98918
3987.78	-2.72327
3990.67	-13.0288
3993.56	-5.03941
3996.45	-9.56382
3999.34	-3.49323