File: Data/3-Raman/processed/bu19w-e-ff11-fi05-v_150 (500nm)_633nm_edge_100%_x100_vis_h50um_60sx2_01_0.txt
#Acq. time (s)=	60
#Accumulations=	2
#Range (cm-¹)=	100...4000
#Windows=	1
#Auto scanning=	Off
#Autofocus=	Off
#Macrospot=	Off
#AutoExposure=	Off
#Spike filter=	Multiple accum.
#Delay time (s)=	2
#Binning=	1
#Readout mode=	Signal
#DeNoise=	Off
#ICS correction=	On
#Dark correction=	Off
#Inst. Process=	Off
#Detector Gain=	Best Dynamic
#Detector ADC=	50 kHz HS
#Detector temperature (°C)=	-60.09
#Instrument=	LabRAM HR Evol
#Detector=	SIN-EM FIVIS
#Objective=	x100_VIS
#Grating=	150 (500nm)
#ND Filter=	100%
#Laser=	633nm_Edge
#Hole=	49.98
#Temperature=	0
#Range=	Visible
#StageXY=	75x50mm Scan+
#StageZ=	Z motor
#X (µm)=	0
#Y (µm)=	0
#Z (µm)=	-290.2
#Full time(mm:ss)=	2:04
#Project=	21_11_04
#Sample=	BU19w
#Site=
#Title=	BU19w-E-FF11-FI05-V_150 (500nm)_633nm_Edge_100%_x100_VIS_H50um_60sX2
#Remark=
#Date=	04.11.2021 16:47
#Acquired=	04.11.2021 16:47:03
#Base:Fit=	16.12.2021 17:39:50
#Base:Fit=	16.12.2021 17:49:45
#Base:Edit=	16.12.2021 17:49:47
#Base:Edit=	16.12.2021 17:49:47
#Base:Edit=	16.12.2021 17:49:49
#Base:Edit=	16.12.2021 17:49:49
#Base:Edit=	16.12.2021 17:49:51
#Base:Edit=	16.12.2021 17:49:52
#Peaks:Remove=	16.12.2021 17:49:54
#Peaks:Remove=	16.12.2021 17:49:56
#Peaks:Remove=	16.12.2021 17:49:58
#Base:Edit=	16.12.2021 17:49:59
#Base:Edit=	16.12.2021 17:50:00
#Base:Edit=	16.12.2021 17:50:01
#Base:Edit=	16.12.2021 17:50:02
#Base:Edit=	16.12.2021 17:50:03
#Base:Edit=	16.12.2021 17:50:04
#Base:Edit=	16.12.2021 17:50:05
#Base:Edit=	16.12.2021 17:50:07
#Base:Edit=	16.12.2021 17:50:08
#Base:Edit=	16.12.2021 17:50:09
#Base:Edit=	16.12.2021 17:50:09
#Base:Edit=	16.12.2021 17:50:10
#Base:Edit=	16.12.2021 17:50:10
#Base:Edit=	16.12.2021 17:50:11
#Base:Edit=	16.12.2021 17:50:11
#Base:Edit=	16.12.2021 17:50:12
#Base:Edit=	16.12.2021 17:50:13
#Base:Edit=	16.12.2021 17:50:14
#Base:Edit=	16.12.2021 17:50:15
#Base:Edit=	16.12.2021 17:50:15
#Base:Edit=	16.12.2021 17:50:15
#Base:Edit=	16.12.2021 17:50:16
#Base:Sub=	16.12.2021 17:50:17
102.881	49.5424
109.397	37.9475
115.908	17.7616
122.414	26.1908
128.914	21.244
135.409	21.038
141.898	17.9113
148.383	17.7018
154.861	26.1597
161.335	46.1553
167.801	8.65334
174.264	4.6127
180.721	7.18446
187.173	4.84718
193.62	5.30486
200.061	-3.71533
206.496	5.57207
212.926	-1.4127
219.352	18.3057
225.772	65.572
232.185	100.201
238.595	52.1446
244.999	40.346
251.397	30.4661
257.791	30.0469
264.178	44.8349
270.561	51.1047
276.939	85.8483
283.31	80.6904
289.678	34.7056
296.039	11.4363
302.396	41.1672
308.746	50.0157
315.093	111.734
321.433	153.592
327.768	103.042
334.099	51.5924
340.423	48.2266
346.743	58.016
353.058	61.1469
359.367	49.1295
365.671	51.1975
371.971	26.009
378.265	21.4897
384.553	13.2626
390.837	22.1206
397.116	13.2842
403.389	5.47914
409.657	12.6906
415.92	21.7063
422.178	36.3595
428.431	51.5587
434.678	46.6236
440.921	59.5499
447.158	38.5675
453.391	64.4254
459.618	36.1234
465.84	15.5618
472.057	17.4717
478.27	12.9903
484.477	25.2657
490.679	19.8315
496.876	44.2287
503.068	36.0289
509.255	36.2314
515.436	28.0715
521.613	20.925
527.785	33.5092
533.952	34.0473
540.113	28.9216
546.27	15.1405
552.423	14.3773
558.568	14.4759
564.711	16.2003
570.848	5.53403
576.979	25.744
583.107	13.1205
589.228	31.4508
595.345	43.3834
601.458	49.9776
607.565	52.1578
613.667	52.5783
619.764	34.4025
625.856	30.3131
631.944	14.6344
638.026	11.8436
644.104	20.1084
650.177	34.912
656.244	22.2901
662.308	15.311
668.365	18.6653
674.418	15.789
680.467	-0.0477448
686.511	-5.5101
692.549	9.7397
698.582	-6.77132
704.611	-1.78145
710.635	-10.0347
716.655	-2.58704
722.669	-0.763596
728.679	0.941513
734.683	-5.84079
740.683	-6.9879
746.678	-3.42384
752.669	6.74489
758.654	12.367
764.635	-4.10564
770.611	-1.79776
776.582	11.7929
782.549	19.6746
788.511	3.90863
794.466	8.78261
800.419	2.21764
806.366	10.6236
812.309	2.00987
818.247	1.77838
824.18	7.12663
830.108	6.87196
836.033	5.98294
841.952	10.0264
847.865	2.88383
853.776	9.88086
859.681	16.024
865.58	16.5538
871.476	14.2084
877.366	5.98387
883.253	13.7883
889.134	10.1017
895.012	13.9206
900.883	22.2865
906.751	4.06918
912.614	19.823
918.473	12.1013
924.326	19.6427
930.174	23.6555
936.019	25.9603
941.859	33.291
947.693	58.7617
953.525	55.8704
959.35	63.3404
965.171	62.0668
970.988	115.347
976.801	129.098
982.608	168.317
988.411	122.036
994.209	96.8775
1000	88.0813
1005.79	76.5751
1011.58	97.7647
1017.36	100.069
1023.13	81.4635
1028.9	63.0003
1034.67	52.193
1040.43	48.138
1046.19	45.9948
1051.94	47.5853
1057.69	46.148
1063.44	34.8159
1069.17	37.8504
1074.91	36.9937
1080.64	45.7569
1086.37	79.6862
1092.09	91.3686
1097.8	97.2162
1103.52	52.7885
1109.22	45.3273
1114.93	53.6609
1120.63	36.9273
1126.32	41.393
1132.01	70.3724
1137.7	68.1214
1143.38	85.4869
1149.06	84.0303
1154.73	60.7415
1160.4	34.2509
1166.06	31.1709
1171.72	18.2987
1177.38	17.1872
1183.03	14.1972
1188.67	27.0293
1194.31	9.71791
1199.95	3.27965
1205.58	7.80672
1211.21	11.4519
1216.84	9.26201
1222.46	-0.847153
1228.07	-2.061
1233.68	-3.36683
1239.29	10.3128
1244.89	8.74469
1250.49	8.01974
1256.08	0.113052
1261.67	9.20403
1267.26	5.13281
1272.84	48.2906
1278.42	10.9015
1283.99	7.74466
1289.56	0.673538
1295.12	-8.29151
1300.68	-1.18061
1306.23	12.0727
1311.78	-2.50852
1317.33	-5.00767
1322.87	4.63222
1328.41	-1.81926
1333.94	-1.22334
1339.47	6.45285
1345	4.82722
1350.52	8.2556
1356.04	17.7951
1361.55	6.70331
1367.06	2.68514
1372.56	17.1038
1378.06	85.9388
1383.56	13.0338
1389.05	2.7776
1394.53	0.812698
1400.02	11.3447
1405.5	2.34135
1410.97	7.78222
1416.44	-0.143051
1421.91	1.23289
1427.37	-2.55221
1432.83	3.01468
1438.28	1.28888
1443.73	16.2843
1449.17	-8.55304
1454.62	-2.09772
1460.05	-2.0253
1465.48	-2.0223
1470.91	2.14975
1476.34	-2.04963
1481.76	17.954
1487.17	9.65179
1492.59	0.347298
1497.99	0.560265
1503.4	-5.52409
1508.8	-2.06328
1514.19	14.2003
1519.59	-1.35027
1524.97	8.67362
1530.36	12.3286
1535.74	-6.57628
1541.11	8.83424
1546.48	-0.734962
1551.85	4.62824
1557.21	6.56818
1562.57	11.7701
1567.93	19.1101
1573.28	13.5038
1578.62	20.9004
1583.97	1.4622
1589.3	5.74366
1594.64	9.00926
1599.97	8.02614
1605.3	10.3496
1610.62	3.0271
1615.94	0.116714
1621.25	8.15374
1626.56	15.1423
1631.87	4.55653
1637.17	4.82883
1642.47	4.88258
1647.76	2.75357
1653.05	11.6439
1658.34	-3.91404
1663.62	9.30246
1668.9	2.528
1674.18	13.4854
1679.45	14.4309
1684.71	14.1871
1689.98	3.95859
1695.23	18.1738
1700.49	-2.85218
1705.74	17.6766
1710.99	-2.35585
1716.23	8.69293
1721.47	1.09409
1726.7	5.6237
1731.94	4.61833
1737.16	4.71599
1742.39	5.93063
1747.61	3.73978
1752.82	4.86778
1758.03	11.5966
1763.24	9.19745
1768.44	-5.6453
1773.64	6.71785
1778.84	16.8898
1784.03	-0.116867
1789.22	6.78545
1794.41	6.90477
1799.59	5.92065
1804.76	12.9919
1809.94	7.39204
1815.11	14.408
1820.27	0.663269
1825.43	13.4962
1830.59	3.19386
1835.74	9.14752
1840.89	3.40207
1846.04	3.43445
1851.18	1.10768
1856.32	11.6071
1861.45	3.44536
1866.58	-2.36157
1871.71	7.08139
1876.83	2.33749
1881.95	9.36911
1887.07	8.10786
1892.18	0.82576
1897.29	7.71692
1902.39	4.09351
1907.49	5.32886
1912.59	-1.62991
1917.68	12.9046
1922.77	8.06947
1927.86	5.73596
1932.94	-5.00795
1938.02	0.991577
1943.09	-5.0649
1948.16	10.4957
1953.23	9.15141
1958.29	-4.28337
1963.35	-2.08028
1968.41	8.5164
1973.46	5.79506
1978.51	-4.14601
1983.55	2.76376
1988.59	-4.74724
1993.63	-3.81953
1998.66	6.75514
2003.69	0.540573
2008.72	1.59245
2013.74	-6.94881
2018.76	-1.06406
2023.77	6.05472
2028.78	6.01997
2033.79	-2.40955
2038.79	0.0541229
2043.79	3.75894
2048.79	18.4583
2053.78	-0.991592
2058.77	5.18347
2063.76	12.6354
2068.74	10.3027
2073.72	9.17368
2078.69	3.09148
2083.66	-12.9229
2088.63	9.27641
2093.59	1.89545
2098.55	10.695
2103.51	-5.31972
2108.46	-1.42236
2113.41	11.2972
2118.36	4.03589
2123.3	4.27158
2128.24	4.48515
2133.17	0.863678
2138.11	-10.4282
2143.03	6.18196
2147.96	3.70215
2152.88	3.69507
2157.79	-5.2991
2162.71	-0.300278
2167.62	-9.41905
2172.52	-9.5576
2177.43	3.12476
2182.32	5.49088
2187.22	2.69455
2192.11	7.65666
2197	-0.131546
2201.89	-0.151184
2206.77	3.74692
2211.64	3.85606
2216.52	-5.03247
2221.39	-12.6354
2226.26	-3.40785
2231.12	9.76935
2235.98	-12.1967
2240.84	-4.20859
2245.69	1.20924
2250.54	1.39552
2255.39	-5.01721
2260.23	-8.79773
2265.07	11.1802
2269.9	3.31828
2274.74	8.64828
2279.57	-7.3299
2284.39	-3.4585
2289.21	-0.958069
2294.03	2.86949
2298.84	-3.90024
2303.66	13.3771
2308.46	9.44801
2313.27	0.229324
2318.07	16.5101
2322.87	-10.1426
2327.66	-0.507446
2332.45	-9.71585
2337.24	2.74988
2342.02	0.354019
2346.8	7.55904
2351.58	-3.02066
2356.35	-10.9904
2361.12	-5.34016
2365.89	8.6002
2370.65	14.2988
2375.41	3.36475
2380.17	-6.25746
2384.92	-10.4374
2389.67	-0.768707
2394.42	-2.29276
2399.16	-8.04971
2403.9	9.84103
2408.64	1.31685
2413.37	-2.77193
2418.1	7.59872
2422.83	-4.69652
2427.55	-3.22255
2432.27	-1.58824
2436.99	5.77881
2441.7	-9.52583
2446.41	3.55721
2451.11	1.01323
2455.82	-1.56702
2460.51	0.151398
2465.21	-5.33185
2469.9	12.2396
2474.59	-6.33302
2479.28	-1.74719
2483.96	1.37056
2488.64	4.4471
2493.32	-10.0168
2497.99	1.83803
2502.66	15.1736
2507.32	9.41206
2511.99	-2.29961
2516.65	9.51024
2521.3	-5.16815
2525.96	14.1151
2530.61	5.31761
2535.25	-12.3633
2539.89	-4.81279
2544.53	5.76004
2549.17	-0.0145721
2553.8	1.65898
2558.43	7.7755
2563.06	16.976
2567.68	8.20857
2572.3	25.0905
2576.92	14.7829
2581.53	16.4862
2586.14	21.1104
2590.75	-9.32318
2595.35	2.84871
2599.96	-1.63972
2604.55	-4.66772
2609.15	1.44218
2613.74	5.96973
2618.33	5.93225
2622.91	-18.6095
2627.49	5.90514
2632.07	7.57288
2636.64	0.130875
2641.22	11.2884
2645.78	0.838974
2650.35	-3.49103
2654.91	-1.67363
2659.47	12.489
2664.03	-4.64421
2668.58	7.92635
2673.13	11.2454
2677.67	0.689133
2682.22	-1.81944
2686.76	-2.83488
2691.29	-23.0886
2695.83	9.12602
2700.36	12.5205
2704.89	4.65739
2709.41	-8.10022
2713.93	14.5852
2718.45	9.94724
2722.96	-10.9698
2727.47	6.90047
2731.98	-6.12077
2736.49	0.319656
2740.99	8.40041
2745.49	14.9523
2749.98	8.56178
2754.47	7.27052
2758.96	-4.05988
2763.45	-7.28514
2767.93	-2.21045
2772.41	14.3956
2776.89	1.44563
2781.36	-13.1313
2785.84	-7.79543
2790.3	0.898849
2794.77	6.26552
2799.23	9.90619
2803.69	10.139
2808.14	-3.1703
2812.59	5.38927
2817.04	2.07437
2821.49	-4.62282
2825.93	5.64865
2830.37	7.43587
2834.81	12.6028
2839.24	-0.961472
2843.67	0.806992
2848.1	6.05507
2852.53	-14.3198
2856.95	8.21913
2861.37	1.6098
2865.78	3.68187
2870.19	-1.14568
2874.6	4.41577
2879.01	8.29556
2883.41	15.7485
2887.81	-4.82347
2892.21	-11.4812
2896.6	-5.78697
2901	-10.6626
2905.38	7.47415
2909.77	-11.8099
2914.15	2.69884
2918.53	1.1265
2922.91	-0.414108
2927.28	-7.31506
2931.65	-1.56793
2936.02	0.499191
2940.38	9.74173
2944.74	-4.66199
2949.1	13.6136
2953.46	-8.19261
2957.81	-4.48557
2962.16	8.39886
2966.5	8.52292
2970.85	-7.84856
2975.19	-13.2271
2979.52	3.49695
2983.86	9.2652
2988.19	-12.6573
2992.52	11.7842
2996.85	-19.5051
3001.17	1.38985
3005.49	5.58852
3009.8	11.6865
3014.12	4.57335
3018.43	1.28711
3022.74	3.67033
3027.04	-13.1056
3031.34	25.3789
3035.64	0.747299
3039.94	4.77916
3044.23	-0.784225
3048.52	18.6298
3052.81	1.44626
3057.09	9.35835
3061.38	1.79594
3065.65	17.4828
3069.93	2.13611
3074.2	23.7262
3078.47	25.9138
3082.74	8.57059
3087	4.94443
3091.27	22.9911
3095.52	5.78061
3099.78	26.0255
3104.03	18.6926
3108.28	1.41252
3112.53	10.0176
3116.77	14.6656
3121.01	23.4116
3125.25	16.1055
3129.49	12.8577
3133.72	7.59479
3137.95	16.6181
3142.18	9.16161
3146.4	32.612
3150.62	45.7899
3154.84	23.4762
3159.06	40.7059
3163.27	37.089
3167.48	24.9811
3171.69	14.9242
3175.89	38.5358
3180.09	38.8214
3184.29	43.2743
3188.49	41.2923
3192.68	28.7987
3196.87	33.3959
3201.06	27.6236
3205.24	15.459
3209.42	29.1121
3213.6	29.941
3217.78	37.3311
3221.95	49.0628
3226.12	43.397
3230.29	26.6777
3234.45	29.6321
3238.61	6.03387
3242.77	20.1026
3246.93	7.55521
3251.08	19.367
3255.23	22.1069
3259.38	31.641
3263.53	18.8166
3267.67	15.3147
3271.81	20.6785
3275.95	23.4794
3280.08	1.0009
3284.21	17.4214
3288.34	22.4088
3292.47	4.36351
3296.59	18.5246
3300.71	9.69255
3304.83	7.75633
3308.95	24.3759
3313.06	24.7409
3317.17	34.4525
3321.27	25.5923
3325.38	21.453
3329.48	19.6855
3333.58	15.7382
3337.67	14.1254
3341.77	12.3054
3345.86	-1.49109
3349.95	27.3798
3354.03	11.1192
3358.11	23.537
3362.19	24.0629
3366.27	22.1614
3370.34	37.0752
3374.42	13.4755
3378.48	30.6994
3382.55	31.0545
3386.61	26.5567
3390.68	19.5996
3394.73	17.4846
3398.79	25.1379
3402.84	40.0293
3406.89	8.72273
3410.94	30.8605
3414.98	18.939
3419.03	48.4288
3423.06	60.8693
3427.1	63.6093
3431.14	27.3499
3435.17	15.5218
3439.2	8.62105
3443.22	26.2852
3447.25	26.9144
3451.27	17.6968
3455.28	6.03615
3459.3	9.30011
3463.31	22.5796
3467.32	30.9562
3471.33	9.24121
3475.34	7.38068
3479.34	28.2977
3483.34	18.953
3487.33	19.6809
3491.33	25.4816
3495.32	26.1626
3499.31	11.4402
3503.3	50.3766
3507.28	17.5426
3511.26	17.867
3515.24	28.4325
3519.22	10.7238
3523.19	16.1438
3527.16	8.74501
3531.13	16.7792
3535.1	19.8834
3539.06	15.3693
3543.02	15.9531
3546.98	19.0655
3550.93	14.308
3554.89	6.76656
3558.84	4.55257
3562.78	7.6082
3566.73	18.5807
3570.67	11.3757
3574.61	19.8598
3578.55	12.6923
3582.48	24.0127
3586.41	16.9057
3590.35	25.657
3594.27	7.85263
3598.2	13.9442
3602.12	1.28587
3606.04	1.94435
3609.95	7.923
3613.87	19.3102
3617.78	9.12503
3621.69	-1.18373
3625.6	7.27431
3629.5	7.6093
3633.4	26.8366
3637.3	-5.27376
3641.2	11.4832
3645.09	-4.21631
3648.98	18.0394
3652.87	-6.0359
3656.76	2.53516
3660.64	13.8388
3664.53	6.0247
3668.4	25.5897
3672.28	9.60303
3676.16	-0.843033
3680.03	7.97537
3683.9	-21.6164
3687.76	-4.38037
3691.63	15.7311
3695.49	-2.96457
3699.35	6.09714
3703.2	1.23428
3707.06	13.1641
3710.91	-16.922
3714.76	11.858
3718.6	1.24271
3722.45	1.84099
3726.29	16.5432
3730.13	-5.54881
3733.97	-2.1373
3737.8	-1.56709
3741.63	-9.57776
3745.46	2.34416
3749.29	5.68642
3753.11	17.5631
3756.93	-7.81647
3760.75	15.4319
3764.57	-1.43663
3768.39	1.76865
3772.2	16.5087
3776.01	-3.19162
3779.81	2.98955
3783.62	0.610107
3787.42	1.11775
3791.22	10.2584
3795.02	5.02527
3798.81	-0.177612
3802.61	3.3297
3806.4	-4.76541
3810.18	-7.06393
3813.97	-6.48701
3817.75	14.5897
3821.53	-17.1118
3825.31	-1.92363
3829.09	-4.35107
3832.86	13.9076
3836.63	-3.26295
3840.4	3.1601
3844.17	21.5296
3847.93	4.11282
3851.69	-1.47116
3855.45	10.7318
3859.21	-3.88235
3862.96	-6.56419
3866.71	-12.0085
3870.46	3.52327
3874.21	6.83788
3877.95	7.18274
3881.69	-1.43915
3885.44	4.92134
3889.17	-3.65996
3892.91	20.7883
3896.64	-8.69035
3900.37	-2.18759
3904.1	-7.73886
3907.82	1.77821
3911.55	-6.78773
3915.27	-15.3576
3918.99	-8.7309
3922.7	-2.01891
3926.42	4.69458
3930.13	-3.87799
3933.84	5.81857
3937.54	9.3739
3941.25	3.78377
3944.95	7.45517
3948.65	1.85895
3952.35	14.713
3956.04	-12.623
3959.73	-6.02841
3963.42	-2.54829
3967.11	-8.39987
3970.8	-17.3966
3974.48	4.62933
3978.16	4.94742
3981.84	8.31706
3985.52	-10.0195
3989.19	2.66188
3992.86	3.0054
3996.53	-9.0036
3998.37	-5.67662