File: Data/3-Raman/processed/bu19w-e-ff11-fi10-s1_150 (500nm)_633nm_edge_100%_x100_vis_h50um_60sx2_01_0.txt
#Acq. time (s)=	60
#Accumulations=	2
#Range (cm-¹)=	100...4000
#Windows=	1
#Auto scanning=	Off
#Autofocus=	Off
#Macrospot=	Off
#AutoExposure=	Off
#Spike filter=	Multiple accum.
#Delay time (s)=	2
#Binning=	1
#Readout mode=	Signal
#DeNoise=	Off
#ICS correction=	On
#Dark correction=	Off
#Inst. Process=	Off
#Detector Gain=	Best Dynamic
#Detector ADC=	50 kHz HS
#Detector temperature (°C)=	-60.28
#Instrument=	LabRAM HR Evol
#Detector=	SIN-EM FIVIS
#Objective=	x100_VIS
#Grating=	150 (500nm)
#ND Filter=	100%
#Laser=	633nm_Edge
#Hole=	49.98
#Temperature=	0
#Range=	Visible
#StageXY=	75x50mm Scan+
#StageZ=	Z motor
#X (µm)=	0
#Y (µm)=	0
#Z (µm)=	-267.6
#Full time(mm:ss)=	2:04
#Project=	21_11_04
#Sample=	BU19w
#Site=
#Title=	BU19w-E-FF11-FI10-S1_150 (500nm)_633nm_Edge_100%_x100_VIS_H50um_60sX2
#Remark=
#Date=	04.11.2021 11:57
#Acquired=	04.11.2021 11:57:47
#Base:Fit=	16.12.2021 17:39:50
#Base:Edit=	16.12.2021 17:54:08
#Base:Edit=	16.12.2021 17:54:09
#Base:Edit=	16.12.2021 17:54:09
#Base:Edit=	16.12.2021 17:54:10
#Base:Edit=	16.12.2021 17:54:10
#Base:Edit=	16.12.2021 17:54:11
#Base:Edit=	16.12.2021 17:54:11
#Base:Edit=	16.12.2021 17:54:12
#Base:Edit=	16.12.2021 17:54:12
#Base:Edit=	16.12.2021 17:54:13
#Base:Edit=	16.12.2021 17:54:19
#Base:Sub=	16.12.2021 17:54:21
102.881	-1.05188
109.397	2.59473
115.908	-16.0896
122.414	30.4968
128.914	169.497
135.409	268.714
141.898	369.124
148.383	402.529
154.861	417.787
161.335	506.743
167.801	593.534
174.264	430.217
180.721	362.675
187.173	306.525
193.62	174.247
200.061	79.8459
206.496	6.51898
212.926	6.23364
219.352	22.0101
225.772	85.8925
232.185	139.242
238.595	183.244
244.999	149.602
251.397	71.3152
257.791	40.2779
264.178	-5.83447
270.561	-18.684
276.939	25.3984
283.31	88.0951
289.678	156.028
296.039	220.602
302.396	277.395
308.746	345.197
315.093	465.791
321.433	746.846
327.768	985.595
334.099	894.269
340.423	653.775
346.743	573.382
353.058	523.814
359.367	493.581
365.671	441.529
371.971	334.119
378.265	292.47
384.553	205.197
390.837	159.495
397.116	106.003
403.389	204.571
409.657	115.505
415.92	110.561
422.178	127.036
428.431	135.93
434.678	179.407
440.921	171.718
447.158	116.885
453.391	88.3276
459.618	120.084
465.84	116.213
472.057	96.9064
478.27	107.136
484.477	156.433
490.679	267.2
496.876	392.966
503.068	573.953
509.255	642.325
515.436	544.894
521.613	444.192
527.785	370.862
533.952	307.19
540.113	282.615
546.27	268.446
552.423	274.984
558.568	201.716
564.711	156.355
570.848	40.7626
576.979	61.1864
583.107	64.7227
589.228	130.251
595.345	162.808
601.458	202.012
607.565	169.468
613.667	189.554
619.764	182.209
625.856	181.721
631.944	148.922
638.026	174.085
644.104	163.102
650.177	162.383
656.244	170.322
662.308	141.559
668.365	111.208
674.418	43.0681
680.467	25.65
686.511	18.9485
692.549	45.5682
698.582	70.5422
704.611	85.0972
710.635	83.2316
716.655	81.8901
722.669	50.5462
728.679	13.1086
734.683	-14.1633
740.683	8.17474
746.678	1.64063
752.669	4.74365
758.654	15.7145
764.635	14.6998
770.611	23.4789
776.582	35.992
782.549	22.6324
788.511	26.7089
794.466	21.9608
800.419	43.1169
806.366	42.1097
812.309	31.4174
818.247	27.8669
824.18	57.86
830.108	34.5231
836.033	50.6003
841.952	44.2202
847.865	39.8203
853.776	32.8199
859.681	51.3552
865.58	10.5037
871.476	30.8202
877.366	19.2679
883.253	29.1776
889.134	28.2478
895.012	34.5834
900.883	4.30084
906.751	4.96024
912.614	5.49292
918.473	25.0827
924.326	17.1133
930.174	26.739
936.019	28.3819
941.859	32.7559
947.693	85.6804
953.525	91.3835
959.35	120.609
965.171	141.818
970.988	165.581
976.801	190.553
982.608	307.494
988.411	395.9
994.209	417.828
1000	380.691
1005.79	383.18
1011.58	368.565
1017.36	345.936
1023.13	375.217
1028.9	414.967
1034.67	525.304
1040.43	641.436
1046.19	679.985
1051.94	585.16
1057.69	508.646
1063.44	466.944
1069.17	421.249
1074.91	403.694
1080.64	375.081
1086.37	406.527
1092.09	432.409
1097.8	505.619
1103.52	529.537
1109.22	470.202
1114.93	476.19
1120.63	481.154
1126.32	464.777
1132.01	465.189
1137.7	446.917
1143.38	463.821
1149.06	455.393
1154.73	480.725
1160.4	402.57
1166.06	299.905
1171.72	275.077
1177.38	247.268
1183.03	222.804
1188.67	200.195
1194.31	214.296
1199.95	204.606
1205.58	165.316
1211.21	130.98
1216.84	94.6714
1222.46	48.2912
1228.07	7.45135
1233.68	28.2039
1239.29	-9.67047
1244.89	-3.87494
1250.49	8.54156
1256.08	-1.57748
1261.67	11.0168
1267.26	-7.77173
1272.84	-2.54395
1278.42	-7.52829
1283.99	-3.42834
1289.56	-8.12082
1295.12	3.46213
1300.68	4.30984
1306.23	-2.4165
1311.78	-5.60477
1317.33	-4.4968
1322.87	5.84103
1328.41	12.3629
1333.94	5.63818
1339.47	10.9018
1345	-6.7168
1350.52	14.3672
1356.04	6.59906
1361.55	23.2132
1367.06	30.2657
1372.56	18.6543
1378.06	17.3218
1383.56	35.4544
1389.05	33.0413
1394.53	27.8132
1400.02	26.2056
1405.5	25.5989
1410.97	24.0904
1416.44	38.2184
1421.91	18.2946
1427.37	28.4669
1432.83	11.6434
1438.28	30.1788
1443.73	22.6304
1449.17	29.5624
1454.62	21.4427
1460.05	20.3806
1465.48	44.3136
1470.91	12.5211
1476.34	29.1154
1481.76	29.0984
1487.17	34.4661
1492.59	16.904
1497.99	33.2068
1503.4	14.8501
1508.8	41.0269
1514.19	30.3174
1519.59	9.02914
1524.97	35.7747
1530.36	39.1051
1535.74	32.8522
1541.11	35.906
1546.48	42.8112
1551.85	18.838
1557.21	38.6975
1562.57	30.5531
1567.93	24.5746
1573.28	34.7557
1578.62	39.7639
1583.97	22.3894
1589.3	21.2758
1594.64	19.2497
1599.97	15.2346
1605.3	10.3076
1610.62	34.8992
1615.94	21.8712
1621.25	31.82
1626.56	2.34125
1631.87	17.7047
1637.17	26.2591
1642.47	34.2475
1647.76	11.3639
1653.05	38.1364
1658.34	33.7214
1663.62	32.5085
1668.9	10.1416
1674.18	32.1101
1679.45	18.5209
1684.71	22.4845
1689.98	19.7567
1695.23	21.6799
1700.49	5.26999
1705.74	35.6756
1710.99	8.05722
1716.23	9.07419
1721.47	23.2251
1726.7	6.73694
1731.94	21.7909
1737.16	-1.40173
1742.39	14.7509
1747.61	19.615
1752.82	15.2768
1758.03	7.38318
1763.24	20.8183
1768.44	10.5245
1773.64	-2.00107
1778.84	9.41284
1784.03	14.1926
1789.22	0.90332
1794.41	0.19046
1799.59	14.4355
1804.76	-7.8988
1809.94	4.03497
1815.11	20.5444
1820.27	7.08969
1825.43	6.33096
1830.59	-3.68924
1835.74	20.0158
1840.89	15.688
1846.04	-2.76633
1851.18	-7.29535
1856.32	-1.41037
1861.45	-4.73529
1866.58	2.57776
1871.71	-0.77771
1876.83	-5.46222
1881.95	5.1431
1887.07	-7.94427
1892.18	0.0118103
1897.29	2.02768
1902.39	-0.423248
1907.49	10.4214
1912.59	-6.96594
1917.68	6.67709
1922.77	19.7294
1927.86	7.94485
1932.94	8.08167
1938.02	-7.47913
1943.09	12.8919
1948.16	1.91177
1953.23	4.03232
1958.29	6.07376
1963.35	23.7278
1968.41	3.92352
1973.46	-0.334106
1978.51	11.0593
1983.55	14.0061
1988.59	-2.25958
1993.63	9.16971
1998.66	-5.79193
2003.69	10.579
2008.72	3.00485
2013.74	5.11844
2018.76	15.6216
2023.77	15.3209
2028.78	11.5388
2033.79	6.6665
2038.79	16.3435
2043.79	26.0829
2048.79	11.5644
2053.78	10.2633
2058.77	13.9208
2063.76	24.9792
2068.74	22.5755
2073.72	13.9707
2078.69	23.766
2083.66	21.1746
2088.63	22.1541
2093.59	31.9225
2098.55	26.9833
2103.51	25.7905
2108.46	19.6628
2113.41	32.338
2118.36	36.3349
2123.3	28.9896
2128.24	15.2291
2133.17	25.3587
2138.11	20.2229
2143.03	26.4524
2147.96	32.6045
2152.88	37.3521
2157.79	31.7914
2162.71	49.1148
2167.62	34.3608
2172.52	24.7746
2177.43	29.29
2182.32	24.6773
2187.22	40.4607
2192.11	30.7791
2197	28.8755
2201.89	36.105
2206.77	46.0381
2211.64	27.7822
2216.52	39.1962
2221.39	27.429
2226.26	33.7592
2231.12	24.5013
2235.98	34.7457
2240.84	35.8712
2245.69	25.2156
2250.54	46.0253
2255.39	41.8735
2260.23	28.4917
2265.07	34.7924
2269.9	34.349
2274.74	29.7974
2279.57	39.7588
2284.39	17.6551
2289.21	19.3956
2294.03	18.4601
2298.84	38.909
2303.66	22.1932
2308.46	20.2851
2313.27	35.8767
2318.07	20.8003
2322.87	24.4701
2327.66	13.3785
2332.45	33.3584
2337.24	39.9488
2342.02	12.6033
2346.8	30.2179
2351.58	23.2449
2356.35	20.2168
2361.12	23.8448
2365.89	6.74277
2370.65	13.0757
2375.41	33.2558
2380.17	28.448
2384.92	20.6749
2389.67	21.1257
2394.42	3.36052
2399.16	13.3311
2403.9	10.7491
2408.64	10.9926
2413.37	25.6025
2418.1	18.7089
2422.83	23.9884
2427.55	6.33185
2432.27	24.1266
2436.99	23.7144
2441.7	14.7773
2446.41	12.8952
2451.11	5.29247
2455.82	1.90359
2460.51	14.2983
2465.21	16.6613
2469.9	10.3121
2474.59	3.88664
2479.28	17.784
2483.96	24.4099
2488.64	7.62978
2493.32	24.3785
2497.99	19.2394
2502.66	8.15105
2507.32	14.6122
2511.99	18.0815
2516.65	24.4538
2521.3	26.4924
2525.96	9.31067
2530.61	18.7232
2535.25	11.917
2539.89	9.58815
2544.53	29.6094
2549.17	24.3799
2553.8	22.1049
2558.43	9.23018
2563.06	20.4147
2567.68	12.1572
2572.3	18.9919
2576.92	16.7337
2581.53	-11.4282
2586.14	16.3521
2590.75	18.2047
2595.35	27.7597
2599.96	25.2594
2604.55	1.29935
2609.15	13.9166
2613.74	17.285
2618.33	-19.1045
2622.91	-6.53864
2627.49	19.9068
2632.07	15.8888
2636.64	21.2716
2641.22	28.3839
2645.78	15.4216
2650.35	25.6475
2654.91	7.76462
2659.47	17.6823
2664.03	15.0352
2668.58	10.8017
2673.13	17.7101
2677.67	4.57584
2682.22	23.3041
2686.76	24.6003
2691.29	19.4147
2695.83	8.98399
2700.36	25.657
2704.89	19.8642
2709.41	12.3905
2713.93	27.4646
2718.45	5.5134
2722.96	15.7968
2727.47	17.8737
2731.98	1.98051
2736.49	2.28593
2740.99	25.3678
2745.49	17.6733
2749.98	26.3907
2754.47	28.9202
2758.96	9.86125
2763.45	18.5549
2767.93	33.9888
2772.41	1.63666
2776.89	12.2527
2781.36	16.4401
2785.84	15.7397
2790.3	10.0049
2794.77	-0.83931
2799.23	18.3598
2803.69	17.3836
2808.14	23.0652
2812.59	21.9651
2817.04	15.696
2821.49	16.2039
2825.93	32.0174
2830.37	18.9622
2834.81	22.845
2839.24	2.87958
2843.67	25.5394
2848.1	10.7362
2852.53	19.9374
2856.95	-3.35416
2861.37	18.0242
2865.78	18.9072
2870.19	12.8879
2874.6	-1.8739
2879.01	19.9195
2883.41	22.6739
2887.81	6.15324
2892.21	12.3686
2896.6	41.6396
2901	1.96486
2905.38	17.0685
2909.77	3.64644
2914.15	9.68625
2918.53	19.3336
2922.91	9.29897
2927.28	11.9077
2931.65	16.3764
2936.02	13.4977
2940.38	10.4697
2944.74	21.9605
2949.1	11.5055
2953.46	6.51743
2957.81	21.602
2962.16	18.4454
2966.5	33.6535
2970.85	21.4086
2975.19	1.77338
2979.52	13.4024
2983.86	21.4613
2988.19	27.7906
2992.52	10.0661
2996.85	5.29874
3001.17	8.04141
3005.49	18.353
3009.8	13.666
3014.12	14.5574
3018.43	28.8199
3022.74	35.564
3027.04	11.6916
3031.34	25.8096
3035.64	11.1482
3039.94	34.7757
3044.23	27.7337
3048.52	43.7195
3052.81	28.8769
3057.09	23.6839
3061.38	30.0678
3065.65	24.8348
3069.93	35.1216
3074.2	29.8822
3078.47	34.3934
3082.74	42.8223
3087	49.4354
3091.27	44.4291
3095.52	47.3818
3099.78	32.5931
3104.03	71.2946
3108.28	48.6519
3112.53	51.865
3116.77	49.0616
3121.01	40.2309
3125.25	45.5527
3129.49	71.3172
3133.72	72.899
3137.95	70.3441
3142.18	67.6533
3146.4	87.591
3150.62	68.1116
3154.84	83.7213
3159.06	63.8485
3163.27	85.7906
3167.48	72.0354
3171.69	106.687
3175.89	103.354
3180.09	46.8936
3184.29	85.5265
3188.49	88.0792
3192.68	107.782
3196.87	89.3934
3201.06	92.651
3205.24	83.1757
3209.42	88.8165
3213.6	94.5356
3217.78	87.3404
3221.95	103.939
3226.12	98.8001
3230.29	73.8115
3234.45	90.456
3238.61	104.964
3242.77	99.7332
3246.93	78.8888
3251.08	106.87
3255.23	98.8507
3259.38	72.8273
3263.53	82.9698
3267.67	71.0114
3271.81	85.9748
3275.95	105.149
3280.08	76.1649
3284.21	74.5765
3288.34	102.844
3292.47	75.9136
3296.59	94.98
3300.71	67.9854
3304.83	82.5392
3308.95	80.9022
3313.06	81.5158
3317.17	70.5258
3321.27	75.8956
3325.38	76.7181
3329.48	98.7143
3333.58	104.642
3337.67	89.3478
3341.77	104.446
3345.86	64.8663
3349.95	98.7206
3354.03	137.465
3358.11	116.879
3362.19	117.739
3366.27	142.517
3370.34	155.399
3374.42	139.337
3378.48	135.145
3382.55	130.898
3386.61	133.852
3390.68	98.0535
3394.73	115.473
3398.79	130.622
3402.84	106.845
3406.89	107.256
3410.94	107.631
3414.98	107.987
3419.03	108.353
3423.06	120.872
3427.1	113.94
3431.14	124.204
3435.17	100.33
3439.2	103.433
3443.22	109.056
3447.25	105.032
3451.27	115.819
3455.28	111.942
3459.3	130.552
3463.31	92.0239
3467.32	95.7358
3471.33	84.3577
3475.34	110.433
3479.34	91.3669
3483.34	115.179
3487.33	103.558
3491.33	91.8393
3495.32	69.7848
3499.31	111.457
3503.3	84.0201
3507.28	105.142
3511.26	85.0145
3515.24	98.2031
3519.22	90.8267
3523.19	88.5861
3527.16	88.981
3531.13	66.1756
3535.1	74.5666
3539.06	67.6512
3543.02	60.6155
3546.98	63.8444
3550.93	64.3751
3554.89	64.6654
3558.84	75.5578
3562.78	47.4735
3566.73	58.5673
3570.67	64.6003
3574.61	62.7743
3578.55	61.0521
3582.48	59.4182
3586.41	55.1554
3590.35	42.8947
3594.27	49.177
3598.2	60.8198
3602.12	13.6067
3606.04	35.8346
3609.95	47.3463
3613.87	29.294
3617.78	38.0992
3621.69	44.1217
3625.6	17.5375
3629.5	17.9465
3633.4	12.8906
3637.3	16.051
3641.2	32.9405
3645.09	9.24802
3648.98	-3.74226
3652.87	-0.497406
3656.76	5.45639
3660.64	27.785
3664.53	20.0904
3668.4	9.71884
3672.28	10.2587
3676.16	16.397
3680.03	17.1669
3683.9	1.52992
3687.76	2.45551
3691.63	-4.90059
3695.49	-9.58563
3699.35	-0.344238
3703.2	-13.3927
3707.06	7.09726
3710.91	10.8676
3714.76	-19.1237
3718.6	4.22426
3722.45	2.21494
3726.29	28.4442
3730.13	3.75352
3733.97	7.40646
3737.8	-6.00201
3741.63	11.8542
3745.46	-1.64658
3749.29	1.92061
3753.11	11.1609
3756.93	26.0878
3760.75	20.9347
3764.57	-10.0312
3768.39	4.87611
3772.2	8.3857
3776.01	14.7816
3779.81	1.11339
3783.62	-6.75775
3787.42	2.66685
3791.22	0.532654
3795.02	7.14043
3798.81	10.9316
3802.61	14.7604
3806.4	15.7294
3810.18	5.02863
3813.97	-8.68651
3817.75	3.90039
3821.53	-6.96921
3825.31	11.4764
3829.09	24.0987
3832.86	-4.49219
3836.63	2.2569
3840.4	26.7543
3844.17	-4.95137
3847.93	-4.28778
3851.69	34.9723
3855.45	14.7792
3859.21	-2.5323
3862.96	15.8769
3866.71	4.8056
3870.46	11.7168
3874.21	12.3178
3877.95	6.95406
3881.69	-1.40639
3885.44	2.21889
3889.17	5.87489
3892.91	27.5858
3896.64	16.4036
3900.37	-0.900269
3904.1	8.8531
3907.82	12.5734
3911.55	1.21083
3915.27	4.97244
3918.99	11.8342
3922.7	24.8661
3926.42	13.5094
3930.13	8.16345
3933.84	5.76764
3937.54	12.5036
3941.25	-2.19321
3944.95	10.7843
3948.65	-3.98952
3952.35	15.0741
3956.04	-2.96547
3959.73	9.82385
3963.42	0.898071
3967.11	4.28955
3970.8	7.61098
3974.48	20.2354
3978.16	23.5226
3981.84	17.4185
3985.52	-7.31972
3989.19	2.03027
3992.86	14.5226
3996.53	2.23204
3998.37	2.30193