File: Data/3-Raman/processed/bu19(2)w-a-ff1-fi09-v_1800 (450-850nm)_532nm_edge_100%_x100_vis_lwd_h100um_30sx2_01.txt
#Acq. time (s)=	30
#Accumulations=	2
#Range (cm-¹)=	1200...2365
#Windows=	3
#Auto scanning=	Off
#Autofocus=	Off
#Macrospot=	Off
#AutoExposure=	Off
#Spike filter=	Multiple accum.
#Delay time (s)=	2
#Binning=	1
#Readout mode=	Signal
#DeNoise=	Off
#ICS correction=	On
#Dark correction=	Off
#Inst. Process=	Off
#Detector Gain=	Best Dynamic
#Detector ADC=	50 kHz HS
#Detector temperature (°C)=	-60.09
#Instrument=	LabRAM HR Evol
#Detector=	SIN-EM FIVIS
#Objective=	x100_VIS_LWD
#Grating=	1800 (450-850nm)
#ND Filter=	100%
#Laser=	532nm_Edge
#Hole=	100.021
#Temperature=	0
#Range=	Visible
#StageXY=	75x50mm Scan+
#StageZ=	Z motor
#X (µm)=	0
#Y (µm)=	0
#Z (µm)=	-56
#Full time(mm:ss)=	3:17
#Project=	21_11_26
#Sample=	BU19(2)w
#Site=
#Title=	BU19(2)w-A-FF1-FI09-V_1800 (450-850nm)_532nm_Edge_100%_x100_VIS_LWD_H100um_30sX2
#Remark=
#Date=	26.11.2021 16:30
#Acquired=	26.11.2021 16:30:03
#Base:Fit=	16.12.2021 16:00:56
#Base:Fit=	16.12.2021 16:08:46
#Base:Sub=	16.12.2021 16:08:47
1202.72	0.649239
1203.84	10.1922
1204.95	9.94377
1206.06	4.2444
1207.17	11.3655
1208.28	2.45106
1209.39	3.15588
1210.5	-4.67134
1211.61	10.9077
1212.72	0.857231
1213.83	2.55366
1214.94	-2.10057
1216.05	3.87209
1217.16	1.22446
1218.27	-5.65565
1219.38	-0.832466
1220.49	-5.55872
1221.6	2.43758
1222.71	-0.25119
1223.81	2.30511
1224.92	-3.54992
1226.03	0.180183
1227.14	-1.39307
1228.25	1.09463
1229.35	4.60683
1230.46	3.25019
1231.57	-2.74361
1232.67	-2.21596
1233.78	3.54607
1234.89	-9.55946
1235.99	-7.95198
1237.1	0.965584
1238.2	0.338112
1239.31	1.81778
1240.41	3.36266
1241.52	1.80296
1242.62	-0.842102
1243.73	4.95761
1244.83	3.39794
1245.94	9.0968
1247.04	11.6834
1248.14	8.02431
1249.25	8.52661
1250.35	14.3142
1251.45	16.881
1252.56	5.89211
1253.66	12.666
1254.76	14.3503
1255.87	22.2684
1256.97	50.0492
1258.07	68.3766
1259.17	61.6063
1260.27	89.4824
1261.37	146.254
1262.48	227.914
1263.58	229.803
1264.68	135.247
1265.78	84.4938
1266.88	76.8171
1267.98	58.8427
1269.08	56.6031
1270.18	64.6505
1271.28	62.0876
1272.38	54.464
1273.47	62.7194
1274.57	66.7722
1275.67	82.2459
1276.77	94.7072
1277.87	122.972
1278.97	161.833
1280.07	326.787
1281.16	1021.86
1282.26	3394.97
1283.36	4161.27
1284.45	1454.91
1285.55	424.248
1286.65	188.128
1287.75	127.853
1288.84	98.1796
1289.94	72.8848
1291.03	66.4853
1292.13	61.0862
1293.22	53.6019
1294.32	31.5499
1295.42	45.2093
1296.51	43.3234
1297.61	33.7336
1298.7	29.3866
1299.79	22.9484
1300.89	24.0137
1301.98	18.7347
1303.08	12.422
1304.17	8.16188
1305.26	10.2785
1306.35	14.432
1307.45	7.06411
1308.54	15.5563
1309.63	6.15093
1310.73	-2.20833
1311.82	10.5479
1312.91	3.29397
1314	6.52544
1315.09	3.47369
1316.18	2.58404
1317.28	-2.58808
1318.37	3.91354
1319.46	-11.7853
1320.55	7.38401
1321.64	-0.972313
1322.73	0.166954
1323.82	-1.79737
1324.91	-5.8232
1326	-1.47175
1327.09	4.89112
1328.18	-1.05108
1329.27	4.55521
1330.35	4.76949
1331.44	-5.61884
1332.53	3.97047
1333.62	-1.16328
1334.71	2.14117
1335.79	-1.86947
1336.88	1.49147
1337.97	3.82829
1339.06	0.89698
1340.14	8.51493
1341.23	4.63184
1342.32	6.99316
1343.4	6.17253
1344.49	-7.11656
1345.58	9.89243
1346.66	0.68586
1347.75	6.12411
1348.83	4.33396
1349.92	8.77747
1351	0.725769
1352.09	14.5317
1353.17	8.71117
1354.25	17.5028
1355.34	17.6288
1356.42	17.9896
1357.51	18.3148
1358.59	13.4402
1359.67	14.7924
1360.76	21.3022
1361.84	38.2336
1362.92	39.6179
1364	52.4866
1365.09	55.9884
1366.17	45.9264
1367.25	54.4639
1368.33	88.9799
1369.41	208.341
1370.5	65.0012
1371.58	60.1329
1372.66	63.4434
1373.74	69.9511
1374.82	79.601
1375.9	85.1733
1376.98	97.8836
1378.06	98.2505
1379.14	131.959
1380.22	132.285
1381.3	175.481
1382.38	239.346
1383.46	354.223
1384.54	735.808
1385.61	2351.23
1386.69	9635.52
1387.77	4541.9
1388.85	865.324
1389.93	392.223
1391	241.236
1392.08	179.952
1393.16	138.223
1394.23	128.35
1395.31	106.267
1396.39	98.5734
1397.46	95.8576
1398.54	88.0788
1399.62	82.4441
1400.69	91.1234
1401.77	94.7074
1402.84	94.365
1403.92	108.299
1404.99	137.337
1406.07	185.827
1407.14	290.736
1408.22	459.415
1409.29	365.646
1410.37	182.553
1411.44	98.699
1412.51	76.5523
1413.59	56.8111
1414.66	49.9076
1415.73	49.3519
1416.81	37.481
1417.88	41.0256
1418.95	35.292
1420.02	31.5702
1421.1	26.7734
1422.17	26.159
1423.24	28.8013
1424.31	31.99
1425.38	26.2405
1426.45	25.6357
1427.52	20.823
1428.59	19.093
1429.67	13.3599
1430.74	9.70714
1431.81	12.2292
1432.87	16.6752
1433.95	8.75149
1435.01	8.12399
1436.08	9.52092
1437.15	16.0164
1438.22	12.2675
1439.29	6.50703
1440.36	5.88593
1441.43	12.4119
1442.49	4.55487
1443.56	10.0291
1444.63	7.28782
1445.7	0.496227
1446.77	5.9476
1447.83	7.28852
1448.9	-2.61609
1449.97	3.85923
1451.03	4.15977
1452.1	3.43919
1453.17	1.70678
1454.23	3.05592
1455.3	4.38951
1456.36	-0.413628
1457.43	1.92085
1458.49	3.23885
1459.56	-6.69961
1460.62	0.759678
1461.69	4.1014
1462.75	1.2832
1463.82	0.501671
1464.88	-4.28432
1465.94	-0.0486336
1467.01	-5.91261
1468.07	1.49049
1469.13	0.728989
1470.2	-5.15543
1471.26	-3.89957
1472.32	0.405796
1473.39	-3.42411
1474.45	-3.19748
1475.51	-3.96569
1476.57	-6.79311
1477.63	-3.52493
1478.69	-0.258072
1479.76	-2.08992
1480.82	-0.894367
1481.88	-0.689014
1482.94	-3.48838
1484	-2.25228
1485.06	-1.11139
1486.12	-0.917324
1487.18	1.31622
1488.24	4.53104
1489.3	-2.39421
1490.36	-0.189793
1491.42	0.987473
1492.48	2.17884
1493.53	-2.70035
1494.59	-1.51318
1495.65	0.665649
1496.71	-0.213039
1497.77	2.97069
1498.82	2.1225
1499.88	-2.75551
1500.94	2.45174
1502	1.57916
1503.05	0.704693
1504.11	3.85611
1505.17	2.99498
1506.22	-4.96262
1507.28	-0.792927
1508.34	-3.68249
1509.39	1.48615
1510.45	-3.42011
1511.5	-2.32058
1512.56	3.76096
1513.61	4.83648
1514.67	3.97279
1515.72	2.04078
1516.78	1.11017
1517.83	0.206356
1518.88	1.32551
1519.94	2.43836
1520.99	-0.480202
1522.05	-0.380329
1523.1	5.71218
1524.15	3.74839
1525.2	-3.19426
1526.26	2.91241
1527.31	3.01231
1528.36	4.076
1529.41	3.13324
1530.47	1.1903
1531.52	5.29109
1532.57	6.35264
1533.62	5.45751
1534.67	4.52167
1535.72	2.556
1536.77	6.56454
1537.82	2.57185
1538.87	4.59892
1539.92	5.70799
1540.97	-3.20285
1542.02	2.83376
1543.07	6.84257
1544.12	4.83425
1545.17	0.893787
1546.22	2.96711
1547.27	3.0084
1548.32	-2.98808
1549.37	0.0245247
1550.42	-2.93964
1551.46	6.21526
1552.51	1.21941
1553.56	10.2436
1554.61	-4.80902
1555.65	7.20221
1556.7	2.20605
1557.75	-0.779797
1558.79	2.20771
1559.84	4.17582
1560.89	2.16603
1561.93	2.17989
1562.98	2.20515
1564.02	-1.79771
1565.07	5.23601
1566.11	3.00668
1567.16	-0.831802
1568.2	2.19137
1569.25	4.19645
1570.29	-1.82406
1571.34	2.16629
1572.38	3.14074
1573.43	2.1105
1574.47	-0.897923
1575.51	1.12212
1576.56	1.11485
1577.6	-1.93545
1578.64	5.98792
1579.69	2.97863
1580.73	5.96481
1581.77	0.944851
1582.81	-2.0827
1583.85	2.87148
1584.9	-0.135429
1585.94	3.8255
1586.98	0.787876
1588.02	1.74613
1589.06	4.72086
1590.1	1.72438
1591.14	0.713669
1592.18	0.680065
1593.22	-1.36977
1594.26	0.540707
1595.3	1.51281
1596.34	5.44437
1597.38	3.43308
1598.42	3.40537
1599.46	-5.59182
1600.5	-2.6673
1601.54	1.22892
1602.58	0.170715
1603.62	-2.85929
1604.66	3.03345
1605.69	0.037941
1606.73	-0.968124
1607.77	-1.84296
1608.81	3.59568
1609.84	-0.696503
1610.88	2.07705
1611.92	3.68782
1612.95	-0.300453
1613.99	0.174156
1615.03	1.1686
1616.06	-0.344986
1617.1	0.590443
1618.13	0.780754
1619.17	0.594463
1620.2	1.9486
1621.24	1.59726
1622.27	1.33036
1623.31	1.60707
1624.34	1.72237
1625.38	-0.931343
1626.41	-0.00939178
1627.45	0.167755
1628.48	0.24794
1629.51	-0.691723
1630.55	2.6155
1631.53	2.37996
1632.57	-0.593666
1633.62	1.33974
1634.66	2.30011
1635.71	2.26304
1636.75	1.22804
1637.8	-1.78006
1638.84	2.11398
1639.89	1.09676
1640.93	-1.88313
1641.98	0.0536346
1643.02	2.96736
1644.06	2.92953
1645.11	-0.0695572
1646.15	2.86265
1647.19	-1.11761
1648.24	-1.15887
1649.28	0.811565
1650.32	5.70287
1651.37	-4.1402
1652.41	2.73575
1653.45	-0.256824
1654.49	2.67985
1655.53	-3.24568
1656.57	3.67087
1657.62	1.67175
1658.66	-0.340546
1659.7	-0.386318
1660.74	2.54156
1661.78	-5.348
1662.82	2.56625
1663.86	0.572086
1664.9	1.51252
1665.94	-4.47491
1666.98	1.4683
1668.02	0.440117
1669.06	0.427391
1670.1	-2.52876
1671.14	-0.545616
1672.18	-0.570633
1673.21	-2.56169
1674.25	0.395378
1675.29	-0.589596
1676.33	-2.57656
1677.37	-0.609501
1678.4	-0.641857
1679.44	-1.66853
1680.48	1.26961
1681.52	-3.69636
1682.55	-1.73408
1683.59	0.227222
1684.63	1.19413
1685.66	0.18845
1686.7	3.14452
1687.73	-2.78245
1688.77	0.155785
1689.81	1.10793
1690.84	-0.882721
1691.88	0.109837
1692.91	-4.83512
1693.95	-1.91543
1694.98	-0.96228
1696.01	-0.962101
1697.05	-5.88408
1698.08	2.94969
1699.12	-1.01715
1700.15	-2.98955
1701.18	0.934315
1702.22	2.87985
1703.25	-0.0939522
1704.28	-0.10397
1705.32	-1.07952
1706.35	-1.08718
1707.38	-0.138466
1708.41	-7.04049
1709.44	-0.220802
1710.48	-0.226479
1711.51	-1.19022
1712.54	2.73291
1713.57	1.6993
1714.6	0.686691
1715.63	1.66828
1716.66	2.6497
1717.69	0.654602
1718.72	-2.32215
1719.75	-3.30211
1720.78	-4.27015
1721.81	-0.399452
1722.84	3.46009
1723.87	3.43895
1724.9	3.43534
1725.93	1.45046
1726.96	1.44611
1727.99	2.41386
1729.02	1.38044
1730.05	1.35308
1731.07	-3.48433
1732.1	-3.4339
1733.13	0.428463
1734.16	-0.5728
1735.18	3.24885
1736.21	-4.47697
1737.24	4.18091
1738.26	-2.56021
1739.29	5.1104
1740.32	-0.69455
1741.34	-0.721222
1742.37	-0.731129
1743.4	-5.51288
1744.42	5.96745
1745.45	4.06131
1746.47	5.01808
1747.5	-2.6511
1748.52	4.02693
1749.55	2.14335
1750.57	4.10258
1751.6	1.26905
1752.62	6.98155
1753.64	0.282108
1754.67	4.08578
1755.69	5.9881
1756.71	1.20741
1757.74	3.08862
1758.76	3.11958
1759.78	3.14178
1760.81	4.10089
1761.83	3.14244
1762.85	6.96112
1763.87	-1.5724
1764.89	5.13324
1765.92	1.36258
1766.94	6.13861
1767.96	2.33808
1768.98	8.04855
1770	2.29052
1771.02	5.18007
1772.04	1.4296
1773.06	4.32455
1774.08	4.36128
1775.1	7.25015
1776.12	7.31108
1777.14	1.61088
1778.16	12.0846
1779.18	3.49743
1780.2	4.46126
1781.22	-1.21834
1782.24	-0.237301
1783.26	1.7108
1784.28	0.795189
1785.29	3.70057
1786.31	1.80097
1787.33	1.83704
1788.35	1.92596
1789.37	3.91418
1790.38	3.96715
1791.4	3.97988
1792.42	3.00902
1793.43	4.95442
1794.45	2.10549
1795.47	1.19673
1796.48	-3.54653
1797.5	4.18272
1798.51	2.29606
1799.53	-0.575466
1800.55	0.377884
1801.56	3.2645
1802.58	0.405701
1803.59	1.40787
1804.61	2.40136
1805.62	-0.440105
1806.64	-0.397881
1807.65	3.48095
1808.66	3.4973
1809.68	3.51662
1810.69	1.60687
1811.7	1.61513
1812.72	-0.294708
1813.73	1.66559
1814.74	-0.219933
1815.76	-6.94627
1816.77	3.70467
1817.78	-1.13741
1818.79	3.71043
1819.8	2.76624
1820.82	0.860054
1821.83	-1.04705
1822.84	-1.02309
1823.85	0.922298
1824.86	2.86893
1825.87	6.76522
1826.88	2.90225
1827.89	1.95256
1828.9	4.86533
1829.91	2.92325
1830.92	0.0109596
1831.93	4.87351
1832.94	6.84161
1833.95	0.0732956
1834.96	1.99298
1835.97	-1.92695
1836.98	1.11057
1837.99	1.97015
1839	4.87445
1840	2.99419
1841.01	0.989189
1842.02	5.75415
1843.03	1.86329
1844.04	1.86517
1845.04	0.903202
1846.05	7.66959
1847.06	0.950329
1848.07	-0.133598
1849.07	-2.05273
1850.08	0.808144
1851.09	1.72486
1852.09	2.66021
1853.1	-3.10496
1854.1	-4.0794
1855.11	-0.278217
1856.11	-0.313885
1857.12	0.635643
1858.12	-3.21093
1859.13	0.586182
1860.13	3.42529
1861.14	0.567661
1862.14	0.581913
1863.15	-2.3156
1864.15	-3.30532
1865.15	-2.38005
1866.16	-3.38116
1867.16	-3.44067
1868.16	0.31609
1869.17	-1.59693
1870.17	-3.51207
1871.17	-3.52567
1872.17	-0.695862
1873.18	-0.725613
1874.18	2.0986
1875.18	-1.73782
1876.18	-5.5836
1877.18	0.0502281
1878.18	2.82318
1879.19	-2.80216
1880.19	-6.57545
1881.19	0.983486
1882.19	-0.971493
1883.19	-1.99799
1884.19	-5.81525
1885.19	-2.98473
1886.19	0.819088
1887.19	1.74498
1888.19	-1.13313
1889.19	-2.1343
1890.19	2.53946
1891.19	-0.277531
1892.18	2.52533
1893.18	-1.27152
1894.18	-1.33821
1895.18	0.509632
1896.18	-2.31397
1897.18	-2.30851
1898.17	-2.3161
1899.17	-4.23183
1900.17	3.24638
1901.16	3.22844
1902.16	1.36057
1903.16	0.416531
1904.16	2.26616
1905.15	2.24223
1906.15	0.330208
1907.14	1.22638
1908.14	1.21288
1909.14	2.15002
1910.13	2.16573
1911.13	4.07602
1912.12	7.83669
1913.12	4.04358
1914.11	1.21656
1915.11	-2.53992
1916.1	-1.60321
1917.1	0.247269
1918.09	-2.61757
1919.08	-2.61558
1920.08	-0.700157
1921.07	-3.54791
1922.06	2.13235
1923.06	-0.729298
1924.05	0.181713
1925.04	1.08949
1926.04	-1.7414
1927.03	2.0627
1928.02	-0.774857
1929.01	-1.72744
1930	1.12545
1931	-0.753792
1931.99	2.07063
1932.98	1.08069
1933.97	-0.830658
1934.96	0.201538
1935.95	1.21392
1936.94	1.15918
1937.93	2.05975
1938.92	1.08636
1939.91	2.04053
1940.9	0.140869
1941.89	-1.7539
1942.88	3.01461
1943.87	2.01912
1944.86	6.80109
1945.85	-3.68907
1946.84	-4.64254
1947.83	2.02791
1948.82	-2.77577
1949.8	-0.85915
1950.79	-1.78641
1951.78	-1.75176
1952.77	3.06059
1953.76	1.12667
1954.74	-0.885933
1955.73	-1.87925
1956.72	-2.79814
1957.7	0.0984421
1958.69	1.06152
1959.68	1.99416
1960.66	-0.922073
1961.65	-3.8413
1962.63	-1.93644
1963.62	-0.0262833
1964.61	-0.990028
1965.59	-1.96893
1966.58	1.87789
1967.56	2.84311
1968.55	-0.0477943
1969.53	-4.88516
1970.52	-2.0535
1971.5	-1.12714
1972.48	2.69714
1973.47	1.71744
1974.45	5.51579
1975.44	6.46635
1976.42	3.59992
1977.4	0.714378
1978.39	0.685246
1979.37	5.45583
1980.35	6.40847
1981.33	2.54398
1982.31	3.47868
1983.3	7.27479
1984.28	4.36694
1985.26	4.34038
1986.24	4.31974
1987.22	3.37066
1988.21	10.9792
1989.19	2.34647
1990.17	4.38975
1991.15	7.8916
1992.13	6.79725
1993.11	3.76582
1994.09	9.49715
1995.07	10.9848
1996.05	10.945
1997.03	6.90664
1998.01	12.434
1998.99	9.67516
1999.97	10.5522
2000.95	12.6034
2001.92	12.4051
2002.9	12.4653
2003.88	11.6619
2004.86	11.1613
2005.84	9.09603
2006.81	13.5842
2007.79	12.6195
2008.77	12.9651
2009.75	12.9698
2010.73	9.21244
2011.7	12.257
2012.68	14.1903
2013.67	11.3187
2014.66	15.0052
2015.64	8.42123
2016.63	5.63161
2017.62	11.3061
2018.61	11.252
2019.6	14.9393
2020.58	13.9908
2021.57	10.2564
2022.56	7.44565
2023.55	9.28809
2024.54	10.1965
2025.52	11.0818
2026.51	11.0564
2027.5	5.58216
2028.48	9.28497
2029.47	2.82171
2030.45	7.38363
2031.44	4.619
2032.43	3.70881
2033.41	8.4489
2034.4	6.60211
2035.38	3.7553
2036.37	3.85801
2037.35	7.60523
2038.34	5.74257
2039.32	5.73647
2040.31	4.78795
2041.29	1.03873
2042.27	-0.821117
2043.26	4.77605
2044.24	-0.75172
2045.23	-0.74976
2046.21	5.88409
2047.19	1.20227
2048.17	5.84058
2049.16	-0.651604
2050.14	-2.45517
2051.12	2.26616
2052.11	-0.530949
2053.09	4.17691
2054.07	0.50589
2055.05	5.22168
2056.03	-0.380356
2057.01	0.570889
2058	3.41239
2058.98	4.40652
2059.96	0.709599
2060.94	-2.0818
2061.92	2.64245
2062.9	1.74474
2063.88	-5.69895
2064.86	-0.969479
2065.84	0.970928
2066.82	-2.73165
2067.8	1.07199
2068.78	1.12083
2069.76	1.14355
2070.73	-3.52533
2071.71	1.22913
2072.69	-0.570473
2073.67	3.22292
2074.65	-3.32593
2075.63	-1.36734
2076.6	-1.29669
2077.58	-0.335136
2078.56	-2.19511
2079.54	-1.19825
2080.51	0.760021
2081.49	-1.09518
2082.47	-0.114681
2083.45	1.81589
2084.42	2.79455
2085.4	2.83251
2086.37	0.990471
2087.35	-2.73013
2088.32	-4.57722
2089.3	1.14419
2090.28	-3.53084
2091.25	0.306568
2092.23	-1.52653
2093.2	1.40034
2094.18	1.47171
2095.15	5.31914
2096.13	-1.31645
2097.1	2.51237
2098.07	-0.320126
2099.05	-5.98523
2100.02	0.691502
2101	0.736183
2101.97	-0.154121
2102.94	-0.118732
2103.92	-1.04684
2104.89	1.84607
2105.86	0.00804138
2106.83	1.01177
2107.8	-1.80036
2108.78	1.05547
2109.75	1.09343
2110.72	1.13855
2111.69	4.02327
2112.66	0.250977
2113.63	1.25749
2114.61	-0.60059
2115.58	-0.563541
2116.55	4.2087
2117.52	-1.46593
2118.49	1.40651
2119.46	-2.38409
2120.43	-0.475136
2121.4	1.46433
2122.37	0.582451
2123.34	-4.10844
2124.31	-5.02397
2125.28	-3.12842
2126.25	-4.08043
2127.21	3.49538
2128.18	-4.9934
2129.15	-3.07287
2130.12	-3.04562
2131.09	-0.185696
2132.06	2.66242
2133.02	-4.8746
2133.99	-0.124096
2134.96	-1.97704
2135.93	-1.00748
2136.89	0.881119
2137.86	-0.0230942
2138.83	-2.83097
2139.79	0.0353622
2140.76	2.86531
2141.73	-2.76407
2142.69	2.89855
2143.66	0.128687
2144.62	-0.845516
2145.59	2.94558
2146.55	2.02737
2147.52	0.162083
2148.48	-4.52223
2149.45	1.12016
2150.42	1.1085
2151.38	3.93861
2152.34	3.98169
2153.31	0.244736
2154.27	2.127
2155.24	1.16777
2156.2	0.213495
2157.16	4.89556
2158.13	1.1946
2159.09	-0.647766
2160.05	1.22415
2161.01	-0.651329
2161.98	-0.641823
2162.94	2.17511
2163.9	1.2474
2164.86	0.311317
2165.83	3.12477
2166.79	3.13558
2167.75	1.26561
2168.71	1.23708
2169.67	1.26516
2170.63	-2.40394
2171.59	5.05097
2172.56	2.2167
2173.51	1.28952
2174.48	-3.33499
2175.44	0.396032
2176.4	4.11794
2177.36	2.2609
2178.32	0.415783
2179.28	4.12113
2180.23	0.419098
2181.19	-2.36214
2182.15	0.421215
2183.11	1.34507
2184.07	1.32242
2185.03	2.24541
2185.99	3.19096
2186.95	-2.34197
2187.9	0.480808
2188.86	1.40038
2189.82	1.36984
2190.78	-3.27582
2191.73	1.36913
2192.69	-0.472795
2193.65	-0.453146
2194.6	1.45138
2195.56	-1.33969
2196.52	4.20134
2197.47	-0.470308
2198.43	2.31104
2199.38	2.34698
2200.34	8.90304
2201.3	3.37808
2202.25	-3.23934
2203.21	2.38558
2204.16	-0.29986
2205.12	1.50302
2206.07	2.34941
2207.03	-1.37821
2207.98	2.35376
2208.93	7.02875
2209.89	0.514029
2210.84	3.30939
2211.8	1.45845
2212.75	1.47068
2213.7	-0.417675
2214.66	1.45309
2215.61	-6.00503
2216.56	-1.34628
2217.51	1.43957
2218.47	0.49634
2219.42	-0.435478
2220.37	1.43712
2221.32	-3.25486
2222.27	-0.493057
2223.23	0.428638
2224.18	1.37575
2225.13	1.39587
2226.08	-0.460201
2227.03	-3.2627
2227.98	-3.26318
2228.93	1.40192
2229.88	0.450083
2230.83	-3.29256
2231.78	0.473082
2232.73	0.481115
2233.68	-1.39438
2234.63	-0.459028
2235.58	-0.499416
2236.53	1.35933
2237.48	3.23563
2238.43	1.38134
2239.38	1.40248
2240.33	-0.516298
2241.27	-1.46476
2242.22	-4.30672
2243.17	2.29189
2244.12	-0.571815
2245.07	4.14366
2246.01	-2.4499
2246.96	1.33463
2247.91	-0.562853
2248.85	-1.53449
2249.8	3.17838
2250.75	-1.57917
2251.69	0.269089
2252.64	-1.63395
2253.59	1.23139
2254.53	-0.653936
2255.48	2.17452
2256.42	1.21564
2257.37	1.21945
2258.32	3.1157
2259.26	-2.59071
2260.2	0.254793
2261.15	-2.60188
2262.1	-1.65017
2263.04	1.20347
2263.98	-1.63606
2264.93	-0.656599
2265.87	0.301647
2266.81	-2.59591
2267.76	-1.68203
2268.7	-7.43835
2269.65	-3.62272
2270.59	-2.64834
2271.53	0.224857
2272.47	-1.68597
2273.42	-3.60958
2274.36	-0.747375
2275.3	0.202301
2276.24	-0.761938
2277.18	1.16964
2278.13	4.07954
2279.07	-0.711708
2280.01	3.09151
2280.95	-7.50317
2281.89	0.140465
2282.83	-0.813105
2283.77	-3.66855
2284.71	-4.59456
2285.65	0.224781
2286.59	-0.766264
2287.54	-0.741095
2288.47	5.0447
2289.41	5.96952
2290.35	1.10557
2291.29	3.02337
2292.23	2.08918
2293.17	5.00102
2294.11	-0.769644
2295.05	0.170837
2295.99	0.147137
2296.93	-1.80857
2297.86	-3.71902
2298.8	3.05098
2299.74	1.1486
2300.68	-2.71092
2301.61	2.12792
2302.55	-0.770927
2303.49	-1.74185
2304.43	-3.66581
2305.36	-2.68366
2306.3	-3.63976
2307.24	3.13069
2308.17	1.18652
2309.11	3.11463
2310.04	3.14679
2310.98	2.19138
2311.92	-0.759073
2312.85	3.07275
2313.79	1.15348
2314.72	1.19841
2315.66	-0.713259
2316.59	5.04444
2317.52	3.10041
2318.46	3.10835
2319.39	5.98394
2320.33	5.97355
2321.26	5.986
2322.2	14.7156
2323.13	14.7475
2324.06	23.464
2325	33.1158
2325.93	66.8424
2326.86	269.377
2327.79	799.372
2328.73	207.384
2329.66	57.9284
2330.59	24.2093
2331.52	11.68
2332.46	9.76375
2333.39	2.03269
2334.32	2.97516
2335.25	5.83155
2336.18	3.90339
2337.11	3.888
2338.04	4.834
2338.97	0.0124168
2339.91	1.92572
2340.84	-0.0256348
2341.77	3.76068
2342.7	1.8003
2343.63	0.81966
2344.56	2.71926
2345.49	0.777237
2346.41	-3.10138
2347.34	-1.21757
2348.27	-2.20087
2349.2	-1.26777
2350.13	1.52297
2351.06	-0.57478
2351.99	-0.481209
2352.91	4.20228
2353.84	3.15533
2354.77	-2.60312
2355.7	3.06818
2356.63	-3.67192
2357.55	0.993065
2358.48	1.86724
2359.41	1.79009
2360.33	2.65495
2361.26	1.60418
2362.19	-3.242
2363.11	-0.508995
2364.04	0.336456
2364.97	-5.44336