File: Data/3-Raman/processed/bu19w-e-ff11-fi09-l_150 (500nm)_633nm_edge_100%_x100_vis_h50um_60sx2_01_0.txt
#Acq. time (s)=	60
#Accumulations=	2
#Range (cm-¹)=	100...4000
#Windows=	1
#Auto scanning=	Off
#Autofocus=	Off
#Macrospot=	Off
#AutoExposure=	Off
#Spike filter=	Multiple accum.
#Delay time (s)=	2
#Binning=	1
#Readout mode=	Signal
#DeNoise=	Off
#ICS correction=	On
#Dark correction=	Off
#Inst. Process=	Off
#Detector Gain=	Best Dynamic
#Detector ADC=	50 kHz HS
#Detector temperature (°C)=	-60.09
#Instrument=	LabRAM HR Evol
#Detector=	SIN-EM FIVIS
#Objective=	x100_VIS
#Grating=	150 (500nm)
#ND Filter=	100%
#Laser=	633nm_Edge
#Hole=	49.98
#Temperature=	0
#Range=	Visible
#StageXY=	75x50mm Scan+
#StageZ=	Z motor
#X (µm)=	0
#Y (µm)=	0
#Z (µm)=	-270
#Full time(mm:ss)=	2:04
#Project=	21_11_04
#Sample=	BU19w
#Site=
#Title=	BU19w-E-FF11-FI09-L_150 (500nm)_633nm_Edge_100%_x100_VIS_H50um_60sX2
#Remark=
#Date=	04.11.2021 16:16
#Acquired=	04.11.2021 16:16:57
#Base:Fit=	16.12.2021 17:39:50
#Base:Edit=	16.12.2021 17:51:32
#Base:Edit=	16.12.2021 17:51:33
#Base:Edit=	16.12.2021 17:51:33
#Base:Edit=	16.12.2021 17:51:34
#Base:Edit=	16.12.2021 17:51:34
#Base:Edit=	16.12.2021 17:51:35
#Base:Edit=	16.12.2021 17:51:35
#Base:Edit=	16.12.2021 17:51:36
#Base:Edit=	16.12.2021 17:51:36
#Base:Edit=	16.12.2021 17:51:37
#Base:Edit=	16.12.2021 17:51:37
#Base:Sub=	16.12.2021 17:51:40
102.881	189.825
109.397	142.235
115.908	135.689
122.414	119.532
128.914	147.379
135.409	123.527
141.898	139.79
148.383	143.725
154.861	186.083
161.335	195.043
167.801	101.466
174.264	57.593
180.721	20.3272
187.173	15.5433
193.62	16.4405
200.061	19.3668
206.496	10.1443
212.926	21.8842
219.352	68.9288
225.772	186.376
232.185	265.27
238.595	133.16
244.999	62.2213
251.397	57.8684
257.791	62.9912
264.178	70.078
270.561	69.6387
276.939	87.278
283.31	95.3794
289.678	39.914
296.039	42.2243
302.396	36.027
308.746	101.65
315.093	294.665
321.433	507.331
327.768	308.709
334.099	128.172
340.423	86.3087
346.743	75.5424
353.058	100.542
359.367	121.656
365.671	88.1511
371.971	47.2048
378.265	19.4644
384.553	10.5775
390.837	14.1031
397.116	11.2037
403.389	3.71428
409.657	19.7353
415.92	29.0811
422.178	60.1478
428.431	104.001
434.678	97.3839
440.921	93.5838
447.158	113.194
453.391	138.244
459.618	96.1168
465.84	49.722
472.057	37.9741
478.27	33.8252
484.477	37.1114
490.679	49.704
496.876	64.1685
503.068	84.2534
509.255	118.36
515.436	118.949
521.613	114.059
527.785	108.326
533.952	88.6059
540.113	72.5147
546.27	61.8373
552.423	50.9317
558.568	38.0254
564.711	31.466
570.848	32.3052
576.979	48.9456
583.107	50.5334
589.228	76.4656
595.345	94.1146
601.458	98.0447
607.565	109.692
613.667	109.318
619.764	90.3401
625.856	63.7838
631.944	55.678
638.026	57.6221
644.104	59.2883
650.177	69.3791
656.244	64.2487
662.308	42.26
668.365	28.7994
674.418	18.4052
680.467	10.8656
686.511	10.8589
692.549	6.27553
698.582	10.115
704.611	9.23013
710.635	3.55038
716.655	7.04892
722.669	0.208092
728.679	2.66916
734.683	4.134
740.683	3.7107
746.678	7.03407
752.669	12.2573
758.654	9.15105
764.635	10.8877
770.611	17.3833
776.582	7.92129
782.549	8.67157
788.511	14.0532
794.466	5.22697
800.419	20.8223
806.366	18.4041
812.309	14.0504
818.247	16.2032
824.18	16.4305
830.108	24.1373
836.033	25.4824
841.952	21.3825
847.865	27.5956
853.776	32.9345
859.681	41.1483
865.58	52.2389
871.476	59.5525
877.366	63.8721
883.253	68.1021
889.134	74.1135
895.012	66.7461
900.883	59.2164
906.751	59.1707
912.614	53.4348
918.473	61.8896
924.326	73.3197
930.174	93.4128
936.019	115.596
941.859	156.17
947.693	187.627
953.525	202.185
959.35	204.235
965.171	217.545
970.988	310.346
976.801	409.625
982.608	450.551
988.411	403.918
994.209	290.408
1000	255.608
1005.79	250.626
1011.58	272.739
1017.36	301.811
1023.13	273.773
1028.9	211.466
1034.67	159.491
1040.43	160.293
1046.19	130.162
1051.94	125.875
1057.69	105.9
1063.44	100.268
1069.17	97.341
1074.91	116.733
1080.64	151.524
1086.37	199.796
1092.09	298.45
1097.8	316.624
1103.52	217.778
1109.22	159.866
1114.93	126.426
1120.63	131.924
1126.32	116.772
1132.01	172.97
1137.7	205.909
1143.38	266.486
1149.06	339.784
1154.73	249.48
1160.4	118.398
1166.06	94.4364
1171.72	68.6008
1177.38	55.5542
1183.03	37.7291
1188.67	28.8677
1194.31	36.7067
1199.95	23.1398
1205.58	13.5718
1211.21	14.8242
1216.84	16.1327
1222.46	13.5111
1228.07	11.8627
1233.68	6.13204
1239.29	3.31098
1244.89	12.4834
1250.49	9.46276
1256.08	18.4964
1261.67	6.21232
1267.26	12.076
1272.84	9.83076
1278.42	12.5794
1283.99	11.3178
1289.56	12.1073
1295.12	2.95916
1300.68	6.86066
1306.23	6.84974
1311.78	3.94421
1317.33	6.11075
1322.87	2.26413
1328.41	1.46066
1333.94	2.67344
1339.47	13.0423
1345	5.98804
1350.52	6.04237
1356.04	7.08874
1361.55	4.99946
1367.06	26.4815
1372.56	33.5315
1378.06	20.0358
1383.56	16.8057
1389.05	2.28921
1394.53	7.32304
1400.02	-0.885216
1405.5	6.31606
1410.97	0.163383
1416.44	4.3464
1421.91	3.38191
1427.37	1.39144
1432.83	1.47656
1438.28	3.64207
1443.73	1.62981
1449.17	0.624878
1454.62	1.64276
1460.05	11.0064
1465.48	3.52679
1470.91	1.28088
1476.34	-0.94635
1481.76	0.00994873
1487.17	8.34795
1492.59	-0.08815
1497.99	3.0826
1503.4	3.12399
1508.8	12.7269
1514.19	-0.949188
1519.59	1.30032
1524.97	-2.83428
1530.36	2.6589
1535.74	13.5942
1541.11	8.31652
1546.48	9.39713
1551.85	6.01867
1557.21	10.0937
1562.57	8.78403
1567.93	9.62963
1573.28	6.16193
1578.62	8.1297
1583.97	4.76339
1589.3	7.88219
1594.64	-2.96931
1599.97	13.1754
1605.3	17.5234
1610.62	15.4594
1615.94	12.3737
1621.25	10.3938
1626.56	12.7763
1631.87	12.9636
1637.17	13.0775
1642.47	16.3522
1647.76	17.4463
1653.05	7.42485
1658.34	6.2076
1663.62	8.28616
1668.9	14.7804
1674.18	10.1765
1679.45	3.3361
1684.71	7.53468
1689.98	12.8212
1695.23	2.66332
1700.49	10.3499
1705.74	10.6381
1710.99	9.46954
1716.23	5.97614
1721.47	10.5236
1726.7	8.24795
1731.94	2.63813
1737.16	9.37257
1742.39	7.10608
1747.61	-0.830505
1752.82	4.73792
1758.03	0.0906067
1763.24	4.44939
1768.44	8.82383
1773.64	4.14745
1778.84	1.76948
1784.03	5.1095
1789.22	11.9154
1794.41	7.36177
1799.59	5.1016
1804.76	3.99557
1809.94	7.44933
1815.11	9.74039
1820.27	8.57636
1825.43	10.8875
1830.59	12.0583
1835.74	0.451042
1840.89	13.2284
1846.04	7.33984
1851.18	1.41679
1856.32	-1.04408
1861.45	5.92082
1866.58	5.88168
1871.71	-1.25387
1876.83	10.4186
1881.95	-1.51199
1887.07	11.331
1892.18	8.74261
1897.29	3.77766
1902.39	4.80933
1907.49	13.0443
1912.59	7.13799
1917.68	9.58986
1922.77	4.6672
1927.86	2.20355
1932.94	8.11804
1938.02	-6.39188
1943.09	0.673004
1948.16	12.5411
1953.23	11.1295
1958.29	13.3032
1963.35	5.81498
1968.41	-5.32141
1973.46	12.4179
1978.51	9.6714
1983.55	14.1418
1988.59	8.99834
1993.63	15.8926
1998.66	10.7862
2003.69	5.70811
2008.72	3.06883
2013.74	5.2664
2018.76	0.222313
2023.77	-4.81744
2028.78	2.25187
2033.79	14.229
2038.79	10.5089
2043.79	6.7858
2048.79	0.629898
2053.78	11.4733
2058.77	7.73065
2063.76	13.7848
2068.74	8.81993
2073.72	9.96974
2078.69	8.64452
2083.66	10.9907
2088.63	15.7688
2093.59	18.1358
2098.55	5.68102
2103.51	4.38109
2108.46	11.8325
2113.41	15.605
2118.36	8.12109
2123.3	16.9472
2128.24	5.60581
2133.17	15.6918
2138.11	15.6444
2143.03	14.3057
2147.96	1.45738
2152.88	12.7547
2157.79	9.99365
2162.71	7.18635
2167.62	1.77163
2172.52	15.5648
2177.43	10.1911
2182.32	3.46543
2187.22	18.469
2192.11	5.36602
2197	6.38626
2201.89	7.47337
2206.77	7.32586
2211.64	4.64696
2216.52	8.43849
2221.39	22.6295
2226.26	1.86239
2231.12	7.00474
2235.98	9.56454
2240.84	0.367622
2245.69	0.306557
2250.54	12.0691
2255.39	10.7066
2260.23	10.6771
2265.07	0.0154343
2269.9	21.0843
2274.74	3.65705
2279.57	15.3939
2284.39	13.7808
2289.21	16.1194
2294.03	11.8004
2298.84	11.5136
2303.66	7.28467
2308.46	3.12402
2313.27	0.341301
2318.07	6.98035
2322.87	6.93501
2327.66	6.91591
2332.45	-1.19066
2337.24	11.0218
2342.02	2.92535
2346.8	11.2057
2351.58	14.0466
2356.35	15.4714
2361.12	3.0242
2365.89	9.83434
2370.65	13.9065
2375.41	2.73059
2380.17	-5.73738
2384.92	6.55448
2389.67	7.68958
2394.42	11.5525
2399.16	2.84057
2403.9	-0.314194
2408.64	7.6883
2413.37	13.1388
2418.1	-1.96664
2422.83	13.5352
2427.55	13.404
2432.27	11.9991
2436.99	9.22533
2441.7	6.43808
2446.41	6.48096
2451.11	12.2449
2455.82	7.99805
2460.51	8.04095
2465.21	12.4019
2469.9	0.868561
2474.59	9.5345
2479.28	3.74147
2483.96	5.16927
2488.64	2.18234
2493.32	6.48357
2497.99	7.88443
2502.66	12.1983
2507.32	3.27065
2511.99	1.64294
2516.65	22.0961
2521.3	5.74667
2525.96	15.9618
2530.61	9.91698
2535.25	9.82741
2539.89	15.7115
2544.53	-3.6895
2549.17	-0.757278
2553.8	9.66438
2558.43	2.08992
2563.06	17.0628
2567.68	6.55748
2572.3	8.10126
2576.92	3.57585
2581.53	3.52242
2586.14	6.4126
2590.75	9.22704
2595.35	12.1007
2599.96	1.33012
2604.55	19.4819
2609.15	5.57111
2613.74	17.5728
2618.33	12.778
2622.91	6.44733
2627.49	17.0078
2632.07	-1.47484
2636.64	18.5668
2641.22	7.92058
2645.78	25.1287
2650.35	22.2015
2654.91	22.3133
2659.47	12.8994
2664.03	15.9188
2668.58	12.6755
2673.13	17.3783
2677.67	27.09
2682.22	19.698
2686.76	20.1176
2691.29	15.6873
2695.83	10.9729
2700.36	20.5997
2704.89	18.9974
2709.41	23.8029
2713.93	20.5489
2718.45	15.7363
2722.96	9.23216
2727.47	4.25069
2731.98	5.6864
2736.49	29.8615
2740.99	26.4294
2745.49	16.5567
2749.98	19.7866
2754.47	1.96671
2758.96	16.6854
2763.45	24.8219
2767.93	5.10785
2772.41	13.3158
2776.89	15.0527
2781.36	18.5557
2785.84	10.4928
2790.3	19.0493
2794.77	15.9103
2799.23	21.0719
2803.69	16.1089
2808.14	14.4425
2812.59	9.3615
2817.04	16.0436
2821.49	19.3739
2825.93	4.07658
2830.37	19.2993
2834.81	3.90875
2839.24	17.4462
2843.67	7.14101
2848.1	8.82104
2852.53	13.9869
2856.95	3.78761
2861.37	17.6573
2865.78	-8.04198
2870.19	7.7014
2874.6	6.15421
2879.01	2.87866
2883.41	17.1207
2887.81	13.9212
2892.21	30.0434
2896.6	-1.43805
2901	21.9027
2905.38	13.254
2909.77	17.0181
2914.15	-4.36804
2918.53	4.6371
2922.91	6.52901
2927.28	6.68208
2931.65	24.9495
2936.02	16.0308
2940.38	21.5062
2944.74	17.8811
2949.1	15.9857
2953.46	3.15117
2957.81	10.3727
2962.16	21.2901
2966.5	13.9399
2970.85	12.1064
2975.19	32.3605
2979.52	26.8791
2983.86	41.7635
2988.19	25.3012
2992.52	32.9466
2996.85	12.7094
3001.17	42.8588
3005.49	24.5014
3009.8	21.0606
3014.12	32.6566
3018.43	33.059
3022.74	42.9573
3027.04	35.6363
3031.34	35.8351
3035.64	43.6002
3039.94	39.8602
3044.23	22.6486
3048.52	43.85
3052.81	45.821
3057.09	40.1028
3061.38	67.2623
3065.65	53.7872
3069.93	65.5203
3074.2	30.5908
3078.47	73.5538
3082.74	71.7386
3087	71.9756
3091.27	64.4783
3095.52	76.7346
3099.78	81.1915
3104.03	87.7164
3108.28	100.332
3112.53	85.1293
3116.77	107.903
3121.01	106.733
3125.25	99.5603
3129.49	122.887
3133.72	97.5072
3137.95	110.831
3142.18	122.112
3146.4	118.889
3150.62	138.396
3154.84	132.818
3159.06	145.969
3163.27	138.253
3167.48	153.523
3171.69	158.351
3175.89	129.267
3180.09	161.235
3184.29	157.169
3188.49	163.577
3192.68	155.301
3196.87	166.314
3201.06	175.689
3205.24	165.964
3209.42	169.225
3213.6	179.038
3217.78	143.437
3221.95	183.678
3226.12	160.819
3230.29	172.868
3234.45	158.501
3238.61	161.678
3242.77	142.824
3246.93	148.399
3251.08	138.074
3255.23	134.159
3259.38	130.267
3263.53	133.35
3267.67	127.923
3271.81	151.737
3275.95	136.372
3280.08	120.765
3284.21	134.906
3288.34	126.108
3292.47	140.264
3296.59	149.819
3300.71	129.47
3304.83	111.327
3308.95	146.482
3313.06	125.911
3317.17	135.583
3321.27	126.708
3325.38	120.252
3329.48	125.559
3333.58	140.592
3337.67	165.18
3341.77	132.741
3345.86	152.194
3349.95	143.072
3354.03	126.793
3358.11	165.504
3362.19	163.746
3366.27	147.544
3370.34	150.504
3374.42	153.374
3378.48	141.674
3382.55	158.865
3386.61	144.655
3390.68	159.395
3394.73	152.395
3398.79	143.069
3402.84	165.184
3406.89	170.259
3410.94	160.71
3414.98	143.827
3419.03	178.098
3423.06	170.932
3427.1	151.615
3431.14	147.037
3435.17	157.22
3439.2	150.388
3443.22	141.14
3447.25	156.651
3451.27	147.599
3455.28	136.16
3459.3	134.753
3463.31	140.857
3467.32	137.013
3471.33	143.117
3475.34	154.054
3479.34	142.488
3483.34	128.296
3487.33	141.903
3491.33	125.018
3495.32	130.938
3499.31	116.334
3503.3	114.371
3507.28	130.269
3511.26	97.2025
3515.24	94.8699
3519.22	89.9534
3523.19	90.1805
3527.16	75.0296
3531.13	101.059
3535.1	99.0796
3539.06	76.5883
3543.02	95.3814
3546.98	82.9983
3550.93	73.0731
3554.89	65.5019
3558.84	60.7066
3562.78	84.6595
3566.73	56.5792
3570.67	75.6146
3574.61	76.363
3578.55	93.0049
3582.48	94.0247
3586.41	68.6358
3590.35	58.9988
3594.27	51.9642
3598.2	60.8883
3602.12	51.0667
3606.04	35.8087
3609.95	44.5979
3613.87	39.9684
3617.78	46.071
3621.69	35.8826
3625.6	14.6992
3629.5	34.0457
3633.4	37.1254
3637.3	13.235
3641.2	19.2735
3645.09	17.2874
3648.98	26.0843
3652.87	4.86064
3656.76	2.66049
3660.64	3.18005
3664.53	6.4191
3668.4	12.4622
3672.28	4.8252
3676.16	-5.46416
3680.03	0.773361
3683.9	1.62396
3687.76	5.31764
3691.63	-10.3255
3695.49	-1.13451
3699.35	-11.3326
3703.2	-7.65509
3707.06	-15.1067
3710.91	2.64391
3714.76	-7.66222
3718.6	-18.0821
3722.45	-20.1034
3726.29	-22.1665
3730.13	-4.39757
3733.97	-29.1192
3737.8	-22.646
3741.63	0.921661
3745.46	-6.84566
3749.29	-20.3869
3753.11	0.325882
3756.93	-7.60376
3760.75	15.9327
3764.57	10.8202
3768.39	-11.4795
3772.2	15.0298
3776.01	1.37694
3779.81	-18.0099
3783.62	17.3281
3787.42	3.75314
3791.22	-18.557
3795.02	-0.378021
3798.81	0.524048
3802.61	-13.0776
3806.4	-9.24442
3810.18	0.439026
3813.97	-4.49706
3817.75	8.11331
3821.53	9.00824
3825.31	3.97568
3829.09	-4.01555
3832.86	8.65608
3836.63	12.4791
3840.4	10.3546
3844.17	17.1772
3847.93	-14.782
3851.69	9.6313
3855.45	1.33179
3859.21	1.87456
3862.96	23.2704
3866.71	6.23631
3870.46	16.1018
3874.21	13.7147
3877.95	11.3318
3881.69	5.95151
3885.44	9.56165
3889.17	4.20674
3892.91	-1.12604
3896.64	11.632
3900.37	-14.7634
3904.1	19.0327
3907.82	10.6315
3911.55	20.3651
3915.27	-0.149063
3918.99	-2.4922
3922.7	-1.76694
3926.42	5.01424
3930.13	14.8295
3933.84	0.0995026
3937.54	-8.60208
3941.25	4.19182
3944.95	10.9043
3948.65	2.17175
3952.35	8.76924
3956.04	-6.31311
3959.73	-9.12715
3963.42	-5.80637
3967.11	9.84827
3970.8	9.94171
3974.48	13.127
3978.16	6.96545
3981.84	16.2266
3985.52	13.0483
3989.19	16.0405
3992.86	15.9618
3996.53	6.597
3998.37	0.36319