File: Data/3-Raman/processed/bu19(2)w-a-ff1-fi05-v_150 (500nm)_532nm_edge_100%_x100_vis_lwd_h50um_30sx2_01.txt
#Acq. time (s)=	30
#Accumulations=	2
#Range (cm-¹)=	99...4000
#Windows=	1
#Auto scanning=	Off
#Autofocus=	Off
#Macrospot=	Off
#AutoExposure=	Off
#Spike filter=	Multiple accum.
#Delay time (s)=	2
#Binning=	1
#Readout mode=	Signal
#DeNoise=	Off
#ICS correction=	On
#Dark correction=	Off
#Inst. Process=	Off
#Detector Gain=	Best Dynamic
#Detector ADC=	50 kHz HS
#Detector temperature (°C)=	-60.09
#Instrument=	LabRAM HR Evol
#Detector=	SIN-EM FIVIS
#Objective=	x100_VIS_LWD
#Grating=	150 (500nm)
#ND Filter=	100%
#Laser=	532nm_Edge
#Hole=	49.98
#Temperature=	0
#Range=	Visible
#StageXY=	75x50mm Scan+
#StageZ=	Z motor
#X (µm)=	0
#Y (µm)=	0
#Z (µm)=	-9.7
#Full time(mm:ss)=	1:05
#Project=	21_11_26
#Sample=	BU19(2)w
#Site=
#Title=	BU19(2)w-A-FF1-FI05-V_150 (500nm)_532nm_Edge_100%_x100_VIS_LWD_H50um_30sX2
#Remark=
#Date=	26.11.2021 13:36
#Acquired=	26.11.2021 13:36:03
#Base:Fit=	16.12.2021 16:00:56
#Base:Edit=	16.12.2021 16:06:40
#Base:Edit=	16.12.2021 16:06:43
#Base:Sub=	16.12.2021 16:06:46
102.91	2248.24
107.534	3749.83
112.156	3770.12
116.775	2425.17
121.392	1303.27
126.005	1325.81
130.617	2158.31
135.227	4195.01
139.835	8325.88
144.439	12696.3
149.042	11819.4
153.643	7429.51
158.242	3937.75
162.839	2109.88
167.431	1155.14
172.023	568.811
176.613	264.666
181.198	63.604
185.783	-0.269653
190.366	-0.448364
194.947	218.438
199.524	789.725
204.1	2528.1
208.674	4096.26
213.243	2255.81
217.813	844.043
222.38	608.057
226.945	1508.29
231.506	3445.59
236.066	3521.98
240.625	1511.77
245.179	417.066
249.732	140.274
254.284	46.1246
258.831	0.413879
263.378	17.6782
267.923	18.8369
272.464	122.86
277.004	380.521
281.54	485.213
286.076	259.491
290.61	129.964
295.139	152.18
299.669	171.97
304.196	258.657
308.718	343.924
313.241	440.786
317.759	584.858
322.278	855.429
326.794	1406.32
331.305	1957.1
335.817	2010.07
340.324	1707.07
344.832	1979.85
349.334	2562.85
353.837	2410.5
358.338	1568.28
362.834	1179.78
367.33	1056.04
371.822	1164.15
376.314	1332.66
380.802	1862.13
385.289	3230.22
389.772	5329.08
394.255	6052.21
398.734	5251.08
403.213	4415.77
407.688	3569.82
412.162	3050.2
416.632	2962.52
421.102	3173.63
425.568	3628.63
430.033	3758.54
434.495	3626.24
438.956	3396.69
443.413	3570.89
447.87	3942.57
452.323	3930.42
456.776	3220.17
461.224	2341.69
465.673	1678.95
470.117	1389.94
474.561	1302.64
479.001	1349.98
483.438	1671.89
487.876	2145
492.309	2933.92
496.742	4127.29
501.172	5790.58
505.601	7291.83
510.025	8067.71
514.448	7509.92
518.871	6337.41
523.289	5200.8
527.707	4537.92
532.121	4288.27
536.533	4288
540.945	4388.54
545.353	4499.29
549.758	4399.17
554.164	3970.83
558.565	3537.3
562.965	2921.72
567.364	2303.31
571.759	1896.08
576.151	1670.65
580.544	1572.45
584.933	1668.87
589.319	1900.57
593.706	2352.88
598.088	2884.02
602.468	3578.73
606.848	5012.5
611.224	8108.56
615.598	13756
619.972	16792
624.341	12362.4
628.709	6946.25
633.074	4081.23
637.44	2594.63
641.801	1839.18
646.16	1313.52
650.517	995.316
654.874	749.785
659.227	600.569
663.578	478.949
667.927	372.336
672.275	283.1
676.62	279.813
680.962	237.218
685.302	237.327
689.643	337.847
693.979	441.567
698.313	629.599
702.645	746.7
706.975	661.215
711.305	490.557
715.631	355.885
719.955	314.446
724.276	280.458
728.596	217.532
732.913	145.62
737.231	57.3751
741.544	13.2131
745.856	18.2054
750.165	3.3208
754.472	0.16626
758.778	-15.628
763.081	3.54413
767.384	-2.28162
771.683	0.794006
775.98	1.94452
780.275	25.9244
784.568	29.088
788.859	54.9388
793.147	77.7086
797.434	75.8439
801.719	109.624
806.004	131.908
810.284	199.657
814.563	273.146
818.839	399.718
823.114	560.559
827.386	793.52
831.657	1117.32
835.925	1504.49
840.192	1851.27
844.456	2010.64
848.719	1864.67
852.979	1593.85
857.237	1312.4
861.493	1109.5
865.748	955.086
870	936.875
874.25	1054.64
878.499	1173.93
882.745	989.267
886.989	649.628
891.231	407.936
895.471	247.687
899.71	178.752
903.946	79.2487
908.18	93.7517
912.412	57.5914
916.642	42.6115
920.87	13.5753
925.096	23.2639
929.321	0.355286
933.543	13.8533
937.763	27.3361
941.981	16.0397
946.197	35.7781
950.412	58.7078
954.622	30.6826
958.832	61.4296
963.04	27.4246
967.246	59.4882
971.451	93.7775
975.653	86.8906
979.853	141.63
984.052	194.424
988.248	291.685
992.442	434.526
996.633	549.641
1000.82	636.068
1005.01	553.256
1009.2	459.839
1013.38	396.041
1017.57	357.428
1021.75	343.291
1025.92	387.667
1030.1	467.027
1034.27	638.008
1038.45	869.541
1042.62	1206.27
1046.78	1344.02
1050.95	1312.86
1055.12	1247.5
1059.28	1280.28
1063.44	1460.03
1067.6	1700.26
1071.75	2149.54
1075.91	2811.08
1080.06	3922.49
1084.21	5723.73
1088.36	8498.11
1092.51	10931.4
1096.65	10747.4
1100.8	7593.61
1104.94	4611.22
1109.08	2808.16
1113.21	1970.63
1117.35	1610.68
1121.48	1448.86
1125.61	1508.26
1129.74	1593.15
1133.87	2040.46
1137.99	2757.34
1142.12	3483.48
1146.24	3520.28
1150.36	2924.25
1154.48	2150.46
1158.59	1477.73
1162.71	1038.39
1166.82	799.731
1170.93	577.359
1175.04	434.238
1179.14	294.273
1183.25	263.624
1187.35	195.811
1191.45	139.088
1195.55	119.257
1199.65	104.43
1203.74	80.3661
1207.83	61.4814
1211.92	71.0973
1216.01	74.6469
1220.1	83.2864
1224.19	77.9126
1228.27	91.7522
1232.35	109.768
1236.43	118.201
1240.51	158.953
1244.58	341.306
1248.66	423.964
1252.73	237.515
1256.8	259.86
1260.87	368.3
1264.93	2729.62
1269	3335.47
1273.06	714.548
1277.12	214.112
1281.18	150.522
1285.23	124.894
1289.29	92.0565
1293.34	80.2362
1297.39	71.3254
1301.44	70.403
1305.49	90.5291
1309.53	58.1917
1313.58	65.088
1317.62	71.7868
1321.66	67.2774
1325.7	67.6077
1329.73	84.9402
1333.77	101.163
1337.8	82.0775
1341.83	107.978
1345.86	145.702
1349.88	198.215
1353.91	313.226
1357.93	279.846
1361.95	425.969
1365.97	971.582
1369.99	6318.79
1374	4115.67
1378.02	717.609
1382.03	271.886
1386.04	228.764
1390.05	424.957
1394.05	555.343
1398.06	189.866
1402.06	81.1341
1406.06	66.8776
1410.06	59.5281
1414.05	21.6129
1418.05	30.998
1422.04	3.83023
1426.03	4.21509
1430.02	7.35028
1434.01	-3.33578
1438	-3.19229
1441.98	-8.99631
1445.96	9.79926
1449.94	13.7355
1453.92	-12.9975
1457.9	-3.28751
1461.87	-16.3333
1465.85	-21.6121
1469.82	-17.0939
1473.78	-17.4743
1477.75	-14.977
1481.72	9.98331
1485.68	-9.1991
1489.65	1.91568
1493.61	-5.54041
1497.56	-1.29788
1501.52	-1.92316
1505.47	-26.8291
1509.43	0.845795
1513.38	4.19983
1517.33	10.4539
1521.27	3.12778
1525.22	7.44235
1529.16	8.84311
1533.11	-5.2533
1537.05	16.4984
1540.98	13.0304
1544.92	24.0733
1548.86	24.4308
1552.79	5.38654
1556.72	13.4045
1560.65	31.9932
1564.58	30.1826
1568.5	30.2508
1572.43	40.8996
1576.35	14.8077
1580.27	45.6507
1584.19	36.8811
1588.1	49.2724
1592.02	51.0224
1595.93	46.9701
1599.84	59.2386
1603.75	70.5322
1607.66	75.1261
1611.57	91.2083
1615.47	89.0681
1619.37	73.5485
1623.27	106.833
1627.17	77.9107
1631.07	80.6118
1634.97	93.9366
1638.86	89.9937
1642.75	79.4201
1646.64	77.514
1650.53	84.2491
1654.42	85.2323
1658.3	84.2444
1662.18	70.7304
1666.07	64.8044
1669.94	78.0442
1673.82	67.1246
1677.7	60.0114
1681.57	79.6056
1685.44	67.388
1689.31	35.9686
1693.18	47.6365
1697.05	61.1264
1700.92	53.495
1704.78	62.0136
1708.64	75.1744
1712.5	62.5554
1716.36	62.2976
1720.21	69.6072
1724.07	57.0623
1727.92	61.4809
1731.77	71.4519
1735.62	71.0794
1739.47	76.2707
1743.32	70.1842
1747.16	89.272
1751.01	85.2502
1754.85	95.2793
1758.69	97.1337
1762.52	95.8615
1766.36	92.4656
1770.19	79.9008
1774.02	78.6303
1777.85	69.9115
1781.68	49.1561
1785.51	47.0516
1789.33	42.1589
1793.16	41.9381
1796.98	48.2824
1800.8	40.526
1804.62	36.3093
1808.43	46.1788
1812.25	37.1691
1816.06	30.9145
1819.87	46.2212
1823.68	34.0815
1827.49	28.4868
1831.3	16.2103
1835.1	33.0795
1838.9	36.6878
1842.71	34.5958
1846.51	21.1646
1850.3	26.5581
1854.1	28.9896
1857.89	31.3341
1861.69	33.5732
1865.48	33.9051
1869.27	26.8349
1873.05	29.0883
1876.84	36.9386
1880.62	30.0107
1884.4	35.2086
1888.19	48.6885
1891.96	22.0032
1895.74	42.2662
1899.52	40.4408
1903.29	34.1432
1907.06	44.4715
1910.83	47.4707
1914.6	42.2885
1918.37	36.1947
1922.13	39.5202
1925.9	36.4035
1929.66	37.0398
1933.42	24.6882
1937.18	46.7558
1940.94	31.5571
1944.69	33.1305
1948.44	43.1462
1952.2	61.4017
1955.95	52.3315
1959.69	69.3938
1963.44	88.2296
1967.19	109.861
1970.93	116.348
1974.67	118.941
1978.41	128.013
1982.15	159.457
1985.89	172.998
1989.62	169.661
1993.35	176.514
1997.09	176.754
2000.82	161.143
2004.55	157.657
2008.27	147.678
2012	133.041
2015.72	135.044
2019.44	114.287
2023.16	115.799
2026.88	103.8
2030.6	94.5862
2034.31	80.9761
2038.03	70.2375
2041.74	72.2893
2045.45	71.575
2049.16	65.3802
2052.86	61.0851
2056.57	39.4071
2060.27	57.2872
2063.98	46.9451
2067.67	48.6066
2071.37	37.4053
2075.07	34.4812
2078.77	28.7992
2082.46	34.2405
2086.15	34.1012
2089.84	34.558
2093.53	28.3868
2097.22	23.2817
2100.9	26.4994
2104.59	18.4698
2108.27	24.3503
2111.95	40.4228
2115.63	12.793
2119.31	28.8312
2122.98	25.2477
2126.66	33.6786
2130.33	29.0829
2134	32.8089
2137.67	25.4241
2141.34	24.4816
2145	18.9014
2148.67	12.4106
2152.33	34.4116
2155.99	7.7718
2159.65	14.1862
2163.31	18.7935
2166.96	17.0495
2170.62	24.48
2174.27	17.4415
2177.92	9.56845
2181.57	6.29391
2185.22	13.9347
2188.87	11.6419
2192.51	12.184
2196.15	10.1066
2199.8	13.5546
2203.44	-7.57962
2207.07	5.06543
2210.71	-0.495651
2214.35	-0.540695
2217.98	7.68407
2221.61	4.92438
2225.24	-4.26451
2228.87	-6.12466
2232.5	-9.82597
2236.12	-9.81857
2239.75	-6.11171
2243.37	-6.10301
2246.99	0.400375
2250.61	12.5187
2254.23	-1.37752
2257.85	-3.16597
2261.46	5.32144
2265.07	-5.85414
2268.68	4.5354
2272.29	7.49991
2275.9	8.52937
2279.51	10.4414
2283.11	-4.78461
2286.72	-3.03529
2290.32	-0.337784
2293.92	5.17282
2297.52	0.29039
2301.11	6.77679
2304.71	15.1292
2308.3	16.8064
2311.9	170.118
2315.49	272.209
2319.08	67.1326
2322.66	21.2689
2326.25	16.968
2329.84	-0.578537
2333.42	12.1054
2337	7.75858
2340.58	10.929
2344.16	11.25
2347.73	4.03809
2351.31	16.5078
2354.88	8.35739
2358.45	4.89288
2362.03	18.1922
2365.59	9.13432
2369.16	4.76729
2372.73	6.02748
2376.29	5.4205
2379.85	12.2052
2383.41	8.86311
2386.97	9.23427
2390.53	4.13055
2394.09	8.25894
2397.64	1.44165
2401.2	7.53281
2404.75	12.8204
2408.3	-2.03131
2411.85	2.44933
2415.39	1.47511
2418.94	12.4917
2422.48	12.5215
2426.03	14.4412
2429.57	2.56868
2433.11	3.63651
2436.64	-1.74171
2440.18	7.73511
2443.72	3.29581
2447.25	6.30083
2450.78	11.2279
2454.31	4.946
2457.84	12.6043
2461.37	8.80083
2464.89	14.3911
2468.42	5.66208
2471.94	11.2373
2475.46	20.2514
2478.98	16.9559
2482.5	10.8657
2486.01	18.8307
2489.53	4.07677
2493.04	16.7004
2496.55	19.7948
2500.06	22.9475
2503.57	16.6638
2507.08	11.2948
2510.58	22.673
2514.09	13.5511
2517.59	15.6487
2521.09	6.63808
2524.59	16.9595
2528.09	24.6667
2531.59	21.3193
2535.08	11.537
2538.58	16.5788
2542.07	10.5839
2545.56	10.208
2549.05	15.4458
2552.54	5.90143
2556.02	16.7362
2559.51	14.709
2562.99	27.5192
2566.47	19.9911
2569.95	23.6673
2573.43	18.9886
2576.91	23.6826
2580.38	25.6079
2583.85	28.4867
2587.33	16.2332
2590.8	23.7662
2594.27	26.4668
2597.74	23.4158
2601.2	19.44
2604.67	23.0738
2608.13	21.8003
2611.59	13.6271
2615.06	12.0253
2618.51	13.3609
2621.97	28.0604
2625.43	26.3749
2628.88	28.4665
2632.33	17.0686
2635.79	21.9365
2639.24	16.1826
2642.69	26.6702
2646.13	4.57269
2649.58	15.9271
2653.02	20.5183
2656.47	17.4203
2659.91	24.724
2663.35	23.4372
2666.79	17.4001
2670.22	15.1436
2673.66	21.3365
2677.09	24.7029
2680.52	23.3885
2683.95	19.3039
2687.39	15.2852
2690.81	22.5674
2694.24	18.7118
2697.66	7.35814
2701.09	15.5868
2704.51	11.7066
2707.93	11.541
2711.35	13.3475
2714.77	14.248
2718.18	9.58401
2721.6	12.3886
2725.01	19.8722
2728.42	11.494
2731.84	13.3784
2735.24	15.2417
2738.65	6.78531
2742.06	-2.65112
2745.46	3.80856
2748.86	12.1179
2752.27	9.14204
2755.67	2.36751
2759.07	3.08176
2762.46	16.0303
2765.86	21.3861
2769.25	5.96628
2772.65	7.46136
2776.04	-1.43987
2779.43	5.62997
2782.82	7.94576
2786.2	8.34724
2789.59	5.90395
2792.98	0.620636
2796.36	11.2911
2799.74	5.97249
2803.12	-3.13727
2806.5	8.37376
2809.88	7.67038
2813.25	-9.9028
2816.63	8.98988
2820	11.0143
2823.37	13.0489
2826.74	10.4272
2830.11	11.5358
2833.48	6.13098
2836.84	10.9963
2840.21	-4.61523
2843.57	6.80966
2846.93	8.95174
2850.29	6.48888
2853.65	-10.8838
2857.01	-8.70166
2860.36	-2.76372
2863.72	14.4312
2867.07	1.66449
2870.42	1.99516
2873.77	9.81653
2877.12	-3.0547
2880.47	16.9789
2883.81	-1.60336
2887.16	1.44423
2890.5	0.703812
2893.84	7.49663
2897.18	12.3458
2900.52	16.211
2903.86	23.8163
2907.19	15.2983
2910.53	17.1551
2913.86	3.8421
2917.19	4.6953
2920.52	26.3152
2923.85	15.7433
2927.18	9.871
2930.51	10.5732
2933.83	16.9006
2937.15	21.2839
2940.48	20.9321
2943.8	21.5095
2947.11	13.6075
2950.43	22.6431
2953.75	20.3631
2957.06	17.1418
2960.38	19.5831
2963.69	12.647
2967	14.161
2970.31	20.423
2973.62	6.0836
2976.92	22.6954
2980.23	29.9615
2983.53	19.3599
2986.84	22.8405
2990.14	20.6947
2993.44	35.4538
2996.73	34.2558
3000.03	39.6433
3003.33	39.3809
3006.62	12.7692
3009.91	39.7973
3013.2	46.1424
3016.49	32.705
3019.78	40.9247
3023.07	51.0279
3026.35	68.6881
3029.64	52.3691
3032.92	60.587
3036.2	69.7379
3039.48	66.5878
3042.76	81.4087
3046.04	76.3666
3049.32	77.0003
3052.59	81.4193
3055.86	84.8997
3059.14	87.4164
3062.41	106.895
3065.68	113.148
3068.94	112.709
3072.21	123.574
3075.48	133.138
3078.74	139.3
3082	128.261
3085.26	135.578
3088.52	162.815
3091.78	158.86
3095.04	170.139
3098.29	176.101
3101.55	198.515
3104.8	209.435
3108.05	230.103
3111.3	219.307
3114.55	220.721
3117.8	257.406
3121.04	261.742
3124.29	288.94
3127.53	291.369
3130.77	285.206
3134.02	313.36
3137.25	327.209
3140.49	362.001
3143.73	327.195
3146.96	372.48
3150.2	391.12
3153.43	397.383
3156.66	424.607
3159.89	424.194
3163.12	458.108
3166.35	480.586
3169.57	498.225
3172.8	517.718
3176.02	523.818
3179.24	528.896
3182.46	560.674
3185.68	581.972
3188.9	580.277
3192.12	592.861
3195.33	618.779
3198.55	637.052
3201.76	665.771
3204.97	682.144
3208.18	670.946
3211.39	697.87
3214.6	744.839
3217.8	720.528
3221.01	734.281
3224.21	767.103
3227.41	783.871
3230.61	780.696
3233.81	799.498
3237.01	827.755
3240.21	840.106
3243.4	876.35
3246.59	879.351
3249.79	875.699
3252.98	887.432
3256.17	929.753
3259.36	977.832
3262.54	967.524
3265.73	958.945
3268.92	991.265
3272.1	997.674
3275.28	1045.09
3278.46	1071.47
3281.64	1050.77
3284.82	1068.02
3288	1124.41
3291.17	1102.45
3294.35	1179.76
3297.52	1158.83
3300.69	1192.23
3303.86	1228.83
3307.03	1261.2
3310.2	1329.52
3313.36	1350.94
3316.53	1383.64
3319.69	1410.55
3322.85	1444.01
3326.02	1455.65
3329.18	1525.02
3332.33	1625.53
3335.49	1617.4
3338.65	1736.92
3341.8	1785.69
3344.95	1867.48
3348.11	1843.25
3351.26	1923.28
3354.41	2015.53
3357.56	2131.64
3360.7	2158.35
3363.85	2249.51
3366.99	2323.82
3370.13	2379.45
3373.28	2464.52
3376.42	2517.9
3379.56	2632.87
3382.69	2729.23
3385.83	2875.66
3388.97	2955.38
3392.1	3062.72
3395.23	3126.45
3398.36	3298.32
3401.49	3461.07
3404.62	3605.49
3407.75	3804.75
3410.88	3927.64
3414	4138.27
3417.13	4379.67
3420.25	4703.14
3423.37	4969.36
3426.49	5197.55
3429.61	5629.24
3432.73	5910.37
3435.84	6278.07
3438.96	6816.88
3442.07	7405.97
3445.18	8198.82
3448.29	9450.1
3451.4	11694.4
3454.51	14572.9
3457.62	17259.1
3460.72	17205.6
3463.83	14834.1
3466.93	12304.1
3470.03	10646
3473.13	9536.48
3476.23	8884.96
3479.33	8543.53
3482.43	8414.88
3485.53	8324.47
3488.62	8214.03
3491.71	8289.14
3494.81	8291.07
3497.9	8281.4
3500.99	8300.4
3504.07	8446.91
3507.16	8554.2
3510.25	8804.52
3513.33	9083.68
3516.41	9470.62
3519.5	9955.75
3522.58	10491.2
3525.66	11124.3
3528.73	11839.7
3531.81	12545.6
3534.89	13157.6
3537.96	13385.5
3541.03	13195.6
3544.11	12347.8
3547.18	11101.1
3550.25	9688.64
3553.32	8114.85
3556.38	6862.23
3559.45	5813.94
3562.51	4917.8
3565.58	4164.59
3568.64	3642.36
3571.7	3201.59
3574.76	2856.49
3577.82	2581.65
3580.87	2289.45
3583.93	2085.26
3586.98	1926.4
3590.04	1820.68
3593.09	1657.86
3596.14	1551.02
3599.19	1442.18
3602.24	1380.81
3605.29	1321.21
3608.33	1229.39
3611.38	1153.75
3614.42	1079.08
3617.46	1091.36
3620.5	1050.86
3623.54	1007.65
3626.58	932.503
3629.62	887.686
3632.65	845.685
3635.69	817.809
3638.72	732.867
3641.76	713.058
3644.79	640.712
3647.82	615.685
3650.84	527.359
3653.87	502.221
3656.9	436.561
3659.92	422.563
3662.95	382.111
3665.97	334.873
3668.99	296.709
3672.01	290.746
3675.03	249.916
3678.05	222.307
3681.07	211.712
3684.08	175.568
3687.1	169.663
3690.11	142.961
3693.12	133.295
3696.13	132.162
3699.14	119.568
3702.15	98.5357
3705.16	67.0418
3708.16	73.5076
3711.17	74.2405
3714.17	52.13
3717.17	50.8904
3720.17	41.123
3723.17	27.5024
3726.17	8.14133
3729.17	-0.771759
3732.16	-8.74841
3735.16	-8.17688
3738.15	-20.9608
3741.14	-12.8158
3744.13	-12.3166
3747.13	-35.6113
3750.11	-31.3353
3753.1	-47.9766
3756.09	-44.6543
3759.07	-59.3472
3762.06	-56.954
3765.04	-55.5246
3768.02	-67.3385
3771	-50.7239
3773.98	-62.4687
3776.96	-64.7254
3779.94	-76.4098
3782.91	-76.731
3785.89	-69.4899
3788.86	-77.34
3791.83	-62.5171
3794.8	-69.3665
3797.77	-70.5326
3800.74	-73.572
3803.71	-75.6391
3806.68	-71.0847
3809.64	-92.9766
3812.61	-83.6838
3815.57	-80.9997
3818.53	-73.5812
3821.49	-71.8291
3824.45	-77.6486
3827.41	-78.7274
3830.36	-75.0706
3833.32	-75.2102
3836.27	-77.2345
3839.23	-81.1591
3842.18	-83.1956
3845.13	-78.5855
3848.08	-68.2607
3851.03	-68.4003
3853.98	-62.8172
3856.92	-68.683
3859.87	-59.2835
3862.81	-72.8225
3865.75	-59.6145
3868.7	-59.804
3871.64	-49.4797
3874.57	-57.3809
3877.51	-56.677
3880.45	-46.4041
3883.39	-47.6837
3886.32	-37.4689
3889.25	-33.0445
3892.18	-34.4098
3895.12	-44.4542
3898.05	-47.808
3900.97	-38.6961
3903.9	-44.0292
3906.83	-36.9013
3909.75	-37.4572
3912.68	-35.164
3915.6	-39.6318
3918.52	-44.1246
3921.44	-39.9579
3924.36	-35.8472
3927.28	-33.6973
3930.2	-34.4616
3933.11	-30.4599
3936.03	-27.392
3938.94	-31.0085
3941.86	-39.3972
3944.77	-33.4606
3947.68	-31.3652
3950.59	-31.1873
3953.49	-25.2731
3956.4	-27.9908
3959.31	-31.674
3962.21	-21.9589
3965.12	-29.5071
3968.02	-20.7731
3970.92	-11.0872
3973.82	-18.6902
3976.72	-8.08481
3979.61	-8.07738
3982.51	-22.5253
3985.41	-15.8631
3988.3	-7.31052
3991.19	-10.3293
3994.09	-13.3993
3996.98	-0.106079
3999.87	-1.274