File: Data/3-Raman/processed/bu19(2)w-a-ff2b-fi04-v_1800 (450-850nm)_532nm_edge_100%_x100_vis_lwd_h50um_30sx2_01.txt
#Acq. time (s)=	30
#Accumulations=	2
#Range (cm-¹)=	1200...2365
#Windows=	3
#Auto scanning=	Off
#Autofocus=	Off
#Macrospot=	Off
#AutoExposure=	Off
#Spike filter=	Multiple accum.
#Delay time (s)=	2
#Binning=	1
#Readout mode=	Signal
#DeNoise=	Off
#ICS correction=	On
#Dark correction=	Off
#Inst. Process=	Off
#Detector Gain=	Best Dynamic
#Detector ADC=	50 kHz HS
#Detector temperature (°C)=	-60.09
#Instrument=	LabRAM HR Evol
#Detector=	SIN-EM FIVIS
#Objective=	x50_VIS_LWD
#Grating=	1800 (450-850nm)
#ND Filter=	100%
#Laser=	532nm_Edge
#Hole=	49.98
#Temperature=	0
#Range=	Visible
#StageXY=	75x50mm Scan+
#StageZ=	Z motor
#X (µm)=	0
#Y (µm)=	0
#Z (µm)=	1.4
#Full time(mm:ss)=	3:22
#Project=	21_11_26
#Sample=	BU19(2)w
#Site=
#Title=	BU19(2)w-A-FF2b-FI01-V_1800 (450-850nm)_532nm_Edge_100%_x50_VIS_LWD_H50um_30sX2
#Remark=
#Date=	26.11.2021 14:41
#Acquired=	26.11.2021 14:41:45
#Base:Fit=	16.12.2021 16:00:56
#Base:Fit=	16.12.2021 16:10:06
#Base:Fit=	16.12.2021 16:10:07
#Base:Sub=	16.12.2021 16:10:08
1202.72	2.29826
1203.84	-1.71481
1204.95	7.11138
1206.06	1.91031
1207.17	6.33622
1208.28	3.28302
1209.39	-1.91545
1210.5	2.52291
1211.61	-2.71182
1212.72	2.71985
1213.83	-1.43629
1214.94	-0.244083
1216.05	-0.130688
1217.16	3.10912
1218.27	-3.21062
1219.38	1.10033
1220.49	-2.01903
1221.6	-0.900028
1222.71	0.169487
1223.81	-5.13571
1224.92	-0.906124
1226.03	-0.864162
1227.14	2.32748
1228.25	0.150307
1229.35	-3.07864
1230.46	-4.01823
1231.57	-0.960678
1232.67	3.24408
1233.78	1.13088
1234.89	-2.01372
1235.99	0.0938301
1237.1	-4.13651
1238.2	-1.05434
1239.31	-0.0767174
1240.41	5.12217
1241.52	-5.38739
1242.62	1.90057
1243.73	2.92513
1244.83	-0.259632
1245.94	6.9925
1247.04	-0.405071
1248.14	13.1437
1249.25	4.69869
1250.35	5.69455
1251.45	4.55756
1252.56	9.69436
1253.66	12.7372
1254.76	2.27331
1255.87	4.31472
1256.97	16.8041
1258.07	15.6913
1259.17	18.7384
1260.27	22.8999
1261.37	34.2498
1262.48	61.5431
1263.58	86.24
1264.68	40.5666
1265.78	25.8037
1266.88	19.4819
1267.98	14.2594
1269.08	11.1406
1270.18	8.99633
1271.28	17.2726
1272.38	18.2781
1273.47	17.2557
1274.57	13.0723
1275.67	14.0847
1276.77	21.4346
1277.87	21.4468
1278.97	41.4479
1280.07	60.3609
1281.16	147.634
1282.26	565.613
1283.36	1576.41
1284.45	589.02
1285.55	125.634
1286.65	53.98
1287.75	33.9175
1288.84	23.3528
1289.94	23.3727
1291.03	18.1076
1292.13	17.0332
1293.22	14.9114
1294.32	16.026
1295.42	7.59497
1296.51	7.69505
1297.61	7.68503
1298.7	6.59986
1299.79	7.63108
1300.89	6.59457
1301.98	2.38398
1303.08	3.4612
1304.17	6.6228
1305.26	8.7432
1306.35	3.44081
1307.45	0.286472
1308.54	1.36523
1309.63	3.51194
1310.73	3.54486
1311.82	5.69083
1312.91	0.464573
1314	-1.62729
1315.09	-4.75543
1316.18	-3.6424
1317.28	-1.49686
1318.37	-5.66752
1319.46	-1.39557
1320.55	-4.51771
1321.64	0.783836
1322.73	2.90602
1323.82	2.94353
1324.91	6.16495
1326	3.02981
1327.09	4.0684
1328.18	-1.06078
1329.27	5.38227
1330.35	2.27744
1331.44	0.200844
1332.53	-2.94616
1333.62	3.38248
1334.71	-1.8431
1335.79	-5.99593
1336.88	3.49661
1337.97	1.46268
1339.06	3.60583
1340.14	1.59323
1341.23	0.634682
1342.32	-5.57522
1343.4	5.98859
1344.49	-2.29222
1345.58	0.918026
1346.66	0.954159
1347.75	0.999966
1348.83	-2.04895
1349.92	0.105164
1351	2.25495
1352.09	6.48421
1353.17	1.41306
1354.25	0.516388
1355.34	-3.62758
1356.42	1.67003
1357.51	6.9501
1358.59	1.8406
1359.67	0.884827
1360.76	4.06643
1361.84	5.20098
1362.92	7.36852
1364	5.42657
1365.09	11.7538
1366.17	14.9315
1367.25	13.9571
1368.33	17.1741
1369.41	60.7327
1370.5	18.4461
1371.58	10.257
1372.66	11.3399
1373.74	12.4587
1374.82	14.626
1375.9	25.0494
1376.98	15.8769
1378.06	18.0409
1379.14	22.3783
1380.22	36.9002
1381.3	35.8464
1382.38	52.3336
1383.46	79.0043
1384.54	145.707
1385.61	454.893
1386.69	2609.17
1387.77	1336.23
1388.85	213.777
1389.93	93.2398
1391	62.4135
1392.08	47.0951
1393.16	28.732
1394.23	25.7659
1395.31	23.8443
1396.39	25.0147
1397.46	25.1126
1398.54	16.0223
1399.62	23.335
1400.69	19.3882
1401.77	21.5893
1402.84	23.8528
1403.92	23.0078
1404.99	27.1993
1406.07	41.6412
1407.14	83.7707
1408.22	165.953
1409.29	126.141
1410.37	43.212
1411.44	19.6909
1412.51	14.6831
1413.59	12.8826
1414.66	11.9269
1415.73	3.85739
1416.81	7.07303
1417.88	1.04906
1418.95	7.34322
1420.02	9.50999
1421.1	11.6515
1422.17	5.61436
1423.24	7.86942
1424.31	14.0123
1425.38	9.00487
1426.45	5.03043
1427.52	7.16124
1428.59	6.21759
1429.67	4.29554
1430.74	0.340296
1431.81	3.57306
1432.87	11.8738
1433.95	-1.39232
1435.01	0.778404
1436.08	2.93835
1437.15	4.06236
1438.22	-1.98232
1439.29	6.33122
1440.36	4.41439
1441.43	-0.597576
1442.49	1.55535
1443.56	4.73422
1444.63	1.75525
1445.7	3.93396
1446.77	-4.18044
1447.83	6.16364
1448.9	2.17158
1449.97	1.23994
1451.03	5.42303
1452.1	0.384541
1453.17	-0.545967
1454.23	3.65207
1455.3	-2.40489
1456.36	2.81832
1457.43	-3.25023
1458.49	-1.11526
1459.56	0.00325966
1460.62	-0.937092
1461.69	1.18615
1462.75	1.25219
1463.82	1.31146
1464.88	0.403608
1465.94	-0.615667
1467.01	0.477665
1468.07	-4.54689
1469.13	-1.41071
1470.2	1.70899
1471.26	-3.3227
1472.32	0.81389
1473.39	-5.22455
1474.45	5.0153
1475.51	2.04001
1476.57	-5.02078
1477.63	-3.94392
1478.69	1.2003
1479.76	-2.8133
1480.82	-4.80123
1481.88	5.40251
1482.94	-1.61694
1484	-0.532866
1485.06	-0.522963
1486.12	-0.468756
1487.18	2.63455
1488.24	-0.358849
1489.3	2.71468
1490.36	-0.270689
1491.42	-3.2615
1492.48	-2.19751
1493.53	1.89737
1494.59	-0.0721779
1495.65	0.97979
1496.71	-1.01413
1497.77	2.05673
1498.82	-0.923601
1499.88	0.139189
1500.94	0.187962
1502	-0.785652
1503.05	1.26727
1504.11	3.31422
1505.17	-0.673925
1506.22	0.353268
1507.28	-3.63443
1508.34	7.48915
1509.39	-1.54058
1510.45	0.516266
1511.5	1.537
1512.56	-3.50365
1513.61	-2.48871
1514.67	-0.431744
1515.72	-3.43109
1516.78	-3.41876
1517.83	0.619307
1518.88	0.65893
1519.94	3.7049
1520.99	-4.29599
1522.05	-2.25822
1523.1	2.77341
1524.15	4.77184
1525.2	1.77966
1526.26	3.81809
1527.31	-2.15821
1528.36	0.861544
1529.41	-0.128147
1530.47	-2.11743
1531.52	1.92488
1532.57	-1.06587
1533.62	1.98561
1534.67	3.01014
1535.72	3.014
1536.77	1.99101
1537.82	1.97786
1538.87	0.976509
1539.92	0.026268
1540.97	2.08437
1542.02	2.08005
1543.07	5.06907
1544.12	-1.95366
1545.17	2.07271
1546.22	-1.89903
1547.27	3.12359
1548.32	-0.887611
1549.37	0.107098
1550.42	-0.878798
1551.46	1.20329
1552.51	1.20966
1553.56	-1.81397
1554.61	1.18184
1555.65	2.16501
1556.7	3.16769
1557.75	-2.83618
1558.79	-3.8522
1559.84	0.125977
1560.89	-0.884537
1561.93	3.11861
1562.98	-3.86748
1564.02	2.12777
1565.07	4.14922
1566.11	5.9681
1567.16	-1.89976
1568.2	-0.885189
1569.25	0.117521
1570.29	-0.896984
1571.34	0.0982265
1572.38	3.07992
1573.43	-0.934162
1574.47	0.0569286
1575.51	1.07439
1576.56	3.0711
1577.6	2.03524
1578.64	0.00504112
1579.69	-0.00307274
1580.73	1.99173
1581.77	-1.01739
1582.81	0.954691
1583.85	-4.03801
1584.9	-1.05667
1585.94	0.926008
1586.98	0.898512
1588.02	-2.10444
1589.06	-8.07723
1590.1	3.86732
1591.14	-3.10544
1592.18	1.85908
1593.22	-4.1438
1594.26	0.784056
1595.3	1.77203
1596.34	1.7527
1597.38	0.751766
1598.42	-5.21792
1599.46	0.709383
1600.5	4.64885
1601.54	-5.30153
1602.58	2.58652
1603.62	-0.415106
1604.66	0.556883
1605.69	0.547745
1606.73	-0.441757
1607.77	-1.46274
1608.81	3.25416
1609.84	2.20014
1610.88	2.97614
1611.92	0.0869446
1612.95	0.212561
1613.99	-2.09127
1615.03	2.11207
1616.06	-3.09504
1617.1	0.638412
1618.13	-0.0295639
1619.17	1.58107
1620.2	0.782362
1621.24	0.0100403
1622.27	-0.369383
1623.31	-0.778639
1624.34	1.0021
1625.38	0.706564
1626.41	-2.51589
1627.45	-0.162514
1628.48	-0.245308
1629.51	0.276987
1630.55	-0.360369
1631.53	0.292994
1632.57	-1.67886
1633.62	-1.69135
1634.66	-4.65432
1635.71	-0.723991
1636.75	0.241869
1637.8	-1.75
1638.84	-0.781866
1639.89	2.161
1640.93	0.185947
1641.98	3.12964
1643.02	0.161747
1644.06	4.08535
1645.11	-3.80529
1646.15	0.126965
1647.19	1.0931
1648.24	0.0933571
1649.28	1.08836
1650.32	6.00056
1651.37	0.105824
1652.41	-1.86931
1653.45	2.0588
1654.49	-2.87148
1655.53	-0.899433
1656.57	-1.8726
1657.62	2.06837
1658.66	-1.8941
1659.7	1.04564
1660.74	1.03519
1661.78	-2.90201
1662.82	0.0761013
1663.86	-4.86769
1664.9	0.0517254
1665.94	-3.92672
1666.98	1.02667
1668.02	1.00873
1669.06	-1.95314
1670.1	2.99496
1671.14	2.01988
1672.18	-1.94268
1673.21	-0.956589
1674.25	1.02162
1675.29	-1.93753
1676.33	-2.92642
1677.37	0.0408726
1678.4	2.00546
1679.44	-0.979231
1680.48	-0.00159836
1681.52	-1.98775
1682.55	-1.00294
1683.59	-0.0188351
1684.63	2.93648
1685.66	0.954889
1686.7	-2.00727
1687.73	-0.028326
1688.77	-1.02653
1689.81	0.931215
1690.84	-1.04843
1691.88	-0.0546474
1692.91	-4.00466
1693.95	-0.0792236
1694.98	0.889482
1696.01	0.893064
1697.05	-1.07112
1698.08	-0.102324
1699.12	-0.116356
1700.15	0.867773
1701.18	-3.07197
1702.22	-0.13028
1703.25	-0.142057
1704.28	1.81911
1705.32	0.843203
1706.35	-1.12449
1707.38	2.78442
1708.41	-2.14219
1709.44	1.75323
1710.48	-0.206892
1711.51	0.783037
1712.54	-3.1298
1713.57	0.757311
1714.6	0.737556
1715.63	-2.18925
1716.66	-0.231905
1717.69	-3.18158
1718.72	1.66267
1719.75	-0.288872
1720.78	0.68845
1721.81	-1.27142
1722.84	-3.22995
1723.87	1.61701
1724.9	1.61514
1725.93	2.55796
1726.96	0.616621
1727.99	-1.32157
1729.02	1.54487
1730.05	0.561838
1731.07	0.555096
1732.1	1.55407
1733.13	-0.381105
1734.16	-1.36717
1735.18	-0.422174
1736.21	-0.435438
1737.24	-2.36244
1738.26	1.47998
1739.29	2.4281
1740.32	-2.39746
1741.34	1.42063
1742.37	0.454908
1743.4	-2.41559
1744.42	1.40952
1745.45	0.456247
1746.47	1.41219
1747.5	5.21636
1748.52	4.25408
1749.55	0.449324
1750.57	0.475574
1751.6	-1.41844
1752.62	3.34689
1753.64	3.33454
1754.67	2.37066
1755.69	-2.39847
1756.71	2.35454
1757.74	4.24098
1758.76	-1.45073
1759.78	-0.488066
1760.81	0.466755
1761.83	4.26475
1762.85	2.3708
1763.87	1.43213
1764.89	2.41016
1765.92	-2.32991
1766.94	-4.22589
1767.96	1.48841
1768.98	0.536873
1770	3.35544
1771.02	3.37802
1772.04	1.50613
1773.06	4.38313
1774.08	3.45203
1775.1	4.42183
1776.12	0.643585
1777.14	0.652981
1778.16	-1.25654
1779.18	1.59164
1780.2	0.645596
1781.22	1.61427
1782.24	1.63039
1783.26	-1.20378
1784.28	3.58307
1785.29	-1.16139
1786.31	-0.203398
1787.33	-2.09288
1788.35	-1.0916
1789.37	2.77743
1790.38	3.76639
1791.4	1.85555
1792.42	-1.02626
1793.43	-1.01105
1794.45	4.75139
1795.47	0.946867
1796.48	1.94049
1797.5	1.0062
1798.51	-1.85855
1799.53	1.99391
1800.55	-2.81689
1801.56	2.94912
1802.58	1.04092
1803.59	-2.78078
1804.61	-0.84071
1805.62	-0.815643
1806.64	3.06243
1807.65	3.07687
1808.66	1.15841
1809.68	2.13334
1810.69	3.10819
1811.7	2.14849
1812.72	0.231062
1813.73	2.17892
1814.74	-0.689842
1815.76	2.23189
1816.77	-1.62262
1817.78	-0.661087
1818.79	2.2477
1819.8	3.22783
1820.82	1.31142
1821.83	3.26395
1822.84	-4.4634
1823.85	0.382622
1824.86	-0.578548
1825.87	1.37154
1826.88	2.34716
1827.89	-0.546841
1828.9	2.36429
1829.91	0.425451
1830.92	3.32669
1831.93	-0.532967
1832.94	4.32944
1833.95	1.43303
1834.96	-1.48333
1835.97	1.3939
1836.98	2.44989
1837.99	-1.48961
1839	2.38391
1840	-0.487951
1841.01	1.41092
1842.02	4.27078
1843.03	2.32363
1844.04	2.32688
1845.04	3.29539
1846.05	0.410473
1847.06	-2.46406
1848.07	0.364706
1849.07	-0.591682
1850.08	1.31954
1851.09	1.29498
1852.09	-0.637808
1853.1	1.28333
1854.1	3.19605
1855.11	3.17287
1856.11	1.23568
1857.12	-0.681965
1858.12	0.269146
1859.13	2.16643
1860.13	0.239288
1861.14	0.248774
1862.14	-1.65338
1863.15	-0.709047
1864.15	-1.6818
1865.15	1.1686
1866.16	-0.766293
1867.16	-0.799786
1868.16	2.02744
1869.17	-1.77858
1870.17	0.118288
1871.17	-0.836498
1872.17	-1.79498
1873.18	2.93978
1874.18	1.03075
1875.18	-4.67994
1876.18	-1.86423
1877.18	0.951763
1878.18	-0.0254059
1879.19	-1.88584
1880.19	0.967281
1881.19	-1.87789
1882.19	-0.962255
1883.19	-0.0624466
1884.19	3.68239
1885.19	-3.85111
1886.19	-1.94481
1887.19	1.8255
1888.19	-0.0854359
1889.19	-0.116339
1890.19	-2.01402
1891.19	-1.06438
1892.18	-0.130711
1893.18	0.797598
1894.18	0.760965
1895.18	-2.07136
1896.18	0.749559
1897.18	1.69956
1898.17	3.5823
1899.17	-0.196854
1900.17	2.60298
1901.16	2.59747
1902.16	0.730013
1903.16	0.733009
1904.16	-2.10097
1905.15	0.710928
1906.15	-0.24258
1907.14	2.55493
1908.14	2.55235
1909.14	1.61712
1910.13	-1.18989
1911.13	0.711243
1912.12	-0.230473
1913.12	1.64391
1914.11	5.41777
1915.11	1.66411
1916.1	0.722679
1917.1	0.705898
1918.09	-0.253578
1919.08	-0.246634
1920.08	0.719984
1921.07	0.717455
1922.06	-0.217447
1923.06	1.66411
1924.05	0.702951
1925.04	-0.258871
1926.04	-4.03329
1927.03	-2.12852
1928.02	1.66456
1929.01	3.56219
1930	0.730255
1931	-2.10187
1931.99	-1.16161
1932.98	-1.17986
1933.97	0.714188
1934.96	0.768839
1935.95	-2.05274
1936.94	1.73381
1937.93	-0.197052
1938.92	-0.205313
1939.91	1.70436
1940.9	0.759443
1941.89	-1.13647
1942.88	1.72852
1943.87	-0.199865
1944.86	-1.1472
1945.85	-0.179699
1946.84	1.73966
1947.83	-0.183428
1948.82	2.67526
1949.8	1.72645
1950.79	-1.1236
1951.78	0.818825
1952.77	-2.05193
1953.76	-1.09625
1954.74	-3.06211
1955.73	-0.204189
1956.72	-0.176216
1957.7	2.71828
1958.69	-0.16003
1959.68	-3.05617
1960.66	4.61106
1961.65	1.70752
1962.63	3.62098
1963.62	-1.18143
1964.61	-0.22151
1965.59	-0.230434
1966.58	-2.14723
1967.56	1.70002
1968.55	2.65915
1969.53	-2.16418
1970.52	0.688351
1971.5	3.54743
1972.48	1.62263
1973.47	3.53004
1974.45	2.5503
1975.44	1.58786
1976.42	1.59385
1977.4	1.58994
1978.39	4.44937
1979.37	0.602114
1980.35	2.51591
1981.33	2.49817
1982.31	-0.388683
1983.3	3.42262
1984.28	1.48783
1985.26	1.47269
1986.24	3.37241
1987.22	-1.40458
1988.21	4.3097
1989.19	4.27428
1990.17	5.13625
1991.15	5.17026
1992.13	2.94533
1993.11	3.57377
1994.09	6.19977
1995.07	2.95259
1996.05	4.32224
1997.03	5.46184
1998.01	5.28
1998.99	6.72477
1999.97	5.7806
2000.95	6.07775
2001.92	7.91456
2002.9	6.52308
2003.88	6.39438
2004.86	5.97303
2005.84	5.97447
2006.81	7.13646
2007.79	6.0301
2008.77	6.58752
2009.75	7.46888
2010.73	7.31182
2011.7	10.9451
2012.68	6.50241
2013.67	7.41638
2014.66	4.55846
2015.64	5.49035
2016.63	7.38308
2017.62	8.34472
2018.61	6.43411
2019.6	6.39904
2020.58	5.45533
2021.57	6.39717
2022.56	2.64894
2023.55	6.37495
2024.54	3.55346
2025.52	0.727362
2026.51	3.51394
2027.5	5.45077
2028.48	4.49314
2029.47	5.4729
2030.45	3.53682
2031.44	3.5533
2032.43	2.63027
2033.41	4.53451
2034.4	0.805273
2035.38	5.4472
2036.37	0.831593
2037.35	4.57293
2038.34	-0.100573
2039.32	0.828993
2040.31	2.6861
2041.29	3.60446
2042.27	5.46603
2043.26	2.66867
2044.24	1.77029
2045.23	-1.0306
2046.21	2.75313
2047.19	0.874537
2048.17	-0.0745316
2049.16	-0.992802
2050.14	-0.0292225
2051.12	1.86364
2052.11	1.86109
2053.09	0.00997734
2054.07	1.91142
2055.05	-0.877655
2056.03	1.92877
2057.01	2.86714
2058	-3.6615
2058.98	1.03996
2059.96	1.06071
2060.94	3.87188
2061.92	1.08393
2062.9	-0.772892
2063.88	-1.68694
2064.86	3.0191
2065.84	0.237206
2066.82	-0.677748
2067.8	2.16094
2068.78	1.24333
2069.76	1.25016
2070.73	1.2607
2071.71	-2.47436
2072.69	-0.554926
2073.67	0.396074
2074.65	0.413893
2075.63	1.39432
2076.6	-2.34584
2077.58	-1.39744
2078.56	-0.444984
2079.54	0.522842
2080.51	0.55624
2081.49	-2.26516
2082.47	-1.30656
2083.45	1.54476
2084.42	-2.22244
2085.4	-0.317633
2086.37	0.648016
2087.35	0.677532
2088.32	2.59031
2089.3	-4.0175
2090.28	2.63791
2091.25	-1.1307
2092.23	-1.10241
2093.2	-0.115665
2094.18	-0.0828476
2095.15	0.886395
2096.13	-2.91064
2097.1	0.899708
2098.07	-1.94556
2099.05	-1.93474
2100.02	-1.92221
2101	1.89297
2101.97	0.971352
2102.94	-1.86428
2103.92	0.040926
2104.89	1.00941
2105.86	-1.81216
2106.83	0.11202
2107.8	2.9805
2108.78	-0.824757
2109.75	-0.809378
2110.72	2.05972
2111.69	-1.72625
2112.66	3.03207
2113.63	-0.741074
2114.61	1.17768
2115.58	-2.60859
2116.55	-2.60052
2117.52	-0.692173
2118.49	0.265417
2119.46	-2.58298
2120.43	2.15817
2121.4	-0.665258
2122.37	-0.634186
2123.34	0.340603
2124.31	0.354315
2125.28	0.344788
2126.25	0.333748
2127.21	-1.55988
2128.18	3.17506
2129.15	-0.594799
2130.12	1.30576
2131.09	-1.51966
2132.06	1.31803
2133.02	2.26449
2133.99	2.27818
2134.96	1.34987
2135.93	-1.47078
2136.89	1.35579
2137.86	0.430998
2138.83	-1.44699
2139.79	-2.37208
2140.76	1.39643
2141.73	-2.36219
2142.69	-2.35694
2143.66	0.494574
2144.62	0.471022
2145.59	-0.455263
2146.55	-1.38568
2147.52	-1.37968
2148.48	0.503372
2149.45	-1.37281
2150.42	-0.442238
2151.38	-0.43433
2152.34	-1.3515
2153.31	-2.28272
2154.27	1.46912
2155.24	1.45321
2156.2	0.504366
2157.16	-2.29363
2158.13	-0.407316
2159.09	0.540884
2160.05	-0.393269
2161.01	-2.26536
2161.98	-3.19356
2162.94	-2.25134
2163.9	1.48184
2164.86	2.40975
2165.83	-1.30826
2166.79	0.561104
2167.75	-0.374151
2168.71	0.5403
2169.67	0.555885
2170.63	-0.343977
2171.59	1.52165
2172.56	-2.21997
2173.51	-1.28847
2174.48	-0.346783
2175.44	-1.26808
2176.4	-2.19357
2177.36	0.595581
2178.32	-0.325418
2179.28	1.52782
2180.23	-1.24999
2181.19	-1.24651
2182.15	0.610273
2183.11	0.609207
2184.07	1.52469
2185.03	0.597328
2185.99	1.53622
2186.95	-2.15415
2187.9	0.653828
2188.86	-0.27779
2189.82	-0.292023
2190.78	-0.295525
2191.73	-0.287868
2192.69	3.43181
2193.65	-3.9773
2194.6	-2.09539
2195.56	1.62362
2196.52	1.60688
2197.47	1.59138
2198.43	-0.261936
2199.38	-1.16908
2200.34	6.29688
2201.3	0.749041
2202.25	-1.16768
2203.21	-2.06873
2204.16	0.7887
2205.12	0.755724
2206.07	2.57153
2207.03	-3.00796
2207.98	2.58191
2208.93	2.59801
2209.89	-0.190096
2210.84	0.745504
2211.8	0.756287
2212.75	0.767105
2213.7	-0.174644
2214.66	-0.167833
2215.61	2.64228
2216.56	-1.09316
2217.51	-2.03098
2218.47	-0.165174
2219.42	2.64244
2220.37	0.78093
2221.32	-0.160427
2222.27	-0.179749
2223.23	-0.182211
2224.18	-1.10562
2225.13	-0.156445
2226.08	-2.01644
2227.03	-1.07108
2227.98	-0.128778
2228.93	-0.137636
2229.88	-2.9543
2230.83	-1.06946
2231.78	-1.05976
2232.73	1.76844
2233.68	2.71828
2234.63	-1.04426
2235.58	0.818947
2236.53	-2.0108
2237.48	0.81181
2238.43	-1.05285
2239.38	2.73447
2240.33	-1.99558
2241.27	1.77863
2242.22	2.72112
2243.17	1.77747
2244.12	0.819231
2245.07	-0.12343
2246.01	-2.94519
2246.96	-0.104147
2247.91	0.843151
2248.85	0.83246
2249.8	2.71832
2250.75	0.81444
2251.69	-2.04367
2252.64	-0.155802
2253.59	-1.08492
2254.53	-0.129169
2255.48	-0.134825
2256.42	0.810587
2257.37	-0.133129
2258.32	-1.08172
2259.26	-1.08349
2260.2	-0.133179
2261.15	-1.08358
2262.1	-1.08043
2263.04	-2.98329
2263.98	-0.114267
2264.93	1.81253
2265.87	-1.04743
2266.81	-1.06309
2267.76	0.824528
2268.7	-0.147594
2269.65	-3.00558
2270.59	-1.08337
2271.53	2.74604
2272.47	-1.07566
2273.42	1.79117
2274.36	-2.99656
2275.3	0.829536
2276.24	0.827665
2277.18	-2.99533
2278.13	-1.0621
2279.07	-2.9777
2280.01	0.84458
2280.95	-3.01508
2281.89	0.806105
2282.83	-3.02505
2283.77	-3.97308
2284.71	0.853346
2285.65	-0.101301
2286.59	0.84539
2287.54	-0.100895
2288.47	-1.05994
2289.41	1.81085
2290.35	-2.06366
2291.29	-1.1043
2292.23	0.834726
2293.17	7.59111
2294.11	2.78242
2295.05	-1.08434
2295.99	-2.05863
2296.93	-0.149242
2297.86	-3.02718
2298.8	0.841431
2299.74	-3.0012
2300.68	-0.10671
2301.61	0.868067
2302.55	-2.9928
2303.49	-0.0987911
2304.43	0.872547
2305.36	-1.04645
2306.3	0.894449
2307.24	0.899939
2308.17	-0.0699711
2309.11	-0.0694618
2310.04	0.916891
2310.98	0.92654
2311.92	-0.064846
2312.85	-1.04216
2313.79	0.897978
2314.72	-1.00544
2315.66	1.91245
2316.59	-0.0387478
2317.52	0.926229
2318.46	-0.029541
2319.39	-0.998693
2320.33	3.82809
2321.26	0.946606
2322.2	4.83578
2323.13	4.85937
2324.06	12.6103
2325	15.5113
2325.93	23.21
2326.86	73.3581
2327.79	292.139
2328.73	69.4328
2329.66	14.4842
2330.59	3.89916
2331.52	2.94596
2332.46	-1.85161
2333.39	3.92901
2334.32	-1.84108
2335.25	1.04765
2336.18	-0.860422
2337.11	1.07388
2338.04	-0.836956
2338.97	-1.78514
2339.91	1.11549
2340.84	-0.799095
2341.77	-2.72113
2342.7	0.161106
2343.63	-1.74118
2344.56	1.15314
2345.49	1.16897
2346.41	-0.742258
2347.34	-0.727196
2348.27	-0.707539
2349.2	0.272001
2350.13	4.08988
2351.06	1.1532
2351.99	-0.661734
2352.91	1.24205
2353.84	1.23643
2354.77	1.25879
2355.7	1.28176
2356.63	-2.5176
2357.55	0.339079
2358.48	3.20281
2359.41	-0.58403
2360.33	-0.570881
2361.26	0.384811
2362.19	-1.50537
2363.11	1.34217
2364.04	0.408375
2364.97	-0.524364