File: Data/3-Raman/processed/bu19w-d-ff2-fi05-v_150 (500nm)_532nm_edge_100%_x100_vis_h50um_15sx2_01_0.txt
#Acq. time (s)=	15
#Accumulations=	2
#Range (cm-¹)=	100...5000
#Windows=	1
#Auto scanning=	Off
#Autofocus=	Off
#Macrospot=	Off
#AutoExposure=	Off
#Spike filter=	Multiple accum.
#Delay time (s)=	2
#Binning=	1
#Readout mode=	Signal
#DeNoise=	Off
#ICS correction=	On
#Dark correction=	Off
#Inst. Process=	Off
#Detector Gain=	Best Dynamic
#Detector ADC=	50 kHz HS
#Detector temperature (°C)=	-60.09
#Instrument=	LabRAM HR Evol
#Detector=	SIN-EM FIVIS
#Objective=	x100_VIS
#Grating=	150 (500nm)
#ND Filter=	100%
#Laser=	532nm_Edge
#Hole=	49.98
#Temperature=	0
#Range=	Visible
#StageXY=	75x50mm Scan+
#StageZ=	Z motor
#X (µm)=	0
#Y (µm)=	0
#Z (µm)=	-14.8
#Full time(s)=	34
#Project=	21_05_14
#Sample=	BU19w
#Site=
#Title=	BU19w-FF2-FI05-V_150 (500nm)_532nm_Edge_100%_x100_VIS_H50um_15sX2
#Remark=
#Date=	14.05.2021 17:54
#Acquired=	14.05.2021 17:54:31
#Base:Fit=	16.12.2021 17:39:50
#Base:Edit=	16.12.2021 18:01:50
#Base:Sub=	16.12.2021 18:01:52
102.699	1028.05
107.322	822.284
111.942	646.459
116.56	556.471
121.173	509.65
125.787	438.667
130.398	426.304
135.006	322.72
139.613	293.304
144.215	274.859
148.817	397.421
153.417	843.608
158.014	960.784
162.607	425.083
167.2	162.891
171.79	159.124
176.379	234.873
180.963	671.417
185.547	909.65
190.128	457.901
194.705	198.049
199.282	93.4154
203.857	58.2824
208.43	35.2572
212.998	-1.34363
217.566	21.8583
222.132	68.1461
226.693	254.697
231.254	369.928
235.813	431.228
240.368	906.919
244.923	770.828
249.475	359.295
254.023	210.146
258.571	143.821
263.117	269.531
267.658	703.17
272.199	1861.3
276.738	2185.18
281.273	1242.77
285.807	556.985
290.34	315.27
294.868	353.518
299.396	460.13
303.919	331.518
308.443	234.69
312.964	215.905
317.481	344.35
321.998	624.036
326.51	736.707
331.023	443.542
335.533	335.561
340.039	527.24
344.544	879.189
349.046	817.056
353.547	476.376
358.045	285.834
362.542	383.182
367.036	445.82
371.527	267.002
376.017	167.179
380.503	196.287
384.99	245.346
389.471	345.926
393.953	273.687
398.43	171.905
402.908	131.798
407.381	202.963
411.854	415.121
416.323	457.024
420.791	202.397
425.256	63.2754
429.72	44.0061
434.18	25.6431
438.64	6.33044
443.095	33.9877
447.551	107.27
452.003	157.45
456.454	122.026
460.901	122.547
465.348	75.0532
469.791	95.9234
474.231	103.748
478.672	160.828
483.108	287.658
487.544	360.939
491.976	422.275
496.408	391.221
500.836	259.077
505.261	220.085
509.687	153.199
514.108	112.994
518.529	85.519
522.946	64.137
527.361	62.4042
531.776	49.2728
536.187	36.1379
540.595	70.4633
545.003	100.152
549.408	118.276
553.812	158.164
558.212	100.747
562.61	89.8248
567.007	46.4541
571.401	111.073
575.792	143.406
580.184	354.729
584.571	683.993
588.956	592.057
593.341	284.043
597.722	202.139
602.101	343.343
606.48	510.06
610.854	417.161
615.227	236.275
619.597	131.56
623.967	82.2448
628.334	86.4117
632.698	142.192
637.06	159.521
641.422	158.578
645.779	138.943
650.135	154.493
654.491	265.863
658.842	416.044
663.192	503.179
667.539	533.071
671.884	554.502
676.23	501.462
680.571	325.227
684.91	168.937
689.247	107.531
693.583	61.0464
697.916	16.8718
702.247	18.0893
706.576	36.9494
710.902	21.5103
715.229	14.6071
719.551	24.9409
723.872	5.18384
728.19	-2.58215
732.506	14.9371
736.82	-1.0448
741.134	-16.0291
745.444	32.4938
749.752	24.4495
754.058	46.2282
758.362	109.363
762.664	169.002
766.964	309.083
771.264	512.736
775.559	606.009
779.853	440.208
784.144	274.737
788.434	135.65
792.722	103.335
797.007	66.8515
801.29	34.2449
805.572	30.5561
809.851	11.5759
814.13	36.7242
818.406	33.2355
822.679	-22.919
826.95	7.93958
831.219	23.4398
835.486	-6.28668
839.752	32.3075
844.015	26.6646
848.276	5.14069
852.535	-4.2851
856.792	29.2756
861.047	21.9881
865.3	23.3032
869.551	5.80627
873.8	18.9141
878.047	13.2548
882.292	15.0391
886.534	6.73547
890.775	8.8125
895.014	4.90125
899.251	-10.1351
903.486	-7.14984
907.719	-0.975159
911.95	17.4969
916.179	33.6284
920.406	13.0587
924.63	29.4134
928.853	85.2702
933.074	82.0569
937.293	125.772
941.51	225.966
945.723	312.849
949.936	303.753
954.147	181.91
958.356	143.439
962.563	151.89
966.768	126.415
970.971	100.107
975.172	87.6639
979.371	61.6339
983.568	39.9014
987.761	54.0588
991.954	11.4722
996.145	33.938
1000.33	35.413
1004.52	42.2742
1008.71	33.3436
1012.89	53.9788
1017.07	70.387
1021.25	71.8632
1025.43	83.6524
1029.6	112.562
1033.77	152.514
1037.95	263.095
1042.11	460.777
1046.28	878.531
1050.45	1045.13
1054.61	763.785
1058.77	468.673
1062.93	298.944
1067.09	248.774
1071.24	294.942
1075.4	366.034
1079.55	581.687
1083.7	921.21
1087.85	1076
1091.99	954.399
1096.14	749.041
1100.28	705.672
1104.42	969.17
1108.55	1032.25
1112.69	860.054
1116.82	733.989
1120.96	731.134
1125.09	867.466
1129.21	909.97
1133.34	787.241
1137.46	552.775
1141.59	476.371
1145.71	455.181
1149.83	522.008
1153.94	693.53
1158.06	628.681
1162.17	498.272
1166.28	451.29
1170.39	369.904
1174.5	242.026
1178.6	126.68
1182.7	117.451
1186.8	75.8885
1190.9	114.192
1195	90.7736
1199.1	83.5448
1203.19	85.4103
1207.28	87.2659
1211.37	106.348
1215.46	200.962
1219.54	254.009
1223.63	230.612
1227.71	168.608
1231.79	204.095
1235.87	284.491
1239.95	235.59
1244.02	214.826
1248.09	286.499
1252.16	204.633
1256.23	137.823
1260.3	140.037
1264.36	314.518
1268.43	1512.56
1272.49	972.983
1276.55	221.249
1280.6	76.0279
1284.66	75.2112
1288.71	64.3053
1292.76	68.338
1296.81	69.3206
1300.86	62.122
1304.91	66.8969
1308.95	52.546
1312.99	52.0784
1317.03	52.394
1321.07	60.6831
1325.11	64.5653
1329.14	93.6827
1333.18	61.2709
1337.21	64.8527
1341.24	66.3419
1345.26	64.7836
1349.29	97.0986
1353.31	136.274
1357.33	123.718
1361.35	179.517
1365.37	250.196
1369.39	1022.83
1373.4	2601.78
1377.41	898.481
1381.43	169.473
1385.43	100.029
1389.44	134.035
1393.45	259.927
1397.45	158.558
1401.45	88.4742
1405.45	49.9731
1409.45	35.1612
1413.44	48.9871
1417.44	27.2748
1421.43	31.1788
1425.42	21.0399
1429.41	9.70197
1433.39	11.3686
1437.38	17.8699
1441.36	-4.23859
1445.34	14.9817
1449.32	33.1829
1453.3	7.84338
1457.27	10.0757
1461.24	22.9479
1465.22	-4.66418
1469.19	13.0371
1473.15	-20.3118
1477.12	21.7584
1481.09	0.0528564
1485.05	7.68494
1489.01	3.57758
1492.97	-8.26733
1496.93	16.9428
1500.88	11.0724
1504.83	-1.45148
1508.79	39.6024
1512.74	36.9154
1516.68	6.15784
1520.63	15.2563
1524.57	-7.61432
1528.52	12.2504
1532.46	17.6215
1536.4	16.2073
1540.33	8.99878
1544.27	18.258
1548.2	8.14349
1552.14	13.49
1556.07	5.17358
1559.99	35.4955
1563.92	40.5703
1567.84	30.1129
1571.77	19.6418
1575.69	28.4775
1579.61	48.8451
1583.52	30.6006
1587.44	35.4529
1591.35	21.0505
1595.27	18.1985
1599.18	12.5006
1603.09	15.5315
1606.99	26.2944
1610.9	25.5562
1614.8	31.6064
1618.7	47.2564
1622.6	53.3286
1626.5	26.9896
1630.39	46.7327
1634.29	36.9209
1638.18	29.0417
1642.07	20.4072
1645.96	42.5135
1649.85	24.4063
1653.73	29.2947
1657.62	8.2016
1661.5	29.3
1665.38	15.6913
1669.26	36.5605
1673.13	31.3286
1677.01	22.081
1680.88	14.4514
1684.75	0.0562744
1688.62	26.7985
1692.49	11.2426
1696.35	10.9253
1700.22	56.2738
1704.08	16.5573
1707.94	22.4736
1711.8	24.5089
1715.66	0.0713501
1719.51	37.1429
1723.37	22.197
1727.22	21.3258
1731.07	7.29572
1734.92	15.8011
1738.76	16.6924
1742.61	28.7477
1746.45	17.7531
1750.29	31.2909
1754.13	0.559692
1757.97	15.1611
1761.81	-5.19672
1765.64	-5.40192
1769.47	38.48
1773.31	13.7325
1777.14	8.59827
1780.96	7.36926
1784.79	23.0288
1788.61	21.9434
1792.43	23.6871
1796.25	25.4269
1800.07	-16.3563
1803.89	2.72314
1807.71	18.9891
1811.52	26.6823
1815.33	14.3502
1819.14	-7.66235
1822.95	6.995
1826.76	36.5807
1830.56	53.6959
1834.37	29.2079
1838.17	7.48334
1841.97	22.3167
1845.77	18.3218
1849.56	17.0243
1853.36	10.7867
1857.15	27.7313
1860.94	4.4151
1864.73	16.5294
1868.52	21.2513
1872.31	24.2122
1876.09	16.1703
1879.87	38.7654
1883.66	1.59009
1887.43	14.618
1891.21	32.6213
1894.99	22.9678
1898.76	16.2574
1902.53	31.8539
1906.31	7.9436
1910.08	28.4191
1913.84	0.171936
1917.61	35.8705
1921.37	9.91284
1925.14	21.9567
1928.9	16.4858
1932.66	30.5591
1936.41	32.5357
1940.17	41.0451
1943.92	-0.856384
1947.68	-1.26508
1951.43	16.8538
1955.18	14.9585
1958.92	25.8675
1962.67	17.9326
1966.41	17.436
1970.16	-2.16949
1973.9	14.6848
1977.64	27.6202
1981.37	7.70374
1985.11	39.0618
1988.84	31.1266
1992.57	33.2789
1996.31	22.3143
2000.03	16.8602
2003.76	13.3754
2007.49	39.1752
2011.21	14.2057
2014.93	40.0319
2018.65	24.064
2022.37	20.3492
2026.09	46.3159
2029.81	29.1077
2033.52	29.9667
2037.23	4.08112
2040.94	31.3381
2044.65	-3.76471
2048.36	29.0379
2052.07	6.0733
2055.77	29.949
2059.47	25.9907
2063.17	50.7525
2066.87	33.3273
2070.57	14.9422
2074.27	26.0797
2077.96	27.1539
2081.65	27.2827
2085.34	21.4181
2089.03	30.4265
2092.72	37.0128
2096.41	48.4003
2100.09	12.9302
2103.77	16.4092
2107.46	5.81671
2111.14	27.7097
2114.81	34.7
2118.49	21.9637
2122.16	40.5305
2125.84	5.23828
2129.51	46.7493
2133.18	11.3901
2136.85	0.0410156
2140.51	35.6189
2144.18	13.9476
2147.84	48.3799
2151.5	39.5929
2155.16	6.15027
2158.82	34.1182
2162.48	19.2164
2166.13	41.8508
2169.79	35.4929
2173.44	7.58417
2177.09	36.1849
2180.74	45.7245
2184.38	31.6183
2188.03	12.3953
2191.67	20.7056
2195.32	42.9479
2198.96	51.623
2202.6	20.2697
2206.23	20.0327
2209.87	55.5947
2213.5	2.43658
2217.14	28.0657
2220.77	46.4511
2224.4	22.5485
2228.03	17.8901
2231.65	22.5276
2235.28	30.901
2238.9	29.9965
2242.52	42.0745
2246.14	32.8042
2249.76	18.9288
2253.38	13.4729
2256.99	16.432
2260.6	16.5287
2264.21	22.2316
2267.82	37.5129
2271.44	26.4987
2275.04	40.6077
2278.65	41.2615
2282.25	2.84906
2285.85	41.0716
2289.45	17.7599
2293.05	17.1028
2296.65	52.471
2300.25	39.5167
2303.84	13.1145
2307.43	32.0807
2311.02	67.0719
2314.62	345.524
2318.2	226.645
2321.79	34.6038
2325.38	22.2939
2328.96	46.8823
2332.54	10.89
2336.12	26.7373
2339.7	22.6924
2343.28	39.2448
2346.85	30.3556
2350.43	24.2747
2354	5.10498
2357.57	20.4444
2361.14	36.6246
2364.71	35.1327
2368.27	13.3857
2371.84	42.6686
2375.4	23.7654
2378.96	27.1409
2382.52	33.349
2386.08	22.1711
2389.64	14.8386
2393.19	12.2856
2396.75	2.64233
2400.3	44.6332
2403.85	60.3201
2407.4	23.8907
2410.95	25.3417
2414.49	13.1441
2418.04	11.1934
2421.58	19.4934
2425.12	19.7071
2428.66	21.9272
2432.2	40.9744
2435.74	33.3041
2439.27	46.1201
2442.81	34.7865
2446.34	7.58142
2449.87	14.1434
2453.4	37.4655
2456.93	24.4655
2460.45	28.0727
2463.98	10.673
2467.5	32.8058
2471.02	43.4872
2474.54	30.5717
2478.06	50.9376
2481.58	41.9397
2485.09	6.21014
2488.61	43.8561
2492.12	12.9852
2495.63	19.4966
2499.14	35.4661
2502.65	18.4099
2506.15	5.98395
2509.66	30.783
2513.16	-4.76355
2516.66	23.0532
2520.16	15.2471
2523.66	14.3175
2527.16	22.9756
2530.66	30.7912
2534.15	19.4278
2537.64	3.60175
2541.13	13.9073
2544.62	11.6665
2548.11	15.0353
2551.6	10.1914
2555.08	32.6022
2558.57	7.77228
2562.05	2.64838
2565.53	16.3698
2569.01	32.2271
2572.49	31.457
2575.96	0.78418
2579.44	20.8602
2582.91	15.5755
2586.38	38.5978
2589.85	15.7641
2593.32	41.1288
2596.79	30.5476
2600.25	8.4939
2603.72	-7.25995
2607.18	4.2746
2610.64	-2.18085
2614.1	30.0801
2617.56	36.171
2621.02	35.3941
2624.47	9.43066
2627.92	24.6661
2631.38	5.18866
2634.83	28.6697
2638.28	13.6643
2641.72	30.0933
2645.17	34.0319
2648.61	17.7905
2652.06	17.609
2655.5	30.557
2658.94	31.0483
2662.38	18.2063
2665.82	37.5042
2669.25	19.9222
2672.69	19.4298
2676.12	38.7091
2679.55	24.3968
2682.98	4.71033
2686.41	28.3954
2689.84	6.82343
2693.26	-2.81189
2696.69	28.6567
2700.11	28.5801
2703.53	8.80701
2706.95	20.2776
2710.37	12.4089
2713.79	8.39398
2717.2	9.17694
2720.62	36.1866
2724.03	17.5598
2727.44	38.2275
2730.85	-0.053833
2734.26	-0.0161133
2737.66	18.7877
2741.07	22.4885
2744.47	22.2929
2747.87	29.6288
2751.28	15.3235
2754.67	35.6799
2758.07	16.6033
2761.47	12.3809
2764.86	9.94733
2768.26	2.65759
2771.65	29.2551
2775.04	14.2764
2778.43	7.67346
2781.82	-1.80798
2785.2	26.3193
2788.59	41.2471
2791.97	33.5445
2795.35	6.20587
2798.73	15.3449
2802.11	44.1666
2805.49	29.8483
2808.87	15.5134
2812.24	12.4
2815.62	40.997
2818.99	13.6311
2822.36	43.3348
2825.73	21.7711
2829.1	46.9008
2832.46	23.7081
2835.83	37.901
2839.19	4.72125
2842.55	42.4876
2845.91	6.84949
2849.27	36.8021
2852.63	17.1489
2855.99	29.3268
2859.34	48.1976
2862.69	24.9747
2866.05	18.6216
2869.4	46.0072
2872.75	25.4849
2876.09	28.4239
2879.44	47.3779
2882.78	31.4239
2886.13	21.995
2889.47	19.2139
2892.81	31.3489
2896.15	37.7314
2899.49	28.8742
2902.82	23.6938
2906.16	43.0681
2909.49	22.6233
2912.82	36.2449
2916.16	33.6505
2919.49	62.2205
2922.81	34.0244
2926.14	42.5727
2929.46	48.2471
2932.79	36.7627
2936.11	38.5016
2939.43	44.0099
2942.75	58.936
2946.07	69.1866
2949.39	46.4929
2952.7	32.2632
2956.02	1.26715
2959.33	31.4171
2962.64	50.2636
2965.95	43.0009
2969.26	50.0923
2972.57	60.8107
2975.87	59.6185
2979.17	71.4113
2982.48	38.1956
2985.78	62.2898
2989.08	69.5162
2992.38	35.4439
2995.68	38.0515
2998.97	59.4797
3002.27	68.6606
3005.56	64.7465
3008.85	72.1655
3012.14	84.3424
3015.43	72.9474
3018.72	64.3563
3022	59.527
3025.29	66.9855
3028.57	55.5571
3031.85	59.2091
3035.14	66.6115
3038.41	68.3539
3041.69	86.1924
3044.97	79.4601
3048.24	82.1675
3051.52	88.7122
3054.79	94.2989
3058.06	84.6244
3061.33	56.742
3064.6	114.326
3067.87	116.777
3071.13	93.0289
3074.4	108.568
3077.66	146.861
3080.92	108.777
3084.18	109.716
3087.44	115.542
3090.7	133.906
3093.95	116.342
3097.21	152.117
3100.46	131.809
3103.71	141.22
3106.96	161.15
3110.21	127.553
3113.46	150.097
3116.71	184.115
3119.95	172.437
3123.2	164.558
3126.44	208.107
3129.68	199.262
3132.92	205.655
3136.16	171.973
3139.4	191.652
3142.63	231.354
3145.87	218.666
3149.1	216.5
3152.33	227.661
3155.56	251.241
3158.79	251.913
3162.02	269.764
3165.25	261.793
3168.47	291.924
3171.69	311.516
3174.92	310.997
3178.14	288.504
3181.36	315.642
3184.58	327.432
3187.79	366.813
3191.01	325.159
3194.22	341.638
3197.43	334.273
3200.65	322.181
3203.86	326.312
3207.07	386.628
3210.27	357.547
3213.48	377.069
3216.69	348.09
3219.89	387.625
3223.09	371.128
3226.29	388.912
3229.49	408.688
3232.69	395.097
3235.89	392.141
3239.08	425.463
3242.28	430.297
3245.47	418.941
3248.66	422.915
3251.85	413.589
3255.04	433.848
3258.23	422.5
3261.42	429.147
3264.6	410.81
3267.79	409.55
3270.97	435.914
3274.15	435.532
3277.33	454.084
3280.51	442.803
3283.68	461.107
3286.86	461.182
3290.04	481.342
3293.21	429.062
3296.38	492.974
3299.55	467.625
3302.72	457.338
3305.89	472.614
3309.06	490.559
3312.22	485.59
3315.39	523.303
3318.55	522.035
3321.71	504.668
3324.87	529.932
3328.03	548.551
3331.19	529.41
3334.34	533.999
3337.5	520.754
3340.65	555.63
3343.81	559.58
3346.96	573.295
3350.11	538.957
3353.25	570.716
3356.4	565.775
3359.55	588.318
3362.69	594.883
3365.84	614.72
3368.98	630.83
3372.12	650.869
3375.26	655.883
3378.4	634.537
3381.53	678.324
3384.67	696.715
3387.8	694.332
3390.94	701.481
3394.07	702.442
3397.2	728.681
3400.33	757.089
3403.46	842.66
3406.58	909.491
3409.71	1117.37
3412.83	1726.25
3415.96	3259.55
3419.08	4753.87
3422.2	3556.7
3425.32	1866.06
3428.44	1150.09
3431.55	950.289
3434.67	857.937
3437.78	813.467
3440.89	732.832
3444	725.397
3447.12	727.48
3450.22	715.056
3453.33	724.539
3456.44	718.589
3459.54	750.644
3462.65	716.084
3465.75	729.894
3468.85	739.48
3471.95	746.587
3475.05	818.178
3478.15	846.222
3481.24	902.609
3484.34	999.62
3487.43	1150.45
3490.53	1371.56
3493.62	1691.7
3496.71	2093.47
3499.79	2351.9
3502.88	2388.03
3505.97	2013.55
3509.05	1617.93
3512.14	1263.12
3515.22	1033.45
3518.3	867.229
3521.38	767.199
3524.46	682.539
3527.54	594.197
3530.61	586.83
3533.69	547.689
3536.76	533.843
3539.83	497.154
3542.9	463.747
3545.97	454.846
3549.04	403.251
3552.11	398.696
3555.18	400.908
3558.24	339.791
3561.3	380.706
3564.37	367.562
3567.43	344.973
3570.49	331.701
3573.55	331.6
3576.61	307.751
3579.66	282.883
3582.72	284.495
3585.77	286.085
3588.82	288.546
3591.87	295.702
3594.92	244.989
3597.97	233.131
3601.02	263.833
3604.07	248.065
3607.11	207.702
3610.16	228.798
3613.2	221.492
3616.24	224.597
3619.28	204.145
3622.32	191.286
3625.36	154.92
3628.39	186.407
3631.43	191.447
3634.46	185.307
3637.5	130.364
3640.53	131.021
3643.56	157.248
3646.59	149.5
3649.62	122.076
3652.64	124.999
3655.67	136.302
3658.69	109.409
3661.72	119.122
3664.74	104.07
3667.76	103.174
3670.78	73.1
3673.79	84.551
3676.81	75.2788
3679.83	67.8671
3682.84	60.4414
3685.86	61.5352
3688.87	63.5934
3691.88	46.726
3694.89	68.6023
3697.9	64.0149
3700.91	42.3721
3703.91	34.9441
3706.92	55.0138
3709.92	25.6184
3712.92	37.9774
3715.92	46.557
3718.92	42.7273
3721.92	8.37671
3724.92	36.8125
3727.92	29.0274
3730.91	27.8602
3733.91	10.4475
3736.9	14.8899
3739.89	5.9472
3742.88	43.5778
3745.87	6.96045
3748.86	5.49857
3751.85	13.5173
3754.83	6.3533
3757.82	24.8013
3760.8	12.8572
3763.78	25.5498
3766.76	23.1148
3769.74	21.6758
3772.72	21.2258
3775.7	45.3792
3778.67	31.7629
3781.65	16.2792
3784.62	44.2592
3787.6	35.4391
3790.57	21.9763
3793.54	15.1744
3796.51	7.45676
3799.47	28.1207
3802.44	-11.6082
3805.41	19.5043
3808.37	6.25037
3811.33	33.6544
3814.3	10.0187
3817.26	17.6072
3820.22	8.17242
3823.18	14.8623
3826.13	4.51297
3829.09	21.6451
3832.04	17.0086
3835	20.9449
3837.95	2.08472
3840.9	2.21143
3843.85	30.8946
3846.8	15.824
3849.75	7.42871
3852.69	6.66479
3855.64	9.72342
3858.58	5.14951
3861.53	31.1519
3864.47	26.558
3867.41	28.627
3870.35	21.0884
3873.29	6.80585
3876.22	17.4187
3879.16	6.85883
3882.1	16.4106
3885.03	26.8853
3887.96	24.8416
3890.89	33.3561
3893.82	23.5459
3896.75	30.9795
3899.68	22.0524
3902.61	22.6711
3905.53	32.9489
3908.46	41.2769
3911.38	17.8486
3914.3	27.0327
3917.23	21.8968
3920.15	26.3014
3923.06	27.7594
3925.98	20.5384
3928.9	19.9855
3931.81	11.8575
3934.73	11.4915
3937.64	17.938
3940.55	38.7175
3943.46	30.778
3946.37	22.8832
3949.28	20.7729
3952.19	34.9592
3955.09	40.5711
3958	22.2582
3960.9	25.9988
3963.8	44.1501
3966.71	25.8892
3969.61	38.3411
3972.51	42.1582
3975.4	21.9363
3978.3	26.646
3981.2	36.1542
3984.09	-6.28061
3986.99	22.4311
3989.88	33.7588
3992.77	19.1918
3995.66	23.8668
3998.55	26.6391
4001.43	21.7134
4004.32	24.5136
4007.21	10.9417
4010.09	36.8818
4012.98	19.4389
4015.86	38.6497
4018.74	10.5704
4021.62	17.2324
4024.5	26.807
4027.37	24.7908
4030.25	16.0159
4033.13	14.0043
4036	33.3043
4038.87	23.5764
4041.75	32.1708
4044.62	28.1645
4047.49	-3.93127
4050.35	23.1291
4053.22	21.1374
4056.09	24.0088
4058.95	14.2263
4061.82	29.6994
4064.68	35.4625
4067.54	20.793
4070.4	30.4365
4073.26	28.3963
4076.12	34.1378
4078.98	39.8816
4081.83	35.8788
4084.69	22.1054
4087.54	16.1127
4090.4	36.4933
4093.25	28.5631
4096.1	4.00327
4098.95	36.1315
4101.8	32.082
4104.64	28.9706
4107.49	17.0255
4110.33	29.5222
4113.18	26.3052
4116.02	21.0787
4118.86	35.3972
4121.7	25.2902
4124.54	18.1487
4127.38	24.7719
4130.22	28.5598
4133.05	23.6231
4135.89	22.3687
4138.72	23.5344
4141.56	26.8285
4144.39	42.2868
4147.22	47.0186
4150.05	33.1039
4152.88	25.8936
4155.7	25.3674
4158.53	20.9346
4161.36	32.2864
4164.18	20.1613
4167	33.4725
4169.82	35.0711
4172.65	31.7955
4175.46	37.3241
4178.28	4.72995
4181.1	22.038
4183.92	20.7791
4186.73	43.9972
4189.55	49.6498
4192.36	27.9511
4195.17	46.4469
4197.98	26.7509
4200.79	59.0111
4203.6	50.0904
4206.41	47.0421
4209.21	44.9693
4212.02	23.2172
4214.83	28.1396
4217.63	24.3157
4220.43	41.1281
4223.23	39.1724
4226.03	30.3096
4228.83	21.4776
4231.63	41.3676
4234.42	36.5585
4237.22	18.8409
4240.01	30.9056
4242.81	43.019
4245.6	28.2471
4248.39	38.3466
4251.18	30.4583
4253.97	39.5303
4256.76	37.5809
4259.55	-1.45834
4262.33	27.6822
4265.12	13.6975
4267.9	29.8714
4270.68	25.9203
4273.47	30.9824
4276.25	11.7509
4279.03	27.809
4281.8	16.5573
4284.58	29.5203
4287.36	26.2542
4290.13	18.906
4292.91	26.7712
4295.68	26.5815
4298.45	51.7323
4301.22	41.3694
4303.99	29.9793
4306.76	24.6801
4309.53	33.6347
4312.3	27.3216
4315.06	21.9618
4317.83	35.9066
4320.59	25.3944
4323.35	25.0332
4326.11	30.7823
4328.87	40.5894
4331.63	21.8638
4334.39	23.502
4337.15	27.1994
4339.9	19.7248
4342.66	33.6754
4345.41	30.3347
4348.17	23.9422
4350.92	26.792
4353.67	23.5361
4356.42	20.2447
4359.17	23.0787
4361.91	12.6136
4364.66	27.7473
4367.41	15.222
4370.15	12.9183
4372.89	24.9381
4375.63	25.6559
4378.38	35.5956
4381.12	33.2244
4383.86	29.8849
4386.59	36.9565
4389.33	26.6277
4392.07	43.2929
4394.8	37.2332
4397.53	26.847
4400.27	14.3541
4403	26.7179
4405.73	30.822
4408.46	29.7136
4411.19	47.2802
4413.92	38.8013
4416.64	39.5879
4419.37	27.8303
4422.09	39.0764
4424.82	37.8073
4427.54	35.4899
4430.26	19.5619
4432.98	39.1887
4435.7	44.1545
4438.42	14.5063
4441.13	33.0536
4443.85	22.2332
4446.57	11.3889
4449.28	47.7742
4451.99	22.1843
4454.71	32.2856
4457.42	13.9838
4460.13	10.4152
4462.83	21.5847
4465.54	19.0876
4468.25	25.0292
4470.95	16.2535
4473.66	26.4702
4476.36	48.3294
4479.07	28.0252
4481.77	28.8209
4484.47	12.6837
4487.17	26.1328
4489.87	37.4204
4492.56	15.7621
4495.26	28.0692
4497.96	23.4385
4500.65	30.3965
4503.34	28.9203
4506.04	30.6398
4508.73	28.1159
4511.42	19.2248
4514.11	17.773
4516.8	14.1914
4519.48	26.6005
4522.17	26.2654
4524.85	15.2674
4527.54	20.2451
4530.22	20.9683
4532.9	16.3762
4535.58	18.1779
4538.27	7.20364
4540.94	18.6432
4543.62	34.397
4546.3	15.9125
4548.98	35.9843
4551.65	15.4095
4554.33	14.1344
4557	18.3495
4559.67	11.8589
4562.34	19.4364
4565.01	30.4804
4567.68	32.7877
4570.35	21.6649
4573.02	16.7264
4575.68	10.8935
4578.35	30.1381
4581.01	0.681519
4583.67	2.48608
4586.34	10.8244
4589	21.3134
4591.66	8.87109
4594.31	18.3613
4596.97	15.7504
4599.63	-2.10257
4602.29	28.2174
4604.94	20.2352
4607.59	6.76697
4610.25	21.8037
4612.9	18.1761
4615.55	15.6496
4618.2	3.23947
4620.85	20.5498
4623.5	20.2195
4626.14	11.0295
4628.79	4.04141
4631.43	15.786
4634.08	23.0824
4636.72	12.6849
4639.36	11.1073
4642	6.26785
4644.64	18.1425
4647.28	15.6755
4649.92	23.301
4652.56	28.8841
4655.19	10.3649
4657.83	7.75085
4660.46	25.303
4663.1	25.0151
4665.73	23.4664
4668.36	14.1253
4670.99	-0.842316
4673.62	12.1929
4676.24	16.2665
4678.87	2.36737
4681.5	3.05389
4684.12	5.99319
4686.75	22.4337
4689.37	15.2728
4691.99	14.8274
4694.61	23.3921
4697.23	26.3322
4699.85	-2.33997
4702.47	16.3719
4705.09	18.1398
4707.7	14.2378
4710.32	22.7749
4712.93	22.2578
4715.55	33.0372
4718.16	9.84253
4720.77	13.7856
4723.38	4.17276
4725.99	20.6684
4728.6	26.9672
4731.21	21.9189
4733.81	25.9526
4736.42	25.4097
4739.02	16.913
4741.63	27.7047
4744.23	-2.45157
4746.83	20.7933
4749.43	23.5714
4752.03	18.3837
4754.63	18.8693
4757.23	10.2734
4759.82	13.0923
4762.42	5.66281
4765.01	-4.00262
4767.61	20.6138
4770.2	15.5001
4772.79	18.375
4775.38	15.5503
4777.97	13.8577
4780.56	21.3064
4783.15	15.0475
4785.74	12.2131
4788.32	34.5578
4790.91	6.56595
4793.49	9.47253
4796.07	10.1233
4798.66	22.2655
4801.24	29.8526
4803.82	11.0538
4806.4	3.76312
4808.98	17.1691
4811.55	20.2471
4814.13	14.1077
4816.71	10.3006
4819.28	0.692261
4821.85	11.917
4824.43	-0.0268555
4827	8.88321
4829.57	2.74429
4832.14	17.543
4834.71	21.9254
4837.28	12.3322
4839.84	-0.789642
4842.41	7.08188
4844.97	-3.82855
4847.54	6.34375
4850.1	16.3617
4852.66	20.3414
4855.22	5.91568
4857.78	12.6646
4860.34	17.0157
4862.9	14.1727
4865.46	4.17996
4868.01	16.7825
4870.57	26.97
4873.12	19.3387
4875.68	25.9357
4878.23	26.5922
4880.78	9.40923
4883.33	4.08438
4885.88	13.0259
4888.43	26.7478
4890.98	13.0867
4893.53	14.8913
4896.07	10.7234
4898.62	12.5137
4901.16	13.0972
4903.7	30.4063
4906.25	8.28253
4908.79	-1.93425
4911.33	12.8913
4913.87	13.3642
4916.41	7.87083
4918.94	16.7267
4921.48	6.46605
4924.02	33.2614
4926.55	14.6333
4929.08	15.1526
4931.62	8.55986
4934.15	7.94206
4936.68	13.2904
4939.21	5.40282
4941.74	-4.87389
4944.27	20.8468
4946.79	20.2321
4949.32	7.63458
4951.85	28.6011
4954.37	13.5982
4956.9	14.2245
4959.42	6.45929
4961.94	2.34053
4964.46	6.69849
4966.98	11.0371
4969.5	5.68773
4972.02	18.4393
4974.53	19.1176
4977.05	7.70349
4979.57	-2.51401
4982.08	12.7068
4984.59	2.48528
4987.1	4.39171
4989.62	16.0209
4992.13	26.4452
4994.64	13.772
4997.15	13.2908
4999.65	23.7975