File: Data/3-Raman/processed/bu19w-a-ff07b-fi06-v_1800 (450-850nm)_532nm_edge_100%_x100_vis_lwd_h50um_60sx2_01.txt
#Acq. time (s)=	60
#Accumulations=	2
#Range (cm-¹)=	1220...2360
#Windows=	3
#Auto scanning=	Off
#Autofocus=	Off
#Macrospot=	Off
#AutoExposure=	Off
#Spike filter=	Multiple accum.
#Delay time (s)=	2
#Binning=	1
#Readout mode=	Signal
#DeNoise=	Off
#ICS correction=	On
#Dark correction=	Off
#Inst. Process=	Off
#Detector Gain=	Best Dynamic
#Detector ADC=	50 kHz HS
#Detector temperature (°C)=	-60.09
#Instrument=	LabRAM HR Evol
#Detector=	SIN-EM FIVIS
#Objective=	x100_VIS_LWD
#Grating=	1800 (450-850nm)
#ND Filter=	100%
#Laser=	532nm_Edge
#Hole=	49.98
#Temperature=	0
#Range=	Visible
#StageXY=	75x50mm Scan+
#StageZ=	Z motor
#X (µm)=	0
#Y (µm)=	0
#Z (µm)=	-27
#Full time(mm:ss)=	6:18
#Project=	21_05_28
#Sample=	BU19w
#Site=
#Title=	BU19w-FF07b-FI06-V_1800 (450-850nm)_532nm_Edge_100%_x100_VIS_LWD_H50um_60sX2
#Remark=
#Date=	28.05.2021 16:25
#Acquired=	28.05.2021 16:25:46
#Base:Fit=	16.12.2021 17:39:50
#Base:Fit=	16.12.2021 17:58:48
#Base:Sub=	16.12.2021 17:58:49
1220.15	3.48888
1220.98	-12.8325
1221.81	-1.58965
1222.64	-12.6456
1223.48	-4.5827
1224.31	-0.628571
1225.14	-8.12422
1225.97	-10.1581
1226.8	0.421036
1227.63	16.0632
1228.46	2.17375
1229.29	16.4511
1230.12	17.8291
1230.95	47.4768
1231.78	62.2197
1232.61	92.0589
1233.44	93.577
1234.27	104.718
1235.1	77.0631
1235.93	63.0794
1236.76	42.6846
1237.59	35.8704
1238.42	18.5888
1239.25	29.7857
1240.08	7.55348
1240.91	20.0096
1241.74	21.9531
1242.57	30.2688
1243.4	21.9096
1244.23	41.847
1245.05	26.0783
1245.88	61.5491
1246.71	71.0277
1247.54	93.1086
1248.37	84.7157
1249.19	104.811
1250.02	133.244
1250.85	138.491
1251.68	156.348
1252.51	105.301
1253.33	137.831
1254.16	110.114
1254.99	89.6837
1255.81	83.8162
1256.64	54.0089
1257.47	42.9147
1258.29	53.7497
1259.12	18.6503
1259.95	20.3074
1260.77	21.6817
1261.6	34.6915
1262.43	52.5091
1263.25	58.6258
1264.08	80.7475
1264.9	45.6558
1265.73	25.2906
1266.56	-6.45885
1267.38	-10.9542
1268.21	3.4624
1269.03	-1.01656
1269.86	-4.59497
1270.68	-18.7212
1271.51	-7.6488
1272.33	-8.96358
1273.16	-11.2793
1273.98	-15.7085
1274.81	-1.35399
1275.63	-10.0447
1276.45	-1.89288
1277.28	3.11917
1278.1	-7.61139
1278.93	10.042
1279.75	5.50613
1280.57	29.3663
1281.4	74.4353
1282.22	233.13
1283.04	619.67
1283.87	1496.87
1284.69	1233.64
1285.51	282.451
1286.34	80.0477
1287.16	43.8881
1287.98	8.76689
1288.8	26.3703
1289.63	1.93829
1290.45	8.00108
1291.27	4.50316
1292.09	-4.23862
1292.91	-0.351959
1293.74	0.514862
1294.56	-0.782104
1295.38	-4.17862
1296.2	-8.49168
1297.02	-8.82631
1297.84	3.42949
1298.66	-4.32922
1299.48	0.543121
1300.31	-0.808273
1301.13	9.39317
1301.95	4.88052
1302.77	-2.85817
1303.59	-1.15462
1304.41	0.592422
1305.23	0.174927
1306.05	-16.1198
1306.87	11.9472
1307.69	5.24979
1308.51	4.86023
1309.33	3.46417
1310.15	-2.18893
1310.97	-9.98123
1311.79	-7.20193
1312.61	-4.40694
1313.43	8.85892
1314.25	-2.14984
1315.06	-7.82745
1315.88	7.61679
1316.7	1.86116
1317.52	7.75859
1318.34	2.03635
1319.16	14.2385
1319.98	4.2507
1320.79	11.1256
1321.61	17.905
1322.43	-7.9961
1323.25	6.2054
1324.06	3.60167
1324.88	13.6235
1325.7	6.66434
1326.52	8.03316
1327.34	4.46922
1328.15	5.11662
1328.97	9.91791
1329.79	8.29292
1330.6	17.1532
1331.42	9.05979
1332.24	19.9137
1333.05	13.9171
1333.87	16.3438
1334.69	6.18244
1335.5	19.1304
1336.32	19.4894
1337.13	10.4276
1337.95	7.63038
1338.76	4.82715
1339.58	25.1137
1340.4	20.2813
1341.21	20.6547
1342.03	18.8817
1342.84	10.7751
1343.66	18.4284
1344.47	17.7347
1345.29	12.7786
1346.1	12.9913
1346.91	25.6963
1347.73	26.955
1348.54	22.017
1349.36	21.2053
1350.17	27.6759
1350.99	12.2664
1351.8	28.0891
1352.61	24.2616
1353.43	23.6971
1354.24	12.2392
1355.05	22.8075
1355.87	19.9418
1356.68	22.2087
1357.49	18.2457
1358.31	29.8219
1359.12	27.8889
1359.93	25.9498
1360.75	22.952
1361.56	24.1737
1362.37	17.0805
1363.18	28.6561
1363.99	36.1501
1364.81	37.3239
1365.62	44.6394
1366.43	35.3867
1367.24	34.4011
1368.05	44.9112
1368.87	51.2881
1369.68	96.9123
1370.49	40.1093
1371.3	41.1743
1372.11	42.1589
1372.92	39.0732
1373.73	24.7059
1374.54	37.144
1375.35	34.1379
1376.16	32.1782
1376.97	45.5213
1377.78	61.0802
1378.6	44.8999
1379.4	43.9275
1380.21	50.0221
1381.03	59.1356
1381.83	51.8691
1382.64	70.1971
1383.45	86.4976
1384.26	102.904
1385.07	162.59
1385.88	346.617
1386.69	1046.34
1387.5	3735.1
1388.31	1204.34
1389.12	274.82
1389.93	145.403
1390.73	81.5517
1391.54	88.6457
1392.35	56.7661
1393.16	60.7951
1393.97	45.396
1394.78	48.434
1395.58	35.1836
1396.39	38.2202
1397.2	45.2954
1398.01	43.1961
1398.81	43.2105
1399.62	34.0239
1400.43	31.9847
1401.23	22.7752
1402.04	37.1625
1402.85	37.3471
1403.66	34.271
1404.46	45.4288
1405.27	41.2153
1406.07	59.5429
1406.88	67.6776
1407.69	94.3173
1408.49	153.772
1409.3	196.86
1410.11	82.9553
1410.91	55.0651
1411.72	46.7261
1412.52	39.572
1413.33	22.3573
1414.13	17.9876
1414.94	19.0502
1415.74	25.1467
1416.55	28.1894
1417.35	21.996
1418.16	28.1016
1418.96	13.6505
1419.77	16.6044
1420.57	19.5268
1421.38	22.4687
1422.18	21.4543
1422.98	15.4644
1423.79	32.3811
1424.59	20.8977
1425.4	23.9205
1426.2	18.7784
1427	17.5602
1427.81	17.3406
1428.61	17.2335
1429.41	21.2746
1430.22	12.0477
1431.02	22.3395
1431.82	4.8392
1432.62	9.80251
1433.43	16.7342
1434.23	13.5005
1435.03	8.36368
1435.83	15.4289
1436.64	6.08249
1437.44	10.0592
1438.24	20.202
1439.04	17.0639
1439.84	10.885
1440.65	15.9607
1441.45	25.0833
1442.25	20.8896
1443.05	12.5934
1443.85	-2.92382
1444.65	9.33394
1445.45	8.25536
1446.26	6.07883
1447.05	12.1094
1447.85	5.82738
1448.66	5.78609
1449.46	17.9862
1450.26	3.48547
1451.06	2.34129
1451.86	11.4394
1452.66	4.17068
1453.46	12.3108
1454.26	8.10762
1455.06	6.98866
1455.86	2.82823
1456.66	-9.56792
1457.45	3.62718
1458.25	8.65751
1459.05	12.6899
1459.85	5.43423
1460.65	3.27721
1461.45	6.22446
1462.25	9.15367
1463.05	10.0171
1463.84	6.83428
1464.64	2.81264
1465.44	7.52421
1466.24	11.5272
1467.04	0.152664
1467.84	-6.05749
1468.63	1.00675
1469.43	6.00055
1470.23	-9.42735
1471.03	4.74209
1471.82	9.71149
1472.62	-0.545067
1473.42	-3.69518
1474.22	6.39132
1475.01	4.32056
1475.81	-10.003
1476.61	-8.0563
1477.4	6.089
1478.2	-0.0911179
1478.99	-3.24522
1479.79	-6.40665
1480.59	7.66143
1481.38	-1.55348
1482.18	7.5947
1482.98	-5.60614
1483.77	5.53757
1484.57	-10.9035
1485.36	2.92091
1486.16	0.138229
1486.95	0.0708771
1487.75	0.991684
1488.54	0.89547
1489.34	-8.292
1490.13	2.79745
1490.93	-0.311882
1491.72	-0.361839
1492.52	-6.44975
1493.31	-5.46828
1494.1	-7.51024
1494.9	9.66133
1495.69	-2.5845
1496.49	1.38371
1497.28	2.35857
1498.08	-0.687431
1498.87	-5.73061
1499.66	-3.6908
1500.46	-0.65947
1501.25	5.3644
1502.04	4.33408
1502.83	-3.78712
1503.63	4.23928
1504.42	3.25837
1505.21	-1.80081
1506	-12.9605
1506.8	-2.86329
1507.59	9.2581
1508.38	5.22618
1509.17	-6.84032
1509.97	16.3831
1510.76	3.23537
1511.55	-7.9372
1512.34	-6.07095
1513.13	-7.13115
1513.93	3.9809
1514.72	-7.03465
1515.51	3.94583
1516.3	6.90178
1517.09	-9.13101
1517.88	-12.0834
1518.67	-7.00439
1519.46	-0.920769
1520.25	-1.89719
1521.04	-0.83075
1521.83	-1.79051
1522.63	7.24564
1523.42	-10.8367
1524.21	-0.850227
1525	7.2017
1525.79	-0.72171
1526.57	5.41615
1527.36	2.4458
1528.15	-1.53502
1528.94	0.49588
1529.73	3.53828
1530.52	-2.39763
1531.31	3.73077
1532.1	-3.23135
1532.89	-2.10178
1533.68	13.0878
1534.47	8.13266
1535.25	3.15102
1536.04	9.11362
1536.83	11.0626
1537.62	9.07796
1538.41	1.08524
1539.2	1.21438
1539.98	3.49741
1540.77	1.69236
1541.56	-1.30572
1542.35	-2.30944
1543.14	11.7085
1543.92	-5.30038
1544.71	4.8443
1545.5	-1.97478
1546.28	0.148384
1547.07	-2.74243
1547.86	4.30959
1548.64	4.43607
1549.43	7.26192
1550.22	4.66782
1551	6.00645
1551.79	3.02836
1552.58	8.23853
1553.36	5.18626
1554.15	12.2471
1554.93	15.2423
1555.72	5.31673
1556.51	8.41128
1557.29	3.52621
1558.08	-0.428238
1558.86	-1.42086
1559.65	5.60555
1560.43	10.6679
1561.22	8.7671
1562	0.964325
1562.79	6.07167
1563.57	4.16666
1564.36	4.37426
1565.14	9.29392
1565.92	8.20991
1566.71	7.50556
1567.49	12.7961
1568.28	12.834
1569.06	11.9226
1569.84	17.0014
1570.63	7.13026
1571.41	5.22051
1572.19	18.2832
1572.98	22.3327
1573.76	11.4256
1574.54	15.6096
1575.33	10.8217
1576.11	7.94656
1576.89	8.98419
1577.68	12.9711
1578.46	1.05054
1579.24	7.14972
1580.02	14.2821
1580.81	6.41814
1581.59	15.457
1582.37	-0.41127
1583.15	10.6482
1583.93	1.79006
1584.72	11.8962
1585.5	21.9716
1586.28	3.11281
1587.06	10.1507
1587.84	7.26894
1588.62	22.3567
1589.4	12.5718
1590.18	9.72105
1590.97	1.9034
1591.75	13.9619
1592.53	7.0277
1593.31	7.05669
1594.09	16.0153
1594.87	6.23396
1595.65	7.32841
1596.43	8.43494
1597.21	2.61749
1597.99	7.71213
1598.77	13.716
1599.55	11.7901
1600.33	18.7945
1601.11	16.8295
1601.89	6.94787
1602.66	12.9343
1603.44	11.9996
1604.22	16.0606
1605	13.2231
1605.78	4.46777
1606.56	15.5119
1607.34	7.7328
1608.12	21.6971
1608.89	12.8792
1609.67	18.83
1610.45	17.8596
1611.23	9.02427
1612.01	6.18453
1612.79	22.1074
1613.56	15.3044
1614.34	9.46254
1615.12	15.4968
1615.9	15.5902
1616.67	9.81537
1617.45	9.92227
1618.23	16.9272
1619	23.8927
1619.78	20.9947
1620.56	15.1688
1621.33	23.1883
1622.11	18.3924
1622.89	16.2631
1623.66	12.0209
1624.44	19.2653
1625.21	8.54466
1625.99	12.579
1626.77	3.12173
1627.54	8.69603
1628.32	17.6021
1629.09	9.95738
1629.87	8.77249
1630.64	4.85643
1631.42	15.5338
1632.2	3.44485
1632.97	10.6542
1633.75	8.09096
1634.52	1.72695
1635.29	1.88438
1636.07	4.45837
1636.84	3.7542
1637.62	2.48672
1638.39	10.7897
1639.17	2.68085
1639.94	5.91956
1640.71	8.23549
1641.49	6.76252
1642.26	-6.03443
1643.04	-3.80437
1643.81	4.67927
1644.58	6.62502
1645.36	-3.97635
1646.12	-13.2358
1646.9	-2.35344
1647.68	-6.2338
1648.47	2.72734
1649.25	-1.0431
1650.03	-5.89993
1650.81	4.10371
1651.59	6.18968
1652.38	-3.58118
1653.16	-0.577103
1653.94	-1.46768
1654.72	3.55241
1655.5	0.738312
1656.28	4.83144
1657.07	2.93583
1657.85	-7.87599
1658.63	5.97277
1659.41	1.06354
1660.19	7.02392
1660.97	-0.749298
1661.75	10.2198
1662.53	-3.40476
1663.31	11.4931
1664.09	-4.37683
1664.87	-0.280693
1665.65	15.4583
1666.43	-9.96295
1667.21	0.793686
1667.99	1.78711
1668.77	0.912422
1669.55	2.99114
1670.33	0.0823669
1671.11	3.16028
1671.89	-7.66406
1672.67	5.24143
1673.45	2.33202
1674.23	5.3793
1675.01	1.51492
1675.79	10.4848
1676.56	1.62943
1677.34	1.66304
1678.12	0.666847
1678.9	1.64287
1679.68	-0.326927
1680.46	10.5511
1681.23	13.5262
1682.01	5.65469
1682.79	0.745544
1683.57	5.71214
1684.35	-2.18585
1685.13	4.74088
1685.9	-2.14419
1686.68	-1.0973
1687.46	12.7557
1688.23	6.81915
1689.01	4.81685
1689.79	0.834808
1690.57	1.84789
1691.34	0.904289
1692.12	1.92739
1692.89	0.913376
1693.67	-1.12458
1694.45	-2.15085
1695.22	-0.16877
1696	3.80347
1696.78	4.81875
1697.55	-1.14252
1698.33	0.775101
1699.1	8.62151
1699.88	-0.221939
1700.65	3.69651
1701.43	11.5465
1702.2	6.57391
1702.98	-0.342842
1703.75	-8.22093
1704.53	-2.30722
1705.3	14.3866
1706.08	8.46521
1706.85	-0.449028
1707.63	7.32068
1708.4	9.17284
1709.18	4.1795
1709.95	1.21743
1710.73	2.20641
1711.5	4.18632
1712.27	1.22551
1713.05	9.89754
1713.82	3.90819
1714.59	-1.02522
1715.37	10.708
1716.14	-2.01193
1716.91	12.547
1717.69	5.5561
1718.46	12.2446
1719.23	1.48592
1720.01	-1.45015
1720.78	1.41277
1721.55	5.21237
1722.32	3.16792
1723.1	5.98825
1723.87	-1.83011
1724.64	4.90281
1725.41	9.61485
1726.18	13.3977
1726.96	8.49539
1727.73	2.64993
1728.5	6.38229
1729.27	-1.66685
1730.04	9.03335
1730.81	3.1703
1731.59	9.01537
1732.36	2.19474
1733.13	3.07088
1733.9	4.84967
1734.67	1.82355
1735.44	0.734314
1736.21	5.46848
1736.98	12.1234
1737.75	7.2298
1738.52	7.12409
1739.29	1.23814
1740.06	3.94536
1740.83	11.4798
1741.6	11.3659
1742.37	1.71882
1743.14	4.52155
1743.91	7.30454
1744.68	5.31387
1745.45	4.31262
1746.22	-1.51817
1746.99	-0.68718
1747.76	3.01014
1748.53	5.82267
1749.3	0.0736694
1750.06	-2.77962
1750.83	5.81982
1751.6	7.6684
1752.37	8.48576
1753.14	6.45466
1753.91	3.48495
1754.68	10.0477
1755.44	8.0459
1756.21	-0.65062
1756.98	5.86423
1757.75	-3.74179
1758.51	9.5682
1759.28	-2.85004
1760.05	9.455
1760.82	-2.05054
1761.59	3.54562
1762.35	4.42944
1763.12	4.39442
1763.88	-6.10875
1764.65	1.51527
1765.42	3.39792
1766.19	1.44347
1766.95	-5.29482
1767.72	3.18083
1768.48	14.5136
1769.25	1.00573
1770.02	-9.5585
1770.78	5.62848
1771.55	-0.999939
1772.31	5.6314
1773.08	11.33
1773.84	-2.022
1774.61	10.3162
1775.38	7.4578
1776.14	7.4738
1776.91	4.52888
1777.67	0.60865
1778.44	-0.460793
1779.2	1.3068
1779.97	6.98004
1780.73	8.85034
1781.5	9.76018
1782.26	2.13158
1783.02	-1.69375
1783.79	4.95889
1784.55	-0.761238
1785.32	1.10128
1786.08	4.83196
1786.84	-1.86908
1787.61	3.90894
1788.37	5.00219
1789.13	14.6067
1789.9	11.7454
1790.66	-2.67233
1791.42	1.01019
1792.19	-0.0185318
1792.95	-1.01085
1793.71	-1.05222
1794.48	-1.11557
1795.24	3.75799
1796	3.77666
1796.76	-2.94379
1797.53	-1.02676
1798.29	9.52356
1799.05	1.76624
1799.81	-1.22945
1800.57	4.43665
1801.34	3.40403
1802.1	-0.478706
1802.86	-1.44985
1803.62	-6.25695
1804.38	-4.35938
1805.14	-16.8657
1805.9	0.477119
1806.67	-7.24252
1807.43	4.27618
1808.19	7.11813
1808.95	5.14752
1809.71	1.25064
1810.47	5.05874
1811.23	-4.64641
1811.99	-7.59089
1812.75	6.86006
1813.51	1.05894
1814.27	0.116096
1815.03	1.11273
1815.79	-0.847664
1816.55	-7.64104
1817.31	-0.970085
1818.07	4.72985
1818.83	9.56475
1819.59	-2.0508
1820.35	6.63769
1821.11	9.52937
1821.87	-1.11115
1822.62	-7.90891
1823.38	0.758743
1824.14	2.63531
1824.9	-4.15733
1825.66	-2.23939
1826.42	1.59453
1827.18	-5.21339
1827.93	9.30634
1828.69	-0.450081
1829.45	3.36005
1830.21	3.28985
1830.97	1.30342
1831.72	2.2759
1832.48	1.31376
1833.24	4.21178
1833.99	-0.652695
1834.75	-1.76804
1835.51	10.6563
1836.27	-1.81282
1837.02	-0.830284
1837.78	-5.90981
1838.54	3.68432
1839.29	-4.84248
1840.05	0.935776
1840.81	-15.7539
1841.56	4.36946
1842.32	1.32743
1843.08	2.26146
1843.83	-5.48671
1844.59	0.281006
1845.34	-1.68855
1846.1	-1.602
1846.86	-3.61631
1847.61	7.64293
1848.37	3.84138
1849.12	-3.94544
1849.88	2.67675
1850.63	2.54833
1851.39	6.30335
1852.14	5.29766
1852.9	-2.40593
1853.65	5.22292
1854.41	5.10227
1855.16	7.89941
1855.91	-4.65319
1856.67	-1.80517
1857.42	2.94322
1858.18	-6.6928
1858.93	6.61481
1859.68	1.75601
1860.44	-4.9309
1861.19	1.80579
1861.95	-8.70298
1862.7	-2.07266
1863.45	1.66713
1864.21	3.5064
1864.96	6.29513
1865.71	10.946
1866.46	-0.640274
1867.22	0.174774
1867.97	-2.75574
1868.72	-2.7669
1869.47	1.9734
1870.23	0.0509186
1870.98	0.0381165
1871.73	-1.89565
1872.48	-3.83815
1873.24	4.65875
1873.99	-3.92077
1874.74	8.33549
1875.49	0.657059
1876.24	-4.20622
1876.99	2.33473
1877.75	-6.32387
1878.5	-3.25607
1879.25	1.59936
1880	-3.18518
1880.75	-2.22943
1881.5	3.36218
1882.25	1.30729
1883	2.08128
1883.75	2.11797
1884.5	-5.46835
1885.25	4.0592
1886	-3.3913
1886.75	2.27079
1887.5	1.25892
1888.25	4.00514
1889	-0.799881
1889.75	2.94556
1890.5	-3.57305
1891.25	-8.26575
1892	1.1553
1892.75	4.90694
1893.5	9.47401
1894.25	5.69251
1895	0.0421524
1895.75	-0.845963
1896.5	1.10667
1897.25	3.05792
1897.99	3.08521
1898.74	4.93913
1899.49	8.65646
1900.24	-3.56567
1900.99	1.183
1901.74	3.15743
1902.49	11.7116
1903.23	-1.46124
1903.98	-4.27528
1904.73	9.84529
1905.47	10.8046
1906.22	-2.40305
1906.97	1.35313
1907.72	3.27667
1908.47	3.3513
1909.21	-0.32814
1909.96	-1.14419
1910.71	-4.77857
1911.45	2.82812
1912.2	7.55946
1912.95	-1.8252
1913.69	2.96361
1914.44	9.6881
1915.18	2.24657
1915.93	0.399834
1916.68	6.05867
1917.42	0.391502
1918.17	-2.39199
1918.92	1.50191
1919.66	-3.06171
1920.41	2.67427
1921.15	8.44109
1921.9	-1.86912
1922.64	12.341
1923.39	4.78304
1924.13	1.95081
1924.88	0.0872574
1925.62	-1.69634
1926.37	11.6812
1927.11	8.97031
1927.86	7.16786
1928.6	-3.17259
1929.34	6.40494
1930.09	4.65087
1930.83	12.3667
1931.58	1.00848
1932.32	7.65738
1933.07	1.97897
1933.81	7.79875
1934.55	4.30347
1935.3	8.37818
1936.04	8.39329
1936.78	13.1702
1937.53	10.2886
1938.27	13.1458
1939.01	5.64982
1939.76	7.65907
1940.5	5.86387
1941.24	4.12991
1941.98	0.26693
1942.73	10.0214
1943.47	4.27277
1944.21	11.0506
1944.95	7.36209
1945.69	-3.01748
1946.44	-0.0453491
1947.18	-2.8592
1947.92	7.70013
1948.66	2.0136
1949.4	7.86994
1950.15	13.7723
1950.89	5.34158
1951.63	9.35882
1952.37	18.1201
1953.11	5.73347
1953.85	12.3858
1954.59	13.2201
1955.33	-3.98595
1956.07	8.67161
1956.81	4.98621
1957.55	7.03392
1958.29	6.16803
1959.03	7.16772
1959.78	6.23271
1960.52	6.23914
1961.26	15.8382
1962	2.45522
1962.74	11.1655
1963.47	4.51654
1964.21	5.56459
1964.95	-3.98618
1965.69	15.284
1966.43	10.6114
1967.17	4.93456
1967.91	7.8905
1968.65	14.6722
1969.39	4.08122
1970.13	-4.58482
1970.87	2.1424
1971.6	8.8829
1972.34	5.12556
1973.08	4.19882
1973.82	1.32233
1974.56	3.28199
1975.3	13.9091
1976.03	1.54266
1976.77	4.48904
1977.51	0.688507
1978.25	8.36742
1978.99	-1.1824
1979.72	1.75593
1980.46	20.9548
1981.2	3.71783
1981.93	20.0305
1982.67	14.2983
1983.41	6.61349
1984.15	5.68139
1984.88	2.82977
1985.62	16.2221
1986.35	23.0092
1987.09	15.4275
1987.83	9.66054
1988.56	11.4587
1989.3	7.49387
1990.04	6.52113
1990.77	11.4155
1991.51	21.0952
1992.24	7.83877
1992.98	8.80187
1993.71	13.5035
1994.45	9.61175
1995.18	5.71857
1995.92	17.08
1996.66	11.4488
1997.39	14.3854
1998.13	16.3265
1998.86	15.3768
1999.59	16.9852
2000.33	3.67351
2001.06	9.58649
2001.8	7.86579
2002.53	10.0441
2003.27	14.571
2004	3.29907
2004.73	5.34312
2005.47	13.3118
2006.2	14.3171
2006.94	5.85042
2007.67	7.67411
2008.4	3.63583
2009.14	7.8092
2009.87	5.5575
2010.6	1.80335
2011.34	2.99716
2012.07	6.82717
2012.8	1.18449
2013.54	6.87566
2014.27	-1.00961
2015	6.14587
2015.73	2.36013
2016.46	7.19212
2017.2	-0.462242
2017.93	2.81656
2018.66	1.86077
2019.39	2.46629
2020.13	1.44473
2020.86	3.06551
2021.59	-1.28164
2022.32	1.77703
2023.05	3.53232
2023.78	0.560921
2024.52	4.1675
2025.25	-1.84068
2025.98	0.600258
2026.71	4.38548
2027.38	0.0752258
2028.12	-3.79951
2028.86	0.302956
2029.6	2.85944
2030.33	-1.08478
2031.08	-3.82124
2031.81	6.44709
2032.55	-2.772
2033.29	-10.1572
2034.03	2.9401
2034.77	-4.71158
2035.51	3.83389
2036.25	2.10578
2036.99	0.219528
2037.73	0.215691
2038.47	4.85689
2039.2	2.01305
2039.94	-3.64684
2040.68	1.88291
2041.42	3.70695
2042.16	6.47647
2042.9	6.45048
2043.63	1.87144
2044.37	0.996445
2045.11	-3.81306
2045.85	-4.47192
2046.59	1.12276
2047.32	0.0889893
2048.06	8.38109
2048.8	2.80843
2049.53	-3.64934
2050.27	-0.762444
2051.01	-0.751472
2051.75	5.72964
2052.48	3.87873
2053.22	1.11782
2053.96	-2.53835
2054.69	-4.40354
2055.43	-5.38226
2056.17	2.06223
2056.9	2.0326
2057.64	8.59043
2058.37	-0.717773
2059.11	5.87938
2059.85	8.68813
2060.58	-5.40688
2061.32	3.97311
2062.05	1.15729
2062.79	1.17122
2063.52	2.13777
2064.26	4.95802
2065	2.17556
2065.73	2.23764
2066.46	7.88783
2067.2	1.32213
2067.93	6.98032
2068.67	-0.531807
2069.4	-0.599739
2070.14	-6.31242
2070.87	10.7251
2071.61	5.13441
2072.34	-0.518822
2073.08	1.32159
2073.81	-10.9478
2074.54	7.88989
2075.28	0.427414
2076.01	5.22053
2076.74	-7.09055
2077.48	6.93711
2078.21	4.0945
2078.94	6.92174
2079.68	4.14687
2080.41	9.82566
2081.14	5.98846
2081.88	9.71845
2082.61	-5.42014
2083.34	-1.68697
2084.08	8.66148
2084.81	2.95113
2085.54	5.74194
2086.27	1.98297
2087	5.76644
2087.74	1.01537
2088.47	1.92236
2089.2	-1.88685
2089.93	0.956413
2090.66	-3.80959
2091.39	3.75286
2092.13	-0.00213623
2092.86	6.68603
2093.59	-2.79014
2094.32	7.657
2095.05	-9.52397
2095.78	-0.123878
2096.51	3.59643
2097.24	7.29683
2097.97	6.25336
2098.71	3.32599
2099.44	0.405411
2100.17	-4.39808
2100.9	6.02394
2101.63	-5.39592
2102.36	5.9369
2103.09	12.4727
2103.82	-0.902321
2104.55	4.75661
2105.28	17.0906
2106.01	-0.0218506
2106.74	1.83248
2107.47	8.4198
2108.2	10.1709
2108.92	-0.403732
2109.66	-4.22173
2110.38	4.25899
2111.11	7.03714
2111.84	1.23372
2112.57	4.01603
2113.3	-2.65674
2114.03	2.04369
2114.76	3.86562
2115.48	10.4299
2116.21	0.813667
2116.94	1.65459
2117.67	-6.02882
2118.4	-2.3672
2119.13	-1.56909
2119.85	0.188339
2120.58	2.93781
2121.31	7.65274
2122.04	-6.58189
2122.76	-4.71729
2123.49	7.56701
2124.22	-1.09611
2124.95	0.601173
2125.67	1.35525
2126.4	-1.64438
2127.13	-5.57246
2127.85	14.1793
2128.58	4.62587
2129.31	1.69392
2130.03	4.42903
2130.76	-7.96286
2131.49	5.13286
2132.21	5.01009
2132.94	-2.67454
2133.66	4.79787
2134.39	4.72164
2135.11	0.85231
2135.84	-3.98643
2136.57	5.28
2137.29	3.32139
2138.02	-1.45668
2138.74	-3.45451
2139.47	3.99408
2140.19	0.0688019
2140.92	1.83313
2141.64	6.4223
2142.37	3.47972
2143.09	-2.12267
2143.82	4.06184
2144.54	0.305222
2145.27	-7.33759
2145.99	5.72382
2146.71	-0.0316315
2147.44	-2.97897
2148.16	6.28945
2148.89	1.46031
2149.61	8.78282
2150.33	-3.5714
2151.06	-0.848022
2151.78	-4.64408
2152.5	0.898048
2153.23	-9.55389
2153.95	1.56635
2154.67	-6.12274
2155.4	-4.45832
2156.12	-3.68655
2156.84	-0.989098
2157.57	10.1611
2158.29	-1.10056
2159.01	-1.20512
2159.73	0.520988
2160.46	3.15572
2161.18	-2.56831
2161.9	-0.812675
2162.62	-1.83518
2163.34	0.839142
2164.07	4.44517
2164.79	-1.30391
2165.51	3.28709
2166.23	4.11974
2166.95	-0.675705
2167.67	-8.28179
2168.4	4.54213
2169.12	-2.02851
2169.84	-4.81313
2170.56	-1.10595
2171.28	1.55863
2172	1.31335
2172.72	8.61044
2173.44	2.01875
2174.16	-4.53732
2174.88	3.74886
2175.6	-7.50166
2176.32	-3.88675
2177.04	0.656517
2177.76	0.578606
2178.48	-1.40062
2179.2	0.360825
2179.92	0.283035
2180.64	-0.737099
2181.36	4.73592
2182.08	1.84018
2182.8	3.58073
2183.52	1.56729
2184.24	3.28902
2184.96	6.93202
2185.68	-0.525482
2186.4	6.8798
2187.12	-8.87184
2187.83	-7.03828
2188.55	-4.37882
2189.27	8.45569
2189.99	-0.0438232
2190.71	-1.95598
2191.43	-6.65044
2192.14	-0.200897
2192.86	9.97619
2193.58	-9.52
2194.3	-1.09673
2195.01	-3.95955
2195.73	-0.36541
2196.45	1.31681
2197.17	10.4611
2197.88	-0.744446
2198.6	-0.737099
2199.32	2.09085
2200.04	-3.41672
2200.75	3.19133
2201.47	4.98315
2202.19	-7.67844
2202.9	7.49262
2203.62	15.0562
2204.34	7.66686
2205.05	-3.76297
2205.77	0.68264
2206.49	-6.79261
2207.2	3.37944
2207.92	2.4654
2208.63	5.27168
2209.35	1.52631
2210.07	-1.31659
2210.78	15.453
2211.5	-4.11302
2212.21	-3.16771
2212.93	-5.10021
2213.64	1.33284
2214.36	-2.35439
2215.07	1.38305
2215.79	2.28444
2216.5	6.90163
2217.22	-3.42155
2217.93	-3.45798
2218.65	3.98799
2219.36	-0.665215
2220.08	2.13165
2220.79	3.94559
2221.5	0.0929794
2222.22	1.86411
2222.93	-3.74737
2223.65	0.950485
2224.36	1.0161
2225.07	-0.814186
2225.79	3.91835
2226.5	6.76234
2227.21	-2.57741
2227.93	-1.65977
2228.64	0.158905
2229.35	3.86899
2230.06	-0.767075
2230.78	3.02368
2231.49	-0.68074
2232.2	4.05786
2232.92	5.97974
2233.63	0.373146
2234.34	-0.57724
2235.05	0.289688
2235.77	-6.37314
2236.48	-7.31965
2237.19	3.98968
2237.9	3.15202
2238.61	-2.41926
2239.32	11.7854
2240.04	0.376694
2240.75	-5.25585
2241.46	-5.23908
2242.17	-3.34139
2242.88	-2.38957
2243.59	-3.38629
2244.3	3.20354
2245.02	6.13744
2245.73	2.43134
2246.44	1.54071
2247.15	-1.26342
2247.86	0.629265
2248.57	8.16866
2249.28	6.24999
2249.99	9.1153
2250.7	6.19944
2251.41	8.01828
2252.12	1.4135
2252.83	6.22749
2253.54	6.36527
2254.25	8.32819
2254.96	4.53123
2255.67	9.28384
2256.38	3.64439
2257.09	13.1936
2257.8	0.899414
2258.51	1.86823
2259.22	4.76487
2259.93	2.89976
2260.63	5.78924
2261.34	1.11402
2262.05	1.13843
2262.76	2.14869
2263.47	-3.46848
2264.18	2.38443
2264.88	3.44069
2265.59	-3.1983
2266.3	2.49754
2267.01	-2.3483
2267.72	4.27907
2268.43	-3.38702
2269.13	-3.32986
2269.84	1.54839
2270.55	3.55743
2271.25	2.67078
2271.96	4.64481
2272.67	-0.112732
2273.38	1.82836
2274.08	-21.1152
2274.79	-0.989418
2275.5	-0.00543213
2276.2	-2.81808
2276.91	-6.5694
2277.62	1.22236
2278.32	8.05532
2279.03	-4.41988
2279.74	7.98033
2280.44	5.01988
2281.15	0.187439
2281.86	6.90182
2282.56	-2.62091
2283.27	-5.40118
2283.97	10.1315
2284.68	6.38906
2285.38	-6.05411
2286.09	-5.14857
2286.79	2.60168
2287.5	-3.06676
2288.2	3.71252
2288.91	2.69665
2289.61	3.53896
2290.32	-2.27705
2291.02	6.41431
2291.73	-6.9539
2292.43	0.818069
2293.14	-1.03135
2293.84	-8.70776
2294.55	-2.96275
2295.25	-2.04293
2295.95	-3.04389
2296.66	3.6261
2297.36	-5.93898
2298.07	0.90316
2298.77	2.90068
2299.47	10.6932
2300.18	4.90862
2300.88	-4.69782
2301.58	-3.70033
2302.29	4.96931
2302.99	4.96422
2303.69	2.06872
2304.4	2.12028
2305.1	1.20688
2305.8	6.06207
2306.51	1.25905
2307.21	4.14761
2307.91	4.10814
2308.61	1.18487
2309.32	4.12988
2310.02	6.14748
2310.72	3.23905
2311.42	-6.57615
2312.12	4.89382
2312.82	5.79527
2313.53	7.78856
2314.23	11.7538
2314.93	8.95985
2315.63	5.01482
2316.33	2.93335
2317.03	3.85065
2317.73	1.95403
2318.44	0.912926
2319.14	-3.99002
2319.84	2.7105
2320.54	3.65751
2321.24	4.65246
2321.94	-1.08322
2322.64	16.3515
2323.34	9.56734
2324.04	-1.08533
2324.74	11.3954
2325.44	9.3213
2326.14	25.6176
2326.84	32.2401
2327.54	69.7138
2328.24	214.225
2328.94	243.967
2329.64	68.4567
2330.34	27.9578
2331.04	20.1845
2331.74	4.78197
2332.44	5.64722
2333.14	6.50762
2333.84	9.29985
2334.53	0.512749
2335.23	7.15924
2335.93	-2.50942
2336.63	9.90323
2337.33	-8.44426
2338.03	5.88683
2338.73	2.92416
2339.42	1.89746
2340.12	7.55604
2340.82	3.56516
2341.52	-9.10243
2342.22	6.09985
2342.91	0.235558
2343.61	3.9798
2344.31	3.90533
2345	-0.988663
2345.7	3.64597
2346.4	0.636414
2347.1	-1.39577
2347.79	2.33721
2348.49	3.22631
2349.19	-5.54308
2349.88	1.84039
2350.58	0.392334
2351.28	7.51543
2351.97	-3.44534
2352.67	4.93747
2353.37	6.61166
2354.06	-4.01479
2354.76	4.49425
2355.45	0.536095
2356.15	1.31069
2356.85	1.99751
2357.54	-2.94537
2358.24	-2.16269
2358.93	-0.446434
2359.63	3.18351
2359.86	-1.6342