File: Data/3-Raman/processed/bu19w-e-ff11b-fi05-v_150 (500nm)_532nm_edge_100%_x100_vis_h50um_30sx2_01_0.txt
#Acq. time (s)=	30
#Accumulations=	2
#Range (cm-¹)=	100...5000
#Windows=	1
#Auto scanning=	Off
#Autofocus=	Off
#Macrospot=	Off
#AutoExposure=	Off
#Spike filter=	Multiple accum.
#Delay time (s)=	2
#Binning=	1
#Readout mode=	Signal
#DeNoise=	Off
#ICS correction=	On
#Dark correction=	Off
#Inst. Process=	Off
#Detector Gain=	Best Dynamic
#Detector ADC=	50 kHz HS
#Detector temperature (°C)=	-60.28
#Instrument=	LabRAM HR Evol
#Detector=	SIN-EM FIVIS
#Objective=	x100_VIS
#Grating=	150 (500nm)
#ND Filter=	100%
#Laser=	532nm_Edge
#Hole=	49.98
#Temperature=	0
#Range=	Visible
#StageXY=	75x50mm Scan+
#StageZ=	Z motor
#X (µm)=	0
#Y (µm)=	0
#Z (µm)=	-263.7
#Full time(mm:ss)=	1:05
#Project=	21_11_04
#Sample=	BU19w
#Site=
#Title=	BU19w-E-FF11b-FI05-V_150 (500nm)_532nm_Edge_100%_x100_VIS_H50um_30sX2
#Remark=
#Date=	04.11.2021 18:56
#Acquired=	04.11.2021 18:56:53
#Base:Fit=	16.12.2021 17:39:50
#Base:Edit=	16.12.2021 17:45:04
#Base:Edit=	16.12.2021 17:45:06
#Base:Sub=	16.12.2021 17:45:09
101.869	367.665
106.493	1067.73
111.113	3866.78
115.732	6034.93
120.349	3314.76
124.964	1015.15
129.577	436.092
134.185	296.276
138.793	187.96
143.399	80.3633
148.003	76.2908
152.602	190.262
157.201	357.467
161.798	626.735
166.392	1082.32
170.982	1632.23
175.572	2757.75
180.16	4408.6
184.745	6682.64
189.326	8773.79
193.907	9534.91
198.486	8527.87
203.06	6453.24
207.634	4453.55
212.206	2955.18
216.776	2017.95
221.341	1369.01
225.906	1025.32
230.469	778.783
235.028	616.277
239.586	543.974
244.142	695.78
248.694	1283.54
253.246	1493.64
257.795	682.46
262.341	141.461
266.886	14.5076
271.428	-78.1488
275.967	-60.1486
280.505	-101.223
285.041	-98.1346
289.573	-127.114
294.105	-126.415
298.632	-82.928
303.159	-87.7321
307.685	-74.2335
312.205	-61.5135
316.726	-37.8619
321.242	-28.692
325.758	-27.7534
330.272	13.7069
334.782	325.929
339.292	1186.42
343.797	1538.85
348.302	791.008
352.803	305.534
357.304	187.577
361.802	177.597
366.297	146.753
370.791	151.101
375.281	245.437
379.77	395.249
384.256	569.355
388.741	889.139
393.223	682.684
397.704	349.546
402.18	250.915
406.657	261.843
411.13	328.252
415.602	388.21
420.07	456.251
424.538	617.815
429.002	966.67
433.465	1665.27
437.925	3229.31
442.384	7116.16
446.839	17967.4
451.294	31072.7
455.745	26549.8
460.196	13580.1
464.642	6334.46
469.089	3694.06
473.531	2525.64
477.971	1842
482.411	1408.12
486.846	1146.31
491.282	1007.39
495.713	979.903
500.144	873.268
504.572	800.966
508.997	692.981
513.421	596.459
517.842	521.875
522.263	424.37
526.679	396.386
531.093	317.556
535.507	318.598
539.917	287.179
544.327	232.442
548.733	199.635
553.137	172.477
557.54	184.398
561.94	150.905
566.337	163.992
570.734	179.778
575.127	146.778
579.518	154.806
583.909	156.833
588.295	149.066
592.68	120.565
597.064	104.675
601.445	102.353
605.823	83.6188
610.201	72.9524
614.575	52.7797
618.947	57.4627
623.317	67.5396
627.686	50.3119
632.052	55.4486
636.415	37.4639
640.777	34.5967
645.138	27.0702
649.495	37.6797
653.85	50.365
658.205	21.0064
662.556	15.9786
666.905	38.061
671.252	61.1177
675.597	94.0495
679.941	167.272
684.282	309.407
688.62	259.618
692.957	125.261
697.293	52.1616
701.625	4.13486
705.955	9.03387
710.283	8.05963
714.609	-9.80688
718.933	-3.31967
723.257	-17.3922
727.577	1.2189
731.894	-20.9964
736.21	-7.60376
740.524	-15.3248
744.835	-20.2935
749.147	-23.9716
753.454	5.78317
757.759	12.8177
762.063	26.6796
766.364	59.082
770.663	65.6044
774.96	120.182
779.257	246.03
783.55	390.357
787.841	486.296
792.13	734.73
796.417	946.433
800.702	617.974
804.985	299.793
809.266	163.578
813.545	106.689
817.821	75.2366
822.096	65.8023
826.371	66.4667
830.641	71.6343
834.91	61.4388
839.176	40.2112
843.441	20.0611
847.703	27.3857
851.964	39.9723
856.222	40.4678
860.479	66.3406
864.733	114.166
868.986	86.9803
873.236	68.5834
877.485	32.606
881.731	39.3977
885.975	21.9851
890.218	8.82422
894.458	29.2249
898.696	19.8938
902.933	26.8697
907.167	23.5573
911.399	24.0092
915.63	-6.56445
919.858	1.7554
924.084	-11.5779
928.308	-8.99197
932.531	-8.02432
936.749	-38.1644
940.967	-19.0263
945.184	-22.4179
949.398	-21.5257
953.61	-26.9021
957.821	-24.749
962.029	-41.6677
966.236	-45.7442
970.44	-37.022
974.642	-53.6691
978.843	-46.9317
983.041	-46.4744
987.236	-62.9439
991.43	-57.1555
995.623	-46.9156
999.813	-51.2918
1004	-71.5258
1008.19	-52.4667
1012.37	-49.2933
1016.55	-46.1967
1020.73	-47.3636
1024.91	-43.2495
1029.09	-42.4513
1033.27	-16.0838
1037.44	-22.0613
1041.61	-5.8407
1045.78	2.88574
1049.94	86.9134
1054.11	184.318
1058.27	211.342
1062.43	260.244
1066.59	470.693
1070.75	627.37
1074.9	417.09
1079.05	162.307
1083.2	72.0948
1087.35	21.8701
1091.5	31.8755
1095.65	28.5574
1099.79	12.0439
1103.93	16.1139
1108.07	-7.323
1112.21	10.2756
1116.34	6.44635
1120.48	-5.16589
1124.61	6.93462
1128.74	28.3308
1132.86	49.8784
1136.99	82.675
1141.11	213.081
1145.23	359.435
1149.35	476.194
1153.47	341.119
1157.59	151.917
1161.7	77.0429
1165.82	37.1176
1169.92	34.2638
1174.03	37.4862
1178.14	40.6318
1182.24	29.3327
1186.35	20.0309
1190.45	30.0862
1194.55	26.7014
1198.64	42.6434
1202.74	47.2116
1206.83	71.0161
1210.92	80.5009
1215.01	101.047
1219.1	130.561
1223.18	134.833
1227.27	128.102
1231.35	118.501
1235.43	116.122
1239.5	125.936
1243.58	136.629
1247.65	180.336
1251.72	293.109
1255.8	224.244
1259.86	167.339
1263.93	203.397
1267.99	611.989
1272.06	2038.85
1276.12	866.041
1280.18	229.976
1284.23	139.493
1288.29	154.412
1292.34	132.032
1296.39	99.4706
1300.44	123.258
1304.49	105.65
1308.53	115.196
1312.58	88.4013
1316.62	104.825
1320.66	125.168
1324.7	106.121
1328.73	119.186
1332.77	120.136
1336.8	128.979
1340.83	119.704
1344.86	140.368
1348.88	158.926
1352.91	181.379
1356.93	220.626
1360.95	244.808
1364.97	301.597
1368.99	429.427
1373.01	1849.13
1377.02	3179.98
1381.03	806.624
1385.04	262.537
1389.05	192.405
1393.06	240.458
1397.06	394.017
1401.06	249.193
1405.06	146.583
1409.06	126.701
1413.06	131.453
1417.05	111.519
1421.05	115.224
1425.04	99.1238
1429.03	94.7305
1433.01	100.184
1437	97.7203
1440.99	97.1991
1444.97	85.7668
1448.95	87.1224
1452.93	93.3519
1456.9	77.8325
1460.88	80.0076
1464.85	96.8505
1468.82	86.0849
1472.79	81.2389
1476.76	86.1683
1480.73	88.091
1484.69	96.8208
1488.65	83.9876
1492.61	78.986
1496.57	83.7292
1500.53	81.6418
1504.48	80.5455
1508.43	84.3444
1512.39	65.797
1516.33	86.0891
1520.28	81.1339
1524.23	81.0264
1528.17	82.8527
1532.11	87.5915
1536.05	96.1934
1539.99	79.5814
1543.93	90.0878
1547.86	89.9153
1551.8	103.287
1555.73	95.3015
1559.66	109.536
1563.58	121.777
1567.51	124.289
1571.44	113.232
1575.36	105.064
1579.28	100.743
1583.2	111.833
1587.11	115.164
1591.03	129.054
1594.94	118.854
1598.85	140.368
1602.76	145.528
1606.67	146.868
1610.58	135.739
1614.48	137.084
1618.38	152.821
1622.29	153.198
1626.18	155.514
1630.08	129.146
1633.98	152.621
1637.87	157.899
1641.76	152.699
1645.65	141.802
1649.54	134.745
1653.43	128.643
1657.31	130.185
1661.2	128.824
1665.08	117.795
1668.96	92.2977
1672.83	109.016
1676.71	101.67
1680.58	91.3215
1684.46	88.5876
1688.33	65.6912
1692.2	54.2885
1696.06	84.0092
1699.93	58.1999
1703.79	64.8436
1707.66	58.0849
1711.52	46.553
1715.37	55.9109
1719.23	39.6931
1723.08	57.5215
1726.94	39.4585
1730.79	49.6321
1734.64	50.3873
1738.49	36.1441
1742.33	37.8042
1746.18	38.5269
1750.02	21.6877
1753.86	31.8866
1757.7	31.0309
1761.54	38.8183
1765.37	27.954
1769.21	33.8392
1773.04	25.8862
1776.87	22.5835
1780.7	30.5126
1784.53	24.5018
1788.35	40.9338
1792.17	16.2255
1796	18.6468
1799.82	11.6742
1803.64	13.0495
1807.45	30.4156
1811.27	19.5183
1815.08	8.5741
1818.89	11.7023
1822.7	2.5173
1826.51	12.1718
1830.32	18.0025
1834.12	6.81873
1837.92	5.97946
1841.72	10.759
1845.52	7.97368
1849.32	6.15179
1853.12	10.8209
1856.91	-1.40504
1860.7	6.8891
1864.5	13.2619
1868.28	14.9815
1872.07	5.5966
1875.86	-5.56207
1879.64	10.1105
1883.42	10.137
1887.21	2.81764
1890.98	0.306107
1894.76	6.10919
1898.54	-1.88762
1902.31	20.5618
1906.08	-0.194199
1909.85	-3.44273
1913.62	13.6588
1917.39	-12.5602
1921.16	-6.38234
1924.92	2.63051
1928.68	-2.20248
1932.44	-12.6056
1936.2	-4.41161
1939.96	-15.7853
1943.71	-8.49263
1947.47	0.719833
1951.22	6.06497
1954.97	6.65634
1958.72	0.582138
1962.46	5.71471
1966.21	-21.0862
1969.95	2.77719
1973.7	0.280289
1977.43	4.31541
1981.17	12.9922
1984.91	-26.9722
1988.65	0.34343
1992.38	-1.32433
1996.11	-15.1066
1999.84	6.3972
2003.57	-5.51176
2007.3	-3.51578
2011.02	2.11453
2014.75	8.64861
2018.47	3.31854
2022.19	-4.6246
2025.91	7.72046
2029.62	-11.0395
2033.34	-3.16826
2037.05	-1.60405
2040.76	-1.88689
2044.47	0.57605
2048.18	3.96138
2051.89	-10.9187
2055.59	-5.62918
2059.3	6.17903
2063	8.97807
2066.7	-5.62193
2070.4	-16.5603
2074.1	-18.2958
2077.79	-9.84537
2081.49	0.515091
2085.18	-5.80385
2088.87	-5.83589
2092.56	-1.33829
2096.25	-6.02576
2099.93	-7.93903
2103.61	-1.54602
2107.3	10.4022
2110.98	-1.85445
2114.66	9.13602
2118.33	-3.12756
2122.01	20.7729
2125.68	0.0532074
2129.36	-3.96223
2133.03	0.347626
2136.7	8.34047
2140.36	7.97818
2144.03	-0.702316
2147.7	-7.52101
2151.36	5.89204
2155.02	-2.72899
2158.68	1.50951
2162.34	-6.11559
2165.99	-13.6788
2169.65	-10.2427
2173.3	1.46793
2176.95	-4.0733
2180.6	-18.678
2184.25	-16.8913
2187.9	-20.5152
2191.54	-11.3216
2195.18	-17.5107
2198.83	-4.52304
2202.47	-12.4567
2206.11	-15.8055
2209.74	-9.06839
2213.38	-9.60173
2217.01	-3.70009
2220.64	-15.2161
2224.27	-12.0369
2227.9	-11.6151
2231.53	-20.4102
2235.16	-5.18556
2238.78	-23.2285
2242.4	-11.6652
2246.02	-15.8499
2249.64	-15.3861
2253.26	-14.8951
2256.88	-12.5134
2260.49	-20.4036
2264.11	-13.3546
2267.72	-25.9612
2271.33	-20.7126
2274.93	-16.4206
2278.54	3.86359
2282.15	-17.4481
2285.75	-10.4776
2289.35	-13.8825
2292.95	-23.9347
2296.55	-22.6363
2300.15	-19.4303
2303.74	-6.76883
2307.34	-11.1935
2310.93	-3.32092
2314.52	86.0483
2318.11	337.424
2321.7	137.593
2325.28	5.98936
2328.87	-9.08476
2332.45	-2.41898
2336.03	-2.3951
2339.61	-10.866
2343.19	-10.8666
2346.77	-7.13249
2350.34	-8.10628
2353.92	-3.47217
2357.49	-13.7941
2361.06	-12.9082
2364.63	-7.37901
2368.2	-3.71243
2371.76	-20.3863
2375.33	-2.80109
2378.89	-18.4971
2382.45	-19.374
2386.01	1.85127
2389.57	-6.35002
2393.13	-12.6563
2396.68	-6.05975
2400.23	7.92317
2403.79	-10.0716
2407.34	-0.538437
2410.88	-5.60175
2414.43	-0.523712
2417.98	-21.1234
2421.52	1.50082
2425.06	-8.0217
2428.61	-8.29964
2432.14	-6.69379
2435.68	-18.0196
2439.22	-15.4445
2442.75	-2.60361
2446.29	-7.43219
2449.82	-2.8961
2453.35	-2.05894
2456.88	-2.26561
2460.4	-7.34305
2463.93	-1.15112
2467.45	3.96968
2470.98	1.65906
2474.5	9.47662
2478.02	-4.48199
2481.54	-5.19109
2485.05	-8.78474
2488.57	-4.01218
2492.08	-1.05544
2495.59	3.69331
2499.1	-6.52083
2502.61	1.96124
2506.12	-3.6319
2509.63	-2.71706
2513.13	-6.45233
2516.63	-8.27788
2520.13	1.0629
2523.63	-5.49191
2527.13	5.7114
2530.63	-12.6229
2534.12	-13.3694
2537.62	-8.53064
2541.11	-4.5847
2544.6	6.8228
2548.09	-12.1531
2551.58	-8.04875
2555.06	-4.82664
2558.55	7.75911
2562.03	-1.9003
2565.51	3.35883
2568.99	6.82758
2572.47	-5.53137
2575.95	-0.124023
2579.43	10.9832
2582.9	-10.8363
2586.37	5.98131
2589.84	0.0889893
2593.31	5.47511
2596.78	-4.40245
2600.25	7.68726
2603.71	7.37619
2607.18	2.16174
2610.64	11.1846
2614.1	3.74144
2617.56	7.89644
2621.02	6.20456
2624.47	16.0053
2627.93	-4.99516
2631.38	7.59607
2634.83	11.4897
2638.28	0.93631
2641.73	13.3507
2645.18	0.828735
2648.62	2.65004
2652.07	22.5322
2655.51	-1.47537
2658.95	5.90114
2662.39	0.90773
2665.83	0.638763
2669.27	9.79128
2672.7	20.7618
2676.14	10.1258
2679.57	13.6016
2683	10.5557
2686.43	9.43907
2689.86	3.77354
2693.29	5.63808
2696.71	7.45023
2700.13	10.2262
2703.56	6.49387
2706.98	12.9788
2710.4	12.1518
2713.82	3.91182
2717.23	10.5883
2720.65	7.98497
2724.06	5.39438
2727.47	23.3521
2730.88	1.15222
2734.29	8.8389
2737.7	14.6621
2741.11	14.8574
2744.51	9.37743
2747.91	17.9485
2751.32	5.84247
2754.72	17.2239
2758.11	7.87558
2761.51	6.056
2764.91	7.0067
2768.3	18.2918
2771.7	11.6343
2775.09	6.8421
2778.48	19.9125
2781.87	22.5832
2785.25	28.0532
2788.64	20.3363
2792.03	23.896
2795.41	18.9817
2798.79	15.0107
2802.17	24.139
2805.55	7.00313
2808.93	16.1099
2812.3	26.1206
2815.68	14.5922
2819.05	14.2813
2822.42	21.4598
2825.79	13.7254
2829.16	21.8556
2832.53	20.6781
2835.89	18.5996
2839.26	16.5481
2842.62	11.7323
2845.98	8.81485
2849.34	24.6028
2852.7	14.3296
2856.06	12.414
2859.41	21.7361
2862.77	17.0545
2866.12	26.4238
2869.47	9.53894
2872.82	4.81046
2876.17	12.2859
2879.52	18.8256
2882.87	20.6565
2886.21	28.1291
2889.55	33.7155
2892.89	24.1839
2896.23	26.8729
2899.57	20.0739
2902.91	18.9108
2906.25	40.4262
2909.58	25.0191
2912.91	41.7631
2916.25	26.3175
2919.58	27.8679
2922.91	38.8584
2926.23	30.9119
2929.56	33.3295
2932.88	37.6066
2936.21	50.3296
2939.53	46.9989
2942.85	53.0905
2946.17	38.4631
2949.49	40.7945
2952.8	55.3304
2956.12	60.451
2959.43	48.7012
2962.74	52.9355
2966.06	62.7999
2969.37	49.2781
2972.67	66.7574
2975.98	52.342
2979.28	67.9931
2982.59	74.229
2985.89	61.7063
2989.19	71.7239
2992.49	71.4214
2995.79	73.948
2999.09	87.7682
3002.38	70.5632
3005.68	82.5031
3008.97	98.2383
3012.26	97.0514
3015.55	85.5036
3018.84	89.9609
3022.13	103.849
3025.41	96.0438
3028.7	110.896
3031.98	121.978
3035.26	128.329
3038.54	134.673
3041.82	133.455
3045.1	128.453
3048.38	156.596
3051.65	142.125
3054.92	159.881
3058.2	155.826
3061.47	153.554
3064.73	174.105
3068	172.792
3071.27	178.065
3074.54	202.863
3077.8	211.016
3081.06	217.1
3084.32	221.67
3087.58	230.009
3090.84	235.63
3094.1	254.653
3097.35	257.834
3100.61	279.402
3103.86	301.812
3107.11	291.192
3110.36	299.537
3113.61	307.711
3116.86	329.265
3120.11	326.082
3123.35	334.329
3126.59	367.342
3129.84	382.243
3133.08	400.974
3136.32	391.099
3139.55	429.806
3142.79	434.191
3146.03	447.16
3149.26	460.176
3152.49	487.522
3155.72	491.95
3158.95	552.692
3162.18	543.77
3165.41	573.981
3168.64	564.999
3171.86	616.08
3175.08	618.461
3178.31	636.988
3181.53	654.542
3184.75	674.028
3187.96	689.584
3191.18	707.967
3194.4	694.893
3197.61	740.878
3200.82	779.192
3204.03	776.589
3207.24	779.734
3210.45	783.877
3213.66	808.067
3216.86	822.817
3220.07	818.542
3223.27	862.815
3226.48	894.838
3229.68	887.881
3232.87	903.862
3236.07	918.796
3239.27	928.291
3242.47	940.718
3245.66	954.176
3248.85	940.958
3252.04	943.109
3255.23	994.911
3258.42	988.532
3261.61	1011.58
3264.8	990.536
3267.98	1044.78
3271.16	1011.97
3274.35	1005.84
3277.53	1052.24
3280.71	1062.09
3283.89	1046.86
3287.06	1067.94
3290.24	1081.24
3293.41	1087.99
3296.58	1112.78
3299.76	1100.41
3302.93	1096.03
3306.1	1157.89
3309.26	1190.1
3312.43	1169.77
3315.59	1120.9
3318.76	1160.31
3321.92	1215.72
3325.08	1230.33
3328.24	1265.75
3331.4	1258.59
3334.56	1320.53
3337.71	1306.03
3340.87	1328.48
3344.02	1355.64
3347.17	1356.77
3350.33	1376.24
3353.47	1421.12
3356.62	1447.35
3359.77	1453.87
3362.92	1430.44
3366.06	1510.78
3369.2	1531.83
3372.34	1569
3375.49	1570.56
3378.62	1557.09
3381.76	1608.92
3384.9	1603.97
3388.04	1618.12
3391.17	1663.53
3394.3	1621.87
3397.43	1697.01
3400.56	1668.16
3403.69	1677.39
3406.82	1704.87
3409.95	1725.88
3413.07	1727.88
3416.2	1737.96
3419.32	1759.38
3422.44	1750.14
3425.56	1767.2
3428.68	1754.32
3431.8	1778.41
3434.91	1792.57
3438.03	1755.61
3441.14	1780.02
3444.25	1722.35
3447.36	1728.19
3450.47	1772.14
3453.58	1742.37
3456.69	1724.04
3459.79	1712.11
3462.9	1695.41
3466	1718.55
3469.11	1680.65
3472.21	1644.3
3475.31	1628.54
3478.4	1636.58
3481.5	1561.47
3484.6	1583.86
3487.69	1505.3
3490.79	1553.56
3493.88	1488.12
3496.97	1455.7
3500.06	1416.56
3503.15	1410.54
3506.23	1357.09
3509.32	1326.36
3512.4	1296.09
3515.49	1263.22
3518.57	1236.37
3521.65	1225.14
3524.73	1212.27
3527.81	1153.35
3530.89	1152.2
3533.96	1107.37
3537.03	1077.91
3540.11	1026.8
3543.18	1019.79
3546.25	1002.99
3549.32	967.323
3552.39	918.077
3555.46	922.566
3558.52	867.646
3561.59	863.833
3564.65	827.569
3567.71	820.488
3570.77	777.738
3573.83	759.119
3576.89	733.909
3579.95	714.312
3583	685.159
3586.06	669.202
3589.11	648.513
3592.16	622.033
3595.21	616.406
3598.27	583.229
3601.31	561.454
3604.36	534.883
3607.41	530.044
3610.45	511.973
3613.5	486.328
3616.54	465.41
3619.58	486.088
3622.62	434.139
3625.66	425.644
3628.69	421.921
3631.73	375.784
3634.77	364.489
3637.8	340.185
3640.83	343.263
3643.86	307.828
3646.89	298.901
3649.92	279.461
3652.95	223.46
3655.98	210.078
3659	206.191
3662.02	190.961
3665.05	158.686
3668.07	160.117
3671.09	128.646
3674.11	127.352
3677.13	120.416
3680.14	99.3304
3683.16	95.2142
3686.17	102.448
3689.19	69.0162
3692.2	61.1177
3695.21	58.9049
3698.22	54.7347
3701.23	52.5222
3704.23	35.1214
3707.24	38.5963
3710.24	23.9903
3713.25	35.0292
3716.25	22.2652
3719.25	14.2723
3722.25	24.3343
3725.25	18.1987
3728.25	23.4704
3731.24	6.82666
3734.24	21.5903
3737.23	11.5724
3740.22	1.54298
3743.21	-8.50304
3746.21	-2.38431
3749.19	7.51352
3752.18	1.23544
3755.17	-7.88365
3758.15	-0.852417
3761.14	7.11624
3764.12	-6.73564
3767.1	-2.57042
3770.08	-15.4259
3773.06	10.5291
3776.04	-12.6803
3779.02	-8.45374
3781.99	-7.04919
3784.97	1.91309
3787.94	-5.16602
3790.91	-6.5665
3793.88	3.39157
3796.85	-5.5101
3799.82	4.47766
3802.79	-1.55371
3805.76	-0.0221405
3808.72	1.51616
3811.69	-15.8341
3814.65	-9.55577
3817.61	-6.10553
3820.57	-1.69788
3823.53	-0.122437
3826.49	-5.16313
3829.45	-9.25948
3832.4	6.5545
3835.36	-0.372574
3838.31	1.24863
3841.26	9.52515
3844.21	1.63989
3847.16	9.92859
3850.11	-4.62767
3853.06	5.59232
3856	7.24335
3858.95	13.6736
3861.89	4.82021
3864.84	-2.14886
3867.78	11.9371
3870.72	-0.807007
3873.66	1.76756
3876.6	4.33662
3879.53	11.6869
3882.47	-10.7586
3885.4	2.31288
3888.34	-0.00418091
3891.27	-2.3317
3894.2	6.87007
3897.13	18.9336
3900.06	12.6997
3902.99	12.2308
3905.91	13.6554
3908.84	12.2195
3911.76	21.3352
3914.69	15.0541
3917.61	8.75786
3920.53	20.7446
3923.45	18.2851
3926.37	12.9255
3929.28	29.6046
3932.2	25.1672
3935.11	18.8637
3938.03	19.3025
3940.94	9.24371
3943.85	12.5683
3946.76	22.6005
3949.67	14.4572
3952.58	26.4316
3955.49	16.3856
3958.39	21.6758
3961.3	28.8905
3964.2	8.31638
3967.1	24.173
3970	22.7793
3972.9	33.8647
3975.8	12.301
3978.7	34.8954
3981.6	12.3191
3984.49	32.02
3987.39	40.1781
3990.28	36.7899
3993.17	17.0139
3996.06	20.3546
3998.95	26.5754
4001.84	27.9913
4004.73	17.8479
4007.61	35.6429
4010.5	29.3526
4013.38	18.2275
4016.27	37.9591
4019.15	24.8895
4022.03	21.4573
4024.91	42.1631
4027.79	32.932
4030.66	33.3542
4033.54	23.1389
4036.42	27.4229
4039.29	32.682
4042.16	26.315
4045.03	21.8426
4047.9	27.0607
4050.77	23.561
4053.64	37.5224
4056.51	31.128
4059.38	34.4265
4062.24	12.4532
4065.1	33.2237
4067.97	28.7213
4070.83	21.2865
4073.69	31.3601
4076.55	30.7199
4079.41	34.9425
4082.26	23.5658
4085.12	27.777
4087.97	29.0507
4090.83	25.4378
4093.68	32.5681
4096.53	13.3123
4099.38	26.2895
4102.23	27.5374
4105.08	30.7297
4107.93	26.0709
4110.77	26.2962
4113.62	29.4331
4116.46	30.5881
4119.3	10.1812
4122.14	27.9364
4124.98	40.8116
4127.82	19.4343
4130.66	33.3279
4133.5	29.6251
4136.33	26.9429
4139.17	29.9373
4142	30.796
4144.83	24.9943
4147.67	30.0397
4150.5	29.2217
4153.33	38.1542
4156.15	31.3481
4158.98	32.295
4161.81	33.288
4164.63	27.4567
4167.45	23.5746
4170.28	25.5622
4173.1	37.3325
4175.92	33.4546
4178.74	25.6592
4181.56	30.5844
4184.37	17.905
4187.19	22.8342
4190	32.6566
4192.82	36.6311
4195.63	22.0172
4198.44	40.7209
4201.25	31.004
4204.06	28.143
4206.87	33.1199
4209.68	12.5624
4212.48	27.3492
4215.29	34.2784
4218.1	34.4219
4220.9	17.807
4223.7	30.7284
4226.5	21.9247
4229.3	6.20557
4232.1	27.0638
4234.9	37.0879
4237.69	27.3073
4240.49	25.4457
4243.28	31.5342
4246.07	14.7411
4248.87	38.7718
4251.66	21.9087
4254.45	34.9807
4257.24	21.0437
4260.03	41.1281
4262.81	36.1884
4265.6	16.1784
4268.38	22.2657
4271.17	22.3228
4273.95	26.4017
4276.73	24.3992
4279.51	10.246
4282.29	26.369
4285.07	14.1797
4287.84	18.139
4290.62	25.1164
4293.39	32.0873
4296.17	22.8734
4298.94	19.7435
4301.71	14.5636
4304.48	17.4903
4307.25	17.3702
4310.02	26.3978
4312.79	26.3005
4315.55	13.9688
4318.32	9.74615
4321.08	4.48836
4323.85	36.8818
4326.61	5.12355
4329.37	15.1141
4332.13	12.865
4334.89	11.6392
4337.65	12.434
4340.4	17.3317
4343.16	30.3894
4345.91	15.9358
4348.67	10.6672
4351.42	30.9134
4354.17	25.6915
4356.92	22.4904
4359.67	4.9619
4362.42	15.0349
4365.17	14.8933
4367.91	13.7134
4370.66	13.5714
4373.4	18.5312
4376.14	21.4356
4378.89	15.0863
4381.63	16.9444
4384.37	5.4547
4387.11	7.35588
4389.84	21.6774
4392.58	7.2058
4395.32	21.726
4398.05	18.6022
4400.78	15.4502
4403.52	8.13036
4406.25	2.87733
4408.98	12.1658
4411.71	6.89755
4414.44	9.92378
4417.16	3.57027
4419.89	-10.1533
4422.62	11.6021
4425.34	-0.00570679
4428.06	6.1344
4430.78	11.2401
4433.51	16.3521
4436.22	-0.523056
4438.94	4.57596
4441.66	6.52234
4444.38	7.42781
4447.1	2.03094
4449.81	-3.36876
4452.52	10.1215
4455.24	-3.6958
4457.95	7.6904
4460.66	11.719
4463.37	8.41368
4466.08	8.26328
4468.78	13.3881
4471.49	1.68327
4474.2	6.84081
4476.9	3.59146
4479.6	7.74005
4482.31	-16.5942
4485.01	-8.20888
4487.71	11.8116
4490.41	0.118454
4493.11	2.138
4495.8	14.716
4498.5	-0.191971
4501.19	8.1951
4503.89	2.79791
4506.58	16.5044
4509.27	-1.58571
4511.96	-5.89032
4514.66	-4.88112
4517.34	14.1956
4520.03	3.55005
4522.72	2.48808
4525.41	6.75101
4528.09	0.375427
4530.77	-1.7345
4533.46	6.82336
4536.14	-0.594803
4538.82	9.06842
4541.5	-1.53232
4544.18	1.75375
4546.86	-1.36124
4549.53	-4.47264
4552.21	-11.8556
4554.88	0.0997925
4557.56	-10.4511
4560.23	-0.527924
4562.9	-0.236816
4565.57	4.43379
4568.24	-5.97008
4570.91	1.93901
4573.58	2.08517
4576.24	-3.27641
4578.91	4.48604
4581.58	-6.14847
4584.24	-0.420929
4586.9	-3.49611
4589.56	8.69002
4592.22	0.150146
4594.88	-6.19977
4597.54	-8.15448
4600.2	15.0194
4602.86	-3.30405
4605.51	-4.11658
4608.17	2.75166
4610.82	-15.5885
4613.47	3.37576
4616.13	1.49768
4618.78	-5.86749
4621.43	3.28946
4624.07	-11.7821
4626.72	-9.23395
4629.37	-1.16039
4632.01	-9.64429
4634.66	9.48759
4637.3	16.4684
4639.94	-5.31685
4642.59	-3.85873
4645.23	5.40657
4647.87	0.316833
4650.5	10.8191
4653.14	2.5027
4655.78	-0.304291
4658.42	7.83241
4661.05	-0.616119
4663.68	3.24219
4666.31	5.97954
4668.95	1.97142
4671.58	10.2979
4674.21	7.43558
4676.84	10.1821
4679.46	-7.26454
4682.09	-2.27179
4684.72	-8.50348
4687.34	13.3824
4689.97	3.79274
4692.59	6.59085
4695.21	7.12987
4697.83	13.3135
4700.45	8.22855
4703.07	8.78632
4705.69	21.7665
4708.3	21.193
4710.92	-2.00766
4713.54	18.9141
4716.15	16.0752
4718.76	14.363
4721.37	14.9171
4723.99	10.9315
4726.59	9.23883
4729.2	0.752747
4731.81	20.6425
4734.42	28.0641
4737.03	34.3547
4739.63	22.4535
4742.23	15.09
4744.84	19.0855
4747.44	19.6628
4750.04	23.6301
4752.64	15.0877
4755.24	21.3389
4757.84	24.1759
4760.44	17.9235
4763.03	21.9309
4765.63	12.2806
4768.22	30.009
4770.82	21.5489
4773.41	22.1681
4776	27.3557
4778.59	16.5604
4781.18	24.0303
4783.77	23.5046
4786.36	25.265
4788.94	29.3117
4791.53	25.3528
4794.11	9.94077
4796.7	35.7616
4799.28	11.1758
4801.86	34.7533
4804.44	39.9997
4807.02	17.6814
4809.6	26.3938
4812.18	28.2011
4814.76	25.3998
4817.33	34.1377
4819.91	25.5613
4822.48	27.3675
4825.06	32.6465
4827.63	29.8011
4830.2	31.583
4832.77	24.0679
4835.34	37.4909
4837.91	36.9586
4840.48	25.9066
4843.04	32.3551
4845.61	35.2597
4848.17	29.9207
4850.74	39.7796
4853.3	37.7686
4855.86	29.8646
4858.42	30.3359
4860.98	35.4949
4863.54	39.4205
4866.1	32.6368
4868.66	40.0114
4871.21	27.2958
4873.77	39.3727
4876.32	26.5226
4878.88	44.4747
4881.43	41.042
4883.98	39.9405
4886.53	20.9758
4889.08	28.1266
4891.63	31.6849
4894.18	34.0165
4896.72	41.0771
4899.27	33.799
4901.81	24.0888
4904.36	42.9651
4906.9	29.5844
4909.44	34.0567
4911.98	39.6517
4914.52	30.8565
4917.06	29.1683
4919.6	29.8397
4922.14	40.0233
4924.67	22.6809
4927.21	28.002
4929.74	12.937
4932.28	25.3482
4934.81	40.1409
4937.34	29.7468
4939.87	28.8621
4942.4	18.2741
4944.93	10.0689
4947.46	16.201
4949.99	17.4797
4952.51	27.1034
4955.04	19.8584
4957.56	19.7699
4960.08	17.2274
4962.61	18.2349
4965.13	16.8137
4967.65	4.50989
4970.17	2.91971
4972.69	6.07083
4975.2	-2.93234
4977.72	-7.19406
4980.24	4.19609
4982.75	2.20595
4985.27	-10.7757
4987.78	-0.803925
4990.29	-0.612289
4992.8	-10.2403
4995.31	-21.1964
4997.82	-17.619