File: Data/3-Raman/processed/bu19w-d-ore2-fi13-v_150 (500nm)_532nm_edge_100%_x100_vis_lwd_h50um_30sx2_01_0.txt
#Acq. time (s)=	30
#Accumulations=	2
#Range (cm-¹)=	100...4000
#Windows=	1
#Auto scanning=	Off
#Autofocus=	Off
#Macrospot=	Off
#AutoExposure=	Off
#Spike filter=	Multiple accum.
#Delay time (s)=	2
#Binning=	1
#Readout mode=	Signal
#DeNoise=	Off
#ICS correction=	On
#Dark correction=	Off
#Inst. Process=	Off
#Detector Gain=	Best Dynamic
#Detector ADC=	50 kHz HS
#Detector temperature (°C)=	-60.09
#Instrument=	LabRAM HR Evol
#Detector=	SIN-EM FIVIS
#Objective=	x100_VIS_LWD
#Grating=	150 (500nm)
#ND Filter=	100%
#Laser=	532nm_Edge
#Hole=	49.98
#Temperature=	0
#Range=	Visible
#StageXY=	75x50mm Scan+
#StageZ=	Z motor
#X (µm)=	0
#Y (µm)=	0
#Z (µm)=	14.4
#Full time(mm:ss)=	1:05
#Project=	21_11_22
#Sample=	BU19w
#Site=
#Title=	BU19w-D-FFore2-FI13-V_150 (500nm)_532nm_Edge_100%_x100_VIS_LWD_H50um_30sX2
#Remark=
#Date=	22.11.2021 14:10
#Acquired=	22.11.2021 14:10:01
#Base:Fit=	16.12.2021 17:39:50
#Base:Edit=	16.12.2021 17:40:44
#Base:Edit=	16.12.2021 17:40:45
#Base:Edit=	16.12.2021 17:40:47
#Base:Sub=	16.12.2021 17:40:50
103.97	307.915
108.592	2350.09
113.209	3678.1
117.826	1955.03
122.441	461.579
127.054	164.012
131.664	125.767
136.27	69.3445
140.876	1.15625
145.48	51.175
150.081	112.381
154.678	308.917
159.275	567.014
163.869	924.494
168.461	1487.81
173.049	2446.77
177.637	3858.94
182.222	5701.08
186.806	7579.38
191.384	8342.94
195.963	7397.17
200.54	5832.92
205.112	3985.31
209.684	2692.93
214.253	1862.71
218.821	1380.84
223.384	963.409
227.947	780.307
232.507	658.143
237.064	583.527
241.62	795.444
246.174	1301.96
250.724	1445.7
255.273	844.611
259.82	288.545
264.363	127.214
268.906	90.166
273.447	42.5537
277.983	7.50513
282.519	-2.73898
287.051	2.19946
291.583	1.70721
296.112	-2.04956
300.637	6.74738
305.162	45.0695
309.685	18.5403
314.204	20.2472
318.722	32.8674
323.236	48.7588
327.75	89.8066
332.262	266.566
336.77	919.583
341.277	1574.29
345.78	1080.81
350.283	457.205
354.782	238.374
359.28	192.07
363.775	194.48
368.269	179.867
372.761	223.273
377.249	314.783
381.736	385.447
386.22	600.073
390.703	563.134
395.182	363.839
399.661	260.477
404.136	301.245
408.61	312.021
413.08	359.416
417.551	412.547
422.017	566.192
426.482	876.7
430.944	1440.78
435.406	2649.57
439.863	5667.4
444.32	14457.3
448.773	25365.5
453.226	23208.6
457.674	12150.4
462.121	5575.37
466.567	3208.87
471.009	2187.8
475.452	1568.25
479.889	1266.37
484.327	981.672
488.761	866.394
493.194	911.624
497.623	985.179
502.051	866.751
506.478	628.287
510.9	497.374
515.323	421.986
519.742	390.683
524.158	323.715
528.574	336.572
532.987	309.056
537.397	261.819
541.807	242.294
546.212	223.907
550.618	229.817
555.019	199.471
559.419	207.547
563.818	191.46
568.213	192.265
572.606	199.817
576.999	205.637
581.388	193.963
585.775	169.079
590.161	161.08
594.544	161.991
598.924	137.994
603.304	130.561
607.68	132.099
612.055	127.48
616.426	115.951
620.798	132.638
625.166	111.764
629.532	82.5041
633.897	113.587
638.258	98.0551
642.618	80.1764
646.975	81.6203
651.332	57.7901
655.685	69.8056
660.036	77.472
664.385	85.0092
668.734	85.7001
673.079	99.8208
677.421	156.601
681.762	232.019
686.1	198.596
690.439	127.011
694.773	74.6268
699.105	55.5951
703.435	31.5199
707.763	24.5432
712.091	38.8404
716.415	40.5907
720.737	22.9536
725.057	43.3888
729.375	36.8584
733.692	13.8088
738.006	34.302
742.317	30.5137
746.627	30.0026
750.934	52.8684
755.24	49.9132
759.543	53.8218
763.846	67.4721
768.146	104.166
772.443	129.987
776.738	220.451
781.031	308.469
785.322	390.078
789.611	637.359
793.898	968.137
798.183	768.205
802.466	443.057
806.748	187.706
811.027	139.206
815.304	98.5087
819.579	88.61
823.851	99.7633
828.122	83.4604
832.391	87.015
836.657	83.9552
840.922	86.3965
845.184	68.8825
849.445	77.6358
853.703	76.4855
857.96	96.289
862.214	110.526
866.467	105.928
870.717	80.4126
874.965	75.7335
879.212	79.7792
883.456	67.295
887.699	41.6324
891.939	57.2329
896.177	41.846
900.414	53.3406
904.648	64.4322
908.88	49.0377
913.111	53.3978
917.339	29.6087
921.565	31.7057
925.79	6.68164
930.012	3.60538
934.232	16.6191
938.451	26.3102
942.667	0.659164
946.881	-1.43332
951.094	8.28682
955.302	-4.33948
959.511	7.55894
963.717	-7.08727
967.921	4.85277
972.124	14.7098
976.324	2.33218
980.523	4.84773
984.719	-0.0507813
988.914	-6.00154
993.104	-1.205
997.295	-2.60602
1001.48	-2.90613
1005.67	12.7509
1009.85	5.05547
1014.04	-2.73953
1018.22	23.5565
1022.4	23.1673
1026.57	22.6629
1030.75	31.7044
1034.92	41.5395
1039.09	56.4904
1043.26	67.1317
1047.42	123.317
1051.59	162.238
1055.75	188.175
1059.91	237.07
1064.07	455.952
1068.23	712.245
1072.38	595.703
1076.54	262.112
1080.69	132.021
1084.84	100.128
1088.98	80.8822
1093.13	71.0948
1097.27	73.7755
1101.41	54.9648
1105.55	50.6106
1109.69	40.2868
1113.83	36.1057
1117.96	44.4635
1122.09	55.1201
1126.22	54.6285
1130.35	65.4647
1134.47	92.658
1138.6	152.745
1142.72	289.23
1146.84	367.278
1150.96	253.327
1155.07	139.002
1159.19	69.9214
1163.3	57.4864
1167.41	58.3935
1171.52	43.7314
1175.62	51.6925
1179.73	38.0002
1183.83	43.7961
1187.93	42.2407
1192.03	51.8719
1196.13	59.3272
1200.22	56.4765
1204.31	65.7937
1208.4	72.0119
1212.49	100.42
1216.58	108.531
1220.67	101.552
1224.75	98.6521
1228.83	90.8455
1232.91	76.2215
1236.99	72.7749
1241.06	80.2356
1245.14	93.7396
1249.21	115.36
1253.28	118.061
1257.35	95.8074
1261.41	111.551
1265.48	184.419
1269.54	463.948
1273.6	392.898
1277.66	128.787
1281.72	75.221
1285.77	74.8262
1289.82	58.2795
1293.88	59.7912
1297.92	65.2986
1301.97	62.6871
1306.02	59.0285
1310.06	59.368
1314.1	57.5982
1318.14	55.7617
1322.18	51.8333
1326.22	71.9697
1330.25	62.9252
1334.28	66.8439
1338.31	70.6942
1342.34	67.4995
1346.37	75.2611
1350.39	74.0292
1354.42	96.6389
1358.44	120.129
1362.46	143.559
1366.47	213.412
1370.49	522.017
1374.5	824.077
1378.51	459.726
1382.52	119.792
1386.53	88.2742
1390.54	84.3706
1394.54	125.848
1398.55	121.045
1402.55	71.8678
1406.55	67.0251
1410.54	64.1599
1414.54	59.3131
1418.53	53.4598
1422.52	51.5172
1426.51	45.5184
1430.5	66.1677
1434.49	52.2571
1438.47	56.1042
1442.45	48.0726
1446.43	59.753
1450.41	56.5906
1454.39	45.5084
1458.36	40.3119
1462.34	45.8811
1466.31	42.5623
1470.28	41.2331
1474.24	34.9749
1478.21	39.4737
1482.17	31.2187
1486.14	43.4879
1490.1	35.2326
1494.05	42.5953
1498.01	37.2936
1501.97	42.7304
1505.92	48.2047
1509.87	34.261
1513.82	25.1904
1517.77	47.1944
1521.71	36.2119
1525.66	45.6088
1529.6	52.113
1533.54	41.1724
1537.48	37.0201
1541.41	51.2784
1545.35	52.9347
1549.28	49.7439
1553.21	55.2458
1557.14	62.6444
1561.07	58.3962
1565	72.5027
1568.92	52.7455
1572.84	63.9125
1576.76	81.8085
1580.68	57.2391
1584.6	72.1954
1588.51	60.1623
1592.43	59.6868
1596.34	93.8046
1600.25	90.4359
1604.16	95.7448
1608.06	86.6736
1611.97	76.6693
1615.87	95.4471
1619.77	94.0902
1623.67	87.023
1627.57	82.8681
1631.46	79.7443
1635.36	97.6817
1639.25	91.7427
1643.14	92.5671
1647.03	82.8743
1650.91	89.4939
1654.8	74.9843
1658.68	65.2496
1662.56	70.8439
1666.44	64.878
1670.32	55.0009
1674.2	59.5238
1678.07	44.7241
1681.94	33.7214
1685.81	47.6561
1689.68	47.1537
1693.55	38.9679
1697.41	24.0865
1701.28	22.5641
1705.14	21.9598
1709	29.8682
1712.86	35.8465
1716.72	19.1104
1720.57	17.5531
1724.42	15.0485
1728.28	21.9264
1732.13	21.2839
1735.97	15.0161
1739.82	11.5562
1743.66	7.19073
1747.51	13.1704
1751.35	1.57201
1755.19	9.57318
1759.02	7.64951
1762.86	5.65002
1766.69	22.2633
1770.53	12.9748
1774.36	-9.34464
1778.18	17.7286
1782.01	17.8539
1785.84	-1.62868
1789.66	16.2994
1793.48	8.02922
1797.3	-4.0313
1801.12	-3.04836
1804.94	12.0417
1808.75	1.69537
1812.57	9.22826
1816.38	8.20509
1820.19	-1.35811
1824	-2.45775
1827.8	7.71713
1831.61	12.1823
1835.41	-0.334351
1839.21	-3.44521
1843.01	-0.948959
1846.81	3.43661
1850.6	4.9324
1854.4	-0.169662
1858.19	10.557
1861.98	5.3925
1865.77	16.9854
1869.56	-5.73207
1873.34	0.349655
1877.13	11.9673
1880.91	3.34322
1884.69	-2.47562
1888.47	-3.49995
1892.25	13.9123
1896.02	0.958023
1899.8	4.64212
1903.57	3.77031
1907.34	-2.60675
1911.11	8.5896
1914.88	-5.0901
1918.64	-8.53264
1922.41	16.7529
1926.17	11.5464
1929.93	-5.74458
1933.69	-2.6088
1937.44	-10.6649
1941.2	11.1756
1944.95	4.9994
1948.7	3.35049
1952.46	-3.06548
1956.2	5.4556
1959.95	16.7305
1963.7	11.0904
1967.44	-3.04152
1971.18	18.4167
1974.92	-0.488083
1978.66	6.82259
1982.4	16.8898
1986.13	15.709
1989.87	14.5074
1993.6	3.04521
1997.33	8.29922
2001.06	7.9798
2004.78	13.1992
2008.51	19.2684
2012.23	10.5996
2015.96	19.4918
2019.67	17.4684
2023.39	7.31749
2027.11	8.19872
2030.83	11.8864
2034.54	12.9227
2038.25	10.2732
2041.96	12.1949
2045.67	5.87477
2049.38	16.9923
2053.08	18.9713
2056.79	18.2886
2060.49	15.8992
2064.19	2.51996
2067.89	8.45718
2071.58	9.80573
2075.28	25.0405
2078.97	20.8962
2082.67	13.0039
2086.36	10.4677
2090.05	10.5949
2093.73	6.16612
2097.42	21.2468
2101.1	16.7319
2104.78	12.1845
2108.47	15.9782
2112.14	25.3407
2115.82	13.3026
2119.5	18.8526
2123.17	28.0555
2126.84	13.1176
2130.52	12.0774
2134.18	22.1225
2137.85	22.8787
2141.52	5.17094
2145.18	12.3481
2148.84	13.9874
2152.51	14.7109
2156.17	5.37164
2159.82	27.1563
2163.48	14.2277
2167.14	13.2156
2170.79	16.8317
2174.44	27.7774
2178.09	8.70433
2181.74	6.01933
2185.38	5.19147
2189.03	13.5325
2192.67	12.8512
2196.32	12.2154
2199.96	17.9811
2203.59	11.9195
2207.23	32.383
2210.87	5.32811
2214.5	13.0423
2218.13	15.2738
2221.76	22.1188
2225.39	9.63138
2229.02	21.0897
2232.65	12.2722
2236.27	10.8255
2239.89	13.0748
2243.51	12.5383
2247.13	12.9347
2250.75	1.24162
2254.37	8.18477
2257.98	6.73616
2261.59	12.7516
2265.2	6.60486
2268.81	15.5114
2272.42	2.75546
2276.03	7.81856
2279.64	3.34863
2283.24	11.1245
2286.84	11.3566
2290.44	19.1266
2294.04	11.7664
2297.64	13.8724
2301.23	12.1623
2304.83	-0.0153656
2308.42	11.4721
2312.01	34.3083
2315.6	92.1715
2319.19	77.9426
2322.77	42.7691
2326.36	25.5918
2329.94	14.1019
2333.52	13.9289
2337.1	19.3808
2340.68	5.99263
2344.26	16.0863
2347.83	3.64647
2351.41	7.13658
2354.98	16.2003
2358.55	6.58803
2362.12	10.021
2365.69	-0.466248
2369.25	16.9034
2372.82	21.2627
2376.38	16.3754
2379.94	15.2111
2383.5	14.987
2387.06	24.897
2390.61	10.9587
2394.17	22.7711
2397.72	14.4676
2401.27	21.8407
2404.82	0.832199
2408.37	11.0503
2411.92	14.9052
2415.47	17.8874
2419.01	5.26454
2422.55	10.1506
2426.09	8.63402
2429.63	5.29559
2433.17	10.3194
2436.71	12.5969
2440.24	20.4827
2443.78	18.1424
2447.31	9.27193
2450.84	9.76686
2454.37	8.2818
2457.89	2.86978
2461.42	3.0683
2464.94	2.19797
2468.47	4.25594
2471.99	10.8087
2475.51	4.0732
2479.03	7.74872
2482.54	3.82556
2486.06	12.9723
2489.57	8.07622
2493.08	-5.32173
2496.59	4.76924
2500.1	14.7937
2503.61	9.802
2507.12	1.99393
2510.62	10.0363
2514.12	18.0897
2517.62	15.0185
2521.12	10.9044
2524.62	11.5997
2528.12	11.4161
2531.61	14.9461
2535.11	15.7576
2538.6	6.45573
2542.09	0.924713
2545.58	16.7072
2549.07	3.86572
2552.55	5.84229
2556.04	7.91682
2559.52	-0.218887
2563	-0.870071
2566.48	11.5756
2569.96	9.17615
2573.44	2.10953
2576.91	7.2533
2580.39	0.181107
2583.86	0.630585
2587.33	14.3221
2590.8	4.21803
2594.27	4.50757
2597.74	4.85197
2601.2	-10.1273
2604.67	8.30487
2608.13	9.3653
2611.59	8.35695
2615.05	5.50739
2618.51	0.654037
2621.96	-4.23328
2625.42	3.32089
2628.87	3.15849
2632.32	-7.60156
2635.77	7.48726
2639.22	2.40305
2642.67	7.81047
2646.11	2.68878
2649.56	-6.27162
2653	8.54041
2656.44	-6.17911
2659.88	8.50983
2663.32	6.09958
2666.76	-1.96037
2670.19	-6.23579
2673.63	-7.65143
2677.06	5.94173
2680.49	0.824203
2683.92	6.04123
2687.35	-10.085
2690.78	-2.82523
2694.2	1.58653
2697.63	-6.06726
2701.05	-2.54092
2704.47	-0.889359
2707.89	2.74878
2711.31	-6.60271
2714.72	5.4818
2718.14	-12.2038
2721.55	4.61432
2724.96	-6.53748
2728.37	1.93129
2731.78	1.04643
2735.19	-0.779175
2738.6	-18.5632
2742	-11.0629
2745.41	-0.75943
2748.81	-1.72319
2752.21	7.64818
2755.61	-7.47371
2759	2.82851
2762.4	2.72377
2765.8	2.59123
2769.19	-5.11378
2772.58	5.07002
2775.97	-3.62248
2779.36	-2.92009
2782.75	-7.88042
2786.13	-3.43831
2789.52	-2.76869
2792.9	2.58647
2796.28	-6.14464
2799.66	2.92706
2803.04	12.9219
2806.42	-14.57
2809.79	4.76299
2813.17	-6.80461
2816.54	1.25629
2819.91	-6.5394
2823.28	3.42085
2826.65	4.98947
2830.02	-0.87709
2833.38	0.743759
2836.75	-5.0602
2840.11	-0.585373
2843.47	2.99811
2846.83	-2.67995
2850.19	1.0163
2853.55	-1.84911
2856.91	1.8477
2860.26	-0.0431824
2863.61	1.81577
2866.96	-4.76476
2870.31	11.1706
2873.66	13.9668
2877.01	14.8788
2880.36	-1.17612
2883.7	6.29988
2887.05	10.0046
2890.39	4.26073
2893.73	16.4204
2897.07	15.322
2900.4	15.1356
2903.74	4.51277
2907.07	-0.453094
2910.41	8.75726
2913.74	13.2228
2917.07	-1.26711
2920.4	18.284
2923.73	3.76921
2927.05	14.748
2930.38	14.359
2933.7	8.27234
2937.02	13.5063
2940.34	21.5556
2943.66	6.05913
2946.98	15.9901
2950.3	23.0757
2953.61	30.151
2956.92	20.3499
2960.24	19.023
2963.55	16.7643
2966.86	27.6915
2970.16	22.7196
2973.47	25.2457
2976.78	14.6795
2980.08	22.8464
2983.38	38.5354
2986.68	44.8545
2989.98	30.5189
2993.28	42.49
2996.58	41.3212
2999.87	41.0876
3003.17	36.1448
3006.46	52.8615
3009.75	47.0041
3013.04	47.7397
3016.33	52.238
3019.62	57.6772
3022.91	48.0194
3026.19	65.7369
3029.47	63.6254
3032.75	63.3868
3036.03	70.7019
3039.31	77.0764
3042.59	95.764
3045.87	77.5367
3049.14	83.9206
3052.42	89.3695
3055.69	79.6352
3058.96	107.75
3062.23	102.704
3065.49	113.753
3068.76	110.519
3072.03	114.553
3075.29	109.448
3078.55	119.377
3081.81	133.396
3085.07	151.2
3088.33	151.076
3091.59	156.725
3094.85	155.201
3098.1	172.947
3101.35	156.37
3104.61	183.73
3107.85	191.08
3111.1	206.856
3114.35	218.864
3117.6	215.649
3120.84	219.097
3124.09	233.017
3127.33	238.348
3130.57	259.887
3133.81	259.495
3137.05	270.513
3140.28	292.963
3143.52	307.786
3146.75	304.526
3149.99	332.75
3153.22	345.691
3156.45	336.709
3159.68	351.553
3162.9	365.452
3166.13	400.29
3169.35	404.543
3172.58	400.181
3175.8	428.2
3179.02	411.362
3182.24	458.45
3185.46	492.083
3188.67	496.124
3191.89	475.381
3195.1	500.365
3198.32	508.169
3201.53	520.757
3204.74	528.601
3207.95	526.956
3211.15	556.757
3214.36	551.406
3217.56	582.203
3220.77	593.992
3223.97	564.011
3227.17	587.312
3230.37	602.127
3233.57	618.769
3236.76	609.913
3239.96	645.851
3243.15	618.992
3246.35	642.615
3249.54	649.186
3252.73	671.055
3255.92	661.438
3259.1	670.782
3262.29	678.095
3265.47	697.697
3268.66	700.965
3271.84	702.26
3275.02	707.378
3278.2	730.442
3281.38	726.57
3284.55	753.262
3287.73	717.845
3290.9	734.022
3294.08	765.387
3297.25	753.86
3300.42	760.703
3303.59	778.686
3306.76	780.392
3309.92	783.83
3313.09	795.742
3316.25	810.459
3319.41	848.804
3322.58	852.052
3325.74	861.925
3328.9	855.73
3332.05	898.75
3335.21	889.879
3338.36	895.265
3341.52	946.861
3344.67	927.998
3347.82	966.02
3350.97	966.304
3354.12	980.876
3357.26	995.507
3360.41	996.164
3363.55	1006.28
3366.7	1034.4
3369.84	1065.41
3372.98	1073.95
3376.12	1063.68
3379.26	1112.07
3382.39	1081.95
3385.53	1109.64
3388.66	1127.91
3391.8	1124.42
3394.93	1132.77
3398.06	1184.63
3401.19	1151.31
3404.31	1186.46
3407.44	1200.86
3410.56	1220.04
3413.69	1196.97
3416.81	1192.85
3419.93	1238.21
3423.05	1219.37
3426.17	1214.57
3429.29	1228.68
3432.41	1193.81
3435.52	1247.34
3438.63	1214.2
3441.75	1230.7
3444.86	1244.96
3447.97	1183.88
3451.08	1194.09
3454.18	1168.1
3457.29	1188.55
3460.39	1176.64
3463.5	1175.12
3466.6	1177.23
3469.7	1148.67
3472.8	1114.02
3475.9	1085.18
3479	1119.83
3482.09	1059.02
3485.19	1070.16
3488.28	1018.24
3491.37	1022.43
3494.46	998.29
3497.55	969.351
3500.64	983.881
3503.73	951.991
3506.81	893.804
3509.9	872.021
3512.98	888.027
3516.06	837.3
3519.14	822.738
3522.22	826.048
3525.3	760.888
3528.38	753.667
3531.46	716.059
3534.53	701.559
3537.6	691.819
3540.67	674.114
3543.75	656.136
3546.82	600.172
3549.88	602.537
3552.95	601.978
3556.02	570.356
3559.08	557.678
3562.14	524.921
3565.21	501.508
3568.27	484.981
3571.33	469.044
3574.39	455.993
3577.44	447.641
3580.5	428.814
3583.55	421.316
3586.61	404.354
3589.66	384.482
3592.71	366.518
3595.76	362.732
3598.81	343.817
3601.85	317.295
3604.9	321.993
3607.95	316.298
3610.99	293.584
3614.03	271.835
3617.07	280.36
3620.11	237.033
3623.15	236.215
3626.19	221.315
3629.22	195.117
3632.26	195.292
3635.29	174.897
3638.33	177.173
3641.36	144.699
3644.39	136.83
3647.42	110.973
3650.44	113.473
3653.47	102.243
3656.5	96.6022
3659.52	76.8122
3662.54	56.9549
3665.56	39.7607
3668.58	47.1609
3671.6	28.1862
3674.62	18.6639
3677.64	8.22028
3680.65	-3.17924
3683.67	-5.11623
3686.68	-7.03059
3689.69	-7.97629
3692.7	-14.5842
3695.71	-32.6118
3698.72	-26.879
3701.73	-27.7666
3704.73	-39.0878
3707.74	-31.4241
3710.74	-41.8176
3713.74	-44.6219
3716.75	-36.9276
3719.75	-46.3718
3722.74	-45.3481
3725.74	-50.9918
3728.74	-48.0622
3731.73	-57.5144
3734.73	-53.6398
3737.72	-47.8622
3740.71	-42.095
3743.7	-47.7467
3746.69	-49.5932
3749.68	-50.4867
3752.66	-38.0748
3755.65	-55.0731
3758.63	-53.0748
3761.62	-54.8714
3764.6	-41.4978
3767.58	-41.3639
3770.56	-46.8753
3773.54	-50.4658
3776.51	-52.1419
3779.49	-44.3492
3782.46	-50.7147
3785.44	-51.3934
3788.41	-55.83
3791.38	-46.0749
3794.35	-51.4004
3797.32	-43.4975
3800.29	-45.95
3803.25	-48.3911
3806.22	-44.2128
3809.18	-32.4578
3812.14	-29.1973
3815.11	-32.5502
3818.07	-37.7922
3821.03	-34.5155
3823.98	-38.8039
3826.94	-29.8271
3829.9	-36.022
3832.85	-25.1297
3835.8	-30.3659
3838.76	-22.3093
3841.71	-24.7143
3844.66	-22.3688
3847.61	-27.6449
3850.55	-17.6758
3853.5	-8.65308
3856.45	-18.7294
3859.39	-14.496
3862.33	-22.7207
3865.27	-20.4419
3868.21	-18.1917
3871.15	-7.33092
3874.09	-14.7162
3877.03	-8.70786
3879.96	-3.69408
3882.9	-19.8638
3885.83	-13.9715
3888.77	-10.994
3891.7	-16.7053
3894.63	-9.9646
3897.56	3.4568
3900.48	-1.42847
3903.41	1.31981
3906.34	2.1321
3909.26	3.85136
3912.18	3.59392
3915.1	-2.4823
3918.02	-0.882309
3920.94	1.59895
3923.86	-8.45886
3926.78	-2.26883
3929.7	0.0189209
3932.61	5.16345
3935.52	9.32513
3938.44	9.63338
3941.35	-6.41277
3944.26	3.33948
3947.17	0.597031
3950.08	-5.07283
3952.98	7.38878
3955.89	6.38844
3958.79	9.15443
3961.7	7.06102
3964.6	-4.6929
3967.5	-3.09874
3970.4	-1.58156
3973.3	7.52979
3976.2	2.1385
3979.09	0.483688
3981.99	4.49879
3984.88	-5.05338
3987.78	-0.286392
3990.67	1.46779
3993.56	-4.54822
3996.45	-4.90666
3999.34	-10.1828