File: Data/3-Raman/processed/bu19w-b-ff1-fi10-v_150 (500nm)_532nm_edge_100%_x100_vis_h50um_15sx2_01.txt
#Acq. time (s)=	15
#Accumulations=	2
#Range (cm-¹)=	100...5000
#Windows=	1
#Auto scanning=	Off
#Autofocus=	Off
#Macrospot=	Off
#AutoExposure=	Off
#Spike filter=	Multiple accum.
#Delay time (s)=	2
#Binning=	1
#Readout mode=	Signal
#DeNoise=	Off
#ICS correction=	On
#Dark correction=	Off
#Inst. Process=	Off
#Detector Gain=	Best Dynamic
#Detector ADC=	50 kHz HS
#Detector temperature (°C)=	-60.09
#Instrument=	LabRAM HR Evol
#Detector=	SIN-EM FIVIS
#Objective=	x100_VIS
#Grating=	150 (500nm)
#ND Filter=	100%
#Laser=	532nm_Edge
#Hole=	49.98
#Temperature=	0
#Range=	Visible
#StageXY=	75x50mm Scan+
#StageZ=	Z motor
#X (µm)=	0
#Y (µm)=	0
#Z (µm)=	-183.3
#Full time(s)=	34
#Project=	21_05_14
#Sample=	BU19w
#Site=
#Title=	BU19w-FF1-FI10-V_150 (500nm)_532nm_Edge_100%_x100_VIS_H50um_15sX2
#Remark=
#Date=	14.05.2021 16:27
#Acquired=	14.05.2021 16:27:41
#Base:Fit=	22.12.2021 12:22:35
#Base:Edit=	22.12.2021 12:26:22
#Base:Edit=	22.12.2021 12:26:24
#Base:Edit=	22.12.2021 12:26:24
#Base:Edit=	22.12.2021 12:26:25
#Base:Sub=	22.12.2021 12:26:26
#Data Range:Extract=	22.12.2021 12:27:19
102.699	580.353
107.322	513.791
111.942	366.993
116.56	204.255
121.173	214.938
125.787	158.396
130.398	143.643
135.006	138.874
139.613	55.8021
144.215	42.9799
148.817	36.2397
153.417	323.047
158.014	900.213
162.607	811.913
167.2	208.558
171.79	149.375
176.379	281.379
180.963	1252.73
185.547	3124.36
190.128	2132.55
194.705	699.115
199.282	107.262
203.857	3.25952
208.43	8.125
212.998	0.764038
217.566	-10.2844
222.132	1.83252
226.693	84.3831
231.254	197.007
235.813	253.38
240.368	488.393
244.923	819.32
249.475	682.585
254.023	428.106
258.571	257.861
263.117	273.934
267.658	556.885
272.199	1555.04
276.738	2869.38
281.273	2297.12
285.807	1029.11
290.34	579.699
294.868	645.543
299.396	1311.95
303.919	1314.1
308.443	757.731
312.964	347.181
317.481	302.989
321.998	477.157
326.51	746.784
331.023	725.48
335.533	434.478
340.039	291.334
344.544	394.383
349.046	499.2
353.547	362.386
358.045	232.117
362.542	154.514
367.036	175.459
371.527	83.7756
376.017	159.157
380.503	242.843
384.99	405.479
389.471	480.786
393.953	582.678
398.43	472.772
402.908	300.172
407.381	227.992
411.854	323.432
416.323	527.653
420.791	300.453
425.256	99.7665
429.72	13.1356
434.18	45.9241
438.64	4.30933
443.095	108.397
447.551	295.458
452.003	774.524
456.454	864.987
460.901	399.421
465.348	193.339
469.791	117.515
474.231	127.322
478.672	138.628
483.108	220.276
487.544	334.044
491.976	426.785
496.408	437.781
500.836	332.234
505.261	282.243
509.687	180.95
514.108	115.783
518.529	175.5
522.946	123.123
527.361	158.68
531.776	162.576
536.187	215.245
540.595	199.555
545.003	201.126
549.408	242.213
553.812	247.469
558.212	287.61
562.61	243.623
567.007	191.979
571.401	142.214
575.792	171.989
580.184	319.1
584.571	782.381
588.956	1066.04
593.341	781.015
597.722	411.55
602.101	376.537
606.48	632.639
610.854	771.503
615.227	634.765
619.597	348.329
623.967	186.972
628.334	198.563
632.698	172.353
637.06	225.258
641.422	219.94
645.779	191.554
650.135	161.178
654.491	195.662
658.842	268.328
663.192	344.313
667.539	419.364
671.884	430.94
676.23	544.546
680.571	386.698
684.91	251.558
689.247	187.38
693.583	104.74
697.916	73.2485
702.247	34.3694
706.576	-11.0298
710.902	41.4124
715.229	104.933
719.551	43.9739
723.872	54.2744
728.19	40.2747
732.506	-19.4758
736.82	60.3494
741.134	53.1509
745.444	54.2566
749.752	169.018
754.058	180.171
758.362	234.7
762.664	322.552
766.964	409.947
771.264	755.207
775.559	1114.86
779.853	1152.89
784.144	867.469
788.434	598.236
792.722	363.907
797.007	233.206
801.29	142.282
805.572	139.597
809.851	169.25
814.13	85.1472
818.406	113.034
822.679	86.626
826.95	85.8647
831.219	63.2083
835.486	75.6538
839.752	86.8071
844.015	77.5676
848.276	120.483
852.535	94.7717
856.792	62.4788
861.047	78.3984
865.3	101.064
869.551	56.0742
873.8	69.7041
878.047	120.067
882.292	10.6646
886.534	93.603
890.775	106.193
895.014	78.8308
899.251	91.6277
903.486	86.2139
907.719	48.3748
911.95	141.287
916.179	95.074
920.406	129.967
924.63	96.3884
928.853	151.792
933.074	158.048
937.293	146.175
941.51	243.111
945.723	292.159
949.936	335.528
954.147	276.872
958.356	339.989
962.563	337.455
966.768	380.764
970.971	398.262
975.172	258.061
979.371	228.92
983.568	187.281
987.761	143.055
991.954	131.38
996.145	103.982
1000.33	142.022
1004.52	139.091
1008.71	115.545
1012.89	198.459
1017.07	108.835
1021.25	227
1025.43	229.455
1029.6	258.689
1033.77	290.21
1037.95	409.252
1042.11	566.632
1046.28	987.923
1050.45	1574.53
1054.61	1624.78
1058.77	1134.13
1062.93	772.905
1067.09	558.426
1071.24	495.003
1075.4	601.603
1079.55	787.846
1083.7	1199.75
1087.85	1713.89
1091.99	1684.53
1096.14	1312.67
1100.28	1058.89
1104.42	1179.49
1108.55	1327.24
1112.69	1379.99
1116.82	1106.32
1120.96	1031.03
1125.09	1111.68
1129.21	1266.67
1133.34	1130.17
1137.46	906.657
1141.59	709.62
1145.71	660.793
1149.83	722.174
1153.94	962.103
1158.06	1075.86
1162.17	845.324
1166.28	689.521
1170.39	537.584
1174.5	380.864
1178.6	346.711
1182.7	282.686
1186.8	304.697
1190.9	272.359
1195	222.763
1199.1	286.473
1203.19	260.932
1207.28	232.48
1211.37	210.473
1215.46	272.33
1219.54	291.243
1223.63	384.579
1227.71	302.671
1231.79	322.271
1235.87	508.906
1239.95	580.011
1244.02	448.924
1248.09	348.347
1252.16	298.521
1256.23	200.294
1260.3	198.443
1264.36	178.11
1268.43	713.611
1272.49	1063.85
1276.55	391.449
1280.6	169.771
1284.66	121.801
1288.71	105.894
1292.76	143.622
1296.81	112.734
1300.86	147.789
1304.91	87.5388
1308.95	65.7209
1312.99	101.269
1317.03	90.3689
1321.07	68.0366
1325.11	142.495
1329.14	156.204
1333.18	99.3391
1337.21	96.999
1341.24	100.268
1345.26	113.259
1349.29	101.383
1353.31	120.449
1357.33	178.134
1361.35	174.111
1365.37	126.589
1369.39	326.407
1373.4	1381.85
1377.41	1417.62
1381.43	351.112
1385.43	102.136
1389.44	107.564
1393.45	152.842
1397.45	262.853
1401.45	43.1365
1405.45	63.2048
1409.45	1.74805
1413.44	83.5071
1417.44	104.078
1421.43	66.2234
1425.42	30.1982
1429.41	101.701
1433.39	75.356
1437.38	124.503
1441.36	100.71
1445.34	79.1819
1449.32	91.1118
1453.3	101.334
1457.27	68.9109
1461.24	16.8406
1465.22	43.8188
1469.19	29.8372
1473.15	82.7246
1477.12	7.32959
1481.09	65.0686
1485.05	30.4971
1489.01	60.4465
1492.97	43.8042
1496.93	123.722
1500.88	66.8813
1504.83	23.5503
1508.79	62.5881
1512.74	9.354
1516.68	66.1985
1520.63	51.5298
1524.57	43.8726
1528.52	81.1912
1532.46	-22.7168
1536.4	20.7324
1540.33	48.7803
1544.27	41.9231
1548.2	43.8215
1552.14	100.725
1556.07	16.6382
1559.99	71.5554
1563.92	-3.53955
1567.84	93.2185
1571.77	103.733
1575.69	31.1624
1579.61	82.9753
1583.52	6.37769
1587.44	88.5667
1591.35	52.2593
1595.27	21.7427
1599.18	119.177
1603.09	53.7844
1606.99	62.6829
1610.9	82.1992
1614.8	40.8267
1618.7	-13.7583
1622.6	60.0317
1626.5	22.499
1630.39	57.4919
1634.29	36.6353
1638.18	66.6428
1642.07	60.4478
1645.96	24.959
1649.85	102.87
1653.73	46.4199
1657.62	38.6057
1661.5	42.9104
1665.38	45.6348
1669.26	64.9851
1673.13	88.3674
1677.01	113.685
1680.88	67.1492
1684.75	69.2671
1688.62	89.0574
1692.49	28.6743
1696.35	49.1733
1700.22	99.4148
1704.08	60.1216
1707.94	73.4314
1711.8	92.031
1715.66	33.144
1719.51	98.3254
1723.37	39.6277
1727.22	52.1316
1731.07	73.8223
1734.92	123.52
1738.76	57.5217
1742.61	52.3298
1746.45	117.353
1750.29	43.9204
1754.13	52.9622
1757.97	70.1245
1761.81	108.535
1765.64	70.2559
1769.47	68.679
1773.31	44.5933
1777.14	-30.1707
1780.96	18.1323
1784.79	30.5564
1788.61	80.7722
1792.43	39.387
1796.25	82.3621
1800.07	55.3743
1803.89	75.873
1807.71	61.427
1811.52	52.9424
1815.33	56.4482
1819.14	102.966
1822.95	96.8555
1826.76	21.9675
1830.56	49.8176
1834.37	22.2471
1838.17	65.6567
1841.97	114.784
1845.77	93.2815
1849.56	107.677
1853.36	89.6326
1857.15	39.8384
1860.94	95.6401
1864.73	42.573
1868.52	83.8235
1872.31	60.749
1876.09	113.096
1879.87	68.5322
1883.66	106.933
1887.43	45.6292
1891.21	70.2988
1894.99	25.6887
1898.76	79.6421
1902.53	112.775
1906.31	68.1316
1910.08	40.0962
1913.84	15.595
1917.61	46.1162
1921.37	38.3157
1925.14	11.4448
1928.9	54.699
1932.66	33.0347
1936.41	64.3394
1940.17	108.763
1943.92	8.03467
1947.68	62.1799
1951.43	22.9773
1955.18	29.8657
1958.92	93.9775
1962.67	65.7109
1966.41	59.561
1970.16	-18.9207
1973.9	123.196
1977.64	224.886
1981.37	87.3508
1985.11	93.2473
1988.84	151.017
1992.57	74.572
1996.31	-3.13306
2000.03	57.0012
2003.76	98.957
2007.49	124.519
2011.21	124.008
2014.93	119.014
2018.65	105.745
2022.37	42.96
2026.09	60.2261
2029.81	38.2996
2033.52	128.163
2037.23	64.9712
2040.94	58.7847
2044.65	63.0105
2048.36	68.1089
2052.07	43.5188
2055.77	43.437
2059.47	56.6707
2063.17	32.7
2066.87	120.531
2070.57	48.3218
2074.27	63.7515
2077.96	28.78
2081.65	66.844
2085.34	15.3279
2089.03	82.1223
2092.72	97.1143
2096.41	92.4885
2100.09	113.742
2103.77	84.1387
2107.46	52.9041
2111.14	83.6289
2114.81	104.934
2118.49	91.5647
2122.16	85.0085
2125.84	69.8206
2129.51	176.143
2133.18	33.3635
2136.85	103.733
2140.51	152.852
2144.18	81.7622
2147.84	92.5835
2151.5	74.9827
2155.16	101.625
2158.82	90.9578
2162.48	4.34766
2166.13	97.321
2169.79	36.4084
2173.44	36.4275
2177.09	113.209
2180.74	54.7603
2184.38	99.1741
2188.03	29.095
2191.67	91.4414
2195.32	65.2197
2198.96	50.2803
2202.6	44.1387
2206.23	67.0159
2209.87	85.1235
2213.5	68.8582
2217.14	59.0632
2220.77	72.4045
2224.4	89.5188
2228.03	37.2625
2231.65	70.2534
2235.28	63.6968
2238.9	123.613
2242.52	54.689
2246.14	91.4678
2249.76	95.3174
2253.38	-8.57397
2256.99	50.8298
2260.6	28.6396
2264.21	40.0198
2267.82	113.456
2271.44	59.1726
2275.04	79.3914
2278.65	128.256
2282.25	7.09424
2285.85	40.6694
2289.45	55.6057
2293.05	52.4492
2296.65	89.342
2300.25	58.7261
2303.84	53.6643
2307.43	107.641
2311.02	112.741
2314.62	102.932
2318.2	202.225
2321.79	129.196
2325.38	86.5972
2328.96	35.7732
2332.54	66.3235
2336.12	95.4355
2339.7	87.2268
2343.28	82.3806
2346.85	62.0957
2350.43	34.2229
2354	125.732
2357.57	124.369
2361.14	132.139
2364.71	99.1948
2368.27	49.4795
2371.84	66.0942
2375.4	145.939
2378.96	33.4028
2382.52	77.2412
2386.08	51.6484
2389.64	95.8159
2393.19	96.9336
2396.75	56.4026
2400.3	111.237
2403.85	79.6689
2407.4	99.3069
2410.95	-39.8611
2414.49	-10.437
2418.04	17.2158
2421.58	21.7336
2425.12	3.40308
2428.66	89.4502
2432.2	11.8389
2435.74	19.0627
2439.27	-18.9795
2442.81	47.4998
2446.34	35.2949
2449.87	38.9624
2453.4	89.4492
2456.93	83.6914
2460.45	17.5864
2463.98	70.5532
2467.5	85.3643
2471.02	55.9175
2474.54	125.728
2478.06	86.7192
2481.58	81.8506
2485.09	82.1714
2488.61	116.272
2492.12	52.2549
2495.63	112.876
2499.14	157.186
2502.65	36.2104
2506.15	49.4141
2509.66	82.6992
2513.16	78.6465
2516.66	34.688
2520.16	61.1641
2523.66	-2.68848
2527.16	67.7803
2530.66	76.832
2534.15	94.5005
2537.64	86.2485
2541.13	56.7212
2544.62	37.7153
2548.11	75.4624
2551.6	52.8691
2555.08	30.8076
2558.57	87.5547
2562.05	21.6182
2565.53	-13.3467
2569.01	-3.3877
2572.49	61.7734
2575.96	8.94678
2579.44	8.94971
2582.91	116.855
2586.38	60.8931
2589.85	30.9429
2593.32	77.4243
2596.79	109.087
2600.25	38.895
2603.72	49.9092
2607.18	35.8242
2610.64	72.9854
2614.1	67.8281
2617.56	84.2212
2621.02	43.083
2624.47	25.7261
2627.92	38.4302
2631.38	66.5825
2634.83	84.7012
2638.28	88.6313
2641.72	14.043
2645.17	84.6924
2648.61	47.4854
2652.06	90.2471
2655.5	94.7598
2658.94	53.2842
2662.38	48.3271
2665.82	103.795
2669.25	16.3867
2672.69	101.838
2676.12	48.8242
2679.55	25.8833
2682.98	76.8623
2686.41	62.249
2689.84	-1.87988
2693.26	42.7773
2696.69	47.2725
2700.11	2.22168
2703.53	32.4644
2706.95	39.0356
2710.37	21.6353
2713.79	4.12256
2717.2	32.1841
2720.62	21.8066
2724.03	-29.3447
2727.44	18.9341
2730.85	65.2036
2734.26	74.0786
2737.66	57.71
2741.07	31.1875
2744.47	13.1548
2747.87	57.209
2751.28	28.8076
2754.67	0.429688
2758.07	55.4946
2761.47	37.7881
2764.86	2.54346
2768.26	76.6797
2771.65	72.3789
2775.04	57.9585
2778.43	78.6699
2781.82	58.5142
2785.2	50.4277
2788.59	71.4604
2791.97	37.6025
2795.35	44.6035
2798.73	22.5088
2802.11	73.6255
2805.49	25.356
2808.87	49.9424
2812.24	28.5015
2815.62	86.1387
2818.99	72.3867
2822.36	-13.3728
2825.73	51.3726
2829.1	26.105
2832.46	31.4888
2835.83	24.5237
2839.19	23.0205
2842.55	49.407
2845.91	56.5745
2849.27	45.1907
2852.63	55.2766
2855.99	6.96509
2859.34	7.91626
2862.69	39.9531
2866.05	32.8975
2869.4	17.9873
2872.75	55.5649
2876.09	69.5632
2879.44	-36.0779
2882.78	34.0745
2886.13	48.366
2889.47	22.3843
2892.81	56.5801
2896.15	122.418
2899.49	82.6516
2902.82	-19.2588
2906.16	25.1958
2909.49	72.9893
2912.82	59.2781
2916.16	35.3394
2919.49	75.436
2922.81	19.9143
2926.14	85.5474
2929.46	92.3645
2932.79	70.844
2936.11	88.0366
2939.43	155.163
2942.75	87.595
2946.07	80.6458
2949.39	60.4255
2952.7	92.6973
2956.02	113.409
2959.33	51.2661
2962.64	122.275
2965.95	96.6704
2969.26	120.597
2972.57	27.4783
2975.87	31.6543
2979.17	59.3604
2982.48	60.0876
2985.78	63.0232
2989.08	67.0332
2992.38	27.0811
2995.68	76.6917
2998.97	85.9937
3002.27	32.0693
3005.56	29.3279
3008.85	92.7139
3012.14	57.4724
3015.43	30.5684
3018.72	64.8677
3022	21.8054
3025.29	50.564
3028.57	41.5596
3031.85	92.8635
3035.14	24.8701
3038.41	19.3064
3041.69	1.46484
3044.97	11.2434
3048.24	57.8284
3051.52	44.0417
3054.79	25.4121
3058.06	13.8792
3061.33	49.7576
3064.6	85.0845
3067.87	22.1111
3071.13	12.9446
3074.4	69.4448
3077.66	24.5156
3080.92	47.2605
3084.18	51.8633
3087.44	70.5137
3090.7	58.7417
3093.95	35.3032
3097.21	61.8386
3100.46	161.639
3103.71	49.7158
3106.96	134.917
3110.21	29.5386
3113.46	86.8291
3116.71	80.5427
3119.95	77.1572
3123.2	86.1216
3126.44	11.1294
3129.68	103.871
3132.92	42.188
3136.16	47.9832
3139.4	54.6401
3142.63	7.90015
3145.87	108.211
3149.1	113.35
3152.33	55.417
3155.56	67.1777
3158.79	133.254
3162.02	100.12
3165.25	31.4102
3168.47	98.853
3171.69	108.866
3174.92	56.5557
3178.14	88.0747
3181.36	104.437
3184.58	115.689
3187.79	64.7659
3191.01	110.11
3194.22	105.856
3197.43	104.368
3200.65	203.925
3203.86	96.0815
3207.07	186.409
3210.27	193.232
3213.48	106.193
3216.69	117.229
3219.89	199.694
3223.09	166.49
3226.29	90.6177
3229.49	177.773
3232.69	160.016
3235.89	81.0674
3239.08	155.754
3242.28	136.446
3245.47	132.391
3248.66	193.499
3251.85	222.439
3255.04	216.137
3258.23	128.211
3261.42	112.257
3264.6	209.404
3267.79	107.419
3270.97	153.194
3274.15	119.696
3277.33	213.555
3280.51	186.204
3283.68	156.954
3286.86	170.313
3290.04	254.456
3293.21	178.419
3296.38	203.247
3299.55	171.973
3302.72	182.87
3305.89	208.5
3309.06	160.306
3312.22	224.864
3315.39	224.69
3318.55	231.948
3321.71	182.37
3324.87	189.705
3328.03	148.862
3331.19	221.723
3334.34	256.098
3337.5	291.749
3340.65	283.045
3343.81	231.765
3346.96	257.109
3350.11	230.681
3353.25	234.828
3356.4	282.542
3359.55	246.872
3362.69	214.17
3365.84	261.841
3368.98	273.806
3372.12	217.353
3375.26	303.653
3378.4	242
3381.53	347.373
3384.67	307.515
3387.8	280.939
3390.94	295.258
3394.07	327.883
3397.2	371.068
3400.33	388.475
3403.46	500.333
3406.58	590.846
3409.71	837.786
3412.83	1259.4
3415.96	2576.28
3419.08	5492.47
3422.2	6597.16
3425.32	4252.47
3428.44	1933.19
3431.55	1004.74
3434.67	669.813
3437.78	511.974
3440.89	468.942
3444	399.265
3447.12	405.853
3450.22	366.992
3453.33	292.904
3456.44	289.705
3459.54	363.414
3462.65	318.086
3465.75	324.728
3468.85	352.892
3471.95	322.49
3475.05	397.595
3478.15	371.6
3481.24	376.926
3484.34	424.988
3487.43	515.83
3490.53	624.938
3493.62	813.406
3496.71	1006
3499.79	1268.67
3502.88	1351.04
3505.97	1344.22
3509.05	1118.28
3512.14	838.565
3515.22	683.408
3518.3	575.617
3521.38	465.288
3524.46	307.167
3527.54	328.733
3530.61	313.905
3533.69	212.948
3536.76	246.295
3539.83	216.213
3542.9	212.696
3545.97	206.891
3549.04	179.734
3552.11	149.924
3555.18	159.46
3558.24	95.5657
3561.3	122.651
3564.37	159.881
3567.43	96.8325
3570.49	111.833
3573.55	60.0366
3576.61	113.365
3579.66	132.264
3582.72	79.6934
3585.77	146.525
3588.82	147.575
3591.87	80.1897
3594.92	126.287
3597.97	154.28
3601.02	111.917
3604.07	112.81
3607.11	111.72
3610.16	117.109
3613.2	57.1462
3616.24	92.6843
3619.28	75.5122
3622.32	137.698
3625.36	75.6213
3628.39	107.751
3631.43	84.0483
3634.46	76.0112
3637.5	56.3528
3640.53	96.3582
3643.56	91.1426
3646.59	126.786
3649.62	132.778
3652.64	72.8528
3655.67	63.6877
3658.69	54.6526
3661.72	96.9363
3664.74	64.2566
3667.76	70.3567
3670.78	7.95776
3673.79	93.8479
3676.81	113.963
3679.83	70.689
3682.84	67.0452
3685.86	94.7029
3688.87	-2.4646
3691.88	68.9702
3694.89	10.998
3697.9	24.4802
3700.91	46.7227
3703.91	67.0925
3706.92	70.0664
3709.92	25.2188
3712.92	67.3997
3715.92	23.1335
3718.92	77.575
3721.92	69.8411
3724.92	15.1326
3727.92	64.9221
3730.91	17.2769
3733.91	58.7769
3736.9	42.8391
3739.89	106.466
3742.88	34.6553
3745.87	37.7061
3748.86	21.4641
3751.85	90.5935
3754.83	27.8
3757.82	5.8418
3760.8	84.1204
3763.78	72.2932
3766.76	17.1584
3769.74	56.0361
3772.72	97.0383
3775.7	27.6438
3778.67	18.9954
3781.65	79.3726
3784.62	43.5701
3787.6	0.404785
3790.57	37.939
3793.54	59.7695
3796.51	40.261
3799.47	81.5735
3802.44	32.4924
3805.41	15.6023
3808.37	33.8533
3811.33	38.0471
3814.3	67.8533
3817.26	26.8494
3820.22	93.8015
3823.18	0.0112305
3826.13	58.7988
3829.09	-2.83643
3832.04	30.585
3835	71.8652
3837.95	30.5684
3840.9	39.5798
3843.85	85.7568
3846.8	56.8672
3849.75	19.5334
3852.69	60.4619
3855.64	48.0198
3858.58	47.0847
3861.53	79.4543
3864.47	139.625
3867.41	70.3062
3870.35	77.45
3873.29	72.0261
3876.22	87.3928
3879.16	96.6729
3882.1	107.485
3885.03	107.435
3887.96	96.6472
3890.89	51.116
3893.82	98.5115
3896.75	47.3882
3899.68	50.0413
3902.61	54.158
3905.53	112.413
3908.46	13.8362
3911.38	51.4631
3914.3	95.4045
3917.23	89.0171
3920.15	103.346
3923.06	34.7217
3925.98	52.1758
3928.9	29.9971
3931.81	74.5112
3934.73	125.382
3937.64	54.4253
3940.55	14.8894
3943.46	67.3184
3946.37	45.3564
3949.28	70.5774
3952.19	61.446
3955.09	42.0439
3958	98.4951
3960.9	80.3594
3963.8	102.653
3966.71	65.6545
3969.61	42.1824
3972.51	64.7507
3975.4	84.2891
3978.3	31.5278
3981.2	103.63
3984.09	61.1836
3986.99	90.8384
3989.88	86.3037
3992.77	54.3826
3995.66	112.928
3998.55	90.7803
4001.43	43.6135