File: Data/3-Raman/processed/bu19w-d-ore2-fi11-v_1800 (450-850nm)_532nm_edge_100%_x100_vis_lwd_h50um_30sx2_01.txt
#Acq. time (s)=	30
#Accumulations=	2
#Range (cm-¹)=	1200...2365
#Windows=	3
#Auto scanning=	Off
#Autofocus=	Off
#Macrospot=	Off
#AutoExposure=	Off
#Spike filter=	Multiple accum.
#Delay time (s)=	2
#Binning=	1
#Readout mode=	Signal
#DeNoise=	Off
#ICS correction=	On
#Dark correction=	Off
#Inst. Process=	Off
#Detector Gain=	Best Dynamic
#Detector ADC=	50 kHz HS
#Detector temperature (°C)=	-60.09
#Instrument=	LabRAM HR Evol
#Detector=	SIN-EM FIVIS
#Objective=	x100_VIS_LWD
#Grating=	1800 (450-850nm)
#ND Filter=	100%
#Laser=	532nm_Edge
#Hole=	49.98
#Temperature=	0
#Range=	Visible
#StageXY=	75x50mm Scan+
#StageZ=	Z motor
#X (µm)=	0
#Y (µm)=	0
#Z (µm)=	37.7
#Full time(mm:ss)=	3:18
#Project=	21_11_22
#Sample=	BU19w
#Site=
#Title=	BU19w-D-FFore2-FI11-V_1800 (450-850nm)_532nm_Edge_100%_x100_VIS_LWD_H50um_30sX2
#Remark=
#Date=	22.11.2021 14:18
#Acquired=	22.11.2021 14:18:37
#Base:Fit=	16.12.2021 17:39:50
#Base:Fit=	16.12.2021 17:40:08
#Base:Sub=	16.12.2021 17:40:09
1202.84	4.68301
1203.95	1.20618
1205.06	-0.0917168
1206.17	-0.309505
1207.29	1.63118
1208.39	-1.78972
1209.51	1.20235
1210.62	-1.11843
1211.72	0.84794
1212.84	0.690102
1213.94	0.503788
1215.05	-1.79215
1216.16	1.23885
1217.27	1.09568
1218.38	2.02218
1219.49	-0.252569
1220.6	1.69595
1221.71	-0.55876
1222.81	-0.662815
1223.92	3.45593
1225.03	1.18576
1226.14	-0.0260429
1227.24	4.18093
1228.35	6.11077
1229.46	6.03045
1230.56	5.95014
1231.67	6.94464
1232.78	2.691
1233.88	1.57322
1234.99	5.67815
1236.09	2.43791
1237.2	3.42515
1238.3	0.237402
1239.41	0.183537
1240.51	-2.99092
1241.62	3.26244
1242.72	2.15428
1243.83	0.0121593
1244.93	3.11891
1246.03	-3.19909
1247.14	3.05509
1248.24	-0.125523
1249.34	0.882607
1250.45	-0.194534
1251.55	1.89847
1252.65	0.852442
1253.75	-2.28015
1254.86	0.844019
1255.96	1.87193
1257.06	0.849989
1258.16	4.9937
1259.26	5.06485
1260.36	4.98532
1261.46	9.29617
1262.56	15.5394
1263.66	20.7767
1264.76	12.4715
1265.86	7.30726
1266.96	3.13832
1268.06	3.12896
1269.16	6.29287
1270.26	9.50197
1271.36	8.51567
1272.46	7.49822
1273.56	8.60356
1274.66	5.51151
1275.76	10.8319
1276.85	8.76937
1277.95	8.80163
1279.05	13.0727
1280.15	18.3563
1281.24	40.4078
1282.34	133.281
1283.44	379.728
1284.53	160.64
1285.63	30.1311
1286.73	14.411
1287.82	10.2533
1288.92	7.1323
1290.01	2.96157
1291.11	6.20536
1292.21	5.20463
1293.3	1.09337
1294.4	1.13739
1295.49	7.50324
1296.58	4.36714
1297.68	3.36868
1298.77	1.30938
1299.87	2.42346
1300.96	2.46181
1302.05	3.5652
1303.15	-2.74019
1304.24	-2.69472
1305.33	-2.64123
1306.42	-1.52768
1307.52	1.6947
1308.61	-2.47054
1309.7	0.761732
1310.79	-2.36081
1311.88	2.97221
1312.98	-1.18404
1314.07	0.977512
1315.16	-1.07338
1316.25	-3.13119
1317.34	-2.02073
1318.43	-3.03914
1319.52	0.157204
1320.61	2.30978
1321.7	-0.797735
1322.79	0.294252
1323.88	0.30209
1324.97	1.4549
1326.06	-3.73142
1327.15	1.5938
1328.23	-1.53742
1329.32	0.585777
1330.41	1.65539
1331.5	-1.4724
1332.59	1.70786
1333.67	-2.45007
1334.76	0.737923
1335.85	0.770277
1336.94	0.821421
1338.02	-3.3126
1339.11	1.96605
1340.2	0.948065
1341.28	3.08902
1342.37	2.08277
1343.45	-1.03523
1344.54	4.1996
1345.63	-3.05882
1346.71	5.30796
1347.8	1.17239
1348.88	-0.87706
1349.96	4.39003
1351.05	0.307646
1352.13	3.41289
1353.22	4.49815
1354.3	4.53196
1355.39	7.67575
1356.47	1.47826
1357.55	5.64617
1358.63	4.64773
1359.72	2.61336
1360.8	2.66895
1361.88	6.8576
1362.97	5.84245
1364.05	4.82202
1365.13	6.93267
1366.21	6.98646
1367.29	1.85508
1368.37	9.10754
1369.45	13.2287
1370.54	3.97076
1371.62	9.15635
1372.7	9.19806
1373.78	13.3456
1374.86	19.5482
1375.94	9.35187
1377.02	19.6826
1378.09	25.8016
1379.18	29.903
1380.25	23.7105
1381.33	28.848
1382.41	42.2766
1383.49	46.4795
1384.57	54.5418
1385.65	133.496
1386.72	637.067
1387.8	340.818
1388.88	53.6724
1389.96	34.1969
1391.03	20.9076
1392.11	13.7773
1393.19	13.8255
1394.26	11.7962
1395.34	11.8229
1396.42	9.82532
1397.49	10.8948
1398.57	5.82399
1399.64	7.95171
1400.72	5.96244
1401.79	4.94902
1402.87	8.0393
1403.94	8.06174
1405.02	11.1783
1406.09	13.2706
1407.17	20.4915
1408.24	45.0743
1409.31	31.77
1410.39	13.4579
1411.46	9.33664
1412.53	3.22213
1413.61	1.20491
1414.68	3.29941
1415.75	3.33237
1416.82	1.29915
1417.9	2.33411
1418.97	1.3348
1420.04	1.41009
1421.11	3.41237
1422.18	6.51046
1423.26	3.4704
1424.33	1.42072
1425.4	3.47026
1426.47	4.52618
1427.54	1.49858
1428.61	2.57944
1429.68	5.66716
1430.75	-0.496525
1431.82	0.557922
1432.89	-2.49348
1433.96	0.595932
1435.02	0.611837
1436.09	0.641251
1437.16	4.77985
1438.23	0.706726
1439.3	5.85184
1440.37	2.79525
1441.43	0.759356
1442.5	2.84968
1443.57	-1.24146
1444.64	4.9219
1445.7	1.87208
1446.77	-0.163374
1447.84	2.91943
1448.9	3.95354
1449.97	-0.128302
1451.04	0.917883
1452.1	-2.14043
1453.17	1.98096
1454.23	-0.0607281
1455.3	3.02533
1456.36	0.996883
1457.43	1.00993
1458.49	1.01584
1459.56	3.06252
1460.62	-0.0114555
1461.69	0.0271721
1462.75	1.00015
1463.81	-1.03308
1464.88	1.01771
1465.94	2.04889
1467	1.02853
1468.07	3.06816
1469.13	0.0136261
1470.19	0.0235004
1471.25	3.07913
1472.32	-1.99284
1473.38	4.11809
1474.44	-4.0179
1475.5	2.08803
1476.56	0.0528984
1477.62	2.07178
1478.68	-1.98364
1479.75	1.08765
1480.81	-2.95817
1481.87	1.06981
1482.93	-2.98024
1483.99	2.09972
1485.05	2.09896
1486.11	-0.945246
1487.17	5.12959
1488.22	-0.940796
1489.28	3.11154
1490.34	-0.924978
1491.4	-0.915806
1492.46	2.11771
1493.52	1.09481
1494.58	-0.920475
1495.63	2.1155
1496.69	-0.898212
1497.75	0.122288
1498.81	0.122883
1499.86	0.123949
1500.92	3.14656
1501.98	1.14124
1503.03	3.14483
1504.09	-3.89792
1505.15	-2.8817
1506.2	0.149776
1507.26	2.17716
1508.31	0.150528
1509.37	2.12712
1510.42	0.101103
1511.48	3.13611
1512.53	4.12676
1513.59	3.10834
1514.64	-0.898506
1515.7	-0.883291
1516.75	0.133089
1517.8	0.137762
1518.86	1.15248
1519.91	-0.855633
1520.96	3.13614
1522.02	1.12967
1523.07	0.144125
1524.12	0.162663
1525.17	1.16367
1526.23	1.16229
1527.28	1.1626
1528.33	3.18812
1529.38	1.18744
1530.43	3.22358
1531.48	2.2312
1532.53	-0.7806
1533.59	0.19928
1534.64	-1.81776
1535.69	-2.82251
1536.74	2.21609
1537.79	-0.74716
1538.84	2.25331
1539.89	3.23795
1540.94	1.21654
1541.98	0.235909
1543.03	7.27415
1544.08	-0.728003
1545.13	5.27593
1546.18	2.26561
1547.23	1.27707
1548.28	0.345325
1549.33	2.36007
1550.37	3.35298
1551.42	2.33893
1552.47	6.33129
1553.52	2.32869
1554.56	1.33675
1555.61	-1.6778
1556.65	1.30617
1557.7	1.30113
1558.75	2.3109
1559.79	1.32964
1560.84	2.33138
1561.88	3.35728
1562.93	1.22621
1563.98	2.32515
1565.02	3.34936
1566.07	4.36157
1567.11	2.35642
1568.15	1.36284
1569.2	5.35464
1570.24	1.35188
1571.29	0.357609
1572.33	1.38372
1573.37	4.3913
1574.42	3.37016
1575.46	4.3457
1576.5	5.34738
1577.55	1.3728
1578.59	3.36309
1579.63	2.35986
1580.67	4.35412
1581.72	2.36986
1582.76	0.383352
1583.8	5.35053
1584.84	1.36776
1585.88	3.37279
1586.92	7.37136
1587.96	3.40266
1589	6.39177
1590.04	2.3944
1591.08	5.34824
1592.12	1.38576
1593.16	3.37175
1594.2	1.39493
1595.24	3.39009
1596.28	9.33114
1597.32	7.33447
1598.36	1.36676
1599.4	5.31124
1600.44	8.26293
1601.48	7.27527
1602.51	8.2743
1603.55	4.33797
1604.59	8.3086
1605.63	6.33495
1606.66	9.28416
1607.7	7.26348
1608.74	8.15992
1609.77	7.31073
1610.81	6.10176
1611.85	4.18231
1612.88	5.33216
1613.92	8.22467
1614.95	3.0081
1615.99	9.39979
1617.03	5.80107
1618.06	6.99193
1619.1	6.57133
1620.13	5.54072
1621.17	8.41395
1622.2	8.13738
1623.23	7.74951
1624.27	8.55678
1625.3	9.61506
1626.34	3.61646
1627.37	7.21213
1628.4	8.27834
1629.44	9.25604
1630.47	5.79581
1631.29	12.3882
1632.33	6.48382
1633.38	8.45377
1634.42	10.4157
1635.47	10.4157
1636.51	6.48655
1637.56	9.45006
1638.6	6.51248
1639.65	4.54676
1640.69	8.49039
1641.73	7.50311
1642.78	10.4734
1643.82	7.52123
1644.86	7.52113
1645.91	8.52785
1646.95	7.56497
1647.99	8.58258
1649.03	6.63137
1650.08	6.63632
1651.12	7.63611
1652.16	11.5983
1653.2	9.66978
1654.24	5.73795
1655.28	6.72645
1656.33	5.73608
1657.37	7.70919
1658.41	8.72502
1659.45	9.71946
1660.49	9.78409
1661.53	8.77601
1662.57	7.77551
1663.61	4.88832
1664.65	7.81123
1665.69	6.82744
1666.72	8.84307
1667.76	7.88345
1668.8	7.89239
1669.84	5.93102
1670.88	6.93506
1671.92	4.98137
1672.96	5.00251
1674	6.00614
1675.03	7.98727
1676.07	6.98989
1677.11	4.02558
1678.15	5.01627
1679.18	3.05029
1680.22	1.08481
1681.25	4.05644
1682.29	2.08606
1683.33	5.06054
1684.36	6.06907
1685.4	2.12005
1686.43	4.09106
1687.47	6.06267
1688.51	4.11153
1689.54	4.12564
1690.58	4.11627
1691.61	0.166519
1692.64	4.119
1693.68	0.196922
1694.71	3.15087
1695.75	3.14488
1696.78	6.10553
1697.81	4.14389
1698.85	-1.75423
1699.88	-0.772612
1700.91	3.16423
1701.95	1.21497
1702.98	3.18878
1704.01	2.19897
1705.04	1.20725
1706.08	1.19233
1707.11	2.17486
1708.14	3.17215
1709.17	2.20941
1710.2	3.17071
1711.23	1.20093
1712.27	-1.72273
1713.3	2.20129
1714.33	2.19027
1715.36	2.16484
1716.39	1.19049
1717.42	-0.744734
1718.45	1.19809
1719.48	-2.69761
1720.51	-0.757624
1721.54	0.220423
1722.56	0.20796
1723.59	-1.72977
1724.62	-1.72793
1725.65	0.206581
1726.68	-0.7941
1727.71	-3.68142
1728.74	1.17961
1729.76	2.1507
1730.79	2.13788
1731.82	2.12154
1732.85	-2.70352
1733.87	-0.775265
1734.9	0.187819
1735.93	-1.73846
1736.95	0.167765
1737.98	3.0293
1739.01	3.02321
1740.03	3.98423
1741.06	1.11505
1742.08	3.9891
1743.11	0.170256
1744.13	2.07304
1745.16	1.11233
1746.18	3.03532
1747.21	-0.759266
1748.23	-0.737587
1749.26	-0.740932
1750.28	-0.745817
1751.31	0.205252
1752.33	2.11088
1753.35	3.05747
1754.38	0.189133
1755.4	-1.69991
1756.42	-0.73558
1757.44	0.223303
1758.47	0.222467
1759.49	1.17755
1760.51	-1.66027
1761.53	0.26166
1762.56	0.284184
1763.58	0.295002
1764.6	-0.651552
1765.62	-3.50353
1766.64	-2.56974
1767.66	1.24574
1768.68	-0.630329
1769.7	1.29168
1770.72	2.2626
1771.74	2.27809
1772.76	-0.551931
1773.78	0.415262
1774.8	2.31871
1775.82	-0.543861
1776.84	1.3581
1777.86	-0.527016
1778.88	1.3913
1779.9	-0.491697
1780.92	-0.473709
1781.94	0.502254
1782.95	0.508633
1783.97	1.47652
1784.99	0.561161
1786.01	-1.31201
1787.03	-3.20376
1788.04	-1.27517
1789.06	0.631285
1790.08	-0.313223
1791.09	1.6156
1792.11	2.59051
1793.13	0.710133
1794.14	-2.14961
1795.16	2.67459
1796.17	-3.08546
1797.19	-0.205162
1798.21	-0.204342
1799.22	-2.11608
1800.24	1.74665
1801.25	1.76386
1802.27	0.824324
1803.28	-0.115431
1804.29	0.862171
1805.31	3.76158
1806.32	1.84356
1807.34	-1.03911
1808.35	-0.0703373
1809.36	-1.02681
1810.38	1.88323
1811.39	2.87024
1812.4	-2.90237
1813.41	1.94002
1814.43	1.94196
1815.44	1.94067
1816.45	0.988289
1817.46	-0.93111
1818.47	0.0502243
1819.49	2.96843
1820.5	1.04
1821.51	2.01183
1822.52	-1.84866
1823.53	2.03174
1824.54	3.01006
1825.55	-1.82652
1826.56	2.04633
1827.57	3.01218
1828.58	0.116035
1829.59	-0.838778
1830.6	4.01819
1831.61	-0.827522
1832.62	-2.78792
1833.63	0.202412
1834.64	0.135191
1835.65	0.105278
1836.65	2.09521
1837.66	0.134237
1838.67	0.102346
1839.68	2.01141
1840.69	1.0529
1841.7	-0.872959
1842.7	0.0949039
1843.71	-0.838995
1844.72	-0.901489
1845.72	1.03351
1846.73	-0.902435
1847.74	2.92259
1848.74	0.0279121
1849.75	-2.85283
1850.75	4.82521
1851.76	1.92521
1852.76	-0.00793839
1853.77	0.947206
1854.78	-0.0145512
1855.78	-0.0265923
1856.79	2.82722
1857.79	1.87902
1858.79	-0.0214062
1859.8	4.75351
1860.8	-1.00029
1861.81	-0.0569477
1862.81	1.83081
1863.81	0.846083
1864.82	1.77007
1865.82	-2.98784
1866.82	1.76343
1867.83	-0.141228
1868.83	1.75427
1869.83	-1.10666
1870.83	-2.06363
1871.84	-0.180847
1872.84	0.743725
1873.84	-0.228502
1874.84	0.673975
1875.84	1.66562
1876.84	-3.05286
1877.84	-0.215364
1878.84	0.705809
1879.84	-0.281126
1880.84	-0.275187
1881.84	1.58326
1882.85	0.661282
1883.85	2.55654
1884.84	0.646189
1885.84	-3.1482
1886.84	1.54495
1887.84	1.55351
1888.84	-1.27685
1889.84	-1.28518
1890.84	-0.375816
1891.84	2.43232
1892.83	-2.26482
1893.83	3.38368
1894.83	0.566692
1895.83	1.49566
1896.83	-0.401361
1897.82	1.47052
1898.82	2.42091
1899.82	1.48807
1900.81	-1.34424
1901.81	0.52927
1902.81	-0.418167
1903.8	-0.437868
1904.8	-1.3822
1905.79	-4.19742
1906.79	0.510592
1907.79	1.47133
1908.78	-1.35082
1909.78	-1.35849
1910.77	-1.35884
1911.77	0.539791
1912.76	1.48851
1913.76	0.53252
1914.75	-2.31182
1915.74	0.519316
1916.74	-1.34948
1917.73	2.42819
1918.72	1.4942
1919.72	-1.34695
1920.71	-0.415209
1921.7	-0.430523
1922.7	2.40717
1923.69	0.53182
1924.68	1.48676
1925.67	0.541182
1926.66	-1.34824
1927.66	-0.387005
1928.65	5.30557
1929.64	-0.406883
1930.63	0.532808
1931.62	1.52463
1932.61	-3.20064
1933.61	0.59449
1934.6	0.572313
1935.59	1.50905
1936.58	5.32664
1937.57	3.42784
1938.56	-0.371389
1939.55	-1.33876
1940.54	0.569235
1941.52	1.52194
1942.51	-0.377962
1943.5	1.5406
1944.49	0.576456
1945.48	0.566313
1946.47	1.52378
1947.46	0.582575
1948.44	-1.31422
1949.43	-2.26634
1950.42	-0.346348
1951.41	-2.30702
1952.39	-5.20375
1953.38	-0.393536
1954.37	0.576443
1955.36	3.46281
1956.34	1.52816
1957.33	2.47115
1958.31	0.52898
1959.3	3.39813
1960.29	2.43343
1961.27	-1.41008
1962.26	1.46163
1963.24	0.499998
1964.23	-0.457771
1965.21	-0.464037
1966.2	0.482401
1967.18	-6.26738
1968.17	-0.527727
1969.15	0.420576
1970.14	-0.548115
1971.12	-1.52784
1972.1	0.380129
1973.09	0.381117
1974.07	2.29386
1975.05	3.23518
1976.04	0.341887
1977.02	0.334967
1978	-0.641216
1978.98	1.25872
1979.97	0.2836
1980.95	-0.696861
1981.93	-0.712475
1982.91	-1.68586
1983.89	0.225046
1984.88	0.205847
1985.86	-0.794704
1986.84	0.112984
1987.82	2.01764
1988.8	-1.76199
1989.78	0.105074
1990.76	-0.891918
1991.74	1.08786
1992.72	0.298855
1993.7	1.64323
1994.68	1.98916
1995.66	-1.47956
1996.64	1.68559
1997.62	-0.420149
1998.6	-0.317823
1999.57	-0.0452614
2000.55	-0.0745087
2001.53	1.79494
2002.51	0.268526
2003.49	1.11035
2004.47	-0.0821514
2005.44	2.48001
2006.42	-0.218752
2007.4	1.23148
2008.38	-0.156786
2009.35	-0.650862
2010.33	-0.849892
2011.3	0.365513
2012.18	1.64814
2013.17	1.64794
2014.16	-1.15845
2015.15	-1.18474
2016.14	-2.15747
2017.13	1.5673
2018.11	1.55804
2019.1	-2.1968
2020.09	-2.21846
2021.08	-0.370941
2022.06	-1.33431
2023.05	-1.36345
2024.04	1.46201
2025.02	1.4712
2026.01	-0.365517
2027	-0.435274
2027.98	1.39434
2028.97	0.465065
2029.96	0.483686
2030.94	-1.3741
2031.93	2.30445
2032.91	0.471861
2033.9	2.33484
2034.88	1.39662
2035.87	0.443939
2036.85	-1.44378
2037.83	-1.46878
2038.82	0.379835
2039.8	2.22627
2040.79	-4.29139
2041.77	2.23723
2042.75	1.30197
2043.74	1.32358
2044.72	1.28133
2045.7	1.27235
2046.69	2.21712
2047.67	-2.43561
2048.65	-2.44833
2049.63	3.15297
2050.62	0.359959
2051.6	-1.49885
2052.58	-0.574926
2053.56	-0.58642
2054.54	1.27936
2055.52	-1.5178
2056.5	3.17048
2057.48	0.354757
2058.46	3.16382
2059.45	2.22744
2060.43	0.36253
2061.4	0.36714
2062.39	-1.49735
2063.37	-1.48517
2064.34	1.33586
2065.32	-0.535732
2066.3	-1.47659
2067.28	-1.49415
2068.26	2.29047
2069.24	-1.4537
2070.22	-0.518314
2071.2	1.36408
2072.18	0.437582
2073.15	-0.47805
2074.13	2.34765
2075.11	3.2734
2076.09	-0.490522
2077.06	0.473032
2078.04	0.476297
2079.02	2.36142
2080	3.31069
2080.97	-1.4171
2081.95	-0.471951
2082.93	2.36376
2083.9	2.38334
2084.88	0.499044
2085.85	1.44815
2086.83	0.513744
2087.8	2.41543
2088.78	-3.26007
2089.75	0.557657
2090.73	2.4793
2091.7	1.53974
2092.68	1.53126
2093.65	-2.27555
2094.63	2.46328
2095.6	0.558901
2096.57	4.35396
2097.55	0.560892
2098.52	1.52557
2099.5	1.52869
2100.47	-1.32834
2101.44	-2.27541
2102.41	-0.362856
2103.39	-0.348198
2104.36	-1.29187
2105.33	0.596413
2106.3	-1.31064
2107.27	-1.29889
2108.25	1.55415
2109.22	-0.349255
2110.19	-3.18994
2111.16	-2.22762
2112.13	-1.27424
2113.1	1.57495
2114.07	-1.281
2115.04	0.617668
2116.01	-0.345074
2116.99	0.591959
2117.96	2.49139
2118.92	-0.332232
2119.9	0.634935
2120.86	-1.25497
2121.83	-1.26574
2122.8	3.44632
2123.77	-1.30036
2124.74	1.53148
2125.71	1.53258
2126.68	-1.30037
2127.65	-2.24314
2128.61	2.47647
2129.58	2.47123
2130.55	-1.30278
2131.52	1.53756
2132.48	-0.34561
2133.45	-0.354719
2134.42	0.593903
2135.39	0.600962
2136.35	3.44761
2137.32	-1.282
2138.28	-0.339708
2139.25	0.59997
2140.22	2.51368
2141.18	-2.23425
2142.15	1.54109
2143.12	0.607908
2144.08	1.5493
2145.05	0.608082
2146.01	0.606602
2146.98	1.53202
2147.94	-1.28372
2148.9	-0.328119
2149.87	3.43066
2150.83	0.616299
2151.8	-1.2694
2152.76	-2.2207
2153.72	0.580988
2154.69	-1.27475
2155.65	-0.323452
2156.61	-0.321318
2157.58	0.605028
2158.54	2.47208
2159.5	0.61322
2160.47	1.54931
2161.43	1.54871
2162.39	1.55264
2163.35	0.629856
2164.31	-0.302698
2165.27	-2.17843
2166.24	1.55095
2167.2	-1.20705
2168.16	-0.263662
2169.12	0.648149
2170.08	-2.13894
2171.04	-1.19619
2172	-0.253122
2172.96	0.683846
2173.92	-0.240934
2174.88	-1.15833
2175.84	-1.15623
2176.8	-2.07279
2177.76	0.722111
2178.72	0.728245
2179.68	-0.195868
2180.64	1.65517
2181.59	-0.19812
2182.55	-0.181568
2183.51	-0.158356
2184.47	-1.05392
2185.43	1.74378
2186.38	-2.90168
2187.34	-0.121588
2188.3	3.6022
2189.26	1.76598
2190.21	-0.995853
2191.17	2.75478
2192.13	0.915121
2193.08	-0.0162868
2194.04	-0.0250111
2195	0.908878
2195.95	-0.919245
2196.91	0.0445728
2197.86	-0.84049
2198.82	1.01847
2199.78	-2.71288
2200.73	1.03507
2201.69	2.02506
2202.64	1.04721
2203.59	-2.65831
2204.55	-1.71706
2205.5	1.10069
2206.46	-3.53468
2207.41	-0.726965
2208.37	0.227201
2209.32	1.18509
2210.27	-0.67227
2211.23	0.26976
2212.18	-1.5676
2213.13	-1.55411
2214.09	2.18911
2215.04	-3.4002
2215.99	-0.583744
2216.94	1.30659
2217.9	-0.551542
2218.85	-1.48897
2219.8	0.383923
2220.75	-1.46121
2221.7	-3.3026
2222.65	-1.4057
2223.6	-0.444975
2224.55	2.39038
2225.5	1.46087
2226.46	1.46737
2227.41	-1.32125
2228.36	0.580652
2229.31	1.54567
2230.26	0.629246
2231.21	-0.290964
2232.16	-3.11181
2233.11	0.650723
2234.05	-1.21765
2235	1.63719
2235.95	-1.15898
2236.9	-1.14658
2237.85	0.743786
2238.8	0.763685
2239.75	1.72313
2240.69	2.66939
2241.64	-0.152802
2242.59	1.76823
2243.54	1.79128
2244.48	-1.03044
2245.43	-0.0779953
2246.38	1.81779
2247.32	-2.9037
2248.27	0.873413
2249.22	-1.0121
2250.16	-0.0387497
2251.11	-1.90824
2252.06	-0.94981
2253	0.00671005
2253.95	2.87171
2254.89	0.990824
2255.84	-3.74772
2256.78	-0.884916
2257.73	-1.82341
2258.67	0.0961533
2259.62	1.05946
2260.56	1.08304
2261.51	2.06949
2262.45	1.13699
2263.39	1.13728
2264.34	0.17086
2265.28	-2.6983
2266.22	0.171591
2267.17	-2.66869
2268.11	-1.6967
2269.05	-0.726799
2270	0.236835
2270.94	0.243668
2271.88	-0.707211
2272.82	1.21285
2273.77	-0.685202
2274.71	0.295408
2275.65	-0.644081
2276.59	0.313578
2277.53	0.292881
2278.47	0.284267
2279.41	-1.62783
2280.36	-1.61153
2281.3	0.340399
2282.24	-0.605726
2283.18	-1.57502
2284.12	1.32377
2285.06	-1.54834
2286	-0.593903
2286.94	2.26647
2287.88	-2.54465
2288.82	2.28155
2289.75	4.22315
2290.69	-0.581486
2291.63	2.30384
2292.57	0.365204
2293.51	2.27259
2294.45	-0.608522
2295.39	0.372383
2296.32	0.386171
2297.26	1.3547
2298.2	-0.569017
2299.14	-0.567179
2300.07	-1.5362
2301.01	0.393572
2301.95	-2.4945
2302.89	2.3419
2303.82	-0.552811
2304.76	-1.52508
2305.69	0.401608
2306.63	1.37801
2307.57	-0.545666
2308.5	-4.42914
2309.44	0.376762
2310.37	0.371641
2311.31	0.393448
2312.24	1.38113
2313.18	-1.53843
2314.11	0.375471
2315.05	1.35052
2315.98	3.26513
2316.92	-1.57077
2317.85	0.360435
2318.78	1.33855
2319.72	0.389551
2320.65	0.391594
2321.58	-0.575338
2322.52	3.26831
2323.45	1.3213
2324.38	3.23341
2325.32	5.15372
2326.25	8.03683
2327.18	35.0024
2328.11	48.4715
2329.05	11.8976
2329.98	7.06267
2330.91	1.27868
2331.84	1.26769
2332.77	1.26776
2333.7	2.23017
2334.63	3.19188
2335.56	-0.653751
2336.5	2.23499
2337.43	0.310354
2338.36	-0.661829
2339.29	-0.672977
2340.22	-1.63078
2341.15	0.292473
2342.08	-1.61677
2343.01	-0.661959
2343.93	0.298384
2344.86	-2.56718
2345.79	1.2777
2346.72	1.26764
2347.65	1.22036
2348.58	-1.56522
2349.51	1.26476
2350.44	0.289167
2351.36	3.15586
2352.29	0.321289
2353.22	-0.6229
2354.15	-1.57953
2355.07	1.28057
2356	-0.609297
2356.93	-0.595856
2357.86	-0.58952
2358.78	-1.53111
2359.71	1.31701
2360.63	2.27608
2361.56	2.29197
2362.49	-2.41909
2363.41	-0.528028
2364.34	-2.36957
2364.8	-0.458944