File: Data/3-Raman/processed/bu19(2)w-a-ff2-fi02-v_150 (500nm)_532nm_edge_100%_x100_vis_lwd_h50um_30sx2_01.txt
#Acq. time (s)=	30
#Accumulations=	2
#Range (cm-¹)=	99...4000
#Windows=	1
#Auto scanning=	Off
#Autofocus=	Off
#Macrospot=	Off
#AutoExposure=	Off
#Spike filter=	Multiple accum.
#Delay time (s)=	2
#Binning=	1
#Readout mode=	Signal
#DeNoise=	Off
#ICS correction=	On
#Dark correction=	Off
#Inst. Process=	Off
#Detector Gain=	Best Dynamic
#Detector ADC=	50 kHz HS
#Detector temperature (°C)=	-60.09
#Instrument=	LabRAM HR Evol
#Detector=	SIN-EM FIVIS
#Objective=	x50_VIS_LWD
#Grating=	150 (500nm)
#ND Filter=	100%
#Laser=	532nm_Edge
#Hole=	49.98
#Temperature=	0
#Range=	Visible
#StageXY=	75x50mm Scan+
#StageZ=	Z motor
#X (µm)=	0
#Y (µm)=	0
#Z (µm)=	-0.3
#Full time(mm:ss)=	1:05
#Project=	21_11_26
#Sample=	BU19(2)w
#Site=
#Title=	BU19(2)w-A-FF02-FI02-V_150 (500nm)_532nm_Edge_100%_x50_VIS_LWD_H50um_30sX2
#Remark=
#Date=	26.11.2021 14:32
#Acquired=	26.11.2021 14:32:10
#Base:Fit=	16.12.2021 16:00:56
#Base:Edit=	16.12.2021 16:10:54
#Base:Edit=	16.12.2021 16:10:55
#Base:Sub=	16.12.2021 16:10:58
102.91	2699.06
107.534	3404.81
112.156	3271.68
116.775	2406.29
121.392	1536.97
126.005	1264.6
130.617	1583.13
135.227	2653.38
139.835	4846.32
144.439	7530.18
149.042	7756.85
153.643	5229.85
158.242	2868.41
162.839	1510.9
167.431	839.698
172.023	442.239
176.613	220.198
181.198	77.8357
185.783	50.5163
190.366	-1.27557
194.947	105.953
199.524	415.014
204.1	1252.51
208.674	2444.57
213.243	1640.51
217.813	595.774
222.38	435.476
226.945	831.603
231.506	1992.49
236.066	2315.53
240.625	1140.02
245.179	363.81
249.732	110.834
254.284	-0.131226
258.831	13.5742
263.378	2.13232
267.923	20.2809
272.464	46.1062
277.004	179.067
281.54	301.549
286.076	184.896
290.61	86.0836
295.139	60.6597
299.669	89.2009
304.196	119.552
308.718	163.718
313.241	209.865
317.759	300.252
322.278	451.488
326.794	762.617
331.305	1090.16
335.817	1218.59
340.324	1091.96
344.832	1123.35
349.334	1444.78
353.837	1481.41
358.338	980.909
362.834	680.723
367.33	618.652
371.822	667.492
376.314	748.976
380.802	1049.88
385.289	1737.96
389.772	3029.03
394.255	3710.17
398.734	3355.99
403.213	2734.09
407.688	2210.83
412.162	1820.34
416.632	1789.61
421.102	1849.92
425.568	2138.27
430.033	2245.43
434.495	2176.14
438.956	2043.36
443.413	2107.32
447.87	2367.25
452.323	2425.35
456.776	2047.54
461.224	1477.37
465.673	1048.43
470.117	808.071
474.561	732.868
479.001	794.077
483.438	909.858
487.876	1210.61
492.309	1687.76
496.742	2335.15
501.172	3299.39
505.601	4208.21
510.025	4787.6
514.448	4634.71
518.871	3918.97
523.289	3358.42
527.707	2874.84
532.121	2655.12
536.533	2652.11
540.945	2694.3
545.353	2774.57
549.758	2700.75
554.164	2490.55
558.565	2250.71
562.965	1792.36
567.364	1467.08
571.759	1198.93
576.151	1023.79
580.544	962.905
584.933	1024.8
589.319	1145.38
593.706	1365.25
598.088	1652.47
602.468	2076.19
606.848	2860.03
611.224	4448.27
615.598	7529.98
619.972	10135.8
624.341	8134.62
628.709	4814.23
633.074	2725.33
637.44	1722.12
641.801	1194.89
646.16	804.074
650.517	631.217
654.874	478.603
659.227	372.727
663.578	280.331
667.927	213.115
672.275	204.944
676.62	154.954
680.962	136.724
685.302	142.042
689.643	174.077
693.979	253.64
698.313	354.186
702.645	440.718
706.975	394.478
711.305	331.98
715.631	222.987
719.955	172.696
724.276	183.996
728.596	164.829
732.913	71.8907
737.231	36.9705
741.544	22.7828
745.856	8.19193
750.165	0.29541
754.472	5.48294
758.778	2.9509
763.081	16.1896
767.384	13.4881
771.683	-14.1364
775.98	11.2257
780.275	15.809
784.568	22.7788
788.859	37.8482
793.147	46.443
797.434	56.9871
801.719	89.7827
806.004	77.8734
810.284	102.502
814.563	145.97
818.839	198.408
823.114	324.645
827.386	469.963
831.657	646.436
835.925	868.406
840.192	1074.06
844.456	1176.1
848.719	1172.83
852.979	988.903
857.237	805.225
861.493	632.785
865.748	583.726
870	531.175
874.25	648.83
878.499	729.741
882.745	628.456
886.989	451.807
891.231	265.759
895.471	181.564
899.71	101.053
903.946	73.9223
908.18	22.275
912.412	35.1923
916.642	21.383
920.87	14.0433
925.096	26.0072
929.321	-2.07254
933.543	-6.91922
937.763	-10.674
941.981	20.8507
946.197	24.4669
950.412	7.8244
954.622	27.6399
958.832	43.2433
963.04	38.721
967.246	15.1929
971.451	25.7686
975.653	58.7311
979.853	82.2214
984.052	94.1856
988.248	179.216
992.442	220.89
996.633	317.074
1000.82	371.524
1005.01	356.278
1009.2	267.835
1013.38	226.02
1017.57	198.874
1021.75	177.023
1025.92	216.938
1030.1	288.747
1034.27	337.98
1038.45	497.437
1042.62	684.779
1046.78	825.788
1050.95	795.982
1055.12	719.392
1059.28	798.301
1063.44	860.655
1067.6	1011.71
1071.75	1234.04
1075.91	1551.01
1080.06	2202.39
1084.21	3169.38
1088.36	4721.86
1092.51	6378.72
1096.65	6723.09
1100.8	5140.79
1104.94	3170.46
1109.08	1879.07
1113.21	1268.4
1117.35	958.241
1121.48	884.726
1125.61	853.238
1129.74	968.288
1133.87	1184.51
1137.99	1603.11
1142.12	2044.5
1146.24	2095.77
1150.36	1840.4
1154.48	1361.35
1158.59	941.852
1162.71	670.398
1166.82	468.763
1170.93	374.309
1175.04	274.557
1179.14	187.221
1183.25	142.228
1187.35	132.131
1191.45	67.4194
1195.55	64.2679
1199.65	47.7306
1203.74	53.5906
1207.83	55.3379
1211.92	60.1449
1216.01	47.7924
1220.1	70.817
1224.19	74.7074
1228.27	91.7198
1232.35	109.84
1236.43	151.259
1240.51	212.894
1244.58	434.106
1248.66	724.27
1252.73	394.944
1256.8	323.276
1260.87	463.538
1264.93	3297.84
1269	6513.25
1273.06	1922
1277.12	436.265
1281.18	285.306
1285.23	201.306
1289.29	178.446
1293.34	178.646
1297.39	147.536
1301.44	141.543
1305.49	130.412
1309.53	114.202
1313.58	115.071
1317.62	131.903
1321.66	124.45
1325.7	125.899
1329.73	132.307
1333.77	127.61
1337.8	161.866
1341.83	176.918
1345.86	245.791
1349.88	290.471
1353.91	440.472
1357.93	386.344
1361.95	436.453
1365.97	1009.12
1369.99	8592.13
1374	8747.45
1378.02	1752.75
1382.03	454.314
1386.04	371.986
1390.05	687.491
1394.05	1031.7
1398.06	434.242
1402.06	188.902
1406.06	150.289
1410.06	121.533
1414.05	99.6785
1418.05	60.029
1422.04	44.0122
1426.03	21.0126
1430.02	35.3748
1434.01	18.1465
1438	7.81271
1441.98	-4.50653
1445.96	-4.04294
1449.94	-14.4638
1453.92	-20.0005
1457.9	-29.5125
1461.87	-45.9605
1465.85	-31.9499
1469.82	-27.8262
1473.78	-8.96318
1477.75	-30.4032
1481.72	-28.3198
1485.68	-24.312
1489.65	-23.2745
1493.61	-18.3337
1497.56	-13.4141
1501.52	-12.3912
1505.47	-14.2635
1509.43	-17.0593
1513.38	-18.8798
1517.33	-11.9656
1521.27	-6.02083
1525.22	-25.2992
1529.16	-15.4776
1533.11	-18.2535
1537.05	-4.56274
1540.98	-12.2065
1544.92	-2.42216
1548.86	-21.7224
1552.79	-5.19138
1556.72	2.57478
1560.65	1.57309
1564.58	-5.2738
1568.5	-4.41336
1572.43	7.04424
1576.35	-3.74443
1580.27	-4.89188
1584.19	-5.09431
1588.1	6.23354
1592.02	5.97017
1595.93	4.72632
1599.84	11.1573
1603.75	12.779
1607.66	8.65961
1611.57	13.1656
1615.47	13.8329
1619.37	22.1778
1623.27	6.54849
1627.17	17.7502
1631.07	8.86142
1634.97	15.3389
1638.86	2.64583
1642.75	28.2882
1646.64	15.6582
1650.53	38.4941
1654.42	30.652
1658.3	25.644
1662.18	21.5653
1666.07	25.1138
1669.94	18.0502
1673.82	18.5943
1677.7	26.8008
1681.57	12.7747
1685.44	32.2971
1689.31	18.1891
1693.18	47.155
1697.05	32.0016
1700.92	30.2119
1704.78	25.5085
1708.64	38.8457
1712.5	32.127
1716.36	48.1703
1720.21	35.7736
1724.07	29.0841
1727.92	31.8102
1731.77	48.5727
1735.62	48.3908
1739.47	36.0103
1743.32	56.3125
1747.16	36.4859
1751.01	47.5345
1754.85	52.1249
1758.69	63.3207
1762.52	64.7037
1766.36	74.2565
1770.19	49.5332
1774.02	42.5396
1777.85	39.2506
1781.68	33.2209
1785.51	29.0653
1789.33	36.1294
1793.16	41.344
1796.98	27.8042
1800.8	34.8762
1804.62	29.5866
1808.43	28.0259
1812.25	29.2563
1816.06	21.9516
1819.87	24.9212
1823.68	31.6029
1827.49	37.2915
1831.3	24.9925
1835.1	23.9532
1838.9	17.2251
1842.71	31.1593
1846.51	26.22
1850.3	38.1956
1854.1	20.9971
1857.89	31.8412
1861.69	13.6542
1865.48	17.8522
1869.27	25.7581
1873.05	25.3071
1876.84	22.1199
1880.62	24.4911
1884.4	26.9353
1888.19	38.5811
1891.96	20.0827
1895.74	40.2405
1899.52	31.8649
1903.29	30.9382
1907.06	41.0963
1910.83	33.7784
1914.6	35.7456
1918.37	23.8817
1922.13	24.1331
1925.9	24.4018
1929.66	31.2
1933.42	25.9524
1937.18	24.4017
1940.94	43.3741
1944.69	18.4457
1948.44	34.6566
1952.2	33.8527
1955.95	31.0787
1959.69	43.2169
1963.44	45.8863
1967.19	76.711
1970.93	80.2122
1974.67	77.0444
1978.41	85.0687
1982.15	89.2838
1985.89	102.781
1989.62	109.673
1993.35	125.808
1997.09	124.158
2000.82	115.96
2004.55	122.62
2008.27	112.589
2012	85.937
2015.72	84.2461
2019.44	75.3475
2023.16	64.7817
2026.88	62.6324
2030.6	61.4131
2034.31	60.3119
2038.03	47.397
2041.74	55.5146
2045.45	34.3162
2049.16	36.0119
2052.86	42.3321
2056.57	45.0055
2060.27	28.5481
2063.98	35.1434
2067.67	26.1796
2071.37	24.5746
2075.07	26.6604
2078.77	22.2982
2082.46	24.4221
2086.15	20.959
2089.84	26.5311
2093.53	12.5022
2097.22	11.5739
2100.9	27.3512
2104.59	17.0233
2108.27	12.241
2111.95	21.3789
2115.63	17.4934
2119.31	11.7273
2122.98	6.81906
2126.66	18.5774
2130.33	8.96823
2134	21.5766
2137.67	13.8076
2141.34	14.3338
2145	13.908
2148.67	3.3542
2152.33	25.8923
2155.99	23.614
2159.65	14.9473
2163.31	9.99118
2166.96	-1.30493
2170.62	2.96017
2174.27	6.3891
2177.92	-5.61581
2181.57	1.52911
2185.22	-8.62018
2188.87	4.93536
2192.51	3.10596
2196.15	0.447968
2199.8	9.67609
2203.44	4.35605
2207.07	6.36328
2210.71	12.0694
2214.35	3.17458
2217.98	9.85513
2221.61	3.70772
2225.24	5.83356
2228.87	1.50742
2232.5	2.71198
2236.12	14.1065
2239.75	11.6508
2243.37	-2.86623
2246.99	8.56616
2250.61	1.44719
2254.23	5.50853
2257.85	-4.39392
2261.46	-5.91803
2265.07	-4.65672
2268.68	2.26048
2272.29	-1.08928
2275.9	-2.61661
2279.51	3.34633
2283.11	-0.239761
2286.72	-3.83223
2290.32	5.8036
2293.92	4.07991
2297.52	8.04156
2301.11	7.28416
2304.71	22.6028
2308.3	50.2128
2311.9	315.729
2315.49	723.395
2319.08	219.111
2322.66	28.6051
2326.25	10.4826
2329.84	26.4135
2333.42	-2.09248
2337	23.1976
2340.58	-0.565247
2344.16	2.04718
2347.73	2.75275
2351.31	11.8743
2354.88	5.99788
2358.45	11.3312
2362.03	-1.05898
2365.59	3.32784
2369.16	12.3506
2372.73	8.42932
2376.29	9.13094
2379.85	3.37857
2383.41	5.0423
2386.97	7.64243
2390.53	-2.59026
2394.09	2.84143
2397.64	7.40517
2401.2	-6.29747
2404.75	1.18602
2408.3	-5.96933
2411.85	16.2986
2415.39	4.68384
2418.94	-1.3922
2422.48	-0.0910797
2426.03	10.4746
2429.57	-3.80025
2433.11	2.25829
2436.64	12.0916
2440.18	-2.16728
2443.72	6.80438
2447.25	11.1556
2450.78	8.08173
2454.31	-6.23889
2457.84	7.47063
2461.37	1.28214
2464.89	0.718094
2468.42	-0.00244141
2471.94	4.14586
2475.46	23.0859
2478.98	4.24725
2482.5	9.96936
2486.01	9.01953
2489.53	13.5949
2493.04	7.93266
2496.55	21.8748
2500.06	6.80939
2503.57	14.1712
2507.08	14.9397
2510.58	4.47736
2514.09	9.88242
2517.59	6.95544
2521.09	10.5623
2524.59	1.06512
2528.09	13.9693
2531.59	-0.816116
2535.08	8.44833
2538.58	7.60689
2542.07	6.80855
2545.56	5.17561
2549.05	1.77211
2552.54	6.68918
2556.02	21.8426
2559.51	5.62166
2562.99	11.6278
2566.47	11.2262
2569.95	7.15031
2573.43	7.77319
2576.91	10.3066
2580.38	6.30566
2583.85	13.6046
2587.33	15.2676
2590.8	20.681
2594.27	2.24355
2597.74	14.1806
2601.2	5.21155
2604.67	0.00849915
2608.13	12.8989
2611.59	25.6589
2615.06	20.0454
2618.51	21.2231
2621.97	22.3141
2625.43	8.94814
2628.88	8.98058
2632.33	11.8587
2635.79	14.6824
2639.24	9.77182
2642.69	22.0666
2646.13	11.3402
2649.58	4.44559
2653.02	17.5405
2656.47	19.1178
2659.91	18.7447
2663.35	13.6114
2666.79	24.5401
2670.22	16.5559
2673.66	9.53423
2677.09	18.5193
2680.52	17.191
2683.95	5.62611
2687.39	14.6862
2690.81	8.92722
2694.24	25.5984
2697.66	8.68173
2701.09	23.4633
2704.51	23.3485
2707.93	8.35831
2711.35	15.8161
2714.77	12.1472
2718.18	5.7117
2721.6	12.3435
2725.01	20.8722
2728.42	6.07829
2731.84	2.47624
2735.24	14.7634
2738.65	10.202
2742.06	14.0587
2745.46	2.85443
2748.86	19.7896
2752.27	6.65373
2755.67	15.1187
2759.07	17.9162
2762.46	8.46744
2765.86	10.2607
2769.25	21.4418
2772.65	-2.28325
2776.04	12.6033
2779.43	16.1397
2782.82	9.2818
2786.2	11.8185
2789.59	13.3974
2792.98	0.859879
2796.36	8.05052
2799.74	3.01976
2803.12	21.4089
2806.5	3.20816
2809.88	29.0418
2813.25	20.189
2816.63	5.72192
2820	27.6966
2823.37	0.19223
2826.74	11.9172
2830.11	23.6342
2833.48	1.81454
2836.84	4.25594
2840.21	27.2133
2843.57	12.0086
2846.93	14.5424
2850.29	16.21
2853.65	11.3844
2857.01	23.3368
2860.36	6.33878
2863.72	8.98267
2867.07	7.88322
2870.42	8.65187
2873.77	27.2512
2877.12	17.6621
2880.47	7.09854
2883.81	15.3458
2887.16	0.00427246
2890.5	7.27977
2893.84	10.7692
2897.18	19.8793
2900.52	-0.359131
2903.86	5.83948
2907.19	12.0081
2910.53	3.01147
2913.86	20.4872
2917.19	-3.69505
2920.52	20.3386
2923.85	2.72769
2927.18	1.17278
2930.51	4.30663
2933.83	0.794373
2937.15	18.0067
2940.48	29.5259
2943.8	21.2347
2947.11	9.18866
2950.43	8.44595
2953.75	12.3874
2957.06	5.04936
2960.38	21.2153
2963.69	5.47157
2967	9.44327
2970.31	1.27591
2973.62	8.14494
2976.92	17.8298
2980.23	1.27425
2983.53	10.0187
2986.84	-5.63344
2990.14	18.1472
2993.44	10.9471
2996.73	9.38457
3000.03	0.305618
3003.33	18.4807
3006.62	26.3163
3009.91	16.2876
3013.2	12.8464
3016.49	6.57283
3019.78	4.05202
3023.07	4.3484
3026.35	22.573
3029.64	15.3174
3032.92	7.09863
3036.2	15.8704
3039.48	26.5291
3042.76	13.5396
3046.04	-0.409332
3049.32	14.9839
3052.59	4.80298
3055.86	8.83313
3059.14	9.05853
3062.41	17.7424
3065.68	24.5628
3068.94	14.2674
3072.21	-6.52533
3075.48	25.6022
3078.74	11.4888
3082	25.7358
3085.26	15.5366
3088.52	8.15596
3091.78	5.57681
3095.04	22.0226
3098.29	19.139
3101.55	35.4286
3104.8	47.8663
3108.05	31.8965
3111.3	32.0511
3114.55	40.6844
3117.8	30.2983
3121.04	31.3405
3124.29	42.8574
3127.53	29.6004
3130.77	51.5845
3134.02	46.8922
3137.25	32.6556
3140.49	51.7629
3143.73	55.6133
3146.96	50.8832
3150.2	49.0297
3153.43	71.0244
3156.66	59.6236
3159.89	58.7215
3163.12	67.3484
3166.35	60.709
3169.57	78.8504
3172.8	84.5612
3176.02	91.2098
3179.24	83.516
3182.46	76.7731
3185.68	80.5298
3188.9	79.4773
3192.12	94.6201
3195.33	116.422
3198.55	89.6223
3201.76	117.112
3204.97	110.329
3208.18	95.9477
3211.39	132.975
3214.6	106.273
3217.8	115.753
3221.01	137.602
3224.21	145.195
3227.41	135.708
3230.61	122.426
3233.81	136.766
3237.01	156.796
3240.21	131.239
3243.4	152.352
3246.59	133.495
3249.79	175.624
3252.98	186.374
3256.17	187.612
3259.36	182.164
3262.54	182.379
3265.73	186.354
3268.92	223.703
3272.1	229.486
3275.28	219.959
3278.46	250.547
3281.64	233.272
3284.82	237.874
3288	283.509
3291.17	257.543
3294.35	285.979
3297.52	278.171
3300.69	324.659
3303.86	302.721
3307.03	322.516
3310.2	332.726
3313.36	355.184
3316.53	379.472
3319.69	388.533
3322.85	435.471
3326.02	426.468
3329.18	452.502
3332.33	494.589
3335.49	499.829
3338.65	562.728
3341.8	555.796
3344.95	596.054
3348.11	616.711
3351.26	654.56
3354.41	718.791
3357.56	714.338
3360.7	772.162
3363.85	816.943
3366.99	873.096
3370.13	897.279
3373.28	931.921
3376.42	989.401
3379.56	1036.61
3382.69	1077.34
3385.83	1129.4
3388.97	1219.48
3392.1	1277.52
3395.23	1371.55
3398.36	1449.14
3401.49	1523.07
3404.62	1584.97
3407.75	1697.53
3410.88	1815.21
3414	1901.67
3417.13	2064.95
3420.25	2241.69
3423.37	2404.14
3426.49	2631.11
3429.61	2858.69
3432.73	3072.56
3435.84	3319.17
3438.96	3711.87
3442.07	4139.23
3445.18	4786.73
3448.29	5704.61
3451.4	7342.25
3454.51	9429.65
3457.62	10955.4
3460.72	10492.7
3463.83	8884.06
3466.93	7151.13
3470.03	6203.14
3473.13	5481.63
3476.23	5245.43
3479.33	4971.13
3482.43	4893.25
3485.53	4841.16
3488.62	4793.29
3491.71	4802.92
3494.81	4796.96
3497.9	4812.53
3500.99	4880.58
3504.07	4961.93
3507.16	5022.59
3510.25	5129.32
3513.33	5315.18
3516.41	5726.72
3519.5	5918.15
3522.58	6320.7
3525.66	6692.05
3528.73	7180.53
3531.81	7621.81
3534.89	7944.55
3537.96	8160.42
3541.03	8102.38
3544.11	7636.36
3547.18	6900.76
3550.25	5958.95
3553.32	5032.3
3556.38	4253.71
3559.45	3491.16
3562.51	2951.19
3565.58	2485.78
3568.64	2091.66
3571.7	1782.39
3574.76	1570.53
3577.82	1408.98
3580.87	1242.53
3583.93	1114.86
3586.98	1013.63
3590.04	932.354
3593.09	865.183
3596.14	817.938
3599.19	728.949
3602.24	679.82
3605.29	644.841
3608.33	642.011
3611.38	576.782
3614.42	547.51
3617.46	538.091
3620.5	523.077
3623.54	479.835
3626.58	493.253
3629.62	444.526
3632.65	417.485
3635.69	436.58
3638.72	379.634
3641.76	365.166
3644.79	303.756
3647.82	300.853
3650.84	256.396
3653.87	245.909
3656.9	227.231
3659.92	205.989
3662.95	182.786
3665.97	196.215
3668.99	163.258
3672.01	129.458
3675.03	160.752
3678.05	129.82
3681.07	126.279
3684.08	119.886
3687.1	123.906
3690.11	102.405
3693.12	88.4742
3696.13	89.6997
3699.14	71.9017
3702.15	85.4777
3705.16	62.0591
3708.16	57.6118
3711.17	57.8794
3714.17	69.5399
3717.17	60.2464
3720.17	38.6074
3723.17	58.805
3726.17	39.9533
3729.17	39.1671
3732.16	39.3172
3735.16	19.4445
3738.15	30.0176
3741.14	28.1909
3744.13	24.4313
3747.13	7.34064
3750.11	7.35495
3753.1	5.45352
3756.09	-3.08963
3759.07	9.26309
3762.06	7.37332
3765.04	6.41428
3768.02	-6.84186
3771	-3.02542
3773.98	-1.0777
3776.96	7.50555
3779.94	2.86908
3782.91	-12.1378
3785.89	-8.24608
3788.86	-14.7279
3791.83	2.40265
3794.8	-4.97256
3797.77	3.71442
3800.74	-1.74594
3803.71	-2.45938
3806.68	-23.001
3809.64	-5.76489
3812.61	-8.35825
3815.57	-11.9026
3818.53	-8.83263
3821.49	-4.81459
3824.45	-12.1607
3827.41	-23.3006
3830.36	-20.2452
3833.32	-15.3048
3836.27	-17.9447
3839.23	-7.29543
3842.18	-16.6101
3845.13	0.677048
3848.08	-2.9677
3851.03	-2.81711
3853.98	-4.58107
3856.92	7.95023
3859.87	6.15511
3862.81	-1.4016
3865.75	1.51552
3868.7	-0.377213
3871.64	-0.402405
3874.57	12.0061
3877.51	22.4728
3880.45	9.84721
3883.39	23.0921
3886.32	9.37642
3889.25	19.6345
3892.18	17.3539
3895.12	15.9875
3898.05	20.324
3900.97	10.1712
3903.9	16.3213
3906.83	28.1686
3909.75	13.088
3912.68	12.3628
3915.6	1.96506
3918.52	15.5251
3921.44	12.7511
3924.36	11.8046
3927.28	2.15025
3930.2	7.77536
3933.11	19.0815
3936.03	11.2267
3938.94	4.3293
3941.86	21.3581
3944.77	5.7518
3947.68	7.33606
3950.59	10.7992
3953.49	-4.93188
3956.4	7.05333
3959.31	5.58919
3962.21	7.90289
3965.12	15.9142
3968.02	23.8776
3970.92	-2.74905
3973.82	-2.58842
3976.72	14.7804
3979.61	15.7404
3982.51	-5.49623
3985.41	16.4317
3988.3	0.777771
3991.19	9.07121
3994.09	23.9881
3996.98	1.34816
3999.87	3.6282