File: Data/3-Raman/processed/bu19w-e-ff11-fi03-l_150 (500nm)_633nm_edge_100%_x100_vis_h50um_60sx2_01_0.txt
#Acq. time (s)=	60
#Accumulations=	2
#Range (cm-¹)=	100...4000
#Windows=	1
#Auto scanning=	Off
#Autofocus=	Off
#Macrospot=	Off
#AutoExposure=	Off
#Spike filter=	Multiple accum.
#Delay time (s)=	2
#Binning=	1
#Readout mode=	Signal
#DeNoise=	Off
#ICS correction=	On
#Dark correction=	Off
#Inst. Process=	Off
#Detector Gain=	Best Dynamic
#Detector ADC=	50 kHz HS
#Detector temperature (°C)=	-60.09
#Instrument=	LabRAM HR Evol
#Detector=	SIN-EM FIVIS
#Objective=	x100_VIS
#Grating=	150 (500nm)
#ND Filter=	100%
#Laser=	633nm_Edge
#Hole=	49.98
#Temperature=	0
#Range=	Visible
#StageXY=	75x50mm Scan+
#StageZ=	Z motor
#X (µm)=	0
#Y (µm)=	0
#Z (µm)=	-256.5
#Full time(mm:ss)=	2:04
#Project=	21_11_04
#Sample=	BU19w
#Site=
#Title=	BU19w-E-FF11-FI03-L_150 (500nm)_633nm_Edge_100%_x100_VIS_H50um_60sX2
#Remark=
#Date=	04.11.2021 16:54
#Acquired=	04.11.2021 16:54:35
#Base:Fit=	16.12.2021 17:39:50
#Base:Edit=	16.12.2021 17:49:26
#Base:Sub=	16.12.2021 17:49:28
102.881	223.578
109.397	199.209
115.908	166.606
122.414	166.714
128.914	235.066
135.409	279.761
141.898	264.325
148.383	277.052
154.861	493.199
161.335	469.471
167.801	190.011
174.264	67.6517
180.721	25.8568
187.173	15.7176
193.62	6.63135
200.061	0.754913
206.496	-0.801788
212.926	56.8831
219.352	170.958
225.772	492.646
232.185	684.798
238.595	318.094
244.999	190.812
251.397	171.129
257.791	230.279
264.178	208.008
270.561	153.701
276.939	203.896
283.31	180.095
289.678	114.562
296.039	103.043
302.396	170.128
308.746	373.19
315.093	904.606
321.433	1332.71
327.768	744.009
334.099	363.274
340.423	239.176
346.743	244.256
353.058	306.736
359.367	335.083
365.671	212.866
371.971	92.8056
378.265	33.979
384.553	39.1118
390.837	35.2303
397.116	33.4619
403.389	43.2048
409.657	79.3408
415.92	115.405
422.178	159.967
428.431	255.702
434.678	262.769
440.921	259.388
447.158	345.032
453.391	389.834
459.618	239.67
465.84	125.931
472.057	100.138
478.27	118.39
484.477	129.162
490.679	149.233
496.876	175.844
503.068	241.668
509.255	296.382
515.436	323.257
521.613	332.703
527.785	292.775
533.952	259.507
540.113	211.875
546.27	165.575
552.423	162.206
558.568	119.922
564.711	95.0979
570.848	95.4934
576.979	121.899
583.107	149.095
589.228	167.005
595.345	187.986
601.458	210.349
607.565	262.118
613.667	255.337
619.764	207.553
625.856	153.013
631.944	103.358
638.026	103.096
644.104	115.585
650.177	132.683
656.244	111.911
662.308	68.7204
668.365	43.5034
674.418	14.0268
680.467	5.14406
686.511	-3.65578
692.549	8.20905
698.582	6.06961
704.611	2.91577
710.635	2.44868
716.655	1.67705
722.669	5.59482
728.679	4.67908
734.683	7.43525
740.683	12.9642
746.678	-3.90482
752.669	14.748
758.654	12.9613
764.635	21.6951
770.611	15.5783
776.582	10.3312
782.549	5.86358
788.511	17.2897
794.466	22.0366
800.419	23.8158
806.366	20.7514
812.309	20.4356
818.247	24.7023
824.18	33.5728
830.108	28.3935
836.033	43.1099
841.952	41.2475
847.865	61.8998
853.776	64.8528
859.681	91.4067
865.58	119.05
871.476	147.709
877.366	159.087
883.253	178.85
889.134	174.68
895.012	155.162
900.883	152.409
906.751	157.036
912.614	148.385
918.473	172.804
924.326	198.465
930.174	253.684
936.019	322.563
941.859	444.495
947.693	525.768
953.525	566.728
959.35	514.858
965.171	539.737
970.988	689.98
976.801	907.797
982.608	1050.08
988.411	911.712
994.209	717.155
1000	603.588
1005.79	594.608
1011.58	710.438
1017.36	820.319
1023.13	691.935
1028.9	528.365
1034.67	408.339
1040.43	368.735
1046.19	321.148
1051.94	267.173
1057.69	249.61
1063.44	228.746
1069.17	235.656
1074.91	294.963
1080.64	383.103
1086.37	560.19
1092.09	845.709
1097.8	831.75
1103.52	575.127
1109.22	427.564
1114.93	354.174
1120.63	324.619
1126.32	364.714
1132.01	453.033
1137.7	568.221
1143.38	810.632
1149.06	1043.34
1154.73	665.223
1160.4	351.018
1166.06	232.433
1171.72	175.075
1177.38	145.28
1183.03	106.911
1188.67	103.049
1194.31	80.7928
1199.95	51.8063
1205.58	45.4676
1211.21	39.1534
1216.84	36.8141
1222.46	22.5681
1228.07	30.1685
1233.68	21.7017
1239.29	27.17
1244.89	16.365
1250.49	27.6223
1256.08	16.5713
1261.67	20.5297
1267.26	23.4378
1272.84	18.2311
1278.42	16.0109
1283.99	14.8107
1289.56	18.6715
1295.12	21.597
1300.68	13.5984
1306.23	11.7027
1311.78	7.93591
1317.33	1.20163
1322.87	8.58503
1328.41	14.0354
1333.94	11.3693
1339.47	-1.58092
1345	8.83974
1350.52	3.8771
1356.04	-0.119064
1361.55	11.2273
1367.06	20.4443
1372.56	15.2268
1378.06	19.2525
1383.56	12.9954
1389.05	15.9726
1394.53	3.61998
1400.02	0.619057
1405.5	8.92271
1410.97	1.81709
1416.44	0.91375
1421.91	5.19599
1427.37	8.47881
1432.83	3.45293
1438.28	9.86985
1443.73	6.89577
1449.17	5.96252
1454.62	7.03114
1460.05	10.1287
1465.48	2.67108
1470.91	10.939
1476.34	3.4812
1481.76	-11.289
1487.17	8.62493
1492.59	6.53264
1497.99	1.31846
1503.4	2.45084
1508.8	13.153
1514.19	1.64735
1519.59	11.4119
1524.97	5.22394
1530.36	9.72062
1535.74	16.4246
1541.11	4.7102
1546.48	9.04475
1551.85	8.90246
1557.21	9.70372
1562.57	9.44618
1567.93	4.87118
1573.28	7.83861
1578.62	13.0101
1583.97	1.01392
1589.3	17.04
1594.64	9.4203
1599.97	3.9898
1605.3	10.4853
1610.62	9.49864
1615.94	11.8548
1621.25	16.4531
1626.56	11.2098
1631.87	19.1163
1637.17	13.7404
1642.47	11.4762
1647.76	15.8706
1653.05	11.3679
1658.34	10.1257
1663.62	8.84557
1668.9	21.9569
1674.18	8.44153
1679.45	12.6475
1684.71	16.7879
1689.98	10.9412
1695.23	-1.47533
1700.49	10.6155
1705.74	12.0519
1710.99	-0.291046
1716.23	8.44739
1721.47	14.1204
1726.7	5.10593
1731.94	11.8311
1737.16	10.6919
1742.39	10.6672
1747.61	16.2729
1752.82	13.9214
1758.03	17.173
1763.24	15.8355
1768.44	6.58339
1773.64	0.736465
1778.84	7.40428
1784.03	13.0055
1789.22	6.14816
1794.41	15.2687
1799.59	3.87102
1804.76	6.20409
1809.94	15.4088
1815.11	10.7922
1820.27	14.2429
1825.43	3.82576
1830.59	18.9018
1835.74	7.31106
1840.89	11.9345
1846.04	11.8712
1851.18	10.6213
1856.32	9.32505
1861.45	10.4338
1866.58	10.4006
1871.71	4.44359
1876.83	11.3923
1881.95	8.89413
1887.07	12.273
1892.18	8.47272
1897.29	9.38934
1902.39	10.4125
1907.49	5.61467
1912.59	-2.67361
1917.68	9.31753
1922.77	-0.39241
1927.86	12.6991
1932.94	15.0428
1938.02	6.55331
1943.09	4.0125
1948.16	2.63544
1953.23	2.41113
1958.29	5.77207
1963.35	-4.14465
1968.41	5.18663
1973.46	14.4622
1978.51	9.28147
1983.55	10.1179
1988.59	6.15729
1993.63	7.0232
1998.66	7.91499
2003.69	1.62704
2008.72	12.2192
2013.74	12.0225
2018.76	4.57829
2023.77	14.0201
2028.78	7.85136
2033.79	18.6569
2038.79	6.49332
2043.79	13.7255
2048.79	14.9255
2053.78	7.53842
2058.77	19.7081
2063.76	12.3626
2068.74	11.1194
2073.72	12.3168
2078.69	23.3598
2083.66	15.8952
2088.63	14.5321
2093.59	21.8908
2098.55	33.0756
2103.51	34.3856
2108.46	31.998
2113.41	42.1522
2118.36	27.2897
2123.3	21.1362
2128.24	27.5488
2133.17	30.1607
2138.11	26.4003
2143.03	25.1427
2147.96	23.8331
2152.88	30.1046
2157.79	23.5721
2162.71	16.9767
2167.62	24.3794
2172.52	17.7533
2177.43	23.9394
2182.32	23.6458
2187.22	13.0702
2192.11	29.4513
2197	30.5297
2201.89	18.8677
2206.77	20.083
2211.64	17.4956
2216.52	14.9321
2221.39	14.9776
2226.26	18.9175
2231.12	12.4712
2235.98	16.424
2240.84	15.1632
2245.69	13.9058
2250.54	4.75449
2255.39	27.1595
2260.23	10.0815
2265.07	16.6982
2269.9	-0.593719
2274.74	8.56528
2279.57	9.7258
2284.39	18.7951
2289.21	13.1925
2294.03	7.58167
2298.84	6.00606
2303.66	15.1516
2308.46	1.72127
2313.27	13.72
2318.07	11.0806
2322.87	33.9759
2327.66	17.9329
2332.45	4.53233
2337.24	15.4914
2342.02	2.05463
2346.8	15.8864
2351.58	14.7232
2356.35	18.9816
2361.12	2.48
2365.89	12.1178
2370.65	19.0291
2375.41	6.54216
2380.17	2.30791
2384.92	10.4897
2389.67	7.49857
2394.42	11.3989
2399.16	-1.4572
2403.9	3.76851
2408.64	6.23582
2413.37	10.3465
2418.1	6.53831
2422.83	-3.15251
2427.55	17.8588
2432.27	9.47606
2436.99	6.76753
2441.7	1.20546
2446.41	15.5453
2451.11	11.409
2455.82	12.9586
2460.51	8.7739
2465.21	23.2899
2469.9	-5.48796
2474.59	10.464
2479.28	17.8048
2483.96	16.4124
2488.64	12.0416
2493.32	17.874
2497.99	22.2782
2502.66	9.05424
2507.32	13.3943
2511.99	5.93037
2516.65	17.5789
2521.3	1.26044
2525.96	20.3774
2530.61	23.2606
2535.25	24.718
2539.89	23.2408
2544.53	8.36583
2549.17	12.8615
2553.8	8.39383
2558.43	17.3411
2563.06	12.8595
2567.68	-0.62355
2572.3	22.0847
2576.92	19.1504
2581.53	14.6152
2586.14	14.5089
2590.75	11.2665
2595.35	27.8598
2599.96	11.0444
2604.55	18.5471
2609.15	29.1007
2613.74	10.552
2618.33	36.3727
2622.91	25.4815
2627.49	26.8793
2632.07	25.3408
2636.64	25.465
2641.22	38.0614
2645.78	25.9631
2650.35	30.8567
2654.91	37.2661
2659.47	27.9023
2664.03	27.8338
2668.58	35.5892
2673.13	32.5196
2677.67	29.7346
2682.22	33.5077
2686.76	40.4151
2691.29	29.7393
2695.83	36.3044
2700.36	23.5484
2704.89	31.6248
2709.41	39.6984
2713.93	39.7226
2718.45	39.8324
2722.96	33.3979
2727.47	20.3551
2731.98	39.6792
2736.49	33.0135
2740.99	26.3416
2745.49	18.1151
2749.98	32.7935
2754.47	33.0562
2758.96	29.8276
2763.45	34.723
2767.93	34.8037
2772.41	44.7449
2776.89	20.1595
2781.36	30.357
2785.84	32.3667
2790.3	31.0371
2794.77	24.6391
2799.23	26.5135
2803.69	28.3341
2808.14	21.6744
2812.59	35.2188
2817.04	26.7516
2821.49	25.0524
2825.93	26.7699
2830.37	30.1712
2834.81	19.9385
2839.24	21.6078
2843.67	26.7101
2848.1	30.1817
2852.53	20.0247
2856.95	20.2067
2861.37	18.6826
2865.78	31.0579
2870.19	19.2744
2874.6	23.052
2879.01	12.9353
2883.41	29.0465
2887.81	29.4894
2892.21	43.9886
2896.6	28.559
2901	29.0356
2905.38	22.2785
2909.77	17.23
2914.15	15.6115
2918.53	26.5391
2922.91	14.1885
2927.28	21.671
2931.65	36.4651
2936.02	29.4834
2940.38	29.6248
2944.74	31.565
2949.1	44.355
2953.46	35.303
2957.81	39.0065
2962.16	28.0978
2966.5	42.86
2970.85	32.0013
2975.19	48.7219
2979.52	54.4447
2983.86	36.2506
2988.19	45.8334
2992.52	49.9529
2996.85	48.529
3001.17	41.5581
3005.49	45.845
3009.8	67.0824
3014.12	84.6338
3018.43	68.3344
3022.74	72.8154
3027.04	65.7379
3031.34	89.0999
3035.64	70.3155
3039.94	85.9689
3044.23	78.6164
3048.52	84.6642
3052.81	100.367
3057.09	108.442
3061.38	118.462
3065.65	114.944
3069.93	113.355
3074.2	109.829
3078.47	141.418
3082.74	149.679
3087	136.574
3091.27	162.828
3095.52	187.416
3099.78	170.704
3104.03	191.632
3108.28	173.009
3112.53	216.265
3116.77	187.616
3121.01	209.153
3125.25	212.771
3129.49	240.923
3133.72	247
3137.95	242.813
3142.18	242.554
3146.4	221.437
3150.62	272.731
3154.84	294.895
3159.06	296.224
3163.27	303.873
3167.48	317.732
3171.69	295.858
3175.89	322.267
3180.09	320.951
3184.29	325.826
3188.49	309.319
3192.68	327.005
3196.87	334.354
3201.06	312.503
3205.24	329.249
3209.42	346.344
3213.6	296.665
3217.78	279.206
3221.95	289.762
3226.12	276.353
3230.29	253.995
3234.45	242.41
3238.61	270.5
3242.77	234.597
3246.93	229.685
3251.08	204.248
3255.23	187.32
3259.38	210.851
3263.53	182.883
3267.67	182.529
3271.81	190.897
3275.95	169.062
3280.08	156.093
3284.21	172.883
3288.34	155.25
3292.47	153.625
3296.59	145.034
3300.71	157.316
3304.83	160.354
3308.95	137.879
3313.06	154.765
3317.17	132.172
3321.27	128.238
3325.38	143.117
3329.48	148.763
3333.58	135.905
3337.67	120.592
3341.77	126.202
3345.86	117.44
3349.95	132.306
3354.03	140.094
3358.11	112.282
3362.19	115.454
3366.27	130.576
3370.34	133.764
3374.42	95.9548
3378.48	137.456
3382.55	101.809
3386.61	104.703
3390.68	105.144
3394.73	93.4933
3398.79	125.565
3402.84	109.056
3406.89	114.327
3410.94	104.979
3414.98	115.077
3419.03	100.835
3423.06	101.168
3427.1	116.19
3431.14	102.024
3435.17	87.8956
3439.2	90.9593
3443.22	84.2594
3447.25	114.595
3451.27	98.2219
3455.28	79.3939
3459.3	97.8235
3463.31	106.448
3467.32	92.632
3471.33	68.6293
3475.34	84.5522
3479.34	72.9157
3483.34	86.4907
3487.33	67.1183
3491.33	90.8717
3495.32	86.6235
3499.31	69.4868
3503.3	85.4867
3507.28	60.4123
3511.26	60.7853
3515.24	55.9763
3519.22	46.0061
3523.19	64.3154
3527.16	46.6631
3531.13	67.6071
3535.1	78.5345
3539.06	66.3864
3543.02	59.2862
3546.98	67.6508
3550.93	55.1459
3554.89	58.0135
3558.84	71.4567
3562.78	56.3401
3566.73	64.763
3570.67	83.7991
3574.61	92.4074
3578.55	74.8722
3582.48	88.9688
3586.41	89.9462
3590.35	77.6472
3594.27	62.6062
3598.2	60.8018
3602.12	45.5388
3606.04	35.5299
3609.95	30.7826
3613.87	42.1649
3617.78	37.3642
3621.69	24.3421
3625.6	46.2841
3629.5	38.4765
3633.4	27.899
3637.3	52.5972
3641.2	28.6985
3645.09	29.2668
3648.98	24.293
3652.87	27.3978
3656.76	14.1199
3660.64	22.6355
3664.53	14.7579
3668.4	20.5894
3672.28	20.9419
3676.16	24.1358
3680.03	10.9528
3683.9	17.0613
3687.76	14.9942
3691.63	12.9258
3695.49	5.23102
3699.35	11.4393
3703.2	-1.87167
3707.06	26.7379
3710.91	24.6435
3714.76	28.1255
3718.6	-2.27684
3722.45	12.3417
3726.29	12.8252
3730.13	7.63846
3733.97	28.0192
3737.8	37.088
3741.63	14.8035
3745.46	15.2573
3749.29	15.6705
3753.11	16.0272
3756.93	22.0567
3760.75	10.8625
3764.57	5.37488
3768.39	22.8418
3772.2	31.7803
3776.01	20.6329
3779.81	26.7639
3783.62	21.4639
3787.42	4.62479
3791.22	2.14777
3795.02	-8.95352
3798.81	11.8391
3802.61	15.3087
3806.4	7.18112
3810.18	7.77205
3813.97	5.40443
3817.75	17.6688
3821.53	9.41551
3825.31	15.7907
3829.09	28.0877
3832.86	22.7777
3836.63	17.4276
3840.4	-2.77411
3844.17	18.5436
3847.93	-7.77861
3851.69	25.2616
3855.45	22.6349
3859.21	8.05008
3862.96	11.3552
3866.71	23.8533
3870.46	9.66124
3874.21	16.0289
3877.95	13.4625
3881.69	10.9091
3885.44	5.39832
3889.17	14.8993
3892.91	30.4839
3896.64	-16.8885
3900.37	7.80119
3904.1	11.4592
3907.82	27.2049
3911.55	0.712677
3915.27	34.7547
3918.99	14.37
3922.7	27.4416
3926.42	28.3557
3930.13	20.0829
3933.84	23.9663
3937.54	9.44162
3941.25	31.7962
3944.95	17.3818
3948.65	-0.18692
3952.35	13.0279
3956.04	16.994
3959.73	24.0271
3963.42	24.8665
3967.11	13.2895
3970.8	23.3797
3974.48	27.3234
3978.16	31.2824
3981.84	7.30093
3985.52	11.2621
3989.19	15.256
3992.86	28.6523
3996.53	35.951
3998.37	36.5351