File: Data/3-Raman/processed/bu19w-b-ff1-fi01-s_150 (500nm)_532nm_edge_100%_x100_vis_h50um_15sx2_01.txt
#Acq. time (s)=	15
#Accumulations=	2
#Range (cm-¹)=	100...5000
#Windows=	1
#Auto scanning=	Off
#Autofocus=	Off
#Macrospot=	Off
#AutoExposure=	Off
#Spike filter=	Multiple accum.
#Delay time (s)=	2
#Binning=	1
#Readout mode=	Signal
#DeNoise=	Off
#ICS correction=	On
#Dark correction=	Off
#Inst. Process=	Off
#Detector Gain=	Best Dynamic
#Detector ADC=	50 kHz HS
#Detector temperature (°C)=	-60.09
#Instrument=	LabRAM HR Evol
#Detector=	SIN-EM FIVIS
#Objective=	x100_VIS
#Grating=	150 (500nm)
#ND Filter=	100%
#Laser=	532nm_Edge
#Hole=	49.98
#Temperature=	0
#Range=	Visible
#StageXY=	75x50mm Scan+
#StageZ=	Z motor
#X (µm)=	0
#Y (µm)=	0
#Z (µm)=	-137.6
#Full time(s)=	34
#Project=	21_05_14
#Sample=	BU19w
#Site=
#Title=	BU19w-FF1-FI01-S_150 (500nm)_532nm_Edge_100%_x100_VIS_H50um_15sX2
#Remark=
#Date=	14.05.2021 11:43
#Acquired=	14.05.2021 11:43:53
#Base:Fit=	22.12.2021 12:22:35
#Base:Fit=	22.12.2021 12:23:15
#Base:Edit=	22.12.2021 12:23:19
#Base:Edit=	22.12.2021 12:23:22
#Base:Edit=	22.12.2021 12:23:24
#Base:Edit=	22.12.2021 12:23:25
#Base:Sub=	22.12.2021 12:23:29
#Data Range:Extract=	22.12.2021 12:27:19
102.699	267.04
107.322	100.596
111.942	235.577
116.56	358.117
121.173	309.517
125.787	480.302
130.398	608.232
135.006	694.851
139.613	807.308
144.215	846.528
148.817	553.511
153.417	283.328
158.014	-12.2156
162.607	-152.153
167.2	-43.9912
171.79	527.55
176.379	1846.02
180.963	2088.52
185.547	752.347
190.128	171.46
194.705	500.949
199.282	2959.23
203.857	8665.71
208.43	7624.96
212.998	2190.28
217.566	552.34
222.132	364.881
226.693	541
231.254	901.961
235.813	894.995
240.368	577.968
244.923	314.892
249.475	330.475
254.023	380.008
258.571	723.288
263.117	1424.32
267.658	1396.57
272.199	904.451
276.738	302.786
281.273	78.5259
285.807	599.657
290.34	2544.21
294.868	5736.14
299.396	5733.45
303.919	2763.89
308.443	1413.4
312.964	1741.75
317.481	3625.77
321.998	4548.52
326.51	2931.51
331.023	1658.93
335.533	1314.59
340.039	1742.78
344.544	2378.87
349.046	2734.93
353.547	2230.35
358.045	1552.66
362.542	1358.13
367.036	1221.07
371.527	992.898
376.017	426.837
380.503	194.352
384.99	118.487
389.471	146.752
393.953	94.6111
398.43	452.6
402.908	1063.86
407.381	1748.56
411.854	2076.08
416.323	1773.94
420.791	1326.43
425.256	868.35
429.72	959.262
434.18	1458.14
438.64	1031.9
443.095	452.96
447.551	440.905
452.003	575.63
456.454	620.159
460.901	521.904
465.348	882.725
469.791	2241.38
474.231	2917.71
478.672	1554
483.108	488.4
487.544	259.631
491.976	323.082
496.408	399.951
500.836	489.853
505.261	783.966
509.687	969.806
514.108	1024.13
518.529	1110.89
522.946	1113.93
527.361	1143.67
531.776	1386.26
536.187	1768.32
540.595	1724.29
545.003	1354.09
549.408	1109.85
553.812	891.665
558.212	743.333
562.61	562.676
567.007	461.045
571.401	353.311
575.792	364.851
580.184	509.224
584.571	486.465
588.956	748.021
593.341	1323.83
597.722	2295.8
602.101	3497.99
606.48	4275.47
610.854	3301.57
615.227	2058.19
619.597	1589.56
623.967	1935.5
628.334	2543.3
632.698	2393.09
637.06	1469.24
641.422	934.526
645.779	739.752
650.135	635.422
654.491	763.389
658.842	829.919
663.192	908.847
667.539	862.23
671.884	864.435
676.23	733.576
680.571	794.734
684.91	669.259
689.247	710.446
693.583	761.429
697.916	817.702
702.247	556.326
706.576	448.299
710.902	273.742
715.229	84.4065
719.551	-25.9644
723.872	-73.8191
728.19	-57.6478
732.506	-66.366
736.82	-90.9668
741.134	-126.27
745.444	-93.2343
749.752	-40.3185
754.058	-55.7808
758.362	-32.1777
762.664	-15.3605
766.964	74.0063
771.264	140.088
775.559	276.787
779.853	500.792
784.144	909.961
788.434	1671.83
792.722	2799.49
797.007	3009.84
801.29	2225.8
805.572	1260.58
809.851	732.402
814.13	526.762
818.406	421.922
822.679	397.766
826.95	372.592
831.219	355.048
835.486	305.224
839.752	216.422
844.015	240.679
848.276	210.494
852.535	154.685
856.792	177.036
861.047	164.899
865.3	187.237
869.551	190.339
873.8	204.876
878.047	216.744
882.292	253.991
886.534	205.082
890.775	213.417
895.014	184.165
899.251	219.063
903.486	251.489
907.719	305.061
911.95	378.078
916.179	494.652
920.406	570.94
924.63	625.627
928.853	661.671
933.074	685.995
937.293	769.392
941.51	781.541
945.723	898.816
949.936	1008.88
954.147	1355.2
958.356	1496.7
962.563	1527.66
966.768	1447.24
970.971	1347.48
975.172	1272.34
979.371	1419.27
983.568	1640.29
987.761	1672.08
991.954	1592.59
996.145	1720.92
1000.33	1699.74
1004.52	1787.1
1008.71	1886
1012.89	2245.78
1017.07	2849.29
1021.25	4083.54
1025.43	4858.52
1029.6	4797.86
1033.77	4554.48
1037.95	4928.14
1042.11	5023.45
1046.28	4421.6
1050.45	3638.27
1054.61	3275.65
1058.77	3453.08
1062.93	4360.1
1067.09	5605.63
1071.24	6269.15
1075.4	5142.22
1079.55	3830.03
1083.7	2896.95
1087.85	2443.77
1091.99	2408.14
1096.14	2706.32
1100.28	3558.78
1104.42	4667.1
1108.55	5138.8
1112.69	4658.46
1116.82	4175.24
1120.96	4185.42
1125.09	4392.97
1129.21	4292.64
1133.34	3718.97
1137.46	3259.69
1141.59	3196.68
1145.71	3500.51
1149.83	3538.2
1153.94	3245.87
1158.06	2599.68
1162.17	2198.17
1166.28	2185.1
1170.39	2592.33
1174.5	2971.07
1178.6	2583.97
1182.7	1803.58
1186.8	1390.27
1190.9	1100.54
1195	909.309
1199.1	791.557
1203.19	788.967
1207.28	786.368
1211.37	821.335
1215.46	836.984
1219.54	794.663
1223.63	653.386
1227.71	535.66
1231.79	513.104
1235.87	590.118
1239.95	760.02
1244.02	711.422
1248.09	682.444
1252.16	869.733
1256.23	1141.57
1260.3	1083.17
1264.36	686.813
1268.43	421.468
1272.49	327.103
1276.55	257.555
1280.6	211.869
1284.66	142.433
1288.71	155.394
1292.76	159.902
1296.81	150.229
1300.86	145.281
1304.91	154.131
1308.95	140.878
1312.99	117.95
1317.03	181.075
1321.07	108.024
1325.11	92.465
1329.14	141.569
1333.18	95.5677
1337.21	128.421
1341.24	82.002
1345.26	97.472
1349.29	104.963
1353.31	106.515
1357.33	72.3468
1361.35	89.7523
1365.37	67.0737
1369.39	89.0787
1373.4	63.188
1377.41	84.8149
1381.43	86.3282
1385.43	84.6193
1389.44	95.9053
1393.45	79.4197
1397.45	97.7528
1401.45	85.1885
1405.45	31.4597
1409.45	66.5918
1413.44	10.1398
1417.44	59.2159
1421.43	69.7413
1425.42	8.58984
1429.41	73.2819
1433.39	43.6548
1437.38	26.6016
1441.36	47.1398
1445.34	41.6597
1449.32	31.2119
1453.3	54.934
1457.27	-21.0201
1461.24	47.3857
1465.22	11.0502
1469.19	30.0037
1473.15	25.434
1477.12	28.3549
1481.09	59.5725
1485.05	0.644043
1489.01	12.1801
1492.97	23.8496
1496.93	11.2092
1500.88	36.8555
1504.83	9.39685
1508.79	59.1003
1512.74	56.3351
1516.68	39.2219
1520.63	65.9553
1524.57	74.3701
1528.52	56.8182
1532.46	37.5067
1536.4	92.8478
1540.33	64.9127
1544.27	66.0574
1548.2	31.389
1552.14	53.7887
1556.07	55.5706
1559.99	60.0441
1563.92	68.2201
1567.84	98.4753
1571.77	92.8905
1575.69	87.2969
1579.61	92.2598
1583.52	74.0199
1587.44	77.8573
1591.35	40.3241
1595.27	42.2596
1599.18	77.9077
1603.09	66.7313
1606.99	74.9495
1610.9	115.806
1614.8	110.882
1618.7	81.1605
1622.6	80.223
1626.5	48.0803
1630.39	48.8773
1634.29	56.7057
1638.18	79.933
1642.07	81.7429
1645.96	77.0776
1649.85	78.3043
1653.73	59.3428
1657.62	38.3035
1661.5	64.153
1665.38	49.3397
1669.26	76.4841
1673.13	80.1699
1677.01	55.5181
1680.88	89.5684
1684.75	82.1417
1688.62	73.5122
1692.49	68.3885
1696.35	60.1617
1700.22	4.85352
1704.08	66.4982
1707.94	41.04
1711.8	54.4119
1715.66	65.0002
1719.51	58.6082
1723.37	103.082
1727.22	82.2145
1731.07	56.6881
1734.92	77.173
1738.76	81.4071
1742.61	80.0042
1746.45	81.1808
1750.29	66.645
1754.13	53.8855
1757.97	37.7937
1761.81	64.3302
1765.64	66.9314
1769.47	50.2734
1773.31	59.0817
1777.14	69.1511
1780.96	76.9911
1784.79	74.7864
1788.61	39.9639
1792.43	74.4746
1796.25	85.5989
1800.07	95.097
1803.89	108.606
1807.71	109.83
1811.52	67.3578
1815.33	108.203
1819.14	71.9581
1822.95	85.3549
1826.76	91.7074
1830.56	97.5396
1834.37	91.6793
1838.17	81.7817
1841.97	125.083
1845.77	88.4507
1849.56	93.7368
1853.36	76.7383
1857.15	99.4436
1860.94	115.137
1864.73	126.165
1868.52	103.069
1872.31	39.6656
1876.09	89.4408
1879.87	83.2969
1883.66	86.8124
1887.43	95.244
1891.21	108.442
1894.99	137.142
1898.76	106.547
1902.53	76.5526
1906.31	123.207
1910.08	122.486
1913.84	121.246
1917.61	76.4006
1921.37	91.3286
1925.14	83.3307
1928.9	123.879
1932.66	91.9954
1936.41	93.4967
1940.17	147.296
1943.92	79.9235
1947.68	113.847
1951.43	127.393
1955.18	156.023
1958.92	115.088
1962.67	117.189
1966.41	146.295
1970.16	165.919
1973.9	135.454
1977.64	114.949
1981.37	123.19
1985.11	128.252
1988.84	131.28
1992.57	131.948
1996.31	145.295
2000.03	132.374
2003.76	138.272
2007.49	111.131
2011.21	89.5453
2014.93	146.6
2018.65	118.586
2022.37	97.9003
2026.09	72.7841
2029.81	129.692
2033.52	133.521
2037.23	118.484
2040.94	134.685
2044.65	157.914
2048.36	153.183
2052.07	101.073
2055.77	109.738
2059.47	103.47
2063.17	116.216
2066.87	122.776
2070.57	123.881
2074.27	133.345
2077.96	141.205
2081.65	130.469
2085.34	118.503
2089.03	140.174
2092.72	150.778
2096.41	125.518
2100.09	100.167
2103.77	134.019
2107.46	121.938
2111.14	139.431
2114.81	102.007
2118.49	153.195
2122.16	137.632
2125.84	116.376
2129.51	106.833
2133.18	150.889
2136.85	147.451
2140.51	174.064
2144.18	104.661
2147.84	123.635
2151.5	132.465
2155.16	180.742
2158.82	143.035
2162.48	135.908
2166.13	161.924
2169.79	130.151
2173.44	139.289
2177.09	130.353
2180.74	138.887
2184.38	149.241
2188.03	123.236
2191.67	168.88
2195.32	190.727
2198.96	179.973
2202.6	185.916
2206.23	154.747
2209.87	193.349
2213.5	170.845
2217.14	220.811
2220.77	203.902
2224.4	187.868
2228.03	145.816
2231.65	144.472
2235.28	212.55
2238.9	152.853
2242.52	157.897
2246.14	214.04
2249.76	166.309
2253.38	141.93
2256.99	151.16
2260.6	156.478
2264.21	145.806
2267.82	139.311
2271.44	175.122
2275.04	149.889
2278.65	156.813
2282.25	153.296
2285.85	141.695
2289.45	119.304
2293.05	127.08
2296.65	166.235
2300.25	149.386
2303.84	160.466
2307.43	183.525
2311.02	154.167
2314.62	138.676
2318.2	170.156
2321.79	112.673
2325.38	132.888
2328.96	143.681
2332.54	154.968
2336.12	117.023
2339.7	106.185
2343.28	125.208
2346.85	121.434
2350.43	111.958
2354	144.404
2357.57	118.806
2361.14	109.02
2364.71	88.1937
2368.27	149.298
2371.84	116.073
2375.4	92.8984
2378.96	136.413
2382.52	129.389
2386.08	138.262
2389.64	109.877
2393.19	144.415
2396.75	102.595
2400.3	140.506
2403.85	144.349
2407.4	114.643
2410.95	120.617
2414.49	73.678
2418.04	120.886
2421.58	70.0226
2425.12	115.481
2428.66	129.195
2432.2	128.559
2435.74	107.834
2439.27	132.744
2442.81	44.089
2446.34	135.683
2449.87	134.451
2453.4	97.8632
2456.93	84.7422
2460.45	91.4005
2463.98	68.0776
2467.5	71.8539
2471.02	108.266
2474.54	99.5342
2478.06	27.4563
2481.58	18.2196
2485.09	101.043
2488.61	68.0454
2492.12	29.7289
2495.63	74.3859
2499.14	49.0483
2502.65	37.962
2506.15	70.4783
2509.66	48.7012
2513.16	94.3226
2516.66	59.4979
2520.16	104.415
2523.66	57.7852
2527.16	31.6479
2530.66	45.5166
2534.15	32.2645
2537.64	58.1643
2541.13	-1.82935
2544.62	42.583
2548.11	24.4144
2551.6	25.0107
2555.08	28.6141
2558.57	47.0786
2562.05	14.3486
2565.53	65.0691
2569.01	83.9358
2572.49	52.7523
2575.96	-4.46387
2579.44	61.5687
2582.91	62.8962
2586.38	58.278
2589.85	12.6753
2593.32	61.3574
2596.79	21.1294
2600.25	15.3156
2603.72	28.712
2607.18	23.4103
2610.64	39.0237
2614.1	23.8284
2617.56	47.2969
2621.02	9.82666
2624.47	-0.352295
2627.92	57.3342
2631.38	55.9946
2634.83	21.3896
2638.28	25.7708
2641.72	25.821
2645.17	39.1627
2648.61	37.755
2652.06	36.7798
2655.5	40.0571
2658.94	17.4973
2662.38	50.5623
2665.82	8.95105
2669.25	44.4623
2672.69	25.6501
2676.12	32.4865
2679.55	21.9469
2682.98	50.213
2686.41	31.1849
2689.84	17.1992
2693.26	47.353
2696.69	8.07788
2700.11	36.1661
2703.53	31.1903
2706.95	41.787
2710.37	18.5309
2713.79	0.316772
2717.2	39.3403
2720.62	-4.22998
2724.03	23.2285
2727.44	17.334
2730.85	53.4191
2734.26	53.0426
2737.66	5.80737
2741.07	3.1864
2744.47	61.2113
2747.87	5.60754
2751.28	75.9532
2754.67	-0.888794
2758.07	27.9637
2761.47	27.9878
2764.86	82.3962
2768.26	30.835
2771.65	55.4995
2775.04	14.8134
2778.43	17.1533
2781.82	8.01892
2785.2	30.7946
2788.59	48.8317
2791.97	32.8447
2795.35	15.2219
2798.73	34.7002
2802.11	71.9899
2805.49	2.42627
2808.87	55.4891
2812.24	28.892
2815.62	26.4535
2818.99	30.853
2822.36	5.76233
2825.73	32.132
2829.1	50.3164
2832.46	27.9148
2835.83	16.1211
2839.19	55.0387
2842.55	38.5082
2845.91	28.2001
2849.27	9.52722
2852.63	86.5796
2855.99	53.7046
2859.34	2.40771
2862.69	56.0283
2866.05	70.5024
2869.4	15.3618
2872.75	17.3961
2876.09	63.6112
2879.44	56.2216
2882.78	21.317
2886.13	39.0562
2889.47	49.4418
2892.81	71.5244
2896.15	71.6133
2899.49	87.4679
2902.82	58.5547
2906.16	45.5875
2909.49	58.8969
2912.82	65.5947
2916.16	85.1566
2919.49	52.5487
2922.81	45.4523
2926.14	106.01
2929.46	78.5747
2932.79	73.3527
2936.11	104.937
2939.43	79.0068
2942.75	84.2323
2946.07	71.7349
2949.39	69.5497
2952.7	41.9344
2956.02	83.2571
2959.33	103.313
2962.64	31.3746
2965.95	69.7063
2969.26	141.731
2972.57	92.3962
2975.87	108.642
2979.17	146.036
2982.48	113.182
2985.78	97.3975
2989.08	164.33
2992.38	129.958
2995.68	161.525
2998.97	119.834
3002.27	68.6062
3005.56	108.843
3008.85	135.126
3012.14	116.347
3015.43	127.669
3018.72	142.751
3022	146.529
3025.29	191.927
3028.57	141.026
3031.85	184.51
3035.14	149.456
3038.41	167.389
3041.69	156.976
3044.97	188.327
3048.24	163.745
3051.52	207.528
3054.79	216.234
3058.06	170.623
3061.33	186.146
3064.6	166.784
3067.87	169.911
3071.13	195.058
3074.4	240.331
3077.66	201.241
3080.92	168.132
3084.18	222.75
3087.44	263.62
3090.7	233.789
3093.95	230.221
3097.21	223.162
3100.46	257.025
3103.71	291.631
3106.96	279.773
3110.21	324.366
3113.46	303.239
3116.71	353.651
3119.95	270.781
3123.2	306
3126.44	358.332
3129.68	412.622
3132.92	372.555
3136.16	369.556
3139.4	421.809
3142.63	419.735
3145.87	447.363
3149.1	473.206
3152.33	494.229
3155.56	494.325
3158.79	540.186
3162.02	584.173
3165.25	592.707
3168.47	611.55
3171.69	618.844
3174.92	728.044
3178.14	709.3
3181.36	707.819
3184.58	793.857
3187.79	804.41
3191.01	830.204
3194.22	856.925
3197.43	890.242
3200.65	917.921
3203.86	969.502
3207.07	1029.76
3210.27	1073.08
3213.48	1160.39
3216.69	1195.44
3219.89	1253.39
3223.09	1331.63
3226.29	1431.88
3229.49	1386.88
3232.69	1539.59
3235.89	1553.03
3239.08	1602.07
3242.28	1616.12
3245.47	1602.58
3248.66	1573.12
3251.85	1712.66
3255.04	1656.74
3258.23	1704.45
3261.42	1753.6
3264.6	1828.05
3267.79	1745.44
3270.97	1703.63
3274.15	1724.89
3277.33	1735.07
3280.51	1710.11
3283.68	1691.84
3286.86	1645.63
3290.04	1614.01
3293.21	1569.05
3296.38	1565.91
3299.55	1561.78
3302.72	1503.78
3305.89	1532.94
3309.06	1552.05
3312.22	1506.27
3315.39	1459.54
3318.55	1463.97
3321.71	1478.82
3324.87	1382.01
3328.03	1379.99
3331.19	1447.16
3334.34	1329.44
3337.5	1295.22
3340.65	1153.55
3343.81	1172.88
3346.96	1102.61
3350.11	1045.61
3353.25	1023.8
3356.4	940.872
3359.55	908.253
3362.69	871.02
3365.84	782.991
3368.98	793.12
3372.12	789.415
3375.26	740.528
3378.4	700.29
3381.53	685.4
3384.67	641.371
3387.8	637.091
3390.94	649.986
3394.07	627.824
3397.2	660.874
3400.33	749.435
3403.46	734.919
3406.58	763.327
3409.71	789.043
3412.83	882.786
3415.96	969.75
3419.08	1169.23
3422.2	1551.64
3425.32	2617.29
3428.44	5362.45
3431.55	11772.7
3434.67	16286
3437.78	11049.4
3440.89	4851.69
3444	2342.57
3447.12	1540.18
3450.22	1131.6
3453.33	957.764
3456.44	830.389
3459.54	838.164
3462.65	811.631
3465.75	804.877
3468.85	888.389
3471.95	809.557
3475.05	874.994
3478.15	881.836
3481.24	896.292
3484.34	1027.07
3487.43	1072.03
3490.53	1149.95
3493.62	1309.09
3496.71	1331.99
3499.79	1610.69
3502.88	1677.37
3505.97	1843.19
3509.05	2052.85
3512.14	2260.84
3515.22	2390.33
3518.3	2319.73
3521.38	1956.24
3524.46	1649.18
3527.54	1342.54
3530.61	1097.54
3533.69	970.906
3536.76	854.227
3539.83	744.034
3542.9	680.847
3545.97	627.28
3549.04	570.469
3552.11	530.181
3555.18	482.626
3558.24	452.289
3561.3	419.541
3564.37	461.457
3567.43	468.432
3570.49	429.537
3573.55	435.912
3576.61	464.969
3579.66	479.632
3582.72	445.731
3585.77	409.883
3588.82	380.493
3591.87	408.835
3594.92	383.945
3597.97	352.4
3601.02	307.479
3604.07	316.373
3607.11	339.397
3610.16	346.25
3613.2	362.451
3616.24	408.882
3619.28	509.131
3622.32	701.757
3625.36	932.968
3628.39	1408.85
3631.43	2333.13
3634.46	2630.33
3637.5	2173.42
3640.53	1828.09
3643.56	1700.03
3646.59	1391.73
3649.62	1429.14
3652.64	1623.09
3655.67	1767.51
3658.69	1853.81
3661.72	1647.75
3664.74	1087.63
3667.76	698.767
3670.78	401.266
3673.79	215.852
3676.81	179.532
3679.83	155.393
3682.84	116.078
3685.86	70.125
3688.87	62.0198
3691.88	57.7349
3694.89	65.4922
3697.9	16.5271
3700.91	50.1461
3703.91	55.3103
3706.92	46.0769
3709.92	48.1057
3712.92	56.5903
3715.92	46.0912
3718.92	53.5479
3721.92	12.3019
3724.92	23.2689
3727.92	52.2167
3730.91	28.6475
3733.91	64.8995
3736.9	9.60425
3739.89	34.1053
3742.88	73.6688
3745.87	53.1445
3748.86	0.202515
3751.85	34.6342
3754.83	47.2225
3757.82	72.1064
3760.8	27.6508
3763.78	46.6943
3766.76	7.11975
3769.74	39.6046
3772.72	54.2048
3775.7	11.228
3778.67	-6.11572
3781.65	66.2953
3784.62	32.0365
3787.6	38.4493
3790.57	45.9982
3793.54	37.6428
3796.51	0.0987549
3799.47	31.6255
3802.44	46.2637
3805.41	37.3275
3808.37	45.4667
3811.33	14.8879
3814.3	16.4609
3817.26	20.9192
3820.22	31.0803
3823.18	10.0741
3826.13	31.7216
3829.09	61.8953
3832.04	21.0278
3835	-8.4198
3837.95	55.2274
3840.9	6.71912
3843.85	34.28
3846.8	14.2927
3849.75	51.5325
3852.69	53.5613
3855.64	46.046
3858.58	47.1326
3861.53	29.001
3864.47	36.6682
3867.41	23.1571
3870.35	69.0028
3873.29	-6.04272
3876.22	43.4814
3879.16	52.5602
3882.1	0.92749
3885.03	83.6981
3887.96	9.71667
3890.89	38.5358
3893.82	46.0475
3896.75	1.43799
3899.68	51.9869
3902.61	40.7865
3905.53	77.7717
3908.46	88.7181
3911.38	63.014
3914.3	38.1115
3917.23	90.2791
3920.15	70.2358
3923.06	38.5037
3925.98	52.6976
3928.9	70.5609
3931.81	14.8854
3934.73	16.9604
3937.64	51.8848
3940.55	41.7133
3943.46	38.2533
3946.37	40.6471
3949.28	57.5043
3952.19	50.4613
3955.09	8.07495
3958	22.2546
3960.9	20.1926
3963.8	103.524
3966.71	59.3993
3969.61	61.3412
3972.51	64.2211
3975.4	38.202
3978.3	54.3319
3981.2	57.9364
3984.09	46.0763
3986.99	65.9325
3989.88	63.4373
3992.77	71.7281
3995.66	54.9976
3998.55	77.7728
4001.43	45.6727