File: Data/3-Raman/processed/bu19w-e-ff11b-fi01-l_150 (500nm)_532nm_edge_100%_x100_vis_h50um_30sx2_01_0.txt
#Acq. time (s)=	30
#Accumulations=	2
#Range (cm-¹)=	100...5000
#Windows=	1
#Auto scanning=	Off
#Autofocus=	Off
#Macrospot=	Off
#AutoExposure=	Off
#Spike filter=	Multiple accum.
#Delay time (s)=	2
#Binning=	1
#Readout mode=	Signal
#DeNoise=	Off
#ICS correction=	On
#Dark correction=	Off
#Inst. Process=	Off
#Detector Gain=	Best Dynamic
#Detector ADC=	50 kHz HS
#Detector temperature (°C)=	-60.09
#Instrument=	LabRAM HR Evol
#Detector=	SIN-EM FIVIS
#Objective=	x100_VIS
#Grating=	150 (500nm)
#ND Filter=	100%
#Laser=	532nm_Edge
#Hole=	49.98
#Temperature=	0
#Range=	Visible
#StageXY=	75x50mm Scan+
#StageZ=	Z motor
#X (µm)=	0
#Y (µm)=	0
#Z (µm)=	-244.6
#Full time(mm:ss)=	1:04
#Project=	21_11_04
#Sample=	BU19w
#Site=
#Title=	BU19w-E-FF11b-FI01-L_150 (500nm)_532nm_Edge_100%_x100_VIS_H50um_30sX2
#Remark=
#Date=	04.11.2021 18:37
#Acquired=	04.11.2021 18:37:01
#Base:Fit=	16.12.2021 17:39:50
#Base:Edit=	16.12.2021 17:46:09
#Base:Sub=	16.12.2021 17:46:11
101.869	8452.25
106.493	9171.68
111.113	12863
115.732	17562.6
120.349	14930.1
124.964	9617.68
129.577	7624.56
134.185	6982.16
138.793	6577.63
143.399	6102.83
148.003	5818.41
152.602	5762.09
157.201	5841.07
161.798	6106.18
166.392	6490.55
170.982	7326.97
175.572	8924.01
180.16	11440.5
184.745	14887.2
189.326	18505.5
193.907	20121.9
198.486	18386.7
203.06	14797.7
207.634	11059.7
212.206	8103.8
216.776	6142.52
221.341	4763.39
225.906	3794.62
230.469	3189.19
235.028	2715.45
239.586	2483.33
244.142	2502.97
248.694	3617.91
253.246	4024.79
257.795	2638.22
262.341	1364.45
266.886	884.563
271.428	583.478
275.967	487.5
280.505	375.834
285.041	286.458
289.573	206.288
294.105	161.737
298.632	96.082
303.159	65.1227
307.685	68.3313
312.205	0.0241699
316.726	-7.70459
321.242	-22.2947
325.758	-35.9781
330.272	6.26514
334.782	378.972
339.292	1659.87
343.797	2127.39
348.302	1126.41
352.803	339.639
357.304	142.265
361.802	81.334
366.297	49.7435
370.791	59.6201
375.281	192.272
379.77	575.422
384.256	874.524
388.741	1059.1
393.223	932.028
397.704	413.002
402.18	255.614
406.657	297.131
411.13	309.594
415.602	429.628
420.07	608.343
424.538	859.573
429.002	1427.63
433.465	2635.45
437.925	5305.4
442.384	11475.5
446.839	28772.3
451.294	36603
455.745	36640.8
460.196	27442.2
464.642	12573.6
469.089	6788.79
473.531	4469.03
477.971	3095.9
482.411	2313.94
486.846	1816.88
491.282	1594.06
495.713	1439.72
500.144	1258.9
504.572	1034.98
508.997	931.026
513.421	770.527
517.842	677.332
522.263	591.811
526.679	511.637
531.093	453.813
535.507	390.663
539.917	239.551
544.327	229.641
548.733	198.958
553.137	160.02
557.54	147.005
561.94	170.269
566.337	146.726
570.734	173.638
575.127	115.15
579.518	162.007
583.909	152.79
588.295	126.602
592.68	90.7173
597.064	56.7449
601.445	49.9094
605.823	70.0693
610.201	33.2809
614.575	44.7152
618.947	41.0618
623.317	22.8224
627.686	54.8656
632.052	42.3356
636.415	18.7792
640.777	19.7771
645.138	25.054
649.495	1.26904
653.85	4.36743
658.205	0.609009
662.556	-0.180542
666.905	20.2076
671.252	61.8124
675.597	151.277
679.941	291.901
684.282	494.118
688.62	483.778
692.957	259.293
697.293	113.29
701.625	62.7059
705.955	20.3536
710.283	40.348
714.609	-28.5702
718.933	27.302
723.257	30.6453
727.577	14.8817
731.894	8.39081
736.21	10.8815
740.524	44.3434
744.835	26.4335
749.147	41.7102
753.454	54.6817
757.759	65.9933
762.063	72.9025
766.364	119.14
770.663	195.004
774.96	277.497
779.257	513.661
783.55	859.719
787.841	1141.81
792.13	1431.7
796.417	1657.42
800.702	1103.49
804.985	550.907
809.266	327.906
813.545	201.786
817.821	187.944
822.096	169.58
826.371	189.938
830.641	192.709
834.91	171.18
839.176	154.989
843.441	182.741
847.703	163.786
851.964	161.832
856.222	233.673
860.479	389.091
864.733	500.032
868.986	381.54
873.236	264.134
877.485	208.164
881.731	149.951
885.975	136.362
890.218	136.517
894.458	124.247
898.696	94.7896
902.933	107.327
907.167	118.807
911.399	117.199
915.63	104.174
919.858	111.466
924.084	55.9667
928.308	82.9088
932.531	45.1103
936.749	41.6179
940.967	57.1662
945.184	50.0752
949.398	27.9619
953.61	36.9476
957.821	31.0147
962.029	30.4342
966.236	31.9857
970.44	29.2971
974.642	30.9194
978.843	7.11078
983.041	22.5653
987.236	5.11859
991.43	25.7321
995.623	24.4395
999.813	0.123779
1004	22.4692
1008.19	57.6157
1012.37	21.5398
1016.55	12.8319
1020.73	47.7422
1024.91	49.4629
1029.09	61.5711
1033.27	64.9401
1037.44	83.6989
1041.61	107.302
1045.78	161.645
1049.94	290.972
1054.11	518.186
1058.27	573.76
1062.43	607.614
1066.59	856.533
1070.75	1047.14
1074.9	713.666
1079.05	377.058
1083.2	206.435
1087.35	138.423
1091.5	143.15
1095.65	102.742
1099.79	106.841
1103.93	85.3445
1108.07	86.5432
1112.21	74.721
1116.34	73.1146
1120.48	90.4691
1124.61	104.25
1128.74	123.287
1132.86	147.635
1136.99	224.164
1141.11	354.207
1145.23	650.453
1149.35	906.113
1153.47	848.025
1157.59	486.913
1161.7	252.266
1165.82	170.061
1169.92	121.762
1174.03	112.473
1178.14	96.8817
1182.24	109.044
1186.35	119.993
1190.45	120.319
1194.55	105.106
1198.64	113.271
1202.74	140.583
1206.83	155.48
1210.92	187.497
1215.01	211.259
1219.1	241.962
1223.18	266.54
1227.27	211.866
1231.35	200.637
1235.43	189.779
1239.5	163.29
1243.58	195.588
1247.65	214.018
1251.72	235.717
1255.8	290.487
1259.86	339.385
1263.93	342.404
1267.99	294.461
1272.06	244.484
1276.12	174.294
1280.18	188.273
1284.23	162.96
1288.29	152.568
1292.34	151.143
1296.39	138.527
1300.44	126.839
1304.49	140.231
1308.53	142.469
1312.58	134.562
1316.62	113.375
1320.66	132.363
1324.7	130.03
1328.73	138.638
1332.77	138.15
1336.8	133.48
1340.83	137.731
1344.86	167.866
1348.88	187.886
1352.91	223.748
1356.93	275.378
1360.95	416.009
1364.97	690.847
1368.99	1030.21
1373.01	1008.57
1377.02	654.922
1381.03	391.775
1385.04	281.898
1389.05	178.135
1393.06	158.161
1397.06	142.291
1401.06	121.457
1405.06	103.517
1409.06	106.29
1413.06	105.141
1417.05	93.1305
1421.05	92.9318
1425.04	85.7605
1429.03	97.1615
1433.01	104.596
1437	88.3347
1440.99	90.8121
1444.97	88.2979
1448.95	94.6205
1452.93	89.0363
1456.9	74.5275
1460.88	76.7182
1464.85	90.5933
1468.82	74.9013
1472.79	79.9042
1476.76	82.8896
1480.73	88.7457
1484.69	72.0463
1488.65	76.8573
1492.61	86.5482
1496.57	92.3205
1500.53	83.4998
1504.48	90.3157
1508.43	95.2662
1512.39	78.871
1516.33	103.276
1520.28	85.967
1524.23	98.7599
1528.17	100.899
1532.11	97.2603
1536.05	112.047
1539.99	116.173
1543.93	134.831
1547.86	130.227
1551.8	157.589
1555.73	166.487
1559.66	174.341
1563.58	181.165
1567.51	201.471
1571.44	205.282
1575.36	238.046
1579.28	238.895
1583.2	247.439
1587.11	271.347
1591.03	283.642
1594.94	284.362
1598.85	326.398
1602.76	352.084
1606.67	364.389
1610.58	372.868
1614.48	374.666
1618.38	387.086
1622.29	430.111
1626.18	403.311
1630.08	413.947
1633.98	421.913
1637.87	412.646
1641.76	417.884
1645.65	405.079
1649.54	405.75
1653.43	358.483
1657.31	344.708
1661.2	320.318
1665.08	305.412
1668.96	281.772
1672.83	235.857
1676.71	237.963
1680.58	217.732
1684.46	189.706
1688.33	167.447
1692.2	148.984
1696.06	144.854
1699.93	121.567
1703.79	118.3
1707.66	106.4
1711.52	76.4256
1715.37	78.8006
1719.23	66.0495
1723.08	64.6887
1726.94	58.6014
1730.79	44.9737
1734.64	32.3643
1738.49	43.1789
1742.33	12.8369
1746.18	25.4882
1750.02	28.0236
1753.86	21.3848
1757.7	30.681
1761.54	22.7923
1765.37	17.5517
1769.21	22.5852
1773.04	19.404
1776.87	6.92932
1780.7	5.68858
1784.53	-8.57234
1788.35	1.45844
1792.17	9.66476
1796	9.46346
1799.82	0.793671
1803.64	2.30057
1807.45	2.83348
1811.27	15.5979
1815.08	0.037735
1818.89	-3.37402
1822.7	4.46811
1826.51	8.48944
1830.32	-0.759781
1834.12	-1.58104
1837.92	12.6211
1841.72	1.36612
1845.52	3.23169
1849.32	-12.7051
1853.12	-3.40259
1856.91	5.80035
1860.7	4.63042
1864.5	8.08882
1868.28	7.84335
1872.07	2.99744
1875.86	-4.5506
1879.64	10.1098
1883.42	-2.82912
1887.21	13.7503
1890.98	12.17
1894.76	0.507401
1898.54	-1.95222
1902.31	6.73083
1906.08	14.5568
1909.85	13.2073
1913.62	6.41425
1917.39	16.2478
1921.16	-4.24632
1924.92	22.4589
1928.68	17.7572
1932.44	21.4317
1936.2	19.5266
1939.96	17.6042
1943.71	18.4735
1947.47	14.67
1951.22	44.4273
1954.97	42.2025
1958.72	32.3179
1962.46	30.7851
1966.21	31.1151
1969.95	44.5136
1973.7	45.5915
1977.43	46.612
1981.17	45.7099
1984.91	45.6988
1988.65	51.2515
1992.38	66.9933
1996.11	64.9529
1999.84	59.1556
2003.57	65.4249
2007.3	68.8806
2011.02	63.9449
2014.75	68.2372
2018.47	70.8096
2022.19	74.4639
2025.91	71.8762
2029.62	77.5776
2033.34	68.7364
2037.05	69.194
2040.76	97.0787
2044.47	82.8337
2048.18	96.0517
2051.89	75.4543
2055.59	94.2601
2059.3	85.7265
2063	88.3995
2066.7	95.761
2070.4	90.2779
2074.1	83.8553
2077.79	94.9954
2081.49	96.0107
2085.18	83.0702
2088.87	95.7715
2092.56	98.0598
2096.25	107.013
2099.93	92.6928
2103.61	90.3342
2107.3	101.871
2110.98	97.5436
2114.66	106.219
2118.33	105.559
2122.01	106.632
2125.68	99.2699
2129.36	104.851
2133.03	109.456
2136.7	89.9968
2140.36	97.3064
2144.03	87.9546
2147.7	82.2902
2151.36	83.9857
2155.02	80.1841
2158.68	75.4916
2162.34	73.5878
2165.99	87.252
2169.65	72.6727
2173.3	80.0959
2176.95	59.3625
2180.6	72.3528
2184.25	63.4938
2187.9	73.7977
2191.54	68.7526
2195.18	62.9043
2198.83	62.5813
2202.47	65.0206
2206.11	51.0724
2209.74	53.5864
2213.38	49.7341
2217.01	70.6376
2220.64	46.6134
2224.27	68.5085
2227.9	63.7407
2231.53	49.7304
2235.16	50.4802
2238.78	51.2227
2242.4	36.1965
2246.02	39.6789
2249.64	46.8964
2253.26	52.2986
2256.88	43.7424
2260.49	51.9748
2264.11	48.0277
2267.72	46.8963
2271.33	42.0545
2274.93	38.0766
2278.54	39.6636
2282.15	38.2683
2285.75	42.5043
2289.35	39.1895
2292.95	32.9929
2296.55	33.4127
2300.15	37.6271
2303.74	27.5936
2307.34	38.3475
2310.93	32.9519
2314.52	32.2556
2318.11	52.3653
2321.7	59.1399
2325.28	51.5536
2328.87	35.4268
2332.45	24.9776
2336.03	28.6627
2339.61	47.3681
2343.19	40.6036
2346.77	43.2117
2350.34	23.3062
2353.92	33.3773
2357.49	36.8601
2361.06	18.8895
2364.63	23.2886
2368.2	17.4756
2371.76	34.8822
2375.33	26.3308
2378.89	36.2619
2382.45	30.5224
2386.01	35.8598
2389.57	21.0038
2393.13	23.6611
2396.68	21.7894
2400.23	30.0718
2403.79	15.5555
2407.34	42.3184
2410.88	21.4949
2414.43	28.2366
2417.98	27.6868
2421.52	19.8085
2425.06	23.9316
2428.61	14.2741
2432.14	18.4916
2435.68	22.7681
2439.22	20.5804
2442.75	23.0495
2446.29	19.9313
2449.82	16.8328
2453.35	26.8883
2456.88	19.9302
2460.4	14.6338
2463.93	21.5393
2467.45	16.0251
2470.98	18.1835
2474.5	13.4376
2478.02	30.2998
2481.54	5.70819
2485.05	22.516
2488.57	9.99315
2492.08	6.04086
2495.59	2.94577
2499.1	14.8885
2502.61	15.5188
2506.12	11.4271
2509.63	9.16652
2513.13	19.9432
2516.63	10.2919
2520.13	9.97896
2523.63	12.294
2527.13	5.55876
2530.63	13.6681
2534.12	8.86284
2537.62	6.88971
2541.11	12.3372
2544.6	9.5744
2548.09	13.3664
2551.58	22.7127
2555.06	-0.259689
2558.55	4.61169
2562.03	3.9192
2565.51	7.96091
2568.99	5.55559
2572.47	-1.48474
2575.95	-11.3413
2579.43	11.6766
2582.9	18.8145
2586.37	0.457977
2589.84	0.911392
2593.31	13.6131
2596.78	12.9822
2600.25	-0.00326538
2603.71	-0.621292
2607.18	-9.0309
2610.64	2.53407
2614.1	8.18138
2617.56	8.15991
2621.02	-5.41214
2624.47	-0.770355
2627.93	7.65141
2631.38	-3.17569
2634.83	14.7444
2638.28	3.80406
2641.73	12.9534
2645.18	1.94868
2648.62	1.46159
2652.07	4.73701
2655.51	-2.52417
2658.95	2.53661
2662.39	1.86406
2665.83	7.78194
2669.27	-6.13408
2672.7	9.1497
2676.14	0.933792
2679.57	5.88617
2683	8.05569
2686.43	2.81653
2689.86	3.31387
2693.29	3.89479
2696.71	7.21066
2700.13	4.9841
2703.56	10.2111
2706.98	-6.89597
2710.4	-0.602539
2713.82	-2.63936
2717.23	9.32536
2720.65	8.30067
2724.06	11.0318
2727.47	12.8485
2730.88	10.0069
2734.29	3.39784
2737.7	15.5128
2741.11	8.88165
2744.51	4.06944
2747.91	-3.60638
2751.32	5.63203
2754.72	31.8014
2758.11	28.7808
2761.51	16.3469
2764.91	21.7378
2768.3	28.0354
2771.7	22.037
2775.09	14.1333
2778.48	1.48042
2781.87	25.5225
2785.25	19.4053
2788.64	13.2823
2792.03	34.4155
2795.41	25.4473
2798.79	25.8808
2802.17	19.6998
2805.55	30.4007
2808.93	37.3299
2812.3	24.5772
2815.68	22.115
2819.05	46.7334
2822.42	43.3459
2825.79	49.3253
2829.16	35.7373
2832.53	55.738
2835.89	46.8944
2839.26	48.3431
2842.62	51.705
2845.98	63.5165
2849.34	66.1117
2852.7	51.0546
2856.06	67.6943
2859.41	57.2807
2862.77	67.4771
2866.12	70.2083
2869.47	90.7783
2872.82	78.493
2876.17	98.1428
2879.52	95.2313
2882.87	90.4185
2886.21	96.8872
2889.55	109.019
2892.89	96.5961
2896.23	112.432
2899.57	113.103
2902.91	111.828
2906.25	133.216
2909.58	123.349
2912.91	138.056
2916.25	151.792
2919.58	156.949
2922.91	159.242
2926.23	170.956
2929.56	177.871
2932.88	171.513
2936.21	202.839
2939.53	202.056
2942.85	194.679
2946.17	219.332
2949.49	227.031
2952.8	233.76
2956.12	228.275
2959.43	212.544
2962.74	241.918
2966.06	249.711
2969.37	291.401
2972.67	294.752
2975.98	289.658
2979.28	319.391
2982.59	332.168
2985.89	349.677
2989.19	377.56
2992.49	371.668
2995.79	368.622
2999.09	406.968
3002.38	393.622
3005.68	441.409
3008.97	446.941
3012.26	479.826
3015.55	512.768
3018.84	511.787
3022.13	528.715
3025.41	570.203
3028.7	599.472
3031.98	626.871
3035.26	641.021
3038.54	646.645
3041.82	694.857
3045.1	724.2
3048.38	764.951
3051.65	770.676
3054.92	810.569
3058.2	835.287
3061.47	879.598
3064.73	930.742
3068	958.04
3071.27	1011.74
3074.54	1043.23
3077.8	1121.67
3081.06	1092.4
3084.32	1167.77
3087.58	1190.91
3090.84	1257.24
3094.1	1338.24
3097.35	1345.72
3100.61	1440.86
3103.86	1463.35
3107.11	1561.9
3110.36	1604.17
3113.61	1677.22
3116.86	1722.86
3120.11	1793.34
3123.35	1857.18
3126.59	1897.2
3129.84	1968.61
3133.08	2060.09
3136.32	2164.9
3139.55	2222.88
3142.79	2276.07
3146.03	2331.18
3149.26	2471.36
3152.49	2475.26
3155.72	2592.54
3158.95	2701.37
3162.18	2784.36
3165.41	2889.35
3168.64	3015.06
3171.86	3026.97
3175.08	3163.76
3178.31	3268.72
3181.53	3318.27
3184.75	3355.51
3187.96	3487.65
3191.18	3589.1
3194.4	3638.08
3197.61	3724.12
3200.82	3770.01
3204.03	3838.89
3207.24	3993.54
3210.45	4005.57
3213.66	4061.65
3216.86	4163.72
3220.07	4226.76
3223.27	4289.94
3226.48	4280.35
3229.68	4369.79
3232.87	4350.24
3236.07	4439.7
3239.27	4493.17
3242.47	4545.05
3245.66	4619.14
3248.85	4673.27
3252.04	4689.83
3255.23	4744.71
3258.42	4769.06
3261.61	4836.64
3264.8	4883.48
3267.98	4944.87
3271.16	4920.73
3274.35	4957.38
3277.53	5086.68
3280.71	5099.29
3283.89	5131.81
3287.06	5135.87
3290.24	5269.06
3293.41	5295.89
3296.58	5268.17
3299.76	5345.18
3302.93	5390.35
3306.1	5471.99
3309.26	5505.48
3312.43	5599.76
3315.59	5678.33
3318.76	5741.46
3321.92	5797.6
3325.08	5884.02
3328.24	5888.01
3331.4	5988.55
3334.56	6076.15
3337.71	6152.84
3340.87	6258.26
3344.02	6304.21
3347.17	6367.75
3350.33	6508.46
3353.47	6609.4
3356.62	6605.6
3359.77	6811.38
3362.92	6897.45
3366.06	6978.99
3369.2	7009.11
3372.34	7130.09
3375.49	7134.09
3378.62	7251.74
3381.76	7306.65
3384.9	7354.55
3388.04	7498.75
3391.17	7551.38
3394.3	7539.61
3397.43	7636.03
3400.56	7793.24
3403.69	7790.12
3406.82	7840.98
3409.95	7869.59
3413.07	7903.91
3416.2	7909.54
3419.32	7941.33
3422.44	8000.14
3425.56	8048.7
3428.68	8002.2
3431.8	8011.85
3434.91	7997.92
3438.03	8003.79
3441.14	8032.69
3444.25	7938.46
3447.36	7997.92
3450.47	7894.2
3453.58	7768.32
3456.69	7750.09
3459.79	7751.6
3462.9	7669.29
3466	7657.02
3469.11	7563.05
3472.21	7404.93
3475.31	7355.77
3478.4	7308.99
3481.5	7115.12
3484.6	7132.45
3487.69	6902.84
3490.79	6795.28
3493.88	6674.82
3496.97	6586.3
3500.06	6483.12
3503.15	6345.45
3506.23	6212.3
3509.32	6038.94
3512.4	5939.93
3515.49	5748.67
3518.57	5715.14
3521.65	5552.12
3524.73	5359.68
3527.81	5280.95
3530.89	5170.07
3533.96	5056.25
3537.03	4931.2
3540.11	4782.79
3543.18	4647.43
3546.25	4529.52
3549.32	4391.76
3552.39	4234.67
3555.46	4139.33
3558.52	4049.4
3561.59	3934.87
3564.65	3845.81
3567.71	3692.52
3570.77	3626.77
3573.83	3543.85
3576.89	3419.36
3579.95	3314.47
3583	3202.64
3586.06	3133.16
3589.11	3058.97
3592.16	2963.49
3595.21	2844.31
3598.27	2767.53
3601.31	2664.32
3604.36	2615.78
3607.41	2491.36
3610.45	2450.28
3613.5	2357.12
3616.54	2266.8
3619.58	2184.26
3622.62	2127.41
3625.66	2045.24
3628.69	1931.27
3631.73	1822
3634.77	1763.54
3637.8	1668.96
3640.83	1642.44
3643.86	1511.7
3646.89	1450.19
3649.92	1315.67
3652.95	1250.27
3655.98	1145
3659	1092.09
3662.02	999.412
3665.05	917.685
3668.07	837.147
3671.09	784.179
3674.11	684.045
3677.13	648.046
3680.14	580.898
3683.16	548.586
3686.17	484.098
3689.19	427.128
3692.2	415.557
3695.21	365.146
3698.22	331.596
3701.23	333.251
3704.23	284.601
3707.24	273.881
3710.24	265.935
3713.25	235.124
3716.25	204.218
3719.25	169.526
3722.25	172.831
3725.25	158.966
3728.25	142.202
3731.24	134.933
3734.24	111.439
3737.23	109.809
3740.22	100.534
3743.21	91.2232
3746.21	65.7239
3749.19	66.8373
3752.18	77.4265
3755.17	69.9608
3758.15	66.3135
3761.14	39.9091
3764.12	34.3619
3767.1	42.0889
3770.08	47.9401
3773.06	25.4451
3776.04	30.4125
3779.02	20.2769
3781.99	17.729
3784.97	32.1871
3787.94	17.391
3790.91	10.1716
3793.88	16.2157
3796.85	10.0159
3799.82	20.8246
3802.79	21.2935
3805.76	7.61331
3808.72	9.99573
3811.69	10.5097
3814.65	3.4693
3817.61	2.10718
3820.57	2.65024
3823.53	-5.31967
3826.49	2.82892
3829.45	12.8888
3832.4	2.09149
3835.36	9.34204
3838.31	18.5193
3841.26	3.94888
3844.21	2.67339
3847.16	0.451248
3850.11	5.85939
3853.06	-5.86909
3856	5.29265
3858.95	4.06133
3861.89	-9.595
3864.84	8.28558
3867.78	-4.44514
3870.72	-8.5914
3873.66	4.51337
3876.6	9.95039
3879.53	14.4052
3882.47	4.42812
3885.4	9.78926
3888.34	9.36729
3891.27	21.4354
3894.2	3.68654
3897.13	12.8308
3900.06	14.2514
3902.99	11.8228
3905.91	20.8947
3908.84	18.4674
3911.76	7.36786
3914.69	28.9173
3917.61	8.1722
3920.53	22.061
3923.45	31.0899
3926.37	11.3
3929.28	17.3972
3932.2	26.3456
3935.11	31.5203
3938.03	18.5551
3940.94	27.6717
3943.85	23.3555
3946.76	8.52388
3949.67	24.3573
3952.58	15.3181
3955.49	19.6949
3958.39	26.0142
3961.3	20.8517
3964.2	32.9531
3967.1	23.0235
3970	30.3682
3972.9	28.1307
3975.8	40.2907
3978.7	25.5439
3981.6	35.7547
3984.49	24.8192
3987.39	35.9803
3990.28	32.7149
3993.17	12.0949
3996.06	21.3454
3998.95	18.0831
4001.84	32.1631
4004.73	23.1409
4007.61	28.578
4010.5	28.2401
4013.38	28.8619
4016.27	30.4509
4019.15	32.0416
4022.03	31.7007
4024.91	29.4283
4027.79	29.0926
4030.66	22.9568
4033.54	12.9545
4036.42	24.2302
4039.29	23.9116
4042.16	18.7453
4045.03	13.5313
4047.9	18.9845
4050.77	19.607
4053.64	20.2425
4056.51	18.9595
4059.38	26.4079
4062.24	13.4494
4065.1	20.8915
4067.97	19.5858
4070.83	8.54434
4073.69	14.0393
4076.55	15.6379
4079.41	14.3112
4082.26	13.9568
4085.12	22.3791
4087.97	1.52914
4090.83	13.843
4093.68	11.5357
4096.53	13.1173
4099.38	19.595
4102.23	13.3644
4105.08	11.0317
4107.93	7.69278
4110.77	-0.541565
4113.62	22.5159
4116.46	8.36021
4119.3	8.8537
4122.14	20.1111
4124.98	3.01331
4127.82	9.40839
4130.66	9.00613
4133.5	11.5756
4136.33	14.2101
4139.17	7.7784
4142	11.9196
4144.83	0.638977
4147.67	6.09966
4150.5	8.64189
4153.33	9.18214
4156.15	11.6035
4158.98	15.8898
4161.81	17.3011
4164.63	23.6378
4167.45	2.58316
4170.28	5.99007
4173.1	5.49492
4175.92	3.04858
4178.74	1.57903
4181.56	1.10144
4184.37	4.54222
4187.19	-8.63754
4190	5.57916
4192.82	1.23337
4195.63	0.82164
4198.44	25.9112
4201.25	4.94283
4204.06	9.46089
4206.87	3.17776
4209.68	5.72748
4212.48	-2.53868
4215.29	6.88068
4218.1	-5.23421
4220.9	9.22884
4223.7	10.8748
4226.5	3.60896
4229.3	7.22726
4232.1	4.92386
4234.9	3.62537
4237.69	9.27652
4240.49	-1.93936
4243.28	-2.24432
4246.07	1.4409
4248.87	10.1088
4251.66	12.7865
4254.45	6.46446
4257.24	5.1107
4260.03	4.7486
4262.81	0.379166
4265.6	-1.9884
4268.38	6.70621
4271.17	11.391
4273.95	-6.09457
4276.73	3.58292
4279.51	3.15012
4282.29	2.69965
4285.07	6.2713
4287.84	7.79688
4290.62	6.2634
4293.39	1.67865
4296.17	5.21548
4298.94	5.72839
4301.71	-4.93451
4304.48	0.622818
4307.25	4.15163
4310.02	8.70515
4312.79	3.11281
4315.55	-4.54955
4318.32	0.988342
4321.08	-2.64598
4323.85	-4.26334
4326.61	-7.92993
4329.37	15.9043
4332.13	-3.0583
4334.89	0.392838
4337.65	19.1102
4340.4	3.21217
4343.16	0.559555
4345.91	3.01801
4348.67	12.6342
4351.42	4.90543
4354.17	-4.83438
4356.92	1.75034
4359.67	9.36078
4362.42	2.63962
4365.17	-1.00612
4367.91	3.52589
4370.66	1.92311
4373.4	5.41696
4376.14	1.71944
4378.89	19.5658
4381.63	1.46375
4384.37	0.825287
4387.11	2.2758
4389.84	-4.4442
4392.58	6.36816
4395.32	3.91397
4398.05	1.3396
4400.78	-0.229507
4403.52	1.28865
4406.25	-2.37503
4408.98	7.463
4411.71	4.82039
4414.44	4.22591
4417.16	-4.71808
4419.89	12.3228
4422.62	4.3692
4425.34	4.76602
4428.06	9.34109
4430.78	-2.8101
4433.51	-2.42937
4436.22	4.22299
4438.94	1.44313
4441.66	9.12349
4444.38	4.22565
4447.1	3.50761
4449.81	-0.364731
4452.52	2.04474
4455.24	6.55109
4457.95	-0.518677
4460.66	-0.243927
4463.37	12.6669
4466.08	10.8537
4468.78	10.0976
4471.49	1.97568
4474.2	1.23058
4476.9	9.98378
4479.6	-1.284
4482.31	-4.11635
4485.01	1.49634
4487.71	0.758072
4490.41	4.24167
4493.11	12.9802
4495.8	0.513306
4498.5	3.95477
4501.19	8.44827
4503.89	-2.97202
4506.58	13.1791
4509.27	11.3149
4511.96	13.6912
4514.66	9.70131
4517.34	4.64777
4520.03	10.2183
4522.72	-12.8976
4525.41	10.7692
4528.09	16.3598
4530.77	2.78528
4533.46	0.919861
4536.14	5.45543
4538.82	11.0667
4541.5	7.08083
4544.18	2.01353
4546.86	15.1333
4549.53	20.7766
4552.21	7.14694
4554.88	11.7603
4557.56	6.73318
4560.23	4.96733
4562.9	8.61093
4565.57	10.1528
4568.24	9.58575
4570.91	10.0063
4573.58	8.07068
4576.24	11.4763
4578.91	21.4841
4581.58	10.9137
4584.24	14.5171
4586.9	12.5727
4589.56	-2.47116
4592.22	6.45128
4594.88	12.1141
4597.54	-7.32008
4600.2	13.6464
4602.86	6.22745
4605.51	3.18591
4608.17	13.2909
4610.82	11.3479
4613.47	7.19698
4616.13	1.9353
4618.78	1.06979
4621.43	13.4243
4624.07	3.75073
4626.72	12.7995
4629.37	-0.228561
4632.01	-5.54869
4634.66	-5.37132
4637.3	8.06958
4639.94	10.4533
4642.59	3.97723
4645.23	10.8283
4647.87	13.2945
4650.5	13.5828
4653.14	10.5901
4655.78	5.31369
4658.42	9.86281
4661.05	5.61449
4663.68	4.73567
4666.31	0.482391
4668.95	-2.70097
4671.58	6.44084
4674.21	1.02499
4676.84	20.2701
4679.46	6.99368
4682.09	-0.692413
4684.72	1.72507
4687.34	-0.353409
4689.97	3.19379
4692.59	4.49667
4695.21	-0.976944
4697.83	11.5866
4700.45	-4.04851
4703.07	4.01044
4705.69	12.064
4708.3	-2.49312
4710.92	-2.36472
4713.54	0.0250854
4716.15	-0.985641
4718.76	-3.13834
4721.37	-1.89671
4723.99	1.60289
4726.59	10.7962
4729.2	4.12497
4731.81	5.39436
4734.42	8.93741
4737.03	3.38841
4739.63	14.8759
4742.23	0.212616
4744.84	3.72717
4747.44	1.54631
4750.04	1.61725
4752.64	6.24588
4755.24	7.45927
4757.84	9.80963
4760.44	-6.03893
4763.03	10.0023
4765.63	-5.83289
4768.22	6.84299
4770.82	5.86824
4773.41	4.85828
4776	6.13429
4778.59	-0.579453
4781.18	-3.87294
4783.77	11.1202
4786.36	-0.16922
4788.94	-0.0272675
4791.53	5.84447
4794.11	9.44052
4796.7	5.02602
4799.28	1.77031
4801.86	9.99651
4804.44	-5.86726
4807.02	1.25084
4809.6	-5.41072
4812.18	-5.17534
4814.76	1.99011
4817.33	-2.36198
4819.91	6.00551
4822.48	1.66354
4825.06	1.95146
4827.63	-1.24107
4830.2	-0.953598
4832.77	0.516922
4835.34	6.65796
4837.91	9.33859
4840.48	1.52704
4843.04	3.05269
4845.61	8.07516
4848.17	4.88181
4850.74	2.81697
4853.3	17.1096
4855.86	-0.322906
4858.42	5.91873
4860.98	7.4566
4863.54	10.1418
4866.1	-1.39772
4868.66	7.15303
4871.21	3.92632
4873.77	-0.523209
4876.32	3.3054
4878.88	-4.72151
4881.43	0.296143
4883.98	4.12697
4886.53	10.3425
4889.08	7.05792
4891.63	-0.985153
4894.18	4.05945
4896.72	9.10989
4899.27	10.5889
4901.81	2.53055
4904.36	2.81886
4906.9	-2.86043
4909.44	-1.38164
4911.98	12.0191
4914.52	3.91451
4917.06	-1.81009
4919.6	4.43027
4922.14	5.89952
4924.67	14.5455
4927.21	4.08846
4929.74	7.96046
4932.28	7.0932
4934.81	18.2219
4937.34	-1.76117
4939.87	2.18491
4942.4	15.6573
4944.93	-1.94466
4947.46	10.4209
4949.99	-9.55949
4952.51	-1.96274
4955.04	12.8306
4957.56	3.66344
4960.08	11.3199
4962.61	-3.83044
4965.13	12.3184
4967.65	-0.374329
4970.17	12.2005
4972.69	13.9335
4975.2	2.38475
4977.72	11.3739
4980.24	9.50191
4982.75	10.0583
4985.27	9.41579
4987.78	8.78307
4990.29	9.37462
4992.8	5.10597
4995.31	3.26762
4997.82	7.54624