File: Data/3-Raman/processed/bu19w-e-ff11-fi09-v_150 (500nm)_633nm_edge_100%_x100_vis_h50um_60sx2_01_0.txt
#Acq. time (s)=	60
#Accumulations=	2
#Range (cm-¹)=	100...4000
#Windows=	1
#Auto scanning=	Off
#Autofocus=	Off
#Macrospot=	Off
#AutoExposure=	Off
#Spike filter=	Multiple accum.
#Delay time (s)=	2
#Binning=	1
#Readout mode=	Signal
#DeNoise=	Off
#ICS correction=	On
#Dark correction=	Off
#Inst. Process=	Off
#Detector Gain=	Best Dynamic
#Detector ADC=	50 kHz HS
#Detector temperature (°C)=	-60.09
#Instrument=	LabRAM HR Evol
#Detector=	SIN-EM FIVIS
#Objective=	x100_VIS
#Grating=	150 (500nm)
#ND Filter=	100%
#Laser=	633nm_Edge
#Hole=	49.98
#Temperature=	0
#Range=	Visible
#StageXY=	75x50mm Scan+
#StageZ=	Z motor
#X (µm)=	0
#Y (µm)=	0
#Z (µm)=	-270.7
#Full time(mm:ss)=	2:04
#Project=	21_11_04
#Sample=	BU19w
#Site=
#Title=	BU19w-E-FF11-FI09-V_150 (500nm)_633nm_Edge_100%_x100_VIS_H50um_60sX2
#Remark=
#Date=	04.11.2021 16:10
#Acquired=	04.11.2021 16:10:44
#Base:Fit=	16.12.2021 17:39:50
#Base:Edit=	16.12.2021 17:52:00
#Base:Edit=	16.12.2021 17:52:02
#Base:Edit=	16.12.2021 17:52:02
#Base:Edit=	16.12.2021 17:52:03
#Base:Edit=	16.12.2021 17:52:04
#Base:Edit=	16.12.2021 17:52:05
#Base:Edit=	16.12.2021 17:52:05
#Base:Edit=	16.12.2021 17:52:08
#Base:Sub=	16.12.2021 17:52:10
102.881	153.829
109.397	125.386
115.908	95.2556
122.414	100.657
128.914	81.4299
135.409	96.8164
141.898	84.6164
148.383	68.8297
154.861	103.062
161.335	127.968
167.801	61.0515
174.264	28.709
180.721	11.793
187.173	7.41461
193.62	12.692
200.061	5.73276
206.496	13.3517
212.926	3.88512
219.352	46.0365
225.772	101.542
232.185	156.878
238.595	79.2112
244.999	38.893
251.397	34.8013
257.791	42.1601
264.178	49.623
270.561	46.7532
276.939	62.0001
283.31	56.4046
289.678	31.8682
296.039	19.6832
302.396	31.2191
308.746	50.3246
315.093	168.603
321.433	275.491
327.768	187.163
334.099	74.4285
340.423	42.8542
346.743	48.0681
353.058	48.5619
359.367	68.7931
365.671	45.7274
371.971	18.9738
378.265	5.42065
384.553	5.06824
390.837	14.2605
397.116	8.56026
403.389	0.120674
409.657	8.61066
415.92	20.8439
422.178	38.7519
428.431	63.9204
434.678	68.034
440.921	63.6418
447.158	70.4907
453.391	81.9406
459.618	51.4369
465.84	27.7293
472.057	27.4218
478.27	20.6998
484.477	24.217
490.679	23.0708
496.876	34.9784
503.068	27.3267
509.255	60.7233
515.436	56.8501
521.613	62.4005
527.785	55.8654
533.952	47.506
540.113	40.0241
546.27	37.1081
552.423	33.1008
558.568	25.2411
564.711	15.3064
570.848	17.5314
576.979	16.8313
583.107	20.8171
589.228	48.1693
595.345	56.9311
601.458	54.6978
607.565	58.2282
613.667	61.8368
619.764	60.8835
625.856	43.9805
631.944	18.3015
638.026	25.3829
644.104	37.9204
650.177	38.1743
656.244	27.0509
662.308	30.9205
668.365	11.4594
674.418	6.21424
680.467	3.81144
686.511	0.534874
692.549	0.134232
698.582	1.61745
704.611	3.07781
710.635	0.715622
716.655	4.75801
722.669	0.344902
728.679	3.37174
734.683	2.60399
740.683	10.2443
746.678	0.146393
752.669	2.23341
758.654	9.9701
764.635	2.00718
770.611	9.99185
776.582	15.1911
782.549	9.97693
788.511	10.3333
794.466	-2.56806
800.419	8.97348
806.366	7.24132
812.309	11.1158
818.247	3.64613
824.18	13.0399
830.108	13.0556
836.033	16.0422
841.952	8.88772
847.865	12.9771
853.776	15.2426
859.681	19.4273
865.58	25.5287
871.476	29.7385
877.366	33.8388
883.253	36.9306
889.134	38.043
895.012	39.0881
900.883	36.2113
906.751	32.3265
912.614	30.3199
918.473	47.1768
924.326	44.4238
930.174	56.8716
936.019	63.8245
941.859	92.7762
947.693	109.665
953.525	125.734
959.35	119.813
965.171	126.146
970.988	157.322
976.801	219.022
982.608	251.468
988.411	230.975
994.209	183.712
1000	145.252
1005.79	133.702
1011.58	153.876
1017.36	195.236
1023.13	171.823
1028.9	132.265
1034.67	89.6829
1040.43	90.2739
1046.19	83.1356
1051.94	72.9394
1057.69	57.7507
1063.44	47.257
1069.17	48.2782
1074.91	53.1758
1080.64	86.1369
1086.37	109.335
1092.09	163.552
1097.8	178.005
1103.52	120.892
1109.22	92.0326
1114.93	82.756
1120.63	75.5244
1126.32	73.9664
1132.01	91.0165
1137.7	118.922
1143.38	145.962
1149.06	197.513
1154.73	146.574
1160.4	69.7672
1166.06	49.9293
1171.72	46.8323
1177.38	37.8528
1183.03	26.0241
1188.67	30.9391
1194.31	12.4908
1199.95	16.5942
1205.58	10.0344
1211.21	10.3681
1216.84	7.77451
1222.46	5.18723
1228.07	6.57098
1233.68	14.9465
1239.29	-1.85991
1244.89	14.4575
1250.49	13.5587
1256.08	15.6264
1261.67	17.588
1267.26	9.44273
1272.84	73.7176
1278.42	62.3951
1283.99	15.0719
1289.56	16.972
1295.12	11.9276
1300.68	9.9359
1306.23	3.01999
1311.78	9.2113
1317.33	10.4626
1322.87	-1.37511
1328.41	2.93865
1333.94	11.3431
1339.47	7.51546
1345	5.63807
1350.52	4.74242
1356.04	3.81136
1361.55	14.134
1367.06	11.0394
1372.56	13.0486
1378.06	186.56
1383.56	42.7095
1389.05	7.74686
1394.53	17.9914
1400.02	28.3624
1405.5	8.90936
1410.97	9.00524
1416.44	11.1927
1421.91	9.25681
1427.37	11.4785
1432.83	9.54922
1438.28	7.60065
1443.73	12.9601
1449.17	3.63192
1454.62	5.75083
1460.05	8.86919
1465.48	17.1962
1470.91	5.55624
1476.34	8.62938
1481.76	5.43498
1487.17	9.61371
1492.59	8.57681
1497.99	10.7338
1503.4	10.8106
1508.8	10.9155
1514.19	9.98452
1519.59	10.1395
1524.97	8.17005
1530.36	2.96729
1535.74	11.7395
1541.11	11.8536
1546.48	10.7861
1551.85	8.51378
1557.21	1.82021
1562.57	13.5019
1567.93	7.90546
1573.28	12.0081
1578.62	8.61266
1583.97	9.56622
1589.3	8.38757
1594.64	9.39551
1599.97	1.80547
1605.3	8.28271
1610.62	11.593
1615.94	6.28455
1621.25	4.2416
1626.56	12.0422
1631.87	18.7888
1637.17	10.0587
1642.47	13.3142
1647.76	8.85107
1653.05	15.4221
1658.34	14.1983
1663.62	11.8346
1668.9	6.12229
1674.18	4.83767
1679.45	11.2982
1684.71	14.3818
1689.98	10.8046
1695.23	9.494
1700.49	14.9468
1705.74	17.4171
1710.99	15.1142
1716.23	1.56284
1721.47	10.5275
1726.7	7.0983
1731.94	13.8017
1737.16	11.5178
1742.39	13.728
1747.61	3.50811
1752.82	5.65829
1758.03	10.0407
1763.24	4.19138
1768.44	14.2073
1773.64	17.4448
1778.84	13.917
1784.03	13.8318
1789.22	5.81165
1794.41	17.1809
1799.59	13.7563
1804.76	6.88972
1809.94	10.3073
1815.11	4.49589
1820.27	3.28051
1825.43	13.6432
1830.59	10.1372
1835.74	8.95281
1840.89	14.7159
1846.04	9.9642
1851.18	11.032
1856.32	9.72731
1861.45	6.11948
1866.58	11.9248
1871.71	7.12479
1876.83	12.8859
1881.95	16.2859
1887.07	14.9423
1892.18	8.79667
1897.29	6.18695
1902.39	13.1209
1907.49	11.8574
1912.59	1.15491
1917.68	8.32052
1922.77	20.1034
1927.86	9.26847
1932.94	16.3733
1938.02	12.6684
1943.09	2.90666
1948.16	6.3395
1953.23	21.7853
1958.29	3.47567
1963.35	6.83582
1968.41	1.73164
1973.46	17.0704
1978.51	21.5576
1983.55	7.98904
1988.59	10.0784
1993.63	4.96444
1998.66	9.48888
2003.69	4.42172
2008.72	6.6021
2013.74	13.6253
2018.76	3.77702
2023.77	16.8363
2028.78	8.24296
2033.79	19.0221
2038.79	5.61684
2043.79	6.74172
2048.79	15.19
2053.78	13.8731
2058.77	7.69557
2063.76	10.0793
2068.74	3.88304
2073.72	11.1776
2078.69	11.096
2083.66	15.9278
2088.63	9.60664
2093.59	0.83326
2098.55	6.96472
2103.51	14.3858
2108.46	10.6445
2113.41	21.9257
2118.36	14.4662
2123.3	13.247
2128.24	6.95419
2133.17	11.9936
2138.11	10.6859
2143.03	19.5287
2147.96	24.5497
2152.88	16.7744
2157.79	12.7761
2162.71	3.62107
2167.62	17.4279
2172.52	6.97001
2177.43	15.7143
2182.32	7.76006
2187.22	22.818
2192.11	12.3276
2197	14.6806
2201.89	9.40307
2206.77	13.1505
2211.64	9.22759
2216.52	15.641
2221.39	5.28822
2226.26	3.96654
2231.12	9.14232
2235.98	10.4321
2240.84	11.7255
2245.69	10.412
2250.54	7.77551
2255.39	11.7027
2260.23	9.06404
2265.07	9.02238
2269.9	0.974739
2274.74	-3.15562
2279.57	11.283
2284.39	12.3855
2289.21	10.7941
2294.03	17.1823
2298.84	15.6255
2303.66	7.45496
2308.46	14.0185
2313.27	-2.08066
2318.07	12.6314
2322.87	24.7319
2327.66	9.96229
2332.45	8.65082
2337.24	16.8492
2342.02	7.43252
2346.8	15.7451
2351.58	11.7682
2356.35	3.58908
2361.12	7.67907
2365.89	11.774
2370.65	10.3523
2375.41	19.999
2380.17	17.1564
2384.92	14.2307
2389.67	18.2085
2394.42	13.7838
2399.16	3.74503
2403.9	11.7901
2408.64	12.8973
2413.37	7.24043
2418.1	15.9147
2422.83	14.623
2427.55	8.9007
2432.27	8.91827
2436.99	20.3079
2441.7	4.79037
2446.41	6.26751
2451.11	10.6161
2455.82	6.37954
2460.51	7.86847
2465.21	5.03852
2469.9	16.6176
2474.59	2.16701
2479.28	9.43983
2483.96	5.07649
2488.64	21.0767
2493.32	13.7452
2497.99	1.99912
2502.66	9.26093
2507.32	13.5852
2511.99	16.4185
2516.65	14.8117
2521.3	10.2879
2525.96	13.1429
2530.61	11.5617
2535.25	11.4952
2539.89	17.399
2544.53	5.46343
2549.17	18.8769
2553.8	23.3678
2558.43	14.3354
2563.06	17.3276
2567.68	9.83826
2572.3	11.3909
2576.92	8.38944
2581.53	22.0045
2586.14	20.3832
2590.75	1.95725
2595.35	12.453
2599.96	6.26939
2604.55	15.2891
2609.15	16.6728
2613.74	4.24433
2618.33	4.05303
2622.91	20.7137
2627.49	5.2397
2632.07	17.4664
2636.64	14.446
2641.22	16.1286
2645.78	24.0416
2650.35	11.7631
2654.91	21.189
2659.47	22.7099
2664.03	14.8037
2668.58	25.6651
2673.13	3.70894
2677.67	16.4901
2682.22	13.7401
2686.76	12.4943
2691.29	14.3789
2695.83	11.2486
2700.36	25.6848
2704.89	32.1282
2709.41	7.96443
2713.93	9.52367
2718.45	15.9997
2722.96	14.3553
2727.47	27.2347
2731.98	15.7168
2736.49	15.5404
2740.99	13.7407
2745.49	15.2618
2749.98	15.2275
2754.47	15.3735
2758.96	21.9194
2763.45	12.0087
2767.93	8.71936
2772.41	16.9349
2776.89	15.3657
2781.36	15.5341
2785.84	10.7615
2790.3	5.94609
2794.77	9.44203
2799.23	6.18413
2803.69	11.2752
2808.14	11.287
2812.59	12.9613
2817.04	19.6628
2821.49	7.7679
2825.93	4.33907
2830.37	7.68143
2834.81	9.31059
2839.24	5.83345
2843.67	4.06396
2848.1	22.851
2852.53	14.3491
2856.95	21.3306
2861.37	19.7498
2865.78	9.59793
2870.19	23.6585
2874.6	18.6812
2879.01	13.6976
2883.41	3.47244
2887.81	14.2631
2892.21	9.23964
2896.6	20.1153
2901	2.71117
2905.38	24.2718
2909.77	24.5081
2914.15	19.2711
2918.53	12.2142
2922.91	14.1497
2927.28	12.5411
2931.65	16.3758
2936.02	18.3444
2940.38	14.7843
2944.74	11.1945
2949.1	25.7505
2953.46	-1.61179
2957.81	20.2867
2962.16	3.82613
2966.5	16.6756
2970.85	13.0702
2975.19	11.3047
2979.52	22.4391
2983.86	18.8953
2988.19	20.9512
2992.52	8.2012
2996.85	19.6119
3001.17	31.1414
3005.49	16.5377
3009.8	20.6423
3014.12	30.4029
3018.43	17.5844
3022.74	23.6752
3027.04	20.1741
3031.34	29.965
3035.64	20.5708
3039.94	18.7979
3044.23	30.4795
3048.52	22.9088
3052.81	40.385
3057.09	21.2335
3061.38	25.2361
3065.65	31.1953
3069.93	23.575
3074.2	41.2411
3078.47	37.5402
3082.74	37.7325
3087	38.0055
3091.27	20.7017
3095.52	32.9151
3099.78	45.2283
3104.03	41.8055
3108.28	44.3842
3112.53	39.0337
3116.77	51.6845
3121.01	50.3705
3125.25	36.9642
3129.49	47.881
3133.72	56.9188
3137.95	61.9125
3142.18	38.0198
3146.4	61.4548
3150.62	58.002
3154.84	62.7205
3159.06	88.3373
3163.27	57.5244
3167.48	76.9218
3171.69	79.5751
3175.89	90.6013
3180.09	67.6615
3184.29	65.773
3188.49	82.8949
3192.68	74.6857
3196.87	70.8156
3201.06	77.8868
3205.24	85.0874
3209.42	68.7788
3213.6	63.1683
3217.78	72.7437
3221.95	56.1797
3226.12	65.7382
3230.29	70.9545
3234.45	58.5413
3238.61	76.9788
3242.77	64.567
3246.93	56.5471
3251.08	57.2456
3255.23	37.5865
3259.38	44.8493
3263.53	41.011
3267.67	53.3536
3271.81	51.9229
3275.95	36.4721
3280.08	48.3202
3284.21	51.0383
3288.34	56.0586
3292.47	61.0733
3296.59	61.4688
3300.71	27.2636
3304.83	41.5403
3308.95	34.9898
3313.06	44.6467
3317.17	35.7374
3321.27	50.1763
3325.38	46.0446
3329.48	27.8632
3333.58	35.6184
3337.67	41.0665
3341.77	27.4164
3345.86	42.0881
3349.95	44.8598
3354.03	45.27
3358.11	31.4652
3362.19	39.1349
3366.27	32.427
3370.34	37.7081
3374.42	35.7336
3378.48	24.0472
3382.55	55.7496
3386.61	31.9368
3390.68	20.1377
3394.73	30.1204
3398.79	42.617
3402.84	47.8006
3406.89	35.9395
3410.94	41.0669
3414.98	43.7583
3419.03	26.968
3423.06	15.0097
3427.1	32.3442
3431.14	25.3432
3435.17	25.7108
3439.2	48.1895
3443.22	36.4079
3447.25	41.906
3451.27	27.7078
3455.28	30.8235
3459.3	39.0157
3463.31	29.846
3467.32	25.6147
3471.33	38.881
3475.34	31.9687
3479.34	30.1348
3483.34	40.9257
3487.33	23.8388
3491.33	44.8092
3495.32	27.5773
3499.31	40.8893
3503.3	43.9392
3507.28	21.2862
3511.26	39.5407
3515.24	26.9584
3519.22	24.6326
3523.19	17.1586
3527.16	35.449
3531.13	22.8433
3535.1	20.7029
3539.06	31.5877
3543.02	26.9105
3546.98	32.5376
3550.93	38.1078
3554.89	35.722
3558.84	51.6759
3562.78	10.3882
3566.73	31.6943
3570.67	29.6156
3574.61	35.3802
3578.55	35.9848
3582.48	39.2914
3586.41	29.4082
3590.35	38.0184
3594.27	28.0506
3598.2	26.0168
3602.12	42.6365
3606.04	16.4175
3609.95	27.6398
3613.87	36.2137
3617.78	12.4161
3621.69	15.4752
3625.6	10.3113
3629.5	13.2361
3633.4	35.0612
3637.3	21.783
3641.2	8.59064
3645.09	11.7256
3648.98	36.5612
3652.87	23.2492
3656.76	28.9706
3660.64	4.67072
3664.53	29.4709
3668.4	35.2274
3672.28	27.2955
3676.16	8.46812
3680.03	6.116
3683.9	28.5894
3687.76	9.84299
3691.63	15.9084
3695.49	13.6241
3699.35	0.224762
3703.2	17.4171
3707.06	9.55548
3710.91	18.472
3714.76	13.3428
3718.6	8.12498
3722.45	22.6193
3726.29	22.9805
3730.13	12.0012
3733.97	26.5611
3737.8	18.4069
3741.63	13.0396
3745.46	16.1964
3749.29	2.17625
3753.11	19.5459
3756.93	19.7182
3760.75	22.7158
3764.57	14.2361
3768.39	0.0269318
3772.2	20.2759
3776.01	20.4535
3779.81	29.2944
3783.62	-2.10008
3787.42	15.4496
3791.22	9.91408
3795.02	13.0918
3798.81	16.3235
3802.61	16.6781
3806.4	14.1474
3810.18	5.76588
3813.97	9.00948
3817.75	15.1848
3821.53	15.4941
3825.31	15.7612
3829.09	16.0338
3832.86	4.54259
3836.63	4.81245
3840.4	10.9753
3844.17	-3.5524
3847.93	8.44649
3851.69	5.58904
3855.45	26.4715
3859.21	-6.20555
3862.96	23.5839
3866.71	14.94
3870.46	15.3186
3874.21	9.43933
3877.95	6.55704
3881.69	6.66869
3885.44	0.820099
3889.17	9.96931
3892.91	7.18289
3896.64	16.494
3900.37	13.7535
3904.1	20.0391
3907.82	14.2585
3911.55	32.685
3915.27	2.73723
3918.99	6.11911
3922.7	15.659
3926.42	6.92024
3930.13	-7.99367
3933.84	16.7842
3937.54	7.88419
3941.25	5.1524
3944.95	5.53792
3948.65	8.98668
3952.35	6.22594
3956.04	6.52974
3959.73	12.9817
3963.42	19.4241
3967.11	10.3483
3970.8	22.9303
3974.48	10.7455
3978.16	14.0595
3981.84	4.93153
3985.52	-1.08249
3989.19	17.7273
3992.86	5.59586
3996.53	-9.5849
3998.37	12.3431