File: Data/3-Raman/processed/bu19(2)w-a-ff2-fi02-v_1800 (450-850nm)_532nm_edge_100%_x100_vis_lwd_h50um_30sx2_01.txt
#Acq. time (s)=	30
#Accumulations=	2
#Range (cm-¹)=	1200...2365
#Windows=	3
#Auto scanning=	Off
#Autofocus=	Off
#Macrospot=	Off
#AutoExposure=	Off
#Spike filter=	Multiple accum.
#Delay time (s)=	2
#Binning=	1
#Readout mode=	Signal
#DeNoise=	Off
#ICS correction=	On
#Dark correction=	Off
#Inst. Process=	Off
#Detector Gain=	Best Dynamic
#Detector ADC=	50 kHz HS
#Detector temperature (°C)=	-60.09
#Instrument=	LabRAM HR Evol
#Detector=	SIN-EM FIVIS
#Objective=	x50_VIS_LWD
#Grating=	1800 (450-850nm)
#ND Filter=	100%
#Laser=	532nm_Edge
#Hole=	49.98
#Temperature=	0
#Range=	Visible
#StageXY=	75x50mm Scan+
#StageZ=	Z motor
#X (µm)=	0
#Y (µm)=	0
#Z (µm)=	-0.3
#Full time(mm:ss)=	3:18
#Project=	21_11_26
#Sample=	BU19(2)w
#Site=
#Title=	BU19(2)w-A-FF02-FI02-V_1800 (450-850nm)_532nm_Edge_100%_x50_VIS_LWD_H50um_30sX2
#Remark=
#Date=	26.11.2021 14:34
#Acquired=	26.11.2021 14:34:04
#Base:Fit=	16.12.2021 16:00:56
#Base:Fit=	16.12.2021 16:11:04
#Base:Sub=	16.12.2021 16:11:05
1202.72	2.54443
1203.84	4.82178
1204.95	0.601112
1206.06	-3.64061
1207.17	2.82783
1208.28	-0.339073
1209.39	-0.29917
1210.5	-0.251297
1211.61	6.16349
1212.72	-2.36247
1213.83	1.91253
1214.94	-1.25247
1216.05	-1.23104
1217.16	-4.43722
1218.27	-1.26279
1219.38	-4.45292
1220.49	-0.215849
1221.6	-3.4062
1222.71	-0.2659
1223.81	0.731993
1224.92	-1.4247
1226.03	-0.384247
1227.14	-1.46551
1228.25	4.77184
1229.35	-1.63543
1230.46	2.61883
1231.57	0.401073
1232.67	0.366346
1233.78	-1.77748
1234.89	-0.755867
1235.99	-3.9387
1237.1	2.31992
1238.2	0.137836
1239.31	0.0594845
1240.41	-3.14162
1241.52	2.05463
1242.62	5.13835
1243.73	3.00263
1244.83	2.95218
1245.94	4.9677
1247.04	4.8983
1248.14	3.79267
1249.25	3.72336
1250.35	-2.60404
1251.45	3.59152
1252.56	1.42907
1253.66	2.40112
1254.76	2.36815
1255.87	-1.85386
1256.97	8.54767
1258.07	8.49028
1259.17	6.33612
1260.27	10.4895
1261.37	22.9192
1262.48	31.3507
1263.58	38.4458
1264.68	28.1568
1265.78	13.4297
1266.88	16.5254
1267.98	10.2543
1269.08	9.2215
1270.18	10.2332
1271.28	9.11552
1272.38	13.2731
1273.47	11.1962
1274.57	11.2051
1275.67	13.2799
1276.77	10.1362
1277.87	20.6509
1278.97	18.57
1280.07	31.1803
1281.16	80.6006
1282.26	278.547
1283.36	681.36
1284.45	324.415
1285.55	69.0932
1286.65	34.3203
1287.75	21.6545
1288.84	15.3205
1289.94	5.86546
1291.03	10.0859
1292.13	14.2936
1293.22	7.97387
1294.32	4.85966
1295.42	5.92778
1296.51	2.83878
1297.61	4.95696
1298.7	1.78034
1299.79	4.94361
1300.89	10.2486
1301.98	10.2713
1303.08	7.13187
1304.17	0.80337
1305.26	2.93476
1306.35	5.04159
1307.45	1.8975
1308.54	2.98294
1309.63	4.07801
1310.73	8.33641
1311.82	0.988104
1312.91	-3.18552
1314	2.12183
1315.09	-1.00308
1316.18	0.108576
1317.28	-0.909578
1318.37	0.200066
1319.46	1.30402
1320.55	3.4651
1321.64	-2.84218
1322.73	-2.81447
1323.82	-0.662237
1324.91	-0.606525
1326	-2.67676
1327.09	1.54628
1328.18	0.602179
1329.27	1.75202
1330.35	2.86455
1331.44	3.95544
1332.53	0.816124
1333.62	3.99722
1334.71	-0.171478
1335.79	1.97203
1336.88	5.16857
1337.97	-3.15813
1339.06	0.036396
1340.14	-0.938732
1341.23	4.37406
1342.32	2.34359
1343.4	3.44015
1344.49	-1.71448
1345.58	1.48819
1346.66	1.52771
1347.75	1.57384
1348.83	-1.48456
1349.92	3.78684
1351	-0.316273
1352.09	2.86767
1353.17	2.97099
1354.25	3.08623
1355.34	5.18231
1356.42	1.10993
1357.51	5.33824
1358.59	7.48241
1359.67	4.43652
1360.76	6.56937
1361.84	4.57776
1362.92	7.76325
1364	5.79414
1365.09	8.99135
1366.17	9.05393
1367.25	6.00784
1368.33	14.3689
1369.41	33.0836
1370.5	11.4549
1371.58	12.5509
1372.66	14.6532
1373.74	11.6288
1374.82	14.8028
1375.9	11.8058
1376.98	10.8546
1378.06	17.1133
1379.14	18.3068
1380.22	25.594
1381.3	28.6722
1382.38	30.7671
1383.46	41.0423
1384.54	81.0856
1385.61	219.818
1386.69	1094.14
1387.77	750.186
1388.85	124.465
1389.93	50.9257
1391	41.6807
1392.08	27.3798
1393.16	18.2215
1394.23	18.3002
1395.31	19.4155
1396.39	21.57
1397.46	16.5256
1398.54	11.4963
1399.62	14.6738
1400.69	16.8267
1401.77	13.865
1402.84	18.1148
1403.92	14.1377
1404.99	17.2815
1406.07	20.423
1407.14	39.9759
1408.22	76.9938
1409.29	66.8566
1410.37	20.8042
1411.44	18.8008
1412.51	15.8075
1413.59	7.7775
1414.66	5.77763
1415.73	8.95627
1416.81	10.0786
1417.88	6.06831
1418.95	6.15779
1420.02	6.23509
1421.1	2.19049
1422.17	9.46142
1423.24	7.54854
1424.31	5.48663
1425.38	7.61939
1426.45	5.65545
1427.52	5.70895
1428.59	3.7152
1429.67	5.84824
1430.74	-0.202692
1431.81	5.03079
1432.87	3.04088
1433.95	4.10609
1435.01	3.1636
1436.08	2.21207
1437.15	4.32649
1438.22	3.36774
1439.29	8.56886
1440.36	2.50805
1441.43	5.65977
1442.49	2.64919
1443.56	0.664867
1444.63	4.82818
1445.7	2.86086
1446.77	3.94444
1447.83	0.924349
1448.9	4.07056
1449.97	3.10412
1451.03	6.23022
1452.1	2.18381
1453.17	4.29191
1454.23	3.32992
1455.3	2.3619
1456.36	-0.650684
1457.43	2.47212
1458.49	-1.57322
1459.56	-0.491003
1460.62	1.60911
1461.69	-0.394594
1462.75	1.69185
1463.82	2.74794
1464.88	0.774162
1465.94	1.78945
1467.01	-0.208757
1468.07	1.87631
1469.13	0.900499
1470.2	0.93446
1471.26	3.00767
1472.32	1.00431
1473.39	-0.991653
1474.45	-0.957153
1475.51	3.15869
1476.57	-2.91258
1477.63	1.18821
1478.69	0.203878
1479.76	-2.81721
1480.82	2.27921
1481.88	-1.74949
1482.94	-0.687374
1484	0.366262
1485.06	-0.649242
1486.12	1.40551
1487.18	2.45347
1488.24	-0.563025
1489.3	-1.55739
1490.36	3.52687
1491.42	-0.499233
1492.48	-0.472273
1493.53	0.564432
1494.59	-1.43084
1495.65	-0.400431
1496.71	0.618618
1497.77	1.6478
1498.82	-0.347578
1499.88	-1.32998
1500.94	2.73202
1502	0.727821
1503.05	-1.27527
1504.11	-2.27093
1505.17	-1.24137
1506.22	1.78633
1507.28	-0.208979
1508.34	2.83163
1509.39	0.833603
1510.45	0.85261
1511.5	-2.16819
1512.56	1.83867
1513.61	-0.175117
1514.67	0.853544
1515.72	-3.16318
1516.78	3.85654
1517.83	1.85992
1518.88	-0.127888
1519.94	3.90049
1520.99	0.898434
1522.05	-1.09561
1523.1	-0.0903015
1524.15	3.90695
1525.2	-0.0996494
1526.26	0.916286
1527.31	0.932217
1528.36	2.93596
1529.41	-1.07205
1530.47	-1.0713
1531.52	-0.0545444
1532.57	0.949089
1533.62	-2.03765
1534.67	0.977158
1535.72	-2.03603
1536.77	0.950415
1537.82	-1.06674
1538.87	0.924643
1539.92	-2.05202
1540.97	-0.0223637
1542.02	0.969742
1543.07	5.95828
1544.12	-0.0678177
1545.17	-1.05935
1546.22	-1.04586
1547.27	-1.04428
1548.32	-2.05555
1549.37	-0.0647316
1550.42	-2.06403
1551.46	1.99082
1552.51	0.983971
1553.56	1.97078
1554.61	0.950745
1555.65	4.93798
1556.7	-1.07823
1557.75	-3.08433
1558.79	0.903746
1559.84	-0.121136
1560.89	-0.135017
1561.93	-1.13749
1562.98	2.865
1564.02	-1.1447
1565.07	0.862366
1566.11	-0.243162
1567.16	1.81513
1568.2	2.82171
1569.25	3.81879
1570.29	-1.1957
1571.34	-3.20255
1572.38	0.779079
1573.43	1.75881
1574.47	2.74693
1575.51	1.75807
1576.56	-2.24497
1577.6	1.72214
1578.64	-0.301527
1579.69	-1.30837
1580.73	0.6817
1581.77	0.664984
1582.81	0.64625
1583.85	-1.35829
1584.9	-1.36673
1585.94	0.615294
1586.98	1.5882
1588.02	-1.4128
1589.06	-0.421642
1590.1	0.570692
1591.14	2.55799
1592.18	3.5402
1593.22	-1.46208
1594.26	-1.49355
1595.3	0.486837
1596.34	0.471395
1597.38	1.45715
1598.42	-0.538166
1599.46	-1.55449
1600.5	-1.57425
1601.54	0.38138
1602.58	0.354828
1603.62	2.30848
1604.66	2.29497
1605.69	2.28758
1606.73	0.30858
1607.77	0.315798
1608.81	2.14252
1609.84	0.897541
1610.88	1.12229
1611.92	-1.19953
1612.95	-0.9031
1613.99	-2.2329
1615.03	-1.47067
1616.06	0.361286
1617.1	-1.00481
1618.13	0.0959415
1619.17	0.584394
1620.2	2.20934
1621.24	0.403103
1622.27	0.120417
1623.31	-1.68475
1624.34	0.65007
1625.38	-0.268734
1626.41	0.0451069
1627.45	0.772186
1628.48	0.0708561
1629.51	-2.1718
1630.55	0.241943
1631.53	-2.08165
1632.57	-1.09574
1633.62	-1.10322
1634.66	0.865932
1635.71	-2.09809
1636.75	0.845579
1637.8	-2.12367
1638.84	2.78833
1639.89	-0.169746
1640.93	-0.171824
1641.98	-0.176552
1643.02	-1.16887
1644.06	0.79262
1645.11	-2.17039
1646.15	0.782297
1647.19	1.75544
1648.24	3.71271
1649.28	-0.209278
1650.32	1.75569
1651.37	-2.17128
1652.41	1.77056
1653.45	0.778435
1654.49	-1.19109
1655.53	-1.18647
1656.57	-0.18519
1657.62	-1.17364
1658.66	-1.1808
1659.7	-1.19126
1660.74	-3.1668
1661.78	-2.17125
1662.82	-1.16762
1663.86	-0.178293
1664.9	-0.189745
1665.94	0.774469
1666.98	2.7717
1668.02	-1.186
1669.06	-0.195368
1670.1	-0.182577
1671.14	0.819206
1672.18	-1.1597
1673.21	-0.168243
1674.25	0.826004
1675.29	-0.151554
1676.33	0.843861
1677.37	1.83737
1678.4	-2.12644
1679.44	0.832167
1680.48	0.828335
1681.52	0.825089
1682.55	-1.14817
1683.59	1.81759
1684.63	-1.14657
1685.66	1.81632
1686.7	-0.153172
1687.73	-0.145159
1688.77	-2.12315
1689.81	-3.11593
1690.84	-0.155605
1691.88	-0.144854
1692.91	-2.11551
1693.95	1.81816
1694.98	3.77938
1696.01	-0.152979
1697.05	3.79922
1698.08	-0.150448
1699.12	-1.14008
1700.15	-3.10282
1701.18	0.834745
1702.22	-1.13449
1703.25	0.827555
1704.28	-1.13518
1705.32	1.82247
1706.35	-2.10452
1707.38	1.81462
1708.41	-2.12043
1709.44	-2.13106
1710.48	-1.14798
1711.51	-2.11445
1712.54	-0.147196
1713.57	2.76929
1714.6	-1.15061
1715.63	1.78789
1716.66	-2.11184
1717.69	2.75615
1718.72	1.75875
1719.75	-2.13434
1720.78	1.76784
1721.81	1.7606
1722.84	2.72304
1723.87	3.68864
1724.9	-0.191826
1725.93	0.763975
1726.96	0.76663
1727.99	-4.07314
1729.02	-0.221066
1730.05	0.737679
1731.07	0.736914
1732.1	-0.199799
1733.13	-4.06127
1734.16	1.72049
1735.18	1.70726
1736.21	-0.225639
1737.24	0.738743
1738.26	0.738552
1739.29	-1.188
1740.32	1.67644
1741.34	1.66548
1742.37	0.705441
1743.4	2.62459
1744.42	2.62507
1745.45	-1.19486
1746.47	0.721809
1747.5	-2.15172
1748.52	1.66812
1749.55	1.68246
1750.57	3.61845
1751.6	1.72527
1752.62	0.763348
1753.64	-1.14953
1754.67	0.756144
1755.69	1.71031
1756.71	0.752306
1757.74	-2.10891
1758.76	1.71188
1759.78	0.772198
1760.81	1.72909
1761.83	-3.02627
1762.85	-0.165037
1763.87	1.74862
1764.89	2.72373
1765.92	3.69429
1766.94	2.75089
1767.96	2.75511
1768.98	2.757
1770	2.73263
1771.02	2.75246
1772.04	1.82693
1773.06	4.70134
1774.08	4.72017
1775.1	1.87993
1776.12	1.90685
1777.14	0.963058
1778.16	3.81944
1779.18	0.00503349
1780.2	1.91481
1781.22	0.0260296
1782.24	0.0398102
1783.26	-0.893432
1784.28	3.89048
1785.29	2.00459
1786.31	2.9626
1787.33	2.02599
1788.35	0.156206
1789.37	2.10355
1790.38	2.128
1791.4	-1.69966
1792.42	2.12823
1793.43	-0.732025
1794.45	5.98667
1795.47	0.259503
1796.48	1.24551
1797.5	-0.655434
1798.51	0.321196
1799.53	1.28855
1800.55	0.323577
1801.56	-0.63453
1802.58	3.21842
1803.59	-1.56809
1804.61	4.21638
1805.62	2.31468
1806.64	-0.554832
1807.65	0.4195
1808.66	-3.42871
1809.68	1.39931
1810.69	0.443461
1811.7	2.37532
1812.72	-0.508707
1813.73	1.43439
1814.74	-0.47577
1815.76	0.507647
1816.77	0.516466
1817.78	1.47802
1818.79	1.48579
1819.8	0.529189
1820.82	4.4095
1821.83	-0.413577
1822.84	1.53315
1823.85	0.569435
1824.86	1.54224
1825.87	0.584085
1826.88	-0.379612
1827.89	-0.37152
1828.9	-0.368543
1829.91	-2.30695
1830.92	1.56346
1831.93	2.54167
1832.94	2.55539
1833.95	-1.31438
1834.96	-0.352556
1835.97	6.39775
1836.98	1.62646
1837.99	1.57466
1839	0.607562
1840	2.56977
1841.01	0.601628
1842.02	1.53922
1843.03	0.561308
1844.04	-0.402137
1845.04	0.564054
1846.05	3.46459
1847.06	-0.379776
1848.07	-1.39347
1849.07	-0.427562
1850.08	0.523292
1851.09	-1.41796
1852.09	0.493405
1853.1	1.45257
1854.1	-1.43404
1855.11	0.46858
1856.11	1.41066
1857.12	-0.508189
1858.12	1.40026
1859.13	-1.48459
1860.13	2.32853
1861.14	-0.534396
1862.14	0.429358
1863.15	-1.49531
1864.15	-2.46482
1865.15	-0.566722
1866.16	-0.587624
1867.16	-1.56678
1868.16	-1.58649
1869.17	2.21242
1870.17	-0.6449
1871.17	2.2012
1872.17	-0.658252
1873.18	1.22882
1874.18	3.11732
1875.18	2.14894
1876.18	1.17302
1877.18	0.206197
1878.18	1.12475
1879.19	0.202694
1880.19	0.211617
1881.19	0.206015
1882.19	-0.766202
1883.19	-1.74447
1884.19	-1.76331
1885.19	-0.817554
1886.19	-1.74712
1887.19	2.96665
1888.19	1.05828
1889.19	1.97325
1890.19	-0.865139
1891.19	-2.74454
1892.18	-0.868709
1893.18	1.0025
1894.18	0.972236
1895.18	0.0201473
1896.18	1.89961
1897.18	0.965595
1898.17	-1.85723
1899.17	2.83008
1900.17	-0.0063448
1901.16	0.927237
1902.16	-0.00568485
1903.16	-0.00533676
1904.16	-1.89737
1905.15	-2.84551
1906.15	-0.0370712
1907.14	-0.992924
1908.14	2.76001
1909.14	-0.996441
1910.13	0.892084
1911.13	-0.0354137
1912.12	-1.92084
1913.12	0.896408
1914.11	-0.0440054
1915.11	-0.978092
1916.1	-0.0350609
1917.1	2.78062
1918.09	-1.00538
1919.08	-2.88864
1920.08	-0.0429392
1921.07	1.84359
1922.06	2.79739
1923.06	-0.0480766
1924.05	0.884369
1925.04	-1.01933
1926.04	-0.0700474
1927.03	-0.0586042
1928.02	0.892125
1929.01	0.893034
1930	1.84889
1931	0.912268
1931.99	-0.0448618
1932.98	2.78629
1933.97	0.88554
1934.96	0.927524
1935.95	-1.90337
1936.94	-0.0168829
1937.93	1.86757
1938.92	-1.94744
1939.91	0.912318
1940.9	1.87134
1941.89	-0.026638
1942.88	2.83818
1943.87	2.82168
1944.86	-0.989717
1945.85	-0.0252581
1946.84	-1.93295
1947.83	-0.0281153
1948.82	-0.0355186
1949.8	0.926047
1950.79	1.90233
1951.78	0.964842
1952.77	-1.90789
1953.76	0.00976372
1954.74	-0.987351
1955.73	-1.00003
1956.72	0.939718
1957.7	1.9115
1958.69	0.954746
1959.68	2.86639
1960.66	0.931704
1961.65	-2.92329
1962.63	-1.00778
1963.62	2.83018
1964.61	-0.0487537
1965.59	-1.97496
1966.58	-0.0499783
1967.56	1.87615
1968.55	2.83707
1969.53	-0.0592251
1970.52	1.83943
1971.5	0.866385
1972.48	0.863008
1973.47	-0.102837
1974.45	2.75977
1975.44	0.841232
1976.42	4.68373
1977.4	-0.113399
1978.39	0.834892
1979.37	-0.131224
1980.35	0.826557
1981.33	2.73167
1982.31	-0.150272
1983.3	3.66713
1984.28	0.782322
1985.26	2.68534
1986.24	0.766256
1987.22	3.63941
1988.21	-0.197973
1989.19	5.44644
1990.17	5.56831
1991.15	3.31552
1992.13	3.61991
1993.11	2.50186
1994.09	3.41468
1995.07	1.51218
1996.05	4.04482
1997.03	3.11996
1998.01	2.26215
1998.99	3.66574
1999.97	2.4891
2000.95	3.22438
2001.92	5.43616
2002.9	3.99932
2003.88	5.56544
2004.86	2.24225
2005.84	5.70366
2006.81	4.07867
2007.79	3.25592
2008.77	3.83112
2009.75	1.62597
2010.73	4.75306
2011.7	4.58257
2012.68	6.47004
2013.67	3.6259
2014.66	3.59715
2015.64	4.5308
2016.63	1.726
2017.62	5.5001
2018.61	3.59822
2019.6	3.57292
2020.58	1.69529
2021.57	7.31993
2022.56	1.69956
2023.55	3.55879
2024.54	2.61222
2025.52	3.52614
2026.51	1.64986
2027.5	1.70117
2028.48	2.62038
2029.47	-1.08719
2030.45	-0.193461
2031.44	3.55218
2032.43	0.761624
2033.41	-1.07998
2034.4	-0.137019
2035.38	0.778891
2036.37	0.821344
2037.35	6.43374
2038.34	1.76062
2039.32	1.75698
2040.31	0.816051
2041.29	1.73979
2042.27	2.67164
2043.26	-1.05491
2044.24	2.70164
2045.23	3.63129
2046.21	0.877079
2047.19	0.870224
2048.17	-0.074317
2049.16	-0.993871
2050.14	3.69921
2051.12	1.85476
2052.11	0.920312
2053.09	0.935345
2054.07	0.0279732
2055.05	-0.892541
2056.03	-0.889722
2057.01	0.0502872
2058	0.0642281
2058.98	1.02243
2059.96	-1.7677
2060.94	1.98118
2061.92	1.06283
2062.9	0.141055
2063.88	-1.71245
2064.86	2.05398
2065.84	0.205282
2066.82	-0.712701
2067.8	-0.694804
2068.78	2.14345
2069.76	-0.668761
2070.73	0.281153
2071.71	2.18377
2072.69	3.1622
2073.67	-0.59493
2074.65	-1.5209
2075.63	2.28027
2076.6	0.424061
2077.58	0.428508
2078.56	-0.506166
2079.54	-0.485353
2080.51	-1.40268
2081.49	-0.445603
2082.47	2.40167
2083.45	-1.3631
2084.42	-1.3512
2085.4	0.552338
2086.37	3.40655
2087.35	-0.350262
2088.32	-1.2793
2089.3	-0.317193
2090.28	-0.293777
2091.25	-1.22325
2092.23	-2.14762
2093.2	-1.16836
2094.18	-1.14162
2095.15	-1.12551
2096.13	0.780288
2097.1	0.789444
2098.07	-3.00434
2099.05	-2.99391
2100.02	-3.93129
2101	-1.0681
2101.97	0.853796
2102.94	-0.0837078
2103.92	-1.97635
2104.89	-1.0108
2105.86	2.813
2106.83	0.933398
2107.8	-2.85496
2108.78	-0.954083
2109.75	-0.940613
2110.72	0.975753
2111.69	-1.86187
2112.66	1.94601
2113.63	1.01872
2114.61	1.03446
2115.58	1.99799
2116.55	2.0036
2117.52	1.06078
2118.49	-0.830678
2119.46	-0.831586
2120.43	-0.829021
2121.4	1.0828
2122.37	1.10995
2123.34	0.18285
2124.31	1.14378
2125.28	-0.760199
2126.25	0.179749
2127.21	0.17886
2128.18	0.185172
2129.15	-0.750168
2130.12	-1.68626
2131.09	-0.733016
2132.06	-0.728872
2133.02	0.218551
2133.99	1.17363
2134.96	0.242582
2135.93	-2.57955
2136.89	-0.693737
2137.86	1.20643
2138.83	2.15467
2139.79	-0.658512
2140.76	0.283028
2141.73	-0.65157
2142.69	-0.647872
2143.66	1.25759
2144.62	-0.64323
2145.59	-1.57234
2146.55	0.315751
2147.52	0.319953
2148.48	0.322865
2149.45	-0.614904
2150.42	0.316403
2151.38	4.07188
2152.34	1.27696
2153.31	-1.53157
2154.27	-0.592003
2155.24	-1.53819
2156.2	3.12602
2157.16	1.25998
2158.13	1.27472
2159.09	1.28541
2160.05	1.28451
2161.01	0.344917
2161.98	2.21342
2162.94	0.354346
2163.9	0.35544
2164.86	1.28421
2165.83	1.29115
2166.79	1.29496
2167.75	-0.571633
2168.71	1.27532
2169.67	0.357433
2170.63	2.24417
2171.59	-1.4781
2172.56	0.365362
2173.51	0.365835
2174.48	2.23409
2175.44	-0.548254
2176.4	0.383053
2177.36	-0.545367
2178.32	-2.39781
2179.28	-1.47183
2180.23	-0.538164
2181.19	0.392084
2182.15	0.391324
2183.11	-0.538066
2184.07	0.379786
2185.03	0.378556
2185.99	-0.539727
2186.95	-0.525694
2187.9	1.34967
2188.86	-2.36765
2189.82	0.404505
2190.78	0.400539
2191.73	0.405931
2192.69	3.1955
2193.65	0.42324
2194.6	-0.483451
2195.56	-0.483412
2196.52	-1.42443
2197.47	0.420074
2198.43	0.420785
2199.38	2.2954
2200.34	6.03986
2201.3	0.484472
2202.25	3.22219
2203.21	2.3218
2204.16	2.38081
2205.12	2.35038
2206.07	3.24017
2207.03	1.37871
2207.98	1.38718
2208.93	2.32977
2209.89	0.471187
2210.84	2.33707
2211.8	2.3462
2212.75	-2.30888
2213.7	0.48167
2214.66	-0.446115
2215.61	0.494182
2216.56	-0.440822
2217.51	0.488765
2218.47	-0.446413
2219.42	2.35952
2220.37	-0.43846
2221.32	2.35911
2222.27	-0.459826
2223.23	0.471492
2224.18	-0.453895
2225.13	2.36381
2226.08	0.503498
2227.03	0.511539
2227.98	-0.422004
2228.93	-0.429191
2229.88	-0.432327
2230.83	0.514146
2231.78	2.40189
2232.73	3.35094
2233.68	-0.403748
2234.63	0.538464
2235.58	2.40436
2236.53	-1.36424
2237.48	1.45866
2238.43	1.4759
2239.38	-2.28333
2240.33	-1.35031
2241.27	-0.406008
2242.22	2.42401
2243.17	0.536758
2244.12	-1.36148
2245.07	0.527614
2246.01	0.540391
2246.96	-1.34652
2247.91	-0.399326
2248.85	1.4856
2249.8	-0.411816
2250.75	-1.36597
2251.69	-1.38102
2252.64	1.45422
2253.59	-0.422357
2254.53	-0.414796
2255.48	-1.36655
2256.42	-0.419876
2257.37	-0.415273
2258.32	0.536075
2259.26	0.536312
2260.2	-0.412366
2261.15	-0.410945
2262.1	1.49614
2263.04	0.547637
2263.98	-2.29951
2264.93	-2.28725
2265.87	-0.37353
2266.81	-0.384941
2267.76	-0.400325
2268.7	-0.413239
2269.65	0.545621
2270.59	1.51539
2271.53	-0.389466
2272.47	-0.385661
2273.42	-2.30078
2274.36	0.569123
2275.3	-1.34589
2276.24	-2.30406
2277.18	2.49576
2278.13	-0.364615
2279.07	1.56233
2280.01	-1.33189
2280.95	-1.34797
2281.89	-1.35708
2282.83	0.564792
2283.77	-1.34092
2284.71	0.60113
2285.65	-2.27861
2286.59	-0.364643
2287.54	-2.27722
2288.47	-1.3104
2289.41	2.52783
2290.35	-2.30272
2291.29	-0.380589
2292.23	0.594423
2293.17	3.49547
2294.11	2.53934
2295.05	2.52906
2295.99	-1.33283
2296.93	-3.26865
2297.86	1.55113
2298.8	1.56633
2299.74	0.614958
2300.68	0.615528
2301.61	2.55362
2302.55	1.58782
2303.49	-1.3094
2304.43	-3.23654
2305.36	-0.331726
2306.3	-2.25893
2307.24	0.643198
2308.17	0.638741
2309.11	1.60345
2310.04	0.651325
2310.98	1.62414
2311.92	-2.26367
2312.85	0.620783
2313.79	-0.339482
2314.72	1.61275
2315.66	-0.310681
2316.59	0.638344
2317.52	1.59897
2318.46	-1.29483
2319.39	-0.336883
2320.33	2.55421
2321.26	-0.335868
2322.2	1.60924
2323.13	0.653546
2324.06	2.59202
2325	7.42102
2325.93	10.2945
2326.86	23.7821
2327.79	89.3082
2328.73	22.7798
2329.66	10.234
2330.59	2.52644
2331.52	-0.365529
2332.46	-0.362141
2333.39	-0.371629
2334.32	-1.34168
2335.25	-1.352
2336.18	1.53176
2337.11	0.564346
2338.04	2.48143
2338.97	-1.3691
2339.91	0.550502
2340.84	-0.421885
2341.77	1.47625
2342.7	1.45918
2343.63	2.40993
2344.56	0.487119
2345.49	0.478563
2346.41	1.41767
2347.34	-2.42384
2348.27	1.39787
2349.2	1.3908
2350.13	0.400959
2351.06	-0.631691
2351.99	-0.587115
2352.91	0.333816
2353.84	-0.653302
2354.77	0.286014
2355.7	-1.63345
2356.63	-0.70641
2357.55	0.210451
2358.48	0.184069
2359.41	-0.792044
2360.33	0.129041
2361.26	1.04205
2362.19	-0.892076
2363.11	0.0165854
2364.04	-0.963823
2364.97	1.83788