File: Data/3-Raman/processed/bu19w-d-ff2-fi10-v_1800 (450-850nm)_532nm_edge_100%_x100_vis_lwd_h50um_30sx2_01.txt
#Acq. time (s)=	30
#Accumulations=	2
#Range (cm-¹)=	1200...2365
#Windows=	3
#Auto scanning=	Off
#Autofocus=	Off
#Macrospot=	Off
#AutoExposure=	Off
#Spike filter=	Multiple accum.
#Delay time (s)=	2
#Binning=	1
#Readout mode=	Signal
#DeNoise=	Off
#ICS correction=	On
#Dark correction=	Off
#Inst. Process=	Off
#Detector Gain=	Best Dynamic
#Detector ADC=	50 kHz HS
#Detector temperature (°C)=	-60.09
#Instrument=	LabRAM HR Evol
#Detector=	SIN-EM FIVIS
#Objective=	x100_VIS_LWD
#Grating=	1800 (450-850nm)
#ND Filter=	100%
#Laser=	532nm_Edge
#Hole=	49.98
#Temperature=	0
#Range=	Visible
#StageXY=	75x50mm Scan+
#StageZ=	Z motor
#X (µm)=	0
#Y (µm)=	0
#Z (µm)=	64.1
#Full time(mm:ss)=	3:19
#Project=	21_11_22
#Sample=	BU19w
#Site=
#Title=	BU19w-D-FF2-FI10-V_1800 (450-850nm)_532nm_Edge_100%_x100_VIS_LWD_H50um_30sX2
#Remark=
#Date=	22.11.2021 13:57
#Acquired=	22.11.2021 13:57:50
#Base:Fit=	16.12.2021 17:39:50
#Base:Fit=	16.12.2021 17:41:01
#Base:Sub=	16.12.2021 17:41:02
1202.84	3.62702
1203.95	2.57444
1205.06	-6.99276
1206.17	4.84881
1207.29	0.672619
1208.39	-0.355946
1209.51	2.8865
1210.62	-2.37276
1211.72	-0.131741
1212.84	1.04173
1213.94	1.07442
1215.05	4.30835
1216.16	7.56511
1217.27	-1.89853
1218.38	2.43543
1219.49	0.351192
1220.6	-2.81861
1221.71	1.44889
1222.81	0.499405
1223.92	3.76206
1225.03	0.574318
1226.14	-2.61275
1227.24	6.06758
1228.35	4.94516
1229.46	8.19238
1230.56	18.783
1231.67	27.3167
1232.78	30.609
1233.88	36.9993
1234.99	31.7344
1236.09	25.4373
1237.2	15.025
1238.3	15.1305
1239.41	3.67504
1240.51	3.79301
1241.62	7.03551
1242.72	10.2224
1243.83	8.18773
1244.93	9.31946
1246.03	9.38071
1247.14	15.754
1248.24	19.9727
1249.34	20.0188
1250.45	20.0663
1251.55	29.6008
1252.65	24.4951
1253.75	23.5667
1254.86	21.5618
1255.96	11.1867
1257.06	14.4642
1258.16	10.3171
1259.26	14.721
1260.36	8.39355
1261.46	9.75103
1262.56	9.7895
1263.66	13.025
1264.76	10.0529
1265.86	6.05056
1266.96	3.01543
1268.06	6.20765
1269.16	14.6886
1270.26	14.8728
1271.36	7.70086
1272.46	6.76539
1273.56	9.01533
1274.66	8.12052
1275.76	8.28214
1276.85	15.7664
1277.95	8.50923
1279.05	8.65904
1280.15	8.74849
1281.24	20.3468
1282.34	24.8216
1283.44	110.224
1284.53	128.162
1285.63	16.6681
1286.73	13.6573
1287.82	11.6808
1288.92	8.62463
1290.01	2.41322
1291.11	2.58487
1292.21	-2.56391
1293.3	0.817081
1294.4	-4.35957
1295.49	5.2292
1296.58	4.25911
1297.68	-5.11683
1298.77	3.44881
1299.87	-1.70549
1300.96	-7.94674
1302.05	0.608559
1303.15	-1.43066
1304.24	-5.54766
1305.33	4.06142
1306.42	-3.19759
1307.52	-0.966839
1308.61	2.31831
1309.7	0.342758
1310.79	1.4958
1311.88	-1.55609
1312.98	2.80421
1314.07	1.85219
1315.16	-2.24716
1316.25	-0.0204697
1317.34	1.14762
1318.43	0.170837
1319.52	-2.92622
1320.61	2.43957
1321.7	-0.610565
1322.79	-3.69033
1323.88	-0.498184
1324.97	-2.41974
1326.06	3.01972
1327.15	1.01083
1328.23	2.13461
1329.32	0.0679169
1330.41	2.2173
1331.5	7.5202
1332.59	-0.810783
1333.67	0.315571
1334.76	-1.69337
1335.85	5.70843
1336.94	4.76218
1338.02	-0.366085
1339.11	1.81441
1340.2	3.96802
1341.28	0.927166
1342.37	2.05373
1343.45	1.04702
1344.54	-4.12193
1345.63	6.37991
1346.71	1.23592
1347.8	3.38035
1348.88	6.5613
1349.96	1.48566
1351.05	3.71761
1352.13	2.65887
1353.22	4.82643
1354.3	1.77983
1355.39	4.95813
1356.47	-0.169453
1357.55	5.06236
1358.63	4.10072
1359.72	7.27925
1360.8	4.27649
1361.88	2.29151
1362.97	5.4451
1364.05	1.34486
1365.13	7.6287
1366.21	6.69276
1367.29	11.9321
1368.37	15.0684
1369.45	20.2242
1370.54	13.047
1371.62	12.0789
1372.7	15.2463
1373.78	13.2404
1374.86	21.529
1375.94	28.9265
1377.02	32.0591
1378.09	36.0914
1379.18	42.2527
1380.25	59.6438
1381.33	60.6793
1382.41	67.0004
1383.49	59.9711
1384.57	63.889
1385.65	63.9744
1386.72	184.418
1387.8	247.73
1388.88	46.7388
1389.96	28.3052
1391.03	21.1773
1392.11	13.0473
1393.19	12.1015
1394.26	14.1808
1395.34	10.1344
1396.42	9.18876
1397.49	7.21473
1398.57	11.3883
1399.64	6.39011
1400.72	9.56905
1401.79	13.6902
1402.87	3.45393
1403.94	9.64025
1405.02	12.7793
1406.09	7.71439
1407.17	6.74728
1408.24	25.1932
1409.31	24.1993
1410.39	6.95394
1411.46	4.88522
1412.53	7.0029
1413.61	1.92294
1414.68	8.14672
1415.75	6.13903
1416.82	2.05644
1417.9	2.06033
1418.97	3.12328
1420.04	0.157635
1421.11	6.22158
1422.18	2.14554
1423.26	3.21982
1424.33	3.20943
1425.4	4.22222
1426.47	2.21463
1427.54	-1.82221
1428.61	2.35753
1429.68	5.43883
1430.75	2.32602
1431.82	4.41224
1432.89	3.41067
1433.96	7.51755
1435.02	2.40593
1436.09	4.4891
1437.16	4.53947
1438.23	2.51949
1439.3	9.71011
1440.37	1.52219
1441.43	3.57896
1442.5	2.60206
1443.57	1.57708
1444.64	-0.475018
1445.7	3.65094
1446.77	-2.49606
1447.84	1.59707
1448.9	-0.456352
1449.97	-0.449429
1451.04	1.61496
1452.1	3.66907
1453.17	3.68545
1454.23	4.69922
1455.3	0.599586
1456.36	2.65988
1457.43	1.63363
1458.49	-0.428917
1459.56	0.570621
1460.62	2.58223
1461.69	4.67429
1462.75	-3.61414
1463.81	0.455177
1464.88	1.46675
1465.94	3.49947
1467	-0.607082
1468.07	2.42646
1469.13	-4.72734
1470.19	-1.68288
1471.25	-1.70583
1472.32	-0.687443
1473.38	-1.7242
1474.44	1.30193
1475.5	2.29696
1476.56	0.230564
1477.62	4.24061
1478.68	5.22976
1479.75	2.20536
1480.81	0.172615
1481.87	-5.9961
1482.93	4.11079
1483.99	4.10582
1485.05	-0.990788
1486.11	-2.04556
1487.17	2.98991
1488.22	1.94374
1489.28	10.0144
1490.34	2.91821
1491.4	-4.17402
1492.46	-1.17049
1493.52	4.83493
1494.58	-0.239086
1495.63	-1.2662
1496.69	-2.28325
1497.75	0.732082
1498.81	4.73645
1499.86	-5.38453
1500.92	2.64719
1501.98	2.63423
1503.03	0.56432
1504.09	-0.458115
1505.15	1.53925
1506.2	1.52122
1507.26	0.501278
1508.31	0.447193
1509.37	5.37693
1510.42	-4.73096
1511.48	0.2939
1512.53	5.25913
1513.59	0.184616
1514.64	0.158329
1515.7	-2.85598
1516.75	-4.87281
1517.8	-2.89112
1518.86	-1.90136
1519.91	1.07124
1520.96	-3.00182
1522.02	-0.0342979
1523.07	2.96673
1524.12	-2.04308
1525.17	-1.07578
1526.23	0.892559
1527.28	-4.14685
1528.33	3.8716
1529.38	1.84048
1530.43	-1.14564
1531.48	4.85854
1532.53	-3.20327
1533.59	4.73656
1534.64	-6.3345
1535.69	2.6217
1536.74	4.66466
1537.79	-1.29931
1538.84	-4.34929
1539.89	1.60276
1540.94	4.53571
1541.98	-3.46243
1543.03	7.57037
1544.08	-0.453823
1545.13	2.51058
1546.18	1.46748
1547.23	-1.54404
1548.28	4.57372
1549.33	-0.4645
1550.37	1.49533
1551.42	4.45449
1552.47	7.40193
1553.52	-2.63665
1554.56	0.356503
1555.61	6.31282
1556.65	1.24356
1557.7	3.20415
1558.75	5.19386
1559.79	2.20108
1560.84	2.17613
1561.88	0.192566
1562.93	1.92122
1563.98	2.0826
1565.02	5.09902
1566.07	5.09496
1567.11	2.05918
1568.15	3.04286
1569.2	3.00883
1570.24	-3.02113
1571.29	4.94655
1572.33	4.97661
1573.37	3.97081
1574.42	2.90854
1575.46	-1.14151
1576.5	4.82528
1577.55	5.82408
1578.59	7.78594
1579.63	4.75932
1580.67	2.74798
1581.72	7.72023
1582.76	4.71989
1583.8	8.65766
1584.84	4.65038
1585.88	8.63824
1586.92	4.66592
1587.96	6.66268
1589	4.65406
1590.04	4.6053
1591.08	5.52743
1592.12	3.5422
1593.16	8.48743
1594.2	8.48735
1595.24	4.51136
1596.28	9.42976
1597.32	10.3838
1598.36	11.316
1599.4	4.33239
1600.44	5.27959
1601.48	8.23317
1602.51	5.26927
1603.55	13.2026
1604.59	9.2544
1605.63	10.2387
1606.66	4.26219
1607.7	5.44932
1608.74	6.38686
1609.77	5.33131
1610.81	11.9422
1611.85	6.26919
1612.88	12.7113
1613.92	15.3979
1614.95	11.9871
1615.99	14.5033
1617.03	7.79248
1618.06	11.8709
1619.1	12.7156
1620.13	14.5621
1621.17	11.126
1622.2	10.7148
1623.23	12.0637
1624.27	11.6296
1625.3	14.4324
1626.34	14.8208
1627.37	8.86048
1628.4	16.2674
1629.44	17.467
1630.47	12.2902
1631.29	15.7207
1632.33	18.6892
1633.38	20.6501
1634.42	18.658
1635.47	12.7465
1636.51	15.7106
1637.56	18.679
1638.6	16.7368
1639.65	16.7375
1640.69	17.7297
1641.73	15.7513
1642.78	14.7991
1643.82	10.8615
1644.86	7.90989
1645.91	13.852
1646.95	21.7647
1647.99	19.8619
1649.03	13.0018
1650.08	17.9368
1651.12	15.0086
1652.16	16.0312
1653.2	14.1379
1654.24	20.0918
1655.28	16.1458
1656.33	19.0957
1657.37	14.1674
1658.41	18.1714
1659.45	10.2968
1660.49	15.3499
1661.53	16.3031
1662.57	14.3064
1663.61	14.4616
1664.65	18.3293
1665.69	15.3776
1666.72	14.4739
1667.76	14.5321
1668.8	14.5539
1669.84	11.6233
1670.88	12.6467
1671.92	15.6671
1672.96	13.7369
1674	11.7905
1675.03	10.8116
1676.07	10.8044
1677.11	9.82502
1678.15	17.7401
1679.18	8.87461
1680.22	8.9017
1681.25	4.97357
1682.29	7.95341
1683.33	10.9472
1684.36	6.05634
1685.4	6.06898
1686.43	8.04492
1687.47	6.07915
1688.51	8.10254
1689.54	5.17852
1690.58	4.18653
1691.61	8.12235
1692.64	5.19995
1693.68	6.23326
1694.71	5.25361
1695.75	5.2533
1696.78	5.28081
1697.81	6.28842
1698.85	2.37113
1699.88	5.3243
1700.91	7.31257
1701.95	7.35539
1702.98	10.331
1704.01	6.397
1705.04	1.48246
1706.08	7.34323
1707.11	2.46593
1708.14	3.49191
1709.17	8.43361
1710.2	2.53957
1711.23	4.48051
1712.27	0.598766
1713.3	2.59802
1714.33	4.54399
1715.36	4.50833
1716.39	1.59953
1717.42	8.45234
1718.45	2.61531
1719.48	2.61406
1720.51	-2.23839
1721.54	1.67334
1722.56	-3.18606
1723.59	1.6771
1724.62	3.62959
1725.65	0.733177
1726.68	4.54196
1727.71	-2.18491
1728.74	-0.176792
1729.76	3.71295
1730.79	3.70408
1731.82	3.6886
1732.85	-2.094
1733.87	0.813709
1734.9	-3.97827
1735.93	6.60244
1736.95	2.74108
1737.98	3.68632
1739.01	2.73435
1740.03	4.67252
1741.06	2.77807
1742.08	-1.9804
1743.11	1.87445
1744.13	-5.76917
1745.16	0.92477
1746.18	0.965969
1747.21	1.02925
1748.23	-1.78062
1749.26	-6.5472
1750.28	0.144836
1751.31	0.154438
1752.33	0.169064
1753.35	1.12931
1754.38	-0.779438
1755.4	1.16507
1756.42	0.25378
1757.44	0.28318
1758.47	-3.50613
1759.49	2.22266
1760.51	-3.43912
1761.53	0.41777
1762.56	-5.23634
1763.58	4.31944
1764.6	1.48844
1765.62	1.5067
1766.64	-1.3709
1767.66	2.47451
1768.68	3.48865
1769.7	1.63985
1770.72	-2.11693
1771.74	0.78162
1772.76	-1.05843
1773.78	-3.87725
1774.8	2.80579
1775.82	3.76139
1776.84	-2.88811
1777.86	1.91825
1778.88	1.9598
1779.9	5.82762
1780.92	-1.74759
1781.94	0.215057
1782.95	-0.712551
1783.97	4.09776
1784.99	-0.589603
1786.01	2.37161
1787.03	0.520222
1788.04	-4.23669
1789.06	0.550911
1790.08	-1.32649
1791.09	-4.16451
1792.11	-3.16523
1793.13	4.5902
1794.14	-0.155849
1795.16	-2.03169
1796.17	-2.00252
1797.19	1.84728
1798.21	0.900391
1799.22	-0.0296745
1800.24	0.979431
1801.25	2.94612
1802.27	0.113132
1803.28	-2.72239
1804.29	1.16943
1805.31	0.232124
1806.32	-3.59457
1807.34	0.290859
1808.35	-5.47338
1809.36	-2.55566
1810.38	2.30825
1811.39	-2.46893
1812.4	0.481091
1813.41	2.44405
1814.43	-0.440418
1815.44	-3.32874
1816.45	2.50377
1817.46	-2.29348
1818.47	2.57932
1819.49	-1.25437
1820.5	2.6412
1821.51	-0.245731
1822.52	0.754822
1823.53	-4.06552
1824.54	-0.165352
1825.55	1.79516
1826.56	0.831917
1827.57	0.837826
1828.58	-1.07437
1829.59	2.83553
1830.6	3.83426
1831.61	2.8744
1832.62	3.79629
1833.63	-3.79401
1834.64	0.948841
1835.65	-0.065361
1836.65	4.88168
1837.66	0.970547
1838.67	0.918636
1839.68	-0.07547
1840.69	-3.91601
1841.7	-0.0440025
1842.7	2.86302
1843.71	1.00097
1844.72	1.84684
1845.72	1.87144
1846.73	-0.0672569
1847.74	-1.05887
1848.74	-0.112267
1849.75	-0.106133
1850.75	0.855099
1851.76	0.827568
1852.76	-2.06929
1853.77	4.63672
1854.78	3.67618
1855.78	-4.95455
1856.79	2.67716
1857.79	-0.172817
1858.79	0.811363
1859.8	0.801907
1860.8	1.73323
1861.81	0.759239
1862.81	0.726486
1863.81	-1.22829
1864.82	6.33826
1865.82	0.629375
1866.82	-0.320744
1867.83	-0.323189
1868.83	2.52233
1869.83	0.605171
1870.83	3.4411
1871.84	-0.380558
1872.84	-2.31271
1873.84	0.485569
1874.84	1.3555
1875.84	5.22592
1876.84	-0.421095
1877.84	-1.37181
1878.84	-3.30368
1879.84	1.3483
1880.84	2.30632
1881.84	-1.51442
1882.85	-2.42184
1883.85	-1.46497
1884.84	0.386818
1885.84	2.22619
1886.84	4.08039
1887.84	2.21467
1888.84	0.323669
1889.84	3.13361
1890.84	1.19098
1891.84	1.17297
1892.83	3.99495
1893.83	3.07331
1894.83	5.90437
1895.83	1.18153
1896.83	1.1513
1897.82	-2.61833
1898.82	2.09776
1899.82	0.230015
1900.81	-0.729353
1901.81	3.01929
1902.81	1.12602
1903.8	2.02832
1904.8	2.95827
1905.79	2.02808
1906.79	2.04761
1907.79	-3.56537
1908.78	-0.735136
1909.78	1.13449
1910.77	1.13494
1911.77	1.16119
1912.76	1.17042
1913.76	-0.73871
1914.75	3.94674
1915.74	-1.706
1916.74	-1.67336
1917.73	2.10307
1918.72	-1.66059
1919.72	2.11373
1920.71	-3.58463
1921.7	0.167614
1922.7	2.06175
1923.69	3.03601
1924.68	2.10434
1925.67	-0.735477
1926.66	4.01553
1927.66	6.89149
1928.65	5.93634
1929.64	-0.73946
1930.63	-4.55151
1931.62	-1.63939
1932.61	0.333103
1933.61	2.20384
1934.6	-0.694727
1935.59	2.13323
1936.58	3.09793
1937.57	2.15322
1938.56	1.2255
1939.55	3.10748
1940.54	-0.709801
1941.52	-0.714815
1942.51	1.21227
1943.5	-1.6454
1944.49	1.2083
1945.48	-0.723505
1946.47	0.232758
1947.46	0.258705
1948.44	3.17443
1949.43	-0.647633
1950.42	0.310825
1951.41	1.189
1952.39	3.05785
1953.38	2.14009
1954.37	-1.68295
1955.36	2.16428
1956.34	4.06263
1957.33	2.10835
1958.31	3.02794
1959.3	2.04868
1960.29	-1.80144
1961.27	2.99191
1962.26	-0.86607
1963.24	-3.75209
1964.23	-0.866276
1965.21	0.0827408
1966.2	-0.90604
1967.18	0.000400543
1968.17	-0.0375252
1969.15	7.61558
1970.14	-1.99491
1971.12	-0.116364
1972.1	-1.09244
1973.09	-0.133415
1974.07	-0.144867
1975.05	1.74194
1976.04	0.751881
1977.02	-2.13722
1978	0.704887
1978.98	2.59065
1979.97	-4.14397
1980.95	2.51184
1981.93	0.568901
1982.91	-2.33201
1983.89	4.35839
1984.88	1.45359
1985.86	-1.49546
1986.84	-0.624325
1987.82	-0.625507
1988.8	-0.59174
1989.78	-2.36231
1990.76	-3.06373
1991.74	0.277397
1992.72	0.799351
1993.7	4.59908
1994.68	-1.73717
1995.66	1.01031
1996.64	2.04695
1997.62	2.11975
1998.6	0.0897141
1999.57	-0.421562
2000.55	2.23792
2001.53	3.76638
2002.51	-3.05259
2003.49	1.32005
2004.47	-1.33892
2005.44	0.0405006
2006.42	2.45017
2007.4	-0.156418
2008.38	-0.0500031
2009.35	-0.237495
2010.33	0.792534
2011.3	-1.65265
2012.18	-0.534412
2013.17	3.21992
2014.16	0.424721
2015.15	2.25385
2016.14	0.310146
2017.13	-0.667873
2018.11	2.12625
2019.1	-2.57118
2020.09	3.94019
2021.08	2.02433
2022.06	1.03547
2023.05	-3.68314
2024.04	0.0925598
2025.02	-0.827663
2026.01	-2.64229
2027	-0.890823
2027.98	1.84459
2028.97	1.85152
2029.96	0.952225
2030.94	2.84609
2031.93	0.873497
2032.91	-0.00190353
2033.9	-0.0131073
2034.88	0.915779
2035.87	-1.91853
2036.85	-1.95216
2037.83	0.801369
2038.82	5.43289
2039.8	2.60536
2040.79	0.755848
2041.77	-3.90521
2042.75	-0.178955
2043.74	0.79039
2044.72	-1.14657
2045.7	3.49985
2046.69	1.6554
2047.67	1.68522
2048.65	-2.0751
2049.63	-2.07885
2050.62	-0.196018
2051.6	-0.175377
2052.58	-1.13143
2053.56	-3.95633
2054.54	1.64534
2055.52	0.725552
2056.5	-3.00329
2057.48	1.66368
2058.46	1.66426
2059.45	0.726608
2060.43	-3.94477
2061.4	1.68496
2062.39	-0.17028
2063.37	-3.90308
2064.34	4.55497
2065.32	-2.94918
2066.3	-1.07198
2067.28	-0.166306
2068.26	5.51929
2069.24	5.56008
2070.22	2.72174
2071.2	-3.87198
2072.18	-0.0809021
2073.15	-4.75324
2074.13	1.84236
2075.11	2.75466
2076.09	0.882744
2077.06	0.916405
2078.04	-0.0246086
2079.02	4.68953
2080	4.69512
2080.97	-4.76183
2081.95	0.905998
2082.93	3.73988
2083.9	-0.95808
2084.88	0.944923
2085.85	0.946888
2086.83	-3.7699
2087.8	-2.81492
2088.78	-1.8516
2089.75	1.03508
2090.73	-0.831055
2091.7	2.03524
2092.68	1.0668
2093.65	2.9516
2094.63	1.03037
2095.6	-0.881325
2096.57	1.01139
2097.55	-1.83445
2098.52	0.0856934
2099.5	-1.81265
2100.47	1.96658
2101.44	3.865
2102.41	-1.81129
2103.39	-0.839939
2104.36	-0.831917
2105.33	1.04123
2106.3	1.97154
2107.27	1.9897
2108.25	0.090168
2109.22	-2.77033
2110.19	1.03976
2111.16	0.108669
2112.13	3.90992
2113.1	0.0997543
2114.07	1.03251
2115.04	-0.873184
2116.01	3.83981
2116.99	0.967831
2117.96	0.968826
2118.92	1.94708
2119.9	-1.8219
2120.86	-0.86404
2121.83	2.90273
2122.8	0.00629425
2123.77	2.81399
2124.74	-0.0405617
2125.71	-0.990276
2126.68	1.84273
2127.65	4.67304
2128.61	0.879227
2129.58	0.864311
2130.55	-5.74675
2131.52	0.867657
2132.48	4.64221
2133.45	5.55636
2134.42	-1.98381
2135.39	1.79196
2136.35	3.70095
2137.32	-0.106754
2138.28	3.65214
2139.25	-1.06782
2140.22	1.80045
2141.18	-0.168034
2142.15	-0.149075
2143.12	-4.84587
2144.08	3.60875
2145.05	-7.67622
2146.01	-3.92775
2146.98	-0.202148
2147.94	-1.15364
2148.9	3.55881
2149.87	-0.187229
2150.83	-2.07233
2151.8	1.64248
2152.76	-1.20667
2153.72	-3.08747
2154.69	4.40038
2155.65	2.55417
2156.61	-1.19004
2157.58	-5.87919
2158.54	0.647591
2159.5	-0.281712
2160.47	3.44597
2161.43	-2.15768
2162.39	-1.22677
2163.35	-1.21983
2164.31	-0.299168
2165.27	-1.26786
2166.24	1.53021
2167.2	2.51324
2168.16	0.664398
2169.12	3.40978
2170.08	4.32858
2171.04	2.48651
2172	3.43205
2172.96	-0.280941
2173.92	4.36243
2174.88	-1.19939
2175.84	-4.91903
2176.8	-2.12104
2177.76	1.60098
2178.72	1.6031
2179.68	1.60088
2180.64	1.58494
2181.59	-0.27636
2182.55	2.52563
2183.51	-2.07587
2184.47	1.68771
2185.43	4.48716
2186.38	4.46536
2187.34	0.74025
2188.3	2.61454
2189.26	-1.07022
2190.21	4.52792
2191.17	-2.84275
2192.13	-0.958508
2193.08	-3.75474
2194.04	6.43265
2195	0.870502
2195.95	4.62913
2196.91	1.90479
2197.86	1.05539
2198.82	1.97391
2199.78	2.87298
2200.73	2.92372
2201.69	2.09322
2202.64	1.07577
2203.59	2.95763
2204.55	1.11383
2205.5	3.02135
2206.46	5.85069
2207.41	4.94215
2208.37	3.11933
2209.32	3.16447
2210.27	1.31098
2211.23	3.19101
2212.18	-1.42144
2213.13	5.13761
2214.09	-3.25016
2215.04	3.30705
2215.99	-3.20136
2216.94	2.44322
2217.9	3.39806
2218.85	1.52098
2219.8	4.33216
2220.75	-3.09488
2221.7	1.63637
2222.65	1.69094
2223.6	-4.81861
2224.55	0.848518
2225.5	-2.8833
2226.46	2.75837
2227.41	3.7492
2228.36	0.0462952
2229.31	-1.78322
2230.26	-0.796015
2231.21	-1.69373
2232.16	4.90345
2233.11	1.14523
2234.05	3.05782
2235	2.1847
2235.95	1.3095
2236.9	5.11539
2237.85	2.30248
2238.8	-0.481077
2239.75	-3.27483
2240.69	-2.31318
2241.64	-0.39679
2242.59	0.616863
2243.54	-0.275951
2244.48	1.66071
2245.43	0.739655
2246.38	-1.13162
2247.32	3.63376
2248.27	-2.04038
2249.22	-1.06766
2250.16	-3.84128
2251.11	2.85464
2252.06	0.0494595
2253	0.0839691
2253.95	0.136721
2254.89	-0.762613
2255.84	-0.723206
2256.78	-0.676947
2257.73	2.22006
2258.67	-3.43142
2259.62	-2.43675
2260.56	-3.32738
2261.51	-0.389843
2262.45	5.40348
2263.39	0.654558
2264.34	-2.20196
2265.28	0.672461
2266.22	0.717241
2267.17	1.74588
2268.11	1.80974
2269.05	3.77985
2270	4.7807
2270.94	0.0400257
2271.88	-2.78874
2272.82	-3.70481
2273.77	-0.769304
2274.71	-2.6164
2275.65	-2.54849
2276.59	-1.55767
2277.53	-0.597282
2278.47	0.382601
2279.41	1.38735
2280.36	-0.462046
2281.3	-1.33046
2282.24	0.658905
2283.18	1.6456
2284.12	-2.14238
2285.06	0.815191
2286	2.76457
2286.94	-1.08871
2287.88	-1.05399
2288.82	1.90334
2289.75	0.0442524
2290.69	2.99795
2291.63	-1.78698
2292.57	3.05265
2293.51	-0.783287
2294.45	0.232462
2295.39	-3.54595
2296.32	4.23396
2297.26	1.39289
2298.2	-2.41132
2299.14	1.49819
2300.07	4.43255
2301.01	1.58263
2301.95	-1.25199
2302.89	-2.16138
2303.82	5.62429
2304.76	-1.10485
2305.69	-1.06768
2306.63	4.79498
2307.57	0.993004
2308.5	5.84161
2309.44	0.0454235
2310.37	0.0840244
2311.31	-1.76568
2312.24	1.21446
2313.18	0.262236
2314.11	-3.58514
2315.05	2.27041
2315.98	4.22031
2316.92	3.28294
2317.85	-3.42433
2318.78	0.501305
2319.72	0.573631
2320.65	2.55501
2321.58	2.59869
2322.52	4.53715
2323.45	2.6225
2324.38	1.67302
2325.32	1.70352
2326.25	7.51535
2327.18	20.0694
2328.11	44.1721
2329.05	11.496
2329.98	8.61707
2330.91	4.78965
2331.84	3.84305
2332.77	0.0301743
2333.7	1.98758
2334.63	0.0969944
2335.56	2.04909
2336.5	4.0087
2337.43	0.187717
2338.36	-0.765886
2339.29	4.03463
2340.22	-0.736197
2341.15	0.252974
2342.08	-0.673872
2343.01	1.25274
2343.93	5.10179
2344.86	2.25271
2345.79	5.16118
2346.72	-0.589338
2347.65	0.303221
2348.58	1.39697
2349.51	0.378267
2350.44	3.202
2351.36	-0.597197
2352.29	2.29074
2353.22	-1.51587
2354.15	-0.585369
2355.07	-4.39015
2356	2.26078
2356.93	1.30938
2357.86	-3.45185
2358.78	4.11437
2359.71	0.299467
2360.63	-2.55405
2361.56	0.271605
2362.49	1.19825
2363.41	0.203554
2364.34	1.17344
2364.8	-2.59923