File: Data/3-Raman/processed/bu19w-c-ore1-fi05-v_150 (500nm)_532nm_edge_100%_x100_vis_h50um_15sx2_01_0.txt
#Acq. time (s)=	15
#Accumulations=	2
#Range (cm-¹)=	100...5000
#Windows=	1
#Auto scanning=	Off
#Autofocus=	Off
#Macrospot=	Off
#AutoExposure=	Off
#Spike filter=	Multiple accum.
#Delay time (s)=	2
#Binning=	1
#Readout mode=	Signal
#DeNoise=	Off
#ICS correction=	On
#Dark correction=	Off
#Inst. Process=	Off
#Detector Gain=	Best Dynamic
#Detector ADC=	50 kHz HS
#Detector temperature (°C)=	-60.09
#Instrument=	LabRAM HR Evol
#Detector=	SIN-EM FIVIS
#Objective=	x100_VIS
#Grating=	150 (500nm)
#ND Filter=	100%
#Laser=	532nm_Edge
#Hole=	49.98
#Temperature=	0
#Range=	Visible
#StageXY=	75x50mm Scan+
#StageZ=	Z motor
#X (µm)=	0
#Y (µm)=	0
#Z (µm)=	-5.8
#Full time(s)=	34
#Project=	21_05_14
#Sample=	BU19w
#Site=
#Title=	BU19w-FF-ore1-FI05-V_150 (500nm)_532nm_Edge_100%_x100_VIS_H50um_15sX2
#Remark=
#Date=	14.05.2021 18:44
#Acquired=	14.05.2021 18:44:07
#Base:Fit=	16.12.2021 17:39:50
#Base:Sub=	16.12.2021 18:01:31
102.699	1624.82
107.322	1517.65
111.942	1342.97
116.56	1248.76
121.173	1113.06
125.787	1024.31
130.398	1025.48
135.006	962.407
139.613	790.21
144.215	798.763
148.817	965.259
153.417	1753.44
158.014	1914.4
162.607	1074.67
167.2	710.714
171.79	755.852
176.379	1146.02
180.963	3110.41
185.547	3086.71
190.128	1191.41
194.705	413.851
199.282	215.874
203.857	178.955
208.43	154.042
212.998	113.01
217.566	42.4063
222.132	29.0289
226.693	121.495
231.254	90.0137
235.813	131.682
240.368	199.541
244.923	121.991
249.475	34.4246
254.023	17.4812
258.571	-0.866943
263.117	183.625
267.658	723.197
272.199	1830.62
276.738	1929.34
281.273	923.175
285.807	371.195
290.34	431.138
294.868	969.775
299.396	1472.47
303.919	834.205
308.443	325.966
312.964	157.695
317.481	197.641
321.998	337.264
326.51	450.544
331.023	197.802
335.533	76.1566
340.039	88.3628
344.544	209.814
349.046	124.075
353.547	8.29108
358.045	1.70435
362.542	60.6992
367.036	83.359
371.527	59.8398
376.017	178.327
380.503	429.387
384.99	496.201
389.471	548.227
393.953	573.454
398.43	410.605
402.908	282.031
407.381	314.881
411.854	486.867
416.323	352.974
420.791	100.783
425.256	33.7283
429.72	31.8517
434.18	27.7869
438.64	86.2635
443.095	232.717
447.551	772.875
452.003	1191.71
456.454	737.647
460.901	284.305
465.348	142.255
469.791	88.92
474.231	101.304
478.672	146.091
483.108	182.674
487.544	239.85
491.976	266.255
496.408	266.424
500.836	236.036
505.261	188.087
509.687	187.336
514.108	117.319
518.529	132.851
522.946	159.279
527.361	186.895
531.776	266.911
536.187	291.49
540.595	298.663
545.003	286.051
549.408	296.63
553.812	299.73
558.212	315.106
562.61	230.146
567.007	141.419
571.401	134.145
575.792	191.533
580.184	412.431
584.571	771.943
588.956	622.767
593.341	359.749
597.722	200.093
602.101	326.24
606.48	396.908
610.854	289.731
615.227	144.558
619.597	48.2084
623.967	77.9859
628.334	107.691
632.698	149.79
637.06	207.292
641.422	163.081
645.779	114.888
650.135	61.8217
654.491	86.2879
658.842	85.0967
663.192	152.095
667.539	161.979
671.884	230.142
676.23	259.562
680.571	188.826
684.91	94.8582
689.247	68.6997
693.583	53.9414
697.916	18.946
702.247	-3.6073
706.576	6.63342
710.902	44.3408
715.229	-1.52576
719.551	3.23663
723.872	23.4636
728.19	20.2437
732.506	15.3141
736.82	44.4827
741.134	50.3077
745.444	89.7312
749.752	104.157
754.058	181.363
758.362	246.775
762.664	416.811
766.964	775.81
771.264	1258.54
775.559	1485.54
779.853	1126.62
784.144	626.905
788.434	378.898
792.722	205.689
797.007	180.673
801.29	113.528
805.572	67.7393
809.851	62.7676
814.13	28.2708
818.406	37.6923
822.679	2.1889
826.95	31.7028
831.219	14.994
835.486	1.51038
839.752	25.4473
844.015	16.1271
848.276	34.9411
852.535	74.6082
856.792	113.122
861.047	149.291
865.3	105.875
869.551	40.3916
873.8	22.0424
878.047	18.9512
882.292	15.5822
886.534	-2.27649
890.775	6.49463
895.014	9.34082
899.251	10.1213
903.486	33.1613
907.719	1.62878
911.95	29.1006
916.179	42.2882
920.406	17.6974
924.63	22.3521
928.853	21.5735
933.074	18.7305
937.293	38.1444
941.51	55.2612
945.723	88.1844
949.936	96.6989
954.147	95.681
958.356	153.25
962.563	233.085
966.768	223.656
970.971	157.198
975.172	111.02
979.371	79.9081
983.568	82.7371
987.761	82.2408
991.954	57.8759
996.145	44.6483
1000.33	80.3594
1004.52	82.2473
1008.71	82.1644
1012.89	92.439
1017.07	98.4419
1021.25	108.677
1025.43	146.243
1029.6	190.261
1033.77	247.288
1037.95	421.648
1042.11	737.251
1046.28	1276.66
1050.45	1555.87
1054.61	1145.12
1058.77	704.212
1062.93	435.658
1067.09	315.567
1071.24	348.702
1075.4	364.092
1079.55	576.338
1083.7	797.5
1087.85	930.724
1091.99	872.055
1096.14	840.155
1100.28	1050.34
1104.42	1373.08
1108.55	1421.14
1112.69	1210.33
1116.82	966.8
1120.96	916.146
1125.09	1024
1129.21	1069.76
1133.34	863.102
1137.46	609.053
1141.59	408.128
1145.71	417.521
1149.83	478.902
1153.94	575.823
1158.06	521.972
1162.17	368.518
1166.28	283.021
1170.39	185.877
1174.5	186.538
1178.6	137.724
1182.7	153.752
1186.8	162.974
1190.9	220.064
1195	194.852
1199.1	220.439
1203.19	144.104
1207.28	137.12
1211.37	160.552
1215.46	191.933
1219.54	253.479
1223.63	237.53
1227.71	287.1
1231.79	335.832
1235.87	466.629
1239.95	441.007
1244.02	350.684
1248.09	324.991
1252.16	234.6
1256.23	229.206
1260.3	257.924
1264.36	366.886
1268.43	1135.58
1272.49	693.294
1276.55	215.811
1280.6	144.366
1284.66	153.035
1288.71	97.2529
1292.76	130.864
1296.81	131.209
1300.86	104.199
1304.91	104.253
1308.95	113.4
1312.99	98.0908
1317.03	116.783
1321.07	93.0793
1325.11	124.302
1329.14	121.459
1333.18	110.284
1337.21	132.01
1341.24	145.567
1345.26	143.051
1349.29	156.487
1353.31	176.847
1357.33	257.645
1361.35	357.929
1365.37	562.981
1369.39	1171.42
1373.4	1870.55
1377.41	686.439
1381.43	213.744
1385.43	154.293
1389.44	184.512
1393.45	244.619
1397.45	158.179
1401.45	94.1581
1405.45	101.144
1409.45	78.6134
1413.44	67.9403
1417.44	78.9466
1421.43	91.8909
1425.42	69.0372
1429.41	56.8063
1433.39	70.4307
1437.38	58.2652
1441.36	46.1207
1445.34	59.4911
1449.32	75.7866
1453.3	79.0925
1457.27	59.6697
1461.24	67.6321
1465.22	39.0365
1469.19	56.7424
1473.15	38.1183
1477.12	49.7706
1481.09	46.6653
1485.05	65.02
1489.01	54.0295
1492.97	36.2982
1496.93	48.8186
1500.88	53.6438
1504.83	44.0306
1508.79	60.8006
1512.74	51.3339
1516.68	50.682
1520.63	48.1517
1524.57	54.3895
1528.52	72.3303
1532.46	76.7529
1536.4	70.5126
1540.33	39.0997
1544.27	73.5733
1548.2	68.3218
1552.14	65.9316
1556.07	83.7596
1559.99	88.8969
1563.92	77.5105
1567.84	81.5385
1571.77	77.802
1575.69	77.917
1579.61	78.9641
1583.52	101.178
1587.44	99.2328
1591.35	95.3611
1595.27	122.244
1599.18	127.988
1603.09	105.994
1606.99	148.362
1610.9	137.978
1614.8	147.823
1618.7	134.71
1622.6	122.575
1626.5	168.983
1630.39	156.211
1634.29	140.705
1638.18	175.008
1642.07	150.203
1645.96	129.299
1649.85	122.809
1653.73	128.77
1657.62	108.743
1661.5	112.638
1665.38	108.711
1669.26	103.674
1673.13	81.1691
1677.01	84.4297
1680.88	74.8539
1684.75	70.0209
1688.62	61.2594
1692.49	38.9843
1696.35	58.7186
1700.22	49.6286
1704.08	68.0358
1707.94	38.7
1711.8	28.3899
1715.66	77.786
1719.51	36.3314
1723.37	59.1149
1727.22	58.1885
1731.07	47.8573
1734.92	27.2788
1738.76	57.1291
1742.61	55.1437
1746.45	1.36139
1750.29	23.3361
1754.13	29.7844
1757.97	15.7202
1761.81	28.8868
1765.64	39.0018
1769.47	13.3266
1773.31	-3.88684
1777.14	5.98553
1780.96	30.0745
1784.79	6.65692
1788.61	13.1722
1792.43	10.355
1796.25	20.6718
1800.07	4.42139
1803.89	29.3082
1807.71	24.0639
1811.52	29.0724
1815.33	35.75
1819.14	4.4386
1822.95	1.30432
1826.76	7.44989
1830.56	6.81055
1834.37	6.97968
1838.17	16.456
1841.97	29.5342
1845.77	9.71509
1849.56	12.3165
1853.36	22.1246
1857.15	27.9801
1860.94	14.1119
1864.73	0.328308
1868.52	16.3564
1872.31	27.8067
1876.09	21.7628
1879.87	20.5367
1883.66	29.6053
1887.43	7.82483
1891.21	23.2628
1894.99	33.1301
1898.76	20.1832
1902.53	33.2307
1906.31	41.7743
1910.08	22.8614
1913.84	17.9045
1917.61	15.9785
1921.37	0.410339
1925.14	29.3756
1928.9	26.029
1932.66	7.78638
1936.41	22.1024
1940.17	31.7847
1943.92	6.98932
1947.68	42.4938
1951.43	47.7644
1955.18	28.2907
1958.92	25.3632
1962.67	19.5619
1966.41	29.6499
1970.16	34.6821
1973.9	63.0047
1977.64	46.1877
1981.37	26.5083
1985.11	26.3647
1988.84	28.9678
1992.57	29.5319
1996.31	44.8411
2000.03	46.0977
2003.76	28.0388
2007.49	47.6257
2011.21	19.2371
2014.93	40.7476
2018.65	38.8279
2022.37	47.3068
2026.09	50.6721
2029.81	58.4762
2033.52	25.785
2037.23	55.143
2040.94	34.1946
2044.65	47.9352
2048.36	56.3435
2052.07	46.5354
2055.77	41.4305
2059.47	61.6758
2063.17	60.1725
2066.87	55.0679
2070.57	17.6862
2074.27	28.2416
2077.96	38.9175
2081.65	60.7449
2085.34	39.4751
2089.03	19.106
2092.72	53.9117
2096.41	55.4298
2100.09	47.2846
2103.77	63.2086
2107.46	44.5944
2111.14	80.7812
2114.81	60.2324
2118.49	61.7776
2122.16	58.3998
2125.84	43.8519
2129.51	65.3176
2133.18	81.1672
2136.85	41.4714
2140.51	54.3149
2144.18	61.5265
2147.84	48.4836
2151.5	36.4137
2155.16	72.9616
2158.82	51.8406
2162.48	47.3469
2166.13	28.3882
2169.79	56.1403
2173.44	27.6958
2177.09	49.3923
2180.74	52.035
2184.38	27.3999
2188.03	49.4915
2191.67	38.178
2195.32	42.595
2198.96	27.9421
2202.6	51.6942
2206.23	55.5228
2209.87	55.817
2213.5	36.0186
2217.14	61.1486
2220.77	30.3118
2224.4	44.4995
2228.03	33.7866
2231.65	44.3563
2235.28	32.7772
2238.9	45.2122
2242.52	40.0459
2246.14	53.444
2249.76	50.2057
2253.38	33.0392
2256.99	37.3256
2260.6	27.5207
2264.21	31.7252
2267.82	51.1345
2271.44	26.3813
2275.04	39.9066
2278.65	27.7154
2282.25	33.1028
2285.85	38.6476
2289.45	19.4905
2293.05	19.2084
2296.65	40.7479
2300.25	36.6851
2303.84	25.8219
2307.43	55.5973
2311.02	65.3785
2314.62	194.463
2318.2	128.135
2321.79	55.8653
2325.38	48.6697
2328.96	18.8505
2332.54	20.1002
2336.12	41.0604
2339.7	55.2812
2343.28	34.6453
2346.85	34.6234
2350.43	18.6695
2354	36.3498
2357.57	51.123
2361.14	25.82
2364.71	35.9127
2368.27	8.09839
2371.84	35.0302
2375.4	18.4042
2378.96	21.2789
2382.52	31.5844
2386.08	45.6258
2389.64	29.4793
2393.19	31.8821
2396.75	22.5981
2400.3	9.03979
2403.85	30.5585
2407.4	2.70117
2410.95	20.9683
2414.49	32.9566
2418.04	7.41235
2421.58	27.046
2425.12	18.3209
2428.66	30.0449
2432.2	26.2059
2435.74	6.67743
2439.27	20.5996
2442.81	31.8231
2446.34	25.4069
2449.87	14.4157
2453.4	33.259
2456.93	28.0355
2460.45	30.0285
2463.98	30.8284
2467.5	34.3796
2471.02	36.8506
2474.54	3.52618
2478.06	16.6837
2481.58	26.8756
2485.09	23.4988
2488.61	16.3634
2492.12	20.5852
2495.63	44.2982
2499.14	8.1579
2502.65	60.6392
2506.15	15.8449
2509.66	41.909
2513.16	28.9894
2516.66	11.6141
2520.16	39.3728
2523.66	40.5798
2527.16	43.0416
2530.66	9.57831
2534.15	44.6403
2537.64	47.518
2541.13	51.6064
2544.62	-3.95618
2548.11	27.3232
2551.6	25.4553
2555.08	29.5224
2558.57	18.7582
2562.05	13.7883
2565.53	17.4009
2569.01	39.8928
2572.49	24.2424
2575.96	38.6943
2579.44	29.7408
2582.91	25.4796
2586.38	41.0024
2589.85	25.8497
2593.32	46.563
2596.79	32.2475
2600.25	20.7829
2603.72	11.8439
2607.18	42.7115
2610.64	15.3058
2614.1	17.9351
2617.56	30.8998
2621.02	27.397
2624.47	23.7011
2627.92	23.7385
2631.38	45.7134
2634.83	23.3228
2638.28	32.4685
2641.72	43.3409
2645.17	35.0499
2648.61	58.1217
2652.06	41.9059
2655.5	43.6361
2658.94	43.3852
2662.38	34.5346
2665.82	55.915
2669.25	0.881165
2672.69	29.7639
2676.12	33.3082
2679.55	34.1667
2682.98	34.2487
2686.41	16.0891
2689.84	47.7553
2693.26	44.729
2696.69	39.0469
2700.11	29.7562
2703.53	43.5587
2706.95	45.7921
2710.37	34.2515
2713.79	15.3796
2717.2	34.8115
2720.62	44.1232
2724.03	12.4227
2727.44	25.5851
2730.85	32.1845
2734.26	42.5374
2737.66	30.41
2741.07	51.9332
2744.47	22.6208
2747.87	32.7559
2751.28	0.554199
2754.67	33.1234
2758.07	32.8547
2761.47	39.9286
2764.86	41.2584
2768.26	29.2526
2771.65	49.2477
2775.04	24.8443
2778.43	53.085
2781.82	39.8232
2785.2	35.9501
2788.59	52.7556
2791.97	49.747
2795.35	31.7846
2798.73	26.8325
2802.11	24.7043
2805.49	39.439
2808.87	35.3879
2812.24	63.1133
2815.62	60.8232
2818.99	67.0318
2822.36	39.7631
2825.73	55.4595
2829.1	28.3408
2832.46	49.8117
2835.83	72.3125
2839.19	69.7899
2842.55	59.9521
2845.91	50.3088
2849.27	85.7581
2852.63	66.939
2855.99	37.8788
2859.34	77.1877
2862.69	58.5159
2866.05	67.0391
2869.4	57.6815
2872.75	59.5609
2876.09	54.8319
2879.44	68.9254
2882.78	66.9591
2886.13	48.8918
2889.47	45.0087
2892.81	48.4832
2896.15	82.1324
2899.49	100.563
2902.82	82.9387
2906.16	82.2915
2909.49	79.6722
2912.82	92.1907
2916.16	71.4596
2919.49	110.274
2922.81	91.3678
2926.14	80.8416
2929.46	117.521
2932.79	90.7442
2936.11	91.3582
2939.43	121.183
2942.75	92.5893
2946.07	119.601
2949.39	111.76
2952.7	92.6268
2956.02	114.008
2959.33	119.529
2962.64	117.518
2965.95	125.052
2969.26	162.895
2972.57	142.45
2975.87	149.503
2979.17	172.349
2982.48	149.252
2985.78	174.083
2989.08	139.785
2992.38	172.199
2995.68	186.836
2998.97	193.036
3002.27	155.928
3005.56	186.62
3008.85	196.668
3012.14	207.71
3015.43	199.889
3018.72	217.507
3022	221.926
3025.29	237.699
3028.57	256.32
3031.85	252.237
3035.14	248.106
3038.41	253.44
3041.69	256.889
3044.97	285.944
3048.24	283.729
3051.52	310.945
3054.79	333.425
3058.06	333.044
3061.33	353.306
3064.6	374.613
3067.87	332.203
3071.13	398.153
3074.4	397.248
3077.66	414.361
3080.92	424.455
3084.18	448.998
3087.44	469.017
3090.7	469.347
3093.95	486.664
3097.21	499.372
3100.46	538.716
3103.71	560.363
3106.96	579.236
3110.21	604.435
3113.46	602.002
3116.71	662.473
3119.95	638.213
3123.2	670.136
3126.44	699.174
3129.68	702.5
3132.92	738.216
3136.16	762.438
3139.4	791.397
3142.63	832.749
3145.87	823.646
3149.1	861.329
3152.33	910.424
3155.56	951.924
3158.79	974.321
3162.02	985.276
3165.25	1014.26
3168.47	1085.1
3171.69	1051.86
3174.92	1058.56
3178.14	1140.56
3181.36	1173.94
3184.58	1181.4
3187.79	1219.27
3191.01	1229.47
3194.22	1272.04
3197.43	1295.49
3200.65	1319.92
3203.86	1354.88
3207.07	1308.06
3210.27	1332.74
3213.48	1360.42
3216.69	1383.37
3219.89	1430.14
3223.09	1460.92
3226.29	1459.43
3229.49	1456.21
3232.69	1480.45
3235.89	1479.34
3239.08	1542.23
3242.28	1470.99
3245.47	1566.46
3248.66	1573.53
3251.85	1592.16
3255.04	1581.24
3258.23	1600.62
3261.42	1588.19
3264.6	1607.91
3267.79	1607.33
3270.97	1631.42
3274.15	1652.63
3277.33	1662.03
3280.51	1683.34
3283.68	1650.23
3286.86	1679.9
3290.04	1719.21
3293.21	1737.51
3296.38	1777.59
3299.55	1803.97
3302.72	1797.57
3305.89	1802.29
3309.06	1827.56
3312.22	1851.63
3315.39	1842.37
3318.55	1902.25
3321.71	1908.98
3324.87	1938.43
3328.03	1931.93
3331.19	1973.78
3334.34	1986.51
3337.5	2050.42
3340.65	2061.44
3343.81	2033.35
3346.96	2068.27
3350.11	2134.34
3353.25	2174.28
3356.4	2165.34
3359.55	2192.58
3362.69	2225.59
3365.84	2241.78
3368.98	2229.77
3372.12	2269.04
3375.26	2311.33
3378.4	2362.38
3381.53	2423.72
3384.67	2401.17
3387.8	2406.1
3390.94	2490.72
3394.07	2503.17
3397.2	2632.78
3400.33	2613.27
3403.46	2708.95
3406.58	2975.21
3409.71	3363.05
3412.83	4523.18
3415.96	7349.96
3419.08	9323.83
3422.2	6960.6
3425.32	4359.06
3428.44	3280.44
3431.55	2904.71
3434.67	2731.33
3437.78	2612.72
3440.89	2628.87
3444	2523.16
3447.12	2478.5
3450.22	2448.64
3453.33	2493.06
3456.44	2453.22
3459.54	2421.89
3462.65	2433.26
3465.75	2373.15
3468.85	2340.71
3471.95	2334.76
3475.05	2283.67
3478.15	2238.48
3481.24	2210.44
3484.34	2220.38
3487.43	2247.54
3490.53	2278.44
3493.62	2254.69
3496.71	2301.39
3499.79	2370.95
3502.88	2245.67
3505.97	2148.98
3509.05	2085.39
3512.14	1943.53
3515.22	1847.28
3518.3	1805.38
3521.38	1725.31
3524.46	1666.95
3527.54	1644.03
3530.61	1582.07
3533.69	1527.44
3536.76	1528.13
3539.83	1418.88
3542.9	1419.13
3545.97	1350.31
3549.04	1351.06
3552.11	1256.88
3555.18	1249
3558.24	1223.32
3561.3	1203.83
3564.37	1125.44
3567.43	1114.37
3570.49	1106.81
3573.55	1103.8
3576.61	1028.63
3579.66	1007.4
3582.72	970.854
3585.77	930.479
3588.82	922.217
3591.87	893.977
3594.92	888.39
3597.97	838.257
3601.02	791.849
3604.07	816.344
3607.11	792.542
3610.16	747.921
3613.2	719.354
3616.24	668.194
3619.28	651.119
3622.32	646.366
3625.36	620.012
3628.39	591.779
3631.43	562.558
3634.46	529.783
3637.5	520.739
3640.53	472.3
3643.56	438.23
3646.59	403.067
3649.62	396.256
3652.64	398.783
3655.67	330.135
3658.69	317.439
3661.72	307.433
3664.74	267.844
3667.76	236.747
3670.78	217.963
3673.79	204.863
3676.81	206.908
3679.83	165.469
3682.84	158.014
3685.86	166.652
3688.87	125.149
3691.88	133.822
3694.89	128.178
3697.9	99.8422
3700.91	93.3363
3703.91	82.074
3706.92	70.7435
3709.92	83.1221
3712.92	67.8533
3715.92	73.5263
3718.92	59.1724
3721.92	42.8535
3724.92	44.5713
3727.92	42.4413
3730.91	43.1202
3733.91	31.3614
3736.9	50.9748
3739.89	34.3513
3742.88	50.0362
3745.87	31.4268
3748.86	34.6488
3751.85	24.5558
3754.83	31.5713
3757.82	38.5759
3760.8	29.4196
3763.78	22.1684
3766.76	43.3553
3769.74	28.6241
3772.72	21.5172
3775.7	35.2422
3778.67	27.2677
3781.65	18.3683
3784.62	7.6124
3787.6	19.5439
3790.57	0.39978
3793.54	17.1774
3796.51	27.3804
3799.47	1.77554
3802.44	22.4716
3805.41	9.18884
3808.37	24.2781
3811.33	17.6535
3814.3	17.6566
3817.26	12.9503
3820.22	30.0258
3823.18	29.1572
3826.13	15.0345
3829.09	17.01
3832.04	19.0265
3835	4.93701
3837.95	8.89063
3840.9	16.6496
3843.85	1.58493
3846.8	5.56372
3849.75	16.2501
3852.69	0.255493
3855.64	12.8863
3858.58	1.65524
3861.53	20.9899
3864.47	-4.64261
3867.41	33.8451
3870.35	3.33255
3873.29	2.50632
3876.22	13.1524
3879.16	12.2324
3882.1	8.36917
3885.03	5.42123
3887.96	22.6386
3890.89	24.4596
3893.82	10.8402
3896.75	15.4278
3899.68	8.46429
3902.61	3.35687
3905.53	8.8721
3908.46	25.8962
3911.38	23.6526
3914.3	7.90472
3917.23	24.9043
3920.15	18.7938
3923.06	14.5432
3925.98	20.8004
3928.9	24.126
3931.81	24.6653
3934.73	9.98315
3937.64	15.5272
3940.55	-9.59671
3943.46	12.204
3946.37	46.4943
3949.28	16.6788
3952.19	18.4769
3955.09	25.1067
3958	14.5198
3960.9	20.2414
3963.8	23.117
3966.71	4.91611
3969.61	25.1064
3972.51	3.06317
3975.4	17.4783
3978.3	25.1411
3981.2	30.8762
3984.09	34.6656
3986.99	31.723
3989.88	37.353
3992.77	9.39194
3995.66	15.1023
3998.55	26.6128
4001.43	19.8385
4004.32	10.1924
4007.21	36.2095
4010.09	33.3143
4012.98	27.5252
4015.86	9.18726
4018.74	21.7219
4021.62	12.0532
4024.5	19.7762
4027.37	47.803
4030.25	27.5189
4033.13	24.6297
4036	19.8228
4038.87	23.7314
4041.75	30.4735
4044.62	25.5828
4047.49	12.9615
4050.35	13.929
4053.22	15.902
4056.09	3.32346
4058.95	19.8481
4061.82	34.4406
4064.68	27.6533
4067.54	23.7708
4070.4	30.5849
4073.26	24.7389
4076.12	23.7486
4078.98	13.0082
4081.83	9.08344
4084.69	2.21707
4087.54	21.6789
4090.4	27.5078
4093.25	18.6875
4096.1	10.8245
4098.95	16.6534
4101.8	24.4214
4104.64	15.5285
4107.49	16.3897
4110.33	11.36
4113.18	17.0392
4116.02	20.7097
4118.86	38.0522
4121.7	24.1195
4124.54	24.8962
4127.38	1.26535
4130.22	20.8029
4133.05	9.0929
4135.89	18.7072
4138.72	29.7506
4141.56	18.4507
4144.39	19.3169
4147.22	34.8992
4150.05	48.4905
4152.88	13.9489
4155.7	7.64182
4158.53	12.1083
4161.36	18.6575
4164.18	25.2053
4167	14.1534
4169.82	19.752
4172.65	14.608
4175.46	25.1134
4178.28	22.9232
4181.1	5.10919
4183.92	26.4342
4186.73	29.1934
4189.55	26.1202
4192.36	22.123
4195.17	34.8247
4197.98	33.8342
4200.79	36.7595
4203.6	44.5965
4206.41	34.757
4209.21	23.9195
4212.02	25.8365
4214.83	32.8152
4217.63	20.2162
4220.43	22.3169
4223.23	17.4675
4226.03	10.6445
4228.83	21.6575
4231.63	27.7684
4234.42	32.9408
4237.22	17.2874
4240.01	30.427
4242.81	28.6867
4245.6	25.9386
4248.39	16.1562
4251.18	29.3059
4253.97	24.452
4256.76	12.5515
4259.55	27.7033
4262.33	34.8744
4265.12	23.9922
4267.9	22.1448
4270.68	26.3218
4273.47	27.4273
4276.25	11.2977
4279.03	9.24631
4281.8	21.3104
4284.58	11.0839
4287.36	-1.22522
4290.13	15.7902
4292.91	9.54568
4295.68	24.6234
4298.45	26.5196
4301.22	14.187
4303.99	8.94656
4306.76	12.8498
4309.53	13.7371
4312.3	29.8572
4315.06	27.6212
4317.83	22.3004
4320.59	30.1791
4323.35	20.724
4326.11	33.6705
4328.87	21.1368
4331.63	23.871
4334.39	2.14267
4337.15	18.1327
4339.9	10.7224
4342.66	20.6577
4345.41	29.619
4348.17	28.3949
4350.92	23.1421
4353.67	12.794
4356.42	30.0129
4359.17	21.6606
4361.91	10.2339
4364.66	23.38
4367.41	19.1161
4370.15	-1.58771
4372.89	16.645
4375.63	0.993225
4378.38	13.0395
4381.12	17.913
4383.86	18.7376
4386.59	6.30579
4389.33	23.817
4392.07	14.7328
4394.8	24.1893
4397.53	10.74
4400.27	12.7914
4403	26.2475
4405.73	22.0984
4408.46	9.59851
4411.19	24.0786
4413.92	19.8014
4416.64	9.16522
4419.37	22.4793
4422.09	21.2515
4424.82	15.846
4427.54	11.4763
4430.26	7.0929
4432.98	24.6719
4435.7	22.3502
4438.42	28.3804
4441.13	5.0423
4443.85	25.7383
4446.57	17.0493
4449.28	16.7349
4451.99	17.4518
4454.71	13.9438
4457.42	18.8175
4460.13	19.5103
4462.83	-1.87234
4465.54	25.1394
4468.25	17.4504
4470.95	30.8427
4473.66	32.6885
4476.36	2.92432
4479.07	23.8002
4481.77	16.1929
4484.47	5.38263
4487.17	16.7618
4489.87	17.5121
4492.56	5.43057
4495.26	26.2568
4497.96	21.6768
4500.65	20.209
4503.34	24.0812
4506.04	18.4262
4508.73	8.52167
4511.42	17.7176
4514.11	25.8735
4516.8	27.6587
4519.48	19.9272
4522.17	26.0204
4524.85	18.2655
4527.54	13.7091
4530.22	19.8066
4532.9	14.1965
4535.58	19.2478
4538.27	25.4132
4540.94	12.3297
4543.62	25.987
4546.3	18.2512
4548.98	15.8689
4551.65	29.6489
4554.33	18.7702
4557	15.5071
4559.67	-2.79703
4562.34	15.5899
4565.01	23.4168
4567.68	10.5672
4570.35	26.6072
4573.02	4.3548
4575.68	15.9413
4578.35	28.7159
4581.01	19.9861
4583.67	40.3748
4586.34	9.53842
4589	22.2578
4591.66	10.9572
4594.31	11.7578
4596.97	12.4715
4599.63	24.1969
4602.29	15.1742
4604.94	15.9934
4607.59	11.3423
4610.25	27.5276
4612.9	12.9639
4615.55	29.175
4618.2	21.2274
4620.85	36.3971
4623.5	25.0976
4626.14	23.6849
4628.79	16.7534
4631.43	18.604
4634.08	14.888
4636.72	16.7079
4639.36	0.784149
4642	18.1465
4644.64	28.9673
4647.28	13.2275
4649.92	28.6745
4652.56	9.78238
4655.19	31.4362
4657.83	16.6143
4660.46	17.4687
4663.1	7.1524
4665.73	12.3463
4668.36	18.7103
4670.99	30.6758
4673.62	22.4738
4676.24	13.1313
4678.87	21.7282
4681.5	19.0977
4684.12	37.8318
4686.75	21.6992
4689.37	19.0802
4691.99	10.7861
4694.61	19.3856
4697.23	11.0743
4699.85	16.3065
4702.47	13.5958
4705.09	27.8337
4707.7	25.1025
4710.32	20.0988
4712.93	17.3492
4715.55	16.8336
4718.16	7.2612
4720.77	14.6359
4723.38	22.0606
4725.99	17.0391
4728.6	8.60754
4731.21	27.4219
4733.81	-0.330414
4736.42	28.6918
4739.02	25.9039
4741.63	17.3833
4744.23	13.4132
4746.83	26.4388
4749.43	18.9941
4752.03	27.4804
4754.63	31.3969
4757.23	30.7845
4759.82	13.1231
4762.42	17.0915
4765.01	10.8542
4767.61	19.5172
4770.2	31.5156
4772.79	25.2657
4775.38	11.022
4777.97	24.1712
4780.56	16.7594
4783.15	27.6371
4785.74	20.2192
4788.32	10.5083
4790.91	13.3987
4793.49	18.5775
4796.07	22.6468
4798.66	7.23438
4801.24	14.7755
4803.82	39.594
4806.4	20.7869
4808.98	19.194
4811.55	14.1548
4814.13	20.6504
4816.71	27.1933
4819.28	21.015
4821.85	22.9321
4824.43	20.2117
4827	27.9117
4829.57	28.6975
4832.14	16.6661
4834.71	15.1278
4837.28	24.1194
4839.84	37.8289
4842.41	24.5641
4844.97	15.9184
4847.54	22.4814
4850.1	22.9965
4852.66	5.71094
4855.22	18.2089
4857.78	10.6986
4860.34	19.6323
4862.9	0.114761
4865.46	8.88295
4868.01	18.9715
4870.57	26.6349
4873.12	22.3977
4875.68	13.4073
4878.23	19.8158
4880.78	9.57436
4883.33	15.9464
4885.88	21.1327
4888.43	0.149765
4890.98	21.9819
4893.53	23.5744
4896.07	10.8434
4898.62	15.9788
4901.16	22.2887
4903.7	7.1259
4906.25	28.9169
4908.79	20.8293
4911.33	15.0778
4913.87	11.6849
4916.41	15.4566
4918.94	24.012
4921.48	2.68738
4924.02	5.26015
4926.55	7.81099
4929.08	17.5507
4931.62	18.9783
4934.15	22.7882
4936.68	-2.15631
4939.21	12.3145
4941.74	13.615
4944.27	7.79285
4946.79	18.7358
4949.32	18.8941
4951.85	16.6313
4954.37	9.56654
4956.9	-3.48819
4959.42	1.47147
4961.94	14.8975
4964.46	0.699753
4966.98	8.12874
4969.5	15.5156
4972.02	22.8963
4974.53	8.51013
4977.05	2.55832
4979.57	7.48607
4982.08	0.292435
4984.59	7.63513
4987.1	12.5523
4989.62	0.43959
4992.13	-1.98816
4994.64	0.457596
4997.15	10.2345
4999.65	-0.733261