File: Data/3-Raman/processed/bu19w-a-ff07b-fi06-v_150 (500nm)_532nm_edge_100%_x100_vis_lwd_h50um_15sx2_01_0.txt
#Acq. time (s)=	15
#Accumulations=	2
#Range (cm-¹)=	50...5000
#Windows=	1
#Auto scanning=	Off
#Autofocus=	Off
#Macrospot=	Off
#AutoExposure=	Off
#Spike filter=	Multiple accum.
#Delay time (s)=	2
#Binning=	1
#Readout mode=	Signal
#DeNoise=	Off
#ICS correction=	On
#Dark correction=	Off
#Inst. Process=	Off
#Detector Gain=	Best Dynamic
#Detector ADC=	50 kHz HS
#Detector temperature (°C)=	-60.09
#Instrument=	LabRAM HR Evol
#Detector=	SIN-EM FIVIS
#Objective=	x100_VIS_LWD
#Grating=	150 (500nm)
#ND Filter=	100%
#Laser=	532nm_Edge
#Hole=	49.98
#Temperature=	0
#Range=	Visible
#StageXY=	75x50mm Scan+
#StageZ=	Z motor
#X (µm)=	0
#Y (µm)=	0
#Z (µm)=	-27
#Full time(s)=	34
#Project=	21_05_28
#Sample=	BU19w
#Site=
#Title=	BU19w-FF07b-FI06-V_150 (500nm)_532nm_Edge_100%_x100_VIS_LWD_H50um_15sX2
#Remark=
#Date=	28.05.2021 16:22
#Acquired=	28.05.2021 16:22:37
#Base:Fit=	16.12.2021 17:39:50
#Base:Sub=	16.12.2021 17:58:53
51.5961	34236.4
56.2453	27777.3
60.8921	20343.1
65.5367	17546.2
70.1768	16222.9
74.8167	10244.2
79.4543	6235.93
84.0897	4417.38
88.7227	3428.26
93.3513	2538.62
97.9798	1961.97
102.606	1479.42
107.23	1179.2
111.851	1057.95
116.469	943.116
121.086	537.01
125.7	400.924
130.313	381.999
134.921	324.071
139.529	198.7
144.134	206.578
148.738	125.913
153.337	0.0435791
157.936	63.3983
162.532	460.022
167.126	1397.44
171.716	1330.47
176.306	365.809
180.894	139.372
185.477	256.726
190.06	1191.17
194.64	4206.32
199.219	4344.39
203.793	1623.43
208.367	394.732
212.939	74.8865
217.506	0.821655
222.073	35.5197
226.638	-0.906799
231.199	30.8263
235.759	112.453
240.318	517.338
244.872	694.406
249.425	1183.03
253.977	2073.62
258.524	1672.76
263.071	1143.76
267.616	647.261
272.156	524.11
276.697	907.958
281.233	2267.06
285.769	5104.88
290.303	5091.21
294.832	2640.69
299.361	1337.74
303.886	1102.36
308.411	1858.69
312.934	2380.68
317.452	1529.65
321.97	777.973
326.484	684.203
330.998	999.533
335.507	1726.51
340.017	1946.37
344.524	1078.17
349.027	757.551
353.53	1144.83
358.028	1608.8
362.527	1396.62
367.021	756.285
371.515	502.221
376.004	621.807
380.494	653.033
384.979	424.332
389.465	489.917
393.946	754.586
398.427	1049.19
402.903	1126.27
407.38	849.269
411.852	493.336
416.324	366.552
420.792	599.306
425.26	876.001
429.723	585.835
434.187	206.562
438.646	87.4871
443.105	93.215
447.56	55.2077
452.015	167.386
456.466	354.698
460.914	1011.05
465.362	1490.51
469.807	868.269
474.251	380.977
478.69	235.373
483.13	249.539
487.566	284.805
491.999	433.168
496.432	643.595
500.861	815.579
505.29	863.018
509.715	776.393
514.138	598.427
518.56	398.549
522.979	300.759
527.395	249.385
531.811	246.698
536.223	214.058
540.635	255.489
545.042	249.35
549.448	271.04
553.853	293.736
558.255	300.729
562.654	331.906
567.053	399.797
571.448	376.5
575.841	284.564
580.232	246.322
584.622	302.979
589.009	521.581
593.393	1325.71
597.777	2272.99
602.157	1759.28
606.535	906.784
610.913	743.909
615.287	1012.82
619.659	1442.9
624.029	1368.97
628.398	711.529
632.763	384.676
637.127	293.79
641.488	310.719
645.849	438.209
650.206	472.654
654.561	399.049
658.914	323.428
663.267	411.322
667.615	564.151
671.962	817.654
676.307	876.45
680.649	961.762
684.991	1093.19
689.33	944.537
693.666	570.975
698	376.072
702.332	185.161
706.662	112.933
710.992	103.971
715.318	64.4071
719.641	49.8716
723.963	65.3622
728.283	55.1593
732.6	62.1741
736.918	58.535
741.231	69.3049
745.542	85.9431
749.852	75.0742
754.159	104.924
758.464	159.688
762.767	206.243
767.068	256.443
771.369	428.288
775.666	682.026
779.961	1232.6
784.254	1999.16
788.545	2217.26
792.834	1597.05
797.12	984.856
801.405	568.887
805.688	376.683
809.968	286.131
814.247	202.323
818.524	130.721
822.798	118.481
827.071	97.6388
831.341	91.1558
835.612	91.2833
839.878	51.6402
844.142	65.9276
848.405	62.2802
852.665	59.2903
856.923	61.8094
861.18	49.9761
865.434	44.6188
869.686	28.0258
873.936	29.9777
878.185	36.1198
882.431	32.2168
886.675	49.8625
890.915	37.5657
895.155	0.0773315
899.393	43.1207
903.63	59.5132
907.864	47.7469
912.096	22.1249
916.326	27.2775
920.554	65.7294
924.78	58.4918
929.004	77.7473
933.227	63.4955
937.447	101.749
941.665	119.319
945.881	195.52
950.095	324.794
954.305	489.103
958.516	628.608
962.724	536.183
966.93	469.583
971.134	508.302
975.337	609.749
979.537	551.238
983.735	361.709
987.93	244.299
992.124	190.564
996.316	166.061
1000.51	173.862
1004.7	151.096
1008.88	162.4
1013.06	167.374
1017.25	151.897
1021.43	165.163
1025.61	180.396
1029.78	214.551
1033.96	254.832
1038.13	359.208
1042.3	385.962
1046.47	541.341
1050.63	795.638
1054.8	1529.85
1058.96	2626.06
1063.12	2872.99
1067.28	2024.84
1071.44	1327.16
1075.59	860.409
1079.74	803.848
1083.89	925.743
1088.04	1217.65
1092.19	1944.29
1096.33	2890.67
1100.48	3195.38
1104.62	2566.65
1108.76	2052.26
1112.89	2039.69
1117.03	2335.51
1121.16	2389.75
1125.29	2061.5
1129.42	1891.77
1133.55	1914.71
1137.68	2122.64
1141.8	2228.31
1145.92	1802.89
1150.04	1369.14
1154.16	1128.08
1158.27	1236.82
1162.39	1685.77
1166.5	2053.5
1170.61	1828.15
1174.72	1316.61
1178.82	1007.39
1182.93	746.019
1187.03	501.19
1191.13	387.722
1195.23	315.307
1199.33	347.034
1203.42	364.054
1207.51	386.979
1211.6	316.646
1215.69	322.494
1219.78	250.845
1223.86	344.496
1227.95	534.201
1232.03	639.537
1236.11	536.682
1240.18	469.681
1244.26	661.126
1248.33	877.874
1252.41	816.897
1256.48	624.372
1260.54	563.807
1264.61	379.319
1268.67	300.867
1272.74	297.59
1276.8	972.672
1280.86	2689.94
1284.91	1165.28
1288.97	290.813
1293.02	205.434
1297.07	170.189
1301.12	173.121
1305.17	138.589
1309.21	137.251
1313.25	140.851
1317.3	153.2
1321.34	155.278
1325.37	120.796
1329.41	125.467
1333.44	128.02
1337.48	108.231
1341.5	147.384
1345.53	94.4224
1349.56	131.346
1353.59	127.357
1357.61	122.426
1361.63	157.094
1365.65	215.554
1369.66	194.914
1373.68	209.095
1377.69	351.562
1381.7	2626.51
1385.72	3720.29
1389.72	1028.57
1393.73	249.566
1397.73	165.848
1401.74	250.431
1405.74	438.494
1409.73	266.032
1413.73	97.4549
1417.73	121.13
1421.72	90.5178
1425.71	101.245
1429.7	70.0681
1433.69	70.5671
1437.67	55.2468
1441.66	77.457
1445.64	46.2272
1449.62	68.2522
1453.6	60.5257
1457.57	30.0498
1461.55	63.5007
1465.52	33.6476
1469.49	27.3989
1473.46	62.5162
1477.43	54.2832
1481.39	15.5894
1485.36	0.420227
1489.32	38.9764
1493.28	23.8123
1497.24	11.624
1501.19	28.7492
1505.15	33.3278
1509.1	29.3693
1513.05	48.78
1517	8.02423
1520.95	30.4601
1524.9	23.8292
1528.84	38.5916
1532.78	18.5465
1536.72	29.5402
1540.66	34.7384
1544.6	25.3998
1548.53	56.7578
1552.46	38.6976
1556.4	41.8506
1560.32	15.8321
1564.25	46.8369
1568.18	12.9299
1572.1	23.4579
1576.02	14.6407
1579.94	36.679
1583.86	36.4819
1587.78	5.38922
1591.69	38.8192
1595.61	24.0854
1599.52	2.64984
1603.43	50.4365
1607.34	-4.3866
1611.24	41.5576
1615.15	28.0856
1619.05	53.0533
1622.95	30.0689
1626.85	41.686
1630.74	9.37701
1634.64	33.794
1638.53	29.4531
1642.42	41.5997
1646.31	0.267273
1650.2	24.1583
1654.09	23.1718
1657.97	35.5543
1661.86	23.8986
1665.74	36.0998
1669.62	43.4106
1673.49	51.4228
1677.37	27.6599
1681.24	56.3099
1685.12	37.6682
1688.99	3.64313
1692.86	10.7071
1696.72	19.547
1700.59	29.1765
1704.45	0.458435
1708.31	17.3495
1712.17	6.45837
1716.03	18.3579
1719.89	42.53
1723.74	26.0355
1727.6	22.7172
1731.45	42.7654
1735.3	42.1609
1739.14	46.131
1742.99	28.5081
1746.83	33.3535
1750.68	9.86664
1754.52	33.1445
1758.36	14.1804
1762.19	13.2648
1766.03	40.5364
1769.86	36.5673
1773.69	31.1348
1777.53	8.96027
1781.35	11.2391
1785.18	28.5944
1789	6.82257
1792.83	22.483
1796.65	39.1545
1800.47	14.4857
1804.29	41.9133
1808.1	31.6536
1811.92	36.3585
1815.73	60.728
1819.54	22.4611
1823.35	22.6535
1827.16	17.0289
1830.97	35.6931
1834.77	22.0759
1838.58	-8.60516
1842.38	19.8881
1846.18	16.1813
1849.97	7.8941
1853.77	26.3983
1857.56	33.4011
1861.36	19.5811
1865.15	51.3167
1868.93	17.0763
1872.72	12.7128
1876.51	6.68384
1880.29	50.5753
1884.07	50.4489
1887.86	43.9098
1891.63	33.77
1895.41	26.415
1899.19	30.1016
1902.96	44.2835
1906.73	42.0708
1910.5	31.6497
1914.27	49.1947
1918.04	24.3727
1921.8	31.4703
1925.57	70.1668
1929.33	36.7796
1933.09	35.8874
1936.85	26.5831
1940.6	48.9565
1944.36	13.3966
1948.11	12.3741
1951.87	14.4338
1955.61	14.2756
1959.36	4.28082
1963.11	10.9107
1966.86	11.8557
1970.6	38.8094
1974.34	26.0143
1978.08	47.7266
1981.82	14.0314
1985.56	50.3473
1989.29	9.01935
1993.02	28.2183
1996.75	-2.09711
2000.49	62.1649
2004.21	3.99945
2007.94	48.5194
2011.67	25.3384
2015.39	28.9582
2019.11	42.1644
2022.83	19.1324
2026.55	37.897
2030.27	39.2775
2033.98	31.0214
2037.69	24.9005
2041.41	32.433
2045.12	55.4601
2048.82	37.3075
2052.53	24.8226
2056.24	45.3633
2059.94	7.71863
2063.64	27.4562
2067.34	34.598
2071.04	40.9191
2074.74	33.4322
2078.43	17.6656
2082.13	35.261
2085.82	15.6787
2089.51	21.012
2093.2	47.3192
2096.88	10.8772
2100.57	54.2166
2104.25	41.4648
2107.94	41.5742
2111.62	15.5079
2115.3	25.6833
2118.97	40.3842
2122.65	50.0629
2126.32	22.4202
2129.99	24.3472
2133.66	45.6194
2137.33	25.1841
2141	14.8033
2144.67	48.5428
2148.33	47.1536
2151.99	7.1864
2155.66	48.976
2159.31	32.0884
2162.97	60.1438
2166.63	28.0364
2170.28	41.7484
2173.94	35.7796
2177.59	19.0993
2181.24	37.1395
2184.89	53.3065
2188.53	48.8005
2192.18	41.9302
2195.82	82.7766
2199.46	36.4382
2203.1	66.731
2206.74	56.1576
2210.38	50.2946
2214.01	43.6364
2217.65	61.7701
2221.28	76.3135
2224.91	56.9272
2228.54	49.3946
2232.16	48.3264
2235.79	71.3699
2239.41	60.2144
2243.04	46.2245
2246.66	78.5845
2250.28	47.8574
2253.89	55.3338
2257.51	32.1296
2261.12	55.5737
2264.74	65.8772
2268.35	45.3634
2271.96	43.7932
2275.57	60.7956
2279.17	54.9579
2282.78	63.5766
2286.38	34.4182
2289.98	43.9591
2293.58	48.6596
2297.18	30.6879
2300.78	77.1286
2304.37	44.8186
2307.97	17.9732
2311.56	24.1657
2315.15	44.441
2318.74	58.8669
2322.33	184.857
2325.91	407.48
2329.5	216.395
2333.08	84.1556
2336.66	53.0215
2340.24	51.0328
2343.82	36.7347
2347.4	70.2155
2350.97	34.2035
2354.54	50.6288
2358.12	29.6133
2361.69	58.9025
2365.26	72.2637
2368.82	47.6113
2372.39	77.9194
2375.95	66.4526
2379.52	47.6725
2383.08	38.2918
2386.64	39.1568
2390.19	44.7789
2393.75	57.9258
2397.31	58.5093
2400.86	33.7675
2404.41	50.8065
2407.96	53.309
2411.51	85.5842
2415.06	48.3855
2418.6	69.2522
2422.15	86.6487
2425.69	63.7913
2429.23	48.5001
2432.77	48.1516
2436.31	74.9048
2439.84	46.1378
2443.38	71.3347
2446.91	84.5448
2450.44	64.3433
2453.97	39.5142
2457.5	56.2629
2461.03	80.6939
2464.55	40.9836
2468.08	66.4227
2471.6	56.8354
2475.12	61.6523
2478.64	75.7531
2482.16	56.0715
2485.67	60.5394
2489.19	64.3889
2492.7	35.9001
2496.21	59.4672
2499.72	66.4623
2503.23	62.821
2506.74	75.8392
2510.25	57.8354
2513.75	79.0477
2517.25	56.7819
2520.75	57.0187
2524.25	76.015
2527.75	52.5058
2531.25	86.5731
2534.74	76.4326
2538.24	59.2244
2541.73	77.3237
2545.22	54.3862
2548.71	66.0276
2552.2	43.5409
2555.68	64.7762
2559.17	79.1439
2562.65	76.8716
2566.13	46.2072
2569.61	81.9155
2573.09	50.7672
2576.57	69.3278
2580.04	68.4455
2583.51	91.2009
2586.99	47.8763
2590.46	72.3487
2593.93	58.395
2597.4	101.388
2600.86	56.0588
2604.33	71.698
2607.79	80.1091
2611.25	79.0527
2614.71	80.1869
2618.17	61.5298
2621.63	67.4302
2625.09	-0.850403
2628.54	92.0291
2631.99	74.254
2635.45	70.6485
2638.9	88.8032
2642.34	66.526
2645.79	108.172
2649.24	57.9834
2652.68	53.475
2656.12	88.6821
2659.56	52.351
2663.01	87.1027
2666.44	69.6373
2669.88	95.5935
2673.32	57.4356
2676.75	93.7392
2680.18	57.0192
2683.61	83.278
2687.04	66.8956
2690.47	81.9691
2693.9	66.6373
2697.32	103.263
2700.75	62.8448
2704.17	60.6426
2707.59	79.8754
2711.01	70.0592
2714.43	83.7139
2717.84	80.8318
2721.26	78.1468
2724.67	111.98
2728.08	79.6606
2731.49	77.2543
2734.9	109.427
2738.31	86.3844
2741.71	73.5667
2745.12	78.3711
2748.52	46.3995
2751.92	70.8185
2755.32	67.9016
2758.72	86.5286
2762.12	75.9976
2765.52	85.9244
2768.91	84.3941
2772.3	56.3145
2775.7	79.9805
2779.09	101.583
2782.47	72.1906
2785.86	71.927
2789.25	97.0283
2792.63	76.9495
2796.01	85.0507
2799.4	86.5737
2802.78	105.759
2806.15	76.1908
2809.53	75.6834
2812.91	82.6119
2816.28	89.4736
2819.65	95.3753
2823.03	102.364
2826.4	87.1039
2829.76	55.1649
2833.13	95.1437
2836.5	96.1639
2839.86	118.789
2843.22	92.2484
2846.59	82.7181
2849.95	96.8611
2853.3	85.1281
2856.66	83.5361
2860.02	83.9518
2863.37	95.7297
2866.72	77.5828
2870.08	80.988
2873.43	69.3065
2876.77	92.3668
2880.12	89.0925
2883.47	92.3748
2886.81	82.3793
2890.15	98.7791
2893.5	72.6329
2896.84	65.1208
2900.17	110.428
2903.51	80.8721
2906.85	75.7851
2910.18	114.143
2913.52	94.7093
2916.85	121.573
2920.18	112.33
2923.51	116.281
2926.83	102.177
2930.16	104.95
2933.48	105.717
2936.81	108.221
2940.13	122.983
2943.45	127.365
2946.77	126.131
2950.09	134.341
2953.4	126.525
2956.72	129.091
2960.03	94.2774
2963.34	126.215
2966.65	110.356
2969.96	102.319
2973.27	119.79
2976.58	72.5835
2979.88	76.1901
2983.19	117.226
2986.49	77.6171
2989.79	137.578
2993.09	58.6033
2996.39	104.597
2999.68	73.6028
3002.98	49.1551
3006.27	82.0812
3009.57	88.7631
3012.86	98.3315
3016.15	78.7226
3019.43	83.5818
3022.72	82.7725
3026.01	115.003
3029.29	55.6834
3032.57	116.278
3035.86	68.1768
3039.14	80.5314
3042.41	74.9297
3045.69	72.1846
3048.97	86.493
3052.24	97.0261
3055.52	93.3789
3058.79	64.0797
3062.06	88.5282
3065.33	83.7211
3068.6	79.7416
3071.86	66.0639
3075.13	63.9036
3078.39	82.6221
3081.65	71.6397
3084.91	51.0367
3088.17	39.8542
3091.43	65.9612
3094.69	69.3511
3097.95	62.9786
3101.2	111.409
3104.45	60.7769
3107.7	60.0268
3110.95	61.9985
3114.2	107.461
3117.45	68.2855
3120.7	57.6918
3123.94	70.9072
3127.18	96.499
3130.43	75.3803
3133.67	94.2985
3136.91	70.3015
3140.14	72.9416
3143.38	65.0835
3146.61	89.6484
3149.85	112.377
3153.08	77.9058
3156.31	67.233
3159.54	86.1593
3162.77	71.664
3166	81.9797
3169.22	62.6262
3172.45	69.9268
3175.67	46.6532
3178.89	81.5078
3182.11	80.0918
3185.33	65.3439
3188.55	67.6589
3191.77	55.6504
3194.98	76.0473
3198.2	54.5035
3201.41	91.045
3204.62	70.4855
3207.83	97.5587
3211.04	78.9907
3214.25	90.9399
3217.45	116.271
3220.66	61.6954
3223.86	66.136
3227.06	95.4024
3230.26	78.0788
3233.46	81.7538
3236.66	69.192
3239.85	94.9044
3243.05	89.2635
3246.24	117.008
3249.44	111.425
3252.63	110.698
3255.82	88.0518
3259.01	101.636
3262.19	88.3571
3265.38	101.681
3268.56	130.161
3271.75	64.9286
3274.93	115.228
3278.11	103.422
3281.29	95.2415
3284.47	101.215
3287.64	116.745
3290.82	77.8278
3293.99	82.8682
3297.17	123.115
3300.34	121.446
3303.51	108.574
3306.68	102.127
3309.84	117.468
3313.01	133.591
3316.18	138.238
3319.34	116.294
3322.5	119.943
3325.66	130.227
3328.82	131.038
3331.98	130.927
3335.14	123.328
3338.29	93.1648
3341.45	117.831
3344.6	142.496
3347.75	142.872
3350.9	143.485
3354.05	129.948
3357.2	142.912
3360.35	122.937
3363.49	151.154
3366.64	136.969
3369.78	199.235
3372.92	210.628
3376.06	229.703
3379.2	197.841
3382.34	178.278
3385.48	214.429
3388.61	167.46
3391.75	242.551
3394.88	282.632
3398.01	280.788
3401.14	271.967
3404.27	319.215
3407.4	398.959
3410.52	526.485
3413.65	676.135
3416.77	1098.19
3419.89	1934.58
3423.01	4202.03
3426.13	9310.57
3429.25	11181.4
3432.37	6614.56
3435.49	2855.6
3438.6	1413.85
3441.72	836.757
3444.83	619.55
3447.94	464.181
3451.05	383.269
3454.16	283.212
3457.26	305.123
3460.37	323.994
3463.47	274.364
3466.58	260.852
3469.68	277.574
3472.78	305.446
3475.88	298.561
3478.98	345.69
3482.07	357.81
3485.17	460.66
3488.26	571.958
3491.36	666.352
3494.45	926.221
3497.54	1233.08
3500.63	1641.48
3503.72	2300.49
3506.81	2979.22
3509.89	3430.28
3512.98	3352.36
3516.06	2710.93
3519.14	1964.37
3522.22	1409.51
3525.3	994.631
3528.38	832.679
3531.45	617.84
3534.53	492.266
3537.61	397.239
3540.68	332.573
3543.75	259.886
3546.82	276.696
3549.89	217.738
3552.96	211.392
3556.03	180.36
3559.09	167.439
3562.16	151.664
3565.22	160.309
3568.28	138.49
3571.34	109.361
3574.4	130.99
3577.46	108.089
3580.52	124.947
3583.57	105.689
3586.63	75.9183
3589.68	99.2523
3592.73	95.9211
3595.78	108.682
3598.83	79.667
3601.88	94.2403
3604.93	70.8412
3607.97	74.8404
3611.02	59.9156
3614.06	83.7103
3617.1	73.4434
3620.14	60.3964
3623.18	64.3833
3626.22	61.7928
3629.26	46.0641
3632.3	67.0391
3635.33	86.0667
3638.36	81.763
3641.4	64.4047
3644.43	54.6736
3647.46	51.7402
3650.49	36.3474
3653.51	52.1204
3656.54	40.522
3659.57	56.107
3662.59	37.7418
3665.61	27.6772
3668.63	54.936
3671.65	31.4881
3674.67	58.0568
3677.69	40.3359
3680.71	41.5295
3683.72	54.9656
3686.74	38.166
3689.75	35.5654
3692.76	35.824
3695.77	37.9849
3698.78	30.5128
3701.79	48.8145
3704.79	42.4593
3707.8	46.535
3710.81	38.1638
3713.81	29.7233
3716.81	24.9836
3719.81	2.21295
3722.81	36.4485
3725.81	26.8368
3728.81	10.4857
3731.8	18.8393
3734.8	9.02417
3737.79	41.9733
3740.78	11.0639
3743.77	27.6599
3746.76	19.4502
3749.75	29.2357
3752.74	26.6029
3755.73	46.7498
3758.71	18.5038
3761.7	37.6832
3764.68	22.6632
3767.66	37.984
3770.64	23.067
3773.62	46.0692
3776.6	5.77411
3779.58	25.0886
3782.55	28.3818
3785.53	31.6857
3788.5	42.5857
3791.47	46.9246
3794.44	9.85876
3797.41	27.5996
3800.38	14.2399
3803.35	34.9677
3806.32	2.85626
3809.28	18.9319
3812.24	27.5052
3815.21	32.3229
3818.17	24.8675
3821.13	26.9012
3824.09	11.9138
3827.04	43.3877
3830	-4.72394
3832.96	38.1648
3835.91	14.7385
3838.86	7.46588
3841.82	29.6512
3844.77	19.5201
3847.72	42.7105
3850.67	32.6238
3853.61	13.0287
3856.56	32.5443
3859.5	45.4174
3862.45	1.91229
3865.39	24.3141
3868.33	5.57233
3871.27	55.7458
3874.21	32.1219
3877.15	9.39197
3880.09	-11.5273
3883.02	34.7092
3885.96	3.04895
3888.89	15.5371
3891.82	28.0031
3894.75	29.86
3897.68	27.7775
3900.61	27.5364
3903.54	7.08398
3906.47	20.1986
3909.39	5.52179
3912.31	19.6144
3915.24	36.5146
3918.16	5.33984
3921.08	9.83636
3924	18.9909
3926.92	21.3433
3929.83	14.9984
3932.75	1.92596
3935.67	12.9809
3938.58	22.2632
3941.49	22.0996
3944.4	10.3817
3947.31	23.5995
3950.22	23.4877
3953.13	31.0906
3956.04	22.4469
3958.94	42.6052
3961.85	48.437
3964.75	3.50391
3967.65	28.5842
3970.55	8.63104
3973.45	25.1565
3976.35	10.9512
3979.25	12.0608
3982.15	26.5812
3985.04	17.0654
3987.94	29.6285
3990.83	24.8625
3993.72	-2.11145
3996.61	26.8403
3999.5	7.67352
4002.39	27.0439
4005.28	12.7302
4008.16	14.8223
4011.05	13.0704
4013.93	36.3805
4016.81	14.3765
4019.7	2.97186
4022.58	18.5891
4025.46	6.21393
4028.33	9.30469
4031.21	38.5041
4034.09	31.9662
4036.96	12.8525
4039.84	19.89
4042.71	35.6324
4045.58	37.7062
4048.45	7.83508
4051.32	9.97583
4054.19	16.0364
4057.05	27.9954
4059.92	25.3738
4062.78	22.7249
4065.65	28.827
4068.51	14.5077
4071.37	12.8149
4074.23	46.165
4077.09	-1.30627
4079.95	19.3811
4082.81	32.2876
4085.66	12.0548
4088.52	19.0887
4091.37	25.1536
4094.22	17.6025
4097.07	29.5296
4099.92	11.2122
4102.77	23.1715
4105.62	48.8115
4108.47	14.7092
4111.31	2.12842
4114.16	14.9136
4117	3.16791
4119.84	29.4996
4122.69	48.0107
4125.53	17.6754
4128.36	10.8437
4131.2	18.8726
4134.04	21.1295
4136.88	23.593
4139.71	26.2104
4142.54	34.1159
4145.38	1.76385
4148.21	16.64
4151.04	33.5392
4153.87	36.5869
4156.69	27.6454
4159.52	37.0283
4162.35	22.1896
4165.17	10.3777
4168	17.1443
4170.82	25.8982
4173.64	30.7783
4176.46	12.207
4179.28	26.8881
4182.1	23.0439
4184.91	37.8071
4187.73	35.0048
4190.54	4.82159
4193.36	33.4507
4196.17	47.4842
4198.98	48.8906
4201.79	17.9185
4204.6	42.8603
4207.41	72.7126
4210.22	58.4149
4213.02	88.301
4215.83	75.9318
4218.63	80.6851
4221.44	36.1274
4224.24	62.447
4227.04	30.4698
4229.84	44.9975
4232.64	64.5248
4235.43	22.7591
4238.23	16.6356
4241.02	48.2509
4243.82	53.1129
4246.61	24.166
4249.4	14.0474
4252.19	45.778
4254.98	66.5694
4257.77	59.3234
4260.56	35.0209
4263.35	43.7903
4266.13	27.4979
4268.92	29.306
4271.7	29.0933
4274.48	40.9538
4277.26	25.4706
4280.04	30.0649
4282.82	22.4951
4285.6	25.9731
4288.38	16.2231
4291.15	43.851
4293.93	20.8411
4296.7	51.5944
4299.47	32.7554
4302.25	35.1375
4305.02	46.6475
4307.79	9.42767
4310.55	13.8512
4313.32	26.4691
4316.09	-2.70166
4318.85	27.0655
4321.62	30.347
4324.38	36.6345
4327.14	14.3812
4329.9	31.863
4332.66	9.55542
4335.42	10.7104
4338.18	21.995
4340.94	28.3013
4343.69	21.3593
4346.45	-10.0023
4349.2	37.2241
4351.95	43.6646
4354.7	23.7159
4357.45	37.4038
4360.2	33.7192
4362.95	5.4292
4365.7	34.511
4368.44	36.9315
4371.19	47.618
4373.93	11.0102
4376.68	31.8347
4379.42	18.738
4382.16	16.9162
4384.9	29.5171
4387.64	18.6068
4390.37	20.2526
4393.11	15.8047
4395.85	6.612
4398.58	11.4501
4401.31	12.1297
4404.05	38.6635
4406.78	33.1149
4409.51	19.2631
4412.24	31.3132
4414.96	3.73743
4417.69	34.4409
4420.42	37.8378
4423.14	33.0039
4425.87	31.3259
4428.59	25.467
4431.31	24.8245
4434.03	10.5626
4436.75	24.5234
4439.47	40.567
4442.19	29.3137
4444.91	29.598
4447.62	18.3011
4450.34	40.588
4453.05	21.879
4455.76	40.9716
4458.47	30.5918
4461.19	61.181
4463.89	27.7116
4466.6	54.1671
4469.31	24.8944
4472.02	24.0474
4474.72	33.7797
4477.43	42.5156
4480.13	27.0399
4482.83	10.5145
4485.53	15.0892
4488.23	13.2804
4490.93	38.9528
4493.63	40.1697
4496.33	21.1814
4499.02	39.3468
4501.72	24.6466
4504.41	39.5666
4507.11	30.1622
4509.8	51.5235
4512.49	37.884
4515.18	49.7216
4517.87	22.2837
4520.56	59.6608
4523.24	21.6387
4525.93	50.5954
4528.61	18.8896
4531.3	27.6389
4533.98	27.8808
4536.66	21.7354
4539.34	32.6771
4542.02	26.5702
4544.7	15.0962
4547.38	32.5115
4550.05	30.6785
4552.73	29.9612
4555.4	41.1315
4558.08	31.985
4560.75	20.8068
4563.42	34.4712
4566.09	26.7368
4568.76	39.6709
4571.43	1.34692
4574.1	45.9803
4576.77	39.4036
4579.43	14.5982
4582.1	30.1918
4584.76	23.0387
4587.42	27.5721
4590.08	15.72
4592.74	2.7077
4595.4	22.4633
4598.06	29.1877
4600.72	27.122
4603.38	14.2021
4606.03	12.2393
4608.69	22.331
4611.34	37.9308
4613.99	17.2966
4616.64	38.3831
4619.29	18.8243
4621.94	23.477
4624.59	49.0587
4627.24	32.7191
4629.89	35.0967
4632.53	27.5102
4635.18	26.4724
4637.82	20.9716
4640.46	11.0259
4643.1	27.657
4645.74	22.2491
4648.38	12.51
4651.02	13.9699
4653.66	31.185
4656.3	14.7982
4658.93	34.6778
4661.57	33.7279
4664.2	23.9171
4666.83	-6.10809
4669.46	3.98969
4672.09	11.8986
4674.72	19.8067
4677.35	34.4476
4679.98	13.1824
4682.61	14.334
4685.23	16.6091
4687.86	6.51141
4690.48	8.78497
4693.1	25.7102
4695.73	18.9438
4698.34	17.799
4700.96	1.98636
4703.58	30.1866
4706.2	10.9106
4708.82	17.605
4711.43	5.05499
4714.05	30.9681
4716.66	12.7217
4719.28	15.9611
4721.89	4.4538
4724.5	24.656
4727.11	13.181
4729.72	8.52866
4732.33	10.6844
4734.93	10.5718
4737.54	38.8479
4740.14	31.8802
4742.75	24.8897
4745.35	13.3077
4747.95	23.3067
4750.55	13.9012
4753.15	19.3023
4755.75	22.4196
4758.35	17.5681
4760.95	16.1726
4763.54	29.6115
4766.14	30.556
4768.73	29.3231
4771.33	4.17487
4773.92	5.15622
4776.51	33.5426
4779.1	2.57571
4781.69	2.42316
4784.28	25.1355
4786.87	-1.29584
4789.45	12.2935
4792.04	12.1782
4794.63	26.9701
4797.21	21.1706
4799.79	1.64944
4802.37	18.8497
4804.95	25.7778
4807.53	23.5783
4810.11	16.8047
4812.69	24.9913
4815.27	18.2289
4817.84	26.4927
4820.42	20.9391
4822.99	18.8445
4825.57	36.4575
4828.14	29.7409
4830.71	-8.35205
4833.28	-3.45624
4835.85	30.5989
4838.42	-0.534149
4840.98	17.3601
4843.55	31.7858
4846.12	21.5686
4848.68	10.1095
4851.24	17.3058
4853.81	8.97308
4856.37	32.4605
4858.93	34.0269
4861.49	26.1413
4864.05	9.86292
4866.61	14.6945
4869.16	17.2025
4871.72	13.8906
4874.27	22.3356
4876.83	18.9008
4879.38	27.3335
4881.93	27.4515
4884.49	0.230316
4887.04	16.9662
4889.58	31.3629
4892.13	48.1702
4894.68	28.076
4897.23	24.6389
4899.77	8.08542
4902.32	16.5653
4904.86	0.00393677
4907.4	27.5919
4909.95	30.1255
4912.49	34.9757
4915.03	18.3113
4917.57	19.5421
4920.1	17.2473
4922.64	23.33
4925.18	16.2912
4927.71	41.5618
4930.25	26.1685
4932.78	24.0399
4935.31	41.1368
4937.84	23.5188
4940.38	34.631
4942.9	27.6412
4945.43	39.9675
4947.96	34.4151
4950.49	32.4587
4953.01	14.964
4955.54	34.6179
4958.06	39.9775
4960.59	53.8036
4963.11	20.8268
4965.63	46.8725
4968.15	1.98575
4970.67	48.5783
4973.19	33.7033
4975.71	42.9772
4978.22	36.5644
4980.74	45.9151
4983.25	40.775
4985.77	36.8762
4988.28	47.5673
4990.79	21.868
4993.3	42.3388
4995.81	53.1286
4998.32	43.315