File: Data/3-Raman/processed/bu19w-e-ff11-fi07-s_150 (500nm)_633nm_edge_100%_x100_vis_h50um_60sx2_01_0.txt
#Acq. time (s)=	60
#Accumulations=	2
#Range (cm-¹)=	100...4000
#Windows=	1
#Auto scanning=	Off
#Autofocus=	Off
#Macrospot=	Off
#AutoExposure=	Off
#Spike filter=	Multiple accum.
#Delay time (s)=	2
#Binning=	1
#Readout mode=	Signal
#DeNoise=	Off
#ICS correction=	On
#Dark correction=	Off
#Inst. Process=	Off
#Detector Gain=	Best Dynamic
#Detector ADC=	50 kHz HS
#Detector temperature (°C)=	-60.09
#Instrument=	LabRAM HR Evol
#Detector=	SIN-EM FIVIS
#Objective=	x100_VIS
#Grating=	150 (500nm)
#ND Filter=	100%
#Laser=	633nm_Edge
#Hole=	49.98
#Temperature=	0
#Range=	Visible
#StageXY=	75x50mm Scan+
#StageZ=	Z motor
#X (µm)=	0
#Y (µm)=	0
#Z (µm)=	-310.5
#Full time(mm:ss)=	2:04
#Project=	21_11_04
#Sample=	BU19w
#Site=
#Title=	BU19w-E-FF11-FI07-S_150 (500nm)_633nm_Edge_100%_x100_VIS_H50um_60sX2
#Remark=
#Date=	04.11.2021 16:58
#Acquired=	04.11.2021 16:58:36
#Base:Fit=	16.12.2021 17:39:50
#Base:Edit=	16.12.2021 17:48:52
#Base:Edit=	16.12.2021 17:48:53
#Base:Fit=	16.12.2021 17:48:56
#Base:Edit=	16.12.2021 17:48:58
#Base:Edit=	16.12.2021 17:48:59
#Base:Edit=	16.12.2021 17:48:59
#Base:Edit=	16.12.2021 17:49:03
#Peaks:Remove=	16.12.2021 17:49:10
#Base:Edit=	16.12.2021 17:49:12
#Base:Edit=	16.12.2021 17:49:13
#Base:Edit=	16.12.2021 17:49:14
#Peaks:Remove=	16.12.2021 17:49:15
#Peaks:Remove=	16.12.2021 17:49:16
#Peaks:Remove=	16.12.2021 17:49:17
#Base:Sub=	16.12.2021 17:49:21
102.881	141.117
109.397	112.024
115.908	100.19
122.414	92.202
128.914	94.8106
135.409	86.9235
141.898	80.96
148.383	77.0397
154.861	84.7392
161.335	94.4718
167.801	47.722
174.264	31.6083
180.721	16.4187
187.173	19.3844
193.62	2.25443
200.061	5.33266
206.496	-3.7854
212.926	18.5882
219.352	35.2729
225.772	82.4151
232.185	103.643
238.595	48.9138
244.999	24.7888
251.397	52.0119
257.791	48.8369
264.178	56.1684
270.561	35.1063
276.939	52.0377
283.31	54.7162
289.678	37.4527
296.039	60.8871
302.396	55.9167
308.746	106.705
315.093	190.488
321.433	311.037
327.768	205.216
334.099	95.7252
340.423	73.0226
346.743	68.2184
353.058	97.3005
359.367	93.3238
365.671	62.9966
371.971	69.3717
378.265	59.7668
384.553	28.6672
390.837	-4.10014
397.116	0.751381
403.389	-1.81245
409.657	12.5625
415.92	16.5019
422.178	26.0786
428.431	43.8426
434.678	32.0851
440.921	37.2931
447.158	40.5526
453.391	47.4944
459.618	30.2221
465.84	13.1601
472.057	7.36984
478.27	8.20061
484.477	14.6087
490.679	10.7585
496.876	28.3454
503.068	26.374
509.255	31.8689
515.436	40.1974
521.613	36.4671
527.785	35.5993
533.952	34.8047
540.113	30.2158
546.27	14.1644
552.423	18.7079
558.568	12.7969
564.711	7.63506
570.848	8.02341
576.979	4.55461
583.107	12.3337
589.228	25.7366
595.345	23.3828
601.458	40.77
607.565	29.4179
613.667	45.2054
619.764	33.9754
625.856	19.9001
631.944	19.7113
638.026	23.0733
644.104	18.695
650.177	28.4126
656.244	28.5875
662.308	7.21383
668.365	12.0902
674.418	5.9547
680.467	2.66908
686.511	2.2515
692.549	-3.68342
698.582	4.42875
704.611	6.90745
710.635	1.79392
716.655	-2.58314
722.669	-0.376114
728.679	-1.0694
734.683	-3.67607
740.683	-4.41074
746.678	2.3401
752.669	9.12258
758.654	5.71523
764.635	5.28512
770.611	0.240959
776.582	-5.78423
782.549	9.73466
788.511	-4.93198
794.466	5.78431
800.419	-4.32517
806.366	-0.36264
812.309	2.60523
818.247	10.1896
824.18	3.65642
830.108	3.70488
836.033	5.79264
841.952	11.7738
847.865	5.61163
853.776	4.16075
859.681	14.0291
865.58	15.4542
871.476	25.3778
877.366	20.9818
883.253	20.3041
889.134	34.7272
895.012	31.0513
900.883	16.8336
906.751	22.4356
912.614	23.2735
918.473	25.1045
924.326	30.8313
930.174	36.7148
936.019	44.6092
941.859	59.3728
947.693	77.1358
953.525	75.0393
959.35	81.4182
965.171	87.6935
970.988	122.666
976.801	150.758
982.608	168.88
988.411	138.928
994.209	112.843
1000	97.3827
1005.79	90.6374
1011.58	100.315
1017.36	129.223
1023.13	86.6114
1028.9	73.6943
1034.67	67.4814
1040.43	49.7182
1046.19	45.3764
1051.94	40.9178
1057.69	31.5036
1063.44	35.5567
1069.17	21.9954
1074.91	46.2986
1080.64	60.8096
1086.37	91.7545
1092.09	112.059
1097.8	118.774
1103.52	75.2042
1109.22	61.789
1114.93	49.5353
1120.63	45.1255
1126.32	53.2486
1132.01	57.5354
1137.7	74.5745
1143.38	102.485
1149.06	135.261
1154.73	90.1591
1160.4	41.8806
1166.06	33.8258
1171.72	29.7208
1177.38	19.7372
1183.03	20.5797
1188.67	13.7342
1194.31	1.10452
1199.95	1.2505
1205.58	9.36594
1211.21	-4.10347
1216.84	3.14495
1222.46	5.5184
1228.07	-2.08183
1233.68	-7.79169
1239.29	4.52009
1244.89	0.643806
1250.49	2.72363
1256.08	-0.310394
1261.67	8.66844
1267.26	4.49837
1272.84	1.3056
1278.42	6.12248
1283.99	3.91389
1289.56	1.75657
1295.12	0.656784
1300.68	-4.38936
1306.23	2.64029
1311.78	1.78387
1317.33	-1.03067
1322.87	-0.809624
1328.41	-3.59735
1333.94	0.700897
1339.47	-7.26377
1345	9.21236
1350.52	5.21095
1356.04	-0.896072
1361.55	6.28795
1367.06	12.3801
1372.56	25.6216
1378.06	10.095
1383.56	-2.35135
1389.05	-0.426689
1394.53	-0.508331
1400.02	-0.487823
1405.5	3.64272
1410.97	7.81115
1416.44	-1.40741
1421.91	-9.62206
1427.37	-2.28945
1432.83	-4.28654
1438.28	-1.08508
1443.73	-4.15089
1449.17	-2.02195
1454.62	1.0871
1460.05	3.09012
1465.48	3.99686
1470.91	8.0317
1476.34	7.88486
1481.76	-0.624771
1487.17	-3.86649
1492.59	-0.764503
1497.99	2.3845
1503.4	-2.87823
1508.8	4.56981
1514.19	-1.71872
1519.59	-8.01824
1524.97	-0.449371
1530.36	8.24437
1535.74	0.86689
1541.11	0.919815
1546.48	4.11184
1551.85	9.33768
1557.21	1.4696
1562.57	1.19088
1567.93	10.6099
1573.28	1.6953
1578.62	4.68118
1583.97	5.56098
1589.3	7.543
1594.64	3.09901
1599.97	4.08143
1605.3	-0.296822
1610.62	7.29419
1615.94	11.7425
1621.25	10.7994
1626.56	2.16582
1631.87	2.25784
1637.17	12.211
1642.47	9.88848
1647.76	4.2617
1653.05	10.7691
1658.34	6.14954
1663.62	10.3644
1668.9	-8.73314
1674.18	3.21278
1679.45	-1.49645
1684.71	2.61344
1689.98	12.2388
1695.23	3.09683
1700.49	1.83436
1705.74	8.70279
1710.99	2.98637
1716.23	1.6312
1721.47	2.73409
1726.7	7.0864
1731.94	-0.853348
1737.16	-7.71223
1742.39	4.5626
1747.61	-0.0746384
1752.82	-1.37923
1758.03	-1.59587
1763.24	4.931
1768.44	-7.78191
1773.64	-1.22746
1778.84	4.2411
1784.03	-0.458031
1789.22	5.11406
1794.41	3.88741
1799.59	7.26044
1804.76	-4.24344
1809.94	7.16187
1815.11	2.45482
1820.27	5.81437
1825.43	1.0929
1830.59	-1.31947
1835.74	3.25002
1840.89	-0.367859
1846.04	6.483
1851.18	-3.03368
1856.32	-3.24368
1861.45	4.81032
1866.58	8.21894
1871.71	6.89756
1876.83	-3.91058
1881.95	11.2176
1887.07	8.62235
1892.18	-2.33369
1897.29	-0.297127
1902.39	-6.4533
1907.49	4.05996
1912.59	5.20206
1917.68	-1.95388
1922.77	3.78358
1927.86	-7.12708
1932.94	4.6982
1938.02	-0.277039
1943.09	3.11688
1948.16	-3.14475
1953.23	4.99497
1958.29	-0.14238
1963.35	-4.09623
1968.41	0.353806
1973.46	-4.87978
1978.51	-0.477966
1983.55	6.32134
1988.59	-3.70956
1993.63	6.71736
1998.66	3.94183
2003.69	1.19748
2008.72	-6.32044
2013.74	5.44168
2018.76	-10.5058
2023.77	-4.75925
2028.78	-0.154457
2033.79	-0.319923
2038.79	0.739868
2043.79	3.03168
2048.79	4.13628
2053.78	1.53752
2058.77	-5.92303
2063.76	1.29639
2068.74	8.54802
2073.72	2.29144
2078.69	-1.54089
2083.66	8.16473
2088.63	-3.16211
2093.59	-7.04565
2098.55	17.6559
2103.51	-6.02279
2108.46	2.63831
2113.41	12.6347
2118.36	0.119942
2123.3	-4.92683
2128.24	-6.23271
2133.17	-5.04191
2138.11	7.54412
2143.03	1.09501
2147.96	3.49992
2152.88	9.68308
2157.79	0.516144
2162.71	5.34962
2167.62	10.1372
2172.52	0.889938
2177.43	-0.67099
2182.32	13.0622
2187.22	-5.24323
2192.11	2.11554
2197	4.40278
2201.89	-7.3469
2206.77	5.3364
2211.64	0.0871201
2216.52	-2.5724
2221.39	15.4913
2226.26	-1.38219
2231.12	-0.130035
2235.98	-0.175171
2240.84	-0.223228
2245.69	10.2236
2250.54	4.95325
2255.39	2.28004
2260.23	-0.385712
2265.07	-0.459869
2269.9	7.3654
2274.74	-3.42841
2279.57	2.99284
2284.39	2.70605
2289.21	3.71104
2294.03	2.05069
2298.84	1.76372
2303.66	-5.12865
2308.46	8.06607
2313.27	6.65933
2318.07	1.27876
2322.87	-9.50085
2327.66	13.39
2332.45	2.63966
2337.24	8.12827
2342.02	1.43016
2346.8	-3.89651
2351.58	-1.0571
2356.35	5.86479
2361.12	5.82832
2365.89	7.15646
2370.65	1.57306
2375.41	1.49408
2380.17	1.38521
2384.92	-5.75702
2389.67	-0.441269
2394.42	7.60474
2399.16	-10.8447
2403.9	1.31528
2408.64	-3.20193
2413.37	-1.92366
2418.1	5.38522
2422.83	-4.33801
2427.55	-1.65501
2432.27	-4.46944
2436.99	1.24754
2441.7	4.16205
2446.41	-2.8768
2451.11	-2.80879
2455.82	7.27046
2460.51	-2.70192
2465.21	-1.21042
2469.9	6.04155
2474.59	-1.17392
2479.28	6.11388
2483.96	13.4062
2488.64	-5.57974
2493.32	4.58209
2497.99	3.07913
2502.66	14.7484
2507.32	7.31847
2511.99	7.18825
2516.65	-3.29021
2521.3	6.91452
2525.96	8.27893
2530.61	11.1257
2535.25	9.57607
2539.89	3.59109
2544.53	-0.915939
2549.17	12.4978
2553.8	-3.95821
2558.43	-2.54602
2563.06	-1.08028
2567.68	0.441788
2572.3	-5.55261
2576.92	9.58838
2581.53	-14.7018
2586.14	-7.27307
2590.75	6.16914
2595.35	10.5639
2599.96	4.3714
2604.55	-3.41501
2609.15	10.1502
2613.74	11.4457
2618.33	11.231
2622.91	0.297455
2627.49	7.78008
2632.07	12.3297
2636.64	7.77737
2641.22	14.1139
2645.78	-1.18767
2650.35	14.4814
2654.91	5.23004
2659.47	0.470001
2664.03	8.15688
2668.58	11.1594
2673.13	9.58078
2677.67	-10.6462
2682.22	0.811172
2686.76	12.3096
2691.29	7.87256
2695.83	1.53941
2700.36	-0.090683
2704.89	1.47346
2709.41	22.3431
2713.93	11.0058
2718.45	6.16464
2722.96	17.4509
2727.47	14.0816
2731.98	9.00232
2736.49	-9.1058
2740.99	15.0488
2745.49	3.50677
2749.98	9.9566
2754.47	13.3775
2758.96	11.7031
2763.45	5.02797
2767.93	-1.58324
2772.41	6.58954
2776.89	19.8629
2781.36	-9.7765
2785.84	3.68356
2790.3	-1.13551
2794.77	0.676483
2799.23	-0.930527
2803.69	5.80957
2808.14	-2.64607
2812.59	0.655121
2817.04	3.9062
2821.49	-4.67426
2825.93	-1.38277
2830.37	15.4946
2834.81	1.76115
2839.24	15.2558
2843.67	8.32149
2848.1	-1.99983
2852.53	-7.16748
2856.95	11.7561
2861.37	11.8458
2865.78	5.11243
2870.19	-3.37639
2874.6	-8.45035
2879.01	12.6239
2883.41	16.3911
2887.81	-9.64822
2892.21	-5.95163
2896.6	4.86493
2901	5.15121
2905.38	3.55409
2909.77	-3.44351
2914.15	-1.64268
2918.53	-7.01245
2922.91	-15.9666
2927.28	-1.47337
2931.65	2.28137
2936.02	-1.28239
2940.38	-1.32779
2944.74	-3.21387
2949.1	-3.3629
2953.46	11.1056
2957.81	5.49809
2962.16	-12.9224
2966.5	-7.53706
2970.85	5.2455
2975.19	7.04807
2979.52	14.3875
2983.86	1.49879
2988.19	7.13824
2992.52	12.8562
2996.85	1.85837
3001.17	2.06163
3005.49	13.5609
3009.8	17.6018
3014.12	-6.68097
3018.43	6.8371
3022.74	16.6412
3027.04	-0.300613
3031.34	18.8994
3035.64	13.1969
3039.94	17.0443
3044.23	15.1409
3048.52	-7.99837
3052.81	17.004
3057.09	22.8013
3061.38	24.732
3065.65	36.3686
3069.93	15.0141
3074.2	32.5222
3078.47	18.9142
3082.74	13.0681
3087	46.4464
3091.27	34.9493
3095.52	29.3919
3099.78	33.7037
3104.03	4.38576
3108.28	46.5658
3112.53	39.1691
3116.77	29.6936
3121.01	36.2932
3125.25	28.853
3129.49	35.6389
3133.72	50.7278
3137.95	43.3573
3142.18	54.3834
3146.4	71.6192
3150.62	76.4417
3154.84	62.3582
3159.06	62.7825
3163.27	54.8399
3167.48	50.9848
3171.69	42.9052
3175.89	60.0389
3180.09	81.3089
3184.29	62.294
3188.49	68.5946
3192.68	62.3001
3196.87	96.5549
3201.06	71.5764
3205.24	67.9556
3209.42	85.9438
3213.6	76.029
3217.78	98.6366
3221.95	66.8658
3226.12	87.3465
3230.29	75.0162
3234.45	77.9758
3238.61	76.4965
3242.77	75.1351
3246.93	60.4247
3251.08	76.7154
3255.23	99.6101
3259.38	75.4206
3263.53	46.7705
3267.67	68.2314
3271.81	71.3746
3275.95	62.7026
3280.08	79.0298
3284.21	61.0123
3288.34	77.3887
3292.47	56.9524
3296.59	64.0932
3300.71	45.9241
3304.83	76.2954
3308.95	41.8166
3313.06	83.8629
3317.17	84.1868
3321.27	68.2543
3325.38	82.767
3329.48	76.3119
3333.58	91.2543
3337.67	75.5976
3341.77	64.3067
3345.86	83.6741
3349.95	91.1243
3354.03	89.0924
3358.11	80.0508
3362.19	70.9855
3366.27	73.8236
3370.34	93.5019
3374.42	81.8831
3378.48	113.508
3382.55	72.7864
3386.61	87.5107
3390.68	80.4579
3394.73	83.098
3398.79	105.253
3402.84	103.085
3406.89	81.4037
3410.94	83.9833
3414.98	108.466
3419.03	94.0164
3423.06	94.1434
3427.1	89.4436
3431.14	84.8391
3435.17	92.5389
3439.2	85.654
3443.22	78.8007
3447.25	79.4654
3451.27	97.4354
3455.28	51.2884
3459.3	81.9629
3463.31	92.9581
3467.32	81.5357
3471.33	80.0157
3475.34	58.1573
3479.34	74.1361
3483.34	107.903
3487.33	70.7709
3491.33	86.8465
3495.32	69.777
3499.31	72.9966
3503.3	71.0054
3507.28	76.6202
3511.26	74.3481
3515.24	54.0414
3519.22	56.8349
3523.19	67.3517
3527.16	83.0951
3531.13	57.6334
3535.1	45.2975
3539.06	53.7675
3543.02	41.4585
3546.98	49.7867
3550.93	55.4389
3554.89	45.2656
3558.84	45.6715
3562.78	30.5279
3566.73	20.6572
3570.67	47.4981
3574.61	29.8605
3578.55	49.0504
3582.48	44.7118
3586.41	48.308
3590.35	1.51767
3594.27	28.9325
3598.2	21.818
3602.12	33.3163
3606.04	18.0345
3609.95	21.4236
3613.87	32.9064
3617.78	20.1156
3621.69	20.684
3625.6	18.3838
3629.5	18.7653
3633.4	-10.6709
3637.3	3.27632
3641.2	11.9885
3645.09	9.97162
3648.98	21.4495
3652.87	-2.54382
3656.76	19.7414
3660.64	-1.60631
3664.53	-1.15793
3668.4	2.09045
3672.28	-11.0872
3676.16	-15.969
3680.03	1.18817
3683.9	-3.50143
3687.76	8.42706
3691.63	-12.7753
3695.49	7.46609
3699.35	-13.8795
3703.2	-10.2558
3707.06	-6.57118
3710.91	2.73888
3714.76	-4.81075
3718.6	-18.1104
3722.45	-0.438492
3726.29	8.76558
3730.13	-4.6721
3733.97	-9.60382
3737.8	-31.6315
3741.63	-19.5744
3745.46	9.62671
3749.29	4.57121
3753.11	2.3017
3756.93	-11.4832
3760.75	-16.7342
3764.57	3.78862
3768.39	-12.9236
3772.2	-0.904755
3776.01	-3.22299
3779.81	3.12749
3783.62	-4.83231
3787.42	-12.8047
3791.22	-17.9472
3795.02	8.78017
3798.81	18.2706
3802.61	-15.7533
3806.4	-9.13713
3810.18	15.0133
3813.97	7.0519
3817.75	-9.748
3821.53	-9.0246
3825.31	-5.41185
3829.09	-1.7843
3832.86	4.85048
3836.63	20.3466
3840.4	-11.5209
3844.17	4.0182
3847.93	13.4405
3851.69	5.01929
3855.45	2.48103
3859.21	11.7492
3862.96	3.22983
3866.71	9.84653
3870.46	-7.27293
3874.21	-0.8862
3877.95	-6.4382
3881.69	-0.0343475
3885.44	6.40323
3889.17	-26.0767
3892.91	7.4135
3896.64	-0.976089
3900.37	8.60655
3904.1	6.13177
3907.82	-11.4695
3911.55	-1.88554
3915.27	10.7775
3918.99	14.4396
3922.7	-9.20961
3926.42	3.58255
3930.13	4.15408
3933.84	7.69574
3937.54	-7.20583
3941.25	-0.613297
3944.95	-3.18703
3948.65	3.42787
3952.35	0.718903
3956.04	-2.04861
3959.73	1.28741
3963.42	-1.61856
3967.11	1.60419
3970.8	4.75839
3974.48	11.0213
3978.16	17.2533
3981.84	1.69281
3985.52	-7.68416
3989.19	-7.77495
3992.86	-7.81746
3996.53	4.60237
3998.37	-4.69235