File: Data/3-Raman/processed/bu19w-e-ff11-fi08-v_150 (500nm)_633nm_edge_100%_x100_vis_h50um_60sx2_01_0.txt
#Acq. time (s)=	60
#Accumulations=	2
#Range (cm-¹)=	100...4000
#Windows=	1
#Auto scanning=	Off
#Autofocus=	Off
#Macrospot=	Off
#AutoExposure=	Off
#Spike filter=	Multiple accum.
#Delay time (s)=	2
#Binning=	1
#Readout mode=	Signal
#DeNoise=	Off
#ICS correction=	On
#Dark correction=	Off
#Inst. Process=	Off
#Detector Gain=	Best Dynamic
#Detector ADC=	50 kHz HS
#Detector temperature (°C)=	-60.09
#Instrument=	LabRAM HR Evol
#Detector=	SIN-EM FIVIS
#Objective=	x100_VIS
#Grating=	150 (500nm)
#ND Filter=	100%
#Laser=	633nm_Edge
#Hole=	49.98
#Temperature=	0
#Range=	Visible
#StageXY=	75x50mm Scan+
#StageZ=	Z motor
#X (µm)=	0
#Y (µm)=	0
#Z (µm)=	-268.8
#Full time(mm:ss)=	2:04
#Project=	21_11_04
#Sample=	BU19w
#Site=
#Title=	BU19w-E-FF11-FI08-V_150 (500nm)_633nm_Edge_100%_x100_VIS_H50um_60sX2
#Remark=
#Date=	04.11.2021 16:22
#Acquired=	04.11.2021 16:22:51
#Base:Fit=	16.12.2021 17:39:50
#Base:Edit=	16.12.2021 17:51:23
#Base:Edit=	16.12.2021 17:51:25
#Base:Edit=	16.12.2021 17:51:25
#Base:Edit=	16.12.2021 17:51:25
#Base:Sub=	16.12.2021 17:51:29
102.881	199.464
109.397	180.064
115.908	155.58
122.414	127.82
128.914	148.447
135.409	172.481
141.898	160.623
148.383	151.249
154.861	214.242
161.335	231.833
167.801	108.976
174.264	68.8193
180.721	39.5058
187.173	19.1093
193.62	21.0284
200.061	6.16615
206.496	8.03326
212.926	26.3808
219.352	80.2916
225.772	220.102
232.185	302.518
238.595	145.625
244.999	80.5418
251.397	75.5901
257.791	96.435
264.178	84.3084
270.561	68.6252
276.939	73.0742
283.31	57.7148
289.678	48.1354
296.039	36.7489
302.396	74.7016
308.746	167.491
315.093	388.676
321.433	538.995
327.768	319.691
334.099	140.26
340.423	109.953
346.743	117.405
353.058	145.592
359.367	129.46
365.671	67.3006
371.971	28.8071
378.265	13.8849
384.553	0.955048
390.837	7.96591
397.116	14.2231
403.389	21.6073
409.657	26.1728
415.92	32.5511
422.178	51.2036
428.431	101.59
434.678	101.507
440.921	102.343
447.158	141.59
453.391	159.04
459.618	106.572
465.84	62.94
472.057	32.5366
478.27	38.6207
484.477	40.0326
490.679	43.297
496.876	74.5269
503.068	101.131
509.255	117.508
515.436	129.282
521.613	132.8
527.785	134.571
533.952	114.885
540.113	83.756
546.27	78.7148
552.423	56.4463
558.568	51.9863
564.711	40.6352
570.848	39.5081
576.979	45.7393
583.107	61.2847
589.228	90.8367
595.345	95.3274
601.458	86.1043
607.565	117.22
613.667	119.544
619.764	111.721
625.856	62.5113
631.944	49.5441
638.026	49.4511
644.104	53.7983
650.177	65.6153
656.244	46.2559
662.308	41.912
668.365	16.14
674.418	10.2284
680.467	12.7541
686.511	8.81914
692.549	8.7079
698.582	15.1614
704.611	9.38364
710.635	13.8378
716.655	7.71227
722.669	-1.22896
728.679	13.2016
734.683	0.373322
740.683	12.8094
746.678	12.1529
752.669	7.81447
758.654	24.9889
764.635	14.388
770.611	21.6096
776.582	12.8787
782.549	17.1809
788.511	22.3482
794.466	21.7895
800.419	17.3497
806.366	23.1813
812.309	30.8181
818.247	24.2506
824.18	18.6035
830.108	33.549
836.033	32.8061
841.952	28.5143
847.865	36.4178
853.776	46.285
859.681	51.5253
865.58	52.0769
871.476	64.8971
877.366	63.3553
883.253	71.201
889.134	81.7761
895.012	77.0683
900.883	75.9609
906.751	73.7983
912.614	65.9556
918.473	75.1501
924.326	90.172
930.174	105.441
936.019	126.582
941.859	163.314
947.693	212.733
953.525	222.545
959.35	216.935
965.171	264.667
970.988	324.848
976.801	413.484
982.608	442.795
988.411	397.987
994.209	296.814
1000	248.552
1005.79	258.751
1011.58	272.224
1017.36	306.021
1023.13	273.176
1028.9	203.185
1034.67	179.039
1040.43	165.448
1046.19	133.407
1051.94	132.041
1057.69	115.963
1063.44	102.565
1069.17	117.109
1074.91	130.664
1080.64	183.867
1086.37	241.799
1092.09	349.153
1097.8	357.629
1103.52	254.913
1109.22	191.249
1114.93	177.335
1120.63	154.85
1126.32	176.875
1132.01	200.059
1137.7	256.667
1143.38	336.113
1149.06	425.335
1154.73	277.072
1160.4	141.117
1166.06	104.393
1171.72	80.5539
1177.38	74.3869
1183.03	51.7115
1188.67	39.0207
1194.31	41.0962
1199.95	27.6435
1205.58	29.0162
1211.21	19.6156
1216.84	15.1446
1222.46	19.6267
1228.07	3.164
1233.68	11.5911
1239.29	11.9466
1244.89	20.254
1250.49	5.2363
1256.08	20.4416
1261.67	15.3202
1267.26	12.2006
1272.84	82.4838
1278.42	41.0003
1283.99	7.72111
1289.56	14.6195
1295.12	4.57889
1300.68	13.592
1306.23	9.7107
1311.78	5.94537
1317.33	17.3135
1322.87	15.6706
1328.41	0.878922
1333.94	7.32257
1339.47	1.51443
1345	-2.36416
1350.52	15.2326
1356.04	9.23033
1361.55	15.4838
1367.06	17.5528
1372.56	22.6608
1378.06	192.081
1383.56	22.5834
1389.05	14.3259
1394.53	11.2607
1400.02	18.59
1405.5	17.6998
1410.97	-0.690704
1416.44	8.77185
1421.91	13.1102
1427.37	15.4114
1432.83	4.19406
1438.28	14.8252
1443.73	11.9021
1449.17	5.77989
1454.62	8.99924
1460.05	5.85586
1465.48	17.3623
1470.91	8.89719
1476.34	13.0495
1481.76	10.9438
1487.17	5.71104
1492.59	-1.59396
1497.99	7.98071
1503.4	8.11425
1508.8	10.3986
1514.19	7.41594
1519.59	9.77261
1524.97	11.0913
1530.36	5.98088
1535.74	7.31174
1541.11	2.08497
1546.48	2.13538
1551.85	10.7072
1557.21	12.6612
1562.57	13.5517
1567.93	19.8249
1573.28	6.69396
1578.62	11.9308
1583.97	9.68157
1589.3	9.61058
1594.64	10.6565
1599.97	11.7466
1605.3	13.9674
1610.62	15.1855
1615.94	14.3144
1621.25	13.4732
1626.56	14.8079
1631.87	10.6357
1637.17	5.25494
1642.47	10.7519
1647.76	14.0722
1653.05	16.2522
1658.34	8.40383
1663.62	13.8221
1668.9	13.6724
1674.18	14.6217
1679.45	16.6573
1684.71	9.76811
1689.98	9.51762
1695.23	13.7519
1700.49	10.3739
1705.74	9.56413
1710.99	16.2041
1716.23	10.4799
1721.47	9.45049
1726.7	10.5352
1731.94	10.5461
1737.16	12.7938
1742.39	12.7867
1747.61	21.7989
1752.82	14.9501
1758.03	14.8309
1763.24	15.7869
1768.44	9.96027
1773.64	9.80766
1778.84	19.9077
1784.03	5.08234
1789.22	11.8799
1794.41	26.7212
1799.59	13.0608
1804.76	22.2969
1809.94	14.2848
1815.11	17.7337
1820.27	8.49169
1825.43	11.9511
1830.59	11.955
1835.74	7.31928
1840.89	8.44305
1846.04	10.7096
1851.18	15.3079
1856.32	6.99609
1861.45	13.9651
1866.58	11.5819
1871.71	19.7583
1876.83	17.2947
1881.95	13.6266
1887.07	17.0164
1892.18	15.5971
1897.29	12.9837
1902.39	14.0145
1907.49	9.21558
1912.59	10.4316
1917.68	12.894
1922.77	4.38387
1927.86	18.6714
1932.94	7.82651
1938.02	8.92699
1943.09	11.1973
1948.16	6.21661
1953.23	10.8193
1958.29	11.7822
1963.35	12.7254
1968.41	16.0439
1973.46	19.3116
1978.51	21.3712
1983.55	7.78342
1988.59	8.65257
1993.63	13.1408
1998.66	16.4495
2003.69	12.5772
2008.72	12.3527
2013.74	15.7687
2018.76	5.91982
2023.77	11.7458
2028.78	17.6415
2033.79	7.88911
2038.79	10.2327
2043.79	4.09825
2048.79	24.7308
2053.78	14.9097
2058.77	14.8605
2063.76	14.8314
2068.74	11.1199
2073.72	11.0694
2078.69	22.0937
2083.66	8.44177
2088.63	18.1854
2093.59	10.6783
2098.55	15.6116
2103.51	23.0766
2108.46	19.3851
2113.41	30.7229
2118.36	20.8132
2123.3	13.3503
2128.24	18.4493
2133.17	9.61987
2138.11	7.05868
2143.03	20.9982
2147.96	14.5701
2152.88	23.3716
2157.79	19.3819
2162.71	23.0082
2167.62	15.0779
2172.52	12.287
2177.43	15.9103
2182.32	11.7837
2187.22	22.9835
2192.11	4.7999
2197	8.42428
2201.89	10.8411
2206.77	13.3156
2211.64	14.5603
2216.52	6.8054
2221.39	5.51197
2226.26	9.40337
2231.12	15.9162
2235.98	13.3332
2240.84	14.6555
2245.69	27.7897
2250.54	6.8229
2255.39	21.3062
2260.23	13.4324
2265.07	12.094
2269.9	19.9745
2274.74	17.2023
2279.57	10.3917
2284.39	12.8138
2289.21	20.5209
2294.03	13.5883
2298.84	16.0132
2303.66	9.17171
2308.46	9.06878
2313.27	15.713
2318.07	15.736
2322.87	17.1079
2327.66	3.68723
2332.45	21.3084
2337.24	16.0125
2342.02	2.5411
2346.8	23.1601
2351.58	17.8717
2356.35	12.4853
2361.12	2.8334
2365.89	12.4505
2370.65	20.7243
2375.41	1.29
2380.17	17.8591
2384.92	28.8312
2389.67	20.2857
2394.42	20.0175
2399.16	14.1283
2403.9	9.619
2408.64	9.30893
2413.37	12.0127
2418.1	15.1558
2422.83	19.508
2427.55	19.4227
2432.27	15.247
2436.99	-0.222
2441.7	-1.58286
2446.41	12.7112
2451.11	5.67099
2455.82	11.4648
2460.51	1.49132
2465.21	11.6266
2469.9	13.1223
2474.59	16.053
2479.28	19.0169
2483.96	8.86081
2488.64	13.1994
2493.32	0.00440979
2497.99	10.2022
2502.66	17.476
2507.32	5.63628
2511.99	2.55771
2516.65	17.1326
2521.3	8.17285
2525.96	9.53484
2530.61	9.41721
2535.25	12.3064
2539.89	15.2342
2544.53	21.165
2549.17	12.2194
2553.8	-4.25267
2558.43	9.1391
2563.06	9.11232
2567.68	1.60446
2572.3	18.2378
2576.92	18.2816
2581.53	10.6773
2586.14	13.5784
2590.75	11.8385
2595.35	11.6706
2599.96	0.897598
2604.55	3.78445
2609.15	12.7705
2613.74	15.5986
2618.33	35.2826
2622.91	15.18
2627.49	44.1447
2632.07	5.73303
2636.64	7.30301
2641.22	21.3338
2645.78	12.2253
2650.35	23.243
2654.91	18.67
2659.47	24.8573
2664.03	12.2408
2668.58	18.3779
2673.13	18.3715
2677.67	26.4997
2682.22	17.5102
2686.76	27.4502
2691.29	39.0083
2695.83	26.3353
2700.36	31.1669
2704.89	23.1407
2709.41	21.4966
2713.93	13.3833
2718.45	11.7753
2722.96	19.8308
2727.47	18.0942
2731.98	21.152
2736.49	32.3239
2740.99	14.241
2745.49	5.96793
2749.98	10.798
2754.47	15.8497
2758.96	24.0254
2763.45	27.236
2767.93	10.8073
2772.41	25.61
2776.89	19.1069
2781.36	20.958
2785.84	29.5291
2790.3	28.1319
2794.77	6.60538
2799.23	25.165
2803.69	5.06975
2808.14	10.1219
2812.59	11.7873
2817.04	21.856
2821.49	16.7285
2825.93	4.82381
2830.37	1.36006
2834.81	18.2842
2839.24	7.9917
2843.67	11.3363
2848.1	18.1653
2852.53	4.51794
2856.95	1.18214
2861.37	1.28708
2865.78	1.46869
2870.19	15.5323
2874.6	12.2965
2879.01	12.5557
2883.41	9.36407
2887.81	25.4855
2892.21	15.2522
2896.6	13.814
2901	15.9552
2905.38	18.0112
2909.77	16.4773
2914.15	14.8226
2918.53	7.77777
2922.91	11.5282
2927.28	26.1766
2931.65	8.38852
2936.02	12.1814
2940.38	6.81371
2944.74	28.7081
2949.1	19.6082
2953.46	19.6283
2957.81	1.36241
2962.16	25.1592
2966.5	17.8988
2970.85	32.6897
2975.19	8.9091
2979.52	25.6008
2983.86	23.9506
2988.19	14.9528
2992.52	24.5306
2996.85	19.2795
3001.17	27.1349
3005.49	29.4643
3009.8	24.2762
3014.12	17.1311
3018.43	32.7542
3022.74	42.7794
3027.04	29.8717
3031.34	22.5486
3035.64	18.9376
3039.94	28.727
3044.23	32.7918
3048.52	42.6095
3052.81	46.666
3057.09	39.1786
3061.38	43.2689
3065.65	49.3173
3069.93	53.445
3074.2	49.8148
3078.47	42.2939
3082.74	66.0044
3087	64.4585
3091.27	64.9844
3095.52	61.677
3099.78	50.4715
3104.03	86.8312
3108.28	77.7497
3112.53	90.6346
3116.77	91.5694
3121.01	96.5835
3125.25	89.5768
3129.49	109.004
3133.72	104.191
3137.95	111.607
3142.18	116.929
3146.4	109.773
3150.62	108.706
3154.84	122.03
3159.06	122.856
3163.27	125.799
3167.48	101.354
3171.69	125.262
3175.89	109.039
3180.09	98.9218
3184.29	126.832
3188.49	120.767
3192.68	119.082
3196.87	119.661
3201.06	120.614
3205.24	110.96
3209.42	99.2051
3213.6	100.352
3217.78	101.563
3221.95	100.514
3226.12	114.776
3230.29	98.3735
3234.45	99.4343
3238.61	93.8308
3242.77	74.9776
3246.93	87.2328
3251.08	79.2255
3255.23	75.4586
3259.38	87.4557
3263.53	43.2697
3267.67	83.0299
3271.81	54.5352
3275.95	80.3411
3280.08	67.221
3284.21	54.0422
3288.34	59.1892
3292.47	57.4205
3296.59	87.9127
3300.71	56.1949
3304.83	47.4899
3308.95	45.7121
3313.06	57.8284
3317.17	49.0622
3321.27	44.984
3325.38	66.6997
3329.48	62.7783
3333.58	44.9121
3337.67	50.5388
3341.77	29.938
3345.86	35.2431
3349.95	38.1172
3354.03	52.9167
3358.11	15.3857
3362.19	44.6676
3366.27	57.2654
3370.34	55.5114
3374.42	41.6489
3378.48	39.7175
3382.55	47.41
3386.61	28.5197
3390.68	57.9388
3394.73	19.6233
3398.79	37.0558
3402.84	39.8988
3406.89	40.2733
3410.94	28.462
3414.98	31.228
3419.03	26.6939
3423.06	5.06255
3427.1	20.0293
3431.14	37.5293
3435.17	35.5536
3439.2	28.7284
3443.22	29.2764
3447.25	32.3911
3451.27	23.1983
3455.28	31.3479
3459.3	17.2981
3463.31	8.15454
3467.32	16.4496
3471.33	39.8163
3475.34	2.80321
3479.34	18.6295
3483.34	31.9997
3487.33	17.504
3491.33	30.8975
3495.32	34.1089
3499.31	39.8272
3503.3	35.2453
3507.28	33.1491
3511.26	36.0442
3515.24	18.3515
3519.22	34.0412
3523.19	34.3124
3527.16	29.4733
3531.13	11.7315
3535.1	27.6651
3539.06	25.6709
3543.02	21.0108
3546.98	0.690582
3550.93	37.4235
3554.89	27.2348
3558.84	35.3752
3562.78	43.5936
3566.73	12.7448
3570.67	26.336
3574.61	34.723
3578.55	40.5938
3582.48	38.6519
3586.41	39.355
3590.35	29.4342
3594.27	27.4243
3598.2	28.0556
3602.12	36.6495
3606.04	26.4886
3609.95	40.3992
3613.87	22.0558
3617.78	22.4794
3621.69	25.516
3625.6	17.6057
3629.5	17.7756
3633.4	9.77803
3637.3	26.2093
3641.2	18.3978
3645.09	18.7898
3648.98	-2.67734
3652.87	16.5947
3656.76	16.7904
3660.64	16.9704
3664.53	22.5904
3668.4	36.4708
3672.28	31.2032
3676.16	26.0172
3680.03	18.1459
3683.9	15.8212
3687.76	19.0687
3691.63	0.199387
3695.49	11.6935
3699.35	14.929
3703.2	18.1557
3707.06	-0.945801
3710.91	19.1084
3714.76	13.925
3718.6	8.64671
3722.45	14.6053
3726.29	26.201
3730.13	3.82468
3733.97	26.8246
3737.8	24.2987
3741.63	4.63017
3745.46	13.4188
3749.29	-3.52774
3753.11	10.9076
3756.93	19.5934
3760.75	11.0619
3764.57	2.50862
3768.39	19.7731
3772.2	5.54553
3776.01	17.1515
3779.81	0.0684967
3783.62	6.04076
3787.42	9.16048
3791.22	18.0385
3795.02	3.86607
3798.81	18.6809
3802.61	21.9608
3806.4	7.82253
3810.18	5.29739
3813.97	2.73097
3817.75	6.01106
3821.53	21.0353
3825.31	21.3717
3829.09	9.94499
3832.86	-1.47037
3836.63	10.7093
3840.4	11.0661
3844.17	-3.33661
3847.93	17.6879
3851.69	6.0551
3855.45	15.1903
3859.21	21.3049
3862.96	15.5934
3866.71	-7.74561
3870.46	7.74699
3874.21	-0.895935
3877.95	17.3867
3881.69	-3.16313
3885.44	27.1938
3889.17	9.71686
3892.91	13.273
3896.64	13.9511
3900.37	5.57846
3904.1	0.208633
3907.82	9.93617
3911.55	7.6579
3915.27	8.45673
3918.99	12.3815
3922.7	22.5007
3926.42	14.369
3930.13	0.0904083
3933.84	4.09944
3937.54	1.99077
3941.25	-3.10735
3944.95	7.24612
3948.65	-0.847382
3952.35	24.9891
3956.04	26.1771
3959.73	11.8817
3963.42	13.0667
3967.11	20.4623
3970.8	27.8715
3974.48	32.2621
3978.16	27.3945
3981.84	34.9392
3985.52	27.0391
3989.19	-2.50052
3992.86	45.6215
3996.53	22.5285
3998.37	23.4375