File: Data/3-Raman/processed/bu19(2)w-a-ff1-fi05-v_1800 (450-850nm)_532nm_edge_100%_x100_vis_lwd_h100um_30sx2_01.txt
#Acq. time (s)=	30
#Accumulations=	2
#Range (cm-¹)=	1200...2365
#Windows=	3
#Auto scanning=	Off
#Autofocus=	Off
#Macrospot=	Off
#AutoExposure=	Off
#Spike filter=	Multiple accum.
#Delay time (s)=	2
#Binning=	1
#Readout mode=	Signal
#DeNoise=	Off
#ICS correction=	On
#Dark correction=	Off
#Inst. Process=	Off
#Detector Gain=	Best Dynamic
#Detector ADC=	50 kHz HS
#Detector temperature (°C)=	-60.09
#Instrument=	LabRAM HR Evol
#Detector=	SIN-EM FIVIS
#Objective=	x100_VIS_LWD
#Grating=	1800 (450-850nm)
#ND Filter=	100%
#Laser=	532nm_Edge
#Hole=	100.021
#Temperature=	0
#Range=	Visible
#StageXY=	75x50mm Scan+
#StageZ=	Z motor
#X (µm)=	0
#Y (µm)=	0
#Z (µm)=	-9.7
#Full time(mm:ss)=	3:23
#Project=	21_11_26
#Sample=	BU19(2)w
#Site=
#Title=	BU19(2)w-A-FF1-FI05-V_1800 (450-850nm)_532nm_Edge_100%_x100_VIS_LWD_H100um_30sX2
#Remark=
#Date=	26.11.2021 13:31
#Acquired=	26.11.2021 13:31:21
#Base:Fit=	16.12.2021 16:00:56
#Base:Fit=	16.12.2021 16:07:13
#Base:Sub=	16.12.2021 16:07:14
1202.72	10.7998
1203.84	2.34322
1204.95	1.24087
1206.06	3.24062
1207.17	0.861336
1208.28	1.75833
1209.39	-0.586342
1210.5	-1.83115
1211.61	2.11857
1212.72	-2.48396
1213.83	3.58685
1214.94	-0.936813
1216.05	1.954
1217.16	-0.636284
1218.27	-2.15023
1219.38	9.09366
1220.49	-5.13434
1221.6	6.07955
1222.71	8.67503
1223.81	5.89786
1224.92	-6.31942
1226.03	0.569496
1227.14	1.07712
1228.25	-0.746124
1229.35	-0.489441
1230.46	-1.87073
1231.57	1.46434
1232.67	2.94446
1233.78	2.28506
1234.89	0.615608
1235.99	12.6016
1237.1	0.32756
1238.2	0.555603
1239.31	2.8752
1240.41	5.25827
1241.52	-0.715157
1242.62	2.68814
1243.73	16.6271
1244.83	4.31657
1245.94	7.6286
1247.04	8.86845
1248.14	3.84945
1249.25	2.97846
1250.35	5.28643
1251.45	5.41008
1252.56	7.63036
1253.66	7.75567
1254.76	3.8192
1255.87	8.18852
1256.97	13.6028
1258.07	17.919
1259.17	12.8033
1260.27	6.75441
1261.37	38.0924
1262.48	36.4177
1263.58	41.4341
1264.68	27.334
1265.78	23.1691
1266.88	11.7979
1267.98	16.1986
1269.08	17.4999
1270.18	20.755
1271.28	15.5303
1272.38	18.7872
1273.47	22.1604
1274.57	26.5624
1275.67	21.4297
1276.77	23.7092
1277.87	29.149
1278.97	36.7101
1280.07	63.1225
1281.16	210.48
1282.26	598.129
1283.36	636.842
1284.45	196.931
1285.55	60.5976
1286.65	29.0757
1287.75	30.1685
1288.84	22.8578
1289.94	25.1143
1291.03	9.43164
1292.13	5.29465
1293.22	6.42941
1294.32	11.9009
1295.42	6.73833
1296.51	2.79304
1297.61	14.4933
1298.7	11.3578
1299.79	9.28537
1300.89	2.01396
1301.98	1.06243
1303.08	0.122093
1304.17	6.51924
1305.26	0.270332
1306.35	1.34847
1307.45	2.48431
1308.54	1.53453
1309.63	-0.449745
1310.73	1.77528
1311.82	0.835762
1312.91	-2.18739
1314	-1.05207
1315.09	-1.99314
1316.18	-6.0676
1317.28	-4.91462
1318.37	-0.552979
1319.46	-2.54905
1320.55	-0.32074
1321.64	-5.54102
1322.73	-4.4388
1323.82	-1.18455
1324.91	2.10378
1326	1.11602
1327.09	4.2584
1328.18	3.47726
1329.27	3.7064
1330.35	4.87796
1331.44	0.718269
1332.53	4.94084
1333.62	-1.34779
1334.71	-8.65355
1335.79	-3.33296
1336.88	3.0464
1337.97	-7.32947
1339.06	3.22476
1340.14	2.31509
1341.23	-0.677887
1342.32	-1.61179
1343.4	5.78593
1344.49	-3.48893
1345.58	-1.28716
1346.66	3.97076
1347.75	0.891571
1348.83	8.29977
1349.92	6.30595
1351	5.35125
1352.09	7.52177
1353.17	-0.593475
1354.25	5.88968
1355.34	3.77179
1356.42	7.03718
1357.51	9.23026
1358.59	9.33382
1359.67	8.39496
1360.76	6.4007
1361.84	17.929
1362.92	13.913
1364	5.81938
1365.09	9.08482
1366.17	19.5223
1367.25	17.5137
1368.33	23.8761
1369.41	28.2033
1370.5	20.0705
1371.58	17.0561
1372.66	20.1802
1373.74	23.3715
1374.82	29.6874
1375.9	22.6383
1376.98	28.9378
1378.06	44.507
1379.14	50.0212
1380.22	52.1843
1381.3	65.4583
1382.38	76.7779
1383.46	78.7781
1384.54	157.801
1385.61	473.23
1386.69	1646.75
1387.77	517.643
1388.85	129.668
1389.93	70.6865
1391	42.9487
1392.08	37.896
1393.16	32.8538
1394.23	18.6487
1395.31	19.8288
1396.39	20.0188
1397.46	25.2477
1398.54	23.3411
1399.62	18.4239
1400.69	14.5187
1401.77	19.8372
1402.84	13.9785
1403.92	19.3478
1404.99	27.6475
1406.07	33.8902
1407.14	56.5633
1408.22	72.1317
1409.29	54.8906
1410.37	28.3989
1411.44	22.3013
1412.51	8.08817
1413.59	5.36684
1414.66	13.6344
1415.73	1.49745
1416.81	8.85315
1417.88	4.92262
1418.95	4.05028
1420.02	3.14558
1421.1	1.17483
1422.17	5.42413
1423.24	3.65758
1424.31	5.60754
1425.38	9.84686
1426.45	2.82051
1427.52	4.9316
1428.59	6.01675
1429.67	0.0217133
1430.74	2.25745
1431.81	1.44596
1432.87	1.53223
1433.95	6.67493
1435.01	2.72294
1436.08	3.86713
1437.15	-3.20687
1438.22	-0.0344543
1439.29	14.4464
1440.36	-5.88519
1441.43	2.44753
1442.49	3.57588
1443.56	6.75706
1444.63	1.72375
1445.7	0.856438
1446.77	-0.0868378
1447.83	5.11771
1448.9	11.3938
1449.97	-2.8751
1451.03	2.31729
1452.1	5.46333
1453.17	0.431343
1454.23	4.63347
1455.3	-3.47811
1456.36	-0.299637
1457.43	1.81077
1458.49	0.861351
1459.56	-1.09214
1460.62	-2.04319
1461.69	0.0581436
1462.75	-1.95366
1463.82	6.24769
1464.88	2.3072
1465.94	8.31081
1467.01	4.27932
1468.07	-6.88231
1469.13	0.318851
1470.2	-0.674297
1471.26	1.39685
1472.32	-9.7751
1473.39	-2.59472
1474.45	-0.528015
1475.51	3.61333
1476.57	1.61256
1477.63	-3.44828
1478.69	-5.4492
1479.76	5.74183
1480.82	1.65968
1481.88	-0.343395
1482.94	3.81028
1484	3.86962
1485.06	0.736683
1486.12	1.77459
1487.18	4.86375
1488.24	2.84402
1489.3	-2.22987
1490.36	-1.19725
1491.42	4.87275
1492.48	-8.24303
1493.53	-1.1402
1494.59	-3.13222
1495.65	-2.11596
1496.71	2.90185
1497.77	1.90171
1498.82	-1.10331
1499.88	6.00167
1500.94	-5.07465
1502	-2.04803
1503.05	4.00243
1504.11	0.963581
1505.17	3.00483
1506.22	4.9781
1507.28	-2.05389
1508.34	0.983524
1509.39	3.01278
1510.45	-7.04342
1511.5	3.9936
1512.56	4.87919
1513.61	2.80545
1514.67	1.84943
1515.72	-4.22223
1516.78	6.76021
1517.83	4.7479
1518.88	1.76698
1519.94	-2.227
1520.99	-3.23721
1522.05	-0.216667
1523.1	2.76437
1524.15	3.69042
1525.2	3.65877
1526.26	2.68018
1527.31	5.71645
1528.36	1.67693
1529.41	6.65467
1530.47	-2.38543
1531.52	5.6613
1532.57	-3.37532
1533.62	0.688446
1534.67	-0.315815
1535.72	1.64885
1536.77	0.547119
1537.82	-1.53414
1538.87	1.41367
1539.92	1.4934
1540.97	3.58834
1542.02	-1.47951
1543.07	-0.554928
1544.12	5.35764
1545.17	2.37971
1546.22	-3.58567
1547.27	-0.58654
1548.32	1.36488
1549.37	2.30876
1550.42	6.31521
1551.46	-0.532875
1552.51	-1.5564
1553.56	1.38671
1554.61	6.33052
1555.65	4.24352
1556.7	-0.793339
1557.75	1.19637
1558.79	-4.88485
1559.84	-1.9748
1560.89	-3.02922
1561.93	1.95501
1562.98	-0.0354576
1564.02	-9.07183
1565.07	4.95572
1566.11	1.53883
1567.16	-2.21424
1568.2	-0.193954
1569.25	-2.20486
1570.29	-1.26191
1571.34	6.70491
1572.38	-1.34462
1573.43	2.5844
1574.47	-4.43641
1575.51	0.589504
1576.56	5.56831
1577.6	-1.52605
1578.64	0.370384
1579.69	-4.64529
1580.73	-0.665665
1581.77	0.276535
1582.81	-2.77424
1583.85	2.16789
1584.9	2.14495
1585.94	-2.86467
1586.98	-0.94593
1588.02	1.98941
1589.06	-0.00392532
1590.1	-3.98786
1591.14	0.983582
1592.18	1.94081
1593.22	5.83422
1594.26	2.72975
1595.3	3.71122
1596.34	-2.29525
1597.38	7.62125
1598.42	0.647854
1599.46	3.5454
1600.5	-3.46586
1601.54	-1.57226
1602.58	3.29235
1603.62	1.23436
1604.66	3.17611
1605.69	-0.793686
1606.73	1.19316
1607.77	4.14243
1608.81	0.289658
1609.84	8.08164
1610.88	4.0376
1611.92	2.44871
1612.95	0.460884
1613.99	4.4018
1615.03	-0.49707
1616.06	0.27861
1617.1	4.98895
1618.13	3.06699
1619.17	5.94066
1620.2	9.28371
1621.24	1.98981
1622.27	3.81371
1623.31	5.30344
1624.34	1.17989
1625.38	6.34146
1626.41	2.97253
1627.45	2.0575
1628.48	4.09475
1629.51	2.63763
1630.55	6.96915
1631.53	2.66909
1632.57	2.69048
1633.62	8.58831
1634.66	12.5405
1635.71	9.56979
1636.75	5.59064
1637.8	5.54482
1638.84	6.50254
1639.89	5.51328
1640.93	13.3971
1641.98	8.47082
1643.02	8.45275
1644.06	5.48601
1645.11	5.45454
1646.15	9.41103
1647.19	2.49619
1648.24	8.37553
1649.28	7.4584
1650.32	10.4111
1651.37	4.57064
1652.41	5.57268
1653.45	6.54557
1654.49	7.55096
1655.53	4.63
1656.57	7.66896
1657.62	5.70325
1658.66	7.65908
1659.7	6.6393
1660.74	8.6091
1661.78	5.71143
1662.82	6.78885
1663.86	0.880325
1664.9	4.79791
1665.94	-4.1543
1666.98	3.8337
1668.02	6.77066
1669.06	5.81233
1670.1	-3.0116
1671.14	5.94633
1672.18	1.99646
1673.21	9.92872
1674.25	4.03181
1675.29	4.08927
1676.33	4.12441
1677.37	5.14042
1678.4	4.13808
1679.44	2.13692
1680.48	4.11081
1681.52	5.09756
1682.55	2.15498
1683.59	-1.77742
1684.63	1.194
1685.66	2.19358
1686.7	-0.737179
1687.73	-3.65935
1688.77	2.2653
1689.81	4.21925
1690.84	4.22944
1691.88	-0.651508
1692.91	2.33019
1693.95	3.28035
1694.98	1.28983
1696.01	-2.61077
1697.05	2.36501
1698.08	6.28271
1699.12	4.29887
1700.15	0.392677
1701.18	-4.50967
1702.22	2.37674
1703.25	-4.50848
1704.28	7.30014
1705.32	2.43624
1706.35	1.47465
1707.38	-3.45786
1708.41	-2.5074
1709.44	-9.39911
1710.48	-5.4579
1711.51	1.45496
1712.54	4.43529
1713.57	4.372
1714.6	0.433208
1715.63	5.3567
1716.66	3.44142
1717.69	-6.3582
1718.72	1.38228
1719.75	-3.46931
1720.78	0.463497
1721.81	4.34165
1722.84	-2.4848
1723.87	-0.544746
1724.9	-0.521511
1725.93	-3.47236
1726.96	0.425171
1727.99	6.26291
1729.02	3.2705
1730.05	5.18019
1731.07	-1.57212
1732.1	1.44306
1733.13	2.42735
1734.16	1.42232
1735.18	6.20542
1736.21	4.26036
1737.24	3.31321
1738.26	6.20592
1739.29	7.15364
1740.32	5.17573
1741.34	6.10292
1742.37	7.05986
1743.4	8.04274
1744.42	-2.46929
1745.45	6.174
1746.47	1.41468
1747.5	0.439373
1748.52	0.449532
1749.55	0.511227
1750.57	0.608871
1751.6	0.683155
1752.62	2.58257
1753.64	2.57603
1754.67	2.57458
1755.69	5.44746
1756.71	8.29255
1757.74	3.51157
1758.76	4.53176
1759.78	2.68274
1760.81	6.51862
1761.83	9.37467
1762.85	3.71317
1763.87	7.57185
1764.89	4.81607
1765.92	12.5091
1766.94	6.83948
1767.96	13.5281
1768.98	6.88488
1770	12.5072
1771.02	9.74271
1772.04	11.7492
1773.06	13.7405
1774.08	10.0121
1775.1	10.0813
1776.12	7.33619
1777.14	7.38192
1778.16	10.2428
1779.18	7.37428
1780.2	3.6017
1781.22	10.3318
1782.24	3.73154
1783.26	8.58329
1784.28	8.66316
1785.29	-0.787472
1786.31	6.8722
1787.33	7.90204
1788.35	6.16095
1789.37	3.42748
1790.38	9.27743
1791.4	5.47766
1792.42	9.30017
1793.43	8.40565
1794.45	5.58686
1795.47	1.84932
1796.48	6.75956
1797.5	-0.836231
1798.51	4.04057
1799.53	2.15172
1800.55	3.11078
1801.56	0.249866
1802.58	-2.58172
1803.59	5.18798
1804.61	6.21671
1805.62	1.49572
1806.64	0.617252
1807.65	4.52507
1808.66	6.49278
1809.68	-0.210197
1810.69	-1.13138
1811.7	3.71607
1812.72	7.6171
1813.73	-3.89113
1814.74	3.91714
1815.76	2.06508
1816.77	-0.788891
1817.78	-2.72312
1818.79	4.08133
1819.8	7.03094
1820.82	1.28965
1821.83	6.18728
1822.84	-1.49964
1823.85	-1.47039
1824.86	-3.37549
1825.87	5.38844
1826.88	-2.32787
1827.89	-4.22211
1828.9	-6.1349
1829.91	0.6544
1830.92	-1.27926
1831.93	0.704582
1832.94	5.60938
1833.95	6.62039
1834.96	1.75724
1835.97	3.62456
1836.98	3.87127
1837.99	3.70042
1839	4.68466
1840	-3.93134
1841.01	2.7548
1842.02	-4.09319
1843.03	3.59694
1844.04	5.54454
1845.04	0.741032
1846.05	2.70528
1847.06	0.848713
1848.07	3.55435
1849.07	-1.23261
1850.08	4.51208
1851.09	0.607529
1852.09	1.54399
1853.1	4.43457
1854.1	2.50311
1855.11	-3.29998
1856.11	-0.466015
1857.12	1.45219
1858.12	7.1856
1859.13	5.22971
1860.13	5.19558
1861.14	3.31824
1862.14	-8.12419
1863.15	1.41523
1864.15	0.415665
1865.15	0.379547
1866.16	-6.3624
1867.16	2.12617
1868.16	-4.5986
1869.17	1.10411
1870.17	4.8996
1871.17	-0.809731
1872.17	-1.77789
1873.18	4.83719
1874.18	0.0685806
1875.18	-2.8271
1876.18	-3.85236
1877.18	1.7668
1878.18	-0.206429
1879.19	0.832466
1880.19	6.55831
1881.19	1.81532
1882.19	-2.99955
1883.19	2.5452
1884.19	10.9597
1885.19	7.21938
1886.19	0.688335
1887.19	5.39605
1888.19	4.38803
1889.19	-1.35085
1890.19	3.31824
1891.19	2.40715
1892.18	-5.14631
1893.18	-4.23546
1894.18	7.89453
1895.18	3.15921
1896.18	-0.589169
1897.18	-1.50169
1898.17	2.26607
1899.17	3.16177
1900.17	4.04984
1901.16	5.91623
1902.16	0.312386
1903.16	-1.55875
1904.16	4.0498
1905.15	5.90737
1906.15	-3.52758
1907.14	2.05624
1908.14	0.171825
1909.14	-1.69651
1910.13	5.86407
1911.13	2.15939
1912.12	3.10371
1913.12	4.02067
1914.11	6.86145
1915.11	3.13513
1916.1	2.19813
1917.1	-1.62006
1918.09	3.99257
1919.08	4.95918
1920.08	4.08392
1921.07	6.91269
1922.06	1.27316
1923.06	2.19248
1924.05	2.14962
1925.04	-0.731663
1926.04	4.01548
1927.03	1.22621
1928.02	2.19089
1929.01	-0.645615
1930	2.22642
1931	-3.42559
1931.99	-2.50177
1932.98	0.293205
1933.97	7.87424
1934.96	0.42865
1935.95	-0.419373
1936.94	0.458572
1937.93	3.24381
1938.92	2.2679
1939.91	2.28094
1940.9	-1.5118
1941.89	-4.34438
1942.88	4.24861
1943.87	-0.578777
1944.86	7.0786
1945.85	1.38568
1946.84	-2.42168
1947.83	3.28588
1948.82	1.34458
1949.8	5.18805
1950.79	4.29615
1951.78	3.41039
1952.77	3.43867
1953.76	5.34553
1954.74	0.398159
1955.73	-3.48579
1956.72	1.38308
1957.7	4.29945
1958.69	5.27081
1959.68	7.15079
1960.66	4.21574
1961.65	-2.56647
1962.63	1.25291
1963.62	4.12128
1964.61	3.1599
1965.59	5.0525
1966.58	6.98725
1967.56	9.88134
1968.55	5.06638
1969.53	4.05139
1970.52	0.123428
1971.5	4.86586
1972.48	10.6014
1973.47	-1.9012
1974.45	5.71225
1975.44	4.73977
1976.42	6.67169
1977.4	15.2909
1978.39	12.3594
1979.37	6.56827
1980.35	16.142
1981.33	3.62961
1982.31	12.2096
1983.3	2.57795
1984.28	15.9109
1985.26	10.1235
1986.24	15.82
1987.22	12.9614
1988.21	18.6269
1989.19	21.2012
1990.17	15.5345
1991.15	18.0701
1992.13	16.5934
1993.11	22.2966
1994.09	19.0671
1995.07	16.1962
1996.05	20.06
1997.03	18.3331
1998.01	16.3515
1998.99	21.0728
1999.97	24.3857
2000.95	17.3096
2001.92	21.9177
2002.9	22.732
2003.88	25.51
2004.86	20.3877
2005.84	24.0747
2006.81	24.8621
2007.79	22.6846
2008.77	21.9267
2009.75	24.8314
2010.73	23.46
2011.7	20.0509
2012.68	25.8184
2013.67	24.7795
2014.66	22.7639
2015.64	17.0955
2016.63	16.1866
2017.62	24.6912
2018.61	22.7023
2019.6	18.833
2020.58	13.1796
2021.57	18.8016
2022.56	21.5901
2023.55	11.2267
2024.54	15.8431
2025.52	20.4153
2026.51	20.3538
2027.5	17.7569
2028.48	11.1346
2029.47	12.1836
2030.45	9.17799
2031.44	14.8124
2032.43	14.8311
2033.41	13.0617
2034.4	15.8819
2035.38	11.1108
2036.37	10.3316
2037.35	14.0608
2038.34	10.311
2039.32	13.0816
2040.31	11.1653
2041.29	17.6364
2042.27	12.0216
2043.26	6.41492
2044.24	16.764
2045.23	4.61447
2046.21	8.49381
2047.19	5.64745
2048.17	5.58296
2049.16	2.8181
2050.14	5.703
2051.12	4.83434
2052.11	4.81678
2053.09	4.85629
2054.07	4.94342
2055.05	4.04848
2056.03	3.10467
2057.01	3.10649
2058	5.0127
2058.98	8.82633
2059.96	3.26402
2060.94	4.20134
2061.92	4.25064
2062.9	1.48031
2063.88	8.10189
2064.86	3.46614
2065.84	-1.14119
2066.82	-0.140347
2067.8	1.79136
2068.78	4.66715
2069.76	-0.01894
2070.73	0.944801
2071.71	1.95284
2072.69	3.94946
2073.67	9.61889
2074.65	0.25008
2075.63	2.23923
2076.6	0.449024
2077.58	1.39757
2078.56	-0.468887
2079.54	-6.06616
2080.51	0.633595
2081.49	1.61252
2082.47	0.70388
2083.45	1.6935
2084.42	-2.05286
2085.4	-0.122574
2086.37	-1.01106
2087.35	-1.87544
2088.32	0.0723763
2089.3	-0.824432
2090.28	2.09579
2091.25	-0.686802
2092.23	3.19057
2093.2	2.35788
2094.18	-1.34555
2095.15	1.56033
2096.13	-5.07994
2097.1	-0.299976
2098.07	-2.18849
2099.05	2.58878
2100.02	-5.91548
2101	-1.11404
2101.97	-7.68229
2102.94	2.8079
2103.92	1.87626
2104.89	-1.86262
2105.86	4.8735
2106.83	1.14696
2107.8	-0.702263
2108.78	1.19213
2109.75	-0.657516
2110.72	5.10411
2111.69	-1.49964
2112.66	-0.515633
2113.63	1.46675
2114.61	5.32837
2115.58	1.5785
2116.55	-0.294605
2117.52	5.43475
2118.49	1.66759
2119.46	-6.87
2120.43	-2.11429
2121.4	0.795219
2122.37	2.79641
2123.34	-0.912525
2124.31	-0.86153
2125.28	3.86358
2126.25	-0.894894
2127.21	-2.77903
2128.18	0.0917816
2129.15	-0.806328
2130.12	2.07246
2131.09	-0.721497
2132.06	4.02612
2133.02	1.2175
2133.99	-6.27668
2134.96	3.22072
2135.93	3.26617
2136.89	-3.32772
2137.86	-1.37359
2138.83	1.49326
2139.79	-5.03515
2140.76	0.63483
2141.73	-1.20423
2142.69	0.709995
2143.66	2.69418
2144.62	0.762417
2145.59	-1.0566
2146.55	-2.88742
2147.52	5.60851
2148.48	4.70004
2149.45	-1.84666
2150.42	3.77887
2151.38	2.88696
2152.34	0.159969
2153.31	3.01421
2154.27	6.79305
2155.24	-3.52438
2156.2	2.07691
2157.16	3.98434
2158.13	1.26245
2159.09	-1.47428
2160.05	1.35781
2161.01	6.03428
2161.98	1.40787
2162.94	2.39677
2163.9	-1.29802
2164.86	5.24789
2165.83	4.37414
2166.79	1.62648
2167.75	-1.14697
2168.71	1.63045
2169.67	0.778343
2170.63	4.62616
2171.59	1.87625
2172.56	3.70431
2173.51	2.81338
2174.48	0.098053
2175.44	-0.772247
2176.4	2.06153
2177.36	-0.684189
2178.32	-1.55333
2179.28	0.331017
2180.23	1.31933
2181.19	1.36696
2182.15	1.40616
2183.11	1.44251
2184.07	3.30367
2185.03	-0.36438
2185.99	-1.2173
2186.95	-2.05022
2187.9	6.41658
2188.86	-1.90805
2189.82	2.73178
2190.78	-1.87202
2191.73	6.53754
2192.69	2.90029
2193.65	2.05693
2194.6	4.04498
2195.56	-1.48432
2196.52	5.94733
2197.47	4.09222
2198.43	-1.42241
2199.38	2.39859
2200.34	9.96518
2201.3	4.52757
2202.25	7.18489
2203.21	1.75122
2204.16	3.85251
2205.12	1.00907
2206.07	3.72671
2207.03	3.77074
2207.98	1.06046
2208.93	-5.36772
2209.89	1.21281
2210.84	-2.45237
2211.8	-0.511066
2212.75	0.500114
2213.7	-0.407284
2214.66	2.46098
2215.61	0.672447
2216.56	-1.14682
2217.51	1.69296
2218.47	1.74065
2219.42	0.873623
2220.37	0.00835419
2221.32	-2.76197
2222.27	-1.82779
2223.23	0.0846214
2224.18	0.167698
2225.13	-2.5458
2226.08	-1.52371
2227.03	1.36591
2227.98	2.37089
2228.93	1.46097
2229.88	-1.30956
2230.83	-4.98339
2231.78	1.6692
2232.73	-4.83413
2233.68	0.880562
2234.63	4.70201
2235.58	-0.00237274
2236.53	0.0278091
2237.48	1.02351
2238.43	-2.64116
2239.38	-3.49458
2240.33	-8.1936
2241.27	-4.36771
2242.22	3.22803
2243.17	3.27959
2244.12	-0.48188
2245.07	5.23754
2246.01	-3.17381
2246.96	6.34912
2247.91	-3.0589
2248.85	3.58852
2249.8	0.782074
2250.75	4.5879
2251.69	2.68765
2252.64	-2.9439
2253.59	2.83284
2254.53	-0.883694
2255.48	-0.849472
2256.42	2.03677
2257.37	2.09969
2258.32	4.05131
2259.26	4.09732
2260.2	2.24725
2261.15	1.34635
2262.1	-3.3531
2263.04	-0.447357
2263.98	0.585793
2264.93	-6.00251
2265.87	-4.9944
2266.81	0.739269
2267.76	1.68161
2268.7	3.58421
2269.65	6.50449
2270.59	-0.0913887
2271.53	-5.7698
2272.47	-1.89599
2273.42	1.96359
2274.36	-3.74454
2275.3	-0.839264
2276.24	0.152702
2277.18	1.17713
2278.13	0.303783
2279.07	0.35796
2280.01	0.346352
2280.95	-0.636406
2281.89	0.32299
2282.83	3.24674
2283.77	-1.47435
2284.71	-1.37904
2285.65	-2.29021
2286.59	-1.33304
2287.54	-0.298962
2288.47	-6.99978
2289.41	-1.2337
2290.35	-3.19285
2291.29	-0.284122
2292.23	-4.06696
2293.17	6.58567
2294.11	0.850033
2295.05	2.77225
2295.99	0.839874
2296.93	1.78417
2297.86	0.872894
2298.8	0.940086
2299.74	0.0364189
2300.68	-0.904594
2301.61	6.86144
2302.55	0.124428
2303.49	-2.75592
2304.43	2.10324
2305.36	-0.744801
2306.3	-0.707268
2307.24	-1.64538
2308.17	0.293297
2309.11	-4.52309
2310.04	-1.56464
2310.98	-3.46493
2311.92	1.3191
2312.85	2.26083
2313.79	3.26015
2314.72	6.24399
2315.66	-3.37478
2316.59	1.42208
2317.52	1.42411
2318.46	-1.4448
2319.39	-0.486526
2320.33	9.16869
2321.26	1.48279
2322.2	-0.387947
2323.13	9.32845
2324.06	4.52846
2325	8.401
2325.93	10.2939
2326.86	35.3538
2327.79	66.1595
2328.73	16.0352
2329.66	12.1639
2330.59	12.1803
2331.52	1.5992
2332.46	2.59656
2333.39	-0.300671
2334.32	-0.301323
2335.25	-0.311642
2336.18	-1.25212
2337.11	0.680401
2338.04	3.5747
2338.97	-1.22029
2339.91	-0.237911
2340.84	-6.00666
2341.77	-4.11525
2342.7	-2.21075
2343.63	4.51101
2344.56	3.57135
2345.49	-1.21012
2346.41	3.56207
2347.34	-3.13493
2348.27	-1.20255
2349.2	1.69246
2350.13	-0.273739
2351.06	1.43404
2351.99	1.63686
2352.91	2.53631
2353.84	-1.32758
2354.77	3.45224
2355.7	2.51673
2356.63	-6.07156
2357.55	1.50113
2358.48	-0.412964
2359.41	4.32797
2360.33	2.41241
2361.26	-2.36399
2362.19	3.2884
2363.11	2.30343
2364.04	-0.553902
2364.97	2.26482