File: Data/3-Raman/processed/bu19w-d-ore2-fi05-v_150 (500nm)_532nm_edge_100%_x100_vis_lwd_h50um_15sx2_01_0.txt
#Acq. time (s)=	15
#Accumulations=	2
#Range (cm-¹)=	50...5000
#Windows=	1
#Auto scanning=	Off
#Autofocus=	Off
#Macrospot=	Off
#AutoExposure=	Off
#Spike filter=	Multiple accum.
#Delay time (s)=	2
#Binning=	1
#Readout mode=	Signal
#DeNoise=	Off
#ICS correction=	On
#Dark correction=	Off
#Inst. Process=	Off
#Detector Gain=	Best Dynamic
#Detector ADC=	50 kHz HS
#Detector temperature (°C)=	-60.09
#Instrument=	LabRAM HR Evol
#Detector=	SIN-EM FIVIS
#Objective=	x100_VIS_LWD
#Grating=	150 (500nm)
#ND Filter=	100%
#Laser=	532nm_Edge
#Hole=	49.98
#Temperature=	0
#Range=	Visible
#StageXY=	75x50mm Scan+
#StageZ=	Z motor
#X (µm)=	0
#Y (µm)=	0
#Z (µm)=	-26.7
#Full time(s)=	34
#Project=	21_05_28
#Sample=	BU19w
#Site=
#Title=	BU19w-FF-ore2-FI05-V_150 (500nm)_532nm_Edge_100%_x100_VIS_LWD_H50um_15sX2
#Remark=
#Date=	28.05.2021 14:59
#Acquired=	28.05.2021 14:59:33
#Base:Fit=	16.12.2021 17:39:50
#Base:Sub=	16.12.2021 18:00:58
51.5961	12527.8
56.2453	12930.6
60.8921	12377.2
65.5367	10249.7
70.1768	8126.86
74.8167	6464.66
79.4543	5319.06
84.0897	4375.44
88.7227	3630.47
93.3513	3155.95
97.9798	2719.69
102.606	2312.87
107.23	2109.98
111.851	1938
116.469	1803.98
121.086	1977.36
125.7	3076.08
130.313	4376.52
134.921	3216.98
139.529	1894.52
144.134	1592.4
148.738	1531.51
153.337	1408.05
157.936	1273.84
162.532	1256.19
167.126	1198.02
171.716	1268.28
176.306	1460.76
180.894	1693.44
185.477	2071.45
190.06	2732.94
194.64	3805.15
199.219	5363.89
203.793	7258.38
208.367	8268.65
212.939	7643.16
217.506	6041.39
222.073	4434.38
226.638	3125
231.199	2297.76
235.759	1720.85
240.318	1378.1
244.872	1127.58
249.425	944.929
253.977	868.977
258.524	876.437
263.071	1349.96
267.616	1689.57
272.156	1019.59
276.697	516.203
281.233	358.406
285.769	242.867
290.303	220.583
294.832	139.757
299.361	126.148
303.886	87.4146
308.411	27.992
312.934	75.7271
317.452	72.6215
321.97	41.5886
326.484	61.1912
330.998	16.744
335.507	12.1866
340.017	1.98785
344.524	-1.99402
349.027	77.2888
353.53	664.45
358.028	1355
362.527	829.459
367.021	240.218
371.515	94.2053
376.004	90.6282
380.494	38.3757
384.979	44.8445
389.465	50.9645
393.946	110.277
398.427	123.154
402.903	225.888
407.38	202.227
411.852	62.0688
416.324	60.7814
420.792	74.5014
425.26	88.1344
429.723	157.949
434.187	185.574
438.646	268.382
443.105	497.183
447.56	949.314
452.015	1833.96
456.466	3889.13
460.914	10658.2
465.362	22926.2
469.807	22754
474.251	11415.5
478.69	4927.38
483.13	2653.15
487.566	1785.9
491.999	1266.93
496.432	917.144
500.861	707.723
505.29	579.15
509.715	605.985
514.138	640.939
518.56	551.099
522.979	365.956
527.395	316.418
531.811	238.251
536.223	197.338
540.635	196.994
545.042	128.231
549.448	160.385
553.853	97.2626
558.255	105.431
562.654	39.0355
567.053	56.0934
571.448	29.478
575.841	33.9783
580.232	12.6917
584.622	57.943
589.009	57.2657
593.393	45.4922
597.777	61.7456
602.157	42.9329
606.535	42.8463
610.913	35.2693
615.287	34.7338
619.659	-0.339722
624.029	20.7413
628.398	46.6713
632.763	13.0101
637.127	57.7772
641.488	18.4722
645.849	1.6394
650.206	-11.0275
654.561	23.7074
658.914	12.6794
663.267	20.5803
667.615	-13.9019
671.962	37.4817
676.307	0.259644
680.649	24.9908
684.991	-4.46008
689.33	63.2612
693.666	69.1418
698	144.423
702.332	161.385
706.662	28.3224
710.992	19.1307
715.318	34.2815
719.641	19.2137
723.963	41.8783
728.283	38.5596
732.6	28.7229
736.918	35.7491
741.231	65.4033
745.542	21.3258
749.852	50.2095
754.159	13.0874
758.464	39.5577
762.767	-0.349365
767.068	27.5159
771.369	11.3596
775.666	56.9257
779.961	75.6357
784.254	59.2815
788.545	144.462
792.834	166.883
797.12	269.902
801.405	400.808
805.688	507.385
809.968	787.161
814.247	687.854
818.524	364.408
822.798	182.705
827.071	189.473
831.341	142.389
835.612	130.528
839.878	101.996
844.142	128.437
848.405	84.8649
852.665	100.089
856.923	95.4429
861.18	77.5284
865.434	95.7068
869.686	88.106
873.936	49.4604
878.185	79.6624
882.431	85.3594
886.675	84.9905
890.915	113.222
895.155	105.983
899.393	95.7092
903.63	112.217
907.864	113.806
912.096	35.7908
916.326	84.1858
920.554	83.5709
924.78	100.732
929.004	45.0217
933.227	57.6503
937.447	60.441
941.665	42.4835
945.881	76.7765
950.095	66.0649
954.305	54.6686
958.516	73.2369
962.724	63.2231
966.93	23.6312
971.134	67.035
975.337	35.3643
979.537	47.3383
983.735	20.3745
987.93	47.3868
992.124	45.9291
996.316	32.7573
1000.51	65.9901
1004.7	25.3217
1008.88	49.5704
1013.06	27.1135
1017.25	67.1045
1021.43	43.1808
1025.61	28.5105
1029.78	51.771
1033.96	37.1986
1038.13	29.7555
1042.3	40.6727
1046.47	46.15
1050.63	42.6366
1054.8	72.7167
1058.96	78.958
1063.12	94.2041
1067.28	180.435
1071.44	163.187
1075.59	185.601
1079.74	393.193
1083.89	649.697
1088.04	523.908
1092.19	250.846
1096.33	112.635
1100.48	110.094
1104.62	71.8872
1108.76	41.5996
1112.89	70.2281
1117.03	26.7825
1121.16	1.71411
1125.29	86.1946
1129.42	46.808
1133.55	41.5168
1137.68	57.3523
1141.8	44.3997
1145.92	39.9386
1150.04	52.5521
1154.16	127.254
1158.27	205.568
1162.39	243.302
1166.5	220.65
1170.61	112.992
1174.72	38.942
1178.82	23.4592
1182.93	24.4199
1187.03	23.8861
1191.13	67.6494
1195.23	63.683
1199.33	70.4614
1203.42	25.8793
1207.51	28.1262
1211.6	82.0621
1215.69	76.1882
1219.78	79.5625
1223.86	62.0369
1227.95	93.0624
1232.03	101.534
1236.11	143.207
1240.18	105.812
1244.26	96.0906
1248.33	150.896
1252.41	67.8086
1256.48	120.882
1260.54	145.315
1264.61	184.052
1268.67	175.153
1272.74	129.429
1276.8	118.742
1280.86	221.51
1284.91	1013.99
1288.97	828.268
1293.02	223.16
1297.07	125.862
1301.12	60.587
1305.17	108.882
1309.21	64.3582
1313.25	67.0354
1317.3	24.8118
1321.34	84.0214
1325.37	42.9358
1329.41	68.0731
1333.44	55.84
1337.48	68.1764
1341.5	34.1788
1345.53	59.0525
1349.56	86.7969
1353.59	84.6331
1357.61	-1.86719
1361.63	88.2953
1365.65	106.191
1369.66	101.57
1373.68	119.077
1377.69	112.172
1381.7	135.142
1385.72	606.832
1389.72	1907.37
1393.73	859.055
1397.73	163.858
1401.74	100.397
1405.74	65.429
1409.73	237.626
1413.73	191.23
1417.73	131.014
1421.72	59.87
1425.71	79.3193
1429.7	44.618
1433.69	68.3439
1437.67	85.1307
1441.66	57.53
1445.64	70.1617
1449.62	83.6918
1453.6	79.1782
1457.57	85.3601
1461.55	50.848
1465.52	13.9119
1469.49	96.892
1473.46	43.4463
1477.43	55.6206
1481.39	76.3801
1485.36	23.5929
1489.32	70.5065
1493.28	35.4574
1497.24	54.1508
1501.19	66.1725
1505.15	50.2704
1509.1	99.0198
1513.05	7.97656
1517	45.2808
1520.95	92.447
1524.9	54.3496
1528.84	23.2096
1532.78	72.7692
1536.72	82.6271
1540.66	94.4885
1544.6	119.931
1548.53	45.5964
1552.46	59.4468
1556.4	53.7266
1560.32	79.7109
1564.25	62.9155
1568.18	103.031
1572.1	67.5979
1576.02	65.995
1579.94	62.4032
1583.86	102.172
1587.78	81.0553
1591.69	97.4821
1595.61	49.4215
1599.52	45.6605
1603.43	112.143
1607.34	80.947
1611.24	94.913
1615.15	108.042
1619.05	65.8563
1622.95	103.084
1626.85	93.6711
1630.74	88.334
1634.64	102.722
1638.53	44.2783
1642.42	68.6304
1646.31	127.875
1650.2	56.0255
1654.09	101.234
1657.97	72.4319
1661.86	90.6091
1665.74	98.8602
1669.62	99.2423
1673.49	83.6929
1677.37	52.6705
1681.24	98.5543
1685.12	53.7002
1688.99	96.0449
1692.86	50.7792
1696.72	83.8156
1700.59	67.7565
1704.45	57.1021
1708.31	119.395
1712.17	51.9093
1716.03	63.3835
1719.89	77.7255
1723.74	74.1262
1727.6	106.18
1731.45	119.948
1735.3	92.5557
1739.14	80.9797
1742.99	44.0435
1746.83	104.212
1750.68	73.2323
1754.52	77.3363
1758.36	75.9657
1762.19	114.693
1766.03	62.0929
1769.86	116.04
1773.69	94.7201
1777.53	83.6583
1781.35	96.4912
1785.18	72.3291
1789	76.3479
1792.83	132.932
1796.65	110.003
1800.47	112.298
1804.29	66.3809
1808.1	94.6448
1811.92	111.444
1815.73	85.4985
1819.54	142.719
1823.35	104.178
1827.16	110.593
1830.97	132.534
1834.77	110.63
1838.58	96.9331
1842.38	74.5226
1846.18	79.9143
1849.97	76.1454
1853.77	98.7021
1857.56	137.541
1861.36	132.727
1865.15	78.4113
1868.93	67.24
1872.72	81.3242
1876.51	108.675
1880.29	70.5256
1884.07	61.8436
1887.86	106.651
1891.63	97.3684
1895.41	119.429
1899.19	76.1665
1902.96	107.321
1906.73	97.4296
1910.5	87.7166
1914.27	110.947
1918.04	130.664
1921.8	103.566
1925.57	78.4089
1929.33	125.872
1933.09	118.837
1936.85	89.3643
1940.6	96.1282
1944.36	109.422
1948.11	118.079
1951.87	163.768
1955.61	97.0259
1959.36	101.589
1963.11	92.3953
1966.86	64.3247
1970.6	100.463
1974.34	118.997
1978.08	124.003
1981.82	70.6693
1985.56	86.301
1989.29	74.6248
1993.02	102.737
1996.75	111.791
2000.49	83.3448
2004.21	104.179
2007.94	89.6074
2011.67	58.9908
2015.39	120.536
2019.11	157.956
2022.83	103.693
2026.55	102.89
2030.27	73.7883
2033.98	124.318
2037.69	111.42
2041.41	129.484
2045.12	93.3829
2048.82	89.375
2052.53	84.8207
2056.24	110.608
2059.94	119.982
2063.64	75.4576
2067.34	100.226
2071.04	97.5956
2074.74	134.676
2078.43	88.8113
2082.13	119.813
2085.82	78.2875
2089.51	98.564
2093.2	52.9979
2096.88	108.663
2100.57	108.255
2104.25	114.66
2107.94	100.277
2111.62	139.547
2115.3	132.264
2118.97	101.511
2122.65	84.9117
2126.32	87.4297
2129.99	115.6
2133.66	116.691
2137.33	86.233
2141	88.7706
2144.67	96.5454
2148.33	122.568
2151.99	104.398
2155.66	122.119
2159.31	65.7247
2162.97	102.949
2166.63	97.4758
2170.28	105.113
2173.94	118.074
2177.59	109.594
2181.24	91.3702
2184.89	94.0054
2188.53	101.695
2192.18	52.8053
2195.82	108.407
2199.46	72.4929
2203.1	87.8016
2206.74	59.618
2210.38	95.679
2214.01	119.289
2217.65	112.816
2221.28	52.1919
2224.91	117.497
2228.54	104.576
2232.16	111.044
2235.79	128.792
2239.41	109.518
2243.04	64.1849
2246.66	68.7813
2250.28	85.5778
2253.89	95.1865
2257.51	91.9386
2261.12	71.8108
2264.74	96.3481
2268.35	112.728
2271.96	77.9008
2275.57	46.2052
2279.17	102.555
2282.78	79.4576
2286.38	106.358
2289.98	35.923
2293.58	81.4806
2297.18	98.769
2300.78	133.202
2304.37	85.871
2307.97	96.8773
2311.56	42.2235
2315.15	103.886
2318.74	54.3373
2322.33	79.2522
2325.91	116.257
2329.5	264.554
2333.08	212.085
2336.66	112.361
2340.24	72.926
2343.82	92.6444
2347.4	91.4199
2350.97	91.9462
2354.54	112.015
2358.12	124.434
2361.69	90.1263
2365.26	58.7205
2368.82	71.1586
2372.39	52.53
2375.95	74.499
2379.52	73.379
2383.08	73.4232
2386.64	54.3403
2390.19	87.0737
2393.75	47.6167
2397.31	35.38
2400.86	76.929
2404.41	95.6541
2407.96	122.873
2411.51	5.08618
2415.06	65.6512
2418.6	91.8619
2422.15	116.592
2425.69	97.6095
2429.23	54.1171
2432.77	42.2806
2436.31	76.2212
2439.84	46.395
2443.38	90.1493
2446.91	55.7416
2450.44	52.4338
2453.97	117.937
2457.5	32.0411
2461.03	59.1913
2464.55	35.332
2468.08	60.8566
2471.6	86.0242
2475.12	23.2061
2478.64	63.0042
2482.16	67.2395
2485.67	69.8528
2489.19	58.1736
2492.7	63.4965
2496.21	25.5844
2499.72	69.9169
2503.23	41.5044
2506.74	108.142
2510.25	81.8667
2513.75	57.6931
2517.25	48.9125
2520.75	29.3495
2524.25	58.6177
2527.75	58.1732
2531.25	33.2592
2534.74	37.2733
2538.24	52.8933
2541.73	65.2462
2545.22	60.9475
2548.71	33.4144
2552.2	46.6058
2555.68	42.7374
2559.17	61.9777
2562.65	69.2487
2566.13	67.1173
2569.61	84.1947
2573.09	50.4211
2576.57	17.7543
2580.04	73.6067
2583.51	33.7173
2586.99	56.952
2590.46	45.709
2593.93	12.5651
2597.4	67.5978
2600.86	10.7089
2604.33	55.8281
2607.79	55.0208
2611.25	30.629
2614.71	79.9027
2618.17	52.079
2621.63	31.181
2625.09	69.5173
2628.54	68.9398
2631.99	69.9965
2635.45	19.7635
2638.9	42.9176
2642.34	56.1344
2645.79	41.2521
2649.24	32.0305
2652.68	50.0807
2656.12	80.933
2659.56	24.924
2663.01	82.6241
2666.44	40.6934
2669.88	27.2081
2673.32	99.2721
2676.75	-6.00427
2680.18	18.6396
2683.61	21.1547
2687.04	64.4103
2690.47	42.535
2693.9	59.5189
2697.32	45.3998
2700.75	14.9567
2704.17	20.8887
2707.59	12.0212
2711.01	20.1785
2714.43	38.0161
2717.84	27.3625
2721.26	47.7909
2724.67	36.7714
2728.08	45.4912
2731.49	9.4519
2734.9	40.6417
2738.31	65.349
2741.71	29.049
2745.12	25.2091
2748.52	61.5345
2751.92	48.1016
2755.32	25.0964
2758.72	80.9633
2762.12	8.82104
2765.52	-5.40564
2768.91	80.0002
2772.3	32.2598
2775.7	14.5387
2779.09	42.6956
2782.47	55.5378
2785.86	51.3079
2789.25	51.7361
2792.63	51.1675
2796.01	34.5883
2799.4	42.4445
2802.78	70.6606
2806.15	75.4299
2809.53	46.4436
2812.91	47.3635
2816.28	53.8007
2819.65	59.2711
2823.03	57.5438
2826.4	44.871
2829.76	20.2354
2833.13	57.3593
2836.5	40.7539
2839.86	18.8645
2843.22	25.2585
2846.59	31.1323
2849.95	69.3354
2853.3	59.4604
2856.66	35.3555
2860.02	16.1154
2863.37	42.9192
2866.72	54.8567
2870.08	16.1606
2873.43	34.5787
2876.77	62.3889
2880.12	29.9664
2883.47	55.8477
2886.81	38.2568
2890.15	5.49573
2893.5	44.3918
2896.84	37.5654
2900.17	67.3848
2903.51	56.2863
2906.85	18.4878
2910.18	60.978
2913.52	-1.6814
2916.85	20.7151
2920.18	29.6235
2923.51	31.8269
2926.83	0.796631
2930.16	43.2722
2933.48	91.1792
2936.81	32.1525
2940.13	43.9375
2943.45	16.1508
2946.77	33.6533
2950.09	56.8341
2953.4	63.0073
2956.72	33.5422
2960.03	62.5959
2963.34	44.856
2966.65	46.0006
2969.96	35.4519
2973.27	12.0664
2976.58	57.2266
2979.88	67.9585
2983.19	27.8307
2986.49	48.8066
2989.79	41.7253
2993.09	55.3613
2996.39	37.1545
2999.68	58.5022
3002.98	12.1418
3006.27	45.7198
3009.57	72.8716
3012.86	32.3328
3016.15	34.1901
3019.43	43.5532
3022.72	52.9034
3026.01	27.3516
3029.29	52.793
3032.57	68.7839
3035.86	39.3391
3039.14	41.9784
3042.41	22.8741
3045.69	20.8258
3048.97	0.795044
3052.24	29.0695
3055.52	30.8743
3058.79	1.31726
3062.06	50.9351
3065.33	14.4674
3068.6	11.9594
3071.86	53.7246
3075.13	21.0861
3078.39	59.26
3081.65	54.2637
3084.91	26.8939
3088.17	52.5685
3091.43	41.6604
3094.69	58.4017
3097.95	38.942
3101.2	3.3584
3104.45	29.2897
3107.7	63.5641
3110.95	54.8173
3114.2	46.5232
3117.45	36.4594
3120.7	44.5308
3123.94	37.365
3127.18	75.9036
3130.43	25.7922
3133.67	24.2937
3136.91	31.3309
3140.14	32.5708
3143.38	31.8861
3146.61	29.3046
3149.85	77.3647
3153.08	37.7244
3156.31	26.627
3159.54	42.2814
3162.77	57.8915
3166	-2.83398
3169.22	35.5481
3172.45	51.8743
3175.67	47.1443
3178.89	65.1884
3182.11	55.547
3185.33	85.9978
3188.55	22.8188
3191.77	90.2263
3194.98	65.1594
3198.2	44.8508
3201.41	32.1439
3204.62	67.1118
3207.83	64.9955
3211.04	23.939
3214.25	41.9871
3217.45	67.7439
3220.66	57.3534
3223.86	51.7743
3227.06	80.5886
3230.26	59.9718
3233.46	89.8894
3236.66	41.6846
3239.85	68.9811
3243.05	27.8162
3246.24	45.7544
3249.44	79.916
3252.63	103.764
3255.82	48.4884
3259.01	33.2141
3262.19	77.8777
3265.38	51.6743
3268.56	59.646
3271.75	66.5181
3274.93	40.8245
3278.11	91.5239
3281.29	82.6945
3284.47	68.8344
3287.64	58.8347
3290.82	63.9801
3293.99	80.6788
3297.17	83.015
3300.34	73.9506
3303.51	69.0305
3306.68	56.1298
3309.84	83.9961
3313.01	79.2937
3316.18	59.3225
3319.34	70.6575
3322.5	63.9131
3325.66	44.8862
3328.82	59.0212
3331.98	55.2047
3335.14	39.2155
3338.29	63.0217
3341.45	66.1429
3344.6	88.1602
3347.75	79.4067
3350.9	59.6908
3354.05	87.0864
3357.2	85.4215
3360.35	59.3219
3363.49	62.6073
3366.64	53.6646
3369.78	51.3923
3372.92	89.7507
3376.06	127.356
3379.2	92.3348
3382.34	89.469
3385.48	122.457
3388.61	81.814
3391.75	89.4103
3394.88	70.4259
3398.01	68.124
3401.14	93.1294
3404.27	122.092
3407.4	109.443
3410.52	78.7708
3413.65	100.341
3416.77	62.541
3419.89	103.721
3423.01	70.4036
3426.13	73.9854
3429.25	101.19
3432.37	103.38
3435.49	83.3208
3438.6	72.4987
3441.72	91.4327
3444.83	74.0636
3447.94	79.3182
3451.05	72.1366
3454.16	95.2522
3457.26	94.499
3460.37	110.681
3463.47	89.7325
3466.58	107.691
3469.68	81.7579
3472.78	94.5079
3475.88	28.0941
3478.98	78.2593
3482.07	104.766
3485.17	54.7278
3488.26	84.1744
3491.36	100.579
3494.45	71.0947
3497.54	83.0872
3500.63	67.6304
3503.72	72.9558
3506.81	92.1974
3509.89	75.6123
3512.98	75.5809
3516.06	57.9287
3519.14	56.3827
3522.22	18.6932
3525.3	84.5844
3528.38	44.2518
3531.45	85.4056
3534.53	47.9211
3537.61	79.6815
3540.68	72.8534
3543.75	81.6802
3546.82	59.1355
3549.89	87.5492
3552.96	63.6731
3556.03	77.4882
3559.09	59.3523
3562.16	65.8158
3565.22	71.0675
3568.28	52.4318
3571.34	51.2433
3574.4	33.3242
3577.46	66.6685
3580.52	54.3838
3583.57	33.4568
3586.63	71.2119
3589.68	71.9648
3592.73	42.2158
3595.78	39.9344
3598.83	27.1172
3601.88	55.0325
3604.93	72.3749
3607.97	20.5332
3611.02	61.4067
3614.06	10.4938
3617.1	77.6516
3620.14	42.8425
3623.18	47.748
3626.22	-0.115112
3629.26	26.5908
3632.3	86.1656
3635.33	30.7626
3638.36	70.7511
3641.4	24.3219
3644.43	54.2445
3647.46	24.256
3650.49	26.8634
3653.51	39.9851
3656.54	31.8328
3659.57	48.8801
3662.59	21.5781
3665.61	38.293
3668.63	51.6415
3671.65	37.931
3674.67	45.0159
3677.69	39.9003
3680.71	62.2322
3683.72	47.6584
3686.74	65.2301
3689.75	18.5104
3692.76	38.0397
3695.77	55.7048
3698.78	15.3257
3701.79	56.7236
3704.79	61.1503
3707.8	43.7152
3710.81	50.8248
3713.81	24.5646
3716.81	38.0881
3719.81	42.1816
3722.81	12.8097
3725.81	55.6874
3728.81	50.8551
3731.8	66.8877
3734.8	32.3289
3737.79	28.1151
3740.78	37.1267
3743.77	6.02673
3746.76	35.7286
3749.75	14.9058
3752.74	20.6208
3755.73	63.3381
3758.71	-2.13354
3761.7	13.0416
3764.68	-0.322632
3767.66	63.998
3770.64	61.1393
3773.62	30.0186
3776.6	18.8617
3779.58	55.0236
3782.55	26.0543
3785.53	23.5586
3788.5	22.0699
3791.47	29.145
3794.44	23.1779
3797.41	13.5227
3800.38	40.7452
3803.35	44.5182
3806.32	56.8483
3809.28	39.9274
3812.24	21.1697
3815.21	57.2618
3818.17	15.8412
3821.13	26.4761
3824.09	36.1995
3827.04	45.0604
3830	17.9156
3832.96	75.1493
3835.91	39.5397
3838.86	-1.76758
3841.82	9.14246
3844.77	51.4471
3847.72	29.0997
3850.67	62.9705
3853.61	42.604
3856.56	21.265
3859.5	41.927
3862.45	53.0701
3865.39	26.8448
3868.33	12.0614
3871.27	50.8325
3874.21	44.5483
3877.15	48.7603
3880.09	26.9224
3883.02	42.4148
3885.96	34.7216
3888.89	60.5869
3891.82	27.766
3894.75	40.0755
3897.68	16.6659
3900.61	32.5641
3903.54	33.0432
3906.47	17.0493
3909.39	27.1344
3912.31	33.2723
3915.24	44.109
3918.16	25.0982
3921.08	42.7671
3924	11.2665
3926.92	31.4823
3929.83	40.0724
3932.75	39.9832
3935.67	39.1857
3938.58	60.6273
3941.49	65.9763
3944.4	31.9686
3947.31	51.6373
3950.22	12.0491
3953.13	59.6644
3956.04	53.7043
3958.94	48.7927
3961.85	20.9271
3964.75	28.5576
3967.65	31.4555
3970.55	28.6489
3973.45	64.2624
3976.35	40.3415
3979.25	51.8774
3982.15	22.0259
3985.04	-5.94263
3987.94	58.3382
3990.83	10.08
3993.72	16.5183
3996.61	30.839
3999.5	9.53668
4002.39	30.6332
4005.28	57.5372
4008.16	54.6418
4011.05	18.0173
4013.93	47.8843
4016.81	19.9012
4019.7	48.8331
4022.58	46.8861
4025.46	33.3508
4028.33	66.2044
4031.21	26.5889
4034.09	53.6946
4036.96	12.1364
4039.84	24.7907
4042.71	18.0561
4045.58	24.7154
4048.45	15.9202
4051.32	27.5305
4054.19	45.0223
4057.05	15.0671
4059.92	19.9997
4062.78	42.3886
4065.65	52.1656
4068.51	9.42468
4071.37	50.3082
4074.23	-9.04712
4077.09	44.4984
4079.95	16.2327
4082.81	44.4763
4085.66	33.7425
4088.52	12.2164
4091.37	50.2079
4094.22	27.7595
4097.07	26.7054
4099.92	7.13611
4102.77	19.7885
4105.62	49.0447
4108.47	14.613
4111.31	53.5673
4114.16	54.2542
4117	0.0338135
4119.84	22.0207
4122.69	38.147
4125.53	31.8787
4128.36	12.91
4131.2	4.95044
4134.04	55.887
4136.88	44.4434
4139.71	58.2695
4142.54	34.0511
4145.38	41.3732
4148.21	19.7083
4151.04	23.5583
4153.87	10.5525
4156.69	49.1168
4159.52	19.7372
4162.35	43.5399
4165.17	22.4592
4168	40.4928
4170.82	27.2722
4173.64	47.3549
4176.46	18.5652
4179.28	49.4308
4182.1	-2.75519
4184.91	38.0007
4187.73	44.5805
4190.54	28.6804
4193.36	8.0163
4196.17	25.6205
4198.98	45.3311
4201.79	24.8297
4204.6	18.0782
4207.41	35.8206
4210.22	36.9039
4213.02	51.7122
4215.83	49.8112
4218.63	28.7535
4221.44	22.3724
4224.24	51.4101
4227.04	29.0342
4229.84	22.5811
4232.64	40.8776
4235.43	36.5398
4238.23	26.2889
4241.02	17.0211
4243.82	29.6272
4246.61	45.3046
4249.4	18.085
4252.19	18.6672
4254.98	32.2173
4257.77	60.7237
4260.56	38.1845
4263.35	25.6614
4266.13	43.2623
4268.92	29.7957
4271.7	42.451
4274.48	17.8141
4277.26	33.3044
4280.04	50.7171
4282.82	8.47009
4285.6	44.9493
4288.38	32.7939
4291.15	62.0341
4293.93	47.714
4296.7	13.2358
4299.47	19.3356
4302.25	52.749
4305.02	47.6178
4307.79	41.4623
4310.55	51.5952
4313.32	37.4208
4316.09	53.6033
4318.85	37.1564
4321.62	29.7987
4324.38	56.9826
4327.14	17.9437
4329.9	37.9927
4332.66	34.5245
4335.42	24.9926
4338.18	28.6186
4340.94	28.3268
4343.69	17.841
4346.45	6.41217
4349.2	47.0803
4351.95	26.5398
4354.7	48.0774
4357.45	31.7234
4360.2	31.7123
4362.95	43.9301
4365.7	36.7831
4368.44	28.5269
4371.19	31.6197
4373.93	22.2537
4376.68	3.61975
4379.42	33.1624
4382.16	20.5885
4384.9	53.2731
4387.64	40.9251
4390.37	48.4301
4393.11	25.1538
4395.85	44.7548
4398.58	57.6063
4401.31	29.0308
4404.05	37.6171
4406.78	33.8073
4409.51	17.5497
4412.24	33.4023
4414.96	62.7023
4417.69	33.6589
4420.42	29.2664
4423.14	50.0582
4425.87	41.6879
4428.59	42.7101
4431.31	20.725
4434.03	32.1705
4436.75	57.2028
4439.47	26.6918
4442.19	41.1428
4444.91	17.8658
4447.62	29.1427
4450.34	33.0779
4453.05	28.5419
4455.76	35.5463
4458.47	38.2741
4461.19	59.8912
4463.89	41.6578
4466.6	23.388
4469.31	7.25031
4472.02	10.0801
4474.72	46.6858
4477.43	52.8275
4480.13	36.8788
4482.83	65.2889
4485.53	28.2262
4488.23	35.451
4490.93	29.9544
4493.63	29.5569
4496.33	43.8579
4499.02	31.8272
4501.72	23.9777
4504.41	17.1204
4507.11	28.3495
4509.8	-2.82178
4512.49	25.4019
4515.18	19.692
4517.87	37.3586
4520.56	42.3175
4523.24	32.4675
4525.93	23.6607
4528.61	9.50226
4531.3	34.7594
4533.98	20.6189
4536.66	28.8788
4539.34	17.9548
4542.02	9.18958
4544.7	41.0271
4547.38	47.2524
4550.05	37.4242
4552.73	17.9946
4555.4	36.2001
4558.08	55.6229
4560.75	11.8076
4563.42	25.0997
4566.09	27.8493
4568.76	17.7899
4571.43	41.9731
4574.1	36.1194
4576.77	41.9089
4579.43	19.7922
4582.1	14.2306
4584.76	44.7053
4587.42	43.2313
4590.08	30.8019
4592.74	44.4661
4595.4	19.9794
4598.06	28.3078
4600.72	-0.596191
4603.38	19.813
4606.03	17.2976
4608.69	21.3548
4611.34	17.7437
4613.99	22.8794
4616.64	14.8218
4619.29	6.77716
4621.94	42.7954
4624.59	38.0658
4627.24	15.6156
4629.89	31.7378
4632.53	23.5439
4635.18	42.8799
4637.82	28.9964
4640.46	-0.416138
4643.1	39.925
4645.74	15.069
4648.38	24.7271
4651.02	22.3393
4653.66	-9.87738
4656.3	0.997986
4658.93	27.9416
4661.57	-1.52124
4664.2	21.5526
4666.83	12.1546
4669.46	29.4416
4672.09	52.4039
4674.72	21.5922
4677.35	42.3088
4679.98	12.5324
4682.61	42.2183
4685.23	17.9919
4687.86	18.4709
4690.48	26.8351
4693.1	14.9387
4695.73	-4.92456
4698.34	34.9571
4700.96	32.0088
4703.58	36.9367
4706.2	-0.00653076
4708.82	4.82538
4711.43	41.3128
4714.05	26.8893
4716.66	12.4225
4719.28	22.8337
4721.89	1.4975
4724.5	14.1221
4727.11	15.4962
4729.72	7.82922
4732.33	28.5355
4734.93	29.9551
4737.54	13.1661
4740.14	30.4282
4742.75	22.66
4745.35	20.5237
4747.95	9.2381
4750.55	30.8633
4753.15	10.4033
4755.75	28.623
4758.35	30.9072
4760.95	17.3107
4763.54	21.9697
4766.14	-0.670959
4768.73	25.8073
4771.33	13.5881
4773.92	8.07928
4776.51	29.9721
4779.1	5.06726
4781.69	16.6909
4784.28	10.0433
4786.87	39.9886
4789.45	39.0767
4792.04	8.42773
4794.63	10.9832
4797.21	20.439
4799.79	9.3277
4802.37	3.97607
4804.95	0.960693
4807.53	17.556
4810.11	34.2283
4812.69	18.6749
4815.27	5.42822
4817.84	29.1399
4820.42	37.9266
4822.99	28.2142
4825.57	17.3318
4828.14	21.4976
4830.71	23.3623
4833.28	19.4749
4835.85	35.4084
4838.42	28.1259
4840.98	13.8619
4843.55	26.4545
4846.12	22.5787
4848.68	10.4183
4851.24	14.5149
4853.81	0.629883
4856.37	12.7071
4858.93	32.4083
4861.49	3.78308
4864.05	16.2635
4866.61	17.9537
4869.16	11.4131
4871.72	8.53815
4874.27	12.6483
4876.83	1.30029
4879.38	-7.68326
4881.93	15.3573
4884.49	2.76422
4887.04	21.0701
4889.58	6.11908
4892.13	23.2988
4894.68	28.582
4897.23	-4.25998
4899.77	16.5058
4902.32	12.2494
4904.86	10.3844
4907.4	26.4151
4909.95	30.5162
4912.49	27.35
4915.03	51.6356
4917.57	29.3019
4920.1	11.8235
4922.64	44.5393
4925.18	7.98474
4927.71	14.5002
4930.25	24.5581
4932.78	38.368
4935.31	48.7227
4937.84	21.9502
4940.38	25.1
4942.9	26.8506
4945.43	24.028
4947.96	28.498
4950.49	28.1831
4953.01	29.1369
4955.54	52.8466
4958.06	22.6895
4960.59	33.4007
4963.11	10.5439
4965.63	44.3625
4968.15	16.9361
4970.67	33.9563
4973.19	42.565
4975.71	0.465363
4978.22	40.5336
4980.74	50.473
4983.25	9.59186
4985.77	45.0687
4988.28	34.5404
4990.79	50.7618
4993.3	58.5163
4995.81	54.1359
4998.32	40.1182