File: Data/3-Raman/processed/bu19w-d-ff2-fi04-v_150 (500nm)_532nm_edge_100%_x100_vis_h50um_15sx2_01_0.txt
#Acq. time (s)=	15
#Accumulations=	2
#Range (cm-¹)=	100...5000
#Windows=	1
#Auto scanning=	Off
#Autofocus=	Off
#Macrospot=	Off
#AutoExposure=	Off
#Spike filter=	Multiple accum.
#Delay time (s)=	2
#Binning=	1
#Readout mode=	Signal
#DeNoise=	Off
#ICS correction=	On
#Dark correction=	Off
#Inst. Process=	Off
#Detector Gain=	Best Dynamic
#Detector ADC=	50 kHz HS
#Detector temperature (°C)=	-60.09
#Instrument=	LabRAM HR Evol
#Detector=	SIN-EM FIVIS
#Objective=	x100_VIS
#Grating=	150 (500nm)
#ND Filter=	100%
#Laser=	532nm_Edge
#Hole=	49.98
#Temperature=	0
#Range=	Visible
#StageXY=	75x50mm Scan+
#StageZ=	Z motor
#X (µm)=	0
#Y (µm)=	0
#Z (µm)=	-18.2
#Full time(s)=	38
#Project=	21_05_14
#Sample=	BU19w
#Site=
#Title=	BU19w-FF2-FI04-V_150 (500nm)_532nm_Edge_100%_x100_VIS_H50um_15sX2
#Remark=
#Date=	14.05.2021 17:49
#Acquired=	14.05.2021 17:49:54
#Base:Fit=	16.12.2021 17:39:50
#Base:Sub=	16.12.2021 18:01:58
102.699	634.709
107.322	487.342
111.942	412.315
116.56	359.57
121.173	368.493
125.787	327.118
130.398	304.837
135.006	293.657
139.613	194.072
144.215	229.8
148.817	408.917
153.417	995.007
158.014	1106.12
162.607	438.29
167.2	184.945
171.79	133.792
176.379	218.51
180.963	814.532
185.547	1007.99
190.128	584.921
194.705	214.33
199.282	60.1591
203.857	45.2446
208.43	13.1158
212.998	4.13708
217.566	-0.0424805
222.132	81.2636
226.693	338.283
231.254	417.624
235.813	548.131
240.368	1088.03
244.923	944.136
249.475	440.737
254.023	202.356
258.571	150.344
263.117	313.451
267.658	949.508
272.199	2416.47
276.738	2694.91
281.273	1408.15
285.807	601.126
290.34	352.147
294.868	422.004
299.396	493.428
303.919	372.158
308.443	224.125
312.964	219.81
317.481	406.648
321.998	774.9
326.51	904.984
331.023	570.07
335.533	402.816
340.039	686.878
344.544	1094.93
349.046	1004.79
353.547	605.454
358.045	347.831
362.542	437.059
367.036	463.685
371.527	286.191
376.017	174.639
380.503	220.641
384.99	319.284
389.471	424.775
393.953	331.87
398.43	171.18
402.908	125.155
407.381	260.635
411.854	542.617
416.323	480.089
420.791	164.099
425.256	38.0668
429.72	14.215
434.18	13.5747
438.64	0.217224
443.095	43.2065
447.551	60.2755
452.003	168.011
456.454	124.436
460.901	96.7555
465.348	70.5334
469.791	83.2425
474.231	136.867
478.672	221.955
483.108	283.39
487.544	462.709
491.976	490.172
496.408	496.081
500.836	345.261
505.261	243.826
509.687	130.71
514.108	93.9918
518.529	56.1279
522.946	63.6277
527.361	41.0636
531.776	64.9171
536.187	80.7042
540.595	83.7225
545.003	106.404
549.408	138.391
553.812	136.424
558.212	142.763
562.61	117.839
567.007	89.396
571.401	104.447
575.792	190.577
580.184	450.769
584.571	841.225
588.956	730.779
593.341	349.923
597.722	281.548
602.101	430.458
606.48	595.917
610.854	466.661
615.227	242.405
619.597	120.37
623.967	108.472
628.334	131.858
632.698	156.587
637.06	206.842
641.422	156.514
645.779	166.382
650.135	226.267
654.491	347.602
658.842	514.501
663.192	570.615
667.539	645.459
671.884	722.847
676.23	656.796
680.571	438.456
684.91	213.503
689.247	108.379
693.583	58.1093
697.916	45.9883
702.247	15.6535
706.576	16.1656
710.902	18.1336
715.229	18.6284
719.551	-0.692719
723.872	19.5432
728.19	5.71808
732.506	18.2485
736.82	16.565
741.134	21.589
745.444	41.4517
749.752	48.7892
754.058	95.0307
758.362	128.569
762.664	236.06
766.964	395.792
771.264	655.67
775.559	795.99
779.853	616.155
784.144	343.96
788.434	229.797
792.722	127.531
797.007	91.7356
801.29	60.8734
805.572	68.7949
809.851	47.1154
814.13	21.152
818.406	11.6325
822.679	38.5594
826.95	18.2229
831.219	0.0848083
835.486	3.93832
839.752	14.3675
844.015	19.1736
848.276	13.6684
852.535	20.2458
856.792	51.0544
861.047	46.5245
865.3	34.1038
869.551	17.1959
873.8	8.96078
878.047	1.75439
882.292	-1.25031
886.534	11.8917
890.775	8.18576
895.014	14.7091
899.251	8.76169
903.486	13.2896
907.719	4.88101
911.95	14.163
916.179	24.3846
920.406	59.3999
924.63	69.8442
928.853	68.1762
933.074	98.774
937.293	176.232
941.51	288.67
945.723	378.145
949.936	340.701
954.147	253.406
958.356	186.641
962.563	204.037
966.768	174.747
970.971	102.199
975.172	107.154
979.371	63.5281
983.568	51.7336
987.761	62.0732
991.954	47.3623
996.145	39.4216
1000.33	36.9112
1004.52	59.9382
1008.71	59.7531
1012.89	60.4281
1017.07	71.7515
1021.25	91.6101
1025.43	123.986
1029.6	162.817
1033.77	209.53
1037.95	324.763
1042.11	609.074
1046.28	1097.22
1050.45	1344.53
1054.61	993.184
1058.77	605.139
1062.93	400.867
1067.09	335.251
1071.24	336.777
1075.4	453.198
1079.55	735.715
1083.7	1147.85
1087.85	1360.34
1091.99	1184.96
1096.14	931.312
1100.28	930.042
1104.42	1226.25
1108.55	1326.17
1112.69	1118.27
1116.82	936.413
1120.96	971.692
1125.09	1075.82
1129.21	1118.81
1133.34	935.041
1137.46	687.569
1141.59	513.796
1145.71	530.884
1149.83	659.829
1153.94	849.177
1158.06	748.49
1162.17	623.508
1166.28	554.085
1170.39	415.215
1174.5	263.956
1178.6	169.537
1182.7	118.466
1186.8	152.287
1190.9	144.805
1195	122.843
1199.1	116.071
1203.19	99.0858
1207.28	105.512
1211.37	147.331
1215.46	241.368
1219.54	327.019
1223.63	265.829
1227.71	186.193
1231.79	244.07
1235.87	312.744
1239.95	294.115
1244.02	194.772
1248.09	148.875
1252.16	120.092
1256.23	94.3892
1260.3	94.7396
1264.36	145.225
1268.43	521.598
1272.49	239.807
1276.55	72.8376
1280.6	46.2093
1284.66	54.5848
1288.71	53.8943
1292.76	36.9604
1296.81	42.1539
1300.86	38.1856
1304.91	35.1287
1308.95	47.2126
1312.99	25.8499
1317.03	32.531
1321.07	38.1345
1325.11	59.5186
1329.14	48.8313
1333.18	38.9527
1337.21	45.006
1341.24	34.9843
1345.26	58.8754
1349.29	31.9121
1353.31	76.6212
1357.33	90.4141
1361.35	90.2765
1365.37	168.428
1369.39	507.104
1373.4	786.026
1377.41	238.766
1381.43	60.9493
1385.43	61.699
1389.44	53.6494
1393.45	80.2932
1397.45	72.5952
1401.45	16.4933
1405.45	45.1794
1409.45	23.6478
1413.44	34.6849
1417.44	4.26202
1421.43	5.38046
1425.42	8.30576
1429.41	29.8229
1433.39	32.7141
1437.38	19.7231
1441.36	33.4059
1445.34	25.2597
1449.32	25.9812
1453.3	23.6329
1457.27	5.4798
1461.24	6.89679
1465.22	10.1697
1469.19	12.5061
1473.15	18.7787
1477.12	14.1433
1481.09	-0.300476
1485.05	6.76358
1489.01	9.90134
1492.97	0.397644
1496.93	11.3838
1500.88	20.4865
1504.83	16.0774
1508.79	9.83682
1512.74	29.8189
1516.68	14.8984
1520.63	22.3483
1524.57	2.67203
1528.52	16.0222
1532.46	9.05505
1536.4	27.2883
1540.33	29.0589
1544.27	10.4775
1548.2	24.8431
1552.14	27.5481
1556.07	27.2614
1559.99	30.779
1563.92	27.4691
1567.84	22.183
1571.77	31.3713
1575.69	24.127
1579.61	20.7286
1583.52	31.7676
1587.44	22.5334
1591.35	49.868
1595.27	45.4283
1599.18	36.22
1603.09	64.5227
1606.99	49.6838
1610.9	40.6257
1614.8	69.0093
1618.7	58.1268
1622.6	53.9609
1626.5	50.8626
1630.39	45.9637
1634.29	62.2175
1638.18	33.4941
1642.07	58.5633
1645.96	48.2585
1649.85	66.7543
1653.73	25.7454
1657.62	40.3494
1661.5	35.6921
1665.38	52.0837
1669.26	40.4948
1673.13	31.6715
1677.01	50.5807
1680.88	18.318
1684.75	32.1047
1688.62	28.5374
1692.49	28.7044
1696.35	31.6622
1700.22	36.4121
1704.08	26.744
1707.94	26.5053
1711.8	48.0304
1715.66	21.2278
1719.51	25.7174
1723.37	15.088
1727.22	21.3579
1731.07	24.7648
1734.92	48.7568
1738.76	44.5318
1742.61	18.8842
1746.45	16.7932
1750.29	38.1997
1754.13	16.1871
1757.97	18.0092
1761.81	19.1466
1765.64	-0.356506
1769.47	-0.0465698
1773.31	33.859
1777.14	24.1454
1780.96	27.6169
1784.79	6.85837
1788.61	11.3448
1792.43	11.1721
1796.25	23.202
1800.07	26.5994
1803.89	39.2164
1807.71	26.3929
1811.52	26.6618
1815.33	24.87
1819.14	21.9427
1822.95	9.47739
1826.76	28.0198
1830.56	21.8926
1834.37	9.07489
1838.17	9.3721
1841.97	18.02
1845.77	15.3672
1849.56	39.7995
1853.36	30.2615
1857.15	29.9515
1860.94	25.8059
1864.73	32.8423
1868.52	44.5464
1872.31	32.2324
1876.09	20.9618
1879.87	17.2459
1883.66	16.4223
1887.43	23.3048
1891.21	36.0065
1894.99	24.743
1898.76	6.26025
1902.53	25.6756
1906.31	32.2789
1910.08	14.1403
1913.84	23.76
1917.61	17.9004
1921.37	31.648
1925.14	28.8108
1928.9	39.0446
1932.66	32.5686
1936.41	40.9734
1940.17	30.6994
1943.92	4.56516
1947.68	6.03424
1951.43	22.3333
1955.18	43.1048
1958.92	28.85
1962.67	32.3941
1966.41	27.4259
1970.16	39.0742
1973.9	24.3557
1977.64	36.7061
1981.37	52.6856
1985.11	54.5161
1988.84	43.2497
1992.57	38.3959
1996.31	29.7593
2000.03	42.3929
2003.76	14.37
2007.49	33.3203
2011.21	53.9968
2014.93	23.2983
2018.65	27.9184
2022.37	43.758
2026.09	41.5606
2029.81	33.7694
2033.52	24.6715
2037.23	28.2362
2040.94	37.3275
2044.65	45.4222
2048.36	40.8192
2052.07	38.1191
2055.77	29.0977
2059.47	40.6885
2063.17	28.6032
2066.87	28.509
2070.57	43.1909
2074.27	45.9254
2077.96	52.4362
2081.65	21.847
2085.34	46.568
2089.03	40.8622
2092.72	19.64
2096.41	26.3978
2100.09	31.0285
2103.77	54.1751
2107.46	47.4586
2111.14	33.2572
2114.81	40.4247
2118.49	30.6978
2122.16	36.5505
2125.84	70.1598
2129.51	33.2173
2133.18	50.9115
2136.85	35.2388
2140.51	53.6215
2144.18	50.7194
2147.84	47.8118
2151.5	49.5067
2155.16	64.9634
2158.82	52.0634
2162.48	35.6493
2166.13	23.0112
2169.79	45.1777
2173.44	71.1837
2177.09	43.5089
2180.74	35.0158
2184.38	52.9095
2188.03	59.2436
2191.67	53.9529
2195.32	49.7763
2198.96	51.1146
2202.6	58.0153
2206.23	65.0306
2209.87	73.9869
2213.5	62.8632
2217.14	28.7711
2220.77	60.7839
2224.4	40.4211
2228.03	69.7512
2231.65	43.8188
2235.28	56.6714
2238.9	63.0468
2242.52	55.5148
2246.14	49.8107
2249.76	36.7023
2253.38	76.768
2256.99	53.4611
2260.6	35.6333
2264.21	56.1676
2267.82	26.1846
2271.44	29.0237
2275.04	32.5917
2278.65	45.3892
2282.25	45.6563
2285.85	27.1461
2289.45	24.5853
2293.05	37.1403
2296.65	45.9618
2300.25	44.3322
2303.84	27.4064
2307.43	52.0865
2311.02	64.3735
2314.62	143.857
2318.2	81.0475
2321.79	21.8387
2325.38	27.7554
2328.96	41.2377
2332.54	30.0467
2336.12	24.4835
2339.7	31.0903
2343.28	16.0251
2346.85	35.6285
2350.43	52.3298
2354	14.782
2357.57	0.64093
2361.14	33.9634
2364.71	38.4008
2368.27	30.8712
2371.84	35.456
2375.4	30.7352
2378.96	57.4413
2382.52	39.0302
2386.08	33.6129
2389.64	17.3062
2393.19	53.4453
2396.75	24.6483
2400.3	36.4379
2403.85	37.4379
2407.4	28.4564
2410.95	36.2128
2414.49	28.4661
2418.04	20.8244
2421.58	21.5476
2425.12	27.9547
2428.66	30.8086
2432.2	29.1553
2435.74	34.0842
2439.27	21.394
2442.81	42.2519
2446.34	30.5464
2449.87	39.5298
2453.4	39.0058
2456.93	28.5681
2460.45	48.9535
2463.98	32.3825
2467.5	28.9368
2471.02	26.3204
2474.54	34.3091
2478.06	40.6066
2481.58	21.3577
2485.09	28.1882
2488.61	34.0549
2492.12	21.2029
2495.63	30.7321
2499.14	39.3898
2502.65	22.5792
2506.15	6.68768
2509.66	55.9746
2513.16	46.6569
2516.66	37.4908
2520.16	16.0527
2523.66	21.7952
2527.16	30.563
2530.66	32.0027
2534.15	32.6802
2537.64	26.0866
2541.13	43.7166
2544.62	32.1126
2548.11	9.45679
2551.6	22.9141
2555.08	20.9717
2558.57	31.0853
2562.05	21.002
2565.53	9.19958
2569.01	27.3768
2572.49	18.6037
2575.96	12.7142
2579.44	36.0413
2582.91	17.957
2586.38	40.444
2589.85	9.55609
2593.32	17.3707
2596.79	36.8233
2600.25	35.3687
2603.72	31.7402
2607.18	19.0581
2610.64	38.4279
2614.1	48.4504
2617.56	21.7644
2621.02	36.282
2624.47	20.8536
2627.92	24.5534
2631.38	11.8209
2634.83	3.73041
2638.28	20.4682
2641.72	44.686
2645.17	19.1436
2648.61	23.1358
2652.06	9.84052
2655.5	34.4656
2658.94	45.653
2662.38	27.4016
2665.82	41.3136
2669.25	27.8006
2672.69	31.3337
2676.12	21.8087
2679.55	21.7847
2682.98	21.8934
2686.41	38.1872
2689.84	25.9142
2693.26	30.2633
2696.69	45.8866
2700.11	29.955
2703.53	33.4333
2706.95	42.926
2710.37	20.0146
2713.79	31.6307
2717.2	26.6086
2720.62	11.4063
2724.03	40.0936
2727.44	31.5185
2730.85	1.3678
2734.26	29.2278
2737.66	-1.92761
2741.07	32.4733
2744.47	30.1808
2747.87	40.1143
2751.28	23.7092
2754.67	29.7589
2758.07	41.5442
2761.47	28.6817
2764.86	34.585
2768.26	24.3535
2771.65	38.5934
2775.04	33.895
2778.43	13.104
2781.82	23.344
2785.2	28.8462
2788.59	41.8584
2791.97	39.7725
2795.35	49.0154
2798.73	16.8338
2802.11	45.6499
2805.49	27.5785
2808.87	36.6508
2812.24	31.6577
2815.62	40.6385
2818.99	38.4788
2822.36	38.2848
2825.73	12.9553
2829.1	17.5307
2832.46	45.4973
2835.83	29.7643
2839.19	25.3159
2842.55	24.7051
2845.91	54.0909
2849.27	35.2599
2852.63	42.4247
2855.99	24.4234
2859.34	38.2962
2862.69	31.6079
2866.05	39.943
2869.4	32.2886
2872.75	39.642
2876.09	41.3466
2879.44	49.6442
2882.78	55.0842
2886.13	38.7856
2889.47	31.0009
2892.81	31.5504
2896.15	54.7248
2899.49	50.3968
2902.82	50.7136
2906.16	56.6696
2909.49	47.4232
2912.82	41.962
2916.16	35.4533
2919.49	55.3921
2922.81	59.2318
2926.14	42.1652
2929.46	55.3177
2932.79	58.8849
2936.11	48.3018
2939.43	75.4305
2942.75	48.8531
2946.07	58.1103
2949.39	56.9948
2952.7	66.1945
2956.02	56.697
2959.33	55.7491
2962.64	62.291
2965.95	61.4565
2969.26	72.1072
2972.57	61.0836
2975.87	76.5515
2979.17	54.3668
2982.48	64.1175
2985.78	72.9789
2989.08	71.5331
2992.38	84.2042
2995.68	68.7328
2998.97	75.8252
3002.27	95.1214
3005.56	98.4954
3008.85	71.7741
3012.14	71.4332
3015.43	96.528
3018.72	93.3444
3022	95.8159
3025.29	104.915
3028.57	97.9626
3031.85	101.374
3035.14	109.486
3038.41	93.0167
3041.69	101.144
3044.97	112.145
3048.24	123.134
3051.52	134.17
3054.79	129.082
3058.06	148.58
3061.33	144.211
3064.6	156.034
3067.87	143.095
3071.13	160.963
3074.4	152.611
3077.66	166.073
3080.92	170.421
3084.18	167.314
3087.44	190.917
3090.7	162.429
3093.95	196.948
3097.21	186.878
3100.46	210.091
3103.71	212.61
3106.96	217.072
3110.21	210.857
3113.46	239.847
3116.71	233.651
3119.95	234.127
3123.2	275.56
3126.44	241.714
3129.68	281.241
3132.92	274.068
3136.16	287.828
3139.4	280.598
3142.63	318.175
3145.87	313.847
3149.1	328.624
3152.33	331.934
3155.56	342.89
3158.79	375.778
3162.02	360.963
3165.25	404.303
3168.47	378.865
3171.69	392.514
3174.92	416.588
3178.14	420.59
3181.36	429.383
3184.58	468.61
3187.79	453.428
3191.01	471.604
3194.22	471.658
3197.43	483.117
3200.65	456.512
3203.86	488.972
3207.07	482.44
3210.27	485.486
3213.48	504.78
3216.69	535.503
3219.89	498.704
3223.09	539.051
3226.29	554.702
3229.49	548.56
3232.69	540.446
3235.89	538.21
3239.08	538.929
3242.28	581.62
3245.47	587.187
3248.66	581.408
3251.85	600.475
3255.04	603.346
3258.23	596.55
3261.42	608.7
3264.6	579.622
3267.79	600.095
3270.97	607.11
3274.15	599.797
3277.33	629.56
3280.51	597.97
3283.68	654.186
3286.86	642.54
3290.04	645.273
3293.21	645.135
3296.38	635.428
3299.55	644.103
3302.72	671.614
3305.89	673.279
3309.06	684.271
3312.22	676.151
3315.39	687.942
3318.55	699.665
3321.71	709.475
3324.87	710.759
3328.03	724.351
3331.19	741.772
3334.34	762.099
3337.5	752.314
3340.65	776.496
3343.81	781.094
3346.96	790.77
3350.11	811.776
3353.25	811.231
3356.4	791.899
3359.55	831.171
3362.69	839.388
3365.84	835.417
3368.98	854.125
3372.12	861.675
3375.26	896.686
3378.4	881.755
3381.53	910.215
3384.67	919.892
3387.8	960.834
3390.94	973.491
3394.07	993.163
3397.2	966.183
3400.33	1056.09
3403.46	1130.18
3406.58	1283.43
3409.71	1589.34
3412.83	2499.24
3415.96	4696.21
3419.08	6195.96
3422.2	4525.83
3425.32	2406.55
3428.44	1566.26
3431.55	1293.61
3434.67	1178.01
3437.78	1105.55
3440.89	1058.97
3444	1049.28
3447.12	1029.07
3450.22	1010.55
3453.33	1005.37
3456.44	1028.53
3459.54	999.3
3462.65	996.666
3465.75	999.61
3468.85	1044.77
3471.95	1044.79
3475.05	1115.01
3478.15	1147.37
3481.24	1244.93
3484.34	1333.01
3487.43	1585.39
3490.53	1828.78
3493.62	2246.69
3496.71	2732.92
3499.79	3186.14
3502.88	3172.65
3505.97	2719.43
3509.05	2148.91
3512.14	1704.1
3515.22	1371.62
3518.3	1209.91
3521.38	1074.11
3524.46	922.39
3527.54	858.372
3530.61	785.621
3533.69	738.626
3536.76	699.926
3539.83	706.398
3542.9	634.934
3545.97	615.404
3549.04	607.981
3552.11	546.443
3555.18	562.585
3558.24	520.155
3561.3	499.243
3564.37	489.607
3567.43	479.061
3570.49	456.973
3573.55	439.515
3576.61	429.605
3579.66	436.697
3582.72	393.44
3585.77	411.809
3588.82	378.895
3591.87	380.076
3594.92	355.611
3597.97	350.091
3601.02	355.878
3604.07	331.307
3607.11	331.333
3610.16	304.861
3613.2	316.174
3616.24	274.619
3619.28	291.645
3622.32	252.096
3625.36	273.895
3628.39	260.802
3631.43	255.206
3634.46	231.846
3637.5	216.142
3640.53	197.69
3643.56	190.686
3646.59	184.528
3649.62	156.803
3652.64	169.836
3655.67	164.84
3658.69	149.825
3661.72	142.242
3664.74	117.445
3667.76	131.306
3670.78	120.71
3673.79	94.0891
3676.81	92.967
3679.83	86.1587
3682.84	80.2836
3685.86	81.9821
3688.87	72.337
3691.88	80.694
3694.89	69.0713
3697.9	61.285
3700.91	48.7715
3703.91	49.5359
3706.92	56.9101
3709.92	40.4837
3712.92	28.7395
3715.92	53.1577
3718.92	17.5926
3721.92	36.2349
3724.92	36.751
3727.92	21.0449
3730.91	55.7711
3733.91	27.5966
3736.9	34.6154
3739.89	29.2074
3742.88	32.325
3745.87	38.2497
3748.86	36.5278
3751.85	26.2464
3754.83	34.0185
3757.82	32.2933
3760.8	43.8049
3763.78	40.1436
3766.76	32.7297
3769.74	25.3648
3772.72	28.4427
3775.7	40.9952
3778.67	24.283
3781.65	15.1474
3784.62	27.7525
3787.6	26.2143
3790.57	25.681
3793.54	24.2487
3796.51	29.4483
3799.47	9.21103
3802.44	19.2148
3805.41	15.0671
3808.37	9.05051
3811.33	31.405
3814.3	19.7385
3817.26	15.6484
3820.22	35.2309
3823.18	16.9731
3826.13	14.8186
3829.09	25.9316
3832.04	39.9363
3835	16.9538
3837.95	17.7014
3840.9	7.98422
3843.85	20.1469
3846.8	20.9122
3849.75	16.9357
3852.69	2.46933
3855.64	14.7196
3858.58	1.19324
3861.53	24.9288
3864.47	16.1508
3867.41	27.45
3870.35	29.1596
3873.29	8.78918
3876.22	30.5963
3879.16	8.19653
3882.1	13.5954
3885.03	20.8835
3887.96	9.8877
3890.89	17.1431
3893.82	16.6627
3896.75	7.47321
3899.68	30.969
3902.61	40.9379
3905.53	29.7977
3908.46	7.10739
3911.38	24.747
3914.3	14.4717
3917.23	14.8394
3920.15	18.0359
3923.06	10.6217
3925.98	12.767
3928.9	19.661
3931.81	1.71677
3934.73	26.9571
3937.64	29.3048
3940.55	21.0956
3943.46	7.14954
3946.37	6.64447
3949.28	11.9179
3952.19	31.5722
3955.09	5.29135
3958	24.0513
3960.9	16.0036
3963.8	24.2723
3966.71	12.4242
3969.61	16.8965
3972.51	10.8077
3975.4	27.747
3978.3	18.7224
3981.2	12.5671
3984.09	6.38718
3986.99	21.3619
3989.88	23.7697
3992.77	23.3586
3995.66	-2.07224
3998.55	16.7828
4001.43	21.2093
4004.32	20.8419
4007.21	11.8097
4010.09	13.3701
4012.98	23.6147
4015.86	6.84964
4018.74	26.7515
4021.62	26.3879
4024.5	23.1345
4027.37	25.678
4030.25	20.4993
4033.13	6.60956
4036	29.5043
4038.87	21.4384
4041.75	28.8017
4044.62	17.7512
4047.49	-0.0692749
4050.35	22.8489
4053.22	28.3523
4056.09	22.2206
4058.95	18.9735
4061.82	23.4954
4064.68	11.4908
4067.54	20.8727
4070.4	25.3923
4073.26	5.56607
4076.12	11.0445
4078.98	8.72913
4081.83	17.1381
4084.69	25.5451
4087.54	27.1156
4090.4	16.9898
4093.25	11.7365
4096.1	13.3091
4098.95	11.9628
4101.8	9.62057
4104.64	22.8985
4107.49	9.74445
4110.33	18.0996
4113.18	3.89871
4116.02	11.1869
4118.86	-3.07758
4121.7	18.9008
4124.54	12.5262
4127.38	16.9722
4130.22	14.6511
4133.05	19.265
4135.89	16.821
4138.72	30.5778
4141.56	17.0722
4144.39	12.7403
4147.22	18.2226
4150.05	28.5709
4152.88	-1.3533
4155.7	12.6454
4158.53	9.02753
4161.36	2.58871
4164.18	14.7367
4167	24.932
4169.82	8.74371
4172.65	22.8863
4175.46	8.67209
4178.28	7.1871
4181.1	11.5933
4183.92	16.0147
4186.73	35.1299
4189.55	15.1415
4192.36	24.5631
4195.17	27.1801
4197.98	39.619
4200.79	36.3752
4203.6	32.1486
4206.41	20.0544
4209.21	30.5442
4212.02	17.4398
4214.83	10.3409
4217.63	5.29144
4220.43	23.8463
4223.23	-0.0450745
4226.03	12.5874
4228.83	19.3533
4231.63	19.226
4234.42	16.1587
4237.22	0.187225
4240.01	16.985
4242.81	12.9397
4245.6	19.8444
4248.39	21.7436
4251.18	10.6365
4253.97	31.4936
4256.76	15.3225
4259.55	28.2004
4262.33	13.0175
4265.12	12.8911
4267.9	10.7585
4270.68	16.6689
4273.47	7.41867
4276.25	3.13565
4279.03	22.0511
4281.8	20.7444
4284.58	10.2884
4287.36	4.84195
4290.13	8.48044
4292.91	3.02774
4295.68	16.8669
4298.45	14.4843
4301.22	9.03552
4303.99	13.7337
4306.76	13.3662
4309.53	9.97641
4312.3	0.462433
4315.06	1.06714
4317.83	10.8096
4320.59	4.24377
4323.35	27.1834
4326.11	16.5243
4328.87	11.9585
4331.63	16.5534
4334.39	5.85931
4337.15	15.5623
4339.9	13.0724
4342.66	9.57672
4345.41	24.4759
4348.17	2.65872
4350.92	3.33496
4353.67	-1.07797
4356.42	17.9997
4359.17	4.34894
4361.91	14.2393
4364.66	2.62646
4367.41	14.5818
4370.15	17.3023
4372.89	-2.58945
4375.63	23.6902
4378.38	15.0498
4381.12	22.8547
4383.86	18.3846
4386.59	25.3369
4389.33	7.66397
4392.07	1.45343
4394.8	17.9352
4397.53	3.27277
4400.27	12.4005
4403	21.5413
4405.73	24.4908
4408.46	8.71225
4411.19	21.9959
4413.92	12.3583
4416.64	6.79163
4419.37	3.28217
4422.09	20.691
4424.82	-0.520142
4427.54	26.3239
4430.26	32.2799
4432.98	19.388
4435.7	2.27136
4438.42	14.4574
4441.13	5.67441
4443.85	4.22043
4446.57	19.5508
4449.28	12.8258
4451.99	8.18094
4454.71	23.4827
4457.42	3.03076
4460.13	-0.588379
4462.83	22.1006
4465.54	7.98132
4468.25	12.8172
4470.95	33.4784
4473.66	21.5205
4476.36	2.18976
4479.07	9.23727
4481.77	12.0756
4484.47	1.15958
4487.17	19.8398
4489.87	19.4398
4492.56	15.7477
4495.26	12.1346
4497.96	-2.07288
4500.65	24.9863
4503.34	13.9369
4506.04	17.7399
4508.73	14.1193
4511.42	11.5609
4514.11	9.01303
4516.8	23.4595
4519.48	26.2722
4522.17	21.6477
4524.85	9.5513
4527.54	23.0141
4530.22	6.65506
4532.9	16.9516
4535.58	21.9238
4538.27	25.8708
4540.94	2.01624
4543.62	13.4426
4546.3	7.75574
4548.98	19.2135
4551.65	10.3786
4554.33	3.68378
4557	14.2798
4559.67	8.79648
4562.34	10.9007
4565.01	8.84613
4567.68	4.52124
4570.35	22.6468
4573.02	-1.82379
4575.68	20.5532
4578.35	19.1258
4581.01	26.613
4583.67	10.9829
4586.34	10.5854
4589	0.332947
4591.66	29.3434
4594.31	22.4414
4596.97	9.98352
4599.63	10.6993
4602.29	13.6347
4604.94	25.3386
4607.59	23.9135
4610.25	11.4952
4612.9	27.6129
4615.55	7.47394
4618.2	2.73337
4620.85	1.28271
4623.5	15.2487
4626.14	17.0718
4628.79	6.75217
4631.43	18.4827
4634.08	13.6013
4636.72	35.2834
4639.36	3.8089
4642	7.81177
4644.64	18.5497
4647.28	6.0493
4649.92	18.0594
4652.56	25.7907
4655.19	16.2028
4657.83	15.8004
4660.46	14.3457
4663.1	-1.63902
4665.73	14.6723
4668.36	18.7325
4670.99	16.0676
4673.62	25.7277
4676.24	21.9324
4678.87	11.3822
4681.5	12.0508
4684.12	38.5863
4686.75	17.8882
4689.37	16.3252
4691.99	15.8545
4694.61	24.3943
4697.23	8.12274
4699.85	4.25374
4702.47	11.6449
4705.09	22.4295
4707.7	28.6856
4710.32	29.2832
4712.93	10.6283
4715.55	10.0542
4718.16	21.9506
4720.77	15.6759
4723.38	24.1772
4725.99	15.6928
4728.6	19.6843
4731.21	16.8667
4733.81	24.2685
4736.42	11.1869
4739.02	24.2516
4741.63	-4.79889
4744.23	23.0263
4746.83	16.6596
4749.43	3.47322
4752.03	9.63063
4754.63	29.4317
4757.23	12.8299
4759.82	29.2682
4762.42	36.602
4765.01	24.615
4767.61	20.6747
4770.2	14.3605
4772.79	17.1725
4775.38	2.86339
4777.97	19.375
4780.56	18.7569
4783.15	28.4306
4785.74	19.808
4788.32	16.9014
4790.91	16.2964
4793.49	14.5397
4796.07	21.9788
4798.66	22.5586
4801.24	28.8937
4803.82	13.4304
4806.4	14.0752
4808.98	28.5225
4811.55	13.0413
4814.13	15.9961
4816.71	12.0525
4819.28	15.0319
4821.85	21.4957
4824.43	7.09529
4827	14.7031
4829.57	28.1818
4832.14	18.3992
4834.71	9.78372
4837.28	17.5141
4839.84	15.9173
4842.41	11.9164
4844.97	21.9522
4847.54	22.5799
4850.1	6.59059
4852.66	1.02759
4855.22	26.3933
4857.78	18.8237
4860.34	12.3598
4862.9	14.0485
4865.46	22.782
4868.01	10.3448
4870.57	17.9534
4873.12	19.597
4875.68	14.1248
4878.23	20.4988
4880.78	12.6026
4883.33	23.7024
4885.88	14.5973
4888.43	3.10493
4890.98	11.8214
4893.53	8.62553
4896.07	16.1353
4898.62	24.84
4901.16	15.6384
4903.7	8.82266
4906.25	17.4824
4908.79	26.121
4911.33	21.5803
4913.87	31.3488
4916.41	7.67036
4918.94	24.6144
4921.48	17.6584
4924.02	23.8515
4926.55	19.2716
4929.08	3.94925
4931.62	14.9753
4934.15	4.46655
4936.68	21.4573
4939.21	22.8229
4941.74	11.0193
4944.27	1.6637
4946.79	4.28096
4949.32	0.905411
4951.85	11.9054
4954.37	8.5192
4956.9	13.5592
4959.42	7.80145
4961.94	5.68176
4964.46	13.2356
4966.98	1.48338
4969.5	-5.50941
4972.02	0.758575
4974.53	14.2763
4977.05	6.03761
4979.57	8.68074
4982.08	13.7495
4984.59	12.7602
4987.1	3.26422
4989.62	14.4022
4992.13	6.07657
4994.64	1.40089
4997.15	6.48476
4999.65	-0.633316