File: Data/3-Raman/processed/bu19w-c-ore1-fi02-v_150 (500nm)_532nm_edge_100%_x100_vis_h50um_15sx2_01_0.txt
#Acq. time (s)=	15
#Accumulations=	2
#Range (cm-¹)=	100...5000
#Windows=	1
#Auto scanning=	Off
#Autofocus=	Off
#Macrospot=	Off
#AutoExposure=	Off
#Spike filter=	Multiple accum.
#Delay time (s)=	2
#Binning=	1
#Readout mode=	Signal
#DeNoise=	Off
#ICS correction=	On
#Dark correction=	Off
#Inst. Process=	Off
#Detector Gain=	Best Dynamic
#Detector ADC=	50 kHz HS
#Detector temperature (°C)=	-60.09
#Instrument=	LabRAM HR Evol
#Detector=	SIN-EM FIVIS
#Objective=	x100_VIS
#Grating=	150 (500nm)
#ND Filter=	100%
#Laser=	532nm_Edge
#Hole=	49.98
#Temperature=	0
#Range=	Visible
#StageXY=	75x50mm Scan+
#StageZ=	Z motor
#X (µm)=	0
#Y (µm)=	0
#Z (µm)=	-15.3
#Full time(s)=	35
#Project=	21_05_14
#Sample=	BU19w
#Site=
#Title=	BU19w-FF-ore1-FI02-V_150 (500nm)_532nm_Edge_100%_x100_VIS_H50um_15sX2
#Remark=
#Date=	14.05.2021 18:32
#Acquired=	14.05.2021 18:32:28
#Base:Fit=	16.12.2021 17:39:50
#Base:Sub=	16.12.2021 18:01:44
102.699	378.515
107.322	310.911
111.942	231.646
116.56	233.5
121.173	172.305
125.787	152.867
130.398	320.561
135.006	199.95
139.613	128.196
144.215	149.108
148.817	496.753
153.417	1565.4
158.014	1565.66
162.607	641.857
167.2	269.094
171.79	387.808
176.379	1138.2
180.963	3552.51
185.547	3012.82
190.128	917.623
194.705	213.45
199.282	64.8499
203.857	23.9926
208.43	51.8391
212.998	40.7467
217.566	-0.737122
222.132	0.733276
226.693	158.624
231.254	211.248
235.813	285.992
240.368	503.191
244.923	336.064
249.475	187.409
254.023	109.791
258.571	157.63
263.117	398.744
267.658	1180.81
272.199	2615.47
276.738	2480.14
281.273	1218.78
285.807	596.11
290.34	659.574
294.868	1430.39
299.396	1781.72
303.919	1044.25
308.443	462.381
312.964	282.813
317.481	404.102
321.998	718.618
326.51	685.802
331.023	347.302
335.533	210.39
340.039	334.912
344.544	465.703
349.046	356.111
353.547	119.186
358.045	94.5577
362.542	135.633
367.036	174.003
371.527	159.14
376.017	279.33
380.503	566.946
384.99	654.977
389.471	772.798
393.953	709.355
398.43	481.183
402.908	341.531
407.381	488.398
411.854	772.493
416.323	388.207
420.791	144.233
425.256	54.7741
429.72	0.0785522
434.18	19.657
438.64	73.5928
443.095	278.902
447.551	944.728
452.003	1315.9
456.454	728.215
460.901	213.817
465.348	76.9993
469.791	82.9079
474.231	120.366
478.672	170.253
483.108	257.381
487.544	302.152
491.976	374.248
496.408	360.731
500.836	265.883
505.261	198.768
509.687	144.188
514.108	133.649
518.529	157.793
522.946	166.267
527.361	226.803
531.776	310.864
536.187	305.92
540.595	306.708
545.003	306.258
549.408	304.65
553.812	355.907
558.212	383.355
562.61	251.296
567.007	168.833
571.401	146.899
575.792	220.636
580.184	520.536
584.571	976.951
588.956	716.544
593.341	348.361
597.722	325.322
602.101	428.954
606.48	530.664
610.854	406.138
615.227	165.029
619.597	84.0112
623.967	121.151
628.334	115.938
632.698	199.551
637.06	259.759
641.422	166.795
645.779	160.116
650.135	92.5016
654.491	160.475
658.842	219.561
663.192	261.437
667.539	305.121
671.884	380.85
676.23	379.505
680.571	232.17
684.91	106.761
689.247	101.736
693.583	19.3145
697.916	32.6525
702.247	40.3123
706.576	28.5981
710.902	28.6076
715.229	19.0281
719.551	29.6646
723.872	56.0729
728.19	67.7826
732.506	53.027
736.82	81.2422
741.134	99.3528
745.444	140.1
749.752	152.431
754.058	239.489
758.362	329.263
762.664	574.706
766.964	1043.81
771.264	1637.68
775.559	1781.28
779.853	1219.99
784.144	719.997
788.434	429.889
792.722	299.425
797.007	190.496
801.29	127.7
805.572	108.319
809.851	95.691
814.13	62.3752
818.406	60.8679
822.679	62.9026
826.95	47.4295
831.219	65.0347
835.486	62.7457
839.752	38.3049
844.015	80.963
848.276	19.2269
852.535	76.5342
856.792	44.5187
861.047	63.0918
865.3	54.8945
869.551	35.5204
873.8	54.3369
878.047	42.2531
882.292	34.2233
886.534	-0.356018
890.775	24.2352
895.014	20.2106
899.251	42.9494
903.486	21.6339
907.719	35.3915
911.95	19.4702
916.179	27.1512
920.406	4.63049
924.63	33.7018
928.853	71.5047
933.074	93.2374
937.293	111.361
941.51	134.654
945.723	164.075
949.936	190.515
954.147	185.05
958.356	219.087
962.563	246.804
966.768	211.925
970.971	190.114
975.172	148.277
979.371	100.393
983.568	92.8442
987.761	91.4787
991.954	78.0465
996.145	67.4985
1000.33	73.1056
1004.52	78.8412
1008.71	94.3872
1012.89	104.295
1017.07	151.522
1021.25	178.537
1025.43	207.134
1029.6	279.592
1033.77	402.126
1037.95	608.435
1042.11	1001.75
1046.28	1744.93
1050.45	1903.45
1054.61	1328.94
1058.77	836.872
1062.93	534.138
1067.09	448.285
1071.24	441.068
1075.4	537.435
1079.55	832
1083.7	1218.84
1087.85	1292.73
1091.99	1145.42
1096.14	1058.5
1100.28	1305.19
1104.42	1750.14
1108.55	1700.17
1112.69	1380.18
1116.82	1168.89
1120.96	1191.99
1125.09	1250.37
1129.21	1325.6
1133.34	1011.05
1137.46	720.511
1141.59	583.934
1145.71	562.058
1149.83	682.612
1153.94	753.936
1158.06	623.856
1162.17	489.996
1166.28	365.219
1170.39	257.581
1174.5	231.206
1178.6	154.372
1182.7	174.321
1186.8	190.326
1190.9	192.623
1195	174.119
1199.1	173.684
1203.19	154.808
1207.28	151.252
1211.37	154.876
1215.46	200.859
1219.54	297.12
1223.63	238.502
1227.71	259.743
1231.79	311.356
1235.87	486.358
1239.95	401.906
1244.02	257.877
1248.09	172.673
1252.16	141.64
1256.23	117.772
1260.3	58.04
1264.36	134.493
1268.43	540.002
1272.49	269.375
1276.55	82.4559
1280.6	52.9038
1284.66	33.0774
1288.71	61.5212
1292.76	63.5873
1296.81	38.4113
1300.86	28.1721
1304.91	22.8041
1308.95	45.7061
1312.99	53.1554
1317.03	46.1676
1321.07	29.0135
1325.11	55.5983
1329.14	31.1169
1333.18	56.4476
1337.21	27.4273
1341.24	46.3654
1345.26	25.2703
1349.29	51.0777
1353.31	53.9674
1357.33	85.623
1361.35	84.4616
1365.37	112.287
1369.39	426.504
1373.4	828.101
1377.41	217.077
1381.43	57.4833
1385.43	64.8118
1389.44	74.2192
1393.45	91.9509
1397.45	16.3331
1401.45	25.1852
1405.45	37.1272
1409.45	16.63
1413.44	41.5626
1417.44	23.0685
1421.43	14.3801
1425.42	27.0955
1429.41	17.7677
1433.39	9.69019
1437.38	5.41345
1441.36	27.8281
1445.34	-1.28589
1449.32	5.11041
1453.3	1.44275
1457.27	32.1994
1461.24	10.4446
1465.22	13.1182
1469.19	11.9621
1473.15	40.2839
1477.12	17.3622
1481.09	2.27643
1485.05	15.5131
1489.01	13.0936
1492.97	26.3688
1496.93	48.4081
1500.88	17.0637
1504.83	16.1317
1508.79	49.4059
1512.74	29.2439
1516.68	32.5006
1520.63	30.0269
1524.57	27.6165
1528.52	39.8578
1532.46	38.611
1536.4	28.6465
1540.33	55.5409
1544.27	47.5427
1548.2	22.1184
1552.14	25.702
1556.07	38.8107
1559.99	45.0104
1563.92	36.5976
1567.84	14.5773
1571.77	24.4252
1575.69	67.0605
1579.61	25.6793
1583.52	19.9788
1587.44	51.7798
1591.35	34.4558
1595.27	46.9481
1599.18	47.9437
1603.09	23.158
1606.99	38.7844
1610.9	60.1667
1614.8	60.5759
1618.7	56.2412
1622.6	36.607
1626.5	43.0214
1630.39	65.9113
1634.29	57.3914
1638.18	16.3474
1642.07	53.1744
1645.96	52.7767
1649.85	54.3654
1653.73	55.9302
1657.62	28.6
1661.5	56.8726
1665.38	44.6158
1669.26	17.7405
1673.13	31.9892
1677.01	33.4834
1680.88	26.8273
1684.75	29.68
1688.62	-3.07007
1692.49	12.8812
1696.35	17.1852
1700.22	21.2826
1704.08	35.6316
1707.94	44.9648
1711.8	64.5988
1715.66	55.8138
1719.51	26.3151
1723.37	71.3618
1727.22	60.5829
1731.07	34.8004
1734.92	20.3736
1738.76	55.3677
1742.61	27.7446
1746.45	30.3698
1750.29	55.7951
1754.13	67.6777
1757.97	41.8058
1761.81	41.4423
1765.64	50.8893
1769.47	27.5206
1773.31	45.2396
1777.14	34.2811
1780.96	36.6348
1784.79	17.6071
1788.61	18.2484
1792.43	40.4863
1796.25	28.9667
1800.07	42.4284
1803.89	36.7079
1807.71	51.6737
1811.52	33.4854
1815.33	28.1611
1819.14	56.4481
1822.95	25.0968
1826.76	48.231
1830.56	37.137
1834.37	53.1651
1838.17	37.9649
1841.97	60.1795
1845.77	66.3508
1849.56	48.889
1853.36	61.0151
1857.15	46.6871
1860.94	24.7629
1864.73	49.4216
1868.52	67.5991
1872.31	50.7044
1876.09	43.2469
1879.87	46.2227
1883.66	40.2072
1887.43	35.7746
1891.21	30.9919
1894.99	55.5821
1898.76	31.6694
1902.53	37.5184
1906.31	63.7561
1910.08	36.8245
1913.84	37.7335
1917.61	25.1691
1921.37	43.4601
1925.14	52.6504
1928.9	19.2679
1932.66	33.2529
1936.41	8.07086
1940.17	54.7403
1943.92	17.4906
1947.68	30.8547
1951.43	60.7728
1955.18	68.6555
1958.92	48.7794
1962.67	32.5757
1966.41	53.8219
1970.16	69.8381
1973.9	38.7701
1977.64	31.9042
1981.37	42.6745
1985.11	55.1005
1988.84	42.2473
1992.57	72.9127
1996.31	39.2368
2000.03	35.2104
2003.76	52.6097
2007.49	33.5864
2011.21	69.825
2014.93	41.8815
2018.65	42.2281
2022.37	55.8403
2026.09	47.0887
2029.81	48.2229
2033.52	52.1514
2037.23	52.1355
2040.94	77.8179
2044.65	37.4275
2048.36	12.8166
2052.07	5.72711
2055.77	41.8746
2059.47	33.9354
2063.17	32.7442
2066.87	53.7618
2070.57	53.6713
2074.27	59.1492
2077.96	38.8368
2081.65	72.2172
2085.34	48.4218
2089.03	89.2207
2092.72	15.3457
2096.41	63.4004
2100.09	32.8539
2103.77	38.4181
2107.46	76.3533
2111.14	41.6643
2114.81	22.7663
2118.49	38.8877
2122.16	76.8705
2125.84	41.4634
2129.51	40.2114
2133.18	59.284
2136.85	44.9262
2140.51	68.2247
2144.18	51.7717
2147.84	52.8071
2151.5	52.9351
2155.16	46.7108
2158.82	68.0019
2162.48	84.8478
2166.13	40.715
2169.79	50.7241
2173.44	20.159
2177.09	37.0275
2180.74	55.798
2184.38	36.3677
2188.03	58.3477
2191.67	47.0283
2195.32	44.264
2198.96	46.1473
2202.6	50.0104
2206.23	13.8511
2209.87	65.5972
2213.5	50.692
2217.14	64.2157
2220.77	72.3101
2224.4	65.7083
2228.03	18.4458
2231.65	33.0202
2235.28	45.8203
2238.9	66.0186
2242.52	35.2288
2246.14	42.4397
2249.76	45.1306
2253.38	41.4064
2256.99	52.655
2260.6	19.8584
2264.21	23.4874
2267.82	34.8729
2271.44	46.2991
2275.04	34.7355
2278.65	58.6123
2282.25	48.9855
2285.85	30.1143
2289.45	43.19
2293.05	22.1882
2296.65	30.5785
2300.25	42.699
2303.84	55.5482
2307.43	2.83618
2311.02	89.3311
2314.62	103.615
2318.2	97.7895
2321.79	54.6041
2325.38	38.4808
2328.96	72.504
2332.54	43.9797
2336.12	20.149
2339.7	53.6326
2343.28	32.4533
2346.85	33.7349
2350.43	37.7793
2354	31.4854
2357.57	6.52051
2361.14	10.4488
2364.71	24.6106
2368.27	29.6236
2371.84	26.4138
2375.4	32.3529
2378.96	38.4017
2382.52	21.5393
2386.08	47.1351
2389.64	21.4644
2393.19	22.6948
2396.75	39.8389
2400.3	26.2573
2403.85	31.3762
2407.4	17.4291
2410.95	36.9105
2414.49	-1.26758
2418.04	6.67084
2421.58	46.116
2425.12	11.2246
2428.66	25.4114
2432.2	5.58429
2435.74	5.3252
2439.27	52.5879
2442.81	50.6955
2446.34	30.2032
2449.87	7.94641
2453.4	36.0688
2456.93	50.2567
2460.45	42.3574
2463.98	33.1378
2467.5	46.4445
2471.02	39.7421
2474.54	24.2189
2478.06	-6.94592
2481.58	3.21216
2485.09	41.9943
2488.61	12.0775
2492.12	25.5241
2495.63	25.5643
2499.14	41.6783
2502.65	39.622
2506.15	42.1124
2509.66	34.2762
2513.16	1.5838
2516.66	28.5933
2520.16	56.9155
2523.66	28.3351
2527.16	26.1718
2530.66	25.0677
2534.15	32.5568
2537.64	6.09961
2541.13	35.4114
2544.62	41.2552
2548.11	31.4955
2551.6	25.566
2555.08	34.0718
2558.57	11.0681
2562.05	3.22675
2565.53	17.0973
2569.01	19.1671
2572.49	34.5471
2575.96	20.168
2579.44	31.2249
2582.91	9.31506
2586.38	30.744
2589.85	11.8887
2593.32	3.08325
2596.79	16.4492
2600.25	-3.52698
2603.72	44.0556
2607.18	35.4229
2610.64	9.45129
2614.1	45.3434
2617.56	19.4286
2621.02	26.9548
2624.47	9.23138
2627.92	14.42
2631.38	32.8531
2634.83	37.5316
2638.28	18.0908
2641.72	36.7387
2645.17	10.4075
2648.61	35.478
2652.06	45.946
2655.5	38.0964
2658.94	46.2932
2662.38	34.4761
2665.82	23.6682
2669.25	31.6285
2672.69	56.597
2676.12	8.51257
2679.55	61.8044
2682.98	38.6003
2686.41	48.6826
2689.84	48.1662
2693.26	39.9323
2696.69	54.2402
2700.11	21.2454
2703.53	21.5396
2706.95	35.5818
2710.37	26.6296
2713.79	24.3696
2717.2	23.2324
2720.62	19.4449
2724.03	29.7246
2727.44	39.196
2730.85	14.946
2734.26	25.2973
2737.66	59.1303
2741.07	39.3594
2744.47	18.425
2747.87	38.8389
2751.28	27.2787
2754.67	39.9835
2758.07	10.4517
2761.47	44.6997
2764.86	45.8582
2768.26	51.5355
2771.65	32.6652
2775.04	32.4913
2778.43	27.4669
2781.82	53.4278
2785.2	50.1621
2788.59	20.5685
2791.97	30.395
2795.35	48.7576
2798.73	55.6315
2802.11	73.7577
2805.49	70.3095
2808.87	48.0941
2812.24	19.3373
2815.62	79.3159
2818.99	20.7618
2822.36	31.4888
2825.73	46.9276
2829.1	34.4919
2832.46	40.8763
2835.83	35.2995
2839.19	33.6225
2842.55	28.4041
2845.91	47.6902
2849.27	-1.63037
2852.63	34.6974
2855.99	47.8168
2859.34	50.8171
2862.69	56.6688
2866.05	62.582
2869.4	29.9317
2872.75	64.8687
2876.09	41.5018
2879.44	39.7448
2882.78	69.9707
2886.13	23.7392
2889.47	50.2238
2892.81	62.306
2896.15	73.3353
2899.49	39.769
2902.82	43.9003
2906.16	61.2194
2909.49	68.9783
2912.82	60.6501
2916.16	63.51
2919.49	66.3043
2922.81	80.4223
2926.14	80.174
2929.46	52.4928
2932.79	70.8936
2936.11	47.773
2939.43	51.0772
2942.75	54.3889
2946.07	96.3369
2949.39	101.528
2952.7	40.9102
2956.02	80.9859
2959.33	88.3192
2962.64	59.0355
2965.95	92.8093
2969.26	71.6066
2972.57	87.7594
2975.87	103.334
2979.17	65.2286
2982.48	94.7366
2985.78	79.2633
2989.08	85.4072
2992.38	54.9542
2995.68	95.0291
2998.97	108.825
3002.27	92.482
3005.56	81.8584
3008.85	48.6705
3012.14	83.3214
3015.43	97.247
3018.72	93.2485
3022	91.1248
3025.29	83.3547
3028.57	75.5708
3031.85	94.2026
3035.14	110.913
3038.41	101.159
3041.69	68.6849
3044.97	91.1339
3048.24	86.0949
3051.52	112.378
3054.79	101.68
3058.06	75.6862
3061.33	90.2666
3064.6	133.401
3067.87	117.577
3071.13	125.722
3074.4	132.437
3077.66	114.505
3080.92	125.513
3084.18	122.474
3087.44	149.981
3090.7	134.96
3093.95	153.237
3097.21	126.951
3100.46	163.42
3103.71	159.293
3106.96	127.607
3110.21	146.086
3113.46	138.838
3116.71	144.96
3119.95	155.853
3123.2	161.022
3126.44	175.691
3129.68	137.001
3132.92	191.691
3136.16	175.807
3139.4	179.913
3142.63	218.337
3145.87	186.254
3149.1	191.39
3152.33	208.895
3155.56	200.659
3158.79	193.352
3162.02	202.263
3165.25	203.477
3168.47	225.605
3171.69	209.517
3174.92	236.29
3178.14	222.951
3181.36	265.913
3184.58	232.483
3187.79	221.895
3191.01	242.755
3194.22	232.149
3197.43	255.809
3200.65	239.491
3203.86	256.528
3207.07	265.983
3210.27	283.104
3213.48	291.733
3216.69	286.105
3219.89	288.103
3223.09	305.413
3226.29	277.091
3229.49	297.369
3232.69	326.143
3235.89	277.051
3239.08	284.197
3242.28	327.599
3245.47	299.568
3248.66	307.82
3251.85	296.093
3255.04	334.941
3258.23	323.097
3261.42	306.318
3264.6	302.755
3267.79	345.881
3270.97	340.202
3274.15	320.193
3277.33	338.222
3280.51	334.053
3283.68	326.061
3286.86	361.854
3290.04	381.469
3293.21	366.75
3296.38	355.808
3299.55	362.279
3302.72	361.898
3305.89	369.945
3309.06	388.271
3312.22	390.326
3315.39	395.191
3318.55	404.742
3321.71	383.012
3324.87	402.024
3328.03	414.394
3331.19	394.678
3334.34	465.729
3337.5	429.204
3340.65	400.267
3343.81	411.158
3346.96	466.665
3350.11	455.254
3353.25	457.15
3356.4	460.041
3359.55	464.956
3362.69	491.598
3365.84	513.594
3368.98	495.062
3372.12	485.143
3375.26	478.105
3378.4	525.935
3381.53	547.274
3384.67	533.728
3387.8	590.209
3390.94	599.474
3394.07	624.335
3397.2	664.07
3400.33	785.679
3403.46	930.447
3406.58	1166.87
3409.71	1821.65
3412.83	3272.44
3415.96	6755.55
3419.08	8616.01
3422.2	5646.87
3425.32	2629.14
3428.44	1453.26
3431.55	1030.18
3434.67	826.247
3437.78	714.155
3440.89	632.712
3444	597.761
3447.12	558.996
3450.22	584.867
3453.33	573.548
3456.44	547.78
3459.54	529.614
3462.65	497.173
3465.75	509.307
3468.85	538.12
3471.95	537.849
3475.05	552.831
3478.15	565.014
3481.24	574.365
3484.34	603.604
3487.43	714.096
3490.53	810.777
3493.62	908.402
3496.71	1120.87
3499.79	1239.06
3502.88	1165.43
3505.97	1021.33
3509.05	890.009
3512.14	703.22
3515.22	607.133
3518.3	543.384
3521.38	482.609
3524.46	433.586
3527.54	394.247
3530.61	403.831
3533.69	363.756
3536.76	348.048
3539.83	340.573
3542.9	341.137
3545.97	306.672
3549.04	332.514
3552.11	293.885
3555.18	316.859
3558.24	319.133
3561.3	299.401
3564.37	269.147
3567.43	239.857
3570.49	259.705
3573.55	215.913
3576.61	255.539
3579.66	263.794
3582.72	251.097
3585.77	249.754
3588.82	224.622
3591.87	226.943
3594.92	199.82
3597.97	230.476
3601.02	187.188
3604.07	220.519
3607.11	221.631
3610.16	204.746
3613.2	181.226
3616.24	198.344
3619.28	189.057
3622.32	167.545
3625.36	166.836
3628.39	151.035
3631.43	147.434
3634.46	166.547
3637.5	170.723
3640.53	157.103
3643.56	130.499
3646.59	147.998
3649.62	136.421
3652.64	120.282
3655.67	109.818
3658.69	130.817
3661.72	121.603
3664.74	116.775
3667.76	120.456
3670.78	92.1411
3673.79	99.694
3676.81	99.7441
3679.83	83.7072
3682.84	91.2798
3685.86	96.0381
3688.87	93.2467
3691.88	83.8402
3694.89	69.5638
3697.9	87.5916
3700.91	86.7004
3703.91	93.4029
3706.92	52.5338
3709.92	45.7904
3712.92	53.2228
3715.92	87.3226
3718.92	74.7543
3721.92	82.1072
3724.92	77.9724
3727.92	53.787
3730.91	60.0139
3733.91	49.0268
3736.9	61.7833
3739.89	78.2628
3742.88	60.4214
3745.87	50.1393
3748.86	81.6211
3751.85	65.5594
3754.83	73.2557
3757.82	53.4321
3760.8	81.9183
3763.78	79.1048
3766.76	80.121
3769.74	78.358
3772.72	65.3046
3775.7	57.9726
3778.67	37.464
3781.65	57.5923
3784.62	41.8608
3787.6	53.5422
3790.57	54.9266
3793.54	67.7032
3796.51	46.5365
3799.47	77.3671
3802.44	51.5981
3805.41	61.7307
3808.37	60.5665
3811.33	47.1324
3814.3	71.533
3817.26	72.325
3820.22	46.6243
3823.18	49.3547
3826.13	49.2628
3829.09	73.8176
3832.04	48.1562
3835	53.8398
3837.95	67.1429
3840.9	56.683
3843.85	53.829
3846.8	45.2773
3849.75	39.6069
3852.69	68.292
3855.64	65.5222
3858.58	49.3794
3861.53	37.0016
3864.47	54.2798
3867.41	48.5463
3870.35	38.9427
3873.29	48.497
3876.22	58.9625
3879.16	47.2811
3882.1	48.0067
3885.03	75.5912
3887.96	49.3188
3890.89	53.785
3893.82	43.7601
3896.75	41.3474
3899.68	52.383
3902.61	40.2538
3905.53	52.2206
3908.46	48.7776
3911.38	41.4389
3914.3	52.2813
3917.23	54.5902
3920.15	13.6223
3923.06	32.1012
3925.98	12.1467
3928.9	49.6593
3931.81	28.813
3934.73	37.7907
3937.64	37.3331
3940.55	60.7791
3943.46	34.4469
3946.37	34.9814
3949.28	48.9743
3952.19	34.2654
3955.09	29.1833
3958	46.1703
3960.9	32.5256
3963.8	17.9466
3966.71	10.1025
3969.61	29.1489
3972.51	18.4449
3975.4	24.0327
3978.3	51.6834
3981.2	24.5507
3984.09	34.8719
3986.99	19.2313
3989.88	41.9637
3992.77	23.4348
3995.66	50.1343
3998.55	23.9305
4001.43	46.8328
4004.32	29.3216
4007.21	34.9438
4010.09	52.1341
4012.98	26.903
4015.86	17.0942
4018.74	6.3111
4021.62	34.1492
4024.5	36.9063
4027.37	31.9366
4030.25	18.2791
4033.13	33.6348
4036	16.126
4038.87	20.8824
4041.75	18.772
4044.62	30.2206
4047.49	12.633
4050.35	32.8863
4053.22	29.9167
4056.09	2.68756
4058.95	47.2876
4061.82	43.3328
4064.68	28.6807
4067.54	21.7921
4070.4	34.36
4073.26	29.4066
4076.12	38.0794
4078.98	15.5717
4081.83	23.2753
4084.69	29.0238
4087.54	11.3412
4090.4	19.0554
4093.25	10.1718
4096.1	30.5827
4098.95	10.9538
4101.8	32.3587
4104.64	14.6082
4107.49	18.3461
4110.33	19.1301
4113.18	7.12421
4116.02	22.4623
4118.86	35.8106
4121.7	21.8124
4124.54	11.7701
4127.38	25.3009
4130.22	33.0935
4133.05	24.3554
4135.89	1.59698
4138.72	31.1017
4141.56	5.99374
4144.39	0.985016
4147.22	29.3006
4150.05	16.457
4152.88	25.9576
4155.7	24.4746
4158.53	25.9403
4161.36	19.7509
4164.18	6.72119
4167	23.0457
4169.82	15.932
4172.65	20.5773
4175.46	39.8992
4178.28	-0.407227
4181.1	16.0448
4183.92	30.568
4186.73	16.7478
4189.55	38.2067
4192.36	38.2185
4195.17	34.3791
4197.98	39.3836
4200.79	53.2185
4203.6	35.6697
4206.41	32.8234
4209.21	56.5035
4212.02	35.9555
4214.83	20.4808
4217.63	24.819
4220.43	16.2678
4223.23	28.3776
4226.03	30.6497
4228.83	18.1555
4231.63	43.2979
4234.42	34.8449
4237.22	36.314
4240.01	16.9243
4242.81	14.4287
4245.6	24.881
4248.39	27.3293
4251.18	42.7444
4253.97	25.1519
4256.76	8.49353
4259.55	13.8705
4262.33	-7.81952
4265.12	1.61911
4267.9	19.1419
4270.68	19.5649
4273.47	23.9581
4276.25	13.1263
4279.03	22.4366
4281.8	30.7076
4284.58	19.7068
4287.36	13.6971
4290.13	22.8371
4292.91	25.942
4295.68	26.0699
4298.45	33.2825
4301.22	29.3127
4303.99	40.5685
4306.76	32.5497
4309.53	16.4319
4312.3	37.8975
4315.06	38.9641
4317.83	36.9432
4320.59	40.9909
4323.35	17.5158
4326.11	10.3286
4328.87	13.3048
4331.63	21.3664
4334.39	9.04282
4337.15	24.2582
4339.9	35.4544
4342.66	13.0305
4345.41	10.0229
4348.17	31.5256
4350.92	33.7236
4353.67	8.36108
4356.42	12.5853
4359.17	33.1759
4361.91	25.1346
4364.66	-2.38382
4367.41	33.6298
4370.15	29.6548
4372.89	14.3323
4375.63	26.6964
4378.38	13.365
4381.12	12.3688
4383.86	22.7563
4386.59	32.2854
4389.33	28.5644
4392.07	25.0723
4394.8	26.6918
4397.53	41.5641
4400.27	34.6999
4403	31.9559
4405.73	28.1923
4408.46	19.1926
4411.19	24.6752
4413.92	12.4173
4416.64	32.3352
4419.37	34.5111
4422.09	10.6649
4424.82	17.0796
4427.54	12.0035
4430.26	17.3721
4432.98	23.7757
4435.7	19.686
4438.42	49.0934
4441.13	22.9377
4443.85	24.0227
4446.57	29.2909
4449.28	16.6864
4451.99	22.9575
4454.71	23.9505
4457.42	17.5523
4460.13	22.7445
4462.83	34.2688
4465.54	22.6565
4468.25	26.8481
4470.95	19.4853
4473.66	26.9073
4476.36	16.4425
4479.07	23.9312
4481.77	28.267
4484.47	15.6689
4487.17	44.2943
4489.87	50.6486
4492.56	4.96222
4495.26	49.3701
4497.96	37.6674
4500.65	26.9323
4503.34	23.6606
4506.04	3.43402
4508.73	36.2362
4511.42	39.3484
4514.11	13.8066
4516.8	40.2936
4519.48	22.22
4522.17	17.957
4524.85	27.5014
4527.54	38.1365
4530.22	0.825256
4532.9	31.7377
4535.58	26.3991
4538.27	29.6434
4540.94	35.0059
4543.62	21.1381
4546.3	14.7378
4548.98	34.0534
4551.65	32.045
4554.33	28.9716
4557	14.2014
4559.67	43.6235
4562.34	23.5681
4565.01	10.1464
4567.68	40.9911
4570.35	14.974
4573.02	27.6232
4575.68	22.0575
4578.35	40.5012
4581.01	44.0483
4583.67	15.6375
4586.34	28.5997
4589	16.4305
4591.66	29.3207
4594.31	10.6782
4596.97	11.5694
4599.63	24.5805
4602.29	37.6515
4604.94	22.2464
4607.59	27.6644
4610.25	31.9731
4612.9	6.60382
4615.55	42.7812
4618.2	24.0182
4620.85	23.9373
4623.5	28.2317
4626.14	21.4557
4628.79	4.73077
4631.43	17.7633
4634.08	16.3808
4636.72	15.0007
4639.36	33.5133
4642	18.8833
4644.64	52.0284
4647.28	4.25989
4649.92	42.1092
4652.56	20.1046
4655.19	16.1594
4657.83	24.8524
4660.46	10.2045
4663.1	8.94073
4665.73	0.794525
4668.36	19.5516
4670.99	14.7955
4673.62	23.4776
4676.24	22.064
4678.87	19.5058
4681.5	28.1743
4684.12	36.8551
4686.75	17.4017
4689.37	4.70212
4691.99	21.2397
4694.61	19.7375
4697.23	25.0089
4699.85	23.5132
4702.47	37.7816
4705.09	14.7456
4707.7	30.1211
4710.32	14.946
4712.93	8.80518
4715.55	18.4783
4718.16	19.1031
4720.77	10.5978
4723.38	8.94467
4725.99	24.3356
4728.6	9.09637
4731.21	25.6374
4733.81	33.1011
4736.42	30.2977
4739.02	33.183
4741.63	-0.384064
4744.23	26.3371
4746.83	46.1479
4749.43	20.4571
4752.03	39.1466
4754.63	25.9461
4757.23	19.6033
4759.82	8.74185
4762.42	26.3484
4765.01	5.28796
4767.61	15.0978
4770.2	12.2506
4772.79	24.2419
4775.38	21.4084
4777.97	20.8473
4780.56	14.572
4783.15	12.8712
4785.74	5.44824
4788.32	20.9128
4790.91	28.4037
4793.49	12.9868
4796.07	2.18011
4798.66	0.55957
4801.24	13.8858
4803.82	6.58929
4806.4	9.68469
4808.98	9.31293
4811.55	6.66086
4814.13	32.8688
4816.71	17.5888
4819.28	3.42242
4821.85	22.8254
4824.43	6.32593
4827	17.6354
4829.57	12.7564
4832.14	19.5058
4834.71	12.3314
4837.28	8.6778
4839.84	-3.15662
4842.41	7.16953
4844.97	-3.62781
4847.54	23.101
4850.1	3.81754
4852.66	18.4142
4855.22	6.48846
4857.78	28.7188
4860.34	4.9144
4862.9	17.5485
4865.46	19.505
4868.01	13.3585
4870.57	11.8578
4873.12	-6.29556
4875.68	1.63733
4878.23	13.1364
4880.78	22.2571
4883.33	9.99985
4885.88	14.3918
4888.43	18.8134
4890.98	20.8527
4893.53	-6.88095
4896.07	16.6022
4898.62	1.9639
4901.16	23.0977
4903.7	1.31476
4906.25	18.8817
4908.79	10.1699
4911.33	10.9772
4913.87	14.1655
4916.41	26.9366
4918.94	19.4354
4921.48	8.36566
4924.02	9.27808
4926.55	7.80414
4929.08	1.60049
4931.62	5.05621
4934.15	2.5517
4936.68	0.0447083
4939.21	7.05258
4941.74	17.6866
4944.27	8.08093
4946.79	21.2657
4949.32	14.1147
4951.85	11.768
4954.37	10.6604
4956.9	6.01807
4959.42	19.446
4961.94	14.9456
4964.46	3.30856
4966.98	29.0118
4969.5	19.7464
4972.02	27.3959
4974.53	36.2886
4977.05	19.828
4979.57	21.5417
4982.08	0.267365
4984.59	34.8023
4987.1	29.3681
4989.62	26.3818
4992.13	30.7138
4994.64	25.3748
4997.15	27.4089
4999.65	17.2798