File: Data/3-Raman/processed/bu19(2)w-a-ff1-fi02-v_1800 (450-850nm)_532nm_edge_100%_x100_vis_lwd_h50um_30sx2_01.txt
#Acq. time (s)=	30
#Accumulations=	2
#Range (cm-¹)=	1200...2365
#Windows=	3
#Auto scanning=	Off
#Autofocus=	Off
#Macrospot=	Off
#AutoExposure=	Off
#Spike filter=	Multiple accum.
#Delay time (s)=	2
#Binning=	1
#Readout mode=	Signal
#DeNoise=	Off
#ICS correction=	On
#Dark correction=	Off
#Inst. Process=	Off
#Detector Gain=	Best Dynamic
#Detector ADC=	50 kHz HS
#Detector temperature (°C)=	-60.09
#Instrument=	LabRAM HR Evol
#Detector=	SIN-EM FIVIS
#Objective=	x100_VIS_LWD
#Grating=	1800 (450-850nm)
#ND Filter=	100%
#Laser=	532nm_Edge
#Hole=	49.98
#Temperature=	0
#Range=	Visible
#StageXY=	75x50mm Scan+
#StageZ=	Z motor
#X (µm)=	0
#Y (µm)=	0
#Z (µm)=	-9.4
#Full time(mm:ss)=	3:15
#Project=	21_11_26
#Sample=	BU19(2)w
#Site=
#Title=	BU19(2)w-A-FF1-FI02-V_1800 (450-850nm)_532nm_Edge_100%_x100_VIS_LWD_H50um_30sX2
#Remark=
#Date=	26.11.2021 11:57
#Acquired=	26.11.2021 11:57:19
#Base:Fit=	16.12.2021 16:00:56
#Base:Fit=	16.12.2021 16:04:55
#Base:Sub=	16.12.2021 16:04:56
1202.72	-0.560791
1203.84	7.44757
1204.95	0.612
1206.06	23.2794
1207.17	2.66364
1208.28	-3.31641
1209.39	16.3896
1210.5	9.81335
1211.61	-17.8577
1212.72	6.89923
1213.83	6.39203
1214.94	-13.71
1216.05	16.1821
1217.16	-16.6257
1218.27	-11.9372
1219.38	0.556702
1220.49	17.4348
1221.6	-13.3308
1222.71	-15.1522
1223.81	-0.463013
1224.92	18.9591
1226.03	-17.6777
1227.14	1.44684
1228.25	9.41901
1229.35	9.90845
1230.46	-3.44855
1231.57	1.98578
1232.67	28.545
1233.78	-15.4518
1234.89	-7.49725
1235.99	15.2427
1237.1	-6.70404
1238.2	-13.6997
1239.31	11.9061
1240.41	4.60449
1241.52	-4.42499
1242.62	6.07971
1243.73	21.3364
1244.83	3.83948
1245.94	2.38641
1247.04	1.22913
1248.14	32.7706
1249.25	19.0478
1250.35	6.82495
1251.45	-22.8123
1252.56	11.4328
1253.66	27.9136
1254.76	7.85736
1255.87	19.8311
1256.97	1.57086
1258.07	19.4922
1259.17	51.7888
1260.27	46.4485
1261.37	27.0929
1262.48	71.1104
1263.58	67.0453
1264.68	57.6758
1265.78	46.7701
1266.88	49.2609
1267.98	38.9864
1269.08	23.7566
1270.18	44.062
1271.28	40.5185
1272.38	33.6837
1273.47	22.5258
1274.57	22.6932
1275.67	30.5501
1276.77	38.9623
1277.87	22.2275
1278.97	52.8653
1280.07	79.7554
1281.16	195.907
1282.26	661.228
1283.36	1463.78
1284.45	744.46
1285.55	181.017
1286.65	96.0476
1287.75	45.5939
1288.84	59.4946
1289.94	37.3022
1291.03	52.7393
1292.13	6.75665
1293.22	11.3817
1294.32	18.1433
1295.42	14.5922
1296.51	16.8419
1297.61	28.8209
1298.7	26.6976
1299.79	19.3314
1300.89	-2.10126
1301.98	-3.60895
1303.08	24.5652
1304.17	39.5135
1305.26	-7.59265
1306.35	12.2361
1307.45	11.5177
1308.54	12.0795
1309.63	8.62128
1310.73	1.87671
1311.82	-13.3157
1312.91	-9.23773
1314	18.4621
1315.09	1.11639
1316.18	46.4365
1317.28	5.62982
1318.37	28.6086
1319.46	-2.50903
1320.55	-0.905273
1321.64	14.885
1322.73	-7.49835
1323.82	-25.1763
1324.91	-6.65875
1326	-20.3619
1327.09	-5.38348
1328.18	-5.50513
1329.27	2.38977
1330.35	-10.8752
1331.44	-32.0914
1332.53	18.8787
1333.62	-16.3831
1334.71	-14.6448
1335.79	0.976257
1336.88	-26.2341
1337.97	-19.6946
1339.06	1.18109
1340.14	-4.55084
1341.23	28.5671
1342.32	0.557068
1343.4	18.1862
1344.49	7.19556
1345.58	9.47693
1346.66	-0.521484
1347.75	9.48285
1348.83	11.7695
1349.92	-1.78223
1351	5.44702
1352.09	10.6183
1353.17	20.0972
1354.25	19.5083
1355.34	28.4915
1356.42	7.198
1357.51	-0.910522
1358.59	8.51544
1359.67	-4.94611
1360.76	-0.983948
1361.84	-9.94305
1362.92	21.4382
1364	42.048
1365.09	67.4985
1366.17	26.9904
1367.25	30.8089
1368.33	33.4902
1369.41	85.0474
1370.5	33.7615
1371.58	48.1213
1372.66	19.6169
1373.74	18.6433
1374.82	24.1771
1375.9	37.1769
1376.98	34.3412
1378.06	61.4544
1379.14	49.1891
1380.22	58.6741
1381.3	63.6218
1382.38	100.312
1383.46	114.993
1384.54	165.355
1385.61	402.013
1386.69	1661.9
1387.77	2595.27
1388.85	450.527
1389.93	164.334
1391	92.7297
1392.08	92.6584
1393.16	68.0428
1394.23	52.0188
1395.31	28.1155
1396.39	43.436
1397.46	40.6153
1398.54	40.1126
1399.62	23.8159
1400.69	18.7032
1401.77	30.0793
1402.84	67.0472
1403.92	39.908
1404.99	38.9811
1406.07	46.3057
1407.14	41.654
1408.22	107.249
1409.29	153.404
1410.37	87.7073
1411.44	40.3533
1412.51	20.4401
1413.59	29.7963
1414.66	9.98926
1415.73	50.1611
1416.81	-10.407
1417.88	13.3608
1418.95	0.926636
1420.02	25.1097
1421.1	23.1144
1422.17	12.6492
1423.24	-7.36346
1424.31	26.4567
1425.38	20.0878
1426.45	6.74921
1427.52	23.0547
1428.59	-3.63721
1429.67	11.7318
1430.74	-11.3199
1431.81	1.85815
1432.87	18.5741
1433.95	21.11
1435.01	-6.48322
1436.08	13.7696
1437.15	-15.4183
1438.22	-15.8749
1439.29	15.9481
1440.36	0.994446
1441.43	21.5175
1442.49	24.2689
1443.56	15.7888
1444.63	28.7097
1445.7	-0.557434
1446.77	-1.06482
1447.83	6.59186
1448.9	-22.0746
1449.97	0.134216
1451.03	1.5451
1452.1	13.3141
1453.17	6.91052
1454.23	-4.43549
1455.3	-8.81128
1456.36	-8.82135
1457.43	14.1777
1458.49	10.7448
1459.56	-4.68079
1460.62	-30.6274
1461.69	24.0826
1462.75	19.1584
1463.82	9.96997
1464.88	12.7922
1465.94	-7.37561
1467.01	-5.81995
1468.07	7.08813
1469.13	9.82001
1470.2	-0.133728
1471.26	17.5474
1472.32	1.58313
1473.39	-4.87878
1474.45	-12.6319
1475.51	31.0776
1476.57	15.2905
1477.63	-9.76282
1478.69	0.893616
1479.76	10.2748
1480.82	11.144
1481.88	-31.9979
1482.94	-14.3397
1484	-5.23895
1485.06	4.90955
1486.12	-13.7914
1487.18	-4.77594
1488.24	-4.41711
1489.3	-0.274048
1490.36	12.4332
1491.42	-5.43652
1492.48	-11.7943
1493.53	8.11426
1494.59	17.993
1495.65	5.2934
1496.71	-11.9263
1497.77	4.78265
1498.82	19.6711
1499.88	12.6089
1500.94	12.4753
1502	23.0156
1503.05	0.272949
1504.11	-8.44305
1505.17	3.54144
1506.22	7.57605
1507.28	13.493
1508.34	7.24573
1509.39	-23.1771
1510.45	21.0935
1511.5	13.0216
1512.56	4.02618
1513.61	-4.19629
1514.67	20.2668
1515.72	-2.81067
1516.78	-29.9029
1517.83	1.83582
1518.88	9.98724
1519.94	30.0889
1520.99	-0.335144
1522.05	13.6628
1523.1	-17.024
1524.15	2.81372
1525.2	-2.79205
1526.26	-5.64185
1527.31	9.64661
1528.36	22.1193
1529.41	36.5911
1530.47	-11.9611
1531.52	-13.6074
1532.57	29.1229
1533.62	7.81293
1534.67	4.72546
1535.72	40.1837
1536.77	-25.4012
1537.82	-4.54968
1538.87	-1.31555
1539.92	7.79102
1540.97	12.055
1542.02	16.2743
1543.07	13.1512
1544.12	-2.10767
1545.17	39.243
1546.22	12.8746
1547.27	3.82385
1548.32	-3.87598
1549.37	0.382263
1550.42	33.4988
1551.46	26.9434
1552.51	8.66693
1553.56	47.8991
1554.61	12.8852
1555.65	3.83173
1556.7	15.5391
1557.75	20.4517
1558.79	46.5014
1559.84	-1.79999
1560.89	10.5003
1561.93	17.4242
1562.98	21.6733
1564.02	26.2557
1565.07	10.7393
1566.11	19.954
1567.16	12.5479
1568.2	-6.98499
1569.25	-2.01953
1570.29	12.2783
1571.34	3.01178
1572.38	26.323
1573.43	13.5287
1574.47	4.19983
1575.51	4.82458
1576.56	13.6943
1577.6	6.37701
1578.64	1.09149
1579.69	28.6896
1580.73	15.7466
1581.77	27.0418
1582.81	11.3214
1583.85	-10.028
1584.9	-2.27026
1585.94	34.2802
1586.98	4.44861
1588.02	5.83746
1589.06	10.8731
1590.1	30.8738
1591.14	-13.933
1592.18	7.52698
1593.22	18.354
1594.26	17.7569
1595.3	11.7047
1596.34	-17.6757
1597.38	-0.950562
1598.42	21.6822
1599.46	23.5763
1600.5	-4.0968
1601.54	17.4467
1602.58	2.39929
1603.62	19.1442
1604.66	-13.9526
1605.69	17.5124
1606.73	0.854736
1607.77	-7.74762
1608.81	12.6182
1609.84	-0.0945435
1610.88	29.0386
1611.92	9.04224
1612.95	1.7674
1613.99	22.8579
1615.03	9.78326
1616.06	0.554932
1617.1	17.0159
1618.13	3.5589
1619.17	8.87543
1620.2	20.201
1621.24	3.36359
1622.27	-3.24707
1623.31	11.8348
1624.34	6.09998
1625.38	1.3783
1626.41	15.8701
1627.45	4.34985
1628.48	10.1561
1629.51	-7.37372
1630.55	-4.52191
1631.53	9.25342
1632.57	-3.39697
1633.62	2.20856
1634.66	-2.74786
1635.71	28.4865
1636.75	-1.67639
1637.8	30.1037
1638.84	21.7325
1639.89	-28.7011
1640.93	-9.1037
1641.98	9.37024
1643.02	-1.86707
1644.06	27.2896
1645.11	20.7813
1646.15	2.11682
1647.19	-17.1333
1648.24	1.05414
1649.28	-13.166
1650.32	11.1902
1651.37	1.8999
1652.41	2.82507
1653.45	0.430725
1654.49	13.2015
1655.53	-23.1225
1656.57	-18.5319
1657.62	-0.969238
1658.66	18.2399
1659.7	-3.19458
1660.74	4.34235
1661.78	-8.08112
1662.82	-25.1221
1663.86	11.3181
1664.9	-11.196
1665.94	2.2807
1666.98	-12.6371
1668.02	-16.27
1669.06	15.2732
1670.1	21.6255
1671.14	-0.667175
1672.18	-9.9259
1673.21	10.7175
1674.25	10.721
1675.29	1.12085
1676.33	-4.81744
1677.37	-1.96887
1678.4	0.384705
1679.44	-2.35748
1680.48	10.9658
1681.52	-1.38654
1682.55	27.0457
1683.59	2.0954
1684.63	9.58716
1685.66	9.22668
1686.7	7.14758
1687.73	-0.732483
1688.77	-14.1332
1689.81	9.75024
1690.84	-10.3887
1691.88	-0.392273
1692.91	26.9528
1693.95	-0.720154
1694.98	0.421753
1696.01	13.179
1697.05	-1.53302
1698.08	7.4502
1699.12	1.75848
1700.15	-1.40222
1701.18	19.8435
1702.22	-2.40845
1703.25	11.6287
1704.28	17.134
1705.32	-12.3358
1706.35	10.8868
1707.38	-3.84204
1708.41	0.921875
1709.44	1.65845
1710.48	1.30865
1711.51	12.225
1712.54	-7.46387
1713.57	-1.08795
1714.6	-5.07172
1715.63	21.1501
1716.66	-5.39154
1717.69	-17.3544
1718.72	29.8163
1719.75	-18.3745
1720.78	-0.0577393
1721.81	-6.78015
1722.84	24.3073
1723.87	4.09326
1724.9	-10.8737
1725.93	13.0184
1726.96	-5.84833
1727.99	-5.25964
1729.02	4.51666
1730.05	12.2082
1731.07	-1.94379
1732.1	8.61774
1733.13	-4.4234
1734.16	4.93317
1735.18	-2.05652
1736.21	12.4062
1737.24	25.3588
1738.26	28.5792
1739.29	20.972
1740.32	7.04034
1741.34	-18.9817
1742.37	-3.39142
1743.4	1.98993
1744.42	-3.32568
1745.45	0.229065
1746.47	3.63538
1747.5	6.43646
1748.52	1.05402
1749.55	6.90125
1750.57	0.842041
1751.6	6.87585
1752.62	10.7502
1753.64	10.8856
1754.67	2.5083
1755.69	17.2233
1756.71	19.2257
1757.74	3.96246
1758.76	-3.42737
1759.78	30.8574
1760.81	-7.49902
1761.83	-4.31201
1762.85	1.27911
1763.87	31.7606
1764.89	18.1176
1765.92	-10.0887
1766.94	1.22992
1767.96	15.2002
1768.98	-6.14099
1770	22.647
1771.02	-7.31512
1772.04	10.4802
1773.06	18.5709
1774.08	3.70343
1775.1	33.4827
1776.12	34.3362
1777.14	25.7352
1778.16	0.38501
1779.18	2.49988
1780.2	-1.46686
1781.22	-4.99518
1782.24	2.86896
1783.26	3.44574
1784.28	1.034
1785.29	-4.10339
1786.31	14.7521
1787.33	-14.406
1788.35	15.9031
1789.37	-4.81622
1790.38	15.1335
1791.4	10.2446
1792.42	11.4935
1793.43	9.87109
1794.45	13.9099
1795.47	22.3897
1796.48	20.5325
1797.5	-11.4192
1798.51	-14.8052
1799.53	-8.12207
1800.55	-4.82281
1801.56	-4.08246
1802.58	18.2268
1803.59	2.55658
1804.61	4.91663
1805.62	8.58905
1806.64	25.7148
1807.65	1.91138
1808.66	5.87079
1809.68	-5.51807
1810.69	15.863
1811.7	-8.29767
1812.72	7.32404
1813.73	11.7039
1814.74	12.5689
1815.76	11.3754
1816.77	-11.5609
1817.78	13.1212
1818.79	23.0007
1819.8	-5.65442
1820.82	9.32587
1821.83	-23.0537
1822.84	11.2609
1823.85	22.962
1824.86	17.2767
1825.87	-15.2382
1826.88	28.4861
1827.89	7.526
1828.9	20.1849
1829.91	-1.30243
1830.92	11.0412
1831.93	14.384
1832.94	8.22308
1833.95	-4.03473
1834.96	9.06061
1835.97	1.07422
1836.98	35.4109
1837.99	-4.06885
1839	-9.83081
1840	3.07813
1841.01	-2.36206
1842.02	-0.909668
1843.03	17.7629
1844.04	-4.30524
1845.04	9.34772
1846.05	-13.434
1847.06	24.2208
1848.07	-8.50946
1849.07	9.10858
1850.08	-21.2496
1851.09	-7.72833
1852.09	7.21332
1853.1	1.53455
1854.1	22.4442
1855.11	6.32214
1856.11	13.2973
1857.12	-6.80737
1858.12	-0.281616
1859.13	25.9481
1860.13	-4.16144
1861.14	22.1724
1862.14	1.74664
1863.15	-2.49005
1864.15	16.9777
1865.15	13.6145
1866.16	6.94287
1867.16	-10.5357
1868.16	-12.3902
1869.17	6.68408
1870.17	-1.87036
1871.17	0.996948
1872.17	-17.2131
1873.18	-4.26794
1874.18	13.5848
1875.18	-0.321533
1876.18	25.1072
1877.18	8.26483
1878.18	15.7006
1879.19	6.89709
1880.19	5.85828
1881.19	-13.954
1882.19	0.120361
1883.19	-13.7531
1884.19	-20.1292
1885.19	4.98615
1886.19	-8.85126
1887.19	0.656189
1888.19	12.2775
1889.19	13.1824
1890.19	-5.94916
1891.19	2.29077
1892.18	6.99835
1893.18	19.9807
1894.18	-0.898987
1895.18	13.9273
1896.18	-13.8005
1897.18	9.50458
1898.17	-15.4771
1899.17	5.84985
1900.17	14.8521
1901.16	6.5614
1902.16	14.9348
1903.16	8.86829
1904.16	-3.48639
1905.15	-14.7166
1906.15	2.06409
1907.14	1.66168
1908.14	15.113
1909.14	14.7429
1910.13	1.61664
1911.13	3.78387
1912.12	1.40057
1913.12	18.4141
1914.11	-9.24396
1915.11	-2.57257
1916.1	7.37915
1917.1	2.4447
1918.09	-0.596069
1919.08	-3.61615
1920.08	28.9287
1921.07	4.72717
1922.06	7.5083
1923.06	13.2639
1924.05	23.5083
1925.04	16.68
1926.04	-2.38068
1927.03	-2.1803
1928.02	26.015
1929.01	19.9547
1930	4.74426
1931	24.8407
1931.99	29.7023
1932.98	3.7959
1933.97	23.123
1934.96	20.1015
1935.95	5.01288
1936.94	-16.55
1937.93	10.5511
1938.92	18.3297
1939.91	-7.65131
1940.9	1.70819
1941.89	-1.13733
1942.88	11.8366
1943.87	18.229
1944.86	-2.91608
1945.85	-6.68207
1946.84	12.2494
1947.83	-10.6235
1948.82	17.2076
1949.8	-13.6141
1950.79	-5.55664
1951.78	-13.6728
1952.77	1.60571
1953.76	13.436
1954.74	-4.44366
1955.73	-24.7897
1956.72	16.1301
1957.7	3.68591
1958.69	15.8471
1959.68	20.5796
1960.66	2.10468
1961.65	25.7229
1962.63	-17.2432
1963.62	8.04718
1964.61	-2.04822
1965.59	20.1411
1966.58	8.30988
1967.56	2.18066
1968.55	16.9502
1969.53	-12.1328
1970.52	-3.2392
1971.5	6.06763
1972.48	24.4848
1973.47	3.39746
1974.45	-0.762695
1975.44	-18.7121
1976.42	-1.79266
1977.4	28.2007
1978.39	-7.50818
1979.37	1.05402
1980.35	-1.55212
1981.33	-8.50659
1982.31	6.71442
1983.3	22.6762
1984.28	1.23956
1985.26	10.6115
1986.24	-4.76178
1987.22	0.495239
1988.21	1.99438
1989.19	6.02014
1990.17	12.1108
1991.15	27.2138
1992.13	4.26001
1993.11	21.0343
1994.09	4.97363
1995.07	4.0921
1996.05	-8.5766
1997.03	5.27869
1998.01	1.5907
1998.99	8.19305
1999.97	7.80768
2000.95	22.0992
2001.92	-2.87036
2002.9	16.6622
2003.88	7.90253
2004.86	1.20697
2005.84	8.57013
2006.81	24.1263
2007.79	4.53015
2008.77	10.8083
2009.75	13.9691
2010.73	13.7505
2011.7	4.98236
2012.68	14.1675
2013.67	35.1854
2014.66	22.8751
2015.64	4.98859
2016.63	-0.958923
2017.62	-27.4071
2018.61	7.52594
2019.6	32.8659
2020.58	29.9832
2021.57	10.6183
2022.56	9.74176
2023.55	18.6415
2024.54	13.5658
2025.52	13.7292
2026.51	14.2877
2027.5	-4.86273
2028.48	-11.0858
2029.47	15.6662
2030.45	-10.7204
2031.44	-7.30438
2032.43	22.038
2033.41	4.64563
2034.4	-10.8746
2035.38	12.4933
2036.37	11.6549
2037.35	-4.2005
2038.34	2.39728
2039.32	21.8039
2040.31	23.2633
2041.29	-8.95764
2042.27	7.74048
2043.26	1.1626
2044.24	24.7288
2045.23	-6.23688
2046.21	11.4969
2047.19	19.4384
2048.17	4.71899
2049.16	-6.93329
2050.14	-1.13788
2051.12	-3.08362
2052.11	1.41339
2053.09	15.9516
2054.07	7.72809
2055.05	25.0917
2056.03	-0.265747
2057.01	2.55988
2058	-11.0102
2058.98	10.4329
2059.96	6.39423
2060.94	3.57013
2061.92	-2.40033
2062.9	3.66486
2063.88	3.47614
2064.86	1.23389
2065.84	2.24084
2066.82	7.68134
2067.8	4.53168
2068.78	3.28107
2069.76	21.1942
2070.73	6.35193
2071.71	20.2856
2072.69	2.82635
2073.67	17.0786
2074.65	-1.29614
2075.63	-4.79395
2076.6	14.2439
2077.58	-0.976563
2078.56	20.802
2079.54	9.23669
2080.51	-18.0653
2081.49	27.5306
2082.47	-3.38519
2083.45	-20.9715
2084.42	-3.74744
2085.4	15.4517
2086.37	8.41003
2087.35	15.8955
2088.32	28.6883
2089.3	-35.2751
2090.28	-12.7244
2091.25	2.94818
2092.23	0.957031
2093.2	9.78156
2094.18	21.2437
2095.15	19.7645
2096.13	13.8894
2097.1	29.1493
2098.07	9.94366
2099.05	4.32776
2100.02	14.9224
2101	11.5459
2101.97	-8.59631
2102.94	25.8065
2103.92	0.998718
2104.89	-7.12372
2105.86	23.1207
2106.83	-0.0172729
2107.8	16.4615
2108.78	17.8647
2109.75	5.79474
2110.72	-14.6669
2111.69	6.44702
2112.66	10.2878
2113.63	6.24615
2114.61	14.2423
2115.58	10.7136
2116.55	28.6955
2117.52	3.98822
2118.49	5.87439
2119.46	18.6724
2120.43	-4.36414
2121.4	29.2656
2122.37	-11.4925
2123.34	19.6024
2124.31	-1.99927
2125.28	-4.58667
2126.25	10.7596
2127.21	-20.8509
2128.18	-1.01025
2129.15	-4.62585
2130.12	-2.62286
2131.09	-17.6632
2132.06	4.87286
2133.02	-23.5948
2133.99	17.2523
2134.96	2.49005
2135.93	9.23114
2136.89	5.9978
2137.86	-41.6345
2138.83	14.0204
2139.79	4.12958
2140.76	6.62933
2141.73	2.9707
2142.69	-23.47
2143.66	-10.3663
2144.62	-6.80859
2145.59	-4.58685
2146.55	4.98492
2147.52	-10.9858
2148.48	30.2963
2149.45	7.60651
2150.42	-15.4557
2151.38	-1.25989
2152.34	-24.0283
2153.31	4.17224
2154.27	-1.51843
2155.24	-16.2816
2156.2	4.5694
2157.16	6.48254
2158.13	28.5949
2159.09	18.7512
2160.05	-10.3241
2161.01	8.93127
2161.98	-9.66858
2162.94	26.068
2163.9	-7.50671
2164.86	-13.2856
2165.83	0.0821533
2166.79	11.4453
2167.75	-8.3194
2168.71	7.73956
2169.67	14.861
2170.63	11.4723
2171.59	5.09381
2172.56	9.77942
2173.51	-14.2995
2174.48	-7.25006
2175.44	-7.81146
2176.4	-3.90717
2177.36	-13.998
2178.32	-1.52948
2179.28	-1.61139
2180.23	8.0733
2181.19	19.4446
2182.15	-1.78894
2183.11	5.71704
2184.07	-6.65442
2185.03	18.4927
2185.99	-17.016
2186.95	16.3929
2187.9	-2.85272
2188.86	-10.2168
2189.82	-10.6089
2190.78	-1.2771
2191.73	-1.66852
2192.69	-21.4528
2193.65	-3.02405
2194.6	7.70361
2195.56	3.3634
2196.52	18.7968
2197.47	-8.41309
2198.43	-11.7465
2199.38	6.16248
2200.34	-8.21619
2201.3	-4.74701
2202.25	-3.94208
2203.21	0.47345
2204.16	-7.74219
2205.12	2.53741
2206.07	-1.58423
2207.03	11.7646
2207.98	5.16266
2208.93	-5.95123
2209.89	-14.6374
2210.84	-2.86017
2211.8	12.9208
2212.75	14.7397
2213.7	2.71429
2214.66	-7.72101
2215.61	-2.18481
2216.56	-8.26471
2217.51	15.406
2218.47	12.1362
2219.42	7.28192
2220.37	-1.26984
2221.32	-15.9495
2222.27	6.23688
2223.23	1.09961
2224.18	4.9306
2225.13	16.4063
2226.08	6.30212
2227.03	18.546
2227.98	-5.95172
2228.93	-9.44495
2229.88	27.5927
2230.83	30.5466
2231.78	10.9731
2232.73	-2.12939
2233.68	-12.4667
2234.63	-0.468567
2235.58	1.32867
2236.53	-19.9623
2237.48	-21.1424
2238.43	-2.79144
2239.38	2.26794
2240.33	17.4894
2241.27	9.76074
2242.22	-10.366
2243.17	-5.91046
2244.12	-0.0839844
2245.07	-1.21307
2246.01	5.74597
2246.96	7.6214
2247.91	14.0652
2248.85	-14.9603
2249.8	8.21277
2250.75	4.72827
2251.69	13.1415
2252.64	-17.4433
2253.59	26.6072
2254.53	26.7702
2255.48	1.69592
2256.42	-0.520142
2257.37	8.95386
2258.32	24.9404
2259.26	-3.80707
2260.2	18.8113
2261.15	-15.5956
2262.1	7.17285
2263.04	-0.578308
2263.98	11.1517
2264.93	5.91638
2265.87	-6.54425
2266.81	-7.38513
2267.76	11.6121
2268.7	-3.62134
2269.65	6.81677
2270.59	-0.459717
2271.53	-1.42682
2272.47	-5.37207
2273.42	7.6416
2274.36	-15.6862
2275.3	-22.743
2276.24	-1.06842
2277.18	11.5076
2278.13	11.9217
2279.07	11.8753
2280.01	9.89404
2280.95	-17.1943
2281.89	14.5696
2282.83	7.71222
2283.77	-1.60754
2284.71	5.72034
2285.65	3.72766
2286.59	18.191
2287.54	-8.51733
2288.47	23.0651
2289.41	21.9919
2290.35	4.23224
2291.29	20.1067
2292.23	-23.9886
2293.17	22.27
2294.11	10.5288
2295.05	3.85223
2295.99	21.2366
2296.93	-1.98877
2297.86	-3.0473
2298.8	-8.69312
2299.74	0.0267334
2300.68	-12.0367
2301.61	15.7726
2302.55	1.70593
2303.49	-1.80786
2304.43	10.3896
2305.36	-10.9833
2306.3	21.5822
2307.24	-5.90039
2308.17	-4.72583
2309.11	8.16956
2310.04	-12.0782
2310.98	-1.77588
2311.92	-0.464905
2312.85	20.5608
2313.79	7.65619
2314.72	2.18097
2315.66	-3.75507
2316.59	5.47614
2317.52	-3.06836
2318.46	23.5297
2319.39	-17.9957
2320.33	-7.18451
2321.26	-7.56396
2322.2	11.765
2323.13	-7.70044
2324.06	20.9113
2325	-8.85828
2325.93	16.8961
2326.86	48.5668
2327.79	166.971
2328.73	86.2197
2329.66	29.3094
2330.59	21.9476
2331.52	2.02313
2332.46	-11.8439
2333.39	-3.18335
2334.32	0.750854
2335.25	23.773
2336.18	3.02106
2337.11	11.9046
2338.04	3.50055
2338.97	3.76398
2339.91	21.475
2340.84	-12.1282
2341.77	11.4719
2342.7	-7.84235
2343.63	18.3124
2344.56	14.8657
2345.49	-6.89886
2346.41	-2.23767
2347.34	4.68091
2348.27	-17.9167
2349.2	18.929
2350.13	-7.52167
2351.06	-18.7604
2351.99	12.8397
2352.91	19.8558
2353.84	-7.40027
2354.77	-18.4174
2355.7	4.87781
2356.63	19.0912
2357.55	-14.6194
2358.48	20.5875
2359.41	-28.7243
2360.33	-0.193787
2361.26	5.29437
2362.19	8.82983
2363.11	28.4743
2364.04	-2.72363
2364.97	-4.5694