File: Data/3-Raman/processed/bu19w-b-ff1-fi05-v_150 (500nm)_532nm_edge_100%_x100_vis_h50um_15sx2_01.txt
#Acq. time (s)=	15
#Accumulations=	2
#Range (cm-¹)=	100...5000
#Windows=	1
#Auto scanning=	Off
#Autofocus=	Off
#Macrospot=	Off
#AutoExposure=	Off
#Spike filter=	Multiple accum.
#Delay time (s)=	2
#Binning=	1
#Readout mode=	Signal
#DeNoise=	Off
#ICS correction=	On
#Dark correction=	Off
#Inst. Process=	Off
#Detector Gain=	Best Dynamic
#Detector ADC=	50 kHz HS
#Detector temperature (°C)=	-60.09
#Instrument=	LabRAM HR Evol
#Detector=	SIN-EM FIVIS
#Objective=	x100_VIS
#Grating=	150 (500nm)
#ND Filter=	100%
#Laser=	532nm_Edge
#Hole=	49.98
#Temperature=	0
#Range=	Visible
#StageXY=	75x50mm Scan+
#StageZ=	Z motor
#X (µm)=	0
#Y (µm)=	0
#Z (µm)=	-136.7
#Full time(s)=	34
#Project=	21_05_14
#Sample=	BU19w
#Site=
#Title=	BU19w-FF1-FI05-V_150 (500nm)_532nm_Edge_100%_x100_VIS_H50um_15sX2
#Remark=
#Date=	14.05.2021 14:29
#Acquired=	14.05.2021 14:29:10
#Base:Fit=	22.12.2021 12:22:35
#Base:Edit=	22.12.2021 12:25:09
#Base:Edit=	22.12.2021 12:25:10
#Base:Edit=	22.12.2021 12:25:10
#Base:Edit=	22.12.2021 12:25:11
#Base:Edit=	22.12.2021 12:25:12
#Base:Edit=	22.12.2021 12:25:13
#Base:Sub=	22.12.2021 12:25:14
#Data Range:Extract=	22.12.2021 12:27:19
102.699	3089.6
107.322	2489.01
111.942	1861.33
116.56	1295.8
121.173	945.513
125.787	641.069
130.398	480.705
135.006	250.497
139.613	184.883
144.215	1.24243
148.817	-66.8274
153.417	4.19189
158.014	673.397
162.607	2190.63
167.2	1571.59
171.79	411.566
176.379	204.292
180.963	771.558
185.547	4220.77
190.128	9156.4
194.705	6008.84
199.282	1491.25
203.857	315.355
208.43	-0.4104
212.998	-12.7035
217.566	103.569
222.132	27.9512
226.693	-1.40552
231.254	257.545
235.813	444.499
240.368	606.457
244.923	1128.18
249.475	1570.91
254.023	1455.81
258.571	1174.59
263.117	788.787
267.658	809.38
272.199	1661.3
276.738	4197.02
281.273	7203.4
285.807	5595.44
290.34	2762.87
294.868	1788.64
299.396	2330.14
303.919	4139.49
308.443	4063.47
312.964	2197.5
317.481	1300.76
321.998	1088.22
326.51	1528.29
331.023	2265.49
335.533	2029.25
340.039	1196.37
344.544	894.572
349.046	1086.85
353.547	1236.35
358.045	809.106
362.542	630.883
367.036	547.39
371.527	623.523
376.017	648.71
380.503	679.466
384.99	1103.58
389.471	1640.88
393.953	1750.09
398.43	1774.57
402.908	1483.62
407.381	1049.53
411.854	991.822
416.323	1319.11
420.791	1453.64
425.256	1006.33
429.72	546.759
434.18	438.546
438.64	458.783
443.095	478.882
447.551	699.087
452.003	1378.04
456.454	2880.13
460.901	2988.88
465.348	1593.22
469.791	783.831
474.231	609.799
478.672	533.169
483.108	652.998
487.544	781.651
491.976	1013.99
496.408	1105.94
500.836	1123.49
505.261	969.356
509.687	870.233
514.108	722.705
518.529	650.275
522.946	621.46
527.361	627.27
531.776	643.969
536.187	675.749
540.595	796.659
545.003	828.252
549.408	775.135
553.812	796.435
558.212	777.593
562.61	873.138
567.007	807.582
571.401	665.689
575.792	538.857
580.184	591.04
584.571	1066.29
588.956	2150.85
593.341	2857.57
597.722	1823.83
602.101	1091.7
606.48	1087.63
610.854	1483.63
615.227	1906.76
619.597	1523.32
623.967	844.52
628.334	496.184
632.698	388.084
637.06	495.875
641.422	599.203
645.779	595.13
650.135	497.78
654.491	423.982
658.842	430.152
663.192	469.388
667.539	648.341
671.884	663.022
676.23	779.762
680.571	871.81
684.91	820.727
689.247	480.125
693.583	343.963
697.916	227.124
702.247	161.594
706.576	124.18
710.902	114.673
715.229	114.211
719.551	62.1505
723.872	90.7583
728.19	66.6522
732.506	83.3474
736.82	125.219
741.134	123.601
745.444	144.343
749.752	208.878
754.058	247.641
758.362	337.613
762.664	429.064
766.964	697.307
771.264	1246.56
775.559	2096.15
779.853	3084.36
784.144	3096.45
788.434	2011.06
792.722	1123.22
797.007	656.953
801.29	403.62
805.572	254.952
809.851	180.364
814.13	170.045
818.406	118.934
822.679	82.6575
826.95	114.916
831.219	29.4591
835.486	5.5918
839.752	4.78223
844.015	6.97375
848.276	-30.677
852.535	29.7297
856.792	-6.84375
861.047	-35.8063
865.3	9.52063
869.551	-17.0182
873.8	-64.7971
878.047	-17.3854
882.292	-50.6127
886.534	-73.5396
890.775	-34.8676
895.014	-62.0028
899.251	-44.2737
903.486	-29.9366
907.719	-76.5764
911.95	-42.7894
916.179	-63.4565
920.406	-44.0564
924.63	-20.7258
928.853	-32.3612
933.074	-39.3976
937.293	-15.9268
941.51	126.035
945.723	136.886
949.936	244.318
954.147	318.713
958.356	337.944
962.563	373.384
966.768	510.83
970.971	675.203
975.172	557.69
979.371	274.687
983.568	173.159
987.761	92.5686
991.954	80.0406
996.145	31.0381
1000.33	0.568115
1004.52	-14.8276
1008.71	44.6759
1012.89	-8.1311
1017.07	70.0831
1021.25	104.683
1025.43	88.0533
1029.6	156.966
1033.77	238.732
1037.95	386.419
1042.11	579.773
1046.28	1071.31
1050.45	2123.81
1054.61	3462.72
1058.77	3552.22
1062.93	2321.87
1067.09	1418.7
1071.24	930.368
1075.4	800.357
1079.55	944.189
1083.7	1405.14
1087.85	2295.21
1091.99	3195.23
1096.14	3231.62
1100.28	2527.97
1104.42	2058.78
1108.55	2330.38
1112.69	2803.1
1116.82	2742.62
1120.96	2395.44
1125.09	2157.69
1129.21	2341.28
1133.34	2639.39
1137.46	2656.62
1141.59	1978.49
1145.71	1396.37
1149.83	1192.23
1153.94	1398.63
1158.06	1916.53
1162.17	2238.93
1166.28	1828.91
1170.39	1132.08
1174.5	804.358
1178.6	534.723
1182.7	336.497
1186.8	310.525
1190.9	350.55
1195	338.541
1199.1	313.544
1203.19	341.236
1207.28	285.672
1211.37	250.826
1215.46	236.406
1219.54	204.429
1223.63	474.835
1227.71	602.966
1231.79	501.714
1235.87	593.816
1239.95	932.419
1244.02	1181.2
1248.09	1023.93
1252.16	949.291
1256.23	866.158
1260.3	508.401
1264.36	423.749
1268.43	751.364
1272.49	4844.43
1276.55	5512.05
1280.6	1206.69
1284.66	361.361
1288.71	285.88
1292.76	167.465
1296.81	209.068
1300.86	147.504
1304.91	212.532
1308.95	148.652
1312.99	114.24
1317.03	69.0337
1321.07	119.26
1325.11	88.7358
1329.14	185.29
1333.18	150.304
1337.21	115.937
1341.24	84.4255
1345.26	148.637
1349.29	177.829
1353.31	221.901
1357.33	292.611
1361.35	368.951
1365.37	349.873
1369.39	498.985
1373.4	1709.77
1377.41	10308.3
1381.43	6791.04
1385.43	1134.87
1389.44	454.818
1393.45	401.979
1397.45	761.326
1401.45	868.093
1405.45	333.711
1409.45	148.161
1413.44	114.517
1417.44	107.436
1421.43	45.9106
1425.42	44.8396
1429.41	26.248
1433.39	22.0793
1437.38	14.6006
1441.36	26.9465
1445.34	-4.59692
1449.32	-6.58521
1453.3	-65.2346
1457.27	-8.68188
1461.24	-38.5095
1465.22	-41.1997
1469.19	-9.26929
1473.15	-69.585
1477.12	-26.3232
1481.09	-69.4424
1485.05	-51.9956
1489.01	-26.7896
1492.97	-62.8928
1496.93	-49.1726
1500.88	-74.0261
1504.83	-41.0029
1508.79	-58.0981
1512.74	-61.5742
1516.68	-133.719
1520.63	-48.4639
1524.57	-35.8687
1528.52	-38.5564
1532.46	-16.8235
1536.4	-83.2856
1540.33	-41.1306
1544.27	-17.4114
1548.2	-51.8076
1552.14	-16.5879
1556.07	26.0029
1559.99	-37.2192
1563.92	-23.2126
1567.84	-48.0837
1571.77	-19.8857
1575.69	-36.1716
1579.61	-17.8066
1583.52	-46.7937
1587.44	-0.769287
1591.35	0.902588
1595.27	-0.342285
1599.18	-22.6086
1603.09	-16.7246
1606.99	-9.67236
1610.9	-61.0515
1614.8	-38.3354
1618.7	-32.7849
1622.6	7.24951
1626.5	5.58521
1630.39	-22.4163
1634.29	-32.811
1638.18	-4.84082
1642.07	-14.4666
1645.96	-27.6794
1649.85	34.061
1653.73	10.3936
1657.62	17.2451
1661.5	20.0183
1665.38	35.8462
1669.26	-26.6365
1673.13	-10.7815
1677.01	25.6191
1680.88	37.8464
1684.75	-15.405
1688.62	-5.64185
1692.49	13.2314
1696.35	47.9712
1700.22	-3.72925
1704.08	-13.8433
1707.94	15.5166
1711.8	-7.62549
1715.66	48.9448
1719.51	19.3945
1723.37	29.4604
1727.22	22.2195
1731.07	34.6233
1734.92	56.3403
1738.76	53.3059
1742.61	19.4841
1746.45	23.8652
1750.29	30.3779
1754.13	65.6953
1757.97	20.2888
1761.81	8.40869
1765.64	48.5176
1769.47	-20.4604
1773.31	13.2227
1777.14	35.2437
1780.96	36.5278
1784.79	-19.8752
1788.61	31.3618
1792.43	53.77
1796.25	16.0974
1800.07	12.22
1803.89	39.4602
1807.71	60.0713
1811.52	42.593
1815.33	27.1563
1819.14	28.7983
1822.95	79.9807
1826.76	7.03149
1830.56	42.8467
1834.37	47.9897
1838.17	120.49
1841.97	75.8225
1845.77	43.3762
1849.56	68.6724
1853.36	65.8049
1857.15	110.844
1860.94	70.4297
1864.73	71.1365
1868.52	53.5701
1872.31	103.078
1876.09	77.9065
1879.87	103.248
1883.66	109.721
1887.43	100.283
1891.21	88.5566
1894.99	39.8528
1898.76	83.8003
1902.53	91.719
1906.31	50.1995
1910.08	125.38
1913.84	74.7976
1917.61	70.3049
1921.37	78.6904
1925.14	36.3621
1928.9	66.6741
1932.66	58.0427
1936.41	70.7461
1940.17	73.1482
1943.92	73.238
1947.68	84.3523
1951.43	59.8274
1955.18	56.697
1958.92	84.2698
1962.67	62.7878
1966.41	96.4336
1970.16	95.9529
1973.9	83.7566
1977.64	58.9138
1981.37	82.3918
1985.11	119.359
1988.84	146.697
1992.57	66.3335
1996.31	118.648
2000.03	129.643
2003.76	99.3359
2007.49	94.998
2011.21	59.272
2014.93	113.404
2018.65	91.0825
2022.37	112.955
2026.09	75.7021
2029.81	73.7134
2033.52	52.0999
2037.23	87.4709
2040.94	75.3838
2044.65	62.0154
2048.36	18.042
2052.07	84.2883
2055.77	56.6233
2059.47	70.3569
2063.17	81.292
2066.87	90.7092
2070.57	86.4072
2074.27	118.19
2077.96	103.157
2081.65	104.683
2085.34	79.627
2089.03	74.5051
2092.72	103.175
2096.41	110.995
2100.09	98.0212
2103.77	94.8772
2107.46	94.0781
2111.14	146.981
2114.81	132.86
2118.49	113.336
2122.16	94.7197
2125.84	89.853
2129.51	107.679
2133.18	107.83
2136.85	93.7842
2140.51	77.4629
2144.18	86.7202
2147.84	90.3638
2151.5	124.291
2155.16	127.107
2158.82	77.0449
2162.48	96.9609
2166.13	105.358
2169.79	127.23
2173.44	118.248
2177.09	110.376
2180.74	84.5537
2184.38	79.6934
2188.03	107.862
2191.67	119.65
2195.32	89.5901
2198.96	128.999
2202.6	95.8601
2206.23	113.339
2209.87	119.377
2213.5	127.51
2217.14	114.611
2220.77	133.958
2224.4	131.293
2228.03	42.6931
2231.65	101.856
2235.28	110.404
2238.9	142.001
2242.52	102.214
2246.14	96.6621
2249.76	164.929
2253.38	129.243
2256.99	173.878
2260.6	94.8777
2264.21	74.6023
2267.82	66.1167
2271.44	126.293
2275.04	56.4951
2278.65	76.1177
2282.25	90.7473
2285.85	89.8872
2289.45	80.0601
2293.05	103.248
2296.65	127.59
2300.25	75.9873
2303.84	119.459
2307.43	92.3845
2311.02	75.3906
2314.62	153.702
2318.2	403.91
2321.79	747.324
2325.38	206.311
2328.96	130.472
2332.54	135.423
2336.12	108.071
2339.7	77.6335
2343.28	93.9785
2346.85	112.791
2350.43	94.9373
2354	132.088
2357.57	123.267
2361.14	97.6323
2364.71	100.965
2368.27	94.5281
2371.84	91.1902
2375.4	124.532
2378.96	124.91
2382.52	112.699
2386.08	93.511
2389.64	62.9641
2393.19	100.996
2396.75	85.7749
2400.3	30.481
2403.85	50.3792
2407.4	31.3403
2410.95	90.4294
2414.49	74.7644
2418.04	74.3579
2421.58	68.884
2425.12	76.0837
2428.66	69.095
2432.2	59.8306
2435.74	84.375
2439.27	67.3435
2442.81	50.377
2446.34	32.6792
2449.87	48.2756
2453.4	43.5144
2456.93	59.0669
2460.45	-17.9187
2463.98	70.0259
2467.5	87.9583
2471.02	89.3359
2474.54	51.4736
2478.06	40.0725
2481.58	48.9458
2485.09	58.2537
2488.61	75.9648
2492.12	82.6792
2495.63	57.7615
2499.14	81.0681
2502.65	80.8875
2506.15	85.9604
2509.66	71.2466
2513.16	57.1262
2516.66	48.2473
2520.16	59.4944
2523.66	63.7607
2527.16	66.5142
2530.66	52.9893
2534.15	98.3823
2537.64	101.824
2541.13	64.853
2544.62	116.948
2548.11	97.2996
2551.6	15.1211
2555.08	12.0281
2558.57	73.876
2562.05	36.5784
2565.53	60.5564
2569.01	18.1616
2572.49	72.5071
2575.96	25.3577
2579.44	28.0942
2582.91	30.0117
2586.38	27.8135
2589.85	63.2285
2593.32	40.7502
2596.79	56.1177
2600.25	106.215
2603.72	70.999
2607.18	82.7234
2610.64	29.3103
2614.1	33.6421
2617.56	33.2192
2621.02	106.281
2624.47	42.1484
2627.92	68.8706
2631.38	86.3965
2634.83	50.3108
2638.28	81.8533
2641.72	61.9871
2645.17	55.4487
2648.61	72.2637
2652.06	52.1819
2655.5	59.0974
2658.94	77.0681
2662.38	105.964
2665.82	70.5874
2669.25	63.3018
2672.69	109.957
2676.12	27.4695
2679.55	48.7058
2682.98	9.82446
2686.41	89.1772
2689.84	67.5383
2693.26	55.4277
2696.69	31.7573
2700.11	15.98
2703.53	55.3958
2706.95	29.8838
2710.37	65.5295
2713.79	57.0486
2717.2	25.8101
2720.62	62.0801
2724.03	60.3494
2727.44	-30.8262
2730.85	27.363
2734.26	8.84888
2737.66	44.7244
2741.07	20.147
2744.47	-4.99585
2747.87	34.7322
2751.28	49.0686
2754.67	78.8784
2758.07	58.2354
2761.47	19.8613
2764.86	35.7788
2768.26	16.2961
2771.65	76.7764
2775.04	9.62744
2778.43	18.3984
2781.82	29.7585
2785.2	90.854
2788.59	57.843
2791.97	59.4082
2795.35	50.915
2798.73	65.3132
2802.11	38.4644
2805.49	78.1733
2808.87	75.5479
2812.24	1.75122
2815.62	50.2583
2818.99	35.5618
2822.36	42.7947
2825.73	56.7236
2829.1	23.3901
2832.46	35.3032
2835.83	32.7339
2839.19	25.0706
2842.55	2.09717
2845.91	29.2854
2849.27	37.1858
2852.63	71.6208
2855.99	19.4705
2859.34	20.989
2862.69	73.2073
2866.05	30.0093
2869.4	22.1992
2872.75	50.9602
2876.09	126.754
2879.44	-19.6328
2882.78	39.9934
2886.13	7.05347
2889.47	51.7065
2892.81	43.687
2896.15	36.2683
2899.49	23.7209
2902.82	37.2844
2906.16	26.0764
2909.49	21.2151
2912.82	21.0879
2916.16	78.2061
2919.49	14.9944
2922.81	24.5698
2926.14	15.6877
2929.46	100.216
2932.79	102.869
2936.11	55.5432
2939.43	63.9001
2942.75	84.5232
2946.07	-11.3767
2949.39	40.4121
2952.7	44.1155
2956.02	31.3333
2959.33	-1.66284
2962.64	65.6787
2965.95	13.5217
2969.26	58.998
2972.57	17.738
2975.87	78.7903
2979.17	50.1807
2982.48	14.1953
2985.78	53.5022
2989.08	72.2539
2992.38	52.6182
2995.68	20.0005
2998.97	-3.19263
3002.27	88.2266
3005.56	72.7002
3008.85	43.1726
3012.14	-0.381592
3015.43	31.3635
3018.72	1.79517
3022	-11.7729
3025.29	3.98169
3028.57	-1.03296
3031.85	76.0725
3035.14	0.889648
3038.41	68.5193
3041.69	46.3196
3044.97	32.7322
3048.24	53.1443
3051.52	42.4495
3054.79	20.3113
3058.06	5.45239
3061.33	8.02124
3064.6	58.2749
3067.87	41.769
3071.13	39.4573
3074.4	49.8445
3077.66	11.8984
3080.92	28.426
3084.18	26.49
3087.44	-2.53467
3090.7	10.7695
3093.95	18.7852
3097.21	29.9832
3100.46	18.3911
3103.71	14.2244
3106.96	66.3403
3110.21	49.2219
3113.46	12.0457
3116.71	24.4966
3119.95	35.0769
3123.2	22.7786
3126.44	5.64551
3129.68	1.86987
3132.92	57.1621
3136.16	40.8608
3139.4	9.24707
3142.63	20.5295
3145.87	48.1572
3149.1	52.0542
3152.33	27.2659
3155.56	3.46704
3158.79	26.3708
3162.02	50.2454
3165.25	44.384
3168.47	86.0481
3171.69	36.9507
3174.92	45.8821
3178.14	61.407
3181.36	97.9817
3184.58	46.6057
3187.79	52.3328
3191.01	27.55
3194.22	75.1726
3197.43	20.8015
3200.65	84.6006
3203.86	19.9607
3207.07	62.9954
3210.27	65.2578
3213.48	62.0066
3216.69	51.1946
3219.89	42.3398
3223.09	68.9143
3226.29	44.2068
3229.49	61.5684
3232.69	74.9724
3235.89	84.0352
3239.08	47.6445
3242.28	103.77
3245.47	78.0059
3248.66	81.0269
3251.85	49.8335
3255.04	94.9832
3258.23	84.5237
3261.42	69.8984
3264.6	78.8032
3267.79	30.1233
3270.97	136.012
3274.15	99.5752
3277.33	135.345
3280.51	96.1011
3283.68	101.73
3286.86	79.4929
3290.04	103.19
3293.21	105.886
3296.38	59.9187
3299.55	88.8687
3302.72	105.97
3305.89	129.424
3309.06	96.4026
3312.22	91.718
3315.39	118.298
3318.55	171.288
3321.71	100.1
3324.87	152.104
3328.03	142.59
3331.19	166.317
3334.34	152.448
3337.5	138.828
3340.65	172.393
3343.81	175.291
3346.96	170.438
3350.11	131.701
3353.25	192.187
3356.4	112.359
3359.55	169.517
3362.69	135.327
3365.84	142.754
3368.98	141.768
3372.12	189.206
3375.26	124.448
3378.4	193.963
3381.53	165.106
3384.67	204.501
3387.8	230.741
3390.94	307.331
3394.07	369.701
3397.2	343.395
3400.33	410.47
3403.46	495.033
3406.58	735.857
3409.71	1012.53
3412.83	1600.44
3415.96	3065.88
3419.08	7090.51
3422.2	15390.1
3425.32	18537.9
3428.44	10840
3431.55	4332.15
3434.67	1979.36
3437.78	1110.27
3440.89	749.344
3444	579.681
3447.12	440.615
3450.22	399.408
3453.33	369.655
3456.44	284.358
3459.54	312.274
3462.65	273.542
3465.75	266.001
3468.85	225.471
3471.95	327.855
3475.05	249.507
3478.15	347.358
3481.24	395.025
3484.34	454.117
3487.43	551.132
3490.53	720.693
3493.62	946.893
3496.71	1315.05
3499.79	1752.14
3502.88	2220.13
3505.97	2594.79
3509.05	2522.11
3512.14	2100.96
3515.22	1529.65
3518.3	1095.7
3521.38	849.063
3524.46	616.887
3527.54	479.012
3530.61	436.03
3533.69	292.498
3536.76	311.853
3539.83	246.084
3542.9	230.159
3545.97	252.271
3549.04	211.675
3552.11	138.419
3555.18	162.908
3558.24	143.186
3561.3	126.704
3564.37	117.601
3567.43	124.72
3570.49	146.632
3573.55	141.736
3576.61	124.416
3579.66	106.914
3582.72	104.381
3585.77	118.859
3588.82	63.9099
3591.87	83.7568
3594.92	78.792
3597.97	82.3101
3601.02	93.2373
3604.07	120.995
3607.11	76.7859
3610.16	117.615
3613.2	62.8821
3616.24	54.5239
3619.28	88.7371
3622.32	83.384
3625.36	75.3423
3628.39	88.937
3631.43	124.964
3634.46	88.8521
3637.5	85.1309
3640.53	89.1765
3643.56	91.8857
3646.59	80.147
3649.62	84.6836
3652.64	53.0227
3655.67	75.9326
3658.69	55.8811
3661.72	50.5742
3664.74	82.0452
3667.76	101.378
3670.78	39.8302
3673.79	84.0314
3676.81	81.2067
3679.83	58.4714
3682.84	47.0375
3685.86	83.8904
3688.87	80.1445
3691.88	24.3588
3694.89	43.9757
3697.9	39.197
3700.91	65.8536
3703.91	69.7511
3706.92	32.5963
3709.92	67.4849
3712.92	85.0138
3715.92	61.7073
3718.92	49.649
3721.92	21.2026
3724.92	47.7871
3727.92	41.848
3730.91	68.103
3733.91	62.7032
3736.9	79.0134
3739.89	38.9268
3742.88	58.6151
3745.87	59.073
3748.86	101.163
3751.85	73.8091
3754.83	40.8417
3757.82	48.681
3760.8	88.5763
3763.78	51.6881
3766.76	65.1399
3769.74	0.252319
3772.72	83.0845
3775.7	55.3994
3778.67	-12.7448
3781.65	86.3628
3784.62	108.088
3787.6	78.9371
3790.57	27.4312
3793.54	37.4877
3796.51	37.277
3799.47	50.5283
3802.44	86.5995
3805.41	66.0736
3808.37	70.2196
3811.33	101.853
3814.3	61.675
3817.26	97.2405
3820.22	78.9213
3823.18	94.8149
3826.13	45.3857
3829.09	83.1132
3832.04	47.9653
3835	50.8865
3837.95	61.4385
3840.9	87.1991
3843.85	90.1768
3846.8	49.4109
3849.75	95.4352
3852.69	71.9457
3855.64	41.7502
3858.58	108.07
3861.53	33.7758
3864.47	55.0836
3867.41	71.4918
3870.35	61.9491
3873.29	79.1943
3876.22	129.865
3879.16	70.8708
3882.1	37.5273
3885.03	47.2391
3887.96	49.1665
3890.89	34.6736
3893.82	113.251
3896.75	88.6659
3899.68	101.535
3902.61	49.7003
3905.53	74.9703
3908.46	45.3549
3911.38	47.2874
3914.3	72.0349
3917.23	63.5162
3920.15	76.8337
3923.06	93.7195
3925.98	37.5175
3928.9	46.3562
3931.81	63.1978
3934.73	49.7743
3937.64	56.9124
3940.55	-10.7484
3943.46	75.7715
3946.37	46.615
3949.28	35.8091
3952.19	103.597
3955.09	37.4738
3958	26.9902
3960.9	41.5009
3963.8	95.4358
3966.71	56.4651
3969.61	101.989
3972.51	58.2405
3975.4	61.4176
3978.3	72.1355
3981.2	78.9736
3984.09	96.2875
3986.99	31.8518
3989.88	83.4594
3992.77	49.771
3995.66	34.3595
3998.55	78.7067
4001.43	116.361