File: Data/3-Raman/processed/bu19(2)w-a-ff2-fi03-v_1800 (450-850nm)_532nm_edge_100%_x100_vis_lwd_h100um_30sx2_01.txt
#Acq. time (s)=	30
#Accumulations=	2
#Range (cm-¹)=	1200...2365
#Windows=	3
#Auto scanning=	Off
#Autofocus=	Off
#Macrospot=	Off
#AutoExposure=	Off
#Spike filter=	Multiple accum.
#Delay time (s)=	2
#Binning=	1
#Readout mode=	Signal
#DeNoise=	Off
#ICS correction=	On
#Dark correction=	Off
#Inst. Process=	Off
#Detector Gain=	Best Dynamic
#Detector ADC=	50 kHz HS
#Detector temperature (°C)=	-60.09
#Instrument=	LabRAM HR Evol
#Detector=	SIN-EM FIVIS
#Objective=	x100_VIS_LWD
#Grating=	1800 (450-850nm)
#ND Filter=	100%
#Laser=	532nm_Edge
#Hole=	100.021
#Temperature=	0
#Range=	Visible
#StageXY=	75x50mm Scan+
#StageZ=	Z motor
#X (µm)=	0
#Y (µm)=	0
#Z (µm)=	-43.7
#Full time(mm:ss)=	3:22
#Project=	21_11_26
#Sample=	BU19(2)w
#Site=
#Title=	BU19(2)w-A-FF2-FI03-V_1800 (450-850nm)_532nm_Edge_100%_x100_VIS_LWD_H100um_30sX2
#Remark=
#Date=	26.11.2021 15:16
#Acquired=	26.11.2021 15:16:39
#Base:Fit=	16.12.2021 16:00:56
#Base:Fit=	16.12.2021 16:11:20
#Base:Sub=	16.12.2021 16:11:22
1202.72	25.7712
1203.84	16.985
1204.95	5.62717
1206.06	4.75119
1207.17	-3.79718
1208.28	10.4059
1209.39	-0.0362854
1210.5	2.52789
1211.61	1.51114
1212.72	-10.1317
1213.83	4.98749
1214.94	1.1716
1216.05	16.4735
1217.16	-3.77859
1218.27	10.0831
1219.38	-16.2554
1220.49	-3.28201
1221.6	3.33286
1222.71	0.0675964
1223.81	-6.54581
1224.92	-1.31857
1226.03	14.8322
1227.14	12.935
1228.25	-8.62088
1229.35	-13.3152
1230.46	0.398834
1231.57	3.92438
1232.67	0.985779
1233.78	5.32053
1234.89	-8.0256
1235.99	-6.65417
1237.1	-1.30035
1238.2	-5.74811
1239.31	3.46735
1240.41	-9.08282
1241.52	5.75751
1242.62	2.61551
1243.73	5.97778
1244.83	-1.25485
1245.94	5.88504
1247.04	-15.135
1248.14	0.577728
1249.25	5.71127
1250.35	21.4698
1251.45	14.9673
1252.56	-4.00244
1253.66	18.7988
1254.76	9.64993
1255.87	10.7995
1256.97	18.2322
1258.07	19.2417
1259.17	2.4118
1260.27	4.74774
1261.37	19.0326
1262.48	60.5754
1263.58	61.682
1264.68	30.4946
1265.78	20.7806
1266.88	11.4068
1267.98	12.7993
1269.08	36.3081
1270.18	15.3822
1271.28	19.2787
1272.38	15.1482
1273.47	15.5636
1274.57	11.7079
1275.67	34.845
1276.77	12.0367
1277.87	10.2257
1278.97	32.6288
1280.07	42.1815
1281.16	84.2827
1282.26	258.255
1283.36	726.216
1284.45	419.527
1285.55	86.9715
1286.65	32.1878
1287.75	22.5956
1288.84	16.216
1289.94	11.1728
1291.03	9.18219
1292.13	19.7041
1293.22	-7.66757
1294.32	28.5902
1295.42	9.71948
1296.51	4.09949
1297.61	-0.138794
1298.7	-2.39554
1299.79	-9.91531
1300.89	-0.280334
1301.98	-1.2507
1303.08	-0.0681152
1304.17	-7.53674
1305.26	-1.18781
1306.35	-20.4008
1307.45	-0.369354
1308.54	-6.62494
1309.63	8.29236
1310.73	11.5634
1311.82	3.22598
1312.91	8.71625
1314	10.7839
1315.09	1.37421
1316.18	8.99463
1317.28	0.556671
1318.37	4.94794
1319.46	-16.0973
1320.55	2.99277
1321.64	2.84268
1322.73	18.4497
1323.82	-15.3346
1324.91	-6.80554
1326	5.71384
1327.09	-1.04547
1328.18	10.1105
1329.27	-2.07748
1330.35	4.29532
1331.44	-9.58893
1332.53	1.63818
1333.62	-4.99661
1334.71	-2.10275
1335.79	18.7135
1336.88	4.97162
1337.97	14.3723
1339.06	0.598358
1340.14	1.7316
1341.23	6.04529
1342.32	6.02429
1343.4	2.70935
1344.49	-0.354553
1345.58	-4.57953
1346.66	21.1923
1347.75	-4.12674
1348.83	-10.416
1349.92	13.4292
1351	1.83786
1352.09	4.83411
1353.17	-1.09875
1354.25	-7.96506
1355.34	-1.28412
1356.42	-4.32104
1357.51	14.335
1358.59	1.78952
1359.67	19.316
1360.76	8.7551
1361.84	3.59201
1362.92	-3.65674
1364	11.0639
1365.09	8.05804
1366.17	12.0422
1367.25	5.60782
1368.33	16.0516
1369.41	39.0062
1370.5	11.1224
1371.58	3.74149
1372.66	19.9063
1373.74	-4.93353
1374.82	21.8765
1375.9	25.0768
1376.98	20.9243
1378.06	33.2787
1379.14	31.8914
1380.22	23.593
1381.3	50.7934
1382.38	40.2629
1383.46	46.0351
1384.54	82.8608
1385.61	231.123
1386.69	1166.31
1387.77	861.387
1388.85	146.709
1389.93	60.4723
1391	34.3997
1392.08	21.9464
1393.16	20.7816
1394.23	14.632
1395.31	17.7991
1396.39	13.9209
1397.46	18.9865
1398.54	24.1446
1399.62	9.04703
1400.69	5.1734
1401.77	0.308807
1402.84	10.1172
1403.92	3.33704
1404.99	25.8003
1406.07	22.6183
1407.14	50.3054
1408.22	86.3994
1409.29	89.697
1410.37	20.1375
1411.44	25.0388
1412.51	5.6124
1413.59	13.7573
1414.66	8.35031
1415.73	21.9395
1416.81	12.8989
1417.88	5.95215
1418.95	-17.5312
1420.02	22.5634
1421.1	-1.21332
1422.17	14.3
1423.24	10.9416
1424.31	18.2011
1425.38	0.869507
1426.45	13.3519
1427.52	1.85263
1428.59	-7.56583
1429.67	2.84579
1430.74	-9.10654
1431.81	-0.437408
1432.87	6.65649
1433.95	-28.55
1435.01	-16.0817
1436.08	20.8812
1437.15	-4.75214
1438.22	-8.85287
1439.29	9.76099
1440.36	-6.34259
1441.43	12.2674
1442.49	-5.13101
1443.56	19.5273
1444.63	-3.02661
1445.7	6.50525
1446.77	5.44138
1447.83	12.5652
1448.9	1.43924
1449.97	-1.62601
1451.03	-2.73868
1452.1	11.5558
1453.17	-2.74927
1454.23	-1.62463
1455.3	8.65146
1456.36	-13.7755
1457.43	1.52313
1458.49	5.61673
1459.56	22.1078
1460.62	-15.7992
1461.69	-1.54791
1462.75	13.6353
1463.82	3.16989
1464.88	-2.59775
1465.94	1.66809
1467.01	-0.434387
1468.07	-1.47171
1469.13	-4.54129
1470.2	-18.9731
1471.26	-6.86356
1472.32	0.13324
1473.39	-12.1091
1474.45	-2.04822
1475.51	9.22156
1476.57	4.04691
1477.63	-4.21875
1478.69	26.1895
1479.76	4.65894
1480.82	-7.83099
1481.88	22.5132
1482.94	6.51105
1484	11.6591
1485.06	-5.18762
1486.12	-9.31735
1487.18	17.0687
1488.24	-19.5453
1489.3	13.6263
1490.36	15.569
1491.42	1.24844
1492.48	1.22073
1493.53	-0.836792
1494.59	8.25259
1495.65	-4.00101
1496.71	9.84293
1497.77	6.72522
1498.82	0.649689
1499.88	-0.29599
1500.94	4.76913
1502	16.7507
1503.05	13.5959
1504.11	1.32962
1505.17	3.36661
1506.22	6.10568
1507.28	1.08182
1508.34	-4.97562
1509.39	15.1676
1510.45	19.2328
1511.5	14.9024
1512.56	-8.84256
1513.61	5.87564
1514.67	9.06564
1515.72	7.77463
1516.78	5.46725
1517.83	-1.62039
1518.88	30.5682
1519.94	4.55099
1520.99	13.5177
1522.05	-1.49896
1523.1	5.3696
1524.15	-3.01617
1525.2	5.84259
1526.26	12.9569
1527.31	2.06982
1528.36	10.9467
1529.41	0.787109
1530.47	13.6888
1531.52	14.8672
1532.57	18.7976
1533.62	10.0788
1534.67	-5.95261
1535.72	-1.10764
1536.77	5.45761
1537.82	17.0995
1538.87	13.8743
1539.92	17.3111
1540.97	-2.25421
1542.02	4.54013
1543.07	2.20309
1544.12	-2.17636
1545.17	-7.02939
1546.22	-1.77155
1547.27	-4.74789
1548.32	-3.93396
1549.37	5.86609
1550.42	15.9482
1551.46	9.81049
1552.51	-2.26419
1553.56	3.49878
1554.61	10.2571
1555.65	17.9586
1556.7	9.88181
1557.75	8.89136
1558.79	-5.40973
1559.84	6.21637
1560.89	-0.971619
1561.93	11.0416
1562.98	12.1721
1564.02	-0.923553
1565.07	4.28323
1566.11	8.37613
1567.16	16.6231
1568.2	8.8356
1569.25	6.87317
1570.29	-3.31052
1571.34	11.6354
1572.38	5.46194
1573.43	4.23996
1574.47	-4.81146
1575.51	-9.55515
1576.56	0.443512
1577.6	12.0299
1578.64	14.6244
1579.69	15.5649
1580.73	-4.32001
1581.77	1.49316
1582.81	3.28131
1583.85	8.16901
1584.9	1.17941
1585.94	5.11545
1586.98	0.868988
1588.02	23.6058
1589.06	15.7264
1590.1	2.87299
1591.14	-8.02466
1592.18	1.84106
1593.22	4.51236
1594.26	0.067688
1595.3	20.9599
1596.34	4.92929
1597.38	13.8768
1598.42	6.91269
1599.46	24.4778
1600.5	17.2877
1601.54	3.0441
1602.58	-1.24628
1603.62	3.41199
1604.66	12.2199
1605.69	14.2054
1606.73	8.39328
1607.77	-3.88272
1608.81	10.9828
1609.84	18.6091
1610.88	7.06436
1611.92	-8.84952
1612.95	10.4026
1613.99	15.8938
1615.03	-2.94547
1616.06	0.517578
1617.1	12.6531
1618.13	17.2126
1619.17	1.39606
1620.2	6.3826
1621.24	2.4454
1622.27	4.01395
1623.31	2.55914
1624.34	11.9292
1625.38	14.362
1626.41	20.6404
1627.45	4.42816
1628.48	5.83163
1629.51	13.6188
1630.55	5.06516
1631.53	-7.2713
1632.57	21.4054
1633.62	-3.26584
1634.66	3.68124
1635.71	14.4901
1636.75	13.3818
1637.8	-3.51514
1638.84	3.29227
1639.89	4.26871
1640.93	14.1499
1641.98	0.360016
1643.02	10.1459
1644.06	13.0514
1645.11	18.8381
1646.15	-8.63838
1647.19	6.02182
1648.24	11.8388
1649.28	13.0601
1650.32	18.959
1651.37	24.1324
1652.41	3.49341
1653.45	21.1719
1654.49	5.46713
1655.53	13.4709
1656.57	33.4913
1657.62	12.777
1658.66	6.77103
1659.7	7.61664
1660.74	0.684265
1661.78	4.82242
1662.82	9.07303
1663.86	18.9962
1664.9	5.00687
1665.94	-1.22787
1666.98	5.02658
1668.02	-14.8336
1669.06	11.8792
1670.1	-3.71774
1671.14	-7.47218
1672.18	8.31638
1673.21	4.40927
1674.25	-4.40849
1675.29	2.67798
1676.33	8.69653
1677.37	2.80533
1678.4	9.63126
1679.44	5.52988
1680.48	-2.44534
1681.52	2.43451
1682.55	11.3453
1683.59	8.39102
1684.63	-2.51019
1685.66	12.2817
1686.7	4.43613
1687.73	-4.36295
1688.77	-0.490448
1689.81	1.3381
1690.84	-13.4925
1691.88	-7.45309
1692.91	-1.52853
1693.95	11.0759
1694.98	-5.83202
1696.01	-12.6579
1697.05	-6.6433
1698.08	-11.7253
1699.12	-1.02754
1700.15	2.93471
1701.18	-6.93156
1702.22	7.73154
1703.25	9.57599
1704.28	14.4612
1705.32	-3.13449
1706.35	10.6037
1707.38	-3.34181
1708.41	5.24942
1709.44	3.99937
1710.48	-12.6574
1711.51	15.8661
1712.54	-14.4364
1713.57	2.85541
1714.6	11.4279
1715.63	-13.9282
1716.66	-3.144
1717.69	1.46921
1718.72	-5.71193
1719.75	7.87183
1720.78	-0.857285
1721.81	7.73
1722.84	-1.22162
1723.87	1.55582
1724.9	4.43689
1725.93	16.7379
1726.96	-4.63193
1727.99	-14.3433
1729.02	6.51457
1730.05	2.44344
1731.07	-6.34271
1732.1	-7.94363
1733.13	0.699585
1734.16	-1.50854
1735.18	-0.804443
1736.21	-0.990723
1737.24	21.0744
1738.26	-15.5722
1739.29	14.0605
1740.32	1.24094
1741.34	1.963
1742.37	3.7558
1743.4	17.1304
1744.42	0.784241
1745.45	-8.78145
1746.47	-3.08362
1747.5	-4.24829
1748.52	-0.524277
1749.55	-5.19003
1750.57	10.3463
1751.6	21.0251
1752.62	1.722
1753.64	6.33447
1754.67	3.33066
1755.69	-4.37547
1756.71	-1.68251
1757.74	3.81995
1758.76	13.4678
1759.78	7.83519
1760.81	8.76884
1761.83	6.7527
1762.85	14.3917
1763.87	14.4743
1764.89	4.2538
1765.92	12.9852
1766.94	0.641663
1767.96	4.42429
1768.98	8.17384
1770	0.16861
1771.02	1.29878
1772.04	-3.20251
1773.06	12.2098
1774.08	7.61266
1775.1	11.5531
1776.12	25.1952
1777.14	6.1795
1778.16	-11.0774
1779.18	-2.65834
1780.2	11.6229
1781.22	12.7079
1782.24	6.1651
1783.26	3.52078
1784.28	-1.07164
1785.29	-0.860916
1786.31	13.4301
1787.33	3.10123
1788.35	0.746155
1789.37	-1.72292
1790.38	-4.33852
1791.4	0.467468
1792.42	3.19424
1793.43	15.7689
1794.45	4.36798
1795.47	8.46732
1796.48	2.07056
1797.5	4.2261
1798.51	12.0837
1799.53	0.563721
1800.55	4.28262
1801.56	-5.35648
1802.58	-3.34813
1803.59	1.66879
1804.61	-8.7632
1805.62	3.98796
1806.64	-2.52258
1807.65	-0.493668
1808.66	0.520325
1809.68	-0.37352
1810.69	-9.94862
1811.7	16.0836
1812.72	-6.9837
1813.73	4.74966
1814.74	11.7671
1815.76	6.19525
1816.77	-0.485062
1817.78	-9.29329
1818.79	4.30197
1819.8	13.1044
1820.82	1.64676
1821.83	4.69937
1822.84	-4.84908
1823.85	-15.4701
1824.86	11.6702
1825.87	12.7572
1826.88	5.04974
1827.89	-13.2612
1828.9	3.2234
1829.91	9.94862
1830.92	1.15826
1831.93	8.05272
1832.94	-4.37679
1833.95	1.52481
1834.96	13.0066
1835.97	-3.80566
1836.98	7.76161
1837.99	13.7714
1839	1.18657
1840	6.37933
1841.01	-4.72934
1842.02	14.1628
1843.03	1.41608
1844.04	2.39198
1845.04	10.1277
1846.05	-0.403107
1847.06	-3.05699
1848.07	20.205
1849.07	-0.919739
1850.08	3.71411
1851.09	-7.14853
1852.09	0.386383
1853.1	0.376526
1854.1	-7.39484
1855.11	3.87105
1856.11	-26.0573
1857.12	-5.01672
1858.12	18.8321
1859.13	-6.25412
1860.13	12.701
1861.14	-2.49548
1862.14	16.7715
1863.15	-3.48357
1864.15	11.5925
1865.15	1.85133
1866.16	-0.369583
1867.16	-7.44403
1868.16	-14.3997
1869.17	8.38287
1870.17	-2.12781
1871.17	22.5325
1872.17	5.32262
1873.18	-5.28288
1874.18	10.7443
1875.18	14.2937
1876.18	-8.8177
1877.18	-1.51106
1878.18	2.85367
1879.19	9.86195
1880.19	-2.26456
1881.19	-9.88478
1882.19	2.99475
1883.19	5.29561
1884.19	7.83955
1885.19	-9.96893
1886.19	-4.0323
1887.19	9.13002
1888.19	0.37915
1889.19	3.79874
1890.19	9.2841
1891.19	20.7164
1892.18	-4.79216
1893.18	12.0197
1894.18	-7.19121
1895.18	2.06721
1896.18	12.4538
1897.18	-3.3963
1898.17	3.22072
1899.17	3.98747
1900.17	6.60686
1901.16	3.74821
1902.16	-4.55815
1903.16	12.4274
1904.16	1.95396
1905.15	18.7993
1906.15	7.38358
1907.14	-1.28001
1908.14	2.46935
1909.14	13.8124
1910.13	12.125
1911.13	-2.6741
1912.12	6.77402
1913.12	-0.842133
1914.11	7.7117
1915.11	3.19548
1916.1	9.84958
1917.1	-2.57877
1918.09	4.80206
1919.08	6.80521
1920.08	15.6075
1921.07	-1.39844
1922.06	-6.92458
1923.06	2.45016
1924.05	0.410339
1925.04	12.5262
1926.04	6.03375
1927.03	-3.20247
1928.02	6.36731
1929.01	-4.94862
1930	-2.90939
1931	9.6356
1931.99	1.01343
1932.98	-8.66574
1933.97	-2.9865
1934.96	-4.25667
1935.95	7.6521
1936.94	1.64136
1937.93	5.18202
1938.92	-5.35962
1939.91	-1.47194
1940.9	4.35677
1941.89	6.4321
1942.88	6.48035
1943.87	-16.6203
1944.86	9.25923
1945.85	2.75308
1946.84	10.5079
1947.83	6.58382
1948.82	-4.02582
1949.8	-2.97794
1950.79	-1.74796
1951.78	-3.35948
1952.77	-0.346664
1953.76	-8.06601
1954.74	-13.4181
1955.73	8.43398
1956.72	-2.72203
1957.7	-8.32457
1958.69	12.8739
1959.68	10.8035
1960.66	2.92628
1961.65	-8.82744
1962.63	2.62857
1963.62	12.2001
1964.61	-7.95216
1965.59	3.47458
1966.58	-0.304016
1967.56	10.3159
1968.55	0.678574
1969.53	-5.28758
1970.52	9.73676
1971.5	1.84404
1972.48	11.3645
1973.47	0.68869
1974.45	5.25673
1975.44	10.9578
1976.42	-0.491348
1977.4	12.8843
1978.39	12.6833
1979.37	-12.3899
1980.35	2.89578
1981.33	3.64917
1982.31	2.52896
1983.3	-6.30795
1984.28	-0.806
1985.26	16.2187
1986.24	17.0166
1987.22	9.38458
1988.21	15.8142
1989.19	9.53441
1990.17	17.9474
1991.15	8.2224
1992.13	2.27145
1993.11	8.00491
1994.09	18.3054
1995.07	16.4132
1996.05	19.0829
1997.03	15.5755
1998.01	14.2234
1998.99	14.3688
1999.97	19.9304
2000.95	10.1621
2001.92	5.4021
2002.9	18.1914
2003.88	15.526
2004.86	18.8397
2005.84	12.8198
2006.81	19.858
2007.79	22.0492
2008.77	14.6849
2009.75	18.9111
2010.73	14.6721
2011.7	9.90984
2012.68	22.073
2013.67	15.2367
2014.66	22.3931
2015.64	28.8759
2016.63	11.1479
2017.62	1.90788
2018.61	8.20299
2019.6	28.5012
2020.58	10.6117
2021.57	9.69121
2022.56	19.0038
2023.55	17.8651
2024.54	13.0071
2025.52	12.7225
2026.51	11.6167
2027.5	15.9487
2028.48	6.35645
2029.47	6.70857
2030.45	4.19604
2031.44	12.7002
2032.43	9.94916
2033.41	13.0452
2034.4	0.9319
2035.38	10.8867
2036.37	12.3067
2037.35	1.96675
2038.34	2.8528
2039.32	9.27148
2040.31	-1.1713
2041.29	5.16234
2042.27	22.7853
2043.26	2.20296
2044.24	8.05984
2045.23	17.2665
2046.21	2.79929
2047.19	-7.65234
2048.17	13.5445
2049.16	16.4124
2050.14	6.41072
2051.12	-4.62234
2052.11	9.27977
2053.09	-7.44621
2054.07	0.268509
2055.05	-1.51903
2056.03	13.3559
2057.01	-2.59084
2058	-1.59137
2058.98	-0.479355
2059.96	-4.10873
2060.94	-1.36101
2061.92	-2.19679
2062.9	-8.68826
2063.88	4.57185
2064.86	10.297
2065.84	1.1404
2066.82	-0.590424
2067.8	4.21542
2068.78	2.4528
2069.76	6.17165
2070.73	11.8063
2071.71	-4.95679
2072.69	-0.885818
2073.67	-6.55365
2074.65	1.04796
2075.63	-8.10175
2076.6	-5.03082
2077.58	-5.11436
2078.56	-2.31487
2079.54	3.48268
2080.51	9.38454
2081.49	3.72832
2082.47	-4.75642
2083.45	3.79573
2084.42	-6.59351
2085.4	-12.235
2086.37	5.81061
2087.35	2.21265
2088.32	5.13284
2089.3	-1.43556
2090.28	6.30533
2091.25	-6.8694
2092.23	7.53152
2093.2	13.5232
2094.18	-1.44998
2095.15	-10.8946
2096.13	-7.18436
2097.1	7.0325
2098.07	7.8707
2099.05	17.3308
2100.02	-7.3541
2101	2.19943
2101.97	10.903
2102.94	6.16003
2103.92	12.7192
2104.89	8.03944
2105.86	5.36191
2106.83	5.4828
2107.8	3.61771
2108.78	-9.86588
2109.75	3.45538
2110.72	14.9248
2111.69	0.682739
2112.66	5.3914
2113.63	0.785919
2114.61	-12.4624
2115.58	-2.93529
2116.55	7.44646
2117.52	6.44034
2118.49	13.0276
2119.46	9.9874
2120.43	1.32217
2121.4	3.29228
2122.37	4.45628
2123.34	7.45494
2124.31	13.1613
2125.28	6.26361
2126.25	-0.632874
2127.21	14.3398
2128.18	-10.3059
2129.15	-7.47598
2130.12	1.95384
2131.09	-1.85849
2132.06	5.60513
2133.02	-7.7066
2133.99	12.1311
2134.96	-2.92909
2135.93	4.6033
2136.89	-10.6488
2137.86	-7.75148
2138.83	1.62964
2139.79	3.5925
2140.76	3.44405
2141.73	-0.349274
2142.69	-5.1349
2143.66	13.8889
2144.62	-14.7245
2145.59	2.23682
2146.55	1.28635
2147.52	9.6871
2148.48	0.218109
2149.45	9.50658
2150.42	3.65779
2151.38	-1.98947
2152.34	0.0149994
2153.31	0.911438
2154.27	8.32909
2155.24	9.92488
2156.2	2.19
2157.16	3.07532
2158.13	6.9252
2159.09	-6.10002
2160.05	-6.18829
2161.01	-1.67734
2161.98	3.87544
2162.94	10.4222
2163.9	-1.76671
2164.86	8.3667
2165.83	8.39226
2166.79	-3.73466
2167.75	10.1098
2168.71	-2.24841
2169.67	2.50517
2170.63	0.929245
2171.59	-10.2702
2172.56	5.23192
2173.51	-10.6096
2174.48	-4.02187
2175.44	9.0239
2176.4	-2.14548
2177.36	10.8256
2178.32	4.36353
2179.28	9.83745
2180.23	8.9509
2181.19	3.37292
2182.15	-1.30751
2183.11	-5.06709
2184.07	-4.29802
2185.03	-5.26105
2185.99	5.96478
2186.95	-5.89632
2187.9	-1.00479
2188.86	11.0062
2189.82	1.53067
2190.78	2.3965
2191.73	-0.310364
2192.69	-0.21228
2193.65	10.147
2194.6	1.19475
2195.56	-0.656342
2196.52	-4.54796
2197.47	5.49765
2198.43	4.59608
2199.38	-20.2139
2200.34	-1.31995
2201.3	2.7818
2202.25	3.9803
2203.21	-8.65639
2204.16	-3.25563
2205.12	-4.52686
2206.07	16.4053
2207.03	11.7655
2207.98	-2.95998
2208.93	13.0583
2209.89	-11.9906
2210.84	-4.45737
2211.8	3.15645
2212.75	6.11874
2213.7	-6.06563
2214.66	5.25365
2215.61	-8.58722
2216.56	7.32394
2217.51	-5.74329
2218.47	8.30196
2219.42	-3.71655
2220.37	12.3036
2221.32	-5.46857
2222.27	-0.956085
2223.23	0.950211
2224.18	-8.19417
2225.13	-6.08868
2226.08	-3.06036
2227.03	9.31
2227.98	0.0744171
2228.93	0.0510864
2229.88	-0.84845
2230.83	5.92499
2231.78	7.07799
2232.73	0.689407
2233.68	2.74763
2234.63	12.266
2235.58	16.836
2236.53	-1.03703
2237.48	-3.75577
2238.43	-4.394
2239.38	5.30524
2240.33	7.1261
2241.27	7.24521
2242.22	0.721558
2243.17	4.59274
2244.12	7.36563
2245.07	9.37363
2246.01	4.92792
2246.96	-2.47284
2247.91	17.5177
2248.85	-8.04997
2249.8	9.01233
2250.75	0.47673
2251.69	1.28876
2252.64	6.0916
2253.59	-3.05392
2254.53	3.78825
2255.48	7.62601
2256.42	2.9613
2257.37	-9.21129
2258.32	0.401367
2259.26	-1.40517
2260.2	0.608093
2261.15	-7.83507
2262.1	-6.73711
2263.04	3.85962
2263.98	7.93134
2264.93	-6.06709
2265.87	10.3227
2266.81	12.1487
2267.76	-1.35486
2268.7	3.3101
2269.65	-1.30615
2270.59	1.8318
2271.53	8.69116
2272.47	4.04707
2273.42	5.06111
2274.36	-3.48868
2275.3	-5.33936
2276.24	7.17484
2277.18	3.55087
2278.13	4.80199
2279.07	-0.80452
2280.01	-5.73369
2280.95	0.800293
2281.89	1.68062
2282.83	3.72244
2283.77	0.135315
2284.71	2.40512
2285.65	10.2531
2286.59	-2.36186
2287.54	-6.94159
2288.47	11.4669
2289.41	-1.20172
2290.35	-10.0982
2291.29	-9.11047
2292.23	-1.20459
2293.17	4.75377
2294.11	3.90446
2295.05	4.76727
2295.99	-11.7074
2296.93	3.53851
2297.86	-1.13445
2298.8	-4.782
2299.74	-3.6413
2300.68	6.9894
2301.61	1.31635
2302.55	1.31586
2303.49	10.9465
2304.43	3.28622
2305.36	0.516739
2306.3	4.46098
2307.24	7.39867
2308.17	0.567429
2309.11	22.7623
2310.04	2.65401
2310.98	0.78157
2311.92	-0.503525
2312.85	7.02446
2313.79	-5.47151
2314.72	-4.25732
2315.66	-16.7151
2316.59	-5.36751
2317.52	-3.52446
2318.46	9.05246
2319.39	-4.6053
2320.33	-4.68404
2321.26	3.07541
2322.2	2.26952
2323.13	9.14775
2324.06	1.44579
2325	12.9632
2325.93	27.1879
2326.86	29.8658
2327.79	50.8606
2328.73	31.4986
2329.66	8.20134
2330.59	10.0796
2331.52	0.384964
2332.46	-0.556656
2333.39	-2.64453
2334.32	4.92024
2335.25	9.54475
2336.18	3.73438
2337.11	-3.09344
2338.04	6.42802
2338.97	6.3365
2339.91	6.28896
2340.84	6.11873
2341.77	-9.54462
2342.7	-7.84177
2343.63	1.6447
2344.56	7.3288
2345.49	1.47374
2346.41	-1.63539
2347.34	-4.63753
2348.27	1.98323
2349.2	2.88011
2350.13	-0.388672
2351.06	2.36301
2351.99	-0.72348
2352.91	-5.89742
2353.84	-4.37994
2354.77	4.0972
2355.7	-0.762344
2356.63	1.83821
2357.55	-5.18813
2358.48	7.88553
2359.41	-3.73746
2360.33	6.46321
2361.26	-2.40427
2362.19	4.83424
2363.11	-9.71451
2364.04	-3.35005
2364.97	0.165253