File: Data/3-Raman/processed/bu20-b-ff4-fi01-v_150 (500nm)_633nm_edge_100%_x100_vis_lwd_h30um_60sx2_01.txt
#Acq. time (s)=	60
#Accumulations=	2
#Range (cm-¹)=	100...4000
#Windows=	1
#Auto scanning=	Off
#Autofocus=	Off
#Macrospot=	Off
#AutoExposure=	Off
#Spike filter=	Multiple accum.
#Delay time (s)=	2
#Binning=	1
#Readout mode=	Signal
#DeNoise=	Off
#ICS correction=	On
#Dark correction=	Off
#Inst. Process=	Off
#Detector Gain=	Best Dynamic
#Detector ADC=	50 kHz HS
#Detector temperature (°C)=	-60.09
#Instrument=	LabRAM HR Evol
#Detector=	SIN-EM FIVIS
#Objective=	x100_VIS_LWD
#Grating=	150 (500nm)
#ND Filter=	100%
#Laser=	633nm_Edge
#Hole=	30.0125
#Temperature=	39.9
#Range=	Visible
#StageXY=	75x50mm Scan+
#StageZ=	Z motor
#X (µm)=	0
#Y (µm)=	0
#Z (µm)=	469.1
#Full time(mm:ss)=	2:05
#Project=	21_08_11
#Sample=	BU20
#Site=
#Title=	BU20-B-FF4-FI01-V_150 (500nm)_633nm_Edge_100%_x100_VIS_LWD_H30um_60sX2
#Remark=
#Date=	13.08.2021 11:43
#Acquired=	13.08.2021 11:43:40
#Data Range:Extract=	16.12.2021 15:36:30
#Base:Fit=	16.12.2021 15:36:40
#Base:Edit=	16.12.2021 15:51:30
#Base:Edit=	16.12.2021 15:51:31
#Base:Sub=	16.12.2021 15:51:38
100.12	590.117
106.638	399.8
113.152	310.699
119.66	254.06
126.162	171.698
132.659	124.799
139.151	98.0628
145.637	85.8637
152.118	64.2721
158.594	51.4933
165.064	34.0703
171.529	34.9474
177.989	19.5893
184.441	7.16803
190.89	8.20775
197.334	-4.96876
203.772	1.18253
210.205	5.5249
216.631	-2.44399
223.054	10.6368
229.471	13.2095
235.881	52.0049
242.288	97.4716
248.689	53.8053
255.083	26.3065
261.474	23.5912
267.858	26.6387
274.238	38.2978
280.613	65.1691
286.982	120.443
293.346	116.881
299.704	63.1924
306.058	36.0777
312.406	18.4951
318.749	23.6285
325.086	49.5977
331.418	107.66
337.746	107.238
344.068	43.6542
350.384	18.7318
356.697	12.6447
363.003	35.7181
369.304	59.6839
375.601	51.68
381.892	31.512
388.177	15.2472
394.457	13.1746
400.733	-0.081955
407.004	-1.1489
413.269	8.14101
419.529	19.2934
425.784	18.0227
432.034	32.5252
438.279	63.8792
444.518	79.0831
450.753	81.0101
456.982	70.8266
463.207	70.1474
469.426	47.2387
475.64	33.7587
481.85	24.9791
488.054	14.3058
494.253	24.1368
500.447	11.5837
506.635	23.2882
512.819	8.87929
518.999	17.8257
525.173	14.689
531.342	11.584
537.505	21.663
543.664	19.4443
549.819	17.088
555.966	13.7535
562.111	15.904
568.25	12.2837
574.383	12.3311
580.513	14.193
586.636	19.8375
592.756	22.752
598.871	53.7038
604.979	86.7841
611.084	77.0616
617.183	62.7321
623.277	65.2912
629.367	68.7652
635.451	74.773
641.532	67.3183
647.606	50.3131
653.675	48.3473
659.741	70.6513
665.801	81.632
671.856	59.1159
677.907	36.9246
683.952	24.9864
689.992	10.3343
696.028	11.6098
702.059	9.11884
708.086	8.45578
714.107	9.50451
720.123	3.9208
726.135	11.4679
732.141	8.5954
738.143	7.59545
744.14	8.47488
750.133	3.78957
756.12	11.2855
762.103	4.01255
768.081	5.24993
774.054	2.75685
780.023	8.66827
785.987	6.98732
791.946	5.25793
797.9	5.34888
803.848	0.647545
809.793	6.27249
815.733	7.11971
821.669	3.23764
827.6	6.83915
833.525	4.9445
839.446	3.19582
845.363	9.03465
851.273	10.2259
857.181	6.75264
863.083	11.7734
868.98	10.2
874.874	7.59125
880.761	13.4365
886.645	8.79571
892.523	20.2232
898.398	12.6124
904.267	8.7012
910.133	13.2761
915.992	13.1302
921.849	14.9867
927.699	14.1449
933.545	26.5865
939.387	28.884
945.224	26.5337
951.056	42.2686
956.884	53.2993
962.708	64.3009
968.526	78.1266
974.34	87.0645
980.149	103.432
985.955	158.881
991.755	225.565
997.551	239.482
1003.34	172.447
1009.13	149.583
1014.91	146.125
1020.69	150.312
1026.46	188.265
1032.23	205.401
1037.99	151.548
1043.75	91.5832
1049.51	74.7961
1055.26	60.7148
1061	46.4785
1066.74	43.7317
1072.48	39.9885
1078.21	41.0575
1083.94	57.6091
1089.67	73.2007
1095.38	78.1412
1101.1	80.1648
1106.81	85.2538
1112.51	48.7711
1118.22	42.5801
1123.91	30.4018
1129.6	25.9696
1135.29	33.2796
1140.98	30.81
1146.65	48.893
1152.33	49.2681
1158	67.2044
1163.66	52.4781
1169.32	23.0374
1174.98	18.1822
1180.63	13.3537
1186.28	11.5578
1191.93	12.7782
1197.56	4.31735
1203.2	1.81278
1208.83	9.19495
1214.46	6.77943
1220.08	5.38319
1225.69	-0.998238
1231.31	7.56634
1236.92	6.08418
1242.52	5.51752
1248.12	11.9299
1253.72	16.2631
1259.31	22.52
1264.89	51.8861
1270.48	24.775
1276.05	27.8492
1281.63	198.319
1287.2	177.098
1292.76	30.1236
1298.33	22.352
1303.88	14.6414
1309.43	17.0325
1314.98	10.5036
1320.53	19.0711
1326.07	15.5968
1331.6	9.05914
1337.13	9.56599
1342.66	15.1339
1348.18	13.4954
1353.7	9.77265
1359.22	13.1847
1364.73	25.7955
1370.23	32.1844
1375.73	20.0694
1381.23	33.627
1386.72	576.701
1392.21	133.57
1397.7	21.0389
1403.18	24.4752
1408.65	62.9721
1414.13	29.3874
1419.59	17.4095
1425.06	15.7611
1430.52	12.0282
1435.97	14.5237
1441.42	6.567
1446.87	8.00496
1452.31	10.4255
1457.75	9.64847
1463.19	3.57589
1468.62	-0.421738
1474.04	3.98046
1479.46	2.11176
1484.88	7.60748
1490.3	9.98692
1495.7	8.19519
1501.11	11.692
1506.51	5.70346
1511.91	10.3145
1517.3	3.27169
1522.69	1.52967
1528.08	7.2771
1533.46	-0.897251
1538.83	5.92995
1544.21	5.17546
1549.58	9.72132
1554.94	1.20315
1560.3	1.31129
1565.66	3.58809
1571.01	9.0847
1576.36	3.81537
1581.7	1.82825
1587.04	13.8513
1592.38	12.9779
1597.71	9.97833
1603.04	5.91235
1608.37	4.0316
1613.68	3.27225
1619	4.72049
1624.31	9.46225
1629.62	7.63876
1634.93	4.66874
1640.23	6.00806
1645.52	9.55087
1650.81	2.00766
1656.1	8.83372
1661.39	2.32898
1666.67	2.46143
1671.94	9.23781
1677.22	9.34615
1682.48	6.11486
1687.75	7.28223
1693.01	8.46717
1698.26	3.06393
1703.52	4.48959
1708.77	10.4197
1714.01	4.85159
1719.25	8.45762
1724.49	4.16409
1729.72	9.98081
1734.95	12.443
1740.18	8.14463
1745.4	8.34139
1750.61	5.11868
1755.83	16.5772
1761.04	7.62912
1766.24	-1.33182
1771.44	2.17134
1776.64	3.42043
1781.84	10.3801
1787.02	1.45049
1792.21	8.47227
1797.39	2.95865
1802.57	8.89569
1807.75	9.11272
1812.92	3.54004
1818.08	1.40578
1823.25	10.8245
1828.41	7.53864
1833.56	4.24193
1838.71	5.58486
1843.86	6.90267
1849	5.87468
1854.14	2.48293
1859.28	-0.903473
1864.41	-6.63789
1869.54	6.44136
1874.67	10.0997
1879.79	11.3953
1884.9	4.41218
1890.02	-1.42583
1895.13	4.52727
1900.23	6.95824
1905.34	2.35363
1910.43	-4.61892
1915.53	7.47763
1920.62	0.443661
1925.71	5.35138
1930.79	9.0839
1935.87	6.81921
1940.94	4.52882
1946.02	-0.192532
1951.08	7.10509
1956.15	2.34085
1961.21	10.8217
1966.27	4.82986
1971.32	0.0189514
1976.37	6.04364
1981.42	3.63742
1986.46	3.64241
1991.5	6.05914
1996.53	2.47275
2001.56	8.51824
2006.59	6.16825
2011.61	3.8323
2016.63	-2.11765
2021.65	1.55557
2026.66	1.64412
2031.67	2.96227
2036.68	0.669518
2041.68	4.43711
2046.68	2.14889
2051.67	5.94686
2056.66	2.40652
2061.65	1.32851
2066.63	1.47424
2071.61	0.383949
2076.59	7.9061
2081.56	3.11277
2086.53	8.16854
2091.49	0.864361
2096.46	-3.95352
2101.41	6.12954
2106.37	5.06174
2111.32	1.50216
2116.26	4.20156
2121.21	3.14513
2126.15	5.85866
2131.09	2.25451
2136.02	-2.64959
2140.95	-2.50424
2145.87	6.54565
2150.79	-0.971329
2155.71	4.24109
2160.63	1.78282
2165.54	3.1378
2170.45	9.60147
2175.35	5.86083
2180.25	2.09587
2185.15	3.42798
2190.04	6.05491
2194.93	1.01912
2199.82	6.2603
2204.7	3.83381
2209.58	5.27876
2214.46	6.7447
2219.33	5.64858
2224.2	7.14263
2229.06	8.64441
2233.92	4.94357
2238.78	9.05956
2243.64	4.03188
2248.49	9.48277
2253.34	7.06101
2258.18	12.5475
2263.02	8.79884
2267.86	5.00869
2272.69	6.49398
2277.52	10.6243
2282.35	16.0703
2287.17	13.5114
2291.99	8.29023
2296.81	9.72422
2301.62	9.85581
2306.43	3.34924
2311.24	4.86689
2316.04	5.06939
2320.84	6.63018
2325.63	6.85465
2330.43	15.1897
2335.21	3.27667
2340	7.59694
2344.78	14.686
2349.56	6.78838
2354.33	5.68325
2359.11	7.29446
2363.87	0.598549
2368.64	3.56196
2373.4	5.1468
2378.16	6.73611
2382.91	4.13344
2387.66	4.28387
2392.41	7.1993
2397.16	1.74854
2401.9	3.2518
2406.64	4.74492
2411.37	0.725136
2416.1	5.16575
2420.83	4.10698
2425.55	2.8818
2430.27	7.33658
2434.99	1.93494
2439.7	7.85645
2444.41	5.2751
2449.12	5.53296
2453.83	4.35836
2458.53	3.17484
2463.22	3.42235
2467.92	3.6645
2472.61	8.23877
2477.3	1.23488
2481.98	7.27975
2486.66	7.50665
2491.34	6.26649
2496.01	15.2685
2500.68	6.70068
2505.35	3.96922
2510.01	-1.72434
2514.67	1.39574
2519.33	6.00182
2523.99	1.76707
2528.64	0.47327
2533.28	8.07477
2537.93	-0.621391
2542.57	5.53418
2547.21	5.75596
2551.84	13.4518
2556.47	10.6847
2561.1	3.40198
2565.73	6.63254
2570.35	3.85524
2574.97	1.06295
2579.58	7.33584
2584.19	6.01536
2588.8	9.22984
2593.41	6.34747
2598.01	9.58457
2602.61	6.71999
2607.2	5.36602
2611.8	3.99681
2616.38	2.62009
2620.97	4.30682
2625.55	1.40319
2630.13	6.18133
2634.71	4.8564
2639.28	6.64225
2643.85	2.24925
2648.42	4.04101
2652.98	1.16515
2657.54	6.03344
2662.1	6.21417
2666.65	3.24754
2671.2	3.42804
2675.75	8.36589
2680.29	5.52888
2684.84	4.23458
2689.37	-1.85951
2693.91	4.77346
2698.44	4.9424
2702.97	9.95215
2707.49	6.92146
2712.02	0.646004
2716.53	7.28838
2721.05	2.61075
2725.56	4.38848
2730.07	9.40272
2734.58	7.91041
2739.08	9.65803
2743.58	4.92075
2748.08	5.07224
2752.57	2.00064
2757.06	2.17093
2761.55	10.5158
2766.04	5.75402
2770.52	7.55959
2775	9.38491
2779.47	4.61802
2783.94	4.82675
2788.41	-1.63179
2792.88	6.90355
2797.34	10.4449
2801.8	7.26717
2806.26	7.42575
2810.71	12.6362
2815.16	2.6386
2819.61	12.9164
2824.05	1.19043
2828.49	8.10462
2832.93	15.0324
2837.37	6.64482
2841.8	5.05622
2846.23	5.17765
2850.65	-4.9648
2855.08	8.88213
2859.5	3.87711
2863.91	10.9306
2868.33	11.1159
2872.74	7.82462
2877.15	4.51339
2881.55	8.1748
2885.95	10.1155
2890.35	6.78155
2894.75	1.65253
2899.14	10.6757
2903.53	17.9664
2907.91	3.88408
2912.3	9.37247
2916.68	5.91023
2921.05	11.4212
2925.43	9.76159
2929.8	6.29575
2934.17	11.8596
2938.53	1.08516
2942.9	4.80507
2947.26	6.70146
2951.61	8.60009
2955.97	8.67462
2960.32	10.576
2964.66	6.99132
2969.01	7.07194
2973.35	5.31581
2977.69	5.39413
2982.03	12.8582
2986.36	9.27101
2990.69	5.67371
2995.01	7.64124
2999.34	0.296988
3003.66	6.01779
3007.98	6.14252
3012.29	8.13938
3016.6	12.0532
3020.91	14.1035
3025.22	10.4343
3029.52	6.71843
3033.82	8.71014
3038.12	8.77008
3042.41	6.92615
3046.71	5.05762
3051	7.03399
3055.28	9.01839
3059.56	11.0104
3063.84	20.7583
3068.12	13.0661
3072.39	13.125
3076.67	11.2388
3080.93	11.2974
3085.2	5.4949
3089.46	19.2914
3093.72	9.58326
3097.98	11.6661
3102.23	7.82319
3106.48	13.9017
3110.73	6.06964
3114.98	20.207
3119.22	10.3288
3123.46	8.45734
3127.7	10.6341
3131.93	14.8836
3136.16	13.029
3140.39	11.1441
3144.61	15.4239
3148.84	19.7249
3153.06	15.6983
3157.27	11.6316
3161.49	18.0066
3165.7	11.8168
3169.91	11.8931
3174.11	14.0919
3178.31	14.1441
3182.51	22.6498
3186.71	24.8053
3190.9	22.7105
3195.1	16.39
3199.28	14.3482
3203.47	14.4802
3207.65	8.18054
3211.83	14.7771
3216.01	12.7783
3220.18	15.1009
3224.36	17.4381
3228.52	15.4105
3232.69	17.7622
3236.85	17.9014
3241.01	13.6298
3245.17	16.024
3249.33	7.23088
3253.48	14.0357
3257.63	23.0959
3261.77	23.2481
3265.92	21.1701
3270.06	10.0159
3274.2	14.7267
3278.33	14.7904
3282.47	17.1495
3286.59	5.74004
3290.72	8.08778
3294.85	8.13357
3298.97	8.18056
3303.09	8.24083
3307.2	10.6166
3311.32	12.9952
3315.43	10.7283
3319.54	6.12761
3323.64	15.545
3327.74	10.9643
3331.84	11.0801
3335.94	11.2196
3340.04	13.704
3344.13	9.04826
3348.22	13.8563
3352.3	35.3446
3356.39	9.242
3360.47	4.54565
3364.54	7.01421
3368.62	9.48895
3372.69	11.9721
3376.76	12.038
3380.83	16.9202
3384.89	14.5658
3388.96	17.0377
3393.02	12.2473
3397.07	19.5823
3401.13	17.2297
3405.18	17.2787
3409.23	5.17136
3413.27	14.9398
3417.31	14.9847
3421.36	12.5899
3425.39	24.8268
3429.43	10.2464
3433.46	7.86877
3437.49	15.2929
3441.52	10.4864
3445.54	13.053
3449.56	13.1856
3453.58	10.8533
3457.6	11.0116
3461.61	8.69564
3465.63	3.86926
3469.63	9.02828
3473.64	11.678
3477.64	1.75857
3481.64	1.88771
3485.64	14.6883
3489.64	9.7632
3493.63	12.4539
3497.62	17.6967
3501.61	5.03194
3505.59	10.2553
3509.58	7.76946
3513.56	2.69452
3517.53	7.89179
3521.51	15.6661
3525.48	8.01767
3529.45	8.08041
3533.42	8.17605
3537.38	5.71705
3541.34	3.25509
3545.3	13.7367
3549.26	6.05379
3553.21	3.51745
3557.16	8.79641
3561.11	1.07692
3565.06	19.4358
3569	9.13569
3572.94	22.3629
3576.88	12.0326
3580.82	17.467
3584.75	22.9431
3588.68	23.1507
3592.61	31.3269
3596.54	23.563
3600.46	23.755
3604.38	10.55
3608.3	5.32233
3612.21	13.512
3616.13	8.25907
3620.04	2.97702
3623.94	3.05509
3627.85	11.2359
3631.75	3.18222
3635.65	5.95256
3639.55	0.618778
3643.44	3.4352
3647.34	3.5544
3651.23	-1.82795
3655.12	6.41848
3659	9.21911
3662.88	3.82709
3666.76	3.89669
3670.64	6.70222
3674.52	9.51964
3678.39	1.39121
3682.26	9.73899
3686.13	4.36108
3689.99	4.48482
3693.85	1.83257
3697.71	10.2752
3701.57	7.61859
3705.43	2.14611
3709.28	13.4591
3713.13	2.35312
3716.98	-0.377203
3720.82	10.9789
3724.66	5.40613
3728.5	-0.195118
3732.34	11.2076
3736.18	2.75393
3740.01	2.80427
3743.84	-0.00655937
3747.67	2.87849
3751.49	2.89828
3755.32	2.90446
3759.14	5.76183
3762.96	2.88223
3766.77	5.72772
3770.58	5.71462
3774.4	5.7018
3778.2	11.435
3782.01	20.069
3785.81	-0.0874672
3789.61	2.77671
3793.41	11.4292
3797.21	20.124
3801	11.4404
3804.79	5.62888
3808.58	5.62134
3812.37	-0.242786
3816.15	5.56904
3819.93	5.52974
3823.71	5.47725
3827.49	-0.475655
3831.26	11.2431
3835.04	2.32402
3838.8	2.23536
3842.57	2.15147
3846.34	10.9371
3850.1	1.88744
3853.86	7.67358
3857.62	10.477
3861.37	7.31825
3865.12	10.1353
3868.87	4.06707
3872.62	0.906403
3876.37	-2.28506
3880.11	3.48148
3883.85	0.274689
3887.59	3.05062
3891.33	2.83111
3895.06	-0.376648
3898.79	2.40538
3902.52	-0.838459
3906.25	4.94658
3909.97	-4.37215
3913.69	-7.66487
3917.41	-1.87411
3921.13	-5.17313
3924.84	-5.44914
3928.56	3.41753
3932.27	-2.99695
3935.97	-0.266579
3939.68	-9.81048
3943.38	-7.08458
3947.08	-4.36228
3950.78	-4.73559
3954.48	-8.22112
3958.17	-5.54499
3961.86	-5.98546
3965.55	-0.245968
3969.24	-3.82733
3972.92	-13.6224
3976.6	-4.82823
3980.29	-5.35726
3983.96	-9.00889
3987.64	-12.6716
3991.31	-10.138
3994.98	-7.60217
3998.65	-11.2729