File: Data/3-Raman/processed/bu20-F-brt1-FI03-633-v.txt
#Acq. time (s)=	20
#Accumulations=	3
#Range (cm-¹)=	100...4000
#Windows=	1
#Auto scanning=	Off
#Autofocus=	Off
#Macrospot=	Off
#AutoExposure=	Off
#Spike filter=	Multiple accum.
#Delay time (s)=	0
#Binning=	1
#Readout mode=	Signal
#DeNoise=	Lite
#ICS correction=	Off
#Dark correction=	Off
#Inst. Process=	Off
#Detector temperature (°C)=	-60.09
#Instrument=	LabRAM HR Evol
#Detector=	SIN-EM FIVIS
#Objective=	x100_VIS
#Grating=	150 (500nm)
#ND Filter=	100%
#Laser=	633nm_Edge
#Hole=	30.0125
#Temperature=	0
#Range=	Visible
#StageXY=	75x50mm Scan+
#StageZ=	Z motor
#X (µm)=	7090.6
#Y (µm)=	-77.9
#Z (µm)=	1848.2
#Full time(mm:ss)=	1:05
#Project=	Buranga
#Sample=	BU18FA20_F
#Site=	F_Bertoss1
#Title=	20-F_brt1_FI03
#Remark=
#Date=	30.07.2019 16:11
#Acquired=	30.07.2019 16:11:02
#Data Range:Extract=	16.12.2021 15:36:30
#Base:Fit=	16.12.2021 15:36:40
#Base:Edit=	16.12.2021 15:40:28
#Base:Edit=	16.12.2021 15:40:28
#Base:Edit=	16.12.2021 15:40:29
#Base:Edit=	16.12.2021 15:40:29
#Base:Edit=	16.12.2021 15:40:30
#Base:Edit=	16.12.2021 15:40:31
#Base:Sub=	16.12.2021 15:40:34
100.38	80.382
106.898	70.415
113.411	54.4967
119.918	43.7527
126.419	39.2328
132.916	36.4574
139.407	36.1294
145.892	31.5927
152.372	24.5737
158.847	17.2946
165.316	17.8395
171.781	18.3124
178.239	12.3702
184.693	7.0989
191.139	2.15595
197.582	0.476166
204.02	1.77754
210.452	-0.401672
216.877	0.269073
223.299	4.11227
229.715	12.7362
236.126	35.5728
242.53	32.9989
248.931	19.4643
255.326	12.8122
261.714	12.4494
268.099	15.5513
274.477	21.0014
280.851	35.0218
287.218	46.5781
293.582	32.7955
299.939	16.4699
306.293	7.85162
312.639	6.29793
318.982	12.1846
325.318	41.4735
331.651	62.1965
337.977	38.5626
344.297	12.9622
350.614	8.53379
356.925	11.9603
363.23	15.4738
369.53	15.9635
375.827	13.4201
382.116	5.2465
388.401	0.32901
394.681	-0.242767
400.956	2.37908
407.226	5.10036
413.49	7.96152
419.749	13.0602
426.003	20.371
432.252	30.3437
438.496	39.4818
444.735	44.7354
450.969	38.8579
457.197	35.7949
463.421	29.9406
469.64	22.3963
475.853	13.646
482.062	9.23081
488.265	8.52234
494.464	7.08232
500.657	8.16606
506.844	13.0494
513.028	16.5571
519.206	17.6442
525.38	17.3621
531.548	15.8629
537.71	12.8654
543.869	10.9881
550.022	11.2278
556.169	10.9299
562.313	10.7183
568.452	10.5369
574.584	10.7916
580.713	11.251
586.837	13.8653
592.954	21.4353
599.068	40.3694
605.176	55.5098
611.28	27.2058
617.378	31.9816
623.473	34.3927
629.561	35.3376
635.644	38.6185
641.724	37.075
647.797	31.9525
653.867	35.5467
659.931	39.2636
665.99	37.9822
672.044	28.0019
678.095	13.9439
684.139	11.1813
690.179	9.23074
696.213	7.28683
702.245	5.24464
708.27	4.7372
714.29	4.97765
720.306	4.76941
726.316	5.04499
732.322	5.47038
738.323	7.22268
744.32	8.01069
750.311	5.53902
756.298	2.82514
762.28	3.54724
768.258	6.32425
774.23	6.98738
780.198	5.46639
786.161	1.18516
792.119	0.170666
798.073	4.52637
804.021	4.28814
809.965	4.44056
815.904	5.6239
821.839	6.87293
827.769	7.78955
833.693	6.95522
839.614	7.98722
845.53	8.03275
851.44	9.28675
857.346	7.92714
863.248	6.13515
869.144	8.22816
875.037	9.28085
880.924	9.94402
886.807	10.099
892.685	11.5279
898.559	10.4319
904.427	9.99643
910.292	9.80696
916.151	9.91476
922.006	11.064
927.856	12.7531
933.701	15.1078
939.543	17.6499
945.379	22.9339
951.21	29.7373
957.037	38.0518
962.861	45.1277
968.678	52.132
974.491	54.6757
980.3	85.1927
986.104	127.721
991.904	150.272
997.699	139.596
1003.49	107.786
1009.28	81.649
1015.06	86.81
1020.83	96.2985
1026.61	107.412
1032.37	86.0596
1038.14	60.8516
1043.9	43.8629
1049.65	35.8563
1055.4	32.6466
1061.15	27.9247
1066.88	22.9648
1072.62	25.3476
1078.35	31.2724
1084.08	37.305
1089.8	42.0612
1095.52	36.7543
1101.23	45.8174
1106.94	38.3887
1112.65	27.1504
1118.35	19.0778
1124.05	14.4095
1129.74	17.1406
1135.42	18.9625
1141.11	20.9467
1146.78	26.155
1152.46	32.0928
1158.13	31.8318
1163.79	24.2519
1169.45	14.8712
1175.11	9.99592
1180.76	7.19166
1186.41	7.44078
1192.05	8.54124
1197.69	9.19262
1203.32	9.67687
1208.95	8.57116
1214.58	7.69688
1220.2	5.55909
1225.82	4.33791
1231.43	6.72883
1237.04	8.53847
1242.64	8.02618
1248.24	8.3282
1253.83	7.53235
1259.42	7.68662
1265.01	8.8679
1270.59	1.0554
1276.17	11.0202
1281.74	21.6951
1287.31	15.9365
1292.88	5.73164
1298.44	4.76553
1303.99	5.10323
1309.55	6.32751
1315.09	6.51413
1320.64	6.53516
1326.18	5.55795
1331.71	3.29269
1337.24	3.64247
1342.77	6.03416
1348.29	5.34155
1353.81	3.82127
1359.32	5.21305
1364.83	6.08199
1370.33	6.37193
1375.84	8.32098
1381.33	17.359
1386.82	27.2481
1392.31	13.2091
1397.8	6.70666
1403.28	7.00324
1408.75	6.33986
1414.22	5.49867
1419.69	-1.15572
1425.15	7.46668
1430.61	6.26528
1436.07	4.45401
1441.52	4.82229
1446.96	5.95271
1452.41	6.5616
1457.84	7.07965
1463.28	4.86414
1468.71	4.85934
1474.13	4.91617
1479.55	6.86005
1484.97	7.21851
1490.39	5.42026
1495.79	2.57389
1501.2	3.20956
1506.6	4.93407
1512	4.53125
1517.39	4.43251
1522.78	4.18035
1528.16	4.5951
1533.54	5.9195
1538.92	6.03466
1544.29	5.89635
1549.66	5.73984
1555.02	4.67679
1560.38	2.89814
1565.74	1.79242
1571.09	5.42112
1576.44	6.76038
1581.78	5.74788
1587.12	4.521
1592.46	4.89042
1597.79	4.92531
1603.12	5.743
1608.44	5.43819
1613.76	6.01121
1619.08	7.30638
1624.39	9.6094
1629.7	10.03
1635	9.07627
1640.3	7.47401
1645.59	7.65802
1650.88	8.30326
1656.17	6.79739
1661.46	6.6579
1666.74	6.98492
1672.01	7.95183
1677.28	7.29342
1682.55	5.13142
1687.82	4.97917
1693.07	4.68613
1698.33	3.14047
1703.58	2.01072
1708.83	1.6271
1714.07	2.91631
1719.31	5.34748
1724.55	3.23197
1729.78	1.45983
1735.01	0.343254
1740.23	-0.0153847
1745.46	0.459332
1750.67	1.76165
1755.89	4.56987
1761.09	7.32172
1766.3	8.18473
1771.5	6.76841
1776.7	4.82889
1781.89	4.07734
1787.08	4.25469
1792.27	5.25409
1797.45	6.46836
1802.62	6.72491
1807.8	6.40842
1812.97	4.89518
1818.14	3.69986
1823.3	2.94132
1828.46	5.72686
1833.61	6.34791
1838.76	4.94154
1843.91	5.16054
1849.05	5.09156
1854.19	4.49237
1859.33	3.98355
1864.46	4.0141
1869.59	4.48833
1874.71	0.508087
1879.83	0.41404
1884.95	2.40292
1890.06	5.22303
1895.17	5.34826
1900.27	5.14474
1905.38	5.4722
1910.47	5.46179
1915.57	2.74836
1920.66	1.30039
1925.74	2.00552
1930.83	4.86325
1935.91	7.52109
1940.98	6.94047
1946.05	6.44165
1951.12	6.54208
1956.18	4.86384
1961.25	3.40956
1966.3	1.956
1971.35	3.87497
1976.4	5.13852
1981.45	3.03099
1986.49	6.12255
1991.53	5.18126
1996.56	4.72773
2001.59	5.5147
2006.62	5.39766
2011.64	3.57755
2016.66	2.53875
2021.68	3.43643
2026.69	5.51731
2031.7	4.34697
2036.7	5.81168
2041.7	5.50971
2046.7	3.3526
2051.7	1.69026
2056.69	2.91248
2061.67	2.97258
2066.65	3.00838
2071.63	4.39199
2076.61	4.93482
2081.58	4.88273
2086.55	3.68875
2091.51	3.32633
2096.47	4.74272
2101.43	6.21864
2106.39	4.49043
2111.34	2.09632
2116.28	1.64129
2121.23	2.09385
2126.17	2.34267
2131.1	3.13471
2136.03	4.07772
2140.96	4.33679
2145.89	3.74998
2150.81	2.34528
2155.73	2.04216
2160.64	3.86501
2165.55	4.63119
2170.46	0.646378
2175.36	2.37223
2180.26	3.69495
2185.16	0.942688
2190.05	-0.296684
2194.94	2.27831
2199.83	4.33321
2204.71	5.2236
2209.59	5.05635
2214.46	4.14867
2219.33	3.59586
2224.2	3.36524
2229.07	3.06993
2233.93	2.87646
2238.79	2.69455
2243.64	3.0789
2248.49	3.07227
2253.34	-2.00805
2258.18	-1.0178
2263.02	5.36727
2267.86	5.119
2272.69	3.91312
2277.52	3.84171
2282.35	2.48095
2287.17	1.90505
2291.99	3.85361
2296.8	5.83131
2301.62	5.63187
2306.43	2.92841
2311.23	3.65198
2316.03	4.13196
2320.83	3.80677
2325.63	1.85117
2330.42	1.51051
2335.21	5.37667
2339.99	6.45216
2344.77	6.18426
2349.55	3.67453
2354.32	2.26441
2359.1	3.12165
2363.86	5.04714
2368.63	5.58603
2373.39	5.3214
2378.15	2.37183
2382.9	1.56672
2387.65	4.43065
2392.4	5.45432
2397.14	5.52857
2401.88	4.1689
2406.62	4.57408
2411.35	5.11516
2416.08	4.19585
2420.81	3.28131
2425.53	3.52117
2430.25	5.11163
2434.97	2.55009
2439.69	4.6763
2444.4	3.49601
2449.1	5.50174
2453.81	5.6403
2458.51	5.74914
2463.2	7.66917
2467.9	7.83173
2472.59	5.51495
2477.27	2.15398
2481.96	3.72201
2486.64	4.87569
2491.31	5.61475
2495.99	8.02092
2500.66	7.25966
2505.32	6.27107
2509.99	4.26694
2514.65	4.95313
2519.31	6.19771
2523.96	5.35773
2528.61	5.08161
2533.26	3.3779
2537.9	3.43886
2542.54	5.32791
2547.18	5.85941
2551.81	3.77832
2556.44	2.92262
2561.07	2.1382
2565.69	5.62169
2570.32	6.56847
2574.93	7.26219
2579.55	7.09584
2584.16	6.56165
2588.77	5.07968
2593.37	4.12743
2597.97	4.43388
2602.57	4.78054
2607.17	4.58553
2611.76	-0.0115814
2616.35	-0.571236
2620.93	1.93893
2625.51	6.5453
2630.09	7.98486
2634.67	8.62154
2639.24	6.54014
2643.81	4.25961
2648.38	4.48915
2652.94	3.65812
2657.5	2.3047
2662.06	6.24722
2666.61	7.98284
2671.16	6.27151
2675.71	4.07368
2680.25	3.555
2684.79	5.0847
2689.33	3.50488
2693.86	3.4706
2698.39	2.92114
2702.92	3.65534
2707.45	6.4435
2711.97	8.32996
2716.49	7.95397
2721	5.9081
2725.51	4.21957
2730.02	4.09424
2734.53	4.92661
2739.03	5.93359
2743.53	6.33592
2748.03	5.95874
2752.52	4.59665
2757.01	3.88293
2761.5	4.37386
2765.98	6.04354
2770.46	6.70864
2774.94	7.6202
2779.42	7.14337
2783.89	6.30132
2788.36	4.69609
2792.82	5.34109
2797.28	5.84795
2801.74	3.00539
2806.2	4.99129
2810.65	0.562504
2815.1	2.92323
2819.55	6.40573
2823.99	6.54216
2828.43	4.68851
2832.87	3.56649
2837.3	4.1345
2841.74	6.38149
2846.17	8.1844
2850.59	7.38328
2855.01	5.33768
2859.43	3.88074
2863.85	6.16748
2868.26	5.84272
2872.67	6.11291
2877.08	5.99785
2881.48	3.52254
2885.89	2.38245
2890.28	6.13139
2894.68	7.16209
2899.07	7.92828
2903.46	7.71252
2907.85	3.27712
2912.23	4.66627
2916.61	4.90721
2920.98	6.5227
2925.36	7.83048
2929.73	7.56158
2934.1	7.75953
2938.46	5.88007
2942.82	3.05372
2947.18	1.93406
2951.54	6.24057
2955.89	8.53451
2960.24	9.12082
2964.59	5.98092
2968.93	1.08772
2973.27	1.86155
2977.61	3.79264
2981.95	3.30865
2986.28	2.97086
2990.61	3.61345
2994.94	3.56769
2999.26	4.12494
3003.58	4.32594
3007.9	5.16704
3012.21	5.87232
3016.52	5.62161
3020.83	5.93038
3025.14	3.89071
3029.44	2.89983
3033.74	2.76134
3038.04	3.50576
3042.33	3.08087
3046.62	2.50688
3050.91	2.23225
3055.2	1.35348
3059.48	1.62234
3063.76	4.60168
3068.03	7.45831
3072.31	6.41975
3076.58	4.43164
3080.85	2.32555
3085.11	2.28453
3089.37	1.46174
3093.63	-0.520584
3097.89	0.584049
3102.14	5.11785
3106.39	6.67278
3110.64	4.69189
3114.89	3.85087
3119.13	5.35895
3123.37	5.39167
3127.6	4.16543
3131.84	3.18857
3136.07	-4.29012
3140.29	0.0210457
3144.52	5.93032
3148.74	6.55482
3152.96	5.49005
3157.18	4.55132
3161.39	2.78802
3165.6	4.25967
3169.81	5.85497
3174.01	5.82014
3178.22	6.25499
3182.42	6.19286
3186.61	5.49091
3190.8	3.48197
3195	3.28369
3199.18	6.56124
3203.37	6.69183
3207.55	6.64455
3211.73	7.33989
3215.91	8.32329
3220.08	6.77467
3224.25	6.79378
3228.42	7.05268
3232.59	6.48064
3236.75	3.97521
3240.91	3.65741
3245.07	4.98824
3249.22	6.52224
3253.37	8.12748
3257.52	7.57392
3261.67	3.64074
3265.81	1.87841
3269.95	1.75838
3274.09	1.82838
3278.22	2.03327
3282.36	2.76732
3286.49	3.86268
3290.61	4.89411
3294.74	3.55062
3298.86	4.51678
3302.98	5.31536
3307.09	1.64754
3311.21	-0.25827
3315.32	-0.342148
3319.42	2.86791
3323.53	4.69293
3327.63	1.66925
3331.73	5.65796
3335.83	3.04934
3339.92	2.28119
3344.01	3.43916
3348.1	4.81482
3352.19	5.12354
3356.27	4.54972
3360.35	4.0728
3364.43	3.87936
3368.5	3.83469
3372.58	3.89114
3376.65	3.26212
3380.71	1.69736
3384.78	2.61015
3388.84	4.06609
3392.9	4.6022
3396.95	4.02158
3401.01	2.59947
3405.06	1.6631
3409.1	1.58089
3413.15	-0.37368
3417.19	2.2283
3421.23	4.06653
3425.27	5.72309
3429.31	4.62387
3433.34	3.48104
3437.37	5.02751
3441.39	7.09066
3445.42	6.89101
3449.44	4.25372
3453.46	3.24339
3457.47	3.61042
3461.49	6.50646
3465.5	4.20319
3469.51	3.29776
3473.51	4.1879
3477.52	3.34828
3481.52	1.02459
3485.51	2.09527
3489.51	3.08767
3493.5	5.01833
3497.49	5.53732
3501.48	3.34195
3505.46	1.88499
3509.45	1.49014
3513.43	3.3044
3517.4	4.13423
3521.38	2.85315
3525.35	1.7208
3529.32	-0.0177269
3533.28	0.864483
3537.25	1.87366
3541.21	1.78212
3545.17	2.74715
3549.12	3.39905
3553.08	2.51173
3557.03	0.406437
3560.98	0.00769043
3564.92	1.17439
3568.87	4.21136
3572.81	6.08513
3576.74	4.44765
3580.68	3.83443
3584.61	2.912
3588.54	3.83179
3592.47	5.8714
3596.4	6.59734
3600.32	3.48129
3604.24	2.63532
3608.16	1.64871
3612.07	1.26479
3615.98	1.15723
3619.89	1.03851
3623.8	-0.704479
3627.71	0.149414
3631.61	2.86798
3635.51	2.53332
3639.41	0.471581
3643.3	-1.47226
3647.19	-0.540462
3651.08	1.55219
3654.97	2.66251
3658.85	2.77556
3662.74	2.68721
3666.62	2.16063
3670.49	4.00095
3674.37	7.57807
3678.24	5.55688
3682.11	1.8831
3685.98	3.12608
3689.84	2.8582
3693.7	-0.522835
3697.56	-2.18054
3701.42	-1.46667
3705.28	1.49677
3709.13	1.77739
3712.98	0.723324
3716.82	-0.117416
3720.67	-0.890648
3724.51	-4.86261
3728.35	-1.60651
3732.19	1.55466
3736.02	1.01617
3739.86	-1.56297
3743.69	-2.51112
3747.51	-0.314308
3751.34	0.539669
3755.16	2.3279
3758.98	1.56019
3762.8	1.59517
3766.61	0.706985
3770.43	0.999554
3774.24	2.55092
3778.05	2.21389
3781.85	1.20535
3785.65	0.707508
3789.45	0.965038
3793.25	0.971832
3797.05	0.843586
3800.84	2.77665
3804.63	4.06534
3808.42	3.75589
3812.21	3.40348
3815.99	3.07896
3819.77	2.23552
3823.55	1.47398
3827.33	1.25957
3831.1	-0.548359
3834.87	-1.43552
3838.64	0.729782
3842.41	4.81536
3846.17	5.36195
3849.93	4.52859
3853.69	1.05548
3857.45	1.50365
3861.21	3.13558
3864.96	5.01484
3868.71	5.54541
3872.46	4.80243
3876.2	0.766975
3879.94	1.44567
3883.68	3.85003
3887.42	5.15942
3891.16	3.78705
3894.89	2.85558
3898.62	2.13203
3902.35	1.58472
3906.08	1.68066
3909.8	2.31918
3913.52	3.61132
3917.24	2.03056
3920.96	1.10244
3924.67	1.98797
3928.38	2.38491
3932.09	2.86632
3935.8	2.06434
3939.51	0.498867
3943.21	2.73884
3946.91	3.79608
3950.61	3.4999
3954.3	2.60272
3958	1.89696
3961.69	2.16172
3965.38	2.1918
3969.06	0.33012
3972.75	-1.1573
3976.43	0.755718
3980.11	0.755096
3983.78	1.20392
3987.46	1.75206
3991.13	-0.905552
3994.8	-1.08859
3998.47	4.3876