File: Data/3-Raman/processed/bu20-b-ff4-fi02-v_180 (450-850nm)_633nm_edge_100%_x100_vis_lwd_h30um_80sx4_01.txt
#Acq. time (s)=	80
#Accumulations=	4
#Range (cm-¹)=	1200...1449
#Windows=	1
#Auto scanning=	Off
#Autofocus=	Off
#Macrospot=	Off
#AutoExposure=	Off
#Spike filter=	Multiple accum.
#Delay time (s)=	2
#Binning=	1
#Readout mode=	Signal
#DeNoise=	Off
#ICS correction=	On
#Dark correction=	Off
#Inst. Process=	Off
#Detector Gain=	Best Dynamic
#Detector ADC=	50 kHz EM
#Detector EM gain=	150
#Detector temperature (°C)=	-60.09
#Instrument=	LabRAM HR Evol
#Detector=	SIN-EM FIVIS
#Objective=	x100_VIS_LWD
#Grating=	1800 (450-850nm)
#ND Filter=	100%
#Laser=	633nm_Edge
#Hole=	30.0125
#Temperature=	40
#Range=	Visible
#StageXY=	75x50mm Scan+
#StageZ=	Z motor
#X (µm)=	0
#Y (µm)=	0
#Z (µm)=	22.1
#Full time(mm:ss)=	5:25
#Project=	21_08_11
#Sample=	BU20
#Site=
#Title=	BU20-B-FF4-FI02-V_1800 (450-850nm)_633nm_Edge_100%_x100_VIS_LWD_H30um_80sX4
#Remark=
#Date=	13.08.2021 14:52
#Acquired=	13.08.2021 14:52:34
#Data Range:Extract=	16.12.2021 15:36:30
#Base:Fit=	16.12.2021 15:36:40
#Base:Fit=	16.12.2021 15:53:04
#Base:Sub=	16.12.2021 15:53:06
1200.07	-2.02246
1200.25	3.08069
1200.42	3.1561
1200.59	0.80777
1200.76	-4.34351
1200.93	-1.95139
1201.11	3.10367
1201.28	-2.27615
1201.45	-0.760529
1201.62	0.961609
1201.79	2.6467
1201.97	-2.19934
1202.14	2.1228
1202.31	0.752808
1202.48	2.90411
1202.65	0.39682
1202.83	2.80753
1203	1.99191
1203.17	-0.874634
1203.34	-0.767242
1203.51	2.53159
1203.69	2.7944
1203.86	-0.703064
1204.03	2.65103
1204.2	-0.582123
1204.37	-2.75339
1204.55	-2.29025
1204.72	-2.24857
1204.89	2.07501
1205.06	4.00574
1205.23	1.91608
1205.41	1.04282
1205.58	2.27557
1205.75	-1.51212
1205.92	1.41986
1206.09	0.799774
1206.26	5.82471
1206.44	-2.32593
1206.61	0.947113
1206.78	3.51343
1206.95	-1.82239
1207.12	4.51718
1207.3	-2.44275
1207.47	-2.89178
1207.64	1.14157
1207.81	1.40817
1207.98	4.06741
1208.16	-1.70743
1208.33	-0.175049
1208.5	4.30682
1208.67	-1.86826
1208.84	-2.58957
1209.02	-2.23547
1209.19	1.18301
1209.36	-0.490997
1209.53	4.13107
1209.7	-1.10004
1209.87	-1.49353
1210.05	1.89899
1210.22	0.193512
1210.39	-2.9725
1210.56	-1.45496
1210.73	-0.995178
1210.9	-2.41379
1211.08	-1.12994
1211.25	-3.14804
1211.42	0.177887
1211.59	-1.12946
1211.76	2.52792
1211.93	3.19983
1212.11	-0.739105
1212.28	0.0203247
1212.45	-0.705017
1212.62	0.499969
1212.79	-1.14273
1212.96	-1.72525
1213.13	1.69809
1213.31	0.602325
1213.48	-1.01752
1213.65	1.72641
1213.82	-1.76535
1213.99	-1.49677
1214.17	0.169556
1214.34	1.45462
1214.51	0.46228
1214.68	1.97345
1214.85	-0.193604
1215.02	-2.43677
1215.19	7.2616
1215.37	1.06406
1215.54	-0.860718
1215.71	-1.81827
1215.88	-1.16794
1216.05	-1.82733
1216.22	-2.27344
1216.4	2.84491
1216.57	-0.691193
1216.74	4.48795
1216.91	-0.318939
1217.08	12.5873
1217.25	-0.728149
1217.42	-2.35504
1217.6	3.71713
1217.77	3.50601
1217.94	2.8728
1218.11	0.987213
1218.28	5.25641
1218.45	1.45566
1218.62	0.707703
1218.79	3.58197
1218.97	2.55109
1219.14	-2.22632
1219.31	2.95798
1219.48	7.2739
1219.65	2.90598
1219.82	2.70728
1219.99	-1.48175
1220.17	3.63712
1220.34	3.76035
1220.51	2.19821
1220.68	-0.132446
1220.85	0.759735
1221.02	0.24884
1221.19	1.12604
1221.36	0.0417786
1221.53	0.327637
1221.71	-1.93723
1221.88	1.12982
1222.05	1.8241
1222.22	0.0272217
1222.39	2.55099
1222.56	2.18329
1222.73	1.42542
1222.91	2.84305
1223.08	1.19763
1223.25	-0.949829
1223.42	1.2254
1223.59	-1.20093
1223.76	0.00344849
1223.93	2.7113
1224.1	-1.26053
1224.28	0.0940552
1224.45	2.65704
1224.62	3.38434
1224.79	0.608856
1224.96	-3.31729
1225.13	0.821045
1225.3	3.25186
1225.47	-1.81757
1225.64	-3.18976
1225.82	7.2146
1225.99	4.18744
1226.16	-2.23615
1226.33	1.28128
1226.5	5.13879
1226.67	2.71722
1226.84	3.18915
1227.01	37.2576
1227.18	7.00006
1227.35	3.86682
1227.53	1.22012
1227.7	6.51779
1227.87	5.74753
1228.04	3.27808
1228.21	1.0654
1228.38	4.08673
1228.55	3.65192
1228.72	8.46136
1228.89	-0.287781
1229.06	7.10468
1229.23	3.59674
1229.41	5.70245
1229.58	2.10663
1229.75	2.73749
1229.92	5.52914
1230.09	14.3691
1230.26	5.92239
1230.43	-0.199982
1230.6	4.58728
1230.77	1.89261
1230.94	7.79904
1231.11	1.45746
1231.29	3.52451
1231.46	1.95975
1231.63	4.5574
1231.8	2.41516
1231.97	7.8002
1232.14	1.69067
1232.31	12.6605
1232.48	0.356415
1232.65	6.25
1232.82	-3.90665
1232.99	2.07498
1233.16	7.53619
1233.34	1.52689
1233.51	3.47681
1233.68	6.60611
1233.85	2.07779
1234.02	2.87445
1234.19	6.47903
1234.36	3.01654
1234.53	4.02148
1234.7	3.96179
1234.87	3.5834
1235.04	9.97028
1235.21	0.7164
1235.38	1.50388
1235.55	6.44116
1235.73	6.24472
1235.89	0.28949
1236.07	1.16217
1236.24	2.76889
1236.41	7.80368
1236.58	1.92795
1236.75	2.04544
1236.92	4.96368
1237.09	4.59476
1237.26	7.25519
1237.43	8.22021
1237.6	4.33871
1237.77	9.4071
1237.94	7.45877
1238.11	4.97153
1238.28	4.72729
1238.46	7.56949
1238.62	5.74689
1238.8	3.56714
1238.97	3.72281
1239.14	5.24808
1239.31	8.50723
1239.48	2.59268
1239.65	3.68066
1239.82	5.24731
1239.99	4.43835
1240.16	4.45789
1240.33	7.40616
1240.5	6.62646
1240.67	6.45834
1240.84	5.91736
1241.01	3.07062
1241.18	3.24414
1241.35	4.3804
1241.52	7.13696
1241.69	2.31693
1241.86	5.76395
1242.03	3.59561
1242.21	4.82129
1242.37	0.273285
1242.55	9.0928
1242.72	4.61411
1242.89	7.48477
1243.06	2.94019
1243.23	5.24316
1243.4	8.80978
1243.57	6.138
1243.74	3.99582
1243.91	5.46494
1244.08	4.17087
1244.25	4.05109
1244.42	7.28586
1244.59	5.56155
1244.76	7.97565
1244.93	-0.0855713
1245.1	5.06012
1245.27	7.21692
1245.44	4.24466
1245.61	9.38062
1245.78	3.83655
1245.95	5.82846
1246.12	4.91916
1246.29	6.95593
1246.46	6.95013
1246.63	8.28763
1246.8	8.6839
1246.97	9.25861
1247.14	4.01071
1247.31	5.57675
1247.48	7.65216
1247.65	5.14642
1247.82	7.1026
1247.99	3.58212
1248.16	9.41797
1248.33	7.56952
1248.5	6.06488
1248.67	10.4602
1248.84	7.55203
1249.01	4.57538
1249.18	-1.71173
1249.35	10.9126
1249.52	5.26047
1249.69	3.18326
1249.86	6.54898
1250.04	5.64368
1250.2	3.53473
1250.38	4.51849
1250.54	6.84146
1250.72	4.19342
1250.88	3.02621
1251.06	7.77164
1251.22	6.11536
1251.4	3.84448
1251.56	6.94418
1251.74	7.06119
1251.9	8.63779
1252.07	4.79379
1252.24	8.09509
1252.41	12.6186
1252.59	7.26489
1252.75	8.11481
1252.93	5.72659
1253.09	2.9827
1253.27	10.174
1253.43	4.37744
1253.6	7.31131
1253.77	2.87772
1253.94	6.79556
1254.11	7.09164
1254.28	3.75302
1254.45	4.09073
1254.62	11.1205
1254.79	1.83328
1254.96	6.69965
1255.13	9.3201
1255.3	5.77539
1255.47	6.11066
1255.64	3.11356
1255.81	7.94604
1255.98	27.7729
1256.15	11.5526
1256.32	7.02179
1256.49	9.22549
1256.66	6.14792
1256.83	9.75021
1257	7.66501
1257.17	6.53433
1257.34	10.8157
1257.51	13.0476
1257.68	11.5664
1257.85	12.2104
1258.02	8.58585
1258.19	10.5307
1258.36	9.80304
1258.53	9.55728
1258.7	8.69434
1258.87	9.13358
1259.04	6.45572
1259.21	13.2987
1259.38	11.8544
1259.55	7.21042
1259.72	8.23129
1259.89	17.0092
1260.06	7.36652
1260.23	8.41898
1260.39	11.6677
1260.56	9.64984
1260.73	10.6779
1260.9	12.0999
1261.07	13.3886
1261.24	10.6294
1261.41	13.4487
1261.58	13.403
1261.75	13.8116
1261.92	13.1418
1262.09	20.212
1262.26	14.2245
1262.43	19.0662
1262.6	15.4514
1262.77	23.1915
1262.94	22.2671
1263.11	25.3768
1263.28	27.1757
1263.45	21.4975
1263.62	23.2379
1263.79	15.1302
1263.95	20.7512
1264.13	13.9984
1264.29	12.3784
1264.46	21.2226
1264.63	15.8759
1264.8	12.2723
1264.97	13.2885
1265.14	9.03671
1265.31	14.9886
1265.48	15.742
1265.65	13.3015
1265.82	10.2212
1265.99	14.7695
1266.16	9.79498
1266.33	28.0544
1266.5	16.3091
1266.67	7.73669
1266.84	6.88843
1267	5.43271
1267.17	12.7306
1267.34	2.27841
1267.51	9.60349
1267.68	9.25174
1267.85	9.70184
1268.02	9.27844
1268.19	9.91391
1268.36	1.69986
1268.53	9.15067
1268.7	6.65536
1268.87	11.8923
1269.04	10.574
1269.21	12.2133
1269.37	5.30728
1269.54	9.14325
1269.71	4.3764
1269.88	8.20029
1270.05	6.45883
1270.22	8.58713
1270.39	3.61633
1270.56	11.6918
1270.73	9.86157
1270.9	3.62036
1271.07	11.11
1271.24	7.11057
1271.4	4.86176
1271.57	2.05612
1271.74	10.0676
1271.91	5.8291
1272.08	10.5891
1272.25	6.18814
1272.42	7.427
1272.59	2.25778
1272.76	7.61819
1272.93	6.03574
1273.1	5.95541
1273.26	10.0711
1273.43	5.51184
1273.6	7.05725
1273.77	16.1334
1273.94	9.54437
1274.11	3.03397
1274.28	6.71161
1274.45	5.60309
1274.62	7.92389
1274.79	6.30057
1274.95	4.03229
1275.12	7.08347
1275.29	9.83426
1275.46	5.58484
1275.63	17.5391
1275.8	9.8786
1275.97	6.39288
1276.14	5.80051
1276.31	9.08484
1276.48	7.39838
1276.64	7.15381
1276.81	5.57095
1276.98	8.14182
1277.15	10.2518
1277.32	6.45306
1277.49	11.2494
1277.66	11.2662
1277.83	5.27072
1278	11.4347
1278.16	7.7431
1278.33	12.5033
1278.5	16.0963
1278.67	15.2986
1278.84	13.2826
1279.01	12.7673
1279.18	15.4848
1279.35	15.8651
1279.52	11.7684
1279.69	14.5329
1279.85	13.6348
1280.02	15.2054
1280.19	17.0383
1280.36	29.4529
1280.53	28.1333
1280.7	24.3898
1280.87	28.4406
1281.03	40.2536
1281.2	43.0736
1281.37	64.0964
1281.54	62.8035
1281.71	75.3042
1281.88	97.1132
1282.05	127.829
1282.22	125.537
1282.38	193.267
1282.55	206.551
1282.72	262.472
1282.89	292.452
1283.06	318.559
1283.23	321.863
1283.4	322.152
1283.57	297.2
1283.73	306.012
1283.9	234.442
1284.07	203.027
1284.24	168.013
1284.41	130.877
1284.58	132.556
1284.75	72.1629
1284.91	78.736
1285.08	48.6707
1285.25	50.5481
1285.42	40.9774
1285.59	29.29
1285.76	28.2865
1285.93	23.598
1286.09	22.9013
1286.26	18.8192
1286.43	24.5526
1286.6	15.7486
1286.77	22.2075
1286.94	7.50168
1287.1	8.99133
1287.27	12.8963
1287.44	9.99152
1287.61	10.5607
1287.78	13.1745
1287.95	11.5604
1288.12	5.03021
1288.28	13.7009
1288.45	4.32648
1288.62	8.2392
1288.79	8.8472
1288.96	4.89386
1289.13	2.80228
1289.29	8.37256
1289.46	5.75314
1289.63	10.259
1289.8	5.36722
1289.97	7.07507
1290.14	10.288
1290.31	3.55771
1290.47	8.15948
1290.64	6.32217
1290.81	1.9216
1290.98	3.99869
1291.15	2.98346
1291.31	2.14972
1291.48	2.55023
1291.65	5.87735
1291.82	6.50113
1291.99	3.52887
1292.16	5.9184
1292.32	5.51462
1292.49	4.9516
1292.66	0.0881958
1292.83	-2.93097
1293	4.96472
1293.17	-0.118805
1293.33	0.548187
1293.5	2.93375
1293.67	7.88055
1293.84	-4.06781
1294.01	6.07736
1294.17	5.24347
1294.34	2.65234
1294.51	0.726807
1294.68	16.4169
1294.85	2.00095
1295.02	2.72467
1295.18	-1.09283
1295.35	7.23975
1295.52	1.47159
1295.69	-2.27377
1295.86	1.24911
1296.03	2.38629
1296.19	4.23749
1296.36	6.08499
1296.53	-0.184998
1296.7	2.00751
1296.86	-0.311249
1297.03	6.62915
1297.2	6.68735
1297.37	1.62842
1297.54	-3.4422
1297.7	-0.526398
1297.87	14.929
1298.04	2.17102
1298.21	0.570953
1298.38	-0.300018
1298.55	-2.36542
1298.71	2.92758
1298.88	-0.556
1299.05	13.5135
1299.22	1.69766
1299.39	-1.15857
1299.55	1.80518
1299.72	0.0503845
1299.89	1.52063
1300.06	2.09195
1300.23	5.78226
1300.39	4.47531
1300.56	0.483246
1300.73	2.42682
1300.9	-0.484833
1301.07	0.513855
1301.23	6.67221
1301.4	1.47433
1301.57	-0.00289917
1301.74	-1.47437
1301.9	0.0883484
1302.07	-1.11609
1302.24	7.20432
1302.41	1.80804
1302.58	-5.11615
1302.74	0.121246
1302.91	0.370209
1303.08	-0.324554
1303.25	2.83389
1303.42	-1.76999
1303.58	0.179901
1303.75	-4.2662
1303.92	-1.19943
1304.09	-0.413208
1304.25	2.26364
1304.42	0.936615
1304.59	0.128448
1304.76	-2.23672
1304.92	-1.31409
1305.09	-4.37848
1305.26	2.95392
1305.43	3.10645
1305.59	4.33224
1305.76	2.09341
1305.93	-6.41861
1306.1	1.45975
1306.27	-1.82306
1306.43	-5.65491
1306.6	-3.80341
1306.77	3.48886
1306.94	-0.137604
1307.1	-1.91812
1307.27	-0.610413
1307.44	-1.17252
1307.61	-4.67258
1307.78	0.10022
1307.94	0.921478
1308.11	-2.55551
1308.28	15.9798
1308.44	5.37418
1308.61	-0.19635
1308.78	18.3325
1308.95	0.360107
1309.12	1.10922
1309.28	-3.57001
1309.45	3.23129
1309.62	0.455353
1309.79	-2.04019
1309.95	-3.0007
1310.12	-1.98761
1310.29	-2.66296
1310.46	-0.435944
1310.62	-3.02408
1310.79	-4.79074
1310.96	-0.472473
1311.13	-1.15918
1311.29	-0.281464
1311.46	1.64587
1311.63	-5.12054
1311.79	1.45871
1311.96	-0.722534
1312.13	4.14001
1312.3	1.57434
1312.47	-5.23544
1312.63	3.87787
1312.8	3.51059
1312.97	-1.06079
1313.13	-1.26376
1313.3	0.917725
1313.47	1.35141
1313.64	0.395844
1313.8	-2.59793
1313.97	-0.683868
1314.14	-0.351044
1314.31	2.40353
1314.47	2.21393
1314.64	-6.81815
1314.81	0.556641
1314.98	-2.23627
1315.14	6.17651
1315.31	2.63803
1315.48	-1.91742
1315.64	5.14511
1315.81	0.276581
1315.98	4.21176
1316.15	0.436676
1316.31	-0.467468
1316.48	0.731903
1316.65	-1.01465
1316.82	-0.541321
1316.98	-3.0238
1317.15	-1.28607
1317.32	-1.15634
1317.48	6.01791
1317.65	4.94516
1317.82	-0.355255
1317.99	2.16614
1318.15	6.23221
1318.32	4.42328
1318.49	9.14682
1318.65	2.74899
1318.82	-3.52509
1318.99	22.5
1319.16	-0.634399
1319.32	-1.24399
1319.49	-4.88705
1319.66	5.05658
1319.82	0.493256
1319.99	-0.0256653
1320.16	-0.930664
1320.33	2.09103
1320.49	0.555511
1320.66	-6.00647
1320.83	4.58121
1320.99	3.80957
1321.16	0.661072
1321.33	0.420776
1321.5	5.72321
1321.66	11.0167
1321.83	3.28351
1322	7.21982
1322.16	3.8226
1322.33	-1.31598
1322.5	1.3147
1322.66	0.473358
1322.83	-1.15909
1323	2.01355
1323.17	5.20831
1323.33	1.98929
1323.5	5.28928
1323.67	3.56802
1323.83	2.91891
1324	2.16888
1324.17	11.0269
1324.33	-0.430786
1324.5	10.7789
1324.67	6.09869
1324.83	4.64307
1325	1.81467
1325.17	5.6864
1325.33	2.55188
1325.5	5.44427
1325.67	5.16742
1325.84	7.64169
1326	-1.17133
1326.17	-0.269135
1326.34	5.49866
1326.5	2.74908
1326.67	-1.32745
1326.84	7.41293
1327	-2.44843
1327.17	7.37231
1327.34	2.37009
1327.5	6.07822
1327.67	2.78799
1327.84	2.08646
1328	5.69266
1328.17	6.00665
1328.34	5.17908
1328.5	5.00821
1328.67	3.51208
1328.84	1.04572
1329	6.69394
1329.17	2.4249
1329.34	4.47952
1329.5	7.70831
1329.67	2.23868
1329.84	4.13663
1330	0.0767517
1330.17	1.37949
1330.34	3.99866
1330.5	6.24283
1330.67	4.26852
1330.84	0.0238342
1331	4.43848
1331.17	4.75055
1331.34	0.639496
1331.5	8.02911
1331.67	3.84711
1331.84	-0.233368
1332	7.61328
1332.17	8.59354
1332.34	-0.442719
1332.5	9.29276
1332.67	5.01157
1332.84	8.60965
1333	3.34894
1333.17	4.40393
1333.34	4.56433
1333.5	6.72226
1333.67	11.2385
1333.84	4.37436
1334	2.31467
1334.17	4.88354
1334.34	12.2817
1334.5	2.00809
1334.67	2.93951
1334.83	6.81152
1335	1.0582
1335.17	2.86661
1335.33	9.10574
1335.5	11.5192
1335.67	8.28275
1335.83	9.28311
1336	1.74622
1336.17	-3.48499
1336.33	6.98413
1336.5	4.04657
1336.66	9.1098
1336.83	6.931
1337	2.72729
1337.16	7.7045
1337.33	12.8872
1337.5	5.13028
1337.66	7.32092
1337.83	9.4491
1338	17.3875
1338.16	14.0828
1338.33	20.3688
1338.49	7.77744
1338.66	8.28473
1338.83	4.15054
1338.99	3.95718
1339.16	6.41461
1339.33	4.17859
1339.49	6.29227
1339.66	3.27213
1339.83	9.78568
1339.99	2.33344
1340.16	6.59268
1340.32	3.00244
1340.49	10.8312
1340.66	3.0954
1340.82	4.47714
1340.99	3.67502
1341.15	8.26547
1341.32	5.10233
1341.49	10.3203
1341.65	6.17352
1341.82	4.24588
1341.99	1.5264
1342.15	3.85394
1342.32	10.1946
1342.48	8.31866
1342.65	4.52823
1342.82	9.90582
1342.98	7.17996
1343.15	1.73727
1343.32	4.99805
1343.48	5.71802
1343.65	0.40155
1343.81	5.48538
1343.98	3.52017
1344.14	8.20529
1344.31	9.00275
1344.48	9.54324
1344.64	3.48431
1344.81	11.9956
1344.98	9.62186
1345.14	16.9854
1345.31	8.16013
1345.47	45.8091
1345.64	7.88754
1345.8	10.5285
1345.97	12.2224
1346.14	7.07455
1346.3	9.53882
1346.47	2.55334
1346.64	6.27994
1346.8	2.97931
1346.97	4.99527
1347.13	8.31906
1347.3	5.20264
1347.46	6.54425
1347.63	9.73547
1347.8	11.301
1347.96	6.42142
1348.13	8.73865
1348.29	6.92038
1348.46	3.97437
1348.63	10.8847
1348.79	6.07468
1348.96	4.46188
1349.12	0.705902
1349.29	11.7769
1349.45	21.2617
1349.62	7.62341
1349.79	10.4222
1349.95	11.3178
1350.12	2.42249
1350.28	5.76648
1350.45	5.93845
1350.62	6.97696
1350.78	3.75027
1350.95	19.4488
1351.11	9.97357
1351.28	7.17523
1351.44	11.4254
1351.61	5.9845
1351.78	10.6317
1351.94	6.48282
1352.11	3.44727
1352.27	12.4325
1352.44	6.98343
1352.6	12.991
1352.77	8.27148
1352.94	5.4812
1353.1	5.57861
1353.27	2.45874
1353.43	11.7714
1353.6	0.352875
1353.76	5.51413
1353.93	6.33984
1354.1	8.56561
1354.26	9.59918
1354.43	8.74127
1354.59	5.18176
1354.76	6.02493
1354.92	13.0652
1355.09	10.5722
1355.26	9.05072
1355.42	9.74646
1355.59	2.21243
1355.75	10.735
1355.92	7.28973
1356.08	6.85666
1356.25	8.99747
1356.41	7.61743
1356.58	6.47394
1356.74	15.8991
1356.91	4.76736
1357.08	8.85135
1357.24	13.4254
1357.41	7.37073
1357.57	10.1381
1357.74	15.8771
1357.9	13.3666
1358.07	8.30942
1358.23	5.72165
1358.4	8.2771
1358.57	12.7034
1358.73	6.86832
1358.9	7.9061
1359.06	8.09674
1359.23	7.98892
1359.39	12.437
1359.56	8.01059
1359.72	10.1905
1359.89	9.27942
1360.05	12.3683
1360.22	7.98648
1360.38	9.01474
1360.55	6.23312
1360.72	9.29248
1360.88	7.16031
1361.05	3.97763
1361.21	6.5957
1361.38	4.88211
1361.54	3.24268
1361.71	6.08112
1361.87	8.99271
1362.04	7.76361
1362.2	7.03677
1362.37	3.69882
1362.53	13.1736
1362.7	7.65759
1362.86	10.7336
1363.03	10.1502
1363.19	8.7287
1363.36	6.84503
1363.53	6.51328
1363.69	7.1991
1363.86	7.25064
1364.02	13.5565
1364.19	12.2685
1364.35	13.4877
1364.52	9.45355
1364.68	10.4563
1364.85	9.67148
1365.01	8.73877
1365.18	7.48047
1365.34	7.73309
1365.51	10.7993
1365.67	12.1349
1365.84	9.41101
1366	10.6198
1366.17	10.2278
1366.33	7.78268
1366.5	9.62006
1366.66	7.72147
1366.83	6.83951
1366.99	13.4122
1367.16	9.29752
1367.32	12.1928
1367.49	9.34821
1367.65	9.95236
1367.82	6.08856
1367.98	16.0645
1368.15	8.30695
1368.31	12.3438
1368.48	17.5956
1368.64	15.5297
1368.81	10.4934
1368.97	18.8216
1369.14	24.0083
1369.3	26.0256
1369.47	25.2684
1369.63	23.2238
1369.8	13.1803
1369.96	15.2371
1370.13	11.415
1370.29	9.72949
1370.46	13.679
1370.62	14.8019
1370.79	13.2562
1370.95	4.18405
1371.12	9.41208
1371.28	6.64828
1371.45	3.61316
1371.61	14.9988
1371.78	9.76813
1371.94	8.29877
1372.11	2.45044
1372.27	10.0608
1372.44	3.34766
1372.6	6.68472
1372.77	9.57532
1372.93	6.63364
1373.1	8.07962
1373.26	14.3788
1373.43	15.3893
1373.59	21.5291
1373.76	7.11319
1373.92	14.3068
1374.09	6.41302
1374.25	11.5289
1374.42	11.4312
1374.58	11.2601
1374.75	8.39618
1374.91	10.6646
1375.07	6.88278
1375.24	34.3636
1375.4	9.90942
1375.57	8.49875
1375.73	13.9327
1375.9	14.7819
1376.06	11.1287
1376.23	10.4224
1376.39	4.09799
1376.56	14.8272
1376.72	13.926
1376.89	14.0256
1377.05	13.7368
1377.22	9.94424
1377.38	7.76617
1377.55	33.2851
1377.71	9.45456
1377.87	11.0699
1378.04	4.72318
1378.2	18.073
1378.37	13.0147
1378.53	7.92905
1378.7	8.21286
1378.86	4.13568
1379.03	9.14359
1379.19	6.62137
1379.36	5.2836
1379.52	10.6953
1379.68	14.0877
1379.85	11.0319
1380.01	8.63852
1380.18	8.12122
1380.34	15.296
1380.51	18.867
1380.67	13.5465
1380.84	16.3951
1381	18.6753
1381.17	12.2506
1381.33	8.43497
1381.49	12.8683
1381.66	13.6634
1381.82	19.7079
1381.99	16.0306
1382.15	13.7238
1382.32	18.8948
1382.48	11.5792
1382.64	15.0319
1382.81	18.731
1382.97	21.9179
1383.14	20.5004
1383.3	26.7562
1383.47	25.5518
1383.63	19.0314
1383.8	25.0645
1383.96	29.928
1384.12	29.3975
1384.29	31.5019
1384.45	45.3204
1384.62	51.4539
1384.78	38.0128
1384.95	54.0048
1385.11	75.6462
1385.28	70.3251
1385.44	66.4649
1385.6	96.8205
1385.77	113.042
1385.93	144.905
1386.1	183.449
1386.26	227.579
1386.42	316.711
1386.59	399.308
1386.75	550.166
1386.92	660.688
1387.08	693.329
1387.25	737.368
1387.41	642.6
1387.57	566.077
1387.74	438.002
1387.9	286.373
1388.07	222.022
1388.23	160.1
1388.4	150.221
1388.56	102.118
1388.72	72.7084
1388.89	67.3904
1389.05	56.2749
1389.22	52.2211
1389.38	42.57
1389.54	30.4328
1389.71	43.5192
1389.87	27.512
1390.04	27.5252
1390.2	25.3783
1390.37	24.6799
1390.53	21.8369
1390.69	19.1364
1390.86	22.8671
1391.02	12.8392
1391.19	12.7273
1391.35	11.3427
1391.51	12.9332
1391.68	17.1204
1391.84	15.3293
1392.01	15.1382
1392.17	6.98044
1392.33	14.8287
1392.5	17.265
1392.66	18.6532
1392.83	12.4934
1392.99	13.1237
1393.15	13.599
1393.32	11.6563
1393.48	4.44812
1393.65	12.9981
1393.81	15.7805
1393.97	14.2072
1394.14	11.7003
1394.3	7.59933
1394.46	15.9762
1394.63	11.1092
1394.79	6.99484
1394.96	9.31732
1395.12	9.24579
1395.28	10.7008
1395.45	4.17752
1395.61	11.4209
1395.78	9.20844
1395.94	12.9103
1396.1	12.702
1396.27	5.52588
1396.43	10.9607
1396.6	10.0368
1396.76	15.5667
1396.92	6.84424
1397.09	11.5053
1397.25	13.2946
1397.41	-1.0412
1397.58	8.72998
1397.74	8.51523
1397.91	7.21725
1398.07	9.70804
1398.23	12.6337
1398.4	3.48694
1398.56	4.81686
1398.72	13.0588
1398.89	6.32782
1399.05	6.60117
1399.21	10.4546
1399.38	4.28415
1399.54	9.01834
1399.71	7.86877
1399.87	2.51187
1400.03	9.61829
1400.2	10.1217
1400.36	3.23682
1400.52	4.78503
1400.69	4.82034
1400.85	8.02557
1401.02	3.27859
1401.18	2.14548
1401.34	7.64279
1401.51	6.87228
1401.67	5.3382
1401.83	7.65094
1402	12.582
1402.16	7.38669
1402.32	4.10458
1402.49	10.2271
1402.65	2.67682
1402.82	7.54907
1402.98	10.4796
1403.14	9.68271
1403.31	7.32947
1403.47	12.5796
1403.63	4.67633
1403.8	8.49933
1403.96	7.54529
1404.12	7.20166
1404.29	6.45819
1404.45	7.0842
1404.61	6.90082
1404.78	3.73453
1404.94	9.23337
1405.1	8.8573
1405.27	9.056
1405.43	10.7999
1405.59	9.43192
1405.76	19.1312
1405.92	15.5555
1406.08	13.8746
1406.25	6.70239
1406.41	12.7672
1406.57	18.5753
1406.74	18.5439
1406.9	7.86765
1407.06	22.9186
1407.23	17.3047
1407.39	20.6863
1407.56	21.7513
1407.72	31.2444
1407.88	22.7535
1408.04	30.0224
1408.21	36.996
1408.37	31.5253
1408.54	35.2343
1408.7	38.8696
1408.86	33.1653
1409.02	30.5123
1409.19	29.4659
1409.35	26.3191
1409.51	32.3724
1409.68	23.1688
1409.84	16.4855
1410	36.0992
1410.17	8.98773
1410.33	12.5602
1410.49	14.7065
1410.66	10.077
1410.82	18.3188
1410.98	4.25497
1411.15	11.5891
1411.31	8.67212
1411.47	6.86279
1411.64	4.65775
1411.8	3.30609
1411.96	2.14398
1412.13	8.68033
1412.29	3.0921
1412.45	5.03113
1412.62	5.7988
1412.78	3.62216
1412.94	8.55807
1413.1	2.42578
1413.27	1.33508
1413.43	4.43289
1413.59	4.30029
1413.76	3.86118
1413.92	-2.71152
1414.08	0.35025
1414.25	5.45206
1414.41	2.93893
1414.57	9.00894
1414.73	4.13068
1414.9	-2.70425
1415.06	3.76196
1415.22	12.3658
1415.39	3.04102
1415.55	4.56003
1415.71	4.42404
1415.88	13.4004
1416.04	10.1004
1416.2	-2.3811
1416.37	2.073
1416.53	0.509918
1416.69	1.75827
1416.85	5.80258
1417.02	6.18375
1417.18	0.684692
1417.34	3.92813
1417.51	3.76489
1417.67	-1.56693
1417.83	1.94455
1417.99	-3.89557
1418.16	1.1673
1418.32	1.25424
1418.48	-1.18591
1418.65	3.84634
1418.81	0.0213013
1418.97	-1.54022
1419.13	1.66452
1419.3	-2.9534
1419.46	10.7323
1419.62	-2.3154
1419.79	2.6658
1419.95	-0.504761
1420.11	3.4581
1420.27	1.92313
1420.44	2.61142
1420.6	3.36392
1420.76	0.457062
1420.93	3.13864
1421.09	-1.25296
1421.25	3.84744
1421.41	1.00922
1421.58	-0.133575
1421.74	3.81226
1421.9	4.43674
1422.06	0.629852
1422.23	2.5766
1422.39	6.58347
1422.55	4.62756
1422.72	-0.0484314
1422.88	1.13852
1423.04	3.9393
1423.2	1.20407
1423.37	2.01538
1423.53	1.5798
1423.69	11.701
1423.85	1.39316
1424.02	1.30356
1424.18	-3.97827
1424.34	3.91812
1424.5	-0.42099
1424.67	-1.1275
1424.83	3.4433
1424.99	-1.30545
1425.16	-1.37433
1425.32	-1.44711
1425.48	-1.07938
1425.64	2.05499
1425.81	-0.267517
1425.97	1.77313
1426.13	-5.51184
1426.29	-0.109741
1426.46	0.0473633
1426.62	1.93082
1426.78	1.18143
1426.94	-1.07999
1427.11	3.20953
1427.27	0.587128
1427.43	0.529358
1427.59	0.627319
1427.76	1.73468
1427.92	8.39023
1428.08	2.76013
1428.24	0.0482178
1428.41	1.1113
1428.57	5.39215
1428.73	1.09805
1428.89	4.82788
1429.05	1.76468
1429.22	2.58655
1429.38	-2.67752
1429.54	-0.880798
1429.7	0.947571
1429.87	1.43039
1430.03	3.96707
1430.19	5.16281
1430.35	1.40128
1430.52	1.64786
1430.68	-3.56857
1430.84	1.01758
1431	-0.0821838
1431.17	-1.21085
1431.33	3.47797
1431.49	1.05273
1431.65	2.92252
1431.81	1.15805
1431.98	-1.07434
1432.14	-1.09805
1432.3	0.408783
1432.46	0.0375366
1432.63	-3.86502
1432.79	0.428497
1432.95	0.116699
1433.11	-3.48611
1433.28	3.9765
1433.44	-2.66122
1433.6	-1.05573
1433.76	-0.0454102
1433.92	-1.00595
1434.09	-2.57321
1434.25	3.67596
1434.41	-2.48206
1434.57	0.650757
1434.74	0.447723
1434.9	0.333313
1435.06	-0.332733
1435.22	5.99161
1435.38	-1.67679
1435.55	2.16159
1435.71	0.756775
1435.87	1.65277
1436.03	-2.37811
1436.2	-2.56583
1436.36	6.93192
1436.52	2.9754
1436.68	-1.01077
1436.84	3.92123
1437.01	-4.56494
1437.17	1.138
1437.33	-0.194672
1437.49	-1.20032
1437.65	-3.83273
1437.82	1.14172
1437.98	1.18558
1438.14	-1.11569
1438.3	-3.2218
1438.46	1.77405
1438.63	0.537842
1438.79	3.89902
1438.95	3.23361
1439.11	0.810028
1439.27	-0.337006
1439.44	0.460358
1439.6	0.0553284
1439.76	-0.0324402
1439.92	-2.24081
1440.08	-1.63467
1440.25	-0.454803
1440.41	3.56741
1440.57	-0.641113
1440.73	-3.19174
1440.89	3.12411
1441.06	3.63806
1441.22	3.53531
1441.38	-1.70651
1441.54	-0.548584
1441.7	-0.453857
1441.86	1.0148
1442.03	0.754425
1442.19	-3.77734
1442.35	-3.92136
1442.51	-1.19101
1442.67	-1.46466
1442.84	3.99268
1443	-2.785
1443.16	0.359436
1443.32	-0.334961
1443.48	-1.7171
1443.64	0.179352
1443.81	-1.46579
1443.97	-2.1539
1444.13	1.81116
1444.29	-1.16428
1444.45	0.239868
1444.62	-0.339539
1444.78	0.0893555
1444.94	0.775177
1445.1	3.88419
1445.26	-2.50711
1445.42	19.1875
1445.59	-0.392548
1445.75	-0.0131836
1445.91	3.55231
1446.07	3.21011
1446.23	-0.463776
1446.39	7.18011
1446.56	1.15564
1446.72	12.2024
1446.88	0.00360107
1447.04	-2.50211
1447.2	3.29327
1447.36	-0.465424
1447.53	-2.48795
1447.69	-1.68747
1447.85	1.24243
1448.01	-0.217529
1448.17	1.8783
1448.33	0.430939
1448.49	1.89832
1448.66	1.85803
1448.82	3.93152
1448.98	0.59845
1449.14	-1.13129
1449.3	0.981628
1449.46	0.873657
1449.63	0.458618
1449.79	-3.81976
1449.95	-1.46707