File: Data/3-Raman/processed/bu20-b-ff4-fi03-v_150 (500nm)_633nm_edge_100%_x100_vis_lwd_h30um_60sx4_01.txt
#Acq. time (s)=	60
#Accumulations=	4
#Range (cm-¹)=	100...4000
#Windows=	1
#Auto scanning=	Off
#Autofocus=	Off
#Macrospot=	Off
#AutoExposure=	Off
#Spike filter=	Multiple accum.
#Delay time (s)=	2
#Binning=	1
#Readout mode=	Signal
#DeNoise=	Off
#ICS correction=	On
#Dark correction=	Off
#Inst. Process=	Off
#Detector Gain=	Best Dynamic
#Detector ADC=	50 kHz HS
#Detector temperature (°C)=	-60.09
#Instrument=	LabRAM HR Evol
#Detector=	SIN-EM FIVIS
#Objective=	x100_VIS_LWD
#Grating=	150 (500nm)
#ND Filter=	100%
#Laser=	633nm_Edge
#Hole=	30.0125
#Temperature=	40
#Range=	Visible
#StageXY=	75x50mm Scan+
#StageZ=	Z motor
#X (µm)=	0
#Y (µm)=	0
#Z (µm)=	450.4
#Full time(mm:ss)=	4:05
#Project=	21_08_11
#Sample=	BU20
#Site=
#Title=	BU20-B-FF4-FI03-V_150 (500nm)_633nm_Edge_100%_x100_VIS_LWD_H30um_60sX4
#Remark=
#Date=	13.08.2021 14:15
#Acquired=	13.08.2021 14:15:56
#Data Range:Extract=	16.12.2021 15:36:30
#Base:Fit=	16.12.2021 15:36:40
#Base:Edit=	16.12.2021 15:53:26
#Base:Edit=	16.12.2021 15:53:27
#Base:Edit=	16.12.2021 15:53:28
#Base:Edit=	16.12.2021 15:53:29
#Base:Edit=	16.12.2021 15:53:31
#Base:Sub=	16.12.2021 15:53:34
100.12	199.907
106.638	146.21
113.152	116.14
119.66	92.7652
126.162	62.749
132.659	57.6469
139.151	46.5114
145.637	33.5526
152.118	23.8727
158.594	17.1717
165.064	13.4186
171.529	9.37668
177.989	1.187
184.441	2.89958
190.89	1.41251
197.334	2.84579
203.772	3.47958
210.205	2.57391
216.631	3.93491
223.054	15.4885
229.471	45.376
235.881	60.6666
242.288	29.4345
248.689	16.716
255.083	16.6429
261.474	26.4222
267.858	32.4394
274.238	68.8504
280.613	79.9835
286.982	63.263
293.346	38.9422
299.704	19.0838
306.058	10.9166
312.406	18.2088
318.749	49.1011
325.086	79.091
331.418	49.0313
337.746	21.1878
344.068	18.5
350.384	19.2458
356.697	23.7231
363.003	34.757
369.304	21.954
375.601	12.6144
381.892	6.42333
388.177	2.20426
394.457	9.65531
400.733	6.8758
407.004	6.27254
413.269	16.3429
419.529	20.7123
425.784	32.2111
432.034	49.3808
438.279	56.7048
444.518	52.0696
450.753	48.3316
456.982	45.581
463.207	28.9595
469.426	19.9227
475.64	14.3755
481.85	12.5873
488.054	16.3677
494.253	12.3884
500.447	13.678
506.635	12.8105
512.819	17.237
518.999	16.4028
525.173	16.2463
531.342	18.3229
537.505	17.3074
543.664	13.695
549.819	13.735
555.966	16.2697
562.111	12.3505
568.25	8.34332
574.383	14.5953
580.513	12.6446
586.636	25.0779
592.756	45.3185
598.871	60.0381
604.979	47.34
611.084	43.0729
617.183	44.1857
623.277	46.2914
629.367	42.4074
635.451	33.5533
641.532	40.2229
647.606	44.2447
653.675	48.8348
659.741	52.0736
665.801	36.6182
671.856	26.2827
677.907	15.8605
683.952	14.1437
689.992	10.3375
696.028	3.14426
702.059	11.8584
708.086	11.1672
714.107	10.0039
720.123	8.47784
726.135	5.06034
732.141	6.88248
738.143	8.06823
744.14	5.52385
750.133	-1.64535
756.12	3.98521
762.103	11.931
768.081	10.359
774.054	1.60075
780.023	4.66817
785.987	11.7607
791.946	2.16917
797.9	10.4304
803.848	-0.24057
809.793	5.39234
815.733	9.07246
821.669	0.200821
827.6	7.87929
833.525	10.9733
839.446	4.86203
845.363	9.44302
851.273	1.86149
857.181	10.8957
863.083	7.73264
868.98	7.70597
874.874	6.02724
880.761	7.75263
886.645	9.43263
892.523	7.26344
898.398	5.67283
904.267	13.1338
910.133	12.053
915.992	13.8034
921.849	14.4092
927.699	13.8738
933.545	16.8935
939.387	26.0526
945.224	38.4938
951.056	39.9799
956.884	47.4698
962.708	55.8736
968.526	62.6252
974.34	88.483
980.149	118.912
985.955	157.086
991.755	139.27
997.551	106.546
1003.34	91.8075
1009.13	94.7042
1014.91	113.429
1020.69	135.065
1026.46	115.207
1032.23	76.7863
1037.99	54.5814
1043.75	38.6827
1049.51	31.382
1055.26	24.6108
1061	26.8086
1066.74	27.2729
1072.48	33.5418
1078.21	38.4718
1083.94	46.6004
1089.67	49.58
1095.38	55.4753
1101.1	51.0364
1106.81	26.0766
1112.51	15.9839
1118.22	14.4872
1123.91	9.01072
1129.6	19.1283
1135.29	19.8435
1140.98	23.1791
1146.65	32.3546
1152.33	41.196
1158	18.7321
1163.66	7.32431
1169.32	9.33894
1174.98	10.6861
1180.63	5.84439
1186.28	1.09182
1191.93	4.22495
1197.56	4.50922
1203.2	3.58622
1208.83	1.07513
1214.46	2.84937
1220.08	3.68816
1225.69	0.891811
1231.31	2.38924
1236.92	2.50614
1242.52	4.23128
1248.12	9.92337
1253.72	22.2985
1259.31	22.1222
1264.89	13.4769
1270.48	42.1078
1276.05	246.409
1281.63	56.7935
1287.2	7.1008
1292.76	14.9041
1298.33	6.43834
1303.88	11.0162
1309.43	4.6811
1314.98	7.10856
1320.53	4.86659
1326.07	6.68521
1331.6	6.83568
1337.13	5.59042
1342.66	4.29036
1348.18	5.3248
1353.7	9.0793
1359.22	14.5147
1364.73	14.7659
1370.23	19.4225
1375.73	114.8
1381.23	358.968
1386.72	40.1758
1392.21	15.4115
1397.7	25.6414
1403.18	37.9745
1408.65	15.6866
1414.13	8.8238
1419.59	1.25884
1425.06	2.65822
1430.52	1.29514
1435.97	-1.47039
1441.42	-0.427742
1446.87	5.51384
1452.31	2.32206
1457.75	-0.919559
1463.19	-1.7478
1468.62	3.35222
1474.04	3.90421
1479.46	-3.21558
1484.88	3.67637
1490.3	0.791824
1495.7	-1.36914
1501.11	-0.00498199
1506.51	3.49557
1511.91	6.32891
1517.3	5.65267
1522.69	3.20297
1528.08	-1.0449
1533.46	3.29056
1538.83	3.66
1544.21	2.90556
1549.58	2.05498
1554.94	4.37319
1560.3	4.14183
1565.66	7.15937
1571.01	1.18597
1576.36	4.92074
1581.7	6.90472
1587.04	4.59648
1592.38	3.02255
1597.71	9.38273
1603.04	2.45643
1608.37	8.89028
1613.68	1.2836
1619	6.01092
1624.31	4.93613
1629.62	4.94427
1634.93	2.72078
1640.23	2.9813
1645.52	3.60065
1650.81	3.46564
1656.1	3.67857
1661.39	6.08167
1666.67	2.92906
1671.94	3.83344
1677.22	2.8785
1682.48	3.02166
1687.75	0.919888
1693.01	1.05093
1698.26	0.119255
1703.52	3.78512
1708.77	1.92158
1714.01	1.62764
1719.25	6.37857
1724.49	6.97741
1729.72	4.61197
1734.95	5.60552
1740.18	4.34111
1745.4	7.96018
1750.61	4.78334
1755.83	4.59694
1761.04	-0.529613
1766.24	1.88592
1771.44	4.68869
1776.64	2.58967
1781.84	3.16138
1787.02	5.64376
1792.21	8.15857
1797.39	6.49794
1802.57	4.84608
1807.75	3.17928
1812.92	13.3778
1818.08	1.69281
1823.25	7.68788
1828.41	0.961777
1833.56	3.5034
1838.71	9.93612
1843.86	3.1407
1849	0.596699
1854.14	8.1726
1859.28	4.45311
1864.41	4.25665
1869.54	4.84816
1874.67	1.4809
1879.79	3.99604
1884.9	6.50782
1890.02	4.27174
1895.13	0.824764
1900.23	3.30799
1905.34	2.29618
1910.43	0.11414
1915.53	3.91663
1920.62	8.85662
1925.71	2.66039
1930.79	5.22977
1935.87	9.40061
1940.94	7.95802
1946.02	2.88397
1951.08	0.99659
1956.15	6.3197
1961.21	10.0301
1966.27	6.49919
1971.32	5.75706
1976.37	5.4106
1981.42	4.26129
1986.46	2.31316
1991.5	3.17715
1996.53	2.04322
2001.56	5.32806
2006.59	3.41805
2011.61	5.12891
2016.63	6.8443
2021.65	4.53267
2026.66	1.83938
2031.67	3.98907
2036.68	5.35241
2041.68	3.48705
2046.68	1.61935
2051.67	5.83782
2056.66	5.97821
2061.65	3.2899
2066.63	3.0425
2071.61	6.47195
2076.59	6.21949
2081.56	5.54554
2086.53	4.85258
2091.49	4.15409
2096.46	6.78698
2101.41	4.05466
2106.37	-2.42002
2111.32	2.3235
2116.26	4.59795
2121.21	0.598148
2126.15	6.65578
2131.09	0.935875
2136.02	6.15977
2140.95	3.77537
2145.87	3.49442
2150.79	4.46727
2155.71	5.00209
2160.63	5.52388
2165.54	4.32444
2170.45	6.10035
2175.35	3.63161
2180.25	4.55714
2185.15	7.16933
2190.04	5.52571
2194.93	5.17775
2199.82	6.13389
2204.7	1.97406
2209.58	5.96321
2214.46	5.25164
2219.33	2.3941
2224.2	4.27589
2229.06	6.16619
2233.92	6.76262
2238.78	1.26614
2243.64	4.03308
2248.49	0.689857
2253.34	1.27309
2258.18	2.30146
2263.02	5.53469
2267.86	4.34504
2272.69	3.57643
2277.52	1.90587
2282.35	5.09191
2287.17	2.49638
2291.99	2.11639
2296.81	5.28679
2301.62	0.932198
2306.43	2.36861
2311.24	5.61186
2316.04	3.97106
2320.84	6.36174
2325.63	5.62376
2330.43	-0.0629997
2335.21	0.99847
2340	2.06922
2344.78	3.61069
2349.56	2.89076
2354.33	2.61055
2359.11	5.97559
2363.87	3.80679
2368.64	1.17775
2373.4	2.68708
2378.16	5.58799
2382.91	4.76913
2387.66	5.31929
2392.41	5.85355
2397.16	4.98179
2401.9	4.56878
2406.64	2.75495
2411.37	3.30631
2416.1	4.40673
2420.83	3.71031
2425.55	3.81469
2430.27	3.95761
2434.99	4.58486
2439.7	8.0605
2444.41	7.28569
2449.12	0.800728
2453.83	1.90525
2458.53	2.05764
2463.22	-0.668793
2467.92	7.1669
2472.61	2.49591
2477.3	4.57225
2481.98	1.8078
2486.66	4.36177
2491.34	1.56509
2496.01	22.6635
2500.68	3.2664
2505.35	1.41908
2510.01	3.97119
2514.67	0.1366
2519.33	1.21103
2523.99	2.78971
2528.64	5.35485
2533.28	3.98016
2537.93	1.12494
2542.57	3.2226
2547.21	-2.12343
2551.84	5.95936
2556.47	2.08574
2561.1	5.19831
2565.73	1.81964
2570.35	0.441978
2574.97	3.59286
2579.58	5.73594
2584.19	5.83949
2588.8	3.39245
2593.41	5.48828
2598.01	2.03253
2602.61	0.593365
2607.2	4.74322
2611.8	2.77672
2616.38	4.37195
2620.97	3.93188
2625.55	2.47331
2630.13	4.60609
2634.71	4.72429
2639.28	3.32911
2643.85	3.47499
2648.42	4.65887
2652.98	6.88409
2657.54	1.79023
2662.1	6.56716
2666.65	4.03772
2671.2	2.04264
2675.75	1.12172
2680.29	1.84055
2684.84	3.08145
2689.37	1.67298
2693.91	5.56226
2698.44	2.97839
2702.97	0.939116
2707.49	2.10143
2712.02	5.94819
2716.53	3.36436
2721.05	3.99598
2725.56	2.99526
2730.07	3.60222
2734.58	0.405508
2739.08	0.990822
2743.58	2.67968
2748.08	3.84035
2752.57	-0.945124
2757.06	2.42124
2761.55	4.67885
2766.04	4.21827
2770.52	2.65666
2775	3.30057
2779.47	9.48112
2783.94	0.22559
2788.41	1.4589
2792.88	0.463905
2797.34	2.80348
2801.8	4.58387
2806.26	5.79658
2810.71	4.19274
2815.16	2.00848
2819.61	6.01988
2824.05	3.26664
2828.49	2.20196
2832.93	6.79724
2837.37	3.45289
2841.8	2.37443
2846.23	4.14698
2850.65	7.64439
2855.08	12.3194
2859.5	4.97944
2863.91	3.36203
2868.33	2.32172
2872.74	3.00671
2877.15	3.1171
2881.55	3.81738
2885.95	2.77645
2890.35	-0.0384159
2894.75	4.18396
2899.14	1.95437
2903.53	13.3256
2907.91	2.16417
2912.3	2.84418
2916.68	4.11094
2921.05	2.39861
2925.43	3.08385
2929.8	3.17959
2934.17	12.3271
2938.53	6.36499
2942.9	5.82312
2947.26	1.01563
2951.61	2.87992
2955.97	2.31245
2960.32	2.96157
2964.66	4.8383
2969.01	3.0582
2973.35	1.88696
2977.69	3.78152
2982.03	5.07134
2986.36	5.14866
2990.69	2.14273
2995.01	5.94594
2999.34	9.15802
3003.66	5.53355
3007.98	4.3926
3012.29	1.97613
3016.6	2.70735
3020.91	2.81701
3025.22	2.27723
3029.52	4.8965
3033.82	4.32634
3038.12	3.09498
3042.41	3.79538
3046.71	1.27579
3051	3.24258
3055.28	1.99932
3059.56	3.33228
3063.84	4.02168
3068.12	4.06623
3072.39	-1.72444
3076.67	6.10621
3080.93	4.2056
3085.2	2.30412
3089.46	7.59904
3093.72	0.483904
3097.98	8.463
3102.23	5.27615
3106.48	4.06654
3110.73	6.84402
3114.98	10.9799
3119.22	5.76604
3123.46	5.23147
3127.7	8.7567
3131.93	6.89425
3136.16	7.74343
3140.39	3.78905
3144.61	5.98413
3148.84	6.80345
3153.06	6.21564
3157.27	7.00404
3161.49	11.2852
3165.7	4.38989
3169.91	11.4772
3174.11	5.2461
3178.31	8.82024
3182.51	15.2143
3186.71	13.8404
3190.9	13.8708
3195.1	7.55
3199.28	6.92193
3203.47	8.46923
3207.65	15.0505
3211.83	5.87488
3216.01	11.0739
3220.18	8.3308
3224.36	14.2962
3228.52	11.5412
3232.69	8.02454
3236.85	9.61805
3241.01	7.54696
3245.17	10.6725
3249.33	9.32595
3253.48	8.6795
3257.63	11.0022
3261.77	8.12346
3265.92	9.773
3270.06	4.64359
3274.2	8.58551
3278.33	7.8885
3282.47	4.13568
3286.59	7.25735
3290.72	8.08699
3294.85	9.682
3298.97	8.97428
3303.09	9.04805
3307.2	9.1184
3311.32	8.40835
3315.43	8.47074
3319.54	1.5445
3323.64	13.2977
3327.74	12.6252
3331.84	10.4046
3335.94	9.76355
3340.04	7.51955
3344.13	14.7122
3348.22	6.07811
3352.3	32.317
3356.39	6.21385
3360.47	11.0737
3364.54	8.77146
3368.62	6.45375
3372.69	13.7434
3376.76	8.99736
3380.83	9.85712
3384.89	14.7405
3388.96	9.9591
3393.02	12.4232
3397.07	9.25377
3401.13	11.7401
3405.18	12.5919
3409.23	13.4482
3413.27	11.0504
3417.31	19.2075
3421.36	13.5611
3425.39	23.354
3429.43	10.394
3433.46	16.1598
3437.49	11.345
3441.52	17.1543
3445.54	9.89183
3449.56	10.0067
3453.58	4.36045
3457.6	11.9248
3461.61	8.77105
3465.63	5.59712
3469.63	8.24375
3473.64	10.8778
3477.64	8.50168
3481.64	12.849
3485.64	5.38717
3489.64	4.65696
3493.63	-0.328207
3497.62	7.42279
3501.61	11.784
3505.59	8.45422
3509.58	9.37018
3513.56	6.84563
3517.53	12.0258
3521.51	12.9254
3525.48	6.97013
3529.45	7.01144
3533.42	6.22516
3537.38	5.46332
3541.34	5.56889
3545.3	6.52098
3549.26	5.73322
3553.21	5.77341
3557.16	4.96123
3561.11	11.9751
3565.06	10.3267
3569	11.3142
3572.94	14.0437
3576.88	11.5496
3580.82	12.5717
3584.75	17.1309
3588.68	19.9488
3592.61	8.61135
3596.54	12.3065
3600.46	5.32381
3604.38	7.22848
3608.3	3.76244
3612.21	0.273794
3616.13	3.95819
3620.04	4.94919
3623.94	5.91082
3627.85	6.86364
3631.75	2.39721
3635.65	4.24772
3639.55	7.02565
3643.44	1.69515
3647.34	3.61149
3651.23	1.84619
3655.12	7.35922
3659	1.05705
3662.88	5.6593
3666.76	0.257677
3670.64	1.22961
3674.52	5.86151
3678.39	2.29648
3682.26	6.06347
3686.13	0.677532
3689.99	1.71622
3693.85	1.83412
3697.71	1.94672
3701.57	0.206263
3705.43	1.24578
3709.28	6.0332
3713.13	5.22495
3716.98	4.39751
3720.82	2.61665
3724.66	6.47553
3728.5	5.62247
3732.34	4.77127
3736.18	4.86568
3740.01	1.15858
3743.84	4.08844
3747.67	4.16509
3751.49	0.418688
3755.32	3.33382
3759.14	0.515612
3762.96	1.51035
3766.77	6.32656
3770.58	6.37833
3774.4	5.47767
3778.2	6.49347
3782.01	15.1986
3785.81	0.881599
3789.61	0.947603
3793.41	1.98032
3797.21	20.4081
3801	1.18505
3804.79	5.15335
3808.58	1.36953
3812.37	0.483351
3816.15	8.37156
3819.93	3.57819
3823.71	4.63688
3827.49	7.65287
3831.26	7.74079
3835.04	2.90721
3838.8	0.0213966
3842.57	2.07609
3846.34	7.07909
3850.1	1.18022
3853.86	11.1189
3857.62	3.22299
3861.37	13.153
3865.12	6.26903
3868.87	0.407576
3872.62	6.43047
3876.37	7.46513
3880.11	0.527473
3883.85	2.56092
3887.59	2.60716
3891.33	1.65924
3895.06	-0.271729
3898.79	3.80111
3902.52	-0.147701
3906.25	2.92836
3909.97	5.0039
3913.69	3.06186
3917.41	9.20766
3921.13	5.26297
3924.84	1.30059
3928.56	7.49202
3932.27	9.62038
3935.97	4.58993
3939.68	4.66154
3943.38	5.77578
3947.08	0.728748
3950.78	2.8571
3954.48	6.01337
3958.17	-0.109514
3961.86	4.06547
3965.55	7.21081
3969.24	2.08117
3972.92	7.28477
3976.6	5.2575
3980.29	5.29006
3983.96	5.31675
3987.64	6.3802
3991.31	4.35186
3994.98	5.43976
3998.65	7.57972