File: Data/3-Raman/processed/bu20-j-ff1-fi02-s_1800 (450-850nm)_532nm_edge_100%_x100_vis_lwd_h30um_30sx2_01.txt
#Acq. time (s)=	30
#Accumulations=	2
#Range=	Off
#Autofocus=	Off
#Macrospot=	Off
#AutoExposure=	Off
#Spike filter=	Multiple accum.
#Delay time (s)=	2
#Binning=	1
#Readout mode=	Signal
#DeNoise=	Off
#ICS correction=	On
#Dark correction=	Off
#Inst. Process=	Off
#Detector Gain=	Best Dynamic
#Detector ADC=	50 kHz HS
#Detector temperature (°C)=	-60.09
#Instrument=	LabRAM HR Evol
#Detector=	SIN-EM FIVIS
#Objective=	x100_VIS_LWD
#Grating=	1800 (450-850nm)
#ND Filter=	100%
#Laser=	532nm_Edge
#Spectro (cm-¹)=	3360
#Hole=	30.0125
#Temperature=	0
#Range=	Visible
#StageXY=	75x50mm Scan+
#StageZ=	Z motor
#X (µm)=	0
#Y (µm)=	0
#Z (µm)=	-16.5
#Full time(mm:ss)=	1:04
#Project=	21_08_11
#Sample=	BU20
#Site=
#Title=	BU20-J-FF1-FI02-S_1800 (450-850nm)_532nm_Edge_100%_x100_VIS_LWD_H30um_30sX2
#Remark=
#Date=	11.08.2021 17:24
#Acquired=	11.08.2021 17:24:45
#Data Range:Extract=	16.12.2021 15:36:30
#Base:Fit=	16.12.2021 15:36:40
#Base:Fit=	16.12.2021 15:56:20
#Base:Fit=	16.12.2021 15:56:22
#Base:Sub=	16.12.2021 15:56:23
3515.51	358.112
3515.13	383.801
3514.74	373.467
3514.36	384.938
3513.98	400.043
3513.6	400.93
3513.21	431.364
3512.83	418.933
3512.45	436.048
3512.06	446.534
3511.68	428.452
3511.3	425.91
3510.91	446.475
3510.53	435.584
3510.15	438.433
3509.76	425.241
3509.38	412.209
3509	396.094
3508.61	409.405
3508.23	368.031
3507.84	384.362
3507.46	364.901
3507.08	353.027
3506.69	331.606
3506.31	313.701
3505.93	307.365
3505.54	298.646
3505.16	275.322
3504.77	292.475
3504.39	254.597
3504.01	231.62
3503.62	247.808
3503.24	210.792
3502.85	208.965
3502.47	211.088
3502.09	193.15
3501.7	191.338
3501.32	185.69
3500.93	166.743
3500.55	146.74
3500.16	134.173
3499.78	133.152
3499.4	122.631
3499.01	122.661
3498.63	114.176
3498.24	127.573
3497.86	106.65
3497.47	99.0517
3497.09	91.4304
3496.7	89.4751
3496.32	82.8205
3495.93	87.6749
3495.55	82.037
3495.17	66.8929
3494.78	66.0198
3494.4	66.0838
3494.01	58.5066
3493.63	53.7314
3493.24	67.0342
3492.86	59.4952
3492.47	51.9183
3492.09	42.1323
3491.7	47.1084
3491.32	47.087
3490.93	45.9861
3490.55	31.7311
3490.16	31.6626
3489.78	31.4303
3489.39	43.7506
3489.01	34.129
3488.62	22.6779
3488.23	28.4951
3487.85	28.5646
3487.46	16.2428
3487.08	23.0269
3486.69	26.9414
3486.31	30.8511
3485.92	17.5698
3485.54	32.0011
3485.15	26.3997
3484.76	8.41338
3484.38	23.8517
3483.99	16.2952
3483.61	7.81297
3483.22	12.694
3482.84	16.6087
3482.45	7.09576
3482.06	-0.525528
3481.68	2.27856
3481.29	2.41243
3480.91	3.18652
3480.52	12.5269
3480.13	-0.740814
3479.75	-1.55386
3479.36	6.09657
3478.98	9.91689
3478.59	5.15796
3478.2	7.108
3477.82	5.43596
3477.43	6.65427
3477.04	18.2554
3476.66	-6.3324
3476.27	4.14415
3475.88	4.58876
3475.5	-10.3438
3475.11	7.15758
3474.73	5.66138
3474.34	2.83507
3473.95	-1.64896
3473.57	3.03575
3473.18	2.41121
3472.79	6.84831
3472.41	5.3732
3472.02	-2.76834
3471.63	1.11992
3471.24	8.15723
3470.86	-4.23027
3470.47	7.78432
3470.08	-0.653305
3469.7	-9.70203
3469.31	2.64185
3468.92	-5.03557
3468.54	-11.6178
3468.15	6.57762
3467.76	6.69962
3467.38	-3.58147
3466.99	-6.37285
3466.6	10.0817
3466.21	2.49471
3465.83	9.22954
3465.44	9.27744
3465.05	4.57283
3464.66	9.48921
3464.28	4.78964
3463.89	-0.864929
3463.5	0.208664
3463.11	4.1754
3462.73	-11.095
3462.34	-5.21091
3461.95	-8.97086
3461.56	-5.03403
3461.18	-3.99991
3460.79	10.5188
3460.4	-8.65356
3460.01	-0.87204
3459.62	7.95789
3459.24	-3.44826
3458.85	9.06087
3458.46	11.9443
3458.07	0.496155
3457.68	2.52144
3457.3	6.38756
3456.91	0.652145
3456.52	4.57817
3456.13	2.80003
3455.74	3.94017
3455.36	16.5657
3454.97	6.04747
3454.58	2.30592
3454.19	15.9068
3453.8	7.33313
3453.41	2.62436
3453.03	7.51627
3452.64	13.4866
3452.25	2.12756
3451.86	10.8712
3451.47	9.9752
3451.08	15.9077
3450.69	17.8399
3450.31	18.8483
3449.92	14.0849
3449.53	16.0672
3449.14	11.3046
3448.75	11.3837
3448.36	22.0555
3447.97	32.7049
3447.58	10.8111
3447.19	25.0834
3446.81	18.7383
3446.42	22.9229
3446.03	30.1029
3445.64	12.9975
3445.25	16.1658
3444.86	39.2803
3444.47	36.6224
3444.08	27.0376
3443.69	39.0418
3443.3	28.0378
3442.91	34.1005
3442.52	39.8592
3442.14	38.9576
3441.75	46.7547
3441.36	47.7938
3440.97	46.9762
3440.58	42.3191
3440.19	58.912
3439.8	57.2089
3439.41	57.6278
3439.02	77.5837
3438.63	74.383
3438.24	81.2551
3437.85	91.8458
3437.46	84.9173
3437.07	98.4752
3436.68	114.045
3436.29	123.886
3435.9	125.039
3435.51	152.264
3435.12	172.738
3434.73	197.099
3434.34	238.619
3433.95	245.452
3433.56	287.082
3433.17	330.537
3432.78	388.648
3432.39	430.594
3432	523.815
3431.61	585.022
3431.22	684.696
3430.83	808.776
3430.44	870.359
3430.05	958.982
3429.66	1037.53
3429.27	977.598
3428.88	965.662
3428.48	901.498
3428.09	785.359
3427.7	691.445
3427.31	622.313
3426.92	526.462
3426.53	487.116
3426.14	411.109
3425.75	342.982
3425.36	300.608
3424.97	287.999
3424.58	239.898
3424.19	217.889
3423.79	198.765
3423.4	183.47
3423.01	177.735
3422.62	173.949
3422.23	147.003
3421.84	142.127
3421.45	116.095
3421.06	101.714
3420.67	86.407
3420.27	99.1009
3419.88	85.7851
3419.49	83.9342
3419.1	81.0979
3418.71	68.6258
3418.32	71.4541
3417.93	71.5454
3417.53	61.0926
3417.14	60.2074
3416.75	54.5426
3416.36	52.787
3415.97	53.8326
3415.58	52.9253
3415.19	48.2233
3414.79	45.4685
3414.4	48.5005
3414.01	33.2859
3413.62	40.1532
3413.22	37.3681
3412.83	30.7132
3412.44	43.2591
3412.05	33.6944
3411.66	33.7845
3411.27	34.8774
3410.87	36.9824
3410.48	39.0876
3410.09	30.5556
3409.7	30.6746
3409.3	23.1006
3408.91	32.822
3408.52	29.0952
3408.13	17.7401
3407.73	32.1365
3407.34	35.2435
3406.95	26.7389
3406.56	22.3315
3406.17	37.5193
3405.77	32.8329
3405.38	32.7261
3404.99	29.9519
3404.59	23.4003
3404.2	29.2126
3403.81	16.0734
3403.42	29.3985
3403.02	21.1481
3402.63	22.3268
3402.24	30.8603
3401.84	28.6115
3401.45	28.3806
3401.06	44.526
3400.67	29.0934
3400.27	27.6431
3399.88	31.3901
3399.49	33.2095
3399.09	42.6245
3398.7	35.3147
3398.31	31.482
3397.91	34.9314
3397.52	31.1567
3397.13	41.8484
3396.73	40.2917
3396.34	38.4383
3395.95	29.8897
3395.55	36.645
3395.16	50.9112
3394.77	44.2544
3394.37	53.0196
3393.98	51.3289
3393.59	49.6496
3393.19	40.3829
3392.8	51.0818
3392.4	47.9655
3392.01	51.1159
3391.62	62.0977
3391.22	56.8964
3390.83	58.1662
3390.44	71.9088
3390.04	71.0414
3389.65	66.2362
3389.25	73.7887
3388.86	72.8344
3388.47	73.2334
3388.07	75.0746
3387.68	77.1176
3387.28	94.3312
3386.89	109.581
3386.49	105.902
3386.1	108.889
3385.71	138.581
3385.31	130.193
3384.92	139.007
3384.52	154.638
3384.13	150.242
3383.73	163.756
3383.34	182.782
3382.95	198.998
3382.55	200.856
3382.16	199.905
3381.76	223.918
3381.37	255.62
3380.97	238.66
3380.58	241.713
3380.18	229.473
3379.79	261.082
3379.39	242.1
3379	238.369
3378.6	233.644
3378.21	213.696
3377.81	208.126
3377.42	204.546
3377.02	213.323
3376.63	192.427
3376.23	187.741
3375.84	158.244
3375.44	158.329
3375.05	138.433
3374.65	144.265
3374.25	131.92
3373.86	131.266
3373.46	116.307
3373.07	120.398
3372.67	101.523
3372.28	99.7442
3371.88	93.1544
3371.49	94.2124
3371.09	76.1439
3370.7	69.6051
3370.3	71.6909
3369.9	81.3502
3369.51	70.9984
3369.11	57.8105
3368.72	67.5115
3368.32	65.7761
3367.93	54.4894
3367.53	56.5289
3367.13	45.239
3366.74	54.0299
3366.34	45.5611
3365.95	43.7497
3365.55	55.2995
3365.15	35.4465
3364.76	33.7348
3364.36	33.9021
3363.97	38.7857
3363.57	38.9653
3363.17	35.362
3362.78	39.3658
3362.38	41.4431
3361.98	32.0761
3361.59	18.8681
3361.19	23.7189
3360.79	26.691
3360.4	29.6626
3360	23.1079
3359.6	18.4561
3359.21	21.4326
3358.81	14.9165
3358.41	19.8314
3358.02	29.5356
3357.62	15.4868
3357.22	14.7258
3356.83	17.7253
3356.43	27.3623
3356.03	16.9828
3355.64	21.8545
3355.24	16.283
3354.84	11.6705
3354.44	20.3891
3354.05	16.7423
3353.65	11.1919
3353.25	11.3495
3352.86	8.65115
3352.46	11.6851
3352.06	14.7352
3351.67	12.9839
3351.27	17.8854
3350.87	2.84883
3350.47	13.508
3350.08	15.5787
3349.68	3.34624
3349.28	8.2234
3348.88	12.1333
3348.49	7.48083
3348.09	13.2708
3347.69	5.78191
3347.29	2.13553
3346.9	8.02457
3346.5	12.0341
3346.1	1.79262
3345.7	1.98438
3345.3	5.94276
3344.91	8.02025
3344.51	13.872
3344.11	9.27298
3343.71	14.244
3343.31	-2.71185
3342.92	3.14481
3342.52	-0.500732
3342.12	7.29422
3341.72	1.77849
3341.32	-6.59059
3340.93	7.88081
3340.53	0.427933
3340.13	8.22408
3339.73	15.0649
3339.33	5.69711
3338.93	1.10219
3338.54	2.17441
3338.14	-6.15025
3337.74	2.70619
3337.34	9.62616
3336.94	4.06676
3336.54	6.0659
3336.14	5.21437
3335.74	0.613647
3335.35	-2.0795
3334.95	9.58366
3334.55	6.94621
3334.15	0.448029
3333.75	-1.29883
3333.35	-9.73425
3332.95	5.71831
3332.55	2.99655
3332.16	-4.50694
3331.76	4.23492
3331.36	-0.382858
3330.96	-1.22818
3330.56	-3.99229
3330.16	0.930115
3329.76	-9.35741
3329.36	2.32039
3328.96	2.59419
3328.56	-1.01215
3328.16	0.113922
3327.76	6.01587
3327.37	-6.29463
3326.97	3.36925
3326.57	-3.25398
3326.17	-2.15034
3325.77	7.54335
3325.37	-6.5397
3324.97	0.970261
3324.57	4.04364
3324.17	-2.36758
3323.77	2.64447
3323.37	5.69133
3322.97	9.70668
3322.57	3.14697
3322.17	-5.3672
3321.77	1.52786
3321.37	-0.149643
3320.97	-0.814224
3320.57	-6.36225
3320.17	-4.31687
3319.77	-0.365936
3319.37	3.57648
3318.97	6.53636
3318.57	3.78352
3318.17	1.05144
3317.77	-1.6116
3317.37	-0.467209
3316.97	-0.275482
3316.57	8.50003
3316.17	13.5475
3315.77	3.93301
3315.37	4.11337
3314.97	-4.10931
3314.57	0.956268
3314.17	0.0804138
3313.77	1.03073
3313.37	-1.83921
3312.97	9.97079
3312.56	-1.31676
3312.16	10.1815
3311.76	3.6091
3311.36	-8.67906
3310.96	-2.77822
3310.56	0.262871
3310.16	-2.46334
3309.76	3.43233
3309.36	2.62106
3308.96	-5.82765
3308.56	1.05873
3308.15	1.28004
3307.75	4.40401
3307.35	1.72376
3306.95	-5.76668
3306.55	0.157143
3306.15	2.20193
3305.75	-0.509277
3305.35	1.58815
3304.94	5.58284
3304.54	13.5039
3304.14	-3.54707
3303.74	6.31673
3303.34	3.51176
3302.94	-10.8914
3302.53	6.70034
3302.13	-5.57527
3301.73	4.03543
3301.33	1.21848
3300.93	-13.0513
3300.53	-4.2519
3300.13	-3.04698
3299.72	1.97459
3299.32	1.97232
3298.92	2.05824
3298.52	-0.685379
3298.12	-10.1147
3297.71	13.22
3297.31	-0.0313492
3296.91	10.7382
3296.51	2.20517
3296.11	-2.49316
3295.7	1.46274
3295.3	-5.15133
3294.9	2.65364
3294.5	0.847633
3294.1	-7.64854
3293.69	2.15147
3293.29	0.390015
3292.89	1.5072
3292.49	-3.1785
3292.08	-1.12254
3291.68	3.08572
3291.28	-5.59362
3290.88	1.22224
3290.47	-8.35915
3290.07	5.13983
3289.67	4.37535
3289.27	-0.211304
3288.86	7.66329
3288.46	-3.71925
3288.06	0.279259
3287.65	6.22364
3287.25	-11.8885
3286.85	-0.172821
3286.45	11.5468
3286.04	-3.71427
3285.64	-2.6246
3285.24	6.146
3284.83	-0.516182
3284.43	-4.27924
3284.03	-6.15777
3283.62	3.58073
3283.22	6.85851
3282.82	5.07957
3282.41	0.219215
3282.01	1.91717
3281.61	-1.36422
3281.2	0.699776
3280.8	4.67232
3280.4	8.65529
3279.99	4.91228
3279.59	6.93759
3279.19	6.1085
3278.78	3.3561
3278.38	-2.26688
3277.98	3.66741
3277.57	-4.84206
3277.17	3.97177
3276.76	-3.59173
3276.36	-4.43369
3275.96	7.23145
3275.55	-2.27203
3275.15	5.48823
3274.74	9.46668
3274.34	-0.870926
3273.94	1.84715
3273.53	7.72303
3273.13	7.93607
3272.72	5.22414
3272.32	3.48296
3271.92	-0.202896
3271.51	11.4541
3271.11	4.87559
3270.7	9.84367
3270.3	10.9615
3269.9	7.26453
3269.49	0.655472
3269.09	7.5248
3268.68	8.59933
3268.28	0.985298
3267.87	4.9299
3267.47	7.90601
3267.06	0.312042
3266.66	11.0149
3266.25	0.581612
3265.85	10.3781
3265.44	16.3474
3265.04	8.83271
3264.64	11.861
3264.23	6.19355
3263.83	10.1474
3263.42	4.44502
3263.02	9.32077
3262.61	5.55137
3262.21	9.47837
3261.8	0.919174
3261.4	18.3586
3260.99	6.94297
3260.59	12.9016
3260.18	8.13793
3259.78	9.3325
3259.37	6.62777
3258.96	-0.99176
3258.56	2.03599
3258.15	3.10175
3257.75	2.20975
3257.34	5.17893
3256.94	10.0544
3256.53	10.1173
3256.13	14.9955
3255.72	9.30376
3255.31	10.359
3254.91	10.5
3254.5	1.952
3254.1	1.07343
3253.69	5.01623
3253.29	8.02104
3252.88	5.27606
3252.47	4.46169
3252.07	6.51897
3251.66	9.51997
3251.26	12.4995
3250.85	11.6045
3250.44	8.75774
3250.04	9.73866
3249.63	6.92173
3249.23	0.316513
3248.82	9.10232
3248.41	2.52839
3248.01	3.66521
3247.6	11.4766
3247.2	8.66522
3246.79	8.72505
3246.38	9.72607
3245.98	5.89117
3245.57	11.6797
3245.16	4.96172
3244.76	6.00282
3244.35	11.9259
3243.94	8.22802
3243.54	10.2475
3243.13	6.5583
3242.72	3.80536
3242.32	11.6053
3241.91	-4.59821
3241.5	7.96596
3241.1	8.06922
3240.69	5.28362
3240.28	10.158
3239.88	6.40367
3239.47	8.42967
3239.06	9.47917
3238.65	7.66972
3238.25	1.01208
3237.84	8.72836
3237.43	14.5407
3237.03	6.95921
3236.62	17.6126
3236.21	4.3235
3235.8	6.37257
3235.4	7.4548
3234.99	11.3935
3234.58	11.4551
3234.18	6.73578
3233.77	3.93078
3233.36	5.92303
3232.95	10.7981
3232.54	4.16795
3232.14	12.8925
3231.73	9.1655
3231.32	10.1468
3230.91	4.44585
3230.51	7.47874
3230.1	7.4652
3229.69	-1.06087
3229.28	2.09457
3228.87	3.82652
3228.47	4.8616
3228.06	6.01257
3227.65	9.75349
3227.24	-0.685539
3226.83	2.12426
3226.43	5.96631
3226.02	4.59831
3225.61	8.51323
3225.2	5.58888
3224.79	1.76266
3224.39	5.57902
3223.98	6.54833
3223.57	-4.86837
3223.16	8.63175
3222.75	13.51
3222.34	10.7286
3221.94	0.283623
3221.53	8.00205
3221.12	3.2422
3220.71	3.25231
3220.3	9.96974
3219.89	6.18098
3219.48	4.33254
3219.07	1.5796
3218.67	5.46008
3218.26	14.0928
3217.85	4.72935
3217.44	-0.756119
3217.03	-3.95956
3216.62	1.24351
3216.21	-4.57793
3215.8	6.80028
3215.39	1.17897
3214.99	10.8535
3214.58	1.3728
3214.17	0.451729
3213.76	6.21822
3213.35	4.35899
3212.94	8.25923
3212.53	4.48837
3212.12	-0.239525
3211.71	5.55133
3211.3	-3.97038
3210.89	-4.8831
3210.48	-1.97408
3210.07	6.69854
3209.66	2.03101
3209.25	-5.53009
3208.84	6.99786
3208.44	5.1339
3208.02	0.360977
3207.62	-3.42541
3207.21	4.26471
3206.8	5.26102
3206.39	-0.434586
3205.98	8.23944
3205.57	9.24071
3205.16	6.39146
3204.75	1.6123
3204.34	1.64921
3203.93	4.57894
3203.52	-3.97666
3203.11	0.866364
3202.7	-5.76987
3202.29	2.90274
3201.88	2.96617
3201.47	3.96617
3201.06	6.84265
3200.65	-2.71404
3200.23	-1.73244
3199.82	-0.749313
3199.41	-2.6311
3199	-3.54202
3198.59	-2.52859
3198.39	-7.2668