File: Data/3-Raman/processed/bu20-b-ff4-fi02-l_150 (500nm)_633nm_edge_100%_x100_vis_lwd_h30um_60sx4_01.txt
#Acq. time (s)=	60
#Accumulations=	4
#Range (cm-¹)=	100...4000
#Windows=	1
#Auto scanning=	Off
#Autofocus=	Off
#Macrospot=	Off
#AutoExposure=	Off
#Spike filter=	Multiple accum.
#Delay time (s)=	2
#Binning=	1
#Readout mode=	Signal
#DeNoise=	Off
#ICS correction=	On
#Dark correction=	Off
#Inst. Process=	Off
#Detector Gain=	Best Dynamic
#Detector ADC=	50 kHz HS
#Detector temperature (°C)=	-60.09
#Instrument=	LabRAM HR Evol
#Detector=	SIN-EM FIVIS
#Objective=	x100_VIS_LWD
#Grating=	150 (500nm)
#ND Filter=	100%
#Laser=	633nm_Edge
#Hole=	30.0125
#Temperature=	39.9
#Range=	Visible
#StageXY=	75x50mm Scan+
#StageZ=	Z motor
#X (µm)=	0
#Y (µm)=	0
#Z (µm)=	470.9
#Full time(mm:ss)=	4:05
#Project=	21_08_11
#Sample=	BU20
#Site=
#Title=	BU20-B-FF4-FI02-L_150 (500nm)_633nm_Edge_100%_x100_VIS_LWD_H30um_60sX4
#Remark=
#Date=	13.08.2021 11:55
#Acquired=	13.08.2021 11:55:24
#Data Range:Extract=	16.12.2021 15:36:30
#Base:Fit=	16.12.2021 15:36:40
#Base:Edit=	16.12.2021 15:52:24
#Base:Edit=	16.12.2021 15:52:25
#Base:Edit=	16.12.2021 15:52:26
#Base:Edit=	16.12.2021 15:52:27
#Base:Sub=	16.12.2021 15:52:30
100.12	264.718
106.638	220.762
113.152	197.026
119.66	161.518
126.162	143.91
132.659	116.472
139.151	114.849
145.637	105.058
152.118	94.4338
158.594	63.8632
165.064	58.2793
171.529	62.9249
177.989	38.7634
184.441	38.8262
190.89	31.81
197.334	22.9664
203.772	12.4937
210.205	17.3525
216.631	-0.00482178
223.054	5.54869
229.471	17.3453
235.881	86.8639
242.288	168.667
248.689	83.1316
255.083	42.5212
261.474	44.0769
267.858	61.4788
274.238	93.788
280.613	154.543
286.982	248.975
293.346	210.239
299.704	95.5268
306.058	38.3423
312.406	31.3337
318.749	26.5475
325.086	76.2447
331.418	201.389
337.746	129.042
344.068	54.5065
350.384	23.9454
356.697	38.2447
363.003	52.4714
369.304	90.1367
375.601	75.1253
381.892	41.691
388.177	13.1132
394.457	5.90017
400.733	8.7907
407.004	4.11215
413.269	8.80078
419.529	13.4144
425.784	29.85
432.034	55.6644
438.279	110.499
444.518	140.591
450.753	139.174
456.982	125.357
463.207	108.663
469.426	67.0056
475.64	39.1432
481.85	29.32
488.054	25.6602
494.253	23.8516
500.447	15.4842
506.635	18.3034
512.819	21.4251
518.999	25.1841
525.173	19.9501
531.342	15.0343
537.505	12.9258
543.664	20.45
549.819	18.1068
555.966	19.1786
562.111	21.9529
568.25	23.028
574.383	23.9809
580.513	22.9889
586.636	25.1632
592.756	39.8323
598.871	77.8486
604.979	165.578
611.084	112.889
617.183	90.6971
623.277	94.4256
629.367	110.369
635.451	117.194
641.532	100.134
647.606	86.3806
653.675	89.8309
659.741	115.005
665.801	129.77
671.856	94.8753
677.907	56.934
683.952	35.7566
689.992	19.926
696.028	20.0004
702.059	12.2275
708.086	8.76563
714.107	7.97858
720.123	6.51456
726.135	8.15835
732.141	8.47238
738.143	7.83593
744.14	7.8228
750.133	3.78527
756.12	5.06925
762.103	2.7188
768.081	7.29391
774.054	3.13845
780.023	4.24783
785.987	4.04356
791.946	5.05777
797.9	5.70638
803.848	8.80514
809.793	5.89896
815.733	8.27753
821.669	7.48843
827.6	5.75035
833.525	5.96433
839.446	11.882
845.363	11.3296
851.273	10.784
857.181	8.37167
863.083	8.78523
868.98	13.9253
874.874	17.7605
880.761	20.9072
886.645	16.7347
892.523	21.3665
898.398	18.0399
904.267	14.01
910.133	10.6109
915.992	10.0506
921.849	15.2047
927.699	16.9886
933.545	23.2429
939.387	39.0778
945.224	50.6532
951.056	76.6114
956.884	110.658
962.708	116.729
968.526	127.496
974.34	136.543
980.149	183.051
985.955	255.438
991.755	363.853
997.551	375.101
1003.34	277.159
1009.13	234.622
1014.91	225.869
1020.69	262.949
1026.46	336.221
1032.23	374.814
1037.99	242.827
1043.75	135.786
1049.51	106.812
1055.26	78.2149
1061	69.821
1066.74	64.5119
1072.48	58.5303
1078.21	73.8609
1083.94	104.001
1089.67	109.264
1095.38	102.919
1101.1	139.142
1106.81	142.958
1112.51	80.0252
1118.22	48.2433
1123.91	39.8992
1129.6	29.2274
1135.29	36.4622
1140.98	51.5835
1146.65	66.3623
1152.33	74.2552
1158	110.554
1163.66	78.0984
1169.32	34.2574
1174.98	26.156
1180.63	24.6067
1186.28	18.2461
1191.93	13.9021
1197.56	10.9168
1203.2	13.2198
1208.83	6.06679
1214.46	4.47261
1220.08	5.20609
1225.69	4.29149
1231.31	2.6843
1236.92	5.72335
1242.52	6.71526
1248.12	6.98431
1253.72	1.15096
1259.31	9.07436
1264.89	5.18061
1270.48	12.0355
1276.05	4.76948
1281.63	7.88866
1287.2	7.34835
1292.76	10.4995
1298.33	8.02148
1303.88	5.23965
1309.43	9.84726
1314.98	3.82055
1320.53	2.13152
1326.07	5.16706
1331.6	4.84488
1337.13	3.47694
1342.66	3.77547
1348.18	6.0934
1353.7	7.03757
1359.22	0.0810204
1364.73	3.70876
1370.23	6.62677
1375.73	7.14077
1381.23	13.8114
1386.72	16.0251
1392.21	7.64669
1397.7	3.41921
1403.18	4.67425
1408.65	1.82046
1414.13	4.47022
1419.59	1.96578
1425.06	3.25741
1430.52	-0.296814
1435.97	2.38118
1441.42	2.62632
1446.87	2.52477
1452.31	3.43533
1457.75	1.87117
1463.19	3.7841
1468.62	0.0830765
1474.04	4.08052
1479.46	3.54324
1484.88	-0.489685
1490.3	2.49316
1495.7	4.44621
1501.11	1.13824
1506.51	2.75919
1511.91	3.69209
1517.3	3.22131
1522.69	4.17458
1528.08	2.99274
1533.46	2.88355
1538.83	5.62504
1544.21	4.38855
1549.58	4.89393
1554.94	5.7125
1560.3	7.23214
1565.66	6.95753
1571.01	5.95998
1576.36	7.12137
1581.7	3.64479
1587.04	10.941
1592.38	8.91758
1597.71	11.222
1603.04	4.9019
1608.37	12.6528
1613.68	11.4236
1619	10.5704
1624.31	8.97967
1629.62	13.2305
1634.93	11.6115
1640.23	12.8677
1645.52	14.4878
1650.81	14.9902
1656.1	15.1065
1661.39	10.395
1666.67	11.9561
1671.94	14.2494
1677.22	6.92256
1682.48	9.19822
1687.75	7.38844
1693.01	8.91204
1698.26	8.62131
1703.52	5.84814
1708.77	4.55439
1714.01	7.91166
1719.25	5.82179
1724.49	2.5626
1729.72	4.16664
1734.95	4.27469
1740.18	5.87944
1745.4	7.48792
1750.61	4.94062
1755.83	6.52394
1761.04	-0.214788
1766.24	2.85336
1771.44	1.77281
1776.64	0.316725
1781.84	5.30596
1787.02	1.97528
1792.21	6.62445
1797.39	2.53441
1802.57	4.16246
1807.75	6.94459
1812.92	7.03516
1818.08	4.43295
1823.25	5.2866
1828.41	4.98679
1833.56	3.13801
1838.71	4.38407
1843.86	2.507
1849	6.85082
1854.14	4.95368
1859.28	4.62225
1864.41	1.94803
1869.54	3.58099
1874.67	4.02205
1879.79	1.70416
1884.9	0.950808
1890.02	5.30679
1895.13	3.73676
1900.23	4.9375
1905.34	3.80632
1910.43	5.4558
1915.53	0.38998
1920.62	3.61363
1925.71	5.65699
1930.79	2.51811
1935.87	0.162863
1940.94	4.60333
1946.02	3.83034
1951.08	2.64474
1956.15	5.06178
1961.21	7.47476
1966.27	5.46241
1971.32	5.0423
1976.37	1.80906
1981.42	2.59029
1986.46	2.16906
1991.5	3.75528
1996.53	4.14261
2001.56	1.33151
2006.59	4.54128
2011.61	2.54781
2016.63	0.954168
2021.65	3.36971
2026.66	4.59855
2031.67	5.03684
2036.68	3.06448
2041.68	1.89465
2046.68	3.15555
2051.67	0.767879
2056.66	8.12155
2061.65	8.99837
2066.63	4.97634
2071.61	3.38895
2076.59	3.02508
2081.56	6.35526
2086.53	4.74415
2091.49	3.12647
2096.46	-0.9583
2101.41	4.88556
2106.37	2.87407
2111.32	4.60688
2116.26	8.02885
2121.21	2.25131
2126.15	6.52321
2131.09	4.49068
2136.02	3.707
2140.95	3.3371
2145.87	7.20429
2150.79	5.12071
2155.71	2.59569
2160.63	0.90872
2165.54	4.74906
2170.45	3.89916
2175.35	3.91452
2180.25	7.33269
2185.15	4.33652
2190.04	1.34826
2194.93	4.34569
2199.82	4.3717
2204.7	0.129913
2209.58	1.88773
2214.46	8.38865
2219.33	4.58802
2224.2	6.38632
2229.06	3.42934
2233.92	2.19432
2238.78	3.12942
2243.64	1.45081
2248.49	1.07779
2253.34	4.64823
2258.18	2.08273
2263.02	0.38356
2267.86	0.873968
2272.69	1.35596
2277.52	-0.383907
2282.35	3.18241
2287.17	0.531359
2291.99	4.97544
2296.81	2.76828
2301.62	3.68068
2306.43	4.16629
2311.24	7.78764
2316.04	1.61234
2320.84	3.47242
2325.63	3.99665
2330.43	2.27793
2335.21	0.557222
2340	2.90385
2344.78	3.91005
2349.56	-0.999086
2354.33	2.28658
2359.11	2.82297
2363.87	2.42111
2368.64	0.642303
2373.4	2.08424
2378.16	0.292654
2382.91	1.72361
2387.66	4.53602
2392.41	1.31002
2397.16	5.96043
2401.9	2.25649
2406.64	0.402685
2411.37	4.61359
2416.1	2.38307
2420.83	-1.22387
2425.55	3.03595
2430.27	3.11056
2434.99	-0.10417
2439.7	2.81285
2444.41	5.27078
2449.12	0.611351
2453.83	3.07648
2458.53	2.20657
2463.22	2.77001
2467.92	3.81356
2472.61	4.37434
2477.3	3.00563
2481.98	0.173023
2486.66	3.14854
2491.34	2.23767
2496.01	16.448
2500.68	2.35801
2505.35	1.92209
2510.01	2.45945
2514.67	3.48253
2519.33	2.051
2523.99	2.59192
2528.64	5.59734
2533.28	3.18089
2537.93	2.74314
2542.57	1.31428
2547.21	-1.11151
2551.84	7.9116
2556.47	2.98677
2561.1	2.54321
2565.73	-0.901196
2570.35	0.166355
2574.97	2.75119
2579.58	2.30831
2584.19	1.84735
2588.8	2.89271
2593.41	0.380043
2598.01	4.48075
2602.61	5.53689
2607.2	5.57144
2611.8	0.502344
2616.38	1.03062
2620.97	2.58278
2625.55	0.564598
2630.13	3.66718
2634.71	5.77705
2639.28	4.83544
2643.85	1.82568
2648.42	3.97435
2652.98	1.97921
2657.54	4.62504
2662.1	2.5805
2666.65	6.25817
2671.2	3.69124
2675.75	1.66521
2680.29	3.3623
2684.84	1.36072
2689.37	3.05914
2693.91	3.15073
2698.44	-0.0227852
2702.97	2.6951
2707.49	3.27047
2712.02	3.84232
2716.53	-0.418077
2721.05	3.93029
2725.56	3.41902
2730.07	3.43713
2734.58	1.27805
2739.08	0.194229
2743.58	4.5469
2748.08	5.11663
2752.57	1.36509
2757.06	6.31939
2761.55	4.15753
2766.04	-0.192427
2770.52	1.47906
2775	6.467
2779.47	4.32234
2783.94	3.84359
2788.41	3.91567
2792.88	5.09633
2797.34	5.15543
2801.8	2.40404
2806.26	2.43597
2810.71	1.89897
2815.16	1.91499
2819.61	4.7491
2824.05	2.5094
2828.49	4.22448
2832.93	6.50687
2837.37	1.97936
2841.8	4.83102
2846.23	4.85037
2850.65	6.01679
2855.08	7.77514
2859.5	3.81069
2863.91	2.1346
2868.33	2.18693
2872.74	5.70818
2877.15	6.35105
2881.55	6.42232
2885.95	2.99418
2890.35	5.98765
2894.75	3.11258
2899.14	7.31747
2903.53	14.5023
2907.91	1.5076
2912.3	3.92327
2916.68	3.35258
2921.05	4.58291
2925.43	6.42469
2929.8	3.46853
2934.17	10.1517
2938.53	6.55907
2942.9	4.76105
2947.26	1.73159
2951.61	2.94778
2955.97	4.1664
2960.32	5.99745
2964.66	5.39563
2969.01	6.63387
2973.35	9.10514
2977.69	3.60347
2982.03	7.31262
2986.36	0.567608
2990.69	1.8341
2995.01	8.07259
2999.34	3.15884
3003.66	7.58215
3007.98	4.52328
3012.29	5.20406
3016.6	9.05275
3020.91	9.13962
3025.22	9.84632
3029.52	7.99106
3033.82	11.8552
3038.12	11.8805
3042.41	13.8447
3046.71	8.10182
3051	8.11959
3055.28	12.0022
3059.56	12.031
3063.84	15.9342
3068.12	13.3798
3072.39	12.1129
3076.67	14.093
3080.93	13.4785
3085.2	13.5216
3089.46	11.6218
3093.72	16.9416
3097.98	19.0199
3102.23	19.7934
3106.48	16.6143
3110.73	19.4044
3114.98	20.8835
3119.22	20.3649
3123.46	23.8947
3127.7	22.0584
3131.93	24.299
3136.16	25.1954
3140.39	27.458
3144.61	22.1439
3148.84	28.5266
3153.06	29.3694
3157.27	29.5047
3161.49	33.8267
3165.7	41.6674
3169.91	36.899
3174.11	35.6405
3178.31	39.9575
3182.51	46.3808
3186.71	40.0829
3190.9	46.4962
3195.1	45.8851
3199.28	44.6256
3203.47	50.5645
3207.65	54.42
3211.83	46.0968
3216.01	48.556
3220.18	45.9413
3224.36	56.4004
3228.52	50.8681
3232.69	57.0193
3236.85	49.1917
3241.01	57.6012
3245.17	54.2411
3249.33	55.2729
3253.48	56.2345
3257.63	54.9059
3261.77	57.4144
3265.92	59.2352
3270.06	55.823
3274.2	53.8685
3278.33	57.823
3282.47	61.0348
3286.59	64.2599
3290.72	56.7516
3294.85	51.5074
3298.97	56.2515
3303.09	55.641
3307.2	53.4744
3311.32	59.803
3315.43	61.4988
3319.54	63.9891
3323.64	71.2021
3327.74	63.6371
3331.84	74.0918
3335.94	60.2968
3340.04	73.176
3344.13	63.9034
3348.22	65.6358
3352.3	102.285
3356.39	72.3357
3360.47	86.8883
3364.54	80.7511
3368.62	76.9717
3372.69	79.5822
3376.76	86.1713
3380.83	88.7368
3384.89	94.5169
3388.96	89.8197
3393.02	89.9361
3397.07	95.7509
3401.13	86.209
3405.18	95.2175
3409.23	99.3854
3413.27	101.907
3417.31	108.502
3421.36	98.0329
3425.39	116.002
3429.43	103.939
3433.46	94.3244
3437.49	101.86
3441.52	94.7281
3445.54	101.543
3449.56	97.7582
3453.58	103.029
3457.6	93.5261
3461.61	86.4801
3465.63	102.692
3469.63	99.7963
3473.64	94.277
3477.64	97.1646
3481.64	91.6359
3485.64	91.9729
3489.64	94.8375
3493.63	89.2092
3497.62	85.2116
3501.61	88.8437
3505.59	77.0628
3509.58	77.166
3513.56	78.9352
3517.53	68.7061
3521.51	76.4612
3525.48	66.2255
3529.45	76.564
3533.42	67.24
3537.38	67.4232
3541.34	58.13
3545.3	66.9133
3549.26	60.1083
3553.21	51.4682
3557.16	54.1194
3561.11	54.1994
3565.06	55.1752
3569	57.0794
3572.94	61.5925
3576.88	57.4031
3580.82	60.2486
3584.75	64.0088
3588.68	66.0195
3592.61	68.0362
3596.54	51.4114
3600.46	43.5757
3604.38	40.154
3608.3	43.8525
3612.21	35.894
3616.13	35.0894
3620.04	29.7668
3623.94	23.4755
3627.85	24.3696
3631.75	18.0356
3635.65	24.3332
3639.55	21.6391
3643.44	18.9726
3647.34	19.9408
3651.23	9.93932
3655.12	18.1058
3659	17.1876
3662.88	16.2596
3666.76	8.96228
3670.64	1.65173
3674.52	11.6745
3678.39	11.6889
3682.26	6.22148
3686.13	9.01441
3689.99	6.2977
3693.85	1.7144
3697.71	13.7755
3701.57	6.39843
3705.43	0.838783
3709.28	5.52829
3713.13	7.43066
3716.98	11.2036
3720.82	2.7544
3724.66	-2.90882
3728.5	5.56218
3732.34	3.66525
3736.18	-0.132814
3740.01	-1.10179
3743.84	0.772728
3747.67	4.55193
3751.49	3.56431
3755.32	1.60989
3759.14	0.598063
3762.96	2.44592
3766.77	-1.43961
3770.58	2.33004
3774.4	3.2391
3778.2	0.320189
3782.01	12.7551
3785.81	-1.66406
3789.61	-2.66147
3793.41	7.9052
3797.21	12.7334
3801	2.10821
3804.79	1.13923
3808.58	2.11533
3812.37	-2.75327
3816.15	2.11403
3819.93	-0.821257
3823.71	3.0845
3827.49	4.05431
3831.26	3.07417
3835.04	1.10958
3838.8	2.09174
3842.57	-5.80141
3846.34	6.04847
3850.1	3.05116
3853.86	-4.90325
3857.62	0.0147247
3861.37	4.93088
3865.12	-0.0293312
3868.87	2.0059
3872.62	3.01037
3876.37	1.0148
3880.11	1.01514
3883.85	-5.95753
3887.59	-3.94585
3891.33	-1.91967
3895.06	-4.86709
3898.79	1.20075
3902.52	1.26841
3906.25	2.34407
3909.97	2.42036
3913.69	1.50728
3917.41	-3.43702
3921.13	4.79001
3924.84	-1.15454
3928.56	-5.08921
3932.27	3.19999
3935.97	4.36156
3939.68	-0.598442
3943.38	-0.425293
3947.08	-0.245182
3950.78	0.96693
3954.48	-2.96573
3958.17	-1.74559
3961.86	-0.522833
3965.55	1.74382
3969.24	-2.18549
3972.92	1.13185
3976.6	-2.76967
3980.29	4.7079
3983.96	8.05873
3987.64	6.25874
3991.31	2.41612
3994.98	2.73804
3998.65	-0.015295