File: Data/3-Raman/processed/bu20-b-ff4-fi01-l_150 (500nm)_633nm_edge_100%_x100_vis_lwd_h30um_60sx2_01.txt
#Acq. time (s)=	60
#Accumulations=	2
#Range (cm-¹)=	100...4000
#Windows=	1
#Auto scanning=	Off
#Autofocus=	Off
#Macrospot=	Off
#AutoExposure=	Off
#Spike filter=	Multiple accum.
#Delay time (s)=	2
#Binning=	1
#Readout mode=	Signal
#DeNoise=	Off
#ICS correction=	On
#Dark correction=	Off
#Inst. Process=	Off
#Detector Gain=	Best Dynamic
#Detector ADC=	50 kHz HS
#Detector temperature (°C)=	-60.09
#Instrument=	LabRAM HR Evol
#Detector=	SIN-EM FIVIS
#Objective=	x100_VIS_LWD
#Grating=	150 (500nm)
#ND Filter=	100%
#Laser=	633nm_Edge
#Hole=	30.0125
#Temperature=	40
#Range=	Visible
#StageXY=	75x50mm Scan+
#StageZ=	Z motor
#X (µm)=	0
#Y (µm)=	0
#Z (µm)=	471.2
#Full time(mm:ss)=	2:04
#Project=	21_08_11
#Sample=	BU20
#Site=
#Title=	BU20-B-FF4-FI01-L_150 (500nm)_633nm_Edge_100%_x100_VIS_LWD_H30um_60sX2
#Remark=
#Date=	13.08.2021 11:47
#Acquired=	13.08.2021 11:47:19
#Data Range:Extract=	16.12.2021 15:36:30
#Base:Fit=	16.12.2021 15:36:40
#Base:Edit=	16.12.2021 15:51:21
#Base:Sub=	16.12.2021 15:51:26
100.12	264.073
106.638	232.324
113.152	197.084
119.66	179.179
126.162	141.4
132.659	125.785
139.151	122.718
145.637	104.574
152.118	99.0999
158.594	66.1217
165.064	64.9338
171.529	70.5581
177.989	42.6699
184.441	35.9006
190.89	24.3796
197.334	36.896
203.772	6.78714
210.205	11.1738
216.631	4.21806
223.054	15.4581
229.471	34.2477
235.881	87.3436
242.288	171.811
248.689	87.4098
255.083	48.6081
261.474	61.1893
267.858	67.2082
274.238	88.4989
280.613	137.328
286.982	240.1
293.346	208.149
299.704	110.968
306.058	43.2614
312.406	27.6693
318.749	40.4539
325.086	75.976
331.418	183.205
337.746	153.646
344.068	63.7561
350.384	22.8927
356.697	39.4727
363.003	67.2798
369.304	92.1995
375.601	76.6878
381.892	49.9594
388.177	27.1791
394.457	11.1072
400.733	-0.187531
407.004	6.35519
413.269	4.3699
419.529	13.6426
425.784	39.7812
432.034	52.2559
438.279	99.4662
444.518	133.251
450.753	141.44
456.982	129.092
463.207	116.057
469.426	80.8697
475.64	43.0396
481.85	22.9506
488.054	19.5844
494.253	22.7345
500.447	23.992
506.635	31.7898
512.819	24.6592
518.999	25.0091
525.173	25.4169
531.342	27.7439
537.505	19.7594
543.664	21.9926
549.819	11.8078
555.966	21.3927
562.111	22.2713
568.25	23.0099
574.383	18.9169
580.513	21.3301
586.636	37.7933
592.756	36.5786
598.871	92.2976
604.979	152.092
611.084	125.27
617.183	102.226
623.277	96.9658
629.367	103.862
635.451	121.712
641.532	114.702
647.606	92.4377
653.675	91.7846
659.741	123.79
665.801	132.274
671.856	99.8425
677.907	58.4981
683.952	46.0452
689.992	29.9529
696.028	19.4841
702.059	17.3855
708.086	17.1048
714.107	12.8804
720.123	12.3539
726.135	9.92421
732.141	1.78563
738.143	13.3034
744.14	3.30665
750.133	0.821404
756.12	6.77107
762.103	10.9869
768.081	9.71268
774.054	7.49977
780.023	0.517822
785.987	2.85734
791.946	2.32877
797.9	4.56757
803.848	5.78687
809.793	6.02047
815.733	8.07291
821.669	6.32789
827.6	14.8587
833.525	17.8669
839.446	9.79907
845.363	13.9739
851.273	15.3638
857.181	19.6086
863.083	10.6822
868.98	14.9461
874.874	18.2026
880.761	15.6956
886.645	27.3669
892.523	19.0498
898.398	18.2615
904.267	19.264
910.133	13.6396
915.992	26.8549
921.849	20.4141
927.699	27.2394
933.545	22.8975
939.387	39.4374
945.224	59.9398
951.056	76.8392
956.884	97.6165
962.708	112.658
968.526	127.638
974.34	141.539
980.149	183.918
985.955	279.638
991.755	370.169
997.551	404.018
1003.34	309.238
1009.13	248.291
1014.91	236.427
1020.69	264.66
1026.46	309.616
1032.23	355.898
1037.99	244.795
1043.75	161.018
1049.51	114.453
1055.26	102.44
1061	87.34
1066.74	61.3557
1072.48	67.3943
1078.21	71.4362
1083.94	97.7359
1089.67	117.25
1095.38	117.396
1101.1	129.139
1106.81	148.814
1112.51	87.2394
1118.22	51.0436
1123.91	42.7911
1129.6	43.2785
1135.29	42.8013
1140.98	59.0054
1146.65	68.2991
1152.33	69.7005
1158	92.5964
1163.66	84.775
1169.32	43.5655
1174.98	31.8806
1180.63	23.1791
1186.28	18.4875
1191.93	12.8947
1197.56	14.2143
1203.2	8.76803
1208.83	8.25783
1214.46	9.73851
1220.08	9.28273
1225.69	-1.14138
1231.31	8.35635
1236.92	9.83822
1242.52	11.2603
1248.12	6.55425
1253.72	5.82853
1259.31	12.107
1264.89	6.22269
1270.48	15.4547
1276.05	3.51386
1281.63	9.66253
1287.2	12.8138
1292.76	11.9917
1298.33	5.22411
1303.88	9.48874
1309.43	10.83
1314.98	7.23052
1320.53	6.64404
1326.07	7.08708
1331.6	13.6352
1337.13	8.98243
1342.66	8.34756
1348.18	6.64057
1353.7	9.01316
1359.22	12.3839
1364.73	7.49322
1370.23	7.70357
1375.73	12.0148
1381.23	16.3178
1386.72	15.4802
1392.21	17.735
1397.7	9.79745
1403.18	9.05143
1408.65	2.13377
1414.13	8.62181
1419.59	7.90619
1425.06	6.15788
1430.52	4.4013
1435.97	4.71407
1441.42	8.15268
1446.87	9.51528
1452.31	4.53167
1457.75	3.70015
1463.19	5.9874
1468.62	18.7516
1474.04	0.0232124
1479.46	0.208199
1484.88	5.65297
1490.3	11.126
1495.7	11.3734
1501.11	3.19292
1506.51	7.68057
1511.91	10.0866
1517.3	9.33027
1522.69	9.64319
1528.08	6.74656
1533.46	14.591
1538.83	10.5834
1544.21	8.67434
1549.58	1.26656
1554.94	4.61166
1560.3	10.0872
1565.66	9.0888
1571.01	10.2402
1576.36	8.16628
1581.7	9.36109
1587.04	18.1038
1592.38	12.8653
1597.71	18.4285
1603.04	15.3831
1608.37	13.4398
1613.68	15.8711
1619	12.8975
1624.31	13.1838
1629.62	13.4645
1634.93	17.0278
1640.23	12.7923
1645.52	16.2735
1650.81	14.2085
1656.1	18.7674
1661.39	12.2133
1666.67	16.7337
1671.94	14.5908
1677.22	12.4362
1682.48	5.83715
1687.75	15.8326
1693.01	9.22703
1698.26	12.6309
1703.52	7.31952
1708.77	4.21717
1714.01	5.32662
1719.25	11.084
1724.49	7.84747
1729.72	5.74254
1734.95	10.3715
1740.18	8.25129
1745.4	3.86301
1750.61	5.09213
1755.83	13.0983
1761.04	5.23349
1766.24	7.5514
1771.44	11.0115
1776.64	9.94847
1781.84	6.63663
1787.02	9.01456
1792.21	4.58123
1797.39	6.98805
1802.57	5.98405
1807.75	10.7156
1812.92	8.53521
1818.08	8.65421
1823.25	2.98783
1828.41	11.2108
1833.56	3.20784
1838.71	7.97708
1843.86	6.90789
1849	-0.0184784
1854.14	9.40786
1859.28	4.80791
1864.41	10.7745
1869.54	3.82271
1874.67	6.25092
1879.79	5.13689
1884.9	2.83158
1890.02	2.86933
1895.13	0.520939
1900.23	5.28419
1905.34	8.92325
1910.43	6.66187
1915.53	0.853333
1920.62	4.50643
1925.71	4.59192
1930.79	8.27591
1935.87	1.16423
1940.94	6.03875
1946.02	2.48849
1951.08	4.94159
1956.15	4.97303
1961.21	14.6397
1966.27	3.80991
1971.32	7.42321
1976.37	5.00774
1981.42	3.79877
1986.46	0.188339
1991.5	6.20511
1996.53	0.204632
2001.56	0.226021
2006.59	1.4632
2011.61	5.12076
2016.63	8.78717
2021.65	7.62801
2026.66	7.6987
2031.67	8.99643
2036.68	5.47036
2041.68	1.93341
2046.68	8.11509
2051.67	2.14143
2056.66	2.22807
2061.65	7.23019
2066.63	7.35328
2071.61	3.78463
2076.59	10.05
2081.56	6.46453
2086.53	5.3238
2091.49	11.6014
2096.46	6.77436
2101.41	3.17758
2106.37	3.31061
2111.32	-0.294468
2116.26	1.10211
2121.21	6.27919
2126.15	5.17763
2131.09	2.79774
2136.02	0.395733
2140.95	9.40929
2145.87	10.8168
2150.79	4.55916
2155.71	0.824753
2160.63	3.46095
2165.54	6.08716
2170.45	7.43118
2175.35	7.51641
2180.25	7.58637
2185.15	6.35783
2190.04	3.8607
2194.93	5.21973
2199.82	2.75562
2204.7	6.72319
2209.58	1.71291
2214.46	5.7192
2219.33	7.17094
2224.2	2.15242
2229.06	10.1022
2233.92	7.67134
2238.78	3.92196
2243.64	5.39099
2248.49	6.86982
2253.34	4.40496
2258.18	7.20807
2263.02	3.40915
2267.86	3.55245
2272.69	7.66369
2277.52	10.4446
2282.35	6.56444
2287.17	5.3223
2291.99	5.41026
2296.81	1.50715
2301.62	2.94507
2306.43	5.73965
2311.24	5.89071
2316.04	10.0743
2320.84	4.88879
2325.63	6.40997
2330.43	2.54435
2335.21	5.43743
2340	4.27589
2344.78	4.47893
2349.56	6.05905
2354.33	0.774298
2359.11	7.82651
2363.87	3.84786
2368.64	5.39003
2373.4	8.31849
2378.16	1.5422
2382.91	4.45252
2387.66	4.57028
2392.41	6.06565
2397.16	7.54933
2401.9	9.02855
2406.64	2.14884
2411.37	9.23176
2416.1	6.64532
2420.83	4.09928
2425.55	4.23342
2430.27	2.99142
2434.99	4.58036
2439.7	7.60367
2444.41	4.95166
2449.12	6.56376
2453.83	6.75142
2458.53	11.2427
2463.22	7.12326
2467.92	2.97407
2472.61	6.02921
2477.3	6.2002
2481.98	7.82229
2486.66	5.06603
2491.34	8.1339
2496.01	14.1425
2500.68	2.5702
2505.35	-0.237114
2510.01	7.23818
2514.67	8.83183
2519.33	7.48022
2523.99	9.08775
2528.64	10.6943
2533.28	6.38057
2537.93	6.51478
2542.57	5.16373
2547.21	0.827288
2551.84	12.9127
2556.47	4.07064
2561.1	10.198
2565.73	2.82587
2570.35	7.48707
2574.97	12.1708
2579.58	10.8007
2584.19	6.36491
2588.8	12.5381
2593.41	6.53863
2598.01	6.64207
2602.61	8.26316
2607.2	14.4614
2611.8	5.37419
2616.38	6.9746
2620.97	7.04845
2625.55	7.12493
2630.13	4.1434
2634.71	8.86464
2639.28	5.92176
2643.85	6.05664
2648.42	3.08682
2652.98	10.9971
2657.54	7.97647
2662.1	8.05847
2666.65	6.56026
2671.2	6.64137
2675.75	9.89972
2680.29	11.6741
2684.84	7.09945
2689.37	4.07337
2693.91	10.601
2698.44	9.06758
2702.97	-0.486601
2707.49	14.0548
2712.02	4.45495
2716.53	9.37279
2721.05	6.20301
2725.56	6.25204
2730.07	9.53458
2734.58	6.30955
2739.08	3.07167
2743.58	6.35241
2748.08	4.76013
2752.57	9.73475
2757.06	4.88479
2761.55	4.91271
2766.04	8.23881
2770.52	8.28095
2775	6.6825
2779.47	6.74532
2783.94	10.1494
2788.41	0.242865
2792.88	6.98037
2797.34	2.01007
2801.8	0.363682
2806.26	8.80266
2810.71	5.45425
2815.16	5.46287
2819.61	8.85188
2824.05	3.77737
2828.49	12.2703
2832.93	13.979
2837.37	5.46744
2841.8	8.87104
2846.23	10.583
2850.65	8.88387
2855.08	10.6251
2859.5	8.93606
2863.91	7.24877
2868.33	5.56042
2872.74	12.5358
2877.15	3.88479
2881.55	5.66529
2885.95	9.21796
2890.35	7.50926
2894.75	0.487215
2899.14	5.83039
2903.53	14.7532
2907.91	9.45027
2912.3	4.10003
2916.68	5.8783
2921.05	7.67269
2925.43	5.87909
2929.8	0.471182
2934.17	11.3294
2938.53	4.06349
2942.9	11.3069
2947.26	3.98866
2951.61	5.76639
2955.97	7.54722
2960.32	-1.64358
2964.66	0.133499
2969.01	3.75736
2973.35	9.23526
2977.69	3.68072
2982.03	-0.0466843
2986.36	3.62278
2990.69	3.60817
2995.01	3.59743
2999.34	5.46057
3003.66	9.21549
3007.98	7.36277
3012.29	7.37082
3016.6	5.50153
3020.91	5.52353
3025.22	13.1466
3029.52	1.69838
3033.82	7.4041
3038.12	7.36172
3042.41	7.33667
3046.71	7.29566
3051	9.17934
3055.28	5.27856
3059.56	5.23497
3063.84	5.18946
3068.12	14.8519
3072.39	10.9338
3076.67	12.8517
3080.93	6.96928
3085.2	16.7209
3089.46	6.92835
3093.72	16.7695
3097.98	20.7683
3102.23	16.876
3106.48	20.9229
3110.73	17.0319
3114.98	17.1193
3119.22	27.2624
3123.46	15.2967
3127.7	15.4075
3131.93	21.652
3136.16	21.8138
3140.39	17.8487
3144.61	30.3593
3148.84	22.2129
3153.06	13.9722
3157.27	20.278
3161.49	26.6214
3165.7	24.5994
3169.91	24.6535
3174.11	22.6141
3178.31	24.7444
3182.51	33.214
3186.71	33.2116
3190.9	35.3222
3195.1	35.3564
3199.28	48.2452
3203.47	37.7622
3207.65	44.4047
3211.83	36.0161
3216.01	44.9079
3220.18	42.9812
3224.36	54.1351
3228.52	36.8813
3232.69	41.4917
3236.85	39.4793
3241.01	46.3566
3245.17	55.5556
3249.33	55.8332
3253.48	44.8218
3257.63	53.9313
3261.77	47.4073
3265.92	52.1999
3270.06	50.2709
3274.2	48.2919
3278.33	46.121
3282.47	43.9484
3286.59	48.6585
3290.72	46.4785
3294.85	51.1946
3298.97	51.312
3303.09	37.5753
3307.2	44.6438
3311.32	56.3738
3315.43	54.1849
3319.54	49.6693
3323.64	59.1929
3327.74	50.0458
3331.84	57.3417
3335.94	45.8673
3340.04	50.8366
3344.13	55.7567
3348.22	58.2812
3352.3	79.8641
3356.39	58.6327
3360.47	61.2313
3364.54	73.4238
3368.62	59.2566
3372.69	64.2648
3376.76	54.7993
3380.83	74.2335
3384.89	71.9739
3388.96	72.1171
3393.02	74.6677
3397.07	72.418
3401.13	84.7289
3405.18	84.865
3409.23	75.2814
3413.27	80.2599
3417.31	94.9992
3421.36	92.6909
3425.39	87.9368
3429.43	88.1041
3433.46	78.5244
3437.49	88.5434
3441.52	76.5434
3445.54	89.1227
3449.56	94.4165
3453.58	84.9242
3457.6	72.9645
3461.61	73.3949
3465.63	68.8402
3469.63	76.772
3473.64	74.6244
3477.64	80.0607
3481.64	70.3585
3485.64	68.1908
3489.64	76.1661
3493.63	76.5287
3497.62	66.6351
3501.61	72.0298
3505.59	74.8433
3509.58	62.2027
3513.56	64.9097
3517.53	67.6151
3521.51	57.4645
3525.48	62.7519
3529.45	65.4629
3533.42	57.9466
3537.38	60.8034
3541.34	45.5647
3545.3	61.3542
3549.26	53.786
3553.21	48.7165
3557.16	54.0782
3561.11	54.2724
3565.06	44.0601
3569	49.5471
3572.94	41.9404
3576.88	47.4575
3580.82	47.7686
3584.75	63.9458
3588.68	64.3195
3592.61	70.0035
3596.54	51.7389
3600.46	49.3777
3604.38	25.5683
3608.3	31.1545
3612.21	31.3703
3616.13	31.5865
3620.04	29.0891
3623.94	23.828
3627.85	15.8382
3631.75	10.5325
3635.65	18.7613
3639.55	13.4834
3643.44	21.7952
3647.34	21.9977
3651.23	16.6677
3655.12	14.0723
3659	6.00925
3662.88	8.84563
3666.76	19.8914
3670.64	11.8131
3674.52	9.20084
3678.39	12.0872
3682.26	6.75338
3686.13	9.68
3689.99	1.56777
3693.85	7.26644
3697.71	1.87007
3701.57	10.381
3705.43	7.75333
3709.28	5.11737
3713.13	2.46161
3716.98	5.40871
3720.82	11.1793
3724.66	-0.00034523
3728.5	5.7643
3732.34	8.71517
3736.18	5.99136
3740.01	8.94573
3743.84	3.34439
3747.67	0.574623
3751.49	6.36602
3755.32	3.56927
3759.14	6.48516
3762.96	0.800419
3766.77	-2.02655
3770.58	12.3624
3774.4	3.80684
3778.2	0.983501
3782.01	12.5514
3785.81	3.98466
3789.61	1.15623
3793.41	4.10192
3797.21	21.5513
3801	4.24612
3804.79	7.23012
3808.58	4.39934
3812.37	7.38975
3816.15	7.45813
3819.93	7.52268
3823.71	7.57832
3827.49	7.62384
3831.26	1.78105
3835.04	4.77727
3838.8	1.85733
3842.57	4.86486
3846.34	7.85261
3850.1	1.91344
3853.86	10.82
3857.62	1.88993
3861.37	7.81182
3865.12	7.82032
3868.87	1.91512
3872.62	4.90566
3876.37	7.8835
3880.11	1.89414
3883.85	4.87688
3887.59	7.87088
3891.33	-1.11694
3895.06	4.90725
3898.79	7.93553
3902.52	4.94814
3906.25	1.9476
3909.97	4.9807
3913.69	5.00902
3917.41	8.0795
3921.13	-4.01922
3924.84	5.15669
3928.56	5.20711
3932.27	5.25128
3935.97	2.21884
3939.68	5.31963
3943.38	5.37712
3947.08	5.4337
3950.78	2.39934
3954.48	5.53089
3958.17	2.48071
3961.86	2.51254
3965.55	2.54578
3969.24	5.67105
3972.92	5.70524
3976.6	2.64533
3980.29	2.68465
3983.96	2.72441
3987.64	-0.327627
3991.31	5.93935
3994.98	9.12977
3998.65	9.2429