File: Data/3-Raman/processed/bu20-j-ff1-fi03-v_1800 (450-850nm)_532nm_edge_100%_x100_vis_lwd_h30um_60sx2_01.txt
#Acq. time (s)=	60
#Accumulations=	2
#Range (cm-¹)=	1200...2360
#Windows=	3
#Auto scanning=	Off
#Autofocus=	Off
#Macrospot=	Off
#AutoExposure=	Off
#Spike filter=	Multiple accum.
#Delay time (s)=	2
#Binning=	1
#Readout mode=	Signal
#DeNoise=	Off
#ICS correction=	On
#Dark correction=	Off
#Inst. Process=	Off
#Detector Gain=	Best Dynamic
#Detector ADC=	50 kHz HS
#Detector temperature (°C)=	-60.09
#Instrument=	LabRAM HR Evol
#Detector=	SIN-EM FIVIS
#Objective=	x100_VIS_LWD
#Grating=	1800 (450-850nm)
#ND Filter=	100%
#Laser=	532nm_Edge
#Hole=	30.0125
#Temperature=	0
#Range=	Visible
#StageXY=	75x50mm Scan+
#StageZ=	Z motor
#X (µm)=	0
#Y (µm)=	0
#Z (µm)=	-19.4
#Full time(mm:ss)=	6:25
#Project=	21_08_11
#Sample=	BU20
#Site=
#Title=	BU20-J-FF1-FI03-V_1800 (450-850nm)_532nm_Edge_100%_x100_VIS_LWD_H30um_60sX2
#Remark=
#Date=	11.08.2021 17:05
#Acquired=	11.08.2021 17:05:31
#Data Range:Extract=	16.12.2021 15:36:30
#Base:Fit=	16.12.2021 15:36:40
#Base:Fit=	16.12.2021 15:57:40
#Base:Sub=	16.12.2021 15:57:41
1201.69	-1.5374
1202.8	-2.44502
1203.91	-1.32266
1205.02	-0.167515
1206.14	-1.20135
1207.25	0.996418
1208.36	-3.21186
1209.47	3.28925
1210.58	6.54564
1211.69	0.191555
1212.8	-2.93911
1213.91	0.348042
1215.02	-1.681
1216.13	-0.55072
1217.24	0.56778
1218.35	-1.48218
1219.45	-1.39665
1220.56	0.819958
1221.67	3.00395
1222.78	4.09098
1223.89	5.19186
1225	8.4459
1226.1	9.60762
1227.21	8.57938
1228.32	21.1643
1229.43	25.6805
1230.53	35.1509
1231.64	39.3112
1232.74	62.4964
1233.85	64.712
1234.96	57.4976
1236.06	41.8342
1237.17	33.4504
1238.27	22.9654
1239.38	18.8387
1240.48	14.7413
1241.59	15.8677
1242.69	10.7365
1243.8	11.8812
1244.9	10.9
1246.01	18.2795
1247.11	19.4116
1248.21	17.375
1249.32	25.8353
1250.42	33.206
1251.52	31.1604
1252.63	29.1151
1253.73	28.1728
1254.83	24.1101
1255.93	23.1593
1257.03	9.67423
1258.14	21.2337
1259.24	12.9636
1260.34	15.1263
1261.44	14.1873
1262.54	28.863
1263.64	59.3677
1264.74	53.172
1265.84	16.6691
1266.94	4.24433
1268.04	3.33353
1269.14	2.38875
1270.24	8.72314
1271.34	8.79395
1272.44	4.73322
1273.54	0.660093
1274.64	8.09387
1275.74	5.054
1276.84	-1.13795
1277.93	0.021925
1279.03	6.43528
1280.13	17.0291
1281.23	39.2551
1282.33	106.717
1283.42	501.692
1284.52	1195.61
1285.62	143.863
1286.71	28.0949
1287.81	19.7302
1288.91	11.4081
1290	8.35311
1291.1	5.26543
1292.19	3.23872
1293.29	2.28376
1294.38	5.544
1295.48	4.62439
1296.57	1.55247
1297.67	1.60517
1298.76	-0.437195
1299.86	2.80975
1300.95	-0.280514
1302.04	-0.191137
1303.14	-2.23554
1304.23	-2.16054
1305.32	2.11802
1306.42	-3.09663
1307.51	1.20001
1308.6	-0.829088
1309.69	0.311775
1310.79	11.9958
1311.88	-1.63832
1312.97	0.543261
1314.06	-1.49736
1315.15	-1.41195
1316.24	1.82994
1317.33	0.851963
1318.43	-2.2405
1319.52	-0.0565166
1320.61	4.23034
1321.7	0.0493431
1322.79	3.26606
1323.88	0.178291
1324.97	1.30039
1326.06	-1.84317
1327.15	2.46967
1328.23	2.58215
1329.32	-1.56549
1330.41	-2.56492
1331.5	2.7341
1332.59	-0.388103
1333.68	0.699924
1334.76	-0.305542
1335.85	2.89088
1336.94	2.94609
1338.03	-7.48116
1339.11	3.05165
1340.2	4.17062
1341.29	-2.0514
1342.37	-0.959181
1343.46	-0.90037
1344.54	0.206308
1345.63	3.3777
1346.72	2.35912
1347.8	1.36229
1348.89	0.370056
1349.97	1.45731
1351.06	2.53785
1352.14	1.56595
1353.23	4.81651
1354.31	0.625906
1355.39	0.684631
1356.48	3.85855
1357.56	1.83009
1358.64	0.835785
1359.73	0.877888
1360.81	5.06792
1361.89	7.19197
1362.98	2.07725
1364.06	6.28792
1365.14	10.4679
1366.22	3.25688
1367.3	8.47005
1368.38	6.47198
1369.47	54.0848
1370.55	5.53734
1371.63	8.65261
1372.71	9.71169
1373.79	4.6062
1374.87	8.77832
1375.95	10.896
1377.03	10.9221
1378.11	8.97613
1379.19	15.2172
1380.27	17.2623
1381.35	21.3938
1382.43	16.2443
1383.51	26.5163
1384.59	54.2924
1385.66	127.333
1386.74	692.073
1387.82	2162.43
1388.9	176.773
1389.98	55.567
1391.05	29.9641
1392.13	18.7099
1393.21	20.7932
1394.28	17.7672
1395.36	14.7686
1396.44	10.7174
1397.51	12.8007
1398.59	11.8422
1399.66	4.74429
1400.74	15.0511
1401.82	14.1132
1402.89	14.2247
1403.97	9.12593
1405.04	13.2648
1406.12	21.4975
1407.19	34.8886
1408.27	94.432
1409.34	110.935
1410.41	26.8359
1411.49	14.5635
1412.56	7.50435
1413.63	4.44463
1414.71	10.6876
1415.78	9.71769
1416.85	7.72727
1417.92	6.75689
1419	9.89071
1420.07	7.86318
1421.14	7.89844
1422.21	5.9328
1423.28	1.80437
1424.36	6.97705
1425.43	6.02736
1426.5	7.08129
1427.57	6.07169
1428.64	9.19353
1429.71	8.23837
1430.78	5.24587
1431.85	2.21186
1432.92	2.23153
1433.99	7.38906
1435.06	3.3478
1436.13	1.33955
1437.2	2.40351
1438.26	11.6743
1439.33	3.53577
1440.4	1.54353
1441.47	5.68462
1442.54	2.66194
1443.61	3.72162
1444.67	6.86587
1445.74	2.80009
1446.81	-1.26422
1447.87	2.87923
1448.94	4.98073
1450.01	1.93612
1451.07	0.947981
1452.14	-1.06203
1453.21	4.11112
1454.27	0.0524349
1455.34	0.0970554
1456.4	-0.886608
1457.47	0.17342
1458.53	-0.805973
1459.6	0.260441
1460.66	2.34335
1461.73	3.39562
1462.79	3.41741
1463.86	0.399136
1464.92	1.43291
1465.98	1.45691
1467.05	3.5258
1468.11	1.52281
1469.17	1.5546
1470.24	0.561522
1471.3	-0.42738
1472.36	-2.42716
1473.42	2.69347
1474.48	2.73432
1475.55	1.75176
1476.61	0.763489
1477.67	2.83124
1478.73	1.83979
1479.79	-0.171312
1480.85	0.86713
1481.91	0.916605
1482.97	-2.08425
1484.04	3.01245
1485.1	0.948097
1486.15	6.0893
1487.22	-0.962795
1488.28	-0.938797
1489.33	1.11312
1490.39	1.14403
1491.45	2.18426
1492.51	2.21952
1493.57	2.25374
1494.63	0.268572
1495.69	0.283455
1496.74	-0.697979
1497.8	1.35476
1498.86	2.40264
1499.92	0.423555
1500.97	-0.557068
1502.03	2.50165
1503.09	2.52151
1504.14	0.542229
1505.2	2.5836
1506.26	3.61432
1507.31	0.631338
1508.37	2.67918
1509.42	0.699135
1510.48	3.74619
1511.53	2.73818
1512.59	-1.27456
1513.64	-0.232651
1514.7	0.797159
1515.75	1.81305
1516.81	0.837599
1517.86	3.88494
1518.92	0.913967
1519.97	2.95072
1521.02	-1.02535
1522.08	2.01056
1523.13	-0.981733
1524.18	0.0373383
1525.24	1.07549
1526.29	1.12078
1527.34	0.144802
1528.39	-0.83271
1529.44	2.19794
1530.5	0.232649
1531.55	1.26856
1532.6	-0.696146
1533.65	1.35036
1534.7	1.3749
1535.75	-2.62349
1536.8	2.39171
1537.85	0.407635
1538.9	1.44576
1539.95	0.512589
1541	0.542431
1542.05	9.56688
1543.1	2.56669
1544.15	1.5921
1545.2	-0.360546
1546.25	0.673616
1547.3	-0.295078
1548.35	1.73476
1549.39	-2.2725
1550.44	0.841782
1551.49	4.86025
1552.54	1.89034
1553.58	1.89401
1554.63	-1.10485
1555.68	1.9284
1556.73	-0.0491657
1557.77	0.971218
1558.82	-0.0220528
1559.87	0.993225
1560.91	-1.98045
1561.96	0.0578632
1563	0.0816002
1564.05	-0.880281
1565.09	-0.92108
1566.14	3.15309
1567.18	1.19318
1568.23	-0.78931
1569.27	3.22295
1570.32	0.252384
1571.36	-1.72776
1572.41	3.28274
1573.45	2.30054
1574.49	0.343742
1575.54	1.37527
1576.58	-1.60899
1577.62	0.390574
1578.67	0.409883
1579.71	-1.55578
1580.75	-2.53234
1581.79	0.472108
1582.84	-1.50023
1583.88	0.514686
1584.92	0.539261
1585.96	2.54451
1587	0.56815
1588.04	-0.401893
1589.08	-0.371009
1590.13	0.651037
1591.17	-0.321449
1592.21	-0.312083
1593.25	-0.309275
1594.29	-2.27916
1595.33	1.71528
1596.37	-0.248915
1597.41	1.76398
1598.44	-1.20549
1599.48	1.78249
1600.52	3.77146
1601.56	-5.13945
1602.6	-0.181079
1603.64	1.81073
1604.67	0.844467
1605.71	-2.97268
1606.75	-2.26631
1607.79	1.38162
1608.82	-0.985954
1609.86	2.41122
1610.9	-0.800426
1611.93	-0.4788
1612.97	-0.864732
1614.01	-0.67391
1615.04	1.21828
1616.08	-0.808685
1617.12	-0.682981
1618.15	0.130427
1619.19	-0.410802
1620.22	-1.23623
1621.26	-2.19063
1622.29	-0.491172
1623.33	-0.397869
1624.36	-0.871963
1625.39	-2.66868
1626.43	-1.24399
1627.46	-0.638847
1628.5	-0.264257
1629.53	-0.99811
1630.41	0.289659
1631.46	-1.65497
1632.5	2.3184
1633.55	-0.631244
1634.59	-2.58203
1635.64	0.388515
1636.68	-1.57162
1637.73	-1.55827
1638.77	0.426893
1639.82	-0.540468
1640.86	-2.48633
1641.91	-2.47223
1642.95	1.48106
1644	-0.476639
1645.04	2.49525
1646.08	0.541486
1647.12	0.553146
1648.17	7.45964
1649.21	0.601321
1650.25	2.59613
1651.29	0.651123
1652.34	-0.31928
1653.38	2.65302
1654.42	2.67474
1655.46	0.736279
1656.5	-0.228045
1657.54	-1.20312
1658.59	-0.207379
1659.63	2.75795
1660.67	1.79795
1661.71	-0.159979
1662.75	-0.115885
1663.79	-1.10419
1664.83	0.895041
1665.87	1.91357
1666.91	-0.0716524
1667.95	-0.0650644
1668.99	2.93083
1670.02	-0.0154924
1671.06	0.00667667
1672.1	2.00089
1673.14	0.0397339
1674.18	3.02854
1675.22	-2.88516
1676.25	-0.890215
1677.29	-2.85757
1678.33	0.114627
1679.37	1.11112
1680.4	-0.856563
1681.44	0.143746
1682.48	-2.80627
1683.51	0.170125
1684.55	4.12899
1685.58	1.17985
1686.62	-1.76367
1687.66	-0.766798
1688.69	1.21261
1689.73	0.227747
1690.76	2.2218
1691.8	0.264526
1692.83	0.267285
1693.87	-0.718734
1694.9	0.276736
1695.94	0.29463
1696.97	0.302363
1698	0.302438
1699.04	-0.673408
1700.07	2.28855
1701.1	-0.654128
1702.14	-0.65187
1703.17	-0.643596
1704.2	0.352936
1705.24	0.363757
1706.27	-0.616434
1707.3	-1.59891
1708.33	0.355611
1709.36	-3.55751
1710.4	-1.58547
1711.43	2.34856
1712.46	-0.591529
1713.49	2.33133
1714.52	-0.59374
1715.55	1.37649
1716.58	-0.577509
1717.61	-1.56387
1718.64	1.35649
1719.67	0.394996
1720.7	-1.55003
1721.73	-0.577828
1722.76	1.36306
1723.79	0.397676
1724.82	2.33406
1725.85	1.36053
1726.88	-0.574517
1727.9	0.40259
1728.93	-0.601673
1729.96	0.381211
1730.99	-1.528
1732.02	1.37825
1733.04	-0.556002
1734.07	-1.52861
1735.1	-0.570536
1736.13	2.3195
1737.15	0.396937
1738.18	-0.565228
1739.21	-1.53149
1740.23	1.3354
1741.26	0.374253
1742.28	0.378409
1743.31	-0.573627
1744.33	-1.52784
1745.36	2.30626
1746.38	1.34444
1747.41	0.384809
1748.44	-1.51511
1749.46	-0.543571
1750.48	1.38631
1751.51	-1.4779
1752.53	0.428695
1753.56	1.38094
1754.58	2.33241
1755.6	-1.48013
1756.63	-1.4858
1757.65	0.422482
1758.67	0.43511
1759.69	3.29708
1760.72	-0.507315
1761.74	0.444551
1762.76	-1.4451
1763.78	0.468054
1764.81	5.24763
1765.83	0.498213
1766.85	0.50308
1767.87	-0.447841
1768.89	1.44408
1769.91	1.44856
1770.93	0.514842
1771.95	4.33569
1772.97	2.44986
1773.99	3.41444
1775.01	0.573897
1776.03	3.45126
1777.05	0.59149
1778.07	1.54058
1779.09	2.48655
1780.11	0.597491
1781.13	-0.343927
1782.15	-0.328364
1783.17	1.59164
1784.18	0.655538
1785.2	0.663543
1786.22	-0.283707
1787.24	4.51508
1788.25	8.38931
1789.27	1.71024
1790.29	0.763095
1791.31	3.62869
1792.32	8.42666
1793.34	1.73227
1794.36	4.61131
1795.37	5.61225
1796.39	3.71162
1797.4	4.69034
1798.42	5.66207
1799.44	3.73504
1800.45	6.61467
1801.47	3.73902
1802.48	2.79278
1803.5	3.77062
1804.51	3.78697
1805.53	2.84558
1806.54	2.8595
1807.55	4.79361
1808.57	1.90962
1809.58	5.77419
1810.59	5.77831
1811.61	4.81953
1812.62	0.976286
1813.63	4.8512
1814.65	3.9091
1815.66	4.88602
1816.67	3.92667
1817.68	5.8492
1818.7	4.898
1819.71	4.91082
1820.72	6.85889
1821.73	5.90721
1822.74	3.98063
1823.75	5.91757
1824.76	3.99308
1825.77	8.84269
1826.78	3.03965
1827.8	4.98631
1828.81	4.98416
1829.82	3.0471
1830.83	8.86162
1831.83	7.909
1832.84	4.04594
1833.85	5.02345
1834.86	4.02645
1835.87	5.00193
1836.88	4.05591
1837.89	4.01165
1838.9	6.00204
1839.91	5.02295
1840.91	4.98871
1841.92	5.93032
1842.93	4.00496
1843.94	5.93668
1844.94	5.94018
1845.95	5.97326
1846.96	4.94999
1847.96	7.85442
1848.97	3.99032
1849.98	4.93369
1850.98	4.92119
1851.99	4.92052
1852.99	1.08139
1854	4.90722
1855.01	4.8947
1856.01	6.80462
1857.02	6.80447
1858.02	5.83824
1859.02	5.82324
1860.03	7.73933
1861.03	3.93032
1862.04	5.84445
1863.04	5.8301
1864.04	2.95388
1865.05	6.75782
1866.05	3.87132
1867.05	3.84762
1868.06	4.79244
1869.06	6.6966
1870.06	6.69528
1871.07	5.74445
1872.07	6.68735
1873.07	2.88253
1874.07	5.72001
1875.07	6.64991
1876.08	4.72999
1877.08	3.75675
1878.08	7.57721
1879.08	5.70783
1880.08	3.80574
1881.08	5.68842
1882.08	6.59436
1883.08	4.77498
1884.08	4.68816
1885.08	5.64719
1886.08	2.83329
1887.08	4.70627
1888.08	7.51401
1889.08	3.73017
1890.08	2.79654
1891.08	4.68324
1892.07	4.68142
1893.07	3.71825
1894.07	0.890237
1895.07	5.58969
1896.07	4.66185
1897.07	3.73264
1898.06	6.55224
1899.06	0.900067
1900.06	2.77576
1901.05	6.54631
1902.05	3.74187
1903.05	3.73759
1904.04	5.61636
1905.04	4.67545
1906.04	3.72288
1907.03	2.78217
1908.03	3.73024
1909.02	6.56196
1910.02	5.64718
1911.01	4.71945
1912.01	6.60216
1913	5.66282
1914	3.79764
1914.99	4.75499
1915.99	4.75379
1916.98	1.91408
1917.98	4.74615
1918.97	2.87986
1919.96	2.89486
1920.96	4.79605
1921.95	0.0734386
1922.94	4.79487
1923.94	1.00749
1924.93	3.84552
1925.92	1.97277
1926.91	1.04025
1927.9	2.94249
1928.9	0.10836
1929.89	1.07269
1930.88	2.02999
1931.87	2.02329
1932.86	1.06944
1933.85	1.09535
1934.84	2.09065
1935.83	3.99536
1936.83	3.9844
1937.82	2.06943
1938.81	2.08051
1939.8	1.13603
1940.79	2.11159
1941.78	1.14365
1942.76	1.16455
1943.75	1.16069
1944.74	1.17361
1945.73	-0.726098
1946.72	0.233402
1947.71	2.14385
1948.7	-0.721696
1949.69	0.248338
1950.67	1.22893
1951.66	-0.674275
1952.65	1.25344
1953.64	3.15368
1954.62	1.21452
1955.61	3.14782
1956.6	2.20868
1957.58	2.21991
1958.57	3.18177
1959.56	0.292706
1960.54	1.24413
1961.53	0.280309
1962.51	3.16243
1963.5	1.24553
1964.48	5.08787
1965.47	1.24953
1966.46	1.26051
1967.44	-0.659726
1968.43	1.26151
1969.41	-0.674422
1970.39	0.276124
1971.38	3.14854
1972.36	1.23299
1973.35	0.264503
1974.33	1.2205
1975.31	0.267676
1976.3	0.271319
1977.28	1.22674
1978.26	3.13596
1979.24	0.260358
1980.23	2.17284
1981.21	-1.66564
1982.19	1.20282
1983.17	0.233302
1984.16	0.228443
1985.14	1.16657
1986.12	2.03041
1987.1	-0.621933
1988.08	0.151193
1989.06	0.681663
1990.04	-0.0715513
1991.02	-0.618829
1992	-0.957662
1992.98	0.966811
1993.96	-0.180488
1994.94	0.232247
1995.92	-1.33119
1996.9	-0.00393677
1997.88	1.04128
1998.86	-0.330756
1999.84	0.728703
2000.82	-0.232279
2001.8	0.431976
2002.78	-1.44001
2003.76	-0.859228
2004.73	1.1444
2005.71	0.563317
2006.69	0.40129
2007.67	-0.444483
2008.64	1.66669
2009.62	-0.923128
2010.52	0.0117693
2011.51	-1.87441
2012.5	0.943941
2013.48	2.80169
2014.47	-0.038434
2015.46	3.72242
2016.45	-0.961084
2017.44	-0.0324163
2018.43	-2.86632
2019.41	1.80527
2020.4	-0.0713501
2021.39	-1.00813
2022.38	-1.95343
2023.36	0.840508
2024.35	-1.04387
2025.34	-0.126466
2026.32	1.75082
2027.31	0.841816
2028.3	1.7593
2029.28	1.76237
2030.27	0.786705
2031.25	2.66648
2032.24	-1.05449
2033.23	0.827404
2034.21	-2.00307
2035.2	-0.122517
2036.18	1.75291
2037.17	0.819916
2038.15	-0.123247
2039.13	-2.0009
2040.12	-1.08091
2041.1	1.70639
2042.09	-1.09842
2043.07	-2.96002
2044.05	-2.01987
2045.04	-2.02295
2046.02	-0.13112
2047	-1.0895
2047.99	0.763137
2048.97	-0.162212
2049.95	-1.08228
2050.93	-0.151195
2051.92	0.779919
2052.9	0.785863
2053.88	-2.00776
2054.86	0.794982
2055.84	0.786758
2056.82	-1.08593
2057.8	-0.146042
2058.78	-0.137121
2059.77	-1.07493
2060.75	-0.140096
2061.73	0.79708
2062.71	-1.07114
2063.69	-0.129721
2064.67	-1.99947
2065.65	0.826504
2066.63	-0.109048
2067.61	-0.103956
2068.58	-0.101689
2069.56	-0.116776
2070.54	1.7833
2071.52	-1.02683
2072.5	-0.0905476
2073.48	0.849629
2074.45	-0.0853548
2075.43	-0.0655394
2076.41	-1.95391
2077.39	-0.0805864
2078.37	-1.01929
2079.34	-3.84217
2080.32	1.82996
2081.3	1.82493
2082.27	-0.0642462
2083.25	-1.0122
2084.23	0.876044
2085.2	-0.0704384
2086.18	1.83091
2087.15	0.889664
2088.13	-1.00387
2089.11	1.84007
2090.08	-0.049592
2091.06	-0.046133
2092.03	1.86554
2093	0.930171
2093.98	-0.0131664
2094.95	-0.0192871
2095.93	0.922033
2096.9	1.86353
2097.88	-0.992028
2098.85	1.8503
2099.82	-0.0501499
2100.8	-0.0444918
2101.77	-2.8941
2102.74	1.84623
2103.72	-1.00614
2104.69	-0.0521212
2105.66	0.90523
2106.63	-0.0437384
2107.6	-1.00355
2108.58	-0.0662575
2109.55	-1.01182
2110.52	-1.01414
2111.49	-0.0706997
2112.46	-0.071106
2113.43	-0.0647888
2114.4	0.881628
2115.38	1.82659
2116.35	-0.0836391
2117.32	0.86139
2118.29	-0.102171
2119.26	1.78011
2120.23	-0.1224
2121.2	-1.06351
2122.17	0.841237
2123.14	0.843744
2124.1	0.832275
2125.07	-1.08768
2126.04	1.7356
2127.01	1.72249
2127.98	1.71581
2128.95	2.65667
2129.92	3.59558
2130.88	0.751885
2131.85	2.6303
2132.82	-2.09785
2133.79	0.73228
2134.75	-1.15861
2135.72	1.66015
2136.69	-0.232989
2137.65	1.65361
2138.62	-1.17757
2139.59	0.694096
2140.55	0.685019
2141.52	3.49946
2142.49	0.67661
2143.45	-0.294264
2144.42	0.65723
2145.38	1.58751
2146.35	-2.17982
2147.31	2.5091
2148.28	-0.318098
2149.24	4.35619
2150.21	2.46484
2151.17	1.52984
2152.14	3.40558
2153.1	-0.355957
2154.06	2.43939
2155.03	3.34675
2155.99	5.19845
2156.95	3.32749
2157.92	1.46377
2158.88	1.45681
2159.84	2.37482
2160.8	4.2292
2161.77	3.28942
2162.73	4.21517
2163.69	2.33993
2164.65	6.05487
2165.61	3.25875
2166.58	3.24605
2167.54	5.08395
2168.5	4.14139
2169.46	4.15552
2170.42	6.02553
2171.38	2.27548
2172.34	4.11761
2173.3	6.90241
2174.26	2.25784
2175.22	5.96941
2176.18	4.10204
2177.14	5.95663
2178.1	5.94662
2179.06	7.79757
2180.02	5.93683
2180.98	4.07291
2181.94	4.99042
2182.9	5.90327
2183.85	5.88484
2184.81	4.03141
2185.77	4.96514
2186.73	5.90981
2187.69	6.84371
2188.64	5.89592
2189.6	4.94642
2190.56	4.01888
2191.52	6.80202
2192.47	5.87982
2193.43	4.96728
2194.39	5.91012
2195.34	6.82461
2196.3	5.86926
2197.26	5.85664
2198.21	6.79379
2199.17	4.95758
2200.12	6.84986
2201.08	6.85656
2202.03	5.84751
2202.99	6.81175
2203.94	7.79768
2204.9	7.74693
2205.85	11.4547
2206.81	4.00951
2207.76	7.74311
2208.71	5.89068
2209.67	4.95758
2210.62	4.96522
2211.57	4.97575
2212.53	4.97334
2213.48	7.76044
2214.43	5.9137
2215.39	6.84834
2216.34	6.84335
2217.29	7.77465
2218.24	5.90655
2219.2	6.84949
2220.15	8.71845
2221.1	4.96487
2222.05	8.68513
2223	7.75981
2223.95	7.78045
2224.91	8.73295
2225.86	5.00287
2226.81	5.01279
2227.76	8.76159
2228.71	6.87782
2229.66	5.95016
2230.61	7.83988
2231.56	5.03579
2232.51	5.04658
2233.46	7.87947
2234.41	7.87288
2235.36	5.97247
2236.31	7.85393
2237.25	5.04531
2238.2	6.00931
2239.15	6.96163
2240.1	7.885
2241.05	6.01455
2242	4.12984
2242.94	6.01353
2243.89	7.8932
2244.84	6.97104
2245.79	6.98484
2246.73	6.04671
2247.68	6.04468
2248.63	4.14408
2249.57	9.8236
2250.52	5.07332
2251.47	5.06341
2252.41	6.967
2253.36	6.04558
2254.3	7.00047
2255.25	6.04857
2256.2	4.15868
2257.14	5.11587
2258.09	5.11732
2259.03	5.12269
2259.98	2.27463
2260.92	4.18597
2261.86	3.2354
2262.81	7.0559
2263.75	6.12793
2264.7	3.28051
2265.64	3.27951
2266.58	2.30574
2267.53	5.15192
2268.47	3.23973
2269.41	6.11789
2270.36	1.35502
2271.3	5.18641
2272.24	2.31912
2273.18	4.23259
2274.13	4.23233
2275.07	7.10516
2276.01	4.23967
2276.95	1.37612
2277.89	3.31292
2278.84	5.22936
2279.78	3.28436
2280.72	4.22758
2281.66	6.14008
2282.6	3.27383
2283.54	4.25735
2284.48	4.27278
2285.42	3.3085
2286.36	5.22567
2287.3	5.24275
2288.24	2.34742
2289.18	2.32394
2290.12	3.27057
2291.06	1.35515
2292	1.36242
2292.93	4.26099
2293.87	1.36529
2294.81	4.24081
2295.75	4.22506
2296.69	2.29193
2297.63	0.377516
2298.56	-3.47194
2299.5	0.386969
2300.44	1.35124
2301.38	2.3171
2302.31	3.27515
2303.25	4.23451
2304.19	-0.588369
2305.12	0.379787
2306.06	-1.55251
2307	1.34082
2307.93	1.33054
2308.87	-0.60152
2309.8	1.34016
2310.74	2.29752
2311.68	0.332928
2312.61	0.321598
2313.55	0.332503
2314.48	1.31368
2315.41	2.26755
2316.35	3.20843
2317.28	3.2097
2318.22	0.300576
2319.15	1.25248
2320.09	1.2469
2321.02	4.14779
2321.95	3.19574
2322.89	2.22713
2323.82	8.99288
2324.75	12.8304
2325.69	24.3863
2326.62	34.957
2327.55	105.278
2328.48	296.074
2329.42	59.9173
2330.35	18.4942
2331.28	4.04969
2332.21	3.0749
2333.14	0.173452
2334.07	3.04485
2335.01	2.07215
2335.94	2.06651
2336.87	3.01958
2337.8	2.04906
2338.73	2.04355
2339.66	2.03451
2340.59	5.8566
2341.52	-0.885488
2342.45	1.97853
2343.38	-0.903942
2344.31	1.00911
2345.24	0.994896
2346.17	0.0243025
2347.1	-0.941855
2348.02	-2.85898
2348.95	-0.000899315
2349.88	1.87201
2350.81	-0.0225258
2351.74	0.898915
2352.67	-0.0901566
2353.59	-2.001
2354.52	0.857066
2355.45	-2.01157
2356.38	-0.130841
2357.3	0.804494
2358.23	3.64115
2359.16	2.6795
2359.85	-1.13197