File: Data/3-Raman/processed/bu20-G-trl1-FI02-v.txt
#Acq. time (s)=	15
#Accumulations=	3
#Range (cm-¹)=	100...4000
#Windows=	1
#Auto scanning=	Off
#Autofocus=	Off
#Macrospot=	Off
#AutoExposure=	Off
#Spike filter=	Multiple accum.
#Delay time (s)=	0
#Binning=	1
#Readout mode=	Signal
#DeNoise=	Lite
#ICS correction=	Off
#Dark correction=	Off
#Inst. Process=	Off
#Detector temperature (°C)=	-60.09
#Instrument=	LabRAM HR Evol
#Detector=	SIN-EM FIVIS
#Objective=	x100_VIS
#Grating=	150 (500nm)
#ND Filter=	100%
#Laser=	532nm_Edge
#Hole=	30.0125
#Temperature=	0
#Range=	Visible
#StageXY=	75x50mm Scan+
#StageZ=	Z motor
#X (µm)=	19541.8
#Y (µm)=	6129.6
#Z (µm)=	1894.4
#Full time(s)=	49
#Project=	Buranga
#Sample=	BU18FA20_G
#Site=	G_trl1
#Title=	20-G_trl1_FI02
#Remark=
#Date=	30.07.2019 17:33
#Acquired=	30.07.2019 17:33:35
#Data Range:Extract=	16.12.2021 15:36:30
#Base:Fit=	16.12.2021 15:36:40
#Base:Sub=	16.12.2021 15:46:02
103.656	4475.9
108.278	3824.42
112.899	3270.01
117.517	2770.77
122.131	2323.69
126.744	1934.43
131.355	1623.34
135.964	1368.46
140.571	1170.05
145.173	1011.58
149.776	904.322
154.375	702.999
158.973	868.584
163.566	1500.34
168.159	2228.06
172.75	1926.26
177.339	898.163
181.923	348.403
186.507	324.338
191.089	678.826
195.668	1228.67
200.243	1527.39
204.818	996.549
209.391	532.65
213.96	218.504
218.528	39.2364
223.094	-0.000427246
227.655	96.4851
232.217	323.171
236.776	694.128
241.331	1204.07
245.886	1818.81
250.439	2550.51
254.987	3181.91
259.535	2275.13
264.081	1148.8
268.622	649.963
273.164	744.151
277.703	1476.09
282.238	3554.49
286.773	5839.69
291.305	5616.71
295.833	3249.9
300.362	1950.62
304.885	1241.43
309.409	863.807
313.93	683.254
318.448	562.57
322.965	1053.29
327.477	1532.65
331.99	1935.23
336.5	2273.46
341.007	2566.38
345.513	2751.08
350.014	2874.19
354.516	3038.19
359.013	3161.61
363.51	2852.86
368.005	2336.57
372.496	1909.4
376.987	1569.43
381.473	1304.76
385.96	1094.77
390.442	952.527
394.923	952.671
399.401	1034.44
403.879	1041.97
408.352	790.551
412.825	466.626
417.294	200.691
421.763	311.633
426.227	308.502
430.692	204.238
435.152	110.606
439.612	37.7129
444.068	0.656525
448.524	-0.671509
452.976	24.0706
457.427	77.987
461.874	161.103
466.32	187.526
470.765	209.129
475.205	223.713
479.646	218.62
484.083	278.557
488.519	430.15
492.951	683.157
497.381	913.058
501.811	1132.3
506.237	1275.99
510.663	1118.17
515.084	865
519.504	560.236
523.923	364.106
528.338	205.267
532.753	135.46
537.164	97.8531
541.572	80.6869
545.981	75.6125
550.385	84.6755
554.788	111.131
559.19	135.674
563.588	163.404
567.986	227.418
572.38	189.949
576.771	181.697
581.163	202.413
585.551	343.784
589.936	651.88
594.319	1329.8
598.702	1843.45
603.081	1376.56
607.458	759.225
611.835	650.373
616.208	593.744
620.578	551.474
624.949	467.128
629.315	380.635
633.68	326.031
638.042	300.735
642.404	308.792
646.762	346.542
651.118	411.471
655.472	508.04
659.825	649.029
664.175	861.013
668.523	1206.79
672.868	1593.5
677.213	1907.66
681.555	2036.99
685.894	1929.67
690.231	1560.87
694.566	1056.1
698.901	598.468
703.232	306.611
707.561	146.702
711.888	77.1205
716.212	47.903
720.537	39.1668
724.858	34.2245
729.176	34.8526
733.493	37.7143
737.807	44.8265
742.119	55.334
746.432	68.0316
750.74	85.0336
755.046	104.591
759.35	153.927
763.652	228.341
767.952	392.421
772.25	691.586
776.546	1108.39
780.842	1838.1
785.133	2717.84
789.423	2870.82
793.711	2057.91
797.997	1277.42
802.28	757.431
806.562	431.572
810.841	295.042
815.119	210.413
819.394	150.171
823.668	118.853
827.941	90.1418
832.211	68.5266
836.478	50.4489
840.743	36.9822
845.006	26.7175
849.268	19.0977
853.527	13.1186
857.784	8.75607
862.039	5.96231
866.293	4.52559
870.544	4.01633
874.793	4.53278
879.04	4.74519
883.285	2.6924
887.528	0.600769
891.769	-0.471512
896.008	0.518707
900.246	5.92209
904.481	10.4762
908.714	14.7787
912.945	19.7431
917.174	23.4623
921.401	28.6958
925.626	43.4079
929.849	56.4163
934.068	79.3957
938.287	136.248
942.504	203.613
946.72	384.737
950.933	580.406
955.144	805.011
959.353	894.184
963.56	751.553
967.765	577.576
971.968	407.334
976.17	316.743
980.367	252.372
984.564	217.72
988.759	187.588
992.953	162.802
997.144	144.041
1001.33	130.575
1005.52	123.346
1009.71	122.303
1013.89	127.646
1018.07	139.263
1022.25	154.706
1026.43	178.781
1030.6	214.711
1034.78	254.315
1038.94	300.432
1043.11	436.025
1047.28	685.273
1051.45	1104.27
1055.61	1901.27
1059.77	2859.05
1063.93	2985.1
1068.09	2118.85
1072.25	1381.35
1076.4	973.725
1080.55	797.675
1084.7	879.61
1088.85	1201.56
1092.99	1912.34
1097.14	2198.41
1101.28	2361.84
1105.42	2491.58
1109.56	2589.35
1113.69	2688.45
1117.83	2755.48
1121.96	2807.48
1126.09	2831.42
1130.22	2805.45
1134.35	2793.63
1138.47	2897.47
1142.59	2908.72
1146.71	2536.59
1150.83	1904.43
1154.95	1554.64
1159.06	1590.12
1163.18	1849.2
1167.29	1962.62
1171.4	1812.55
1175.5	1537.57
1179.61	1273.44
1183.71	984.635
1187.81	664.29
1191.91	411.326
1196.01	368.364
1200.1	338.328
1204.2	320.485
1208.29	307.722
1212.38	299.638
1216.47	311.337
1220.55	375.529
1224.64	506.687
1228.72	751.612
1232.8	818.617
1236.88	773.259
1240.95	665.911
1245.03	737.745
1249.1	785.359
1253.17	813.347
1257.24	819.72
1261.31	802.682
1265.37	755.553
1269.44	551.058
1273.5	672.62
1277.56	2435.32
1281.61	4327.02
1285.67	4112.71
1289.72	1618.4
1293.77	481.045
1297.83	386.118
1301.87	344.269
1305.92	311.559
1309.96	290.532
1314.01	275.306
1318.05	260.242
1322.09	247.661
1326.12	238.475
1330.16	232.61
1334.19	229.865
1338.22	230.775
1342.25	235.457
1346.28	244.656
1350.3	255.487
1354.33	274.714
1358.35	308.254
1362.37	365.751
1366.39	430.097
1370.4	473.825
1374.42	486.091
1378.43	1451.1
1382.44	5397.09
1386.45	6744.28
1390.46	5176.69
1394.46	1202.51
1398.46	505.352
1402.47	732.405
1406.46	813.313
1410.46	702.905
1414.46	405.502
1418.45	255.802
1422.45	224.249
1426.43	188.677
1430.42	159.742
1434.41	134.091
1438.39	110.859
1442.38	90.2719
1446.36	71.7481
1450.34	55.5581
1454.31	42.3949
1458.29	31.8428
1462.27	22.6572
1466.24	17.1037
1470.21	12.4232
1474.18	8.82413
1478.14	5.84166
1482.11	3.47078
1486.07	1.58946
1490.03	0.0990906
1493.99	-0.293671
1497.95	-0.158936
1501.9	0.444122
1505.86	1.58673
1509.81	2.29462
1513.76	2.08243
1517.71	1.0114
1521.65	0.128998
1525.6	-0.576569
1529.54	-0.816864
1533.48	-0.00868225
1537.42	0.925964
1541.36	1.79547
1545.29	2.14151
1549.23	2.56873
1553.16	2.74542
1557.09	2.92741
1561.02	4.01645
1564.94	5.20421
1568.87	7.02911
1572.79	8.42624
1576.71	8.41223
1580.63	7.75288
1584.55	6.67511
1588.47	5.36591
1592.38	4.51451
1596.29	4.13081
1600.2	4.21492
1604.11	4.91728
1608.02	5.88861
1611.92	6.29852
1615.83	5.42377
1619.73	4.53542
1623.63	3.85475
1627.53	3.74582
1631.42	6.36403
1635.32	4.96562
1639.21	4.41788
1643.1	4.43723
1646.99	6.37019
1650.88	7.94003
1654.76	8.58218
1658.64	7.25409
1662.53	5.98904
1666.41	4.97746
1670.28	4.22493
1674.16	3.54559
1678.04	3.08658
1681.91	2.99295
1685.78	2.62956
1689.65	0.839302
1693.52	-0.417931
1697.38	-0.786057
1701.25	-0.0937042
1705.11	1.23911
1708.97	2.83524
1712.83	4.46457
1716.69	5.79012
1720.54	6.80729
1724.4	7.35149
1728.25	7.46576
1732.1	7.3585
1735.95	7.31525
1739.79	7.23686
1743.64	7.11191
1747.48	6.92812
1751.33	6.53151
1755.17	4.78438
1759	3.74849
1762.84	3.40258
1766.68	5.13129
1770.51	7.13156
1774.34	9.79483
1778.17	13.7117
1782	14.4373
1785.82	13.6039
1789.65	12.1529
1793.47	10.1687
1797.29	8.18102
1801.11	6.94769
1804.93	5.83091
1808.74	5.32996
1812.56	4.2022
1816.37	4.39981
1820.18	4.94977
1823.99	5.70625
1827.79	5.76588
1831.6	6.86183
1835.4	8.00146
1839.2	9.15106
1843	10.2531
1846.8	11.3375
1850.6	12.4077
1854.39	13.3988
1858.19	14.3879
1861.98	15.0044
1865.77	13.7283
1869.56	12.3661
1873.34	10.4888
1877.13	10.7689
1880.91	12.0533
1884.69	14.476
1888.47	15.8831
1892.25	16.0198
1896.03	15.0648
1899.8	13.3304
1903.57	10.8352
1907.34	9.30239
1911.11	8.62663
1914.88	9.70461
1918.65	11.5323
1922.41	11.854
1926.18	11.0934
1929.94	9.59633
1933.7	7.23535
1937.45	5.38623
1941.21	4.31683
1944.96	4.47552
1948.72	4.78405
1952.47	5.29042
1956.22	4.7671
1959.96	4.76102
1963.71	5.14024
1967.45	5.16679
1971.2	4.95689
1974.94	4.4625
1978.68	4.05946
1982.42	1.80986
1986.15	-1.02233
1989.89	-0.81633
1993.62	0.279701
1997.35	2.49612
2001.08	4.55463
2004.8	5.22829
2008.53	6.33218
2012.25	5.62292
2015.98	4.49568
2019.7	3.38776
2023.42	2.51814
2027.13	1.84107
2030.85	1.31305
2034.56	0.789986
2038.28	0.389702
2041.99	0.134758
2045.7	0.44529
2049.41	1.56168
2053.11	2.88505
2056.82	4.2818
2060.52	5.84679
2064.22	7.23743
2067.92	6.92934
2071.62	5.85105
2075.31	4.10069
2079.01	2.46821
2082.7	1.1347
2086.39	0.299377
2090.08	1.64816
2093.77	3.40011
2097.45	5.15035
2101.14	6.64066
2104.82	6.40692
2108.5	4.89013
2112.18	3.47934
2115.86	2.2987
2119.54	2.47205
2123.21	3.36459
2126.88	4.72998
2130.56	5.83221
2134.23	6.86134
2137.89	8.68431
2141.56	10.8199
2145.23	12.3479
2148.89	13.5598
2152.55	14.376
2156.21	14.843
2159.87	15.9393
2163.53	18.1956
2167.18	21.4023
2170.84	25.1948
2174.49	28.4401
2178.14	32.4588
2181.79	34.885
2185.44	38.4929
2189.08	41.758
2192.73	44.7427
2196.37	47.5635
2200.01	50.6343
2203.65	52.344
2207.29	53.1794
2210.92	54.0593
2214.56	54.901
2218.19	56.2851
2221.82	58.3538
2225.45	60.7336
2229.08	63.3313
2232.7	65.4982
2236.33	67.7818
2239.95	67.1013
2243.57	62.2671
2247.19	55.3715
2250.81	47.4527
2254.43	39.7886
2258.04	34.2892
2261.66	30.7882
2265.27	28.1914
2268.88	26.3596
2272.49	25.8807
2276.1	25.1748
2279.7	25.1506
2283.31	24.4719
2286.91	23.8325
2290.51	23.5252
2294.11	23.0391
2297.71	24.2158
2301.3	23.6961
2304.9	23.349
2308.49	24.5589
2312.08	32.7403
2315.67	51.0538
2319.26	131.447
2322.85	545.5
2326.43	991.554
2330.02	816.609
2333.6	267.664
2337.18	63.0259
2340.76	40.1551
2344.34	30.2377
2347.91	22.8092
2351.49	19.2591
2355.06	17.7076
2358.63	17.932
2362.2	18.6965
2365.77	19.8855
2369.33	20.6367
2372.9	21.4552
2376.46	21.9568
2380.02	22.0213
2383.58	21.5949
2387.14	21.0017
2390.7	20.0571
2394.25	18.9077
2397.81	17.5262
2401.36	16.8527
2404.91	17.2028
2408.46	17.7397
2412.01	18.1938
2415.56	18.3239
2419.1	18.1222
2422.64	17.8592
2426.18	17.3248
2429.72	17.0324
2433.26	16.3441
2436.8	15.309
2440.34	13.6882
2443.87	11.9504
2447.4	10.279
2450.93	8.82358
2454.46	7.80498
2457.99	7.20599
2461.52	7.14997
2465.04	7.65643
2468.56	8.31725
2472.09	8.72774
2475.61	8.70138
2479.13	8.38075
2482.64	7.77133
2486.16	6.96089
2489.67	5.88432
2493.18	4.96234
2496.69	4.24949
2500.2	3.63064
2503.71	3.13216
2507.22	2.68535
2510.72	3.40662
2514.23	4.54675
2517.73	5.36845
2521.23	5.85584
2524.73	6.55354
2528.23	7.08339
2531.72	6.64102
2535.21	5.65006
2538.71	5.10413
2542.2	4.43208
2545.69	3.60197
2549.18	4.02373
2552.66	4.69859
2556.15	5.19813
2559.63	6.46538
2563.12	7.07377
2566.6	6.72173
2570.08	5.25694
2573.55	1.54567
2577.03	-0.0122681
2580.5	-1.31412
2583.98	0.766106
2587.45	3.17116
2590.92	5.98538
2594.39	8.8878
2597.86	5.57178
2601.32	3.7076
2604.79	3.02858
2608.25	2.84265
2611.71	1.98351
2615.17	1.39101
2618.63	0.99427
2622.08	-1.1667
2625.54	-1.78176
2628.99	-1.75943
2632.45	-0.376564
2635.9	3.20692
2639.35	2.88589
2642.79	2.68397
2646.24	3.75735
2649.69	5.18475
2653.13	5.76568
2656.57	5.06827
2660.01	4.80207
2663.45	3.99267
2666.89	3.83924
2670.32	4.61686
2673.76	5.22993
2677.19	5.76371
2680.62	6.24667
2684.05	6.0153
2687.48	5.43918
2690.91	5.12464
2694.33	5.82165
2697.76	5.82016
2701.18	5.04382
2704.6	3.55239
2708.02	2.17466
2711.44	1.26228
2714.86	0.995773
2718.27	1.54533
2721.69	2.51285
2725.1	2.41682
2728.51	2.12079
2731.92	1.8189
2735.33	2.56746
2738.74	3.12749
2742.14	3.25867
2745.55	3.4697
2748.95	3.45284
2752.35	2.22408
2755.75	2.95901
2759.15	3.73762
2762.54	4.26909
2765.94	4.49399
2769.33	4.30241
2772.72	3.76651
2776.12	2.93756
2779.51	1.93722
2782.89	1.14609
2786.28	0.598381
2789.67	0.230133
2793.05	0.496841
2796.43	1.38875
2799.81	2.86169
2803.19	5.32582
2806.57	7.3962
2809.95	8.58386
2813.32	8.72805
2816.69	7.80728
2820.06	6.57796
2823.44	4.72758
2826.81	3.77332
2830.17	3.37745
2833.54	5.16327
2836.9	7.01868
2840.27	8.57189
2843.63	10.1395
2846.99	10.3644
2850.35	9.33624
2853.71	6.73694
2857.06	4.01973
2860.42	2.19448
2863.77	1.69708
2867.12	3.78235
2870.48	4.72762
2873.83	5.66461
2877.17	6.85412
2880.52	6.96901
2883.86	7.37584
2887.21	7.84878
2890.55	8.57222
2893.89	9.09912
2897.23	9.1359
2900.57	8.80358
2903.91	8.26855
2907.24	7.50424
2910.57	6.68571
2913.91	6.92067
2917.24	7.27989
2920.57	7.70604
2923.9	8.02094
2927.22	8.32436
2930.55	7.89774
2933.87	7.19852
2937.19	6.53323
2940.51	5.86445
2943.83	5.44975
2947.15	5.07101
2950.47	5.07597
2953.79	5.33255
2957.1	5.79585
2960.41	7.5928
2963.72	7.6546
2967.03	7.17008
2970.34	7.05975
2973.65	6.47192
2976.95	6.51727
2980.26	6.81357
2983.56	7.29789
2986.86	8.06443
2990.16	8.8182
2993.46	9.26868
2996.76	9.4127
3000.06	9.29501
3003.35	8.95206
3006.64	8.17834
3009.94	6.21149
3013.23	3.85503
3016.51	1.98412
3019.8	0.73526
3023.09	0.431999
3026.38	0.308434
3029.66	0.227829
3032.94	0.0440445
3036.22	-0.0439835
3039.5	-0.0248642
3042.78	0.296852
3046.05	0.847458
3049.33	1.17905
3052.6	0.866478
3055.88	-0.790833
3059.15	-1.44234
3062.42	-1.26592
3065.69	-0.82653
3068.95	0.0588226
3072.22	0.00140381
3075.48	-0.0908356
3078.75	-0.293617
3082.01	-0.484596
3085.27	-0.56102
3088.53	-0.727478
3091.79	-0.173363
3095.04	0.500488
3098.3	0.998436
3101.55	1.26825
3104.8	1.23217
3108.05	0.292191
3111.3	0.23259
3114.55	0.618271
3117.8	1.65764
3121.04	2.63776
3124.29	3.17506
3127.53	3.80739
3130.77	4.46565
3134.01	4.99506
3137.25	5.60887
3140.49	6.35912
3143.72	7.43103
3146.96	8.5563
3150.19	9.81346
3153.42	11.0782
3156.65	12.0467
3159.88	13.2921
3163.11	14.0362
3166.34	14.2601
3169.56	13.9447
3172.79	13.1366
3176.01	12.9548
3179.23	14.7777
3182.45	17.6704
3185.67	20.3166
3188.88	23.2345
3192.1	23.8863
3195.31	24.1318
3198.53	24.5804
3201.74	24.9556
3204.95	25.2827
3208.16	25.7253
3211.37	26.367
3214.57	26.8414
3217.78	26.5696
3220.98	26.1905
3224.18	25.9428
3227.39	26.2884
3230.59	27.4699
3233.78	29.313
3236.98	31.7837
3240.18	35.1501
3243.37	38.7726
3246.56	41.0753
3249.76	42.8793
3252.95	44.5606
3256.14	46.3723
3259.32	48.737
3262.51	50.6939
3265.7	51.9003
3268.88	51.5938
3272.06	51.0578
3275.24	50.5621
3278.42	49.5489
3281.6	48.6821
3284.78	48.505
3287.96	49.3891
3291.13	50.6075
3294.31	52.0053
3297.48	52.9383
3300.65	55.0183
3303.82	57.8177
3306.99	60.7532
3310.15	64.1886
3313.32	64.6995
3316.48	65.4543
3319.65	66.4315
3322.81	68.878
3325.97	71.6969
3329.13	75.3634
3332.28	79.7098
3335.44	84.5396
3338.6	89.8486
3341.75	94.29
3344.9	98.788
3348.05	103.407
3351.2	108.39
3354.35	113.884
3357.5	120.351
3360.65	127.445
3363.79	135.236
3366.94	144.048
3370.08	153.389
3373.22	163.38
3376.36	165.187
3379.5	167.983
3382.63	172.95
3385.77	185.662
3388.9	206.374
3392.04	234.096
3395.17	268.036
3398.3	305.878
3401.43	323.232
3404.56	389.836
3407.69	487.706
3410.81	636.53
3413.94	897.579
3417.06	1406.63
3420.18	2639.68
3423.3	5606.74
3426.42	9602.79
3429.54	9868.85
3432.65	6292.91
3435.77	3071.97
3438.88	1566.03
3442	987.096
3445.11	659.852
3448.22	555.03
3451.33	479.243
3454.43	427.205
3457.54	398.967
3460.65	388.548
3463.75	399.181
3466.85	427.027
3469.95	472.786
3473.05	532.17
3476.15	606.721
3479.25	728.813
3482.35	869.63
3485.44	1033.43
3488.54	1282.18
3491.63	1700.26
3494.72	2249.34
3497.81	3042.42
3500.9	4176.5
3503.99	5622.58
3507.07	7093.66
3510.16	7718.74
3513.24	7203.82
3516.32	5754.9
3519.41	4263.98
3522.49	3056.07
3525.56	2229.15
3528.64	1664.23
3531.72	1285.31
3534.79	1021.51
3537.87	819.619
3540.94	680.139
3544.01	572.842
3547.08	494.291
3550.15	429.197
3553.22	377.198
3556.28	332.911
3559.35	296.315
3562.41	265.949
3565.47	241.969
3568.54	222.799
3571.6	206.749
3574.65	192.159
3577.71	179.254
3580.77	169.02
3583.82	160.376
3586.88	153.008
3589.93	146.716
3592.98	141.264
3596.03	136.99
3599.08	133.109
3602.13	129.419
3605.18	125.638
3608.22	121.495
3611.27	117.06
3614.31	112.356
3617.35	108.402
3620.39	103.495
3623.43	99.0087
3626.47	95.2686
3629.5	92.1039
3632.54	89.2617
3635.57	86.4168
3638.61	83.1045
3641.64	79.9234
3644.67	74.1804
3647.7	70.8962
3650.73	67.8175
3653.75	65.0807
3656.78	62.6911
3659.8	60.5763
3662.83	56.9331
3665.85	52.4241
3668.87	50.1353
3671.89	48.4059
3674.91	46.8656
3677.92	46.1216
3680.94	44.1956
3683.96	40.3749
3686.97	36.5661
3689.98	33.2809
3692.99	29.9681
3696	27.7087
3699.01	26.7333
3702.02	26.9507
3705.02	27.9421
3708.03	29.0697
3711.03	30.3177
3714.03	31.6134
3717.04	31.4254
3720.04	29.577
3723.04	26.9051
3726.03	23.8958
3729.03	19.8517
3732.03	18.6845
3735.02	18.0438
3738.01	19.6819
3741	22.217
3743.99	25.2765
3746.98	27.7129
3749.97	28.934
3752.96	26.9926
3755.95	25.6802
3758.93	24.7248
3761.91	24.1174
3764.9	24.4779
3767.88	25.1583
3770.86	26.1991
3773.84	26.7246
3776.81	26.8813
3779.79	26.8986
3782.77	26.127
3785.74	25.4089
3788.71	24.7118
3791.68	24.0524
3794.65	22.7976
3797.62	21.812
3800.59	22.0151
3803.56	22.7235
3806.52	22.6518
3809.49	21.9377
3812.45	20.9981
3815.41	20.5452
3818.37	20.055
3821.33	19.7001
3824.29	19.6212
3827.25	18.3583
3830.21	15.9433
3833.16	14.1241
3836.11	15.0891
3839.07	15.8131
3842.02	16.0737
3844.97	16.3002
3847.92	18.3422
3850.87	18.8872
3853.81	18.6197
3856.76	17.1377
3859.7	15.4707
3862.65	13.8574
3865.59	12.1295
3868.53	10.7236
3871.47	9.53836
3874.41	8.9978
3877.34	8.18991
3880.28	7.18674
3883.22	6.0627
3886.15	0.987961
3889.08	-0.684265
3892.01	1.01073
3894.94	2.33928
3897.87	2.38152
3900.8	2.87605
3903.73	3.58708
3906.65	3.60959
3909.58	3.98259
3912.5	5.23083
3915.42	5.30383
3918.35	4.64009
3921.27	4.69771
3924.18	5.93678
3927.1	7.40611
3930.02	6.67677
3932.93	6.81606
3935.85	5.53105
3938.76	4.37851
3941.67	2.98657
3944.58	1.53163
3947.49	-0.00688171
3950.4	-0.635239
3953.31	-0.21994
3956.22	0.774841
3959.12	1.14056
3962.02	1.67278
3964.93	1.7182
3967.83	-0.460297
3970.73	-0.0406036
3973.63	0.705948
3976.53	1.93839
3979.42	4.83093
3982.32	6.69379
3985.21	9.94333
3988.11	4.88727
3991	6.17682
3993.89	6.7981
3996.78	4.71977
3999.67	0.372391