File: Data/3-Raman/processed/bu20-F-brt1-FI04-633-v.txt
#Acq. time (s)=	20
#Accumulations=	3
#Range (cm-¹)=	100...4000
#Windows=	1
#Auto scanning=	Off
#Autofocus=	Off
#Macrospot=	Off
#AutoExposure=	Off
#Spike filter=	Multiple accum.
#Delay time (s)=	0
#Binning=	1
#Readout mode=	Signal
#DeNoise=	Lite
#ICS correction=	Off
#Dark correction=	Off
#Inst. Process=	Off
#Detector temperature (°C)=	-60.09
#Instrument=	LabRAM HR Evol
#Detector=	SIN-EM FIVIS
#Objective=	x100_VIS
#Grating=	150 (500nm)
#ND Filter=	100%
#Laser=	633nm_Edge
#Hole=	30.0125
#Temperature=	0
#Range=	Visible
#StageXY=	75x50mm Scan+
#StageZ=	Z motor
#X (µm)=	7222.2
#Y (µm)=	125
#Z (µm)=	1863.3
#Full time(mm:ss)=	1:02
#Project=	Buranga
#Sample=	BU18FA20_F
#Site=	F_Bertoss1
#Title=	20-F_brt1_FI04
#Remark=
#Date=	30.07.2019 16:15
#Acquired=	30.07.2019 16:15:52
#Data Range:Extract=	16.12.2021 15:36:30
#Base:Fit=	16.12.2021 15:36:40
#Base:Edit=	16.12.2021 15:40:41
#Base:Edit=	16.12.2021 15:40:41
#Base:Edit=	16.12.2021 15:40:42
#Base:Edit=	16.12.2021 15:40:43
#Base:Edit=	16.12.2021 15:40:43
#Base:Edit=	16.12.2021 15:40:43
#Base:Edit=	16.12.2021 15:40:44
#Base:Edit=	16.12.2021 15:40:45
#Base:Edit=	16.12.2021 15:40:46
#Base:Sub=	16.12.2021 15:40:50
100.38	275.965
106.898	220.78
113.411	176.757
119.918	144.259
126.419	120.464
132.916	104.283
139.407	86.822
145.892	74.9275
152.372	65.3953
158.847	51.0629
165.316	61.157
171.781	40.8277
178.239	28.2316
184.693	27.4443
191.139	17.7406
197.582	10.0217
204.02	5.43689
210.452	2.51125
216.877	-0.163467
223.299	2.50009
229.715	14.7344
236.126	60.6941
242.53	76.7479
248.931	29.9063
255.326	22.2365
261.714	26.1945
268.099	36.2863
274.477	23.5078
280.851	59.6505
287.218	99.4317
293.582	64.3555
299.939	30.7922
306.293	11.3566
312.639	11.9866
318.982	33.203
325.318	81.4417
331.651	126.239
337.977	73.9327
344.297	31.7919
350.614	21.156
356.925	32.9254
363.23	45.6255
369.53	39.7714
375.827	21.9951
382.116	9.38196
388.401	0.108932
394.681	0.796463
400.956	5.1902
407.226	12.341
413.49	17.2742
419.749	25.9642
426.003	38.1549
432.252	67.0913
438.496	90.5139
444.735	83.6932
450.969	75.2164
457.197	73.5121
463.421	63.2533
469.64	43.5867
475.853	27.6367
482.062	20.9195
488.265	20.2365
494.464	22.2945
500.657	25.1918
506.844	27.8715
513.028	30.1321
519.206	30.2466
525.38	30.3895
531.548	29.3317
537.71	25.2583
543.869	22.0658
550.022	19.4617
556.169	20.629
562.313	23.4563
568.452	21.14
574.584	17.286
580.713	20.147
586.837	28.6942
592.954	52.2402
599.068	83.1571
605.176	98.5787
611.28	89.0935
617.378	77.5073
623.473	74.3992
629.561	78.3554
635.644	76.3196
641.724	71.827
647.797	61.3212
653.867	64.7174
659.931	72.3744
665.99	68.2962
672.044	50.8199
678.095	37.9223
684.139	23.5536
690.179	12.6989
696.213	10.3255
702.245	12.965
708.27	13.5295
714.29	9.78239
720.306	9.75609
726.316	11.6255
732.322	10.4721
738.323	6.80547
744.32	5.23413
750.311	5.76882
756.298	5.92788
762.28	5.47105
768.258	4.08014
774.23	2.34512
780.198	1.12457
786.161	3.55699
792.119	5.91273
798.073	6.42659
804.021	3.18858
809.965	1.63699
815.904	4.0605
821.839	5.97175
827.769	3.47835
833.693	4.06392
839.614	4.00986
845.53	5.01479
851.44	6.68
857.346	6.34449
863.248	6.07922
869.144	7.73579
875.037	10.5474
880.924	13.4105
886.807	15.1178
892.685	14.1402
898.559	10.2636
904.427	7.38146
910.292	7.16904
916.151	15.9376
922.006	9.38885
927.856	9.37377
933.701	13.6737
939.543	18.0402
945.379	28.1329
951.21	42.7146
957.037	57.2096
962.861	67.2125
968.678	81.697
974.491	108.233
980.3	157.476
986.104	225.878
991.904	284.617
997.699	230.026
1003.49	183.727
1009.28	153.922
1015.06	153.02
1020.83	166.241
1026.61	188.448
1032.37	159.055
1038.14	111.106
1043.9	78.9848
1049.65	63.0017
1055.4	51.8362
1061.15	40.4934
1066.88	36.1805
1072.62	38.6228
1078.35	47.7768
1084.08	58.3532
1089.8	65.4776
1095.52	63.4962
1101.23	78.7887
1106.94	67.8041
1112.65	44.3784
1118.35	26.3124
1124.05	18.0321
1129.74	18.4414
1135.42	25.1205
1141.11	34.6408
1146.78	44.7159
1152.46	50.4472
1158.13	48.2774
1163.79	37.0984
1169.45	23.5722
1175.11	12.2932
1180.76	11.0857
1186.41	12.2117
1192.05	7.92814
1197.69	4.05767
1203.32	3.75093
1208.95	2.30242
1214.58	1.53609
1220.2	1.26085
1225.82	1.54857
1231.43	0.235146
1237.04	-0.366096
1242.64	0.00685883
1248.24	2.63627
1253.83	4.86857
1259.42	8.4737
1265.01	15.7727
1270.59	9.78146
1276.17	15.4067
1281.74	130.383
1287.31	35.7565
1292.88	17.6701
1298.44	10.203
1303.99	5.18845
1309.55	4.335
1315.09	5.91473
1320.64	6.58373
1326.18	4.7147
1331.71	2.09595
1337.24	3.42295
1342.77	5.17873
1348.29	6.61505
1353.81	7.0755
1359.32	8.33527
1364.83	9.76252
1370.33	8.34722
1375.84	9.61056
1381.33	46.6705
1386.82	240.145
1392.31	22.5439
1397.8	7.44435
1403.28	17.6512
1408.75	21.6135
1414.22	11.0383
1419.69	6.70882
1425.15	6.64681
1430.61	6.53659
1436.07	3.69772
1441.52	1.74538
1446.96	1.25341
1452.41	1.92845
1457.84	2.9874
1463.28	4.10106
1468.71	3.24917
1474.13	0.299469
1479.55	-0.655617
1484.97	-0.310135
1490.39	1.06207
1495.79	2.29462
1501.2	5.75495
1506.6	3.07774
1512	3.28751
1517.39	4.56508
1522.78	4.74913
1528.16	3.94478
1533.54	3.441
1538.92	-0.270447
1544.29	2.41789
1549.66	3.00718
1555.02	3.81453
1560.38	6.8034
1565.74	6.29254
1571.09	3.3661
1576.44	3.98679
1581.78	7.70216
1587.12	10.137
1592.46	9.39714
1597.79	6.87626
1603.12	5.9456
1608.44	7.54874
1613.76	11.1657
1619.08	10.0082
1624.39	7.99234
1629.7	7.70135
1635	8.79404
1640.3	9.1702
1645.59	8.9907
1650.88	8.81597
1656.17	9.89764
1661.46	6.88203
1666.74	4.06541
1672.01	5.84348
1677.28	8.73133
1682.55	8.19713
1687.82	6.97838
1693.07	7.51478
1698.33	9.29218
1703.58	8.95663
1708.83	7.54655
1714.07	6.72231
1719.31	5.9583
1724.55	5.35101
1729.78	4.54693
1735.01	4.0442
1740.23	2.0587
1745.46	-2.58738
1750.67	2.3031
1755.89	5.28403
1761.09	3.09449
1766.3	2.22227
1771.5	2.58456
1776.7	2.87505
1781.89	3.60878
1787.08	5.52641
1792.27	6.76275
1797.45	5.95715
1802.62	2.66505
1807.8	0.823036
1812.97	2.41087
1818.14	5.23598
1823.3	6.6831
1828.46	6.59853
1833.61	5.76151
1838.76	4.49063
1843.91	4.83097
1849.05	3.55567
1854.19	2.81591
1859.33	2.63243
1864.46	3.37651
1869.59	2.93903
1874.71	3.74523
1879.83	4.2775
1884.95	4.15585
1890.06	4.03862
1895.17	4.56123
1900.27	4.54205
1905.38	3.43587
1910.47	2.00417
1915.57	0.457924
1920.66	1.82737
1925.74	4.01005
1930.83	3.40876
1935.91	1.24175
1940.98	-0.437271
1946.05	0.340279
1951.12	0.930428
1956.18	0.649826
1961.25	2.62151
1966.3	3.74712
1971.35	3.89291
1976.4	2.88924
1981.45	1.47784
1986.49	2.11472
1991.53	1.53185
1996.56	1.80854
2001.59	2.59958
2006.62	2.25269
2011.64	-1.13651
2016.66	1.65074
2021.68	3.88586
2026.69	3.4842
2031.7	1.94707
2036.7	-1.34958
2041.7	-1.03621
2046.7	0.056076
2051.7	1.18132
2056.69	0.103504
2061.67	-0.101543
2066.65	2.61139
2071.63	5.48309
2076.61	2.79223
2081.58	-0.0545082
2086.55	-2.17115
2091.51	-1.38844
2096.47	0.305138
2101.43	-0.00118637
2106.39	-1.47668
2111.34	-1.12288
2116.28	0.561554
2121.23	-0.188301
2126.17	-0.726048
2131.1	-0.468945
2136.03	-3.42702
2140.96	0.87075
2145.89	3.90696
2150.81	1.30019
2155.73	1.2238
2160.64	2.04371
2165.55	2.43329
2170.46	1.98485
2175.36	-0.160358
2180.26	-1.53329
2185.16	-1.53244
2190.05	-0.297428
2194.94	1.03418
2199.83	1.26551
2204.71	2.89949
2209.59	3.57127
2214.46	1.78252
2219.33	1.66745
2224.2	0.395748
2229.07	-3.45216
2233.93	3.98197
2238.79	1.64417
2243.64	-0.530399
2248.49	-2.99413
2253.34	1.38181
2258.18	1.01489
2263.02	-0.227032
2267.86	-1.1597
2272.69	0.49361
2277.52	1.06202
2282.35	0.658585
2287.17	0.539387
2291.99	1.2307
2296.8	1.62117
2301.62	1.26353
2306.43	1.00692
2311.23	1.39321
2316.03	1.20319
2320.83	3.59781
2325.63	9.29303
2330.42	6.90206
2335.21	4.48834
2339.99	4.4435
2344.77	5.21701
2349.55	5.47255
2354.32	3.22018
2359.1	0.387245
2363.86	-0.0536461
2368.63	0.871296
2373.39	1.82548
2378.15	0.387981
2382.9	-0.589729
2387.65	-0.0140762
2392.4	2.80859
2397.14	3.32355
2401.88	1.83096
2406.62	-0.143414
2411.35	2.54168
2416.08	0.134998
2420.81	-0.176102
2425.53	2.17575
2430.25	0.937778
2434.97	0.676178
2439.69	1.80043
2444.4	2.62593
2449.1	3.87905
2453.81	4.79541
2458.51	4.08508
2463.2	2.33958
2467.9	0.883438
2472.59	2.63716
2477.27	2.94193
2481.96	3.38757
2486.64	3.96541
2491.31	4.23588
2495.99	1.59293
2500.66	-0.644379
2505.32	1.4244
2509.99	3.862
2514.65	4.84628
2519.31	4.08266
2523.96	3.43449
2528.61	3.50574
2533.26	5.6659
2537.9	6.79327
2542.54	6.65287
2547.18	5.5128
2551.81	5.04688
2556.44	4.16837
2561.07	3.01249
2565.69	3.4877
2570.32	4.16009
2574.93	3.32125
2579.55	2.8533
2584.16	2.86664
2588.77	4.71159
2593.37	5.43707
2597.97	4.79537
2602.57	4.22592
2607.17	3.99483
2611.76	3.35185
2616.35	4.66471
2620.93	6.21852
2625.51	5.01709
2630.09	4.4545
2634.67	4.94249
2639.24	4.93434
2643.81	2.25
2648.38	1.79303
2652.94	4.90966
2657.5	6.69428
2662.06	5.33176
2666.61	1.82089
2671.16	1.49383
2675.71	1.46815
2680.25	1.17588
2684.79	1.1461
2689.33	1.67432
2693.86	2.61778
2698.39	4.07953
2702.92	4.97234
2707.45	6.45966
2711.97	6.66215
2716.49	4.95947
2721	3.17601
2725.51	3.50708
2730.02	5.32454
2734.53	6.17065
2739.03	4.82532
2743.53	3.72335
2748.03	3.33184
2752.52	3.71258
2757.01	4.06678
2761.5	1.14452
2765.98	4.76851
2770.46	3.34296
2774.94	3.79007
2779.42	5.45356
2783.89	-0.172146
2788.36	0.374756
2792.82	2.57426
2797.28	5.46989
2801.74	5.07199
2806.2	3.76985
2810.65	2.39113
2815.1	1.96926
2819.55	0.579151
2823.99	4.92029
2828.43	7.17226
2832.87	6.53463
2837.3	5.75718
2841.74	5.14724
2846.17	4.66045
2850.59	5.24204
2855.01	5.67483
2859.43	4.07452
2863.85	3.36821
2868.26	2.93295
2872.67	2.40636
2877.08	1.82291
2881.48	1.95376
2885.89	4.07319
2890.28	3.28067
2894.68	-0.109081
2899.07	-0.663376
2903.46	-0.000953674
2907.85	0.311069
2912.23	-0.0143089
2916.61	0.267685
2920.98	2.35833
2925.36	3.67208
2929.73	2.7083
2934.1	1.68533
2938.46	-0.0925674
2942.82	-0.39534
2947.18	0.0198059
2951.54	0.966694
2955.89	2.12995
2960.24	1.10579
2964.59	3.97266
2968.93	1.99662
2973.27	2.85066
2977.61	2.04387
2981.95	0.721333
2986.28	0.22028
2990.61	1.96778
2994.94	2.12404
2999.26	1.60806
3003.58	1.70633
3007.9	1.92783
3012.21	1.45427
3016.52	1.09163
3020.83	2.57386
3025.14	2.59097
3029.44	1.92723
3033.74	1.39737
3038.04	1.25987
3042.33	1.98255
3046.62	1.70922
3050.91	-0.381702
3055.2	-0.454906
3059.48	0.593449
3063.76	2.22926
3068.03	1.94699
3072.31	3.09214
3076.58	3.03709
3080.85	2.3102
3085.11	2.13707
3089.37	2.46893
3093.63	1.29014
3097.89	0.167442
3102.14	-0.213432
3106.39	0.502998
3110.64	2.33066
3114.89	4.37717
3119.13	4.41065
3123.37	3.55653
3127.6	3.15703
3131.84	2.94719
3136.07	4.33689
3140.29	6.64507
3144.52	5.97276
3148.74	5.89005
3152.96	6.76551
3157.18	6.78732
3161.39	5.63831
3165.6	6.22965
3169.81	6.92932
3174.01	6.65412
3178.22	6.65644
3182.42	5.47754
3186.61	5.48212
3190.8	6.72359
3195	7.9589
3199.18	11.4081
3203.37	11.3165
3207.55	9.06244
3211.73	6.8224
3215.91	6.71867
3220.08	5.59966
3224.25	5.15417
3228.42	2.55474
3232.59	5.40956
3236.75	6.73467
3240.91	8.08528
3245.07	6.93978
3249.22	5.57295
3253.37	5.54563
3257.52	6.38213
3261.67	6.91249
3265.81	6.86131
3269.95	5.67821
3274.09	4.59732
3278.22	1.68947
3282.36	2.63258
3286.49	3.65445
3290.61	3.76927
3294.74	2.39027
3298.86	1.16653
3302.98	0.800743
3307.09	1.35117
3311.21	2.75418
3315.32	4.07965
3319.42	5.16785
3323.53	4.83075
3327.63	6.63301
3331.73	6.95705
3335.83	5.35119
3339.92	3.88096
3344.01	3.24001
3348.1	3.22989
3352.19	5.18127
3356.27	5.48296
3360.35	5.89874
3364.43	7.02858
3368.5	6.08443
3372.58	6.51667
3376.65	6.73364
3380.71	4.32701
3384.78	4.75586
3388.84	6.09499
3392.9	7.57492
3396.95	9.02446
3401.01	8.15611
3405.06	6.77048
3409.1	7.57118
3413.15	9.64671
3417.19	9.40945
3421.23	9.05184
3425.27	9.68898
3429.31	10.9923
3433.34	10.4549
3437.37	8.36122
3441.39	7.33385
3445.42	8.2234
3449.44	9.93101
3453.46	10.3487
3457.47	8.69478
3461.49	6.93494
3465.5	7.2941
3469.51	8.56185
3473.51	8.70377
3477.52	7.1725
3481.52	6.89252
3485.51	8.19963
3489.51	7.71946
3493.5	6.48404
3497.49	6.08147
3501.48	5.91891
3505.46	5.99988
3509.45	5.91326
3513.43	5.6432
3517.4	5.77953
3521.38	2.89756
3525.35	2.26936
3529.32	7.12566
3533.28	5.6753
3537.25	5.23444
3541.21	5.11604
3545.17	5.69242
3549.12	5.91487
3553.08	5.11718
3557.03	4.71751
3560.98	5.39277
3564.92	8.0693
3568.87	8.71233
3572.81	9.8303
3576.74	12.3649
3580.68	13.1504
3584.61	13.8592
3588.54	13.8264
3592.47	13.0678
3596.4	12.9486
3600.32	9.31981
3604.24	6.13284
3608.16	2.43598
3612.07	0.971897
3615.98	2.96109
3619.89	3.84513
3623.8	4.28108
3627.71	3.46667
3631.61	2.66638
3635.51	1.69044
3639.41	0.771454
3643.3	-0.592073
3647.19	0.335949
3651.08	4.45511
3654.97	4.47025
3658.85	4.06885
3662.74	0.927635
3666.62	2.97421
3670.49	3.12281
3674.37	2.80429
3678.24	1.7564
3682.11	1.4183
3685.98	1.25678
3689.84	1.75955
3693.7	4.4139
3697.56	4.05426
3701.42	3.04127
3705.28	2.42762
3709.13	2.56734
3712.98	2.91189
3716.82	2.0074
3720.67	0.793858
3724.51	-0.314066
3728.35	0.789608
3732.19	1.31888
3736.02	1.6
3739.86	2.09272
3743.69	1.14748
3747.51	-0.351519
3751.34	0.788469
3755.16	1.7178
3758.98	3.28261
3762.8	4.43284
3766.61	3.21852
3770.43	2.07836
3774.24	1.00708
3778.05	1.35807
3781.85	2.44972
3785.65	2.02248
3789.45	1.85109
3793.25	3.36602
3797.05	2.71922
3800.84	2.08677
3804.63	2.16769
3808.42	2.44161
3812.21	2.89634
3815.99	3.36894
3819.77	2.99669
3823.55	2.1359
3827.33	1.9951
3831.1	2.28384
3834.87	1.73159
3838.64	1.30767
3842.41	1.87804
3846.17	3.03516
3849.93	3.03161
3853.69	3.15368
3857.45	4.07314
3861.21	2.79373
3864.96	1.71702
3868.71	0.91065
3872.46	0.109217
3876.2	1.63105
3879.94	3.01561
3883.68	2.37345
3887.42	0.506886
3891.16	-0.0131016
3894.89	0.85614
3898.62	1.06502
3902.35	0.37928
3906.08	1.05278
3909.8	1.96659
3913.52	4.01542
3917.24	4.04554
3920.96	2.35526
3924.67	1.792
3928.38	1.83268
3932.09	2.17063
3935.8	2.25731
3939.51	1.5923
3943.21	1.85468
3946.91	1.21313
3950.61	1.49367
3954.3	1.94873
3958	2.64773
3961.69	2.88481
3965.38	2.42063
3969.06	1.50737
3972.75	0.459478
3976.43	-0.248917
3980.11	2.21488
3983.78	3.70306
3987.46	4.08677
3991.13	3.52948
3994.8	3.72667
3998.47	5.80685