File: Data/3-Raman/processed/bu20-C-brt1-FI08-633-v.txt
#Acq. time (s)=	20
#Accumulations=	3
#Range (cm-¹)=	100...4000
#Windows=	1
#Auto scanning=	Off
#Autofocus=	Off
#Macrospot=	Off
#AutoExposure=	Off
#Spike filter=	Multiple accum.
#Delay time (s)=	0
#Binning=	1
#Readout mode=	Signal
#DeNoise=	Lite
#ICS correction=	Off
#Dark correction=	Off
#Inst. Process=	Off
#Detector temperature (°C)=	-60.09
#Instrument=	LabRAM HR Evol
#Detector=	SIN-EM FIVIS
#Objective=	x50_VIS_LWD
#Grating=	150 (500nm)
#ND Filter=	100%
#Laser=	633nm_Edge
#Hole=	30.0125
#Temperature=	0
#Range=	Visible
#StageXY=	75x50mm Scan+
#StageZ=	Z motor
#X (µm)=	7340
#Y (µm)=	4609.7
#Z (µm)=	-42.4
#Full time(mm:ss)=	1:02
#Project=	Buranga
#Sample=	BU18FA20_C
#Site=	C_Bertoss1
#Title=	20-C_brt1_FI08
#Remark=
#Date=	30.07.2019 14:43
#Acquired=	30.07.2019 14:43:14
#Data Range:Extract=	16.12.2021 15:36:30
#Base:Fit=	16.12.2021 15:36:40
#Base:Edit=	16.12.2021 15:38:45
#Base:Sub=	16.12.2021 15:38:47
100.38	451.558
106.898	361.864
113.411	276.373
119.918	217.904
126.419	172.676
132.916	139.391
139.407	116.595
145.892	97.4612
152.372	80.9756
158.847	61.9963
165.316	48.4978
171.781	41.2357
178.239	28.2076
184.693	22.0849
191.139	19.7997
197.582	19.6601
204.02	10.3554
210.452	2.74431
216.877	-0.00474548
223.299	1.73497
229.715	9.08627
236.126	31.5139
242.53	76.3109
248.931	72.2291
255.326	32.0663
261.714	20.7186
268.099	24.4462
274.477	37.6466
280.851	59.5844
287.218	105.448
293.582	98.4423
299.939	51.1438
306.293	19.7908
312.639	9.16985
318.982	19.3427
325.318	47.9666
331.651	121.186
337.977	123.639
344.297	46.8484
350.614	17.4183
356.925	14.5368
363.23	27.7386
369.53	46.9953
375.827	41.395
382.116	25.4729
388.401	11.2436
394.681	2.3336
400.956	-0.462723
407.226	1.78519
413.49	5.08438
419.749	10.8422
426.003	21.4926
432.252	36.1317
438.496	59.6081
444.735	78.6393
450.969	77.9946
457.197	73.1167
463.421	66.5566
469.64	52.1939
475.853	31.8046
482.062	18.5262
488.265	15.0031
494.464	15.577
500.657	15.8931
506.844	15.289
513.028	14.2842
519.206	16.9978
525.38	23.2328
531.548	21.7668
537.71	16.2382
543.869	12.8458
550.022	11.1074
556.169	10.8646
562.313	11.4789
568.452	10.0945
574.584	7.9653
580.713	7.78568
586.837	13.0034
592.954	22.9454
599.068	49.9844
605.176	90.2244
611.28	86.5387
617.378	62.2508
623.473	58.5252
629.561	63.2054
635.644	67.8915
641.724	66.5774
647.797	50.9757
653.867	49.1735
659.931	62.1177
665.99	73.2506
672.044	62.1873
678.095	39.8317
684.139	23.5616
690.179	15.7467
696.213	11.1822
702.245	6.9198
708.27	2.67415
714.29	1.73462
720.306	5.67923
726.316	8.76979
732.322	8.12436
738.323	3.68239
744.32	0.102814
750.311	0.0687561
756.298	2.7005
762.28	6.94028
768.258	10.1085
774.23	8.75586
780.198	6.98199
786.161	5.46332
792.119	5.26501
798.073	6.02016
804.021	7.39853
809.965	9.21561
815.904	8.50101
821.839	6.73444
827.769	4.63777
833.693	5.72942
839.614	8.7784
845.53	12.838
851.44	14.8705
857.346	11.47
863.248	6.54814
869.144	6.40317
875.037	11.9875
880.924	12.5805
886.807	11.8965
892.685	10.4226
898.559	8.7651
904.427	8.07962
910.292	13.544
916.151	14.0303
922.006	11.4101
927.856	11.4307
933.701	13.9883
939.543	17.1222
945.379	26.4864
951.21	44.197
957.037	62.1445
962.861	72.1187
968.678	77.1657
974.491	91.9181
980.3	122.899
986.104	175.829
991.904	256.562
997.699	292.848
1003.49	211.573
1009.28	165.821
1015.06	150.755
1020.83	175.423
1026.61	207.2
1032.37	199.281
1038.14	154.625
1043.9	100.726
1049.65	76.6771
1055.4	59.0837
1061.15	48.4607
1066.88	39.7626
1072.62	33.9141
1078.35	39.787
1084.08	49.5784
1089.8	62.0805
1095.52	72.4863
1101.23	81.5433
1106.94	90.6347
1112.65	57.072
1118.35	34.9131
1124.05	27.2045
1129.74	23.6
1135.42	20.4701
1141.11	23.6733
1146.78	31.338
1152.46	44.0808
1158.13	59.512
1163.79	49.812
1169.45	28.9105
1175.11	19.4671
1180.76	12.8481
1186.41	9.35404
1192.05	7.41653
1197.69	5.76494
1203.32	9.2071
1208.95	0.298538
1214.58	0.734459
1220.2	6.66399
1225.82	3.08074
1231.43	2.4586
1237.04	5.2919
1242.64	8.59968
1248.24	11.3682
1253.83	11.6617
1259.42	15.3271
1265.01	23.6376
1270.59	19.3143
1276.17	16.5705
1281.74	161.292
1287.31	156.575
1292.88	34.1756
1298.44	19.0079
1303.99	13.3871
1309.55	12.4084
1315.09	13.1443
1320.64	13.8532
1326.18	12.6247
1331.71	8.85811
1337.24	8.6626
1342.77	7.45023
1348.29	1.19299
1353.81	0.59053
1359.32	7.43386
1364.83	15.4309
1370.33	24.6638
1375.84	18.7699
1381.33	36.3152
1386.82	424.498
1392.31	128.758
1397.8	28.263
1403.28	24.6896
1408.75	38.8589
1414.22	24.2695
1419.69	11.4698
1425.15	4.19737
1430.61	0.446449
1436.07	1.97111
1441.52	2.95979
1446.96	0.706352
1452.41	-1.57006
1457.84	0.401054
1463.28	2.91364
1468.71	1.07281
1474.13	-1.25222
1479.55	-0.55394
1484.97	1.41634
1490.39	3.18595
1495.79	2.50476
1501.2	8.15912
1506.6	3.75233
1512	1.57276
1517.39	2.47244
1522.78	3.16294
1528.16	2.81068
1533.54	-0.308693
1538.92	-4.72507
1544.29	-0.475555
1549.66	1.93919
1555.02	2.43967
1560.38	2.87529
1565.74	3.08663
1571.09	4.24058
1576.44	4.46962
1581.78	5.50344
1587.12	3.93819
1592.46	1.17694
1597.79	0.93087
1603.12	2.23859
1608.44	4.052
1613.76	4.80353
1619.08	4.5191
1624.39	4.32398
1629.7	4.53697
1635	3.91553
1640.3	3.03649
1645.59	2.05828
1650.88	0.645012
1656.17	0.449295
1661.46	3.2743
1666.74	7.48197
1672.01	9.01935
1677.28	4.73878
1682.55	1.6293
1687.82	2.54405
1693.07	3.30846
1698.33	4.11792
1703.58	5.66363
1708.83	5.80951
1714.07	4.64267
1719.31	3.77185
1724.55	3.81834
1729.78	3.34338
1735.01	3.99786
1740.23	7.58468
1745.46	8.02045
1750.67	7.20724
1755.89	6.72176
1761.09	7.42786
1766.3	8.12339
1771.5	8.48872
1776.7	6.71684
1781.89	5.18206
1787.08	3.86163
1792.27	2.76536
1797.45	2.14641
1802.62	2.60963
1807.8	4.43835
1812.97	5.8894
1818.14	5.08243
1823.3	4.14821
1828.46	5.36848
1833.61	5.08546
1838.76	2.06236
1843.91	1.61662
1849.05	2.97138
1854.19	4.29048
1859.33	5.13357
1864.46	3.59852
1869.59	1.51169
1874.71	2.2506
1879.83	4.07083
1884.95	4.02246
1890.06	1.84145
1895.17	-0.479111
1900.27	-0.233253
1905.38	2.61188
1910.47	4.28235
1915.57	6.15298
1920.66	6.82265
1925.74	6.32474
1930.83	4.56611
1935.91	1.68291
1940.98	-0.148193
1946.05	0.348465
1951.12	0.532028
1956.18	0.876389
1961.25	1.87446
1966.3	2.38554
1971.35	3.13828
1976.4	4.25007
1981.45	6.08235
1986.49	7.3263
1991.53	3.03768
1996.56	0.216553
2001.59	1.44001
2006.62	3.37608
2011.64	6.45714
2016.66	6.79666
2021.68	6.27084
2026.69	7.96961
2031.7	7.38512
2036.7	6.27644
2041.7	5.93186
2046.7	4.42925
2051.7	6.6748
2056.69	8.49834
2061.67	9.09674
2066.65	6.20016
2071.63	1.61502
2076.61	1.18345
2081.58	2.74728
2086.55	3.58617
2091.51	6.88373
2096.47	9.44484
2101.43	9.66433
2106.39	8.70068
2111.34	7.15434
2116.28	5.32052
2121.23	3.81506
2126.17	4.15458
2131.1	6.29967
2136.03	7.56347
2140.96	6.28357
2145.89	-0.289528
2150.81	4.9735
2155.73	4.76939
2160.64	3.04268
2165.55	3.60813
2170.46	5.26352
2175.36	6.75189
2180.26	6.71095
2185.16	6.81999
2190.05	4.27822
2194.94	2.34703
2199.83	0.906395
2204.71	0.307304
2209.59	1.9968
2214.46	3.31826
2219.33	5.08628
2224.2	5.17503
2229.07	5.60224
2233.93	5.97861
2238.79	3.73682
2243.64	2.10494
2248.49	3.52615
2253.34	4.75007
2258.18	5.00624
2263.02	6.60366
2267.86	7.45213
2272.69	6.67927
2277.52	5.14597
2282.35	3.65737
2287.17	3.40211
2291.99	1.27701
2296.8	3.34245
2301.62	5.2111
2306.43	5.45429
2311.23	6.07652
2316.03	-0.584358
2320.83	4.81446
2325.63	11.1611
2330.42	8.85002
2335.21	8.1269
2339.99	8.19229
2344.77	5.9491
2349.55	4.75449
2354.32	4.58226
2359.1	6.18829
2363.86	7.703
2368.63	6.57108
2373.39	2.63166
2378.15	3.81104
2382.9	5.31848
2387.65	5.87829
2392.4	5.02895
2397.14	4.43714
2401.88	3.83862
2406.62	1.68155
2411.35	0.16494
2416.08	1.83892
2420.81	3.6637
2425.53	4.84786
2430.25	3.66182
2434.97	2.59137
2439.69	2.42258
2444.4	2.8195
2449.1	3.48724
2453.81	5.04401
2458.51	3.95332
2463.2	0.409737
2467.9	0.800362
2472.59	3.33227
2477.27	4.13541
2481.96	6.43298
2486.64	9.70499
2491.31	6.69999
2495.99	5.75863
2500.66	6.21767
2505.32	7.25405
2509.99	6.90048
2514.65	6.06359
2519.31	3.99718
2523.96	3.8571
2528.61	5.78162
2533.26	5.75056
2537.9	3.12517
2542.54	2.96436
2547.18	5.41423
2551.81	6.0546
2556.44	6.7328
2561.07	9.12984
2565.69	9.55575
2570.32	8.47421
2574.93	4.56441
2579.55	4.5016
2584.16	4.57284
2588.77	7.03488
2593.37	8.39686
2597.97	8.589
2602.57	7.2855
2607.17	4.96436
2611.76	4.57209
2616.35	5.54803
2620.93	6.12634
2625.51	6.01701
2630.09	5.01721
2634.67	3.508
2639.24	3.71429
2643.81	5.43932
2648.38	6.70511
2652.94	6.14384
2657.5	5.69966
2662.06	5.43457
2666.61	5.13466
2671.16	5.43615
2675.71	7.9304
2680.25	6.88705
2684.79	3.43653
2689.33	1.36314
2693.86	3.54192
2698.39	8.17339
2702.92	7.8386
2707.45	3.37763
2711.97	3.211
2716.49	5.566
2721	6.76534
2725.51	6.67702
2730.02	5.93647
2734.53	6.32153
2739.03	7.22288
2743.53	7.03311
2748.03	6.52689
2752.52	5.02741
2757.01	1.42073
2761.5	4.34097
2765.98	6.84396
2770.46	6.97443
2774.94	7.77637
2779.42	9.33029
2783.89	12.4002
2788.36	10.8327
2792.82	7.10192
2797.28	6.02905
2801.74	6.96278
2806.2	3.50846
2810.65	3.1498
2815.1	5.10699
2819.55	1.5823
2823.99	2.27758
2828.43	3.44756
2832.87	5.90814
2837.3	6.71156
2841.74	4.72954
2846.17	4.06932
2850.59	4.24657
2855.01	6.00346
2859.43	6.63944
2863.85	6.49614
2868.26	6.14538
2872.67	7.01275
2877.08	7.19141
2881.48	6.35196
2885.89	3.92789
2890.28	0.660347
2894.68	4.19559
2899.07	4.59366
2903.46	3.91568
2907.85	3.92947
2912.23	5.75018
2916.61	4.91516
2920.98	5.85041
2925.36	7.80949
2929.73	6.66597
2934.1	5.10538
2938.46	4.87406
2942.82	3.42052
2947.18	6.02614
2951.54	6.32587
2955.89	4.03831
2960.24	3.19167
2964.59	3.88241
2968.93	0.906586
2973.27	3.1169
2977.61	5.42988
2981.95	6.84618
2986.28	5.26526
2990.61	0.830681
2994.94	0.181877
2999.26	4.02584
3003.58	4.2284
3007.9	4.83148
3012.21	5.46843
3016.52	6.149
3020.83	4.9355
3025.14	3.88968
3029.44	5.22529
3033.74	5.92362
3038.04	7.16778
3042.33	7.25332
3046.62	5.11592
3050.91	6.39736
3055.2	7.10435
3059.48	5.86714
3063.76	6.85098
3068.03	9.61142
3072.31	11.7262
3076.58	12.294
3080.85	8.97424
3085.11	7.05074
3089.37	8.46315
3093.63	7.70475
3097.89	6.89523
3102.14	10.2544
3106.39	15.5219
3110.64	13.0294
3114.89	10.2618
3119.13	9.56294
3123.37	9.77744
3127.6	11.4455
3131.84	10.0878
3136.07	8.64256
3140.29	9.81768
3144.52	12.1442
3148.74	13.6949
3152.96	12.5481
3157.18	12.1654
3161.39	10.2701
3165.6	10.2174
3169.81	9.98785
3174.01	14.6858
3178.22	16.3149
3182.42	16.9033
3186.61	14.5133
3190.8	12.0082
3195	11.6484
3199.18	12.3758
3203.37	14.3033
3207.55	15.1179
3211.73	14.9584
3215.91	14.8683
3220.08	17.2519
3224.25	18.11
3228.42	17.6657
3232.59	16.8847
3236.75	15.5351
3240.91	15.7916
3245.07	14.9108
3249.22	12.5905
3253.37	14.3965
3257.52	16.0744
3261.67	12.8159
3265.81	14.1213
3269.95	12.7922
3274.09	10.603
3278.22	12.0414
3282.36	13.5562
3286.49	13.5328
3290.61	14.2073
3294.74	10.3362
3298.86	9.17159
3302.98	11.9473
3307.09	11.417
3311.21	11.9062
3315.32	12.4723
3319.42	11.6901
3323.53	9.60698
3327.63	9.42875
3331.73	10.8403
3335.83	8.73319
3339.92	12.4616
3344.01	15.4419
3348.1	16.2669
3352.19	14.3327
3356.27	12.011
3360.35	12.6132
3364.43	13.5221
3368.5	14.8153
3372.58	16.3237
3376.65	17.8891
3380.71	17.6334
3384.78	16.6688
3388.84	16.3484
3392.9	16.6331
3396.95	16.9929
3401.01	16.2763
3405.06	16.1249
3409.1	14.04
3413.15	14.8153
3417.19	19.5601
3421.23	20.1301
3425.27	19.8207
3429.31	18.8299
3433.34	18.7682
3437.37	18.0496
3441.39	17.7676
3445.42	17.0906
3449.44	15.8891
3453.46	14.8217
3457.47	14.0895
3461.49	15.6972
3465.5	16.616
3469.51	17.7579
3473.51	15.5015
3477.52	14.0071
3481.52	15.0994
3485.51	15.686
3489.51	17.8644
3493.5	16.6594
3497.49	14.7554
3501.48	15.7428
3505.46	16.0653
3509.45	16.498
3513.43	11.1856
3517.4	8.60334
3521.38	8.58926
3525.35	14.1097
3529.32	12.4929
3533.28	12.0732
3537.25	11.5922
3541.21	12.219
3545.17	12.8364
3549.12	12.3635
3553.08	12.2817
3557.03	14.2661
3560.98	14.625
3564.92	14.038
3568.87	12.6915
3572.81	13.9177
3576.74	16.1727
3580.68	19.4295
3584.61	22.1356
3588.54	22.9687
3592.47	17.8668
3596.4	15.5885
3600.32	15.2041
3604.24	13.814
3608.16	12.085
3612.07	8.9401
3615.98	5.87513
3619.89	5.82403
3623.8	8.30752
3627.71	6.4628
3631.61	8.42364
3635.51	8.00249
3639.41	7.04677
3643.3	6.61214
3647.19	6.69151
3651.08	7.84699
3654.97	6.96304
3658.85	2.9057
3662.74	-0.100842
3666.62	0.212952
3670.49	3.15284
3674.37	8.15839
3678.24	6.64327
3682.11	1.90181
3685.98	1.89481
3689.84	5.10066
3693.7	6.7177
3697.56	4.6152
3701.42	3.17073
3705.28	3.23281
3709.13	3.49055
3712.98	3.10866
3716.82	2.84801
3720.67	2.53211
3724.51	1.4518
3728.35	-0.23481
3732.19	1.7651
3736.02	4.81641
3739.86	5.04922
3743.69	4.53845
3747.51	2.5452
3751.34	4.19146
3755.16	2.99136
3758.98	1.54885
3762.8	3.30195
3766.61	3.38724
3770.43	3.53978
3774.24	2.91198
3778.05	3.44757
3781.85	3.974
3785.65	4.17345
3789.45	3.96021
3793.25	3.55127
3797.05	3.18723
3800.84	3.77436
3804.63	2.41764
3808.42	0.86396
3812.21	0.145493
3815.99	0.279049
3819.77	1.32655
3823.55	1.28591
3827.33	1.14482
3831.1	0.437855
3834.87	0.976345
3838.64	3.54957
3842.41	2.81376
3846.17	2.01875
3849.93	1.39589
3853.69	0.337147
3857.45	-0.0721779
3861.21	0.548748
3864.96	2.14757
3868.71	3.13371
3872.46	3.34844
3876.2	3.29128
3879.94	3.04534
3883.68	2.23316
3887.42	-0.0188713
3891.16	-1.19595
3894.89	-0.193615
3898.62	1.77577
3902.35	0.365986
3906.08	0.572758
3909.8	2.20058
3913.52	2.36084
3917.24	4.43103
3920.96	4.71093
3924.67	4.52399
3928.38	2.62872
3932.09	0.946594
3935.8	2.4315
3939.51	3.778
3943.21	4.90356
3946.91	0.291431
3950.61	1.33758
3954.3	0.540836
3958	0.888462
3961.69	3.57676
3965.38	4.4808
3969.06	4.50277
3972.75	4.37842
3976.43	2.62001
3980.11	3.3321
3983.78	5.86943
3987.46	4.55907
3991.13	3.56445
3994.8	2.56422
3998.47	6.90556