File: Data/3-Raman/processed/bu20-C-brt1-FI05-633-v.txt
#Acq. time (s)=	20
#Accumulations=	3
#Range (cm-¹)=	100...4000
#Windows=	1
#Auto scanning=	Off
#Autofocus=	Off
#Macrospot=	Off
#AutoExposure=	Off
#Spike filter=	Multiple accum.
#Delay time (s)=	0
#Binning=	1
#Readout mode=	Signal
#DeNoise=	Lite
#ICS correction=	Off
#Dark correction=	Off
#Inst. Process=	Off
#Detector temperature (°C)=	-60.09
#Instrument=	LabRAM HR Evol
#Detector=	SIN-EM FIVIS
#Objective=	x50_VIS_LWD
#Grating=	150 (500nm)
#ND Filter=	100%
#Laser=	633nm_Edge
#Hole=	30.0125
#Temperature=	0
#Range=	Visible
#StageXY=	75x50mm Scan+
#StageZ=	Z motor
#X (µm)=	7406.8
#Y (µm)=	4383.9
#Z (µm)=	-31.3
#Full time(mm:ss)=	1:02
#Project=	Buranga
#Sample=	BU18FA20_C
#Site=	C_Bertoss1
#Title=	20-C_brt1_FI05
#Remark=
#Date=	30.07.2019 14:37
#Acquired=	30.07.2019 14:37:08
#Data Range:Extract=	16.12.2021 15:36:30
#Base:Fit=	16.12.2021 15:36:40
#Base:Edit=	16.12.2021 15:37:58
#Base:Edit=	16.12.2021 15:38:00
#Base:Edit=	16.12.2021 15:38:02
#Base:Edit=	16.12.2021 15:38:03
#Base:Edit=	16.12.2021 15:38:04
#Base:Sub=	16.12.2021 15:38:06
100.38	496.86
106.898	366.614
113.411	291.631
119.918	220.596
126.419	161.982
132.916	120.632
139.407	96.4903
145.892	79.3561
152.372	61.9816
158.847	48.8712
165.316	43.175
171.781	41.8152
178.239	26.7704
184.693	12.3254
191.139	6.04498
197.582	2.56296
204.02	0.0296478
210.452	-1.31073
216.877	-1.98156
223.299	-1.33173
229.715	1.36888
236.126	26.8681
242.53	91.7975
248.931	57.2183
255.326	31.793
261.714	21.2945
268.099	20.4117
274.477	27.8334
280.851	49.5509
287.218	82.022
293.582	102.098
299.939	59.0408
306.293	25.1642
312.639	11.4552
318.982	18.7379
325.318	54.1029
331.651	130.169
337.977	111.4
344.297	56.3883
350.614	23.6988
356.925	15.1455
363.23	24.7564
369.53	36.4871
375.827	35.5684
382.116	21.4457
388.401	5.99615
394.681	0.68763
400.956	2.72133
407.226	7.82539
413.49	12.6477
419.749	16.0218
426.003	26.5991
432.252	49.8004
438.496	71.4509
444.735	83.3866
450.969	80.748
457.197	73.1162
463.421	63.3499
469.64	50.5663
475.853	35.5769
482.062	20.0902
488.265	12.7315
494.464	12.3274
500.657	15.2938
506.844	22.3778
513.028	26.9767
519.206	27.6658
525.38	24.6912
531.548	21.7738
537.71	20.7501
543.869	19.3518
550.022	19.376
556.169	17.7473
562.313	15.6762
568.452	13.4319
574.584	12.8526
580.713	14.3212
586.837	17.7399
592.954	30.9788
599.068	56.3763
605.176	94.3104
611.28	92.6527
617.378	70.4781
623.473	62.5537
629.561	67.3852
635.644	70.1597
641.724	68.4377
647.797	60.3525
653.867	59.5278
659.931	69.483
665.99	77.0862
672.044	59.222
678.095	36.3401
684.139	22.4111
690.179	15.5046
696.213	11.1321
702.245	8.21988
708.27	3.84267
714.29	2.61352
720.306	0.521339
726.316	1.1957
732.322	3.30813
738.323	2.72154
744.32	0.0360489
750.311	-0.969086
756.298	-0.650734
762.28	1.67035
768.258	5.27694
774.23	4.58527
780.198	0.164093
786.161	-0.151138
792.119	2.11349
798.073	4.5422
804.021	6.16097
809.965	6.93975
815.904	5.75362
821.839	2.44369
827.769	0.706711
833.693	0.739182
839.614	4.13885
845.53	8.81274
851.44	11.9858
857.346	8.84354
863.248	4.9157
869.144	4.77929
875.037	6.68543
880.924	9.02544
886.807	10.6348
892.685	11.2196
898.559	11.2672
904.427	11.8513
910.292	14.577
916.151	8.39613
922.006	3.67419
927.856	6.17504
933.701	11.4846
939.543	19.6704
945.379	30.3789
951.21	43.1824
957.037	58.1377
962.861	74.032
968.678	75.6449
974.491	85.7593
980.3	117.694
986.104	174.625
991.904	267.381
997.699	293.594
1003.49	225.843
1009.28	180.06
1015.06	156.216
1020.83	166.448
1026.61	200.757
1032.37	209.353
1038.14	158.757
1043.9	104.205
1049.65	72.5354
1055.4	56.652
1061.15	46.17
1066.88	39.2578
1072.62	36.0505
1078.35	43.5562
1084.08	53.3021
1089.8	63.0061
1095.52	72.6494
1101.23	83.502
1106.94	87.982
1112.65	60.3747
1118.35	39.9997
1124.05	26.0195
1129.74	22.5489
1135.42	24.8115
1141.11	31.0472
1146.78	39.8636
1152.46	50.1064
1158.13	58.9051
1163.79	53.4871
1169.45	30.1898
1175.11	16.8301
1180.76	13.1434
1186.41	9.44221
1192.05	6.06415
1197.69	3.66304
1203.32	2.93043
1208.95	0.653778
1214.58	-0.234268
1220.2	0.25383
1225.82	1.12837
1231.43	1.92829
1237.04	1.45416
1242.64	2.32104
1248.24	6.28778
1253.83	11.8839
1259.42	18.4444
1265.01	28.011
1270.59	18.4969
1276.17	20.1839
1281.74	149.645
1287.31	237.79
1292.88	31.8703
1298.44	14.7309
1303.99	10.7998
1309.55	9.83391
1315.09	9.63339
1320.64	8.37001
1326.18	7.59709
1331.71	7.6708
1337.24	7.59098
1342.77	7.4697
1348.29	6.34624
1353.81	5.92847
1359.32	8.85242
1364.83	9.84602
1370.33	21.5467
1375.84	17.9146
1381.33	31.1605
1386.82	485.417
1392.31	166.559
1397.8	20.0286
1403.28	19.3197
1408.75	44.7219
1414.22	24.4217
1419.69	9.38284
1425.15	3.99037
1430.61	1.48611
1436.07	1.13463
1441.52	3.65478
1446.96	5.29018
1452.41	3.81738
1457.84	0.382957
1463.28	-1.33903
1468.71	0.521133
1474.13	2.45118
1479.55	3.62006
1484.97	3.67829
1490.39	2.24168
1495.79	2.51619
1501.2	2.22536
1506.6	1.60253
1512	1.44993
1517.39	0.916962
1522.78	-0.0898514
1528.16	-4.65985
1533.54	-4.48222
1538.92	-0.629936
1544.29	0.0131073
1549.66	-1.13046
1555.02	-1.37653
1560.38	-1.52381
1565.74	-2.07062
1571.09	-0.967575
1576.44	1.69804
1581.78	4.01839
1587.12	4.06091
1592.46	1.20679
1597.79	-2.05055
1603.12	-1.0052
1608.44	2.42268
1613.76	5.65231
1619.08	4.43398
1624.39	4.32298
1629.7	3.08773
1635	1.53179
1640.3	2.06905
1645.59	2.03542
1650.88	1.04209
1656.17	-2.11146
1661.46	-4.5094
1666.74	-3.31698
1672.01	1.12682
1677.28	3.19849
1682.55	1.97549
1687.82	0.880806
1693.07	3.24765
1698.33	2.3727
1703.58	1.90912
1708.83	1.63334
1714.07	1.03889
1719.31	-1.61781
1724.55	2.46668
1729.78	7.97214
1735.01	9.51091
1740.23	5.31764
1745.46	2.52412
1750.67	2.27256
1755.89	2.76006
1761.09	2.1408
1766.3	1.65394
1771.5	1.97051
1776.7	3.7846
1781.89	5.26579
1787.08	3.12618
1792.27	2.91554
1797.45	2.48346
1802.62	2.32391
1807.8	2.86796
1812.97	1.33284
1818.14	3.37527
1823.3	1.69965
1828.46	1.96824
1833.61	3.46117
1838.76	3.57523
1843.91	2.40063
1849.05	-0.562271
1854.19	1.1349
1859.33	2.22303
1864.46	1.17834
1869.59	5.33038
1874.71	2.83944
1879.83	5.06346
1884.95	3.04074
1890.06	-0.0849533
1895.17	-0.549934
1900.27	0.881897
1905.38	1.86289
1910.47	1.57688
1915.57	1.64298
1920.66	3.19518
1925.74	3.90487
1930.83	4.21171
1935.91	3.58445
1940.98	1.50126
1946.05	1.5519
1951.12	2.96999
1956.18	2.34148
1961.25	2.78251
1966.3	3.98556
1971.35	4.32091
1976.4	5.78262
1981.45	-0.127182
1986.49	1.14696
1991.53	2.87537
1996.56	3.54408
2001.59	3.56702
2006.62	2.03845
2011.64	3.14697
2016.66	3.81526
2021.68	3.54189
2026.69	4.02809
2031.7	3.9216
2036.7	2.27824
2041.7	1.50862
2046.7	2.12732
2051.7	2.41264
2056.69	2.8887
2061.67	7.22228
2066.65	6.6602
2071.63	2.25074
2076.61	1.61031
2081.58	3.62629
2086.55	4.86386
2091.51	6.01454
2096.47	4.97393
2101.43	2.60332
2106.39	0.779335
2111.34	1.31297
2116.28	2.91371
2121.23	4.18731
2126.17	4.1828
2131.1	2.08698
2136.03	-0.163284
2140.96	3.93031
2145.89	5.59536
2150.81	6.02142
2155.73	0.265999
2160.64	-1.44098
2165.55	-0.212189
2170.46	4.30332
2175.36	3.48438
2180.26	3.00544
2185.16	3.16527
2190.05	3.62695
2194.94	3.76109
2199.83	3.47621
2204.71	4.22364
2209.59	3.66724
2214.46	3.0163
2219.33	2.64715
2224.2	1.16396
2229.07	1.0332
2233.93	3.3048
2238.79	3.60916
2243.64	2.99809
2248.49	-0.936935
2253.34	0.562668
2258.18	2.81168
2263.02	2.33962
2267.86	2.25763
2272.69	3.5237
2277.52	4.73313
2282.35	6.08829
2287.17	7.15136
2291.99	6.55393
2296.8	5.32944
2301.62	3.20211
2306.43	3.91878
2311.23	5.36335
2316.03	6.82433
2320.83	8.63512
2325.63	9.89742
2330.42	12.1727
2335.21	12.5046
2339.99	8.56634
2344.77	5.55119
2349.55	1.91791
2354.32	-0.675552
2359.1	1.16776
2363.86	4.6797
2368.63	7.37745
2373.39	7.60284
2378.15	6.20197
2382.9	4.93491
2387.65	2.68571
2392.4	2.15387
2397.14	4.24886
2401.88	3.93404
2406.62	4.06443
2411.35	5.09635
2416.08	5.10605
2420.81	5.88371
2425.53	5.45518
2430.25	7.18629
2434.97	5.05357
2439.69	2.93843
2444.4	3.42046
2449.1	6.68285
2453.81	5.57088
2458.51	1.82508
2463.2	5.66391
2467.9	3.96848
2472.59	1.25358
2477.27	2.37567
2481.96	4.57119
2486.64	3.8156
2491.31	7.60394
2495.99	10.4514
2500.66	11.4769
2505.32	9.16225
2509.99	6.30333
2514.65	5.3332
2519.31	5.84215
2523.96	5.2624
2528.61	6.01352
2533.26	6.6739
2537.9	6.74155
2542.54	5.80325
2547.18	5.86403
2551.81	6.38268
2556.44	5.70916
2561.07	5.04113
2565.69	4.39742
2570.32	3.3866
2574.93	2.27572
2579.55	2.29317
2584.16	3.79557
2588.77	6.05775
2593.37	6.92405
2597.97	6.59731
2602.57	6.90851
2607.17	2.7349
2611.76	6.99659
2616.35	8.04951
2620.93	5.06437
2625.51	5.53471
2630.09	5.12247
2634.67	5.45309
2639.24	6.07383
2643.81	7.341
2648.38	4.98087
2652.94	7.02267
2657.5	5.8271
2662.06	4.20815
2666.61	4.53941
2671.16	4.38217
2675.71	3.54076
2680.25	2.99457
2684.79	2.89589
2689.33	3.32959
2693.86	2.15021
2698.39	1.9417
2702.92	3.73979
2707.45	3.58582
2711.97	3.94414
2716.49	5.55949
2721	7.02321
2725.51	8.64369
2730.02	6.30499
2734.53	4.29137
2739.03	3.6896
2743.53	3.86895
2748.03	1.18748
2752.52	0.29538
2757.01	0.142212
2761.5	3.86871
2765.98	6.61173
2770.46	4.43047
2774.94	2.77313
2779.42	-0.342926
2783.89	0.932297
2788.36	4.03955
2792.82	5.02624
2797.28	3.53072
2801.74	2.7411
2806.2	4.04918
2810.65	3.75764
2815.1	4.04668
2819.55	5.73688
2823.99	0.680176
2828.43	4.04201
2832.87	6.22114
2837.3	6.80611
2841.74	6.28939
2846.17	5.06624
2850.59	5.43546
2855.01	5.51857
2859.43	3.09718
2863.85	0.73687
2868.26	0.779602
2872.67	3.28787
2877.08	5.10774
2881.48	5.59725
2885.89	4.67936
2890.28	2.61076
2894.68	1.64339
2899.07	1.61169
2903.46	2.57578
2907.85	2.80334
2912.23	-0.0244293
2916.61	-2.16244
2920.98	-0.477692
2925.36	3.10546
2929.73	5.37801
2934.1	4.07357
2938.46	1.98988
2942.82	0.0404358
2947.18	3.54612
2951.54	5.49728
2955.89	3.28075
2960.24	3.8458
2964.59	4.46178
2968.93	3.29453
2973.27	1.82787
2977.61	-0.121582
2981.95	0.175331
2986.28	-0.40065
2990.61	-0.45491
2994.94	0.260101
2999.26	1.42741
3003.58	2.13981
3007.9	1.47778
3012.21	-0.899132
3016.52	2.51335
3020.83	2.29787
3025.14	1.00259
3029.44	0.207047
3033.74	1.54512
3038.04	2.17107
3042.33	2.378
3046.62	2.32386
3050.91	3.19503
3055.2	4.07543
3059.48	1.62098
3063.76	0.790207
3068.03	1.74578
3072.31	1.56671
3076.58	2.30515
3080.85	3.2258
3085.11	4.19448
3089.37	4.98102
3093.63	4.87684
3097.89	3.72327
3102.14	4.14923
3106.39	4.18224
3110.64	3.44626
3114.89	3.17327
3119.13	4.95271
3123.37	3.72867
3127.6	1.26003
3131.84	0.062851
3136.07	0.504044
3140.29	0.852386
3144.52	0.132698
3148.74	2.29609
3152.96	2.96455
3157.18	4.5061
3161.39	4.43566
3165.6	2.63568
3169.81	5.60632
3174.01	5.18806
3178.22	-1.07815
3182.42	5.37878
3186.61	6.92422
3190.8	5.28793
3195	5.92098
3199.18	7.41293
3203.37	7.15082
3207.55	2.35313
3211.73	2.40688
3215.91	8.21256
3220.08	11.3071
3224.25	8.46642
3228.42	5.14798
3232.59	4.84339
3236.75	9.10015
3240.91	10.6618
3245.07	10.453
3249.22	9.27111
3253.37	7.62637
3257.52	6.01315
3261.67	5.87777
3265.81	6.70521
3269.95	5.40179
3274.09	6.06477
3278.22	2.84605
3282.36	2.18548
3286.49	1.37441
3290.61	0.244484
3294.74	0.897781
3298.86	3.31975
3302.98	3.78709
3307.09	4.37142
3311.21	2.96854
3315.32	4.15293
3319.42	5.42643
3323.53	5.93217
3327.63	5.0627
3331.73	2.52024
3335.83	1.92886
3339.92	2.33719
3344.01	2.43442
3348.1	1.55885
3352.19	2.34267
3356.27	0.46666
3360.35	1.07938
3364.43	3.89666
3368.5	5.26588
3372.58	6.22959
3376.65	4.88577
3380.71	4.36769
3384.78	3.70974
3388.84	5.08345
3392.9	6.10806
3396.95	5.09271
3401.01	6.45603
3405.06	4.39471
3409.1	0.676083
3413.15	4.16187
3417.19	10.1629
3421.23	11.0285
3425.27	8.79551
3429.31	6.22718
3433.34	5.86745
3437.37	6.53767
3441.39	8.2243
3445.42	7.84837
3449.44	4.22784
3453.46	4.07988
3457.47	4.25584
3461.49	2.91778
3465.5	4.21985
3469.51	5.7448
3473.51	6.42009
3477.52	6.91533
3481.52	7.34813
3485.51	6.50329
3489.51	4.31776
3493.5	3.08055
3497.49	3.17658
3501.48	3.88033
3505.46	4.96398
3509.45	4.08128
3513.43	3.66235
3517.4	4.93935
3521.38	3.18097
3525.35	2.80881
3529.32	2.51043
3533.28	2.43589
3537.25	3.10141
3541.21	4.54263
3545.17	3.04041
3549.12	3.11797
3553.08	5.31664
3557.03	5.77177
3560.98	5.35496
3564.92	5.8778
3568.87	7.91011
3572.81	9.17742
3576.74	9.98795
3580.68	13.348
3584.61	13.6821
3588.54	14.2976
3592.47	14.7394
3596.4	14.5815
3600.32	12.9367
3604.24	7.1721
3608.16	4.46039
3612.07	3.49168
3615.98	4.45904
3619.89	7.34134
3623.8	3.89932
3627.71	-0.0699959
3631.61	-1.39043
3635.51	1.09093
3639.41	3.81261
3643.3	5.3432
3647.19	5.33565
3651.08	5.51962
3654.97	3.02217
3658.85	2.58168
3662.74	5.09253
3666.62	5.64281
3670.49	5.80144
3674.37	4.97255
3678.24	3.99818
3682.11	3.8944
3685.98	1.96618
3689.84	2.96613
3693.7	4.28188
3697.56	3.46565
3701.42	4.64365
3705.28	4.45591
3709.13	1.16048
3712.98	1.53093
3716.82	2.90281
3720.67	4.00328
3724.51	3.79461
3728.35	1.46494
3732.19	2.43929
3736.02	2.74244
3739.86	2.11444
3743.69	1.56651
3747.51	2.87929
3751.34	2.44234
3755.16	2.28997
3758.98	1.11143
3762.8	1.13683
3766.61	1.64635
3770.43	2.19423
3774.24	2.83894
3778.05	2.16742
3781.85	1.52786
3785.65	0.871326
3789.45	0.411842
3793.25	1.60848
3797.05	0.649334
3800.84	2.1913
3804.63	1.86392
3808.42	-0.126221
3812.21	-0.751293
3815.99	0.693943
3819.77	1.7553
3823.55	2.74672
3827.33	3.53472
3831.1	3.40978
3834.87	1.47395
3838.64	-0.122925
3842.41	1.12662
3846.17	0.952957
3849.93	0.650658
3853.69	1.14698
3857.45	0.607227
3861.21	0.93124
3864.96	1.86093
3868.71	0.15831
3872.46	1.50437
3876.2	3.05541
3879.94	3.9033
3883.68	4.0692
3887.42	3.22872
3891.16	3.38237
3894.89	2.20545
3898.62	2.42723
3902.35	3.32499
3906.08	2.72327
3909.8	2.01364
3913.52	2.50292
3917.24	3.91294
3920.96	3.36071
3924.67	1.96886
3928.38	2.15836
3932.09	3.28175
3935.8	4.41935
3939.51	4.85032
3943.21	5.07671
3946.91	3.57908
3950.61	1.95811
3954.3	1.72037
3958	4.95255
3961.69	4.01027
3965.38	1.52636
3969.06	-0.194466
3972.75	4.00835
3976.43	7.4248
3980.11	8.46144
3983.78	4.29543
3987.46	6.04842
3991.13	5.18118
3994.8	8.05872
3998.47	5.48959