File: Data/3-Raman/processed/bu20-C-brt1-FI02-633-v.txt
#Acq. time (s)=	20
#Accumulations=	3
#Range (cm-¹)=	100...4000
#Windows=	1
#Auto scanning=	Off
#Autofocus=	Off
#Macrospot=	Off
#AutoExposure=	Off
#Spike filter=	Multiple accum.
#Delay time (s)=	0
#Binning=	1
#Readout mode=	Signal
#DeNoise=	Lite
#ICS correction=	Off
#Dark correction=	Off
#Inst. Process=	Off
#Detector temperature (°C)=	-60.09
#Instrument=	LabRAM HR Evol
#Detector=	SIN-EM FIVIS
#Objective=	x50_VIS_LWD
#Grating=	150 (500nm)
#ND Filter=	100%
#Laser=	633nm_Edge
#Hole=	30.0125
#Temperature=	0
#Range=	Visible
#StageXY=	75x50mm Scan+
#StageZ=	Z motor
#X (µm)=	7300.2
#Y (µm)=	4433.6
#Z (µm)=	-20.8
#Full time(mm:ss)=	1:35
#Project=	Buranga
#Sample=	BU18FA20_C
#Site=	C_Bertoss1
#Title=	20-C_brt1_FI02
#Remark=
#Date=	30.07.2019 14:24
#Acquired=	30.07.2019 14:24:07
#Data Range:Extract=	16.12.2021 15:36:30
#Base:Fit=	16.12.2021 15:36:40
#Base:Edit=	16.12.2021 15:37:18
#Base:Edit=	16.12.2021 15:37:19
#Base:Sub=	16.12.2021 15:37:22
100.38	1085.51
106.898	802.343
113.411	613.53
119.918	483.348
126.419	377.501
132.916	291.148
139.407	232.395
145.892	186.502
152.372	147.653
158.847	117.662
165.316	96.1761
171.781	81.0228
178.239	64.6203
184.693	45.5865
191.139	32.1744
197.582	28.2837
204.02	18.0619
210.452	8.61491
216.877	1.57053
223.299	1.18504
229.715	8.33215
236.126	33.56
242.53	76.3243
248.931	50.2486
255.326	20.8538
261.714	14.2838
268.099	22.4159
274.477	31.5634
280.851	42.3195
287.218	81.1742
293.582	81.7034
299.939	42.3409
306.293	15.8323
312.639	5.59563
318.982	11.4854
325.318	33.4827
331.651	125.114
337.977	81.1512
344.297	35.6211
350.614	11.9228
356.925	9.82631
363.23	22.4497
369.53	31.9118
375.827	22.2849
382.116	11.6316
388.401	2.9022
394.681	1.69563
400.956	2.62237
407.226	1.04903
413.49	0.0611954
419.749	5.65208
426.003	18.4273
432.252	37.2984
438.496	58.9624
444.735	66.9537
450.969	65.4286
457.197	60.1851
463.421	56.9977
469.64	41.2387
475.853	26.3918
482.062	18.1606
488.265	15.288
494.464	17.3598
500.657	18.3306
506.844	18.5641
513.028	18.027
519.206	21.4299
525.38	20.3612
531.548	16.6085
537.71	14.9917
543.869	13.4149
550.022	12.2347
556.169	11.8815
562.313	14.278
568.452	16.0445
574.584	14.0691
580.713	11.8304
586.837	15.6499
592.954	31.4913
599.068	57.7883
605.176	83.6352
611.28	80.5113
617.378	63.7391
623.473	60.7577
629.561	65.1821
635.644	67.3402
641.724	63.0248
647.797	53.7918
653.867	52.6805
659.931	72.8671
665.99	73.3051
672.044	53.0013
678.095	34.7247
684.139	22.1555
690.179	15.5405
696.213	14.8744
702.245	9.1068
708.27	4.73496
714.29	2.07831
720.306	3.45585
726.316	5.54858
732.322	5.86782
738.323	4.31889
744.32	3.59772
750.311	3.61999
756.298	7.78629
762.28	6.33881
768.258	1.89594
774.23	0.769341
780.198	1.22302
786.161	-0.295174
792.119	-0.728836
798.073	0.86441
804.021	1.81189
809.965	-0.865578
815.904	-1.48133
821.839	1.60772
827.769	4.8147
833.693	8.16189
839.614	4.85217
845.53	1.45092
851.44	2.01874
857.346	1.81789
863.248	2.40228
869.144	2.03365
875.037	1.54703
880.924	1.46384
886.807	2.90945
892.685	4.8839
898.559	5.27691
904.427	2.65319
910.292	-0.0317383
916.151	0.829727
922.006	4.08385
927.856	7.3924
933.701	9.21352
939.543	13.2028
945.379	20.2363
951.21	28.5166
957.037	45.5605
962.861	58.3999
968.678	63.1435
974.491	75.8418
980.3	102.86
986.104	169.168
991.904	230.704
997.699	230.484
1003.49	175.725
1009.28	129.643
1015.06	124.795
1020.83	147.118
1026.61	173.438
1032.37	170.634
1038.14	119.633
1043.9	74.5527
1049.65	53.7948
1055.4	43.1292
1061.15	32.8452
1066.88	25.2833
1072.62	21.9224
1078.35	25.8219
1084.08	35.5681
1089.8	47.0694
1095.52	58.3007
1101.23	66.923
1106.94	66.7898
1112.65	48.9561
1118.35	26.2631
1124.05	10.009
1129.74	6.09223
1135.42	12.4675
1141.11	20.8835
1146.78	29.8456
1152.46	39.7545
1158.13	45.6886
1163.79	35.7635
1169.45	18.9953
1175.11	1.74963
1180.76	0.871971
1186.41	1.05735
1192.05	0.552818
1197.69	2.17526
1203.32	1.20876
1208.95	-11.4922
1214.58	-1.03727
1220.2	-4.75092
1225.82	-5.71298
1231.43	-3.24505
1237.04	-1.20153
1242.64	1.12574
1248.24	5.26084
1253.83	16.1349
1259.42	33.7665
1265.01	65.437
1270.59	26.1102
1276.17	45.4154
1281.74	493.046
1287.31	305.422
1292.88	49.5392
1298.44	28.5267
1303.99	23.437
1309.55	20.7981
1315.09	17.8947
1320.64	14.4502
1326.18	11.2535
1331.71	11.0804
1337.24	12.0379
1342.77	12.4837
1348.29	11.5987
1353.81	11.693
1359.32	14.79
1364.83	22.8016
1370.33	40.4749
1375.84	37.6949
1381.33	67.4134
1386.82	1284.21
1392.31	224.573
1397.8	43.1831
1403.28	34.293
1408.75	87.5501
1414.22	39.0301
1419.69	18.4869
1425.15	11.3611
1430.61	6.68451
1436.07	5.24368
1441.52	4.7655
1446.96	3.02743
1452.41	0.547829
1457.84	-1.53393
1463.28	-2.11228
1468.71	-1.24287
1474.13	-0.870712
1479.55	-0.299202
1484.97	0.35051
1490.39	0.829803
1495.79	1.01793
1501.2	0.792465
1506.6	-0.612915
1512	-2.38241
1517.39	-1.14648
1522.78	0.637497
1528.16	0.694328
1533.54	0.508095
1538.92	0.136803
1544.29	1.66241
1549.66	4.26633
1555.02	4.6158
1560.38	1.21846
1565.74	3.65738
1571.09	5.16489
1576.44	3.56091
1581.78	3.80332
1587.12	4.71393
1592.46	5.19825
1597.79	3.62393
1603.12	0.976883
1608.44	-0.679817
1613.76	-0.661476
1619.08	1.15525
1624.39	2.65959
1629.7	3.83409
1635	4.31522
1640.3	4.43621
1645.59	4.71211
1650.88	4.91487
1656.17	4.86614
1661.46	4.4559
1666.74	4.26868
1672.01	4.90722
1677.28	4.50508
1682.55	3.32292
1687.82	2.61553
1693.07	2.83315
1698.33	4.01602
1703.58	6.07617
1708.83	8.37582
1714.07	6.4023
1719.31	1.79884
1724.55	0.468864
1729.78	1.65004
1735.01	3.30116
1740.23	5.57224
1745.46	6.55121
1750.67	3.05419
1755.89	4.34371
1761.09	4.11019
1766.3	2.80487
1771.5	0.51284
1776.7	0.204742
1781.89	2.2088
1787.08	3.35626
1792.27	3.5418
1797.45	2.76095
1802.62	1.56683
1807.8	1.52679
1812.97	1.87657
1818.14	1.44134
1823.3	2.72685
1828.46	1.49136
1833.61	-0.958344
1838.76	0.468124
1843.91	2.21023
1849.05	1.06817
1854.19	-0.0891571
1859.33	1.57114
1864.46	3.17387
1869.59	2.59059
1874.71	1.22012
1879.83	1.39898
1884.95	2.11454
1890.06	2.48085
1895.17	2.59808
1900.27	1.78846
1905.38	0.142326
1910.47	-0.128593
1915.57	0.806564
1920.66	3.13503
1925.74	4.39637
1930.83	3.91241
1935.91	2.83035
1940.98	1.55158
1946.05	-0.16111
1951.12	-1.31805
1956.18	-1.84369
1961.25	0.0181808
1966.3	1.87595
1971.35	3.21111
1976.4	2.7472
1981.45	0.220314
1986.49	-4.32553
1991.53	-4.88736
1996.56	-3.74838
2001.59	-3.65284
2006.62	-3.34182
2011.64	-1.1438
2016.66	0.246529
2021.68	-1.86471
2026.69	-1.33051
2031.7	0.581261
2036.7	1.31498
2041.7	0.454124
2046.7	-2.31676
2051.7	-3.68265
2056.69	-3.54597
2061.67	-2.55007
2066.65	-0.871323
2071.63	1.28355
2076.61	1.23643
2081.58	-1.33038
2086.55	-3.8601
2091.51	-5.34811
2096.47	-6.17683
2101.43	-5.83509
2106.39	-4.61266
2111.34	-0.913963
2116.28	-0.803276
2121.23	-1.63504
2126.17	-1.5659
2131.1	-3.62352
2136.03	-5.70214
2140.96	-6.11111
2145.89	-4.5919
2150.81	-2.25203
2155.73	-1.89543
2160.64	-3.93626
2165.55	-6.81802
2170.46	-6.78024
2175.36	-5.83588
2180.26	-7.8285
2185.16	-10.2781
2190.05	-10.2482
2194.94	-5.94489
2199.83	-1.01753
2204.71	0.729271
2209.59	-1.56066
2214.46	-2.85973
2219.33	-2.6046
2224.2	-2.18584
2229.07	-1.73956
2233.93	-2.5895
2238.79	-3.75208
2243.64	-5.30022
2248.49	-3.63364
2253.34	-2.81997
2258.18	-3.15239
2263.02	-3.68217
2267.86	-5.09997
2272.69	-5.74538
2277.52	-3.50838
2282.35	-2.53239
2287.17	-2.78986
2291.99	-4.05045
2296.8	-4.58166
2301.62	-4.41572
2306.43	-3.69126
2311.23	-4.51801
2316.03	-3.76381
2320.83	0.0223694
2325.63	9.99752
2330.42	11.7579
2335.21	4.31618
2339.99	-0.809235
2344.77	-4.06289
2349.55	-3.50591
2354.32	-1.97563
2359.1	-1.41311
2363.86	-2.92689
2368.63	-4.777
2373.39	-6.06187
2378.15	-6.59677
2382.9	-6.57674
2387.65	-6.03224
2392.4	-4.74181
2397.14	-3.56981
2401.88	-1.91049
2406.62	-7.83296
2411.35	-6.54779
2416.08	-2.99238
2420.81	-2.39066
2425.53	-1.64434
2430.25	-2.03159
2434.97	-2.80421
2439.69	-1.04189
2444.4	-0.757004
2449.1	-2.54258
2453.81	-2.45465
2458.51	-1.14207
2463.2	0.561394
2467.9	0.0450745
2472.59	-0.88842
2477.27	-3.1954
2481.96	-4.18316
2486.64	-3.80786
2491.31	-1.40077
2495.99	-0.0262222
2500.66	0.830368
2505.32	-0.0871964
2509.99	-1.71286
2514.65	-3.87959
2519.31	-2.59573
2523.96	0.381386
2528.61	2.57301
2533.26	-0.571472
2537.9	-0.267075
2542.54	0.724335
2547.18	0.801521
2551.81	0.046875
2556.44	-0.316635
2561.07	0.847603
2565.69	0.713844
2570.32	1.79336
2574.93	0.659393
2579.55	0.716766
2584.16	2.28674
2588.77	2.24876
2593.37	2.6843
2597.97	2.79608
2602.57	1.97423
2607.17	0.966759
2611.76	-0.0371246
2616.35	-0.343399
2620.93	-1.25018
2625.51	-2.67266
2630.09	-3.73827
2634.67	-2.21352
2639.24	1.21841
2643.81	3.13071
2648.38	3.72175
2652.94	3.31432
2657.5	2.17866
2662.06	0.699188
2666.61	-0.54882
2671.16	0.0427284
2675.71	1.93717
2680.25	2.25238
2684.79	2.79482
2689.33	2.67556
2693.86	3.01104
2698.39	4.56276
2702.92	4.57997
2707.45	1.99461
2711.97	1.79712
2716.49	2.38678
2721	1.72294
2725.51	2.35973
2730.02	4.72804
2734.53	5.42522
2739.03	3.34237
2743.53	2.82032
2748.03	2.557
2752.52	2.05419
2757.01	0.626682
2761.5	0.409626
2765.98	4.23932
2770.46	3.6626
2774.94	5.69567
2779.42	7.07929
2783.89	7.8973
2788.36	5.09775
2792.82	3.41048
2797.28	3.70528
2801.74	5.8745
2806.2	4.17278
2810.65	-1.31977
2815.1	0.875069
2819.55	2.94156
2823.99	3.3271
2828.43	1.88659
2832.87	0.192616
2837.3	-0.975777
2841.74	5.22168
2846.17	5.81985
2850.59	6.21953
2855.01	5.47135
2859.43	2.58532
2863.85	2.08196
2868.26	5.0214
2872.67	5.81671
2877.08	4.57962
2881.48	5.99409
2885.89	4.26064
2890.28	3.32497
2894.68	2.11831
2899.07	5.50116
2903.46	8.90909
2907.85	6.60483
2912.23	3.8179
2916.61	1.70438
2920.98	1.36775
2925.36	2.25165
2929.73	4.44861
2934.1	6.81153
2938.46	7.47371
2942.82	5.99727
2947.18	4.56547
2951.54	2.84795
2955.89	2.41772
2960.24	6.24075
2964.59	7.72003
2968.93	4.3873
2973.27	1.27646
2977.61	-1.24715
2981.95	2.44131
2986.28	4.4513
2990.61	3.22289
2994.94	3.10049
2999.26	0.302437
3003.58	6.72446
3007.9	5.81351
3012.21	2.85956
3016.52	4.19713
3020.83	1.59423
3025.14	2.07074
3029.44	6.74216
3033.74	3.73213
3038.04	1.39946
3042.33	-1.0827
3046.62	0.885387
3050.91	-0.600128
3055.2	-0.527454
3059.48	1.98405
3063.76	3.67613
3068.03	5.53884
3072.31	6.08897
3076.58	3.83118
3080.85	5.07208
3085.11	5.71278
3089.37	5.76542
3093.63	7.8617
3097.89	8.28223
3102.14	9.44435
3106.39	7.23539
3110.64	5.98933
3114.89	5.9477
3119.13	4.9175
3123.37	1.25101
3127.6	2.37695
3131.84	5.94867
3136.07	7.68362
3140.29	5.49976
3144.52	4.0073
3148.74	3.0471
3152.96	2.59008
3157.18	3.14556
3161.39	7.66463
3165.6	10.3792
3169.81	9.66234
3174.01	8.2592
3178.22	6.14737
3182.42	5.48013
3186.61	5.89043
3190.8	6.63915
3195	6.64334
3199.18	7.33118
3203.37	3.76314
3207.55	5.81949
3211.73	6.42126
3215.91	7.67681
3220.08	6.23114
3224.25	6.17075
3228.42	6.116
3232.59	3.98238
3236.75	6.95122
3240.91	7.53481
3245.07	4.99267
3249.22	2.60999
3253.37	2.27064
3257.52	3.06221
3261.67	2.39973
3265.81	3.04435
3269.95	5.1174
3274.09	4.84442
3278.22	3.16436
3282.36	2.35181
3286.49	3.65504
3290.61	3.79829
3294.74	2.09291
3298.86	1.85609
3302.98	2.0159
3307.09	1.19222
3311.21	0.791443
3315.32	0.435993
3319.42	0.569363
3323.53	2.93237
3327.63	4.92952
3331.73	5.60965
3335.83	3.76943
3339.92	2.04821
3344.01	3.10294
3348.1	2.12309
3352.19	1.57256
3356.27	-0.214024
3360.35	-0.246376
3364.43	0.208153
3368.5	1.75359
3372.58	2.31416
3376.65	4.39195
3380.71	6.69209
3384.78	2.90546
3388.84	5.83773
3392.9	5.85169
3396.95	4.46997
3401.01	4.76486
3405.06	6.22325
3409.1	6.72188
3413.15	6.2081
3417.19	6.23455
3421.23	7.46632
3425.27	7.42805
3429.31	6.64545
3433.34	5.00022
3437.37	5.38311
3441.39	5.98157
3445.42	6.12418
3449.44	4.01849
3453.46	6.11231
3457.47	6.81281
3461.49	8.23424
3465.5	5.6647
3469.51	3.15125
3473.51	2.39191
3477.52	2.07278
3481.52	2.76012
3485.51	3.94066
3489.51	2.62356
3493.5	5.05134
3497.49	6.77575
3501.48	8.00718
3505.46	8.57312
3509.45	4.76571
3513.43	6.31307
3517.4	7.77375
3521.38	7.10911
3525.35	6.35962
3529.32	5.97851
3533.28	5.92594
3537.25	6.89605
3541.21	8.49815
3545.17	8.85792
3549.12	7.98415
3553.08	8.03611
3557.03	7.06828
3560.98	7.02941
3564.92	8.23681
3568.87	9.30656
3572.81	8.91982
3576.74	8.97799
3580.68	12.5337
3584.61	15.688
3588.54	16.0084
3592.47	14.178
3596.4	10.5747
3600.32	7.8188
3604.24	9.22881
3608.16	9.94902
3612.07	9.10503
3615.98	6.59998
3619.89	6.00158
3623.8	7.01205
3627.71	7.81265
3631.61	7.63928
3635.51	7.52742
3639.41	6.89739
3643.3	6.90556
3647.19	7.84021
3651.08	8.22338
3654.97	7.41175
3658.85	6.96075
3662.74	5.22128
3666.62	6.44519
3670.49	5.85427
3674.37	4.21808
3678.24	4.95445
3682.11	6.97018
3685.98	5.31676
3689.84	4.7147
3693.7	5.81103
3697.56	3.22248
3701.42	1.76305
3705.28	1.77366
3709.13	2.99058
3712.98	5.25813
3716.82	6.49453
3720.67	7.31256
3724.51	5.81313
3728.35	4.23722
3732.19	5.42842
3736.02	6.48026
3739.86	5.37894
3743.69	4.83928
3747.51	5.331
3751.34	7.66873
3755.16	6.09281
3758.98	-2.71897
3762.8	3.93346
3766.61	7.24739
3770.43	7.43373
3774.24	6.19328
3778.05	5.93006
3781.85	5.82084
3785.65	4.1884
3789.45	4.11875
3793.25	5.45491
3797.05	5.74857
3800.84	4.68058
3804.63	3.33823
3808.42	3.14706
3812.21	4.14806
3815.99	5.27915
3819.77	6.0133
3823.55	5.06936
3827.33	3.05198
3831.1	1.80096
3834.87	2.61663
3838.64	4.74633
3842.41	3.69736
3846.17	2.37829
3849.93	2.56546
3853.69	2.47813
3857.45	2.66464
3861.21	3.67447
3864.96	3.17218
3868.71	1.86544
3872.46	0.504501
3876.2	0.597359
3879.94	2.2278
3883.68	4.23436
3887.42	2.782
3891.16	1.08255
3894.89	1.01697
3898.62	1.59187
3902.35	1.63651
3906.08	0.878262
3909.8	0.29808
3913.52	-0.55415
3917.24	2.29604
3920.96	0.485607
3924.67	-0.0624466
3928.38	-0.371559
3932.09	-0.738907
3935.8	0.112358
3939.51	2.24444
3943.21	3.41772
3946.91	1.94403
3950.61	0.140434
3954.3	1.47135
3958	2.04432
3961.69	1.18193
3965.38	-0.631302
3969.06	-3.59712
3972.75	-2.36719
3976.43	-1.59722
3980.11	-0.592991
3983.78	0.249294
3987.46	-1.02098
3991.13	-1.7693
3994.8	-1.23823
3998.47	-4.30978