File: Data/3-Raman/processed/bu20-B-brt2-FI03-633-v.txt
#Acq. time (s)=	20
#Accumulations=	3
#Range (cm-¹)=	100...4000
#Windows=	1
#Auto scanning=	Off
#Autofocus=	Off
#Macrospot=	Off
#AutoExposure=	Off
#Spike filter=	Multiple accum.
#Delay time (s)=	0
#Binning=	1
#Readout mode=	Signal
#DeNoise=	Lite
#ICS correction=	On
#Dark correction=	Off
#Inst. Process=	Off
#Detector temperature (°C)=	-60.09
#Instrument=	LabRAM HR Evol
#Detector=	SIN-EM FIVIS
#Objective=	x100_VIS
#Grating=	150 (500nm)
#ND Filter=	100%
#Laser=	633nm_Edge
#Hole=	30.0125
#Temperature=	0
#Range=	Visible
#StageXY=	75x50mm Scan+
#StageZ=	Z motor
#X (µm)=	8832.1
#Y (µm)=	4492.9
#Z (µm)=	1847.2
#Full time(mm:ss)=	1:03
#Project=	Buranga
#Sample=	BU18FA20_C
#Site=	C_Bertoss2
#Title=	20-C_brt2_FI03
#Remark=
#Date=	30.07.2019 15:31
#Acquired=	30.07.2019 15:31:25
#Data Range:Extract=	16.12.2021 15:36:30
#Base:Fit=	16.12.2021 15:36:40
#Base:Edit=	16.12.2021 15:39:16
#Base:Edit=	16.12.2021 15:39:16
#Base:Edit=	16.12.2021 15:39:17
#Base:Edit=	16.12.2021 15:39:17
#Base:Edit=	16.12.2021 15:39:18
#Base:Edit=	16.12.2021 15:39:19
#Base:Edit=	16.12.2021 15:39:19
#Base:Edit=	16.12.2021 15:39:19
#Base:Edit=	16.12.2021 15:39:29
#Base:Edit=	16.12.2021 15:39:29
#Base:Edit=	16.12.2021 15:39:30
#Base:Edit=	16.12.2021 15:39:30
#Base:Edit=	16.12.2021 15:39:31
#Base:Edit=	16.12.2021 15:39:32
#Base:Edit=	16.12.2021 15:39:33
#Base:Edit=	16.12.2021 15:39:33
#Base:Edit=	16.12.2021 15:39:34
#Base:Sub=	16.12.2021 15:39:36
100.38	73.7192
106.898	49.8867
113.411	42.5382
119.918	35.8999
126.419	30.0169
132.916	26.2008
139.407	24.6548
145.892	21.8606
152.372	19.4162
158.847	17.8644
165.316	16.8191
171.781	14.955
178.239	12.326
184.693	9.3933
191.139	7.59871
197.582	7.05172
204.02	7.44818
210.452	4.80862
216.877	0.894966
223.299	-0.0362778
229.715	2.65162
236.126	14.0165
242.53	19.8733
248.931	14.6355
255.326	9.98279
261.714	6.80207
268.099	6.08532
274.477	8.1194
280.851	15.8594
287.218	19.4729
293.582	18.5984
299.939	10.3557
306.293	5.07308
312.639	2.84321
318.982	7.02021
325.318	15.3207
331.651	24.4513
337.977	19.5181
344.297	9.11871
350.614	3.24165
356.925	3.45887
363.23	7.40741
369.53	10.8424
375.827	7.80997
382.116	4.73717
388.401	1.08516
394.681	0.192699
400.956	-0.120327
407.226	0.246429
413.49	1.33492
419.749	3.10359
426.003	5.9425
432.252	10.5674
438.496	19.9249
444.735	20.227
450.969	18.1321
457.197	15.3121
463.421	12.1734
469.64	9.6362
475.853	6.86547
482.062	3.49891
488.265	2.77925
494.464	3.10902
500.657	3.79942
506.844	4.02197
513.028	4.65282
519.206	6.03603
525.38	6.62167
531.548	5.36463
537.71	4.08123
543.869	3.0709
550.022	2.35381
556.169	3.56339
562.313	4.7843
568.452	3.96444
574.584	3.18539
580.713	3.86815
586.837	4.41578
592.954	8.25355
599.068	14.3067
605.176	19.7589
611.28	18.7458
617.378	15.2942
623.473	13.9116
629.561	14.4615
635.644	15.1161
641.724	13.6247
647.797	11.3776
653.867	14.1376
659.931	19.1743
665.99	17.8783
672.044	12.8815
678.095	6.71154
684.139	3.72921
690.179	2.41857
696.213	1.52975
702.245	0.290882
708.27	-0.22205
714.29	0.00731277
720.306	0.255539
726.316	1.26462
732.322	1.03272
738.323	0.896015
744.32	1.27233
750.311	0.932739
756.298	1.60053
762.28	2.17454
768.258	0.990398
774.23	0.956982
780.198	1.27145
786.161	0.897911
792.119	0.498112
798.073	0.54528
804.021	0.846924
809.965	1.18858
815.904	1.64254
821.839	1.75445
827.769	1.04213
833.693	0.116711
839.614	-0.2024
845.53	0.223061
851.44	0.984814
857.346	1.39771
863.248	0.552521
869.144	0.43082
875.037	1.74346
880.924	1.58188
886.807	1.19369
892.685	2.02853
898.559	0.496994
904.427	0.0968437
910.292	0.910175
916.151	1.7647
922.006	1.10883
927.856	0.973427
933.701	3.66088
939.543	5.12923
945.379	6.26564
951.21	8.4407
957.037	12.3865
962.861	15.6982
968.678	18.3361
974.491	22.0292
980.3	29.1428
986.104	40.9003
991.904	57.7358
997.699	52.0299
1003.49	42.8586
1009.28	37.7921
1015.06	36.9811
1020.83	42.5108
1026.61	48.393
1032.37	42.5351
1038.14	32.3555
1043.9	20.428
1049.65	13.7456
1055.4	10.4653
1061.15	11.3241
1066.88	9.59756
1072.62	6.01561
1078.35	8.32615
1084.08	11.2992
1089.8	14.4297
1095.52	17.4207
1101.23	20.0104
1106.94	18.6867
1112.65	12.7627
1118.35	7.18572
1124.05	5.15088
1129.74	4.74385
1135.42	4.92439
1141.11	6.53336
1146.78	10.42
1152.46	13.732
1158.13	11.9219
1163.79	8.59257
1169.45	6.20866
1175.11	4.74294
1180.76	3.61226
1186.41	1.68936
1192.05	0.362076
1197.69	0.2187
1203.32	-0.0876465
1208.95	0.21323
1214.58	1.33475
1220.2	2.41793
1225.82	2.7037
1231.43	2.07101
1237.04	0.982681
1242.64	-0.101372
1248.24	-0.225807
1253.83	1.16237
1259.42	2.53623
1265.01	3.9183
1270.59	4.35498
1276.17	5.3922
1281.74	11.8127
1287.31	16.8899
1292.88	5.50165
1298.44	3.31867
1303.99	2.30406
1309.55	2.83717
1315.09	3.72326
1320.64	3.86692
1326.18	3.71418
1331.71	2.73536
1337.24	1.92485
1342.77	2.06617
1348.29	1.75879
1353.81	1.73524
1359.32	2.46061
1364.83	3.30635
1370.33	3.66454
1375.84	4.69712
1381.33	8.39594
1386.82	37.3583
1392.31	9.66407
1397.8	4.75137
1403.28	4.47678
1408.75	3.70749
1414.22	2.32177
1419.69	1.72081
1425.15	1.01445
1430.61	0.510284
1436.07	1.88043
1441.52	2.66527
1446.96	2.53717
1452.41	0.901791
1457.84	-0.161278
1463.28	2.15171
1468.71	2.92562
1474.13	2.89287
1479.55	-0.138474
1484.97	1.091
1490.39	2.0771
1495.79	2.03218
1501.2	2.36589
1506.6	2.47391
1512	2.42225
1517.39	2.10452
1522.78	1.34667
1528.16	1.7149
1533.54	2.78717
1538.92	3.95056
1544.29	3.5579
1549.66	4.3646
1555.02	5.51484
1560.38	3.17167
1565.74	2.09275
1571.09	1.08862
1576.44	2.24208
1581.78	1.77279
1587.12	2.17575
1592.46	2.30568
1597.79	2.14338
1603.12	2.05758
1608.44	3.20196
1613.76	4.50191
1619.08	4.91369
1624.39	4.21194
1629.7	3.07987
1635	2.68475
1640.3	3.27016
1645.59	4.15332
1650.88	5.63644
1656.17	4.51446
1661.46	4.2783
1666.74	4.42625
1672.01	5.05288
1677.28	4.6354
1682.55	3.79236
1687.82	2.59005
1693.07	2.6559
1698.33	3.31074
1703.58	4.4144
1708.83	3.69388
1714.07	2.55886
1719.31	2.79465
1724.55	-0.0109634
1729.78	3.22358
1735.01	2.41302
1740.23	2.3507
1745.46	2.53366
1750.67	2.03873
1755.89	1.61271
1761.09	1.203
1766.3	1.83008
1771.5	2.36259
1776.7	3.12226
1781.89	3.88961
1787.08	3.12976
1792.27	2.03584
1797.45	1.79179
1802.62	0.403252
1807.8	1.0623
1812.97	2.09505
1818.14	2.47656
1823.3	3.39898
1828.46	0.525791
1833.61	0.972591
1838.76	2.96189
1843.91	4.54415
1849.05	3.342
1854.19	1.55037
1859.33	1.08915
1864.46	1.43945
1869.59	2.14357
1874.71	2.11069
1879.83	2.7402
1884.95	1.22034
1890.06	0.46888
1895.17	0.170177
1900.27	3.33268
1905.38	2.69781
1910.47	1.93324
1915.57	2.04115
1920.66	2.84166
1925.74	2.74572
1930.83	0.979069
1935.91	0.541386
1940.98	1.5745
1946.05	1.49039
1951.12	1.78117
1956.18	2.25643
1961.25	1.69804
1966.3	0.871624
1971.35	-0.195118
1976.4	1.33501
1981.45	1.68569
1986.49	3.02107
1991.53	2.72013
1996.56	1.5225
2001.59	0.933781
2006.62	-0.178593
2011.64	0.3592
2016.66	0.696064
2021.68	1.37499
2026.69	1.79718
2031.7	0.904152
2036.7	0.819702
2041.7	0.608665
2046.7	0.714825
2051.7	0.895081
2056.69	0.807484
2061.67	2.04223
2066.65	2.63351
2071.63	3.10873
2076.61	3.6188
2081.58	3.73464
2086.55	2.55324
2091.51	1.89347
2096.47	2.14627
2101.43	3.03333
2106.39	2.85293
2111.34	2.13908
2116.28	1.66549
2121.23	1.67438
2126.17	1.04932
2131.1	1.65141
2136.03	1.48963
2140.96	0.389683
2145.89	0.148228
2150.81	1.70031
2155.73	-0.20298
2160.64	0.214165
2165.55	0.769997
2170.46	1.87701
2175.36	0.900341
2180.26	2.41288
2185.16	2.25286
2190.05	2.14839
2194.94	2.10621
2199.83	1.72139
2204.71	1.40254
2209.59	1.84611
2214.46	2.31
2219.33	-0.839314
2224.2	-1.59659
2229.07	-0.467472
2233.93	1.18446
2238.79	1.41734
2243.64	-1.04036
2248.49	2.93733
2253.34	3.14891
2258.18	-2.38083
2263.02	-0.165207
2267.86	0.951683
2272.69	0.888866
2277.52	-0.305126
2282.35	-3.28881
2287.17	-0.705341
2291.99	2.19329
2296.8	2.19815
2301.62	1.66156
2306.43	1.8022
2311.23	2.42542
2316.03	1.79287
2320.83	1.86988
2325.63	2.25615
2330.42	1.56326
2335.21	1.8584
2339.99	2.3266
2344.77	1.93764
2349.55	1.03907
2354.32	1.6596
2359.1	1.78229
2363.86	0.151886
2368.63	-0.17392
2373.39	0.599091
2378.15	0.402451
2382.9	2.16474
2387.65	2.83811
2392.4	2.79319
2397.14	2.40437
2401.88	2.18945
2406.62	1.77497
2411.35	-0.370026
2416.08	-0.913074
2420.81	-1.36384
2425.53	-0.072094
2430.25	2.46651
2434.97	2.64551
2439.69	0.994484
2444.4	-0.555584
2449.1	1.22572
2453.81	-0.466488
2458.51	-0.780098
2463.2	0.500195
2467.9	1.99874
2472.59	1.79976
2477.27	1.26691
2481.96	0.580528
2486.64	0.627388
2491.31	2.32099
2495.99	0.948917
2500.66	2.70208
2505.32	3.38364
2509.99	2.35067
2514.65	1.32938
2519.31	0.889801
2523.96	1.84773
2528.61	3.04802
2533.26	2.11826
2537.9	1.61996
2542.54	1.87808
2547.18	2.08542
2551.81	2.20642
2556.44	1.36673
2561.07	1.47525
2565.69	2.23478
2570.32	2.67459
2574.93	2.49771
2579.55	1.55694
2584.16	0.187004
2588.77	-1.54736
2593.37	-0.685284
2597.97	0.826397
2602.57	0.427635
2607.17	1.50529
2611.76	3.14515
2616.35	3.28566
2620.93	2.11367
2625.51	1.86996
2630.09	2.4769
2634.67	1.53181
2639.24	1.62458
2643.81	0.935802
2648.38	0.505802
2652.94	0.704807
2657.5	1.0424
2662.06	-1.68406
2666.61	-1.3232
2671.16	1.23449
2675.71	4.34537
2680.25	4.02663
2684.79	3.05498
2689.33	1.68837
2693.86	-0.590004
2698.39	0.100601
2702.92	-0.0836296
2707.45	0.722881
2711.97	1.87063
2716.49	3.12934
2721	3.70053
2725.51	1.79
2730.02	-0.338295
2734.53	2.64185
2739.03	2.47332
2743.53	0.956772
2748.03	-1.41596
2752.52	1.47837
2757.01	3.62297
2761.5	3.91767
2765.98	2.17178
2770.46	1.1884
2774.94	0.199413
2779.42	-2.01319
2783.89	0.968224
2788.36	3.04156
2792.82	4.1403
2797.28	4.49914
2801.74	3.48875
2806.2	2.31824
2810.65	0.88916
2815.1	1.29341
2819.55	2.00196
2823.99	2.34836
2828.43	2.05872
2832.87	0.877533
2837.3	0.491875
2841.74	1.16592
2846.17	1.27897
2850.59	1.30717
2855.01	3.11085
2859.43	3.26307
2863.85	1.6107
2868.26	0.704029
2872.67	0.858486
2877.08	2.73295
2881.48	5.19579
2885.89	-2.57112
2890.28	0.733673
2894.68	1.0929
2899.07	1.02578
2903.46	3.29274
2907.85	4.56068
2912.23	3.32573
2916.61	2.02805
2920.98	1.16225
2925.36	0.580502
2929.73	0.608315
2934.1	1.56747
2938.46	1.70111
2942.82	1.9595
2947.18	-1.2006
2951.54	-1.83776
2955.89	0.0882874
2960.24	4.01904
2964.59	5.05034
2968.93	4.90139
2973.27	3.32345
2977.61	3.59486
2981.95	4.45727
2986.28	3.39812
2990.61	3.15106
2994.94	3.34552
2999.26	2.17943
3003.58	1.2196
3007.9	4.19572
3012.21	6.49994
3016.52	6.4783
3020.83	5.49333
3025.14	3.7563
3029.44	3.18758
3033.74	2.67056
3038.04	3.31056
3042.33	2.05997
3046.62	3.84541
3050.91	5.87009
3055.2	6.48389
3059.48	7.92509
3063.76	7.18934
3068.03	7.60989
3072.31	6.19987
3076.58	3.2708
3080.85	3.73385
3085.11	5.50561
3089.37	6.63145
3093.63	8.01308
3097.89	9.02039
3102.14	6.97738
3106.39	7.41538
3110.64	9.08011
3114.89	8.57211
3119.13	8.23405
3123.37	8.1352
3127.6	8.19586
3131.84	10.9049
3136.07	15.4059
3140.29	12.9529
3144.52	11.0158
3148.74	9.09122
3152.96	9.36002
3157.18	12.3539
3161.39	13.7338
3165.6	14.9604
3169.81	18.0225
3174.01	18.8677
3178.22	17.4384
3182.42	17.3573
3186.61	14.5984
3190.8	12.3088
3195	12.9997
3199.18	14.6454
3203.37	16.4366
3207.55	18.4149
3211.73	20.2779
3215.91	21.2137
3220.08	21.9986
3224.25	22.747
3228.42	22.3774
3232.59	20.4584
3236.75	17.1262
3240.91	15.8077
3245.07	16.0459
3249.22	18.4858
3253.37	19.3993
3257.52	19.6043
3261.67	20.7252
3265.81	20.0643
3269.95	20.4217
3274.09	19.021
3278.22	15.9784
3282.36	17.0993
3286.49	21.3651
3290.61	22.1071
3294.74	19.7111
3298.86	17.5997
3302.98	18.9582
3307.09	19.7085
3311.21	18.2365
3315.32	19.3253
3319.42	19.8604
3323.53	15.3754
3327.63	18.1501
3331.73	21.0853
3335.83	21.911
3339.92	19.8047
3344.01	16.1818
3348.1	15.0325
3352.19	16.3868
3356.27	19.9978
3360.35	25.2115
3364.43	26.7389
3368.5	21.9151
3372.58	20.6365
3376.65	27.2133
3380.71	29.4408
3384.78	28.7301
3388.84	24.527
3392.9	20.9629
3396.95	23.673
3401.01	28.4934
3405.06	27.3484
3409.1	26.7653
3413.15	27.2535
3417.19	27.3392
3421.23	26.0641
3425.27	25.2396
3429.31	24.9889
3433.34	21.1962
3437.37	25.4578
3441.39	27.5636
3445.42	22.8318
3449.44	21.4113
3453.46	21.4886
3457.47	22.0524
3461.49	24.9675
3465.5	24.8314
3469.51	23.401
3473.51	24.021
3477.52	24.8746
3481.52	24.9166
3485.51	20.7273
3489.51	22.1507
3493.5	20.5423
3497.49	20.0809
3501.48	21.0563
3505.46	21.9131
3509.45	19.8303
3513.43	19.8076
3517.4	20.2566
3521.38	17.8273
3525.35	15.4102
3529.32	16.0595
3533.28	19.6586
3537.25	19.3718
3541.21	18.0515
3545.17	16.5201
3549.12	14.4378
3553.08	11.9566
3557.03	13.34
3560.98	15.2696
3564.92	14.3965
3568.87	13.6144
3572.81	11.0658
3576.74	10.691
3580.68	17.1552
3584.61	19.2407
3588.54	16.8738
3592.47	14.1988
3596.4	13.9986
3600.32	10.3258
3604.24	10.5898
3608.16	13.5111
3612.07	12.082
3615.98	12.5793
3619.89	11.7064
3623.8	10.7772
3627.71	9.71346
3631.61	8.7034
3635.51	8.53456
3639.41	8.04691
3643.3	8.31057
3647.19	5.58179
3651.08	5.43962
3654.97	1.73176
3658.85	2.49913
3662.74	1.99068
3666.62	3.92288
3670.49	2.62121
3674.37	6.50813
3678.24	8.46377
3682.11	5.0547
3685.98	1.13372
3689.84	1.38529
3693.7	5.48734
3697.56	7.6077
3701.42	3.21313
3705.28	-0.242294
3709.13	-1.13177
3712.98	0.778831
3716.82	2.56951
3720.67	2.69141
3724.51	3.19991
3728.35	3.30274
3732.19	3.97461
3736.02	2.17074
3739.86	3.71484
3743.69	-0.0163269
3747.51	-2.57738
3751.34	-0.652534
3755.16	2.31328
3758.98	3.1323
3762.8	4.86443
3766.61	5.74562
3770.43	6.07211
3774.24	4.86967
3778.05	5.65742
3781.85	3.6547
3785.65	5.416
3789.45	5.50523
3793.25	4.16148
3797.05	1.34058
3800.84	1.51337
3804.63	5.21252
3808.42	6.0136
3812.21	4.15724
3815.99	2.2729
3819.77	0.598991
3823.55	0.693672
3827.33	1.52489
3831.1	2.35557
3834.87	-0.068718
3838.64	-1.68415
3842.41	2.66507
3846.17	2.72478
3849.93	1.87167
3853.69	0.244621
3857.45	0.646065
3861.21	2.33742
3864.96	3.01702
3868.71	3.55466
3872.46	2.99625
3876.2	2.09431
3879.94	0.133972
3883.68	-1.3119
3887.42	-2.47916
3891.16	-0.659241
3894.89	1.12339
3898.62	1.99216
3902.35	1.91849
3906.08	3.45731
3909.8	2.50932
3913.52	-0.424088
3917.24	-0.268456
3920.96	0.240692
3924.67	-0.561295
3928.38	3.30832
3932.09	3.32005
3935.8	4.69716
3939.51	5.00235
3943.21	3.64432
3946.91	3.3317
3950.61	2.84364
3954.3	2.59917
3958	3.36947
3961.69	3.42763
3965.38	0.453087
3969.06	-0.178696
3972.75	1.83427
3976.43	2.88049
3980.11	1.69018
3983.78	2.51756
3987.46	2.67924
3991.13	1.72455
3994.8	2.06041
3998.47	-2.83035