File: Data/3-Raman/processed/bu20-E-trl1-FI05-s-top.txt
#Acq. time (s)=	15
#Accumulations=	3
#Range (cm-¹)=	100...4000
#Windows=	1
#Auto scanning=	Off
#Autofocus=	Off
#Macrospot=	Off
#AutoExposure=	Off
#Spike filter=	Multiple accum.
#Delay time (s)=	0
#Binning=	1
#Readout mode=	Signal
#DeNoise=	Lite
#ICS correction=	Off
#Dark correction=	Off
#Inst. Process=	Off
#Detector temperature (°C)=	-60.09
#Instrument=	LabRAM HR Evol
#Detector=	SIN-EM FIVIS
#Objective=	x100_VIS
#Grating=	150 (500nm)
#ND Filter=	100%
#Laser=	532nm_Edge
#Hole=	30.0125
#Temperature=	0
#Range=	Visible
#StageXY=	75x50mm Scan+
#StageZ=	Z motor
#X (µm)=	14328.9
#Y (µm)=	4593.9
#Z (µm)=	1878.3
#Full time(s)=	47
#Project=	Buranga
#Sample=	BU18FA20_G
#Site=	G_trl1
#Title=	20-E_trl1_FI05_s-top
#Remark=
#Date=	30.07.2019 18:48
#Acquired=	30.07.2019 18:48:18
#Data Range:Extract=	16.12.2021 15:36:30
#Base:Fit=	16.12.2021 15:36:40
#Base:Sub=	16.12.2021 15:50:37
103.656	-63.289
108.278	-60.6954
112.899	-83.3569
117.517	-18.6821
122.131	99.1738
126.744	524.38
131.355	1581.5
135.964	2549.38
140.571	1861.31
145.173	476.593
149.776	66.7213
154.375	49.9201
158.973	288.032
163.566	893.129
168.159	1281.02
172.75	1205.1
177.339	654.045
181.923	400.814
186.507	653.427
191.089	1270.16
195.668	1577.4
200.243	1376.97
204.818	643.97
209.391	143.627
213.96	23.6931
218.528	-0.000366211
223.094	42.5477
227.655	119.729
232.217	204.44
236.776	337.444
241.331	505.564
245.886	705.658
250.439	972.561
254.987	1183.18
259.535	839.477
264.081	671.99
268.622	838.643
273.164	1321.26
277.703	2104.98
282.238	3522.63
286.773	6334.63
291.305	9289.88
295.833	9721.69
300.362	6314.04
304.885	4391.37
309.409	3764.3
313.93	3191.42
318.448	2674.61
322.965	2222.37
327.477	1843.87
331.99	1543.05
336.5	1316.22
341.007	1169.64
345.513	1078.8
350.014	1044.33
354.516	1126.14
359.013	1237.42
363.51	1095.26
368.005	868.362
372.496	801.054
376.987	871.103
381.473	967.642
385.96	1061.33
390.442	1135.91
394.923	1174.24
399.401	1189.18
403.879	1160.41
408.352	1125.35
412.825	1085.87
417.294	1052.41
421.763	1298.54
426.227	1497.93
430.692	885.972
435.152	356.814
439.612	136.006
444.068	75.7389
448.524	89.4724
452.976	140.615
457.427	206.95
461.874	289.417
466.32	393.32
470.765	500.149
475.205	633.514
479.646	822.827
484.083	1062.26
488.519	1229.44
492.951	1319.29
497.381	1284.37
501.811	1151.13
506.237	948.683
510.663	686.71
515.084	447.576
519.504	279.724
523.923	203.826
528.338	147.428
532.753	133.129
537.164	136.11
541.572	140.551
545.981	138.811
550.385	134.871
554.788	135.183
559.19	142.829
563.588	155.744
567.986	179.045
572.38	211.144
576.771	238.835
581.163	359.982
585.551	701.166
589.936	1684.86
594.319	3124.47
598.702	2579.15
603.081	1918.45
607.458	1396.49
611.835	989.536
616.208	901.911
620.578	931.434
624.949	1161.35
629.315	1452.58
633.68	2129.08
638.042	3504.84
642.404	5315.25
646.762	4719.61
651.118	2337.19
655.472	1024.81
659.825	605.461
664.175	623.598
668.523	702.727
672.868	752.923
677.213	767.744
681.555	744.773
685.894	683.192
690.231	541.979
694.566	359.426
698.901	184.205
703.232	84.3015
707.561	20.8537
711.888	-0.0949097
716.212	0.141083
720.537	8.14679
724.858	41.6553
729.176	72.8415
733.493	101.053
737.807	122.382
742.119	129.088
746.432	109.813
750.74	91.9331
755.046	87.1346
759.35	108.255
763.652	153.766
767.952	247.259
772.25	419.506
776.546	777.787
780.842	1248.65
785.133	1776.37
789.423	2126
793.711	2121.8
797.997	1849.76
802.28	1282
806.562	745.824
810.841	416.597
815.119	216.493
819.394	137.357
823.668	99.0662
827.941	64.5586
832.211	45.0345
836.478	33.6488
840.743	20.9491
845.006	11.7208
849.268	4.38538
853.527	0.0361023
857.784	-0.933014
862.039	-0.0664673
866.293	0.909698
870.544	3.62399
874.793	4.29654
879.04	5.74469
883.285	6.60916
887.528	6.20645
891.769	7.4743
896.008	13.3506
900.246	21.2503
904.481	30.5709
908.714	41.0121
912.945	53.6673
917.174	60.3994
921.401	67.6842
925.626	78.3203
929.849	102.053
934.068	141.349
938.287	195.312
942.504	265.855
946.72	333.456
950.933	408.113
955.144	475.965
959.353	529.2
963.56	580.054
967.765	625.812
971.968	683.729
976.17	768.812
980.367	903.028
984.564	1103.49
988.759	1424.08
992.953	2246.24
997.144	3755.16
1001.33	7034.11
1005.52	11141.7
1009.71	12712.5
1013.89	9693.71
1018.07	5458.14
1022.25	3174.05
1026.43	2394.54
1030.6	2682.96
1034.78	4092.46
1038.94	6495.14
1043.11	8579.35
1047.28	9513.98
1051.45	10338
1055.61	11145.6
1059.77	8999.69
1063.93	5099.45
1068.09	2764.84
1072.25	1614.74
1076.4	839.766
1080.55	939.295
1084.7	956.157
1088.85	1250.32
1092.99	1764.68
1097.14	2488.14
1101.28	3025.6
1105.42	3225.9
1109.56	2736.81
1113.69	2118.69
1117.83	1784.57
1121.96	1530.33
1126.09	1321.06
1130.22	1218.68
1134.35	1298.16
1138.47	1308.63
1142.59	1216.15
1146.71	1013.88
1150.83	774.559
1154.95	681.332
1159.06	902.417
1163.18	973.649
1167.29	960.599
1171.4	915.87
1175.5	841.09
1179.61	782.407
1183.71	684.37
1187.81	561.366
1191.91	444.767
1196.01	342.545
1200.1	250.686
1204.2	198.274
1208.29	167.354
1212.38	161.647
1216.47	164.94
1220.55	207.731
1224.64	270.758
1228.72	310.348
1232.8	321.701
1236.88	317.597
1240.95	307.466
1245.03	287.99
1249.1	263.073
1253.17	230.678
1257.24	192.445
1261.31	150.107
1265.37	114.362
1269.44	88.3364
1273.5	76.0181
1277.56	67.1214
1281.61	58.9679
1285.67	51.8904
1289.72	45.7711
1293.77	40.7095
1297.83	36.9835
1301.87	34.8985
1305.92	34.2062
1309.96	33.8672
1314.01	33.156
1318.05	31.814
1322.09	29.7007
1326.12	26.8188
1330.16	23.2583
1334.19	19.1423
1338.22	13.6774
1342.25	13.0181
1346.28	12.477
1350.3	13.288
1354.33	15.7611
1358.35	14.7828
1362.37	13.1886
1366.39	20.0855
1370.4	37.2941
1374.42	57.8094
1378.43	74.8047
1382.44	70.552
1386.45	35.2178
1390.46	26.3876
1394.46	23.7886
1398.46	20.5179
1402.47	17.7584
1406.46	10.8559
1410.46	5.87723
1414.46	3.9713
1418.45	2.65453
1422.45	1.69624
1426.43	0.997864
1430.42	0.662628
1434.41	0.199051
1438.39	0.543243
1442.38	1.04359
1446.36	0.466187
1450.34	-0.396393
1454.31	-1.24556
1458.29	-1.54825
1462.27	-1.14977
1466.24	2.90459
1470.21	6.05176
1474.18	7.94284
1478.14	8.60323
1482.11	7.45653
1486.07	5.55643
1490.03	4.96898
1493.99	5.81982
1497.95	7.68275
1501.9	11.0966
1505.86	14.9902
1509.81	19.1752
1513.76	24.6982
1517.71	26.4907
1521.65	24.7454
1525.6	21.6542
1529.54	19.9547
1533.48	27.415
1537.42	31.3333
1541.36	33.5085
1545.29	36.9918
1549.23	43.6873
1553.16	54.5552
1557.09	66.231
1561.02	78.3434
1564.94	91.0133
1568.87	103.287
1572.79	114.495
1576.71	118.317
1580.63	117.725
1584.55	113.596
1588.47	106.656
1592.38	97.8377
1596.29	88.597
1600.2	80.9308
1604.11	76.7569
1608.02	72.0815
1611.92	71.895
1615.83	73.7873
1619.73	74.8782
1623.63	75.0498
1627.53	75.1621
1631.42	75.1615
1635.32	74.5924
1639.21	73.1355
1643.1	71.0675
1646.99	68.7238
1650.88	66.1652
1654.76	63.4862
1658.64	60.464
1662.53	57.3267
1666.41	54.1858
1670.28	51.2503
1674.16	48.4117
1678.04	46.2117
1681.91	44.0665
1685.78	42.8683
1689.65	41.8927
1693.52	40.5693
1697.38	38.1483
1701.25	36.9447
1705.11	36.3561
1708.97	35.8347
1712.83	35.1147
1716.69	34.0135
1720.54	32.6386
1724.4	31.1344
1728.25	29.3187
1732.1	26.5533
1735.95	24.8955
1739.79	23.9982
1743.64	26.8042
1747.48	29.9086
1751.33	31.7795
1755.17	32.2375
1759	32.4006
1762.84	32.0138
1766.68	30.7918
1770.51	28.0833
1774.34	23.9243
1778.17	20.8638
1782	20.4463
1785.82	22.3389
1789.65	21.4182
1793.47	20.6511
1797.29	18.0099
1801.11	17.0789
1804.93	16.7723
1808.74	15.9376
1812.56	14.8375
1816.37	14.1691
1820.18	15.4461
1823.99	17.4794
1827.79	19.6255
1831.6	20.8011
1835.4	20.8399
1839.2	22.041
1843	22.7697
1846.8	23.0592
1850.6	22.2309
1854.39	20.125
1858.19	18.0732
1861.98	16.2455
1865.77	14.7102
1869.56	13.6089
1873.34	12.8887
1877.13	12.5417
1880.91	12.4504
1884.69	13.4291
1888.47	14.0655
1892.25	14.4145
1896.03	14.4582
1899.8	14.1541
1903.57	13.5877
1907.34	12.7284
1911.11	11.2949
1914.88	9.24612
1918.65	6.55281
1922.41	4.57242
1926.18	2.47397
1929.94	2.12532
1933.7	2.63588
1937.45	3.8421
1941.21	4.26752
1944.96	5.51672
1948.72	6.50034
1952.47	7.39392
1956.22	7.85316
1959.96	8.38853
1963.71	8.55627
1967.45	7.67557
1971.2	6.39693
1974.94	5.30699
1978.68	4.75841
1982.42	6.13358
1986.15	7.86833
1989.89	8.45288
1993.62	8.8748
1997.35	8.85115
2001.08	9.08806
2004.8	8.64673
2008.53	9.21185
2012.25	10.4194
2015.98	9.69836
2019.7	8.92734
2023.42	6.22253
2027.13	5.31499
2030.85	4.20303
2034.56	3.81705
2038.28	4.12866
2041.99	6.45082
2045.7	11.1767
2049.41	10.6893
2053.11	9.37198
2056.82	6.46169
2060.52	3.10934
2064.22	1.40175
2067.92	0.445709
2071.62	-0.356155
2075.31	-0.332581
2079.01	-0.282852
2082.7	-0.603531
2086.39	-0.329544
2090.08	2.07104
2093.77	4.70795
2097.45	6.87003
2101.14	8.98964
2104.82	7.33513
2108.5	4.65665
2112.18	2.92725
2115.86	2.3452
2119.54	2.23132
2123.21	2.27283
2126.88	1.70293
2130.56	0.628891
2134.23	-0.850739
2137.89	-2.18678
2141.56	-1.40166
2145.23	-0.346634
2148.89	1.11674
2152.55	2.74001
2156.21	4.31627
2159.87	6.12961
2163.53	8.09917
2167.18	9.64404
2170.84	11.6975
2174.49	14.2015
2178.14	17.0715
2181.79	17.8987
2185.44	20.2555
2189.08	19.9387
2192.73	19.7283
2196.37	19.7751
2200.01	20.0648
2203.65	21.4683
2207.29	22.3379
2210.92	23.8295
2214.56	24.0401
2218.19	23.42
2221.82	22.9137
2225.45	22.3821
2229.08	21.9179
2232.7	22.015
2236.33	22.4254
2239.95	20.779
2243.57	18.9301
2247.19	17.0289
2250.81	16.4134
2254.43	16.1461
2258.04	15.6424
2261.66	14.5639
2265.27	13.3888
2268.88	11.6402
2272.49	10.1766
2276.1	9.67473
2279.7	10.6015
2283.31	11.6225
2286.91	13.1617
2290.51	14.8447
2294.11	14.1903
2297.71	11.0507
2301.3	7.40884
2304.9	4.01205
2308.49	2.23657
2312.08	1.27228
2315.67	1.25377
2319.26	4.11945
2322.85	7.34544
2326.43	11.8324
2330.02	15.118
2333.6	18.2124
2337.18	20.7529
2340.76	23.64
2344.34	25.8508
2347.91	26.9567
2351.49	27.6857
2355.06	27.7977
2358.63	26.096
2362.2	23.2268
2365.77	19.6193
2369.33	17.3263
2372.9	15.9905
2376.46	15.0869
2380.02	14.3197
2383.58	13.6117
2387.14	12.7052
2390.7	12.4078
2394.25	12.1624
2397.81	12.6491
2401.36	12.8039
2404.91	11.4571
2408.46	10.5499
2412.01	8.98955
2415.56	6.64311
2419.1	5.31445
2422.64	4.62433
2426.18	5.11324
2429.72	5.46574
2433.26	6.39516
2436.8	7.80945
2440.34	9.70314
2443.87	11.3788
2447.4	10.8828
2450.93	7.63277
2454.46	4.18437
2457.99	1.38907
2461.52	-0.356491
2465.04	0.251328
2468.56	1.05074
2472.09	1.9382
2475.61	3.46358
2479.13	4.39722
2482.64	4.84117
2486.16	5.47325
2489.67	5.92709
2493.18	5.69438
2496.69	5.13051
2500.2	4.57115
2503.71	3.92743
2507.22	3.15573
2510.72	0.320953
2514.23	2.67873
2517.73	5.63486
2521.23	8.71863
2524.73	11.4834
2528.23	12.9402
2531.72	12.7309
2535.21	12.1458
2538.71	11.2039
2542.2	11.5858
2545.69	12.3452
2549.18	12.7628
2552.66	12.3757
2556.15	11.7176
2559.63	11.1121
2563.12	10.5183
2566.6	9.3932
2570.08	8.84918
2573.55	8.17778
2577.03	10.2239
2580.5	12.5148
2583.98	13.4302
2587.45	14.957
2590.92	15.7399
2594.39	5.34729
2597.86	5.567
2601.32	8.12843
2604.79	10.4919
2608.25	12.4318
2611.71	13.2742
2615.17	14.6425
2618.63	15.3306
2622.08	15.3456
2625.54	14.4717
2628.99	12.7689
2632.45	10.0833
2635.9	6.44527
2639.35	2.86951
2642.79	2.97095
2646.24	-0.441833
2649.69	8.91237
2653.13	13.1921
2656.57	16.9016
2660.01	18.2067
2663.45	17.8328
2666.89	15.6083
2670.32	14.6486
2673.76	13.9686
2677.19	14.478
2680.62	16.2384
2684.05	16.8009
2687.48	17.1167
2690.91	16.8176
2694.33	15.7194
2697.76	14.298
2701.18	12.9005
2704.6	9.9958
2708.02	11.964
2711.44	11.7784
2714.86	10.5576
2718.27	9.70963
2721.69	10.9459
2725.1	12.8739
2728.51	13.0399
2731.92	12.6097
2735.33	12.5752
2738.74	11.3261
2742.14	10.3344
2745.55	10.2022
2748.95	10.7476
2752.35	12.0437
2755.75	11.9284
2759.15	10.7135
2762.54	8.83565
2765.94	7.00351
2769.33	4.39006
2772.72	5.04539
2776.12	7.08757
2779.51	9.35562
2782.89	12.0613
2786.28	13.8761
2789.67	14.2759
2793.05	14.9431
2796.43	13.9451
2799.81	12.6362
2803.19	10.9076
2806.57	10.9034
2809.95	11.3188
2813.32	11.9892
2816.69	12.9536
2820.06	10.4797
2823.44	8.34073
2826.81	7.2516
2830.17	7.51843
2833.54	6.86436
2836.9	6.4183
2840.27	7.04823
2843.63	8.0672
2846.99	9.7403
2850.35	13.2618
2853.71	11.7809
2857.06	9.81731
2860.42	3.9398
2863.77	-0.493317
2867.12	-0.133331
2870.48	-3.75607
2873.83	4.04652
2877.17	4.8288
2880.52	6.38545
2883.86	4.41524
2887.21	4.64391
2890.55	5.11389
2893.89	5.4211
2897.23	5.58679
2900.57	5.44601
2903.91	5.22559
2907.24	4.88554
2910.57	4.62466
2913.91	4.00624
2917.24	2.58015
2920.57	1.00903
2923.9	-0.496979
2927.22	1.45369
2930.55	2.11903
2933.87	2.34435
2937.19	1.67824
2940.51	1.8069
2943.83	1.87042
2947.15	2.70525
2950.47	4.16269
2953.79	6.09087
2957.1	7.94382
2960.41	9.27188
2963.72	9.99008
2967.03	10.5207
2970.34	8.8541
2973.65	7.17387
2976.95	6.86185
2980.26	5.92455
2983.56	5.62802
2986.86	4.90259
2990.16	5.84027
2993.46	6.7619
2996.76	9.42862
3000.06	10.634
3003.35	11.9674
3006.64	13.3768
3009.94	15.2336
3013.23	15.9705
3016.51	17.8744
3019.8	19.3331
3023.09	19.7412
3026.38	19.8453
3029.66	20.5104
3032.94	21.6919
3036.22	23.1217
3039.5	24.4915
3042.78	25.7056
3046.05	27.7877
3049.33	32.1267
3052.6	33.8807
3055.88	34.6396
3059.15	38.5852
3062.42	38.4902
3065.69	39.8321
3068.95	44.5704
3072.22	53.5565
3075.48	60.9798
3078.75	66.9383
3082.01	73.205
3085.27	78.1546
3088.53	80.9013
3091.79	84.1963
3095.04	86.7169
3098.3	90.4675
3101.55	98.0123
3104.8	107.602
3108.05	113.899
3111.3	119.849
3114.55	127.548
3117.8	137.286
3121.04	142.589
3124.29	146.767
3127.53	151.982
3130.77	157.992
3134.01	166.352
3137.25	174.434
3140.49	182.761
3143.72	190.429
3146.96	197.427
3150.19	204.308
3153.42	211.241
3156.65	217.908
3159.88	229.4
3163.11	242.782
3166.34	256.193
3169.56	269.68
3172.79	282.009
3176.01	292.05
3179.23	303.317
3182.45	314.842
3185.67	322.461
3188.88	331.548
3192.1	340.922
3195.31	350.656
3198.53	360.901
3201.74	372.147
3204.95	382.84
3208.16	392.611
3211.37	400.431
3214.57	414.773
3217.78	425.937
3220.98	440.001
3224.18	455.325
3227.39	459.252
3230.59	449.271
3233.78	467.93
3236.98	485.265
3240.18	498.104
3243.37	509.336
3246.56	518.36
3249.76	529.808
3252.95	539.292
3256.14	545.829
3259.32	549.674
3262.51	548.386
3265.7	545.752
3268.88	542.52
3272.06	537.867
3275.24	534.776
3278.42	533.992
3281.6	535.566
3284.78	539.416
3287.96	545.606
3291.13	555.294
3294.31	567.654
3297.48	582.533
3300.65	598.922
3303.82	614.586
3306.99	630.607
3310.15	646.734
3313.32	662.323
3316.48	677.73
3319.65	694.351
3322.81	712.235
3325.97	733.072
3329.13	752.621
3332.28	777.19
3335.44	807.905
3338.6	850.272
3341.75	907.329
3344.9	978.766
3348.05	1062.99
3351.2	1173.3
3354.35	1342.75
3357.5	1540.82
3360.65	1803.99
3363.79	2323.41
3366.94	3281.66
3370.08	5029.94
3373.22	7727.24
3376.36	10273.6
3379.5	10476.9
3382.63	7951.28
3385.77	5314.68
3388.9	3694.1
3392.04	2792.6
3395.17	2282.34
3398.3	1988.23
3401.43	1803.93
3404.56	1665.15
3407.69	1540.13
3410.81	1617.86
3413.94	1706.47
3417.06	2007.14
3420.18	2720.84
3423.3	4449.57
3426.42	5905.32
3429.54	5348.11
3432.65	3568.93
3435.77	2212.77
3438.88	1551.59
3442	1362.65
3445.11	1230.5
3448.22	1145.7
3451.33	1097.02
3454.43	1070.27
3457.54	1056.37
3460.65	1048.21
3463.75	1049.97
3466.85	1061.33
3469.95	1074.28
3473.05	1094.11
3476.15	1127.64
3479.25	1176.16
3482.35	1246.1
3485.44	1330.18
3488.54	1488.1
3491.63	1654.62
3494.72	1918.17
3497.81	2208.29
3500.9	2840.69
3503.99	3478.4
3507.07	4035.94
3510.16	4120.56
3513.24	3695.4
3516.32	3081.33
3519.41	2441.97
3522.49	1974.44
3525.56	1634.16
3528.64	1328.33
3531.72	1151.69
3534.79	1035.01
3537.87	952.397
3540.94	882.386
3544.01	817.277
3547.08	757.705
3550.15	703.402
3553.22	654.521
3556.28	610.568
3559.35	573.093
3562.41	538.134
3565.47	508.104
3568.54	482.785
3571.6	461.821
3574.65	443.48
3577.71	424.769
3580.77	405.578
3583.82	396.718
3586.88	388.968
3589.93	371.623
3592.98	352.104
3596.03	320.559
3599.08	305.701
3602.13	311.28
3605.18	311.889
3608.22	301.414
3611.27	284.422
3614.31	267.003
3617.35	248.723
3620.39	233.379
3623.43	222.197
3626.47	213.916
3629.5	206.194
3632.54	198.361
3635.57	186.804
3638.61	175.693
3641.64	165.223
3644.67	152.332
3647.7	144.536
3650.73	140.014
3653.75	131.425
3656.78	121.614
3659.8	112.112
3662.83	102.081
3665.85	90.6861
3668.87	75.6953
3671.89	67.0934
3674.91	60.6162
3677.92	56.3839
3680.94	51.519
3683.96	47.4033
3686.97	43.4039
3689.98	39.3659
3692.99	32.7404
3696	26.6039
3699.01	21.2796
3702.02	16.7185
3705.02	8.43311
3708.03	0.607971
3711.03	-0.76825
3714.03	-0.565277
3717.04	1.94101
3720.04	4.55246
3723.04	5.20331
3726.03	4.00589
3729.03	3.59203
3732.03	3.81558
3735.02	3.2755
3738.01	4.72763
3741	5.44821
3743.99	4.67332
3746.98	2.97751
3749.97	0.998108
3752.96	-0.318878
3755.95	0.283875
3758.93	2.02155
3761.91	4.31894
3764.9	5.49898
3767.88	6.41499
3770.86	7.07454
3773.84	7.86673
3776.81	8.83269
3779.79	9.82794
3782.77	12.797
3785.74	16.1037
3788.71	19.8196
3791.68	23.8278
3794.65	25.8264
3797.62	26.9505
3800.59	25.6284
3803.56	26.4435
3806.52	28.0176
3809.49	30.2823
3812.45	31.5092
3815.41	32.6707
3818.37	34.4705
3821.33	36.8096
3824.29	39.8267
3827.25	43.2863
3830.21	47.4213
3833.16	50.5296
3836.11	51.0954
3839.07	51.7835
3842.02	52.9233
3844.97	54.3846
3847.92	55.7269
3850.87	56.969
3853.81	57.1213
3856.76	64.6409
3859.7	67.9415
3862.65	66.0632
3865.59	65.2551
3868.53	62.4965
3871.47	44.6703
3874.41	61.5049
3877.34	71.0666
3880.28	74.2664
3883.22	74.3143
3886.15	74.6353
3889.08	65.257
3892.01	69.4816
3894.94	74.663
3897.87	73.9112
3900.8	74.0195
3903.73	75.0859
3906.65	76.765
3909.58	77.728
3912.5	77.9631
3915.42	76.7068
3918.35	74.9386
3921.27	73.049
3924.18	71.5492
3927.1	70.2442
3930.02	69.4184
3932.93	68.7309
3935.85	68.4253
3938.76	68.3094
3941.67	68.3639
3944.58	67.8848
3947.49	67.2389
3950.4	66.3281
3953.31	65.028
3956.22	62.9377
3959.12	59.8367
3962.02	55.2318
3964.93	50.8309
3967.83	46.3396
3970.73	42.5531
3973.63	40.6715
3976.53	47.3659
3979.42	45.082
3982.32	42.3086
3985.21	39.4855
3988.11	36.2842
3991	32.9518
3993.89	29.3013
3996.78	18.5501
3999.67	-0.0213165