File: Data/3-Raman/processed/bu20-C-brt1-FI10-633-v.txt
#Acq. time (s)=	20
#Accumulations=	3
#Range (cm-¹)=	100...4000
#Windows=	1
#Auto scanning=	Off
#Autofocus=	Off
#Macrospot=	Off
#AutoExposure=	Off
#Spike filter=	Multiple accum.
#Delay time (s)=	0
#Binning=	1
#Readout mode=	Signal
#DeNoise=	Lite
#ICS correction=	Off
#Dark correction=	Off
#Inst. Process=	Off
#Detector temperature (°C)=	-60.09
#Instrument=	LabRAM HR Evol
#Detector=	SIN-EM FIVIS
#Objective=	x50_VIS_LWD
#Grating=	150 (500nm)
#ND Filter=	100%
#Laser=	633nm_Edge
#Hole=	30.0125
#Temperature=	0
#Range=	Visible
#StageXY=	75x50mm Scan+
#StageZ=	Z motor
#X (µm)=	7377.7
#Y (µm)=	4349.7
#Z (µm)=	-28.6
#Full time(mm:ss)=	1:02
#Project=	Buranga
#Sample=	BU18FA20_C
#Site=	C_Bertoss1
#Title=	20-C_brt1_FI10
#Remark=
#Date=	30.07.2019 14:35
#Acquired=	30.07.2019 14:35:08
#Data Range:Extract=	16.12.2021 15:36:30
#Base:Fit=	16.12.2021 15:36:40
#Base:Edit=	16.12.2021 15:37:47
#Base:Edit=	16.12.2021 15:37:49
#Base:Edit=	16.12.2021 15:37:50
#Base:Edit=	16.12.2021 15:37:51
#Base:Edit=	16.12.2021 15:37:52
#Base:Edit=	16.12.2021 15:37:52
#Base:Sub=	16.12.2021 15:37:54
100.38	395.051
106.898	308.199
113.411	238.712
119.918	189.158
126.419	142.04
132.916	106.493
139.407	88.423
145.892	73.557
152.372	60.3797
158.847	42.8304
165.316	30.3888
171.781	38.6644
178.239	23.3718
184.693	12.5931
191.139	10.0795
197.582	7.13872
204.02	3.70055
210.452	-0.0269241
216.877	-1.20238
223.299	-0.24234
229.715	4.9538
236.126	35.4168
242.53	127.851
248.931	98.22
255.326	51.6625
261.714	37.0911
268.099	37.5685
274.477	49.5999
280.851	79.77
287.218	161.145
293.582	149.392
299.939	89.1969
306.293	44.951
312.639	23.7133
318.982	27.4
325.318	63.7937
331.651	169.251
337.977	157.539
344.297	75.3625
350.614	36.9264
356.925	28.7327
363.23	50.8195
369.53	72.4976
375.827	67.1021
382.116	38.9527
388.401	16.1398
394.681	2.82984
400.956	-1.95586
407.226	2.8287
413.49	10.84
419.749	19.9861
426.003	37.5631
432.252	69.4915
438.496	107.416
444.735	130.792
450.969	126.447
457.197	109.9
463.421	88.4784
469.64	65.8519
475.853	37.3372
482.062	20.8577
488.265	20.6555
494.464	21.1136
500.657	22.2173
506.844	24.3394
513.028	27.9836
519.206	30.9891
525.38	30.5749
531.548	30.7945
537.71	27.0046
543.869	23.9425
550.022	22.0736
556.169	21.3269
562.313	21.7982
568.452	19.4707
574.584	16.1785
580.713	14.7353
586.837	21.4466
592.954	37.6223
599.068	69.3857
605.176	128.166
611.28	127.709
617.378	95.725
623.473	86.5709
629.561	93.0995
635.644	99.7673
641.724	98.6525
647.797	88.9588
653.867	88.7957
659.931	108.352
665.99	114.554
672.044	87.6783
678.095	54.9489
684.139	31.0065
690.179	17.2289
696.213	11.7435
702.245	9.53629
708.27	8.41639
714.29	8.90503
720.306	8.4784
726.316	7.36078
732.322	5.04388
738.323	5.87753
744.32	6.54628
750.311	5.728
756.298	6.30879
762.28	7.10623
768.258	6.96842
774.23	5.02182
780.198	3.15219
786.161	2.82332
792.119	-0.0432816
798.073	1.62657
804.021	4.96532
809.965	4.03997
815.904	3.15606
821.839	4.45344
827.769	7.73347
833.693	10.0699
839.614	10.2369
845.53	8.67172
851.44	7.21114
857.346	6.91035
863.248	7.94919
869.144	8.99225
875.037	10.5788
880.924	14.173
886.807	17.4463
892.685	17.4695
898.559	17.4855
904.427	15.7049
910.292	14.036
916.151	14.362
922.006	16.8642
927.856	18.3756
933.701	20.5532
939.543	27.4726
945.379	41.464
951.21	62.2033
957.037	86.9563
962.861	102.677
968.678	113.387
974.491	135.835
980.3	178.274
986.104	232.906
991.904	376.531
997.699	402.235
1003.49	312.314
1009.28	249.657
1015.06	215.797
1020.83	242.681
1026.61	289.995
1032.37	321.987
1038.14	224.799
1043.9	135.132
1049.65	102.769
1055.4	84.2249
1061.15	70.419
1066.88	57.0844
1072.62	51.9704
1078.35	60.1474
1084.08	79.8579
1089.8	98.4992
1095.52	105.332
1101.23	112.128
1106.94	123.714
1112.65	90.3443
1118.35	55.3511
1124.05	33.649
1129.74	28.4969
1135.42	31.9501
1141.11	38.8372
1146.78	50.4345
1152.46	63.6998
1158.13	85.7314
1163.79	70.7998
1169.45	39.7198
1175.11	26.5254
1180.76	21.9543
1186.41	18.6942
1192.05	13.2805
1197.69	8.28059
1203.32	4.08165
1208.95	1.98711
1214.58	1.14974
1220.2	1.27345
1225.82	2.50718
1231.43	4.05563
1237.04	4.10155
1242.64	2.18689
1248.24	0.401405
1253.83	0.350914
1259.42	8.84937
1265.01	16.6812
1270.59	15.8727
1276.17	18.5206
1281.74	114.703
1287.31	168.883
1292.88	15.2666
1298.44	8.82159
1303.99	6.18703
1309.55	5.37038
1315.09	5.71684
1320.64	5.62078
1326.18	4.55606
1331.71	3.76775
1337.24	4.12252
1342.77	5.08609
1348.29	3.89322
1353.81	2.72156
1359.32	4.89532
1364.83	7.52177
1370.33	12.4045
1375.84	13.0645
1381.33	23.0829
1386.82	330.217
1392.31	122.403
1397.8	20.577
1403.28	8.13123
1408.75	33.1592
1414.22	22.8934
1419.69	13.8048
1425.15	9.28091
1430.61	4.98348
1436.07	2.7436
1441.52	1.80917
1446.96	2.97193
1452.41	4.63345
1457.84	1.67036
1463.28	-0.104332
1468.71	0.944511
1474.13	3.02985
1479.55	-0.502388
1484.97	1.0915
1490.39	3.10562
1495.79	4.91364
1501.2	4.57327
1506.6	0.894127
1512	-0.554611
1517.39	0.461502
1522.78	1.96097
1528.16	1.81968
1533.54	0.756432
1538.92	1.63805
1544.29	2.45922
1549.66	2.71708
1555.02	2.19338
1560.38	0.68343
1565.74	0.61681
1571.09	2.71619
1576.44	4.10447
1581.78	4.57999
1587.12	4.55701
1592.46	7.0767
1597.79	7.40546
1603.12	6.30235
1608.44	4.86301
1613.76	5.16586
1619.08	6.85687
1624.39	7.57597
1629.7	7.1321
1635	6.27757
1640.3	5.45084
1645.59	4.70581
1650.88	4.07091
1656.17	3.72778
1661.46	3.71291
1666.74	5.19521
1672.01	6.13868
1677.28	5.97457
1682.55	5.20245
1687.82	4.98331
1693.07	6.2883
1698.33	6.93678
1703.58	8.64329
1708.83	6.46939
1714.07	4.1095
1719.31	2.77123
1724.55	2.14711
1729.78	2.30167
1735.01	4.12128
1740.23	5.74433
1745.46	3.3035
1750.67	1.57737
1755.89	2.05583
1761.09	2.82177
1766.3	3.15081
1771.5	3.60311
1776.7	4.40154
1781.89	5.86439
1787.08	6.29582
1792.27	4.53443
1797.45	3.53322
1802.62	4.97368
1807.8	6.17292
1812.97	6.15578
1818.14	4.90765
1823.3	3.88034
1828.46	4.35284
1833.61	4.68491
1838.76	6.37738
1843.91	6.86673
1849.05	5.77893
1854.19	3.75618
1859.33	1.2309
1864.46	0.669407
1869.59	5.69525
1874.71	3.26217
1879.83	1.88332
1884.95	5.33786
1890.06	5.78608
1895.17	5.32735
1900.27	4.66519
1905.38	3.96731
1910.47	4.58866
1915.57	4.23317
1920.66	3.1714
1925.74	2.0268
1930.83	1.42762
1935.91	3.15985
1940.98	4.20096
1946.05	5.83813
1951.12	6.521
1956.18	6.83749
1961.25	6.15944
1966.3	5.53012
1971.35	6.60146
1976.4	6.36034
1981.45	5.36825
1986.49	5.46464
1991.53	5.81083
1996.56	5.17728
2001.59	3.9726
2006.62	3.26477
2011.64	2.92419
2016.66	-0.188282
2021.68	1.26619
2026.69	4.87139
2031.7	6.6888
2036.7	7.77924
2041.7	8.07667
2046.7	2.21732
2051.7	4.63506
2056.69	6.20734
2061.67	6.15226
2066.65	4.93947
2071.63	3.47546
2076.61	3.15056
2081.58	4.1226
2086.55	5.17588
2091.51	5.43422
2096.47	4.55837
2101.43	3.06389
2106.39	2.57964
2111.34	3.74764
2116.28	5.11321
2121.23	5.2439
2126.17	4.36946
2131.1	3.73827
2136.03	4.47425
2140.96	5.28811
2145.89	4.10577
2150.81	3.60208
2155.73	2.61422
2160.64	1.29618
2165.55	0.786915
2170.46	2.54213
2175.36	4.39994
2180.26	5.91807
2185.16	5.38342
2190.05	5.86315
2194.94	2.50006
2199.83	-3.07378
2204.71	3.66527
2209.59	5.61169
2214.46	5.51036
2219.33	3.79478
2224.2	3.90565
2229.07	3.55456
2233.93	4.17457
2238.79	4.53069
2243.64	4.19979
2248.49	3.6188
2253.34	4.05559
2258.18	1.93521
2263.02	2.19207
2267.86	4.27184
2272.69	5.02708
2277.52	4.41885
2282.35	3.0703
2287.17	0.644318
2291.99	1.79349
2296.8	4.38988
2301.62	6.0878
2306.43	5.24219
2311.23	4.40859
2316.03	4.50753
2320.83	6.21842
2325.63	8.0639
2330.42	10.7615
2335.21	7.97307
2339.99	5.54406
2344.77	7.63731
2349.55	8.38503
2354.32	5.93107
2359.1	2.50084
2363.86	1.73871
2368.63	1.91123
2373.39	2.08418
2378.15	1.09942
2382.9	1.86318
2387.65	2.28922
2392.4	2.79225
2397.14	3.50852
2401.88	2.52432
2406.62	-0.442265
2411.35	1.83386
2416.08	3.20189
2420.81	3.30656
2425.53	4.34094
2430.25	3.43398
2434.97	2.93464
2439.69	2.45363
2444.4	3.44158
2449.1	5.07248
2453.81	3.73614
2458.51	1.51904
2463.2	0.920868
2467.9	2.10024
2472.59	4.65025
2477.27	4.01731
2481.96	1.8511
2486.64	1.78687
2491.31	2.676
2495.99	2.85278
2500.66	2.62822
2505.32	1.68851
2509.99	0.0835533
2514.65	0.638443
2519.31	2.00962
2523.96	2.71205
2528.61	2.79591
2533.26	1.11938
2537.9	1.1428
2542.54	2.4848
2547.18	5.31138
2551.81	6.46341
2556.44	5.96173
2561.07	3.47434
2565.69	0.00959015
2570.32	0.811073
2574.93	2.23942
2579.55	4.66133
2584.16	4.63025
2588.77	3.8848
2593.37	3.26075
2597.97	3.05016
2602.57	3.46687
2607.17	3.03358
2611.76	5.44905
2616.35	3.03285
2620.93	2.69591
2625.51	4.13846
2630.09	4.38187
2634.67	4.31304
2639.24	4.84739
2643.81	4.21381
2648.38	3.41209
2652.94	2.07338
2657.5	0.33466
2662.06	-0.450314
2666.61	1.1937
2671.16	3.33201
2675.71	5.05177
2680.25	6.61211
2684.79	6.51944
2689.33	5.92395
2693.86	4.07268
2698.39	3.92847
2702.92	2.78054
2707.45	0.871212
2711.97	-0.989559
2716.49	0.99691
2721	3.1111
2725.51	4.44294
2730.02	5.1027
2734.53	5.55337
2739.03	3.79372
2743.53	2.94705
2748.03	4.04488
2752.52	5.63436
2757.01	6.66608
2761.5	7.2617
2765.98	6.57075
2770.46	5.32056
2774.94	3.29062
2779.42	2.07291
2783.89	1.39361
2788.36	3.14522
2792.82	3.55484
2797.28	3.742
2801.74	4.82919
2806.2	0.767113
2810.65	2.46844
2815.1	4.22023
2819.55	-1.62935
2823.99	-0.531174
2828.43	1.43094
2832.87	-0.551792
2837.3	4.15518
2841.74	3.89215
2846.17	2.27294
2850.59	1.76211
2855.01	0.781734
2859.43	1.6053
2863.85	2.35673
2868.26	3.07857
2872.67	4.22385
2877.08	3.27842
2881.48	3.77431
2885.89	5.24042
2890.28	6.12679
2894.68	3.98653
2899.07	1.88907
2903.46	0.63929
2907.85	0.763279
2912.23	2.41383
2916.61	3.36512
2920.98	1.25349
2925.36	1.51408
2929.73	0.938816
2934.1	0.717888
2938.46	-0.172291
2942.82	0.7673
2947.18	3.33391
2951.54	3.09312
2955.89	2.05386
2960.24	2.92535
2964.59	2.19191
2968.93	2.90802
2973.27	4.08342
2977.61	2.96058
2981.95	0.863918
2986.28	0.907227
2990.61	-0.384319
2994.94	3.84786
2999.26	4.02283
3003.58	3.29161
3007.9	2.27206
3012.21	1.76955
3016.52	2.54517
3020.83	2.12205
3025.14	2.14629
3029.44	2.79394
3033.74	2.28875
3038.04	1.43485
3042.33	-0.279411
3046.62	1.75302
3050.91	2.00441
3055.2	1.69167
3059.48	2.51671
3063.76	2.47422
3068.03	2.98343
3072.31	3.54188
3076.58	5.28283
3080.85	4.26709
3085.11	0.824615
3089.37	2.03448
3093.63	3.41619
3097.89	3.63202
3102.14	3.69798
3106.39	3.87556
3110.64	4.80466
3114.89	3.39143
3119.13	4.34665
3123.37	4.37805
3127.6	5.3435
3131.84	6.22234
3136.07	4.08613
3140.29	6.88279
3144.52	7.84625
3148.74	6.6165
3152.96	5.20813
3157.18	6.19876
3161.39	5.66908
3165.6	5.24583
3169.81	6.87312
3174.01	6.68943
3178.22	8.56132
3182.42	10.0382
3186.61	9.51312
3190.8	7.68191
3195	7.29615
3199.18	6.73548
3203.37	7.75474
3207.55	11.0684
3211.73	10.4509
3215.91	10.0167
3220.08	7.99382
3224.25	6.48011
3228.42	7.55328
3232.59	9.8997
3236.75	8.85541
3240.91	7.62715
3245.07	5.24737
3249.22	6.26717
3253.37	6.24881
3257.52	6.67139
3261.67	4.6729
3265.81	3.66056
3269.95	2.3673
3274.09	1.40928
3278.22	1.06535
3282.36	3.62734
3286.49	4.43407
3290.61	4.81742
3294.74	2.91851
3298.86	1.4346
3302.98	1.56821
3307.09	1.38092
3311.21	1.48941
3315.32	4.01054
3319.42	3.34026
3323.53	4.36774
3327.63	3.74161
3331.73	3.87537
3335.83	5.04852
3339.92	4.40119
3344.01	4.14832
3348.1	2.8587
3352.19	3.30363
3356.27	5.07375
3360.35	6.89908
3364.43	6.62514
3368.5	1.46558
3372.58	0.549458
3376.65	6.10939
3380.71	7.10352
3384.78	7.47672
3388.84	6.79977
3392.9	6.37943
3396.95	6.54842
3401.01	7.35672
3405.06	8.53027
3409.1	8.56336
3413.15	7.49552
3417.19	6.38762
3421.23	4.63821
3425.27	5.09289
3429.31	5.67854
3433.34	5.56729
3437.37	5.9835
3441.39	6.11777
3445.42	7.51254
3449.44	8.49661
3453.46	6.07693
3457.47	4.82856
3461.49	4.86372
3465.5	5.37583
3469.51	4.09752
3473.51	4.04871
3477.52	3.11458
3481.52	5.52705
3485.51	7.06443
3489.51	6.68688
3493.5	4.89729
3497.49	3.78563
3501.48	2.2754
3505.46	1.79235
3509.45	5.09671
3513.43	2.19324
3517.4	0.266232
3521.38	1.55748
3525.35	3.5128
3529.32	4.18364
3533.28	3.84657
3537.25	3.93925
3541.21	2.82102
3545.17	1.68118
3549.12	2.62964
3553.08	2.46077
3557.03	4.99385
3560.98	3.60529
3564.92	5.06156
3568.87	6.40591
3572.81	8.85866
3576.74	12.178
3580.68	13.8068
3584.61	14.7544
3588.54	16.0744
3592.47	17.9813
3596.4	15.7801
3600.32	8.15016
3604.24	7.27232
3608.16	7.27856
3612.07	3.97899
3615.98	0.71627
3619.89	0.334949
3623.8	-0.617233
3627.71	-1.36347
3631.61	0.420372
3635.51	2.10096
3639.41	3.0896
3643.3	1.92743
3647.19	2.05959
3651.08	2.32138
3654.97	-0.507614
3658.85	-5.23272
3662.74	-1.80951
3666.62	0.646832
3670.49	0.396751
3674.37	-1.01874
3678.24	-1.85415
3682.11	-0.672585
3685.98	0.767895
3689.84	0.868511
3693.7	0.545868
3697.56	0.393234
3701.42	0.899147
3705.28	0.766792
3709.13	0.232933
3712.98	0.236206
3716.82	-0.0294762
3720.67	-0.927658
3724.51	-0.525623
3728.35	0.532074
3732.19	1.09134
3736.02	0.55468
3739.86	1.44836
3743.69	0.508564
3747.51	-0.86446
3751.34	-0.920177
3755.16	0.0288658
3758.98	0.978355
3762.8	-0.914597
3766.61	0.563808
3770.43	2.52357
3774.24	1.45031
3778.05	-0.00450134
3781.85	1.36647
3785.65	2.76151
3789.45	2.47334
3793.25	1.43274
3797.05	0.643963
3800.84	0.126038
3804.63	0.12468
3808.42	0.0156059
3812.21	-0.840389
3815.99	-0.923634
3819.77	1.27478
3823.55	2.37097
3827.33	2.77466
3831.1	0.794888
3834.87	1.50536
3838.64	2.24993
3842.41	1.60388
3846.17	0.844666
3849.93	0.457722
3853.69	1.46183
3857.45	1.55523
3861.21	1.51141
3864.96	1.85571
3868.71	0.401958
3872.46	0.0916824
3876.2	-0.0592422
3879.94	0.993412
3883.68	1.47688
3887.42	1.24498
3891.16	1.14505
3894.89	1.37793
3898.62	1.49882
3902.35	1.2131
3906.08	1.72136
3909.8	1.7757
3913.52	1.122
3917.24	0.729881
3920.96	0.56918
3924.67	0.3885
3928.38	1.36054
3932.09	1.33837
3935.8	0.785305
3939.51	-1.18758
3943.21	1.11795
3946.91	-0.00977707
3950.61	-0.828796
3954.3	0.395485
3958	-0.356373
3961.69	0.932755
3965.38	0.266987
3969.06	-1.32659
3972.75	-0.00729752
3976.43	1.53271
3980.11	1.45462
3983.78	-0.265038
3987.46	-1.54515
3991.13	-1.70832
3994.8	-0.654049
3998.47	0.555828