File: Data/3-Raman/processed/bu20-C-brt1-FI07-633-v.txt
#Acq. time (s)=	20
#Accumulations=	3
#Range (cm-¹)=	100...4000
#Windows=	1
#Auto scanning=	Off
#Autofocus=	Off
#Macrospot=	Off
#AutoExposure=	Off
#Spike filter=	Multiple accum.
#Delay time (s)=	0
#Binning=	1
#Readout mode=	Signal
#DeNoise=	Lite
#ICS correction=	Off
#Dark correction=	Off
#Inst. Process=	Off
#Detector temperature (°C)=	-60.09
#Instrument=	LabRAM HR Evol
#Detector=	SIN-EM FIVIS
#Objective=	x50_VIS_LWD
#Grating=	150 (500nm)
#ND Filter=	100%
#Laser=	633nm_Edge
#Hole=	30.0125
#Temperature=	0
#Range=	Visible
#StageXY=	75x50mm Scan+
#StageZ=	Z motor
#X (µm)=	7435.8
#Y (µm)=	4166.6
#Z (µm)=	-29.5
#Full time(mm:ss)=	1:02
#Project=	Buranga
#Sample=	BU18FA20_C
#Site=	C_Bertoss1
#Title=	20-C_brt1_FI07
#Remark=
#Date=	30.07.2019 14:30
#Acquired=	30.07.2019 14:30:37
#Data Range:Extract=	16.12.2021 15:36:30
#Base:Fit=	16.12.2021 15:36:40
#Base:Edit=	16.12.2021 15:37:31
#Base:Sub=	16.12.2021 15:37:33
100.38	631.889
106.898	456.448
113.411	343.328
119.918	264.267
126.419	210.899
132.916	156.243
139.407	124.139
145.892	108.484
152.372	81.6961
158.847	54.5339
165.316	43.6022
171.781	43.0526
178.239	24.5093
184.693	15.579
191.139	8.39612
197.582	6.36496
204.02	1.08296
210.452	5.39011
216.877	1.74831
223.299	-0.804642
229.715	15.9613
236.126	46.7462
242.53	145.498
248.931	95.0313
255.326	48.1717
261.714	34.1426
268.099	39.8207
274.477	60.4012
280.851	94.7129
287.218	148.9
293.582	162.179
299.939	97.0627
306.293	42.6347
312.639	21.1664
318.982	27.4093
325.318	70.3796
331.651	182.511
337.977	178.51
344.297	77.4836
350.614	36.819
356.925	30.6096
363.23	56.1425
369.53	72.548
375.827	64.3695
382.116	39.328
388.401	11.6591
394.681	0.051796
400.956	3.53636
407.226	8.52076
413.49	11.2396
419.749	18.2198
426.003	28.9114
432.252	59.0175
438.496	98.9723
444.735	123.747
450.969	118.144
457.197	105.251
463.421	91.1054
469.64	71.686
475.853	46.0251
482.062	28.4685
488.265	22.0008
494.464	18.9391
500.657	18.1372
506.844	20.2672
513.028	25.517
519.206	28.3035
525.38	28.5775
531.548	27.9802
537.71	29.1703
543.869	26.2016
550.022	20.3804
556.169	16.7122
562.313	17.5989
568.452	22.7058
574.584	22.1058
580.713	18.5559
586.837	20.4647
592.954	30.3365
599.068	68.4564
605.176	139.131
611.28	137.995
617.378	97.4652
623.473	89.0101
629.561	100.17
635.644	104.224
641.724	102.153
647.797	88.8077
653.867	84.8177
659.931	95.8416
665.99	113.376
672.044	98.3613
678.095	38.8661
684.139	22.4901
690.179	12.8728
696.213	8.81416
702.245	7.0553
708.27	4.04552
714.29	1.73153
720.306	1.56738
726.316	2.82394
732.322	2.80776
738.323	1.4602
744.32	0.981415
750.311	1.31411
756.298	2.67838
762.28	1.74805
768.258	-0.602692
774.23	-0.34111
780.198	0.43158
786.161	-1.46147
792.119	-1.12115
798.073	0.944489
804.021	1.68115
809.965	1.75005
815.904	0.993782
821.839	0.792351
827.769	2.74978
833.693	5.38308
839.614	7.48347
845.53	8.78636
851.44	9.77721
857.346	9.08401
863.248	7.14864
869.144	6.44261
875.037	8.28371
880.924	11.9851
886.807	13.7083
892.685	12.7957
898.559	11.3762
904.427	10.8878
910.292	12.9927
916.151	18.3719
922.006	22.2065
927.856	21.9607
933.701	22.9404
939.543	28.0417
945.379	44.9609
951.21	65.9587
957.037	82.0886
962.861	98.0223
968.678	113.277
974.491	136.803
980.3	187.253
986.104	271.038
991.904	387.728
997.699	440.382
1003.49	322.204
1009.28	242.407
1015.06	212.559
1020.83	230.167
1026.61	295.703
1032.37	314.982
1038.14	216.775
1043.9	149.62
1049.65	110.416
1055.4	90.041
1061.15	75.7178
1066.88	65.3334
1072.62	59.3235
1078.35	64.6034
1084.08	83.8948
1089.8	107.921
1095.52	118.086
1101.23	124.478
1106.94	132.886
1112.65	95.2215
1118.35	61.5656
1124.05	40.7598
1129.74	34.8533
1135.42	36.881
1141.11	43.6368
1146.78	54.8212
1152.46	64.4101
1158.13	81.105
1163.79	75.5074
1169.45	45.5736
1175.11	26.2736
1180.76	19.2968
1186.41	17.7591
1192.05	16.1408
1197.69	13.9542
1203.32	10.492
1208.95	6.54829
1214.58	3.94463
1220.2	5.20181
1225.82	9.26012
1231.43	10.4747
1237.04	8.83464
1242.64	4.94843
1248.24	4.1423
1253.83	11.174
1259.42	24.1379
1265.01	39.033
1270.59	33.3389
1276.17	32.1745
1281.74	194.268
1287.31	290.525
1292.88	38.0084
1298.44	22.0009
1303.99	16.5309
1309.55	17.4432
1315.09	16.8163
1320.64	14.286
1326.18	12.3527
1331.71	11.031
1337.24	11.2007
1342.77	10.735
1348.29	11.6094
1353.81	14.8973
1359.32	18.3071
1364.83	22.6402
1370.33	29.4669
1375.84	30.0978
1381.33	41.6838
1386.82	558.908
1392.31	191.135
1397.8	17.7444
1403.28	21.0662
1408.75	53.5606
1414.22	31.3283
1419.69	13.0891
1425.15	11.138
1430.61	10.2718
1436.07	7.70771
1441.52	5.39196
1446.96	4.55781
1452.41	6.13626
1457.84	8.45516
1463.28	9.72408
1468.71	8.87666
1474.13	8.78024
1479.55	7.45969
1484.97	2.29993
1490.39	1.5257
1495.79	2.4031
1501.2	4.08676
1506.6	5.59325
1512	5.07731
1517.39	3.45042
1522.78	2.41077
1528.16	3.76234
1533.54	6.03926
1538.92	6.35506
1544.29	2.18919
1549.66	0.413177
1555.02	-3.05676
1560.38	6.38658
1565.74	7.01624
1571.09	5.67262
1576.44	4.20425
1581.78	6.71353
1587.12	3.72623
1592.46	4.11075
1597.79	4.58678
1603.12	3.70016
1608.44	3.90479
1613.76	5.60892
1619.08	7.37124
1624.39	6.38004
1629.7	5.67311
1635	6.97354
1640.3	7.87264
1645.59	6.73771
1650.88	5.07394
1656.17	2.79528
1661.46	2.79361
1666.74	3.74802
1672.01	6.89888
1677.28	8.53107
1682.55	8.12966
1687.82	5.62177
1693.07	3.65353
1698.33	3.45766
1703.58	3.29622
1708.83	4.43118
1714.07	4.2077
1719.31	4.29947
1724.55	6.71918
1729.78	10.2729
1735.01	8.01972
1740.23	7.01684
1745.46	7.82051
1750.67	9.31151
1755.89	9.35598
1761.09	7.31182
1766.3	4.69106
1771.5	5.3149
1776.7	5.75175
1781.89	7.24591
1787.08	8.73168
1792.27	9.31385
1797.45	8.63855
1802.62	6.26867
1807.8	4.58163
1812.97	4.55903
1818.14	6.89346
1823.3	9.57861
1828.46	9.88878
1833.61	6.69582
1838.76	4.12279
1843.91	4.10406
1849.05	4.38847
1854.19	6.79109
1859.33	8.7154
1864.46	2.97902
1869.59	4.66293
1874.71	6.19207
1879.83	6.06257
1884.95	6.95247
1890.06	5.68428
1895.17	4.28347
1900.27	4.67053
1905.38	5.37624
1910.47	4.70222
1915.57	4.03474
1920.66	4.13499
1925.74	4.52961
1930.83	3.55861
1935.91	-0.236271
1940.98	2.20354
1946.05	3.89213
1951.12	5.12303
1956.18	4.62439
1961.25	3.12304
1966.3	2.70905
1971.35	3.35688
1976.4	3.24495
1981.45	3.07993
1986.49	3.36901
1991.53	3.30879
1996.56	2.44431
2001.59	3.15447
2006.62	4.25483
2011.64	4.91826
2016.66	3.31038
2021.68	2.26332
2026.69	1.83138
2031.7	0.939674
2036.7	0.474182
2041.7	3.52747
2046.7	7.98235
2051.7	8.3349
2056.69	5.31261
2061.67	1.25969
2066.65	0.518669
2071.63	2.40418
2076.61	5.69262
2081.58	7.43127
2086.55	6.864
2091.51	7.43451
2096.47	6.29302
2101.43	3.42033
2106.39	2.85143
2111.34	4.08043
2116.28	5.29585
2121.23	5.78006
2126.17	3.87528
2131.1	2.69469
2136.03	2.03129
2140.96	2.7448
2145.89	3.87894
2150.81	5.23108
2155.73	6.30118
2160.64	4.67912
2165.55	1.75544
2170.46	2.1565
2175.36	1.83902
2180.26	1.30703
2185.16	0.168739
2190.05	0.429504
2194.94	1.01448
2199.83	2.01801
2204.71	3.46328
2209.59	4.03087
2214.46	3.01942
2219.33	2.28062
2224.2	2.69035
2229.07	2.8825
2233.93	6.47071
2238.79	7.54864
2243.64	5.46519
2248.49	3.39419
2253.34	2.37103
2258.18	1.80679
2263.02	1.83325
2267.86	1.91449
2272.69	2.65777
2277.52	3.60772
2282.35	5.16278
2287.17	5.55606
2291.99	7.21543
2296.8	7.72079
2301.62	5.26334
2306.43	6.42215
2311.23	5.77781
2316.03	4.51815
2320.83	7.12837
2325.63	11.1962
2330.42	12.891
2335.21	10.0674
2339.99	7.45654
2344.77	5.27028
2349.55	3.95168
2354.32	2.76546
2359.1	1.96235
2363.86	4.47043
2368.63	4.18831
2373.39	2.00633
2378.15	0.686382
2382.9	0.861641
2387.65	2.23668
2392.4	3.96989
2397.14	3.2378
2401.88	2.2456
2406.62	0.406498
2411.35	3.35001
2416.08	0.927582
2420.81	3.2601
2425.53	6.90163
2430.25	8.44536
2434.97	6.38084
2439.69	4.78979
2444.4	4.89316
2449.1	5.66461
2453.81	4.41112
2458.51	0.582695
2463.2	1.80433
2467.9	3.31067
2472.59	3.40086
2477.27	0.972027
2481.96	1.39269
2486.64	3.9121
2491.31	2.41064
2495.99	5.23167
2500.66	3.61808
2505.32	3.26017
2509.99	4.04158
2514.65	4.9917
2519.31	5.9533
2523.96	6.39114
2528.61	4.70478
2533.26	3.93047
2537.9	2.96181
2542.54	2.78042
2547.18	2.54868
2551.81	7.8327
2556.44	7.61186
2561.07	7.42112
2565.69	5.15173
2570.32	5.40231
2574.93	6.46756
2579.55	2.20188
2584.16	-1.0922
2588.77	1.3268
2593.37	4.15089
2597.97	6.7328
2602.57	6.5944
2607.17	3.2776
2611.76	4.30749
2616.35	5.54095
2620.93	6.41129
2625.51	5.98708
2630.09	5.85085
2634.67	5.76838
2639.24	5.21661
2643.81	5.22416
2648.38	4.39436
2652.94	3.53108
2657.5	1.40209
2662.06	4.16613
2666.61	7.11284
2671.16	6.46013
2675.71	5.93992
2680.25	5.85616
2684.79	6.03505
2689.33	7.20358
2693.86	8.2424
2698.39	6.02835
2702.92	3.31382
2707.45	-0.0195961
2711.97	1.86332
2716.49	5.86399
2721	7.36191
2725.51	7.02568
2730.02	6.82269
2734.53	4.73798
2739.03	4.66722
2743.53	7.7013
2748.03	4.8469
2752.52	4.69597
2757.01	4.13927
2761.5	5.13448
2765.98	7.31295
2770.46	7.59343
2774.94	7.11903
2779.42	4.67527
2783.89	3.13625
2788.36	2.50055
2792.82	3.19039
2797.28	4.61518
2801.74	4.92749
2806.2	5.62794
2810.65	4.70768
2815.1	3.82312
2819.55	6.90826
2823.99	7.9074
2828.43	6.31132
2832.87	4.11529
2837.3	3.50943
2841.74	3.06285
2846.17	4.21453
2850.59	4.92515
2855.01	4.17453
2859.43	3.18186
2863.85	3.35143
2868.26	4.38363
2872.67	4.76558
2877.08	5.01719
2881.48	4.99711
2885.89	4.58221
2890.28	4.82824
2894.68	6.02794
2899.07	8.48885
2903.46	8.00677
2907.85	5.8208
2912.23	4.09536
2916.61	1.00906
2920.98	0.408646
2925.36	1.29335
2929.73	2.85362
2934.1	5.09375
2938.46	6.51097
2942.82	4.91485
2947.18	3.70449
2951.54	3.11015
2955.89	3.76534
2960.24	4.5634
2964.59	5.59708
2968.93	4.84588
2973.27	3.12861
2977.61	3.59421
2981.95	2.87376
2986.28	1.76058
2990.61	2.43454
2994.94	3.0235
2999.26	2.8394
3003.58	3.06633
3007.9	2.64986
3012.21	3.20004
3016.52	4.61047
3020.83	6.36988
3025.14	5.43824
3029.44	4.47331
3033.74	4.20625
3038.04	4.01523
3042.33	2.44297
3046.62	5.11713
3050.91	5.69344
3055.2	4.52752
3059.48	4.91927
3063.76	3.88298
3068.03	3.95887
3072.31	3.22635
3076.58	2.87142
3080.85	5.84295
3085.11	7.5188
3089.37	5.90809
3093.63	2.55948
3097.89	3.44953
3102.14	7.45414
3106.39	9.54657
3110.64	8.73841
3114.89	7.96613
3119.13	6.56002
3123.37	7.43537
3127.6	6.94271
3131.84	8.28821
3136.07	9.26154
3140.29	9.34367
3144.52	7.49921
3148.74	7.44357
3152.96	6.21501
3157.18	4.94298
3161.39	7.14277
3165.6	7.58588
3169.81	8.10163
3174.01	9.49212
3178.22	10.958
3182.42	11.1225
3186.61	11.4848
3190.8	10.8011
3195	8.62794
3199.18	7.72839
3203.37	10.4488
3207.55	10.8948
3211.73	11.2534
3215.91	10.0826
3220.08	8.94349
3224.25	9.0163
3228.42	8.65417
3232.59	8.64195
3236.75	10.763
3240.91	9.34086
3245.07	7.44512
3249.22	5.72511
3253.37	3.59854
3257.52	3.66048
3261.67	4.34605
3265.81	4.945
3269.95	4.45044
3274.09	3.3595
3278.22	3.97165
3282.36	4.38892
3286.49	3.04776
3290.61	0.273212
3294.74	-0.374619
3298.86	1.98475
3302.98	3.40872
3307.09	2.61957
3311.21	0.275261
3315.32	1.09474
3319.42	4.29753
3323.53	4.45219
3327.63	3.80658
3331.73	1.94927
3335.83	3.32719
3339.92	3.71701
3344.01	3.44915
3348.1	3.26067
3352.19	5.18945
3356.27	4.51221
3360.35	4.24132
3364.43	4.46568
3368.5	2.44101
3372.58	4.42292
3376.65	6.43646
3380.71	6.22978
3384.78	5.93568
3388.84	8.18486
3392.9	9.97784
3396.95	9.30034
3401.01	7.10847
3405.06	8.9116
3409.1	5.02082
3413.15	3.65578
3417.19	9.09951
3421.23	9.0488
3425.27	10.0535
3429.31	9.95954
3433.34	8.97413
3437.37	7.29765
3441.39	5.77759
3445.42	3.22286
3449.44	1.5326
3453.46	3.40303
3457.47	5.18792
3461.49	3.28741
3465.5	1.19089
3469.51	2.74986
3473.51	5.84185
3477.52	4.15779
3481.52	3.27334
3485.51	1.79867
3489.51	0.0975227
3493.5	1.30492
3497.49	3.30984
3501.48	3.53873
3505.46	3.5125
3509.45	4.62128
3513.43	4.73806
3517.4	4.58019
3521.38	5.17168
3525.35	5.4928
3529.32	5.45265
3533.28	1.79239
3537.25	-0.368065
3541.21	0.0867157
3545.17	1.02213
3549.12	3.11067
3553.08	5.36914
3557.03	7.36648
3560.98	7.4108
3564.92	6.73169
3568.87	7.46766
3572.81	9.58181
3576.74	12.446
3580.68	16.1618
3584.61	17.8392
3588.54	15.5617
3592.47	15.3135
3596.4	15.8734
3600.32	10.7771
3604.24	7.48741
3608.16	6.1251
3612.07	5.02838
3615.98	5.01694
3619.89	5.46307
3623.8	4.797
3627.71	4.05268
3631.61	3.30074
3635.51	3.45994
3639.41	3.89359
3643.3	3.34892
3647.19	4.57319
3651.08	5.12195
3654.97	5.47835
3658.85	5.28427
3662.74	4.39667
3666.62	1.88281
3670.49	0.616123
3674.37	2.37113
3678.24	3.98763
3682.11	4.46399
3685.98	4.75344
3689.84	4.48828
3693.7	5.47569
3697.56	4.95712
3701.42	3.93422
3705.28	3.46545
3709.13	3.55668
3712.98	4.26976
3716.82	4.84703
3720.67	6.16853
3724.51	5.43727
3728.35	4.12125
3732.19	3.15843
3736.02	3.94929
3739.86	3.56483
3743.69	2.54656
3747.51	2.41432
3751.34	4.83948
3755.16	6.74018
3758.98	6.81086
3762.8	5.10389
3766.61	2.99442
3770.43	1.51402
3774.24	1.1645
3778.05	2.2425
3781.85	5.25687
3785.65	5.2766
3789.45	4.31779
3793.25	3.82665
3797.05	1.67692
3800.84	1.22943
3804.63	3.02927
3808.42	2.56849
3812.21	4.5382
3815.99	4.29034
3819.77	3.94853
3823.55	3.73322
3827.33	3.00834
3831.1	3.82578
3834.87	4.87909
3838.64	5.04827
3842.41	4.35426
3846.17	2.65541
3849.93	2.25988
3853.69	3.50086
3857.45	4.90164
3861.21	4.96509
3864.96	1.47533
3868.71	-0.428432
3872.46	1.1674
3876.2	3.34978
3879.94	5.09999
3883.68	2.97712
3887.42	1.76876
3891.16	2.116
3894.89	3.55936
3898.62	3.17112
3902.35	3.61406
3906.08	3.93545
3909.8	3.63054
3913.52	4.23997
3917.24	3.71567
3920.96	2.33237
3924.67	1.00059
3928.38	0.490768
3932.09	2.59452
3935.8	1.59583
3939.51	0.898361
3943.21	1.36332
3946.91	1.31252
3950.61	0.367661
3954.3	2.67035
3958	2.54841
3961.69	3.21704
3965.38	0.911873
3969.06	1.47141
3972.75	1.65387
3976.43	1.58218
3980.11	1.85131
3983.78	0.0153351
3987.46	-0.191048
3991.13	0.374531
3994.8	0.985729
3998.47	2.83946