File: Data/3-Raman/processed/bu20-F-brt1-FI05-1-633-v.txt
#Acq. time (s)=	20
#Accumulations=	3
#Range (cm-¹)=	100...4000
#Windows=	1
#Auto scanning=	Off
#Autofocus=	Off
#Macrospot=	Off
#AutoExposure=	Off
#Spike filter=	Multiple accum.
#Delay time (s)=	0
#Binning=	1
#Readout mode=	Signal
#DeNoise=	Lite
#ICS correction=	Off
#Dark correction=	Off
#Inst. Process=	Off
#Detector temperature (°C)=	-60.09
#Instrument=	LabRAM HR Evol
#Detector=	SIN-EM FIVIS
#Objective=	x100_VIS
#Grating=	150 (500nm)
#ND Filter=	100%
#Laser=	633nm_Edge
#Hole=	30.0125
#Temperature=	0
#Range=	Visible
#StageXY=	75x50mm Scan+
#StageZ=	Z motor
#X (µm)=	6849.3
#Y (µm)=	-44.4
#Z (µm)=	1885.1
#Full time(mm:ss)=	1:03
#Project=	Buranga
#Sample=	BU18FA20_F
#Site=	F_Bertoss1
#Title=	20-F_brt1_FI05_1
#Remark=
#Date=	30.07.2019 16:20
#Acquired=	30.07.2019 16:20:21
#Data Range:Extract=	16.12.2021 15:36:30
#Base:Fit=	16.12.2021 15:36:40
#Base:Edit=	16.12.2021 15:40:54
#Base:Edit=	16.12.2021 15:40:55
#Base:Edit=	16.12.2021 15:40:56
#Base:Sub=	16.12.2021 15:40:59
100.38	290.946
106.898	232.842
113.411	185.343
119.918	151.446
126.419	128.671
132.916	114.677
139.407	102.667
145.892	93.648
152.372	71.9778
158.847	66.6459
165.316	73.6758
171.781	65.8083
178.239	33.7792
184.693	24.9213
191.139	17.7179
197.582	11.3884
204.02	9.00423
210.452	6.20639
216.877	0.0641632
223.299	12.5575
229.715	43.1813
236.126	155.418
242.53	193.783
248.931	97.9203
255.326	73.8369
261.714	90.1556
268.099	94.9292
274.477	103.74
280.851	170.973
287.218	275.062
293.582	181.025
299.939	90.5343
306.293	47.5524
312.639	57.8768
318.982	110.86
325.318	248.597
331.651	374.615
337.977	215.873
344.297	95.0299
350.614	59.1201
356.925	71.0717
363.23	85.1809
369.53	96.5311
375.827	70.7001
382.116	34.5925
388.401	1.75049
394.681	11.4292
400.956	19.4138
407.226	32.2755
413.49	47.0934
419.749	67.9163
426.003	112.231
432.252	169.922
438.496	226.55
444.735	221.781
450.969	181.837
457.197	148.313
463.421	141.935
469.64	93.1111
475.853	55.141
482.062	39.1883
488.265	36.7952
494.464	35.1346
500.657	40.4879
506.844	52.6594
513.028	63.8148
519.206	70.9722
525.38	68.6725
531.548	65.6495
537.71	63.1068
543.869	50.0816
550.022	41.315
556.169	43.1296
562.313	39.5936
568.452	31.7476
574.584	28.6285
580.713	30.8443
586.837	47.5252
592.954	85.4799
599.068	168.719
605.176	227.481
611.28	164.266
617.378	142.961
623.473	132.045
629.561	140.65
635.644	155.116
641.724	133.934
647.797	133.553
653.867	154.272
659.931	165.95
665.99	142.155
672.044	97.3762
678.095	58.3104
684.139	31.0217
690.179	17.4177
696.213	1.67735
702.245	3.212
708.27	5.11417
714.29	6.04165
720.306	4.99862
726.316	4.19696
732.322	3.68293
738.323	3.22937
744.32	0.8377
750.311	1.44821
756.298	2.44238
762.28	2.38146
768.258	1.58066
774.23	0.627769
780.198	-0.677116
786.161	-1.84246
792.119	-0.306015
798.073	2.01214
804.021	4.26713
809.965	5.63581
815.904	7.06716
821.839	10.2685
827.769	12.2429
833.693	11.3967
839.614	13.4455
845.53	15.1605
851.44	12.8639
857.346	11.7821
863.248	13.3499
869.144	18.8908
875.037	22.9492
880.924	26.8419
886.807	30.4436
892.685	31.7801
898.559	31.031
904.427	27.0461
910.292	25.2307
916.151	27.5021
922.006	30.6133
927.856	41.949
933.701	47.2307
939.543	64.6502
945.379	95.2777
951.21	132.842
957.037	167.465
962.861	184.858
968.678	207.731
974.491	266.133
980.3	363.584
986.104	549.538
991.904	682.409
997.699	593.521
1003.49	457.981
1009.28	383.061
1015.06	373.411
1020.83	426.43
1026.61	535.918
1032.37	430.763
1038.14	282.705
1043.9	202.387
1049.65	145.963
1055.4	112.727
1061.15	104.251
1066.88	96.2079
1072.62	96.2002
1078.35	115.228
1084.08	139.306
1089.8	163.21
1095.52	188.79
1101.23	208.858
1106.94	187.077
1112.65	122.149
1118.35	79.8124
1124.05	59.1493
1129.74	58.5703
1135.42	68.157
1141.11	83.6817
1146.78	101.457
1152.46	122.685
1158.13	150.082
1163.79	86.7917
1169.45	48.9885
1175.11	37.5583
1180.76	35.9724
1186.41	32.3126
1192.05	22.4297
1197.69	17.1207
1203.32	13.3391
1208.95	10.9966
1214.58	8.57524
1220.2	5.61146
1225.82	2.10117
1231.43	2.13319
1237.04	3.45824
1242.64	5.74632
1248.24	8.59411
1253.83	11.6956
1259.42	15.2165
1265.01	16.7554
1270.59	13.849
1276.17	30.1975
1281.74	113.006
1287.31	44.8446
1292.88	21.6122
1298.44	8.05742
1303.99	6.61203
1309.55	8.7612
1315.09	10.2327
1320.64	7.34578
1326.18	7.12
1331.71	4.80646
1337.24	3.81809
1342.77	1.06017
1348.29	-0.916122
1353.81	0.0948181
1359.32	2.61632
1364.83	6.44482
1370.33	8.49676
1375.84	11.0736
1381.33	51.8298
1386.82	200.377
1392.31	35.0261
1397.8	10.1986
1403.28	10.0929
1408.75	10.1907
1414.22	7.54343
1419.69	3.82355
1425.15	2.07128
1430.61	2.85219
1436.07	2.93554
1441.52	0.263702
1446.96	-0.212715
1452.41	1.86944
1457.84	1.80107
1463.28	0.344315
1468.71	-1.6644
1474.13	2.29536
1479.55	2.35871
1484.97	4.41803
1490.39	2.90776
1495.79	0.476089
1501.2	-3.15626
1506.6	0.696495
1512	4.45655
1517.39	4.68422
1522.78	1.93639
1528.16	3.00876
1533.54	2.04197
1538.92	1.85265
1544.29	3.12026
1549.66	3.51123
1555.02	5.0675
1560.38	4.48886
1565.74	0.793472
1571.09	1.50876
1576.44	1.25755
1581.78	2.62952
1587.12	6.18362
1592.46	4.58956
1597.79	2.8605
1603.12	1.08788
1608.44	1.56268
1613.76	6.46825
1619.08	4.29822
1624.39	1.90151
1629.7	2.35132
1635	5.78378
1640.3	4.95126
1645.59	5.81488
1650.88	7.25098
1656.17	6.8599
1661.46	5.86712
1666.74	5.88211
1672.01	6.50084
1677.28	9.10258
1682.55	8.32549
1687.82	5.26056
1693.07	3.68401
1698.33	6.5424
1703.58	8.90666
1708.83	9.3815
1714.07	8.55589
1719.31	5.52785
1724.55	4.76958
1729.78	6.15606
1735.01	6.80619
1740.23	9.70128
1745.46	7.24151
1750.67	4.95074
1755.89	4.8158
1761.09	6.10049
1766.3	2.87376
1771.5	1.32408
1776.7	2.47224
1781.89	4.93
1787.08	6.38805
1792.27	5.5269
1797.45	2.74481
1802.62	2.78539
1807.8	4.0932
1812.97	6.32216
1818.14	5.98811
1823.3	6.50127
1828.46	7.35255
1833.61	6.38145
1838.76	5.40193
1843.91	4.75843
1849.05	4.48685
1854.19	4.5361
1859.33	4.57298
1864.46	5.26258
1869.59	2.97733
1874.71	1.92877
1879.83	3.22434
1884.95	6.33647
1890.06	7.54162
1895.17	6.01199
1900.27	6.11853
1905.38	4.91777
1910.47	4.3664
1915.57	3.60931
1920.66	4.71321
1925.74	5.953
1930.83	5.56328
1935.91	6.17905
1940.98	3.93604
1946.05	2.84588
1951.12	2.86291
1956.18	1.65997
1961.25	4.508
1966.3	7.93306
1971.35	6.48408
1976.4	5.27827
1981.45	5.6564
1986.49	5.08081
1991.53	4.50404
1996.56	6.01247
2001.59	6.97263
2006.62	6.88932
2011.64	1.39489
2016.66	-1.62286
2021.68	1.03979
2026.69	3.74778
2031.7	6.05421
2036.7	8.28274
2041.7	5.56927
2046.7	4.2826
2051.7	3.80212
2056.69	4.50173
2061.67	5.65166
2066.65	6.51308
2071.63	6.87997
2076.61	6.76876
2081.58	5.45359
2086.55	6.35307
2091.51	6.99859
2096.47	6.62276
2101.43	1.39265
2106.39	4.05982
2111.34	6.00702
2116.28	5.52799
2121.23	5.94616
2126.17	6.90469
2131.1	6.48181
2136.03	4.65737
2140.96	3.51763
2145.89	3.62189
2150.81	4.93714
2155.73	6.09064
2160.64	6.16113
2165.55	3.31418
2170.46	4.00182
2175.36	5.16098
2180.26	5.96704
2185.16	5.8758
2190.05	4.58981
2194.94	4.26853
2199.83	1.2778
2204.71	0.712841
2209.59	3.14349
2214.46	2.99323
2219.33	0.33791
2224.2	2.49351
2229.07	4.95442
2233.93	4.05705
2238.79	4.7817
2243.64	4.23088
2248.49	0.60965
2253.34	-0.490616
2258.18	2.84011
2263.02	4.93333
2267.86	4.86079
2272.69	4.59925
2277.52	6.01441
2282.35	6.13351
2287.17	6.04517
2291.99	5.84761
2296.8	4.99681
2301.62	3.67252
2306.43	2.29617
2311.23	1.19809
2316.03	1.71323
2320.83	4.43062
2325.63	8.8211
2330.42	7.96025
2335.21	5.93932
2339.99	5.5655
2344.77	3.02396
2349.55	2.65925
2354.32	4.23775
2359.1	4.93754
2363.86	4.44774
2368.63	1.79479
2373.39	0.679569
2378.15	3.75373
2382.9	0.296455
2387.65	-1.57091
2392.4	0.379841
2397.14	3.28828
2401.88	5.67373
2406.62	4.891
2411.35	2.8131
2416.08	1.80522
2420.81	2.39082
2425.53	4.31113
2430.25	4.78139
2434.97	4.30438
2439.69	3.51525
2444.4	2.20205
2449.1	2.02797
2453.81	3.87745
2458.51	4.02036
2463.2	3.77175
2467.9	4.01368
2472.59	3.19256
2477.27	3.02925
2481.96	3.77594
2486.64	4.75753
2491.31	5.38863
2495.99	5.69238
2500.66	3.95087
2505.32	3.30436
2509.99	1.84674
2514.65	3.17813
2519.31	4.05107
2523.96	3.46893
2528.61	2.40281
2533.26	3.44702
2537.9	5.01059
2542.54	4.77873
2547.18	3.91883
2551.81	3.38196
2556.44	3.51925
2561.07	4.32838
2565.69	3.80811
2570.32	5.23304
2574.93	6.34791
2579.55	4.72228
2584.16	2.35392
2588.77	3.42982
2593.37	4.02689
2597.97	4.27288
2602.57	4.83411
2607.17	4.48474
2611.76	3.94617
2616.35	3.93879
2620.93	3.21175
2625.51	3.54644
2630.09	3.22856
2634.67	2.86602
2639.24	3.95613
2643.81	3.92617
2648.38	3.84272
2652.94	4.27391
2657.5	5.50226
2662.06	6.22968
2666.61	4.54167
2671.16	3.21003
2675.71	2.89657
2680.25	3.09799
2684.79	3.36795
2689.33	3.58435
2693.86	3.56458
2698.39	3.43911
2702.92	3.5257
2707.45	3.89585
2711.97	2.5629
2716.49	2.455
2721	2.89481
2725.51	3.2765
2730.02	3.54506
2734.53	1.01078
2739.03	4.94233
2743.53	3.7006
2748.03	2.76841
2752.52	2.49142
2757.01	3.41911
2761.5	4.40608
2765.98	3.28926
2770.46	2.03734
2774.94	1.35332
2779.42	2.04651
2783.89	2.61365
2788.36	2.15519
2792.82	0.964931
2797.28	-0.466183
2801.74	1.96114
2806.2	4.53701
2810.65	3.423
2815.1	2.1373
2819.55	3.20569
2823.99	4.65654
2828.43	3.61538
2832.87	3.5061
2837.3	2.73571
2841.74	1.17666
2846.17	2.45224
2850.59	2.40408
2855.01	2.73903
2859.43	3.16611
2863.85	4.04754
2868.26	2.45673
2872.67	0.542816
2877.08	0.555382
2881.48	2.59847
2885.89	2.41983
2890.28	1.93102
2894.68	2.22229
2899.07	2.24953
2903.46	2.77897
2907.85	3.59259
2912.23	2.63883
2916.61	2.02132
2920.98	1.66026
2925.36	1.59169
2929.73	1.69956
2934.1	1.90364
2938.46	0.980385
2942.82	0.869129
2947.18	2.34784
2951.54	3.0667
2955.89	1.998
2960.24	2.52756
2964.59	1.74101
2968.93	0.42775
2973.27	1.56638
2977.61	4.37333
2981.95	4.88701
2986.28	3.68658
2990.61	-1.75933
2994.94	3.38346
2999.26	3.51579
3003.58	4.78708
3007.9	5.64444
3012.21	6.05003
3016.52	3.20477
3020.83	1.62782
3025.14	2.84272
3029.44	4.79511
3033.74	5.16486
3038.04	2.52895
3042.33	2.45846
3046.62	5.24444
3050.91	8.50106
3055.2	6.01686
3059.48	4.98409
3063.76	5.55445
3068.03	7.16404
3072.31	7.63137
3076.58	6.36964
3080.85	6.39372
3085.11	8.82273
3089.37	8.78138
3093.63	8.73299
3097.89	10.1708
3102.14	10.8493
3106.39	10.1882
3110.64	10.5708
3114.89	11.5892
3119.13	12.6541
3123.37	12.1285
3127.6	11.5697
3131.84	10.9618
3136.07	13.6147
3140.29	15.0811
3144.52	13.3212
3148.74	12.3745
3152.96	13.9831
3157.18	15.3764
3161.39	16.4616
3165.6	19.417
3169.81	21.6533
3174.01	22.4688
3178.22	22.212
3182.42	22.5086
3186.61	23.4648
3190.8	24.9481
3195	24.9415
3199.18	24.1927
3203.37	23.3209
3207.55	18.1011
3211.73	20.6435
3215.91	22.3128
3220.08	21.9818
3224.25	21.2079
3228.42	20.2757
3232.59	21.2526
3236.75	22.0001
3240.91	20.4395
3245.07	19.2167
3249.22	17.4709
3253.37	18.3037
3257.52	17.598
3261.67	14.7275
3265.81	13.8511
3269.95	14.3554
3274.09	15.8574
3278.22	15.7664
3282.36	12.6913
3286.49	9.23765
3290.61	10.6285
3294.74	13.0283
3298.86	12.7934
3302.98	14.9626
3307.09	13.1873
3311.21	11.7806
3315.32	15.6742
3319.42	15.0063
3323.53	14.3823
3327.63	13.2345
3331.73	13.306
3335.83	15.4914
3339.92	13.7635
3344.01	14.4445
3348.1	14.739
3352.19	15.6579
3356.27	16.9742
3360.35	15.8862
3364.43	14.2556
3368.5	13.7098
3372.58	16.2547
3376.65	17.1496
3380.71	17.0706
3384.78	15.9605
3388.84	16.998
3392.9	18.2509
3396.95	19.8829
3401.01	20.8724
3405.06	19.9527
3409.1	19.1707
3413.15	18.4921
3417.19	17.2263
3421.23	14.5098
3425.27	17.1157
3429.31	17.7645
3433.34	16.0968
3437.37	15.3585
3441.39	15.2347
3445.42	15.2922
3449.44	15.4508
3453.46	13.917
3457.47	11.844
3461.49	10.7114
3465.5	13.6994
3469.51	8.26765
3473.51	8.36185
3477.52	8.9613
3481.52	9.34476
3485.51	10.1644
3489.51	10.0845
3493.5	8.3179
3497.49	9.53295
3501.48	11.5542
3505.46	12.0381
3509.45	10.02
3513.43	11.2719
3517.4	9.70237
3521.38	11.3804
3525.35	11.1633
3529.32	10.0744
3533.28	9.37962
3537.25	9.18939
3541.21	9.57172
3545.17	10.2167
3549.12	10.6212
3553.08	10.2462
3557.03	9.46674
3560.98	8.63497
3564.92	11.6621
3568.87	14.8584
3572.81	17.5735
3576.74	20.387
3580.68	23.7819
3584.61	25.3193
3588.54	25.289
3592.47	24.4881
3596.4	22.1299
3600.32	15.502
3604.24	9.81823
3608.16	7.01911
3612.07	6.66861
3615.98	5.15924
3619.89	2.95672
3623.8	3.45597
3627.71	5.13133
3631.61	6.42416
3635.51	5.57934
3639.41	5.18814
3643.3	4.86393
3647.19	3.17438
3651.08	1.75436
3654.97	0.33918
3658.85	2.66461
3662.74	4.9511
3666.62	4.34691
3670.49	2.83879
3674.37	1.67014
3678.24	3.11854
3682.11	2.15421
3685.98	1.96714
3689.84	3.03743
3693.7	4.18402
3697.56	0.873932
3701.42	-0.488422
3705.28	2.32687
3709.13	3.46123
3712.98	3.05957
3716.82	2.14364
3720.67	1.2981
3724.51	3.08287
3728.35	4.61381
3732.19	3.61183
3736.02	2.92529
3739.86	4.42925
3743.69	3.50906
3747.51	1.02076
3751.34	-0.0451622
3755.16	1.61409
3758.98	2.91761
3762.8	2.21954
3766.61	0.941639
3770.43	2.66943
3774.24	3.14551
3778.05	2.05154
3781.85	0.677753
3785.65	0.47057
3789.45	0.974529
3793.25	3.35211
3797.05	4.34539
3800.84	3.27938
3804.63	1.2094
3808.42	1.65352
3812.21	2.37162
3815.99	4.09211
3819.77	2.31594
3823.55	1.5405
3827.33	2.10651
3831.1	1.70803
3834.87	2.01709
3838.64	2.33918
3842.41	2.15375
3846.17	1.87637
3849.93	1.1778
3853.69	1.93239
3857.45	1.38065
3861.21	2.33866
3864.96	1.84769
3868.71	0.107697
3872.46	0.916832
3876.2	3.30991
3879.94	3.9804
3883.68	4.4
3887.42	4.72663
3891.16	4.57888
3894.89	4.51722
3898.62	4.77287
3902.35	3.61838
3906.08	1.12687
3909.8	-0.897387
3913.52	0.927387
3917.24	4.6835
3920.96	5.82621
3924.67	5.1339
3928.38	4.29654
3932.09	3.41327
3935.8	2.48319
3939.51	1.52326
3943.21	0.590488
3946.91	0.0813255
3950.61	1.87263
3954.3	2.99521
3958	2.38472
3961.69	1.16349
3965.38	0.340235
3969.06	-0.232887
3972.75	0.590782
3976.43	3.28285
3980.11	4.81866
3983.78	4.73071
3987.46	3.60144
3991.13	1.52514
3994.8	1.54697
3998.47	0.357857