File: Data/3-Raman/processed/bu20-C-brt1-FI04-633-v.txt
#Acq. time (s)=	20
#Accumulations=	3
#Range (cm-¹)=	100...4000
#Windows=	1
#Auto scanning=	Off
#Autofocus=	Off
#Macrospot=	Off
#AutoExposure=	Off
#Spike filter=	Multiple accum.
#Delay time (s)=	0
#Binning=	1
#Readout mode=	Signal
#DeNoise=	Lite
#ICS correction=	Off
#Dark correction=	Off
#Inst. Process=	Off
#Detector temperature (°C)=	-60.09
#Instrument=	LabRAM HR Evol
#Detector=	SIN-EM FIVIS
#Objective=	x50_VIS_LWD
#Grating=	150 (500nm)
#ND Filter=	100%
#Laser=	633nm_Edge
#Hole=	30.0125
#Temperature=	0
#Range=	Visible
#StageXY=	75x50mm Scan+
#StageZ=	Z motor
#X (µm)=	7297.3
#Y (µm)=	4547.7
#Z (µm)=	-30.3
#Full time(mm:ss)=	1:02
#Project=	Buranga
#Sample=	BU18FA20_C
#Site=	C_Bertoss1
#Title=	20-C_brt1_FI04
#Remark=
#Date=	30.07.2019 14:41
#Acquired=	30.07.2019 14:41:13
#Data Range:Extract=	16.12.2021 15:36:30
#Base:Fit=	16.12.2021 15:36:40
#Base:Edit=	16.12.2021 15:38:38
#Base:Edit=	16.12.2021 15:38:39
#Base:Sub=	16.12.2021 15:38:41
100.38	605.188
106.898	445.453
113.411	332.719
119.918	251.673
126.419	189.491
132.916	141.745
139.407	108.474
145.892	88.5123
152.372	71.6087
158.847	54.0574
165.316	41.1363
171.781	38.6006
178.239	32.1344
184.693	16.2684
191.139	16.3789
197.582	13.3613
204.02	9.24701
210.452	3.73907
216.877	-0.982208
223.299	4.33751
229.715	20.8038
236.126	65.2826
242.53	146.478
248.931	111.655
255.326	70.3044
261.714	53.1463
268.099	55.379
274.477	75.1409
280.851	107.668
287.218	166.937
293.582	177.08
299.939	107.354
306.293	58.9949
312.639	40.4974
318.982	50.6297
325.318	94.6282
331.651	197.623
337.977	179.518
344.297	97.1494
350.614	61.9664
356.925	55.4104
363.23	68.1632
369.53	82.9241
375.827	78.6634
382.116	58.4442
388.401	35.6601
394.681	24.1252
400.956	20.9089
407.226	22.9067
413.49	28.2411
419.749	33.3691
426.003	43.8905
432.252	75.1267
438.496	112.237
444.735	137.933
450.969	136.124
457.197	121.691
463.421	115.228
469.64	92.034
475.853	65.6458
482.062	48.5071
488.265	41.0903
494.464	38.738
500.657	34.2674
506.844	34.4079
513.028	37.3702
519.206	42.2443
525.38	35.9731
531.548	30.7564
537.71	31.0337
543.869	32.0633
550.022	32.5507
556.169	31.8037
562.313	27.6511
568.452	23.3344
574.584	20.0429
580.713	18.5649
586.837	25.9419
592.954	46.1646
599.068	79.0222
605.176	131.561
611.28	121.229
617.378	102.145
623.473	95.7275
629.561	97.8301
635.644	104.746
641.724	102.437
647.797	80.1574
653.867	85.8971
659.931	105.042
665.99	104.505
672.044	86.1236
678.095	56.2174
684.139	33.4458
690.179	21.3124
696.213	16.1991
702.245	10.3327
708.27	4.6368
714.29	2.42394
720.306	0.862442
726.316	0.998543
732.322	0.94059
738.323	0.143509
744.32	1.78436
750.311	4.13542
756.298	4.91779
762.28	3.40978
768.258	3.07893
774.23	0.650146
780.198	-1.13417
786.161	-1.16004
792.119	0.536041
798.073	1.38671
804.021	0.726204
809.965	0.395912
815.904	0.806984
821.839	1.09132
827.769	4.05389
833.693	7.53049
839.614	8.68787
845.53	5.20644
851.44	2.60041
857.346	1.53704
863.248	1.40594
869.144	1.95337
875.037	5.47286
880.924	8.22353
886.807	10.6333
892.685	12.195
898.559	10.8814
904.427	10.041
910.292	9.88844
916.151	10.0747
922.006	11.4892
927.856	16.3406
933.701	23.7
939.543	32.482
945.379	44.064
951.21	61.4108
957.037	83.0573
962.861	98.6346
968.678	107.939
974.491	122.209
980.3	165.109
986.104	244.853
991.904	369.376
997.699	408.34
1003.49	305.856
1009.28	241.975
1015.06	217.061
1020.83	229.175
1026.61	276.835
1032.37	317.745
1038.14	222.191
1043.9	143.377
1049.65	102.19
1055.4	84.0415
1061.15	71.1643
1066.88	50.9468
1072.62	45.428
1078.35	48.2025
1084.08	73.6492
1089.8	92.3996
1095.52	100.948
1101.23	112.232
1106.94	113.991
1112.65	85.5602
1118.35	53.8244
1124.05	34.3504
1129.74	29.1732
1135.42	33.5619
1141.11	41.2357
1146.78	52.173
1152.46	67.1529
1158.13	81.0923
1163.79	69.0919
1169.45	37.5832
1175.11	23.6903
1180.76	18.1813
1186.41	14.501
1192.05	10.7289
1197.69	8.24586
1203.32	6.70815
1208.95	4.7155
1214.58	3.29174
1220.2	3.60782
1225.82	7.46672
1231.43	8.80668
1237.04	6.63387
1242.64	4.57331
1248.24	6.87502
1253.83	14.9744
1259.42	25.5627
1265.01	36.0653
1270.59	26.9055
1276.17	27.1138
1281.74	230.567
1287.31	233.877
1292.88	35.06
1298.44	25.7369
1303.99	18.2986
1309.55	13.1164
1315.09	10.2773
1320.64	9.74524
1326.18	14.3229
1331.71	14.4077
1337.24	9.41815
1342.77	4.25307
1348.29	7.14877
1353.81	9.00921
1359.32	10.6174
1364.83	14.1043
1370.33	21.0665
1375.84	31.7968
1381.33	43.344
1386.82	643.22
1392.31	180.497
1397.8	25.7726
1403.28	30.445
1408.75	50.6293
1414.22	30.7377
1419.69	14.2329
1425.15	8.31339
1430.61	5.94294
1436.07	2.94016
1441.52	3.19888
1446.96	2.66678
1452.41	-0.0796661
1457.84	-3.27219
1463.28	2.1704
1468.71	3.24715
1474.13	3.20669
1479.55	2.47703
1484.97	1.31219
1490.39	0.354996
1495.79	0.956902
1501.2	3.51429
1506.6	0.831619
1512	-1.16762
1517.39	-1.21626
1522.78	-1.06787
1528.16	-0.444565
1533.54	0.573456
1538.92	2.42056
1544.29	4.50426
1549.66	5.08263
1555.02	4.28281
1560.38	2.14422
1565.74	2.76778
1571.09	6.0577
1576.44	5.83325
1581.78	4.60309
1587.12	3.68526
1592.46	5.07021
1597.79	6.23377
1603.12	4.11153
1608.44	1.69186
1613.76	1.61681
1619.08	4.45697
1624.39	4.38142
1629.7	1.46091
1635	0.823914
1640.3	3.6191
1645.59	3.76535
1650.88	3.08479
1656.17	2.41656
1661.46	4.90927
1666.74	7.28602
1672.01	6.75763
1677.28	4.42334
1682.55	2.97535
1687.82	6.1395
1693.07	9.77911
1698.33	3.35381
1703.58	3.50124
1708.83	4.05269
1714.07	4.29626
1719.31	4.88401
1724.55	4.02297
1729.78	3.22952
1735.01	2.86794
1740.23	3.78306
1745.46	5.38493
1750.67	5.31078
1755.89	4.37347
1761.09	4.11817
1766.3	4.80234
1771.5	4.64052
1776.7	4.11277
1781.89	3.94839
1787.08	4.21076
1792.27	5.21088
1797.45	7.5248
1802.62	8.97459
1807.8	9.17778
1812.97	7.51263
1818.14	4.23287
1823.3	2.61241
1828.46	4.39034
1833.61	7.37024
1838.76	3.79858
1843.91	2.30758
1849.05	1.48237
1854.19	0.926086
1859.33	2.09041
1864.46	5.52105
1869.59	7.5123
1874.71	6.34215
1879.83	3.32388
1884.95	4.23679
1890.06	6.38242
1895.17	4.60987
1900.27	1.8069
1905.38	4.03618
1910.47	5.26848
1915.57	3.26191
1920.66	1.80939
1925.74	1.44062
1930.83	6.1909
1935.91	4.71621
1940.98	5.59407
1946.05	5.17963
1951.12	3.31208
1956.18	1.63808
1961.25	2.21968
1966.3	3.35258
1971.35	4.04269
1976.4	6.19644
1981.45	7.04268
1986.49	5.43689
1991.53	3.98987
1996.56	-1.54791
2001.59	0.414612
2006.62	2.67188
2011.64	3.09546
2016.66	2.55104
2021.68	2.15858
2026.69	1.82325
2031.7	2.12115
2036.7	4.63624
2041.7	5.63017
2046.7	4.93663
2051.7	3.57138
2056.69	2.66471
2061.67	2.44179
2066.65	-1.12991
2071.63	1.05938
2076.61	2.97754
2081.58	3.28607
2086.55	5.05991
2091.51	4.65736
2096.47	3.37938
2101.43	1.84737
2106.39	2.35525
2111.34	6.11392
2116.28	0.339767
2121.23	2.48089
2126.17	1.74033
2131.1	1.67099
2136.03	1.56289
2140.96	0.785446
2145.89	1.65175
2150.81	2.75915
2155.73	3.35113
2160.64	3.04228
2165.55	2.34782
2170.46	3.31342
2175.36	-2.75458
2180.26	-6.41079
2185.16	1.64209
2190.05	4.8024
2194.94	6.05826
2199.83	5.63069
2204.71	3.67742
2209.59	3.50919
2214.46	5.91714
2219.33	6.52156
2224.2	3.77328
2229.07	3.55826
2233.93	5.38287
2238.79	7.06436
2243.64	6.27072
2248.49	1.8656
2253.34	0.523911
2258.18	3.15555
2263.02	3.54321
2267.86	1.33315
2272.69	1.32584
2277.52	1.00866
2282.35	2.20341
2287.17	5.03534
2291.99	6.86025
2296.8	5.12215
2301.62	3.56137
2306.43	4.0076
2311.23	2.91087
2316.03	1.86049
2320.83	0.542175
2325.63	9.43736
2330.42	14.6806
2335.21	8.06938
2339.99	3.62762
2344.77	4.46506
2349.55	3.91747
2354.32	4.64896
2359.1	4.7788
2363.86	4.31
2368.63	4.9493
2373.39	1.42281
2378.15	-1.452
2382.9	-0.823799
2387.65	3.89605
2392.4	5.98028
2397.14	6.46387
2401.88	2.80713
2406.62	1.38587
2411.35	1.43796
2416.08	5.37566
2420.81	4.79059
2425.53	4.95623
2430.25	3.71551
2434.97	3.80648
2439.69	4.62951
2444.4	1.61106
2449.1	-1.04607
2453.81	0.525581
2458.51	1.80355
2463.2	5.11017
2467.9	8.13841
2472.59	8.27141
2477.27	5.47131
2481.96	3.20597
2486.64	2.0314
2491.31	2.18477
2495.99	3.17157
2500.66	0.621407
2505.32	0.155205
2509.99	1.00365
2514.65	2.38781
2519.31	4.08209
2523.96	5.51167
2528.61	4.77242
2533.26	5.5275
2537.9	7.42963
2542.54	4.31441
2547.18	-1.13934
2551.81	2.37375
2556.44	-1.49866
2561.07	-0.0590134
2565.69	3.5802
2570.32	1.17776
2574.93	1.93054
2579.55	3.05928
2584.16	4.08968
2588.77	3.85442
2593.37	2.4836
2597.97	1.35713
2602.57	4.46672
2607.17	3.47517
2611.76	2.14424
2616.35	1.12271
2620.93	1.60436
2625.51	4.84631
2630.09	5.88682
2634.67	5.76119
2639.24	3.20956
2643.81	-0.773491
2648.38	-0.643089
2652.94	0.754654
2657.5	1.5173
2662.06	4.92996
2666.61	5.43726
2671.16	3.19329
2675.71	4.86366
2680.25	5.22272
2684.79	3.04293
2689.33	4.04062
2693.86	5.77036
2698.39	6.7321
2702.92	3.27917
2707.45	1.31349
2711.97	1.93069
2716.49	3.56921
2721	2.41338
2725.51	1.62003
2730.02	0.134689
2734.53	-0.903763
2739.03	0.677658
2743.53	3.0124
2748.03	3.6318
2752.52	2.20156
2757.01	1.4689
2761.5	3.77718
2765.98	5.06367
2770.46	5.66969
2774.94	3.01596
2779.42	1.12753
2783.89	0.495445
2788.36	1.0911
2792.82	3.04451
2797.28	5.06777
2801.74	4.67231
2806.2	2.97003
2810.65	3.73406
2815.1	3.13889
2819.55	3.96643
2823.99	4.67302
2828.43	4.47146
2832.87	3.1851
2837.3	3.31149
2841.74	5.23165
2846.17	6.13874
2850.59	5.08102
2855.01	4.04143
2859.43	4.48272
2863.85	6.66321
2868.26	5.82031
2872.67	3.38206
2877.08	2.14239
2881.48	1.63989
2885.89	2.51295
2890.28	2.24787
2894.68	1.84963
2899.07	1.82554
2903.46	2.55457
2907.85	3.13625
2912.23	2.71705
2916.61	2.1289
2920.98	1.01927
2925.36	-0.272041
2929.73	0.282433
2934.1	2.57097
2938.46	5.05254
2942.82	6.53341
2947.18	5.91151
2951.54	4.02151
2955.89	1.25309
2960.24	1.47293
2964.59	3.0794
2968.93	3.62752
2973.27	2.96251
2977.61	2.91958
2981.95	2.99953
2986.28	3.6142
2990.61	5.9338
2994.94	7.22581
2999.26	5.15053
3003.58	4.75015
3007.9	4.75175
3012.21	3.422
3016.52	2.80423
3020.83	2.3793
3025.14	2.58659
3029.44	2.42924
3033.74	1.11221
3038.04	1.50214
3042.33	3.02345
3046.62	4.69972
3050.91	4.88119
3055.2	2.89899
3059.48	2.98402
3063.76	4.35576
3068.03	2.47683
3072.31	6.07996
3076.58	4.36914
3080.85	2.25332
3085.11	2.14478
3089.37	3.23886
3093.63	3.79916
3097.89	4.84198
3102.14	5.84987
3106.39	6.41618
3110.64	6.30339
3114.89	5.2159
3119.13	7.25132
3123.37	6.39806
3127.6	3.5549
3131.84	1.92406
3136.07	3.8158
3140.29	4.37272
3144.52	4.57262
3148.74	4.01337
3152.96	3.59723
3157.18	4.08625
3161.39	5.42666
3165.6	8.02766
3169.81	7.36256
3174.01	8.69232
3178.22	9.72575
3182.42	6.01665
3186.61	6.2645
3190.8	7.23142
3195	9.21891
3199.18	11.3337
3203.37	11.1981
3207.55	10.5727
3211.73	7.13141
3215.91	8.12331
3220.08	8.90693
3224.25	8.1074
3228.42	7.70544
3232.59	7.79035
3236.75	9.21326
3240.91	11.6
3245.07	8.59658
3249.22	4.79085
3253.37	2.27371
3257.52	2.74109
3261.67	4.29927
3265.81	5.35005
3269.95	6.8995
3274.09	4.49457
3278.22	2.30099
3282.36	1.16724
3286.49	0.941086
3290.61	2.28941
3294.74	2.88539
3298.86	0.0751724
3302.98	-0.524101
3307.09	2.71535
3311.21	2.85727
3315.32	3.35189
3319.42	3.12799
3323.53	2.98705
3327.63	2.17699
3331.73	2.68011
3335.83	4.56525
3339.92	2.88712
3344.01	1.16538
3348.1	2.4117
3352.19	0.813667
3356.27	2.88343
3360.35	4.08184
3364.43	2.93136
3368.5	1.37887
3372.58	3.15858
3376.65	4.14027
3380.71	6.54984
3384.78	8.33841
3388.84	7.78242
3392.9	7.79794
3396.95	6.6027
3401.01	7.85402
3405.06	8.75297
3409.1	7.65265
3413.15	6.29624
3417.19	8.8864
3421.23	10.799
3425.27	9.51523
3429.31	6.94547
3433.34	3.39141
3437.37	6.00032
3441.39	9.24787
3445.42	6.91073
3449.44	1.61438
3453.46	1.64453
3457.47	5.29033
3461.49	6.21532
3465.5	4.3129
3469.51	-1.23515
3473.51	1.9549
3477.52	3.66166
3481.52	4.76192
3485.51	5.37229
3489.51	4.97385
3493.5	5.90845
3497.49	6.05618
3501.48	6.46776
3505.46	5.12752
3509.45	2.89291
3513.43	2.88753
3517.4	3.32006
3521.38	5.60365
3525.35	8.03554
3529.32	8.29868
3533.28	8.20966
3537.25	5.92246
3541.21	5.98489
3545.17	6.84522
3549.12	6.67291
3553.08	6.7757
3557.03	5.95373
3560.98	6.74681
3564.92	8.689
3568.87	12.422
3572.81	17.8348
3576.74	22.5724
3580.68	26.3564
3584.61	29.1626
3588.54	31.3804
3592.47	28.2664
3596.4	18.6657
3600.32	17.7514
3604.24	16.881
3608.16	7.32434
3612.07	4.1987
3615.98	4.78917
3619.89	5.74523
3623.8	4.87689
3627.71	3.19514
3631.61	5.69173
3635.51	6.68473
3639.41	4.06936
3643.3	1.02758
3647.19	0.785728
3651.08	2.28161
3654.97	3.58881
3658.85	5.3539
3662.74	6.23239
3666.62	5.57678
3670.49	5.2108
3674.37	6.2464
3678.24	6.97753
3682.11	7.1651
3685.98	6.6018
3689.84	8.01924
3693.7	6.18762
3697.56	6.03207
3701.42	6.71354
3705.28	7.11839
3709.13	8.75993
3712.98	4.92837
3716.82	6.68586
3720.67	7.20317
3724.51	5.83106
3728.35	4.09126
3732.19	3.61528
3736.02	5.20135
3739.86	7.27835
3743.69	7.30035
3747.51	6.85478
3751.34	6.55454
3755.16	7.49072
3758.98	5.99957
3762.8	4.44944
3766.61	3.85984
3770.43	4.30826
3774.24	5.79269
3778.05	6.24172
3781.85	7.66501
3785.65	7.1228
3789.45	5.13107
3793.25	5.02577
3797.05	6.54555
3800.84	7.39753
3804.63	7.69383
3808.42	8.17959
3812.21	9.26255
3815.99	8.69428
3819.77	6.44365
3823.55	6.65481
3827.33	7.74467
3831.1	5.36409
3834.87	5.86377
3838.64	5.73499
3842.41	4.67867
3846.17	5.59248
3849.93	5.87204
3853.69	6.18947
3857.45	5.00208
3861.21	5.77534
3864.96	4.54581
3868.71	5.25307
3872.46	5.95844
3876.2	4.99298
3879.94	4.49019
3883.68	3.87674
3887.42	3.1077
3891.16	2.48502
3894.89	2.71133
3898.62	5.13279
3902.35	4.09592
3906.08	3.41069
3909.8	4.67347
3913.52	3.64317
3917.24	5.35876
3920.96	3.79422
3924.67	1.81193
3928.38	-0.0385246
3932.09	-0.620594
3935.8	0.226421
3939.51	0.805199
3943.21	1.81186
3946.91	3.38682
3950.61	3.69757
3954.3	4.17545
3958	4.52634
3961.69	5.63597
3965.38	4.27684
3969.06	2.33942
3972.75	2.00297
3976.43	1.60009
3980.11	1.58517
3983.78	2.56523
3987.46	1.03017
3991.13	1.12874
3994.8	1.72158
3998.47	0.0220337