File: Data/3-Raman/processed/bu20-C-brt1-FI03-633-v.txt
#Acq. time (s)=	20
#Accumulations=	3
#Range (cm-¹)=	100...4000
#Windows=	1
#Auto scanning=	Off
#Autofocus=	Off
#Macrospot=	Off
#AutoExposure=	Off
#Spike filter=	Multiple accum.
#Delay time (s)=	0
#Binning=	1
#Readout mode=	Signal
#DeNoise=	Lite
#ICS correction=	Off
#Dark correction=	Off
#Inst. Process=	Off
#Detector temperature (°C)=	-60.09
#Instrument=	LabRAM HR Evol
#Detector=	SIN-EM FIVIS
#Objective=	x50_VIS_LWD
#Grating=	150 (500nm)
#ND Filter=	100%
#Laser=	633nm_Edge
#Hole=	30.0125
#Temperature=	0
#Range=	Visible
#StageXY=	75x50mm Scan+
#StageZ=	Z motor
#X (µm)=	7362.6
#Y (µm)=	4426.1
#Z (µm)=	-30.3
#Full time(mm:ss)=	1:02
#Project=	Buranga
#Sample=	BU18FA20_C
#Site=	C_Bertoss1
#Title=	20-C_brt1_FI03
#Remark=
#Date=	30.07.2019 14:39
#Acquired=	30.07.2019 14:39:04
#Data Range:Extract=	16.12.2021 15:36:30
#Base:Fit=	16.12.2021 15:36:40
#Base:Edit=	16.12.2021 15:38:11
#Base:Edit=	16.12.2021 15:38:14
#Base:Edit=	16.12.2021 15:38:14
#Base:Sub=	16.12.2021 15:38:15
100.38	549.996
106.898	409.852
113.411	319.053
119.918	256.362
126.419	204.349
132.916	162.031
139.407	130.137
145.892	106.186
152.372	85.4301
158.847	64.1666
165.316	52.4756
171.781	43.8107
178.239	32.4131
184.693	8.63467
191.139	14.982
197.582	7.43842
204.02	0.275711
210.452	0.606842
216.877	3.37901
223.299	6.92191
229.715	17.4031
236.126	78.7053
242.53	194.384
248.931	119.205
255.326	61.3904
261.714	47.8597
268.099	57.5038
274.477	85.2599
280.851	131.875
287.218	215.759
293.582	244.78
299.939	130.906
306.293	61.7627
312.639	29.4085
318.982	45.1914
325.318	102.538
331.651	242.868
337.977	206.488
344.297	102.978
350.614	45.202
356.925	50.2163
363.23	75.1567
369.53	95.9402
375.827	92.4291
382.116	43.3809
388.401	10.0068
394.681	0.787758
400.956	0.940109
407.226	6.88927
413.49	14.4095
419.749	22.1666
426.003	40.7245
432.252	75.0814
438.496	132.831
444.735	166.464
450.969	172.26
457.197	155.644
463.421	135.812
469.64	99.4976
475.853	60.8658
482.062	32.9863
488.265	21.0853
494.464	17.7359
500.657	23.9841
506.844	32.6536
513.028	37.174
519.206	35.6178
525.38	31.055
531.548	30.7522
537.71	29.2326
543.869	25.5028
550.022	26.2586
556.169	29.8556
562.313	27.8176
568.452	21.1557
574.584	19.0271
580.713	23.4114
586.837	37.1527
592.954	63.6618
599.068	104.187
605.176	209.16
611.28	184.262
617.378	143.83
623.473	125.077
629.561	136
635.644	145.36
641.724	141.489
647.797	126.309
653.867	127.128
659.931	151.128
665.99	174.723
672.044	128.788
678.095	74.7252
684.139	45.2096
690.179	28.7775
696.213	18.097
702.245	11.729
708.27	9.71779
714.29	10.0686
720.306	10.2414
726.316	9.98528
732.322	10.3093
738.323	10.1808
744.32	8.44999
750.311	7.63181
756.298	7.74886
762.28	8.87003
768.258	11.1825
774.23	11.7159
780.198	9.29883
786.161	4.49693
792.119	-0.015419
798.073	2.01247
804.021	8.54088
809.965	9.04378
815.904	8.30414
821.839	10.7472
827.769	10.1391
833.693	11.194
839.614	13.2817
845.53	15.2007
851.44	14.3222
857.346	12.8916
863.248	12.6492
869.144	14.0021
875.037	16.4845
880.924	17.5806
886.807	21.4364
892.685	23.2738
898.559	28.4433
904.427	24.081
910.292	21.0937
916.151	24.556
922.006	31.9244
927.856	36.2048
933.701	40.4092
939.543	48.7198
945.379	65.1523
951.21	90.6303
957.037	120.852
962.861	152.02
968.678	169.045
974.491	197.835
980.3	251.594
986.104	389.216
991.904	566.854
997.699	597.038
1003.49	467.689
1009.28	369.387
1015.06	333.592
1020.83	344.753
1026.61	425.006
1032.37	462.424
1038.14	326.161
1043.9	221.014
1049.65	159.677
1055.4	126.701
1061.15	105.048
1066.88	88.5823
1072.62	84.5305
1078.35	93.9609
1084.08	117.669
1089.8	145.733
1095.52	166.582
1101.23	179.842
1106.94	176.626
1112.65	127.09
1118.35	80.0547
1124.05	50.8793
1129.74	41.6032
1135.42	45.9912
1141.11	57.7822
1146.78	72.8256
1152.46	89.3978
1158.13	105.492
1163.79	90.7239
1169.45	52.5368
1175.11	31.5161
1180.76	25.7334
1186.41	21.8906
1192.05	18.0203
1197.69	15.3737
1203.32	10.6277
1208.95	5.79629
1214.58	3.94555
1220.2	5.13219
1225.82	7.93323
1231.43	6.279
1237.04	4.0828
1242.64	4.80302
1248.24	6.92317
1253.83	8.18478
1259.42	12.6667
1265.01	26.8671
1270.59	15.25
1276.17	23.0162
1281.74	164.837
1287.31	188.97
1292.88	30.0204
1298.44	19.7688
1303.99	14.7826
1309.55	12.6573
1315.09	8.37506
1320.64	4.29328
1326.18	4.67198
1331.71	6.64754
1337.24	10.7888
1342.77	10.6553
1348.29	4.53914
1353.81	1.22967
1359.32	4.11382
1364.83	9.10843
1370.33	15.6336
1375.84	9.56539
1381.33	29.5529
1386.82	475.732
1392.31	103.597
1397.8	16.0625
1403.28	27.151
1408.75	32.4555
1414.22	17.5696
1419.69	0.663422
1425.15	5.06969
1430.61	-0.994537
1436.07	1.68288
1441.52	1.32985
1446.96	1.94735
1452.41	2.5217
1457.84	1.26599
1463.28	-2.27177
1468.71	-2.6593
1474.13	-0.740868
1479.55	1.37455
1484.97	1.59926
1490.39	-0.287529
1495.79	-0.100418
1501.2	1.66339
1506.6	1.00558
1512	0.0290451
1517.39	2.05428
1522.78	3.22694
1528.16	2.23763
1533.54	0.297668
1538.92	-1.38876
1544.29	0.316132
1549.66	2.34665
1555.02	3.4297
1560.38	0.55899
1565.74	0.248734
1571.09	3.2821
1576.44	0.456459
1581.78	3.21424
1587.12	6.66271
1592.46	8.47141
1597.79	4.62379
1603.12	3.75774
1608.44	4.04613
1613.76	4.82307
1619.08	4.76833
1624.39	2.13171
1629.7	0.651772
1635	2.22881
1640.3	5.48068
1645.59	5.88905
1650.88	5.82748
1656.17	4.38938
1661.46	3.27001
1666.74	2.99335
1672.01	3.9211
1677.28	5.33118
1682.55	6.17767
1687.82	4.35285
1693.07	5.39614
1698.33	8.07274
1703.58	9.05929
1708.83	5.56133
1714.07	3.23648
1719.31	2.6081
1724.55	3.58498
1729.78	4.98606
1735.01	4.17375
1740.23	6.25431
1745.46	6.27463
1750.67	5.83981
1755.89	5.0374
1761.09	4.72015
1766.3	4.40945
1771.5	4.43364
1776.7	6.76237
1781.89	7.99884
1787.08	6.78577
1792.27	5.14159
1797.45	5.8056
1802.62	7.78616
1807.8	9.19713
1812.97	8.67765
1818.14	6.86169
1823.3	2.07633
1828.46	6.0371
1833.61	5.10287
1838.76	5.40361
1843.91	7.32831
1849.05	7.15389
1854.19	6.44315
1859.33	7.13818
1864.46	6.80247
1869.59	6.5895
1874.71	6.11619
1879.83	6.0824
1884.95	6.47115
1890.06	6.60296
1895.17	7.05858
1900.27	7.0204
1905.38	4.69804
1910.47	2.96973
1915.57	2.63723
1920.66	3.64146
1925.74	6.44064
1930.83	4.02245
1935.91	1.6928
1940.98	5.58301
1946.05	3.74882
1951.12	6.2825
1956.18	9.214
1961.25	2.41503
1966.3	4.89806
1971.35	7.41611
1976.4	4.17604
1981.45	3.70596
1986.49	5.85453
1991.53	5.55982
1996.56	3.83311
2001.59	2.50439
2006.62	2.57724
2011.64	4.60913
2016.66	5.92095
2021.68	5.79737
2026.69	2.69527
2031.7	0.63369
2036.7	0.382652
2041.7	1.48955
2046.7	4.48068
2051.7	6.81264
2056.69	6.34475
2061.67	4.13757
2066.65	3.85458
2071.63	4.22704
2076.61	6.39119
2081.58	5.5637
2086.55	6.26768
2091.51	8.03709
2096.47	5.14713
2101.43	3.01218
2106.39	3.87767
2111.34	5.44494
2116.28	6.1936
2121.23	2.13346
2126.17	-0.032692
2131.1	1.92039
2136.03	1.62896
2140.96	0.885056
2145.89	2.88262
2150.81	6.78249
2155.73	8.97862
2160.64	9.03418
2165.55	5.83113
2170.46	2.54888
2175.36	1.09575
2180.26	1.1325
2185.16	3.75228
2190.05	4.86716
2194.94	3.89983
2199.83	3.9499
2204.71	0.603218
2209.59	0.62925
2214.46	5.26535
2219.33	6.46364
2224.2	4.88985
2229.07	2.93644
2233.93	1.23564
2238.79	-0.281189
2243.64	0.504234
2248.49	1.5098
2253.34	2.0649
2258.18	2.85629
2263.02	4.34274
2267.86	5.48513
2272.69	5.03446
2277.52	3.39358
2282.35	2.02771
2287.17	1.69261
2291.99	2.44942
2296.8	4.82507
2301.62	5.88869
2306.43	5.24045
2311.23	-0.0812988
2316.03	1.18556
2320.83	5.16373
2325.63	10.1648
2330.42	11.2159
2335.21	8.67225
2339.99	4.50123
2344.77	3.49559
2349.55	2.19808
2354.32	4.44971
2359.1	4.44022
2363.86	3.36338
2368.63	1.40874
2373.39	-0.074028
2378.15	2.34602
2382.9	3.79535
2387.65	3.29317
2392.4	3.05821
2397.14	3.28317
2401.88	3.61234
2406.62	4.01558
2411.35	1.72769
2416.08	3.45367
2420.81	2.33447
2425.53	2.46747
2430.25	2.95676
2434.97	3.13239
2439.69	4.24106
2444.4	2.95696
2449.1	1.72414
2453.81	1.55867
2458.51	1.35516
2463.2	0.107765
2467.9	-0.396385
2472.59	-0.519241
2477.27	2.28558
2481.96	4.01003
2486.64	2.70463
2491.31	1.23776
2495.99	0.20858
2500.66	-0.541763
2505.32	2.82666
2509.99	4.28989
2514.65	4.58525
2519.31	5.20441
2523.96	3.42244
2528.61	0.203476
2533.26	0.952232
2537.9	3.55817
2542.54	4.16125
2547.18	2.74215
2551.81	1.56065
2556.44	2.42809
2561.07	6.47224
2565.69	5.95355
2570.32	5.40599
2574.93	2.36256
2579.55	3.62639
2584.16	2.42145
2588.77	2.18591
2593.37	2.16852
2597.97	3.864
2602.57	2.19417
2607.17	3.20808
2611.76	4.32146
2616.35	5.49358
2620.93	7.2486
2625.51	5.46391
2630.09	5.96666
2634.67	3.30995
2639.24	1.84373
2643.81	3.46953
2648.38	3.81795
2652.94	2.23006
2657.5	-0.620979
2662.06	-0.0231705
2666.61	0.795807
2671.16	1.06049
2675.71	0.520676
2680.25	-0.346016
2684.79	-0.490471
2689.33	1.0739
2693.86	3.28108
2698.39	4.93172
2702.92	2.51204
2707.45	0.581253
2711.97	2.13371
2716.49	2.56811
2721	2.12671
2725.51	1.74164
2730.02	1.5864
2734.53	0.420403
2739.03	0.347656
2743.53	1.7196
2748.03	3.33096
2752.52	4.29175
2757.01	-0.348839
2761.5	2.26022
2765.98	2.13387
2770.46	1.55439
2774.94	3.74237
2779.42	3.35724
2783.89	2.99844
2788.36	3.70397
2792.82	2.51234
2797.28	2.121
2801.74	2.42224
2806.2	3.8429
2810.65	4.06773
2815.1	4.07198
2819.55	3.22673
2823.99	2.35254
2828.43	2.37546
2832.87	3.08356
2837.3	3.54873
2841.74	3.27715
2846.17	4.81815
2850.59	5.85287
2855.01	6.52862
2859.43	6.32705
2863.85	5.24355
2868.26	3.65987
2872.67	2.34003
2877.08	1.48114
2881.48	4.44596
2885.89	4.75698
2890.28	4.28627
2894.68	1.88847
2899.07	1.40969
2903.46	2.63558
2907.85	2.71562
2912.23	5.14433
2916.61	0.536736
2920.98	-0.751953
2925.36	0.268501
2929.73	1.83705
2934.1	1.77885
2938.46	1.50665
2942.82	1.66879
2947.18	1.89417
2951.54	2.51669
2955.89	2.71884
2960.24	1.33549
2964.59	0.241821
2968.93	0.857735
2973.27	2.52692
2977.61	4.0275
2981.95	2.09703
2986.28	2.64877
2990.61	2.04757
2994.94	1.39948
2999.26	0.188843
3003.58	0.228622
3007.9	0.774132
3012.21	3.12408
3016.52	2.64343
3020.83	1.57308
3025.14	3.425
3029.44	3.88859
3033.74	3.56635
3038.04	0.920959
3042.33	-1.06007
3046.62	-1.71425
3050.91	-1.27759
3055.2	0.378922
3059.48	1.69708
3063.76	3.06285
3068.03	5.25774
3072.31	4.86897
3076.58	0.931877
3080.85	-1.34252
3085.11	1.06214
3089.37	3.72202
3093.63	4.6457
3097.89	4.48481
3102.14	4.05787
3106.39	5.33327
3110.64	6.60819
3114.89	4.8905
3119.13	2.39741
3123.37	2.90789
3127.6	3.70901
3131.84	4.49252
3136.07	4.28329
3140.29	3.63258
3144.52	3.09377
3148.74	2.54627
3152.96	3.05099
3157.18	6.18629
3161.39	9.35422
3165.6	10.3394
3169.81	8.11554
3174.01	6.95962
3178.22	9.38857
3182.42	10.4464
3186.61	10.6642
3190.8	8.69742
3195	7.26474
3199.18	8.91223
3203.37	8.68752
3207.55	11.0447
3211.73	12.8819
3215.91	11.2738
3220.08	8.65786
3224.25	5.89255
3228.42	5.41151
3232.59	7.87115
3236.75	5.9651
3240.91	4.80709
3245.07	3.75158
3249.22	2.90921
3253.37	3.42232
3257.52	2.9529
3261.67	2.71502
3265.81	3.91267
3269.95	3.09709
3274.09	2.31168
3278.22	2.2369
3282.36	1.86948
3286.49	0.708168
3290.61	-0.548485
3294.74	-2.47915
3298.86	-4.25517
3302.98	0.97406
3307.09	0.966515
3311.21	-1.37666
3315.32	0.248642
3319.42	1.85713
3323.53	1.9119
3327.63	1.82693
3331.73	-0.313911
3335.83	-0.363022
3339.92	-0.133751
3344.01	1.22565
3348.1	2.23172
3352.19	1.28553
3356.27	1.51228
3360.35	1.0694
3364.43	1.81689
3368.5	2.4994
3372.58	3.00432
3376.65	3.33244
3380.71	5.02801
3384.78	7.15147
3388.84	8.3993
3392.9	7.87033
3396.95	5.05727
3401.01	4.29287
3405.06	5.73853
3409.1	5.99769
3413.15	8.06386
3417.19	10.9849
3421.23	9.53784
3425.27	7.40691
3429.31	5.393
3433.34	4.05029
3437.37	2.58526
3441.39	3.30155
3445.42	4.49757
3449.44	5.06001
3453.46	4.62278
3457.47	5.08576
3461.49	3.60072
3465.5	0.605804
3469.51	1.9267
3473.51	3.21623
3477.52	2.37591
3481.52	1.60317
3485.51	0.928818
3489.51	-0.305496
3493.5	2.44685
3497.49	2.37224
3501.48	1.43382
3505.46	0.694946
3509.45	3.18004
3513.43	5.29621
3517.4	3.35001
3521.38	2.75411
3525.35	2.34328
3529.32	1.51345
3533.28	0.739029
3537.25	1.63194
3541.21	2.05824
3545.17	1.37263
3549.12	1.90723
3553.08	1.88284
3557.03	2.50896
3560.98	3.89412
3564.92	7.25749
3568.87	10.1773
3572.81	15.2931
3576.74	18.3179
3580.68	21.316
3584.61	24.7602
3588.54	23.1797
3592.47	20.8042
3596.4	22.0504
3600.32	18.444
3604.24	12.6792
3608.16	9.6583
3612.07	4.53001
3615.98	0.941029
3619.89	1.66666
3623.8	4.62802
3627.71	3.69067
3631.61	2.43808
3635.51	1.75969
3639.41	0.558205
3643.3	2.16989
3647.19	4.46526
3651.08	3.88688
3654.97	3.03469
3658.85	2.2668
3662.74	1.67049
3666.62	1.45308
3670.49	1.6878
3674.37	0.931976
3678.24	1.57634
3682.11	1.45243
3685.98	2.8427
3689.84	4.96146
3693.7	2.36866
3697.56	-0.494205
3701.42	-1.24081
3705.28	0.298634
3709.13	1.8598
3712.98	1.10455
3716.82	1.30021
3720.67	2.40017
3724.51	3.53284
3728.35	2.0273
3732.19	0.106403
3736.02	-1.1588
3739.86	-0.450687
3743.69	-1.28344
3747.51	-0.210701
3751.34	1.6414
3755.16	2.1167
3758.98	2.30096
3762.8	1.08468
3766.61	0.528866
3770.43	0.56192
3774.24	1.1298
3778.05	1.88064
3781.85	3.67673
3785.65	1.63212
3789.45	2.21781
3793.25	2.89601
3797.05	0.684353
3800.84	-1.59089
3804.63	-2.79152
3808.42	-1.76873
3812.21	4.46116
3815.99	2.52028
3819.77	0.530979
3823.55	0.618629
3827.33	0.906681
3831.1	0.529755
3834.87	1.118
3838.64	2.6468
3842.41	3.91468
3846.17	2.95242
3849.93	1.77571
3853.69	2.032
3857.45	2.58115
3861.21	3.08807
3864.96	3.13704
3868.71	2.08541
3872.46	1.09039
3876.2	1.80218
3879.94	1.11628
3883.68	0.041275
3887.42	-0.858387
3891.16	1.91175
3894.89	3.18428
3898.62	2.74632
3902.35	-0.336536
3906.08	0.636944
3909.8	2.38698
3913.52	4.28471
3917.24	4.49758
3920.96	5.86757
3924.67	5.53915
3928.38	2.80129
3932.09	-0.38496
3935.8	-0.416561
3939.51	2.06048
3943.21	3.17643
3946.91	1.71074
3950.61	0.628578
3954.3	2.71105
3958	4.47539
3961.69	4.88002
3965.38	4.67166
3969.06	3.56168
3972.75	2.0834
3976.43	1.01281
3980.11	-0.23761
3983.78	0.397884
3987.46	1.71668
3991.13	3.12382
3994.8	4.93404
3998.47	6.00792