File: Data/3-Raman/processed/bu20-H-trl1-FI06-v.txt
#Acq. time (s)=	15
#Accumulations=	3
#Range (cm-¹)=	100...4000
#Windows=	1
#Auto scanning=	Off
#Autofocus=	Off
#Macrospot=	Off
#AutoExposure=	Off
#Spike filter=	Multiple accum.
#Delay time (s)=	0
#Binning=	1
#Readout mode=	Signal
#DeNoise=	Lite
#ICS correction=	Off
#Dark correction=	Off
#Inst. Process=	Off
#Detector temperature (°C)=	-60.09
#Instrument=	LabRAM HR Evol
#Detector=	SIN-EM FIVIS
#Objective=	x100_VIS
#Grating=	150 (500nm)
#ND Filter=	100%
#Laser=	532nm_Edge
#Hole=	30.0125
#Temperature=	0
#Range=	Visible
#StageXY=	75x50mm Scan+
#StageZ=	Z motor
#X (µm)=	12554.2
#Y (µm)=	6998.6
#Z (µm)=	1906.6
#Full time(s)=	48
#Project=	Buranga
#Sample=	BU18FA20_G
#Site=	G_trl1
#Title=	20-H_trl1_FI06
#Remark=
#Date=	30.07.2019 18:32
#Acquired=	30.07.2019 18:32:46
#Data Range:Extract=	16.12.2021 15:36:30
#Base:Fit=	16.12.2021 15:36:40
#Base:Edit=	16.12.2021 15:50:21
#Base:Edit=	16.12.2021 15:50:22
#Base:Edit=	16.12.2021 15:50:24
#Base:Sub=	16.12.2021 15:50:26
103.656	7793.38
108.278	6760.48
112.899	5889.98
117.517	5052.17
122.131	4288.75
126.744	3584.69
131.355	2984.21
135.964	2503.9
140.571	2115.77
145.173	1809.4
149.776	1579.56
154.375	1406.39
158.973	1492.18
163.566	2493.31
168.159	3574.06
172.75	3346.36
177.339	1661.49
181.923	735.502
186.507	642.04
191.089	1506.02
195.668	2542.13
200.243	2788.38
204.818	1812.91
209.391	1004.02
213.96	447.608
218.528	102.292
223.094	1.26959
227.655	131.281
232.217	481.882
236.776	1072.14
241.331	1931.92
245.886	2941.9
250.439	4198.53
254.987	5170.54
259.535	4509.1
264.081	2346.41
268.622	1252.03
273.164	1325.53
277.703	2579.63
282.238	5810.17
286.773	9462.91
291.305	9852.4
295.833	5879.02
300.362	3707.34
304.885	2453.94
309.409	1713.7
313.93	1230.27
318.448	1098.36
322.965	1613.02
327.477	2402.7
331.99	3168.39
336.5	3851.07
341.007	4356.74
345.513	4714.23
350.014	4919.59
354.516	4994.58
359.013	4967.96
363.51	4583.47
368.005	4033.25
372.496	3353.2
376.987	2690.62
381.473	2201.9
385.96	1927.46
390.442	1693.36
394.923	1634.02
399.401	1766.82
403.879	1811.82
408.352	1420.57
412.825	847.764
417.294	444.851
421.763	648.06
426.227	727.784
430.692	562.92
435.152	349.155
439.612	173.978
444.068	79.6467
448.524	81.0327
452.976	174.989
457.427	310.048
461.874	443.3
466.32	509.796
470.765	531.735
475.205	514.22
479.646	508.821
484.083	577.553
488.519	826.754
492.951	1210.3
497.381	1657.02
501.811	2086.57
506.237	2250.77
510.663	1986.57
515.084	1524.65
519.504	1094.91
523.923	764.718
528.338	526.199
532.753	371.526
537.164	293.874
541.572	264.036
545.981	264.697
550.385	286.341
554.788	317.993
559.19	354.519
563.588	389.917
567.986	425.698
572.38	450.552
576.771	477.544
581.163	508.992
585.551	668.225
589.936	1463.58
594.319	3096.44
598.702	3493.71
603.081	2962.67
607.458	1820.8
611.835	1224.44
616.208	1233.25
620.578	1252.26
624.949	1023.2
629.315	813.784
633.68	664.124
638.042	611.635
642.404	686.439
646.762	812.233
651.118	931.861
655.472	1021.92
659.825	1151.46
664.175	1479.9
668.523	2128.21
672.868	2820.94
677.213	3289.03
681.555	3465.19
685.894	3325.76
690.231	2767.86
694.566	1896.32
698.901	1078.76
703.232	619.697
707.561	321.864
711.888	165.891
716.212	122.243
720.537	97.7856
724.858	78.3207
729.176	67.6281
733.493	64.6713
737.807	71.7669
742.119	90.5239
746.432	112.624
750.74	135.492
755.046	166.88
759.35	227.483
763.652	357.288
767.952	625.545
772.25	1083.57
776.546	1785.72
780.842	2953.08
785.133	4315.19
789.423	4874.57
793.711	3759.05
797.997	2325.22
802.28	1345.36
806.562	740.347
810.841	437.159
815.119	274.438
819.394	200.214
823.668	144.081
827.941	100.35
832.211	59.9564
836.478	31.277
840.743	8.3591
845.006	-10.7642
849.268	-25.2301
853.527	-39.5631
857.784	-50.9521
862.039	-62.01
866.293	-69.8248
870.544	-75.2169
874.793	-78.8878
879.04	-82.5967
883.285	-89.7355
887.528	-91.5476
891.769	-89.405
896.008	-86.5232
900.246	-81.6636
904.481	-75.0963
908.714	-66.5099
912.945	-56.176
917.174	-43.7111
921.401	-28.2005
925.626	-15.774
929.849	5.70392
934.068	37.2567
938.287	116.845
942.504	273.938
946.72	513.289
950.933	877.924
955.144	1294.08
959.353	1617.41
963.56	1413.91
967.765	959.091
971.968	733.827
976.17	568.757
980.367	428.793
984.564	315.196
988.759	230.883
992.953	169.272
997.144	121.9
1001.33	90.468
1005.52	70.9298
1009.71	64.0582
1013.89	70.7841
1018.07	86.609
1022.25	113.551
1026.43	150.924
1030.6	195.928
1034.78	291.668
1038.94	378.609
1043.11	596.737
1047.28	1010.62
1051.45	1701.14
1055.61	3169.95
1059.77	4809.24
1063.93	5242.52
1068.09	3953.95
1072.25	2496.73
1076.4	1602.13
1080.55	1232.61
1084.7	1390.01
1088.85	2016.9
1092.99	3310.67
1097.14	4100.4
1101.28	4392.26
1105.42	4520.31
1109.56	4625.18
1113.69	4709.6
1117.83	4780.38
1121.96	4829.08
1126.09	4828.7
1130.22	4792.38
1134.35	4734.94
1138.47	4870.53
1142.59	4790.07
1146.71	4300.29
1150.83	3205.85
1154.95	2528.24
1159.06	2661.78
1163.18	3216.95
1167.29	3489.3
1171.4	3245.08
1175.5	2688.28
1179.61	2239.33
1183.71	1671.62
1187.81	1053.72
1191.91	729.338
1196.01	548.447
1200.1	476.248
1204.2	437.798
1208.29	396.915
1212.38	368.281
1216.47	355.595
1220.55	588.967
1224.64	784.276
1228.72	961.544
1232.8	1101.3
1236.88	1216.06
1240.95	1257.77
1245.03	1336.98
1249.1	1355.82
1253.17	1323.04
1257.24	1198.07
1261.31	927.827
1265.37	789.527
1269.44	811.574
1273.5	2372.58
1277.56	3568.23
1281.61	3548.78
1285.67	2099.28
1289.72	694.215
1293.77	347.153
1297.83	288.518
1301.87	237.211
1305.92	196.662
1309.96	170.731
1314.01	152.58
1318.05	153.508
1322.09	160.15
1326.12	164.318
1330.16	165.598
1334.19	156.917
1338.22	144.943
1342.25	138.254
1346.28	150.541
1350.3	175.031
1354.33	211.662
1358.35	268.144
1362.37	344.943
1366.39	442.754
1370.4	569.078
1374.42	1052.08
1378.43	4053.41
1382.44	6715.81
1386.45	6461.82
1390.46	3549.25
1394.46	1066.09
1398.46	681.871
1402.47	749.379
1406.46	673.996
1410.46	523.942
1414.46	235.972
1418.45	130.691
1422.45	79.3688
1426.43	41.0865
1430.42	9.17587
1434.41	-14.8781
1438.39	-33.3034
1442.38	-45.2345
1446.36	-53.8197
1450.34	-59.3341
1454.31	-63.7312
1458.29	-67.1224
1462.27	-69.8173
1466.24	-72.8459
1470.21	-74.2234
1474.18	-74.6872
1478.14	-74.4748
1482.11	-73.3133
1486.07	-72.0213
1490.03	-70.5342
1493.99	-68.883
1497.95	-67.6857
1501.9	-67.1122
1505.86	-66.7612
1509.81	-67.4228
1513.76	-69.0118
1517.71	-70.9411
1521.65	-70.8962
1525.6	-69.9943
1529.54	-69.0822
1533.48	-67.9553
1537.42	-65.1061
1541.36	-61.2392
1545.29	-57.3757
1549.23	-53.4012
1553.16	-49.9196
1557.09	-46.8802
1561.02	-44.4829
1564.94	-41.9372
1568.87	-39.9583
1572.79	-38.1204
1576.71	-36.8127
1580.63	-36.295
1584.55	-36.0127
1588.47	-36.0168
1592.38	-36.3122
1596.29	-36.6505
1600.2	-36.9149
1604.11	-35.8205
1608.02	-32.2321
1611.92	-30.6142
1615.83	-30.9219
1619.73	-32.053
1623.63	-40.5215
1627.53	-29.3216
1631.42	-26.9057
1635.32	-26.4283
1639.21	-25.7719
1643.1	-23.4317
1646.99	-21.0875
1650.88	-18.8156
1654.76	-17.3505
1658.64	-17.8306
1662.53	-18.595
1666.41	-18.7468
1670.28	-19.442
1674.16	-19.0222
1678.04	-17.3433
1681.91	-15.8396
1685.78	-14.1287
1689.65	-12.0048
1693.52	-9.95255
1697.38	-7.47882
1701.25	-5.39388
1705.11	-3.03026
1708.97	0.400543
1712.83	2.35043
1716.69	2.01613
1720.54	0.543808
1724.4	-1.20387
1728.25	0.126678
1732.1	1.21645
1735.95	2.11615
1739.79	2.91377
1743.64	3.61923
1747.48	4.37781
1751.33	5.06049
1755.17	8.20886
1759	10.394
1762.84	12.3213
1766.68	12.3989
1770.51	11.6832
1774.34	10.7599
1778.17	10.159
1782	8.43916
1785.82	10.9759
1789.65	14.1649
1793.47	19.7379
1797.29	19.5317
1801.11	18.6767
1804.93	17.7322
1808.74	15.4708
1812.56	14.3962
1816.37	13.2643
1820.18	11.9254
1823.99	23.1805
1827.79	13.5245
1831.6	10.3158
1835.4	9.44849
1839.2	10.6233
1843	12.7273
1846.8	15.1482
1850.6	15.2984
1854.39	13.621
1858.19	12.7983
1861.98	15.6619
1865.77	19.0529
1869.56	22.9422
1873.34	26.8922
1877.13	30.5791
1880.91	33.6267
1884.69	35.4887
1888.47	35.8052
1892.25	33.6727
1896.03	28.4806
1899.8	37.3099
1903.57	35.1176
1907.34	30.0062
1911.11	24.5294
1914.88	20.8202
1918.65	19.7588
1922.41	18.2464
1926.18	18.4886
1929.94	19.2463
1933.7	20.0332
1937.45	20.1722
1941.21	19.267
1944.96	17.4514
1948.72	15.7737
1952.47	14.0764
1956.22	12.7728
1959.96	11.7387
1963.71	11.3654
1967.45	11.9749
1971.2	13.0209
1974.94	14.0792
1978.68	14.5238
1982.42	14.4953
1986.15	14.2647
1989.89	13.6804
1993.62	12.9663
1997.35	12.1407
2001.08	11.0264
2004.8	9.66708
2008.53	8.27122
2012.25	7.6994
2015.98	7.82132
2019.7	9.68024
2023.42	11.3287
2027.13	11.8709
2030.85	12.6721
2034.56	13.2117
2038.28	11.9463
2041.99	10.5728
2045.7	9.28371
2049.41	8.68515
2053.11	8.77713
2056.82	9.28467
2060.52	9.96057
2064.22	10.6354
2067.92	11.1351
2071.62	11.4239
2075.31	8.84712
2079.01	6.70096
2082.7	4.39209
2086.39	4.48697
2090.08	5.74551
2093.77	7.39561
2097.45	7.98918
2101.14	7.84489
2104.82	7.46786
2108.5	7.052
2112.18	6.51682
2115.86	7.45901
2119.54	11.0217
2123.21	13.5062
2126.88	17.1407
2130.56	19.1024
2134.23	19.1012
2137.89	18.0353
2141.56	16.0334
2145.23	15.2791
2148.89	15.932
2152.55	17.8452
2156.21	21.1393
2159.87	25.2513
2163.53	30.1575
2167.18	35.107
2170.84	40.2011
2174.49	45.0114
2178.14	51.7647
2181.79	58.3452
2185.44	63.961
2189.08	69.145
2192.73	73.6875
2196.37	77.0985
2200.01	79.3255
2203.65	82.2324
2207.29	85.7684
2210.92	88.3716
2214.56	90.0189
2218.19	90.7642
2221.82	90.4935
2225.45	89.2928
2229.08	86.9845
2232.7	84.0967
2236.33	78.422
2239.95	72.2758
2243.57	65.8941
2247.19	60.4133
2250.81	55.5829
2254.43	52.5568
2258.04	48.9031
2261.66	44.4359
2265.27	41.3582
2268.88	39.9881
2272.49	38.389
2276.1	35.4319
2279.7	32.9533
2283.31	30.2616
2286.91	27.8458
2290.51	25.5599
2294.11	23.4541
2297.71	21.7245
2301.3	20.3281
2304.9	23.2012
2308.49	5.08386
2312.08	18.155
2315.67	19.3788
2319.26	131.251
2322.85	417.129
2326.43	429.015
2330.02	310.907
2333.6	69.6782
2337.18	23.5423
2340.76	21.9727
2344.34	22.1917
2347.91	23.0032
2351.49	20.5222
2355.06	20.014
2358.63	20.2741
2362.2	18.4454
2365.77	14.5937
2369.33	10.2382
2372.9	5.62093
2376.46	2.67265
2380.02	-0.0614624
2383.58	-0.449341
2387.14	-0.694916
2390.7	1.41191
2394.25	2.66899
2397.81	2.86003
2401.36	2.24443
2404.91	1.15741
2408.46	-0.172211
2412.01	-1.47081
2415.56	-2.30208
2419.1	-0.674408
2422.64	-0.0407257
2426.18	1.7612
2429.72	2.64496
2433.26	-0.771439
2436.8	-5.5461
2440.34	-7.1311
2443.87	-8.61447
2447.4	-10.1078
2450.93	-11.1922
2454.46	-11.9409
2457.99	-12.9647
2461.52	-14.28
2465.04	-15.9914
2468.56	-17.7555
2472.09	-19.4715
2475.61	-19.4174
2479.13	-18.6515
2482.64	-17.2142
2486.16	-16.3796
2489.67	-13.8739
2493.18	-10.9471
2496.69	-8.11436
2500.2	-6.14868
2503.71	-5.64291
2507.22	-5.83482
2510.72	-6.52473
2514.23	-8.13231
2517.73	-9.92628
2521.23	-11.7954
2524.73	-11.8334
2528.23	-8.36589
2531.72	-4.76982
2535.21	-1.28627
2538.71	-0.783966
2542.2	-3.35733
2545.69	-5.72356
2549.18	-7.55122
2552.66	-8.88477
2556.15	-9.90462
2559.63	-9.76506
2563.12	-9.35046
2566.6	-8.72301
2570.08	-8.02533
2573.55	-7.54562
2577.03	-7.18335
2580.5	-7.18854
2583.98	-6.59598
2587.45	-5.60004
2590.92	-4.74275
2594.39	-3.70532
2597.86	-4.37022
2601.32	-5.17754
2604.79	-5.96098
2608.25	-7.08604
2611.71	-7.87698
2615.17	-8.54025
2618.63	-8.31941
2622.08	-6.69743
2625.54	-5.40379
2628.99	-5.21288
2632.45	-5.39624
2635.9	-7.30843
2639.35	-8.91222
2642.79	-5.97876
2646.24	-2.78511
2649.69	-1.5226
2653.13	-1.81885
2656.57	-2.42624
2660.01	-3.48769
2663.45	-4.65903
2666.89	-5.28262
2670.32	-3.60167
2673.76	-1.90033
2677.19	0.707123
2680.62	3.36424
2684.05	6.24478
2687.48	8.31671
2690.91	8.27281
2694.33	7.05228
2697.76	5.90477
2701.18	4.89375
2704.6	4.06104
2708.02	3.52689
2711.44	3.29645
2714.86	3.75708
2718.27	3.64296
2721.69	2.92346
2725.1	2.18779
2728.51	1.71359
2731.92	1.99405
2735.33	3.48892
2738.74	5.35001
2742.14	6.843
2745.55	8.11812
2748.95	8.86127
2752.35	9.3627
2755.75	9.25455
2759.15	4.77405
2762.54	4.95828
2765.94	7.32516
2769.33	7.09189
2772.72	5.97614
2776.12	5.24463
2779.51	4.70844
2782.89	4.29836
2786.28	4.7079
2789.67	5.53648
2793.05	6.31325
2796.43	7.299
2799.81	8.80472
2803.19	9.40164
2806.57	8.95879
2809.95	8.56134
2813.32	8.99542
2816.69	9.56079
2820.06	10.2295
2823.44	10.9356
2826.81	11.1971
2830.17	11.4864
2833.54	10.911
2836.9	10.4426
2840.27	10.1066
2843.63	9.95483
2846.99	10.3697
2850.35	10.8642
2853.71	11.4813
2857.06	12.1459
2860.42	10.9645
2863.77	10.5878
2867.12	10.3841
2870.48	11.4448
2873.83	12.2838
2877.17	12.9662
2880.52	13.5005
2883.86	13.9825
2887.21	14.2441
2890.55	14.2865
2893.89	13.9235
2897.23	13.4171
2900.57	12.5482
2903.91	11.457
2907.24	10.211
2910.57	9.12946
2913.91	8.18695
2917.24	7.34488
2920.57	7.02171
2923.9	11.186
2927.22	16.0161
2930.55	12.9534
2933.87	10.9251
2937.19	9.70053
2940.51	9.35814
2943.83	9.52699
2947.15	10.3028
2950.47	10.6253
2953.79	9.09401
2957.1	8.03603
2960.41	6.02315
2963.72	7.06143
2967.03	8.13277
2970.34	9.17207
2973.65	10.5195
2976.95	12.553
2980.26	14.3647
2983.56	15.8098
2986.86	16.1911
2990.16	18.2534
2993.46	18.1592
2996.76	15.9475
3000.06	11.9119
3003.35	8.3877
3006.64	6.41553
3009.94	5.37636
3013.23	5.73695
3016.51	6.37537
3019.8	6.03355
3023.09	5.90395
3026.38	4.72025
3029.66	2.43755
3032.94	0.894012
3036.22	0.0990448
3039.5	-0.245789
3042.78	0.548203
3046.05	0.106216
3049.33	-2.62741
3052.6	-4.40698
3055.88	-5.0797
3059.15	-5.00208
3062.42	-3.09058
3065.69	-1.15663
3068.95	1.13071
3072.22	2.38737
3075.48	2.49887
3078.75	1.84872
3082.01	0.573013
3085.27	-0.973526
3088.53	-2.09859
3091.79	-2.95015
3095.04	-0.0267487
3098.3	0.416031
3101.55	-1.73035
3104.8	-5.78073
3108.05	-9.87599
3111.3	-11.2906
3114.55	-9.10529
3117.8	-6.00584
3121.04	-4.03955
3124.29	-2.70166
3127.53	-2.09526
3130.77	-2.91286
3134.01	-4.68637
3137.25	-6.61528
3140.49	-8.07759
3143.72	-8.40041
3146.96	-8.36412
3150.19	-8.55087
3153.42	-8.48062
3156.65	-7.95824
3159.88	-5.37656
3163.11	-5.90393
3166.34	-6.52222
3169.56	-8.17297
3172.79	-8.37439
3176.01	-9.04085
3179.23	-8.1147
3182.45	2.91882
3185.67	-1.86026
3188.88	-5.83499
3192.1	-8.55969
3195.31	-10.0935
3198.53	-10.2027
3201.74	-8.86496
3204.95	-6.1519
3208.16	-2.18265
3211.37	1.8152
3214.57	4.94412
3217.78	6.18842
3220.98	5.59619
3224.18	3.8839
3227.39	2.65727
3230.59	2.40584
3233.78	3.32594
3236.98	5.49292
3240.18	8.56834
3243.37	10.9811
3246.56	12.2207
3249.76	11.0947
3252.95	11.2686
3256.14	13.2621
3259.32	17.1981
3262.51	20.1839
3265.7	22.7945
3268.88	22.4986
3272.06	21.7547
3275.24	21.0912
3278.42	20.6463
3281.6	20.7988
3284.78	21.7143
3287.96	23.8311
3291.13	26.5545
3294.31	28.8842
3297.48	31.7131
3300.65	33.6029
3303.82	36.5447
3306.99	40.4705
3310.15	44.8762
3313.32	48.9159
3316.48	51.9114
3319.65	55.3539
3322.81	59.4767
3325.97	63.5017
3329.13	68.5483
3332.28	72.2021
3335.44	75.8345
3338.6	77.8517
3341.75	97.929
3344.9	101.307
3348.05	101.841
3351.2	103.542
3354.35	104.702
3357.5	107.062
3360.65	110.356
3363.79	118.356
3366.94	131.078
3370.08	143.546
3373.22	146.286
3376.36	152.958
3379.5	172.646
3382.63	200.061
3385.77	235.116
3388.9	284.058
3392.04	358.923
3395.17	426.81
3398.3	492.432
3401.43	545.164
3404.56	632.959
3407.69	786.738
3410.81	1115.14
3413.94	1588.7
3417.06	2704.26
3420.18	5315.84
3423.3	12174.4
3426.42	20408
3429.54	20456.6
3432.65	12716.2
3435.77	5994.82
3438.88	2870.44
3442	1685.07
3445.11	1185.42
3448.22	847.306
3451.33	749.695
3454.43	677.761
3457.54	636.34
3460.65	624.695
3463.75	645.348
3466.85	701.414
3469.95	764.113
3473.05	866.159
3476.15	993.435
3479.25	1202.42
3482.35	1461.86
3485.44	1806.96
3488.54	2310.57
3491.63	3026.35
3494.72	4082.13
3497.81	5692.92
3500.9	7776.71
3503.99	10709.5
3507.07	13712.3
3510.16	15498.2
3513.24	14744
3516.32	12268.8
3519.41	8964.7
3522.49	6490.56
3525.56	4656.43
3528.64	3370.31
3531.72	2520.2
3534.79	1944.79
3537.87	1587.91
3540.94	1232.15
3544.01	1036.72
3547.08	871.831
3550.15	739.911
3553.22	636.381
3556.28	553.502
3559.35	490.818
3562.41	440.561
3565.47	397.27
3568.54	358.614
3571.6	329.207
3574.65	305.623
3577.71	285.006
3580.77	264.807
3583.82	250.055
3586.88	235.382
3589.93	222.304
3592.98	206.536
3596.03	190.76
3599.08	175.331
3602.13	161.103
3605.18	147.701
3608.22	136.176
3611.27	127.105
3614.31	120.627
3617.35	116.752
3620.39	115.237
3623.43	116.441
3626.47	117.441
3629.5	116.841
3632.54	111.982
3635.57	102.918
3638.61	92.0342
3641.64	82.4932
3644.67	74.351
3647.7	67.8427
3650.73	62.528
3653.75	58.5127
3656.78	55.2995
3659.8	53.4885
3662.83	51.3156
3665.85	48.3095
3668.87	53.4272
3671.89	51.5697
3674.91	49.1599
3677.92	44.8318
3680.94	36.3789
3683.96	32.2968
3686.97	24.8107
3689.98	17.8004
3692.99	16.8434
3696	15.4995
3699.01	13.8959
3702.02	10.6431
3705.02	2.24132
3708.03	0.747238
3711.03	6.02869
3714.03	9.84018
3717.04	8.01346
3720.04	6.44989
3723.04	5.10068
3726.03	4.04265
3729.03	3.51752
3732.03	3.118
3735.02	2.81627
3738.01	2.63716
3741	2.32399
3743.99	2.02832
3746.98	2.50494
3749.97	2.09979
3752.96	3.0627
3755.95	4.68059
3758.93	6.38705
3761.91	7.37819
3764.9	7.92407
3767.88	7.23254
3770.86	6.82768
3773.84	6.17607
3776.81	3.58693
3779.79	-0.0415802
3782.77	0.802628
3785.74	1.48257
3788.71	1.58827
3791.68	1.19992
3794.65	1.51958
3797.62	1.93555
3800.59	3.37619
3803.56	3.75752
3806.52	3.84451
3809.49	3.0847
3812.45	1.17133
3815.41	-0.405075
3818.37	-1.52252
3821.33	-1.41901
3824.29	0.0615692
3827.25	1.42511
3830.21	3.481
3833.16	3.74745
3836.11	2.54311
3839.07	1.31564
3842.02	-0.069397
3844.97	-0.179794
3847.92	0.864655
3850.87	2.49788
3853.81	2.52443
3856.76	2.09546
3859.7	1.07841
3862.65	-0.786865
3865.59	-3.17509
3868.53	-4.17328
3871.47	-1.07715
3874.41	0.603439
3877.34	2.88318
3880.28	4.48259
3883.22	3.95296
3886.15	3.5983
3889.08	1.42404
3892.01	0.219742
3894.94	-0.865173
3897.87	-2.04349
3900.8	-3.07649
3903.73	-4.05701
3906.65	-3.04713
3909.58	-1.88446
3912.5	-0.880859
3915.42	0.234055
3918.35	1.00154
3921.27	0.693344
3924.18	-0.492157
3927.1	-1.89236
3930.02	-3.14647
3932.93	-3.82568
3935.85	-4.04121
3938.76	-3.36713
3941.67	-1.67741
3944.58	0.0399017
3947.49	1.21146
3950.4	0.0945892
3953.31	-0.500931
3956.22	2.69537
3959.12	5.63115
3962.02	8.1664
3964.93	8.96429
3967.83	10.1032
3970.73	11.0387
3973.63	11.2627
3976.53	11.0632
3979.42	9.7576
3982.32	10.9744
3985.21	13.2835
3988.11	11.4166
3991	10.8436
3993.89	5.75684
3996.78	8.81883
3999.67	3.62202