File: Data/3-Raman/processed/bu20-H-trl1-FI01-v.txt
#Acq. time (s)=	15
#Accumulations=	3
#Range (cm-¹)=	100...4000
#Windows=	1
#Auto scanning=	Off
#Autofocus=	Off
#Macrospot=	Off
#AutoExposure=	Off
#Spike filter=	Multiple accum.
#Delay time (s)=	0
#Binning=	1
#Readout mode=	Signal
#DeNoise=	Lite
#ICS correction=	Off
#Dark correction=	Off
#Inst. Process=	Off
#Detector temperature (°C)=	-60.09
#Instrument=	LabRAM HR Evol
#Detector=	SIN-EM FIVIS
#Objective=	x100_VIS
#Grating=	150 (500nm)
#ND Filter=	100%
#Laser=	532nm_Edge
#Hole=	30.0125
#Temperature=	0
#Range=	Visible
#StageXY=	75x50mm Scan+
#StageZ=	Z motor
#X (µm)=	13419.7
#Y (µm)=	5078.5
#Z (µm)=	1832.8
#Full time(s)=	47
#Project=	Buranga
#Sample=	BU18FA20_G
#Site=	G_trl1
#Title=	20-H_trl1_FI01
#Remark=
#Date=	30.07.2019 17:54
#Acquired=	30.07.2019 17:54:51
#Data Range:Extract=	16.12.2021 15:36:30
#Base:Fit=	16.12.2021 15:36:40
#Base:Edit=	16.12.2021 15:49:14
#Base:Sub=	16.12.2021 15:49:17
103.656	325.233
108.278	299.546
112.899	267.391
117.517	236.671
122.131	208.654
126.744	184.046
131.355	162.97
135.964	144.969
140.571	128.402
145.173	114.397
149.776	104.209
154.375	95.4478
158.973	115.088
163.566	234.596
168.159	358.195
172.75	288.517
177.339	150.88
181.923	55.744
186.507	59.3303
191.089	136.328
195.668	229.501
200.243	221.732
204.818	137.307
209.391	64.7423
213.96	21.908
218.528	0.684906
223.094	-0.939545
227.655	16.4229
232.217	52.4798
236.776	107.437
241.331	179.707
245.886	265.276
250.439	368.048
254.987	459.048
259.535	337.559
264.081	143.06
268.622	94.1688
273.164	102.316
277.703	217.481
282.238	520.885
286.773	901.062
291.305	721.565
295.833	481.326
300.362	299.033
304.885	177.821
309.409	109.032
313.93	66.3083
318.448	85.9774
322.965	144.825
327.477	218.406
331.99	297.392
336.5	359.883
341.007	394.138
345.513	414.866
350.014	432.34
354.516	454.091
359.013	483.447
363.51	402.582
368.005	322.185
372.496	258.191
376.987	207.801
381.473	170.44
385.96	142.891
390.442	127.875
394.923	127.903
399.401	143.285
403.879	159.028
408.352	88.6933
412.825	44.1788
417.294	32.6497
421.763	31.1114
426.227	27.3076
430.692	18.7645
435.152	8.48541
439.612	2.14349
444.068	-0.370392
448.524	1.53818
452.976	7.00662
457.427	11.9615
461.874	19.2115
466.32	27.4479
470.765	30.2738
475.205	33.2293
479.646	37.6603
484.083	47.7623
488.519	65.495
492.951	99.7772
497.381	142.552
501.811	194.613
506.237	210.222
510.663	166.253
515.084	124.223
519.504	92.7793
523.923	69.1229
528.338	52.3934
532.753	40.4948
537.164	33.5648
541.572	30.8106
545.981	30.7251
550.385	32.2552
554.788	34.3583
559.19	37.8961
563.588	42.5117
567.986	47.3398
572.38	50.8744
576.771	53.0615
581.163	55.6916
585.551	71.2874
589.936	105.539
594.319	201.211
598.702	254.05
603.081	202.682
607.458	124.751
611.835	98.1842
616.208	84.6573
620.578	74.2465
624.949	64.7721
629.315	55.9773
633.68	50.7337
638.042	49.348
642.404	52.1559
646.762	59.2371
651.118	69.6748
655.472	84.4221
659.825	106.196
664.175	139.785
668.523	185.653
672.868	238.968
677.213	295.042
681.555	319.807
685.894	311.468
690.231	219.237
694.566	146.417
698.901	85.424
703.232	54.8939
707.561	34.0681
711.888	15.3012
716.212	11.8362
720.537	11.8426
724.858	13.7505
729.176	16.941
733.493	19.0246
737.807	18.62
742.119	17.073
746.432	15.5198
750.74	16.9282
755.046	21.5918
759.35	28.9693
763.652	45.1771
767.952	74.9448
772.25	124.894
776.546	195.083
780.842	312.942
785.133	403.612
789.423	429.693
793.711	318.502
797.997	185.226
802.28	123.873
806.562	83.9908
810.841	62.8898
815.119	48.9752
819.394	36.5632
823.668	28.3361
827.941	22.821
832.211	16.1935
836.478	8.92468
840.743	3.59537
845.006	-0.214874
849.268	-2.24292
853.527	-3.06793
857.784	-2.79303
862.039	-1.6557
866.293	0.272736
870.544	1.6499
874.793	2.43671
879.04	3.15765
883.285	3.9274
887.528	4.75647
891.769	5.73569
896.008	6.96695
900.246	8.18918
904.481	9.4418
908.714	10.7751
912.945	10.6195
917.174	9.08722
921.401	6.67349
925.626	5.24738
929.849	8.728
934.068	13.4089
938.287	22.1462
942.504	32.9109
946.72	50.1714
950.933	68.0771
955.144	78.6512
959.353	82.7766
963.56	79.4951
967.765	72.575
971.968	63.024
976.17	52.4131
980.367	44.7241
984.564	34.2323
988.759	28.0014
992.953	26.2602
997.144	23.2195
1001.33	20.0011
1005.52	17.4475
1009.71	15.4215
1013.89	14.8739
1018.07	15.5215
1022.25	18.4318
1026.43	23.229
1030.6	28.7296
1034.78	36.8688
1038.94	49.3438
1043.11	65.6095
1047.28	90.4085
1051.45	155.464
1055.61	286.133
1059.77	462.773
1063.93	427.514
1068.09	315.335
1072.25	189.935
1076.4	154.651
1080.55	107.347
1084.7	150.507
1088.85	202.934
1092.99	264.151
1097.14	322.716
1101.28	368.026
1105.42	336.329
1109.56	360.491
1113.69	392.79
1117.83	434.505
1121.96	437.972
1126.09	433.996
1130.22	399.926
1134.35	405.77
1138.47	429.094
1142.59	424.558
1146.71	373.412
1150.83	270.943
1154.95	223.199
1159.06	221.561
1163.18	297.241
1167.29	280.093
1171.4	229.51
1175.5	184.699
1179.61	143.681
1183.71	108.099
1187.81	77.7323
1191.91	54.2271
1196.01	40.6769
1200.1	32.9214
1204.2	30.1887
1208.29	32.0053
1212.38	34.7591
1216.47	42.719
1220.55	53.312
1224.64	66.3084
1228.72	77.4953
1232.8	86.267
1236.88	91.4392
1240.95	93.8064
1245.03	93.3391
1249.1	89.9896
1253.17	83.784
1257.24	73.9599
1261.31	61.2284
1265.37	46.9243
1269.44	32.1393
1273.5	23.0567
1277.56	153.209
1281.61	241.113
1285.67	164.69
1289.72	67.83
1293.77	34.4436
1297.83	17.6111
1301.87	2.81525
1305.92	-2.60977
1309.96	-5.87192
1314.01	-3.50101
1318.05	0.845947
1322.09	5.64987
1326.12	11.8938
1330.16	11.8586
1334.19	10.933
1338.22	7.85864
1342.25	4.61386
1346.28	2.42685
1350.3	1.71704
1354.33	2.84094
1358.35	4.59613
1362.37	9.62866
1366.39	14.5894
1370.4	18.2851
1374.42	32.1817
1378.43	80.1093
1382.44	362.438
1386.45	421.462
1390.46	222.489
1394.46	29.9862
1398.46	17.3382
1402.47	28.7466
1406.46	38.5809
1410.46	37.229
1414.46	9.21802
1418.45	10.8301
1422.45	11.0432
1426.43	10.3852
1430.42	8.38589
1434.41	6.02853
1438.39	3.78482
1442.38	1.73672
1446.36	0.200226
1450.34	0.325897
1454.31	-0.039093
1458.29	0.36142
1462.27	0.521149
1466.24	0.100891
1470.21	-0.471252
1474.18	-0.63089
1478.14	-0.548248
1482.11	1.44217
1486.07	4.20758
1490.03	7.06671
1493.99	10.9064
1497.95	12.5829
1501.9	13.1847
1505.86	11.0462
1509.81	8.79895
1513.76	6.9321
1517.71	6.30396
1521.65	6.40433
1525.6	6.68921
1529.54	5.05234
1533.48	2.22409
1537.42	-0.70993
1541.36	-3.07736
1545.29	-4.6669
1549.23	-5.64246
1553.16	-3.57227
1557.09	-1.26733
1561.02	0.435669
1564.94	1.94595
1568.87	2.96097
1572.79	3.18127
1576.71	2.85934
1580.63	2.664
1584.55	2.1875
1588.47	1.64853
1592.38	0.93396
1596.29	0.264343
1600.2	-0.283722
1604.11	-0.776215
1608.02	-0.660431
1611.92	0.106689
1615.83	1.47882
1619.73	5.49741
1623.63	6.78146
1627.53	7.26035
1631.42	8.18442
1635.32	9.52408
1639.21	9.34381
1643.1	9.09399
1646.99	8.50183
1650.88	7.99878
1654.76	7.32703
1658.64	4.79675
1662.53	4.6665
1666.41	4.48279
1670.28	4.16724
1674.16	4.22137
1678.04	5.12305
1681.91	7.40573
1685.78	9.1557
1689.65	10.0268
1693.52	9.69669
1697.38	7.35028
1701.25	4.98306
1705.11	2.79749
1708.97	0.97171
1712.83	2.58383
1716.69	5.28073
1720.54	8.6087
1724.4	9.22977
1728.25	8.71381
1732.1	8.49298
1735.95	8.88333
1739.79	10.2883
1743.64	11.7549
1747.48	12.515
1751.33	10.3104
1755.17	8.61819
1759	8.88916
1762.84	10.733
1766.68	10.5065
1770.51	11.445
1774.34	13.1096
1778.17	13.6584
1782	11.4308
1785.82	8.7316
1789.65	6.05142
1793.47	6.2616
1797.29	7.04807
1801.11	7.71292
1804.93	7.73822
1808.74	9.1835
1812.56	10.318
1816.37	10.7647
1820.18	10.8528
1823.99	10.9796
1827.79	12.4202
1831.6	12.8759
1835.4	12.6211
1839.2	12.6313
1843	12.225
1846.8	10.9484
1850.6	10.241
1854.39	10.0652
1858.19	10.9325
1861.98	12.5514
1865.77	14.1283
1869.56	15.5173
1873.34	16.5225
1877.13	16.4042
1880.91	16.86
1884.69	17.9291
1888.47	15.8858
1892.25	19.5565
1896.03	24.9387
1899.8	25.1898
1903.57	23.5416
1907.34	21.174
1911.11	18.5683
1914.88	16.6452
1918.65	15.6551
1922.41	14.4987
1926.18	12.7878
1929.94	9.99792
1933.7	7.0325
1937.45	4.58853
1941.21	2.80405
1944.96	1.80783
1948.72	1.22171
1952.47	0.95105
1956.22	1.44641
1959.96	2.22284
1963.71	3.84854
1967.45	5.15448
1971.2	6.02487
1974.94	6.8436
1978.68	5.85959
1982.42	4.05139
1986.15	2.25485
1989.89	1.20364
1993.62	1.02774
1997.35	1.31808
2001.08	1.75616
2004.8	2.71558
2008.53	4.37262
2012.25	6.32938
2015.98	8.12766
2019.7	10.1856
2023.42	12.8917
2027.13	14.5546
2030.85	15.9324
2034.56	14.8372
2038.28	13.4905
2041.99	12.2145
2045.7	10.984
2049.41	10.0572
2053.11	8.97363
2056.82	7.95279
2060.52	6.96835
2064.22	6.02933
2067.92	5.66388
2071.62	5.23758
2075.31	4.45084
2079.01	4.16843
2082.7	4.05646
2086.39	4.21805
2090.08	4.52386
2093.77	4.5907
2097.45	5.20541
2101.14	6.07675
2104.82	6.98633
2108.5	7.54965
2112.18	5.09775
2115.86	3.59039
2119.54	2.93011
2123.21	3.05597
2126.88	3.56726
2130.56	4.29434
2134.23	4.63651
2137.89	4.15384
2141.56	5.04059
2145.23	5.76321
2148.89	6.11682
2152.55	6.18234
2156.21	6.45294
2159.87	6.84399
2163.53	7.60773
2167.18	8.75299
2170.84	10.53
2174.49	14.0824
2178.14	12.0393
2181.79	11.3677
2185.44	12.1925
2189.08	13.7567
2192.73	16.5943
2196.37	19.312
2200.01	21.6746
2203.65	21.787
2207.29	19.7591
2210.92	17.3409
2214.56	15.0875
2218.19	12.8254
2221.82	11.0088
2225.45	10.0427
2229.08	9.67215
2232.7	9.91641
2236.33	10.6315
2239.95	10.954
2243.57	11.4194
2247.19	11.5134
2250.81	11.6071
2254.43	9.99393
2258.04	8.01193
2261.66	5.7952
2265.27	3.48419
2268.88	2.10233
2272.49	0.600128
2276.1	-0.604218
2279.7	-0.989563
2283.31	-1.09604
2286.91	-0.89798
2290.51	-0.534637
2294.11	-0.615112
2297.71	-2.99689
2301.3	-5.03876
2304.9	-4.65027
2308.49	-5.52985
2312.08	-2.86966
2315.67	5.10419
2319.26	25.2112
2322.85	40.7111
2326.43	43.2838
2330.02	37.8855
2333.6	25.4385
2337.18	16.1767
2340.76	9.30261
2344.34	4.8754
2347.91	3.11426
2351.49	3.41434
2355.06	5.37372
2358.63	6.85275
2362.2	9.08151
2365.77	11.5156
2369.33	13.7896
2372.9	15.7848
2376.46	17.3363
2380.02	18.5596
2383.58	18.3135
2387.14	18.4296
2390.7	18.0422
2394.25	17.2465
2397.81	16.6375
2401.36	16.4793
2404.91	15.6897
2408.46	14.1646
2412.01	11.5035
2415.56	8.27185
2419.1	5.5318
2422.64	4.07492
2426.18	2.88745
2429.72	3.65305
2433.26	5.01526
2436.8	6.39389
2440.34	7.91464
2443.87	9.17981
2447.4	9.98917
2450.93	9.26343
2454.46	8.55081
2457.99	7.21533
2461.52	5.78598
2465.04	5.34912
2468.56	6.32254
2472.09	8.05194
2475.61	9.41379
2479.13	10.8944
2482.64	12.1643
2486.16	12.8521
2489.67	12.7207
2493.18	11.4658
2496.69	11.3219
2500.2	11.9776
2503.71	12.9767
2507.22	13.8414
2510.72	14.2699
2514.23	14.5122
2517.73	14.5844
2521.23	14.4961
2524.73	14.5188
2528.23	13.3119
2531.72	12.1835
2535.21	11.6553
2538.71	12.0587
2542.2	13.8975
2545.69	15.8079
2549.18	15.8328
2552.66	15.1684
2556.15	13.6962
2559.63	11.4403
2563.12	9.55231
2566.6	10.5604
2570.08	9.85748
2573.55	8.80835
2577.03	7.56277
2580.5	6.36087
2583.98	6.29932
2587.45	6.23593
2590.92	6.15561
2594.39	6.14868
2597.86	6.62308
2601.32	6.3306
2604.79	4.90787
2608.25	3.1947
2611.71	2.70288
2615.17	2.46802
2618.63	1.72214
2622.08	1.03735
2625.54	1.55612
2628.99	-0.274811
2632.45	-1.63663
2635.9	0.184845
2639.35	2.02829
2642.79	4.30576
2646.24	6.64926
2649.69	9.7464
2653.13	8.17407
2656.57	6.48196
2660.01	5.45822
2663.45	5.65048
2666.89	8.88092
2670.32	10.8156
2673.76	11.8745
2677.19	9.60767
2680.62	7.37888
2684.05	5.90317
2687.48	5.21182
2690.91	5.64542
2694.33	6.53934
2697.76	7.80399
2701.18	9.96796
2704.6	12.3931
2708.02	13.9131
2711.44	14.7856
2714.86	14.1425
2718.27	13.2033
2721.69	12.3406
2725.1	11.8777
2728.51	13.0434
2731.92	13.6917
2735.33	13.997
2738.74	13.599
2742.14	12.1456
2745.55	10.3625
2748.95	11.9099
2752.35	11.8315
2755.75	11.2992
2759.15	9.47058
2762.54	8.29727
2765.94	6.93134
2769.33	5.85477
2772.72	4.27448
2776.12	2.72885
2779.51	3.05734
2782.89	3.30869
2786.28	5.3017
2789.67	7.65009
2793.05	7.63449
2796.43	6.89383
2799.81	6.87302
2803.19	7.6113
2806.57	8.90619
2809.95	10.8467
2813.32	13.6133
2816.69	16.8808
2820.06	19.567
2823.44	20.4048
2826.81	18.3659
2830.17	17.9215
2833.54	17.703
2836.9	17.4276
2840.27	17.3024
2843.63	17.5404
2846.99	17.7688
2850.35	18.1609
2853.71	18.7891
2857.06	19.3018
2860.42	19.6583
2863.77	19.7675
2867.12	19.3023
2870.48	18.5378
2873.83	17.4665
2877.17	16.1002
2880.52	14.5694
2883.86	12.9233
2887.21	11.3212
2890.55	9.69623
2893.89	8.67352
2897.23	7.52173
2900.57	6.1442
2903.91	5.00156
2907.24	5.70679
2910.57	8.22791
2913.91	9.82214
2917.24	9.68423
2920.57	8.85266
2923.9	7.51965
2927.22	6.08179
2930.55	4.74884
2933.87	3.55313
2937.19	3.18994
2940.51	4.04077
2943.83	6.90445
2947.15	10.5776
2950.47	13.708
2953.79	15.6825
2957.1	14.1272
2960.41	11.4619
2963.72	9.02252
2967.03	6.23236
2970.34	4.65955
2973.65	4.87231
2976.95	6.349
2980.26	7.62866
2983.56	9.76373
2986.86	8.62173
2990.16	6.57111
2993.46	4.48444
2996.76	2.2962
3000.06	1.11713
3003.35	1.08832
3006.64	3.50156
3009.94	6.20151
3013.23	8.03702
3016.51	7.86823
3019.8	6.84906
3023.09	5.01129
3026.38	3.37704
3029.66	2.48724
3032.94	2.43494
3036.22	3.3226
3039.5	4.82693
3042.78	3.94
3046.05	11.8181
3049.33	15.6297
3052.6	15.037
3055.88	12.9845
3059.15	8.87622
3062.42	8.27396
3065.69	8.62595
3068.95	9.09256
3072.22	9.5524
3075.48	9.93182
3078.75	9.32327
3082.01	8.12943
3085.27	7.60278
3088.53	6.16428
3091.79	15.3604
3095.04	15.1372
3098.3	1.71329
3101.55	-2.32849
3104.8	-5.16196
3108.05	-0.96109
3111.3	4.24481
3114.55	7.05881
3117.8	7.48587
3121.04	6.76791
3124.29	7.76639
3127.53	10.2622
3130.77	13.15
3134.01	13.1752
3137.25	12.8708
3140.49	12.1748
3143.72	11.3361
3146.96	10.5889
3150.19	9.86365
3153.42	10.904
3156.65	11.5037
3159.88	11.8209
3163.11	11.4608
3166.34	10.8487
3169.56	10.1797
3172.79	9.81488
3176.01	9.61823
3179.23	9.61401
3182.45	9.96265
3185.67	9.12497
3188.88	7.89441
3192.1	6.57117
3195.31	5.45822
3198.53	4.26147
3201.74	6.0126
3204.95	7.84528
3208.16	9.68686
3211.37	11.1768
3214.57	12.5869
3217.78	12.911
3220.98	12.5378
3224.18	11.9865
3227.39	11.5905
3230.59	9.63062
3233.78	9.79898
3236.98	7.89828
3240.18	9.5303
3243.37	12.4108
3246.56	14.1282
3249.76	14.3056
3252.95	12.3806
3256.14	10.6201
3259.32	9.70648
3262.51	9.02795
3265.7	8.5137
3268.88	7.90491
3272.06	4.8757
3275.24	6.05194
3278.42	7.67676
3281.6	6.09872
3284.78	1.60181
3287.96	0.686615
3291.13	1.08914
3294.31	4.36511
3297.48	9.76154
3300.65	11.5622
3303.82	11.8539
3306.99	11.4206
3310.15	10.3348
3313.32	8.99756
3316.48	7.41214
3319.65	7.84622
3322.81	10.7517
3325.97	14.303
3329.13	17.719
3332.28	19.9296
3335.44	20.9253
3338.6	21.35
3341.75	21.453
3344.9	20.9775
3348.05	21.4128
3351.2	22.5344
3354.35	24.2046
3357.5	25.5427
3360.65	25.9978
3363.79	25.3207
3366.94	23.3994
3370.08	21.0152
3373.22	18.9742
3376.36	20.8278
3379.5	25.7672
3382.63	31.1831
3385.77	36.8261
3388.9	42.4685
3392.04	48.0314
3395.17	53.2243
3398.3	57.3975
3401.43	66.1148
3404.56	71.1582
3407.69	79.1194
3410.81	101.903
3413.94	124.374
3417.06	269.732
3420.18	505.597
3423.3	1115.47
3426.42	1857.34
3429.54	1860.21
3432.65	1188.08
3435.77	518.383
3438.88	271.386
3442	173.064
3445.11	125.902
3448.22	97.1049
3451.33	84.2152
3454.43	77.5553
3457.54	73.7733
3460.65	73.1019
3463.75	75.2823
3466.85	77.7796
3469.95	83.6942
3473.05	94.4865
3476.15	106.079
3479.25	124.554
3482.35	149.51
3485.44	189.478
3488.54	249.989
3491.63	324.984
3494.72	417
3497.81	554.998
3500.9	748.106
3503.99	1083.49
3507.07	1344.88
3510.16	1512.18
3513.24	1348.71
3516.32	1075.07
3519.41	804.259
3522.49	589.327
3525.56	432.069
3528.64	333.244
3531.72	244.613
3534.79	189.741
3537.87	149.181
3540.94	129.012
3544.01	113.465
3547.08	100.236
3550.15	88.6954
3553.22	78.5375
3556.28	69.1123
3559.35	60.8472
3562.41	54.203
3565.47	48.5208
3568.54	44.3588
3571.6	41.1846
3574.65	38.8577
3577.71	37.1182
3580.77	35.3199
3583.82	34.0229
3586.88	31.2235
3589.93	28.425
3592.98	25.0347
3596.03	21.7656
3599.08	19.2681
3602.13	18.1349
3605.18	18.2863
3608.22	19.144
3611.27	19.7011
3614.31	19.8082
3617.35	19.4702
3620.39	18.4295
3623.43	17.6678
3626.47	16.9657
3629.5	15.761
3632.54	14.9131
3635.57	14.2525
3638.61	14.4698
3641.64	14.4145
3644.67	15.0459
3647.7	12.6566
3650.73	11.2715
3653.75	10.6393
3656.78	9.66248
3659.8	8.05316
3662.83	5.67386
3665.85	5.45026
3668.87	5.95499
3671.89	8.13861
3674.91	9.85443
3677.92	11.6362
3680.94	12.5796
3683.96	12.1614
3686.97	9.7486
3689.98	6.63864
3692.99	3.26935
3696	0.935547
3699.01	0.172852
3702.02	0.333282
3705.02	1.84155
3708.03	3.32098
3711.03	3.91388
3714.03	4.39816
3717.04	4.77847
3720.04	4.52698
3723.04	4.2793
3726.03	4.03391
3729.03	4.82153
3732.03	5.82138
3735.02	6.34741
3738.01	6.57132
3741	7.76361
3743.99	6.88129
3746.98	6.09781
3749.97	5.62234
3752.96	5.7673
3755.95	6.49484
3758.93	8.28519
3761.91	11.8541
3764.9	12.3325
3767.88	11.4142
3770.86	9.98743
3773.84	8.44058
3776.81	7.60172
3779.79	4.91614
3782.77	3.46637
3785.74	3.05542
3788.71	3.91394
3791.68	6.52618
3794.65	8.36526
3797.62	9.63
3800.59	10.4945
3803.56	10.6772
3806.52	12.2234
3809.49	12.4145
3812.45	12.1336
3815.41	11.5371
3818.37	10.1253
3821.33	9.68961
3824.29	10.0401
3827.25	10.0432
3830.21	9.62787
3833.16	10.6137
3836.11	12.3741
3839.07	12.9549
3842.02	11.1336
3844.97	7.62427
3847.92	4.18759
3850.87	3.32889
3853.81	4.36115
3856.76	5.09259
3859.7	6.31735
3862.65	7.94528
3865.59	9.78418
3868.53	9.0658
3871.47	6.38895
3874.41	3.20398
3877.34	0.87149
3880.28	-0.0678101
3883.22	-1.24707
3886.15	-1.46686
3889.08	-0.392426
3892.01	2.60663
3894.94	6.81912
3897.87	10.4666
3900.8	13.093
3903.73	14.9213
3906.65	15.6524
3909.58	15.1362
3912.5	13.9383
3915.42	13.4223
3918.35	14.4768
3921.27	15.0228
3924.18	16.0128
3927.1	16.6544
3930.02	14.9642
3932.93	12.9007
3935.85	10.7309
3938.76	9.11505
3941.67	7.80215
3944.58	8.41443
3947.49	10.304
3950.4	13.7287
3953.31	14.8367
3956.22	16.415
3959.12	14.1619
3962.02	11.7988
3964.93	10.1472
3967.83	9.75107
3970.73	11.6025
3973.63	13.6752
3976.53	15.6016
3979.42	17.4286
3982.32	18.7028
3985.21	20.0421
3988.11	18.4063
3991	16.8608
3993.89	13.6478
3996.78	6.95401
3999.67	1.12714