File: Data/3-Raman/processed/bu20-b-ff4-fi03-l_150 (500nm)_633nm_edge_100%_x100_vis_lwd_h30um_60sx4_01.txt
#Acq. time (s)=	60
#Accumulations=	4
#Range (cm-¹)=	100...4000
#Windows=	1
#Auto scanning=	Off
#Autofocus=	Off
#Macrospot=	Off
#AutoExposure=	Off
#Spike filter=	Multiple accum.
#Delay time (s)=	2
#Binning=	1
#Readout mode=	Signal
#DeNoise=	Off
#ICS correction=	On
#Dark correction=	Off
#Inst. Process=	Off
#Detector Gain=	Best Dynamic
#Detector ADC=	50 kHz HS
#Detector temperature (°C)=	-60.09
#Instrument=	LabRAM HR Evol
#Detector=	SIN-EM FIVIS
#Objective=	x100_VIS_LWD
#Grating=	150 (500nm)
#ND Filter=	100%
#Laser=	633nm_Edge
#Hole=	30.0125
#Temperature=	39.9
#Range=	Visible
#StageXY=	75x50mm Scan+
#StageZ=	Z motor
#X (µm)=	0
#Y (µm)=	0
#Z (µm)=	-0.2
#Full time(mm:ss)=	4:05
#Project=	21_08_11
#Sample=	BU20
#Site=
#Title=	BU20-B-FF4-FI03-L_150 (500nm)_633nm_Edge_100%_x100_VIS_LWD_H30um_60sX4
#Remark=
#Date=	13.08.2021 14:27
#Acquired=	13.08.2021 14:27:06
#Data Range:Extract=	16.12.2021 15:36:30
#Base:Fit=	16.12.2021 15:36:40
#Base:Edit=	16.12.2021 15:53:13
#Base:Edit=	16.12.2021 15:53:14
#Base:Edit=	16.12.2021 15:53:15
#Base:Edit=	16.12.2021 15:53:16
#Base:Edit=	16.12.2021 15:53:17
#Base:Sub=	16.12.2021 15:53:21
100.12	84.5963
106.638	79.3376
113.152	66.4596
119.66	55.4058
126.162	48.1258
132.659	45.8964
139.151	42.3043
145.637	34.2376
152.118	30.9519
158.594	33.7587
165.064	27.2981
171.529	15.9774
177.989	10.9587
184.441	15.7478
190.89	0.0316467
197.334	4.71947
203.772	9.83167
210.205	5.07499
216.631	3.8037
223.054	24.4303
229.471	68.0707
235.881	79.2906
242.288	36.9923
248.689	24.5895
255.083	23.2048
261.474	43.0269
267.858	57.1523
274.238	100.064
280.613	119.563
286.982	86.8338
293.346	42.068
299.704	18.4932
306.058	13.2127
312.406	19.5888
318.749	57.4145
325.086	106.585
331.418	65.8119
337.746	25.3597
344.068	15.0846
350.384	24.2584
356.697	31.4903
363.003	41.1865
369.304	33.6185
375.601	11.6589
381.892	9.43584
388.177	4.80319
394.457	0.260551
400.733	7.07371
407.004	4.15733
413.269	11.902
419.529	16.7748
425.784	36.3487
432.034	66.6018
438.279	69.6804
444.518	71.1527
450.753	65.3647
456.982	53.7311
463.207	27.6517
469.426	20.3618
475.64	14.387
481.85	7.51359
488.054	7.76267
494.253	11.4352
500.447	8.88509
506.635	11.9474
512.819	5.37667
518.999	8.47189
525.173	4.45074
531.342	5.45433
537.505	5.23605
543.664	4.0086
549.819	5.82871
555.966	9.52124
562.111	8.35327
568.25	6.15993
574.383	7.34002
580.513	8.15938
586.636	24.5883
592.756	52.5342
598.871	70.5986
604.979	45.7121
611.084	41.6757
617.183	43.9516
623.277	51.6097
629.367	49.8563
635.451	44.3983
641.532	39.6932
647.606	39.9063
653.675	62.3049
659.741	58.6063
665.801	42.479
671.856	26.5021
677.907	14.7819
683.952	6.78989
689.992	1.03785
696.028	-0.320679
702.059	5.8086
708.086	3.46786
714.107	4.13104
720.123	0.0553284
726.135	1.60396
732.141	1.20988
738.143	3.92935
744.14	3.84464
750.133	2.54113
756.12	2.21388
762.103	-0.806335
768.081	0.297131
774.054	2.97922
780.023	2.50049
785.987	3.53171
791.946	0.444618
797.9	3.90888
803.848	2.91234
809.793	1.57236
815.733	1.75759
821.669	6.28955
827.6	7.66769
833.525	8.50761
839.446	6.96407
845.363	6.11386
851.273	5.27137
857.181	6.01231
863.083	3.62267
868.98	8.78384
874.874	5.69202
880.761	12.6525
886.645	5.02662
892.523	11.903
898.398	8.92714
904.267	7.77432
910.133	13.525
915.992	14.8576
921.849	10.3242
927.699	22.1573
933.545	19.9868
939.387	33.0215
945.224	46.8259
951.056	65.2048
956.884	73.1698
962.708	71.1969
968.526	90.8502
974.34	121.319
980.149	166.253
985.955	207.375
991.755	186.427
997.551	144.208
1003.34	119.372
1009.13	130.937
1014.91	154.536
1020.69	192.83
1026.46	178.555
1032.23	109.293
1037.99	71.1534
1043.75	57.2378
1049.51	51.282
1055.26	40.3608
1061	35.8042
1066.74	39.8771
1072.48	41.9829
1078.21	54.7223
1083.94	52.8715
1089.67	64.932
1095.38	82.4731
1101.1	72.8906
1106.81	39.2364
1112.51	27.2116
1118.22	23.7447
1123.91	17.2676
1129.6	24.4237
1135.29	25.0939
1140.98	38.5238
1146.65	46.6937
1152.33	57.1506
1158	37.9482
1163.66	20.6212
1169.32	11.1752
1174.98	15.1407
1180.63	9.64457
1186.28	6.49658
1191.93	8.60929
1197.56	5.89331
1203.2	3.88819
1208.83	4.53242
1214.46	4.53674
1220.08	5.2301
1225.69	3.27777
1231.31	5.9649
1236.92	4.27542
1242.52	8.90715
1248.12	10.1287
1253.72	2.21031
1259.31	6.69436
1264.89	8.44032
1270.48	7.82747
1276.05	6.18082
1281.63	9.88034
1287.2	4.24972
1292.76	11.6557
1298.33	3.77105
1303.88	4.58019
1309.43	5.44869
1314.98	6.04689
1320.53	5.31658
1326.07	0.890778
1331.6	5.23974
1337.13	4.83725
1342.66	5.42094
1348.18	2.2145
1353.7	4.79674
1359.22	4.61778
1364.73	5.77548
1370.23	8.27296
1375.73	14.1866
1381.23	4.34895
1386.72	5.46319
1392.21	3.50962
1397.7	-2.84252
1403.18	5.19757
1408.65	3.65788
1414.13	5.56585
1419.59	3.00969
1425.06	4.59816
1430.52	1.69093
1435.97	2.58741
1441.42	3.48078
1446.87	4.73146
1452.31	5.59191
1457.75	0.121769
1463.19	2.67325
1468.62	5.55821
1474.04	3.89549
1479.46	6.10169
1484.88	2.71775
1490.3	2.50206
1495.7	5.81828
1501.11	1.06905
1506.51	-0.163261
1511.91	3.91614
1517.3	1.65059
1522.69	0.8008
1528.08	6.01857
1533.46	4.11737
1538.83	5.40908
1544.21	6.31412
1549.58	1.73933
1554.94	1.79651
1560.3	6.15453
1565.66	5.47996
1571.01	5.87996
1576.36	7.36304
1581.7	4.93518
1587.04	11.4905
1592.38	0.82933
1597.71	3.47195
1603.04	7.93777
1608.37	7.39461
1613.68	6.52197
1619	6.03233
1624.31	8.45868
1629.62	8.33508
1634.93	8.92474
1640.23	3.92693
1645.52	9.22795
1650.81	8.99292
1656.1	7.63194
1661.39	10.3129
1666.67	3.00517
1671.94	5.67159
1677.22	6.11212
1682.48	3.95797
1687.75	5.10692
1693.01	1.47195
1698.26	5.2546
1703.52	5.48158
1708.77	3.49703
1714.01	1.65672
1719.25	5.55622
1724.49	4.94385
1729.72	5.47157
1734.95	5.99915
1740.18	6.5231
1745.4	2.90932
1750.61	3.78793
1755.83	3.14663
1761.04	3.61219
1766.24	4.45332
1771.44	3.03571
1776.64	2.00173
1781.84	0.228371
1787.02	1.49321
1792.21	4.29999
1797.39	1.78964
1802.57	2.71743
1807.75	0.199486
1812.92	3.7934
1818.08	5.8651
1823.25	3.70288
1828.41	3.0804
1833.56	3.2331
1838.71	2.99627
1843.86	0.0163021
1849	2.47386
1854.14	2.19568
1859.28	-1.19885
1864.41	3.62558
1869.54	2.19583
1874.67	3.48905
1879.79	-1.12232
1884.9	4.88336
1890.02	2.21268
1895.13	3.85583
1900.23	-0.00453377
1905.34	0.9049
1910.43	0.251089
1915.53	2.80152
1920.62	1.72748
1925.71	4.64118
1930.79	2.37672
1935.87	3.69896
1940.94	-0.195072
1946.02	3.91306
1951.08	1.59391
1956.15	5.68552
1961.21	8.96959
1966.27	3.40777
1971.32	1.84708
1976.37	3.49462
1981.42	1.52969
1986.46	4.37963
1991.5	-3.18882
1996.53	1.27205
2001.56	5.33986
2006.59	2.20583
2011.61	3.49079
2016.63	3.57478
2021.65	2.44516
2026.66	4.95186
2031.67	7.47935
2036.68	2.35855
2041.68	4.90298
2046.68	2.19358
2051.67	5.16027
2056.66	3.64296
2061.65	4.99269
2066.63	3.07981
2071.61	8.52418
2076.59	5.7811
2081.56	5.89803
2086.53	5.17832
2091.49	3.62881
2096.46	5.81455
2101.41	0.974085
2106.37	3.17658
2111.32	4.98142
2116.26	5.13369
2121.21	4.8661
2126.15	7.95383
2131.09	6.41398
2136.02	4.85506
2140.95	2.8571
2145.87	6.78488
2150.79	4.75924
2155.71	0.587934
2160.63	3.63806
2165.54	3.69619
2170.45	2.46957
2175.35	0.401724
2180.25	0.879704
2185.15	2.19656
2190.04	4.80126
2194.93	3.57685
2199.82	4.07665
2204.7	5.44747
2209.58	4.69019
2214.46	4.79769
2219.33	2.32909
2224.2	3.73697
2229.06	7.74948
2233.92	6.57059
2238.78	4.07817
2243.64	3.75412
2248.49	4.74166
2253.34	4.41406
2258.18	2.76721
2263.02	3.31222
2267.86	5.16926
2272.69	4.80646
2277.52	6.20249
2282.35	4.48326
2287.17	0.528448
2291.99	2.77987
2296.81	3.25826
2301.62	4.19573
2306.43	1.59486
2311.24	5.68275
2316.04	4.88688
2320.84	4.0952
2325.63	2.85067
2330.43	1.60321
2335.21	4.41895
2340	4.53699
2344.78	5.11767
2349.56	3.88444
2354.33	5.37717
2359.11	4.56385
2363.87	0.962471
2368.64	3.34199
2373.4	7.11147
2378.16	3.95479
2382.91	6.32754
2387.66	4.05164
2392.41	1.75901
2397.16	0.381989
2401.9	3.17635
2406.64	4.10688
2411.37	3.21791
2416.1	3.78705
2420.83	3.94533
2425.55	3.99662
2430.27	5.01861
2434.99	4.64221
2439.7	4.7429
2444.41	3.41819
2449.12	3.98802
2453.83	3.60465
2458.53	1.78209
2463.22	3.30558
2467.92	8.68091
2472.61	0.572901
2477.3	2.57843
2481.98	4.59116
2486.66	3.20107
2491.34	3.74717
2496.01	13.5659
2500.68	3.86486
2505.35	1.46718
2510.01	3.46844
2514.67	-0.917013
2519.33	5.99738
2523.99	2.10409
2528.64	3.12733
2533.28	7.12223
2537.93	4.70426
2542.57	7.73671
2547.21	4.32356
2551.84	9.3652
2556.47	2.93743
2561.1	3.98619
2565.73	1.54075
2570.35	4.11604
2574.97	5.19233
2579.58	3.73687
2584.19	5.29242
2588.8	1.26492
2593.41	6.34311
2598.01	-0.219891
2602.61	3.87001
2607.2	4.90961
2611.8	6.45168
2616.38	2.89315
2620.97	-1.1788
2625.55	4.96238
2630.13	3.45694
2634.71	2.99563
2639.28	2.0416
2643.85	5.21127
2648.42	2.70934
2652.98	3.82284
2657.54	0.222662
2662.1	2.33238
2666.65	0.784176
2671.2	2.90522
2675.75	1.92307
2680.29	5.20687
2684.84	0.572659
2689.37	3.33528
2693.91	5.03113
2698.44	3.99361
2702.97	5.11176
2707.49	5.15287
2712.02	3.57574
2716.53	0.930374
2721.05	4.74084
2725.56	4.76981
2730.07	-2.24738
2734.58	0.460079
2739.08	3.70796
2743.58	2.63872
2748.08	3.20681
2752.57	2.72553
2757.06	-1.0498
2761.55	2.79656
2766.04	3.38066
2770.52	5.0645
2775	5.66644
2779.47	2.97797
2783.94	0.847052
2788.41	-0.743593
2792.88	0.99321
2797.34	-0.0636883
2801.8	0.54579
2806.26	-0.53686
2810.71	1.74488
2815.16	1.20906
2819.61	2.92585
2824.05	3.52229
2828.49	2.98891
2832.93	6.41771
2837.37	-0.933737
2841.8	-1.48179
2846.23	-0.886219
2850.65	3.7116
2855.08	7.20158
2859.5	0.964649
2863.91	3.90481
2868.33	3.41216
2872.74	2.33515
2877.15	2.99507
2881.55	3.66657
2885.95	3.18159
2890.35	4.44711
2894.75	3.36342
2899.14	2.87746
2903.53	17.7847
2907.91	2.4545
2912.3	2.52044
2916.68	2.57517
2921.05	4.43517
2925.43	2.10826
2929.8	0.981443
2934.17	11.92
2938.53	3.52534
2942.9	0.54376
2947.26	2.39902
2951.61	3.6509
2955.97	1.86148
2960.32	1.28632
2964.66	2.54624
2969.01	2.59425
2973.35	2.03275
2977.69	3.92629
2982.03	3.37003
2986.36	5.29283
2990.69	4.76065
2995.01	3.6102
2999.34	2.46123
3003.66	6.30523
3007.98	-0.467575
3012.29	8.41172
3016.6	5.38659
3020.91	6.14262
3025.22	1.17666
3029.52	9.52892
3033.82	5.1527
3038.12	9.0472
3042.41	3.3695
3046.71	5.99571
3051	7.98613
3055.28	8.05502
3059.56	11.3507
3063.84	1.08958
3068.12	5.03084
3072.39	8.98609
3076.67	6.46471
3080.93	7.83928
3085.2	13.139
3089.46	11.9447
3093.72	10.1073
3097.98	14.1909
3102.23	12.3631
3106.48	11.1992
3110.73	11.364
3114.98	19.543
3119.22	12.3729
3123.46	17.2709
3127.7	20.1938
3131.93	19.7647
3136.16	18.6479
3140.39	18.1934
3144.61	24.604
3148.84	21.372
3153.06	23.6332
3157.27	18.9354
3161.49	28.165
3165.7	22.7467
3169.91	28.5079
3174.11	27.2794
3178.31	23.1747
3182.51	27.5076
3186.71	35.3748
3190.9	31.2205
3195.1	31.3441
3199.28	30.099
3203.47	36.0375
3207.65	32.7284
3211.83	43.7796
3216.01	34.7276
3220.18	40.8067
3224.36	44.7446
3228.52	30.4455
3232.69	27.7627
3236.85	39.0234
3241.01	37.0939
3245.17	35.9186
3249.33	39.9092
3253.48	40.1269
3257.63	36.5618
3261.77	40.558
3265.92	43.1124
3270.06	41.1865
3274.2	48.3458
3278.33	43.1848
3282.47	46.4105
3286.59	41.994
3290.72	45.9896
3294.85	46.1466
3298.97	37.8377
3303.09	41.0856
3307.2	38.9299
3311.32	36.7546
3315.43	53.1847
3319.54	43.263
3323.64	48.9065
3327.74	49.91
3331.84	43.9064
3335.94	48.9042
3340.04	46.0094
3344.13	45.4041
3348.22	56.6378
3352.3	73.4735
3356.39	53.0349
3360.47	51.6443
3364.54	60.6251
3368.62	50.4323
3372.69	62.636
3376.76	61.9996
3380.83	69.3825
3384.89	63.0882
3388.96	67.246
3393.02	68.9781
3397.07	64.2837
3401.13	73.331
3405.18	74.252
3409.23	59.7763
3413.27	68.7811
3417.31	69.6862
3421.36	70.585
3425.39	76.3588
3429.43	74.039
3433.46	79.888
3437.49	62.9274
3441.52	72.9129
3445.54	61.6636
3449.56	65.1838
3453.58	67.9068
3457.6	66.5644
3461.61	68.554
3465.63	56.4118
3469.63	57.5375
3473.64	67.8197
3477.64	64.751
3481.64	65.0265
3485.64	58.5307
3489.64	62.1532
3493.63	56.4403
3497.62	60.8847
3501.61	63.6166
3505.59	49.232
3509.58	59.5745
3513.56	60.4789
3517.53	51.9546
3521.51	64.8449
3525.48	49.4558
3529.45	45.1953
3533.42	46.9983
3537.38	49.7189
3541.34	46.4225
3545.3	33.5625
3549.26	37.9613
3553.21	37.105
3557.16	35.4031
3561.11	41.5324
3565.06	47.6993
3569	39.1197
3572.94	37.475
3576.88	38.4707
3580.82	49.1524
3584.75	45.8238
3588.68	39.821
3592.61	40.863
3596.54	32.1394
3600.46	29.5828
3604.38	22.5414
3608.3	27.9769
3612.21	24.4562
3616.13	28.107
3620.04	23.6586
3623.94	21.8541
3627.85	19.1301
3631.75	19.0951
3635.65	15.4568
3639.55	19.0623
3643.44	19.996
3647.34	9.15993
3651.23	16.3825
3655.12	15.457
3659	12.7042
3662.88	13.5792
3666.76	9.90877
3670.64	10.7909
3674.52	8.94263
3678.39	7.10746
3682.26	6.19573
3686.13	9.88991
3689.99	6.2363
3693.85	3.48308
3697.71	12.7521
3701.57	7.2123
3705.43	2.56857
3709.28	7.24507
3713.13	4.45207
3716.98	7.26253
3720.82	4.4321
3724.66	4.40992
3728.5	0.60614
3732.34	-1.31609
3736.18	2.44044
3740.01	2.40943
3743.84	3.32333
3747.67	4.23457
3751.49	5.13835
3755.32	2.21693
3759.14	3.10105
3762.96	4.93649
3766.77	1.03851
3770.58	4.79598
3774.4	2.82158
3778.2	3.72007
3782.01	14.2259
3785.81	1.71531
3789.61	2.63173
3793.41	8.37296
3797.21	16.0823
3801	1.57783
3804.79	1.56049
3808.58	7.3795
3812.37	-0.416546
3816.15	3.46254
3819.93	3.4458
3823.71	3.42398
3827.49	5.35794
3831.26	3.37933
3835.04	-3.52621
3838.8	-1.58422
3842.57	-4.56344
3846.34	9.24743
3850.1	0.29298
3853.86	5.19415
3857.62	0.186775
3861.37	9.04602
3865.12	2.08334
3868.87	-2.86205
3872.62	3.08964
3876.37	1.06888
3880.11	-0.950596
3883.85	3.01948
3887.59	-0.980045
3891.33	1.01856
3895.06	3.04965
3898.79	8.09263
3902.52	1.10442
3906.25	0.130527
3909.97	0.16428
3913.69	-2.81228
3917.41	3.31093
3921.13	2.38784
3924.84	1.46725
3928.56	-2.51286
3932.27	0.628632
3935.97	0.70908
3939.68	3.86771
3943.38	5.01281
3947.08	7.19197
3950.78	3.20478
3954.48	4.35359
3958.17	-0.680721
3961.86	3.55984
3965.55	2.6475
3969.24	-0.336149
3972.92	4.95645
3976.6	-1.10805
3980.29	5.23409
3983.96	0.208015
3987.64	4.49833
3991.31	3.63928
3994.98	1.77003
3998.65	3.02853