File: Data/3-Raman/processed/bu20-C-brt1-FI01-150-633-v.txt
#Acq. time (s)=	15
#Accumulations=	2
#Range (cm-¹)=	50...5000
#Windows=	2
#Auto scanning=	Off
#Autofocus=	Off
#Macrospot=	Off
#AutoExposure=	Off
#Spike filter=	Multiple accum.
#Delay time (s)=	0
#Binning=	1
#Readout mode=	Signal
#DeNoise=	Lite
#ICS correction=	Off
#Dark correction=	Off
#Inst. Process=	Off
#Detector temperature (°C)=	-60.09
#Instrument=	LabRAM HR Evol
#Detector=	SIN-EM FIVIS
#Objective=	x50_VIS_LWD
#Grating=	150 (500nm)
#ND Filter=	100%
#Laser=	633nm_Edge
#Hole=	30.0125
#Temperature=	0
#Range=	Visible
#StageXY=	75x50mm Scan+
#StageZ=	Z motor
#X (µm)=	7344.5
#Y (µm)=	4274.6
#Z (µm)=	-23.7
#Full time(mm:ss)=	1:37
#Project=	Buranga
#Sample=	BU18FA20_C
#Site=	C_Bertoss1
#Title=	20-C_brt1_FI01_150
#Remark=
#Date=	30.07.2019 14:13
#Acquired=	30.07.2019 14:13:00
#Data Range:Extract=	16.12.2021 15:36:30
#Base:Fit=	16.12.2021 15:36:40
#Base:Sub=	16.12.2021 15:37:11
99.0332	533.046
105.552	412.9
112.066	316.076
118.574	229.642
125.077	162.833
131.574	128.801
138.066	102.201
144.551	78.9572
151.033	60.3699
157.509	42.0944
163.979	51.6474
170.444	38.054
176.904	17.2829
183.357	6.22276
189.806	6.29321
196.25	10.1096
202.689	13.6283
209.121	4.09904
215.549	-0.0865479
221.971	0.898087
228.387	8.32991
234.799	20.8328
241.206	32.4895
247.606	22.5515
254.002	3.42175
260.392	4.13934
266.778	13.2906
273.157	21.8875
279.532	21.8331
285.9	28.1734
292.265	29.1197
298.623	24.269
304.978	14.5323
311.325	7.13913
317.669	8.746
324.007	18.1302
330.339	43.1845
336.667	41.6319
342.989	22.9196
349.306	15.0895
355.617	12.3313
361.925	15.2754
368.226	11.7952
374.522	5.2471
380.813	2.30991
387.099	4.7117
393.381	-0.505676
399.656	5.97723
405.927	16.9438
412.192	20.5792
418.452	11.0864
424.707	4.69348
430.957	8.3978
437.202	23.1352
443.442	29.1506
449.677	26.8746
455.907	37.6256
462.131	41.0735
468.351	32.6961
474.566	17.4559
480.774	9.04935
486.978	9.07364
493.178	11.1809
499.372	14.0557
505.562	19.2779
511.745	22.3404
517.924	20.2238
524.099	11.9522
530.268	7.85864
536.431	6.95447
542.591	6.11935
548.746	5.55646
554.894	5.56558
561.038	6.48529
567.177	10.7509
573.312	9.68744
579.44	7.31796
585.565	8.54605
591.685	13.2724
597.799	27.0002
603.907	41.4557
610.012	45.4036
616.111	43.4935
622.207	38.2173
628.296	33.1762
634.38	30.6995
640.461	30.4369
646.536	31.1236
652.605	31.6512
658.671	32.8483
664.731	33.1048
670.786	31.245
676.837	27.6664
682.882	25.455
688.924	24.8665
694.96	21.7106
700.991	17.4244
707.017	13.6467
713.038	11.2711
719.055	9.9191
725.066	8.68915
731.073	7.07584
737.075	5.31418
743.073	4.63278
749.065	5.03061
755.053	3.36362
761.036	18.9355
767.014	12.6478
772.988	7.76895
778.957	5.91971
784.919	8.51532
790.879	17.7454
796.833	17.3669
802.783	16.8542
808.727	18.5119
814.668	25.2501
820.603	29.1151
826.534	28.2865
832.459	23.434
838.381	14.4402
844.298	11.6461
850.209	15.0878
856.117	18.5529
862.018	20.7797
867.917	20.4863
873.809	19.4846
879.698	18.8393
885.581	19.6593
891.461	20.6408
897.334	20.9839
903.203	22.3709
909.069	22.6087
914.929	20.4095
920.786	12.9199
926.636	10.7766
932.482	20.7951
938.324	28.8432
944.162	33.9215
949.995	34.9655
955.822	36.5726
961.645	40.3458
967.464	45.7659
973.279	51.9702
979.089	63.9733
984.894	82.6671
990.694	116.872
996.49	110.515
1002.28	87.4097
1008.07	75.3466
1013.85	74.9929
1019.63	83.7808
1025.4	88.7249
1031.17	87.1584
1036.93	75.1688
1042.69	60.5653
1048.45	41.8626
1054.2	29.5936
1059.94	26.2948
1065.69	31.952
1071.42	33.9036
1077.16	29.5874
1082.88	27.5638
1088.61	31.0725
1094.33	40.4882
1100.04	50.7052
1105.75	57.3737
1111.46	47.72
1117.16	34.4613
1122.85	27.4124
1128.55	27.5925
1134.23	30.164
1139.92	33.7151
1145.6	36.9943
1151.27	38.7608
1156.94	38.013
1162.61	35.2878
1168.27	31.1232
1173.92	27.5919
1179.58	25.4704
1185.23	24.988
1190.87	25.0811
1196.51	25.0902
1202.14	26.4186
1207.77	25.5176
1213.4	20.631
1219.02	18.9542
1224.64	19.5467
1230.25	20.3996
1235.86	16.7588
1241.47	10.0359
1247.07	13.7142
1252.66	23.2653
1258.25	32.8096
1263.84	41.728
1269.42	47.6195
1275	55.3007
1280.58	256.457
1286.15	241.305
1291.71	36.1477
1297.27	22.9841
1302.83	51.8142
1308.38	10.9345
1313.93	20.7622
1319.47	31.4578
1325.01	26.6518
1330.55	20.0005
1336.08	24.4224
1341.61	27.197
1347.13	23.8686
1352.65	22.323
1358.16	24.0143
1363.67	30.3264
1369.18	47.6017
1374.68	35.9596
1380.18	50.8521
1385.67	641.528
1391.16	178.26
1396.65	27.2556
1402.13	47.0769
1407.6	66.5075
1413.07	47.5547
1418.54	23.4211
1424.01	12.5668
1429.47	10.4422
1434.92	15.1537
1440.37	17.9265
1445.82	15.5267
1451.26	9.66963
1456.7	5.94429
1462.14	9.26291
1467.57	11.2004
1472.99	9.72356
1478.42	9.33626
1483.83	12.8143
1489.25	17.7421
1494.66	20.3951
1500.06	20.6562
1505.46	18.7595
1510.86	14.2214
1516.26	9.19572
1521.64	5.77524
1527.03	7.2991
1532.41	8.3447
1537.79	5.30199
1543.16	6.32394
1548.53	10.1746
1553.89	19.5499
1559.25	16.7093
1564.61	7.64009
1569.96	4.13274
1575.31	7.17924
1580.66	11.7224
1586	10.3271
1591.33	9.16901
1596.67	7.04396
1601.99	9.09473
1607.32	12.0699
1612.64	11.2832
1617.96	8.64194
1623.27	5.84193
1628.58	3.98662
1633.88	1.81294
1639.18	1.83525
1644.48	8.40749
1649.77	10.8631
1655.06	3.85808
1660.34	-0.387466
1665.62	2.96951
1670.9	11.3286
1676.17	21.0315
1681.44	23.9836
1686.7	21.8551
1691.96	13.9149
1697.22	8.68245
1702.47	5.86559
1707.72	6.58076
1712.97	10.3376
1718.21	10.9655
1723.45	9.19263
1728.68	7.68274
1733.91	12.7732
1739.13	18.5928
1744.35	18.1321
1749.57	10.2426
1754.78	6.85715
1759.99	8.97215
1765.2	9.94038
1770.4	9.31207
1775.6	8.33392
1780.79	7.62459
1785.98	9.74231
1791.17	7.08646
1796.35	5.00798
1801.53	4.40565
1806.71	5.31122
1811.88	6.918
1817.04	7.4216
1822.21	4.79541
1827.37	8.51637
1832.52	11.2733
1837.67	12.3533
1842.82	11.7392
1847.96	9.9976
1853.1	7.74713
1858.24	4.53362
1863.37	1.67097
1868.5	3.02794
1873.63	5.48143
1878.75	7.85692
1883.86	10.5022
1888.98	7.3847
1894.09	4.10046
1899.19	0.760727
1904.3	3.51878
1909.39	5.74524
1914.49	6.46896
1919.58	4.93564
1924.67	3.73703
1929.75	3.17598
1934.83	2.53244
1939.91	2.42812
1944.98	3.49194
1950.05	5.19484
1955.11	7.39677
1960.17	5.63852
1965.23	-0.334244
1970.28	2.32549
1975.33	6.90697
1980.38	11.5267
1985.42	9.5069
1990.46	5.58554
1995.49	4.76155
2000.53	7.54518
2005.55	12.64
2010.58	15.2065
2015.6	15.0748
2020.61	11.8494
2025.63	6.15091
2030.63	5.37816
2035.64	6.48477
2040.64	7.59045
2045.64	8.7337
2050.63	10.9414
2055.63	15.7998
2060.61	13.4503
2065.6	7.3936
2070.57	0.432068
2075.55	2.14072
2080.52	8.93033
2085.49	11.8143
2090.46	11.7401
2095.42	9.75818
2100.38	6.85316
2105.33	4.46358
2110.28	3.38042
2115.23	3.6758
2120.17	4.04216
2125.11	4.28992
2130.05	4.34541
2134.98	4.16898
2139.91	3.67935
2144.84	2.93919
2149.76	5.71251
2154.68	5.78674
2159.59	3.79974
2164.5	2.86533
2169.41	4.53535
2174.32	6.26367
2179.22	7.31406
2184.11	7.67688
2189.01	7.00894
2193.9	5.81583
2198.78	4.58643
2203.67	4.08632
2208.55	4.5589
2213.42	6.74991
2218.29	10.632
2223.16	9.25356
2228.03	6.0294
2232.89	4.73888
2237.75	4.89883
2242.6	5.5037
2247.45	6.992
2252.3	8.2706
2257.15	8.49628
2261.99	5.97379
2266.82	4.53777
2271.66	6.72913
2276.49	8.26376
2281.32	8.0507
2286.14	5.65127
2290.96	1.77649
2295.78	6.60419
2300.59	14.5654
2305.4	10.1574
2310.2	7.61314
2315.01	7.765
2319.81	11.1887
2324.6	18.5526
2329.39	22.4424
2334.18	9.46436
2338.97	0.549789
2343.75	6.7916
2348.53	11.4554
2353.3	13.075
2358.07	12.0619
2362.84	9.10864
2367.61	11.6569
2372.37	12.2941
2377.13	9.65403
2381.88	6.37479
2386.63	6.9607
2391.38	6.4287
2396.13	4.394
2400.87	4.11137
2405.61	6.12118
2410.34	8.3288
2415.07	9.11559
2419.8	9.7425
2424.52	10.539
2429.24	10.8691
2433.96	9.21378
2438.68	6.51687
2443.39	5.56792
2448.09	7.9491
2452.8	12.4887
2457.5	15.7643
2462.19	15.9034
2466.89	12.4992
2471.58	5.35882
2476.27	7.71583
2480.95	7.48426
2485.63	5.63791
2490.31	6.54478
2494.98	8.14827
2499.65	10.6728
2504.32	13.7823
2508.99	16.1595
2513.65	1.49396
2518.3	2.95244
2522.96	6.51719
2527.61	9.04929
2532.26	13.8432
2536.9	18.384
2541.54	5.85464
2546.18	5.13764
2550.82	5.08208
2555.45	5.42193
2560.08	6.4007
2564.7	7.9899
2569.32	9.47082
2573.94	9.73569
2578.55	12.9614
2583.17	10.4425
2587.78	5.3024
2592.38	6.51087
2596.98	12.3453
2601.58	17.2479
2606.18	14.2243
2610.77	5.87378
2615.36	9.19477
2619.94	12.9707
2624.53	13.5124
2629.11	9.69109
2633.68	9.02425
2638.26	11.796
2642.83	14.0821
2647.39	14.0609
2651.96	14.2222
2656.52	12.2388
2661.07	9.49744
2665.63	8.79602
2670.18	11.2416
2674.73	13.27
2679.27	14.4568
2683.81	15.0401
2688.35	14.2869
2692.88	10.1158
2697.41	4.16622
2701.94	4.18198
2706.47	5.7425
2710.99	8.04726
2715.51	11.2924
2720.03	13.1177
2724.54	12.0721
2729.05	7.77734
2733.55	6.70723
2738.06	11.7407
2742.56	16.9086
2747.06	11.6898
2751.55	8.36618
2756.04	6.57689
2760.53	10.009
2765.01	9.37276
2769.49	7.44031
2773.97	8.26199
2778.45	9.80299
2782.92	10.7917
2787.39	8.58731
2791.85	8.78056
2796.32	13.2101
2800.78	17.7808
2805.23	16.4994
2809.69	11.5332
2814.14	10.0535
2818.59	13.8542
2823.03	15.3456
2827.47	13.881
2831.91	11.9046
2836.34	14.0115
2840.78	15.8346
2845.21	16.2754
2849.63	15.5873
2854.05	12.4982
2858.47	8.52261
2862.89	7.178
2867.3	8.13892
2871.72	11.4653
2876.12	13.8912
2880.53	14.6322
2884.93	14.6114
2889.33	14.287
2893.72	13.0396
2898.12	13.4156
2902.51	15.2346
2906.89	14.1188
2911.28	13.7588
2915.66	9.82395
2920.03	10.4945
2924.41	14.2373
2928.78	12.8337
2933.15	9.49387
2937.51	9.03419
2941.88	10.719
2946.24	12.3506
2950.59	13.213
2954.95	13.9053
2959.3	14.4233
2963.64	14.7125
2967.99	14.5264
2972.33	13.4732
2976.67	15.8213
2981	17.8828
2985.34	17.6704
2989.67	15.6398
2993.99	11.2651
2998.32	12.1627
3002.64	14.3959
3006.96	16.436
3011.27	13.5825
3015.58	7.39027
3019.89	5.56718
3024.2	9.47296
3028.5	16.9571
3032.8	20.1645
3037.1	17.098
3041.4	11.8453
3045.69	9.51982
3049.98	9.59096
3054.26	11.2065
3058.54	11.6652
3062.82	10.8586
3067.1	11.415
3071.38	13.7927
3075.65	15.5587
3079.91	16.256
3084.18	15.8942
3088.44	14.5239
3092.7	12.7322
3096.96	10.1883
3101.21	11.6102
3105.47	13.7951
3109.71	14.8044
3113.96	15.3336
3118.2	15.2501
3122.44	16.1769
3126.68	18.6762
3130.91	2.89739
3135.14	7.34106
3139.37	13.2176
3143.6	15.6181
3147.82	15.6969
3152.04	17.8324
3156.25	19.883
3160.47	12.5559
3164.68	10.8205
3168.89	12.072
3173.09	12.9737
3177.3	12.5858
3181.49	14.0235
3185.69	16.319
3189.89	17.4004
3194.08	17.925
3198.27	14.7913
3202.45	12.2301
3206.63	11.7034
3210.81	13.0199
3214.99	14.783
3219.17	18.2571
3223.34	13.2722
3227.51	7.84626
3231.67	6.53703
3235.84	8.57751
3240	12.2484
3244.15	14.1732
3248.31	13.4824
3252.46	9.86544
3256.61	8.08717
3260.76	9.86787
3264.9	7.86971
3269.04	6.69209
3273.18	7.44931
3277.32	8.33733
3281.45	9.01863
3285.58	7.86469
3289.71	8.61037
3293.83	10.94
3297.95	12.875
3302.07	14.7297
3306.19	11.7774
3310.3	7.32887
3314.41	5.91604
3318.52	7.72437
3322.63	12.1106
3326.73	11.4531
3330.83	8.62407
3334.92	8.34759
3339.02	7.76942
3343.11	9.09809
3347.2	10.5665
3351.29	8.61697
3355.37	6.48822
3359.45	6.36909
3363.53	7.58383
3367.6	9.10258
3371.68	9.23176
3375.75	9.2239
3379.81	9.80804
3383.88	11.2246
3387.94	11.8915
3392	11.8661
3396.06	11.4504
3400.11	10.1943
3404.16	10.2852
3408.21	6.73963
3412.26	3.98111
3416.3	8.94173
3420.34	8.26971
3424.38	8.4003
3428.41	9.42102
3432.45	10.731
3436.48	10.9921
3440.5	10.697
3444.53	10.848
3448.55	10.1692
3452.57	7.73842
3456.59	7.9498
3460.6	7.19028
3464.61	12.5562
3468.62	8.31872
3472.63	5.37133
3476.63	4.15062
3480.63	3.60635
3484.63	3.29544
3488.62	3.47667
3492.62	4.2377
3496.61	5.69462
3500.6	7.34367
3504.58	9.29845
3508.56	8.01622
3512.54	4.77765
3516.52	4.04221
3520.49	6.13803
3524.47	9.75944
3528.44	9.54183
3532.4	8.67933
3536.37	6.65221
3540.33	5.17184
3544.29	3.30818
3548.25	2.13633
3552.2	3.30946
3556.15	5.76141
3560.1	8.74738
3564.05	8.83386
3567.99	6.50847
3571.93	5.33656
3575.87	6.05753
3579.8	7.44793
3583.74	8.20721
3587.67	8.61377
3591.6	8.43583
3595.52	6.97131
3599.45	5.88781
3603.37	5.03604
3607.28	3.37311
3611.2	3.85856
3615.11	5.15322
3619.02	6.08588
3622.93	6.65896
3626.84	6.3221
3630.74	5.57656
3634.64	6.09818
3638.54	6.55354
3642.43	4.20818
3646.33	3.95299
3650.22	6.21944
3654.1	4.49442
3657.99	3.46222
3661.87	3.91325
3665.75	3.45413
3669.63	0.871197
3673.5	8.03011
3677.38	8.3266
3681.25	1.17307
3685.11	-0.871349
3688.98	0.522476
3692.84	1.11589
3696.7	2.4564
3700.56	0.179302
3704.41	-0.317127
3708.27	1.36976
3712.12	3.64898
3715.96	4.96905
3719.81	4.31097
3723.65	5.26257
3727.49	5.45156
3731.33	3.3021
3735.17	2.1658
3739	1.88837
3742.83	1.41505
3746.66	2.06077
3750.48	1.75095
3754.31	0.998165
3758.13	0.29303
3761.94	0.875957
3765.76	2.48948
3769.57	3.53032
3773.38	4.36913
3777.19	4.42627
3781	4.41616
3784.8	4.63052
3788.6	4.24812
3792.4	3.42859
3796.2	2.72433
3799.99	2.5561
3803.78	2.80215
3807.57	3.35959
3811.36	4.40874
3815.14	3.51448
3818.92	3.0402
3822.7	2.75225
3826.48	2.59685
3830.25	3.92847
3834.03	2.99918
3837.79	0.390251
3841.56	0.286842
3845.33	2.5121
3849.09	3.42074
3852.85	1.78316
3856.61	0.342999
3860.36	0.0726967
3864.11	0.689404
3867.86	0.741627
3871.61	1.25723
3875.36	2.12444
3879.1	2.31325
3882.84	2.04408
3886.58	2.56847
3890.32	1.29285
3894.05	0.708374
3897.78	2.55495
3901.51	3.29156
3905.24	2.83612
3908.96	1.27782
3912.68	0.187836
3916.4	0.239639
3920.12	0.845333
3923.83	2.12577
3927.55	0.827225
3931.26	1.51424
3934.97	2.97622
3938.67	3.00534
3942.37	1.39906
3946.07	-0.350964
3949.77	-1.4563
3953.47	-0.538513
3957.16	1.0005
3960.85	0.212234
3964.54	0.865776
3968.23	1.64452
3971.91	-0.541618
3975.6	1.22109
3979.28	1.69057
3981.24	1.9626
3984.92	2.27995
3988.6	2.0792
3992.29	0.862736
3995.96	0.876606
3999.64	0.567612