File: Data/3-Raman/processed/bu20-E-trl1-FI07-v.txt
#Acq. time (s)=	15
#Accumulations=	3
#Range (cm-¹)=	100...4000
#Windows=	1
#Auto scanning=	Off
#Autofocus=	Off
#Macrospot=	Off
#AutoExposure=	Off
#Spike filter=	Multiple accum.
#Delay time (s)=	0
#Binning=	1
#Readout mode=	Signal
#DeNoise=	Lite
#ICS correction=	Off
#Dark correction=	Off
#Inst. Process=	Off
#Detector temperature (°C)=	-60.09
#Instrument=	LabRAM HR Evol
#Detector=	SIN-EM FIVIS
#Objective=	x100_VIS
#Grating=	150 (500nm)
#ND Filter=	100%
#Laser=	532nm_Edge
#Hole=	30.0125
#Temperature=	0
#Range=	Visible
#StageXY=	75x50mm Scan+
#StageZ=	Z motor
#X (µm)=	14127.4
#Y (µm)=	4711.9
#Z (µm)=	1895.4
#Full time(s)=	47
#Project=	Buranga
#Sample=	BU18FA20_G
#Site=	G_trl1
#Title=	20-E_trl1_FI07
#Remark=
#Date=	30.07.2019 18:59
#Acquired=	30.07.2019 18:59:15
#Data Range:Extract=	16.12.2021 15:36:30
#Base:Fit=	16.12.2021 15:36:40
#Base:Sub=	16.12.2021 15:50:51
103.656	850.223
108.278	984.194
112.899	866.995
117.517	755.286
122.131	636.776
126.744	530.671
131.355	456.598
135.964	402.296
140.571	380.715
145.173	373.946
149.776	372.893
154.375	436.67
158.973	895.786
163.566	2260.92
168.159	2847.9
172.75	2366.34
177.339	891.472
181.923	355.147
186.507	787.721
191.089	2162.11
195.668	3300.57
200.243	3281.62
204.818	1739.95
209.391	847.685
213.96	286.069
218.528	26.9376
223.094	0.000183105
227.655	213.486
232.217	697.146
236.776	1457.74
241.331	2433.87
245.886	3594.54
250.439	5012.51
254.987	5232.51
259.535	3923.18
264.081	2215.92
268.622	1383.21
273.164	1745.7
277.703	3839.64
282.238	7757.02
286.773	10291.2
291.305	9038.33
295.833	4835.02
300.362	3481.35
304.885	2589.56
309.409	2025.83
313.93	1657.93
318.448	1842.23
322.965	2261.63
327.477	2789.98
331.99	3375.03
336.5	3824.3
341.007	4231.95
345.513	4478.53
350.014	4664.1
354.516	4734.84
359.013	4752.71
363.51	4224.46
368.005	3551.17
372.496	2893.73
376.987	2296.47
381.473	1849.06
385.96	1684.93
390.442	1540.24
394.923	1587.05
399.401	1683.63
403.879	1616.11
408.352	1182.22
412.825	730.779
417.294	871.216
421.763	1525.49
426.227	1588.49
430.692	940.684
435.152	388.541
439.612	70.272
444.068	-83.2231
448.524	-80.8478
452.976	133.466
457.427	402.184
461.874	606.843
466.32	587.075
470.765	487.041
475.205	359.631
479.646	380.276
484.083	513.145
488.519	774.475
492.951	1166.99
497.381	1666.96
501.811	1970.13
506.237	1989.31
510.663	1604.6
515.084	1171.06
519.504	812.741
523.923	486.706
528.338	296.023
532.753	171.357
537.164	101.188
541.572	71.1257
545.981	67.9683
550.385	94.0057
554.788	131.091
559.19	182.503
563.588	211.944
567.986	259.164
572.38	255.874
576.771	305.63
581.163	432.106
585.551	716.028
589.936	1994.46
594.319	2655.56
598.702	2685.65
603.081	2527.67
607.458	2140.22
611.835	1793.96
616.208	1749.67
620.578	1660.91
624.949	1349.97
629.315	897.863
633.68	508.203
638.042	527.357
642.404	652.713
646.762	708.066
651.118	788.447
655.472	919.296
659.825	1153.91
664.175	1584.1
668.523	2243.11
672.868	2875.76
677.213	3267.23
681.555	3315.98
685.894	3040.66
690.231	2339.14
694.566	1459.35
698.901	774.853
703.232	409.032
707.561	155.234
711.888	59.0345
716.212	24.4719
720.537	10.7379
724.858	-0.242035
729.176	-6.17203
733.493	-0.000915527
737.807	16.3188
742.119	50.4329
746.432	82.5592
750.74	125.916
755.046	184.16
759.35	288.449
763.652	460.794
767.952	793.608
772.25	1384.75
776.546	2288.25
780.842	3609.61
785.133	4690.28
789.423	4356.75
793.711	2991.15
797.997	1874.73
802.28	1138.99
806.562	651.239
810.841	389.741
815.119	295.772
819.394	206.725
823.668	168.574
827.941	138.099
832.211	111.106
836.478	86.0904
840.743	68.0793
845.006	52.17
849.268	41.1071
853.527	35.8109
857.784	28.3847
862.039	23.113
866.293	19.9002
870.544	18.3287
874.793	18.1906
879.04	18.9153
883.285	21.2545
887.528	25.3079
891.769	31.0341
896.008	38.0864
900.246	47.5331
904.481	59.5239
908.714	74.1191
912.945	90.6562
917.174	112.3
921.401	129.068
925.626	147.874
929.849	187.65
934.068	256.874
938.287	381.083
942.504	594.139
946.72	921.844
950.933	1337.64
955.144	1787.3
959.353	1705.97
963.56	1473.57
967.765	1249.05
971.968	1041.5
976.17	864.407
980.367	709.903
984.564	583.411
988.759	472.865
992.953	388.933
997.144	334.159
1001.33	300.81
1005.52	287.617
1009.71	287.379
1013.89	304.526
1018.07	334.976
1022.25	380.581
1026.43	439.865
1030.6	508.478
1034.78	607.689
1038.94	749.352
1043.11	1020.24
1047.28	1625.13
1051.45	2670.82
1055.61	4503.54
1059.77	5668.23
1063.93	5387.23
1068.09	3833.16
1072.25	2651.22
1076.4	2049.2
1080.55	2025.61
1084.7	2602.49
1088.85	3775.43
1092.99	5628.76
1097.14	6112.4
1101.28	6004.61
1105.42	5839.02
1109.56	5688.71
1113.69	5598.02
1117.83	5507.91
1121.96	5463.29
1126.09	5353.64
1130.22	5269.38
1134.35	5288.04
1138.47	5464.36
1142.59	5235.65
1146.71	4434.1
1150.83	3414.95
1154.95	3173.18
1159.06	3807.46
1163.18	4453.72
1167.29	4500.78
1171.4	3954.94
1175.5	3178.09
1179.61	2460.9
1183.71	1803.27
1187.81	1183.18
1191.91	887.783
1196.01	731.888
1200.1	691.308
1204.2	646.746
1208.29	624.724
1212.38	631.321
1216.47	682.065
1220.55	784.036
1224.64	1148.96
1228.72	1303.79
1232.8	1371.34
1236.88	1239.27
1240.95	1141.37
1245.03	1207
1249.1	1218.43
1253.17	1076.15
1257.24	839.906
1261.31	607.859
1265.37	426.949
1269.44	331.488
1273.5	365.439
1277.56	634.766
1281.61	793.026
1285.67	670.146
1289.72	254.698
1293.77	178.015
1297.83	170.44
1301.87	159.843
1305.92	157.787
1309.96	153.535
1314.01	150.403
1318.05	147.14
1322.09	144.102
1326.12	141.237
1330.16	138.048
1334.19	132.792
1338.22	126.618
1342.25	121.163
1346.28	116.927
1350.3	111.322
1354.33	107.682
1358.35	105.786
1362.37	106.598
1366.39	108.62
1370.4	111.985
1374.42	142.201
1378.43	397.141
1382.44	875.22
1386.45	1110.37
1390.46	525.816
1394.46	113.333
1398.46	100.78
1402.47	134.027
1406.46	132.029
1410.46	105.843
1414.46	66.5388
1418.45	49.2892
1422.45	41.8168
1426.43	33.568
1430.42	24.5897
1434.41	18.6362
1438.39	16.5045
1442.38	14.5721
1446.36	10.7043
1450.34	7.89583
1454.31	0.501625
1458.29	-1.57726
1462.27	-1.74979
1466.24	-0.15107
1470.21	0.515739
1474.18	0.295509
1478.14	0.689247
1482.11	1.28693
1486.07	2.09474
1490.03	0.834129
1493.99	0.821259
1497.95	0.829445
1501.9	0.838959
1505.86	1.21404
1509.81	2.94966
1513.76	6.38741
1517.71	9.17935
1521.65	7.51493
1525.6	5.79918
1529.54	4.43504
1533.48	2.1482
1537.42	1.19321
1541.36	1.17963
1545.29	2.22108
1549.23	3.7881
1553.16	3.57786
1557.09	4.21021
1561.02	5.3468
1564.94	7.22323
1568.87	9.38777
1572.79	9.66582
1576.71	8.53986
1580.63	6.05464
1584.55	4.08851
1588.47	2.64477
1592.38	1.87769
1596.29	1.5032
1600.2	0.952713
1604.11	0.518188
1608.02	-0.393738
1611.92	0.901154
1615.83	2.67221
1619.73	2.16204
1623.63	1.95838
1627.53	0.282112
1631.42	-2.15421
1635.32	-3.06861
1639.21	-2.77631
1643.1	-1.4054
1646.99	0.391571
1650.88	2.00945
1654.76	3.39534
1658.64	3.79808
1662.53	4.29241
1666.41	4.81904
1670.28	5.36444
1674.16	6.08948
1678.04	5.6256
1681.91	4.28356
1685.78	2.352
1689.65	0.720062
1693.52	0.271683
1697.38	0.346031
1701.25	1.16748
1705.11	0.456528
1708.97	-1.09763
1712.83	-1.97158
1716.69	-2.58144
1720.54	-2.15132
1724.4	-1.63985
1728.25	0.0404816
1732.1	2.34147
1735.95	3.54327
1739.79	4.62624
1743.64	5.63177
1747.48	6.166
1751.33	6.74417
1755.17	7.35815
1759	8.17172
1762.84	8.9465
1766.68	9.92497
1770.51	10.0933
1774.34	9.54366
1778.17	8.30338
1782	6.51611
1785.82	4.63096
1789.65	3.78841
1793.47	5.35812
1797.29	6.49689
1801.11	7.44107
1804.93	8.77988
1808.74	9.99831
1812.56	8.57309
1816.37	6.1535
1820.18	1.26341
1823.99	-1.20387
1827.79	0.085556
1831.6	1.73212
1835.4	3.88966
1839.2	4.5179
1843	5.1839
1846.8	5.33112
1850.6	6.12433
1854.39	7.96859
1858.19	10.1534
1861.98	13.5543
1865.77	16.316
1869.56	17.7318
1873.34	18.8533
1877.13	19.8403
1880.91	19.9792
1884.69	19.3401
1888.47	18.3952
1892.25	18.3109
1896.03	18.1072
1899.8	17.6514
1903.57	17.1278
1907.34	16.3316
1911.11	15.2372
1914.88	14.3223
1918.65	13.2177
1922.41	11.9728
1926.18	10.2282
1929.94	9.40868
1933.7	9.39397
1937.45	9.86442
1941.21	10.0776
1944.96	9.79452
1948.72	8.60888
1952.47	7.32365
1956.22	6.48557
1959.96	5.70306
1963.71	4.78738
1967.45	4.1343
1971.2	3.83959
1974.94	3.16996
1978.68	2.18652
1982.42	0.772903
1986.15	-0.890968
1989.89	-3.15561
1993.62	-3.39101
1997.35	-1.82485
2001.08	-0.746849
2004.8	0.288445
2008.53	1.18282
2012.25	1.55216
2015.98	1.46071
2019.7	1.43161
2023.42	-1.14488
2027.13	-2.91707
2030.85	-3.2794
2034.56	-2.51929
2038.28	-1.31232
2041.99	1.03612
2045.7	2.22913
2049.41	3.374
2053.11	1.51436
2056.82	2.50198
2060.52	4.18687
2064.22	4.17593
2067.92	4.10612
2071.62	4.63424
2075.31	5.7977
2079.01	7.73398
2082.7	9.28265
2086.39	10.1059
2090.08	10.4046
2093.77	10.3389
2097.45	9.81457
2101.14	10.0234
2104.82	10.3081
2108.5	11.4443
2112.18	13.3501
2115.86	14.9374
2119.54	17.0663
2123.21	18.9763
2126.88	19.7448
2130.56	20.3572
2134.23	20.6653
2137.89	19.7967
2141.56	19.3697
2145.23	19.9849
2148.89	22.5945
2152.55	27.6456
2156.21	33.9231
2159.87	39.3152
2163.53	42.4247
2167.18	45.2766
2170.84	48.9231
2174.49	53.6804
2178.14	58.5122
2181.79	66.7667
2185.44	75.86
2189.08	82.7972
2192.73	88.5769
2196.37	92.3608
2200.01	94.7682
2203.65	95.0335
2207.29	95.1593
2210.92	95.9458
2214.56	98.4804
2218.19	100.158
2221.82	100.53
2225.45	99.2569
2229.08	97.6409
2232.7	94.4146
2236.33	92.1998
2239.95	87.9962
2243.57	81.9443
2247.19	75.9299
2250.81	67.8858
2254.43	62.2375
2258.04	58.2591
2261.66	55.4684
2265.27	53.3312
2268.88	50.1924
2272.49	47.8725
2276.1	45.7336
2279.7	43.5555
2283.31	41.1565
2286.91	38.7643
2290.51	36.7439
2294.11	34.242
2297.71	30.9973
2301.3	27.7967
2304.9	27.3306
2308.49	26.4465
2312.08	25.6736
2315.67	32.4646
2319.26	61.3506
2322.85	146.918
2326.43	165.876
2330.02	117.475
2333.6	32.4862
2337.18	27.6474
2340.76	25.6014
2344.34	21.8912
2347.91	19.0163
2351.49	15.9002
2355.06	15.4495
2358.63	15.0454
2362.2	14.6222
2365.77	14.2634
2369.33	14.3196
2372.9	15.0432
2376.46	16.3355
2380.02	16.7868
2383.58	17.8391
2387.14	18.1386
2390.7	17.2118
2394.25	16.6289
2397.81	15.6075
2401.36	16.2669
2404.91	14.599
2408.46	12.3592
2412.01	10.3054
2415.56	8.65602
2419.1	7.63438
2422.64	7.11697
2426.18	7.02517
2429.72	7.31611
2433.26	7.67683
2436.8	7.91018
2440.34	6.99812
2443.87	5.42126
2447.4	3.65981
2450.93	3.69035
2454.46	3.65411
2457.99	2.5423
2461.52	2.1813
2465.04	2.2205
2468.56	2.68512
2472.09	3.70203
2475.61	3.74632
2479.13	3.10462
2482.64	2.45336
2486.16	0.374908
2489.67	-2.27266
2493.18	-3.51048
2496.69	-3.13094
2500.2	-2.23472
2503.71	-1.69173
2507.22	-1.21255
2510.72	-1.15131
2514.23	-0.780098
2517.73	-0.799294
2521.23	-1.37979
2524.73	-1.43056
2528.23	-0.74279
2531.72	-0.0487595
2535.21	0.375679
2538.71	1.25887
2542.2	1.52607
2545.69	1.25316
2549.18	0.825813
2552.66	0.996231
2556.15	1.25163
2559.63	0.844948
2563.12	0.629387
2566.6	0.630035
2570.08	0.810577
2573.55	1.14371
2577.03	1.5805
2580.5	2.11825
2583.98	2.81559
2587.45	3.63567
2590.92	3.71878
2594.39	3.59023
2597.86	3.15524
2601.32	2.34946
2604.79	1.5294
2608.25	0.833252
2611.71	0.389389
2615.17	0.054245
2618.63	-0.133331
2622.08	-0.0869217
2625.54	0.320396
2628.99	1.88123
2632.45	3.86764
2635.9	4.57468
2639.35	4.56287
2642.79	4.59224
2646.24	4.30994
2649.69	3.18259
2653.13	1.55351
2656.57	-1.12045
2660.01	-1.79326
2663.45	2.81676
2666.89	2.06445
2670.32	0.982445
2673.76	-0.787422
2677.19	-3.06831
2680.62	-3.1908
2684.05	-3.22467
2687.48	-3.40936
2690.91	-3.09723
2694.33	-1.97123
2697.76	-0.537216
2701.18	0.364319
2704.6	1.91263
2708.02	3.14329
2711.44	4.38593
2714.86	5.34286
2718.27	5.80721
2721.69	5.98667
2725.1	6.07231
2728.51	5.07858
2731.92	3.73113
2735.33	1.50414
2738.74	0.562187
2742.14	-0.147606
2745.55	-0.667816
2748.95	-0.148994
2752.35	0.78006
2755.75	1.78886
2759.15	3.05489
2762.54	4.06148
2765.94	4.88767
2769.33	5.39841
2772.72	5.453
2776.12	4.84827
2779.51	3.04097
2782.89	1.21358
2786.28	0.572266
2789.67	2.58382
2793.05	5.28083
2796.43	4.78895
2799.81	4.41582
2803.19	-0.128059
2806.57	0.375427
2809.95	2.06292
2813.32	3.69395
2816.69	5.83417
2820.06	6.21629
2823.44	5.73148
2826.81	5.21172
2830.17	6.96531
2833.54	5.91566
2836.9	4.81461
2840.27	4.06699
2843.63	3.44918
2846.99	3.16179
2850.35	2.9834
2853.71	2.8354
2857.06	2.74617
2860.42	1.62092
2863.77	1.02335
2867.12	2.10587
2870.48	3.36934
2873.83	3.81676
2877.17	4.15579
2880.52	4.0078
2883.86	3.21725
2887.21	0.900826
2890.55	0.13726
2893.89	0.846748
2897.23	1.63681
2900.57	2.56702
2903.91	3.62932
2907.24	4.4372
2910.57	5.15755
2913.91	4.72741
2917.24	4.03341
2920.57	3.36317
2923.9	2.86489
2927.22	2.12504
2930.55	0.859032
2933.87	-0.0808792
2937.19	-0.378082
2940.51	-0.621742
2943.83	-0.851486
2947.15	-1.57754
2950.47	-0.976883
2953.79	-0.611046
2957.1	-0.134521
2960.41	-0.706169
2963.72	0.699287
2967.03	1.97655
2970.34	3.02489
2973.65	3.68972
2976.95	3.69397
2980.26	3.18826
2983.56	3.88464
2986.86	5.46152
2990.16	4.13109
2993.46	-5.09762
2996.76	-0.485481
3000.06	0.812134
3003.35	1.53757
3006.64	2.39777
3009.94	4.05747
3013.23	3.09863
3016.51	2.49315
3019.8	2.31503
3023.09	2.85754
3026.38	3.89651
3029.66	3.10316
3032.94	1.7271
3036.22	-1.54827
3039.5	-1.47379
3042.78	-1.05874
3046.05	0.0445251
3049.33	0.891457
3052.6	1.16383
3055.88	2.05565
3059.15	1.58218
3062.42	-0.67691
3065.69	-2.29449
3068.95	-3.28451
3072.22	-3.56267
3075.48	-3.32162
3078.75	-0.227074
3082.01	2.73204
3085.27	5.65112
3088.53	5.7506
3091.79	3.16169
3095.04	0.980835
3098.3	-0.841209
3101.55	-1.99525
3104.8	-1.95208
3108.05	-1.90806
3111.3	-0.949295
3114.55	0.950104
3117.8	2.14009
3121.04	1.97684
3124.29	1.95787
3127.53	1.89825
3130.77	1.29408
3134.01	0.658875
3137.25	0.425049
3140.49	0.6791
3143.72	1.56444
3146.96	3.1207
3150.19	5.29493
3153.42	7.81494
3156.65	10.2579
3159.88	10.642
3163.11	9.74562
3166.34	7.65263
3169.56	6.24162
3172.79	5.65085
3176.01	4.03976
3179.23	-0.2397
3182.45	-0.884308
3185.67	0.761948
3188.88	5.23122
3192.1	9.48831
3195.31	12.8116
3198.53	14.689
3201.74	16.0538
3204.95	17.5647
3208.16	19.3827
3211.37	16.8403
3214.57	19.2187
3217.78	20.4362
3220.98	22.6054
3224.18	26.6655
3227.39	31.7291
3230.59	36.4799
3233.78	38.7672
3236.98	39.6708
3240.18	40.6419
3243.37	41.0415
3246.56	41.5921
3249.76	41.088
3252.95	46.5876
3256.14	50.6023
3259.32	53.3838
3262.51	56.5003
3265.7	59.5089
3268.88	61.5122
3272.06	62.7595
3275.24	63.1755
3278.42	63.2958
3281.6	57.4803
3284.78	52.6786
3287.96	52.3316
3291.13	58.5725
3294.31	61.2418
3297.48	65.4882
3300.65	72.5742
3303.82	75.9723
3306.99	77.6028
3310.15	79.5357
3313.32	82.3587
3316.48	86.2249
3319.65	92.2519
3322.81	99.0662
3325.97	105.126
3329.13	110.758
3332.28	116.336
3335.44	121.955
3338.6	128.475
3341.75	136.413
3344.9	145.244
3348.05	154.515
3351.2	160.327
3354.35	165.526
3357.5	170.053
3360.65	174.613
3363.79	179.603
3366.94	185.58
3370.08	188.73
3373.22	198.279
3376.36	215.849
3379.5	237.239
3382.63	265.325
3385.77	316.625
3388.9	379.772
3392.04	452.006
3395.17	528.743
3398.3	574.877
3401.43	649.872
3404.56	796.158
3407.69	1039.72
3410.81	1464.08
3413.94	2229.4
3417.06	3720.71
3420.18	7522.04
3423.3	15239.4
3426.42	21540.7
3429.54	19131
3432.65	11683.4
3435.77	5583.7
3438.88	2903.05
3442	1807.49
3445.11	1308.51
3448.22	998.74
3451.33	850.837
3454.43	794.543
3457.54	752.508
3460.65	734.396
3463.75	756.493
3466.85	804.285
3469.95	875.78
3473.05	1005.18
3476.15	1209.6
3479.25	1461.01
3482.35	1781.85
3485.44	2230.68
3488.54	2818.3
3491.63	3761.75
3494.72	5063.2
3497.81	6938.66
3500.9	9462.13
3503.99	12703.6
3507.07	15499.1
3510.16	16255.6
3513.24	14516.1
3516.32	11505.6
3519.41	8488.09
3522.49	6097.62
3525.56	4449.15
3528.64	3265.69
3531.72	2532.37
3534.79	1924.8
3537.87	1577.83
3540.94	1289.58
3544.01	1078.55
3547.08	894.249
3550.15	756.984
3553.22	645.104
3556.28	558.766
3559.35	508.892
3562.41	465.989
3565.47	415.635
3568.54	376.73
3571.6	348.225
3574.65	324.715
3577.71	301.433
3580.77	284.186
3583.82	268.747
3586.88	253.832
3589.93	240.151
3592.98	225.925
3596.03	211.704
3599.08	197.219
3602.13	182.487
3605.18	167.871
3608.22	154.317
3611.27	141.226
3614.31	129.259
3617.35	117.74
3620.39	105.412
3623.43	97.5525
3626.47	93.4844
3629.5	91.6329
3632.54	92.2523
3635.57	88.5221
3638.61	82.5375
3641.64	76.7889
3644.67	70.3567
3647.7	64.7514
3650.73	61.7591
3653.75	59.7211
3656.78	57.7872
3659.8	56.2523
3662.83	53.9221
3665.85	51.0171
3668.87	47.9005
3671.89	44.2175
3674.91	37.2298
3677.92	29.094
3680.94	26.4497
3683.96	24.3069
3686.97	22.829
3689.98	20.5416
3692.99	17.968
3696	15.3981
3699.01	13.0421
3702.02	11.4874
3705.02	8.31624
3708.03	5.27405
3711.03	3.16653
3714.03	1.55843
3717.04	-0.695679
3720.04	0.406601
3723.04	1.38634
3726.03	2.00134
3729.03	1.71046
3732.03	1.24628
3735.02	0.362488
3738.01	-0.3815
3741	-0.834702
3743.99	0.149216
3746.98	0.213608
3749.97	1.12184
3752.96	3.76619
3755.95	5.46552
3758.93	7.0708
3761.91	8.89095
3764.9	10.1236
3767.88	11.0091
3770.86	10.9118
3773.84	10.6874
3776.81	10.4404
3779.79	10.2685
3782.77	10.0378
3785.74	9.62456
3788.71	8.7084
3791.68	6.3495
3794.65	3.77995
3797.62	3.46445
3800.59	7.46541
3803.56	5.83635
3806.52	2.13475
3809.49	-1.48705
3812.45	-2.29488
3815.41	-3.07686
3818.37	-2.46275
3821.33	-0.24646
3824.29	0.903946
3827.25	4.39058
3830.21	8.52368
3833.16	9.73439
3836.11	9.61206
3839.07	8.72586
3842.02	7.62119
3844.97	6.50417
3847.92	5.5038
3850.87	4.85689
3853.81	4.32149
3856.76	4.28947
3859.7	4.23367
3862.65	3.04643
3865.59	2.69525
3868.53	3.40182
3871.47	5.62924
3874.41	9.15703
3877.34	8.07741
3880.28	1.77005
3883.22	-3.95091
3886.15	-7.16635
3889.08	-4.31677
3892.01	-0.237228
3894.94	3.23557
3897.87	6.70525
3900.8	9.29997
3903.73	11.329
3906.65	12.0181
3909.58	11.888
3912.5	10.6881
3915.42	8.44849
3918.35	3.45912
3921.27	0.620605
3924.18	3.71246
3927.1	4.43542
3930.02	6.74904
3932.93	6.98228
3935.85	5.51678
3938.76	3.48721
3941.67	1.98825
3944.58	1.19051
3947.49	1.61052
3950.4	3.33702
3953.31	3.78268
3956.22	4.08887
3959.12	4.62456
3962.02	5.38937
3964.93	6.39343
3967.83	5.38188
3970.73	2.77919
3973.63	1.5582
3976.53	1.45474
3979.42	2.55377
3982.32	4.23985
3985.21	3.94382
3988.11	-0.695129
3991	-2.59645
3993.89	-2.55745
3996.78	-0.809586
3999.67	-1.54787