File: Data/3-Raman/processed/bu20-j-ff1-fi03-s_1800 (450-850nm)_532nm_edge_100%_x100_vis_lwd_h30um_30sx2_01.txt
#Acq. time (s)=	30
#Accumulations=	2
#Range=	Off
#Autofocus=	Off
#Macrospot=	Off
#AutoExposure=	Off
#Spike filter=	Multiple accum.
#Delay time (s)=	2
#Binning=	1
#Readout mode=	Signal
#DeNoise=	Off
#ICS correction=	On
#Dark correction=	Off
#Inst. Process=	Off
#Detector Gain=	Best Dynamic
#Detector ADC=	50 kHz HS
#Detector temperature (°C)=	-60.09
#Instrument=	LabRAM HR Evol
#Detector=	SIN-EM FIVIS
#Objective=	x100_VIS_LWD
#Grating=	1800 (450-850nm)
#ND Filter=	100%
#Laser=	532nm_Edge
#Spectro (cm-¹)=	3360
#Hole=	30.0125
#Temperature=	0
#Range=	Visible
#StageXY=	75x50mm Scan+
#StageZ=	Z motor
#X (µm)=	0
#Y (µm)=	0
#Z (µm)=	-19.5
#Full time(mm:ss)=	1:05
#Project=	21_08_11
#Sample=	BU20
#Site=
#Title=	BU20-J-FF1-FI03-S_1800 (450-850nm)_532nm_Edge_100%_x100_VIS_LWD_H30um_30sX2
#Remark=
#Date=	11.08.2021 17:27
#Acquired=	11.08.2021 17:27:49
#Data Range:Extract=	16.12.2021 15:36:30
#Base:Fit=	16.12.2021 15:36:40
#Base:Fit=	16.12.2021 15:57:22
#Base:Sub=	16.12.2021 15:57:24
3515.51	453.835
3515.13	481.664
3514.74	481.102
3514.36	505.187
3513.98	511.941
3513.6	512.099
3513.21	530.394
3512.83	570.509
3512.45	562.165
3512.06	578.591
3511.68	561.686
3511.3	567.991
3510.91	567.78
3510.53	565.599
3510.15	553.459
3509.76	560.472
3509.38	545.633
3509	517.554
3508.61	510.026
3508.23	493.64
3507.84	483.717
3507.46	452.881
3507.08	456.629
3506.69	421.191
3506.31	415.775
3505.93	396.236
3505.54	383.066
3505.16	347.422
3504.77	340.097
3504.39	331.03
3504.01	307.288
3503.62	304.647
3503.24	256.417
3502.85	243.369
3502.47	256.171
3502.09	239.39
3501.7	239.683
3501.32	222.796
3500.93	204.999
3500.55	207.117
3500.16	182.336
3499.78	179.594
3499.4	173.068
3499.01	161.858
3498.63	139.274
3498.24	156.668
3497.86	144.505
3497.47	128.515
3497.09	129.652
3496.7	121.208
3496.32	111.876
3495.93	98.8084
3495.55	97.1567
3495.17	91.7174
3494.78	76.7181
3494.4	84.5829
3494.01	73.3636
3493.63	82.1142
3493.24	72.711
3492.86	45.3133
3492.47	67.4637
3492.09	70.248
3491.7	51.5596
3491.32	53.6169
3490.93	48.8935
3490.55	40.4107
3490.16	52.9457
3489.78	61.4834
3489.39	39.6125
3489.01	41.6163
3488.62	52.2633
3488.23	36.2983
3487.85	35.5675
3487.46	31.9843
3487.08	29.3726
3486.69	27.7052
3486.31	33.67
3485.92	19.5782
3485.54	23.6399
3485.15	29.6421
3484.76	29.9596
3484.38	27.3554
3483.99	18.0226
3483.61	24.0378
3483.22	11.8143
3482.84	15.8665
3482.45	17.034
3482.06	15.3055
3481.68	14.4327
3481.29	11.8211
3480.91	5.11145
3480.52	9.86118
3480.13	10.1013
3479.75	2.71579
3479.36	8.59761
3478.98	8.73845
3478.59	6.98674
3478.2	9.07176
3477.82	1.75504
3477.43	4.01605
3477.04	12.8616
3476.66	-1.10881
3476.27	17.1893
3475.88	8.27773
3475.5	-1.80325
3475.11	3.32729
3474.73	19.2902
3474.34	5.89326
3473.95	4.53967
3473.57	1.72522
3473.18	10.7351
3472.79	-1.83807
3472.41	4.36652
3472.02	2.96509
3471.63	2.17435
3471.24	3.73331
3470.86	-5.89078
3470.47	-5.14317
3470.08	-1.03886
3469.7	5.29648
3469.31	3.37488
3468.92	7.34157
3468.54	-14.512
3468.15	4.77892
3467.76	-0.765808
3467.38	-10.9991
3466.99	0.729919
3466.6	7.66443
3466.21	-0.790131
3465.83	1.25507
3465.44	2.37155
3465.05	-2.24048
3464.66	8.5368
3464.28	3.92723
3463.89	0.28418
3463.5	4.33339
3463.11	-1.23976
3462.73	-3.91179
3462.34	3.02344
3461.95	8.98633
3461.56	-2.39928
3461.18	1.61758
3460.79	7.55908
3460.4	0.0328369
3460.01	0.196808
3459.62	0.422791
3459.24	2.58012
3458.85	15.1962
3458.46	4.69588
3458.07	7.77563
3457.68	-1.68147
3457.3	1.32191
3456.91	8.19792
3456.52	6.42888
3456.13	5.67937
3455.74	3.98697
3455.36	6.08569
3454.97	10.1035
3454.58	-2.24396
3454.19	7.57153
3453.8	8.71063
3453.41	8.89189
3453.03	10.0038
3452.64	11.2016
3452.25	12.4324
3451.86	10.6345
3451.47	19.4659
3451.08	17.7344
3450.69	10.104
3450.31	15.0519
3449.92	20.9748
3449.53	17.2437
3449.14	13.5182
3448.75	8.84322
3448.36	24.4064
3447.97	36.0925
3447.58	22.9043
3447.19	18.0167
3446.81	23.2301
3446.42	16.8004
3446.03	42.4981
3445.64	24.4639
3445.25	32.4814
3444.86	31.5678
3444.47	35.6846
3444.08	30.9859
3443.69	33.5493
3443.3	44.6565
3442.91	47.853
3442.52	47.8983
3442.14	48.9822
3441.75	59.7239
3441.36	54.0701
3440.97	48.4737
3440.58	60.2441
3440.19	67.2261
3439.8	69.4103
3439.41	81.427
3439.02	88.9248
3438.63	88.5916
3438.24	108.078
3437.85	112.924
3437.46	120.546
3437.07	129.322
3436.68	152.653
3436.29	161.567
3435.9	182.073
3435.51	214.17
3435.12	218.259
3434.73	242.657
3434.34	294.841
3433.95	323.93
3433.56	369.458
3433.17	434.185
3432.78	469.154
3432.39	571.066
3432	694.166
3431.61	765.106
3431.22	911.189
3430.83	1043.87
3430.44	1169.12
3430.05	1296.3
3429.66	1379.54
3429.27	1424.98
3428.88	1368.85
3428.48	1357.95
3428.09	1179.28
3427.7	1064.02
3427.31	961.47
3426.92	792.521
3426.53	704.994
3426.14	604.914
3425.75	535.915
3425.36	471.357
3424.97	434.599
3424.58	357.577
3424.19	325.949
3423.79	286.584
3423.4	256.831
3423.01	231.806
3422.62	228.036
3422.23	193.386
3421.84	188.524
3421.45	171.182
3421.06	141.393
3420.67	140.554
3420.27	133.984
3419.88	122.605
3419.49	122.695
3419.1	102.525
3418.71	93.9232
3418.32	91.0015
3417.93	93.0299
3417.53	77.7705
3417.14	76.8985
3416.75	70.2798
3416.36	69.4861
3415.97	67.6556
3415.58	76.3838
3415.19	57.2583
3414.79	60.2778
3414.4	55.6129
3414.01	49.0507
3413.62	43.4084
3413.22	40.6297
3412.83	40.7194
3412.44	43.6648
3412.05	38.9235
3411.66	48.6306
3411.27	43.9546
3410.87	36.4334
3410.48	42.3692
3410.09	40.5659
3409.7	34.9136
3409.3	41.7588
3408.91	31.2905
3408.52	36.212
3408.13	33.493
3407.73	24.8497
3407.34	30.807
3406.95	30.9415
3406.56	30.5167
3406.17	28.2621
3405.77	30.2963
3405.38	32.1594
3404.99	22.6638
3404.59	26.6487
3404.2	20.9547
3403.81	24.0776
3403.42	23.0564
3403.02	20.4819
3402.63	32.1923
3402.24	22.529
3401.84	35.7143
3401.45	18.0606
3401.06	29.4832
3400.67	16.0237
3400.27	23.0838
3399.88	31.6637
3399.49	17.2536
3399.09	26.4428
3398.7	22.2165
3398.31	27.9668
3397.91	20.7431
3397.52	21.7611
3397.13	34.3409
3396.73	25.9916
3396.34	28.9304
3395.95	29.9577
3395.55	25.2201
3395.16	26.1368
3394.77	28.0955
3394.37	27.2683
3393.98	26.4808
3393.59	30.4852
3393.19	24.9694
3392.8	29.8878
3392.4	22.09
3392.01	26.1207
3391.62	23.9268
3391.22	13.7687
3390.83	17.8071
3390.44	27.0346
3390.04	25.2067
3389.65	22.9214
3389.25	27.6704
3388.86	27.6966
3388.47	32.7411
3388.07	33.6752
3387.68	30.9152
3387.28	21.4151
3386.89	33.8437
3386.49	28.2269
3386.1	28.327
3385.71	37.9652
3385.31	40.9624
3384.92	41.1149
3384.52	47.06
3384.13	31.0443
3383.73	41.6595
3383.34	46.4394
3382.95	41.7045
3382.55	50.3138
3382.16	48.4505
3381.76	55.2451
3381.37	54.4338
3380.97	62.1979
3380.58	62.324
3380.18	76.7482
3379.79	69.2127
3379.39	67.3891
3379	66.513
3378.6	68.4789
3378.21	66.6428
3377.81	61.9824
3377.42	62.128
3377.02	67.023
3376.63	51.84
3376.23	49.0529
3375.84	54.8278
3375.44	52.9924
3375.05	54.029
3374.65	54.1145
3374.25	51.2983
3373.86	41.9581
3373.46	40.2292
3373.07	42.3088
3372.67	45.3009
3372.28	42.529
3371.88	33.0576
3371.49	35.9934
3371.09	40.7922
3370.7	32.306
3370.3	38.143
3369.9	32.515
3369.51	42.1287
3369.11	29.8436
3368.72	28.0532
3368.32	32.9294
3367.93	24.4514
3367.53	26.4456
3367.13	24.6341
3366.74	25.7281
3366.34	26.7509
3365.95	17.2856
3365.55	29.7457
3365.15	23.1739
3364.76	22.3484
3364.36	23.4098
3363.97	27.2959
3363.57	12.172
3363.17	16.1157
3362.78	14.3328
3362.38	14.4418
3361.98	24.0784
3361.59	18.4442
3361.19	12.7764
3360.79	8.08424
3360.4	18.631
3360	20.601
3359.6	11.1456
3359.21	19.7837
3358.81	7.50298
3358.41	14.2618
3358.02	20.0911
3357.62	16.4337
3357.22	10.8423
3356.83	7.11988
3356.43	10.9974
3356.03	13.9046
3355.64	13.9704
3355.24	8.34407
3354.84	21.7496
3354.44	9.47799
3354.05	15.2827
3353.65	9.67048
3353.25	9.76608
3352.86	8.9088
3352.46	1.40744
3352.06	11.9966
3351.67	10.184
3351.27	9.31647
3350.87	11.3397
3350.47	7.64748
3350.08	14.4128
3349.68	5.92847
3349.28	9.80049
3348.88	7.95132
3348.49	6.10414
3348.09	18.5056
3347.69	9.06092
3347.29	6.3008
3346.9	6.41358
3346.5	7.49123
3346.1	12.3878
3345.7	9.65184
3345.3	9.73934
3344.91	14.6023
3344.51	11.8265
3344.11	12.8712
3343.71	4.43382
3343.31	8.35208
3342.92	5.57581
3342.52	0.909744
3342.12	6.72794
3341.72	2.086
3341.32	4.11841
3340.93	4.22202
3340.53	9.089
3340.13	14.9083
3339.73	6.42509
3339.33	6.52104
3338.93	3.76115
3338.54	7.63558
3338.14	-4.59879
3337.74	7.97801
3337.34	3.34723
3336.94	5.35794
3336.54	6.35175
3336.14	6.40094
3335.74	-4.00153
3335.35	5.64521
3334.95	7.67729
3334.55	7.81738
3334.15	2.19632
3333.75	5.15788
3333.35	2.38675
3332.95	0.560684
3332.55	-3.18349
3332.16	0.718903
3331.76	4.61627
3331.36	0.883301
3330.96	-0.974701
3330.56	7.66917
3330.16	12.5236
3329.76	-2.62513
3329.36	3.23416
3328.96	-1.37818
3328.56	-5.07523
3328.16	0.763557
3327.76	-0.107117
3327.37	-4.82289
3326.97	6.70135
3326.57	0.985306
3326.17	3.93307
3325.77	-6.51517
3325.37	-6.35818
3324.97	-0.744919
3324.57	8.92789
3324.17	4.32843
3323.77	0.643837
3323.37	1.70035
3322.97	7.54911
3322.57	3.79375
3322.17	1.91998
3321.77	7.77759
3321.37	9.83963
3320.97	0.451096
3320.57	2.48838
3320.17	8.30298
3319.77	2.60767
3319.37	1.70082
3318.97	0.77903
3318.57	5.62408
3318.17	-1.00354
3317.77	2.94927
3317.37	2.09928
3316.97	-1.6219
3316.57	-2.49779
3316.17	-4.26649
3315.77	5.27072
3315.37	-3.24599
3314.97	-4.90623
3314.57	-1.86426
3314.17	-2.79036
3313.77	-7.61521
3313.37	-2.84344
3312.97	-3.61208
3312.56	-4.44283
3312.16	0.32373
3311.76	3.2677
3311.36	-1.42938
3310.96	-2.30609
3310.56	0.66098
3310.16	2.65722
3309.76	4.65112
3309.36	-0.0620117
3308.96	3.87222
3308.56	-0.820396
3308.15	-3.56648
3307.75	-2.46069
3307.35	-2.34528
3306.95	-2.2331
3306.55	6.50143
3306.15	0.798424
3305.75	-0.0663605
3305.35	0.033287
3304.94	0.114868
3304.54	3.13554
3304.14	-3.43681
3303.74	2.48286
3303.34	-8.07272
3302.94	4.42751
3302.53	5.56719
3302.13	-0.059082
3301.73	1.82388
3301.33	0.884438
3300.93	1.93108
3300.53	-0.875801
3300.13	2.1627
3299.72	3.25169
3299.32	-9.28266
3298.92	-6.35855
3298.52	-5.32207
3298.12	-0.406761
3297.71	-0.25412
3297.31	-0.118988
3296.91	-0.0186234
3296.51	-4.76189
3296.11	3.96414
3295.7	3.0497
3295.3	-2.66203
3294.9	-6.45918
3294.5	-1.58788
3294.1	2.35351
3293.69	3.42062
3293.29	0.626923
3292.89	0.714088
3292.49	-0.181396
3292.08	0.85096
3291.68	0.122337
3291.28	5.86757
3290.88	3.00653
3290.47	-1.8038
3290.07	2.04487
3289.67	6.00851
3289.27	4.22545
3288.86	0.482933
3288.46	0.579361
3288.06	2.58895
3287.65	-2.12514
3287.25	4.72694
3286.85	0.00369263
3286.45	9.73038
3286.04	1.14919
3285.64	6.9984
3285.24	1.26769
3284.83	-3.51164
3284.43	5.18999
3284.03	4.23077
3283.62	-1.47041
3283.22	-3.14215
3282.82	2.72438
3282.41	-5.03103
3282.01	5.34862
3281.61	-1.93885
3281.2	-2.82154
3280.8	-5.64083
3280.4	2.1358
3279.99	3.15578
3279.59	0.322578
3279.19	-2.48689
3278.78	-2.40921
3278.38	2.49165
3277.98	1.62732
3277.57	-2.12984
3277.17	-3.00303
3276.76	-2.92042
3276.36	-1.88824
3275.96	1.06339
3275.55	4.98493
3275.15	0.198532
3274.74	5.08595
3274.34	5.25482
3273.94	0.295563
3273.53	0.361053
3273.13	0.497246
3272.72	1.56652
3272.32	6.49247
3271.92	7.55898
3271.51	4.73784
3271.11	0.0252991
3270.7	0.122971
3270.3	-0.742973
3269.9	5.13126
3269.49	-0.565056
3269.09	-1.44904
3268.68	-0.418312
3268.28	0.59539
3267.87	2.57539
3267.47	-6.03189
3267.06	3.65039
3266.66	5.65006
3266.25	5.74723
3265.85	8.75053
3265.44	9.84259
3265.04	9.00928
3264.64	6.20701
3264.23	-1.43009
3263.83	5.3774
3263.42	-6.13586
3263.02	7.38126
3262.61	1.65437
3262.21	4.58838
3261.8	0.803009
3261.4	-2.00192
3260.99	0.0067749
3260.59	-5.64559
3260.18	0.160149
3259.78	3.20697
3259.37	5.26155
3258.96	-5.27942
3258.56	0.594543
3258.15	3.5528
3257.75	5.52317
3257.34	-4.05335
3256.94	2.72645
3256.53	9.50174
3256.13	-1.99297
3255.72	9.59718
3255.31	-0.912254
3254.91	0.14669
3254.5	1.18092
3254.1	1.23741
3253.69	5.15038
3253.29	5.23689
3252.88	4.37534
3252.47	5.44373
3252.07	3.61689
3251.66	2.73794
3251.26	3.76786
3250.85	-3.87517
3250.44	2.8838
3250.04	-1.90118
3249.63	5.827
3249.23	4.95205
3248.82	2.17947
3248.41	5.17275
3248.01	-3.34505
3247.6	-7.10136
3247.2	0.647438
3246.79	8.38255
3246.38	4.57237
3245.98	2.66
3245.57	-2.10526
3245.16	-2.10085
3244.76	-9.69741
3244.35	1.9286
3243.94	3.95126
3243.54	-8.43276
3243.13	10.8613
3242.72	10.0029
3242.32	2.42463
3241.91	-1.32398
3241.5	2.58711
3241.1	8.4304
3240.69	1.78976
3240.28	8.57272
3239.88	3.84629
3239.47	5.85444
3239.06	0.173561
3238.65	-5.49358
3238.25	-0.638687
3237.84	2.28278
3237.43	-2.45383
3237.03	3.37682
3236.62	6.34467
3236.21	-2.17351
3235.8	2.733
3235.4	-6.76151
3234.99	1.00537
3234.58	7.78615
3234.18	4.02167
3233.77	0.254143
3233.36	7.04168
3232.95	-0.558884
3232.54	4.31927
3232.14	13.0388
3231.73	1.62499
3231.32	-4.09205
3230.91	0.763725
3230.51	-0.0626068
3230.1	1.86943
3229.69	1.00803
3229.28	9.88306
3228.87	2.0794
3228.47	3.11712
3228.06	0.404625
3227.65	-4.42203
3227.24	4.29419
3226.83	8.09354
3226.43	5.25938
3226.02	-2.94229
3225.61	-2.86132
3225.2	-4.7781
3224.79	-5.69817
3224.39	2.94437
3223.98	6.81102
3223.57	0.190987
3223.16	-1.62259
3222.75	1.34564
3222.34	2.4004
3221.94	0.583023
3221.53	-1.25989
3221.12	-3.11974
3220.71	-1.1628
3220.3	6.5401
3219.89	-2.96133
3219.48	4.77006
3219.07	-4.67417
3218.67	-0.771744
3218.26	-0.714073
3217.85	-3.408
3217.44	0.652542
3217.03	-1.47461
3216.62	4.624
3216.21	-3.05849
3215.8	3.60333
3215.39	-0.0964584
3214.99	-2.84915
3214.58	2.04221
3214.17	-0.760353
3213.76	4.08543
3213.35	0.341896
3212.94	5.22293
3212.53	4.35189
3212.12	4.43817
3211.71	-0.262825
3211.3	-4.00993
3210.89	1.80852
3210.48	1.88454
3210.07	0.0671692
3209.66	-6.50028
3209.25	0.32077
3208.84	1.38592
3208.44	3.38995
3208.02	5.3672
3207.62	-6.99598
3207.21	3.61076
3206.8	8.47868
3206.39	1.86696
3205.98	-5.694
3205.57	0.137177
3205.16	1.16766
3204.75	3.14256
3204.34	1.31317
3203.93	2.37109
3203.52	0.556946
3203.11	0.6586
3202.7	-3.0637
3202.29	3.73941
3201.88	-1.89932
3201.47	4.89738
3201.06	-2.69702
3200.65	0.251114
3200.23	-1.58155
3199.82	-3.41212
3199.41	-1.40926
3199	-1.30973
3198.59	6.45635
3198.39	4.61343