File: Data/3-Raman/processed/bu20-B-brt2-FI01-633-v.txt
#Acq. time (s)=	20
#Accumulations=	3
#Range (cm-¹)=	100...4000
#Windows=	1
#Auto scanning=	Off
#Autofocus=	Off
#Macrospot=	Off
#AutoExposure=	Off
#Spike filter=	Multiple accum.
#Delay time (s)=	0
#Binning=	1
#Readout mode=	Signal
#DeNoise=	Lite
#ICS correction=	Off
#Dark correction=	Off
#Inst. Process=	Off
#Detector temperature (°C)=	-60.09
#Instrument=	LabRAM HR Evol
#Detector=	SIN-EM FIVIS
#Objective=	x100_VIS
#Grating=	150 (500nm)
#ND Filter=	100%
#Laser=	633nm_Edge
#Hole=	30.0125
#Temperature=	0
#Range=	Visible
#StageXY=	75x50mm Scan+
#StageZ=	Z motor
#X (µm)=	9005.3
#Y (µm)=	4615.5
#Z (µm)=	1865.5
#Full time(mm:ss)=	1:03
#Project=	Buranga
#Sample=	BU18FA20_C
#Site=	C_Bertoss2
#Title=	20-C_brt2_FI01
#Remark=
#Date=	30.07.2019 15:11
#Acquired=	30.07.2019 15:11:23
#Data Range:Extract=	16.12.2021 15:36:30
#Base:Fit=	16.12.2021 15:36:40
#Base:Edit=	16.12.2021 15:39:06
#Base:Edit=	16.12.2021 15:39:07
#Base:Edit=	16.12.2021 15:39:08
#Base:Edit=	16.12.2021 15:39:09
#Base:Edit=	16.12.2021 15:39:09
#Base:Edit=	16.12.2021 15:39:10
#Base:Edit=	16.12.2021 15:39:11
#Base:Edit=	16.12.2021 15:39:11
#Base:Sub=	16.12.2021 15:39:13
100.38	150.293
106.898	118.254
113.411	99.2329
119.918	81.7561
126.419	70.1261
132.916	61.4109
139.407	50.2089
145.892	40.0975
152.372	36.6367
158.847	33.8017
165.316	33.3941
171.781	34.1226
178.239	27.6869
184.693	18.3701
191.139	13.1032
197.582	12.0671
204.02	8.96179
210.452	2.90637
216.877	-0.719238
223.299	1.91554
229.715	14.3431
236.126	38.5272
242.53	52.7959
248.931	33.066
255.326	18.0023
261.714	12.8408
268.099	15.7682
274.477	25.6761
280.851	40.6332
287.218	54.5896
293.582	50.057
299.939	28.3392
306.293	9.06635
312.639	3.77856
318.982	17.3504
325.318	43.4838
331.651	74.3775
337.977	62.3591
344.297	33.1766
350.614	16.9664
356.925	15.2743
363.23	24.3612
369.53	33.3668
375.827	26.794
382.116	13.8806
388.401	4.87984
394.681	-0.264938
400.956	2.78607
407.226	6.83524
413.49	8.25163
419.749	13.3936
426.003	22.4831
432.252	40.1715
438.496	55.764
444.735	61.2086
450.969	55.5578
457.197	52.2964
463.421	47.5854
469.64	32.8555
475.853	24.3842
482.062	20.8196
488.265	20.872
494.464	21.5112
500.657	20.529
506.844	20.2633
513.028	20.7548
519.206	22.4361
525.38	22.7687
531.548	22.7462
537.71	23.7632
543.869	25.2222
550.022	27.1334
556.169	16.3931
562.313	16.3298
568.452	18.0571
574.584	17.3704
580.713	15.9314
586.837	16.7821
592.954	24.4509
599.068	42.4832
605.176	60.1398
611.28	59.241
617.378	50.9594
623.473	50.1616
629.561	48.3614
635.644	44.9279
641.724	40.1334
647.797	41.111
653.867	47.9771
659.931	53.4366
665.99	52.9922
672.044	42.724
678.095	27.5207
684.139	17.4213
690.179	13.2211
696.213	8.62689
702.245	5.73962
708.27	5.33273
714.29	4.83777
720.306	5.32829
726.316	6.49335
732.322	9.2952
738.323	11.3895
744.32	9.79286
750.311	5.07274
756.298	0.932678
762.28	1.24347
768.258	1.42825
774.23	0.786758
780.198	-0.638718
786.161	-1.55701
792.119	5.88441
798.073	7.13924
804.021	4.55284
809.965	3.66817
815.904	4.13455
821.839	5.01408
827.769	5.31317
833.693	7.17592
839.614	8.50456
845.53	6.48135
851.44	3.77113
857.346	3.76044
863.248	5.82686
869.144	6.95007
875.037	8.9492
880.924	9.18657
886.807	8.06963
892.685	6.26697
898.559	4.78757
904.427	8.3317
910.292	7.62508
916.151	4.44377
922.006	4.71504
927.856	7.36609
933.701	9.2386
939.543	11.3713
945.379	20.9194
951.21	35.1196
957.037	45.2005
962.861	48.7697
968.678	49.8484
974.491	63.7215
980.3	89.6249
986.104	122.014
991.904	157.24
997.699	158.819
1003.49	128.459
1009.28	100.995
1015.06	101.447
1020.83	117.889
1026.61	130.388
1032.37	119.802
1038.14	87.5259
1043.9	62.6244
1049.65	42.9323
1055.4	31.2917
1061.15	31.7241
1066.88	27.2953
1072.62	21.06
1078.35	25.6691
1084.08	35.719
1089.8	45.3018
1095.52	52.5989
1101.23	55.0237
1106.94	50.5678
1112.65	36.3925
1118.35	22.6977
1124.05	16.1825
1129.74	14.7919
1135.42	14.5733
1141.11	17.102
1146.78	22.3881
1152.46	33.5757
1158.13	44.239
1163.79	31.3812
1169.45	16.7418
1175.11	12.4597
1180.76	9.81564
1186.41	12.1058
1192.05	6.75655
1197.69	0.809921
1203.32	3.59027
1208.95	4.34483
1214.58	4.87648
1220.2	2.14711
1225.82	1.13974
1231.43	3.53624
1237.04	1.64943
1242.64	2.65981
1248.24	5.46443
1253.83	8.45593
1259.42	10.345
1265.01	10.7315
1270.59	11.2079
1276.17	10.1243
1281.74	31.3211
1287.31	40.0983
1292.88	14.1675
1298.44	-4.00864
1303.99	5.58897
1309.55	5.41465
1315.09	4.83752
1320.64	5.3432
1326.18	7.1861
1331.71	2.85147
1337.24	6.01907
1342.77	-1.2591
1348.29	-3.87124
1353.81	2.87148
1359.32	4.88004
1364.83	6.999
1370.33	8.03872
1375.84	14.9186
1381.33	32.822
1386.82	112.563
1392.31	20.1975
1397.8	7.02087
1403.28	9.12017
1408.75	9.85633
1414.22	7.15263
1419.69	3.82787
1425.15	2.72503
1430.61	0.0977859
1436.07	2.99712
1441.52	2.75161
1446.96	-1.22593
1452.41	-5.86922
1457.84	-3.54758
1463.28	2.44885
1468.71	4.57529
1474.13	5.94431
1479.55	6.6713
1484.97	6.59923
1490.39	5.31412
1495.79	1.16036
1501.2	2.24282
1506.6	4.66906
1512	5.41547
1517.39	2.98352
1522.78	2.50464
1528.16	3.50242
1533.54	5.31509
1538.92	3.45184
1544.29	0.619995
1549.66	2.79976
1555.02	5.03048
1560.38	8.82346
1565.74	8.05653
1571.09	7.36216
1576.44	7.07333
1581.78	6.99509
1587.12	7.66846
1592.46	6.45915
1597.79	2.40389
1603.12	-2.24744
1608.44	4.27462
1613.76	8.41033
1619.08	9.90505
1624.39	10.3258
1629.7	10.2707
1635	10.7286
1640.3	10.8403
1645.59	10.4376
1650.88	10.9797
1656.17	13.7002
1661.46	10.3707
1666.74	4.58487
1672.01	3.60416
1677.28	7.29257
1682.55	9.24733
1687.82	8.13632
1693.07	2.92043
1698.33	4.23438
1703.58	3.73702
1708.83	5.03973
1714.07	6.11974
1719.31	3.23944
1724.55	-0.153755
1729.78	2.71092
1735.01	4.05608
1740.23	2.5674
1745.46	3.37681
1750.67	5.55466
1755.89	8.65817
1761.09	5.06207
1766.3	1.77332
1771.5	1.46569
1776.7	0.711571
1781.89	-0.646614
1787.08	1.78376
1792.27	3.92594
1797.45	6.95679
1802.62	4.17988
1807.8	1.32618
1812.97	-0.0802002
1818.14	4.24319
1823.3	6.88462
1828.46	6.0192
1833.61	5.91393
1838.76	4.20241
1843.91	2.59968
1849.05	1.42087
1854.19	0.125496
1859.33	-0.723145
1864.46	-0.735596
1869.59	-3.09678
1874.71	-2.11475
1879.83	-3.45377
1884.95	1.07819
1890.06	4.15144
1895.17	3.69946
1900.27	1.97839
1905.38	0.82608
1910.47	0.362694
1915.57	0.36554
1920.66	0.963989
1925.74	2.22017
1930.83	-0.171219
1935.91	-0.563965
1940.98	0.654953
1946.05	-0.0309601
1951.12	1.77133
1956.18	3.13097
1961.25	2.73359
1966.3	3.19514
1971.35	3.44881
1976.4	3.46509
1981.45	2.72078
1986.49	3.85728
1991.53	4.31268
1996.56	3.85028
2001.59	2.20286
2006.62	5.4408
2011.64	6.0796
2016.66	5.25353
2021.68	5.29539
2026.69	5.29783
2031.7	4.51855
2036.7	2.55975
2041.7	4.52182
2046.7	2.48538
2051.7	-1.02354
2056.69	-2.23898
2061.67	-0.0493774
2066.65	2.98016
2071.63	5.40159
2076.61	5.72825
2081.58	3.13528
2086.55	2.27301
2091.51	4.40394
2096.47	5.48633
2101.43	5.50283
2106.39	5.61407
2111.34	5.29778
2116.28	2.20373
2121.23	2.97948
2126.17	4.38573
2131.1	4.38286
2136.03	3.14271
2140.96	4.46554
2145.89	3.39959
2150.81	3.06214
2155.73	3.7434
2160.64	1.22842
2165.55	0.968208
2170.46	1.79549
2175.36	2.05416
2180.26	2.91967
2185.16	4.61748
2190.05	6.53436
2194.94	7.72733
2199.83	6.94978
2204.71	4.06474
2209.59	2.34242
2214.46	3.46879
2219.33	9.40137
2224.2	8.67985
2229.07	2.48456
2233.93	-1.29493
2238.79	-1.74383
2243.64	0.210762
2248.49	0.906525
2253.34	2.13866
2258.18	1.65133
2263.02	3.70561
2267.86	2.90549
2272.69	2.82613
2277.52	2.66858
2282.35	2.30589
2287.17	3.83105
2291.99	4.28843
2296.8	3.61674
2301.62	2.7733
2306.43	3.83319
2311.23	4.73774
2316.03	6.8845
2320.83	10.1544
2325.63	8.0697
2330.42	7.44711
2335.21	5.64407
2339.99	4.97667
2344.77	6.12325
2349.55	7.50562
2354.32	2.73033
2359.1	2.12799
2363.86	2.66306
2368.63	4.02831
2373.39	3.61383
2378.15	5.02059
2382.9	5.72676
2387.65	4.7746
2392.4	2.65775
2397.14	-0.0170822
2401.88	1.2635
2406.62	5.47198
2411.35	5.46062
2416.08	4.14086
2420.81	5.28515
2425.53	8.37067
2430.25	7.98317
2434.97	4.68737
2439.69	1.80035
2444.4	1.48689
2449.1	4.43675
2453.81	6.10223
2458.51	7.55647
2463.2	6.64223
2467.9	6.4808
2472.59	6.30099
2477.27	4.91516
2481.96	3.09647
2486.64	4.14848
2491.31	5.37325
2495.99	5.8458
2500.66	5.47906
2505.32	6.76633
2509.99	3.81319
2514.65	1.40939
2519.31	1.90284
2523.96	4.8021
2528.61	5.09668
2533.26	2.96236
2537.9	2.27288
2542.54	5.63825
2547.18	6.73466
2551.81	6.53008
2556.44	6.06101
2561.07	4.92366
2565.69	6.19105
2570.32	6.77146
2574.93	3.84277
2579.55	1.80988
2584.16	1.80753
2588.77	-0.260345
2593.37	0.694923
2597.97	4.26552
2602.57	6.13091
2607.17	5.21151
2611.76	4.59361
2616.35	4.59317
2620.93	8.15111
2625.51	8.47382
2630.09	7.16489
2634.67	4.96488
2639.24	3.63593
2643.81	2.81781
2648.38	3.3256
2652.94	2.54939
2657.5	1.46496
2662.06	4.45398
2666.61	4.82581
2671.16	4.52667
2675.71	2.13863
2680.25	2.24583
2684.79	4.08319
2689.33	5.56409
2693.86	6.39027
2698.39	5.44446
2702.92	2.61475
2707.45	1.94768
2711.97	-0.658936
2716.49	-4.09387
2721	0.793282
2725.51	5.70649
2730.02	5.7555
2734.53	4.07357
2739.03	0.644279
2743.53	0.216194
2748.03	1.63527
2752.52	0.411896
2757.01	1.63026
2761.5	8.8122
2765.98	3.81988
2770.46	2.83209
2774.94	3.87088
2779.42	2.89726
2783.89	2.47527
2788.36	3.86603
2792.82	6.97982
2797.28	5.11411
2801.74	0.658257
2806.2	0.507652
2810.65	3.10966
2815.1	2.44508
2819.55	0.0788345
2823.99	-0.0297775
2828.43	1.48439
2832.87	3.10661
2837.3	4.68317
2841.74	6.42107
2846.17	4.29602
2850.59	0.841774
2855.01	-1.8974
2859.43	-1.59335
2863.85	-0.237541
2868.26	0.901154
2872.67	1.4708
2877.08	4.10538
2881.48	4.10793
2885.89	3.51747
2890.28	2.50038
2894.68	1.40351
2899.07	2.00808
2903.46	2.39304
2907.85	2.69132
2912.23	2.09963
2916.61	1.13895
2920.98	0.558662
2925.36	1.43158
2929.73	1.13828
2934.1	0.697868
2938.46	-0.293289
2942.82	-0.747818
2947.18	1.03821
2951.54	1.88818
2955.89	0.450737
2960.24	0.00400543
2964.59	2.7423
2968.93	5.5161
2973.27	4.77678
2977.61	0.759247
2981.95	-0.813744
2986.28	-0.363663
2990.61	-0.466858
2994.94	-0.213753
2999.26	1.71069
3003.58	2.13209
3007.9	2.09869
3012.21	3.86399
3016.52	2.0841
3020.83	-1.6041
3025.14	-1.98322
3029.44	1.01083
3033.74	3.84711
3038.04	3.5397
3042.33	2.35912
3046.62	1.32514
3050.91	0.950867
3055.2	0.597504
3059.48	1.49635
3063.76	3.17747
3068.03	4.54099
3072.31	5.55725
3076.58	5.18661
3080.85	5.49186
3085.11	5.16393
3089.37	4.45781
3093.63	5.20148
3097.89	6.36758
3102.14	6.11691
3106.39	5.49447
3110.64	5.11614
3114.89	4.41115
3119.13	4.26719
3123.37	4.62506
3127.6	5.20377
3131.84	6.76648
3136.07	6.63744
3140.29	7.9922
3144.52	9.7961
3148.74	11.0429
3152.96	7.91232
3157.18	6.94627
3161.39	9.85257
3165.6	12.8875
3169.81	15.7504
3174.01	14.2411
3178.22	14.0722
3182.42	11.0861
3186.61	13.0236
3190.8	14.836
3195	14.5816
3199.18	13.3265
3203.37	15.0482
3207.55	17.6585
3211.73	17.4254
3215.91	17.631
3220.08	15.0002
3224.25	14.2696
3228.42	15.8244
3232.59	15.3634
3236.75	15.584
3240.91	12.9205
3245.07	12.6758
3249.22	13.7251
3253.37	14.016
3257.52	14.1768
3261.67	14.0953
3265.81	12.213
3269.95	11.2012
3274.09	7.53684
3278.22	10.1326
3282.36	12.2244
3286.49	14.2486
3290.61	14.1203
3294.74	12.6488
3298.86	12.0655
3302.98	14.0303
3307.09	10.2829
3311.21	9.715
3315.32	13.9113
3319.42	14.9056
3323.53	14.4878
3327.63	15.7364
3331.73	15.4102
3335.83	14.9996
3339.92	15.8599
3344.01	14.0027
3348.1	12.6659
3352.19	12.0273
3356.27	12.6265
3360.35	14.8926
3364.43	18.6516
3368.5	22.6305
3372.58	25.6482
3376.65	24.4162
3380.71	21.6081
3384.78	19.1526
3388.84	20.0386
3392.9	22.381
3396.95	24.0474
3401.01	15.8907
3405.06	10.6185
3409.1	14.8777
3413.15	17.0055
3417.19	21.1343
3421.23	19.046
3425.27	25.1069
3429.31	25.0281
3433.34	16.1129
3437.37	15.844
3441.39	18.1028
3445.42	21.8152
3449.44	20.1237
3453.46	18.3779
3457.47	16.9599
3461.49	18.1186
3465.5	21.6517
3469.51	23.1787
3473.51	21.9686
3477.52	20.3122
3481.52	18.6289
3485.51	16.9456
3489.51	15.1536
3493.5	18.4171
3497.49	11.3123
3501.48	14.5014
3505.46	17.3428
3509.45	18.3856
3513.43	16.7694
3517.4	15.1886
3521.38	14.6829
3525.35	15.3097
3529.32	10.9859
3533.28	10.8913
3537.25	13.6029
3541.21	12.5122
3545.17	12.8969
3549.12	11.5548
3553.08	10.0791
3557.03	8.89763
3560.98	8.7203
3564.92	9.67276
3568.87	10.3498
3572.81	12.1123
3576.74	11.2716
3580.68	10.8399
3584.61	13.387
3588.54	14.3386
3592.47	13.7564
3596.4	14.2148
3600.32	9.66955
3604.24	5.83111
3608.16	5.49041
3612.07	6.17656
3615.98	7.01953
3619.89	4.0027
3623.8	1.31078
3627.71	0.817127
3631.61	1.13928
3635.51	0.973495
3639.41	2.7336
3643.3	4.57718
3647.19	4.63757
3651.08	4.31443
3654.97	4.25587
3658.85	3.46951
3662.74	3.65586
3666.62	3.29036
3670.49	3.31728
3674.37	3.30791
3678.24	2.42155
3682.11	-0.145973
3685.98	0.441013
3689.84	1.78368
3693.7	1.79153
3697.56	2.02372
3701.42	1.261
3705.28	1.1068
3709.13	3.25095
3712.98	2.19005
3716.82	0.253334
3720.67	-1.15691
3724.51	-1.6022
3728.35	-1.19825
3732.19	-0.0282097
3736.02	1.86352
3739.86	3.90467
3743.69	3.97454
3747.51	2.96701
3751.34	0.83292
3755.16	1.34038
3758.98	1.53833
3762.8	1.17384
3766.61	1.08633
3770.43	2.09557
3774.24	2.8575
3778.05	3.14513
3781.85	3.05193
3785.65	3.57912
3789.45	0.79266
3793.25	-2.50585
3797.05	0.542789
3800.84	2.98728
3804.63	3.18519
3808.42	0.886402
3812.21	1.42221
3815.99	3.02131
3819.77	4.36433
3823.55	5.18377
3827.33	5.15359
3831.1	4.42613
3834.87	2.51358
3838.64	0.29472
3842.41	1.00727
3846.17	2.11519
3849.93	3.2081
3853.69	3.78762
3857.45	3.17511
3861.21	3.64446
3864.96	3.19602
3868.71	3.42315
3872.46	2.07293
3876.2	1.37682
3879.94	1.29212
3883.68	2.16289
3887.42	2.83147
3891.16	3.32658
3894.89	2.65372
3898.62	2.41925
3902.35	2.83669
3906.08	1.89862
3909.8	3.14613
3913.52	3.18133
3917.24	1.70392
3920.96	1.70803
3924.67	3.17984
3928.38	2.63932
3932.09	3.65847
3935.8	3.93513
3939.51	3.77073
3943.21	3.36228
3946.91	3.39325
3950.61	2.64607
3954.3	1.22586
3958	2.23223
3961.69	2.87248
3965.38	2.77091
3969.06	1.63759
3972.75	1.35502
3976.43	4.09908
3980.11	3.38038
3983.78	0.388054
3987.46	-1.15414
3991.13	3.54666
3994.8	0.312222
3998.47	3.09283