File: Data/3-Raman/processed/bu20-E-FF1-FI04-1-v.txt
#Acq. time (s)=	15
#Accumulations=	3
#Range (cm-¹)=	100...4000
#Windows=	1
#Auto scanning=	Off
#Autofocus=	Off
#Macrospot=	Off
#AutoExposure=	Off
#Spike filter=	Multiple accum.
#Delay time (s)=	0
#Binning=	1
#Readout mode=	Signal
#DeNoise=	Lite
#ICS correction=	Off
#Dark correction=	Off
#Inst. Process=	Off
#Detector temperature (°C)=	-60.09
#Instrument=	LabRAM HR Evol
#Detector=	SIN-EM FIVIS
#Objective=	x100_VIS
#Grating=	150 (500nm)
#ND Filter=	100%
#Laser=	532nm_Edge
#Hole=	30.0125
#Temperature=	0
#Range=	Visible
#StageXY=	75x50mm Scan+
#StageZ=	Z motor
#X (µm)=	-4486.6
#Y (µm)=	1052.1
#Z (µm)=	14.8
#Full time(s)=	51
#Project=	Buranga
#Sample=	BU18FA20_E
#Site=	E_FF1
#Title=	20-E_FF1_FI04_1
#Remark=
#Date=	19.06.2019 19:38
#Acquired=	19.06.2019 19:38:18
#Data Range:Extract=	16.12.2021 15:36:30
#Base:Fit=	16.12.2021 15:36:40
#Base:Edit=	16.12.2021 15:41:41
#Base:Edit=	16.12.2021 15:41:43
#Base:Edit=	16.12.2021 15:41:44
#Base:Edit=	16.12.2021 15:41:45
#Base:Sub=	16.12.2021 15:41:48
103.617	2922.67
108.24	2519.15
112.86	2155.77
117.476	1830.22
122.092	1571.03
126.706	1363.43
131.317	1227.58
135.927	1130.63
140.531	1101.93
145.136	1119.95
149.738	1192.72
154.338	1992.56
158.934	3720.91
163.53	3827.38
168.123	1758.24
172.714	710.83
177.301	573.343
181.887	1348.32
186.471	2896.94
191.051	3569.33
195.631	2297.17
200.208	1293.25
204.783	586.042
209.354	152.186
213.925	-1.28595
218.493	111.279
223.058	486.878
227.622	1152.97
232.183	2082.64
236.741	3200.59
241.298	4548.15
245.853	6231.54
250.404	5058.19
254.954	2648.06
259.502	1386.86
264.046	1172.06
268.59	2425.6
273.132	5703.58
277.669	10770.3
282.206	11244.1
286.741	6054.66
291.272	4005.17
295.802	2727.81
300.331	1896.45
304.855	1449.98
309.379	1187.04
313.898	1853.05
318.417	2523.46
322.935	3214.33
327.448	3842.65
331.96	4349
336.469	4739.18
340.977	4985.42
345.481	5110.79
349.985	5052.97
354.487	4853.22
358.985	4202.27
363.482	3472.35
367.975	2798.74
372.468	2222.23
376.957	1913.56
381.446	1572.07
385.93	1659.42
390.414	1764.72
394.894	1854.2
399.374	1518.42
403.85	906.422
408.326	398.877
412.797	1019.24
417.268	1574.86
421.735	1027.92
426.202	508.697
430.664	155.082
435.127	-39.8859
439.585	-47.3711
444.043	63.4907
448.497	254.202
452.951	500.709
457.401	556.258
461.85	502.755
466.296	412.568
470.741	405.276
475.182	516.943
479.621	731.139
484.059	1139.86
488.494	1606.19
492.928	2058.31
497.359	2246.65
501.789	2074.94
506.215	1596.88
510.639	1128.7
515.062	637.272
519.482	446.984
523.901	318.816
528.316	231.061
532.73	180.479
537.143	163.347
541.552	173.758
545.958	207.05
550.365	266.23
554.767	318.972
559.17	365.681
563.568	390.687
567.964	366.432
572.36	368.071
576.752	599.472
581.142	1140.57
585.531	2504.57
589.917	3547.57
594.3	3000.39
598.682	1696.39
603.063	1220.73
607.44	1554.78
611.815	1647.56
616.19	1356.14
620.561	987.382
624.929	712.471
629.298	565.207
633.662	583.331
638.025	671.805
642.385	794.828
646.745	944.954
651.101	1067.49
655.455	1555.19
659.807	2204.2
664.159	2906.49
668.507	3435.82
672.852	3655.52
677.196	3537.14
681.54	2910.29
685.879	2069.16
690.216	1192.97
694.552	482.267
698.885	273.498
703.218	140.954
707.547	87.8983
711.874	56.9995
716.199	36.1266
720.521	24.7772
724.842	24.2225
729.163	35.7293
733.48	62.707
737.794	100.591
742.107	121.189
746.417	146.619
750.725	210.771
755.034	336.506
759.338	578.798
763.64	1098.21
767.94	1929.09
772.238	3105.88
776.535	4607.69
780.829	5326.07
785.12	3905.59
789.412	2367.35
793.7	1421.93
797.986	804.617
802.27	447.962
806.552	307.926
810.831	221.385
815.109	145.023
819.385	97.4099
823.658	49.9003
827.93	13.2222
832.199	-14.8005
836.467	-35.7284
840.732	-50.1653
844.996	-58.3936
849.257	-64.9956
853.519	-71.554
857.776	-77.6299
862.031	-82.931
866.285	-88.7706
870.536	-101.68
874.786	-97.983
879.033	-93.8967
883.278	-82.6191
887.521	-85.0557
891.763	-86.8903
896.002	-86.2315
900.239	-82.6705
904.474	-73.7524
908.706	-60.1806
912.937	-34.8398
917.166	-11.4695
921.393	21.7954
925.619	65.9442
929.842	141.845
934.063	298.532
938.282	540.991
942.5	993.973
946.715	1460.17
950.928	1827.97
955.14	1536.93
959.349	1119.1
963.556	794.917
967.762	637.474
971.963	500.284
976.164	384.059
980.364	280.824
984.561	207.143
988.757	151.853
992.95	114.468
997.141	91.9794
1001.33	85.4128
1005.52	94.1669
1009.7	116.907
1013.89	151.726
1018.07	197.509
1022.25	253.368
1026.42	318.563
1030.6	390.252
1034.77	632.182
1038.94	1066.75
1043.11	1889.59
1047.28	3325.19
1051.45	5408.18
1055.61	5980.09
1059.77	4140.18
1063.93	2699.68
1068.09	1838.89
1072.24	1512.73
1076.4	1729.67
1080.55	2475.23
1084.7	4101.72
1088.85	5438.92
1092.99	5414.93
1097.14	5201.64
1101.28	5144.6
1105.42	5233.06
1109.56	5248.51
1113.7	5293.88
1117.83	5214.77
1121.96	5131.29
1126.09	5114.18
1130.22	5315.43
1134.35	5364.79
1138.47	4736.89
1142.59	3585.03
1146.72	2848.61
1150.83	2948.88
1154.95	3804.36
1159.07	4156.04
1163.18	3757.81
1167.29	3168.86
1171.4	2554.34
1175.51	1868.52
1179.61	1151.99
1183.72	772.899
1187.82	588.827
1191.92	500.231
1196.01	453.488
1200.11	421.062
1204.2	420.064
1208.29	412.351
1212.38	542.006
1216.47	890.382
1220.56	1091.96
1224.64	1183.29
1228.72	1216.43
1232.81	1205.88
1236.89	1178.33
1240.96	1106.44
1245.04	1018.14
1249.11	870.666
1253.18	683.395
1257.25	485.843
1261.32	304.256
1265.38	255.734
1269.44	761.443
1273.51	2101.18
1277.56	2046.93
1281.62	597.697
1285.68	149.345
1289.73	117.421
1293.78	99.0807
1297.83	88.4986
1301.88	79.7768
1305.93	72.5966
1309.97	66.98
1314.02	61.9677
1318.06	57.3071
1322.1	54.4929
1326.13	53.5168
1330.17	54.4636
1334.2	56.3695
1338.23	58.8618
1342.26	61.4884
1346.29	67.2949
1350.31	74.5137
1354.34	92.5928
1358.36	109.965
1362.38	109.392
1366.4	102.724
1370.42	425.178
1374.43	1799.73
1378.44	3688.32
1382.45	2128.3
1386.46	492.168
1390.47	117.599
1394.47	111.284
1398.48	322.059
1402.48	311.024
1406.48	90.9766
1410.48	54.2253
1414.47	32.0033
1418.47	11.9152
1422.46	-2.9005
1426.45	-14.7754
1430.44	-24.0703
1434.43	-30.9858
1438.41	-36.0876
1442.39	-39.6057
1446.37	-41.6811
1450.35	-43.0022
1454.33	-43.529
1458.31	-43.5684
1462.28	-43.7819
1466.25	-44.923
1470.22	-45.4881
1474.19	-45.6133
1478.16	-45.1299
1482.12	-42.7154
1486.08	-39.9741
1490.05	-37.1908
1494.01	-34.5805
1497.96	-32.58
1501.92	-30.8393
1505.87	-29.3567
1509.83	-27.8698
1513.78	-26.3519
1517.72	-24.9131
1521.67	-23.0668
1525.62	-20.8462
1529.56	-18.8768
1533.5	-16.4447
1537.44	-15.3815
1541.38	-14.1631
1545.31	-12.507
1549.25	-10.9025
1553.18	-9.23094
1557.11	-8.15668
1561.04	-7.26085
1564.96	-5.19444
1568.89	-2.66077
1572.81	0.846909
1576.73	3.51924
1580.65	6.24504
1584.57	6.39534
1588.48	5.03534
1592.4	4.65865
1596.31	6.93518
1600.22	6.1581
1604.13	5.90295
1608.04	6.01536
1611.94	7.19349
1615.85	9.31423
1619.75	11.5982
1623.65	13.6903
1627.55	15.7401
1631.44	17.4156
1635.34	19.0747
1639.23	20.6733
1643.12	22.0672
1647.01	23.2594
1650.9	24.082
1654.78	24.4767
1658.67	24.2728
1662.55	23.4662
1666.43	22.4435
1670.31	21.5852
1674.19	20.6267
1678.06	19.5928
1681.93	19.1738
1685.81	19.6785
1689.68	20.5797
1693.54	21.933
1697.41	23.9648
1701.27	25.8579
1705.14	27.7006
1709	28.7352
1712.86	29.9353
1716.71	31.2396
1720.57	31.1176
1724.42	30.7621
1728.28	29.7349
1732.13	31.1464
1735.97	32.6316
1739.82	34.2511
1743.67	37.2917
1747.51	38.407
1751.35	39.4483
1755.19	40.1832
1759.03	40.8918
1762.87	41.4637
1766.7	41.6829
1770.53	41.9013
1774.37	41.3093
1778.2	39.6647
1782.02	37.9591
1785.85	37.0204
1789.67	36.6124
1793.5	36.1078
1797.32	36.5743
1801.14	29.0995
1804.95	36.0363
1808.77	36.6716
1812.58	37.2884
1816.4	35.8039
1820.21	33.1196
1824.02	31.3941
1827.82	31.6996
1831.63	34.5122
1835.43	34.554
1839.23	34.4912
1843.03	34.4998
1846.83	34.7687
1850.63	34.8185
1854.42	35.3569
1858.22	36.442
1862.01	38.0545
1865.8	40.4267
1869.59	43.0942
1873.38	44.2348
1877.16	45.0062
1880.94	44.9172
1884.72	43.2188
1888.51	40.9597
1892.28	38.2332
1896.06	35.6749
1899.83	34.1872
1903.61	33.4641
1907.38	32.5468
1911.15	31.7622
1914.91	31.4452
1918.68	30.5571
1922.45	28.078
1926.21	26.0322
1929.97	24.192
1933.73	22.3727
1937.49	21.5727
1941.24	21.7988
1945	24.5326
1948.75	24.1383
1952.5	22.3769
1956.25	19.2236
1960	15.593
1963.75	13.8113
1967.49	12.0631
1971.23	10.4188
1974.97	9.21304
1978.71	8.04127
1982.45	7.44511
1986.19	6.55473
1989.92	5.9558
1993.65	5.53236
1997.38	5.18072
2001.11	4.06941
2004.84	3.58121
2008.57	2.03798
2012.29	3.37547
2016.01	3.28577
2019.74	3.06308
2023.45	2.893
2027.17	2.6199
2030.89	2.28584
2034.6	1.8717
2038.31	1.45058
2042.03	1.05026
2045.74	0.623177
2049.44	0.0699234
2053.15	-0.476906
2056.85	-1.06823
2060.56	-1.51956
2064.26	-2.35455
2067.96	-2.67307
2071.65	-2.58382
2075.35	-2.17933
2079.05	-0.777443
2082.74	-1.10072
2086.43	-2.38972
2090.12	-5.73266
2093.81	-7.57235
2097.49	-6.63744
2101.18	-4.89404
2104.86	-2.07714
2108.54	1.20884
2112.22	1.70694
2115.9	1.80059
2119.58	2.59673
2123.25	2.33134
2126.93	1.95712
2130.6	1.07743
2134.27	1.16038
2137.94	1.15107
2141.6	2.10468
2145.27	4.11646
2148.93	7.23983
2152.59	10.7533
2156.25	14.4893
2159.91	18.5129
2163.57	23.0551
2167.23	27.9677
2170.88	33.7987
2174.53	39.8139
2178.18	45.9989
2181.83	52.0672
2185.48	58.0581
2189.12	63.1959
2192.77	69.437
2196.41	72.3808
2200.05	73.2166
2203.69	73.0834
2207.33	73.0365
2210.97	73.588
2214.6	74.5734
2218.23	77.0171
2221.86	78.7626
2225.49	78.308
2229.12	75.8678
2232.75	73.0056
2236.37	66.1352
2240	56.1022
2243.62	46.2273
2247.24	36.0598
2250.86	27.4027
2254.47	22.3128
2258.09	20.4243
2261.7	19.1751
2265.32	18.3309
2268.93	17.6572
2272.53	17.1074
2276.14	16.1944
2279.75	13.4319
2283.35	10.4254
2286.96	6.87729
2290.56	3.15044
2294.16	0.0518799
2297.75	-1.84012
2301.35	-4.93533
2304.94	1.36095
2308.54	-3.20596
2312.13	27.0261
2315.72	177.511
2319.31	515.533
2322.9	453.566
2326.48	85.9107
2330.07	10.3279
2333.65	4.44734
2337.23	-0.779007
2340.81	-3.33871
2344.38	-5.16988
2347.96	-6.47926
2351.53	-7.12144
2355.11	-7.15283
2358.68	-6.62529
2362.25	-5.52524
2365.82	-5.35014
2369.38	-8.44991
2372.95	-9.66878
2376.51	-10.5742
2380.07	-11.25
2383.63	-11.9949
2387.19	-12.5546
2390.75	-12.5733
2394.3	-12.964
2397.86	-13.3247
2401.41	-13.8539
2404.96	-15.0267
2408.51	-15.3271
2412.06	-16.9688
2415.61	-19.6292
2419.15	-22.0059
2422.69	-23.6791
2426.24	-24.1771
2429.78	-24.0394
2433.32	-23.4118
2436.85	-22.3004
2440.39	-21.1949
2443.92	-20.6595
2447.45	-20.2095
2450.99	-19.9567
2454.52	-19.6999
2458.04	-19.3919
2461.57	-19.1245
2465.09	-18.3457
2468.62	-17.5372
2472.14	-16.6152
2475.66	-15.6187
2479.18	-14.5024
2482.7	-14.1871
2486.21	-13.7568
2489.73	-15.0615
2493.24	-16.4036
2496.75	-23.9841
2500.26	-18.3406
2503.77	-15.68
2507.27	-13.1478
2510.78	-15.3232
2514.28	-15.7509
2517.78	-13.9071
2521.28	-11.1271
2524.78	-8.54996
2528.28	-6.88351
2531.78	-5.34264
2535.27	-5.27756
2538.76	-4.50388
2542.26	-3.47696
2545.75	-4.67029
2549.23	-7.70544
2552.72	-12.101
2556.21	-13.374
2559.69	-8.26744
2563.17	-6.24811
2566.65	-5.8751
2570.13	-7.73334
2573.61	-8.53082
2577.09	-6.47207
2580.56	-4.2421
2584.03	-3.70876
2587.51	-1.52524
2590.98	0.0131226
2594.45	-0.0362549
2597.91	0.182587
2601.38	-0.207695
2604.84	-0.64402
2608.31	-0.808823
2611.77	-0.744583
2615.23	-0.480522
2618.69	-0.276871
2622.14	-0.060051
2625.6	1.18468
2629.05	2.63748
2632.51	3.9234
2635.96	4.98145
2639.41	5.6479
2642.85	6.11329
2646.3	6.29956
2649.75	5.57107
2653.19	2.25224
2656.63	2.61811
2660.07	3.87878
2663.51	6.25622
2666.95	8.58443
2670.38	10.2093
2673.82	11.3146
2677.25	10.4858
2680.69	9.93442
2684.11	9.41106
2687.54	8.9503
2690.97	10.1544
2694.4	11.5886
2697.82	12.8093
2701.24	13.55
2704.67	14.3703
2708.09	13.4446
2711.5	11.9708
2714.92	10.4708
2718.34	9.41879
2721.75	9.45267
2725.16	9.82461
2728.58	10.7598
2731.98	12.0241
2735.39	13.9621
2738.8	15.6148
2742.21	15.6623
2745.61	15.8366
2749.01	15.6419
2752.41	15.1589
2755.81	14.2468
2759.21	13.7795
2762.61	12.9214
2766	11.9847
2769.4	13.2159
2772.79	13.9118
2776.18	15.2529
2779.57	16.3196
2782.96	17.3132
2786.34	18.0225
2789.73	18.7946
2793.11	19.6172
2796.5	20.6538
2799.88	20.47
2803.26	19.714
2806.63	20.3336
2810.01	20.2176
2813.39	20.1595
2816.76	20.3237
2820.13	20.5418
2823.5	21.0079
2826.87	21.0886
2830.24	20.7267
2833.61	20.5375
2836.97	20.7825
2840.33	21.2889
2843.7	20.9753
2847.06	20.4725
2850.42	20.0504
2853.78	19.7811
2857.13	19.6857
2860.49	19.6394
2863.84	19.4205
2867.19	19.0151
2870.54	18.0123
2873.89	16.9887
2877.24	16.2675
2880.59	17.1083
2883.93	18.0714
2887.28	19.1223
2890.62	19.2777
2893.96	19.335
2897.3	19.1953
2900.64	18.5283
2903.97	17.5389
2907.31	16.6479
2910.64	16.568
2913.98	16.7477
2917.31	15.688
2920.64	13.2417
2923.97	10.879
2927.29	9.29434
2930.62	8.08806
2933.94	8.06071
2937.26	9.01704
2940.59	10.3001
2943.91	11.3649
2947.22	12.0354
2950.54	12.2076
2953.86	11.3875
2957.17	10.2206
2960.48	8.81946
2963.79	7.26968
2967.1	5.6473
2970.41	5.09853
2973.72	5.14603
2977.03	5.92063
2980.33	7.13683
2983.63	8.16807
2986.94	10.1546
2990.24	12.7399
2993.53	9.47815
2996.83	4.02422
3000.13	6.60541
3003.42	10.4307
3006.72	11.9478
3010.01	9.76527
3013.3	7.13024
3016.59	3.87785
3019.88	1.87941
3023.16	1.63337
3026.45	1.63735
3029.73	1.82128
3033.01	1.92882
3036.3	1.17848
3039.58	0.0296631
3042.85	-1.41553
3046.13	-2.69911
3049.41	-3.73409
3052.68	-4.50322
3055.95	-5.0574
3059.22	-5.47826
3062.49	-5.68575
3065.76	-5.85962
3069.03	-5.68051
3072.3	-4.91782
3075.56	-5.02483
3078.82	-5.40988
3082.08	-6.10579
3085.35	-7.00781
3088.6	-7.49646
3091.86	-8.06752
3095.12	-8.25581
3098.37	-8.21313
3101.63	-8.92432
3104.88	-9.54164
3108.13	-11.0602
3111.38	-12.6555
3114.63	-12.2087
3117.87	-12.227
3121.12	-11.294
3124.36	-11.7366
3127.61	-11.0883
3130.85	-11.5945
3134.09	-11.703
3137.33	-12.3003
3140.56	-13.0625
3143.8	-13.8364
3147.04	-14.6812
3150.27	-15.4239
3153.5	-16.2155
3156.73	-17.2053
3159.96	-17.9277
3163.19	-18.2104
3166.42	-17.2536
3169.64	-15.1054
3172.86	-12.9072
3176.09	-11.0485
3179.31	-9.36867
3182.53	-7.30745
3185.75	-6.0015
3188.96	-5.59799
3192.18	-5.26451
3195.39	-5.59311
3198.61	-6.31918
3201.82	-5.1801
3205.03	-4.2041
3208.24	-1.28011
3211.45	1.69553
3214.65	5.00128
3217.86	8.48746
3221.06	11.5077
3224.27	13.5984
3227.47	14.7164
3230.67	13.7922
3233.86	13.8044
3237.06	13.3728
3240.26	17.4556
3243.45	21.2445
3246.65	23.1893
3249.84	26.2089
3253.03	28.9796
3256.22	30.9235
3259.41	31.242
3262.59	31.5633
3265.78	31.3014
3268.96	31.5734
3272.15	32.6458
3275.33	32.8113
3278.51	33.3153
3281.69	33.8451
3284.86	32.6783
3288.04	30.3352
3291.21	31.8683
3294.39	33.5929
3297.56	37.0927
3300.73	42.5981
3303.9	50.0269
3307.07	59.6269
3310.24	65.8754
3313.4	71.0862
3316.57	76.1071
3319.73	80.5067
3322.89	82.9249
3326.05	76.2451
3329.21	77.3054
3332.37	88.4602
3335.53	104.874
3338.68	120.21
3341.84	131.856
3344.99	135.855
3348.14	140.362
3351.29	144.285
3354.44	148.573
3357.59	153.607
3360.73	159.931
3363.88	167.72
3367.02	175.662
3370.16	190.729
3373.3	208.818
3376.44	234.298
3379.58	262.131
3382.72	313.984
3385.86	372.986
3388.99	452.274
3392.12	523.934
3395.26	604.99
3398.39	681.967
3401.52	889.895
3404.65	1196.4
3407.77	1690.59
3410.9	2701.28
3414.02	4854
3417.15	10161.7
3420.27	19699.5
3423.39	22591.2
3426.51	14683
3429.63	6942.74
3432.74	3442.53
3435.86	2056.34
3438.97	1466.15
3442.08	1078.26
3445.2	910.961
3448.31	784.728
3451.42	723.74
3454.52	711.816
3457.63	723.381
3460.74	751.4
3463.84	810.916
3466.94	922.238
3470.04	1090.76
3473.14	1272.94
3476.24	1620.91
3479.34	2028.88
3482.44	2492.87
3485.53	3293.35
3488.63	4318.88
3491.72	5884.9
3494.81	8092.93
3497.9	10981
3500.99	14267
3504.08	16535.1
3507.16	16010.2
3510.25	12997.3
3513.33	9789.35
3516.41	7049.45
3519.5	5049.57
3522.58	3741.69
3525.66	2796.82
3528.73	2173.97
3531.81	1776.12
3534.89	1370.09
3537.96	1157.9
3541.03	970.44
3544.1	828.33
3547.17	726.121
3550.24	621.819
3553.31	527.536
3556.38	480.549
3559.44	438.382
3562.5	399.608
3565.57	368.209
3568.63	340.441
3571.69	315.196
3574.75	292.324
3577.81	271.765
3580.86	253.261
3583.92	236.739
3586.97	221.82
3590.02	208.193
3593.08	198.014
3596.13	188.599
3599.18	176.535
3602.22	156.21
3605.27	152.084
3608.31	145.758
3611.36	135.613
3614.4	124.534
3617.44	119.493
3620.48	115.398
3623.52	115.83
3626.56	114.857
3629.6	109.439
3632.63	102.793
3635.67	95.7944
3638.7	88.3869
3641.73	80.9381
3644.76	74.9522
3647.79	69.6261
3650.82	66.0532
3653.85	63.3453
3656.87	61.136
3659.9	58.9433
3662.92	55.92
3665.94	52.8811
3668.96	49.931
3671.98	46.8715
3675	43.1743
3678.02	38.3337
3681.04	32.4892
3684.05	26.5561
3687.06	21.3033
3690.08	17.4735
3693.09	15.1837
3696.1	14.7301
3699.11	14.8272
3702.11	15.1855
3705.12	15.6891
3708.13	15.863
3711.13	16.1532
3714.13	16.3682
3717.13	16.4451
3720.13	15.8119
3723.13	15.4118
3726.13	14.0797
3729.13	12.4841
3732.12	11.1302
3735.12	9.91432
3738.11	9.02718
3741.1	8.40945
3744.09	8.17499
3747.08	6.53282
3750.07	2.54529
3753.06	2.38083
3756.04	1.80852
3759.03	9.28709
3762.01	9.89195
3765	10.4872
3767.98	10.8937
3770.96	10.9027
3773.94	10.1494
3776.91	10.394
3779.89	10.5411
3782.86	10.6833
3785.84	10.8279
3788.81	14.0404
3791.78	10.6113
3794.75	8.60747
3797.72	5.69666
3800.69	2.69179
3803.66	1.0972
3806.62	-1.061
3809.59	-1.39426
3812.55	-0.959229
3815.51	-0.308731
3818.47	0.878265
3821.43	2.47018
3824.39	5.25284
3827.35	8.5069
3830.31	9.18996
3833.26	8.32097
3836.22	6.54448
3839.17	4.00967
3842.12	0.68988
3845.07	-3.601
3848.02	-6.79068
3850.97	-8.5528
3853.91	-8.31584
3856.86	-9.16681
3859.8	-10.0553
3862.75	-11.245
3865.69	-11.7318
3868.63	-10.5569
3871.57	-8.80025
3874.51	-6.90254
3877.45	-5.40065
3880.38	-5.57565
3883.32	-6.00038
3886.25	-6.92647
3889.19	-8.41951
3892.12	-11.0052
3895.05	-12.9526
3897.98	-13.6763
3900.9	-13.0307
3903.83	-11.6815
3906.76	-7.94704
3909.68	-3.98836
3912.61	-2.71021
3915.53	-4.9357
3918.45	-9.75713
3921.37	-7.21004
3924.29	-4.96051
3927.21	-5.50314
3930.12	-7.19299
3933.04	-11.6495
3935.95	-15.0667
3938.87	-13.5987
3941.78	-10.3869
3944.69	-5.62814
3947.6	-3.85396
3950.51	-4.99352
3953.42	-7.8446
3956.32	-9.92429
3959.23	-8.11092
3962.13	-5.88918
3965.03	-3.20248
3967.93	0.264511
3970.84	3.69106
3973.74	7.04042
3976.63	9.51511
3979.53	9.77922
3982.43	8.7516
3985.32	12.9333
3988.21	15.9396
3991.11	18.363
3994	21.6868
3996.89	25.8381
3999.78	14.2386