File: Data/3-Raman/processed/bu20-b-ff4-fi02-v_150 (500nm)_633nm_edge_100%_x100_vis_lwd_h30um_60sx4_01.txt
#Acq. time (s)=	60
#Accumulations=	4
#Range (cm-¹)=	100...4000
#Windows=	1
#Auto scanning=	Off
#Autofocus=	Off
#Macrospot=	Off
#AutoExposure=	Off
#Spike filter=	Multiple accum.
#Delay time (s)=	2
#Binning=	1
#Readout mode=	Signal
#DeNoise=	Off
#ICS correction=	On
#Dark correction=	Off
#Inst. Process=	Off
#Detector Gain=	Best Dynamic
#Detector ADC=	50 kHz HS
#Detector temperature (°C)=	-60.09
#Instrument=	LabRAM HR Evol
#Detector=	SIN-EM FIVIS
#Objective=	x100_VIS_LWD
#Grating=	150 (500nm)
#ND Filter=	100%
#Laser=	633nm_Edge
#Hole=	30.0125
#Temperature=	40
#Range=	Visible
#StageXY=	75x50mm Scan+
#StageZ=	Z motor
#X (µm)=	0
#Y (µm)=	0
#Z (µm)=	470.9
#Full time(mm:ss)=	4:05
#Project=	21_08_11
#Sample=	BU20
#Site=
#Title=	BU20-B-FF4-FI01-L_150 (500nm)_633nm_Edge_100%_x100_VIS_LWD_H30um_60sX4
#Remark=
#Date=	13.08.2021 11:50
#Acquired=	13.08.2021 11:50:50
#Data Range:Extract=	16.12.2021 15:36:30
#Base:Fit=	16.12.2021 15:36:40
#Base:Sub=	16.12.2021 15:52:56
100.12	607.425
106.638	415.014
113.152	312.378
119.66	227.88
126.162	166.76
132.659	126.524
139.151	95.0585
145.637	80.4527
152.118	59.4269
158.594	44.1273
165.064	29.7342
171.529	25.4825
177.989	10.9165
184.441	8.09102
190.89	4.87164
197.334	5.76927
203.772	1.62785
210.205	1.91783
216.631	-0.045517
223.054	8.76225
229.471	10.4908
235.881	41.0504
242.288	74.081
248.689	40.0264
255.083	22.7087
261.474	24.0707
267.858	28.2729
274.238	34.6912
280.613	43.9373
286.982	91.675
293.346	79.6165
299.704	39.8
306.058	18.9381
312.406	17.0012
318.749	14.4353
325.086	30.4557
331.418	82.9426
337.746	56.8063
344.068	26.5858
350.384	15.2081
356.697	17.6252
363.003	26.9168
369.304	36.493
375.601	38.2174
381.892	23.6833
388.177	9.86638
394.457	0.487949
400.733	1.17097
407.004	5.93493
413.269	4.402
419.529	5.66729
425.784	10.6427
432.034	23.9414
438.279	43.7525
444.518	54.6848
450.753	56.1425
456.982	48.283
463.207	43.6564
469.426	32.9146
475.64	18.8314
481.85	6.33153
488.054	15.5601
494.253	2.74438
500.447	0.174725
506.635	8.81083
512.819	8.75617
518.999	7.1666
525.173	6.86163
531.342	5.33829
537.505	1.63715
543.664	6.3622
549.819	5.05947
555.966	5.63352
562.111	9.57172
568.25	6.21663
574.383	3.44723
580.513	9.71821
586.636	8.52671
592.756	14.2351
598.871	24.9648
604.979	66.3123
611.084	50.5362
617.183	40.394
623.277	39.6317
629.367	36.3313
635.451	44.4812
641.532	48.7073
647.606	36.2007
653.675	25.5938
659.741	46.832
665.801	49.2845
671.856	38.7479
677.907	18.4649
683.952	16.2118
689.992	10.911
696.028	0.328331
702.059	3.45501
708.086	5.63197
714.107	5.83571
720.123	4.44335
726.135	4.6087
732.141	1.60036
738.143	6.08288
744.14	1.53066
750.133	5.09359
756.12	3.09314
762.103	3.35366
768.081	2.43604
774.054	6.83964
780.023	1.51593
785.987	2.0957
791.946	5.16688
797.9	3.48788
803.848	1.13585
809.793	0.962608
815.733	1.38328
821.669	-0.0932083
827.6	3.41584
833.525	8.22345
839.446	2.21029
845.363	7.16115
851.273	9.95173
857.181	8.69578
863.083	9.32988
868.98	9.01867
874.874	8.65677
880.761	11.7243
886.645	9.69986
892.523	12.6977
898.398	13.1231
904.267	6.86258
910.133	11.3059
915.992	11.338
921.849	9.55897
927.699	10.0367
933.545	15.592
939.387	16.2321
945.224	27.6419
951.056	35.3582
956.884	46.9118
962.708	51.7711
968.526	60.4166
974.34	68.6806
980.149	77.0996
985.955	115.73
991.755	161.843
997.551	171.812
1003.34	130.35
1009.13	103.079
1014.91	103.35
1020.69	109.355
1026.46	137.873
1032.23	155.723
1037.99	107.673
1043.75	65.4471
1049.51	52.6351
1055.26	43.24
1061	36.9834
1066.74	29.9768
1072.48	34.2825
1078.21	39.2002
1083.94	50.5514
1089.67	60.6123
1095.38	50.6604
1101.1	69.7379
1106.81	66.6575
1112.51	43.5993
1118.22	26.8027
1123.91	24.4622
1129.6	23.0791
1135.29	25.2851
1140.98	28.8075
1146.65	35.5662
1152.33	34.442
1158	53.5671
1163.66	34.1965
1169.32	19.7683
1174.98	17.4648
1180.63	17.4528
1186.28	16.192
1191.93	12.378
1197.56	11.8713
1203.2	11.7544
1208.83	8.72195
1214.46	11.2788
1220.08	12.5613
1225.69	10.5394
1231.31	12.1556
1236.92	7.71249
1242.52	12.9403
1248.12	17.4587
1253.72	22.2755
1259.31	23.9967
1264.89	55.9183
1270.48	27.999
1276.05	39.9967
1281.63	254.441
1287.2	207.308
1292.76	39.1583
1298.33	32.8732
1303.88	19.302
1309.43	16.1183
1314.98	17.6728
1320.53	13.2034
1326.07	18.1661
1331.6	15.7264
1337.13	19.0173
1342.66	17.5203
1348.18	12.9028
1353.7	17.1469
1359.22	21.0291
1364.73	26.5904
1370.23	39.306
1375.73	36.9404
1381.23	46.2091
1386.72	675.65
1392.21	141.687
1397.7	31.0031
1403.18	31.4877
1408.65	83.16
1414.13	28.0447
1419.59	20.9934
1425.06	15.9945
1430.52	14.7866
1435.97	8.70382
1441.42	10.5962
1446.87	9.35953
1452.31	4.92719
1457.75	7.4576
1463.19	4.0152
1468.62	2.30929
1474.04	3.40499
1479.46	5.21772
1484.88	3.53981
1490.3	3.27854
1495.7	5.49374
1501.11	4.91479
1506.51	3.99242
1511.91	0.25239
1517.3	1.82173
1522.69	5.18727
1528.08	3.58101
1533.46	5.91558
1538.83	-0.388849
1544.21	2.97861
1549.58	1.97089
1554.94	4.16093
1560.3	4.5316
1565.66	4.19154
1571.01	4.56739
1576.36	4.59044
1581.7	5.00329
1587.04	2.55499
1592.38	2.63069
1597.71	2.00522
1603.04	3.19186
1608.37	6.20963
1613.68	4.56743
1619	2.57235
1624.31	5.67131
1629.62	4.76198
1634.93	0.155672
1640.23	6.52134
1645.52	3.31684
1650.81	6.36821
1656.1	3.50116
1661.39	6.15765
1666.67	4.3728
1671.94	2.95254
1677.22	5.9621
1682.48	0.8346
1687.75	0.126402
1693.01	0.168373
1698.26	3.19269
1703.52	2.26516
1708.77	1.34624
1714.01	6.93315
1719.25	4.11094
1724.49	4.2209
1729.72	5.09722
1734.95	4.10154
1740.18	3.09755
1745.4	6.60413
1750.61	2.19383
1755.83	3.79678
1761.04	6.13566
1766.24	-0.585917
1771.44	4.77927
1776.64	1.84224
1781.84	0.809387
1787.02	4.33319
1792.21	4.46651
1797.39	4.60396
1802.57	2.46262
1807.75	4.90344
1812.92	5.41916
1818.08	1.32187
1823.25	5.30166
1828.41	3.89303
1833.56	2.48111
1838.71	5.33198
1843.86	3.89814
1849	5.18023
1854.14	2.55356
1859.28	2.6642
1864.41	2.00125
1869.54	5.65495
1874.67	5.76369
1879.79	4.29272
1884.9	0.449808
1890.02	6.43943
1895.13	2.56161
1900.23	3.03217
1905.34	2.35628
1910.43	5.652
1915.53	4.23132
1920.62	5.13933
1925.71	4.86013
1930.79	4.98187
1935.87	3.09822
1940.94	1.99992
1946.02	6.10388
1951.08	3.37986
1956.15	4.65731
1961.21	10.3491
1966.27	-0.437227
1971.32	8.8473
1976.37	5.67578
1981.42	7.32117
1986.46	4.95727
1991.5	2.59949
1996.53	2.6516
2001.56	5.9171
2006.59	5.18631
2011.61	4.06267
2016.63	6.55244
2021.65	3.01123
2026.66	3.50231
2031.67	2.79777
2036.68	5.73231
2041.68	2.20851
2046.68	4.75309
2051.67	4.06043
2056.66	1.72067
2061.65	3.87224
2066.63	4.39936
2071.61	5.74214
2076.59	5.44701
2081.56	6.37777
2086.53	4.00521
2091.49	7.39674
2096.46	6.6886
2101.41	3.49739
2106.37	8.18755
2111.32	7.07915
2116.26	8.47832
2121.21	7.78898
2126.15	5.8289
2131.09	4.69315
2136.02	2.69711
2140.95	5.76641
2145.87	4.59938
2150.79	7.23851
2155.71	3.91591
2160.63	4.40957
2165.54	7.02234
2170.45	6.64755
2175.35	2.4464
2180.25	6.76371
2185.15	6.37312
2190.04	5.13651
2194.93	8.60616
2199.82	3.97694
2204.7	7.90905
2209.58	7.14771
2214.46	7.25061
2219.33	8.22421
2224.2	3.58718
2229.06	7.15454
2233.92	2.48865
2238.78	5.63344
2243.64	7.4837
2248.49	2.78074
2253.34	6.82294
2258.18	6.92921
2263.02	5.26858
2267.86	2.70263
2272.69	5.42466
2277.52	7.25764
2282.35	6.4208
2287.17	8.22799
2291.99	6.48664
2296.81	7.40662
2301.62	7.00995
2306.43	3.07121
2311.24	4.92431
2316.04	4.11506
2320.84	6.44214
2325.63	7.88351
2330.43	14.287
2335.21	4.93776
2340	9.57035
2344.78	4.69864
2349.56	5.72639
2354.33	8.58146
2359.11	8.22161
2363.87	2.77751
2368.64	6.07043
2373.4	4.75562
2378.16	3.43323
2382.91	7.18592
2387.66	5.83108
2392.41	4.92561
2397.16	5.40084
2401.9	6.3358
2406.64	4.01588
2411.37	5.905
2416.1	6.46595
2420.83	3.80487
2425.55	6.19003
2430.27	7.20339
2434.99	2.57627
2439.7	6.43569
2444.41	4.15152
2449.12	5.6581
2453.83	5.26331
2458.53	2.95098
2463.22	6.38047
2467.92	8.86224
2472.61	7.49153
2477.3	7.08216
2481.98	6.18259
2486.66	8.66892
2491.34	3.85773
2496.01	15.6146
2500.68	4.92686
2505.35	6.92581
2510.01	2.54808
2514.67	7.97254
2519.33	10.954
2523.99	7.05658
2528.64	7.0889
2533.28	7.6191
2537.93	6.6737
2542.57	7.7117
2547.21	6.27231
2551.84	7.31721
2556.47	5.86365
2561.1	5.40321
2565.73	6.45521
2570.35	6.01009
2574.97	6.06632
2579.58	5.10224
2584.19	7.65853
2588.8	7.16808
2593.41	3.622
2598.01	0.595625
2602.61	7.72454
2607.2	6.21117
2611.8	7.74312
2616.38	4.68455
2620.97	0.602669
2625.55	5.20081
2630.13	5.72839
2634.71	2.17843
2639.28	4.80206
2643.85	5.89581
2648.42	3.37493
2652.98	4.46959
2657.54	3.9756
2662.1	6.07586
2666.65	5.56148
2671.2	6.6293
2675.75	1.44414
2680.29	4.17048
2684.84	4.26632
2689.37	5.42399
2693.91	5.50266
2698.44	6.0522
2702.97	2.87187
2707.49	3.42704
2712.02	3.44154
2716.53	0.237555
2721.05	5.64691
2725.56	2.4167
2730.07	6.74386
2734.58	1.31964
2739.08	1.84353
2743.58	10.5209
2748.08	6.19199
2752.57	6.78557
2757.06	4.09005
2761.55	2.45575
2766.04	3.56645
2770.52	5.77874
2775	1.40818
2779.47	3.64909
2783.94	8.69015
2788.41	5.43274
2792.88	3.26221
2797.34	3.86261
2801.8	2.21651
2806.26	6.72773
2810.71	3.37559
2815.16	2.25667
2819.61	0.567448
2824.05	2.26727
2828.49	5.10501
2832.93	9.64779
2837.37	3.98101
2841.8	3.41665
2846.23	6.27396
2850.65	5.15422
2855.08	12.624
2859.5	3.50591
2863.91	2.97415
2868.33	0.71768
2872.74	2.49492
2877.15	2.54404
2881.55	8.42349
2885.95	3.24708
2890.35	1.54784
2894.75	5.71802
2899.14	5.20691
2903.53	13.5697
2907.91	6.51665
2912.3	1.19794
2916.68	3.0111
2921.05	4.24184
2925.43	2.48243
2929.8	3.73167
2934.17	9.21068
2938.53	3.80365
2942.9	6.85331
2947.26	4.43756
2951.61	5.05354
2955.97	0.190701
2960.32	6.28882
2964.66	3.2498
2969.01	3.87793
2973.35	4.51122
2977.69	1.4633
2982.03	4.55949
2986.36	3.36572
2990.69	4.02872
2995.01	2.83912
2999.34	5.38233
3003.66	-0.1646
3007.98	4.9002
3012.29	-0.0625286
3016.6	0.625437
3020.91	7.01766
3025.22	4.55372
3029.52	0.148731
3033.82	2.09131
3038.12	4.0264
3042.41	3.42216
3046.71	2.80315
3051	4.1077
3055.28	6.70651
3059.56	-0.357212
3063.84	3.53533
3068.12	0.323196
3072.39	0.341396
3076.67	2.96068
3080.93	2.9877
3085.2	3.0209
3089.46	4.37507
3093.72	3.78461
3097.98	4.516
3102.23	5.25335
3106.48	9.31923
3110.73	5.44355
3114.98	6.21242
3119.22	6.31811
3123.46	6.43481
3127.7	1.82779
3131.93	3.98192
3136.16	8.20484
3140.39	7.65784
3144.61	5.71542
3148.84	4.4395
3153.06	7.9896
3157.27	2.50671
3161.49	10.2495
3165.7	8.93642
3169.91	11.8142
3174.11	7.68234
3178.31	7.72875
3182.51	10.5857
3186.71	8.49476
3190.9	7.10079
3195.1	10.6863
3199.28	9.34622
3203.47	11.6017
3207.65	11.0202
3211.83	14.0344
3216.01	11.3102
3220.18	10.728
3224.36	10.8657
3228.52	8.81322
3232.69	11.8752
3236.85	7.5811
3241.01	7.7059
3245.17	10.0745
3249.33	5.73291
3253.48	11.7935
3257.63	5.87984
3261.77	9.73696
3265.92	0.819584
3270.06	9.27388
3274.2	8.65607
3278.33	11.0055
3282.47	5.72756
3286.59	10.3799
3290.72	5.84383
3294.85	6.6643
3298.97	9.79738
3303.09	6.01269
3307.2	8.39225
3311.32	7.67838
3315.43	5.41014
3319.54	7.02337
3323.64	10.995
3327.74	0.938864
3331.84	8.07395
3335.94	4.26865
3340.04	6.73047
3344.13	8.3845
3348.22	4.48695
3352.3	22.788
3356.39	10.1723
3360.47	3.88457
3364.54	7.14871
3368.62	9.62244
3372.69	8.89774
3376.76	8.95827
3380.83	8.20779
3384.89	8.25684
3388.96	9.10845
3393.02	12.3776
3397.07	14.0533
3401.13	6.83377
3405.18	10.1098
3409.23	11.773
3413.27	6.93969
3417.31	15.0925
3421.36	10.2548
3425.39	18.4184
3429.43	7.89226
3433.46	12.8356
3437.49	9.64229
3441.52	3.17486
3445.54	8.98587
3449.56	5.80085
3453.58	9.1933
3457.6	6.01459
3461.61	10.2877
3465.63	3.77316
3469.63	7.23187
3473.64	8.1748
3477.64	7.45494
3481.64	6.72862
3485.64	5.14877
3489.64	1.01411
3493.63	4.50014
3497.62	6.28887
3501.61	10.6359
3505.59	5.5845
3509.58	12.4784
3513.56	4.81307
3517.53	-0.293764
3521.51	11.7355
3525.48	3.19932
3529.45	9.23927
3533.42	5.00764
3537.38	6.81245
3541.34	8.63185
3545.3	8.71125
3549.26	6.18248
3553.21	2.74935
3557.16	6.26069
3561.11	13.2644
3565.06	8.99557
3569	9.09181
3572.94	6.56101
3576.88	13.6602
3580.82	6.76783
3584.75	19.212
3588.68	17.5996
3592.61	18.6322
3596.54	23.223
3600.46	14.4676
3604.38	7.44769
3608.3	10.2264
3612.21	4.9395
3616.13	9.51333
3620.04	5.99688
3623.94	8.7475
3627.85	7.88681
3631.75	2.5075
3635.65	7.05238
3639.55	1.68872
3643.44	2.66411
3647.34	0.0268726
3651.23	6.41382
3655.12	6.46509
3659	7.42142
3662.88	2.914
3666.76	2.95912
3670.64	0.270544
3674.52	5.79692
3678.39	7.69879
3682.26	1.37455
3686.13	6.97873
3689.99	4.32409
3693.85	4.42422
3697.71	6.37194
3701.57	5.54729
3705.43	0.988003
3709.28	6.68277
3713.13	6.78705
3716.98	12.5096
3720.82	6.95998
3724.66	4.20802
3728.5	2.38498
3732.34	8.1248
3736.18	5.35961
3740.01	4.47793
3743.84	3.58744
3747.67	0.78463
3751.49	9.40537
3755.32	4.67507
3759.14	9.47567
3762.96	7.58978
3766.77	1.87775
3770.58	8.59888
3774.4	7.67791
3778.2	5.79871
3782.01	18.3153
3785.81	9.74161
3789.61	0.172258
3793.41	5.99468
3797.21	20.5391
3801	5.15559
3804.79	3.28378
3808.58	8.20917
3812.37	9.25275
3816.15	9.31925
3819.93	5.47222
3823.71	14.3366
3827.49	5.56277
3831.26	4.62899
3835.04	5.66099
3838.8	-0.21521
3842.57	5.75324
3846.34	11.7134
3850.1	5.78183
3853.86	12.715
3857.62	7.7552
3861.37	9.72064
3865.12	8.74298
3868.87	8.80549
3872.62	6.8288
3876.37	1.84223
3880.11	0.834736
3883.85	8.80448
3887.59	8.80555
3891.33	4.81264
3895.06	7.83617
3898.79	10.8602
3902.52	10.8793
3906.25	5.86218
3909.97	3.84847
3913.69	7.89036
3917.41	10.9421
3921.13	10.9803
3924.84	5.93889
3928.56	6.9719
3932.27	4.93885
3935.97	7.98913
3939.68	2.86534
3943.38	2.86049
3947.08	9.01077
3950.78	3.85615
3954.48	4.8545
3958.17	3.78409
3961.86	5.79237
3965.55	3.66548
3969.24	3.58724
3972.92	3.50687
3976.6	5.49136
3980.29	5.39754
3983.96	6.32693
3987.64	10.3552
3991.31	7.15197
3994.98	10.1628
3998.65	3.87131