File: Data/3-Raman/processed/bu20-B-brt2-FI04-633-v.txt
#Acq. time (s)=	20
#Accumulations=	3
#Range (cm-¹)=	100...4000
#Windows=	1
#Auto scanning=	Off
#Autofocus=	Off
#Macrospot=	Off
#AutoExposure=	Off
#Spike filter=	Multiple accum.
#Delay time (s)=	0
#Binning=	1
#Readout mode=	Signal
#DeNoise=	Lite
#ICS correction=	On
#Dark correction=	Off
#Inst. Process=	Off
#Detector temperature (°C)=	-60.09
#Instrument=	LabRAM HR Evol
#Detector=	SIN-EM FIVIS
#Objective=	x100_VIS
#Grating=	150 (500nm)
#ND Filter=	100%
#Laser=	633nm_Edge
#Hole=	30.0125
#Temperature=	0
#Range=	Visible
#StageXY=	75x50mm Scan+
#StageZ=	Z motor
#X (µm)=	8694.4
#Y (µm)=	4538.1
#Z (µm)=	1850.8
#Full time(mm:ss)=	1:02
#Project=	Buranga
#Sample=	BU18FA20_C
#Site=	C_Bertoss2
#Title=	20-C_brt2_FI04
#Remark=
#Date=	30.07.2019 15:34
#Acquired=	30.07.2019 15:34:25
#Data Range:Extract=	16.12.2021 15:36:30
#Base:Fit=	16.12.2021 15:36:40
#Base:Edit=	16.12.2021 15:39:41
#Base:Edit=	16.12.2021 15:39:42
#Base:Edit=	16.12.2021 15:39:42
#Base:Edit=	16.12.2021 15:39:43
#Base:Edit=	16.12.2021 15:39:44
#Base:Edit=	16.12.2021 15:39:44
#Base:Edit=	16.12.2021 15:39:44
#Base:Edit=	16.12.2021 15:39:45
#Base:Edit=	16.12.2021 15:39:45
#Base:Edit=	16.12.2021 15:39:46
#Base:Edit=	16.12.2021 15:39:49
#Base:Edit=	16.12.2021 15:39:50
#Base:Sub=	16.12.2021 15:39:52
100.38	187.701
106.898	145.698
113.411	114.402
119.918	88.2595
126.419	64.9398
132.916	53.849
139.407	45.0166
145.892	36.642
152.372	27.4168
158.847	20.3563
165.316	16.0403
171.781	12.6058
178.239	9.69819
184.693	6.47708
191.139	5.2452
197.582	3.97556
204.02	2.72814
210.452	1.30358
216.877	0.505043
223.299	0.499123
229.715	1.01096
236.126	10.7306
242.53	18.6128
248.931	11.7067
255.326	6.98701
261.714	4.80774
268.099	5.51449
274.477	7.62558
280.851	13.2282
287.218	28.7478
293.582	22.2377
299.939	11.1716
306.293	2.67094
312.639	1.60484
318.982	6.59569
325.318	16.3844
331.651	26.45
337.977	20.507
344.297	8.24591
350.614	3.7182
356.925	3.80671
363.23	7.26486
369.53	10.2447
375.827	8.82124
382.116	5.10892
388.401	0.540588
394.681	-3.06247
400.956	-0.262688
407.226	3.08886
413.49	1.51779
419.749	2.71088
426.003	7.89304
432.252	15.7523
438.496	23.3027
444.735	25.1661
450.969	20.7268
457.197	16.1614
463.421	12.3129
469.64	10.0529
475.853	6.81864
482.062	3.24002
488.265	2.34449
494.464	3.16483
500.657	5.32872
506.844	7.74285
513.028	9.03967
519.206	7.82166
525.38	6.02522
531.548	4.76943
537.71	5.02204
543.869	6.45583
550.022	7.91357
556.169	7.27757
562.313	6.27477
568.452	5.88117
574.584	6.24675
580.713	7.21872
586.837	6.5141
592.954	9.67875
599.068	18.4896
605.176	25.5178
611.28	24.3764
617.378	20.1012
623.473	18.2119
629.561	18.0954
635.644	17.575
641.724	15.9059
647.797	15.763
653.867	18.4539
659.931	21.7568
665.99	20.8716
672.044	16.0965
678.095	8.95837
684.139	4.47483
690.179	4.2946
696.213	2.07064
702.245	1.96123
708.27	4.26929
714.29	3.549
720.306	2.99745
726.316	2.66374
732.322	2.70747
738.323	2.12925
744.32	0.757664
750.311	-0.34454
756.298	0.0398064
762.28	1.3461
768.258	2.81514
774.23	2.85802
780.198	2.12654
786.161	2.35408
792.119	3.13972
798.073	1.98218
804.021	-0.187725
809.965	-0.952095
815.904	-0.0951157
821.839	1.77393
827.769	2.7163
833.693	2.18909
839.614	1.62525
845.53	0.752064
851.44	0.232227
857.346	0.0508881
863.248	0.178082
869.144	0.0462189
875.037	0.169193
880.924	2.51949
886.807	3.02268
892.685	0.576004
898.559	-0.166386
904.427	0.581963
910.292	1.47458
916.151	2.35594
922.006	3.3553
927.856	4.51261
933.701	3.5597
939.543	4.95581
945.379	7.33447
951.21	10.9642
957.037	14.246
962.861	17.4106
968.678	19.9202
974.491	24.6887
980.3	32.8676
986.104	47.6978
991.904	64.5008
997.699	63.3711
1003.49	49.6106
1009.28	40.9559
1015.06	38.9957
1020.83	43.3824
1026.61	51.6909
1032.37	47.0139
1038.14	32.8381
1043.9	20.7473
1049.65	13.3966
1055.4	10.5073
1061.15	9.62748
1066.88	9.43941
1072.62	9.92046
1078.35	11.1041
1084.08	13.0545
1089.8	15.887
1095.52	18.8082
1101.23	20.5578
1106.94	18.4121
1112.65	11.0722
1118.35	5.77676
1124.05	2.98096
1129.74	2.22648
1135.42	4.53677
1141.11	7.6629
1146.78	11.6476
1152.46	13.7099
1158.13	12.8886
1163.79	8.57959
1169.45	5.41803
1175.11	2.85777
1180.76	4.96815
1186.41	6.06998
1192.05	4.2779
1197.69	2.79047
1203.32	2.74257
1208.95	2.33058
1214.58	1.98373
1220.2	1.12164
1225.82	0.569851
1231.43	0.829521
1237.04	1.92109
1242.64	3.18632
1248.24	5.07705
1253.83	7.62693
1259.42	9.86401
1265.01	6.57676
1270.59	3.84766
1276.17	18.6118
1281.74	121.199
1287.31	19.2784
1292.88	7.23067
1298.44	4.08121
1303.99	3.70258
1309.55	4.08399
1315.09	4.31963
1320.64	3.67453
1326.18	3.74503
1331.71	4.80173
1337.24	4.25366
1342.77	2.66285
1348.29	3.37222
1353.81	5.23886
1359.32	6.35388
1364.83	7.17176
1370.33	8.68951
1375.84	10.4048
1381.33	34.203
1386.82	232.355
1392.31	22.5164
1397.8	9.84563
1403.28	11.4849
1408.75	9.55769
1414.22	5.11746
1419.69	2.67636
1425.15	1.86049
1430.61	2.60052
1436.07	2.784
1441.52	0.936031
1446.96	3.59125
1452.41	4.16364
1457.84	2.8877
1463.28	1.73407
1468.71	1.52679
1474.13	2.68518
1479.55	4.1537
1484.97	4.4238
1490.39	3.29305
1495.79	1.5267
1501.2	1.4841
1506.6	1.87727
1512	1.36779
1517.39	1.94174
1522.78	-0.259476
1528.16	-1.92757
1533.54	-0.496555
1538.92	0.775475
1544.29	1.67913
1549.66	2.43117
1555.02	3.09509
1560.38	0.627205
1565.74	-0.244774
1571.09	3.55054
1576.44	4.27503
1581.78	3.55578
1587.12	2.50177
1592.46	1.75039
1597.79	1.76449
1603.12	2.39776
1608.44	3.52021
1613.76	3.37437
1619.08	2.56741
1624.39	1.99893
1629.7	2.46233
1635	3.86901
1640.3	0.552834
1645.59	-0.0198059
1650.88	2.78085
1656.17	4.77001
1661.46	5.14468
1666.74	2.42851
1672.01	0.908638
1677.28	1.0858
1682.55	3.28188
1687.82	6.28494
1693.07	5.38721
1698.33	2.45715
1703.58	0.58831
1708.83	0.155281
1714.07	1.09207
1719.31	3.11852
1724.55	1.7289
1729.78	2.32933
1735.01	2.1376
1740.23	3.08036
1745.46	5.19563
1750.67	6.88892
1755.89	6.23293
1761.09	4.45285
1766.3	0.748917
1771.5	-0.151634
1776.7	1.62377
1781.89	3.33546
1787.08	3.51112
1792.27	3.0567
1797.45	2.56881
1802.62	3.33873
1807.8	4.21335
1812.97	5.26221
1818.14	4.93879
1823.3	1.98058
1828.46	-0.636871
1833.61	1.14743
1838.76	2.91537
1843.91	3.18063
1849.05	2.72933
1854.19	1.57436
1859.33	1.86485
1864.46	2.81157
1869.59	2.19553
1874.71	1.09031
1879.83	2.69891
1884.95	0.575508
1890.06	0.184944
1895.17	1.52871
1900.27	3.70843
1905.38	4.58781
1910.47	3.40239
1915.57	1.9716
1920.66	2.67583
1925.74	4.49873
1930.83	3.17233
1935.91	1.85207
1940.98	2.07851
1946.05	4.26971
1951.12	5.89951
1956.18	6.06472
1961.25	5.31729
1966.3	4.50708
1971.35	3.60574
1976.4	2.28793
1981.45	1.73985
1986.49	2.62469
1991.53	2.96912
1996.56	3.83801
2001.59	4.58694
2006.62	3.78127
2011.64	4.27093
2016.66	4.68117
2021.68	5.07101
2026.69	4.12827
2031.7	2.22044
2036.7	2.07081
2041.7	3.53594
2046.7	5.33866
2051.7	4.22216
2056.69	2.77123
2061.67	3.59399
2066.65	2.948
2071.63	0.706802
2076.61	4.48912
2081.58	6.37863
2086.55	5.91931
2091.51	3.921
2096.47	2.89196
2101.43	2.13599
2106.39	1.08602
2111.34	1.24452
2116.28	2.6881
2121.23	3.04448
2126.17	3.7918
2131.1	4.53229
2136.03	4.39825
2140.96	3.58383
2145.89	2.78172
2150.81	3.77241
2155.73	4.9534
2160.64	6.41014
2165.55	4.24239
2170.46	1.18764
2175.36	2.21063
2180.26	3.44183
2185.16	4.6068
2190.05	6.05611
2194.94	4.18886
2199.83	2.53942
2204.71	2.30405
2209.59	3.10315
2214.46	3.73007
2219.33	3.42154
2224.2	3.02074
2229.07	3.50674
2233.93	4.54372
2238.79	4.11174
2243.64	3.39315
2248.49	-0.424828
2253.34	-3.29225
2258.18	-3.24904
2263.02	-0.995392
2267.86	1.84853
2272.69	3.56047
2277.52	4.82586
2282.35	6.60371
2287.17	7.47929
2291.99	5.76987
2296.8	6.6718
2301.62	6.53047
2306.43	7.33992
2311.23	6.55362
2316.03	5.02821
2320.83	4.58413
2325.63	5.66047
2330.42	7.6461
2335.21	7.68127
2339.99	8.65987
2344.77	5.76784
2349.55	4.04536
2354.32	4.05319
2359.1	6.88713
2363.86	7.96797
2368.63	5.53062
2373.39	4.8186
2378.15	4.51686
2382.9	5.4712
2387.65	7.48527
2392.4	6.38853
2397.14	5.22307
2401.88	5.42328
2406.62	4.04935
2411.35	4.94683
2416.08	5.6958
2420.81	3.0098
2425.53	1.28016
2430.25	4.4552
2434.97	6.80885
2439.69	3.95112
2444.4	2.87276
2449.1	4.17619
2453.81	5.02995
2458.51	4.64939
2463.2	5.94233
2467.9	5.61091
2472.59	4.01044
2477.27	2.56788
2481.96	3.69585
2486.64	5.13221
2491.31	5.99689
2495.99	6.98967
2500.66	7.53481
2505.32	8.20614
2509.99	6.80194
2514.65	5.47649
2519.31	4.17064
2523.96	5.31422
2528.61	7.70638
2533.26	8.71462
2537.9	7.25755
2542.54	2.76836
2547.18	2.60586
2551.81	6.72237
2556.44	6.54741
2561.07	6.33485
2565.69	4.86761
2570.32	4.11036
2574.93	4.33894
2579.55	4.29066
2584.16	6.74262
2588.77	9.02391
2593.37	7.04138
2597.97	2.49764
2602.57	2.06244
2607.17	1.87872
2611.76	1.36941
2616.35	4.6113
2620.93	7.74489
2625.51	9.2513
2630.09	8.57127
2634.67	5.43661
2639.24	3.49586
2643.81	3.57506
2648.38	4.94981
2652.94	4.64112
2657.5	2.30633
2662.06	2.52738
2666.61	3.30531
2671.16	3.12492
2675.71	2.61394
2680.25	4.02766
2684.79	3.08115
2689.33	2.61002
2693.86	3.77034
2698.39	5.09416
2702.92	5.14851
2707.45	5.03294
2711.97	3.72228
2716.49	2.63056
2721	1.17037
2725.51	0.896797
2730.02	2.97632
2734.53	7.34308
2739.03	5.00596
2743.53	3.10279
2748.03	3.84333
2752.52	0.492737
2757.01	0.923904
2761.5	3.48376
2765.98	4.95946
2770.46	4.77804
2774.94	3.094
2779.42	1.31623
2783.89	1.09348
2788.36	4.99757
2792.82	6.40364
2797.28	6.06165
2801.74	5.03418
2806.2	3.90111
2810.65	3.64923
2815.1	6.02456
2819.55	7.33981
2823.99	6.16187
2828.43	2.0288
2832.87	-1.0827
2837.3	0.797058
2841.74	2.77919
2846.17	2.90872
2850.59	2.71275
2855.01	1.853
2859.43	2.62323
2863.85	5.28037
2868.26	5.13037
2872.67	3.78201
2877.08	1.75664
2881.48	3.30143
2885.89	4.68336
2890.28	4.08322
2894.68	3.32139
2899.07	1.92824
2903.46	0.313644
2907.85	-1.28674
2912.23	2.67259
2916.61	2.24877
2920.98	0.58371
2925.36	-0.16758
2929.73	1.27975
2934.1	6.9044
2938.46	8.13288
2942.82	6.15305
2947.18	2.52059
2951.54	-1.07834
2955.89	-1.30897
2960.24	0.584259
2964.59	1.89611
2968.93	2.67011
2973.27	3.70866
2977.61	3.197
2981.95	0.649002
2986.28	3.35014
2990.61	1.04281
2994.94	-2.99458
2999.26	-6.35519
3003.58	-2.04612
3007.9	0.325012
3012.21	-0.132416
3016.52	-0.419212
3020.83	-0.217972
3025.14	-3.5201
3029.44	-1.31018
3033.74	-0.351822
3038.04	0.345299
3042.33	0.317322
3046.62	-0.284889
3050.91	2.03175
3055.2	3.47263
3059.48	2.17091
3063.76	0.32238
3068.03	-0.992279
3072.31	-1.35312
3076.58	-1.19432
3080.85	0.822456
3085.11	3.26827
3089.37	0.951958
3093.63	-3.87416
3097.89	-6.30888
3102.14	-1.46253
3106.39	2.71891
3110.64	4.57825
3114.89	0.395821
3119.13	-0.72258
3123.37	-0.809273
3127.6	0.641426
3131.84	1.74129
3136.07	0.341797
3140.29	-0.335167
3144.52	1.63606
3148.74	2.15943
3152.96	1.96874
3157.18	3.3531
3161.39	3.34949
3165.6	1.96725
3169.81	-3.52797
3174.01	6.90461
3178.22	12.9637
3182.42	6.99698
3186.61	5.61685
3190.8	4.88776
3195	6.27773
3199.18	8.43451
3203.37	7.15164
3207.55	2.70735
3211.73	0.915634
3215.91	5.26509
3220.08	3.97105
3224.25	-2.80143
3228.42	-5.24638
3232.59	-0.651901
3236.75	0.849518
3240.91	2.3573
3245.07	5.69298
3249.22	1.33487
3253.37	0.60498
3257.52	1.4268
3261.67	2.43317
3265.81	5.25357
3269.95	0.623917
3274.09	-0.477844
3278.22	1.53275
3282.36	-1.87329
3286.49	-2.29453
3290.61	1.18228
3294.74	2.53021
3298.86	1.0179
3302.98	-0.623459
3307.09	-0.0988922
3311.21	-1.4485
3315.32	-2.63873
3319.42	-3.15942
3323.53	1.11282
3327.63	5.59373
3331.73	5.28865
3335.83	3.05144
3339.92	1.75557
3344.01	2.75221
3348.1	-5.29729
3352.19	-0.744415
3356.27	6.11241
3360.35	-0.379303
3364.43	-2.47893
3368.5	0.718964
3372.58	3.54585
3376.65	3.42561
3380.71	0.471146
3384.78	0.188614
3388.84	3.78214
3392.9	7.43808
3396.95	8.58797
3401.01	7.0247
3405.06	3.37704
3409.1	5.79604
3413.15	7.731
3417.19	7.51651
3421.23	8.31497
3425.27	7.58333
3429.31	3.83257
3433.34	2.48578
3437.37	7.10448
3441.39	7.89082
3445.42	4.52196
3449.44	7.36429
3453.46	2.56051
3457.47	2.72239
3461.49	3.47221
3465.5	3.39911
3469.51	4.73403
3473.51	5.87005
3477.52	3.26167
3481.52	-1.39387
3485.51	-0.874863
3489.51	2.67052
3493.5	2.8705
3497.49	0.418579
3501.48	-1.11456
3505.46	0.456306
3509.45	4.37092
3513.43	6.29634
3517.4	8.18346
3521.38	4.37482
3525.35	2.49667
3529.32	3.33209
3533.28	6.38042
3537.25	5.98108
3541.21	3.65851
3545.17	0.591881
3549.12	-1.00362
3553.08	-0.688721
3557.03	0.55114
3560.98	1.93463
3564.92	3.7083
3568.87	4.41753
3572.81	3.71405
3576.74	1.96424
3580.68	2.88729
3584.61	7.60944
3588.54	3.68604
3592.47	4.64746
3596.4	8.16421
3600.32	6.90671
3604.24	3.49998
3608.16	-1.708
3612.07	-1.98234
3615.98	6.23943
3619.89	7.40383
3623.8	3.31535
3627.71	2.07952
3631.61	4.54661
3635.51	1.2718
3639.41	-0.885147
3643.3	4.92614
3647.19	6.26359
3651.08	-2.7404
3654.97	-1.48886
3658.85	4.7428
3662.74	7.534
3666.62	7.08405
3670.49	-0.481453
3674.37	2.55939
3678.24	-1.76984
3682.11	3.93832
3685.98	2.84066
3689.84	1.03317
3693.7	0.0795975
3697.56	1.80556
3701.42	7.39521
3705.28	8.04193
3709.13	8.96016
3712.98	8.45415
3716.82	1.86173
3720.67	-4.86107
3724.51	-6.43349
3728.35	2.60883
3732.19	2.8689
3736.02	5.50869
3739.86	-1.04877
3743.69	3.28415
3747.51	3.4254
3751.34	1.53265
3755.16	3.05619
3758.98	3.67919
3762.8	3.70711
3766.61	3.40785
3770.43	3.62175
3774.24	5.48203
3778.05	5.76546
3781.85	4.06932
3785.65	1.18791
3789.45	3.98702
3793.25	8.18777
3797.05	9.39233
3800.84	7.13205
3804.63	4.84064
3808.42	2.23071
3812.21	1.49106
3815.99	4.58076
3819.77	7.52072
3823.55	7.13013
3827.33	4.27724
3831.1	-0.144249
3834.87	-0.0688171
3838.64	2.10835
3842.41	2.27232
3846.17	7.91386
3849.93	11.1991
3853.69	9.96928
3857.45	8.07314
3861.21	5.58582
3864.96	3.00039
3868.71	3.3617
3872.46	5.62313
3876.2	3.37157
3879.94	0.430367
3883.68	0.381248
3887.42	0.373154
3891.16	0.354996
3894.89	5.71336
3898.62	6.05728
3902.35	6.23993
3906.08	7.80382
3909.8	7.49883
3913.52	4.89345
3917.24	0.852295
3920.96	2.80965
3924.67	5.74542
3928.38	6.88496
3932.09	7.14379
3935.8	8.19855
3939.51	7.0861
3943.21	5.56007
3946.91	5.19196
3950.61	4.80213
3954.3	2.11099
3958	0.765129
3961.69	3.70754
3965.38	6.91489
3969.06	7.36803
3972.75	4.92524
3976.43	2.59678
3980.11	2.04324
3983.78	3.17672
3987.46	5.62767
3991.13	4.83958
3994.8	-0.288177
3998.47	-3.02409