File: Data/3-Raman/processed/bu20-H-trl1-FI02-v.txt
#Acq. time (s)=	15
#Accumulations=	3
#Range (cm-¹)=	100...4000
#Windows=	1
#Auto scanning=	Off
#Autofocus=	Off
#Macrospot=	Off
#AutoExposure=	Off
#Spike filter=	Multiple accum.
#Delay time (s)=	0
#Binning=	1
#Readout mode=	Signal
#DeNoise=	Lite
#ICS correction=	Off
#Dark correction=	Off
#Inst. Process=	Off
#Detector temperature (°C)=	-60.09
#Instrument=	LabRAM HR Evol
#Detector=	SIN-EM FIVIS
#Objective=	x100_VIS
#Grating=	150 (500nm)
#ND Filter=	100%
#Laser=	532nm_Edge
#Hole=	30.0125
#Temperature=	0
#Range=	Visible
#StageXY=	75x50mm Scan+
#StageZ=	Z motor
#X (µm)=	13597.1
#Y (µm)=	4790.7
#Z (µm)=	1906.5
#Full time(s)=	47
#Project=	Buranga
#Sample=	BU18FA20_G
#Site=	G_trl1
#Title=	20-H_trl1_FI02
#Remark=
#Date=	30.07.2019 18:00
#Acquired=	30.07.2019 18:00:02
#Data Range:Extract=	16.12.2021 15:36:30
#Base:Fit=	16.12.2021 15:36:40
#Base:Sub=	16.12.2021 15:49:25
103.656	1966.73
108.278	1684.77
112.899	1442.96
117.517	1221.9
122.131	1023.54
126.744	845.779
131.355	710.698
135.964	598.056
140.571	514.548
145.173	448.252
149.776	395.176
154.375	340.851
158.973	357.492
163.566	613.915
168.159	825.421
172.75	827.055
177.339	421.08
181.923	203.843
186.507	172.952
191.089	324.622
195.668	552.542
200.243	740.488
204.818	459.789
209.391	257.224
213.96	115.086
218.528	30.9358
223.094	-0.00244141
227.655	22.5743
232.217	96.3491
236.776	221.578
241.331	402.802
245.886	613.645
250.439	859.375
254.987	1057.76
259.535	897.629
264.081	428.846
268.622	247.598
273.164	239.482
277.703	507.795
282.238	1262.14
286.773	2055.92
291.305	2188.15
295.833	1232.48
300.362	778.858
304.885	527.021
309.409	368.364
313.93	308.303
318.448	260.744
322.965	370.076
327.477	521.047
331.99	661.402
336.5	787.404
341.007	880.011
345.513	942.394
350.014	980.659
354.516	1001.41
359.013	1016.61
363.51	922.076
368.005	784.638
372.496	641.105
376.987	514.597
381.473	421.372
385.96	364.012
390.442	315.218
394.923	340.186
399.401	355.189
403.879	334.32
408.352	277.417
412.825	191.065
417.294	130.912
421.763	127.102
426.227	129.403
430.692	96.235
435.152	50.3697
439.612	20.0929
444.068	2.24374
448.524	0.00842285
452.976	13.5812
457.427	51.3598
461.874	88.9879
466.32	111.899
470.765	106.134
475.205	88.7213
479.646	93.2546
484.083	105.279
488.519	157.193
492.951	235.147
497.381	336.496
501.811	427.596
506.237	470.135
510.663	393.869
515.084	297.64
519.504	190.328
523.923	134.226
528.338	92.4436
532.753	63.1724
537.164	47.4592
541.572	40.9561
545.981	41.1719
550.385	46.4671
554.788	52.239
559.19	61.4435
563.588	72.4474
567.986	82.6831
572.38	89.1358
576.771	92.6266
581.163	91.937
585.551	132.198
589.936	280.87
594.319	575.845
598.702	799.919
603.081	621.105
607.458	356.164
611.835	270.989
616.208	272.343
620.578	268.396
624.949	217.836
629.315	172.31
633.68	141.254
638.042	121.82
642.404	120.228
646.762	131.751
651.118	153.743
655.472	184.778
659.825	222.923
664.175	292.229
668.523	409.598
672.868	572.427
677.213	669.93
681.555	696.107
685.894	664.265
690.231	576.167
694.566	366.927
698.901	197.17
703.232	98.3026
707.561	52.7458
711.888	32.5723
716.212	21.0607
720.537	13.3878
724.858	8.64758
729.176	6.49741
733.493	7.44397
737.807	10.6295
742.119	15.9329
746.432	21.3772
750.74	27.8111
755.046	34.3991
759.35	49.6345
763.652	80.4875
767.952	142.377
772.25	241.035
776.546	399.968
780.842	629.826
785.133	917.403
789.423	1013.62
793.711	741.193
797.997	440.093
802.28	239.703
806.562	145.683
810.841	100.61
815.119	70.5923
819.394	52.5551
823.668	39.2036
827.941	31.0197
832.211	26.253
836.478	22.6517
840.743	19.1465
845.006	13.8745
849.268	8.6478
853.527	3.33673
857.784	-0.0700378
862.039	0.0535583
866.293	1.47113
870.544	2.91312
874.793	4.36252
879.04	5.15552
883.285	4.71832
887.528	4.57355
891.769	4.85236
896.008	6.24036
900.246	5.34259
904.481	4.3992
908.714	4.7475
912.945	6.75558
917.174	10.5498
921.401	16.8587
925.626	22.1727
929.849	30.5609
934.068	40.6152
938.287	55.765
942.504	79.7955
946.72	119.944
950.933	207.474
955.144	310.828
959.353	343.528
963.56	311.176
967.765	246.887
971.968	172.83
976.17	147.417
980.367	123.331
984.564	102.656
988.759	84.8946
992.953	71.1164
997.144	61.4244
1001.33	56.2796
1005.52	51.7766
1009.71	49.308
1013.89	49.225
1018.07	52.587
1022.25	59.8911
1026.43	71.5307
1030.6	89.6105
1034.78	111.961
1038.94	138.86
1043.11	183.296
1047.28	261.672
1051.45	422.782
1055.61	701.565
1059.77	1057.6
1063.93	1169.49
1068.09	864.947
1072.25	557.794
1076.4	389.539
1080.55	320.754
1084.7	358.459
1088.85	496.384
1092.99	736.296
1097.14	899.743
1101.28	964.257
1105.42	985.686
1109.56	1014.27
1113.69	1051.55
1117.83	1083.69
1121.96	1104.69
1126.09	1112.85
1130.22	1101.43
1134.35	1088.96
1138.47	1085.93
1142.59	1065.24
1146.71	955.482
1150.83	743.581
1154.95	649.41
1159.06	633.715
1163.18	681.107
1167.29	728.892
1171.4	692.843
1175.5	608.042
1179.61	497.089
1183.71	374.06
1187.81	255.554
1191.91	191.694
1196.01	160.297
1200.1	139.403
1204.2	130.012
1208.29	130.939
1212.38	137.97
1216.47	153.542
1220.55	175.391
1224.64	224.503
1228.72	270.671
1232.8	301.385
1236.88	319.671
1240.95	335.896
1245.03	349.553
1249.1	365.42
1253.17	373.557
1257.24	384.782
1261.31	377.104
1265.37	349.699
1269.44	283.771
1273.5	419.621
1277.56	1318.36
1281.61	1855.59
1285.67	1886.82
1289.72	638.048
1293.77	207.543
1297.83	165.195
1301.87	147.601
1305.92	134.747
1309.96	125.622
1314.01	119.729
1318.05	115.322
1322.09	113.009
1326.12	108.498
1330.16	105.401
1334.19	103.904
1338.22	104.471
1342.25	107.632
1346.28	113.003
1350.3	121.172
1354.33	132.046
1358.35	145.486
1362.37	170.422
1366.39	194.539
1370.4	226.166
1374.42	264.153
1378.43	973.947
1382.44	2545.16
1386.45	3200.38
1390.46	2220.59
1394.46	484.801
1398.46	249.28
1402.47	338.681
1406.46	366.927
1410.46	316.966
1414.46	159.315
1418.45	113.651
1422.45	100.924
1426.43	85.4501
1430.42	71.7313
1434.41	59.8174
1438.39	49.8838
1442.38	41.5301
1446.36	33.4192
1450.34	26.2502
1454.31	19.9124
1458.29	14.5954
1462.27	10.4345
1466.24	7.16418
1470.21	4.70795
1474.18	2.02618
1478.14	-0.0345459
1482.11	0.0300903
1486.07	1.61557
1490.03	3.99356
1493.99	6.07629
1497.95	7.23492
1501.9	8.14124
1505.86	8.15625
1509.81	8.35654
1513.76	8.92023
1517.71	9.76083
1521.65	9.42889
1525.6	8.23557
1529.54	7.3688
1533.48	6.33676
1537.42	5.96689
1541.36	6.34946
1545.29	5.85254
1549.23	4.75394
1553.16	3.41772
1557.09	2.63913
1561.02	2.74313
1564.94	5.02945
1568.87	7.08615
1572.79	8.5524
1576.71	9.48941
1580.63	9.87857
1584.55	9.2619
1588.47	7.02625
1592.38	6.20703
1596.29	6.83267
1600.2	7.96625
1604.11	9.36658
1608.02	10.7439
1611.92	11.0882
1615.83	10.6046
1619.73	9.89087
1623.63	9.27563
1627.53	8.57941
1631.42	7.81857
1635.32	7.02515
1639.21	6.35788
1643.1	6.61679
1646.99	7.60297
1650.88	10.0095
1654.76	8.62387
1658.64	7.88293
1662.53	7.48489
1666.41	4.86707
1670.28	0.716797
1674.16	0.128113
1678.04	0.216553
1681.91	1.16617
1685.78	4.32272
1689.65	7.66083
1693.52	9.23898
1697.38	9.98312
1701.25	8.45248
1705.11	6.70868
1708.97	5.99023
1712.83	5.03244
1716.69	4.12943
1720.54	3.02173
1724.4	2.30939
1728.25	2.0141
1732.1	2.20609
1735.95	2.82635
1739.79	3.39584
1743.64	5.25797
1747.48	6.88217
1751.33	7.39023
1755.17	8.98859
1759	10.3003
1762.84	11.5079
1766.68	12.1449
1770.51	11.9694
1774.34	11.2474
1778.17	9.8963
1782	8.42285
1785.82	8.16071
1789.65	7.67697
1793.47	6.08994
1797.29	3.8168
1801.11	1.76797
1804.93	-0.1651
1808.74	-0.310394
1812.56	-0.224274
1816.37	0.287567
1820.18	0.930054
1823.99	1.40549
1827.79	1.84476
1831.6	2.71225
1835.4	2.5032
1839.2	2.49152
1843	6.84369
1846.8	11.543
1850.6	14.9728
1854.39	11.5904
1858.19	7.98233
1861.98	6.06122
1865.77	4.70898
1869.56	3.9967
1873.34	3.94232
1877.13	4.41205
1880.91	5.16629
1884.69	5.76782
1888.47	6.29639
1892.25	12.3892
1896.03	13.0982
1899.8	12.098
1903.57	10.3032
1907.34	8.77255
1911.11	7.25171
1914.88	6.4747
1918.65	5.27142
1922.41	5.60248
1926.18	5.73074
1929.94	5.07689
1933.7	4.09058
1937.45	3.67418
1941.21	3.96288
1944.96	4.70361
1948.72	6.41252
1952.47	7.23048
1956.22	6.3206
1959.96	5.50011
1963.71	4.86729
1967.45	4.12766
1971.2	3.97852
1974.94	5.02518
1978.68	4.2749
1982.42	3.93524
1986.15	3.49384
1989.89	3.30739
1993.62	3.52048
1997.35	4.66423
2001.08	5.30406
2004.8	-1.11461
2008.53	0.562042
2012.25	1.18326
2015.98	4.81842
2019.7	11.8118
2023.42	12.5001
2027.13	12.9536
2030.85	12.0869
2034.56	11.5815
2038.28	12.6751
2041.99	13.6425
2045.7	14.4045
2049.41	12.9337
2053.11	11.7299
2056.82	9.01009
2060.52	5.58759
2064.22	3.66348
2067.92	3.83835
2071.62	4.11823
2075.31	4.3994
2079.01	4.55515
2082.7	4.82791
2086.39	4.13269
2090.08	3.01064
2093.77	1.35886
2097.45	0.313553
2101.14	-0.0279541
2104.82	0.498474
2108.5	1.96513
2112.18	3.77812
2115.86	5.79868
2119.54	8.61623
2123.21	11.1929
2126.88	13.3549
2130.56	14.6551
2134.23	15.2567
2137.89	15.4949
2141.56	15.7597
2145.23	16.4457
2148.89	16.4495
2152.55	16.6023
2156.21	17.5263
2159.87	21.0838
2163.53	19.8411
2167.18	17.8374
2170.84	17.6102
2174.49	18.9138
2178.14	21.9553
2181.79	24.9263
2185.44	27.6679
2189.08	29.0237
2192.73	29.6937
2196.37	29.7482
2200.01	29.1057
2203.65	28.5051
2207.29	28.9673
2210.92	30.0143
2214.56	30.1736
2218.19	28.9183
2221.82	28.5178
2225.45	26.601
2229.08	25.8473
2232.7	24.6749
2236.33	22.4994
2239.95	21.1707
2243.57	19.7346
2247.19	18.5348
2250.81	16.5767
2254.43	14.759
2258.04	15.4757
2261.66	17.5498
2265.27	20.4583
2268.88	22.8905
2272.49	21.1636
2276.1	14.4203
2279.7	13.8302
2283.31	13.8163
2286.91	14.3988
2290.51	15.473
2294.11	17.1702
2297.71	19.349
2301.3	16.8383
2304.9	14.6023
2308.49	19.4235
2312.08	22.432
2315.67	32.6565
2319.26	55.085
2322.85	306.305
2326.43	429.498
2330.02	360.691
2333.6	116.886
2337.18	26.3074
2340.76	17.6206
2344.34	13.4736
2347.91	14.6212
2351.49	15.4783
2355.06	15.8514
2358.63	15.8053
2362.2	17.5838
2365.77	17.8117
2369.33	16.552
2372.9	14.5698
2376.46	11.3346
2380.02	9.91383
2383.58	15.1663
2387.14	17.627
2390.7	17.95
2394.25	18.2506
2397.81	18.044
2401.36	17.6916
2404.91	17.0835
2408.46	16.646
2412.01	16.6298
2415.56	17.9734
2419.1	20.67
2422.64	11.6016
2426.18	7.79622
2429.72	8.01093
2433.26	9.93396
2436.8	13.145
2440.34	14.4312
2443.87	13.9657
2447.4	12.7147
2450.93	11.1337
2454.46	9.27803
2457.99	7.38239
2461.52	5.15881
2465.04	3.12633
2468.56	1.30997
2472.09	0.235641
2475.61	-0.338821
2479.13	-0.199753
2482.64	0.477692
2486.16	1.67909
2489.67	3.18974
2493.18	5.23299
2496.69	7.40184
2500.2	9.6272
2503.71	11.4502
2507.22	12.7156
2510.72	13.4471
2514.23	13.5744
2517.73	13.3187
2521.23	12.4301
2524.73	10.9972
2528.23	9.53285
2531.72	7.98157
2535.21	6.77562
2538.71	5.59377
2542.2	3.7872
2545.69	2.38747
2549.18	3.35631
2552.66	5.44518
2556.15	8.39261
2559.63	10.7793
2563.12	12.2063
2566.6	12.7771
2570.08	12.5426
2573.55	11.6241
2577.03	9.79314
2580.5	8.20039
2583.98	7.59747
2587.45	7.65717
2590.92	6.83751
2594.39	5.75842
2597.86	4.06955
2601.32	1.42557
2604.79	0.0435028
2608.25	-0.54422
2611.71	-0.435242
2615.17	0.163712
2618.63	1.2413
2622.08	2.83829
2625.54	4.67773
2628.99	4.48338
2632.45	4.6946
2635.9	4.10823
2639.35	3.59329
2642.79	2.61162
2646.24	1.8781
2649.69	2.28807
2653.13	3.84862
2656.57	6.91475
2660.01	7.88281
2663.45	6.21529
2666.89	3.89531
2670.32	3.25113
2673.76	3.68425
2677.19	5.4064
2680.62	8.54881
2684.05	12.4849
2687.48	15.0625
2690.91	16.4563
2694.33	16.2023
2697.76	14.1987
2701.18	10.74
2704.6	9.0379
2708.02	8.33862
2711.44	8.08112
2714.86	7.89861
2718.27	7.88791
2721.69	7.95599
2725.1	8.14972
2728.51	8.47841
2731.92	8.80128
2735.33	5.86629
2738.74	5.34288
2742.14	6.53693
2745.55	2.97333
2748.95	0.627075
2752.35	-0.238266
2755.75	0.37767
2759.15	1.67221
2762.54	4.01979
2765.94	7.10893
2769.33	9.461
2772.72	12.0835
2776.12	7.32663
2779.51	3.13635
2782.89	0.315826
2786.28	-0.0684052
2789.67	0.188751
2793.05	10.5542
2796.43	15.1342
2799.81	12.6944
2803.19	9.10023
2806.57	6.1333
2809.95	3.7511
2813.32	2.09001
2816.69	1.97498
2820.06	2.93742
2823.44	4.65582
2826.81	7.3811
2830.17	9.1479
2833.54	8.96278
2836.9	7.7859
2840.27	7.2122
2843.63	7.4585
2846.99	8.76939
2850.35	10.657
2853.71	12.662
2857.06	14.4
2860.42	15.7002
2863.77	16.4199
2867.12	16.5179
2870.48	16.0107
2873.83	15.1319
2877.17	13.7807
2880.52	12.1498
2883.86	11.0232
2887.21	11.1999
2890.55	9.67137
2893.89	7.33997
2897.23	5.32631
2900.57	3.5546
2903.91	2.43645
2907.24	2.17923
2910.57	3.18816
2913.91	5.41974
2917.24	9.53105
2920.57	14.1498
2923.9	15.0155
2927.22	13.8391
2930.55	10.5846
2933.87	7.63838
2937.19	6.46744
2940.51	6.34155
2943.83	5.3723
2947.15	5.09216
2950.47	5.50128
2953.79	4.65746
2957.1	3.27808
2960.41	2.58116
2963.72	1.41722
2967.03	2.00027
2970.34	2.89828
2973.65	8.67419
2976.95	14.7515
2980.26	17.0407
2983.56	8.91136
2986.86	4.32756
2990.16	0.957703
2993.46	-0.193939
2996.76	-0.281387
3000.06	0.348969
3003.35	1.67593
3006.64	3.51024
3009.94	6.01065
3013.23	8.81833
3016.51	11.2226
3019.8	11.6801
3023.09	11.9684
3026.38	10.8003
3029.66	10.3561
3032.94	9.52963
3036.22	8.3127
3039.5	6.49983
3042.78	4.47923
3046.05	3.18333
3049.33	2.50035
3052.6	2.80542
3055.88	2.78818
3059.15	3.31511
3062.42	5.41353
3065.69	7.95555
3068.95	10.2172
3072.22	11.9997
3075.48	12.9929
3078.75	13.5153
3082.01	13.7169
3085.27	13.6416
3088.53	13.7542
3091.79	13.5559
3095.04	12.7776
3098.3	11.9743
3101.55	10.0417
3104.8	8.76953
3108.05	11.2483
3111.3	17.0063
3114.55	18.4499
3117.8	19.6402
3121.04	18.6011
3124.29	17.5473
3127.53	16.2682
3130.77	14.9171
3134.01	13.5686
3137.25	12.5142
3140.49	13.7638
3143.72	15.0421
3146.96	16.6167
3150.19	18.5202
3153.42	20.7765
3156.65	23.2533
3159.88	25.5257
3163.11	27.2178
3166.34	28.544
3169.56	29.5555
3172.79	30.2794
3176.01	30.1888
3179.23	29.4913
3182.45	28.627
3185.67	28.1201
3188.88	29.1229
3192.1	30.6324
3195.31	33.3701
3198.53	36.7504
3201.74	40.2604
3204.95	42.5701
3208.16	43.4249
3211.37	42.9571
3214.57	42.4068
3217.78	41.9488
3220.98	40.8722
3224.18	41.0649
3227.39	42.6826
3230.59	45.3386
3233.78	47.1149
3236.98	47.2664
3240.18	46.0139
3243.37	45.8498
3246.56	47.1804
3249.76	48.1662
3252.95	49.4998
3256.14	51.0017
3259.32	53.3431
3262.51	54.3024
3265.7	55.0773
3268.88	55.6797
3272.06	56.0723
3275.24	56.534
3278.42	56.8196
3281.6	56.7696
3284.78	56.3403
3287.96	55.4196
3291.13	54.3537
3294.31	54.5195
3297.48	56.9716
3300.65	59.4259
3303.82	61.173
3306.99	62.5606
3310.15	63.3947
3313.32	63.9908
3316.48	64.0892
3319.65	65.2796
3322.81	67.985
3325.97	71.0474
3329.13	74.2233
3332.28	77.5286
3335.44	80.3854
3338.6	82.8369
3341.75	84.4674
3344.9	84.5723
3348.05	84.7363
3351.2	85.3957
3354.35	86.5879
3357.5	89.7136
3360.65	94.304
3363.79	99.802
3366.94	106.572
3370.08	111.348
3373.22	118.093
3376.36	121.633
3379.5	125.076
3382.63	129.248
3385.77	133.213
3388.9	139.035
3392.04	146.594
3395.17	156.8
3398.3	169.79
3401.43	185.478
3404.56	202.184
3407.69	235.695
3410.81	311.542
3413.94	406.429
3417.06	623.23
3420.18	1218.25
3423.3	2688.27
3426.42	4476.29
3429.54	4818.32
3432.65	3129.35
3435.77	1518.39
3438.88	711.425
3442	422.279
3445.11	345.567
3448.22	267.875
3451.33	239.918
3454.43	224.671
3457.54	215.311
3460.65	212.03
3463.75	209.102
3466.85	213.089
3469.95	222.055
3473.05	241.865
3476.15	272.151
3479.25	317.164
3482.35	369.648
3485.44	434.442
3488.54	542.911
3491.63	657.653
3494.72	907.958
3497.81	1224.86
3500.9	1680.5
3503.99	2286.22
3507.07	2899.35
3510.16	3246.49
3513.24	3036.64
3516.32	2482.79
3519.41	1838.94
3522.49	1364.1
3525.56	917.261
3528.64	716.43
3531.72	540.855
3534.79	421.7
3537.87	353.411
3540.94	303.758
3544.01	264.068
3547.08	224.767
3550.15	197.655
3553.22	174.338
3556.28	156.461
3559.35	142.587
3562.41	130.879
3565.47	120.391
3568.54	111.107
3571.6	103.001
3574.65	96.115
3577.71	90.3657
3580.77	85.9082
3583.82	81.9557
3586.88	78.231
3589.93	74.8071
3592.98	71.2438
3596.03	68.2108
3599.08	64.6602
3602.13	61.4101
3605.18	58.7681
3608.22	57.6084
3611.27	55.6137
3614.31	52.5576
3617.35	49.5085
3620.39	46.0935
3623.43	42.2256
3626.47	41.1949
3629.5	40.4366
3632.54	38.3448
3635.57	36.4416
3638.61	34.8634
3641.64	33.2731
3644.67	31.5678
3647.7	29.7921
3650.73	27.463
3653.75	25.0816
3656.78	22.2618
3659.8	19.5522
3662.83	17.0397
3665.85	14.7314
3668.87	12.7892
3671.89	11.093
3674.91	9.4648
3677.92	7.85841
3680.94	6.12849
3683.96	5.33342
3686.97	5.99602
3689.98	5.74966
3692.99	5.58914
3696	3.51285
3699.01	2.96973
3702.02	3.05301
3705.02	3.30956
3708.03	5.39615
3711.03	5.04553
3714.03	3.73593
3717.04	3.40483
3720.04	3.32265
3723.04	2.89023
3726.03	1.25525
3729.03	0.427551
3732.03	-0.0635071
3735.02	-0.346741
3738.01	-0.23555
3741	-0.0489044
3743.99	0.462418
3746.98	0.535309
3749.97	0.33696
3752.96	0.271057
3755.95	1.1424
3758.93	2.4438
3761.91	3.95929
3764.9	5.53798
3767.88	7.77928
3770.86	9.89348
3773.84	11.278
3776.81	11.5301
3779.79	11.239
3782.77	10.4497
3785.74	9.10555
3788.71	7.63924
3791.68	5.55031
3794.65	3.29465
3797.62	1.0896
3800.59	-0.568863
3803.56	-0.774231
3806.52	-0.200027
3809.49	0.768372
3812.45	3.10829
3815.41	4.78847
3818.37	5.50304
3821.33	4.34428
3824.29	1.75667
3827.25	0.410492
3830.21	2.19083
3833.16	3.29968
3836.11	6.2729
3839.07	6.08292
3842.02	4.41193
3844.97	3.95723
3847.92	4.37297
3850.87	4.99135
3853.81	5.83749
3856.76	6.05954
3859.7	6.39546
3862.65	6.47603
3865.59	6.92473
3868.53	8.47878
3871.47	8.62883
3874.41	8.40695
3877.34	7.94269
3880.28	7.72073
3883.22	9.15092
3886.15	10.5213
3889.08	11.1428
3892.01	11.6049
3894.94	11.9844
3897.87	12.2366
3900.8	12.3002
3903.73	12.1743
3906.65	11.7921
3909.58	10.7726
3912.5	9.45833
3915.42	7.96619
3918.35	6.9281
3921.27	7.56168
3924.18	7.93764
3927.1	8.00165
3930.02	7.97766
3932.93	8.17206
3935.85	8.23227
3938.76	8.61925
3941.67	9.05244
3944.58	9.47327
3947.49	9.45587
3950.4	9.65047
3953.31	8.92566
3956.22	7.74098
3959.12	6.24557
3962.02	3.98598
3964.93	3.21251
3967.83	3.35307
3970.73	4.03735
3973.63	4.26912
3976.53	4.63652
3979.42	4.29996
3982.32	4.48254
3985.21	4.83191
3988.11	4.95291
3991	4.26871
3993.89	3.39328
3996.78	-0.0121613
3999.67	11.6501