File: Data/3-Raman/processed/bu20-j-ff1-fi01-v_1800 (450-850nm)_532nm_edge_100%_x100_vis_lwd_h30um_60sx2_02.txt
#Acq. time (s)=	60
#Accumulations=	2
#Range (cm-¹)=	1200...2365
#Windows=	3
#Auto scanning=	Off
#Autofocus=	Off
#Macrospot=	Off
#AutoExposure=	Off
#Spike filter=	Multiple accum.
#Delay time (s)=	2
#Binning=	1
#Readout mode=	Signal
#DeNoise=	Off
#ICS correction=	On
#Dark correction=	Off
#Inst. Process=	Off
#Detector Gain=	Best Dynamic
#Detector ADC=	50 kHz EM
#Detector EM gain=	150
#Detector temperature (°C)=	-60.09
#Instrument=	LabRAM HR Evol
#Detector=	SIN-EM FIVIS
#Objective=	x100_VIS_LWD
#Grating=	1800 (450-850nm)
#ND Filter=	100%
#Laser=	532nm_Edge
#Hole=	30.0125
#Temperature=	40
#Range=	Visible
#StageXY=	75x50mm Scan+
#StageZ=	Z motor
#X (µm)=	0
#Y (µm)=	0
#Z (µm)=	63.6
#Full time(mm:ss)=	6:19
#Project=	21_08_11
#Sample=	BU20
#Site=
#Title=	BU20-J-FF1-FI01-V_1800 (450-850nm)_532nm_Edge_100%_x100_VIS_LWD_H30um_60sX2
#Remark=
#Date=	13.08.2021 15:05
#Acquired=	13.08.2021 15:05:04
#Data Range:Extract=	16.12.2021 15:36:30
#Base:Fit=	16.12.2021 15:36:40
#Base:Fit=	16.12.2021 15:55:45
#Base:Sub=	16.12.2021 15:55:46
1202.73	-3.02933
1203.84	-0.402588
1204.95	8.13983
1206.06	3.27072
1207.18	17.8416
1208.29	-6.99472
1209.4	-10.2793
1210.51	-15.9393
1211.62	9.27103
1212.73	1.51224
1213.84	-9.12988
1214.95	2.70425
1216.06	1.41632
1217.17	-2.14038
1218.28	0.861603
1219.38	-21.444
1220.49	0.912598
1221.6	-7.77029
1222.71	14.9556
1223.82	13.4559
1224.93	3.93997
1226.03	16.8451
1227.14	22.7534
1228.25	8.03937
1229.36	27.5285
1230.46	45.8789
1231.57	76.6469
1232.67	66.1614
1233.78	92.6349
1234.89	69.8863
1235.99	63.8034
1237.1	46.7202
1238.2	21.0991
1239.31	19.9823
1240.41	33.7581
1241.52	35.8856
1242.62	33.0187
1243.73	31.1147
1244.83	44.6625
1245.94	24.5217
1247.04	45.5425
1248.14	49.5843
1249.25	72.7603
1250.35	71.6049
1251.45	64.1189
1252.56	74.374
1253.66	51.6065
1254.76	35.2376
1255.86	40.6444
1256.97	54.4182
1258.07	30.4112
1259.17	56.5884
1260.27	45.1888
1261.37	57.8904
1262.47	111.312
1263.58	173.681
1264.68	224.082
1265.77	98.7216
1266.88	70.9989
1267.98	69.7076
1269.08	48.1283
1270.17	46.8479
1271.27	59.3734
1272.37	63.153
1273.47	57.4778
1274.57	43.0796
1275.67	56.08
1276.77	57.6181
1277.87	69.7257
1278.97	67.0287
1280.06	72.357
1281.16	111.818
1282.26	262.604
1283.36	1018.29
1284.45	3534.71
1285.55	772.909
1286.65	201.206
1287.74	124.27
1288.84	65.6639
1289.93	50.3319
1291.03	43.0271
1292.13	50.5841
1293.22	39.3632
1294.32	27.1614
1295.41	22.6303
1296.51	25.2418
1297.6	38.8232
1298.69	31.4718
1299.79	3.14151
1300.88	30.766
1301.98	4.7106
1303.07	12.172
1304.16	22.8671
1305.26	30.1719
1306.35	16.3836
1307.44	20.8124
1308.54	23.1502
1309.63	25.6042
1310.72	16.2767
1311.81	39.8364
1312.9	14.6285
1314	10.5272
1315.09	22.4843
1316.18	15.2884
1317.27	17.6331
1318.36	12.5901
1319.45	20.1349
1320.54	14.9209
1321.63	37.9126
1322.72	17.7866
1323.81	16.9423
1324.9	21.3058
1325.99	20.6948
1327.08	30.7353
1328.17	7.22763
1329.26	15.9094
1330.35	23.2621
1331.43	21.8246
1332.52	16.2616
1333.61	12.8256
1334.7	28.3915
1335.78	9.41788
1336.87	17.811
1337.96	18.7662
1339.05	21.9494
1340.13	1.24344
1341.22	46.3773
1342.31	26.3333
1343.39	4.4061
1344.48	24.3908
1345.57	25.2093
1346.65	3.96924
1347.74	24.7105
1348.82	13.2133
1349.91	11.037
1350.99	18.1668
1352.08	16.2752
1353.16	14.0817
1354.24	4.80222
1355.33	23.5708
1356.41	24.7642
1357.5	37.2018
1358.58	20.4855
1359.66	18.2959
1360.75	27.5406
1361.83	14.1471
1362.91	42.2739
1363.99	23.9205
1365.08	51.7926
1366.16	37.1053
1367.24	38.0523
1368.32	71.433
1369.4	151.209
1370.48	61.174
1371.56	51.5238
1372.65	68.8098
1373.73	50.2675
1374.81	96.6848
1375.89	91.7256
1376.97	85.2687
1378.05	123.229
1379.13	143.052
1380.21	186.605
1381.28	184.226
1382.37	197.846
1383.44	196.445
1384.52	241.967
1385.6	396.799
1386.68	1267.14
1387.76	6358.36
1388.84	988.59
1389.91	296.919
1390.99	217.963
1392.07	165.412
1393.14	85.5167
1394.22	76.3643
1395.3	85.9376
1396.37	92.1243
1397.45	69.5663
1398.53	56.5642
1399.6	90.6785
1400.68	53.1815
1401.75	51.6134
1402.83	46.3161
1403.9	64.7248
1404.98	52.4195
1406.05	45.1946
1407.13	120.296
1408.2	243.643
1409.28	457.379
1410.35	154.635
1411.43	62.2635
1412.5	45.7305
1413.57	40.4021
1414.64	17.4656
1415.72	36.1932
1416.79	22.156
1417.86	22.4268
1418.93	24.6908
1420.01	39.9987
1421.08	16.3483
1422.15	19.0471
1423.22	34.504
1424.29	27.6521
1425.36	39.4541
1426.44	31.1682
1427.51	14.493
1428.58	24.9136
1429.65	19.1936
1430.72	14.7158
1431.79	12.8349
1432.86	11.5762
1433.93	5.34805
1435	2.63687
1436.07	-0.340088
1437.13	15.0973
1438.2	-2.08362
1439.27	21.8053
1440.34	12.9644
1441.41	8.96011
1442.48	3.09967
1443.55	4.13361
1444.61	18.9459
1445.68	14.9507
1446.75	16.0395
1447.81	-8.45547
1448.88	13.3621
1449.95	2.07007
1451.01	-1.96744
1452.08	6.3194
1453.15	-5.70364
1454.21	3.65048
1455.28	16.1351
1456.34	6.05585
1457.41	6.08865
1458.47	3.22934
1459.54	3.40289
1460.6	1.40323
1461.67	3.42212
1462.73	-4.88184
1463.8	-5.64203
1464.86	7.43082
1465.92	-0.900665
1466.99	1.08377
1468.05	4.25589
1469.11	10.4158
1470.18	21.5402
1471.24	-8.01898
1472.3	1.24988
1473.36	16.532
1474.43	6.53122
1475.49	-3.53406
1476.55	7.65497
1477.61	2.65079
1478.67	20.891
1479.73	4.49634
1480.79	13.514
1481.86	-17.6172
1482.91	0.954254
1483.98	1.89362
1485.04	5.88995
1486.1	3.71521
1487.16	16.9928
1488.22	2.72214
1489.28	-4.37115
1490.33	0.757538
1491.39	-8.31955
1492.45	7.99945
1493.51	-14.1147
1494.57	-5.85086
1495.63	-8.07666
1496.68	-7.05856
1497.74	-8.94284
1498.8	-1.67004
1499.86	1.60117
1500.91	2.66699
1501.97	1.74554
1503.03	-7.40881
1504.09	-0.154541
1505.14	-0.132141
1506.2	11.9039
1507.25	4.10709
1508.31	-4.83362
1509.37	6.42105
1510.42	7.46591
1511.48	11.099
1512.53	0.701447
1513.59	-4.10971
1514.64	-1.0434
1515.7	-4.25742
1516.75	0.810425
1517.8	-5.95135
1518.86	3.32721
1519.91	3.46088
1520.97	-5.33261
1522.02	-1.25916
1523.07	0.623871
1524.13	-8.53027
1525.18	-0.291931
1526.23	-7.90289
1527.28	4.19919
1528.33	9.23157
1529.39	-1.71967
1530.44	4.54654
1531.49	6.77704
1532.54	10.0943
1533.59	8.47095
1534.64	-3.508
1535.69	6.28983
1536.74	2.03577
1537.8	-15.036
1538.85	-3.79584
1539.9	-7.95181
1540.95	7.27939
1542	1.10135
1543.05	18.9408
1544.09	-8.00922
1545.14	16.544
1546.19	11.781
1547.24	13.0378
1548.29	3.078
1549.34	4.58572
1550.39	14.3686
1551.43	7.14417
1552.48	18.5676
1553.53	2.21649
1554.58	0.984406
1555.62	6.14267
1556.67	16.2798
1557.72	7.27341
1558.76	6.03564
1559.81	15.9442
1560.86	14.0323
1561.9	-3.54901
1562.95	-10.4483
1563.99	2.93106
1565.04	15.8001
1566.08	15.892
1567.13	-4.73303
1568.17	15.2409
1569.22	15.1606
1570.26	2.35001
1571.31	2.35559
1572.35	7.32785
1573.39	26.2634
1574.44	2.71872
1575.48	3.02911
1576.53	15.9256
1577.57	11.6158
1578.61	20.6028
1579.65	7.86606
1580.7	6.93854
1581.74	3.87402
1582.78	14.8851
1583.82	12.0057
1584.86	13.1697
1585.91	22.0913
1586.95	6.11349
1587.99	14.232
1589.03	25.4886
1590.07	14.743
1591.11	23.8633
1592.15	9.78281
1593.19	27.3918
1594.23	15.4368
1595.27	28.5067
1596.31	18.6649
1597.35	19.8778
1598.39	29.6956
1599.43	9.73544
1600.47	11.5704
1601.51	16.2627
1602.54	8.18887
1603.58	16.0648
1604.62	25.1148
1605.66	12.4964
1606.7	21.6602
1607.73	39.1118
1608.77	27.6451
1609.81	20.3559
1610.84	31.5755
1611.88	17.3436
1612.92	17.5765
1613.95	15.9661
1614.99	17.3245
1616.03	17.3635
1617.06	24.3554
1618.1	24.4777
1619.13	30.4431
1620.17	23.6621
1621.2	22.5951
1622.24	25.4445
1623.27	25.8416
1624.31	24.8232
1625.34	32.431
1626.37	23.6039
1627.41	37.2987
1628.44	25.3911
1629.48	34.2489
1630.51	21.5439
1631.29	27.1415
1632.33	11.7828
1633.38	36.2899
1634.42	22.7111
1635.47	14.8633
1636.52	18.751
1637.56	20.7044
1638.6	28.642
1639.65	42.5242
1640.69	49.6886
1641.74	26.0742
1642.78	33.0348
1643.82	21.2334
1644.87	37.0972
1645.91	46.0418
1646.95	22.4155
1648	25.5042
1649.04	43.6342
1650.08	36.0154
1651.13	31.4177
1652.17	40.4036
1653.21	44.403
1654.25	17.0258
1655.29	42.1159
1656.33	38.5051
1657.38	26.6854
1658.42	47.3621
1659.46	9.7807
1660.5	30.7628
1661.54	28.16
1662.58	26.7987
1663.62	26.3867
1664.66	24.9648
1665.7	47.0789
1666.74	28.8027
1667.78	29.6682
1668.82	22.2726
1669.86	24.3205
1670.9	20.7397
1671.93	13.969
1672.97	29.9171
1674.01	25.2299
1675.05	28.5054
1676.09	24.6883
1677.12	29.7118
1678.16	16.7168
1679.2	33.4765
1680.24	14.6773
1681.27	22.6277
1682.31	23.7216
1683.35	26.7671
1684.38	20.8293
1685.42	15.9769
1686.45	21.1542
1687.49	36.9777
1688.53	17.1479
1689.56	28.836
1690.6	18.1998
1691.63	19.3799
1692.67	20.2776
1693.7	6.25909
1694.74	11.1671
1695.77	15.3084
1696.8	14.3856
1697.84	25.0146
1698.87	13.1618
1699.91	17.1761
1700.94	2.43497
1701.97	16.0686
1703.01	17.0304
1704.04	12.2254
1705.07	7.3912
1706.1	10.2577
1707.14	11.0219
1708.17	8.73621
1709.2	17.3734
1710.23	25.3252
1711.26	11.8539
1712.3	10.7459
1713.33	13.2531
1714.36	7.32495
1715.39	17.3064
1716.42	10.3439
1717.45	16.7136
1718.48	1.8342
1719.51	7.74664
1720.54	2.8399
1721.57	13.3437
1722.6	16.0324
1723.63	-0.516388
1724.66	-4.55792
1725.69	2.92676
1726.71	0.937134
1727.74	2.94388
1728.77	8.59897
1729.8	7.04172
1730.83	1.54712
1731.85	5.45963
1732.88	4.35269
1733.91	-5.65555
1734.94	1.74829
1735.97	5.50397
1736.99	-1.31891
1738.02	8.16052
1739.04	-10.3366
1740.07	-1.1463
1741.1	-0.385284
1742.12	9.13998
1743.15	4.34671
1744.17	-3.42014
1745.2	2.39337
1746.23	6.03702
1747.25	-0.877228
1748.28	1.06805
1749.3	3.2175
1750.32	-4.10318
1751.35	-3.12708
1752.37	-0.486298
1753.4	8.89957
1754.42	-3.64948
1755.44	-10.4252
1756.47	1.68637
1757.49	-2.21265
1758.51	0.855713
1759.54	0.930878
1760.56	10.3848
1761.58	-6.83969
1762.6	-0.0296936
1763.63	-3.71753
1764.65	-1.47089
1765.67	-5.13437
1766.69	6.30716
1767.71	1.47815
1768.73	8.82758
1769.75	2.95642
1770.77	-0.58139
1771.79	-5.98019
1772.82	6.65051
1773.84	-0.782227
1774.86	8.94269
1775.87	-1.18103
1776.89	-6.00467
1777.91	2.4248
1778.93	1.25854
1779.95	10.0093
1780.97	-2.21381
1781.99	2.79926
1783.01	-5.54416
1784.03	-3.35706
1785.05	0.603607
1786.06	-2.23541
1787.08	-1.87836
1788.1	9.44537
1789.12	-1.65381
1790.13	-1.45154
1791.15	0.24057
1792.17	8.91318
1793.18	1.39227
1794.2	15.8454
1795.22	4.01413
1796.23	-0.499817
1797.25	1.70328
1798.27	10.5159
1799.28	8.50616
1800.3	11.2757
1801.31	10.3524
1802.33	0.944458
1803.34	4.10934
1804.36	3.37451
1805.37	14.3185
1806.38	8.78613
1807.4	7.90594
1808.41	14.7476
1809.43	6.18192
1810.44	-2.44638
1811.45	4.34467
1812.47	5.5065
1813.48	12.4915
1814.49	5.16821
1815.5	13.071
1816.52	2.54187
1817.53	9.07532
1818.54	15.1105
1819.55	11.4254
1820.56	1.95291
1821.58	10.8907
1822.59	12.97
1823.6	21.6601
1824.61	9.24106
1825.62	4.52148
1826.63	3.64206
1827.64	5.73718
1828.65	11.4861
1829.66	5.65399
1830.67	31.7979
1831.68	12.6522
1832.69	4.14883
1833.7	8.14224
1834.71	10.5886
1835.72	12.3095
1836.73	11.079
1837.74	16.0124
1838.75	8.13373
1839.75	12.0244
1840.76	9.38721
1841.77	8.94202
1842.78	3.12845
1843.78	7.00183
1844.79	7.05045
1845.8	14.223
1846.81	15.3767
1847.81	6.84644
1848.82	16.2546
1849.83	5.3233
1850.83	16.5902
1851.84	6.92368
1852.84	0.221161
1853.85	5.76102
1854.85	4.5748
1855.86	-2.31116
1856.87	13.9753
1857.87	3.30481
1858.88	8.79227
1859.88	10.6802
1860.88	-1.50403
1861.89	-5.2648
1862.89	13.6236
1863.9	5.77496
1864.9	-2.10181
1865.9	7.95728
1866.91	0.831024
1867.91	8.25854
1868.91	11.1505
1869.92	12.0678
1870.92	4.45612
1871.92	2.43881
1872.92	2.29712
1873.92	8.7941
1874.93	7.55585
1875.93	22.2441
1876.93	-2.75067
1877.93	2.67551
1878.93	17.0232
1879.93	8.33231
1880.93	1.61978
1881.93	13.3008
1882.93	7.77066
1883.94	6.26053
1884.94	-6.73541
1885.94	3.98117
1886.93	11.2858
1887.93	5.3027
1888.93	-3.50922
1889.93	4.10657
1890.93	0.438446
1891.93	3.24786
1892.93	1.9762
1893.93	3.62039
1894.92	-2.99194
1895.92	-3.75604
1896.92	-3.54483
1897.92	9.62259
1898.92	4.68637
1899.91	-3.86722
1900.91	0.0596924
1901.91	3.16995
1902.9	3.1171
1903.9	-2.57184
1904.9	4.93137
1905.89	-2.80133
1906.89	7.4581
1907.88	0.112061
1908.88	-1.5961
1909.88	2.55325
1910.87	8.48508
1911.87	-7.52811
1912.86	0.971619
1913.86	2.22894
1914.85	7.20544
1915.85	1.54453
1916.84	-2.40088
1917.83	3.26129
1918.83	-2.05115
1919.82	8.68344
1920.81	2.2182
1921.81	-0.465881
1922.8	4.1445
1923.79	4.02145
1924.79	2.13562
1925.78	0.576355
1926.77	14.1427
1927.76	2.0043
1928.76	18.2807
1929.75	7.25235
1930.74	11.2748
1931.73	5.46027
1932.72	7.23322
1933.71	7.66095
1934.7	6.72659
1935.69	1.07861
1936.68	10.4439
1937.67	4.5
1938.67	8.49011
1939.66	5.8111
1940.64	4.36694
1941.63	8.87717
1942.62	8.41177
1943.61	2.48996
1944.6	0.892883
1945.59	9.78564
1946.58	9.90643
1947.57	2.20197
1948.56	1.29144
1949.55	5.40869
1950.53	5.90961
1951.52	1.52792
1952.51	10.3241
1953.5	8.14404
1954.48	-1.96912
1955.47	2.0795
1956.46	15.9961
1957.44	5.68506
1958.43	18.2492
1959.42	8.50446
1960.4	3.5126
1961.39	10.1086
1962.38	2.49689
1963.36	4.47491
1964.35	7.41422
1965.33	3.60513
1966.32	8.65948
1967.3	-1.8414
1968.29	3.9379
1969.27	9.40118
1970.26	-0.432831
1971.24	2.31497
1972.23	3.34363
1973.21	9.87183
1974.19	13.6255
1975.18	8.9559
1976.16	10.993
1977.14	3.27301
1978.12	3.10861
1979.11	-0.732697
1980.09	9.76108
1981.07	9.60501
1982.06	9.52444
1983.04	14.0316
1984.02	11.0474
1985	1.29547
1985.98	6.17859
1986.96	-2.41345
1987.95	0.994812
1988.93	7.82532
1989.91	2.57263
1990.89	2.72998
1991.87	1.02036
1992.85	16.3987
1993.83	7.88016
1994.81	7.39832
1995.79	8.57489
1996.77	-0.173401
1997.75	0.979706
1998.73	5.64432
1999.71	3.15601
2000.69	0.452576
2001.66	4.63608
2002.64	-0.731567
2003.62	2.65588
2004.6	4.75763
2005.58	1.58099
2006.55	4.26389
2007.53	2.71054
2008.51	1.66846
2009.49	9.92422
2010.46	-1.98581
2011.44	-3.10666
2012.41	1.45041
2013.4	-5.57532
2014.39	-4.19131
2015.38	7.20779
2016.37	-1.86926
2017.36	-3.95633
2018.34	3.0914
2019.33	0.866455
2020.32	-0.139862
2021.31	1.75497
2022.3	2.49686
2023.28	-1.53488
2024.27	0.0116882
2025.26	-6.89551
2026.24	6.3324
2027.23	-5.15811
2028.22	-4.89444
2029.2	1.23453
2030.19	0.198944
2031.18	-2.25864
2032.16	6.4238
2033.15	0.207214
2034.13	9.90247
2035.12	-0.130524
2036.1	7.60989
2037.09	-5.42975
2038.07	-4.65115
2039.06	-0.185242
2040.04	-3.29895
2041.02	3.92792
2042.01	-0.884491
2042.99	-3.64325
2043.98	7.84628
2044.96	-3.58212
2045.94	2.96979
2046.93	-4.2301
2047.91	-5.46896
2048.89	-2.49814
2049.87	-7.7515
2050.85	-4.94238
2051.84	3.39316
2052.82	-1.12894
2053.8	1.05798
2054.78	0.0974121
2055.77	-0.0630493
2056.75	-7.59988
2057.73	-3.72882
2058.71	7.75818
2059.69	10.5754
2060.67	-7.2326
2061.65	-6.24002
2062.63	2.32303
2063.61	0.599426
2064.59	0.751617
2065.57	5.75754
2066.55	4.94119
2067.53	-1.48727
2068.51	0.496368
2069.49	4.86758
2070.47	-13.5155
2071.45	23.5693
2072.42	1.8342
2073.4	1.82349
2074.38	4.81616
2075.36	-3.1748
2076.34	11.9923
2077.31	0.346405
2078.29	4.25571
2079.27	6.45404
2080.25	-0.950226
2081.22	-1.02545
2082.2	2.79074
2083.18	8.42908
2084.15	3.69754
2085.13	-5.74634
2086.11	12.4682
2087.08	9.77893
2088.06	2.22391
2089.03	-2.3974
2090.01	-1.30954
2090.98	-1.19492
2091.96	1.98785
2092.93	0.424622
2093.91	7.29376
2094.88	3.40524
2095.86	3.23047
2096.83	-0.697144
2097.8	5.81357
2098.78	4.78027
2099.75	18.0421
2100.73	4.92212
2101.7	2.11938
2102.67	3.88974
2103.64	8.55655
2104.62	-3.64294
2105.59	2.26056
2106.56	-2.4158
2107.53	1.24008
2108.51	9.50235
2109.48	2.04926
2110.45	12.4874
2111.42	-0.916504
2112.39	9.55191
2113.36	9.74921
2114.34	-2.65564
2115.31	12.4857
2116.28	7.54495
2117.25	6.53986
2118.22	4.3671
2119.19	3.13831
2120.16	3.95074
2121.13	-2.48898
2122.1	5.32721
2123.07	9.23538
2124.04	2.40787
2125.01	2.83838
2125.97	9.11539
2126.94	-2.47919
2127.91	3.0914
2128.88	0.213684
2129.85	5.80225
2130.82	-0.954071
2131.78	13.041
2132.75	13.804
2133.72	-6.93164
2134.69	4.37125
2135.66	1.35693
2136.62	4.04016
2137.59	5.06741
2138.55	3.13626
2139.52	-8.40506
2140.49	7.4505
2141.45	-1.17944
2142.42	8.28265
2143.39	-6.49963
2144.35	4.17798
2145.32	-3.49548
2146.28	6.73251
2147.25	7.50726
2148.21	3.59314
2149.18	-1.405
2150.14	10.505
2151.11	-0.667053
2152.07	3.15356
2153.04	7.64722
2154	-6.6568
2154.96	2.20383
2155.93	-3.68958
2156.89	1.8952
2157.85	5.78952
2158.82	-2.70538
2159.78	3.56363
2160.74	-8.7673
2161.7	-5.12012
2162.67	-2.39676
2163.63	-1.60901
2164.59	-9.27383
2165.55	-2.71216
2166.52	-0.0898438
2167.48	-0.435364
2168.44	-2.51404
2169.4	-5.97479
2170.36	6.33279
2171.32	-0.580688
2172.28	0.0402222
2173.24	-3.69614
2174.2	-3.6192
2175.16	-9.24857
2176.12	-1.91992
2177.08	3.63141
2178.04	1.67068
2179	1.59418
2179.96	1.57938
2180.92	-6.84897
2181.88	-10.6941
2182.84	0.25882
2183.8	3.69534
2184.75	8.36105
2185.71	2.02875
2186.67	-9.73477
2187.63	5.27673
2188.59	5.02072
2189.54	2.83807
2190.5	7.50665
2191.46	11.2727
2192.41	-2.5249
2193.37	7.0314
2194.33	-3.79654
2195.29	5.31427
2196.24	-2.48734
2197.2	-0.807648
2198.15	-5.27396
2199.11	3.45355
2200.06	3.0675
2201.02	-2.29965
2201.98	4.76184
2202.93	-4.76773
2203.89	1.61282
2204.84	-2.71664
2205.79	-1.98441
2206.75	-6.67078
2207.7	-0.850098
2208.66	-9.03568
2209.61	-1.56882
2210.57	7.92444
2211.52	3.49341
2212.47	10.9861
2213.43	8.05157
2214.38	-0.936951
2215.33	4.73575
2216.28	-1.82147
2217.24	8.45471
2218.19	-5.51828
2219.14	-6.26685
2220.09	2.19534
2221.05	4.81415
2222	-3.77563
2222.95	1.04358
2223.9	8.86139
2224.85	-7.69223
2225.8	3.82922
2226.75	-0.631165
2227.71	5.9747
2228.66	-5.35126
2229.61	5.15295
2230.56	8.21609
2231.51	7.5509
2232.46	4.97189
2233.41	-5.16077
2234.36	7.99054
2235.3	6.80588
2236.25	8.75204
2237.2	4.3046
2238.15	-1.87109
2239.1	4.95642
2240.05	-0.933899
2241	2.17432
2241.95	4.16913
2242.89	-0.534546
2243.84	2.22086
2244.79	-2.14105
2245.74	7.58496
2246.68	1.15018
2247.63	0.24762
2248.58	-1.70828
2249.52	14.4626
2250.47	5.72952
2251.42	13.1779
2252.36	10.579
2253.31	-4.10922
2254.25	5.55396
2255.2	10.3003
2256.15	-7.54266
2257.09	17.3445
2258.04	1.30447
2258.98	4.31253
2259.93	11.1018
2260.87	14.2063
2261.82	3.845
2262.76	9.81921
2263.7	8.36517
2264.65	6.81683
2265.59	10.7215
2266.54	7.59137
2267.48	1.66809
2268.42	2.59705
2269.37	0.062561
2270.31	0.383179
2271.25	8.25021
2272.19	4.55786
2273.14	11.3398
2274.08	8.54919
2275.02	10.5597
2275.96	8.83694
2276.91	5.31647
2277.85	1.92017
2278.79	10.5898
2279.73	-3.18661
2280.67	3.33377
2281.61	4.28516
2282.55	7.42203
2283.49	-5.53735
2284.43	4.43787
2285.37	3.5722
2286.31	3.48767
2287.25	3.85739
2288.19	3.87686
2289.13	3.55008
2290.07	11.0341
2291.01	-4.11154
2291.95	2.87967
2292.89	9.89493
2293.83	3.17969
2294.77	7.82779
2295.71	6.71402
2296.64	-6.84787
2297.58	4.07339
2298.52	-0.470337
2299.46	12.2499
2300.4	2.70618
2301.33	-1.98505
2302.27	3.78122
2303.21	-2.97464
2304.14	2.03934
2305.08	11.8817
2306.02	-1.50168
2306.96	3.3335
2307.89	0.33902
2308.83	3.3674
2309.76	0.770355
2310.7	4.58728
2311.63	0.18454
2312.57	1.0271
2313.5	3.3121
2314.44	6.65103
2315.38	3.63525
2316.31	6.18011
2317.24	12.091
2318.18	-0.547028
2319.11	6.06155
2320.05	9.93405
2320.98	4.34909
2321.91	14.3744
2322.85	24.142
2323.78	22.2885
2324.71	23.9631
2325.65	32.4038
2326.58	97.7327
2327.51	250.744
2328.45	777.9
2329.38	218.635
2330.31	50.0848
2331.24	35.7767
2332.17	24.1493
2333.11	10.5427
2334.04	-0.198029
2334.97	-3.16098
2335.9	9.37244
2336.83	10.308
2337.76	10.2713
2338.69	3.57391
2339.62	10.2764
2340.55	-2.41943
2341.48	11.6515
2342.41	1.94641
2343.34	0.999573
2344.27	-0.848358
2345.2	2.86139
2346.13	2.74075
2347.06	-2.07693
2347.99	-5.7825
2348.92	9.40088
2349.85	-2.69516
2350.77	8.10303
2351.7	2.93484
2352.63	4.2981
2353.56	-1.41141
2354.49	-1.23398
2355.41	-4.14801
2356.34	2.16473
2357.27	-0.850555
2358.2	-0.0142822
2359.12	1.83218
2360.05	-0.268402
2360.98	-7.14059
2361.9	-0.770081
2362.83	-0.00579834
2363.76	-2.93826
2364.68	-1.17133
2364.91	2.57858