File: Data/3-Raman/processed/bu20-C-brt1-FI09-1-633-v.txt
#Acq. time (s)=	20
#Accumulations=	3
#Range (cm-¹)=	100...4000
#Windows=	1
#Auto scanning=	Off
#Autofocus=	Off
#Macrospot=	Off
#AutoExposure=	Off
#Spike filter=	Multiple accum.
#Delay time (s)=	0
#Binning=	1
#Readout mode=	Signal
#DeNoise=	Lite
#ICS correction=	Off
#Dark correction=	Off
#Inst. Process=	Off
#Detector temperature (°C)=	-60.09
#Instrument=	LabRAM HR Evol
#Detector=	SIN-EM FIVIS
#Objective=	x50_VIS_LWD
#Grating=	150 (500nm)
#ND Filter=	100%
#Laser=	633nm_Edge
#Hole=	30.0125
#Temperature=	0
#Range=	Visible
#StageXY=	75x50mm Scan+
#StageZ=	Z motor
#X (µm)=	7287.7
#Y (µm)=	4714.8
#Z (µm)=	-60.7
#Full time(mm:ss)=	1:03
#Project=	Buranga
#Sample=	BU18FA20_C
#Site=	C_Bertoss1
#Title=	20-C_brt1_FI09_1
#Remark=
#Date=	30.07.2019 14:48
#Acquired=	30.07.2019 14:48:25
#Data Range:Extract=	16.12.2021 15:36:30
#Base:Fit=	16.12.2021 15:36:40
#Base:Edit=	16.12.2021 15:38:51
#Base:Edit=	16.12.2021 15:38:51
#Base:Edit=	16.12.2021 15:38:52
#Base:Edit=	16.12.2021 15:38:52
#Base:Edit=	16.12.2021 15:38:53
#Base:Sub=	16.12.2021 15:38:54
100.38	176.503
106.898	134.573
113.411	102.576
119.918	81.5342
126.419	64.9324
132.916	53.6998
139.407	45.6511
145.892	39.0195
152.372	29.0283
158.847	26.0808
165.316	26.0338
171.781	26.1342
178.239	17.1459
184.693	9.24154
191.139	2.31797
197.582	-0.280701
204.02	2.23032
210.452	2.55397
216.877	-0.0812912
223.299	1.49635
229.715	6.66209
236.126	28.0091
242.53	43.4162
248.931	38.7327
255.326	23.7167
261.714	16.9001
268.099	15.7486
274.477	18.5672
280.851	30.224
287.218	50.8502
293.582	58.3324
299.939	34.1603
306.293	13.1535
312.639	6.32607
318.982	13.6786
325.318	39.0684
331.651	73.4561
337.977	62.8386
344.297	36.7776
350.614	15.9828
356.925	15.8382
363.23	21.5946
369.53	23.1045
375.827	16.9923
382.116	7.2276
388.401	1.56275
394.681	0.0387573
400.956	3.65421
407.226	8.91724
413.49	12.0518
419.749	15.5247
426.003	13.4268
432.252	27.4873
438.496	52.1659
444.735	61.9015
450.969	57.0236
457.197	44.6548
463.421	37.8724
469.64	31.5994
475.853	22.8053
482.062	14.0744
488.265	11.1023
494.464	10.0413
500.657	13.5847
506.844	16.9943
513.028	21.5765
519.206	24.44
525.38	21.1495
531.548	17.0458
537.71	11.6641
543.869	8.87194
550.022	12.3593
556.169	11.9506
562.313	9.31286
568.452	8.04071
574.584	8.24928
580.713	9.61469
586.837	11.9852
592.954	19.0381
599.068	36.5293
605.176	55.1839
611.28	58.339
617.378	48.2964
623.473	38.8897
629.561	33.8463
635.644	35.237
641.724	37.0493
647.797	34.5568
653.867	37.7575
659.931	44.3895
665.99	42.3478
672.044	31.0888
678.095	18.7419
684.139	8.72747
690.179	8.78502
696.213	4.26997
702.245	1.12818
708.27	0.756935
714.29	0.948151
720.306	3.44821
726.316	4.23372
732.322	0.913574
738.323	-0.464012
744.32	0.906357
750.311	6.82374
756.298	2.89564
762.28	3.85185
768.258	5.24335
774.23	4.1401
780.198	2.37256
786.161	1.11256
792.119	0.545456
798.073	1.40627
804.021	2.87193
809.965	4.75053
815.904	8.0531
821.839	8.05289
827.769	5.87814
833.693	5.01348
839.614	5.49796
845.53	6.57208
851.44	8.24597
857.346	6.72404
863.248	6.2476
869.144	5.04861
875.037	4.375
880.924	8.71238
886.807	12.5517
892.685	12.5755
898.559	11.5023
904.427	10.5187
910.292	10.6351
916.151	11.5402
922.006	10.7342
927.856	9.02757
933.701	11.9376
939.543	18.453
945.379	28.1947
951.21	29.0419
957.037	40.4116
962.861	46.6684
968.678	53.5726
974.491	48.2892
980.3	75.8289
986.104	125.406
991.904	162.834
997.699	175.476
1003.49	144.176
1009.28	111.754
1015.06	87.6959
1020.83	98.7042
1026.61	116.672
1032.37	125.951
1038.14	95.0955
1043.9	62.9772
1049.65	44.3626
1055.4	38.3777
1061.15	34.0425
1066.88	26.7804
1072.62	22.3831
1078.35	23.7149
1084.08	35.9981
1089.8	44.413
1095.52	49.4388
1101.23	55.0372
1106.94	58.8593
1112.65	41.7383
1118.35	24.5047
1124.05	20.0965
1129.74	19.5192
1135.42	17.3266
1141.11	24.2497
1146.78	31.2864
1152.46	38.0184
1158.13	47.975
1163.79	37.3803
1169.45	18.2985
1175.11	11.4821
1180.76	9.80005
1186.41	8.56027
1192.05	6.38888
1197.69	4.02833
1203.32	5.73419
1208.95	6.86108
1214.58	4.04017
1220.2	4.33791
1225.82	4.75836
1231.43	0.631409
1237.04	2.41488
1242.64	2.44872
1248.24	4.18119
1253.83	8.04463
1259.42	9.51352
1265.01	9.02605
1270.59	9.39706
1276.17	8.80611
1281.74	60.5671
1287.31	66.8702
1292.88	10.1771
1298.44	9.32275
1303.99	8.74892
1309.55	7.36491
1315.09	4.48016
1320.64	3.22575
1326.18	5.71876
1331.71	7.23914
1337.24	6.62128
1342.77	5.71415
1348.29	5.52022
1353.81	7.66592
1359.32	10.7929
1364.83	13.7921
1370.33	13.6777
1375.84	9.71837
1381.33	9.40759
1386.82	157.101
1392.31	50.2152
1397.8	12.6147
1403.28	10.8988
1408.75	15.9134
1414.22	12.9197
1419.69	7.23192
1425.15	2.49802
1430.61	0.842575
1436.07	4.07433
1441.52	7.10873
1446.96	5.75291
1452.41	2.10031
1457.84	2.52923
1463.28	4.06081
1468.71	5.60782
1474.13	4.76237
1479.55	2.80264
1484.97	2.91077
1490.39	4.83757
1495.79	6.19089
1501.2	6.88416
1506.6	6.63102
1512	4.91263
1517.39	3.00706
1522.78	1.44428
1528.16	1.46055
1533.54	3.00705
1538.92	4.24529
1544.29	3.1855
1549.66	2.42986
1555.02	3.69493
1560.38	3.24932
1565.74	2.44769
1571.09	4.08258
1576.44	5.0891
1581.78	5.74393
1587.12	3.7319
1592.46	3.99388
1597.79	7.30351
1603.12	5.55457
1608.44	5.46111
1613.76	5.92322
1619.08	6.26434
1624.39	4.86912
1629.7	2.93451
1635	5.6583
1640.3	4.96219
1645.59	2.23338
1650.88	-0.121033
1656.17	-0.932243
1661.46	4.29121
1666.74	6.18941
1672.01	4.90017
1677.28	5.03254
1682.55	4.25025
1687.82	3.23666
1693.07	2.43896
1698.33	3.8296
1703.58	2.98242
1708.83	3.18034
1714.07	5.75414
1719.31	3.93618
1724.55	2.06764
1729.78	3.03436
1735.01	3.60398
1740.23	3.82739
1745.46	4.60098
1750.67	4.61633
1755.89	6.51947
1761.09	3.74739
1766.3	2.41748
1771.5	2.36079
1776.7	4.02866
1781.89	3.81087
1787.08	3.17734
1792.27	2.09074
1797.45	7.2082
1802.62	-2.606
1807.8	1.1098
1812.97	4.42429
1818.14	2.2598
1823.3	0.354004
1828.46	2.69314
1833.61	4.65981
1838.76	2.90558
1843.91	-0.18515
1849.05	-0.460892
1854.19	3.45892
1859.33	3.38267
1864.46	2.24545
1869.59	0.952202
1874.71	0.604065
1879.83	0.65554
1884.95	1.85643
1890.06	2.12738
1895.17	2.1321
1900.27	2.67663
1905.38	1.88899
1910.47	2.9882
1915.57	4.85247
1920.66	-1.04531
1925.74	0.470749
1930.83	3.17326
1935.91	4.01557
1940.98	3.9575
1946.05	3.43179
1951.12	3.53952
1956.18	3.27324
1961.25	2.19085
1966.3	4.41256
1971.35	3.16881
1976.4	2.32929
1981.45	4.672
1986.49	4.28168
1991.53	1.471
1996.56	2.47618
2001.59	4.81089
2006.62	6.325
2011.64	5.5672
2016.66	1.60838
2021.68	3.0082
2026.69	4.94872
2031.7	4.68969
2036.7	2.85464
2041.7	2.51851
2046.7	4.37756
2051.7	7.30414
2056.69	5.09589
2061.67	3.81345
2066.65	2.83835
2071.63	3.24391
2076.61	5.15062
2081.58	3.87696
2086.55	3.07149
2091.51	3.95827
2096.47	2.42704
2101.43	0.821671
2106.39	2.00304
2111.34	2.18948
2116.28	2.60461
2121.23	3.09109
2126.17	1.44528
2131.1	3.49341
2136.03	4.80299
2140.96	4.11149
2145.89	4.05613
2150.81	3.57405
2155.73	2.36374
2160.64	3.2075
2165.55	2.08265
2170.46	3.26074
2175.36	4.23498
2180.26	2.63464
2185.16	1.82722
2190.05	2.02027
2194.94	2.8261
2199.83	1.39332
2204.71	2.22956
2209.59	4.52783
2214.46	1.59059
2219.33	-0.347771
2224.2	1.10413
2229.07	2.97827
2233.93	2.99246
2238.79	4.15649
2243.64	0.788651
2248.49	2.2801
2253.34	2.29366
2258.18	3.04107
2263.02	5.01272
2267.86	2.3881
2272.69	2.37814
2277.52	3.61079
2282.35	4.70096
2287.17	5.15564
2291.99	4.46658
2296.8	3.38087
2301.62	2.53701
2306.43	0.526367
2311.23	1.64101
2316.03	4.40784
2320.83	5.14107
2325.63	5.15294
2330.42	5.04768
2335.21	4.04544
2339.99	1.82825
2344.77	1.99506
2349.55	3.42075
2354.32	1.78113
2359.1	-0.377518
2363.86	-0.936066
2368.63	-0.269478
2373.39	1.70451
2378.15	3.28328
2382.9	3.53843
2387.65	2.81211
2392.4	2.41656
2397.14	2.55786
2401.88	1.72605
2406.62	0.798325
2411.35	3.04868
2416.08	5.29022
2420.81	5.04897
2425.53	5.67031
2430.25	6.22191
2434.97	7.18198
2439.69	7.16943
2444.4	3.80365
2449.1	3.01732
2453.81	6.50926
2458.51	4.50653
2463.2	1.26702
2467.9	2.9459
2472.59	4.43829
2477.27	3.01702
2481.96	2.76731
2486.64	4.03258
2491.31	5.53548
2495.99	5.24545
2500.66	4.40489
2505.32	4.04563
2509.99	4.85885
2514.65	6.51483
2519.31	6.65662
2523.96	5.07334
2528.61	2.29608
2533.26	3.05344
2537.9	5.80439
2542.54	5.16436
2547.18	4.41631
2551.81	3.73459
2556.44	3.10567
2561.07	2.03153
2565.69	1.07826
2570.32	2.57611
2574.93	2.68216
2579.55	2.47229
2584.16	3.5663
2588.77	2.71633
2593.37	2.52203
2597.97	4.76487
2602.57	4.18618
2607.17	1.44299
2611.76	1.69393
2616.35	-0.10788
2620.93	4.57536
2625.51	7.14115
2630.09	6.88071
2634.67	5.7719
2639.24	4.68442
2643.81	3.08097
2648.38	0.994736
2652.94	1.20522
2657.5	5.19728
2662.06	3.08011
2666.61	1.93736
2671.16	5.85954
2675.71	2.1104
2680.25	2.80485
2684.79	3.6182
2689.33	5.05284
2693.86	4.27592
2698.39	3.00337
2702.92	2.21684
2707.45	1.42525
2711.97	1.34074
2716.49	1.84719
2721	3.08611
2725.51	3.56051
2730.02	2.71351
2734.53	1.3928
2739.03	1.2334
2743.53	2.89966
2748.03	3.84581
2752.52	4.57921
2757.01	5.13755
2761.5	5.17946
2765.98	4.83583
2770.46	3.84827
2774.94	4.31598
2779.42	5.20654
2783.89	3.52837
2788.36	1.96696
2792.82	3.44254
2797.28	0.702095
2801.74	-1.01119
2806.2	-1.19717
2810.65	1.47354
2815.1	3.12846
2819.55	3.55544
2823.99	4.29406
2828.43	4.97193
2832.87	6.25067
2837.3	6.2161
2841.74	5.28822
2846.17	3.7722
2850.59	2.30869
2855.01	3.30409
2859.43	4.30923
2863.85	5.13376
2868.26	2.81163
2872.67	0.0506439
2877.08	-1.77636
2881.48	0.344215
2885.89	3.42289
2890.28	3.63652
2894.68	1.41602
2899.07	0.139069
2903.46	2.60721
2907.85	5.28062
2912.23	4.21254
2916.61	3.45031
2920.98	3.98135
2925.36	4.76685
2929.73	3.46996
2934.1	3.46579
2938.46	2.2774
2942.82	2.27642
2947.18	5.64429
2951.54	3.90559
2955.89	3.5946
2960.24	4.55989
2964.59	3.58097
2968.93	1.00402
2973.27	0.393875
2977.61	1.46327
2981.95	3.92594
2986.28	6.49296
2990.61	5.09991
2994.94	1.32118
2999.26	-1.24179
3003.58	-0.0281525
3007.9	1.9707
3012.21	4.39756
3016.52	3.5745
3020.83	1.85081
3025.14	2.35987
3029.44	4.40875
3033.74	5.28699
3038.04	6.02663
3042.33	4.51426
3046.62	2.36856
3050.91	1.40181
3055.2	1.9986
3059.48	4.38802
3063.76	5.82237
3068.03	2.30191
3072.31	0.181347
3076.58	0.430759
3080.85	2.86964
3085.11	4.73297
3089.37	5.46015
3093.63	5.77952
3097.89	6.32016
3102.14	6.4207
3106.39	7.98931
3110.64	8.90529
3114.89	9.41877
3119.13	7.02016
3123.37	3.6073
3127.6	4.21556
3131.84	8.10319
3136.07	9.18399
3140.29	7.59143
3144.52	4.80114
3148.74	2.38934
3152.96	3.10058
3157.18	6.5281
3161.39	7.99794
3165.6	9.16139
3169.81	6.90093
3174.01	3.74185
3178.22	2.89366
3182.42	4.37551
3186.61	8.30568
3190.8	10.0497
3195	8.68873
3199.18	9.28705
3203.37	9.27507
3207.55	7.78836
3211.73	8.74251
3215.91	9.30588
3220.08	9.5624
3224.25	7.83039
3228.42	12.1205
3232.59	10.6979
3236.75	9.8116
3240.91	11.2375
3245.07	8.51007
3249.22	5.79209
3253.37	4.91226
3257.52	4.99821
3261.67	5.62024
3265.81	7.13124
3269.95	4.40839
3274.09	4.18837
3278.22	5.25667
3282.36	-4.03009
3286.49	7.73878
3290.61	9.13845
3294.74	-3.47217
3298.86	5.01241
3302.98	5.35904
3307.09	3.95166
3311.21	3.02139
3315.32	4.02113
3319.42	4.71253
3323.53	4.51598
3327.63	2.97456
3331.73	2.27347
3335.83	2.44781
3339.92	4.41242
3344.01	4.7749
3348.1	4.84041
3352.19	5.62263
3356.27	5.98125
3360.35	4.32421
3364.43	4.24424
3368.5	6.29202
3372.58	8.25413
3376.65	9.18065
3380.71	10.0193
3384.78	9.64476
3388.84	9.05685
3392.9	7.67652
3396.95	6.26067
3401.01	4.3718
3405.06	2.63704
3409.1	9.92466
3413.15	7.41368
3417.19	7.66408
3421.23	9.8875
3425.27	10.2545
3429.31	5.59587
3433.34	12.6332
3437.37	10.7652
3441.39	8.63853
3445.42	7.97816
3449.44	7.43876
3453.46	8.73026
3457.47	9.38398
3461.49	9.48535
3465.5	8.57246
3469.51	6.40243
3473.51	5.4626
3477.52	5.89701
3481.52	8.08664
3485.51	7.05985
3489.51	7.95792
3493.5	9.67627
3497.49	8.4356
3501.48	6.56221
3505.46	6.37912
3509.45	6.95482
3513.43	5.49225
3517.4	7.10494
3521.38	9.12535
3525.35	9.53984
3529.32	8.36428
3533.28	6.05378
3537.25	5.004
3541.21	4.95876
3545.17	4.82384
3549.12	6.59425
3553.08	6.35138
3557.03	6.36013
3560.98	7.23561
3564.92	7.87118
3568.87	7.97158
3572.81	7.8679
3576.74	6.96485
3580.68	8.91942
3584.61	12.3369
3588.54	14.5636
3592.47	13.43
3596.4	10.6781
3600.32	7.69192
3604.24	6.11185
3608.16	4.346
3612.07	6.20346
3615.98	5.94058
3619.89	4.57877
3623.8	5.46657
3627.71	4.84839
3631.61	2.95356
3635.51	4.23901
3639.41	4.29097
3643.3	3.00011
3647.19	2.73058
3651.08	2.95438
3654.97	3.46653
3658.85	2.8576
3662.74	1.28667
3666.62	3.83902
3670.49	5.7496
3674.37	5.08855
3678.24	5.19218
3682.11	4.22449
3685.98	3.29609
3689.84	3.4171
3693.7	4.86335
3697.56	5.48918
3701.42	5.31679
3705.28	4.65591
3709.13	3.71456
3712.98	2.46587
3716.82	0.988594
3720.67	0.274773
3724.51	1.96422
3728.35	4.79202
3732.19	3.58364
3736.02	1.35807
3739.86	2.90096
3743.69	3.20658
3747.51	2.88492
3751.34	2.40653
3755.16	3.22689
3758.98	1.38403
3762.8	-0.215553
3766.61	0.923374
3770.43	3.59203
3774.24	6.37566
3778.05	4.71953
3781.85	3.00181
3785.65	2.26349
3789.45	2.33333
3793.25	2.89318
3797.05	2.53748
3800.84	2.34976
3804.63	3.32091
3808.42	3.62067
3812.21	2.7091
3815.99	1.69149
3819.77	1.59947
3823.55	1.48282
3827.33	0.931202
3831.1	0.922897
3834.87	-0.401546
3838.64	1.06379
3842.41	1.16026
3846.17	1.16717
3849.93	0.599796
3853.69	1.08541
3857.45	0.310001
3861.21	-0.89465
3864.96	-0.705772
3868.71	0.597305
3872.46	2.66616
3876.2	4.27445
3879.94	4.41123
3883.68	1.15942
3887.42	-0.0104713
3891.16	1.58301
3894.89	2.31139
3898.62	2.55853
3902.35	1.5123
3906.08	-1.16322
3909.8	-0.00634384
3913.52	3.28493
3917.24	3.65372
3920.96	2.59666
3924.67	2.74567
3928.38	2.70951
3932.09	3.63103
3935.8	0.909119
3939.51	0.0769958
3943.21	0.948925
3946.91	2.60975
3950.61	3.71006
3954.3	4.37093
3958	1.93932
3961.69	0.983807
3965.38	5.28083
3969.06	3.73009
3972.75	3.52814
3976.43	5.60995
3980.11	6.18704
3983.78	6.33861
3987.46	5.94629
3991.13	6.12201
3994.8	8.57748
3998.47	5.52449