File: Data/3-Raman/processed/bu20-F-brt1-FI02-633-v.txt
#Acq. time (s)=	20
#Accumulations=	3
#Range (cm-¹)=	100...4000
#Windows=	1
#Auto scanning=	Off
#Autofocus=	Off
#Macrospot=	Off
#AutoExposure=	Off
#Spike filter=	Multiple accum.
#Delay time (s)=	0
#Binning=	1
#Readout mode=	Signal
#DeNoise=	Lite
#ICS correction=	Off
#Dark correction=	Off
#Inst. Process=	Off
#Detector temperature (°C)=	-60.09
#Instrument=	LabRAM HR Evol
#Detector=	SIN-EM FIVIS
#Objective=	x100_VIS
#Grating=	150 (500nm)
#ND Filter=	100%
#Laser=	633nm_Edge
#Hole=	30.0125
#Temperature=	0
#Range=	Visible
#StageXY=	75x50mm Scan+
#StageZ=	Z motor
#X (µm)=	7059.8
#Y (µm)=	-65.9
#Z (µm)=	1872
#Full time(mm:ss)=	1:02
#Project=	Buranga
#Sample=	BU18FA20_F
#Site=	F_Bertoss1
#Title=	20-F_brt1_FI02
#Remark=
#Date=	30.07.2019 15:58
#Acquired=	30.07.2019 15:58:51
#Data Range:Extract=	16.12.2021 15:36:30
#Base:Fit=	16.12.2021 15:36:40
#Base:Edit=	16.12.2021 15:40:19
#Base:Edit=	16.12.2021 15:40:22
#Base:Edit=	16.12.2021 15:40:22
#Base:Edit=	16.12.2021 15:40:23
#Base:Sub=	16.12.2021 15:40:24
100.38	157.28
106.898	122.028
113.411	88.8565
119.918	81.0974
126.419	75.057
132.916	62.4578
139.407	51.6506
145.892	44.025
152.372	39.8634
158.847	35.8377
165.316	30.7848
171.781	24.2565
178.239	15.5816
184.693	17.5122
191.139	14.5423
197.582	10.1553
204.02	5.96846
210.452	2.33201
216.877	0.815002
223.299	0.233017
229.715	19.3472
236.126	34.6291
242.53	39.6422
248.931	26.9959
255.326	15.693
261.714	10.1219
268.099	9.37655
274.477	18.3755
280.851	38.9997
287.218	53.9313
293.582	37.9508
299.939	18.7101
306.293	7.46983
312.639	5.34621
318.982	15.7041
325.318	46.7114
331.651	73.1823
337.977	39.3223
344.297	18.8344
350.614	9.82794
356.925	16.1077
363.23	22.1874
369.53	20.1134
375.827	14.9243
382.116	5.83451
388.401	-0.00601959
394.681	1.94987
400.956	7.16579
407.226	8.54854
413.49	8.255
419.749	12.6108
426.003	23.575
432.252	38.6371
438.496	53.6043
444.735	57.021
450.969	52.4836
457.197	47.1217
463.421	37.1115
469.64	24.3206
475.853	14.7041
482.062	13.7476
488.265	13.8414
494.464	14.4456
500.657	15.5889
506.844	17.579
513.028	18.8776
519.206	19.029
525.38	16.9209
531.548	16.8051
537.71	16.4032
543.869	15.0865
550.022	13.7216
556.169	12.9409
562.313	11.9776
568.452	11.9872
574.584	9.924
580.713	10.0111
586.837	15.5524
592.954	27.9633
599.068	50.9578
605.176	67.2793
611.28	56.6748
617.378	47.0924
623.473	41.704
629.561	46.3709
635.644	49.4702
641.724	39.2905
647.797	34.4511
653.867	39.6266
659.931	50.8315
665.99	45.3559
672.044	29.5765
678.095	15.2415
684.139	11.6456
690.179	10.768
696.213	10.8539
702.245	9.53999
708.27	5.33445
714.29	2.25224
720.306	0.278397
726.316	-0.578667
732.322	-0.0993958
738.323	0.659157
744.32	2.64873
750.311	3.65382
756.298	3.01146
762.28	2.82927
768.258	4.30363
774.23	4.5461
780.198	4.68203
786.161	5.05109
792.119	6.85133
798.073	7.70724
804.021	7.18844
809.965	5.18304
815.904	1.80821
821.839	1.14027
827.769	5.6492
833.693	7.45033
839.614	7.10236
845.53	6.01855
851.44	3.14944
857.346	0.406792
863.248	-0.274475
869.144	1.33997
875.037	6.37194
880.924	9.14451
886.807	9.82803
892.685	5.12733
898.559	1.81081
904.427	3.14005
910.292	4.063
916.151	5.16484
922.006	5.56643
927.856	6.35251
933.701	10.3069
939.543	16.3976
945.379	22.6283
951.21	27.0675
957.037	32.1383
962.861	39.9485
968.678	52.3501
974.491	72.9422
980.3	100.33
986.104	140.16
991.904	174.104
997.699	150.704
1003.49	113.367
1009.28	92.2941
1015.06	94.2532
1020.83	107.996
1026.61	118.882
1032.37	105.315
1038.14	78.5713
1043.9	54.2336
1049.65	41.8056
1055.4	34.9962
1061.15	28.9401
1066.88	23.1048
1072.62	25.1761
1078.35	32.7267
1084.08	40.8261
1089.8	46.4041
1095.52	47.6151
1101.23	56.8574
1106.94	43.7665
1112.65	28.5594
1118.35	17.278
1124.05	12.0449
1129.74	12.2662
1135.42	15.5292
1141.11	21.7206
1146.78	29.0453
1152.46	34.2256
1158.13	31.8417
1163.79	21.1797
1169.45	13.7361
1175.11	11.416
1180.76	12.0977
1186.41	10.4004
1192.05	10.0868
1197.69	11.0043
1203.32	9.33255
1208.95	5.98091
1214.58	3.8112
1220.2	2.57982
1225.82	0.145622
1231.43	2.10436
1237.04	5.53259
1242.64	7.86137
1248.24	10.0318
1253.83	8.77171
1259.42	11.4115
1265.01	13.555
1270.59	15.2963
1276.17	23.1003
1281.74	66.4747
1287.31	41.1241
1292.88	15.314
1298.44	12.5468
1303.99	10.1181
1309.55	7.97547
1315.09	6.45913
1320.64	5.80577
1326.18	6.88927
1331.71	6.48061
1337.24	5.20279
1342.77	4.23322
1348.29	4.06104
1353.81	5.41676
1359.32	5.69572
1364.83	6.20766
1370.33	9.85238
1375.84	16.0511
1381.33	29.2765
1386.82	144.002
1392.31	23.8924
1397.8	13.262
1403.28	11.7963
1408.75	12.4102
1414.22	8.0088
1419.69	5.13465
1425.15	4.03341
1430.61	3.75922
1436.07	4.09339
1441.52	4.38531
1446.96	2.23979
1452.41	2.21085
1457.84	4.00601
1463.28	-0.808109
1468.71	4.89032
1474.13	5.68493
1479.55	4.91492
1484.97	0.115356
1490.39	-1.36352
1495.79	2.80593
1501.2	3.06277
1506.6	1.84584
1512	2.74476
1517.39	3.34048
1522.78	4.2837
1528.16	3.2869
1533.54	2.57431
1538.92	3.11229
1544.29	2.44361
1549.66	1.20868
1555.02	-0.0788193
1560.38	4.15795
1565.74	4.4455
1571.09	4.0481
1576.44	3.15634
1581.78	2.87869
1587.12	2.11736
1592.46	2.7427
1597.79	3.73957
1603.12	3.96781
1608.44	5.42943
1613.76	6.08642
1619.08	9.43984
1624.39	7.10141
1629.7	5.63284
1635	4.27397
1640.3	3.89367
1645.59	4.25337
1650.88	4.86121
1656.17	5.26294
1661.46	4.67448
1666.74	3.6241
1672.01	1.59678
1677.28	3.55294
1682.55	4.11277
1687.82	3.04643
1693.07	4.18601
1698.33	3.88388
1703.58	5.62939
1708.83	5.54421
1714.07	6.01271
1719.31	2.30513
1724.55	1.72763
1729.78	1.00523
1735.01	0.816193
1740.23	0.884441
1745.46	3.26991
1750.67	4.30396
1755.89	3.34055
1761.09	-0.828419
1766.3	0.174591
1771.5	-0.0355301
1776.7	0.305073
1781.89	0.375832
1787.08	-2.38187
1792.27	1.72327
1797.45	3.65104
1802.62	1.60178
1807.8	0.112198
1812.97	-0.434593
1818.14	-0.909935
1823.3	-1.19087
1828.46	-1.15826
1833.61	-0.42799
1838.76	0.547737
1843.91	1.72314
1849.05	0.775795
1854.19	-0.992619
1859.33	-0.187206
1864.46	-1.24968
1869.59	-0.915955
1874.71	-0.845688
1879.83	1.20272
1884.95	1.58091
1890.06	0.473469
1895.17	-2.205
1900.27	-3.202
1905.38	-2.65183
1910.47	-0.136932
1915.57	1.3365
1920.66	-0.572609
1925.74	-2.88062
1930.83	-4.39631
1935.91	-4.20509
1940.98	-2.55951
1946.05	0.29792
1951.12	0.694664
1956.18	1.00599
1961.25	2.31758
1966.3	1.7201
1971.35	-0.154331
1976.4	-6.62774
1981.45	1.4182
1986.49	2.27587
1991.53	-2.6539
1996.56	-2.57971
2001.59	-0.175941
2006.62	4.04176
2011.64	0.85968
2016.66	-1.41162
2021.68	0.844967
2026.69	-1.20555
2031.7	-1.64937
2036.7	-2.32949
2041.7	-1.93903
2046.7	-1.67806
2051.7	-1.22104
2056.69	1.28797
2061.67	2.3766
2066.65	1.96742
2071.63	1.35926
2076.61	-11.1399
2081.58	1.68316
2086.55	-0.274174
2091.51	-1.35425
2096.47	-0.183552
2101.43	1.15353
2106.39	1.18059
2111.34	0.542824
2116.28	-1.1924
2121.23	-3.13211
2126.17	-2.60986
2131.1	-0.277966
2136.03	3.12186
2140.96	3.82809
2145.89	-0.283844
2150.81	-2.47515
2155.73	-2.92434
2160.64	-1.61308
2165.55	-0.621128
2170.46	-0.289585
2175.36	0.227329
2180.26	0.159328
2185.16	-1.97844
2190.05	-3.86048
2194.94	-4.40705
2199.83	-2.40696
2204.71	-1.56803
2209.59	-0.816925
2214.46	-0.655388
2219.33	-0.70866
2224.2	-0.439678
2229.07	-0.334129
2233.93	0.10675
2238.79	-10.6403
2243.64	5.1248
2248.49	-0.550552
2253.34	-2.22846
2258.18	-1.32464
2263.02	-0.62479
2267.86	-1.14334
2272.69	-1.89152
2277.52	-1.80101
2282.35	-0.749817
2287.17	1.1707
2291.99	0.733284
2296.8	0.00725174
2301.62	0.568855
2306.43	-0.322376
2311.23	-0.472649
2316.03	-0.685631
2320.83	2.04734
2325.63	3.37221
2330.42	3.85573
2335.21	3.1469
2339.99	1.13394
2344.77	-0.899731
2349.55	-0.908672
2354.32	-0.251709
2359.1	-0.0580368
2363.86	0.110966
2368.63	-0.045723
2373.39	1.09275
2378.15	1.41618
2382.9	1.12478
2387.65	1.29731
2392.4	0.461205
2397.14	-1.1173
2401.88	-0.825851
2406.62	0.33868
2411.35	0.833843
2416.08	2.51034
2420.81	2.23653
2425.53	0.229298
2430.25	-1.13296
2434.97	-1.26324
2439.69	0.874535
2444.4	1.1684
2449.1	2.622
2453.81	3.46179
2458.51	2.68225
2463.2	2.07641
2467.9	1.41753
2472.59	1.39316
2477.27	1.16605
2481.96	0.883335
2486.64	1.2434
2491.31	2.65632
2495.99	1.50546
2500.66	-2.50364
2505.32	-3.84087
2509.99	-2.04594
2514.65	2.0075
2519.31	3.67091
2523.96	3.74295
2528.61	0.168579
2533.26	-1.48668
2537.9	-1.18905
2542.54	-0.658199
2547.18	1.44939
2551.81	2.84458
2556.44	2.69831
2561.07	0.600838
2565.69	0.746895
2570.32	2.88335
2574.93	4.5257
2579.55	4.32755
2584.16	2.18101
2588.77	3.50735
2593.37	5.16868
2597.97	5.71803
2602.57	4.01475
2607.17	2.85897
2611.76	3.10349
2616.35	4.42833
2620.93	2.54388
2625.51	3.12908
2630.09	4.38218
2634.67	4.70885
2639.24	4.20029
2643.81	2.0834
2648.38	2.91166
2652.94	4.68474
2657.5	3.28351
2662.06	2.08646
2666.61	1.17865
2671.16	0.658154
2675.71	0.419197
2680.25	1.0462
2684.79	1.23039
2689.33	0.0358658
2693.86	1.24337
2698.39	3.70112
2702.92	4.32296
2707.45	3.58996
2711.97	2.21921
2716.49	2.86753
2721	2.01133
2725.51	3.85764
2730.02	2.98524
2734.53	4.27856
2739.03	5.39904
2743.53	3.14756
2748.03	2.7076
2752.52	2.76958
2757.01	4.51498
2761.5	4.62564
2765.98	4.09147
2770.46	3.52501
2774.94	3.25467
2779.42	1.24895
2783.89	2.52166
2788.36	3.06106
2792.82	2.74002
2797.28	1.86246
2801.74	2.07888
2806.2	1.10643
2810.65	-0.0333023
2815.1	0.703842
2819.55	2.91819
2823.99	4.53913
2828.43	4.46681
2832.87	3.30471
2837.3	2.17874
2841.74	-0.306438
2846.17	-0.892303
2850.59	0.454147
2855.01	2.42444
2859.43	1.88287
2863.85	1.47794
2868.26	1.81584
2872.67	1.68895
2877.08	1.08548
2881.48	0.511951
2885.89	-0.0983315
2890.28	0.178608
2894.68	-0.195393
2899.07	3.77634
2903.46	4.48064
2907.85	1.54085
2912.23	-0.960083
2916.61	-0.903309
2920.98	-1.08116
2925.36	0.872074
2929.73	-2.26292
2934.1	-0.201149
2938.46	2.4534
2942.82	2.28923
2947.18	-0.0389061
2951.54	-0.283371
2955.89	0.753887
2960.24	0.585926
2964.59	0.338619
2968.93	1.97073
2973.27	2.0435
2977.61	2.52779
2981.95	2.68288
2986.28	1.3131
2990.61	0.754093
2994.94	1.37015
2999.26	2.9795
3003.58	3.40545
3007.9	-0.590523
3012.21	1.16788
3016.52	1.48288
3020.83	-0.0356522
3025.14	-0.750237
3029.44	0.773228
3033.74	2.89426
3038.04	3.69832
3042.33	3.93429
3046.62	2.96573
3050.91	1.23066
3055.2	0.370338
3059.48	1.0308
3063.76	3.10823
3068.03	4.19976
3072.31	3.97148
3076.58	5.18015
3080.85	4.95741
3085.11	4.11327
3089.37	4.60825
3093.63	6.03611
3097.89	6.56993
3102.14	7.06872
3106.39	6.61646
3110.64	7.88484
3114.89	9.13703
3119.13	9.8854
3123.37	9.3666
3127.6	8.75071
3131.84	9.62257
3136.07	10.722
3140.29	10.9856
3144.52	10.6405
3148.74	11.0221
3152.96	10.8848
3157.18	10.078
3161.39	11.0217
3165.6	12.8117
3169.81	13.2082
3174.01	13.1887
3178.22	13.1902
3182.42	14.2271
3186.61	16.7444
3190.8	19.1937
3195	19.1405
3199.18	18.0141
3203.37	17.0003
3207.55	17.2426
3211.73	17.4833
3215.91	15.9039
3220.08	18.5688
3224.25	18.042
3228.42	16.4327
3232.59	17.1981
3236.75	16.7743
3240.91	16.4013
3245.07	15.4527
3249.22	16.3223
3253.37	17.1696
3257.52	16.3775
3261.67	16.14
3265.81	17.6525
3269.95	17.1474
3274.09	15.6499
3278.22	15.7093
3282.36	18.0941
3286.49	19.3735
3290.61	16.0988
3294.74	14.3424
3298.86	18.1023
3302.98	20.0106
3307.09	19.2156
3311.21	16.8166
3315.32	12.8644
3319.42	15.813
3323.53	17.6713
3327.63	16.5622
3331.73	16.0279
3335.83	15.6499
3339.92	15.3861
3344.01	15.2175
3348.1	14.9843
3352.19	15.8272
3356.27	17.7957
3360.35	17.7499
3364.43	15.7738
3368.5	12.2132
3372.58	12.7888
3376.65	18.0271
3380.71	22.0838
3384.78	22.0652
3388.84	21.6092
3392.9	21.7257
3396.95	21.9426
3401.01	22.2222
3405.06	22.3873
3409.1	21.4798
3413.15	21.3154
3417.19	21.6889
3421.23	23.8894
3425.27	23.6337
3429.31	24.2053
3433.34	23.2648
3437.37	19.2758
3441.39	18.0891
3445.42	22.7206
3449.44	22.2126
3453.46	21.122
3457.47	18.651
3461.49	19.2578
3465.5	22.0943
3469.51	19.2237
3473.51	16.8194
3477.52	19.8449
3481.52	20.4689
3485.51	19.7471
3489.51	18.0851
3493.5	19.5002
3497.49	17.5356
3501.48	16.8041
3505.46	17.4087
3509.45	15.9402
3513.43	14.5403
3517.4	13.4352
3521.38	15.2406
3525.35	13.2311
3529.32	10.6407
3533.28	13.3457
3537.25	11.9696
3541.21	9.32103
3545.17	10.9513
3549.12	11.6153
3553.08	12.8245
3557.03	11.6768
3560.98	9.88303
3564.92	9.25542
3568.87	10.5632
3572.81	11.36
3576.74	12.3545
3580.68	13.6351
3584.61	12.865
3588.54	10.9744
3592.47	11.5561
3596.4	12.3942
3600.32	10.8051
3604.24	6.62109
3608.16	5.91197
3612.07	6.56647
3615.98	7.56171
3619.89	5.86856
3623.8	2.05172
3627.71	0.598961
3631.61	2.67849
3635.51	3.92428
3639.41	4.93233
3643.3	5.74441
3647.19	7.29818
3651.08	6.2714
3654.97	4.12501
3658.85	1.982
3662.74	1.32108
3666.62	1.51611
3670.49	2.09187
3674.37	1.91749
3678.24	0.861717
3682.11	0.89843
3685.98	1.51641
3689.84	1.83825
3693.7	2.05731
3697.56	1.41186
3701.42	-1.50753
3705.28	1.33738
3709.13	2.13473
3712.98	0.568611
3716.82	-0.469341
3720.67	-1.90117
3724.51	-1.54461
3728.35	0.264645
3732.19	0.608784
3736.02	-0.816856
3739.86	-2.15026
3743.69	-1.94651
3747.51	-0.294525
3751.34	-0.733364
3755.16	-0.572941
3758.98	-0.746746
3762.8	0.609848
3766.61	0.915054
3770.43	0.983894
3774.24	1.01578
3778.05	1.27399
3781.85	1.80856
3785.65	2.1659
3789.45	1.33941
3793.25	0.845146
3797.05	1.95248
3800.84	3.04201
3804.63	2.59069
3808.42	1.41814
3812.21	0.972641
3815.99	0.983074
3819.77	0.803596
3823.55	0.1315
3827.33	0.603374
3831.1	1.7415
3834.87	1.46944
3838.64	0.371174
3842.41	1.26135
3846.17	3.22117
3849.93	2.72154
3853.69	1.99807
3857.45	0.941277
3861.21	0.985149
3864.96	2.65879
3868.71	3.13879
3872.46	2.27925
3876.2	0.978008
3879.94	1.17097
3883.68	1.64584
3887.42	2.02176
3891.16	2.46547
3894.89	1.31661
3898.62	1.89672
3902.35	1.63379
3906.08	0.590996
3909.8	-0.0910301
3913.52	1.45338
3917.24	2.56304
3920.96	2.3621
3924.67	1.59829
3928.38	0.732552
3932.09	1.04588
3935.8	1.42365
3939.51	0.184654
3943.21	-1.43388
3946.91	2.35154
3950.61	2.27827
3954.3	2.11102
3958	0.929802
3961.69	-0.581711
3965.38	0.0644302
3969.06	1.94804
3972.75	2.31393
3976.43	2.72397
3980.11	0.330681
3983.78	0.0268345
3987.46	1.43841
3991.13	1.2518
3994.8	0.663511
3998.47	-1.12083