File: Data/3-Raman/processed/bu20-j-ff1-fi01-s_1800 (450-850nm)_532nm_edge_100%_x100_vis_lwd_h30um_30sx2_01.txt
#Acq. time (s)=	30
#Accumulations=	2
#Range=	Off
#Autofocus=	Off
#Macrospot=	Off
#AutoExposure=	Off
#Spike filter=	Multiple accum.
#Delay time (s)=	2
#Binning=	1
#Readout mode=	Signal
#DeNoise=	Off
#ICS correction=	On
#Dark correction=	Off
#Inst. Process=	Off
#Detector Gain=	Best Dynamic
#Detector ADC=	50 kHz HS
#Detector temperature (°C)=	-60.09
#Instrument=	LabRAM HR Evol
#Detector=	SIN-EM FIVIS
#Objective=	x100_VIS_LWD
#Grating=	1800 (450-850nm)
#ND Filter=	100%
#Laser=	532nm_Edge
#Spectro (cm-¹)=	3360
#Hole=	30.0125
#Temperature=	0
#Range=	Visible
#StageXY=	75x50mm Scan+
#StageZ=	Z motor
#X (µm)=	0
#Y (µm)=	0
#Z (µm)=	-8.5
#Full time(mm:ss)=	1:04
#Project=	21_08_11
#Sample=	BU20
#Site=
#Title=	BU20-J-FF1-FI01-S_1800 (450-850nm)_532nm_Edge_100%_x100_VIS_LWD_H30um_30sX2
#Remark=
#Date=	11.08.2021 16:44
#Acquired=	11.08.2021 16:44:50
#Data Range:Extract=	16.12.2021 15:36:30
#Base:Fit=	16.12.2021 15:36:40
#Base:Fit=	16.12.2021 15:55:02
#Base:Sub=	16.12.2021 15:55:08
3515.51	185.801
3515.13	228.098
3514.74	212.499
3514.36	234.872
3513.98	229.465
3513.6	232.681
3513.21	244.512
3512.83	285.781
3512.45	259.556
3512.06	290.443
3511.68	283.245
3511.3	265.912
3510.91	264.044
3510.53	287.785
3510.15	262.527
3509.76	254.501
3509.38	234.26
3509	242.352
3508.61	227.518
3508.23	210.315
3507.84	208.054
3507.46	218.421
3507.08	207.048
3506.69	197.501
3506.31	189.436
3505.93	177.71
3505.54	169.469
3505.16	156.811
3504.77	158.217
3504.39	153.202
3504.01	119.163
3503.62	147.151
3503.24	134.326
3502.85	83.3957
3502.47	116.401
3502.09	94.1084
3501.7	101.263
3501.32	96.9534
3500.93	67.9152
3500.55	78.7897
3500.16	78.9106
3499.78	67.7432
3499.4	63.2769
3499.01	98.9129
3498.63	66.0552
3498.24	65.5358
3497.86	65.9385
3497.47	46.3091
3497.09	49.5138
3496.7	58.3524
3496.32	56.8049
3495.93	46.8021
3495.55	57.738
3495.17	40.1257
3494.78	23.4205
3494.4	35.289
3494.01	29.02
3493.63	24.5635
3493.24	39.1132
3492.86	19.5493
3492.47	24.715
3492.09	12.2246
3491.7	21.4572
3491.32	21.731
3490.93	46.555
3490.55	21.9039
3490.16	26.8648
3489.78	32.4797
3489.39	3.99173
3489.01	10.8362
3488.62	30.1902
3488.23	17.2948
3487.85	14.8416
3487.46	4.77448
3487.08	11.9206
3486.69	19.0528
3486.31	13.758
3485.92	29.4798
3485.54	29.9333
3485.15	26.619
3484.76	27.23
3484.38	14.3353
3483.99	17.6543
3483.61	15.2952
3483.22	23.3889
3482.84	17.0909
3482.45	23.2257
3482.06	13.021
3481.68	32.2853
3481.29	16.509
3480.91	19.2633
3480.52	17.1673
3480.13	15.7135
3479.75	16.2321
3479.36	37.5014
3478.98	18.603
3478.59	-2.15378
3478.2	28.7348
3477.82	18.9087
3477.43	13.8888
3477.04	29.6397
3476.66	25.7332
3476.27	5.66046
3475.88	18.3109
3475.5	2.03757
3475.11	14.2403
3474.73	22.0412
3474.34	23.2509
3473.95	15.4667
3473.57	28.8653
3473.18	21.1109
3472.79	12.0482
3472.41	29.3423
3472.02	8.44
3471.63	32.7185
3471.24	31.6681
3470.86	13.7534
3470.47	19.7708
3470.08	26.0771
3469.7	34.1272
3469.31	34.9506
3468.92	37.0535
3468.54	17.3498
3468.15	34.7069
3467.76	33.2003
3467.38	14.7216
3466.99	27.5738
3466.6	43.3408
3466.21	17.7489
3465.83	29.4626
3465.44	43.1805
3465.05	26.2365
3464.66	27.567
3464.28	46.2162
3463.89	48.5331
3463.5	38.3238
3463.11	26.1917
3462.73	31.4266
3462.34	34.6755
3461.95	54.2733
3461.56	35.3164
3461.18	39.4506
3460.79	44.543
3460.4	42.9428
3460.01	44.1888
3459.62	41.7485
3459.24	20.9933
3458.85	27.831
3458.46	43.3671
3458.07	42.7539
3457.68	37.2935
3457.3	48.9996
3456.91	51.13
3456.52	54.2846
3456.13	46.0333
3455.74	41.6868
3455.36	55.4845
3454.97	55.7649
3454.58	54.1774
3454.19	43.8874
3453.8	57.7
3453.41	55.1391
3453.03	62.1315
3452.64	53.9202
3452.25	64.1248
3451.86	61.4328
3451.47	50.0839
3451.08	52.3874
3450.69	52.4897
3450.31	55.566
3449.92	51.919
3449.53	53.0795
3449.14	69.6797
3448.75	48.7071
3448.36	52.7798
3447.97	54.8865
3447.58	41.0466
3447.19	69.6897
3446.81	67.6685
3446.42	70.3118
3446.03	73.216
3445.64	72.795
3445.25	50.2723
3444.86	82.1177
3444.47	72.0251
3444.08	73.1829
3443.69	76.1406
3443.3	88.8141
3442.91	81.7054
3442.52	88.4736
3442.14	80.9484
3441.75	60.9372
3441.36	87.1711
3440.97	99.0754
3440.58	93.6606
3440.19	89.2637
3439.8	100.349
3439.41	103.1
3439.02	110.336
3438.63	103.799
3438.24	114.685
3437.85	123.39
3437.46	126.083
3437.07	147.463
3436.68	140.986
3436.29	150.049
3435.9	140.762
3435.51	172.991
3435.12	177.212
3434.73	197.88
3434.34	235.621
3433.95	220.356
3433.56	240.861
3433.17	281.527
3432.78	329.152
3432.39	358.704
3432	412.41
3431.61	447.675
3431.22	504.008
3430.83	607.971
3430.44	642.677
3430.05	720.833
3429.66	791.849
3429.27	782.142
3428.88	766.44
3428.48	763.207
3428.09	685.833
3427.7	604.581
3427.31	578.842
3426.92	514.027
3426.53	420.793
3426.14	417.266
3425.75	344.495
3425.36	322.497
3424.97	314.762
3424.58	283.182
3424.19	247.803
3423.79	254.874
3423.4	239.703
3423.01	204.123
3422.62	223.582
3422.23	198.644
3421.84	182.197
3421.45	200.538
3421.06	147.675
3420.67	176.795
3420.27	177.096
3419.88	149.467
3419.49	161.175
3419.1	161.272
3418.71	140.166
3418.32	157.374
3417.93	140.206
3417.53	136.596
3417.14	138.65
3416.75	157.122
3416.36	127.594
3415.97	138.315
3415.58	128.772
3415.19	136.648
3414.79	132.064
3414.4	112.115
3414.01	113.398
3413.62	124.206
3413.22	136.876
3412.83	109.088
3412.44	129.323
3412.05	129.37
3411.66	102.591
3411.27	130.679
3410.87	101.202
3410.48	117.862
3410.09	128.632
3409.7	126.895
3409.3	135.728
3408.91	116.659
3408.52	130.298
3408.13	105.62
3407.73	139.132
3407.34	128.967
3406.95	134.972
3406.56	130.71
3406.17	122.765
3405.77	145.041
3405.38	128.393
3404.99	143.889
3404.59	130.73
3404.2	154.741
3403.81	144.776
3403.42	137.691
3403.02	149.031
3402.63	130.217
3402.24	143.309
3401.84	157.766
3401.45	138.24
3401.06	146.418
3400.67	149.92
3400.27	160.475
3399.88	155.354
3399.49	154.06
3399.09	154.752
3398.7	136.092
3398.31	169.422
3397.91	162.04
3397.52	159.172
3397.13	176.649
3396.73	173.52
3396.34	190.79
3395.95	191.784
3395.55	163.03
3395.16	184.715
3394.77	196.147
3394.37	167.702
3393.98	208.243
3393.59	205.785
3393.19	206.376
3392.8	233.44
3392.4	212.59
3392.01	222.682
3391.62	228.077
3391.22	217.71
3390.83	239.34
3390.44	270.245
3390.04	261.718
3389.65	247.536
3389.25	291.115
3388.86	308.133
3388.47	321.403
3388.07	343.951
3387.68	355.567
3387.28	364.997
3386.89	384.811
3386.49	402.145
3386.1	425.171
3385.71	438.664
3385.31	478.083
3384.92	515.695
3384.52	572.777
3384.13	567.877
3383.73	629.188
3383.34	657.397
3382.95	688.647
3382.55	749.339
3382.16	789.154
3381.76	835.189
3381.37	884.251
3380.97	945.664
3380.58	952.66
3380.18	970.062
3379.79	988.3
3379.39	974.968
3379	1003.56
3378.6	994.812
3378.21	968.044
3377.81	974.901
3377.42	917.214
3377.02	879.399
3376.63	860.293
3376.23	826.878
3375.84	760.013
3375.44	740.919
3375.05	693.334
3374.65	651.49
3374.25	641.78
3373.86	598.618
3373.46	585.886
3373.07	575.027
3372.67	523.86
3372.28	486.771
3371.88	480.071
3371.49	432.441
3371.09	427.518
3370.7	416.196
3370.3	391.688
3369.9	373.702
3369.51	367.141
3369.11	364.452
3368.72	317.056
3368.32	320.139
3367.93	293.621
3367.53	278.502
3367.13	291.035
3366.74	276.139
3366.34	275.236
3365.95	255.24
3365.55	242.948
3365.15	224.057
3364.76	230.055
3364.36	214.073
3363.97	211.305
3363.57	199.163
3363.17	192.804
3362.78	177.825
3362.38	174.227
3361.98	151.55
3361.59	144.053
3361.19	149.775
3360.79	135.562
3360.4	146.117
3360	149.991
3359.6	143.384
3359.21	114.926
3358.81	134.106
3358.41	126.671
3358.02	119.306
3357.62	112.988
3357.22	98.9614
3356.83	119.103
3356.43	108.708
3356.03	103.977
3355.64	104.053
3355.24	107.988
3354.84	104.328
3354.44	94.0374
3354.05	82.7996
3353.65	92.4891
3353.25	66.9773
3352.86	73.808
3352.46	83.5471
3352.06	68.5778
3351.67	87.7759
3351.27	66.0285
3350.87	77.7012
3350.47	74.1342
3350.08	74.3273
3349.68	72.5696
3349.28	65.9879
3348.88	61.2846
3348.49	63.2457
3348.09	55.6528
3347.69	61.4412
3347.29	68.264
3346.9	66.599
3346.5	72.5848
3346.1	37.7016
3345.7	65.5461
3345.3	48.5754
3344.91	51.6384
3344.51	47.018
3344.11	41.484
3343.71	49.3816
3343.31	49.6089
3342.92	46.8935
3342.52	51.839
3342.12	51.1017
3341.72	49.4601
3341.32	50.6973
3340.93	36.6138
3340.53	51.1155
3340.13	54.1754
3339.73	36.2541
3339.33	57.4203
3338.93	27.1129
3338.54	46.2717
3338.14	44.7659
3337.74	32.7718
3337.34	35.0128
3336.94	40.9503
3336.54	45.7516
3336.14	29.5793
3335.74	33.6029
3335.35	31.8966
3334.95	34.0747
3334.55	29.6146
3334.15	26.037
3333.75	48.2142
3333.35	46.5038
3332.95	41.8925
3332.55	34.3943
3332.16	33.5847
3331.76	22.2484
3331.36	34.858
3330.96	36.8408
3330.56	24.4751
3330.16	29.4027
3329.76	23.0307
3329.36	31.9191
3328.96	30.4286
3328.56	20.212
3328.16	24.2414
3327.76	29.2048
3327.37	26.462
3326.97	26.5012
3326.57	17.8915
3326.17	19.9608
3325.77	32.5158
3325.37	27.1832
3324.97	26.7219
3324.57	27.0078
3324.17	24.5741
3323.77	20.1263
3323.37	40.4352
3322.97	24.4134
3322.57	20.7271
3322.17	21.7321
3321.77	19.1329
3321.37	17.5633
3320.97	32.4025
3320.57	25.018
3320.17	18.4267
3319.77	25.2321
3319.37	17.6517
3318.97	11.9483
3318.57	29.287
3318.17	23.6902
3317.77	27.8153
3317.37	29.0223
3316.97	26.4086
3316.57	17.9617
3316.17	9.70712
3315.77	13.3612
3315.37	22.2132
3314.97	16.2116
3314.57	20.4694
3314.17	26.2638
3313.77	34.7239
3313.37	7.75862
3312.97	6.33118
3312.56	18.1574
3312.16	31.4288
3311.76	25.8241
3311.36	9.75024
3310.96	30.0533
3310.56	16.8501
3310.16	21.8176
3309.76	12.4041
3309.36	15.4523
3308.96	0.353088
3308.56	18.8014
3308.15	16.2546
3307.75	-1.60707
3307.35	27.4808
3306.95	24.8788
3306.55	7.78996
3306.15	22.3289
3305.75	28.3219
3305.35	9.34503
3304.94	14.3373
3304.54	24.2968
3304.14	18.9498
3303.74	13.541
3303.34	0.11908
3302.94	15.4484
3302.53	14.938
3302.13	17.2524
3301.73	18.049
3301.33	14.2248
3300.93	19.235
3300.53	15.571
3300.13	1.53181
3299.72	13.3984
3299.32	28.6672
3298.92	13.3432
3298.52	11.5968
3298.12	14.7559
3297.71	17.0825
3297.31	20.3242
3296.91	20.577
3296.51	21.7113
3296.11	16.0639
3295.7	19.0573
3295.3	15.3542
3294.9	15.4649
3294.5	17.5266
3294.1	17.7608
3293.69	9.36548
3293.29	27.89
3292.89	11.7435
3292.49	26.3436
3292.08	18.8118
3291.68	17.5342
3291.28	9.70142
3290.88	14.5709
3290.47	13.5802
3290.07	9.71896
3289.67	13.8719
3289.27	-3.07729
3288.86	0.078537
3288.46	3.21286
3288.06	9.20349
3287.65	21.9764
3287.25	4.93794
3286.85	18.6624
3286.45	11.197
3286.04	-2.05988
3285.64	21.2383
3285.24	11.7262
3284.83	10.8419
3284.43	12.8589
3284.03	17.664
3283.62	-5.23677
3283.22	11.8245
3282.82	21.6862
3282.41	8.02733
3282.01	6.52945
3281.61	22.0597
3281.2	18.4215
3280.8	3.19826
3280.4	23.6139
3279.99	16.0633
3279.59	6.5806
3279.19	3.8998
3278.78	-1.66451
3278.38	9.16228
3277.98	21.9403
3277.57	9.68188
3277.17	23.4066
3276.76	17.8558
3276.36	11.3027
3275.96	5.69794
3275.55	13.5932
3275.15	1.15273
3274.74	10.9853
3274.34	13.3708
3273.94	12.9495
3273.53	18.8922
3273.13	8.70766
3272.72	13.8157
3272.32	25.6851
3271.92	10.5827
3271.51	13.6531
3271.11	21.6272
3270.7	14.2055
3270.3	23.1446
3269.9	19.5695
3269.49	3.43002
3269.09	27.7306
3268.68	12.5146
3268.28	8.80919
3267.87	14.7429
3267.47	7.19614
3267.06	18.9182
3266.66	20.0988
3266.25	16.5288
3265.85	22.6329
3265.44	25.8867
3265.04	18.5463
3264.64	18.8032
3264.23	10.3434
3263.83	8.60008
3263.42	26.0813
3263.02	18.4802
3262.61	13.8164
3262.21	20.6963
3261.8	23.7698
3261.4	9.58093
3260.99	20.4154
3260.59	18.8579
3260.18	14.1398
3259.78	22.3082
3259.37	17.8672
3258.96	13.2243
3258.56	27.9587
3258.15	21.4206
3257.75	25.4133
3257.34	21.7237
3256.94	13.1918
3256.53	20.0625
3256.13	26.9441
3255.72	16.5349
3255.31	20.582
3254.91	24.727
3254.5	31.6824
3254.1	26.0918
3253.69	3.24228
3253.29	13.1183
3252.88	29.7639
3252.47	22.3982
3252.07	15.0006
3251.66	12.3738
3251.26	21.2485
3250.85	11.7975
3250.44	20.5558
3250.04	-0.499161
3249.63	20.7862
3249.23	22.974
3248.82	23.3086
3248.41	28.4586
3248.01	8.68227
3247.6	13.7741
3247.2	22.6166
3246.79	17.9762
3246.38	12.3423
3245.98	25.8357
3245.57	12.5217
3245.16	10.6434
3244.76	12.7806
3244.35	21.8116
3243.94	13.5164
3243.54	10.9044
3243.13	17.9745
3242.72	22.1298
3242.32	15.7264
3241.91	4.50296
3241.5	17.2224
3241.1	21.3396
3240.69	10.0825
3240.28	29.5016
3239.88	19.1898
3239.47	18.5226
3239.06	16.863
3238.65	14.2858
3238.25	24.0806
3237.84	16.5707
3237.43	6.23071
3237.03	23.754
3236.62	17.3461
3236.21	3.32449
3235.8	20.9506
3235.4	17.4546
3234.99	18.7107
3234.58	7.41708
3234.18	28.7917
3233.77	9.84915
3233.36	24.4932
3232.95	4.60823
3232.54	12.5644
3232.14	26.2869
3231.73	12.2287
3231.32	14.3094
3230.91	17.4093
3230.51	8.24768
3230.1	16.9748
3229.69	24.9774
3229.28	9.36839
3228.87	8.15439
3228.47	5.56201
3228.06	15.6642
3227.65	21.3581
3227.24	19.7736
3226.83	15.9357
3226.43	3.67383
3226.02	16.4033
3225.61	-0.591248
3225.2	16.7464
3224.79	10.1968
3224.39	5.5224
3223.98	15.274
3223.57	-1.66321
3223.16	12.0893
3222.75	28.7048
3222.34	20.4277
3221.94	13.1099
3221.53	8.59425
3221.12	3.07364
3220.71	18.5756
3220.3	10.1767
3219.89	11.3812
3219.48	13.5955
3219.07	1.56981
3218.67	15.2487
3218.26	1.13985
3217.85	11.2782
3217.44	14.8763
3217.03	5.74193
3216.62	14.4517
3216.21	23.0993
3215.8	21.1492
3215.39	5.32088
3214.99	11.47
3214.58	20.4623
3214.17	9.25075
3213.76	0.897644
3213.35	10.7793
3212.94	16.8745
3212.53	12.4143
3212.12	15.6106
3211.71	5.40311
3211.3	20.0607
3210.89	11.7585
3210.48	-1.33054
3210.07	15.2825
3209.66	10.9563
3209.25	8.51149
3208.84	14.6465
3208.44	14.026
3208.02	16.209
3207.62	8.87473
3207.21	8.22171
3206.8	8.54518
3206.39	-0.685883
3205.98	8.29446
3205.57	15.3343
3205.16	14.6773
3204.75	-2.27502
3204.34	10.4945
3203.93	9.91656
3203.52	10.2918
3203.11	8.75964
3202.7	14.9005
3202.29	11.4527
3201.88	15.6822
3201.47	1.67506
3201.06	19.2022
3200.65	9.94296
3200.23	-0.253387
3199.82	5.82698
3199.41	19.5779
3199	1.7771
3198.59	17.4979
3198.39	8.17105