File: Data/3-Raman/processed/bu20-B-brt2-FI05-1-633-v.txt
#Acq. time (s)=	20
#Accumulations=	3
#Range (cm-¹)=	100...4000
#Windows=	1
#Auto scanning=	Off
#Autofocus=	Off
#Macrospot=	Off
#AutoExposure=	Off
#Spike filter=	Multiple accum.
#Delay time (s)=	0
#Binning=	1
#Readout mode=	Signal
#DeNoise=	Lite
#ICS correction=	Off
#Dark correction=	Off
#Inst. Process=	Off
#Detector temperature (°C)=	-60.09
#Instrument=	LabRAM HR Evol
#Detector=	SIN-EM FIVIS
#Objective=	x100_VIS
#Grating=	150 (500nm)
#ND Filter=	100%
#Laser=	633nm_Edge
#Hole=	30.0125
#Temperature=	0
#Range=	Visible
#StageXY=	75x50mm Scan+
#StageZ=	Z motor
#X (µm)=	8743.1
#Y (µm)=	4539.3
#Z (µm)=	1852.1
#Full time(mm:ss)=	1:02
#Project=	Buranga
#Sample=	BU18FA20_C
#Site=	C_Bertoss2
#Title=	20-C_brt2_FI05_1
#Remark=
#Date=	30.07.2019 15:42
#Acquired=	30.07.2019 15:42:00
#Data Range:Extract=	16.12.2021 15:36:30
#Base:Fit=	16.12.2021 15:36:40
#Base:Edit=	16.12.2021 15:40:02
#Base:Sub=	16.12.2021 15:40:07
100.38	106.407
106.898	82.2949
113.411	71.3651
119.918	59.579
126.419	49.2654
132.916	39.4605
139.407	33.657
145.892	29.2969
152.372	25.6534
158.847	21.3562
165.316	25.6144
171.781	20.5099
178.239	9.26209
184.693	7.52103
191.139	5.58106
197.582	-4.35518
204.02	3.55601
210.452	2.15271
216.877	0.693161
223.299	8.48768
229.715	30.954
236.126	78.1522
242.53	107.055
248.931	53.1651
255.326	36.2038
261.714	33.5574
268.099	40.3347
274.477	56.1063
280.851	98.4494
287.218	150.622
293.582	111.942
299.939	55.2088
306.293	24.0185
312.639	19.3167
318.982	39.4046
325.318	84.956
331.651	156.796
337.977	98.5922
344.297	39.3384
350.614	22.0496
356.925	19.8966
363.23	37.5297
369.53	52.2421
375.827	46.7829
382.116	28.3849
388.401	10.8557
394.681	5.09914
400.956	2.38853
407.226	-0.00419617
413.49	3.18866
419.749	13.0537
426.003	29.7769
432.252	49.6284
438.496	85.7653
444.735	95.5481
450.969	91.9421
457.197	79.9544
463.421	65.4297
469.64	41.1845
475.853	22.1981
482.062	8.19749
488.265	5.30791
494.464	7.02718
500.657	11.0577
506.844	14.6599
513.028	16.6895
519.206	16.1152
525.38	14.8495
531.548	13.572
537.71	13.2622
543.869	13.1798
550.022	11.1583
556.169	9.57224
562.313	8.13723
568.452	9.2147
574.584	8.87167
580.713	9.63233
586.837	6.07529
592.954	27.7154
599.068	65.666
605.176	99.4774
611.28	80.9954
617.378	61.1466
623.473	54.2551
629.561	61.1336
635.644	68.1794
641.724	62.3839
647.797	56.7365
653.867	62.7371
659.931	83.728
665.99	83.8554
672.044	60.419
678.095	36.5517
684.139	19.9215
690.179	9.09306
696.213	1.81543
702.245	-0.74939
708.27	-0.04142
714.29	0.566383
720.306	1.30122
726.316	0.145454
732.322	-2.10516
738.323	-3.27441
744.32	-2.18826
750.311	1.635
756.298	3.79796
762.28	-2.85854
768.258	2.66965
774.23	5.89115
780.198	4.76295
786.161	3.07858
792.119	-0.0894623
798.073	-0.13623
804.021	1.42169
809.965	4.54825
815.904	8.32423
821.839	9.7794
827.769	9.03479
833.693	7.88495
839.614	8.76102
845.53	10.3544
851.44	11.6933
857.346	11.3205
863.248	10.3357
869.144	10.3285
875.037	12.4146
880.924	13.5338
886.807	15.8169
892.685	16.3881
898.559	17.9155
904.427	14.343
910.292	17.089
916.151	17.3248
922.006	18.5432
927.856	21.4441
933.701	26.3752
939.543	35.8948
945.379	50.7229
951.21	69.2102
957.037	87.5352
962.861	97.6841
968.678	110.213
974.491	136.143
980.3	180.462
986.104	251.338
991.904	339.872
997.699	300.095
1003.49	237.217
1009.28	195.482
1015.06	194.694
1020.83	223.556
1026.61	259.266
1032.37	242.984
1038.14	167.014
1043.9	111.429
1049.65	81.7591
1055.4	64.8382
1061.15	55.4991
1066.88	50.6494
1072.62	47.8727
1078.35	52.4216
1084.08	70.0152
1089.8	82.1746
1095.52	92.8801
1101.23	103.948
1106.94	104.386
1112.65	66.6527
1118.35	41.1768
1124.05	32.5546
1129.74	31.5316
1135.42	34.6478
1141.11	40.6972
1146.78	48.8081
1152.46	60.6602
1158.13	71.3264
1163.79	51.5088
1169.45	23.7325
1175.11	19.1733
1180.76	18.6593
1186.41	15.4669
1192.05	14.0499
1197.69	9.67479
1203.32	9.92913
1208.95	12.2187
1214.58	10.4668
1220.2	7.73301
1225.82	6.46026
1231.43	6.10818
1237.04	2.86969
1242.64	2.23969
1248.24	5.91279
1253.83	10.0294
1259.42	11.3549
1265.01	12.2611
1270.59	11.0931
1276.17	9.62716
1281.74	38.5399
1287.31	24.7833
1292.88	12.526
1298.44	11.5815
1303.99	11.1363
1309.55	9.60399
1315.09	7.0759
1320.64	3.58954
1326.18	4.83057
1331.71	5.33255
1337.24	-0.2836
1342.77	4.34519
1348.29	4.30695
1353.81	4.18237
1359.32	5.06729
1364.83	6.95808
1370.33	9.45712
1375.84	10.4721
1381.33	13.4659
1386.82	105.13
1392.31	14.1659
1397.8	-0.194229
1403.28	10.7177
1408.75	11.3602
1414.22	7.71061
1419.69	5.19514
1425.15	4.49061
1430.61	7.47577
1436.07	6.85455
1441.52	6.28659
1446.96	3.51727
1452.41	1.81353
1457.84	1.6972
1463.28	1.66948
1468.71	1.84923
1474.13	1.8229
1479.55	1.41998
1484.97	1.18044
1490.39	2.30844
1495.79	3.32639
1501.2	1.92458
1506.6	1.26049
1512	3.13988
1517.39	4.89618
1522.78	4.02899
1528.16	1.54967
1533.54	0.123638
1538.92	-0.197285
1544.29	0.527916
1549.66	1.66097
1555.02	2.84679
1560.38	3.39332
1565.74	3.1357
1571.09	4.1296
1576.44	5.34195
1581.78	3.73686
1587.12	5.73524
1592.46	3.42591
1597.79	3.3531
1603.12	3.77876
1608.44	4.23036
1613.76	5.59253
1619.08	5.1024
1624.39	3.1739
1629.7	1.76149
1635	0.916397
1640.3	2.24386
1645.59	4.14761
1650.88	4.5487
1656.17	3.29491
1661.46	3.30132
1666.74	4.20267
1672.01	4.375
1677.28	3.91837
1682.55	3.73685
1687.82	3.85051
1693.07	2.01974
1698.33	-1.36374
1703.58	0.0452499
1708.83	3.17682
1714.07	3.04483
1719.31	1.37085
1724.55	3.36938
1729.78	3.855
1735.01	3.25662
1740.23	2.82708
1745.46	2.84626
1750.67	3.67345
1755.89	4.28021
1761.09	3.84867
1766.3	2.90329
1771.5	3.83689
1776.7	4.68201
1781.89	6.01518
1787.08	2.4354
1792.27	-0.495316
1797.45	6.32855
1802.62	5.59276
1807.8	3.44033
1812.97	2.71745
1818.14	3.46537
1823.3	7.08596
1828.46	4.02642
1833.61	-0.455963
1838.76	0.373932
1843.91	2.49605
1849.05	2.65299
1854.19	1.1142
1859.33	1.17303
1864.46	3.6675
1869.59	4.05185
1874.71	3.64539
1879.83	2.18458
1884.95	2.38797
1890.06	0.799385
1895.17	0.827515
1900.27	2.71954
1905.38	3.7141
1910.47	6.43482
1915.57	6.1705
1920.66	3.03128
1925.74	4.53397
1930.83	2.97765
1935.91	1.16042
1940.98	0.297905
1946.05	0.497086
1951.12	2.70616
1956.18	1.67278
1961.25	0.744576
1966.3	1.29725
1971.35	3.68843
1976.4	4.5535
1981.45	-0.499794
1986.49	5.3392
1991.53	3.08935
1996.56	1.92081
2001.59	1.63309
2006.62	1.81034
2011.64	2.52941
2016.66	4.51073
2021.68	5.84783
2026.69	5.02496
2031.7	3.15247
2036.7	2.23109
2041.7	3.83889
2046.7	4.1178
2051.7	1.98965
2056.69	0.610741
2061.67	2.35789
2066.65	2.50869
2071.63	2.17025
2076.61	3.06837
2081.58	0.596748
2086.55	1.17608
2091.51	5.52425
2096.47	4.58266
2101.43	4.52348
2106.39	4.1557
2111.34	7.29887
2116.28	6.59899
2121.23	4.77113
2126.17	4.81873
2131.1	5.13875
2136.03	-0.141205
2140.96	1.00819
2145.89	3.88872
2150.81	4.57661
2155.73	4.59714
2160.64	2.79018
2165.55	1.49572
2170.46	0.563828
2175.36	1.18076
2180.26	4.19403
2185.16	4.97785
2190.05	4.26685
2194.94	3.1826
2199.83	4.02728
2204.71	1.06113
2209.59	2.6678
2214.46	6.52062
2219.33	8.17999
2224.2	4.50643
2229.07	3.39479
2233.93	3.79865
2238.79	4.00669
2243.64	4.06719
2248.49	4.24976
2253.34	-0.35817
2258.18	5.52555
2263.02	3.88374
2267.86	2.25126
2272.69	1.23343
2277.52	1.03772
2282.35	1.50216
2287.17	2.41473
2291.99	4.13471
2296.8	4.52681
2301.62	1.20392
2306.43	2.79717
2311.23	4.20534
2316.03	4.8632
2320.83	5.21442
2325.63	5.71449
2330.42	6.37356
2335.21	6.22633
2339.99	5.75948
2344.77	4.95112
2349.55	3.52518
2354.32	3.35966
2359.1	2.60085
2363.86	2.57105
2368.63	4.17706
2373.39	5.05964
2378.15	5.39523
2382.9	2.13425
2387.65	2.54558
2392.4	3.34158
2397.14	2.60599
2401.88	-0.211884
2406.62	1.58918
2411.35	3.92468
2416.08	4.47363
2420.81	4.26054
2425.53	4.48054
2430.25	5.59939
2434.97	6.97998
2439.69	6.58109
2444.4	5.63278
2449.1	1.41763
2453.81	0.291725
2458.51	0.650505
2463.2	1.86999
2467.9	3.35694
2472.59	1.44771
2477.27	-0.296333
2481.96	1.83395
2486.64	2.10794
2491.31	3.75877
2495.99	4.02921
2500.66	5.73007
2505.32	6.26574
2509.99	5.32647
2514.65	3.45425
2519.31	2.37708
2523.96	0.990898
2528.61	0.848854
2533.26	2.72821
2537.9	5.40348
2542.54	6.03521
2547.18	6.21123
2551.81	6.08782
2556.44	3.87582
2561.07	1.65407
2565.69	1.00793
2570.32	1.54356
2574.93	1.06667
2579.55	3.32187
2584.16	3.72447
2588.77	3.08686
2593.37	2.78179
2597.97	2.80062
2602.57	3.74749
2607.17	3.23201
2611.76	3.08991
2616.35	4.6163
2620.93	3.72987
2625.51	2.77301
2630.09	3.59178
2634.67	5.65121
2639.24	5.11574
2643.81	2.55846
2648.38	-0.239601
2652.94	1.6655
2657.5	3.10783
2662.06	1.01347
2666.61	-3.2791
2671.16	-0.37056
2675.71	2.75539
2680.25	1.54182
2684.79	2.6387
2689.33	5.39227
2693.86	6.00211
2698.39	3.12514
2702.92	0.982948
2707.45	1.03313
2711.97	-1.09859
2716.49	1.561
2721	2.29048
2725.51	2.30627
2730.02	1.97807
2734.53	1.33073
2739.03	2.02779
2743.53	3.27919
2748.03	1.83081
2752.52	-0.00331116
2757.01	0.0981064
2761.5	0.98909
2765.98	2.28173
2770.46	1.21677
2774.94	1.51522
2779.42	4.69217
2783.89	1.08942
2788.36	-0.309761
2792.82	-3.04626
2797.28	-5.02985
2801.74	-4.03216
2806.2	-0.976616
2810.65	2.79947
2815.1	2.6338
2819.55	2.91991
2823.99	2.63398
2828.43	1.09451
2832.87	0.735893
2837.3	1.13629
2841.74	-0.441345
2846.17	-3.21324
2850.59	-0.714821
2855.01	1.31468
2859.43	-0.0414581
2863.85	-0.68985
2868.26	-2.96189
2872.67	-3.9155
2877.08	-3.32555
2881.48	-0.78907
2885.89	2.77183
2890.28	2.92023
2894.68	0.853851
2899.07	2.22853
2903.46	3.45147
2907.85	-0.53009
2912.23	-2.35086
2916.61	-0.93663
2920.98	-0.448448
2925.36	-0.0384216
2929.73	-0.52607
2934.1	-0.632309
2938.46	-0.449654
2942.82	0.531273
2947.18	2.43229
2951.54	3.01472
2955.89	2.77278
2960.24	2.85675
2964.59	3.15692
2968.93	4.19734
2973.27	3.88019
2977.61	1.93759
2981.95	0.903694
2986.28	0.619743
2990.61	3.75583
2994.94	4.25608
2999.26	0.684921
3003.58	-0.894058
3007.9	-0.0108109
3012.21	2.75366
3016.52	5.10361
3020.83	3.54308
3025.14	-0.417419
3029.44	-3.88194
3033.74	-2.56721
3038.04	1.42502
3042.33	0.991341
3046.62	1.68036
3050.91	-0.67617
3055.2	0.3601
3059.48	2.88092
3063.76	2.2002
3068.03	0.56826
3072.31	-0.583939
3076.58	-0.888016
3080.85	4.36497
3085.11	7.86404
3089.37	6.49788
3093.63	4.34647
3097.89	4.54796
3102.14	3.71922
3106.39	-0.931213
3110.64	1.34406
3114.89	5.97247
3119.13	7.74648
3123.37	6.62205
3127.6	6.44856
3131.84	7.41876
3136.07	7.48531
3140.29	4.86776
3144.52	4.94031
3148.74	5.06128
3152.96	7.41384
3157.18	7.93481
3161.39	6.97188
3165.6	5.18167
3169.81	2.87513
3174.01	2.66955
3178.22	5.64436
3182.42	8.67741
3186.61	8.74619
3190.8	10.0847
3195	13.0913
3199.18	12.9461
3203.37	9.84187
3207.55	8.65619
3211.73	11.6081
3215.91	13.3501
3220.08	11.4466
3224.25	10.323
3228.42	9.16318
3232.59	7.33461
3236.75	7.80573
3240.91	8.28918
3245.07	8.91328
3249.22	9.10046
3253.37	8.84285
3257.52	8.13913
3261.67	6.81936
3265.81	4.68428
3269.95	2.78203
3274.09	2.8047
3278.22	3.27271
3282.36	4.09708
3286.49	4.618
3290.61	2.45145
3294.74	1.91537
3298.86	3.80806
3302.98	3.27058
3307.09	1.62916
3311.21	-0.20927
3315.32	-0.316193
3319.42	1.4571
3323.53	2.08798
3327.63	2.20085
3331.73	2.93602
3335.83	3.72719
3339.92	4.9894
3344.01	5.54333
3348.1	4.26394
3352.19	3.46315
3356.27	2.8774
3360.35	2.35115
3364.43	3.16534
3368.5	4.29776
3372.58	4.71198
3376.65	5.89892
3380.71	7.45874
3384.78	8.99799
3388.84	9.52557
3392.9	9.74109
3396.95	9.76269
3401.01	10.5712
3405.06	8.64247
3409.1	7.95574
3413.15	9.73609
3417.19	11.8364
3421.23	13.3451
3425.27	12.7536
3429.31	10.8858
3433.34	9.43574
3437.37	8.60117
3441.39	8.08659
3445.42	8.03212
3449.44	7.03139
3453.46	7.57651
3457.47	9.36718
3461.49	7.40311
3465.5	7.39327
3469.51	4.9157
3473.51	5.19744
3477.52	7.02237
3481.52	8.87527
3485.51	8.50071
3489.51	6.96138
3493.5	5.92472
3497.49	7.01514
3501.48	6.56047
3505.46	5.54041
3509.45	5.50856
3513.43	3.18368
3517.4	5.95447
3521.38	6.79718
3525.35	5.77106
3529.32	6.78726
3533.28	3.45004
3537.25	2.09441
3541.21	3.07064
3545.17	1.32664
3549.12	2.08765
3553.08	3.40058
3557.03	5.11144
3560.98	5.86666
3564.92	6.41245
3568.87	7.64204
3572.81	9.6307
3576.74	12.4874
3580.68	13.7812
3584.61	16.5364
3588.54	16.3494
3592.47	14.0645
3596.4	13.5656
3600.32	11.4549
3604.24	6.59295
3608.16	3.78134
3612.07	2.87332
3615.98	2.04652
3619.89	0.600208
3623.8	1.58981
3627.71	2.08014
3631.61	3.08671
3635.51	6.23923
3639.41	4.69402
3643.3	3.06172
3647.19	2.20748
3651.08	0.949451
3654.97	-0.0521469
3658.85	-0.480705
3662.74	1.89521
3666.62	2.7557
3670.49	3.97959
3674.37	5.25633
3678.24	2.80296
3682.11	2.46557
3685.98	4.34443
3689.84	3.97437
3693.7	1.41259
3697.56	1.69397
3701.42	1.76559
3705.28	2.50789
3709.13	2.78112
3712.98	1.2151
3716.82	2.0078
3720.67	2.08298
3724.51	0.508465
3728.35	0.197079
3732.19	0.514214
3736.02	-0.256016
3739.86	0.764549
3743.69	3.61493
3747.51	3.64547
3751.34	2.89294
3755.16	3.54682
3758.98	3.9739
3762.8	3.15625
3766.61	2.60379
3770.43	4.27639
3774.24	5.28345
3778.05	5.39595
3781.85	4.92356
3785.65	4.70819
3789.45	4.32051
3793.25	4.94603
3797.05	4.02001
3800.84	3.36777
3804.63	3.30894
3808.42	2.39011
3812.21	3.05932
3815.99	2.77015
3819.77	3.26833
3823.55	6.06657
3827.33	5.73035
3831.1	4.00592
3834.87	2.43398
3838.64	4.19169
3842.41	4.28007
3846.17	1.6245
3849.93	-0.212822
3853.69	0.377159
3857.45	3.64865
3861.21	6.21581
3864.96	6.18309
3868.71	5.89488
3872.46	5.59162
3876.2	5.01579
3879.94	4.26498
3883.68	3.09583
3887.42	2.45663
3891.16	2.93157
3894.89	4.16103
3898.62	4.25508
3902.35	0.927319
3906.08	-0.749348
3909.8	1.08764
3913.52	2.69802
3917.24	4.24319
3920.96	3.40031
3924.67	2.00306
3928.38	1.49715
3932.09	1.71413
3935.8	1.00141
3939.51	0.427456
3943.21	2.14935
3946.91	3.43896
3950.61	2.26797
3954.3	0.374771
3958	1.29881
3961.69	2.86121
3965.38	3.1026
3969.06	2.19285
3972.75	-0.476734
3976.43	0.900185
3980.11	2.9274
3983.78	1.75169
3987.46	0.118164
3991.13	1.18555
3994.8	-0.681427
3998.47	-2.55154