File: Data/3-Raman/processed/bu20-F-brt1-FI01-633-v.txt
#Acq. time (s)=	20
#Accumulations=	3
#Range (cm-¹)=	100...4000
#Windows=	1
#Auto scanning=	Off
#Autofocus=	Off
#Macrospot=	Off
#AutoExposure=	Off
#Spike filter=	Multiple accum.
#Delay time (s)=	0
#Binning=	1
#Readout mode=	Signal
#DeNoise=	Lite
#ICS correction=	Off
#Dark correction=	Off
#Inst. Process=	Off
#Detector temperature (°C)=	-60.09
#Instrument=	LabRAM HR Evol
#Detector=	SIN-EM FIVIS
#Objective=	x100_VIS
#Grating=	150 (500nm)
#ND Filter=	100%
#Laser=	633nm_Edge
#Hole=	30.0125
#Temperature=	0
#Range=	Visible
#StageXY=	75x50mm Scan+
#StageZ=	Z motor
#X (µm)=	7064
#Y (µm)=	-135.7
#Z (µm)=	1846.5
#Full time(mm:ss)=	1:02
#Project=	Buranga
#Sample=	BU18FA20_F
#Site=	F_Bertoss1
#Title=	20-F_brt1_FI01
#Remark=
#Date=	30.07.2019 15:56
#Acquired=	30.07.2019 15:56:48
#Data Range:Extract=	16.12.2021 15:36:30
#Base:Fit=	16.12.2021 15:36:40
#Base:Edit=	16.12.2021 15:40:10
#Base:Sub=	16.12.2021 15:40:16
100.38	140.038
106.898	115.192
113.411	86.8288
119.918	68.975
126.419	61.3461
132.916	52.4017
139.407	49.2224
145.892	43.5807
152.372	37.552
158.847	33.3372
165.316	29.9079
171.781	25.0841
178.239	19.2555
184.693	14.6549
191.139	8.18301
197.582	6.14034
204.02	5.52996
210.452	1.71297
216.877	-0.0970001
223.299	4.35551
229.715	17.922
236.126	47.386
242.53	57.7604
248.931	19.3765
255.326	17.5263
261.714	24.8393
268.099	17.1893
274.477	40.6787
280.851	65.4633
287.218	78.6781
293.582	58.7828
299.939	28.8308
306.293	10.625
312.639	11.7406
318.982	30.8129
325.318	70.3708
331.651	107.275
337.977	65.6027
344.297	36.1963
350.614	24.1177
356.925	22.3983
363.23	34.1244
369.53	36.2451
375.827	28.23
382.116	17.4373
388.401	4.65314
394.681	3.85603
400.956	11.3342
407.226	17.2064
413.49	21.5755
419.749	27.9162
426.003	37.4412
432.252	58.6213
438.496	72.2105
444.735	70.1005
450.969	65.5379
457.197	59.2389
463.421	52.1377
469.64	41.7771
475.853	31.4854
482.062	22.0291
488.265	18.825
494.464	18.7192
500.657	21.4244
506.844	26.019
513.028	29.0409
519.206	29.8018
525.38	29.1287
531.548	30.2544
537.71	29.3698
543.869	25.9067
550.022	23.5389
556.169	24.0879
562.313	22.1074
568.452	18.6152
574.584	14.8827
580.713	16.5071
586.837	24.8036
592.954	41.764
599.068	63.2881
605.176	74.4802
611.28	65.6927
617.378	56.8798
623.473	53.1015
629.561	54.9539
635.644	56.7197
641.724	51.822
647.797	49.7093
653.867	53.7214
659.931	58.7488
665.99	54.5072
672.044	41.0283
678.095	28.2407
684.139	18.2086
690.179	11.2436
696.213	7.74944
702.245	6.32997
708.27	7.46509
714.29	10.032
720.306	10.2276
726.316	9.00156
732.322	3.36028
738.323	1.7242
744.32	5.56324
750.311	5.82404
756.298	4.88153
762.28	4.00857
768.258	2.32834
774.23	2.54901
780.198	2.44736
786.161	1.98177
792.119	1.27213
798.073	4.18572
804.021	5.2694
809.965	-0.0485458
815.904	3.59409
821.839	7.47754
827.769	4.47606
833.693	0.543999
839.614	6.08894
845.53	5.11604
851.44	4.39931
857.346	5.12817
863.248	6.13419
869.144	8.045
875.037	7.68175
880.924	6.76205
886.807	6.63234
892.685	8.07423
898.559	8.13234
904.427	7.42511
910.292	6.40066
916.151	4.50132
922.006	6.12722
927.856	9.86777
933.701	13.6898
939.543	19.6811
945.379	28.5165
951.21	37.0283
957.037	45.6413
962.861	55.2078
968.678	66.3455
974.491	82.1431
980.3	118.359
986.104	166.448
991.904	212.295
997.699	184.089
1003.49	139.49
1009.28	117.995
1015.06	124.711
1020.83	141.31
1026.61	153.314
1032.37	135.931
1038.14	86.9847
1043.9	55.2625
1049.65	43.2563
1055.4	34.2508
1061.15	26.4455
1066.88	23.9532
1072.62	31.0865
1078.35	39.9896
1084.08	47.7419
1089.8	54.8814
1095.52	59.4789
1101.23	64.8997
1106.94	55.2429
1112.65	36.0188
1118.35	24.2766
1124.05	17.7546
1129.74	15.8756
1135.42	19.2013
1141.11	25.2459
1146.78	33.7053
1152.46	41.7601
1158.13	40.9541
1163.79	29.3825
1169.45	15.7294
1175.11	11.9698
1180.76	10.9754
1186.41	9.12842
1192.05	4.98035
1197.69	2.95579
1203.32	2.85177
1208.95	3.77467
1214.58	3.03767
1220.2	4.22735
1225.82	3.62596
1231.43	3.24004
1237.04	4.38095
1242.64	5.93806
1248.24	1.62532
1253.83	0.343689
1259.42	5.32556
1265.01	9.11028
1270.59	5.07673
1276.17	8.26659
1281.74	68.4556
1287.31	20.5052
1292.88	6.67515
1298.44	1.03019
1303.99	2.61742
1309.55	6.8341
1315.09	8.72603
1320.64	8.78623
1326.18	7.71316
1331.71	6.19694
1337.24	5.51715
1342.77	5.1825
1348.29	4.21478
1353.81	4.17065
1359.32	5.36519
1364.83	7.18932
1370.33	8.02773
1375.84	9.49391
1381.33	25.2592
1386.82	136.575
1392.31	21.0356
1397.8	4.0292
1403.28	12.3952
1408.75	12.4431
1414.22	6.95003
1419.69	8.16143
1425.15	7.60773
1430.61	6.12244
1436.07	3.62059
1441.52	1.75998
1446.96	3.57697
1452.41	0.91642
1457.84	3.90958
1463.28	7.59547
1468.71	7.1366
1474.13	4.1933
1479.55	2.15151
1484.97	1.15798
1490.39	0.95649
1495.79	1.55872
1501.2	4.11535
1506.6	4.5488
1512	5.6395
1517.39	5.42678
1522.78	5.03949
1528.16	4.66801
1533.54	0.633675
1538.92	0.18808
1544.29	2.31823
1549.66	4.19037
1555.02	5.67695
1560.38	5.38831
1565.74	5.03013
1571.09	6.03776
1576.44	8.11263
1581.78	8.91042
1587.12	8.26781
1592.46	7.21993
1597.79	7.44267
1603.12	6.35711
1608.44	9.22978
1613.76	10.9772
1619.08	10.9513
1624.39	10.0648
1629.7	8.9855
1635	7.40497
1640.3	6.80923
1645.59	6.7955
1650.88	8.60946
1656.17	11.3494
1661.46	10.7348
1666.74	9.61401
1672.01	7.31095
1677.28	7.90334
1682.55	8.69918
1687.82	9.66827
1693.07	9.55478
1698.33	7.87233
1703.58	7.94595
1708.83	8.65972
1714.07	6.60854
1719.31	6.46892
1724.55	8.7856
1729.78	9.87899
1735.01	7.60709
1740.23	7.8198
1745.46	8.52453
1750.67	8.65383
1755.89	1.77874
1761.09	2.18282
1766.3	8.08291
1771.5	9.54269
1776.7	7.08819
1781.89	6.79845
1787.08	6.93941
1792.27	7.86304
1797.45	9.03082
1802.62	9.96
1807.8	7.59348
1812.97	6.34671
1818.14	5.98657
1823.3	5.45053
1828.46	5.41267
1833.61	4.28657
1838.76	6.11057
1843.91	6.13225
1849.05	2.20273
1854.19	4.99077
1859.33	7.56229
1864.46	8.92416
1869.59	7.74331
1874.71	4.71162
1879.83	4.44019
1884.95	4.609
1890.06	5.42225
1895.17	6.70438
1900.27	7.01151
1905.38	9.84902
1910.47	7.83753
1915.57	6.08699
1920.66	8.91293
1925.74	8.50933
1930.83	6.42453
1935.91	4.27222
1940.98	1.9693
1946.05	3.44701
1951.12	3.62953
1956.18	7.3679
1961.25	5.8644
1966.3	6.47847
1971.35	6.7785
1976.4	6.12063
1981.45	8.14066
1986.49	10.1501
1991.53	8.26305
1996.56	7.59148
2001.59	5.10604
2006.62	3.32989
2011.64	5.78612
2016.66	6.10383
2021.68	6.61602
2026.69	6.96049
2031.7	5.64914
2036.7	6.16129
2041.7	7.01868
2046.7	7.63898
2051.7	8.17864
2056.69	7.17715
2061.67	3.21643
2066.65	3.10934
2071.63	3.97617
2076.61	6.56711
2081.58	8.4715
2086.55	6.91025
2091.51	8.41424
2096.47	8.7419
2101.43	8.84769
2106.39	10.9459
2111.34	8.24045
2116.28	5.92867
2121.23	4.98499
2126.17	5.09927
2131.1	5.89454
2136.03	6.03319
2140.96	6.67443
2145.89	9.73758
2150.81	9.26852
2155.73	5.74869
2160.64	2.37672
2165.55	3.17665
2170.46	6.00773
2175.36	8.07939
2180.26	5.73118
2185.16	8.66299
2190.05	7.41187
2194.94	8.18494
2199.83	8.83537
2204.71	11.9354
2209.59	9.92637
2214.46	10.2018
2219.33	8.84208
2224.2	5.71719
2229.07	2.24409
2233.93	3.84359
2238.79	6.49585
2243.64	8.09137
2248.49	7.86147
2253.34	7.00217
2258.18	5.01555
2263.02	5.50241
2267.86	5.27034
2272.69	6.5049
2277.52	7.43122
2282.35	7.48367
2287.17	6.46965
2291.99	8.25401
2296.8	6.08517
2301.62	1.26885
2306.43	4.79587
2311.23	7.69771
2316.03	10.1623
2320.83	12.0215
2325.63	11.1074
2330.42	9.10431
2335.21	7.17441
2339.99	5.77773
2344.77	4.86855
2349.55	6.0398
2354.32	9.67214
2359.1	9.30025
2363.86	6.27978
2368.63	4.98717
2373.39	7.00265
2378.15	10.0008
2382.9	6.42339
2387.65	3.85188
2392.4	0.735275
2397.14	6.87366
2401.88	6.88604
2406.62	6.55598
2411.35	4.90614
2416.08	4.28288
2420.81	6.78618
2425.53	8.88908
2430.25	8.94011
2434.97	5.85338
2439.69	5.54826
2444.4	6.91006
2449.1	7.7987
2453.81	8.14311
2458.51	6.05171
2463.2	2.8375
2467.9	0.462898
2472.59	2.31875
2477.27	5.39645
2481.96	7.68305
2486.64	9.14607
2491.31	9.31679
2495.99	9.78636
2500.66	8.26454
2505.32	7.0928
2509.99	5.89297
2514.65	3.49815
2519.31	0.147797
2523.96	-0.189415
2528.61	4.18753
2533.26	7.08118
2537.9	8.07726
2542.54	9.81288
2547.18	9.42514
2551.81	8.44057
2556.44	7.34874
2561.07	6.68642
2565.69	6.97559
2570.32	7.73283
2574.93	9.924
2579.55	6.29874
2584.16	6.95434
2588.77	8.95905
2593.37	9.59513
2597.97	6.27448
2602.57	2.80405
2607.17	3.58815
2611.76	5.47168
2616.35	7.0531
2620.93	7.75733
2625.51	6.89245
2630.09	6.22411
2634.67	7.53915
2639.24	9.75193
2643.81	8.42616
2648.38	5.39524
2652.94	5.15889
2657.5	7.09732
2662.06	9.34228
2666.61	7.11293
2671.16	7.55819
2675.71	6.57838
2680.25	7.58485
2684.79	7.09763
2689.33	11.4147
2693.86	10.3025
2698.39	6.67825
2702.92	7.1432
2707.45	6.21751
2711.97	5.55
2716.49	7.77772
2721	10.4442
2725.51	12.4141
2730.02	11.0387
2734.53	8.78126
2739.03	9.44189
2743.53	10.1376
2748.03	6.31591
2752.52	7.91219
2757.01	7.51009
2761.5	10.8301
2765.98	7.41727
2770.46	9.09355
2774.94	6.65512
2779.42	3.35029
2783.89	-0.432961
2788.36	5.79448
2792.82	8.06447
2797.28	8.13718
2801.74	9.09912
2806.2	9.83004
2810.65	9.51806
2815.1	9.26514
2819.55	9.3488
2823.99	10.0285
2828.43	9.42918
2832.87	8.52119
2837.3	6.18052
2841.74	1.29057
2846.17	-0.52282
2850.59	5.11917
2855.01	7.7254
2859.43	7.84072
2863.85	6.96157
2868.26	7.71053
2872.67	7.94565
2877.08	8.2205
2881.48	4.24352
2885.89	4.84144
2890.28	3.7542
2894.68	4.47802
2899.07	8.02687
2903.46	8.95414
2907.85	6.32136
2912.23	7.10166
2916.61	5.32408
2920.98	3.91346
2925.36	6.30428
2929.73	7.10327
2934.1	4.50538
2938.46	0.795906
2942.82	2.69959
2947.18	8.65598
2951.54	9.26551
2955.89	5.75008
2960.24	4.40402
2964.59	4.01375
2968.93	2.84825
2973.27	4.70284
2977.61	10.2024
2981.95	7.86381
2986.28	3.65347
2990.61	2.35947
2994.94	5.09373
2999.26	8.50594
3003.58	6.88187
3007.9	4.57204
3012.21	3.09907
3016.52	3.0496
3020.83	2.97198
3025.14	3.80843
3029.44	1.73135
3033.74	1.23158
3038.04	0.0167694
3042.33	1.90498
3046.62	3.00928
3050.91	4.04444
3055.2	5.54311
3059.48	5.55408
3063.76	9.26653
3068.03	8.17858
3072.31	6.01168
3076.58	4.67085
3080.85	3.1991
3085.11	4.4297
3089.37	6.84158
3093.63	6.03343
3097.89	5.30139
3102.14	3.96652
3106.39	5.3993
3110.64	7.26283
3114.89	8.88688
3119.13	8.61639
3123.37	7.78876
3127.6	6.79343
3131.84	2.09611
3136.07	2.84808
3140.29	5.0518
3144.52	5.228
3148.74	3.80602
3152.96	2.84047
3157.18	2.73649
3161.39	3.92426
3165.6	5.2262
3169.81	5.17151
3174.01	6.18244
3178.22	7.40784
3182.42	6.96861
3186.61	6.1438
3190.8	8.46977
3195	7.42246
3199.18	9.07993
3203.37	10.1429
3207.55	9.89391
3211.73	7.87319
3215.91	7.15063
3220.08	7.01624
3224.25	10.7118
3228.42	10.3226
3232.59	9.19709
3236.75	8.05523
3240.91	7.38397
3245.07	9.10786
3249.22	10.0564
3253.37	10.2565
3257.52	8.80083
3261.67	7.90503
3265.81	4.50694
3269.95	2.82018
3274.09	3.07294
3278.22	4.23717
3282.36	3.96253
3286.49	3.16999
3290.61	-0.533211
3294.74	2.04485
3298.86	0.258324
3302.98	2.38578
3307.09	4.97157
3311.21	0.482475
3315.32	-1.09851
3319.42	0.192078
3323.53	2.69483
3327.63	3.86993
3331.73	2.16925
3335.83	0.909821
3339.92	1.32278
3344.01	1.23575
3348.1	4.38055
3352.19	3.55871
3356.27	1.14249
3360.35	1.82834
3364.43	4.52952
3368.5	6.91685
3372.58	6.87664
3376.65	2.53725
3380.71	2.08316
3384.78	3.11173
3388.84	1.56818
3392.9	1.70623
3396.95	5.8707
3401.01	8.67829
3405.06	9.81915
3409.1	8.6059
3413.15	8.41579
3417.19	8.89384
3421.23	5.59142
3425.27	7.08311
3429.31	7.7495
3433.34	7.88964
3437.37	6.64177
3441.39	5.06072
3445.42	4.80829
3449.44	6.10919
3453.46	7.39439
3457.47	6.21398
3461.49	5.48145
3465.5	5.02789
3469.51	1.23696
3473.51	0.795448
3477.52	2.62454
3481.52	3.79919
3485.51	4.59752
3489.51	5.64285
3493.5	5.01577
3497.49	4.68418
3501.48	5.54804
3505.46	5.26062
3509.45	3.33665
3513.43	2.8656
3517.4	0.321205
3521.38	0.46553
3525.35	2.26367
3529.32	3.42773
3533.28	2.92123
3537.25	2.15347
3541.21	1.51202
3545.17	0.842789
3549.12	0.830208
3553.08	1.52587
3557.03	2.68061
3560.98	3.16019
3564.92	5.00945
3568.87	6.53149
3572.81	5.71774
3576.74	6.66032
3580.68	9.78715
3584.61	10.0928
3588.54	10.2989
3592.47	8.97092
3596.4	8.25682
3600.32	6.46386
3604.24	1.70181
3608.16	-2.54123
3612.07	-3.37411
3615.98	-2.59033
3619.89	-0.562378
3623.8	1.54376
3627.71	1.81933
3631.61	2.60768
3635.51	2.07129
3639.41	0.594734
3643.3	2.19711
3647.19	3.53136
3651.08	3.74591
3654.97	3.92268
3658.85	4.3677
3662.74	2.80287
3666.62	-0.320236
3670.49	1.1706
3674.37	2.65273
3678.24	1.84536
3682.11	0.408104
3685.98	0.709648
3689.84	2.65933
3693.7	3.88694
3697.56	4.93464
3701.42	3.87762
3705.28	3.29626
3709.13	3.47002
3712.98	4.3337
3716.82	5.50636
3720.67	3.12642
3724.51	1.94304
3728.35	2.64961
3732.19	2.65023
3736.02	2.7861
3739.86	2.66735
3743.69	4.1433
3747.51	3.41779
3751.34	2.28093
3755.16	2.94204
3758.98	2.42229
3762.8	3.28761
3766.61	4.85959
3770.43	1.46828
3774.24	-1.9127
3778.05	-0.310188
3781.85	3.54751
3785.65	4.97343
3789.45	4.1878
3793.25	5.36182
3797.05	6.22599
3800.84	4.99903
3804.63	3.01182
3808.42	1.51791
3812.21	1.23309
3815.99	2.60841
3819.77	3.3339
3823.55	1.99886
3827.33	0.941742
3831.1	2.3707
3834.87	4.96499
3838.64	5.69521
3842.41	5.94876
3846.17	5.85435
3849.93	5.24746
3853.69	4.23532
3857.45	5.45126
3861.21	7.42156
3864.96	5.22985
3868.71	6.12617
3872.46	6.42887
3876.2	5.55716
3879.94	3.69001
3883.68	4.58006
3887.42	5.44624
3891.16	4.47447
3894.89	4.96965
3898.62	5.95087
3902.35	6.87975
3906.08	6.7193
3909.8	4.62744
3913.52	0.57972
3917.24	-0.605671
3920.96	0.325729
3924.67	1.2483
3928.38	2.26303
3932.09	3.47457
3935.8	2.47567
3939.51	-0.0431404
3943.21	-0.375286
3946.91	0.900284
3950.61	1.75053
3954.3	0.921299
3958	0.39386
3961.69	0.39893
3965.38	1.14124
3969.06	2.20941
3972.75	2.55823
3976.43	1.05701
3980.11	0.467579
3983.78	0.548595
3987.46	0.255508
3991.13	-0.292381
3994.8	-0.768253
3998.47	0.865696