File: Data/3-Raman/processed/bu20-b-ff4-fi01-v_180 (450-850nm)_633nm_edge_100%_x100_vis_lwd_h30um_80sx4_01.txt
#Acq. time (s)=	80
#Accumulations=	4
#Range (cm-¹)=	1200...1449
#Windows=	1
#Auto scanning=	Off
#Autofocus=	Off
#Macrospot=	Off
#AutoExposure=	Off
#Spike filter=	Multiple accum.
#Delay time (s)=	2
#Binning=	1
#Readout mode=	Signal
#DeNoise=	Off
#ICS correction=	On
#Dark correction=	Off
#Inst. Process=	Off
#Detector Gain=	Best Dynamic
#Detector ADC=	50 kHz EM
#Detector EM gain=	150
#Detector temperature (°C)=	-60.09
#Instrument=	LabRAM HR Evol
#Detector=	SIN-EM FIVIS
#Objective=	x100_VIS_LWD
#Grating=	1800 (450-850nm)
#ND Filter=	100%
#Laser=	633nm_Edge
#Hole=	30.0125
#Temperature=	39.9
#Range=	Visible
#StageXY=	75x50mm Scan+
#StageZ=	Z motor
#X (µm)=	0
#Y (µm)=	0
#Z (µm)=	22.9
#Full time(mm:ss)=	5:25
#Project=	21_08_11
#Sample=	BU20
#Site=
#Title=	BU20-B-FF4-FI01-V_1800 (450-850nm)_633nm_Edge_100%_x100_VIS_LWD_H30um_80sX4
#Remark=
#Date=	13.08.2021 14:46
#Acquired=	13.08.2021 14:46:08
#Data Range:Extract=	16.12.2021 15:36:30
#Base:Fit=	16.12.2021 15:36:40
#Base:Fit=	16.12.2021 15:51:53
#Base:Sub=	16.12.2021 15:51:55
1200.07	-0.968781
1200.25	-1.10193
1200.42	-0.0458069
1200.59	-3.37341
1200.76	-1.01044
1200.93	-1.23419
1201.11	1.20276
1201.28	5.95065
1201.45	-0.0543518
1201.62	7.88846
1201.79	-2.20547
1201.97	4.07443
1202.14	1.8494
1202.31	1.78708
1202.48	2.62668
1202.65	-0.537262
1202.83	1.87341
1203	1.71051
1203.17	4.07541
1203.34	-0.402802
1203.51	0.935547
1203.69	2.83356
1203.86	-6.22696
1204.03	1.7038
1204.2	-0.552216
1204.37	0.548523
1204.55	-1.93204
1204.72	0.0723572
1204.89	-2.15479
1205.06	5.34613
1205.23	2.92294
1205.41	2.0462
1205.58	0.333923
1205.75	1.77365
1205.92	2.41656
1206.09	0.161072
1206.26	-4.29919
1206.44	-3.29178
1206.61	0.963348
1206.78	-1.7135
1206.95	-7.05368
1207.12	0.922302
1207.3	-0.470215
1207.47	1.03549
1207.64	3.43893
1207.81	-0.881134
1207.98	5.05847
1208.16	-3.67197
1208.33	-1.81354
1208.5	-0.283508
1208.67	3.04938
1208.84	-1.6124
1209.02	-1.58685
1209.19	1.83154
1209.36	-3.44812
1209.53	1.82675
1209.7	-0.777985
1209.87	4.41174
1210.05	-3.03357
1210.22	4.11337
1210.39	2.58038
1210.56	0.167023
1210.73	-4.62085
1210.9	4.45444
1211.08	-0.818573
1211.25	-2.84348
1211.42	-4.10629
1211.59	0.485291
1211.76	0.860748
1211.93	2.51691
1212.11	-1.42627
1212.28	4.25238
1212.45	1.88995
1212.62	2.43567
1212.79	1.12003
1212.96	-0.772675
1213.13	1.00632
1213.31	-4.034
1213.48	0.260803
1213.65	2.67902
1213.82	-2.46622
1213.99	-0.887115
1214.17	-0.861145
1214.34	0.423553
1214.51	0.745178
1214.68	-0.0468445
1214.85	0.0816345
1215.02	-5.1171
1215.19	2.93292
1215.37	-0.304901
1215.54	3.0397
1215.71	0.101074
1215.88	-2.21219
1216.05	2.07062
1216.22	-0.0349426
1216.4	2.45627
1216.57	-1.41281
1216.74	1.79218
1216.91	1.5863
1217.08	6.60184
1217.25	2.50586
1217.42	1.86768
1217.6	-1.63019
1217.77	4.43124
1217.94	1.48459
1218.11	0.916046
1218.28	19.3549
1218.45	1.71017
1218.62	1.29541
1218.79	4.16766
1218.97	3.46848
1219.14	5.63278
1219.31	-0.090332
1219.48	-1.05795
1219.65	6.12619
1219.82	4.61224
1219.99	0.0928955
1220.17	0.911011
1220.34	2.3555
1220.51	4.10092
1220.68	4.7468
1220.85	2.99432
1221.02	6.79202
1221.19	0.0455933
1221.36	-1.37177
1221.53	1.22546
1221.71	2.92569
1221.88	1.0372
1222.05	3.05832
1222.22	-4.37274
1222.39	0.799713
1222.56	-1.22644
1222.73	1.33105
1222.91	-0.56955
1223.08	0.103546
1223.25	2.25803
1223.42	0.791473
1223.59	-2.29797
1223.76	2.55075
1223.93	1.61154
1224.1	1.93713
1224.28	6.93109
1224.45	5.86359
1224.62	-1.04187
1224.79	1.49844
1224.96	-2.76654
1225.13	-0.289215
1225.3	-5.48483
1225.47	1.71204
1225.64	2.32697
1225.82	2.11783
1225.99	2.40872
1226.16	8.26413
1226.33	3.82367
1226.5	2.02783
1226.67	-1.05756
1226.84	1.40521
1227.01	23.4857
1227.18	6.8772
1227.35	0.414917
1227.53	7.72687
1227.7	2.06689
1227.87	4.95203
1228.04	3.81464
1228.21	9.61493
1228.38	4.96201
1228.55	-1.13995
1228.72	6.6637
1228.89	8.55591
1229.06	10.6276
1229.23	5.46161
1229.41	2.56693
1229.58	4.29581
1229.75	9.26038
1229.92	4.38983
1230.09	7.56512
1230.26	0.780365
1230.43	6.98868
1230.6	11.4457
1230.77	2.41766
1230.94	6.31992
1231.11	0.643158
1231.29	4.04312
1231.46	6.15472
1231.63	5.75229
1231.8	0.262543
1231.97	0.304932
1232.14	6.5444
1232.31	9.50305
1232.48	3.20035
1232.65	5.42609
1232.82	3.95145
1232.99	8.91983
1233.16	9.04071
1233.34	10.0309
1233.51	1.97876
1233.68	5.10864
1233.85	11.2934
1234.02	5.05084
1234.19	9.99637
1234.36	6.20236
1234.53	7.53503
1234.7	1.11996
1234.87	7.09967
1235.04	16.1736
1235.21	3.23434
1235.38	5.68597
1235.55	4.93008
1235.73	4.39944
1235.89	4.47198
1236.07	2.3316
1236.24	5.61786
1236.41	9.98077
1236.58	7.79068
1236.75	3.88004
1236.92	6.12601
1237.09	4.42004
1237.26	3.38391
1237.43	9.37872
1237.6	6.83862
1237.77	6.5426
1237.94	4.59442
1238.11	1.76959
1238.28	2.86484
1238.46	10.7573
1238.62	9.26163
1238.8	11.1099
1238.97	4.20734
1239.14	1.03104
1239.31	7.64676
1239.48	3.07031
1239.65	3.82776
1239.82	6.40094
1239.99	1.22278
1240.16	4.93338
1240.33	6.20538
1240.5	8.4538
1240.67	6.94574
1240.84	5.05109
1241.01	4.88846
1241.18	7.75403
1241.35	2.16281
1241.52	4.24512
1241.69	4.81302
1241.86	6.91638
1242.03	6.43155
1242.21	3.60721
1242.37	6.46259
1242.55	9.22403
1242.72	5.76071
1242.89	6.60736
1243.06	6.45303
1243.23	4.702
1243.4	3.87881
1243.57	4.58072
1243.74	7.15686
1243.91	0.195587
1244.08	11.7301
1244.25	4.52203
1244.42	14.1909
1244.59	6.02905
1244.76	9.11185
1244.93	4.41879
1245.1	7.2092
1245.27	3.2832
1245.44	9.09897
1245.61	5.1098
1245.78	8.00504
1245.95	3.24429
1246.12	8.75015
1246.29	4.70724
1246.46	6.39661
1246.63	4.33875
1246.8	3.04623
1246.97	4.30075
1247.14	6.15018
1247.31	8.39499
1247.48	6.75082
1247.65	8.65082
1247.82	3.82925
1247.99	8.76654
1248.16	7.83484
1248.33	9.03387
1248.5	3.46429
1248.67	5.82471
1248.84	4.27066
1249.01	3.66858
1249.18	4.14926
1249.35	3.22543
1249.52	7.05905
1249.69	7.34546
1249.86	7.32858
1250.04	4.38959
1250.2	8.04156
1250.38	8.01358
1250.54	3.88809
1250.72	5.63898
1250.88	5.82156
1251.06	6.17307
1251.22	9.95157
1251.4	6.99658
1251.56	3.30612
1251.74	9.52502
1251.9	12.1219
1252.07	10.6487
1252.24	7.16718
1252.41	11.6903
1252.59	3.96014
1252.75	8.20163
1252.93	9.88162
1253.09	8.15372
1253.27	8.22382
1253.43	9.21725
1253.6	8.41403
1253.77	6.36188
1253.94	0.769958
1254.11	6.15271
1254.28	3.83032
1254.45	7.22406
1254.62	7.46323
1254.79	4.29913
1254.96	7.46432
1255.13	6.34006
1255.3	5.17349
1255.47	3.129
1255.64	9.64886
1255.81	8.36246
1255.98	28.8732
1256.15	8.90619
1256.32	7.77701
1256.49	8.95587
1256.66	9.95325
1256.83	4.72159
1257	11.4792
1257.17	7.96478
1257.34	13.5982
1257.51	12.7716
1257.68	6.53729
1257.85	9.89557
1258.02	16.8298
1258.19	8.55463
1258.36	11.2271
1258.53	12.343
1258.7	8.75565
1258.87	10.2119
1259.04	12.6326
1259.21	2.46796
1259.38	11.9135
1259.55	12.3598
1259.72	11.6754
1259.89	12.6479
1260.06	8.09268
1260.23	8.81152
1260.39	8.65991
1260.56	15.8271
1260.73	11.4073
1260.9	11.4691
1261.07	15.4714
1261.24	8.29694
1261.41	11.794
1261.58	13.1067
1261.75	22.02
1261.92	10.8059
1262.09	17.8752
1262.26	17.9983
1262.43	25.5769
1262.6	19.5612
1262.77	20.5109
1262.94	24.0214
1263.11	24.0579
1263.28	23.1346
1263.45	30.7075
1263.62	20.5529
1263.79	24.0273
1263.95	20.1078
1264.13	19.4684
1264.29	16.4763
1264.46	17.1759
1264.63	18.2882
1264.8	16.7278
1264.97	12.6409
1265.14	18.9433
1265.31	5.82928
1265.48	10.6652
1265.65	5.50089
1265.82	13.6529
1265.99	18.8841
1266.16	4.71265
1266.33	27.7427
1266.5	6.80942
1266.67	11.838
1266.84	10.6459
1267	7.83405
1267.17	8.66571
1267.34	8.41812
1267.51	3.84494
1267.68	10.6313
1267.85	10.0579
1268.02	7.59311
1268.19	9.92764
1268.36	9.19107
1268.53	8.1427
1268.7	4.96655
1268.87	3.07028
1269.04	10.2443
1269.21	13.2354
1269.37	8.36835
1269.54	3.71729
1269.71	5.73566
1269.88	13.6417
1270.05	0.0116272
1270.22	3.15958
1270.39	12.4368
1270.56	6.26181
1270.73	14.281
1270.9	9.73535
1271.07	11.4461
1271.24	7.44977
1271.4	6.21338
1271.57	5.44138
1271.74	9.38287
1271.91	6.83557
1272.08	9.56293
1272.25	7.53683
1272.42	2.66995
1272.59	2.92471
1272.76	7.60052
1272.93	2.97083
1273.1	5.94458
1273.26	6.66257
1273.43	3.80154
1273.6	6.36215
1273.77	11.0284
1273.94	12.5851
1274.11	2.67636
1274.28	7.37357
1274.45	4.90811
1274.62	8.93008
1274.79	8.65729
1274.95	5.0246
1275.12	6.72226
1275.29	4.04108
1275.46	8.62415
1275.63	19.9043
1275.8	8.15897
1275.97	6.70432
1276.14	10.1803
1276.31	3.97235
1276.48	7.70807
1276.64	6.78571
1276.81	7.23831
1276.98	8.78632
1277.15	8.86374
1277.32	10.4842
1277.49	10.1988
1277.66	7.50275
1277.83	8.29349
1278	14.1131
1278.16	8.0448
1278.33	7.38361
1278.5	6.9054
1278.67	10.8544
1278.84	15.9562
1279.01	10.6943
1279.18	9.68753
1279.35	19.5393
1279.52	10.3692
1279.69	18.5383
1279.85	12.9117
1280.02	14.4865
1280.19	19.3702
1280.36	22.2942
1280.53	31.1302
1280.7	35.8461
1280.87	33.1139
1281.03	39.8605
1281.2	48.0938
1281.37	54.2271
1281.54	60.7206
1281.71	81.3255
1281.88	87.9438
1282.05	107.498
1282.22	124.128
1282.38	182.035
1282.55	206.836
1282.72	228.609
1282.89	259.321
1283.06	305.681
1283.23	315.386
1283.4	306.211
1283.57	282.602
1283.73	260.36
1283.9	246.187
1284.07	176.33
1284.24	171.316
1284.41	121.001
1284.58	119.643
1284.75	72.4336
1284.91	66.49
1285.08	53.6753
1285.25	52.5032
1285.42	33.821
1285.59	31.5775
1285.76	30.2365
1285.93	25.5481
1286.09	16.0727
1286.26	25.4919
1286.43	20.7657
1286.6	12.2973
1286.77	10.9841
1286.94	15.5406
1287.1	11.6182
1287.27	11.1305
1287.44	10.5938
1287.61	14.5222
1287.78	14.4344
1287.95	4.06091
1288.12	2.58627
1288.28	6.20331
1288.45	6.2666
1288.62	10.5144
1288.79	11.7954
1288.96	4.13168
1289.13	9.12247
1289.29	4.91479
1289.46	10.3851
1289.63	7.13492
1289.8	11.693
1289.97	7.66318
1290.14	4.12646
1290.31	6.83057
1290.47	6.38135
1290.64	3.87033
1290.81	3.17398
1290.98	1.20969
1291.15	1.20166
1291.31	6.07977
1291.48	6.49545
1291.65	6.79041
1291.82	6.73981
1291.99	4.43774
1292.16	2.45355
1292.32	4.0661
1292.49	-2.5549
1292.66	6.72491
1292.83	-1.69202
1293	2.84262
1293.17	0.792206
1293.33	3.13855
1293.5	-1.20462
1293.67	-0.296692
1293.84	1.53708
1294.01	3.27881
1294.17	3.79266
1294.34	3.21503
1294.51	-2.40805
1294.68	6.9014
1294.85	3.56714
1295.02	2.27795
1295.18	0.140259
1295.35	2.75549
1295.52	4.04697
1295.69	-2.0517
1295.86	7.85095
1296.03	1.26471
1296.19	6.14093
1296.36	3.953
1296.53	1.04486
1296.7	-0.79715
1296.86	-0.433014
1297.03	8.52271
1297.2	-0.147278
1297.37	1.51028
1297.54	1.80765
1297.7	2.36572
1297.87	10.7841
1298.04	1.03824
1298.21	-2.2373
1298.38	-0.424408
1298.55	1.87854
1298.71	1.79819
1298.88	3.35464
1299.05	10.7029
1299.22	8.27429
1299.39	0.0556946
1299.55	3.35397
1299.72	-1.08481
1299.89	-2.29977
1300.06	2.30377
1300.23	-1.06073
1300.39	-3.04053
1300.56	-0.650177
1300.73	5.32138
1300.9	0.391998
1301.07	0.386078
1301.23	-1.51593
1301.4	7.38412
1301.57	-0.804535
1301.74	-0.598358
1301.9	2.64093
1302.07	-2.92578
1302.24	1.01709
1302.41	7.39999
1302.58	-3.90469
1302.74	5.67789
1302.91	3.9151
1303.08	4.58371
1303.25	-2.00912
1303.42	-0.214661
1303.58	-3.31305
1303.75	3.98248
1303.92	-2.6778
1304.09	0.464417
1304.25	0.786102
1304.42	-1.55048
1304.59	2.68015
1304.76	4.33597
1304.92	-3.13196
1305.09	1.1843
1305.26	-0.879547
1305.43	-2.0705
1305.59	-2.52347
1305.76	-1.06693
1305.93	4.51221
1306.1	1.99078
1306.27	-0.619873
1306.43	-1.10455
1306.6	1.08655
1306.77	-3.70416
1306.94	-0.616577
1307.1	-5.08139
1307.27	3.94821
1307.44	-1.31671
1307.61	0.54837
1307.78	-0.380371
1307.94	-1.57248
1308.11	0.680206
1308.28	5.41241
1308.44	-0.146454
1308.61	-0.675507
1308.78	7.46121
1308.95	-3.47638
1309.12	-2.05811
1309.28	-0.0240479
1309.45	-2.28754
1309.62	2.32745
1309.79	-0.497192
1309.95	-1.47049
1310.12	0.213928
1310.29	-1.13287
1310.46	-1.92761
1310.62	2.20657
1310.79	5.49167
1310.96	2.073
1311.13	-3.32196
1311.29	-2.10956
1311.46	4.85962
1311.63	-4.26755
1311.79	0.64151
1311.96	-0.53125
1312.13	4.66592
1312.3	2.44516
1312.47	-4.04065
1312.63	-4.3313
1312.8	5.04141
1312.97	-3.22684
1313.13	-1.41406
1313.3	3.7887
1313.47	-0.478912
1313.64	-0.425262
1313.8	-4.76642
1313.97	3.87643
1314.14	1.1817
1314.31	-1.77762
1314.47	0.715118
1314.64	-7.30917
1314.81	2.76068
1314.98	0.30246
1315.14	-0.359863
1315.31	4.16574
1315.48	-1.73587
1315.64	5.66257
1315.81	-2.22964
1315.98	-3.00961
1316.15	2.6441
1316.31	-1.62689
1316.48	1.25189
1316.65	1.86459
1316.82	-1.70151
1316.98	-2.49445
1317.15	8.03229
1317.32	4.1022
1317.48	4.18448
1317.65	6.48514
1317.82	-0.501465
1317.99	8.42758
1318.15	0.686981
1318.32	5.95654
1318.49	1.25272
1318.65	-0.0975342
1318.82	0.706696
1318.99	14.9326
1319.16	2.92728
1319.32	1.64429
1319.49	4.05209
1319.66	-3.17624
1319.82	-4.375
1319.99	-1.86343
1320.16	3.62946
1320.33	1.60233
1320.49	1.75818
1320.66	1.61829
1320.83	4.77353
1320.99	1.63519
1321.16	1.52356
1321.33	2.96677
1321.5	0.513763
1321.66	12.2155
1321.83	1.78534
1322	0.658936
1322.16	-3.40784
1322.33	-2.81735
1322.5	3.52225
1322.66	1.67139
1322.83	-0.635284
1323	-0.500092
1323.17	1.3447
1323.33	1.49902
1323.5	3.44968
1323.67	3.077
1323.83	-2.97507
1324	-0.00726318
1324.17	4.79837
1324.33	-2.60739
1324.5	1.50165
1324.67	8.65134
1324.83	7.54358
1325	7.77689
1325.17	2.49414
1325.33	3.08264
1325.5	8.68002
1325.67	3.66708
1325.84	8.17599
1326	-5.37589
1326.17	4.66821
1326.34	2.30518
1326.5	8.36374
1326.67	-3.16599
1326.84	7.27039
1327	2.82535
1327.17	5.87317
1327.34	1.21188
1327.5	1.86221
1327.67	9.79251
1327.84	3.98059
1328	2.49612
1328.17	5.19113
1328.34	6.74359
1328.5	8.61029
1328.67	-0.0232239
1328.84	10.4062
1329	11.6402
1329.17	2.6171
1329.34	2.6434
1329.5	7.57626
1329.67	4.48651
1329.84	4.34698
1330	7.08685
1330.17	1.58078
1330.34	2.50259
1330.5	5.76962
1330.67	-0.975647
1330.84	3.29117
1331	2.60062
1331.17	5.63196
1331.34	-0.180664
1331.5	7.55017
1331.67	8.12357
1331.84	4.72275
1332	0.328247
1332.17	5.39539
1332.34	9.6163
1332.5	12.5514
1332.67	7.26862
1332.84	7.11551
1333	2.53482
1333.17	-1.85913
1333.34	3.06714
1333.5	6.24893
1333.67	4.96265
1333.84	4.58612
1334	3.55017
1334.17	5.43512
1334.34	10.4455
1334.5	1.87393
1334.67	1.78485
1334.83	10.4315
1335	1.95081
1335.17	1.03098
1335.33	4.53986
1335.5	2.51541
1335.67	7.81192
1335.83	9.15594
1336	0.935974
1336.17	1.85007
1336.33	3.78357
1336.5	2.8931
1336.66	6.93335
1336.83	7.14658
1337	-1.84003
1337.16	4.84491
1337.33	6.95065
1337.5	4.66245
1337.66	2.75458
1337.83	3.1705
1338	17.9511
1338.16	6.78043
1338.33	17.1681
1338.49	4.918
1338.66	8.84711
1338.83	6.76596
1338.99	-1.98373
1339.16	0.818695
1339.33	11.2238
1339.49	10.6145
1339.66	4.5217
1339.83	7.95358
1339.99	13.8764
1340.16	6.47491
1340.32	3.5687
1340.49	8.99878
1340.66	3.65625
1340.82	4.35175
1340.99	-1.91821
1341.15	10.5426
1341.32	8.75452
1341.49	8.48819
1341.65	7.76172
1341.82	5.83597
1341.99	3.46411
1342.15	6.48163
1342.32	9.05118
1342.48	17.463
1342.65	8.5213
1342.82	3.27631
1342.98	8.43604
1343.15	11.2244
1343.32	0.767151
1343.48	8.69385
1343.65	5.08981
1343.81	7.086
1343.98	7.86691
1344.14	10.8406
1344.31	11.9837
1344.48	9.08875
1344.64	6.80896
1344.81	6.04364
1344.98	2.98636
1345.14	-0.648041
1345.31	2.20502
1345.47	40.1999
1345.64	6.06244
1345.8	6.29257
1345.97	12.8028
1346.14	4.90515
1346.3	9.76773
1346.47	1.41092
1346.64	4.45383
1346.8	8.71033
1346.97	9.0083
1347.13	2.71667
1347.3	5.43713
1347.46	10.5693
1347.63	7.56705
1347.8	1.91629
1347.96	5.28571
1348.13	11.7412
1348.29	8.88327
1348.46	8.0058
1348.63	13.1951
1348.79	1.50201
1348.96	8.1395
1349.12	3.70901
1349.29	7.88803
1349.45	16.3452
1349.62	11.3108
1349.79	9.98087
1349.95	4.33347
1350.12	7.13541
1350.28	12.5608
1350.45	7.57132
1350.62	4.12262
1350.78	6.06714
1350.95	8.0108
1351.11	10.5645
1351.28	7.76947
1351.44	5.47302
1351.61	13.5015
1351.78	2.25742
1351.94	10.1877
1352.11	10.585
1352.27	6.81863
1352.44	8.27545
1352.6	11.8665
1352.77	7.14789
1352.94	6.08243
1353.1	3.41751
1353.27	5.81143
1353.43	12.7198
1353.6	7.88531
1353.76	9.24591
1353.93	9.36935
1354.1	11.9379
1354.26	6.40515
1354.43	8.31055
1354.59	9.24121
1354.76	10.4337
1354.92	8.48517
1355.09	12.222
1355.26	5.16873
1355.42	4.83273
1355.59	5.22867
1355.75	5.46268
1355.92	11.7146
1356.08	7.12512
1356.25	6.15027
1356.41	8.23022
1356.58	8.46466
1356.74	12.3629
1356.91	2.95822
1357.08	6.35138
1357.24	8.49881
1357.41	11.4484
1357.57	6.60269
1357.74	13.0326
1357.9	7.40842
1358.07	9.26843
1358.23	11.5262
1358.4	3.70267
1358.57	9.16885
1358.73	9.55698
1358.9	9.5625
1359.06	4.56219
1359.23	13.7931
1359.39	9.94089
1359.56	7.5925
1359.72	3.53809
1359.89	9.89981
1360.05	6.76456
1360.22	5.83704
1360.38	12.7339
1360.55	3.39355
1360.72	5.4137
1360.88	7.43964
1361.05	8.05432
1361.21	6.86496
1361.38	6.53754
1361.54	5.25046
1361.71	8.08551
1361.87	6.15549
1362.04	8.73453
1362.2	9.74435
1362.37	8.82773
1362.53	6.18863
1362.7	4.13034
1362.86	5.12891
1363.03	11.4697
1363.19	7.62616
1363.36	5.05011
1363.53	18.9074
1363.69	11.6333
1363.86	6.14926
1364.02	8.2991
1364.19	12.899
1364.35	7.87848
1364.52	5.92712
1364.68	9.00949
1364.85	16.1982
1365.01	2.09705
1365.18	9.49081
1365.34	16.6689
1365.51	12.4764
1365.67	8.6087
1365.84	10.7424
1366	3.64044
1366.17	10.8611
1366.33	5.30042
1366.5	6.79108
1366.66	11.8241
1366.83	2.9715
1366.99	10.2387
1367.16	4.74094
1367.32	5.20761
1367.49	3.74683
1367.65	8.16739
1367.82	10.212
1367.98	5.59592
1368.15	14.4921
1368.31	7.78763
1368.48	11.9966
1368.64	10.6246
1368.81	6.97565
1368.97	12.871
1369.14	16.6635
1369.3	26.6766
1369.47	21.0605
1369.63	18.6715
1369.8	11.0522
1369.96	16.9146
1370.13	13.8003
1370.29	13.4979
1370.46	12.2462
1370.62	10.5948
1370.79	12.5169
1370.95	12.7859
1371.12	0.33728
1371.28	6.61383
1371.45	3.22726
1371.61	13.2224
1371.78	6.95255
1371.94	7.56232
1372.11	12.123
1372.27	8.63583
1372.44	10.9581
1372.6	10.4502
1372.77	7.10886
1372.93	5.20737
1373.1	9.07318
1373.26	10.8746
1373.43	7.37714
1373.59	13.8655
1373.76	10.5449
1373.92	11.4968
1374.09	8.10287
1374.25	1.79288
1374.42	10.3573
1374.58	12.9607
1374.75	8.7092
1374.91	8.89648
1375.07	12.0323
1375.24	28.4434
1375.4	12.9894
1375.57	8.46857
1375.73	8.3465
1375.9	8.84689
1376.06	18.7289
1376.23	8.31207
1376.39	9.26138
1376.56	4.07651
1376.72	12.5101
1376.89	17.1227
1377.05	13.7146
1377.22	13.3849
1377.38	10.1711
1377.55	27.7041
1377.71	10.4796
1377.87	13.1323
1378.04	12.3283
1378.2	5.90698
1378.37	19.9171
1378.53	9.28693
1378.7	12.3323
1378.86	9.99551
1379.03	4.96335
1379.19	9.02686
1379.36	12.5553
1379.52	9.28943
1379.68	8.52267
1379.85	15.1646
1380.01	6.88733
1380.18	10.5325
1380.34	9.73105
1380.51	17.1185
1380.67	16.3159
1380.84	15.3399
1381	14.1552
1381.17	11.1952
1381.33	8.76923
1381.49	18.3965
1381.66	13.3008
1381.82	11.7377
1381.99	13.938
1382.15	11.9782
1382.32	14.0304
1382.48	17.7988
1382.64	20.5763
1382.81	16.6418
1382.97	19.1358
1383.14	15.6443
1383.3	19.1279
1383.47	24.5053
1383.63	22.1427
1383.8	26.0952
1383.96	24.0287
1384.12	30.4279
1384.29	30.1107
1384.45	34.2432
1384.62	49.7163
1384.78	41.1281
1384.95	55.0453
1385.11	50.7002
1385.28	79.6621
1385.44	75.8119
1385.6	97.8533
1385.77	109.923
1385.93	141.786
1386.1	192.831
1386.26	230.367
1386.42	318.101
1386.59	388.585
1386.75	519.035
1386.92	629.583
1387.08	690.908
1387.25	707.913
1387.41	621.467
1387.57	529.36
1387.74	370.848
1387.9	304.738
1388.07	196.453
1388.23	158.029
1388.4	118.383
1388.56	93.8084
1388.72	70.9872
1388.89	51.4548
1389.05	62.1741
1389.22	42.5596
1389.38	34.6239
1389.54	38.0505
1389.71	31.0703
1389.87	29.2584
1390.04	27.1961
1390.2	24.701
1390.37	20.8873
1390.53	22.1995
1390.69	17.422
1390.86	29.465
1391.02	8.35294
1391.19	28.3651
1391.35	11.0134
1391.51	14.3405
1391.68	13.6786
1391.84	11.5422
1392.01	11.6974
1392.17	10.4689
1392.33	8.61819
1392.5	12.7889
1392.66	8.64136
1392.83	16.6777
1392.99	4.12268
1393.15	6.3446
1393.32	9.95309
1393.48	10.3575
1393.65	18.5682
1393.81	13.3858
1393.97	14.2338
1394.14	10.3474
1394.3	9.01437
1394.46	6.99893
1394.63	15.2822
1394.79	8.40112
1394.96	14.1817
1395.12	5.12793
1395.28	7.96619
1395.45	8.02264
1395.61	12.5037
1395.78	3.36087
1395.94	8.44858
1396.1	12.0443
1396.27	8.33029
1396.43	12.7357
1396.6	10.0807
1396.76	12.1467
1396.92	10.6887
1397.09	7.39984
1397.25	0.229431
1397.41	5.21982
1397.58	14.9945
1397.74	9.25363
1397.91	5.53207
1398.07	15.9739
1398.23	7.15176
1398.4	0.767059
1398.56	8.65796
1398.72	9.64624
1398.89	10.8791
1399.05	8.03662
1399.21	9.46814
1399.38	7.79385
1399.54	5.26694
1399.71	9.30219
1399.87	12.2361
1400.03	7.59653
1400.2	6.02362
1400.36	3.28973
1400.52	5.87741
1400.69	3.84058
1400.85	9.47104
1401.02	8.87439
1401.18	8.77771
1401.34	9.43228
1401.51	5.5491
1401.67	6.09277
1401.83	4.59915
1402	10.57
1402.16	8.49338
1402.32	4.51785
1402.49	4.40576
1402.65	4.13016
1402.82	13.4873
1402.98	5.70593
1403.14	8.71521
1403.31	6.36456
1403.47	13.3468
1403.63	8.55762
1403.8	10.9969
1403.96	9.00192
1404.12	3.12354
1404.29	6.1864
1404.45	6.81284
1404.61	13.8987
1404.78	5.54175
1404.94	13.4558
1405.1	11.0067
1405.27	7.40503
1405.43	7.07477
1405.59	10.8955
1405.76	10.9048
1405.92	13.2162
1406.08	8.07764
1406.25	11.2837
1406.41	9.39075
1406.57	11.0426
1406.74	14.1323
1406.9	5.1871
1407.06	8.47672
1407.23	15.6637
1407.39	16.6271
1407.56	20.4577
1407.72	25.4505
1407.88	22.5012
1408.04	31.5019
1408.21	24.627
1408.37	28.5064
1408.54	29.4492
1408.7	31.3532
1408.86	34.3071
1409.02	23.3295
1409.19	29.9172
1409.35	30.9248
1409.51	21.3877
1409.68	27.7902
1409.84	16.2504
1410	52.8566
1410.17	11.1687
1410.33	9.89731
1410.49	9.62073
1410.66	13.999
1410.82	14.2708
1410.98	6.79398
1411.15	7.19681
1411.31	12.2513
1411.47	5.59155
1411.64	3.04218
1411.8	0.997284
1411.96	7.10693
1412.13	1.52133
1412.29	7.70898
1412.45	2.37946
1412.62	6.61276
1412.78	0.625153
1412.94	7.64438
1413.1	0.124084
1413.27	2.14993
1413.43	-1.33252
1413.59	9.97748
1413.76	-1.56067
1413.92	5.05756
1414.08	1.18091
1414.25	8.01398
1414.41	3.06982
1414.57	-0.218445
1414.73	4.95807
1414.9	-3.60883
1415.06	2.16595
1415.22	5.56982
1415.39	0.0578918
1415.55	1.57758
1415.71	-0.986572
1415.88	17.7003
1416.04	10.5897
1416.2	-2.23215
1416.37	-2.29807
1416.53	0.656372
1416.69	5.73367
1416.85	1.78827
1417.02	3.21045
1417.18	2.92477
1417.34	-0.0884094
1417.51	9.12625
1417.67	0.678986
1417.83	-0.677185
1417.99	-2.0079
1418.16	1.67361
1418.32	1.77155
1418.48	6.63254
1418.65	4.0155
1418.81	2.26758
1418.97	-4.15573
1419.13	-3.73163
1419.3	-0.0065918
1419.46	7.07458
1419.62	1.6752
1419.79	1.44641
1419.95	1.05637
1420.11	0.153229
1420.27	-1.72794
1420.44	-2.42606
1420.6	2.84189
1420.76	5.15829
1420.93	-4.34705
1421.09	-1.76868
1421.25	3.33398
1421.41	1.19028
1421.58	2.48721
1421.74	4.35254
1421.9	2.88385
1422.06	1.16885
1422.23	2.76965
1422.39	5.73178
1422.55	3.42496
1422.72	3.61325
1422.88	-0.758179
1423.04	3.78625
1423.2	0.00924683
1423.37	-1.9696
1423.53	-1.00873
1423.69	3.1933
1423.85	-0.497498
1424.02	1.85837
1424.18	-0.973816
1424.34	4.47354
1424.5	-2.30688
1424.67	3.97025
1424.83	-2.6174
1424.99	-2.14594
1425.16	-1.86441
1425.32	1.21191
1425.48	-1.2149
1425.64	0.175995
1425.81	2.3916
1425.97	-6.38382
1426.13	-2.49564
1426.29	-1.98386
1426.46	4.10648
1426.62	3.54999
1426.78	0.00848389
1426.94	6.83032
1427.11	2.0397
1427.27	-0.231476
1427.43	3.21252
1427.59	-0.888245
1427.76	0.220337
1427.92	4.42865
1428.08	-0.848969
1428.24	4.12067
1428.41	-5.99631
1428.57	3.88278
1428.73	-4.60803
1428.89	6.823
1429.05	-0.440643
1429.22	1.77612
1429.38	1.05569
1429.54	0.759003
1429.7	-0.203033
1429.87	-1.12024
1430.03	-1.38528
1430.19	0.868591
1430.35	-2.19348
1430.52	-5.78305
1430.68	3.32245
1430.84	-0.826324
1431	-4.37354
1431.17	-2.00146
1431.33	0.587982
1431.49	1.31342
1431.65	-2.41287
1431.81	-2.77731
1431.98	0.243378
1432.14	0.56662
1432.3	6.6268
1432.46	-0.746246
1432.63	-1.16278
1432.79	-1.75165
1432.95	-2.06235
1433.11	-2.16351
1433.28	1.10004
1433.44	-0.634399
1433.6	-3.58035
1433.76	-0.116394
1433.92	5.56531
1434.09	2.59641
1434.25	-3.39285
1434.41	-1.84729
1434.57	0.583282
1434.74	-0.318085
1434.9	-0.43335
1435.06	-2.84695
1435.22	2.77774
1435.38	1.76492
1435.55	-0.350403
1435.71	1.40814
1435.87	-0.155487
1436.03	3.5296
1436.2	1.92914
1436.36	4.07639
1436.52	9.9519
1436.68	2.45309
1436.84	4.22693
1437.01	-1.80685
1437.17	-1.01151
1437.33	-3.04544
1437.49	2.98248
1437.65	2.10529
1437.82	0.750732
1437.98	-1.66129
1438.14	-0.453247
1438.3	-3.96066
1438.46	-0.716827
1438.63	1.19998
1438.79	3.51312
1438.95	0.746552
1439.11	3.94324
1439.27	3.49164
1439.44	5.35254
1439.6	-1.02408
1439.76	4.50815
1439.92	0.889038
1440.08	2.19592
1440.25	-3.98462
1440.41	2.14398
1440.57	-1.00558
1440.73	-3.20825
1440.89	4.15543
1441.06	-0.586578
1441.22	1.06448
1441.38	0.0346375
1441.54	-0.206177
1441.7	9.04327
1441.86	-0.397858
1442.03	1.09714
1442.19	-3.08847
1442.35	2.72797
1442.51	1.95999
1442.67	2.05862
1442.84	0.4776
1443	0.360962
1443.16	0.359711
1443.32	-3.49075
1443.48	-4.52039
1443.64	-4.38309
1443.81	-2.1579
1443.97	3.13272
1444.13	0.41687
1444.29	3.07574
1444.45	3.4075
1444.62	-3.83936
1444.78	-0.244141
1444.94	1.85385
1445.1	4.61139
1445.26	3.85544
1445.42	21.3194
1445.59	-2.12827
1445.75	-1.74719
1445.91	2.17108
1446.07	-0.984222
1446.23	2.73642
1446.39	4.39716
1446.56	-1.62595
1446.72	16.098
1446.88	-1.01852
1447.04	-1.76581
1447.2	-0.893097
1447.36	2.04517
1447.53	0.712982
1447.69	-4.46176
1447.85	-1.88184
1448.01	-2.28525
1448.17	0.869293
1448.33	-0.929352
1448.49	1.24448
1448.66	5.42249
1448.82	-3.41043
1448.98	2.76086
1449.14	2.08862
1449.3	2.4473
1449.46	1.99078
1449.63	4.74219
1449.79	4.34857
1449.95	-1.05283