File: Data/3-Raman/processed/bu20-C-brt1-FI06-633-v.txt
#Acq. time (s)=	20
#Accumulations=	3
#Range (cm-¹)=	100...4000
#Windows=	1
#Auto scanning=	Off
#Autofocus=	Off
#Macrospot=	Off
#AutoExposure=	Off
#Spike filter=	Multiple accum.
#Delay time (s)=	0
#Binning=	1
#Readout mode=	Signal
#DeNoise=	Lite
#ICS correction=	Off
#Dark correction=	Off
#Inst. Process=	Off
#Detector temperature (°C)=	-60.09
#Instrument=	LabRAM HR Evol
#Detector=	SIN-EM FIVIS
#Objective=	x50_VIS_LWD
#Grating=	150 (500nm)
#ND Filter=	100%
#Laser=	633nm_Edge
#Hole=	30.0125
#Temperature=	0
#Range=	Visible
#StageXY=	75x50mm Scan+
#StageZ=	Z motor
#X (µm)=	7466
#Y (µm)=	4175.7
#Z (µm)=	-32.7
#Full time(mm:ss)=	1:02
#Project=	Buranga
#Sample=	BU18FA20_C
#Site=	C_Bertoss1
#Title=	20-C_brt1_FI06
#Remark=
#Date=	30.07.2019 14:32
#Acquired=	30.07.2019 14:32:44
#Data Range:Extract=	16.12.2021 15:36:30
#Base:Fit=	16.12.2021 15:36:40
#Base:Edit=	16.12.2021 15:37:36
#Base:Edit=	16.12.2021 15:37:37
#Base:Edit=	16.12.2021 15:37:38
#Base:Edit=	16.12.2021 15:37:39
#Base:Sub=	16.12.2021 15:37:43
100.38	326.775
106.898	260.164
113.411	205.09
119.918	160.704
126.419	128.646
132.916	103.522
139.407	90.734
145.892	82.3835
152.372	65.675
158.847	53.6939
165.316	45.281
171.781	45.4336
178.239	28.7078
184.693	18.0652
191.139	12.6641
197.582	9.43407
204.02	6.47935
210.452	2.49165
216.877	-0.634933
223.299	3.01547
229.715	17.2256
236.126	42.9482
242.53	144.332
248.931	88.4686
255.326	49.1788
261.714	36.4468
268.099	42.3572
274.477	56.0736
280.851	54.3763
287.218	128.799
293.582	158.845
299.939	88.6925
306.293	38.7784
312.639	16.2925
318.982	19.4995
325.318	60.7294
331.651	173.706
337.977	156.287
344.297	79.0242
350.614	29.2905
356.925	27.642
363.23	46.3845
369.53	65.4109
375.827	57.5229
382.116	33.7357
388.401	7.07819
394.681	-0.127991
400.956	0.411591
407.226	3.61313
413.49	7.78391
419.749	12.9568
426.003	21.0551
432.252	53.6374
438.496	76.2149
444.735	120.505
450.969	110.449
457.197	100.084
463.421	85.6891
469.64	63.0806
475.853	35.6101
482.062	20.443
488.265	13.4689
494.464	5.53586
500.657	8.52116
506.844	16.4533
513.028	21.2613
519.206	23.2568
525.38	24.0832
531.548	22.2251
537.71	20.7007
543.869	19.28
550.022	17.9464
556.169	13.2709
562.313	5.67749
568.452	14.1469
574.584	15.3759
580.713	13.6599
586.837	12.303
592.954	34.3974
599.068	69.0854
605.176	115.799
611.28	120.213
617.378	94.8643
623.473	88.8607
629.561	92.0043
635.644	97.4773
641.724	94.4883
647.797	79.524
653.867	81.6635
659.931	95.2681
665.99	103.372
672.044	84.5375
678.095	55.4625
684.139	33.1864
690.179	17.9559
696.213	8.81725
702.245	6.48595
708.27	10.8991
714.29	10.6844
720.306	2.97152
726.316	-0.617065
732.322	1.4425
738.323	5.76736
744.32	10.4502
750.311	10.7486
756.298	9.33572
762.28	9.54845
768.258	9.89355
774.23	9.87663
780.198	9.6409
786.161	9.10368
792.119	9.28683
798.073	6.36108
804.021	5.5193
809.965	3.04548
815.904	8.71983
821.839	12.8503
827.769	13.7511
833.693	15.3179
839.614	15.9959
845.53	16.2817
851.44	15.8089
857.346	19.5926
863.248	17.7432
869.144	18.3512
875.037	16.5068
880.924	19.896
886.807	25.0996
892.685	28.2972
898.559	25.7242
904.427	24.2986
910.292	24.6914
916.151	26.8734
922.006	31.2711
927.856	33.5723
933.701	35.7365
939.543	42.9778
945.379	56.2213
951.21	71.2814
957.037	91.4208
962.861	111.345
968.678	122.265
974.491	141.09
980.3	176.705
986.104	259.179
991.904	368.887
997.699	392.341
1003.49	306.191
1009.28	243.408
1015.06	210.091
1020.83	231.571
1026.61	272.504
1032.37	293.065
1038.14	225.13
1043.9	149.841
1049.65	105.815
1055.4	96.5163
1061.15	73.5471
1066.88	66.1644
1072.62	66.3704
1078.35	67.1
1084.08	80.372
1089.8	96.3596
1095.52	111.78
1101.23	124.117
1106.94	128.12
1112.65	99.5442
1118.35	69.1848
1124.05	47.8526
1129.74	35.9362
1135.42	40.3638
1141.11	52.6386
1146.78	64.5513
1152.46	75.0441
1158.13	89.9971
1163.79	84.2963
1169.45	51.9175
1175.11	27.6561
1180.76	23.7583
1186.41	23.5047
1192.05	18.2467
1197.69	13.4373
1203.32	12.852
1208.95	14.1683
1214.58	11.9661
1220.2	9.17786
1225.82	8.03104
1231.43	9.05333
1237.04	10.9174
1242.64	12.056
1248.24	10.4869
1253.83	12.1192
1259.42	13.7753
1265.01	16.9278
1270.59	13.4674
1276.17	8.02058
1281.74	64.1048
1287.31	106.605
1292.88	20.4254
1298.44	14.1341
1303.99	9.92237
1309.55	10.0507
1315.09	10.9521
1320.64	11.0965
1326.18	8.85004
1331.71	7.58712
1337.24	7.2907
1342.77	3.85193
1348.29	2.22511
1353.81	1.95929
1359.32	5.38294
1364.83	8.39987
1370.33	10.5374
1375.84	12.4251
1381.33	13.1707
1386.82	194.022
1392.31	76.2251
1397.8	12.0643
1403.28	15.4075
1408.75	19.2732
1414.22	14.0598
1419.69	5.77876
1425.15	3.01785
1430.61	0.947441
1436.07	0.838112
1441.52	1.9866
1446.96	2.89188
1452.41	2.12416
1457.84	-1.76537
1463.28	0.69175
1468.71	0.252258
1474.13	-0.484573
1479.55	0.435959
1484.97	1.75265
1490.39	2.7985
1495.79	3.54607
1501.2	2.82276
1506.6	0.974258
1512	-0.691872
1517.39	-0.910332
1522.78	0.331772
1528.16	-1.15036
1533.54	-3.22896
1538.92	-3.55476
1544.29	-3.65676
1549.66	-3.80034
1555.02	0.168777
1560.38	0.305061
1565.74	1.947
1571.09	4.09676
1576.44	2.68496
1581.78	2.05557
1587.12	2.4439
1592.46	3.06052
1597.79	3.57639
1603.12	2.58442
1608.44	-0.000816345
1613.76	0.345078
1619.08	1.00885
1624.39	1.5034
1629.7	2.35654
1635	1.64864
1640.3	-0.677605
1645.59	-1.38727
1650.88	0.152
1656.17	1.33784
1661.46	3.26108
1666.74	4.87836
1672.01	4.87307
1677.28	4.02058
1682.55	4.33104
1687.82	5.01806
1693.07	6.59988
1698.33	5.16209
1703.58	1.18008
1708.83	-0.920807
1714.07	0.948502
1719.31	3.45802
1724.55	2.79985
1729.78	2.68992
1735.01	3.42063
1740.23	4.26738
1745.46	4.5112
1750.67	2.64738
1755.89	1.30101
1761.09	2.4279
1766.3	2.26866
1771.5	1.657
1776.7	1.46419
1781.89	1.75061
1787.08	2.52821
1792.27	3.91997
1797.45	3.6756
1802.62	1.19881
1807.8	0.351067
1812.97	1.72458
1818.14	2.20478
1823.3	3.84216
1828.46	4.54886
1833.61	3.02354
1838.76	1.46569
1843.91	2.26991
1849.05	3.77443
1854.19	4.20347
1859.33	2.63931
1864.46	0.824341
1869.59	1.30963
1874.71	2.25275
1879.83	4.04564
1884.95	4.94434
1890.06	6.44005
1895.17	5.5965
1900.27	5.06219
1905.38	4.6853
1910.47	-1.31975
1915.57	2.66885
1920.66	3.16284
1925.74	1.84592
1930.83	1.65079
1935.91	0.856461
1940.98	1.00487
1946.05	1.59328
1951.12	2.07698
1956.18	1.74049
1961.25	4.93143
1966.3	1.33714
1971.35	2.64108
1976.4	3.55224
1981.45	3.69218
1986.49	4.1032
1991.53	5.41881
1996.56	5.35439
2001.59	4.4989
2006.62	3.24213
2011.64	0.910194
2016.66	1.73869
2021.68	1.80729
2026.69	0.835915
2031.7	1.13946
2036.7	1.88048
2041.7	3.3275
2046.7	4.96571
2051.7	3.77192
2056.69	3.08581
2061.67	2.73679
2066.65	2.81377
2071.63	2.96275
2076.61	3.57776
2081.58	3.79307
2086.55	5.23222
2091.51	6.00317
2096.47	4.54443
2101.43	3.58749
2106.39	4.38739
2111.34	3.70044
2116.28	2.11977
2121.23	0.784737
2126.17	-0.0695648
2131.1	-2.04772
2136.03	-0.00140381
2140.96	2.26653
2145.89	2.59245
2150.81	2.8704
2155.73	3.80908
2160.64	4.60526
2165.55	6.17001
2170.46	-0.206764
2175.36	-2.01584
2180.26	0.219933
2185.16	3.35391
2190.05	5.16496
2194.94	3.95248
2199.83	1.64891
2204.71	0.351524
2209.59	-0.188034
2214.46	0.230042
2219.33	1.46014
2224.2	3.6122
2229.07	4.65445
2233.93	2.54343
2238.79	5.91603
2243.64	6.03564
2248.49	5.13131
2253.34	4.45377
2258.18	6.79904
2263.02	7.39212
2267.86	6.43253
2272.69	6.78899
2277.52	3.26839
2282.35	4.53626
2287.17	6.51835
2291.99	4.27023
2296.8	2.45662
2301.62	2.88745
2306.43	5.02923
2311.23	6.57047
2316.03	7.88498
2320.83	5.91822
2325.63	5.87279
2330.42	5.97081
2335.21	6.45412
2339.99	4.01987
2344.77	3.81789
2349.55	5.39337
2354.32	5.28784
2359.1	3.29696
2363.86	3.32928
2368.63	6.51255
2373.39	5.92054
2378.15	5.52194
2382.9	5.91605
2387.65	3.88858
2392.4	1.79583
2397.14	3.37583
2401.88	4.54377
2406.62	4.54896
2411.35	4.52356
2416.08	3.65138
2420.81	3.56481
2425.53	3.00256
2430.25	3.95204
2434.97	6.13924
2439.69	1.61323
2444.4	4.52151
2449.1	4.92254
2453.81	5.1842
2458.51	4.51486
2463.2	2.86061
2467.9	2.585
2472.59	2.80186
2477.27	1.8019
2481.96	2.63514
2486.64	3.95649
2491.31	5.29305
2495.99	4.70722
2500.66	0.616119
2505.32	1.70892
2509.99	3.74283
2514.65	5.21185
2519.31	4.35925
2523.96	-0.463799
2528.61	-1.73616
2533.26	4.1986
2537.9	4.82744
2542.54	4.39188
2547.18	4.29379
2551.81	4.14038
2556.44	3.51278
2561.07	1.31026
2565.69	3.06202
2570.32	3.06078
2574.93	4.13735
2579.55	4.78738
2584.16	4.8582
2588.77	4.2822
2593.37	4.77883
2597.97	6.12476
2602.57	6.4776
2607.17	5.73642
2611.76	4.05564
2616.35	4.37965
2620.93	5.02369
2625.51	3.98796
2630.09	2.31611
2634.67	1.76421
2639.24	2.89287
2643.81	4.07143
2648.38	5.53321
2652.94	3.08308
2657.5	3.44933
2662.06	3.87421
2666.61	2.33834
2671.16	1.78415
2675.71	2.08055
2680.25	3.0076
2684.79	4.71595
2689.33	4.56749
2693.86	3.54236
2698.39	3.47184
2702.92	4.94964
2707.45	3.85342
2711.97	4.29849
2716.49	4.66321
2721	5.06816
2725.51	3.99285
2730.02	2.5368
2734.53	0.848572
2739.03	2.70881
2743.53	4.6244
2748.03	5.77431
2752.52	5.1759
2757.01	4.1243
2761.5	4.86345
2765.98	6.02972
2770.46	3.95425
2774.94	3.26532
2779.42	2.54524
2783.89	1.84699
2788.36	1.72418
2792.82	2.34372
2797.28	3.09668
2801.74	3.93798
2806.2	4.66248
2810.65	1.19622
2815.1	1.89743
2819.55	4.00805
2823.99	4.83568
2828.43	5.83274
2832.87	3.65085
2837.3	2.62243
2841.74	3.10517
2846.17	2.85195
2850.59	1.8998
2855.01	3.8599
2859.43	2.0225
2863.85	-2.42971
2868.26	0.234756
2872.67	3.08369
2877.08	1.96609
2881.48	1.64827
2885.89	3.34266
2890.28	2.41141
2894.68	1.5538
2899.07	2.1789
2903.46	2.40773
2907.85	1.54724
2912.23	1.21957
2916.61	-0.318298
2920.98	-1.829
2925.36	1.67208
2929.73	0.911453
2934.1	0.769569
2938.46	2.50459
2942.82	1.9238
2947.18	2.79856
2951.54	3.66661
2955.89	3.43068
2960.24	3.83125
2964.59	3.60204
2968.93	3.72146
2973.27	4.31486
2977.61	2.42601
2981.95	0.521873
2986.28	0.799061
2990.61	0.384125
2994.94	0.374065
2999.26	0.69738
3003.58	1.48917
3007.9	2.46471
3012.21	2.89571
3016.52	1.42125
3020.83	2.38266
3025.14	2.76368
3029.44	1.98792
3033.74	1.16435
3038.04	2.50238
3042.33	2.43393
3046.62	2.4272
3050.91	2.67828
3055.2	2.60714
3059.48	1.76395
3063.76	2.99198
3068.03	3.74885
3072.31	3.81627
3076.58	4.91956
3080.85	4.52277
3085.11	3.45711
3089.37	4.98573
3093.63	5.40018
3097.89	5.14719
3102.14	2.70992
3106.39	-3.10123
3110.64	5.08706
3114.89	7.03846
3119.13	6.46666
3123.37	4.01077
3127.6	2.13796
3131.84	3.31107
3136.07	5.95057
3140.29	7.27264
3144.52	7.51595
3148.74	6.54228
3152.96	5.25518
3157.18	5.01879
3161.39	3.94003
3165.6	4.19261
3169.81	5.65355
3174.01	6.70942
3178.22	7.10561
3182.42	7.62038
3186.61	7.9036
3190.8	9.1385
3195	10.993
3199.18	9.45315
3203.37	8.46016
3207.55	7.53035
3211.73	6.58672
3215.91	7.74397
3220.08	9.55126
3224.25	10.4202
3228.42	9.41329
3232.59	9.9933
3236.75	7.76686
3240.91	5.18098
3245.07	4.29335
3249.22	6.88848
3253.37	7.46765
3257.52	6.55851
3261.67	6.64861
3265.81	6.68432
3269.95	5.45435
3274.09	3.34339
3278.22	1.42736
3282.36	2.88838
3286.49	3.78652
3290.61	4.50742
3294.74	5.06518
3298.86	4.01653
3302.98	2.4868
3307.09	-0.00373459
3311.21	2.48227
3315.32	4.00305
3319.42	3.43079
3323.53	2.72023
3327.63	2.44731
3331.73	2.20671
3335.83	3.34262
3339.92	3.99032
3344.01	3.50054
3348.1	2.62503
3352.19	2.92512
3356.27	2.83701
3360.35	2.56023
3364.43	5.2649
3368.5	5.61104
3372.58	5.6956
3376.65	5.18788
3380.71	6.11343
3384.78	5.97066
3388.84	5.19807
3392.9	5.41431
3396.95	4.95703
3401.01	4.26327
3405.06	6.66799
3409.1	7.43356
3413.15	5.9999
3417.19	3.8374
3421.23	2.6791
3425.27	8.49131
3429.31	7.91393
3433.34	6.65423
3437.37	5.53061
3441.39	4.38434
3445.42	4.71896
3449.44	4.53913
3453.46	4.12748
3457.47	4.19352
3461.49	3.47996
3465.5	2.47961
3469.51	1.62387
3473.51	2.18079
3477.52	2.94637
3481.52	4.08966
3485.51	4.22644
3489.51	4.52681
3493.5	5.69247
3497.49	6.1254
3501.48	5.28015
3505.46	2.06482
3509.45	0.825336
3513.43	2.46864
3517.4	5.65864
3521.38	4.42904
3525.35	4.29352
3529.32	3.71151
3533.28	3.23184
3537.25	0.149342
3541.21	-0.266716
3545.17	1.89391
3549.12	4.99623
3553.08	4.8629
3557.03	2.40583
3560.98	2.4236
3564.92	3.26084
3568.87	6.38725
3572.81	5.70536
3576.74	9.51933
3580.68	14.7275
3584.61	16.7028
3588.54	11.9556
3592.47	16.3839
3596.4	16.0472
3600.32	16.3223
3604.24	12.2772
3608.16	6.78047
3612.07	5.27546
3615.98	4.95733
3619.89	4.06305
3623.8	1.99246
3627.71	0.326099
3631.61	0.385605
3635.51	2.40207
3639.41	4.0985
3643.3	3.21952
3647.19	0.090992
3651.08	0.0646172
3654.97	0.234753
3658.85	0.169605
3662.74	-0.924648
3666.62	0.113598
3670.49	1.64854
3674.37	2.14611
3678.24	1.57689
3682.11	1.6165
3685.98	1.78265
3689.84	2.58192
3693.7	3.703
3697.56	3.72232
3701.42	1.84412
3705.28	1.2185
3709.13	1.37188
3712.98	2.58353
3716.82	2.98292
3720.67	1.56554
3724.51	0.681591
3728.35	1.30991
3732.19	1.55561
3736.02	2.54792
3739.86	3.90846
3743.69	3.7786
3747.51	2.68993
3751.34	2.28589
3755.16	2.49036
3758.98	2.48817
3762.8	2.66333
3766.61	2.01728
3770.43	1.85812
3774.24	2.61685
3778.05	4.28946
3781.85	5.15676
3785.65	3.42449
3789.45	4.43643
3793.25	3.80828
3797.05	3.30124
3800.84	3.14994
3804.63	2.84127
3808.42	0.761734
3812.21	0.812767
3815.99	3.22507
3819.77	3.4532
3823.55	4.47299
3827.33	4.18888
3831.1	3.51958
3834.87	3.6825
3838.64	4.33646
3842.41	4.58216
3846.17	3.45747
3849.93	3.16589
3853.69	3.57774
3857.45	2.9221
3861.21	3.64973
3864.96	3.35659
3868.71	1.89661
3872.46	0.999416
3876.2	2.78966
3879.94	3.52126
3883.68	3.5439
3887.42	3.29798
3891.16	4.64138
3894.89	5.0819
3898.62	3.84829
3902.35	2.91858
3906.08	0.354279
3909.8	0.429932
3913.52	1.38513
3917.24	1.36031
3920.96	0.956627
3924.67	-0.239609
3928.38	-0.328686
3932.09	0.603683
3935.8	2.26231
3939.51	2.64219
3943.21	2.13158
3946.91	1.5764
3950.61	1.48676
3954.3	2.1796
3958	1.70979
3961.69	0.505131
3965.38	1.10638
3969.06	2.25616
3972.75	1.90052
3976.43	0.786636
3980.11	0.930622
3983.78	1.28167
3987.46	1.26438
3991.13	1.45527
3994.8	0.972233
3998.47	-0.856571