File: Data/3-Raman/processed/bu20-C-brt1-FI01-151-633-v.txt
#Acq. time (s)=	20
#Accumulations=	3
#Range (cm-¹)=	100...4000
#Windows=	1
#Auto scanning=	Off
#Autofocus=	Off
#Macrospot=	Off
#AutoExposure=	Off
#Spike filter=	Multiple accum.
#Delay time (s)=	0
#Binning=	1
#Readout mode=	Signal
#DeNoise=	Lite
#ICS correction=	Off
#Dark correction=	Off
#Inst. Process=	Off
#Detector temperature (°C)=	-60.09
#Instrument=	LabRAM HR Evol
#Detector=	SIN-EM FIVIS
#Objective=	x50_VIS_LWD
#Grating=	150 (500nm)
#ND Filter=	100%
#Laser=	633nm_Edge
#Hole=	30.0125
#Temperature=	0
#Range=	Visible
#StageXY=	75x50mm Scan+
#StageZ=	Z motor
#X (µm)=	7344.4
#Y (µm)=	4274
#Z (µm)=	-22.8
#Full time(mm:ss)=	1:02
#Project=	Buranga
#Sample=	BU18FA20_C
#Site=	C_Bertoss1
#Title=	20-C_brt1_FI01
#Remark=
#Date=	30.07.2019 14:26
#Acquired=	30.07.2019 14:26:11
#Data Range:Extract=	16.12.2021 15:36:30
#Base:Fit=	16.12.2021 15:36:40
#Base:Sub=	16.12.2021 15:37:26
100.38	746.262
106.898	528.568
113.411	377.426
119.918	268.866
126.419	193.186
132.916	144.666
139.407	105.374
145.892	78.4113
152.372	59.0637
158.847	35.1958
165.316	21.4125
171.781	19.9916
178.239	10.761
184.693	2.35724
191.139	-0.668518
197.582	-0.32605
204.02	-0.027359
210.452	-1.53984
216.877	-2.19246
223.299	6.10352e-005
229.715	5.42458
236.126	20.4189
242.53	46.7393
248.931	40.3
255.326	28.7177
261.714	25.5664
268.099	31.5628
274.477	40.4699
280.851	50.9372
287.218	70.0022
293.582	76.5027
299.939	51.5521
306.293	31.9254
312.639	25.3412
318.982	33.0285
325.318	57.4577
331.651	87.7341
337.977	79.1069
344.297	58.156
350.614	44.2903
356.925	42.498
363.23	47.325
369.53	51.8974
375.827	52.0362
382.116	42.4153
388.401	32.5348
394.681	33.4381
400.956	35.0916
407.226	36.174
413.49	32.9978
419.749	29.3499
426.003	37.806
432.252	51.0007
438.496	66.9851
444.735	77.3327
450.969	76.9344
457.197	72.0253
463.421	64.3322
469.64	54.4225
475.853	42.7428
482.062	33.1676
488.265	29.5676
494.464	27.1295
500.657	26.273
506.844	28.3742
513.028	30.2189
519.206	28.6429
525.38	26.1511
531.548	25.3916
537.71	29.5785
543.869	30.7485
550.022	26.7563
556.169	18.3563
562.313	20.7695
568.452	25.9709
574.584	24.2512
580.713	22.3511
586.837	24.3111
592.954	33.8348
599.068	52.8142
605.176	70.2379
611.28	67.7245
617.378	55.8939
623.473	47.7734
629.561	44.946
635.644	44.2399
641.724	44.3689
647.797	45.201
653.867	49.1643
659.931	55.7978
665.99	59.6355
672.044	49.0249
678.095	34.9092
684.139	27.5258
690.179	19.2705
696.213	11.0956
702.245	6.79773
708.27	5.14908
714.29	5.26668
720.306	4.26651
726.316	2.35878
732.322	-0.0326233
738.323	0.377228
744.32	2.21687
750.311	2.65453
756.298	4.4982
762.28	6.75954
768.258	5.8188
774.23	1.7291
780.198	-2.7314
786.161	-2.35445
792.119	-1.27795
798.073	-0.190735
804.021	3.24475
809.965	5.39894
815.904	2.28142
821.839	-2.26401
827.769	-2.6624
833.693	3.49861
839.614	8.9554
845.53	8.35309
851.44	4.73622
857.346	1.5446
863.248	-0.389175
869.144	-0.773209
875.037	-4.36226
880.924	-2.49171
886.807	1.38551
892.685	2.98299
898.559	1.85394
904.427	0.0284424
910.292	-0.587753
916.151	0.250839
922.006	3.8613
927.856	5.99944
933.701	5.26021
939.543	9.67334
945.379	13.137
951.21	21.1883
957.037	29.1839
962.861	35.9348
968.678	42.6346
974.491	56.3964
980.3	75.2166
986.104	106.664
991.904	141.223
997.699	146.443
1003.49	121.017
1009.28	95.0199
1015.06	76.1174
1020.83	89.5633
1026.61	113.45
1032.37	108.111
1038.14	77.1076
1043.9	48.0123
1049.65	35.9269
1055.4	30.1164
1061.15	24.0635
1066.88	21.1931
1072.62	21.2538
1078.35	25.2506
1084.08	31.8834
1089.8	37.439
1095.52	42.7119
1101.23	46.3588
1106.94	47.0742
1112.65	33.2806
1118.35	24.1653
1124.05	15.5041
1129.74	12.1382
1135.42	14.4595
1141.11	19.2076
1146.78	22.6892
1152.46	28.7239
1158.13	34.6483
1163.79	30.5863
1169.45	17.8358
1175.11	7.93719
1180.76	8.35655
1186.41	10.2035
1192.05	10.1797
1197.69	8.51199
1203.32	10.4047
1208.95	6.85713
1214.58	2.40097
1220.2	6.37456
1225.82	1.54372
1231.43	0.229004
1237.04	6.61977
1242.64	13.2342
1248.24	18.5945
1253.83	23.6553
1259.42	33.1688
1265.01	51.9346
1270.59	26.846
1276.17	42.419
1281.74	374.163
1287.31	278.87
1292.88	51.0293
1298.44	20.1475
1303.99	27.5878
1309.55	26.02
1315.09	26.801
1320.64	24.7917
1326.18	21.3665
1331.71	21.0736
1337.24	21.5243
1342.77	19.0364
1348.29	14.5676
1353.81	12.5403
1359.32	15.925
1364.83	25.6482
1370.33	41.4912
1375.84	45.2715
1381.33	64.5665
1386.82	972.771
1392.31	198.38
1397.8	52.9837
1403.28	37.5812
1408.75	90.6297
1414.22	46.9419
1419.69	22.152
1425.15	18.8696
1430.61	21.0636
1436.07	16.6525
1441.52	15.1553
1446.96	12.381
1452.41	10.6503
1457.84	9.81433
1463.28	7.98592
1468.71	6.9001
1474.13	7.25487
1479.55	7.68103
1484.97	10.465
1490.39	10.966
1495.79	7.63919
1501.2	4.18497
1506.6	3.16292
1512	3.78371
1517.39	0.957855
1522.78	0.738403
1528.16	1.9856
1533.54	4.18205
1538.92	6.03014
1544.29	13.7786
1549.66	14.0268
1555.02	7.88914
1560.38	3.36281
1565.74	3.64003
1571.09	4.58464
1576.44	6.99615
1581.78	10.7164
1587.12	8.30522
1592.46	9.58797
1597.79	10.3719
1603.12	10.2642
1608.44	9.90128
1613.76	10.2273
1619.08	11.1437
1624.39	12.4044
1629.7	12.1197
1635	9.20708
1640.3	5.77133
1645.59	3.33664
1650.88	2.51328
1656.17	4.8159
1661.46	7.15065
1666.74	6.8627
1672.01	4.40498
1677.28	2.2812
1682.55	2.25729
1687.82	6.16904
1693.07	6.69312
1698.33	6.74539
1703.58	8.07759
1708.83	8.66518
1714.07	7.18106
1719.31	5.62541
1724.55	0.926254
1729.78	2.47948
1735.01	4.97377
1740.23	8.18951
1745.46	8.13496
1750.67	6.75499
1755.89	4.48189
1761.09	1.58333
1766.3	-0.240707
1771.5	0.183365
1776.7	6.10425
1781.89	11.2259
1787.08	7.50932
1792.27	3.65311
1797.45	2.02599
1802.62	5.39302
1807.8	9.71317
1812.97	7.71625
1818.14	5.40323
1823.3	3.1088
1828.46	1.48947
1833.61	2.79613
1838.76	6.21025
1843.91	9.24194
1849.05	6.46176
1854.19	3.74309
1859.33	0.955673
1864.46	2.26952
1869.59	1.69725
1874.71	2.16933
1879.83	3.74364
1884.95	7.84084
1890.06	8.7217
1895.17	9.23133
1900.27	8.84169
1905.38	5.68164
1910.47	3.77447
1915.57	5.34248
1920.66	5.61882
1925.74	3.75288
1930.83	0.970169
1935.91	-1.05768
1940.98	1.68473
1946.05	5.7066
1951.12	6.89751
1956.18	6.53777
1961.25	6.28518
1966.3	6.82467
1971.35	9.00256
1976.4	11.698
1981.45	12.6286
1986.49	12.0522
1991.53	9.51005
1996.56	12.5099
2001.59	12.7214
2006.62	9.66949
2011.64	4.57115
2016.66	0.290634
2021.68	1.22828
2026.69	4.91668
2031.7	6.62399
2036.7	6.24931
2041.7	6.33318
2046.7	7.05083
2051.7	5.61018
2056.69	8.86314
2061.67	7.8586
2066.65	6.94273
2071.63	7.37677
2076.61	8.38316
2081.58	8.43848
2086.55	8.6673
2091.51	7.5157
2096.47	4.55966
2101.43	2.84045
2106.39	0.342094
2111.34	6.46054
2116.28	8.58945
2121.23	6.67599
2126.17	5.16158
2131.1	5.00147
2136.03	4.31802
2140.96	1.74794
2145.89	-0.424225
2150.81	1.78648
2155.73	6.60587
2160.64	7.45624
2165.55	6.12505
2170.46	3.76818
2175.36	1.69424
2180.26	3.0169
2185.16	8.33649
2190.05	8.96657
2194.94	8.18854
2199.83	6.8561
2204.71	6.33876
2209.59	6.42177
2214.46	6.92223
2219.33	5.89767
2224.2	11.004
2229.07	11.0397
2233.93	8.3214
2238.79	6.28312
2243.64	5.64075
2248.49	5.39303
2253.34	6.10173
2258.18	8.26861
2263.02	9.51756
2267.86	8.7433
2272.69	6.99088
2277.52	5.03954
2282.35	6.07343
2287.17	7.84322
2291.99	8.67503
2296.8	8.5116
2301.62	7.70796
2306.43	7.27132
2311.23	7.48337
2316.03	8.78883
2320.83	12.0037
2325.63	17.0256
2330.42	18.5425
2335.21	13.1428
2339.99	9.00826
2344.77	5.39763
2349.55	7.75838
2354.32	9.81702
2359.1	7.528
2363.86	5.41797
2368.63	8.07252
2373.39	9.36018
2378.15	8.43201
2382.9	5.46441
2387.65	4.81757
2392.4	6.20046
2397.14	7.03845
2401.88	6.3979
2406.62	5.52853
2411.35	6.70979
2416.08	7.06761
2420.81	4.35293
2425.53	2.3787
2430.25	3.48112
2434.97	7.3242
2439.69	9.59885
2444.4	7.9088
2449.1	8.16504
2453.81	7.77747
2458.51	8.83256
2463.2	8.53741
2467.9	7.60683
2472.59	8.06741
2477.27	8.66397
2481.96	8.50798
2486.64	6.87698
2491.31	6.48454
2495.99	5.27325
2500.66	5.21588
2505.32	6.35678
2509.99	6.72668
2514.65	7.03762
2519.31	6.66679
2523.96	6.51274
2528.61	5.12972
2533.26	6.78252
2537.9	10.8889
2542.54	11.6398
2547.18	9.88115
2551.81	9.02134
2556.44	9.27892
2561.07	7.79137
2565.69	5.61677
2570.32	4.60796
2574.93	4.26672
2579.55	9.18321
2584.16	10.1803
2588.77	6.4912
2593.37	8.31686
2597.97	9.31074
2602.57	9.46763
2607.17	7.96137
2611.76	6.27663
2616.35	7.6765
2620.93	10.5076
2625.51	12.7621
2630.09	9.1983
2634.67	6.80331
2639.24	7.88779
2643.81	9.19822
2648.38	8.26706
2652.94	9.45474
2657.5	12.5594
2662.06	11.6021
2666.61	12.4925
2671.16	12.1121
2675.71	5.82396
2680.25	10.2861
2684.79	9.49588
2689.33	8.34296
2693.86	8.4791
2698.39	8.37841
2702.92	7.54681
2707.45	7.35738
2711.97	8.7915
2716.49	6.16037
2721	3.81612
2725.51	4.41523
2730.02	5.69533
2734.53	5.578
2739.03	4.3409
2743.53	4.86205
2748.03	6.84402
2752.52	7.38795
2757.01	6.29765
2761.5	8.46636
2765.98	6.38091
2770.46	5.40037
2774.94	7.36422
2779.42	4.36494
2783.89	2.46938
2788.36	5.68848
2792.82	7.75044
2797.28	7.56679
2801.74	5.10435
2806.2	0.950493
2810.65	2.85824
2815.1	5.69978
2819.55	7.97762
2823.99	7.93793
2828.43	5.88354
2832.87	3.87023
2837.3	4.57358
2841.74	5.65252
2846.17	6.45054
2850.59	6.33206
2855.01	4.81592
2859.43	4.51157
2863.85	3.38896
2868.26	1.83788
2872.67	6.92878
2877.08	7.18436
2881.48	5.24072
2885.89	2.75521
2890.28	0.299545
2894.68	0.122704
2899.07	3.05246
2903.46	4.8099
2907.85	6.21535
2912.23	4.72601
2916.61	4.93196
2920.98	5.39503
2925.36	4.69334
2929.73	5.12158
2934.1	6.70432
2938.46	5.90913
2942.82	5.95845
2947.18	5.78793
2951.54	3.07544
2955.89	-1.0881
2960.24	1.5248
2964.59	4.17568
2968.93	6.72543
2973.27	7.52063
2977.61	7.95017
2981.95	6.19032
2986.28	4.09723
2990.61	2.04514
2994.94	2.44276
2999.26	2.77509
3003.58	3.8671
3007.9	0.916359
3012.21	2.65279
3016.52	0.842468
3020.83	0.847549
3025.14	1.64224
3029.44	3.51394
3033.74	5.37168
3038.04	3.1321
3042.33	0.816559
3046.62	0.476509
3050.91	3.67374
3055.2	2.00631
3059.48	2.93778
3063.76	3.9987
3068.03	4.21754
3072.31	2.59369
3076.58	3.42015
3080.85	4.50146
3085.11	3.72885
3089.37	3.35889
3093.63	4.37549
3097.89	5.20335
3102.14	5.24119
3106.39	3.9798
3110.64	4.25882
3114.89	4.62311
3119.13	4.78786
3123.37	4.47015
3127.6	5.269
3131.84	5.53127
3136.07	2.86657
3140.29	1.62753
3144.52	-0.107368
3148.74	3.03041
3152.96	8.30367
3157.18	8.54417
3161.39	5.28047
3165.6	3.46442
3169.81	3.05994
3174.01	3.0101
3178.22	3.27686
3182.42	5.18467
3186.61	4.94083
3190.8	2.90812
3195	3.01441
3199.18	6.34205
3203.37	5.50841
3207.55	4.98711
3211.73	5.21023
3215.91	4.75481
3220.08	5.33949
3224.25	3.28098
3228.42	3.58784
3232.59	10.0056
3236.75	11.1275
3240.91	7.63842
3245.07	2.9913
3249.22	6.4917
3253.37	7.76975
3257.52	6.06158
3261.67	4.56469
3265.81	2.77367
3269.95	2.24355
3274.09	1.96035
3278.22	2.52874
3282.36	2.2402
3286.49	5.47196
3290.61	3.41293
3294.74	3.23199
3298.86	4.89278
3302.98	5.35686
3307.09	4.23923
3311.21	1.89091
3315.32	2.14318
3319.42	3.45219
3323.53	5.39635
3327.63	6.2423
3331.73	3.70951
3335.83	3.48901
3339.92	4.79904
3344.01	5.38793
3348.1	7.77354
3352.19	7.78394
3356.27	6.67764
3360.35	6.77072
3364.43	6.71953
3368.5	6.07739
3372.58	4.44875
3376.65	2.64948
3380.71	5.13248
3384.78	8.97801
3388.84	8.52812
3392.9	6.82057
3396.95	7.9303
3401.01	8.94804
3405.06	7.77483
3409.1	7.82776
3413.15	8.9826
3417.19	11.1659
3421.23	11.2743
3425.27	10.138
3429.31	9.11172
3433.34	8.59419
3437.37	8.62497
3441.39	10.229
3445.42	8.99416
3449.44	9.00941
3453.46	10.3111
3457.47	4.89217
3461.49	2.18478
3465.5	9.90336
3469.51	9.41975
3473.51	7.64166
3477.52	8.5192
3481.52	11.3318
3485.51	11.8834
3489.51	5.28083
3493.5	7.6735
3497.49	6.95396
3501.48	9.42231
3505.46	10.5615
3509.45	10.5131
3513.43	6.60092
3517.4	7.66377
3521.38	11.7071
3525.35	8.6004
3529.32	7.7209
3533.28	5.63479
3537.25	6.31228
3541.21	8.99082
3545.17	10.5557
3549.12	9.55725
3553.08	8.88775
3557.03	9.00357
3560.98	8.62915
3564.92	8.74087
3568.87	8.41502
3572.81	11.1964
3576.74	14.4487
3580.68	16.6677
3584.61	18.6217
3588.54	18.0635
3592.47	17.0519
3596.4	14.3992
3600.32	10.1714
3604.24	7.69134
3608.16	5.40853
3612.07	5.96262
3615.98	9.08276
3619.89	7.81248
3623.8	7.82151
3627.71	8.51574
3631.61	10.1716
3635.51	7.95995
3639.41	7.8276
3643.3	8.28034
3647.19	7.23737
3651.08	6.78289
3654.97	7.18534
3658.85	6.85826
3662.74	4.85928
3666.62	4.2571
3670.49	5.58739
3674.37	9.0715
3678.24	9.73624
3682.11	9.11781
3685.98	7.49409
3689.84	7.06055
3693.7	6.84161
3697.56	6.45325
3701.42	7.30033
3705.28	8.94596
3709.13	8.11314
3712.98	5.55682
3716.82	5.86154
3720.67	5.14925
3724.51	4.54822
3728.35	6.75405
3732.19	5.91249
3736.02	5.98911
3739.86	7.15777
3743.69	7.63417
3747.51	7.14617
3751.34	7.19689
3755.16	7.41344
3758.98	6.79943
3762.8	4.42148
3766.61	2.06415
3770.43	7.94544
3774.24	6.64032
3778.05	5.60138
3781.85	7.03143
3785.65	3.41994
3789.45	3.83471
3793.25	3.99714
3797.05	6.0434
3800.84	7.12342
3804.63	5.79065
3808.42	4.09009
3812.21	4.28106
3815.99	4.82509
3819.77	5.98112
3823.55	4.86625
3827.33	3.98725
3831.1	4.12812
3834.87	5.43875
3838.64	5.08562
3842.41	4.55706
3846.17	2.00142
3849.93	0.919594
3853.69	1.32804
3857.45	3.21357
3861.21	4.82088
3864.96	3.78568
3868.71	2.88693
3872.46	2.12355
3876.2	0.663967
3879.94	1.44936
3883.68	2.27913
3887.42	0.866749
3891.16	-0.445522
3894.89	-0.207241
3898.62	1.14539
3902.35	1.72968
3906.08	2.64288
3909.8	3.05815
3913.52	2.93208
3917.24	2.38383
3920.96	0.314678
3924.67	1.67415
3928.38	3.05982
3932.09	2.57078
3935.8	1.89473
3939.51	1.21313
3943.21	0.306915
3946.91	-0.611599
3950.61	-0.527756
3954.3	0.138432
3958	0.505264
3961.69	0.0863876
3965.38	0.981579
3969.06	2.46286
3972.75	1.71012
3976.43	0.814419
3980.11	0.322544
3983.78	0.0234261
3987.46	-0.0168877
3991.13	0.343441
3994.8	1.71635
3998.47	9.45772