File: Data/3-Raman/processed/bu20-E-FF1-FI01-v.txt
#Acq. time (s)=	15
#Accumulations=	3
#Range (cm-¹)=	100...4000
#Windows=	1
#Auto scanning=	Off
#Autofocus=	Off
#Macrospot=	Off
#AutoExposure=	Off
#Spike filter=	Multiple accum.
#Delay time (s)=	0
#Binning=	1
#Readout mode=	Signal
#DeNoise=	Lite
#ICS correction=	Off
#Dark correction=	Off
#Inst. Process=	Off
#Detector temperature (°C)=	-60.09
#Instrument=	LabRAM HR Evol
#Detector=	SIN-EM FIVIS
#Objective=	x100_VIS
#Grating=	150 (500nm)
#ND Filter=	100%
#Laser=	532nm_Edge
#Hole=	30.0125
#Temperature=	0
#Range=	Visible
#StageXY=	75x50mm Scan+
#StageZ=	Z motor
#X (µm)=	-4553.8
#Y (µm)=	729.6
#Z (µm)=	-19.2
#Full time(s)=	47
#Project=	Buranga
#Sample=	BU18FA20_E
#Site=	E_FF1
#Title=	20-E_FF1_FI01
#Remark=
#Date=	19.06.2019 19:49
#Acquired=	19.06.2019 19:49:32
#Data Range:Extract=	16.12.2021 15:36:30
#Base:Fit=	16.12.2021 15:36:40
#Base:Sub=	16.12.2021 15:42:07
103.617	2741.61
108.24	2347.06
112.86	1895.33
117.476	1581.3
122.092	1310.24
126.706	1082.1
131.317	887.975
135.927	733.124
140.531	607.828
145.136	521.699
149.738	481.645
154.338	504.538
158.934	652.408
163.53	772.694
168.123	497.585
172.714	235.998
177.301	157.416
181.887	214.048
186.471	422.165
191.051	617.943
195.631	414.3
200.208	245.178
204.783	121.726
209.354	38.6689
213.925	-0.693451
218.493	0.7229
223.058	42.5933
227.622	121.311
232.183	247.143
236.741	400.936
241.298	571.09
245.853	787.01
250.404	819.247
254.954	476.259
259.502	244.848
264.046	159.158
268.59	214.36
273.132	630.986
277.669	1376.13
282.206	1802.36
286.741	1223.43
291.272	658.98
295.802	434.939
300.331	287.773
304.855	244.86
309.379	163.27
313.898	224.275
318.417	326.478
322.935	433.714
327.448	535.737
331.96	615.013
336.469	678.53
340.977	699.886
345.481	738.058
349.985	747.837
354.487	739.499
358.985	655.979
363.482	533.498
367.975	429.063
372.468	347.734
376.957	284.869
381.446	257.181
385.93	242.404
390.414	239.435
394.894	241.478
399.374	238.056
403.85	187.242
408.326	118.899
412.797	162.098
417.268	244.565
421.735	174.359
426.202	76.8114
430.664	23.7099
435.127	-0.0445099
439.585	1.97992
444.043	19.082
448.497	38.552
452.951	58.7617
457.401	66.292
461.85	63.4256
466.296	59.0037
470.741	60.6843
475.182	72.3251
479.621	96.0499
484.059	132.382
488.494	195.996
492.928	274.278
497.359	339.849
501.789	329.994
506.215	261.742
510.639	193.777
515.062	135.418
519.482	90.5816
523.901	57.1447
528.316	41.4639
532.73	33.9397
537.143	33.5363
541.552	36.3317
545.958	41.003
550.365	48.7368
554.767	56.3789
559.17	65.3108
563.568	70.2677
567.964	69.0767
572.36	64.6838
576.752	69.9004
581.142	135.957
585.531	335.948
589.917	406.188
594.3	381.126
598.682	346.136
603.063	309.264
607.44	271.468
611.815	238.56
616.19	208.795
620.561	165.231
624.929	124.621
629.298	89.216
633.662	83.7866
638.025	100.159
642.385	121.307
646.745	133.7
651.101	152.606
655.455	195.256
659.807	277.831
664.159	398.207
668.507	499.614
672.852	546.625
677.196	543.967
681.54	486.527
685.879	372.33
690.216	208.255
694.552	107.027
698.885	54.54
703.218	32.4686
707.547	21.3238
711.874	14.3203
716.199	10.9627
720.521	9.703
724.842	10.0662
729.163	10.7758
733.48	11.6233
737.794	14.2651
742.107	19.222
746.417	29.1513
750.725	43.5314
755.034	64.5575
759.338	91.6285
763.64	138.531
767.94	238.486
772.238	381.174
776.535	584.044
780.829	775.776
785.12	591.708
789.412	408.425
793.7	268.462
797.986	158.565
802.27	98.3326
806.552	70.124
810.831	54.1439
815.109	45.4245
819.385	39.1806
823.658	34.5176
827.93	28.9082
832.199	23.8011
836.467	19.0452
840.732	14.0646
844.996	9.17262
849.257	3.90559
853.519	1.09825
857.776	0.138641
862.031	-0.254318
866.285	-0.321167
870.536	-0.0574341
874.786	0.543793
879.033	1.63805
883.278	2.4696
887.521	3.47351
891.763	4.76443
896.002	6.70372
900.239	7.55379
904.474	8.87717
908.706	11.1454
912.937	13.9404
917.166	18.6341
921.393	22.9594
925.619	30.7804
929.842	42.9673
934.063	64.2531
938.282	94.442
942.5	140.096
946.715	206.773
950.928	259.139
955.14	248.324
959.349	192.505
963.556	151.29
967.762	124.354
971.963	103.981
976.164	87.4222
980.364	74.1849
984.561	64.1731
988.757	55.7164
992.95	51.8144
997.141	47.7857
1001.33	40.1491
1005.52	35.3323
1009.7	34.1042
1013.89	37.2707
1018.07	44.5013
1022.25	58.6048
1026.42	77.2336
1030.6	95.8626
1034.77	119.853
1038.94	163.033
1043.11	265.257
1047.28	474.569
1051.45	774.297
1055.61	971.226
1059.77	791.752
1063.93	511.378
1068.09	352.42
1072.24	284.278
1076.4	307.699
1080.55	406.942
1084.7	632.544
1088.85	824.521
1092.99	847.74
1097.14	856.21
1101.28	864.814
1105.42	868.117
1109.56	871.575
1113.7	872.782
1117.83	863.589
1121.96	847.067
1126.09	829.531
1130.22	823.069
1134.35	853.566
1138.47	790.644
1142.59	637.828
1146.72	522.689
1150.83	474.566
1154.95	548.318
1159.07	646.362
1163.18	637.242
1167.29	518.904
1171.4	414.001
1175.51	316.464
1179.61	233.423
1183.72	152.98
1187.82	126.084
1191.92	108.275
1196.01	106.188
1200.11	109.047
1204.2	118.562
1208.29	115.898
1212.38	130.489
1216.47	157.746
1220.56	227.494
1224.64	297.804
1228.72	284.735
1232.81	250
1236.89	248.183
1240.96	285.447
1245.04	343.076
1249.11	428.951
1253.18	544.552
1257.25	502.772
1261.32	390.968
1265.38	487.162
1269.44	1587.36
1273.51	3805.55
1277.56	3439.74
1281.62	884.924
1285.68	339.588
1289.73	265.937
1293.78	225.871
1297.83	198.53
1301.88	181.212
1305.93	169.567
1309.97	162.988
1314.02	160.871
1318.06	161.285
1322.1	162.992
1326.13	165.272
1330.17	167.114
1334.2	166.927
1338.23	169.137
1342.26	175.461
1346.29	190.223
1350.31	211.429
1354.34	259.184
1358.36	328.278
1362.38	401.122
1366.4	403.77
1370.42	775.603
1374.43	3185.75
1378.44	7223.89
1382.45	4916.03
1386.46	978.169
1390.47	443.305
1394.47	482.439
1398.48	641.571
1402.48	650.7
1406.48	324.828
1410.48	172.486
1414.47	140.896
1418.47	120.383
1422.46	99.5277
1426.45	78.8212
1430.44	63.7393
1434.43	52.2136
1438.41	42.7292
1442.39	35.4116
1446.37	30.1248
1450.35	27.2726
1454.33	26.1402
1458.31	25.434
1462.28	23.1215
1466.25	19.4324
1470.22	16.0134
1474.19	13.2937
1478.16	11.3288
1482.12	9.86755
1486.08	8.85008
1490.05	9.01221
1494.01	9.45432
1497.96	9.96129
1501.92	10.5363
1505.87	11.2794
1509.83	10.5317
1513.78	10.3067
1517.72	10.1625
1521.67	9.79613
1525.62	8.97684
1529.56	7.07034
1533.5	6.07271
1537.44	5.2278
1541.38	4.7903
1545.31	4.5464
1549.25	3.79013
1553.18	3.27409
1557.11	3.03343
1561.04	3.07813
1564.96	3.07697
1568.89	-0.909668
1572.81	2.63643
1576.73	7.59924
1580.65	10.3484
1584.57	10.7959
1588.48	8.42091
1592.4	5.68297
1596.31	5.39006
1600.22	6.30333
1604.13	9.76059
1608.04	12.2913
1611.94	11.8136
1615.85	10.3578
1619.75	9.00844
1623.65	7.54654
1627.55	6.0976
1631.44	4.70587
1635.34	3.77617
1639.23	2.54329
1643.12	1.55223
1647.01	0.678558
1650.9	0.098053
1654.78	-0.0759277
1658.67	0.037262
1662.55	0.480423
1666.43	1.12834
1670.31	1.91263
1674.19	3.22005
1678.06	4.10043
1681.93	4.76985
1685.81	5.21158
1689.68	5.03889
1693.54	4.68863
1697.41	4.30635
1701.27	3.95261
1705.14	4.66187
1709	4.60002
1712.86	4.09772
1716.71	3.1521
1720.57	2.99965
1724.42	3.55551
1728.28	4.9855
1732.13	7.19107
1735.97	10.5666
1739.82	12.7275
1743.67	13.5105
1747.51	12.7141
1751.35	10.8082
1755.19	9.64554
1759.03	8.68684
1762.87	8.15764
1766.7	8.04997
1770.53	7.46416
1774.37	7.81618
1778.2	7.88535
1782.02	7.76617
1785.85	7.75745
1789.67	8.00966
1793.5	8.62685
1797.32	9.55447
1801.14	10.4455
1804.95	12.8415
1808.77	10.9534
1812.58	7.68724
1816.4	4.50226
1820.21	1.9097
1824.02	0.104019
1827.82	-0.36351
1831.63	1.20255
1835.43	3.79509
1839.23	6.78185
1843.03	8.78893
1846.83	10.1149
1850.63	10.5913
1854.42	10.3044
1858.22	8.77802
1862.01	7.51152
1865.8	8.0843
1869.59	9.47125
1873.38	11.1944
1877.16	12.5228
1880.94	13.4978
1884.72	14.3628
1888.51	15.0346
1892.28	16.6786
1896.06	14.1041
1899.83	11.7061
1903.61	9.44489
1907.38	7.49532
1911.15	6.26964
1914.91	5.95454
1918.68	6.43478
1922.45	7.45149
1926.21	8.90991
1929.97	10.3696
1933.73	9.806
1937.49	8.21458
1941.24	7.22182
1945	6.12544
1948.75	3.84259
1952.5	1.14044
1956.25	0.759537
1960	1.35594
1963.75	2.94167
1967.49	4.63039
1971.23	5.94157
1974.97	7.04895
1978.71	7.69867
1982.45	8.64941
1986.19	8.45033
1989.92	7.19127
1993.65	4.06717
1997.38	1.75316
2001.11	0.944214
2004.84	2.19424
2008.57	3.73264
2012.29	5.15797
2016.01	6.35298
2019.74	7.20386
2023.45	7.89191
2027.17	8.17719
2030.89	6.17561
2034.6	5.89488
2038.31	5.87514
2042.03	6.11385
2045.74	6.38254
2049.44	6.82339
2053.15	7.80614
2056.85	7.40889
2060.56	5.9538
2064.26	4.71201
2067.96	3.17813
2071.65	1.79974
2075.35	0.42717
2079.05	-0.595871
2082.74	-0.378784
2086.43	0.348801
2090.12	1.54988
2093.81	2.66895
2097.49	4.25911
2101.18	5.80089
2104.86	6.67657
2108.54	7.48245
2112.22	8.14134
2115.9	6.18597
2119.58	6.57004
2123.25	6.6691
2126.93	7.26633
2130.6	8.31516
2134.27	9.67807
2137.94	11.2713
2141.6	13.2483
2145.27	15.269
2148.93	7.2538
2152.59	9.02422
2156.25	9.75621
2159.91	10.9565
2163.57	12.5265
2167.23	13.5836
2170.88	14.3671
2174.53	14.92
2178.18	15.4837
2181.83	18.1451
2185.48	20.9061
2189.12	23.5233
2192.77	25.748
2196.41	27.1084
2200.05	27.7157
2203.69	27.034
2207.33	25.9748
2210.97	24.6306
2214.6	21.7899
2218.23	22.7382
2221.86	23.9541
2225.49	24.4966
2229.12	23.7784
2232.75	22.1508
2236.37	19.7706
2240	16.7327
2243.62	15.4644
2247.24	14.5609
2250.86	13.6338
2254.47	12.7758
2258.09	11.8382
2261.7	11.0201
2265.32	10.2999
2268.93	9.68175
2272.53	9.576
2276.14	9.02792
2279.75	8.4231
2283.35	7.98384
2286.96	7.73314
2290.56	8.58121
2294.16	6.94157
2297.75	5.25073
2301.35	7.86908
2304.94	11.4562
2308.54	14.6217
2312.13	29.1331
2315.72	72.2719
2319.31	248.928
2322.9	262.875
2326.48	53.2377
2330.07	25.7555
2333.65	20.7941
2337.23	13.2526
2340.81	11.6978
2344.38	11.301
2347.96	11.3276
2351.53	11.6453
2355.11	12.2538
2358.68	12.6652
2362.25	13.8238
2365.82	15.1338
2369.38	16.0302
2372.95	14.6822
2376.51	16.4743
2380.07	17.0872
2383.63	17.784
2387.19	19.0068
2390.75	19.9705
2394.3	20.2934
2397.86	20.149
2401.41	17.8024
2404.96	16.4702
2408.51	15.3423
2412.06	14.7471
2415.61	14.2045
2419.15	13.6617
2422.69	13.1482
2426.24	12.3266
2429.78	11.3233
2433.32	10.5018
2436.85	10.1033
2440.39	9.95201
2443.92	9.28824
2447.45	9.76482
2450.99	10.3404
2454.52	10.7789
2458.04	11.0994
2461.57	11.0558
2465.09	10.3905
2468.62	8.82878
2472.14	7.73318
2475.66	6.94382
2479.18	6.39507
2482.7	5.86771
2486.21	5.61107
2489.73	5.77713
2493.24	7.74498
2496.75	10.1427
2500.26	12.2135
2503.77	13.8375
2507.27	14.7911
2510.78	15.458
2514.28	15.8941
2517.78	15.6546
2521.28	14.8882
2524.78	13.859
2528.28	13.026
2531.78	12.8136
2535.27	12.3404
2538.76	11.7589
2542.26	11.2059
2545.75	10.4303
2549.23	10.8229
2552.72	10.481
2556.21	10.1089
2559.69	9.97447
2563.17	9.51111
2566.65	8.82451
2570.13	7.85446
2573.61	6.92094
2577.09	6.29787
2580.56	5.87546
2584.03	5.68294
2587.51	5.91197
2590.98	6.66772
2594.45	7.49788
2597.91	8.13675
2601.38	8.12239
2604.84	7.3403
2608.31	5.52159
2611.77	6.11266
2615.23	5.78752
2618.69	5.67981
2622.14	5.03381
2625.6	3.84529
2629.05	2.61302
2632.51	1.13892
2635.96	1.54547
2639.41	2.8105
2642.85	4.70468
2646.3	7.07927
2649.75	9.82796
2653.19	12.1057
2656.63	12.9022
2660.07	13.7432
2663.51	13.2586
2666.95	12.1323
2670.38	11.166
2673.82	10.4112
2677.25	9.7437
2680.69	9.30832
2684.11	9.21092
2687.54	9.69629
2690.97	8.06104
2694.4	1.78383
2697.82	3.82353
2701.24	4.39932
2704.67	8.33865
2708.09	9.30737
2711.5	9.77376
2714.92	14.2279
2718.34	3.91888
2721.75	-0.601089
2725.16	-0.861343
2728.58	0.206146
2731.98	2.78712
2735.39	4.86575
2738.8	6.19206
2742.21	6.26082
2745.61	4.27419
2749.01	3.67543
2752.41	4.42316
2755.81	5.14517
2759.21	5.61072
2762.61	5.95753
2766	6.64885
2769.4	7.33521
2772.79	7.56206
2776.18	8.89818
2779.57	9.91791
2782.96	10.0205
2786.34	9.6606
2789.73	7.46518
2793.11	6.91827
2796.5	7.55954
2799.88	9.89238
2803.26	10.4154
2806.63	9.27531
2810.01	8.85547
2813.39	8.785
2816.76	8.53304
2820.13	8.84833
2823.5	9.21649
2826.87	10.0246
2830.24	11.1637
2833.61	12.203
2836.97	12.9153
2840.33	12.4538
2843.7	9.77679
2847.06	12.8883
2850.42	14.6584
2853.78	15.7995
2857.13	13.0123
2860.49	11.4982
2863.84	9.85887
2867.19	10.2224
2870.54	9.85492
2873.89	8.56677
2877.24	6.8943
2880.59	4.68074
2883.93	5.55045
2887.28	6.64432
2890.62	6.78267
2893.96	6.48119
2897.3	7.20554
2900.64	10.4891
2903.97	11.5143
2907.31	12.9514
2910.64	13.7114
2913.98	13.7532
2917.31	12.9486
2920.64	10.7283
2923.97	8.34113
2927.29	5.76701
2930.62	4.15825
2933.94	4.79919
2937.26	6.20796
2940.59	8.1797
2943.91	9.81934
2947.22	10.7017
2950.54	10.257
2953.86	8.95146
2957.17	7.49525
2960.48	5.45668
2963.79	4.44324
2967.1	4.43343
2970.41	5.70389
2973.72	5.44133
2977.03	6.64555
2980.33	6.15793
2983.63	5.08936
2986.94	4.3445
2990.24	3.78539
2993.53	3.13625
2996.83	3.32796
3000.13	4.31746
3003.42	6.30342
3006.72	7.40323
3010.01	7.57068
3013.3	6.44542
3016.59	5.3633
3019.88	5.53859
3023.16	6.92207
3026.45	8.14726
3029.73	7.42448
3033.01	6.59282
3036.3	6.18996
3039.58	5.9084
3042.85	5.63022
3046.13	5.31674
3049.41	4.41211
3052.68	3.73378
3055.95	3.19966
3059.22	3.08955
3062.49	2.17349
3065.76	0.897552
3069.03	0.11026
3072.3	-0.147171
3075.56	0.829269
3078.82	2.29323
3082.08	3.38724
3085.35	4.09608
3088.6	4.351
3091.86	4.24377
3095.12	3.64374
3098.37	2.61234
3101.63	1.2908
3104.88	0.0142517
3108.13	-0.0196381
3111.38	0.170059
3114.63	0.548447
3117.87	1.10477
3121.12	1.83495
3124.36	2.52609
3127.61	2.82968
3130.85	2.16214
3134.09	0.0844879
3137.33	0.888
3140.56	9.15889
3143.8	1.14632
3147.04	-0.512589
3150.27	-1.04158
3153.5	1.26944
3156.73	4.09537
3159.96	8.21358
3163.19	9.5551
3166.42	8.31326
3169.64	6.88609
3172.86	5.78214
3176.09	5.02571
3179.31	4.69943
3182.53	4.70314
3185.75	4.88879
3188.96	5.55301
3192.18	7.1972
3195.39	8.20287
3198.61	8.16844
3201.82	8.45691
3205.03	8.50829
3208.24	8.2543
3211.45	7.17787
3214.65	5.39925
3217.86	4.6459
3221.06	7.25795
3224.27	16.1953
3227.47	14.3999
3230.67	13.5891
3233.86	13.989
3237.06	15.0378
3240.26	16.6116
3243.45	18.578
3246.65	17.1921
3249.84	15.5596
3253.03	13.8459
3256.22	11.9992
3259.41	11.399
3262.59	11.709
3265.78	13.3159
3268.96	16.1995
3272.15	16.8484
3275.33	17.3601
3278.51	16.7317
3281.69	16.1967
3284.86	15.8424
3288.04	15.5969
3291.21	16.4967
3294.39	18.213
3297.56	20.7896
3300.73	23.481
3303.9	26.2043
3307.07	28.9527
3310.24	30.9722
3313.4	32.2504
3316.57	32.7148
3319.73	32.5551
3322.89	31.6248
3326.05	28.9178
3329.21	31.6725
3332.37	32.9988
3335.53	34.577
3338.68	35.7641
3341.84	37.0976
3344.99	38.5126
3348.14	38.7108
3351.29	38.9159
3354.44	39.3271
3357.59	40.3999
3360.73	41.6674
3363.88	43.1997
3367.02	44.5894
3370.16	47.0806
3373.3	47.1901
3376.44	56.1033
3379.58	60.6871
3382.72	67.7876
3385.86	76.4597
3388.99	84.7632
3392.12	97.9657
3395.26	110.038
3398.39	126.099
3401.52	158.329
3404.65	195.205
3407.77	260.572
3410.9	387.009
3414.02	654.068
3417.15	1311.77
3420.27	2649.48
3423.39	3765.18
3426.51	2958.89
3429.63	1508.59
3432.74	717.302
3435.86	382.141
3438.97	267.026
3442.08	209.504
3445.2	172.876
3448.31	148.162
3451.42	132.724
3454.52	125.437
3457.63	122.904
3460.74	126.967
3463.84	139.185
3466.94	159.528
3470.04	186.165
3473.14	220.107
3476.24	263.375
3479.34	319.918
3482.44	391.205
3485.53	483.109
3488.63	623.395
3491.72	839.485
3494.81	1154.64
3497.9	1595.38
3500.99	2058.11
3504.08	2439.84
3507.16	2508.85
3510.25	2200.48
3513.33	1591.03
3516.41	1164.76
3519.5	838.803
3522.58	637.088
3525.66	492.103
3528.73	384.419
3531.81	297.104
3534.89	236.269
3537.96	192.548
3541.03	158.094
3544.1	135.412
3547.17	119.66
3550.24	110.435
3553.31	104.844
3556.38	98.9299
3559.44	91.4423
3562.5	84.2189
3565.57	77.5493
3568.63	70.3177
3571.69	57.3439
3574.75	48.9868
3577.81	45.5636
3580.86	44.8443
3583.92	45.4075
3586.97	46.8879
3590.02	49.3522
3593.08	50.1172
3596.13	45.8294
3599.18	40.3347
3602.22	34.7703
3605.27	30.3899
3608.31	27.3831
3611.36	25.98
3614.4	25.5889
3617.44	25.9463
3620.48	27.3143
3623.52	29.4488
3626.56	31.4899
3629.6	32.949
3632.63	33.3245
3635.67	32.7465
3638.7	31.1582
3641.73	29.171
3644.76	27.1554
3647.79	25.2449
3650.82	23.4884
3653.85	21.6346
3656.87	19.4146
3659.9	17.0142
3662.92	15.187
3665.94	14.4719
3668.96	13.8864
3671.98	13.0628
3675	10.8616
3678.02	8.2917
3681.04	6.97026
3684.05	5.79225
3687.06	4.99265
3690.08	6.81468
3693.09	9.20946
3696.1	10.6564
3699.11	10.4729
3702.11	9.14046
3705.12	6.26897
3708.13	3.59393
3711.13	-0.185211
3714.13	0.0130463
3717.13	1.56726
3720.13	4.29353
3723.13	6.63123
3726.13	8.0027
3729.13	8.52948
3732.12	6.50803
3735.12	3.79378
3738.11	2.25131
3741.1	1.83551
3744.09	2.4268
3747.08	4.05626
3750.07	6.23203
3753.06	8.84938
3756.04	11.552
3759.03	13.0284
3762.01	13.5495
3765	12.1663
3767.98	10.4076
3770.96	8.39648
3773.94	6.20715
3776.91	4.0379
3779.89	2.10242
3782.86	1.43433
3785.84	2.28345
3788.81	4.11877
3791.78	7.83371
3794.75	8.10666
3797.72	7.15173
3800.69	4.84088
3803.66	2.11328
3806.62	0.264343
3809.59	-1.18234
3812.55	-0.147736
3815.51	0.429626
3818.47	0.493835
3821.43	0.493561
3824.39	2.46304
3827.35	4.94061
3830.31	6.58823
3833.26	7.54446
3836.22	7.76828
3839.17	6.59845
3842.12	4.65836
3845.07	2.44534
3848.02	0.836304
3850.97	0.153168
3853.91	-0.156372
3856.86	-0.116211
3859.8	0.0400391
3862.75	0.457336
3865.69	1.5206
3868.63	3.25262
3871.57	5.99548
3874.51	6.99414
3877.45	7.46722
3880.38	7.48178
3883.32	7.23285
3886.25	6.99313
3889.19	6.58115
3892.12	5.59091
3895.05	4.21539
3897.98	0.319244
3900.9	-0.931
3903.83	-0.0591125
3906.76	1.55286
3909.68	2.27924
3912.61	1.75845
3915.53	2.39059
3918.45	0.69223
3921.37	1.94046
3924.29	4.9382
3927.21	7.24854
3930.12	8.88458
3933.04	10.0105
3935.95	10.1262
3938.87	9.42899
3941.78	8.4263
3944.69	6.72684
3947.6	7.07007
3950.51	7.9653
3953.42	8.69907
3956.32	9.26468
3959.23	9.57114
3962.13	9.91098
3965.03	9.45206
3967.93	8.95569
3970.84	8.4285
3973.74	7.98538
3976.63	7.62589
3979.53	7.55441
3982.43	8.14352
3985.32	8.84357
3988.21	9.24715
3991.11	9.20842
3994	8.78802
3996.89	7.54137
3999.78	0.104477