File: Data/3-Raman/processed/bu20-j-ff1-fi02-v_1800 (450-850nm)_532nm_edge_100%_x100_vis_lwd_h30um_60sx2_01.txt
#Acq. time (s)=	60
#Accumulations=	2
#Range (cm-¹)=	1200...2360
#Windows=	3
#Auto scanning=	Off
#Autofocus=	Off
#Macrospot=	Off
#AutoExposure=	Off
#Spike filter=	Multiple accum.
#Delay time (s)=	2
#Binning=	1
#Readout mode=	Signal
#DeNoise=	Off
#ICS correction=	On
#Dark correction=	Off
#Inst. Process=	Off
#Detector Gain=	Best Dynamic
#Detector ADC=	50 kHz HS
#Detector temperature (°C)=	-60.09
#Instrument=	LabRAM HR Evol
#Detector=	SIN-EM FIVIS
#Objective=	x100_VIS_LWD
#Grating=	1800 (450-850nm)
#ND Filter=	100%
#Laser=	532nm_Edge
#Hole=	30.0125
#Temperature=	0
#Range=	Visible
#StageXY=	75x50mm Scan+
#StageZ=	Z motor
#X (µm)=	0
#Y (µm)=	0
#Z (µm)=	-17.3
#Full time(mm:ss)=	6:23
#Project=	21_08_11
#Sample=	BU20
#Site=
#Title=	BU20-J-FF1-FI02-V_1800 (450-850nm)_532nm_Edge_100%_x100_VIS_LWD_H30um_60sX2
#Remark=
#Date=	11.08.2021 17:12
#Acquired=	11.08.2021 17:12:55
#Data Range:Extract=	16.12.2021 15:36:30
#Base:Fit=	16.12.2021 15:36:40
#Base:Fit=	16.12.2021 15:56:39
#Base:Sub=	16.12.2021 15:56:41
1201.69	-0.435024
1202.8	1.87012
1203.91	-0.255268
1205.02	0.882534
1206.14	0.903545
1207.25	-3.34117
1208.36	0.995502
1209.47	4.2707
1210.58	0.0364647
1211.69	1.13921
1212.8	1.18663
1213.91	-0.867058
1215.02	-0.783413
1216.13	-4.98691
1217.24	-0.691719
1218.35	-2.75631
1219.45	-2.68607
1220.56	-0.485348
1221.67	-2.55324
1222.78	-0.412846
1223.89	-2.48838
1225	2.8637
1226.1	6.12025
1227.21	10.3537
1228.32	10.308
1229.43	16.8765
1230.53	26.3479
1231.64	37.8677
1232.74	41.0791
1233.85	49.5793
1234.96	39.1886
1236.06	35.0723
1237.17	21.4299
1238.27	20.3864
1239.38	17.2946
1240.48	7.9411
1241.59	6.95939
1242.69	8.09997
1243.8	11.3266
1244.9	11.3792
1246.01	14.5574
1247.11	18.8155
1248.21	23.0404
1249.32	22.0738
1250.42	28.3879
1251.52	32.5987
1252.63	23.2331
1253.73	24.3635
1254.83	16.1082
1255.93	16.1875
1257.03	13.1321
1258.14	15.2807
1259.24	13.2612
1260.34	10.1927
1261.44	10.2823
1262.54	22.8597
1263.64	54.3855
1264.74	56.5385
1265.84	20.0218
1266.94	7.58646
1268.04	5.61997
1269.14	8.85443
1270.24	0.515268
1271.34	4.76191
1272.44	5.92158
1273.54	3.93431
1274.64	7.16059
1275.74	6.20674
1276.84	3.15437
1277.93	11.6648
1279.03	9.65729
1280.13	16.0312
1281.23	35.0864
1282.33	100.43
1283.42	519.574
1284.52	1150.3
1285.62	143.857
1286.71	47.028
1287.81	18.6482
1288.91	10.314
1290	7.24675
1291.1	2.0413
1292.19	4.216
1293.29	0.0886307
1294.38	6.49977
1295.48	3.45811
1296.57	5.65899
1297.67	6.75308
1298.76	1.53086
1299.86	1.59942
1300.95	0.609867
1302.04	0.688835
1303.14	2.85721
1304.23	-4.47041
1305.32	-2.31149
1306.42	1.95703
1307.51	2.0248
1308.6	-2.12447
1309.69	-2.04984
1310.79	4.34691
1311.88	0.201687
1312.97	-0.79438
1314.06	1.37717
1315.15	2.50999
1316.24	1.5175
1317.33	1.58579
1318.43	-0.460037
1319.52	2.77037
1320.61	-1.40223
1321.7	-1.36766
1322.79	1.83999
1323.88	-0.20319
1324.97	0.909285
1326.06	-0.139572
1327.15	-0.0472717
1328.23	1.10758
1329.32	1.17057
1330.41	-3.00329
1331.5	3.33933
1332.59	1.25813
1333.68	-1.86671
1334.76	2.36733
1335.85	1.35805
1336.94	5.59741
1338.03	-2.74619
1339.11	2.54063
1340.2	2.60349
1341.29	2.65526
1342.37	-0.450378
1343.46	0.645298
1344.54	-1.39393
1345.63	-1.36345
1346.72	1.78745
1347.8	1.82445
1348.89	1.86488
1349.97	7.10591
1351.06	1.93272
1352.14	4.07299
1353.23	2.11007
1354.31	4.15231
1355.39	1.08574
1356.48	8.4059
1357.56	1.17639
1358.64	0.174166
1359.73	3.31782
1360.81	4.39063
1361.89	-0.741802
1362.98	3.45566
1364.06	4.55169
1365.14	12.8652
1366.22	2.54132
1367.3	4.64638
1368.38	8.84295
1369.47	64.7185
1370.55	10.9906
1371.63	12.0269
1372.71	14.1055
1373.79	3.83917
1374.87	9.03421
1375.95	17.325
1377.03	12.1919
1378.11	17.4579
1379.19	20.5994
1380.27	21.5975
1381.35	27.7732
1382.43	30.814
1383.51	41.0648
1384.59	56.5332
1385.66	130.597
1386.74	676.849
1387.82	2188.17
1388.9	169.749
1389.98	53.6725
1391.05	30.1132
1392.13	22.9474
1393.21	21.9517
1394.28	15.8493
1395.36	15.9149
1396.44	13.9035
1397.51	7.79612
1398.59	9.89964
1399.66	4.84232
1400.74	12.0715
1401.82	10.1008
1402.89	5.06846
1403.97	11.2546
1405.04	11.2841
1406.12	18.4867
1407.19	34.947
1408.27	93.4596
1409.34	126.37
1410.41	28.9274
1411.49	17.6719
1412.56	11.6424
1413.63	10.622
1414.71	6.60177
1415.78	8.70646
1416.85	8.76537
1417.92	3.67976
1419	6.80821
1420.07	5.80383
1421.14	2.75519
1422.21	6.94565
1423.28	4.85608
1424.36	7.97382
1425.43	10.0988
1426.5	7.0434
1427.57	1.93182
1428.64	5.04852
1429.71	1.01191
1430.78	2.11097
1431.85	4.20244
1432.92	5.23852
1433.99	6.29216
1435.06	4.29566
1436.13	-0.791147
1437.2	2.31688
1438.26	9.53453
1439.33	1.39099
1440.4	4.52094
1441.47	4.55579
1442.54	1.52871
1443.61	4.63422
1444.67	4.69793
1445.74	3.70534
1446.81	2.71244
1447.87	2.74987
1448.94	0.745062
1450.01	0.773119
1451.07	3.87983
1452.14	0.840378
1453.21	0.886236
1454.27	-3.17621
1455.34	0.963533
1456.4	1.00052
1457.47	1.03119
1458.53	4.14635
1459.6	2.13535
1460.66	0.116804
1461.73	3.21302
1462.79	1.18489
1463.86	-1.83749
1464.92	1.23737
1465.98	-0.784645
1467.05	1.28127
1468.11	3.35506
1469.17	5.42134
1470.24	0.345612
1471.3	0.371126
1472.36	1.42224
1473.42	-0.587029
1474.48	1.48598
1475.55	-1.53509
1476.61	1.5428
1477.67	5.64053
1478.73	2.61087
1479.79	-0.420527
1480.85	1.6285
1481.91	2.6911
1482.97	-1.32713
1484.04	1.73563
1485.1	-0.33172
1486.15	3.79364
1487.22	3.82896
1488.28	2.83337
1489.33	-1.19006
1490.39	0.861063
1491.45	-1.13487
1492.51	1.93052
1493.57	-1.07059
1494.63	-0.0259762
1495.69	0.994793
1496.74	3.03768
1497.8	0.0413971
1498.86	0.077322
1499.92	0.114624
1500.97	2.15883
1502.03	0.169044
1503.09	0.187162
1504.14	0.222202
1505.2	3.26864
1506.26	0.26618
1507.31	2.31881
1508.37	-0.674046
1509.42	-0.641136
1510.48	3.4109
1511.53	2.39898
1512.59	0.390854
1513.64	0.42696
1514.7	2.45777
1515.75	1.46249
1516.81	3.49252
1517.86	-1.48447
1518.92	1.56076
1519.97	0.585875
1521.02	-0.382235
1522.08	0.644903
1523.13	-1.34714
1524.18	4.67587
1525.24	-0.295897
1526.29	-1.25484
1527.34	-1.23027
1528.39	-0.206148
1529.44	2.82218
1530.5	-2.14958
1531.55	2.89249
1532.6	0.927713
1533.65	-1.03828
1534.7	0.990627
1535.75	0.996193
1536.8	-0.999647
1537.85	0.0154934
1538.9	0.0523033
1539.95	2.12481
1541	2.15327
1542.05	9.17037
1543.1	2.16776
1544.15	-0.808994
1545.2	-1.76274
1546.25	-1.73164
1547.3	-1.69999
1548.35	0.328529
1549.39	0.319614
1550.44	0.437834
1551.49	5.45723
1552.54	-0.525167
1553.58	-2.52727
1554.63	0.486881
1555.68	-0.488258
1556.73	-1.46512
1557.77	-4.451
1558.82	-1.44021
1559.87	0.573488
1560.91	-2.40135
1561.96	0.636894
1563	-3.34067
1564.05	0.698767
1565.09	-1.34883
1566.14	-0.271357
1567.18	0.767574
1568.23	-3.2162
1569.27	0.795868
1570.32	-1.17625
1571.36	1.83754
1572.41	1.85248
1573.45	-0.128489
1574.49	-0.0891838
1575.54	0.942064
1576.58	-0.046545
1577.62	-3.03782
1578.67	0.969107
1579.71	0.00053215
1580.75	2.01337
1581.79	0.0319023
1582.84	0.0508518
1583.88	0.0730133
1584.92	-2.8911
1585.96	2.10125
1587	-2.86108
1588.04	1.1436
1589.08	4.16228
1590.13	2.19774
1591.17	-0.76675
1592.21	0.236303
1593.25	0.23616
1594.29	0.251793
1595.33	-0.72064
1596.37	0.294571
1597.41	-0.672848
1598.44	0.329088
1599.48	3.3147
1600.52	3.31845
1601.56	-1.63373
1602.6	0.35261
1603.64	2.3433
1604.67	-1.58938
1605.71	1.48186
1606.75	-3.21572
1607.79	1.45135
1608.82	1.92614
1609.86	0.404121
1610.9	0.714516
1611.93	-0.413866
1612.97	1.6158
1614.01	-0.170811
1615.04	-0.113256
1616.08	-1.19335
1617.12	-0.164042
1618.15	1.33916
1619.19	0.870911
1620.22	0.399971
1621.26	0.987471
1622.29	0.0134544
1623.33	0.0290222
1624.36	-0.165173
1625.39	-0.805947
1626.43	0.191422
1627.46	0.0127983
1628.5	-1.40745
1629.53	-2.14557
1630.41	-0.169729
1631.46	2.81353
1632.5	1.86074
1633.55	2.85278
1634.59	1.88873
1635.64	-0.0690861
1636.68	0.924959
1637.73	1.92171
1638.77	-1.99942
1639.82	1.9551
1640.86	0.0112209
1641.91	2.97781
1642.95	0.0406399
1644	1.03491
1645.04	-2.88039
1646.08	0.0862198
1647.12	-0.885487
1648.17	7.98891
1649.21	-0.836334
1650.25	3.12884
1651.29	1.18541
1652.34	2.18602
1653.38	2.20283
1654.42	4.19669
1655.46	-1.68481
1656.5	2.28667
1657.54	3.28465
1658.59	2.3054
1659.63	1.32601
1660.67	-2.59253
1661.71	0.382057
1662.75	2.40734
1663.79	1.41512
1664.83	1.44198
1665.87	-0.502994
1666.91	2.44962
1667.95	0.48155
1668.99	1.50516
1670.02	-1.44039
1671.06	0.559278
1672.1	-1.39951
1673.14	0.594412
1674.18	2.59589
1675.22	1.63179
1676.25	3.62811
1677.29	2.64999
1678.33	0.673859
1679.37	1.67038
1680.4	0.690876
1681.44	-2.25991
1682.48	0.718367
1683.51	-0.255984
1684.55	1.72849
1685.58	1.74272
1686.62	0.776815
1687.66	0.785754
1688.69	-1.18357
1689.73	0.791966
1690.76	1.8013
1691.8	0.83219
1692.83	-1.13793
1693.87	-0.152333
1694.9	2.81403
1695.94	-1.10749
1696.97	-1.0987
1698	0.870965
1699.04	1.86351
1700.07	0.890702
1701.1	-0.0837679
1702.14	0.900929
1703.17	-2.03813
1704.2	-1.04048
1705.24	-0.045949
1706.27	-1.02571
1707.3	0.934598
1708.33	0.925909
1709.36	-0.0504723
1710.4	-1.01367
1711.43	-0.016243
1712.46	-0.997088
1713.49	-1.98279
1714.52	1.93137
1715.55	0.973094
1716.58	1.94824
1717.61	1.93089
1718.64	-0.0202351
1719.67	-0.00676346
1720.7	-0.00512981
1721.73	-0.978579
1722.76	0.962677
1723.79	-0.972674
1724.82	-1.9449
1725.85	-0.00720882
1726.88	0.964621
1727.9	0.00588894
1728.93	-0.0354671
1729.96	-0.0156956
1730.99	-0.956159
1732.02	0.984781
1733.04	-0.948973
1734.07	0.00647449
1735.1	0.962423
1736.13	0.965279
1737.15	0.00594425
1738.18	-1.91666
1739.21	0.958206
1740.23	0.945284
1741.26	2.85769
1742.28	-1.92465
1743.31	-0.96094
1744.33	-1.91422
1745.36	0.964829
1746.38	2.87099
1747.41	1.91011
1748.44	0.0117464
1749.46	2.89702
1750.48	0.0522375
1751.51	0.0560322
1752.53	1.00682
1753.56	1.00526
1754.58	1.00433
1755.6	-0.901499
1756.63	-0.907893
1757.65	1.0015
1758.67	1.01627
1759.69	-0.877906
1760.72	1.97795
1761.74	0.0777502
1762.76	0.0915594
1763.78	0.104896
1764.81	1.07926
1765.83	2.04332
1766.85	0.145447
1767.87	-1.75575
1768.89	2.98828
1769.91	3.94375
1770.93	0.162302
1771.95	3.03418
1772.97	2.10169
1773.99	-0.740004
1775.01	3.08775
1776.03	3.10956
1777.05	2.15665
1778.07	0.248805
1779.09	-1.65764
1780.11	2.16446
1781.13	5.03379
1782.15	3.15008
1783.17	4.12103
1784.18	1.28158
1785.2	-0.616633
1786.22	0.345886
1787.24	3.23826
1788.25	8.07149
1789.27	5.22843
1790.29	4.28463
1791.31	4.27403
1792.32	8.11614
1793.34	1.42373
1794.36	5.26244
1795.37	0.509294
1796.39	3.41078
1797.4	5.3532
1798.42	3.44243
1799.44	1.51769
1800.45	3.43895
1801.47	4.40726
1802.48	3.46381
1803.5	0.59778
1804.51	3.50165
1805.53	7.37924
1806.54	2.57912
1807.55	2.58739
1808.57	3.56087
1809.58	5.49945
1810.59	3.57713
1811.61	3.58419
1812.62	1.67195
1813.63	5.54986
1814.65	3.64534
1815.66	6.55746
1816.67	3.66692
1817.68	4.62455
1818.7	2.70874
1819.71	4.65658
1820.72	6.60692
1821.73	4.68974
1822.74	3.73307
1823.75	3.73581
1824.76	5.68586
1825.77	4.72712
1826.78	3.76847
1827.8	4.74858
1828.81	4.74789
1829.82	4.74892
1830.83	5.72387
1831.83	4.77202
1832.84	6.72554
1833.85	2.85827
1834.86	1.86492
1835.87	4.7778
1836.88	6.74132
1837.89	1.85717
1838.9	6.75337
1839.91	4.80645
1840.91	6.70416
1841.92	1.85545
1842.93	6.68439
1843.94	-0.0634413
1844.94	2.83564
1845.95	4.79969
1846.96	3.77828
1847.96	6.68457
1848.97	1.85977
1849.98	4.72887
1850.98	2.79646
1851.99	5.67856
1852.99	7.6018
1854	4.70768
1855.01	4.69617
1856.01	3.73405
1857.02	2.77847
1858.02	3.73
1859.02	4.6739
1860.03	5.63572
1861.03	3.74158
1862.04	5.65745
1863.04	4.68826
1864.04	4.67929
1865.05	3.71139
1866.05	1.78248
1867.05	4.61554
1868.06	4.61063
1869.06	3.66477
1870.06	1.76486
1871.07	2.7171
1872.07	2.71308
1873.07	3.65809
1874.07	2.70163
1875.07	6.47826
1876.08	4.55875
1877.08	4.53013
1878.08	5.51734
1879.08	7.43825
1880.08	2.69595
1881.08	6.47278
1882.08	5.48835
1883.08	4.61852
1884.08	1.70026
1885.08	6.43398
1886.08	5.51263
1887.08	2.66625
1888.08	3.59241
1889.08	4.52015
1890.08	3.58911
1891.08	6.41963
1892.07	4.53593
1893.07	3.57332
1894.07	4.505
1895.07	7.32707
1896.07	4.52248
1897.07	3.59569
1898.06	2.65521
1899.06	3.58496
1900.06	5.46125
1901.05	2.65657
1902.05	2.67376
1903.05	7.37315
1904.04	3.61186
1905.04	3.61302
1906.04	3.60161
1907.03	6.41893
1908.03	2.6735
1909.02	3.62694
1910.02	1.7703
1911.01	0.842473
1912.01	0.843748
1913	1.78982
1914	4.63808
1914.99	3.71151
1915.99	2.76871
1916.98	-0.0684366
1917.98	2.76539
1918.97	4.67618
1919.96	4.69561
1920.96	0.927478
1921.95	2.82624
1922.94	4.71183
1923.94	1.87067
1924.93	-0.0139723
1925.92	0.950079
1926.91	0.966341
1927.9	1.92357
1928.9	2.88285
1929.89	2.90443
1930.88	-0.882177
1931.87	3.85882
1932.86	1.00853
1933.85	1.98839
1934.84	2.99129
1935.83	-0.820712
1936.83	3.93482
1937.82	2.97273
1938.81	0.129914
1939.8	0.139681
1940.79	1.11712
1941.78	1.1044
1942.76	0.173829
1943.75	0.17184
1944.74	-2.67934
1945.73	2.11348
1946.72	1.16295
1947.71	1.16248
1948.7	4.03749
1949.69	0.22814
1950.67	1.21218
1951.66	1.23237
1952.65	2.20275
1953.64	0.264738
1954.62	-0.711762
1955.61	1.22235
1956.6	1.24408
1957.58	3.17919
1958.57	1.25983
1959.56	0.2943
1960.54	1.24694
1961.53	1.24439
1962.51	1.24908
1963.5	0.293912
1964.48	3.1779
1965.47	1.26199
1966.46	-0.646711
1967.44	1.28001
1968.43	-0.642108
1969.41	2.22573
1970.39	0.2969
1971.38	-1.62482
1972.36	-0.661368
1973.35	1.24866
1974.33	0.289149
1975.31	3.17398
1976.3	1.26214
1977.28	0.300888
1978.26	2.21194
1979.24	0.296689
1980.23	3.16899
1981.21	3.16277
1982.19	0.286099
1983.17	-0.68159
1984.16	-2.5973
1985.14	1.21107
1986.12	0.230347
1987.1	2.02052
1988.08	0.134706
1989.06	0.264008
1990.04	0.570184
1991.02	0.734179
1992	1.54867
1992.98	-0.908612
1993.96	0.827534
1994.94	0.541086
1995.92	0.152617
1996.9	-1.13745
1997.88	0.677977
1998.86	-0.71258
1999.84	-1.70121
2000.82	1.3762
2001.8	-0.958047
2002.78	-0.627339
2003.76	-0.117702
2004.73	0.133294
2005.71	0.23908
2006.69	-0.294375
2007.67	1.06974
2008.64	0.424311
2009.62	-1.07745
2010.52	1.03083
2011.51	-0.853798
2012.5	1.02423
2013.48	-1.81708
2014.47	-1.83433
2015.46	2.86677
2016.45	0.0648355
2017.44	-1.82364
2018.43	-0.903534
2019.41	-0.916589
2020.4	0.954988
2021.39	0.0201492
2022.38	0.0112848
2023.36	0.934216
2024.35	0.918683
2025.34	-0.964288
2026.32	2.78224
2027.31	2.81414
2028.3	2.79571
2029.28	2.80112
2030.27	1.82176
2031.25	1.83927
2032.24	-0.0118103
2033.23	0.00372601
2034.21	0.907218
2035.2	0.925778
2036.18	2.80405
2037.17	1.87326
2038.15	-1.87265
2039.13	-1.88017
2040.12	-0.0265179
2041.1	-0.0355215
2042.09	0.888911
2043.07	-0.969956
2044.05	-0.0255327
2045.04	-0.960052
2046.02	-0.932054
2047	-0.955598
2047.99	1.83024
2048.97	-0.957937
2049.95	-1.87627
2050.93	-0.943457
2051.92	-0.0106144
2052.9	0.931491
2053.88	0.0114422
2054.86	0.00962639
2055.84	0.937985
2056.82	-0.933084
2057.8	0.944318
2058.78	0.956546
2059.77	0.0204706
2060.75	-3.72351
2061.73	0.0237436
2062.71	0.967718
2063.69	-0.899634
2064.67	0.0460176
2065.65	-2.75662
2066.63	-2.75237
2067.61	-1.80684
2068.58	1.95721
2069.56	-0.876469
2070.54	1.0253
2071.52	0.100413
2072.5	-2.72817
2073.48	-0.84484
2074.45	-0.836575
2075.43	-0.815069
2076.41	1.07398
2077.39	-2.71275
2078.37	1.06679
2079.34	1.08233
2080.32	-1.74613
2081.3	-1.74892
2082.27	-2.69198
2083.25	-0.803331
2084.23	1.08663
2085.2	1.08689
2086.18	-0.791913
2087.15	-0.786065
2088.13	-1.73157
2089.11	1.11404
2090.08	1.12082
2091.06	2.07459
2092.03	-1.70245
2093	1.16089
2093.98	-0.730865
2094.95	3.06655
2095.93	0.207656
2096.9	-1.69798
2097.88	-1.70309
2098.85	0.191847
2099.82	2.08924
2100.8	-0.750593
2101.77	1.15048
2102.74	1.14343
2103.72	0.191223
2104.69	0.198164
2105.66	2.10833
2106.63	-1.69072
2107.6	3.05309
2108.58	2.08922
2109.55	-0.753124
2110.52	1.14619
2111.49	0.19099
2112.46	1.14222
2113.43	0.20099
2114.4	1.14893
2115.38	-1.70548
2116.35	4.93456
2117.32	2.08226
2118.29	0.169953
2119.26	2.05306
2120.23	2.047
2121.2	-0.786885
2122.17	-1.72686
2123.14	-0.774047
2124.1	-0.783281
2125.07	-1.75283
2126.04	2.01826
2127.01	2.0061
2127.98	1.05553
2128.95	1.05285
2129.92	1.99359
2130.88	-0.848067
2131.85	1.03245
2132.82	-0.862825
2133.79	-1.80578
2134.75	0.0798388
2135.72	0.0697346
2136.69	-0.878704
2137.65	1.95253
2138.62	2.89532
2139.59	4.76457
2140.55	1.92944
2141.52	1.92045
2142.49	0.040575
2143.45	-0.928691
2144.42	1.90584
2145.38	1.89654
2146.35	1.89017
2147.31	2.82055
2148.28	1.87254
2149.24	4.66947
2150.21	1.84167
2151.17	3.72119
2152.14	1.84779
2153.1	-0.0370092
2154.06	2.75913
2155.03	2.73162
2155.99	3.65073
2156.95	-1.02133
2157.92	5.52706
2158.88	3.6515
2159.84	3.63502
2160.8	3.62369
2161.77	1.7526
2162.73	2.68018
2163.69	3.60381
2164.65	2.66053
2165.61	5.45687
2166.58	5.44413
2167.54	5.41987
2168.5	6.33787
2169.46	5.42575
2170.42	5.43605
2171.38	4.47731
2172.34	3.53134
2173.3	3.5303
2174.26	4.46301
2175.22	3.5294
2176.18	5.38012
2177.14	4.44941
2178.1	4.44133
2179.06	4.43702
2180.02	4.43491
2180.98	5.35762
2181.94	6.27597
2182.9	4.40731
2183.85	9.02413
2184.81	7.17298
2185.77	6.25587
2186.73	4.4193
2187.69	4.42569
2188.64	4.40898
2189.6	2.53501
2190.56	5.31741
2191.52	4.39305
2192.47	7.18288
2193.43	5.3451
2194.39	5.36077
2195.34	6.27687
2196.3	6.2511
2197.26	4.38461
2198.21	6.25089
2199.17	2.55762
2200.12	6.31019
2201.08	7.25004
2202.03	9.02278
2202.99	9.06627
2203.94	6.33204
2204.9	6.28502
2205.85	5.34501
2206.81	9.06027
2207.76	9.07767
2208.71	6.29683
2209.67	4.43411
2210.62	3.51146
2211.57	7.25345
2212.53	8.18555
2213.48	3.51397
2214.43	4.46493
2215.39	4.46731
2216.34	5.39767
2217.29	4.46323
2218.24	6.33155
2219.2	5.40792
2220.15	5.40922
2221.1	7.26289
2222.05	5.38248
2223	3.52322
2223.95	5.41132
2224.91	5.42768
2225.86	8.25474
2226.81	3.58117
2227.76	8.26921
2228.71	7.32456
2229.66	7.33737
2230.61	9.23028
2231.56	5.48978
2232.51	7.38399
2233.46	5.51467
2234.41	7.3921
2235.36	7.37408
2236.31	5.49535
2237.25	3.62809
2238.2	4.59246
2239.15	4.60246
2240.1	4.58628
2241.05	6.48903
2242	5.55026
2242.94	10.2673
2243.89	6.48543
2244.84	6.50867
2245.79	7.46991
2246.73	5.58773
2247.68	5.58738
2248.63	5.5809
2249.57	4.63733
2250.52	5.56688
2251.47	1.7765
2252.41	6.51819
2253.36	4.65082
2254.3	-1.03043
2255.25	-0.0843773
2256.2	6.56308
2257.14	6.57449
2258.09	6.57825
2259.03	2.78545
2259.98	8.49395
2260.92	6.60683
2261.86	1.85208
2262.81	5.67347
2263.75	8.56158
2264.7	5.71911
2265.64	5.72042
2266.58	1.88281
2267.53	5.68443
2268.47	3.77396
2269.41	3.79079
2270.36	2.85046
2271.3	7.64131
2272.24	4.77691
2273.18	7.64982
2274.13	5.73785
2275.07	3.82572
2276.01	3.83436
2276.95	4.80876
2277.89	2.91118
2278.84	6.75016
2279.78	0.00845146
2280.72	4.78984
2281.66	3.82828
2282.6	4.79991
2283.54	3.86639
2284.48	3.88363
2285.42	3.88334
2286.36	4.84015
2287.3	3.89588
2288.24	1.00244
2289.18	0.981932
2290.12	2.89235
2291.06	1.94088
2292	3.87653
2292.93	1.96094
2293.87	0.994441
2294.81	2.90872
2295.75	4.82041
2296.69	-0.960238
2297.63	2.90408
2298.56	1.95141
2299.5	0.991937
2300.44	1.95838
2301.38	1.9612
2302.31	0.0257092
2303.25	1.95219
2304.19	1.95833
2305.12	2.92991
2306.06	1.96725
2307	2.92922
2307.93	-1.91041
2308.87	0.024291
2309.8	0.0340223
2310.74	-0.94052
2311.68	-0.00196934
2312.61	-0.0113611
2313.55	0.00148869
2314.48	1.95191
2315.41	0.00687981
2316.35	3.84886
2317.28	0.954603
2318.22	2.87595
2319.15	2.8632
2320.09	1.8946
2321.02	4.79808
2321.95	1.91582
2322.89	2.88266
2323.82	4.81575
2324.75	13.4892
2325.69	14.4285
2326.62	30.796
2327.55	104.976
2328.48	246.626
2329.42	50.952
2330.35	14.3469
2331.28	3.7566
2332.21	2.78387
2333.14	1.80961
2334.07	1.796
2335.01	0.825688
2335.94	0.822139
2336.87	1.77747
2337.8	-0.151959
2338.73	-1.11659
2339.66	1.7601
2340.59	7.50471
2341.52	1.72156
2342.45	5.54492
2343.38	-1.16989
2344.31	0.745296
2345.24	0.733222
2346.17	-1.19284
2347.1	2.63034
2348.02	0.716532
2348.95	-0.253957
2349.88	0.66623
2350.81	0.685106
2351.74	-2.211
2352.67	-3.19191
2353.59	-0.338215
2354.52	-3.1944
2355.45	1.5609
2356.38	-2.26889
2357.3	-1.33003
2358.23	-0.390372
2359.16	-1.34849
2359.85	-1.3591