File: Data/3-Raman/processed/bu22-D-scz1-FI01-v.txt
#Acq. time (s)=	15
#Accumulations=	3
#Range (cm-¹)=	100...4000
#Windows=	1
#Auto scanning=	Off
#Autofocus=	Off
#Macrospot=	Off
#AutoExposure=	Off
#Spike filter=	Multiple accum.
#Delay time (s)=	0
#Binning=	1
#Readout mode=	Signal
#DeNoise=	Lite
#ICS correction=	Off
#Dark correction=	Off
#Inst. Process=	Off
#Detector temperature (°C)=	-60.09
#Instrument=	LabRAM HR Evol
#Detector=	SIN-EM FIVIS
#Objective=	x100_VIS
#Grating=	150 (500nm)
#ND Filter=	100%
#Laser=	532nm_Edge
#Hole=	30.0125
#Temperature=	0
#Range=	Visible
#StageXY=	75x50mm Scan+
#StageZ=	Z motor
#X (µm)=	18747.1
#Y (µm)=	2709.2
#Z (µm)=	1897.2
#Full time(s)=	52
#Project=	Buranga
#Sample=	BU18FA20_G
#Site=	G_trl1
#Title=	22-D_scz1_FI01
#Remark=
#Date=	30.07.2019 19:30
#Acquired=	30.07.2019 19:30:00
#Data Range:Extract=	16.12.2021 15:29:10
#Base:Fit=	16.12.2021 15:29:21
#Base:Edit=	16.12.2021 15:30:13
#Base:Edit=	16.12.2021 15:30:14
#Base:Edit=	16.12.2021 15:30:14
#Base:Edit=	16.12.2021 15:30:15
#Base:Sub=	16.12.2021 15:30:16
103.656	379.628
108.278	126.297
112.899	55.2285
117.517	1.08044
122.131	13.979
126.744	17.0283
131.355	23.7936
135.964	36.264
140.571	53.8615
145.173	73.9709
149.776	56.2494
154.375	47.2235
158.973	59.0847
163.566	99.9497
168.159	140.608
172.75	228.736
177.339	413.706
181.923	948.646
186.507	1442.05
191.089	1454.13
195.668	837.893
200.243	324.092
204.818	192.153
209.391	104.397
213.96	47.8697
218.528	26.2233
223.094	21.5399
227.655	56.4324
232.217	114.959
236.776	249.62
241.331	469.664
245.886	614.266
250.439	447.779
254.987	233.242
259.535	164.509
264.081	255.581
268.622	335.463
273.164	348.61
277.703	211.366
282.238	88.3968
286.773	24.6171
291.305	-3.06451
295.833	-0.582275
300.362	26.5616
304.885	68.0722
309.409	127.729
313.93	204.507
318.448	288.019
322.965	403.24
327.477	522.073
331.99	719.667
336.5	891.241
341.007	796.429
345.513	625.666
350.014	513.957
354.516	421.097
359.013	422.739
363.51	483.021
368.005	547.368
372.496	560.006
376.987	480.534
381.473	343.182
385.96	231.227
390.442	175.386
394.923	350.873
399.401	764.284
403.879	1149.63
408.352	1012.9
412.825	462.722
417.294	248.234
421.763	156.347
426.227	141.256
430.692	130.519
435.152	128.38
439.612	133.626
444.068	145.338
448.524	161.257
452.976	182.639
457.427	209.058
461.874	234.385
466.32	287.504
470.765	319.366
475.205	262.003
479.646	187.178
484.083	115.503
488.519	95.1192
492.951	117.876
497.381	156.218
501.811	197.917
506.237	229.255
510.663	253.195
515.084	268.056
519.504	275.248
523.923	269.71
528.338	256.015
532.753	231.959
537.164	206.511
541.572	184.25
545.981	174.599
550.385	168.258
554.788	176.97
559.19	195.378
563.588	210
567.986	225.776
572.38	240.473
576.771	238.826
581.163	237.034
585.551	286.779
589.936	357.144
594.319	475.867
598.702	542.191
603.081	594.448
607.458	565.25
611.835	516.308
616.208	544.452
620.578	634.562
624.949	821.01
629.315	878.214
633.68	798.736
638.042	558.604
642.404	377.558
646.762	247.932
651.118	182.516
655.472	141.949
659.825	107.893
664.175	77.0452
668.523	50.0339
672.868	29.0698
677.213	15.0182
681.555	7.92789
685.894	7.46475
690.231	12.9334
694.566	20.6496
698.901	33.9204
703.232	48.6307
707.561	69.6263
711.888	89.6615
716.212	107.913
720.537	124.194
724.858	140.171
729.176	152.421
733.493	162.834
737.807	170.274
742.119	171.891
746.432	168.869
750.74	160.638
755.046	148.503
759.35	133.991
763.652	119.458
767.952	105.713
772.25	94.4454
776.546	86.437
780.842	81.6906
785.133	74.4759
789.423	68.4746
793.711	62.7055
797.997	57.7721
802.28	54.2348
806.562	51.5245
810.841	49.2385
815.119	47.5072
819.394	45.4608
823.668	43.2116
827.941	40.0825
832.211	35.9204
836.478	31.5162
840.743	26.4603
845.006	21.1915
849.268	16.4901
853.527	8.52176
857.784	9.54382
862.039	12.943
866.293	13.3512
870.544	11.8666
874.793	8.42184
879.04	4.64194
883.285	0.305603
887.528	-3.80945
891.769	-6.84213
896.008	-7.77963
900.246	-6.33841
904.481	-4.29242
908.714	-3.2746
912.945	-3.48563
917.174	-4.33835
921.401	-2.72235
925.626	0.376007
929.849	1.11749
934.068	7.41974
938.287	15.8213
942.504	23.461
946.72	29.3143
950.933	37.2454
955.144	49.3457
959.353	62.4855
963.56	78.5656
967.765	103.948
971.968	137.34
976.17	178.929
980.367	227.487
984.564	283.953
988.759	336.109
992.953	387.876
997.144	453.109
1001.33	569.667
1005.52	650.864
1009.71	651.961
1013.89	554.795
1018.07	464.081
1022.25	477.14
1026.43	601.002
1030.6	833.664
1034.78	1389.87
1038.94	2423.2
1043.11	3308.53
1047.28	3256.85
1051.45	2329.15
1055.61	1325.45
1059.77	816.739
1063.93	604.655
1068.09	528.291
1072.25	562.155
1076.4	656.81
1080.55	845.058
1084.7	968.299
1088.85	1063.53
1092.99	904.358
1097.14	727.266
1101.28	587.109
1105.42	487.72
1109.56	444.201
1113.69	467.168
1117.83	544.34
1121.96	663.115
1126.09	844.438
1130.22	971.528
1134.35	935.157
1138.47	702.154
1142.59	550.005
1146.71	442.807
1150.83	361.373
1154.95	308.722
1159.06	270.068
1163.18	239.787
1167.29	218.618
1171.4	202.051
1175.5	189.032
1179.61	177.702
1183.71	171.227
1187.81	165.575
1191.91	164.024
1196.01	163.908
1200.1	161.398
1204.2	156.102
1208.29	145.525
1212.38	129.596
1216.47	111.36
1220.55	90.6854
1224.64	72.8329
1228.72	57.3096
1232.8	44.3448
1236.88	34.3291
1240.95	27.3416
1245.03	27.939
1249.1	29.8531
1253.17	33.5958
1257.24	43.6929
1261.31	58.997
1265.37	66.0201
1269.44	50.9923
1273.5	63.9946
1277.56	243.043
1281.61	440.795
1285.67	267.955
1289.72	59.2793
1293.77	32.6795
1297.83	18.6515
1301.87	14.9534
1305.92	13.8347
1309.96	14.33
1314.01	15.9841
1318.05	18.0112
1322.09	19.6683
1326.12	21.6136
1330.16	22.2883
1334.19	22.6987
1338.22	20.7508
1342.25	19.5724
1346.28	19.6192
1350.3	19.2646
1354.33	20.9944
1358.35	20.4401
1362.37	27.3694
1366.39	47.0749
1370.4	62.5783
1374.42	80.2864
1378.43	169.243
1382.44	546.044
1386.45	666.321
1390.46	268.604
1394.46	61.8928
1398.46	61.1881
1402.47	91.606
1406.46	96.7968
1410.46	69.5489
1414.46	47.8923
1418.45	31.5341
1422.45	24.5753
1426.43	23.4942
1430.42	23.8774
1434.41	24.1386
1438.39	23.3231
1442.38	23.3287
1446.36	19.4713
1450.34	13.5593
1454.31	10.4565
1458.29	13.5471
1462.27	20.8536
1466.24	24.6303
1470.21	24.6789
1474.18	24.3362
1478.14	23.9185
1482.11	23.1125
1486.07	23.0125
1490.03	22.8165
1493.99	22.5069
1497.95	21.8834
1501.9	20.9524
1505.86	19.1775
1509.81	16.7442
1513.76	17.1265
1517.71	16.8717
1521.65	17.213
1525.6	19.0536
1529.54	22.8188
1533.48	23.7818
1537.42	26.2046
1541.36	25.8516
1545.29	24.5944
1549.23	24.0941
1553.16	24.8543
1557.09	24.1
1561.02	24.091
1564.94	23.2161
1568.87	22.0473
1572.79	20.3484
1576.71	19.1152
1580.63	16.3367
1584.55	15.012
1588.47	13.8627
1592.38	12.7332
1596.29	11.5752
1600.2	10.8431
1604.11	12.9515
1608.02	16.4955
1611.92	18.4683
1615.83	24.1553
1619.73	26.2368
1623.63	28.6718
1627.53	30.3205
1631.42	31.6851
1635.32	29.867
1639.21	26.2586
1643.1	21.9832
1646.99	29.6314
1650.88	27.4995
1654.76	28.3175
1658.64	29.9354
1662.53	32.255
1666.41	33.5726
1670.28	31.4078
1674.16	28.9316
1678.04	25.9274
1681.91	22.5541
1685.78	19.3765
1689.65	16.6006
1693.52	14.3967
1697.38	12.6719
1701.25	11.2689
1705.11	10.2614
1708.97	9.80331
1712.83	10.0047
1716.69	10.0865
1720.54	9.0545
1724.4	8.63113
1728.25	9.2742
1732.1	11.3567
1735.95	11.2766
1739.79	13.791
1743.64	13.2947
1747.48	10.1031
1751.33	5.33148
1755.17	2.06949
1759	4.0506
1762.84	7.81165
1766.68	10.7031
1770.51	11.7384
1774.34	10.5343
1778.17	8.21207
1782	4.7449
1785.82	1.879
1789.65	-0.948425
1793.47	-1.92123
1797.29	-1.64059
1801.11	-1.50156
1804.93	-1.11795
1808.74	-0.752594
1812.56	-1.29434
1816.37	-1.90933
1820.18	-3.51849
1823.99	-4.53503
1827.79	-4.35367
1831.6	-3.68509
1835.4	-1.0892
1839.2	2.29495
1843	3.47668
1846.8	6.32751
1850.6	4.15137
1854.39	2.46265
1858.19	1.44275
1861.98	1.0708
1865.77	1.85272
1869.56	3.48166
1873.34	5.41745
1877.13	7.35303
1880.91	7.18561
1884.69	2.81375
1888.47	0.755157
1892.25	0.123505
1896.03	2.41882
1899.8	0.615936
1903.57	1.42795
1907.34	2.99908
1911.11	5.14909
1914.88	4.57605
1918.65	1.30086
1922.41	-0.786728
1926.18	-4.09879
1929.94	-3.25598
1933.7	-2.29875
1937.45	-1.07288
1941.21	0.355392
1944.96	1.72005
1948.72	2.96939
1952.47	4.17416
1956.22	5.3681
1959.96	5.71873
1963.71	1.9962
1967.45	1.21828
1971.2	3.23878
1974.94	5.28914
1978.68	4.71935
1982.42	4.48415
1986.15	4.66304
1989.89	5.33794
1993.62	6.55635
1997.35	8.55788
2001.08	10.78
2004.8	13.262
2008.53	16.4195
2012.25	17.3067
2015.98	16.3194
2019.7	13.5636
2023.42	12.0922
2027.13	13.3659
2030.85	15.9838
2034.56	18.1889
2038.28	20.4386
2041.99	22.4503
2045.7	21.4092
2049.41	19.6991
2053.11	16.3149
2056.82	13.8666
2060.52	13.3694
2064.22	13.9834
2067.92	13.862
2071.62	13.7299
2075.31	12.6305
2079.01	12.9048
2082.7	14.5901
2086.39	16.4745
2090.08	18.4203
2093.77	20.433
2097.45	23.4104
2101.14	25.5599
2104.82	25.6985
2108.5	24.8873
2112.18	24.0083
2115.86	23.9459
2119.54	24.6301
2123.21	28.1143
2126.88	30.7208
2130.56	33.5719
2134.23	34.8611
2137.89	36.1112
2141.56	35.1626
2145.23	33.3028
2148.89	31.6435
2152.55	29.643
2156.21	29.1898
2159.87	30.9955
2163.53	30.2765
2167.18	34.7933
2170.84	38.9866
2174.49	43.3524
2178.14	45.8929
2181.79	44.1918
2185.44	37.8607
2189.08	20.681
2192.73	39.5901
2196.37	43.0841
2200.01	43.0111
2203.65	39.9986
2207.29	37.4388
2210.92	33.9158
2214.56	27.4023
2218.19	23.0273
2221.82	24.7523
2225.45	25.8239
2229.08	28.1101
2232.7	31.8865
2236.33	36.4554
2239.95	36.1212
2243.57	36.2907
2247.19	37.3372
2250.81	37.6058
2254.43	38.351
2258.04	36.7568
2261.66	34.8359
2265.27	32.8136
2268.88	30.8129
2272.49	29.7677
2276.1	29.546
2279.7	29.571
2283.31	29.5926
2286.91	29.5895
2290.51	28.8026
2294.11	27.4441
2297.71	24.4023
2301.3	19.3707
2304.9	14.7077
2308.49	7.5952
2312.08	9.52281
2315.67	17.4674
2319.26	31.4395
2322.85	54.1511
2326.43	59.2142
2330.02	55.4288
2333.6	35.6403
2337.18	22.9554
2340.76	16.9221
2344.34	11.7132
2347.91	9.97246
2351.49	10.6538
2355.06	13.2656
2358.63	15.1638
2362.2	16.9754
2365.77	17.8878
2369.33	18.179
2372.9	18.7558
2376.46	19.6667
2380.02	20.6113
2383.58	20.0789
2387.14	17.9253
2390.7	15.7542
2394.25	14.5943
2397.81	13.7756
2401.36	11.8593
2404.91	10.0068
2408.46	8.67592
2412.01	7.80592
2415.56	7.31163
2419.1	6.98157
2422.64	6.51135
2426.18	6.17455
2429.72	6.02989
2433.26	5.58186
2436.8	4.92542
2440.34	4.47174
2443.87	4.2381
2447.4	4.11253
2450.93	4.09114
2454.46	4.28934
2457.99	3.98001
2461.52	4.26605
2465.04	3.65576
2468.56	3.97258
2472.09	5.14815
2475.61	7.71126
2479.13	8.96233
2482.64	9.34378
2486.16	8.696
2489.67	6.7822
2493.18	7.15079
2496.69	7.49065
2500.2	7.18716
2503.71	6.18636
2507.22	5.68062
2510.72	5.47543
2514.23	5.80779
2517.73	6.21672
2521.23	6.60518
2524.73	6.89713
2528.23	6.81273
2531.72	6.55692
2535.21	7.30496
2538.71	8.56413
2542.2	9.49622
2545.69	10.0615
2549.18	10.317
2552.66	10.9843
2556.15	11.8964
2559.63	11.2533
2563.12	11.0955
2566.6	11.3215
2570.08	10.7088
2573.55	8.4771
2577.03	6.04547
2580.5	3.6958
2583.98	1.39006
2587.45	-0.457626
2590.92	-1.84291
2594.39	-2.52112
2597.86	-0.562988
2601.32	1.64629
2604.79	2.85883
2608.25	4.62781
2611.71	4.20987
2615.17	2.84016
2618.63	0.68103
2622.08	-2.0791
2625.54	-4.92467
2628.99	-6.95177
2632.45	-7.7787
2635.9	-7.4449
2639.35	-6.36574
2642.79	-4.98306
2646.24	-3.57176
2649.69	-2.13147
2653.13	-0.575104
2656.57	1.04434
2660.01	2.81317
2663.45	4.64745
2666.89	5.50392
2670.32	5.33559
2673.76	4.55995
2677.19	4.79121
2680.62	3.63797
2684.05	1.71405
2687.48	-0.418762
2690.91	-2.78343
2694.33	-4.61522
2697.76	-4.95857
2701.18	0.999603
2704.6	4.69142
2708.02	3.48288
2711.44	0.919342
2714.86	-1.35191
2718.27	-1.46419
2721.69	-1.3723
2725.1	-2.43983
2728.51	-4.58878
2731.92	-4.65253
2735.33	-3.97058
2738.74	-4.46854
2742.14	-6.12949
2745.55	-6.36397
2748.95	-5.51178
2752.35	-3.99606
2755.75	-3.16399
2759.15	-3.00006
2762.54	-3.60541
2765.94	-4.12198
2769.33	-5.78166
2772.72	-6.86021
2776.12	-7.19077
2779.51	-7.84833
2782.89	-7.90425
2786.28	-7.33504
2789.67	-6.36734
2793.05	-5.8154
2796.43	-4.93115
2799.81	-2.91586
2803.19	-2.09189
2806.57	-2.46928
2809.95	-3.99786
2813.32	-4.21301
2816.69	-3.97984
2820.06	-3.586
2823.44	-3.20961
2826.81	-2.61763
2830.17	-1.49965
2833.54	-0.00874329
2836.9	0.910019
2840.27	1.21959
2843.63	-0.0351257
2846.99	-2.29987
2850.35	-5.85033
2853.71	-9.54214
2857.06	-12.6973
2860.42	-15.1367
2863.77	-15.516
2867.12	-13.8074
2870.48	-12.4397
2873.83	-5.98282
2877.17	-5.09473
2880.52	-5.41789
2883.86	-8.10919
2887.21	-7.35742
2890.55	-5.59978
2893.89	-3.65288
2897.23	-3.11674
2900.57	-5.52428
2903.91	-7.24536
2907.24	-6.64807
2910.57	-6.28909
2913.91	-5.14732
2917.24	-4.34251
2920.57	-3.69434
2923.9	-4.27769
2927.22	-5.29677
2930.55	-6.20758
2933.87	-6.89571
2937.19	-7.42711
2940.51	-8.24612
2943.83	-9.02802
2947.15	-8.38533
2950.47	-7.24908
2953.79	-5.80338
2957.1	-4.4124
2960.41	-3.04857
2963.72	-1.82036
2967.03	-0.540939
2970.34	-0.0629272
2973.65	-0.00315857
2976.95	-0.293274
2980.26	-0.743637
2983.56	-1.08601
2986.86	-1.3961
2990.16	-1.27145
2993.46	-0.700958
2996.76	0.0699158
3000.06	1.65305
3003.35	3.52788
3006.64	5.15962
3009.94	3.1432
3013.23	1.32776
3016.51	2.26897
3019.8	4.44122
3023.09	7.70273
3026.38	9.97787
3029.66	11.7642
3032.94	13.0979
3036.22	13.7763
3039.5	13.6548
3042.78	12.7194
3046.05	11.1168
3049.33	9.13373
3052.6	5.49867
3055.88	5.55397
3059.15	6.90424
3062.42	9.67616
3065.69	12.3844
3068.95	16.4574
3072.22	19.7186
3075.48	20.8962
3078.75	21.1613
3082.01	21.3739
3085.27	22.0352
3088.53	23.1168
3091.79	24.6047
3095.04	26.4696
3098.3	28.7207
3101.55	33.4787
3104.8	34.1938
3108.05	34.7062
3111.3	36.0441
3114.55	42.6869
3117.8	42.8686
3121.04	43.1714
3124.29	42.7124
3127.53	41.9574
3130.77	42.332
3134.01	44.943
3137.25	48.0376
3140.49	51.3925
3143.72	54.172
3146.96	55.5803
3150.19	57.7428
3153.42	60.8279
3156.65	65.4013
3159.88	70.2898
3163.11	74.3353
3166.34	77.9131
3169.56	81.0504
3172.79	83.9777
3176.01	88.3974
3179.23	92.0509
3182.45	95.319
3185.67	101.916
3188.88	108.506
3192.1	114.796
3195.31	120.322
3198.53	124.694
3201.74	127.559
3204.95	129.93
3208.16	132.256
3211.37	133.604
3214.57	136.573
3217.78	140.266
3220.98	143.161
3224.18	146.173
3227.39	149.976
3230.59	152.841
3233.78	155.371
3236.98	158.035
3240.18	160.927
3243.37	162.997
3246.56	165.703
3249.76	168.678
3252.95	172.472
3256.14	176.553
3259.32	181.474
3262.51	186.399
3265.7	190.07
3268.88	195.205
3272.06	201.242
3275.24	205.132
3278.42	206.239
3281.6	204.883
3284.78	203.534
3287.96	206.421
3291.13	209.605
3294.31	214.179
3297.48	220.025
3300.65	225.507
3303.82	231.994
3306.99	235.828
3310.15	236.607
3313.32	238.048
3316.48	239.371
3319.65	241.86
3322.81	245.634
3325.97	251.852
3329.13	261.54
3332.28	274.547
3335.44	288.407
3338.6	293.32
3341.75	298.182
3344.9	335.229
3348.05	363.652
3351.2	424.753
3354.35	514.237
3357.5	637.3
3360.65	802.182
3363.79	995.767
3366.94	1121.74
3370.08	1211.76
3373.22	1105.11
3376.36	973.761
3379.5	817.76
3382.63	743.78
3385.77	662.305
3388.9	605.112
3392.04	554.436
3395.17	512.61
3398.3	476.045
3401.43	446.512
3404.56	422.629
3407.69	403.687
3410.81	392.347
3413.94	384.979
3417.06	387.459
3420.18	392.988
3423.3	399.034
3426.42	404.469
3429.54	408.358
3432.65	409.904
3435.77	412.58
3438.88	413.346
3442	412.577
3445.11	411.134
3448.22	410.85
3451.33	406.481
3454.43	402.295
3457.54	399.256
3460.65	391.775
3463.75	384.235
3466.85	373.723
3469.95	367.766
3473.05	363.117
3476.15	358.832
3479.25	355.221
3482.35	351.68
3485.44	341.971
3488.54	333.048
3491.63	329.812
3494.72	330.355
3497.81	331.286
3500.9	329.733
3503.99	325.402
3507.07	317.921
3510.16	308.5
3513.24	297.683
3516.32	287.646
3519.41	277.311
3522.49	268.752
3525.56	264.091
3528.64	259.14
3531.72	252.67
3534.79	246.65
3537.87	241.151
3540.94	236.254
3544.01	230.549
3547.08	222.043
3550.15	212.798
3553.22	202.647
3556.28	194.951
3559.35	189.009
3562.41	183.49
3565.47	178.307
3568.54	173.475
3571.6	166.382
3574.65	160.608
3577.71	154.737
3580.77	149.051
3583.82	144.261
3586.88	145.454
3589.93	142.016
3592.98	131.829
3596.03	119.491
3599.08	111.033
3602.13	107.026
3605.18	104.319
3608.22	104.083
3611.27	102.957
3614.31	100.953
3617.35	99.1967
3620.39	94.7755
3623.43	88.671
3626.47	81.7087
3629.5	75.955
3632.54	70.0143
3635.57	67.8055
3638.61	68.0424
3641.64	69.4544
3644.67	65.2922
3647.7	55.9808
3650.73	46.6376
3653.75	35.9891
3656.78	32.9895
3659.8	30.3133
3662.83	28.6364
3665.85	25.7425
3668.87	21.7191
3671.89	17.3211
3674.91	15.5001
3677.92	10.3139
3680.94	6.87283
3683.96	3.25928
3686.97	0.222916
3689.98	-2.8586
3692.99	-6.08388
3696	-8.34113
3699.01	-9.80896
3702.02	-10.8023
3705.02	-13.1163
3708.03	-13.3252
3711.03	-12.5571
3714.03	-12.2835
3717.04	-14.0947
3720.04	-19.1051
3723.04	-25.6356
3726.03	-21.4378
3729.03	-18.5867
3732.03	-19.8008
3735.02	-21.3237
3738.01	-22.5532
3741	-23.3347
3743.99	-23.5982
3746.98	-23.6639
3749.97	-23.4257
3752.96	-22.9969
3755.95	-22.65
3758.93	-21.9967
3761.91	-21.3173
3764.9	-20.795
3767.88	-20.3737
3770.86	-20.1725
3773.84	-20.0481
3776.81	-19.9867
3779.79	-20.1431
3782.77	-20.448
3785.74	-20.9313
3788.71	-20.8904
3791.68	-20.2995
3794.65	-19.6929
3797.62	-18.4846
3800.59	-16.702
3803.56	-12.8354
3806.52	-11.314
3809.49	-11.4515
3812.45	-12.9554
3815.41	-13.0413
3818.37	-13.4698
3821.33	-13.313
3824.29	-12.4515
3827.25	-11.3628
3830.21	-11.117
3833.16	-10.9418
3836.11	-10.6666
3839.07	-10.3828
3842.02	-9.77762
3844.97	-8.58504
3847.92	-6.95664
3850.87	-6.52116
3853.81	-5.86888
3856.76	-4.98907
3859.7	-5.62659
3862.65	-5.78219
3865.59	-5.32882
3868.53	-4.38346
3871.47	-3.8215
3874.41	-3.81298
3877.34	-3.59257
3880.28	-3.33147
3883.22	-2.96425
3886.15	-2.32653
3889.08	-1.745
3892.01	-0.795525
3894.94	-0.118256
3897.87	0.173203
3900.8	0.500549
3903.73	0.332977
3906.65	1.12719
3909.58	2.61917
3912.5	4.25238
3915.42	6.2021
3918.35	6.4119
3921.27	5.65919
3924.18	4.29665
3927.1	3.50713
3930.02	2.6254
3932.93	2.06963
3935.85	1.29647
3938.76	3.24318
3941.67	4.54793
3944.58	5.02045
3947.49	4.12115
3950.4	3.85771
3953.31	3.35041
3956.22	4.70121
3959.12	4.79488
3962.02	4.06512
3964.93	3.59775
3967.83	3.059
3970.73	2.05137
3973.63	2.18156
3976.53	2.26688
3979.42	1.6832
3982.32	2.65673
3985.21	4.28024
3988.11	3.81192
3991	3.60571
3993.89	3.02475
3996.78	2.31316
3999.67	-10.3016