File: Data/3-Raman/processed/bu22-D-scz1-FI03-v.txt
#Acq. time (s)=	15
#Accumulations=	3
#Range (cm-¹)=	100...4000
#Windows=	1
#Auto scanning=	Off
#Autofocus=	Off
#Macrospot=	Off
#AutoExposure=	Off
#Spike filter=	Multiple accum.
#Delay time (s)=	0
#Binning=	1
#Readout mode=	Signal
#DeNoise=	Lite
#ICS correction=	Off
#Dark correction=	Off
#Inst. Process=	Off
#Detector temperature (°C)=	-60.09
#Instrument=	LabRAM HR Evol
#Detector=	SIN-EM FIVIS
#Objective=	x100_VIS
#Grating=	150 (500nm)
#ND Filter=	100%
#Laser=	532nm_Edge
#Hole=	30.0125
#Temperature=	0
#Range=	Visible
#StageXY=	75x50mm Scan+
#StageZ=	Z motor
#X (µm)=	18848
#Y (µm)=	2650
#Z (µm)=	1910.1
#Full time(s)=	47
#Project=	Buranga
#Sample=	BU18FA20_G
#Site=	G_trl1
#Title=	22-D_scz1_FI03
#Remark=
#Date=	30.07.2019 19:24
#Acquired=	30.07.2019 19:24:32
#Data Range:Extract=	16.12.2021 15:29:10
#Base:Fit=	16.12.2021 15:29:21
#Base:Edit=	16.12.2021 15:29:57
#Base:Edit=	16.12.2021 15:29:59
#Base:Edit=	16.12.2021 15:30:00
#Base:Edit=	16.12.2021 15:30:00
#Base:Edit=	16.12.2021 15:30:02
#Base:Sub=	16.12.2021 15:30:05
103.656	2641.6
108.278	1845.02
112.899	1396.02
117.517	1145.28
122.131	966.662
126.744	852.311
131.355	776.875
135.964	710.016
140.571	646.769
145.173	597.483
149.776	518.752
154.375	461.469
158.973	450.31
163.566	475.209
168.159	474.264
172.75	587.102
177.339	1022.12
181.923	1824.19
186.507	2490.44
191.089	2256.32
195.668	1247.08
200.243	555.155
204.818	280.073
209.391	184.053
213.96	98.8513
218.528	57.5341
223.094	54.8597
227.655	90.2848
232.217	197.408
236.776	466.185
241.331	840.619
245.886	902.652
250.439	687.075
254.987	332.679
259.535	214.361
264.081	347.075
268.622	466.381
273.164	451.619
277.703	312.163
282.238	124.448
286.773	31.0808
291.305	-4.1167
295.833	9.02539
300.362	63.7245
304.885	145.468
309.409	254.462
313.93	384.998
318.448	509.866
322.965	683.483
327.477	952.383
331.99	1238.03
336.5	1463.13
341.007	1373.83
345.513	1093.55
350.014	825.815
354.516	708.348
359.013	700.249
363.51	833.32
368.005	903.559
372.496	934.818
376.987	712.712
381.473	519.593
385.96	398.285
390.442	344.871
394.923	625.497
399.401	1177.82
403.879	1426.06
408.352	1148.21
412.825	551.925
417.294	252.67
421.763	226.442
426.227	206.106
430.692	190.56
435.152	184.611
439.612	187.125
444.068	199.184
448.524	220.206
452.976	250.606
457.427	290.886
461.874	329.783
466.32	398.213
470.765	479.623
475.205	440.285
479.646	293.541
484.083	185.672
488.519	151.071
492.951	218.844
497.381	307.544
501.811	382.491
506.237	446.169
510.663	510.554
515.084	536.475
519.504	523.53
523.923	495.108
528.338	449.245
532.753	400.04
537.164	356.118
541.572	326.951
545.981	314.68
550.385	313.286
554.788	320.809
559.19	338.228
563.588	363.338
567.986	388.14
572.38	408.175
576.771	393.364
581.163	408.455
585.551	480.702
589.936	635.264
594.319	859.514
598.702	974.453
603.081	1018.09
607.458	974.884
611.835	963.795
616.208	1004.33
620.578	1186.45
624.949	1417.65
629.315	1533.73
633.68	1322.3
638.042	908.407
642.404	625.43
646.762	450.21
651.118	344.102
655.472	258.368
659.825	190.814
664.175	133.771
668.523	89.6148
672.868	57.8512
677.213	38.5226
681.555	28.7482
685.894	31.1478
690.231	44.4893
694.566	67.8875
698.901	96.4716
703.232	126.307
707.561	155.612
711.888	183.828
716.212	210.445
720.537	234.978
724.858	257.952
729.176	278.71
733.493	302.667
737.807	321.025
742.119	328.704
746.432	321.47
750.74	295.744
755.046	252.672
759.35	216.118
763.652	194.08
767.952	176.978
772.25	161.723
776.546	148.183
780.842	130.97
785.133	116.195
789.423	103.876
793.711	94.0607
797.997	86.6122
802.28	81.0699
806.562	76.6411
810.841	73.7054
815.119	70.1537
819.394	65.9151
823.668	61.6059
827.941	56.2437
832.211	50.9663
836.478	46.0435
840.743	41.7048
845.006	37.6149
849.268	33.4951
853.527	27.858
857.784	16.5626
862.039	11.5721
866.293	8.62024
870.544	6.33307
874.793	2.44727
879.04	-3.89178
883.285	-5.60297
887.528	-4.75238
891.769	-3.11749
896.008	-1.91431
900.246	-1.13867
904.481	-0.896301
908.714	-1.96204
912.945	-2.63312
917.174	-2.32068
921.401	-0.64032
925.626	-0.00469971
929.849	0.807556
934.068	3.80347
938.287	9.27588
942.504	18.7931
946.72	29.79
950.933	44.0048
955.144	63.5035
959.353	85.522
963.56	110.457
967.765	170.562
971.968	234.512
976.17	306.826
980.367	388.421
984.564	478.475
988.759	577.816
992.953	666.371
997.144	771.365
1001.33	904.591
1005.52	1003.7
1009.71	986.666
1013.89	888.913
1018.07	785.48
1022.25	830.546
1026.43	965.404
1030.6	1436.51
1034.78	2483.75
1038.94	4183.96
1043.11	5383.17
1047.28	4858.36
1051.45	3379.53
1055.61	2068.69
1059.77	1253.84
1063.93	913.979
1068.09	896.969
1072.25	965.428
1076.4	1130.4
1080.55	1356.4
1084.7	1624.63
1088.85	1728.5
1092.99	1471.83
1097.14	1187.53
1101.28	958.363
1105.42	834.855
1109.56	811.1
1113.69	846.731
1117.83	945.202
1121.96	1102.83
1126.09	1329.17
1130.22	1488.93
1134.35	1308.76
1138.47	1096.94
1142.59	907.847
1146.71	769.772
1150.83	645.835
1154.95	550.081
1159.06	476.769
1163.18	430.03
1167.29	397.858
1171.4	372.47
1175.5	347.818
1179.61	327.479
1183.71	311.796
1187.81	298.002
1191.91	299.186
1196.01	300.238
1200.1	307.198
1204.2	297.943
1208.29	278.408
1212.38	251.577
1216.47	214.922
1220.55	177.218
1224.64	142.452
1228.72	113.746
1232.8	94.5359
1236.88	86.1901
1240.95	86.1909
1245.03	91.3853
1249.1	118.877
1253.17	188.429
1257.24	300.839
1261.31	355.496
1265.37	298.105
1269.44	186.924
1273.5	662.717
1277.56	1900.89
1281.61	2145.08
1285.67	1273.28
1289.72	254.235
1293.77	147.102
1297.83	108.059
1301.87	84.0658
1305.92	67.9528
1309.96	62.3368
1314.01	66.8271
1318.05	74.614
1322.09	80.7438
1326.12	83.3148
1330.16	85.382
1334.19	87.3538
1338.22	83.7213
1342.25	83.0914
1346.28	82.3939
1350.3	87.894
1354.33	105.245
1358.35	126.51
1362.37	167.813
1366.39	207.316
1370.4	258.11
1374.42	371.962
1378.43	1706.55
1382.44	3488.09
1386.45	3334.65
1390.46	1201.22
1394.46	308.806
1398.46	313.41
1402.47	557.031
1406.46	566.669
1410.46	356.262
1414.46	214.698
1418.45	153.432
1422.45	123.1
1426.43	99.353
1430.42	77.8823
1434.41	64.4327
1438.39	53.0975
1442.38	44.5732
1446.36	38.4941
1450.34	34.5805
1454.31	32.8834
1458.29	33.2659
1462.27	36.0168
1466.24	37.5828
1470.21	36.2606
1474.18	32.7463
1478.14	27.6855
1482.11	25.1323
1486.07	24.5358
1490.03	24.2023
1493.99	24.1691
1497.95	24.7932
1501.9	24.5821
1505.86	24.1716
1509.81	23.2368
1513.76	21.075
1517.71	20.123
1521.65	19.9725
1525.6	22.5806
1529.54	22.2739
1533.48	20.3539
1537.42	13.9807
1541.36	10.4011
1545.29	9.93109
1549.23	13.5757
1553.16	16.4915
1557.09	21.2152
1561.02	23.0757
1564.94	21.8459
1568.87	17.5862
1572.79	12.159
1576.71	7.2301
1580.63	3.7179
1584.55	2.71918
1588.47	5.73975
1592.38	10.3018
1596.29	14.541
1600.2	17.4753
1604.11	18.5666
1608.02	19.2714
1611.92	20.2035
1615.83	21.6301
1619.73	22.8744
1623.63	24.1427
1627.53	25.0729
1631.42	25.9099
1635.32	26.4647
1639.21	28.1364
1643.1	30.8177
1646.99	32.6435
1650.88	33.3645
1654.76	32.4081
1658.64	30.5751
1662.53	28.4567
1666.41	25.7337
1670.28	21.5208
1674.16	15.5769
1678.04	9.80472
1681.91	4.6058
1685.78	0.932373
1689.65	-1.2991
1693.52	0.634491
1697.38	1.85699
1701.25	3.74216
1705.11	6.08673
1708.97	7.13007
1712.83	8.70557
1716.69	8.65295
1720.54	6.93362
1724.4	5.6889
1728.25	4.95209
1732.1	5.24939
1735.95	5.90002
1739.79	6.56842
1743.64	7.13538
1747.48	7.57361
1751.33	7.68359
1755.17	8.13809
1759	9.34756
1762.84	10.1595
1766.68	10.1934
1770.51	8.98917
1774.34	6.58542
1778.17	0.842987
1782	-2.29294
1785.82	-5.56253
1789.65	-7.2995
1793.47	-10.2278
1797.29	-6.53687
1801.11	-3.50201
1804.93	-2.45401
1808.74	-4.35379
1812.56	-14.3431
1816.37	-9.00476
1820.18	-3.20154
1823.99	-2.89081
1827.79	-4.89655
1831.6	-6.56345
1835.4	-7.66165
1839.2	-7.10504
1843	-5.1087
1846.8	-1.87933
1850.6	-6.78842
1854.39	17.3368
1858.19	15.0188
1861.98	1.98294
1865.77	-8.57434
1869.56	-4.58594
1873.34	2.74466
1877.13	6.3248
1880.91	6.63882
1884.69	0.828888
1888.47	-6.28351
1892.25	3.55853
1896.03	17.3788
1899.8	28.7091
1903.57	12.6663
1907.34	-8.73041
1911.11	0.328674
1914.88	5.69177
1918.65	6.72845
1922.41	6.80054
1926.18	5.83359
1929.94	4.69632
1933.7	5.22037
1937.45	5.61005
1941.21	4.74457
1944.96	2.24167
1948.72	-1.60611
1952.47	-6.01645
1956.22	-7.54279
1959.96	-8.75525
1963.71	-8.75278
1967.45	-6.18222
1971.2	-0.727509
1974.94	9.92221
1978.68	16.8801
1982.42	19.9514
1986.15	12.7227
1989.89	5.82343
1993.62	-5.17502
1997.35	7.76563
2001.08	17.141
2004.8	23.2549
2008.53	26.2104
2012.25	25.9889
2015.98	23.5511
2019.7	22.1356
2023.42	20.4627
2027.13	18.3673
2030.85	10.6093
2034.56	16.826
2038.28	27.4603
2041.99	34.4009
2045.7	38.0701
2049.41	39.1407
2053.11	39.3079
2056.82	39.577
2060.52	40.0575
2064.22	40.2855
2067.92	40.5545
2071.62	40.5434
2075.31	40.6824
2079.01	41.1866
2082.7	42.2023
2086.39	43.5335
2090.08	45.3661
2093.77	47.8082
2097.45	50.3188
2101.14	52.3402
2104.82	53.5163
2108.5	53.3524
2112.18	50.4796
2115.86	51.1992
2119.54	53.9142
2123.21	58.9842
2126.88	63.1639
2130.56	67.0862
2134.23	70.1039
2137.89	71.0398
2141.56	70.0905
2145.23	68.715
2148.89	67.6046
2152.55	67.6962
2156.21	68.6792
2159.87	70.173
2163.53	71.9197
2167.18	73.7639
2170.84	75.4102
2174.49	76.6726
2178.14	77.3907
2181.79	77.4441
2185.44	76.6579
2189.08	81.1063
2192.73	84.4039
2196.37	83.1036
2200.01	81.8903
2203.65	75.2854
2207.29	84.0689
2210.92	91.7808
2214.56	89.3983
2218.19	84.2112
2221.82	76.5515
2225.45	70.8883
2229.08	68.66
2232.7	70.3301
2236.33	72.047
2239.95	73.8905
2243.57	75.7833
2247.19	77.457
2250.81	78.5544
2254.43	78.7431
2258.04	77.6031
2261.66	75.6308
2265.27	72.6265
2268.88	69.19
2272.49	65.2078
2276.1	65.9332
2279.7	66.6811
2283.31	68.3113
2286.91	68.7004
2290.51	68.4503
2294.11	69.0483
2297.71	69.2317
2301.3	69.4438
2304.9	77.808
2308.49	40.8918
2312.08	70.5112
2315.67	108.008
2319.26	172.084
2322.85	398.526
2326.43	425.767
2330.02	171.839
2333.6	95.0157
2337.18	75.5825
2340.76	62.7029
2344.34	53.4812
2347.91	44.3244
2351.49	38.9377
2355.06	41.3404
2358.63	44.7911
2362.2	44.8684
2365.77	47.8696
2369.33	45.0395
2372.9	39.4218
2376.46	37.1153
2380.02	36.879
2383.58	38.6863
2387.14	42.0913
2390.7	42.6945
2394.25	41.47
2397.81	40.8409
2401.36	38.657
2404.91	37.9498
2408.46	35.6093
2412.01	34.2395
2415.56	32.5713
2419.1	31.2452
2422.64	30.2369
2426.18	29.297
2429.72	29.0422
2433.26	31.6131
2436.8	25.3119
2440.34	22.359
2443.87	21.3799
2447.4	21.703
2450.93	23.6385
2454.46	24.8788
2457.99	20.0533
2461.52	22.3569
2465.04	25.7885
2468.56	25.7747
2472.09	23.961
2475.61	19.541
2479.13	15.4938
2482.64	13.0225
2486.16	12.7896
2489.67	14.5987
2493.18	13.7507
2496.69	14.0373
2500.2	12.9081
2503.71	12.5013
2507.22	13.0937
2510.72	13.9527
2514.23	15.0686
2517.73	16.3533
2521.23	16.4794
2524.73	16.8111
2528.23	17.1823
2531.72	17.3407
2535.21	16.7666
2538.71	20.4272
2542.2	20.3549
2545.69	18.9667
2549.18	13.8221
2552.66	9.15118
2556.15	5.88002
2559.63	6.42796
2563.12	6.69887
2566.6	8.1498
2570.08	9.80336
2573.55	13.4185
2577.03	11.1548
2580.5	8.91721
2583.98	3.23677
2587.45	3.29533
2590.92	2.37202
2594.39	2.4881
2597.86	1.51459
2601.32	-0.631332
2604.79	-1.65326
2608.25	-1.60892
2611.71	-1.58937
2615.17	-1.83351
2618.63	-2.18147
2622.08	-2.72847
2625.54	-2.66219
2628.99	-1.49556
2632.45	-1.62544
2635.9	-1.86699
2639.35	-2.11049
2642.79	-1.70638
2646.24	-1.57861
2649.69	-0.435059
2653.13	0.494965
2656.57	1.03163
2660.01	1.1205
2663.45	0.386337
2666.89	-0.710678
2670.32	-2.29095
2673.76	-4.05956
2677.19	-6.89912
2680.62	-9.35947
2684.05	-8.8858
2687.48	-5.19249
2690.91	-0.907761
2694.33	2.51167
2697.76	4.55304
2701.18	3.51068
2704.6	2.85921
2708.02	0.713669
2711.44	-1.24068
2714.86	-2.79375
2718.27	-4.10123
2721.69	-3.8669
2725.1	-3.66652
2728.51	-4.5352
2731.92	-5.24982
2735.33	-3.76735
2738.74	-1.79314
2742.14	-1.71796
2745.55	-2.57425
2748.95	-6.31871
2752.35	-8.81657
2755.75	-11.8812
2759.15	-15.2406
2762.54	-17.1792
2765.94	-16.8887
2769.33	-15.8264
2772.72	-14.6093
2776.12	-13.7215
2779.51	-12.423
2782.89	-10.3719
2786.28	-7.54823
2789.67	-6.79521
2793.05	-5.6778
2796.43	-5.02788
2799.81	-5.02301
2803.19	-5.87305
2806.57	-6.07568
2809.95	-8.27673
2813.32	-10.4486
2816.69	-12.7298
2820.06	-14.1339
2823.44	-16.6055
2826.81	-16.7847
2830.17	-16.7489
2833.54	-16.1432
2836.9	-15.1208
2840.27	-13.8415
2843.63	-13.4486
2846.99	-12.6183
2850.35	-11.4577
2853.71	-13.5566
2857.06	-10.6248
2860.42	-5.05556
2863.77	-5.71236
2867.12	-9.69579
2870.48	-14.3245
2873.83	-19.2315
2877.17	-21.8923
2880.52	-22.3411
2883.86	-24.1027
2887.21	-23.5656
2890.55	-20.0653
2893.89	-16.5243
2897.23	-13.0656
2900.57	-9.87476
2903.91	-8.27187
2907.24	-8.58319
2910.57	-8.08226
2913.91	-7.58716
2917.24	-8.85652
2920.57	-8.6548
2923.9	-10.9187
2927.22	-12.5339
2930.55	-13.5572
2933.87	-14.0124
2937.19	-13.8732
2940.51	-13.2133
2943.83	-11.9819
2947.15	-10.484
2950.47	-9.72066
2953.79	-9.84723
2957.1	-10.2811
2960.41	-11.1823
2963.72	-11.7551
2967.03	-11.4113
2970.34	-11.0912
2973.65	-11.5086
2976.95	-11.1433
2980.26	-8.55528
2983.56	-6.31439
2986.86	-5.81691
2990.16	-4.7635
2993.46	-3.63823
2996.76	-1.95483
3000.06	-0.658005
3003.35	0.97261
3006.64	2.12685
3009.94	3.84831
3013.23	3.83318
3016.51	3.58434
3019.8	3.31413
3023.09	0.618271
3026.38	-1.14847
3029.66	-0.789307
3032.94	0.352951
3036.22	2.10898
3039.5	4.08319
3042.78	6.51042
3046.05	8.04738
3049.33	9.74594
3052.6	10.2932
3055.88	9.71269
3059.15	8.90236
3062.42	8.53656
3065.69	8.5213
3068.95	9.0264
3072.22	9.57762
3075.48	10.945
3078.75	11.8235
3082.01	14.2847
3085.27	17.4115
3088.53	20.5403
3091.79	22.6686
3095.04	25.076
3098.3	28.5401
3101.55	31.957
3104.8	33.9834
3108.05	36.5287
3111.3	34.6208
3114.55	36.8261
3117.8	40.2844
3121.04	43.5916
3124.29	47.2673
3127.53	51.3357
3130.77	57.2094
3134.01	59.8229
3137.25	61.5028
3140.49	62.4209
3143.72	63.8214
3146.96	65.8853
3150.19	67.2073
3153.42	71.4032
3156.65	76.6328
3159.88	82.4211
3163.11	89.0705
3166.34	89.9223
3169.56	94.1099
3172.79	100.525
3176.01	107.58
3179.23	114.877
3182.45	121.471
3185.67	126.318
3188.88	130.579
3192.1	134.327
3195.31	139.202
3198.53	143.42
3201.74	150.137
3204.95	155.266
3208.16	160.194
3211.37	165.632
3214.57	171.819
3217.78	177.377
3220.98	184.108
3224.18	190.005
3227.39	195.858
3230.59	201.997
3233.78	208.333
3236.98	213.788
3240.18	218.89
3243.37	226.033
3246.56	233.332
3249.76	240.066
3252.95	246.528
3256.14	252.711
3259.32	256.594
3262.51	258.253
3265.7	260.288
3268.88	264.935
3272.06	270.978
3275.24	277.499
3278.42	283.408
3281.6	287.682
3284.78	285.33
3287.96	305.075
3291.13	311.568
3294.31	312.609
3297.48	309.604
3300.65	315.007
3303.82	316.484
3306.99	319.45
3310.15	318.307
3313.32	327.814
3316.48	339.192
3319.65	352.616
3322.81	367.796
3325.97	384.169
3329.13	402.214
3332.28	411.907
3335.44	426.954
3338.6	448.95
3341.75	480.285
3344.9	522.112
3348.05	590.09
3351.2	673.724
3354.35	809.591
3357.5	1005.37
3360.65	1301.84
3363.79	1678.04
3366.94	1900.07
3370.08	1975.3
3373.22	1753.03
3376.36	1558.19
3379.5	1345.24
3382.63	1189.82
3385.77	1074.73
3388.9	976.18
3392.04	890.008
3395.17	809.935
3398.3	745.462
3401.43	695.208
3404.56	656.276
3407.69	624.158
3410.81	601.424
3413.94	589.555
3417.06	586.693
3420.18	595.435
3423.3	606.563
3426.42	617.77
3429.54	633.306
3432.65	642.428
3435.77	645.522
3438.88	642.799
3442	640.111
3445.11	636.789
3448.22	632.118
3451.33	629.36
3454.43	625.859
3457.54	620.129
3460.65	613.694
3463.75	606.588
3466.85	599.773
3469.95	590.282
3473.05	575.052
3476.15	563.084
3479.25	555.455
3482.35	545.109
3485.44	539.934
3488.54	533.007
3491.63	526.229
3494.72	518.98
3497.81	508.451
3500.9	498.023
3503.99	488.161
3507.07	479.65
3510.16	472.756
3513.24	460.958
3516.32	445.296
3519.41	424.054
3522.49	415.869
3525.56	415.933
3528.64	401.998
3531.72	394.611
3534.79	390.982
3537.87	387.638
3540.94	382.557
3544.01	371.86
3547.08	358.67
3550.15	344.789
3553.22	331.067
3556.28	317.925
3559.35	305.881
3562.41	294.26
3565.47	283.003
3568.54	272.185
3571.6	263.866
3574.65	258.808
3577.71	256.949
3580.77	250.067
3583.82	238.151
3586.88	228.394
3589.93	217.657
3592.98	207.616
3596.03	196.803
3599.08	191.108
3602.13	187.048
3605.18	184.447
3608.22	181.793
3611.27	174.737
3614.31	166.717
3617.35	159.627
3620.39	151.621
3623.43	142.36
3626.47	130.782
3629.5	115.564
3632.54	125.06
3635.57	123.279
3638.61	119.268
3641.64	110.211
3644.67	101.297
3647.7	92.393
3650.73	84.3072
3653.75	76.1374
3656.78	67.9666
3659.8	60.1731
3662.83	52.84
3665.85	46.0847
3668.87	39.887
3671.89	34.2371
3674.91	29.3254
3677.92	24.9553
3680.94	21.0225
3683.96	17.4792
3686.97	14.2001
3689.98	10.7902
3692.99	7.4377
3696	4.09854
3699.01	0.0436554
3702.02	-4.5363
3705.02	-5.72334
3708.03	-5.61847
3711.03	-4.32675
3714.03	-3.33638
3717.04	-2.74142
3720.04	-3.13518
3723.04	-4.10306
3726.03	-5.46292
3729.03	-6.82381
3732.03	-7.71091
3735.02	-10.4048
3738.01	-13.0104
3741	-15.2896
3743.99	-16.9093
3746.98	-19.064
3749.97	-20.2146
3752.96	-20.3499
3755.95	-18.9289
3758.93	-16.8208
3761.91	-14.4026
3764.9	-11.8261
3767.88	-10.5732
3770.86	-10.4029
3773.84	-10.316
3776.81	-10.6716
3779.79	-10.8013
3782.77	-11.5731
3785.74	-12.8167
3788.71	-14.3672
3791.68	-15.8747
3794.65	-15.3413
3797.62	-12.9567
3800.59	-11.6084
3803.56	-10.4212
3806.52	-9.53191
3809.49	-8.28639
3812.45	-6.92491
3815.41	-5.91995
3818.37	-5.5909
3821.33	-6.51224
3824.29	-2.55542
3827.25	0.428268
3830.21	1.95866
3833.16	2.34657
3836.11	1.01961
3839.07	-0.809509
3842.02	-2.98799
3844.97	-4.55447
3847.92	-4.4762
3850.87	-4.32402
3853.81	-3.92087
3856.76	-2.96269
3859.7	-1.45805
3862.65	0.400681
3865.59	2.55603
3868.53	4.69722
3871.47	6.35506
3874.41	6.81866
3877.34	6.6104
3880.28	6.06194
3883.22	5.36392
3886.15	4.55885
3889.08	4.19769
3892.01	4.02174
3894.94	3.93329
3897.87	3.88242
3900.8	3.94012
3903.73	4.22946
3906.65	4.62161
3909.58	4.11484
3912.5	3.5645
3915.42	2.81691
3918.35	4.99675
3921.27	7.47198
3924.18	7.87183
3927.1	6.55945
3930.02	5.32739
3932.93	5.45436
3935.85	6.69444
3938.76	7.68265
3941.67	8.78682
3944.58	9.75296
3947.49	10.6578
3950.4	12.2536
3953.31	7.93318
3956.22	1.27393
3959.12	0.731567
3962.02	5.08478
3964.93	5.61137
3967.83	5.2776
3970.73	4.2874
3973.63	3.03572
3976.53	1.55373
3979.42	0.0335388
3982.32	-1.56934
3985.21	-3.20587
3988.11	-4.82751
3991	-6.01639
3993.89	-7.47369
3996.78	2.98555
3999.67	-7.59508