File: Data/3-Raman/processed/bu22-A-qtz2-FI04-v.txt
#Acq. time (s)=	15
#Accumulations=	3
#Range (cm-¹)=	50...5000
#Windows=	1
#Auto scanning=	Off
#Autofocus=	Off
#Macrospot=	Off
#AutoExposure=	Off
#Spike filter=	Multiple accum.
#Delay time (s)=	0
#Binning=	1
#Readout mode=	Signal
#DeNoise=	Lite
#ICS correction=	Off
#Dark correction=	Off
#Inst. Process=	Off
#Detector temperature (°C)=	-60.09
#Instrument=	LabRAM HR Evol
#Detector=	SIN-EM FIVIS
#Objective=	x100_VIS
#Grating=	150 (500nm)
#ND Filter=	100%
#Laser=	532nm_Edge
#Hole=	30.0125
#Temperature=	0
#Range=	Visible
#StageXY=	75x50mm Scan+
#StageZ=	Z motor
#X (µm)=	14108.7
#Y (µm)=	36.7
#Z (µm)=	-384.8
#Full time(s)=	47
#Project=	Buranga
#Sample=	BU18FA22_A
#Site=	A_Qtz3
#Title=	22-A_qtz2_FI04
#Remark=
#Date=	09.07.2019 18:56
#Acquired=	09.07.2019 18:56:39
#Data Range:Extract=	16.12.2021 15:29:10
#Base:Fit=	16.12.2021 15:29:21
#Base:Edit=	16.12.2021 15:33:50
#Base:Edit=	16.12.2021 15:33:50
#Base:Sub=	16.12.2021 15:33:54
98.6609	735.176
103.286	784.799
107.909	1123.28
112.53	1515.59
117.146	1037.68
121.762	380.588
126.376	229.794
130.988	125.244
135.595	56.5682
140.202	14.1595
144.807	0.247559
149.41	22.8439
154.008	78.681
158.606	156.494
163.201	284.734
167.795	485.396
172.384	837.366
176.973	1386.28
181.559	2003.51
186.142	2667.5
190.724	2832.03
195.304	2557.66
199.881	1871.93
204.454	1281.19
209.028	883.555
213.598	618.493
218.165	425.34
222.731	287.785
227.295	209.667
231.855	190.47
236.415	205.579
240.972	279.411
245.525	466.358
250.078	559.409
254.629	263.304
259.175	86.6276
263.722	48.9723
268.264	27.1403
272.805	14.4696
277.345	5.9016
281.88	0.589783
286.415	-1.05212
290.948	0.423935
295.477	6.40608
300.005	15.2788
304.529	24.4505
309.053	32.1656
313.575	40.9615
318.093	37.0159
322.61	51.5665
327.123	66.4722
331.636	130.248
336.145	380.881
340.653	450.459
345.157	227.072
349.662	130.458
354.164	108.63
358.661	84.9713
363.159	82.6323
367.652	93.9688
372.145	110.678
376.634	177.003
381.123	216.701
385.608	189.082
390.092	156.553
394.572	134.781
399.052	128.206
403.528	135.28
408.004	147.493
412.475	172.244
416.947	216.128
421.414	265.212
425.881	368.671
430.343	643.51
434.806	1162.86
439.264	2663.11
443.723	6102.28
448.177	9683.35
452.629	8261.35
457.081	4305.28
461.528	2029.14
465.976	1210.93
470.419	818.164
474.862	626.612
479.301	492.467
483.738	417.243
488.175	376.158
492.607	337.833
497.04	301.94
501.468	268.712
505.894	238.65
510.32	213.103
514.742	191.114
519.164	172.14
523.581	156.001
527.997	140.978
532.412	127.112
536.823	114.097
541.232	102.9
545.641	92.5211
550.046	84.9431
554.449	79.5355
558.851	77.3958
563.25	78.8257
567.646	85.6998
572.042	84.7019
576.434	79.8524
580.824	74.9046
585.214	69.4708
589.599	64.0617
593.983	59.3701
598.367	55.4321
602.746	52.1196
607.123	49.3111
611.498	48.8075
615.873	45.4903
620.244	41.5083
624.613	35.0959
628.98	29.5547
633.346	24.8945
637.709	20.7179
642.069	17.5944
646.428	16.7169
650.786	17.5
655.14	19.8906
659.492	23.555
663.842	29.8941
668.192	33.44
672.538	43.1349
676.882	55.7836
681.223	67.0873
685.563	55.9595
689.902	43.6886
694.238	30.6138
698.571	20.1932
702.902	11.8565
707.231	7.27852
711.559	4.14212
715.886	2.75107
720.209	1.28273
724.529	0.401215
728.848	0.101563
733.165	0.605103
737.48	1.99165
741.792	4.12592
746.105	8.76924
750.413	13.2977
754.72	17.3738
759.024	23.4567
763.327	34.1069
767.627	55.0384
771.925	83.06
776.221	122.9
780.518	172.723
784.81	225.75
789.1	303.469
793.388	370.883
797.674	239.25
801.958	116.776
806.24	76.6222
810.52	52.1222
814.797	43.1527
819.073	34.6919
823.347	28.9676
827.619	25.2155
831.888	23.4025
836.156	23.4793
840.422	24.0835
844.685	25.27
848.947	24.608
853.206	26.2083
857.464	30.807
861.719	34.1423
865.973	33.6959
870.224	31.9386
874.474	28.3677
878.721	24.2513
882.967	21.5092
887.21	20.016
891.452	21.4222
895.691	22.7386
899.929	23.4369
904.164	23.6312
908.397	22.9397
912.629	21.7211
916.858	19.7274
921.086	16.9571
925.311	13.6133
929.534	11.0852
933.756	10.6441
937.975	11.651
942.191	12.691
946.406	13.904
950.619	14.9667
954.831	14.2137
959.04	11.1949
963.248	7.13277
967.453	4.83142
971.657	3.17494
975.858	2.29208
980.056	2.42946
984.253	4.48973
988.449	2.75941
992.643	0.537094
996.834	-0.821838
1001.02	-1.67848
1005.21	-1.84749
1009.4	-0.120956
1013.58	3.07431
1017.76	12.7745
1021.94	10.7058
1026.12	6.59564
1030.29	2.3624
1034.47	2.00934
1038.64	8.63753
1042.81	18.5425
1046.98	50.8804
1051.14	89.7655
1055.3	116.711
1059.47	144.676
1063.63	183.769
1067.78	203.936
1071.94	148.345
1076.09	70.7423
1080.25	43.4335
1084.4	25.7005
1088.54	20.4979
1092.69	27.5942
1096.83	29.07
1100.98	24.8306
1105.12	20.0191
1109.26	15.1648
1113.39	10.9703
1117.53	11.4121
1121.66	14.9829
1125.79	17.572
1129.92	27.8142
1134.04	41.2179
1138.17	58.4256
1142.29	89.0422
1146.41	107.144
1150.53	93.4061
1154.65	64.11
1158.76	40.8704
1162.88	24.1205
1166.99	12.4344
1171.1	9.90034
1175.2	8.89389
1179.31	11.2296
1183.41	13.6678
1187.51	19.2242
1191.61	23.6054
1195.71	27.4548
1199.81	36.3199
1203.9	47.2055
1207.99	58.6871
1212.08	74.1922
1216.17	84.7903
1220.26	96.0662
1224.34	102.807
1228.42	107.561
1232.5	109.487
1236.58	120.008
1240.66	149.925
1244.73	218.605
1248.81	346.462
1252.88	370.301
1256.95	241.508
1261.02	250.076
1265.08	979.642
1269.14	2836.2
1273.2	2442.76
1277.27	667.323
1281.32	205.193
1285.38	171.803
1289.43	143.921
1293.48	130.7
1297.53	120.56
1301.58	112.579
1305.63	107.134
1309.67	104.548
1313.72	101.69
1317.76	100.275
1321.8	100.808
1325.83	102.896
1329.87	107.002
1333.9	113.69
1337.93	122.262
1341.96	134.812
1345.99	152.512
1350.02	171.279
1354.04	239.675
1358.06	251.228
1362.08	247.609
1366.1	553.419
1370.12	2652.98
1374.13	4906.54
1378.14	2550.11
1382.16	515.679
1386.16	265.252
1390.17	300.828
1394.18	529.407
1398.18	430.99
1402.18	198.255
1406.18	120.434
1410.18	100.438
1414.18	91.8882
1418.17	78.4341
1422.16	64.2101
1426.15	52.6201
1430.14	46.3038
1434.13	46.2741
1438.11	33.5013
1442.1	24.0482
1446.08	8.56595
1450.06	2.0303
1454.04	4.5654
1458.01	12.6289
1461.98	10.1288
1465.96	8.00165
1469.93	6.17511
1473.9	4.88892
1477.86	3.34473
1481.83	1.97531
1485.79	0.86203
1489.75	0.307068
1493.71	0.254547
1497.67	0.513977
1501.62	0.907562
1505.58	1.30469
1509.53	1.93765
1513.48	3.07816
1517.43	4.35083
1521.38	4.74396
1525.32	4.16354
1529.26	2.77426
1533.2	1.93018
1537.14	1.13965
1541.08	0.275146
1545.02	0.67395
1548.95	2.20474
1552.88	4.14337
1556.81	6.20868
1560.74	8.28299
1564.67	10.8322
1568.6	13.2787
1572.52	15.3374
1576.44	17.0524
1580.36	18.5974
1584.28	20.0353
1588.19	21.4508
1592.11	24.2311
1596.02	26.5902
1599.93	26.9911
1603.84	29.92
1607.75	31.7701
1611.65	32.4955
1615.56	31.5674
1619.46	34.3683
1623.36	29.0423
1627.25	22.7666
1631.15	17.5553
1635.05	15.7287
1638.94	17.8318
1642.83	20.478
1646.72	21.8584
1650.61	22.026
1654.49	21.3701
1658.38	20.0734
1662.26	18.0771
1666.14	15.4964
1670.02	12.454
1673.89	8.23685
1677.77	5.7066
1681.64	3.46655
1685.51	3.71838
1689.38	3.7493
1693.25	2.65265
1697.12	0.437531
1700.98	-1.88962
1704.85	-3.49597
1708.71	-1.81619
1712.57	-0.541962
1716.42	1.14713
1720.28	1.52502
1724.13	1.54041
1727.99	0.784088
1731.84	0.232452
1735.69	-0.0997314
1739.53	-0.202362
1743.38	0.285095
1747.22	1.15652
1751.06	3.6076
1754.9	5.30109
1758.74	7.36029
1762.58	7.80267
1766.41	6.98117
1770.25	6.0834
1774.08	7.77008
1777.91	3.43481
1781.73	0.40506
1785.56	-0.61319
1789.39	-0.90509
1793.21	-0.684296
1797.03	1.59192
1800.85	6.69107
1804.67	9.15939
1808.48	10.5408
1812.3	9.87283
1816.11	9.17374
1819.92	8.77576
1823.73	9.21739
1827.54	8.97694
1831.34	8.1217
1835.14	6.32643
1838.95	5.0295
1842.75	4.37201
1846.55	4.26567
1850.34	4.39436
1854.14	5.84155
1857.93	8.06319
1861.72	12.1873
1865.51	12.6238
1869.3	12.9399
1873.09	10.5364
1876.87	8.48337
1880.66	10.2744
1884.44	11.9565
1888.22	12.218
1892	11.6856
1895.77	10.1552
1899.55	9.46489
1903.32	11.1285
1907.09	12.5609
1910.86	14.0981
1914.63	15.6074
1918.4	17.4448
1922.16	19.4508
1925.92	21.2844
1929.68	22.7506
1933.44	23.5038
1937.2	24.0845
1940.96	25.5438
1944.71	23.6309
1948.46	21.5081
1952.22	20.1563
1955.97	19.748
1959.71	20.6342
1963.46	22.0661
1967.2	29.1503
1970.95	28.0523
1974.69	27.7207
1978.43	29.123
1982.17	31.6328
1985.9	33.5982
1989.64	37.9713
1993.37	34.2484
1997.1	31.2936
2000.83	25.7408
2004.56	20.5659
2008.28	30.832
2012.01	36.2739
2015.73	40.9333
2019.45	41.132
2023.17	41.1965
2026.89	40.4733
2030.6	39.4865
2034.32	37.6242
2038.03	36.2095
2041.74	36.1231
2045.45	36.933
2049.16	38.2699
2052.87	39.2216
2056.57	39.7894
2060.27	39.9579
2063.98	38.3813
2067.67	36.6664
2071.37	35.2845
2075.07	34.1531
2078.76	35.5708
2082.46	38.061
2086.15	41.2886
2089.84	44.3238
2093.53	46.2335
2097.21	45.5936
2100.9	45.3645
2104.58	44.3265
2108.26	43.4162
2111.94	42.5949
2115.62	42.5662
2119.3	42.8891
2122.97	43.6291
2126.64	44.6496
2130.32	44.7988
2133.99	45.7152
2137.66	46.8759
2141.32	48.0062
2144.99	49.1
2148.65	49.0129
2152.31	47.8323
2155.97	48.9978
2159.63	46.5433
2163.29	52.1246
2166.94	59.3693
2170.6	65.3223
2174.25	66.035
2177.9	66.8092
2181.55	51.1018
2185.2	50.4961
2188.84	52.5907
2192.49	54.7372
2196.13	56.7128
2199.77	57.9396
2203.41	58.7095
2207.05	59.0679
2210.69	58.8056
2214.32	57.9691
2217.95	56.8421
2221.59	55.7989
2225.22	53.26
2228.84	51.9072
2232.47	50.2843
2236.09	48.6667
2239.72	46.8381
2243.34	45.6833
2246.96	45.065
2250.58	44.626
2254.2	44.6842
2257.81	44.9909
2261.42	45.2202
2265.04	45.9878
2268.65	47.1183
2272.26	48.2431
2275.86	49.2229
2279.47	49.9794
2283.08	50.319
2286.68	50.274
2290.28	50.2387
2293.88	49.15
2297.48	46.589
2301.07	46.4295
2304.67	43.364
2308.26	78.6664
2311.85	236.188
2315.44	660.91
2319.03	508.624
2322.62	138.055
2326.2	83.4977
2329.79	62.5313
2333.37	57.7187
2336.95	55.6082
2340.53	52.7731
2344.11	50.3334
2347.68	48.2177
2351.26	47.5339
2354.83	47.1674
2358.4	47.3652
2361.97	46.4661
2365.54	46.1089
2369.11	46.4724
2372.67	47.8181
2376.23	51.1794
2379.8	55.63
2383.36	58.2525
2386.92	59.6778
2390.47	60.3954
2394.03	57.0508
2397.58	52.4065
2401.14	48.2548
2404.69	44.7081
2408.24	41.8687
2411.78	41.1227
2415.33	40.9349
2418.88	41.6201
2422.42	42.2988
2425.96	42.6059
2429.5	42.787
2433.04	41.6107
2436.58	40.4567
2440.11	39.1186
2443.65	37.7431
2447.18	36.8091
2450.71	35.5325
2454.24	34.4107
2457.77	32.6297
2461.3	32.0575
2464.82	31.6561
2468.34	30.7182
2471.86	30.0432
2475.39	29.9554
2478.9	30.2617
2482.42	31.1734
2485.94	32.2171
2489.45	33.1933
2492.96	33.6064
2496.47	32.3768
2499.98	31.0315
2503.49	31.9541
2507	35.1613
2510.5	39.3925
2514.01	40.9172
2517.51	41.4393
2521.01	39.1472
2524.51	36.506
2528.01	33.5952
2531.5	32.3211
2535	32.1151
2538.49	32.4546
2541.98	32.6755
2545.47	32.5902
2548.96	32.1406
2552.45	31.295
2555.93	29.7587
2559.42	27.7343
2562.9	25.4692
2566.38	24.6019
2569.86	27.1081
2573.34	26.8634
2576.81	25.8307
2580.29	23.8312
2583.76	21.3059
2587.23	18.1744
2590.71	14.9059
2594.17	13.5368
2597.64	15.0595
2601.11	14.905
2604.57	19.1513
2608.03	5.33609
2611.5	4.84967
2614.96	6.64386
2618.42	10.3141
2621.87	15.4568
2625.33	17.889
2628.78	18.005
2632.23	14.5016
2635.68	12.1142
2639.13	10.6822
2642.58	9.94016
2646.03	8.99377
2649.47	8.36548
2652.92	7.60538
2656.36	7.18478
2659.8	7.08401
2663.24	7.25925
2666.68	7.14401
2670.11	4.41788
2673.55	5.285
2676.98	7.60919
2680.41	10.6441
2683.84	14.3165
2687.27	17.1182
2690.7	14.8939
2694.13	10.1802
2697.55	6.45673
2700.97	3.77097
2704.4	1.58841
2707.82	-0.561768
2711.23	-2.48679
2714.65	-2.90347
2718.07	-2.46109
2721.48	-1.50137
2724.9	-1.56372
2728.31	-1.13437
2731.72	1.60382
2735.12	2.84256
2738.53	3.02792
2741.94	1.56729
2745.34	-0.187439
2748.74	-0.767426
2752.14	-1.67712
2755.54	-2.68851
2758.94	-4.47888
2762.34	-5.12784
2765.73	-4.13202
2769.13	-5.46646
2772.52	-6.16525
2775.91	-6.42764
2779.3	-6.18024
2782.69	-5.48544
2786.08	-4.84009
2789.46	-4.68646
2792.85	-5.56049
2796.23	-6.55884
2799.61	-7.37604
2802.99	-8.67667
2806.37	-10.2265
2809.74	-11.5365
2813.12	-12.5085
2816.49	-12.2306
2819.86	-11.2907
2823.23	-8.50836
2826.61	-5.89801
2829.97	-4.08221
2833.34	-3.73828
2836.7	-4.24521
2840.07	-4.81796
2843.43	-5.28351
2846.79	-5.8699
2850.15	-7.29486
2853.51	-9.04037
2856.87	-10.5637
2860.22	-11.4525
2863.57	-11.7755
2866.93	-11.9066
2870.28	-11.4678
2873.63	-10.2501
2876.98	-8.74335
2880.32	-7.436
2883.67	-6.66177
2887.01	-6.60767
2890.35	-7.15582
2893.69	-7.21796
2897.03	-5.67221
2900.37	-12.2797
2903.71	-16.2992
2907.04	-11.6464
2910.38	-7.37036
2913.71	-3.71606
2917.04	2.78375
2920.37	4.09628
2923.7	1.76324
2927.03	-1.78036
2930.35	-4.84418
2933.68	-6.97061
2937	-8.38617
2940.32	-9.05246
2943.64	-8.82709
2946.96	-7.68185
2950.27	-2.44324
2953.59	0.275116
2956.91	0.754364
2960.22	-0.0760193
2963.53	0.451141
2966.84	-1.19043
2970.15	-2.18054
2973.46	-3.68329
2976.76	-2.35175
2980.07	-0.497375
2983.37	3.11972
2986.67	7.19931
2989.97	9.35815
2993.27	7.62726
2996.57	6.69009
2999.86	5.03192
3003.16	5.42245
3006.45	6.12204
3009.75	7.09924
3013.03	6.11469
3016.32	5.95972
3019.61	5.88583
3022.9	5.3381
3026.19	6.31436
3029.47	7.66537
3032.75	10.7247
3036.03	15.1498
3039.31	19.1922
3042.59	21.7043
3045.87	22.9921
3049.14	20.7642
3052.42	17.8484
3055.69	17.6409
3058.96	19.0046
3062.23	24.3676
3065.5	29.5348
3068.77	34.8085
3072.03	39.8969
3075.3	44.6844
3078.56	48.0861
3081.82	51.1924
3085.08	54.3775
3088.34	58.6206
3091.6	61.4938
3094.86	63.3489
3098.11	64.958
3101.36	66.5963
3104.62	68.8008
3107.87	70.8254
3111.12	73.3657
3114.37	76.7208
3117.61	81.2422
3120.86	87.6
3124.1	95.365
3127.34	101.317
3130.59	116.389
3133.83	126.595
3137.07	131.31
3140.3	133.859
3143.54	136.89
3146.77	140.269
3150.01	143.752
3153.24	146.937
3156.47	150.368
3159.7	158.402
3162.93	172.878
3166.15	187.249
3169.38	190.737
3172.6	194.073
3175.83	196.071
3179.05	199.175
3182.27	204.065
3185.49	208.371
3188.7	212.906
3191.92	218.239
3195.13	223.885
3198.35	230.106
3201.56	236.76
3204.77	243.623
3207.98	250.974
3211.19	259.938
3214.39	267.074
3217.6	270.852
3220.8	274.104
3224	280.433
3227.21	283.463
3230.41	286.585
3233.6	290.274
3236.8	293.948
3240	297.779
3243.19	301.707
3246.39	304.76
3249.58	308.467
3252.77	311.886
3255.96	314.786
3259.15	317.211
3262.33	318.441
3265.52	321.722
3268.7	324.258
3271.89	328.838
3275.07	331.152
3278.25	332.015
3281.43	331.319
3284.6	331.56
3287.78	338.5
3290.95	347.779
3294.13	360.626
3297.3	366.806
3300.47	370.307
3303.64	373.552
3306.81	373.97
3309.98	376.973
3313.14	380.01
3316.31	387.9
3319.47	395.837
3322.63	399.734
3325.79	406.673
3328.95	411.769
3332.11	417.622
3335.27	423.691
3338.42	430.132
3341.58	436.707
3344.73	445.099
3347.88	454.537
3351.03	464.055
3354.18	470.641
3357.33	476.872
3360.47	481.963
3363.62	487.743
3366.76	493.367
3369.91	499.313
3373.05	505.105
3376.19	509.833
3379.32	514.578
3382.46	519.815
3385.6	525.274
3388.73	530.188
3391.87	534.143
3395	537.23
3398.13	539.715
3401.26	540.98
3404.39	539.869
3407.51	539.965
3410.64	539.024
3413.76	542.618
3416.89	549.757
3420.01	556.555
3423.13	564.783
3426.25	565.018
3429.37	563.277
3432.48	560.307
3435.6	556.281
3438.71	553.021
3441.83	548.684
3444.94	542.558
3448.05	544.419
3451.16	547.776
3454.27	555.895
3457.37	563.111
3460.48	540.145
3463.58	535.601
3466.69	533.341
3469.79	532.014
3472.89	524.592
3475.99	515.729
3479.08	504.783
3482.18	495.784
3485.28	490.137
3488.37	483.634
3491.46	476.434
3494.55	469.166
3497.64	458.814
3500.73	445.684
3503.82	432.965
3506.91	421.421
3509.99	412.55
3513.08	403.798
3516.16	395.908
3519.24	389.998
3522.32	383.074
3525.4	375.2
3528.48	363.224
3531.55	350.198
3534.63	337.438
3537.7	326.94
3540.78	316.335
3543.85	308.104
3546.92	298.501
3549.99	290.726
3553.05	284.593
3556.12	278.992
3559.19	270.133
3562.25	259.678
3565.31	247.47
3568.37	232.454
3571.43	219.301
3574.49	208.045
3577.55	193.308
3580.61	165.876
3583.66	189.854
3586.72	191.29
3589.77	182.213
3592.82	172.915
3595.87	164.199
3598.92	156.713
3601.97	151.84
3605.02	144.457
3608.06	131.466
3611.11	125.226
3614.15	119.24
3617.19	115.435
3620.23	113.765
3623.27	111.589
3626.31	107.826
3629.34	102.529
3632.38	95.9302
3635.41	87.5429
3638.45	79.903
3641.48	73.2969
3644.51	67.4491
3647.54	62.458
3650.57	58.8986
3653.59	53.1134
3656.62	47.2135
3659.65	40.8186
3662.67	32.7099
3665.69	24.0055
3668.71	14.7086
3671.73	7.25198
3674.75	0.957733
3677.77	-3.57361
3680.78	-7.23099
3683.8	-10.0069
3686.81	-12.1297
3689.82	-13.7102
3692.84	-15.7006
3695.84	-19.0793
3698.85	-22.8084
3701.86	-26.0272
3704.87	-27.1599
3707.87	-23.0491
3710.88	-21.9094
3713.88	-23.0288
3716.88	-24.818
3719.88	-26.6477
3722.88	-28.6075
3725.88	-29.8105
3728.88	-30.506
3731.87	-30.4524
3734.87	-30.1773
3737.86	-29.7093
3740.85	-28.7723
3743.84	-27.2881
3746.83	-25.3226
3749.82	-23.2419
3752.81	-21.1505
3755.79	-20.6819
3758.78	-21.91
3761.76	-23.9935
3764.74	-25.3011
3767.73	-26.203
3770.71	-25.7851
3773.68	-24.4219
3776.66	-22.9072
3779.64	-22.9281
3782.61	-30.9084
3785.59	-26.0598
3788.56	-29.4757
3791.53	-23.5681
3794.5	-22.2413
3797.47	-18.8332
3800.44	-14.5862
3803.41	-9.43591
3806.37	-13.2647
3809.34	-15.4368
3812.3	-15.9762
3815.26	-12.8802
3818.22	-9.95386
3821.18	-7.92932
3824.14	-6.09399
3827.1	-4.78632
3830.06	-3.4249
3833.01	-1.49533
3835.96	-0.213898
3838.92	0.374023
3841.87	-0.240509
3844.82	-0.743866
3847.77	-3.69382
3850.72	-10.2369
3853.66	-13.7207
3856.61	-12.0368
3859.55	-7.41486
3862.5	-3.06595
3865.44	0.738037
3868.38	0.90744
3871.32	1.20197
3874.26	1.79134
3877.2	2.71442
3880.13	3.78952
3883.07	5.14442
3886	3.44412
3888.94	3.55557
3891.87	4.07059
3894.8	4.78966
3897.73	4.94772
3900.66	5.66614
3903.58	7.57912
3906.51	9.67348
3909.43	12.9393
3912.36	14.671
3915.28	15.4855
3918.2	12.4333
3921.12	5.97534
3924.04	6.45993
3926.96	7.42682
3929.87	8.16904
3932.79	8.56248
3935.7	8.24341
3938.62	7.48277
3941.53	6.11794
3944.44	5.29988
3947.35	7.21843
3950.26	8.24651
3953.17	9.37918
3956.07	9.39175
3958.98	7.78191
3961.88	5.97961
3964.78	5.96132
3967.69	7.54868
3970.59	11.4056
3973.49	14.6228
3976.38	12.9387
3979.28	10.1118
3982.18	7.91809
3985.07	5.95711
3987.97	4.27008
3990.86	3.53625
3993.75	2.42908
3996.64	0.607666
3999.53	0.149582