File: Data/3-Raman/processed/bu22-A-qtz3a-FI02-v.txt
#Acq. time (s)=	15
#Accumulations=	3
#Range (cm-¹)=	50...5000
#Windows=	1
#Auto scanning=	Off
#Autofocus=	Off
#Macrospot=	Off
#AutoExposure=	Off
#Spike filter=	Multiple accum.
#Delay time (s)=	0
#Binning=	1
#Readout mode=	Signal
#DeNoise=	Lite
#ICS correction=	Off
#Dark correction=	Off
#Inst. Process=	Off
#Detector temperature (°C)=	-60.09
#Instrument=	LabRAM HR Evol
#Detector=	SIN-EM FIVIS
#Objective=	x100_VIS
#Grating=	150 (500nm)
#ND Filter=	100%
#Laser=	532nm_Edge
#Hole=	30.0125
#Temperature=	0
#Range=	Visible
#StageXY=	75x50mm Scan+
#StageZ=	Z motor
#X (µm)=	14511.3
#Y (µm)=	1696.7
#Z (µm)=	-371.1
#Full time(s)=	51
#Project=	Buranga
#Sample=	BU18FA22_A
#Site=	A_Qtz3
#Title=	22-A_qtz3a_FI02
#Remark=
#Date=	09.07.2019 18:32
#Acquired=	09.07.2019 18:32:27
#Data Range:Extract=	16.12.2021 15:29:10
#Base:Fit=	16.12.2021 15:29:21
#Base:Edit=	16.12.2021 15:32:43
#Base:Edit=	16.12.2021 15:32:44
#Base:Edit=	16.12.2021 15:32:45
#Base:Sub=	16.12.2021 15:32:47
98.6609	1.72559
103.286	1452.71
107.909	6157.2
112.53	9270.05
117.146	4677.34
121.762	1237.31
126.376	340.508
130.988	204.119
135.595	58.3848
140.202	-13.3831
144.807	-2.75391
149.41	99.885
154.008	298.603
158.606	595.335
163.201	991.279
167.795	1583.18
172.384	2550.38
176.973	4077.23
181.559	6010.35
186.142	7721.58
190.724	8214.62
195.304	7131.49
199.881	5314.1
204.454	3719.6
209.028	2511.51
213.598	1702.01
218.165	1190.17
222.731	848.186
227.295	654.842
231.855	553.249
236.415	484.211
240.972	527.073
245.525	667.642
250.078	757.808
254.629	378.036
259.175	127.691
263.722	56.6031
268.264	23.951
272.805	8.83191
277.345	-3.39941
281.88	-7.13129
286.415	-7.73474
290.948	-6.05969
295.477	-0.335083
300.005	9.93823
304.529	25.0436
309.053	47.607
313.575	59.9478
318.093	108.103
322.61	142.902
327.123	208.535
331.636	470.855
336.145	1470.33
340.653	1347.36
345.157	723.588
349.662	376.157
354.164	209.274
358.661	182.763
363.159	239.979
367.652	409.6
372.145	751.694
376.634	1734.68
381.123	1847.43
385.608	981.736
390.092	478.633
394.572	335.03
399.052	358.671
403.528	369.605
408.004	408.113
412.475	473.625
416.947	568.704
421.414	682.248
425.881	1066.77
430.343	1740.74
434.806	3311.99
439.264	7060.99
443.723	17701.7
448.177	30276.3
452.629	25394.6
457.081	12571.7
461.528	6001.64
465.976	3508.4
470.419	2360.01
474.862	1812.48
479.301	1429.81
483.738	1144.75
488.175	999.032
492.607	870.008
497.04	778.597
501.468	705.651
505.894	642.521
510.32	589.008
514.742	540.745
519.164	497.956
523.581	456.812
527.997	419.684
532.412	385.494
536.823	349.482
541.232	310.473
545.641	278.752
550.046	255.501
554.449	243.22
558.851	239.234
563.25	239.794
567.646	238.927
572.042	236.141
576.434	231.171
580.824	220.936
585.214	207.452
589.599	191.783
593.983	176.105
598.367	163.017
602.746	151.64
607.123	141.998
611.498	135.079
615.873	130.844
620.244	126.494
624.613	121.322
628.98	114.202
633.346	103.595
637.709	92.2393
642.069	81.0711
646.428	70.5851
650.786	66.6442
655.14	73.2672
659.492	94.3394
663.842	110.652
668.192	149.296
672.538	268.674
676.882	520.498
681.223	637.052
685.563	431.44
689.902	207.941
694.238	136.61
698.571	97.9893
702.902	69.6862
707.231	51.0036
711.559	39.5239
715.886	31.3433
720.209	24.24
724.529	19.9328
728.848	15.7457
733.165	13.6109
737.48	10.636
741.792	11.3475
746.105	8.76874
750.413	7.24121
754.72	7.85117
759.024	15.1743
763.327	30.8256
767.627	77.9063
771.925	120.929
776.221	247.349
780.518	396.653
784.81	393.699
789.1	300.178
793.388	196.852
797.674	124.24
801.958	77.3032
806.24	65.7729
810.52	55.9062
814.797	47.676
819.073	42.9952
823.347	41.4167
827.619	41.4674
831.888	39.1193
836.156	40.9297
840.422	23.6933
844.685	26.2057
848.947	28.5226
853.206	46.2318
857.464	64.835
861.719	74.2047
865.973	67.2057
870.224	53.4713
874.474	42.3633
878.721	34.7397
882.967	29.619
887.21	30.6307
891.452	33.6681
895.691	36.3076
899.929	40.7411
904.164	44.6801
908.397	40.9097
912.629	34.2631
916.858	25.2977
921.086	17.7466
925.311	12.954
929.534	5.04187
933.756	-2.37946
937.975	-2.6889
942.191	-0.538849
946.406	0.549255
950.619	0.254547
954.831	-4.99966
959.04	-12.3828
963.248	-15.7479
967.453	-18.2249
971.657	-19.6474
975.858	-19.8089
980.056	-18.6241
984.253	-16.0003
988.449	-15.0394
992.643	-16.7738
996.834	-19.2431
1001.02	-21.6317
1005.21	-20.5804
1009.4	-18.4909
1013.58	-15.427
1017.76	-10.8444
1021.94	-2.91025
1026.12	4.48538
1030.29	10.4868
1034.47	28.2
1038.64	32.2756
1042.81	60.5704
1046.98	177.312
1051.14	257.796
1055.3	241.954
1059.47	209.497
1063.63	179.077
1067.78	142.318
1071.94	103.982
1076.09	70.8439
1080.25	41.8622
1084.4	29.9794
1088.54	25.8602
1092.69	24.2341
1096.83	24.5358
1100.98	24.5951
1105.12	27.7031
1109.26	33.2603
1113.39	42.0248
1117.53	55.0108
1121.66	75.451
1125.79	82.7491
1129.92	132.646
1134.04	240.12
1138.17	477.253
1142.29	924.057
1146.41	1450.66
1150.53	1214.94
1154.65	609.791
1158.76	266.68
1162.88	129.185
1166.99	83.9264
1171.1	62.584
1175.2	52.2707
1179.31	48.1296
1183.41	45.5165
1187.51	46.1508
1191.61	50.3835
1195.71	56.6369
1199.81	65.0215
1203.9	74.5482
1207.99	84.3472
1212.08	97.2297
1216.17	103.875
1220.26	108.945
1224.34	109.775
1228.42	110.479
1232.5	108.011
1236.58	113.889
1240.66	120.139
1244.73	148.013
1248.81	177.327
1252.88	193.715
1256.95	165.488
1261.02	185.82
1265.08	281.221
1269.14	674.52
1273.2	1011.63
1277.27	375.273
1281.32	131.485
1285.38	106.929
1289.43	91.2241
1293.48	78.9384
1297.53	73.9334
1301.58	70.6782
1305.63	69.8083
1309.67	71.1354
1313.72	71.471
1317.76	71.9376
1321.8	72.7549
1325.83	73.8271
1329.87	77.6503
1333.9	76.1676
1337.93	76.4244
1341.96	80.7045
1345.99	87.0629
1350.02	99.2987
1354.04	134.223
1358.06	181.856
1362.08	260.483
1366.1	369.949
1370.12	715.858
1374.13	1566.48
1378.14	1294.29
1382.16	283.153
1386.16	162.365
1390.17	162.013
1394.18	163.938
1398.18	175.711
1402.18	130.633
1406.18	98.4193
1410.18	73.7866
1414.18	66.9987
1418.17	61.9515
1422.16	55.6006
1426.15	50.8443
1430.14	47.1637
1434.13	44.2771
1438.11	40.9784
1442.1	37.8925
1446.08	32.508
1450.06	29.2769
1454.04	27.3245
1458.01	26.1493
1461.98	23.4507
1465.96	21.0721
1469.93	19.496
1473.9	19.3654
1477.86	20.7874
1481.83	22.7746
1485.79	25.0655
1489.75	25.8047
1493.71	26.1344
1497.67	25.7449
1501.62	24.7868
1505.58	24.8928
1509.53	28.8936
1513.48	28.0499
1517.43	27.5619
1521.38	27.9263
1525.32	26.1379
1529.26	26.5107
1533.2	28.3317
1537.14	33.9975
1541.08	38.1115
1545.02	41.6674
1548.95	44.0664
1552.88	46.6489
1556.81	49.7575
1560.74	53.2727
1564.67	57.4021
1568.6	61.832
1572.52	66.9282
1576.44	72.4493
1580.36	78.4132
1584.28	85.391
1588.19	92.0777
1592.11	100.499
1596.02	107.831
1599.93	114.695
1603.84	121.272
1607.75	126.747
1611.65	131.818
1615.56	136.4
1619.46	139.176
1623.36	140.428
1627.25	140.368
1631.15	138.445
1635.05	135.285
1638.94	130.143
1642.83	124.151
1646.72	122.787
1650.61	113.203
1654.49	104.807
1658.38	98.1667
1662.26	91.1038
1666.14	82.7807
1670.02	73.0137
1673.89	63.2873
1677.77	53.9715
1681.64	45.1892
1685.51	36.6893
1689.38	28.9966
1693.25	22.2365
1697.12	16.6768
1700.98	12.0775
1704.85	7.73172
1708.71	3.87991
1712.57	1.02887
1716.42	-0.0657349
1720.28	-0.504974
1724.13	-1.63962
1727.99	-2.5141
1731.84	-3.95419
1735.69	-6.4404
1739.53	-11.4909
1743.38	-13.6218
1747.22	-12.6916
1751.06	-8.40158
1754.9	-5.83289
1758.74	-5.54254
1762.58	-6.50082
1766.41	-8.85193
1770.25	-11.8552
1774.08	-14.5205
1777.91	-15.1774
1781.73	-14.6557
1785.56	-13.4585
1789.39	-9.13635
1793.21	-10.1854
1797.03	-12.459
1800.85	-16.3
1804.67	-20.2287
1808.48	-23.9836
1812.3	-24.526
1816.11	-23.1721
1819.92	-22.1079
1823.73	-18.5987
1827.54	-15.211
1831.34	-12.7281
1835.14	-10.9814
1838.95	-10.33
1842.75	-11.4038
1846.55	-14.6402
1850.34	-17.0382
1854.14	-15.0826
1857.93	-13.2014
1861.72	-11.3271
1865.51	-10.8636
1869.3	-11.1346
1873.09	-11.2018
1876.87	-10.6748
1880.66	-9.47952
1884.44	-8.09247
1888.22	-6.4364
1892	-4.68994
1895.77	-3.1478
1899.55	-0.953369
1903.32	1.01297
1907.09	1.81027
1910.86	2.6727
1914.63	2.84082
1918.4	2.18997
1922.16	0.642181
1925.92	0.161499
1929.68	-1.40091
1933.44	-3.50452
1937.2	-4.9119
1940.96	-6.04813
1944.71	-12.2085
1948.46	-6.18649
1952.22	1.49234
1955.97	5.98569
1959.71	9.28476
1963.46	10.5361
1967.2	10.1247
1970.95	12.1554
1974.69	14.7073
1978.43	16.1182
1982.17	17.7465
1985.9	19.6673
1989.64	21.5189
1993.37	23.2989
1997.1	24.7921
2000.83	26.0606
2004.56	27.4227
2008.28	28.7464
2012.01	29.8417
2015.73	30.7876
2019.45	31.4113
2023.17	31.9323
2026.89	32.7337
2030.6	32.7787
2034.32	32.3999
2038.03	31.7214
2041.74	31.292
2045.45	31.9344
2049.16	33.7415
2052.87	38.1368
2056.57	39.5012
2060.27	38.4651
2063.98	38.7258
2067.67	38.4858
2071.37	38.0435
2075.07	38.3318
2078.76	38.8611
2082.46	39.9847
2086.15	41.6314
2089.84	39.6783
2093.53	38.2124
2097.21	37.4981
2100.9	37.317
2104.58	38.3124
2108.26	39.9374
2111.94	39.3149
2115.62	37.7578
2119.3	35.8621
2122.97	38.0687
2126.64	40.872
2130.32	43.3032
2133.99	45.3961
2137.66	46.4299
2141.32	47.3322
2144.99	47.4642
2148.65	46.4222
2152.31	44.7332
2155.97	41.3393
2159.63	40.1272
2163.29	39.241
2166.94	38.6146
2170.6	38.4843
2174.25	38.6501
2177.9	39.1193
2181.55	39.735
2185.2	37.6876
2188.84	37.6231
2192.49	38.3866
2196.13	39.2758
2199.77	39.7051
2203.41	39.3736
2207.05	38.6044
2210.69	37.0502
2214.32	35.059
2217.95	32.6269
2221.59	29.6268
2225.22	27.2596
2228.84	25.6537
2232.47	25.1873
2236.09	25.8826
2239.72	27.1849
2243.34	28.5276
2246.96	29.6522
2250.58	30.5883
2254.2	30.2637
2257.81	28.9326
2261.42	27.5655
2265.04	23.3382
2268.65	20.8295
2272.26	29.5974
2275.86	28.8451
2279.47	28.5389
2283.08	27.099
2286.68	22.6775
2290.28	16.7867
2293.88	11.7529
2297.48	8.29236
2301.07	10.9436
2304.67	13.0098
2308.26	29.0168
2311.85	65.4171
2315.44	150.344
2319.03	161.52
2322.62	78.2684
2326.2	35.9097
2329.79	24.1263
2333.37	19.9091
2336.95	15.4843
2340.53	12.7443
2344.11	12.8241
2347.68	13.414
2351.26	14.6736
2354.83	15.695
2358.4	16.0008
2361.97	15.7972
2365.54	15.5751
2369.11	15.7023
2372.67	14.5727
2376.23	14.7781
2379.8	12.7475
2383.36	11.0601
2386.92	10.3628
2390.47	9.59265
2394.03	9.55806
2397.58	10.2534
2401.14	9.86084
2404.69	12.5257
2408.24	16.2644
2411.78	23.2706
2415.33	22.3576
2418.88	19.5162
2422.42	17.5808
2425.96	12.5472
2429.5	7.70685
2433.04	6.42453
2436.58	7.11043
2440.11	8.45308
2443.65	8.22513
2447.18	7.70233
2450.71	5.58453
2454.24	2.71573
2457.77	0.123642
2461.3	-1.57204
2464.82	-2.09283
2468.34	-2.01486
2471.86	-1.31003
2475.39	-0.345139
2478.9	1.08643
2482.42	3.02138
2485.94	4.78455
2489.45	5.72473
2492.96	6.52686
2496.47	6.58751
2499.98	6.42944
2503.49	3.70508
2507	0.378113
2510.5	-0.901794
2514.01	-1.18665
2517.51	-3.93604
2521.01	-5.54587
2524.51	-6.94118
2528.01	-8.03137
2531.5	-8.65138
2535	-9.00868
2538.49	-8.41217
2541.98	-7.24579
2545.47	-5.46957
2548.96	-4.2579
2552.45	-3.7182
2555.93	-5.02209
2559.42	-6.85667
2562.9	-9.27274
2566.38	-12.8401
2569.86	-14.6341
2573.34	-16.8627
2576.81	-18.7681
2580.29	-19.7643
2583.76	-20.036
2587.23	-20.4204
2590.71	-20.8082
2594.17	-21.2856
2597.64	-21.943
2601.11	-22.8624
2604.57	-24.5061
2608.03	-22.5244
2611.5	-25.6227
2614.96	-27.1166
2618.42	-26.8873
2621.87	-26.0799
2625.33	-24.3511
2628.78	-22.1919
2632.23	-20.7861
2635.68	-20.7118
2639.13	-20.8354
2642.58	-20.5145
2646.03	-20.8016
2649.47	-21.2146
2652.92	-21.6005
2656.36	-22.2261
2659.8	-22.9403
2663.24	-23.7525
2666.68	-22.8406
2670.11	-22.0687
2673.55	-22.1643
2676.98	-25.1581
2680.41	-26.6652
2683.84	-25.1253
2687.27	-23.8326
2690.7	-23.0667
2694.13	-22.8512
2697.55	-24.5662
2700.97	-27.0558
2704.4	-29.8232
2707.82	-31.6356
2711.23	-31.9708
2714.65	-31.0478
2718.07	-29.8912
2721.48	-30.1826
2724.9	-31.7317
2728.31	-33.3019
2731.72	-36.3966
2735.12	-36.852
2738.53	-38.3601
2741.94	-38.018
2745.34	-34.7032
2748.74	-31.5305
2752.14	-29.1599
2755.54	-27.3566
2758.94	-27.2527
2762.34	-27.8753
2765.73	-29.1482
2769.13	-30.9865
2772.52	-33.2182
2775.91	-36.1704
2779.3	-37.6099
2782.69	-37.6245
2786.08	-37.5993
2789.46	-37.2509
2792.85	-35.0223
2796.23	-34.2958
2799.61	-34.1303
2802.99	-34.8852
2806.37	-36.6819
2809.74	-37.0212
2813.12	-36.7407
2816.49	-35.4673
2819.86	-33.3158
2823.23	-31.2532
2826.61	-31.0428
2829.97	-31.5925
2833.34	-32.0559
2836.7	-31.673
2840.07	-33.7993
2843.43	-34.152
2846.79	-32.774
2850.15	-28.4558
2853.51	-24.7535
2856.87	-20.837
2860.22	-20.1213
2863.57	-18.3927
2866.93	-17.17
2870.28	-16.5761
2873.63	-16.7656
2876.98	-17.269
2880.32	-17.6982
2883.67	-17.8257
2887.01	-18.5886
2890.35	-19.443
2893.69	-19.1355
2897.03	-17.8711
2900.37	-14.9371
2903.71	-12.1136
2907.04	-10.2456
2910.38	-10.4116
2913.71	-5.72397
2917.04	-0.649811
2920.37	2.10104
2923.7	-0.984863
2927.03	-1.51288
2930.35	-0.13147
2933.68	3.71811
2937	8.97974
2940.32	14.4891
2943.64	20.8104
2946.96	25.2855
2950.27	29.1066
2953.59	30.5862
2956.91	30.913
2960.22	31.8022
2963.53	33.114
2966.84	35.1085
2970.15	37.431
2973.46	41.6583
2976.76	45.7712
2980.07	50.1914
2983.37	55.7112
2986.67	62.7153
2989.97	69.1454
2993.27	75.1879
2996.57	78.1553
2999.86	81.5675
3003.16	85.1342
3006.45	88.5998
3009.75	92.876
3013.03	98.3121
3016.32	104.155
3019.61	111.691
3022.9	118.909
3026.19	125.021
3029.47	133.319
3032.75	142.24
3036.03	153.67
3039.31	166.599
3042.59	179.459
3045.87	193.175
3049.14	206.298
3052.42	216.172
3055.69	224.351
3058.96	231.83
3062.23	240.22
3065.5	249.392
3068.77	260.905
3072.03	275.307
3075.3	284.353
3078.56	300.127
3081.82	317.828
3085.08	332.658
3088.34	347.973
3091.6	362.108
3094.86	376.371
3098.11	391.858
3101.36	408.44
3104.62	426.335
3107.87	444.702
3111.12	463.637
3114.37	486.977
3117.61	509.513
3120.86	536.575
3124.1	563.632
3127.34	590.701
3130.59	616.635
3133.83	641.931
3137.07	663.163
3140.3	686.4
3143.54	711.57
3146.77	738.703
3150.01	767.783
3153.24	798.116
3156.47	824.266
3159.7	850.96
3162.93	881.69
3166.15	912.872
3169.38	943.996
3172.6	974.726
3175.83	1000.81
3179.05	1031.75
3182.27	1065.02
3185.49	1096.88
3188.7	1128.24
3191.92	1160.06
3195.13	1193.71
3198.35	1215.93
3201.56	1239.57
3204.77	1260.2
3207.98	1281.21
3211.19	1308.26
3214.39	1342.57
3217.6	1372.89
3220.8	1408.34
3224	1436.71
3227.21	1456.57
3230.41	1470.35
3233.6	1484.27
3236.8	1495.02
3240	1510.01
3243.19	1528.03
3246.39	1544.37
3249.58	1567.78
3252.77	1589.67
3255.96	1607.4
3259.15	1624.92
3262.33	1640.7
3265.52	1657.33
3268.7	1671.76
3271.89	1688.33
3275.07	1707.04
3278.25	1726.68
3281.43	1743.6
3284.6	1761.45
3287.78	1774
3290.95	1782.53
3294.13	1792.36
3297.3	1804.26
3300.47	1823.31
3303.64	1848.08
3306.81	1874.78
3309.98	1906.5
3313.14	1942.81
3316.31	1980.88
3319.47	2011.84
3322.63	2048.12
3325.79	2082.68
3328.95	2117.7
3332.11	2152.73
3335.27	2180.77
3338.42	2220.92
3341.58	2258.99
3344.73	2284.72
3347.88	2310.75
3351.03	2337.73
3354.18	2370.1
3357.33	2403.55
3360.47	2443.12
3363.62	2492.16
3366.76	2539.09
3369.91	2581.46
3373.05	2619.98
3376.19	2650.4
3379.32	2675.79
3382.46	2681.61
3385.6	2696.94
3388.73	2723.77
3391.87	2769.54
3395	2801.78
3398.13	2824.83
3401.26	2849.32
3404.39	2867.51
3407.51	2881.41
3410.64	2891.77
3413.76	2896.85
3416.89	2906.2
3420.01	2915.21
3423.13	2930
3426.25	2941.57
3429.37	2949.1
3432.48	2952.17
3435.6	2946.71
3438.71	2939.45
3441.83	2929.48
3444.94	2910.84
3448.05	2891.15
3451.16	2866.22
3454.27	2867.45
3457.37	2861.73
3460.48	2853.8
3463.58	2828.99
3466.69	2785.31
3469.79	2747.32
3472.89	2718.64
3475.99	2689.33
3479.08	2658.41
3482.18	2623.66
3485.28	2586.53
3488.37	2543.67
3491.46	2493.67
3494.55	2442.07
3497.64	2396.15
3500.73	2354.45
3503.82	2309.95
3506.91	2258.84
3509.99	2202.3
3513.08	2147.05
3516.16	2096.7
3519.24	2049.7
3522.32	2000.43
3525.4	1947.47
3528.48	1894.91
3531.55	1843.5
3534.63	1792.84
3537.7	1742.32
3540.78	1694.27
3543.85	1632.92
3546.92	1579.63
3549.99	1529.76
3553.05	1483.14
3556.12	1436.11
3559.19	1388.07
3562.25	1343.25
3565.31	1302.48
3568.37	1264.88
3571.43	1230.17
3574.49	1194.78
3577.55	1159.64
3580.61	1124.89
3583.66	1090.65
3586.72	1055.45
3589.77	1009.93
3592.82	968.101
3595.87	934.587
3598.92	905.675
3601.97	875.836
3605.02	842.493
3608.06	802.473
3611.11	764.283
3614.15	727.728
3617.19	692.554
3620.23	661.135
3623.27	634.549
3626.31	604.919
3629.34	575.556
3632.38	545.809
3635.41	504.882
3638.45	459.365
3641.48	423.646
3644.51	391.352
3647.54	354.989
3650.57	334.284
3653.59	294.87
3656.62	257.606
3659.65	220.889
3662.67	191.989
3665.69	165.735
3668.71	138.76
3671.73	114.646
3674.75	95.1341
3677.77	77.3955
3680.78	55.8079
3683.8	36.1426
3686.81	16.4122
3689.82	-1.59637
3692.84	-17.7817
3695.84	-31.5979
3698.85	-42.9377
3701.86	-51.4363
3704.87	-57.5855
3707.87	-61.9884
3710.88	-66.97
3713.88	-71.4286
3716.88	-76.4194
3719.88	-82.1797
3722.88	-88.5949
3725.88	-95.8775
3728.88	-102.796
3731.87	-108.155
3734.87	-111.684
3737.86	-115.279
3740.85	-115.068
3743.84	-115.133
3746.83	-117.123
3749.82	-119.412
3752.81	-121.849
3755.79	-126.458
3758.78	-133.872
3761.76	-124.253
3764.74	-123.551
3767.73	-122.336
3770.71	-123.109
3773.68	-124.304
3776.66	-125.614
3779.64	-126.205
3782.61	-125.916
3785.59	-125.092
3788.56	-124.629
3791.53	-123.155
3794.5	-121.618
3797.47	-120.821
3800.44	-121.914
3803.41	-122.449
3806.37	-122.971
3809.34	-121.182
3812.3	-117.343
3815.26	-115.047
3818.22	-111.253
3821.18	-108.812
3824.14	-107.023
3827.1	-105.808
3830.06	-104.671
3833.01	-103.486
3835.96	-102.514
3838.92	-100.505
3841.87	-98.4655
3844.82	-95.8572
3847.77	-93.3456
3850.72	-91.3875
3853.66	-89.8626
3856.61	-88.9926
3859.55	-89.4268
3862.5	-90.4771
3865.44	-92.0084
3868.38	-89.5553
3871.32	-86.7648
3874.26	-83.7718
3877.2	-80.5566
3880.13	-78.1557
3883.07	-76.1436
3886	-77.2411
3888.94	-77.5223
3891.87	-74.7979
3894.8	-70.4509
3897.73	-65.3077
3900.66	-62.0956
3903.58	-57.5872
3906.51	-54.3719
3909.43	-51.6466
3912.36	-47.4097
3915.28	-46.265
3918.2	-51.6318
3921.12	-52.3326
3924.04	-50.0904
3926.96	-48.0519
3929.87	-44.9978
3932.79	-44.3192
3935.7	-42.493
3938.62	-40.036
3941.53	-37.7583
3944.44	-34.9418
3947.35	-33.8128
3950.26	-36.1423
3953.17	-35.1608
3956.07	-34.1649
3958.98	-33.1844
3961.88	-33.9001
3964.78	-32.2974
3967.69	-29.8042
3970.59	-27.3149
3973.49	-26.5087
3976.38	-25.8622
3979.28	-25.9652
3982.18	-22.6131
3985.07	-21.3913
3987.97	-20.8625
3990.86	-20.5107
3993.75	-21.8597
3996.64	-23.2345
3999.53	-23.9719