File: Data/3-Raman/processed/bu32-A-FF1-FI01-s.txt
#Acq. time (s)=	15
#Accumulations=	3
#Range (cm-¹)=	50...5000
#Windows=	1
#Auto scanning=	Off
#Autofocus=	Off
#Macrospot=	Off
#AutoExposure=	Off
#Spike filter=	Multiple accum.
#Delay time (s)=	0
#Binning=	1
#Readout mode=	Signal
#DeNoise=	Lite
#ICS correction=	Off
#Dark correction=	Off
#Inst. Process=	Off
#Detector temperature (°C)=	-60.09
#Instrument=	LabRAM HR Evol
#Detector=	SIN-EM FIVIS
#Objective=	x100_VIS
#Grating=	150 (500nm)
#ND Filter=	100%
#Laser=	532nm_Edge
#Hole=	30.0125
#Temperature=	0
#Range=	Visible
#StageXY=	75x50mm Scan+
#StageZ=	Z motor
#X (µm)=	-16402.7
#Y (µm)=	2645.5
#Z (µm)=	-384.6
#Full time(s)=	47
#Project=	Buranga
#Sample=	BU18FA32_A
#Site=	A_FF1
#Title=	32-A_FF1_FI01_solid
#Remark=
#Date=	09.07.2019 14:19
#Acquired=	09.07.2019 14:19:38
#Base:Fit=	16.12.2021 14:49:03
#Base:Sub=	16.12.2021 14:49:05
#Data Range:Extract=	16.12.2021 14:49:22
98.6609	1219.55
103.286	1021.12
107.909	753.817
112.53	509.547
117.146	457.672
121.762	856.606
126.376	3335.86
130.988	3332.06
135.595	1789.15
140.202	899.977
144.807	331.998
149.41	108.709
154.008	-0.00341797
158.606	175.191
163.201	481.33
167.795	1129.06
172.384	2229.48
176.973	2679.83
181.559	1317.7
186.142	1428.18
190.724	2051.81
195.304	3101.47
199.881	4546.11
204.454	5659.66
209.028	5782.38
213.598	4752.44
218.165	3763.37
222.731	2913.63
227.295	2206.09
231.855	1657.11
236.415	1225.65
240.972	924.415
245.525	740.696
250.078	659.345
254.629	691.977
259.175	774.581
263.722	1025.41
268.264	889.897
272.805	667.302
277.345	482.288
281.88	319.22
286.415	203.81
290.948	132.217
295.477	111.022
300.005	116.229
304.529	153.05
309.053	277.49
313.575	537.609
318.093	504.978
322.61	353.444
327.123	214.348
331.636	127.678
336.145	96.9966
340.653	179.24
345.157	378
349.662	742.859
354.164	2128.87
358.661	2509.26
363.159	1536.28
367.652	875.278
372.145	504.004
376.634	328.149
381.123	230.88
385.608	379.885
390.092	582.032
394.572	769.569
399.052	961.101
403.528	1125
408.004	1307.96
412.475	1546.14
416.947	1806.79
421.414	2034.19
425.881	2241.82
430.343	2419.14
434.806	2539.31
439.264	2741.85
443.723	2946.16
448.177	3229.3
452.629	4146.15
457.081	6875.91
461.528	15155.3
465.976	22748.6
470.419	14187.9
474.862	6482.14
479.301	3545.3
483.738	2469.03
488.175	1974.98
492.607	1678.47
497.04	1498.7
501.468	1733.36
505.894	2163.69
510.32	2546.58
514.742	2849
519.164	3077.8
523.581	3226.96
527.997	3298.33
532.412	3302.92
536.823	3197.17
541.232	3019.56
545.641	2780.99
550.046	2626.71
554.449	2625.67
558.851	2757.37
563.25	2760.18
567.646	2639.88
572.042	2416.84
576.434	2277.4
580.824	2158.4
585.214	2235.28
589.599	2500.75
593.983	3013.76
598.367	3844.36
602.746	4519.64
607.123	4709.29
611.498	3854.11
615.873	2989.22
620.244	2460.74
624.613	2033.86
628.98	1682.5
633.346	1406.41
637.709	1188.53
642.069	1031.69
646.428	935.899
650.786	881.567
655.14	884.661
659.492	916.959
663.842	1012.31
668.192	1030.44
672.538	923.487
676.882	702.305
681.223	561.368
685.563	467.059
689.902	451.946
694.238	435.092
698.571	392.17
702.902	312.992
707.231	240.547
711.559	184.975
715.886	144.492
720.209	113.298
724.529	87.144
728.848	64.2487
733.165	44.7521
737.48	28.7419
741.792	16.3889
746.105	7.45068
750.413	2.17639
754.72	0.031189
759.024	1.57916
763.327	6.32813
767.627	14.632
771.925	27.1039
776.221	43.9434
780.518	56.9562
784.81	68.9831
789.1	90.1824
793.388	140.385
797.674	214.063
801.958	294.079
806.24	565.702
810.52	737.565
814.797	328.584
819.073	179.089
823.347	113.631
827.619	84.7015
831.888	74.3382
836.156	68.6766
840.422	66.9406
844.685	62.8676
848.947	63.6987
853.206	55.4936
857.464	52.2091
861.719	47.4107
865.973	51.7405
870.224	56.1289
874.474	63.1161
878.721	79.3992
882.967	90.0967
887.21	89.3667
891.452	77.5322
895.691	55.2764
899.929	39.1138
904.164	25.3945
908.397	26.8242
912.629	34.2198
916.858	53.5837
921.086	83.8324
925.311	124.43
929.534	186.039
933.756	265.206
937.975	372.131
942.191	494.714
946.406	630.02
950.619	779.133
954.831	901.224
959.04	1053.2
963.248	1251.06
967.453	1493.78
971.657	1785.05
975.858	2283.73
980.056	2919.35
984.253	3573.15
988.449	3818.06
992.643	3225.25
996.834	2389.81
1001.02	1919.46
1005.21	1734.75
1009.4	1922.03
1013.58	2354.26
1017.76	3137.93
1021.94	4087.31
1026.12	4553.28
1030.29	4503.2
1034.47	3955.31
1038.64	3362.93
1042.81	2830.73
1046.98	2290.5
1051.14	1728.22
1055.3	1383.9
1059.47	1212.13
1063.63	1175.15
1067.78	1318.72
1071.94	1558.25
1076.09	1834.83
1080.25	2147.58
1084.4	2155.4
1088.54	1762.28
1092.69	1444.74
1096.83	1190.35
1100.98	1021.89
1105.12	988.279
1109.26	1038.21
1113.39	1195
1117.53	1324.63
1121.66	1277.72
1125.79	1061.54
1129.92	813.547
1134.04	631.637
1138.17	496.771
1142.29	411.598
1146.41	364.466
1150.53	405.02
1154.65	457.248
1158.76	619.898
1162.88	656.509
1166.99	383.347
1171.1	242.545
1175.2	168.988
1179.31	121.9
1183.41	82.863
1187.51	61.2725
1191.61	46.8079
1195.71	36.9796
1199.81	31.3528
1203.9	28.537
1207.99	29.3512
1212.08	33.515
1216.17	43.2343
1220.26	53.901
1224.34	65.1581
1228.42	75.8237
1232.5	84.8652
1236.58	75.8174
1240.66	57.8042
1244.73	30.3269
1248.81	26.6349
1252.88	24.667
1256.95	26.095
1261.02	29.1005
1265.08	34.7572
1269.14	35.41
1273.2	38.9449
1277.27	41.6367
1281.32	33.6018
1285.38	22.7028
1289.43	10.0696
1293.48	1.31699
1297.53	-5.28476
1301.58	-9.34058
1305.63	-11.4299
1309.67	-10.1225
1313.72	-8.02042
1317.76	-4.80432
1321.8	-1.47556
1325.83	1.4408
1329.87	3.95825
1333.9	4.09938
1337.93	4.59561
1341.96	4.22762
1345.99	3.2677
1350.02	2.39413
1354.04	4.41539
1358.06	11.4081
1362.08	20.8278
1366.1	31.6416
1370.12	45.3293
1374.13	58.8141
1378.14	126.619
1382.16	203.483
1386.16	211.707
1390.17	123.207
1394.18	68.2368
1398.18	41.5562
1402.18	20.3792
1406.18	9.22902
1410.18	5.11812
1414.18	2.20647
1418.17	5.12498
1422.16	7.43236
1426.15	8.39696
1430.14	6.88399
1434.13	0.759872
1438.11	-0.211365
1442.1	-1.05827
1446.08	1.19357
1450.06	3.28546
1454.04	6.65459
1458.01	11.196
1461.98	13.2175
1465.96	14.392
1469.93	16.0466
1473.9	17.7795
1477.86	18.9772
1481.83	19.3568
1485.79	18.8841
1489.75	18.3133
1493.71	17.2768
1497.67	16.9219
1501.62	17.1537
1505.58	17.9268
1509.53	20.6819
1513.48	22.6723
1517.43	24.6306
1521.38	26.3415
1525.32	28.3258
1529.26	31.3252
1533.2	34.8248
1537.14	37.7371
1541.08	40.2122
1545.02	41.6213
1548.95	42.5312
1552.88	42.3323
1556.81	43.0553
1560.74	45.0194
1564.67	46.544
1568.6	49.2747
1572.52	52.9042
1576.44	57.6776
1580.36	60.205
1584.28	63.0486
1588.19	66.4771
1592.11	70.4928
1596.02	75.1659
1599.93	80.5072
1603.84	86.5155
1607.75	92.4789
1611.65	98.9089
1615.56	104.001
1619.46	107.97
1623.36	111.004
1627.25	113.133
1631.15	114.384
1635.05	114.748
1638.94	114.342
1642.83	112.868
1646.72	110.591
1650.61	107.113
1654.49	103.078
1658.38	98.811
1662.26	95.895
1666.14	91.6368
1670.02	86.9355
1673.89	82.571
1677.77	78.1796
1681.64	74.0669
1685.51	64.5668
1689.38	57.5626
1693.25	50.4765
1697.12	45.8229
1700.98	39.2194
1704.85	33.9884
1708.71	28.7921
1712.57	26.8958
1716.42	26.3764
1720.28	25.9158
1724.13	25.4235
1727.99	24.9242
1731.84	24.3633
1735.69	23.7317
1739.53	22.978
1743.38	22.1087
1747.22	19.5724
1751.06	17.2672
1754.9	17.2442
1758.74	16.2199
1762.58	15.5124
1766.41	13.6343
1770.25	12.2341
1774.08	10.3689
1777.91	9.37234
1781.73	8.59866
1785.56	8.48744
1789.39	7.5975
1793.21	6.0885
1797.03	4.9619
1800.85	4.05264
1804.67	3.67255
1808.48	3.13727
1812.3	2.5237
1816.11	1.42708
1819.92	0.767181
1823.73	0.903336
1827.54	-0.621643
1831.34	-0.575104
1835.14	1.03127
1838.95	0.979385
1842.75	1.38805
1846.55	-2.06451
1850.34	-4.68372
1854.14	-1.73015
1857.93	1.97054
1861.72	3.95003
1865.51	5.92407
1869.3	7.87624
1873.09	9.243
1876.87	10.7527
1880.66	12.6015
1884.44	13.1468
1888.22	13.2589
1892	12.9372
1895.77	12.6331
1899.55	12.2338
1903.32	11.707
1907.09	11.0955
1910.86	10.6764
1914.63	10.6355
1918.4	11.1318
1922.16	11.9983
1925.92	13.829
1929.68	15.1218
1933.44	16.4732
1937.2	16.2463
1940.96	15.8054
1944.71	13.8978
1948.46	13.1055
1952.22	13.397
1955.97	14.3184
1959.71	15.9144
1963.46	18.159
1967.2	20.4328
1970.95	22.1937
1974.69	23.6387
1978.43	24.274
1982.17	24.0099
1985.9	23.521
1989.64	22.6521
1993.37	22.7034
1997.1	22.6077
2000.83	22.6795
2004.56	23.5413
2008.28	25.6934
2012.01	27.8178
2015.73	30.3582
2019.45	31.5915
2023.17	32.009
2026.89	32.3817
2030.6	32.759
2034.32	32.1268
2038.03	31.6036
2041.74	31.8629
2045.45	32.4301
2049.16	33.1101
2052.87	33.5544
2056.57	33.8835
2060.27	34.0679
2063.98	34.1748
2067.67	34.2633
2071.37	34.4925
2075.07	34.659
2078.76	34.7987
2082.46	35.0027
2086.15	35.249
2089.84	35.5269
2093.53	35.895
2097.21	36.2798
2100.9	37.3895
2104.58	38.4196
2108.26	38.8422
2111.94	38.6858
2115.62	37.7514
2119.3	37.2907
2122.97	37.1497
2126.64	36.7288
2130.32	36.1698
2133.99	35.0574
2137.66	34.0135
2141.32	32.7968
2144.99	27.415
2148.65	27.5287
2152.31	29.0194
2155.97	29.8841
2159.63	30.4121
2163.29	30.8957
2166.94	31.2717
2170.6	31.8877
2174.25	32.3979
2177.9	33.047
2181.55	33.5741
2185.2	33.908
2188.84	33.2095
2192.49	32.3133
2196.13	30.7937
2199.77	29.8365
2203.41	27.3156
2207.05	24.9482
2210.69	23.4698
2214.32	22.4493
2217.95	24.1335
2221.59	25.9773
2225.22	29.145
2228.84	30.0332
2232.47	28.625
2236.09	27.1215
2239.72	26.3668
2243.34	26.3093
2246.96	25.4269
2250.58	24.6227
2254.2	23.3077
2257.81	22.7044
2261.42	23.6259
2265.04	23.4514
2268.65	23.1373
2272.26	21.9167
2275.86	20.2988
2279.47	18.0679
2283.08	16.8088
2286.68	16.7294
2290.28	17.2367
2293.88	19.106
2297.48	21.9898
2301.07	23.8314
2304.67	23.7427
2308.26	22.541
2311.85	20.1984
2315.44	16.8451
2319.03	16.8165
2322.62	19.4316
2326.2	23.4916
2329.79	26.6647
2333.37	29.2605
2336.95	30.1427
2340.53	31.2394
2344.11	28.7543
2347.68	25.1634
2351.26	19.3931
2354.83	15.8451
2358.4	17.6116
2361.97	19.7325
2365.54	23.2012
2369.11	21.0345
2372.67	7.95839
2376.23	13.0164
2379.8	18.455
2383.36	20.5797
2386.92	21.3009
2390.47	21.5003
2394.03	21.5904
2397.58	21.2093
2401.14	20.6953
2404.69	19.3115
2408.24	17.4785
2411.78	15.6205
2415.33	13.2335
2418.88	19.8436
2422.42	21.4138
2425.96	23.9732
2429.5	21.553
2433.04	19.1775
2436.58	17.466
2440.11	17.0095
2443.65	16.4818
2447.18	18.7553
2450.71	16.5647
2454.24	14.8468
2457.77	13.6419
2461.3	12.7811
2464.82	12.0755
2468.34	11.3544
2471.86	10.6464
2475.39	9.86568
2478.9	8.95847
2482.42	7.70229
2485.94	8.45619
2489.45	10.2319
2492.96	11.7945
2496.47	12.8341
2499.98	13.8877
2503.49	14.2427
2507	13.5451
2510.5	11.7375
2514.01	9.59731
2517.51	8.59242
2521.01	8.87648
2524.51	9.49507
2528.01	10.2435
2531.5	10.9931
2535	11.6115
2538.49	12.0015
2541.98	12.0804
2545.47	11.7286
2548.96	10.7609
2552.45	10.8347
2555.93	11.1328
2559.42	10.5691
2562.9	9.68033
2566.38	7.8315
2569.86	6.3376
2573.34	6.35912
2576.81	5.25677
2580.29	4.30991
2583.76	3.61041
2587.23	2.92249
2590.71	2.88567
2594.17	3.97284
2597.64	6.27814
2601.11	7.29568
2604.57	4.2999
2608.03	2.2896
2611.5	0.677032
2614.96	-1.53041
2618.42	-3.03
2621.87	-2.67931
2625.33	-0.955994
2628.78	-0.707916
2632.23	0.487411
2635.68	2.25418
2639.13	4.24075
2642.58	6.00563
2646.03	7.54442
2649.47	8.70891
2652.92	7.04013
2656.36	0.489868
2659.8	-0.160339
2663.24	-0.284088
2666.68	2.78828
2670.11	1.39404
2673.55	0.212509
2676.98	-0.721024
2680.41	-1.33896
2683.84	0.662491
2687.27	1.71117
2690.7	6.07648
2694.13	8.90688
2697.55	10.6656
2700.97	11.4454
2704.4	11.3821
2707.82	10.8819
2711.23	8.37543
2714.65	5.70029
2718.07	7.20551
2721.48	9.51323
2724.9	13.3499
2728.31	10.5883
2731.72	7.8792
2735.12	8.17874
2738.53	8.31259
2741.94	8.56683
2745.34	8.64037
2748.74	9.86852
2752.14	10.6053
2755.54	7.73102
2758.94	3.68472
2762.34	0.378754
2765.73	-1.73778
2769.13	-2.4749
2772.52	-1.77173
2775.91	1.97073
2779.3	6.51712
2782.69	11.3292
2786.08	16.4362
2789.46	17.1864
2792.85	15.8868
2796.23	12.4086
2799.61	7.40086
2802.99	1.73885
2806.37	0.417465
2809.74	3.30685
2813.12	8.09608
2816.49	11.1557
2819.86	14.2714
2823.23	16.8382
2826.61	17.7904
2829.97	15.9409
2833.34	14.9325
2836.7	15.3695
2840.07	14.3353
2843.43	15.0573
2846.79	15.869
2850.15	17.8882
2853.51	20.6431
2856.87	23.6515
2860.22	25.827
2863.57	27.205
2866.93	27.8457
2870.28	25.3698
2873.63	25.9819
2876.98	26.8421
2880.32	26.703
2883.67	28.0901
2887.01	29.6693
2890.35	30.8339
2893.69	30.7517
2897.03	30.2082
2900.37	31.5965
2903.71	34.7684
2907.04	35.9481
2910.38	37.7275
2913.71	38.4335
2917.04	40.4904
2920.37	41.8579
2923.7	43.4388
2927.03	46.1023
2930.35	46.5284
2933.68	47.0926
2937	48.082
2940.32	48.8002
2943.64	49.6239
2946.96	50.6708
2950.27	53.2769
2953.59	57.0104
2956.91	61.5656
2960.22	64.161
2963.53	66.9168
2966.84	69.7084
2970.15	72.5464
2973.46	72.9073
2976.76	72.5859
2980.07	74.0147
2983.37	81.6906
2986.67	90.0667
2989.97	95.3201
2993.27	100.221
2996.57	98.01
2999.86	93.4312
3003.16	105.129
3006.45	113.196
3009.75	117.103
3013.03	124.97
3016.32	128.367
3019.61	131.071
3022.9	133.568
3026.19	136.261
3029.47	139.413
3032.75	143.987
3036.03	149.965
3039.31	155.371
3042.59	160.721
3045.87	166.534
3049.14	172.915
3052.42	179.818
3055.69	187.265
3058.96	195.299
3062.23	205.056
3065.5	214.982
3068.77	223.575
3072.03	230.481
3075.3	238.315
3078.56	247.002
3081.82	257.532
3085.08	271.639
3088.34	288.027
3091.6	302.295
3094.86	313.068
3098.11	318.741
3101.36	325.955
3104.62	334.841
3107.87	345.643
3111.12	357.915
3114.37	371.416
3117.61	385.81
3120.86	401.481
3124.1	417.781
3127.34	434.76
3130.59	452.369
3133.83	470.402
3137.07	484.88
3140.3	495.511
3143.54	511.645
3146.77	530.227
3150.01	552.891
3153.24	577.915
3156.47	598.194
3159.7	610.855
3162.93	625.595
3166.15	642.389
3169.38	661.475
3172.6	682.706
3175.83	708.344
3179.05	734.35
3182.27	764.613
3185.49	787.722
3188.7	809.636
3191.92	832.631
3195.13	854.006
3198.35	873.404
3201.56	898.297
3204.77	924.121
3207.98	950.611
3211.19	974.87
3214.39	999.514
3217.6	1025.24
3220.8	1052.17
3224	1080.76
3227.21	1112.64
3230.41	1148.09
3233.6	1179.02
3236.8	1208.65
3240	1234.85
3243.19	1258.58
3246.39	1274.68
3249.58	1292.61
3252.77	1312.94
3255.96	1335.82
3259.15	1369.28
3262.33	1407.6
3265.52	1446.66
3268.7	1481.17
3271.89	1512.2
3275.07	1538.61
3278.25	1562.77
3281.43	1583.12
3284.6	1601.88
3287.78	1619.38
3290.95	1637.34
3294.13	1654.93
3297.3	1670.3
3300.47	1697.91
3303.64	1708.27
3306.81	1717.93
3309.98	1743.27
3313.14	1767.37
3316.31	1782.11
3319.47	1795.36
3322.63	1798.23
3325.79	1813.54
3328.95	1832.73
3332.11	1853.84
3335.27	1877.22
3338.42	1899.9
3341.58	1925.3
3344.73	1953.45
3347.88	1984.89
3351.03	2017.43
3354.18	2050.87
3357.33	2085.75
3360.47	2121.82
3363.62	2158
3366.76	2195.65
3369.91	2235.7
3373.05	2278.66
3376.19	2324.12
3379.32	2373.08
3382.46	2425.77
3385.6	2475.06
3388.73	2528.74
3391.87	2593.23
3395	2654.79
3398.13	2733.84
3401.26	2819.35
3404.39	2909.15
3407.51	2990.05
3410.64	3050.42
3413.76	3096.36
3416.89	3113.54
3420.01	3088.58
3423.13	3037.94
3426.25	2982.65
3429.37	2937.27
3432.48	2904.71
3435.6	2884.56
3438.71	2874.72
3441.83	2878.1
3444.94	2882.71
3448.05	2900.4
3451.16	2927.99
3454.27	2969.59
3457.37	3022.39
3460.48	3079.66
3463.58	3159.69
3466.69	3254.29
3469.79	3367.97
3472.89	3494.36
3475.99	3625.71
3479.08	3746.39
3482.18	3846.07
3485.28	3921.65
3488.37	3957.08
3491.46	3951.54
3494.55	3898.2
3497.64	3823.89
3500.73	3720.85
3503.82	3612.25
3506.91	3510.22
3509.99	3410.27
3513.08	3312.2
3516.16	3205.41
3519.24	3094.52
3522.32	2978.43
3525.4	2839.26
3528.48	2703.65
3531.55	2566.67
3534.63	2432.23
3537.7	2308.82
3540.78	2183.51
3543.85	2076.08
3546.92	1997.8
3549.99	1947.67
3553.05	1902.13
3556.12	1858.38
3559.19	1822.74
3562.25	1786.06
3565.31	1745.93
3568.37	1699.6
3571.43	1637.43
3574.49	1571.76
3577.55	1506.32
3580.61	1442.03
3583.66	1378.29
3586.72	1317.71
3589.77	1267.91
3592.82	1225.36
3595.87	1200.97
3598.92	1188.1
3601.97	1174.85
3605.02	1158.66
3608.06	1134.7
3611.11	1110.26
3614.15	1085.11
3617.19	1059.97
3620.23	1039.67
3623.27	1023.05
3626.31	1001.69
3629.34	979.941
3632.38	956.16
3635.41	928.318
3638.45	897.242
3641.48	864.916
3644.51	831.867
3647.54	797.562
3650.57	762.042
3653.59	722.546
3656.62	680.578
3659.65	636.387
3662.67	592.863
3665.69	547.642
3668.71	504.568
3671.73	464.235
3674.75	426.523
3677.77	390.998
3680.78	358.683
3683.8	328.726
3686.81	301.458
3689.82	277.578
3692.84	253.858
3695.84	233.016
3698.85	207.189
3701.86	188.739
3704.87	175.082
3707.87	162.312
3710.88	149.772
3713.88	139.957
3716.88	127.287
3719.88	117.535
3722.88	103.251
3725.88	97.5115
3728.88	93.7142
3731.87	91.698
3734.87	90.547
3737.86	86.9911
3740.85	80.5141
3743.84	76.5369
3746.83	71.2058
3749.82	68.3059
3752.81	66.4962
3755.79	64.8373
3758.78	62.7757
3761.76	60.2363
3764.74	56.6519
3767.73	52.0335
3770.71	47.7314
3773.68	45.7549
3776.66	42.8861
3779.64	39.8814
3782.61	35.2496
3785.59	29.0849
3788.56	24.2626
3791.53	24.7562
3794.5	26.1182
3797.47	27.6301
3800.44	29.1478
3803.41	30.5224
3806.37	32.0142
3809.34	32.3666
3812.3	32.7867
3815.26	32.9369
3818.22	31.9691
3821.18	30.0395
3824.14	27.4132
3827.1	25.2014
3830.06	22.5812
3833.01	20.3459
3835.96	18.6292
3838.92	15.4437
3841.87	12.5234
3844.82	9.1765
3847.77	10.7178
3850.72	9.28577
3853.66	8.64656
3856.61	8.63786
3859.55	3.82054
3862.5	4.33226
3865.44	10.5461
3868.38	11.8873
3871.32	13.3709
3874.26	10.2021
3877.2	7.91147
3880.13	6.10918
3883.07	4.48625
3886	3.716
3888.94	3.95439
3891.87	5.06894
3894.8	7.47371
3897.73	9.80545
3900.66	11.938
3903.58	12.5558
3906.51	11.4017
3909.43	9.45494
3912.36	4.56113
3915.28	7.33313
3918.2	13.0644
3921.12	8.42694
3924.04	0.63768
3926.96	-1.58273
3929.87	-0.623703
3932.79	1.36583
3935.7	4.06253
3938.62	6.73401
3941.53	8.91284
3944.44	9.4034
3947.35	9.27359
3950.26	9.66321
3953.17	10.6156
3956.07	10.9404
3958.98	11.6609
3961.88	13.0535
3964.78	14.9494
3967.69	15.6661
3970.59	15.7278
3973.49	15.9633
3976.38	14.5937
3979.28	12.929
3982.18	11.1479
3985.07	9.51883
3987.97	8.02043
3990.86	6.68785
3993.75	5.60631
3996.64	4.41663
3999.53	1.02266