File: Data/3-Raman/processed/bu32-b-ff2-fi05-v_1800 (450-850nm)_532nm_edge_100%_x100_vis_lwd_h30um_30sx2_01.txt
#Acq. time (s)=	30
#Accumulations=	2
#Range (cm-¹)=	1200...2999
#Windows=	5
#Auto scanning=	Off
#Autofocus=	Off
#Macrospot=	Off
#AutoExposure=	Off
#Spike filter=	Multiple accum.
#Delay time (s)=	2
#Binning=	1
#Readout mode=	Signal
#DeNoise=	Off
#ICS correction=	On
#Dark correction=	Off
#Inst. Process=	Off
#Detector Gain=	Best Dynamic
#Detector ADC=	50 kHz EM
#Detector EM gain=	150
#Detector temperature (°C)=	-60.09
#Instrument=	LabRAM HR Evol
#Detector=	SIN-EM FIVIS
#Objective=	x100_VIS_LWD
#Grating=	1800 (450-850nm)
#ND Filter=	100%
#Laser=	532nm_Edge
#Hole=	30.0125
#Temperature=	39.9
#Range=	Visible
#StageXY=	75x50mm Scan+
#StageZ=	Z motor
#X (µm)=	0
#Y (µm)=	0
#Z (µm)=	57.1
#Full time(mm:ss)=	5:33
#Project=	21_08_11
#Sample=	BU32
#Site=
#Title=	BU32-B-FF2-FI05-V_1800 (450-850nm)_532nm_Edge_100%_x100_VIS_LWD_H30um_30sX2
#Remark=
#Date=	13.08.2021 16:03
#Acquired=	13.08.2021 16:03:49
#Base:Fit=	16.12.2021 15:06:17
#Base:Fit=	16.12.2021 15:06:22
#Base:Fit=	16.12.2021 15:06:29
#Base:Fit=	16.12.2021 15:06:33
#Base:Sub=	16.12.2021 15:06:35
1200.05	1.87836
1201.44	-0.899048
1202.83	1.91205
1204.22	0.510773
1205.61	2.19864
1207	-2.60208
1208.39	-1.75241
1209.78	-7.16818
1211.16	3.08603
1212.55	2.70538
1213.94	-7.93985
1215.33	1.7514
1216.71	1.33981
1218.1	-6.33984
1219.49	2.11429
1220.87	1.09283
1222.26	-5.68274
1223.64	0.154449
1225.03	4.36343
1226.41	-0.777161
1227.79	5.84552
1229.18	-1.57736
1230.56	6.21506
1231.94	1.46848
1233.33	1.56821
1234.71	-4.39932
1236.09	-3.14212
1237.47	-0.291595
1238.86	-5.8111
1240.24	2.66251
1241.62	0.62207
1243	14.5073
1244.38	-1.09955
1245.76	2.82178
1247.14	3.94873
1248.52	0.740784
1249.9	5.00797
1251.27	3.77301
1252.65	2.56595
1254.03	8.0708
1255.41	5.12723
1256.79	-0.904907
1258.16	11.6096
1259.54	10.8464
1260.92	17.8687
1262.29	18.4908
1263.67	66.9886
1265.04	49.2454
1266.42	30.6309
1267.79	17.6982
1269.17	20.2218
1270.54	16.8326
1271.92	13.9482
1273.29	9.32312
1274.66	20.1042
1276.04	15.2831
1277.41	27.3347
1278.78	23.6192
1280.15	20.5251
1281.53	64.0804
1282.9	198.301
1284.27	1292.32
1285.64	223.677
1287.01	54.128
1288.38	27.8696
1289.75	32.5282
1291.12	28.3891
1292.49	29.5449
1293.86	28.0332
1295.23	17.9595
1296.6	15.3355
1297.96	12.0419
1299.33	16.2261
1300.7	11.1576
1302.07	14.6186
1303.43	18.846
1304.8	23.113
1306.17	15.5284
1307.53	18.8524
1308.9	22.2626
1310.26	11.897
1311.63	12.1531
1312.99	15.4517
1314.36	12.4094
1315.72	21.1471
1317.08	12.8224
1318.45	23.5972
1319.81	17.38
1321.17	21.403
1322.53	19.1277
1323.9	16.0662
1325.26	12.8395
1326.62	14.594
1327.98	21.7631
1329.34	3.03189
1330.7	14.4708
1332.06	24.5488
1333.42	17.8269
1334.78	15.4588
1336.14	10.0722
1337.5	17.3297
1338.86	21.4045
1340.22	17.3981
1341.58	17.3951
1342.93	10.9244
1344.29	14.1479
1345.65	14.9046
1347	9.25476
1348.36	15.4223
1349.72	19.4075
1351.07	15.0081
1352.43	23.6078
1353.78	14.2615
1355.14	23.2289
1356.49	15.0536
1357.85	25.3156
1359.2	16.855
1360.56	17.6464
1361.91	24.9034
1363.26	17.8368
1364.61	27.2079
1365.97	16.5979
1367.32	11.2813
1368.67	25.984
1370.02	38.3362
1371.37	25.6153
1372.72	28.3775
1374.07	21.1253
1375.42	20.1838
1376.77	27.1152
1378.12	48.438
1379.47	46.394
1380.82	38.628
1382.17	54.4848
1383.52	56.1634
1384.87	87.3992
1386.21	229.63
1387.56	2364.84
1388.91	242.978
1390.26	75.2511
1391.6	52.3973
1392.95	45.068
1394.3	18.45
1395.64	18.6941
1396.99	25.7422
1398.33	24.866
1399.68	19.9995
1401.02	28.4877
1402.37	29.2318
1403.71	32.3648
1405.05	39.5003
1406.39	23.0333
1407.74	52.9864
1409.08	143.499
1410.42	49.001
1411.76	22.2923
1413.11	15.9554
1414.45	16.9876
1415.79	15.1188
1417.13	29.7878
1418.47	15.5697
1419.81	19.5903
1421.15	14.3441
1422.49	29.5442
1423.83	20.1552
1425.17	14.3281
1426.51	22.5573
1427.84	29.4106
1429.18	17.3576
1430.52	10.7281
1431.86	9.87665
1433.19	12.5504
1434.53	30.171
1435.87	13.8257
1437.2	8.68271
1438.54	11.9385
1439.87	10.2515
1441.21	14.4386
1442.54	13.5845
1443.88	18.6769
1445.21	12.8527
1446.55	20.0084
1447.88	16.9654
1449.21	15.0569
1450.55	7.79968
1451.88	10.8448
1453.21	3.86313
1454.54	4.94168
1455.88	9.20724
1457.21	9.13547
1458.54	11.3072
1459.87	7.27667
1461.2	6.17273
1462.53	10.0603
1463.86	15.3276
1465.19	7.52246
1466.52	13.5539
1467.85	9.55084
1469.18	6.44724
1470.51	3.24274
1471.83	2.14157
1473.16	7.20029
1474.49	7.27115
1475.82	5.22934
1477.14	6.17407
1478.47	8.11264
1479.79	6.85074
1481.12	10.7717
1482.45	14.1297
1483.77	10.1056
1485.1	5.85626
1486.42	3.59921
1487.75	6.55695
1489.07	2.33502
1490.39	7.36273
1491.72	9.36929
1493.04	5.35651
1494.36	7.4942
1495.69	5.17145
1497.01	8.15421
1498.33	5.2001
1499.65	6.39288
1500.97	8.38708
1502.29	9.35669
1503.62	8.29013
1504.93	5.2886
1506.26	7.15289
1507.58	13.3458
1508.89	8.38736
1510.21	6.4021
1511.53	7.91846
1512.85	5.48834
1514.17	2.71371
1515.49	9.4216
1516.81	5.32715
1518.12	6.52573
1519.44	2.67557
1520.76	11.8045
1522.07	3.77347
1523.39	2.49222
1524.71	3.43967
1526.02	5.76544
1527.34	7.79599
1528.65	3.72943
1529.97	4.74017
1531.28	7.98938
1532.59	3.22229
1533.91	2.46313
1535.22	5.28525
1536.54	8.88037
1537.85	8.68936
1539.16	5.12457
1540.47	10.7972
1541.79	7.49078
1543.1	8.19128
1544.41	6.30923
1545.72	4.7211
1547.03	5.89862
1548.34	11.9142
1549.65	15.6468
1550.96	5.72952
1552.27	3.85657
1553.58	7.52057
1554.89	9.22824
1556.2	7.26929
1557.5	4.33661
1558.81	8.9606
1560.12	10.8019
1561.43	8.98102
1562.74	5.14676
1564.04	0.419373
1565.35	7.60202
1566.65	9.16809
1567.96	2.36008
1569.27	2.25714
1570.57	7.34576
1571.88	3.2511
1573.18	5.0752
1574.48	5.39633
1575.79	6.59793
1577.09	12.2174
1578.4	11.9961
1579.7	14.1372
1581	8.10739
1582.3	3.98975
1583.61	6.96991
1584.91	11.0644
1586.21	10.9019
1587.51	5.86517
1588.81	7.09763
1590.11	13.2321
1591.41	8.30463
1592.72	7.99533
1594.01	6.67166
1595.31	11.7151
1596.61	0.864746
1597.91	9.85431
1599.21	1.65927
1600.51	4.20685
1601.81	3.91809
1603.1	5.16733
1604.4	5.81372
1605.7	14.0643
1607	12.5596
1608.29	7.21451
1609.59	6.71362
1610.88	5.57547
1612.18	8.58667
1613.48	6.39349
1614.77	8.36954
1616.07	11.1049
1617.36	14.5098
1618.65	11.9255
1619.95	10.2182
1621.24	6.63675
1622.54	6.01993
1623.83	4.02762
1625.12	10.4256
1626.41	6.21933
1627.56	13.7603
1628.87	5.92499
1630.17	3.9151
1631.48	6.06424
1632.79	10.1276
1634.1	9.20801
1635.4	13.1409
1636.71	9.04999
1638.01	4.05286
1639.32	14.9327
1640.62	10.1801
1641.93	6.20615
1643.23	12.1166
1644.54	9.07513
1645.84	7.21539
1647.15	7.12991
1648.45	4.38589
1649.75	6.53915
1651.05	4.93188
1652.36	6.93115
1653.66	8.00223
1654.96	14.1622
1656.26	3.68173
1657.56	9.57019
1658.86	7.45636
1660.16	8.45557
1661.46	5.81155
1662.77	12.2061
1664.07	6.01773
1665.36	9.17178
1666.66	4.88672
1667.96	4.96405
1669.26	17.2471
1670.56	12.5886
1671.86	13.6248
1673.15	10.7468
1674.45	10.9924
1675.75	13.1364
1677.05	7.25369
1678.34	11.994
1679.64	12.8785
1680.94	8.86157
1682.23	7.92575
1683.53	11.893
1684.82	7.88443
1686.12	10.9614
1687.41	12.9819
1688.71	8.87109
1690	5.78323
1691.29	9.94043
1692.59	3.93073
1693.88	0.669586
1695.17	6.59399
1696.47	6.73178
1697.76	17.2922
1699.05	10.3093
1700.34	1.44827
1701.63	7.21484
1702.92	8.06903
1704.21	5.18536
1705.5	5.1842
1706.79	3.91461
1708.08	0.575287
1709.37	4.25272
1710.66	11.2514
1711.95	5.42899
1713.24	5.8569
1714.53	5.71332
1715.82	2.90485
1717.11	6.38809
1718.39	7.86423
1719.68	10.8319
1720.97	7.69754
1722.25	5.43445
1723.54	3.34152
1724.83	4.03073
1726.11	-1.02808
1727.4	-0.118439
1728.68	5.57306
1729.97	10.585
1731.25	-1.64279
1732.54	6.94537
1733.82	-2.19299
1735.1	-1.62549
1736.39	8.81445
1737.67	0.940033
1738.95	0.630646
1740.24	4.9057
1741.52	-3.96472
1742.8	0.758636
1744.08	-2.27307
1745.36	1.57233
1746.65	-3.50616
1747.93	0.128693
1749.21	-1.59854
1750.49	0.621124
1751.77	1.40869
1753.05	0.189819
1754.33	-0.0341187
1755.6	-0.22641
1756.88	-0.589539
1758.16	0.483215
1759.44	-2.31641
1760.72	-2.44366
1762	6.0224
1763.27	-3.37134
1764.55	-1.15179
1765.83	4.68015
1767.1	-1.08246
1768.38	5.43246
1769.66	5.93796
1770.93	0.571686
1772.21	3.70346
1773.48	-0.85025
1774.76	-4.49283
1776.03	-3.21454
1777.31	5.20178
1778.58	2.07437
1779.85	2.12823
1781.13	0.363373
1782.4	-0.317627
1783.67	9.45038
1784.94	1.08142
1786.22	0.145172
1787.49	6.45139
1788.76	3.26334
1790.03	4.52023
1791.3	0.427429
1792.57	5.32434
1793.84	-3.17267
1795.11	1.13928
1796.38	8.1792
1797.65	1.7168
1798.92	0.767822
1800.19	8.26358
1801.46	0.592621
1802.73	9.49463
1804	8.76797
1805.26	12.0298
1806.53	4.57324
1807.8	9.45001
1809.07	7.61221
1810.33	3.8075
1811.6	3.8291
1812.87	4.05011
1814.13	6.34421
1815.4	5.6188
1816.66	4.73956
1817.93	3.6243
1819.19	5.75119
1820.46	6.91693
1821.72	13.9244
1822.99	8.20679
1824.25	10.1843
1825.51	11.2955
1826.77	14.286
1828.04	8.57693
1829.3	3.64578
1830.56	9.38779
1831.82	4.77603
1833.09	9.80392
1834.35	7.66556
1835.61	7.29523
1836.87	7.83508
1838.13	4.21341
1839.39	9.90613
1840.65	6.23245
1841.91	4.72037
1843.17	2.81171
1844.43	13.4491
1845.69	4.10538
1846.94	9.08728
1848.2	1.46463
1849.46	8.89374
1850.72	4.66324
1851.97	0.730042
1853.23	6.44675
1854.49	2.28375
1855.74	6.8006
1857	5.81317
1858.26	4.63281
1859.51	1.55023
1860.77	2.71521
1862.02	8.50919
1863.28	4.37906
1864.53	6.99799
1865.78	5.55795
1867.04	3.08963
1868.29	3.92474
1869.54	1.05478
1870.8	2.93402
1872.05	5.6351
1873.3	5.47504
1874.56	3.28311
1875.81	3.72171
1877.06	2.22452
1878.31	1.80219
1879.56	-1.76022
1880.81	-0.85437
1882.06	-3.46664
1883.31	-0.638489
1884.56	3.8031
1885.81	-2.37265
1887.06	3.0459
1888.31	7.33481
1889.56	-2.27609
1890.81	8.26147
1892.05	-1.20682
1893.3	-2.64011
1894.55	0.0719299
1895.8	1.18036
1897.04	-1.40472
1898.29	-4.3107
1899.54	-4.53775
1900.78	4.01862
1902.03	6.22186
1903.27	-0.459747
1904.52	-0.49942
1905.76	4.94485
1907.01	-0.765198
1908.25	-0.592499
1909.5	6.32898
1910.74	0.14743
1911.98	4.86816
1913.23	4.02194
1914.47	3.46948
1915.71	3.55457
1916.96	3.36588
1918.2	5.37372
1919.44	3.99643
1920.68	0.369537
1921.92	3.39301
1923.16	-1.47232
1924.41	1.22818
1925.65	5.33466
1926.89	0.967651
1928.12	2.09647
1929.36	9.05081
1930.6	0.846985
1931.84	4.52454
1933.08	3.50696
1934.32	4.49265
1935.56	1.0531
1936.8	6.59311
1938.03	5.46231
1939.27	0.0316162
1940.51	8.09872
1941.75	0.259583
1942.98	5.37473
1944.22	0.751495
1945.45	7.8046
1946.69	12.7333
1947.92	1.21405
1949.16	8.11859
1950.4	7.70679
1951.63	7.24582
1952.86	12.2508
1954.1	5.79968
1955.33	10.6062
1956.56	7.341
1957.8	12.4152
1959.03	4.66852
1960.26	5.44589
1961.5	6.27438
1962.73	-0.360046
1963.96	8.40149
1965.19	5.52325
1966.42	-0.919678
1967.65	9.73462
1968.88	2.86572
1970.11	9.25775
1971.34	7.18274
1972.57	4.35928
1973.8	7.02924
1975.03	7.1264
1976.26	-0.391205
1977.49	3.34943
1978.72	5.16168
1979.95	4.21289
1981.17	5.95352
1982.4	7.52328
1983.63	5.06091
1984.85	6.03506
1986.08	3.66428
1987.31	6.14874
1988.53	2.35629
1989.76	2.46457
1990.98	2.32272
1992.21	1.44357
1993.43	4.41504
1994.66	2.63437
1995.88	7.45737
1997.11	1.93854
1998.33	3.84665
1999.55	4.3667
2000.78	3.05038
2002	-0.122528
2003.22	2.49329
2004.45	6.08121
2005.59	3.29993
2006.83	2.3927
2008.06	8.64731
2009.3	1.65833
2010.54	-4.21597
2011.77	2.33835
2013.01	1.99295
2014.25	-0.470551
2015.48	3.41608
2016.72	4.64023
2017.95	1.38763
2019.19	-2.81384
2020.42	-1.01608
2021.66	4.60861
2022.89	-2.24277
2024.12	-2.57413
2025.36	-0.202271
2026.59	-1.55896
2027.82	0.045105
2029.06	-1.9758
2030.29	-2.27261
2031.52	0.858582
2032.75	-4.28625
2033.98	1.10107
2035.21	3.10754
2036.45	-0.435577
2037.68	-0.461304
2038.91	-3.47977
2040.14	-3.81403
2041.37	2.51602
2042.6	-2.28558
2043.83	2.77505
2045.05	-5.63367
2046.28	2.14935
2047.51	1.62479
2048.74	4.59723
2049.97	-1.51044
2051.2	-0.678772
2052.42	-0.559906
2053.65	-0.179626
2054.88	-2.98529
2056.1	-0.331085
2057.33	8.1593
2058.56	-1.82849
2059.78	7.57895
2061.01	1.0795
2062.23	2.11295
2063.46	0.463593
2064.68	-4.01077
2065.91	-0.860779
2067.13	2.11142
2068.35	7.94797
2069.58	-1.74365
2070.8	-0.381653
2072.02	2.78299
2073.25	2.76321
2074.47	1.09402
2075.69	0.689392
2076.91	6.20355
2078.13	0.536377
2079.35	0.881348
2080.58	4.77109
2081.8	0.989716
2083.02	1.0235
2084.24	6.70291
2085.46	6.75485
2086.68	-2.39383
2087.9	6.22049
2089.12	8.26938
2090.33	7.50192
2091.55	4.93542
2092.77	0.637054
2093.99	-0.0366516
2095.21	4.58408
2096.43	7.32559
2097.64	8.09174
2098.86	8.96912
2100.08	8.04428
2101.29	4.46872
2102.51	7.24945
2103.73	9.05545
2104.94	2.63055
2106.16	3.78116
2107.37	3.74332
2108.59	5.34058
2109.8	2.65228
2111.01	4.53436
2112.23	6.39136
2113.44	12.327
2114.66	3.7507
2115.87	-0.19458
2117.08	1.62653
2118.29	9.87808
2119.51	3.8967
2120.72	7.73315
2121.93	7.11194
2123.14	6.31781
2124.35	3.17099
2125.57	11.1663
2126.78	4.23056
2127.99	0.352081
2129.2	5.03198
2130.41	3.05215
2131.62	0.979309
2132.82	5.53323
2134.03	1.81204
2135.24	5.52228
2136.45	6.22141
2137.66	3.479
2138.87	1.68118
2140.08	9.77448
2141.28	8.69998
2142.49	7.78705
2143.7	2.53491
2144.9	3.59903
2146.11	-0.23761
2147.32	0.540894
2148.52	5.99893
2149.73	1.8559
2150.93	0.909576
2152.14	0.0635986
2153.34	2.68857
2154.55	-3.38348
2155.75	0.873108
2156.96	2.72372
2158.16	5.67963
2159.36	-1.04053
2160.57	8.94083
2161.77	2.33215
2162.97	0.369781
2164.17	2.00406
2165.38	1.08234
2166.58	-0.942352
2167.78	-1.40179
2168.98	6.11667
2170.18	-0.944733
2171.38	2.3519
2172.58	5.82321
2173.78	2.18787
2174.98	4.03928
2176.18	9.50336
2177.38	-0.720337
2178.58	0.9823
2179.78	1.93054
2180.98	0.933502
2182.18	2.64676
2183.38	-2.27823
2184.57	3.22662
2185.77	-2.15152
2186.97	1.95044
2188.16	3.74774
2189.36	-3.12372
2190.56	2.44949
2191.76	4.40289
2192.95	-2.8197
2194.15	-3.28232
2195.34	-4.39261
2196.54	4.49988
2197.73	-0.181
2198.93	17.8835
2200.12	1.78287
2201.31	-0.22876
2202.51	4.32208
2203.7	5.01233
2204.89	-1.22763
2206.09	4.23822
2207.28	3.38644
2208.47	0.874237
2209.67	5.58798
2210.86	-1.64542
2212.05	6.98874
2213.24	-2.50385
2214.43	2.4978
2215.62	0.701416
2216.81	-1.19647
2218	1.64258
2219.19	12.132
2220.38	7.50131
2221.57	10.9436
2222.76	-1.12646
2223.95	3.92307
2225.14	0.537109
2226.33	7.39447
2227.51	1.92529
2228.7	5.58841
2229.89	9.59573
2231.08	0.5289
2232.27	4.57385
2233.45	11.4243
2234.64	7.57205
2235.82	2.73276
2237.01	5.73431
2238.2	-0.357391
2239.38	14.8876
2240.57	5.51004
2241.75	8.45239
2242.94	8.48441
2244.12	4.69388
2245.3	8.91516
2246.49	11.0607
2247.67	1.67325
2248.85	6.33157
2250.04	8.2218
2251.22	4.20355
2252.4	2.55414
2253.59	6.82428
2254.77	8.81503
2255.95	6.10571
2257.13	12.0485
2258.31	10.2671
2259.49	2.84412
2260.67	6.87534
2261.85	8.93024
2263.03	6.41412
2264.21	10.7526
2265.39	13.8344
2266.57	8.77277
2267.75	11.3859
2268.93	8.69992
2270.11	7.21985
2271.29	8.41364
2272.47	3.75928
2273.64	11.5011
2274.82	7.76123
2276	16.5839
2277.17	9.32056
2278.35	15.4069
2279.53	9.35181
2280.71	7.16171
2281.88	10.0698
2283.06	12.3886
2284.23	3.29971
2285.41	6.30228
2286.58	10.2312
2287.76	16.2783
2288.93	12.0881
2290.1	12.7536
2291.28	8.24066
2292.45	15.2827
2293.62	17.3475
2294.8	10.3867
2295.97	13.9312
2297.14	11.2148
2298.31	17.3546
2299.49	17.5868
2300.66	13.8505
2301.83	13.8852
2303	8.05545
2304.17	11.1187
2305.34	7.43066
2306.51	14.2919
2307.68	14.1741
2308.85	11.3553
2310.02	13.5675
2311.19	11.1751
2312.36	11.823
2313.53	14.0746
2314.7	8.72189
2315.87	12.1572
2317.03	8.18051
2318.2	5.23508
2319.37	4.07971
2320.54	11.8765
2321.7	10.289
2322.87	8.49356
2324.03	17.2218
2325.2	26.4788
2326.37	24.2229
2327.53	53.8281
2328.7	118.283
2329.86	19.896
2331.03	11.2206
2332.19	11.1677
2333.36	15.8003
2334.52	6.89807
2335.68	11.7013
2336.85	9.68851
2338.01	6.71909
2339.17	4.79523
2340.34	5.53925
2341.5	8.95117
2342.66	4.98041
2343.82	10.5588
2344.98	10.1727
2346.14	7.99826
2347.31	9.75565
2348.47	5.91498
2349.63	2.57675
2350.79	6.16058
2351.95	11.9521
2353.11	5.28049
2354.27	8.72986
2355.43	4.66559
2356.59	3.77148
2357.74	5.86206
2358.9	4.83646
2360.06	7.62439
2361.22	7.03137
2362.38	4.0871
2363.53	0.916687
2364.69	1.3584
2365.74	-1.54346
2366.92	7.32877
2368.09	5.27438
2369.26	1.22723
2370.43	7.49304
2371.6	0.685577
2372.77	3.28653
2373.94	2.13797
2375.11	-0.0132751
2376.28	1.7027
2377.45	1.51816
2378.62	-0.641479
2379.79	3.67584
2380.96	-2.02881
2382.13	3.56107
2383.29	5.34235
2384.46	3.42407
2385.63	3.16089
2386.8	-0.0509644
2387.97	-5.8302
2389.13	2.4707
2390.3	-3.15234
2391.47	4.34821
2392.63	-3.33966
2393.8	-0.999451
2394.96	-3.88333
2396.13	-1.09747
2397.29	-1.29779
2398.46	1.47495
2399.62	-0.383881
2400.79	2.32635
2401.95	1.25632
2403.12	-4.97202
2404.28	2.97342
2405.44	-4.25146
2406.61	3.28192
2407.77	0.453461
2408.93	3.18555
2410.09	-0.540588
2411.26	0.398712
2412.42	1.48941
2413.58	-1.25995
2414.74	-2.31116
2415.9	-7.18158
2417.06	0.391602
2418.22	0.605499
2419.38	0.991302
2420.54	2.9566
2421.7	0.825256
2422.86	-1.69717
2424.02	2.23926
2425.18	0.661865
2426.34	-2.81967
2427.5	-0.798645
2428.66	-0.887329
2429.81	3.75757
2430.97	0.0542908
2432.13	-2.35544
2433.29	4.51559
2434.44	-2.01416
2435.6	7.67242
2436.76	3.19174
2437.91	-2.50095
2439.07	2.46405
2440.23	13.2002
2441.38	-1.84314
2442.53	9.70728
2443.69	3.3161
2444.84	5.40909
2446	0.869568
2447.15	3.0864
2448.31	4.05869
2449.46	-0.635956
2450.61	3.51044
2451.77	11.4119
2452.92	8.54422
2454.07	5.68597
2455.22	7.92865
2456.38	10.1518
2457.53	0.757294
2458.68	3.63879
2459.83	1.92352
2460.98	7.78033
2462.14	6.80902
2463.29	7.87079
2464.43	3.77048
2465.59	9.5322
2466.74	4.64761
2467.88	9.34976
2469.03	15.9282
2470.18	6.51672
2471.33	2.83578
2472.48	6.96933
2473.63	9.84225
2474.78	5.27631
2475.92	5.84964
2477.07	13.6437
2478.22	9.56409
2479.37	11.139
2480.51	2.18262
2481.66	2.86813
2482.81	5.70901
2483.95	2.745
2485.1	5.59299
2486.24	7.56781
2487.39	2.556
2488.53	5.25159
2489.68	9.93228
2490.82	3.25641
2491.97	4.96091
2493.11	5.25699
2494.25	11.6629
2495.4	8.60422
2496.54	3.99625
2497.69	4.54263
2498.83	4.78677
2499.97	5.68307
2501.11	12.7609
2502.25	1.08539
2503.4	1.9418
2504.54	1.70383
2505.68	5.45126
2506.82	4.70645
2507.96	0.00134277
2509.1	5.67191
2510.24	2.4512
2511.38	8.42111
2512.52	7.31592
2513.66	-0.0827332
2514.8	8.29141
2515.94	3.99164
2517.08	2.5455
2518.21	13.5297
2519.35	-1.6088
2520.49	3.36414
2521.63	4.37134
2522.77	7.80893
2523.9	2.09097
2525.04	7.55945
2526.18	5.108
2527.31	2.08066
2528.45	4.97617
2529.58	-1.4642
2530.72	7.82806
2531.86	1.03076
2532.99	1.71399
2534.13	2.76993
2535.26	11.9498
2536.4	4.40707
2537.53	5.13132
2538.66	0.138184
2539.8	5.47229
2540.93	6.35037
2542.06	-0.88623
2543.2	2.92773
2544.33	4.57361
2545.46	-0.0969849
2546.59	-4.91287
2547.73	7.25223
2548.86	0.840729
2549.99	0.140503
2551.12	-1.49484
2552.25	11.7899
2553.38	5.09686
2554.51	-1.4834
2555.64	5.3046
2556.77	5.73886
2557.9	5.84399
2559.03	4.92218
2560.16	-2.69199
2561.29	6.71432
2562.42	10.6309
2563.55	9.22131
2564.67	4.05771
2565.8	0.304169
2566.93	3.16043
2568.06	10.6684
2569.18	4.12265
2570.31	9.08072
2571.44	6.77847
2572.56	2.5159
2573.69	2.76602
2574.81	8.2569
2575.94	18.0247
2577.06	3.06363
2578.19	3.49576
2579.31	8.64801
2580.44	9.84
2581.56	11.8727
2582.69	6.23358
2583.81	3.44733
2584.94	0.744049
2586.06	5.98477
2587.18	4.47668
2588.3	9.88727
2589.43	11.9044
2590.55	7.08987
2591.67	13.8377
2592.79	16.9745
2593.91	7.71228
2595.04	8.90906
2596.16	10.9508
2597.28	10.5287
2598.4	19.9993
2599.52	9.76379
2600.64	6.944
2601.76	5.52979
2602.88	12.265
2604	13.2592
2605.12	7.54419
2606.24	13.3878
2607.35	16.4414
2608.47	13.9896
2609.59	11.2479
2610.71	16.204
2611.83	9.30945
2612.94	14.0212
2614.06	13.2173
2615.18	14.7206
2616.29	11.9822
2617.41	16.9736
2618.53	11.2122
2619.64	20.4984
2620.76	12.3181
2621.87	15.7614
2622.99	15.87
2624.1	8.16031
2625.22	15.9752
2626.33	14.1844
2627.45	15.2766
2628.56	11.3314
2629.67	14.126
2630.79	9.34738
2631.9	12.3831
2633.01	8.4328
2634.12	16.0433
2635.24	8.70636
2636.35	13.118
2637.46	10.7614
2638.57	15.5953
2639.68	6.97308
2640.8	19.9619
2641.91	9.58752
2643.02	6.98669
2644.13	12.4944
2645.24	11.264
2646.35	14.0008
2647.46	8.03159
2648.57	10.3992
2649.67	5.37366
2650.78	15.9245
2651.89	13.7059
2653	7.80637
2654.11	8.59351
2655.22	2.48187
2656.32	6.31625
2657.43	11.2535
2658.54	2.37894
2659.65	7.61914
2660.75	5.6525
2661.86	6.24496
2662.96	5.50595
2664.07	2.39835
2665.18	6.10629
2666.28	7.91052
2667.39	1.98752
2668.49	9.22455
2669.6	12.9371
2670.7	9.17661
2671.8	9.88458
2672.91	6.6004
2674.01	2.53577
2675.11	2.75079
2676.22	2.20871
2677.32	1.00519
2678.42	6.47318
2679.53	0.590698
2680.63	1.42068
2681.73	8.13193
2682.83	-2.61917
2683.93	4.99261
2685.03	-1.66901
2686.14	5.03641
2687.24	0.950287
2688.34	-3.35803
2689.44	4.87433
2690.54	3.62436
2691.64	2.41489
2692.74	-0.628204
2693.84	-1.03781
2694.93	1.72021
2696.03	1.0137
2697.13	2.18994
2698.23	-0.762817
2699.33	0.638306
2700.43	-2.89728
2701.52	-6.43466
2702.62	-0.983337
2703.72	-3.79352
2704.81	4.78168
2705.9	-1.22098
2707.01	6.28162
2708.12	5.10928
2709.23	-2.30624
2710.34	2.47495
2711.45	3.26453
2712.56	-1.86288
2713.67	-2.70782
2714.78	0.577637
2715.89	-4.121
2716.99	-1.539
2718.1	-5.28867
2719.21	-2.21756
2720.32	4.78149
2721.43	2.05859
2722.54	9.36029
2723.64	3.66769
2724.75	3.96368
2725.86	10.4404
2726.96	3.80438
2728.07	-5.48358
2729.18	1.18173
2730.28	5.19443
2731.39	-3.92288
2732.49	-2.09625
2733.6	-1.39883
2734.71	-0.428864
2735.81	0.921204
2736.91	1.99832
2738.02	0.0841675
2739.12	4.00308
2740.23	9.54523
2741.33	5.6221
2742.43	1.26666
2743.54	0.674866
2744.64	-0.843933
2745.74	3.84827
2746.84	8.35037
2747.95	-5.83691
2749.05	-0.0868225
2750.15	3.69482
2751.25	7.73874
2752.35	-1.36099
2753.45	-2.20621
2754.55	4.30362
2755.66	7.01941
2756.76	-2.27841
2757.86	0.705566
2758.96	5.41949
2760.05	-0.330139
2761.15	6.67212
2762.25	5.27316
2763.35	-0.212311
2764.45	2.89383
2765.55	2.81271
2766.65	6.41302
2767.75	9.02728
2768.84	6.14798
2769.94	17.7186
2771.04	-1.22061
2772.13	2.2251
2773.23	-4.41327
2774.33	5.65402
2775.42	3.64746
2776.52	4.37894
2777.61	4.33359
2778.71	6.27014
2779.81	4.07367
2780.9	-2.6405
2782	5.02264
2783.09	8.59131
2784.18	1.69211
2785.28	2.81757
2786.37	3.94547
2787.47	5.59772
2788.56	4.22836
2789.65	-0.687134
2790.74	-0.807831
2791.84	1.79028
2792.93	2.87485
2794.02	2.74854
2795.11	0.89975
2796.2	6.36203
2797.3	3.38821
2798.39	-2.45694
2799.48	5.25211
2800.57	4.19849
2801.66	-6.29465
2802.75	8.95935
2803.84	3.91116
2804.93	-1.0965
2806.02	2.74039
2807.11	-2.98035
2808.2	1.66318
2809.28	1.57336
2810.37	7.11691
2811.46	-3.58069
2812.55	2.75238
2813.64	-2.76822
2814.73	1.78815
2815.81	6.28931
2816.9	0.518188
2817.99	-1.73199
2819.07	-6.64005
2820.16	-0.622375
2821.25	-2.98666
2822.33	4.39136
2823.42	-5.18198
2824.5	-6.9725
2825.59	-1.47446
2826.67	0.58725
2827.76	12.0175
2828.84	9.75919
2829.93	-4.36221
2831.01	-1.45984
2832.09	-1.68518
2833.18	3.73889
2834.26	-0.913422
2835.34	0.219391
2836.43	5.99014
2837.51	-3.42047
2838.59	5.86868
2839.67	5.0892
2840.75	0.900146
2841.84	1.7439
2842.92	-6.92358
2844	10.7193
2845.08	2.1586
2846.16	-0.362823
2847.24	-0.146759
2848.32	-0.498016
2849.4	-4.16675
2850.48	-1.1546
2851.56	-0.11676
2852.64	-0.216827
2853.72	1.73389
2854.8	-1.95929
2855.87	3.68069
2856.95	-0.111877
2858.03	3.72372
2859.11	2.75137
2860.19	4.6326
2861.26	9.79718
2862.34	4.48801
2863.42	-2.33109
2864.49	5.01874
2865.57	5.15106
2866.65	7.24564
2867.72	1.64001
2868.8	3.90939
2869.87	3.80774
2870.95	10.4135
2872.02	4.59109
2873.1	-1.02411
2874.17	18.2447
2875.25	6.27509
2876.32	2.41595
2877.4	-4.18915
2878.47	6.36435
2879.54	5.245
2880.62	0.499939
2881.69	5.51627
2882.76	2.78247
2883.83	7.1774
2884.9	5.53543
2885.98	4.7926
2887.05	8.6723
2888.12	3.29605
2889.19	3.42282
2890.26	9.05414
2891.33	10.8936
2892.4	3.3967
2893.47	4.58267
2894.54	5.17032
2895.61	6.63223
2896.68	3.64197
2897.75	5.57947
2898.82	0.871918
2899.89	2.98822
2900.96	7.79016
2902.03	1.99307
2903.09	5.85153
2904.16	4.17346
2905.23	10.9489
2906.3	9.71201
2907.36	2.90799
2908.43	4.01984
2909.5	1.06641
2910.57	1.14688
2911.63	20.278
2912.7	7.02658
2913.76	8.82651
2914.83	4.83597
2915.89	5.78235
2916.96	9.61511
2918.02	2.94464
2919.09	1.91592
2920.15	1.69943
2921.22	2.4361
2922.28	3.19092
2923.34	8.84879
2924.41	2.17816
2925.47	5.93954
2926.53	5.86124
2927.6	7.67963
2928.66	3.73877
2929.72	6.11389
2930.78	8.66656
2931.84	5.9407
2932.91	4.71887
2933.97	2.93912
2935.03	6.52203
2936.09	11.0976
2937.15	3.59784
2938.21	1.63477
2939.27	7.97714
2940.33	6.16193
2941.39	2.91513
2942.45	1.22601
2943.51	8.94113
2944.57	2.54123
2945.63	1.0069
2946.68	7.20062
2947.74	13.0142
2948.8	5.40723
2949.86	9.92615
2950.92	-1.35516
2951.97	2.521
2953.03	10.9152
2954.09	1.12274
2955.14	8.39935
2956.2	3.65033
2957.25	0.915375
2958.31	3.77643
2959.37	4.71295
2960.42	-2.02914
2961.48	9.16409
2962.53	-4.43094
2963.59	3.28433
2964.64	5.39975
2965.7	-2.32639
2966.75	8.69199
2967.8	6.56461
2968.86	8.50818
2969.91	1.94934
2970.96	4.82928
2972.02	3.89969
2973.07	11.4403
2974.12	-1.83459
2975.17	-0.0935974
2976.22	-1.98016
2977.28	5.63962
2978.33	5.84738
2979.38	-2.54266
2980.43	-3.62607
2981.48	-1.85861
2982.53	0.767853
2983.58	1.52548
2984.63	7.01044
2985.68	-2.41
2986.73	8.09979
2987.78	-3.13889
2988.83	6.39597
2989.88	2.60913
2990.93	0.726196
2991.98	6.51599
2993.02	2.65405
2994.07	7.28412
2995.12	6.57544
2996.17	1.25195
2997.21	5.11325
2998.26	-3.22641
2999.31	5.30365
2999.94	3.32327