File: Data/3-Raman/processed/bu32-A-FF1-FI09-V.txt
#Acq. time (s)=	15
#Accumulations=	3
#Range (cm-¹)=	50...5000
#Windows=	1
#Auto scanning=	Off
#Autofocus=	Off
#Macrospot=	Off
#AutoExposure=	Off
#Spike filter=	Multiple accum.
#Delay time (s)=	0
#Binning=	1
#Readout mode=	Signal
#DeNoise=	Lite
#ICS correction=	Off
#Dark correction=	Off
#Inst. Process=	Off
#Detector temperature (°C)=	-60.09
#Instrument=	LabRAM HR Evol
#Detector=	SIN-EM FIVIS
#Objective=	x100_VIS
#Grating=	150 (500nm)
#ND Filter=	100%
#Laser=	532nm_Edge
#Hole=	30.0125
#Temperature=	0
#Range=	Visible
#StageXY=	75x50mm Scan+
#StageZ=	Z motor
#X (µm)=	-16869
#Y (µm)=	2629
#Z (µm)=	-407.9
#Full time(s)=	47
#Project=	Buranga
#Sample=	BU18FA32_A
#Site=	A_FF1
#Title=	32-A_FF1_FI09_V
#Remark=
#Date=	09.07.2019 15:05
#Acquired=	09.07.2019 15:05:30
#Data Range:Extract=	16.12.2021 14:53:05
#Base:Fit=	16.12.2021 14:58:42
#Base:Edit=	16.12.2021 14:58:44
#Base:Edit=	16.12.2021 14:58:44
#Base:Sub=	16.12.2021 14:58:46
98.6609	1784.81
103.286	1373.07
107.909	1031.15
112.53	800.449
117.146	607.679
121.762	484.908
126.376	359.973
130.988	293.207
135.595	264.61
140.202	243.059
144.807	209.111
149.41	201.347
154.008	185.703
158.606	154.83
163.201	166.26
167.795	414.042
172.384	727.898
176.973	375.872
181.559	75.9239
186.142	25.0193
190.724	3.90677
195.304	0.0130615
199.881	4.91644
204.454	32.6268
209.028	82.4116
213.598	123.849
218.165	139.339
222.731	144.882
227.295	132.714
231.855	76.9089
236.415	34.352
240.972	72.4752
245.525	95.2261
250.078	122.638
254.629	132.663
259.175	96.9637
263.722	77.2017
268.264	111.034
272.805	160.865
277.345	162.053
281.88	136.515
286.415	115.3
290.948	102.723
295.477	108.116
300.005	133.891
304.529	176.163
309.053	241.583
313.575	328.731
318.093	257.096
322.61	176.93
327.123	110.137
331.636	81.2179
336.145	81.2158
340.653	108.555
345.157	156.775
349.662	252.396
354.164	412.653
358.661	535.065
363.159	379.618
367.652	217.959
372.145	129.95
376.634	84.6311
381.123	52.0706
385.608	42.3318
390.092	48.0041
394.572	71.6234
399.052	111.959
403.528	171.744
408.004	241.941
412.475	321.724
416.947	373.053
421.414	411.56
425.881	435.256
430.343	445.405
434.806	446.289
439.264	443.785
443.723	437.308
448.177	417.42
452.629	380.365
457.081	358.203
461.528	358.814
465.976	420.695
470.419	379.646
474.862	290.252
479.301	201.257
483.738	159.973
488.175	164.962
492.607	195.989
497.04	249.653
501.468	393.987
505.894	526.803
510.32	684.15
514.742	830.149
519.164	940.354
523.581	1016.48
527.997	1069.16
532.412	1079.22
536.823	1070.43
541.232	1002.62
545.641	894.238
550.046	862.023
554.449	906.673
558.851	912.902
563.25	905.191
567.646	822.459
572.042	720.821
576.434	601.565
580.824	528.656
585.214	522.792
589.599	615.231
593.983	755.088
598.367	995.62
602.746	1092.68
607.123	913.734
611.498	612.249
615.873	430.35
620.244	325.507
624.613	262.168
628.98	213.493
633.346	180.617
637.709	163.006
642.069	160.824
646.428	169.747
650.786	196.35
655.14	232.795
659.492	283.771
663.842	312.407
668.192	344.216
672.538	284.352
676.882	190.85
681.223	123.219
685.563	79.2426
689.902	47.147
694.238	32.1851
698.571	23.6892
702.902	19.0755
707.231	18.3005
711.559	17.2405
715.886	13.4086
720.209	8.98557
724.529	4.6757
728.848	1.17812
733.165	-0.578171
737.48	-0.950363
741.792	0.238831
746.105	2.74596
750.413	5.93283
754.72	7.35591
759.024	7.51959
763.327	5.86983
767.627	4.53381
771.925	3.87622
776.221	5.27509
780.518	6.57538
784.81	7.23233
789.1	7.35231
793.388	6.6441
797.674	5.30537
801.958	3.52464
806.24	1.16563
810.52	-0.25528
814.797	0.727158
819.073	2.54298
823.347	3.61761
827.619	4.52434
831.888	2.78629
836.156	0.94429
840.422	-0.0241699
844.685	-0.379517
848.947	-0.491913
853.206	1.23068
857.464	4.10965
861.719	4.31586
865.973	4.01929
870.224	3.47586
874.474	2.89609
878.721	2.72035
882.967	5.07529
887.21	8.41063
891.452	12.5534
895.691	17.8417
899.929	21.1067
904.164	24.2806
908.397	26.4908
912.629	30.9582
916.858	41.1312
921.086	57.8632
925.311	80.9859
929.534	109.966
933.756	144.779
937.975	185.743
942.191	232.257
946.406	280.372
950.619	337.485
954.831	398.047
959.04	474.012
963.248	574.393
967.453	696.366
971.657	849.563
975.858	1052.2
980.056	1332.21
984.253	1526.77
988.449	1480.86
992.643	1212.02
996.834	822.848
1001.02	733.597
1005.21	761.942
1009.4	786.283
1013.58	1043.62
1017.76	1319.96
1021.94	1627.29
1026.12	1734.98
1030.29	1621.78
1034.47	1454.82
1038.64	1299.56
1042.81	1100.29
1046.98	868.005
1051.14	678.511
1055.3	545.149
1059.47	481.77
1063.63	485.647
1067.78	573.639
1071.94	661.992
1076.09	766.665
1080.25	792.419
1084.4	768.13
1088.54	690.858
1092.69	594.284
1096.83	510.945
1100.98	461.483
1105.12	480.924
1109.26	508.363
1113.39	610.744
1117.53	687.43
1121.66	597.814
1125.79	485.363
1129.92	380.858
1134.04	259.847
1138.17	209.077
1142.29	167.614
1146.41	140.9
1150.53	118.598
1154.65	100.351
1158.76	86.9751
1162.88	76.5075
1166.99	67.2396
1171.1	56.4329
1175.2	45.9041
1179.31	35.5227
1183.41	24.0944
1187.51	19.5868
1191.61	18.117
1195.71	22.3641
1199.81	20.4266
1203.9	20.8887
1207.99	19.6094
1212.08	18.5975
1216.17	18.0867
1220.26	19.5906
1224.34	21.9583
1228.42	25.0633
1232.5	29.1367
1236.58	33.8241
1240.66	38.2553
1244.73	44.2744
1248.81	54.9012
1252.88	64.5854
1256.95	72.8097
1261.02	166.151
1265.08	246.299
1269.14	115.443
1273.2	100.584
1277.27	147.722
1281.32	1281.86
1285.38	2159.99
1289.43	299.116
1293.48	99.078
1297.53	79.919
1301.58	72.281
1305.63	66.8591
1309.67	62.7452
1313.72	58.9094
1317.76	55.866
1321.8	53.7299
1325.83	52.3291
1329.87	51.7336
1333.9	51.8146
1337.93	51.543
1341.96	52.1004
1345.99	54.0286
1350.02	57.3381
1354.04	62.4467
1358.06	69.2008
1362.08	82.1191
1366.1	111.138
1370.12	134.796
1374.13	120.972
1378.14	129.841
1382.16	413.063
1386.16	3448.1
1390.17	1994.14
1394.18	206.169
1398.18	112.197
1402.18	107.221
1406.18	254.241
1410.18	329.257
1414.18	91.6965
1418.17	74.4452
1422.16	66.3731
1426.15	53.6064
1430.14	43.1886
1434.13	34.0629
1438.11	26.0094
1442.1	19.2817
1446.08	13.853
1450.06	9.7579
1454.04	8.07774
1458.01	7.26851
1461.98	6.90923
1465.96	6.42244
1469.93	5.54805
1473.9	5.1869
1477.86	5.17603
1481.83	4.31512
1485.79	3.36766
1489.75	2.52972
1493.71	1.73065
1497.67	1.10272
1501.62	0.51149
1505.58	-0.0370026
1509.53	-0.52182
1513.48	-0.910797
1517.43	-1.05653
1521.38	-0.916809
1525.32	-0.64743
1529.26	-0.194656
1533.2	0.263458
1537.14	0.468369
1541.08	0.478973
1545.02	-0.047699
1548.95	-1.29205
1552.88	-2.35683
1556.81	-2.16501
1560.74	-1.22168
1564.67	-0.569168
1568.6	0.811539
1572.52	2.01913
1576.44	2.57295
1580.36	2.65266
1584.28	2.41862
1588.19	1.93567
1592.11	3.31909
1596.02	5.77823
1599.93	7.27602
1603.84	7.2948
1607.75	6.20453
1611.65	4.48604
1615.56	2.74045
1619.46	1.20323
1623.36	0.00483704
1627.25	-1.09041
1631.15	0.0340118
1635.05	2.10683
1638.94	4.76813
1642.83	7.10826
1646.72	8.80649
1650.61	9.78041
1654.49	9.94112
1658.38	9.63722
1662.26	8.76624
1666.14	7.08873
1670.02	5.41885
1673.89	4.24786
1677.77	3.52864
1681.64	3.40588
1685.51	3.25516
1689.38	3.24884
1693.25	3.42886
1697.12	2.89661
1700.98	2.26401
1704.85	2.44019
1708.71	3.57809
1712.57	4.72729
1716.42	5.98529
1720.28	6.25546
1724.13	5.619
1727.99	3.62311
1731.84	2.39119
1735.69	1.65396
1739.53	1.0415
1743.38	0.172836
1747.22	4.3768
1751.06	6.19525
1754.9	7.10957
1758.74	7.3987
1762.58	7.05945
1766.41	6.36055
1770.25	5.25102
1774.08	4.28796
1777.91	3.0388
1781.73	2.9382
1785.56	3.3479
1789.39	3.5649
1793.21	2.60176
1797.03	1.76964
1800.85	1.33815
1804.67	1.3801
1808.48	2.6349
1812.3	4.49509
1816.11	7.4628
1819.92	7.95912
1823.73	6.80238
1827.54	4.8573
1831.34	2.9957
1835.14	1.40454
1838.95	0.0591431
1842.75	-1.43326
1846.55	-2.59213
1850.34	-2.8968
1854.14	-2.53891
1857.93	-0.920944
1861.72	1.57455
1865.51	4.34018
1869.3	6.25148
1873.09	7.83646
1876.87	8.02274
1880.66	8.37572
1884.44	6.50272
1888.22	5.93755
1892	6.12149
1895.77	6.93974
1899.55	7.05591
1903.32	6.72229
1907.09	5.0703
1910.86	4.015
1914.63	3.46661
1918.4	3.79494
1922.16	4.40205
1925.92	4.57909
1929.68	3.86452
1933.44	3.4207
1937.2	3.74863
1940.96	4.02815
1944.71	5.36438
1948.46	5.59296
1952.22	4.90588
1955.97	3.16118
1959.71	0.754898
1963.46	-1.44475
1967.2	-2.23755
1970.95	-1.33905
1974.69	0.313812
1978.43	2.75154
1982.17	4.35954
1985.9	4.46214
1989.64	1.95557
1993.37	2.52991
1997.1	3.51706
2000.83	4.83337
2004.56	5.77316
2008.28	6.35216
2012.01	6.85164
2015.73	7.8148
2019.45	7.89453
2023.17	7.31592
2026.89	6.46095
2030.6	5.47107
2034.32	5.02797
2038.03	4.85994
2041.74	5.07257
2045.45	5.48512
2049.16	6.133
2052.87	7.22159
2056.57	7.95369
2060.27	8.62033
2063.98	9.51595
2067.67	10.203
2071.37	4.5011
2075.07	6.72719
2078.76	8.59987
2082.46	9.90637
2086.15	8.41745
2089.84	8.69531
2093.53	9.36659
2097.21	10.2031
2100.9	11.1039
2104.58	12.1598
2108.26	12.788
2111.94	13.2115
2115.62	13.0787
2119.3	12.5948
2122.97	11.6555
2126.64	10.7471
2130.32	9.96472
2133.99	9.39253
2137.66	9.14114
2141.32	9.10957
2144.99	9.24567
2148.65	9.48373
2152.31	9.43561
2155.97	8.77066
2159.63	7.0843
2163.29	7.785
2166.94	8.95854
2170.6	10.8781
2174.25	12.1709
2177.9	12.964
2181.55	13.1143
2185.2	12.5037
2188.84	11.7211
2192.49	10.8368
2196.13	9.79768
2199.77	8.96379
2203.41	8.79825
2207.05	8.9816
2210.69	8.72162
2214.32	8.54788
2217.95	8.40498
2221.59	8.34506
2225.22	8.5159
2228.84	9.01031
2232.47	10.3774
2236.09	11.7997
2239.72	12.9006
2243.34	14.9187
2246.96	10.8829
2250.58	9.21562
2254.2	8.03999
2257.81	8.16948
2261.42	9.17596
2265.04	10.7618
2268.65	12.1534
2272.26	12.858
2275.86	12.0176
2279.47	10.1828
2283.08	7.57014
2286.68	3.91939
2290.28	1.69449
2293.88	-0.00973511
2297.48	-0.677933
2301.07	-0.115555
2304.67	1.28053
2308.26	7.22456
2311.85	4.82707
2315.44	13.277
2319.03	18.8251
2322.62	39.3886
2326.2	223.675
2329.79	344.221
2333.37	48.3849
2336.95	19.9987
2340.53	16.2254
2344.11	13.3631
2347.68	11.3079
2351.26	9.64532
2354.83	8.80672
2358.4	8.86987
2361.97	9.63713
2365.54	9.64886
2369.11	9.29225
2372.67	8.95975
2376.23	7.74571
2379.8	7.54749
2383.36	10.0682
2386.92	12.364
2390.47	15.2953
2394.03	17.9576
2397.58	19.1566
2401.14	19.7285
2404.69	19.9962
2408.24	20.196
2411.78	19.7222
2415.33	19.1378
2418.88	17.8963
2422.42	17.9619
2425.96	20.0089
2429.5	22.3918
2433.04	22.674
2436.58	22.1708
2440.11	20.8636
2443.65	19.19
2447.18	15.7319
2450.71	13.5119
2454.24	11.3885
2457.77	10.7977
2461.3	11.2036
2464.82	12.6716
2468.34	13.7081
2471.86	14.5327
2475.39	15.4571
2478.9	14.9675
2482.42	14.2543
2485.94	13.1052
2489.45	11.9583
2492.96	10.4391
2496.47	9.8006
2499.98	10.6947
2503.49	12.5079
2507	14.8851
2510.5	16.4227
2514.01	16.9811
2517.51	17.3609
2521.01	17.4738
2524.51	17.3902
2528.01	17.0278
2531.5	16.0017
2535	16.5117
2538.49	16.6852
2541.98	17.6186
2545.47	18.7384
2548.96	18.7963
2552.45	18.2072
2555.93	17.5739
2559.42	16.0808
2562.9	14.4026
2566.38	12.1267
2569.86	9.39465
2573.34	6.778
2576.81	6.04622
2580.29	6.22234
2583.76	6.82057
2587.23	8.76343
2590.71	10.1559
2594.17	11.1147
2597.64	11.4396
2601.11	11.1234
2604.57	10.2213
2608.03	10.4849
2611.5	10.8032
2614.96	11.5208
2618.42	11.784
2621.87	12.278
2625.33	12.1963
2628.78	11.5322
2632.23	9.14194
2635.68	5.09891
2639.13	2.21106
2642.58	0.884613
2646.03	1.35614
2649.47	5.01343
2652.92	7.11115
2656.36	10.1387
2659.8	11.6207
2663.24	12.6278
2666.68	13.703
2670.11	15.0514
2673.55	16.3512
2676.98	17.7505
2680.41	21.8532
2683.84	21.1554
2687.27	21.8788
2690.7	20.8099
2694.13	18.7966
2697.55	25.7606
2700.97	25.8676
2704.4	23.8291
2707.82	21.0635
2711.23	18.6469
2714.65	16.5244
2718.07	14.5498
2721.48	12.7763
2724.9	11.0074
2728.31	10.4422
2731.72	11.2357
2735.12	14.7876
2738.53	20.2879
2741.94	20.7032
2745.34	18.751
2748.74	15.7769
2752.14	13.6116
2755.54	12.3954
2758.94	12.0385
2762.34	13.0158
2765.73	14.68
2769.13	16.1761
2772.52	16.9624
2775.91	16.6295
2779.3	15.063
2782.69	14.1437
2786.08	12.8363
2789.46	12.8987
2792.85	13.0742
2796.23	13.6192
2799.61	14.4931
2802.99	14.2424
2806.37	11.7308
2809.74	7.08069
2813.12	5.91953
2816.49	11.0116
2819.86	13.7688
2823.23	11.7916
2826.61	10.0515
2829.97	6.26462
2833.34	5.56821
2836.7	5.37402
2840.07	6.59402
2843.43	8.81714
2846.79	12.4122
2850.15	17.4549
2853.51	16.8896
2856.87	15.5011
2860.22	12.2939
2863.57	9.47061
2866.93	13.7034
2870.28	15.0528
2873.63	15.1595
2876.98	14.2723
2880.32	13.6662
2883.67	12.1221
2887.01	8.79239
2890.35	9.34018
2893.69	8.1402
2897.03	7.59064
2900.37	7.92862
2903.71	10.314
2907.04	11.4353
2910.38	11.1625
2913.71	10.5443
2917.04	8.18112
2920.37	6.0867
2923.7	5.41187
2927.03	5.495
2930.35	4.45886
2933.68	3.38425
2937	3.09103
2940.32	2.70392
2943.64	2.63516
2946.96	2.86218
2950.27	3.54788
2953.59	4.36142
2956.91	5.2587
2960.22	5.05493
2963.53	8.05884
2966.84	9.62842
2970.15	8.61261
2973.46	5.72577
2976.76	4.81653
2980.07	4.47534
2983.37	4.89859
2986.67	7.01093
2989.97	9.2168
2993.27	11.1884
2996.57	12.2097
2999.86	11.3259
3003.16	9.14722
3006.45	6.55484
3009.75	4.08859
3013.03	1.44217
3016.32	-0.883759
3019.61	-1.50339
3022.9	-0.367279
3026.19	2.73679
3029.47	2.74289
3032.75	1.14636
3036.03	0.906219
3039.31	2.5441
3042.59	3.4296
3045.87	3.29788
3049.14	3.14899
3052.42	0.560699
3055.69	-1.49738
3058.96	-2.88104
3062.23	-3.60089
3065.5	-3.92255
3068.77	-2.91135
3072.03	-1.71359
3075.3	0.69342
3078.56	2.72302
3081.82	3.73007
3085.08	4.52277
3088.34	6.48593
3091.6	5.98132
3094.86	4.26874
3098.11	1.11792
3101.36	0.534363
3104.62	2.12714
3107.87	9.62527
3111.12	10.196
3114.37	9.00763
3117.61	6.91486
3120.86	7.3439
3124.1	7.81396
3127.34	7.37332
3130.59	5.99878
3133.83	4.4747
3137.07	3.81561
3140.3	3.90161
3143.54	4.30847
3146.77	6.97928
3150.01	10.6866
3153.24	13.867
3156.47	16.6983
3159.7	19.1589
3162.93	20.8577
3166.15	21.9081
3169.38	22.8989
3172.6	23.6276
3175.83	24.5428
3179.05	26.4116
3182.27	29.2583
3185.49	32.5099
3188.7	37.6081
3191.92	41.4024
3195.13	45.5116
3198.35	48.2976
3201.56	50.1479
3204.77	51.8575
3207.98	53.4803
3211.19	55.6526
3214.39	57.9305
3217.6	60.4605
3220.8	63.5008
3224	69.6633
3227.21	76.47
3230.41	84.8275
3233.6	94.4031
3236.8	104.437
3240	113.502
3243.19	123.11
3246.39	132.853
3249.58	141.283
3252.77	150.999
3255.96	163.224
3259.15	177.285
3262.33	188.807
3265.52	197.786
3268.7	204.844
3271.89	211.003
3275.07	214.617
3278.25	216.977
3281.43	218.272
3284.6	226.233
3287.78	234.331
3290.95	240.564
3294.13	244.646
3297.3	246.424
3300.47	246.246
3303.64	245.775
3306.81	244.725
3309.98	249.388
3313.14	251.235
3316.31	251.625
3319.47	251.258
3322.63	249.699
3325.79	247.101
3328.95	244.185
3332.11	245.152
3335.27	247.003
3338.42	249.595
3341.58	249.568
3344.73	249.676
3347.88	252.02
3351.03	255.75
3354.18	261.951
3357.33	274.719
3360.47	288.33
3363.62	304.146
3366.76	320.413
3369.91	334.024
3373.05	343.603
3376.19	351.021
3379.32	355.785
3382.46	360.95
3385.6	372.995
3388.73	391.628
3391.87	415.205
3395	447.29
3398.13	483.269
3401.26	522.109
3404.39	553.948
3407.51	579.442
3410.64	600.75
3413.76	610.517
3416.89	609.828
3420.01	598.964
3423.13	582.361
3426.25	559.504
3429.37	539.828
3432.48	522.459
3435.6	508.819
3438.71	500.469
3441.83	497.062
3444.94	500.73
3448.05	512.293
3451.16	523.349
3454.27	530.611
3457.37	539.883
3460.48	554.359
3463.58	578.13
3466.69	609.843
3469.79	644.105
3472.89	681.96
3475.99	724.499
3479.08	767.648
3482.18	811.232
3485.28	844.384
3488.37	861.172
3491.46	861.804
3494.55	851.84
3497.64	839.635
3500.73	819.244
3503.82	802.401
3506.91	780.374
3509.99	755.882
3513.08	733.684
3516.16	706.612
3519.24	673.587
3522.32	640.661
3525.4	597.342
3528.48	552.054
3531.55	507.743
3534.63	468.505
3537.7	431.798
3540.78	401.419
3543.85	377.738
3546.92	360.842
3549.99	350.443
3553.05	345.861
3556.12	345.326
3559.19	345.329
3562.25	338.995
3565.31	329.064
3568.37	318.193
3571.43	305.337
3574.49	286.283
3577.55	263.313
3580.61	240.832
3583.66	218.795
3586.72	199.776
3589.77	184.677
3592.82	177.447
3595.87	177.002
3598.92	179.377
3601.97	182.5
3605.02	185.689
3608.06	186.256
3611.11	182.097
3614.15	179.419
3617.19	172.518
3620.23	162.759
3623.27	155.555
3626.31	150.672
3629.34	145.907
3632.38	145.14
3635.41	144.318
3638.45	142.779
3641.48	141.582
3644.51	137.526
3647.54	129.952
3650.57	117.751
3653.59	104.515
3656.62	93.4407
3659.65	82.539
3662.67	76.8147
3665.69	72.5822
3668.71	65.2914
3671.73	58.7417
3674.75	51.6227
3677.77	45.5687
3680.78	39.6184
3683.8	34.4548
3686.81	29.3975
3689.82	24.5726
3692.84	19.5924
3695.84	15.3205
3698.85	11.2739
3701.86	7.40909
3704.87	5.30011
3707.87	3.60648
3710.88	2.66397
3713.88	2.33243
3716.88	1.74008
3719.88	1.37476
3722.88	1.10196
3725.88	1.12393
3728.88	1.40887
3731.87	1.91943
3734.87	2.595
3737.86	3.61356
3740.85	1.98187
3743.84	1.99124
3746.83	1.51257
3749.82	1.82892
3752.81	0.745819
3755.79	-0.806885
3758.78	-2.62167
3761.76	-4.67157
3764.74	-7.03424
3767.73	-9.68033
3770.71	-12.8541
3773.68	-17.74
3776.66	-21.0873
3779.64	-17.9586
3782.61	-12.8561
3785.59	-6.35101
3788.56	-1.13522
3791.53	0.699249
3794.5	0.71106
3797.47	2.2204
3800.44	4.32574
3803.41	6.33719
3806.37	4.02875
3809.34	3.06537
3812.3	2.30106
3815.26	1.23505
3818.22	4.78018
3821.18	3.88449
3824.14	3.36157
3827.1	4.32248
3830.06	6.30478
3833.01	5.99225
3835.96	3.39368
3838.92	1.13248
3841.87	0.579834
3844.82	1.81351
3847.77	4.20956
3850.72	-0.2117
3853.66	-0.674652
3856.61	-0.729523
3859.55	1.75806
3862.5	3.54709
3865.44	3.67816
3868.38	3.93491
3871.32	4.42728
3874.26	5.28128
3877.2	6.49982
3880.13	7.75418
3883.07	9.13361
3886	10.2337
3888.94	9.8544
3891.87	10.5171
3894.8	10.0082
3897.73	8.85382
3900.66	8.9548
3903.58	11.0399
3906.51	14.389
3909.43	17.3389
3912.36	17.8163
3915.28	14.8377
3918.2	10.5055
3921.12	6.92599
3924.04	4.5502
3926.96	2.47888
3929.87	1.22034
3932.79	0.415619
3935.7	0.0540466
3938.62	-0.24823
3941.53	0.85733
3944.44	3.06613
3947.35	5.85956
3950.26	7.98172
3953.17	7.95215
3956.07	7.72244
3958.98	7.59039
3961.88	7.40967
3964.78	7.31335
3967.69	7.17285
3970.59	6.918
3973.49	5.06531
3976.38	3.09149
3979.28	2.68414
3982.18	2.48019
3985.07	2.0871
3987.97	1.71582
3990.86	0.397339
3993.75	-1.3627
3996.64	-2.24463
3999.53	-1.95975