File: Data/3-Raman/processed/bu32-b-ff2-fi02-v_1800 (450-850nm)_532nm_edge_100%_x100_vis_lwd_h30um_30sx2_01.txt
#Acq. time (s)=	30
#Accumulations=	2
#Range (cm-¹)=	1200...2999
#Windows=	5
#Auto scanning=	Off
#Autofocus=	Off
#Macrospot=	Off
#AutoExposure=	Off
#Spike filter=	Multiple accum.
#Delay time (s)=	2
#Binning=	1
#Readout mode=	Signal
#DeNoise=	Off
#ICS correction=	On
#Dark correction=	Off
#Inst. Process=	Off
#Detector Gain=	Best Dynamic
#Detector ADC=	50 kHz EM
#Detector EM gain=	150
#Detector temperature (°C)=	-60.09
#Instrument=	LabRAM HR Evol
#Detector=	SIN-EM FIVIS
#Objective=	x100_VIS_LWD
#Grating=	1800 (450-850nm)
#ND Filter=	100%
#Laser=	532nm_Edge
#Hole=	30.0125
#Temperature=	40
#Range=	Visible
#StageXY=	75x50mm Scan+
#StageZ=	Z motor
#X (µm)=	0
#Y (µm)=	0
#Z (µm)=	65
#Full time(mm:ss)=	5:33
#Project=	21_08_11
#Sample=	BU32
#Site=
#Title=	BU32-B-FF2-FI02-V_1800 (450-850nm)_532nm_Edge_100%_x100_VIS_LWD_H30um_30sX2
#Remark=
#Date=	13.08.2021 16:12
#Acquired=	13.08.2021 16:12:23
#Base:Fit=	16.12.2021 15:06:42
#Base:Sub=	16.12.2021 15:06:44
1200.05	14.4241
1201.44	8.27252
1202.83	8.90393
1204.22	14.9182
1205.61	10.0327
1207	5.10498
1208.39	-5.9126
1209.78	11.0375
1211.16	6.21753
1212.55	0.405121
1213.94	6.71851
1215.33	-1.75824
1216.71	1.98492
1218.1	1.64218
1219.49	0.467957
1220.87	-10.1679
1222.26	-5.38229
1223.64	5.62851
1225.03	0.259125
1226.41	-1.77841
1227.79	-1.59052
1229.18	-2.70648
1230.56	-2.39502
1231.94	-3.0271
1233.33	-1.94049
1234.71	1.50192
1236.09	-9.91168
1237.47	10.7053
1238.86	15.5674
1240.24	4.05789
1241.62	-2.23917
1243	11.5945
1244.38	3.26544
1245.76	5.00214
1247.14	-7.53836
1248.52	0.695251
1249.9	-1.37198
1251.27	-7.90167
1252.65	6.4805
1254.03	0.457123
1255.41	12.0802
1256.79	-3.39822
1258.16	12.1849
1259.54	-2.19934
1260.92	21.4478
1262.29	14.7425
1263.67	45.4315
1265.04	32.8617
1266.42	13.1518
1267.79	5.41071
1269.17	11.0361
1270.54	10.7208
1271.92	2.55807
1273.29	22.0141
1274.66	6.54022
1276.04	13.2267
1277.41	3.18298
1278.78	12.0428
1280.15	12.054
1281.53	29.2589
1282.9	157.14
1284.27	980.272
1285.64	161.332
1287.01	47.5436
1288.38	12.8168
1289.75	19.545
1291.12	5.88068
1292.49	19.6297
1293.86	7.54742
1295.23	2.71158
1296.6	10.6243
1297.96	8.32941
1299.33	13.5164
1300.7	22.1366
1302.07	17.1225
1303.43	9.68335
1304.8	-0.873413
1306.17	2.04752
1307.53	4.27762
1308.9	7.65134
1310.26	5.68997
1311.63	8.02518
1312.99	4.95108
1314.36	11.3712
1315.72	16.9137
1317.08	18.0568
1318.45	22.463
1319.81	14.0952
1321.17	1.17401
1322.53	3.07651
1323.9	5.2504
1325.26	6.19525
1326.62	14.2018
1327.98	-1.81238
1329.34	8.96265
1330.7	11.9073
1332.06	9.28546
1333.42	10.919
1334.78	13.7427
1336.14	7.25555
1337.5	16.5622
1338.86	0.692596
1340.22	17.6002
1341.58	13.3682
1342.93	11.0292
1344.29	12.1272
1345.65	1.33475
1347	6.06146
1348.36	15.3107
1349.72	15.0786
1351.07	2.3071
1352.43	4.64038
1353.78	24.3871
1355.14	17.693
1356.49	12.6058
1357.85	19.7095
1359.2	6.0192
1360.56	8.83847
1361.91	22.2756
1363.26	10.0078
1364.61	29.704
1365.97	11.7951
1367.32	7.46899
1368.67	7.67856
1370.02	38.6029
1371.37	16.5343
1372.72	11.0037
1374.07	27.4186
1375.42	19.239
1376.77	6.56628
1378.12	15.5043
1379.47	16.5299
1380.82	29.3197
1382.17	17.4036
1383.52	19.0741
1384.87	63.6167
1386.21	153.442
1387.56	1809.61
1388.91	192.435
1390.26	57.5312
1391.6	29.5251
1392.95	26.2664
1394.3	35.4368
1395.64	11.1113
1396.99	13.012
1398.33	4.95566
1399.68	3.14249
1401.02	26.978
1402.37	24.6714
1403.71	19.5747
1405.05	22.5836
1406.39	19.418
1407.74	42.1832
1409.08	129.606
1410.42	40.2079
1411.76	21.6697
1413.11	12.2931
1414.45	14.328
1415.79	12.4483
1417.13	10.6745
1418.47	9.80124
1419.81	13.7935
1421.15	16.729
1422.49	26.833
1423.83	1.96695
1425.17	9.46021
1426.51	15.6193
1427.84	18.3376
1429.18	8.3251
1430.52	19.1434
1431.86	14.1823
1433.19	26.0128
1434.53	38.5092
1435.87	13.9488
1437.2	15.9519
1438.54	6.91034
1439.87	12.4063
1441.21	9.40268
1442.54	6.4902
1443.88	18.7385
1445.21	7.79248
1446.55	2.62231
1447.88	14.9458
1449.21	7.90244
1450.55	2.6731
1451.88	21.0666
1453.21	5.88724
1454.54	5.927
1455.88	9.16397
1457.21	13.1658
1458.54	15.3308
1459.87	23.5816
1461.2	21.4205
1462.53	14.0069
1463.86	5.97083
1465.19	13.4259
1466.52	8.20871
1467.85	15.417
1469.18	15.35
1470.51	1.92166
1471.83	18.1087
1473.16	10.9287
1474.49	8.95477
1475.82	14.0194
1477.14	-1.33295
1478.47	10.751
1479.79	0.313141
1481.12	3.19821
1482.45	19.7624
1483.77	3.54565
1485.1	13.3573
1486.42	5.09369
1487.75	6.00516
1489.07	3.77905
1490.39	8.79089
1491.72	22.9157
1493.04	7.77151
1494.36	6.87466
1495.69	16.6308
1497.01	10.5095
1498.33	7.55038
1499.65	10.7679
1500.97	11.7382
1502.29	11.6833
1503.62	6.56653
1504.93	2.54871
1506.26	3.38397
1507.58	12.6018
1508.89	6.63287
1510.21	13.7081
1511.53	7.11282
1512.85	8.65332
1514.17	1.87445
1515.49	5.53677
1516.81	11.4545
1518.12	-1.37799
1519.44	22.8676
1520.76	2.90112
1522.07	-7.14224
1523.39	12.5964
1524.71	17.5326
1526.02	1.84995
1527.34	6.88239
1528.65	3.80542
1529.97	0.804138
1531.28	18.0938
1532.59	13.3474
1533.91	11.6061
1535.22	4.37476
1536.54	3.92618
1537.85	7.71579
1539.16	11.1895
1540.47	21.9415
1541.79	12.5794
1543.1	13.2418
1544.41	-2.64258
1545.72	-4.20895
1547.03	6.9971
1548.34	7.9989
1549.65	10.707
1550.96	16.9322
1552.27	10.0477
1553.58	8.65305
1554.89	13.3344
1556.2	10.3736
1557.5	3.43719
1558.81	4.02466
1560.12	4.85303
1561.43	11.0407
1562.74	5.21869
1564.04	26.533
1565.35	12.5044
1566.65	12.2322
1567.96	23.4375
1569.27	14.3172
1570.57	5.42166
1571.88	10.3066
1573.18	9.11365
1574.48	11.4629
1575.79	7.68723
1577.09	0.298737
1578.4	10.0374
1579.7	18.1729
1581	14.1301
1582.3	9.99594
1583.61	-1.96561
1584.91	14.0895
1586.21	3.95697
1587.51	14.836
1588.81	4.1488
1590.11	14.2797
1591.41	11.3484
1592.72	-3.9097
1594.01	10.6448
1595.31	14.7026
1596.61	4.853
1597.91	14.8409
1599.21	12.5721
1600.51	16.6308
1601.81	4.3501
1603.1	13.6978
1604.4	9.34064
1605.7	7.84421
1607	3.32013
1608.29	2.9617
1609.59	-1.51816
1610.88	9.84198
1612.18	3.03625
1613.48	9.14413
1614.77	9.76407
1616.07	9.60229
1617.36	2.06354
1618.65	4.77756
1619.95	4.16089
1621.24	2.8916
1622.54	-2.64429
1623.83	2.00223
1625.12	-1.21393
1626.41	5.28467
1627.56	-1.03958
1628.87	-1.96884
1630.17	-4.96106
1631.48	5.08786
1632.79	-0.690826
1634.1	4.31323
1635.4	-2.58951
1636.71	-10.6176
1638.01	3.09442
1639.32	-6.68787
1640.62	1.37225
1641.93	-8.50397
1643.23	1.3512
1644.54	5.19839
1645.84	3.35254
1647.15	-0.667511
1648.45	3.49591
1649.75	-1.22031
1651.05	10.998
1652.36	15.9607
1653.66	-2.66287
1654.96	6.47574
1656.26	8.85806
1657.56	0.932434
1658.86	-6.11313
1660.16	1.79752
1661.46	12.9985
1662.77	6.60278
1664.07	3.36545
1665.36	7.5293
1666.66	-2.69537
1667.96	0.354279
1669.26	8.72522
1670.56	3.10303
1671.86	6.12741
1673.15	4.25171
1674.45	-0.424652
1675.75	4.70541
1677.05	8.73111
1678.34	9.50433
1679.64	7.42361
1680.94	8.35028
1682.23	5.45071
1683.53	-9.34128
1684.82	4.43475
1686.12	5.55347
1687.41	12.5242
1688.71	8.40768
1690	0.384949
1691.29	-2.3428
1692.59	10.3964
1693.88	0.211639
1695.17	7.13068
1696.47	5.31821
1697.76	3.06757
1699.05	1.01166
1700.34	10.8523
1701.63	14.6435
1702.92	-4.16129
1704.21	-4.08328
1705.5	-10.9517
1706.79	-0.44278
1708.08	5.01718
1709.37	4.76221
1710.66	9.82437
1711.95	-0.880798
1713.24	-0.479126
1714.53	1.33148
1715.82	-0.481079
1717.11	3.95526
1718.39	3.45657
1719.68	2.54303
1720.97	9.13562
1722.25	3.93765
1723.54	13.4947
1724.83	-1.36169
1726.11	-5.45557
1727.4	2.24149
1728.68	-4.70657
1729.97	0.326569
1731.25	9.38983
1732.54	4.44946
1733.82	8.78616
1735.1	-4.1683
1736.39	7.23282
1737.67	6.08481
1738.95	0.950409
1740.24	-1.51993
1741.52	-0.820282
1742.8	2.94958
1744.08	-2.95691
1745.36	0.900848
1746.65	2.49429
1747.93	-0.563202
1749.21	-1.30887
1750.49	-3.83035
1751.77	-11.6407
1753.05	-1.40747
1754.33	3.12799
1755.6	2.92715
1756.88	-3.16901
1758.16	6.48856
1759.44	-6.76227
1760.72	-3.08301
1762	2.53473
1763.27	3.62073
1764.55	-2.6796
1765.83	3.17377
1767.1	-6.38858
1768.38	-4.62744
1769.66	-1.28348
1770.93	4.79037
1772.21	8.9129
1773.48	3.43973
1774.76	-3.98413
1776.03	-7.43146
1777.31	8.60678
1778.58	0.705627
1779.85	-4.93457
1781.13	-2.86978
1782.4	11.7278
1783.67	2.466
1784.94	2.71002
1786.22	0.833069
1787.49	4.33484
1788.76	5.99835
1790.03	1.54333
1791.3	1.27393
1792.57	-0.513245
1793.84	11.1342
1795.11	4.96484
1796.38	9.16589
1797.65	-0.145203
1798.92	10.4556
1800.19	15.0577
1801.46	-2.20587
1802.73	1.92148
1804	-0.702118
1805.26	2.59253
1806.53	1.90881
1807.8	5.83878
1809.07	13.6606
1810.33	-0.732056
1811.6	12.8009
1812.87	14.0238
1814.13	19.2701
1815.4	15.6873
1816.66	9.99643
1817.93	7.91165
1819.19	14.9031
1820.46	16.1034
1821.72	14.4387
1822.99	11.6454
1824.25	9.76675
1825.51	6.06012
1826.77	6.16342
1828.04	7.25565
1829.3	9.10959
1830.56	10.9842
1831.82	9.31192
1833.09	6.61557
1834.35	4.47574
1835.61	11.8296
1836.87	4.68359
1838.13	1.98901
1839.39	8.72873
1840.65	5.00708
1841.91	1.53506
1843.17	17.9688
1844.43	15.1164
1845.69	9.67465
1846.94	10.7355
1848.2	14.6883
1849.46	4.77823
1850.72	5.33746
1851.97	11.9716
1853.23	0.414703
1854.49	4.87402
1855.74	5.54663
1857	16.0616
1858.26	7.21207
1859.51	-6.39417
1860.77	16.7989
1862.02	7.30374
1863.28	2.20685
1864.53	14.3677
1865.78	6.21582
1867.04	13.2234
1868.29	18.81
1869.54	-2.11105
1870.8	11.1842
1872.05	11.9811
1873.3	11.8166
1874.56	14.3468
1875.81	6.21774
1877.06	5.62692
1878.31	9.99777
1879.56	5.52588
1880.81	9.27914
1882.06	3.75952
1883.31	5.6553
1884.56	5.3649
1885.81	-0.759888
1887.06	-2.89856
1888.31	16.4498
1889.56	0.239319
1890.81	5.15491
1892.05	7.93661
1893.3	1.75848
1894.55	8.22998
1895.8	14.069
1897.04	8.70398
1898.29	-1.7226
1899.54	7.43588
1900.78	4.74002
1902.03	2.27969
1903.27	14.4101
1904.52	7.79581
1905.76	5.7153
1907.01	-2.80582
1908.25	-8.24472
1909.5	9.05563
1910.74	10.4588
1911.98	6.71591
1913.23	-0.704163
1914.47	4.44159
1915.71	6.43335
1916.96	10.011
1918.2	6.38449
1919.44	10.7315
1920.68	5.24228
1921.92	23.4286
1923.16	-5.07788
1924.41	9.90732
1925.65	-4.85287
1926.89	1.22552
1928.12	-3.3028
1929.36	6.52917
1930.6	2.15985
1931.84	6.78821
1933.08	11.4688
1934.32	12.5735
1935.56	15.8576
1936.8	11.8613
1938.03	12.6282
1939.27	9.14447
1940.51	12.5024
1941.75	5.60822
1942.98	5.99765
1944.22	10.9471
1945.45	19.0099
1946.69	11.534
1947.92	0.979675
1949.16	9.82645
1950.4	6.59729
1951.63	16.7479
1952.86	23.7082
1954.1	14.3111
1955.33	1.87866
1956.56	15.9385
1957.8	10.4812
1959.03	11.3897
1960.26	15.04
1961.5	13.9454
1962.73	15.9704
1963.96	9.39481
1965.19	13.2499
1966.42	16.4596
1967.65	13.677
1968.88	15.4536
1970.11	22.7756
1971.34	7.26422
1972.57	7.3342
1973.8	15.7479
1975.03	12.9901
1976.26	13.173
1977.49	11.1587
1978.72	7.2197
1979.95	12.0336
1981.17	16.6398
1982.4	16.6953
1983.63	16.8993
1984.85	3.53973
1986.08	12.745
1987.31	6.50238
1988.53	20.525
1989.76	4.80457
1990.98	15.5206
1992.21	6.52908
1993.43	8.64972
1994.66	6.1875
1995.88	6.34198
1997.11	5.8847
1998.33	3.6196
1999.55	2.91922
2000.78	0.48877
2002	-1.11807
2003.22	3.5658
2004.45	1.83087
2005.59	-4.18149
2006.83	-10.7467
2008.06	3.05875
2009.3	-3.94229
2010.54	-1.34265
2011.77	3.33511
2013.01	-1.73099
2014.25	-6.09982
2015.48	2.49973
2016.72	3.75562
2017.95	13.6172
2019.19	-0.935059
2020.42	-6.62604
2021.66	-8.48279
2022.89	2.44064
2024.12	2.08707
2025.36	1.62872
2026.59	-0.608765
2027.82	8.45227
2029.06	5.59042
2030.29	1.44373
2031.52	1.81595
2032.75	3.26117
2033.98	7.70078
2035.21	6.92776
2036.45	-0.327545
2037.68	-3.15018
2038.91	3.16611
2040.14	-1.85806
2041.37	0.735504
2042.6	4.31824
2043.83	7.56268
2045.05	10.3567
2046.28	-0.487122
2047.51	-6.63168
2048.74	-10.1704
2049.97	1.49033
2051.2	3.25543
2052.42	-5.01263
2053.65	5.68906
2054.88	3.82736
2056.1	-8.48157
2057.33	9.37137
2058.56	9.71234
2059.78	2.28439
2061.01	1.41412
2062.23	5.27335
2063.46	2.71515
2064.68	12.3365
2065.91	-1.36185
2067.13	6.32794
2068.35	-0.0307922
2069.58	-3.15463
2070.8	13.2948
2072.02	6.15244
2073.25	5.19742
2074.47	5.43912
2075.69	5.09253
2076.91	-5.43814
2078.13	10.6014
2079.35	4.38126
2080.58	0.729401
2081.8	10.1839
2083.02	2.66922
2084.24	14.9718
2085.46	-2.92072
2086.68	3.08963
2087.9	5.09576
2089.12	7.16327
2090.33	7.36365
2091.55	4.82544
2092.77	8.1673
2093.99	11.3325
2095.21	7.39209
2096.43	0.632172
2097.64	8.99033
2098.86	5.12387
2100.08	9.90219
2101.29	9.20126
2102.51	9.13373
2103.73	9.98962
2104.94	-0.210846
2106.16	-1.89203
2107.37	11.3815
2108.59	1.56055
2109.8	7.43878
2111.01	3.62616
2112.23	4.53674
2113.44	10.4949
2114.66	9.5267
2115.87	15.0727
2117.08	13.0909
2118.29	-4.29907
2119.51	4.88126
2120.72	5.88385
2121.93	7.1889
2123.14	14.0074
2124.35	-6.2352
2125.57	3.63663
2126.78	13.7121
2127.99	8.88336
2129.2	9.78348
2130.41	7.80087
2131.62	12.3255
2132.82	10.2604
2134.03	12.2121
2135.24	5.54132
2136.45	2.45639
2137.66	11.9839
2138.87	4.54068
2140.08	3.18576
2141.28	9.64209
2142.49	4.96979
2143.7	2.50629
2144.9	7.34567
2146.11	12.9069
2147.32	11.7914
2148.52	2.21191
2149.73	6.4874
2150.93	12.1076
2152.14	2.83621
2153.34	2.63791
2154.55	16.1851
2155.75	0.764526
2156.96	-0.18454
2158.16	12.1327
2159.36	6.33316
2160.57	0.425415
2161.77	-3.38388
2162.97	8.64127
2164.17	6.52789
2165.38	0.95166
2166.58	15.6824
2167.78	20.743
2168.98	0.375671
2170.18	-2.00418
2171.38	7.77454
2172.58	-1.78122
2173.78	-3.55035
2174.98	4.80936
2176.18	13.9841
2177.38	9.33698
2178.58	3.59796
2179.78	-1.01993
2180.98	3.55127
2182.18	9.8945
2183.38	4.01624
2184.57	-5.30823
2185.77	7.87042
2186.97	15.7331
2188.16	6.38535
2189.36	2.26575
2190.56	14.3327
2191.76	-4.10434
2192.95	-7.60272
2194.15	11.4885
2195.34	7.56973
2196.54	2.50125
2197.73	8.95163
2198.93	8.48285
2200.12	7.30774
2201.31	12.7284
2202.51	22.8505
2203.7	7.78696
2204.89	4.28436
2206.09	2.30133
2207.28	18.2008
2208.47	8.27695
2209.67	-8.42258
2210.86	15.1093
2212.05	11.6505
2213.24	10.5349
2214.43	1.57773
2215.62	15.6602
2216.81	1.62326
2218	4.46683
2219.19	-0.909271
2220.38	12.2184
2221.57	6.29947
2222.76	5.44019
2223.95	16.1384
2225.14	9.05063
2226.33	11.2541
2227.51	17.9902
2228.7	2.89316
2229.89	8.79419
2231.08	15.7202
2232.27	20.7429
2233.45	9.74585
2234.64	15.2969
2235.82	13.2656
2237.01	13.4644
2238.2	2.71063
2239.38	18.9124
2240.57	19.9175
2241.75	8.71667
2242.94	11.5828
2244.12	9.67865
2245.3	8.26828
2246.49	14.2163
2247.67	12.4063
2248.85	11.3791
2250.04	13.2687
2251.22	22.4644
2252.4	15.1708
2253.59	10.9673
2254.77	13.9138
2255.95	10.2677
2257.13	14.3327
2258.31	8.76065
2259.49	13.7045
2260.67	14.907
2261.85	5.55603
2263.03	25.9277
2264.21	7.42987
2265.39	14.3448
2266.57	20.7125
2267.75	4.22525
2268.93	16.8123
2270.11	16.3302
2271.29	10.8532
2272.47	12.9054
2273.64	13.9552
2274.82	7.34882
2276	14.2681
2277.17	16.6231
2278.35	20.8187
2279.53	23.3704
2280.71	21.1452
2281.88	22.1378
2283.06	25.4604
2284.23	27.0114
2285.41	11.7484
2286.58	14.72
2287.76	15.9714
2288.93	21.3776
2290.1	19.1258
2291.28	11.7515
2292.45	22.67
2293.62	20.8904
2294.8	24.5026
2295.97	7.80304
2297.14	17.6076
2298.31	8.35641
2299.49	22.1001
2300.66	5.8259
2301.83	23.2321
2303	11.6048
2304.17	17.5762
2305.34	24.5304
2306.51	11.1032
2307.68	23.5354
2308.85	12.9897
2310.02	14.2529
2311.19	9.89044
2312.36	7.61804
2313.53	18.5784
2314.7	21.9687
2315.87	16.6547
2317.03	13.6298
2318.2	1.98608
2319.37	25.9024
2320.54	13.4379
2321.7	21.5369
2322.87	20.7198
2324.03	27.5132
2325.2	35.7578
2326.37	45.0408
2327.53	66.8938
2328.7	154.458
2329.86	37.7463
2331.03	18.4705
2332.19	21.297
2333.36	23.0182
2334.52	14.0873
2335.68	12.1534
2336.85	19.7433
2338.01	19.6433
2339.17	-0.548126
2340.34	9.78326
2341.5	21.7837
2342.66	11.9564
2343.82	17.5607
2344.98	23.5642
2346.14	14.4175
2347.31	26.8747
2348.47	7.40137
2349.63	16.3381
2350.79	20.959
2351.95	5.13382
2353.11	7.88098
2354.27	5.24667
2355.43	14.2261
2356.59	23.7618
2357.74	7.25711
2358.9	12.2628
2360.06	7.26743
2361.22	3.17651
2362.38	8.9032
2363.53	-0.214844
2364.69	8.00107
2365.74	15.3203
2366.92	24.2371
2368.09	5.15549
2369.26	-2.6929
2370.43	10.1423
2371.6	9.90244
2372.77	-3.52539
2373.94	4.71201
2375.11	8.16769
2376.28	-5.16428
2377.45	7.77209
2378.62	-2.86014
2379.79	10.7878
2380.96	0.386963
2382.13	-5.26447
2383.29	1.18378
2384.46	-7.29395
2385.63	9.25052
2386.8	-4.27679
2387.97	6.71649
2389.13	-5.51797
2390.3	-3.69016
2391.47	9.40176
2392.63	-2.97528
2393.8	-1.60934
2394.96	4.79364
2396.13	10.4728
2397.29	-0.0179138
2398.46	-1.91809
2399.62	2.74374
2400.79	-1.08835
2401.95	4.34793
2403.12	-1.01617
2404.28	6.03583
2405.44	1.62012
2406.61	11.0178
2407.77	-5.80951
2408.93	9.03033
2410.09	-6.8244
2411.26	6.22775
2412.42	-8.53455
2413.58	9.23822
2414.74	4.43381
2415.9	-3.26312
2417.06	3.37955
2418.22	3.60364
2419.38	4.9494
2420.54	12.5239
2421.7	9.4205
2422.86	3.1799
2424.02	-5.03787
2425.18	10.2511
2426.34	-4.46042
2427.5	7.8811
2428.66	6.83578
2429.81	5.84048
2430.97	9.63525
2432.13	1.62643
2433.29	1.93311
2434.44	2.9213
2435.6	-0.555328
2436.76	2.50287
2437.91	6.21844
2439.07	1.77182
2440.23	-3.52609
2441.38	12.5868
2442.53	16.594
2443.69	-1.13495
2444.84	15.1594
2446	11.5793
2447.15	8.13336
2448.31	-4.18085
2449.46	20.5252
2450.61	15.2169
2451.77	13.6348
2452.92	8.8537
2454.07	12.6407
2455.22	20.6197
2456.38	5.71558
2457.53	7.76181
2458.68	15.4034
2459.83	7.02051
2460.98	13.834
2462.14	17.6243
2463.29	14.8672
2464.43	7.95377
2465.59	21.3665
2466.74	2.10114
2467.88	8.70038
2469.03	14.3022
2470.18	15.4198
2471.33	7.91351
2472.48	9.18875
2473.63	12.9247
2474.78	8.45224
2475.92	7.06317
2477.07	24.4437
2478.22	26.073
2479.37	11.3241
2480.51	21.5855
2481.66	6.88998
2482.81	13.5485
2483.95	8.64789
2485.1	7.65097
2486.24	13.451
2487.39	13.1916
2488.53	5.33167
2489.68	-1.48416
2490.82	6.17563
2491.97	3.07053
2493.11	8.07504
2494.25	7.83728
2495.4	11.4412
2496.54	7.7037
2497.69	7.24905
2498.83	1.78903
2499.97	1.71695
2501.11	4.94595
2502.25	11.2856
2503.4	17.8151
2504.54	10.893
2505.68	2.29343
2506.82	11.0414
2507.96	20.5679
2509.1	-1.30576
2510.24	14.401
2511.38	10.8194
2512.52	15.3604
2513.66	8.91351
2514.8	6.85797
2515.94	7.2261
2517.08	8.54803
2518.21	10.0743
2519.35	6.21091
2520.49	0.837677
2521.63	7.49017
2522.77	4.29611
2523.9	1.3833
2525.04	6.82486
2526.18	9.00931
2527.31	12.5152
2528.45	-3.3595
2529.58	0.520203
2530.72	13.5451
2531.86	6.71149
2532.99	8.29272
2534.13	3.72333
2535.26	19.4318
2536.4	-0.306885
2537.53	-1.48224
2538.66	13.1294
2539.8	16.5471
2540.93	14.6031
2542.06	-1.96942
2543.2	6.51254
2544.33	0.647888
2545.46	-4.97101
2546.59	7.0033
2547.73	10.7499
2548.86	7.14084
2549.99	4.58078
2551.12	10.4454
2552.25	10.6217
2553.38	8.58646
2554.51	16.9729
2555.64	0.350983
2556.77	8.30838
2557.9	4.65289
2559.03	14.9878
2560.16	20.4914
2561.29	12.9867
2562.42	2.81363
2563.55	-7.05411
2564.67	9.46045
2565.8	7.58002
2566.93	6.65387
2568.06	17.9155
2569.18	-3.72641
2570.31	-0.657379
2571.44	4.61581
2572.56	19.3167
2573.69	12.0045
2574.81	2.30054
2575.94	10.1743
2577.06	3.75208
2578.19	11.8112
2579.31	11.2819
2580.44	8.6702
2581.56	-0.739868
2582.69	26.0263
2583.81	18.4687
2584.94	0.50412
2586.06	21.0627
2587.18	32.9968
2588.3	17.4003
2589.43	8.85684
2590.55	6.90512
2591.67	8.8414
2592.79	16.7827
2593.91	11.3811
2595.04	22.2118
2596.16	13.6602
2597.28	10.378
2598.4	9.21173
2599.52	16.3585
2600.64	2.90726
2601.76	22.8023
2602.88	13.0691
2604	13.0827
2605.12	7.35995
2606.24	22.873
2607.35	8.49188
2608.47	6.04956
2609.59	16.8929
2610.71	16.0171
2611.83	9.09927
2612.94	6.02023
2614.06	14.9204
2615.18	2.83557
2616.29	9.82339
2617.41	22.5995
2618.53	20.7281
2619.64	16.3294
2620.76	19.7643
2621.87	14.4895
2622.99	17.5118
2624.1	7.84595
2625.22	21.4916
2626.33	19.7013
2627.45	15.9146
2628.56	12.925
2629.67	15.6925
2630.79	9.93185
2631.9	18.8133
2633.01	12.892
2634.12	18.5192
2635.24	25.7131
2636.35	16.5371
2637.46	10.2326
2638.57	17.968
2639.68	22.0026
2640.8	24.2953
2641.91	9.86862
2643.02	4.36633
2644.13	15.653
2645.24	17.289
2646.35	2.56073
2647.46	21.7346
2648.57	15.3206
2649.67	8.32813
2650.78	11.133
2651.89	6.94965
2653	5.84805
2654.11	6.60526
2655.22	16.8159
2656.32	8.11871
2657.43	15.9406
2658.54	14.728
2659.65	4.51331
2660.75	-0.354675
2661.86	20.3451
2662.96	10.8778
2664.07	16.3358
2665.18	4.71753
2666.28	-0.192474
2667.39	-7.09824
2668.49	22.0371
2669.6	14.2791
2670.7	4.78522
2671.8	1.64771
2672.91	4.9834
2674.01	9.43842
2675.11	13.468
2676.22	0.494995
2677.32	10.6422
2678.42	-6.69186
2679.53	3.51172
2680.63	4.31409
2681.73	3.43579
2682.83	11.4752
2683.93	-6.02887
2685.03	6.24033
2686.14	8.32382
2687.24	3.66595
2688.34	3.11563
2689.44	4.93689
2690.54	11.985
2691.64	7.94742
2692.74	4.25787
2693.84	4.55014
2694.93	7.22351
2696.03	5.34149
2697.13	4.6478
2698.23	5.47702
2699.33	5.07101
2700.43	-3.34332
2701.52	0.520294
2702.62	4.2814
2703.72	-2.56662
2704.81	-0.837128
2705.9	-3.65506
2707.01	-7.44513
2708.12	-10.5219
2709.23	-1.04474
2710.34	2.78864
2711.45	-5.84286
2712.56	8.67966
2713.67	2.20236
2714.78	2.7037
2715.89	2.68738
2716.99	-2.28577
2718.1	-2.29507
2719.21	11.125
2720.32	6.86957
2721.43	-4.3349
2722.54	-5.53424
2723.64	1.92679
2724.75	-7.1875
2725.86	10.5652
2726.96	2.02591
2728.07	-1.61581
2729.18	2.21432
2730.28	11.8919
2731.39	-0.0370483
2732.49	-2.95285
2733.6	-0.407349
2734.71	6.20892
2735.81	-4.69122
2736.91	0.159729
2738.02	3.89813
2739.12	2.14157
2740.23	1.98495
2741.33	-0.0741882
2742.43	1.25723
2743.54	4.47119
2744.64	9.61658
2745.74	12.3897
2746.84	4.52676
2747.95	5.49179
2749.05	1.75327
2750.15	2.6734
2751.25	11.468
2752.35	6.19547
2753.45	7.24863
2754.55	-2.43033
2755.66	-0.689941
2756.76	5.21936
2757.86	-7.96536
2758.96	7.19073
2760.05	5.22458
2761.15	-3.93607
2762.25	6.03183
2763.35	11.0174
2764.45	7.4751
2765.55	3.56116
2766.65	-1.43707
2767.75	13.5049
2768.84	-6.50507
2769.94	15.5202
2771.04	16.5552
2772.13	-0.900482
2773.23	3.89297
2774.33	13.8938
2775.42	8.05124
2776.52	7.79202
2777.61	2.96982
2778.71	7.74802
2779.81	5.50717
2780.9	1.62262
2782	6.4249
2783.09	-4.29327
2784.18	-0.780426
2785.28	4.14352
2786.37	1.47183
2787.47	7.83563
2788.56	-0.229553
2789.65	3.35538
2790.74	11.733
2791.84	1.02951
2792.93	-0.730103
2794.02	-5.61621
2795.11	2.93896
2796.2	-8.6694
2797.3	3.46964
2798.39	-0.516327
2799.48	7.19223
2800.57	-0.506531
2801.66	3.15762
2802.75	-8.06915
2803.84	1.97211
2804.93	-9.68335
2806.02	-3.9696
2807.11	6.33832
2808.2	3.40717
2809.28	-1.42438
2810.37	-7.2243
2811.46	3.71783
2812.55	-7.88132
2813.64	3.54364
2814.73	-6.99475
2815.81	11.5896
2816.9	3.90875
2817.99	6.30011
2819.07	3.22794
2820.16	1.76306
2821.25	13.408
2822.33	3.01627
2823.42	-3.86234
2824.5	-8.47159
2825.59	-2.99985
2826.67	10.3199
2827.76	-2.64423
2828.84	-10.5588
2829.93	9.9805
2831.01	0.694153
2832.09	6.98917
2833.18	-4.47858
2834.26	1.15723
2835.34	-3.32623
2836.43	1.50491
2837.51	8.01563
2838.59	1.34503
2839.67	11.8185
2840.75	-6.41718
2841.84	-3.78897
2842.92	12.9277
2844	6.13757
2845.08	7.86813
2846.16	-2.14218
2847.24	2.7771
2848.32	4.2511
2849.4	7.14957
2850.48	-4.85434
2851.56	7.45496
2852.64	0.753082
2853.72	4.57703
2854.8	3.69763
2855.87	-12.2964
2856.95	5.51489
2858.03	0.883881
2859.11	5.53647
2860.19	9.28516
2861.26	-6.23062
2862.34	3.547
2863.42	1.40494
2864.49	4.95465
2865.57	-4.33466
2866.65	9.07407
2867.72	8.17627
2868.8	1.03546
2869.87	7.52036
2870.95	1.83997
2872.02	17.6971
2873.1	-3.96848
2874.17	3.03412
2875.25	0.526825
2876.32	12.73
2877.4	2.33099
2878.47	5.31732
2879.54	14.5758
2880.62	-1.53558
2881.69	5.38812
2882.76	-6.82144
2883.83	-9.08557
2884.9	3.47806
2885.98	-5.78967
2887.05	3.77219
2888.12	1.25702
2889.19	-7.16446
2890.26	6.99658
2891.33	-9.22055
2892.4	-3.43011
2893.47	0.613281
2894.54	-0.740448
2895.61	-5.90903
2896.68	3.44095
2897.75	3.46854
2898.82	2.55832
2899.89	7.54126
2900.96	10.4327
2902.03	-2.99936
2903.09	11.3241
2904.16	11.5672
2905.23	4.04666
2906.3	-1.03189
2907.36	7.37488
2908.43	-8.65073
2909.5	9.32791
2910.57	5.59808
2911.63	0.906708
2912.7	19.1004
2913.76	10.3941
2914.83	25.4207
2915.89	28.2612
2916.96	10.1819
2918.02	1.5957
2919.09	9.1199
2920.15	6.01157
2921.22	4.81165
2922.28	-0.166901
2923.34	-6.87677
2924.41	10.1974
2925.47	-1.25861
2926.53	5.29672
2927.6	1.39886
2928.66	11.6768
2929.72	9.3479
2930.78	2.35849
2931.84	-10.8226
2932.91	5.97638
2933.97	1.34952
2935.03	-6.48999
2936.09	-2.88257
2937.15	-2.79364
2938.21	4.71933
2939.27	9.12369
2940.33	2.56549
2941.39	3.15872
2942.45	6.12537
2943.51	13.847
2944.57	4.51715
2945.63	16.2754
2946.68	9.15179
2947.74	9.29239
2948.8	-9.68292
2949.86	6.16568
2950.92	-0.388153
2951.97	5.38208
2953.03	-4.21936
2954.09	-3.64215
2955.14	-1.11792
2956.2	0.731171
2957.25	-0.114136
2958.31	-5.75943
2959.37	-1.05334
2960.42	-3.09308
2961.48	-4.19022
2962.53	-2.7334
2963.59	4.04984
2964.64	-9.86636
2965.7	-10.0616
2966.75	-1.90054
2967.8	-4.05103
2968.86	-4.93744
2969.91	6.39987
2970.96	-2.02985
2972.02	-5.79321
2973.07	3.62524
2974.12	-14.3744
2975.17	9.95685
2976.22	-10.7752
2977.28	4.38174
2978.33	-2.94083
2979.38	7.40613
2980.43	7.37039
2981.48	8.17291
2982.53	14.5342
2983.58	1.13785
2984.63	7.54169
2985.68	-4.70862
2986.73	3.92697
2987.78	7.75546
2988.83	-3.42609
2989.88	-11.9309
2990.93	5.02393
2991.98	-14.6278
2993.02	-0.592743
2994.07	6.85132
2995.12	12.7615
2996.17	9.36279
2997.21	0.00827026
2998.26	-11.1577
2999.31	-6.4115
2999.94	10.4969