File: Data/3-Raman/processed/bu32-b-ff2-fi04-v_1800 (450-850nm)_532nm_edge_100%_x100_vis_lwd_h30um_30sx2_01.txt
#Acq. time (s)=	30
#Accumulations=	2
#Range (cm-¹)=	1200...2999
#Windows=	5
#Auto scanning=	Off
#Autofocus=	Off
#Macrospot=	Off
#AutoExposure=	Off
#Spike filter=	Multiple accum.
#Delay time (s)=	2
#Binning=	1
#Readout mode=	Signal
#DeNoise=	Off
#ICS correction=	On
#Dark correction=	Off
#Inst. Process=	Off
#Detector Gain=	Best Dynamic
#Detector ADC=	50 kHz EM
#Detector EM gain=	150
#Detector temperature (°C)=	-60.09
#Instrument=	LabRAM HR Evol
#Detector=	SIN-EM FIVIS
#Objective=	x100_VIS_LWD
#Grating=	1800 (450-850nm)
#ND Filter=	100%
#Laser=	532nm_Edge
#Hole=	30.0125
#Temperature=	40
#Range=	Visible
#StageXY=	75x50mm Scan+
#StageZ=	Z motor
#X (µm)=	0
#Y (µm)=	0
#Z (µm)=	71.2
#Full time(mm:ss)=	5:34
#Project=	21_08_11
#Sample=	BU32
#Site=
#Title=	BU32-B-FF2-FI04-V_1800 (450-850nm)_532nm_Edge_100%_x100_VIS_LWD_H30um_30sX2
#Remark=
#Date=	13.08.2021 15:57
#Acquired=	13.08.2021 15:57:04
#Base:Fit=	16.12.2021 15:06:56
#Base:Sub=	16.12.2021 15:06:58
1200.05	8.25912
1201.44	3.30533
1202.83	8.27853
1204.22	2.55954
1205.61	-0.0578918
1207	1.56158
1208.39	4.53888
1209.78	3.38895
1211.16	0.812469
1212.55	6.81842
1213.94	5.74887
1215.33	1.59674
1216.71	-5.19876
1218.1	7.28796
1219.49	3.00146
1220.87	7.27759
1222.26	-4.80939
1223.64	-1.0957
1225.03	4.16559
1226.41	0.0782166
1227.79	3.52881
1229.18	-2.83798
1230.56	-5.58179
1231.94	1.24463
1233.33	-1.80972
1234.71	-1.47263
1236.09	-1.26764
1237.47	6.82257
1238.86	0.23877
1240.24	-8.06281
1241.62	2.47195
1243	4.82617
1244.38	8.08511
1245.76	1.52026
1247.14	-0.49472
1248.52	2.57166
1249.9	7.8819
1251.27	2.4603
1252.65	1.24963
1254.03	-4.73102
1255.41	4.85315
1256.79	0.909393
1258.16	12.3758
1259.54	1.16858
1260.92	11.3268
1262.29	4.63089
1263.67	33.2564
1265.04	30.1523
1266.42	3.17191
1267.79	7.99765
1269.17	8.41907
1270.54	5.03824
1271.92	9.47812
1273.29	14.2862
1274.66	6.18967
1276.04	9.75696
1277.41	9.19409
1278.78	1.25433
1280.15	9.73288
1281.53	16.4407
1282.9	61.3576
1284.27	473.322
1285.64	71.7597
1287.01	19.1129
1288.38	14.9621
1289.75	16.4511
1291.12	3.88763
1292.49	11.3633
1293.86	14.0492
1295.23	14.5201
1296.6	0.269226
1297.96	9.6572
1299.33	11.729
1300.7	5.60385
1302.07	2.72519
1303.43	15.4026
1304.8	15.4464
1306.17	12.0839
1307.53	9.07913
1308.9	7.21124
1310.26	4.23001
1311.63	4.48395
1312.99	10.9492
1314.36	11.0735
1315.72	5.02499
1317.08	12.543
1318.45	21.2054
1319.81	10.7619
1321.17	20.0649
1322.53	14.624
1323.9	11.5623
1325.26	14.6589
1326.62	11.1441
1327.98	7.76706
1329.34	9.07687
1330.7	9.96631
1332.06	17.9415
1333.42	7.02234
1334.78	14.1068
1336.14	16.0577
1337.5	9.68765
1338.86	10.6242
1340.22	12.9001
1341.58	12.8975
1342.93	11.6572
1344.29	7.56
1345.65	14.5875
1347	13.1032
1348.36	19.2663
1349.72	6.58762
1351.07	6.35834
1352.43	6.63193
1353.78	10.8119
1355.14	8.35541
1356.49	11.6045
1357.85	13.5637
1359.2	-1.11169
1360.56	1.7677
1361.91	7.99347
1363.26	-3.21854
1364.61	9.26294
1365.97	4.87589
1367.32	1.63342
1368.67	15.3004
1370.02	25.5897
1371.37	7.72076
1372.72	4.31815
1374.07	9.43875
1375.42	18.8002
1376.77	12.3528
1378.12	6.85483
1379.47	8.94345
1380.82	11.5287
1382.17	20.2463
1383.52	27.0924
1384.87	21.3625
1386.21	79.308
1387.56	919.483
1388.91	95.7966
1390.26	32.8459
1391.6	31.5468
1392.95	21.1606
1394.3	23.1999
1395.64	15.2591
1396.99	20.2621
1398.33	20.4094
1399.68	8.37857
1401.02	21.9833
1402.37	10.4095
1403.71	20.7269
1405.05	15.561
1406.39	14.4796
1407.74	21.8744
1409.08	70.3209
1410.42	25.0732
1411.76	18.8669
1413.11	10.477
1414.45	13.5639
1415.79	9.64224
1417.13	13.0088
1418.47	16.2595
1419.81	10.0078
1421.15	14.0042
1422.49	22.0115
1423.83	16.7381
1425.17	19.1151
1426.51	12.9911
1427.84	12.686
1429.18	12.9202
1430.52	5.26443
1431.86	11.5956
1433.19	13.2379
1434.53	26.7621
1435.87	3.24582
1437.2	4.25171
1438.54	14.6795
1439.87	3.77087
1441.21	21.2882
1442.54	6.07986
1443.88	8.09961
1445.21	6.37482
1446.55	10.4563
1447.88	8.44089
1449.21	8.58377
1450.55	10.5536
1451.88	12.573
1453.21	6.61899
1454.54	9.74741
1455.88	9.91629
1457.21	14.9657
1458.54	8.94339
1459.87	15.1584
1461.2	17.1212
1462.53	9.74442
1463.86	13.9904
1465.19	12.3058
1466.52	13.2333
1467.85	9.23141
1469.18	9.18665
1470.51	3.94107
1471.83	13.0215
1473.16	7.89737
1474.49	5.93369
1475.82	14.0675
1477.14	5.85452
1478.47	9.82535
1479.79	9.57458
1481.12	14.507
1482.45	11.7799
1483.77	3.69653
1485.1	8.55902
1486.42	7.33029
1487.75	7.24771
1489.07	8.08252
1490.39	4.00583
1491.72	6.01379
1493.04	9.07852
1494.36	14.2513
1495.69	6.86868
1497.01	14.8971
1498.33	9.92569
1499.65	8.09372
1500.97	7.05991
1502.29	12.0655
1503.62	8.98087
1504.93	5.98001
1506.26	4.82034
1507.58	5.97672
1508.89	14.1191
1510.21	6.08893
1511.53	2.57312
1512.85	3.15961
1514.17	7.41818
1515.49	6.09183
1516.81	9.01718
1518.12	6.20792
1519.44	5.36993
1520.76	7.47729
1522.07	8.47574
1523.39	3.17886
1524.71	8.13196
1526.02	-0.559357
1527.34	8.48795
1528.65	8.4277
1529.97	4.431
1531.28	4.67737
1532.59	9.93732
1533.91	14.2008
1535.22	14.0047
1536.54	7.57565
1537.85	7.38443
1539.16	2.82257
1540.47	6.49286
1541.79	13.206
1543.1	10.8955
1544.41	7.01471
1545.72	7.43607
1547.03	1.60263
1548.34	12.6293
1549.65	7.35226
1550.96	11.4773
1552.27	1.57306
1553.58	20.2812
1554.89	9.95032
1556.2	10.9974
1557.5	11.0712
1558.81	2.6799
1560.12	6.52377
1561.43	10.7026
1562.74	-0.129089
1564.04	5.15128
1565.35	8.30759
1566.65	7.89587
1567.96	9.08908
1569.27	6.98334
1570.57	7.07727
1571.88	10.973
1573.18	7.79974
1574.48	3.13312
1575.79	3.3374
1577.09	2.97122
1578.4	8.73862
1579.7	11.8784
1581	4.85287
1582.3	11.6946
1583.61	3.71844
1584.91	12.7947
1586.21	7.65344
1587.51	9.58261
1588.81	9.82507
1590.11	4.01337
1591.41	9.04514
1592.72	8.73245
1594.01	-3.52045
1595.31	4.50406
1596.61	8.55463
1597.91	9.59909
1599.21	6.36349
1600.51	9.00891
1601.81	1.78918
1603.1	4.2648
1604.4	-0.449524
1605.7	9.02756
1607	4.43307
1608.29	4.76187
1609.59	4.3385
1610.88	8.75269
1612.18	5.10712
1613.48	5.28616
1614.77	4.51746
1616.07	1.55884
1617.36	2.64905
1618.65	9.52347
1619.95	3.01865
1621.24	7.64856
1622.54	4.31839
1623.83	0.65033
1625.12	6.22141
1626.41	1.82956
1627.56	7.60217
1628.87	5.68063
1630.17	5.6413
1631.48	7.79388
1632.79	14.8167
1634.1	7.98456
1635.4	12.9039
1636.71	2.90363
1638.01	-1.10648
1639.32	11.7434
1640.62	-0.885406
1641.93	8.92612
1643.23	6.96301
1644.54	2.94012
1645.84	13.8724
1647.15	6.89932
1648.45	-1.7457
1649.75	5.32965
1651.05	5.69662
1652.36	3.75552
1653.66	8.76971
1654.96	5.07288
1656.26	5.44562
1657.56	4.42621
1658.86	12.1768
1660.16	3.31577
1661.46	0.671295
1662.77	4.09955
1664.07	8.7774
1665.36	0.0829163
1666.66	5.67105
1667.96	8.70953
1669.26	9.14944
1670.56	8.44257
1671.86	3.54901
1673.15	13.5234
1674.45	3.88153
1675.75	6.02524
1677.05	7.07123
1678.34	9.83264
1679.64	7.7529
1680.94	0.774139
1682.23	3.7912
1683.53	6.77191
1684.82	6.71509
1686.12	11.769
1687.41	6.87695
1688.71	15.6001
1690	6.5892
1691.29	7.78885
1692.59	5.72571
1693.88	8.37146
1695.17	16.2661
1696.47	6.5542
1697.76	6.28394
1699.05	7.17752
1700.34	10.123
1701.63	2.1188
1702.92	4.94043
1704.21	5.00583
1705.5	5.00525
1706.79	4.71475
1708.08	5.29007
1709.37	2.10828
1710.66	8.12909
1711.95	7.20407
1713.24	0.781921
1714.53	8.45416
1715.82	3.69431
1717.11	3.27072
1718.39	0.853027
1719.68	0.900482
1720.97	5.55591
1722.25	5.23593
1723.54	1.19995
1724.83	4.79886
1726.11	6.52133
1727.4	11.3031
1728.68	6.32428
1729.97	3.6149
1731.25	3.94815
1732.54	4.80499
1733.82	1.45178
1735.1	0.0841064
1736.39	-1.02493
1737.67	-2.1629
1738.95	-1.51117
1740.24	-4.90497
1741.52	0.59491
1742.8	-1.38391
1744.08	-4.41547
1745.36	-5.35153
1746.65	1.99417
1747.93	-1.05881
1749.21	-2.78436
1750.49	3.26151
1751.77	1.17996
1753.05	3.7757
1754.33	-2.17377
1755.6	-3.31873
1756.88	1.07516
1758.16	-4.5108
1759.44	-1.60031
1760.72	-5.53329
1762	1.98285
1763.27	1.14722
1764.55	-0.432343
1765.83	-2.21521
1767.1	-1.31363
1768.38	-3.36047
1769.66	-1.89542
1770.93	-1.56247
1772.21	1.57065
1773.48	-3.93387
1774.76	5.75714
1776.03	5.14291
1777.31	4.02512
1778.58	6.60623
1779.85	-6.66321
1781.13	-3.66925
1782.4	-2.44482
1783.67	-1.25735
1784.94	-2.95184
1786.22	-1.97952
1787.49	0.505646
1788.76	-2.68796
1790.03	0.4841
1791.3	4.05432
1792.57	3.20563
1793.84	0.458801
1795.11	12.4594
1796.38	11.8284
1797.65	6.3331
1798.92	-0.384338
1800.19	7.11023
1801.46	8.08453
1802.73	2.57547
1804	2.80844
1805.26	12.8087
1806.53	7.28268
1807.8	4.4494
1809.07	5.50357
1810.33	5.55557
1811.6	8.46942
1812.87	-3.84543
1814.13	1.34079
1815.4	6.41312
1816.66	15.2016
1817.93	-0.413116
1819.19	9.44635
1820.46	11.5833
1821.72	7.94989
1822.99	3.19986
1824.25	5.17734
1825.51	13.067
1826.77	7.34085
1828.04	10.3507
1829.3	7.35461
1830.56	9.22177
1831.82	9.45612
1833.09	3.82553
1834.35	4.59512
1835.61	9.06104
1836.87	17.3607
1838.13	1.14288
1839.39	9.7431
1840.65	3.16183
1841.91	9.36688
1843.17	7.45789
1844.43	2.66119
1845.69	8.75864
1846.94	4.09055
1848.2	7.06006
1849.46	0.0503845
1850.72	-1.29025
1851.97	13.9822
1853.23	4.33478
1854.49	11.6763
1855.74	12.3487
1857	7.52881
1858.26	6.34409
1859.51	7.08136
1860.77	9.20822
1862.02	10.2191
1863.28	0.349457
1864.53	2.96896
1865.78	1.5303
1867.04	-6.64328
1868.29	4.65219
1869.54	9.38547
1870.8	0.80838
1872.05	10.1572
1873.3	14.7379
1874.56	7.79114
1875.81	12.0009
1877.06	-1.79803
1878.31	-4.11481
1879.56	2.73535
1880.81	5.5322
1882.06	1.95041
1883.31	5.72125
1884.56	7.32336
1885.81	7.76712
1887.06	5.62479
1888.31	8.96237
1889.56	3.11261
1890.81	4.2359
1892.05	0.416809
1893.3	-1.96555
1894.55	10.1386
1895.8	-0.026001
1897.04	2.09286
1898.29	6.70599
1899.54	1.76852
1900.78	6.56793
1902.03	-1.57117
1903.27	3.97226
1904.52	0.169891
1905.76	-7.54077
1907.01	6.47202
1908.25	1.01205
1909.5	17.3441
1910.74	-0.121826
1911.98	4.59802
1913.23	3.75168
1914.47	3.202
1915.71	2.34338
1916.96	11.5808
1918.2	0.387421
1919.44	8.45374
1920.68	8.61029
1921.92	3.12759
1923.16	-2.68546
1924.41	-0.931702
1925.65	-1.55386
1926.89	5.43613
1928.12	1.83121
1929.36	4.99387
1930.6	9.13074
1931.84	5.20987
1933.08	-0.553375
1934.32	9.94696
1935.56	12.2352
1936.8	5.38306
1938.03	0.44281
1939.27	8.34628
1940.51	7.84265
1941.75	5.71988
1942.98	7.9805
1944.22	12.907
1945.45	1.81375
1946.69	10.5656
1947.92	5.73837
1949.16	8.81946
1950.4	6.49615
1951.63	3.15665
1952.86	7.19894
1954.1	6.50189
1955.33	10.3487
1956.56	7.08759
1957.8	10.2408
1959.03	4.41422
1960.26	7.10861
1961.5	9.85266
1962.73	5.13828
1963.96	3.33859
1965.19	6.2204
1966.42	20.9244
1967.65	12.3561
1968.88	23.7382
1970.11	5.14853
1971.34	14.582
1972.57	6.00302
1973.8	7.70926
1975.03	8.76477
1976.26	7.96274
1977.49	2.10855
1978.72	5.83542
1979.95	2.00958
1981.17	8.53717
1982.4	4.05536
1983.63	4.04678
1984.85	8.75116
1986.08	11.1947
1987.31	8.96304
1988.53	2.78979
1989.76	2.30682
1990.98	2.73972
1992.21	5.33542
1993.43	6.46979
1994.66	4.25839
1995.88	3.09097
1997.11	2.22354
1998.33	4.17413
1999.55	4.91147
2000.78	3.54211
2002	2.69321
2003.22	5.70374
2004.45	1.16486
2005.59	-1.78824
2006.83	-0.807312
2008.06	3.55756
2009.3	5.05283
2010.54	5.76404
2011.77	-0.869446
2013.01	2.54517
2014.25	-9.31351
2015.48	4.89688
2016.72	6.1235
2017.95	-1.83023
2019.19	3.33438
2020.42	1.38107
2021.66	3.25754
2022.89	-3.59799
2024.12	-2.06503
2025.36	1.23175
2026.59	-3.85699
2027.82	-0.388733
2029.06	4.14923
2030.29	-3.64761
2031.52	5.08237
2032.75	2.7511
2033.98	7.19397
2035.21	-0.140472
2036.45	-1.81607
2037.68	-0.909485
2038.91	-6.73459
2040.14	1.32474
2041.37	1.12094
2042.6	-3.68399
2043.83	-1.42209
2045.05	-3.30273
2046.28	0.748322
2047.51	-1.64648
2048.74	-0.54187
2049.97	7.3566
2051.2	4.44617
2052.42	3.63184
2053.65	2.14883
2054.88	-2.53003
2056.1	2.9238
2057.33	-3.54645
2058.56	0.493713
2059.78	-3.2056
2061.01	2.46207
2062.23	-0.251648
2063.46	-0.0284119
2064.68	3.00003
2065.91	3.34244
2067.13	3.49741
2068.35	3.69373
2069.58	-0.364807
2070.8	5.70401
2072.02	6.05219
2073.25	2.263
2074.47	-3.17572
2075.69	-1.69687
2076.91	4.75754
2078.13	0.0309143
2079.35	2.26566
2080.58	8.04413
2081.8	2.37003
2083.02	4.29138
2084.24	4.29822
2085.46	-0.378174
2086.68	4.65814
2087.9	4.75513
2089.12	0.173706
2090.33	1.2955
2091.55	11.0523
2092.77	11.5149
2093.99	3.24588
2095.21	5.00958
2096.43	6.79666
2097.64	4.71011
2098.86	3.68643
2100.08	-0.0888672
2101.29	10.5763
2102.51	5.75497
2103.73	9.45578
2104.94	3.03067
2106.16	6.08209
2107.37	13.6442
2108.59	6.67886
2109.8	5.89001
2111.01	4.91873
2112.23	5.8222
2113.44	8.90546
2114.66	5.07806
2115.87	5.87671
2117.08	4.8429
2118.29	5.49512
2119.51	3.30225
2120.72	4.29239
2121.93	6.51462
2123.14	5.71866
2124.35	6.35907
2125.57	-0.80719
2126.78	6.44696
2127.99	0.672638
2129.2	3.45834
2130.41	9.03287
2131.62	7.89459
2132.82	3.00296
2134.03	3.05359
2135.24	4.87225
2136.45	4.6228
2137.66	3.76355
2138.87	6.6799
2140.08	2.51202
2141.28	5.20212
2142.49	10.8773
2143.7	-1.90979
2144.9	8.55292
2146.11	10.3503
2147.32	5.4805
2148.52	5.29657
2149.73	5.83392
2150.93	5.82129
2152.14	8.72568
2153.34	-2.71909
2154.55	0.565155
2155.75	2.93832
2156.96	6.65338
2158.16	8.67484
2159.36	0.0785828
2160.57	15.6506
2161.77	3.43793
2162.97	11.7287
2164.17	3.09695
2165.38	-2.48767
2166.58	-0.790833
2167.78	-3.11969
2168.98	-2.11487
2170.18	2.92062
2171.38	3.41257
2172.58	-7.06042
2173.78	-0.479248
2174.98	-4.2077
2176.18	6.82816
2177.38	2.17429
2178.58	4.79791
2179.78	6.6713
2180.98	4.74002
2182.18	-3.76025
2183.38	-2.1983
2184.57	4.22855
2185.77	1.63129
2186.97	2.02533
2188.16	3.81784
2189.36	5.28159
2190.56	2.50681
2191.76	-0.179901
2192.95	-2.76654
2194.15	4.21051
2195.34	2.15985
2196.54	3.61176
2197.73	1.70935
2198.93	10.4878
2200.12	4.61652
2201.31	13.7641
2202.51	-4.02106
2203.7	-4.27866
2204.89	5.30588
2206.09	5.18362
2207.28	4.32898
2208.47	2.74835
2209.67	4.66501
2210.86	-0.706268
2212.05	4.1962
2213.24	-0.639587
2214.43	-1.23608
2215.62	9.10095
2216.81	2.52969
2218	4.43182
2219.19	10.2498
2220.38	10.2878
2221.57	8.11768
2222.76	-3.95657
2223.95	7.63544
2225.14	3.3183
2226.33	3.61752
2227.51	1.89499
2228.7	4.61517
2229.89	12.3738
2231.08	11.7642
2232.27	4.53619
2233.45	7.62097
2234.64	2.82333
2235.82	-0.139038
2237.01	1.9176
2238.2	9.96231
2239.38	20.4944
2240.57	12.0576
2241.75	1.78629
2242.94	5.58911
2244.12	10.2889
2245.3	15.4655
2246.49	9.10022
2247.67	4.44077
2248.85	7.20053
2250.04	6.24762
2251.22	13.5683
2252.4	5.30197
2253.59	11.4744
2254.77	16.3078
2255.95	7.90771
2257.13	7.20477
2258.31	9.21753
2259.49	7.4942
2260.67	4.86938
2261.85	9.77563
2263.03	12.9774
2264.21	4.92099
2265.39	7.04141
2266.57	16.2929
2267.75	7.44925
2268.93	7.62085
2270.11	9.00693
2271.29	4.46265
2272.47	15.112
2273.64	4.66925
2274.82	13.3697
2276	7.82336
2277.17	13.98
2278.35	10.4666
2279.53	14.0027
2280.71	5.08936
2281.88	14.704
2283.06	10.3094
2284.23	13.7226
2285.41	11.9152
2286.58	14.8795
2287.76	5.51556
2288.93	12.8756
2290.1	7.76343
2291.28	10.9431
2292.45	7.39059
2293.62	16.1951
2294.8	17.8951
2295.97	16.6122
2297.14	10.0442
2298.31	10.3992
2299.49	12.5533
2300.66	13.6369
2301.83	11.7367
2303	10.727
2304.17	14.7548
2305.34	17.8301
2306.51	19.8584
2307.68	12.0023
2308.85	15.9443
2310.02	17.1924
2311.19	8.98737
2312.36	10.593
2313.53	7.04694
2314.7	11.3591
2315.87	11.8812
2317.03	18.5205
2318.2	8.80896
2319.37	12.468
2320.54	13.5068
2321.7	11.9211
2322.87	18.8246
2324.03	16.9131
2325.2	17.4688
2326.37	11.3542
2327.53	31.3236
2328.7	59.1638
2329.86	17.6198
2331.03	9.90237
2332.19	9.84366
2333.36	16.3943
2334.52	10.368
2335.68	7.4722
2336.85	10.2613
2338.01	14.0135
2339.17	5.35611
2340.34	12.8147
2341.5	13.3272
2342.66	15.9074
2343.82	10.1612
2344.98	13.6337
2346.14	11.7904
2347.31	4.20087
2348.47	8.00604
2349.63	10.4478
2350.79	4.67032
2351.95	7.27563
2353.11	7.77621
2354.27	9.84711
2355.43	8.33231
2356.59	5.74594
2357.74	9.35275
2358.9	7.21167
2360.06	5.49167
2361.22	5.77768
2362.38	4.74902
2363.53	3.64828
2364.69	1.15283
2365.74	6.35458
2366.92	4.84363
2368.09	5.61578
2369.26	4.38925
2370.43	7.81348
2371.6	7.58945
2372.77	9.23514
2373.94	4.31207
2375.11	1.20953
2376.28	-0.839203
2377.45	3.6615
2378.62	6.17734
2379.79	1.11154
2380.96	9.4415
2382.13	-2.75919
2383.29	-0.0473633
2384.46	0.835602
2385.63	-1.30447
2386.8	9.47949
2387.97	0.887329
2389.13	-0.146637
2390.3	0.751984
2391.47	10.1136
2392.63	2.4119
2393.8	5.66058
2394.96	3.69772
2396.13	-5.6145
2397.29	8.16891
2398.46	-3.05362
2399.62	2.54276
2400.79	-2.21381
2401.95	-0.493805
2403.12	9.07294
2404.28	1.21036
2405.44	-4.15338
2406.61	1.51041
2407.77	-6.91907
2408.93	3.26624
2410.09	1.39914
2411.26	-4.19385
2412.42	5.28748
2413.58	2.534
2414.74	-2.25748
2415.9	-3.40869
2417.06	2.2973
2418.22	2.51044
2419.38	1.03033
2420.54	4.86124
2421.7	2.71817
2422.86	-1.67346
2424.02	-5.22504
2425.18	5.36551
2426.34	4.69998
2427.5	4.84552
2428.66	-2.75476
2429.81	-6.55569
2430.97	-0.886902
2432.13	14.5496
2433.29	2.63174
2434.44	1.73962
2435.6	0.13147
2436.76	1.29575
2437.91	10.6706
2439.07	6.21628
2440.23	1.85052
2441.38	10.4097
2442.53	5.8999
2443.69	9.90851
2444.84	8.21738
2446	-0.111816
2447.15	8.74197
2448.31	1.17313
2449.46	5.95953
2450.61	4.41507
2451.77	2.8078
2452.92	4.68842
2454.07	20.8415
2455.22	5.01398
2456.38	6.28015
2457.53	10.23
2458.68	1.66296
2459.83	0.89798
2460.98	12.4794
2462.14	8.63745
2463.29	6.83035
2464.43	6.56287
2465.59	2.74393
2466.74	4.55457
2467.88	11.1634
2469.03	18.6899
2470.18	1.6192
2471.33	9.42474
2472.48	11.647
2473.63	5.88211
2474.78	4.1926
2475.92	14.3379
2477.07	9.6683
2478.22	6.53986
2479.37	4.27887
2480.51	8.73813
2481.66	8.44882
2482.81	9.36667
2483.95	4.47855
2485.1	11.1509
2486.24	7.37445
2487.39	0.438507
2488.53	9.82312
2489.68	8.75635
2490.82	13.5525
2491.97	3.77042
2493.11	4.05179
2494.25	7.59277
2495.4	13.1254
2496.54	8.48557
2497.69	3.30392
2498.83	5.44989
2499.97	5.38696
2501.11	7.69788
2502.25	18.8063
2503.4	-0.285583
2504.54	3.26221
2505.68	7.00269
2506.82	5.30743
2507.96	5.34375
2509.1	8.15982
2510.24	7.76755
2511.38	3.30258
2512.52	3.13666
2513.66	0.462616
2514.8	5.99121
2515.94	13.0078
2517.08	6.81949
2518.21	0.843262
2519.35	9.22858
2520.49	2.90634
2521.63	-1.74515
2522.77	-0.195221
2523.9	7.25601
2525.04	8.95029
2526.18	15.8669
2527.31	0.627686
2528.45	-0.235199
2529.58	6.46146
2530.72	-3.02686
2531.86	0.489899
2532.99	-5.39618
2534.13	7.83945
2535.26	3.89069
2536.4	-0.847656
2537.53	-1.06573
2538.66	7.9624
2539.8	6.73862
2540.93	2.00491
2542.06	9.72147
2543.2	4.1821
2544.33	4.88248
2545.46	4.8786
2546.59	5.65622
2547.73	8.47488
2548.86	4.86435
2549.99	-1.44678
2551.12	7.21405
2552.25	5.51157
2553.38	6.30447
2554.51	2.52701
2555.64	4.63055
2556.77	4.12717
2557.9	4.22763
2559.03	11.7521
2560.16	11.6385
2561.29	7.89569
2562.42	8.05203
2563.55	8.52286
2564.67	8.07428
2565.8	7.14368
2566.93	3.39545
2568.06	9.01129
2569.18	-0.368805
2570.31	1.75247
2571.44	7.00507
2572.56	-1.04282
2573.69	8.6828
2574.81	6.58115
2575.94	8.75977
2577.06	5.17865
2578.19	8.46802
2579.31	3.15796
2580.44	7.20187
2581.56	18.7612
2582.69	4.53885
2583.81	10.3311
2584.94	2.85757
2586.06	14.7959
2587.18	4.68698
2588.3	9.1445
2589.43	7.31857
2590.55	7.2962
2591.67	9.23965
2592.79	7.56793
2593.91	13.6841
2595.04	8.14597
2596.16	12.1098
2597.28	17.4833
2598.4	5.72552
2599.52	15.7501
2600.64	10.9959
2601.76	10.5609
2602.88	11.4837
2604	10.537
2605.12	9.65698
2606.24	10.6548
2607.35	4.98547
2608.47	13.1909
2609.59	17.2417
2610.71	17.3402
2611.83	6.55402
2612.94	19.0222
2614.06	15.3054
2615.18	10.007
2616.29	12.1304
2617.41	18.0923
2618.53	6.48178
2619.64	11.8694
2620.76	6.60126
2621.87	30.4773
2622.99	15.0094
2624.1	12.165
2625.22	15.1046
2626.33	21.1075
2627.45	26.0994
2628.56	1.67242
2629.67	15.1827
2630.79	19.1747
2631.9	11.4825
2633.01	3.62469
2634.12	15.1271
2635.24	19.4512
2636.35	11.2154
2637.46	18.5815
2638.57	7.83536
2639.68	19.6563
2640.8	17.0613
2641.91	8.60461
2643.02	8.91537
2644.13	9.56036
2645.24	16.0732
2646.35	10.0825
2647.46	13.7858
2648.57	14.1944
2649.67	16.882
2650.78	3.28732
2651.89	11.6791
2653	16.3789
2654.11	12.3335
2655.22	7.16803
2656.32	1.37018
2657.43	14.9695
2658.54	3.19528
2659.65	8.41757
2660.75	0.680725
2661.86	15.6574
2662.96	6.26105
2664.07	7.92377
2665.18	6.84201
2666.28	12.4607
2667.39	12.2556
2668.49	0.389801
2669.6	1.23688
2670.7	18.4507
2671.8	4.84659
2672.91	-0.347961
2674.01	2.23792
2675.11	6.25781
2676.22	2.84308
2677.32	3.52615
2678.42	21.31
2679.53	-4.49319
2680.63	8.64636
2681.73	6.82709
2682.83	3.51431
2683.93	6.46671
2685.03	2.97647
2686.14	8.66595
2687.24	5.06393
2688.34	4.04291
2689.44	8.08197
2690.54	-3.81027
2691.64	-0.170898
2692.74	6.33624
2693.84	-2.63409
2694.93	3.90781
2696.03	2.93338
2697.13	0.290497
2698.23	-0.622589
2699.33	-0.425751
2700.43	-0.389984
2701.52	1.71204
2702.62	-0.716858
2703.72	3.31891
2704.81	-0.251862
2705.9	6.70483
2707.01	-2.71091
2708.12	0.807617
2709.23	-5.67361
2710.34	2.86111
2711.45	1.76373
2712.56	-0.563049
2713.67	4.21771
2714.78	1.88177
2715.89	-4.70154
2716.99	0.687317
2718.1	5.38397
2719.21	12.2251
2720.32	1.36435
2721.43	3.34543
2722.54	10.636
2723.64	0.232635
2724.75	-1.35767
2725.86	7.93787
2726.96	16.3592
2728.07	1.42358
2729.18	6.20288
2730.28	0.789734
2731.39	9.60751
2732.49	6.70551
2733.6	-0.160431
2734.71	2.69183
2735.81	8.77374
2736.91	7.01709
2738.02	-5.29941
2739.12	-0.439789
2740.23	6.04147
2741.33	6.83588
2742.43	6.26959
2743.54	18.0019
2744.64	10.8185
2745.74	2.2244
2746.84	-2.75995
2747.95	2.95239
2749.05	4.90866
2750.15	7.73697
2751.25	9.88699
2752.35	5.54584
2753.45	1.84863
2754.55	14.0504
2755.66	3.45544
2756.76	6.51273
2757.86	5.69476
2758.96	3.74527
2760.05	10.3519
2761.15	5.94495
2762.25	-0.221008
2763.35	0.949249
2764.45	5.00955
2765.55	8.72964
2766.65	7.55936
2767.75	-4.09818
2768.84	0.623169
2769.94	16.9454
2771.04	-1.04535
2772.13	2.40927
2773.23	5.30426
2774.33	3.91519
2775.42	6.66263
2776.52	3.57672
2777.61	1.62308
2778.71	9.26404
2779.81	6.10294
2780.9	6.9855
2782	-0.562256
2783.09	1.10095
2784.18	0.841583
2785.28	1.01614
2786.37	4.99344
2787.47	3.78586
2788.56	0.508423
2789.65	5.06418
2790.74	2.0918
2791.84	2.78418
2792.93	1.97363
2794.02	5.62741
2795.11	-4.74695
2796.2	0.70993
2797.3	4.35233
2798.39	7.00677
2799.48	9.99036
2800.57	-0.527618
2801.66	5.99002
2802.75	3.27847
2803.84	8.61737
2804.93	-2.06906
2806.02	6.48541
2807.11	9.25455
2808.2	7.28275
2809.28	-3.19394
2810.37	2.34439
2811.46	2.94641
2812.55	7.38086
2813.64	4.68692
2814.73	2.64215
2815.81	3.37079
2816.9	7.93817
2817.99	9.42294
2819.07	5.43637
2820.16	8.65616
2821.25	4.38437
2822.33	-5.13986
2823.42	-4.39581
2824.5	5.06415
2825.59	-3.50928
2826.67	5.11707
2827.76	-2.22095
2828.84	-1.66211
2829.93	9.51825
2831.01	-3.51489
2832.09	5.62082
2833.18	3.54147
2834.26	5.44089
2835.34	3.76773
2836.43	1.10132
2837.51	2.9371
2838.59	-1.84113
2839.67	-0.749481
2840.75	-1.18286
2841.84	1.51273
2842.92	4.12106
2844	12.3687
2845.08	0.987823
2846.16	6.91675
2847.24	-3.19409
2848.32	3.95309
2849.4	10.6098
2850.48	0.482574
2851.56	2.45947
2852.64	3.29208
2853.72	1.483
2854.8	3.42767
2855.87	3.42416
2856.95	4.32709
2858.03	0.640228
2859.11	3.42459
2860.19	3.42188
2861.26	8.59171
2862.34	0.456909
2863.42	5.88089
2864.49	6.6264
2865.57	11.4698
2866.65	-2.45767
2867.72	4.19217
2868.8	3.63766
2869.87	-5.91022
2870.95	2.57999
2872.02	5.24704
2873.1	-3.20169
2874.17	10.3994
2875.25	9.77878
2876.32	14.4274
2877.4	11.6049
2878.47	3.23615
2879.54	3.05728
2880.62	4.93103
2881.69	8.06149
2882.76	-0.356201
2883.83	14.4409
2884.9	1.44196
2885.98	10.1769
2887.05	9.31628
2888.12	8.69168
2889.19	5.02209
2890.26	-1.69598
2891.33	-2.70755
2892.4	-2.61182
2893.47	8.07779
2894.54	10.5488
2895.61	8.22482
2896.68	-2.37845
2897.75	1.45792
2898.82	8.16147
2899.89	1.71887
2900.96	3.66263
2902.03	11.1873
2903.09	15.9984
2904.16	10.52
2905.23	4.90619
2906.3	11.2841
2907.36	1.61771
2908.43	2.72995
2909.5	12.1509
2910.57	5.56656
2911.63	4.68906
2912.7	3.82272
2913.76	6.57147
2914.83	12.0986
2915.89	7.32849
2916.96	11.1595
2918.02	7.34406
2919.09	4.40558
2920.15	14.6476
2921.22	9.6619
2922.28	6.60367
2923.34	11.3075
2924.41	10.3356
2925.47	15.9934
2926.53	1.65927
2927.6	4.42419
2928.66	3.32712
2929.72	17.1217
2930.78	9.20456
2931.84	7.43018
2932.91	23.2914
2933.97	-3.18024
2935.03	8.94409
2936.09	1.17667
2937.15	11.7089
2938.21	5.94458
2939.27	4.68845
2940.33	3.82059
2941.39	7.23257
2942.45	3.61694
2943.51	8.48941
2944.57	-0.766907
2945.63	4.33273
2946.68	3.8876
2947.74	5.91513
2948.8	-5.47946
2949.86	10.3888
2950.92	8.56772
2951.97	-2.6937
2953.03	8.53583
2954.09	7.24097
2955.14	2.23004
2956.2	1.25531
2957.25	1.35355
2958.31	7.99203
2959.37	13.6498
2960.42	-0.654266
2961.48	4.87073
2962.53	-3.07419
2963.59	0.871918
2964.64	-9.28226
2965.7	5.63696
2966.75	-1.26926
2967.8	-6.22156
2968.86	0.429169
2969.91	-7.07367
2970.96	3.34357
2972.02	3.35535
2973.07	0.526703
2974.12	3.27078
2975.17	7.83054
2976.22	3.11722
2977.28	2.25925
2978.33	-5.07535
2979.38	-4.0535
2980.43	-7.95096
2981.48	0.412079
2982.53	-7.33051
2983.58	-1.86655
2984.63	-6.73508
2985.68	-1.10175
2986.73	5.64581
2987.78	0.999237
2988.83	3.0007
2989.88	1.09689
2990.93	0.155334
2991.98	4.06204
2993.02	5.85223
2994.07	-6.48074
2995.12	6.00589
2996.17	7.29816
2997.21	0.774078
2998.26	2.83035
2999.31	3.80011
2999.94	3.70737