File: Data/3-Raman/processed/bu32-C-FF1-FI01-v.txt
#Acq. time (s)=	15
#Accumulations=	3
#Range (cm-¹)=	50...5000
#Windows=	1
#Auto scanning=	Off
#Autofocus=	Off
#Macrospot=	Off
#AutoExposure=	Off
#Spike filter=	Multiple accum.
#Delay time (s)=	0
#Binning=	1
#Readout mode=	Signal
#DeNoise=	Lite
#ICS correction=	Off
#Dark correction=	Off
#Inst. Process=	Off
#Detector temperature (°C)=	-60.09
#Instrument=	LabRAM HR Evol
#Detector=	SIN-EM FIVIS
#Objective=	x100_VIS
#Grating=	150 (500nm)
#ND Filter=	100%
#Laser=	532nm_Edge
#Hole=	30.0125
#Temperature=	0
#Range=	Visible
#StageXY=	75x50mm Scan+
#StageZ=	Z motor
#X (µm)=	17876.8
#Y (µm)=	4502.7
#Z (µm)=	-406.8
#Full time(s)=	47
#Project=	Buranga
#Sample=	BU18FA32_C
#Site=	C_FF1
#Title=	32-C_FF1_FI01
#Remark=
#Date=	09.07.2019 16:31
#Acquired=	09.07.2019 16:31:26
#Data Range:Extract=	16.12.2021 14:53:05
#Base:Fit=	16.12.2021 15:00:10
#Base:Sub=	16.12.2021 15:00:13
98.6609	1684.43
103.286	1349.24
107.909	1076.26
112.53	865.53
117.146	677.866
121.762	540.552
126.376	452.526
130.988	398.633
135.595	373.408
140.202	321.801
144.807	305.512
149.41	274.058
154.008	472.039
158.606	1246.56
163.201	2307.6
167.795	1299.15
172.384	391.194
176.973	101.365
181.559	29.7038
186.142	0.0359802
190.724	26.9124
195.304	79.0028
199.881	156.768
204.454	228.248
209.028	279.38
213.598	332.232
218.165	353.952
222.731	157.779
227.295	22.1055
231.855	50.5834
236.415	88.5273
240.972	125.428
245.525	121.563
250.078	27.0266
254.629	-0.0534363
259.175	80.2326
263.722	125.003
268.264	146.474
272.805	130.536
277.345	107.518
281.88	90.5715
286.415	79.2672
290.948	101.115
295.477	146.061
300.005	270.093
304.529	334.38
309.053	327.138
313.575	209.343
318.093	126.905
322.61	81.9546
327.123	76.1779
331.636	102.842
336.145	168.747
340.653	285.558
345.157	500.864
349.662	714.335
354.164	544.613
358.661	307.594
363.159	160.397
367.652	86.3132
372.145	37.2771
376.634	21.208
381.123	34.8036
385.608	78.3105
390.092	139.006
394.572	250.455
399.052	378.142
403.528	517.509
408.004	623.975
412.475	659.159
416.947	659.412
421.414	615.16
425.881	574.202
430.343	543.062
434.806	512.005
439.264	480.3
443.723	450.123
448.177	418.903
452.629	418.23
457.081	478.584
461.528	500.714
465.976	384.877
470.419	261.468
474.862	222.33
479.301	254.804
483.738	312.795
488.175	474.488
492.607	698.955
497.04	994.48
501.468	1286.18
505.894	1527.53
510.32	1760.04
514.742	1869.85
519.164	1944.41
523.581	1952.11
527.997	1910.1
532.412	1784.73
536.823	1667.98
541.232	1627.53
545.641	1648.53
550.046	1629.04
554.449	1619.31
558.851	1492.22
563.25	1361.94
567.646	1205.58
572.042	1051.51
576.434	963.997
580.824	1049.73
585.214	1374.42
589.599	1750.08
593.983	2137.71
598.367	2036.79
602.746	1519.21
607.123	1063.13
611.498	774.01
615.873	576.838
620.244	474.696
624.613	397.481
628.98	331.847
633.346	286.088
637.709	259.688
642.069	253.816
646.428	254.389
650.786	321.243
655.14	387.48
659.492	386.723
663.842	310.142
668.192	232.145
672.538	164.409
676.882	108.805
681.223	62.743
685.563	34.1943
689.902	18.4575
694.238	4.69635
698.571	9.75803
702.902	26.9996
707.231	35.2398
711.559	31.5561
715.886	24.859
720.209	16.1978
724.529	8.32034
728.848	5.349
733.165	5.67941
737.48	6.35797
741.792	7.13184
746.105	7.84576
750.413	8.43976
754.72	8.80341
759.024	8.96457
763.327	8.8028
767.627	8.65448
771.925	8.43275
776.221	7.60429
780.518	5.94846
784.81	3.815
789.1	1.79842
793.388	0.0611572
797.674	-1.34758
801.958	-1.09631
806.24	-0.34317
810.52	0.940536
814.797	2.7509
819.073	3.02628
823.347	3.29846
827.619	4.71407
831.888	6.11584
836.156	7.58052
840.422	8.42543
844.685	10.6232
848.947	12.2409
853.206	14.0481
857.464	16.6267
861.719	18.3199
865.973	19.7808
870.224	21.2
874.474	23.3464
878.721	27.9518
882.967	34.919
887.21	41.7643
891.452	48.0076
895.691	55.1996
899.929	66.1133
904.164	76.2149
908.397	89.9303
912.629	106.044
916.858	123.278
921.086	172.133
925.311	232.388
929.534	315.483
933.756	404.182
937.975	500.125
942.191	601.456
946.406	676.568
950.619	771.02
954.831	901.888
959.04	1039.21
963.248	1218.79
967.453	1516.85
971.657	1920.41
975.858	2270.92
980.056	2225.49
984.253	1843.09
988.449	1409.29
992.643	1210.54
996.834	1242.62
1001.02	1469.6
1005.21	1939.85
1009.4	2686.49
1013.58	3517.9
1017.76	3924.45
1021.94	3776.23
1026.12	3302.39
1030.29	2902.59
1034.47	2449.98
1038.64	1863.04
1042.81	1433.27
1046.98	1078.18
1051.14	885.951
1055.3	807.936
1059.47	833.22
1063.63	937.401
1067.78	1010.34
1071.94	1048.15
1076.09	989.838
1080.25	885.662
1084.4	764.365
1088.54	651.585
1092.69	588.943
1096.83	560.724
1100.98	597.556
1105.12	651.93
1109.26	724.7
1113.39	674.087
1117.53	559.245
1121.66	451.854
1125.79	355.011
1129.92	279.804
1134.04	234.633
1138.17	208.906
1142.29	187.26
1146.41	169.894
1150.53	155.685
1154.65	141.622
1158.76	124.735
1162.88	108.151
1166.99	91.6338
1171.1	76.005
1175.2	63.1562
1179.31	52.689
1183.41	44.455
1187.51	39.9536
1191.61	37.8123
1195.71	36.0856
1199.81	34.7121
1203.9	36.2671
1207.99	37.7117
1212.08	39.4036
1216.17	41.7425
1220.26	45.3537
1224.34	50.6549
1228.42	58.5719
1232.5	64.0963
1236.58	73.2174
1240.66	90.3213
1244.73	91.7763
1248.81	115.963
1252.88	220.026
1256.95	330.205
1261.02	174.15
1265.08	139.276
1269.14	207.397
1273.2	1462.51
1277.27	2989.62
1281.32	733.728
1285.38	188.436
1289.43	135.18
1293.48	114.285
1297.53	98.4349
1301.58	93.0397
1305.63	90.3442
1309.67	87.153
1313.72	82.6336
1317.76	87.1432
1321.8	89.6093
1325.83	91.4919
1329.87	90.5295
1333.9	88.7132
1337.93	90.0622
1341.96	92.9034
1345.99	98.7981
1350.02	104.209
1354.04	124.834
1358.06	148.83
1362.08	182.557
1366.1	165.546
1370.12	186.778
1374.13	558.649
1378.14	4204.62
1382.16	3290.59
1386.16	512.545
1390.17	192.498
1394.18	174.445
1398.18	340.386
1402.18	465.321
1406.18	186.409
1410.18	123.269
1414.18	90.3128
1418.17	79.8657
1422.16	64.0706
1426.15	51.1565
1430.14	42.2363
1434.13	35.8889
1438.11	30.333
1442.1	25.3618
1446.08	20.8286
1450.06	16.9939
1454.04	12.8456
1458.01	5.60893
1461.98	4.46071
1465.96	3.75281
1469.93	3.90912
1473.9	4.55217
1477.86	5.25969
1481.83	4.9705
1485.79	3.2083
1489.75	1.92149
1493.71	1.05745
1497.67	1.46295
1501.62	1.7804
1505.58	1.2182
1509.53	0.514908
1513.48	-0.0526276
1517.43	-0.469101
1521.38	-0.277893
1525.32	0.336639
1529.26	1.30574
1533.2	1.6579
1537.14	1.05594
1541.08	0.077301
1545.02	-1.05595
1548.95	-1.33469
1552.88	-1.1655
1556.81	-2.03296
1560.74	-1.32956
1564.67	-0.450027
1568.6	0.151779
1572.52	0.630707
1576.44	2.22836
1580.36	3.68552
1584.28	5.12785
1588.19	6.49745
1592.11	7.33951
1596.02	7.74921
1599.93	5.45055
1603.84	2.67778
1607.75	0.11438
1611.65	-0.37883
1615.56	0.0829163
1619.46	0.828201
1623.36	2.52582
1627.25	3.87466
1631.15	6.28514
1635.05	6.71637
1638.94	6.30672
1642.83	5.72961
1646.72	5.75208
1650.61	5.76265
1654.49	5.95737
1658.38	5.07188
1662.26	1.91995
1666.14	-1.52628
1670.02	-1.00742
1673.89	2.45085
1677.77	3.9698
1681.64	4.97862
1685.51	5.70874
1689.38	5.74345
1693.25	5.00749
1697.12	3.73601
1700.98	2.83701
1704.85	3.23289
1708.71	3.5329
1712.57	4.57738
1716.42	6.59833
1720.28	8.42665
1724.13	9.38441
1727.99	8.74524
1731.84	8.04254
1735.69	7.30504
1739.53	5.92313
1743.38	5.02615
1747.22	4.53036
1751.06	5.08672
1754.9	6.08147
1758.74	6.80159
1762.58	7.45251
1766.41	7.51982
1770.25	8.00691
1774.08	9.33824
1777.91	7.98782
1781.73	4.46973
1785.56	3.80049
1789.39	2.28372
1793.21	3.94962
1797.03	10.2153
1800.85	8.56026
1804.67	5.84477
1808.48	3.12468
1812.3	1.03322
1816.11	-0.607986
1819.92	-0.192108
1823.73	0.117386
1827.54	1.0262
1831.34	1.42075
1835.14	2.31761
1838.95	3.6476
1842.75	4.8158
1846.55	7.38268
1850.34	7.93666
1854.14	8.02289
1857.93	8.42157
1861.72	9.56703
1865.51	10.2672
1869.3	10.1409
1873.09	9.17723
1876.87	8.80107
1880.66	9.29991
1884.44	7.62402
1888.22	3.93163
1892	0.164322
1895.77	0.0287781
1899.55	9.79472
1903.32	9.25435
1907.09	9.68402
1910.86	8.40787
1914.63	8.32892
1918.4	10.3854
1922.16	13.9773
1925.92	14.6549
1929.68	4.68262
1933.44	2.42737
1937.2	0.626648
1940.96	1.11719
1944.71	1.13983
1948.46	1.4447
1952.22	3.16687
1955.97	6.01242
1959.71	8.01871
1963.46	8.52173
1967.2	7.45584
1970.95	6.22992
1974.69	4.24112
1978.43	2.87766
1982.17	2.10776
1985.9	2.0748
1989.64	3.77161
1993.37	5.76978
1997.1	7.72781
2000.83	7.72342
2004.56	7.10883
2008.28	7.72305
2012.01	8.7403
2015.73	9.37952
2019.45	10.0063
2023.17	10.324
2026.89	10.5021
2030.6	9.22925
2034.32	6.6774
2038.03	6.55731
2041.74	7.26974
2045.45	8.0466
2049.16	8.22369
2052.87	7.77386
2056.57	7.20834
2060.27	5.95569
2063.98	2.93555
2067.67	0.499054
2071.37	-1.61493
2075.07	-5.72409
2078.76	-3.33609
2082.46	0.105652
2086.15	4.11679
2089.84	6.76999
2093.53	9.30591
2097.21	7.34662
2100.9	6.25314
2104.58	5.63962
2108.26	5.11813
2111.94	4.724
2115.62	4.49661
2119.3	4.4006
2122.97	4.45654
2126.64	4.52957
2130.32	4.67944
2133.99	4.76233
2137.66	4.71838
2141.32	4.56958
2144.99	4.25098
2148.65	3.89227
2152.31	2.98218
2155.97	2.25134
2159.63	1.65506
2163.29	1.47046
2166.94	3.17487
2170.6	3.62769
2174.25	3.0484
2177.9	1.32306
2181.55	-0.415039
2185.2	-1.75549
2188.84	-2.0368
2192.49	1.69727
2196.13	3.65298
2199.77	5.207
2203.41	6.3121
2207.05	6.85281
2210.69	6.77441
2214.32	6.01221
2217.95	4.74338
2221.59	4.12579
2225.22	4.3092
2228.84	4.15808
2232.47	3.45523
2236.09	2.96829
2239.72	2.77188
2243.34	2.95181
2246.96	3.24005
2250.58	3.53613
2254.2	3.772
2257.81	4.10013
2261.42	4.49918
2265.04	4.86414
2268.65	6.44754
2272.26	8.0787
2275.86	7.3631
2279.47	5.65491
2283.08	3.79202
2286.68	2.10663
2290.28	0.857635
2293.88	0.0431824
2297.48	0.146149
2301.07	1.38397
2304.67	2.94073
2308.26	4.56277
2311.85	11.1432
2315.44	41.8971
2319.03	290.411
2322.62	500.564
2326.2	104.719
2329.79	14.878
2333.37	12.7021
2336.95	-0.550659
2340.53	0.632416
2344.11	3.03775
2347.68	13.0151
2351.26	19.4636
2354.83	21.1719
2358.4	22.538
2361.97	22.6163
2365.54	21.6583
2369.11	20.5576
2372.67	19.5044
2376.23	18.6541
2379.8	18.0876
2383.36	17.7809
2386.92	18.4212
2390.47	19.451
2394.03	20.7065
2397.58	21.4869
2401.14	21.2496
2404.69	19.7456
2408.24	17.6036
2411.78	15.8382
2415.33	14.0322
2418.88	11.8593
2422.42	9.90836
2425.96	11.2084
2429.5	14.308
2433.04	17.6874
2436.58	16.7049
2440.11	14.8335
2443.65	13.1795
2447.18	11.111
2450.71	9.59161
2454.24	9.39316
2457.77	11.2271
2461.3	13.9219
2464.82	16.821
2468.34	19.189
2471.86	17.4488
2475.39	14.9218
2478.9	13.0225
2482.42	11.2431
2485.94	9.28903
2489.45	7.595
2492.96	6.78564
2496.47	7.32614
2499.98	9.64758
2503.49	12.3121
2507	14.3401
2510.5	15.1013
2514.01	15.2803
2517.51	15.2382
2521.01	14.1625
2524.51	14.537
2528.01	15.2722
2531.5	16.073
2535	16.5938
2538.49	15.0601
2541.98	15.0088
2545.47	13.7033
2548.96	13.6937
2552.45	14.3386
2555.93	14.203
2559.42	15.3946
2562.9	18.2292
2566.38	16.662
2569.86	13.5099
2573.34	8.69174
2576.81	4.62405
2580.29	3.62585
2583.76	2.57724
2587.23	2.43027
2590.71	2.04599
2594.17	1.12967
2597.64	2.51907
2601.11	5.27994
2604.57	8.89471
2608.03	10.8313
2611.5	12.0421
2614.96	12.7053
2618.42	11.7384
2621.87	8.46432
2625.33	1.20392
2628.78	-2.53
2632.23	-1.74805
2635.68	1.18033
2639.13	6.26007
2642.58	10.1553
2646.03	10.5299
2649.47	12.1055
2652.92	11.7115
2656.36	9.76852
2659.8	7.77469
2663.24	6.16293
2666.68	7.57834
2670.11	9.04056
2673.55	10.2138
2676.98	12.4857
2680.41	14.2501
2683.84	16.2648
2687.27	17.6104
2690.7	18.0482
2694.13	16.7941
2697.55	14.957
2700.97	12.9793
2704.4	11.7378
2707.82	10.5104
2711.23	9.13071
2714.65	7.53104
2718.07	6.91583
2721.48	9.302
2724.9	12.8723
2728.31	16.2776
2731.72	14.5442
2735.12	13.8552
2738.53	13.9526
2741.94	12.6873
2745.34	10.5477
2748.74	9.56958
2752.14	10.5737
2755.54	13.4722
2758.94	16.4063
2762.34	19.4018
2765.73	22.2449
2769.13	23.9567
2772.52	24.8903
2775.91	17.699
2779.3	2.07285
2782.69	-1.30869
2786.08	0.981049
2789.46	10.4059
2792.85	12.6428
2796.23	15.2138
2799.61	18.1395
2802.99	20.674
2806.37	22.5074
2809.74	23.812
2813.12	24.3115
2816.49	23.0131
2819.86	21.4492
2823.23	19.6791
2826.61	18.1112
2829.97	15.2017
2833.34	14.2755
2836.7	17.5905
2840.07	19.3622
2843.43	23.471
2846.79	16.5377
2850.15	11.8496
2853.51	10.1287
2856.87	6.95697
2860.22	4.32614
2863.57	-2.51685
2866.93	3.59857
2870.28	9.79633
2873.63	11.0496
2876.98	10.3369
2880.32	6.03653
2883.67	1.87628
2887.01	0.0150452
2890.35	0.173157
2893.69	2.58499
2897.03	6.24277
2900.37	11.1246
2903.71	13.3317
2907.04	15.1824
2910.38	15.3572
2913.71	11.6491
2917.04	6.6355
2920.37	4.88425
2923.7	3.76721
2927.03	5.46683
2930.35	7.11807
2933.68	8.58813
2937	9.64343
2940.32	10.1648
2943.64	10.2667
2946.96	8.82529
2950.27	8.79547
2953.59	9.37302
2956.91	11.046
2960.22	13.7642
2963.53	14.8233
2966.84	16.8072
2970.15	18.3065
2973.46	20.3936
2976.76	23.5613
2980.07	23.5334
2983.37	21.909
2986.67	18.8423
2989.97	13.9677
2993.27	6.3793
2996.57	4.09
2999.86	3.57141
3003.16	4.08984
3006.45	5.24307
3009.75	8.4635
3013.03	9.82281
3016.32	10.4926
3019.61	11.0006
3022.9	10.8208
3026.19	10.4745
3029.47	10.2791
3032.75	9.62341
3036.03	10.0731
3039.31	8.70657
3042.59	5.83453
3045.87	0.598785
3049.14	0.717438
3052.42	0.963318
3055.69	1.76462
3058.96	3.78049
3062.23	6.45114
3065.5	9.37024
3068.77	11.5417
3072.03	13.2424
3075.3	13.9884
3078.56	17.4855
3081.82	23.7332
3085.08	24.062
3088.34	20.8896
3091.6	14.4092
3094.86	7.91898
3098.11	0.733063
3101.36	-1.4592
3104.62	3.52643
3107.87	8.58228
3111.12	13.2335
3114.37	16.8608
3117.61	18.6648
3120.86	19.3999
3124.1	16.9494
3127.34	13.9488
3130.59	11.0408
3133.83	8.79138
3137.07	7.07602
3140.3	5.77481
3143.54	6.95813
3146.77	10.1571
3150.01	14.3813
3153.24	18.0806
3156.47	20.8298
3159.7	22.2651
3162.93	20.844
3166.15	20.8954
3169.38	21.5153
3172.6	26.4395
3175.83	34.3024
3179.05	41.1697
3182.27	49.1519
3185.49	55.6037
3188.7	58.0922
3191.92	56.8935
3195.13	55.1181
3198.35	56.7435
3201.56	60.9497
3204.77	67.3239
3207.98	74.7672
3211.19	82.3691
3214.39	90.5301
3217.6	98.9311
3220.8	106.455
3224	112.378
3227.21	115.266
3230.41	120.096
3233.6	126.566
3236.8	130.684
3240	137.528
3243.19	147.567
3246.39	161.81
3249.58	177.356
3252.77	193.329
3255.96	208.319
3259.15	222.044
3262.33	234.357
3265.52	245.306
3268.7	254.98
3271.89	263.429
3275.07	270.777
3278.25	276.86
3281.43	281.301
3284.6	284.239
3287.78	286.765
3290.95	289.226
3294.13	289.966
3297.3	290.222
3300.47	286.873
3303.64	289.914
3306.81	296.992
3309.98	304.465
3313.14	312.91
3316.31	321.743
3319.47	327.885
3322.63	332.324
3325.79	334.92
3328.95	336.669
3332.11	340.505
3335.27	343.301
3338.42	351.441
3341.58	367.291
3344.73	382.155
3347.88	397.579
3351.03	411.773
3354.18	429.385
3357.33	450.075
3360.47	468.698
3363.62	487.011
3366.76	502.055
3369.91	515.463
3373.05	528.638
3376.19	539.703
3379.32	559.2
3382.46	585.175
3385.6	612.641
3388.73	649.527
3391.87	685.306
3395	723.726
3398.13	762.486
3401.26	795.973
3404.39	824.265
3407.51	839.823
3410.64	842.484
3413.76	830.957
3416.89	807.155
3420.01	773.72
3423.13	734.374
3426.25	703.771
3429.37	682.62
3432.48	678.35
3435.6	682.599
3438.71	699.572
3441.83	715.009
3444.94	737.298
3448.05	763.486
3451.16	789.605
3454.27	823.015
3457.37	859.68
3460.48	915.661
3463.58	983.721
3466.69	1057.63
3469.79	1132.11
3472.89	1195.39
3475.99	1241.37
3479.08	1277.14
3482.18	1293.54
3485.28	1289.93
3488.37	1272.91
3491.46	1249.71
3494.55	1217.99
3497.64	1178.06
3500.73	1124.72
3503.82	1079.15
3506.91	1032.03
3509.99	974.185
3513.08	920.051
3516.16	869.279
3519.24	821.749
3522.32	777.544
3525.4	733.499
3528.48	689.396
3531.55	646.588
3534.63	605.818
3537.7	567.57
3540.78	536.232
3543.85	515.409
3546.92	498.167
3549.99	483.356
3553.05	470.316
3556.12	457.685
3559.19	442.546
3562.25	426.153
3565.31	405.454
3568.37	385.416
3571.43	366.601
3574.49	345.558
3577.55	325.889
3580.61	309.326
3583.66	295.875
3586.72	286.07
3589.77	281.474
3592.82	279.381
3595.87	279.446
3598.92	280.058
3601.97	281.024
3605.02	280.518
3608.06	276.24
3611.11	271.284
3614.15	265.129
3617.19	259.584
3620.23	254.599
3623.27	253.304
3626.31	252.766
3629.34	249.599
3632.38	244.3
3635.41	236.525
3638.45	227.754
3641.48	218.068
3644.51	207.572
3647.54	197.728
3650.57	185.184
3653.59	170.926
3656.62	149.197
3659.65	130.552
3662.67	115.488
3665.69	108.421
3668.71	101.096
3671.73	92.9542
3674.75	85.7605
3677.77	78.5564
3680.78	71.9289
3683.8	63.8438
3686.81	53.9057
3689.82	45.1665
3692.84	35.2951
3695.84	29.3221
3698.85	25.3389
3701.86	22.4445
3704.87	22.3571
3707.87	20.1101
3710.88	15.2039
3713.88	13.1618
3716.88	12.8223
3719.88	10.5343
3722.88	7.55444
3725.88	6.70523
3728.88	8.73187
3731.87	11.0679
3734.87	10.3242
3737.86	9.60248
3740.85	2.50113
3743.84	-2.39902
3746.83	1.26202
3749.82	4.09003
3752.81	5.10007
3755.79	3.76959
3758.78	1.02896
3761.76	2.3913
3764.74	4.73438
3767.73	9.44757
3770.71	12.4439
3773.68	12.859
3776.66	15.674
3779.64	17.8553
3782.61	19.4473
3785.59	19.9259
3788.56	17.5187
3791.53	15.0498
3794.5	10.5018
3797.47	7.46429
3800.44	6.36783
3803.41	7.42355
3806.37	10.613
3809.34	12.2786
3812.3	12.4817
3815.26	13.8858
3818.22	14.0266
3821.18	6.32986
3824.14	-17.293
3827.1	5.073
3830.06	13.4626
3833.01	17.7531
3835.96	18.5981
3838.92	19.2667
3841.87	16.6127
3844.82	15.1206
3847.77	13.1412
3850.72	14.7014
3853.66	17.4741
3856.61	19.3618
3859.55	19.5859
3862.5	18.3097
3865.44	15.7968
3868.38	11.7199
3871.32	8.15988
3874.26	6.64944
3877.2	4.79327
3880.13	6.21286
3883.07	6.9245
3886	8.14276
3888.94	9.47366
3891.87	11.0303
3894.8	12.8773
3897.73	14.9763
3900.66	18.1298
3903.58	19.3636
3906.51	17.9399
3909.43	16.0079
3912.36	14.2557
3915.28	11.2737
3918.2	11.3832
3921.12	12.2153
3924.04	13.6308
3926.96	15.2514
3929.87	14.1064
3932.79	13.5325
3935.7	10.7627
3938.62	9.0444
3941.53	9.56906
3944.44	11.828
3947.35	10.8253
3950.26	8.41302
3953.17	9.73758
3956.07	10.4731
3958.98	10.4801
3961.88	9.79724
3964.78	7.94446
3967.69	5.38242
3970.59	2.66721
3973.49	0.478455
3976.38	0.101044
3979.28	0.50647
3982.18	0.861206
3985.07	-0.400238
3987.97	-0.529602
3990.86	0.85376
3993.75	3.43723
3996.64	1.14429
3999.53	-1.44806