File: Data/3-Raman/processed/bu32-C-FF1-FI08-v.txt
#Acq. time (s)=	15
#Accumulations=	3
#Range (cm-¹)=	50...5000
#Windows=	1
#Auto scanning=	Off
#Autofocus=	Off
#Macrospot=	Off
#AutoExposure=	Off
#Spike filter=	Multiple accum.
#Delay time (s)=	0
#Binning=	1
#Readout mode=	Signal
#DeNoise=	Lite
#ICS correction=	Off
#Dark correction=	Off
#Inst. Process=	Off
#Detector temperature (°C)=	-60.09
#Instrument=	LabRAM HR Evol
#Detector=	SIN-EM FIVIS
#Objective=	x100_VIS
#Grating=	150 (500nm)
#ND Filter=	100%
#Laser=	532nm_Edge
#Hole=	30.0125
#Temperature=	0
#Range=	Visible
#StageXY=	75x50mm Scan+
#StageZ=	Z motor
#X (µm)=	17774.9
#Y (µm)=	4242.8
#Z (µm)=	-419.5
#Full time(s)=	47
#Project=	Buranga
#Sample=	BU18FA32_C
#Site=	C_FF1
#Title=	32-C_FF1_FI08
#Remark=
#Date=	09.07.2019 16:49
#Acquired=	09.07.2019 16:49:26
#Data Range:Extract=	16.12.2021 14:53:05
#Base:Fit=	16.12.2021 15:01:18
#Base:Edit=	16.12.2021 15:01:20
#Base:Edit=	16.12.2021 15:01:20
#Base:Sub=	16.12.2021 15:01:22
98.6609	1092.03
103.286	851.551
107.909	659.749
112.53	512.996
117.146	415.827
121.762	341.944
126.376	288.667
130.988	258.357
135.595	251.697
140.202	253.609
144.807	194.78
149.41	152.812
154.008	278.13
158.606	685.721
163.201	1052.76
167.795	551.604
172.384	157.322
176.973	23.1236
181.559	0.449371
186.142	3.5668
190.724	11.9074
195.304	42.483
199.881	81.1705
204.454	120.045
209.028	159.161
213.598	173.076
218.165	109.388
222.731	43.7033
227.295	25.603
231.855	59.7073
236.415	117.208
240.972	176.325
245.525	152.772
250.078	94.0576
254.629	77.0951
259.175	112.885
263.722	116.837
268.264	101.747
272.805	84.1705
277.345	68.4768
281.88	54.2001
286.415	50.8318
290.948	61.7188
295.477	78.5173
300.005	177.476
304.529	250.526
309.053	187.037
313.575	112.837
318.093	60.7256
322.61	38.2763
327.123	46.3987
331.636	70.3081
336.145	116.92
340.653	195.003
345.157	351.245
349.662	422.535
354.164	307.262
358.661	142.861
363.159	72.5621
367.652	30.704
372.145	5.08218
376.634	-1.9632
381.123	8.35016
385.608	34.8666
390.092	77.5634
394.572	135.792
399.052	205.215
403.528	285.331
408.004	362.163
412.475	427.2
416.947	474.918
421.414	516.577
425.881	543.711
430.343	570.501
434.806	560.986
439.264	512.761
443.723	462.029
448.177	447.533
452.629	511.719
457.081	658.117
461.528	567.229
465.976	389.2
470.419	256.559
474.862	183.042
479.301	182.077
483.738	233.158
488.175	317.64
492.607	425.556
497.04	627.568
501.468	825.658
505.894	1013.92
510.32	1153.9
514.742	1250.18
519.164	1320.64
523.581	1327.43
527.997	1284.15
532.412	1215.01
536.823	1132.87
541.232	1073.23
545.641	1138.32
550.046	1154.75
554.449	1091.67
558.851	1047.07
563.25	940.176
567.646	781.223
572.042	705.875
576.434	640.828
580.824	688.6
585.214	871.632
589.599	998.086
593.983	1188.63
598.367	1085.52
602.746	831.163
607.123	654.774
611.498	495.681
615.873	398.878
620.244	324.923
624.613	272.475
628.98	236.516
633.346	217.427
637.709	213.798
642.069	210.291
646.428	247.41
650.786	296.71
655.14	354.747
659.492	333.48
663.842	255.626
668.192	182.952
672.538	122.165
676.882	71.6822
681.223	42.9145
685.563	22.4543
689.902	14.9306
694.238	20.539
698.571	27.3736
702.902	31.7165
707.231	31.5476
711.559	27.6707
715.886	22.0415
720.209	15.623
724.529	9.11877
728.848	4.80922
733.165	2.85133
737.48	2.54474
741.792	3.52809
746.105	4.49701
750.413	5.4577
754.72	6.34726
759.024	6.28032
763.327	4.71901
767.627	2.84549
771.925	1.5392
776.221	0.271042
780.518	-1.4198
784.81	-2.13875
789.1	-2.42371
793.388	-3.05948
797.674	-2.38408
801.958	1.01538
806.24	1.59149
810.52	0.910736
814.797	-2.07246
819.073	-4.93683
823.347	-4.16522
827.619	-3.38345
831.888	-3.67479
836.156	-3.2724
840.422	-1.2569
844.685	0.837692
848.947	2.26978
853.206	5.2748
857.464	4.79134
861.719	4.05594
865.973	3.72028
870.224	3.78693
874.474	4.88947
878.721	6.81184
882.967	10.0616
887.21	14.3518
891.452	19.213
895.691	25.5982
899.929	33.9636
904.164	44.3118
908.397	56.541
912.629	73.4074
916.858	97.9133
921.086	129.404
925.311	171.464
929.534	221.788
933.756	279.404
937.975	346.261
942.191	424.957
946.406	512.807
950.619	608.93
954.831	729.67
959.04	841.708
963.248	973.38
967.453	1188.96
971.657	1469.35
975.858	1695.64
980.056	1575.25
984.253	1220.98
988.449	1002.86
992.643	900.835
996.834	911.233
1001.02	1101.57
1005.21	1486.46
1009.4	1938.5
1013.58	2399.96
1017.76	2601.15
1021.94	2502.22
1026.12	2246.29
1030.29	2053.72
1034.47	1637.15
1038.64	1361.9
1042.81	996.344
1046.98	761.775
1051.14	676.174
1055.3	663.572
1059.47	702.999
1063.63	798.657
1067.78	868.915
1071.94	864.336
1076.09	821.273
1080.25	727.632
1084.4	612.756
1088.54	494.289
1092.69	492.591
1096.83	462.942
1100.98	562.287
1105.12	600.627
1109.26	707.963
1113.39	650.808
1117.53	517.69
1121.66	389.156
1125.79	285.796
1129.92	212.081
1134.04	177.126
1138.17	156.068
1142.29	136.834
1146.41	119.424
1150.53	101.977
1154.65	86.4819
1158.76	73.3597
1162.88	62.195
1166.99	52.2457
1171.1	43.9908
1175.2	37.5393
1179.31	32.8258
1183.41	28.9033
1187.51	24.2625
1191.61	20.1914
1195.71	17.8067
1199.81	17.2786
1203.9	18.056
1207.99	20.3761
1212.08	24.0628
1216.17	28.217
1220.26	31.7306
1224.34	33.1452
1228.42	34.2166
1232.5	35.2486
1236.58	43.5927
1240.66	54.7964
1244.73	70.8076
1248.81	86.1953
1252.88	173.194
1256.95	219.099
1261.02	117.855
1265.08	102.996
1269.14	206.625
1273.2	1506.26
1277.27	1806.39
1281.32	362.508
1285.38	98.1096
1289.43	79.1061
1293.48	72.6031
1297.53	68.9833
1301.58	65.7229
1305.63	63.3706
1309.67	61.977
1313.72	61.525
1317.76	61.2841
1321.8	60.4286
1325.83	59.8298
1329.87	58.7899
1333.9	59.2422
1337.93	61.3776
1341.96	63.3497
1345.99	70.77
1350.02	80.3456
1354.04	94.0732
1358.06	114.873
1362.08	148.413
1366.1	125.497
1370.12	177.687
1374.13	677.673
1378.14	3477.65
1382.16	1698.63
1386.16	259.594
1390.17	147.555
1394.18	117.51
1398.18	285.459
1402.18	302.402
1406.18	98.5755
1410.18	73.3641
1414.18	63.9612
1418.17	53.9502
1422.16	45.5555
1426.15	38.7625
1430.14	32.9522
1434.13	27.4784
1438.11	23.0909
1442.1	19.11
1446.08	14.8549
1450.06	10.7382
1454.04	7.1158
1458.01	3.82684
1461.98	1.11743
1465.96	-3.60252
1469.93	-1.1154
1473.9	0.301697
1477.86	1.80751
1481.83	3.34471
1485.79	4.97823
1489.75	7.26108
1493.71	9.5247
1497.67	11.0754
1501.62	12.9873
1505.58	12.2322
1509.53	10.8197
1513.48	8.34125
1517.43	6.59201
1521.38	4.83859
1525.32	4.15573
1529.26	4.93076
1533.2	7.11543
1537.14	10.1301
1541.08	13.2394
1545.02	14.5299
1548.95	13.351
1552.88	11.2472
1556.81	8.34825
1560.74	6.13387
1564.67	3.66312
1568.6	2.68198
1572.52	3.79617
1576.44	5.93024
1580.36	9.0871
1584.28	12.3914
1588.19	13.8501
1592.11	14.4426
1596.02	14.309
1599.93	13.3314
1603.84	12.7205
1607.75	12.2318
1611.65	11.9256
1615.56	12.714
1619.46	15.4774
1623.36	8.43181
1627.25	16.5598
1631.15	20.7117
1635.05	20.2851
1638.94	18.6427
1642.83	8.64606
1646.72	0.976013
1650.61	9.1427
1654.49	10.8134
1658.38	11.4978
1662.26	10.2778
1666.14	9.31706
1670.02	8.6693
1673.89	9.80954
1677.77	10.8187
1681.64	11.4873
1685.51	12.1562
1689.38	12.616
1693.25	13.3905
1697.12	12.7767
1700.98	11.1445
1704.85	9.69325
1708.71	8.27025
1712.57	7.46696
1716.42	7.06482
1720.28	6.97261
1724.13	6.53061
1727.99	4.7751
1731.84	4.0067
1735.69	3.38007
1739.53	2.49695
1743.38	2.68195
1747.22	3.55292
1751.06	6.38618
1754.9	10.0506
1758.74	11.6538
1762.58	11.6587
1766.41	11.0528
1770.25	9.79097
1774.08	7.86879
1777.91	5.98236
1781.73	3.59976
1785.56	1.0318
1789.39	-1.34438
1793.21	-2.79831
1797.03	-3.72519
1800.85	-2.93312
1804.67	-1.05302
1808.48	1.4978
1812.3	2.76355
1816.11	4.81282
1819.92	5.72539
1823.73	5.72978
1827.54	4.47527
1831.34	4.09306
1835.14	1.53255
1838.95	-3.24599
1842.75	-5.03334
1846.55	-1.19644
1850.34	3.86432
1854.14	7.28522
1857.93	9.07655
1861.72	10.1025
1865.51	10.4854
1869.3	10.1973
1873.09	9.28365
1876.87	8.01907
1880.66	8.70084
1884.44	3.51575
1888.22	2.028
1892	11.3645
1895.77	9.41014
1899.55	7.67592
1903.32	3.56328
1907.09	1.44429
1910.86	1.0318
1914.63	1.61879
1918.4	2.82317
1922.16	3.6255
1925.92	4.45285
1929.68	3.39522
1933.44	3.13348
1937.2	0.349045
1940.96	0.531387
1944.71	0.447632
1948.46	-1.12503
1952.22	-0.729507
1955.97	0.612
1959.71	1.67545
1963.46	3.57332
1967.2	4.17209
1970.95	3.93002
1974.69	3.37085
1978.43	1.96182
1982.17	0.549469
1985.9	-0.593826
1989.64	-1.2877
1993.37	-1.28267
1997.1	-0.937836
2000.83	-0.229324
2004.56	0.920242
2008.28	2.48929
2012.01	4.2592
2015.73	6.11591
2019.45	7.31633
2023.17	8.75049
2026.89	8.64847
2030.6	8.90073
2034.32	8.23091
2038.03	7.00092
2041.74	4.90363
2045.45	2.64824
2049.16	0.827972
2052.87	-1.08073
2056.57	-2.8317
2060.27	-3.45622
2063.98	-2.40315
2067.67	0.620331
2071.37	4.64949
2075.07	7.88161
2078.76	9.15286
2082.46	8.68959
2086.15	7.6127
2089.84	6.104
2093.53	4.15872
2097.21	1.22342
2100.9	-1.362
2104.58	-1.14578
2108.26	0.752502
2111.94	3.24042
2115.62	6.40164
2119.3	8.69745
2122.97	10.4489
2126.64	10.7507
2130.32	9.86874
2133.99	9.79059
2137.66	9.63721
2141.32	6.79523
2144.99	5.38129
2148.65	6.00946
2152.31	9.44669
2155.97	10.3256
2159.63	9.84067
2163.29	9.92834
2166.94	9.9425
2170.6	9.69592
2174.25	9.03198
2177.9	8.28854
2181.55	7.11539
2185.2	5.99591
2188.84	5.33499
2192.49	5.00348
2196.13	4.84622
2199.77	4.83353
2203.41	4.59875
2207.05	4.14514
2210.69	3.4982
2214.32	2.67224
2217.95	1.81665
2221.59	1.09601
2225.22	0.555206
2228.84	0.266907
2232.47	-0.125824
2236.09	-0.0336304
2239.72	1.04727
2243.34	2.70435
2246.96	4.26245
2250.58	5.85754
2254.2	7.32495
2257.81	8.35397
2261.42	8.32962
2265.04	7.54666
2268.65	6.51208
2272.26	5.55606
2275.86	4.58643
2279.47	3.41223
2283.08	2.26309
2286.68	1.35739
2290.28	0.610718
2293.88	-0.0340576
2297.48	0.759857
2301.07	2.96188
2304.67	1.04916
2308.26	1.21707
2311.85	11.0051
2315.44	35.0899
2319.03	243.924
2322.62	251.362
2326.2	46.9328
2329.79	17.5434
2333.37	10.5697
2336.95	7.61316
2340.53	8.00357
2344.11	7.49078
2347.68	9.60321
2351.26	11.1039
2354.83	13.6735
2358.4	15.4609
2361.97	15.7161
2365.54	15.3358
2369.11	14.2243
2372.67	13.4662
2376.23	13.3024
2379.8	12.9618
2383.36	13.7155
2386.92	15.2075
2390.47	16.9656
2394.03	18.1069
2397.58	18.9293
2401.14	19.2793
2404.69	19.3053
2408.24	19.0499
2411.78	18.3984
2415.33	16.3156
2418.88	15.4472
2422.42	15.8432
2425.96	17.3434
2429.5	19.2655
2433.04	21.0001
2436.58	21.885
2440.11	20.7795
2443.65	18.3836
2447.18	12.9854
2450.71	10.0856
2454.24	8.58173
2457.77	7.88986
2461.3	8.0813
2464.82	8.97586
2468.34	10.0541
2471.86	10.7662
2475.39	11.4011
2478.9	10.7605
2482.42	10.0762
2485.94	9.99719
2489.45	10.5467
2492.96	11.5862
2496.47	12.9759
2499.98	15.0791
2503.49	18.6213
2507	20.8757
2510.5	20.9289
2514.01	19.8971
2517.51	18.1871
2521.01	16.2737
2524.51	13.9829
2528.01	12.8838
2531.5	12.9478
2535	17.8965
2538.49	24.3151
2541.98	27.6192
2545.47	29.6704
2548.96	29.6032
2552.45	28.3618
2555.93	24.4687
2559.42	21.0778
2562.9	13.6703
2566.38	12.5713
2569.86	13.8423
2573.34	14.4269
2576.81	13.5655
2580.29	11.0097
2583.76	9.11801
2587.23	7.74097
2590.71	7.18649
2594.17	8.83917
2597.64	10.0287
2601.11	10.1009
2604.57	10.3792
2608.03	10.1478
2611.5	14.407
2614.96	12.671
2618.42	7.27972
2621.87	3.16278
2625.33	-7.73453
2628.78	12.6951
2632.23	20.8298
2635.68	21.2251
2639.13	18.2677
2642.58	15.9193
2646.03	15.7027
2649.47	16.5311
2652.92	18.96
2656.36	20.3268
2659.8	19.6164
2663.24	18.8299
2666.68	16.9307
2670.11	15.9133
2673.55	14.3886
2676.98	12.9168
2680.41	12.2404
2683.84	13.3516
2687.27	16.4089
2690.7	18.2229
2694.13	19.7045
2697.55	20.9006
2700.97	21.3579
2704.4	21.6759
2707.82	21.5758
2711.23	22.1341
2714.65	22.2923
2718.07	21.1213
2721.48	19.4572
2724.9	12.4165
2728.31	8.70099
2731.72	7.31097
2735.12	5.5687
2738.53	3.61652
2741.94	3.95248
2745.34	7.76132
2748.74	3.64551
2752.14	-0.412659
2755.54	-1.84769
2758.94	-0.407867
2762.34	7.32556
2765.73	12.9572
2769.13	13.4233
2772.52	11.1541
2775.91	10.2507
2779.3	10.4009
2782.69	11.0188
2786.08	12.147
2789.46	13.1062
2792.85	14.7094
2796.23	15.2681
2799.61	16.0467
2802.99	16.4907
2806.37	16.2372
2809.74	15.7488
2813.12	15.543
2816.49	15.7392
2819.86	16.3687
2823.23	16.1374
2826.61	15.5948
2829.97	14.6484
2833.34	13.7731
2836.7	12.9573
2840.07	12.7996
2843.43	13.0787
2846.79	13.6665
2850.15	19.1381
2853.51	20.515
2856.87	20.325
2860.22	18.9151
2863.57	16.4431
2866.93	14.6067
2870.28	12.3193
2873.63	13.7648
2876.98	10.8523
2880.32	8.41617
2883.67	7.3544
2887.01	6.16257
2890.35	6.42487
2893.69	1.46411
2897.03	4.71893
2900.37	8.49838
2903.71	14.4352
2907.04	21.4577
2910.38	19.0707
2913.71	10.5195
2917.04	4.659
2920.37	1.09308
2923.7	-1.64603
2927.03	-3.34726
2930.35	-1.39807
2933.68	0.369934
2937	2.77466
2940.32	4.87949
2943.64	4.87912
2946.96	4.63513
2950.27	5.60815
2953.59	7.34607
2956.91	9.58575
2960.22	11.1009
2963.53	12.7761
2966.84	13.69
2970.15	16.1783
2973.46	16.1762
2976.76	14.5475
2980.07	12.0581
2983.37	7.97034
2986.67	3.77988
2989.97	0.603638
2993.27	-2.23209
2996.57	-3.47021
2999.86	-2.79254
3003.16	0.311554
3006.45	2.82312
3009.75	5.87024
3013.03	9.09747
3016.32	11.3328
3019.61	10.3951
3022.9	8.45593
3026.19	7.23206
3029.47	4.14969
3032.75	1.66803
3036.03	2.59564
3039.31	4.83292
3042.59	7.56851
3045.87	11.0696
3049.14	15.0173
3052.42	19.2745
3055.69	22.0348
3058.96	25.3282
3062.23	29.459
3065.5	26.92
3068.77	21.085
3072.03	14.4417
3075.3	11.6988
3078.56	12.6339
3081.82	17.2944
3085.08	24.0377
3088.34	28.4319
3091.6	34.3547
3094.86	40.5715
3098.11	41.1427
3101.36	41.7774
3104.62	39.2625
3107.87	42.1804
3111.12	43.7535
3114.37	46.4621
3117.61	50.2401
3120.86	53.7177
3124.1	55.8178
3127.34	57.0928
3130.59	56.7914
3133.83	54.3571
3137.07	56.7726
3140.3	68.6974
3143.54	75.4837
3146.77	77.6509
3150.01	78.46
3153.24	78.9559
3156.47	79.6308
3159.7	81.3246
3162.93	82.9785
3166.15	84.8209
3169.38	86.9541
3172.6	93.149
3175.83	100.576
3179.05	109.408
3182.27	117.167
3185.49	123.854
3188.7	130.282
3191.92	136.507
3195.13	141.126
3198.35	144.036
3201.56	147.691
3204.77	153.478
3207.98	160.985
3211.19	170.207
3214.39	181.018
3217.6	193.408
3220.8	204.614
3224	214.517
3227.21	222.06
3230.41	225.4
3233.6	229.561
3236.8	236.965
3240	246.292
3243.19	257.146
3246.39	271.113
3249.58	284.625
3252.77	298.091
3255.96	309.467
3259.15	319.668
3262.33	328.233
3265.52	334.712
3268.7	339.464
3271.89	341.774
3275.07	349.031
3278.25	356.841
3281.43	365.695
3284.6	373.484
3287.78	378.084
3290.95	381.238
3294.13	382.383
3297.3	382.469
3300.47	378.359
3303.64	372.968
3306.81	380.343
3309.98	382.898
3313.14	384.572
3316.31	385.986
3319.47	389.855
3322.63	394.57
3325.79	400.141
3328.95	406.245
3332.11	409.449
3335.27	413.637
3338.42	423.43
3341.58	439.836
3344.73	453.581
3347.88	464.125
3351.03	473.545
3354.18	481.468
3357.33	489.574
3360.47	497.912
3363.62	508.432
3366.76	531.835
3369.91	541.365
3373.05	553.752
3376.19	564.807
3379.32	581.027
3382.46	598.735
3385.6	624.731
3388.73	660.795
3391.87	695.131
3395	726.743
3398.13	759.98
3401.26	786.292
3404.39	802.807
3407.51	811.635
3410.64	810.564
3413.76	805.168
3416.89	780.871
3420.01	755.475
3423.13	734.543
3426.25	717.991
3429.37	712.11
3432.48	707.262
3435.6	705.087
3438.71	707.14
3441.83	712.264
3444.94	722.658
3448.05	738.021
3451.16	755.763
3454.27	769.349
3457.37	784.968
3460.48	808.028
3463.58	836.895
3466.69	880.736
3469.79	925.59
3472.89	965.672
3475.99	993.522
3479.08	1013.81
3482.18	1020.45
3485.28	1015.07
3488.37	1001.91
3491.46	987.964
3494.55	972.504
3497.64	954.338
3500.73	933.337
3503.82	903.419
3506.91	864.236
3509.99	815.723
3513.08	777.063
3516.16	767.11
3519.24	737.54
3522.32	698.958
3525.4	654.34
3528.48	608.269
3531.55	570.729
3534.63	538.832
3537.7	511.029
3540.78	489.197
3543.85	473.152
3546.92	461.418
3549.99	458.164
3553.05	458.668
3556.12	452.929
3559.19	440.504
3562.25	423.495
3565.31	404.441
3568.37	380.315
3571.43	353.689
3574.49	325.745
3577.55	298.584
3580.61	275.826
3583.66	272.078
3586.72	266.382
3589.77	262.803
3592.82	263.284
3595.87	262.303
3598.92	253.915
3601.97	243.911
3605.02	233.7
3608.06	231.639
3611.11	229.96
3614.15	231.675
3617.19	228.694
3620.23	226.5
3623.27	225.065
3626.31	216.676
3629.34	208.463
3632.38	197.651
3635.41	188.488
3638.45	179.299
3641.48	170.411
3644.51	160.836
3647.54	150.855
3650.57	139.63
3653.59	125.849
3656.62	113.55
3659.65	99.4931
3662.67	89.3779
3665.69	79.8485
3668.71	65.0168
3671.73	68.7117
3674.75	69.3191
3677.77	57.1866
3680.78	46.2858
3683.8	37.7946
3686.81	29.9934
3689.82	24.3335
3692.84	19.8674
3695.84	16.3072
3698.85	13.2109
3701.86	10.8521
3704.87	9.67291
3707.87	7.38223
3710.88	3.32474
3713.88	-1.44138
3716.88	-2.4599
3719.88	-3.34628
3722.88	-4.74359
3725.88	-5.07004
3728.88	-4.53986
3731.87	-8.9025
3734.87	-5.26608
3737.86	-2.64838
3740.85	-0.747772
3743.84	-1.68231
3746.83	-4.29199
3749.82	-13.5243
3752.81	-18.489
3755.79	-18.9567
3758.78	-12.475
3761.76	-5.961
3764.74	1.12466
3767.73	1.03168
3770.71	-0.834076
3773.68	-4.93555
3776.66	-10.3129
3779.64	-14.3576
3782.61	-17.2899
3785.59	-21.6163
3788.56	-20.5904
3791.53	-17.3534
3794.5	-12.7328
3797.47	-8.47983
3800.44	-4.90802
3803.41	-3.90457
3806.37	-4.76529
3809.34	-3.16318
3812.3	-1.53973
3815.26	-0.457703
3818.22	0.349426
3821.18	0.667816
3824.14	0.475952
3827.1	-0.777771
3830.06	-2.51749
3833.01	-5.92661
3835.96	-8.47644
3838.92	-9.23337
3841.87	-7.97003
3844.82	-5.09094
3847.77	-1.40314
3850.72	0.395447
3853.66	1.99811
3856.61	1.5618
3859.55	-0.181549
3862.5	-2.51886
3865.44	-4.38965
3868.38	-5.30597
3871.32	-5.47504
3874.26	-3.67804
3877.2	0.144196
3880.13	3.69983
3883.07	5.60468
3886	7.52472
3888.94	7.33743
3891.87	6.17657
3894.8	3.2532
3897.73	-0.415771
3900.66	-3.43628
3903.58	-3.45309
3906.51	-1.77127
3909.43	0.688232
3912.36	3.03308
3915.28	7.15475
3918.2	6.91977
3921.12	5.73941
3924.04	2.5314
3926.96	1.39005
3929.87	2.87054
3932.79	9.01749
3935.7	11.9976
3938.62	11.3524
3941.53	6.70752
3944.44	0.729645
3947.35	-1.35529
3950.26	-1.71875
3953.17	-0.812561
3956.07	1.4523
3958.98	3.34335
3961.88	3.60208
3964.78	2.91583
3967.69	2.11292
3970.59	2.49344
3973.49	1.56332
3976.38	-0.182617
3979.28	-3.23788
3982.18	-5.53799
3985.07	-4.91855
3987.97	-3.32529
3990.86	-0.774841
3993.75	2.10971
3996.64	0.695099
3999.53	-2.02469