File: Data/3-Raman/processed/bu32-A-FF1-FI06-v.txt
#Acq. time (s)=	15
#Accumulations=	3
#Range (cm-¹)=	50...5000
#Windows=	1
#Auto scanning=	Off
#Autofocus=	Off
#Macrospot=	Off
#AutoExposure=	Off
#Spike filter=	Multiple accum.
#Delay time (s)=	0
#Binning=	1
#Readout mode=	Signal
#DeNoise=	Lite
#ICS correction=	Off
#Dark correction=	Off
#Inst. Process=	Off
#Detector temperature (°C)=	-60.09
#Instrument=	LabRAM HR Evol
#Detector=	SIN-EM FIVIS
#Objective=	x100_VIS
#Grating=	150 (500nm)
#ND Filter=	100%
#Laser=	532nm_Edge
#Hole=	30.0125
#Temperature=	0
#Range=	Visible
#StageXY=	75x50mm Scan+
#StageZ=	Z motor
#X (µm)=	-16446
#Y (µm)=	2792.4
#Z (µm)=	-414.5
#Full time(s)=	48
#Project=	Buranga
#Sample=	BU18FA32_A
#Site=	A_FF1
#Title=	32-A_FF1_FI06
#Remark=
#Date=	09.07.2019 14:48
#Acquired=	09.07.2019 14:48:05
#Data Range:Extract=	16.12.2021 14:53:05
#Base:Fit=	16.12.2021 14:56:44
#Base:Sub=	16.12.2021 14:56:47
98.6609	1785.73
103.286	1450.39
107.909	1127.67
112.53	898.894
117.146	718.488
121.762	579.464
126.376	473.923
130.988	392.131
135.595	330.216
140.202	282.594
144.807	251.836
149.41	226.943
154.008	204.79
158.606	184.757
163.201	169.507
167.795	310.806
172.384	629.648
176.973	438.305
181.559	108.246
186.142	23.7062
190.724	7.30576
195.304	-1.05606
199.881	1.13382
204.454	7.21567
209.028	20.8062
213.598	36.4904
218.165	65.7805
222.731	69.772
227.295	65.1242
231.855	20.7222
236.415	1.01727
240.972	17.9797
245.525	22.7279
250.078	25.1726
254.629	24.8387
259.175	20.204
263.722	8.76901
268.264	18.1602
272.805	42.1059
277.345	64.5421
281.88	51.1901
286.415	43.1667
290.948	31.5135
295.477	28.5469
300.005	26.5655
304.529	52.9322
309.053	107.311
313.575	148.23
318.093	153.092
322.61	116.885
327.123	55.6096
331.636	24.0461
336.145	15.0152
340.653	21.4264
345.157	53.8351
349.662	112.714
354.164	221.023
358.661	343.933
363.159	305.702
367.652	160.136
372.145	71.1635
376.634	25.1442
381.123	3.87848
385.608	-0.189819
390.092	8.50983
394.572	25.5787
399.052	49.0749
403.528	88.1757
408.004	136.469
412.475	198.728
416.947	252.722
421.414	280.658
425.881	297.053
430.343	305.849
434.806	307.097
439.264	306.374
443.723	298.596
448.177	277.87
452.629	245.635
457.081	215.72
461.528	210.454
465.976	259.374
470.419	272.009
474.862	207.314
479.301	118.282
483.738	95.1556
488.175	108.196
492.607	138.294
497.04	198.73
501.468	279.663
505.894	387.878
510.32	502.723
514.742	606.782
519.164	701.869
523.581	786.325
527.997	840.331
532.412	853.574
536.823	818.699
541.232	769.252
545.641	692.732
550.046	663.601
554.449	669.02
558.851	725.681
563.25	684.527
567.646	638.736
572.042	575.803
576.434	506.422
580.824	440.558
585.214	392.287
589.599	437.523
593.983	547.979
598.367	721.797
602.746	889.263
607.123	838.981
611.498	548.02
615.873	383.466
620.244	264.645
624.613	206.691
628.98	176.361
633.346	154.792
637.709	143.461
642.069	137.011
646.428	142.19
650.786	153.999
655.14	175.563
659.492	205.516
663.842	236.389
668.192	248.711
672.538	234.829
676.882	171.933
681.223	121.187
685.563	74.5405
689.902	50.0144
694.238	31.921
698.571	22.0848
702.902	17.7785
707.231	16.7496
711.559	15.66
715.886	14.3813
720.209	13.0358
724.529	11.6584
728.848	10.2586
733.165	7.83765
737.48	4.231
741.792	-0.667419
746.105	1.38536
750.413	5.7888
754.72	9.03825
759.024	11.1309
763.327	11.6148
767.627	12.5655
771.925	12.0123
776.221	10.4126
780.518	13.8284
784.81	16.6041
789.1	18.5453
793.388	19.1119
797.674	13.7887
801.958	9.88828
806.24	6.23012
810.52	3.34543
814.797	0.658173
819.073	-0.142303
823.347	0.242371
827.619	2.00177
831.888	3.5184
836.156	4.75636
840.422	5.72765
844.685	6.30852
848.947	6.51433
853.206	6.0074
857.464	4.43608
861.719	1.96194
865.973	0.805923
870.224	5.57614
874.474	-0.890427
878.721	-2.15681
882.967	-1.12138
887.21	1.43233
891.452	4.27678
895.691	7.20715
899.929	14.1168
904.164	19.2928
908.397	22.8515
912.629	25.3155
916.858	28.5159
921.086	34.3849
925.311	47.4946
929.534	68.2783
933.756	93.1938
937.975	124.328
942.191	159.714
946.406	198.936
950.619	240.509
954.831	288.015
959.04	345.205
963.248	416.846
967.453	510.495
971.657	610.267
975.858	734.945
980.056	924.26
984.253	1106.7
988.449	1159
992.643	944.117
996.834	716.624
1001.02	586.908
1005.21	558.379
1009.4	616.587
1013.58	695.892
1017.76	941.605
1021.94	1198.2
1026.12	1315.63
1030.29	1278.66
1034.47	1162.21
1038.64	990.863
1042.81	875.716
1046.98	714.48
1051.14	532.104
1055.3	435.409
1059.47	366.367
1063.63	377.926
1067.78	402.617
1071.94	459.958
1076.09	545.834
1080.25	606.751
1084.4	563.711
1088.54	493.12
1092.69	432.215
1096.83	387.483
1100.98	349.119
1105.12	342.695
1109.26	361.535
1113.39	400.208
1117.53	500.232
1121.66	454.499
1125.79	352.633
1129.92	274.341
1134.04	208.247
1138.17	160.233
1142.29	124.805
1146.41	101.482
1150.53	81.9865
1154.65	68.8222
1158.76	58.5738
1162.88	49.9149
1166.99	38.4549
1171.1	28.972
1175.2	20.0463
1179.31	14.1389
1183.41	10.0349
1187.51	7.16847
1191.61	4.97839
1195.71	2.96976
1199.81	1.41135
1203.9	0.652298
1207.99	0.936905
1212.08	0.267914
1216.17	-0.31337
1220.26	-0.737244
1224.34	0.336517
1228.42	2.66838
1232.5	6.31956
1236.58	12.3113
1240.66	20.4349
1244.73	31.0134
1248.81	40.9975
1252.88	48.7022
1256.95	64.2501
1261.02	113.25
1265.08	210.913
1269.14	104.19
1273.2	73.2445
1277.27	105.299
1281.32	603.354
1285.38	2103.41
1289.43	566.465
1293.48	104.985
1297.53	69.229
1301.58	55.8727
1305.63	48.9117
1309.67	47.8823
1313.72	45.9615
1317.76	43.8987
1321.8	43.278
1325.83	44.5161
1329.87	46.0239
1333.9	47.7817
1337.93	49.6761
1341.96	51.7807
1345.99	53.8753
1350.02	56.0143
1354.04	58.7307
1358.06	61.5598
1362.08	64.6636
1366.1	77.5178
1370.12	106.632
1374.13	110.489
1378.14	131.756
1382.16	249.276
1386.16	1924.46
1390.17	2664.47
1394.18	346.52
1398.18	123.387
1402.18	88.4265
1406.18	150.986
1410.18	352.168
1414.18	135.263
1418.17	67.4774
1422.16	58.5299
1426.15	49.1301
1430.14	38.5178
1434.13	29.3808
1438.11	21.7525
1442.1	15.4054
1446.08	10.2363
1450.06	4.90189
1454.04	2.11288
1458.01	1.7281
1461.98	2.858
1465.96	4.91573
1469.93	5.21217
1473.9	6.069
1477.86	2.8587
1481.83	1.88643
1485.79	-0.303329
1489.75	-2.67625
1493.71	-3.57397
1497.67	-3.032
1501.62	-0.845688
1505.58	2.19424
1509.53	4.86992
1513.48	5.46449
1517.43	5.81094
1521.38	6.64993
1525.32	8.14899
1529.26	8.8663
1533.2	8.14972
1537.14	7.88936
1541.08	7.77306
1545.02	7.20479
1548.95	8.50732
1552.88	8.64955
1556.81	7.02966
1560.74	4.8653
1564.67	3.51424
1568.6	2.87451
1572.52	4.52332
1576.44	7.12903
1580.36	9.70995
1584.28	11.2782
1588.19	11.8722
1592.11	11.2487
1596.02	8.64807
1599.93	7.45763
1603.84	6.08304
1607.75	5.80084
1611.65	7.23547
1615.56	5.84241
1619.46	3.18021
1623.36	3.21388
1627.25	7.63332
1631.15	12.4056
1635.05	13.5733
1638.94	14.1815
1642.83	16.8977
1646.72	16.563
1650.61	15.2027
1654.49	12.6661
1658.38	10.7415
1662.26	11.0145
1666.14	13.3846
1670.02	15.3369
1673.89	15.959
1677.77	14.8423
1681.64	13.0328
1685.51	6.57344
1689.38	3.57698
1693.25	1.64418
1697.12	4.05981
1700.98	7.30292
1704.85	10.0747
1708.71	12.488
1712.57	14.4363
1716.42	15.8221
1720.28	16.8454
1724.13	17.4239
1727.99	17.7062
1731.84	17.7567
1735.69	17.5642
1739.53	17.2911
1743.38	16.8643
1747.22	16.4303
1751.06	15.8281
1754.9	18.9681
1758.74	19.8257
1762.58	19.5526
1766.41	19.0256
1770.25	17.3481
1774.08	15.8189
1777.91	15.5262
1781.73	18.1536
1785.56	19.1563
1789.39	18.7108
1793.21	17.8538
1797.03	16.8834
1800.85	15.7678
1804.67	14.5623
1808.48	13.1952
1812.3	11.6446
1816.11	10.0427
1819.92	8.53329
1823.73	6.5379
1827.54	4.33386
1831.34	2.42065
1835.14	1.17072
1838.95	2.15308
1842.75	3.88483
1846.55	6.18658
1850.34	8.92303
1854.14	12.3766
1857.93	15.8372
1861.72	17.2477
1865.51	14.3905
1869.3	10.3084
1873.09	6.21042
1876.87	5.69287
1880.66	5.62036
1884.44	5.93417
1888.22	6.59485
1892	7.41733
1895.77	8.09741
1899.55	7.40036
1903.32	4.76334
1907.09	4.23822
1910.86	5.21036
1914.63	6.61584
1918.4	8.32739
1922.16	9.49741
1925.92	10.3688
1929.68	11.2958
1933.44	12.5125
1937.2	13.0875
1940.96	14.4893
1944.71	12.8412
1948.46	8.41193
1952.22	4.46545
1955.97	1.35617
1959.71	-0.6409
1963.46	-1.64334
1967.2	-1.397
1970.95	0.0965271
1974.69	3.42374
1978.43	7.27173
1982.17	9.0412
1985.9	9.71115
1989.64	10.6996
1993.37	11.637
1997.1	12.6752
2000.83	14.2149
2004.56	16.7302
2008.28	16.9828
2012.01	16.3195
2015.73	15.0389
2019.45	12.7045
2023.17	10.2584
2026.89	8.00104
2030.6	7.30707
2034.32	6.57956
2038.03	6.16733
2041.74	5.83398
2045.45	5.12103
2049.16	4.57938
2052.87	5.3454
2056.57	5.5867
2060.27	2.69937
2063.98	2.11459
2067.67	5.84741
2071.37	8.6835
2075.07	10.6013
2078.76	11.0105
2082.46	8.57965
2086.15	5.48163
2089.84	3.31015
2093.53	1.55829
2097.21	0.710785
2100.9	0.93457
2104.58	2.6889
2108.26	5.49417
2111.94	4.32834
2115.62	3.89752
2119.3	0.340942
2122.97	-2.07803
2126.64	-3.26804
2130.32	-3.33282
2133.99	-2.20831
2137.66	-0.124908
2141.32	2.79156
2144.99	6.03467
2148.65	8.14505
2152.31	8.31631
2155.97	3.78629
2159.63	0.161011
2163.29	2.06171
2166.94	3.05118
2170.6	2.94916
2174.25	2.58859
2177.9	2.38916
2181.55	2.19464
2185.2	2.27399
2188.84	2.82092
2192.49	3.91891
2196.13	5.00146
2199.77	7.61676
2203.41	10.6095
2207.05	11.3093
2210.69	11.8856
2214.32	10.13
2217.95	5.99567
2221.59	2.50168
2225.22	1.84714
2228.84	1.85724
2232.47	1.32352
2236.09	0.83429
2239.72	-0.847443
2243.34	-2.26105
2246.96	2.86536
2250.58	4.78833
2254.2	4.02402
2257.81	2.98788
2261.42	2.08255
2265.04	1.41135
2268.65	1.55392
2272.26	1.44241
2275.86	-0.440125
2279.47	-0.491974
2283.08	-0.240936
2286.68	0.0439453
2290.28	0.221832
2293.88	0.287109
2297.48	0.255127
2301.07	0.0978699
2304.67	-0.183868
2308.26	0.629944
2311.85	-0.454834
2315.44	1.32071
2319.03	13.2189
2322.62	15.9274
2326.2	137.861
2329.79	322.39
2333.37	76.3041
2336.95	10.7708
2340.53	3.79959
2344.11	2.02948
2347.68	3.26495
2351.26	6.96637
2354.83	9.77438
2358.4	11.8694
2361.97	14.0839
2365.54	15.2148
2369.11	16.0055
2372.67	15.308
2376.23	13.7567
2379.8	14.7369
2383.36	16.3186
2386.92	17.5797
2390.47	18.6429
2394.03	19.3625
2397.58	19.7407
2401.14	19.5795
2404.69	19.2764
2408.24	18.8923
2411.78	18.4807
2415.33	18.1296
2418.88	18.757
2422.42	15.5613
2425.96	13.5229
2429.5	18.0803
2433.04	24.5124
2436.58	19.4667
2440.11	15.7078
2443.65	13.8208
2447.18	12.5177
2450.71	10.5181
2454.24	8.8671
2457.77	2.72922
2461.3	4.43246
2464.82	6.07306
2468.34	5.41351
2471.86	2.8703
2475.39	1.84058
2478.9	2.38965
2482.42	4.16708
2485.94	6.76913
2489.45	9.56836
2492.96	11.9057
2496.47	13.9939
2499.98	15.4116
2503.49	15.5494
2507	15.0252
2510.5	15.5027
2514.01	17.0534
2517.51	18.3171
2521.01	19.6526
2524.51	20.8245
2528.01	21.5007
2531.5	21.4861
2535	19.8726
2538.49	17.3086
2541.98	15.9895
2545.47	17.8703
2548.96	18.5409
2552.45	18.6006
2555.93	18.19
2559.42	17.4279
2562.9	16.304
2566.38	14.9083
2569.86	13.5044
2573.34	12.1567
2576.81	11.4366
2580.29	12.0853
2583.76	14.0208
2587.23	12.6495
2590.71	11.9658
2594.17	11.0915
2597.64	6.57394
2601.11	2.82852
2604.57	0.084259
2608.03	-1.68176
2611.5	-1.69635
2614.96	-0.57019
2618.42	1.53888
2621.87	3.65005
2625.33	4.59467
2628.78	4.96008
2632.23	5.31354
2635.68	6.41049
2639.13	8.24353
2642.58	9.96158
2646.03	12.2635
2649.47	14.3408
2652.92	15.7731
2656.36	16.824
2659.8	17.0155
2663.24	16.3438
2666.68	14.7838
2670.11	13.7895
2673.55	14.7522
2676.98	16.8369
2680.41	19.1963
2683.84	24.6663
2687.27	30.1808
2690.7	32.4509
2694.13	30.0606
2697.55	24.6257
2700.97	21.1495
2704.4	21.3331
2707.82	21.8645
2711.23	23.4135
2714.65	24.9944
2718.07	25.0712
2721.48	23.8
2724.9	22.6647
2728.31	18.0579
2731.72	14.4418
2735.12	14.3646
2738.53	15.0651
2741.94	16.0281
2745.34	17.2229
2748.74	18.2051
2752.14	18.9497
2755.54	18.8751
2758.94	17.3038
2762.34	13.8716
2765.73	8.66034
2769.13	4.05618
2772.52	0.709045
2775.91	-0.844971
2779.3	-1.09238
2782.69	1.18756
2786.08	6.0163
2789.46	12.5747
2792.85	17.4294
2796.23	20.2057
2799.61	18.3259
2802.99	14.5452
2806.37	10.4666
2809.74	6.90067
2813.12	6.28372
2816.49	7.93442
2819.86	12.2276
2823.23	17.4662
2826.61	21.0226
2829.97	23.3667
2833.34	24.0698
2836.7	21.6304
2840.07	19.0711
2843.43	17.6449
2846.79	17.1431
2850.15	19.8496
2853.51	20.3718
2856.87	14.2504
2860.22	14.8951
2863.57	16.3185
2866.93	15.9999
2870.28	13.2831
2873.63	2.99588
2876.98	3.47977
2880.32	6.93512
2883.67	9.57654
2887.01	11.2684
2890.35	12.4702
2893.69	13.9942
2897.03	16.6369
2900.37	19.1617
2903.71	21.2203
2907.04	20.5848
2910.38	20.2771
2913.71	35.4499
2917.04	33.9698
2920.37	21.0888
2923.7	12.7227
2927.03	5.61246
2930.35	4.2308
2933.68	3.30344
2937	10.8424
2940.32	17.6084
2943.64	17.3672
2946.96	15.4706
2950.27	11.8269
2953.59	6.24588
2956.91	4.30618
2960.22	2.43204
2963.53	3.24313
2966.84	4.18079
2970.15	6.3364
2973.46	9.86237
2976.76	10.7845
2980.07	10.6178
2983.37	9.75549
2986.67	8.32056
2989.97	6.42392
2993.27	4.03888
2996.57	1.08618
2999.86	-1.22006
3003.16	-0.661621
3006.45	-0.0193176
3009.75	0.279907
3013.03	0.965881
3016.32	1.68863
3019.61	2.56854
3022.9	3.46347
3026.19	4.66595
3029.47	4.69034
3032.75	4.33243
3036.03	3.80502
3039.31	3.60199
3042.59	3.57309
3045.87	3.4382
3049.14	3.35608
3052.42	2.48172
3055.69	1.54846
3058.96	2.47171
3062.23	4.6402
3065.5	7.71051
3068.77	9.17117
3072.03	10.2006
3075.3	11.0752
3078.56	9.3425
3081.82	6.07843
3085.08	2.82086
3088.34	0.207275
3091.6	-1.46921
3094.86	-2.3063
3098.11	-1.91214
3101.36	-0.792084
3104.62	1.26978
3107.87	4.00824
3111.12	7.35199
3114.37	9.44153
3117.61	10.7765
3120.86	9.59842
3124.1	7.74783
3127.34	5.51334
3130.59	2.94827
3133.83	2.0162
3137.07	3.20529
3140.3	4.47717
3143.54	7.87012
3146.77	15.5806
3150.01	24.8327
3153.24	29.7176
3156.47	29.4875
3159.7	22.8803
3162.93	23.5281
3166.15	28.6087
3169.38	31.0572
3172.6	34.2347
3175.83	37.4021
3179.05	38.7207
3182.27	35.9653
3185.49	34.5555
3188.7	36.5353
3191.92	39.6854
3195.13	44.7064
3198.35	45.7563
3201.56	47.5235
3204.77	50.3123
3207.98	52.9957
3211.19	55.2214
3214.39	55.2953
3217.6	58.0458
3220.8	61.3989
3224	70.5682
3227.21	79.8782
3230.41	88.7188
3233.6	98.2366
3236.8	107.914
3240	116.266
3243.19	123.129
3246.39	128.876
3249.58	133.407
3252.77	137.562
3255.96	143.004
3259.15	149.299
3262.33	156.518
3265.52	164.361
3268.7	170.998
3271.89	177.667
3275.07	180.968
3278.25	184.137
3281.43	185.791
3284.6	188.003
3287.78	191.232
3290.95	196.38
3294.13	202.277
3297.3	209.607
3300.47	216.777
3303.64	221.287
3306.81	224.568
3309.98	224.967
3313.14	219.92
3316.31	217.734
3319.47	214.878
3322.63	215.447
3325.79	215.95
3328.95	216.742
3332.11	216.94
3335.27	218.132
3338.42	220.872
3341.58	225.287
3344.73	230.768
3347.88	237.062
3351.03	243.946
3354.18	251.225
3357.33	258.911
3360.47	265.388
3363.62	272.649
3366.76	281.837
3369.91	293.647
3373.05	304.934
3376.19	316.631
3379.32	326.304
3382.46	333.508
3385.6	338.913
3388.73	353.873
3391.87	371.281
3395	387.069
3398.13	407.986
3401.26	436.614
3404.39	466.876
3407.51	485.597
3410.64	504.795
3413.76	512.507
3416.89	513.733
3420.01	508.702
3423.13	501.156
3426.25	489.569
3429.37	457.183
3432.48	464.78
3435.6	462.908
3438.71	456.923
3441.83	449.716
3444.94	445.757
3448.05	444.289
3451.16	447.232
3454.27	450.399
3457.37	457.024
3460.48	471.221
3463.58	485.924
3466.69	512.161
3469.79	546.79
3472.89	583.494
3475.99	622.223
3479.08	665.93
3482.18	701.194
3485.28	712.271
3488.37	723.509
3491.46	723.884
3494.55	718.012
3497.64	705.005
3500.73	684.307
3503.82	663.139
3506.91	642.15
3509.99	613.068
3513.08	596.789
3516.16	578.65
3519.24	558.249
3522.32	537.783
3525.4	516.803
3528.48	495.682
3531.55	469.027
3534.63	421.346
3537.7	385.953
3540.78	359.317
3543.85	344.097
3546.92	328.919
3549.99	316.58
3553.05	304.225
3556.12	294.6
3559.19	289.745
3562.25	286.626
3565.31	282.314
3568.37	273.801
3571.43	264.325
3574.49	251.419
3577.55	232.938
3580.61	214.232
3583.66	197.382
3586.72	183.139
3589.77	171.975
3592.82	163.19
3595.87	159.045
3598.92	158.654
3601.97	151.269
3605.02	168.811
3608.06	166.482
3611.11	162.369
3614.15	156.099
3617.19	147.28
3620.23	144.78
3623.27	145.054
3626.31	147.128
3629.34	150.774
3632.38	154.584
3635.41	156.468
3638.45	151.395
3641.48	143.669
3644.51	133.05
3647.54	124.033
3650.57	113.211
3653.59	100.978
3656.62	90.6841
3659.65	81.7715
3662.67	73.7336
3665.69	67.4875
3668.71	63.8567
3671.73	61.7429
3674.75	58.3649
3677.77	55.0424
3680.78	47.9062
3683.8	36.45
3686.81	28.6769
3689.82	22.0891
3692.84	18.9997
3695.84	15.1791
3698.85	11.9213
3701.86	4.35208
3704.87	5.45203
3707.87	8.18991
3710.88	11.4421
3713.88	14.9919
3716.88	15.5775
3719.88	13.2961
3722.88	9.92422
3725.88	7.3902
3728.88	5.88974
3731.87	5.83908
3734.87	7.1987
3737.86	9.10229
3740.85	9.39484
3743.84	5.69812
3746.83	0.262817
3749.82	-1.1561
3752.81	-0.0809021
3755.79	0.932251
3758.78	2.07178
3761.76	2.6893
3764.74	3.64746
3767.73	4.88922
3770.71	6.48859
3773.68	8.66412
3776.66	8.20859
3779.64	5.21814
3782.61	1.87402
3785.59	-1.40103
3788.56	-3.21301
3791.53	-2.89761
3794.5	-0.829498
3797.47	1.4476
3800.44	3.96234
3803.41	6.27393
3806.37	7.95947
3809.34	9.90311
3812.3	11.326
3815.26	12.3531
3818.22	10.2687
3821.18	8.67099
3824.14	8.57596
3827.1	8.34821
3830.06	4.25552
3833.01	-0.392456
3835.96	-0.983856
3838.92	1.46954
3841.87	4.36877
3844.82	7.27255
3847.77	6.44785
3850.72	3.32318
3853.66	1.33783
3856.61	-0.109253
3859.55	-0.61438
3862.5	-0.316925
3865.44	0.720978
3868.38	1.08035
3871.32	-3.03342
3874.26	-7.38898
3877.2	-6.37354
3880.13	-1.30133
3883.07	2.76923
3886	4.48941
3888.94	5.2998
3891.87	4.93954
3894.8	3.66803
3897.73	1.89594
3900.66	-2.22406
3903.58	-3.591
3906.51	-3.34235
3909.43	-2.61768
3912.36	-2.09348
3915.28	-1.4787
3918.2	-0.637604
3921.12	-0.412231
3924.04	-1.62048
3926.96	-4.54849
3929.87	-5.1593
3932.79	-4.38647
3935.7	-1.79852
3938.62	0.463013
3941.53	1.59924
3944.44	3.5661
3947.35	5.34427
3950.26	6.62405
3953.17	7.05307
3956.07	6.78806
3958.98	5.94574
3961.88	3.79105
3964.78	2.38318
3967.69	2.83685
3970.59	3.63138
3973.49	2.96713
3976.38	1.72983
3979.28	3.82373
3982.18	5.91055
3985.07	8.15298
3987.97	7.69843
3990.86	7.14285
3993.75	2.26126
3996.64	1.12399
3999.53	-1.10394