File: Data/3-Raman/processed/bu32-AII-incC-fi01-s_150 (500nm)_532nm_edge_100%_x100_vis_lwd_h30um_15sx2_01.txt
#Acq. time (s)=	15
#Accumulations=	2
#Range (cm-¹)=	99...4000
#Windows=	1
#Auto scanning=	Off
#Autofocus=	Off
#Macrospot=	Off
#AutoExposure=	Off
#Spike filter=	Multiple accum.
#Delay time (s)=	2
#Binning=	1
#Readout mode=	Signal
#DeNoise=	Off
#ICS correction=	On
#Dark correction=	Off
#Inst. Process=	Off
#Detector Gain=	Best Dynamic
#Detector ADC=	50 kHz HS
#Detector temperature (°C)=	-60.09
#Instrument=	LabRAM HR Evol
#Detector=	SIN-EM FIVIS
#Objective=	x100_VIS_LWD
#Grating=	150 (500nm)
#ND Filter=	100%
#Laser=	532nm_Edge
#Hole=	30.0125
#Temperature=	0
#Range=	Visible
#StageXY=	75x50mm Scan+
#StageZ=	Z motor
#X (µm)=	0
#Y (µm)=	0
#Z (µm)=	0.8
#Full time(s)=	34
#Project=	21_11_26
#Sample=	BU32
#Site=
#Title=	BU32-A-incC-FI01-S_150 (500nm)_532nm_Edge_100%_x100_VIS_LWD_H30um_15sX2
#Remark=
#Date=	26.11.2021 17:30
#Acquired=	26.11.2021 17:30:30
#Base:Fit=	16.12.2021 14:32:39
#Base:Sub=	16.12.2021 14:32:41
#Correction:Norma=	16.12.2021 14:36:20
#Data Range:Extract=	16.12.2021 14:36:58
#Math:AB=	16.12.2021 14:37:13
102.91	0.0227406
107.534	-0.179717
112.156	0.00336297
116.775	-0.104505
121.392	-0.624178
126.005	-0.338103
130.617	0.130596
135.227	-1.28041
139.835	-0.839967
144.439	-0.3578
149.042	-0.719763
153.643	-0.948761
158.242	-0.287832
162.839	1.30828
167.431	1.5977
172.023	2.64451
176.613	3.3351
181.198	2.1429
185.783	1.7523
190.366	1.26172
194.947	1.02068
199.524	0.701163
204.1	1.30304
208.674	1.17857
213.243	1.07126
217.813	1.26902
222.38	1.14452
226.945	0.588753
231.506	0.355738
236.066	0.204391
240.625	1.97551
245.179	1.79004
249.732	1.32037
254.284	2.80189
258.831	4.9621
263.378	8.47959
267.923	15.5507
272.464	24.5975
277.004	25.9797
281.54	19.8494
286.076	12.0603
290.61	7.52688
295.139	4.07801
299.669	3.01817
304.196	2.08701
308.718	1.81033
313.241	1.09427
317.759	1.261
322.278	1.02594
326.794	2.12598
331.305	1.58309
335.817	3.40729
340.324	3.45056
344.832	0.808702
349.334	0.467668
353.837	0.241259
358.338	0.566515
362.834	0.728168
367.33	-0.301399
371.822	-0.107592
376.314	-0.903864
380.802	-0.388079
385.289	-0.659803
389.772	-0.313433
394.255	-0.437127
398.734	-0.320273
403.213	-0.660404
407.688	-0.483327
412.162	-0.0921376
416.632	-0.444513
421.102	-0.259656
425.568	-0.809017
430.033	-0.831255
434.495	-0.967793
438.956	-1.61396
443.413	-1.28565
447.87	-1.39744
452.323	-1.35337
456.776	-0.950502
461.224	-1.52553
465.673	-1.26096
470.117	-1.85204
474.561	-1.73439
479.001	-1.38282
483.438	-1.01101
487.876	-1.14082
492.309	-1.24177
496.742	-0.278951
501.172	-1.02277
505.601	-0.116862
510.025	-0.464643
514.448	-0.315525
518.871	0.614886
523.289	-0.463352
527.707	-1.10821
532.121	-0.507817
536.533	-0.518774
540.945	-0.376092
545.353	-0.564834
549.758	-0.641316
554.164	-1.67144
558.565	-1.68959
562.965	-1.32864
567.364	-0.831478
571.759	-0.320699
576.151	-0.152045
580.544	1.18761
584.933	0.903661
589.319	1.93504
593.706	1.16708
598.088	1.86767
602.468	0.805015
606.848	0.987086
611.224	1.66593
615.598	0.730574
619.972	1.09561
624.341	0.817563
628.709	0.486394
633.074	0.0909495
637.44	0.0413845
641.801	-0.0667191
646.16	0.737907
650.517	0.197901
654.874	0.187894
659.227	0.565738
663.578	0.675056
667.927	-0.129284
672.275	0.949276
676.62	0.182911
680.962	-0.0801237
685.302	-0.0392516
689.643	-0.1245
693.979	-0.130527
698.313	-0.15911
702.645	0.293496
706.975	0.218813
711.305	1.15015
715.631	2.93944
719.955	2.0283
724.276	2.20474
728.596	0.582701
732.913	1.18651
737.231	-0.286052
741.544	0.0263865
745.856	0.032845
750.165	-0.0964338
754.472	-0.165059
758.778	-0.387362
763.081	0.085658
767.384	-0.287525
771.683	-0.507812
775.98	0.281163
780.275	-0.883489
784.568	0.513486
788.859	-0.31333
793.147	-0.346391
797.434	0.0259819
801.719	0.184826
806.004	-0.309774
810.284	0.189862
814.563	-0.111585
818.839	-0.11692
823.114	-0.265105
827.386	-0.0172849
831.657	-0.999357
835.925	-0.138992
840.192	-0.0983661
844.456	-0.472171
848.719	0.277252
852.979	-0.0232968
857.237	-0.325539
861.493	-0.637865
865.748	-0.106566
870	-0.11433
874.25	-0.360791
878.499	0.177727
882.745	-0.0890386
886.989	-0.150593
891.231	-0.506051
895.471	-0.108719
899.71	-0.259947
903.946	0.0413679
908.18	-0.275444
912.412	-0.753788
916.642	-0.0135481
920.87	0.359964
925.096	0.311819
929.321	0.610083
933.543	-0.694297
937.763	0.539867
941.981	0.159723
946.197	-0.888752
950.412	-1.57951
954.622	-0.856106
958.832	-2.5062
963.04	-2.2111
967.246	-2.93661
971.451	0
975.653	-1.12271
979.853	0.509254
984.052	-0.788551
988.248	-0.991688
992.442	-0.235577
996.633	-1.57288
1000.82	-0.823769
1005.01	-1.76643
1009.2	-0.304911
1013.38	-0.910307
1017.57	-1.10264
1021.75	-0.0539999
1025.92	0.239509
1030.1	0.0252495
1034.27	0.155036
1038.45	-0.31438
1042.62	0.815218
1046.78	0.923733
1050.95	0.934465
1055.12	2.11904
1059.28	2.92669
1063.44	5.18963
1067.6	9.67987
1071.75	24.9918
1075.91	49.971
1080.06	47.23
1084.21	19.1238
1088.36	5.74035
1092.51	3.44868
1096.65	0.697022
1100.8	1.17824
1104.94	0.0524607
1109.08	-0.610678
1113.21	0.400523
1117.35	0.231931
1121.48	0.177344
1125.61	0.06953
1129.74	0.695746
1133.87	0.590663
1137.99	-0.0702424
1142.12	-0.137531
1146.24	-0.386885
1150.36	-1.10197
1154.48	-0.38311
1158.59	-0.763112
1162.71	-0.224232
1166.82	-0.21579
1170.93	-0.534677
1175.04	-0.863745
1179.14	-0.237735
1183.25	-0.378208
1187.35	-0.390009
1191.45	0.111391
1195.55	-0.206309
1199.65	0.27695
1203.74	-0.248053
1207.83	0.15472
1211.92	-0.339581
1216.01	0.0407373
1220.1	0.21328
1224.19	0.445302
1228.27	-0.170259
1232.35	0.0324664
1236.43	-0.0692828
1240.51	0.602513
1244.58	-0.105524
1248.66	0.0278431
1252.73	-0.0267633
1256.8	-0.0878466
1260.87	0.154185
1264.93	0.375575
1269	-0.539043
1273.06	-0.466646
1277.12	0.126729
1281.18	0.229
1285.23	0.366989
1289.29	0.0232715
1293.34	0.23758
1297.39	0.368472
1301.44	0.205088
1305.49	0.125651
1309.53	-0.203837
1313.58	0.119427
1317.62	0.22424
1321.66	0.554613
1325.7	-0.0154491
1329.73	-0.207591
1333.77	-0.0555366
1337.8	0.420418
1341.83	0.161789
1345.86	0.165283
1349.88	0.313811
1353.91	0.0346506
1357.93	-0.359653
1361.95	0.345861
1365.97	0.170827
1369.99	-0.487624
1374	0.344319
1378.02	0.177709
1382.03	0.659048
1386.04	0.737514
1390.05	0.0433685
1394.05	1.03955
1398.06	0.864868
1402.06	1.34232
1406.06	0.669865
1410.06	1.63664
1414.05	1.29679
1418.05	1.80761
1422.04	0.747031
1426.03	0.851192
1430.02	0.466034
1434.01	1.13907
1438	0.884486
1441.98	0.462538
1445.96	0.737718
1449.94	1.35161
1453.92	0.111792
1457.9	0.36509
1461.87	1.02082
1465.85	0.169907
1469.82	0.0128559
1473.78	-0.289532
1477.75	0.66482
1481.72	0.184577
1485.68	-0.36617
1489.65	0.765203
1493.61	0.129232
1497.56	0.6061
1501.52	0.428019
1505.47	0.173477
1509.43	0.129172
1513.38	0.215735
1517.33	0.526213
1521.27	0.593398
1525.22	0.673923
1529.16	0.556335
1533.11	0.279829
1537.05	0.349603
1540.98	-0.020082
1544.92	0.594802
1548.86	0.234813
1552.79	0.232834
1556.72	0.201256
1560.65	0.684179
1564.58	0.752667
1568.5	0.631343
1572.43	0.296828
1576.35	0.631213
1580.27	0.184174
1584.19	0.0314483
1588.1	0.580638
1592.02	0.49019
1595.93	-0.304897
1599.84	0.264074
1603.75	-0.177048
1607.66	0.785471
1611.57	0.557241
1615.47	0.518926
1619.37	0.581068
1623.27	-0.0356654
1627.17	0.833366
1631.07	0.12143
1634.97	0.198501
1638.86	0.317266
1642.75	0.559567
1646.64	0.0413958
1650.53	0.342665
1654.42	0.106
1658.3	0.590931
1662.18	0.850114
1666.07	0.932131
1669.94	-0.0984319
1673.82	0.250077
1677.7	0.666109
1681.57	0.471284
1685.44	0.278842
1689.31	0.680019
1693.18	-0.265376
1697.05	1.04441
1700.92	0.748989
1704.78	0.696842
1708.64	1.02921
1712.5	1.88218
1716.36	2.46153
1720.21	2.69559
1724.07	1.28407
1727.92	1.25025
1731.77	1.0069
1735.62	0.643774
1739.47	1.09175
1743.32	0.819276
1747.16	0.774511
1751.01	0.42288
1754.85	0.508112
1758.69	0.704888
1762.52	1.13953
1766.36	0.539985
1770.19	0.841987
1774.02	0.773088
1777.85	0.445542
1781.68	0.448743
1785.51	0.646972
1789.33	0.57417
1793.16	0.433629
1796.98	0.51947
1800.8	0.713969
1804.62	0.520864
1808.43	0.0643943
1812.25	0.629883
1816.06	1.11015
1819.87	1.21168
1823.68	0.490036
1827.49	0.747759
1831.3	0.590227
1835.1	0.776042
1838.9	0.9938
1842.71	0.866311
1846.51	0.739562
1850.3	0.50054
1854.1	0.757805
1857.89	0.329852
1861.69	0.698973
1865.48	0.79341
1869.27	0.57034
1873.05	0.288158
1876.84	-0.0888372
1880.62	0.592791
1884.4	0.374285
1888.19	-0.571548
1891.96	0.902016
1895.74	0.342461
1899.52	0.365078
1903.29	1.12234
1907.06	0.761348
1910.83	-0.148394
1914.6	0.352457
1918.37	0.438221
1922.13	-0.0513482
1925.9	0.0485455
1929.66	0.82778
1933.42	0.858328
1937.18	0.597078
1940.94	0.205705
1944.69	1.15716
1948.44	0.20296
1952.2	0.402932
1955.95	1.00004
1959.69	1.0268
1963.44	1.06016
1967.19	0.407925
1970.93	0.0506701
1974.67	0.39864
1978.41	0.530493
1982.15	0.869955
1985.89	0.777375
1989.62	0.291701
1993.35	0.846916
1997.09	0.779931
2000.82	0.828121