File: Data/3-Raman/processed/bu32-AII-incC-fi02-v_1800 (450-850nm)_532nm_edge_100%_x100_vis_lwd_h30um_40sx2_01.txt
#Acq. time (s)=	40
#Accumulations=	2
#Range (cm-¹)=	1200...2365
#Windows=	3
#Auto scanning=	Off
#Autofocus=	Off
#Macrospot=	Off
#AutoExposure=	Off
#Spike filter=	Multiple accum.
#Delay time (s)=	2
#Binning=	1
#Readout mode=	Signal
#DeNoise=	Off
#ICS correction=	On
#Dark correction=	Off
#Inst. Process=	Off
#Detector Gain=	Best Dynamic
#Detector ADC=	50 kHz EM
#Detector EM gain=	400
#Detector temperature (°C)=	-60.09
#Instrument=	LabRAM HR Evol
#Detector=	SIN-EM FIVIS
#Objective=	x100_VIS_LWD
#Grating=	1800 (450-850nm)
#ND Filter=	100%
#Laser=	532nm_Edge
#Hole=	30.0125
#Temperature=	0
#Range=	Visible
#StageXY=	75x50mm Scan+
#StageZ=	Z motor
#X (µm)=	0
#Y (µm)=	0
#Z (µm)=	1.4
#Full time(mm:ss)=	4:20
#Project=	21_11_26
#Sample=	BU32
#Site=
#Title=	BU32-A-incC-FI02-V_1800 (450-850nm)_532nm_Edge_100%_x100_VIS_LWD_H30um_40sX2
#Remark=
#Date=	26.11.2021 17:41
#Acquired=	26.11.2021 17:41:20
#Base:Fit=	16.12.2021 14:33:36
#Base:Fit=	16.12.2021 14:33:39
#Base:Sub=	16.12.2021 14:33:41
1202.72	8.15915
1203.84	-1.07523
1204.95	-15.0756
1206.06	-6.8017
1207.17	20.5488
1208.28	-11.7652
1209.39	-6.58746
1210.5	21.258
1211.61	29.3766
1212.72	-11.4872
1213.83	20.3171
1214.94	6.64911
1216.05	-3.85242
1217.16	4.28073
1218.27	-1.27805
1219.38	-18.3014
1220.49	5.06943
1221.6	31.6404
1222.71	4.78696
1223.81	21.1317
1224.92	-19.2826
1226.03	0.993073
1227.14	3.21481
1228.25	-2.79004
1229.35	-16.1709
1230.46	9.30157
1231.57	5.16559
1232.67	3.24557
1233.78	10.6911
1234.89	4.7236
1235.99	-33.8139
1237.1	23.0373
1238.2	5.86697
1239.31	8.70013
1240.41	-18.5251
1241.52	-18.3144
1242.62	-13.0502
1243.73	12.4005
1244.83	-2.11121
1245.94	1.87521
1247.04	-35.8655
1248.14	-23.23
1249.25	-0.267212
1250.35	-10.5693
1251.45	2.82846
1252.56	12.0984
1253.66	-10.9818
1254.76	-13.7286
1255.87	-3.06042
1256.97	-8.03226
1258.07	-1.69772
1259.17	16.0038
1260.27	15.3938
1261.37	30.7443
1262.48	1.52875
1263.58	-15.0248
1264.68	90.9777
1265.78	20.6484
1266.88	19.7752
1267.98	0.475189
1269.08	6.41238
1270.18	-19.6074
1271.28	-7.23846
1272.38	-3.89066
1273.47	-1.15741
1274.57	-4.80246
1275.67	-0.391418
1276.77	-23.0149
1277.87	23.6944
1278.97	2.16479
1280.07	-4.95212
1281.16	-1.61945
1282.26	0.925903
1283.36	13.5433
1284.45	318.309
1285.55	524.053
1286.65	43.916
1287.75	-7.66986
1288.84	12.3964
1289.94	8.59991
1291.03	13.0984
1292.13	3.74805
1293.22	10.2194
1294.32	17.2188
1295.42	12.2198
1296.51	-11.0509
1297.61	15.4902
1298.7	27.0517
1299.79	12.2266
1300.89	-4.36481
1301.98	33.8879
1303.08	-23.9153
1304.17	3.57721
1305.26	-1.56152
1306.35	-3.82858
1307.45	8.93451
1308.54	-7.73132
1309.63	-12.7078
1310.73	5.4744
1311.82	18.3835
1312.91	-1.29865
1314	10.3723
1315.09	-10.52
1316.18	-9.08221
1317.28	-21.6344
1318.37	0.850922
1319.46	-8.45313
1320.55	3.35803
1321.64	2.21289
1322.73	10.4807
1323.82	6.30603
1324.91	-0.867188
1326	7.49094
1327.09	19.6474
1328.18	9.99536
1329.27	2.22076
1330.35	-24.0183
1331.44	-5.16629
1332.53	12.3606
1333.62	6.76126
1334.71	3.35391
1335.79	21.0508
1336.88	6.30566
1337.97	11.5754
1339.06	15.6383
1340.14	9.5264
1341.23	-0.728027
1342.32	5.59241
1343.4	17.987
1344.49	9.76865
1345.58	10.8126
1346.66	-5.21573
1347.75	12.2366
1348.83	2.85696
1349.92	24.6341
1351	-3.59747
1352.09	-3.69681
1353.17	0.889038
1354.25	13.9593
1355.34	14.2563
1356.42	1.92853
1357.51	-2.2326
1358.59	1.85959
1359.67	17.3273
1360.76	-6.70502
1361.84	3.71567
1362.92	-8.67352
1364	-15.6184
1365.09	11.4706
1366.17	-2.14093
1367.25	18.2979
1368.33	41.2016
1369.41	6.34149
1370.5	30.1871
1371.58	3.16376
1372.66	2.78104
1373.74	-7.61243
1374.82	2.74689
1375.9	12.1815
1376.98	-1.21176
1378.06	0.884766
1379.14	-31.3165
1380.22	33.5986
1381.3	11.3206
1382.38	33.6816
1383.46	-0.5961
1384.54	43.443
1385.61	49.1426
1386.69	53.7762
1387.77	703.266
1388.85	373.93
1389.93	53.1896
1391	39.3739
1392.08	19.7362
1393.16	26.7561
1394.23	4.2518
1395.31	14.6269
1396.39	20.0303
1397.46	2.5965
1398.54	7.79074
1399.62	8.11353
1400.69	5.33554
1401.77	0.551453
1402.84	18.7209
1403.92	6.92932
1404.99	-2.41495
1406.07	23.1314
1407.14	3.69699
1408.22	31.6439
1409.29	170.371
1410.37	54.7334
1411.44	12.4382
1412.51	12.5179
1413.59	18.8675
1414.66	2.13327
1415.73	0.401184
1416.81	7.85806
1417.88	15.3766
1418.95	23.8164
1420.02	29.0026
1421.1	15.4836
1422.17	4.36032
1423.24	15.5823
1424.31	14.4473
1425.38	-2.82867
1426.45	-4.63617
1427.52	9.48831
1428.59	-7.11551
1429.67	15.6611
1430.74	29.4617
1431.81	15.744
1432.87	6.43454
1433.95	-6.28201
1435.01	2.1767
1436.08	13.5803
1437.15	0.279175
1438.22	5.43536
1439.29	52.8226
1440.36	27.6343
1441.43	24.7977
1442.49	4.37589
1443.56	39.3455
1444.63	44.516
1445.7	38.8124
1446.77	40.8571
1447.83	18.2745
1448.9	16.4668
1449.97	23.7094
1451.03	31.8437
1452.1	22.6033
1453.17	18.6087
1454.23	1.37061
1455.3	22.9826
1456.36	1.66971
1457.43	31.3493
1458.49	15.0107
1459.56	3.92386
1460.62	10.133
1461.69	-10.3989
1462.75	-9.508
1463.82	19.9359
1464.88	-17.3934
1465.94	12.3104
1467.01	17.4023
1468.07	34.7906
1469.13	-7.99359
1470.2	-3.01962
1471.26	5.05228
1472.32	14.124
1473.39	14.1671
1474.45	5.94769
1475.51	-10.1687
1476.57	-25.4515
1477.63	4.99426
1478.69	-2.15582
1479.76	-5.33804
1480.82	16.7052
1481.88	14.6377
1482.94	7.90125
1484	6.04181
1485.06	-10.8393
1486.12	-4.76602
1487.18	4.49313
1488.24	1.36319
1489.3	10.2706
1490.36	0.14859
1491.42	9.15057
1492.48	8.19809
1493.53	3.19318
1494.59	-1.77753
1495.65	-15.9792
1496.71	-17.2333
1497.77	-2.09824
1498.82	-9.08862
1499.88	-15.9809
1500.94	10.3869
1502	3.26608
1503.05	-4.85229
1504.11	11.1911
1505.17	6.27747
1506.22	9.05856
1507.28	-5.93387
1508.34	-9.87338
1509.39	1.30478
1510.45	0.441956
1511.5	6.24481
1512.56	9.63364
1513.61	1.27756
1514.67	-8.44907
1515.72	-4.65494
1516.78	5.13168
1517.83	-11.8852
1518.88	7.39114
1519.94	11.5915
1520.99	12.6321
1522.05	8.77246
1523.1	3.68399
1524.15	22.3896
1525.2	10.2912
1526.26	11.5322
1527.31	-8.23398
1528.36	20.7749
1529.41	-12.3374
1530.47	-10.3532
1531.52	-4.02847
1532.57	-18.0262
1533.62	16.5194
1534.67	9.63934
1535.72	7.54385
1536.77	13.1266
1537.82	3.80447
1538.87	2.66388
1539.92	6.28729
1540.97	-13.0832
1542.02	1.81204
1543.07	12.5488
1544.12	-3.79541
1545.17	1.50906
1546.22	-11.0812
1547.27	9.11078
1548.32	17.0125
1549.37	-6.14279
1550.42	-5.93961
1551.46	15.2552
1552.51	2.29465
1553.56	15.1506
1554.61	-3.09073
1555.65	34.7387
1556.7	17.7574
1557.75	-6.14771
1558.79	-15.3621
1559.84	2.3255
1560.89	28.2066
1561.93	-5.62799
1562.98	-5.35916
1564.02	0.652405
1565.07	30.0396
1566.11	-1.06412
1567.16	16.4875
1568.2	1.86276
1569.25	19.0259
1570.29	15.9199
1571.34	-7.99496
1572.38	3.91071
1573.43	7.76257
1574.47	0.816925
1575.51	17.2307
1576.56	21.3605
1577.6	-8.94949
1578.64	15.6537
1579.69	18.699
1580.73	14.9016
1581.77	24.783
1582.81	10.7019
1583.85	19.6757
1584.9	-18.0754
1585.94	19.8377
1586.98	19.6331
1588.02	8.62811
1589.06	19.7855
1590.1	-0.898285
1591.14	-16.6486
1592.18	4.27243
1593.22	20.9298
1594.26	2.5881
1595.3	0.749939
1596.34	-18.1612
1597.38	-9.0997
1598.42	33.717
1599.46	17.5757
1600.5	12.4472
1601.54	12.1309
1602.58	0.958282
1603.62	8.64359
1604.66	28.4227
1605.69	-9.03073
1606.73	-5.81851
1607.77	19.7443
1608.81	2.10349
1609.84	12.7367
1610.88	2.7811
1611.92	4.59143
1612.95	5.78903
1613.99	-19.9544
1615.03	6.57568
1616.06	1.84039
1617.1	6.20547
1618.13	-3.96893
1619.17	-0.161591
1620.2	-4.4946
1621.24	-5.07208
1622.27	-1.19418
1623.31	9.12601
1624.34	1.54797
1625.38	0.323761
1626.41	9.43604
1627.45	-5.19855
1628.48	2.99622
1629.51	6.98145
1630.55	-15.6106
1631.53	16.6254
1632.57	-17.6006
1633.62	-4.72754
1634.66	-0.606537
1635.71	7.34076
1636.75	-2.57422
1637.8	6.1792
1638.84	-8.60202
1639.89	9.21005
1640.93	31.0263
1641.98	-8.2608
1643.02	5.54169
1644.06	-13.1227
1645.11	17.322
1646.15	-9.03979
1647.19	-1.20975
1648.24	23.3565
1649.28	7.06534
1650.32	35.6964
1651.37	12.5077
1652.41	-7.03259
1653.45	4.80588
1654.49	37.5021
1655.53	31.8578
1656.57	5.71429
1657.62	-5.03656
1658.66	22.5638
1659.7	2.72018
1660.74	15.5813
1661.78	-1.80994
1662.82	4.61868
1663.86	26.4985
1664.9	-7.22644
1665.94	15.0982
1666.98	0.862305
1668.02	6.68918
1669.06	-2.0199
1670.1	-7.58728
1671.14	-2.28458
1672.18	11.5904
1673.21	4.81253
1674.25	7.96786
1675.29	10.2574
1676.33	14.4048
1677.37	11.5739
1678.4	1.60693
1679.44	-1.49094
1680.48	-8.43542
1681.52	9.33109
1682.55	16.3409
1683.59	10.4926
1684.63	12.48
1685.66	-1.31168
1686.7	15.6161
1687.73	-2.95813
1688.77	17.7278
1689.81	2.76859
1690.84	4.75363
1691.88	-13.7606
1692.91	24.787
1693.95	-10.9699
1694.98	2.66675
1696.01	8.73544
1697.05	10.9135
1698.08	-1.09003
1699.12	-5.16348
1700.15	7.71848
1701.18	13.6312
1702.22	-3.16699
1703.25	16.3736
1704.28	4.59525
1705.32	-2.10791
1706.35	21.4955
1707.38	4.56134
1708.41	3.28784
1709.44	9.80933
1710.48	10.8121
1711.51	7.12476
1712.54	14.1063
1713.57	16.5909
1714.6	-1.27362
1715.63	-26.5702
1716.66	1.85513
1717.69	9.31778
1718.72	-0.90802
1719.75	16.5876
1720.78	25.4358
1721.81	-9.80496
1722.84	22.0317
1723.87	-8.24356
1724.9	13.109
1725.93	1.07663
1726.96	8.80157
1727.99	-1.85754
1729.02	-8.24362
1730.05	-3.65619
1731.07	20.3744
1732.1	-0.349335
1733.13	-12.9517
1734.16	13.7186
1735.18	-17.4688
1736.21	0.604767
1737.24	1.50616
1738.26	-12.0587
1739.29	5.0441
1740.32	6.52258
1741.34	3.33899
1742.37	4.15305
1743.4	5.10275
1744.42	18.4191
1745.45	-8.33908
1746.47	-1.6745
1747.5	3.78571
1748.52	6.53821
1749.55	-10.4661
1750.57	-2.44849
1751.6	11.1844
1752.62	-9.11209
1753.64	-24.5688
1754.67	-9.46158
1755.69	-0.965729
1756.71	-4.98395
1757.74	13.7797
1758.76	15.8983
1759.78	-1.09698
1760.81	10.3233
1761.83	3.53281
1762.85	3.60541
1763.87	8.49884
1764.89	3.15314
1765.92	0.550781
1766.94	5.38184
1767.96	0.612793
1768.98	-10.8537
1770	3.82861
1771.02	1.25903
1772.04	-2.16348
1773.06	-3.77371
1774.08	19.3156
1775.1	25.2422
1776.12	19.9765
1777.14	1.00522
1778.16	-2.93069
1779.18	-9.78561
1780.2	-10.7015
1781.22	-0.0263672
1782.24	0.166809
1783.26	10.9707
1784.28	7.43234
1785.29	-0.825897
1786.31	-15.1321
1787.33	6.11105
1788.35	24.0755
1789.37	-22.2195
1790.38	58.6718
1791.4	-17.9626
1792.42	-11.4227
1793.43	0.265259
1794.45	29.1724
1795.47	-1.09952
1796.48	0.330841
1797.5	15.1007
1798.51	8.63705
1799.53	15.4212
1800.55	6.6196
1801.56	7.56204
1802.58	0.0322876
1803.59	-3.48419
1804.61	-9.01813
1805.62	23.1174
1806.64	23.4927
1807.65	15.0009
1808.66	1.61121
1809.68	16.2034
1810.69	9.58365
1811.7	7.69049
1812.72	-4.70856
1813.73	-0.592499
1814.74	-2.13324
1815.76	27.1985
1816.77	2.22714
1817.78	-4.65967
1818.79	-11.2899
1819.8	16.9176
1820.82	1.68857
1821.83	16.4503
1822.84	13.7742
1823.85	6.10803
1824.86	18.7837
1825.87	-1.34531
1826.88	5.53082
1827.89	9.5824
1828.9	-0.0419922
1829.91	27.0441
1830.92	23.1019
1831.93	44.623
1832.94	27.4811
1833.95	16.0229
1834.96	40.078
1835.97	20.2297
1836.98	10.9352
1837.99	20.5577
1839	7.05179
1840	13.4092
1841.01	-4.61661
1842.02	13.1903
1843.03	18.7456
1844.04	-24.5952
1845.04	2.49237
1846.05	7.4838
1847.06	11.7503
1848.07	3.888
1849.07	-3.6846
1850.08	-8.6842
1851.09	-0.371948
1852.09	14.8375
1853.1	9.11942
1854.1	-3.43286
1855.11	27.9258
1856.11	12.313
1857.12	-0.128479
1858.12	-4.02213
1859.13	27.3386
1860.13	11.8494
1861.14	15.8845
1862.14	12.3092
1863.15	18.8366
1864.15	18.5854
1865.15	-6.44461
1866.16	17.037
1867.16	-11.1047
1868.16	26.5791
1869.17	4.72906
1870.17	5.6745
1871.17	0.922089
1872.17	10.3535
1873.18	-3.09332
1874.18	1.57376
1875.18	14.5961
1876.18	-5.74393
1877.18	-8.87494
1878.18	-16.8426
1879.19	15.9016
1880.19	1.08466
1881.19	12.459
1882.19	7.27884
1883.19	0.956696
1884.19	-4.0614
1885.19	6.53061
1886.19	-11.8659
1887.19	0.414825
1888.19	-2.68427
1889.19	-5.90363
1890.19	28.7902
1891.19	-3.90155
1892.18	-2.03955
1893.18	-2.13708
1894.18	15.2641
1895.18	-5.51517
1896.18	10.6149
1897.18	4.30646
1898.17	-4.96255
1899.17	8.05606
1900.17	-1.52411
1901.16	8.84732
1902.16	-8.70587
1903.16	-4.77478
1904.16	6.43042
1905.15	-11.4428
1906.15	8.21088
1907.14	-15.4606
1908.14	-3.16559
1909.14	-1.09872
1910.13	3.01028
1911.13	7.22876
1912.12	-8.64258
1913.12	-10.5351
1914.11	0.0276184
1915.11	4.16742
1916.1	20.3786
1917.1	-1.44418
1918.09	-2.50516
1919.08	1.52673
1920.08	-7.41397
1921.07	-0.696869
1922.06	27.9841
1923.06	-4.17352
1924.05	7.07428
1925.04	7.897
1926.04	-9.79144
1927.03	8.59412
1928.02	-7.25278
1929.01	-11.8123
1930	15.043
1931	18.302
1931.99	-4.47632
1932.98	-4.62234
1933.97	-0.731354
1934.96	-10.2104
1935.95	-6.61096
1936.94	2.64835
1937.93	19.5356
1938.92	0.516113
1939.91	-2.11499
1940.9	10.5436
1941.89	-13.9153
1942.88	28.2613
1943.87	16.6435
1944.86	22.6575
1945.85	19.2147
1946.84	16.6177
1947.83	-8.25916
1948.82	7.0369
1949.8	6.3338
1950.79	-3.69946
1951.78	0.677582
1952.77	0.0230713
1953.76	9.70477
1954.74	15.7359
1955.73	9.84546
1956.72	-7.77832
1957.7	11.7741
1958.69	4.29456
1959.68	30.1658
1960.66	-0.710938
1961.65	8.69531
1962.63	8.73996
1963.62	23.2294
1964.61	8.97327
1965.59	5.12943
1966.58	4.38385
1967.56	4.57779
1968.55	18.1323
1969.53	23.7466
1970.52	7.07581
1971.5	22.263
1972.48	-2.64651
1973.47	3.07269
1974.45	-1.89331
1975.44	19.2579
1976.42	6.04474
1977.4	4.18604
1978.39	19.3937
1979.37	1.10815
1980.35	25.1371
1981.33	2.94727
1982.31	13.3974
1983.3	9.397
1984.28	13.0255
1985.26	28.2012
1986.24	-3.42224
1987.22	7.24268
1988.21	5.12198
1989.19	18.5334
1990.17	4.17578
1991.15	15.9217
1992.13	-1.58551
1993.11	7.38724
1994.09	8.09311
1995.07	12.8098
1996.05	15.4846
1997.03	12.8958
1998.01	4.53577
1998.99	-3.23108
1999.97	14.2848
2000.95	1.05658
2001.92	8.26303
2002.9	5.01321
2003.88	4.29312
2004.86	7.2291
2005.84	14.0379
2006.81	13.7404
2007.79	-3.13754
2008.77	9.63638
2009.75	0.46875
2010.73	9.12326
2011.7	0.174957
2012.68	4.79865
2013.67	-7.7688
2014.66	11.4669
2015.64	-0.842133
2016.63	3.09082
2017.62	9.92346
2018.61	14.1987
2019.6	-17.1982
2020.58	-6.0593
2021.57	2.41437
2022.56	-11.6887
2023.55	-4.4635
2024.54	0.904205
2025.52	12.6403
2026.51	-11.8548
2027.5	3.96893
2028.48	-4.78662
2029.47	0.435394
2030.45	9.73615
2031.44	-9.67651
2032.43	8.14633
2033.41	20.7598
2034.4	9.62039
2035.38	-9.52536
2036.37	18.3137
2037.35	-2.32489
2038.34	2.2915
2039.32	4.9238
2040.31	19.6103
2041.29	5.31561
2042.27	-11.5796
2043.26	-3.29181
2044.24	-6.61081
2045.23	22.1353
2046.21	-2.33582
2047.19	10.4646
2048.17	4.47809
2049.16	-3.79462
2050.14	-3.39908
2051.12	1.55206
2052.11	-7.00522
2053.09	1.5419
2054.07	11.2841
2055.05	-10.0855
2056.03	7.56204
2057.01	-10.2704
2058	-20.4454
2058.98	-11.7536
2059.96	7.15411
2060.94	-6.97205
2061.92	2.55399
2062.9	-2.01862
2063.88	11.3357
2064.86	16.1887
2065.84	2.47437
2066.82	4.5892
2067.8	-1.80914
2068.78	0.25531
2069.76	5.83789
2070.73	3.95935
2071.71	13.6086
2072.69	14.1177
2073.67	8.44058
2074.65	9.49612
2075.63	13.716
2076.6	-9.47995
2077.58	9.26349
2078.56	1.66675
2079.54	12.2623
2080.51	8.85251
2081.49	-3.41061
2082.47	7.95633
2083.45	-1.41931
2084.42	18.4315
2085.4	0.52005
2086.37	2.54559
2087.35	10.3959
2088.32	27.5553
2089.3	9.65915
2090.28	13.705
2091.25	-1.31839
2092.23	-1.04337
2093.2	19.332
2094.18	20.639
2095.15	1.71896
2096.13	-5.09219
2097.1	0.5466
2098.07	18.4077
2099.05	0.313904
2100.02	10.7284
2101	9.86798
2101.97	0.603302
2102.94	8.19867
2103.92	9.95074
2104.89	13.8378
2105.86	4.59158
2106.83	11.4171
2107.8	-2.80267
2108.78	17.7919
2109.75	-1.18176
2110.72	14.107
2111.69	5.55011
2112.66	15.9139
2113.63	31.3282
2114.61	-2.81183
2115.58	15.2605
2116.55	17.0242
2117.52	15.0124
2118.49	23.441
2119.46	-4.39078
2120.43	19.0753
2121.4	12.5357
2122.37	-8.01898
2123.34	2.62247
2124.31	31.0892
2125.28	0.304108
2126.25	24.4805
2127.21	-5.1412
2128.18	3.24759
2129.15	34.3985
2130.12	21.0935
2131.09	7.77759
2132.06	3.82059
2133.02	10.2399
2133.99	2.68762
2134.96	4.60123
2135.93	12.0872
2136.89	28.7506
2137.86	0.544128
2138.83	15.5135
2139.79	10.885
2140.76	-5.40463
2141.73	13.3532
2142.69	16.9472
2143.66	4.02274
2144.62	11.8399
2145.59	12.7975
2146.55	-11.7054
2147.52	14.4792
2148.48	-2.59122
2149.45	14.1076
2150.42	-1.28827
2151.38	14.5658
2152.34	-4.96582
2153.31	3.36099
2154.27	6.9361
2155.24	-6.63657
2156.2	-16.4076
2157.16	-7.18637
2158.13	20.0333
2159.09	1.38303
2160.05	-10.0242
2161.01	11.1442
2161.98	-10.4434
2162.94	0.722778
2163.9	3.36719
2164.86	-0.60434
2165.83	4.03769
2166.79	2.09421
2167.75	-2.81375
2168.71	6.95218
2169.67	8.9187
2170.63	6.52029
2171.59	-1.96469
2172.56	-2.51816
2173.51	-7.29645
2174.48	2.99503
2175.44	0.197021
2176.4	-9.18646
2177.36	-10.2323
2178.32	-3.73294
2179.28	4.41046
2180.23	10.908
2181.19	9.89993
2182.15	6.98248
2183.11	-8.01019
2184.07	18.5508
2185.03	5.44296
2185.99	1.83078
2186.95	4.84952
2187.9	-11.5341
2188.86	9.65829
2189.82	13.9121
2190.78	-1.09531
2191.73	3.5827
2192.69	9.22882
2193.65	19.6046
2194.6	-8.74048
2195.56	-2.29831
2196.52	12.2009
2197.47	3.50562
2198.43	3.46786
2199.38	2.87521
2200.34	29.3505
2201.3	11.2832
2202.25	-4.72006
2203.21	23.6978
2204.16	0.636505
2205.12	23.3049
2206.07	3.84094
2207.03	10.2797
2207.98	-3.51276
2208.93	4.15482
2209.89	20.9809
2210.84	6.12952
2211.8	7.23175
2212.75	14.8694
2213.7	8.15454
2214.66	-8.52029
2215.61	9.3772
2216.56	0.949982
2217.51	3.66763
2218.47	-1.02411
2219.42	7.48508
2220.37	-3.60352
2221.32	0.0205383
2222.27	-4.99268
2223.23	23.9224
2224.18	0.80777
2225.13	6.71814
2226.08	-2.37308
2227.03	-11.5387
2227.98	-0.165894
2228.93	-8.7334
2229.88	-7.82816
2230.83	4.59872
2231.78	-2.67273
2232.73	5.9906
2233.68	9.94623
2234.63	-5.97684
2235.58	6.90399
2236.53	13.389
2237.48	0.295441
2238.43	-4.01459
2239.38	18.9607
2240.33	0.841736
2241.27	5.65048
2242.22	17.9549
2243.17	3.85822
2244.12	1.78513
2245.07	18.8731
2246.01	-0.617798
2246.96	8.0647
2247.91	7.21454
2248.85	-12.7753
2249.8	-0.520935
2250.75	14.4958
2251.69	-6.62128
2252.64	-0.922607
2253.59	22.2238
2254.53	-0.264252
2255.48	-1.23193
2256.42	-6.89301
2257.37	6.56241
2258.32	-10.4222
2259.26	4.83368
2260.2	3.97845
2261.15	-8.28561
2262.1	-4.32886
2263.04	-8.97284
2263.98	-4.84769
2264.93	12.7379
2265.87	-2.3718
2266.81	-4.49158
2267.76	-7.65601
2268.7	0.680511
2269.65	4.6608
2270.59	19.3573
2271.53	-4.34335
2272.47	17.7939
2273.42	6.32828
2274.36	30.2812
2275.3	-14.6765
2276.24	14.0806
2277.18	-0.986877
2278.13	14.7592
2279.07	15.9064
2280.01	-14.1391
2280.95	3.72803
2281.89	-11.8008
2282.83	12.3007
2283.77	5.93375
2284.71	11.2508
2285.65	10.4749
2286.59	-13.8053
2287.54	-18.3075
2288.47	8.77817
2289.41	7.5206
2290.35	14.755
2291.29	10.9061
2292.23	11.22
2293.17	23.0365
2294.11	7.76709
2295.05	-4.9595
2295.99	4.46622
2296.93	10.9092
2297.86	8.22086
2298.8	7.57474
2299.74	3.02512
2300.68	20.398
2301.61	22.5046
2302.55	-14.1901
2303.49	-18.0957
2304.43	2.25687
2305.36	18.8773
2306.3	-0.319366
2307.24	-5.09296
2308.17	-0.363007
2309.11	-2.33258
2310.04	-3.00125
2310.98	-4.82339
2311.92	-0.484467
2312.85	4.05069
2313.79	-13.2148
2314.72	8.47638
2315.66	15.48
2316.59	24.7296
2317.52	1.4429
2318.46	-1.36969
2319.39	4.25067
2320.33	14.7924
2321.26	19.75
2322.2	18.1597
2323.13	-4.77664
2324.06	12.7579
2325	-7.59387
2325.93	24.9398
2326.86	16.9834
2327.79	42.7946
2328.73	96.7515
2329.66	15.6357
2330.59	8.93784
2331.52	15.7063
2332.46	1.43137
2333.39	-1.57739
2334.32	-2.60721
2335.25	6.87741
2336.18	-17.066
2337.11	11.8004
2338.04	-11.2421
2338.97	8.02545
2339.91	11.0286
2340.84	8.0769
2341.77	6.83289
2342.7	3.81619
2343.63	21.1391
2344.56	4.01526
2345.49	16.5586
2346.41	-7.51556
2347.34	0.205994
2348.27	-1.56171
2349.2	2.45895
2350.13	0.208771
2351.06	10.2513
2351.99	12.7231
2352.91	15.2512
2353.84	6.36679
2354.77	8.47079
2355.7	-6.56146
2356.63	1.02969
2357.55	-4.8717
2358.48	5.61444
2359.41	-9.52274
2360.33	4.76218
2361.26	12.2727
2362.19	-5.83542
2363.11	8.29553
2364.04	3.62387
2364.97	13.1487