File: Data/3-Raman/processed/bu32-AII-incC-fi01-v_1800 (450-850nm)_532nm_edge_100%_x100_vis_lwd_h30um_40sx2_01.txt
#Acq. time (s)=	40
#Accumulations=	2
#Range (cm-¹)=	1200...2365
#Windows=	3
#Auto scanning=	Off
#Autofocus=	Off
#Macrospot=	Off
#AutoExposure=	Off
#Spike filter=	Multiple accum.
#Delay time (s)=	2
#Binning=	1
#Readout mode=	Signal
#DeNoise=	Off
#ICS correction=	On
#Dark correction=	Off
#Inst. Process=	Off
#Detector Gain=	Best Dynamic
#Detector ADC=	50 kHz EM
#Detector EM gain=	400
#Detector temperature (°C)=	-60.09
#Instrument=	LabRAM HR Evol
#Detector=	SIN-EM FIVIS
#Objective=	x100_VIS_LWD
#Grating=	1800 (450-850nm)
#ND Filter=	100%
#Laser=	532nm_Edge
#Hole=	30.0125
#Temperature=	0
#Range=	Visible
#StageXY=	75x50mm Scan+
#StageZ=	Z motor
#X (µm)=	0
#Y (µm)=	0
#Z (µm)=	3.9
#Full time(mm:ss)=	4:22
#Project=	21_11_26
#Sample=	BU32
#Site=
#Title=	BU32-A-incC-FI01-V_1800 (450-850nm)_532nm_Edge_100%_x100_VIS_LWD_H30um_40sX2
#Remark=
#Date=	26.11.2021 17:46
#Acquired=	26.11.2021 17:46:55
#Base:Fit=	16.12.2021 14:32:51
#Base:Fit=	16.12.2021 14:32:55
#Base:Edit=	16.12.2021 14:33:03
#Base:Edit=	16.12.2021 14:33:05
#Base:Sub=	16.12.2021 14:33:08
1202.72	-3.19522
1203.84	15.5745
1204.95	1.49554
1206.06	43.9511
1207.17	12.0547
1208.28	-2.29599
1209.39	25.0351
1210.5	-25.483
1211.61	-2.75717
1212.72	22.0536
1213.83	1.17532
1214.94	8.30569
1216.05	24.9377
1217.16	7.96494
1218.27	-7.79892
1219.38	33.9337
1220.49	8.85269
1221.6	23.0266
1222.71	29.279
1223.81	-1.76077
1224.92	17.1832
1226.03	-18.2863
1227.14	-16.9409
1228.25	-2.79086
1229.35	-14.001
1230.46	22.1803
1231.57	5.41107
1232.67	16.1541
1233.78	-8.93866
1234.89	19.7863
1235.99	31.7237
1237.1	-1.8663
1238.2	12.4141
1239.31	-17.3542
1240.41	-11.1133
1241.52	0.540558
1242.62	-2.70078
1243.73	23.6895
1244.83	11.142
1245.94	7.61868
1247.04	5.2944
1248.14	-32.4827
1249.25	-29.5768
1250.35	-0.319641
1251.45	8.67349
1252.56	17.7199
1253.66	-7.67746
1254.76	35.3176
1255.87	-0.170837
1256.97	-6.40726
1258.07	-11.7978
1259.17	-8.95303
1260.27	16.3082
1261.37	47.0326
1262.48	5.11932
1263.58	45.5832
1264.68	65.8394
1265.78	26.6058
1266.88	-0.648743
1267.98	-8.68954
1269.08	-10.3152
1270.18	0.0711365
1271.28	2.7182
1272.38	1.62677
1273.47	3.09851
1274.57	32.7961
1275.67	21.2261
1276.77	-3.71002
1277.87	-1.33936
1278.97	-3.1311
1280.07	6.33997
1281.16	-6.34973
1282.26	9.65598
1283.36	24.12
1284.45	183.529
1285.55	362.532
1286.65	20.1329
1287.75	6.21237
1288.84	15.5193
1289.94	8.36615
1291.03	14.765
1292.13	8.35834
1293.22	1.98251
1294.32	6.70166
1295.42	18.3838
1296.51	-9.22281
1297.61	9.72549
1298.7	17.9159
1299.79	34.5625
1300.89	-8.58527
1301.98	-12.7417
1303.08	-12.6177
1304.17	-30.7101
1305.26	-0.109375
1306.35	2.71249
1307.45	-13.158
1308.54	12.225
1309.63	10.2926
1310.73	7.24554
1311.82	30.586
1312.91	13.9716
1314	-2.99429
1315.09	-4.99591
1316.18	-7.87
1317.28	-2.57993
1318.37	10.3159
1319.46	-29.7174
1320.55	16.8669
1321.64	28.2692
1322.73	21.6316
1323.82	0.493073
1324.91	-16.2398
1326	-18.5013
1327.09	9.3526
1328.18	10.2292
1329.27	18.274
1330.35	10.9673
1331.44	-8.23273
1332.53	21.8328
1333.62	-1.73605
1334.71	-2.05963
1335.79	-5.40039
1336.88	-4.45038
1337.97	-17.0284
1339.06	25.7574
1340.14	-19.1143
1341.23	0.994293
1342.32	12.5288
1343.4	2.91702
1344.49	19.7994
1345.58	-9.4895
1346.66	15.1776
1347.75	1.29156
1348.83	-29.9709
1349.92	31.3951
1351	5.23126
1352.09	5.12161
1353.17	22.2513
1354.25	7.29132
1355.34	-16.3524
1356.42	8.75989
1357.51	21.2315
1358.59	-5.80939
1359.67	10.7179
1360.76	21.93
1361.84	4.41171
1362.92	21.0506
1364	20.3961
1365.09	-5.28403
1366.17	-18.8566
1367.25	14.0225
1368.33	20.4479
1369.41	-0.90329
1370.5	-1.80856
1371.58	-20.5082
1372.66	9.06345
1373.74	9.01517
1374.82	32.8216
1375.9	8.32959
1376.98	8.38135
1378.06	22.8885
1379.14	10.4492
1380.22	33.1508
1381.3	4.70499
1382.38	10.6765
1383.46	-10.2055
1384.54	25.6972
1385.61	35.6021
1386.69	54.7169
1387.77	542.342
1388.85	232.506
1389.93	24.5971
1391	28.2857
1392.08	0.516876
1393.16	11.7044
1394.23	-0.488007
1395.31	2.80899
1396.39	5.23636
1397.46	-15.1905
1398.54	8.49918
1399.62	9.94821
1400.69	-9.10791
1401.77	-13.7944
1402.84	-0.633392
1403.92	28.7435
1404.99	4.05768
1406.07	1.98181
1407.14	0.0549927
1408.22	33.2241
1409.29	68.4649
1410.37	42.1441
1411.44	13.2346
1412.51	14.4177
1413.59	14.7883
1414.66	-17.2906
1415.73	28.2953
1416.81	2.99149
1417.88	-7.88779
1418.95	2.69171
1420.02	-8.48245
1421.1	8.88089
1422.17	26.5876
1423.24	26.6895
1424.31	20.3588
1425.38	2.13748
1426.45	29.1416
1427.52	-0.790497
1428.59	13.3759
1429.67	2.44617
1430.74	-8.26254
1431.81	19.143
1432.87	-2.4234
1433.95	12.5525
1435.01	12.9032
1436.08	-7.38763
1437.15	9.08368
1438.22	8.15311
1439.29	12.5928
1440.36	7.97043
1441.43	39.0453
1442.49	0.226196
1443.56	-17.0349
1444.63	-6.67114
1445.7	-0.0153809
1446.77	31.8363
1447.83	4.17914
1448.9	51.6654
1449.97	29.2184
1451.03	19.968
1452.1	13.8513
1453.17	-2.38361
1454.23	13.2274
1455.3	-4.04794
1456.36	21.8409
1457.43	8.52127
1458.49	13.7446
1459.56	4.76279
1460.62	1.79718
1461.69	17.1436
1462.75	8.83264
1463.82	-7.72873
1464.88	3.09891
1465.94	10.2445
1467.01	27.6151
1468.07	-12.0855
1469.13	-14.0256
1470.2	-13.1028
1471.26	-9.07547
1472.32	0.0279541
1473.39	-8.03671
1474.45	17.3614
1475.51	16.5586
1476.57	-19.0557
1477.63	14.4605
1478.69	24.6152
1479.76	-3.96744
1480.82	1.83844
1481.88	-24.5492
1482.94	-9.93631
1484	33.9369
1485.06	1.76822
1486.12	-18.4791
1487.18	25.2647
1488.24	13.0262
1489.3	23.9551
1490.36	-26.6141
1491.42	-7.47223
1492.48	-12.4399
1493.53	39.1961
1494.59	-12.2482
1495.65	-7.22894
1496.71	-0.415314
1497.77	4.64307
1498.82	-9.38507
1499.88	3.94745
1500.94	-15.0821
1502	7.08881
1503.05	5.03839
1504.11	5.96524
1505.17	3.09875
1506.22	-18.2971
1507.28	-16.1323
1508.34	-8.96024
1509.39	-6.82278
1510.45	-1.60767
1511.5	11.2463
1512.56	21.6301
1513.61	-1.80276
1514.67	20.661
1515.72	10.381
1516.78	2.10501
1517.83	3.15985
1518.88	-7.60886
1519.94	-6.38562
1520.99	34.81
1522.05	27.9792
1523.1	-4.18011
1524.15	-12.5189
1525.2	-9.56381
1526.26	18.7616
1527.31	-13.9849
1528.36	-19.0219
1529.41	1.9902
1530.47	5.99701
1531.52	5.37024
1532.57	2.42072
1533.62	-0.0561523
1534.67	27.2054
1535.72	3.06494
1536.77	20.6645
1537.82	7.3382
1538.87	8.21353
1539.92	1.91434
1540.97	-19.3832
1542.02	7.56168
1543.07	34.3219
1544.12	-13.0408
1545.17	7.3262
1546.22	1.82193
1547.27	7.03748
1548.32	20.9762
1549.37	14.8586
1550.42	28.1378
1551.46	53.576
1552.51	28.6152
1553.56	18.4016
1554.61	-17.862
1555.65	19.0018
1556.7	11.0834
1557.75	9.27145
1558.79	14.0872
1559.84	11.7643
1560.89	3.70013
1561.93	16.9001
1562.98	-7.75195
1564.02	-3.68927
1565.07	16.7673
1566.11	12.4909
1567.16	7.29932
1568.2	20.7386
1569.25	13.9766
1570.29	11.9205
1571.34	30.0406
1572.38	16.0087
1573.43	-13.0426
1574.47	7.02841
1575.51	-5.43393
1576.56	9.75677
1577.6	6.44684
1578.64	6.1463
1579.69	18.2341
1580.73	17.5084
1581.77	30.4403
1582.81	10.438
1583.85	20.4781
1584.9	17.6682
1585.94	13.8223
1586.98	5.71851
1588.02	24.6361
1589.06	18.9699
1590.1	10.3255
1591.14	24.5466
1592.18	-10.2218
1593.22	30.385
1594.26	4.13177
1595.3	22.2575
1596.34	24.2765
1597.38	33.4354
1598.42	26.6772
1599.46	-8.24622
1600.5	26.3922
1601.54	56.8418
1602.58	14.0209
1603.62	20.7804
1604.66	29.7726
1605.69	33.9508
1606.73	7.61514
1607.77	25.335
1608.81	41.4073
1609.84	32.4708
1610.88	33.5758
1611.92	1.45575
1612.95	9.74387
1613.99	5.35004
1615.03	19.2552
1616.06	29.0883
1617.1	4.27359
1618.13	10.5113
1619.17	12.7229
1620.2	3.1499
1621.24	13.4665
1622.27	16.5588
1623.31	9.4144
1624.34	16.0676
1625.38	15.4276
1626.41	14.7465
1627.45	14.7016
1628.48	13.3756
1629.51	10.1127
1630.55	-3.93933
1631.53	-15.8662
1632.57	-17.4622
1633.62	17.2012
1634.66	5.67786
1635.71	2.89594
1636.75	-21.6899
1637.8	7.85342
1638.84	-14.6934
1639.89	-7.59119
1640.93	-1.40778
1641.98	-9.0705
1643.02	10.7529
1644.06	-6.81165
1645.11	17.8384
1646.15	7.35144
1647.19	-21.1095
1648.24	-6.25583
1649.28	1.19455
1650.32	11.2469
1651.37	-2.95139
1652.41	10.1547
1653.45	6.34549
1654.49	4.68158
1655.53	29.7223
1656.57	-5.15524
1657.62	13.8319
1658.66	5.03766
1659.7	7.01315
1660.74	32.8159
1661.78	-6.12512
1662.82	13.2951
1663.86	18.5115
1664.9	-14.1063
1665.94	-6.46274
1666.98	-4.77194
1668.02	28.8069
1669.06	-8.38712
1670.1	0.0156555
1671.14	-19.2435
1672.18	40.2267
1673.21	-6.94397
1674.25	-4.64484
1675.29	-2.22052
1676.33	-5.85803
1677.37	-21.4251
1678.4	-10.4814
1679.44	-4.55698
1680.48	-16.3189
1681.52	-9.29364
1682.55	-14.0093
1683.59	1.01782
1684.63	11.0334
1685.66	-0.65744
1686.7	14.4265
1687.73	-10.9291
1688.77	30.6163
1689.81	7.86935
1690.84	-6.79376
1691.88	6.40182
1692.91	-10.1857
1693.95	18.2767
1694.98	19.1985
1696.01	27.3696
1697.05	-0.865967
1698.08	9.89923
1699.12	5.93106
1700.15	9.09631
1701.18	8.24185
1702.22	-3.52286
1703.25	1.39029
1704.28	7.41705
1705.32	20.4924
1706.35	14.7357
1707.38	9.69019
1708.41	16.3554
1709.44	-11.3116
1710.48	22.1161
1711.51	8.76324
1712.54	20.7599
1713.57	8.65784
1714.6	-4.21533
1715.63	-6.92926
1716.66	16.7252
1717.69	-13.7867
1718.72	-12.1996
1719.75	-0.435852
1720.78	7.54922
1721.81	1.60309
1722.84	12.143
1723.87	19.8432
1724.9	-13.0733
1725.93	4.09863
1726.96	10.9529
1727.99	13.9557
1729.02	-7.85703
1730.05	8.40775
1731.07	-7.0527
1732.1	2.26688
1733.13	-24.7343
1734.16	6.85492
1735.18	-5.93762
1736.21	0.656067
1737.24	13.1915
1738.26	-6.0643
1739.29	14.9566
1740.32	7.85703
1741.34	-3.87695
1742.37	-9.68069
1743.4	7.629
1744.42	14.3269
1745.45	1.99969
1746.47	8.73941
1747.5	-0.0695801
1748.52	-4.87735
1749.55	0.158722
1750.57	0.6297
1751.6	8.61087
1752.62	4.61847
1753.64	12.1178
1754.67	6.28281
1755.69	-6.13092
1756.71	-8.17972
1757.74	3.03503
1758.76	22.3498
1759.78	-6.94763
1760.81	8.34232
1761.83	-15.5035
1762.85	-1.10696
1763.87	0.996613
1764.89	1.42361
1765.92	-10.6356
1766.94	-1.93912
1767.96	18.0908
1768.98	-1.89435
1770	-11.8833
1771.02	1.74777
1772.04	13.5998
1773.06	-3.16837
1774.08	17.1185
1775.1	-10.2332
1776.12	2.63181
1777.14	1.81473
1778.16	-4.94373
1779.18	7.27094
1780.2	5.4386
1781.22	-1.92615
1782.24	4.97244
1783.26	6.29318
1784.28	8.51251
1785.29	-1.61316
1786.31	-14.9366
1787.33	6.34174
1788.35	2.36227
1789.37	-8.48972
1790.38	26.4399
1791.4	10.2131
1792.42	-3.36493
1793.43	32.301
1794.45	16.2018
1795.47	24.3102
1796.48	15.2371
1797.5	18.5117
1798.51	-0.42926
1799.53	16.9441
1800.55	31.2058
1801.56	-2.4285
1802.58	15.03
1803.59	18.2706
1804.61	-11.2881
1805.62	0.643036
1806.64	2.9397
1807.65	4.08633
1808.66	29.2536
1809.68	26.5003
1810.69	13.1342
1811.7	7.38181
1812.72	12.3377
1813.73	-0.900726
1814.74	-2.43744
1815.76	5.63455
1816.77	12.5526
1817.78	21.1028
1818.79	3.84064
1819.8	18.5133
1820.82	13.9155
1821.83	12.2277
1822.84	23.0917
1823.85	5.7309
1824.86	3.8703
1825.87	33.1118
1826.88	10.9182
1827.89	36.269
1828.9	24.6862
1829.91	22.6859
1830.92	9.03821
1831.93	18.9125
1832.94	6.58255
1833.95	34.8416
1834.96	33.6639
1835.97	8.94666
1836.98	52.0487
1837.99	28.5744
1839	16.9735
1840	16.5457
1841.01	46.8228
1842.02	8.48932
1843.03	7.25491
1844.04	16.9355
1845.04	24.6981
1846.05	5.54086
1847.06	12.6786
1848.07	12.4413
1849.07	12.5385
1850.08	-2.13953
1851.09	8.99631
1852.09	0.1474
1853.1	7.8338
1854.1	9.63608
1855.11	22.7113
1856.11	-2.5271
1857.12	-5.431
1858.12	10.7383
1859.13	11.4222
1860.13	14.0582
1861.14	5.62262
1862.14	6.78943
1863.15	12.313
1864.15	-8.05252
1865.15	-0.651611
1866.16	14.1812
1867.16	3.11597
1868.16	-0.162567
1869.17	-0.190033
1870.17	6.41177
1871.17	1.61139
1872.17	1.4917
1873.18	-8.2052
1874.18	-4.53625
1875.18	11.279
1876.18	4.13562
1877.18	-9.46945
1878.18	6.11221
1879.19	-3.70551
1880.19	6.04269
1881.19	3.16711
1882.19	5.49884
1883.19	-18.8163
1884.19	1.57101
1885.19	-6.73175
1886.19	14.4761
1887.19	2.16208
1888.19	9.37717
1889.19	4.19513
1890.19	20.9456
1891.19	9.87482
1892.18	12.6275
1893.18	-0.705444
1894.18	-18.1459
1895.18	-1.38287
1896.18	15.6482
1897.18	15.8904
1898.17	17.8724
1899.17	-3.95758
1900.17	-6.06561
1901.16	-6.0712
1902.16	8.29938
1903.16	8.4382
1904.16	-5.79446
1905.15	-7.72696
1906.15	18.458
1907.14	-3.39151
1908.14	-11.7953
1909.14	15.6054
1910.13	5.59619
1911.13	-9.0372
1912.12	9.90686
1913.12	-15.5729
1914.11	-1.27271
1915.11	15.1063
1916.1	-16.8322
1917.1	-12.2688
1918.09	9.26102
1919.08	5.73074
1920.08	5.28595
1921.07	-7.86526
1922.06	11.3342
1923.06	7.51416
1924.05	7.38077
1925.04	-0.333649
1926.04	12.2077
1927.03	0.320648
1928.02	-3.23569
1929.01	2.6109
1930	-2.77646
1931	0.455566
1931.99	-0.511047
1932.98	5.00446
1933.97	13.6244
1934.96	-3.40448
1935.95	13.576
1936.94	-12.4713
1937.93	-5.12039
1938.92	3.4545
1939.91	19.8713
1940.9	4.897
1941.89	10.0133
1942.88	-6.0354
1943.87	10.0157
1944.86	15.0712
1945.85	14.4939
1946.84	13.8091
1947.83	-1.51309
1948.82	-8.21573
1949.8	8.29849
1950.79	16.4899
1951.78	-11.7086
1952.77	3.96497
1953.76	-8.44354
1954.74	6.22391
1955.73	-5.41489
1956.72	-6.72165
1957.7	16.6928
1958.69	-8.0715
1959.68	8.19751
1960.66	9.9856
1961.65	14.5854
1962.63	-8.39349
1963.62	-5.41266
1964.61	-11.979
1965.59	-3.32623
1966.58	5.55331
1967.56	18.2663
1968.55	3.9632
1969.53	-9.62207
1970.52	0.622711
1971.5	24.4596
1972.48	9.16461
1973.47	-15.7903
1974.45	-1.55911
1975.44	9.07358
1976.42	14.112
1977.4	1.73087
1978.39	-7.00781
1979.37	4.45227
1980.35	4.54895
1981.33	19.7594
1982.31	1.49878
1983.3	18.5892
1984.28	8.84515
1985.26	6.84195
1986.24	7.75623
1987.22	17.512
1988.21	2.99152
1989.19	12.6096
1990.17	-5.05313
1991.15	1.8559
1992.13	-3.30273
1993.11	15.6521
1994.09	-4.40817
1995.07	4.01099
1996.05	20.6217
1997.03	-4.12848
1998.01	-3.93707
1998.99	2.27963
1999.97	1.79874
2000.95	-3.30634
2001.92	-4.74738
2002.9	-3.84305
2003.88	5.22955
2004.86	7.44504
2005.84	4.78052
2006.81	1.08722
2007.79	-4.28503
2008.77	1.52975
2009.75	-0.871948
2010.73	-8.55429
2011.7	18.6026
2012.68	-4.22473
2013.67	2.08505
2014.66	-15.2654
2015.64	-1.21658
2016.63	-9.41611
2017.62	1.2453
2018.61	-5.67133
2019.6	1.43582
2020.58	-22.0193
2021.57	-1.29562
2022.56	10.8927
2023.55	-6.16141
2024.54	-14.7464
2025.52	2.67386
2026.51	-5.88904
2027.5	7.24835
2028.48	16.303
2029.47	5.74689
2030.45	6.68481
2031.44	-13.5796
2032.43	17.3902
2033.41	-11.9493
2034.4	-10.8612
2035.38	4.62128
2036.37	2.66107
2037.35	26.9872
2038.34	-8.52292
2039.32	-3.94049
2040.31	0.559082
2041.29	-2.45459
2042.27	-14.6087
2043.26	-0.652039
2044.24	-6.67477
2045.23	-6.75305
2046.21	-5.0274
2047.19	0.382111
2048.17	-13.9106
2049.16	7.73306
2050.14	18.5009
2051.12	-2.60248
2052.11	13.1958
2053.09	20.8994
2054.07	-1.97635
2055.05	-6.42984
2056.03	-6.4726
2057.01	14.0999
2058	18.037
2058.98	0.644897
2059.96	3.72604
2060.94	-15.9382
2061.92	7.70889
2062.9	-3.33847
2063.88	-1.14883
2064.86	11.2785
2065.84	7.9649
2066.82	10.1632
2067.8	10.4219
2068.78	5.99048
2069.76	4.12622
2070.73	8.89789
2071.71	29.9106
2072.69	14.5165
2073.67	-2.38818
2074.65	12.8625
2075.63	-6.40924
2076.6	11.0397
2077.58	4.36261
2078.56	9.09628
2079.54	-1.94324
2080.51	23.0494
2081.49	11.7953
2082.47	-1.34003
2083.45	14.8616
2084.42	17.7638
2085.4	12.1985
2086.37	28.4698
2087.35	9.91299
2088.32	3.47147
2089.3	10.2392
2090.28	-6.49493
2091.25	-10.0985
2092.23	19.625
2093.2	24.8925
2094.18	8.20096
2095.15	6.44144
2096.13	-0.326782
2097.1	19.6055
2098.07	12.8146
2099.05	-0.488892
2100.02	6.17215
2101	15.7947
2101.97	5.62741
2102.94	4.71332
2103.92	19.7926
2104.89	13.2745
2105.86	-4.48566
2106.83	3.3215
2107.8	6.24585
2108.78	3.11401
2109.75	25.9586
2110.72	-4.31705
2111.69	21.35
2112.66	7.99146
2113.63	29.1276
2114.61	17.8178
2115.58	27.3568
2116.55	9.18289
2117.52	35.6768
2118.49	17.5327
2119.46	14.3716
2120.43	16.0384
2121.4	29.4133
2122.37	6.98917
2123.34	8.15652
2124.31	4.35489
2125.28	16.262
2126.25	-2.18652
2127.21	11.7195
2128.18	7.80814
2129.15	11.5421
2130.12	8.63248
2131.09	7.59506
2132.06	11.1822
2133.02	6.26086
2133.99	26.0642
2134.96	34.5732
2135.93	3.35193
2136.89	0.207275
2137.86	2.15024
2138.83	39.7198
2139.79	19.0497
2140.76	15.9154
2141.73	12.0398
2142.69	-0.395721
2143.66	16.7874
2144.62	-0.843048
2145.59	20.7685
2146.55	3.75177
2147.52	31.774
2148.48	22.1718
2149.45	-11.8727
2150.42	6.47107
2151.38	11.0338
2152.34	7.40448
2153.31	3.49475
2154.27	1.4006
2155.24	4.62628
2156.2	26.5589
2157.16	8.62399
2158.13	27.3912
2159.09	5.88718
2160.05	7.49945
2161.01	-10.6048
2161.98	4.14301
2162.94	-6.20551
2163.9	-3.6185
2164.86	-4.8526
2165.83	8.11533
2166.79	-3.20844
2167.75	-7.24844
2168.71	3.38174
2169.67	2.49368
2170.63	13.996
2171.59	-17.834
2172.56	17.8081
2173.51	12.0225
2174.48	5.52258
2175.44	-8.49908
2176.4	10.8511
2177.36	1.36438
2178.32	17.0811
2179.28	24.2056
2180.23	-13.9384
2181.19	5.4046
2182.15	17.2589
2183.11	6.82162
2184.07	9.18668
2185.03	9.90018
2185.99	-10.4714
2186.95	15.6563
2187.9	8.50049
2188.86	-3.81943
2189.82	-1.4938
2190.78	6.5968
2191.73	1.92545
2192.69	14.9132
2193.65	-5.4122
2194.6	22.8354
2195.56	2.23984
2196.52	-1.92422
2197.47	15.2795
2198.43	-6.17499
2199.38	-5.9216
2200.34	43.7241
2201.3	16.2985
2202.25	9.45801
2203.21	16.4399
2204.16	29.7151
2205.12	21.4828
2206.07	5.6441
2207.03	-0.0804443
2207.98	9.30466
2208.93	0.156158
2209.89	32.741
2210.84	22.4794
2211.8	13.2704
2212.75	8.7186
2213.7	-3.66385
2214.66	22.5052
2215.61	-0.717316
2216.56	13.1949
2217.51	-15.8979
2218.47	-0.115967
2219.42	23.2795
2220.37	-12.1584
2221.32	-11.3994
2222.27	-9.00214
2223.23	3.98233
2224.18	-2.37723
2225.13	-0.256897
2226.08	5.58466
2227.03	2.00549
2227.98	-4.47583
2228.93	6.59637
2229.88	-8.48206
2230.83	3.90936
2231.78	13.5133
2232.73	6.17624
2233.68	23.2743
2234.63	4.50198
2235.58	11.6916
2236.53	7.79907
2237.48	3.14697
2238.43	-1.17001
2239.38	1.04407
2240.33	6.48218
2241.27	-7.58829
2242.22	-0.962524
2243.17	24.5756
2244.12	5.49387
2245.07	-15.1852
2246.01	11.6115
2246.96	0.442413
2247.91	0.541412
2248.85	14.6223
2249.8	-8.12943
2250.75	12.5741
2251.69	19.828
2252.64	-4.71005
2253.59	5.20587
2254.53	-10.6296
2255.48	-11.5714
2256.42	0.816803
2257.37	1.02997
2258.32	3.07556
2259.26	-0.619934
2260.2	5.22223
2261.15	5.37067
2262.1	0.828613
2263.04	-18.0353
2263.98	0.444092
2264.93	29.5655
2265.87	-6.47809
2266.81	-19.0373
2267.76	-11.6345
2268.7	7.25955
2269.65	1.78549
2270.59	-9.22479
2271.53	2.5177
2272.47	5.61777
2273.42	12.4211
2274.36	-9.4696
2275.3	-9.34482
2276.24	12.8123
2277.18	-14.6059
2278.13	-0.680206
2279.07	9.2153
2280.01	11.913
2280.95	10.6846
2281.89	5.80991
2282.83	-5.43472
2283.77	-8.80856
2284.71	12.9729
2285.65	-2.10211
2286.59	-0.278534
2287.54	-21.9536
2288.47	5.27161
2289.41	3.18854
2290.35	7.67752
2291.29	-15.257
2292.23	15.9846
2293.17	13.51
2294.11	7.06491
2295.05	18.5723
2295.99	0.214539
2296.93	16.4331
2297.86	4.28342
2298.8	7.65311
2299.74	24.4893
2300.68	-5.24069
2301.61	8.59897
2302.55	17.4307
2303.49	20.4408
2304.43	-9.2283
2305.36	5.62054
2306.3	-4.71793
2307.24	6.13779
2308.17	1.36447
2309.11	2.45609
2310.04	18.3979
2310.98	13.8439
2311.92	-1.97504
2312.85	-2.10794
2313.79	10.707
2314.72	11.3242
2315.66	11.7138
2316.59	4.69284
2317.52	5.70071
2318.46	12.6917
2319.39	0.103546
2320.33	15.6074
2321.26	16.8379
2322.2	3.78235
2323.13	-3.57135
2324.06	17.9501
2325	10.2764
2325.93	14.8929
2326.86	23.4467
2327.79	33.921
2328.73	74.4727
2329.66	43.5395
2330.59	4.16281
2331.52	5.21698
2332.46	13.1514
2333.39	4.40393
2334.32	0.519806
2335.25	19.6445
2336.18	22.645
2337.11	5.35336
2338.04	3.45297
2338.97	11.1637
2339.91	2.5997
2340.84	3.44836
2341.77	7.90564
2342.7	14.4001
2343.63	13.4174
2344.56	13.4427
2345.49	5.73398
2346.41	16.9639
2347.34	12.0745
2348.27	16.8336
2349.2	-6.15094
2350.13	23.9037
2351.06	-13.04
2351.99	30.1749
2352.91	6.63632
2353.84	10.7955
2354.77	1.14328
2355.7	1.95837
2356.63	0.59726
2357.55	-0.00360107
2358.48	3.39658
2359.41	7.75201
2360.33	-3.1449
2361.26	1.00815
2362.19	23.1075
2363.11	-10.7075
2364.04	0.103485
2364.97	-8.03781