File: Data/3-Raman/processed/bu32-AII-incC-fi02-v_150 (500nm)_532nm_edge_100%_x100_vis_lwd_h30um_15sx2_01.txt
#Acq. time (s)=	15
#Accumulations=	2
#Range (cm-¹)=	99...4000
#Windows=	1
#Auto scanning=	Off
#Autofocus=	Off
#Macrospot=	Off
#AutoExposure=	Off
#Spike filter=	Multiple accum.
#Delay time (s)=	2
#Binning=	1
#Readout mode=	Signal
#DeNoise=	Off
#ICS correction=	On
#Dark correction=	Off
#Inst. Process=	Off
#Detector Gain=	Best Dynamic
#Detector ADC=	50 kHz HS
#Detector temperature (°C)=	-60.09
#Instrument=	LabRAM HR Evol
#Detector=	SIN-EM FIVIS
#Objective=	x100_VIS_LWD
#Grating=	150 (500nm)
#ND Filter=	100%
#Laser=	532nm_Edge
#Hole=	30.0125
#Temperature=	0
#Range=	Visible
#StageXY=	75x50mm Scan+
#StageZ=	Z motor
#X (µm)=	0
#Y (µm)=	0
#Z (µm)=	0.6
#Full time(s)=	34
#Project=	21_11_26
#Sample=	BU32
#Site=
#Title=	BU32-A-incC-FI02-V_150 (500nm)_532nm_Edge_100%_x100_VIS_LWD_H30um_15sX2
#Remark=
#Date=	26.11.2021 17:36
#Acquired=	26.11.2021 17:36:15
#Base:Fit=	16.12.2021 14:33:32
#Base:Sub=	16.12.2021 14:33:33
102.91	101.2
107.534	110.541
112.156	82.3394
116.775	72.5569
121.392	45.3511
126.005	97.3784
130.617	76.524
135.227	110.076
139.835	104.158
144.439	85.9808
149.042	61.663
153.643	53.3389
158.242	32.8118
162.839	29.4833
167.431	49.4106
172.023	26.4737
176.613	12.1252
181.198	7.55954
185.783	-0.70282
190.366	0.780029
194.947	14.4485
199.524	18.276
204.1	39.163
208.674	37.9552
213.243	53.8159
217.813	50.0544
222.38	62.1339
226.945	50.8872
231.506	34.6302
236.066	51.2933
240.625	38.5468
245.179	31.8112
249.732	55.487
254.284	82.6958
258.831	74.5147
263.378	110.06
267.923	100.561
272.464	86.1772
277.004	64.5117
281.54	50.1617
286.076	54.0705
290.61	52.0638
295.139	28.2869
299.669	11.7103
304.196	14.5077
308.718	8.63962
313.241	-0.13147
317.759	10.5001
322.278	10.356
326.794	9.6879
331.305	14.705
335.817	11.3964
340.324	20.4023
344.832	13.1397
349.334	28.9648
353.837	13.2461
358.338	30.4821
362.834	25.2482
367.33	25.8066
371.822	18.8845
376.314	31.9726
380.802	24.4909
385.289	38.2612
389.772	40.1016
394.255	69.0811
398.734	107.962
403.213	119.343
407.688	127.186
412.162	103.651
416.632	109.955
421.102	121.093
425.568	135.964
430.033	152.989
434.495	218.16
438.956	263.524
443.413	280.775
447.87	328.32
452.323	324.895
456.776	385.992
461.224	433.794
465.673	424.547
470.117	379.712
474.561	289.335
479.001	236.402
483.438	200.87
487.876	179.96
492.309	152.235
496.742	152.146
501.172	157.758
505.601	126.736
510.025	97.1244
514.448	84.8402
518.871	71.3804
523.289	52.1908
527.707	52.6726
532.121	55.482
536.533	66.4132
540.945	113.253
545.353	177.511
549.758	267.374
554.164	379.336
558.565	506.137
562.965	455.073
567.364	286.782
571.759	192.257
576.151	192.951
580.544	204.391
584.933	241.273
589.319	285.097
593.706	296.639
598.088	303.619
602.468	271.67
606.848	262.18
611.224	238.903
615.598	222.815
619.972	209.937
624.341	184.218
628.709	164.175
633.074	114.018
637.44	78.5838
641.801	78.655
646.16	61.4968
650.517	72.8352
654.874	65.7673
659.227	68.5496
663.578	57.7992
667.927	50.4257
672.275	48.6995
676.62	27.7543
680.962	31.643
685.302	30.9848
689.643	16.9134
693.979	8.73259
698.313	1.23631
702.645	3.364
706.975	13.1405
711.305	16.7681
715.631	-0.964935
719.955	5.85187
724.276	5.86002
728.596	24.2104
732.913	4.89861
737.231	11.7085
741.544	8.06215
745.856	-0.2677
750.165	13.2175
754.472	19.7267
758.778	11.1807
763.081	6.05577
767.384	19.8787
771.683	7.11299
775.98	16.4322
780.275	13.6491
784.568	20.8883
788.859	10.5565
793.147	15.742
797.434	26.3244
801.719	29.2556
806.004	23.5144
810.284	7.94341
814.563	12.1927
818.839	14.2713
823.114	11.9505
827.386	14.0764
831.657	27.2372
835.925	21.6827
840.192	21.6264
844.456	27.0712
848.719	28.0466
852.979	18.9983
857.237	12.1676
861.493	25.1742
865.748	24.9263
870	25.7269
874.25	28.6889
878.499	27.2159
882.745	19.1448
886.989	25.2409
891.231	29.0331
895.471	37.0797
899.71	36.7323
903.946	40.0417
908.18	42.0185
912.412	55.6749
916.642	80.2278
920.87	92.7967
925.096	120.328
929.321	172.325
933.543	211.642
937.763	307.679
941.981	417.245
946.197	581.984
950.412	761.086
954.622	1007.02
958.832	1333.3
963.04	1905.6
967.246	2665.85
971.451	3155.46
975.653	3061.84
979.853	2564.03
984.052	2127.63
988.248	1636.52
992.442	1271.88
996.633	1059.65
1000.82	860.62
1005.01	698.491
1009.2	603.005
1013.38	529.623
1017.57	461.205
1021.75	401.155
1025.92	366.483
1030.1	342.255
1034.27	325.333
1038.45	315.413
1042.62	299.909
1046.78	288.689
1050.95	263.555
1055.12	274.469
1059.28	260.891
1063.44	269.412
1067.6	293.543
1071.75	282.878
1075.91	282.694
1080.06	264.784
1084.21	254.139
1088.36	232.231
1092.51	232.208
1096.65	234.379
1100.8	261.308
1104.94	261.543
1109.08	220.063
1113.21	219.703
1117.35	183.765
1121.48	169.726
1125.61	184.556
1129.74	177.068
1133.87	158.386
1137.99	137.506
1142.12	129.896
1146.24	113.056
1150.36	84.7506
1154.48	88.2247
1158.59	78.1984
1162.71	89.7922
1166.82	71.3867
1170.93	68.4135
1175.04	61.2515
1179.14	53.0375
1183.25	27.3408
1187.35	32.4841
1191.45	23.1546
1195.55	28.1477
1199.65	28.9819
1203.74	17.55
1207.83	30.5445
1211.92	27.2721
1216.01	18.9792
1220.1	24.8511
1224.19	23.6853
1228.27	16.5465
1232.35	27.5107
1236.43	20.5744
1240.51	16.7391
1244.58	20.8657
1248.66	15.067
1252.73	39.3043
1256.8	49.613
1260.87	25.9814
1264.93	11.3441
1269	18.7384
1273.06	102.352
1277.12	207.228
1281.18	24.0067
1285.23	7.30659
1289.29	17.7229
1293.34	15.0465
1297.39	9.32303
1301.44	8.62044
1305.49	18.9779
1309.53	9.16826
1313.58	7.40599
1317.62	6.60301
1321.66	6.77896
1325.7	1.87419
1329.73	3.99699
1333.77	15.1352
1337.8	18.1781
1341.83	14.1829
1345.86	9.1881
1349.88	7.19942
1353.91	6.21683
1357.93	17.1635
1361.95	22.1107
1365.97	18.1592
1369.99	22.1498
1374	30.1122
1378.02	341.753
1382.03	167.221
1386.04	31.463
1390.05	29.7019
1394.05	15.1873
1398.06	47.9898
1402.06	53.2225
1406.06	21.0082
1410.06	6.52782
1414.05	17.6876
1418.05	13.0716
1422.04	-0.437431
1426.03	15.6523
1430.02	8.96301
1434.01	-2.6525
1438	9.42654
1441.98	6.69494
1445.96	12.8271
1449.94	4.14455
1453.92	10.2413
1457.9	8.43076
1461.87	15.4644
1465.85	9.64789
1469.82	-1.08067
1473.78	8.85197
1477.75	6.97404
1481.72	3.1233
1485.68	11.9933
1489.65	5.19446
1493.61	8.1809
1497.56	10.1867
1501.52	8.30579
1505.47	5.4772
1509.43	5.60209
1513.38	16.4185
1517.33	6.84251
1521.27	9.90215
1525.22	7.14669
1529.16	7.30982
1533.11	14.2726
1537.05	10.5728
1540.98	8.81441
1544.92	8.9932
1548.86	14.015
1552.79	9.34607
1556.72	13.3785
1560.65	14.4826
1564.58	18.4722
1568.5	9.87065
1572.43	3.20184
1576.35	5.2298
1580.27	16.8979
1584.19	7.33012
1588.1	15.1082
1592.02	13.2422
1595.93	1.75814
1599.84	22.9626
1603.75	19.1782
1607.66	17.3369
1611.57	16.4586
1615.47	20.3806
1619.37	6.11424
1623.27	5.25668
1627.17	9.2024
1631.07	13.1605
1634.97	11.4136
1638.86	16.3595
1642.75	6.01675
1646.64	15.8089
1650.53	15.0768
1654.42	5.71205
1658.3	13.6048
1662.18	1.32523
1666.07	11.1147
1669.94	13.2046
1673.82	7.56361
1677.7	18.2556
1681.57	12.5379
1685.44	7.75525
1689.31	15.4352
1693.18	13.4936
1697.05	11.5373
1700.92	13.3849
1704.78	15.1992
1708.64	15.0755
1712.5	11.1263
1716.36	7.19321
1720.21	10.8458
1724.07	14.4853
1727.92	7.73782
1731.77	8.51691
1735.62	12.1137
1739.47	13.8083
1743.32	5.2129
1747.16	15.2843
1751.01	8.659
1754.85	12.3052
1758.69	14.1561
1762.52	5.99758
1766.36	9.81731
1770.19	10.8955
1774.02	13.8913
1777.85	6.6572
1781.68	5.96684
1785.51	2.49121
1789.33	3.69017
1793.16	-0.723198
1796.98	10.8007
1800.8	5.43838
1804.62	8.45591
1808.43	3.93346
1812.25	2.21634
1816.06	9.90901
1819.87	5.29002
1823.68	1.58295
1827.49	7.28896
1831.3	4.47248
1835.1	18.5892
1838.9	9.12687
1842.71	14.7099
1846.51	10.8587
1850.3	4.21668
1854.1	6.90599
1857.89	13.2945
1861.69	14.0223
1865.48	11.0105
1869.27	2.45292
1873.05	8.76687
1876.84	11.3798
1880.62	6.60667
1884.4	3.73926
1888.19	4.56596
1891.96	10.1185
1895.74	5.55032
1899.52	8.34328
1903.29	6.5839
1907.06	-0.679771
1910.83	4.95641
1914.6	3.26418
1918.37	6.19102
1922.13	2.72434
1925.9	6.66553
1929.66	0.431992
1933.42	3.48179
1937.18	9.33559
1940.94	8.67267
1944.69	4.26156
1948.44	2.64397
1952.2	6.56568
1955.95	1.0583
1959.69	13.3366
1963.44	-1.66048
1967.19	-5.39111
1970.93	-1.64219
1974.67	8.62791
1978.41	8.55015
1982.15	2.83894
1985.89	4.59857
1989.62	7.27317
1993.35	8.05829
1997.09	11.6067
2000.82	10.4805
2004.55	11.2159
2008.27	2.69675
2012	5.24982
2015.72	9.63398
2019.44	12.2191
2023.16	-0.724808
2026.88	8.40466
2030.6	1.96497
2034.31	12.0562
2038.03	13.0343
2041.74	3.9306
2045.45	7.63544
2049.16	1.27115
2052.86	7.7477
2056.57	5.98947
2060.27	3.36906
2063.98	9.07337
2067.67	8.38499
2071.37	9.5461
2075.07	-0.363373
2078.77	2.64481
2082.46	7.52522
2086.15	5.91185
2089.84	11.5956
2093.53	7.9411
2097.22	8.98515
2100.9	3.50074
2104.59	6.34772
2108.27	6.38559
2111.95	3.61707
2115.63	11.0728
2119.31	7.35794
2122.98	0.817863
2126.66	7.25446
2130.33	11.8071
2134	8.93464
2137.67	-1.33162
2141.34	6.87143
2145	5.81853
2148.67	8.44151
2152.33	10.1357
2155.99	9.07884
2159.65	6.19974
2163.31	8.8266
2166.96	5.9883
2170.62	7.73458
2174.27	9.52361
2177.92	5.87361
2181.57	16.8026
2185.22	7.70539
2188.87	8.64786
2192.51	11.4534
2196.15	8.8468
2199.8	8.99454
2203.44	10.9795
2207.07	6.59556
2210.71	10.4476
2214.35	7.91732
2217.98	9.97019
2221.61	12.0321
2225.24	6.74848
2228.87	-0.401596
2232.5	1.65514
2236.12	6.50002
2239.75	14.1343
2243.37	2.32112
2246.99	1.60927
2250.61	1.83009
2254.23	18.8319
2257.85	9.77235
2261.46	7.22243
2265.07	8.39662
2268.68	6.77165
2272.29	13.6254
2275.9	-3.06812
2279.51	7.50554
2283.11	9.53726
2286.72	9.68077
2290.32	5.09732
2293.92	7.11352
2297.52	6.29653
2301.11	7.37656
2304.71	9.38701
2308.3	9.48035
2311.9	1.97491
2315.49	12.4631
2319.08	24.8257
2322.66	41.8897
2326.25	8.68433
2329.84	14.2975
2333.42	11.3858
2337	7.52439
2340.58	11.1912
2344.16	4.49622
2347.73	1.56347
2351.31	1.44374
2354.88	15.3419
2358.45	6.78793
2362.03	9.43456
2365.59	9.28109
2369.16	10.9905
2372.73	9.94312
2376.29	6.11799
2379.85	0.463417
2383.41	8.65927
2386.97	4.88198
2390.53	4.80768
2394.09	6.58973
2397.64	12.9843
2401.2	4.74549
2404.75	3.8987
2408.3	0.314552
2411.85	12.3618
2415.39	4.25719
2418.94	8.10831
2422.48	5.54359
2426.03	7.60393
2429.57	11.5435
2433.11	-0.205376
2436.64	3.77678
2440.18	4.99911
2443.72	7.16576
2447.25	10.2779
2450.78	5.00384
2454.31	6.28797
2457.84	12.2127
2461.37	2.99281
2464.89	6.94028
2468.42	18.3502
2471.94	6.26432
2475.46	14.7612
2478.98	-0.347267
2482.5	8.14225
2486.01	15.6382
2489.53	18.3444
2493.04	7.95489
2496.55	5.97392
2500.06	4.9706
2503.57	11.4189
2507.08	8.48988
2510.58	3.68362
2514.09	17.5083
2517.59	0.661125
2521.09	15.417
2524.59	7.82919
2528.09	10.5396
2531.59	0.338585
2535.08	-4.29421
2538.58	10.483
2542.07	7.74641
2545.56	6.90461
2549.05	6.10577
2552.54	5.30983
2556.02	9.16585
2559.51	1.03447
2562.99	5.87358
2566.47	7.0536
2569.95	8.27007
2573.43	-1.69827
2576.91	6.1062
2580.38	16.7947
2583.85	10.5788
2587.33	9.99845
2590.8	5.59179
2594.27	9.66551
2597.74	10.8799
2601.2	13.0852
2604.67	9.54565
2608.13	1.13389
2611.59	7.01639
2615.06	8.03288
2618.51	15.8135
2621.97	8.17755
2625.43	19.7372
2628.88	15.891
2632.33	12.0285
2635.79	9.10245
2639.24	16.6935
2642.69	3.18361
2646.13	3.07318
2649.58	6.77422
2653.02	17.1106
2656.47	10.2571
2659.91	8.15479
2663.35	8.8904
2666.79	6.77716
2670.22	14.0963
2673.66	8.20926
2677.09	6.11828
2680.52	5.92306
2683.95	8.55322
2687.39	6.54501
2690.81	7.40306
2694.24	6.43179
2697.66	2.64621
2701.09	8.19281
2704.51	5.36493
2707.93	-1.17688
2711.35	4.4382
2714.77	8.21631
2718.18	12.0185
2721.6	10.2544
2725.01	12.2315
2728.42	12.3524
2731.84	11.5438
2735.24	12.5985
2738.65	10.843
2742.06	-1.24208
2745.46	10.1044
2748.86	12.996
2752.27	11.1905
2755.67	10.3132
2759.07	4.71482
2762.46	3.82111
2765.86	15.1485
2769.25	5.73045
2772.65	7.60169
2776.04	14.1738
2779.43	15.0717
2782.82	7.47899
2786.2	12.1181
2789.59	2.64005
2792.98	15.7269
2796.36	6.24881
2799.74	11.8019
2803.12	9.82452
2806.5	5.97584
2809.88	3.06642
2813.25	11.3845
2816.63	0.0475464
2820	4.60737
2823.37	8.24074
2826.74	11.8823
2830.11	1.54385
2833.48	1.47764
2836.84	7.94957
2840.21	0.463882
2843.57	6.97012
2846.93	3.25168
2850.29	10.7558
2853.65	5.22696
2857.01	5.28139
2860.36	10.9604
2863.72	7.30067
2867.07	8.32303
2870.42	7.47089
2873.77	4.73048
2877.12	7.62285
2880.47	2.04525
2883.81	11.5298
2887.16	8.76141
2890.5	11.6492
2893.84	6.03178
2897.18	0.381119
2900.52	6.05981
2903.86	13.6182
2907.19	9.81131
2910.53	4.10123
2913.86	6.89938
2917.19	12.5282
2920.52	5.84058
2923.85	1.04182
2927.18	5.69057
2930.51	10.32
2933.83	10.2097
2937.15	9.13963
2940.48	0.528168
2943.8	0.40873
2947.11	2.17494
2950.43	17.111
2953.75	1.00087
2957.06	2.76428
2960.38	8.29665
2963.69	8.20226
2967	5.30029
2970.31	2.43032
2973.62	4.26786
2976.92	0.481224
2980.23	7.03051
2983.53	7.93955
2986.84	15.4262
2990.14	9.77795
2993.44	6.94757
2996.73	3.18134
3000.03	-5.28263
3003.33	3.17226
3006.62	8.81222
3009.91	9.75963
3013.2	6.00495
3016.49	8.84454
3019.78	3.19926
3023.07	9.80964
3026.35	9.82101
3029.64	-2.44241
3032.92	7.9556
3036.2	9.8514
3039.48	6.07188
3042.76	3.23608
3046.04	5.13309
3049.32	11.7684
3052.59	7.98755
3055.86	7.05029
3059.14	2.31424
3062.41	11.7725
3065.68	4.17198
3068.94	8.89318
3072.21	10.7454
3075.48	2.07236
3078.74	4.8871
3082	1.98052
3085.26	9.59383
3088.52	3.92282
3091.78	9.67251
3095.04	9.73439
3098.29	11.5603
3101.55	13.4571
3104.8	6.77584
3108.05	4.89718
3111.3	11.5692
3114.55	-2.73254
3117.8	8.67809
3121.04	11.526
3124.29	1.99297
3127.53	13.4149
3130.77	9.59228
3134.02	11.4892
3137.25	3.85223
3140.49	16.2279
3143.73	11.4444
3146.96	13.3359
3150.2	16.1896
3153.43	6.64841
3156.66	4.73194
3159.89	16.1755
3163.12	8.53583
3166.35	11.3928
3169.57	19.967
3172.8	17.0821
3176.02	10.3768
3179.24	-0.151337
3182.46	13.1713
3185.68	15.0479
3188.9	9.28371
3192.12	14.0061
3195.33	17.7736
3198.55	7.24895
3201.76	20.5372
3204.97	11.9273
3208.18	22.3622
3211.39	17.5743
3214.6	14.7001
3217.8	17.5436
3221.01	22.2906
3224.21	11.8231
3227.41	10.8804
3230.61	15.6496
3233.81	18.5267
3237.01	15.6885
3240.21	18.587
3243.4	13.8774
3246.59	15.8396
3249.79	13.9931
3252.98	19.7857
3256.17	17.0023
3259.36	27.579
3262.54	16.1846
3265.73	21.0061
3268.92	14.3503
3272.1	24.8788
3275.28	19.1619
3278.46	22.9969
3281.64	22.9869
3284.82	20.0929
3288	26.7456
3291.17	11.4518
3294.35	20.9637
3297.52	10.4582
3300.69	23.7707
3303.86	25.6795
3307.03	20.8958
3310.2	35.1255
3313.36	17.0097
3316.53	23.602
3319.69	28.2847
3322.85	29.1648
3326.02	23.417
3329.18	20.5199
3332.33	26.1408
3335.49	22.3159
3338.65	18.5082
3341.8	27.9245
3344.95	25.0758
3348.11	28.8604
3351.26	27.9627
3354.41	29.8925
3357.56	29.0103
3360.7	40.3903
3363.85	29.1637
3366.99	27.3668
3370.13	30.2934
3373.28	31.3416
3376.42	32.4067
3379.56	40.0911
3382.69	35.5063
3385.83	20.5123
3388.97	34.8384
3392.1	34.9863
3395.23	40.8111
3398.36	38.0815
3401.49	40.1654
3404.62	35.6233
3407.75	33.9356
3410.88	22.7429
3414	45.7943
3417.13	33.6042
3420.25	34.7355
3423.37	39.6733
3426.49	38.8621
3429.61	46.6198
3432.73	46.7226
3435.84	33.4296
3438.96	30.6128
3442.07	31.6313
3445.18	36.4634
3448.29	29.8219
3451.4	38.4363
3454.51	36.5431
3457.62	45.1232
3460.72	41.3041
3463.83	38.4396
3466.93	46.9724
3470.03	35.5405
3473.13	38.3293
3476.23	23.1596
3479.33	29.7877
3482.43	33.5751
3485.53	38.3061
3488.62	43.0405
3491.71	40.2403
3494.81	38.4228
3497.9	39.4322
3500.99	32.8875
3504.07	41.4361
3507.16	32.9931
3510.25	38.687
3513.33	36.803
3516.41	31.1846
3519.5	35.0785
3522.58	30.5605
3525.66	25.1786
3528.73	33.879
3531.81	42.5321
3534.89	43.6068
3537.96	30.456
3541.03	33.3685
3544.11	31.6148
3547.18	29.8403
3550.25	27.2058
3553.32	31.1555
3556.38	23.7483
3559.45	40.0126
3562.51	33.5696
3565.58	20.4615
3568.64	22.4895
3571.7	32.1409
3574.76	23.7213
3577.82	32.3764
3580.87	27.7438
3583.93	26.8948
3586.98	25.086
3590.04	19.4834
3593.09	15.7644
3596.14	30.0521
3599.19	22.528
3602.24	19.7444
3605.29	19.7906
3608.33	19.8279
3611.38	8.51622
3614.42	20.8378
3617.46	15.1948
3620.5	16.1702
3623.54	10.5452
3626.58	9.64297
3629.62	13.4592
3632.65	13.4974
3635.69	13.5295
3638.72	22.0561
3641.76	13.6566
3644.79	18.4419
3647.82	10.0806
3650.84	10.1581
3653.87	14.9532
3656.9	11.1517
3659.92	13.2161
3662.95	13.3899
3665.97	12.6014
3668.99	10.8217
3672.01	8.12007
3675.03	8.24957
3678.05	0.832115
3681.07	0.965935
3684.08	11.49
3687.1	13.5155
3690.11	13.6529
3693.12	7.16399
3696.13	11.0889
3699.14	6.46587
3702.15	7.54854
3705.16	0.0877991
3708.16	5.91356
3711.17	-0.621788
3714.17	8.0428
3717.17	2.43269
3720.17	10.1467
3723.17	4.52548
3726.17	2.7011
3729.17	5.62817
3732.16	1.88183
3735.16	17.1711
3738.15	-2.78428
3741.14	2.96114
3744.13	7.73952
3747.13	6.79841
3750.11	-1.75669
3753.1	8.69073
3756.09	5.83147
3759.07	6.7724
3762.06	3.91599
3765.04	3.89764
3768.02	0.0935745
3771	8.60159
3773.98	9.54223
3776.96	1.03558
3779.94	1.04505
3782.91	0.115051
3785.89	2.0194
3788.86	2.03923
3791.83	1.12047
3794.8	1.15931
3797.77	3.0928
3800.74	5.03194
3803.71	3.207
3806.68	-0.503349
3809.64	0.510559
3812.61	9.09187
3815.57	4.44495
3818.53	-1.1493
3821.49	5.55842
3824.45	9.43497
3827.41	-0.888466
3830.36	3.94536
3833.32	3.09383
3836.27	5.09817
3839.23	0.461685
3842.18	5.32521
3845.13	0.683502
3848.08	2.70199
3851.03	6.63418
3853.98	1.99763
3856.92	-1.68916
3859.87	3.21733
3862.81	3.3548
3865.75	6.3599
3868.7	3.6259
3871.64	0.882454
3874.57	1.01221
3877.51	12.6577
3880.45	3.18318
3883.39	3.29977
3886.32	2.44794
3889.25	3.51498
3892.18	0.736397
3895.12	8.53452
3898.05	-1.9461
3900.97	6.80109
3903.9	0.163918
3906.83	1.21379
3909.75	1.31702
3912.68	-0.504875
3915.6	7.2786
3918.52	11.2152
3921.44	3.64982
3924.36	-1.04292
3927.28	5.77756
3930.2	3.95986
3933.11	5.98022
3936.03	7.06918
3938.94	5.31072
3941.86	6.44882
3944.77	5.67147
3947.68	3.95
3950.59	2.24574
3953.49	10.1317
3956.4	13.2443
3959.31	13.5023
3962.21	8.02502
3965.12	9.2686
3968.02	-2.89751
3970.92	9.88577
3973.82	0.616928
3976.72	9.59511
3979.61	1.29372
3982.51	13.1752
3985.41	10.6547
3988.3	0.448265
3991.19	14.2934
3994.09	10.8313
3996.98	6.43592
3999.87	5.90133