File: Data/3-Raman/processed/bu32-AII-incC-fi04-s_150 (500nm)_532nm_edge_100%_x100_vis_lwd_h30um_15sx2_01.txt
#Acq. time (s)=	15
#Accumulations=	2
#Range (cm-¹)=	99...4000
#Windows=	1
#Auto scanning=	Off
#Autofocus=	Off
#Macrospot=	Off
#AutoExposure=	Off
#Spike filter=	Multiple accum.
#Delay time (s)=	2
#Binning=	1
#Readout mode=	Signal
#DeNoise=	Off
#ICS correction=	On
#Dark correction=	Off
#Inst. Process=	Off
#Detector Gain=	Best Dynamic
#Detector ADC=	50 kHz EM
#Detector EM gain=	400
#Detector temperature (°C)=	-60.28
#Instrument=	LabRAM HR Evol
#Detector=	SIN-EM FIVIS
#Objective=	x100_VIS_LWD
#Grating=	150 (500nm)
#ND Filter=	100%
#Laser=	532nm_Edge
#Hole=	30.0125
#Temperature=	0
#Range=	Visible
#StageXY=	75x50mm Scan+
#StageZ=	Z motor
#X (µm)=	0
#Y (µm)=	0
#Z (µm)=	14.1
#Full time(s)=	35
#Project=	21_11_26
#Sample=	BU32
#Site=
#Title=	BU32-A-incC-FI04-S_150 (500nm)_532nm_Edge_100%_x100_VIS_LWD_H30um_15sX2
#Remark=
#Date=	26.11.2021 18:33
#Acquired=	26.11.2021 18:33:28
#Base:Fit=	16.12.2021 14:46:28
#Base:Sub=	16.12.2021 14:46:31
102.91	168.935
107.534	183.362
112.156	0.236816
116.775	198.064
121.392	283.584
126.005	299.254
130.617	595.953
135.227	531.969
139.835	620.048
144.439	623.588
149.042	633.052
153.643	615.669
158.242	453.34
162.839	547.917
167.431	436.905
172.023	664.14
176.613	543.082
181.198	276.883
185.783	179.699
190.366	195.038
194.947	223.754
199.524	153.212
204.1	257.318
208.674	345.135
213.243	295.854
217.813	458.124
222.38	405.05
226.945	503.147
231.506	229.937
236.066	342.739
240.625	332.966
245.179	450.731
249.732	583.982
254.284	621.81
258.831	843.391
263.378	1126.75
267.923	1243.46
272.464	1379.6
277.004	1423.83
281.54	1175.95
286.076	641.913
290.61	573.297
295.139	440.83
299.669	344.977
304.196	72.5422
308.718	197.103
313.241	-0.952393
317.759	177.222
322.278	161.343
326.794	187.44
331.305	188.173
335.817	394.083
340.324	271.424
344.832	334.576
349.334	296.053
353.837	253.326
358.338	282.856
362.834	312.893
367.33	351.291
371.822	225.613
376.314	229.077
380.802	385.23
385.289	380.608
389.772	632.361
394.255	435.207
398.734	847.939
403.213	1045.12
407.688	939.033
412.162	1055.26
416.632	1079.84
421.102	1111.58
425.568	1250.53
430.033	1449.71
434.495	1885.65
438.956	2214.24
443.413	2525.68
447.87	2789.12
452.323	3137.23
456.776	3369.98
461.224	3964.73
465.673	4110.68
470.117	3735.74
474.561	3139.84
479.001	2574.8
483.438	2095.93
487.876	1977.41
492.309	1735.77
496.742	1722.28
501.172	1550.28
505.601	1324.04
510.025	1156.95
514.448	979.152
518.871	701.708
523.289	592.32
527.707	639.182
532.121	456.013
536.533	911.633
540.945	995.866
545.353	1488.96
549.758	1996.52
554.164	2671.14
558.565	3774.14
562.965	3767.45
567.364	2789.43
571.759	1999.3
576.151	1867.21
580.544	2023.19
584.933	2237.53
589.319	2848.16
593.706	2992.21
598.088	2886.75
602.468	2435.14
606.848	2733.74
611.224	2347.5
615.598	2423.54
619.972	2136.35
624.341	1672.15
628.709	1597.56
633.074	1267.67
637.44	972.976
641.801	745.392
646.16	602.584
650.517	585.783
654.874	582.652
659.227	552.383
663.578	516.614
667.927	610.599
672.275	342.945
676.62	374.828
680.962	322.081
685.302	198.652
689.643	266.658
693.979	151.066
698.313	183.99
702.645	57.7238
706.975	156.449
711.305	356.627
715.631	336.126
719.955	184.557
724.276	314.384
728.596	127.357
732.913	95.7881
737.231	11.3019
741.544	108.225
745.856	6.56042
750.165	88.366
754.472	103.695
758.778	120.528
763.081	31.8269
767.384	-16.9509
771.683	35.1318
775.98	57.9943
780.275	83.3246
784.568	6.23193
788.859	129.463
793.147	61.9916
797.434	63.1338
801.719	188.27
806.004	40.6925
810.284	103.83
814.563	79.2834
818.839	46.2261
823.114	-7.73755
827.386	89.5287
831.657	179.383
835.925	179.039
840.192	134.49
844.456	100.778
848.719	141.528
852.979	30.2167
857.237	179.211
861.493	156.183
865.748	228.697
870	122.389
874.25	219.202
878.499	189.227
882.745	198.417
886.989	229.826
891.231	195.818
895.471	278.622
899.71	342.582
903.946	160.06
908.18	323.321
912.412	369.203
916.642	485.37
920.87	558.751
925.096	955.542
929.321	1264.36
933.543	1702.3
937.763	2247.25
941.981	3050.96
946.197	4067.5
950.412	5274.69
954.622	6386.23
958.832	8039.52
963.04	10237.5
967.246	13338.7
971.451	16813.4
975.653	19011.7
979.853	18760.1
984.052	16624.6
988.248	13691.3
992.442	11034.7
996.633	9360.2
1000.82	7732.74
1005.01	6412.39
1009.2	5202.45
1013.38	4577.77
1017.57	3897.73
1021.75	3800.5
1025.92	3350.75
1030.1	3079.08
1034.27	2905.1
1038.45	2795.02
1042.62	2756.13
1046.78	2534.13
1050.95	2476.22
1055.12	2498.2
1059.28	2433.28
1063.44	2788.38
1067.6	3201.28
1071.75	4039.95
1075.91	5498.9
1080.06	5530.47
1084.21	3860.34
1088.36	2873.73
1092.51	2396.84
1096.65	2368.5
1100.8	2335.68
1104.94	2327.01
1109.08	2308.77
1113.21	2028.26
1117.35	1913.35
1121.48	1891.05
1125.61	1615.06
1129.74	1583.74
1133.87	1403.75
1137.99	1401.83
1142.12	1277.5
1146.24	1160.52
1150.36	869.271
1154.48	711.109
1158.59	772.714
1162.71	850.384
1166.82	754.997
1170.93	663.245
1175.04	439.972
1179.14	292.97
1183.25	238.823
1187.35	327.165
1191.45	222.415
1195.55	201.557
1199.65	203.781
1203.74	139.405
1207.83	67.173
1211.92	239.505
1216.01	160.546
1220.1	91.2631
1224.19	158.249
1228.27	172.163
1232.35	89.5653
1236.43	187.34
1240.51	90.0612
1244.58	161.351
1248.66	56.5016
1252.73	128.191
1256.8	132.355
1260.87	151.786
1264.93	111.465
1269	99.4161
1273.06	18.4133
1277.12	57.6519
1281.18	92.9063
1285.23	-12.7784
1289.29	121.616
1293.34	31.4868
1297.39	-34.7731
1301.44	15.6868
1305.49	32.6559
1309.53	38.4508
1313.58	92.476
1317.62	46.218
1321.66	27.9102
1325.7	15.17
1329.73	26.4008
1333.77	-15.7266
1337.8	132.256
1341.83	107.434
1345.86	24.6299
1349.88	211.251
1353.91	87.7826
1357.93	13.495
1361.95	90.0753
1365.97	31.0353
1369.99	73.2029
1374	180.716
1378.02	153.132
1382.03	32.278
1386.04	126.807
1390.05	76.8463
1394.05	92.2196
1398.06	116.033
1402.06	36.3195
1406.06	123.01
1410.06	81.7428
1414.05	36.606
1418.05	62.4674
1422.04	95.2291
1426.03	88.3221
1430.02	182.439
1434.01	63.3564
1438	129.871
1441.98	55.1932
1445.96	89.8907
1449.94	119.541
1453.92	113.416
1457.9	38.1375
1461.87	129.203
1465.85	87.799
1469.82	14.9297
1473.78	61.1965
1477.75	133.672
1481.72	62.7439
1485.68	59.4106
1489.65	108.749
1493.61	95.5785
1497.56	-9.16418
1501.52	-11.3262
1505.47	76.1788
1509.43	171.638
1513.38	14.5139
1517.33	61.4734
1521.27	132.753
1525.22	88.6185
1529.16	142.514
1533.11	99.5806
1537.05	80.8994
1540.98	95.1858
1544.92	119.137
1548.86	155.657
1552.79	168.89
1556.72	149.004
1560.65	84.3768
1564.58	128.989
1568.5	179.202
1572.43	124.857
1576.35	174.837
1580.27	188.962
1584.19	132.617
1588.1	148.499
1592.02	148.894
1595.93	180.978
1599.84	224.513
1603.75	212.372
1607.66	121.747
1611.57	102.201
1615.47	195.823
1619.37	212.87
1623.27	114.895
1627.17	134.893
1631.07	151.188
1634.97	230.067
1638.86	77.2079
1642.75	234.822
1646.64	139.868
1650.53	181.039
1654.42	157.048
1658.3	203.937
1662.18	184.511
1666.07	174.403
1669.94	171.812
1673.82	176.495
1677.7	95.519
1681.57	163.819
1685.44	64.665
1689.31	129.543
1693.18	40.7681
1697.05	150.03
1700.92	223.421
1704.78	132.288
1708.64	181.102
1712.5	251.283
1716.36	287.041
1720.21	214.872
1724.07	199.635
1727.92	138.184
1731.77	123.771
1735.62	109.495
1739.47	80.161
1743.32	145.995
1747.16	145.458
1751.01	76.8385
1754.85	83.9934
1758.69	117.711
1762.52	-41.6251
1766.36	163
1770.19	21.7217
1774.02	14.5985
1777.85	151.737
1781.68	22.0771
1785.51	161.969
1789.33	117.268
1793.16	76.1913
1796.98	111.913
1800.8	100.682
1804.62	67.037
1808.43	55.8116
1812.25	84.952
1816.06	18.6411
1819.87	101.821
1823.68	65.8205
1827.49	125.829
1831.3	7.25397
1835.1	109.016
1838.9	5.19019
1842.71	118.614
1846.51	32.3892
1850.3	62.8046
1854.1	104.795
1857.89	147.268
1861.69	92.189
1865.48	39.0807
1869.27	129.281
1873.05	68.1838
1876.84	91.6863
1880.62	125.32
1884.4	57.9137
1888.19	91.9811
1891.96	14.9468
1895.74	51.1444
1899.52	-33.2103
1903.29	117.506
1907.06	83.473
1910.83	55.0255
1914.6	9.38849
1918.37	-8.58826
1922.13	66.4655
1925.9	39.9821
1929.66	101.731
1933.42	34.5543
1937.18	63.9698
1940.94	109.324
1944.69	55.6568
1948.44	16.7594
1952.2	35.108
1955.95	90.6269
1959.69	4.73157
1963.44	102.565
1967.19	90.4316
1970.93	30.0879
1974.67	108.232
1978.41	81.0724
1982.15	26.6487
1985.89	-19.4083
1989.62	37.172
1993.35	74.7716
1997.09	138.976
2000.82	95.0931
2004.55	59.7667
2008.27	94.6791
2012	119.026
2015.72	73.4092
2019.44	91.8206
2023.16	91.4984
2026.88	126.639
2030.6	40.0306
2034.31	81.2029
2038.03	87.9655
2041.74	91.8801
2045.45	83.8052
2049.16	36.3787
2052.86	74.3129
2056.57	75.6849
2060.27	94.1081
2063.98	108.657
2067.67	173.184
2071.37	89.688
2075.07	105.593
2078.77	79.0983
2082.46	104.465
2086.15	46.2437
2089.84	35.8849
2093.53	90.0721
2097.22	113.217
2100.9	91.5547
2104.59	58.3517
2108.27	69.6064
2111.95	78.8365
2115.63	98.2578
2119.31	-26.5117
2122.98	70.4145
2126.66	47.2751
2130.33	130.586
2134	35.9064
2137.67	73.572
2141.34	62.042
2145	60.5248
2148.67	88.3807
2152.33	87.6604
2155.99	75.9891
2159.65	36.9446
2163.31	88.6244
2166.96	21.6908
2170.62	109.162
2174.27	104.015
2177.92	39.9484
2181.57	43.4264
2185.22	39.5861
2188.87	33.2974
2192.51	-15.3466
2196.15	84.7503
2199.8	75.9111
2203.44	58.0625
2207.07	22.0857
2210.71	107.788
2214.35	105.993
2217.98	91.4191
2221.61	8.87439
2225.24	21.7904
2228.87	2.43939
2232.5	64.2492
2236.12	106.022
2239.75	90.5131
2243.37	56.3922
2246.99	109.411
2250.61	42.6802
2254.23	73.6649
2257.85	60.0609
2261.46	104.357
2265.07	70.0134
2268.68	64.748
2272.29	69.1055
2275.9	14.8155
2279.51	10.0621
2283.11	81.0973
2286.72	72.8884
2290.32	105.303
2293.92	66.6887
2297.52	-22.0938
2301.11	76.556
2304.71	113.563
2308.3	57.4956
2311.9	3.15906
2315.49	60.5263
2319.08	32.4167
2322.66	24.9462
2326.25	27.2988
2329.84	34.2792
2333.42	157.255
2337	31.7972
2340.58	47.7885
2344.16	107.808
2347.73	57.7164
2351.31	56.4384
2354.88	80.3611
2358.45	13.6326
2362.03	60.7111
2365.59	97.3704
2369.16	32.8619
2372.73	39.2109
2376.29	40.8464
2379.85	36.0488
2383.41	23.1081
2386.97	66.4237
2390.53	17.0128
2394.09	35.8294
2397.64	14.5711
2401.2	44.0769
2404.75	-29.4384
2408.3	52.0633
2411.85	29.4965
2415.39	69.5609
2418.94	21.7271
2422.48	-26.0656
2426.03	75.5228
2429.57	-40.1653
2433.11	60.3414
2436.64	17.8028
2440.18	38.3499
2443.72	23.6783
2447.25	67.7693
2450.78	20.5656
2454.31	-0.451416
2457.84	-60.753
2461.37	16.4071
2464.89	24.8336
2468.42	-26.961
2471.94	48.4326
2475.46	29.7548
2478.98	-6.0304
2482.5	50.7532
2486.01	131.573
2489.53	35.7039
2493.04	56.1436
2496.55	42.2159
2500.06	30.541
2503.57	87.7975
2507.08	36.3785
2510.58	70.677
2514.09	43.5173
2517.59	46.4095
2521.09	15.1443
2524.59	59.2337
2528.09	8.01312
2531.59	30.1102
2535.08	62.4665
2538.58	55.3986
2542.07	53.1744
2545.56	51.417
2549.05	90.7144
2552.54	65.4119
2556.02	30.1458
2559.51	17.4898
2562.99	44.7156
2566.47	58.5058
2569.95	-4.72717
2573.43	21.69
2576.91	58.7316
2580.38	81.1199
2583.85	48.9957
2587.33	8.14246
2590.8	25.6134
2594.27	98.7661
2597.74	62.485
2601.2	82.6682
2604.67	92.3149
2608.13	40.0234
2611.59	29.015
2615.06	97.9887
2618.51	36.7272
2621.97	68.2195
2625.43	32.2505
2628.88	0.831421
2632.33	83.5383
2635.79	77.6194
2639.24	97.2891
2642.69	98.5313
2646.13	93.8256
2649.58	77.5992
2653.02	72.6221
2656.47	63.5928
2659.91	68.6268
2663.35	106.667
2666.79	109.465
2670.22	80.1678
2673.66	82.9156
2677.09	102.687
2680.52	61.6595
2683.95	107.899
2687.39	49.8281
2690.81	38.1783
2694.24	70.6577
2697.66	-29.334
2701.09	71.0659
2704.51	92.3238
2707.93	53.1491
2711.35	55.5594
2714.77	-1.39899
2718.18	72.106
2721.6	95.572
2725.01	46.4243
2728.42	116.786
2731.84	13.4224
2735.24	101.663
2738.65	42.0094
2742.06	17.816
2745.46	84.4584
2748.86	36.4125
2752.27	88.9083
2755.67	122.555
2759.07	1.71051
2762.46	89.8535
2765.86	61.8932
2769.25	107.26
2772.65	33.7106
2776.04	59.9497
2779.43	43.6078
2782.82	45.9586
2786.2	26.5739
2789.59	5.2785
2792.98	63.8505
2796.36	54.6689
2799.74	93.3567
2803.12	98.9785
2806.5	110.208
2809.88	14.6073
2813.25	57.5872
2816.63	125.657
2820	88.9504
2823.37	-7.29156
2826.74	39.411
2830.11	28.3135
2833.48	32.2419
2836.84	120.162
2840.21	43.3356
2843.57	105.482
2846.93	24.3588
2850.29	32.9957
2853.65	-0.163452
2857.01	85.1511
2860.36	61.3125
2863.72	82.4639
2867.07	76.5012
2870.42	47.0518
2873.77	61.6089
2877.12	97.7762
2880.47	20.0634
2883.81	40.1454
2887.16	97.8978
2890.5	73.5799
2893.84	-31.1654
2897.18	108.561
2900.52	24.1135
2903.86	40.6674
2907.19	59.9301
2910.53	61.1138
2913.86	44.2274
2917.19	58.4803
2920.52	54.5895
2923.85	-2.33221
2927.18	18.2006
2930.51	61.238
2933.83	42.7118
2937.15	22.1607
2940.48	37.4481
2943.8	27.2581
2947.11	-13.9709
2950.43	73.7446
2953.75	35.3154
2957.06	78.6755
2960.38	47.0235
2963.69	44.5601
2967	-10.3858
2970.31	-24.7159
2973.62	45.5159
2976.92	1.33936
2980.23	-37.0877
2983.53	97.0265
2986.84	13.4656
2990.14	67.9289
2993.44	10.6722
2996.73	54.8904
3000.03	54.0618
3003.33	79.536
3006.62	11.8825
3009.91	44.9443
3013.2	148.713
3016.49	55.6642
3019.78	92.5832
3023.07	24.8024
3026.35	55.1006
3029.64	64.658
3032.92	17.5029
3036.2	2.38086
3039.48	39.2208
3042.76	0.397461
3046.04	171.694
3049.32	99.7574
3052.59	113.017
3055.86	79.8574
3059.14	44.7144
3062.41	57.5954
3065.68	100.041
3068.94	42.7134
3072.21	18.3666
3075.48	113.59
3078.74	68.5367
3082	153.024
3085.26	112.335
3088.52	128.485
3091.78	112.659
3095.04	93.0638
3098.29	89.1913
3101.55	101.212
3104.8	38.8552
3108.05	128.211
3111.3	77.5693
3114.55	221.705
3117.8	168.895
3121.04	130.377
3124.29	185.187
3127.53	183.786
3130.77	137.561
3134.02	87.5234
3137.25	213.777
3140.49	197.956
3143.73	212.622
3146.96	173.904
3150.2	198.191
3153.43	239.68
3156.66	238.204
3159.89	278.741
3163.12	223.831
3166.35	303.469
3169.57	312.378
3172.8	331.693
3176.02	286.064
3179.24	367.231
3182.46	326.257
3185.68	386.427
3188.9	425.434
3192.12	411.005
3195.33	397.54
3198.55	427.887
3201.76	371.53
3204.97	401.909
3208.18	431.377
3211.39	408.573
3214.6	329.752
3217.8	380.434
3221.01	355.971
3224.21	501.844
3227.41	579.391
3230.61	470.531
3233.81	515.917
3237.01	518.403
3240.21	540.286
3243.4	466.114
3246.59	497.718
3249.79	673.284
3252.98	584.117
3256.17	528.308
3259.36	599.383
3262.54	585.313
3265.73	623.553
3268.92	617.643
3272.1	625.913
3275.28	680.906
3278.46	649.921
3281.64	610.016
3284.82	633.803
3288	624.234
3291.17	684.159
3294.35	689.866
3297.52	640.267
3300.69	652.66
3303.86	752.09
3307.03	755.849
3310.2	762.302
3313.36	653.509
3316.53	681.526
3319.69	815.729
3322.85	686.162
3326.02	756.683
3329.18	758.994
3332.33	794.464
3335.49	837.598
3338.65	902.579
3341.8	850.654
3344.95	902.6
3348.11	880.555
3351.26	913.703
3354.41	895.954
3357.56	979.32
3360.7	908.247
3363.85	1015.62
3366.99	985.442
3370.13	1052.55
3373.28	979.241
3376.42	1097.78
3379.56	953.067
3382.69	1107.89
3385.83	1058.59
3388.97	1064.33
3392.1	1135.46
3395.23	1107.16
3398.36	1163.57
3401.49	1080.08
3404.62	1214.93
3407.75	1261.02
3410.88	1255.06
3414	1202.42
3417.13	1232.06
3420.25	1201.56
3423.37	1150.81
3426.49	1177.85
3429.61	1236.05
3432.73	1188.95
3435.84	1248.36
3438.96	1244.26
3442.07	1292.98
3445.18	1329.26
3448.29	1320.25
3451.4	1274.99
3454.51	1417.18
3457.62	1244.01
3460.72	1353.37
3463.83	1284.78
3466.93	1210.53
3470.03	1233.85
3473.13	1204.63
3476.23	1206.53
3479.33	1190.62
3482.43	1328.08
3485.53	1255.67
3488.62	1307.28
3491.71	1100.63
3494.81	1253.36
3497.9	1168.23
3500.99	1123.61
3504.07	1105.52
3507.16	1046.62
3510.25	1186.56
3513.33	1075.3
3516.41	1122.7
3519.5	1004.42
3522.58	974.588
3525.66	1048.96
3528.73	1003.57
3531.81	914.721
3534.89	976.519
3537.96	892.009
3541.03	970.116
3544.11	910.367
3547.18	822.947
3550.25	932.411
3553.32	861.95
3556.38	890.609
3559.45	897.901
3562.51	778.362
3565.58	708.575
3568.64	768.348
3571.7	695.096
3574.76	665.578
3577.82	701.618
3580.87	600.985
3583.93	684.27
3586.98	597.667
3590.04	531.982
3593.09	568.56
3596.14	567.212
3599.19	538.293
3602.24	582.368
3605.29	450.201
3608.33	514.904
3611.38	469.874
3614.42	348.316
3617.46	408.233
3620.5	378.518
3623.54	372.528
3626.58	410.943
3629.62	322.226
3632.65	326.811
3635.69	320.073
3638.72	263.824
3641.76	333.889
3644.79	247.945
3647.82	247.969
3650.84	240.165
3653.87	232.561
3656.9	68.4395
3659.92	226.479
3662.95	141.797
3665.97	207.56
3668.99	129.63
3672.01	153.754
3675.03	70.4299
3678.05	123.968
3681.07	69.0279
3684.08	50.8434
3687.1	-11.7762
3690.11	69.4055
3693.12	30.48
3696.13	84.3856
3699.14	66.1274
3702.15	0.638672
3705.16	-6.07623
3708.16	-8.05188
3711.17	-8.22137
3714.17	35.2911
3717.17	10.2442
3720.17	6.18494
3723.17	60.0856
3726.17	12.0609
3729.17	17.2748
3732.16	2.43091
3735.16	0.836792
3738.15	2.00848
3741.14	10.7205
3744.13	49.7736
3747.13	46.8737
3750.11	-0.791199
3753.1	30.3846
3756.09	48.2137
3759.07	103.04
3762.06	29.757
3765.04	-7.49945
3768.02	45.2541
3771	-25.0209
3773.98	24.9497
3776.96	59.7861
3779.94	36.9808
3782.91	82.2319
3785.89	65.116
3788.86	28.2056
3791.83	0.768005
3794.8	51.761
3797.77	76.3538
3800.74	64.1461
3803.71	65.2177
3806.68	104.065
3809.64	108.899
3812.61	42.8492
3815.57	77.8837
3818.53	24.9365
3821.49	92.1046
3824.45	86.3868
3827.41	37.0721
3830.36	104.24
3833.32	127.778
3836.27	138.063
3839.23	143.577
3842.18	56.8109
3845.13	80.1747
3848.08	137.774
3851.03	110.615
3853.98	122.458
3856.92	115.153
3859.87	67.6262
3862.81	96.4042
3865.75	123.166
3868.7	142.2
3871.64	90.1616
3874.57	98.3317
3877.51	122.675
3880.45	115.147
3883.39	123.735
3886.32	147.482
3889.25	132.599
3892.18	82.9268
3895.12	80.1816
3898.05	70.466
3900.97	106.68
3903.9	121.562
3906.83	91.0085
3909.75	81.5446
3912.68	119.902
3915.6	99.3943
3918.52	147.83
3921.44	157.8
3924.36	93.5181
3927.28	112.487
3930.2	114.874
3933.11	79.665
3936.03	57.8853
3938.94	104.058
3941.86	102.278
3944.77	92.5569
3947.68	75.0085
3950.59	45.8293
3953.49	77.762
3956.4	74.0731
3959.31	37.6495
3962.21	82.4572
3965.12	98.3341
3968.02	26.7579
3970.92	86.3489
3973.82	110.25
3976.72	27.2986
3979.61	-51.2353
3982.51	17.8624
3985.41	-16.1497
3988.3	35.0898
3991.19	-7.25867
3994.09	28.8787
3996.98	17.731
3999.87	-11.066