File: Data/3-Raman/processed/bu32-b-ff2-fi03-v_1800 (450-850nm)_532nm_edge_100%_x100_vis_lwd_h30um_30sx2_01.txt
#Acq. time (s)=	30
#Accumulations=	2
#Range (cm-¹)=	1200...2999
#Windows=	5
#Auto scanning=	Off
#Autofocus=	Off
#Macrospot=	Off
#AutoExposure=	Off
#Spike filter=	Multiple accum.
#Delay time (s)=	2
#Binning=	1
#Readout mode=	Signal
#DeNoise=	Off
#ICS correction=	On
#Dark correction=	Off
#Inst. Process=	Off
#Detector Gain=	Best Dynamic
#Detector ADC=	50 kHz EM
#Detector EM gain=	150
#Detector temperature (°C)=	-60.09
#Instrument=	LabRAM HR Evol
#Detector=	SIN-EM FIVIS
#Objective=	x100_VIS_LWD
#Grating=	1800 (450-850nm)
#ND Filter=	100%
#Laser=	532nm_Edge
#Hole=	30.0125
#Temperature=	40
#Range=	Visible
#StageXY=	75x50mm Scan+
#StageZ=	Z motor
#X (µm)=	0
#Y (µm)=	0
#Z (µm)=	80.2
#Full time(mm:ss)=	5:26
#Project=	21_08_11
#Sample=	BU32
#Site=
#Title=	BU32-B-FF2-FI03-V_1800 (450-850nm)_532nm_Edge_100%_x100_VIS_LWD_H30um_30sX2
#Remark=
#Date=	13.08.2021 15:49
#Acquired=	13.08.2021 15:49:24
#Base:Fit=	16.12.2021 15:06:49
#Base:Sub=	16.12.2021 15:06:50
1200.05	-0.677521
1201.44	-1.28088
1202.83	-0.596161
1204.22	-5.19916
1205.61	-1.33554
1207	-8.25238
1208.39	-5.23651
1209.78	4.3353
1211.16	2.85135
1212.55	2.49002
1213.94	-0.681
1215.33	-5.87146
1216.71	-2.00082
1218.1	-0.105103
1219.49	0.941467
1220.87	-3.23929
1222.26	9.06223
1223.64	-9.40695
1225.03	7.49567
1226.41	17.1552
1227.79	-1.52121
1229.18	-2.60391
1230.56	-2.16321
1231.94	0.479218
1233.33	1.65018
1234.71	3.06238
1236.09	3.29059
1237.47	5.09995
1238.86	-2.50577
1240.24	-7.63971
1241.62	2.91733
1243	15.7757
1244.38	9.62198
1245.76	19.8277
1247.14	7.36465
1248.52	18.8153
1249.9	8.45828
1251.27	18.728
1252.65	10.2188
1254.03	7.39417
1255.41	12.8234
1256.79	24.5693
1258.16	28.7372
1259.54	20.6894
1260.92	31.8879
1262.29	47.1746
1263.67	112.441
1265.04	83.2056
1266.42	44.7549
1267.79	29.7705
1269.17	26.037
1270.54	24.75
1271.92	31.3087
1273.29	22.5345
1274.66	27.0463
1276.04	29.5982
1277.41	34.3271
1278.78	39.0533
1280.15	49.6453
1281.53	92.1884
1282.9	301.029
1284.27	2121.31
1285.64	376.111
1287.01	89.673
1288.38	58.1605
1289.75	52.3297
1291.12	40.8303
1292.49	38.8413
1293.86	46.8504
1295.23	33.6458
1296.6	41.6276
1297.96	28.8232
1299.33	24.5689
1300.7	34.2992
1302.07	17.717
1303.43	31.4611
1304.8	13.5708
1306.17	15.5008
1307.53	27.2773
1308.9	21.2097
1310.26	23.5217
1311.63	23.7971
1312.99	18.6646
1314.36	18.8035
1315.72	27.5588
1317.08	30.8663
1318.45	23.6999
1319.81	18.5528
1321.17	23.6428
1322.53	12.9423
1323.9	20.4389
1325.26	20.384
1326.62	26.3486
1327.98	28.2856
1329.34	30.6709
1330.7	23.1239
1332.06	22.6757
1333.42	18.0694
1334.78	22.0087
1336.14	25.0165
1337.5	30.1811
1338.86	22.7407
1340.22	20.8415
1341.58	23.9898
1342.93	33.2124
1344.29	31.2168
1345.65	22.5628
1347	27.3375
1348.36	25.1686
1349.72	19.7862
1351.07	15.3972
1352.43	25.0493
1353.78	27.1554
1355.14	28.8435
1356.49	11.3322
1357.85	41.327
1359.2	19.3824
1360.56	22.253
1361.91	25.377
1363.26	23.5001
1364.61	32.8806
1365.97	31.5835
1367.32	26.2649
1368.67	34.78
1370.02	65.7395
1371.37	36.4794
1372.72	44.3903
1374.07	24.7776
1375.42	41.359
1376.77	29.7532
1378.12	45.9372
1379.47	58.331
1380.82	39.2366
1382.17	75.6324
1383.52	83.4431
1384.87	110.609
1386.21	389.483
1387.56	3478.35
1388.91	436.667
1390.26	147.704
1391.6	67.4157
1392.95	54.9659
1394.3	42.6779
1395.64	54.201
1396.99	38.729
1398.33	38.886
1399.68	42.2223
1401.02	60.9731
1402.37	53.5796
1403.71	30.0431
1405.05	55.6462
1406.39	54.5538
1407.74	92.7286
1409.08	251.99
1410.42	85.6736
1411.76	43.5861
1413.11	42.4406
1414.45	30.1264
1415.79	24.161
1417.13	26.5131
1418.47	24.6339
1419.81	23.5209
1421.15	25.464
1422.49	29.3807
1423.83	25.1223
1425.17	35.7118
1426.51	27.5406
1427.84	26.2031
1429.18	17.2286
1430.52	13.6829
1431.86	22.0728
1433.19	19.6117
1434.53	38.2659
1435.87	14.7537
1437.2	13.7134
1438.54	23.1236
1439.87	22.4778
1441.21	18.4681
1442.54	27.8765
1443.88	13.4914
1445.21	14.8506
1446.55	13.8072
1447.88	22.0496
1449.21	10.9183
1450.55	21.0924
1451.88	13.8928
1453.21	16.141
1454.54	8.00101
1455.88	15.3475
1457.21	17.3266
1458.54	8.23462
1459.87	11.3805
1461.2	12.3271
1462.53	10.0764
1463.86	15.3487
1465.19	9.58972
1466.52	12.5644
1467.85	8.56619
1469.18	15.6639
1470.51	11.4381
1471.83	8.30032
1473.16	9.28967
1474.49	9.36481
1475.82	3.25671
1477.14	11.3256
1478.47	8.1835
1479.79	8.9563
1481.12	9.83621
1482.45	20.3045
1483.77	10.1927
1485.1	13.0233
1486.42	15.852
1487.75	7.66815
1489.07	9.51962
1490.39	3.42325
1491.72	12.512
1493.04	6.4805
1494.36	8.6218
1495.69	2.26233
1497.01	15.3426
1498.33	6.33606
1499.65	10.5612
1500.97	7.51096
1502.29	2.43103
1503.62	9.43781
1504.93	6.43909
1506.26	16.365
1507.58	13.494
1508.89	6.52307
1510.21	3.53345
1511.53	11.0917
1512.85	9.66327
1514.17	20.9558
1515.49	-0.445587
1516.81	11.5097
1518.12	6.69504
1519.44	4.85385
1520.76	5.95844
1522.07	5.95593
1523.39	6.67834
1524.71	6.62479
1526.02	4.94601
1527.34	7.9809
1528.65	5.91968
1529.97	8.93481
1531.28	7.17819
1532.59	8.4277
1533.91	9.67941
1535.22	9.49048
1536.54	11.0796
1537.85	5.88959
1539.16	16.3365
1540.47	11
1541.79	13.7051
1543.1	11.3983
1544.41	7.51694
1545.72	5.93127
1547.03	4.10422
1548.34	3.10858
1549.65	12.8568
1550.96	5.94287
1552.27	13.11
1553.58	10.7449
1554.89	8.44305
1556.2	8.4884
1557.5	4.55499
1558.81	8.17972
1560.12	7.02435
1561.43	11.2014
1562.74	5.36835
1564.04	4.64468
1565.35	7.82492
1566.65	9.39157
1567.96	6.58353
1569.27	8.47736
1570.57	9.56943
1571.88	6.4729
1573.18	5.30093
1574.48	3.62463
1575.79	12.8201
1577.09	10.4482
1578.4	16.2105
1579.7	11.3724
1581	5.34384
1582.3	8.20142
1583.61	6.20099
1584.91	6.31097
1586.21	14.1148
1587.51	6.09195
1588.81	9.31519
1590.11	7.48373
1591.41	12.5138
1592.72	10.2102
1594.01	12.8565
1595.31	12.9336
1596.61	5.06271
1597.91	3.12573
1599.21	10.8131
1600.51	9.33792
1601.81	1.76794
1603.1	6.92307
1604.4	0.077179
1605.7	6.20438
1607	6.99695
1608.29	3.19012
1609.59	8.38489
1610.88	10.8859
1612.18	3.92822
1613.48	6.74567
1614.77	8.19675
1616.07	6.56128
1617.36	5.59442
1618.65	4.577
1619.95	6.84439
1621.24	7.29361
1622.54	7.09637
1623.83	6.64224
1625.12	4.07642
1626.41	10.3904
1627.56	6.08023
1628.87	11.0537
1630.17	11.0108
1631.48	7.24863
1632.79	5.39685
1634.1	6.4469
1635.4	7.42245
1636.71	12.1971
1638.01	17.0406
1639.32	11.1848
1640.62	3.47491
1641.93	6.39215
1643.23	5.41116
1644.54	14.1764
1645.84	1.49234
1647.15	8.29205
1648.45	4.56268
1649.75	4.74518
1651.05	12.0027
1652.36	7.10199
1653.66	9.15649
1654.96	5.45438
1656.26	8.78192
1657.56	5.78537
1658.86	10.5752
1660.16	14.53
1661.46	8.92816
1662.77	12.3597
1664.07	11.1053
1665.36	2.40677
1666.66	6.01971
1667.96	9.05429
1669.26	8.49893
1670.56	12.7279
1671.86	2.88812
1673.15	15.8242
1674.45	5.1886
1675.75	10.2966
1677.05	12.3285
1678.34	9.15155
1679.64	10.0348
1680.94	13.9197
1682.23	12.9812
1683.53	5.09134
1684.82	7.99472
1686.12	7.11816
1687.41	12.0989
1688.71	9.95984
1690	8.84131
1691.29	4.11478
1692.59	9.94254
1693.88	7.65662
1695.17	10.6217
1696.47	7.80124
1697.76	5.56012
1699.05	9.4032
1700.34	14.3123
1701.63	8.26962
1702.92	6.17224
1704.21	8.19858
1705.5	10.1587
1706.79	5.93619
1708.08	10.4297
1709.37	9.19962
1710.66	11.3003
1711.95	7.43311
1713.24	1.98978
1714.53	6.72879
1715.82	15.6406
1717.11	6.42001
1718.39	7.8927
1719.68	5.01462
1720.97	7.71899
1722.25	9.33908
1723.54	10.1531
1724.83	8.89124
1726.11	6.73193
1727.4	5.69763
1728.68	4.60788
1729.97	2.85712
1731.25	8.98077
1732.54	0.172363
1733.82	1.64932
1735.1	3.16998
1736.39	3.98077
1737.67	5.72122
1738.95	5.40216
1740.24	5.83014
1741.52	-0.172577
1742.8	2.63116
1744.08	1.50723
1745.36	3.43552
1746.65	7.90384
1747.93	1.98019
1749.21	-4.52524
1750.49	3.42325
1751.77	-2.4819
1753.05	-0.838196
1754.33	8.46826
1755.6	-0.30835
1756.88	1.22696
1758.16	-0.558502
1759.44	2.3472
1760.72	6.9682
1762	-1.68521
1763.27	2.2269
1764.55	-1.26297
1765.83	-0.195587
1767.1	0.701385
1768.38	3.40616
1769.66	-5.58563
1770.93	2.34021
1772.21	1.66376
1773.48	-0.991577
1774.76	-0.829102
1776.03	3.30872
1777.31	4.0946
1778.58	-4.74634
1779.85	-2.79382
1781.13	1.14761
1782.4	5.22717
1783.67	-1.21515
1784.94	0.900055
1786.22	-1.94882
1787.49	-7.12064
1788.76	0.194885
1790.03	3.36194
1791.3	5.96948
1792.57	5.11554
1793.84	0.44693
1795.11	9.55887
1796.38	1.23175
1797.65	5.33514
1798.92	-1.38699
1800.19	3.22363
1801.46	6.11447
1802.73	2.51932
1804	4.66919
1805.26	5.99576
1806.53	7.20401
1807.8	3.40158
1809.07	0.593781
1810.33	9.31717
1811.6	-0.307007
1812.87	12.4478
1814.13	2.19153
1815.4	4.35794
1816.66	0.573578
1817.93	8.15057
1819.19	8.34201
1820.46	0.799835
1821.72	12.6376
1822.99	6.91486
1824.25	8.88733
1825.51	5.15097
1826.77	9.10403
1828.04	7.26425
1829.3	10.0763
1830.56	0.320557
1831.82	6.35477
1833.09	15.2559
1834.35	4.39084
1835.61	5.95392
1836.87	12.3006
1838.13	5.76205
1839.39	9.51675
1840.65	3.90485
1841.91	5.28543
1843.17	5.30081
1844.43	7.25143
1845.69	14.3112
1846.94	9.62985
1848.2	8.74298
1849.46	4.61517
1850.72	7.10931
1851.97	0.289032
1853.23	0.24054
1854.49	-1.04422
1855.74	-0.360992
1857	8.22415
1858.26	3.20877
1859.51	2.98978
1860.77	7.97729
1862.02	4.19919
1863.28	5.80197
1864.53	6.5043
1865.78	-3.51874
1867.04	6.38986
1868.29	2.46442
1869.54	6.24292
1870.8	3.36401
1872.05	10.8082
1873.3	3.99472
1874.56	3.69479
1875.81	-1.55215
1877.06	0.732788
1878.31	5.03415
1879.56	3.36261
1880.81	8.99478
1882.06	9.18201
1883.31	3.50726
1884.56	6.05243
1885.81	-0.124725
1887.06	4.34219
1888.31	2.97055
1889.56	1.82889
1890.81	1.06155
1892.05	5.71338
1893.3	-4.19803
1894.55	1.3273
1895.8	-1.32852
1897.04	-2.97992
1898.29	4.45206
1899.54	1.39279
1900.78	5.24692
1902.03	-3.84161
1903.27	8.28098
1904.52	3.53329
1905.76	0.514038
1907.01	0.434113
1908.25	3.42096
1909.5	5.63901
1910.74	-0.548096
1911.98	1.34149
1913.23	0.488922
1914.47	3.7005
1915.71	1.89319
1916.96	-0.186096
1918.2	0.871948
1919.44	-2.40692
1920.68	3.41006
1921.92	-0.190247
1923.16	0.611877
1924.41	-0.473755
1925.65	4.57184
1926.89	4.93353
1928.12	3.21719
1929.36	7.32266
1930.6	10.5054
1931.84	5.63144
1933.08	1.76154
1934.32	9.40158
1935.56	3.10419
1936.8	1.9697
1938.03	7.4982
1939.27	1.11182
1940.51	10.1301
1941.75	1.32971
1942.98	5.48697
1944.22	2.76816
1945.45	5.99506
1946.69	9.00482
1947.92	0.349121
1949.16	10.1185
1950.4	8.74756
1951.63	4.44342
1952.86	4.6376
1954.1	0.113983
1955.33	2.03955
1956.56	12.1976
1957.8	14.3878
1959.03	7.59555
1960.26	1.64325
1961.5	5.34656
1962.73	5.42584
1963.96	8.42245
1965.19	6.49863
1966.42	2.93512
1967.65	9.73947
1968.88	10.5508
1970.11	4.45102
1971.34	8.1272
1972.57	8.17603
1973.8	8.91949
1975.03	7.09415
1976.26	3.40829
1977.49	5.22354
1978.72	4.15341
1979.95	3.19885
1981.17	10.6807
1982.4	8.50378
1983.63	4.6218
1984.85	2.55118
1986.08	7.21805
1987.31	9.71927
1988.53	6.49396
1989.76	5.34503
1990.98	5.53839
1992.21	5.5119
1993.43	3.25653
1994.66	3.33411
1995.88	2.70969
1997.11	6.26297
1998.33	3.42166
1999.55	1.15509
2000.78	4.20425
2002	0.106934
2003.22	1.8577
2004.45	3.6691
2005.59	2.16516
2006.83	3.14233
2008.06	3.72516
2009.3	-0.436615
2010.54	-1.60675
2011.77	2.11603
2013.01	3.64462
2014.25	-3.52332
2015.48	-0.582245
2016.72	7.21216
2017.95	4.88617
2019.19	5.35526
2020.42	-2.22098
2021.66	-3.15768
2022.89	0.282593
2024.12	1.80954
2025.36	5.0997
2026.59	0.0105591
2027.82	3.47333
2029.06	-1.34918
2030.29	0.204041
2031.52	6.13309
2032.75	-2.74564
2033.98	2.63358
2035.21	-4.7074
2036.45	2.02325
2037.68	0.121674
2038.91	-4.77219
2040.14	1.41788
2041.37	3.07632
2042.6	-3.59549
2043.83	-2.27261
2045.05	-4.15652
2046.28	4.55771
2047.51	0.291626
2048.74	-1.40533
2049.97	6.48566
2051.2	7.30783
2052.42	-0.982208
2053.65	-7.15375
2054.88	-3.418
2056.1	1.09937
2057.33	3.03976
2058.56	-3.21393
2059.78	-7.85336
2061.01	-1.25375
2062.23	-0.226379
2063.46	-2.81946
2064.68	2.07816
2065.91	-0.402954
2067.13	1.62491
2068.35	1.81558
2069.58	-2.24207
2070.8	3.81808
2072.02	3.21716
2073.25	4.13297
2074.47	3.40228
2075.69	11.4948
2076.91	0.95755
2078.13	1.8887
2079.35	-2.49139
2080.58	6.11633
2081.8	6.10864
2083.02	1.41251
2084.24	0.471375
2085.46	7.13266
2086.68	0.818634
2087.9	12.2681
2089.12	8.63358
2090.33	5.96655
2091.55	3.39435
2092.77	21.8865
2093.99	-0.638428
2095.21	11.5785
2096.43	7.66141
2097.64	3.67416
2098.86	3.59756
2100.08	5.51407
2101.29	6.68121
2102.51	5.65695
2103.73	4.60947
2104.94	1.02664
2106.16	13.5791
2107.37	2.12805
2108.59	3.71964
2109.8	4.82556
2111.01	11.4512
2112.23	5.70313
2113.44	4.98035
2114.66	8.75433
2115.87	0.050293
2117.08	10.4119
2118.29	7.26315
2119.51	8.85864
2120.72	1.31644
2121.93	4.47986
2123.14	1.78082
2124.35	13.8055
2125.57	-6.10352e-005
2126.78	5.36157
2127.99	-3.24979
2129.2	11.8208
2130.41	2.27435
2131.62	8.69278
2132.82	8.51746
2134.03	5.73526
2135.24	0.00308228
2136.45	-2.12839
2137.66	11.153
2138.87	7.46579
2140.08	1.41306
2141.28	-3.43021
2142.49	-0.583038
2143.7	3.57037
2144.9	3.68991
2146.11	5.48712
2147.32	6.25571
2148.52	0.437225
2149.73	7.54462
2150.93	0.0297546
2152.14	1.05414
2153.34	4.60892
2154.55	0.396637
2155.75	1.83646
2156.96	-1.92398
2158.16	-1.77921
2159.36	3.64227
2160.57	8.94559
2161.77	2.33093
2162.97	9.68832
2164.17	-0.805847
2165.38	-0.801239
2166.58	4.6192
2167.78	-0.506927
2168.98	-5.08386
2170.18	3.66891
2171.38	-1.41885
2172.58	-7.24234
2173.78	2.12476
2174.98	2.11197
2176.18	3.85474
2177.38	3.84412
2178.58	-1.88977
2179.78	-1.87555
2180.98	-7.51895
2182.18	0.686829
2183.38	-0.536163
2184.57	2.18253
2185.77	-2.27316
2186.97	4.61166
2188.16	5.47418
2189.36	1.37375
2190.56	-0.475433
2191.76	3.32721
2192.95	5.38123
2194.15	-1.57748
2195.34	2.87891
2196.54	2.47522
2197.73	4.28256
2198.93	16.7772
2200.12	-1.18893
2201.31	1.44742
2202.51	3.2009
2203.7	2.95557
2204.89	1.36197
2206.09	-2.4791
2207.28	4.10437
2208.47	2.52075
2209.67	2.57324
2210.86	3.72238
2212.05	3.02902
2213.24	0.0584106
2214.43	0.393188
2215.62	6.99454
2216.81	6.02405
2218	2.32321
2219.19	4.39987
2220.38	2.56674
2221.57	0.404999
2222.76	3.26877
2223.95	0.841248
2225.14	-3.48743
2226.33	5.23718
2227.51	7.26477
2228.7	1.54572
2229.89	3.66949
2231.08	-0.709961
2232.27	8.97263
2233.45	10.1768
2234.64	0.673645
2235.82	0.533691
2237.01	4.47107
2238.2	12.5167
2239.38	11.7297
2240.57	4.23364
2241.75	2.45212
2242.94	3.42242
2244.12	10.0095
2245.3	2.89328
2246.49	9.76114
2247.67	10.7794
2248.85	5.9679
2250.04	8.79916
2251.22	2.88266
2252.4	2.17511
2253.59	9.2869
2254.77	12.2222
2255.95	9.51053
2257.13	13.5543
2258.31	10.8194
2259.49	3.39313
2260.67	12.1775
2261.85	14.2313
2263.03	10.7664
2264.21	16.0664
2265.39	6.73041
2266.57	1.6683
2267.75	8.09454
2268.93	10.1735
2270.11	10.6051
2271.29	7.01691
2272.47	9.05542
2273.64	8.18082
2274.82	13.0521
2276	13.2526
2277.17	14.6174
2278.35	6.30035
2279.53	13.6801
2280.71	9.56146
2281.88	11.5064
2283.06	11.9053
2284.23	4.73849
2285.41	5.81326
2286.58	12.6252
2287.76	11.928
2288.93	14.4711
2290.1	12.2429
2291.28	12.5386
2292.45	8.98599
2293.62	12.9715
2294.8	21.4167
2295.97	11.4728
2297.14	9.71426
2298.31	3.31989
2299.49	11.255
2300.66	7.51218
2301.83	7.54141
2303	9.42767
2304.17	11.5226
2305.34	5.89899
2306.51	13.7222
2307.68	14.565
2308.85	10.7756
2310.02	12.0174
2311.19	14.4482
2312.36	17.9796
2313.53	15.4062
2314.7	14.8918
2315.87	20.2415
2317.03	11.4277
2318.2	7.51093
2319.37	10.2072
2320.54	18.9668
2321.7	24.1503
2322.87	20.4244
2324.03	30.1164
2325.2	30.6572
2326.37	39.9652
2327.53	119.668
2328.7	285.269
2329.86	54.8607
2331.03	21.137
2332.19	12.4098
2333.36	13.1853
2334.52	16.7804
2335.68	8.1149
2336.85	14.7505
2338.01	14.6577
2339.17	6.00082
2340.34	12.5002
2341.5	19.7297
2342.66	-0.0837402
2343.82	19.1723
2344.98	13.106
2346.14	5.99216
2347.31	5.02039
2348.47	7.00089
2349.63	7.86765
2350.79	5.00604
2351.95	8.8237
2353.11	7.9852
2354.27	4.59845
2355.43	6.38904
2356.59	6.6904
2357.74	3.6235
2358.9	6.05249
2360.06	6.80139
2361.22	4.98883
2362.38	6.13373
2363.53	4.27103
2364.69	2.86566
2365.74	-0.517365
2366.92	4.57547
2368.09	2.5163
2369.26	14.5042
2370.43	2.84048
2371.6	2.62198
2372.77	3.33249
2373.94	4.05789
2375.11	0.0184631
2376.28	-0.149841
2377.45	2.47549
2378.62	3.11996
2379.79	-1.93896
2380.96	1.71295
2382.13	8.23364
2383.29	0.650757
2384.46	9.95514
2385.63	4.07031
2386.8	5.51559
2387.97	2.52502
2389.13	2.42459
2390.3	-0.405884
2391.47	3.36023
2392.63	-6.19772
2393.8	-0.140411
2394.96	-1.16977
2396.13	8.16278
2397.29	3.28632
2398.46	4.18872
2399.62	5.12332
2400.79	-2.42953
2401.95	-2.57147
2403.12	-3.22339
2404.28	3.79419
2405.44	1.22922
2406.61	-0.565369
2407.77	1.26407
2408.93	1.19379
2410.09	0.26001
2411.26	3.992
2412.42	3.21594
2413.58	-1.40344
2414.74	12.4639
2415.9	-0.812836
2417.06	-2.56537
2418.22	-3.28937
2419.38	8.30493
2420.54	5.59491
2421.7	-5.88663
2422.86	4.67255
2424.02	2.06128
2425.18	-4.2012
2426.34	-1.12607
2427.5	0.892822
2428.66	-2.95328
2429.81	-1.12631
2430.97	-1.08298
2432.13	-5.37323
2433.29	1.49313
2434.44	-0.338806
2435.6	5.58209
2436.76	0.155304
2437.91	-6.48416
2439.07	0.361237
2440.23	0.70816
2441.38	12.1011
2442.53	6.64752
2443.69	1.1976
2444.84	8.01962
2446	5.37405
2447.15	-2.83713
2448.31	3.82111
2449.46	3.86572
2450.61	11.8165
2451.77	3.56052
2452.92	4.49167
2454.07	4.48141
2455.22	1.00964
2456.38	-0.58847
2457.53	6.21915
2458.68	13.8652
2459.83	8.33734
2460.98	11.3297
2462.14	13.2179
2463.29	-1.95889
2464.43	11.1542
2465.59	4.46429
2466.74	8.1908
2467.88	5.23062
2469.03	15.6313
2470.18	2.38809
2471.33	7.32138
2472.48	3.78857
2473.63	2.83429
2474.78	0.167084
2475.92	0.738281
2477.07	8.52679
2478.22	7.31808
2479.37	6.01654
2480.51	9.51825
2481.66	14.0219
2482.81	13.0248
2483.95	8.1376
2485.1	4.27646
2486.24	8.16296
2487.39	15.5878
2488.53	11.5725
2489.68	14.3328
2490.82	8.6095
2491.97	6.48007
2493.11	7.71448
2494.25	2.65805
2495.4	7.24094
2496.54	5.48148
2497.69	-0.643555
2498.83	1.49881
2499.97	4.29474
2501.11	4.71133
2502.25	3.48093
2503.4	4.33105
2504.54	0.289581
2505.68	8.77432
2506.82	7.0806
2507.96	-1.42542
2509.1	17.53
2510.24	9.54517
2511.38	5.08167
2512.52	8.6991
2513.66	1.29865
2514.8	0.209778
2515.94	8.18509
2517.08	13.3177
2518.21	0.748596
2519.35	6.31241
2520.49	-0.954895
2521.63	0.989594
2522.77	3.48123
2523.9	11.8746
2525.04	3.22305
2526.18	11.0944
2527.31	4.30359
2528.45	6.25781
2529.58	-0.184998
2530.72	9.10123
2531.86	-1.45566
2532.99	4.84412
2534.13	2.14856
2535.26	1.01648
2536.4	0.963867
2537.53	2.61945
2538.66	2.29605
2539.8	5.75177
2540.93	1.01996
2542.06	-1.54846
2543.2	6.00232
2544.33	4.83511
2545.46	-2.64371
2546.59	5.61252
2547.73	7.49817
2548.86	-1.72021
2549.99	3.18835
2551.12	1.55392
2552.25	5.46936
2553.38	1.58209
2554.51	2.48849
2555.64	1.78021
2556.77	13.4736
2557.9	10.7613
2559.03	8.89639
2560.16	-0.602661
2561.29	5.0437
2562.42	10.8355
2563.55	0.0170898
2564.67	8.03574
2565.8	3.33539
2566.93	1.47345
2568.06	9.91922
2569.18	-1.3457
2570.31	-0.169373
2571.44	4.13193
2572.56	2.70746
2573.69	4.85217
2574.81	5.59756
2575.94	7.7746
2577.06	7.98892
2578.19	11.281
2579.31	9.78116
2580.44	0.492554
2581.56	10.1428
2582.69	15.9408
2583.81	5.52371
2584.94	6.63611
2586.06	11.8877
2587.18	12.3029
2588.3	9.09946
2589.43	8.2337
2590.55	5.33356
2591.67	17.8355
2592.79	7.52499
2593.91	6.90717
2595.04	14.8399
2596.16	15.9178
2597.28	10.6826
2598.4	11.467
2599.52	10.8762
2600.64	10.9506
2601.76	8.57782
2602.88	7.56686
2604	13.3943
2605.12	4.77155
2606.24	5.76932
2607.35	14.628
2608.47	16.0551
2609.59	15.2535
2610.71	13.4092
2611.83	4.5675
2612.94	8.30408
2614.06	16.2334
2615.18	3.1517
2616.29	20.8456
2617.41	17.0725
2618.53	13.2557
2619.64	7.93652
2620.76	12.3922
2621.87	9.9978
2622.99	16.916
2624.1	22.8383
2625.22	15.0648
2626.33	25.9407
2627.45	13.3837
2628.56	15.2828
2629.67	12.2217
2630.79	14.263
2631.9	18.2725
2633.01	24.0676
2634.12	4.37219
2635.24	6.77277
2636.35	6.30914
2637.46	14.6585
2638.57	11.7001
2639.68	11.8369
2640.8	5.33209
2641.91	15.3733
2643.02	10.8363
2644.13	15.361
2645.24	11.2128
2646.35	18.7843
2647.46	6.99771
2648.57	4.52359
2649.67	8.18469
2650.78	3.28168
2651.89	5.88846
2653	-0.0151367
2654.11	3.65985
2655.22	5.2449
2656.32	10.999
2657.43	-0.437164
2658.54	10.8986
2659.65	19.9539
2660.75	10.2952
2661.86	6.07462
2662.96	1.49249
2664.07	5.07336
2665.18	5.90555
2666.28	10.5699
2667.39	11.3226
2668.49	6.13733
2669.6	3.16959
2670.7	7.03192
2671.8	2.01514
2672.91	-6.02722
2674.01	6.07327
2675.11	15.8042
2676.22	-0.921478
2677.32	1.66458
2678.42	0.485352
2679.53	2.18008
2680.63	-3.62915
2681.73	7.81442
2682.83	4.53421
2683.93	6.35028
2685.03	3.71637
2686.14	2.70435
2687.24	-3.72104
2688.34	0.0508728
2689.44	-0.313568
2690.54	5.25653
2691.64	0.663147
2692.74	-0.426056
2693.84	1.28232
2694.93	-2.30463
2696.03	-2.81091
2697.13	0.236938
2698.23	-1.13281
2699.33	4.31647
2700.43	0.859924
2701.52	2.65472
2702.62	-4.13782
2703.72	1.62967
2704.81	2.68619
2705.9	-5.45642
2707.01	-1.7182
2708.12	9.31174
2709.23	2.83264
2710.34	2.91315
2711.45	-7.57489
2712.56	2.30496
2713.67	-1.35715
2714.78	-3.7063
2715.89	1.92578
2716.99	-0.201385
2718.1	7.31165
2719.21	1.9332
2720.32	-1.4158
2721.43	-4.14566
2722.54	5.97421
2723.64	5.92062
2724.75	2.44983
2725.86	1.38684
2726.96	16.3985
2728.07	-5.13226
2729.18	-3.18286
2730.28	3.65256
2731.39	0.196991
2732.49	2.95978
2733.6	2.69992
2734.71	3.6647
2735.81	-2.5368
2736.91	5.15067
2738.02	4.17496
2739.12	7.14621
2740.23	0.390564
2741.33	5.91144
2742.43	-6.01288
2743.54	-2.82562
2744.64	10.8279
2745.74	-2.50949
2746.84	1.98749
2747.95	2.01169
2749.05	4.91409
2750.15	3.00034
2751.25	-6.2449
2752.35	5.54282
2753.45	9.44934
2754.55	4.54156
2755.66	5.34888
2756.76	8.40469
2757.86	5.68298
2758.96	1.83014
2760.05	-0.122681
2761.15	6.87863
2762.25	-1.18881
2763.35	-3.82831
2764.45	2.12881
2765.55	5.84833
2766.65	2.77658
2767.75	-2.22253
2768.84	4.39841
2769.94	2.64661
2771.04	0.82486
2772.13	5.23111
2773.23	9.07806
2774.33	4.82727
2775.42	2.81256
2776.52	-3.12552
2777.61	-4.12894
2778.71	-0.297119
2779.81	-0.597717
2780.9	-2.56699
2782	2.23834
2783.09	1.99881
2784.18	1.73801
2785.28	0.0101624
2786.37	3.0329
2787.47	-1.0228
2788.56	6.13794
2789.65	4.05481
2790.74	-2.70859
2791.84	5.55994
2792.93	-1.88266
2794.02	3.66437
2795.11	-2.92542
2796.2	4.42148
2797.3	2.38501
2798.39	0.311951
2799.48	5.17999
2800.57	0.335052
2801.66	1.17819
2802.75	-4.37668
2803.84	0.96933
2804.93	1.61581
2806.02	9.22369
2807.11	3.49374
2808.2	-4.14218
2809.28	3.30905
2810.37	-0.589447
2811.46	-4.69632
2812.55	1.62589
2813.64	0.808746
2814.73	-1.23642
2815.81	2.315
2816.9	0.297424
2817.99	-0.0878906
2819.07	-10.6398
2820.16	8.52972
2821.25	2.38098
2822.33	6.01648
2823.42	0.159302
2824.5	-8.19925
2825.59	5.72513
2826.67	0.283722
2827.76	5.13916
2828.84	-10.2483
2829.93	3.74182
2831.01	-0.859619
2832.09	-1.09714
2833.18	-0.36615
2834.26	-3.15353
2835.34	-1.08966
2836.43	-9.38937
2837.51	2.7565
2838.59	-4.83725
2839.67	-2.81454
2840.75	-5.13779
2841.84	3.19098
2842.92	3.91794
2844	4.65811
2845.08	-3.91055
2846.16	0.1297
2847.24	-2.4765
2848.32	-0.962738
2849.4	0.0552063
2850.48	3.06577
2851.56	1.27963
2852.64	0.229614
2853.72	-2.52515
2854.8	6.93329
2855.87	-2.47516
2856.95	8.76331
2858.03	-7.15082
2859.11	1.27057
2860.19	-3.43839
2861.26	1.71301
2862.34	2.0491
2863.42	6.52594
2864.49	-2.14963
2865.57	-2.02707
2866.65	-0.885529
2867.72	2.92999
2868.8	3.31082
2869.87	-0.577362
2870.95	-0.589111
2872.02	6.79315
2873.1	1.17056
2874.17	2.48395
2875.25	3.73962
2876.32	-0.12912
2877.4	-2.01279
2878.47	7.58926
2879.54	2.673
2880.62	-3.02722
2881.69	9.55795
2882.76	-1.70767
2883.83	3.62329
2884.9	2.92105
2885.98	6.91055
2887.05	7.93893
2888.12	10.153
2889.19	3.62814
2890.26	-4.04507
2891.33	7.28046
2892.4	6.42352
2893.47	6.65671
2894.54	1.52899
2895.61	11.5454
2896.68	7.59036
2897.75	2.8634
2898.82	6.70712
2899.89	3.11145
2900.96	1.24042
2902.03	0.193024
2903.09	4.99469
2904.16	-0.500488
2905.23	1.49963
2906.3	6.9227
2907.36	2.96347
2908.43	5.02136
2909.5	14.4351
2910.57	2.12891
2911.63	7.91269
2912.7	13.712
2913.76	2.15814
2914.83	7.68127
2915.89	30.5217
2916.96	14.3466
2918.02	9.57135
2919.09	5.67297
2920.15	2.58478
2921.22	3.30667
2922.28	3.09677
2923.34	7.79352
2924.41	0.162292
2925.47	0.112335
2926.53	0.973663
2927.6	6.58044
2928.66	6.42447
2929.72	3.09793
2930.78	10.3874
2931.84	5.75372
2932.91	3.56677
2933.97	-7.72177
2935.03	1.55017
2936.09	4.2168
2937.15	0.503052
2938.21	3.27411
2939.27	7.70218
2940.33	3.98114
2941.39	10.2336
2942.45	3.76105
2943.51	3.8826
2944.57	2.2001
2945.63	12.9774
2946.68	12.5127
2947.74	2.23141
2948.8	3.13123
2949.86	1.96213
2950.92	6.75146
2951.97	3.99722
2953.03	4.80945
2954.09	1.62073
2955.14	2.2713
2956.2	10.7281
2957.25	-1.45737
2958.31	4.22668
2959.37	9.87497
2960.42	3.11694
2961.48	-2.69455
2962.53	0.673065
2963.59	3.66818
2964.64	1.05768
2965.7	2.75354
2966.75	-2.2738
2967.8	-5.35086
2968.86	-3.42026
2969.91	1.31473
2970.96	-2.41263
2972.02	-1.46899
2973.07	6.05991
2974.12	5.02341
2975.17	0.15332
2976.22	0.139038
2977.28	-11.0954
2978.33	4.18015
2979.38	-2.35498
2980.43	0.340057
2981.48	8.6897
2982.53	2.81549
2983.58	0.731842
2984.63	9.02469
2985.68	6.17877
2986.73	-0.261688
2987.78	11.0886
2988.83	-0.106995
2989.88	0.804565
2990.93	2.67834
2991.98	3.74677
2993.02	-0.128632
2994.07	4.48819
2995.12	2.82721
2996.17	6.93582
2997.21	0.399902
2998.26	-0.391083
2999.31	-1.32373
2999.94	6.13702