File: Data/3-Raman/processed/bu32-AII-incC-fi05-v_1800 (450-850nm)_532nm_edge_100%_x100_vis_lwd_h30um_40sx2_01.txt
#Acq. time (s)=	40
#Accumulations=	2
#Range (cm-¹)=	1200...2365
#Windows=	3
#Auto scanning=	Off
#Autofocus=	Off
#Macrospot=	Off
#AutoExposure=	Off
#Spike filter=	Multiple accum.
#Delay time (s)=	2
#Binning=	1
#Readout mode=	Signal
#DeNoise=	Off
#ICS correction=	On
#Dark correction=	Off
#Inst. Process=	Off
#Detector Gain=	Best Dynamic
#Detector ADC=	50 kHz EM
#Detector EM gain=	400
#Detector temperature (°C)=	-60.09
#Instrument=	LabRAM HR Evol
#Detector=	SIN-EM FIVIS
#Objective=	x100_VIS_LWD
#Grating=	1800 (450-850nm)
#ND Filter=	100%
#Laser=	532nm_Edge
#Hole=	30.0125
#Temperature=	0
#Range=	Visible
#StageXY=	75x50mm Scan+
#StageZ=	Z motor
#X (µm)=	0
#Y (µm)=	0
#Z (µm)=	14.6
#Full time(mm:ss)=	4:22
#Project=	21_11_26
#Sample=	BU32
#Site=
#Title=	BU32-A-incC-FI05-V_1800 (450-850nm)_532nm_Edge_100%_x100_VIS_LWD_H30um_40sX2
#Remark=
#Date=	26.11.2021 18:16
#Acquired=	26.11.2021 18:16:44
#Base:Fit=	16.12.2021 14:47:12
#Base:Fit=	16.12.2021 14:47:15
#Base:Sub=	16.12.2021 14:47:17
1202.72	-13.8306
1203.84	27.6224
1204.95	18.9844
1206.06	29.2823
1207.17	16.7977
1208.28	12.295
1209.39	38.8141
1210.5	44.2411
1211.61	1.03033
1212.72	40.0879
1213.83	10.0893
1214.94	33.7789
1216.05	-11.7675
1217.16	38.8438
1218.27	2.44275
1219.38	40.6378
1220.49	-5.95306
1221.6	5.85577
1222.71	16.0685
1223.81	17.5089
1224.92	39.3806
1226.03	-9.89676
1227.14	-30.7967
1228.25	-2.09424
1229.35	-0.903687
1230.46	27.1376
1231.57	-10.852
1232.67	13.6197
1233.78	-6.146
1234.89	-1.4433
1235.99	-1.95953
1237.1	-11.2328
1238.2	46.1629
1239.31	26.9285
1240.41	7.12451
1241.52	5.38055
1242.62	17.011
1243.73	14.3304
1244.83	19.8625
1245.94	59.4657
1247.04	26.995
1248.14	-7.37442
1249.25	-9.45493
1250.35	24.2954
1251.45	3.20901
1252.56	11.4834
1253.66	30.1957
1254.76	-10.9734
1255.87	29.0765
1256.97	-18.5651
1258.07	10.8438
1259.17	4.60193
1260.27	-32.3783
1261.37	15.3701
1262.48	17.8384
1263.58	16.7201
1264.68	72.0237
1265.78	-17.0817
1266.88	-12.6105
1267.98	13.2603
1269.08	-30.8088
1270.18	-5.38531
1271.28	-24.4093
1272.38	38.72
1273.47	0.873016
1274.57	35.2026
1275.67	-31.5929
1276.77	24.6863
1277.87	45.3616
1278.97	-3.28903
1280.07	-2.91821
1281.16	5.78064
1282.26	30.6097
1283.36	29.5919
1284.45	129.354
1285.55	431.944
1286.65	40.3637
1287.75	23.5726
1288.84	20.5472
1289.94	14.8052
1291.03	25.747
1292.13	10.1566
1293.22	37.7752
1294.32	6.01044
1295.42	-4.15186
1296.51	9.83685
1297.61	2.6308
1298.7	-2.67236
1299.79	-12.1758
1300.89	-8.60016
1301.98	-10.3828
1303.08	-40.6275
1304.17	-10.9784
1305.26	-7.60349
1306.35	-7.7688
1307.45	-13.9359
1308.54	-24.1957
1309.63	9.96252
1310.73	38.7858
1311.82	-5.20984
1312.91	17.4485
1314	10.1455
1315.09	14.6625
1316.18	54.2519
1317.28	0.546387
1318.37	-19.1263
1319.46	-17.8043
1320.55	13.0805
1321.64	5.57898
1322.73	-19.9466
1323.82	42.3327
1324.91	-30.1582
1326	16.1371
1327.09	-28.6475
1328.18	-20.2484
1329.27	-26.8383
1330.35	33.4615
1331.44	22.7102
1332.53	-28.3209
1333.62	16.4961
1334.71	-30.045
1335.79	3.37061
1336.88	20.0641
1337.97	-1.92572
1339.06	-11.5111
1340.14	26.3881
1341.23	-7.91312
1342.32	-8.92636
1343.4	-17.497
1344.49	16.1402
1345.58	26.5681
1346.66	-17.7822
1347.75	26.6978
1348.83	33.9622
1349.92	26.5073
1351	-22.5957
1352.09	25.0969
1353.17	4.80914
1354.25	3.41858
1355.34	-28.6885
1356.42	28.6061
1357.51	24.3963
1358.59	-19.3198
1359.67	-13.2299
1360.76	-14.523
1361.84	-17.5874
1362.92	6.24197
1364	-24.48
1365.09	1.57483
1366.17	7.55313
1367.25	-33.1101
1368.33	-5.03638
1369.41	13.8849
1370.5	-18.1138
1371.58	-5.93436
1372.66	-4.38586
1373.74	17.1042
1374.82	-22.0295
1375.9	1.82312
1376.98	-10.5848
1378.06	7.94516
1379.14	53.2381
1380.22	-17.9723
1381.3	-11.5613
1382.38	-43.7352
1383.46	1.96201
1384.54	35.6818
1385.61	26.0656
1386.69	67.7271
1387.77	509.987
1388.85	225.689
1389.93	22.9337
1391	50.0156
1392.08	2.61353
1393.16	9.55554
1394.23	0.30954
1395.31	26.0143
1396.39	-5.41296
1397.46	15.9777
1398.54	21.1318
1399.62	14.3225
1400.69	28.9666
1401.77	10.9086
1402.84	-21.031
1403.92	41.1339
1404.99	-8.33334
1406.07	16.1083
1407.14	22.2527
1408.22	51.2397
1409.29	109.987
1410.37	37.4227
1411.44	42.1654
1412.51	-3.9072
1413.59	-16.8707
1414.66	12.4773
1415.73	18.9877
1416.81	-11.5383
1417.88	19.6284
1418.95	35.2591
1420.02	21.9025
1421.1	25.7408
1422.17	10.4958
1423.24	7.51324
1424.31	2.97742
1425.38	2.09103
1426.45	11.5741
1427.52	-5.18317
1428.59	24.1836
1429.67	18.2989
1430.74	28.0656
1431.81	9.31946
1432.87	4.03891
1433.95	17.7871
1435.01	9.87146
1436.08	9.98047
1437.15	2.7735
1438.22	15.0493
1439.29	22.4977
1440.36	30.1455
1441.43	28.3405
1442.49	2.75827
1443.56	-0.238098
1444.63	29.5017
1445.7	28.9732
1446.77	-2.87949
1447.83	28.835
1448.9	35.245
1449.97	18.863
1451.03	40.2553
1452.1	15.587
1453.17	28.9858
1454.23	15.8446
1455.3	50.7497
1456.36	-8.4754
1457.43	-0.367188
1458.49	54.9703
1459.56	25.4471
1460.62	26.4984
1461.69	-24.8228
1462.75	-8.65967
1463.82	11.4747
1464.88	17.2186
1465.94	11.8118
1467.01	1.55127
1468.07	-16.7948
1469.13	-27.9826
1470.2	-5.74759
1471.26	-22.1928
1472.32	30.6108
1473.39	9.23935
1474.45	-36.6936
1475.51	-27.3682
1476.57	4.11066
1477.63	29.3952
1478.69	24.2201
1479.76	41.2634
1480.82	-2.83127
1481.88	-21.1725
1482.94	-17.7208
1484	-8.40594
1485.06	-9.26031
1486.12	27.1674
1487.18	44.5392
1488.24	3.85822
1489.3	35.9487
1490.36	-13.6696
1491.42	-18.8766
1492.48	-10.7434
1493.53	-43.0592
1494.59	-19.7315
1495.65	4.42731
1496.71	32.3287
1497.77	-10.1098
1498.82	2.06729
1499.88	-14.8963
1500.94	22.5828
1502	23.4892
1503.05	-13.9306
1504.11	-3.9834
1505.17	36.4902
1506.22	-4.16812
1507.28	5.0311
1508.34	12.1782
1509.39	-10.8994
1510.45	-3.68286
1511.5	-6.01862
1512.56	-14.8581
1513.61	-18.2747
1514.67	18.2647
1515.72	27.9769
1516.78	-11.488
1517.83	14.6023
1518.88	-40.2892
1519.94	1.05591
1520.99	3.09702
1522.05	5.28363
1523.1	-4.85126
1524.15	10.7551
1525.2	-29.4106
1526.26	42.9983
1527.31	42.3594
1528.36	-29.8781
1529.41	45.1823
1530.47	50.1393
1531.52	-21.5741
1532.57	23.5417
1533.62	-38.0291
1534.67	11.2878
1535.72	11.1669
1536.77	-33.4405
1537.82	-4.79453
1538.87	3.02396
1539.92	-17.2108
1540.97	3.67438
1542.02	-38.6044
1543.07	43.1754
1544.12	5.70328
1545.17	4.09283
1546.22	5.64697
1547.27	18.8742
1548.32	4.71375
1549.37	39.5756
1550.42	-9.20035
1551.46	13.3067
1552.51	47.5648
1553.56	-0.862061
1554.61	11.9418
1555.65	8.62613
1556.7	2.68399
1557.75	-12.1637
1558.79	-2.40628
1559.84	40.1798
1560.89	-3.93597
1561.93	-16.737
1562.98	-7.38913
1564.02	46.631
1565.07	49.1468
1566.11	25.3202
1567.16	-19.5002
1568.2	20.9373
1569.25	-1.83261
1570.29	4.05042
1571.34	16.1443
1572.38	11.0468
1573.43	1.8909
1574.47	-13.0143
1575.51	-18.4628
1576.56	11.6942
1577.6	7.26697
1578.64	-12.0932
1579.69	-0.042511
1580.73	19.1582
1581.77	-26.7876
1582.81	25.8904
1583.85	0.0203857
1584.9	33.0355
1585.94	-7.7056
1586.98	-8.91922
1588.02	-1.00638
1589.06	10.2239
1590.1	31.4325
1591.14	-9.13577
1592.18	16.7843
1593.22	0.553009
1594.26	-13.8851
1595.3	-0.760864
1596.34	4.17603
1597.38	9.3223
1598.42	16.428
1599.46	19.1176
1600.5	-4.87833
1601.54	26.4678
1602.58	-3.57779
1603.62	-2.8504
1604.66	30.7986
1605.69	-0.665161
1606.73	-2.3031
1607.77	22.7391
1608.81	26.7476
1609.84	20.2495
1610.88	-3.86832
1611.92	-18.539
1612.95	8.47797
1613.99	-9.67639
1615.03	-7.58618
1616.06	-16.8211
1617.1	-1.04251
1618.13	-16.2497
1619.17	8.07962
1620.2	4.98676
1621.24	-9.11005
1622.27	0.314148
1623.31	-7.84384
1624.34	15.1565
1625.38	-0.725311
1626.41	3.73822
1627.45	9.51599
1628.48	-9.39273
1629.51	-12.5764
1630.55	-27.0395
1631.53	14.6707
1632.57	-16.5104
1633.62	23.9951
1634.66	12.4232
1635.71	12.5262
1636.75	4.59076
1637.8	-11.2762
1638.84	-11.2646
1639.89	-34.7455
1640.93	14.6937
1641.98	-12.7294
1643.02	0.120941
1644.06	-3.74429
1645.11	11.952
1646.15	8.2991
1647.19	20.0734
1648.24	31.8706
1649.28	-2.00095
1650.32	24.7093
1651.37	-18.0646
1652.41	16.6561
1653.45	12.7556
1654.49	11.0315
1655.53	-17.2126
1656.57	16.9389
1657.62	5.25391
1658.66	9.18973
1659.7	10.0621
1660.74	34.7909
1661.78	25.4216
1662.82	-20.3259
1663.86	2.59946
1664.9	-26.1802
1665.94	-44.3215
1666.98	19.5261
1668.02	-11.1662
1669.06	-9.94101
1670.1	46.83
1671.14	-20.8635
1672.18	-16.8346
1673.21	33.7772
1674.25	-24.2927
1675.29	17.6518
1676.33	-18.7032
1677.37	17.1203
1678.4	-8.66946
1679.44	10.9705
1680.48	9.96918
1681.52	20.834
1682.55	3.19284
1683.59	-4.58691
1684.63	2.36996
1685.66	32.0607
1686.7	9.54712
1687.73	-2.04398
1688.77	7.79114
1689.81	35.2558
1690.84	14.5702
1691.88	54.3644
1692.91	39.6581
1693.95	-11.9223
1694.98	-0.271667
1696.01	14.7238
1697.05	29.7871
1698.08	26.6097
1699.12	5.77719
1700.15	19.6863
1701.18	-9.79495
1702.22	-5.92963
1703.25	10.6583
1704.28	14.6245
1705.32	13.8823
1706.35	12.9485
1707.38	40.1545
1708.41	-1.40372
1709.44	-29.2064
1710.48	33.5052
1711.51	-13.1897
1712.54	12.4485
1713.57	15.8299
1714.6	-6.96249
1715.63	7.83597
1716.66	33.3722
1717.69	22.1947
1718.72	-5.67926
1719.75	2.09268
1720.78	18.7688
1721.81	5.87686
1722.84	3.64484
1723.87	-15.9554
1724.9	-0.409485
1725.93	-24.1305
1726.96	-2.81949
1727.99	-3.77121
1729.02	-3.51077
1730.05	-17.3232
1731.07	10.5675
1732.1	-6.16357
1733.13	16.985
1734.16	3.98917
1735.18	36.341
1736.21	20.6307
1737.24	-16.9632
1738.26	31.0146
1739.29	24.0267
1740.32	3.32309
1741.34	22.1219
1742.37	1.8381
1743.4	15.2437
1744.42	32.3769
1745.45	-14.4514
1746.47	14.2122
1747.5	-17.6475
1748.52	4.1951
1749.55	-2.25204
1750.57	-12.2806
1751.6	-31.0857
1752.62	-23.687
1753.64	2.82236
1754.67	-18.3564
1755.69	8.24228
1756.71	8.93707
1757.74	19.0721
1758.76	11.7379
1759.78	10.0097
1760.81	31.9027
1761.83	10.8157
1762.85	27.0766
1763.87	20.6054
1764.89	-8.42593
1765.92	22.356
1766.94	0.556213
1767.96	-1.3501
1768.98	0.49823
1770	19.7889
1771.02	-34.9514
1772.04	18.7462
1773.06	-10.366
1774.08	25.1607
1775.1	13.0534
1776.12	23.1352
1777.14	13.7245
1778.16	10.7098
1779.18	5.70691
1780.2	25.7387
1781.22	-4.45264
1782.24	-18.4931
1783.26	-3.80807
1784.28	17.5047
1785.29	22.6937
1786.31	-6.87494
1787.33	2.98572
1788.35	7.73846
1789.37	-3.95959
1790.38	13.7839
1791.4	15.7606
1792.42	14.5747
1793.43	6.20392
1794.45	-1.25793
1795.47	29.9218
1796.48	-18.4271
1797.5	6.9863
1798.51	1.54474
1799.53	12.1912
1800.55	11.0465
1801.56	1.42108
1802.58	38.122
1803.59	7.7948
1804.61	22.5249
1805.62	21.084
1806.64	28.2891
1807.65	-18.7094
1808.66	21.9014
1809.68	-4.92331
1810.69	-2.83688
1811.7	11.6704
1812.72	26.3034
1813.73	34.3585
1814.74	20.3913
1815.76	-11.0616
1816.77	-7.00488
1817.78	30.5251
1818.79	-12.7841
1819.8	26.0986
1820.82	13.8315
1821.83	0.600006
1822.84	14.425
1823.85	-3.87064
1824.86	21.4105
1825.87	15.8564
1826.88	6.29214
1827.89	29.761
1828.9	12.4007
1829.91	-1.20166
1830.92	15.1825
1831.93	8.66141
1832.94	14.8203
1833.95	7.27463
1834.96	30.3291
1835.97	-7.98914
1836.98	17.8737
1837.99	47.5616
1839	33.0951
1840	35.7379
1841.01	15.5918
1842.02	9.09421
1843.03	4.95224
1844.04	38.7957
1845.04	1.26965
1846.05	31.3873
1847.06	8.72348
1848.07	16.0131
1849.07	15.211
1850.08	15.9214
1851.09	5.86133
1852.09	13.345
1853.1	11.4757
1854.1	-3.97659
1855.11	13.8873
1856.11	15.4663
1857.12	25.0539
1858.12	8.68582
1859.13	1.715
1860.13	12.9675
1861.14	-8.77539
1862.14	-1.78311
1863.15	31.4902
1864.15	-25.2077
1865.15	-7.28729
1866.16	10.3827
1867.16	12.5922
1868.16	-1.18765
1869.17	-12.5763
1870.17	8.3287
1871.17	23.5303
1872.17	1.5813
1873.18	34.6249
1874.18	15.5263
1875.18	12.3515
1876.18	20.3122
1877.18	1.94421
1878.18	-13.7006
1879.19	12.5661
1880.19	20.5425
1881.19	23.3925
1882.19	-6.49182
1883.19	-1.62366
1884.19	44.1717
1885.19	23.7223
1886.19	17.7301
1887.19	30.0039
1888.19	25.8638
1889.19	1.78586
1890.19	2.55014
1891.19	17.9344
1892.18	20.7227
1893.18	14.9382
1894.18	7.76129
1895.18	-29.0161
1896.18	-4.40488
1897.18	-29.4738
1898.17	-21.794
1899.17	-40.7713
1900.17	12.5782
1901.16	4.1622
1902.16	-18.9701
1903.16	28.2589
1904.16	12.1588
1905.15	0.856262
1906.15	12.9597
1907.14	3.31921
1908.14	17.5089
1909.14	-9.50629
1910.13	-23.1996
1911.13	-7.61371
1912.12	1.9697
1913.12	-14.0622
1914.11	22.9239
1915.11	-3.96109
1916.1	-9.42456
1917.1	28.1496
1918.09	-5.95761
1919.08	-8.478
1920.08	-3.15051
1921.07	-14.3694
1922.06	3.0174
1923.06	26.6405
1924.05	-12.2509
1925.04	20.664
1926.04	36.1284
1927.03	-22.0098
1928.02	-3.73135
1929.01	41.015
1930	33.8399
1931	29.6086
1931.99	6.8201
1932.98	9.46759
1933.97	10.5265
1934.96	-5.35504
1935.95	20.3633
1936.94	23.8022
1937.93	25.3668
1938.92	-13.6525
1939.91	-5.77103
1940.9	-6.40924
1941.89	12.1231
1942.88	14.2482
1943.87	1.63458
1944.86	-14.2696
1945.85	10.0391
1946.84	24.6992
1947.83	32.3168
1948.82	30.3831
1949.8	9.64859
1950.79	3.55759
1951.78	14.7794
1952.77	-0.211456
1953.76	-14.541
1954.74	6.70395
1955.73	13.225
1956.72	23.5655
1957.7	21.1208
1958.69	-7.46671
1959.68	5.88327
1960.66	-1.9808
1961.65	12.1615
1962.63	13.1591
1963.62	1.73401
1964.61	21.0958
1965.59	-28.857
1966.58	-5.57132
1967.56	3.29565
1968.55	0.509705
1969.53	-16.9819
1970.52	-0.113312
1971.5	9.26395
1972.48	14.0797
1973.47	-21.4759
1974.45	23.3536
1975.44	34.9144
1976.42	9.26834
1977.4	16.9941
1978.39	15.8425
1979.37	-17.8173
1980.35	27.2905
1981.33	2.16748
1982.31	8.74243
1983.3	14.2526
1984.28	11.1107
1985.26	7.11121
1986.24	12.7289
1987.22	-11.9692
1988.21	42.223
1989.19	-0.49057
1990.17	-10.0291
1991.15	-0.370636
1992.13	-3.63519
1993.11	-4.3486
1994.09	6.26501
1995.07	9.59308
1996.05	0.445679
1997.03	-4.37534
1998.01	4.66602
1998.99	-3.1218
1999.97	-5.8812
2000.95	0.887726
2001.92	1.39642
2002.9	-3.15845
2003.88	15.8835
2004.86	3.15952
2005.84	1.90219
2006.81	13.7922
2007.79	19.029
2008.77	8.70551
2009.75	4.23593
2010.73	4.57346
2011.7	-13.6086
2012.68	-3.3266
2013.67	5.65125
2014.66	-0.622192
2015.64	28.3284
2016.63	38.8662
2017.62	3.47211
2018.61	6.70282
2019.6	29.5372
2020.58	13.4458
2021.57	2.23621
2022.56	22.7419
2023.55	24.2349
2024.54	-20.9784
2025.52	-14.9311
2026.51	-6.83929
2027.5	-16.0766
2028.48	-11.8376
2029.47	-25.2422
2030.45	-0.25354
2031.44	-7.52789
2032.43	-7.44769
2033.41	15.4988
2034.4	11.8224
2035.38	-21.4639
2036.37	23.321
2037.35	-7.65137
2038.34	32.4425
2039.32	-5.18768
2040.31	-14.8518
2041.29	12.7496
2042.27	-10.7351
2043.26	20.7857
2044.24	-2.03412
2045.23	27.5684
2046.21	3.23419
2047.19	42.9977
2048.17	52.691
2049.16	1.5278
2050.14	12.2511
2051.12	11.6344
2052.11	9.53207
2053.09	17.1432
2054.07	5.44409
2055.05	3.70755
2056.03	0.708069
2057.01	-13.4426
2058	39.9414
2058.98	15.0189
2059.96	7.72681
2060.94	14.1245
2061.92	27.398
2062.9	8.76385
2063.88	-13.4762
2064.86	11.0446
2065.84	9.55789
2066.82	27.6481
2067.8	27.8295
2068.78	26.1436
2069.76	17.5619
2070.73	12.8143
2071.71	7.43216
2072.69	25.8871
2073.67	6.02908
2074.65	0.466553
2075.63	-19.7911
2076.6	12.7099
2077.58	7.77029
2078.56	-15.927
2079.54	8.81265
2080.51	5.4292
2081.49	32.8
2082.47	16.7186
2083.45	-12.5388
2084.42	-8.8056
2085.4	34.6613
2086.37	9.25928
2087.35	10.5016
2088.32	-17.7943
2089.3	11.592
2090.28	-6.14606
2091.25	-2.25143
2092.23	-15.2467
2093.2	18.4488
2094.18	3.61731
2095.15	-11.5416
2096.13	-4.19019
2097.1	17.5225
2098.07	22.9293
2099.05	15.201
2100.02	21.7509
2101	1.86838
2101.97	2.08966
2102.94	16.2711
2103.92	11.2781
2104.89	4.67993
2105.86	18.2279
2106.83	7.92682
2107.8	27.8787
2108.78	-42.8683
2109.75	9.33127
2110.72	24.5808
2111.69	-19.1886
2112.66	23.3873
2113.63	10.2853
2114.61	22.6618
2115.58	19.7663
2116.55	-1.36566
2117.52	19.33
2118.49	10.5804
2119.46	9.17459
2120.43	-2.54868
2121.4	22.142
2122.37	-30.6493
2123.34	1.79724
2124.31	5.51807
2125.28	-14.9696
2126.25	-8.92874
2127.21	18.0954
2128.18	36.7807
2129.15	9.24536
2130.12	22.3278
2131.09	14.5965
2132.06	-16.8544
2133.02	5.51151
2133.99	13.9382
2134.96	-5.91028
2135.93	9.99194
2136.89	29.3506
2137.86	13.3578
2138.83	19.75
2139.79	-7.54657
2140.76	27.8629
2141.73	-3.38297
2142.69	34.005
2143.66	4.13849
2144.62	-12.7072
2145.59	-3.34485
2146.55	2.16321
2147.52	41.4061
2148.48	-4.89163
2149.45	0.436554
2150.42	10.2193
2151.38	-4.94012
2152.34	7.38675
2153.31	24.0627
2154.27	35.0249
2155.24	6.26965
2156.2	26.221
2157.16	11.9874
2158.13	20.5011
2159.09	26.1093
2160.05	9.9151
2161.01	11.3376
2161.98	-6.60114
2162.94	-14.1512
2163.9	6.12888
2164.86	-17.5234
2165.83	28.0669
2166.79	-18.6688
2167.75	-15.2931
2168.71	7.34259
2169.67	17.6604
2170.63	-4.23029
2171.59	6.76767
2172.56	5.0867
2173.51	-5.34448
2174.48	7.71231
2175.44	3.94229
2176.4	-9.22113
2177.36	27.7502
2178.32	-19.6671
2179.28	17.1765
2180.23	28.2816
2181.19	5.86438
2182.15	-1.75848
2183.11	6.37576
2184.07	-32.071
2185.03	20.5609
2185.99	13.2417
2186.95	33.0003
2187.9	16.7053
2188.86	19.2513
2189.82	6.6828
2190.78	12.0062
2191.73	1.84073
2192.69	16.7614
2193.65	-4.39279
2194.6	2.64185
2195.56	9.9794
2196.52	16.0028
2197.47	-13.2038
2198.43	24.7697
2199.38	25.2038
2200.34	51.8111
2201.3	-4.29434
2202.25	11.0372
2203.21	-24.5774
2204.16	32.7612
2205.12	18.8621
2206.07	37.3175
2207.03	9.33997
2207.98	-5.34232
2208.93	8.90057
2209.89	26.6798
2210.84	-8.64664
2211.8	42.8356
2212.75	35.6245
2213.7	13.9461
2214.66	-20.4102
2215.61	-3.39816
2216.56	14.3252
2217.51	13.3035
2218.47	25.4312
2219.42	8.77921
2220.37	-8.79752
2221.32	8.83893
2222.27	25.2283
2223.23	-2.78857
2224.18	-21.1675
2225.13	-15.1752
2226.08	-8.26837
2227.03	-0.481445
2227.98	-18.1056
2228.93	16.4636
2229.88	25.8409
2230.83	-19.788
2231.78	0.262726
2232.73	3.38394
2233.68	-19.8535
2234.63	-0.896271
2235.58	12.8974
2236.53	25.9918
2237.48	-18.0731
2238.43	-12.8314
2239.38	21.5956
2240.33	9.14288
2241.27	-26.5289
2242.22	7.54187
2243.17	-8.36871
2244.12	-0.0373535
2245.07	-17.794
2246.01	23.3245
2246.96	-16.1096
2247.91	8.67856
2248.85	-7.48157
2249.8	18.0856
2250.75	-9.43246
2251.69	20.5263
2252.64	15.9165
2253.59	6.12415
2254.53	-2.96234
2255.48	-3.84988
2256.42	-17.953
2257.37	5.11673
2258.32	-10.8028
2259.26	-12.5399
2260.2	16.1756
2261.15	-2.62036
2262.1	14.796
2263.04	-0.183044
2263.98	5.08408
2264.93	8.56705
2265.87	-1.62726
2266.81	21.1279
2267.76	-3.96948
2268.7	-22.2879
2269.65	18.0805
2270.59	1.46341
2271.53	-22.0958
2272.47	18.3509
2273.42	-15.0074
2274.36	-10.0828
2275.3	10.168
2276.24	3.62405
2277.18	-27.5706
2278.13	-9.73032
2279.07	0.203735
2280.01	14.3701
2280.95	8.26959
2281.89	26.3574
2282.83	-6.90515
2283.77	21.4707
2284.71	-1.79691
2285.65	41.8513
2286.59	12.8119
2287.54	-18.4203
2288.47	-22.0111
2289.41	-4.89981
2290.35	-2.43906
2291.29	14.9865
2292.23	-11.4508
2293.17	45.8052
2294.11	-7.84985
2295.05	6.48251
2295.99	15.0145
2296.93	-16.9778
2297.86	2.625
2298.8	17.5862
2299.74	7.44168
2300.68	-4.00089
2301.61	17.5537
2302.55	39.8496
2303.49	-19.9282
2304.43	-0.404297
2305.36	5.75049
2306.3	-2.6781
2307.24	-11.1911
2308.17	29.3817
2309.11	12.0524
2310.04	-12.6016
2310.98	14.7281
2311.92	6.47235
2312.85	7.17865
2313.79	9.34637
2314.72	19.6685
2315.66	-0.253845
2316.59	19.6475
2317.52	-2.60281
2318.46	23.6665
2319.39	14.8409
2320.33	15.7974
2321.26	-2.30072
2322.2	14.5943
2323.13	23.6869
2324.06	-7.01978
2325	23.9239
2325.93	13.9291
2326.86	28.1827
2327.79	59.7774
2328.73	87.7538
2329.66	45.1876
2330.59	19.2742
2331.52	19.3416
2332.46	-5.461
2333.39	5.97467
2334.32	1.09634
2335.25	-1.93951
2336.18	18.3867
2337.11	37.6357
2338.04	11.7068
2338.97	5.97937
2339.91	11.8752
2340.84	-3.6041
2341.77	23.859
2342.7	-0.332642
2343.63	17.9186
2344.56	26.6529
2345.49	5.60269
2346.41	29.3269
2347.34	14.9517
2348.27	-13.6801
2349.2	13.2676
2350.13	-7.34644
2351.06	-3.40204
2351.99	-1.73422
2352.91	15.8737
2353.84	18.2091
2354.77	-3.61432
2355.7	-0.664429
2356.63	16.258
2357.55	12.9566
2358.48	-1.47247
2359.41	12.6433
2360.33	-35.9638
2361.26	-5.90646
2362.19	27.8485
2363.11	24.6231
2364.04	-7.76093
2364.97	7.16681