File: Data/3-Raman/processed/bu32-b-ff2-fi05-v_150 (500nm)_532nm_edge_100%_x100_vis_lwd_h30um_30sx2_01.txt
#Acq. time (s)=	30
#Accumulations=	2
#Range (cm-¹)=	100...5000
#Windows=	1
#Auto scanning=	Off
#Autofocus=	Off
#Macrospot=	Off
#AutoExposure=	Off
#Spike filter=	Multiple accum.
#Delay time (s)=	2
#Binning=	1
#Readout mode=	Signal
#DeNoise=	Off
#ICS correction=	On
#Dark correction=	Off
#Inst. Process=	Off
#Detector Gain=	Best Dynamic
#Detector ADC=	50 kHz HS
#Detector temperature (°C)=	-60.09
#Instrument=	LabRAM HR Evol
#Detector=	SIN-EM FIVIS
#Objective=	x100_VIS_LWD
#Grating=	150 (500nm)
#ND Filter=	100%
#Laser=	532nm_Edge
#Hole=	30.0125
#Temperature=	40
#Range=	Visible
#StageXY=	75x50mm Scan+
#StageZ=	Z motor
#X (µm)=	0
#Y (µm)=	0
#Z (µm)=	55.7
#Full time(mm:ss)=	1:04
#Project=	21_08_11
#Sample=	BU32
#Site=
#Title=	BU32-B-FF2-FI05-V_150 (500nm)_532nm_Edge_100%_x100_VIS_LWD_H30um_30sX2
#Remark=
#Date=	13.08.2021 15:36
#Acquired=	13.08.2021 15:36:22
#Data Range:Extract=	16.12.2021 14:53:05
#Base:Fit=	16.12.2021 15:05:46
#Base:Edit=	16.12.2021 15:05:48
#Base:Edit=	16.12.2021 15:05:48
#Base:Edit=	16.12.2021 15:05:49
#Base:Edit=	16.12.2021 15:05:49
#Base:Sub=	16.12.2021 15:05:50
102.095	1287.1
106.719	1083.41
111.341	844.77
115.96	637.012
120.577	573.608
125.19	417.661
129.802	389.872
134.413	309.425
139.021	258.815
143.624	262.526
148.228	229.332
152.829	247.759
157.428	409.722
162.022	657.3
166.617	664.632
171.209	334.225
175.799	111.824
180.384	38.7902
184.969	2.44659
189.552	-0.915039
194.133	12.7914
198.71	26.4259
203.286	61.9916
207.86	96.2235
212.43	86.3473
216.999	120.432
221.566	79.8348
226.131	19.5551
230.692	1.91312
235.253	12.2739
239.811	40.822
244.365	41.1139
248.919	23.017
253.47	-2.46405
258.018	14.6125
262.565	35.2343
267.11	70.3285
271.65	55.5388
276.191	55.2769
280.727	40.4882
285.263	24.601
289.797	23.429
294.326	28.4318
298.856	101.467
303.383	118.634
307.906	131.938
312.428	104.158
316.947	98.1345
321.465	45.1003
325.981	55.6496
330.493	60.6676
335.005	76.7396
339.512	128.14
344.019	187.689
348.524	258.194
353.025	280.563
357.526	197.417
362.022	101.705
366.518	72.734
371.01	52.7895
375.502	36.5243
379.99	62.0399
384.477	53.258
388.961	107.299
393.444	142.384
397.923	179.679
402.401	236.209
406.878	268.84
411.35	304.081
415.823	342.755
420.291	335.419
424.758	303.85
429.222	319.27
433.684	334.65
438.145	272.989
442.602	280.777
447.059	250.829
451.512	270.744
455.965	298.897
460.413	332.335
464.862	277.049
469.306	218.099
473.75	181.695
478.19	162.67
482.63	190.053
487.065	227.093
491.499	310.742
495.932	424.862
500.361	516.221
504.79	638.237
509.215	697.204
513.638	780.349
518.06	812.556
522.479	885.478
526.897	855.794
531.311	827.403
535.723	751.7
540.135	722.216
544.543	705.352
548.948	716.302
553.354	739.885
557.755	678.188
562.157	625.052
566.554	528.747
570.949	497.452
575.344	470.556
579.734	477.93
584.123	544.254
588.512	648.342
592.896	800.156
597.279	778.185
601.659	688.751
606.039	507.131
610.415	388.34
614.789	324.363
619.163	250.808
623.532	221.147
627.9	180.009
632.267	166.95
636.631	158.284
640.992	150.882
645.351	150.224
649.71	210.018
654.065	206.721
658.418	220.888
662.769	202.244
667.12	155.205
671.466	120.779
675.811	90.9548
680.154	65.7876
684.494	55.2835
688.834	57.0932
693.171	41.3822
697.505	40.056
701.837	49.3093
706.169	34.8156
710.497	33.3392
714.823	35.1668
719.146	25.5821
723.468	28.243
727.788	15.47
732.107	29.2889
736.423	3.70642
740.737	16.2537
745.048	5.96393
749.357	39.0224
753.665	27.8053
757.972	26.2826
762.275	20.292
766.576	20.9282
770.875	22.9785
775.172	5.85167
779.467	7.82961
783.76	16.4888
788.051	9.78688
792.34	-2.36343
796.629	16.2662
800.914	7.41521
805.196	2.00047
809.477	4.34505
813.756	10.0142
818.032	3.61449
822.307	0.510208
826.58	7.35492
830.85	3.20868
835.119	0.164383
839.385	-0.687454
843.649	-7.07141
847.912	-1.36852
852.172	3.14163
856.431	14.2644
860.687	6.64571
864.941	13.3245
869.194	5.64426
873.444	15.5262
877.692	6.69873
881.938	17.5761
886.183	1.03706
890.425	7.37535
894.665	4.92419
898.903	13.5872
903.14	25.8749
907.374	21.668
911.606	21.5883
915.836	23.7841
920.064	43.2166
924.291	66.839
928.515	66.5772
932.737	122.432
936.957	147.029
941.176	195.039
945.392	227.889
949.606	248.873
953.818	297.616
958.029	385.661
962.237	428.909
966.443	502.924
970.645	671.301
974.848	803.523
979.048	801.127
983.246	724.794
987.443	571.238
991.637	489.818
995.83	469.202
1000.02	519.958
1004.21	616.596
1008.39	864.472
1012.58	1114.16
1016.76	1343.91
1020.94	1353.42
1025.12	1235.61
1029.29	1113.9
1033.47	974.625
1037.64	748.895
1041.81	571.067
1045.98	463.976
1050.15	354.915
1054.31	309.774
1058.47	304.894
1062.64	329.446
1066.79	350.57
1070.95	386.191
1075.1	365.099
1079.26	326.419
1083.41	292.007
1087.56	240.289
1091.7	235.408
1095.85	200.863
1099.99	207.672
1104.13	212.44
1108.27	253.081
1112.41	268.285
1116.55	215.255
1120.68	166.845
1124.81	130.92
1128.94	90.9004
1133.07	81.5274
1137.19	68.986
1141.32	61.5239
1145.44	49.9603
1149.56	51.7046
1153.67	33.752
1157.79	24.9969
1161.9	14.1382
1166.02	22.8425
1170.13	16.0321
1174.23	11.2438
1178.34	12.6197
1182.45	15.0184
1186.55	-1.12696
1190.65	-6.00636
1194.75	-2.70936
1198.84	4.62106
1202.94	10.8638
1207.03	9.95402
1211.12	7.03003
1215.21	6.15081
1219.3	24.4305
1223.38	15.5065
1227.47	31.7212
1231.55	25.9072
1235.63	43.2099
1239.7	55.5873
1243.78	65.9131
1247.85	69.3058
1251.93	146.683
1256	214.178
1260.06	215.831
1264.13	141.514
1268.19	234.319
1272.26	947.82
1276.32	1481.29
1280.38	1417.17
1284.43	355.218
1288.49	128.592
1292.54	81.8548
1296.59	78.349
1300.64	72.8041
1304.69	75.2822
1308.73	62.6235
1312.78	63.0471
1316.82	68.4445
1320.86	54.6614
1324.89	60.9613
1328.93	73.2485
1332.96	56.3799
1337	70.5701
1341.03	59.6678
1345.06	87.7332
1349.08	80.7978
1353.11	92.7957
1357.13	119.656
1361.15	148.383
1365.17	153.292
1369.19	178.979
1373.2	654.758
1377.22	2036.62
1381.23	2502.88
1385.24	1509.51
1389.25	268.223
1393.25	169.152
1397.26	254.286
1401.26	294.147
1405.26	266.024
1409.26	116.669
1413.25	86.5266
1417.25	62.2717
1421.24	59.7032
1425.23	52.1692
1429.22	40.6053
1433.21	25.0962
1437.2	25.3818
1441.18	26.6497
1445.16	11.1145
1449.14	14.3238
1453.12	6.65804
1457.1	9.82815
1461.07	12.9715
1465.05	5.24525
1469.02	6.37086
1472.99	3.57462
1476.95	2.72942
1480.92	11.6665
1484.88	10.7837
1488.85	8.91372
1492.81	7.05087
1496.77	9.08929
1500.72	7.23354
1504.68	13.1747
1508.63	11.354
1512.58	-2.11665
1516.53	3.84285
1520.48	9.80123
1524.42	10.9064
1528.37	12.0132
1532.31	20.882
1536.25	21.0221
1540.19	22.1291
1544.12	16.4481
1548.06	12.7013
1551.99	10.8875
1555.92	21.648
1559.85	7.20789
1563.78	23.7292
1567.7	15.0722
1571.63	19.9426
1575.55	19.0049
1579.47	21.919
1583.39	18.0707
1587.31	21.9231
1591.22	11.3217
1595.13	21.8903
1599.05	22.8264
1602.96	27.6051
1606.86	29.5109
1610.77	27.5774
1614.67	21.8155
1618.58	27.5649
1622.48	29.4682
1626.38	40.9544
1630.27	22.7789
1634.17	28.5634
1638.06	18.0667
1641.95	27.6963
1645.84	31.6058
1649.73	24.9805
1653.62	21.2254
1657.5	23.2125
1661.39	23.2711
1665.27	20.4213
1669.15	36.7798
1673.02	24.2603
1676.9	24.226
1680.77	23.169
1684.65	28.798
1688.52	19.0595
1692.39	19.8517
1696.25	14.8825
1700.12	7.99567
1703.98	14.4555
1707.84	26.5765
1711.7	13.9285
1715.56	13.6497
1719.42	21.8843
1723.27	4.6
1727.13	2.44518
1730.98	5.91948
1734.83	5.63052
1738.68	4.3933
1742.52	14.3457
1746.37	15.8723
1750.21	2.57941
1754.05	2.35297
1757.89	11.4488
1761.73	4.92481
1765.56	4.83088
1769.4	9.4083
1773.23	9.38986
1777.06	3.78851
1780.89	8.45364
1784.71	-7.3896
1788.54	-2.70625
1792.36	6.67844
1796.18	11.4043
1800	10.5005
1803.82	4.82467
1807.64	-0.87484
1811.45	-1.88356
1815.27	-1.96841
1819.08	3.56778
1822.89	6.24734
1826.7	8.90616
1830.5	16.2484
1834.31	-1.8886
1838.11	7.2867
1841.91	-4.26186
1845.71	2.0383
1849.51	10.2074
1853.3	2.3849
1857.1	3.90994
1860.89	2.59843
1864.68	4.07057
1868.47	3.68633
1872.26	3.31209
1876.04	0.182816
1879.83	2.60883
1883.61	2.29954
1887.39	-4.44883
1891.17	2.71606
1894.95	0.681992
1898.72	4.16753
1902.5	5.85361
1906.27	6.64007
1910.04	12.0433
1913.81	-1.87128
1917.58	9.11626
1921.34	9.10332
1925.1	2.61926
1928.87	-2.01596
1932.63	3.56813
1936.38	9.17287
1940.14	3.59358
1943.9	14.8274
1947.65	1.73845
1951.4	5.42061
1955.15	2.49543
1958.9	4.21246
1962.65	6.83386
1966.39	0.0578842
1970.14	9.21311
1973.88	11.751
1977.62	3.0194
1981.36	3.64691
1985.09	7.05796
1988.83	0.18364
1992.56	4.4922
1996.29	4.11586
2000.02	1.86588
2003.75	-0.371826
2007.48	2.00987
2011.21	8.9635
2014.93	3.93308
2018.65	-0.110268
2022.37	8.74731
2026.09	3.91188
2029.81	5.50011
2033.52	8.9641
2037.23	11.5568
2040.95	17.8014
2044.66	8.47462
2048.37	9.22097
2052.07	10.9065
2055.78	4.35632
2059.48	4.27039
2063.18	10.6803
2066.88	1.50542
2070.58	14.4209
2074.28	2.46544
2077.97	7.11995
2081.67	14.5816
2085.36	9.06396
2089.05	6.19198
2092.74	-1.38262
2096.43	-7.05338
2100.11	0.276031
2103.8	5.71446
2107.48	6.48507
2111.16	3.51983
2114.84	14.4982
2118.51	5.01181
2122.19	6.63744
2125.86	11.9468
2129.54	2.40182
2133.21	1.19919
2136.88	12.0095
2140.55	13.5416
2144.21	6.75849
2147.87	8.26972
2151.54	6.10125
2155.2	2.11183
2158.86	5.46285
2162.52	0.592697
2166.17	-4.2456
2169.83	3.70952
2173.48	3.49725
2177.13	8.77511
2180.78	4.05386
2184.43	7.52104
2188.08	6.46854
2191.72	15.469
2195.36	-0.048645
2199.01	6.30262
2202.65	2.6485
2206.29	5.39661
2209.92	5.42974
2213.56	12.8048
2217.19	2.78901
2220.82	14.7863
2224.45	1.99564
2228.08	2.05589
2231.71	8.57803
2235.33	7.74007
2238.96	3.19532
2242.58	5.12406
2246.2	8.91294
2249.82	14.5803
2253.44	0.718384
2257.06	12.9502
2260.67	12.1362
2264.28	-4.61368
2267.9	6.73384
2271.5	6.87188
2275.11	11.6901
2278.72	12.7179
2282.32	8.00776
2285.93	8.00735
2289.53	-1.44344
2293.13	11.7766
2296.73	13.6611
2300.32	6.08395
2303.92	14.5866
2307.52	5.06287
2311.11	21.1123
2314.7	46.6242
2318.29	153.611
2321.88	250.056
2325.46	202.296
2329.05	50.6099
2332.63	14.4531
2336.21	12.3179
2339.79	8.28966
2343.37	11.781
2346.95	9.61517
2350.52	6.51138
2354.09	0.608383
2357.67	29.2446
2361.24	6.54229
2364.81	3.44467
2368.37	11.4972
2371.94	2.88201
2375.5	13.7008
2379.07	17.1016
2382.63	16.8218
2386.19	8.27637
2389.74	8.04317
2393.3	5.9993
2396.85	2.16048
2400.41	13.9445
2403.96	-1.7025
2407.51	8.32847
2411.06	18.4165
2414.61	5.60251
2418.15	8.41418
2421.7	7.5712
2425.24	5.83231
2428.78	-1.4212
2432.32	12.5939
2435.86	12.79
2439.39	9.28364
2442.93	6.70126
2446.46	10.6436
2449.99	4.33508
2453.52	5.52065
2457.05	14.161
2460.58	2.0004
2464.1	10.5377
2467.63	6.7251
2471.15	5.82878
2474.67	6.63174
2478.19	16.8348
2481.71	6.31059
2485.22	10.8244
2488.74	17.1294
2492.25	1.87795
2495.77	7.23859
2499.28	5.12595
2502.78	10.465
2506.29	16.6962
2509.8	4.23346
2513.3	2.05654
2516.8	16.6329
2520.31	17.2733
2523.81	9.48708
2527.3	12.0188
2530.8	9.03396
2534.3	-2.23895
2537.79	7.75675
2541.28	11.3144
2544.77	9.39431
2548.26	9.37328
2551.75	14.902
2555.24	13.9963
2558.72	7.5919
2562.2	16.9454
2565.68	10.579
2569.16	7.95192
2572.64	6.27775
2576.12	17.7388
2579.6	17.069
2583.07	4.14318
2586.54	8.16173
2590.01	10.2742
2593.48	18.0326
2596.95	10.5537
2600.42	3.07767
2603.88	20.4455
2607.35	11.9088
2610.81	8.03768
2614.27	16.549
2617.73	6.86507
2621.19	9.60908
2624.64	2.7168
2628.1	4.43616
2631.55	9.97189
2635	13.5477
2638.45	12.2813
2641.9	21.5224
2645.35	19.2343
2648.79	10.2576
2652.24	11.7593
2655.68	4.65617
2659.12	11.79
2662.56	-0.0674591
2666	12.6797
2669.44	8.39315
2672.87	6.93597
2676.31	8.31727
2679.74	13.4531
2683.17	15.7906
2686.6	18.1644
2690.03	5.70415
2693.45	5.41959
2696.88	11.6209
2700.3	11.3279
2703.73	13.8287
2707.15	15.3957
2710.57	13.3394
2713.98	3.86306
2717.4	6.50352
2720.81	5.44307
2724.23	26.7862
2727.64	8.95684
2731.05	10.7295
2734.46	7.81495
2737.87	2.07996
2741.27	8.52035
2744.68	10.249
2748.08	11.9575
2751.48	5.2047
2754.88	2.1926
2758.28	1.04132
2761.68	11.1935
2765.08	-1.30026
2768.47	-5.34055
2771.86	13.2106
2775.25	16.6683
2778.64	17.2703
2782.03	2.7832
2785.42	-1.35208
2788.81	16.141
2792.19	10.1064
2795.58	4.07042
2798.96	-4.77667
2802.34	-6.13165
2805.71	12.1974
2809.09	11.759
2812.47	10.3741
2815.84	10.8496
2819.22	1.97668
2822.59	11.803
2825.96	2.97751
2829.33	9.08521
2832.69	3.08945
2836.06	12.0255
2839.42	-1.37497
2842.79	5.74312
2846.15	3.57608
2849.51	2.38689
2852.87	0.294785
2856.22	6.58827
2859.58	-2.05302
2862.93	1.47417
2866.29	1.26379
2869.64	-4.57774
2872.99	0.830093
2876.34	5.30276
2879.68	6.95502
2883.03	-1.76144
2886.38	-2.0188
2889.72	16.5984
2893.06	7.83891
2896.4	13.2089
2899.74	23.2895
2903.08	10.6443
2906.41	18.789
2909.75	14.618
2913.08	18.9494
2916.41	12.8594
2919.74	-1.76875
2923.07	8.18977
2926.4	7.72705
2929.72	-4.09879
2933.05	10.5115
2936.37	5.25974
2939.69	2.84238
2943.01	9.84807
2946.33	20.6114
2949.65	5.02251
2952.97	12.0091
2956.28	3.95886
2959.6	10.9632
2962.91	11.4055
2966.22	19.3587
2969.53	2.97212
2972.84	11.9396
2976.14	17.16
2979.45	16.7821
2982.75	12.6287
2986.05	19.7475
2989.36	7.16208
2992.65	20.8733
2995.95	16.7506
2999.25	20.1538
3002.54	22.6176
3005.84	18.4981
3009.13	20.0365
3012.42	8.40155
3015.71	16.5462
3019	13.3819
3022.29	18.7018
3025.57	21.1972
3028.86	31.2534
3032.14	31.8693
3035.42	41.93
3038.7	45.3749
3041.98	20.4409
3045.26	20.0999
3048.54	49.12
3051.81	42.1632
3055.08	35.2067
3058.36	39.6181
3061.63	45.8661
3064.9	57.8426
3068.16	40.3783
3071.43	58.9362
3074.7	56.4136
3077.96	55.0739
3081.22	44.1778
3084.48	72.3563
3087.74	68.2852
3091	60.4756
3094.26	61.2349
3097.51	74.0518
3100.77	73.7181
3104.02	81.8944
3107.27	96.8588
3110.52	95.6229
3113.77	99.0609
3117.02	116.808
3120.26	106.004
3123.51	100.912
3126.75	106.297
3129.99	108.819
3133.24	123.739
3136.47	102.437
3139.71	131.642
3142.95	132.25
3146.19	148.118
3149.42	152.571
3152.65	159.898
3155.88	168.169
3159.11	165.007
3162.34	158.974
3165.57	179.665
3168.8	174.563
3172.02	199.977
3175.24	191.024
3178.46	212.576
3181.69	201.687
3184.9	188.906
3188.12	226.627
3191.34	225.238
3194.55	248.629
3197.77	234.851
3200.98	232.504
3204.19	247.318
3207.4	268.804
3210.61	266.517
3213.82	253.8
3217.02	281.078
3220.23	275.062
3223.43	306.167
3226.63	295.469
3229.83	298.104
3233.03	300.784
3236.23	313.901
3239.43	328.092
3242.62	323.283
3245.82	325.17
3249.01	330.878
3252.2	338.555
3255.39	347.215
3258.58	355.882
3261.77	392.178
3264.95	367.291
3268.14	380.533
3271.32	363.157
3274.5	399.247
3277.68	397.127
3280.86	391.073
3284.04	401.147
3287.22	399.785
3290.39	422.217
3293.57	423.716
3296.74	422.339
3299.91	427.641
3303.08	415.959
3306.25	426.017
3309.42	424.603
3312.59	431.653
3315.75	428.216
3318.91	457.982
3322.08	442.182
3325.24	441.575
3328.4	456.12
3331.56	479.172
3334.71	477.678
3337.87	475.307
3341.02	489.035
3344.18	471.651
3347.33	496.873
3350.48	526.978
3353.63	530.682
3356.78	530.707
3359.92	544.916
3363.07	562.054
3366.21	571.68
3369.36	570.983
3372.5	580.705
3375.64	599.974
3378.78	618.358
3381.92	627.359
3385.05	628.774
3388.19	652.972
3391.32	664.912
3394.46	700.517
3397.59	691.391
3400.72	722.582
3403.85	725.446
3406.97	700.864
3410.1	758.068
3413.22	744.935
3416.35	709.647
3419.47	741.945
3422.59	720.784
3425.71	701.328
3428.83	708.438
3431.95	693.474
3435.06	688.842
3438.18	684.011
3441.29	688.844
3444.41	727.061
3447.52	701.171
3450.63	745.836
3453.73	722.679
3456.84	724.294
3459.95	746.717
3463.05	774.8
3466.16	783.797
3469.26	808.781
3472.36	845.853
3475.46	853.822
3478.56	881.715
3481.65	835.861
3484.75	844.917
3487.84	849.318
3490.94	826.502
3494.03	817.202
3497.12	802.221
3500.21	773.982
3503.3	748.628
3506.39	757.07
3509.47	700.516
3512.55	696.473
3515.64	676.6
3518.72	645.215
3521.8	621.698
3524.88	578.936
3527.96	568.727
3531.04	519.452
3534.11	516.279
3537.19	478.791
3540.26	476.3
3543.33	437.294
3546.4	435.926
3549.47	436.9
3552.54	432.057
3555.61	427.157
3558.67	393.969
3561.74	381.585
3564.8	347.288
3567.86	374.487
3570.92	363.021
3573.98	335.17
3577.04	335.796
3580.1	303.188
3583.15	295.208
3586.21	300.467
3589.26	289.609
3592.31	269.221
3595.37	276.326
3598.41	257.809
3601.46	273.409
3604.51	257.714
3607.56	257.146
3610.6	228.213
3613.64	233.319
3616.69	220.464
3619.73	240.683
3622.77	215.622
3625.81	198.148
3628.84	195.797
3631.88	203.794
3634.91	189.174
3637.95	178.422
3640.98	161.138
3644.01	161.774
3647.04	156.852
3650.07	142.434
3653.1	120.545
3656.13	118.054
3659.15	102.064
3662.17	104.851
3665.2	99.1191
3668.22	71.5892
3671.24	71.4377
3674.26	65.6382
3677.28	67.3979
3680.29	42.7259
3683.31	36.9163
3686.32	28.2657
3689.33	41.3751
3692.35	19.4721
3695.36	2.28035
3698.37	32.4384
3701.37	24.7247
3704.38	11.3046
3707.39	10.2135
3710.39	-0.401917
3713.4	5.12677
3716.4	14.4459
3719.4	-0.00823975
3722.4	-1.16324
3725.4	-5.18755
3728.39	-8.27345
3731.39	3.86818
3734.38	3.6156
3737.38	2.39478
3740.37	4.01773
3743.36	3.71945
3746.35	0.55574
3749.34	4.98607
3752.33	-8.64987
3755.32	-4.23331
3758.3	-10.2574
3761.28	-10.5893
3764.27	-6.19459
3767.25	1.03512
3770.23	-13.5008
3773.21	-10.043
3776.19	-7.52805
3779.16	-5.95624
3782.14	-5.3261
3785.11	3.8006
3788.09	-3.1236
3791.06	-9.09756
3794.03	-8.44971
3797	-4.02222
3799.97	-11.8639
3802.94	-4.59204
3805.9	4.57283
3808.87	4.29337
3811.83	-12.9974
3814.8	11.2981
3817.76	-0.335327
3820.72	-9.14214
3823.68	-0.918182
3826.63	2.57854
3829.59	-2.45857
3832.55	-5.61286
3835.5	-0.226212
3838.45	-8.13233
3841.41	-6.55264
3844.36	-6.88239
3847.31	5.15659
3850.26	-3.74976
3853.2	3.53624
3856.15	-0.624496
3859.09	2.84098
3862.04	-4.21243
3864.98	10.714
3867.92	-1.15902
3870.86	-11.1527
3873.8	-3.91044
3876.74	3.3275
3879.68	-0.971085
3882.61	-1.45218
3885.55	7.6542
3888.48	-0.555817
3891.41	2.75353
3894.34	-7.41478
3897.27	-1.25886
3900.2	-1.85678
3903.13	0.416618
3906.06	6.51068
3908.98	4.91484
3911.91	10.0254
3914.83	15.1116
3917.75	-3.8343
3920.67	-4.52043
3923.59	7.2413
3926.51	4.57891
3929.43	2.85663
3932.34	7.82652
3935.26	-5.39372
3938.17	9.16964
3941.08	2.67063
3944	4.76715
3946.91	14.5151
3949.81	6.06955
3952.72	-0.467964
3955.63	-4.14361
3958.54	-4.95203
3961.44	0.93763
3964.34	11.615
3967.25	-0.722603
3970.15	0.35202
3973.05	-6.26239
3975.95	9.18883
3978.84	2.53612
3981.74	2.58548
3984.63	8.38725
3987.53	3.59558
3990.42	-6.98632
3993.32	-2.20599
3996.21	4.50406
3999.1	-5.16027