File: Data/3-Raman/processed/bu32-A-FF1-FI09-L.txt
#Acq. time (s)=	15
#Accumulations=	3
#Range (cm-¹)=	50...5000
#Windows=	1
#Auto scanning=	Off
#Autofocus=	Off
#Macrospot=	Off
#AutoExposure=	Off
#Spike filter=	Multiple accum.
#Delay time (s)=	0
#Binning=	1
#Readout mode=	Signal
#DeNoise=	Lite
#ICS correction=	Off
#Dark correction=	Off
#Inst. Process=	Off
#Detector temperature (°C)=	-60.09
#Instrument=	LabRAM HR Evol
#Detector=	SIN-EM FIVIS
#Objective=	x100_VIS
#Grating=	150 (500nm)
#ND Filter=	100%
#Laser=	532nm_Edge
#Hole=	30.0125
#Temperature=	0
#Range=	Visible
#StageXY=	75x50mm Scan+
#StageZ=	Z motor
#X (µm)=	-16864
#Y (µm)=	2622.4
#Z (µm)=	-406.8
#Full time(s)=	47
#Project=	Buranga
#Sample=	BU18FA32_A
#Site=	A_FF1
#Title=	32-A_FF1_FI09_L
#Remark=
#Date=	09.07.2019 15:07
#Acquired=	09.07.2019 15:07:09
#Data Range:Extract=	16.12.2021 14:53:05
#Base:Fit=	16.12.2021 14:58:50
#Base:Edit=	16.12.2021 14:58:52
#Base:Edit=	16.12.2021 14:58:53
#Base:Edit=	16.12.2021 14:58:53
#Base:Edit=	16.12.2021 14:58:53
#Base:Edit=	16.12.2021 14:58:54
#Base:Edit=	16.12.2021 14:58:54
#Peaks:Remove=	16.12.2021 14:58:56
#Peaks:Remove=	16.12.2021 14:58:57
#Peaks:Remove=	16.12.2021 14:58:58
#Peaks:Remove=	16.12.2021 14:58:59
#Base:Edit=	16.12.2021 14:59:01
#Base:Edit=	16.12.2021 14:59:01
#Base:Edit=	16.12.2021 14:59:02
#Base:Edit=	16.12.2021 14:59:02
#Base:Sub=	16.12.2021 14:59:06
98.6609	1181.86
103.286	916.883
107.909	616.518
112.53	411
117.146	224.654
121.762	125.423
126.376	69.4207
130.988	31.3943
135.595	30.6075
140.202	45.8469
144.807	69.7101
149.41	88.3159
154.008	109.908
158.606	81.9342
163.201	158.645
167.795	594.249
172.384	1101.73
176.973	470.984
181.559	58.4637
186.142	-8.38062
190.724	-45.899
195.304	-55.1292
199.881	-57.8411
204.454	-34.2491
209.028	-6.25549
213.598	18.7089
218.165	46.7844
222.731	58.9108
227.295	40.5255
231.855	-72.8337
236.415	-86.9868
240.972	-39.6793
245.525	14.8208
250.078	65.1086
254.629	119.524
259.175	-6.59912
263.722	-4.69812
268.264	58.9069
272.805	131.73
277.345	112.37
281.88	79.6611
286.415	34.316
290.948	-27.2989
295.477	0.110107
300.005	32.3737
304.529	149.266
309.053	296.026
313.575	398.464
318.093	289.956
322.61	172.537
327.123	93.6863
331.636	51.231
336.145	72.0615
340.653	109.851
345.157	217.065
349.662	377.673
354.164	668.2
358.661	903.153
363.159	665.01
367.652	342.538
372.145	207.564
376.634	131.452
381.123	88.9758
385.608	74.6892
390.092	88.0488
394.572	130.558
399.052	201.511
403.528	301.94
408.004	437.703
412.475	592.248
416.947	699.951
421.414	783.506
425.881	842.659
430.343	881.397
434.806	897.973
439.264	899.157
443.723	885.199
448.177	819.068
452.629	716.252
457.081	646.553
461.528	718.295
465.976	927.825
470.419	767.554
474.862	577.586
479.301	436.387
483.738	355.209
488.175	362.057
492.607	420.39
497.04	539.495
501.468	757.407
505.894	1008.95
510.32	1318.09
514.742	1553.67
519.164	1736.51
523.581	1862
527.997	1937.04
532.412	1989.99
536.823	1922.99
541.232	1757.39
545.641	1649.46
550.046	1519.64
554.449	1662.27
558.851	1715.89
563.25	1610.03
567.646	1497.76
572.042	1330.07
576.434	1116.21
580.824	1019.62
585.214	1027.62
589.599	1151.12
593.983	1433.15
598.367	1800.03
602.746	1947.23
607.123	1644.41
611.498	1043.51
615.873	741.176
620.244	583.989
624.613	487.698
628.98	426.847
633.346	382.986
637.709	363.268
642.069	353.286
646.428	360.757
650.786	399.418
655.14	448.428
659.492	547.572
663.842	699.872
668.192	666.541
672.538	521.218
676.882	370.202
681.223	258.676
685.563	175.742
689.902	120.529
694.238	88.87
698.571	72.4435
702.902	63.3448
707.231	64.2699
711.559	56.2931
715.886	48.1115
720.209	40.2174
724.529	32.6377
728.848	24.9641
733.165	17.5742
737.48	13.6593
741.792	11.8188
746.105	12.0995
750.413	11.65
754.72	13.2449
759.024	16.8114
763.327	18.9109
767.627	17.7491
771.925	14.4303
776.221	11.4321
780.518	7.04916
784.81	0.797577
789.1	-2.22122
793.388	-4.9913
797.674	-9.58286
801.958	-15.1211
806.24	-19.8864
810.52	-23.9453
814.797	-26.4837
819.073	-27.0336
823.347	-26.4219
827.619	-28.5842
831.888	-28.8084
836.156	-28.1451
840.422	-28.399
844.685	-30.4495
848.947	-28.2408
853.206	-25.5961
857.464	-14.3485
861.719	-1.4043
865.973	6.82492
870.224	44.9028
874.474	61.993
878.721	63.2044
882.967	39.2129
887.21	15.8413
891.452	4.17065
895.691	0.999268
899.929	-0.522705
904.164	3.87527
908.397	17.076
912.629	30.0887
916.858	44.9766
921.086	69.7684
925.311	106.293
929.534	153.784
933.756	213.465
937.975	283.328
942.191	366.861
946.406	464.281
950.619	582.297
954.831	716.224
959.04	869.003
963.248	1044.95
967.453	1264.51
971.657	1543.17
975.858	1889.05
980.056	2425.79
984.253	2811.92
988.449	2618.78
992.643	2031.71
996.834	1523.09
1001.02	1302.12
1005.21	1314.02
1009.4	1509.45
1013.58	1844.21
1017.76	2411.74
1021.94	2951.69
1026.12	3067.42
1030.29	2879.13
1034.47	2593.99
1038.64	2278.51
1042.81	1948.87
1046.98	1542.85
1051.14	1181.49
1055.3	969.124
1059.47	842.742
1063.63	860.346
1067.78	1011.53
1071.94	1230.81
1076.09	1427.07
1080.25	1482.62
1084.4	1429.04
1088.54	1218.72
1092.69	991.173
1096.83	880.661
1100.98	838.134
1105.12	822.592
1109.26	957.582
1113.39	1132.46
1117.53	1265.15
1121.66	1165.62
1125.79	898.652
1129.92	658.017
1134.04	455.306
1138.17	363.338
1142.29	289.434
1146.41	245.716
1150.53	211.255
1154.65	182.77
1158.76	158.861
1162.88	137.406
1166.99	117.561
1171.1	100.087
1175.2	85.0242
1179.31	72.2361
1183.41	61.4324
1187.51	53.3069
1191.61	47.586
1195.71	43.2016
1199.81	40.0788
1203.9	36.1989
1207.99	32.6214
1212.08	29.9526
1216.17	28.0898
1220.26	27.2552
1224.34	27.2287
1228.42	28.0646
1232.5	29.448
1236.58	28.5345
1240.66	27.4116
1244.73	27.5915
1248.81	34.4026
1252.88	42.0087
1256.95	55.8938
1261.02	72.7329
1265.08	94.6195
1269.14	113.423
1273.2	122.759
1277.27	116.418
1281.32	100.053
1285.38	83.5515
1289.43	67.5843
1293.48	52.0115
1297.53	37.4321
1301.58	30.5864
1305.63	25.8398
1309.67	23.9208
1313.72	24.9495
1317.76	26.1594
1321.8	27.0849
1325.83	28.038
1329.87	29.1893
1333.9	30.6017
1337.93	32.1126
1341.96	35.6138
1345.99	38.2355
1350.02	41.942
1354.04	47.1492
1358.06	58.5826
1362.08	74.2699
1366.1	102.532
1370.12	140.67
1374.13	248.166
1378.14	436.095
1382.16	540.09
1386.16	398.5
1390.17	213.64
1394.18	139.224
1398.18	94.9962
1402.18	69.2282
1406.18	53.1424
1410.18	36.7298
1414.18	31.0425
1418.17	24.5721
1422.16	16.742
1426.15	13.8404
1430.14	11.8112
1434.13	12.0616
1438.11	12.2537
1442.1	13.3479
1446.08	15.7973
1450.06	16.1926
1454.04	15.9987
1458.01	13.7296
1461.98	11.6887
1465.96	9.77522
1469.93	9.32677
1473.9	11.0474
1477.86	12.7453
1481.83	12.0607
1485.79	13.023
1489.75	16.315
1493.71	18.4533
1497.67	19.027
1501.62	18.9655
1505.58	18.5097
1509.53	17.8041
1513.48	17.6244
1517.43	17.636
1521.38	17.9688
1525.32	18.7224
1529.26	19.9782
1533.2	21.2525
1537.14	23.9051
1541.08	27.3241
1545.02	31.4119
1548.95	36.0148
1552.88	39.9458
1556.81	42.4696
1560.74	42.7721
1564.67	43.8258
1568.6	45.2664
1572.52	47.4176
1576.44	50.4485
1580.36	54.8632
1584.28	60.181
1588.19	66.7722
1592.11	73.4679
1596.02	80.6401
1599.93	88.9225
1603.84	96.691
1607.75	103.953
1611.65	111.027
1615.56	116.225
1619.46	123.102
1623.36	130.292
1627.25	137.021
1631.15	140.978
1635.05	144.123
1638.94	146.128
1642.83	147.343
1646.72	146.844
1650.61	143.055
1654.49	137.435
1658.38	130.593
1662.26	120.185
1666.14	111.239
1670.02	104.415
1673.89	98.2502
1677.77	88.5233
1681.64	81.8001
1685.51	77.1087
1689.38	72.8293
1693.25	68.0614
1697.12	63.0081
1700.98	56.9866
1704.85	50.9561
1708.71	44.2491
1712.57	38.6001
1716.42	34.1007
1720.28	30.8823
1724.13	28.6082
1727.99	27.0204
1731.84	24.315
1735.69	21.4637
1739.53	18.3251
1743.38	14.9784
1747.22	11.2942
1751.06	7.69679
1754.9	4.71294
1758.74	1.98515
1762.58	2.34656
1766.41	2.45639
1770.25	1.90298
1774.08	1.166
1777.91	0.202774
1781.73	-1.31482
1785.56	-3.04041
1789.39	-4.8215
1793.21	-6.8438
1797.03	-8.8806
1800.85	-10.9622
1804.67	-12.6891
1808.48	-14.4849
1812.3	-16.3179
1816.11	-18.1937
1819.92	-19.7307
1823.73	-18.3157
1827.54	-16.1836
1831.34	-14.4205
1835.14	-13.1735
1838.95	-12.8069
1842.75	-12.1332
1846.55	-12.9825
1850.34	-14.3814
1854.14	-13.6709
1857.93	-13.1175
1861.72	-12.108
1865.51	-10.1894
1869.3	-8.60062
1873.09	-7.36687
1876.87	-6.35658
1880.66	-5.64877
1884.44	-5.06897
1888.22	-5.30898
1892	-4.80031
1895.77	-4.14275
1899.55	-3.66666
1903.32	-3.08722
1907.09	-2.76923
1910.86	-2.79526
1914.63	-3.11693
1918.4	-3.35487
1922.16	-3.6964
1925.92	-4.72073
1929.68	-4.22327
1933.44	-3.37743
1937.2	-2.54665
1940.96	-1.69102
1944.71	-0.98909
1948.46	-1.9158
1952.22	-1.58826
1955.97	-1.56583
1959.71	0.470596
1963.46	2.57552
1967.2	4.47679
1970.95	6.0856
1974.69	7.27899
1978.43	8.2151
1982.17	8.98914
1985.9	9.7366
1989.64	10.3176
1993.37	10.2734
1997.1	10.9772
2000.83	12.5335
2004.56	15.2147
2008.28	17.321
2012.01	19.7936
2015.73	21.881
2019.45	21.7447
2023.17	20.8269
2026.89	25.9149
2030.6	30.3149
2034.32	31.7551
2038.03	31.0105
2041.74	30.1326
2045.45	29.185
2049.16	27.2876
2052.87	27.329
2056.57	28.6032
2060.27	31.4034
2063.98	33.8469
2067.67	36.9413
2071.37	36.9873
2075.07	35.423
2078.76	33.6899
2082.46	29.8891
2086.15	28.3842
2089.84	27.8282
2093.53	28.7304
2097.21	29.9208
2100.9	31.2651
2104.58	33.4271
2108.26	35.8842
2111.94	36.6933
2115.62	36.9621
2119.3	37.3107
2122.97	37.6978
2126.64	38.1778
2130.32	38.2375
2133.99	38.6583
2137.66	40.2225
2141.32	41.192
2144.99	42.8493
2148.65	30.6971
2152.31	36.1619
2155.97	40.2922
2159.63	43.0388
2163.29	43.3531
2166.94	42.932
2170.6	41.2174
2174.25	38.9917
2177.9	37.2311
2181.55	35.9501
2185.2	35.1112
2188.84	33.9595
2192.49	32.3344
2196.13	30.2843
2199.77	30.3762
2203.41	32.9632
2207.05	31.1861
2210.69	31.7618
2214.32	31.2489
2217.95	29.053
2221.59	25.9368
2225.22	18.7513
2228.84	18.8559
2232.47	20.2881
2236.09	19.7787
2239.72	19.5114
2243.34	21.5956
2246.96	18.6843
2250.58	14.209
2254.2	10.6663
2257.81	11.0058
2261.42	11.5735
2265.04	12.0872
2268.65	12.2209
2272.26	11.2847
2275.86	10.6919
2279.47	10.5605
2283.08	10.9569
2286.68	11.1133
2290.28	10.5656
2293.88	10.0295
2297.48	9.84875
2301.07	9.54492
2304.67	8.8645
2308.26	8.53217
2311.85	8.64682
2315.44	9.78571
2319.03	9.1998
2322.62	10.9452
2326.2	14.7561
2329.79	13.3232
2333.37	12.0166
2336.95	10.1688
2340.53	9.2937
2344.11	10.8791
2347.68	11.2027
2351.26	11.5194
2354.83	8.66779
2358.4	6.11847
2361.97	3.60529
2365.54	2.93472
2369.11	4.76193
2372.67	9.27252
2376.23	16.219
2379.8	22.2789
2383.36	19.5852
2386.92	17.2717
2390.47	13.7733
2394.03	11.3857
2397.58	10.2816
2401.14	10.2781
2404.69	11.5236
2408.24	11.743
2411.78	11.2149
2415.33	10.6635
2418.88	10.6924
2422.42	12.0101
2425.96	12.5377
2429.5	12.9211
2433.04	13.8308
2436.58	13.9947
2440.11	12.5202
2443.65	9.85516
2447.18	8.15128
2450.71	7.14633
2454.24	3.79822
2457.77	2.66711
2461.3	2.41116
2464.82	1.06616
2468.34	-0.047699
2471.86	-0.718262
2475.39	-0.621552
2478.9	-1.02451
2482.42	-0.918213
2485.94	1.77899
2489.45	3.49411
2492.96	-0.977478
2496.47	-4.81393
2499.98	-14.0376
2503.49	-14.4534
2507	-13.3252
2510.5	-5.1922
2514.01	3.74649
2517.51	6.01514
2521.01	8.30417
2524.51	7.89255
2528.01	6.7406
2531.5	5.50089
2535	4.01727
2538.49	2.47073
2541.98	0.881561
2545.47	0.340729
2548.96	0.482391
2552.45	0.90274
2555.93	0.955048
2559.42	0.611664
2562.9	0.128967
2566.38	-0.331757
2569.86	-0.824249
2573.34	-2.1738
2576.81	-2.3732
2580.29	-3.51682
2583.76	-5.51154
2587.23	-7.54089
2590.71	-11.0278
2594.17	-14.7675
2597.64	-20.9362
2601.11	-25.5377
2604.57	-26.0442
2608.03	-26.6492
2611.5	-26.0185
2614.96	-24.7548
2618.42	-20.9606
2621.87	-17.0594
2625.33	-15.7178
2628.78	-15.5768
2632.23	-15.7814
2635.68	-16.4669
2639.13	-17.5323
2642.58	-20.3586
2646.03	-23.773
2649.47	-26.6825
2652.92	-29.067
2656.36	-30.8188
2659.8	-33.6616
2663.24	-29.692
2666.68	-23.2916
2670.11	-20.478
2673.55	-18.0815
2676.98	-40.419
2680.41	-36.7259
2683.84	-28.1697
2687.27	-18.6166
2690.7	-16.9052
2694.13	-16.9282
2697.55	-19.0694
2700.97	-21.7351
2704.4	-24.8082
2707.82	-27.6618
2711.23	-27.6572
2714.65	-27.5427
2718.07	-27.2201
2721.48	-26.7127
2724.9	-25.8577
2728.31	-25.7884
2731.72	-25.9292
2735.12	-28.092
2738.53	-30.1446
2741.94	-32.4062
2745.34	-36.2802
2748.74	-39.5603
2752.14	-40.3916
2755.54	-39.7219
2758.94	-38.5926
2762.34	-37.3088
2765.73	-35.8294
2769.13	-36.6769
2772.52	-36.05
2775.91	-34.1872
2779.3	-31.5972
2782.69	-33.1854
2786.08	-35.058
2789.46	-38.6063
2792.85	-41.574
2796.23	-43.408
2799.61	-43.4972
2802.99	-41.5636
2806.37	-37.1935
2809.74	-33.3714
2813.12	-30.0022
2816.49	-27.3652
2819.86	-30.1688
2823.23	-33.9322
2826.61	-36.402
2829.97	-37.6147
2833.34	-37.7215
2836.7	-37.3853
2840.07	-35.7361
2843.43	-34.8211
2846.79	-35.4321
2850.15	-37.5473
2853.51	-40.2774
2856.87	-43.2191
2860.22	-42.6725
2863.57	-41.6003
2866.93	-40.1036
2870.28	-38.197
2873.63	-36.5425
2876.98	-37.3764
2880.32	-35.6528
2883.67	-32.9074
2887.01	-30.3517
2890.35	-29.3796
2893.69	-29.8962
2897.03	-30.0638
2900.37	-30.9122
2903.71	-30.3589
2907.04	-29.3399
2910.38	-28.3022
2913.71	-26.2562
2917.04	-23.3932
2920.37	-19.9013
2923.7	-15.7372
2927.03	-11.2923
2930.35	-7.2493
2933.68	-2.81436
2937	-4.039
2940.32	-0.0346985
2943.64	6.82303
2946.96	14.8254
2950.27	20.5628
2953.59	26.856
2956.91	27.2611
2960.22	31.973
2963.53	43.2896
2966.84	49
2970.15	54.0569
2973.46	53.4814
2976.76	46.1421
2980.07	49.612
2983.37	65.8418
2986.67	76.0677
2989.97	83.0069
2993.27	90.5038
2996.57	94.3396
2999.86	98.0234
3003.16	104.021
3006.45	112.571
3009.75	123.429
3013.03	137.246
3016.32	152.656
3019.61	164.839
3022.9	178.815
3026.19	194.675
3029.47	211.007
3032.75	222.442
3036.03	232.595
3039.31	246.496
3042.59	260.562
3045.87	271.536
3049.14	282.013
3052.42	295.736
3055.69	314.324
3058.96	331.733
3062.23	344.818
3065.5	359.89
3068.77	376.908
3072.03	397.523
3075.3	415.393
3078.56	425.161
3081.82	478.954
3085.08	504.25
3088.34	526.033
3091.6	542.674
3094.86	559.288
3098.11	590.781
3101.36	624.276
3104.62	665.306
3107.87	703.748
3111.12	739.005
3114.37	776.843
3117.61	800.474
3120.86	839.596
3124.1	872.009
3127.34	903.97
3130.59	927.25
3133.83	974.625
3137.07	1020.64
3140.3	1052.4
3143.54	1087.61
3146.77	1126.88
3150.01	1167.76
3153.24	1214.81
3156.47	1264.66
3159.7	1316.41
3162.93	1367.25
3166.15	1419.23
3169.38	1472.31
3172.6	1521.52
3175.83	1561.2
3179.05	1595.56
3182.27	1643.32
3185.49	1700.48
3188.7	1755.1
3191.92	1807.87
3195.13	1858.89
3198.35	1908.16
3201.56	1956.01
3204.77	2001.61
3207.98	2046.77
3211.19	2090.08
3214.39	2131.24
3217.6	2170.94
3220.8	2207.23
3224	2242.37
3227.21	2282.4
3230.41	2324.14
3233.6	2367.21
3236.8	2401.73
3240	2431.56
3243.19	2465.95
3246.39	2500.81
3249.58	2542.74
3252.77	2583.69
3255.96	2623.65
3259.15	2652.85
3262.33	2687.65
3265.52	2718.91
3268.7	2750.81
3271.89	2787.94
3275.07	2825.92
3278.25	2850.02
3281.43	2875.24
3284.6	2898.88
3287.78	2917.49
3290.95	2933.7
3294.13	2946.72
3297.3	2960.13
3300.47	2973.86
3303.64	3000.75
3306.81	3031.73
3309.98	3004.27
3313.14	3078.96
3316.31	3109.35
3319.47	3140.3
3322.63	3172.11
3325.79	3208.77
3328.95	3243.49
3332.11	3270.63
3335.27	3299.96
3338.42	3334.79
3341.58	3374.17
3344.73	3417.35
3347.88	3463.32
3351.03	3510.09
3354.18	3557.46
3357.33	3602.63
3360.47	3648.73
3363.62	3649.99
3366.76	3743.27
3369.91	3792.39
3373.05	3843.37
3376.19	3897.25
3379.32	3950.01
3382.46	4001.35
3385.6	4055.46
3388.73	4119.32
3391.87	4182.35
3395	4254.1
3398.13	4327.13
3401.26	4418.85
3404.39	4495.7
3407.51	4567.42
3410.64	4629.52
3413.76	4668.04
3416.89	4687.41
3420.01	4674.57
3423.13	4638.04
3426.25	4602.63
3429.37	4570.68
3432.48	4544.83
3435.6	4530.6
3438.71	4517.8
3441.83	4518.33
3444.94	4523.65
3448.05	4520.35
3451.16	4523.22
3454.27	4528.91
3457.37	4537.61
3460.48	4544.73
3463.58	4547.69
3466.69	4567.76
3469.79	4596.04
3472.89	4645.12
3475.99	4688.37
3479.08	4713.49
3482.18	4722.22
3485.28	4716.65
3488.37	4694.7
3491.46	4656.46
3494.55	4602.14
3497.64	4535.36
3500.73	4455.27
3503.82	4361.72
3506.91	4256.78
3509.99	4152.93
3513.08	4049.98
3516.16	3947.15
3519.24	3842.68
3522.32	3733.1
3525.4	3601.9
3528.48	3472.5
3531.55	3348.71
3534.63	3229.57
3537.7	3115.14
3540.78	3010.17
3543.85	2908.99
3546.92	2812.06
3549.99	2721.94
3553.05	2636.03
3556.12	2572.68
3559.19	2515.53
3562.25	2458.84
3565.31	2402.99
3568.37	2330.88
3571.43	2261.3
3574.49	2179.42
3577.55	2098.29
3580.61	2011.58
3583.66	1929.01
3586.72	1863
3589.77	1803.68
3592.82	1752.3
3595.87	1710.96
3598.92	1665.69
3601.97	1630.49
3605.02	1592.07
3608.06	1546.59
3611.11	1495.33
3614.15	1452.12
3617.19	1411.37
3620.23	1374.66
3623.27	1325.55
3626.31	1276.99
3629.34	1229.74
3632.38	1184.95
3635.41	1142.48
3638.45	1105.47
3641.48	1065.8
3644.51	1016.68
3647.54	962.545
3650.57	908.991
3653.59	849.953
3656.62	787.542
3659.65	726.485
3662.67	668.003
3665.69	613.802
3668.71	557.517
3671.73	500.629
3674.75	445
3677.77	390.63
3680.78	347.035
3683.8	302.699
3686.81	261.33
3689.82	223.616
3692.84	192.18
3695.84	165.451
3698.85	146.037
3701.86	122.866
3704.87	101.588
3707.87	79.5878
3710.88	54.8275
3713.88	33.2015
3716.88	25.6288
3719.88	22.0256
3722.88	20.2741
3725.88	18.4257
3728.88	15.5285
3731.87	8.66364
3734.87	1.20386
3737.86	-5.31427
3740.85	-10.4152
3743.84	-15.9247
3746.83	-20.5704
3749.82	-24.856
3752.81	-30.5806
3755.79	-30.3257
3758.78	-30.5495
3761.76	-26.5283
3764.74	-24.9096
3767.73	-25.0871
3770.71	-27.9102
3773.68	-31.3764
3776.66	-33.6703
3779.64	-34.5298
3782.61	-33.8135
3785.59	-31.6728
3788.56	-28.1554
3791.53	-24.2666
3794.5	-20.7232
3797.47	-17.1553
3800.44	-13.9654
3803.41	-10.5294
3806.37	-4.95264
3809.34	-3.50769
3812.3	-3.11536
3815.26	-1.87677
3818.22	-0.112579
3821.18	1.11108
3824.14	3.14471
3827.1	4.20236
3830.06	5.89999
3833.01	6.48737
3835.96	6.39774
3838.92	7.15918
3841.87	8.26282
3844.82	9.86517
3847.77	12.1053
3850.72	14.7772
3853.66	17.695
3856.61	18.568
3859.55	15.3655
3862.5	13.4919
3865.44	13.5423
3868.38	18.4868
3871.32	23.8874
3874.26	30.6678
3877.2	33.2303
3880.13	35.763
3883.07	37.5778
3886	39.4373
3888.94	39.7459
3891.87	39.5866
3894.8	39.9401
3897.73	42.4878
3900.66	44.6641
3903.58	45.941
3906.51	47.27
3909.43	47.9868
3912.36	48.3659
3915.28	48.5104
3918.2	48.5683
3921.12	48.4382
3924.04	47.8068
3926.96	45.6981
3929.87	44.4138
3932.79	45.3162
3935.7	45.7019
3938.62	44.2992
3941.53	42.6464
3944.44	40.9037
3947.35	39.0176
3950.26	37.033
3953.17	34.4476
3956.07	31.0226
3958.98	27.7884
3961.88	24.5224
3964.78	21.1643
3967.69	17.3966
3970.59	13.341
3973.49	8.93329
3976.38	4.57141
3979.28	-1.78125
3982.18	-7.24814
3985.07	-11.1728
3987.97	-13.9392
3990.86	-18.8108
3993.75	-28.1748
3996.64	-38.3689
3999.53	-48.5001