File: Data/3-Raman/processed/bu32-C-FF1-FI02-S.txt
#Acq. time (s)=	15
#Accumulations=	3
#Range (cm-¹)=	50...5000
#Windows=	1
#Auto scanning=	Off
#Autofocus=	Off
#Macrospot=	Off
#AutoExposure=	Off
#Spike filter=	Multiple accum.
#Delay time (s)=	0
#Binning=	1
#Readout mode=	Signal
#DeNoise=	Lite
#ICS correction=	Off
#Dark correction=	Off
#Inst. Process=	Off
#Detector temperature (°C)=	-60.09
#Instrument=	LabRAM HR Evol
#Detector=	SIN-EM FIVIS
#Objective=	x100_VIS
#Grating=	150 (500nm)
#ND Filter=	100%
#Laser=	532nm_Edge
#Hole=	30.0125
#Temperature=	0
#Range=	Visible
#StageXY=	75x50mm Scan+
#StageZ=	Z motor
#X (µm)=	17694.9
#Y (µm)=	4317
#Z (µm)=	-382.9
#Full time(s)=	47
#Project=	Buranga
#Sample=	BU18FA32_C
#Site=	C_FF1
#Title=	32-C_FF1_FI02_S
#Remark=
#Date=	09.07.2019 16:43
#Acquired=	09.07.2019 16:43:51
#Data Range:Extract=	16.12.2021 14:53:05
#Base:Fit=	16.12.2021 15:00:27
#Base:Edit=	16.12.2021 15:00:29
#Base:Edit=	16.12.2021 15:00:29
#Base:Edit=	16.12.2021 15:00:30
#Base:Edit=	16.12.2021 15:00:30
#Base:Edit=	16.12.2021 15:00:32
#Peaks:Remove=	16.12.2021 15:00:33
#Peaks:Remove=	16.12.2021 15:00:34
#Peaks:Remove=	16.12.2021 15:00:35
#Peaks:Remove=	16.12.2021 15:00:38
#Base:Edit=	16.12.2021 15:00:39
#Base:Edit=	16.12.2021 15:00:39
#Peaks:Remove=	16.12.2021 15:00:41
#Peaks:Remove=	16.12.2021 15:00:48
#Peaks:Remove=	16.12.2021 15:00:49
#Peaks:Remove=	16.12.2021 15:00:50
#Peaks:Remove=	16.12.2021 15:00:51
#Peaks:Remove=	16.12.2021 15:00:54
#Peaks:Remove=	16.12.2021 15:00:56
#Peaks:Remove=	16.12.2021 15:00:58
#Peaks:Remove=	16.12.2021 15:00:59
#Peaks:Remove=	16.12.2021 15:01:00
#Peaks:Remove=	16.12.2021 15:01:01
#Base:Edit=	16.12.2021 15:01:03
#Base:Edit=	16.12.2021 15:01:05
#Base:Edit=	16.12.2021 15:01:06
#Base:Edit=	16.12.2021 15:01:06
#Base:Edit=	16.12.2021 15:01:08
#Base:Edit=	16.12.2021 15:01:08
#Base:Edit=	16.12.2021 15:01:11
#Base:Sub=	16.12.2021 15:01:14
98.6609	1131.98
103.286	1668.45
107.909	1017.97
112.53	387.341
117.146	113.968
121.762	8.76904
126.376	9.17383
130.988	18.0981
135.595	44.0659
140.202	93.4771
144.807	161.173
149.41	235.502
154.008	315.033
158.606	887.039
163.201	908.419
167.795	877.292
172.384	894.94
176.973	905.75
181.559	1060.6
186.142	1185.86
190.724	1287.89
195.304	1359.26
199.881	1371.9
204.454	1599.74
209.028	2260.63
213.598	3378.25
218.165	4426.39
222.731	4431.06
227.295	3142.34
231.855	1867.3
236.415	1133.32
240.972	748.527
245.525	516.519
250.078	312.6
254.629	240.112
259.175	331.871
263.722	370.275
268.264	320.538
272.805	226.556
277.345	133.605
281.88	57.2703
286.415	-10.9116
290.948	-21.3157
295.477	-12.2886
300.005	4.31445
304.529	19.9299
309.053	40.4935
313.575	69.2633
318.093	108.016
322.61	154.871
327.123	214.412
331.636	282.379
336.145	374.905
340.653	513.778
345.157	660.635
349.662	811.59
354.164	866.613
358.661	737.225
363.159	716.227
367.652	771.684
372.145	903.405
376.634	1120.45
381.123	1335.66
385.608	1721.99
390.092	2384.36
394.572	3448.15
399.052	5090.17
403.528	7162.39
408.004	8576.65
412.475	7398.54
416.947	5263.79
421.414	3622.86
425.881	2751.46
430.343	2241.43
434.806	1880.45
439.264	1591.86
443.723	1389.15
448.177	1304.21
452.629	1321.4
457.081	1221.21
461.528	1047.57
465.976	876.4
470.419	735.451
474.862	658.448
479.301	599.03
483.738	639.491
488.175	712.971
492.607	811.214
497.04	925.402
501.468	1074.37
505.894	1206.79
510.32	1303.44
514.742	1368.79
519.164	1402.22
523.581	1408.1
527.997	1331.95
532.412	1261.14
536.823	1192.66
541.232	1126.49
545.641	1165.57
550.046	1172.05
554.449	1129.81
558.851	1061.34
563.25	957.08
567.646	854.555
572.042	771.548
576.434	695.967
580.824	775.212
585.214	871.174
589.599	1090.72
593.983	1286.88
598.367	1088.41
602.746	862.379
607.123	694.038
611.498	557.33
615.873	459.12
620.244	382.185
624.613	327.434
628.98	295.76
633.346	274.973
637.709	273.342
642.069	276.697
646.428	288.447
650.786	308.195
655.14	337.346
659.492	328.516
663.842	272.097
668.192	217.223
672.538	168.282
676.882	124.307
681.223	97.2973
685.563	79.4355
689.902	66.07
694.238	55.3776
698.571	51.3128
702.902	49.3658
707.231	47.7479
711.559	43.2731
715.886	37.0893
720.209	31.0579
724.529	27.2274
728.848	19.1978
733.165	9.80035
737.48	5.89496
741.792	7.72546
746.105	16.951
750.413	38.2607
754.72	59.0533
759.024	88.3627
763.327	147.711
767.627	254.784
771.925	337.394
776.221	365.711
780.518	361.726
784.81	290.537
789.1	207.536
793.388	130.205
797.674	70.7386
801.958	28.0143
806.24	14.606
810.52	-1.46301
814.797	-13.8111
819.073	-19.8453
823.347	-30.0244
827.619	-48.0796
831.888	-60.8123
836.156	-66.382
840.422	-65.0143
844.685	-57.1925
848.947	-40.4649
853.206	-17.2184
857.464	17.0042
861.719	84.8665
865.973	202.917
870.224	218.642
874.474	102.533
878.721	14.1328
882.967	-26.3434
887.21	-54.7586
891.452	-63.426
895.691	-65.795
899.929	-62.0635
904.164	-55.0755
908.397	-43.5439
912.629	-38.4589
916.858	-24.5946
921.086	-2.29675
925.311	35.219
929.534	78.2818
933.756	129.553
937.975	174.518
942.191	226.757
946.406	290.752
950.619	366.501
954.831	460.682
959.04	564.848
963.248	689.375
967.453	851.082
971.657	1043.65
975.858	1243.83
980.056	1155.75
984.253	906.269
988.449	714.178
992.643	628.198
996.834	612.099
1001.02	823.697
1005.21	1103.73
1009.4	1549.99
1013.58	1893.29
1017.76	2028.53
1021.94	1982.57
1026.12	1833.85
1030.29	1613.36
1034.47	1291.1
1038.64	987.193
1042.81	776.481
1046.98	582.182
1051.14	514.522
1055.3	554.696
1059.47	708.053
1063.63	933.515
1067.78	1070.38
1071.94	926.869
1076.09	734.608
1080.25	595.378
1084.4	477.809
1088.54	397.408
1092.69	333.569
1096.83	331.651
1100.98	356.279
1105.12	420.977
1109.26	472.746
1113.39	435.041
1117.53	348.303
1121.66	265.337
1125.79	182.768
1129.92	135.544
1134.04	105.195
1138.17	93.2008
1142.29	95.8434
1146.41	83.9561
1150.53	72.0061
1154.65	61.6414
1158.76	42.3365
1162.88	41.9402
1166.99	42.4719
1171.1	63.9438
1175.2	82.1053
1179.31	93.0532
1183.41	92.7929
1187.51	81.2475
1191.61	69.7384
1195.71	56.9669
1199.81	46.2195
1203.9	37.5113
1207.99	31.1864
1212.08	26.9745
1216.17	25.4956
1220.26	26.0664
1224.34	28.2613
1228.42	32.2677
1232.5	38.1111
1236.58	42.3628
1240.66	42.248
1244.73	73.4543
1248.81	117.172
1252.88	157.034
1256.95	222.693
1261.02	272.992
1265.08	289.574
1269.14	279.553
1273.2	244.585
1277.27	205.576
1281.32	158.073
1285.38	124.184
1289.43	97.7538
1293.48	83.0554
1297.53	74.4394
1301.58	71.6398
1305.63	68.3018
1309.67	66.0162
1313.72	66.1861
1317.76	67.7249
1321.8	69.0789
1325.83	68.6593
1329.87	69.3936
1333.9	71.0762
1337.93	81.2047
1341.96	90.9435
1345.99	99.5368
1350.02	126.413
1354.04	177.002
1358.06	259.654
1362.08	385.694
1366.1	592.553
1370.12	1117.05
1374.13	1429.92
1378.14	1107.77
1382.16	614.609
1386.16	341.194
1390.17	220.609
1394.18	157.1
1398.18	117.891
1402.18	87.3575
1406.18	61.429
1410.18	42.6631
1414.18	30.1963
1418.17	23.168
1422.16	16.8439
1426.15	16.3467
1430.14	17.2066
1434.13	18.1609
1438.11	18.6415
1442.1	15.5784
1446.08	13.2334
1450.06	11.5331
1454.04	9.35767
1458.01	9.37924
1461.98	11.4689
1465.96	12.9149
1469.93	11.9365
1473.9	11.9415
1477.86	11.7153
1481.83	14.8347
1485.79	20.7901
1489.75	24.7978
1493.71	26.1777
1497.67	24.3043
1501.62	23.4969
1505.58	28.1974
1509.53	30.3202
1513.48	32.7627
1517.43	36.2642
1521.38	40.6949
1525.32	45.0707
1529.26	51.5106
1533.2	55.9411
1537.14	59.2668
1541.08	65.9792
1545.02	77.8218
1548.95	93.6864
1552.88	98.0669
1556.81	102.2
1560.74	107.816
1564.67	115.083
1568.6	123.197
1572.52	134.433
1576.44	148.326
1580.36	162.768
1584.28	180.627
1588.19	198.731
1592.11	216.686
1596.02	233.467
1599.93	251.688
1603.84	268.728
1607.75	285.443
1611.65	301.958
1615.56	316.561
1619.46	334.481
1623.36	352.363
1627.25	365.409
1631.15	372.148
1635.05	370.32
1638.94	362.391
1642.83	357.814
1646.72	351.409
1650.61	341.854
1654.49	325.117
1658.38	300.317
1662.26	280.837
1666.14	262.238
1670.02	247.238
1673.89	228.701
1677.77	208.121
1681.64	188.274
1685.51	168.817
1689.38	149.203
1693.25	129.641
1697.12	113.154
1700.98	100.477
1704.85	89.6601
1708.71	81.0037
1712.57	76.5523
1716.42	70.0046
1720.28	61.4726
1724.13	53.683
1727.99	43.2993
1731.84	33.2111
1735.69	24.6231
1739.53	18.015
1743.38	12.623
1747.22	9.19876
1751.06	6.08231
1754.9	6.55072
1758.74	4.3884
1762.58	2.99927
1766.41	2.3786
1770.25	1.92383
1774.08	-2.1503
1777.91	-6.672
1781.73	-6.0509
1785.56	-7.00854
1789.39	-8.45963
1793.21	-9.90472
1797.03	-10.6139
1800.85	-12.6663
1804.67	-15.6183
1808.48	-18.9778
1812.3	-24.2823
1816.11	-25.1652
1819.92	-23.1267
1823.73	-21.3343
1827.54	-18.9364
1831.34	-15.9959
1835.14	-13.1777
1838.95	-13.9201
1842.75	-13.9201
1846.55	-13.3958
1850.34	-12.373
1854.14	-11.6673
1857.93	-10.2859
1861.72	-8.45673
1865.51	-13.5911
1869.3	-10.8232
1873.09	-6.16766
1876.87	1.16774
1880.66	3.86359
1884.44	5.81322
1888.22	7.27942
1892	8.66455
1895.77	9.83092
1899.55	9.61626
1903.32	9.26006
1907.09	9.27718
1910.86	9.72415
1914.63	11.155
1918.4	11.4121
1922.16	12.5422
1925.92	13.1992
1929.68	13.0947
1933.44	16.8075
1937.2	21.4075
1940.96	25.9611
1944.71	29.8746
1948.46	32.7124
1952.22	34.7496
1955.97	35.86
1959.71	36.0134
1963.46	36.1302
1967.2	36.3743
1970.95	39.7328
1974.69	43.7801
1978.43	46.2491
1982.17	48.7843
1985.9	51.4325
1989.64	53.608
1993.37	54.2984
1997.1	56.0555
2000.83	60.4615
2004.56	64.4953
2008.28	68.2173
2012.01	70.9023
2015.73	71.2297
2019.45	72.8174
2023.17	75.3039
2026.89	78.5198
2030.6	82.0893
2034.32	85.3968
2038.03	89.2323
2041.74	92.917
2045.45	95.389
2049.16	97.3893
2052.87	99.194
2056.57	100.475
2060.27	100.675
2063.98	98.6199
2067.67	97.7199
2071.37	98.5126
2075.07	102.171
2078.76	104.431
2082.46	105.44
2086.15	104.41
2089.84	102.366
2093.53	100.627
2097.21	99.2789
2100.9	97.549
2104.58	95.7008
2108.26	94.4437
2111.94	93.9834
2115.62	92.8006
2119.3	95.2623
2122.97	100.325
2126.64	106.786
2130.32	109.949
2133.99	110.246
2137.66	109.219
2141.32	106.536
2144.99	103.583
2148.65	101.431
2152.31	98.5694
2155.97	95.1717
2159.63	92.8936
2163.29	92.1438
2166.94	92.9176
2170.6	93.889
2174.25	93.0863
2177.9	85.3993
2181.55	87.6565
2185.2	88.445
2188.84	89.8113
2192.49	88.3895
2196.13	83.6996
2199.77	78.9871
2203.41	74.7251
2207.05	70.7282
2210.69	67.1488
2214.32	63.6083
2217.95	62.787
2221.59	61.9455
2225.22	61.7262
2228.84	58.7603
2232.47	55.7821
2236.09	53.156
2239.72	50.638
2243.34	47.8295
2246.96	44.829
2250.58	41.728
2254.2	38.7995
2257.81	36.0114
2261.42	33.3922
2265.04	30.6802
2268.65	28.4254
2272.26	27.2882
2275.86	25.6728
2279.47	23.0692
2283.08	19.8891
2286.68	15.8541
2290.28	12.4094
2293.88	9.76591
2297.48	8.09447
2301.07	7.29643
2304.67	7.18594
2308.26	7.55728
2311.85	7.20505
2315.44	8.93167
2319.03	7.43823
2322.62	4.56714
2326.2	12.0798
2329.79	12.8211
2333.37	10.614
2336.95	6.22031
2340.53	1.73578
2344.11	-2.58466
2347.68	-7.22186
2351.26	-1.08954
2354.83	-3.04059
2358.4	-5.40463
2361.97	-7.0415
2365.54	-8.12802
2369.11	-8.16269
2372.67	-6.90128
2376.23	-4.84573
2379.8	-5.72729
2383.36	-7.73615
2386.92	-9.4502
2390.47	-11.306
2394.03	-11.8551
2397.58	-11.988
2401.14	-11.1445
2404.69	-12.1371
2408.24	-14.5336
2411.78	-18.8771
2415.33	-19.4328
2418.88	-23.2523
2422.42	-27.5934
2425.96	-32.7708
2429.5	-26.1779
2433.04	-25.4087
2436.58	-27.9093
2440.11	-29.9816
2443.65	-33.9036
2447.18	-39.395
2450.71	-41.048
2454.24	-42.1642
2457.77	-42.3974
2461.3	-42.5307
2464.82	-43.2794
2468.34	-43.4632
2471.86	-43.2824
2475.39	-43.5925
2478.9	-44.7441
2482.42	-46.2687
2485.94	-48.0841
2489.45	-49.7336
2492.96	-47.5287
2496.47	-49.1407
2499.98	-50.9988
2503.49	-51.6788
2507	-51.3596
2510.5	-50.1949
2514.01	-48.5173
2517.51	-49.9388
2521.01	-53.0138
2524.51	-56.7197
2528.01	-58.5592
2531.5	-59.2217
2535	-58.3872
2538.49	-57.6702
2541.98	-55.8229
2545.47	-53.478
2548.96	-54.4762
2552.45	-56.5199
2555.93	-58.5775
2559.42	-60.4589
2562.9	-62.2497
2566.38	-64.5663
2569.86	-64.7026
2573.34	-67.0413
2576.81	-69.459
2580.29	-71.7511
2583.76	-73.698
2587.23	-75.301
2590.71	-77.5842
2594.17	-79.3241
2597.64	-81.6482
2601.11	-92.554
2604.57	-86.6195
2608.03	-81.4761
2611.5	-83.0345
2614.96	-83.5583
2618.42	-83.918
2621.87	-80.7859
2625.33	-80.4823
2628.78	-81.2392
2632.23	-81.573
2635.68	-82.0816
2639.13	-80.256
2642.58	-78.1341
2646.03	-76.0398
2649.47	-74.0827
2652.92	-72.2479
2656.36	-72.4167
2659.8	-72.5981
2663.24	-72.6912
2666.68	-72.1155
2670.11	-74.7492
2673.55	-75.3705
2676.98	-74.2184
2680.41	-72.5266
2683.84	-71.0077
2687.27	-69.8027
2690.7	-68.9945
2694.13	-70.0826
2697.55	-68.7151
2700.97	-71.2714
2704.4	-72.7722
2707.82	-72.6628
2711.23	-71.1893
2714.65	-68.677
2718.07	-65.1629
2721.48	-62.5078
2724.9	-60.4052
2728.31	-60.5333
2731.72	-61.3615
2735.12	-61.56
2738.53	-61.0296
2741.94	-59.8925
2745.34	-58.1985
2748.74	-54.4775
2752.14	-53.2937
2755.54	-53.0467
2758.94	-53.9896
2762.34	-52.6504
2765.73	-49.9676
2769.13	-45.0943
2772.52	-44.3416
2775.91	-43.4029
2779.3	-42.0273
2782.69	-40.3062
2786.08	-39.5254
2789.46	-36.5372
2792.85	-32.7535
2796.23	-31.455
2799.61	-27.6425
2802.99	-23.9307
2806.37	-19.8073
2809.74	-16.7161
2813.12	-13.671
2816.49	-10.3378
2819.86	-10.5336
2823.23	-1.5972
2826.61	4.80634
2829.97	11.3354
2833.34	14.4874
2836.7	16.9612
2840.07	19.0468
2843.43	20.0905
2846.79	21.7693
2850.15	26.4246
2853.51	28.9982
2856.87	37.7524
2860.22	47.4928
2863.57	57.4732
2866.93	65.6454
2870.28	69.8086
2873.63	72.678
2876.98	72.8762
2880.32	76.7199
2883.67	82.438
2887.01	84.5976
2890.35	93.0751
2893.69	102.094
2897.03	109.713
2900.37	120.363
2903.71	120.983
2907.04	133.914
2910.38	150.312
2913.71	172.181
2917.04	175.156
2920.37	183.95
2923.7	192.214
2927.03	205.961
2930.35	220.131
2933.68	235.147
2937	249.492
2940.32	264.225
2943.64	276.194
2946.96	287.05
2950.27	301.824
2953.59	317.598
2956.91	333.323
2960.22	348.81
2963.53	367.34
2966.84	390.737
2970.15	415.813
2973.46	438.496
2976.76	460.079
2980.07	482.107
2983.37	500.812
2986.67	521.204
2989.97	543.598
2993.27	566.046
2996.57	593.93
2999.86	622.407
3003.16	650.231
3006.45	673.494
3009.75	693.285
3013.03	727.494
3016.32	762.907
3019.61	799.355
3022.9	831.042
3026.19	866.673
3029.47	906.484
3032.75	948.555
3036.03	992.258
3039.31	1037.71
3042.59	1081.31
3045.87	1126.21
3049.14	1169.55
3052.42	1219.41
3055.69	1272.74
3058.96	1327.9
3062.23	1384.59
3065.5	1442.85
3068.77	1502.4
3072.03	1561.77
3075.3	1621.86
3078.56	1683.09
3081.82	1745.57
3085.08	1809.71
3088.34	1875.42
3091.6	1941.92
3094.86	2008.33
3098.11	2066.29
3101.36	2148.14
3104.62	2249.87
3107.87	2356.74
3111.12	2450.45
3114.37	2540.65
3117.61	2632.41
3120.86	2737.31
3124.1	2843.76
3127.34	2952.73
3130.59	3062.62
3133.83	3172.24
3137.07	3283.3
3140.3	3395.29
3143.54	3508.79
3146.77	3622.33
3150.01	3735.96
3153.24	3847.71
3156.47	3957.36
3159.7	4068.82
3162.93	4176.5
3166.15	4280.41
3169.38	4392.77
3172.6	4528.01
3175.83	4665.29
3179.05	4797.92
3182.27	4927.96
3185.49	5049.61
3188.7	5164.28
3191.92	5269.37
3195.13	5371.34
3198.35	5345.74
3201.56	5514.17
3204.77	5666.91
3207.98	5760.11
3211.19	5858.64
3214.39	5945.88
3217.6	6016.25
3220.8	6098.31
3224	6172.04
3227.21	6241.15
3230.41	6304.46
3233.6	6353.82
3236.8	6402.88
3240	6452.47
3243.19	6503.9
3246.39	6558.04
3249.58	6613.51
3252.77	6663.15
3255.96	6714.34
3259.15	6770.38
3262.33	6817.99
3265.52	6862.94
3268.7	6906.97
3271.89	6953.49
3275.07	6995.08
3278.25	7007.74
3281.43	7046.54
3284.6	7099.19
3287.78	7158.66
3290.95	7222.52
3294.13	7276.38
3297.3	7331.88
3300.47	7386.29
3303.64	7441.53
3306.81	7470.24
3309.98	7530.55
3313.14	7620.34
3316.31	7704.98
3319.47	7769.47
3322.63	7843.03
3325.79	7924.88
3328.95	8008.09
3332.11	8095.83
3335.27	8181.75
3338.42	8270.66
3341.58	8361.73
3344.73	8454.39
3347.88	8545.32
3351.03	8632.84
3354.18	8732.69
3357.33	8832.53
3360.47	8928.72
3363.62	9005.1
3366.76	9072.61
3369.91	9131.39
3373.05	9213.03
3376.19	9300.87
3379.32	9390.85
3382.46	9482.19
3385.6	9574.42
3388.73	9670.88
3391.87	9764.21
3395	9844.24
3398.13	9916.19
3401.26	9991.76
3404.39	10049.9
3407.51	10077.9
3410.64	10087.7
3413.76	10085.6
3416.89	10086.1
3420.01	10103
3423.13	10090.6
3426.25	10048.4
3429.37	10064.2
3432.48	10066
3435.6	10052.3
3438.71	10039.2
3441.83	10008.8
3444.94	9973.77
3448.05	9932.25
3451.16	9892.85
3454.27	9877.78
3457.37	9824.15
3460.48	9768.96
3463.58	9742.51
3466.69	9713.31
3469.79	9682.61
3472.89	9626.96
3475.99	9533.95
3479.08	9437.85
3482.18	9329.42
3485.28	9210.56
3488.37	9081.03
3491.46	8931.89
3494.55	8765.66
3497.64	8594.4
3500.73	8427.84
3503.82	8286.5
3506.91	8163.3
3509.99	7991.8
3513.08	7807.39
3516.16	7620.08
3519.24	7426.53
3522.32	7220.23
3525.4	7015.1
3528.48	6817.17
3531.55	6631.75
3534.63	6412.71
3537.7	6287.92
3540.78	6122.35
3543.85	5972.87
3546.92	5840.09
3549.99	5704.38
3553.05	5565.22
3556.12	5426.14
3559.19	5288.07
3562.25	5149.97
3565.31	5010.17
3568.37	4871.99
3571.43	4735.06
3574.49	4593.96
3577.55	4453.05
3580.61	4306
3583.66	4179.75
3586.72	4064.11
3589.77	3957.22
3592.82	3858.84
3595.87	3767.23
3598.92	3676.56
3601.97	3577.01
3605.02	3472.82
3608.06	3369.45
3611.11	3268.15
3614.15	3168.52
3617.19	3070.98
3620.23	2975
3623.27	2880.94
3626.31	2786.68
3629.34	2686.75
3632.38	2580.67
3635.41	2472.49
3638.45	2365.54
3641.48	2248.39
3644.51	2129.37
3647.54	2009.66
3650.57	1889.76
3653.59	1769.42
3656.62	1649.5
3659.65	1529.56
3662.67	1410.58
3665.69	1295.48
3668.71	1182.99
3671.73	1076.75
3674.75	979.958
3677.77	888.351
3680.78	803.245
3683.8	725.945
3686.81	655.986
3689.82	591.36
3692.84	531.903
3695.84	477.584
3698.85	426.817
3701.86	380.919
3704.87	338.338
3707.87	300.708
3710.88	268.526
3713.88	241.354
3716.88	219.131
3719.88	194.737
3722.88	170.83
3725.88	150.76
3728.88	134.633
3731.87	122.006
3734.87	111.696
3737.86	99.8953
3740.85	82.5567
3743.84	67.1967
3746.83	54.2638
3749.82	45.1627
3752.81	37.5591
3755.79	34.7421
3758.78	31.6944
3761.76	29.6896
3764.74	28.8516
3767.73	26.4472
3770.71	23.6859
3773.68	18.6396
3776.66	13.1281
3779.64	6.81744
3782.61	2.11069
3785.59	-2.37598
3788.56	-3.30994
3791.53	-1.42862
3794.5	-0.582123
3797.47	1.25803
3800.44	2.61169
3803.41	2.94431
3806.37	2.96371
3809.34	2.64896
3812.3	2.98602
3815.26	3.11844
3818.22	2.29581
3821.18	-0.789429
3824.14	-3.50381
3827.1	-4.29407
3830.06	-3.78644
3833.01	-2.43539
3835.96	2.48755
3838.92	11.2302
3841.87	14.9365
3844.82	16.1721
3847.77	15.4712
3850.72	18.7951
3853.66	20.2473
3856.61	20.2106
3859.55	22.5498
3862.5	27.3403
3865.44	30.153
3868.38	31.5933
3871.32	33.4389
3874.26	35.7139
3877.2	36.5843
3880.13	39.7031
3883.07	42.8702
3886	45.7994
3888.94	46.9016
3891.87	47.7706
3894.8	48.6403
3897.73	49.139
3900.66	49.1239
3903.58	49.2557
3906.51	50.6194
3909.43	54.8731
3912.36	57.8456
3915.28	61.0683
3918.2	64.1041
3921.12	64.218
3924.04	61.5895
3926.96	60.726
3929.87	60.8347
3932.79	58.1222
3935.7	56.2559
3938.62	56.3291
3941.53	55.5105
3944.44	55.2105
3947.35	54.7975
3950.26	52.9261
3953.17	50.9933
3956.07	49.1235
3958.98	45.3883
3961.88	40.876
3964.78	36.4716
3967.69	31.9023
3970.59	29.7479
3973.49	27.6387
3976.38	22.8416
3979.28	15.5052
3982.18	9.36316
3985.07	3.74887
3987.97	-1.96988
3990.86	-8.66275
3993.75	-16.1856
3996.64	-23.9171
3999.53	-32.2016