File: Data/3-Raman/processed/bu32-b-ff2-fi01-l_150 (500nm)_532nm_edge_100%_x100_vis_lwd_h30um_30sx2_01.txt
#Acq. time (s)=	30
#Accumulations=	2
#Range (cm-¹)=	100...5000
#Windows=	1
#Auto scanning=	Off
#Autofocus=	Off
#Macrospot=	Off
#AutoExposure=	Off
#Spike filter=	Multiple accum.
#Delay time (s)=	2
#Binning=	1
#Readout mode=	Signal
#DeNoise=	Off
#ICS correction=	On
#Dark correction=	Off
#Inst. Process=	Off
#Detector Gain=	Best Dynamic
#Detector ADC=	50 kHz HS
#Detector temperature (°C)=	-60.09
#Instrument=	LabRAM HR Evol
#Detector=	SIN-EM FIVIS
#Objective=	x100_VIS_LWD
#Grating=	150 (500nm)
#ND Filter=	100%
#Laser=	532nm_Edge
#Hole=	30.0125
#Temperature=	40
#Range=	Visible
#StageXY=	75x50mm Scan+
#StageZ=	Z motor
#X (µm)=	0
#Y (µm)=	0
#Z (µm)=	77
#Full time(mm:ss)=	1:05
#Project=	21_08_11
#Sample=	BU32
#Site=
#Title=	BU32-B-FF2-FI01-L_150 (500nm)_532nm_Edge_100%_x100_VIS_LWD_H30um_30sX2
#Remark=
#Date=	13.08.2021 15:23
#Acquired=	13.08.2021 15:23:42
#Data Range:Extract=	16.12.2021 14:53:05
#Base:Fit=	16.12.2021 15:02:30
#Base:Edit=	16.12.2021 15:02:35
#Base:Edit=	16.12.2021 15:02:36
#Base:Edit=	16.12.2021 15:02:36
#Base:Edit=	16.12.2021 15:02:37
#Peaks:Remove=	16.12.2021 15:02:42
#Peaks:Remove=	16.12.2021 15:02:44
#Peaks:Remove=	16.12.2021 15:02:45
#Peaks:Remove=	16.12.2021 15:02:46
#Base:Edit=	16.12.2021 15:02:47
#Peaks:Remove=	16.12.2021 15:02:48
#Peaks:Remove=	16.12.2021 15:02:50
#Peaks:Remove=	16.12.2021 15:02:53
#Peaks:Remove=	16.12.2021 15:02:54
#Peaks:Remove=	16.12.2021 15:02:55
#Peaks:Remove=	16.12.2021 15:02:58
#Peaks:Remove=	16.12.2021 15:02:59
#Peaks:Remove=	16.12.2021 15:03:01
#Peaks:Remove=	16.12.2021 15:03:04
#Peaks:Remove=	16.12.2021 15:03:05
#Peaks:Remove=	16.12.2021 15:03:06
#Peaks:Remove=	16.12.2021 15:03:07
#Peaks:Remove=	16.12.2021 15:03:08
#Peaks:Remove=	16.12.2021 15:03:12
#Peaks:Remove=	16.12.2021 15:03:13
#Peaks:Remove=	16.12.2021 15:03:15
#Peaks:Remove=	16.12.2021 15:03:16
#Base:Edit=	16.12.2021 15:03:17
#Base:Edit=	16.12.2021 15:03:18
#Base:Edit=	16.12.2021 15:03:18
#Base:Edit=	16.12.2021 15:03:19
#Base:Edit=	16.12.2021 15:03:21
#Base:Edit=	16.12.2021 15:03:23
#Base:Edit=	16.12.2021 15:03:24
#Base:Edit=	16.12.2021 15:03:25
#Base:Edit=	16.12.2021 15:03:26
#Base:Edit=	16.12.2021 15:03:27
#Base:Edit=	16.12.2021 15:03:30
#Base:Edit=	16.12.2021 15:03:32
#Base:Edit=	16.12.2021 15:03:34
#Base:Edit=	16.12.2021 15:03:35
#Base:Sub=	16.12.2021 15:03:40
102.095	636.993
106.719	441.776
111.341	323.578
115.96	216.237
120.577	177.278
125.19	60.1938
129.802	75.3232
134.413	35.2432
139.021	110.469
143.624	99.0859
148.228	86.9788
152.829	261.057
157.428	714.774
162.022	1168.1
166.617	1185.24
171.209	685.039
175.799	116.18
180.384	25.2393
184.969	-39.4272
189.552	-33.8325
194.133	-71.6458
198.71	-50.0859
203.286	1.61157
207.86	30.8647
212.43	33.082
216.999	-2.53491
221.566	-13.5505
226.131	-135.791
230.692	-183.488
235.253	-203.868
239.811	-160.25
244.365	-162.624
248.919	-203.193
253.47	-236.731
258.018	-140.142
262.565	-125.156
267.11	-83.3594
271.65	-90.0145
276.191	-65.9885
280.727	-93.4714
285.263	-49.6194
289.797	-64.9535
294.326	-1.45776
298.856	115.131
303.383	154.754
307.906	189.717
312.428	166.768
316.947	138.311
321.465	103.983
325.981	112.788
330.493	149.665
335.005	199.471
339.512	307.667
344.019	439.248
348.524	580.593
353.025	586.378
357.526	460.319
362.022	349.705
366.518	266.219
371.01	241.057
375.502	261.109
379.99	261.832
384.477	334.059
388.961	356.04
393.444	457.384
397.923	491.169
402.401	605.618
406.878	728.268
411.35	768.961
415.823	803.496
420.291	781.69
424.758	743.462
429.222	726.822
433.684	686.557
438.145	663.973
442.602	623.986
447.059	589.173
451.512	606.393
455.965	607.044
460.413	630.146
464.862	535.32
469.306	501.451
473.75	454.878
478.19	472.994
482.63	504.799
487.065	613.733
491.499	750.808
495.932	934.433
500.361	1110.84
504.79	1276.31
509.215	1487.29
513.638	1569.69
518.06	1672.78
522.479	1700.27
526.897	1609.33
531.311	1532.61
535.723	1444.68
540.135	1387.95
544.543	1393.6
548.948	1437.61
553.354	1414.08
557.755	1292.97
562.157	1226.56
566.554	1091.36
570.949	955.084
575.344	894.039
579.734	918.153
584.123	1044.74
588.512	1289.3
592.896	1534.87
597.279	1577.92
601.659	1377.04
606.039	975.811
610.415	765.753
614.789	584.182
619.163	456.089
623.532	386.085
627.9	356.055
632.267	311.15
636.631	264.687
640.992	279.283
645.351	277.661
649.71	321.47
654.065	369.363
658.418	329.583
662.769	299.788
667.12	269.879
671.466	176.72
675.811	116.588
680.154	72.6129
684.494	81.4928
688.834	60.1757
693.171	50.1492
697.505	48.1461
701.837	35.1885
706.169	20.2926
710.497	42.6379
714.823	11.0724
719.146	15.9855
723.468	7.06915
727.788	10.7254
732.107	16.0812
736.423	-6.17767
740.737	-3.51666
745.048	-1.60065
749.357	10.9387
753.665	4.68616
757.972	-5.28021
762.275	-4.98572
766.576	-29.6105
770.875	-11.8156
775.172	-16.0376
779.467	-17.427
783.76	-28.5346
788.051	-19.2569
792.34	-48.4171
796.629	-24.9122
800.914	-36.4115
805.196	-49.6845
809.477	-42.9576
813.756	-37.2421
818.032	-33.6325
822.307	-48.731
826.58	-54.9021
830.85	-53.3296
835.119	-37.4217
839.385	-40.2848
843.649	-29.9692
847.912	-20.9206
852.172	-6.64929
856.431	5.39969
860.687	71.403
864.941	163.642
869.194	182.917
873.444	128.411
877.692	50.8718
881.938	-3.5383
886.183	-6.58368
890.425	-39.2783
894.665	-19.8359
898.903	-21.4789
903.14	-2.67017
907.374	-8.31912
911.606	20.1321
915.836	31.4585
920.064	70.7072
924.291	74.0805
928.515	116.894
932.737	199.918
936.957	249.41
941.176	313.543
945.392	363.455
949.606	433.411
953.818	508.671
958.029	624.234
962.237	745.984
966.443	933.387
970.645	1167.21
974.848	1368.06
979.048	1430.01
983.246	1325.93
987.443	1059.91
991.637	897.848
995.83	831.917
1000.02	962.643
1004.21	1213.77
1008.39	1630.41
1012.58	2141.88
1016.76	2419.59
1020.94	2498.4
1025.12	2318.42
1029.29	1997.18
1033.47	1692.04
1037.64	1361.46
1041.81	1011.32
1045.98	795.14
1050.15	655.741
1054.31	581.284
1058.47	574.54
1062.64	614.994
1066.79	666.478
1070.95	680.797
1075.1	643.67
1079.26	593.167
1083.41	529.185
1087.56	451.199
1091.7	392.408
1095.85	368.099
1099.99	390.292
1104.13	423.666
1108.27	456.1
1112.41	439.786
1116.55	388.949
1120.68	317.628
1124.81	247.772
1128.94	200.331
1133.07	166.121
1137.19	150.079
1141.32	165.74
1145.44	135.182
1149.56	127.032
1153.67	108.281
1157.79	110.981
1161.9	101.169
1166.02	88.104
1170.13	73.8877
1174.23	75.0006
1178.34	55.4133
1182.45	55.363
1186.55	65.4674
1190.65	57.8896
1194.75	43.0525
1198.84	53.6902
1202.94	52.9606
1207.03	64.3656
1211.12	44.2884
1215.21	55.6156
1219.3	48.7435
1223.38	51.9656
1227.47	57.2051
1231.55	44.4821
1235.63	59.9554
1239.7	73.5493
1243.78	90.0255
1247.85	81.6122
1251.93	123.258
1256	146.998
1260.06	194.784
1264.13	243.669
1268.19	238.636
1272.26	214.595
1276.32	183.449
1280.38	139.135
1284.43	112.75
1288.49	103.343
1292.54	86.8165
1296.59	76.2478
1300.64	77.7155
1304.69	77.0941
1308.73	84.4955
1312.78	68.6654
1316.82	72.8766
1320.86	84.0541
1324.89	55.8574
1328.93	65.8502
1332.96	67.7525
1337	57.5169
1341.03	68.2664
1345.06	82.931
1349.08	83.5672
1353.11	108.08
1357.13	142.441
1361.15	220.269
1365.17	348.366
1369.19	551.254
1373.2	764.6
1377.22	759.693
1381.23	565.826
1385.24	331.22
1389.25	196.319
1393.25	122.584
1397.26	96.2201
1401.26	61.9355
1405.26	63.0847
1409.26	34.6891
1413.25	37.8484
1417.25	20.2935
1421.24	31.3464
1425.23	13.7389
1429.22	15.7696
1433.21	7.93944
1437.2	13.9352
1441.18	9.07263
1445.16	12.081
1449.14	-6.63419
1453.12	9.15956
1457.1	8.15935
1461.07	11.069
1465.05	5.05339
1469.02	5.9218
1472.99	4.85936
1476.95	-5.04933
1480.92	2.6812
1484.88	7.44965
1488.85	-1.48325
1492.81	13.0519
1496.77	1.24683
1500.72	2.15559
1504.68	10.8876
1508.63	17.7286
1512.58	14.8748
1516.53	16.8983
1520.48	19.9237
1524.42	14.2422
1528.37	27.0134
1532.31	32.0614
1536.25	35.186
1540.19	40.2652
1544.12	44.3858
1548.06	22.3576
1551.99	46.8455
1555.92	49.9992
1559.85	57.9642
1563.78	74.6132
1567.7	87.359
1571.63	82.6832
1575.55	81.883
1579.47	112.93
1583.39	104.398
1587.31	117.065
1591.22	130.676
1595.13	146.193
1599.05	149.203
1602.96	169.53
1606.86	163.989
1610.77	197.792
1614.67	205.718
1618.58	218.494
1622.48	234.121
1626.38	243.109
1630.27	247.378
1634.17	243.181
1638.06	252.381
1641.95	247.34
1645.84	226.111
1649.73	240.382
1653.62	217.284
1657.5	199.891
1661.39	191.115
1665.27	189.957
1669.15	165.691
1673.02	168.238
1676.9	137.124
1680.77	132.774
1684.65	116.836
1688.52	92.2794
1692.39	82.0966
1696.25	93.9102
1700.12	80.8212
1703.98	59.1466
1707.84	57.4942
1711.7	45.3619
1715.56	36.1337
1719.42	31.6914
1723.27	31.057
1727.13	8.75426
1730.98	19.4186
1734.83	5.67867
1738.68	9.76466
1742.52	-5.78224
1746.37	4.832
1750.21	-1.21597
1754.05	-7.17487
1757.89	-4.67732
1761.73	-3.76582
1765.56	-2.9545
1769.4	-1.15846
1773.23	-10.4334
1777.06	-23.443
1780.89	-16.8659
1784.71	-13.978
1788.54	-10.1304
1792.36	-16.5672
1796.18	-8.0123
1800	-17.2953
1803.82	-14.4637
1807.64	-10.7019
1811.45	-15.4352
1815.27	-6.05374
1819.08	-17.489
1822.89	-12.9256
1826.7	-16.8822
1830.5	-14.2745
1834.31	-3.22815
1838.11	-8.23027
1841.91	-7.60445
1845.71	4.25406
1849.51	-9.2283
1853.3	-11.4994
1857.1	-6.32324
1860.89	-9.60907
1864.68	-3.59291
1868.47	3.33636
1872.26	-9.20753
1876.04	7.91541
1879.83	2.82925
1883.61	0.5811
1887.39	8.46799
1891.17	1.77884
1894.95	12.5789
1898.72	13.2462
1902.5	23.1739
1906.27	19.3225
1910.04	21.0012
1913.81	15.353
1917.58	15.2341
1921.34	21.6707
1925.1	22.5781
1928.87	22.5759
1932.63	22.5754
1936.38	33.7394
1940.14	39.3272
1943.9	37.4351
1947.65	23.3398
1951.4	41.905
1955.15	33.1897
1958.9	40.3364
1962.65	31.4457
1966.39	41.317
1970.14	43.6091
1973.88	44.8823
1977.62	56.4111
1981.36	36.9914
1985.09	43.7447
1988.83	54.1772
1992.56	55.2216
1996.29	68.2982
2000.02	64.5747
2003.75	61.7861
2007.48	70.0655
2011.21	69.9499
2014.93	65.2296
2018.65	67.9472
2022.37	77.1633
2026.09	69.0618
2029.81	81.1119
2033.52	85.9032
2037.23	75.1983
2040.95	86.4274
2044.66	81.147
2048.37	80.4308
2052.07	91.6447
2055.78	79.96
2059.48	81.1814
2063.18	80.6822
2066.88	90.3326
2070.58	85.2763
2074.28	94.0332
2077.97	93.5737
2081.67	95.8917
2085.36	87.0366
2089.05	84.4063
2092.74	90.9405
2096.43	84.5526
2100.11	92.9898
2103.8	95.7598
2107.48	90.1053
2111.16	92.7717
2114.84	77.75
2118.51	97.0813
2122.19	83.7878
2125.86	78.8036
2129.54	88.6093
2133.21	82.621
2136.88	89.5585
2140.55	85.3493
2144.21	70.9686
2147.87	77.7627
2151.54	73.4937
2155.2	69.2306
2158.86	85.1085
2162.52	76.2708
2166.17	76.6006
2169.83	65.0987
2173.48	60.9679
2177.13	67.7962
2180.78	70.0784
2184.43	63.2408
2188.08	66.4447
2191.72	66.9816
2195.36	54.8411
2199.01	55.4666
2202.65	63.3968
2206.29	69.5355
2209.92	51.0277
2213.56	66.3568
2217.19	48.7224
2220.82	39.2922
2224.45	50.9851
2228.08	52.5592
2231.71	55.0535
2235.33	39.0802
2238.96	39.701
2242.58	53.2885
2246.2	52.9742
2249.82	36.8484
2253.44	43.9686
2257.06	42.7225
2260.67	33.0462
2264.28	37.3553
2267.9	58.574
2271.5	39.4907
2275.11	31.583
2278.72	38.6815
2282.32	27.7417
2285.93	28.102
2289.53	33.1817
2293.13	24.0504
2296.73	20.5831
2300.32	20.8992
2303.92	22.129
2307.52	12.8926
2311.11	23.5285
2314.7	2.8532
2318.29	22.902
2321.88	30.5788
2325.46	16.3629
2329.05	17.275
2332.63	14.3817
2336.21	14.2952
2339.79	25.4772
2343.37	5.58029
2346.95	11.9956
2350.52	4.31979
2354.09	8.81088
2357.67	6.73706
2361.24	-1.86433
2364.81	-0.217209
2368.37	5.1382
2371.94	-8.01105
2375.5	0.131088
2379.07	0.860962
2382.63	1.60507
2386.19	-4.99945
2389.74	-6.04938
2393.3	-7.98425
2396.85	-14.4549
2400.41	-9.86916
2403.96	-14.3643
2407.51	-12.421
2411.06	-15.9137
2414.61	-7.43596
2418.15	-19.1174
2421.7	-16.0756
2425.24	-23.1209
2428.78	-17.2219
2432.32	-24.2131
2435.86	-19.1436
2439.39	-20.5316
2442.93	-16.3192
2446.46	-19.543
2449.99	-21.807
2453.52	-31.5557
2457.05	-22.6268
2460.58	-26.0406
2464.1	-28.5315
2467.63	-40.5761
2471.15	-28.9201
2474.67	-25.0422
2478.19	-22.1445
2481.71	-19.2164
2485.22	-25.7642
2488.74	-31.451
2492.25	-31.4034
2495.77	-33.3071
2499.28	-28.595
2502.78	-38.9045
2506.29	-33.3288
2509.8	-29.666
2513.3	-36.2354
2516.8	-29.7353
2520.31	-26.9301
2523.81	-32.5748
2527.3	-41.7315
2530.8	-44.3568
2534.3	-24.7928
2537.79	-35.6423
2541.28	-34.4463
2544.77	-40.5456
2548.26	-43.8002
2551.75	-34.102
2555.24	-37.2861
2558.72	-39.458
2562.2	-47.1943
2565.68	-39.9964
2569.16	-31.7718
2572.64	-45.8813
2576.12	-35.6544
2579.6	-46.9452
2583.07	-49.7945
2586.54	-47.9191
2590.01	-39.4183
2593.48	-45.2101
2596.95	-51.9978
2600.42	-42.5204
2603.88	-39.6993
2607.35	-35.9917
2610.81	-48.7248
2614.27	-44.2953
2617.73	-49.3926
2621.19	-52.6292
2624.64	-44.3552
2628.1	-36.1185
2631.55	-52.8711
2635	-41.8063
2638.45	-49.0141
2641.9	-45.6937
2645.35	-49.0988
2648.79	-57.2684
2652.24	-43.5174
2655.68	-46.9735
2659.12	-50.4418
2662.56	-45.3797
2666	-47.9082
2669.44	-48.5337
2672.87	-48.2177
2676.31	-43.1764
2679.74	-40.9318
2683.17	-39.5842
2686.6	-30.7074
2690.03	-46.8946
2693.45	-35.034
2696.88	-46.4968
2700.3	-44.8695
2703.73	-35.7856
2707.15	-36.9274
2710.57	-45.373
2713.98	-35.1706
2717.4	-34.2239
2720.81	-43.4845
2724.23	-35.0059
2727.64	-39.5633
2731.05	-34.762
2734.46	-42.1228
2737.87	-31.6875
2741.27	-26.8598
2744.68	-32.3826
2748.08	-34.1769
2751.48	-26.5624
2754.88	-19.8885
2758.28	-32.0544
2761.68	-28.2098
2765.08	-19.6973
2768.47	-12.1496
2771.86	-14.998
2775.25	-18.8014
2778.64	-12.273
2782.03	-20.8397
2785.42	-22.8234
2788.81	-12.5827
2792.19	-13.6386
2795.58	-4.36575
2798.96	-3.55061
2802.34	-5.58571
2805.71	-19.7998
2809.09	-0.278793
2812.47	-6.06845
2815.84	3.09837
2819.22	-3.6368
2822.59	5.53793
2825.96	6.33456
2829.33	-1.24454
2832.69	12.6418
2836.06	21.901
2839.42	10.7021
2842.79	25.6292
2846.15	29.4338
2849.51	21.2022
2852.87	36.3495
2856.22	36.538
2859.58	50.7839
2862.93	49.1705
2866.29	38.1847
2869.64	55.3219
2872.99	56.5018
2876.34	55.7868
2879.68	59.7621
2883.03	65.6125
2886.38	72.3853
2889.72	79.1533
2893.06	88.7431
2896.4	78.4085
2899.74	82.1971
2903.08	75.5241
2906.41	110.433
2909.75	98.9423
2913.08	112.964
2916.41	113.703
2919.74	127.622
2923.07	140.556
2926.4	131.691
2929.72	140.721
2933.05	147.796
2936.37	143.466
2939.69	170.24
2943.01	161.156
2946.33	191.62
2949.65	187.229
2952.97	211.011
2956.28	207.512
2959.6	229.418
2962.91	234.433
2966.22	246.954
2969.53	268.03
2972.84	250.724
2976.14	270.93
2979.45	295.903
2982.75	302.971
2986.05	314.747
2989.36	348.135
2992.65	340.214
2995.95	375.518
2999.25	387.36
3002.54	406.706
3005.84	414.755
3009.13	408.721
3012.42	431.886
3015.71	473.914
3019	488.605
3022.29	521.197
3025.57	501.893
3028.86	562.822
3032.14	578.423
3035.42	596.81
3038.7	641.643
3041.98	658.112
3045.26	685.947
3048.54	708.107
3051.81	726.469
3055.08	771.394
3058.36	788.789
3061.63	836.191
3064.9	866.668
3068.16	893.196
3071.43	928.018
3074.7	941.783
3077.96	1011.76
3081.22	1040.48
3084.48	1106.36
3087.74	1145.64
3091	1137.84
3094.26	1204.3
3097.51	1253.62
3100.77	1337.19
3104.02	1371.93
3107.27	1427.43
3110.52	1497.95
3113.77	1531.72
3117.02	1613.24
3120.26	1665.29
3123.51	1722.09
3126.75	1780.76
3129.99	1818.38
3133.24	1926.55
3136.47	1977.47
3139.71	2032.06
3142.95	2141.89
3146.19	2188.79
3149.42	2271.11
3152.65	2340.13
3155.88	2409.03
3159.11	2506.62
3162.34	2532.53
3165.57	2673.92
3168.8	2742.48
3172.02	2814.61
3175.24	2883.71
3178.46	2992.55
3181.69	3073.62
3184.9	3147.08
3188.12	3178.12
3191.34	3246.18
3194.55	3391.35
3197.77	3450.61
3200.98	3514.47
3204.19	3542.25
3207.4	3642.44
3210.61	3726.57
3213.82	3789.99
3217.02	3846.99
3220.23	3871.62
3223.43	3951.53
3226.63	3980.49
3229.83	4067.54
3233.03	4148.29
3236.23	4111.64
3239.43	4209.23
3242.62	4199.51
3245.82	4301.46
3249.01	4354.87
3252.2	4336.32
3255.39	4369.38
3258.58	4492.11
3261.77	4507.27
3264.95	4536.06
3268.14	4533.57
3271.32	4613.67
3274.5	4636.13
3277.68	4666.15
3280.86	4716.1
3284.04	4648.6
3287.22	4749.17
3290.39	4779.55
3293.57	4808.43
3296.74	4834.2
3299.91	4846.64
3303.08	4853.67
3306.25	4963
3309.42	5044.12
3312.59	5104.29
3315.75	5107.04
3318.91	5215.91
3322.08	5258
3325.24	5263.13
3328.4	5289.1
3331.56	5451.28
3334.71	5465.3
3337.87	5474.13
3341.02	5574.91
3344.18	5596.49
3347.33	5706.26
3350.48	5837.34
3353.63	5823.15
3356.78	5927.51
3359.92	6019.95
3363.07	6059.49
3366.21	6146.34
3369.36	6273.23
3372.5	6353.31
3375.64	6333.26
3378.78	6383.41
3381.92	6550.19
3385.05	6629.84
3388.19	6644.93
3391.32	6781.31
3394.46	6775.54
3397.59	6846.38
3400.72	6880.75
3403.85	7041.12
3406.97	7066.71
3410.1	7076.65
3413.22	7181.65
3416.35	7028.71
3419.47	7087.68
3422.59	7157.51
3425.71	7069.32
3428.83	7100.97
3431.95	7064.77
3435.06	7036.6
3438.18	7023.84
3441.29	7017.81
3444.41	7116.62
3447.52	6949.62
3450.63	6956.12
3453.73	7041.57
3456.84	6997.28
3459.95	6977.69
3463.05	6988.45
3466.16	6980.78
3469.26	7027.13
3472.36	6932.63
3475.46	7006.46
3478.56	6871.48
3481.65	6704.01
3484.75	6743.02
3487.84	6578.56
3490.94	6567.38
3494.03	6462
3497.12	6298.95
3500.21	6175.17
3503.3	6025.35
3506.39	5880.23
3509.47	5776.77
3512.55	5521.81
3515.64	5418.83
3518.72	5347.29
3521.8	5180.42
3524.88	5057.22
3527.96	4912.05
3531.04	4741.5
3534.11	4648.18
3537.19	4516.5
3540.26	4367.42
3543.33	4274.51
3546.4	4155.18
3549.47	4007.23
3552.54	3978.07
3555.61	3858.67
3558.67	3703.09
3561.74	3614.69
3564.8	3517.81
3567.86	3399.45
3570.92	3308.03
3573.98	3179.61
3577.04	3082.74
3580.1	2965.71
3583.15	2927.21
3586.21	2803.11
3589.26	2752.15
3592.31	2640.19
3595.37	2612.66
3598.41	2521.47
3601.46	2452.24
3604.51	2355.38
3607.56	2324.73
3610.6	2212.86
3613.64	2112.42
3616.69	2093.32
3619.73	2047.1
3622.77	1946.45
3625.81	1864.01
3628.84	1758.36
3631.88	1702.72
3634.91	1628.28
3637.95	1554.57
3640.98	1461.55
3644.01	1372.66
3647.04	1293.8
3650.07	1223.91
3653.1	1103.64
3656.13	1007.66
3659.15	953.032
3662.17	825.759
3665.2	765.032
3668.22	679.213
3671.24	604.107
3674.26	537.578
3677.28	467.371
3680.29	412.351
3683.31	332.741
3686.32	275.844
3689.33	264.427
3692.35	190.621
3695.36	177.469
3698.37	132.025
3701.37	89.6157
3704.38	70.0255
3707.39	43.8495
3710.39	28.1206
3713.4	6.72522
3716.4	-17.5171
3719.4	-18.8117
3722.4	-52.4409
3725.4	-59.3766
3728.39	-54.8373
3731.39	-77.8537
3734.38	-81.7792
3737.38	-102.8
3740.37	-95.2011
3743.36	-112.305
3746.35	-90.3459
3749.34	-104.486
3752.33	-118.551
3755.32	-113.541
3758.3	-111.301
3761.28	-114.689
3764.27	-114.236
3767.25	-100.456
3770.23	-96.0719
3773.21	-110.522
3776.19	-107.867
3779.16	-105.147
3782.14	-94.814
3785.11	-109.939
3788.09	-97.6276
3791.06	-89.9952
3794.03	-84.184
3797	-96.2699
3799.97	-72.4596
3802.94	-76.9265
3805.9	-71.9381
3808.87	-65.0549
3811.83	-69.5047
3814.8	-67.3464
3817.76	-57.6394
3820.72	-45.1039
3823.68	-43.0011
3826.63	-39.0264
3829.59	-37.9378
3832.55	-30.2645
3835.5	-25.4704
3838.45	-14.0786
3841.41	-3.69826
3844.36	-9.55972
3847.31	3.52263
3850.26	5.1028
3853.2	-1.03838
3856.15	22.2838
3859.09	25.4664
3862.04	16.0961
3864.98	38.134
3867.92	32.2879
3870.86	51.1769
3873.8	38.2735
3876.74	53.0014
3879.68	47.3761
3882.61	50.1796
3885.55	62.3721
3888.48	70.5028
3891.41	63.026
3894.34	81.2727
3897.27	71.3675
3900.2	76.5764
3903.13	77.6727
3906.06	87.123
3908.98	83.8162
3911.91	81.1562
3914.83	84.8949
3917.75	97.9009
3920.67	100.042
3923.59	95.0734
3926.51	106.993
3929.43	96.453
3932.34	81.6932
3935.26	86.7032
3938.17	99.9488
3941.08	84.0703
3944	85.9171
3946.91	89.2244
3949.81	76.7542
3952.72	83.9079
3955.63	75.2367
3958.54	71.7996
3961.44	64.9506
3964.34	62.3417
3967.25	49.5723
3970.15	48.6797
3973.05	40.4614
3975.95	27.762
3978.84	23.9937
3981.74	-10.2532
3984.63	-4.83269
3987.53	-12.6348
3990.42	-21.1768
3993.32	-48.7762
3996.21	-45.3657
3999.1	-70.6672