File: Data/3-Raman/processed/bu32-AII-incC-fi03-l_150 (500nm)_532nm_edge_100%_x100_vis_lwd_h30um_15sx2_01.txt
#Acq. time (s)=	15
#Accumulations=	2
#Range (cm-¹)=	99...4000
#Windows=	1
#Auto scanning=	Off
#Autofocus=	Off
#Macrospot=	Off
#AutoExposure=	Off
#Spike filter=	Multiple accum.
#Delay time (s)=	2
#Binning=	1
#Readout mode=	Signal
#DeNoise=	Off
#ICS correction=	On
#Dark correction=	Off
#Inst. Process=	Off
#Detector Gain=	Best Dynamic
#Detector ADC=	50 kHz HS
#Detector temperature (°C)=	-60.09
#Instrument=	LabRAM HR Evol
#Detector=	SIN-EM FIVIS
#Objective=	x100_VIS_LWD
#Grating=	150 (500nm)
#ND Filter=	100%
#Laser=	532nm_Edge
#Hole=	30.0125
#Temperature=	0
#Range=	Visible
#StageXY=	75x50mm Scan+
#StageZ=	Z motor
#X (µm)=	0
#Y (µm)=	0
#Z (µm)=	9
#Full time(s)=	34
#Project=	21_11_26
#Sample=	BU32
#Site=
#Title=	BU32-A-incC-FI03-L_150 (500nm)_532nm_Edge_100%_x100_VIS_LWD_H30um_15sX2
#Remark=
#Date=	26.11.2021 17:19
#Acquired=	26.11.2021 17:19:14
#Base:Fit=	16.12.2021 14:33:49
#Base:Edit=	16.12.2021 14:33:52
#Base:Edit=	16.12.2021 14:33:53
#Base:Edit=	16.12.2021 14:33:54
#Base:Edit=	16.12.2021 14:33:56
#Base:Sub=	16.12.2021 14:33:59
102.91	20.1194
107.534	40.881
112.156	17.3939
116.775	10.4115
121.392	20.5291
126.005	73.8948
130.617	73.3871
135.227	101.713
139.835	68.6467
144.439	83.9025
149.042	75.9191
153.643	60.8367
158.242	56.0317
162.839	49.1723
167.431	2.23346
172.023	24.2526
176.613	-13.2628
181.198	-28.3355
185.783	-45.4614
190.366	-26.7408
194.947	3.3714
199.524	-5.27997
204.1	9.69794
208.674	28.7282
213.243	26.2017
217.813	74.3196
222.38	27.5491
226.945	43.598
231.506	46.5718
236.066	47.6238
240.625	52.8622
245.179	23.2061
249.732	51.4932
254.284	88.866
258.831	146.317
263.378	150.891
267.923	161.053
272.464	127.043
277.004	90.2523
281.54	75.0262
286.076	36.6523
290.61	44.3195
295.139	39.7372
299.669	21.4179
304.196	-4.65631
308.718	17.3639
313.241	12.4553
317.759	37.5661
322.278	22.7654
326.794	13.8215
331.305	19.6087
335.817	52.0385
340.324	36.6994
344.832	80.9178
349.334	31.128
353.837	72.7964
358.338	60.3603
362.834	65.21
367.33	33.5814
371.822	72.9258
376.314	65.1851
380.802	74.8711
385.289	87.1653
389.772	118.917
394.255	134.764
398.734	163.157
403.213	199.024
407.688	203.822
412.162	206.481
416.632	216.29
421.102	212.135
425.568	240.321
430.033	293.955
434.495	402.641
438.956	481.16
443.413	523.395
447.87	521.8
452.323	607.088
456.776	677.085
461.224	743.837
465.673	768.289
470.117	641.605
474.561	537.799
479.001	400.811
483.438	361.835
487.876	296.043
492.309	295.842
496.742	293.748
501.172	263.679
505.601	203.336
510.025	171.281
514.448	156.535
518.871	125.575
523.289	100.528
527.707	98.6781
532.121	101.513
536.533	134.512
540.945	218.516
545.353	306.063
549.758	392.583
554.164	602.133
558.565	800.793
562.965	669.664
567.364	439.359
571.759	358.516
576.151	301.996
580.544	330.329
584.933	412.96
589.319	506.061
593.706	520.974
598.088	484.869
602.468	417.467
606.848	436.928
611.224	426.561
615.598	392.142
619.972	365.285
624.341	293.362
628.709	255.603
633.074	194.194
637.44	159.97
641.801	116.815
646.16	126.082
650.517	98.5954
654.874	93.7481
659.227	94.8297
663.578	97.3318
667.927	71.3334
672.275	77.0524
676.62	48.7921
680.962	34.1803
685.302	6.14951
689.643	26.2731
693.979	2.3649
698.313	-4.19699
702.645	6.07901
706.975	-10.8728
711.305	-3.04932
715.631	13.7153
719.955	5.49277
724.276	6.09372
728.596	-1.65155
732.913	0.947357
737.231	-2.90219
741.544	2.77472
745.856	0.122009
750.165	7.39877
754.472	9.68997
758.778	-0.18045
763.081	11.3448
767.384	5.82428
771.683	10.9664
775.98	-7.77521
780.275	8.29932
784.568	12.2667
788.859	3.26236
793.147	-2.29865
797.434	10.6752
801.719	3.98907
806.004	3.08701
810.284	2.32446
814.563	18.121
818.839	10.8906
823.114	26.7647
827.386	17.441
831.657	31.278
835.925	8.77094
840.192	11.5806
844.456	11.0471
848.719	20.3199
852.979	20.5557
857.237	38.434
861.493	43.0679
865.748	41.0248
870	56.4595
874.25	44.318
878.499	41.9863
882.745	30.8234
886.989	44.6762
891.231	33.1868
895.471	43.3361
899.71	30.2508
903.946	75.4967
908.18	52.9464
912.412	80.8537
916.642	95.959
920.87	143.324
925.096	189.281
929.321	262.701
933.543	367.734
937.763	481.026
941.981	713.711
946.197	919.854
950.412	1254.4
954.622	1596.85
958.832	2086.51
963.04	2910.14
967.246	4061.46
971.451	4849.24
975.653	4610.52
979.853	3925.63
984.052	3255
988.248	2629.33
992.442	2058.37
996.633	1663.81
1000.82	1340.96
1005.01	1140.81
1009.2	926.539
1013.38	785.116
1017.57	710.143
1021.75	641.372
1025.92	583.983
1030.1	545.392
1034.27	513.963
1038.45	458.207
1042.62	442.594
1046.78	425.919
1050.95	387.801
1055.12	385.701
1059.28	413.01
1063.44	446.283
1067.6	449.695
1071.75	458.226
1075.91	443.632
1080.06	437.425
1084.21	391.575
1088.36	364.728
1092.51	367.079
1096.65	370.68
1100.8	425.816
1104.94	410.14
1109.08	360.092
1113.21	347.253
1117.35	350.889
1121.48	321.825
1125.61	284.174
1129.74	270.139
1133.87	248.028
1137.99	235.932
1142.12	210.398
1146.24	181.788
1150.36	168.389
1154.48	134.041
1158.59	148.994
1162.71	134.943
1166.82	103.196
1170.93	109.525
1175.04	85.8011
1179.14	33.1989
1183.25	40.3598
1187.35	50.4756
1191.45	52.1427
1195.55	33.2163
1199.65	21.4084
1203.74	43.177
1207.83	36.3582
1211.92	32.6237
1216.01	34.9837
1220.1	29.301
1224.19	26.7067
1228.27	36.2259
1232.35	15.8052
1236.43	27.6781
1240.51	26.7317
1244.58	11.7307
1248.66	32.7987
1252.73	31.0782
1256.8	38.4172
1260.87	22.8289
1264.93	40.2727
1269	34.783
1273.06	32.3373
1277.12	35.9029
1281.18	30.4182
1285.23	16.8191
1289.29	25.274
1293.34	2.48419
1297.39	18.9062
1301.44	10.1151
1305.49	14.359
1309.53	7.49088
1313.58	38.8877
1317.62	11.7054
1321.66	31.8096
1325.7	31.6348
1329.73	32.4179
1333.77	24.1277
1337.8	30.7834
1341.83	40.359
1345.86	46.8655
1349.88	38.3853
1353.91	43.8722
1357.93	43.3935
1361.95	54.7837
1365.97	51.3481
1369.99	78.6143
1374	91.0858
1378.02	64.1505
1382.03	35.3622
1386.04	12.67
1390.05	31.3955
1394.05	9.84918
1398.06	2.20752
1402.06	8.32651
1406.06	1.62723
1410.06	-3.07596
1414.05	1.11987
1418.05	19.1375
1422.04	-1.33429
1426.03	11.7144
1430.02	12.7599
1434.01	17.7797
1438	6.99475
1441.98	4.11273
1445.96	8.09476
1449.94	7.12146
1453.92	13.9877
1457.9	3.07022
1461.87	11.8152
1465.85	14.5418
1469.82	9.37817
1473.78	-3.5882
1477.75	4.03357
1481.72	4.74026
1485.68	7.38165
1489.65	9.01685
1493.61	-0.0639954
1497.56	5.50531
1501.52	13.04
1505.47	16.7225
1509.43	5.90793
1513.38	1.92941
1517.33	5.73807
1521.27	15.3982
1525.22	12.4626
1529.16	16.3406
1533.11	3.77667
1537.05	13.5179
1540.98	12.6063
1544.92	13.6348
1548.86	34.0426
1552.79	10.852
1556.72	25.406
1560.65	24.4126
1564.58	17.5797
1568.5	16.5261
1572.43	25.1151
1576.35	26.9279
1580.27	32.5859
1584.19	25.6926
1588.1	15.8969
1592.02	34.9883
1595.93	31.9216
1599.84	33.6666
1603.75	37.3567
1607.66	42.0529
1611.57	41.959
1615.47	40.932
1619.37	33.248
1623.27	43.7452
1627.17	53.3305
1631.07	45.7313
1634.97	27.7128
1638.86	47.9671
1642.75	30.9724
1646.64	39.9016
1650.53	44.0817
1654.42	39.6493
1658.3	42.8646
1662.18	38.3851
1666.07	31.9164
1669.94	49.4428
1673.82	31.2988
1677.7	37.1695
1681.57	32.2945
1685.44	23.5055
1689.31	22.3778
1693.18	39.3872
1697.05	9.43842
1700.92	28.2344
1704.78	10.6725
1708.64	22.6125
1712.5	27.7932
1716.36	22.5313
1720.21	0.282806
1724.07	8.33539
1727.92	9.73776
1731.77	22.3627
1735.62	14.3301
1739.47	12.8482
1743.32	12.2702
1747.16	9.85098
1751.01	9.48239
1754.85	5.51157
1758.69	14.701
1762.52	9.53958
1766.36	10.6625
1770.19	-1.10611
1774.02	7.70206
1777.85	-1.1463
1781.68	-3.39548
1785.51	6.53177
1789.33	5.30222
1793.16	-9.03134
1796.98	-14.9636
1800.8	6.32916
1804.62	0.206238
1808.43	10.0584
1812.25	-1.78757
1816.06	-8.98602
1819.87	17.6564
1823.68	6.4838
1827.49	5.63654
1831.3	-9.43332
1835.1	11.2477
1838.9	11.1359
1842.71	10.0381
1846.51	4.17776
1850.3	20.8808
1854.1	23.3481
1857.89	9.83734
1861.69	3.75052
1865.48	6.96399
1869.27	14.8348
1873.05	-1.38437
1876.84	25.0568
1880.62	-2.11401
1884.4	-3.2699
1888.19	8.47702
1891.96	0.289886
1895.74	4.99796
1899.52	13.3842
1903.29	-7.55048
1907.06	9.30249
1910.83	12.3825
1914.6	7.27539
1918.37	17.87
1922.13	16.6636
1925.9	12.7023
1929.66	12.4886
1933.42	4.8602
1937.18	3.71396
1940.94	3.48532
1944.69	11.6656
1948.44	7.69043
1952.2	11.9191
1955.95	16.9753
1959.69	18.1238
1963.44	21.05
1967.19	23.9573
1970.93	12.6872
1974.67	20.079
1978.41	19.9003
1982.15	24.3481
1985.89	12.8463
1989.62	6.00784
1993.35	9.38931
1997.09	21.9962
2000.82	24.2906
2004.55	9.92377
2008.27	18.6803
2012	15.3422
2015.72	23.0638
2019.44	18.9645
2023.16	22.3686
2026.88	30.5268
2030.6	21.2943
2034.31	28.6849
2038.03	15.1267
2041.74	18.9314
2045.45	10.8092
2049.16	22.8345
2052.86	1.03503
2056.57	22.2958
2060.27	29.0624
2063.98	16.7513
2067.67	13.6683
2071.37	9.6749
2075.07	28.7443
2078.77	13.6884
2082.46	13.4183
2086.15	15.8919
2089.84	26.3845
2093.53	19.0936
2097.22	22.1616
2100.9	25.1785
2104.59	28.093
2108.27	26.3019
2111.95	37.481
2115.63	15.1764
2119.31	15.1494
2122.98	8.50543
2126.66	23.1465
2130.33	29.3682
2134	22.5881
2137.67	37.0616
2141.34	32.059
2145	20.573
2148.67	26.5803
2152.33	21.5407
2155.99	24.7786
2159.65	30.7611
2163.31	23.053
2166.96	15.4119
2170.62	26.0706
2174.27	23.1682
2177.92	12.1409
2181.57	17.541
2185.22	0.181
2188.87	24.7397
2192.51	20.3034
2196.15	13.2518
2199.8	15.3623
2203.44	4.74023
2207.07	16.9632
2210.71	30.1778
2214.35	5.0166
2217.98	16.4708
2221.61	19.6999
2225.24	30.3115
2228.87	2.24246
2232.5	22.9911
2236.12	29.9677
2239.75	23.0713
2243.37	7.79984
2246.99	14.7521
2250.61	17.0879
2254.23	11.0768
2257.85	15.3345
2261.46	25.2088
2265.07	14.4761
2268.68	5.6106
2272.29	16.5141
2275.9	15.1356
2279.51	29.7018
2283.11	16.7297
2286.72	-0.0486755
2290.32	19.0597
2293.92	14.5083
2297.52	13.7438
2301.11	13.9345
2304.71	24.4973
2308.3	18.8919
2311.9	17.9804
2315.49	17.9712
2319.08	11.2763
2322.66	22.5194
2326.25	23.1548
2329.84	3.9054
2333.42	15.8218
2337	14.4678
2340.58	22.4914
2344.16	7.89987
2347.73	20.5294
2351.31	19.0427
2354.88	15.6754
2358.45	3.90433
2362.03	9.85162
2365.59	20.4158
2369.16	7.76804
2372.73	10.9748
2376.29	22.4664
2379.85	1.62799
2383.41	11.294
2386.97	5.31876
2390.53	-4.26819
2394.09	27.5143
2397.64	7.06277
2401.2	2.31073
2404.75	8.7088
2408.3	6.89334
2411.85	13.4489
2415.39	9.98441
2418.94	-1.69064
2422.48	4.13171
2426.03	13.7217
2429.57	4.02795
2433.11	-0.0973816
2436.64	6.9433
2440.18	16.8304
2443.72	8.15912
2447.25	10.6546
2450.78	7.60504
2454.31	1.77042
2457.84	15.4788
2461.37	-3.98111
2464.89	16.085
2468.42	18.0161
2471.94	18.2966
2475.46	16.2066
2478.98	5.58411
2482.5	-0.267456
2486.01	15.446
2489.53	2.73282
2493.04	1.47293
2496.55	7.56537
2500.06	16.549
2503.57	14.1868
2507.08	23.9223
2510.58	16.7798
2514.09	-7.99274
2517.59	11.0386
2521.09	18.0041
2524.59	9.93289
2528.09	4.01971
2531.59	20.3599
2535.08	5.33081
2538.58	19.9293
2542.07	-0.471741
2545.56	15.2497
2549.05	17.2587
2552.54	8.19232
2556.02	15.8418
2559.51	-8.78415
2562.99	11.0722
2566.47	6.94287
2569.95	6.61273
2573.43	22.2445
2576.91	0.523407
2580.38	1.29199
2583.85	4.91092
2587.33	11.3877
2590.8	15.9313
2594.27	20.3449
2597.74	3.76523
2601.2	1.51895
2604.67	6.8956
2608.13	-0.338531
2611.59	4.65457
2615.06	6.57837
2618.51	-6.76227
2621.97	11.4835
2625.43	15.2614
2628.88	-6.97827
2632.33	7.24097
2635.79	9.85883
2639.24	0.884338
2642.69	-1.42026
2646.13	16.3038
2649.58	12.9538
2653.02	15.2648
2656.47	5.12436
2659.91	5.40704
2663.35	5.65622
2666.79	7.76563
2670.22	-3.33871
2673.66	5.34027
2677.09	6.51834
2680.52	-0.69281
2683.95	9.00488
2687.39	5.70776
2690.81	-7.65335
2694.24	-13.447
2697.66	-0.667694
2701.09	-2.73132
2704.51	-1.06323
2707.93	0.613403
2711.35	0.624878
2714.77	4.41608
2718.18	-1.97552
2721.6	10.3163
2725.01	0.277161
2728.42	10.7869
2731.84	2.63483
2735.24	7.55338
2738.65	8.73361
2742.06	5.2113
2745.46	4.44214
2748.86	-4.82605
2752.27	-3.76138
2755.67	13.2764
2759.07	2.05685
2762.46	14.3789
2765.86	4.01825
2769.25	4.91675
2772.65	-8.36823
2776.04	0.937439
2779.43	-19.01
2782.82	3.38766
2786.2	1.27463
2789.59	18.9034
2792.98	-0.158661
2796.36	6.15527
2799.74	16.2148
2803.12	3.69754
2806.5	3.38663
2809.88	8.68735
2813.25	12.0898
2816.63	13.5976
2820	3.88678
2823.37	17.568
2826.74	-0.443237
2830.11	7.68823
2833.48	7.46295
2836.84	2.6319
2840.21	-10.5341
2843.57	5.23096
2846.93	7.09134
2850.29	1.59509
2853.65	13.8912
2857.01	0.0113525
2860.36	-1.69901
2863.72	14.4087
2867.07	12.7534
2870.42	9.21774
2873.77	0.0163574
2877.12	-9.216
2880.47	-2.47247
2883.81	13.6963
2887.16	2.51685
2890.5	12.0775
2893.84	-1.98511
2897.18	9.38733
2900.52	18.8358
2903.86	7.42828
2907.19	-0.23764
2910.53	24.2412
2913.86	24.0936
2917.19	18.2448
2920.52	0.997864
2923.85	-0.180695
2927.18	13.739
2930.51	23.8211
2933.83	5.52386
2937.15	19.2873
2940.48	16.0555
2943.8	21.3055
2947.11	21.8476
2950.43	18.6328
2953.75	7.88846
2957.06	30.0428
2960.38	26.8706
2963.69	-0.670654
2967	30.9192
2970.31	33.5117
2973.62	24.9038
2976.92	27.5603
2980.23	31.2052
2983.53	16.9805
2986.84	25.2951
2990.14	42.0803
2993.44	13.7997
2996.73	32.4937
3000.03	33.3568
3003.33	40.7964
3006.62	27.5432
3009.91	33.1256
3013.2	38.7282
3016.49	33.9759
3019.78	23.5501
3023.07	44.2349
3026.35	44.1765
3029.64	58.2851
3032.92	53.5023
3036.2	40.1873
3039.48	56.165
3042.76	47.5569
3046.04	60.7169
3049.32	69.1542
3052.59	72.859
3055.86	45.2903
3059.14	80.2758
3062.41	85.754
3065.68	80.8506
3068.94	76.8445
3072.21	83.1944
3075.48	75.9343
3078.74	87.0679
3082	93.3339
3085.26	98.9823
3088.52	105.564
3091.78	111.313
3095.04	105.685
3098.29	94.7861
3101.55	109.807
3104.8	125.706
3108.05	120.877
3111.3	128.355
3114.55	131.891
3117.8	118.325
3121.04	142.855
3124.29	121.671
3127.53	157.632
3130.77	158.334
3134.02	159.993
3137.25	156.87
3140.49	171.833
3143.73	194.416
3146.96	193.167
3150.2	207.206
3153.43	220.304
3156.66	226.703
3159.89	210.22
3163.12	231.879
3166.35	238.275
3169.57	215.99
3172.8	237.562
3176.02	262.924
3179.24	265.333
3182.46	274.409
3185.68	300.66
3188.9	279.152
3192.12	305.3
3195.33	288.547
3198.55	300.372
3201.76	332.172
3204.97	343.986
3208.18	339.635
3211.39	314.38
3214.6	344.359
3217.8	335.369
3221.01	366.334
3224.21	355.465
3227.41	379.859
3230.61	394.757
3233.81	403.051
3237.01	398.929
3240.21	369.259
3243.4	421.502
3246.59	423.332
3249.79	423.261
3252.98	417.541
3256.17	424.239
3259.36	437.612
3262.54	427.97
3265.73	454.514
3268.92	456.122
3272.1	446.191
3275.28	465.828
3278.46	464.437
3281.64	484.848
3284.82	477.42
3288	471.925
3291.17	497.835
3294.35	490.431
3297.52	494.434
3300.69	510.827
3303.86	501.697
3307.03	508.538
3310.2	516.245
3313.36	528.563
3316.53	520.876
3319.69	568.204
3322.85	553.812
3326.02	528.092
3329.18	580.959
3332.33	612.017
3335.49	607.197
3338.65	589.249
3341.8	627.06
3344.95	598.848
3348.11	632.168
3351.26	633.663
3354.41	602.162
3357.56	672.568
3360.7	658.203
3363.85	642.071
3366.99	681.599
3370.13	696.68
3373.28	690.119
3376.42	697.837
3379.56	723.558
3382.69	731.407
3385.83	729.768
3388.97	740.521
3392.1	753.2
3395.23	776.265
3398.36	782.026
3401.49	779.886
3404.62	797.776
3407.75	766.417
3410.88	826.354
3414	795.954
3417.13	796.677
3420.25	824.984
3423.37	843.689
3426.49	828.771
3429.61	849.924
3432.73	822.232
3435.84	851.596
3438.96	851.098
3442.07	837.396
3445.18	831.31
3448.29	825.002
3451.4	828.209
3454.51	826.49
3457.62	834.274
3460.72	812.399
3463.83	819.066
3466.93	802.873
3470.03	795.09
3473.13	790.928
3476.23	805.126
3479.33	790.982
3482.43	784.486
3485.53	783.711
3488.62	748.086
3491.71	760.819
3494.81	769.133
3497.9	729.299
3500.99	729.985
3504.07	718.452
3507.16	698.289
3510.25	700.755
3513.33	688.792
3516.41	660.125
3519.5	672.742
3522.58	639.704
3525.66	621.444
3528.73	629.093
3531.81	607.056
3534.89	590.48
3537.96	570.646
3541.03	556.587
3544.11	540.089
3547.18	515.905
3550.25	524.437
3553.32	532.783
3556.38	498.515
3559.45	493.702
3562.51	462.387
3565.58	445.1
3568.64	449.495
3571.7	424.762
3574.76	430.012
3577.82	401.169
3580.87	391.246
3583.93	386.023
3586.98	380.75
3590.04	346.093
3593.09	353.094
3596.14	355.351
3599.19	333.876
3602.24	323.798
3605.29	311.782
3608.33	294.071
3611.38	280.173
3614.42	279.506
3617.46	273.168
3620.5	264.994
3623.54	257.816
3626.58	245.967
3629.62	211.565
3632.65	209.207
3635.69	188.958
3638.72	188.63
3641.76	184.624
3644.79	165.64
3647.82	147.733
3650.84	161.705
3653.87	142.823
3656.9	138.447
3659.92	109.674
3662.95	108.124
3665.97	96.1446
3668.99	83.9832
3672.01	68.1476
3675.03	65.536
3678.05	68.6212
3681.07	53.7984
3684.08	55.018
3687.1	38.2896
3690.11	39.5434
3693.12	10.5207
3696.13	17.4814
3699.14	14.9213
3702.15	2.9516
3705.16	16.6073
3708.16	-9.60782
3711.17	1.19135
3714.17	2.4809
3717.17	2.79526
3720.17	11.7068
3723.17	-19.3845
3726.17	-7.65662
3729.17	-3.55707
3732.16	-8.03772
3735.16	-3.01276
3738.15	-2.77017
3741.14	-26.34
3744.13	-7.09702
3747.13	-19.2691
3750.11	-16.2366
3753.1	-0.868408
3756.09	-17.7939
3759.07	-3.37354
3762.06	-11.7284
3765.04	-10.6114
3768.02	-9.48329
3771	3.02347
3773.98	-11.8799
3776.96	5.39349
3779.94	-3.7867
3782.91	-13.886
3785.89	-6.97614
3788.86	-10.4392
3791.83	-11.0542
3794.8	3.46957
3797.77	-3.69713
3800.74	-0.469086
3803.71	-0.0435791
3806.68	5.1123
3809.64	6.49295
3812.61	-2.51408
3815.57	5.48894
3818.53	7.81969
3821.49	3.5275
3824.45	14.3761
3827.41	-3.18112
3830.36	3.87721
3833.32	-1.40346
3836.27	16.0967
3839.23	6.06967
3842.18	20.7244
3845.13	-7.42873
3848.08	1.48793
3851.03	8.50046
3853.98	14.5608
3856.92	22.5202
3859.87	8.50006
3862.81	9.72656
3865.75	20.481
3868.7	17.8151
3871.64	21.802
3874.57	20.0001
3877.51	22.949
3880.45	19.116
3883.39	23.8631
3886.32	19.8968
3889.25	9.1411
3892.18	26.2127
3895.12	28.8107
3898.05	6.32875
3900.97	27.0494
3903.9	17.9034
3906.83	33.6764
3909.75	33.081
3912.68	32.4084
3915.6	20.128
3918.52	23.1492
3921.44	24.2301
3924.36	24.2417
3927.28	29.9185
3930.2	10.572
3933.11	38.1202
3936.03	8.16394
3938.94	16.5012
3941.86	26.7177
3944.77	20.5563
3947.68	29.6474
3950.59	24.319
3953.49	13.1774
3956.4	21.1093
3959.31	25.1444
3962.21	4.18628
3965.12	21.4744
3968.02	17.595
3970.92	8.8268
3973.82	0.914505
3976.72	-0.393082
3979.61	-0.864532
3982.51	5.26497
3985.41	-5.06349
3988.3	2.74538
3991.19	-0.151611
3994.09	-10.8965
3996.98	-6.33461
3999.87	-12.4923