File: Data/3-Raman/processed/bu32-AII-incC-fi03-v_1800 (450-850nm)_532nm_edge_100%_x100_vis_lwd_h30um_40sx2_01.txt
#Acq. time (s)=	40
#Accumulations=	2
#Range (cm-¹)=	1200...2365
#Windows=	3
#Auto scanning=	Off
#Autofocus=	Off
#Macrospot=	Off
#AutoExposure=	Off
#Spike filter=	Multiple accum.
#Delay time (s)=	2
#Binning=	1
#Readout mode=	Signal
#DeNoise=	Off
#ICS correction=	On
#Dark correction=	Off
#Inst. Process=	Off
#Detector Gain=	Best Dynamic
#Detector ADC=	50 kHz EM
#Detector EM gain=	400
#Detector temperature (°C)=	-60.09
#Instrument=	LabRAM HR Evol
#Detector=	SIN-EM FIVIS
#Objective=	x100_VIS_LWD
#Grating=	1800 (450-850nm)
#ND Filter=	100%
#Laser=	532nm_Edge
#Hole=	30.0125
#Temperature=	0
#Range=	Visible
#StageXY=	75x50mm Scan+
#StageZ=	Z motor
#X (µm)=	0
#Y (µm)=	0
#Z (µm)=	10.2
#Full time(mm:ss)=	4:24
#Project=	21_11_26
#Sample=	BU32
#Site=
#Title=	BU32-A-incC-FI03-V_1800 (450-850nm)_532nm_Edge_100%_x100_VIS_LWD_H30um_40sX2
#Remark=
#Date=	26.11.2021 18:11
#Acquired=	26.11.2021 18:11:05
#Base:Fit=	16.12.2021 14:46:20
#Base:Sub=	16.12.2021 14:46:22
1202.72	-3.4715
1203.84	-4.19846
1204.95	-0.115692
1206.06	32.5627
1207.17	35.9507
1208.28	44.0153
1209.39	-35.6393
1210.5	12.2423
1211.61	30.6773
1212.72	16.0765
1213.83	-11.079
1214.94	11.1136
1216.05	-18.9156
1217.16	-11.2191
1218.27	11.4512
1219.38	-9.2092
1220.49	-2.20468
1221.6	-14.2667
1222.71	13.4673
1223.81	-9.89041
1224.92	-21.2638
1226.03	14.3413
1227.14	-13.5341
1228.25	-10.6817
1229.35	44.6271
1230.46	-17.6175
1231.57	-5.59595
1232.67	-6.01431
1233.78	1.85886
1234.89	20.499
1235.99	-10.242
1237.1	38.5788
1238.2	-10.8353
1239.31	9.10492
1240.41	-1.0105
1241.52	-3.59543
1242.62	34.462
1243.73	-11.0204
1244.83	-12.6467
1245.94	-32.4859
1247.04	29.4905
1248.14	10.9786
1249.25	-2.44659
1250.35	30.3844
1251.45	-6.21039
1252.56	13.7084
1253.66	22.1247
1254.76	24.8554
1255.87	7.54587
1256.97	20.5377
1258.07	-3.24155
1259.17	4.1796
1260.27	-16.0839
1261.37	9.84833
1262.48	-26.4842
1263.58	12.3348
1264.68	-16.2428
1265.78	11.8574
1266.88	18.4254
1267.98	47.4042
1269.08	47.2867
1270.18	5.66028
1271.28	4.46106
1272.38	-0.465332
1273.47	13.9355
1274.57	7.27997
1275.67	14.9208
1276.77	28.1059
1277.87	32.9293
1278.97	11.5068
1280.07	16.0262
1281.16	6.789
1282.26	6.25723
1283.36	12.5839
1284.45	13.5142
1285.55	12.4051
1286.65	22.0351
1287.75	12.5751
1288.84	-18.9181
1289.94	14.1664
1291.03	-16.0643
1292.13	-22.2428
1293.22	0.0352173
1294.32	10.2428
1295.42	39.0059
1296.51	7.42453
1297.61	11.7659
1298.7	16.9672
1299.79	15.8434
1300.89	26.7115
1301.98	22.724
1303.08	4.00153
1304.17	-21.3407
1305.26	-5.37918
1306.35	4.96478
1307.45	-3.39331
1308.54	-1.09018
1309.63	-0.79718
1310.73	16.3165
1311.82	10.213
1312.91	41.2073
1314	-3.11948
1315.09	11.8587
1316.18	-18.3845
1317.28	30.2826
1318.37	-1.10699
1319.46	-15.7197
1320.55	7.68399
1321.64	-19.9149
1322.73	-4.31046
1323.82	10.4548
1324.91	33.8331
1326	16.8207
1327.09	9.92752
1328.18	10.8371
1329.27	-0.0826416
1330.35	6.34583
1331.44	20.8918
1332.53	-2.75674
1333.62	-3.1644
1334.71	1.76361
1335.79	27.7919
1336.88	24.5217
1337.97	20.3077
1339.06	2.31219
1340.14	44.343
1341.23	28.8322
1342.32	1.60049
1343.4	44.2702
1344.49	20.3337
1345.58	26.5566
1346.66	13.5576
1347.75	17.3615
1348.83	29.825
1349.92	45.2848
1351	32.5952
1352.09	31.3804
1353.17	45.3618
1354.25	28.298
1355.34	21.1764
1356.42	40.0002
1357.51	33.7102
1358.59	-0.658478
1359.67	19.957
1360.76	20.7402
1361.84	44.5965
1362.92	24.9218
1364	19.032
1365.09	39.8984
1366.17	14.8406
1367.25	25.9106
1368.33	38.4755
1369.41	38.7803
1370.5	8.85825
1371.58	-20.2446
1372.66	34.0085
1373.74	3.99014
1374.82	34.9448
1375.9	32.0232
1376.98	36.1172
1378.06	42.3144
1379.14	50.4701
1380.22	78.2383
1381.3	52.713
1382.38	88.3589
1383.46	77.5554
1384.54	77.4601
1385.61	80.1733
1386.69	37.6449
1387.77	46.8683
1388.85	35.9992
1389.93	10.4306
1391	16.1264
1392.08	-10.6686
1393.16	37.3231
1394.23	7.66748
1395.31	-1.36932
1396.39	8.17126
1397.46	-8.21844
1398.54	28.716
1399.62	-1.59579
1400.69	-20.7015
1401.77	-8.02682
1402.84	1.00354
1403.92	12.8906
1404.99	23.0515
1406.07	29.1213
1407.14	17.921
1408.22	6.97214
1409.29	0.121765
1410.37	13.7586
1411.44	-33.6081
1412.51	6.4863
1413.59	-9.61722
1414.66	1.3978
1415.73	-16.6856
1416.81	26.7823
1417.88	2.53625
1418.95	2.82034
1420.02	-15.5673
1421.1	15.1248
1422.17	-10.3058
1423.24	-3.08084
1424.31	-4.22018
1425.38	-16.3006
1426.45	25.0519
1427.52	19.7058
1428.59	5.17285
1429.67	2.43143
1430.74	9.15146
1431.81	18.1115
1432.87	0.646393
1433.95	-20.2396
1435.01	25.1916
1436.08	20.2769
1437.15	18.3073
1438.22	8.16528
1439.29	56.6704
1440.36	22.3663
1441.43	31.9257
1442.49	31.063
1443.56	22.0207
1444.63	19.0681
1445.7	6.27643
1446.77	17.6339
1447.83	-3.84442
1448.9	-6.58746
1449.97	26.3749
1451.03	31.5016
1452.1	12.0891
1453.17	-2.065
1454.23	-2.81583
1455.3	13.7592
1456.36	12.0164
1457.43	1.80951
1458.49	21.4133
1459.56	-15.1891
1460.62	18.7681
1461.69	6.49997
1462.75	9.49283
1463.82	-19.2974
1464.88	11.0172
1465.94	-11.4248
1467.01	20.2833
1468.07	20.4174
1469.13	14.4436
1470.2	24.5712
1471.26	-6.00986
1472.32	-0.929749
1473.39	-25.23
1474.45	-2.82327
1475.51	10.6777
1476.57	5.64609
1477.63	-3.5072
1478.69	27.0443
1479.76	21.8849
1480.82	-3.74286
1481.88	3.41171
1482.94	25.2167
1484	14.325
1485.06	10.626
1486.12	-30.8366
1487.18	1.8251
1488.24	-8.31357
1489.3	6.74219
1490.36	12.8955
1491.42	-0.275543
1492.48	-0.122498
1493.53	16.1958
1494.59	4.24454
1495.65	10.3335
1496.71	8.1084
1497.77	22.3147
1498.82	9.36264
1499.88	-6.50626
1500.94	20.9709
1502	-12.3094
1503.05	-19.3299
1504.11	-20.3414
1505.17	-5.99973
1506.22	6.93314
1507.28	-4.93854
1508.34	-22.8896
1509.39	3.49826
1510.45	1.72757
1511.5	14.6428
1512.56	-2.05362
1513.61	-11.343
1514.67	-17.9502
1515.72	-3.04205
1516.78	16.8345
1517.83	-8.11783
1518.88	-16.8203
1519.94	41.6523
1520.99	-13.4014
1522.05	25.9762
1523.1	-0.104248
1524.15	17.6587
1525.2	-15.3911
1526.26	-4.03967
1527.31	7.36548
1528.36	-9.64655
1529.41	5.40836
1530.47	-22.5742
1531.52	19.9234
1532.57	16.0237
1533.62	15.6216
1534.67	21.8731
1535.72	1.7962
1536.77	0.421417
1537.82	-15.8364
1538.87	42.0795
1539.92	7.84772
1540.97	-2.36243
1542.02	9.58441
1543.07	37.3865
1544.12	10.0625
1545.17	14.4751
1546.22	29.0508
1547.27	3.25452
1548.32	33.2537
1549.37	4.14734
1550.42	35.4782
1551.46	12.7809
1552.51	20.9844
1553.56	41.9097
1554.61	1.6481
1555.65	-8.55804
1556.7	2.58377
1557.75	-8.22006
1558.79	12.6492
1559.84	22.3487
1560.89	22.2954
1561.93	20.525
1562.98	27.8967
1564.02	2.97189
1565.07	16.4443
1566.11	24.119
1567.16	10.9979
1568.2	15.4542
1569.25	9.70023
1570.29	21.6451
1571.34	19.784
1572.38	42.7206
1573.43	23.639
1574.47	37.7185
1575.51	30.2814
1576.56	31.4853
1577.6	26.1503
1578.64	50.7471
1579.69	4.00653
1580.73	10.2492
1581.77	38.1263
1582.81	32.0555
1583.85	21.1619
1584.9	18.3375
1585.94	23.4398
1586.98	11.3298
1588.02	29.231
1589.06	16.5789
1590.1	40.7673
1591.14	-0.798096
1592.18	44.0699
1593.22	35.8543
1594.26	17.5109
1595.3	18.7184
1596.34	2.82855
1597.38	9.96503
1598.42	22.0451
1599.46	26.7891
1600.5	-1.12094
1601.54	35.2625
1602.58	23.105
1603.62	14.9791
1604.66	14.0409
1605.69	22.1275
1606.73	22.4503
1607.77	28.4571
1608.81	45.1938
1609.84	21.8273
1610.88	22.1823
1611.92	42.8208
1612.95	37.7185
1613.99	15.3842
1615.03	23.983
1616.06	10.0809
1617.1	22.2286
1618.13	9.76093
1619.17	25.3042
1620.2	31.2823
1621.24	31.539
1622.27	28.2068
1623.31	33.253
1624.34	36.1095
1625.38	25.4028
1626.41	21.5718
1627.45	29.8557
1628.48	41.3803
1629.51	28.8114
1630.55	24.8936
1631.53	6.07974
1632.57	67.488
1633.62	45.8964
1634.66	33.3147
1635.71	31.4341
1636.75	60.936
1637.8	65.7306
1638.84	20.4407
1639.89	26.473
1640.93	29.6229
1641.98	27.7798
1643.02	32.7409
1644.06	15.0826
1645.11	42.5821
1646.15	24.1404
1647.19	11.3185
1648.24	29.0175
1649.28	27.553
1650.32	76.8832
1651.37	30.1436
1652.41	48.0894
1653.45	35.3069
1654.49	11.8736
1655.53	7.2449
1656.57	49.2361
1657.62	30.6196
1658.66	25.6649
1659.7	15.6919
1660.74	23.6448
1661.78	34.9233
1662.82	25.6496
1663.86	26.8152
1664.9	24.6936
1665.94	43.0219
1666.98	9.13965
1668.02	39.644
1669.06	16.1696
1670.1	19.5542
1671.14	16.0292
1672.18	18.0621
1673.21	29.1082
1674.25	31.3148
1675.29	9.91672
1676.33	14.0974
1677.37	8.32669
1678.4	28.0519
1679.44	17.0355
1680.48	10.1004
1681.52	12.0704
1682.55	32.9368
1683.59	7.35464
1684.63	19.2385
1685.66	28.1779
1686.7	22.4243
1687.73	7.83652
1688.77	32.4814
1689.81	26.3987
1690.84	18.5322
1691.88	32.6265
1692.91	20.8678
1693.95	26.5162
1694.98	35.2047
1696.01	36.3836
1697.05	20.8656
1698.08	32.4913
1699.12	34.3063
1700.15	2.93222
1701.18	6.89804
1702.22	23.5468
1703.25	23.4271
1704.28	-5.03424
1705.32	18.7545
1706.35	27.6379
1707.38	6.77271
1708.41	22.1595
1709.44	35.5047
1710.48	20.8598
1711.51	5.46136
1712.54	27.1627
1713.57	-3.63516
1714.6	9.77985
1715.63	15.7708
1716.66	36.408
1717.69	22.3562
1718.72	1.37775
1719.75	21.811
1720.78	8.29318
1721.81	7.11813
1722.84	15.6166
1723.87	39.7339
1724.9	0.904358
1725.93	11.1764
1726.96	26.6687
1727.99	0.524994
1729.02	-16.5258
1730.05	-1.30386
1731.07	-18.7683
1732.1	4.0119
1733.13	1.08633
1734.16	10.3661
1735.18	3.26685
1736.21	10.7358
1737.24	23.1958
1738.26	3.86319
1739.29	14.2336
1740.32	4.17584
1741.34	-3.79636
1742.37	8.52435
1743.4	-10.6058
1744.42	9.43265
1745.45	10.4406
1746.47	32.4175
1747.5	-4.1821
1748.52	-4.27319
1749.55	-20.2879
1750.57	-0.758392
1751.6	-8.11423
1752.62	8.86374
1753.64	5.80695
1754.67	-11.5189
1755.69	11.2917
1756.71	-4.15524
1757.74	0.344177
1758.76	1.54749
1759.78	8.37631
1760.81	-20.1385
1761.83	-9.78
1762.85	-5.87292
1763.87	15.2192
1764.89	0.415558
1765.92	11.1849
1766.94	-5.84885
1767.96	17.9612
1768.98	-3.00327
1770	15.4492
1771.02	-7.0184
1772.04	-0.88446
1773.06	-0.542633
1774.08	17.8335
1775.1	-6.66962
1776.12	20.4992
1777.14	-9.87671
1778.16	18.5995
1779.18	4.12473
1780.2	4.18768
1781.22	32.0459
1782.24	-0.0866699
1783.26	-5.43185
1784.28	8.22992
1785.29	11.4729
1786.31	-28.5638
1787.33	30.8929
1788.35	-29.4219
1789.37	1.84329
1790.38	7.08905
1791.4	12.9158
1792.42	-12.1573
1793.43	9.15228
1794.45	13.1869
1795.47	-1.698
1796.48	5.55487
1797.5	-17.0962
1798.51	23.5828
1799.53	1.55457
1800.55	4.30856
1801.56	12.9619
1802.58	11.2363
1803.59	3.93353
1804.61	-6.36163
1805.62	10.427
1806.64	1.20956
1807.65	2.38922
1808.66	15.0576
1809.68	-13.6926
1810.69	-0.0330811
1811.7	14.4934
1812.72	1.16782
1813.73	16.9095
1814.74	-18.358
1815.76	7.14621
1816.77	13.1406
1817.78	6.26508
1818.79	-8.05737
1819.8	29.8558
1820.82	12.7419
1821.83	14.9749
1822.84	-0.24408
1823.85	-5.9433
1824.86	2.89142
1825.87	8.9433
1826.88	9.07281
1827.89	14.1317
1828.9	24.8811
1829.91	4.52631
1830.92	12.2306
1831.93	35.7231
1832.94	23.4646
1833.95	12.041
1834.96	6.08035
1835.97	15.295
1836.98	2.21353
1837.99	28.2708
1839	9.9516
1840	7.65094
1841.01	34.1096
1842.02	8.38531
1843.03	32.2791
1844.04	22.727
1845.04	-5.14273
1846.05	-15.5604
1847.06	9.01602
1848.07	11.6978
1849.07	19.561
1850.08	34.7544
1851.09	20.9088
1852.09	-15.7417
1853.1	-5.11197
1854.1	8.27161
1855.11	-1.61398
1856.11	-7.61856
1857.12	-6.62903
1858.12	-11.4644
1859.13	14.1651
1860.13	6.33835
1861.14	30.487
1862.14	-10.3694
1863.15	3.82864
1864.15	21.7452
1865.15	1.48932
1866.16	20.1828
1867.16	24.384
1868.16	5.91501
1869.17	4.99792
1870.17	-4.4996
1871.17	-8.28702
1872.17	16.3565
1873.18	11.4536
1874.18	-4.75891
1875.18	-5.96008
1876.18	0.223297
1877.18	-5.76129
1878.18	2.30444
1879.19	2.01865
1880.19	-3.31021
1881.19	-7.07358
1882.19	6.66113
1883.19	12.5686
1884.19	-4.72592
1885.19	14.3737
1886.19	3.57898
1887.19	3.59271
1888.19	-9.89584
1889.19	-9.35974
1890.19	-10.4381
1891.19	4.90384
1892.18	-8.30106
1893.18	-5.57523
1894.18	-9.81381
1895.18	-6.16089
1896.18	12.8007
1897.18	-1.95044
1898.17	9.48349
1899.17	-15.1207
1900.17	-19.9999
1901.16	1.64755
1902.16	-7.42999
1903.16	5.91769
1904.16	5.82852
1905.15	4.87411
1906.15	1.95868
1907.14	4.57004
1908.14	9.35583
1909.14	-11.1152
1910.13	10.8729
1911.13	3.82532
1912.12	13.3898
1913.12	30.3237
1914.11	-9.97174
1915.11	-4.88162
1916.1	-10.3742
1917.1	-11.4492
1918.09	20.4725
1919.08	10.3774
1920.08	-1.36102
1921.07	9.13309
1922.06	4.73328
1923.06	13.2255
1924.05	-2.96277
1925.04	-6.87985
1926.04	-9.44748
1927.03	-4.29816
1928.02	-13.5213
1929.01	9.39194
1930	14.4595
1931	-0.308929
1931.99	6.32584
1932.98	22.2755
1933.97	-7.05191
1934.96	-4.12769
1935.95	10.9642
1936.94	4.92285
1937.93	-17.2635
1938.92	-2.97858
1939.91	17.246
1940.9	-0.589478
1941.89	29.3313
1942.88	5.64981
1943.87	23.588
1944.86	21.0101
1945.85	25.2126
1946.84	14.9629
1947.83	17.7922
1948.82	1.50763
1949.8	-11.6452
1950.79	18.5465
1951.78	13.3735
1952.77	20.4077
1953.76	7.97736
1954.74	21.6072
1955.73	4.17975
1956.72	-28.7962
1957.7	7.06235
1958.69	19.7494
1959.68	11.9514
1960.66	10.8163
1961.65	3.85535
1962.63	9.63071
1963.62	35.6147
1964.61	-0.745422
1965.59	2.10077
1966.58	2.29678
1967.56	9.19882
1968.55	33.303
1969.53	7.15665
1970.52	-3.79431
1971.5	25.743
1972.48	15.1906
1973.47	-17.4956
1974.45	-8.11877
1975.44	9.16611
1976.42	7.43604
1977.4	17.0561
1978.39	12.0776
1979.37	-10.0814
1980.35	1.45227
1981.33	18.5086
1982.31	28.9098
1983.3	5.70645
1984.28	29.373
1985.26	-12.8734
1986.24	7.08707
1987.22	13.903
1988.21	20.3231
1989.19	12.71
1990.17	3.17206
1991.15	13.3042
1992.13	13.6565
1993.11	8.13907
1994.09	19.2299
1995.07	-1.56204
1996.05	0.950378
1997.03	6.54739
1998.01	10.2272
1998.99	7.17596
1999.97	-3.81796
2000.95	13.7119
2001.92	14.7202
2002.9	7.8446
2003.88	4.24652
2004.86	-7.32944
2005.84	-0.997101
2006.81	-5.28311
2007.79	13.5787
2008.77	-1.01904
2009.75	-11.6928
2010.73	-3.88306
2011.7	1.47968
2012.68	19.1871
2013.67	21.5845
2014.66	-10.9532
2015.64	-1.71472
2016.63	2.18893
2017.62	13.6963
2018.61	-13.0744
2019.6	12.651
2020.58	0.311707
2021.57	-9.98587
2022.56	18.9425
2023.55	-2.92426
2024.54	21.0763
2025.52	0.975616
2026.51	5.34479
2027.5	-5.87848
2028.48	23.6089
2029.47	10.1664
2030.45	-1.19794
2031.44	14.8192
2032.43	-21.5211
2033.41	14.4138
2034.4	-28.5406
2035.38	-8.50528
2036.37	9.06607
2037.35	-6.00284
2038.34	1.37613
2039.32	-5.38434
2040.31	7.3873
2041.29	16.3574
2042.27	2.20752
2043.26	19.7621
2044.24	8.07224
2045.23	5.99631
2046.21	-5.40863
2047.19	-0.128632
2048.17	3.15549
2049.16	-4.20978
2050.14	-8.48404
2051.12	-3.54752
2052.11	0.925415
2053.09	-13.8969
2054.07	-7.91296
2055.05	1.5603
2056.03	11.6819
2057.01	-11.7959
2058	0.447113
2058.98	6.34268
2059.96	7.45892
2060.94	28.8602
2061.92	20.5989
2062.9	-2.71689
2063.88	6.88159
2064.86	-8.90463
2065.84	2.69681
2066.82	8.56284
2067.8	-4.41931
2068.78	-5.18381
2069.76	2.25275
2070.73	-4.34512
2071.71	15.6403
2072.69	-10.1934
2073.67	3.88284
2074.65	4.92746
2075.63	15.7597
2076.6	-3.6434
2077.58	32.997
2078.56	27.2617
2079.54	2.95117
2080.51	-7.06726
2081.49	17.507
2082.47	12.8013
2083.45	1.53049
2084.42	20.4256
2085.4	12.9027
2086.37	27.2237
2087.35	12.4018
2088.32	12.5289
2089.3	-8.20981
2090.28	-9.84561
2091.25	26.2978
2092.23	3.85333
2093.2	15.7215
2094.18	-5.76184
2095.15	-3.76627
2096.13	0.813873
2097.1	-9.70267
2098.07	19.5434
2099.05	9.98889
2100.02	3.32095
2101	15.7588
2101.97	4.62183
2102.94	16.9712
2103.92	0.677399
2104.89	16.9206
2105.86	4.85492
2106.83	12.6545
2107.8	0.350098
2108.78	-8.51401
2109.75	15.2653
2110.72	-16.9206
2111.69	17.2848
2112.66	14.359
2113.63	10.8014
2114.61	-1.46103
2115.58	0.474701
2116.55	5.10355
2117.52	-0.690643
2118.49	8.70551
2119.46	23.5582
2120.43	-26.9026
2121.4	15.8642
2122.37	10.5418
2123.34	-3.44342
2124.31	-0.578522
2125.28	-9.52393
2126.25	17.5
2127.21	11.5371
2128.18	-6.53119
2129.15	-10.3249
2130.12	15.1555
2131.09	-0.965729
2132.06	-3.00818
2133.02	23.2544
2133.99	-11.628
2134.96	6.36862
2135.93	-3.09561
2136.89	0.40097
2137.86	-4.1925
2138.83	-8.03958
2139.79	-10.7389
2140.76	23.8813
2141.73	21.9512
2142.69	12.3954
2143.66	8.01254
2144.62	-24.6084
2145.59	1.78342
2146.55	18.6905
2147.52	11.0741
2148.48	8.13315
2149.45	14.5368
2150.42	-16.7747
2151.38	-1.80673
2152.34	1.22855
2153.31	-12.9003
2154.27	-4.5882
2155.24	17.435
2156.2	-8.22937
2157.16	-3.63235
2158.13	19.92
2159.09	-15.4904
2160.05	9.59003
2161.01	7.44754
2161.98	0.842163
2162.94	-0.0582275
2163.9	-1.09033
2164.86	-5.01144
2165.83	13.6732
2166.79	20.1737
2167.75	-7.04224
2168.71	20.4272
2169.67	13.1751
2170.63	-9.60651
2171.59	-9.646
2172.56	1.92566
2173.51	14.86
2174.48	6.64813
2175.44	-6.30109
2176.4	10.4008
2177.36	-24.9557
2178.32	-7.23553
2179.28	9.32529
2180.23	-6.38599
2181.19	3.81924
2182.15	0.0427246
2183.11	6.45648
2184.07	-23.4807
2185.03	4.26233
2185.99	-6.68118
2186.95	19.6178
2187.9	-18.9378
2188.86	16.2509
2189.82	14.9867
2190.78	1.90073
2191.73	-14.6638
2192.69	-14.504
2193.65	2.44531
2194.6	0.211456
2195.56	9.51746
2196.52	4.5629
2197.47	12.6307
2198.43	21.9483
2199.38	16.8369
2200.34	36.0018
2201.3	13.403
2202.25	8.54437
2203.21	8.26367
2204.16	5.84137
2205.12	17.3574
2206.07	36.9836
2207.03	11.8892
2207.98	-1.81107
2208.93	-2.42581
2209.89	34.0405
2210.84	9.02924
2211.8	20.4791
2212.75	3.96252
2213.7	12.2404
2214.66	17.1125
2215.61	6.17603
2216.56	3.42813
2217.51	-0.315735
2218.47	16.5432
2219.42	9.26559
2220.37	5.74017
2221.32	2.89166
2222.27	14.7363
2223.23	-2.9563
2224.18	-19.4635
2225.13	0.550507
2226.08	1.84491
2227.03	-2.5444
2227.98	-12.6544
2228.93	24.7868
2229.88	8.88766
2230.83	2.64517
2231.78	-13.937
2232.73	-6.1409
2233.68	17.6436
2234.63	26.269
2235.58	17.5445
2236.53	16.5661
2237.48	-3.04184
2238.43	-6.32635
2239.38	15.7863
2240.33	-6.99377
2241.27	18.6345
2242.22	14.0194
2243.17	30.1953
2244.12	14.0059
2245.07	4.72699
2246.01	8.92819
2246.96	-2.1828
2247.91	9.32672
2248.85	5.47168
2249.8	1.68948
2250.75	-5.95709
2251.69	-10.0061
2252.64	1.41727
2253.59	1.9071
2254.53	8.84927
2255.48	3.1871
2256.42	10.8518
2257.37	-7.89697
2258.32	10.2945
2259.26	-13.3461
2260.2	16.2482
2261.15	-2.6225
2262.1	-10.9862
2263.04	16.7777
2263.98	-11.4229
2264.93	6.20786
2265.87	-13.642
2266.81	-16.692
2267.76	-3.6153
2268.7	14.2682
2269.65	-6.51489
2270.59	7.25543
2271.53	17.0415
2272.47	4.78131
2273.42	-15.2774
2274.36	17.3044
2275.3	-2.74695
2276.24	5.92215
2277.18	-0.498657
2278.13	10.4827
2279.07	6.84573
2280.01	-6.88095
2280.95	-7.24863
2281.89	-4.56454
2282.83	9.00558
2283.77	6.49753
2284.71	2.22769
2285.65	-13.9406
2286.59	13.7196
2287.54	2.52475
2288.47	-11.8001
2289.41	14.8565
2290.35	-16.4028
2291.29	26.8535
2292.23	8.90466
2293.17	22.6502
2294.11	5.45041
2295.05	15.8245
2295.99	7.88538
2296.93	8.52518
2297.86	-1.87082
2298.8	-5.41776
2299.74	-3.22977
2300.68	19.9133
2301.61	18.1489
2302.55	-6.01907
2303.49	4.52786
2304.43	19.0781
2305.36	-8.73798
2306.3	16.4907
2307.24	7.83359
2308.17	-7.76205
2309.11	23.0918
2310.04	12.7659
2310.98	-14.2234
2311.92	-5.09357
2312.85	9.05325
2313.79	0.455048
2314.72	7.66098
2315.66	-6.63086
2316.59	-3.19873
2317.52	-3.33383
2318.46	-27.4194
2319.39	-0.586182
2320.33	14.7492
2321.26	6.17227
2322.2	2.62683
2323.13	-19.3673
2324.06	3.94452
2325	-6.76749
2325.93	-1.31537
2326.86	5.18518
2327.79	30.0056
2328.73	-3.77069
2329.66	10.5084
2330.59	-17.399
2331.52	2.83664
2332.46	0.108154
2333.39	17.2943
2334.32	1.80054
2335.25	21.8389
2336.18	-11.7288
2337.11	-4.02673
2338.04	-6.88562
2338.97	1.8042
2339.91	2.88693
2340.84	-3.90845
2341.77	-3.23328
2342.7	3.34189
2343.63	3.42017
2344.56	-2.18356
2345.49	16.129
2346.41	-9.85031
2347.34	-6.89227
2348.27	19.1389
2349.2	12.6665
2350.13	-5.83994
2351.06	3.24136
2351.99	13.4491
2352.91	23.6365
2353.84	7.15393
2354.77	0.750061
2355.7	-10.3995
2356.63	-4.64496
2357.55	-0.968323
2358.48	2.94287
2359.41	4.04416
2360.33	-0.574005
2361.26	-4.34726
2362.19	10.8275
2363.11	22.2106
2364.04	-6.9462
2364.97	-9.57788