File: Data/3-Raman/raw/20-C_brt2_FI01.txt
#Acq. time (s)=	20
#Accumulations=	3
#Range (cm-¹)=	100...4000
#Windows=	1
#Auto scanning=	Off
#Autofocus=	Off
#Macrospot=	Off
#AutoExposure=	Off
#Spike filter=	Multiple accum.
#Delay time (s)=	0
#Binning=	1
#Readout mode=	Signal
#DeNoise=	Lite
#ICS correction=	Off
#Dark correction=	Off
#Inst. Process=	Off
#Detector temperature (°C)=	-60.09
#Instrument=	LabRAM HR Evol
#Detector=	SIN-EM FIVIS
#Objective=	x100_VIS
#Grating=	150 (500nm)
#ND Filter=	100%
#Laser=	633nm_Edge
#Hole=	30.0125
#Temperature=	0
#Range=	Visible
#StageXY=	75x50mm Scan+
#StageZ=	Z motor
#X (µm)=	9005.3
#Y (µm)=	4615.5
#Z (µm)=	1865.5
#Full time(mm:ss)=	1:03
#Project=	Buranga
#Sample=	BU18FA20_C
#Site=	C_Bertoss2
#Title=	20-C_brt2_FI01
#Remark=
#Date=	30.07.2019 15:11
#Acquired=	30.07.2019 15:11:23
100.38	322.585
106.898	291.078
113.411	272.522
119.918	255.45
126.419	244.166
132.916	235.743
139.407	224.784
145.892	214.869
152.372	211.562
158.847	208.842
165.316	208.512
171.781	209.285
178.239	202.863
184.693	193.533
191.139	188.226
197.582	187.127
204.02	183.938
210.452	177.779
216.877	174.034
223.299	176.534
229.715	188.813
236.126	212.837
242.53	226.935
248.931	207.026
255.326	191.775
261.714	186.42
268.099	189.149
274.477	198.854
280.851	213.605
287.218	227.353
293.582	222.611
299.939	200.682
306.293	181.199
312.639	175.701
318.982	189.064
325.318	214.99
331.651	245.679
337.977	233.458
344.297	204.076
350.614	187.669
356.925	185.784
363.23	194.682
369.53	203.502
375.827	196.748
382.116	183.657
388.401	174.483
394.681	169.17
400.956	172.057
407.226	175.946
413.49	177.207
419.749	182.198
426.003	191.14
432.252	208.685
438.496	224.139
444.735	229.449
450.969	223.667
457.197	220.278
463.421	215.443
469.64	200.592
475.853	192.003
482.062	188.324
488.265	188.264
494.464	188.794
500.657	187.704
506.844	187.333
513.028	187.722
519.206	189.301
525.38	189.534
531.548	189.412
537.71	190.331
543.869	191.692
550.022	193.506
556.169	182.669
562.313	182.509
568.452	184.139
574.584	183.354
580.713	181.817
586.837	182.568
592.954	190.136
599.068	208.067
605.176	225.62
611.28	224.615
617.378	216.226
623.473	215.319
629.561	213.406
635.644	209.858
641.724	204.945
647.797	205.802
653.867	212.544
659.931	217.876
665.99	217.301
672.044	206.898
678.095	191.557
684.139	181.315
690.179	176.968
696.213	172.223
702.245	169.18
708.27	168.614
714.29	167.954
720.306	168.276
726.316	169.267
732.322	171.89
738.323	173.8
744.32	172.015
750.311	167.101
756.298	162.761
762.28	162.867
768.258	162.842
774.23	161.986
780.198	160.339
786.161	159.195
792.119	166.405
798.073	167.423
804.021	164.594
809.965	163.461
815.904	163.674
821.839	164.294
827.769	164.329
833.693	165.922
839.614	166.975
845.53	164.671
851.44	161.674
857.346	161.372
863.248	163.141
869.144	163.962
875.037	165.654
880.924	165.579
886.807	164.144
892.685	162.019
898.559	160.211
904.427	163.423
910.292	162.379
916.151	158.855
922.006	158.78
927.856	161.08
933.701	162.596
939.543	164.369
945.379	173.552
951.21	187.384
957.037	197.092
962.861	200.284
968.678	200.982
974.491	214.471
980.3	239.986
986.104	271.984
991.904	306.815
997.699	307.995
1003.49	277.234
1009.28	249.365
1015.06	249.41
1020.83	265.441
1026.61	277.528
1032.37	266.526
1038.14	233.831
1043.9	208.509
1049.65	188.395
1055.4	176.329
1061.15	176.335
1066.88	171.478
1072.62	164.812
1078.35	168.99
1084.08	178.606
1089.8	187.755
1095.52	194.616
1101.23	196.604
1106.94	191.711
1112.65	177.097
1118.35	162.963
1124.05	156.008
1129.74	154.178
1135.42	153.519
1141.11	155.607
1146.78	160.452
1152.46	171.199
1158.13	181.422
1163.79	168.124
1169.45	153.045
1175.11	148.324
1180.76	145.241
1186.41	147.094
1192.05	141.308
1197.69	134.925
1203.32	137.271
1208.95	137.591
1214.58	137.691
1220.2	134.53
1225.82	133.093
1231.43	135.062
1237.04	132.749
1242.64	133.335
1248.24	135.716
1253.83	138.287
1259.42	139.758
1265.01	139.728
1270.59	139.79
1276.17	138.294
1281.74	159.081
1287.31	167.451
1292.88	141.115
1298.44	122.537
1303.99	131.735
1309.55	131.164
1315.09	130.193
1320.64	130.307
1326.18	131.762
1331.71	127.042
1337.24	129.827
1342.77	122.17
1348.29	119.182
1353.81	125.552
1359.32	127.19
1364.83	128.943
1370.33	129.619
1375.84	136.14
1381.33	153.687
1386.82	233.075
1392.31	140.36
1397.8	126.837
1403.28	128.594
1408.75	128.991
1414.22	125.951
1419.69	122.295
1425.15	120.864
1430.61	117.912
1436.07	120.49
1441.52	119.927
1446.96	115.635
1452.41	110.682
1457.84	112.697
1463.28	118.391
1468.71	120.218
1474.13	121.292
1479.55	121.727
1484.97	121.366
1490.39	119.797
1495.79	115.362
1501.2	116.167
1506.6	118.32
1512	118.796
1517.39	116.098
1522.78	115.356
1528.16	116.095
1533.54	117.652
1538.92	115.536
1544.29	112.456
1549.66	114.39
1555.02	116.379
1560.38	119.934
1565.74	118.932
1571.09	118.006
1576.44	117.489
1581.78	117.186
1587.12	117.637
1592.46	116.21
1597.79	111.939
1603.12	107.076
1608.44	113.389
1613.76	117.319
1619.08	118.61
1624.39	118.831
1629.7	118.579
1635	118.843
1640.3	118.764
1645.59	118.173
1650.88	118.529
1656.17	121.067
1661.46	117.557
1666.74	111.594
1672.01	110.438
1677.28	113.955
1682.55	115.739
1687.82	114.461
1693.07	109.08
1698.33	110.231
1703.58	109.574
1708.83	110.718
1714.07	111.642
1719.31	108.608
1724.55	105.063
1729.78	107.778
1735.01	108.975
1740.23	107.34
1745.46	108.006
1750.67	110.041
1755.89	113.004
1761.09	109.269
1766.3	105.844
1771.5	105.4
1776.7	104.512
1781.89	103.021
1787.08	105.321
1792.27	107.333
1797.45	110.236
1802.62	107.332
1807.8	104.352
1812.97	102.821
1818.14	107.021
1823.3	109.539
1828.46	108.552
1833.61	108.327
1838.76	106.495
1843.91	104.774
1849.05	103.477
1854.19	102.064
1859.33	101.099
1864.46	100.971
1869.59	98.4943
1874.71	99.3617
1879.83	97.9085
1884.95	102.327
1890.06	105.287
1895.17	104.722
1900.27	102.888
1905.38	101.624
1910.47	101.048
1915.57	100.939
1920.66	101.426
1925.74	102.571
1930.83	100.068
1935.91	99.5644
1940.98	100.672
1946.05	99.8749
1951.12	101.566
1956.18	102.814
1961.25	102.305
1966.3	102.655
1971.35	102.797
1976.4	102.701
1981.45	101.845
1986.49	102.868
1991.53	103.211
1996.56	102.635
2001.59	100.874
2006.62	103.998
2011.64	104.523
2016.66	103.582
2021.68	103.508
2026.69	103.395
2031.7	102.499
2036.7	100.424
2041.7	102.269
2046.7	100.114
2051.7	96.4868
2056.69	95.1523
2061.67	97.2222
2066.65	100.131
2071.63	102.432
2076.61	102.637
2081.58	99.9217
2086.55	98.9365
2091.51	100.944
2096.47	101.902
2101.43	101.793
2106.39	101.779
2111.34	101.336
2116.28	98.1148
2121.23	98.7626
2126.17	100.04
2131.1	99.908
2136.03	98.5378
2140.96	99.7298
2145.89	98.5322
2150.81	98.0625
2155.73	98.6107
2160.64	95.962
2165.55	95.5673
2170.46	96.2594
2175.36	96.3822
2180.26	97.1111
2185.16	98.6716
2190.05	100.45
2194.94	101.505
2199.83	100.588
2204.71	97.5628
2209.59	95.6998
2214.46	96.6849
2219.33	102.476
2224.2	101.611
2229.07	95.273
2233.93	91.3498
2238.79	90.7566
2243.64	92.5663
2248.49	93.1167
2253.34	94.2029
2258.18	93.5691
2263.02	95.4765
2267.86	94.529
2272.69	94.3018
2277.52	93.996
2282.35	93.4847
2287.17	94.8608
2291.99	95.1688
2296.8	94.3473
2301.62	93.3538
2306.43	94.2634
2311.23	95.0173
2316.03	97.0132
2320.83	100.132
2325.63	97.8959
2330.42	97.1219
2335.21	95.1672
2339.99	94.348
2344.77	95.3428
2349.55	96.5732
2354.32	91.646
2359.1	90.8916
2363.86	91.2747
2368.63	92.488
2373.39	91.9217
2378.15	93.1766
2382.9	93.7311
2387.65	92.6274
2392.4	90.3592
2397.14	87.5333
2401.88	88.6629
2406.62	92.7207
2411.35	92.559
2416.08	91.0892
2420.81	92.0838
2425.53	95.0199
2430.25	94.4835
2434.97	91.0392
2439.69	88.0041
2444.4	87.5431
2449.1	90.3459
2453.81	91.8648
2458.51	93.1731
2463.2	92.1135
2467.9	91.8074
2472.59	91.4835
2477.27	89.9543
2481.96	87.9929
2486.64	88.903
2491.31	89.9865
2495.99	90.3187
2500.66	89.8124
2505.32	90.9609
2509.99	87.8698
2514.65	85.329
2519.31	85.6864
2523.96	88.4505
2528.61	88.6109
2533.26	86.3434
2537.9	85.5217
2542.54	88.7559
2547.18	89.7222
2551.81	89.3886
2556.44	88.7916
2561.07	87.5274
2565.69	88.6691
2570.32	89.125
2574.93	86.073
2579.55	83.918
2584.16	83.7947
2588.77	81.6071
2593.37	82.444
2597.97	85.8974
2602.57	87.6469
2607.17	86.613
2611.76	85.8818
2616.35	85.7695
2620.93	89.2168
2625.51	89.4303
2630.09	88.0136
2634.67	85.7071
2639.24	84.2731
2643.81	83.3514
2648.38	83.7569
2652.94	82.8799
2657.5	81.6962
2662.06	84.5873
2666.61	84.8626
2671.16	84.4685
2675.71	81.9869
2680.25	82.0021
2684.79	83.7489
2689.33	85.1406
2693.86	85.8792
2698.39	84.8473
2702.92	81.9329
2707.45	81.1827
2711.97	78.4944
2716.49	74.9793
2721	79.7878
2725.51	84.6238
2730.02	84.5971
2734.53	82.8409
2739.03	79.3389
2743.53	78.8395
2748.03	80.1888
2752.52	78.8971
2757.01	80.0486
2761.5	87.165
2765.98	82.1087
2770.46	81.0583
2774.94	82.036
2779.42	81.0026
2783.89	80.5222
2788.36	81.856
2792.82	84.9142
2797.28	82.9943
2801.74	78.4855
2806.2	78.2833
2810.65	80.8351
2815.1	80.1215
2819.55	77.7076
2823.99	77.5526
2828.43	79.0216
2832.87	80.5998
2837.3	82.1336
2841.74	83.83
2846.17	81.6645
2850.59	78.171
2855.01	75.3936
2859.43	75.6606
2863.85	76.9804
2868.26	78.0842
2872.67	78.6199
2877.08	81.2216
2881.48	81.1921
2885.89	80.5706
2890.28	79.5234
2894.68	78.3973
2899.07	78.9735
2903.46	79.3309
2907.85	79.6025
2912.23	78.9848
2916.61	77.9989
2920.98	77.394
2925.36	78.2431
2929.73	77.9265
2934.1	77.4635
2938.46	76.4503
2942.82	75.9742
2947.18	77.7393
2951.54	78.5687
2955.89	77.1111
2960.24	76.6447
2964.59	79.3637
2968.93	82.1184
2973.27	81.3604
2977.61	77.3244
2981.95	75.7332
2986.28	76.1652
2990.61	76.0441
2994.94	76.2794
2999.26	78.186
3003.58	78.5897
3007.9	78.5386
3012.21	80.2861
3016.52	78.4883
3020.83	74.7821
3025.14	74.3849
3029.44	77.3605
3033.74	80.1782
3038.04	79.8519
3042.33	78.6521
3046.62	77.5985
3050.91	77.2042
3055.2	76.8304
3059.48	77.7083
3063.76	79.368
3068.03	80.7095
3072.31	81.7031
3076.58	81.3092
3080.85	81.5905
3085.11	81.2379
3089.37	80.5063
3093.63	81.2237
3097.89	82.3628
3102.14	82.0841
3106.39	81.4328
3110.64	81.0246
3114.89	80.2888
3119.13	80.1129
3123.37	80.4378
3127.6	80.9825
3131.84	82.51
3136.07	82.3445
3140.29	83.6617
3144.52	85.4267
3148.74	86.6333
3152.96	83.4612
3157.18	82.4523
3161.39	85.3144
3165.6	88.3035
3169.81	91.1193
3174.01	89.5614
3178.22	89.3423
3182.42	86.3044
3186.61	88.1886
3190.8	89.9459
3195	89.6349
3199.18	88.3215
3203.37	89.9832
3207.55	92.5317
3211.73	92.235
3215.91	92.3752
3220.08	89.6773
3224.25	88.8776
3228.42	90.3615
3232.59	89.8276
3236.75	89.9735
3240.91	87.2333
3245.07	86.9099
3249.22	87.8786
3253.37	88.0868
3257.52	88.163
3261.67	87.9946
3265.81	86.0236
3269.95	84.9209
3274.09	81.1635
3278.22	83.6642
3282.36	85.6587
3286.49	87.5835
3290.61	87.3537
3294.74	85.7785
3298.86	85.0893
3302.98	86.946
3307.09	83.0883
3311.21	82.408
3315.32	86.4896
3319.42	87.367
3323.53	86.8301
3327.63	87.9574
3331.73	87.5076
3335.83	86.9713
3339.92	87.7035
3344.01	85.7161
3348.1	84.2468
3352.19	83.4736
3356.27	83.9359
3360.35	86.0629
3364.43	89.6806
3368.5	93.516
3372.58	96.388
3376.65	95.0082
3380.71	92.0501
3384.78	89.4424
3388.84	90.1741
3392.9	92.3601
3396.95	93.8679
3401.01	85.5506
3405.06	80.1157
3409.1	84.2101
3413.15	86.1712
3417.19	90.1311
3421.23	87.872
3425.27	93.7601
3429.31	93.5066
3433.34	84.4149
3437.37	83.9674
3441.39	86.0458
3445.42	89.5761
3449.44	87.7005
3453.46	85.7689
3457.47	84.1635
3461.49	85.133
3465.5	88.4752
3469.51	89.8097
3473.51	88.4055
3477.52	86.5534
3481.52	84.673
3485.51	82.791
3489.51	80.799
3493.5	83.861
3497.49	76.5534
3501.48	79.5384
3505.46	82.1743
3509.45	83.0106
3513.43	81.1866
3517.4	79.3969
3521.38	78.6813
3525.35	79.0972
3529.32	74.5614
3533.28	74.254
3537.25	76.7519
3541.21	75.4466
3545.17	75.616
3549.12	74.0579
3553.08	72.3656
3557.03	70.967
3560.98	70.5719
3564.92	71.3062
3568.87	71.7645
3572.81	73.308
3576.74	72.248
3580.68	71.5968
3584.61	73.9242
3588.54	74.656
3592.47	73.8539
3596.4	74.0924
3600.32	69.3273
3604.24	65.2692
3608.16	64.709
3612.07	65.1759
3615.98	65.8
3619.89	62.5646
3623.8	59.6546
3627.71	58.9433
3631.61	59.0484
3635.51	58.6662
3639.41	60.2107
3643.3	61.8393
3647.19	61.6855
3651.08	61.1492
3654.97	60.8783
3658.85	59.8807
3662.74	59.8568
3666.62	59.2822
3670.49	59.1013
3674.37	58.8852
3678.24	57.7936
3682.11	55.0221
3685.98	55.4066
3689.84	56.5482
3693.7	56.3566
3697.56	56.3909
3701.42	55.4319
3705.28	55.0832
3709.13	57.0346
3712.98	55.7827
3716.82	53.657
3720.67	52.0596
3724.51	51.4291
3728.35	51.6498
3732.19	52.6387
3736.02	54.3514
3739.86	56.2156
3743.69	56.1107
3747.51	54.9307
3751.34	52.6263
3755.16	52.9659
3758.98	52.9981
3762.8	52.4703
3766.61	52.2219
3770.43	53.0726
3774.24	53.6785
3778.05	53.8124
3781.85	53.568
3785.65	53.9465
3789.45	51.0139
3793.25	47.5717
3797.05	50.4791
3800.84	52.7849
3804.63	52.8467
3808.42	50.4143
3812.21	50.819
3815.99	52.2894
3819.77	53.5063
3823.55	54.2021
3827.33	54.0507
3831.1	53.2044
3834.87	51.1755
3838.64	48.8426
3842.41	49.4435
3846.17	50.442
3849.93	51.4278
3853.69	51.9024
3857.45	51.1871
3861.21	51.5557
3864.96	51.0086
3868.71	51.139
3872.46	49.694
3876.2	48.9048
3879.94	48.7288
3883.68	49.51
3887.42	50.0904
3891.16	50.4989
3894.89	49.7406
3898.62	49.4221
3902.35	49.7565
3906.08	48.7363
3909.8	49.9027
3913.52	49.8574
3917.24	48.3001
3920.96	48.2247
3924.67	49.6173
3928.38	48.9976
3932.09	49.9375
3935.8	50.1347
3939.51	49.8904
3943.21	49.4014
3946.91	49.351
3950.61	48.5214
3954.3	47.0175
3958	47.9386
3961.69	48.4919
3965.38	48.3015
3969.06	47.077
3972.75	46.7009
3976.43	49.3485
3980.11	48.5304
3983.78	45.4354
3987.46	43.7869
3991.13	48.3774
3994.8	45.0285
3998.47	47.69