File: Data/3-Raman/raw/20-C_brt1_FI01_151.txt
#Acq. time (s)=	20
#Accumulations=	3
#Range (cm-¹)=	100...4000
#Windows=	1
#Auto scanning=	Off
#Autofocus=	Off
#Macrospot=	Off
#AutoExposure=	Off
#Spike filter=	Multiple accum.
#Delay time (s)=	0
#Binning=	1
#Readout mode=	Signal
#DeNoise=	Lite
#ICS correction=	Off
#Dark correction=	Off
#Inst. Process=	Off
#Detector temperature (°C)=	-60.09
#Instrument=	LabRAM HR Evol
#Detector=	SIN-EM FIVIS
#Objective=	x50_VIS_LWD
#Grating=	150 (500nm)
#ND Filter=	100%
#Laser=	633nm_Edge
#Hole=	30.0125
#Temperature=	0
#Range=	Visible
#StageXY=	75x50mm Scan+
#StageZ=	Z motor
#X (µm)=	7344.4
#Y (µm)=	4274
#Z (µm)=	-22.8
#Full time(mm:ss)=	1:02
#Project=	Buranga
#Sample=	BU18FA20_C
#Site=	C_Bertoss1
#Title=	20-C_brt1_FI01
#Remark=
#Date=	30.07.2019 14:26
#Acquired=	30.07.2019 14:26:11
100.38	1006.84
106.898	784.148
113.411	628.248
119.918	515.16
126.419	435.175
132.916	382.566
139.407	339.396
145.892	308.759
152.372	285.936
158.847	258.784
165.316	241.904
171.781	237.566
178.239	225.593
184.693	214.617
191.139	209.182
197.582	207.274
204.02	205.475
210.452	202.012
216.877	199.552
223.299	200.074
229.715	203.961
236.126	217.545
242.53	242.579
248.931	234.971
255.326	222.334
261.714	218.237
268.099	223.393
274.477	231.56
280.851	241.384
287.218	259.898
293.582	265.936
299.939	240.607
306.293	220.683
312.639	213.878
318.982	221.418
325.318	245.77
331.651	276.035
337.977	267.459
344.297	246.619
350.614	232.921
356.925	231.349
363.23	236.447
369.53	241.337
375.827	241.838
382.116	232.621
388.401	223.183
394.681	224.565
400.956	226.731
407.226	228.356
413.49	225.752
419.749	222.702
426.003	231.78
432.252	245.618
438.496	262.266
444.735	273.294
450.969	273.593
457.197	269.393
463.421	262.422
469.64	253.244
475.853	242.303
482.062	233.474
488.265	230.625
494.464	228.941
500.657	228.841
506.844	231.698
513.028	234.298
519.206	233.475
525.38	231.732
531.548	231.717
537.71	236.641
543.869	238.542
550.022	235.272
556.169	227.585
562.313	230.702
568.452	236.595
574.584	235.554
580.713	234.321
586.837	236.934
592.954	247.095
599.068	266.698
605.176	284.729
611.28	282.806
617.378	271.549
623.473	263.984
629.561	261.695
635.644	261.508
641.724	262.137
647.797	263.449
653.867	267.873
659.931	274.947
665.99	279.205
672.044	268.993
678.095	255.255
684.139	248.229
690.179	240.309
696.213	232.447
702.245	228.441
708.27	227.062
714.29	227.428
720.306	226.653
726.316	224.949
732.322	222.739
738.323	223.308
744.32	225.285
750.311	225.838
756.298	227.775
762.28	230.107
768.258	229.216
774.23	225.153
780.198	220.699
786.161	221.06
792.119	222.1
798.073	223.129
804.021	226.486
809.965	228.54
815.904	225.303
821.839	220.617
827.769	220.058
833.693	226.039
839.614	231.296
845.53	230.474
851.44	226.619
857.346	223.171
863.248	220.962
869.144	220.284
875.037	216.384
880.924	217.926
886.807	221.458
892.685	222.693
898.559	221.185
904.427	218.964
910.292	217.937
916.151	218.349
922.006	221.518
927.856	223.2
933.701	221.991
939.543	225.919
945.379	228.885
951.21	236.425
957.037	243.896
962.861	250.11
968.678	256.261
974.491	269.462
980.3	287.71
986.104	318.575
991.904	352.54
997.699	357.155
1003.49	331.115
1009.28	304.495
1015.06	284.96
1020.83	297.764
1026.61	321
1032.37	315.003
1038.14	283.335
1043.9	253.566
1049.65	240.801
1055.4	234.304
1061.15	227.558
1066.88	223.988
1072.62	223.345
1078.35	226.631
1084.08	232.549
1089.8	237.386
1095.52	241.935
1101.23	244.855
1106.94	244.839
1112.65	230.311
1118.35	220.458
1124.05	211.057
1129.74	206.949
1135.42	208.525
1141.11	212.527
1146.78	215.261
1152.46	220.547
1158.13	225.721
1163.79	220.909
1169.45	207.407
1175.11	196.758
1180.76	196.426
1186.41	197.523
1192.05	196.749
1197.69	194.332
1203.32	195.477
1208.95	191.183
1214.58	185.982
1220.2	189.212
1225.82	183.64
1231.43	181.586
1237.04	187.24
1242.64	193.121
1248.24	197.75
1253.83	202.083
1259.42	210.871
1265.01	228.915
1270.59	203.108
1276.17	217.967
1281.74	549
1287.31	453
1292.88	224.457
1298.44	192.877
1303.99	199.623
1309.55	197.366
1315.09	197.462
1320.64	194.773
1326.18	190.672
1331.71	189.709
1337.24	189.495
1342.77	186.347
1348.29	181.224
1353.81	178.547
1359.32	181.288
1364.83	190.373
1370.33	205.584
1375.84	208.737
1381.33	227.411
1386.82	1135
1392.31	360
1397.8	214
1403.28	198
1408.75	250.457
1414.22	206.184
1419.69	180.814
1425.15	176.958
1430.61	178.585
1436.07	173.613
1441.52	171.561
1446.96	168.238
1452.41	165.964
1457.84	164.592
1463.28	162.233
1468.71	160.623
1474.13	160.46
1479.55	160.375
1484.97	162.653
1490.39	162.655
1495.79	158.835
1501.2	154.894
1506.6	153.39
1512	153.536
1517.39	150.241
1522.78	149.559
1528.16	150.349
1533.54	152.094
1538.92	153.497
1544.29	160.806
1549.66	160.62
1555.02	154.054
1560.38	149.106
1565.74	148.966
1571.09	149.499
1576.44	151.505
1581.78	154.825
1587.12	152.019
1592.46	152.912
1597.79	153.312
1603.12	152.825
1608.44	152.088
1613.76	152.045
1619.08	152.598
1624.39	153.499
1629.7	152.86
1635	149.598
1640.3	145.818
1645.59	143.043
1650.88	141.884
1656.17	143.855
1661.46	145.863
1666.74	145.252
1672.01	142.476
1677.28	140.038
1682.55	139.704
1687.82	143.31
1693.07	143.531
1698.33	143.285
1703.58	144.322
1708.83	144.619
1714.07	142.847
1719.31	141.007
1724.55	136.027
1729.78	137.303
1735.01	139.522
1740.23	142.467
1745.46	142.144
1750.67	140.499
1755.89	137.963
1761.09	134.805
1766.3	132.724
1771.5	132.894
1776.7	138.563
1781.89	143.435
1787.08	139.472
1792.27	135.371
1797.45	133.501
1802.62	136.628
1807.8	140.71
1812.97	138.476
1818.14	135.929
1823.3	133.402
1828.46	131.552
1833.61	132.629
1838.76	135.816
1843.91	138.621
1849.05	135.616
1854.19	132.674
1859.33	129.665
1864.46	130.758
1869.59	129.966
1874.71	130.22
1879.83	131.577
1884.95	135.457
1890.06	136.123
1895.17	136.418
1900.27	135.814
1905.38	132.441
1910.47	130.321
1915.57	131.677
1920.66	131.742
1925.74	129.666
1930.83	126.673
1935.91	124.435
1940.98	126.967
1946.05	130.78
1951.12	131.762
1956.18	131.193
1961.25	130.732
1966.3	131.063
1971.35	133.032
1976.4	135.519
1981.45	136.241
1986.49	135.456
1991.53	132.705
1996.56	135.496
2001.59	135.499
2006.62	132.238
2011.64	126.93
2016.66	122.44
2021.68	123.168
2026.69	126.646
2031.7	128.143
2036.7	127.558
2041.7	127.43
2046.7	127.937
2051.7	126.284
2056.69	129.324
2061.67	128.107
2066.65	126.978
2071.63	127.198
2076.61	127.99
2081.58	127.831
2086.55	127.845
2091.51	126.477
2096.47	123.305
2101.43	121.369
2106.39	118.653
2111.34	124.554
2116.28	126.464
2121.23	124.332
2126.17	122.598
2131.1	122.218
2136.03	121.314
2140.96	118.523
2145.89	116.129
2150.81	118.117
2155.73	122.714
2160.64	123.341
2165.55	121.786
2170.46	119.206
2175.36	116.907
2180.26	118.004
2185.16	123.099
2190.05	123.503
2194.94	122.498
2199.83	120.939
2204.71	120.194
2209.59	120.05
2214.46	120.323
2219.33	119.07
2224.2	123.947
2229.07	123.754
2233.93	120.807
2238.79	118.539
2243.64	117.667
2248.49	117.19
2253.34	117.669
2258.18	119.605
2263.02	120.624
2267.86	119.619
2272.69	117.637
2277.52	115.455
2282.35	116.258
2287.17	117.798
2291.99	118.399
2296.8	118.005
2301.62	116.971
2306.43	116.305
2311.23	116.287
2316.03	117.363
2320.83	120.348
2325.63	125.14
2330.42	126.428
2335.21	120.8
2339.99	116.437
2344.77	112.599
2349.55	114.732
2354.32	116.563
2359.1	114.048
2363.86	111.712
2368.63	114.141
2373.39	115.203
2378.15	114.051
2382.9	110.859
2387.65	109.989
2392.4	111.15
2397.14	111.766
2401.88	110.905
2406.62	109.815
2411.35	110.777
2416.08	110.917
2420.81	107.985
2425.53	105.794
2430.25	106.681
2434.97	110.309
2439.69	112.37
2444.4	110.468
2449.1	110.512
2453.81	109.914
2458.51	110.76
2463.2	110.257
2467.9	109.119
2472.59	109.374
2477.27	109.766
2481.96	109.407
2486.64	107.574
2491.31	106.981
2495.99	105.571
2500.66	105.315
2505.32	106.26
2509.99	106.435
2514.65	106.552
2519.31	105.989
2523.96	105.644
2528.61	104.072
2533.26	105.537
2537.9	109.457
2542.54	110.023
2547.18	108.082
2551.81	107.04
2556.44	107.118
2561.07	105.452
2565.69	103.101
2570.32	101.917
2574.93	101.403
2579.55	106.147
2584.16	106.974
2588.77	103.117
2593.37	104.776
2597.97	105.605
2602.57	105.599
2607.17	103.931
2611.76	102.087
2616.35	103.328
2620.93	106.003
2625.51	108.103
2630.09	104.387
2634.67	101.841
2639.24	102.776
2643.81	103.939
2648.38	102.862
2652.94	103.905
2657.5	106.868
2662.06	105.77
2666.61	106.521
2671.16	106.004
2675.71	99.5801
2680.25	103.909
2684.79	102.986
2689.33	101.703
2693.86	101.711
2698.39	101.483
2702.92	100.526
2707.45	100.213
2711.97	101.525
2716.49	98.7734
2721	96.3103
2725.51	96.7922
2730.02	97.9566
2734.53	97.7252
2739.03	96.3754
2743.53	96.7855
2748.03	98.6579
2752.52	99.0936
2757.01	97.8966
2761.5	99.96
2765.98	97.7707
2770.46	96.6876
2774.94	98.5503
2779.42	95.4512
2783.89	93.457
2788.36	96.5788
2792.82	98.5447
2797.28	98.2661
2801.74	95.71
2806.2	91.4636
2810.65	93.2798
2815.1	96.031
2819.55	98.2195
2823.99	98.0915
2828.43	95.9497
2832.87	93.85
2837.3	94.4678
2841.74	95.4621
2846.17	96.1763
2850.59	95.9747
2855.01	94.3763
2859.43	93.9904
2863.85	92.7869
2868.26	91.1555
2872.67	96.1668
2877.08	96.3432
2881.48	94.321
2885.89	91.7574
2890.28	89.224
2894.68	88.9699
2899.07	91.8227
2903.46	93.5034
2907.85	94.8325
2912.23	93.267
2916.61	93.3969
2920.98	93.7841
2925.36	93.0066
2929.73	93.3591
2934.1	94.8661
2938.46	93.9951
2942.82	93.9685
2947.18	93.722
2951.54	90.9333
2955.89	86.6933
2960.24	89.2294
2964.59	91.8033
2968.93	94.2756
2973.27	94.993
2977.61	95.3442
2981.95	93.5056
2986.28	91.3332
2990.61	89.2012
2994.94	89.5182
2999.26	89.7693
3003.58	90.7794
3007.9	87.7459
3012.21	89.3988
3016.52	87.5041
3020.83	87.4239
3025.14	88.1323
3029.44	89.9168
3033.74	91.6863
3038.04	89.3574
3042.33	86.9514
3046.62	86.5198
3050.91	89.6243
3055.2	87.8629
3059.48	88.6991
3063.76	89.6634
3068.03	89.7843
3072.31	88.0612
3076.58	88.7869
3080.85	89.766
3085.11	88.8897
3089.37	88.4146
3093.63	89.3244
3097.89	90.0439
3102.14	89.9717
3106.39	88.5986
3110.64	88.7643
3114.89	89.0135
3119.13	89.0615
3123.37	88.6251
3127.6	89.3036
3131.84	89.4436
3136.07	86.6547
3140.29	85.2897
3144.52	83.4269
3148.74	86.4348
3152.96	91.5763
3157.18	91.683
3161.39	88.2836
3165.6	86.3297
3169.81	85.7854
3174.01	85.5937
3178.22	85.7166
3182.42	87.4783
3186.61	87.0864
3190.8	84.9035
3195	84.8575
3199.18	88.0308
3203.37	87.0406
3207.55	86.3606
3211.73	86.4229
3215.91	85.8045
3220.08	86.2241
3224.25	83.9984
3228.42	84.1358
3232.59	90.3821
3236.75	91.3302
3240.91	87.6654
3245.07	82.8403
3249.22	86.1607
3253.37	87.2565
3257.52	85.3641
3261.67	83.6808
3265.81	81.7013
3269.95	80.9806
3274.09	80.5049
3278.22	80.8786
3282.36	80.3935
3286.49	83.4266
3290.61	81.167
3294.74	80.7834
3298.86	82.2398
3302.98	82.4975
3307.09	81.1716
3311.21	78.6132
3315.32	78.6535
3319.42	79.7488
3323.53	81.4776
3327.63	82.1063
3331.73	79.3547
3335.83	78.9138
3339.92	80.0018
3344.01	80.367
3348.1	82.5274
3352.19	82.3112
3356.27	80.9769
3360.35	80.8406
3364.43	80.5586
3368.5	79.6844
3372.58	77.8225
3376.65	75.7888
3380.71	78.0362
3384.78	81.6451
3388.84	80.9576
3392.9	79.0114
3396.95	79.8816
3401.01	80.659
3405.06	79.2447
3409.1	79.0558
3413.15	79.9681
3417.19	81.9084
3421.23	81.7732
3425.27	80.3929
3429.31	79.1221
3433.34	78.3599
3437.37	78.1456
3441.39	79.5045
3445.42	78.0245
3449.44	77.7944
3453.46	78.8509
3457.47	73.1869
3461.49	70.2345
3465.5	77.7085
3469.51	76.9806
3473.51	74.9587
3477.52	75.5929
3481.52	78.1628
3485.51	78.4724
3489.51	71.6285
3493.5	73.7808
3497.49	72.8217
3501.48	75.0515
3505.46	75.9532
3509.45	75.6685
3513.43	71.5213
3517.4	72.3506
3521.38	76.1616
3525.35	72.8241
3529.32	71.7154
3533.28	69.4019
3537.25	69.8536
3541.21	72.3082
3545.17	73.6512
3549.12	72.4327
3553.08	71.5453
3557.03	71.4454
3560.98	70.8575
3564.92	70.7581
3568.87	70.2235
3572.81	72.7987
3576.74	75.8474
3580.68	77.8653
3584.61	79.6211
3588.54	78.8675
3592.47	77.6633
3596.4	74.821
3600.32	70.4066
3604.24	67.7431
3608.16	65.28
3612.07	65.657
3615.98	68.6034
3619.89	67.1627
3623.8	67.0048
3627.71	67.5356
3631.61	69.0316
3635.51	66.6637
3639.41	66.3788
3643.3	66.6826
3647.19	65.4946
3651.08	64.8989
3654.97	65.1639
3658.85	64.7034
3662.74	62.5749
3666.62	61.8471
3670.49	63.0559
3674.37	66.4226
3678.24	66.974
3682.11	66.2463
3685.98	64.5174
3689.84	63.9829
3693.7	63.6671
3697.56	63.1861
3701.42	63.9447
3705.28	65.506
3709.13	64.593
3712.98	61.9607
3716.82	62.1935
3720.67	61.4135
3724.51	60.7489
3728.35	62.8952
3732.19	61.9981
3736.02	62.0233
3739.86	63.1445
3743.69	63.5773
3747.51	63.0496
3751.34	63.0644
3755.16	63.2487
3758.98	62.6062
3762.8	60.2034
3766.61	57.8246
3770.43	63.6879
3774.24	62.3681
3778.05	61.3177
3781.85	62.7393
3785.65	59.1224
3789.45	59.5346
3793.25	59.6972
3797.05	61.7461
3800.84	62.8312
3804.63	61.5058
3808.42	59.8147
3812.21	60.017
3815.99	60.5741
3819.77	61.7447
3823.55	60.6458
3827.33	59.7838
3831.1	59.9426
3834.87	61.2718
3838.64	60.9376
3842.41	60.4282
3846.17	57.8916
3849.93	56.8284
3853.69	57.2549
3857.45	59.1574
3861.21	60.7805
3864.96	59.7595
3868.71	58.873
3872.46	58.1197
3876.2	56.6675
3879.94	57.4574
3883.68	58.2883
3887.42	56.8732
3891.16	55.5542
3894.89	55.7811
3898.62	57.1174
3902.35	57.68
3906.08	58.5655
3909.8	58.9467
3913.52	58.7798
3917.24	58.1833
3920.96	56.0581
3924.67	57.3531
3928.38	58.6653
3932.09	58.0934
3935.8	57.3243
3939.51	56.539
3943.21	55.5178
3946.91	54.4724
3950.61	54.4169
3954.3	54.9304
3958	55.1307
3961.69	54.5307
3965.38	55.2295
3969.06	56.4983
3972.75	55.5164
3976.43	54.3739
3980.11	53.6169
3983.78	53.0336
3987.46	52.689
3991.13	52.7243
3994.8	53.7505
3998.47	61.1225