File: Data/3-Raman/raw/20-C_brt2_FI05_1.txt
#Acq. time (s)=	20
#Accumulations=	3
#Range (cm-¹)=	100...4000
#Windows=	1
#Auto scanning=	Off
#Autofocus=	Off
#Macrospot=	Off
#AutoExposure=	Off
#Spike filter=	Multiple accum.
#Delay time (s)=	0
#Binning=	1
#Readout mode=	Signal
#DeNoise=	Lite
#ICS correction=	Off
#Dark correction=	Off
#Inst. Process=	Off
#Detector temperature (°C)=	-60.09
#Instrument=	LabRAM HR Evol
#Detector=	SIN-EM FIVIS
#Objective=	x100_VIS
#Grating=	150 (500nm)
#ND Filter=	100%
#Laser=	633nm_Edge
#Hole=	30.0125
#Temperature=	0
#Range=	Visible
#StageXY=	75x50mm Scan+
#StageZ=	Z motor
#X (µm)=	8743.1
#Y (µm)=	4539.3
#Z (µm)=	1852.1
#Full time(mm:ss)=	1:02
#Project=	Buranga
#Sample=	BU18FA20_C
#Site=	C_Bertoss2
#Title=	20-C_brt2_FI05_1
#Remark=
#Date=	30.07.2019 15:42
#Acquired=	30.07.2019 15:42:00
100.38	191.671
106.898	168.928
113.411	159.287
119.918	148.714
126.419	139.539
132.916	130.802
139.407	125.999
145.892	122.573
152.372	119.801
158.847	116.314
165.316	121.324
171.781	116.915
178.239	106.31
184.693	105.159
191.139	103.759
197.582	94.3155
204.02	102.674
210.452	101.673
216.877	100.575
223.299	108.69
229.715	131.438
236.126	178.882
242.53	207.995
248.931	154.28
255.326	137.462
261.714	134.929
268.099	141.789
274.477	157.616
280.851	199.987
287.218	252.163
293.582	213.461
299.939	156.682
306.293	125.425
312.639	120.635
318.982	140.615
325.318	186.04
331.651	257.735
337.977	199.37
344.297	139.938
350.614	122.457
356.925	120.097
363.23	137.509
369.53	151.988
375.827	146.284
382.116	127.629
388.401	109.833
394.681	103.799
400.956	100.803
407.226	98.1152
413.49	101.005
419.749	110.56
426.003	126.967
432.252	146.495
438.496	182.303
444.735	191.751
450.969	187.806
457.197	175.475
463.421	160.603
469.64	136.006
475.853	116.666
482.062	102.308
488.265	99.059
494.464	100.417
500.657	104.084
506.844	107.322
513.028	108.985
519.206	108.044
525.38	106.411
531.548	104.766
537.71	104.089
543.869	103.639
550.022	101.25
556.169	99.2979
562.313	97.4972
568.452	98.2099
574.584	97.5034
580.713	97.9019
586.837	93.9841
592.954	115.265
599.068	152.859
605.176	186.315
611.28	167.48
617.378	147.28
623.473	140.04
629.561	146.572
635.644	153.274
641.724	147.137
647.797	141.151
653.867	146.816
659.931	167.474
665.99	167.271
672.044	143.507
678.095	119.316
684.139	102.365
690.179	91.2182
696.213	83.6257
702.245	80.7492
708.27	81.1487
714.29	81.4514
720.306	81.8843
726.316	80.43
732.322	77.8841
738.323	76.4229
744.32	77.2204
750.311	80.7585
756.298	82.6395
762.28	75.7046
768.258	80.9576
774.23	83.9074
780.198	82.5108
786.161	80.5614
792.119	77.1317
798.073	76.8266
804.021	78.1296
809.965	81.0045
815.904	84.5322
821.839	85.7423
827.769	84.7559
833.693	83.3676
839.614	84.0085
845.53	85.3698
851.44	86.48
857.346	85.8816
863.248	84.6742
869.144	84.4478
875.037	86.3177
880.924	87.2238
886.807	89.2968
892.685	89.661
898.559	90.9843
904.427	87.2108
910.292	89.7587
916.151	89.7993
922.006	90.8254
927.856	93.5369
933.701	98.2815
939.543	107.617
945.379	122.264
951.21	140.573
957.037	158.723
962.861	168.699
968.678	181.058
974.491	206.82
980.3	250.975
986.104	321.687
991.904	410.062
997.699	370.128
1003.49	307.095
1009.28	265.208
1015.06	264.269
1020.83	292.984
1026.61	328.549
1032.37	312.124
1038.14	236.013
1043.9	180.29
1049.65	150.484
1055.4	133.43
1061.15	123.959
1066.88	118.98
1072.62	116.076
1078.35	120.5
1084.08	137.97
1089.8	150.009
1095.52	160.596
1101.23	171.546
1106.94	171.87
1112.65	134.024
1118.35	108.437
1124.05	99.7056
1129.74	98.5755
1135.42	101.587
1141.11	107.533
1146.78	115.542
1152.46	127.295
1158.13	137.863
1163.79	117.949
1169.45	90.0788
1175.11	85.4271
1180.76	84.8223
1186.41	81.5407
1192.05	80.0364
1197.69	75.5755
1203.32	75.7458
1208.95	77.953
1214.58	76.1202
1220.2	73.3072
1225.82	71.9568
1231.43	71.5287
1237.04	68.2157
1242.64	67.5127
1248.24	71.1143
1253.83	75.161
1259.42	76.418
1265.01	77.2572
1270.59	76.0238
1276.17	74.4937
1281.74	103.344
1287.31	89.526
1292.88	77.2089
1298.44	76.206
1303.99	75.7038
1309.55	74.1159
1315.09	71.5335
1320.64	67.9942
1326.18	69.1836
1331.71	69.6353
1337.24	63.9702
1342.77	68.5513
1348.29	68.4667
1353.81	68.2971
1359.32	69.1382
1364.83	70.9864
1370.33	73.4441
1375.84	74.419
1381.33	77.374
1386.82	169
1392.31	78
1397.8	63.6046
1403.28	74.4825
1408.75	75.0921
1414.22	71.4109
1419.69	68.8649
1425.15	68.131
1430.61	71.088
1436.07	70.4397
1441.52	69.8458
1446.96	67.0516
1452.41	65.3242
1457.84	65.1852
1463.28	65.136
1468.71	65.2953
1474.13	65.2496
1479.55	64.8284
1484.97	64.5716
1490.39	65.6834
1495.79	66.6862
1501.2	65.2703
1506.6	64.5931
1512	66.4604
1517.39	68.2057
1522.78	67.3284
1528.16	64.8401
1533.54	63.406
1538.92	63.0779
1544.29	63.797
1549.66	64.9249
1555.02	66.1065
1560.38	66.6498
1565.74	66.3898
1571.09	67.3823
1576.44	68.5942
1581.78	66.9895
1587.12	68.9892
1592.46	66.6821
1597.79	66.6124
1603.12	67.0421
1608.44	67.4986
1613.76	68.8665
1619.08	68.3829
1624.39	66.4619
1629.7	65.0577
1635	64.2217
1640.3	65.5591
1645.59	67.4736
1650.88	67.8862
1656.17	66.6448
1661.46	66.6643
1666.74	67.5795
1672.01	67.7665
1677.28	67.3253
1682.55	67.16
1687.82	67.2906
1693.07	65.4775
1698.33	62.1124
1703.58	63.5404
1708.83	66.6918
1714.07	66.5803
1719.31	64.9275
1724.55	66.9479
1729.78	67.4561
1735.01	66.8809
1740.23	66.4752
1745.46	66.5188
1750.67	67.3712
1755.89	68.0037
1761.09	67.5985
1766.3	66.6801
1771.5	67.6412
1776.7	68.5145
1781.89	69.8764
1787.08	66.3259
1792.27	63.425
1797.45	70.2792
1802.62	69.5744
1807.8	67.4534
1812.97	66.7625
1818.14	67.5429
1823.3	71.1964
1828.46	68.1703
1833.61	63.7219
1838.76	64.5862
1843.91	66.7432
1849.05	66.9354
1854.19	65.4324
1859.33	65.5274
1864.46	68.0584
1869.59	68.4798
1874.71	68.1107
1879.83	66.6877
1884.95	66.9292
1890.06	65.3792
1895.17	65.4462
1900.27	67.3774
1905.38	68.4116
1910.47	71.1722
1915.57	70.9481
1920.66	67.8494
1925.74	69.3929
1930.83	67.8777
1935.91	66.1018
1940.98	65.281
1946.05	65.5221
1951.12	67.7733
1956.18	66.7823
1961.25	65.8967
1966.3	66.4922
1971.35	68.9265
1976.4	69.8348
1981.45	64.8249
1986.49	70.7075
1991.53	68.5014
1996.56	67.3768
2001.59	67.1332
2006.62	67.3547
2011.64	68.1181
2016.66	70.1439
2021.68	71.5256
2026.69	70.7474
2031.7	68.9196
2036.7	68.0431
2041.7	69.6959
2046.7	70.0197
2051.7	67.9367
2056.69	66.6028
2061.67	68.3951
2066.65	68.591
2071.63	68.2978
2076.61	69.2411
2081.58	66.8146
2086.55	67.4391
2091.51	71.8324
2096.47	70.936
2101.43	70.9219
2106.39	70.5991
2111.34	73.7873
2116.28	73.1323
2121.23	71.3493
2126.17	71.4417
2131.1	71.8064
2136.03	66.5711
2140.96	67.765
2145.89	70.6899
2150.81	71.422
2155.73	71.4867
2160.64	69.7238
2165.55	68.4732
2170.46	67.585
2175.36	68.2455
2180.26	71.3021
2185.16	72.1292
2190.05	71.4612
2194.94	70.4198
2199.83	71.3072
2204.71	68.3835
2209.59	70.0324
2214.46	73.9273
2219.33	75.6284
2224.2	71.9965
2229.07	70.9262
2233.93	71.3712
2238.79	71.6201
2243.64	71.7212
2248.49	71.9441
2253.34	67.3763
2258.18	73.2998
2263.02	71.6976
2267.86	70.1043
2272.69	69.1255
2277.52	68.9684
2282.35	69.4713
2287.17	70.4219
2291.99	72.1796
2296.8	72.6092
2301.62	69.3234
2306.43	70.9534
2311.23	72.398
2316.03	73.092
2320.83	73.479
2325.63	74.0145
2330.42	74.7087
2335.21	74.5962
2339.99	74.1637
2344.77	73.3893
2349.55	71.997
2354.32	71.8647
2359.1	71.1388
2363.86	71.1415
2368.63	72.7796
2373.39	73.6939
2378.15	74.0608
2382.9	70.8308
2387.65	71.2726
2392.4	72.0988
2397.14	71.3929
2401.88	68.6043
2406.62	70.4343
2411.35	72.7983
2416.08	73.3753
2420.81	73.1898
2425.53	73.437
2430.25	74.5826
2434.97	75.9896
2439.69	75.6166
2444.4	74.6938
2449.1	70.5036
2453.81	69.4023
2458.51	69.7852
2463.2	71.0284
2467.9	72.5386
2472.59	70.6522
2477.27	68.9305
2481.96	71.0827
2486.64	71.3781
2491.31	73.0499
2495.99	73.3408
2500.66	75.0617
2505.32	75.6169
2509.99	74.6968
2514.65	72.8432
2519.31	71.7842
2523.96	70.4157
2528.61	70.2909
2533.26	72.187
2537.9	74.8785
2542.54	75.526
2547.18	75.7174
2551.81	75.6088
2556.44	73.4111
2561.07	71.2032
2565.69	70.5705
2570.32	71.119
2574.93	70.6545
2579.55	72.9216
2584.16	73.3356
2588.77	72.709
2593.37	72.4143
2597.97	72.4431
2602.57	73.3994
2607.17	72.8929
2611.76	72.7593
2616.35	74.2937
2620.93	73.4147
2625.51	72.4648
2630.09	73.2901
2634.67	75.3555
2639.24	74.8255
2643.81	72.2732
2648.38	69.4797
2652.94	71.3887
2657.5	72.8346
2662.06	70.7432
2666.61	66.4531
2671.16	69.3636
2675.71	72.491
2680.25	71.2784
2684.79	72.3757
2689.33	75.1292
2693.86	75.7385
2698.39	72.8605
2702.92	70.7167
2707.45	70.7648
2711.97	68.6305
2716.49	71.287
2721	72.0129
2725.51	72.0245
2730.02	71.6917
2734.53	71.0392
2739.03	71.7306
2743.53	72.9758
2748.03	71.5207
2752.52	69.6794
2757.01	69.773
2761.5	70.6558
2765.98	71.9396
2770.46	70.8654
2774.94	71.154
2779.42	74.3206
2783.89	70.707
2788.36	69.2965
2792.82	66.548
2797.28	64.552
2801.74	65.5368
2806.2	68.5788
2810.65	72.3409
2815.1	72.1606
2819.55	72.4317
2823.99	72.1301
2828.43	70.5745
2832.87	70.1992
2837.3	70.5824
2841.74	68.987
2846.17	66.1968
2850.59	68.6764
2855.01	70.6865
2859.43	69.3104
2863.85	68.6415
2868.26	66.3485
2872.67	65.3733
2877.08	65.9411
2881.48	68.4549
2885.89	71.9926
2890.28	72.1172
2894.68	70.0265
2899.07	71.3762
2903.46	72.5737
2907.85	68.5661
2912.23	66.7187
2916.61	68.1058
2920.98	68.5662
2925.36	68.9479
2929.73	68.4314
2934.1	68.2956
2938.46	68.4482
2942.82	69.3985
2947.18	71.2683
2951.54	71.8189
2955.89	71.5446
2960.24	71.5955
2964.59	71.8621
2968.93	72.8683
2973.27	72.5164
2977.61	70.5384
2981.95	69.4684
2986.28	69.1479
2990.61	72.2467
2994.94	72.7091
2999.26	69.0995
3003.58	67.4814
3007.9	68.3249
3012.21	71.049
3016.52	73.358
3020.83	71.7558
3025.14	67.753
3029.44	64.2456
3033.74	65.5168
3038.04	69.4648
3042.33	68.9862
3046.62	69.6297
3050.91	67.227
3055.2	68.2164
3059.48	70.6897
3063.76	69.9608
3068.03	68.28
3072.31	67.0783
3076.58	66.724
3080.85	71.926
3085.11	75.3735
3089.37	73.955
3093.63	71.7506
3097.89	71.8984
3102.14	71.0153
3106.39	66.3097
3110.64	68.5292
3114.89	73.101
3119.13	74.8177
3123.37	73.6353
3127.6	73.4031
3131.84	74.3138
3136.07	74.3201
3140.29	71.6417
3144.52	71.6525
3148.74	71.711
3152.96	74.0004
3157.18	74.4574
3161.39	73.4297
3165.6	71.574
3169.81	69.2012
3174.01	68.9286
3178.22	71.8356
3182.42	74.8
3186.61	74.7994
3190.8	76.0678
3195	79.0034
3199.18	78.7864
3203.37	75.6096
3207.55	74.3505
3211.73	77.2282
3215.91	78.8953
3220.08	76.9159
3224.25	75.7156
3228.42	74.4784
3232.59	72.5715
3236.75	72.9635
3240.91	73.367
3245.07	73.9103
3249.22	74.0158
3253.37	73.6757
3257.52	72.8886
3261.67	71.4847
3265.81	69.2646
3269.95	67.2764
3274.09	67.2123
3278.22	67.5927
3282.36	68.3286
3286.49	68.7601
3290.61	66.5034
3294.74	65.8762
3298.86	67.6769
3302.98	67.0466
3307.09	65.3114
3311.21	63.3784
3315.32	63.1759
3319.42	64.8529
3323.53	65.3865
3327.63	65.4012
3331.73	66.0373
3335.83	66.7286
3339.92	67.89
3344.01	68.3422
3348.1	66.9602
3352.19	66.0559
3356.27	65.3658
3360.35	64.7342
3364.43	65.4422
3368.5	66.4676
3372.58	66.7738
3376.65	67.8519
3380.71	69.302
3384.78	70.7306
3388.84	71.1467
3392.9	71.2498
3396.95	71.1581
3401.01	71.8525
3405.06	69.8087
3409.1	69.006
3413.15	70.6695
3417.19	72.6522
3421.23	74.0423
3425.27	73.3314
3429.31	71.3433
3433.34	69.7721
3437.37	68.8155
3441.39	68.1781
3445.42	67.9999
3449.44	66.8746
3453.46	67.2943
3457.47	68.9588
3461.49	66.8677
3465.5	66.7299
3469.51	64.1237
3473.51	64.276
3477.52	65.9706
3481.52	67.6924
3485.51	67.186
3489.51	65.514
3493.5	64.3439
3497.49	65.3001
3501.48	64.7105
3505.46	63.5547
3509.45	63.3865
3513.43	60.9244
3517.4	63.5574
3521.38	64.2615
3525.35	63.0962
3529.32	63.9724
3533.28	60.4946
3537.25	58.9977
3541.21	59.832
3545.17	57.9455
3549.12	58.5633
3553.08	59.7325
3557.03	61.299
3560.98	61.9093
3564.92	62.3096
3568.87	63.3932
3572.81	65.2353
3576.74	67.945
3580.68	69.0912
3584.61	71.6983
3588.54	71.3628
3592.47	68.929
3596.4	68.2807
3600.32	66.0202
3604.24	61.0082
3608.16	58.046
3612.07	56.9872
3615.98	56.0092
3619.89	54.4114
3623.8	55.2493
3627.71	55.5876
3631.61	56.442
3635.51	59.4421
3639.41	57.7443
3643.3	55.9593
3647.19	54.9521
3651.08	53.5411
3654.97	52.3865
3658.85	51.8048
3662.74	54.0276
3666.62	54.735
3670.49	55.8058
3674.37	56.9296
3678.24	54.3233
3682.11	53.8332
3685.98	55.5594
3689.84	55.037
3693.7	52.323
3697.56	52.4525
3701.42	52.3725
3705.28	52.9635
3709.13	53.0859
3712.98	51.3694
3716.82	52.012
3720.67	51.9376
3724.51	50.214
3728.35	49.7542
3732.19	49.9234
3736.02	49.0059
3739.86	49.8799
3743.69	52.5844
3747.51	52.4699
3751.34	51.573
3755.16	52.0835
3758.98	52.3681
3762.8	51.4089
3766.61	50.7158
3770.43	52.2489
3774.24	53.1175
3778.05	53.0927
3781.85	52.4842
3785.65	52.1339
3789.45	51.6127
3793.25	52.1059
3797.05	51.049
3800.84	50.2674
3804.63	50.0807
3808.42	49.0355
3812.21	49.58
3815.99	49.1678
3819.77	49.5446
3823.55	52.2233
3827.33	51.7694
3831.1	49.9292
3834.87	48.2435
3838.64	49.8894
3842.41	49.8681
3846.17	47.1051
3849.93	45.1625
3853.69	45.6495
3857.45	48.8204
3861.21	51.2894
3864.96	51.161
3868.71	50.7796
3872.46	50.3859
3876.2	49.7223
3879.94	48.8865
3883.68	47.6353
3887.42	46.9169
3891.16	47.3157
3894.89	48.472
3898.62	48.4962
3902.35	45.1017
3906.08	43.3617
3909.8	45.1387
3913.52	46.6927
3917.24	48.1849
3920.96	47.2928
3924.67	45.85
3928.38	45.3024
3932.09	45.4816
3935.8	44.7351
3939.51	44.1314
3943.21	45.8278
3946.91	47.0961
3950.61	45.9082
3954.3	44.0025
3958	44.9187
3961.69	46.4778
3965.38	46.7206
3969.06	45.8172
3972.75	43.1588
3976.43	44.552
3980.11	46.6006
3983.78	45.4515
3987.46	43.8499
3991.13	44.9547
3994.8	43.1307
3998.47	41.3092