File: Data/3-Raman/raw/20-C_brt1_FI03.txt
#Acq. time (s)=	20
#Accumulations=	3
#Range (cm-¹)=	100...4000
#Windows=	1
#Auto scanning=	Off
#Autofocus=	Off
#Macrospot=	Off
#AutoExposure=	Off
#Spike filter=	Multiple accum.
#Delay time (s)=	0
#Binning=	1
#Readout mode=	Signal
#DeNoise=	Lite
#ICS correction=	Off
#Dark correction=	Off
#Inst. Process=	Off
#Detector temperature (°C)=	-60.09
#Instrument=	LabRAM HR Evol
#Detector=	SIN-EM FIVIS
#Objective=	x50_VIS_LWD
#Grating=	150 (500nm)
#ND Filter=	100%
#Laser=	633nm_Edge
#Hole=	30.0125
#Temperature=	0
#Range=	Visible
#StageXY=	75x50mm Scan+
#StageZ=	Z motor
#X (µm)=	7362.6
#Y (µm)=	4426.1
#Z (µm)=	-30.3
#Full time(mm:ss)=	1:02
#Project=	Buranga
#Sample=	BU18FA20_C
#Site=	C_Bertoss1
#Title=	20-C_brt1_FI03
#Remark=
#Date=	30.07.2019 14:39
#Acquired=	30.07.2019 14:39:04
100.38	607.569
106.898	475.736
113.411	392.656
119.918	337.119
126.419	291.724
132.916	255.512
139.407	229.239
145.892	210.447
152.372	194.411
158.847	177.451
165.316	169.669
171.781	164.54
178.239	156.323
184.693	135.391
191.139	144.267
197.582	138.954
204.02	133.74
210.452	135.754
216.877	139.959
223.299	144.699
229.715	156.157
236.126	218.229
242.53	334.484
248.931	259.698
255.326	202.108
261.714	188.644
268.099	198.208
274.477	225.748
280.851	272.021
287.218	355.445
293.582	383.9
299.939	269.361
306.293	199.461
312.639	166.268
318.982	181.137
325.318	237.502
331.651	376.789
337.977	339.312
344.297	234.656
350.614	175.692
356.925	179.48
363.23	203.163
369.53	222.661
375.827	217.842
382.116	167.468
388.401	132.755
394.681	122.186
400.956	120.982
407.226	125.572
413.49	131.733
419.749	138.134
426.003	155.341
432.252	188.357
438.496	244.775
444.735	277.09
450.969	281.584
457.197	263.683
463.421	242.586
469.64	205.025
475.853	165.169
482.062	136.09
488.265	123.013
494.464	118.513
500.657	123.638
506.844	131.211
513.028	134.664
519.206	132.069
525.38	126.496
531.548	125.214
537.71	122.745
543.869	118.097
550.022	117.964
556.169	120.705
562.313	117.841
568.452	110.384
574.584	107.492
580.713	111.144
586.837	124.183
592.954	150.021
599.068	189.905
605.176	294.268
611.28	268.788
617.378	227.805
623.473	208.529
629.561	218.958
635.644	227.852
641.724	223.542
647.797	207.951
653.867	208.384
659.931	232.024
665.99	255.285
672.044	209.041
678.095	154.693
684.139	124.916
690.179	108.245
696.213	97.3475
702.245	90.7841
708.27	88.5984
714.29	88.7948
720.306	88.8327
726.316	88.4603
732.322	88.6862
738.323	88.4771
744.32	86.6823
750.311	85.8161
756.298	85.9006
762.28	87.0038
768.258	89.3123
774.23	89.8551
780.198	87.46
786.161	82.6922
792.119	78.2252
798.073	80.3092
804.021	86.9038
809.965	87.4824
815.904	86.8273
821.839	89.3631
827.769	88.8555
833.693	90.0179
839.614	92.2196
845.53	94.2586
851.44	93.5055
857.346	92.2052
863.248	92.0974
869.144	93.5887
875.037	96.2129
880.924	97.4537
886.807	101.457
892.685	103.443
898.559	108.763
904.427	104.552
910.292	101.717
916.151	105.332
922.006	112.853
927.856	117.285
933.701	121.641
939.543	130.101
945.379	146.682
951.21	172.307
957.037	202.673
962.861	233.983
968.678	251.146
974.491	280.072
980.3	333.965
986.104	471.716
991.904	649.48
997.699	679.786
1003.49	550.554
1009.28	452.366
1015.06	416.68
1020.83	427.945
1026.61	508.298
1032.37	545.809
1038.14	409.637
1043.9	304.574
1049.65	243.315
1055.4	210.413
1061.15	188.828
1066.88	172.425
1072.62	168.43
1078.35	177.912
1084.08	201.665
1089.8	229.769
1095.52	250.652
1101.23	263.94
1106.94	260.746
1112.65	211.227
1118.35	164.201
1124.05	135.031
1129.74	125.754
1135.42	130.135
1141.11	141.913
1146.78	156.938
1152.46	173.486
1158.13	189.55
1163.79	174.748
1169.45	136.52
1175.11	115.453
1180.76	109.619
1186.41	105.72
1192.05	101.787
1197.69	99.0741
1203.32	94.2563
1208.95	89.3481
1214.58	87.4159
1220.2	88.5164
1225.82	91.2268
1231.43	89.4774
1237.04	87.1817
1242.64	87.7983
1248.24	89.8108
1253.83	90.9607
1259.42	95.3271
1265.01	109.408
1270.59	97.6686
1276.17	105.309
1281.74	247
1287.31	271
1292.88	111.915
1298.44	101.525
1303.99	96.3979
1309.55	94.1289
1315.09	89.7004
1320.64	85.4702
1326.18	85.6983
1331.71	87.5212
1337.24	91.508
1342.77	91.2182
1348.29	84.9443
1353.81	81.4756
1359.32	84.1993
1364.83	89.0322
1370.33	95.3947
1375.84	89.163
1381.33	108.986
1386.82	555
1392.31	182.7
1397.8	95
1403.28	105.923
1408.75	111.061
1414.22	96.0096
1419.69	78.9379
1425.15	83.1789
1430.61	76.9499
1436.07	79.4631
1441.52	78.9466
1446.96	79.4014
1452.41	79.814
1457.84	78.3977
1463.28	74.7004
1468.71	74.1546
1474.13	75.9163
1479.55	77.8764
1484.97	77.9474
1490.39	75.9086
1495.79	75.9455
1501.2	77.561
1506.6	76.7568
1512	75.636
1517.39	77.5192
1522.78	78.552
1528.16	77.4252
1533.54	75.3502
1538.92	73.5311
1544.29	75.106
1549.66	77.0091
1555.02	77.9675
1560.38	74.9749
1565.74	74.5456
1571.09	77.4628
1576.44	74.5239
1581.78	77.1715
1587.12	80.5128
1592.46	82.2174
1597.79	78.2689
1603.12	77.3052
1608.44	77.4991
1613.76	78.1849
1619.08	78.0422
1624.39	75.3211
1629.7	73.7599
1635	75.2592
1640.3	78.4367
1645.59	78.7742
1650.88	78.6452
1656.17	77.1431
1661.46	75.9632
1666.74	75.6296
1672.01	76.5038
1677.28	77.864
1682.55	78.664
1687.82	76.7962
1693.07	77.8001
1698.33	80.4408
1703.58	81.395
1708.83	77.8681
1714.07	75.5179
1719.31	74.8676
1724.55	75.826
1729.78	77.212
1735.01	76.3881
1740.23	78.4605
1745.46	78.476
1750.67	78.0397
1755.89	77.2391
1761.09	76.927
1766.3	76.6248
1771.5	76.6606
1776.7	79.0042
1781.89	80.2587
1787.08	79.0668
1792.27	77.4468
1797.45	78.1381
1802.62	80.149
1807.8	81.5932
1812.97	81.1099
1818.14	79.333
1823.3	74.5895
1828.46	78.5949
1833.61	77.708
1838.76	78.0588
1843.91	80.0362
1849.05	79.917
1854.19	79.264
1859.33	80.0192
1864.46	79.7461
1869.59	79.5981
1874.71	79.192
1879.83	79.2276
1884.95	79.688
1890.06	79.8936
1895.17	80.425
1900.27	80.4646
1905.38	78.222
1910.47	76.5752
1915.57	76.3261
1920.66	77.4155
1925.74	80.3014
1930.83	77.9717
1935.91	75.732
1940.98	79.7137
1946.05	77.9724
1951.12	80.6003
1956.18	83.6273
1961.25	76.9251
1966.3	79.5061
1971.35	82.1232
1976.4	78.9832
1981.45	78.6142
1986.49	80.8647
1991.53	80.6728
1996.56	79.0497
2001.59	77.8253
2006.62	78.0031
2011.64	80.1406
2016.66	81.5585
2021.68	81.5416
2026.69	78.5465
2031.7	76.5922
2036.7	76.4489
2041.7	77.6636
2046.7	80.7628
2051.7	83.203
2056.69	82.8433
2061.67	80.7443
2066.65	80.5695
2071.63	81.05
2076.61	83.3221
2081.58	82.6023
2086.55	83.4136
2091.51	85.2901
2096.47	82.5068
2101.43	80.4782
2106.39	81.4494
2111.34	83.1219
2116.28	83.9753
2121.23	80.0192
2126.17	77.9564
2131.1	80.0121
2136.03	79.8226
2140.96	79.1798
2145.89	81.2776
2150.81	85.2768
2155.73	87.5713
2160.64	87.7243
2165.55	84.6177
2170.46	81.4308
2175.36	80.072
2180.26	80.2019
2185.16	82.9137
2190.05	84.1194
2194.94	83.2417
2199.83	83.3801
2204.71	80.1205
2209.59	80.2323
2214.46	84.9529
2219.33	86.2342
2224.2	84.7421
2229.07	82.869
2233.93	81.247
2238.79	79.8075
2243.64	80.6688
2248.49	81.7488
2253.34	82.3767
2258.18	83.2394
2263.02	84.7957
2267.86	86.0063
2272.69	85.6222
2277.52	84.0463
2282.35	82.7439
2287.17	82.4706
2291.99	83.2875
2296.8	85.7216
2301.62	86.8421
2306.43	86.2491
2311.23	80.9809
2316.03	82.2996
2320.83	86.328
2325.63	91.3776
2330.42	92.4755
2335.21	89.977
2339.99	85.8495
2344.77	84.8857
2349.55	83.6283
2354.32	85.9184
2359.1	85.9457
2363.86	84.904
2368.63	82.9828
2373.39	81.5319
2378.15	83.9821
2382.9	85.4599
2387.65	84.9847
2392.4	84.775
2397.14	85.0237
2401.88	85.3749
2406.62	85.7987
2411.35	83.5297
2416.08	85.2731
2420.81	84.1697
2425.53	84.317
2430.25	84.8191
2434.97	85.006
2439.69	86.1245
2444.4	84.8488
2449.1	83.6228
2453.81	83.4629
2458.51	83.2634
2463.2	82.0187
2467.9	81.5159
2472.59	81.393
2477.27	84.1965
2481.96	85.9183
2486.64	84.609
2491.31	83.1369
2495.99	82.1013
2500.66	81.3434
2505.32	84.703
2509.99	86.1562
2514.65	86.4405
2519.31	87.0474
2523.96	85.2521
2528.61	82.0187
2533.26	82.7521
2537.9	85.3416
2542.54	85.9272
2547.18	84.4897
2551.81	83.2889
2556.44	84.1361
2561.07	88.1591
2565.69	87.6185
2570.32	87.0481
2574.93	83.9811
2579.55	85.2205
2584.16	83.9904
2588.77	83.729
2593.37	83.6851
2597.97	85.3533
2602.57	83.6556
2607.17	84.641
2611.76	85.7253
2616.35	86.8678
2620.93	88.5926
2625.51	86.7771
2630.09	87.2487
2634.67	84.5603
2639.24	83.0619
2643.81	84.6552
2648.38	84.9707
2652.94	83.3495
2657.5	80.4648
2662.06	81.0287
2666.61	81.8134
2671.16	82.0435
2675.71	81.4689
2680.25	80.5672
2684.79	80.3875
2689.33	81.9165
2693.86	84.0881
2698.39	85.703
2702.92	83.2474
2707.45	81.2807
2711.97	82.7971
2716.49	83.1954
2721	82.7178
2725.51	82.2965
2730.02	82.1051
2734.53	80.9028
2739.03	80.7939
2743.53	82.1297
2748.03	83.7049
2752.52	84.6296
2757.01	79.953
2761.5	82.5262
2765.98	82.364
2770.46	81.7489
2774.94	83.9013
2779.42	83.4807
2783.89	83.0866
2788.36	83.757
2792.82	82.5304
2797.28	82.1042
2801.74	82.3708
2806.2	83.757
2810.65	83.9476
2815.1	83.9178
2819.55	83.0387
2823.99	82.1308
2828.43	82.1203
2832.87	82.7951
2837.3	83.2272
2841.74	82.9228
2846.17	84.4312
2850.59	85.4335
2855.01	86.0771
2859.43	85.8436
2863.85	84.7283
2868.26	83.113
2872.67	81.7618
2877.08	80.8718
2881.48	83.8056
2885.89	84.0858
2890.28	83.5845
2894.68	81.1563
2899.07	80.6473
2903.46	81.843
2907.85	81.8931
2912.23	84.292
2916.61	79.6547
2920.98	78.3365
2925.36	79.3275
2929.73	80.8667
2934.1	80.7792
2938.46	80.4778
2942.82	80.6107
2947.18	80.807
2951.54	81.4004
2955.89	81.5735
2960.24	80.1611
2964.59	79.0383
2968.93	79.625
2973.27	81.265
2977.61	82.7363
2981.95	80.7765
2986.28	81.2987
2990.61	80.6679
2994.94	79.99
2999.26	78.7494
3003.58	78.7591
3007.9	79.2742
3012.21	81.5936
3016.52	81.082
3020.83	79.9805
3025.14	81.801
3029.44	82.2328
3033.74	81.8784
3038.04	79.2005
3042.33	77.1866
3046.62	76.499
3050.91	76.9019
3055.2	78.5241
3059.48	79.8075
3063.76	81.1379
3068.03	83.2969
3072.31	82.8717
3076.58	78.8976
3080.85	76.5854
3085.11	78.9518
3089.37	81.5726
3093.63	82.4565
3097.89	82.2551
3102.14	81.7869
3106.39	83.0203
3110.64	84.2523
3114.89	82.4909
3119.13	79.9532
3123.37	80.4182
3127.6	81.1729
3131.84	81.909
3136.07	81.6514
3140.29	80.9513
3144.52	80.3621
3148.74	79.7631
3152.96	80.2153
3157.18	83.297
3161.39	86.4101
3165.6	87.3393
3169.81	85.0583
3174.01	83.8441
3178.22	86.2134
3182.42	87.2104
3186.61	87.3661
3190.8	85.3359
3195	83.8384
3199.18	85.4198
3203.37	85.1276
3207.55	87.4159
3211.73	89.1829
3215.91	87.5031
3220.08	84.8139
3224.25	81.974
3228.42	81.4168
3232.59	83.7988
3236.75	81.8136
3240.91	80.5749
3245.07	79.4371
3249.22	78.5108
3253.37	78.9385
3257.52	78.382
3261.67	78.0555
3265.81	79.1628
3269.95	78.2553
3274.09	77.3763
3278.22	77.2062
3282.36	76.7419
3286.49	75.4819
3290.61	74.125
3294.74	72.0923
3298.86	70.2125
3302.98	75.3363
3307.09	75.2216
3311.21	72.7696
3315.32	74.2843
3319.42	75.7805
3323.53	75.7212
3327.63	75.5205
3331.73	73.2621
3335.83	73.0938
3339.92	73.2022
3344.01	74.4389
3348.1	75.3206
3352.19	74.2484
3356.27	74.3474
3360.35	73.7751
3364.43	74.3914
3368.5	74.9412
3372.58	75.3116
3376.65	75.5037
3380.71	77.0615
3384.78	79.0456
3388.84	80.1526
3392.9	79.4811
3396.95	76.5239
3401.01	75.6139
3405.06	76.9124
3409.1	77.0229
3413.15	78.9389
3417.19	81.7083
3421.23	80.1082
3425.27	77.8229
3429.31	75.6531
3433.34	74.1532
3437.37	72.5296
3441.39	73.0861
3445.42	74.121
3449.44	74.5211
3453.46	73.9203
3457.47	74.2186
3461.49	72.5677
3465.5	69.4059
3469.51	70.5587
3473.51	71.6792
3477.52	70.6689
3481.52	69.7252
3485.51	68.879
3489.51	67.4719
3493.5	70.0507
3497.49	69.8017
3501.48	68.6882
3505.46	67.7736
3509.45	70.0823
3513.43	72.0214
3517.4	69.8977
3521.38	69.1237
3525.35	68.5343
3529.32	67.5255
3533.28	66.5718
3537.25	67.2851
3541.21	67.5316
3545.17	66.6659
3549.12	67.0203
3553.08	66.8156
3557.03	67.2614
3560.98	68.4661
3564.92	71.6492
3568.87	74.3889
3572.81	79.3246
3576.74	82.1696
3580.68	84.9882
3584.61	88.2532
3588.54	86.494
3592.47	83.9401
3596.4	85.0084
3600.32	81.2248
3604.24	75.2832
3608.16	72.0863
3612.07	66.7826
3615.98	63.0191
3619.89	63.571
3623.8	66.3594
3627.71	65.2501
3631.61	63.8265
3635.51	62.9781
3639.41	61.6078
3643.3	63.0517
3647.19	65.1805
3651.08	64.4368
3654.97	63.4205
3658.85	62.4898
3662.74	61.7321
3666.62	61.3546
3670.49	61.4308
3674.37	60.5178
3678.24	61.0067
3682.11	60.7288
3685.98	61.9666
3689.84	63.9346
3693.7	61.1927
3697.56	58.1824
3701.42	57.2901
3705.28	58.6856
3709.13	60.1046
3712.98	59.2089
3716.82	59.266
3720.67	60.2292
3724.51	61.227
3728.35	59.5884
3732.19	57.5363
3736.02	56.1418
3739.86	56.7224
3743.69	55.7641
3747.51	56.7131
3751.34	58.4433
3755.16	58.7986
3758.98	58.8647
3762.8	57.532
3766.61	56.8616
3770.43	56.7818
3774.24	57.2386
3778.05	57.88
3781.85	59.5683
3785.65	57.4176
3789.45	57.8987
3793.25	58.4738
3797.05	56.1605
3800.84	53.7849
3804.63	52.4854
3808.42	53.4104
3812.21	59.5438
3815.99	57.5074
3819.77	55.4235
3823.55	55.4175
3827.33	55.6126
3831.1	55.1435
3834.87	55.64
3838.64	57.0775
3842.41	58.2544
3846.17	57.2012
3849.93	55.9337
3853.69	56.0989
3857.45	56.5567
3861.21	56.9717
3864.96	56.9282
3868.71	55.7831
3872.46	54.6937
3876.2	55.3097
3879.94	54.5266
3883.68	53.3528
3887.42	52.3523
3891.16	55.0195
3894.89	56.1867
3898.62	55.6407
3902.35	52.4469
3906.08	53.3062
3909.8	54.9385
3913.52	56.7147
3917.24	56.802
3920.96	58.0419
3924.67	57.5786
3928.38	54.7008
3932.09	51.3691
3935.8	51.1862
3939.51	53.5057
3943.21	54.4575
3946.91	52.8206
3950.61	51.5598
3954.3	53.4558
3958	55.0252
3961.69	55.2262
3965.38	54.8049
3969.06	53.4723
3972.75	51.7611
3976.43	50.4468
3980.11	48.9413
3983.78	49.31
3987.46	50.3495
3991.13	51.4643
3994.8	52.9687
3998.47	53.7224