File: Data/3-Raman/raw/20-C_brt1_FI06.txt
#Acq. time (s)=	20
#Accumulations=	3
#Range (cm-¹)=	100...4000
#Windows=	1
#Auto scanning=	Off
#Autofocus=	Off
#Macrospot=	Off
#AutoExposure=	Off
#Spike filter=	Multiple accum.
#Delay time (s)=	0
#Binning=	1
#Readout mode=	Signal
#DeNoise=	Lite
#ICS correction=	Off
#Dark correction=	Off
#Inst. Process=	Off
#Detector temperature (°C)=	-60.09
#Instrument=	LabRAM HR Evol
#Detector=	SIN-EM FIVIS
#Objective=	x50_VIS_LWD
#Grating=	150 (500nm)
#ND Filter=	100%
#Laser=	633nm_Edge
#Hole=	30.0125
#Temperature=	0
#Range=	Visible
#StageXY=	75x50mm Scan+
#StageZ=	Z motor
#X (µm)=	7466
#Y (µm)=	4175.7
#Z (µm)=	-32.7
#Full time(mm:ss)=	1:02
#Project=	Buranga
#Sample=	BU18FA20_C
#Site=	C_Bertoss1
#Title=	20-C_brt1_FI06
#Remark=
#Date=	30.07.2019 14:32
#Acquired=	30.07.2019 14:32:44
100.38	405.615
106.898	344.934
113.411	295.455
119.918	256.342
126.419	229.248
132.916	208.793
139.407	200.39
145.892	196.153
152.372	183.298
158.847	174.922
165.316	169.875
171.781	173.166
178.239	159.36
184.693	151.429
191.139	148.54
197.582	147.632
204.02	146.818
210.452	144.798
216.877	143.473
223.299	148.769
229.715	164.474
236.126	191.549
242.53	294.15
248.931	239.374
255.326	201.049
261.714	189.165
268.099	195.814
274.477	210.163
280.851	209
287.218	283.863
293.582	314.26
299.939	244.375
306.293	194.649
312.639	172.276
318.982	175.526
325.318	216.733
331.651	329.624
337.977	312.061
344.297	234.6
350.614	184.616
356.925	182.67
363.23	201.07
369.53	219.712
375.827	211.402
382.116	187.156
388.401	160.007
394.681	152.278
400.956	152.268
407.226	154.893
413.49	158.464
419.749	163.015
426.003	170.473
432.252	202.397
438.496	224.301
444.735	267.902
450.969	257.146
457.197	246.07
463.421	230.955
469.64	207.618
475.853	179.413
482.062	163.505
488.265	155.787
494.464	147.106
500.657	149.342
506.844	156.524
513.028	160.581
519.206	161.827
525.38	161.905
531.548	159.301
537.71	157.034
543.869	154.875
550.022	152.806
556.169	147.401
562.313	139.083
568.452	146.834
574.584	147.351
580.713	144.93
586.837	142.875
592.954	164.279
599.068	198.284
605.176	244.323
611.28	248.07
617.378	222.064
623.473	215.411
629.561	217.915
635.644	222.757
641.724	219.146
647.797	203.569
653.867	205.105
659.931	218.115
665.99	225.635
672.044	206.225
678.095	176.585
684.139	153.753
690.179	137.975
696.213	128.3
702.245	125.44
708.27	129.335
714.29	128.611
720.306	120.398
726.316	116.318
732.322	117.895
738.323	121.747
744.32	125.965
750.311	125.807
756.298	123.947
762.28	123.72
768.258	123.635
774.23	123.195
780.198	122.544
786.161	121.599
792.119	121.382
798.073	118.064
804.021	116.837
809.965	113.986
815.904	119.289
821.839	123.055
827.769	123.598
833.693	124.813
839.614	125.146
845.53	125.093
851.44	124.287
857.346	127.743
863.248	125.572
869.144	125.864
875.037	123.708
880.924	126.791
886.807	131.693
892.685	134.594
898.559	131.729
904.427	130.016
910.292	130.125
916.151	132.028
922.006	136.15
927.856	138.18
933.701	140.076
939.543	147.053
945.379	160.035
951.21	174.838
957.037	194.722
962.861	214.395
968.678	225.065
974.491	243.644
980.3	279.015
986.104	361.247
991.904	470.717
997.699	493.934
1003.49	407.548
1009.28	344.533
1015.06	310.984
1020.83	332.236
1026.61	372.941
1032.37	393.276
1038.14	325.116
1043.9	249.603
1049.65	205.356
1055.4	195.836
1061.15	172.648
1066.88	165.046
1072.62	165.035
1078.35	165.548
1084.08	178.604
1089.8	194.377
1095.52	209.583
1101.23	221.706
1106.94	225.496
1112.65	196.708
1118.35	166.137
1124.05	144.593
1129.74	132.466
1135.42	136.682
1141.11	148.747
1146.78	160.45
1152.46	170.733
1158.13	185.476
1163.79	179.566
1169.45	146.978
1175.11	122.508
1180.76	118.401
1186.41	117.939
1192.05	112.472
1197.69	107.454
1203.32	106.661
1208.95	107.769
1214.58	105.358
1220.2	102.362
1225.82	101.006
1231.43	101.821
1237.04	103.476
1242.64	104.407
1248.24	102.63
1253.83	104.054
1259.42	105.502
1265.01	108.447
1270.59	104.778
1276.17	99.1236
1281.74	155
1287.31	197.293
1292.88	110.905
1298.44	104.406
1303.99	99.9872
1309.55	99.9082
1315.09	100.602
1320.64	100.54
1326.18	98.0866
1331.71	96.617
1337.24	96.1142
1342.77	92.4692
1348.29	90.6364
1353.81	90.1649
1359.32	93.3831
1364.83	96.1949
1370.33	98.1277
1375.84	99.811
1381.33	100.353
1386.82	281
1392.31	163
1397.8	98.6363
1403.28	101.777
1408.75	105.441
1414.22	100.026
1419.69	91.5443
1425.15	88.5831
1430.61	86.3129
1436.07	86.0044
1441.52	86.9543
1446.96	87.6617
1452.41	86.6967
1457.84	82.6106
1463.28	84.8718
1468.71	84.2371
1474.13	83.3059
1479.55	84.0328
1484.97	85.1566
1490.39	86.0104
1495.79	86.5667
1501.2	85.653
1506.6	83.6149
1512	81.7602
1517.39	81.3539
1522.78	82.4092
1528.16	80.7411
1533.54	78.4776
1538.92	77.9678
1544.29	77.6828
1549.66	77.3572
1555.02	81.1453
1560.38	81.1016
1565.74	82.5646
1571.09	84.5365
1576.44	82.9479
1581.78	82.1428
1587.12	82.3565
1592.46	82.7996
1597.79	83.1431
1603.12	81.9798
1608.44	79.2244
1613.76	79.4014
1619.08	79.8972
1624.39	80.2251
1629.7	80.9127
1635	80.0405
1640.3	77.551
1645.59	76.6794
1650.88	78.0578
1656.17	79.084
1661.46	80.8488
1666.74	82.3088
1672.01	82.1475
1677.28	81.1402
1682.55	81.297
1687.82	81.8316
1693.07	83.2622
1698.33	81.6744
1703.58	77.5435
1708.83	75.295
1714.07	77.0179
1719.31	79.3821
1724.55	78.5799
1729.78	78.3271
1735.01	78.9161
1740.23	79.6223
1745.46	79.7268
1750.67	77.7248
1755.89	76.2414
1761.09	77.2324
1766.3	76.9384
1771.5	76.1932
1776.7	75.8679
1781.89	76.023
1787.08	76.6703
1792.27	77.9329
1797.45	77.5605
1802.62	74.9567
1807.8	73.9831
1812.97	75.2317
1818.14	75.5882
1823.3	77.1027
1828.46	77.6877
1833.61	76.0417
1838.76	74.3641
1843.91	75.0495
1849.05	76.4363
1854.19	76.7485
1859.33	75.0685
1864.46	73.1385
1869.59	73.5098
1874.71	74.3398
1879.83	76.0204
1884.95	76.8077
1890.06	78.1929
1895.17	77.2397
1900.27	76.5966
1905.38	76.1116
1910.47	69.9994
1915.57	73.8815
1920.66	74.2698
1925.74	72.8479
1930.83	72.5486
1935.91	71.6508
1940.98	71.6964
1946.05	72.1827
1951.12	72.5649
1956.18	72.1277
1961.25	75.2184
1966.3	71.5246
1971.35	72.7296
1976.4	73.5424
1981.45	73.5846
1986.49	73.8984
1991.53	75.1173
1996.56	74.9568
2001.59	74.0056
2006.62	72.6537
2011.64	70.2271
2016.66	70.9614
2021.68	70.9362
2026.69	69.8715
2031.7	70.0821
2036.7	70.7306
2041.7	72.0855
2046.7	73.632
2051.7	72.3468
2056.69	71.5696
2061.67	71.1298
2066.65	71.1164
2071.63	71.1752
2076.61	71.7004
2081.58	71.8262
2086.55	73.176
2091.51	73.8579
2096.47	72.3104
2101.43	71.2648
2106.39	71.9764
2111.34	71.2012
2116.28	69.5326
2121.23	68.1097
2126.17	67.1678
2131.1	65.1021
2136.03	67.0611
2140.96	69.2418
2145.89	69.4807
2150.81	69.6716
2155.73	70.5235
2160.64	71.2329
2165.55	72.711
2170.46	66.2476
2175.36	64.352
2180.26	66.5013
2185.16	69.5489
2190.05	71.2736
2194.94	69.9748
2199.83	67.585
2204.71	66.2014
2209.59	65.5756
2214.46	65.9076
2219.33	67.0515
2224.2	69.1174
2229.07	70.0735
2233.93	67.8764
2238.79	71.1628
2243.64	71.1963
2248.49	70.2058
2253.34	69.4421
2258.18	71.7012
2263.02	72.2081
2267.86	71.1624
2272.69	71.4326
2277.52	67.8258
2282.35	69.0074
2287.17	70.9033
2291.99	68.5689
2296.8	66.669
2301.62	67.0135
2306.43	69.0689
2311.23	70.5238
2316.03	71.752
2320.83	69.6989
2325.63	69.5671
2330.42	69.5787
2335.21	69.9756
2339.99	67.455
2344.77	67.1666
2349.55	68.6558
2354.32	68.4639
2359.1	66.3866
2363.86	66.3326
2368.63	69.4296
2373.39	68.7513
2378.15	68.2664
2382.9	68.5743
2387.65	66.4607
2392.4	64.2818
2397.14	65.7757
2401.88	66.8577
2406.62	66.7769
2411.35	66.6656
2416.08	65.7077
2420.81	65.5354
2425.53	64.8876
2430.25	65.7516
2434.97	67.8534
2439.69	63.2421
2444.4	66.0653
2449.1	66.3813
2453.81	66.5581
2458.51	65.804
2463.2	64.0653
2467.9	63.7053
2472.59	63.8379
2477.27	62.754
2481.96	63.5034
2486.64	64.7411
2491.31	65.9943
2495.99	65.3253
2500.66	61.1512
2505.32	62.1613
2509.99	64.1128
2514.65	65.4996
2519.31	64.5651
2523.96	59.6604
2528.61	58.3067
2533.26	64.1604
2537.9	64.7085
2542.54	64.1926
2547.18	64.0144
2551.81	63.7812
2556.44	63.0742
2561.07	60.7926
2565.69	62.4657
2570.32	62.3862
2574.93	63.3848
2579.55	63.9573
2584.16	63.951
2588.77	63.2983
2593.37	63.7186
2597.97	64.9887
2602.57	65.2661
2607.17	64.45
2611.76	62.6947
2616.35	62.9447
2620.93	63.5152
2625.51	62.4064
2630.09	60.6619
2634.67	60.038
2639.24	61.0951
2643.81	62.2026
2648.38	63.5938
2652.94	61.0737
2657.5	61.3705
2662.06	61.7265
2666.61	60.1222
2671.16	59.5002
2675.71	59.7294
2680.25	60.5898
2684.79	62.2321
2689.33	62.0181
2693.86	60.9281
2698.39	60.7933
2702.92	62.2074
2707.45	61.0481
2711.97	61.4307
2716.49	61.7336
2721	62.0772
2725.51	60.9413
2730.02	59.4253
2734.53	57.6777
2739.03	59.4792
2743.53	61.3367
2748.03	62.4292
2752.52	61.774
2757.01	60.6663
2761.5	61.3499
2765.98	62.4613
2770.46	60.3316
2774.94	59.5891
2779.42	58.8161
2783.89	58.0656
2788.36	57.8912
2792.82	58.4598
2797.28	59.1624
2801.74	59.9541
2806.2	60.6296
2810.65	57.1149
2815.1	57.7684
2819.55	59.8319
2823.99	60.6131
2828.43	61.5643
2832.87	59.3373
2837.3	58.2643
2841.74	58.7031
2846.17	58.4065
2850.59	57.4117
2855.01	59.3297
2859.43	57.4507
2863.85	52.9576
2868.26	55.5818
2872.67	58.391
2877.08	57.2342
2881.48	56.8778
2885.89	58.5341
2890.28	57.5654
2894.68	56.6709
2899.07	57.2596
2903.46	57.4525
2907.85	56.5566
2912.23	56.1941
2916.61	54.6219
2920.98	53.0773
2925.36	56.545
2929.73	55.7514
2934.1	55.5771
2938.46	57.28
2942.82	56.6676
2947.18	57.5112
2951.54	58.3484
2955.89	58.0821
2960.24	58.4526
2964.59	58.1937
2968.93	58.2838
2973.27	58.8482
2977.61	56.9307
2981.95	54.9982
2986.28	55.2473
2990.61	54.8046
2994.94	54.767
2999.26	55.063
3003.58	55.8277
3007.9	56.7763
3012.21	57.1806
3016.52	55.6797
3020.83	56.6147
3025.14	56.9695
3029.44	56.1677
3033.74	55.3181
3038.04	56.6302
3042.33	56.5359
3046.62	56.5034
3050.91	56.7287
3055.2	56.6318
3059.48	55.7628
3063.76	56.965
3068.03	57.696
3072.31	57.7375
3076.58	58.8148
3080.85	58.3919
3085.11	57.2999
3089.37	58.8021
3093.63	59.19
3097.89	58.9102
3102.14	56.4459
3106.39	50.6076
3110.64	58.7683
3114.89	60.692
3119.13	60.0921
3123.37	57.6078
3127.6	55.7063
3131.84	56.8503
3136.07	59.4603
3140.29	60.7525
3144.52	60.9654
3148.74	59.961
3152.96	58.6426
3157.18	58.3745
3161.39	57.2635
3165.6	57.4833
3169.81	58.9109
3174.01	59.9328
3178.22	60.2944
3182.42	60.774
3186.61	61.0214
3190.8	62.2199
3195	64.0372
3199.18	62.4595
3203.37	61.4279
3207.55	60.4587
3211.73	59.475
3215.91	60.5913
3220.08	62.3569
3224.25	63.1833
3228.42	62.1329
3232.59	62.6687
3236.75	60.397
3240.91	57.7651
3245.07	56.8304
3249.22	59.3776
3253.37	59.9078
3257.52	58.9488
3261.67	58.9879
3265.81	58.9717
3269.95	57.6888
3274.09	55.5238
3278.22	53.5526
3282.36	54.9574
3286.49	55.7983
3290.61	56.4607
3294.74	56.9589
3298.86	55.8495
3302.98	54.2579
3307.09	51.7043
3311.21	54.126
3315.32	55.5813
3319.42	54.9424
3323.53	54.1639
3327.63	53.8217
3331.73	53.5107
3335.83	54.5749
3339.92	55.1496
3344.01	54.5855
3348.1	53.6344
3352.19	53.8576
3356.27	53.6912
3360.35	53.3349
3364.43	55.9587
3368.5	56.2226
3372.58	56.2236
3376.65	55.6309
3380.71	56.4702
3384.78	56.2397
3388.84	55.3781
3392.9	55.5039
3396.95	54.9549
3401.01	54.1679
3405.06	56.4781
3409.1	57.1478
3413.15	55.6168
3417.19	53.3556
3421.23	52.0972
3425.27	57.808
3429.31	57.1278
3433.34	55.7639
3437.37	54.5347
3441.39	53.2815
3445.42	53.5079
3449.44	53.2184
3453.46	52.6958
3457.47	52.6495
3461.49	51.8223
3465.5	50.7069
3469.51	49.7349
3473.51	50.1743
3477.52	50.821
3481.52	51.8441
3485.51	51.8595
3489.51	52.0372
3493.5	53.079
3497.49	53.3868
3501.48	52.4152
3505.46	49.0724
3509.45	47.7042
3513.43	49.2177
3517.4	52.2768
3521.38	50.9152
3525.35	50.6465
3529.32	49.9303
3533.28	49.3154
3537.25	46.0966
3541.21	45.5433
3545.17	47.5657
3549.12	50.5289
3553.08	50.2555
3557.03	47.6575
3560.98	47.5335
3564.92	48.2281
3568.87	51.2111
3572.81	50.385
3576.74	54.0541
3580.68	59.1166
3584.61	60.9457
3588.54	56.0516
3592.47	60.3325
3596.4	59.8477
3600.32	59.9743
3604.24	55.7802
3608.16	50.134
3612.07	48.4791
3615.98	48.0108
3619.89	46.966
3623.8	44.7447
3627.71	42.9273
3631.61	42.8357
3635.51	44.7008
3639.41	46.2459
3643.3	45.2155
3647.19	41.9355
3651.08	41.7578
3654.97	41.7767
3658.85	41.5604
3662.74	40.3153
3666.62	41.2029
3670.49	42.5876
3674.37	42.9352
3678.24	42.2165
3682.11	42.1071
3685.98	42.1248
3689.84	42.7762
3693.7	43.75
3697.56	43.6228
3701.42	41.5988
3705.28	40.8282
3709.13	40.8376
3712.98	41.9061
3716.82	42.1634
3720.67	40.605
3724.51	39.5811
3728.35	40.0707
3732.19	40.179
3736.02	41.0352
3739.86	42.2609
3743.69	41.9978
3747.51	40.7774
3751.34	40.2431
3755.16	40.3191
3758.98	40.1901
3762.8	40.2402
3766.61	39.471
3770.43	39.1906
3774.24	39.8301
3778.05	41.3855
3781.85	42.1378
3785.65	40.2926
3789.45	41.194
3793.25	40.4576
3797.05	39.8447
3800.84	39.5901
3804.63	39.1806
3808.42	37.0029
3812.21	36.9585
3815.99	39.2781
3819.77	39.4163
3823.55	40.3491
3827.33	39.981
3831.1	39.2308
3834.87	39.3159
3838.64	39.8952
3842.41	40.0696
3846.17	38.8769
3849.93	38.5206
3853.69	38.8713
3857.45	38.1581
3861.21	38.8317
3864.96	38.4883
3868.71	36.9818
3872.46	36.0418
3876.2	37.7932
3879.94	38.49
3883.68	38.4817
3887.42	38.209
3891.16	39.5298
3894.89	39.9519
3898.62	38.7042
3902.35	37.7648
3906.08	35.1951
3909.8	35.2699
3913.52	36.2287
3917.24	36.2122
3920.96	35.8214
3924.67	34.6428
3928.38	34.5761
3932.09	35.5358
3935.8	37.2265
3939.51	37.6434
3943.21	37.1749
3946.91	36.6668
3950.61	36.6293
3954.3	37.3795
3958	36.9722
3961.69	35.8353
3965.38	36.5095
3969.06	37.7377
3972.75	37.4657
3976.43	36.441
3980.11	36.6795
3983.78	37.1306
3987.46	37.2188
3991.13	37.5208
3994.8	37.1544
3998.47	35.4478