File: Data/3-Raman/raw/20-C_brt2_FI04.txt
#Acq. time (s)=	20
#Accumulations=	3
#Range (cm-¹)=	100...4000
#Windows=	1
#Auto scanning=	Off
#Autofocus=	Off
#Macrospot=	Off
#AutoExposure=	Off
#Spike filter=	Multiple accum.
#Delay time (s)=	0
#Binning=	1
#Readout mode=	Signal
#DeNoise=	Lite
#ICS correction=	On
#Dark correction=	Off
#Inst. Process=	Off
#Detector temperature (°C)=	-60.09
#Instrument=	LabRAM HR Evol
#Detector=	SIN-EM FIVIS
#Objective=	x100_VIS
#Grating=	150 (500nm)
#ND Filter=	100%
#Laser=	633nm_Edge
#Hole=	30.0125
#Temperature=	0
#Range=	Visible
#StageXY=	75x50mm Scan+
#StageZ=	Z motor
#X (µm)=	8694.4
#Y (µm)=	4538.1
#Z (µm)=	1850.8
#Full time(mm:ss)=	1:02
#Project=	Buranga
#Sample=	BU18FA20_C
#Site=	C_Bertoss2
#Title=	20-C_brt2_FI04
#Remark=
#Date=	30.07.2019 15:34
#Acquired=	30.07.2019 15:34:25
100.38	217.567
106.898	178.023
113.411	149.015
119.918	124.997
126.419	103.646
132.916	94.3772
139.407	87.2276
145.892	80.4042
152.372	72.6058
158.847	66.8544
165.316	63.7366
171.781	61.3956
178.239	59.4828
184.693	57.1638
191.139	56.7466
197.582	56.2099
204.02	55.6186
210.452	54.7781
216.877	54.4961
223.299	54.944
229.715	55.851
236.126	65.911
242.53	74.0827
248.931	67.4191
255.326	62.8981
261.714	60.8771
268.099	61.705
274.477	63.9031
280.851	69.5613
287.218	85.1077
293.582	78.5985
299.939	67.5095
306.293	58.9646
312.639	57.835
318.982	62.7453
325.318	72.4382
331.651	82.3946
337.977	76.3307
344.297	63.9388
350.614	59.2717
356.925	59.2137
363.23	62.5197
369.53	65.3429
375.827	63.7593
382.116	59.8847
388.401	55.1529
394.681	51.3862
400.956	54.0228
407.226	57.2126
413.49	55.482
419.749	56.5184
426.003	61.5474
432.252	69.2575
438.496	76.6633
444.735	78.3873
450.969	73.8139
457.197	69.1203
463.421	65.1498
469.64	62.7744
475.853	59.4314
482.062	55.7511
488.265	54.761
494.464	55.4942
500.657	57.5783
506.844	59.9203
513.028	61.1526
519.206	59.8777
525.38	58.0321
531.548	56.7349
537.71	56.9538
543.869	58.3615
550.022	59.8007
556.169	59.1537
562.313	58.1473
568.452	57.7574
574.584	58.1339
580.713	59.1239
586.837	58.4442
592.954	61.6405
599.068	70.4896
605.176	77.5626
611.28	76.4721
617.378	72.254
623.473	70.4276
629.561	70.3797
635.644	69.9334
641.724	68.3436
647.797	68.2851
653.867	71.0654
659.931	74.4622
665.99	73.6754
672.044	69.0028
678.095	61.9712
684.139	57.598
690.179	57.5317
696.213	55.4249
702.245	55.4359
708.27	57.8672
714.29	57.2729
720.306	56.8498
726.316	56.6469
732.322	56.8234
738.323	56.38
744.32	55.1448
750.311	54.1805
756.298	54.7041
762.28	56.1507
768.258	57.761
774.23	57.946
780.198	57.3571
786.161	57.7277
792.119	58.6567
798.073	57.6426
804.021	55.616
809.965	54.9948
815.904	55.9945
821.839	58.0059
827.769	59.09
833.693	58.7037
839.614	58.2799
845.53	57.5458
851.44	57.1639
857.346	57.1193
863.248	57.3819
869.144	57.384
875.037	57.6395
880.924	60.1207
886.807	60.7531
892.685	58.4339
898.559	57.8171
904.427	58.6892
910.292	59.7036
916.151	60.7048
922.006	61.8219
927.856	63.0947
933.701	62.2553
939.543	63.7626
945.379	66.2503
951.21	69.9868
957.037	73.3731
962.861	76.6398
968.678	79.2493
974.491	84.1152
980.3	92.3893
986.104	107.312
991.904	124.206
997.699	123.164
1003.49	109.489
1009.28	100.918
1015.06	99.0391
1020.83	103.505
1026.61	111.89
1032.37	107.287
1038.14	93.1832
1043.9	81.1622
1049.65	73.8792
1055.4	71.0553
1061.15	70.2389
1066.88	70.1121
1072.62	70.6525
1078.35	71.8934
1084.08	73.8992
1089.8	76.7852
1095.52	79.7579
1101.23	81.5574
1106.94	79.4597
1112.65	72.1663
1118.35	66.9156
1124.05	64.163
1129.74	63.4502
1135.42	65.8007
1141.11	68.9656
1146.78	72.9878
1152.46	75.0863
1158.13	74.3
1163.79	70.0248
1169.45	66.896
1175.11	64.3675
1180.76	66.5087
1186.41	67.6405
1192.05	65.8775
1197.69	64.4185
1203.32	64.3983
1208.95	64.0134
1214.58	63.6931
1220.2	62.8571
1225.82	62.331
1231.43	62.616
1237.04	63.7326
1242.64	65.0227
1248.24	66.9381
1253.83	69.5127
1259.42	71.7744
1265.01	68.5118
1270.59	65.8076
1276.17	80.5968
1281.74	183.21
1287.31	81.3143
1292.88	69.2925
1298.44	66.1695
1303.99	65.8178
1309.55	66.2267
1315.09	66.4904
1320.64	65.8741
1326.18	65.9742
1331.71	67.0612
1337.24	66.5443
1342.77	64.9856
1348.29	65.728
1353.81	67.6287
1359.32	68.7789
1364.83	69.633
1370.33	71.1881
1375.84	72.942
1381.33	96.7801
1386.82	294.973
1392.31	85.1771
1397.8	72.5502
1403.28	74.2348
1408.75	72.3543
1414.22	67.9623
1419.69	65.571
1425.15	64.8065
1430.61	65.5995
1436.07	65.8376
1441.52	64.0459
1446.96	66.7591
1452.41	67.3911
1457.84	66.1767
1463.28	65.0863
1468.71	64.944
1474.13	66.1693
1479.55	67.7066
1484.97	68.0472
1490.39	66.989
1495.79	65.297
1501.2	65.3307
1506.6	65.8022
1512	65.3729
1517.39	66.029
1522.78	63.912
1528.16	62.33
1533.54	63.8492
1538.92	65.2113
1544.29	66.2072
1549.66	67.0534
1555.02	67.8135
1560.38	65.4438
1565.74	64.672
1571.09	68.5695
1576.44	69.3983
1581.78	68.7853
1587.12	67.8396
1592.46	67.1985
1597.79	67.3249
1603.12	68.0724
1608.44	69.3112
1613.76	69.2836
1619.08	68.5968
1624.39	68.1505
1629.7	68.7381
1635	70.2708
1640.3	67.0826
1645.59	66.6399
1650.88	69.5723
1656.17	71.6951
1661.46	72.2053
1666.74	69.6265
1672.01	68.2458
1677.28	68.564
1682.55	70.9028
1687.82	74.0504
1693.07	73.299
1698.33	70.5169
1703.58	68.7977
1708.83	68.5161
1714.07	69.6059
1719.31	71.787
1724.55	70.5536
1729.78	71.3119
1735.01	71.2795
1740.23	72.3832
1745.46	74.6609
1750.67	76.518
1755.89	76.0274
1761.09	74.414
1766.3	70.8782
1771.5	70.1472
1776.7	72.0934
1781.89	73.9772
1787.08	74.3263
1792.27	74.0466
1797.45	73.7346
1802.62	74.6815
1807.8	75.7344
1812.97	76.9626
1818.14	76.8197
1823.3	74.043
1828.46	71.6081
1833.61	73.576
1838.76	75.5285
1843.91	75.9793
1849.05	75.7144
1854.19	74.7468
1859.33	75.2255
1864.46	76.3613
1869.59	75.9351
1874.71	75.0205
1879.83	76.8204
1884.95	74.8892
1890.06	74.6914
1895.17	76.2286
1900.27	78.6024
1905.38	79.6765
1910.47	78.6863
1915.57	77.4513
1920.66	78.3519
1925.74	80.3716
1930.83	79.2425
1935.91	78.12
1940.98	78.5446
1946.05	80.9344
1951.12	82.7631
1956.18	83.1276
1961.25	82.5798
1966.3	81.9695
1971.35	81.2683
1976.4	80.1508
1981.45	79.8034
1986.49	80.8891
1991.53	81.4346
1996.56	82.5047
2001.59	83.4549
2006.62	82.8507
2011.64	83.5419
2016.66	84.1538
2021.68	84.7454
2026.69	84.0043
2031.7	82.2983
2036.7	82.3504
2041.7	84.0174
2046.7	86.0219
2051.7	85.1071
2056.69	83.8578
2061.67	84.8822
2066.65	84.4377
2071.63	82.398
2076.61	86.3816
2081.58	88.4723
2086.55	88.2141
2091.51	86.4167
2096.47	85.5884
2101.43	85.0331
2106.39	84.1836
2111.34	84.5424
2116.28	86.186
2121.23	86.7423
2126.17	87.6893
2131.1	88.6292
2136.03	88.6945
2140.96	88.0791
2145.89	87.4758
2150.81	88.665
2155.73	90.0443
2160.64	91.6992
2165.55	89.7293
2170.46	86.8721
2175.36	88.0925
2180.26	89.5208
2185.16	90.8826
2190.05	92.5285
2194.94	90.8576
2199.83	89.4043
2204.71	89.3647
2209.59	90.3594
2214.46	91.1817
2219.33	91.0683
2224.2	90.8624
2229.07	91.543
2233.93	92.7744
2238.79	92.5366
2243.64	92.0119
2248.49	88.3877
2253.34	85.7137
2258.18	85.9502
2263.02	88.397
2267.86	91.4338
2272.69	93.3384
2277.52	94.7963
2282.35	96.7665
2287.17	97.8342
2291.99	96.3168
2296.8	97.4105
2301.62	97.4609
2306.43	98.4619
2311.23	97.867
2316.03	96.5329
2320.83	96.28
2325.63	97.5475
2330.42	99.7241
2335.21	99.9502
2339.99	101.12
2344.77	98.4184
2349.55	96.8867
2354.32	97.0852
2359.1	100.11
2363.86	101.381
2368.63	99.1346
2373.39	98.6133
2378.15	98.5022
2382.9	99.6472
2387.65	101.852
2392.4	100.946
2397.14	99.9715
2401.88	100.363
2406.62	99.1797
2411.35	100.268
2416.08	101.209
2420.81	98.7139
2425.53	97.1757
2430.25	100.542
2434.97	103.088
2439.69	100.422
2444.4	99.5357
2449.1	101.031
2453.81	102.078
2458.51	101.89
2463.2	103.376
2467.9	103.237
2472.59	101.83
2477.27	100.581
2481.96	101.903
2486.64	103.534
2491.31	104.593
2495.99	105.78
2500.66	106.521
2505.32	107.387
2509.99	106.179
2514.65	105.049
2519.31	103.94
2523.96	105.28
2528.61	107.869
2533.26	109.075
2537.9	107.815
2542.54	103.524
2547.18	103.56
2551.81	107.875
2556.44	107.9
2561.07	107.887
2565.69	106.619
2570.32	106.063
2574.93	106.492
2579.55	106.645
2584.16	109.298
2588.77	111.782
2593.37	110.002
2597.97	105.661
2602.57	105.429
2607.17	105.449
2611.76	105.143
2616.35	108.59
2620.93	111.928
2625.51	113.64
2630.09	113.166
2634.67	110.237
2639.24	108.503
2643.81	108.789
2648.38	110.371
2652.94	110.27
2657.5	108.144
2662.06	108.574
2666.61	109.56
2671.16	109.589
2675.71	109.288
2680.25	110.912
2684.79	110.176
2689.33	109.915
2693.86	111.287
2698.39	112.822
2702.92	113.088
2707.45	113.185
2711.97	112.087
2716.49	111.208
2721	109.96
2725.51	109.9
2730.02	112.193
2734.53	116.774
2739.03	114.65
2743.53	112.961
2748.03	113.916
2752.52	110.78
2757.01	111.426
2761.5	114.201
2765.98	115.892
2770.46	115.925
2774.94	114.456
2779.42	112.894
2783.89	112.887
2788.36	117.006
2792.82	118.627
2797.28	118.501
2801.74	117.689
2806.2	116.771
2810.65	116.734
2815.1	119.325
2819.55	120.855
2823.99	119.892
2828.43	115.974
2832.87	113.077
2837.3	115.171
2841.74	117.367
2846.17	117.711
2850.59	117.728
2855.01	117.082
2859.43	118.065
2863.85	120.935
2868.26	120.997
2872.67	119.86
2877.08	118.046
2881.48	119.802
2885.89	121.394
2890.28	121.003
2894.68	120.451
2899.07	119.266
2903.46	117.859
2907.85	116.466
2912.23	120.632
2916.61	120.414
2920.98	118.954
2925.36	118.407
2929.73	120.058
2934.1	125.885
2938.46	127.315
2942.82	125.536
2947.18	122.103
2951.54	118.703
2955.89	118.67
2960.24	120.76
2964.59	122.267
2968.93	123.236
2973.27	124.467
2977.61	124.148
2981.95	121.791
2986.28	124.681
2990.61	122.562
2994.94	118.712
2999.26	115.537
3003.58	120.03
3007.9	122.584
3012.21	122.308
3016.52	122.201
3020.83	122.58
3025.14	119.454
3029.44	121.839
3033.74	122.971
3038.04	123.84
3042.33	123.981
3046.62	123.547
3050.91	126.03
3055.2	127.636
3059.48	126.497
3063.76	124.809
3068.03	123.653
3072.31	123.449
3076.58	123.763
3080.85	125.932
3085.11	128.529
3089.37	126.361
3093.63	121.682
3097.89	119.391
3102.14	124.38
3106.39	128.701
3110.64	130.699
3114.89	126.652
3119.13	125.666
3123.37	125.71
3127.6	127.29
3131.84	128.516
3136.07	127.24
3140.29	126.684
3144.52	128.774
3148.74	129.413
3152.96	129.336
3157.18	130.832
3161.39	130.937
3165.6	129.661
3169.81	124.269
3174.01	134.802
3178.22	140.959
3182.42	135.087
3186.61	133.8
3190.8	133.161
3195	134.638
3199.18	136.879
3203.37	135.677
3207.55	131.312
3211.73	129.596
3215.91	134.018
3220.08	132.794
3224.25	126.089
3228.42	123.708
3232.59	128.364
3236.75	129.924
3240.91	131.487
3245.07	134.876
3249.22	130.567
3253.37	129.884
3257.52	130.75
3261.67	131.797
3265.81	134.655
3269.95	130.06
3274.09	128.99
3278.22	131.029
3282.36	127.649
3286.49	127.251
3290.61	130.747
3294.74	132.112
3298.86	130.613
3302.98	128.983
3307.09	129.515
3311.21	128.17
3315.32	126.981
3319.42	126.459
3323.53	130.727
3327.63	135.201
3331.73	134.886
3335.83	132.635
3339.92	131.323
3344.01	132.301
3348.1	124.229
3352.19	128.757
3356.27	135.586
3360.35	129.064
3364.43	126.931
3368.5	130.092
3372.58	132.88
3376.65	132.718
3380.71	129.718
3384.78	129.388
3388.84	132.931
3392.9	136.534
3396.95	137.628
3401.01	136.006
3405.06	132.298
3409.1	134.653
3413.15	136.521
3417.19	136.238
3421.23	136.965
3425.27	136.159
3429.31	132.332
3433.34	130.907
3437.37	135.444
3441.39	136.147
3445.42	132.692
3449.44	135.446
3453.46	130.552
3457.47	130.621
3461.49	131.276
3465.5	131.105
3469.51	132.341
3473.51	133.376
3477.52	130.664
3481.52	125.904
3485.51	126.315
3489.51	129.752
3493.5	129.841
3497.49	127.276
3501.48	125.629
3505.46	127.083
3509.45	130.88
3513.43	132.686
3517.4	134.452
3521.38	130.521
3525.35	128.519
3529.32	129.229
3533.28	132.151
3537.25	131.624
3541.21	129.172
3545.17	125.975
3549.12	124.248
3553.08	124.43
3557.03	125.536
3560.98	126.785
3564.92	128.423
3568.87	128.996
3572.81	128.155
3576.74	126.267
3580.68	127.051
3584.61	131.634
3588.54	127.57
3592.47	128.391
3596.4	131.767
3600.32	130.367
3604.24	126.819
3608.16	121.468
3612.07	121.051
3615.98	129.13
3619.89	130.152
3623.8	125.92
3627.71	124.541
3631.61	126.864
3635.51	123.446
3639.41	121.146
3643.3	126.814
3647.19	128.009
3651.08	118.862
3654.97	119.971
3658.85	126.061
3662.74	128.71
3666.62	128.119
3670.49	120.412
3674.37	123.312
3678.24	118.843
3682.11	124.412
3685.98	123.175
3689.84	121.229
3693.7	120.138
3697.56	121.727
3701.42	127.181
3705.28	127.692
3709.13	128.475
3712.98	127.836
3716.82	121.11
3720.67	114.255
3724.51	112.551
3728.35	121.463
3732.19	121.594
3736.02	124.105
3739.86	117.419
3743.69	121.625
3747.51	121.641
3751.34	119.623
3755.16	121.022
3758.98	121.522
3762.8	121.428
3766.61	121.007
3770.43	121.101
3774.24	122.842
3778.05	123.006
3781.85	121.192
3785.65	118.194
3789.45	120.877
3793.25	124.962
3797.05	126.051
3800.84	123.677
3804.63	121.272
3808.42	118.549
3812.21	117.697
3815.99	120.674
3819.77	123.502
3823.55	123
3827.33	120.036
3831.1	115.504
3834.87	115.468
3838.64	117.535
3842.41	117.588
3846.17	123.118
3849.93	126.291
3853.69	124.95
3857.45	122.941
3861.21	120.34
3864.96	117.641
3868.71	117.888
3872.46	120.033
3876.2	117.664
3879.94	114.605
3883.68	114.435
3887.42	114.306
3891.16	114.164
3894.89	119.397
3898.62	119.613
3902.35	119.665
3906.08	121.096
3909.8	120.655
3913.52	117.911
3917.24	113.728
3920.96	115.54
3924.67	118.326
3928.38	119.313
3932.09	119.414
3935.8	120.307
3939.51	119.027
3943.21	117.329
3946.91	116.784
3950.61	116.211
3954.3	113.331
3958	111.789
3961.69	114.53
3965.38	117.528
3969.06	117.765
3972.75	115.098
3976.43	112.537
3980.11	111.743
3983.78	112.626
3987.46	114.818
3991.13	113.762
3994.8	108.355
3998.47	105.33