File: Data/3-Raman/raw/20-C_brt1_FI05.txt
#Acq. time (s)=	20
#Accumulations=	3
#Range (cm-¹)=	100...4000
#Windows=	1
#Auto scanning=	Off
#Autofocus=	Off
#Macrospot=	Off
#AutoExposure=	Off
#Spike filter=	Multiple accum.
#Delay time (s)=	0
#Binning=	1
#Readout mode=	Signal
#DeNoise=	Lite
#ICS correction=	Off
#Dark correction=	Off
#Inst. Process=	Off
#Detector temperature (°C)=	-60.09
#Instrument=	LabRAM HR Evol
#Detector=	SIN-EM FIVIS
#Objective=	x50_VIS_LWD
#Grating=	150 (500nm)
#ND Filter=	100%
#Laser=	633nm_Edge
#Hole=	30.0125
#Temperature=	0
#Range=	Visible
#StageXY=	75x50mm Scan+
#StageZ=	Z motor
#X (µm)=	7406.8
#Y (µm)=	4383.9
#Z (µm)=	-31.3
#Full time(mm:ss)=	1:02
#Project=	Buranga
#Sample=	BU18FA20_C
#Site=	C_Bertoss1
#Title=	20-C_brt1_FI05
#Remark=
#Date=	30.07.2019 14:37
#Acquired=	30.07.2019 14:37:08
100.38	589.459
106.898	462.493
113.411	390.535
119.918	322.281
126.419	266.219
132.916	227.202
139.407	205.186
145.892	189.982
152.372	174.351
158.847	162.81
165.316	158.517
171.781	158.403
178.239	144.458
184.693	130.973
191.139	125.522
197.582	122.747
204.02	120.806
210.452	119.949
216.877	119.66
223.299	120.598
229.715	123.498
236.126	149.114
242.53	214.084
248.931	179.474
255.326	153.953
261.714	143.297
268.099	142.201
274.477	149.358
280.851	170.763
287.218	202.879
293.582	222.56
299.939	179.073
306.293	144.734
312.639	130.533
318.982	137.299
325.318	172.124
331.651	247.63
337.977	228.284
344.297	172.681
350.614	139.387
356.925	130.219
363.23	139.207
369.53	150.309
375.827	148.757
382.116	133.998
388.401	117.912
394.681	111.967
400.956	113.366
407.226	117.839
413.49	122.034
419.749	124.786
426.003	134.748
432.252	157.342
438.496	178.393
444.735	189.738
450.969	186.519
457.197	178.316
463.421	167.991
469.64	154.659
475.853	139.134
482.062	123.124
488.265	115.255
494.464	114.353
500.657	116.835
506.844	123.448
513.028	127.59
519.206	127.835
525.38	124.431
531.548	121.098
537.71	119.673
543.869	117.887
550.022	117.537
556.169	115.548
562.313	113.131
568.452	110.554
574.584	109.655
580.713	110.818
586.837	113.943
592.954	126.902
599.068	152.032
605.176	189.712
611.28	187.811
617.378	165.406
623.473	157.263
629.561	161.887
635.644	164.465
641.724	162.557
647.797	154.297
653.867	153.307
659.931	163.108
665.99	170.565
672.044	152.565
678.095	129.556
684.139	115.508
690.179	108.491
696.213	104.016
702.245	101.009
708.27	96.5438
714.29	95.2339
720.306	93.0675
726.316	93.674
732.322	95.7245
738.323	95.0816
744.32	92.345
750.311	91.2939
756.298	91.5709
762.28	93.855
768.258	97.4288
774.23	96.708
780.198	92.2612
786.161	91.9236
792.119	94.1688
798.073	96.5807
804.021	98.1851
809.965	98.9516
815.904	97.755
821.839	94.4363
827.769	92.6919
833.693	92.7181
839.614	96.1124
845.53	100.782
851.44	103.951
857.346	100.804
863.248	96.8728
869.144	96.7325
875.037	98.6344
880.924	100.97
886.807	102.574
892.685	103.152
898.559	103.193
904.427	103.769
910.292	106.485
916.151	100.293
922.006	95.5589
927.856	98.0457
933.701	103.339
939.543	111.508
945.379	122.196
951.21	134.978
957.037	149.91
962.861	165.778
968.678	167.362
974.491	177.446
980.3	209.347
986.104	266.242
991.904	358.96
997.699	385.132
1003.49	317.337
1009.28	271.508
1015.06	247.614
1020.83	257.795
1026.61	292.049
1032.37	300.588
1038.14	249.932
1043.9	195.317
1049.65	163.581
1055.4	147.629
1061.15	137.076
1066.88	130.09
1072.62	126.805
1078.35	134.231
1084.08	143.895
1089.8	153.514
1095.52	163.069
1101.23	173.831
1106.94	178.218
1112.65	150.515
1118.35	130.042
1124.05	115.961
1129.74	112.388
1135.42	114.545
1141.11	120.673
1146.78	129.379
1152.46	139.509
1158.13	148.193
1163.79	142.659
1169.45	119.243
1175.11	105.763
1180.76	101.953
1186.41	98.1276
1192.05	94.6233
1197.69	92.0943
1203.32	91.2321
1208.95	88.8242
1214.58	87.8035
1220.2	88.1575
1225.82	88.8966
1231.43	89.5598
1237.04	88.9477
1242.64	89.6755
1248.24	93.5021
1253.83	98.9571
1259.42	105.376
1265.01	114.799
1270.59	105.142
1276.17	106.684
1281.74	236
1287.31	324
1292.88	117.934
1298.44	100.649
1303.99	96.5709
1309.55	95.4582
1315.09	95.1107
1320.64	93.7002
1326.18	92.7802
1331.71	92.7068
1337.24	92.4801
1342.77	92.2121
1348.29	90.9421
1353.81	90.3782
1359.32	93.1564
1364.83	94.0047
1370.33	105.561
1375.84	101.784
1381.33	114.887
1386.82	569
1392.31	250
1397.8	103.329
1403.28	102.479
1408.75	127.742
1414.22	107.303
1419.69	92.1271
1425.15	86.5984
1430.61	83.9589
1436.07	83.4734
1441.52	85.8609
1446.96	87.3648
1452.41	85.7619
1457.84	82.1987
1463.28	80.3494
1468.71	82.0836
1474.13	83.8892
1479.55	84.9352
1484.97	84.8721
1490.39	83.3158
1495.79	83.4721
1501.2	83.0648
1506.6	82.3272
1512	82.0615
1517.39	81.4172
1522.78	80.3008
1528.16	75.623
1533.54	75.6946
1538.92	79.4426
1544.29	79.9833
1549.66	78.7392
1555.02	78.3945
1560.38	78.1505
1565.74	77.5088
1571.09	78.5188
1576.44	81.0934
1581.78	83.3246
1587.12	83.2798
1592.46	80.3404
1597.79	76.9997
1603.12	77.9636
1608.44	81.312
1613.76	84.4641
1619.08	83.1701
1624.39	82.9854
1629.7	81.6783
1635	80.0525
1640.3	80.5218
1645.59	80.4221
1650.88	79.3646
1656.17	76.1488
1661.46	73.6904
1666.74	74.8243
1672.01	79.2113
1677.28	81.2281
1682.55	79.9521
1687.82	78.8061
1693.07	81.1235
1698.33	80.2008
1703.58	79.6912
1708.83	79.3712
1714.07	78.7342
1719.31	76.0366
1724.55	80.0819
1729.78	85.5497
1735.01	87.0525
1740.23	82.8249
1745.46	79.9985
1750.67	79.7156
1755.89	80.1733
1761.09	79.5258
1766.3	79.012
1771.5	79.3032
1776.7	81.0932
1781.89	82.5517
1787.08	80.3908
1792.27	80.1601
1797.45	79.7093
1802.62	79.5322
1807.8	80.06
1812.97	78.5097
1818.14	80.5382
1823.3	78.8497
1828.46	79.1066
1833.61	80.5888
1838.76	80.6932
1843.91	79.5099
1849.05	76.5393
1854.19	78.2297
1859.33	79.3119
1864.46	78.2621
1869.59	82.41
1874.71	79.9156
1879.83	82.1369
1884.95	80.1123
1890.06	76.9854
1895.17	76.5198
1900.27	77.9517
1905.38	78.9333
1910.47	78.6485
1915.57	78.7164
1920.66	80.2708
1925.74	80.9832
1930.83	81.2933
1935.91	80.6696
1940.98	78.5903
1946.05	78.6453
1951.12	80.068
1956.18	79.4444
1961.25	79.8906
1966.3	81.099
1971.35	81.44
1976.4	82.9075
1981.45	77.0036
1986.49	78.2837
1991.53	80.0183
1996.56	80.6932
2001.59	80.7223
2006.62	79.2
2011.64	80.3147
2016.66	80.9892
2021.68	80.722
2026.69	81.2142
2031.7	81.1136
2036.7	79.4761
2041.7	78.7121
2046.7	79.3363
2051.7	79.6269
2056.69	80.108
2061.67	84.4464
2066.65	83.8889
2071.63	79.4837
2076.61	78.8473
2081.58	80.8669
2086.55	82.1079
2091.51	83.2616
2096.47	82.2236
2101.43	79.8553
2106.39	78.0332
2111.34	78.5684
2116.28	80.1702
2121.23	81.4445
2126.17	81.4402
2131.1	79.3441
2136.03	77.0932
2140.96	81.1856
2145.89	82.849
2150.81	83.273
2155.73	77.5149
2160.64	75.8048
2165.55	77.03
2170.46	81.5413
2175.36	80.7177
2180.26	80.2335
2185.16	80.3876
2190.05	80.843
2194.94	80.9703
2199.83	80.678
2204.71	81.4175
2209.59	80.8526
2214.46	80.1927
2219.33	79.8139
2224.2	78.3206
2229.07	78.1791
2233.93	80.4395
2238.79	80.7321
2243.64	80.1087
2248.49	76.1607
2253.34	77.6469
2258.18	79.882
2263.02	79.3954
2267.86	79.2984
2272.69	80.5489
2277.52	81.7422
2282.35	83.0808
2287.17	84.1267
2291.99	83.5117
2296.8	82.2691
2301.62	80.1231
2306.43	80.8207
2311.23	82.2457
2316.03	83.6867
2320.83	85.477
2325.63	86.7184
2330.42	88.9723
2335.21	89.2823
2339.99	85.3219
2344.77	82.2841
2349.55	78.6278
2354.32	76.0109
2359.1	77.8304
2363.86	81.3182
2368.63	83.9914
2373.39	84.1919
2378.15	82.7658
2382.9	81.4733
2387.65	79.1982
2392.4	78.6403
2397.14	80.7089
2401.88	80.3674
2406.62	80.4708
2411.35	81.4755
2416.08	81.4578
2420.81	82.2079
2425.53	81.7515
2430.25	83.4546
2434.97	81.2936
2439.69	79.1501
2444.4	79.6036
2449.1	82.8373
2453.81	81.6965
2458.51	77.9218
2463.2	81.7316
2467.9	80.007
2472.59	77.2629
2477.27	78.3558
2481.96	80.5219
2486.64	79.737
2491.31	83.4959
2495.99	86.314
2500.66	87.3101
2505.32	84.9661
2509.99	82.0778
2514.65	81.0783
2519.31	81.5579
2523.96	80.9489
2528.61	81.6709
2533.26	82.3022
2537.9	82.3408
2542.54	81.3736
2547.18	81.4055
2551.81	81.8955
2556.44	81.1934
2561.07	80.4969
2565.69	79.8249
2570.32	78.7859
2574.93	77.6471
2579.55	77.6367
2584.16	79.1115
2588.77	81.3462
2593.37	82.1852
2597.97	81.8314
2602.57	82.1158
2607.17	77.9155
2611.76	82.1507
2616.35	83.1774
2620.93	80.1663
2625.51	80.6108
2630.09	80.173
2634.67	80.4783
2639.24	81.074
2643.81	82.3163
2648.38	79.9316
2652.94	81.9491
2657.5	80.7294
2662.06	79.0866
2666.61	79.3942
2671.16	79.2136
2675.71	78.349
2680.25	77.78
2684.79	77.6586
2689.33	78.0699
2693.86	76.8684
2698.39	76.6379
2702.92	78.4143
2707.45	78.2388
2711.97	78.5759
2716.49	80.1702
2721	81.6131
2725.51	83.2129
2730.02	80.8538
2734.53	78.8199
2739.03	78.1981
2743.53	78.3576
2748.03	75.6564
2752.52	74.7447
2757.01	74.5722
2761.5	78.2794
2765.98	81.0033
2770.46	78.803
2774.94	77.1268
2779.42	73.9919
2783.89	75.2484
2788.36	78.3371
2792.82	79.3052
2797.28	77.7911
2801.74	76.983
2806.2	78.2726
2810.65	77.9626
2815.1	78.2331
2819.55	79.9048
2823.99	74.8295
2828.43	78.1727
2832.87	80.3332
2837.3	80.8993
2841.74	80.3637
2846.17	79.1216
2850.59	79.4716
2855.01	79.5354
2859.43	77.0945
2863.85	74.7145
2868.26	74.7373
2872.67	77.2253
2877.08	79.0248
2881.48	79.4935
2885.89	78.5546
2890.28	76.4647
2894.68	75.4756
2899.07	75.4218
2903.46	76.3635
2907.85	76.5682
2912.23	73.7171
2916.61	71.5554
2920.98	73.2159
2925.36	76.7743
2929.73	79.0216
2934.1	77.6914
2938.46	75.5813
2942.82	73.6049
2947.18	77.0831
2951.54	79.006
2955.89	76.7606
2960.24	77.2961
2964.59	77.8818
2968.93	76.6835
2973.27	75.1851
2977.61	73.2031
2981.95	73.4666
2986.28	72.8565
2990.61	72.7672
2994.94	73.4463
2999.26	74.5767
3003.58	75.2514
3007.9	74.5507
3012.21	72.1341
3016.52	75.5059
3020.83	75.2487
3025.14	73.9107
3029.44	73.0714
3033.74	74.3645
3038.04	74.9445
3042.33	75.1043
3046.62	75.0018
3050.91	75.8235
3055.2	76.6533
3059.48	74.1469
3063.76	73.263
3068.03	74.1642
3072.31	73.9294
3076.58	74.6109
3080.85	75.4732
3085.11	76.3822
3089.37	77.1078
3093.63	76.9412
3097.89	75.7238
3102.14	76.0846
3106.39	76.0509
3110.64	75.2469
3114.89	74.9043
3119.13	76.6127
3123.37	75.3161
3127.6	72.7734
3131.84	71.5006
3136.07	71.8647
3140.29	72.1343
3144.52	71.3344
3148.74	73.4159
3152.96	74.001
3157.18	75.4575
3161.39	75.3004
3165.6	73.4122
3169.81	76.2929
3174.01	75.7832
3178.22	69.4238
3182.42	75.7859
3186.61	77.2348
3190.8	75.5004
3195	76.0336
3199.18	77.4241
3203.37	77.0588
3207.55	72.1563
3211.73	72.1035
3215.91	77.801
3220.08	80.7857
3224.25	77.8334
3228.42	74.4018
3232.59	73.9823
3236.75	78.1225
3240.91	79.5659
3245.07	79.2372
3249.22	77.9337
3253.37	76.1658
3257.52	74.4278
3261.67	74.1659
3265.81	74.8653
3269.95	73.4322
3274.09	73.9639
3278.22	70.6123
3282.36	69.8173
3286.49	68.8702
3290.61	67.6027
3294.74	68.1169
3298.86	70.3983
3302.98	70.7236
3307.09	71.1644
3311.21	69.6165
3315.32	70.6545
3319.42	71.7802
3323.53	72.1367
3327.63	71.1166
3331.73	68.4223
3335.83	67.6777
3339.92	67.9315
3344.01	67.8729
3348.1	66.8403
3352.19	67.4659
3356.27	65.4305
3360.35	65.8828
3364.43	68.5384
3368.5	69.7449
3372.58	70.5449
3376.65	69.0363
3380.71	68.3525
3384.78	67.5279
3388.84	68.7341
3392.9	69.5902
3396.95	68.4056
3401.01	69.5989
3405.06	67.3668
3409.1	63.4767
3413.15	66.7903
3417.19	72.6186
3421.23	73.3109
3425.27	70.904
3429.31	68.1613
3433.34	67.6268
3437.37	68.1218
3441.39	69.6329
3445.42	69.0812
3449.44	65.2845
3453.46	64.9603
3457.47	64.9598
3461.49	63.4451
3465.5	64.5705
3469.51	65.9188
3473.51	66.4175
3477.52	66.7362
3481.52	66.9926
3485.51	65.9715
3489.51	63.61
3493.5	62.1972
3497.49	62.1179
3501.48	62.6467
3505.46	63.5558
3509.45	62.4991
3513.43	61.9067
3517.4	63.0109
3521.38	61.0804
3525.35	60.5367
3529.32	60.0676
3533.28	59.8232
3537.25	60.3196
3541.21	61.5927
3545.17	59.9233
3549.12	59.8347
3553.08	61.8682
3557.03	62.1594
3560.98	61.5797
3564.92	61.9409
3568.87	63.8128
3572.81	64.921
3576.74	65.5738
3580.68	68.7775
3584.61	68.9566
3588.54	69.4187
3592.47	69.7086
3596.4	69.4003
3600.32	67.6068
3604.24	61.695
3608.16	58.8378
3612.07	57.7254
3615.98	58.5507
3619.89	61.2927
3623.8	57.7123
3627.71	53.6064
3631.61	52.1512
3635.51	54.4997
3639.41	57.0904
3643.3	58.492
3647.19	58.3574
3651.08	58.4163
3654.97	55.7957
3658.85	55.2341
3662.74	57.6258
3666.62	58.059
3670.49	58.1026
3674.37	57.1606
3678.24	56.0752
3682.11	55.8625
3685.98	53.8272
3689.84	54.7222
3693.7	55.9349
3697.56	55.0176
3701.42	56.0965
3705.28	55.8117
3709.13	52.421
3712.98	52.698
3716.82	53.9784
3720.67	54.9891
3724.51	54.6925
3728.35	52.2765
3732.19	53.1662
3736.02	53.3864
3739.86	52.6769
3743.69	52.049
3747.51	53.2832
3751.34	52.769
3755.16	52.5406
3758.98	51.2872
3762.8	51.2389
3766.61	51.6757
3770.43	52.1516
3774.24	52.7253
3778.05	51.9833
3781.85	51.2738
3785.65	50.5478
3789.45	50.0192
3793.25	51.1468
3797.05	50.1186
3800.84	51.5914
3804.63	51.1945
3808.42	49.1345
3812.21	48.4388
3815.99	49.8127
3819.77	50.8016
3823.55	51.7194
3827.33	52.4324
3831.1	52.2308
3834.87	50.2166
3838.64	48.5392
3842.41	49.7059
3846.17	49.4469
3849.93	49.0565
3853.69	49.4616
3857.45	48.8274
3861.21	49.0533
3864.96	49.8809
3868.71	48.0721
3872.46	49.3075
3876.2	50.743
3879.94	51.4702
3883.68	51.5099
3887.42	50.5374
3891.16	50.5529
3894.89	49.2312
3898.62	49.3012
3902.35	50.0399
3906.08	49.2713
3909.8	48.3866
3913.52	48.6922
3917.24	49.9095
3920.96	49.1551
3924.67	47.551
3928.38	47.5179
3932.09	48.4077
3935.8	49.3002
3939.51	49.474
3943.21	49.4309
3946.91	47.6506
3950.61	45.7334
3954.3	45.1852
3958	48.0921
3961.69	46.8092
3965.38	43.9686
3969.06	41.8744
3972.75	45.6866
3976.43	48.6945
3980.11	49.3038
3983.78	44.6912
3987.46	45.9774
3991.13	44.6226
3994.8	46.9911
3998.47	43.8904