File: Data/3-Raman/raw/20-C_brt1_FI01_150.txt
#Acq. time (s)=	15
#Accumulations=	2
#Range (cm-¹)=	50...5000
#Windows=	2
#Auto scanning=	Off
#Autofocus=	Off
#Macrospot=	Off
#AutoExposure=	Off
#Spike filter=	Multiple accum.
#Delay time (s)=	0
#Binning=	1
#Readout mode=	Signal
#DeNoise=	Lite
#ICS correction=	Off
#Dark correction=	Off
#Inst. Process=	Off
#Detector temperature (°C)=	-60.09
#Instrument=	LabRAM HR Evol
#Detector=	SIN-EM FIVIS
#Objective=	x50_VIS_LWD
#Grating=	150 (500nm)
#ND Filter=	100%
#Laser=	633nm_Edge
#Hole=	30.0125
#Temperature=	0
#Range=	Visible
#StageXY=	75x50mm Scan+
#StageZ=	Z motor
#X (µm)=	7344.5
#Y (µm)=	4274.6
#Z (µm)=	-23.7
#Full time(mm:ss)=	1:37
#Project=	Buranga
#Sample=	BU18FA20_C
#Site=	C_Bertoss1
#Title=	20-C_brt1_FI01_150
#Remark=
#Date=	30.07.2019 14:13
#Acquired=	30.07.2019 14:13:00
53.2466	2609
59.8037	3600.33
66.3553	2828.03
72.903	2149.76
79.4437	1620.6
85.979	1226
92.5088	938.973
99.0332	741.476
105.552	623.691
112.066	529.241
118.574	445.192
125.077	380.774
131.574	349.139
138.066	324.936
144.551	304.088
151.033	287.894
157.509	272.004
163.979	283.935
170.444	272.708
176.904	254.291
183.357	245.569
189.806	247.961
196.25	254.079
202.689	259.88
209.121	252.609
215.549	250.659
221.971	253.854
228.387	263.468
234.799	278.125
241.206	291.907
247.606	284.063
254.002	266.995
260.392	269.742
266.778	280.889
273.157	291.445
279.532	293.316
285.9	301.544
292.265	304.341
298.623	301.303
304.978	293.341
311.325	287.682
317.669	290.984
324.007	302.023
330.339	328.692
336.667	328.713
342.989	311.533
349.306	305.193
355.617	303.883
361.925	308.234
368.226	306.118
374.522	300.892
380.813	299.234
387.099	302.873
393.381	298.85
399.656	306.485
405.927	318.561
412.192	323.263
418.452	314.795
424.707	309.385
430.957	314.029
437.202	329.665
443.442	336.538
449.677	335.077
455.907	346.602
462.131	350.783
468.351	343.099
474.566	328.51
480.774	320.716
486.978	321.313
493.178	323.953
499.372	327.322
505.562	333
511.745	336.48
517.924	334.743
524.099	326.814
530.268	323.026
536.431	322.39
542.591	321.788
548.746	321.423
554.894	321.594
561.038	322.642
567.177	327.001
573.312	325.998
579.44	323.656
585.565	324.879
591.685	329.567
597.799	343.226
603.907	357.582
610.012	361.4
616.111	359.329
622.207	353.863
628.296	348.604
634.38	345.88
640.461	345.343
646.536	345.728
652.605	345.928
658.671	346.77
664.731	346.647
670.786	344.382
676.837	340.374
682.882	337.709
688.924	336.644
694.96	332.989
700.991	328.181
707.017	323.859
713.038	320.919
719.055	318.981
725.066	317.146
731.073	314.907
737.075	312.502
743.073	311.157
749.065	310.874
755.053	308.509
761.036	323.365
767.014	316.346
772.988	310.719
778.957	308.107
784.919	309.924
790.879	318.361
796.833	317.176
802.783	315.843
808.727	316.667
814.668	322.559
820.603	325.566
826.534	323.867
832.459	318.134
838.381	308.248
844.298	304.552
850.209	307.082
856.117	309.625
862.018	310.921
867.917	309.689
873.809	307.739
879.698	306.139
885.581	305.996
891.461	306.008
897.334	305.375
903.203	305.779
909.069	305.029
914.929	301.836
920.786	293.347
926.636	290.2
932.482	299.21
938.324	306.246
944.162	310.308
949.995	310.333
955.822	310.917
961.645	313.665
967.464	318.058
973.279	323.232
979.089	334.203
984.894	351.863
990.694	385.034
996.49	377.641
1002.28	353.499
1008.07	340.399
1013.85	339.008
1019.63	346.759
1025.4	350.666
1031.17	348.064
1036.93	335.039
1042.69	319.401
1048.45	299.665
1054.2	286.364
1059.94	282.035
1065.69	286.664
1071.42	287.59
1077.16	282.25
1082.88	279.205
1088.61	281.695
1094.33	290.095
1100.04	299.299
1105.75	304.958
1111.46	294.298
1117.16	280.036
1122.85	271.988
1128.55	271.173
1134.23	272.753
1139.92	275.317
1145.6	277.613
1151.27	278.4
1156.94	276.678
1162.61	272.983
1168.27	267.853
1173.92	263.361
1179.58	260.284
1185.23	258.852
1190.87	257.999
1196.51	257.068
1202.14	257.462
1207.77	255.631
1213.4	249.82
1219.02	247.224
1224.64	246.904
1230.25	246.849
1235.86	242.306
1241.47	234.687
1247.07	237.475
1252.66	246.142
1258.25	254.808
1263.84	262.853
1269.42	267.878
1275	274.699
1280.58	475
1286.15	459
1291.71	253
1297.27	239
1302.83	267
1308.38	225.296
1313.93	234.306
1319.47	244.19
1325.01	238.578
1330.55	231.127
1336.08	234.756
1341.61	236.743
1347.13	232.634
1352.65	230.314
1358.16	231.237
1363.67	236.786
1369.18	253.305
1374.68	240.913
1380.18	255.062
1385.67	845
1391.16	381
1396.65	229.27
1402.13	248.371
1407.6	267.088
1413.07	247.427
1418.54	222.591
1424.01	211.041
1429.47	208.226
1434.92	212.253
1440.37	214.347
1445.82	211.275
1451.26	204.75
1456.7	200.363
1462.14	203.026
1467.57	204.313
1472.99	202.191
1478.42	201.164
1483.83	204.008
1489.25	208.307
1494.66	210.337
1500.06	209.98
1505.46	207.47
1510.86	202.325
1516.26	196.696
1521.64	192.678
1527.03	193.609
1532.41	194.067
1537.79	190.442
1543.16	190.886
1548.53	194.163
1553.89	202.97
1559.25	199.565
1564.61	189.936
1569.96	185.874
1575.31	188.37
1580.66	192.367
1586	190.43
1591.33	188.734
1596.67	186.076
1601.99	187.598
1607.32	190.047
1612.64	188.74
1617.96	185.581
1623.27	182.268
1628.58	179.903
1633.88	177.223
1639.18	176.743
1644.48	182.817
1649.77	184.778
1655.06	177.281
1660.34	172.547
1665.62	175.419
1670.9	183.297
1676.17	192.522
1681.44	194.998
1686.7	192.398
1691.96	183.989
1697.22	178.29
1702.47	175.01
1707.72	175.265
1712.97	178.564
1718.21	178.737
1723.45	176.512
1728.68	174.553
1733.91	179.196
1739.13	184.571
1744.35	183.668
1749.57	175.339
1754.78	171.516
1759.99	173.196
1765.2	173.731
1770.4	172.672
1775.6	171.264
1780.79	170.128
1785.98	171.821
1791.17	168.742
1796.35	166.242
1801.53	165.221
1806.71	165.709
1811.88	166.899
1817.04	166.989
1822.21	163.95
1827.37	167.259
1832.52	169.607
1837.67	170.278
1842.82	169.257
1847.96	167.11
1853.1	164.455
1858.24	160.839
1863.37	157.574
1868.5	158.53
1873.63	160.584
1878.75	162.561
1883.86	164.809
1888.98	161.295
1894.09	157.615
1899.19	153.881
1904.3	156.245
1909.39	158.079
1914.49	158.411
1919.58	156.486
1924.67	154.897
1929.75	153.946
1934.83	152.913
1939.91	152.42
1944.98	153.095
1950.05	154.411
1955.11	156.226
1960.17	154.081
1965.23	147.722
1970.28	149.996
1975.33	154.192
1980.38	158.427
1985.42	156.023
1990.46	151.717
1995.49	150.51
2000.53	152.91
2005.55	157.621
2010.58	159.804
2015.6	159.29
2020.61	155.682
2025.63	149.601
2030.63	148.446
2035.64	149.17
2040.64	149.893
2045.64	150.655
2050.63	152.481
2055.63	156.957
2060.61	154.226
2065.6	147.787
2070.57	140.444
2075.55	141.771
2080.52	148.179
2085.49	150.681
2090.46	150.225
2095.42	147.861
2100.38	144.574
2105.33	141.803
2110.28	140.338
2115.23	140.251
2120.17	140.236
2125.11	140.101
2130.05	139.775
2134.98	139.216
2139.91	138.344
2144.84	137.221
2149.76	139.612
2154.68	139.304
2159.59	136.934
2164.5	135.617
2169.41	136.904
2174.32	138.249
2179.22	138.916
2184.11	138.896
2189.01	137.845
2193.9	136.268
2198.78	134.656
2203.67	133.772
2208.55	133.861
2213.42	135.669
2218.29	139.167
2223.16	137.405
2228.03	133.797
2232.89	132.123
2237.75	131.899
2242.6	132.12
2247.45	133.224
2252.3	134.119
2257.15	133.961
2261.99	131.054
2266.82	129.235
2271.66	131.042
2276.49	132.193
2281.32	131.596
2286.14	128.813
2290.96	124.555
2295.78	128.999
2300.59	136.577
2305.4	131.786
2310.2	128.859
2315.01	128.628
2319.81	131.669
2324.6	138.65
2329.39	142.157
2334.18	128.797
2338.97	119.501
2343.75	125.361
2348.53	129.643
2353.3	130.882
2358.07	129.488
2362.84	126.154
2367.61	128.322
2372.37	128.579
2377.13	125.56
2381.88	121.901
2386.63	122.108
2391.38	121.198
2396.13	118.786
2400.87	118.125
2405.61	119.758
2410.34	121.589
2415.07	122
2419.8	122.251
2424.52	122.673
2429.24	122.629
2433.96	120.6
2438.68	117.529
2443.39	116.208
2448.09	118.217
2452.8	122.385
2457.5	125.29
2462.19	125.059
2466.89	121.286
2471.58	113.777
2476.27	115.766
2480.95	115.168
2485.63	112.955
2490.31	113.497
2494.98	114.736
2499.65	116.897
2504.32	119.643
2508.99	121.659
2513.65	106.632
2518.3	107.73
2522.96	110.936
2527.61	113.11
2532.26	117.546
2536.9	121.731
2541.54	108.847
2546.18	107.776
2550.82	107.367
2555.45	107.355
2560.08	107.983
2564.7	109.222
2569.32	110.354
2573.94	110.272
2578.55	113.151
2583.17	110.287
2587.78	104.803
2592.38	105.669
2596.98	111.162
2601.58	115.724
2606.18	112.362
2610.77	103.674
2615.36	106.658
2619.94	110.099
2624.53	110.307
2629.11	106.154
2633.68	105.156
2638.26	107.598
2642.83	109.556
2647.39	109.209
2651.96	109.045
2656.52	106.737
2661.07	103.674
2665.63	102.652
2670.18	104.778
2674.73	106.488
2679.27	107.359
2683.81	107.628
2688.35	106.561
2692.88	102.078
2697.41	95.8188
2701.94	95.5261
2706.47	96.7797
2710.99	98.7793
2715.51	101.721
2720.03	103.244
2724.54	101.898
2729.05	97.3048
2733.55	95.9377
2738.06	100.676
2742.56	105.55
2747.06	100.04
2751.55	96.4257
2756.04	94.3478
2760.53	97.4932
2765.01	96.5719
2769.49	94.3562
2773.97	94.8964
2778.45	96.1576
2782.92	96.8683
2787.39	94.3877
2791.85	94.3065
2796.32	98.4633
2800.78	102.763
2805.23	101.213
2809.69	95.9793
2814.14	94.2341
2818.59	97.7712
2823.03	99.0008
2827.47	97.2762
2831.91	95.0416
2836.34	96.8922
2840.78	98.4608
2845.21	98.6489
2849.63	97.71
2854.05	94.3719
2858.47	90.1492
2862.89	88.5593
2867.3	89.2767
2871.72	92.3615
2876.12	94.5477
2880.53	95.0507
2884.93	94.7939
2889.33	94.2353
2893.72	92.7555
2898.12	92.901
2902.51	94.4913
2906.89	93.1487
2911.28	92.5637
2915.66	88.4057
2920.03	88.855
2924.41	92.3782
2928.78	90.757
2933.15	87.2013
2937.51	86.5276
2941.88	88.0002
2946.24	89.4215
2950.59	90.0753
2954.95	90.5608
2959.3	90.874
2963.64	90.96
2967.99	90.5724
2972.33	89.3196
2976.67	91.4699
2981	93.3354
2985.34	92.9288
2989.67	90.7056
2993.99	86.1401
2998.32	86.8487
3002.64	88.8945
3006.96	90.749
3011.27	87.7117
3015.58	81.3372
3019.89	79.3337
3024.2	83.0606
3028.5	90.3677
3032.8	93.3996
3037.1	90.1593
3041.4	84.7344
3045.69	82.2384
3049.98	82.1406
3054.26	83.5889
3058.54	83.8819
3062.82	82.9113
3067.1	83.3051
3071.38	85.5218
3075.65	87.1284
3079.91	87.6679
3084.18	87.1497
3088.44	85.6246
3092.7	83.6795
3096.96	80.9838
3101.21	82.2553
3105.47	84.2912
3109.71	85.1531
3113.96	85.5363
3118.2	85.3081
3122.44	86.0917
3126.68	88.4491
3130.91	72.5298
3135.14	76.8344
3139.37	82.5732
3143.6	84.8371
3147.82	84.7809
3152.04	86.7824
3156.25	88.7005
3160.47	81.242
3164.68	79.3766
3168.89	80.4992
3173.09	81.2733
3177.3	80.759
3181.49	82.0713
3185.69	84.2427
3189.89	85.2011
3194.08	85.604
3198.27	82.3495
3202.45	79.6687
3206.63	79.0234
3210.81	80.2224
3214.99	81.869
3219.17	85.2277
3223.34	80.1283
3227.51	74.5889
3231.67	73.1671
3235.84	75.096
3240	78.6562
3244.15	80.4713
3248.31	79.6717
3252.46	75.9468
3256.61	74.0614
3260.76	75.7359
3264.9	73.6323
3269.04	72.35
3273.18	73.0034
3277.32	73.7883
3281.45	74.3672
3285.58	73.1117
3289.71	73.7565
3293.83	75.9858
3297.95	77.8213
3302.07	79.5771
3306.19	76.5265
3310.3	71.9803
3314.41	70.4704
3318.52	72.1823
3322.63	76.4726
3326.73	75.7197
3330.83	72.7958
3334.92	72.425
3339.02	71.7529
3343.11	72.9882
3347.2	74.3636
3351.29	72.3216
3355.37	70.1007
3359.45	69.8899
3363.53	71.0133
3367.6	72.4411
3371.68	72.4796
3375.75	72.3814
3379.81	72.8756
3383.88	74.2024
3387.94	74.7799
3392	74.6653
3396.06	74.1606
3400.11	72.8157
3404.16	72.8181
3408.21	69.1842
3412.26	66.3375
3416.3	71.2101
3420.34	70.4502
3424.38	70.493
3428.41	71.4261
3432.45	72.6486
3436.48	72.8221
3440.5	72.4396
3444.53	72.5032
3448.55	71.737
3452.57	69.2189
3456.59	69.3429
3460.6	68.496
3464.61	73.7746
3468.62	69.4496
3472.63	66.4147
3476.63	65.1064
3480.63	64.4745
3484.63	64.0758
3488.62	64.1691
3492.62	64.8421
3496.61	66.2109
3500.6	67.7716
3504.58	69.6379
3508.56	68.2671
3512.54	64.9397
3516.52	64.1152
3520.49	66.1218
3524.47	69.6537
3528.44	69.3464
3532.4	68.3939
3536.37	66.2766
3540.33	64.7058
3544.29	62.7514
3548.25	61.4885
3552.2	62.5703
3556.15	64.9306
3560.1	67.8247
3564.05	67.8189
3567.99	65.4009
3571.93	64.1361
3575.87	64.7638
3579.8	66.0606
3583.74	66.7259
3587.67	67.0381
3591.6	66.7655
3595.52	65.2059
3599.45	64.0269
3603.37	63.0793
3607.28	61.3202
3611.2	61.709
3615.11	62.9066
3619.02	63.7418
3622.93	64.217
3626.84	63.7819
3630.74	62.9377
3634.64	63.3602
3638.54	63.7161
3642.43	61.2708
3646.33	60.9152
3650.22	63.0809
3654.1	61.2546
3657.99	60.1208
3661.87	60.4697
3665.75	59.9081
3669.63	57.2222
3673.5	64.2778
3677.38	64.4705
3681.25	57.2127
3685.11	55.0637
3688.98	56.3524
3692.84	56.8404
3696.7	58.075
3700.56	55.6916
3704.41	55.0885
3708.27	56.6682
3712.12	58.8399
3715.96	60.0521
3719.81	59.2857
3723.65	60.1286
3727.49	60.2085
3731.33	57.9496
3735.17	56.7035
3739	56.3159
3742.83	55.7321
3746.66	56.267
3750.48	55.8459
3754.31	54.9816
3758.13	54.1647
3761.94	54.6354
3765.76	56.1365
3769.57	57.0646
3773.38	57.7904
3777.19	57.7343
3781	57.6107
3784.8	57.7113
3788.6	57.2148
3792.4	56.2811
3796.2	55.4624
3799.99	55.1796
3803.78	55.3108
3807.57	55.7533
3811.36	56.6873
3815.14	55.6778
3818.92	55.0881
3822.7	54.6847
3826.48	54.4138
3830.25	55.6297
3834.03	54.5848
3837.79	51.8601
3841.56	51.641
3845.33	53.7505
3849.09	54.5434
3852.85	52.7901
3856.61	51.2343
3860.36	50.8484
3864.11	51.3497
3867.86	51.2865
3871.61	51.6869
3875.36	52.439
3879.1	52.513
3882.84	52.1291
3886.58	52.539
3890.32	51.1492
3894.05	50.4507
3897.78	52.1836
3901.51	52.8069
3905.24	52.2384
3908.96	50.5675
3912.68	49.3652
3916.4	49.3052
3920.12	49.7995
3923.83	50.969
3927.55	49.56
3931.26	50.1371
3934.97	51.4896
3938.67	51.4099
3942.37	49.6954
3946.07	47.8378
3949.77	46.6255
3953.47	47.4371
3957.16	48.8705
3960.85	47.9775
3964.54	48.527
3968.23	49.2025
3971.91	46.914
3975.6	48.5752
3979.28	48.944
3981.24	49.1628
3984.92	49.3807
3988.6	49.0815
3992.29	47.7675
3995.96	47.685
3999.64	47.2807
4003.32	48.2856
4006.99	49.5494
4010.66	49.3454
4014.32	46.285
4017.99	44.6463
4021.65	45.0091
4025.31	43.7281
4028.97	47.8397
4032.62	47.6231
4036.28	45.399
4039.93	46.0779
4043.58	48.9658
4047.22	49.6439
4050.87	47.687
4054.51	45.978
4058.15	45.7265
4061.79	46.1563
4065.42	47.2106
4069.06	48.1262
4072.69	48.4611
4076.31	48.2292
4079.94	46.587
4083.56	46.9883
4087.19	46.7659
4090.81	47.7509
4094.42	47.5903
4098.04	47.7531
4101.65	47.4495
4105.26	45.9302
4108.87	47.3219
4112.47	43.8726
4116.08	41.3119
4119.68	45.2784
4123.28	47.8563
4126.88	47.5156
4130.47	47.3569
4134.06	43.6316
4137.65	37.9206
4141.24	43.6263
4144.83	43.6877
4148.41	45.6366
4151.99	46.0714
4155.57	44.9892
4159.15	46.5699
4162.72	46.1268
4166.29	45.0189
4169.86	44.1386
4173.43	43.3691
4177	43.745
4180.56	43.7586
4184.12	43.1138
4187.68	42.4792
4191.24	41.1016
4194.79	41.2002
4198.35	42.6861
4201.9	42.614
4205.44	42.5482
4208.99	44.1361
4212.53	44.9862
4216.08	43.82
4219.62	42.693
4223.15	42.1658
4226.69	41.6047
4230.22	41.2006
4233.75	42.0515
4237.28	42.2824
4240.81	43.245
4244.33	41.421
4247.85	38.2284
4251.37	38.8775
4254.89	40.1772
4258.41	41.5926
4261.92	43.076
4265.43	43.9887
4268.94	42.4527
4272.45	41.4262
4275.95	39.9482
4279.45	42.07
4282.95	40.9132
4286.45	40.3474
4289.95	40.6098
4293.44	42.1377
4296.93	43.2046
4300.42	42.2903
4303.91	42.7154
4307.4	42.0078
4310.88	40.1128
4314.36	41.1116
4317.84	41.4368
4321.32	42.1176
4324.79	42.3498
4328.27	41.2036
4331.74	40.6777
4335.2	39.9938
4338.67	39.5767
4342.14	39.5773
4345.6	41.3804
4349.06	42.0601
4352.52	38.6703
4355.97	36.587
4359.42	37.959
4362.88	38.7268
4366.33	38.4447
4369.77	36.4627
4373.22	37.287
4376.66	38.8334
4380.1	38.6635
4383.54	37.6044
4386.98	36.9505
4390.41	36.7802
4393.85	37.1962
4397.28	37.9786
4400.71	38.9711
4404.13	39.2846
4407.56	37.678
4410.98	37.6945
4414.4	41.8858
4417.82	40.6123
4421.23	41.3398
4424.65	41.5875
4428.06	39.8035
4431.47	37.6584
4434.88	36.4562
4438.28	37.1745
4441.69	38.089
4445.09	37.5565
4448.49	36.8166
4451.89	37.7285
4455.28	38.7993
4458.68	38.2779
4462.07	39.3298
4465.46	38.4895
4468.84	37.543
4472.23	36.773
4475.61	36.0703
4478.99	35.628
4482.37	37.6836
4485.75	38.1605
4489.12	39.7605
4492.5	38.6512
4495.87	37.914
4499.24	36.8341
4502.6	36.0051
4505.97	35.7041
4509.33	35.8276
4512.69	36.3629
4516.05	35.5048
4519.41	33.7145
4522.76	32.5458
4526.12	35.1022
4529.47	35.8504
4532.82	36.0136
4536.16	35.5737
4539.51	34.5157
4542.85	33.4916
4546.19	35.2101
4549.53	37.0707
4552.87	35.5718
4556.2	33.9655
4559.54	33.0306
4562.87	33.7223
4566.2	35.3895
4569.52	35.7088
4572.85	36.5476
4576.17	37.2129
4579.49	34.7683
4582.81	34.2334
4586.13	34.2857
4589.44	34.5256
4592.75	32.7394
4596.06	36.0919
4599.37	36.0262
4602.68	35.1515
4605.99	33.5506
4609.29	31.8098
4612.59	30.4954
4615.89	31.4171
4619.19	34.4014
4622.48	35.2624
4625.77	32.8337
4629.07	31.3756
4632.36	33.5794
4635.64	33.7741
4638.93	33.7862
4642.21	32.4087
4645.49	31.0252
4648.77	32.6018
4652.05	34.3879
4655.33	33.8193
4658.6	34.0889
4661.87	33.7654
4665.14	32.2645
4668.41	32.0076
4671.68	32.3711
4674.94	32.8624
4678.2	33.4139
4681.46	33.8023
4684.72	33.9848
4687.98	32.177
4691.23	31.6034
4694.48	32.8479
4697.73	31.7605
4700.98	31.5915
4704.23	32.1771
4707.47	33.1453
4710.72	33.0124
4713.96	32.1518
4717.2	32.028
4720.43	31.1055
4723.67	29.0961
4726.9	30.4401
4730.13	32.5071
4733.36	32.73
4736.59	32.2935
4739.82	32.2802
4743.04	33.1306
4746.26	33.0333
4749.48	32.2146
4752.7	31.1903
4755.92	30.5316
4759.13	31.4107
4762.34	31.9386
4765.55	32.0263
4768.76	31.7496
4771.97	28.0836
4775.17	29.1108
4778.38	32.1713
4781.58	33.4424
4784.78	31.0139
4787.97	27.4387
4791.17	28.5395
4794.36	30.52
4797.56	30.9524
4800.75	31.4072
4803.93	32.3539
4807.12	32.9542
4810.3	32.5074
4813.49	30.5282
4816.67	30.4203
4819.85	31.8045
4823.02	31.5103
4826.2	30.095
4829.37	29.0327
4832.54	29.3891
4835.71	30.0573
4838.88	30.6493
4842.04	30.3724
4845.21	29.7059
4848.37	27.1133
4851.53	27.0203
4854.69	27.8187
4857.84	29.135
4861	30.8656
4864.15	30.5534
4867.3	28.4347
4870.45	29.6869
4873.6	29.5771
4876.74	28.2866
4879.89	26.8797
4883.03	26.8254
4886.17	27.0968
4889.31	28.676
4892.44	28.3602
4895.58	27.7073
4898.71	27.3043
4901.84	27.1889
4904.97	27.6184
4908.1	28.7444
4911.22	29.9821
4914.35	28.8331
4917.47	28.2068
4920.59	29.0703
4923.71	28.5862
4926.82	26.1303
4929.94	26.375
4933.05	28.8697
4936.16	27.986
4939.27	26.7924
4942.38	27.1051
4945.48	28.7188
4948.59	29.9686
4951.69	30.8616
4954.79	30.4062
4957.89	29.4771
4960.98	24.9172
4964.08	27.3882
4967.17	25.9306
4970.26	25.704
4973.35	26.6813
4976.44	26.5077
4979.53	25.9221
4982.61	26.8426
4985.69	28.4861
4988.77	28.4116
4991.85	26.5295
4994.93	25.5225
4998.01	26.2415
4999.54	28.9376