File: Data/3-Raman/raw/20-C_brt2_FI03.txt
#Acq. time (s)=	20
#Accumulations=	3
#Range (cm-¹)=	100...4000
#Windows=	1
#Auto scanning=	Off
#Autofocus=	Off
#Macrospot=	Off
#AutoExposure=	Off
#Spike filter=	Multiple accum.
#Delay time (s)=	0
#Binning=	1
#Readout mode=	Signal
#DeNoise=	Lite
#ICS correction=	On
#Dark correction=	Off
#Inst. Process=	Off
#Detector temperature (°C)=	-60.09
#Instrument=	LabRAM HR Evol
#Detector=	SIN-EM FIVIS
#Objective=	x100_VIS
#Grating=	150 (500nm)
#ND Filter=	100%
#Laser=	633nm_Edge
#Hole=	30.0125
#Temperature=	0
#Range=	Visible
#StageXY=	75x50mm Scan+
#StageZ=	Z motor
#X (µm)=	8832.1
#Y (µm)=	4492.9
#Z (µm)=	1847.2
#Full time(mm:ss)=	1:03
#Project=	Buranga
#Sample=	BU18FA20_C
#Site=	C_Bertoss2
#Title=	20-C_brt2_FI03
#Remark=
#Date=	30.07.2019 15:31
#Acquired=	30.07.2019 15:31:25
100.38	116.229
106.898	93.0279
113.411	86.2614
119.918	80.1586
126.419	74.7669
132.916	71.4001
139.407	70.2638
145.892	67.8418
152.372	65.7341
158.847	64.4855
165.316	63.7116
171.781	62.0891
178.239	59.6736
184.693	56.9278
191.139	55.2952
197.582	54.8868
204.02	55.3998
210.452	52.8563
216.877	49.0194
223.299	48.1469
229.715	50.8767
236.126	62.2678
242.53	68.1362
248.931	62.8965
255.326	58.2293
261.714	55.0225
268.099	54.269
274.477	56.2564
280.851	63.9407
287.218	67.4902
293.582	66.5442
299.939	58.223
306.293	52.8557
312.639	50.5356
318.982	54.6172
325.318	62.8179
331.651	71.8448
337.977	66.8044
344.297	56.2948
350.614	50.3049
356.925	50.4072
363.23	54.239
369.53	57.5558
375.827	54.404
382.116	51.2111
388.401	47.4385
394.681	46.4252
400.956	45.9913
407.226	46.2374
413.49	47.2057
419.749	48.8548
426.003	51.575
432.252	56.0822
438.496	65.3231
444.735	65.5098
450.969	63.3009
457.197	60.3685
463.421	57.1189
469.64	54.4724
475.853	51.5942
482.062	48.1219
488.265	47.2985
494.464	47.5263
500.657	48.1167
506.844	48.2413
513.028	48.7761
519.206	50.0653
525.38	50.5589
531.548	49.2119
537.71	47.8405
543.869	46.7442
550.022	45.9431
556.169	47.0706
562.313	48.2114
568.452	47.3133
574.584	46.4579
580.713	47.0662
586.837	47.5411
592.954	51.3079
599.068	57.2918
605.176	62.6765
611.28	61.5974
617.378	58.0815
623.473	56.636
629.561	57.1245
635.644	57.7191
641.724	56.1691
647.797	53.8646
653.867	56.5686
659.931	61.5504
665.99	60.2006
672.044	55.1511
678.095	48.9294
684.139	45.8963
690.179	44.5358
696.213	43.598
702.245	42.3109
708.27	41.7505
714.29	41.9331
720.306	42.1351
726.316	43.0986
732.322	42.8216
738.323	42.6403
744.32	42.9724
750.311	42.5889
756.298	43.2132
762.28	43.744
768.258	42.5168
774.23	42.4406
780.198	42.7124
786.161	42.2963
792.119	41.854
798.073	41.8586
804.021	42.1178
809.965	42.4169
815.904	42.8283
821.839	42.8975
827.769	42.1423
833.693	41.1739
839.614	40.8116
845.53	41.1937
851.44	41.9118
857.346	42.2808
863.248	41.3914
869.144	41.2253
875.037	42.4931
880.924	42.2864
886.807	41.8528
892.685	42.6418
898.559	41.0641
904.427	40.6174
910.292	41.3838
916.151	42.191
922.006	41.4874
927.856	41.3039
933.701	43.9428
939.543	45.3622
945.379	46.4494
951.21	48.5747
957.037	52.4704
962.861	55.7316
968.678	58.3186
974.491	61.9606
980.3	69.0226
986.104	80.7281
991.904	97.5113
997.699	91.7528
1003.49	82.5286
1009.28	77.4088
1015.06	76.5442
1020.83	82.0202
1026.61	87.8483
1032.37	81.9361
1038.14	71.7019
1043.9	59.7197
1049.65	52.9823
1055.4	49.6469
1061.15	50.4505
1066.88	48.6686
1072.62	45.0312
1078.35	47.2862
1084.08	50.2037
1089.8	53.2785
1095.52	56.214
1101.23	58.7481
1106.94	57.3688
1112.65	51.3894
1118.35	45.757
1124.05	43.667
1129.74	43.2049
1135.42	43.3305
1141.11	44.8848
1146.78	48.717
1152.46	51.9749
1158.13	50.1109
1163.79	46.728
1169.45	44.2909
1175.11	42.7723
1180.76	41.5892
1186.41	39.6144
1192.05	38.2356
1197.69	38.0412
1203.32	37.6843
1208.95	37.9353
1214.58	39.0074
1220.2	40.0419
1225.82	40.2795
1231.43	39.5994
1237.04	38.4643
1242.64	37.3342
1248.24	37.1645
1253.83	38.5082
1259.42	39.8383
1265.01	41.1775
1270.59	41.5722
1276.17	42.5683
1281.74	48.9485
1287.31	53.9864
1292.88	42.5598
1298.44	40.3394
1303.99	39.2885
1309.55	39.7862
1315.09	40.638
1320.64	40.7484
1326.18	40.5636
1331.71	39.5537
1337.24	38.7134
1342.77	38.826
1348.29	38.491
1353.81	38.4412
1359.32	39.1414
1364.83	39.9633
1370.33	40.2988
1375.84	41.3101
1381.33	44.9888
1386.82	73.9325
1392.31	46.2208
1397.8	41.292
1403.28	41.0027
1408.75	40.22
1414.22	38.8223
1419.69	38.2107
1425.15	37.4952
1430.61	36.9833
1436.07	38.3471
1441.52	39.127
1446.96	38.9955
1452.41	37.3581
1457.84	36.2945
1463.28	38.6085
1468.71	39.3848
1474.13	39.356
1479.55	36.3301
1484.97	37.5666
1490.39	38.5611
1495.79	38.5262
1501.2	38.8714
1506.6	38.9925
1512	38.9554
1517.39	38.6537
1522.78	37.9135
1528.16	38.3009
1533.54	39.3939
1538.92	40.5795
1544.29	40.2106
1549.66	41.0426
1555.02	42.2197
1560.38	39.9049
1565.74	38.8558
1571.09	37.8831
1576.44	39.0695
1581.78	38.6347
1587.12	39.0737
1592.46	39.2411
1597.79	39.1178
1603.12	39.0725
1608.44	40.2588
1613.76	41.6022
1619.08	42.059
1624.39	41.4036
1629.7	40.3195
1635	39.9737
1640.3	40.6099
1645.59	41.5452
1650.88	43.082
1656.17	42.0151
1661.46	41.8354
1666.74	42.0412
1672.01	42.7271
1677.28	42.3702
1682.55	41.5891
1687.82	40.4501
1693.07	40.5806
1698.33	41.3014
1703.58	42.4724
1708.83	41.8204
1714.07	40.7552
1719.31	41.0621
1724.55	38.3289
1729.78	41.637
1735.01	40.9013
1740.23	40.915
1745.46	41.1751
1750.67	40.7586
1755.89	40.4121
1761.09	40.0831
1766.3	40.792
1771.5	41.4074
1776.7	42.2511
1781.89	43.1035
1787.08	42.4297
1792.27	41.423
1797.45	41.2672
1802.62	39.9678
1807.8	40.717
1812.97	41.8409
1818.14	42.3145
1823.3	43.33
1828.46	40.5508
1833.61	41.0924
1838.76	43.1774
1843.91	44.8563
1849.05	43.7515
1854.19	42.0582
1859.33	41.696
1864.46	42.1461
1869.59	42.9509
1874.71	43.0193
1879.83	43.7509
1884.95	42.3339
1890.06	41.6859
1895.17	41.4914
1900.27	44.7587
1905.38	44.2293
1910.47	43.5708
1915.57	43.7854
1920.66	44.6932
1925.74	44.705
1930.83	43.0468
1935.91	42.718
1940.98	43.8605
1946.05	43.8863
1951.12	44.2875
1956.18	44.8736
1961.25	44.4265
1966.3	43.7118
1971.35	42.7572
1976.4	44.3998
1981.45	44.8633
1986.49	46.3119
1991.53	46.1246
1996.56	45.0408
2001.59	44.5663
2006.62	43.5684
2011.64	44.221
2016.66	44.6728
2021.68	45.467
2026.69	46.0047
2031.7	45.2274
2036.7	45.2588
2041.7	45.1638
2046.7	45.3862
2051.7	45.6829
2056.69	45.7118
2061.67	47.0632
2066.65	47.7713
2071.63	48.3633
2076.61	48.9904
2081.58	49.2232
2086.55	48.1589
2091.51	47.6162
2096.47	47.9861
2101.43	48.9904
2106.39	48.9272
2111.34	48.3305
2116.28	47.974
2121.23	48.1
2126.17	47.5921
2131.1	48.3112
2136.03	48.2664
2140.96	47.2834
2145.89	47.1587
2150.81	48.8276
2155.73	47.0409
2160.64	47.5746
2165.55	48.2468
2170.46	49.4701
2175.36	48.6096
2180.26	50.2382
2185.16	50.194
2190.05	50.2052
2194.94	50.2786
2199.83	50.0091
2204.71	49.8054
2209.59	50.364
2214.46	50.9427
2219.33	47.908
2224.2	47.2651
2229.07	48.5084
2233.93	50.2743
2238.79	50.6209
2243.64	48.2767
2248.49	52.3677
2253.34	52.6923
2258.18	47.2754
2263.02	49.6036
2267.86	50.8328
2272.69	50.882
2277.52	49.7998
2282.35	46.9277
2287.17	49.6224
2291.99	52.6321
2296.8	52.7477
2301.62	52.3215
2306.43	52.5724
2311.23	53.3055
2316.03	52.7826
2320.83	52.969
2325.63	53.4644
2330.42	52.8803
2335.21	53.284
2339.99	53.8605
2344.77	53.5795
2349.55	52.7886
2354.32	53.5166
2359.1	53.7464
2363.86	52.2229
2368.63	52.0036
2373.39	52.8829
2378.15	52.7923
2382.9	54.6603
2387.65	55.4392
2392.4	55.4995
2397.14	55.2155
2401.88	55.1053
2406.62	54.7951
2411.35	52.7543
2416.08	52.3151
2420.81	51.9679
2425.53	53.3629
2430.25	56.0046
2434.97	56.2864
2439.69	54.7379
2444.4	53.2901
2449.1	55.1735
2453.81	53.5831
2458.51	53.371
2463.2	54.7526
2467.9	56.3522
2472.59	56.2541
2477.27	55.8219
2481.96	55.2359
2486.64	55.3829
2491.31	57.1764
2495.99	55.9041
2500.66	57.7568
2505.32	58.5377
2509.99	57.6038
2514.65	56.6814
2519.31	56.3406
2523.96	57.397
2528.61	58.6956
2533.26	57.864
2537.9	57.4637
2542.54	57.8196
2547.18	58.1245
2551.81	58.343
2556.44	57.6006
2561.07	57.8062
2565.69	58.6627
2570.32	59.1994
2574.93	59.1191
2579.55	58.2749
2584.16	57.0013
2588.77	55.3632
2593.37	56.3214
2597.97	57.9291
2602.57	57.6262
2607.17	58.7996
2611.76	60.5351
2616.35	60.7711
2620.93	59.6946
2625.51	59.5461
2630.09	60.2483
2634.67	59.3983
2639.24	59.5861
2643.81	58.9922
2648.38	58.657
2652.94	58.9508
2657.5	59.383
2662.06	56.7512
2666.61	57.2065
2671.16	59.8587
2675.71	63.0639
2680.25	62.8395
2684.79	61.962
2689.33	60.6896
2693.86	58.5053
2698.39	59.29
2702.92	59.1997
2707.45	60.1002
2711.97	61.3419
2716.49	62.6944
2721	63.3594
2725.51	61.5426
2730.02	59.508
2734.53	62.5818
2739.03	62.5069
2743.53	61.0839
2748.03	58.8047
2752.52	61.7925
2757.01	64.0306
2761.5	64.4187
2765.98	62.7662
2770.46	61.8761
2774.94	60.9804
2779.42	58.8611
2783.89	61.9357
2788.36	64.1022
2792.82	65.2941
2797.28	65.746
2801.74	64.8287
2806.2	63.7512
2810.65	62.4151
2815.1	62.9122
2819.55	63.7136
2823.99	64.1528
2828.43	63.956
2832.87	62.8675
2837.3	62.5745
2841.74	63.3411
2846.17	63.5467
2850.59	63.6674
2855.01	65.5634
2859.43	65.808
2863.85	64.2479
2868.26	63.4333
2872.67	63.6799
2877.08	65.6464
2881.48	68.2011
2885.89	60.5261
2890.28	63.9226
2894.68	64.3734
2899.07	64.3978
2903.46	66.7562
2907.85	68.1154
2912.23	66.9716
2916.61	65.765
2920.98	64.9901
2925.36	64.4991
2929.73	64.6175
2934.1	65.6672
2938.46	65.8911
2942.82	66.2397
2947.18	63.1695
2951.54	62.6222
2955.89	64.6378
2960.24	68.658
2964.59	69.7786
2968.93	69.7186
2973.27	68.2295
2977.61	68.5895
2981.95	69.5403
2986.28	68.5693
2990.61	68.4101
2994.94	68.6922
2999.26	67.6135
3003.58	66.7408
3007.9	69.8038
3012.21	72.1945
3016.52	72.2591
3020.83	71.3601
3025.14	69.7087
3029.44	69.2254
3033.74	68.7933
3038.04	69.518
3042.33	68.3517
3046.62	70.2211
3050.91	72.3293
3055.2	73.0263
3059.48	74.5504
3063.76	73.897
3068.03	74.3996
3072.31	73.0711
3076.58	70.2232
3080.85	70.767
3085.11	72.619
3089.37	73.8247
3093.63	75.2857
3097.89	76.3719
3102.14	74.4072
3106.39	74.9231
3110.64	76.6652
3114.89	76.234
3119.13	75.9723
3123.37	75.9492
3127.6	76.0851
3131.84	78.8688
3136.07	83.4438
3140.29	81.0643
3144.52	79.2001
3148.74	77.3478
3152.96	77.6883
3157.18	80.7531
3161.39	82.2034
3165.6	83.4998
3169.81	86.631
3174.01	87.5446
3178.22	86.183
3182.42	86.1689
3186.61	83.4763
3190.8	81.2523
3195	82.0081
3199.18	83.7179
3203.37	85.5725
3207.55	87.6135
3211.73	89.5383
3215.91	90.5352
3220.08	91.3804
3224.25	92.1883
3228.42	91.8774
3232.59	90.0162
3236.75	86.741
3240.91	85.4787
3245.07	85.7723
3249.22	88.2667
3253.37	89.2338
3257.52	89.4915
3261.67	90.6643
3265.81	90.0544
3269.95	90.4618
3274.09	89.1103
3278.22	86.1159
3282.36	87.2841
3286.49	91.5962
3290.61	92.3836
3294.74	90.0322
3298.86	87.9642
3302.98	89.3652
3307.09	90.1571
3311.21	88.7256
3315.32	89.8541
3319.42	90.4277
3323.53	85.9803
3327.63	88.7916
3331.73	91.7623
3335.83	92.6226
3339.92	90.5497
3344.01	86.9594
3348.1	85.8415
3352.19	87.2262
3356.27	90.8665
3360.35	96.1085
3364.43	97.663
3368.5	92.8655
3372.58	91.6119
3376.65	98.2128
3380.71	100.463
3384.78	99.7745
3388.84	95.5922
3392.9	92.0479
3396.95	94.7766
3401.01	99.6146
3405.06	98.4861
3409.1	97.9184
3413.15	98.4209
3417.19	98.52
3421.23	97.257
3425.27	96.4436
3429.31	96.2028
3433.34	92.419
3437.37	96.6885
3441.39	98.8011
3445.42	94.0749
3449.44	92.659
3453.46	92.7399
3457.47	93.3062
3461.49	96.2227
3465.5	96.0869
3469.51	94.6558
3473.51	95.274
3477.52	96.1248
3481.52	96.1629
3485.51	91.9688
3489.51	93.3862
3493.5	91.7708
3497.49	91.3015
3501.48	92.2679
3505.46	93.1147
3509.45	91.021
3513.43	90.9863
3517.4	91.4223
3521.38	88.9792
3525.35	86.5471
3529.32	87.1806
3533.28	90.763
3537.25	90.4585
3541.21	89.1196
3545.17	87.5687
3549.12	85.466
3553.08	82.9635
3557.03	84.3248
3560.98	86.2315
3564.92	85.3345
3568.87	84.5278
3572.81	81.9537
3576.74	81.5527
3580.68	87.9898
3584.61	90.0475
3588.54	87.6521
3592.47	84.9478
3596.4	84.7176
3600.32	81.0142
3604.24	81.2468
3608.16	84.136
3612.07	82.6743
3615.98	83.1383
3619.89	82.2316
3623.8	81.2679
3627.71	80.1691
3631.61	79.1235
3635.51	78.9186
3639.41	78.3943
3643.3	78.6209
3647.19	75.8547
3651.08	75.6746
3654.97	71.9284
3658.85	72.657
3662.74	72.1095
3666.62	74.0022
3670.49	72.6608
3674.37	76.5077
3678.24	78.4231
3682.11	74.9735
3685.98	71.0119
3689.84	71.2225
3693.7	75.2835
3697.56	77.3627
3701.42	72.9269
3705.28	69.4301
3709.13	68.4993
3712.98	70.3685
3716.82	72.1178
3720.67	72.1984
3724.51	72.6656
3728.35	72.7273
3732.19	73.3582
3736.02	71.5135
3739.86	73.0169
3743.69	69.2453
3747.51	66.6441
3751.34	68.5291
3755.16	71.4553
3758.98	72.2352
3762.8	73.9285
3766.61	74.7713
3770.43	75.0598
3774.24	73.8199
3778.05	74.5707
3781.85	72.5316
3785.65	74.2571
3789.45	74.3112
3793.25	72.9329
3797.05	70.0782
3800.84	70.2178
3804.63	73.8846
3808.42	74.6541
3812.21	72.767
3815.99	70.8528
3819.77	69.1499
3823.55	69.2165
3827.33	70.0206
3831.1	70.8251
3834.87	68.3758
3838.64	66.7363
3842.41	71.0626
3846.17	71.1006
3849.93	70.2269
3853.69	68.5804
3857.45	68.9637
3861.21	70.6382
3864.96	71.3022
3868.71	71.8256
3872.46	71.2543
3876.2	70.3409
3879.94	68.3706
3883.68	66.9162
3887.42	65.742
3891.16	67.5564
3894.89	69.3352
3898.62	70.2017
3902.35	70.1274
3906.08	71.6673
3909.8	70.7221
3913.52	67.7932
3917.24	67.9551
3920.96	68.4724
3924.67	67.6803
3928.38	71.5618
3932.09	71.5872
3935.8	72.9799
3939.51	73.3027
3943.21	71.9643
3946.91	71.6732
3950.61	71.2088
3954.3	70.99
3958	71.7881
3961.69	71.8762
3965.38	68.9337
3969.06	68.3362
3972.75	70.3855
3976.43	71.4704
3980.11	70.321
3983.78	71.1915
3987.46	71.3986
3991.13	70.4917
3994.8	70.8776
3998.47	66.0393