File: Data/3-Raman/raw/20-C_brt1_FI04.txt
#Acq. time (s)=	20
#Accumulations=	3
#Range (cm-¹)=	100...4000
#Windows=	1
#Auto scanning=	Off
#Autofocus=	Off
#Macrospot=	Off
#AutoExposure=	Off
#Spike filter=	Multiple accum.
#Delay time (s)=	0
#Binning=	1
#Readout mode=	Signal
#DeNoise=	Lite
#ICS correction=	Off
#Dark correction=	Off
#Inst. Process=	Off
#Detector temperature (°C)=	-60.09
#Instrument=	LabRAM HR Evol
#Detector=	SIN-EM FIVIS
#Objective=	x50_VIS_LWD
#Grating=	150 (500nm)
#ND Filter=	100%
#Laser=	633nm_Edge
#Hole=	30.0125
#Temperature=	0
#Range=	Visible
#StageXY=	75x50mm Scan+
#StageZ=	Z motor
#X (µm)=	7297.3
#Y (µm)=	4547.7
#Z (µm)=	-30.3
#Full time(mm:ss)=	1:02
#Project=	Buranga
#Sample=	BU18FA20_C
#Site=	C_Bertoss1
#Title=	20-C_brt1_FI04
#Remark=
#Date=	30.07.2019 14:41
#Acquired=	30.07.2019 14:41:13
100.38	761.956
106.898	602.148
113.411	489.269
119.918	408.011
126.419	345.556
132.916	297.482
139.407	263.831
145.892	243.443
152.372	226.07
158.847	208.012
165.316	194.55
171.781	191.444
178.239	184.38
184.693	167.892
191.139	167.362
197.582	163.686
204.02	158.899
210.452	152.706
216.877	147.292
223.299	151.911
229.715	167.673
236.126	211.444
242.53	291.931
248.931	256.402
255.326	214.347
261.714	196.489
268.099	198.028
274.477	217.104
280.851	248.953
287.218	307.553
293.582	317.039
299.939	246.666
306.293	197.673
312.639	178.555
318.982	188.08
325.318	231.486
331.651	333.903
337.977	315.236
344.297	232.322
350.614	196.609
356.925	189.539
363.23	201.795
369.53	216.077
375.827	211.353
382.116	190.689
388.401	167.476
394.681	155.531
400.956	151.92
407.226	153.541
413.49	158.516
419.749	163.301
426.003	173.496
432.252	204.423
438.496	241.239
444.735	266.658
450.969	264.587
457.197	249.907
463.421	243.213
469.64	219.802
475.853	193.212
482.062	175.885
488.265	168.293
494.464	165.78
500.657	161.161
506.844	161.165
513.028	164.004
519.206	168.765
525.38	162.393
531.548	157.086
537.71	157.283
543.869	158.243
550.022	158.669
556.169	157.87
562.313	153.675
568.452	149.323
574.584	146.004
580.713	144.506
586.837	151.869
592.954	172.085
599.068	204.941
605.176	257.484
611.28	247.161
617.378	228.091
623.473	221.691
629.561	223.816
635.644	230.757
641.724	228.476
647.797	206.227
653.867	212
659.931	231.18
665.99	230.679
672.044	212.335
678.095	182.467
684.139	159.734
690.179	147.639
696.213	142.565
702.245	136.736
708.27	131.077
714.29	128.901
720.306	127.374
726.316	127.543
732.322	127.515
738.323	126.747
744.32	128.414
750.311	130.788
756.298	131.591
762.28	130.101
768.258	129.784
774.23	127.365
780.198	125.587
786.161	125.564
792.119	127.259
798.073	128.103
804.021	127.432
809.965	127.087
815.904	127.479
821.839	127.738
827.769	130.671
833.693	134.113
839.614	135.231
845.53	131.704
851.44	129.048
857.346	127.928
863.248	127.735
869.144	128.216
875.037	131.662
880.924	134.335
886.807	136.66
892.685	138.132
898.559	136.723
904.427	135.781
910.292	135.521
916.151	135.594
922.006	136.889
927.856	141.616
933.701	148.845
939.543	157.49
945.379	168.93
951.21	186.129
957.037	207.622
962.861	223.041
968.678	232.18
974.491	246.28
980.3	289.005
986.104	368.568
991.904	492.905
997.699	531.677
1003.49	428.996
1009.28	364.914
1015.06	339.792
1020.83	351.694
1026.61	399.138
1032.37	439.827
1038.14	344.047
1043.9	265.002
1049.65	223.58
1055.4	205.192
1061.15	192.072
1066.88	171.606
1072.62	165.836
1078.35	168.355
1084.08	193.542
1089.8	212.03
1095.52	220.312
1101.23	231.326
1106.94	232.812
1112.65	204.105
1118.35	172.09
1124.05	152.334
1129.74	146.872
1135.42	150.973
1141.11	158.357
1146.78	169.001
1152.46	183.687
1158.13	197.329
1163.79	185.03
1169.45	153.221
1175.11	139.025
1180.76	133.212
1186.41	129.227
1192.05	125.148
1197.69	122.357
1203.32	120.51
1208.95	118.208
1214.58	116.473
1220.2	116.478
1225.82	120.024
1231.43	121.052
1237.04	118.566
1242.64	116.193
1248.24	118.181
1253.83	125.968
1259.42	136.243
1265.01	146.433
1270.59	136.961
1276.17	136.858
1281.74	340
1287.31	343
1292.88	143.874
1298.44	134.242
1303.99	126.496
1309.55	121.008
1315.09	117.864
1320.64	117.028
1326.18	121.304
1331.71	121.088
1337.24	115.799
1342.77	110.337
1348.29	112.937
1353.81	114.504
1359.32	115.821
1364.83	119.019
1370.33	125.694
1375.84	136.139
1381.33	147.404
1386.82	747
1392.31	284
1397.8	129
1403.28	133.4
1408.75	153.315
1414.22	133.156
1419.69	116.387
1425.15	110.206
1430.61	107.577
1436.07	104.319
1441.52	104.326
1446.96	103.544
1452.41	100.552
1457.84	97.1161
1463.28	102.319
1468.71	103.159
1474.13	102.886
1479.55	101.926
1484.97	100.535
1490.39	99.3544
1495.79	99.7367
1501.2	102.078
1506.6	99.1825
1512	96.974
1517.39	96.7197
1522.78	96.6659
1528.16	97.0906
1533.54	97.9136
1538.92	99.5693
1544.29	101.465
1549.66	101.859
1555.02	100.879
1560.38	98.5632
1565.74	99.0134
1571.09	102.133
1576.44	101.743
1581.78	100.35
1587.12	99.2733
1592.46	100.503
1597.79	101.515
1603.12	99.2443
1608.44	96.68
1613.76	96.4639
1619.08	99.1665
1624.39	98.957
1629.7	95.906
1635	95.142
1640.3	97.8136
1645.59	97.8397
1650.88	97.0425
1656.17	96.2609
1661.46	98.6437
1666.74	100.914
1672.01	100.282
1677.28	97.8477
1682.55	96.3029
1687.82	99.3734
1693.07	102.923
1698.33	96.41
1703.58	96.4732
1708.83	96.9435
1714.07	97.109
1719.31	97.6216
1724.55	96.6883
1729.78	95.8256
1735.01	95.3975
1740.23	96.249
1745.46	97.79
1750.67	97.6577
1755.89	96.6649
1761.09	96.3568
1766.3	96.9907
1771.5	96.7812
1776.7	96.2082
1781.89	96.0011
1787.08	96.223
1792.27	97.1851
1797.45	99.4633
1802.62	100.88
1807.8	101.051
1812.97	99.3571
1818.14	96.0503
1823.3	94.4048
1828.46	96.1596
1833.61	99.1184
1838.76	95.5275
1843.91	94.0191
1849.05	93.1783
1854.19	92.6081
1859.33	93.7602
1864.46	97.1802
1869.59	99.1624
1874.71	97.9848
1879.83	94.9604
1884.95	95.8687
1890.06	98.011
1895.17	96.2365
1900.27	93.4328
1905.38	95.6626
1910.47	96.8965
1915.57	94.8927
1920.66	93.4439
1925.74	93.0799
1930.83	97.836
1935.91	96.3679
1940.98	97.2532
1946.05	96.8471
1951.12	94.9886
1956.18	93.3243
1961.25	93.9163
1966.3	95.0602
1971.35	95.7619
1976.4	97.9277
1981.45	98.7865
1986.49	97.1936
1991.53	95.76
1996.56	90.2359
2001.59	92.2124
2006.62	94.4839
2011.64	94.9219
2016.66	94.392
2021.68	94.0143
2026.69	93.6937
2031.7	94.0065
2036.7	96.5364
2041.7	97.5451
2046.7	96.8663
2051.7	95.5157
2056.69	94.6235
2061.67	94.4149
2066.65	90.8572
2071.63	93.0603
2076.61	94.992
2081.58	95.3138
2086.55	97.1005
2091.51	96.7104
2096.47	95.4445
2101.43	93.9241
2106.39	94.4431
2111.34	98.2125
2116.28	92.4485
2121.23	94.5992
2126.17	93.8676
2131.1	93.8067
2136.03	93.7064
2140.96	92.9361
2145.89	93.8089
2150.81	94.922
2155.73	95.5191
2160.64	95.2146
2165.55	94.5237
2170.46	95.4921
2175.36	89.4261
2180.26	85.7712
2185.16	93.8244
2190.05	96.9843
2194.94	98.2389
2199.83	97.8092
2204.71	95.8529
2209.59	95.6808
2214.46	98.084
2219.33	98.6827
2224.2	95.9278
2229.07	95.7052
2233.93	97.5213
2238.79	99.1934
2243.64	98.3894
2248.49	93.973
2253.34	92.619
2258.18	95.2374
2263.02	95.6108
2267.86	93.3856
2272.69	93.3621
2277.52	93.0278
2282.35	94.2045
2287.17	97.0173
2291.99	98.8222
2296.8	97.0631
2301.62	95.4803
2306.43	95.9036
2311.23	94.7829
2316.03	93.7077
2320.83	92.3635
2325.63	101.232
2330.42	106.447
2335.21	99.8074
2339.99	95.3361
2344.77	96.1429
2349.55	95.5639
2354.32	96.263
2359.1	96.3595
2363.86	95.8565
2368.63	96.4607
2373.39	92.8982
2378.15	89.9866
2382.9	90.5771
2387.65	95.2584
2392.4	97.3032
2397.14	97.7466
2401.88	94.0488
2406.62	92.5858
2411.35	92.5952
2416.08	96.4896
2420.81	95.8603
2425.53	95.9811
2430.25	94.6947
2434.97	94.7394
2439.69	95.5154
2444.4	92.4492
2449.1	89.7436
2453.81	91.2662
2458.51	92.4945
2463.2	95.7507
2467.9	98.728
2472.59	98.8095
2477.27	95.9572
2481.96	93.6392
2486.64	92.4114
2491.31	92.511
2495.99	93.4435
2500.66	90.8385
2505.32	90.317
2509.99	91.1097
2514.65	92.4377
2519.31	94.0753
2523.96	95.4478
2528.61	94.6511
2533.26	95.3484
2537.9	97.1923
2542.54	94.0185
2547.18	88.5059
2551.81	91.9597
2556.44	88.0278
2561.07	89.4076
2565.69	92.9868
2570.32	90.524
2574.93	91.2162
2579.55	92.2841
2584.16	93.2535
2588.77	92.9571
2593.37	91.5249
2597.97	90.3369
2602.57	93.3848
2607.17	92.3314
2611.76	90.9385
2616.35	89.8549
2620.93	90.2744
2625.51	93.4541
2630.09	94.4323
2634.67	94.2443
2639.24	91.6303
2643.81	87.5848
2648.38	87.6527
2652.94	88.988
2657.5	89.6882
2662.06	93.0384
2666.61	93.4832
2671.16	91.1769
2675.71	92.7849
2680.25	93.0816
2684.79	90.8396
2689.33	91.7751
2693.86	93.4428
2698.39	94.3425
2702.92	90.8276
2707.45	88.8001
2711.97	89.3556
2716.49	90.9325
2721	89.7152
2725.51	88.8605
2730.02	87.3139
2734.53	86.2143
2739.03	87.7348
2743.53	90.0087
2748.03	90.5674
2752.52	89.0766
2757.01	88.2835
2761.5	90.5315
2765.98	91.7579
2770.46	92.3039
2774.94	89.5904
2779.42	87.6422
2783.89	86.9506
2788.36	87.4869
2792.82	89.381
2797.28	91.3452
2801.74	90.8907
2806.2	89.1296
2810.65	89.8349
2815.1	89.1811
2819.55	89.9502
2823.99	90.5984
2828.43	90.3386
2832.87	88.9941
2837.3	89.0624
2841.74	90.9246
2846.17	91.7738
2850.59	90.6583
2855.01	89.561
2859.43	89.9445
2863.85	92.0674
2868.26	91.1669
2872.67	88.671
2877.08	87.3737
2881.48	86.8137
2885.89	87.6291
2890.28	87.3064
2894.68	86.8506
2899.07	86.7688
2903.46	87.44
2907.85	87.9639
2912.23	87.4867
2916.61	86.8406
2920.98	85.6728
2925.36	84.3232
2929.73	84.8192
2934.1	87.0492
2938.46	89.4719
2942.82	90.8938
2947.18	90.2127
2951.54	88.2633
2955.89	85.4352
2960.24	85.595
2964.59	87.1412
2968.93	87.6288
2973.27	86.9029
2977.61	86.7987
2981.95	86.817
2986.28	87.3697
2990.61	89.6269
2994.94	90.8561
2999.26	88.7175
3003.58	88.2534
3007.9	88.1908
3012.21	86.7963
3016.52	86.1132
3020.83	85.6225
3025.14	85.7634
3029.44	85.539
3033.74	84.1544
3038.04	84.476
3042.33	85.9284
3046.62	87.5351
3050.91	87.6462
3055.2	85.593
3059.48	85.6062
3063.76	86.9054
3068.03	84.9531
3072.31	88.4821
3076.58	86.6963
3080.85	84.5045
3085.11	84.3192
3089.37	85.3356
3093.63	85.8173
3097.89	86.7806
3102.14	87.708
3106.39	88.1928
3110.64	87.9975
3114.89	86.8264
3119.13	88.7772
3123.37	87.8383
3127.6	84.9083
3131.84	83.1895
3136.07	84.9922
3140.29	85.4589
3144.52	85.5674
3148.74	84.9155
3152.96	84.4055
3157.18	84.7995
3161.39	86.0435
3165.6	88.5469
3169.81	87.7829
3174.01	89.0124
3178.22	89.9443
3182.42	86.1323
3186.61	86.2759
3190.8	87.1372
3195	89.0176
3199.18	91.0239
3203.37	90.7785
3207.55	90.0417
3211.73	86.4876
3215.91	87.3652
3220.08	88.0331
3224.25	87.1163
3228.42	86.5956
3232.59	86.5603
3236.75	87.8614
3240.91	90.1248
3245.07	86.9965
3249.22	83.0643
3253.37	80.4192
3257.52	80.757
3261.67	82.184
3265.81	83.102
3269.95	84.5171
3274.09	81.9763
3278.22	79.6451
3282.36	78.3722
3286.49	78.0053
3290.61	79.2113
3294.74	79.6633
3298.86	76.7075
3302.98	75.961
3307.09	79.0516
3311.21	79.0431
3315.32	79.3857
3319.42	79.0082
3323.53	78.712
3327.63	77.7451
3331.73	78.0898
3335.83	79.8149
3339.92	77.9753
3344.01	76.0903
3348.1	77.172
3352.19	75.4077
3356.27	77.3097
3360.35	78.3388
3364.43	77.0175
3368.5	75.2927
3372.58	76.8987
3376.65	77.7051
3380.71	79.938
3384.78	81.5484
3388.84	80.8129
3392.9	80.6475
3396.95	79.27
3401.01	80.3376
3405.06	81.0516
3409.1	79.765
3413.15	78.221
3417.19	80.6224
3421.23	82.3449
3425.27	80.8699
3429.31	78.1077
3433.34	74.3601
3437.37	76.7743
3441.39	79.8261
3445.42	77.2921
3449.44	71.7979
3453.46	71.6292
3457.47	75.0752
3461.49	75.7995
3465.5	73.6955
3469.51	67.945
3473.51	70.9318
3477.52	72.4346
3481.52	73.3302
3485.51	73.7351
3489.51	73.1306
3493.5	73.8586
3497.49	73.7991
3501.48	74.003
3505.46	72.4546
3509.45	70.0114
3513.43	69.797
3517.4	70.0203
3521.38	72.0943
3525.35	74.3163
3529.32	74.3695
3533.28	74.0704
3537.25	71.573
3541.21	71.4253
3545.17	72.0754
3549.12	71.693
3553.08	71.5859
3557.03	70.5542
3560.98	71.1377
3564.92	72.8708
3568.87	76.3949
3572.81	81.5993
3576.74	86.129
3580.68	89.7056
3584.61	92.305
3588.54	94.3167
3592.47	90.9972
3596.4	81.1919
3600.32	80.0737
3604.24	79.0004
3608.16	69.2418
3612.07	65.9152
3615.98	66.3058
3619.89	67.0632
3623.8	65.9973
3627.71	64.1193
3631.61	66.4209
3635.51	67.2204
3639.41	64.413
3643.3	61.1806
3647.19	60.7497
3651.08	62.0583
3654.97	63.1798
3658.85	64.761
3662.74	65.4575
3666.62	64.6217
3670.49	64.0775
3674.37	64.9369
3678.24	65.4939
3682.11	65.5095
3685.98	64.7763
3689.84	66.0262
3693.7	64.0294
3697.56	63.7109
3701.42	64.2319
3705.28	64.4788
3709.13	65.9649
3712.98	61.9805
3716.82	63.5877
3720.67	63.9575
3724.51	62.4407
3728.35	60.5589
3732.19	59.9438
3736.02	61.3937
3739.86	63.3374
3743.69	63.2291
3747.51	62.6563
3751.34	62.2319
3755.16	63.0471
3758.98	61.438
3762.8	59.7732
3766.61	59.0722
3770.43	59.4124
3774.24	60.792
3778.05	61.1395
3781.85	62.4646
3785.65	61.8277
3789.45	59.7446
3793.25	59.5514
3797.05	60.9868
3800.84	61.7578
3804.63	61.9766
3808.42	62.3884
3812.21	63.4009
3815.99	62.7657
3819.77	60.4517
3823.55	60.603
3827.33	61.6365
3831.1	59.2031
3834.87	59.6535
3838.64	59.479
3842.41	58.3804
3846.17	59.2554
3849.93	59.4996
3853.69	59.7851
3857.45	58.5692
3861.21	59.3173
3864.96	58.0659
3868.71	58.7546
3872.46	59.4447
3876.2	58.4671
3879.94	57.9554
3883.68	57.3361
3887.42	56.5642
3891.16	55.9417
3894.89	56.171
3898.62	58.5983
3902.35	57.57
3906.08	56.8959
3909.8	58.1724
3913.52	57.1583
3917.24	58.8925
3920.96	57.3487
3924.67	55.3893
3928.38	53.5638
3932.09	53.0085
3935.8	53.8841
3939.51	54.493
3943.21	55.5313
3946.91	57.1393
3950.61	57.4841
3954.3	57.9971
3958	58.3839
3961.69	59.5301
3965.38	58.208
3969.06	56.3079
3972.75	56.0087
3976.43	55.6431
3980.11	55.665
3983.78	56.6814
3987.46	55.1818
3991.13	55.3148
3994.8	55.9407
3998.47	54.2727