File: Data/3-Raman/raw/20-C_brt1_FI02.txt
#Acq. time (s)=	20
#Accumulations=	3
#Range (cm-¹)=	100...4000
#Windows=	1
#Auto scanning=	Off
#Autofocus=	Off
#Macrospot=	Off
#AutoExposure=	Off
#Spike filter=	Multiple accum.
#Delay time (s)=	0
#Binning=	1
#Readout mode=	Signal
#DeNoise=	Lite
#ICS correction=	Off
#Dark correction=	Off
#Inst. Process=	Off
#Detector temperature (°C)=	-60.09
#Instrument=	LabRAM HR Evol
#Detector=	SIN-EM FIVIS
#Objective=	x50_VIS_LWD
#Grating=	150 (500nm)
#ND Filter=	100%
#Laser=	633nm_Edge
#Hole=	30.0125
#Temperature=	0
#Range=	Visible
#StageXY=	75x50mm Scan+
#StageZ=	Z motor
#X (µm)=	7300.2
#Y (µm)=	4433.6
#Z (µm)=	-20.8
#Full time(mm:ss)=	1:35
#Project=	Buranga
#Sample=	BU18FA20_C
#Site=	C_Bertoss1
#Title=	20-C_brt1_FI02
#Remark=
#Date=	30.07.2019 14:24
#Acquired=	30.07.2019 14:24:07
100.38	1097
106.898	824.515
113.411	645.666
119.918	524.768
126.419	427.558
132.916	349.227
139.407	297.912
145.892	258.903
152.372	226.411
158.847	202.279
165.316	186.178
171.781	175.963
178.239	164.074
184.693	149.155
191.139	139.477
197.582	138.966
204.02	131.787
210.452	125.065
216.877	120.448
223.299	122.21
229.715	131.242
236.126	158.107
242.53	202.278
248.931	177.394
255.326	148.989
261.714	143.22
268.099	151.979
274.477	161.591
280.851	172.66
287.218	211.689
293.582	212.265
299.939	172.83
306.293	146.14
312.639	135.623
318.982	141.142
325.318	162.686
331.651	253.789
337.977	209.232
344.297	163.047
350.614	138.641
356.925	135.79
363.23	147.617
369.53	156.248
375.827	145.759
382.116	134.219
388.401	124.582
394.681	122.452
400.956	122.443
407.226	119.925
413.49	117.988
419.749	122.628
426.003	134.454
432.252	152.38
438.496	173.106
444.735	180.169
450.969	177.727
457.197	171.58
463.421	167.504
469.64	150.875
475.853	135.175
482.062	126.112
488.265	122.429
494.464	123.712
500.657	123.917
506.844	123.41
513.028	122.157
519.206	124.868
525.38	123.135
531.548	118.743
537.71	116.515
543.869	114.353
550.022	112.614
556.169	111.73
562.313	113.622
568.452	114.91
574.584	112.484
580.713	109.821
586.837	113.242
592.954	128.711
599.068	154.661
605.176	180.186
611.28	176.764
617.378	159.718
623.473	156.487
629.561	160.684
635.644	162.637
641.724	158.138
647.797	148.743
653.867	147.49
659.931	167.554
665.99	167.889
672.044	147.5
678.095	129.156
684.139	116.535
690.179	109.886
696.213	109.2
702.245	103.427
708.27	99.0638
714.29	96.4287
720.306	97.84
726.316	99.978
732.322	100.353
738.323	98.8701
744.32	98.224
750.311	98.3298
756.298	102.587
762.28	101.238
768.258	96.9001
774.23	95.8839
780.198	96.4528
786.161	95.0542
792.119	94.7437
798.073	96.463
804.021	97.539
809.965	94.9917
815.904	94.5073
821.839	97.7282
827.769	101.067
833.693	104.545
839.614	101.366
845.53	98.0931
851.44	98.7873
857.346	98.7102
863.248	99.4152
869.144	99.1637
875.037	98.7902
880.924	98.8157
886.807	100.365
892.685	102.438
898.559	102.925
904.427	100.388
910.292	97.7845
916.151	98.7206
922.006	102.043
927.856	105.412
933.701	107.286
939.543	111.322
945.379	118.393
951.21	126.704
957.037	143.769
962.861	156.622
968.678	161.371
974.491	174.065
980.3	201.071
986.104	267.358
991.904	328.863
997.699	328.604
1003.49	273.796
1009.28	227.656
1015.06	222.741
1020.83	244.988
1026.61	271.222
1032.37	268.323
1038.14	217.218
1043.9	172.024
1049.65	151.143
1055.4	140.345
1061.15	129.92
1066.88	122.208
1072.62	118.688
1078.35	122.419
1084.08	131.989
1089.8	143.304
1095.52	154.342
1101.23	162.761
1106.94	162.417
1112.65	144.364
1118.35	121.444
1124.05	104.955
1129.74	100.795
1135.42	106.92
1141.11	115.078
1146.78	123.776
1152.46	133.413
1158.13	139.068
1163.79	128.858
1169.45	111.798
1175.11	94.2539
1180.76	93.0721
1186.41	92.9477
1192.05	92.1277
1197.69	93.4294
1203.32	92.137
1208.95	79.1051
1214.58	89.2246
1220.2	85.1709
1225.82	83.8647
1231.43	85.9843
1237.04	87.6758
1242.64	89.6476
1248.24	93.4238
1253.83	103.936
1259.42	121.203
1265.01	152.506
1270.59	112.81
1276.17	131.743
1281.74	579
1287.31	391
1292.88	134.741
1298.44	113.35
1303.99	107.882
1309.55	104.863
1315.09	101.579
1320.64	97.7542
1326.18	94.177
1331.71	93.6234
1337.24	94.2008
1342.77	94.267
1348.29	93.0032
1353.81	92.7199
1359.32	95.4402
1364.83	103.077
1370.33	120.377
1375.84	117.225
1381.33	146.573
1386.82	1363
1392.31	303
1397.8	121.248
1403.28	111.998
1408.75	164.897
1414.22	116.024
1419.69	95.1295
1425.15	87.6563
1430.61	82.6357
1436.07	80.8547
1441.52	80.0402
1446.96	77.9696
1452.41	75.1618
1457.84	72.756
1463.28	71.858
1468.71	72.4122
1474.13	72.4738
1479.55	72.7395
1484.97	73.0883
1490.39	73.2716
1495.79	73.1687
1501.2	72.6575
1506.6	70.9715
1512	68.9268
1517.39	69.8929
1522.78	71.4126
1528.16	71.2106
1533.54	70.7712
1538.92	70.1525
1544.29	71.4364
1549.66	73.8044
1555.02	73.9238
1560.38	70.3023
1565.74	72.523
1571.09	73.8183
1576.44	72.0081
1581.78	72.0503
1587.12	72.7668
1592.46	73.063
1597.79	71.3068
1603.12	68.4839
1608.44	66.6574
1613.76	66.5121
1619.08	68.1712
1624.39	69.5242
1629.7	70.5533
1635	70.8951
1640.3	70.8829
1645.59	71.0316
1650.88	71.1131
1656.17	70.9492
1661.46	70.4297
1666.74	70.1391
1672.01	70.6801
1677.28	70.1863
1682.55	68.9183
1687.82	68.1307
1693.07	68.2739
1698.33	69.3879
1703.58	71.3847
1708.83	73.6266
1714.07	71.6007
1719.31	66.9503
1724.55	65.5786
1729.78	66.7233
1735.01	68.3432
1740.23	70.588
1745.46	71.5457
1750.67	68.0324
1755.89	69.3104
1761.09	69.0702
1766.3	67.7628
1771.5	65.4732
1776.7	65.1721
1781.89	67.1875
1787.08	68.3506
1792.27	68.5559
1797.45	67.799
1802.62	66.6328
1807.8	66.6245
1812.97	67.0099
1818.14	66.6139
1823.3	67.9423
1828.46	66.7531
1833.61	64.3531
1838.76	65.8325
1843.91	67.6307
1849.05	66.5478
1854.19	65.4526
1859.33	67.1778
1864.46	68.8481
1869.59	68.3351
1874.71	67.0373
1879.83	67.2913
1884.95	68.0842
1890.06	68.5301
1895.17	68.7289
1900.27	68.0028
1905.38	66.442
1910.47	66.2582
1915.57	67.282
1920.66	69.7006
1925.74	71.0535
1930.83	70.6623
1935.91	69.6743
1940.98	68.4905
1946.05	66.8738
1951.12	65.8137
1956.18	65.3856
1961.25	67.3456
1966.3	69.3021
1971.35	70.7364
1976.4	70.3719
1981.45	67.9447
1986.49	63.4986
1991.53	63.0365
1996.56	64.2752
2001.59	64.4702
2006.62	64.8805
2011.64	67.1774
2016.66	68.6661
2021.68	66.6526
2026.69	67.284
2031.7	69.2922
2036.7	70.1215
2041.7	69.3554
2046.7	66.6781
2051.7	65.4049
2056.69	65.633
2061.67	66.7191
2066.65	68.4867
2071.63	70.7291
2076.61	70.768
2081.58	68.2856
2086.55	65.8388
2091.51	64.4319
2096.47	63.6826
2101.43	64.102
2106.39	65.4001
2111.34	69.1726
2116.28	69.3551
2121.23	68.593
2126.17	68.7298
2131.1	66.7376
2136.03	64.7222
2140.96	64.3742
2145.89	65.9521
2150.81	68.3482
2155.73	68.7587
2160.64	66.7693
2165.55	63.9365
2170.46	64.0207
2175.36	65.009
2180.26	63.0576
2185.16	60.6467
2190.05	60.7126
2194.94	65.0492
2199.83	70.0072
2204.71	71.7819
2209.59	69.5171
2214.46	68.2404
2219.33	68.5151
2224.2	68.9506
2229.07	69.4109
2233.93	68.5721
2238.79	67.4178
2243.64	65.8751
2248.49	67.5443
2253.34	68.3577
2258.18	68.0222
2263.02	67.4865
2267.86	66.0599
2272.69	65.4028
2277.52	67.6253
2282.35	68.584
2287.17	68.3063
2291.99	67.0228
2296.8	66.4658
2301.62	66.6032
2306.43	67.2963
2311.23	66.4354
2316.03	67.1528
2320.83	70.8994
2325.63	80.8324
2330.42	82.5478
2335.21	75.0586
2339.99	69.883
2344.77	66.5766
2349.55	67.0782
2354.32	68.5507
2359.1	69.0529
2363.86	67.4763
2368.63	65.561
2373.39	64.2085
2378.15	63.6037
2382.9	63.5514
2387.65	64.0214
2392.4	65.2351
2397.14	66.3281
2401.88	67.9063
2406.62	61.9007
2411.35	63.1006
2416.08	66.5688
2420.81	67.0813
2425.53	67.7365
2430.25	67.2562
2434.97	66.3888
2439.69	68.0546
2444.4	68.2412
2449.1	66.3557
2453.81	66.342
2458.51	67.5515
2463.2	69.1504
2467.9	68.528
2472.59	67.4871
2477.27	65.0714
2481.96	63.9736
2486.64	64.2376
2491.31	66.5323
2495.99	67.7933
2500.66	68.5353
2505.32	67.5021
2509.99	65.7599
2514.65	63.4758
2519.31	64.6414
2523.96	67.4995
2528.61	69.5714
2533.26	66.3066
2537.9	66.4901
2542.54	67.36
2547.18	67.3152
2551.81	66.4382
2556.44	65.952
2561.07	66.9932
2565.69	66.7362
2570.32	67.6922
2574.93	66.4347
2579.55	66.3684
2584.16	67.8147
2588.77	67.653
2593.37	67.965
2597.97	67.9534
2602.57	67.0083
2607.17	65.8779
2611.76	64.7513
2616.35	64.3227
2620.93	63.294
2625.51	61.7501
2630.09	60.5636
2634.67	61.968
2639.24	65.2801
2643.81	67.0733
2648.38	67.546
2652.94	67.0209
2657.5	65.7683
2662.06	64.1728
2666.61	62.8097
2671.16	63.287
2675.71	65.0682
2680.25	65.2711
2684.79	65.7024
2689.33	65.473
2693.86	65.6995
2698.39	67.1434
2702.92	67.0539
2707.45	64.3632
2711.97	64.0615
2716.49	64.5483
2721	63.783
2725.51	64.3196
2730.02	66.5891
2734.53	67.1889
2739.03	65.0101
2743.53	64.3936
2748.03	64.0373
2752.52	63.443
2757.01	61.9255
2761.5	61.62
2765.98	65.3629
2770.46	64.7009
2774.94	66.6504
2779.42	67.9519
2783.89	68.6895
2788.36	65.8112
2792.82	64.0468
2797.28	64.2662
2801.74	66.3616
2806.2	64.5878
2810.65	59.0248
2815.1	61.1509
2819.55	63.1503
2823.99	63.4705
2828.43	61.9663
2832.87	60.2103
2837.3	58.9816
2841.74	65.1204
2846.17	65.6616
2850.59	66.006
2855.01	65.2041
2859.43	62.2661
2863.85	61.7124
2868.26	64.6031
2872.67	65.3512
2877.08	64.0686
2881.48	65.4391
2885.89	63.6632
2890.28	62.6867
2894.68	61.4407
2899.07	64.7857
2903.46	68.1573
2907.85	65.8181
2912.23	62.9977
2916.61	60.8521
2920.98	60.4847
2925.36	61.3393
2929.73	63.5082
2934.1	65.8443
2938.46	66.481
2942.82	64.9803
2947.18	63.5254
2951.54	61.7859
2955.89	61.3348
2960.24	65.1381
2964.59	66.5986
2968.93	63.2482
2973.27	60.1205
2977.61	57.5811
2981.95	61.2546
2986.28	63.2504
2990.61	62.0086
2994.94	61.8736
2999.26	59.0636
3003.58	65.4744
3007.9	64.5528
3012.21	61.5888
3016.52	62.9167
3020.83	60.3047
3025.14	60.7725
3029.44	65.4356
3033.74	62.4175
3038.04	60.0771
3042.33	57.5874
3046.62	59.548
3050.91	58.0552
3055.2	58.1207
3059.48	60.6249
3063.76	62.3097
3068.03	64.165
3072.31	64.7076
3076.58	62.442
3080.85	63.6748
3085.11	64.3071
3089.37	64.351
3093.63	66.4381
3097.89	66.8489
3102.14	68.0008
3106.39	65.7811
3110.64	64.5235
3114.89	64.4697
3119.13	63.4266
3123.37	59.7463
3127.6	60.8576
3131.84	64.4138
3136.07	66.1322
3140.29	63.9308
3144.52	62.4197
3148.74	61.4397
3152.96	60.9617
3157.18	61.495
3161.39	65.9906
3165.6	68.6803
3169.81	67.9373
3174.01	66.5065
3178.22	64.3655
3182.42	63.6676
3186.61	64.0456
3190.8	64.7605
3195	64.7291
3199.18	65.3797
3203.37	61.7727
3207.55	63.7882
3211.73	64.3473
3215.91	65.5583
3220.08	64.0662
3224.25	63.9574
3228.42	63.8522
3232.59	61.6661
3236.75	64.5804
3240.91	65.1074
3245.07	62.5065
3249.22	60.0629
3253.37	59.6604
3257.52	60.3866
3261.67	59.6566
3265.81	60.2313
3269.95	62.2322
3274.09	61.8847
3278.22	60.1278
3282.36	59.236
3286.49	60.4577
3290.61	60.517
3294.74	58.7252
3298.86	58.3995
3302.98	58.4681
3307.09	57.5507
3311.21	57.0538
3315.32	56.5997
3319.42	56.632
3323.53	58.8914
3327.63	60.7825
3331.73	61.3541
3335.83	59.403
3339.92	57.5683
3344.01	58.5071
3348.1	57.409
3352.19	56.7377
3356.27	54.8279
3360.35	54.6699
3364.43	54.9965
3368.5	56.4115
3372.58	56.8394
3376.65	58.7821
3380.71	60.9449
3384.78	57.0186
3388.84	59.809
3392.9	59.6789
3396.95	58.1508
3401.01	58.2972
3405.06	59.6051
3409.1	59.951
3413.15	59.2825
3417.19	59.1523
3421.23	60.2254
3425.27	60.0266
3429.31	59.0815
3433.34	57.2721
3437.37	57.4889
3441.39	57.9197
3445.42	57.893
3449.44	55.6164
3453.46	57.5378
3457.47	58.0644
3461.49	59.3105
3465.5	56.5643
3469.51	53.8729
3473.51	52.9345
3477.52	52.4352
3481.52	52.9412
3485.51	53.9395
3489.51	52.4393
3493.5	54.6831
3497.49	56.2228
3501.48	57.2689
3505.46	57.6489
3509.45	53.6551
3513.43	55.0156
3517.4	56.2892
3521.38	55.4372
3525.35	54.5002
3529.32	53.9315
3533.28	53.6915
3537.25	54.4743
3541.21	55.8893
3545.17	56.0623
3549.12	55.0022
3553.08	54.8684
3557.03	53.7155
3560.98	53.4921
3564.92	54.516
3568.87	55.4031
3572.81	54.8348
3576.74	54.7125
3580.68	58.089
3584.61	61.0654
3588.54	61.2094
3592.47	59.2042
3596.4	55.4278
3600.32	52.5005
3604.24	53.741
3608.16	54.2936
3612.07	53.2842
3615.98	50.6158
3619.89	49.8565
3623.8	50.7083
3627.71	51.3528
3631.61	51.026
3635.51	50.7633
3639.41	49.9853
3643.3	49.8484
3647.19	50.6409
3651.08	50.885
3654.97	49.9376
3658.85	49.354
3662.74	47.4853
3666.62	48.5835
3670.49	47.8704
3674.37	46.1156
3678.24	46.7371
3682.11	48.6418
3685.98	46.8812
3689.84	46.1759
3693.7	47.173
3697.56	44.4892
3701.42	42.9388
3705.28	42.8626
3709.13	43.997
3712.98	46.1864
3716.82	47.349
3720.67	48.0976
3724.51	46.5333
3728.35	44.8969
3732.19	46.0323
3736.02	47.0328
3739.86	45.8848
3743.69	45.303
3747.51	45.7573
3751.34	48.0622
3755.16	46.4581
3758.98	37.6227
3762.8	44.2562
3766.61	47.5558
3770.43	47.7324
3774.24	46.4868
3778.05	46.2229
3781.85	46.1174
3785.65	44.4932
3789.45	44.4362
3793.25	45.7892
3797.05	46.104
3800.84	45.0612
3804.63	43.7482
3808.42	43.5902
3812.21	44.6283
3815.99	45.8001
3819.77	46.5786
3823.55	45.6824
3827.33	43.7161
3831.1	42.5193
3834.87	43.3921
3838.64	45.5818
3842.41	44.5953
3846.17	43.3411
3849.93	43.5953
3853.69	43.5769
3857.45	43.8341
3861.21	44.916
3864.96	44.4869
3868.71	43.2543
3872.46	41.968
3876.2	42.1358
3879.94	43.8411
3883.68	45.9221
3887.42	44.5435
3891.16	42.9167
3894.89	42.9222
3898.62	43.5663
3902.35	43.6778
3906.08	42.9837
3909.8	42.4644
3913.52	41.6694
3917.24	44.5726
3920.96	42.8106
3924.67	42.3057
3928.38	42.034
3932.09	41.6978
3935.8	42.5733
3939.51	44.7221
3943.21	45.9041
3946.91	44.4303
3950.61	42.6171
3954.3	43.9284
3958	44.471
3961.69	43.5666
3965.38	41.6991
3969.06	38.6659
3972.75	39.8146
3976.43	40.4886
3980.11	41.3814
3983.78	42.0958
3987.46	40.6803
3991.13	39.7685
3994.8	40.1169
3998.47	36.8425