File: Data/3-Raman/raw/20-C_brt1_FI08.txt
#Acq. time (s)=	20
#Accumulations=	3
#Range (cm-¹)=	100...4000
#Windows=	1
#Auto scanning=	Off
#Autofocus=	Off
#Macrospot=	Off
#AutoExposure=	Off
#Spike filter=	Multiple accum.
#Delay time (s)=	0
#Binning=	1
#Readout mode=	Signal
#DeNoise=	Lite
#ICS correction=	Off
#Dark correction=	Off
#Inst. Process=	Off
#Detector temperature (°C)=	-60.09
#Instrument=	LabRAM HR Evol
#Detector=	SIN-EM FIVIS
#Objective=	x50_VIS_LWD
#Grating=	150 (500nm)
#ND Filter=	100%
#Laser=	633nm_Edge
#Hole=	30.0125
#Temperature=	0
#Range=	Visible
#StageXY=	75x50mm Scan+
#StageZ=	Z motor
#X (µm)=	7340
#Y (µm)=	4609.7
#Z (µm)=	-42.4
#Full time(mm:ss)=	1:02
#Project=	Buranga
#Sample=	BU18FA20_C
#Site=	C_Bertoss1
#Title=	20-C_brt1_FI08
#Remark=
#Date=	30.07.2019 14:43
#Acquired=	30.07.2019 14:43:14
100.38	568.622
106.898	482.376
113.411	400.114
119.918	344.668
126.419	302.263
132.916	271.612
139.407	251.27
145.892	234.418
152.372	220.05
158.847	203.033
165.316	191.349
171.781	185.76
178.239	174.271
184.693	169.56
191.139	168.565
197.582	169.602
204.02	161.365
210.452	154.718
216.877	152.836
223.299	155.35
229.715	163.389
236.126	186.422
242.53	231.747
248.931	228.119
255.326	188.342
261.714	177.314
268.099	181.301
274.477	194.703
280.851	216.789
287.218	262.75
293.582	255.794
299.939	208.502
306.293	177.114
312.639	166.419
318.982	176.483
325.318	204.965
331.651	278.011
337.977	280.263
344.297	203.244
350.614	173.563
356.925	170.407
363.23	183.315
369.53	202.259
375.827	196.329
382.116	180.062
388.401	165.474
394.681	156.193
400.956	153.015
407.226	154.871
413.49	157.77
419.749	163.12
426.003	173.357
432.252	187.577
438.496	210.629
444.735	229.233
450.969	228.158
457.197	222.848
463.421	215.854
469.64	201.057
475.853	180.233
482.062	166.521
488.265	162.565
494.464	162.707
500.657	162.593
506.844	161.562
513.028	160.132
519.206	162.423
525.38	168.24
531.548	166.358
537.71	160.418
543.869	156.618
550.022	154.476
556.169	153.834
562.313	154.053
568.452	152.278
574.584	149.763
580.713	149.202
586.837	154.044
592.954	163.614
599.068	190.286
605.176	230.164
611.28	226.12
617.378	201.48
623.473	197.406
629.561	201.743
635.644	206.09
641.724	204.441
647.797	188.51
653.867	186.382
659.931	199.005
665.99	209.82
672.044	198.444
678.095	175.779
684.139	159.204
690.179	151.087
696.213	146.225
702.245	141.668
708.27	137.131
714.29	135.903
720.306	139.563
726.316	142.372
732.322	141.447
738.323	136.729
744.32	132.875
750.311	132.57
756.298	134.932
762.28	138.905
768.258	141.808
774.23	140.192
780.198	138.157
786.161	136.379
792.119	135.922
798.073	136.42
804.021	137.543
809.965	139.106
815.904	138.138
821.839	136.118
827.769	133.77
833.693	134.61
839.614	137.409
845.53	141.218
851.44	143.001
857.346	139.351
863.248	134.18
869.144	133.785
875.037	139.12
880.924	139.464
886.807	138.531
892.685	136.807
898.559	134.899
904.427	133.963
910.292	139.177
916.151	139.412
922.006	136.539
927.856	136.307
933.701	138.612
939.543	141.492
945.379	150.601
951.21	168.056
957.037	185.747
962.861	195.464
968.678	200.253
974.491	214.746
980.3	245.467
986.104	298.135
991.904	378.606
997.699	414.629
1003.49	333.09
1009.28	287.073
1015.06	271.741
1020.83	296.141
1026.61	327.651
1032.37	319.462
1038.14	274.536
1043.9	220.365
1049.65	196.044
1055.4	178.177
1061.15	167.28
1066.88	158.307
1072.62	152.182
1078.35	157.777
1084.08	167.291
1089.8	179.514
1095.52	189.64
1101.23	198.416
1106.94	207.226
1112.65	173.381
1118.35	150.939
1124.05	142.947
1129.74	139.059
1135.42	135.644
1141.11	138.562
1146.78	145.941
1152.46	158.397
1158.13	173.541
1163.79	163.554
1169.45	142.365
1175.11	132.634
1180.76	125.727
1186.41	121.945
1192.05	119.719
1197.69	117.779
1203.32	120.932
1208.95	111.735
1214.58	111.882
1220.2	117.523
1225.82	113.652
1231.43	112.742
1237.04	115.287
1242.64	118.307
1248.24	120.789
1253.83	120.795
1259.42	124.175
1265.01	132.199
1270.59	127.591
1276.17	124.562
1281.74	269
1287.31	264
1292.88	141.318
1298.44	125.868
1303.99	119.967
1309.55	118.708
1315.09	119.165
1320.64	119.596
1326.18	118.091
1331.71	114.048
1337.24	113.578
1342.77	112.092
1348.29	105.563
1353.81	104.689
1359.32	111.263
1364.83	118.992
1370.33	127.958
1375.84	121.799
1381.33	139.08
1386.82	527
1392.31	231
1397.8	130.245
1403.28	126.414
1408.75	140.328
1414.22	125.484
1419.69	112.432
1425.15	104.909
1430.61	100.909
1436.07	102.186
1441.52	102.93
1446.96	100.433
1452.41	97.9147
1457.84	99.6463
1463.28	101.921
1468.71	99.8447
1474.13	97.286
1479.55	97.7526
1484.97	99.4933
1490.39	101.035
1495.79	100.129
1501.2	105.56
1506.6	100.932
1512	98.5327
1517.39	99.2153
1522.78	99.6909
1528.16	99.1259
1533.54	95.7959
1538.92	91.171
1544.29	95.2142
1549.66	97.4249
1555.02	97.7234
1560.38	97.9593
1565.74	97.9731
1571.09	98.9317
1576.44	98.9676
1581.78	99.8105
1587.12	98.0564
1592.46	95.1086
1597.79	94.6781
1603.12	95.8036
1608.44	97.437
1613.76	98.0107
1619.08	97.5505
1624.39	97.1819
1629.7	97.2234
1635	96.4328
1640.3	95.3866
1645.59	94.2433
1650.88	92.6672
1656.17	92.3106
1661.46	94.9769
1666.74	99.0278
1672.01	100.411
1677.28	95.9774
1682.55	92.7173
1687.82	93.4834
1693.07	94.1012
1698.33	94.766
1703.58	96.169
1708.83	96.1741
1714.07	94.8684
1719.31	93.8605
1724.55	93.7718
1729.78	93.1635
1735.01	93.6865
1740.23	97.1436
1745.46	97.4514
1750.67	96.5119
1755.89	95.9019
1761.09	96.4852
1766.3	97.0596
1771.5	97.3054
1776.7	95.4156
1781.89	93.7645
1787.08	92.3293
1792.27	91.1198
1797.45	90.3891
1802.62	90.7421
1807.8	92.462
1812.97	93.8057
1818.14	92.8927
1823.3	91.8539
1828.46	92.9709
1833.61	92.5859
1838.76	89.4621
1843.91	88.9169
1849.05	90.1734
1854.19	91.3955
1859.33	92.1427
1864.46	90.5129
1869.59	88.3324
1874.71	88.9788
1879.83	90.7075
1884.95	90.5686
1890.06	88.298
1895.17	85.8889
1900.27	86.0471
1905.38	88.8055
1910.47	90.3901
1915.57	92.1757
1920.66	92.7612
1925.74	92.1798
1930.83	90.3385
1935.91	87.3734
1940.98	85.461
1946.05	85.8771
1951.12	85.9807
1956.18	86.2458
1961.25	87.1651
1966.3	87.598
1971.35	88.2731
1976.4	89.3078
1981.45	91.0635
1986.49	92.2313
1991.53	87.8669
1996.56	84.9705
2001.59	86.119
2006.62	87.9805
2011.64	90.9873
2016.66	91.2529
2021.68	90.6535
2026.69	92.2789
2031.7	91.6213
2036.7	90.4397
2041.7	90.0224
2046.7	88.4473
2051.7	90.6205
2056.69	92.3719
2061.67	92.8982
2066.65	89.9296
2071.63	85.2726
2076.61	84.7692
2081.58	86.2612
2086.55	87.0283
2091.51	90.2542
2096.47	92.7435
2101.43	92.8912
2106.39	91.8557
2111.34	90.2375
2116.28	88.3317
2121.23	86.7543
2126.17	87.0217
2131.1	89.0945
2136.03	90.2859
2140.96	88.9335
2145.89	82.2878
2150.81	87.478
2155.73	87.2009
2160.64	85.401
2165.55	85.8931
2170.46	87.475
2175.36	88.8896
2180.26	88.7746
2185.16	88.8094
2190.05	86.1932
2194.94	84.1873
2199.83	82.6717
2204.71	81.9974
2209.59	83.6114
2214.46	84.8571
2219.33	86.5491
2224.2	86.5615
2229.07	86.9122
2233.93	87.2116
2238.79	84.8927
2243.64	83.1833
2248.49	84.5267
2253.34	85.6726
2258.18	85.8504
2263.02	87.3691
2267.86	88.1386
2272.69	87.2864
2277.52	85.6735
2282.35	84.105
2287.17	83.7695
2291.99	81.5638
2296.8	83.5484
2301.62	85.336
2306.43	85.4977
2311.23	86.0382
2316.03	79.2952
2320.83	84.6117
2325.63	90.8758
2330.42	88.4817
2335.21	87.6754
2339.99	87.6573
2344.77	85.3303
2349.55	84.0517
2354.32	83.7951
2359.1	85.3165
2363.86	86.7464
2368.63	85.5294
2373.39	81.5046
2378.15	82.5984
2382.9	84.02
2387.65	84.4937
2392.4	83.5581
2397.14	82.8798
2401.88	82.1946
2406.62	79.9506
2411.35	78.3468
2416.08	79.9335
2420.81	81.6708
2425.53	82.7673
2430.25	81.4934
2434.97	80.335
2439.69	80.078
2444.4	80.3867
2449.1	80.966
2453.81	82.4342
2458.51	81.2548
2463.2	77.6224
2467.9	77.9242
2472.59	80.3671
2477.27	81.0811
2481.96	83.2895
2486.64	86.4723
2491.31	83.378
2495.99	82.3473
2500.66	82.7169
2505.32	83.6639
2509.99	83.2208
2514.65	82.2944
2519.31	80.1385
2523.96	79.9089
2528.61	81.7439
2533.26	81.6234
2537.9	78.9085
2542.54	78.6582
2547.18	81.0187
2551.81	81.5696
2556.44	82.1585
2561.07	84.4663
2565.69	84.8029
2570.32	83.6322
2574.93	79.6334
2579.55	79.4816
2584.16	79.4639
2588.77	81.8371
2593.37	83.1104
2597.97	83.214
2602.57	81.822
2607.17	79.4125
2611.76	78.932
2616.35	79.8199
2620.93	80.3102
2625.51	80.1131
2630.09	79.0256
2634.67	77.4289
2639.24	77.5478
2643.81	79.1856
2648.38	80.3644
2652.94	79.7162
2657.5	79.1854
2662.06	78.8338
2666.61	78.4475
2671.16	78.6628
2675.71	81.0711
2680.25	79.942
2684.79	76.4059
2689.33	74.247
2693.86	76.3406
2698.39	80.887
2702.92	80.4674
2707.45	75.9218
2711.97	75.6707
2716.49	77.9415
2721	79.0568
2725.51	78.8846
2730.02	78.0604
2734.53	78.362
2739.03	79.1801
2743.53	78.9072
2748.03	78.3181
2752.52	76.7359
2757.01	73.0468
2761.5	75.8847
2765.98	78.3055
2770.46	78.354
2774.94	79.0741
2779.42	80.5464
2783.89	83.5349
2788.36	81.8861
2792.82	78.0741
2797.28	76.9203
2801.74	77.7732
2806.2	74.2382
2810.65	73.7989
2815.1	75.6757
2819.55	72.0707
2823.99	72.6858
2828.43	73.7757
2832.87	76.1564
2837.3	76.88
2841.74	74.8182
2846.17	74.0783
2850.59	74.1759
2855.01	75.8533
2859.43	76.4099
2863.85	76.1871
2868.26	75.757
2872.67	76.5451
2877.08	76.6445
2881.48	75.7258
2885.89	73.2225
2890.28	69.8757
2894.68	73.3317
2899.07	73.6505
2903.46	72.8932
2907.85	72.8277
2912.23	74.569
2916.61	73.6546
2920.98	74.5103
2925.36	76.3898
2929.73	75.1666
2934.1	73.5263
2938.46	73.2151
2942.82	71.6816
2947.18	74.2071
2951.54	74.4265
2955.89	72.0586
2960.24	71.1314
2964.59	71.7413
2968.93	68.6846
2973.27	70.8138
2977.61	73.0454
2981.95	74.3801
2986.28	72.7174
2990.61	68.2008
2994.94	67.4697
2999.26	71.2311
3003.58	71.3508
3007.9	71.8708
3012.21	72.4243
3016.52	73.0211
3020.83	71.7235
3025.14	70.5933
3029.44	71.8442
3033.74	72.4574
3038.04	73.6161
3042.33	73.6158
3046.62	71.3922
3050.91	72.587
3055.2	73.2069
3059.48	71.8822
3063.76	72.7782
3068.03	75.4503
3072.31	77.4763
3076.58	77.9549
3080.85	74.5454
3085.11	72.5317
3089.37	73.8535
3093.63	73.0039
3097.89	72.1027
3102.14	75.3697
3106.39	80.5445
3110.64	77.9588
3114.89	75.0974
3119.13	74.3043
3123.37	74.424
3127.6	75.9966
3131.84	74.543
3136.07	73.0012
3140.29	74.0792
3144.52	76.308
3148.74	77.7604
3152.96	76.5148
3157.18	76.0327
3161.39	74.0373
3165.6	73.884
3169.81	73.5531
3174.01	78.1493
3178.22	79.6759
3182.42	80.1611
3186.61	77.6675
3190.8	75.058
3195	74.5933
3199.18	75.2152
3203.37	77.0366
3207.55	77.7444
3211.73	77.4775
3215.91	77.2794
3220.08	79.5544
3224.25	80.3033
3228.42	79.7492
3232.59	78.8578
3236.75	77.3972
3240.91	77.5421
3245.07	76.549
3249.22	74.116
3253.37	75.8086
3257.52	77.3726
3261.67	73.9996
3265.81	75.19
3269.95	73.7453
3274.09	71.44
3278.22	72.7617
3282.36	74.1593
3286.49	74.0182
3290.61	74.5745
3294.74	70.5847
3298.86	69.3009
3302.98	71.957
3307.09	71.3066
3311.21	71.6753
3315.32	72.1204
3319.42	71.2169
3323.53	69.012
3327.63	68.7116
3331.73	70.0007
3335.83	67.7707
3339.92	71.3759
3344.01	74.2327
3348.1	74.9339
3352.19	72.8756
3356.27	70.4295
3360.35	70.9072
3364.43	71.6912
3368.5	72.8595
3372.58	74.2427
3376.65	75.6827
3380.71	75.3016
3384.78	74.2114
3388.84	73.7653
3392.9	73.9242
3396.95	74.1582
3401.01	73.3158
3405.06	73.0386
3409.1	70.8279
3413.15	71.4775
3417.19	76.0967
3421.23	76.5411
3425.27	76.1063
3429.31	74.9902
3433.34	74.8035
3437.37	73.9601
3441.39	73.5535
3445.42	72.7522
3449.44	71.4266
3453.46	70.2355
3457.47	69.38
3461.49	70.8647
3465.5	71.661
3469.51	72.6808
3473.51	70.3028
3477.52	68.6873
3481.52	69.659
3485.51	70.1256
3489.51	72.1846
3493.5	70.8608
3497.49	68.8386
3501.48	69.7085
3505.46	69.9142
3509.45	70.2309
3513.43	64.8033
3517.4	62.1066
3521.38	61.9789
3525.35	67.3867
3529.32	65.6579
3533.28	65.1274
3537.25	64.5364
3541.21	65.0542
3545.17	65.5635
3549.12	64.9837
3553.08	64.796
3557.03	66.6756
3560.98	66.9308
3564.92	66.2413
3568.87	64.7934
3572.81	65.9193
3576.74	68.0753
3580.68	71.2344
3584.61	73.844
3588.54	74.5819
3592.47	69.3861
3596.4	67.0153
3600.32	66.5397
3604.24	65.0597
3608.16	63.2422
3612.07	60.0103
3615.98	56.8596
3619.89	56.7243
3623.8	59.125
3627.71	57.199
3631.61	59.0799
3635.51	58.5804
3639.41	57.5478
3643.3	57.0378
3647.19	57.0432
3651.08	58.1263
3654.97	57.1715
3658.85	53.0448
3662.74	49.9704
3666.62	50.2178
3670.49	53.0928
3674.37	58.035
3678.24	56.458
3682.11	51.6561
3685.98	51.5901
3689.84	54.7385
3693.7	56.2994
3697.56	54.1423
3701.42	52.6445
3705.28	52.6547
3709.13	52.8619
3712.98	52.4308
3716.82	52.1222
3720.67	51.7595
3724.51	50.6337
3728.35	48.9028
3732.19	50.8595
3736.02	53.8687
3739.86	54.0605
3743.69	53.5096
3747.51	51.4772
3751.34	53.0851
3755.16	51.8476
3758.98	50.3683
3762.8	52.0854
3766.61	52.1352
3770.43	52.2529
3774.24	51.5906
3778.05	52.0921
3781.85	52.5847
3785.65	52.7505
3789.45	52.5037
3793.25	52.0612
3797.05	51.6635
3800.84	52.2167
3804.63	50.8257
3808.42	49.2373
3812.21	48.4836
3815.99	48.5812
3819.77	49.5918
3823.55	49.5134
3827.33	49.3333
3831.1	48.5862
3834.87	49.083
3838.64	51.613
3842.41	50.8323
3846.17	49.9903
3849.93	49.3185
3853.69	48.2085
3857.45	47.7454
3861.21	48.3099
3864.96	49.8494
3868.71	50.7732
3872.46	50.9223
3876.2	50.796
3879.94	50.4771
3883.68	49.5881
3887.42	47.2549
3891.16	45.9923
3894.89	46.9043
3898.62	48.7785
3902.35	47.2682
3906.08	47.3688
3909.8	48.8848
3913.52	48.9271
3917.24	50.8728
3920.96	51.0215
3924.67	50.6964
3928.38	48.6556
3932.09	46.8201
3935.8	48.1437
3939.51	49.3204
3943.21	50.2674
3946.91	45.4676
3950.61	46.3165
3954.3	45.3126
3958	45.4428
3961.69	47.9028
3965.38	48.5675
3969.06	48.3385
3972.75	47.9512
3976.43	45.9173
3980.11	46.341
3983.78	48.5765
3987.46	46.9504
3991.13	45.6257
3994.8	44.2805
3998.47	48.2614