File: Data/3-Raman/raw/20-C_brt1_FI09_1.txt
#Acq. time (s)=	20
#Accumulations=	3
#Range (cm-¹)=	100...4000
#Windows=	1
#Auto scanning=	Off
#Autofocus=	Off
#Macrospot=	Off
#AutoExposure=	Off
#Spike filter=	Multiple accum.
#Delay time (s)=	0
#Binning=	1
#Readout mode=	Signal
#DeNoise=	Lite
#ICS correction=	Off
#Dark correction=	Off
#Inst. Process=	Off
#Detector temperature (°C)=	-60.09
#Instrument=	LabRAM HR Evol
#Detector=	SIN-EM FIVIS
#Objective=	x50_VIS_LWD
#Grating=	150 (500nm)
#ND Filter=	100%
#Laser=	633nm_Edge
#Hole=	30.0125
#Temperature=	0
#Range=	Visible
#StageXY=	75x50mm Scan+
#StageZ=	Z motor
#X (µm)=	7287.7
#Y (µm)=	4714.8
#Z (µm)=	-60.7
#Full time(mm:ss)=	1:03
#Project=	Buranga
#Sample=	BU18FA20_C
#Site=	C_Bertoss1
#Title=	20-C_brt1_FI09_1
#Remark=
#Date=	30.07.2019 14:48
#Acquired=	30.07.2019 14:48:25
100.38	257.603
106.898	217.467
113.411	187.136
119.918	167.638
126.419	152.465
132.916	142.553
139.407	135.721
145.892	130.208
152.372	121.243
158.847	119.234
165.316	120.042
171.781	120.92
178.239	112.636
184.693	105.365
191.139	99.0104
197.582	96.9188
204.02	99.8791
210.452	100.598
216.877	98.3064
223.299	100.18
229.715	105.598
236.126	127.155
242.53	142.733
248.931	138.184
255.326	123.269
261.714	116.522
268.099	115.412
274.477	118.244
280.851	129.891
287.218	150.483
293.582	157.911
299.939	133.665
306.293	112.567
312.639	105.633
318.982	112.864
325.318	138.119
331.651	172.36
337.977	161.586
344.297	135.359
350.614	114.39
356.925	114.064
363.23	119.633
369.53	120.95
375.827	114.64
382.116	104.675
388.401	98.8061
394.681	97.076
400.956	100.484
407.226	105.538
413.49	108.464
419.749	111.728
426.003	109.421
432.252	123.274
438.496	147.746
444.735	157.277
450.969	152.197
457.197	139.628
463.421	132.647
469.64	126.179
475.853	117.193
482.062	108.273
488.265	105.115
494.464	103.872
500.657	107.236
506.844	110.47
513.028	114.881
519.206	117.576
525.38	114.122
531.548	109.857
537.71	104.319
543.869	101.373
550.022	104.711
556.169	104.157
562.313	101.377
568.452	99.9661
574.584	100.04
580.713	101.273
586.837	103.515
592.954	110.443
599.068	127.812
605.176	146.348
611.28	149.387
617.378	139.232
623.473	129.714
629.561	124.563
635.644	125.848
641.724	127.558
647.797	124.965
653.867	128.067
659.931	134.602
665.99	132.465
672.044	121.113
678.095	108.675
684.139	98.5705
690.179	98.5394
696.213	93.9368
702.245	90.7087
708.27	90.252
714.29	90.3587
720.306	92.7749
726.316	93.4771
732.322	90.0742
738.323	88.6143
744.32	89.9025
750.311	95.738
756.298	91.728
762.28	92.6022
768.258	93.9116
774.23	92.726
780.198	90.8757
786.161	89.5326
792.119	88.8819
798.073	89.6584
804.021	91.0391
809.965	92.832
815.904	96.0481
821.839	95.9604
827.769	93.6973
833.693	92.7432
839.614	93.1372
845.53	94.1197
851.44	95.7007
857.346	94.0847
863.248	93.5129
869.144	92.2173
875.037	91.4456
880.924	95.6836
886.807	99.422
892.685	99.3435
898.559	98.1665
904.427	97.0777
910.292	97.0873
916.151	97.8841
922.006	96.9683
927.856	95.1503
933.701	97.9474
939.543	104.348
945.379	113.974
951.21	114.704
957.037	125.954
962.861	132.091
968.678	138.873
974.491	133.466
980.3	160.88
986.104	210.331
991.904	247.631
997.699	260.143
1003.49	228.713
1009.28	196.159
1015.06	171.967
1020.83	182.841
1026.61	200.672
1032.37	209.815
1038.14	178.821
1043.9	146.563
1049.65	127.808
1055.4	121.681
1061.15	117.203
1066.88	109.798
1072.62	105.256
1078.35	106.442
1084.08	118.579
1089.8	126.847
1095.52	131.725
1101.23	137.175
1106.94	140.848
1112.65	123.577
1118.35	106.193
1124.05	101.634
1129.74	100.906
1135.42	98.5621
1141.11	105.333
1146.78	112.218
1152.46	118.798
1158.13	128.602
1163.79	117.855
1169.45	98.6208
1175.11	91.6521
1180.76	89.8177
1186.41	88.4257
1192.05	86.1023
1197.69	83.59
1203.32	85.1444
1208.95	86.1201
1214.58	83.1485
1220.2	83.2961
1225.82	83.5668
1231.43	79.2906
1237.04	80.9256
1242.64	80.8115
1248.24	82.3968
1253.83	86.1139
1259.42	87.4372
1265.01	86.805
1270.59	87.0322
1276.17	86.2984
1281.74	137.917
1287.31	144.08
1292.88	87.247
1298.44	86.254
1303.99	85.5428
1309.55	84.0226
1315.09	81.0029
1320.64	79.6148
1326.18	81.9755
1331.71	83.3649
1337.24	82.6175
1342.77	81.5823
1348.29	81.2617
1353.81	83.2823
1359.32	86.2856
1364.83	89.1628
1370.33	88.9279
1375.84	84.8497
1381.33	84.4218
1386.82	232
1392.31	125
1397.8	87.2874
1403.28	85.4612
1408.75	90.3671
1414.22	87.2666
1419.69	81.4737
1425.15	76.6366
1430.61	74.8797
1436.07	78.0118
1441.52	80.9485
1446.96	79.4968
1452.41	75.7502
1457.84	76.087
1463.28	77.5284
1468.71	78.987
1474.13	78.0552
1479.55	76.0109
1484.97	76.0364
1490.39	77.8825
1495.79	79.1571
1501.2	79.7735
1506.6	79.4453
1512	77.6539
1517.39	75.6772
1522.78	74.0452
1528.16	73.9941
1533.54	75.4751
1538.92	76.6498
1544.29	75.5283
1549.66	74.7128
1555.02	75.9199
1560.38	75.4182
1565.74	74.5622
1571.09	76.1446
1576.44	77.1004
1581.78	77.7064
1587.12	75.6472
1592.46	75.8638
1597.79	79.1299
1603.12	77.339
1608.44	77.2053
1613.76	77.6289
1619.08	77.9332
1624.39	76.5027
1629.7	74.5345
1635	77.2263
1640.3	76.4997
1645.59	73.742
1650.88	71.3603
1656.17	70.5232
1661.46	75.7222
1666.74	77.5975
1672.01	76.2867
1677.28	76.399
1682.55	75.5979
1687.82	74.5669
1693.07	73.7531
1698.33	75.1289
1703.58	74.2682
1708.83	74.4537
1714.07	77.0164
1719.31	75.1884
1724.55	73.311
1729.78	74.27
1735.01	74.8329
1740.23	75.0507
1745.46	75.8196
1750.67	75.8313
1755.89	77.7317
1761.09	74.9578
1766.3	73.627
1771.5	73.5702
1776.7	75.2388
1781.89	75.0226
1787.08	74.3913
1792.27	73.3077
1797.45	78.4289
1802.62	68.619
1807.8	72.3398
1812.97	75.6599
1818.14	73.5015
1823.3	71.6024
1828.46	73.9487
1833.61	75.923
1838.76	74.1768
1843.91	71.0945
1849.05	70.8276
1854.19	74.7566
1859.33	74.6898
1864.46	73.5624
1869.59	72.2791
1874.71	71.9412
1879.83	72.0031
1884.95	73.2146
1890.06	73.4962
1895.17	73.5118
1900.27	74.0672
1905.38	73.2905
1910.47	74.4006
1915.57	76.2758
1920.66	70.3889
1925.74	71.9158
1930.83	74.6291
1935.91	75.482
1940.98	75.4344
1946.05	74.919
1951.12	75.0368
1956.18	74.7804
1961.25	73.7077
1966.3	75.9388
1971.35	74.7042
1976.4	73.8734
1981.45	76.2246
1986.49	75.8424
1991.53	73.0395
1996.56	74.052
2001.59	76.3936
2006.62	77.9142
2011.64	77.1625
2016.66	73.2092
2021.68	74.6141
2026.69	76.5592
2031.7	76.3043
2036.7	74.4727
2041.7	74.1396
2046.7	76.001
2051.7	78.9294
2056.69	76.7224
2061.67	75.4405
2066.65	74.4654
2071.63	74.8703
2076.61	76.7757
2081.58	75.5
2086.55	74.6919
2091.51	75.5754
2096.47	74.0401
2101.43	72.43
2106.39	73.606
2111.34	73.7863
2116.28	74.1945
2121.23	74.6734
2126.17	73.0193
2131.1	75.0583
2136.03	76.358
2140.96	75.6559
2145.89	75.5892
2150.81	75.095
2155.73	73.8718
2160.64	74.702
2165.55	73.5627
2170.46	74.7256
2175.36	75.6838
2180.26	74.0668
2185.16	73.2418
2190.05	73.4166
2194.94	74.2033
2199.83	72.7507
2204.71	73.5663
2209.59	75.8432
2214.46	72.8838
2219.33	70.9225
2224.2	72.3507
2229.07	74.2004
2233.93	74.1894
2238.79	75.3275
2243.64	71.933
2248.49	73.397
2253.34	73.3823
2258.18	74.1009
2263.02	76.0429
2267.86	73.3879
2272.69	73.3469
2277.52	74.5478
2282.35	75.6055
2287.17	76.0271
2291.99	75.3042
2296.8	74.184
2301.62	73.305
2306.43	71.2586
2311.23	72.3368
2316.03	75.0666
2320.83	75.7621
2325.63	75.7357
2330.42	75.5915
2335.21	74.5498
2339.99	72.2926
2344.77	72.4187
2349.55	73.8032
2354.32	72.1219
2359.1	69.9209
2363.86	69.3196
2368.63	69.9429
2373.39	71.873
2378.15	73.4075
2382.9	73.6179
2387.65	72.8463
2392.4	72.4051
2397.14	72.5002
2401.88	71.6219
2406.62	70.6472
2411.35	72.8501
2416.08	75.0439
2420.81	74.7545
2425.53	75.3274
2430.25	75.8301
2434.97	76.741
2439.69	76.6789
2444.4	73.2633
2449.1	72.4269
2453.81	75.8684
2458.51	73.815
2463.2	70.5245
2467.9	72.1522
2472.59	73.5931
2477.27	72.1202
2481.96	71.8186
2486.64	73.0318
2491.31	74.4824
2495.99	74.1399
2500.66	73.2468
2505.32	72.8347
2509.99	73.595
2514.65	75.198
2519.31	75.2866
2523.96	73.65
2528.61	70.8194
2533.26	71.5233
2537.9	74.2207
2542.54	73.527
2547.18	72.7253
2551.81	71.9899
2556.44	71.3072
2561.07	70.1792
2565.69	69.1721
2570.32	70.6161
2574.93	70.6684
2579.55	70.4046
2584.16	71.4448
2588.77	70.541
2593.37	70.293
2597.97	72.4821
2602.57	71.8496
2607.17	69.0528
2611.76	69.2501
2616.35	67.3947
2620.93	72.0245
2625.51	74.5368
2630.09	74.2231
2634.67	73.061
2639.24	71.9203
2643.81	70.2637
2648.38	68.1245
2652.94	68.282
2657.5	72.2213
2662.06	70.0514
2666.61	68.856
2671.16	72.7256
2675.71	68.9241
2680.25	69.5662
2684.79	70.3273
2689.33	71.7099
2693.86	70.881
2698.39	69.5565
2702.92	68.7182
2707.45	67.8749
2711.97	67.7388
2716.49	68.1938
2721	69.3814
2725.51	69.8045
2730.02	68.9063
2734.53	67.5345
2739.03	67.3241
2743.53	68.9395
2748.03	69.8348
2752.52	70.5174
2757.01	71.0251
2761.5	71.0164
2765.98	70.6223
2770.46	69.5842
2774.94	70.0015
2779.42	70.8417
2783.89	69.1131
2788.36	67.5014
2792.82	68.9267
2797.28	66.136
2801.74	64.3724
2806.2	64.1362
2810.65	66.7566
2815.1	68.3612
2819.55	68.7379
2823.99	69.4261
2828.43	70.0536
2832.87	71.2819
2837.3	71.1968
2841.74	70.2184
2846.17	68.6516
2850.59	67.1374
2855.01	68.0819
2859.43	69.036
2863.85	69.8094
2868.26	67.436
2872.67	64.6236
2877.08	62.745
2881.48	64.8138
2885.89	67.8405
2890.28	68.002
2894.68	65.7291
2899.07	64.3995
2903.46	66.8148
2907.85	69.4351
2912.23	68.3136
2916.61	67.4977
2920.98	67.9748
2925.36	68.706
2929.73	67.3545
2934.1	67.2954
2938.46	66.0517
2942.82	65.995
2947.18	69.3068
2951.54	67.5117
2955.89	67.1438
2960.24	68.0518
2964.59	67.0152
2968.93	64.3801
2973.27	63.7112
2977.61	64.7215
2981.95	67.1245
2986.28	69.6314
2990.61	68.1777
2994.94	64.3377
2999.26	61.713
3003.58	62.8643
3007.9	64.8002
3012.21	67.1635
3016.52	66.2763
3020.83	64.4879
3025.14	64.9315
3029.44	66.9143
3033.74	67.7259
3038.04	68.3981
3042.33	66.8176
3046.62	64.6031
3050.91	63.5668
3055.2	64.0934
3059.48	66.4118
3063.76	67.7744
3068.03	64.1814
3072.31	61.9876
3076.58	62.1629
3080.85	64.5269
3085.11	66.3145
3089.37	66.9652
3093.63	67.2072
3097.89	67.6696
3102.14	67.6911
3106.39	69.1799
3110.64	70.0151
3114.89	70.4469
3119.13	67.9658
3123.37	64.4695
3127.6	64.9934
3131.84	68.7958
3136.07	69.7904
3140.29	68.1108
3144.52	65.2325
3148.74	62.7317
3152.96	63.3531
3157.18	66.6898
3161.39	68.0679
3165.6	69.1387
3169.81	66.7846
3174.01	63.5309
3178.22	62.5871
3182.42	63.9724
3186.61	67.8051
3190.8	69.4508
3195	67.9904
3199.18	68.4883
3203.37	68.375
3207.55	66.7861
3211.73	67.637
3215.91	68.0962
3220.08	68.2476
3224.25	66.4095
3228.42	70.5927
3232.59	69.0621
3236.75	68.067
3240.91	69.3831
3245.07	66.545
3249.22	63.7154
3253.37	62.7231
3257.52	62.6957
3261.67	63.2034
3265.81	64.5993
3269.95	61.7604
3274.09	61.4236
3278.22	62.3742
3282.36	52.9689
3286.49	64.6185
3290.61	65.898
3294.74	53.1665
3298.86	61.5294
3302.98	61.7536
3307.09	60.2231
3311.21	59.169
3315.32	60.0441
3319.42	60.6102
3323.53	60.2877
3327.63	58.6197
3331.73	57.7914
3335.83	57.8379
3339.92	59.6741
3344.01	59.9076
3348.1	59.8436
3352.19	60.4958
3356.27	60.7239
3360.35	58.9358
3364.43	58.7244
3368.5	60.6403
3372.58	62.4701
3376.65	63.264
3380.71	63.9696
3384.78	63.4618
3388.84	62.7403
3392.9	61.2261
3396.95	59.6761
3401.01	57.6529
3405.06	55.7837
3409.1	62.9366
3413.15	60.2909
3417.19	60.4065
3421.23	62.495
3425.27	62.7271
3429.31	57.9335
3433.34	64.836
3437.37	62.8331
3441.39	60.5718
3445.42	59.7769
3449.44	59.1031
3453.46	60.2604
3457.47	60.7802
3461.49	60.7479
3465.5	59.7017
3469.51	57.3986
3473.51	56.3262
3477.52	56.6284
3481.52	58.6862
3485.51	57.5282
3489.51	58.2955
3493.5	59.8836
3497.49	58.5133
3501.48	56.5109
3505.46	56.1994
3509.45	56.6475
3513.43	55.0579
3517.4	56.5445
3521.38	58.4395
3525.35	58.7294
3529.32	57.4301
3533.28	54.9968
3537.25	53.8251
3541.21	53.659
3545.17	53.4041
3549.12	55.0556
3553.08	54.6949
3557.03	54.5869
3560.98	55.3467
3564.92	55.8678
3568.87	55.8548
3572.81	55.639
3576.74	54.625
3580.68	56.4699
3584.61	59.779
3588.54	61.8986
3592.47	60.6593
3596.4	57.8029
3600.32	54.7138
3604.24	53.0321
3608.16	51.166
3612.07	52.9247
3615.98	52.5644
3619.89	51.1067
3623.8	51.9001
3627.71	51.189
3631.61	49.2028
3635.51	50.3983
3639.41	50.3619
3643.3	48.9842
3647.19	48.6294
3651.08	48.7694
3654.97	49.1993
3658.85	48.5096
3662.74	46.8595
3666.62	49.3342
3670.49	51.1687
3674.37	50.433
3678.24	50.4635
3682.11	49.4242
3685.98	48.4257
3689.84	48.478
3693.7	49.857
3697.56	50.4169
3701.42	50.1801
3705.28	49.4561
3709.13	48.453
3712.98	47.1438
3716.82	45.6073
3720.67	44.8354
3724.51	46.468
3728.35	49.24
3732.19	47.9769
3736.02	45.6977
3739.86	47.1879
3743.69	47.4417
3747.51	47.0691
3751.34	46.5404
3755.16	47.3113
3758.98	45.4195
3762.8	43.7716
3766.61	44.8626
3770.43	47.4837
3774.24	50.22
3778.05	48.5168
3781.85	46.752
3785.65	45.9666
3789.45	45.9892
3793.25	46.5015
3797.05	46.098
3800.84	45.8618
3804.63	46.784
3808.42	47.0339
3812.21	46.0716
3815.99	45.0022
3819.77	44.8571
3823.55	44.6861
3827.33	44.0785
3831.1	44.0125
3834.87	42.6285
3838.64	44.0322
3842.41	44.0647
3846.17	44.0053
3849.93	43.3689
3853.69	43.7826
3857.45	42.9322
3861.21	41.6493
3864.96	41.7563
3868.71	42.9738
3872.46	44.953
3876.2	46.4674
3879.94	46.5057
3883.68	43.1507
3887.42	41.8725
3891.16	43.3524
3894.89	43.9615
3898.62	44.0834
3902.35	42.9057
3906.08	40.0921
3909.8	41.1041
3913.52	44.2432
3917.24	44.4523
3920.96	43.2276
3924.67	43.2008
3928.38	42.9801
3932.09	43.7081
3935.8	40.7832
3939.51	39.7383
3943.21	40.3872
3946.91	41.8144
3950.61	42.6701
3954.3	43.0747
3958	40.375
3961.69	39.1389
3965.38	43.1424
3969.06	41.2848
3972.75	40.7623
3976.43	42.509
3980.11	42.7361
3983.78	42.5224
3987.46	41.7487
3991.13	41.5266
3994.8	43.5672
3998.47	40.0816