File: Data/3-Raman/raw/20-C_brt1_FI10.txt
#Acq. time (s)=	20
#Accumulations=	3
#Range (cm-¹)=	100...4000
#Windows=	1
#Auto scanning=	Off
#Autofocus=	Off
#Macrospot=	Off
#AutoExposure=	Off
#Spike filter=	Multiple accum.
#Delay time (s)=	0
#Binning=	1
#Readout mode=	Signal
#DeNoise=	Lite
#ICS correction=	Off
#Dark correction=	Off
#Inst. Process=	Off
#Detector temperature (°C)=	-60.09
#Instrument=	LabRAM HR Evol
#Detector=	SIN-EM FIVIS
#Objective=	x50_VIS_LWD
#Grating=	150 (500nm)
#ND Filter=	100%
#Laser=	633nm_Edge
#Hole=	30.0125
#Temperature=	0
#Range=	Visible
#StageXY=	75x50mm Scan+
#StageZ=	Z motor
#X (µm)=	7377.7
#Y (µm)=	4349.7
#Z (µm)=	-28.6
#Full time(mm:ss)=	1:02
#Project=	Buranga
#Sample=	BU18FA20_C
#Site=	C_Bertoss1
#Title=	20-C_brt1_FI10
#Remark=
#Date=	30.07.2019 14:35
#Acquired=	30.07.2019 14:35:08
100.38	491.067
106.898	407.84
113.411	341.689
119.918	295.197
126.419	250.878
132.916	217.883
139.407	202.128
145.892	189.354
152.372	178.058
158.847	162.188
165.316	151.236
171.781	160.822
178.239	146.669
184.693	136.871
191.139	135.187
197.582	132.933
204.02	130.049
210.452	126.749
216.877	125.884
223.299	127.044
229.715	132.336
236.126	162.799
242.53	255.144
248.931	225.338
255.326	178.529
261.714	163.634
268.099	163.72
274.477	175.3
280.851	204.961
287.218	285.775
293.582	273.414
299.939	212.568
306.293	167.631
312.639	145.668
318.982	148.598
325.318	184.206
331.651	288.853
337.977	276.31
344.297	193.283
350.614	153.98
356.925	144.907
363.23	166.103
369.53	186.882
375.827	180.581
382.116	151.523
388.401	127.798
394.681	113.576
400.956	107.88
407.226	111.757
413.49	118.865
419.749	127.114
426.003	143.8
432.252	174.847
438.496	211.898
444.735	234.413
450.969	229.217
457.197	211.831
463.421	189.584
469.64	166.146
475.853	136.833
482.062	119.571
488.265	118.602
494.464	118.308
500.657	118.677
506.844	120.081
513.028	123.023
519.206	125.344
525.38	124.262
531.548	123.832
537.71	119.41
543.869	115.733
550.022	113.267
556.169	111.941
562.313	111.85
568.452	108.978
574.584	105.159
580.713	103.206
586.837	109.425
592.954	125.125
599.068	156.43
605.176	214.768
611.28	213.885
617.378	181.492
623.473	171.943
629.561	178.094
635.644	184.398
641.724	182.935
647.797	172.908
653.867	172.425
659.931	191.676
665.99	197.586
672.044	170.431
678.095	137.436
684.139	113.24
690.179	99.2211
696.213	93.5062
702.245	91.0806
708.27	89.7534
714.29	90.0454
720.306	89.4323
726.316	88.138
732.322	85.6539
738.323	86.3294
744.32	86.8488
750.311	85.8894
756.298	86.337
762.28	87.0088
768.258	86.7526
774.23	84.6945
780.198	82.7198
786.161	82.292
792.119	79.3323
798.073	80.9144
804.021	84.1706
809.965	83.1675
815.904	82.2102
821.839	83.4383
827.769	86.6529
833.693	88.9274
839.614	89.0357
845.53	87.4147
851.44	85.901
857.346	85.5494
863.248	86.5394
869.144	87.5356
875.037	89.0767
880.924	92.6269
886.807	95.8572
892.685	95.8382
898.559	95.8126
904.427	93.9908
910.292	92.2809
916.151	92.5658
922.006	95.0267
927.856	96.4965
933.701	98.6318
939.543	105.508
945.379	119.456
951.21	140.15
957.037	164.857
962.861	180.53
968.678	191.191
974.491	213.588
980.3	255.973
986.104	310.552
991.904	454.12
997.699	479.765
1003.49	389.783
1009.28	327.063
1015.06	293.138
1020.83	319.954
1026.61	367.197
1032.37	399.117
1038.14	301.853
1043.9	212.108
1049.65	179.663
1055.4	161.036
1061.15	147.144
1066.88	133.72
1072.62	128.513
1078.35	136.595
1084.08	156.208
1089.8	174.748
1095.52	181.477
1101.23	188.167
1106.94	199.643
1112.65	166.161
1118.35	131.053
1124.05	109.233
1129.74	103.96
1135.42	107.289
1141.11	114.05
1146.78	125.518
1152.46	138.652
1158.13	160.549
1163.79	145.48
1169.45	114.26
1175.11	100.924
1180.76	96.2077
1186.41	92.8005
1192.05	87.2373
1197.69	82.0856
1203.32	77.7326
1208.95	75.4818
1214.58	74.4861
1220.2	74.4494
1225.82	75.5208
1231.43	76.9049
1237.04	76.7847
1242.64	74.7021
1248.24	72.747
1253.83	72.5253
1259.42	80.851
1265.01	88.5086
1270.59	87.5244
1276.17	89.9953
1281.74	186
1287.31	240
1292.88	86.2034
1298.44	79.5769
1303.99	76.76
1309.55	75.7602
1315.09	75.9228
1320.64	75.6421
1326.18	74.3922
1331.71	73.4182
1337.24	73.5869
1342.77	74.364
1348.29	72.9844
1353.81	71.6259
1359.32	73.6126
1364.83	76.052
1370.33	80.7477
1375.84	81.2209
1381.33	91.0527
1386.82	398
1392.31	190
1397.8	87.9888
1403.28	75.358
1408.75	100.201
1414.22	89.7519
1419.69	80.4802
1425.15	75.7739
1430.61	71.295
1436.07	68.8746
1441.52	67.7607
1446.96	68.7449
1452.41	70.2291
1457.84	67.0898
1463.28	65.1402
1468.71	66.0154
1474.13	67.9285
1479.55	64.2254
1484.97	65.6499
1490.39	67.4961
1495.79	69.1379
1501.2	68.6328
1506.6	64.7907
1512	63.1807
1517.39	64.0373
1522.78	65.3791
1528.16	65.082
1533.54	63.8648
1538.92	64.5945
1544.29	65.2656
1549.66	65.3755
1555.02	64.7058
1560.38	63.052
1565.74	62.8436
1571.09	64.8033
1576.44	66.0541
1581.78	66.3944
1587.12	66.2383
1592.46	68.6272
1597.79	68.8274
1603.12	67.598
1608.44	66.0347
1613.76	66.2159
1619.08	67.7876
1624.39	68.3897
1629.7	67.8313
1635	66.8645
1640.3	65.9279
1645.59	65.0754
1650.88	64.3355
1656.17	63.8896
1661.46	63.7745
1666.74	65.1589
1672.01	66.007
1677.28	65.7498
1682.55	64.887
1687.82	64.5796
1693.07	65.7988
1698.33	66.3638
1703.58	67.9892
1708.83	65.7366
1714.07	63.3004
1719.31	61.8881
1724.55	61.1923
1729.78	61.2775
1735.01	63.0301
1740.23	64.5885
1745.46	62.0852
1750.67	60.2989
1755.89	60.7194
1761.09	61.4296
1766.3	61.7051
1771.5	62.1061
1776.7	62.8553
1781.89	64.2711
1787.08	64.6576
1792.27	62.8534
1797.45	61.8114
1802.62	63.2131
1807.8	64.3755
1812.97	64.3236
1818.14	63.0426
1823.3	61.9844
1828.46	62.4279
1833.61	62.7327
1838.76	64.3998
1843.91	64.8656
1849.05	63.756
1854.19	61.7132
1859.33	59.1695
1864.46	58.5912
1869.59	63.6019
1874.71	61.1553
1879.83	59.7645
1884.95	63.2085
1890.06	63.6478
1895.17	63.1815
1900.27	62.5132
1905.38	61.8105
1910.47	62.4284
1915.57	62.0708
1920.66	61.0081
1925.74	59.8638
1930.83	59.2662
1935.91	61.001
1940.98	62.0459
1946.05	63.6879
1951.12	64.3766
1956.18	64.7
1961.25	64.0297
1966.3	63.4091
1971.35	64.49
1976.4	64.2593
1981.45	63.2785
1986.49	63.3869
1991.53	63.7458
1996.56	63.1257
2001.59	61.9351
2006.62	61.2419
2011.64	60.9166
2016.66	57.82
2021.68	59.2908
2026.69	62.9128
2031.7	64.7474
2036.7	65.8555
2041.7	66.1709
2046.7	60.3299
2051.7	62.7663
2056.69	64.3575
2061.67	64.3216
2066.65	63.1281
2071.63	61.6836
2076.61	61.3784
2081.58	62.3702
2086.55	63.4433
2091.51	63.7215
2096.47	62.8655
2101.43	61.3909
2106.39	60.9265
2111.34	62.1142
2116.28	63.4994
2121.23	63.6496
2126.17	62.7946
2131.1	62.1825
2136.03	62.9375
2140.96	63.7701
2145.89	62.6062
2150.81	62.1208
2155.73	61.1508
2160.64	59.8503
2165.55	59.3583
2170.46	61.1304
2175.36	63.0046
2180.26	64.5388
2185.16	64.0198
2190.05	64.5147
2194.94	61.1663
2199.83	55.6067
2204.71	62.3595
2209.59	64.3191
2214.46	64.2305
2219.33	62.527
2224.2	62.6494
2229.07	62.3093
2233.93	62.9397
2238.79	63.3056
2243.64	62.9839
2248.49	62.4115
2253.34	62.8562
2258.18	60.7431
2263.02	61.0066
2267.86	63.0923
2272.69	63.8528
2277.52	63.2492
2282.35	61.9046
2287.17	59.4819
2291.99	60.6336
2296.8	63.2318
2301.62	64.9309
2306.43	64.0857
2311.23	63.2518
2316.03	63.3498
2320.83	65.0589
2325.63	66.902
2330.42	69.5965
2335.21	66.8042
2339.99	64.3706
2344.77	66.4586
2349.55	67.2003
2354.32	64.7396
2359.1	61.302
2363.86	60.5317
2368.63	60.6954
2373.39	60.8589
2378.15	59.8639
2382.9	60.6168
2387.65	61.0312
2392.4	61.522
2397.14	62.2254
2401.88	61.2276
2406.62	58.2468
2411.35	60.5081
2416.08	61.8606
2420.81	61.9491
2425.53	62.9667
2430.25	62.0424
2434.97	61.5251
2439.69	61.0256
2444.4	61.9944
2449.1	63.6056
2453.81	62.249
2458.51	60.0111
2463.2	59.3916
2467.9	60.5492
2472.59	63.0768
2477.27	62.421
2481.96	60.2315
2486.64	60.1435
2491.31	61.0084
2495.99	61.1604
2500.66	60.9108
2505.32	59.9455
2509.99	58.3147
2514.65	58.8432
2519.31	60.1877
2523.96	60.8631
2528.61	60.9196
2533.26	59.2154
2537.9	59.2108
2542.54	60.5245
2547.18	63.3225
2551.81	64.4457
2556.44	63.915
2561.07	61.3983
2565.69	57.904
2570.32	58.6757
2574.93	60.0742
2579.55	62.466
2584.16	62.4046
2588.77	61.6288
2593.37	60.9743
2597.97	60.7331
2602.57	61.1191
2607.17	60.655
2611.76	63.0396
2616.35	60.5925
2620.93	60.2246
2625.51	61.6362
2630.09	61.8487
2634.67	61.7489
2639.24	62.2524
2643.81	61.5879
2648.38	60.7554
2652.94	59.3859
2657.5	57.6166
2662.06	56.801
2666.61	58.4146
2671.16	60.5225
2675.71	62.2121
2680.25	63.7424
2684.79	63.6198
2689.33	62.9946
2693.86	61.1138
2698.39	60.9402
2702.92	59.7632
2707.45	57.8249
2711.97	55.9354
2716.49	57.8935
2721	59.9794
2725.51	61.2833
2730.02	61.9154
2734.53	62.3387
2739.03	60.5519
2743.53	59.6784
2748.03	60.7497
2752.52	62.3129
2757.01	63.3188
2761.5	63.8888
2765.98	63.1726
2770.46	61.8975
2774.94	59.8429
2779.42	58.601
2783.89	57.8978
2788.36	59.6259
2792.82	60.0123
2797.28	60.1767
2801.74	61.2414
2806.2	57.1573
2810.65	58.8369
2815.1	60.5673
2819.55	54.6968
2823.99	55.7744
2828.43	57.7163
2832.87	55.7137
2837.3	60.4012
2841.74	60.1191
2846.17	58.4811
2850.59	57.952
2855.01	56.9536
2859.43	57.7595
2863.85	58.4937
2868.26	59.1987
2872.67	60.3274
2877.08	59.3658
2881.48	59.8458
2885.89	61.2964
2890.28	62.1676
2894.68	60.0125
2899.07	57.9005
2903.46	56.6366
2907.85	56.7466
2912.23	58.3836
2916.61	59.3216
2920.98	57.1969
2925.36	57.4448
2929.73	56.857
2934.1	56.6238
2938.46	55.7217
2942.82	56.6495
2947.18	59.2046
2951.54	58.9525
2955.89	57.9021
2960.24	58.7626
2964.59	58.0184
2968.93	58.7239
2973.27	59.8888
2977.61	58.7556
2981.95	56.6488
2986.28	56.6819
2990.61	55.3804
2994.94	59.6026
2999.26	59.7676
3003.58	59.0265
3007.9	57.9972
3012.21	57.4848
3016.52	58.2506
3020.83	57.8176
3025.14	57.8319
3029.44	58.4696
3033.74	57.9543
3038.04	57.0903
3042.33	55.3657
3046.62	57.3878
3050.91	57.6286
3055.2	57.3051
3059.48	58.1192
3063.76	58.0656
3068.03	58.5634
3072.31	59.1102
3076.58	60.8393
3080.85	59.8113
3085.11	56.3564
3089.37	57.5534
3093.63	58.9219
3097.89	59.1242
3102.14	59.1761
3106.39	59.3393
3110.64	60.2536
3114.89	58.8251
3119.13	59.7646
3123.37	59.7797
3127.6	60.7283
3131.84	61.5898
3136.07	59.4357
3140.29	62.2139
3144.52	63.1583
3148.74	61.9088
3152.96	60.4801
3157.18	61.4497
3161.39	60.8982
3165.6	60.4525
3169.81	62.0567
3174.01	61.849
3178.22	63.6962
3182.42	65.1476
3186.61	64.5962
3190.8	62.7378
3195	62.3241
3199.18	61.7345
3203.37	62.724
3207.55	66.007
3211.73	65.3578
3215.91	64.8911
3220.08	62.8346
3224.25	61.2864
3228.42	62.324
3232.59	64.6339
3236.75	63.552
3240.91	62.2851
3245.07	59.8656
3249.22	60.8446
3253.37	60.7843
3257.52	61.1638
3261.67	59.1211
3265.81	58.0635
3269.95	56.7237
3274.09	55.718
3278.22	55.3252
3282.36	57.8371
3286.49	58.5925
3290.61	58.9233
3294.74	56.9706
3298.86	55.4317
3302.98	55.509
3307.09	55.2642
3311.21	55.3138
3315.32	57.7748
3319.42	57.0431
3323.53	58.0078
3327.63	57.3176
3331.73	57.386
3335.83	58.4924
3339.92	57.777
3344.01	57.4547
3348.1	56.0944
3352.19	56.4672
3356.27	58.1639
3360.35	59.9145
3364.43	59.5644
3368.5	54.3273
3372.58	53.3323
3376.65	58.8121
3380.71	59.7246
3384.78	60.0149
3388.84	59.2537
3392.9	58.7478
3396.95	58.8298
3401.01	59.5498
3405.06	60.6337
3409.1	60.5759
3413.15	59.4158
3417.19	58.2143
3421.23	56.37
3425.27	56.7285
3429.31	57.2167
3433.34	57.0067
3437.37	57.3229
3441.39	57.3559
3445.42	58.6482
3449.44	59.5285
3453.46	57.004
3457.47	55.6495
3461.49	55.5773
3465.5	55.981
3469.51	54.5931
3473.51	54.4335
3477.52	53.3876
3481.52	55.6871
3485.51	57.1105
3489.51	56.6179
3493.5	54.7123
3497.49	53.4836
3501.48	51.8553
3505.46	51.2533
3509.45	54.4377
3513.43	51.4134
3517.4	49.3647
3521.38	50.5334
3525.35	52.3654
3529.32	52.912
3533.28	52.4501
3537.25	52.4171
3541.21	51.1725
3545.17	49.9056
3549.12	50.7264
3553.08	50.4293
3557.03	52.8335
3560.98	51.3155
3564.92	52.6419
3568.87	53.8559
3572.81	56.1778
3576.74	59.366
3580.68	60.8632
3584.61	61.6788
3588.54	62.8667
3592.47	64.6411
3596.4	62.3073
3600.32	54.5445
3604.24	53.5337
3608.16	53.4068
3612.07	49.9741
3615.98	46.5783
3619.89	46.0638
3623.8	44.9786
3627.71	44.0994
3631.61	45.7504
3635.51	47.2984
3639.41	48.1547
3643.3	46.8604
3647.19	46.8607
3651.08	46.9911
3654.97	44.0311
3658.85	39.1754
3662.74	42.4685
3666.62	44.7952
3670.49	44.4161
3674.37	42.8722
3678.24	41.909
3682.11	42.9635
3685.98	44.2777
3689.84	44.2527
3693.7	43.8054
3697.56	43.5288
3701.42	43.9117
3705.28	43.6573
3709.13	43.0024
3712.98	42.8856
3716.82	42.501
3720.67	41.4849
3724.51	41.7701
3728.35	42.7122
3732.19	43.1571
3736.02	42.5072
3739.86	43.289
3743.69	42.2386
3747.51	40.7563
3751.34	40.5927
3755.16	41.4352
3758.98	42.2796
3762.8	40.2831
3766.61	41.6593
3770.43	43.5185
3774.24	42.3461
3778.05	40.7938
3781.85	42.0688
3785.65	43.3694
3789.45	42.9885
3793.25	41.8568
3797.05	40.9785
3800.84	40.3727
3804.63	40.2852
3808.42	40.0917
3812.21	39.1529
3815.99	38.9886
3819.77	41.1076
3823.55	42.126
3827.33	42.4537
3831.1	40.3996
3834.87	41.0374
3838.64	41.711
3842.41	40.9957
3846.17	40.1688
3849.93	39.7159
3853.69	40.6556
3857.45	40.6862
3861.21	40.5811
3864.96	40.8657
3868.71	39.3538
3872.46	38.9868
3876.2	38.7806
3879.94	39.7794
3883.68	40.2103
3887.42	39.9271
3891.16	39.7772
3894.89	39.9613
3898.62	40.0345
3902.35	39.7022
3906.08	40.1649
3909.8	40.1745
3913.52	39.477
3917.24	39.0418
3920.96	38.8388
3924.67	38.6163
3928.38	39.5471
3932.09	39.484
3935.8	38.8904
3939.51	36.8771
3943.21	39.1423
3946.91	37.9741
3950.61	37.1146
3954.3	38.298
3958	37.5048
3961.69	38.752
3965.38	38.0436
3969.06	36.4065
3972.75	37.6812
3976.43	39.1754
3980.11	39.0502
3983.78	37.2818
3987.46	35.9511
3991.13	35.7355
3994.8	36.7352
3998.47	37.8881