File: Data/3-Raman/raw/20-C_brt1_FI07.txt
#Acq. time (s)=	20
#Accumulations=	3
#Range (cm-¹)=	100...4000
#Windows=	1
#Auto scanning=	Off
#Autofocus=	Off
#Macrospot=	Off
#AutoExposure=	Off
#Spike filter=	Multiple accum.
#Delay time (s)=	0
#Binning=	1
#Readout mode=	Signal
#DeNoise=	Lite
#ICS correction=	Off
#Dark correction=	Off
#Inst. Process=	Off
#Detector temperature (°C)=	-60.09
#Instrument=	LabRAM HR Evol
#Detector=	SIN-EM FIVIS
#Objective=	x50_VIS_LWD
#Grating=	150 (500nm)
#ND Filter=	100%
#Laser=	633nm_Edge
#Hole=	30.0125
#Temperature=	0
#Range=	Visible
#StageXY=	75x50mm Scan+
#StageZ=	Z motor
#X (µm)=	7435.8
#Y (µm)=	4166.6
#Z (µm)=	-29.5
#Full time(mm:ss)=	1:02
#Project=	Buranga
#Sample=	BU18FA20_C
#Site=	C_Bertoss1
#Title=	20-C_brt1_FI07
#Remark=
#Date=	30.07.2019 14:30
#Acquired=	30.07.2019 14:30:37
100.38	743.343
106.898	570.558
113.411	459.879
119.918	383.057
126.419	331.735
132.916	278.942
139.407	248.528
145.892	234.399
152.372	208.982
158.847	183.045
165.316	173.199
171.781	173.605
178.239	155.893
184.693	147.679
191.139	141.103
197.582	139.576
204.02	134.702
210.452	139.326
216.877	135.917
223.299	133.518
229.715	150.364
236.126	181.16
242.53	279.859
248.931	229.28
255.326	182.253
261.714	168.005
268.099	173.417
274.477	193.688
280.851	227.651
287.218	281.453
293.582	294.313
299.939	228.749
306.293	173.845
312.639	151.876
318.982	157.596
325.318	200.025
331.651	311.598
337.977	307.022
344.297	205.409
350.614	164.146
356.925	157.33
363.23	182.248
369.53	198.033
375.827	189.23
382.116	163.56
388.401	135.262
394.681	123.025
400.956	125.88
407.226	130.237
413.49	132.331
419.749	138.69
426.003	148.765
432.252	178.26
438.496	217.609
444.735	241.784
450.969	235.59
457.197	222.112
463.421	207.39
469.64	187.403
475.853	161.183
482.062	143.077
488.265	136.069
494.464	132.477
500.657	131.154
506.844	132.773
513.028	137.523
519.206	139.819
525.38	139.613
531.548	138.546
537.71	139.277
543.869	135.86
550.022	129.6
556.169	125.504
562.313	125.972
568.452	130.671
574.584	129.673
580.713	125.735
586.837	127.265
592.954	136.767
599.068	174.527
605.176	244.851
611.28	243.372
617.378	202.51
623.473	193.73
629.561	204.573
635.644	208.318
641.724	205.946
647.797	192.308
653.867	188.031
659.931	198.776
665.99	216.038
672.044	200.758
678.095	141.003
684.139	124.373
690.179	114.508
696.213	110.206
702.245	108.21
708.27	104.968
714.29	102.426
720.306	102.039
726.316	103.076
732.322	102.844
738.323	101.285
744.32	100.598
750.311	100.726
756.298	101.888
762.28	100.758
768.258	98.2102
774.23	98.277
780.198	98.8571
786.161	96.7731
792.119	96.9242
798.073	98.802
804.021	99.3522
809.965	99.2355
815.904	98.2945
821.839	97.909
827.769	99.6829
833.693	102.133
839.614	104.05
845.53	105.17
851.44	105.978
857.346	105.101
863.248	102.982
869.144	102.092
875.037	103.748
880.924	107.263
886.807	108.8
892.685	107.699
898.559	106.091
904.427	105.412
910.292	107.326
916.151	112.513
922.006	116.153
927.856	115.712
933.701	116.494
939.543	121.397
945.379	138.115
951.21	158.911
957.037	174.837
962.861	190.565
968.678	205.612
974.491	228.929
980.3	279.167
986.104	362.738
991.904	479.213
997.699	531.65
1003.49	413.253
1009.28	333.235
1015.06	303.164
1020.83	320.547
1026.61	385.856
1032.37	404.907
1038.14	306.47
1043.9	239.082
1049.65	199.644
1055.4	179.033
1061.15	164.472
1066.88	153.848
1072.62	147.597
1078.35	152.634
1084.08	171.681
1089.8	195.462
1095.52	205.379
1101.23	211.522
1106.94	219.681
1112.65	181.765
1118.35	147.856
1124.05	126.796
1129.74	120.635
1135.42	122.407
1141.11	128.905
1146.78	139.832
1152.46	149.162
1158.13	165.597
1163.79	159.739
1169.45	129.544
1175.11	109.983
1180.76	102.744
1186.41	100.944
1192.05	99.0624
1197.69	96.6126
1203.32	92.8871
1208.95	88.68
1214.58	85.8129
1220.2	86.8067
1225.82	90.6017
1231.43	91.5531
1237.04	89.6503
1242.64	85.5016
1248.24	84.4334
1253.83	91.2036
1259.42	103.906
1265.01	118.541
1270.59	112.588
1276.17	111.164
1281.74	273
1287.31	369
1292.88	116.228
1298.44	99.9654
1303.99	94.2418
1309.55	94.9017
1315.09	94.0237
1320.64	91.2437
1326.18	89.0621
1331.71	87.4936
1337.24	87.4182
1342.77	86.709
1348.29	87.3415
1353.81	90.3894
1359.32	93.5609
1364.83	97.6575
1370.33	104.25
1375.84	104.648
1381.33	116.004
1386.82	633
1392.31	265
1397.8	91.3857
1403.28	94.4857
1408.75	126.761
1414.22	104.311
1419.69	85.857
1425.15	83.6935
1430.61	82.6173
1436.07	79.8457
1441.52	77.325
1446.96	76.2884
1452.41	77.667
1457.84	79.7887
1463.28	80.863
1468.71	79.8236
1474.13	79.538
1479.55	78.0309
1484.97	72.6874
1490.39	71.7321
1495.79	72.4313
1501.2	73.9395
1506.6	75.2733
1512	74.5876
1517.39	72.7937
1522.78	71.5899
1528.16	72.7801
1533.54	74.8986
1538.92	75.0588
1544.29	70.7402
1549.66	68.8144
1555.02	65.1975
1560.38	74.4967
1565.74	74.9851
1571.09	73.5031
1576.44	71.8992
1581.78	74.2758
1587.12	71.1586
1592.46	71.4161
1597.79	71.768
1603.12	70.7599
1608.44	70.8459
1613.76	72.4342
1619.08	74.0834
1624.39	72.9819
1629.7	72.1673
1635	73.3628
1640.3	74.1596
1645.59	72.9251
1650.88	71.1643
1656.17	68.7913
1661.46	68.6978
1666.74	69.5629
1672.01	72.627
1677.28	74.1749
1682.55	73.6917
1687.82	71.1044
1693.07	69.0592
1698.33	68.7887
1703.58	68.555
1708.83	69.6199
1714.07	69.3287
1719.31	69.3549
1724.55	71.7112
1729.78	75.2037
1735.01	72.8914
1740.23	71.8315
1745.46	72.5801
1750.67	74.0181
1755.89	74.0114
1761.09	71.9181
1766.3	69.25
1771.5	69.8283
1776.7	70.2213
1781.89	71.6735
1787.08	73.1189
1792.27	73.6624
1797.45	72.95
1802.62	70.5445
1807.8	68.8234
1812.97	68.7683
1818.14	71.0715
1823.3	73.7269
1828.46	74.0086
1833.61	70.7885
1838.76	68.1895
1843.91	68.146
1849.05	68.4068
1854.19	70.7869
1859.33	72.6898
1864.46	66.933
1869.59	68.5974
1874.71	70.108
1879.83	69.9608
1884.95	70.8338
1890.06	69.5496
1895.17	68.1334
1900.27	68.5058
1905.38	69.1975
1910.47	68.5101
1915.57	67.8298
1920.66	67.9177
1925.74	68.3005
1930.83	67.3181
1935.91	63.5123
1940.98	65.9414
1946.05	67.6197
1951.12	68.8405
1956.18	68.332
1961.25	66.8211
1966.3	66.3976
1971.35	67.036
1976.4	66.9148
1981.45	66.7405
1986.49	67.0203
1991.53	66.9508
1996.56	66.077
2001.59	66.7776
2006.62	67.8684
2011.64	68.522
2016.66	66.9042
2021.68	65.8469
2026.69	65.4044
2031.7	64.5019
2036.7	64.0253
2041.7	67.0671
2046.7	71.5101
2051.7	71.8503
2056.69	68.8153
2061.67	64.7492
2066.65	63.9944
2071.63	65.8657
2076.61	69.1393
2081.58	70.8626
2086.55	70.2794
2091.51	70.8334
2096.47	69.6747
2101.43	66.7841
2106.39	66.1967
2111.34	67.4065
2116.28	68.602
2121.23	69.0655
2126.17	67.1393
2131.1	65.9365
2136.03	65.2502
2140.96	65.94
2145.89	67.0496
2150.81	68.3763
2155.73	69.4202
2160.64	67.7712
2165.55	64.8196
2170.46	65.192
2175.36	64.8449
2180.26	64.2825
2185.16	63.1128
2190.05	63.3414
2194.94	63.8933
2199.83	64.8628
2204.71	66.2732
2209.59	66.805
2214.46	65.7568
2219.33	64.9804
2224.2	65.3517
2229.07	65.5044
2233.93	69.0523
2238.79	70.0891
2243.64	67.9635
2248.49	65.8495
2253.34	64.7825
2258.18	64.1735
2263.02	64.1543
2267.86	64.189
2272.69	64.8849
2277.52	65.7866
2282.35	67.2926
2287.17	67.6359
2291.99	69.2445
2296.8	69.6983
2301.62	67.1884
2306.43	68.294
2311.23	67.5957
2316.03	66.2812
2320.83	68.8359
2325.63	72.8474
2330.42	74.4852
2335.21	71.6037
2339.99	68.9344
2344.77	66.689
2349.55	65.3105
2354.32	64.0638
2359.1	63.1995
2363.86	65.6457
2368.63	65.3012
2373.39	63.0562
2378.15	61.6726
2382.9	61.7837
2387.65	63.094
2392.4	64.762
2397.14	63.9642
2401.88	62.9058
2406.62	61
2411.35	63.8764
2416.08	61.3864
2420.81	63.651
2425.53	67.2242
2430.25	68.6992
2434.97	66.5657
2439.69	64.9053
2444.4	64.939
2449.1	65.6405
2453.81	64.3168
2458.51	60.418
2463.2	61.5691
2467.9	63.0046
2472.59	63.0238
2477.27	60.5239
2481.96	60.8734
2486.64	63.3215
2491.31	61.7486
2495.99	64.4982
2500.66	62.8132
2505.32	62.3838
2509.99	63.0938
2514.65	63.9725
2519.31	64.8627
2523.96	65.2293
2528.61	63.4718
2533.26	62.6265
2537.9	61.5869
2542.54	61.3349
2547.18	61.0326
2551.81	66.2463
2556.44	65.9554
2561.07	65.6949
2565.69	63.356
2570.32	63.5373
2574.93	64.5337
2579.55	60.1994
2584.16	56.8371
2588.77	59.1883
2593.37	61.9449
2597.97	64.4598
2602.57	64.2548
2607.17	60.8719
2611.76	61.8361
2616.35	63.0044
2620.93	63.81
2625.51	63.3217
2630.09	63.1218
2634.67	62.9763
2639.24	62.362
2643.81	62.3076
2648.38	61.4165
2652.94	60.4925
2657.5	58.3034
2662.06	61.008
2666.61	63.8959
2671.16	63.1851
2675.71	62.6074
2680.25	62.4669
2684.79	62.5897
2689.33	63.7029
2693.86	64.6871
2698.39	62.4191
2702.92	59.6514
2707.45	56.2656
2711.97	58.0968
2716.49	62.0466
2721	63.4943
2725.51	63.1087
2730.02	62.8571
2734.53	60.7246
2739.03	60.6068
2743.53	63.5947
2748.03	60.6948
2752.52	60.4993
2757.01	59.8987
2761.5	60.8509
2765.98	62.9871
2770.46	63.2262
2774.94	62.7112
2779.42	60.2276
2783.89	58.6495
2788.36	57.9756
2792.82	58.628
2797.28	60.0162
2801.74	60.2926
2806.2	60.958
2810.65	60.0035
2815.1	59.0854
2819.55	62.1378
2823.99	63.105
2828.43	61.4777
2832.87	59.2512
2837.3	58.6156
2841.74	58.14
2846.17	59.2634
2850.59	59.9464
2855.01	59.1689
2859.43	58.15
2863.85	58.2941
2868.26	59.3014
2872.67	59.6591
2877.08	59.8872
2881.48	59.8442
2885.89	59.4069
2890.28	59.6312
2894.68	60.8097
2899.07	63.25
2903.46	62.7478
2907.85	60.5423
2912.23	58.7979
2916.61	55.693
2920.98	55.0745
2925.36	55.9416
2929.73	57.4847
2934.1	59.708
2938.46	61.1089
2942.82	59.4967
2947.18	58.2707
2951.54	57.6611
2955.89	58.3012
2960.24	59.0846
2964.59	60.1038
2968.93	59.3383
2973.27	57.607
2977.61	58.0588
2981.95	57.3247
2986.28	56.198
2990.61	56.8585
2994.94	57.4342
2999.26	57.2368
3003.58	57.4506
3007.9	57.0209
3012.21	57.5579
3016.52	58.9551
3020.83	60.7012
3025.14	59.7561
3029.44	58.7777
3033.74	58.4969
3038.04	58.2921
3042.33	56.7058
3046.62	59.3657
3050.91	59.9275
3055.2	58.7467
3059.48	59.1234
3063.76	58.0716
3068.03	58.1317
3072.31	57.3829
3076.58	57.0113
3080.85	59.9657
3085.11	61.624
3089.37	59.9952
3093.63	56.6279
3097.89	57.4988
3102.14	61.4836
3106.39	63.5556
3110.64	62.7263
3114.89	61.9323
3119.13	60.5037
3123.37	61.3559
3127.6	60.8393
3131.84	62.16
3136.07	63.1078
3140.29	63.1635
3144.52	61.2918
3148.74	61.208
3152.96	59.9503
3157.18	58.6482
3161.39	60.817
3165.6	61.2281
3169.81	61.7109
3174.01	63.0673
3178.22	64.498
3182.42	64.6263
3186.61	64.9513
3190.8	64.2291
3195	62.0162
3199.18	61.0758
3203.37	63.7542
3207.55	64.1569
3211.73	64.471
3215.91	63.2544
3220.08	62.0682
3224.25	62.0926
3228.42	61.6808
3232.59	61.6175
3236.75	63.6862
3240.91	62.2103
3245.07	60.2593
3249.22	58.4827
3253.37	56.2982
3257.52	56.3007
3261.67	56.9253
3265.81	57.4619
3269.95	56.9035
3274.09	55.7473
3278.22	56.2926
3282.36	56.6416
3286.49	55.2306
3290.61	52.3847
3294.74	51.664
3298.86	53.9489
3302.98	55.2969
3307.09	54.4302
3311.21	52.0069
3315.32	52.7457
3319.42	55.8663
3323.53	55.9372
3327.63	55.2063
3331.73	53.2621
3335.83	54.5516
3339.92	54.8515
3344.01	54.4921
3348.1	54.2105
3352.19	56.0446
3356.27	55.2712
3360.35	54.9026
3364.43	55.0277
3368.5	52.9023
3372.58	54.7819
3376.65	56.6916
3380.71	56.3797
3384.78	55.9788
3388.84	58.1198
3392.9	59.8031
3396.95	59.0145
3401.01	56.7102
3405.06	58.3994
3409.1	54.3933
3413.15	52.9116
3417.19	58.2373
3421.23	58.0673
3425.27	58.9514
3429.31	58.7355
3433.34	57.6269
3437.37	55.826
3441.39	54.1804
3445.42	51.4989
3449.44	49.6806
3453.46	51.422
3457.47	53.0768
3461.49	51.0451
3465.5	48.8163
3469.51	50.2421
3473.51	53.1999
3477.52	51.3807
3481.52	50.3603
3485.51	48.7488
3489.51	46.91
3493.5	47.9789
3497.49	49.8446
3501.48	49.9336
3505.46	49.7668
3509.45	50.7344
3513.43	50.7094
3517.4	50.4093
3521.38	50.858
3525.35	51.0359
3529.32	50.8521
3533.28	47.0479
3537.25	44.7432
3541.21	45.0534
3545.17	45.8441
3549.12	47.7877
3553.08	49.9012
3557.03	51.7535
3560.98	51.6527
3564.92	50.8285
3568.87	51.4195
3572.81	53.3888
3576.74	56.1084
3580.68	59.6799
3584.61	61.2132
3588.54	58.792
3592.47	58.4004
3596.4	58.8176
3600.32	53.579
3604.24	50.1476
3608.16	48.6442
3612.07	47.407
3615.98	47.2559
3619.89	47.5632
3623.8	46.7591
3627.71	45.8777
3631.61	44.9897
3635.51	45.0138
3639.41	45.3134
3643.3	44.6359
3647.19	45.7285
3651.08	46.1468
3654.97	46.3741
3658.85	46.0522
3662.74	45.0383
3666.62	42.3995
3670.49	41.0095
3674.37	42.6427
3678.24	44.139
3682.11	44.4969
3685.98	44.6696
3689.84	44.2895
3693.7	45.1637
3697.56	44.5339
3701.42	43.4016
3705.28	42.8255
3709.13	42.8114
3712.98	43.4212
3716.82	43.8973
3720.67	45.1197
3724.51	44.2917
3728.35	42.881
3732.19	41.8259
3736.02	42.5267
3739.86	42.0545
3743.69	40.9509
3747.51	40.7358
3751.34	43.0805
3755.16	44.9032
3758.98	44.8983
3762.8	43.1184
3766.61	40.9384
3770.43	39.3901
3774.24	38.9753
3778.05	39.9905
3781.85	42.9448
3785.65	42.907
3789.45	41.8933
3793.25	41.3498
3797.05	39.1505
3800.84	38.656
3804.63	40.4114
3808.42	39.9089
3812.21	41.8394
3815.99	41.555
3819.77	41.1792
3823.55	40.9324
3827.33	40.1786
3831.1	40.9697
3834.87	41.9991
3838.64	42.1468
3842.41	41.4337
3846.17	39.7182
3849.93	39.3082
3853.69	40.5371
3857.45	41.928
3861.21	41.9836
3864.96	38.4882
3868.71	36.5807
3872.46	38.1748
3876.2	40.3573
3879.94	42.1094
3883.68	39.9901
3887.42	38.7869
3891.16	39.1408
3894.89	40.5922
3898.62	40.2132
3902.35	40.6666
3906.08	40.9995
3909.8	40.7069
3913.52	41.3295
3917.24	40.8189
3920.96	39.4499
3924.67	38.1326
3928.38	37.6375
3932.09	39.7559
3935.8	38.7716
3939.51	38.0883
3943.21	38.5667
3946.91	38.5287
3950.61	37.5956
3954.3	39.9088
3958	39.7961
3961.69	40.4722
3965.38	38.1727
3969.06	38.7357
3972.75	38.9193
3976.43	38.8461
3980.11	39.1108
3983.78	37.2671
3987.46	37.0496
3991.13	37.6002
3994.8	38.1923
3998.47	40.0226