File: Data/3-Raman/raw/20-F_brt1_FI01.txt
#Acq. time (s)=	20
#Accumulations=	3
#Range (cm-¹)=	100...4000
#Windows=	1
#Auto scanning=	Off
#Autofocus=	Off
#Macrospot=	Off
#AutoExposure=	Off
#Spike filter=	Multiple accum.
#Delay time (s)=	0
#Binning=	1
#Readout mode=	Signal
#DeNoise=	Lite
#ICS correction=	Off
#Dark correction=	Off
#Inst. Process=	Off
#Detector temperature (°C)=	-60.09
#Instrument=	LabRAM HR Evol
#Detector=	SIN-EM FIVIS
#Objective=	x100_VIS
#Grating=	150 (500nm)
#ND Filter=	100%
#Laser=	633nm_Edge
#Hole=	30.0125
#Temperature=	0
#Range=	Visible
#StageXY=	75x50mm Scan+
#StageZ=	Z motor
#X (µm)=	7064
#Y (µm)=	-135.7
#Z (µm)=	1846.5
#Full time(mm:ss)=	1:02
#Project=	Buranga
#Sample=	BU18FA20_F
#Site=	F_Bertoss1
#Title=	20-F_brt1_FI01
#Remark=
#Date=	30.07.2019 15:56
#Acquired=	30.07.2019 15:56:48
100.38	207.242
106.898	185.406
113.411	159.782
119.918	144.41
126.419	139.02
132.916	132.086
139.407	130.701
145.892	126.65
152.372	122.02
158.847	119.025
165.316	116.646
171.781	112.715
178.239	107.63
184.693	103.635
191.139	97.6395
197.582	95.9528
204.02	95.5863
210.452	91.9093
216.877	90.1431
223.299	94.5504
229.715	107.99
236.126	137.251
242.53	147.355
248.931	108.636
255.326	106.395
261.714	113.265
268.099	105.125
274.477	128.083
280.851	152.299
287.218	164.913
293.582	144.388
299.939	113.781
306.293	94.9002
312.639	95.3232
318.982	113.689
325.318	152.529
331.651	188.706
337.977	146.303
344.297	116.162
350.614	103.348
356.925	100.896
363.23	111.892
369.53	113.289
375.827	104.557
382.116	93.057
388.401	79.5761
394.681	78.0941
400.956	84.9005
407.226	90.1156
413.49	93.843
419.749	99.5585
426.003	108.475
432.252	129.066
438.496	142.083
444.735	139.422
450.969	134.327
457.197	127.516
463.421	119.924
469.64	109.093
475.853	98.3519
482.062	88.4678
488.265	84.8574
494.464	84.3668
500.657	86.7087
506.844	90.9616
513.028	93.6631
519.206	94.1249
525.38	93.1739
531.548	94.0425
537.71	92.9216
543.869	89.2426
550.022	86.679
556.169	87.0521
562.313	84.9151
568.452	81.2854
574.584	77.4342
580.713	78.9582
586.837	87.172
592.954	104.067
599.068	125.543
605.176	136.704
611.28	127.9
617.378	119.087
623.473	115.324
629.561	117.205
635.644	119.014
641.724	114.173
647.797	112.13
653.867	116.224
659.931	121.346
665.99	117.209
672.044	103.847
678.095	91.1855
684.139	81.2895
690.179	74.47
696.213	71.13
702.245	69.873
708.27	71.1783
714.29	73.9225
720.306	74.3022
726.316	73.2665
732.322	67.8213
738.323	66.3866
744.32	70.4317
750.311	70.9031
756.298	70.175
762.28	69.5199
768.258	68.0605
774.23	68.5047
780.198	68.6288
786.161	68.3907
792.119	67.9099
798.073	71.0534
804.021	72.3676
809.965	67.2805
815.904	71.154
821.839	75.2678
827.769	72.4961
833.693	68.7926
839.614	74.5648
845.53	73.8176
851.44	73.3246
857.346	74.275
863.248	75.5002
869.144	77.6274
875.037	77.4776
880.924	76.7682
886.807	76.8455
892.685	78.4907
898.559	78.7484
904.427	78.2368
910.292	77.4039
916.151	75.6918
922.006	77.5005
927.856	81.4192
933.701	85.4147
939.543	91.5746
945.379	100.574
951.21	109.244
957.037	118.011
962.861	127.725
968.678	139.006
974.491	154.941
980.3	191.289
986.104	239.506
991.904	285.473
997.699	257.383
1003.49	212.894
1009.28	191.504
1015.06	198.319
1020.83	215.011
1026.61	227.102
1032.37	209.801
1038.14	160.932
1043.9	129.281
1049.65	117.34
1055.4	108.395
1061.15	100.644
1066.88	98.2011
1072.62	105.378
1078.35	114.32
1084.08	122.106
1089.8	129.274
1095.52	133.895
1101.23	139.334
1106.94	129.691
1112.65	110.475
1118.35	98.7373
1124.05	92.2147
1129.74	90.3306
1135.42	93.6469
1141.11	99.6777
1146.78	108.119
1152.46	116.152
1158.13	115.32
1163.79	103.718
1169.45	90.0314
1175.11	86.2346
1180.76	85.1994
1186.41	83.3083
1192.05	79.1128
1197.69	77.0378
1203.32	76.8802
1208.95	77.7467
1214.58	76.9506
1220.2	78.0786
1225.82	77.413
1231.43	76.9605
1237.04	78.0326
1242.64	79.5188
1248.24	75.1333
1253.83	73.777
1259.42	78.6826
1265.01	82.3894
1270.59	78.2765
1276.17	81.3858
1281.74	141.493
1287.31	93.4597
1292.88	79.546
1298.44	73.8165
1303.99	75.3185
1309.55	79.4494
1315.09	81.2552
1320.64	81.229
1326.18	80.0693
1331.71	78.4665
1337.24	77.7001
1342.77	77.279
1348.29	76.2252
1353.81	76.0954
1359.32	77.2047
1364.83	78.9443
1370.33	79.6989
1375.84	81.0821
1381.33	96.7653
1386.82	208
1392.31	92.3808
1397.8	75.2958
1403.28	83.5845
1408.75	83.5565
1414.22	77.9891
1419.69	79.1277
1425.15	78.5028
1430.61	76.9482
1436.07	74.3788
1441.52	72.4526
1446.96	74.206
1452.41	71.4838
1457.84	74.4176
1463.28	78.0462
1468.71	77.5323
1474.13	74.5364
1479.55	72.4443
1484.97	71.4029
1490.39	71.156
1495.79	71.7154
1501.2	74.2317
1506.6	74.6275
1512	75.6832
1517.39	75.4382
1522.78	75.0214
1528.16	74.6232
1533.54	70.5649
1538.92	70.0982
1544.29	72.2101
1549.66	74.0669
1555.02	75.5411
1560.38	75.243
1565.74	74.8783
1571.09	75.8823
1576.44	77.9566
1581.78	78.7568
1587.12	78.1195
1592.46	77.08
1597.79	77.3141
1603.12	76.243
1608.44	79.133
1613.76	80.9008
1619.08	80.8983
1624.39	80.0381
1629.7	78.9881
1635	77.4398
1640.3	76.8793
1645.59	76.9037
1650.88	78.7587
1656.17	81.5426
1661.46	80.9747
1666.74	79.9035
1672.01	77.6529
1677.28	78.3005
1682.55	79.1543
1687.82	80.1841
1693.07	80.1339
1698.33	78.5175
1703.58	78.6597
1708.83	79.4447
1714.07	77.4672
1719.31	77.4039
1724.55	79.7992
1729.78	80.9737
1735.01	78.7853
1740.23	79.0838
1745.46	79.8766
1750.67	80.0962
1755.89	73.3136
1761.09	73.8123
1766.3	79.809
1771.5	81.3675
1776.7	79.0137
1781.89	78.8265
1787.08	79.0719
1792.27	80.1018
1797.45	81.3775
1802.62	82.4164
1807.8	80.1612
1812.97	79.0273
1818.14	78.7815
1823.3	78.3614
1828.46	78.4407
1833.61	77.4332
1838.76	79.3771
1843.91	79.5198
1849.05	75.7125
1854.19	78.6239
1859.33	81.3197
1864.46	82.8069
1869.59	81.7523
1874.71	78.8476
1879.83	78.704
1884.95	79.0014
1890.06	79.9438
1895.17	81.3558
1900.27	81.7932
1905.38	84.7616
1910.47	82.8813
1915.57	81.2623
1920.66	84.2201
1925.74	83.9485
1930.83	81.996
1935.91	79.976
1940.98	77.8055
1946.05	79.4156
1951.12	79.7304
1956.18	83.601
1961.25	82.2295
1966.3	82.9753
1971.35	83.4068
1976.4	82.88
1981.45	85.0307
1986.49	87.1703
1991.53	85.413
1996.56	84.8706
2001.59	82.5136
2006.62	80.8653
2011.64	83.4486
2016.66	83.8927
2021.68	84.5304
2026.69	84.9994
2031.7	83.8118
2036.7	84.4467
2041.7	85.4258
2046.7	86.1667
2051.7	86.826
2056.69	85.9429
2061.67	82.0994
2066.65	82.1083
2071.63	83.0899
2076.61	85.7943
2081.58	87.8108
2086.55	86.3602
2091.51	87.9735
2096.47	88.409
2101.43	88.6212
2106.39	90.8243
2111.34	88.2222
2116.28	86.0121
2121.23	85.1686
2126.17	85.3814
2131.1	86.2735
2136.03	86.5074
2140.96	87.2421
2145.89	90.397
2150.81	90.018
2155.73	86.5864
2160.64	83.3009
2165.55	84.1854
2170.46	87.0993
2175.36	89.252
2180.26	86.9829
2185.16	89.992
2190.05	88.8162
2194.94	89.6628
2199.83	90.3849
2204.71	93.5546
2209.59	91.6133
2214.46	91.9546
2219.33	90.6588
2224.2	87.5959
2229.07	84.1828
2233.93	85.8404
2238.79	88.5489
2243.64	90.1986
2248.49	90.021
2253.34	89.2121
2258.18	87.2739
2263.02	87.8073
2267.86	87.6198
2272.69	88.897
2277.52	89.8641
2282.35	89.9554
2287.17	88.9784
2291.99	90.7978
2296.8	88.6622
2301.62	83.8773
2306.43	87.4338
2311.23	90.3634
2316.03	92.8538
2320.83	94.7372
2325.63	93.8454
2330.42	91.8629
2335.21	89.9518
2339.99	88.5722
2344.77	87.6785
2349.55	88.8635
2354.32	92.5079
2359.1	92.1464
2363.86	89.1348
2368.63	87.8494
2373.39	89.8706
2378.15	92.8729
2382.9	89.2981
2387.65	86.7277
2392.4	83.6108
2397.14	89.7475
2401.88	89.7567
2406.62	89.4222
2411.35	87.7665
2416.08	87.1361
2420.81	89.631
2425.53	91.7242
2430.25	91.7644
2434.97	88.6656
2439.69	88.3473
2444.4	89.6947
2449.1	90.568
2453.81	90.8959
2458.51	88.7871
2463.2	85.5544
2467.9	83.1604
2472.59	84.9959
2477.27	88.0524
2481.96	90.317
2486.64	91.7572
2491.31	91.9043
2495.99	92.3495
2500.66	90.8027
2505.32	89.6052
2509.99	88.3791
2514.65	85.9573
2519.31	82.5795
2523.96	82.2143
2528.61	86.5627
2533.26	89.4274
2537.9	90.3942
2542.54	92.1001
2547.18	91.6823
2551.81	90.6674
2556.44	89.5449
2561.07	88.8517
2565.69	89.1098
2570.32	89.8359
2574.93	91.9957
2579.55	88.339
2584.16	88.9631
2588.77	90.9362
2593.37	91.5408
2597.97	88.1887
2602.57	84.6868
2607.17	85.4396
2611.76	87.292
2616.35	88.8424
2620.93	89.5158
2625.51	88.6204
2630.09	87.9217
2634.67	89.2067
2639.24	91.3898
2643.81	90.0347
2648.38	86.9748
2652.94	86.7099
2657.5	88.6202
2662.06	90.8374
2666.61	88.5809
2671.16	88.9995
2675.71	87.9935
2680.25	88.9744
2684.79	88.4621
2689.33	92.7548
2693.86	91.6188
2698.39	87.9714
2702.92	88.4139
2707.45	87.4664
2711.97	86.7778
2716.49	88.9852
2721	91.632
2725.51	93.5831
2730.02	92.1897
2734.53	89.9149
2739.03	90.559
2743.53	91.2391
2748.03	87.4025
2752.52	88.9848
2757.01	88.5695
2761.5	91.8773
2765.98	88.453
2770.46	90.1188
2774.94	87.6707
2779.42	84.3571
2783.89	80.566
2788.36	86.7865
2792.82	89.0504
2797.28	89.118
2801.74	90.0758
2806.2	90.8034
2810.65	90.489
2815.1	90.2346
2819.55	90.3178
2823.99	90.9978
2828.43	90.3998
2832.87	89.494
2837.3	87.1564
2841.74	82.2704
2846.17	80.4619
2850.59	86.1096
2855.01	88.7224
2859.43	88.8452
2863.85	87.9744
2868.26	88.7325
2872.67	88.9776
2877.08	89.2633
2881.48	85.2979
2885.89	85.9082
2890.28	84.8341
2894.68	85.5718
2899.07	89.1353
2903.46	90.0779
2907.85	87.4611
2912.23	88.2581
2916.61	86.4979
2920.98	85.1053
2925.36	87.5147
2929.73	88.3329
2934.1	85.7547
2938.46	82.0655
2942.82	83.99
2947.18	89.9677
2951.54	90.5989
2955.89	87.1056
2960.24	85.7821
2964.59	85.4147
2968.93	84.2725
2973.27	86.1506
2977.61	91.674
2981.95	89.3595
2986.28	85.1734
2990.61	83.9038
2994.94	86.6626
2999.26	90.0995
3003.58	88.5002
3007.9	86.2151
3012.21	84.7669
3016.52	84.7421
3020.83	84.6891
3025.14	85.5501
3029.44	83.4973
3033.74	83.0217
3038.04	81.8307
3042.33	83.7425
3046.62	84.8701
3050.91	85.9282
3055.2	87.4493
3059.48	87.4823
3063.76	91.2163
3068.03	90.1494
3072.31	88.0029
3076.58	86.6819
3080.85	85.2293
3085.11	86.4783
3089.37	88.9078
3093.63	88.1165
3097.89	87.4005
3102.14	86.0807
3106.39	87.5276
3110.64	89.4044
3114.89	91.0406
3119.13	90.7811
3123.37	89.9635
3127.6	88.9769
3131.84	84.2872
3136.07	85.0454
3140.29	87.2542
3144.52	87.434
3148.74	86.0143
3152.96	85.0496
3157.18	84.9449
3161.39	86.1305
3165.6	87.4286
3169.81	87.3685
3174.01	88.3724
3178.22	89.589
3182.42	89.1393
3186.61	88.3021
3190.8	90.6139
3195	89.5505
3199.18	91.19
3203.37	92.233
3207.55	91.962
3211.73	89.9173
3215.91	89.1686
3220.08	89.006
3224.25	92.671
3228.42	92.2492
3232.59	91.0888
3236.75	89.9098
3240.91	89.199
3245.07	90.881
3249.22	91.7852
3253.37	91.9386
3257.52	90.4337
3261.67	89.4862
3265.81	86.0339
3269.95	84.2903
3274.09	84.4837
3278.22	85.5858
3282.36	85.2465
3286.49	84.3865
3290.61	80.6132
3294.74	83.1184
3298.86	81.2562
3302.98	83.3052
3307.09	85.8097
3311.21	81.2366
3315.32	79.5686
3319.42	80.7693
3323.53	83.1793
3327.63	84.2587
3331.73	82.4594
3335.83	81.0983
3339.92	81.4067
3344.01	81.2121
3348.1	84.2463
3352.19	83.3109
3356.27	80.7781
3360.35	81.3443
3364.43	83.9228
3368.5	86.1844
3372.58	86.0154
3376.65	81.5442
3380.71	80.9552
3384.78	81.8458
3388.84	80.1613
3392.9	80.1552
3396.95	84.1726
3401.01	86.83
3405.06	87.8177
3409.1	86.4482
3413.15	86.0988
3417.19	86.4146
3421.23	82.9469
3425.27	84.2703
3429.31	84.7655
3433.34	84.7314
3437.37	83.3064
3441.39	81.5453
3445.42	81.11
3449.44	82.2251
3453.46	83.3216
3457.47	81.9498
3461.49	81.0229
3465.5	80.3724
3469.51	76.3817
3473.51	75.7377
3477.52	77.3617
3481.52	78.3286
3485.51	78.9166
3489.51	79.749
3493.5	78.9066
3497.49	78.3571
3501.48	79.0007
3505.46	78.4906
3509.45	76.3416
3513.43	75.6432
3517.4	72.8694
3521.38	72.782
3525.35	74.3463
3529.32	75.2745
3533.28	74.5301
3537.25	73.5225
3541.21	72.6393
3545.17	71.7264
3549.12	71.4685
3553.08	71.9171
3557.03	72.8232
3560.98	73.0524
3564.92	74.6499
3568.87	75.9187
3572.81	74.8504
3576.74	75.5372
3580.68	78.4069
3584.61	78.4544
3588.54	78.4012
3592.47	76.813
3596.4	75.8377
3600.32	73.7828
3604.24	68.7581
3608.16	64.2517
3612.07	63.1549
3615.98	63.6743
3619.89	65.4374
3623.8	67.2785
3627.71	67.2887
3631.61	67.8116
3635.51	67.0098
3639.41	65.2679
3643.3	66.605
3647.19	67.6742
3651.08	67.6242
3654.97	67.5367
3658.85	67.718
3662.74	65.8902
3666.62	62.5048
3670.49	63.7342
3674.37	64.9558
3678.24	63.8889
3682.11	62.1934
3685.98	62.2378
3689.84	63.9317
3693.7	64.905
3697.56	65.6999
3701.42	64.3917
3705.28	63.561
3709.13	63.4873
3712.98	64.1054
3716.82	65.0345
3720.67	62.4132
3724.51	60.9908
3728.35	61.4607
3732.19	61.227
3736.02	61.1312
3739.86	60.7835
3743.69	62.0332
3747.51	61.0844
3751.34	59.7272
3755.16	60.1711
3758.98	59.4372
3762.8	60.0917
3766.61	61.4562
3770.43	57.8609
3774.24	54.2796
3778.05	55.6853
3781.85	59.35
3785.65	60.5868
3789.45	59.616
3793.25	60.6088
3797.05	61.2958
3800.84	59.896
3804.63	57.7401
3808.42	56.082
3812.21	55.6373
3815.99	56.8573
3819.77	57.4321
3823.55	55.951
3827.33	54.7525
3831.1	56.0449
3834.87	58.5076
3838.64	59.111
3842.41	59.2428
3846.17	59.0317
3849.93	58.3132
3853.69	57.1946
3857.45	58.3093
3861.21	60.1836
3864.96	57.9012
3868.71	58.7121
3872.46	58.9347
3876.2	57.9883
3879.94	56.0518
3883.68	56.878
3887.42	57.6858
3891.16	56.6611
3894.89	57.1087
3898.62	58.0479
3902.35	58.9402
3906.08	58.7486
3909.8	56.6311
3913.52	52.5631
3917.24	51.3628
3920.96	52.2847
3924.67	53.2031
3928.38	54.219
3932.09	55.4369
3935.8	54.4496
3939.51	51.9475
3943.21	51.6371
3946.91	52.9395
3950.61	53.8214
3954.3	53.0287
3958	52.5426
3961.69	52.5936
3965.38	53.3864
3969.06	54.5094
3972.75	54.9174
3976.43	53.4795
3980.11	52.9574
3983.78	53.1096
3987.46	52.8915
3991.13	52.4221
3994.8	52.0281
3998.47	53.7471