File: Data/3-Raman/raw/20-F_brt1_FI02.txt
#Acq. time (s)=	20
#Accumulations=	3
#Range (cm-¹)=	100...4000
#Windows=	1
#Auto scanning=	Off
#Autofocus=	Off
#Macrospot=	Off
#AutoExposure=	Off
#Spike filter=	Multiple accum.
#Delay time (s)=	0
#Binning=	1
#Readout mode=	Signal
#DeNoise=	Lite
#ICS correction=	Off
#Dark correction=	Off
#Inst. Process=	Off
#Detector temperature (°C)=	-60.09
#Instrument=	LabRAM HR Evol
#Detector=	SIN-EM FIVIS
#Objective=	x100_VIS
#Grating=	150 (500nm)
#ND Filter=	100%
#Laser=	633nm_Edge
#Hole=	30.0125
#Temperature=	0
#Range=	Visible
#StageXY=	75x50mm Scan+
#StageZ=	Z motor
#X (µm)=	7059.8
#Y (µm)=	-65.9
#Z (µm)=	1872
#Full time(mm:ss)=	1:02
#Project=	Buranga
#Sample=	BU18FA20_F
#Site=	F_Bertoss1
#Title=	20-F_brt1_FI02
#Remark=
#Date=	30.07.2019 15:58
#Acquired=	30.07.2019 15:58:51
100.38	298.147
106.898	262.116
113.411	228.125
119.918	219.508
126.419	212.577
132.916	199.057
139.407	187.303
145.892	178.707
152.372	173.556
158.847	168.524
165.316	162.451
171.781	154.892
178.239	145.177
184.693	146.061
191.139	142.04
197.582	136.601
204.02	131.361
210.452	126.674
216.877	124.109
223.299	122.485
229.715	140.562
236.126	154.816
242.53	158.809
248.931	145.154
255.326	132.853
261.714	126.296
268.099	124.578
274.477	132.618
280.851	152.299
287.218	166.301
293.582	149.408
299.939	129.271
306.293	117.151
312.639	114.166
318.982	123.679
325.318	153.859
331.651	179.522
337.977	144.871
344.297	123.612
350.614	113.852
356.925	119.397
363.23	124.761
369.53	121.99
375.827	116.121
382.116	106.371
388.401	99.8887
394.681	101.221
400.956	105.831
407.226	106.625
413.49	105.761
419.749	109.564
426.003	119.992
432.252	134.535
438.496	148.999
444.735	151.93
450.969	146.922
457.197	141.105
463.421	130.655
469.64	117.439
475.853	107.412
482.062	106.059
488.265	105.77
494.464	106.005
500.657	106.793
506.844	108.439
513.028	109.406
519.206	109.238
525.38	106.822
531.548	106.409
537.71	105.72
543.869	104.128
550.022	102.496
556.169	101.458
562.313	100.247
568.452	100.017
574.584	97.7233
580.713	97.5873
586.837	102.913
592.954	115.116
599.068	137.908
605.176	154.035
611.28	143.241
617.378	133.475
623.473	127.909
629.561	132.403
635.644	135.334
641.724	124.991
647.797	119.992
653.867	125.012
659.931	136.064
665.99	130.44
672.044	114.514
678.095	100.036
684.139	96.2988
690.179	95.2823
696.213	95.2313
702.245	93.782
708.27	89.4426
714.29	86.2277
720.306	84.1221
726.316	83.1342
732.322	83.4831
738.323	84.1117
744.32	85.9715
750.311	86.8469
756.298	86.0746
762.28	85.7623
768.258	87.106
774.23	87.2173
780.198	87.2213
786.161	87.4576
792.119	89.1241
798.073	89.8452
804.021	89.1904
809.965	87.0477
815.904	83.5341
821.839	82.726
827.769	87.0933
833.693	88.7511
839.614	88.2581
845.53	87.0276
851.44	84.01
857.346	81.117
863.248	80.2835
869.144	81.7439
875.037	86.6198
880.924	89.2344
886.807	89.7579
892.685	84.8953
898.559	81.4148
904.427	82.5782
910.292	83.3332
916.151	84.2652
922.006	84.4949
927.856	85.1072
933.701	88.8858
939.543	94.799
945.379	100.85
951.21	105.108
957.037	109.996
962.861	117.621
968.678	129.836
974.491	150.24
980.3	177.438
986.104	217.076
991.904	250.827
997.699	227.233
1003.49	189.7
1009.28	168.43
1015.06	170.191
1020.83	183.734
1026.61	194.419
1032.37	180.65
1038.14	153.703
1043.9	129.162
1049.65	116.529
1055.4	109.514
1061.15	103.252
1066.88	97.2102
1072.62	99.0742
1078.35	106.417
1084.08	114.308
1089.8	119.678
1095.52	120.68
1101.23	129.714
1106.94	116.414
1112.65	100.998
1118.35	89.5077
1124.05	84.066
1129.74	84.079
1135.42	87.134
1141.11	93.1178
1146.78	100.235
1152.46	105.209
1158.13	102.62
1163.79	91.7525
1169.45	84.1046
1175.11	81.5811
1180.76	82.0603
1186.41	80.1616
1192.05	79.6477
1197.69	80.3662
1203.32	78.4966
1208.95	74.9484
1214.58	72.5835
1220.2	71.1585
1225.82	68.5322
1231.43	70.3004
1237.04	73.5397
1242.64	75.6814
1248.24	77.6664
1253.83	76.2228
1259.42	78.6809
1265.01	80.6447
1270.59	82.2083
1276.17	89.8366
1281.74	133.037
1287.31	107.516
1292.88	81.5362
1298.44	78.6021
1303.99	76.0087
1309.55	73.7038
1315.09	72.0275
1320.64	71.2166
1326.18	72.145
1331.71	71.5837
1337.24	70.1558
1342.77	69.0386
1348.29	68.7214
1353.81	69.9347
1359.32	70.0739
1364.83	70.4486
1370.33	73.9589
1375.84	80.0258
1381.33	93.122
1386.82	207.721
1392.31	87.4878
1397.8	76.7365
1403.28	75.1525
1408.75	75.651
1414.22	71.1369
1419.69	68.1528
1425.15	66.9444
1430.61	66.5657
1436.07	66.7982
1441.52	66.9913
1446.96	64.7496
1452.41	64.6272
1457.84	66.3317
1463.28	61.4297
1468.71	67.0429
1474.13	67.7549
1479.55	66.9051
1484.97	62.0284
1490.39	60.475
1495.79	64.5725
1501.2	64.7601
1506.6	63.4765
1512	64.3113
1517.39	64.8454
1522.78	65.7295
1528.16	64.6762
1533.54	63.9094
1538.92	64.3957
1544.29	63.6777
1549.66	62.3958
1555.02	61.0637
1560.38	65.2581
1565.74	65.5055
1571.09	65.0702
1576.44	64.1428
1581.78	63.8315
1587.12	63.0387
1592.46	63.6346
1597.79	64.6041
1603.12	64.8069
1608.44	66.245
1613.76	66.8803
1619.08	70.214
1624.39	67.8575
1629.7	66.3727
1635	64.9992
1640.3	64.6059
1645.59	64.9543
1650.88	65.5523
1656.17	65.9458
1661.46	65.3504
1666.74	64.2946
1672.01	62.2632
1677.28	64.2165
1682.55	64.7747
1687.82	63.708
1693.07	64.8483
1698.33	64.548
1703.58	66.2964
1708.83	66.215
1714.07	66.6883
1719.31	62.9864
1724.55	62.4153
1729.78	61.7002
1735.01	61.5191
1740.23	61.5959
1745.46	63.9906
1750.67	65.0344
1755.89	64.0813
1761.09	59.923
1766.3	60.9371
1771.5	60.7385
1776.7	61.0909
1781.89	61.1736
1787.08	58.4281
1792.27	62.5456
1797.45	64.4858
1802.62	62.449
1807.8	60.9719
1812.97	60.4375
1818.14	59.9745
1823.3	59.7057
1828.46	59.7503
1833.61	60.4923
1838.76	61.4794
1843.91	62.6659
1849.05	61.7292
1854.19	59.9711
1859.33	60.7863
1864.46	59.7331
1869.59	60.0755
1874.71	60.1539
1879.83	62.2098
1884.95	62.5948
1890.06	61.4934
1895.17	58.8203
1900.27	57.8278
1905.38	58.3817
1910.47	60.8994
1915.57	62.3747
1920.66	60.4666
1925.74	58.1586
1930.83	56.6419
1935.91	56.8311
1940.98	58.4736
1946.05	61.3268
1951.12	61.7183
1956.18	62.0231
1961.25	63.327
1966.3	62.7207
1971.35	60.8362
1976.4	54.3514
1981.45	62.3847
1986.49	63.2285
1991.53	58.2835
1996.56	58.3411
2001.59	60.7269
2006.62	64.9253
2011.64	61.7225
2016.66	59.429
2021.68	61.6621
2026.69	59.5866
2031.7	59.1163
2036.7	58.4083
2041.7	58.7693
2046.7	58.9994
2051.7	59.4241
2056.69	61.8992
2061.67	62.9525
2066.65	62.5064
2071.63	61.8599
2076.61	49.3207
2081.58	62.1024
2086.55	60.1021
2091.51	58.9775
2096.47	60.1021
2101.43	61.3917
2106.39	61.3696
2111.34	60.6813
2116.28	58.8939
2121.23	56.9006
2126.17	57.3677
2131.1	59.643
2136.03	62.9847
2140.96	63.6313
2145.89	59.4583
2150.81	57.2045
2155.73	56.6913
2160.64	57.9372
2165.55	58.8623
2170.46	59.1256
2175.36	59.5729
2180.26	59.4339
2185.16	57.2237
2190.05	55.268
2194.94	54.6463
2199.83	56.5701
2204.71	57.3314
2209.59	58.0036
2214.46	58.085
2219.33	57.9504
2224.2	58.1368
2229.07	58.1586
2233.93	58.5146
2238.79	47.6815
2243.64	63.3595
2248.49	57.5959
2253.34	55.8288
2258.18	56.6423
2263.02	57.2509
2267.86	56.6401
2272.69	55.7988
2277.52	55.7952
2282.35	56.7515
2287.17	58.5762
2291.99	58.0422
2296.8	57.2187
2301.62	57.6822
2306.43	56.6921
2311.23	56.4422
2316.03	56.129
2320.83	58.7611
2325.63	59.9846
2330.42	60.3661
2335.21	59.5547
2339.99	57.4388
2344.77	55.3016
2349.55	55.1888
2354.32	55.7415
2359.1	55.8306
2363.86	55.8947
2368.63	55.6328
2373.39	56.6658
2378.15	56.8836
2382.9	56.4864
2387.65	56.553
2392.4	55.6108
2397.14	53.9262
2401.88	54.1115
2406.62	55.1699
2411.35	55.559
2416.08	57.1295
2420.81	56.7498
2425.53	54.6369
2430.25	53.1691
2434.97	52.9335
2439.69	54.9663
2444.4	55.1554
2449.1	56.5046
2453.81	57.2404
2458.51	56.3572
2463.2	55.6482
2467.9	54.8866
2472.59	54.76
2477.27	54.4313
2481.96	54.0475
2486.64	54.3071
2491.31	55.6201
2495.99	54.3701
2500.66	50.2626
2505.32	48.8277
2509.99	50.5257
2514.65	54.483
2519.31	56.0511
2523.96	56.0287
2528.61	52.3608
2533.26	50.6129
2537.9	50.8189
2542.54	51.2591
2547.18	53.277
2551.81	54.5836
2556.44	54.3498
2561.07	52.1658
2565.69	52.2266
2570.32	54.2788
2574.93	55.8381
2579.55	55.5581
2584.16	53.331
2588.77	54.5779
2593.37	56.1611
2597.97	56.6337
2602.57	54.8548
2607.17	53.6249
2611.76	53.7965
2616.35	55.0499
2620.93	53.0953
2625.51	53.6118
2630.09	54.7976
2634.67	55.0584
2639.24	54.4854
2643.81	52.3056
2648.38	53.0723
2652.94	54.7854
2657.5	53.3257
2662.06	52.0717
2666.61	51.1085
2671.16	50.5341
2675.71	50.2427
2680.25	50.8189
2684.79	50.9539
2689.33	49.7117
2693.86	50.8731
2698.39	53.2864
2702.92	53.8653
2707.45	53.091
2711.97	51.6805
2716.49	52.2906
2721	51.3979
2725.51	53.2093
2730.02	52.3035
2734.53	53.5651
2739.03	54.6554
2743.53	52.3754
2748.03	51.9084
2752.52	51.945
2757.01	53.6666
2761.5	53.755
2765.98	53.2002
2770.46	52.6146
2774.94	52.3267
2779.42	50.305
2783.89	51.5632
2788.36	52.0896
2792.82	51.7571
2797.28	50.8696
2801.74	51.0775
2806.2	50.0981
2810.65	48.9528
2815.1	49.6858
2819.55	51.8975
2823.99	53.5171
2828.43	53.4449
2832.87	52.2843
2837.3	51.1611
2841.74	48.6801
2846.17	48.0997
2850.59	49.4529
2855.01	51.4312
2859.43	50.8989
2863.85	50.5044
2868.26	50.854
2872.67	50.74
2877.08	50.1505
2881.48	49.592
2885.89	48.998
2890.28	49.2922
2894.68	48.9364
2899.07	52.9275
2903.46	53.6521
2907.85	50.7335
2912.23	48.2547
2916.61	48.3345
2920.98	48.1805
2925.36	50.1585
2929.73	47.049
2934.1	49.137
2938.46	51.8185
2942.82	51.682
2947.18	49.3821
2951.54	49.1666
2955.89	50.2333
2960.24	50.0954
2964.59	49.8787
2968.93	51.5418
2973.27	51.646
2977.61	52.1622
2981.95	52.3495
2986.28	51.0123
2990.61	50.4861
2994.94	51.1352
2999.26	52.7779
3003.58	53.2372
3007.9	49.2748
3012.21	51.0669
3016.52	51.4156
3020.83	49.9308
3025.14	49.2499
3029.44	50.8069
3033.74	52.9614
3038.04	53.7988
3042.33	54.0679
3046.62	53.1323
3050.91	51.4298
3055.2	50.6018
3059.48	51.2942
3063.76	53.4031
3068.03	54.5257
3072.31	54.328
3076.58	55.5668
3080.85	55.3736
3085.11	54.5583
3089.37	55.0816
3093.63	56.537
3097.89	57.0976
3102.14	57.6225
3106.39	57.1955
3110.64	58.4883
3114.89	59.764
3119.13	60.535
3123.37	60.0378
3127.6	59.4426
3131.84	60.334
3136.07	61.4519
3140.29	61.733
3144.52	61.404
3148.74	61.8007
3152.96	61.6772
3157.18	60.8829
3161.39	61.8379
3165.6	63.6377
3169.81	64.0428
3174.01	64.0304
3178.22	64.0375
3182.42	65.0786
3186.61	67.5986
3190.8	70.0492
3195	69.9956
3199.18	68.8671
3203.37	67.8497
3207.55	68.0866
3211.73	68.3204
3215.91	66.7323
3220.08	69.3867
3224.25	68.8477
3228.42	67.2244
3232.59	67.974
3236.75	67.5325
3240.91	67.14
3245.07	66.1699
3249.22	67.0162
3253.37	67.8382
3257.52	67.0188
3261.67	66.7521
3265.81	68.2334
3269.95	67.695
3274.09	66.1623
3278.22	66.1844
3282.36	68.5298
3286.49	69.7678
3290.61	66.4495
3294.74	64.6475
3298.86	68.3597
3302.98	70.2182
3307.09	69.3712
3311.21	66.918
3315.32	62.9095
3319.42	65.7998
3323.53	67.5975
3327.63	66.4257
3331.73	65.8266
3335.83	65.3815
3339.92	65.0485
3344.01	64.8086
3348.1	64.5017
3352.19	65.269
3356.27	67.1596
3360.35	67.0339
3364.43	64.9756
3368.5	61.3308
3372.58	61.82
3376.65	66.9698
3380.71	70.9358
3384.78	70.8245
3388.84	70.2738
3392.9	70.2935
3396.95	70.4114
3401.01	70.5901
3405.06	70.6522
3409.1	69.6398
3413.15	69.3685
3417.19	69.633
3421.23	71.7227
3425.27	71.3543
3429.31	71.8112
3433.34	70.7542
3437.37	66.6469
3441.39	65.3401
3445.42	69.8497
3449.44	69.218
3453.46	68.002
3457.47	65.404
3461.49	65.8821
3465.5	68.5882
3469.51	65.5857
3473.51	63.0479
3477.52	65.9386
3481.52	66.4261
3485.51	65.5665
3489.51	63.7652
3493.5	65.0397
3497.49	62.9332
3501.48	62.0585
3505.46	62.5188
3509.45	60.9047
3513.43	59.3581
3517.4	58.1053
3521.38	59.762
3525.35	57.6028
3529.32	54.8617
3533.28	57.4151
3537.25	55.8866
3541.21	53.0849
3545.17	54.5613
3549.12	55.0707
3553.08	56.1247
3557.03	54.8214
3560.98	52.8713
3564.92	52.087
3568.87	53.2377
3572.81	53.8771
3576.74	54.7139
3580.68	55.8366
3584.61	54.9084
3588.54	52.8596
3592.47	53.2831
3596.4	53.963
3600.32	52.2157
3604.24	47.8737
3608.16	47.0067
3612.07	47.5036
3615.98	48.3416
3619.89	46.4916
3623.8	42.5183
3627.71	40.9095
3631.61	42.8336
3635.51	43.9246
3639.41	44.7785
3643.3	45.4372
3647.19	46.8383
3651.08	45.6597
3654.97	43.3624
3658.85	41.0695
3662.74	40.2597
3666.62	40.3069
3670.49	40.7359
3674.37	40.416
3678.24	39.216
3682.11	39.1097
3685.98	39.586
3689.84	39.7676
3693.7	39.8479
3697.56	39.0651
3701.42	36.01
3705.28	38.7208
3709.13	39.3856
3712.98	37.6886
3716.82	36.5216
3720.67	34.9624
3724.51	35.1934
3728.35	36.8789
3732.19	37.1013
3736.02	35.5557
3739.86	34.1043
3743.69	34.1921
3747.51	35.7301
3751.34	35.1793
3755.16	35.2299
3758.98	34.9483
3762.8	36.1992
3766.61	36.4008
3770.43	36.3682
3774.24	36.3008
3778.05	36.4618
3781.85	36.9013
3785.65	37.1659
3789.45	36.2487
3793.25	35.6659
3797.05	36.6868
3800.84	37.6921
3804.63	37.1587
3808.42	35.9061
3812.21	35.3827
3815.99	35.3173
3819.77	35.064
3823.55	34.3201
3827.33	34.7221
3831.1	35.7923
3834.87	35.4542
3838.64	34.2917
3842.41	35.1195
3846.17	37.0186
3849.93	36.4599
3853.69	35.6789
3857.45	34.5661
3861.21	34.5555
3864.96	36.1759
3868.71	36.604
3872.46	35.6937
3876.2	34.3427
3879.94	34.4869
3883.68	34.9139
3887.42	35.2426
3891.16	35.6398
3894.89	34.4448
3898.62	34.9791
3902.35	34.6706
3906.08	33.5822
3909.8	32.8545
3913.52	34.3529
3917.24	35.4161
3920.96	35.1681
3924.67	34.3563
3928.38	33.4416
3932.09	33.7048
3935.8	34.0309
3939.51	32.7386
3943.21	31.0649
3946.91	34.793
3950.61	34.6601
3954.3	34.4306
3958	33.1842
3961.69	31.6043
3965.38	32.1787
3969.06	33.9868
3972.75	34.2732
3976.43	34.5994
3980.11	32.1176
3983.78	31.7203
3987.46	33.033
3991.13	32.7419
3994.8	32.0431
3998.47	30.1419