File: Data/3-Raman/raw/20-F_trl1_FI01.txt
#Acq. time (s)=	20
#Accumulations=	3
#Range (cm-¹)=	100...4000
#Windows=	1
#Auto scanning=	Off
#Autofocus=	Off
#Macrospot=	Off
#AutoExposure=	Off
#Spike filter=	Multiple accum.
#Delay time (s)=	0
#Binning=	1
#Readout mode=	Signal
#DeNoise=	Lite
#ICS correction=	Off
#Dark correction=	Off
#Inst. Process=	Off
#Detector temperature (°C)=	-60.09
#Instrument=	LabRAM HR Evol
#Detector=	SIN-EM FIVIS
#Objective=	x100_VIS
#Grating=	150 (500nm)
#ND Filter=	100%
#Laser=	633nm_Edge
#Hole=	30.0125
#Temperature=	0
#Range=	Visible
#StageXY=	75x50mm Scan+
#StageZ=	Z motor
#X (µm)=	8575.5
#Y (µm)=	1358
#Z (µm)=	1839.1
#Full time(mm:ss)=	1:02
#Project=	Buranga
#Sample=	BU18FA20_F
#Site=	F_trol1
#Title=	20-F_trl1_FI01
#Remark=
#Date=	30.07.2019 16:25
#Acquired=	30.07.2019 16:25:09
100.38	129.257
106.898	122.732
113.411	113.65
119.918	110.75
126.419	107.668
132.916	104.772
139.407	102.011
145.892	98.9603
152.372	95.2234
158.847	103.886
165.316	140.449
171.781	169.984
178.239	91
184.693	94.0058
191.139	114.172
197.582	160.973
204.02	125.959
210.452	94.0211
216.877	86.05
223.299	84.2138
229.715	91.4907
236.126	107.032
242.53	131.647
248.931	129
255.326	209.041
261.714	142.007
268.099	102.265
274.477	110.746
280.851	170.677
287.218	304.527
293.582	239
299.939	132.057
306.293	122.4
312.639	130.815
318.982	115.241
325.318	114.421
331.651	135.758
337.977	184.447
344.297	145.298
350.614	133.126
356.925	186.66
363.23	176.732
369.53	126.825
375.827	127.7
382.116	120.815
388.401	113.369
394.681	119.511
400.956	125.512
407.226	115.78
413.49	104.834
419.749	102.051
426.003	107.9
432.252	102.728
438.496	92.986
444.735	86.0999
450.969	85.3564
457.197	92.0855
463.421	98.4688
469.64	97.736
475.853	95.659
482.062	93.1689
488.265	98.7969
494.464	111.257
500.657	124.111
506.844	127.852
513.028	117.412
519.206	105.495
525.38	96.1034
531.548	89.9158
537.71	87.9163
543.869	90.479
550.022	93.56
556.169	95.101
562.313	96.1643
568.452	94.4472
574.584	90.2293
580.713	89.4001
586.837	95.6652
592.954	116.922
599.068	139.95
605.176	117.673
611.28	102.648
617.378	111.853
623.473	113.008
629.561	103.77
635.644	95.2696
641.724	92.5501
647.797	94.3547
653.867	97.4943
659.931	101.179
665.99	110.673
672.044	124.201
678.095	135.9
684.139	142.509
690.179	127.93
696.213	106.024
702.245	88.8917
708.27	84.0889
714.29	84.0047
720.306	83.7212
726.316	78.4707
732.322	79.2995
738.323	81.8512
744.32	83.7432
750.311	86.5075
756.298	90.3375
762.28	93.1052
768.258	97.2965
774.23	108.182
780.198	131.16
786.161	154.278
792.119	148.277
798.073	115.05
804.021	95.2791
809.965	89.75
815.904	87.4252
821.839	85.0576
827.769	81.7717
833.693	79.6308
839.614	80.8456
845.53	82.6384
851.44	83.2428
857.346	83.2321
863.248	83.6826
869.144	83.5509
875.037	82.8256
880.924	81.7581
886.807	81.0108
892.685	80.3806
898.559	77.9878
904.427	76.452
910.292	77.0835
916.151	78.6287
922.006	80.6422
927.856	82.655
933.701	83.7797
939.543	83.8989
945.379	87.1656
951.21	94.5211
957.037	97.6372
962.861	93.1419
968.678	93.4124
974.491	91.1752
980.3	87.5043
986.104	83.0512
991.904	79.2182
997.699	77.8788
1003.49	77.7873
1009.28	79.7708
1015.06	81.5913
1020.83	83.3507
1026.61	85.4717
1032.37	84.8071
1038.14	81.8356
1043.9	83.0717
1049.65	100.376
1055.4	125.218
1061.15	160.42
1066.88	137.266
1072.62	111.304
1078.35	99.1904
1084.08	101.91
1089.8	117.848
1095.52	145.721
1101.23	154.762
1106.94	131.99
1112.65	145.774
1118.35	157.475
1124.05	162.31
1129.74	142.67
1135.42	149.575
1141.11	153.629
1146.78	144.758
1152.46	121.014
1158.13	102.194
1163.79	123.621
1169.45	126.809
1175.11	115.912
1180.76	100.817
1186.41	91.1188
1192.05	85.6093
1197.69	85.548
1203.32	86.8221
1208.95	87.7409
1214.58	87.5137
1220.2	86.669
1225.82	88.0604
1231.43	92.1658
1237.04	94.7484
1242.64	93.9784
1248.24	91.4506
1253.83	88.1628
1259.42	84.9311
1265.01	82.0535
1270.59	80.4841
1276.17	90.0911
1281.74	113.754
1287.31	95.7092
1292.88	82.3671
1298.44	79.2169
1303.99	80.1982
1309.55	81.5815
1315.09	78.8997
1320.64	76.1429
1326.18	75.87
1331.71	74.8923
1337.24	74.1422
1342.77	75.7388
1348.29	75.6655
1353.81	76.6916
1359.32	75.5928
1364.83	73.2063
1370.33	75.516
1375.84	78.213
1381.33	91.3007
1386.82	177
1392.31	74.3954
1397.8	80.9491
1403.28	83.8704
1408.75	85.4359
1414.22	78.6522
1419.69	77.0517
1425.15	79.554
1430.61	74.0955
1436.07	69.0429
1441.52	74.3188
1446.96	73.4714
1452.41	69.6222
1457.84	70.0012
1463.28	71.9467
1468.71	73.9799
1474.13	75.5667
1479.55	75.0783
1484.97	74.1201
1490.39	73.0446
1495.79	73.5415
1501.2	71.6505
1506.6	69.8662
1512	72.0551
1517.39	72.7209
1522.78	71.7478
1528.16	69.9863
1533.54	69.0166
1538.92	71.9136
1544.29	74.0685
1549.66	74.0727
1555.02	72.736
1560.38	71.7033
1565.74	71.2281
1571.09	71.6117
1576.44	72.9573
1581.78	72.3607
1587.12	71.8559
1592.46	73.331
1597.79	73.1557
1603.12	74.3489
1608.44	74.6194
1613.76	73.7819
1619.08	72.2212
1624.39	75.8481
1629.7	74.6187
1635	73.6044
1640.3	75.7934
1645.59	73.9066
1650.88	74.7946
1656.17	73.4004
1661.46	71.8016
1666.74	71.4314
1672.01	71.8643
1677.28	72.1462
1682.55	73.9995
1687.82	75.3572
1693.07	74.3618
1698.33	74.0113
1703.58	75.2321
1708.83	73.786
1714.07	72.2236
1719.31	71.3274
1724.55	69.7225
1729.78	71.5154
1735.01	71.334
1740.23	72.3212
1745.46	75.9224
1750.67	75.0918
1755.89	71.8386
1761.09	69.1373
1766.3	67.7114
1771.5	69.4359
1776.7	71.6124
1781.89	72.8942
1787.08	73.2202
1792.27	70.3455
1797.45	76.3428
1802.62	69.5005
1807.8	69.5554
1812.97	73.7455
1818.14	72.7705
1823.3	70.9252
1828.46	68.7053
1833.61	67.7174
1838.76	68.1402
1843.91	70.2156
1849.05	72.4461
1854.19	74.371
1859.33	74.5772
1864.46	70.5508
1869.59	70.9934
1874.71	71.4817
1879.83	71.5412
1884.95	70.1705
1890.06	67.1704
1895.17	66.3868
1900.27	69.4414
1905.38	66.6564
1910.47	67.158
1915.57	69.6775
1920.66	70.8621
1925.74	70.9679
1930.83	70.1237
1935.91	68.722
1940.98	69.8043
1946.05	72.4736
1951.12	74.6264
1956.18	73.5498
1961.25	70.7659
1966.3	71.6449
1971.35	73.9034
1976.4	76.8724
1981.45	73.8268
1986.49	69.6624
1991.53	69.2863
1996.56	72.3091
2001.59	73.5402
2006.62	75.4108
2011.64	75.3677
2016.66	75.1482
2021.68	73.2462
2026.69	72.4084
2031.7	74.6482
2036.7	75.2463
2041.7	73.699
2046.7	70.3543
2051.7	71.9757
2056.69	72.5593
2061.67	72.5616
2066.65	72.5383
2071.63	71.4841
2076.61	71.6475
2081.58	71.2917
2086.55	72.7385
2091.51	75.5269
2096.47	76.5461
2101.43	72.9499
2106.39	69.746
2111.34	68.4418
2116.28	70.3475
2121.23	72.5124
2126.17	74.2899
2131.1	74.199
2136.03	73.551
2140.96	73.7362
2145.89	74.8546
2150.81	74.2001
2155.73	72.1868
2160.64	71.1132
2165.55	70.9558
2170.46	70.9027
2175.36	71.682
2180.26	74.0287
2185.16	76.6932
2190.05	77.3562
2194.94	75.499
2199.83	72.3272
2204.71	72.3992
2209.59	72.5989
2214.46	73.9672
2219.33	74.1745
2224.2	74.2638
2229.07	74.8186
2233.93	76.0247
2238.79	75.231
2243.64	73.674
2248.49	71.2854
2253.34	73.2771
2258.18	74.2347
2263.02	74.2645
2267.86	74.4099
2272.69	73.7538
2277.52	74.5438
2282.35	71.966
2287.17	73.1451
2291.99	74.5865
2296.8	74.4426
2301.62	75.2507
2306.43	75.0329
2311.23	73.4734
2316.03	70.9848
2320.83	71.9349
2325.63	75.2363
2330.42	76.7066
2335.21	75.7816
2339.99	75.0414
2344.77	74.129
2349.55	71.8362
2354.32	70.013
2359.1	71.7278
2363.86	72.2351
2368.63	72.7234
2373.39	75.3901
2378.15	75.1981
2382.9	73.277
2387.65	71.2515
2392.4	71.7001
2397.14	72.1677
2401.88	72.5186
2406.62	73.2371
2411.35	72.8612
2416.08	71.4741
2420.81	73.3935
2425.53	73.4485
2430.25	72.0652
2434.97	72.7791
2439.69	74.701
2444.4	71.4438
2449.1	70.364
2453.81	72.1298
2458.51	71.5702
2463.2	72.4834
2467.9	72.3533
2472.59	72.8012
2477.27	71.1842
2481.96	68.5806
2486.64	68.6666
2491.31	70.138
2495.99	72.7042
2500.66	75.2203
2505.32	73.6138
2509.99	71.2705
2514.65	69.9871
2519.31	68.4183
2523.96	66.3785
2528.61	69.7999
2533.26	72.6449
2537.9	72.759
2542.54	69.0123
2547.18	67.3538
2551.81	68.0032
2556.44	69.9884
2561.07	70.5106
2565.69	70.8584
2570.32	71.1134
2574.93	71.3053
2579.55	71.5168
2584.16	72.2147
2588.77	71.9243
2593.37	70.9839
2597.97	69.4682
2602.57	65.4564
2607.17	63.6529
2611.76	67.7977
2616.35	71.9514
2620.93	71.5615
2625.51	71.5393
2630.09	71.4969
2634.67	72.0322
2639.24	73.2981
2643.81	69.1086
2648.38	66.5524
2652.94	67.9892
2657.5	71.1144
2662.06	70.4961
2666.61	69.8483
2671.16	69.9517
2675.71	69.1754
2680.25	68.4362
2684.79	66.6144
2689.33	66.5474
2693.86	67.8569
2698.39	69.6573
2702.92	71.5144
2707.45	69.8323
2711.97	66.3833
2716.49	63.6204
2721	65.5156
2725.51	65.8092
2730.02	66.4562
2734.53	68.9242
2739.03	71.0095
2743.53	70.7338
2748.03	69.2644
2752.52	67.8016
2757.01	67.6416
2761.5	67.6992
2765.98	66.6407
2770.46	65.0253
2774.94	64.0648
2779.42	65.2184
2783.89	68.2295
2788.36	69.1791
2792.82	70.8396
2797.28	70.6615
2801.74	70.2654
2806.2	67.5538
2810.65	66.6648
2815.1	66.3037
2819.55	66.7862
2823.99	67.655
2828.43	66.6117
2832.87	66.4763
2837.3	66.327
2841.74	65.7371
2846.17	66.4237
2850.59	67.9352
2855.01	66.2139
2859.43	67.6064
2863.85	64.1472
2868.26	65.0352
2872.67	67.1228
2877.08	67.8431
2881.48	64.7887
2885.89	62.7403
2890.28	62.5549
2894.68	63.8872
2899.07	66.0026
2903.46	67.3901
2907.85	68.0926
2912.23	66.2801
2916.61	64.6722
2920.98	63.8405
2925.36	63.9465
2929.73	65.7563
2934.1	68.1049
2938.46	66.7911
2942.82	65.1944
2947.18	65.1763
2951.54	64.8307
2955.89	63.8259
2960.24	63.71
2964.59	64.3465
2968.93	65.6882
2973.27	65.8145
2977.61	66.8554
2981.95	66.378
2986.28	65.6671
2990.61	63.2578
2994.94	62.5385
2999.26	64.2541
3003.58	64.8121
3007.9	64.7552
3012.21	65.3265
3016.52	65.6478
3020.83	64.1436
3025.14	60.163
3029.44	58.3761
3033.74	58.7298
3038.04	62.6511
3042.33	66.9666
3046.62	66.1364
3050.91	62.8219
3055.2	61.6795
3059.48	63.7034
3063.76	67.1241
3068.03	66.6468
3072.31	64.5817
3076.58	62.1942
3080.85	61.3026
3085.11	62.74
3089.37	64.0067
3093.63	64.0645
3097.89	61.6726
3102.14	62.6897
3106.39	64.8439
3110.64	62.9246
3114.89	61.825
3119.13	61.2847
3123.37	61.1987
3127.6	61.0594
3131.84	61.1931
3136.07	62.9837
3140.29	62.3746
3144.52	63.4163
3148.74	64.0485
3152.96	61.6103
3157.18	60.5516
3161.39	61.2579
3165.6	61.1619
3169.81	61.607
3174.01	59.5193
3178.22	61.6729
3182.42	62.2386
3186.61	60.7632
3190.8	60.7117
3195	59.654
3199.18	60.4264
3203.37	62.2092
3207.55	60.7809
3211.73	58.3507
3215.91	57.3816
3220.08	57.6207
3224.25	59.222
3228.42	60.5727
3232.59	57.792
3236.75	57.1466
3240.91	59.386
3245.07	57.6139
3249.22	56.6143
3253.37	57.996
3257.52	57.8062
3261.67	56.0152
3265.81	54.7208
3269.95	54.5596
3274.09	57.1588
3278.22	57.2174
3282.36	60.4037
3286.49	61.8971
3290.61	59.2257
3294.74	54.5115
3298.86	54.1691
3302.98	56.596
3307.09	58.2585
3311.21	58.8611
3315.32	58.2326
3319.42	57.7997
3323.53	55.4064
3327.63	54.7404
3331.73	56.8348
3335.83	58.2508
3339.92	59.3927
3344.01	57.99
3348.1	55.9909
3352.19	55.9124
3356.27	55.0752
3360.35	54.8694
3364.43	55.3986
3368.5	56.9232
3372.58	59.4792
3376.65	58.3023
3380.71	57.8714
3384.78	52.4867
3388.84	52.9122
3392.9	55.5623
3396.95	58.8061
3401.01	60.2399
3405.06	59.4568
3409.1	58.8459
3413.15	61.3379
3417.19	68.793
3421.23	85.2157
3425.27	135.647
3429.31	161
3433.34	82.9109
3437.37	70.949
3441.39	63.3006
3445.42	59.7725
3449.44	58.0753
3453.46	61.612
3457.47	60.7637
3461.49	58.1639
3465.5	57.8641
3469.51	55.8223
3473.51	57.3875
3477.52	59.5644
3481.52	60.5062
3485.51	60.7413
3489.51	62.499
3493.5	64.7642
3497.49	70.9489
3501.48	83.8918
3505.46	95.6036
3509.45	103.209
3513.43	98.3322
3517.4	84.6586
3521.38	73.0416
3525.35	66.5024
3529.32	61.0046
3533.28	58.3195
3537.25	57.3596
3541.21	56.7524
3545.17	55.8859
3549.12	52.7588
3553.08	52.1586
3557.03	53.847
3560.98	54.8947
3564.92	55.7144
3568.87	54.8015
3572.81	54.3565
3576.74	53.2461
3580.68	51.3293
3584.61	47.5468
3588.54	46.8919
3592.47	50.7169
3596.4	50.3605
3600.32	47.2103
3604.24	44.7523
3608.16	47.2293
3612.07	51.04
3615.98	50.9422
3619.89	50.6556
3623.8	50.531
3627.71	49.7795
3631.61	51.0547
3635.51	50.7767
3639.41	50.3561
3643.3	49.9668
3647.19	49.3608
3651.08	47.3629
3654.97	49.7117
3658.85	48.4308
3662.74	47.366
3666.62	47.0196
3670.49	46.5464
3674.37	47.2857
3678.24	46.9967
3682.11	47.3033
3685.98	47.4009
3689.84	47.4155
3693.7	46.4356
3697.56	45.6429
3701.42	46.338
3705.28	48.0545
3709.13	47.8007
3712.98	47.7292
3716.82	48.3983
3720.67	48.2508
3724.51	46.3004
3728.35	45.9101
3732.19	45.5198
3736.02	45.3452
3739.86	45.1654
3743.69	44.5915
3747.51	46.3016
3751.34	46.4726
3755.16	44.6006
3758.98	44.062
3762.8	45.087
3766.61	45.7648
3770.43	45.0931
3774.24	45.6945
3778.05	45.5783
3781.85	47.1591
3785.65	48.0059
3789.45	47.9713
3793.25	47.9483
3797.05	49.4187
3800.84	47.1155
3804.63	44.4772
3808.42	42.7751
3812.21	44.557
3815.99	45.8645
3819.77	46.7438
3823.55	46.2136
3827.33	45.7818
3831.1	44.1784
3834.87	42.1698
3838.64	41.7129
3842.41	43.8801
3846.17	44.2343
3849.93	43.5887
3853.69	43.4182
3857.45	43.6226
3861.21	43.5616
3864.96	43.2802
3868.71	43.476
3872.46	42.2732
3876.2	43.2571
3879.94	42.8738
3883.68	44.4052
3887.42	42.5842
3891.16	41.4195
3894.89	43.1529
3898.62	44.708
3902.35	44.7078
3906.08	43.5416
3909.8	42.6228
3913.52	41.7053
3917.24	41.3638
3920.96	41.7936
3924.67	42.0401
3928.38	42.785
3932.09	43.6185
3935.8	43.3205
3939.51	42.4133
3943.21	41.9681
3946.91	43.0591
3950.61	40.4944
3954.3	39.9893
3958	40.7325
3961.69	41.1564
3965.38	42.2339
3969.06	41.5712
3972.75	40.9427
3976.43	39.5982
3980.11	41.7389
3983.78	43.4576
3987.46	43.0722
3991.13	42.7327
3994.8	41.9597
3998.47	39.4099