File: Data/3-Raman/raw/20-F_brt1_FI03.txt
#Acq. time (s)=	20
#Accumulations=	3
#Range (cm-¹)=	100...4000
#Windows=	1
#Auto scanning=	Off
#Autofocus=	Off
#Macrospot=	Off
#AutoExposure=	Off
#Spike filter=	Multiple accum.
#Delay time (s)=	0
#Binning=	1
#Readout mode=	Signal
#DeNoise=	Lite
#ICS correction=	Off
#Dark correction=	Off
#Inst. Process=	Off
#Detector temperature (°C)=	-60.09
#Instrument=	LabRAM HR Evol
#Detector=	SIN-EM FIVIS
#Objective=	x100_VIS
#Grating=	150 (500nm)
#ND Filter=	100%
#Laser=	633nm_Edge
#Hole=	30.0125
#Temperature=	0
#Range=	Visible
#StageXY=	75x50mm Scan+
#StageZ=	Z motor
#X (µm)=	7090.6
#Y (µm)=	-77.9
#Z (µm)=	1848.2
#Full time(mm:ss)=	1:05
#Project=	Buranga
#Sample=	BU18FA20_F
#Site=	F_Bertoss1
#Title=	20-F_brt1_FI03
#Remark=
#Date=	30.07.2019 16:11
#Acquired=	30.07.2019 16:11:02
100.38	127.984
106.898	120.607
113.411	107.096
119.918	98.5841
126.419	96.1305
132.916	95.2634
139.407	96.6933
145.892	93.7718
152.372	88.2326
158.847	82.3044
165.316	84.0785
171.781	85.665
178.239	80.727
184.693	76.3565
191.139	72.2164
197.582	71.2474
204.02	73.1724
210.452	71.5347
216.877	72.6697
223.299	76.9046
229.715	85.8521
236.126	108.948
242.53	106.574
248.931	93.1826
255.326	86.6215
261.714	86.3009
268.099	89.3996
274.477	94.8043
280.851	108.74
287.218	120.176
293.582	106.239
299.939	89.7282
306.293	80.8968
312.639	79.1042
318.982	84.7285
325.318	113.734
331.651	134.154
337.977	110.2
344.297	84.2638
350.614	79.4862
356.925	82.5516
363.23	85.6937
369.53	85.803
375.827	82.8717
382.116	74.3042
388.401	68.9879
394.681	68.0135
400.956	70.2301
407.226	72.5446
413.49	74.9984
419.749	79.69
426.003	86.5948
432.252	96.1635
438.496	104.9
444.735	109.756
450.969	103.484
457.197	100.032
463.421	93.7928
469.64	85.8695
475.853	76.7463
482.062	71.9645
488.265	70.8962
494.464	69.1035
500.657	69.842
506.844	74.3877
513.028	77.5656
519.206	78.331
525.38	77.7355
531.548	75.9312
537.71	72.6372
543.869	70.472
550.022	70.4325
556.169	69.8641
562.313	69.3907
568.452	68.9563
574.584	68.9668
580.713	69.1908
586.837	71.5783
592.954	78.9302
599.068	97.6548
605.176	112.594
611.28	84.0976
617.378	88.6891
623.473	90.9241
629.561	91.7011
635.644	94.8219
641.724	93.1262
647.797	87.8591
653.867	91.3162
659.931	94.9034
665.99	93.4994
672.044	83.4036
678.095	69.2369
684.139	66.3723
690.179	64.3262
696.213	62.2931
702.245	60.1679
708.27	59.5833
714.29	59.7524
720.306	59.4784
726.316	59.6936
732.322	60.0637
738.323	61.7658
744.32	62.5085
750.311	59.9961
756.298	57.2459
762.28	57.936
768.258	60.685
774.23	61.3241
780.198	59.7828
786.161	55.4849
792.119	54.457
798.073	58.8025
804.021	58.5572
809.965	58.7053
815.904	59.8872
821.839	61.1372
827.769	62.0572
833.693	61.2286
839.614	62.2683
845.53	62.3236
851.44	63.5891
857.346	62.2427
863.248	60.4655
869.144	62.5747
875.037	63.6448
880.924	64.3266
886.807	64.5012
892.685	65.9507
898.559	64.8761
904.427	64.4628
910.292	64.296
916.151	64.4271
922.006	65.6
927.856	67.3132
933.701	69.6921
939.543	72.2586
945.379	77.5671
951.21	84.395
957.037	92.7339
962.861	99.8342
968.678	106.863
974.491	109.43
980.3	139.971
986.104	182.522
991.904	205.096
997.699	194.442
1003.49	162.655
1009.28	136.539
1015.06	141.72
1020.83	151.229
1026.61	162.362
1032.37	141.028
1038.14	115.839
1043.9	98.8674
1049.65	90.8775
1055.4	87.6838
1061.15	82.9772
1066.88	78.0319
1072.62	80.4284
1078.35	86.3662
1084.08	92.4111
1089.8	97.1788
1095.52	91.8826
1101.23	100.956
1106.94	93.5362
1112.65	82.3064
1118.35	74.2415
1124.05	69.5803
1129.74	72.3177
1135.42	74.1452
1141.11	76.1344
1146.78	81.347
1152.46	87.2886
1158.13	87.0307
1163.79	79.4533
1169.45	70.0746
1175.11	65.2007
1180.76	62.3974
1186.41	62.647
1192.05	63.7475
1197.69	64.3985
1203.32	64.882
1208.95	63.7752
1214.58	62.8995
1220.2	60.76
1225.82	59.5369
1231.43	61.9257
1237.04	63.733
1242.64	63.2182
1248.24	63.5177
1253.83	62.7192
1259.42	62.8708
1265.01	64.0494
1270.59	56.2342
1276.17	66.1965
1281.74	76.8689
1287.31	71.108
1292.88	60.901
1298.44	59.933
1303.99	60.2691
1309.55	61.492
1315.09	61.6777
1320.64	61.6981
1326.18	60.7206
1331.71	58.4556
1337.24	58.806
1342.77	61.1989
1348.29	60.508
1353.81	58.99
1359.32	60.3847
1364.83	61.2572
1370.33	61.5513
1375.84	63.5053
1381.33	72.5489
1386.82	82.4444
1392.31	68.4126
1397.8	61.9182
1403.28	62.2236
1408.75	61.5699
1414.22	60.7393
1419.69	54.0965
1425.15	62.7313
1430.61	61.5434
1436.07	59.7465
1441.52	60.1303
1446.96	61.2772
1452.41	61.9036
1457.84	62.4402
1463.28	60.2444
1468.71	60.2604
1474.13	60.3391
1479.55	62.3061
1484.97	62.6887
1490.39	60.9158
1495.79	58.096
1501.2	58.7594
1506.6	60.5128
1512	60.1401
1517.39	60.0727
1522.78	59.8531
1528.16	60.3017
1533.54	61.6611
1538.92	61.8125
1544.29	61.7117
1549.66	61.594
1555.02	60.5709
1560.38	58.8335
1565.74	57.7703
1571.09	61.4427
1576.44	62.8269
1581.78	61.8606
1587.12	60.6812
1592.46	61.0993
1597.79	61.1841
1603.12	62.0529
1608.44	61.8005
1613.76	62.427
1619.08	63.777
1624.39	66.1359
1629.7	66.6136
1635	65.7181
1640.3	64.1753
1645.59	64.4198
1650.88	65.1267
1656.17	63.6837
1661.46	63.608
1666.74	64
1672.01	65.0329
1677.28	64.4416
1682.55	62.3476
1687.82	62.2645
1693.07	62.0415
1698.33	60.5669
1703.58	59.5091
1708.83	59.1984
1714.07	60.5614
1719.31	63.0673
1724.55	61.0274
1729.78	59.3316
1735.01	58.2922
1740.23	58.0116
1745.46	58.5651
1750.67	59.9469
1755.89	62.8353
1761.09	65.6681
1766.3	66.6127
1771.5	65.2785
1776.7	63.4218
1781.89	62.7537
1787.08	63.015
1792.27	64.0988
1797.45	65.3981
1802.62	65.7401
1807.8	65.5095
1812.97	64.0825
1818.14	62.9739
1823.3	62.3024
1828.46	65.1753
1833.61	65.884
1838.76	64.5656
1843.91	64.8728
1849.05	64.8922
1854.19	64.3816
1859.33	63.9614
1864.46	64.0808
1869.59	64.644
1874.71	60.7528
1879.83	60.7478
1884.95	62.8257
1890.06	65.7348
1895.17	65.949
1900.27	65.8344
1905.38	66.2506
1910.47	66.3288
1915.57	63.7038
1920.66	62.3442
1925.74	63.1373
1930.83	66.0828
1935.91	68.8282
1940.98	68.3347
1946.05	67.9228
1951.12	68.1097
1956.18	66.5176
1961.25	65.149
1966.3	63.7807
1971.35	65.7844
1976.4	67.1322
1981.45	65.1085
1986.49	68.2833
1991.53	67.4246
1996.56	67.0531
2001.59	67.9215
2006.62	67.8853
2011.64	66.1453
2016.66	65.1859
2021.68	66.1624
2026.69	68.3212
2031.7	67.2281
2036.7	68.7693
2041.7	68.543
2046.7	66.4608
2051.7	64.8725
2056.69	66.1678
2061.67	66.3002
2066.65	66.4074
2071.63	67.8615
2076.61	68.474
2081.58	68.4905
2086.55	67.3642
2091.51	67.0685
2096.47	68.5505
2101.43	70.0912
2106.39	68.4267
2111.34	66.0952
2116.28	65.7018
2121.23	66.2149
2126.17	66.5232
2131.1	67.3736
2136.03	68.3739
2140.96	68.6892
2145.89	68.1575
2150.81	66.8068
2155.73	66.5565
2160.64	68.431
2165.55	69.2478
2170.46	65.3123
2175.36	67.0864
2180.26	68.4562
2185.16	65.7499
2190.05	64.5552
2194.94	67.1738
2199.83	69.271
2204.71	70.2026
2209.59	70.0753
2214.46	69.2064
2219.33	68.6912
2224.2	68.497
2229.07	68.2369
2233.93	68.0774
2238.79	67.9283
2243.64	68.3443
2248.49	68.3681
2253.34	63.317
2258.18	64.3353
2263.02	70.7472
2267.86	70.5246
2272.69	69.3432
2277.52	69.2951
2282.35	67.9565
2287.17	67.4016
2291.99	69.37
2296.8	71.3663
2301.62	71.1844
2306.43	68.4973
2311.23	69.2362
2316.03	69.7303
2320.83	69.4181
2325.63	67.4744
2330.42	67.1446
2335.21	71.0205
2339.99	72.1046
2344.77	71.8443
2349.55	69.3411
2354.32	67.9365
2359.1	68.7982
2363.86	70.7271
2368.63	71.2684
2373.39	71.0052
2378.15	68.0561
2382.9	67.2505
2387.65	70.1129
2392.4	71.1342
2397.14	71.2051
2401.88	69.8411
2406.62	70.2411
2411.35	70.7762
2416.08	69.8499
2420.81	68.9276
2425.53	69.1589
2430.25	70.7399
2434.97	68.1681
2439.69	70.2833
2444.4	69.0912
2449.1	71.0844
2453.81	71.2096
2458.51	71.3044
2463.2	73.2097
2467.9	73.3568
2472.59	71.024
2477.27	67.6462
2481.96	69.1969
2486.64	70.3325
2491.31	71.0529
2495.99	73.4399
2500.66	72.6589
2505.32	71.65
2509.99	69.625
2514.65	70.2898
2519.31	71.5125
2523.96	70.6502
2528.61	70.3512
2533.26	68.6243
2537.9	68.6616
2542.54	70.5265
2547.18	71.0336
2551.81	68.9276
2556.44	68.0467
2561.07	67.2368
2565.69	70.6944
2570.32	71.6151
2574.93	72.2823
2579.55	72.0893
2584.16	71.5281
2588.77	70.019
2593.37	69.0393
2597.97	69.3182
2602.57	69.6371
2607.17	69.4141
2611.76	64.7889
2616.35	64.201
2620.93	66.6829
2625.51	71.2608
2630.09	72.6718
2634.67	73.2799
2639.24	71.1698
2643.81	68.8606
2648.38	69.0614
2652.94	68.2016
2657.5	66.8195
2662.06	70.7333
2666.61	72.4402
2671.16	70.7002
2675.71	68.4738
2680.25	67.9266
2684.79	69.4279
2689.33	67.8197
2693.86	67.7572
2698.39	67.1796
2702.92	67.8858
2707.45	70.6461
2711.97	72.5048
2716.49	72.1012
2721	70.028
2725.51	68.3122
2730.02	68.1599
2734.53	68.9654
2739.03	69.9458
2743.53	70.3217
2748.03	69.9183
2752.52	68.5302
2757.01	67.7908
2761.5	68.2562
2765.98	69.9006
2770.46	70.5407
2774.94	71.4275
2779.42	70.9262
2783.89	70.06
2788.36	68.4308
2792.82	69.0521
2797.28	69.5356
2801.74	66.6699
2806.2	68.633
2810.65	64.1816
2815.1	66.5201
2819.55	69.9806
2823.99	70.0954
2828.43	68.2203
2832.87	67.0772
2837.3	67.6244
2841.74	69.8508
2846.17	71.6335
2850.59	70.8124
2855.01	68.7471
2859.43	67.2708
2863.85	69.5384
2868.26	69.1948
2872.67	69.4464
2877.08	69.313
2881.48	66.8197
2885.89	65.6618
2890.28	69.3932
2894.68	70.4066
2899.07	71.1557
2903.46	70.9231
2907.85	66.4711
2912.23	67.8438
2916.61	68.0686
2920.98	69.6681
2925.36	70.9601
2929.73	70.6756
2934.1	70.8581
2938.46	68.9634
2942.82	66.1219
2947.18	64.9873
2951.54	69.2789
2955.89	71.5582
2960.24	72.1299
2964.59	68.9754
2968.93	64.0678
2973.27	64.8273
2977.61	66.7441
2981.95	66.2459
2986.28	65.8938
2990.61	66.5222
2994.94	66.4623
2999.26	67.0053
3003.58	67.1921
3007.9	68.019
3012.21	68.7099
3016.52	68.4448
3020.83	68.7391
3025.14	66.6849
3029.44	65.6793
3033.74	65.526
3038.04	66.2554
3042.33	65.8154
3046.62	65.2261
3050.91	64.9359
3055.2	64.0414
3059.48	64.2943
3063.76	67.2573
3068.03	70.0974
3072.31	69.0421
3076.58	67.0368
3080.85	64.9133
3085.11	64.8544
3089.37	64.0135
3093.63	62.0126
3097.89	63.0982
3102.14	67.6126
3106.39	69.1477
3110.64	67.1465
3114.89	66.2847
3119.13	67.7714
3123.37	67.7823
3127.6	66.5337
3131.84	65.5339
3136.07	58.0317
3140.29	62.3188
3144.52	68.2033
3148.74	68.8024
3152.96	67.7116
3157.18	66.7461
3161.39	64.9554
3165.6	66.3989
3169.81	67.9653
3174.01	67.9009
3178.22	68.3053
3182.42	68.212
3186.61	67.478
3190.8	65.4362
3195	65.2041
3199.18	68.4471
3203.37	68.5422
3207.55	68.4585
3211.73	69.1165
3215.91	70.0617
3220.08	68.4738
3224.25	68.4527
3228.42	68.6704
3232.59	68.0561
3236.75	65.5074
3240.91	65.1453
3245.07	66.4308
3249.22	67.9183
3253.37	69.476
3257.52	68.8738
3261.67	64.8908
3265.81	63.0775
3269.95	62.9054
3274.09	62.9221
3278.22	63.0726
3282.36	63.751
3286.49	64.7895
3290.61	65.7628
3294.74	64.36
3298.86	65.2656
3302.98	66.0023
3307.09	62.2714
3311.21	60.3012
3315.32	60.1516
3319.42	63.2947
3323.53	65.0515
3327.63	61.9582
3331.73	65.8759
3335.83	63.195
3339.92	62.3533
3344.01	63.4362
3348.1	64.7356
3352.19	64.9666
3356.27	64.3137
3360.35	63.7563
3364.43	63.4811
3368.5	63.3532
3372.58	63.3251
3376.65	62.6101
3380.71	60.958
3384.78	61.782
3388.84	63.1478
3392.9	63.5924
3396.95	62.9188
3401.01	61.4024
3405.06	60.3703
3409.1	60.191
3413.15	58.1379
3417.19	60.6401
3421.23	62.377
3425.27	63.931
3429.31	62.7278
3433.34	61.4796
3437.37	62.9193
3441.39	64.8744
3445.42	64.5654
3449.44	61.8173
3453.46	60.6949
3457.47	60.9486
3461.49	63.7299
3465.5	61.3107
3469.51	60.288
3473.51	61.0596
3477.52	60.1002
3481.52	57.6555
3485.51	58.6039
3489.51	59.4729
3493.5	61.2788
3497.49	61.672
3501.48	59.3496
3505.46	57.7645
3509.45	57.2403
3513.43	58.9241
3517.4	59.6225
3521.38	58.2088
3525.35	56.9428
3529.32	55.0696
3533.28	55.8161
3537.25	56.6886
3541.21	56.4595
3545.17	57.2859
3549.12	57.7983
3553.08	56.7706
3557.03	54.5241
3560.98	53.9833
3564.92	55.0071
3568.87	57.9003
3572.81	59.6297
3576.74	57.847
3580.68	57.0879
3584.61	56.0189
3588.54	56.7915
3592.47	58.6833
3596.4	59.2608
3600.32	55.9958
3604.24	55.0004
3608.16	53.8638
3612.07	53.3295
3615.98	53.0711
3619.89	52.8011
3623.8	50.9065
3627.71	51.6085
3631.61	54.1748
3635.51	53.6877
3639.41	51.4733
3643.3	49.3766
3647.19	50.1554
3651.08	52.0949
3654.97	53.052
3658.85	53.0118
3662.74	52.7702
3666.62	52.0904
3670.49	53.7775
3674.37	57.2016
3678.24	55.0275
3682.11	51.201
3685.98	52.2914
3689.84	51.8713
3693.7	48.3382
3697.56	46.5288
3701.42	47.0914
3705.28	49.9039
3709.13	50.0341
3712.98	48.83
3716.82	47.8398
3720.67	46.9176
3724.51	42.7972
3728.35	45.9055
3732.19	48.9196
3736.02	48.2346
3739.86	45.5098
3743.69	44.4166
3747.51	46.4692
3751.34	47.1798
3755.16	48.8256
3758.98	47.9162
3762.8	47.8104
3766.61	46.7825
3770.43	46.9362
3774.24	48.3498
3778.05	47.876
3781.85	46.7317
3785.65	46.0992
3789.45	46.2232
3793.25	46.0976
3797.05	45.8382
3800.84	47.6411
3804.63	48.801
3808.42	48.3639
3812.21	47.8852
3815.99	47.4355
3819.77	46.4682
3823.55	45.5842
3827.33	45.2486
3831.1	43.3207
3834.87	42.315
3838.64	44.3631
3842.41	48.3328
3846.17	48.7649
3849.93	47.8184
3853.69	44.2335
3857.45	44.5713
3861.21	46.0942
3864.96	47.8658
3868.71	48.2901
3872.46	47.4422
3876.2	43.3032
3879.94	43.8796
3883.68	46.1831
3887.42	47.3929
3891.16	45.9222
3894.89	44.8937
3898.62	44.0744
3902.35	43.4325
3906.08	43.4351
3909.8	43.9815
3913.52	45.1826
3917.24	43.5118
3920.96	42.4949
3924.67	43.2925
3928.38	43.6026
3932.09	43.998
3935.8	43.111
3939.51	41.4612
3943.21	43.6177
3946.91	44.5922
3950.61	44.2139
3954.3	43.2351
3958	42.4483
3961.69	42.6324
3965.38	42.5822
3969.06	40.6404
3972.75	39.0732
3976.43	40.9064
3980.11	40.826
3983.78	41.1949
3987.46	41.6629
3991.13	38.9248
3994.8	38.6609
3998.47	44.0556