File: Data/3-Raman/raw/20-F_brt1_FI04.txt
#Acq. time (s)=	20
#Accumulations=	3
#Range (cm-¹)=	100...4000
#Windows=	1
#Auto scanning=	Off
#Autofocus=	Off
#Macrospot=	Off
#AutoExposure=	Off
#Spike filter=	Multiple accum.
#Delay time (s)=	0
#Binning=	1
#Readout mode=	Signal
#DeNoise=	Lite
#ICS correction=	Off
#Dark correction=	Off
#Inst. Process=	Off
#Detector temperature (°C)=	-60.09
#Instrument=	LabRAM HR Evol
#Detector=	SIN-EM FIVIS
#Objective=	x100_VIS
#Grating=	150 (500nm)
#ND Filter=	100%
#Laser=	633nm_Edge
#Hole=	30.0125
#Temperature=	0
#Range=	Visible
#StageXY=	75x50mm Scan+
#StageZ=	Z motor
#X (µm)=	7222.2
#Y (µm)=	125
#Z (µm)=	1863.3
#Full time(mm:ss)=	1:02
#Project=	Buranga
#Sample=	BU18FA20_F
#Site=	F_Bertoss1
#Title=	20-F_brt1_FI04
#Remark=
#Date=	30.07.2019 16:15
#Acquired=	30.07.2019 16:15:52
100.38	359.633
106.898	311.514
113.411	274.036
119.918	247.585
126.419	229.366
132.916	218.314
139.407	205.56
145.892	197.971
152.372	192.365
158.847	181.6
165.316	194.923
171.781	177.504
178.239	167.516
184.693	169.053
191.139	161.407
197.582	155.494
204.02	152.481
210.452	150.905
216.877	149.374
223.299	152.987
229.715	165.991
236.126	212.551
242.53	229.049
248.931	182.506
255.326	175
261.714	178.997
268.099	189.012
274.477	176.051
280.851	211.914
287.218	251.327
293.582	215.8
299.939	181.713
306.293	161.687
312.639	161.666
318.982	182.178
325.318	229.665
331.651	273.667
337.977	220.53
344.297	177.526
350.614	166
356.925	176.857
363.23	188.626
369.53	181.826
375.827	163.093
382.116	149.516
388.401	139.275
394.681	138.992
400.956	142.417
407.226	148.604
413.49	152.579
419.749	160.319
426.003	171.571
432.252	199.581
438.496	222.091
444.735	214.373
450.969	205.016
457.197	202.449
463.421	191.348
469.64	170.858
475.853	154.107
482.062	146.61
488.265	145.17
494.464	146.494
500.657	148.681
506.844	150.674
513.028	152.272
519.206	151.749
525.38	151.278
531.548	149.632
537.71	144.994
543.869	141.261
550.022	138.142
556.169	138.818
562.313	141.177
568.452	138.417
574.584	134.143
580.713	136.606
586.837	144.778
592.954	167.971
599.068	198.556
605.176	213.667
611.28	203.892
617.378	192.036
623.473	188.677
629.561	192.402
635.644	190.153
641.724	185.464
647.797	174.78
653.867	178.014
659.931	185.524
665.99	181.314
672.044	163.72
678.095	150.719
684.139	136.259
690.179	125.326
696.213	122.886
702.245	125.47
708.27	125.989
714.29	122.206
720.306	122.153
726.316	124.004
732.322	122.84
738.323	119.17
744.32	117.601
750.311	118.144
756.298	118.317
762.28	117.879
768.258	116.51
774.23	114.801
780.198	113.609
786.161	116.072
792.119	118.461
798.073	119.009
804.021	115.805
809.965	114.289
815.904	116.747
821.839	118.692
827.769	116.231
833.693	116.848
839.614	116.823
845.53	117.855
851.44	119.544
857.346	119.229
863.248	118.98
869.144	120.65
875.037	123.47
880.924	126.337
886.807	128.044
892.685	127.061
898.559	123.173
904.427	120.273
910.292	120.038
916.151	128.777
922.006	122.193
927.856	122.136
933.701	126.387
939.543	130.698
945.379	140.727
951.21	155.239
957.037	169.656
962.861	179.574
968.678	193.966
974.491	220.401
980.3	269.537
986.104	337.824
991.904	396.439
997.699	341.716
1003.49	295.277
1009.28	265.325
1015.06	264.268
1020.83	277.325
1026.61	299.361
1032.37	269.789
1038.14	221.653
1043.9	189.336
1049.65	173.151
1055.4	161.775
1061.15	150.214
1066.88	145.675
1072.62	147.884
1078.35	156.797
1084.08	167.126
1089.8	173.995
1095.52	171.751
1101.23	186.774
1106.94	175.514
1112.65	151.805
1118.35	133.449
1124.05	124.873
1129.74	124.98
1135.42	131.351
1141.11	140.557
1146.78	150.312
1152.46	155.717
1158.13	153.216
1163.79	141.7
1169.45	127.832
1175.11	116.206
1180.76	114.647
1186.41	115.416
1192.05	110.772
1197.69	106.536
1203.32	105.86
1208.95	104.039
1214.58	102.895
1220.2	102.24
1225.82	102.144
1231.43	100.444
1237.04	99.4526
1242.64	99.433
1248.24	101.667
1253.83	103.502
1259.42	106.708
1265.01	113.605
1270.59	107.21
1276.17	112.43
1281.74	227
1287.31	131.966
1292.88	113.471
1298.44	105.594
1303.99	100.169
1309.55	98.9044
1315.09	100.073
1320.64	100.33
1326.18	98.0499
1331.71	95.0198
1337.24	95.9358
1342.77	97.2811
1348.29	98.3075
1353.81	98.359
1359.32	99.2107
1364.83	100.231
1370.33	98.4101
1375.84	99.2692
1381.33	135.927
1386.82	329
1392.31	111
1397.8	95.5033
1403.28	105.315
1408.75	108.885
1414.22	97.9191
1419.69	93.2017
1425.15	92.7544
1430.61	92.2615
1436.07	89.0429
1441.52	86.7137
1446.96	85.8478
1452.41	86.1522
1457.84	86.8436
1463.28	87.5931
1468.71	86.3804
1474.13	83.0733
1479.55	81.7645
1484.97	81.7598
1490.39	82.7856
1495.79	83.6754
1501.2	86.7969
1506.6	83.7847
1512	83.6634
1517.39	84.6139
1522.78	84.475
1528.16	83.3517
1533.54	82.5331
1538.92	78.511
1544.29	80.8929
1549.66	81.1799
1555.02	81.6893
1560.38	84.3845
1565.74	83.5842
1571.09	80.3726
1576.44	80.7125
1581.78	84.1514
1587.12	86.314
1592.46	85.3064
1597.79	82.522
1603.12	81.3322
1608.44	82.6804
1613.76	86.0469
1619.08	84.6431
1624.39	82.3853
1629.7	81.8565
1635	82.7158
1640.3	82.8626
1645.59	82.458
1650.88	82.0623
1656.17	82.9271
1661.46	79.6987
1666.74	76.6733
1672.01	78.2467
1677.28	80.9338
1682.55	80.2027
1687.82	78.7909
1693.07	79.1381
1698.33	80.73
1703.58	80.2127
1708.83	78.6245
1714.07	77.6258
1719.31	76.6908
1724.55	75.916
1729.78	74.9478
1735.01	74.2843
1740.23	72.1413
1745.46	67.3409
1750.67	72.0802
1755.89	74.9131
1761.09	72.5784
1766.3	71.564
1771.5	71.787
1776.7	71.9409
1781.89	72.5408
1787.08	74.3272
1792.27	75.4348
1797.45	74.503
1802.62	71.0871
1807.8	69.1235
1812.97	70.592
1818.14	73.3
1823.3	74.632
1828.46	74.4343
1833.61	73.4861
1838.76	72.1058
1843.91	72.3385
1849.05	70.9572
1854.19	70.113
1859.33	69.8266
1864.46	70.4691
1869.59	69.9314
1874.71	70.6387
1879.83	71.0732
1884.95	70.8548
1890.06	70.6418
1895.17	71.0697
1900.27	70.9566
1905.38	69.7572
1910.47	68.233
1915.57	66.5948
1920.66	67.8729
1925.74	69.9647
1930.83	69.2729
1935.91	67.0157
1940.98	65.2466
1946.05	65.9343
1951.12	66.4347
1956.18	66.0643
1961.25	67.9462
1966.3	68.9819
1971.35	69.0375
1976.4	67.9435
1981.45	66.4413
1986.49	66.9871
1991.53	66.3126
1996.56	66.4972
2001.59	67.1956
2006.62	66.7554
2011.64	63.2722
2016.66	65.9647
2021.68	68.1042
2026.69	67.6062
2031.7	65.9717
2036.7	62.5767
2041.7	62.7908
2046.7	63.7827
2051.7	64.8065
2056.69	63.6261
2061.67	63.3172
2066.65	65.9251
2071.63	68.6905
2076.61	65.892
2081.58	62.9363
2086.55	60.7094
2091.51	61.3803
2096.47	62.9607
2101.43	62.5397
2106.39	60.9481
2111.34	61.1842
2116.28	62.7494
2121.23	61.8788
2126.17	61.2187
2131.1	61.3518
2136.03	58.2681
2140.96	62.4387
2145.89	65.346
2150.81	62.6086
2155.73	62.4
2160.64	63.086
2165.55	63.34
2170.46	62.7542
2175.36	60.47
2180.26	58.9564
2185.16	58.8148
2190.05	59.9058
2194.94	61.0916
2199.83	61.1754
2204.71	62.6603
2209.59	63.1812
2214.46	61.24
2219.33	60.9708
2224.2	59.5433
2229.07	55.538
2233.93	62.8131
2238.79	60.3147
2243.64	57.978
2248.49	55.3505
2253.34	59.5613
2258.18	59.0276
2263.02	57.6174
2267.86	56.5151
2272.69	57.9974
2277.52	58.3933
2282.35	57.816
2287.17	57.5216
2291.99	58.0364
2296.8	58.2492
2301.62	57.7126
2306.43	57.2758
2311.23	57.4808
2316.03	57.1083
2320.83	59.3194
2325.63	64.8301
2330.42	62.2536
2335.21	59.6534
2339.99	59.4212
2344.77	60.0064
2349.55	60.0729
2354.32	57.6307
2359.1	54.6072
2363.86	53.9751
2368.63	54.7082
2373.39	55.47
2378.15	53.8395
2382.9	52.6684
2387.65	53.0502
2392.4	55.6787
2397.14	55.9991
2401.88	54.3118
2406.62	52.1424
2411.35	54.6324
2416.08	52.0305
2420.81	51.5241
2425.53	53.6807
2430.25	52.2475
2434.97	51.7909
2439.69	52.7202
2444.4	53.3511
2449.1	54.4099
2453.81	55.1322
2458.51	54.2283
2463.2	52.2897
2467.9	50.641
2472.59	52.2027
2477.27	52.3161
2481.96	52.571
2486.64	52.9589
2491.31	53.0403
2495.99	50.2091
2500.66	47.7844
2505.32	49.6669
2509.99	51.9191
2514.65	52.7192
2519.31	51.7725
2523.96	50.9424
2528.61	50.833
2533.26	52.8139
2537.9	53.7632
2542.54	53.4463
2547.18	52.1311
2551.81	51.4916
2556.44	50.4411
2561.07	49.1149
2565.69	49.4214
2570.32	49.9268
2574.93	48.9227
2579.55	48.2913
2584.16	48.1431
2588.77	49.8284
2593.37	50.3962
2597.97	49.5988
2602.57	48.8757
2607.17	48.493
2611.76	47.7006
2616.35	48.8662
2620.93	50.2749
2625.51	48.9307
2630.09	48.2275
2634.67	48.5773
2639.24	48.4333
2643.81	45.6154
2648.38	45.0274
2652.94	48.0154
2657.5	49.6739
2662.06	48.1878
2666.61	44.5558
2671.16	44.1102
2675.71	43.9687
2680.25	43.5631
2684.79	43.4227
2689.33	43.8429
2693.86	44.6811
2698.39	46.0402
2702.92	46.8332
2707.45	48.2234
2711.97	48.3315
2716.49	46.5373
2721	44.665
2725.51	44.9101
2730.02	46.6444
2734.53	47.4101
2739.03	45.9872
2743.53	44.8105
2748.03	44.3471
2752.52	44.6588
2757.01	44.9468
2761.5	41.9611
2765.98	45.5246
2770.46	44.0413
2774.94	44.4335
2779.42	46.045
2783.89	40.37
2788.36	40.8705
2792.82	43.0264
2797.28	45.8811
2801.74	45.4452
2806.2	44.1077
2810.65	42.6964
2815.1	42.2447
2819.55	40.8275
2823.99	45.1442
2828.43	47.3744
2832.87	46.7176
2837.3	45.9237
2841.74	45.2998
2846.17	44.8017
2850.59	45.3745
2855.01	45.8009
2859.43	44.1968
2863.85	43.4891
2868.26	43.0549
2872.67	42.5317
2877.08	41.954
2881.48	42.0929
2885.89	44.2227
2890.28	43.4427
2894.68	40.0677
2899.07	39.5303
2903.46	40.2117
2907.85	40.5447
2912.23	40.2424
2916.61	40.5493
2920.98	42.6669
2925.36	44.0094
2929.73	43.0762
2934.1	42.0855
2938.46	40.3417
2942.82	40.0746
2947.18	40.527
2951.54	41.5127
2955.89	42.7163
2960.24	41.7339
2964.59	44.6439
2968.93	42.7123
2973.27	43.612
2977.61	42.8521
2981.95	41.5776
2986.28	41.1256
2990.61	42.9232
2994.94	43.1305
2999.26	42.6665
3003.58	42.8174
3007.9	43.0924
3012.21	42.673
3016.52	42.3652
3020.83	43.9028
3025.14	43.9757
3029.44	43.3682
3033.74	42.8949
3038.04	42.8143
3042.33	43.594
3046.62	43.3779
3050.91	41.3443
3055.2	41.3284
3059.48	42.434
3063.76	44.1269
3068.03	43.9016
3072.31	45.1033
3076.58	45.1046
3080.85	44.4336
3085.11	44.3159
3089.37	44.7026
3093.63	43.578
3097.89	42.5089
3102.14	42.1808
3106.39	42.9492
3110.64	44.8279
3114.89	46.9245
3119.13	47.0071
3123.37	46.2009
3127.6	45.8482
3131.84	45.684
3136.07	47.118
3140.29	49.4691
3144.52	48.8383
3148.74	48.7955
3152.96	49.7095
3157.18	49.7681
3161.39	48.6543
3165.6	49.279
3169.81	50.0103
3174.01	49.7649
3178.22	49.795
3182.42	48.642
3186.61	48.6704
3190.8	49.9336
3195	51.1886
3199.18	54.6551
3203.37	54.5787
3207.55	52.3376
3211.73	50.108
3215.91	50.0124
3220.08	48.8991
3224.25	48.4568
3228.42	45.858
3232.59	48.7109
3236.75	50.0315
3240.91	51.3749
3245.07	50.2195
3249.22	48.84
3253.37	48.7972
3257.52	49.6155
3261.67	50.1248
3265.81	50.0496
3269.95	48.8397
3274.09	47.729
3278.22	44.7884
3282.36	45.6958
3286.49	46.6789
3290.61	46.7519
3294.74	45.3281
3298.86	44.0565
3302.98	43.6397
3307.09	44.1361
3311.21	45.482
3315.32	46.7472
3319.42	47.772
3323.53	47.3683
3327.63	49.1009
3331.73	49.3521
3335.83	47.6703
3339.92	46.121
3344.01	45.3979
3348.1	45.3024
3352.19	47.1654
3356.27	47.3755
3360.35	47.6966
3364.43	48.7287
3368.5	47.6838
3372.58	48.0122
3376.65	48.1223
3380.71	45.6058
3384.78	45.9217
3388.84	47.1451
3392.9	48.5063
3396.95	49.8342
3401.01	48.8414
3405.06	47.3285
3409.1	47.9991
3413.15	49.9418
3417.19	49.569
3421.23	49.0732
3425.27	49.5696
3429.31	50.7295
3433.34	50.0463
3437.37	47.8042
3441.39	46.6261
3445.42	47.3626
3449.44	48.9148
3453.46	49.1749
3457.47	47.3611
3461.49	45.4393
3465.5	45.6345
3469.51	46.7364
3473.51	46.7105
3477.52	45.0095
3481.52	44.5581
3485.51	45.6921
3489.51	45.0372
3493.5	43.6256
3497.49	43.0453
3501.48	42.7037
3505.46	42.6043
3509.45	42.3361
3513.43	41.8834
3517.4	41.8361
3521.38	38.7695
3525.35	37.9558
3529.32	42.6258
3533.28	40.9886
3537.25	40.3603
3541.21	40.054
3545.17	40.442
3549.12	40.4759
3553.08	39.4894
3557.03	38.901
3560.98	39.3874
3564.92	41.8752
3568.87	42.3297
3572.81	43.2595
3576.74	45.6064
3580.68	46.2046
3584.61	46.7268
3588.54	46.5082
3592.47	45.5646
3596.4	45.2613
3600.32	41.4494
3604.24	38.0805
3608.16	34.203
3612.07	32.5596
3615.98	34.3709
3619.89	35.0786
3623.8	35.3399
3627.71	34.3525
3631.61	33.3812
3635.51	32.2361
3639.41	31.15
3643.3	29.6216
3647.19	30.3869
3651.08	34.3456
3654.97	34.2028
3658.85	33.6459
3662.74	30.3518
3666.62	32.2482
3670.49	32.2494
3674.37	31.7863
3678.24	30.5967
3682.11	30.12
3685.98	29.8228
3689.84	30.1931
3693.7	32.7182
3697.56	32.2326
3701.42	31.0969
3705.28	30.364
3709.13	30.3879
3712.98	30.6202
3716.82	29.6069
3720.67	28.2881
3724.51	27.0786
3728.35	28.0844
3732.19	28.5194
3736.02	28.7099
3739.86	29.1158
3743.69	28.0874
3747.51	26.509
3751.34	27.5733
3755.16	28.4308
3758.98	29.9274
3762.8	31.0131
3766.61	29.738
3770.43	28.5406
3774.24	27.4158
3778.05	27.7168
3781.85	28.762
3785.65	28.2917
3789.45	28.0807
3793.25	29.5593
3797.05	28.8794
3800.84	28.2169
3804.63	28.2709
3808.42	28.5208
3812.21	28.9544
3815.99	29.4084
3819.77	29.0202
3823.55	28.1457
3827.33	27.9935
3831.1	28.2729
3834.87	27.7132
3838.64	27.2835
3842.41	27.8495
3846.17	29.0035
3849.93	28.9979
3853.69	29.1188
3857.45	30.0375
3861.21	28.7576
3864.96	27.6805
3868.71	26.8734
3872.46	26.0706
3876.2	27.5901
3879.94	28.9711
3883.68	28.3238
3887.42	26.4501
3891.16	25.9207
3894.89	26.7777
3898.62	26.9712
3902.35	26.2664
3906.08	26.9169
3909.8	27.8032
3913.52	29.8196
3917.24	29.8118
3920.96	28.0775
3924.67	27.4638
3928.38	27.447
3932.09	27.7198
3935.8	27.7331
3939.51	26.9858
3943.21	27.1565
3946.91	26.4131
3950.61	26.581
3954.3	26.9119
3958	27.4746
3961.69	27.5624
3965.38	26.9352
3969.06	25.8445
3972.75	24.6039
3976.43	23.6866
3980.11	25.9245
3983.78	27.169
3987.46	27.2902
3991.13	26.4506
3994.8	26.345
3998.47	28.1007