File: Data/3-Raman/raw/20-F_brt1_FI05_1.txt
#Acq. time (s)=	20
#Accumulations=	3
#Range (cm-¹)=	100...4000
#Windows=	1
#Auto scanning=	Off
#Autofocus=	Off
#Macrospot=	Off
#AutoExposure=	Off
#Spike filter=	Multiple accum.
#Delay time (s)=	0
#Binning=	1
#Readout mode=	Signal
#DeNoise=	Lite
#ICS correction=	Off
#Dark correction=	Off
#Inst. Process=	Off
#Detector temperature (°C)=	-60.09
#Instrument=	LabRAM HR Evol
#Detector=	SIN-EM FIVIS
#Objective=	x100_VIS
#Grating=	150 (500nm)
#ND Filter=	100%
#Laser=	633nm_Edge
#Hole=	30.0125
#Temperature=	0
#Range=	Visible
#StageXY=	75x50mm Scan+
#StageZ=	Z motor
#X (µm)=	6849.3
#Y (µm)=	-44.4
#Z (µm)=	1885.1
#Full time(mm:ss)=	1:03
#Project=	Buranga
#Sample=	BU18FA20_F
#Site=	F_Bertoss1
#Title=	20-F_brt1_FI05_1
#Remark=
#Date=	30.07.2019 16:20
#Acquired=	30.07.2019 16:20:21
100.38	456.987
106.898	401.026
113.411	355.441
119.918	323.243
126.419	301.961
132.916	289.265
139.407	278.369
145.892	270.291
152.372	249.397
158.847	244.685
165.316	252.189
171.781	244.658
178.239	212.835
184.693	204.061
191.139	196.828
197.582	190.361
204.02	187.738
210.452	184.609
216.877	178.048
223.299	190.041
229.715	220.088
236.126	331.679
242.53	369.333
248.931	272.7
255.326	247.791
261.714	263.234
268.099	267.086
274.477	274.934
280.851	341.166
287.218	444.22
293.582	349.117
299.939	257.534
306.293	213.436
312.639	222.624
318.982	274.453
325.318	411.021
331.651	535.857
337.977	375.925
344.297	253.883
350.614	216.769
356.925	227.513
363.23	240.414
369.53	250.557
375.827	223.52
382.116	186.211
388.401	152.172
394.681	160.662
400.956	167.465
407.226	179.155
413.49	192.811
419.749	212.484
426.003	255.661
432.252	312.228
438.496	367.746
444.735	361.882
450.969	320.859
457.197	286.271
463.421	278.846
469.64	228.993
475.853	190.01
482.062	173.064
488.265	169.695
494.464	167.077
500.657	171.492
506.844	182.744
513.028	192.999
519.206	199.275
525.38	196.114
531.548	192.248
537.71	188.882
543.869	175.053
550.022	165.501
556.169	166.55
562.313	162.267
568.452	153.693
574.584	149.864
580.713	151.389
586.837	167.397
592.954	204.697
599.068	287.299
605.176	345.442
611.28	281.625
617.378	259.734
623.473	248.249
629.561	256.302
635.644	270.232
641.724	248.529
647.797	247.643
653.867	267.872
659.931	279.075
665.99	254.818
672.044	209.592
678.095	170.092
684.139	142.383
690.179	128.371
696.213	112.235
702.245	113.386
708.27	114.917
714.29	115.484
720.306	114.091
726.316	112.95
732.322	112.108
738.323	111.335
744.32	108.634
750.311	108.944
756.298	109.646
762.28	109.302
768.258	108.226
774.23	107.005
780.198	105.44
786.161	104.021
792.119	105.31
798.073	107.388
804.021	109.408
809.965	110.547
815.904	111.755
821.839	114.738
827.769	116.498
833.693	115.442
839.614	117.285
845.53	118.799
851.44	116.304
857.346	115.027
863.248	116.403
869.144	121.755
875.037	125.627
880.924	129.335
886.807	132.755
892.685	133.911
898.559	132.983
904.427	128.821
910.292	126.829
916.151	128.925
922.006	131.862
927.856	143.024
933.701	148.132
939.543	165.379
945.379	195.833
951.21	233.224
957.037	267.674
962.861	284.893
968.678	307.591
974.491	365.818
980.3	463.094
986.104	648.872
991.904	781.564
997.699	692.498
1003.49	556.778
1009.28	481.677
1015.06	471.844
1020.83	524.679
1026.61	633.981
1032.37	528.639
1038.14	380.392
1043.9	299.884
1049.65	243.268
1055.4	209.837
1061.15	201.165
1066.88	192.924
1072.62	192.716
1078.35	211.541
1084.08	235.416
1089.8	259.113
1095.52	284.485
1101.23	304.343
1106.94	282.349
1112.65	217.207
1118.35	174.654
1124.05	153.772
1129.74	152.972
1135.42	162.336
1141.11	177.636
1146.78	195.184
1152.46	216.183
1158.13	243.349
1163.79	179.826
1169.45	141.788
1175.11	130.121
1180.76	128.296
1186.41	124.396
1192.05	114.27
1197.69	108.717
1203.32	104.69
1208.95	102.1
1214.58	99.4289
1220.2	96.2143
1225.82	92.4517
1231.43	92.2298
1237.04	93.2995
1242.64	95.3309
1248.24	97.9207
1253.83	100.763
1259.42	104.023
1265.01	105.301
1270.59	102.131
1276.17	118.216
1281.74	200.76
1287.31	132.333
1292.88	108.834
1298.44	95.0117
1303.99	93.2983
1309.55	95.1787
1315.09	96.381
1320.64	93.2242
1326.18	92.7282
1331.71	90.1439
1337.24	88.8845
1342.77	85.8553
1348.29	83.6075
1353.81	84.3468
1359.32	86.5966
1364.83	90.1534
1370.33	91.9337
1375.84	94.2389
1381.33	134.724
1386.82	283
1392.31	117.378
1397.8	92.2801
1403.28	91.9044
1408.75	91.7326
1414.22	88.8163
1419.69	84.828
1425.15	82.808
1430.61	83.3218
1436.07	83.1389
1441.52	80.2016
1446.96	79.4606
1452.41	81.2791
1457.84	80.9481
1463.28	79.2298
1468.71	76.9605
1474.13	80.6609
1479.55	80.466
1484.97	82.2684
1490.39	80.5025
1495.79	77.8164
1501.2	73.9311
1506.6	77.5322
1512	81.0422
1517.39	81.0212
1522.78	78.0262
1528.16	78.853
1533.54	77.6423
1538.92	77.2106
1544.29	78.2376
1549.66	78.3896
1555.02	79.7086
1560.38	78.8946
1565.74	74.9655
1571.09	75.4489
1576.44	74.9677
1581.78	76.1116
1587.12	79.4394
1592.46	77.621
1597.79	75.6696
1603.12	73.6765
1608.44	73.9329
1613.76	78.622
1619.08	76.2375
1624.39	73.6284
1629.7	73.8678
1635	77.0919
1640.3	76.0531
1645.59	76.7125
1650.88	77.9465
1656.17	77.3554
1661.46	76.1647
1666.74	75.9838
1672.01	76.4088
1677.28	78.8189
1682.55	77.8523
1687.82	74.5999
1693.07	72.8381
1698.33	75.5133
1703.58	77.6965
1708.83	77.9923
1714.07	76.9898
1719.31	73.787
1724.55	72.856
1729.78	74.0719
1735.01	74.5535
1740.23	77.2821
1745.46	74.6579
1750.67	72.2048
1755.89	71.9095
1761.09	73.0359
1766.3	69.6528
1771.5	67.9488
1776.7	68.9446
1781.89	71.2521
1787.08	72.5617
1792.27	71.554
1797.45	68.6274
1802.62	68.5253
1807.8	69.6923
1812.97	71.7824
1818.14	71.3112
1823.3	71.6891
1828.46	72.407
1833.61	71.3042
1838.76	70.1947
1843.91	69.423
1849.05	69.025
1854.19	68.9495
1859.33	68.8632
1864.46	69.4314
1869.59	67.0263
1874.71	65.8595
1879.83	67.0383
1884.95	70.0353
1890.06	71.1268
1895.17	69.4851
1900.27	69.481
1905.38	68.171
1910.47	67.5118
1915.57	66.6483
1920.66	67.6472
1925.74	68.7832
1930.83	68.2911
1935.91	68.8058
1940.98	66.4629
1946.05	65.2741
1951.12	65.1937
1956.18	63.8945
1961.25	66.6474
1966.3	69.9785
1971.35	68.4366
1976.4	67.139
1981.45	67.4263
1986.49	66.7609
1991.53	66.0954
1996.56	67.516
2001.59	68.3893
2006.62	68.22
2011.64	62.6404
2016.66	59.5384
2021.68	62.1176
2026.69	64.743
2031.7	66.9676
2036.7	69.1151
2041.7	66.3213
2046.7	64.9549
2051.7	64.3955
2056.69	65.0168
2061.67	66.0891
2066.65	66.8734
2071.63	67.1638
2076.61	66.9767
2081.58	65.5862
2086.55	66.4108
2091.51	66.982
2096.47	66.5323
2101.43	61.2287
2106.39	63.8229
2111.34	65.6975
2116.28	65.1463
2121.23	65.4927
2126.17	66.3798
2131.1	65.8858
2136.03	63.9906
2140.96	62.7804
2145.89	62.8145
2150.81	64.0598
2155.73	65.1436
2160.64	65.1447
2165.55	62.2285
2170.46	62.8472
2175.36	63.9375
2180.26	64.675
2185.16	64.5152
2190.05	63.1609
2194.94	62.7715
2199.83	59.7127
2204.71	59.0798
2209.59	61.4426
2214.46	61.2246
2219.33	58.5017
2224.2	60.5897
2229.07	62.9831
2233.93	62.0182
2238.79	62.6755
2243.64	62.0573
2248.49	58.3687
2253.34	57.2011
2258.18	60.4645
2263.02	62.4905
2267.86	62.3507
2272.69	62.0218
2277.52	63.3697
2282.35	63.4215
2287.17	63.2659
2291.99	63.001
2296.8	62.0828
2301.62	60.6912
2306.43	59.2475
2311.23	58.082
2316.03	58.5297
2320.83	61.1796
2325.63	65.5026
2330.42	64.5743
2335.21	62.4858
2339.99	62.0444
2344.77	59.4353
2349.55	59.003
2354.32	60.5139
2359.1	61.1461
2363.86	60.5886
2368.63	57.868
2373.39	56.6851
2378.15	59.6916
2382.9	56.1667
2387.65	54.2316
2392.4	56.1147
2397.14	58.9555
2401.88	61.2733
2406.62	60.423
2411.35	58.2775
2416.08	57.2021
2420.81	57.7202
2425.53	59.5731
2430.25	59.976
2434.97	59.4316
2439.69	58.5752
2444.4	57.1949
2449.1	56.9537
2453.81	58.7362
2458.51	58.8122
2463.2	58.4968
2467.9	58.6721
2472.59	57.7844
2477.27	57.5547
2481.96	58.2351
2486.64	59.1507
2491.31	59.7158
2495.99	59.9538
2500.66	58.1467
2505.32	57.4348
2509.99	55.912
2514.65	57.1784
2519.31	57.9866
2523.96	57.3399
2528.61	56.2095
2533.26	57.1897
2537.9	58.6895
2542.54	58.3941
2547.18	57.471
2551.81	56.8711
2556.44	56.9458
2561.07	57.6926
2565.69	57.1103
2570.32	58.4735
2574.93	59.527
2579.55	57.8404
2584.16	55.4113
2588.77	56.4269
2593.37	56.9641
2597.97	57.1505
2602.57	57.6526
2607.17	57.2445
2611.76	56.6476
2616.35	56.5823
2620.93	55.7977
2625.51	56.0754
2630.09	55.7009
2634.67	55.2822
2639.24	56.3166
2643.81	56.2313
2648.38	56.0931
2652.94	56.47
2657.5	57.6446
2662.06	58.3187
2666.61	56.5779
2671.16	55.1939
2675.71	54.8286
2680.25	54.9788
2684.79	55.198
2689.33	55.3642
2693.86	55.2947
2698.39	55.1201
2702.92	55.1581
2707.45	55.4802
2711.97	54.0997
2716.49	53.9449
2721	54.3383
2725.51	54.6742
2730.02	54.8975
2734.53	52.3185
2739.03	56.2059
2743.53	54.9206
2748.03	53.9454
2752.52	53.626
2757.01	54.5119
2761.5	55.4576
2765.98	54.3
2770.46	53.008
2774.94	52.2844
2779.42	52.9386
2783.89	53.4674
2788.36	52.9711
2792.82	51.7435
2797.28	50.2757
2801.74	52.6669
2806.2	55.2071
2810.65	54.0581
2815.1	52.7379
2819.55	53.7723
2823.99	55.1898
2828.43	54.1158
2832.87	53.9741
2837.3	53.1719
2841.74	51.5816
2846.17	52.8264
2850.59	52.748
2855.01	53.0531
2859.43	53.4509
2863.85	54.3035
2868.26	52.6844
2872.67	50.7426
2877.08	50.7278
2881.48	52.7439
2885.89	52.5387
2890.28	52.0238
2894.68	52.2894
2899.07	52.2914
2903.46	52.796
2907.85	53.5851
2912.23	52.6072
2916.61	51.9659
2920.98	51.5814
2925.36	51.4898
2929.73	51.5749
2934.1	51.7565
2938.46	50.8111
2942.82	50.6779
2947.18	52.135
2951.54	52.8325
2955.89	51.7427
2960.24	52.2513
2964.59	51.4441
2968.93	50.1103
2973.27	51.2286
2977.61	54.0153
2981.95	54.509
2986.28	53.2886
2990.61	47.8229
2994.94	52.9459
2999.26	53.0586
3003.58	54.3103
3007.9	55.1481
3012.21	55.5341
3016.52	52.6693
3020.83	51.0728
3025.14	52.2681
3029.44	54.2008
3033.74	54.5508
3038.04	51.8951
3042.33	51.8046
3046.62	54.5705
3050.91	57.8069
3055.2	55.3023
3059.48	54.2489
3063.76	54.7985
3068.03	56.387
3072.31	56.8331
3076.58	55.5498
3080.85	55.552
3085.11	57.9588
3089.37	57.895
3093.63	57.8237
3097.89	59.2383
3102.14	59.8932
3106.39	59.2081
3110.64	59.5662
3114.89	60.5597
3119.13	61.5992
3123.37	61.0478
3127.6	60.4625
3131.84	59.8277
3136.07	62.4531
3140.29	63.8915
3144.52	62.103
3148.74	61.127
3152.96	62.7056
3157.18	64.0685
3161.39	65.1225
3165.6	68.0459
3169.81	70.2497
3174.01	71.0319
3178.22	70.7409
3182.42	71.0027
3186.61	71.9234
3190.8	73.3702
3195	73.3264
3199.18	72.5396
3203.37	71.6289
3207.55	66.3694
3211.73	68.871
3215.91	70.4988
3220.08	70.1253
3224.25	69.3081
3228.42	68.3316
3232.59	69.2632
3236.75	69.9645
3240.91	68.3566
3245.07	67.0855
3249.22	65.2905
3253.37	66.073
3257.52	65.3161
3261.67	62.3932
3265.81	61.4633
3269.95	61.9131
3274.09	63.3595
3278.22	63.2119
3282.36	60.079
3286.49	56.5665
3290.61	57.8973
3294.74	60.236
3298.86	59.9389
3302.98	62.0446
3307.09	60.2048
3311.21	58.7324
3315.32	62.5591
3319.42	61.8231
3323.53	61.1299
3327.63	59.9117
3331.73	59.9117
3335.83	62.0243
3339.92	60.2225
3344.01	60.8283
3348.1	61.0465
3352.19	61.8879
3356.27	63.1256
3360.35	61.9577
3364.43	60.2461
3368.5	59.618
3372.58	62.0795
3376.65	62.8899
3380.71	62.7251
3384.78	61.5281
3388.84	62.4775
3392.9	63.6412
3396.95	65.1828
3401.01	66.0808
3405.06	65.0686
3409.1	64.1928
3413.15	63.4193
3417.19	62.0575
3421.23	59.2439
3425.27	61.7517
3429.31	62.3013
3433.34	60.5332
3437.37	59.6936
3441.39	59.4676
3445.42	59.4217
3449.44	59.4759
3453.46	57.8368
3457.47	55.6575
3461.49	54.4176
3465.5	57.2974
3469.51	51.7566
3473.51	51.7408
3477.52	52.2294
3481.52	52.5012
3485.51	53.2083
3489.51	53.0151
3493.5	51.1344
3497.49	52.2346
3501.48	54.1402
3505.46	54.5078
3509.45	52.3727
3513.43	53.507
3517.4	51.8192
3521.38	53.3783
3525.35	53.0417
3529.32	51.8328
3533.28	51.0175
3537.25	50.7062
3541.21	50.9671
3545.17	51.4902
3549.12	51.7723
3553.08	51.2747
3557.03	50.3722
3560.98	49.417
3564.92	52.3206
3568.87	55.393
3572.81	57.984
3576.74	60.6733
3580.68	63.9438
3584.61	65.3568
3588.54	65.202
3592.47	64.2765
3596.4	61.7938
3600.32	55.0413
3604.24	49.2331
3608.16	46.3096
3612.07	45.8349
3615.98	44.2016
3619.89	41.8753
3623.8	42.2509
3627.71	43.8031
3631.61	44.973
3635.51	44.0056
3639.41	43.4923
3643.3	43.0464
3647.19	41.2356
3651.08	39.6949
3654.97	38.1595
3658.85	40.3654
3662.74	42.5329
3666.62	41.8104
3670.49	40.1847
3674.37	38.8992
3678.24	40.2315
3682.11	39.152
3685.98	38.8504
3689.84	39.8072
3693.7	40.8411
3697.56	37.4193
3701.42	35.9461
3705.28	38.6517
3709.13	39.6773
3712.98	39.168
3716.82	38.1456
3720.67	37.1946
3724.51	38.8751
3728.35	40.3029
3732.19	39.1991
3736.02	38.4119
3739.86	39.8165
3743.69	38.7982
3747.51	36.2131
3751.34	35.0517
3755.16	36.6168
3758.98	37.8276
3762.8	37.0381
3766.61	35.6703
3770.43	37.3095
3774.24	37.6985
3778.05	36.5188
3781.85	35.0608
3785.65	34.7708
3789.45	35.1935
3793.25	37.4912
3797.05	38.4061
3800.84	37.2632
3804.63	35.1178
3808.42	35.488
3812.21	36.1337
3815.99	37.7831
3819.77	35.9374
3823.55	35.0938
3827.33	35.5932
3831.1	35.1294
3834.87	35.3746
3838.64	35.6341
3842.41	35.3875
3846.17	35.0503
3849.93	34.2931
3853.69	34.9904
3857.45	34.3826
3861.21	35.2857
3864.96	34.7409
3868.71	32.9482
3872.46	33.7057
3876.2	36.0482
3879.94	36.6689
3883.68	37.0397
3887.42	37.3183
3891.16	37.1233
3894.89	37.015
3898.62	37.2247
3902.35	36.0247
3906.08	33.4882
3909.8	31.4193
3913.52	33.1997
3917.24	36.9115
3920.96	38.0101
3924.67	37.2736
3928.38	36.3919
3932.09	35.464
3935.8	34.489
3939.51	33.4835
3943.21	32.5047
3946.91	31.9486
3950.61	33.6922
3954.3	34.7659
3958	34.1054
3961.69	32.8328
3965.38	31.9566
3969.06	31.3289
3972.75	32.0962
3976.43	34.7298
3980.11	36.2048
3983.78	36.0538
3987.46	34.8588
3991.13	32.7139
3994.8	32.6641
3998.47	31.4001