File: Data/3-Raman/raw/20-G_trl1_FI02_L.txt
#Acq. time (s)=	15
#Accumulations=	3
#Range (cm-¹)=	100...4000
#Windows=	1
#Auto scanning=	Off
#Autofocus=	Off
#Macrospot=	Off
#AutoExposure=	Off
#Spike filter=	Multiple accum.
#Delay time (s)=	0
#Binning=	1
#Readout mode=	Signal
#DeNoise=	Lite
#ICS correction=	Off
#Dark correction=	Off
#Inst. Process=	Off
#Detector temperature (°C)=	-60.09
#Instrument=	LabRAM HR Evol
#Detector=	SIN-EM FIVIS
#Objective=	x100_VIS
#Grating=	150 (500nm)
#ND Filter=	100%
#Laser=	532nm_Edge
#Hole=	30.0125
#Temperature=	0
#Range=	Visible
#StageXY=	75x50mm Scan+
#StageZ=	Z motor
#X (µm)=	19541.3
#Y (µm)=	6122.2
#Z (µm)=	1894.4
#Full time(s)=	47
#Project=	Buranga
#Sample=	BU18FA20_G
#Site=	G_trl1
#Title=	20-G_trl1_FI02_L
#Remark=
#Date=	30.07.2019 17:36
#Acquired=	30.07.2019 17:36:48
103.656	9536.02
108.278	9205.04
112.899	8846.96
117.517	8443.76
122.131	8061.96
126.744	7683.87
131.355	7348.19
135.964	7063.34
140.571	6827.25
145.173	6622.36
149.776	6474.35
154.375	6368.89
158.973	6420.37
163.566	7435.7
168.159	8388
172.75	7809.65
177.339	6153.26
181.923	5160.53
186.507	4990.12
191.089	5353.45
195.668	6118.96
200.243	6515.36
204.818	5417.23
209.391	4542.91
213.96	3903.1
218.528	3480.94
223.094	3290.46
227.655	3321.43
232.217	3571.2
236.776	4046.27
241.331	4737.81
245.886	5559
250.439	6679.93
254.987	7462.42
259.535	6047.05
264.081	4189.96
268.622	3355.34
273.164	3497.79
277.703	4669.5
282.238	8073
286.773	11291
291.305	10922.8
295.833	6999.02
300.362	5007.89
304.885	3897.77
309.409	3349.54
313.93	2863.91
318.448	3167
322.965	3736.43
327.477	4334.32
331.99	4908.49
336.5	5371.49
341.007	5843.27
345.513	6103.7
350.014	6293.12
354.516	6594.8
359.013	6760.87
363.51	6208.61
368.005	5429.46
372.496	4807.45
376.987	4290.07
381.473	3892.94
385.96	3575.55
390.442	3376.54
394.923	3335.23
399.401	3474.34
403.879	3475.04
408.352	3020.79
412.825	2513.04
417.294	2203.86
421.763	2338.17
426.227	2295.73
430.692	2162.43
435.152	2013.42
439.612	1824.23
444.068	1800.35
448.524	1781.11
452.976	1871.21
457.427	1948.19
461.874	2032.17
466.32	2079.35
470.765	2077.98
475.205	2075.84
479.646	2121.35
484.083	2238.68
488.519	2437.64
492.951	2739.01
497.381	3104.98
501.811	3473.77
506.237	3691.85
510.663	3473.41
515.084	2965.95
519.504	2465.25
523.923	2196.97
528.338	1987.83
532.753	1859.58
537.164	1773.45
541.572	1714.92
545.981	1690.38
550.385	1692.36
554.788	1717.3
559.19	1759.25
563.588	1810.09
567.986	1853.53
572.38	1808.27
576.771	1814.9
581.163	1835.44
585.551	2018.32
589.936	2702.46
594.319	3971.41
598.702	4701.43
603.081	3848.9
607.458	2729.08
611.835	2335.05
616.208	2350.25
620.578	2248.68
624.949	2091.39
629.315	1957.33
633.68	1864.44
638.042	1819.3
642.404	1838.04
646.762	1905.66
651.118	2015.43
655.472	2155.52
659.825	2364.22
664.175	2663.48
668.523	3211.24
672.868	3817.89
677.213	4269.2
681.555	4406.55
685.894	4269.42
690.231	3631.22
694.566	2812.96
698.901	2023.23
703.232	1627.22
707.561	1409.75
711.888	1296.28
716.212	1234.53
720.537	1186.34
724.858	1149.05
729.176	1126
733.493	1111.45
737.807	1108.73
742.119	1116.85
746.432	1133.43
750.74	1157.2
755.046	1196.2
759.35	1238.81
763.652	1315.83
767.952	1529.57
772.25	2009.17
776.546	2772.14
780.842	3904.77
785.133	5240.72
789.423	5389.21
793.711	4085.18
797.997	2850.84
802.28	2061.38
806.562	1535.98
810.841	1292.45
815.119	1173.86
819.394	1066.49
823.668	1009.66
827.941	960.516
832.211	919.053
836.478	885.646
840.743	859.732
845.006	841.864
849.268	831.243
853.527	824.729
857.784	821.076
862.039	833.883
866.293	865.997
870.544	912.704
874.793	931.978
879.04	900.176
883.285	840.835
887.528	765.905
891.769	735.452
896.008	715.487
900.246	703.231
904.481	694.23
908.714	692.596
912.945	696.498
917.174	701.477
921.401	714.311
925.626	735.849
929.849	753.472
934.068	805.094
938.287	863.052
942.504	988.002
946.72	1230.64
950.933	1566
955.144	1942.59
959.353	2163.65
963.56	1925.4
967.765	1544.44
971.968	1240.93
976.17	1117.72
980.367	1021.7
984.564	948.482
988.759	896.018
992.953	851.354
997.144	817.459
1001.33	791.756
1005.52	776.879
1009.71	772.349
1013.89	778.911
1018.07	796.034
1022.25	824.043
1026.43	863.958
1030.6	906.637
1034.78	966.18
1038.94	1031.34
1043.11	1250.85
1047.28	1571
1051.45	2307
1055.61	3640.68
1059.77	5119
1063.93	5282.74
1068.09	3920.78
1072.25	2762.98
1076.4	2073.37
1080.55	1793.11
1084.7	1957.21
1088.85	2467.18
1092.99	3588.55
1097.14	4054.1
1101.28	4307.81
1105.42	4335.45
1109.56	4507.72
1113.69	4792.94
1117.83	4947.8
1121.96	5036.04
1126.09	5038.05
1130.22	4976.12
1134.35	4986.27
1138.47	5140.56
1142.59	5157.14
1146.71	4474.56
1150.83	3466.53
1154.95	3020.69
1159.06	3077.74
1163.18	3496.56
1167.29	3690.22
1171.4	3390.4
1175.5	2977.07
1179.61	2526.01
1183.71	2024.99
1187.81	1478.4
1191.91	1193.08
1196.01	1061.34
1200.1	1004.59
1204.2	965.295
1208.29	934.695
1212.38	923.562
1216.47	917.659
1220.55	1094.83
1224.64	1305.32
1228.72	1450.37
1232.8	1545.7
1236.88	1600.7
1240.95	1610.18
1245.03	1574.79
1249.1	1516.14
1253.17	1422.39
1257.24	1275.92
1261.31	1086.49
1265.37	946.192
1269.44	898.395
1273.5	878.464
1277.56	819.912
1281.61	763.437
1285.67	699.168
1289.72	665.925
1293.77	631.504
1297.83	602.684
1301.87	582.788
1305.92	570.368
1309.96	565.597
1314.01	564.518
1318.05	559.094
1322.09	553.795
1326.12	548.61
1330.16	531.453
1334.19	516.105
1338.22	513.153
1342.25	527.12
1346.28	538.133
1350.3	541.498
1354.33	536.094
1358.35	553.123
1362.37	622.62
1366.39	729.246
1370.4	950.921
1374.42	1184.9
1378.43	1388.14
1382.44	1476.61
1386.45	1303.81
1390.46	871.211
1394.46	676.03
1398.46	587.867
1402.47	522.113
1406.46	477.925
1410.46	445.144
1414.46	420.484
1418.45	403.714
1422.45	392.774
1426.43	386.258
1430.42	381.778
1434.41	377.877
1438.39	373.835
1442.38	369.229
1446.36	364.581
1450.34	360.38
1454.31	355.937
1458.29	351.722
1462.27	351.153
1466.24	353.88
1470.21	357.178
1474.18	360.329
1478.14	360.661
1482.11	359.612
1486.07	358.033
1490.03	355.131
1493.99	353.914
1497.95	352.841
1501.9	353.893
1505.86	357.159
1509.81	359.79
1513.76	363.034
1517.71	364.941
1521.65	369.037
1525.6	373.938
1529.54	379.531
1533.48	387.245
1537.42	394.776
1541.36	400.973
1545.29	406.583
1549.23	411.485
1553.16	415.861
1557.09	419.786
1561.02	426.002
1564.94	431.065
1568.87	438.22
1572.79	450.557
1576.71	464.95
1580.63	483.037
1584.55	503.192
1588.47	523.356
1592.38	543.562
1596.29	563.889
1600.2	587.828
1604.11	612.883
1608.02	635.882
1611.92	659.258
1615.83	683.686
1619.73	706.291
1623.63	725.069
1627.53	746.289
1631.42	766.32
1635.32	781.045
1639.21	789.068
1643.1	790.202
1646.99	782.631
1650.88	769.954
1654.76	754.047
1658.64	734.882
1662.53	713.861
1666.41	690.315
1670.28	660.438
1674.16	631.357
1678.04	601.9
1681.91	572.866
1685.78	543.799
1689.65	518.3
1693.52	498.756
1697.38	470.921
1701.25	445.984
1705.11	423.362
1708.97	402.84
1712.83	384.444
1716.69	368.134
1720.54	353.739
1724.4	340.823
1728.25	330.116
1732.1	321.258
1735.95	313.506
1739.79	306.086
1743.64	299.393
1747.48	293.281
1751.33	282.77
1755.17	278.922
1759	275.696
1762.84	272.535
1766.68	270.488
1770.51	266.427
1774.34	260.599
1778.17	256.354
1782	251.815
1785.82	247.555
1789.65	243.768
1793.47	240.838
1797.29	238.093
1801.11	232.533
1804.93	230.24
1808.74	228.96
1812.56	228.466
1816.37	229.084
1820.18	231.729
1823.99	233.038
1827.79	231.106
1831.6	229.366
1835.4	227.612
1839.2	226.279
1843	225.073
1846.8	224.111
1850.6	223.367
1854.39	222.842
1858.19	222.834
1861.98	222.996
1865.77	223.935
1869.56	226.151
1873.34	229.078
1877.13	231.317
1880.91	233.432
1884.69	234.676
1888.47	235.803
1892.25	236.098
1896.03	235.469
1899.8	232.547
1903.57	229.9
1907.34	229.923
1911.11	233.757
1914.88	237.981
1918.65	241.016
1922.41	243.52
1926.18	244.627
1929.94	244.981
1933.7	243.356
1937.45	240.21
1941.21	236.614
1944.96	234.923
1948.72	237.131
1952.47	240.087
1956.22	241.91
1959.96	244.329
1963.71	246.443
1967.45	249.639
1971.2	251.84
1974.94	256.118
1978.68	260.162
1982.42	263.034
1986.15	266.185
1989.89	270.438
1993.62	274.265
1997.35	277.92
2001.08	281.472
2004.8	284.749
2008.53	288.006
2012.25	291.202
2015.98	294.574
2019.7	297.239
2023.42	296.315
2027.13	296.794
2030.85	300.158
2034.56	307.119
2038.28	312.758
2041.99	314.836
2045.7	316.495
2049.41	318.202
2053.11	319.656
2056.82	320.82
2060.52	321.621
2064.22	321.927
2067.92	321.287
2071.62	319.132
2075.31	317.64
2079.01	316.926
2082.7	320.186
2086.39	323.756
2090.08	328.129
2093.77	329.858
2097.45	330.562
2101.14	329.176
2104.82	327.331
2108.5	324.279
2112.18	321.728
2115.86	320.302
2119.54	324.388
2123.21	325.729
2126.88	322.255
2130.56	322.466
2134.23	321.674
2137.89	320.951
2141.56	317.496
2145.23	315.841
2148.89	314.642
2152.55	315.575
2156.21	317.684
2159.87	320.913
2163.53	324.825
2167.18	330.712
2170.84	332.84
2174.49	334.478
2178.14	335.211
2181.79	335.496
2185.44	327.115
2189.08	330.154
2192.73	340.15
2196.37	347.994
2200.01	349.087
2203.65	349.557
2207.29	339.425
2210.92	339.76
2214.56	335.102
2218.19	326.307
2221.82	324.851
2225.45	325.588
2229.08	328.423
2232.7	328.342
2236.33	325.67
2239.95	321.188
2243.57	313.615
2247.19	302.035
2250.81	290.836
2254.43	280.616
2258.04	271.676
2261.66	264.537
2265.27	259.346
2268.88	257.116
2272.49	254.794
2276.1	251.835
2279.7	247.733
2283.31	242.88
2286.91	237.706
2290.51	232.602
2294.11	228.077
2297.71	224.745
2301.3	225.999
2304.9	226.578
2308.49	221.301
2312.08	215.047
2315.67	214.492
2319.26	215.452
2322.85	216.391
2326.43	216.925
2330.02	216.47
2333.6	215.215
2337.18	213.482
2340.76	211.292
2344.34	208.654
2347.91	205.789
2351.49	204.133
2355.06	202.032
2358.63	199.2
2362.2	195.944
2365.77	192.579
2369.33	190.564
2372.9	189.468
2376.46	188.714
2380.02	188.505
2383.58	188.723
2387.14	188.773
2390.7	185.574
2394.25	181.898
2397.81	178.269
2401.36	173.708
2404.91	173.085
2408.46	174.494
2412.01	174.247
2415.56	174.048
2419.1	173.921
2422.64	174.296
2426.18	174.069
2429.72	174.06
2433.26	173.552
2436.8	171.934
2440.34	170.351
2443.87	169.685
2447.4	169.357
2450.93	169.965
2454.46	169.237
2457.99	163.137
2461.52	161.259
2465.04	158.924
2468.56	161.072
2472.09	162.238
2475.61	163.08
2479.13	163.129
2482.64	162.893
2486.16	162.867
2489.67	159.9
2493.18	156.98
2496.69	155.381
2500.2	154.333
2503.71	151.629
2507.22	152.387
2510.72	154.599
2514.23	158.612
2517.73	160.944
2521.23	162.504
2524.73	163.623
2528.23	164.167
2531.72	164.208
2535.21	163.81
2538.71	162.394
2542.2	160.14
2545.69	157.713
2549.18	155.33
2552.66	153.112
2556.15	152.974
2559.63	153.894
2563.12	154.916
2566.6	156.106
2570.08	157.585
2573.55	158.519
2577.03	158.037
2580.5	157.034
2583.98	155.503
2587.45	153.247
2590.92	151.166
2594.39	149.485
2597.86	148.592
2601.32	148.655
2604.79	149.699
2608.25	150.88
2611.71	146.107
2615.17	142.314
2618.63	142.884
2622.08	143.895
2625.54	145.484
2628.99	146.697
2632.45	147.783
2635.9	148.083
2639.35	148.154
2642.79	149.829
2646.24	149.396
2649.69	146.745
2653.13	144.723
2656.57	145.557
2660.01	146.864
2663.45	150.139
2666.89	153.359
2670.32	155.815
2673.76	157.468
2677.19	158.638
2680.62	159.564
2684.05	160.335
2687.48	160.966
2690.91	161.443
2694.33	161.533
2697.76	161.75
2701.18	161.92
2704.6	162.562
2708.02	163.876
2711.44	165.749
2714.86	167.69
2718.27	169.96
2721.69	171.238
2725.1	171.992
2728.51	172.349
2731.92	172.395
2735.33	172.462
2738.74	172.593
2742.14	172.862
2745.55	173.493
2748.95	174.391
2752.35	175.584
2755.75	177.069
2759.15	177.928
2762.54	179.801
2765.94	182.259
2769.33	185.407
2772.72	187.803
2776.12	190.001
2779.51	192.311
2782.89	193.35
2786.28	196.228
2789.67	198.851
2793.05	200.041
2796.43	203.181
2799.81	205.587
2803.19	208.42
2806.57	208.481
2809.95	209.485
2813.32	213.606
2816.69	220.62
2820.06	224.693
2823.44	227.536
2826.81	229.957
2830.17	232.636
2833.54	233.979
2836.9	238.301
2840.27	243.423
2843.63	249.779
2846.99	257.325
2850.35	265.49
2853.71	270.766
2857.06	274.273
2860.42	278.448
2863.77	283.641
2867.12	289.328
2870.48	295.449
2873.83	302.429
2877.17	309.537
2880.52	314.853
2883.86	320.663
2887.21	322.384
2890.55	324.634
2893.89	327.361
2897.23	330.499
2900.57	336.781
2903.91	345.368
2907.24	359.068
2910.57	372.754
2913.91	383.053
2917.24	391.198
2920.57	393.634
2923.9	398.657
2927.22	407.143
2930.55	418.296
2933.87	435.669
2937.19	450.451
2940.51	467.118
2943.83	479.029
2947.15	490.09
2950.47	501.47
2953.79	511.827
2957.1	523.334
2960.41	536.425
2963.72	551.683
2967.03	570.023
2970.34	587.206
2973.65	604.318
2976.95	621.862
2980.26	642.313
2983.56	663.338
2986.86	684.46
2990.16	705.718
2993.46	726.827
2996.76	747.793
3000.06	772.099
3003.35	798.336
3006.64	825.816
3009.94	849.131
3013.23	866.95
3016.51	889.029
3019.8	915.557
3023.09	946.85
3026.38	983.704
3029.66	1022.5
3032.94	1054.63
3036.22	1083.58
3039.5	1120.03
3042.78	1158.83
3046.05	1199.48
3049.33	1241.02
3052.6	1282.86
3055.88	1324.55
3059.15	1367.53
3062.42	1411.1
3065.69	1458.83
3068.95	1507.39
3072.22	1558.59
3075.48	1612.21
3078.75	1668.74
3082.01	1730.71
3085.27	1794.26
3088.53	1857.88
3091.79	1923.91
3095.04	1990.73
3098.3	2058
3101.55	2127.01
3104.8	2191.69
3108.05	2260.44
3111.3	2335.69
3114.55	2423.01
3117.8	2516.36
3121.04	2605.7
3124.29	2692.56
3127.53	2779.9
3130.77	2872.59
3134.01	2970.6
3137.25	3075.43
3140.49	3178.71
3143.72	3285.87
3146.96	3396.04
3150.19	3507.43
3153.42	3618.23
3156.65	3724.96
3159.88	3833.89
3163.11	3947.34
3166.34	4064.67
3169.56	4187.82
3172.79	4313.8
3176.01	4416.03
3179.23	4522.8
3182.45	4648.18
3185.67	4781.24
3188.88	4916.77
3192.1	5049.27
3195.31	5179.46
3198.53	5285.64
3201.74	5390.03
3204.95	5496.33
3208.16	5610.23
3211.37	5723.67
3214.57	5842.14
3217.78	5956.99
3220.98	6059.44
3224.18	6141.92
3227.39	6232.51
3230.59	6330.07
3233.78	6416.97
3236.98	6495.01
3240.18	6571.37
3243.37	6642.51
3246.56	6708
3249.76	6780.77
3252.95	6844.26
3256.14	6895.05
3259.32	6942.59
3262.51	6992.04
3265.7	7043.88
3268.88	7101.72
3272.06	7153.44
3275.24	7206.73
3278.42	7265.18
3281.6	7329.14
3284.78	7397.5
3287.96	7461.9
3291.13	7524.1
3294.31	7591.21
3297.48	7669.04
3300.65	7753.95
3303.82	7843.11
3306.99	7930.88
3310.15	8017.77
3313.32	8104.42
3316.48	8184.1
3319.65	8266.77
3322.81	8346.99
3325.97	8437.67
3329.13	8547.23
3332.28	8667.24
3335.44	8778.86
3338.6	8865.16
3341.75	8989.86
3344.9	9125.99
3348.05	9261.25
3351.2	9398.54
3354.35	9534.1
3357.5	9666.56
3360.65	9798.09
3363.79	9930.05
3366.94	10067.6
3370.08	10198.7
3373.22	10330.1
3376.36	10464
3379.5	10601.9
3382.63	10733.2
3385.77	10865.5
3388.9	11004.1
3392.04	11139
3395.17	11287.1
3398.3	11443.8
3401.43	11590.6
3404.56	11802.8
3407.69	11979.1
3410.81	12184.1
3413.94	12690.8
3417.06	13539
3420.18	15673
3423.3	20379
3426.42	26830
3429.54	26675
3432.65	21099
3435.77	16381
3438.88	13928.9
3442	13011.2
3445.11	12588.6
3448.22	12353.7
3451.33	12165.8
3454.43	12062
3457.54	11981.8
3460.65	11929.2
3463.75	11886.8
3466.85	11854.2
3469.95	11832.2
3473.05	11820.6
3476.15	11832.4
3479.25	11863.4
3482.35	11964.3
3485.44	12205.2
3488.54	12442.9
3491.63	12946.7
3494.72	13565
3497.81	14652.8
3500.9	16274.1
3503.99	18219.5
3507.07	20329
3510.16	21118
3513.24	20292
3516.32	17781
3519.41	15390
3522.49	13305
3525.56	11814
3528.64	10629.5
3531.72	9874.37
3534.79	9317.68
3537.87	8889.12
3540.94	8506.72
3544.01	8165.72
3547.08	7843.98
3550.15	7554.53
3553.22	7286.89
3556.28	7051.08
3559.35	6837.98
3562.41	6632.25
3565.47	6435.33
3568.54	6245.48
3571.6	6062.27
3574.65	5885.25
3577.71	5714.79
3580.77	5550.68
3583.82	5393.02
3586.88	5240.93
3589.93	5093.71
3592.98	4950.1
3596.03	4811.47
3599.08	4678.54
3602.13	4550.01
3605.18	4428.49
3608.22	4304.25
3611.27	4186.94
3614.31	4068.66
3617.35	3940.53
3620.39	3802.21
3623.43	3664.62
3626.47	3549.08
3629.5	3437.85
3632.54	3317.98
3635.57	3198.43
3638.61	3074.65
3641.64	2947.92
3644.67	2828.19
3647.7	2701.86
3650.73	2575.16
3653.75	2445.05
3656.78	2316.37
3659.8	2188.4
3662.83	2060.14
3665.85	1930.67
3668.87	1812.16
3671.89	1695.37
3674.91	1593.7
3677.92	1503.25
3680.94	1409.98
3683.96	1315.74
3686.97	1228.62
3689.98	1146.56
3692.99	1068.9
3696	1002.79
3699.01	946.148
3702.02	896.388
3705.02	853.934
3708.03	815.911
3711.03	780.069
3714.03	745.191
3717.04	712.629
3720.04	682.091
3723.04	653.765
3726.03	627.629
3729.03	603.809
3732.03	582.078
3735.02	561.214
3738.01	542.834
3741	527.216
3743.99	508.937
3746.98	492.641
3749.97	480.798
3752.96	471.472
3755.95	467.121
3758.93	458.424
3761.91	448.556
3764.9	437.325
3767.88	428.032
3770.86	422.81
3773.84	417.594
3776.81	412.756
3779.79	407.59
3782.77	401.719
3785.74	396.273
3788.71	390.871
3791.68	385.679
3794.65	380.51
3797.62	375.987
3800.59	370.379
3803.56	364.768
3806.52	360.015
3809.49	357.771
3812.45	358.958
3815.41	361.215
3818.37	362.177
3821.33	361.844
3824.29	361.185
3827.25	360.188
3830.21	356.596
3833.16	356.801
3836.11	354.635
3839.07	352.278
3842.02	349.669
3844.97	346.814
3847.92	345.127
3850.87	343.864
3853.81	341.384
3856.76	338.93
3859.7	334.932
3862.65	330.908
3865.59	328.615
3868.53	328.73
3871.47	331.777
3874.41	334.313
3877.34	335.712
3880.28	332.568
3883.22	331.204
3886.15	332.697
3889.08	332.551
3892.01	333.699
3894.94	337.493
3897.87	339.989
3900.8	342.613
3903.73	348.054
3906.65	347.239
3909.58	344.537
3912.5	340.707
3915.42	338.388
3918.35	337.393
3921.27	336.33
3924.18	333.987
3927.1	331.205
3930.02	333.067
3932.93	336.284
3935.85	342.97
3938.76	341.019
3941.67	337.235
3944.58	334.381
3947.49	332.321
3950.4	331.052
3953.31	330.868
3956.22	334.81
3959.12	335.957
3962.02	334.975
3964.93	331.32
3967.83	329.513
3970.73	327.674
3973.63	329.219
3976.53	330.001
3979.42	331.124
3982.32	332.706
3985.21	335.773
3988.11	333.463
3991	332.094
3993.89	330.338
3996.78	327.669
3999.67	327.329