File: Data/3-Raman/raw/20-H_trl1_FI03.txt
#Acq. time (s)=	15
#Accumulations=	3
#Range (cm-¹)=	100...4000
#Windows=	1
#Auto scanning=	Off
#Autofocus=	Off
#Macrospot=	Off
#AutoExposure=	Off
#Spike filter=	Multiple accum.
#Delay time (s)=	0
#Binning=	1
#Readout mode=	Signal
#DeNoise=	Lite
#ICS correction=	Off
#Dark correction=	Off
#Inst. Process=	Off
#Detector temperature (°C)=	-60.09
#Instrument=	LabRAM HR Evol
#Detector=	SIN-EM FIVIS
#Objective=	x100_VIS
#Grating=	150 (500nm)
#ND Filter=	100%
#Laser=	532nm_Edge
#Hole=	30.0125
#Temperature=	0
#Range=	Visible
#StageXY=	75x50mm Scan+
#StageZ=	Z motor
#X (µm)=	12512.7
#Y (µm)=	6890.5
#Z (µm)=	1909.9
#Full time(s)=	49
#Project=	Buranga
#Sample=	BU18FA20_G
#Site=	G_trl1
#Title=	20-H_trl1_FI03
#Remark=
#Date=	30.07.2019 18:14
#Acquired=	30.07.2019 18:14:46
103.656	2853.83
108.278	2502.16
112.899	2296.43
117.517	2067.97
122.131	1862.8
126.744	1680.24
131.355	1521.97
135.964	1388.68
140.571	1282.77
145.173	1198.95
149.776	1138.18
154.375	1098.49
158.973	1105.87
163.566	1250.37
168.159	1448.06
172.75	1414.74
177.339	1078.97
181.923	845.257
186.507	795.162
191.089	949.446
195.668	1084.48
200.243	1151.86
204.818	943.548
209.391	774.429
213.96	651.37
218.528	572.188
223.094	537.61
227.655	548.198
232.217	601.135
236.776	699.332
241.331	845.547
245.886	1041.23
250.439	1277.44
254.987	1451.94
259.535	1391.31
264.081	962.253
268.622	722.971
273.164	731.519
277.703	992.178
282.238	1594.17
286.773	2267
291.305	2369
295.833	1642.31
300.362	1189.92
304.885	920.72
309.409	764.426
313.93	711.112
318.448	629.867
322.965	739.995
327.477	878.22
331.99	1017.16
336.5	1141.75
341.007	1235.81
345.513	1302.16
350.014	1328.95
354.516	1353.26
359.013	1384.83
363.51	1316.52
368.005	1171.11
372.496	1023.02
376.987	903.88
381.473	818.574
385.96	755.734
390.442	719.871
394.923	709.719
399.401	723.933
403.879	752.081
408.352	688.156
412.825	537.057
417.294	485.003
421.763	529.496
426.227	601.211
430.692	559.119
435.152	487.575
439.612	415.528
444.068	380.207
448.524	376.847
452.976	400.742
457.427	429.361
461.874	452.352
466.32	471.515
470.765	471.142
475.205	468.504
479.646	466.053
484.083	471.177
488.519	518.673
492.951	592.131
497.381	693.326
501.811	762.228
506.237	778.847
510.663	747.421
515.084	664.966
519.504	574.446
523.923	506.419
528.338	455.333
532.753	420.239
537.164	398.095
541.572	386.365
545.981	383.052
550.385	385.398
554.788	391.084
559.19	400.253
563.588	410.219
567.986	419.966
572.38	416.74
576.771	414.648
581.163	419.845
585.551	473.712
589.936	624.048
594.319	876.136
598.702	995.195
603.081	884.357
607.458	659.588
611.835	548.667
616.208	574.2
620.578	601.274
624.949	573.773
629.315	488.376
633.68	437.477
638.042	432.321
642.404	450.419
646.762	469.382
651.118	487.837
655.472	507.215
659.825	531.649
664.175	600.889
668.523	734.496
672.868	867.922
677.213	955.786
681.555	994.331
685.894	972.635
690.231	851.856
694.566	677.676
698.901	508.083
703.232	427.412
707.561	373.604
711.888	340.139
716.212	320.623
720.537	310.598
724.858	309.166
729.176	304.084
733.493	299.668
737.807	297.809
742.119	298.193
746.432	302.505
750.74	309.78
755.046	321.373
759.35	339.576
763.652	362.009
767.952	402.776
772.25	475.962
776.546	619.612
780.842	856.457
785.133	1114.61
789.423	1199.95
793.711	1003.76
797.997	754.793
802.28	562.052
806.562	419.379
810.841	375.241
815.119	350.855
819.394	336.388
823.668	322.881
827.941	309.231
832.211	297.916
836.478	289.424
840.743	283.298
845.006	279.078
849.268	277.249
853.527	276.819
857.784	278.496
862.039	280.3
866.293	281.624
870.544	282.396
874.793	281.869
879.04	280.151
883.285	277.57
887.528	273.409
891.769	269.329
896.008	266.362
900.246	265.274
904.481	270.144
908.714	267.584
912.945	263.59
917.174	262.92
921.401	263.624
925.626	268.024
929.849	277.434
934.068	293.318
938.287	311.12
942.504	330.713
946.72	381.659
950.933	465.797
955.144	561.303
959.353	601.79
963.56	554.423
967.765	481.956
971.968	425.662
976.17	386.421
980.367	360.266
984.564	343.552
988.759	329.868
992.953	320.29
997.144	312.844
1001.33	307.299
1005.52	303.286
1009.71	300.901
1013.89	299.945
1018.07	300.236
1022.25	302.448
1026.43	303.623
1030.6	310.741
1034.78	333.652
1038.94	374.303
1043.11	444.428
1047.28	532.148
1051.45	671.156
1055.61	929.776
1059.77	1230.04
1063.93	1305.41
1068.09	1041.99
1072.25	772.681
1076.4	606.036
1080.55	536.686
1084.7	585.407
1088.85	728.608
1092.99	962.292
1097.14	1149.98
1101.28	1216.24
1105.42	1242.8
1109.56	1255.39
1113.69	1258.92
1117.83	1272.87
1121.96	1277.65
1126.09	1248.08
1130.22	1217.75
1134.35	1201.4
1138.47	1254.52
1142.59	1271.92
1146.71	1117.18
1150.83	891.393
1154.95	790.283
1159.06	782.897
1163.18	887.26
1167.29	924.679
1171.4	905.343
1175.5	837.114
1179.61	727.565
1183.71	621.65
1187.81	507.375
1191.91	413.032
1196.01	381.449
1200.1	366.289
1204.2	354.111
1208.29	347.454
1212.38	340.029
1216.47	351.865
1220.55	377.691
1224.64	437.481
1228.72	500.387
1232.8	546.259
1236.88	540.035
1240.95	523.032
1245.03	535.756
1249.1	555.327
1253.17	560.8
1257.24	577.202
1261.31	594.266
1265.37	583.811
1269.44	480.427
1273.5	629
1277.56	1505
1281.61	2265
1285.67	2243
1289.72	875
1293.77	431.512
1297.83	383.894
1301.87	363.853
1305.92	352.402
1309.96	344.694
1314.01	338.523
1318.05	334.174
1322.09	331.357
1326.12	328.793
1330.16	326.981
1334.19	325.522
1338.22	322.838
1342.25	322.718
1346.28	325.964
1350.3	334.866
1354.33	348.223
1358.35	365.423
1362.37	390.232
1366.39	420.02
1370.4	466.262
1374.42	503.08
1378.43	1197
1382.44	2839
1386.45	3805
1390.46	2493
1394.46	719
1398.46	461
1402.47	552
1406.46	620
1410.46	583
1414.46	386.335
1418.45	340.058
1422.45	309.513
1426.43	287.826
1430.42	272.541
1434.41	262.035
1438.39	253.65
1442.38	245.93
1446.36	239.569
1450.34	232.692
1454.31	226.897
1458.29	221.839
1462.27	217.289
1466.24	215.009
1470.21	213.664
1474.18	212.762
1478.14	212.152
1482.11	212.922
1486.07	213.449
1490.03	212.905
1493.99	212.215
1497.95	212.163
1501.9	212.189
1505.86	211.425
1509.81	211.031
1513.76	209.918
1517.71	209.843
1521.65	209.788
1525.6	209.633
1529.54	209.84
1533.48	208.107
1537.42	206.37
1541.36	204.712
1545.29	204.678
1549.23	206.042
1553.16	210.077
1557.09	214.555
1561.02	217.501
1564.94	216.73
1568.87	216.402
1572.79	216.303
1576.71	216.085
1580.63	215.179
1584.55	213.86
1588.47	212.774
1592.38	215.437
1596.29	219.722
1600.2	224.272
1604.11	227.94
1608.02	231.135
1611.92	233.393
1615.83	234.821
1619.73	235.252
1623.63	235.169
1627.53	235.178
1631.42	235.471
1635.32	236.43
1639.21	237.596
1643.1	240.002
1646.99	241.852
1650.88	242.51
1654.76	240.632
1658.64	237.051
1662.53	232.208
1666.41	227.226
1670.28	222.439
1674.16	218.957
1678.04	217.037
1681.91	215.848
1685.78	214.915
1689.65	213.658
1693.52	211.93
1697.38	211.12
1701.25	210.33
1705.11	209.915
1708.97	208.526
1712.83	206.632
1716.69	204.036
1720.54	200.693
1724.4	198.373
1728.25	196.018
1732.1	194.839
1735.95	195.388
1739.79	196.59
1743.64	198.226
1747.48	200.243
1751.33	202.563
1755.17	203.313
1759	203.369
1762.84	202.499
1766.68	201.313
1770.51	199.94
1774.34	198.534
1778.17	197.153
1782	195.352
1785.82	194.788
1789.65	195.996
1793.47	197.14
1797.29	197.152
1801.11	196.242
1804.93	194.895
1808.74	194.404
1812.56	193.939
1816.37	192.925
1820.18	191.207
1823.99	190.544
1827.79	190.995
1831.6	190.927
1835.4	190.497
1839.2	189.566
1843	187.987
1846.8	188.265
1850.6	190.115
1854.39	193.795
1858.19	196.988
1861.98	201.05
1865.77	203.598
1869.56	203.31
1873.34	202.188
1877.13	200.276
1880.91	198.574
1884.69	196.927
1888.47	195.589
1892.25	194.733
1896.03	194.746
1899.8	195.468
1903.57	195.231
1907.34	195.299
1911.11	195.53
1914.88	195.954
1918.65	196.174
1922.41	195.791
1926.18	194.751
1929.94	193.138
1933.7	191.133
1937.45	188.517
1941.21	186.722
1944.96	186.31
1948.72	187.564
1952.47	190.628
1956.22	192.936
1959.96	193.696
1963.71	193.851
1967.45	193.821
1971.2	193.561
1974.94	191.803
1978.68	191.413
1982.42	192.323
1986.15	192.786
1989.89	194.927
1993.62	197.086
1997.35	199.71
2001.08	202.499
2004.8	204.651
2008.53	204.82
2012.25	203.336
2015.98	201.855
2019.7	198.274
2023.42	196.866
2027.13	197.83
2030.85	199.701
2034.56	202.343
2038.28	204.219
2041.99	205.329
2045.7	205.534
2049.41	204.766
2053.11	204.042
2056.82	202.491
2060.52	201.347
2064.22	201.421
2067.92	201.694
2071.62	199.514
2075.31	197.06
2079.01	195.686
2082.7	194.872
2086.39	194.761
2090.08	195.962
2093.77	197.078
2097.45	197.577
2101.14	197.648
2104.82	197.877
2108.5	198.54
2112.18	202.214
2115.86	202.105
2119.54	201.964
2123.21	201.798
2126.88	201.445
2130.56	200.751
2134.23	199.873
2137.89	199.016
2141.56	198.225
2145.23	197.499
2148.89	196.913
2152.55	196.351
2156.21	196.133
2159.87	196.932
2163.53	198.14
2167.18	198.434
2170.84	200.056
2174.49	202.588
2178.14	205.748
2181.79	209.183
2185.44	213.739
2189.08	217.188
2192.73	218.949
2196.37	219.372
2200.01	219.967
2203.65	217.587
2207.29	218.106
2210.92	212.034
2214.56	207.862
2218.19	212.221
2221.82	214.895
2225.45	216.335
2229.08	216.626
2232.7	216.59
2236.33	214.775
2239.95	211.737
2243.57	207.545
2247.19	203.431
2250.81	199.658
2254.43	197.589
2258.04	195.763
2261.66	194.864
2265.27	194.722
2268.88	195.51
2272.49	197.815
2276.1	199.889
2279.7	201.441
2283.31	202.43
2286.91	202.73
2290.51	202.182
2294.11	200.367
2297.71	197.585
2301.3	195.493
2304.9	190.38
2308.49	186.558
2312.08	194.738
2315.67	216.971
2319.26	256.068
2322.85	473
2326.43	633
2330.02	527
2333.6	282.878
2337.18	232.771
2340.76	206.423
2344.34	195.732
2347.91	191.775
2351.49	187.337
2355.06	189.223
2358.63	189.694
2362.2	192.416
2365.77	194.329
2369.33	194.886
2372.9	194.462
2376.46	193.258
2380.02	191.89
2383.58	190.437
2387.14	190.212
2390.7	191.071
2394.25	192.638
2397.81	194.51
2401.36	196.072
2404.91	196.888
2408.46	196.745
2412.01	195.27
2415.56	193.333
2419.1	191.691
2422.64	189.36
2426.18	186.813
2429.72	184.915
2433.26	184.113
2436.8	186.249
2440.34	186.568
2443.87	186.28
2447.4	185.704
2450.93	185.704
2454.46	186.237
2457.99	186.89
2461.52	187.411
2465.04	187.736
2468.56	188.068
2472.09	188.49
2475.61	189.286
2479.13	188.516
2482.64	187.785
2486.16	187.246
2489.67	186.695
2493.18	185.962
2496.69	185.293
2500.2	183.717
2503.71	181.13
2507.22	178.057
2510.72	177.188
2514.23	178.333
2517.73	181.601
2521.23	183.016
2524.73	184.214
2528.23	183.953
2531.72	183.882
2535.21	183.814
2538.71	183.728
2542.2	183.224
2545.69	183.054
2549.18	183.485
2552.66	184.621
2556.15	186.575
2559.63	187.955
2563.12	188.52
2566.6	187.727
2570.08	186.114
2573.55	183.746
2577.03	181.211
2580.5	178.452
2583.98	175.969
2587.45	174
2590.92	173.098
2594.39	173.481
2597.86	175.572
2601.32	177.394
2604.79	177.654
2608.25	177.939
2611.71	177.847
2615.17	177.715
2618.63	177.328
2622.08	176.589
2625.54	176.941
2628.99	178.724
2632.45	180.047
2635.9	178.836
2639.35	176.832
2642.79	175.91
2646.24	175.2
2649.69	175.003
2653.13	175.372
2656.57	176.433
2660.01	177.959
2663.45	180.393
2666.89	183.685
2670.32	185.726
2673.76	186.772
2677.19	186.682
2680.62	185.842
2684.05	182.109
2687.48	181.749
2690.91	182.366
2694.33	183.453
2697.76	184.597
2701.18	184.947
2704.6	184.999
2708.02	184.842
2711.44	184.77
2714.86	184.726
2718.27	184.551
2721.69	184.715
2725.1	185.034
2728.51	185.517
2731.92	185.981
2735.33	186.394
2738.74	186.753
2742.14	186.784
2745.55	179.901
2748.95	179.542
2752.35	179.342
2755.75	179.855
2759.15	181.58
2762.54	181.723
2765.94	182.436
2769.33	183.06
2772.72	183.085
2776.12	182.705
2779.51	181.452
2782.89	180.092
2786.28	179.545
2789.67	180.253
2793.05	181.927
2796.43	184.982
2799.81	187.968
2803.19	191.102
2806.57	194.379
2809.95	194.708
2813.32	194.234
2816.69	193.639
2820.06	192.874
2823.44	191.825
2826.81	190.348
2830.17	188.716
2833.54	187.411
2836.9	187.231
2840.27	187.831
2843.63	189.069
2846.99	189.946
2850.35	190.818
2853.71	191.764
2857.06	192.662
2860.42	192.796
2863.77	193.24
2867.12	193.709
2870.48	194.258
2873.83	194.897
2877.17	195.628
2880.52	196.478
2883.86	197.302
2887.21	198.353
2890.55	200.011
2893.89	201.201
2897.23	201.28
2900.57	200.712
2903.91	201.446
2907.24	202.604
2910.57	203.966
2913.91	206.037
2917.24	206.497
2920.57	206.764
2923.9	206.404
2927.22	206.122
2930.55	206.992
2933.87	208.123
2937.19	210.879
2940.51	213.355
2943.83	214.897
2947.15	215.962
2950.47	216.221
2953.79	216.015
2957.1	215.273
2960.41	213.821
2963.72	225.549
2967.03	225.947
2970.34	224.525
2973.65	221.614
2976.95	219.512
2980.26	219.047
2983.56	222.364
2986.86	227.523
2990.16	235.206
2993.46	238.536
2996.76	239.74
3000.06	236.024
3003.35	233.578
3006.64	235.225
3009.94	238.506
3013.23	242.553
3016.51	246.73
3019.8	252.047
3023.09	257.013
3026.38	257.688
3029.66	259.505
3032.94	262.586
3036.22	265.778
3039.5	268.335
3042.78	271.854
3046.05	274.377
3049.33	274.275
3052.6	274.802
3055.88	278.515
3059.15	284.912
3062.42	290.615
3065.69	296.046
3068.95	301.603
3072.22	308.515
3075.48	313.587
3078.75	319.024
3082.01	323.94
3085.27	328.427
3088.53	330.97
3091.79	334.389
3095.04	339.359
3098.3	344.167
3101.55	350.112
3104.8	357.446
3108.05	362.814
3111.3	370.622
3114.55	378.415
3117.8	387.605
3121.04	396.527
3124.29	404.687
3127.53	412.602
3130.77	419.871
3134.01	427.575
3137.25	435.714
3140.49	444.344
3143.72	453.19
3146.96	463.639
3150.19	474.786
3153.42	486.001
3156.65	497.379
3159.88	508.265
3163.11	519.13
3166.34	529.74
3169.56	540.152
3172.79	549.151
3176.01	559.533
3179.23	571.505
3182.45	584.198
3185.67	596.159
3188.88	606.131
3192.1	616.678
3195.31	624.21
3198.53	631.446
3201.74	639.073
3204.95	647.315
3208.16	656.266
3211.37	666.23
3214.57	677.979
3217.78	691.227
3220.98	704.517
3224.18	715.639
3227.39	724.578
3230.59	731.729
3233.78	737.221
3236.98	741.731
3240.18	747.68
3243.37	747.956
3246.56	750.813
3249.76	757.735
3252.95	768.381
3256.14	784.617
3259.32	797.804
3262.51	803.905
3265.7	808.87
3268.88	813.134
3272.06	816.379
3275.24	818.689
3278.42	818.367
3281.6	816.512
3284.78	822.948
3287.96	830.385
3291.13	838.925
3294.31	851.2
3297.48	859.642
3300.65	862.231
3303.82	865.222
3306.99	868.98
3310.15	876.018
3313.32	883.141
3316.48	889.809
3319.65	899.289
3322.81	911.354
3325.97	923.498
3329.13	935.403
3332.28	946.557
3335.44	955.429
3338.6	966.605
3341.75	981.173
3344.9	995.74
3348.05	1008.54
3351.2	1021.12
3354.35	1033.21
3357.5	1045.07
3360.65	1056.55
3363.79	1069.22
3366.94	1083.53
3370.08	1106.18
3373.22	1132.68
3376.36	1161.04
3379.5	1180.27
3382.63	1194.03
3385.77	1206.34
3388.9	1217.49
3392.04	1229.83
3395.17	1244.66
3398.3	1258.3
3401.43	1273.34
3404.56	1295.54
3407.69	1330.83
3410.81	1381.61
3413.94	1494.9
3417.06	1748
3420.18	2329
3423.3	3741
3426.42	5306
3429.54	5447
3432.65	3931
3435.77	2471
3438.88	1782.1
3442	1528.39
3445.11	1440.29
3448.22	1382.43
3451.33	1348.11
3454.43	1317.9
3457.54	1307.97
3460.65	1302.26
3463.75	1308.45
3466.85	1317.62
3469.95	1328.77
3473.05	1339.5
3476.15	1357.75
3479.25	1383.28
3482.35	1430.35
3485.44	1484.85
3488.54	1573.38
3491.63	1702.76
3494.72	1932.4
3497.81	2214.56
3500.9	2645.29
3503.99	3254
3507.07	3767
3510.16	4053
3513.24	4022
3516.32	3450.49
3519.41	2778.68
3522.49	2248.49
3525.56	1838.13
3528.64	1608.24
3531.72	1422.6
3534.79	1278.49
3537.87	1174.12
3540.94	1109.48
3544.01	1052.48
3547.08	1002.63
3550.15	964.514
3553.22	927.881
3556.28	890.346
3559.35	856.182
3562.41	829.531
3565.47	806.077
3568.54	786.146
3571.6	769.729
3574.65	753.568
3577.71	736.672
3580.77	722.089
3583.82	708.567
3586.88	689.588
3589.93	670.551
3592.98	651.106
3596.03	638.097
3599.08	627.54
3602.13	617.938
3605.18	608.188
3608.22	599.094
3611.27	587.127
3614.31	571.9
3617.35	558.088
3620.39	545.351
3623.43	532.232
3626.47	518.944
3629.5	504.827
3632.54	492.528
3635.57	482.839
3638.61	473.761
3641.64	464.247
3644.67	453.075
3647.7	442.115
3650.73	432.353
3653.75	422.562
3656.78	406.329
3659.8	395.026
3662.83	385.774
3665.85	375.985
3668.87	368.288
3671.89	360.512
3674.91	349.247
3677.92	336.065
3680.94	323.712
3683.96	311.749
3686.97	300.602
3689.98	291.843
3692.99	285.264
3696	279.291
3699.01	273.769
3702.02	268.603
3705.02	263.996
3708.03	260.317
3711.03	256.333
3714.03	250.403
3717.04	248.578
3720.04	247.41
3723.04	246.923
3726.03	245.274
3729.03	244.101
3732.03	241.158
3735.02	238.978
3738.01	236.727
3741	234.517
3743.99	233.343
3746.98	233.313
3749.97	234.174
3752.96	236.658
3755.95	238.074
3758.93	238.506
3761.91	237.384
3764.9	235.732
3767.88	232.959
3770.86	230.504
3773.84	228.309
3776.81	226.502
3779.79	225.07
3782.77	224.09
3785.74	223.776
3788.71	223.737
3791.68	223.829
3794.65	224.007
3797.62	224.031
3800.59	224.363
3803.56	224.788
3806.52	224.983
3809.49	224.741
3812.45	223.962
3815.41	223.02
3818.37	221.805
3821.33	220.988
3824.29	221.846
3827.25	222.175
3830.21	222.321
3833.16	222.67
3836.11	222.643
3839.07	222.628
3842.02	223.267
3844.97	224.426
3847.92	226.406
3850.87	223.001
3853.81	220.19
3856.76	218.191
3859.7	217
3862.65	217.212
3865.59	215.592
3868.53	215.284
3871.47	215.938
3874.41	216.148
3877.34	216.363
3880.28	216.69
3883.22	216.633
3886.15	216.665
3889.08	216.688
3892.01	216.388
3894.94	216.01
3897.87	215.753
3900.8	215.415
3903.73	215.02
3906.65	215.033
3909.58	214.269
3912.5	213.007
3915.42	213.241
3918.35	213.47
3921.27	215.206
3924.18	218.359
3927.1	220.611
3930.02	221.944
3932.93	222.434
3935.85	221.32
3938.76	218.526
3941.67	216.828
3944.58	216.19
3947.49	216.558
3950.4	217.643
3953.31	219.368
3956.22	221.156
3959.12	222.42
3962.02	221.995
3964.93	221.262
3967.83	220.893
3970.73	220.88
3973.63	219.858
3976.53	217.71
3979.42	216.141
3982.32	214.891
3985.21	211.042
3988.11	209.157
3991	208.792
3993.89	209.306
3996.78	210.656
3999.67	215.263