File: Data/3-Raman/raw/20-H_trl1_FI08.txt
#Acq. time (s)=	15
#Accumulations=	3
#Range (cm-¹)=	100...4000
#Windows=	1
#Auto scanning=	Off
#Autofocus=	Off
#Macrospot=	Off
#AutoExposure=	Off
#Spike filter=	Multiple accum.
#Delay time (s)=	0
#Binning=	1
#Readout mode=	Signal
#DeNoise=	Lite
#ICS correction=	Off
#Dark correction=	Off
#Inst. Process=	Off
#Detector temperature (°C)=	-60.09
#Instrument=	LabRAM HR Evol
#Detector=	SIN-EM FIVIS
#Objective=	x100_VIS
#Grating=	150 (500nm)
#ND Filter=	100%
#Laser=	532nm_Edge
#Hole=	30.0125
#Temperature=	0
#Range=	Visible
#StageXY=	75x50mm Scan+
#StageZ=	Z motor
#X (µm)=	13533.5
#Y (µm)=	4874.4
#Z (µm)=	1880.8
#Full time(s)=	48
#Project=	Buranga
#Sample=	BU18FA20_G
#Site=	G_trl1
#Title=	20-H_trl1_FI08
#Remark=
#Date=	30.07.2019 18:04
#Acquired=	30.07.2019 18:04:20
103.656	908.686
108.278	853.398
112.899	790.479
117.517	716.864
122.131	651.619
126.744	594.643
131.355	546.984
135.964	527.032
140.571	498.497
145.173	475.615
149.776	464.395
154.375	458.598
158.973	512.038
163.566	705
168.159	855
172.75	830.729
177.339	545.606
181.923	414.48
186.507	409.542
191.089	499.172
195.668	664.7
200.243	742.359
204.818	588.163
209.391	467.613
213.96	386.148
218.528	339.868
223.094	330.134
227.655	354.793
232.217	414.659
236.776	510.626
241.331	641.085
245.886	798.593
250.439	997.801
254.987	1165.76
259.535	955.597
264.081	631.188
268.622	487.058
273.164	529.63
277.703	756.822
282.238	1292.07
286.773	1853
291.305	1664.22
295.833	1203.1
300.362	885.36
304.885	672.011
309.409	558.625
313.93	490.602
318.448	482.913
322.965	599.983
327.477	723.393
331.99	838.277
336.5	935.74
341.007	1006.11
345.513	1058.92
350.014	1081.08
354.516	1098.93
359.013	1107.54
363.51	1030.31
368.005	925.887
372.496	822.209
376.987	724.999
381.473	652.88
385.96	601.092
390.442	564.619
394.923	554.063
399.401	579.784
403.879	569.358
408.352	499.23
412.825	417.909
417.294	375.01
421.763	375.864
426.227	396.78
430.692	374.879
435.152	338.105
439.612	313.701
444.068	299.664
448.524	296.826
452.976	302.045
457.427	315.284
461.874	337.107
466.32	360.498
470.765	369.07
475.205	356.196
479.646	353.262
484.083	370.327
488.519	407.103
492.951	465.108
497.381	543.895
501.811	612.746
506.237	627.201
510.663	572.273
515.084	501.378
519.504	440.218
523.923	392.729
528.338	356.97
532.753	333.358
537.164	319.146
541.572	312.744
545.981	312.874
550.385	314.543
554.788	318.561
559.19	323.525
563.588	330.334
567.986	337.199
572.38	343.587
576.771	342.817
581.163	345.812
585.551	362.111
589.936	471.786
594.319	715.82
598.702	713.51
603.081	629.619
607.458	553.856
611.835	491.706
616.208	450.555
620.578	416.05
624.949	388.074
629.315	366.825
633.68	349.153
638.042	345.995
642.404	362.93
646.762	380.641
651.118	397.541
655.472	415.745
659.825	440.158
664.175	504.253
668.523	598.313
672.868	700.505
677.213	779.53
681.555	792.148
685.894	786.381
690.231	667.552
694.566	548.512
698.901	435.289
703.232	370.605
707.561	325.841
711.888	297.484
716.212	284.344
720.537	279.685
724.858	278.842
729.176	279.885
733.493	279.983
737.807	281.805
742.119	284.866
746.432	290.982
750.74	294.799
755.046	303.505
759.35	317.25
763.652	340.667
767.952	386.185
772.25	461.106
776.546	601.427
780.842	788.64
785.133	993.375
789.423	999.305
793.711	831.764
797.997	596.549
802.28	457.227
806.562	383.401
810.841	340.911
815.119	322.599
819.394	310.545
823.668	300.255
827.941	291.923
832.211	285.963
836.478	281.789
840.743	279.887
845.006	279.304
849.268	277.908
853.527	276.354
857.784	275.125
862.039	273.994
866.293	273.782
870.544	275.045
874.793	277.969
879.04	266.19
883.285	261.955
887.528	260.87
891.769	262.781
896.008	266.568
900.246	270.421
904.481	274.367
908.714	277.723
912.945	278.66
917.174	279.073
921.401	279.323
925.626	281.034
929.849	285.577
934.068	297.02
938.287	313.128
942.504	334.921
946.72	381.956
950.933	434.517
955.144	491.332
959.353	513.909
963.56	480.349
967.765	428.964
971.968	381.63
976.17	363.525
980.367	348.314
984.564	337.231
988.759	329.082
992.953	323.663
997.144	321.513
1001.33	315.171
1005.52	309.609
1009.71	305.519
1013.89	303.415
1018.07	304.987
1022.25	309.078
1026.43	318.689
1030.6	329.682
1034.78	344.7
1038.94	360.655
1043.11	393.096
1047.28	469.801
1051.45	591.277
1055.61	805.483
1059.77	1028.1
1063.93	1077.09
1068.09	871.491
1072.25	679.432
1076.4	545.63
1080.55	495.296
1084.7	512.321
1088.85	582.371
1092.99	800.986
1097.14	897.348
1101.28	931.523
1105.42	955.529
1109.56	978.231
1113.69	996.661
1117.83	1012.78
1121.96	1026.26
1126.09	1029.72
1130.22	1029.84
1134.35	1029.28
1138.47	1040.69
1142.59	1049.1
1146.71	946.56
1150.83	791.981
1154.95	677.962
1159.06	698.951
1163.18	794.025
1167.29	795.792
1171.4	748.844
1175.5	687.047
1179.61	611.327
1183.71	524.614
1187.81	431.67
1191.91	384.65
1196.01	364.062
1200.1	354.284
1204.2	352.376
1208.29	352.511
1212.38	355.517
1216.47	362.46
1220.55	379.567
1224.64	412.384
1228.72	445.795
1232.8	467.874
1236.88	476.945
1240.95	480.284
1245.03	479.208
1249.1	473.153
1253.17	461.525
1257.24	443.914
1261.31	431.246
1265.37	403.023
1269.44	359.641
1273.5	379.133
1277.56	589.705
1281.61	855.993
1285.67	1003
1289.72	513
1293.77	338.031
1297.83	328.279
1301.87	323.353
1305.92	318.805
1309.96	314.682
1314.01	310.435
1318.05	307.793
1322.09	306.518
1326.12	305.703
1330.16	303.461
1334.19	302.303
1338.22	302.568
1342.25	303.543
1346.28	305.244
1350.3	308.014
1354.33	311.837
1358.35	316.666
1362.37	332.903
1366.39	339.15
1370.4	343.027
1374.42	356.317
1378.43	476.153
1382.44	941
1386.45	1365
1390.46	1131
1394.46	422.856
1398.46	363.061
1402.47	368.643
1406.46	372.334
1410.46	354.3
1414.46	334.637
1418.45	318.728
1422.45	305.726
1426.43	295.998
1430.42	289.106
1434.41	284.725
1438.39	283.008
1442.38	282.272
1446.36	281.33
1450.34	279.616
1454.31	276.764
1458.29	273.686
1462.27	272.198
1466.24	270.413
1470.21	267.893
1474.18	265.595
1478.14	267.221
1482.11	268.39
1486.07	269.196
1490.03	269.822
1493.99	270.27
1497.95	270.701
1501.9	271.301
1505.86	271.846
1509.81	272.22
1513.76	272.367
1517.71	271.99
1521.65	271.801
1525.6	271.692
1529.54	271.624
1533.48	271.596
1537.42	272.25
1541.36	272.789
1545.29	273.257
1549.23	273.335
1553.16	273.19
1557.09	271.75
1561.02	270.39
1564.94	270.044
1568.87	271.088
1572.79	272.802
1576.71	273.564
1580.63	274.312
1584.55	275.075
1588.47	275.597
1592.38	276.387
1596.29	276.759
1600.2	277.84
1604.11	278.061
1608.02	279.175
1611.92	278.356
1615.83	276.839
1619.73	276.015
1623.63	277.623
1627.53	278.857
1631.42	277.439
1635.32	276.915
1639.21	278.226
1643.1	279.324
1646.99	280.048
1650.88	280.269
1654.76	280.152
1658.64	280.036
1662.53	279.587
1666.41	278.385
1670.28	275.8
1674.16	273.308
1678.04	270.926
1681.91	269.98
1685.78	268.729
1689.65	268.251
1693.52	266.808
1697.38	270.384
1701.25	276.983
1705.11	277.589
1708.97	276.72
1712.83	275.732
1716.69	273.167
1720.54	270.548
1724.4	267.634
1728.25	265.608
1732.1	264.026
1735.95	263.053
1739.79	264.339
1743.64	268.688
1747.48	273.689
1751.33	277.644
1755.17	280.428
1759	282.605
1762.84	282.152
1766.68	280.748
1770.51	277.714
1774.34	274.468
1778.17	270.775
1782	269.299
1785.82	268.597
1789.65	269.477
1793.47	271.342
1797.29	274.179
1801.11	276.332
1804.93	277.76
1808.74	276.503
1812.56	274.364
1816.37	271.271
1820.18	268.016
1823.99	266.317
1827.79	268.818
1831.6	271.136
1835.4	272.924
1839.2	274.103
1843	274.723
1846.8	276.379
1850.6	276.462
1854.39	275.504
1858.19	275.538
1861.98	276.614
1865.77	277.562
1869.56	278.113
1873.34	278.27
1877.13	278.17
1880.91	271.716
1884.69	277.049
1888.47	275.841
1892.25	273.694
1896.03	271.218
1899.8	272.233
1903.57	273.85
1907.34	275.124
1911.11	276.123
1914.88	276.913
1918.65	277.911
1922.41	278.762
1926.18	278.827
1929.94	276.586
1933.7	274.279
1937.45	272.487
1941.21	274.737
1944.96	272.371
1948.72	269.257
1952.47	267.41
1956.22	267.449
1959.96	268.057
1963.71	269.277
1967.45	270.231
1971.2	271.05
1974.94	271.58
1978.68	272.166
1982.42	272.185
1986.15	272.041
1989.89	271.719
1993.62	271.201
1997.35	270.592
2001.08	269.912
2004.8	269.528
2008.53	269.769
2012.25	270.142
2015.98	270.733
2019.7	271.359
2023.42	271.95
2027.13	272.688
2030.85	273.161
2034.56	273.489
2038.28	273.691
2041.99	273.768
2045.7	273.989
2049.41	274.561
2053.11	275.896
2056.82	277.187
2060.52	278.556
2064.22	279.338
2067.92	278.862
2071.62	277.257
2075.31	274.65
2079.01	274.111
2082.7	276.798
2086.39	279.904
2090.08	282.72
2093.77	282.536
2097.45	280.421
2101.14	276.516
2104.82	272.545
2108.5	269.784
2112.18	267.061
2115.86	266.809
2119.54	267.441
2123.21	268.583
2126.88	270.112
2130.56	271.454
2134.23	271.672
2137.89	272.134
2141.56	272.714
2145.23	273.245
2148.89	274.026
2152.55	275.328
2156.21	277.231
2159.87	279.678
2163.53	282.092
2167.18	283.735
2170.84	283.746
2174.49	283.597
2178.14	283.712
2181.79	284.659
2185.44	287.235
2189.08	291.149
2192.73	294.449
2196.37	296.059
2200.01	295.526
2203.65	294.465
2207.29	290.739
2210.92	285.956
2214.56	281.199
2218.19	278.152
2221.82	277.428
2225.45	278.775
2229.08	280.869
2232.7	283.681
2236.33	284.741
2239.95	283.443
2243.57	280.203
2247.19	276.465
2250.81	271.312
2254.43	271.393
2258.04	280.035
2261.66	281.699
2265.27	281.935
2268.88	280.137
2272.49	277.199
2276.1	275.633
2279.7	273.888
2283.31	272.598
2286.91	272.029
2290.51	271.214
2294.11	270.877
2297.71	270.376
2301.3	270.692
2304.9	271.189
2308.49	270.292
2312.08	268.81
2315.67	273.007
2319.26	295.25
2322.85	354.577
2326.43	407.657
2330.02	384.233
2333.6	326.654
2337.18	296.532
2340.76	283.948
2344.34	276.675
2347.91	273.043
2351.49	270.802
2355.06	271.02
2358.63	271.921
2362.2	272.455
2365.77	271.073
2369.33	269.548
2372.9	269.908
2376.46	271.442
2380.02	273.783
2383.58	277.067
2387.14	280.624
2390.7	283.039
2394.25	284.036
2397.81	282.859
2401.36	279.258
2404.91	276.228
2408.46	273.837
2412.01	272.122
2415.56	270.845
2419.1	270.608
2422.64	271.255
2426.18	272.403
2429.72	273.13
2433.26	272.543
2436.8	271.805
2440.34	271.81
2443.87	271.888
2447.4	271.863
2450.93	271.571
2454.46	270.633
2457.99	269.233
2461.52	267.547
2465.04	265.5
2468.56	263.574
2472.09	261.84
2475.61	261.291
2479.13	268.624
2482.64	275.37
2486.16	271.379
2489.67	268.967
2493.18	266.783
2496.69	265.872
2500.2	265.193
2503.71	267.108
2507.22	270.801
2510.72	274.016
2514.23	275.97
2517.73	274.679
2521.23	272.851
2524.73	272.822
2528.23	273.358
2531.72	273.815
2535.21	274.634
2538.71	274.153
2542.2	273.584
2545.69	272.213
2549.18	270.13
2552.66	269.491
2556.15	268.79
2559.63	268.372
2563.12	267.883
2566.6	267.191
2570.08	266.384
2573.55	265.558
2577.03	264.698
2580.5	264.166
2583.98	264.483
2587.45	265.485
2590.92	266.263
2594.39	266.443
2597.86	265.942
2601.32	265.28
2604.79	264.442
2608.25	263.489
2611.71	262.775
2615.17	262.599
2618.63	262.6
2622.08	262.403
2625.54	261.759
2628.99	258.433
2632.45	256.948
2635.9	256.84
2639.35	256.905
2642.79	256.863
2646.24	256.865
2649.69	257.287
2653.13	257.646
2656.57	258.371
2660.01	259.307
2663.45	260.762
2666.89	263.018
2670.32	265.296
2673.76	273.412
2677.19	275.428
2680.62	273.036
2684.05	268.984
2687.48	262.102
2690.91	255.386
2694.33	253.86
2697.76	257.334
2701.18	264.753
2704.6	270.97
2708.02	267.51
2711.44	264.644
2714.86	262.899
2718.27	263.545
2721.69	268.721
2725.1	274.73
2728.51	266.079
2731.92	263.422
2735.33	262.284
2738.74	262.492
2742.14	262.505
2745.55	263.7
2748.95	265.132
2752.35	266.549
2755.75	267.515
2759.15	267.855
2762.54	266.771
2765.94	264.848
2769.33	263.165
2772.72	261.569
2776.12	260.203
2779.51	258.92
2782.89	258.287
2786.28	257.891
2789.67	257.718
2793.05	258.174
2796.43	258.893
2799.81	259.547
2803.19	260.885
2806.57	262.22
2809.95	263.809
2813.32	263.955
2816.69	263.959
2820.06	263.643
2823.44	263.022
2826.81	262.617
2830.17	261.975
2833.54	262.796
2836.9	264.086
2840.27	264.348
2843.63	264.68
2846.99	264.955
2850.35	265.362
2853.71	265.94
2857.06	266.51
2860.42	267.09
2863.77	267.227
2867.12	266.854
2870.48	266.548
2873.83	265.427
2877.17	264.431
2880.52	263.119
2883.86	261.318
2887.21	260.31
2890.55	259.743
2893.89	260.691
2897.23	262.484
2900.57	263.134
2903.91	262.012
2907.24	260.734
2910.57	259.538
2913.91	258.688
2917.24	258.383
2920.57	258.709
2923.9	259.142
2927.22	261.14
2930.55	264.179
2933.87	266.739
2937.19	267.454
2940.51	265.22
2943.83	262.57
2947.15	260.31
2950.47	261.17
2953.79	264.228
2957.1	266.876
2960.41	266.344
2963.72	263.527
2967.03	258.896
2970.34	255.138
2973.65	256.759
2976.95	259.181
2980.26	261.848
2983.56	264.678
2986.86	267.431
2990.16	269.733
2993.46	270.418
2996.76	269.763
3000.06	267.256
3003.35	264.357
3006.64	261.511
3009.94	259.576
3013.23	258.64
3016.51	258.131
3019.8	258.894
3023.09	259.927
3026.38	261.122
3029.66	262.251
3032.94	262.595
3036.22	263.383
3039.5	264.307
3042.78	265.931
3046.05	267.929
3049.33	267.852
3052.6	265.76
3055.88	261.325
3059.15	253.708
3062.42	267.448
3065.69	273.465
3068.95	272.688
3072.22	270.451
3075.48	267.788
3078.75	265.926
3082.01	265.245
3085.27	265.24
3088.53	265.772
3091.79	267.534
3095.04	268.834
3098.3	268.606
3101.55	269.1
3104.8	270.437
3108.05	272.529
3111.3	272.928
3114.55	273.377
3117.8	273.919
3121.04	274.245
3124.29	274.383
3127.53	274.465
3130.77	275.172
3134.01	276.791
3137.25	278.191
3140.49	281.693
3143.72	284.23
3146.96	286.429
3150.19	287.714
3153.42	287.181
3156.65	284.697
3159.88	284.027
3163.11	287.01
3166.34	290.187
3169.56	292.532
3172.79	294.112
3176.01	294.196
3179.23	294.435
3182.45	294.424
3185.67	295.284
3188.88	292.805
3192.1	294.737
3195.31	298.179
3198.53	300.183
3201.74	299.986
3204.95	300.237
3208.16	301.043
3211.37	301.172
3214.57	300.886
3217.78	306.273
3220.98	313.187
3224.18	315.184
3227.39	315.73
3230.59	314.974
3233.78	313.476
3236.98	314.516
3240.18	316.271
3243.37	318.833
3246.56	322.032
3249.76	324.31
3252.95	323.668
3256.14	322.495
3259.32	321.22
3262.51	319.947
3265.7	318.864
3268.88	317.931
3272.06	318.003
3275.24	318.086
3278.42	318.339
3281.6	317.75
3284.78	318.203
3287.96	321.169
3291.13	324.153
3294.31	328.033
3297.48	330.901
3300.65	331.289
3303.82	331.099
3306.99	329.929
3310.15	330.98
3313.32	333.966
3316.48	338.321
3319.65	341.68
3322.81	344.328
3325.97	346.41
3329.13	348.154
3332.28	348.63
3335.44	349.45
3338.6	346.541
3341.75	348.189
3344.9	353.419
3348.05	356.14
3351.2	361.729
3354.35	366.717
3357.5	370.634
3360.65	373.34
3363.79	374.345
3366.94	374.899
3370.08	376.657
3373.22	380.294
3376.36	384.844
3379.5	389.514
3382.63	395.186
3385.77	401.679
3388.9	410.141
3392.04	419.84
3395.17	431.266
3398.3	446.542
3401.43	455.267
3404.56	473.141
3407.69	499.539
3410.81	516.396
3413.94	609.613
3417.06	787
3420.18	1219
3423.3	2329
3426.42	3619
3429.54	3749
3432.65	2563
3435.77	1410
3438.88	839
3442	631.268
3445.11	559.704
3448.22	510.744
3451.33	484.76
3454.43	471.453
3457.54	464.66
3460.65	464.516
3463.75	466.493
3466.85	474.847
3469.95	484.856
3473.05	502.591
3476.15	526.547
3479.25	564.982
3482.35	611.447
3485.44	688.379
3488.54	757.32
3491.63	890.755
3494.72	1097.33
3497.81	1359.25
3500.9	1730.57
3503.99	2235
3507.07	2674
3510.16	2971
3513.24	2840
3516.32	2365
3519.41	1799.4
3522.49	1363
3525.56	1088.6
3528.64	859.744
3531.72	732.924
3534.79	660.912
3537.87	611.001
3540.94	567.197
3544.01	528.617
3547.08	494.699
3550.15	465.769
3553.22	441.077
3556.28	421.429
3559.35	406.939
3562.41	396.607
3565.47	388.685
3568.54	371.323
3571.6	363.774
3574.65	360.606
3577.71	356.948
3580.77	353.514
3583.82	349.872
3586.88	345.848
3589.93	340.494
3592.98	337.728
3596.03	337.234
3599.08	337.129
3602.13	336.587
3605.18	340.405
3608.22	338.998
3611.27	335.334
3614.31	329.889
3617.35	322.564
3620.39	313.73
3623.43	307.347
3626.47	305.694
3629.5	304.409
3632.54	303.592
3635.57	303.519
3638.61	301.803
3641.64	298.669
3644.67	296.646
3647.7	295.537
3650.73	294.033
3653.75	292.682
3656.78	286.994
3659.8	288.567
3662.83	291.589
3665.85	293.655
3668.87	292.659
3671.89	291.632
3674.91	290.202
3677.92	288.686
3680.94	286.903
3683.96	285.004
3686.97	283.792
3689.98	280.508
3692.99	276.945
3696	274.121
3699.01	271.387
3702.02	270.045
3705.02	268.46
3708.03	266.754
3711.03	265.697
3714.03	263.695
3717.04	262.656
3720.04	261.419
3723.04	261.189
3726.03	261.316
3729.03	261.495
3732.03	261.537
3735.02	261.91
3738.01	262.205
3741	262.309
3743.99	263.514
3746.98	263.527
3749.97	263.473
3752.96	263.589
3755.95	263.973
3758.93	264.147
3761.91	264.769
3764.9	265.627
3767.88	266.364
3770.86	266.687
3773.84	266.25
3776.81	264.655
3779.79	262.586
3782.77	260.305
3785.74	259.547
3788.71	259.512
3791.68	260.715
3794.65	261.047
3797.62	261.23
3800.59	264.201
3803.56	269.099
3806.52	272.002
3809.49	267.432
3812.45	264.23
3815.41	259.936
3818.37	259.583
3821.33	259.547
3824.29	259.929
3827.25	260.485
3830.21	260.815
3833.16	261.141
3836.11	261.285
3839.07	260.263
3842.02	259.262
3844.97	257.974
3847.92	256.946
3850.87	257.39
3853.81	260.074
3856.76	262.818
3859.7	264.244
3862.65	264.71
3865.59	263.607
3868.53	259.679
3871.47	254.346
3874.41	255.472
3877.34	253.995
3880.28	260.708
3883.22	267.131
3886.15	268.042
3889.08	244.602
3892.01	253.115
3894.94	257.31
3897.87	260.87
3900.8	272.56
3903.73	273.026
3906.65	271.121
3909.58	266.637
3912.5	261.819
3915.42	258.798
3918.35	255.461
3921.27	252.586
3924.18	252.634
3927.1	254.287
3930.02	253.804
3932.93	263.234
3935.85	265.681
3938.76	265.941
3941.67	263.708
3944.58	262.7
3947.49	260.641
3950.4	256.773
3953.31	255.233
3956.22	254.482
3959.12	254.879
3962.02	260.342
3964.93	262.117
3967.83	262.391
3970.73	261.758
3973.63	261.779
3976.53	261.749
3979.42	261.262
3982.32	260.358
3985.21	258.988
3988.11	257.295
3991	255.137
3993.89	252.364
3996.78	248.979
3999.67	253.149