File: Data/3-Raman/raw/22-A_qtz3a_FI01.txt
#Acq. time (s)=	15
#Accumulations=	3
#Range (cm-¹)=	50...5000
#Windows=	1
#Auto scanning=	Off
#Autofocus=	Off
#Macrospot=	Off
#AutoExposure=	Off
#Spike filter=	Multiple accum.
#Delay time (s)=	0
#Binning=	1
#Readout mode=	Signal
#DeNoise=	Lite
#ICS correction=	Off
#Dark correction=	Off
#Inst. Process=	Off
#Detector temperature (°C)=	-60.09
#Instrument=	LabRAM HR Evol
#Detector=	SIN-EM FIVIS
#Objective=	x100_VIS
#Grating=	150 (500nm)
#ND Filter=	100%
#Laser=	532nm_Edge
#Hole=	30.0125
#Temperature=	0
#Range=	Visible
#StageXY=	75x50mm Scan+
#StageZ=	Z motor
#X (µm)=	14358.7
#Y (µm)=	1717.3
#Z (µm)=	-360.1
#Full time(s)=	47
#Project=	Buranga
#Sample=	BU18FA22_A
#Site=	A_Qtz3
#Title=	22-A_qtz3a_FI01
#Remark=
#Date=	09.07.2019 18:28
#Acquired=	09.07.2019 18:28:27
52.2859	22394
56.9342	17322
61.5802	13343
66.2217	10356
70.8631	8028
75.5021	6434.71
80.1389	5146.54
84.7734	4150.9
89.4056	3571
94.0333	3182
98.6609	3123
103.286	4419
107.909	9061
112.53	11338
117.146	7362
121.762	3567
126.376	2387.93
130.988	2006.52
135.595	1748.43
140.202	1517.72
144.807	1440.99
149.41	1523.34
154.008	1624.09
158.606	1854.08
163.201	2275.28
167.795	2848.83
172.384	3981.26
176.973	5534.76
181.559	7648.81
186.142	9380
190.724	9690
195.304	8629.39
199.881	6601.41
204.454	4818.69
209.028	3485.34
213.598	2589.73
218.165	2024.38
222.731	1625.3
227.295	1381.17
231.855	1222.91
236.415	1172.36
240.972	1228.89
245.525	1655
250.078	1567
254.629	1041.09
259.175	634.451
263.722	498.119
268.264	441.664
272.805	397.001
277.345	363.856
281.88	338.974
286.415	319.781
290.948	306.373
295.477	297.99
300.005	295.795
304.529	298.499
309.053	304.594
313.575	308.812
318.093	330.663
322.61	353.924
327.123	414.365
331.636	714
336.145	1792
340.653	2006
345.157	1017
349.662	496.783
354.164	373.955
358.661	341.991
363.159	364.296
367.652	421
372.145	672.2
376.634	1409
381.123	1668.79
385.608	1337.74
390.092	825
394.572	531
399.052	441.143
403.528	433.662
408.004	468.927
412.475	539.285
416.947	648.543
421.414	862.043
425.881	1235.68
430.343	2004
434.806	3709
439.264	8257
443.723	20097
448.177	31687
452.629	26674
457.081	14176
461.528	6741
465.976	3942
470.419	2709
474.862	2009.69
479.301	1673.05
483.738	1466.5
488.175	1311.25
492.607	1174.53
497.04	1042.56
501.468	918.872
505.894	808.492
510.32	727.746
514.742	673.937
519.164	631.678
523.581	592.155
527.997	555.822
532.412	520.928
536.823	486.696
541.232	457.636
545.641	432.773
550.046	412.195
554.449	395.131
558.851	380.844
563.25	372.802
567.646	372.124
572.042	382.159
576.434	378.74
580.824	371.994
585.214	364.339
589.599	355.875
593.983	348.17
598.367	340.715
602.746	334.654
607.123	329.464
611.498	324.964
615.873	320.658
620.244	317.15
624.613	313.668
628.98	308.799
633.346	301.063
637.709	292.491
642.069	286.623
646.428	285.974
650.786	290.066
655.14	295.047
659.492	306.629
663.842	326.674
668.192	375.775
672.538	462.362
676.882	729.038
681.223	855.943
685.563	720.579
689.902	488.498
694.238	361.976
698.571	340.23
702.902	317.175
707.231	309.429
711.559	304.718
715.886	301.968
720.209	298.59
724.529	294.558
728.848	289.785
733.165	286.032
737.48	283.009
741.792	281.448
746.105	283.331
750.413	288.795
754.72	299.719
759.024	317.153
763.327	337.251
767.627	368.219
771.925	424.325
776.221	569.214
780.518	699
784.81	817.343
789.1	905.836
793.388	865.643
797.674	657.371
801.958	479.151
806.24	406.849
810.52	375.158
814.797	351.616
819.073	356.262
823.347	352.499
827.619	348.909
831.888	341.591
836.156	335.478
840.422	328.823
844.685	322.625
848.947	317.35
853.206	312.665
857.464	312.775
861.719	314.644
865.973	317.59
870.224	328.649
874.474	339.292
878.721	342.724
882.967	336.215
887.21	330.14
891.452	325.51
895.691	328.449
899.929	340.852
904.164	346.496
908.397	340.881
912.629	329.343
916.858	312.015
921.086	296.641
925.311	288.509
929.534	283.087
933.756	281.054
937.975	282.28
942.191	284.326
946.406	282.882
950.619	272.024
954.831	260.957
959.04	250.877
963.248	248.018
967.453	246.442
971.657	245.514
975.858	245.433
980.056	244.16
984.253	242.716
988.449	240.185
992.643	237.285
996.834	234.789
1001.02	233.578
1005.21	233.503
1009.4	233.692
1013.58	235.179
1017.76	241.594
1021.94	252.354
1026.12	257.457
1030.29	250.205
1034.47	266.216
1038.64	301.766
1042.81	355.903
1046.98	427.685
1051.14	474.029
1055.3	504.424
1059.47	515.193
1063.63	514.851
1067.78	505.759
1071.94	452.074
1076.09	357.689
1080.25	302.013
1084.4	269.266
1088.54	264.552
1092.69	266.378
1096.83	262.4
1100.98	261.347
1105.12	260.476
1109.26	262.589
1113.39	262.651
1117.53	265.256
1121.66	287.152
1125.79	318.233
1129.92	380.245
1134.04	451.186
1138.17	698
1142.29	1108
1146.41	1451
1150.53	1268
1154.65	785
1158.76	491.607
1162.88	372.41
1166.99	311.634
1171.1	287.714
1175.2	279.034
1179.31	274.204
1183.41	272.087
1187.51	272.474
1191.61	276.463
1195.71	285.884
1199.81	299.149
1203.9	315.698
1207.99	343.846
1212.08	375.04
1216.17	403.446
1220.26	409.78
1224.34	389.101
1228.42	377.499
1232.5	374.393
1236.58	378.998
1240.66	400.582
1244.73	437.029
1248.81	578.219
1252.88	683
1256.95	546
1261.02	489
1265.08	811
1269.14	2278
1273.2	3539
1277.27	1640
1281.32	563.643
1285.38	438.966
1289.43	403.254
1293.48	381.055
1297.53	365.492
1301.58	354.01
1305.63	348.192
1309.67	345.02
1313.72	343.345
1317.76	343.345
1321.8	343.416
1325.83	346.355
1329.87	347.205
1333.9	350.005
1337.93	356.099
1341.96	363.185
1345.99	375.149
1350.02	400.46
1354.04	442.989
1358.06	512.112
1362.08	489
1366.1	629.253
1370.12	1730
1374.13	4493
1378.14	4762
1382.16	1306
1386.16	553
1390.17	544
1394.18	690
1398.18	827
1402.18	524.647
1406.18	416.356
1410.18	377.473
1414.18	347.832
1418.17	324.409
1422.16	305.732
1426.15	291.478
1430.14	281.271
1434.13	273.996
1438.11	268.763
1442.1	259.063
1446.08	251.981
1450.06	248.232
1454.04	245.493
1458.01	243.812
1461.98	242.428
1465.96	241.616
1469.93	240.76
1473.9	239.924
1477.86	239.281
1481.83	237.86
1485.79	236.609
1489.75	235.22
1493.71	236.236
1497.67	237.664
1501.62	238.895
1505.58	240.038
1509.53	240.796
1513.48	241.643
1517.43	242.219
1521.38	242.326
1525.32	239.011
1529.26	237.015
1533.2	237.198
1537.14	238.337
1541.08	239.656
1545.02	241.181
1548.95	242.432
1552.88	245.52
1556.81	246.723
1560.74	246.95
1564.67	248.198
1568.6	249.958
1572.52	252.013
1576.44	254.445
1580.36	256.723
1584.28	259.324
1588.19	261.928
1592.11	264.188
1596.02	266.211
1599.93	267.555
1603.84	268.059
1607.75	267.816
1611.65	266.759
1615.56	264.87
1619.46	262.349
1623.36	259.235
1627.25	256.065
1631.15	253.343
1635.05	251.195
1638.94	249.468
1642.83	243.984
1646.72	244.187
1650.61	244.519
1654.49	245.129
1658.38	245.625
1662.26	244.521
1666.14	242.351
1670.02	234.397
1673.89	233.768
1677.77	233.637
1681.64	232.975
1685.51	231.825
1689.38	230.322
1693.25	228.583
1697.12	226.456
1700.98	227.754
1704.85	227.358
1708.71	225.675
1712.57	222.253
1716.42	221.903
1720.28	222.076
1724.13	222.371
1727.99	222.659
1731.84	222.816
1735.69	223.006
1739.53	222.642
1743.38	222.461
1747.22	221.705
1751.06	219.633
1754.9	218.23
1758.74	216.825
1762.58	217.354
1766.41	216.743
1770.25	218.232
1774.08	220.522
1777.91	222.456
1781.73	224.403
1785.56	225.962
1789.39	227.136
1793.21	226.12
1797.03	224.234
1800.85	221.632
1804.67	217.633
1808.48	214.368
1812.3	211.684
1816.11	210.145
1819.92	211.532
1823.73	214.032
1827.54	214.894
1831.34	214.523
1835.14	214.405
1838.95	215.178
1842.75	216.246
1846.55	220.442
1850.34	220.85
1854.14	220.652
1857.93	220.124
1861.72	219.855
1865.51	219.457
1869.3	219.033
1873.09	218.811
1876.87	218.323
1880.66	217.897
1884.44	217.254
1888.22	217.265
1892	217.6
1895.77	217.512
1899.55	217.626
1903.32	216.108
1907.09	214.852
1910.86	214.457
1914.63	214.525
1918.4	214.613
1922.16	215.293
1925.92	215.488
1929.68	215.582
1933.44	215.435
1937.2	214.923
1940.96	214.065
1944.71	206.445
1948.46	209.338
1952.22	212.789
1955.97	215.706
1959.71	216.52
1963.46	215.067
1967.2	214.982
1970.95	215.962
1974.69	216.96
1978.43	218.038
1982.17	218.979
1985.9	219.545
1989.64	219.344
1993.37	205.813
1997.1	221.158
2000.83	220.251
2004.56	219.017
2008.28	217.194
2012.01	216.417
2015.73	214.043
2019.45	213.617
2023.17	214.4
2026.89	215.237
2030.6	216.049
2034.32	216.565
2038.03	216.724
2041.74	216.534
2045.45	215.885
2049.16	214.697
2052.87	212.955
2056.57	210.731
2060.27	208.85
2063.98	208.394
2067.67	209.207
2071.37	209.444
2075.07	209.814
2078.76	209.914
2082.46	208.554
2086.15	208.637
2089.84	211.027
2093.53	214.301
2097.21	218.361
2100.9	223.92
2104.58	227.409
2108.26	228.137
2111.94	227.329
2115.62	225.468
2119.3	222.743
2122.97	221.869
2126.64	220.871
2130.32	220.603
2133.99	220.181
2137.66	219.871
2141.32	221.114
2144.99	217.868
2148.65	215.599
2152.31	214.472
2155.97	216.737
2159.63	218.549
2163.29	220.492
2166.94	222.602
2170.6	222.88
2174.25	213.874
2177.9	211.584
2181.55	210.898
2185.2	212.649
2188.84	213.954
2192.49	214.285
2196.13	216.098
2199.77	214.777
2203.41	212.506
2207.05	209.404
2210.69	205.589
2214.32	202.496
2217.95	201.287
2221.59	202.012
2225.22	204.397
2228.84	206.501
2232.47	209.718
2236.09	211.206
2239.72	210.018
2243.34	208.901
2246.96	208.472
2250.58	208.303
2254.2	208.463
2257.81	209.03
2261.42	209.047
2265.04	209.089
2268.65	208.615
2272.26	208.087
2275.86	207.619
2279.47	207.49
2283.08	207.753
2286.68	208.425
2290.28	209.501
2293.88	212.005
2297.48	210.136
2301.07	209.241
2304.67	214.935
2308.26	221.619
2311.85	350.694
2315.44	679
2319.03	850
2322.62	432
2326.2	245.464
2329.79	222.535
2333.37	214.174
2336.95	210.528
2340.53	209.702
2344.11	211.829
2347.68	212.05
2351.26	211.629
2354.83	211.252
2358.4	210.753
2361.97	210.322
2365.54	209.991
2369.11	209.869
2372.67	209.854
2376.23	210.767
2379.8	211.574
2383.36	211.737
2386.92	211.298
2390.47	210.319
2394.03	207.845
2397.58	205.813
2401.14	205.208
2404.69	204.954
2408.24	205.515
2411.78	206.89
2415.33	207.415
2418.88	205.984
2422.42	203.859
2425.96	201.405
2429.5	199.383
2433.04	198.9
2436.58	198.078
2440.11	202.581
2443.65	205.003
2447.18	208.546
2450.71	206.225
2454.24	198.039
2457.77	198.661
2461.3	197.438
2464.82	197.684
2468.34	197.963
2471.86	198.004
2475.39	198.043
2478.9	197.845
2482.42	197.668
2485.94	197.68
2489.45	197.749
2492.96	198.197
2496.47	197.428
2499.98	196.346
2503.49	195.743
2507	195.53
2510.5	196.318
2514.01	198.61
2517.51	199.842
2521.01	200.321
2524.51	200.548
2528.01	199.658
2531.5	198.571
2535	197.501
2538.49	196.164
2541.98	196.574
2545.47	197.897
2548.96	199.445
2552.45	199.98
2555.93	198.438
2559.42	196.348
2562.9	194.098
2566.38	192.436
2569.86	191.264
2573.34	190.161
2576.81	188.922
2580.29	187.488
2583.76	186.306
2587.23	185.551
2590.71	185.182
2594.17	185.055
2597.64	185.368
2601.11	185.599
2604.57	185.77
2608.03	185.138
2611.5	183.962
2614.96	183.16
2618.42	182.664
2621.87	182.274
2625.33	182.85
2628.78	184.97
2632.23	188.177
2635.68	190.071
2639.13	191.486
2642.58	192.064
2646.03	192.205
2649.47	191.623
2652.92	190.859
2656.36	191.281
2659.8	191.097
2663.24	190.831
2666.68	190.77
2670.11	191.182
2673.55	192.893
2676.98	193.326
2680.41	192.763
2683.84	191.358
2687.27	191.188
2690.7	191.191
2694.13	191.9
2697.55	193.499
2700.97	195.854
2704.4	196.156
2707.82	194.183
2711.23	192.572
2714.65	191.596
2718.07	192.515
2721.48	192.702
2724.9	192.801
2728.31	192.329
2731.72	192.022
2735.12	191.619
2738.53	191.755
2741.94	190.555
2745.34	189.008
2748.74	188.281
2752.14	188.949
2755.54	190.071
2758.94	191.241
2762.34	192.644
2765.73	193.351
2769.13	192.718
2772.52	191.534
2775.91	190.291
2779.3	188.69
2782.69	187.329
2786.08	188.463
2789.46	188.938
2792.85	189.323
2796.23	189.472
2799.61	188.766
2802.99	188.527
2806.37	188.557
2809.74	189.814
2813.12	190.752
2816.49	191.455
2819.86	191.097
2823.23	189.09
2826.61	188.864
2829.97	190.882
2833.34	192.68
2836.7	196.817
2840.07	200.121
2843.43	201.734
2846.79	202.016
2850.15	200.375
2853.51	198.984
2856.87	197.087
2860.22	195.714
2863.57	195.208
2866.93	195.808
2870.28	196.787
2873.63	197.91
2876.98	198.616
2880.32	199.272
2883.67	200.025
2887.01	200.292
2890.35	200.312
2893.69	199.472
2897.03	198.603
2900.37	198.604
2903.71	199.088
2907.04	199.3
2910.38	199.441
2913.71	199.121
2917.04	198.745
2920.37	198.225
2923.7	197.762
2927.03	197.4
2930.35	199.78
2933.68	198.677
2937	195.798
2940.32	193.03
2943.64	191.38
2946.96	190.838
2950.27	191.431
2953.59	193.377
2956.91	195.335
2960.22	196.899
2963.53	198.826
2966.84	200.287
2970.15	200.737
2973.46	200.697
2976.76	200.288
2980.07	199.16
2983.37	204.393
2986.67	199.379
2989.97	197.895
2993.27	195.739
2996.57	201.165
2999.86	204.723
3003.16	207.2
3006.45	205.22
3009.75	203.955
3013.03	201.861
3016.32	201.269
3019.61	202.766
3022.9	204.206
3026.19	204.737
3029.47	206.349
3032.75	207.914
3036.03	208.221
3039.31	209.023
3042.59	210.087
3045.87	211.809
3049.14	210.369
3052.42	209.915
3055.69	209.411
3058.96	212.072
3062.23	218.619
3065.5	221.871
3068.77	220.138
3072.03	217.778
3075.3	216.613
3078.56	216.1
3081.82	216.284
3085.08	217.828
3088.34	220.916
3091.6	224.775
3094.86	228.412
3098.11	231.557
3101.36	232.049
3104.62	233.435
3107.87	234.411
3111.12	235.516
3114.37	236.802
3117.61	238.154
3120.86	238.899
3124.1	239.266
3127.34	244.41
3130.59	248.312
3133.83	251.731
3137.07	256.815
3140.3	259.501
3143.54	260.16
3146.77	262.7
3150.01	265.05
3153.24	267.041
3156.47	264.525
3159.7	269.562
3162.93	274.487
3166.15	277.093
3169.38	279.958
3172.6	281.934
3175.83	284.069
3179.05	286.39
3182.27	288.233
3185.49	290.599
3188.7	294.417
3191.92	298.62
3195.13	302.608
3198.35	304.344
3201.56	305.845
3204.77	307.237
3207.98	308.629
3211.19	310.034
3214.39	311.762
3217.6	315.364
3220.8	319.813
3224	323.507
3227.21	326.485
3230.41	326.618
3233.6	326.618
3236.8	326.931
3240	327.227
3243.19	327.298
3246.39	327.07
3249.58	326.296
3252.77	325.902
3255.96	326.583
3259.15	329.476
3262.33	333.941
3265.52	340.149
3268.7	344.663
3271.89	348.834
3275.07	347.119
3278.25	345.122
3281.43	343.656
3284.6	342.673
3287.78	342.301
3290.95	343.232
3294.13	347.716
3297.3	349.828
3300.47	353.629
3303.64	357.09
3306.81	357.013
3309.98	357.242
3313.14	357.98
3316.31	359.732
3319.47	361.516
3322.63	365.125
3325.79	369.544
3328.95	375.641
3332.11	382.573
3335.27	386.674
3338.42	389.622
3341.58	391.863
3344.73	395.529
3347.88	397.553
3351.03	399.161
3354.18	400.48
3357.33	401.685
3360.47	403.112
3363.62	404.467
3366.76	405.582
3369.91	406.649
3373.05	408.197
3376.19	411.188
3379.32	415.682
3382.46	422.142
3385.6	423.026
3388.73	422.483
3391.87	423.716
3395	429.285
3398.13	434.038
3401.26	441.145
3404.39	441.695
3407.51	442.42
3410.64	442.605
3413.76	441.774
3416.89	441.184
3420.01	438.611
3423.13	441.225
3426.25	440.134
3429.37	434.765
3432.48	435.345
3435.6	438.683
3438.71	450.14
3441.83	448.896
3444.94	447.722
3448.05	446.206
3451.16	443.343
3454.27	439.884
3457.37	435.514
3460.48	431.181
3463.58	427.068
3466.69	423.078
3469.79	419.202
3472.89	414.958
3475.99	419.666
3479.08	414.527
3482.18	411.823
3485.28	410.082
3488.37	405.089
3491.46	400.543
3494.55	395.997
3497.64	390.997
3500.73	380.832
3503.82	379.505
3506.91	378.301
3509.99	376.738
3513.08	373.753
3516.16	370.079
3519.24	365.447
3522.32	359.732
3525.4	353.485
3528.48	346.725
3531.55	338.754
3534.63	332.191
3537.7	326.588
3540.78	321.702
3543.85	317.266
3546.92	311.706
3549.99	311.264
3553.05	308.449
3556.12	306.33
3559.19	303.11
3562.25	301.128
3565.31	296.473
3568.37	293.203
3571.43	291.897
3574.49	290.415
3577.55	288.747
3580.61	286.871
3583.66	284.678
3586.72	282.189
3589.77	277.334
3592.82	273.066
3595.87	269.202
3598.92	265.746
3601.97	264.679
3605.02	262.602
3608.06	260.944
3611.11	260.069
3614.15	258.806
3617.19	256.094
3620.23	252.673
3623.27	246.5
3626.31	240.057
3629.34	234.953
3632.38	229.914
3635.41	224.779
3638.45	222.736
3641.48	220.732
3644.51	216.07
3647.54	212.852
3650.57	209.126
3653.59	205.055
3656.62	200.854
3659.65	196.907
3662.67	194.646
3665.69	192.721
3668.71	190.969
3671.73	189.084
3674.75	187.082
3677.77	184.465
3680.78	180.542
3683.8	177.063
3686.81	173.264
3689.82	170.671
3692.84	170.796
3695.84	169.927
3698.85	169.208
3701.86	169.005
3704.87	168.743
3707.87	168.506
3710.88	168.265
3713.88	167.767
3716.88	167.43
3719.88	168.555
3722.88	169.373
3725.88	169.653
3728.88	169.245
3731.87	168.4
3734.87	167.404
3737.86	166.878
3740.85	165.138
3743.84	163.237
3746.83	162.528
3749.82	163.461
3752.81	159.211
3755.79	158.799
3758.78	160.035
3761.76	161.98
3764.74	163.917
3767.73	164.197
3770.71	163.907
3773.68	161.202
3776.66	160.816
3779.64	160.263
3782.61	158.881
3785.59	157.228
3788.56	156.145
3791.53	155.57
3794.5	155.516
3797.47	156.038
3800.44	154.6
3803.41	152.877
3806.37	152.003
3809.34	151.747
3812.3	152.153
3815.26	153.124
3818.22	154.745
3821.18	157.182
3824.14	158.382
3827.1	158.293
3830.06	156.632
3833.01	155.324
3835.96	154.109
3838.92	153.067
3841.87	149.931
3844.82	149.801
3847.77	149.691
3850.72	148.384
3853.66	149.182
3856.61	149.607
3859.55	150.236
3862.5	150.198
3865.44	149.327
3868.38	148.315
3871.32	147.512
3874.26	147.206
3877.2	148.756
3880.13	149.8
3883.07	150.62
3886	151.272
3888.94	151.811
3891.87	152.444
3894.8	153.135
3897.73	153.426
3900.66	153.079
3903.58	152.447
3906.51	151.939
3909.43	152.374
3912.36	151.95
3915.28	150.478
3918.2	149.113
3921.12	148.461
3924.04	149.25
3926.96	149.387
3929.87	149.217
3932.79	148.874
3935.7	148.602
3938.62	148.196
3941.53	147.728
3944.44	147.219
3947.35	146.497
3950.26	145.933
3953.17	146.812
3956.07	148.05
3958.98	145.232
3961.88	143.703
3964.78	143.52
3967.69	145.308
3970.59	147.247
3973.49	148.845
3976.38	149.545
3979.28	149.096
3982.18	147.456
3985.07	145.647
3987.97	144.045
3990.86	143.078
3993.75	140.079
3996.64	139.053
3999.53	139.61
4002.42	141.889
4005.3	143.312
4008.19	142.398
4011.07	142.564
4013.96	142.467
4016.84	142.312
4019.72	142.114
4022.6	141.892
4025.48	141.746
4028.36	141.691
4031.23	141.881
4034.11	141.831
4036.98	141.204
4039.86	140.438
4042.73	139.592
4045.6	138.738
4048.47	139.822
4051.34	136.847
4054.21	133.239
4057.07	132.074
4059.94	140.542
4062.8	142.2
4065.67	138.122
4068.53	137.376
4071.39	134.69
4074.25	137.574
4077.11	139.285
4079.97	141.243
4082.82	140.879
4085.68	140.813
4088.53	140.762
4091.39	138.316
4094.24	138.267
4097.09	138.546
4099.94	138.565
4102.79	138.108
4105.63	137.465
4108.48	135.96
4111.33	136.542
4114.17	137.57
4117.01	138.58
4119.86	139.602
4122.7	140.002
4125.54	138.311
4128.38	136.294
4131.21	134.847
4134.05	134.12
4136.88	133.657
4139.72	133.622
4142.55	132.976
4145.38	132.578
4148.21	132.487
4151.04	132.705
4153.87	133.345
4156.7	134.376
4159.53	136.502
4162.35	138.03
4165.18	139.218
4168	139.468
4170.82	138.4
4173.64	136.833
4176.46	134.849
4179.28	132.707
4182.1	131.02
4184.91	130.13
4187.73	129.436
4190.55	129.484
4193.36	131.073
4196.17	132.583
4198.98	133.457
4201.79	132.976
4204.6	133.349
4207.41	133.446
4210.21	133.342
4213.02	132.436
4215.82	131.235
4218.63	129.488
4221.43	127.931
4224.23	126.482
4227.03	125.114
4229.83	124.26
4232.63	125.143
4235.43	124.284
4238.22	123.824
4241.02	124.144
4243.81	124.911
4246.6	126.002
4249.4	127.135
4252.19	127.513
4254.98	127.371
4257.76	126.84
4260.55	125.842
4263.34	123.637
4266.12	122.606
4268.91	122.032
4271.69	121.989
4274.47	122.396
4277.25	122.803
4280.03	122.982
4282.81	122.893
4285.59	122.673
4288.36	122.054
4291.14	122.48
4293.91	122.988
4296.69	123.471
4299.46	123.568
4302.23	123.516
4305	122.659
4307.77	121.404
4310.54	119.567
4313.3	118.119
4316.07	116.862
4318.83	117.074
4321.6	118.183
4324.36	120.069
4327.12	121.167
4329.88	122.515
4332.64	122.156
4335.4	121.28
4338.16	119.959
4340.91	118.733
4343.67	117.108
4346.42	115.817
4349.18	120.438
4351.93	119.718
4354.68	118.066
4357.43	116.916
4360.18	117.86
4362.93	118.575
4365.67	119.495
4368.42	118.57
4371.16	117.37
4373.91	116.257
4376.65	121.747
4379.39	122.806
4382.13	122.769
4384.87	122.479
4387.61	121.998
4390.34	121.316
4393.08	120.489
4395.82	120.096
4398.55	118.388
4401.28	116.419
4404.02	114.727
4406.75	112.837
4409.48	114.694
4412.21	115.063
4414.93	110.533
4417.66	113.658
4420.38	113.915
4423.11	114.183
4425.83	114.351
4428.56	114.49
4431.28	114.614
4434	114.76
4436.72	114.836
4439.44	114.569
4442.15	114.374
4444.87	113.939
4447.58	113.388
4450.3	112.848
4453.01	112.196
4455.72	111.819
4458.44	111.869
4461.15	112.352
4463.86	113.094
4466.56	113.818
4469.27	114.748
4471.98	115.298
4474.68	114.245
4477.39	112.062
4480.09	109.366
4482.79	107.061
4485.49	107.898
4488.19	108.439
4490.89	108.971
4493.59	109.33
4496.28	109.488
4498.98	109.059
4501.67	108.808
4504.37	108.584
4507.06	108.262
4509.75	107.928
4512.44	107.571
4515.13	107.257
4517.82	106.971
4520.51	106.528
4523.2	106.094
4525.88	105.363
4528.56	104.467
4531.25	104.039
4533.93	104.506
4536.61	106.946
4539.29	108.77
4541.97	110.249
4544.65	111.063
4547.33	111.358
4550	111.204
4552.68	111.094
4555.35	109.977
4558.03	108.746
4560.7	107.898
4563.37	106.364
4566.04	105.083
4568.71	104.946
4571.38	105.097
4574.05	104.663
4576.71	104.512
4579.38	104.362
4582.04	104.34
4584.7	103.997
4587.37	103.589
4590.03	102.968
4592.69	102.068
4595.35	100.934
4598	99.68
4600.66	99.6605
4603.32	100.367
4605.97	101.477
4608.63	102.808
4611.28	103.699
4613.93	104.499
4616.58	105.707
4619.23	105.735
4621.88	104.637
4624.53	102.787
4627.18	101.04
4629.82	100.276
4632.47	101.022
4635.11	101.826
4637.76	101.797
4640.4	101.084
4643.04	100.731
4645.68	100.928
4648.32	98.966
4650.96	99.3397
4653.59	99.8507
4656.23	100.712
4658.86	101.793
4661.5	99.0313
4664.13	95.3592
4666.76	94.2876
4669.4	95.0861
4672.03	96.7043
4674.65	97.0821
4677.28	98.1148
4679.91	97.308
4682.54	96.5372
4685.16	95.6413
4687.79	95.0761
4690.41	95.1678
4693.03	96.3397
4695.65	99.3896
4698.27	102.416
4700.89	102.535
4703.51	101.532
4706.13	99.8624
4708.75	98.1965
4711.36	96.5533
4713.97	94.92
4716.59	95.1542
4719.2	95.5293
4721.81	94.5336
4724.42	93.154
4727.03	92.3621
4729.64	89.4965
4732.25	86.5891
4734.85	86.4427
4737.46	87.3024
4740.06	88.951
4742.67	90.629
4745.27	92.204
4747.87	93.5197
4750.47	93.5001
4753.07	93.5646
4755.67	93.6088
4758.27	93.776
4760.87	93.5855
4763.46	94.4022
4766.06	94.8998
4768.65	94.841
4771.25	94.2858
4773.84	93.2114
4776.43	90.2117
4779.02	90.4314
4781.61	90.1239
4784.2	89.8026
4786.78	89.4063
4789.37	88.822
4791.96	87.3553
4794.54	86.5377
4797.12	86.9214
4799.71	87.5408
4802.29	88.4088
4804.87	89.013
4807.45	88.6895
4810.02	88.35
4812.6	87.866
4815.18	86.8146
4817.76	86.5176
4820.33	86.4714
4822.9	86.7328
4825.48	87.5054
4828.05	88.7762
4830.62	90.5921
4833.19	91.5291
4835.76	92.0292
4838.33	91.8985
4840.89	91.8611
4843.46	90.4502
4846.02	87.9963
4848.59	86.4418
4851.15	85.6825
4853.71	85.3251
4856.27	85.3884
4858.83	85.7387
4861.39	86.1358
4863.95	86.5389
4866.51	87.0194
4869.07	87.4624
4871.62	87.7927
4874.18	87.9667
4876.73	87.7675
4879.28	87.0419
4881.84	85.8302
4884.39	84.4507
4886.94	83.7228
4889.49	83.2029
4892.03	82.5311
4894.58	82.4411
4897.13	82.9653
4899.67	84.0376
4902.22	85.7289
4904.76	87.2287
4907.3	87.7335
4909.84	87.8146
4912.38	87.5367
4914.92	86.0864
4917.46	82.4503
4920	78.3577
4922.54	78.3917
4925.07	79.9738
4927.61	81.1471
4930.14	81.3155
4932.68	81.537
4935.21	81.7715
4937.74	81.8926
4940.27	81.7319
4942.8	81.2588
4945.33	80.5237
4947.85	79.7791
4950.38	79.2593
4952.91	79.1572
4955.43	79.5666
4957.96	80.5182
4960.48	81.9649
4963	83.3348
4965.52	84.5006
4968.04	84.1184
4970.56	82.8725
4973.08	81.9998
4975.59	81.216
4978.11	80.633
4980.63	80.0273
4983.14	79.6006
4985.66	79.9315
4988.17	81.5057
4990.68	83.4595
4993.19	83.9555
4995.7	83.4683
4998.21	75.9253