File: Data/3-Raman/raw/22-A_qtz3b_FI01.txt
#Acq. time (s)=	15
#Accumulations=	3
#Range (cm-¹)=	50...5000
#Windows=	1
#Auto scanning=	Off
#Autofocus=	Off
#Macrospot=	Off
#AutoExposure=	Off
#Spike filter=	Multiple accum.
#Delay time (s)=	0
#Binning=	1
#Readout mode=	Signal
#DeNoise=	Lite
#ICS correction=	Off
#Dark correction=	Off
#Inst. Process=	Off
#Detector temperature (°C)=	-60.09
#Instrument=	LabRAM HR Evol
#Detector=	SIN-EM FIVIS
#Objective=	x100_VIS
#Grating=	150 (500nm)
#ND Filter=	100%
#Laser=	532nm_Edge
#Hole=	30.0125
#Temperature=	0
#Range=	Visible
#StageXY=	75x50mm Scan+
#StageZ=	Z motor
#X (µm)=	14196
#Y (µm)=	2411.6
#Z (µm)=	-374.4
#Full time(s)=	47
#Project=	Buranga
#Sample=	BU18FA22_A
#Site=	A_Trl4
#Title=	22-A_qtz3b_FI01
#Remark=
#Date=	09.07.2019 18:10
#Acquired=	09.07.2019 18:10:58
52.2859	10619
56.9342	8260
61.5802	6426.35
66.2217	5049.03
70.8631	4072.25
75.5021	3304.77
80.1389	2726.78
84.7734	2275.4
89.4056	1985.16
94.0333	1830.27
98.6609	1871.38
103.286	2311
107.909	4943
112.53	8213
117.146	6109
121.762	2809
126.376	1763.46
130.988	1509.97
135.595	1334.33
140.202	1212.24
144.807	1140.66
149.41	1117.19
154.008	1234.04
158.606	1371
163.201	1603.85
167.795	1967
172.384	2585
176.973	3515
181.559	4923
186.142	6475
190.724	7304
195.304	6811
199.881	5511
204.454	4027
209.028	2977
213.598	2259
218.165	1777
222.731	1448.53
227.295	1218.78
231.855	1061.15
236.415	978.464
240.972	1008.86
245.525	1249.44
250.078	1361
254.629	997
259.175	647.467
263.722	571.303
268.264	513.955
272.805	473.337
277.345	442.941
281.88	418.498
286.415	399.888
290.948	387.852
295.477	382.243
300.005	400.478
304.529	388.265
309.053	391.453
313.575	399.274
318.093	411.807
322.61	452.541
327.123	481.544
331.636	638.829
336.145	1236
340.653	1754
345.157	1049
349.662	556.679
354.164	447.8
358.661	413.352
363.159	439.829
367.652	495.371
372.145	637.264
376.634	1273
381.123	1366
385.608	1103.52
390.092	823.086
394.572	597.73
399.052	516.082
403.528	504.928
408.004	521.682
412.475	559.046
416.947	621.418
421.414	749.365
425.881	908.409
430.343	1382
434.806	2345
439.264	4471
443.723	11051
448.177	21593
452.629	22373
457.081	12598
461.528	5899
465.976	3411
470.419	2271
474.862	1777
479.301	1430.16
483.738	1244.37
488.175	1113.76
492.607	1033.09
497.04	947.501
501.468	871.174
505.894	799.707
510.32	745.672
514.742	703.916
519.164	670.207
523.581	642.698
527.997	616.903
532.412	591.179
536.823	567.345
541.232	545.197
545.641	523.376
550.046	505.186
554.449	489.821
558.851	479.771
563.25	477.378
567.646	482.412
572.042	485.951
576.434	487.218
580.824	482.013
585.214	475.794
589.599	468.985
593.983	461.796
598.367	454.355
602.746	446.341
607.123	437.54
611.498	432.459
615.873	430.618
620.244	423.939
624.613	444.747
628.98	432.999
633.346	425.09
637.709	418.005
642.069	414.17
646.428	410.55
650.786	410.085
655.14	422.192
659.492	433.879
663.842	445.203
668.192	481.188
672.538	553.626
676.882	712.126
681.223	840.465
685.563	771.311
689.902	601.066
694.238	522.552
698.571	478.611
702.902	445.88
707.231	431.494
711.559	419.835
715.886	418.298
720.209	417.804
724.529	419.302
728.848	423.928
733.165	425.5
737.48	424.596
741.792	421.853
746.105	418.376
750.413	416.733
754.72	420.999
759.024	431.719
763.327	449.955
767.627	473.558
771.925	505.623
776.221	571.497
780.518	644.32
784.81	724.407
789.1	800.596
793.388	816.304
797.674	724.171
801.958	633.342
806.24	550.746
810.52	510.754
814.797	484.53
819.073	465.805
823.347	457.447
827.619	472.56
831.888	473.281
836.156	467.563
840.422	459.878
844.685	451.116
848.947	448.25
853.206	446.106
857.464	444.237
861.719	443.352
865.973	447.863
870.224	452.973
874.474	457.515
878.721	461.39
882.967	464.415
887.21	465.765
891.452	466.488
895.691	468.486
899.929	470.766
904.164	471.184
908.397	469.201
912.629	465.046
916.858	458.516
921.086	450.182
925.311	444.489
929.534	440.396
933.756	437.892
937.975	436.237
942.191	430.436
946.406	424.838
950.619	419.081
954.831	413.559
959.04	407.569
963.248	401.8
967.453	397.904
971.657	395.388
975.858	396.641
980.056	398.91
984.253	401.683
988.449	403.413
992.643	404.234
996.834	402.7
1001.02	401.156
1005.21	402.013
1009.4	401.41
1013.58	400.774
1017.76	400.991
1021.94	402.307
1026.12	404.606
1030.29	405.106
1034.47	414.349
1038.64	425.875
1042.81	456.544
1046.98	489.854
1051.14	518.69
1055.3	539.168
1059.47	546.358
1063.63	547.794
1067.78	550.265
1071.94	523.012
1076.09	478.74
1080.25	448.465
1084.4	426.944
1088.54	418.7
1092.69	419.141
1096.83	419.101
1100.98	417.624
1105.12	417.3
1109.26	419.604
1113.39	421.251
1117.53	426.287
1121.66	432.436
1125.79	458.079
1129.92	495.706
1134.04	556.051
1138.17	671.713
1142.29	1014.5
1146.41	1363.04
1150.53	1220
1154.65	856
1158.76	585.842
1162.88	510.036
1166.99	467.126
1171.1	455.268
1175.2	447.326
1179.31	442.383
1183.41	440.632
1187.51	441.836
1191.61	446.494
1195.71	452.398
1199.81	463.121
1203.9	471.711
1207.99	490.43
1212.08	518.22
1216.17	547.011
1220.26	555.139
1224.34	544.163
1228.42	520.692
1232.5	503.95
1236.58	496.572
1240.66	500.632
1244.73	529.881
1248.81	575.245
1252.88	621.403
1256.95	551.4
1261.02	551.067
1265.08	629.55
1269.14	1436
1273.2	1997
1277.27	1005
1281.32	553.448
1285.38	520.522
1289.43	502.759
1293.48	487.284
1297.53	476.949
1301.58	469.272
1305.63	463.977
1309.67	459.091
1313.72	459.409
1317.76	460.465
1321.8	462.991
1325.83	466.92
1329.87	471.098
1333.9	477.355
1337.93	479.307
1341.96	482.36
1345.99	488.838
1350.02	501.832
1354.04	528.906
1358.06	551.563
1362.08	566.528
1366.1	590.449
1370.12	1045
1374.13	2715
1378.14	2453
1382.16	842.105
1386.16	627.39
1390.17	576.724
1394.18	645.911
1398.18	669.861
1402.18	549.378
1406.18	504.983
1410.18	486.206
1414.18	474.292
1418.17	465.982
1422.16	462.304
1426.15	458.863
1430.14	455.357
1434.13	452.429
1438.11	447.177
1442.1	441.836
1446.08	436.873
1450.06	432.463
1454.04	429.084
1458.01	428.114
1461.98	428.616
1465.96	429.998
1469.93	431.578
1473.9	433.045
1477.86	434.356
1481.83	435.475
1485.79	436.354
1489.75	437.146
1493.71	437.876
1497.67	437.023
1501.62	435.895
1505.58	435.051
1509.53	433.742
1513.48	435.182
1517.43	437.096
1521.38	439.562
1525.32	441.611
1529.26	444.075
1533.2	445.621
1537.14	441.705
1541.08	442.924
1545.02	440.343
1548.95	443.644
1552.88	449.623
1556.81	451.257
1560.74	457.177
1564.67	456.711
1568.6	453.15
1572.52	446.619
1576.44	443.262
1580.36	452.758
1584.28	457.664
1588.19	461.173
1592.11	463.879
1596.02	466.205
1599.93	468.007
1603.84	469.121
1607.75	469.75
1611.65	470.098
1615.56	470.19
1619.46	470.006
1623.36	468.022
1627.25	466.528
1631.15	464.834
1635.05	463.116
1638.94	462.207
1642.83	462.022
1646.72	460.501
1650.61	458.066
1654.49	453.655
1658.38	448.936
1662.26	444.543
1666.14	440.976
1670.02	438.2
1673.89	436.019
1677.77	434.457
1681.64	433.43
1685.51	432.848
1689.38	432.756
1693.25	432.779
1697.12	433.793
1700.98	435.161
1704.85	436.165
1708.71	436.313
1712.57	435.693
1716.42	434.736
1720.28	433.2
1724.13	433.977
1727.99	437.012
1731.84	436.546
1735.69	436.43
1739.53	436.046
1743.38	435.508
1747.22	437.479
1751.06	439.678
1754.9	441.744
1758.74	444.152
1762.58	444.93
1766.41	444.277
1770.25	442.353
1774.08	439.569
1777.91	434.484
1781.73	432.068
1785.56	430.125
1789.39	428.529
1793.21	427.26
1797.03	427.359
1800.85	428.35
1804.67	428.672
1808.48	428.498
1812.3	429.165
1816.11	429.46
1819.92	429.656
1823.73	429.924
1827.54	429.79
1831.34	428.429
1835.14	427.224
1838.95	426.698
1842.75	428.926
1846.55	431.563
1850.34	435.212
1854.14	437.598
1857.93	440.752
1861.72	441.613
1865.51	440.781
1869.3	439.018
1873.09	435.493
1876.87	432.766
1880.66	431.586
1884.44	431.424
1888.22	431.518
1892	432.634
1895.77	433.103
1899.55	433.233
1903.32	434.479
1907.09	433.74
1910.86	432.325
1914.63	430.263
1918.4	428.287
1922.16	426.818
1925.92	427.28
1929.68	429.429
1933.44	428.416
1937.2	428.041
1940.96	426.593
1944.71	424.535
1948.46	422.278
1952.22	420.042
1955.97	422.136
1959.71	425.924
1963.46	431.159
1967.2	435.7
1970.95	440.187
1974.69	445.124
1978.43	447.77
1982.17	445.121
1985.9	441.084
1989.64	435.679
1993.37	431.897
1997.1	427.087
2000.83	426.9
2004.56	429.406
2008.28	432.999
2012.01	438.379
2015.73	440.868
2019.45	440.789
2023.17	437.4
2026.89	434.881
2030.6	432.684
2034.32	430.482
2038.03	430.499
2041.74	431.262
2045.45	432.293
2049.16	433.458
2052.87	433.814
2056.57	433.011
2060.27	431.013
2063.98	428.183
2067.67	428.967
2071.37	417.164
2075.07	427.902
2078.76	432.483
2082.46	432.842
2086.15	430.519
2089.84	427.898
2093.53	425.392
2097.21	423.571
2100.9	422.527
2104.58	425.761
2108.26	422.922
2111.94	422.056
2115.62	422.912
2119.3	424.937
2122.97	426.487
2126.64	430.257
2130.32	434.533
2133.99	437.999
2137.66	434.146
2141.32	427.71
2144.99	426.547
2148.65	424.719
2152.31	426.762
2155.97	427.361
2159.63	426.012
2163.29	425.099
2166.94	425.223
2170.6	425.832
2174.25	426.73
2177.9	427.677
2181.55	428.699
2185.2	429.343
2188.84	429.401
2192.49	429.802
2196.13	427.7
2199.77	423.452
2203.41	418.048
2207.05	416.82
2210.69	416.872
2214.32	418.635
2217.95	421.321
2221.59	423.529
2225.22	424.226
2228.84	423.846
2232.47	421.659
2236.09	414.871
2239.72	410.649
2243.34	408.651
2246.96	408.69
2250.58	409.354
2254.2	409.549
2257.81	408.588
2261.42	407.319
2265.04	407.16
2268.65	406.832
2272.26	405.197
2275.86	403.703
2279.47	402.154
2283.08	400.513
2286.68	398.41
2290.28	396.057
2293.88	395.516
2297.48	396.664
2301.07	397.672
2304.67	404.713
2308.26	404.384
2311.85	428.482
2315.44	635.331
2319.03	673.466
2322.62	490.979
2326.2	440.242
2329.79	416.734
2333.37	406.753
2336.95	401.577
2340.53	403.742
2344.11	404.259
2347.68	404.222
2351.26	404.538
2354.83	405.112
2358.4	406.015
2361.97	407.183
2365.54	409.082
2369.11	411.193
2372.67	413.121
2376.23	415.3
2379.8	414.695
2383.36	411.787
2386.92	408.484
2390.47	405.372
2394.03	404.282
2397.58	403.137
2401.14	404.039
2404.69	405.208
2408.24	405.652
2411.78	405.048
2415.33	402.367
2418.88	399.231
2422.42	396.178
2425.96	393.366
2429.5	391.457
2433.04	390.173
2436.58	389.795
2440.11	389.492
2443.65	388.915
2447.18	389.395
2450.71	390.397
2454.24	390.84
2457.77	390.946
2461.3	389.702
2464.82	388.034
2468.34	386.255
2471.86	384.535
2475.39	383.088
2478.9	379.495
2482.42	381.937
2485.94	389.118
2489.45	394.331
2492.96	402.241
2496.47	403.747
2499.98	399.101
2503.49	392.091
2507	386.21
2510.5	382.268
2514.01	383.025
2517.51	384.06
2521.01	385.605
2524.51	387.583
2528.01	387.003
2531.5	389.022
2535	390.376
2538.49	392.557
2541.98	395.74
2545.47	397.551
2548.96	393.796
2552.45	388.45
2555.93	383.871
2559.42	379.804
2562.9	376.681
2566.38	375.208
2569.86	375.336
2573.34	377.141
2576.81	383.776
2580.29	383.77
2583.76	384.334
2587.23	380.356
2590.71	376.869
2594.17	376.508
2597.64	375.525
2601.11	373.709
2604.57	371.334
2608.03	368.67
2611.5	366.14
2614.96	364.416
2618.42	364.927
2621.87	365.767
2625.33	364.7
2628.78	365.828
2632.23	368.375
2635.68	371.148
2639.13	373.593
2642.58	375.384
2646.03	376.118
2649.47	374.86
2652.92	373.581
2656.36	373.289
2659.8	373.456
2663.24	373.806
2666.68	374.763
2670.11	376.162
2673.55	372.33
2676.98	374.075
2680.41	375.908
2683.84	377.677
2687.27	379.305
2690.7	380.095
2694.13	379.575
2697.55	377.031
2700.97	372.845
2704.4	368.698
2707.82	364.912
2711.23	364.829
2714.65	366.337
2718.07	368.67
2721.48	371.755
2724.9	375.376
2728.31	377.766
2731.72	378.831
2735.12	378.574
2738.53	376.869
2741.94	373.922
2745.34	369.816
2748.74	364.353
2752.14	359.639
2755.54	350.372
2758.94	369.507
2762.34	373.452
2765.73	373.723
2769.13	371.153
2772.52	368.177
2775.91	366.607
2779.3	366.385
2782.69	367.806
2786.08	368.288
2789.46	368.257
2792.85	367.697
2796.23	366.579
2799.61	365.131
2802.99	365.348
2806.37	365.666
2809.74	366.811
2813.12	368.237
2816.49	369.738
2819.86	370.947
2823.23	370.773
2826.61	369.885
2829.97	369.478
2833.34	369.962
2836.7	370.17
2840.07	369.915
2843.43	369.187
2846.79	367.992
2850.15	367.897
2853.51	367.64
2856.87	367.354
2860.22	368.02
2863.57	367.052
2866.93	365.235
2870.28	362.216
2873.63	359.528
2876.98	360.95
2880.32	362.148
2883.67	363.335
2887.01	364.395
2890.35	365.512
2893.69	366.638
2897.03	367.711
2900.37	368.797
2903.71	365.957
2907.04	363.227
2910.38	360.801
2913.71	356.713
2917.04	350.877
2920.37	351.087
2923.7	354.195
2927.03	362.607
2930.35	369.788
2933.68	373.891
2937	369.862
2940.32	367.831
2943.64	367.153
2946.96	366.583
2950.27	367.427
2953.59	368.059
2956.91	369.287
2960.22	368.517
2963.53	366.779
2966.84	363.779
2970.15	361.366
2973.46	359.624
2976.76	358.219
2980.07	357.194
2983.37	358.701
2986.67	361.536
2989.97	365.624
2993.27	368.795
2996.57	370.226
2999.86	369.787
3003.16	368.992
3006.45	367.702
3009.75	366.428
3013.03	365.719
3016.32	365.159
3019.61	365.272
3022.9	365.706
3026.19	366.169
3029.47	368.247
3032.75	372.186
3036.03	376.731
3039.31	377.499
3042.59	373.771
3045.87	369.798
3049.14	368.994
3052.42	369.532
3055.69	370.889
3058.96	372.632
3062.23	375.903
3065.5	380.477
3068.77	385.243
3072.03	388.902
3075.3	391.583
3078.56	392.907
3081.82	392.27
3085.08	395.38
3088.34	397.856
3091.6	399.515
3094.86	398.969
3098.11	399.004
3101.36	400.275
3104.62	402.952
3107.87	406.378
3111.12	410.082
3114.37	413.384
3117.61	416.655
3120.86	419.65
3124.1	422.199
3127.34	424.36
3130.59	426.197
3133.83	427.409
3137.07	428.367
3140.3	429.118
3143.54	428.45
3146.77	425.879
3150.01	424.22
3153.24	425.574
3156.47	429.418
3159.7	437.959
3162.93	445.61
3166.15	452.132
3169.38	457.438
3172.6	461.474
3175.83	464.058
3179.05	466.283
3182.27	472.128
3185.49	477.912
3188.7	483.099
3191.92	488.09
3195.13	493.008
3198.35	497.653
3201.56	494.989
3204.77	493.907
3207.98	492.151
3211.19	503.47
3214.39	513.636
3217.6	519.601
3220.8	517.533
3224	512.059
3227.21	509.68
3230.41	509.501
3233.6	509.522
3236.8	513.008
3240	519.567
3243.19	526.087
3246.39	531.811
3249.58	536.81
3252.77	538.129
3255.96	536.767
3259.15	535.479
3262.33	533.657
3265.52	531.316
3268.7	529.53
3271.89	530.064
3275.07	534.405
3278.25	539.593
3281.43	544.407
3284.6	548.424
3287.78	551.91
3290.95	554.74
3294.13	557.115
3297.3	559.15
3300.47	561.244
3303.64	563.606
3306.81	566.511
3309.98	569.525
3313.14	571.477
3316.31	572.505
3319.47	572.718
3322.63	575.144
3325.79	578.693
3328.95	583.191
3332.11	590.271
3335.27	594.272
3338.42	594.765
3341.58	592.991
3344.73	587.617
3347.88	591.499
3351.03	597.595
3354.18	605.819
3357.33	614.524
3360.47	622.957
3363.62	629.693
3366.76	633.354
3369.91	630.828
3373.05	627.734
3376.19	626.903
3379.32	627.889
3382.46	631.715
3385.6	637.631
3388.73	644.28
3391.87	649.627
3395	653.957
3398.13	657.717
3401.26	660.367
3404.39	661.676
3407.51	662.955
3410.64	664.092
3413.76	664.375
3416.89	664.128
3420.01	662.788
3423.13	659.891
3426.25	655.777
3429.37	650.876
3432.48	648.639
3435.6	648.451
3438.71	649.645
3441.83	651.664
3444.94	653.335
3448.05	655.434
3451.16	655.743
3454.27	656.815
3457.37	657.597
3460.48	655.545
3463.58	651.778
3466.69	646.019
3469.79	639.786
3472.89	635.062
3475.99	630.293
3479.08	628.676
3482.18	626.56
3485.28	622.883
3488.37	617.431
3491.46	609.084
3494.55	597.577
3497.64	586.977
3500.73	576.746
3503.82	567.992
3506.91	561.625
3509.99	557.952
3513.08	555.764
3516.16	551.467
3519.24	547.507
3522.32	542.036
3525.4	530.57
3528.48	512.438
3531.55	506.272
3534.63	510.534
3537.7	511.193
3540.78	510.738
3543.85	512.524
3546.92	501.23
3549.99	486.447
3553.05	476.053
3556.12	468.31
3559.19	468.131
3562.25	468.234
3565.31	464.05
3568.37	460.751
3571.43	455.45
3574.49	448.963
3577.55	442.805
3580.61	435.841
3583.66	432.583
3586.72	429.496
3589.77	425.197
3592.82	418.527
3595.87	413.942
3598.92	409.732
3601.97	407.23
3605.02	402.27
3608.06	396.614
3611.11	391.344
3614.15	386.358
3617.19	382.043
3620.23	378.656
3623.27	374.962
3626.31	368.988
3629.34	362.741
3632.38	357.709
3635.41	353.716
3638.45	351.98
3641.48	350.67
3644.51	351.277
3647.54	349.542
3650.57	347.21
3653.59	342.269
3656.62	336.025
3659.65	327.914
3662.67	319.694
3665.69	314.901
3668.71	311.683
3671.73	314.53
3674.75	305.889
3677.77	304.081
3680.78	301.672
3683.8	301.137
3686.81	300.927
3689.82	298.818
3692.84	296.225
3695.84	293.474
3698.85	290.876
3701.86	288.189
3704.87	285.372
3707.87	282.712
3710.88	280.039
3713.88	279.572
3716.88	279.602
3719.88	278.692
3722.88	278.95
3725.88	278.302
3728.88	276.52
3731.87	273.564
3734.87	269.094
3737.86	266.624
3740.85	265.562
3743.84	266.098
3746.83	267.615
3749.82	268.903
3752.81	270.856
3755.79	273.789
3758.78	274.872
3761.76	274.816
3764.74	272.523
3767.73	269.731
3770.71	267.175
3773.68	264.903
3776.66	262.853
3779.64	261.339
3782.61	260.161
3785.59	258.929
3788.56	257.67
3791.53	258.019
3794.5	258.881
3797.47	260.339
3800.44	262.118
3803.41	264.098
3806.37	266.74
3809.34	266.025
3812.3	261.419
3815.26	259.309
3818.22	261.134
3821.18	261.201
3824.14	260.735
3827.1	259.996
3830.06	257.839
3833.01	256.92
3835.96	257.524
3838.92	257.447
3841.87	257.39
3844.82	257.17
3847.77	257.067
3850.72	256.486
3853.66	255.186
3856.61	253.163
3859.55	250.015
3862.5	249.827
3865.44	250.013
3868.38	250.399
3871.32	251.203
3874.26	251.993
3877.2	252.725
3880.13	253.08
3883.07	251.966
3886	247.581
3888.94	246.284
3891.87	247.725
3894.8	251.076
3897.73	254.562
3900.66	252.888
3903.58	250.889
3906.51	247.644
3909.43	246.663
3912.36	248.845
3915.28	249.249
3918.2	249.305
3921.12	249.148
3924.04	248.814
3926.96	248.296
3929.87	246.639
3932.79	246.768
3935.7	248.99
3938.62	250.711
3941.53	251.792
3944.44	249.511
3947.35	247.994
3950.26	247.282
3953.17	246.256
3956.07	246.693
3958.98	246.095
3961.88	245.189
3964.78	244.019
3967.69	242.859
3970.59	241.368
3973.49	239.666
3976.38	238.058
3979.28	237.923
3982.18	238.526
3985.07	239.64
3987.97	241.699
3990.86	241.81
3993.75	241.274
3996.64	240.974
3999.53	240.231
4002.42	238.713
4005.3	238.452
4008.19	239.049
4011.07	238.856
4013.96	238.078
4016.84	238.161
4019.72	238.579
4022.6	240.232
4025.48	242.504
4028.36	243.528
4031.23	244.227
4034.11	244.34
4036.98	243.727
4039.86	240.266
4042.73	235.561
4045.6	229.549
4048.47	226.363
4051.34	225.671
4054.21	226.708
4057.07	227.662
4059.94	228.779
4062.8	229.754
4065.67	230.936
4068.53	230.331
4071.39	228.757
4074.25	228.039
4077.11	227.918
4079.97	228.601
4082.82	230.155
4085.68	229.978
4088.53	230.638
4091.39	228.317
4094.24	227.245
4097.09	226.822
4099.94	226.909
4102.79	225.421
4105.63	224.497
4108.48	223.59
4111.33	221.852
4114.17	219.468
4117.01	219.42
4119.86	220.761
4122.7	222.625
4125.54	226.93
4128.38	229.412
4131.21	230.676
4134.05	230.582
4136.88	230.382
4139.72	229.634
4142.55	228.668
4145.38	227.557
4148.21	226.026
4151.04	224.956
4153.87	221.805
4156.7	219.399
4159.53	217.629
4162.35	217.697
4165.18	219.048
4168	220.338
4170.82	221.602
4173.64	222.864
4176.46	223.18
4179.28	221.584
4182.1	218.033
4184.91	214.166
4187.73	211.944
4190.55	212.799
4193.36	213.177
4196.17	214.274
4198.98	214.623
4201.79	214.722
4204.6	214.915
4207.41	215.24
4210.21	214.427
4213.02	214.92
4215.82	214.196
4218.63	213.196
4221.43	211.57
4224.23	209.469
4227.03	207.692
4229.83	206.956
4232.63	206.07
4235.43	204.214
4238.22	202.776
4241.02	201.294
4243.81	200.084
4246.6	199.304
4249.4	198.783
4252.19	198.575
4254.98	198.582
4257.76	199.167
4260.55	200.245
4263.34	202.332
4266.12	204.016
4268.91	205.401
4271.69	206.884
4274.47	206.179
4277.25	202.885
4280.03	200.442
4282.81	198.907
4285.59	198.136
4288.36	198.006
4291.14	198.511
4293.91	200.064
4296.69	201.755
4299.46	196.494
4302.23	194.558
4305	195.784
4307.77	197.013
4310.54	197.425
4313.3	198.311
4316.07	198.171
4318.83	197.895
4321.6	197.694
4324.36	197.555
4327.12	197.371
4329.88	197.236
4332.64	197.283
4335.4	197.451
4338.16	197.362
4340.91	197.727
4343.67	196.853
4346.42	194.689
4349.18	193.619
4351.93	192.836
4354.68	192.509
4357.43	193.39
4360.18	194.018
4362.93	195.573
4365.67	195.434
4368.42	195.046
4371.16	194.718
4373.91	193.76
4376.65	192.957
4379.39	191.542
4382.13	188.907
4384.87	186.391
4387.61	183.623
4390.34	181.335
4393.08	180.624
4395.82	181.421
4398.55	181.902
4401.28	185.475
4404.02	189.693
4406.75	191.336
4409.48	188.699
4412.21	186.168
4414.93	184.632
4417.66	183.099
4420.38	182.344
4423.11	181.74
4425.83	181.128
4428.56	179.27
4431.28	178.375
4434	178.178
4436.72	179.206
4439.44	180.542
4442.15	182.328
4444.87	183.852
4447.58	184.852
4450.3	185.765
4453.01	186.485
4455.72	185.467
4458.44	182.426
4461.15	178.84
4463.86	176.34
4466.56	175.386
4469.27	175.568
4471.98	175.836
4474.68	175.453
4477.39	175.107
4480.09	174.992
4482.79	175.112
4485.49	175.563
4488.19	176.397
4490.89	176.815
4493.59	177.422
4496.28	175.117
4498.98	174.422
4501.67	173.662
4504.37	172.627
4507.06	171.587
4509.75	170.996
4512.44	169.584
4515.13	169.05
4517.82	168.734
4520.51	168.637
4523.2	168.584
4525.88	168.844
4528.56	169.26
4531.25	169.558
4533.93	169.915
4536.61	170.521
4539.29	169.945
4541.97	168.632
4544.65	166.959
4547.33	166.278
4550	166.609
4552.68	167.777
4555.35	167.935
4558.03	168.462
4560.7	167.799
4563.37	166.325
4566.04	164.406
4568.71	162.265
4571.38	160.687
4574.05	160.839
4576.71	161.952
4579.38	161.77
4582.04	161.152
4584.7	160.183
4587.37	158.567
4590.03	157.094
4592.69	156.08
4595.35	155.579
4598	156.839
4600.66	159.77
4603.32	162.019
4605.97	162.691
4608.63	162.019
4611.28	161.315
4613.93	160.44
4616.58	158.898
4619.23	157.536
4621.88	156.5
4624.53	155.779
4627.18	156.912
4629.82	157.127
4632.47	156.073
4635.11	154.924
4637.76	153.501
4640.4	152.576
4643.04	152.748
4645.68	152.571
4648.32	150.889
4650.96	149.793
4653.59	149.015
4656.23	148.405
4658.86	149.298
4661.5	149.57
4664.13	149.558
4666.76	149.599
4669.4	149.759
4672.03	149.121
4674.65	148.434
4677.28	146.642
4679.91	144.562
4682.54	143.316
4685.16	143.308
4687.79	144.519
4690.41	145.397
4693.03	146.349
4695.65	145.869
4698.27	145.017
4700.89	144.845
4703.51	145.38
4706.13	146.112
4708.75	146.783
4711.36	147.788
4713.97	149.453
4716.59	149.534
4719.2	148.01
4721.81	147.988
4724.42	146.959
4727.03	145.833
4729.64	144.698
4732.25	143.534
4734.85	142.917
4737.46	141.585
4740.06	139.879
4742.67	138.339
4745.27	136.308
4747.87	136.862
4750.47	139.059
4753.07	142.16
4755.67	145.756
4758.27	148.782
4760.87	150.545
4763.46	150.576
4766.06	148.534
4768.65	145.645
4771.25	142.079
4773.84	139.032
4776.43	136.971
4779.02	136.232
4781.61	136.504
4784.2	137.249
4786.78	138.331
4789.37	139.426
4791.96	140.378
4794.54	141.175
4797.12	141.801
4799.71	142.196
4802.29	142.245
4804.87	141.625
4807.45	140.57
4810.02	139.249
4812.6	137.83
4815.18	136.774
4817.76	135.881
4820.33	134.827
4822.9	134.453
4825.48	134.883
4828.05	135.134
4830.62	136.393
4833.19	137.535
4835.76	137.775
4838.33	137.469
4840.89	136.951
4843.46	136.274
4846.02	135.391
4848.59	134.403
4851.15	133.391
4853.71	132.423
4856.27	131.597
4858.83	130.82
4861.39	130.061
4863.95	128.806
4866.51	128.208
4869.07	128.466
4871.62	129.57
4874.18	130.908
4876.73	131.045
4879.28	130.974
4881.84	130.475
4884.39	129.865
4886.94	129.186
4889.49	128.467
4892.03	127.782
4894.58	127.096
4897.13	126.541
4899.67	126.14
4902.22	125.744
4904.76	125.183
4907.3	124.419
4909.84	123.638
4912.38	123.212
4914.92	123.358
4917.46	123.061
4920	122.686
4922.54	122.212
4925.07	122.033
4927.61	122.301
4930.14	123.577
4932.68	124.651
4935.21	125.373
4937.74	125.847
4940.27	126.26
4942.8	126.303
4945.33	126.196
4947.85	125.737
4950.38	123.977
4952.91	122.327
4955.43	120.568
4957.96	118.657
4960.48	116.907
4963	117.153
4965.52	119.722
4968.04	124.321
4970.56	128.55
4973.08	126.028
4975.59	122.894
4978.11	121.486
4980.63	119.257
4983.14	119.966
4985.66	119.637
4988.17	121.088
4990.68	123.658
4993.19	123.615
4995.7	127.652
4998.21	121.86