File: Data/3-Raman/raw/32-A_FF1_FI02.txt
#Acq. time (s)=	15
#Accumulations=	3
#Range (cm-¹)=	50...5000
#Windows=	1
#Auto scanning=	Off
#Autofocus=	Off
#Macrospot=	Off
#AutoExposure=	Off
#Spike filter=	Multiple accum.
#Delay time (s)=	0
#Binning=	1
#Readout mode=	Signal
#DeNoise=	Lite
#ICS correction=	Off
#Dark correction=	Off
#Inst. Process=	Off
#Detector temperature (°C)=	-60.09
#Instrument=	LabRAM HR Evol
#Detector=	SIN-EM FIVIS
#Objective=	x100_VIS
#Grating=	150 (500nm)
#ND Filter=	100%
#Laser=	532nm_Edge
#Hole=	30.0125
#Temperature=	0
#Range=	Visible
#StageXY=	75x50mm Scan+
#StageZ=	Z motor
#X (µm)=	-16646.7
#Y (µm)=	2674.1
#Z (µm)=	-431.2
#Full time(s)=	47
#Project=	Buranga
#Sample=	BU18FA32_A
#Site=	A_FF1
#Title=	32-A_FF1_FI02
#Remark=
#Date=	09.07.2019 14:22
#Acquired=	09.07.2019 14:22:35
52.2859	13457
56.9342	16566
61.5802	16416
66.2217	13877
70.8631	11344
75.5021	9065
80.1389	7463.21
84.7734	6187.14
89.4056	5130.82
94.0333	4239.92
98.6609	3454.7
103.286	2880.93
107.909	2315.24
112.53	1920.91
117.146	1572.54
121.762	1304.32
126.376	1105.56
130.988	958.057
135.595	838.317
140.202	743.096
144.807	664.789
149.41	589.917
154.008	534.721
158.606	506.529
163.201	490.019
167.795	538.762
172.384	747.231
176.973	661
181.559	416.932
186.142	338.283
190.724	287.195
195.304	270.208
199.881	284.812
204.454	288.527
209.028	295.897
213.598	315.254
218.165	330.844
222.731	343.54
227.295	333.313
231.855	317.627
236.415	294.297
240.972	291.942
245.525	303.962
250.078	316.167
254.629	334.493
259.175	313.588
263.722	313
268.264	305.792
272.805	331.152
277.345	330.152
281.88	324.056
286.415	316.839
290.948	308.89
295.477	296.647
300.005	312.074
304.529	326.269
309.053	344.041
313.575	366.682
318.093	369.728
322.61	353.149
327.123	320.772
331.636	295.945
336.145	281.315
340.653	284.652
345.157	300.752
349.662	324.433
354.164	394.717
358.661	473.058
363.159	480.155
367.652	377.016
372.145	317.602
376.634	284.721
381.123	261.961
385.608	249.873
390.092	247.738
394.572	254.057
399.052	270.346
403.528	299.399
408.004	335.613
412.475	372.776
416.947	403.272
421.414	430.218
425.881	453.148
430.343	471.214
434.806	483.421
439.264	487.882
443.723	487.264
448.177	480.564
452.629	452.559
457.081	420.369
461.528	423.952
465.976	473.487
470.419	468.478
474.862	411.004
479.301	365.054
483.738	337.854
488.175	329.357
492.607	339.889
497.04	369.066
501.468	413.275
505.894	502.696
510.32	600.331
514.742	693.879
519.164	771.221
523.581	832.89
527.997	866.266
532.412	867.563
536.823	856.478
541.232	829.408
545.641	770.106
550.046	756.038
554.449	739.128
558.851	769.272
563.25	760.304
567.646	730.613
572.042	686.747
576.434	617.843
580.824	562.789
585.214	527.895
589.599	521.48
593.983	621.366
598.367	713.289
602.746	785.171
607.123	785.76
611.498	638.92
615.873	506.9
620.244	431.058
624.613	385.18
628.98	349.067
633.346	321.303
637.709	302.079
642.069	290.727
646.428	287.963
650.786	291.907
655.14	302.013
659.492	331.267
663.842	356.793
668.192	371.312
672.538	344.563
676.882	300.824
681.223	262.879
685.563	229.915
689.902	208.431
694.238	193.193
698.571	183.873
702.902	180.653
707.231	180.253
711.559	181.208
715.886	182.382
720.209	179.821
724.529	175.739
728.848	171.634
733.165	167.923
737.48	165.594
741.792	164.998
746.105	165.068
750.413	166.99
754.72	169.682
759.024	172.361
763.327	173.599
767.627	174.472
771.925	174.875
776.221	175.119
780.518	174.033
784.81	172.029
789.1	171.752
793.388	171.136
797.674	170.429
801.958	169.811
806.24	167.859
810.52	166.69
814.797	166.142
819.073	166.111
823.347	166.358
827.619	165.01
831.888	163.651
836.156	162.212
840.422	160.219
844.685	158.233
848.947	156.585
853.206	155.171
857.464	154.064
861.719	153.146
865.973	152.944
870.224	153.467
874.474	154.316
878.721	156.083
882.967	157.522
887.21	157.672
891.452	158.628
895.691	158.566
899.929	159.215
904.164	160.73
908.397	163.116
912.629	166.281
916.858	171.344
921.086	179.209
925.311	190.127
929.534	204.463
933.756	223.274
937.975	243.712
942.191	273.381
946.406	306.822
950.619	341.04
954.831	383.135
959.04	430.808
963.248	488.824
967.453	553.029
971.657	620.89
975.858	716.107
980.056	844.547
984.253	982.859
988.449	1052.95
992.643	923
996.834	739.221
1001.02	629
1005.21	605
1009.4	592
1013.58	736
1017.76	882
1021.94	1083
1026.12	1250.53
1030.29	1197
1034.47	1142.31
1038.64	1017.73
1042.81	905.768
1046.98	777.634
1051.14	665.309
1055.3	545.24
1059.47	483.543
1063.63	458.736
1067.78	476.132
1071.94	522.728
1076.09	585.564
1080.25	637.995
1084.4	615.429
1088.54	546.314
1092.69	499.119
1096.83	455.659
1100.98	408.193
1105.12	391.05
1109.26	428.079
1113.39	492.284
1117.53	519.743
1121.66	534.004
1125.79	465.222
1129.92	387.742
1134.04	335.202
1138.17	290.367
1142.29	261.223
1146.41	250.215
1150.53	254.331
1154.65	264.824
1158.76	210.886
1162.88	190.943
1166.99	180.04
1171.1	181.603
1175.2	180.594
1179.31	172.253
1183.41	162.331
1187.51	153.999
1191.61	143.649
1195.71	144.441
1199.81	144.561
1203.9	145.888
1207.99	146.286
1212.08	145.441
1216.17	145.334
1220.26	146.545
1224.34	149.239
1228.42	153.287
1232.5	158.675
1236.58	165.389
1240.66	174.993
1244.73	183.455
1248.81	193.009
1252.88	204.222
1256.95	259.28
1261.02	338.59
1265.08	426.914
1269.14	338
1273.2	294
1277.27	461
1281.32	1651
1285.38	2687
1289.43	823
1293.48	337
1297.53	276.79
1301.58	242.679
1305.63	234.187
1309.67	224.653
1313.72	219.179
1317.76	214.411
1321.8	210.848
1325.83	208.389
1329.87	206.952
1333.9	206.321
1337.93	206.431
1341.96	206.823
1345.99	208.6
1350.02	212.762
1354.04	220.516
1358.06	231.909
1362.08	252.808
1366.1	283.174
1370.12	328.854
1374.13	348.982
1378.14	376.555
1382.16	887
1386.16	3459
1390.17	3916
1394.18	896
1398.18	388
1402.18	341
1406.18	459
1410.18	529
1414.18	346.403
1418.17	246.892
1422.16	218.021
1426.15	195.055
1430.14	178.521
1434.13	162.163
1438.11	154.396
1442.1	149.422
1446.08	146.872
1450.06	144.935
1454.04	143.528
1458.01	142.482
1461.98	141.038
1465.96	138.713
1469.93	137.156
1473.9	135.042
1477.86	134.537
1481.83	136.114
1485.79	137.823
1489.75	138.872
1493.71	139.168
1497.67	137.033
1501.62	135.676
1505.58	134.439
1509.53	133.455
1513.48	132.76
1517.43	131.774
1521.38	131.095
1525.32	130.87
1529.26	130.251
1533.2	130.805
1537.14	132.484
1541.08	138.894
1545.02	129.667
1548.95	130.329
1552.88	130.666
1556.81	132.157
1560.74	132.018
1564.67	131.34
1568.6	132.046
1572.52	132.394
1576.44	133.077
1580.36	133.959
1584.28	133.977
1588.19	135.282
1592.11	136.493
1596.02	137.361
1599.93	137.359
1603.84	137.168
1607.75	137.072
1611.65	136.289
1615.56	137.539
1619.46	137.941
1623.36	139.07
1627.25	137.159
1631.15	137.081
1635.05	137.71
1638.94	139.224
1642.83	140.232
1646.72	140.886
1650.61	141.031
1654.49	140.633
1658.38	140.037
1662.26	139.438
1666.14	138.625
1670.02	137.22
1673.89	136.11
1677.77	135.913
1681.64	136.489
1685.51	138.246
1689.38	139.458
1693.25	140.033
1697.12	140.047
1700.98	139.303
1704.85	138.566
1708.71	137.622
1712.57	137.462
1716.42	137.715
1720.28	138.453
1724.13	139.191
1727.99	139.926
1731.84	140.68
1735.69	141.493
1739.53	142.386
1743.38	143.281
1747.22	143.944
1751.06	145.227
1754.9	146.641
1758.74	148.07
1762.58	148.846
1766.41	149.145
1770.25	149.254
1774.08	149.215
1777.91	148.98
1781.73	148.781
1785.56	148.176
1789.39	147.025
1793.21	145.421
1797.03	144.193
1800.85	143.883
1804.67	143.265
1808.48	143.396
1812.3	143.291
1816.11	143.184
1819.92	143.059
1823.73	141.857
1827.54	140.8
1831.34	140.348
1835.14	140.269
1838.95	140.805
1842.75	144.437
1846.55	148.651
1850.34	151.403
1854.14	152.482
1857.93	151.835
1861.72	149.876
1865.51	147.96
1869.3	148.603
1873.09	148.822
1876.87	149.437
1880.66	150.396
1884.44	151.344
1888.22	151.519
1892	146.273
1895.77	148.632
1899.55	151.796
1903.32	155.112
1907.09	158.876
1910.86	162.444
1914.63	163.776
1918.4	164.258
1922.16	163.504
1925.92	162.345
1929.68	160.092
1933.44	157.151
1937.2	154.666
1940.96	153.372
1944.71	153.401
1948.46	153.42
1952.22	154.597
1955.97	155.582
1959.71	156.033
1963.46	156.827
1967.2	155.28
1970.95	156.259
1974.69	157.134
1978.43	158.09
1982.17	159.759
1985.9	161.056
1989.64	162.214
1993.37	163.119
1997.1	163.872
2000.83	164.515
2004.56	165.131
2008.28	165.753
2012.01	166.383
2015.73	167.004
2019.45	167.537
2023.17	168.204
2026.89	169.302
2030.6	170.91
2034.32	171.882
2038.03	172.782
2041.74	172.281
2045.45	171.566
2049.16	170.833
2052.87	169.985
2056.57	168.56
2060.27	167.119
2063.98	166.639
2067.67	168.382
2071.37	170.997
2075.07	173.115
2078.76	174.462
2082.46	174.893
2086.15	174.138
2089.84	172.419
2093.53	170.16
2097.21	166.385
2100.9	164.042
2104.58	167.404
2108.26	171.012
2111.94	174.449
2115.62	177.012
2119.3	178.598
2122.97	179.221
2126.64	178.793
2130.32	175.565
2133.99	174.208
2137.66	175.364
2141.32	179.782
2144.99	182.702
2148.65	185.294
2152.31	184.256
2155.97	184.672
2159.63	184.283
2163.29	181.785
2166.94	182.305
2170.6	184.389
2174.25	186.789
2177.9	187.056
2181.55	186.957
2185.2	186.797
2188.84	186.764
2192.49	187.223
2196.13	187.656
2199.77	188.343
2203.41	188.969
2207.05	189.585
2210.69	190.017
2214.32	190.297
2217.95	190.416
2221.59	189.792
2225.22	189.519
2228.84	190.507
2232.47	191.349
2236.09	191.635
2239.72	192.039
2243.34	192.914
2246.96	193.868
2250.58	193.423
2254.2	192.27
2257.81	190.966
2261.42	190.681
2265.04	190.627
2268.65	193.547
2272.26	195.772
2275.86	197.2
2279.47	197.973
2283.08	197.209
2286.68	195.662
2290.28	194.665
2293.88	193.949
2297.48	193.72
2301.07	194.129
2304.67	194.888
2308.26	196.779
2311.85	199.228
2315.44	201.477
2319.03	206.055
2322.62	217.198
2326.2	269.793
2329.79	374
2333.37	254.112
2336.95	218.917
2340.53	207.71
2344.11	205.919
2347.68	205.764
2351.26	206.408
2354.83	208.234
2358.4	208.175
2361.97	208.098
2365.54	204.725
2369.11	204.183
2372.67	205.505
2376.23	208.931
2379.8	213.242
2383.36	216.777
2386.92	219.626
2390.47	220.72
2394.03	222.198
2397.58	221.099
2401.14	219.791
2404.69	217.887
2408.24	216.595
2411.78	217.114
2415.33	219.105
2418.88	222.142
2422.42	223.053
2425.96	222.603
2429.5	220.728
2433.04	218.718
2436.58	217.559
2440.11	217.282
2443.65	218.333
2447.18	220.602
2450.71	221.309
2454.24	221.568
2457.77	221.05
2461.3	220.174
2464.82	218.846
2468.34	217.585
2471.86	216.255
2475.39	213.925
2478.9	215.349
2482.42	217.05
2485.94	218.51
2489.45	220.256
2492.96	222.487
2496.47	225.004
2499.98	227.255
2503.49	228.006
2507	227.647
2510.5	227.38
2514.01	227.557
2517.51	227.9
2521.01	227.773
2524.51	227.753
2528.01	227.567
2531.5	228.381
2535	230.292
2538.49	232.927
2541.98	233.662
2545.47	232.792
2548.96	230.671
2552.45	228.153
2555.93	220.888
2559.42	222.352
2562.9	225.394
2566.38	231.371
2569.86	234.652
2573.34	237.76
2576.81	238.446
2580.29	237.481
2583.76	235.895
2587.23	233.638
2590.71	231.757
2594.17	229.78
2597.64	227.985
2601.11	226.458
2604.57	225.266
2608.03	225.463
2611.5	225.272
2614.96	223.229
2618.42	218.673
2621.87	232.223
2625.33	234.79
2628.78	234.569
2632.23	233.399
2635.68	234.24
2639.13	235.87
2642.58	236.885
2646.03	238.041
2649.47	238.783
2652.92	239.475
2656.36	239.112
2659.8	238.667
2663.24	238.287
2666.68	238.038
2670.11	237.321
2673.55	236.973
2676.98	236.791
2680.41	235.46
2683.84	227.208
2687.27	237.119
2690.7	236.926
2694.13	238.714
2697.55	237.306
2700.97	238.353
2704.4	241.533
2707.82	246.539
2711.23	252.145
2714.65	259.197
2718.07	260.412
2721.48	256.43
2724.9	251.353
2728.31	243.366
2731.72	240.179
2735.12	238.805
2738.53	240.052
2741.94	242.619
2745.34	244.506
2748.74	246.336
2752.14	248.889
2755.54	250.542
2758.94	251.052
2762.34	251.027
2765.73	253.16
2769.13	252.224
2772.52	250.3
2775.91	249.076
2779.3	247.914
2782.69	247.739
2786.08	249.194
2789.46	254.936
2792.85	258.921
2796.23	261.046
2799.61	259.732
2802.99	256.089
2806.37	252.691
2809.74	250.078
2813.12	249.147
2816.49	250.285
2819.86	251.994
2823.23	253.48
2826.61	254.746
2829.97	255.766
2833.34	256.52
2836.7	257.119
2840.07	258.34
2843.43	258.091
2846.79	257.266
2850.15	256.614
2853.51	256.547
2856.87	256.662
2860.22	257.428
2863.57	259.736
2866.93	263.54
2870.28	265.325
2873.63	265.06
2876.98	261.4
2880.32	258.515
2883.67	256.515
2887.01	255.377
2890.35	254.884
2893.69	254.205
2897.03	254.79
2900.37	256.553
2903.71	257.857
2907.04	258.955
2910.38	259.951
2913.71	260.972
2917.04	261.443
2920.37	260.455
2923.7	260.117
2927.03	260.342
2930.35	260.975
2933.68	262.509
2937	264.236
2940.32	265.221
2943.64	266.175
2946.96	265.234
2950.27	264.089
2953.59	262.771
2956.91	261.602
2960.22	265.763
2963.53	269.689
2966.84	270.148
2970.15	269.592
2973.46	265.962
2976.76	253.455
2980.07	263.917
2983.37	268.674
2986.67	269.99
2989.97	268.504
2993.27	265.498
2996.57	261.679
2999.86	270.323
3003.16	272.398
3006.45	272.79
3009.75	271.036
3013.03	267.372
3016.32	267.751
3019.61	267.901
3022.9	268.852
3026.19	270.778
3029.47	268.011
3032.75	265.333
3036.03	264.279
3039.31	264.563
3042.59	265.795
3045.87	266.981
3049.14	268.028
3052.42	268.899
3055.69	269.681
3058.96	269.888
3062.23	269.071
3065.5	266.925
3068.77	268.803
3072.03	270.671
3075.3	270.239
3078.56	266.616
3081.82	263.25
3085.08	262.509
3088.34	262.741
3091.6	263.832
3094.86	265.548
3098.11	268.132
3101.36	270.759
3104.62	273.852
3107.87	277.031
3111.12	279.139
3114.37	279.093
3117.61	278.821
3120.86	279.156
3124.1	279.396
3127.34	281.181
3130.59	282.185
3133.83	282.739
3137.07	283.161
3140.3	283.31
3143.54	283.111
3146.77	284.163
3150.01	285.032
3153.24	285.493
3156.47	282.207
3159.7	279.043
3162.93	277.66
3166.15	288.25
3169.38	290.386
3172.6	290.457
3175.83	290.765
3179.05	291.233
3182.27	291.927
3185.49	292.876
3188.7	293.428
3191.92	296.057
3195.13	297.634
3198.35	300.043
3201.56	301.465
3204.77	303.425
3207.98	306.65
3211.19	310.051
3214.39	314.28
3217.6	319.008
3220.8	324.236
3224	328.995
3227.21	331.564
3230.41	334.529
3233.6	337.873
3236.8	341.454
3240	347.605
3243.19	354.311
3246.39	359.043
3249.58	363.794
3252.77	368.398
3255.96	372.546
3259.15	381.827
3262.33	389.278
3265.52	396.994
3268.7	403.991
3271.89	409.436
3275.07	413.472
3278.25	414.782
3281.43	415.034
3284.6	415.421
3287.78	417.902
3290.95	420.564
3294.13	425.864
3297.3	429.712
3300.47	431.825
3303.64	433.699
3306.81	435.404
3309.98	432.981
3313.14	430.117
3316.31	427.679
3319.47	427.218
3322.63	427.808
3325.79	428.901
3328.95	430.345
3332.11	432.894
3335.27	435.596
3338.42	438.486
3341.58	440.689
3344.73	442.952
3347.88	445.069
3351.03	444.709
3354.18	449.506
3357.33	456.564
3360.47	464.509
3363.62	474.61
3366.76	481.98
3369.91	488.465
3373.05	490.917
3376.19	494.683
3379.32	500.074
3382.46	506.987
3385.6	515.107
3388.73	524.78
3391.87	533.878
3395	549.276
3398.13	564.708
3401.26	579.924
3404.39	594.54
3407.51	609.957
3410.64	621.745
3413.76	630.128
3416.89	632.401
3420.01	630.465
3423.13	621.592
3426.25	611.784
3429.37	602.376
3432.48	591.42
3435.6	582.288
3438.71	576.633
3441.83	573.113
3444.94	573.073
3448.05	576.01
3451.16	583.9
3454.27	592.223
3457.37	602.36
3460.48	614.579
3463.58	629.83
3466.69	649.753
3469.79	673.482
3472.89	700.658
3475.99	730.342
3479.08	758.737
3482.18	783.031
3485.28	796.937
3488.37	804.888
3491.46	802.265
3494.55	795.928
3497.64	786.833
3500.73	775.396
3503.82	762.248
3506.91	746.668
3509.99	732.243
3513.08	715.235
3516.16	696.28
3519.24	676.637
3522.32	655.915
3525.4	634.621
3528.48	612.671
3531.55	589.913
3534.63	566.409
3537.7	541.829
3540.78	518.992
3543.85	498.702
3546.92	486.36
3549.99	478.807
3553.05	478.221
3556.12	477.441
3559.19	479.118
3562.25	481.336
3565.31	479.729
3568.37	474.732
3571.43	467.108
3574.49	461.23
3577.55	444.583
3580.61	428.586
3583.66	415.405
3586.72	405.133
3589.77	397.291
3592.82	391.089
3595.87	386.351
3598.92	383.644
3601.97	382.23
3605.02	379.714
3608.06	379.989
3611.11	383.582
3614.15	381.857
3617.19	378.315
3620.23	375.152
3623.27	375.685
3626.31	376.76
3629.34	378.511
3632.38	378.74
3635.41	377.523
3638.45	375.531
3641.48	373.167
3644.51	370.245
3647.54	366.931
3650.57	363.32
3653.59	358.881
3656.62	353.843
3659.65	348.178
3662.67	342.025
3665.69	337.304
3668.71	335.225
3671.73	333.521
3674.75	330.395
3677.77	326.591
3680.78	321.947
3683.8	317.048
3686.81	312.359
3689.82	307.242
3692.84	301.604
3695.84	296.467
3698.85	291.856
3701.86	287.864
3704.87	284.396
3707.87	281.335
3710.88	278.816
3713.88	277.02
3716.88	276.074
3719.88	275.855
3722.88	275.9
3725.88	276.052
3728.88	277.085
3731.87	277.173
3734.87	276.098
3737.86	274.207
3740.85	272.112
3743.84	273.731
3746.83	273.965
3749.82	273.967
3752.81	274.195
3755.79	273.429
3758.78	271.31
3761.76	268.978
3764.74	266.904
3767.73	265.651
3770.71	265.684
3773.68	266.7
3776.66	268.865
3779.64	271.782
3782.61	275.696
3785.59	277.215
3788.56	277.214
3791.53	276.371
3794.5	274.654
3797.47	273.151
3800.44	272.204
3803.41	271.914
3806.37	272.225
3809.34	273.454
3812.3	273.581
3815.26	273.746
3818.22	274.476
3821.18	272.765
3824.14	270.137
3827.1	271.556
3830.06	273.702
3833.01	273.678
3835.96	272.271
3838.92	269.563
3841.87	265.352
3844.82	261.561
3847.77	259.57
3850.72	259.829
3853.66	262.092
3856.61	264.484
3859.55	265.223
3862.5	265.431
3865.44	264.981
3868.38	264.059
3871.32	262.841
3874.26	261.256
3877.2	259.852
3880.13	260.995
3883.07	262.657
3886	265.06
3888.94	265.231
3891.87	262.473
3894.8	260.684
3897.73	259.596
3900.66	257.584
3903.58	257.354
3906.51	257.992
3909.43	259.914
3912.36	261.996
3915.28	262.827
3918.2	263.516
3921.12	261.863
3924.04	260.251
3926.96	258.497
3929.87	257.008
3932.79	256.429
3935.7	256.678
3938.62	257.725
3941.53	259.639
3944.44	261.762
3947.35	263.218
3950.26	263.505
3953.17	262.951
3956.07	261.295
3958.98	259.873
3961.88	258.875
3964.78	258.012
3967.69	257.985
3970.59	259.602
3973.49	263.019
3976.38	266.457
3979.28	268.488
3982.18	267.402
3985.07	265.189
3987.97	262.812
3990.86	260.786
3993.75	259.486
3996.64	258.752
3999.53	261.108
4002.42	262.987
4005.3	264.391
4008.19	263.683
4011.07	262.339
4013.96	260.602
4016.84	258.59
4019.72	256.541
4022.6	254.445
4025.48	253.064
4028.36	253.083
4031.23	254.731
4034.11	257.495
4036.98	260.521
4039.86	262.071
4042.73	262.417
4045.6	261.556
4048.47	258.893
4051.34	251.849
4054.21	248.902
4057.07	249.471
4059.94	250.871
4062.8	253.271
4065.67	255.418
4068.53	255.254
4071.39	249.404
4074.25	246.426
4077.11	243.78
4079.97	241.063
4082.82	240.96
4085.68	245.132
4088.53	248.351
4091.39	250.105
4094.24	252.117
4097.09	253.703
4099.94	254.625
4102.79	250.486
4105.63	250.088
4108.48	250.968
4111.33	253.208
4114.17	255.849
4117.01	253.875
4119.86	255.549
4122.7	257.642
4125.54	260.116
4128.38	259.342
4131.21	258.274
4134.05	257.087
4136.88	255.636
4139.72	252.535
4142.55	252.292
4145.38	252.555
4148.21	252.649
4151.04	252.716
4153.87	252.446
4156.7	252.434
4159.53	251.627
4162.35	251.411
4165.18	251.186
4168	251.264
4170.82	251.195
4173.64	251.613
4176.46	252.029
4179.28	251.883
4182.1	251.72
4184.91	251.728
4187.73	252.192
4190.55	253.277
4193.36	253.259
4196.17	253.185
4198.98	254.325
4201.79	254.95
4204.6	254.623
4207.41	253.15
4210.21	246.772
4213.02	251.063
4215.82	253.029
4218.63	252.481
4221.43	254.452
4224.23	251.53
4227.03	248.731
4229.83	247.421
4232.63	246.722
4235.43	246.132
4238.22	245.242
4241.02	244.217
4243.81	243.615
4246.6	243.474
4249.4	243.798
4252.19	244.93
4254.98	246.126
4257.76	247.88
4260.55	249.963
4263.34	248.758
4266.12	245.908
4268.91	242.645
4271.69	241.042
4274.47	241.573
4277.25	242.074
4280.03	241.592
4282.81	242.829
4285.59	243.288
4288.36	242.2
4291.14	240.529
4293.91	238.818
4296.69	238.869
4299.46	239.405
4302.23	240.734
4305	242.356
4307.77	242.536
4310.54	236.504
4313.3	237.153
4316.07	241.215
4318.83	241.178
4321.6	241.591
4324.36	240.608
4327.12	241.114
4329.88	240.578
4332.64	245.477
4335.4	248.664
4338.16	244.078
4340.91	236.319
4343.67	235.613
4346.42	235.773
4349.18	236.587
4351.93	238.261
4354.68	237.068
4357.43	236.551
4360.18	232.217
4362.93	230.782
4365.67	233.426
4368.42	237.283
4371.16	235.063
4373.91	230.226
4376.65	228.595
4379.39	228.145
4382.13	228.678
4384.87	233.166
4387.61	231.715
4390.34	229.652
4393.08	227.671
4395.82	227.918
4398.55	229.117
4401.28	230.035
4404.02	230.697
4406.75	231.877
4409.48	233.041
4412.21	236.041
4414.93	231.813
4417.66	227.294
4420.38	223.876
4423.11	222.341
4425.83	222.487
4428.56	228.388
4431.28	232.26
4434	234.939
4436.72	235.839
4439.44	234.801
4442.15	233.066
4444.87	231.133
4447.58	229.381
4450.3	227.611
4453.01	225.939
4455.72	224.371
4458.44	223.897
4461.15	223.74
4463.86	225.29
4466.56	227.165
4469.27	228.74
4471.98	229.649
4474.68	229.949
4477.39	229.37
4480.09	228.385
4482.79	227.49
4485.49	226.702
4488.19	224.101
4490.89	220.916
4493.59	217.661
4496.28	214.515
4498.98	211.608
4501.67	210.043
4504.37	213.349
4507.06	217.007
4509.75	220.636
4512.44	223.706
4515.13	226.494
4517.82	227.15
4520.51	224.541
4523.2	221.209
4525.88	218.219
4528.56	218.084
4531.25	219.01
4533.93	220.386
4536.61	221.275
4539.29	221.604
4541.97	222.233
4544.65	222.196
4547.33	221.636
4550	218.356
4552.68	214.726
4555.35	214.171
4558.03	213.835
4560.7	213.293
4563.37	213.501
4566.04	214.764
4568.71	215.225
4571.38	214.624
4574.05	213.973
4576.71	211.392
4579.38	207.848
4582.04	206.29
4584.7	207.734
4587.37	208.591
4590.03	209.043
4592.69	208.873
4595.35	208.028
4598	206.389
4600.66	208.081
4603.32	209.677
4605.97	211.61
4608.63	213.049
4611.28	212.44
4613.93	211.108
4616.58	209.178
4619.23	207.295
4621.88	206.911
4624.53	204.123
4627.18	203.148
4629.82	204.975
4632.47	209.386
4635.11	210.737
4637.76	211.595
4640.4	211.887
4643.04	209.399
4645.68	208.113
4648.32	207.759
4650.96	207.462
4653.59	205.858
4656.23	204.101
4658.86	202.437
4661.5	201.127
4664.13	200.468
4666.76	200.53
4669.4	201.185
4672.03	202.654
4674.65	203.168
4677.28	203.464
4679.91	203.146
4682.54	198.403
4685.16	197.135
4687.79	197.274
4690.41	198.496
4693.03	195.461
4695.65	195.816
4698.27	197.087
4700.89	197.902
4703.51	196.928
4706.13	196.715
4708.75	197.546
4711.36	199.697
4713.97	200.355
4716.59	199.335
4719.2	197.382
4721.81	195.392
4724.42	192.755
4727.03	190.98
4729.64	191.024
4732.25	192.07
4734.85	194.129
4737.46	196.521
4740.06	196.218
4742.67	195.565
4745.27	194.61
4747.87	193.242
4750.47	191.399
4753.07	188.568
4755.67	186.208
4758.27	185.001
4760.87	185.527
4763.46	187.855
4766.06	189.281
4768.65	190.983
4771.25	192.224
4773.84	193.423
4776.43	194.851
4779.02	195.315
4781.61	195.067
4784.2	193.726
4786.78	190.57
4789.37	187.597
4791.96	184.446
4794.54	184.642
4797.12	187.449
4799.71	191.244
4802.29	191.314
4804.87	189.979
4807.45	187.37
4810.02	183.444
4812.6	182.234
4815.18	183.085
4817.76	185.006
4820.33	186.261
4822.9	186.793
4825.48	185.923
4828.05	183.765
4830.62	181.405
4833.19	179.884
4835.76	179.347
4838.33	179.365
4840.89	179.592
4843.46	179.859
4846.02	180.311
4848.59	180.783
4851.15	181.134
4853.71	181.282
4856.27	181.348
4858.83	181.221
4861.39	180.632
4863.95	177.506
4866.51	177.903
4869.07	179.745
4871.62	181.934
4874.18	181.934
4876.73	181.03
4879.28	180.162
4881.84	179.357
4884.39	178.759
4886.94	177.86
4889.49	176.802
4892.03	175.786
4894.58	174.686
4897.13	173.471
4899.67	172.274
4902.22	171.144
4904.76	170.219
4907.3	170.416
4909.84	171.273
4912.38	172.339
4914.92	173.201
4917.46	170.434
4920	169.84
4922.54	170.98
4925.07	171.403
4927.61	171.947
4930.14	172.331
4932.68	172.331
4935.21	172.213
4937.74	171.4
4940.27	170.804
4942.8	170.235
4945.33	169.521
4947.85	168.515
4950.38	167.582
4952.91	166.708
4955.43	165.837
4957.96	165.463
4960.48	167.728
4963	169.078
4965.52	170.839
4968.04	172.922
4970.56	174.387
4973.08	173.347
4975.59	170.411
4978.11	168.301
4980.63	166.218
4983.14	165.136
4985.66	165.52
4988.17	166.089
4990.68	167.904
4993.19	169.034
4995.7	168.55
4998.21	162.884