File: Data/3-Raman/raw/32-C_FF1_FI08.txt
#Acq. time (s)=	15
#Accumulations=	3
#Range (cm-¹)=	50...5000
#Windows=	1
#Auto scanning=	Off
#Autofocus=	Off
#Macrospot=	Off
#AutoExposure=	Off
#Spike filter=	Multiple accum.
#Delay time (s)=	0
#Binning=	1
#Readout mode=	Signal
#DeNoise=	Lite
#ICS correction=	Off
#Dark correction=	Off
#Inst. Process=	Off
#Detector temperature (°C)=	-60.09
#Instrument=	LabRAM HR Evol
#Detector=	SIN-EM FIVIS
#Objective=	x100_VIS
#Grating=	150 (500nm)
#ND Filter=	100%
#Laser=	532nm_Edge
#Hole=	30.0125
#Temperature=	0
#Range=	Visible
#StageXY=	75x50mm Scan+
#StageZ=	Z motor
#X (µm)=	17774.9
#Y (µm)=	4242.8
#Z (µm)=	-419.5
#Full time(s)=	47
#Project=	Buranga
#Sample=	BU18FA32_C
#Site=	C_FF1
#Title=	32-C_FF1_FI08
#Remark=
#Date=	09.07.2019 16:49
#Acquired=	09.07.2019 16:49:26
52.2859	12001
56.9342	9679
61.5802	7443
66.2217	5735
70.8631	4678.23
75.5021	3854.12
80.1389	3127.85
84.7734	2566.54
89.4056	2124.94
94.0333	1726.14
98.6609	1426.51
103.286	1193.46
107.909	1008.68
112.53	868.567
117.146	777.661
121.762	709.68
126.376	661.956
130.988	636.859
135.595	635.083
140.202	641.565
144.807	587
149.41	549
154.008	678
158.606	1089
163.201	1459.18
167.795	960.914
172.384	569.271
176.973	437.476
181.559	416.976
186.142	422.046
190.724	432.127
195.304	464.24
199.881	504.267
204.454	544.292
209.028	584.378
213.598	599.087
218.165	536.026
222.731	470.808
227.295	453.019
231.855	487.288
236.415	544.811
240.972	603.815
245.525	580.019
250.078	520.938
254.629	503.49
259.175	538.681
263.722	541.926
268.264	526.026
272.805	507.541
277.345	490.846
281.88	475.478
286.415	470.935
290.948	480.566
295.477	496.033
300.005	593.588
304.529	665.166
309.053	600.141
313.575	524.343
318.093	470.578
322.61	446.42
327.123	452.785
331.636	474.888
336.145	519.65
340.653	595.841
345.157	750.154
349.662	819.478
354.164	702.206
358.661	535.777
363.159	463.42
367.652	419.48
372.145	391.753
376.634	382.581
381.123	390.748
385.608	415.103
390.092	455.622
394.572	511.661
399.052	578.883
403.528	656.788
408.004	731.402
412.475	794.215
416.947	839.703
421.414	879.132
425.881	904.031
430.343	928.588
434.806	916.839
439.264	866.385
443.723	813.425
448.177	796.707
452.629	858.676
457.081	1002.86
461.528	909.773
465.976	729.551
470.419	594.726
474.862	519.034
479.301	515.906
483.738	564.836
488.175	647.178
492.607	752.969
497.04	952.87
501.468	1148.86
505.894	1335.04
510.32	1472.96
514.742	1567.18
519.164	1635.61
523.581	1640.38
527.997	1595.11
532.412	1523.98
536.823	1439.87
541.232	1378.29
545.641	1441.45
550.046	1455.97
554.449	1391
558.851	1344.53
563.25	1235.78
567.646	1075
572.042	997.839
576.434	931
580.824	977
585.214	1158.28
589.599	1283
593.983	1471.83
598.367	1367.03
602.746	1111
607.123	932.959
611.498	772.235
615.873	673.82
620.244	598.274
624.613	544.255
628.98	506.745
633.346	486.123
637.709	480.982
642.069	475.984
646.428	511.63
650.786	559.477
655.14	616.08
659.492	593.399
663.842	514.149
668.192	440.099
672.538	377.955
676.882	326.133
681.223	296.045
685.563	274.283
689.902	265.474
694.238	269.817
698.571	275.403
702.902	278.515
707.231	277.133
711.559	272.06
715.886	265.251
720.209	257.67
724.529	250.02
728.848	244.581
733.165	241.51
737.48	240.106
741.792	240.008
746.105	239.91
750.413	239.82
754.72	239.674
759.024	238.586
763.327	236.019
767.627	233.153
771.925	230.869
776.221	228.638
780.518	225.997
784.81	224.342
789.1	223.134
793.388	221.589
797.674	221.368
801.958	223.883
806.24	223.588
810.52	222.048
814.797	218.218
819.073	214.519
823.347	214.468
827.619	214.438
831.888	213.346
836.156	212.96
840.422	214.197
844.685	215.524
848.947	216.2
853.206	218.459
857.464	217.239
861.719	215.778
865.973	214.726
870.224	214.086
874.474	214.492
878.721	215.727
882.967	218.298
887.21	221.919
891.452	226.12
895.691	231.854
899.929	239.576
904.164	249.29
908.397	260.893
912.629	277.141
916.858	301.037
921.086	331.926
925.311	373.391
929.534	423.128
933.756	480.165
937.975	546.451
942.191	624.582
946.406	711.874
950.619	807.447
954.831	927.644
959.04	1039.15
963.248	1170.29
967.453	1385.35
971.657	1665.21
975.858	1891
980.056	1770.1
984.253	1415.34
988.449	1196.72
992.643	1094.21
996.834	1104.13
1001.02	1294
1005.21	1678.42
1009.4	2130
1013.58	2591
1017.76	2791.74
1021.94	2692.37
1026.12	2436
1030.29	2243
1034.47	1826
1038.64	1550.32
1042.81	1184.35
1046.98	949.371
1051.14	863.364
1055.3	850.36
1059.47	889.392
1063.63	984.659
1067.78	1054.53
1071.94	1049.57
1076.09	1006.13
1080.25	912.121
1084.4	796.88
1088.54	678.053
1092.69	676
1096.83	646
1100.98	745
1105.12	783
1109.26	890
1113.39	832.514
1117.53	699.071
1121.66	570.217
1125.79	466.541
1129.92	392.515
1134.04	357.254
1138.17	335.896
1142.29	316.366
1146.41	298.664
1150.53	280.932
1154.65	265.155
1158.76	251.757
1162.88	240.321
1166.99	230.105
1171.1	221.589
1175.2	214.881
1179.31	209.917
1183.41	205.748
1187.51	200.866
1191.61	196.559
1195.71	193.943
1199.81	193.189
1203.9	193.745
1207.99	195.85
1212.08	199.326
1216.17	203.275
1220.26	206.588
1224.34	207.808
1228.42	208.689
1232.5	209.537
1236.58	217.702
1240.66	228.731
1244.73	244.574
1248.81	259.798
1252.88	346.639
1256.95	392.392
1261.02	291
1265.08	276
1269.14	379.493
1273.2	1679
1277.27	1979
1281.32	535
1285.38	270.488
1289.43	251.376
1293.48	244.77
1297.53	241.053
1301.58	237.701
1305.63	235.263
1309.67	233.789
1313.72	233.263
1317.76	232.954
1321.8	232.035
1325.83	231.38
1329.87	230.288
1333.9	230.696
1337.93	232.791
1341.96	234.73
1345.99	242.123
1350.02	251.677
1354.04	265.389
1358.06	286.179
1362.08	319.715
1366.1	296.802
1370.12	349
1374.13	849
1378.14	3649
1382.16	1870
1386.16	431
1390.17	319
1394.18	289
1398.18	457
1402.18	474
1406.18	270.237
1410.18	245.095
1414.18	235.767
1418.17	225.838
1422.16	217.531
1426.15	210.833
1430.14	205.123
1434.13	199.755
1438.11	195.481
1442.1	191.619
1446.08	187.489
1450.06	183.503
1454.04	180.019
1458.01	176.874
1461.98	174.314
1465.96	169.75
1469.93	172.4
1473.9	173.986
1477.86	175.666
1481.83	177.385
1485.79	179.206
1489.75	181.682
1493.71	184.145
1497.67	185.902
1501.62	188.025
1505.58	187.488
1509.53	186.3
1513.48	184.052
1517.43	182.539
1521.38	181.028
1525.32	180.594
1529.26	181.623
1533.2	184.068
1537.14	187.35
1541.08	190.732
1545.02	192.301
1548.95	191.406
1552.88	189.593
1556.81	186.99
1560.74	185.078
1564.67	182.915
1568.6	182.248
1572.52	183.682
1576.44	186.141
1580.36	189.629
1584.28	193.271
1588.19	195.072
1592.11	196.012
1596.02	196.233
1599.93	195.614
1603.84	195.368
1607.75	195.25
1611.65	195.32
1615.56	196.489
1619.46	199.639
1623.36	192.986
1627.25	201.511
1631.15	206.066
1635.05	206.047
1638.94	204.818
1642.83	195.239
1646.72	187.992
1650.61	196.587
1654.49	198.691
1658.38	199.814
1662.26	199.037
1666.14	198.525
1670.02	198.33
1673.89	199.928
1677.77	201.399
1681.64	202.535
1685.51	203.676
1689.38	204.612
1693.25	205.867
1697.12	205.739
1700.98	204.597
1704.85	203.64
1708.71	202.715
1712.57	202.415
1716.42	202.519
1720.28	202.938
1724.13	203.012
1727.99	201.776
1731.84	201.53
1735.69	201.431
1739.53	201.079
1743.38	201.799
1747.22	203.209
1751.06	206.585
1754.9	210.795
1758.74	212.948
1762.58	213.506
1766.41	213.457
1770.25	212.755
1774.08	211.397
1777.91	210.077
1781.73	208.265
1785.56	206.27
1789.39	204.47
1793.21	203.596
1797.03	203.251
1800.85	204.629
1804.67	207.097
1808.48	210.239
1812.3	212.099
1816.11	214.745
1819.92	216.256
1823.73	216.863
1827.54	216.213
1831.34	216.437
1835.14	214.486
1838.95	210.319
1842.75	209.145
1846.55	213.598
1850.34	219.277
1854.14	223.318
1857.93	225.732
1861.72	227.382
1865.51	228.392
1869.3	228.732
1873.09	228.448
1876.87	227.815
1880.66	229.13
1884.44	224.58
1888.22	223.729
1892	233.704
1895.77	232.389
1899.55	231.295
1903.32	227.825
1907.09	226.35
1910.86	226.582
1914.63	227.815
1918.4	229.666
1922.16	231.116
1925.92	232.593
1929.68	232.185
1933.44	232.574
1937.2	230.442
1940.96	231.277
1944.71	231.846
1948.46	230.927
1952.22	231.978
1955.97	233.974
1959.71	235.693
1963.46	238.247
1967.2	239.502
1970.95	239.917
1974.69	240.015
1978.43	239.264
1982.17	238.509
1985.9	238.024
1989.64	237.988
1993.37	238.651
1997.1	239.654
2000.83	241.021
2004.56	242.829
2008.28	245.055
2012.01	247.483
2015.73	249.997
2019.45	251.855
2023.17	253.947
2026.89	254.502
2030.6	255.41
2034.32	255.396
2038.03	254.822
2041.74	253.38
2045.45	251.779
2049.16	250.613
2052.87	249.358
2056.57	248.26
2060.27	248.288
2063.98	249.992
2067.67	253.666
2071.37	258.346
2075.07	262.227
2078.76	264.147
2082.46	264.331
2086.15	263.901
2089.84	263.039
2093.53	261.738
2097.21	259.447
2100.9	257.504
2104.58	258.363
2108.26	260.902
2111.94	264.03
2115.62	267.829
2119.3	270.763
2122.97	273.151
2126.64	274.088
2130.32	273.84
2133.99	274.395
2137.66	274.874
2141.32	272.662
2144.99	271.878
2148.65	273.134
2152.31	277.198
2155.97	278.702
2159.63	278.841
2163.29	279.552
2166.94	280.187
2170.6	280.561
2174.25	280.516
2177.9	280.39
2181.55	279.832
2185.2	279.328
2188.84	279.28
2192.49	279.56
2196.13	280.013
2199.77	280.609
2203.41	280.982
2207.05	281.135
2210.69	281.092
2214.32	280.87
2217.95	280.616
2221.59	280.495
2225.22	280.554
2228.84	280.863
2232.47	281.066
2236.09	281.752
2239.72	283.426
2243.34	285.675
2246.96	287.824
2250.58	290.008
2254.2	292.062
2257.81	293.677
2261.42	294.237
2265.04	294.037
2268.65	293.585
2272.26	293.209
2275.86	292.818
2279.47	292.222
2283.08	291.649
2286.68	291.318
2290.28	291.145
2293.88	291.072
2297.48	292.437
2301.07	295.209
2304.67	293.864
2308.26	294.599
2311.85	304.953
2315.44	329.602
2319.03	539
2322.62	547
2326.2	343.132
2329.79	314.302
2333.37	307.887
2336.95	305.488
2340.53	306.435
2344.11	306.477
2347.68	309.144
2351.26	311.197
2354.83	314.319
2358.4	316.658
2361.97	317.463
2365.54	317.632
2369.11	317.068
2372.67	316.858
2376.23	317.24
2379.8	317.445
2383.36	318.743
2386.92	320.779
2390.47	323.08
2394.03	324.764
2397.58	326.128
2401.14	327.019
2404.69	327.585
2408.24	327.869
2411.78	327.756
2415.33	326.212
2418.88	325.881
2422.42	326.814
2425.96	328.851
2429.5	331.31
2433.04	333.58
2436.58	335
2440.11	334.429
2443.65	332.568
2447.18	327.704
2450.71	325.338
2454.24	324.368
2457.77	324.209
2461.3	324.934
2464.82	326.361
2468.34	327.972
2471.86	329.217
2475.39	330.385
2478.9	330.277
2482.42	330.125
2485.94	330.578
2489.45	331.66
2492.96	333.232
2496.47	335.155
2499.98	337.791
2503.49	341.866
2507	344.654
2510.5	345.24
2514.01	344.742
2517.51	343.566
2521.01	342.187
2524.51	340.431
2528.01	339.867
2531.5	340.466
2535	345.951
2538.49	352.906
2541.98	356.747
2545.47	359.335
2548.96	359.806
2552.45	359.103
2555.93	355.749
2559.42	352.898
2562.9	346.031
2566.38	345.473
2569.86	347.286
2573.34	348.414
2576.81	348.096
2580.29	346.085
2583.76	344.738
2587.23	343.907
2590.71	343.9
2594.17	346.1
2597.64	347.839
2601.11	348.461
2604.57	349.29
2608.03	349.611
2611.5	354.423
2614.96	353.241
2618.42	348.405
2621.87	344.845
2625.33	334.505
2628.78	355.493
2632.23	364.188
2635.68	365.144
2639.13	362.75
2642.58	360.965
2646.03	361.313
2649.47	362.708
2652.92	365.705
2656.36	367.641
2659.8	367.5
2663.24	367.286
2666.68	365.96
2670.11	365.517
2673.55	364.568
2676.98	363.674
2680.41	363.577
2683.84	365.268
2687.27	368.908
2690.7	371.305
2694.13	373.372
2697.55	375.155
2700.97	376.2
2704.4	377.108
2707.82	377.599
2711.23	378.75
2714.65	379.503
2718.07	378.927
2721.48	377.861
2724.9	371.42
2728.31	368.305
2731.72	367.517
2735.12	366.379
2738.53	365.032
2741.94	365.976
2745.34	370.394
2748.74	366.888
2752.14	363.442
2755.54	362.621
2758.94	364.676
2762.34	373.027
2765.73	379.277
2769.13	380.363
2772.52	378.716
2775.91	378.436
2779.3	379.211
2782.69	380.456
2786.08	382.212
2789.46	383.802
2792.85	386.036
2796.23	387.228
2799.61	388.641
2802.99	389.721
2806.37	390.105
2809.74	390.256
2813.12	390.691
2816.49	391.529
2819.86	392.802
2823.23	393.216
2826.61	393.32
2829.97	393.021
2833.34	392.795
2836.7	392.63
2840.07	393.124
2843.43	394.056
2846.79	395.298
2850.15	401.425
2853.51	403.459
2856.87	403.928
2860.22	403.177
2863.57	401.366
2866.93	400.191
2870.28	398.566
2873.63	400.676
2876.98	398.428
2880.32	396.658
2883.67	396.263
2887.01	395.739
2890.35	396.67
2893.69	392.379
2897.03	396.304
2900.37	400.754
2903.71	407.363
2907.04	415.058
2910.38	413.345
2913.71	405.467
2917.04	400.281
2920.37	397.39
2923.7	395.327
2927.03	394.301
2930.35	396.927
2933.68	399.372
2937	402.453
2940.32	405.235
2943.64	405.913
2946.96	406.346
2950.27	407.997
2953.59	410.412
2956.91	413.33
2960.22	415.523
2963.53	417.875
2966.84	419.467
2970.15	422.632
2973.46	423.307
2976.76	422.355
2980.07	420.541
2983.37	417.129
2986.67	413.614
2989.97	411.112
2993.27	408.95
2996.57	408.385
2999.86	409.735
3003.16	413.511
3006.45	416.693
3009.75	420.41
3013.03	424.305
3016.32	427.208
3019.61	426.937
3022.9	425.663
3026.19	425.103
3029.47	422.682
3032.75	420.861
3036.03	422.448
3039.31	425.343
3042.59	428.735
3045.87	432.89
3049.14	437.49
3052.42	442.398
3055.69	445.806
3058.96	449.746
3062.23	454.521
3065.5	452.624
3068.77	447.429
3072.03	441.423
3075.3	439.315
3078.56	440.883
3081.82	446.173
3085.08	453.543
3088.34	458.562
3091.6	465.106
3094.86	471.941
3098.11	473.128
3101.36	474.374
3104.62	472.469
3107.87	475.992
3111.12	478.168
3114.37	481.475
3117.61	485.849
3120.86	489.918
3124.1	492.606
3127.34	494.465
3130.59	494.744
3133.83	492.886
3137.07	495.874
3140.3	508.367
3143.54	515.717
3146.77	518.444
3150.01	519.809
3153.24	520.855
3156.47	522.076
3159.7	524.311
3162.93	526.502
3166.15	528.876
3169.38	531.536
3172.6	538.252
3175.83	546.196
3179.05	555.54
3182.27	563.804
3185.49	570.992
3188.7	577.915
3191.92	584.629
3195.13	589.733
3198.35	593.121
3201.56	597.249
3204.77	603.501
3207.98	611.469
3211.19	621.145
3214.39	632.404
3217.6	645.235
3220.8	656.877
3224	667.208
3227.21	675.174
3230.41	678.929
3233.6	683.499
3236.8	691.305
3240	701.027
3243.19	712.27
3246.39	726.617
3249.58	740.503
3252.77	754.336
3255.96	766.07
3259.15	776.623
3262.33	785.533
3265.52	792.348
3268.7	797.429
3271.89	800.06
3275.07	807.63
3278.25	815.746
3281.43	824.898
3284.6	832.975
3287.78	837.857
3290.95	841.283
3294.13	842.693
3297.3	843.035
3300.47	839.172
3303.64	834.021
3306.81	841.625
3309.98	844.402
3313.14	846.288
3316.31	847.907
3319.47	851.971
3322.63	856.871
3325.79	862.619
3328.95	868.891
3332.11	872.254
3335.27	876.591
3338.42	886.524
3341.58	903.06
3344.73	916.927
3347.88	927.582
3351.03	937.103
3354.18	945.118
3357.33	953.306
3360.47	961.717
3363.62	972.3
3366.76	995.756
3369.91	1005.33
3373.05	1017.75
3376.19	1028.83
3379.32	1045.06
3382.46	1062.77
3385.6	1088.76
3388.73	1124.8
3391.87	1159.11
3395	1190.68
3398.13	1223.87
3401.26	1250.12
3404.39	1266.57
3407.51	1275.32
3410.64	1274.15
3413.76	1268.66
3416.89	1244.25
3420.01	1218.73
3423.13	1197.66
3426.25	1180.96
3429.37	1174.93
3432.48	1169.91
3435.6	1167.56
3438.71	1169.43
3441.83	1174.35
3444.94	1184.54
3448.05	1199.68
3451.16	1217.19
3454.27	1230.54
3457.37	1245.9
3460.48	1268.7
3463.58	1297.29
3466.69	1340.84
3469.79	1385.4
3472.89	1425.18
3475.99	1452.71
3479.08	1472.67
3482.18	1478.96
3485.28	1473.23
3488.37	1459.71
3491.46	1445.39
3494.55	1429.55
3497.64	1410.99
3500.73	1389.58
3503.82	1359.24
3506.91	1319.63
3509.99	1270.68
3513.08	1231.57
3516.16	1221.16
3519.24	1191.12
3522.32	1152.05
3525.4	1106.94
3528.48	1060.37
3531.55	1022.32
3534.63	989.897
3537.7	961.559
3540.78	939.183
3543.85	922.582
3546.92	910.284
3549.99	906.454
3553.05	906.373
3556.12	900.037
3559.19	887.006
3562.25	869.382
3565.31	849.702
3568.37	824.94
3571.43	797.668
3574.49	769.069
3577.55	741.243
3580.61	717.81
3583.66	713.379
3586.72	706.99
3589.77	702.708
3592.82	702.477
3595.87	700.776
3598.92	691.657
3601.97	680.915
3605.02	669.956
3608.06	667.14
3611.11	664.696
3614.15	665.638
3617.19	661.875
3620.23	658.892
3623.27	656.659
3626.31	647.465
3629.34	638.438
3632.38	626.805
3635.41	616.813
3638.45	606.788
3641.48	597.056
3644.51	586.631
3647.54	575.792
3650.57	563.703
3653.59	549.051
3656.62	535.875
3659.65	520.933
3662.67	509.928
3665.69	499.503
3668.71	483.769
3671.73	486.556
3674.75	486.25
3677.77	473.199
3680.78	461.375
3683.8	451.954
3686.81	443.22
3689.82	436.622
3692.84	431.213
3695.84	426.707
3698.85	422.66
3701.86	419.346
3704.87	417.21
3707.87	413.957
3710.88	408.935
3713.88	403.202
3716.88	401.214
3719.88	399.354
3722.88	396.982
3725.88	395.679
3728.88	395.23
3731.87	389.888
3734.87	392.543
3737.86	394.178
3740.85	395.095
3743.84	393.176
3746.83	389.583
3749.82	379.366
3752.81	373.417
3755.79	371.966
3758.78	377.465
3761.76	382.997
3764.74	389.102
3767.73	388.03
3770.71	385.187
3773.68	380.11
3776.66	373.761
3779.64	368.746
3782.61	364.847
3785.59	359.557
3788.56	359.622
3791.53	361.903
3794.5	365.572
3797.47	368.878
3800.44	371.507
3803.41	371.573
3806.37	369.781
3809.34	370.457
3812.3	371.16
3815.26	371.328
3818.22	371.229
3821.18	370.648
3824.14	369.564
3827.1	367.426
3830.06	364.81
3833.01	360.533
3835.96	357.124
3838.92	355.518
3841.87	355.941
3844.82	357.99
3847.77	360.858
3850.72	361.848
3853.66	362.652
3856.61	361.429
3859.55	358.911
3862.5	355.811
3865.44	353.189
3868.38	351.536
3871.32	350.643
3874.26	351.729
3877.2	354.856
3880.13	357.729
3883.07	358.967
3886	360.236
3888.94	359.413
3891.87	357.632
3894.8	354.105
3897.73	349.85
3900.66	346.261
3903.58	345.693
3906.51	346.842
3909.43	348.787
3912.36	350.636
3915.28	354.282
3918.2	353.591
3921.12	351.975
3924.04	348.352
3926.96	346.817
3929.87	347.926
3932.79	353.723
3935.7	356.375
3938.62	355.426
3941.53	350.5
3944.44	344.265
3947.35	341.948
3950.26	341.376
3953.17	342.1
3956.07	344.208
3958.98	345.968
3961.88	346.122
3964.78	345.359
3967.69	344.507
3970.59	344.866
3973.49	343.943
3976.38	342.233
3979.28	339.243
3982.18	337.039
3985.07	337.784
3987.97	339.534
3990.86	342.273
3993.75	345.378
3996.64	344.216
3999.53	341.781
4002.42	338.748
4005.3	336.354
4008.19	335.671
4011.07	335.42
4013.96	336.969
4016.84	340.418
4019.72	342.784
4022.6	344.209
4025.48	345.122
4028.36	345.135
4031.23	344.307
4034.11	342.601
4036.98	339.522
4039.86	336.887
4042.73	334.751
4045.6	333.283
4048.47	332.353
4051.34	332.47
4054.21	332.96
4057.07	332.953
4059.94	331.321
4062.8	329.5
4065.67	329.351
4068.53	329.873
4071.39	330.651
4074.25	334.407
4077.11	336.974
4079.97	337.875
4082.82	337.016
4085.68	333.934
4088.53	330.349
4091.39	326.998
4094.24	323.514
4097.09	322.622
4099.94	324.085
4102.79	325.151
4105.63	326.115
4108.48	325.798
4111.33	324.831
4114.17	323.641
4117.01	322.041
4119.86	320.466
4122.7	319.551
4125.54	317.398
4128.38	315.399
4131.21	314.574
4134.05	310.975
4136.88	310.229
4139.72	307.565
4142.55	309.65
4145.38	311.56
4148.21	313.756
4151.04	315.558
4153.87	315.653
4156.7	316.773
4159.53	317.947
4162.35	319.561
4165.18	321.27
4168	322.226
4170.82	321.91
4173.64	319.306
4176.46	315.173
4179.28	309.407
4182.1	307.512
4184.91	307.268
4187.73	308.721
4190.55	311.607
4193.36	316.327
4196.17	319.988
4198.98	318.477
4201.79	315.907
4204.6	315.239
4207.41	308.539
4210.21	305.215
4213.02	305.836
4215.82	308.169
4218.63	309.873
4221.43	311.009
4224.23	309.771
4227.03	307.48
4229.83	304.968
4232.63	302.18
4235.43	300.177
4238.22	298.927
4241.02	298.351
4243.81	297.907
4246.6	299.054
4249.4	301.005
4252.19	303.117
4254.98	305.5
4257.76	309.221
4260.55	308.592
4263.34	301.836
4266.12	294.271
4268.91	292.396
4271.69	291.261
4274.47	290.492
4277.25	290.248
4280.03	290.466
4282.81	290.964
4285.59	290.593
4288.36	289.947
4291.14	289.324
4293.91	288.768
4296.69	288.516
4299.46	288.328
4302.23	286.982
4305	285.957
4307.77	286.07
4310.54	284.36
4313.3	282.145
4316.07	282.409
4318.83	283.472
4321.6	283.711
4324.36	282.535
4327.12	281.816
4329.88	279.954
4332.64	277.751
4335.4	276.524
4338.16	277.409
4340.91	278.799
4343.67	279.962
4346.42	280.918
4349.18	281.117
4351.93	281.432
4354.68	280.183
4357.43	278.865
4360.18	276.887
4362.93	275.511
4365.67	275.419
4368.42	275.968
4371.16	279.734
4373.91	279.728
4376.65	278.369
4379.39	275.356
4382.13	273.438
4384.87	271.693
4387.61	270.873
4390.34	271.289
4393.08	272.45
4395.82	271.23
4398.55	271.336
4401.28	273.307
4404.02	276.593
4406.75	276.052
4409.48	274.936
4412.21	272.984
4414.93	271.281
4417.66	270.467
4420.38	270.059
4423.11	271.678
4425.83	272.189
4428.56	273.446
4431.28	274.444
4434	272
4436.72	271.142
4439.44	271.829
4442.15	273.397
4444.87	273.895
4447.58	272.457
4450.3	268.494
4453.01	266.032
4455.72	264.48
4458.44	262.23
4461.15	260.508
4463.86	261.464
4466.56	260.858
4469.27	260.393
4471.98	259.522
4474.68	257.991
4477.39	257.393
4480.09	257.342
4482.79	257.529
4485.49	258.587
4488.19	259.889
4490.89	261.074
4493.59	262.321
4496.28	262.352
4498.98	261.565
4501.67	261.435
4504.37	260.102
4507.06	257.802
4509.75	255.912
4512.44	253.532
4515.13	253.975
4517.82	254.258
4520.51	252.629
4523.2	251.082
4525.88	247.793
4528.56	243.655
4531.25	243.273
4533.93	243.443
4536.61	244.444
4539.29	246.089
4541.97	248.412
4544.65	249.006
4547.33	249.002
4550	248.317
4552.68	247.619
4555.35	247.428
4558.03	248.013
4560.7	247.941
4563.37	247.428
4566.04	246.722
4568.71	245.839
4571.38	244.678
4574.05	243.558
4576.71	241.253
4579.38	239.029
4582.04	238.195
4584.7	238.788
4587.37	240.554
4590.03	238.764
4592.69	237.853
4595.35	239.817
4598	239.298
4600.66	236.463
4603.32	236.854
4605.97	237.488
4608.63	222.416
4611.28	236.613
4613.93	237.026
4616.58	235.258
4619.23	234.17
4621.88	233.846
4624.53	231.494
4627.18	232.858
4629.82	228.95
4632.47	228.307
4635.11	228.192
4637.76	229.826
4640.4	229.622
4643.04	229.293
4645.68	229.514
4648.32	229.784
4650.96	229.111
4653.59	227.146
4656.23	225.914
4658.86	226.26
4661.5	224.943
4664.13	223.2
4666.76	221.293
4669.4	220.129
4672.03	219.35
4674.65	218.889
4677.28	219.159
4679.91	219.033
4682.54	217.337
4685.16	215.955
4687.79	214.85
4690.41	213.8
4693.03	214.432
4695.65	215.315
4698.27	217.204
4700.89	218.741
4703.51	219.206
4706.13	218.911
4708.75	218.194
4711.36	216.83
4713.97	215.281
4716.59	213.717
4719.2	212.072
4721.81	210.453
4724.42	208.633
4727.03	207.675
4729.64	209.893
4732.25	208.367
4734.85	206.486
4737.46	205.34
4740.06	204.906
4742.67	205.202
4745.27	206.197
4747.87	207.193
4750.47	208.037
4753.07	208.637
4755.67	210.879
4758.27	212.863
4760.87	214.412
4763.46	214.522
4766.06	213.911
4768.65	212.981
4771.25	212.065
4773.84	209.946
4776.43	207.857
4779.02	206.63
4781.61	205.726
4784.2	205.421
4786.78	204.351
4789.37	203.653
4791.96	204.052
4794.54	206.017
4797.12	206.661
4799.71	206.125
4802.29	204.84
4804.87	204.077
4807.45	190.657
4810.02	197.858
4812.6	200.95
4815.18	201.061
4817.76	200.494
4820.33	200.106
4822.9	200.681
4825.48	201.318
4828.05	201.116
4830.62	200.88
4833.19	199.442
4835.76	196.638
4838.33	194.499
4840.89	193.17
4843.46	192.445
4846.02	192.931
4848.59	194.96
4851.15	197.595
4853.71	198.177
4856.27	198.259
4858.83	198.114
4861.39	195.642
4863.95	192.887
4866.51	190.667
4869.07	188.765
4871.62	187.178
4874.18	186.166
4876.73	185.221
4879.28	184.066
4881.84	183.618
4884.39	184.139
4886.94	185.168
4889.49	185.865
4892.03	186.737
4894.58	187.403
4897.13	187.136
4899.67	188.444
4902.22	190.253
4904.76	191.435
4907.3	190.526
4909.84	187.096
4912.38	182.709
4914.92	181.901
4917.46	181.5
4920	182.771
4922.54	183.68
4925.07	184.986
4927.61	187.374
4930.14	186.798
4932.68	186.287
4935.21	185.806
4937.74	185.587
4940.27	184.637
4942.8	183.289
4945.33	181.835
4947.85	182.017
4950.38	185.486
4952.91	187.29
4955.43	187.693
4957.96	185.371
4960.48	180.579
4963	181.268
4965.52	180.044
4968.04	178.265
4970.56	178.72
4973.08	180.275
4975.59	183.109
4978.11	184.504
4980.63	183.281
4983.14	180.589
4985.66	176.823
4988.17	173.716
4990.68	172.025
4993.19	172.552
4995.7	168.833
4998.21	161.017