File: Data/3-Raman/raw/32-C_FF1_FI06.txt
#Acq. time (s)=	15
#Accumulations=	3
#Range (cm-¹)=	50...5000
#Windows=	1
#Auto scanning=	Off
#Autofocus=	Off
#Macrospot=	Off
#AutoExposure=	Off
#Spike filter=	Multiple accum.
#Delay time (s)=	0
#Binning=	1
#Readout mode=	Signal
#DeNoise=	Lite
#ICS correction=	Off
#Dark correction=	Off
#Inst. Process=	Off
#Detector temperature (°C)=	-60.09
#Instrument=	LabRAM HR Evol
#Detector=	SIN-EM FIVIS
#Objective=	x100_VIS
#Grating=	150 (500nm)
#ND Filter=	100%
#Laser=	532nm_Edge
#Hole=	30.0125
#Temperature=	0
#Range=	Visible
#StageXY=	75x50mm Scan+
#StageZ=	Z motor
#X (µm)=	17768.7
#Y (µm)=	4080.4
#Z (µm)=	-412.2
#Full time(s)=	47
#Project=	Buranga
#Sample=	BU18FA32_C
#Site=	C_FF1
#Title=	32-C_FF1_FI06
#Remark=
#Date=	09.07.2019 16:54
#Acquired=	09.07.2019 16:54:49
52.2859	15234.4
56.9342	12708.6
61.5802	10614.6
66.2217	8973.41
70.8631	7682.54
75.5021	6548.09
80.1389	5531.99
84.7734	4619.08
89.4056	3829.69
94.0333	3161.35
98.6609	2621.92
103.286	2177.11
107.909	1794.3
112.53	1526.02
117.146	1320.25
121.762	1195.5
126.376	1106.84
130.988	1115.49
135.595	1130.36
140.202	1103.48
144.807	1053.09
149.41	1063.06
154.008	1367
158.606	2419
163.201	3133
167.795	1820
172.384	1061.49
176.973	835
181.559	814.186
186.142	785
190.724	863.294
195.304	912.471
199.881	1017.58
204.454	1153.16
209.028	1250.71
213.598	1260.74
218.165	1182.93
222.731	1006.03
227.295	984.157
231.855	1113.04
236.415	1250.36
240.972	1494.76
245.525	1425.19
250.078	1173.35
254.629	1138.36
259.175	1240.5
263.722	1310.37
268.264	1285.85
272.805	1189.55
277.345	1103.61
281.88	1043
286.415	1024.09
290.948	1027.64
295.477	1243.91
300.005	1389
304.529	1554.36
309.053	1361.11
313.575	1183.38
318.093	1070.06
322.61	1014.34
327.123	1034.1
331.636	1067.01
336.145	1203.16
340.653	1453.95
345.157	1816.16
349.662	1960.38
354.164	1603
358.661	1201.96
363.159	1039.3
367.652	923.339
372.145	854.063
376.634	830.698
381.123	847.612
385.608	910.236
390.092	982.938
394.572	1178.81
399.052	1380.31
403.528	1578.72
408.004	1754.59
412.475	1903.14
416.947	2041.56
421.414	2142.86
425.881	2243.83
430.343	2382.21
434.806	2409.09
439.264	2171.04
443.723	1956.74
448.177	1990.36
452.629	2301.07
457.081	2595.01
461.528	2227.24
465.976	1752.38
470.419	1406.96
474.862	1240.75
479.301	1208.25
483.738	1309.58
488.175	1544.4
492.607	1849
497.04	2311.12
501.468	2781.87
505.894	3232.02
510.32	3597.59
514.742	3873.21
519.164	4038.2
523.581	4069.38
527.997	3949.25
532.412	3724.54
536.823	3454.42
541.232	3481.93
545.641	3567.62
550.046	3577.26
554.449	3542.24
558.851	3285.84
563.25	2991.34
567.646	2668.08
572.042	2380.1
576.434	2319.72
580.824	2441.09
585.214	2771.58
589.599	3212.83
593.983	3505.81
598.367	3166.96
602.746	2617.93
607.123	2194
611.498	1883.08
615.873	1644.62
620.244	1454.16
624.613	1317.2
628.98	1224.16
633.346	1163.87
637.709	1151.98
642.069	1195.2
646.428	1290.38
650.786	1440.38
655.14	1574.67
659.492	1436.92
663.842	1263.68
668.192	1075.49
672.538	897.793
676.882	797.082
681.223	701.119
685.563	640.425
689.902	612.773
694.238	617.365
698.571	635.182
702.902	652.771
707.231	662.262
711.559	644.963
715.886	619.456
720.209	593.622
724.529	570.846
728.848	559.953
733.165	551.764
737.48	547.76
741.792	546.117
746.105	546.063
750.413	545.994
754.72	542.842
759.024	539.955
763.327	533.25
767.627	525.731
771.925	518.004
776.221	510.451
780.518	503.151
784.81	495.844
789.1	488.289
793.388	480.56
797.674	473.562
801.958	468.253
806.24	464.89
810.52	462.71
814.797	464.378
819.073	468.313
823.347	473.75
827.619	479.836
831.888	481.616
836.156	480.244
840.422	477.866
844.685	477.498
848.947	480.06
853.206	485.259
857.464	492.208
861.719	499.774
865.973	506.157
870.224	511.917
874.474	517.183
878.721	521.886
882.967	526.896
887.21	532.451
891.452	539.2
895.691	548.177
899.929	563.452
904.164	585.788
908.397	615.585
912.629	659.024
916.858	722.179
921.086	806.984
925.311	912.743
929.534	1040.67
933.756	1191.99
937.975	1366.25
942.191	1568.14
946.406	1807.32
950.619	2087.54
954.831	2410.59
959.04	2781.68
963.248	3168.12
967.453	3691.84
971.657	4409.28
975.858	4876.03
980.056	4487
984.253	3655
988.449	3041.26
992.643	2775.99
996.834	2894.77
1001.02	3453.26
1005.21	4396.98
1009.4	5725.88
1013.58	6887
1017.76	7225
1021.94	6892.24
1026.12	6324.02
1030.29	5612.94
1034.47	4833.22
1038.64	3882.19
1042.81	3088.62
1046.98	2535.67
1051.14	2247.68
1055.3	2192.77
1059.47	2320.55
1063.63	2617
1067.78	2791.76
1071.94	2783.3
1076.09	2582.94
1080.25	2299.11
1084.4	1965
1088.54	1817.57
1092.69	1746.85
1096.83	1754.99
1100.98	1963.91
1105.12	2208.03
1109.26	2396
1113.39	2192.69
1117.53	1831.9
1121.66	1464.74
1125.79	1238.1
1129.92	1013.33
1134.04	871
1138.17	867.374
1142.29	831.917
1146.41	767.625
1150.53	707.656
1154.65	657.115
1158.76	618.197
1162.88	587.246
1166.99	563.45
1171.1	545.719
1175.2	532.03
1179.31	522.253
1183.41	516.997
1187.51	509.735
1191.61	501.305
1195.71	495.322
1199.81	491.579
1203.9	490.321
1207.99	490.237
1212.08	489.782
1216.17	491.409
1220.26	496.431
1224.34	494.217
1228.42	496.44
1232.5	488.76
1236.58	485.27
1240.66	500.018
1244.73	527.635
1248.81	604.305
1252.88	684.039
1256.95	640.531
1261.02	588
1265.08	605
1269.14	1266
1273.2	3181
1277.27	1781
1281.32	711
1285.38	548.065
1289.43	536.503
1293.48	520.025
1297.53	516.191
1301.58	513.425
1305.63	510.936
1309.67	508.894
1313.72	507.088
1317.76	505.716
1321.8	504.929
1325.83	504.978
1329.87	506.275
1333.9	508.502
1337.93	512.824
1341.96	519.613
1345.99	529.388
1350.02	544.048
1354.04	558.437
1358.06	600.135
1362.08	628.471
1366.1	639.644
1370.12	768.972
1374.13	2498
1378.14	5396
1382.16	1936
1386.16	755
1390.17	620
1394.18	674
1398.18	875
1402.18	754
1406.18	550.087
1410.18	506.592
1414.18	490.261
1418.17	477.698
1422.16	469.091
1426.15	465.063
1430.14	461.924
1434.13	458.942
1438.11	456.507
1442.1	454.068
1446.08	451.817
1450.06	448.682
1454.04	437.564
1458.01	430.938
1461.98	428.637
1465.96	428.761
1469.93	431.972
1473.9	438.288
1477.86	440.735
1481.83	439.282
1485.79	438.106
1489.75	435.476
1493.71	433.4
1497.67	434.171
1501.62	434.736
1505.58	435.13
1509.53	436.704
1513.48	434.135
1517.43	426.954
1521.38	425.776
1525.32	426.591
1529.26	429.142
1533.2	435.071
1537.14	439.39
1541.08	443.066
1545.02	444.083
1548.95	445.167
1552.88	446.112
1556.81	447.277
1560.74	448.363
1564.67	449.366
1568.6	450.262
1572.52	451.058
1576.44	451.693
1580.36	451.971
1584.28	451.742
1588.19	452.257
1592.11	452.902
1596.02	453.696
1599.93	453.894
1603.84	453.345
1607.75	451.988
1611.65	451.559
1615.56	450.87
1619.46	459.296
1623.36	463.954
1627.25	459.9
1631.15	455.043
1635.05	453.402
1638.94	455.048
1642.83	457.47
1646.72	461.597
1650.61	464.264
1654.49	465.323
1658.38	465.764
1662.26	465.021
1666.14	463.996
1670.02	461.753
1673.89	459.742
1677.77	459.711
1681.64	459.733
1685.51	462.108
1689.38	465.876
1693.25	472.333
1697.12	477.537
1700.98	481.689
1704.85	484.942
1708.71	486.019
1712.57	484.294
1716.42	482.629
1720.28	483.277
1724.13	484.448
1727.99	486.064
1731.84	488.008
1735.69	489.964
1739.53	491.654
1743.38	493.091
1747.22	494.722
1751.06	496.403
1754.9	497.187
1758.74	497.227
1762.58	496.605
1766.41	496.095
1770.25	494.548
1774.08	492.947
1777.91	490.428
1781.73	488.73
1785.56	486.925
1789.39	489.672
1793.21	490.721
1797.03	492.494
1800.85	492.265
1804.67	490.291
1808.48	487.392
1812.3	484.969
1816.11	483.032
1819.92	481.817
1823.73	483.974
1827.54	486.422
1831.34	491.589
1835.14	498.651
1838.95	504.777
1842.75	509.543
1846.55	512.141
1850.34	514.245
1854.14	514.351
1857.93	515.739
1861.72	518.633
1865.51	520.507
1869.3	522.876
1873.09	524.121
1876.87	526.042
1880.66	530.85
1884.44	534.724
1888.22	537.956
1892	540.242
1895.77	540.178
1899.55	539.031
1903.32	535.626
1907.09	533.778
1910.86	533.423
1914.63	534.488
1918.4	537.767
1922.16	539.076
1925.92	540.043
1929.68	539.271
1933.44	537.699
1937.2	534.35
1940.96	531.279
1944.71	528.996
1948.46	527.615
1952.22	527.24
1955.97	527.785
1959.71	529.163
1963.46	532.723
1967.2	538.389
1970.95	543.077
1974.69	546.037
1978.43	546.573
1982.17	545.908
1985.9	545.063
1989.64	545.33
1993.37	546.474
1997.1	548.653
2000.83	552.405
2004.56	557.488
2008.28	561.941
2012.01	565.6
2015.73	568.018
2019.45	570.025
2023.17	573.165
2026.89	576.057
2030.6	578.385
2034.32	580.282
2038.03	581.721
2041.74	581.592
2045.45	581.36
2049.16	582.225
2052.87	583.889
2056.57	586.09
2060.27	589.031
2063.98	591.006
2067.67	590.614
2071.37	590.031
2075.07	588.287
2078.76	586.701
2082.46	584.73
2086.15	584.384
2089.84	587.311
2093.53	596.308
2097.21	599.73
2100.9	598.321
2104.58	596.551
2108.26	595.26
2111.94	594.699
2115.62	594.84
2119.3	597.07
2122.97	600.173
2126.64	603.316
2130.32	607.67
2133.99	611.221
2137.66	612.417
2141.32	610.687
2144.99	609.277
2148.65	608.599
2152.31	608.72
2155.97	611.823
2159.63	615.357
2163.29	619.172
2166.94	622.35
2170.6	623.498
2174.25	618.436
2177.9	626.252
2181.55	629.077
2185.2	626.069
2188.84	624.207
2192.49	620.679
2196.13	620.068
2199.77	621.118
2203.41	622.739
2207.05	626.053
2210.69	631.784
2214.32	638.116
2217.95	644.259
2221.59	644.63
2225.22	644.931
2228.84	643.026
2232.47	639.815
2236.09	640.414
2239.72	638.122
2243.34	633.873
2246.96	631.922
2250.58	631.848
2254.2	633.943
2257.81	638.448
2261.42	648.375
2265.04	653.117
2268.65	653.671
2272.26	650.937
2275.86	647.735
2279.47	644.698
2283.08	642.543
2286.68	641.343
2290.28	641.063
2293.88	641.366
2297.48	641.154
2301.07	641.309
2304.67	637.417
2308.26	647.92
2311.85	654.077
2315.44	700.733
2319.03	787.643
2322.62	734.129
2326.2	678.118
2329.79	657.586
2333.37	657.9
2336.95	660.526
2340.53	662.533
2344.11	665.895
2347.68	670.035
2351.26	673.756
2354.83	671.201
2358.4	666.891
2361.97	667.978
2365.54	669.563
2369.11	671.649
2372.67	674.552
2376.23	678.301
2379.8	681.797
2383.36	686.574
2386.92	691.111
2390.47	692.143
2394.03	691.054
2397.58	691.456
2401.14	690.455
2404.69	693.075
2408.24	693.755
2411.78	693.157
2415.33	691.951
2418.88	691.099
2422.42	689.457
2425.96	688.156
2429.5	688.618
2433.04	690.449
2436.58	692.653
2440.11	694.647
2443.65	696.224
2447.18	697.09
2450.71	697.893
2454.24	698.474
2457.77	698.92
2461.3	699.136
2464.82	699.265
2468.34	699.366
2471.86	700.684
2475.39	702.365
2478.9	701.628
2482.42	697.09
2485.94	702.905
2489.45	703.295
2492.96	702.382
2496.47	703.158
2499.98	704.289
2503.49	706.327
2507	709.975
2510.5	714.868
2514.01	716.863
2517.51	717.513
2521.01	717.386
2524.51	718.467
2528.01	730.764
2531.5	744.502
2535	733.146
2538.49	724.813
2541.98	722.229
2545.47	728.584
2548.96	735.053
2552.45	738.479
2555.93	737.722
2559.42	732.707
2562.9	729.444
2566.38	726.834
2569.86	729.238
2573.34	727.945
2576.81	724.338
2580.29	720.139
2583.76	712.87
2587.23	709.128
2590.71	708.457
2594.17	709.563
2597.64	712.273
2601.11	716.064
2604.57	718.328
2608.03	718.394
2611.5	716.793
2614.96	710.651
2618.42	718.187
2621.87	718.557
2625.33	711.618
2628.78	710.108
2632.23	711.06
2635.68	716.968
2639.13	722.637
2642.58	728.071
2646.03	731.89
2649.47	733.229
2652.92	730.304
2656.36	727.703
2659.8	726.436
2663.24	727.099
2666.68	733.131
2670.11	738.964
2673.55	747.526
2676.98	755.224
2680.41	761.07
2683.84	765.266
2687.27	767.389
2690.7	767.352
2694.13	765.84
2697.55	763.427
2700.97	759.07
2704.4	756.219
2707.82	753.345
2711.23	754.859
2714.65	755.009
2718.07	754.457
2721.48	754.592
2724.9	751.835
2728.31	753.499
2731.72	753.712
2735.12	753.82
2738.53	753.89
2741.94	753.998
2745.34	755.367
2748.74	756.026
2752.14	755.405
2755.54	754.293
2758.94	760.345
2762.34	761.241
2765.73	757.92
2769.13	753.108
2772.52	752.605
2775.91	752.948
2779.3	753.868
2782.69	754.488
2786.08	758.385
2789.46	762.87
2792.85	769.576
2796.23	775.554
2799.61	779.316
2802.99	781.649
2806.37	781.175
2809.74	779.019
2813.12	775.474
2816.49	772.164
2819.86	770.56
2823.23	772.626
2826.61	777.853
2829.97	784.178
2833.34	787.496
2836.7	787.757
2840.07	783.826
2843.43	780.03
2846.79	777.353
2850.15	775.1
2853.51	773.23
2856.87	772.051
2860.22	772.717
2863.57	773.731
2866.93	772.858
2870.28	771.628
2873.63	768.052
2876.98	766.328
2880.32	766.464
2883.67	768.396
2887.01	772.236
2890.35	777.614
2893.69	783.554
2897.03	787.424
2900.37	800.868
2903.71	808.334
2907.04	807.857
2910.38	799.336
2913.71	790.105
2917.04	789.287
2920.37	789.138
2923.7	789.229
2927.03	788.963
2930.35	787.658
2933.68	786.732
2937	784.466
2940.32	782.186
2943.64	779.733
2946.96	779.227
2950.27	780.155
2953.59	784.845
2956.91	791.171
2960.22	797.002
2963.53	800.615
2966.84	802.175
2970.15	802.292
2973.46	801.811
2976.76	798.578
2980.07	795.661
2983.37	792.393
2986.67	788.276
2989.97	791.845
2993.27	799.713
2996.57	809.615
2999.86	808.348
3003.16	806.791
3006.45	807.128
3009.75	810.051
3013.03	808.265
3016.32	805.975
3019.61	798.841
3022.9	795.251
3026.19	792.506
3029.47	794.911
3032.75	798.504
3036.03	812.034
3039.31	815.675
3042.59	813.976
3045.87	811.413
3049.14	808.453
3052.42	806.921
3055.69	806.02
3058.96	807.355
3062.23	811.948
3065.5	815.061
3068.77	817.572
3072.03	817.944
3075.3	817.062
3078.56	817.094
3081.82	816.592
3085.08	812.854
3088.34	806.914
3091.6	809.725
3094.86	810.454
3098.11	812.24
3101.36	816.351
3104.62	822.144
3107.87	828.084
3111.12	835.512
3114.37	840.192
3117.61	843.841
3120.86	845.597
3124.1	847.328
3127.34	850.706
3130.59	855.236
3133.83	859.25
3137.07	860.615
3140.3	857.279
3143.54	857.386
3146.77	857.218
3150.01	857.868
3153.24	864.03
3156.47	872.225
3159.7	881.147
3162.93	891.55
3166.15	898.008
3169.38	904.893
3172.6	910.901
3175.83	927.108
3179.05	936.145
3182.27	926.93
3185.49	924.779
3188.7	927
3191.92	938.014
3195.13	953.238
3198.35	968.719
3201.56	986.846
3204.77	1004.3
3207.98	1021.46
3211.19	1019.42
3214.39	1026.44
3217.6	1040.18
3220.8	1061.32
3224	1086.03
3227.21	1111.39
3230.41	1136.47
3233.6	1159.48
3236.8	1182.89
3240	1206.51
3243.19	1230.36
3246.39	1254.53
3249.58	1278.78
3252.77	1304.97
3255.96	1332.51
3259.15	1360.65
3262.33	1385.51
3265.52	1410.14
3268.7	1433.32
3271.89	1458.37
3275.07	1480.44
3278.25	1507.63
3281.43	1524.25
3284.6	1534.34
3287.78	1540.86
3290.95	1529.92
3294.13	1526.77
3297.3	1525.41
3300.47	1522.94
3303.64	1518.9
3306.81	1514.65
3309.98	1505.84
3313.14	1509.93
3316.31	1530.31
3319.47	1522.62
3322.63	1507.69
3325.79	1510.85
3328.95	1524.29
3332.11	1539.06
3335.27	1553.19
3338.42	1567.88
3341.58	1581.4
3344.73	1598.63
3347.88	1617.79
3351.03	1637.49
3354.18	1660.53
3357.33	1689.29
3360.47	1720.77
3363.62	1749.59
3366.76	1767.45
3369.91	1791.12
3373.05	1820.72
3376.19	1856.27
3379.32	1899
3382.46	1957.12
3385.6	2020.76
3388.73	2097.1
3391.87	2179.28
3395	2268.32
3398.13	2354.2
3401.26	2422.66
3404.39	2475.46
3407.51	2515.59
3410.64	2490.97
3413.76	2452.15
3416.89	2399.8
3420.01	2339.85
3423.13	2292.02
3426.25	2259.49
3429.37	2237.22
3432.48	2223.37
3435.6	2225.08
3438.71	2230.66
3441.83	2245.66
3444.94	2261.28
3448.05	2282.42
3451.16	2312.34
3454.27	2352.78
3457.37	2401.28
3460.48	2460.44
3463.58	2536.04
3466.69	2635.99
3469.79	2751.34
3472.89	2850.33
3475.99	2926.73
3479.08	2990.16
3482.18	3025.78
3485.28	3035.28
3488.37	3012.36
3491.46	2977.01
3494.55	2931.84
3497.64	2881.5
3500.73	2839.41
3503.82	2802.02
3506.91	2753.22
3509.99	2697.49
3513.08	2625.76
3516.16	2544.46
3519.24	2427.38
3522.32	2308.9
3525.4	2188.9
3528.48	2070.23
3531.55	1963.65
3534.63	1875.73
3537.7	1799.16
3540.78	1765.36
3543.85	1746.81
3546.92	1739.2
3549.99	1733.22
3553.05	1726.64
3556.12	1718.8
3559.19	1693.4
3562.25	1655.48
3565.31	1608.06
3568.37	1551
3571.43	1485.51
3574.49	1421.33
3577.55	1372.11
3580.61	1346.73
3583.66	1331.52
3586.72	1322.87
3589.77	1321.76
3592.82	1317.88
3595.87	1311.72
3598.92	1303
3601.97	1293.4
3605.02	1278.67
3608.06	1261.05
3611.11	1242.53
3614.15	1223.93
3617.19	1211.62
3620.23	1202.3
3623.27	1191.29
3626.31	1180.48
3629.34	1168.4
3632.38	1155.13
3635.41	1136.71
3638.45	1118.75
3641.48	1100.54
3644.51	1080.94
3647.54	1063.73
3650.57	1042.68
3653.59	1010.68
3656.62	983.885
3659.65	953.961
3662.67	929.613
3665.69	916.958
3668.71	902.202
3671.73	886.609
3674.75	867.964
3677.77	851.707
3680.78	838.391
3683.8	826.441
3686.81	813.708
3689.82	798.572
3692.84	780.203
3695.84	767.531
3698.85	760.008
3701.86	752.572
3704.87	745.227
3707.87	738.24
3710.88	738.96
3713.88	735.647
3716.88	730.072
3719.88	724.896
3722.88	722.122
3725.88	719.66
3728.88	716.629
3731.87	713.01
3734.87	708.685
3737.86	703.6
3740.85	700.064
3743.84	697.279
3746.83	694.752
3749.82	691.704
3752.81	689.025
3755.79	686.727
3758.78	686.843
3761.76	688.613
3764.74	691.186
3767.73	693.239
3770.71	694.744
3773.68	695.328
3776.66	694.399
3779.64	691.198
3782.61	686.428
3785.59	680.281
3788.56	674.475
3791.53	669.716
3794.5	665.797
3797.47	662.679
3800.44	660.513
3803.41	659.816
3806.37	662.367
3809.34	663.026
3812.3	661.457
3815.26	659.373
3818.22	656.54
3821.18	654.478
3824.14	652.619
3827.1	650.117
3830.06	650.05
3833.01	648.821
3835.96	647.14
3838.92	645.308
3841.87	642.979
3844.82	640.083
3847.77	634.716
3850.72	631.206
3853.66	630.829
3856.61	628.578
3859.55	627.803
3862.5	626.542
3865.44	624.039
3868.38	621.793
3871.32	620.769
3874.26	619.93
3877.2	618.984
3880.13	618.342
3883.07	617.46
3886	616.306
3888.94	616.955
3891.87	619.422
3894.8	623.041
3897.73	624.4
3900.66	625.099
3903.58	626.209
3906.51	618.707
3909.43	611.4
3912.36	605.703
3915.28	602.37
3918.2	603.242
3921.12	605.709
3924.04	606.974
3926.96	606.372
3929.87	606.765
3932.79	607.205
3935.7	607.038
3938.62	604.907
3941.53	605.642
3944.44	606.492
3947.35	607.658
3950.26	608.899
3953.17	609.219
3956.07	604.265
3958.98	597.133
3961.88	591.73
3964.78	587.85
3967.69	586.41
3970.59	589.37
3973.49	591.908
3976.38	592.762
3979.28	593.941
3982.18	591.785
3985.07	588.302
3987.97	587.563
3990.86	589.542
3993.75	591.691
3996.64	595.839
3999.53	599.886
4002.42	599.354
4005.3	595.442
4008.19	587.558
4011.07	579.288
4013.96	572.932
4016.84	568.613
4019.72	568.033
4022.6	566.844
4025.48	566.125
4028.36	566.049
4031.23	564.247
4034.11	561.098
4036.98	557.961
4039.86	555.091
4042.73	553.68
4045.6	555.311
4048.47	560.144
4051.34	562.573
4054.21	564.5
4057.07	564.972
4059.94	568.798
4062.8	564.01
4065.67	545.875
4068.53	550.657
4071.39	554.458
4074.25	556.339
4077.11	552.311
4079.97	547.167
4082.82	545.674
4085.68	541.143
4088.53	547.851
4091.39	552.317
4094.24	551.104
4097.09	548.603
4099.94	542.396
4102.79	538.965
4105.63	537.214
4108.48	535.518
4111.33	534.583
4114.17	533.769
4117.01	534.463
4119.86	536.893
4122.7	536.641
4125.54	535.76
4128.38	535.114
4131.21	534.064
4134.05	533.574
4136.88	533.809
4139.72	533.923
4142.55	534.394
4145.38	535.007
4148.21	534.735
4151.04	533.997
4153.87	530.801
4156.7	528.23
4159.53	525.484
4162.35	522.875
4165.18	520.47
4168	519.289
4170.82	519.279
4173.64	521.939
4176.46	522.866
4179.28	520.286
4182.1	516.532
4184.91	513.922
4187.73	512.298
4190.55	511.832
4193.36	512.498
4196.17	514.497
4198.98	516.919
4201.79	519.758
4204.6	519.594
4207.41	517.643
4210.21	514.724
4213.02	511.925
4215.82	508.803
4218.63	506.303
4221.43	504.334
4224.23	501.278
4227.03	500.542
4229.83	502.113
4232.63	505.353
4235.43	506.939
4238.22	506.436
4241.02	503.786
4243.81	497.083
4246.6	494.17
4249.4	492.066
4252.19	492.59
4254.98	492.734
4257.76	495.842
4260.55	495.287
4263.34	493.637
4266.12	491.253
4268.91	488.739
4271.69	484.499
4274.47	481.099
4277.25	478.939
4280.03	479.208
4282.81	482.292
4285.59	483.87
4288.36	481.472
4291.14	476.177
4293.91	470.368
4296.69	468.315
4299.46	466.662
4302.23	468.601
4305	472.66
4307.77	479.846
4310.54	481.445
4313.3	480.85
4316.07	477.672
4318.83	475.927
4321.6	473.277
4324.36	469.84
4327.12	470.419
4329.88	467.151
4332.64	464.573
4335.4	464.185
4338.16	464.796
4340.91	464.001
4343.67	463.239
4346.42	462.227
4349.18	460.106
4351.93	458.322
4354.68	456.854
4357.43	454.911
4360.18	453.117
4362.93	451.642
4365.67	449.75
4368.42	447.525
4371.16	444.698
4373.91	441.91
4376.65	439.195
4379.39	441.714
4382.13	439.77
4384.87	436.955
4387.61	436.99
4390.34	436.859
4393.08	437.41
4395.82	438.542
4398.55	440.207
4401.28	440.501
4404.02	440.389
4406.75	439.419
4409.48	437.505
4412.21	429.546
4414.93	432.292
4417.66	434.805
4420.38	435.564
4423.11	432.915
4425.83	430.14
4428.56	428.086
4431.28	427.829
4434	428.162
4436.72	428.918
4439.44	429.62
4442.15	430.242
4444.87	430.908
4447.58	431.546
4450.3	431.763
4453.01	432.267
4455.72	429.206
4458.44	425.8
4461.15	422.724
4463.86	417.995
4466.56	414.458
4469.27	413.054
4471.98	415.1
4474.68	416.719
4477.39	418.65
4480.09	419.323
4482.79	419.718
4485.49	419.455
4488.19	418.482
4490.89	417.983
4493.59	417.037
4496.28	416.308
4498.98	412.727
4501.67	408.22
4504.37	406.278
4507.06	403.957
4509.75	403.211
4512.44	400.288
4515.13	398.468
4517.82	397.525
4520.51	395.669
4523.2	394.407
4525.88	394.302
4528.56	395.891
4531.25	393.482
4533.93	391.02
4536.61	388.061
4539.29	388.479
4541.97	390.785
4544.65	391.178
4547.33	390.487
4550	389.423
4552.68	388.354
4555.35	387.45
4558.03	386.432
4560.7	385.564
4563.37	384.429
4566.04	383.773
4568.71	383.192
4571.38	381.86
4574.05	380.315
4576.71	377.542
4579.38	374.904
4582.04	373.215
4584.7	371.954
4587.37	371.23
4590.03	370.776
4592.69	370.474
4595.35	370.326
4598	370.424
4600.66	370.967
4603.32	371.166
4605.97	370.919
4608.63	368.507
4611.28	366.152
4613.93	366.716
4616.58	366.469
4619.23	365.278
4621.88	363.317
4624.53	361.767
4627.18	361.488
4629.82	360.786
4632.47	360.091
4635.11	359.087
4637.76	357.918
4640.4	356.508
4643.04	354.712
4645.68	353.064
4648.32	352.875
4650.96	353.293
4653.59	354.527
4656.23	352.976
4658.86	352.59
4661.5	352.271
4664.13	347.046
4666.76	342.053
4669.4	336.549
4672.03	334.554
4674.65	335.147
4677.28	337.315
4679.91	343.425
4682.54	345.494
4685.16	345.847
4687.79	344.432
4690.41	342.731
4693.03	338.16
4695.65	333.14
4698.27	331.163
4700.89	332.949
4703.51	333.559
4706.13	333.71
4708.75	333.072
4711.36	332.389
4713.97	331.962
4716.59	331.979
4719.2	332.576
4721.81	332.458
4724.42	333.25
4727.03	334.475
4729.64	331.836
4732.25	331.088
4734.85	329.796
4737.46	328.482
4740.06	327.818
4742.67	326.96
4745.27	326.082
4747.87	324.342
4750.47	323.666
4753.07	322.629
4755.67	321.816
4758.27	322.157
4760.87	320.509
4763.46	319.321
4766.06	313.337
4768.65	319.123
4771.25	319.52
4773.84	318.134
4776.43	316.096
4779.02	313.589
4781.61	311.611
4784.2	311.524
4786.78	313.778
4789.37	315.293
4791.96	315.962
4794.54	316.455
4797.12	315.756
4799.71	314.447
4802.29	312.775
4804.87	311.101
4807.45	309.486
4810.02	307.528
4812.6	306.02
4815.18	305.746
4817.76	306.138
4820.33	306.895
4822.9	308.316
4825.48	308.701
4828.05	306.475
4830.62	304.904
4833.19	301.822
4835.76	298.659
4838.33	298.349
4840.89	298.584
4843.46	298.763
4846.02	298.811
4848.59	298.557
4851.15	298.378
4853.71	298.289
4856.27	297.671
4858.83	296.792
4861.39	295.695
4863.95	295.934
4866.51	294.391
4869.07	292.375
4871.62	288.724
4874.18	285.286
4876.73	282.699
4879.28	288.668
4881.84	289.416
4884.39	288.883
4886.94	281.989
4889.49	284.173
4892.03	284.822
4894.58	286.033
4897.13	287.766
4899.67	286.255
4902.22	283.011
4904.76	280.491
4907.3	278.008
4909.84	276.301
4912.38	275.298
4914.92	274.935
4917.46	275.458
4920	275.848
4922.54	275.399
4925.07	275.638
4927.61	276.78
4930.14	278.979
4932.68	276.979
4935.21	276.196
4937.74	275.473
4940.27	274.423
4942.8	273.229
4945.33	272.339
4947.85	271.142
4950.38	269.09
4952.91	266.709
4955.43	268.587
4957.96	271.224
4960.48	271.284
4963	270.89
4965.52	269.27
4968.04	266.604
4970.56	265.329
4973.08	266.982
4975.59	267.336
4978.11	267.108
4980.63	266.388
4983.14	264.979
4985.66	262.961
4988.17	260.759
4990.68	258.693
4993.19	261.135
4995.7	253.85
4998.21	254.811