File: Data/3-Raman/raw/bu02aw-a-ff1-fi01-v_1800 (450-850nm)_532nm_edge_100%_x100_vis_lwd_h50um_30sx2_01.txt
#Acq. time (s)=	30
#Accumulations=	2
#Range (cm-¹)=	1200...2365
#Windows=	3
#Auto scanning=	Off
#Autofocus=	Off
#Macrospot=	Off
#AutoExposure=	Off
#Spike filter=	Multiple accum.
#Delay time (s)=	2
#Binning=	1
#Readout mode=	Signal
#DeNoise=	Off
#ICS correction=	On
#Dark correction=	Off
#Inst. Process=	Off
#Detector Gain=	Best Dynamic
#Detector ADC=	50 kHz HS
#Detector temperature (°C)=	-60.09
#Instrument=	LabRAM HR Evol
#Detector=	SIN-EM FIVIS
#Objective=	x100_VIS_LWD
#Grating=	1800 (450-850nm)
#ND Filter=	100%
#Laser=	532nm_Edge
#Hole=	49.98
#Temperature=	0
#Range=	Visible
#StageXY=	75x50mm Scan+
#StageZ=	Z motor
#X (µm)=	0
#Y (µm)=	0
#Z (µm)=	-10.3
#Full time(mm:ss)=	3:11
#Project=	21_11_26
#Sample=	BU02Aw
#Site=
#Title=	BU02aW-A-FF1-FI01-V_1800 (450-850nm)_532nm_Edge_100%_x100_VIS_LWD_H50um_30sX2
#Remark=
#Date=	26.11.2021 10:39
#Acquired=	26.11.2021 10:39:57
1202.72	25.2723
1203.84	27.4351
1204.95	25.2661
1206.06	29.5241
1207.17	30.5404
1208.28	29.4386
1209.39	28.3393
1210.5	25.1204
1211.61	25.0829
1212.72	29.3124
1213.83	29.286
1214.94	27.1538
1216.05	23.956
1217.16	27.1108
1218.27	26.0193
1219.38	23.8814
1220.49	27.0536
1221.6	23.8642
1222.71	25.9511
1223.81	29.0745
1224.92	29.0419
1226.03	26.9326
1227.14	27.9836
1228.25	25.8146
1229.35	29.9571
1230.46	25.8243
1231.57	26.8032
1232.67	27.8546
1233.78	27.8493
1234.89	28.9115
1235.99	27.8739
1237.1	28.9194
1238.2	33.0823
1239.31	25.7042
1240.41	26.7441
1241.52	26.7475
1242.62	24.6423
1243.73	28.8437
1244.83	26.7476
1245.94	28.8182
1247.04	28.8029
1248.14	29.8431
1249.25	27.7353
1250.35	32.9648
1251.45	29.8011
1252.56	27.6919
1253.66	27.6733
1254.76	26.6454
1255.87	28.7387
1256.97	35.0126
1258.07	30.8278
1259.17	34.9875
1260.27	33.9663
1261.37	36.0158
1262.48	37.1401
1263.58	45.3836
1264.68	58.0814
1265.78	42.3503
1266.88	32.9459
1267.98	40.3012
1269.08	31.9754
1270.18	37.2137
1271.28	38.2261
1272.38	41.3706
1273.47	38.2766
1274.57	35.1672
1275.67	38.319
1276.77	35.1993
1277.87	36.2795
1278.97	38.4164
1280.07	43.6836
1281.16	52.1
1282.26	61.6093
1283.36	135.232
1284.45	362.228
1285.55	201.721
1286.65	59.5331
1287.75	42.6671
1288.84	35.2897
1289.94	33.205
1291.03	32.1612
1292.13	35.3176
1293.22	32.1567
1294.32	31.142
1295.42	32.2045
1296.51	31.2157
1297.61	33.3252
1298.7	32.2507
1299.79	26.9562
1300.89	31.1883
1301.98	26.9691
1303.08	29.0894
1304.17	25.9111
1305.26	29.0763
1306.35	31.1617
1307.45	31.1562
1308.54	30.104
1309.63	31.1687
1310.73	29.0635
1311.82	35.4009
1312.91	29.0827
1314	32.2407
1315.09	30.1328
1316.18	32.2612
1317.28	34.3684
1318.37	33.3232
1319.46	32.2688
1320.55	28.0438
1321.64	32.2477
1322.73	26.9452
1323.82	26.9361
1324.91	30.1014
1326	29.0282
1327.09	30.0332
1328.18	27.977
1329.27	29.0658
1330.35	29.0624
1331.44	29.0385
1332.53	27.9448
1333.62	34.2154
1334.71	28.9278
1335.79	29.9535
1336.88	30.9839
1337.97	29.924
1339.06	28.8539
1340.14	30.9476
1341.23	33.045
1342.32	31.9861
1343.4	33.0046
1344.49	28.8186
1345.58	30.8962
1346.66	33.9854
1347.75	28.7319
1348.83	27.6769
1349.92	29.7404
1351	32.8397
1352.09	28.6565
1353.17	30.7557
1354.25	32.8698
1355.34	27.5988
1356.42	30.7133
1357.51	29.6602
1358.59	31.7176
1359.67	30.6588
1360.76	30.6301
1361.84	27.5135
1362.92	27.5036
1364	32.6919
1365.09	35.7976
1366.17	37.8371
1367.25	36.7629
1368.33	37.7956
1369.41	38.8401
1370.5	43.9981
1371.58	33.6338
1372.66	37.7108
1373.74	41.8078
1374.82	40.7647
1375.9	40.7638
1376.98	52.0726
1378.06	57.2013
1379.14	60.3867
1380.22	67.5699
1381.3	78.7439
1382.38	80.7167
1383.46	83.679
1384.54	84.6571
1385.61	104.235
1386.69	162.864
1387.77	630.567
1388.85	341.852
1389.93	83.7693
1391	59.0352
1392.08	47.7184
1393.16	39.4919
1394.23	41.5241
1395.31	37.429
1396.39	39.4883
1397.46	38.4457
1398.54	32.3007
1399.62	33.3379
1400.69	33.3498
1401.77	24.1484
1402.84	37.5192
1403.92	34.4746
1404.99	33.4253
1406.07	33.4044
1407.14	38.5203
1408.22	42.633
1409.29	64.1831
1410.37	54.9662
1411.44	34.4161
1412.51	34.4103
1413.59	29.3672
1414.66	29.3334
1415.73	32.4272
1416.81	23.195
1417.88	28.3437
1418.95	27.3217
1420.02	26.2882
1421.1	30.3748
1422.17	31.4041
1423.24	25.2966
1424.31	26.2405
1425.38	28.2932
1426.45	29.3274
1427.52	28.2746
1428.59	26.201
1429.67	29.2817
1430.74	25.2072
1431.81	28.3188
1432.87	26.2523
1433.95	25.1902
1435.01	27.2488
1436.08	27.2493
1437.15	28.2661
1438.22	28.2595
1439.29	28.2698
1440.36	25.2153
1441.43	23.1718
1442.49	21.1191
1443.56	28.296
1444.63	26.2407
1445.7	25.2357
1446.77	25.2283
1447.83	27.2703
1448.9	19.0744
1449.97	23.1739
1451.03	28.2885
1452.1	25.2055
1453.17	25.205
1454.23	23.1602
1455.3	26.2333
1456.36	22.1402
1457.43	23.1566
1458.49	25.2022
1459.56	21.1089
1460.62	26.2287
1461.69	25.194
1462.75	25.1775
1463.82	21.0665
1464.88	24.1606
1465.94	20.0093
1467.01	22.0442
1468.07	22.0412
1469.13	21.0189
1470.2	24.0642
1471.26	24.0526
1472.32	24.0405
1473.39	23.019
1474.45	25.044
1475.51	23.0131
1476.57	23.0058
1477.63	26.0463
1478.69	24.0042
1479.76	21.9574
1480.82	17.8752
1481.88	20.913
1482.94	21.9434
1484	24.9946
1485.06	20.8908
1486.12	21.8985
1487.18	30.0075
1488.24	20.8784
1489.3	23.8981
1490.36	21.869
1491.42	27.925
1492.48	22.8676
1493.53	22.8655
1494.59	24.8872
1495.65	26.8988
1496.71	22.8356
1497.77	26.867
1498.82	23.8386
1499.88	18.7973
1500.94	20.8185
1502	20.8109
1503.05	21.8126
1504.11	21.8024
1505.17	23.822
1506.22	23.8017
1507.28	21.7891
1508.34	24.8127
1509.39	26.829
1510.45	22.8025
1511.5	27.8176
1512.56	21.735
1513.61	23.7197
1514.67	25.7443
1515.72	22.7119
1516.78	26.7033
1517.83	23.6919
1518.88	24.7043
1519.94	23.7083
1520.99	25.7124
1522.05	21.7041
1523.1	21.6956
1524.15	26.6813
1525.2	28.6735
1526.26	24.6786
1527.31	20.6825
1528.36	22.6795
1529.41	22.6719
1530.47	23.6674
1531.52	21.6792
1532.57	20.6747
1533.62	22.7026
1534.67	26.7191
1535.72	25.7049
1536.77	18.6617
1537.82	25.6442
1538.87	24.6298
1539.92	23.6652
1540.97	21.6985
1542.02	22.6879
1543.07	30.6758
1544.12	23.6418
1545.17	22.6561
1546.22	23.6798
1547.27	23.6853
1548.32	23.674
1549.37	23.6611
1550.42	24.6708
1551.46	26.7502
1552.51	24.7435
1553.56	26.7328
1554.61	22.7037
1555.65	26.6914
1556.7	25.6881
1557.75	25.6925
1558.79	21.6687
1559.84	25.6447
1560.89	22.6343
1561.93	28.6364
1562.98	22.6513
1564.02	24.6474
1565.07	27.6694
1566.11	22.5327
1567.16	23.6241
1568.2	25.6418
1569.25	26.6482
1570.29	21.6388
1571.34	25.6361
1572.38	28.6217
1573.43	25.6101
1574.47	24.6098
1575.51	27.6311
1576.56	25.6368
1577.6	28.602
1578.64	25.5791
1579.69	26.5748
1580.73	25.5857
1581.77	27.5684
1582.81	32.5348
1583.85	26.5528
1584.9	28.5468
1585.94	27.5498
1586.98	26.5344
1588.02	28.5148
1589.06	27.5298
1590.1	26.5449
1591.14	29.5405
1592.18	27.5435
1593.22	27.5187
1594.26	28.4736
1595.3	25.4985
1596.34	28.47
1597.38	24.5003
1598.42	26.4888
1599.46	26.4662
1600.5	24.4653
1601.54	29.3936
1602.58	30.3549
1603.62	30.3293
1604.66	27.357
1605.69	29.3377
1606.73	36.2763
1607.77	31.3315
1608.81	28.2356
1609.84	27.727
1610.88	29.4481
1611.92	26.9606
1612.95	28.8535
1613.99	29.1285
1615.03	31.9862
1616.06	31.6874
1617.1	30.7324
1618.13	29.1546
1619.17	29.5252
1620.2	29.9897
1621.24	27.306
1622.27	30.9457
1623.31	30.8899
1624.34	30.1945
1625.38	29.7188
1626.41	32.5093
1627.45	30.3509
1628.48	28.4308
1629.51	31.7909
1630.55	29.8192
1631.53	29.3702
1632.57	36.2821
1633.62	35.2934
1634.66	32.345
1635.71	33.3277
1636.75	32.3279
1637.8	29.3554
1638.84	32.2993
1639.89	35.2522
1640.93	31.32
1641.98	32.3043
1643.02	32.2974
1644.06	33.2761
1645.11	32.2777
1646.15	28.3511
1647.19	29.3235
1648.24	33.2474
1649.28	31.3091
1650.32	40.1668
1651.37	30.3515
1652.41	33.3137
1653.45	29.3647
1654.49	33.3129
1655.53	31.3556
1656.57	34.3496
1657.62	32.3762
1658.66	31.3777
1659.7	29.387
1660.74	27.4103
1661.78	28.4169
1662.82	32.4007
1663.86	31.4166
1664.9	32.3827
1665.94	31.3538
1666.98	31.3942
1668.02	32.3635
1669.06	30.396
1670.1	29.4305
1671.14	29.4526
1672.18	28.4586
1673.21	26.4846
1674.25	31.4348
1675.29	25.5167
1676.33	31.4604
1677.37	30.4736
1678.4	22.5445
1679.44	28.461
1680.48	27.4621
1681.52	31.4041
1682.55	29.4274
1683.59	32.389
1684.63	28.4301
1685.66	27.437
1686.7	27.4396
1687.73	24.4828
1688.77	28.4214
1689.81	23.4674
1690.84	27.407
1691.88	24.4565
1692.91	26.4269
1693.95	23.443
1694.98	24.41
1696.01	24.4135
1697.05	28.3623
1698.08	26.3698
1699.12	25.3672
1700.15	22.4139
1701.18	24.3753
1702.22	27.3123
1703.25	26.3123
1704.28	22.3757
1705.32	24.3452
1706.35	24.3394
1707.38	26.2789
1708.41	23.3079
1709.44	22.2996
1710.48	24.2522
1711.51	22.3018
1712.54	25.2411
1713.57	25.2023
1714.6	25.1754
1715.63	22.2444
1716.66	25.1742
1717.69	23.1906
1718.72	24.126
1719.75	26.0637
1720.78	22.1678
1721.81	22.1481
1722.84	23.0976
1723.87	23.0801
1724.9	23.0725
1725.93	24.9788
1726.96	24.0001
1727.99	22.0551
1729.02	20.0772
1730.05	22.9539
1731.07	21.9747
1732.1	22.0004
1733.13	25.855
1734.16	23.8907
1735.18	20.0059
1736.21	20.9489
1737.24	24.7873
1738.26	22.8493
1739.29	18.0252
1740.32	23.7526
1741.34	21.8083
1742.37	18.9203
1743.4	21.7856
1744.42	23.6876
1745.45	22.7258
1746.47	25.5853
1747.5	22.692
1748.52	18.8597
1749.55	19.8185
1750.57	20.7899
1751.6	20.7987
1752.62	19.8234
1753.64	19.8061
1754.67	21.6975
1755.69	23.5916
1756.71	21.6658
1757.74	25.4473
1758.76	23.5524
1759.78	23.5544
1760.81	19.7421
1761.83	18.7781
1762.85	22.5792
1763.87	20.68
1764.89	24.5017
1765.92	21.6565
1766.94	22.6065
1767.96	24.5027
1768.98	19.7355
1770	20.6487
1771.02	20.6595
1772.04	19.7254
1773.06	23.5424
1774.08	20.6969
1775.1	22.6078
1776.12	21.6764
1777.14	19.7697
1778.16	20.7094
1779.18	23.547
1780.2	16.8812
1781.22	19.7425
1782.24	19.748
1783.26	21.6668
1784.28	20.7244
1785.29	19.7841
1786.31	21.6864
1787.33	20.7422
1788.35	21.7377
1789.37	21.7695
1790.38	27.54
1791.4	25.6195
1792.42	21.7684
1793.43	22.733
1794.45	21.7794
1795.47	21.7986
1796.48	19.9025
1797.5	21.8398
1798.51	20.8892
1799.53	19.9255
1800.55	18.951
1801.56	19.9055
1802.58	22.7914
1803.59	21.8461
1804.61	20.8939
1805.62	21.8742
1806.64	20.9279
1807.65	24.7886
1808.66	20.9344
1809.68	20.9371
1810.69	20.9396
1811.7	19.9724
1812.72	20.9395
1813.73	22.8798
1814.74	22.9005
1815.76	20.0187
1816.77	21.9561
1817.78	19.0445
1818.79	20.9798
1819.8	22.919
1820.82	20.0283
1821.83	18.103
1822.84	23.9182
1823.85	20.0461
1824.86	23.9188
1825.87	24.8958
1826.88	22.9602
1827.89	20.0603
1828.9	21.0281
1829.91	21.9897
1830.92	22.9489
1831.93	20.052
1832.94	22.9711
1833.95	23.9466
1834.96	21.9928
1835.97	20.9918
1836.98	21.0686
1837.99	20.0343
1839	21.0001
1840	19.0905
1841.01	20.9872
1842.02	17.0869
1843.03	19.9657
1844.04	18.0361
1845.04	24.789
1846.05	17.0763
1847.06	21.9222
1848.07	18.9591
1849.07	20.8879
1850.08	19.9095
1851.09	21.8066
1852.09	19.8715
1853.1	23.7109
1854.1	21.7814
1855.11	17.9229
1856.11	18.8633
1857.12	20.7757
1858.12	19.8102
1859.13	20.7503
1860.13	22.6474
1861.14	19.7875
1862.14	20.755
1863.15	22.6538
1864.15	18.8115
1865.15	22.6164
1866.16	19.7265
1867.16	23.501
1868.16	19.6679
1869.17	21.5667
1870.17	21.5624
1871.17	17.7569
1872.17	18.6999
1873.18	18.6882
1874.18	18.6803
1875.18	23.404
1876.18	17.6883
1877.18	20.5067
1878.18	21.4215
1879.19	21.4566
1880.19	22.4203
1881.19	27.151
1882.19	21.4388
1883.19	21.3936
1884.19	23.2552
1885.19	21.381
1886.19	18.5757
1887.19	18.5729
1888.19	18.5547
1889.19	17.5877
1890.19	20.4013
1891.19	23.2393
1892.18	23.2341
1893.18	20.3996
1894.18	23.1877
1895.18	21.2979
1896.18	23.184
1897.18	19.4374
1898.17	23.2049
1899.17	26.0115
1900.17	24.1145
1901.16	20.3557
1902.16	22.2515
1903.16	22.2597
1904.16	21.3108
1905.15	22.247
1906.15	24.1174
1907.14	21.283
1908.14	24.1031
1909.14	21.2943
1910.13	19.4324
1911.13	21.3391
1912.12	22.287
1913.12	22.2831
1914.11	17.582
1915.11	22.315
1916.1	25.154
1917.1	18.5392
1918.09	20.4154
1919.08	23.2585
1920.08	22.346
1921.07	22.35
1922.06	21.4222
1923.06	22.3645
1924.05	21.4098
1925.04	19.5098
1926.04	20.4683
1927.03	23.3305
1928.02	21.4507
1929.01	23.3546
1930	22.4253
1931	23.3984
1931.99	23.3958
1932.98	21.4848
1933.97	20.5393
1934.96	25.3565
1935.95	24.4579
1936.94	24.4344
1937.93	22.5089
1938.92	23.4596
1939.91	21.5675
1940.9	20.6289
1941.89	15.8766
1942.88	23.5199
1943.87	22.5521
1944.86	20.6584
1945.85	23.5453
1946.84	20.6917
1947.83	22.6009
1948.82	20.6856
1949.8	21.6555
1950.79	20.7273
1951.78	22.6781
1952.77	20.7755
1953.76	21.7383
1954.74	22.6509
1955.73	18.8068
1956.72	24.5965
1957.7	22.6982
1958.69	21.7484
1959.68	22.7021
1960.66	19.8093
1961.65	23.6344
1962.63	22.6751
1963.62	25.5584
1964.61	18.8444
1965.59	19.8022
1966.58	19.8126
1967.56	24.6277
1968.55	19.8251
1969.53	23.6578
1970.52	20.752
1971.5	20.7397
1972.48	23.6172
1973.47	24.5711
1974.45	21.68
1975.44	23.5988
1976.42	20.7334
1977.4	18.8163
1978.39	23.6005
1979.37	19.759
1980.35	20.7191
1981.33	22.6241
1982.31	20.7003
1983.3	22.602
1984.28	24.4994
1985.26	25.4442
1986.24	22.5683
1987.22	25.4446
1988.21	23.515
1989.19	23.4604
1990.17	23.3469
1991.15	22.3533
1992.13	22.2903
1993.11	21.766
1994.09	23.4693
1995.07	21.8168
1996.05	21.38
1997.03	22.9892
1998.01	23.4624
1998.99	23.2615
1999.97	22.7782
2000.95	21.2633
2001.92	20.9733
2002.9	21.4406
2003.88	21.568
2004.86	21.9514
2005.84	22.4207
2006.81	23.1473
2007.79	22.6941
2008.77	22.4503
2009.75	20.2713
2010.73	22.7003
2011.7	22.5532
2012.68	21.5107
2013.67	21.4857
2014.66	24.2672
2015.64	24.2564
2016.63	24.2664
2017.62	21.463
2018.61	20.4951
2019.6	23.2749
2020.58	21.3909
2021.57	22.3275
2022.56	22.3207
2023.55	24.1703
2024.54	23.2143
2025.52	22.2494
2026.51	22.2305
2027.5	22.2883
2028.48	23.196
2029.47	19.4897
2030.45	20.3626
2031.44	22.2374
2032.43	23.174
2033.41	23.2032
2034.4	25.0749
2035.38	24.1025
2036.37	18.542
2037.35	26.0163
2038.34	19.4648
2039.32	22.2547
2040.31	21.3017
2041.29	24.0775
2042.27	20.3376
2043.26	23.1235
2044.24	21.2845
2045.23	21.2714
2046.21	23.1832
2047.19	22.2277
2048.17	23.131
2049.16	20.3391
2050.14	24.0955
2051.12	21.3107
2052.11	22.2316
2053.09	25.0407
2054.07	21.3272
2055.05	25.0755
2056.03	22.258
2057.01	20.3809
2058	24.1251
2058.98	20.4007
2059.96	22.2823
2060.94	20.4019
2061.92	21.346
2062.9	22.287
2063.88	21.3633
2064.86	22.3087
2065.84	23.2682
2066.82	24.2213
2067.8	23.2921
2068.78	26.1224
2069.76	21.4164
2070.73	21.4139
2071.71	22.3676
2072.69	21.4571
2073.67	24.2772
2074.65	26.1662
2075.63	19.598
2076.6	23.3951
2077.58	24.3264
2078.56	22.4334
2079.54	26.221
2080.51	20.5779
2081.49	24.3562
2082.47	20.5762
2083.45	20.5785
2084.42	23.4114
2085.4	23.4119
2086.37	24.3644
2087.35	21.5446
2088.32	24.3895
2089.3	19.6603
2090.28	22.515
2091.25	23.4695
2092.23	22.5388
2093.2	16.8694
2094.18	22.588
2095.15	19.7398
2096.13	24.4789
2097.1	23.5219
2098.07	21.608
2099.05	23.5004
2100.02	22.5473
2101	23.5004
2101.97	27.314
2102.94	26.3616
2103.92	19.7026
2104.89	23.5039
2105.86	23.5197
2106.83	20.6781
2107.8	22.5801
2108.78	24.4564
2109.75	21.6067
2110.72	22.5608
2111.69	23.5083
2112.66	23.5005
2113.63	22.5632
2114.61	23.5164
2115.58	20.6646
2116.55	25.4044
2117.52	25.3941
2118.49	20.6376
2119.46	20.6163
2120.43	23.443
2121.4	22.5001
2122.37	18.7251
2123.34	23.4818
2124.31	21.5812
2125.28	23.4483
2126.25	22.4684
2127.21	24.3391
2128.18	22.4376
2129.15	23.3786
2130.12	19.5923
2131.09	22.4204
2132.06	22.407
2133.02	21.4493
2133.99	22.3916
2134.96	23.3361
2135.93	24.2741
2136.89	28.0216
2137.86	22.3697
2138.83	24.2461
2139.79	24.2513
2140.76	24.2304
2141.73	23.2818
2142.69	22.3278
2143.66	20.4603
2144.62	22.2995
2145.59	21.3598
2146.55	22.2953
2147.52	25.1047
2148.48	22.2742
2149.45	19.4439
2150.42	25.0461
2151.38	23.1646
2152.34	20.3619
2153.31	25.9796
2154.27	24.0915
2155.24	24.9924
2156.2	23.0895
2157.16	23.0803
2158.13	24.0235
2159.09	23.0918
2160.05	22.1435
2161.01	22.1225
2161.98	20.248
2162.94	22.112
2163.9	19.3041
2164.86	23.0171
2165.83	23.0162
2166.79	22.0792
2167.75	23.9242
2168.71	24.8199
2169.67	17.3882
2170.63	23.9276
2171.59	21.1275
2172.56	21.0915
2173.51	23.8706
2174.48	23.8766
2175.44	20.1591
2176.4	22.9416
2177.36	24.7918
2178.32	22.0057
2179.28	19.2066
2180.23	17.3502
2181.19	24.7735
2182.15	21.0525
2183.11	23.8271
2184.07	17.3163
2185.03	21.9429
2185.99	19.1697
2186.95	21.9678
2187.9	21.9915
2188.86	20.1249
2189.82	22.885
2190.78	23.8015
2191.73	21.9519
2192.69	23.814
2193.65	19.1871
2194.6	25.7212
2195.56	22.0004
2196.52	21.9777
2197.47	23.8119
2198.43	21.9559
2199.38	25.6953
2200.34	27.592
2201.3	24.8438
2202.25	21.975
2203.21	24.8031
2204.16	19.2904
2205.12	24.8463
2206.07	27.5753
2207.03	22.9243
2207.98	21.0772
2208.93	22.9559
2209.89	24.8254
2210.84	19.2423
2211.8	22.9831
2212.75	20.1993
2213.7	21.1227
2214.66	21.1325
2215.61	23.013
2216.56	23.9476
2217.51	21.1438
2218.47	23.9457
2219.42	21.1541
2220.37	22.0994
2221.32	24.8977
2222.27	21.1401
2223.23	21.1409
2224.18	23.0275
2225.13	20.2452
2226.08	24.0104
2227.03	24.9665
2227.98	21.2287
2228.93	19.348
2229.88	22.1616
2230.83	23.1192
2231.78	22.2003
2232.73	21.2773
2233.68	20.3519
2234.63	24.1244
2235.58	25.9874
2236.53	24.1027
2237.48	24.1118
2238.43	18.492
2239.38	24.1742
2240.33	22.2775
2241.27	23.2305
2242.22	25.124
2243.17	26.0765
2244.12	22.291
2245.07	22.3007
2246.01	24.218
2246.96	21.3964
2247.91	20.4593
2248.85	20.4551
2249.8	23.2942
2250.75	18.5582
2251.69	19.4889
2252.64	24.222
2253.59	24.2569
2254.53	22.3828
2255.48	21.4367
2256.42	24.2872
2257.37	23.3548
2258.32	20.5171
2259.26	21.4739
2260.2	21.4832
2261.15	22.4436
2262.1	22.4577
2263.04	24.3733
2263.98	24.4012
2264.93	22.5265
2265.87	21.5859
2266.81	21.575
2267.76	23.4659
2268.7	21.5443
2269.65	21.558
2270.59	23.4955
2271.53	19.6878
2272.47	20.6553
2273.42	22.5724
2274.36	21.6199
2275.3	20.6672
2276.24	21.6294
2277.18	20.6905
2278.13	21.6774
2279.07	17.8498
2280.01	21.6754
2280.95	19.7359
2281.89	23.56
2282.83	20.6953
2283.77	18.7987
2284.71	17.8674
2285.65	21.7281
2286.59	21.7148
2287.54	19.8127
2288.47	22.7117
2289.41	19.8056
2290.35	23.6256
2291.29	21.704
2292.23	21.7255
2293.17	26.56
2294.11	21.7538
2295.05	21.7418
2295.99	20.7663
2296.93	22.673
2297.86	18.8364
2298.8	20.7821
2299.74	22.7287
2300.68	20.8006
2301.61	24.6721
2302.55	19.8452
2303.49	23.7027
2304.43	20.8128
2305.36	19.8592
2306.3	21.7991
2307.24	20.836
2308.17	23.7276
2309.11	21.7919
2310.04	20.8439
2310.98	22.7849
2311.92	19.8512
2312.85	19.8323
2313.79	18.8721
2314.72	22.7624
2315.66	20.8419
2316.59	21.7809
2317.52	20.8062
2318.46	20.8092
2319.39	22.7261
2320.33	23.6831
2321.26	22.7239
2322.2	20.811
2323.13	24.6906
2324.06	22.7625
2325	26.6219
2325.93	21.7639
2326.86	26.5693
2327.79	37.152
2328.73	70.8784
2329.66	40.0089
2330.59	30.3736
2331.52	19.775
2332.46	21.7068
2333.39	17.8417
2334.32	22.6444
2335.25	23.59
2336.18	15.8961
2337.11	23.5836
2338.04	23.578
2338.97	26.4563
2339.91	22.6119
2340.84	25.4809
2341.77	21.6115
2342.7	26.3876
2343.63	22.5478
2344.56	22.5472
2345.49	25.4184
2346.41	19.6512
2347.34	19.6453
2348.27	23.4744
2349.2	21.5612
2350.13	17.703
2351.06	23.3275
2351.99	23.4211
2352.91	21.4768
2353.84	21.4449
2354.77	24.3031
2355.7	22.3985
2356.63	20.4778
2357.55	20.4519
2358.48	19.4894
2359.41	19.4796
2360.33	22.3162
2361.26	22.2947
2362.19	23.2192
2363.11	23.1958
2364.04	20.3436
2364.97	20.3314