File: Data/3-Raman/raw/bu02aw-a-ff1-fi03-v_1800 (450-850nm)_532nm_edge_100%_x100_vis_lwd_h100um_30sx2_01.txt
#Acq. time (s)=	30
#Accumulations=	2
#Range (cm-¹)=	1200...2365
#Windows=	3
#Auto scanning=	Off
#Autofocus=	Off
#Macrospot=	Off
#AutoExposure=	Off
#Spike filter=	Multiple accum.
#Delay time (s)=	2
#Binning=	1
#Readout mode=	Signal
#DeNoise=	Off
#ICS correction=	On
#Dark correction=	Off
#Inst. Process=	Off
#Detector Gain=	Best Dynamic
#Detector ADC=	50 kHz HS
#Detector temperature (°C)=	-60.09
#Instrument=	LabRAM HR Evol
#Detector=	SIN-EM FIVIS
#Objective=	x100_VIS_LWD
#Grating=	1800 (450-850nm)
#ND Filter=	100%
#Laser=	532nm_Edge
#Hole=	100.021
#Temperature=	0
#Range=	Visible
#StageXY=	75x50mm Scan+
#StageZ=	Z motor
#X (µm)=	0
#Y (µm)=	0
#Z (µm)=	-11.5
#Full time(mm:ss)=	3:13
#Project=	21_11_26
#Sample=	BU02Aw
#Site=
#Title=	BU02aW-A-FF1-FI03-V_1800 (450-850nm)_532nm_Edge_100%_x100_VIS_LWD_H100um_30sX2
#Remark=
#Date=	26.11.2021 11:11
#Acquired=	26.11.2021 11:11:48
1202.72	86.5712
1203.84	81.2132
1204.95	76.8406
1206.06	81.0084
1207.17	79.7689
1208.28	80.741
1209.39	82.781
1210.5	78.4532
1211.61	83.6553
1212.72	79.264
1213.83	74.9172
1214.94	79.1522
1216.05	75.9296
1217.16	85.3715
1218.27	85.2611
1219.38	72.46
1220.49	74.5352
1221.6	75.5557
1222.71	76.4999
1223.81	78.4572
1224.92	74.1295
1226.03	83.6217
1227.14	77.2572
1228.25	77.0676
1229.35	82.1236
1230.46	78.1176
1231.57	76.8324
1232.67	79.9701
1233.78	80.9891
1234.89	82.0568
1235.99	76.823
1237.1	76.7913
1238.2	75.6283
1239.31	88.1068
1240.41	79.6761
1241.52	79.6701
1242.62	77.5297
1243.73	78.5881
1244.83	75.4281
1245.94	74.2965
1247.04	87.8479
1248.14	77.3475
1249.25	82.5189
1250.35	81.4568
1251.45	82.4138
1252.56	77.1184
1253.66	77.05
1254.76	83.3438
1255.87	83.3426
1256.97	87.5242
1258.07	87.4885
1259.17	94.7347
1260.27	97.9151
1261.37	100.921
1262.48	120.992
1263.58	166.533
1264.68	196.342
1265.78	134.479
1266.88	111.475
1267.98	100.063
1269.08	92.8498
1270.18	94.9307
1271.28	101.106
1272.38	96.9153
1273.47	93.873
1274.57	90.8026
1275.67	97.0931
1276.77	94.0036
1277.87	105.625
1278.97	104.656
1280.07	123.595
1281.16	155.139
1282.26	260.49
1283.36	748.548
1284.45	2127.38
1285.55	838.801
1286.65	225.798
1287.75	147.795
1288.84	122.484
1289.94	117.277
1291.03	94.1218
1292.13	100.415
1293.22	93.0227
1294.32	95.2315
1295.42	87.8568
1296.51	92.2567
1297.61	89.0584
1298.7	85.8238
1299.79	82.5958
1300.89	87.8857
1301.98	83.6594
1303.08	81.5544
1304.17	78.3401
1305.26	79.3729
1306.35	79.2886
1307.45	80.3128
1308.54	84.5228
1309.63	78.2031
1310.73	79.2559
1311.82	82.4195
1312.91	81.3887
1314	81.3474
1315.09	81.3401
1316.18	80.3115
1317.28	77.1147
1318.37	72.8986
1319.46	78.1694
1320.55	83.4376
1321.64	71.7506
1322.73	76.9432
1323.82	82.1723
1324.91	73.7262
1326	85.2526
1327.09	78.783
1328.18	78.9048
1329.27	82.1512
1330.35	84.2348
1331.44	78.8774
1332.53	77.6942
1333.62	77.5745
1334.71	82.7205
1335.79	78.4394
1336.88	76.2778
1337.97	82.52
1339.06	76.1558
1340.14	70.9018
1341.23	78.2233
1342.32	78.1778
1343.4	82.2769
1344.49	72.8413
1345.58	73.8363
1346.66	73.7157
1347.75	69.4394
1348.83	76.6864
1349.92	76.6152
1351	76.5391
1352.09	73.3463
1353.17	80.6617
1354.25	76.5631
1355.34	78.4446
1356.42	77.3818
1357.51	78.3662
1358.59	77.2625
1359.67	80.3032
1360.76	81.2458
1361.84	85.3477
1362.92	81.1582
1364	87.3851
1365.09	96.6865
1366.17	87.2735
1367.25	91.2962
1368.33	85.0755
1369.41	127.475
1370.5	123.29
1371.58	89.0875
1372.66	89.9716
1373.74	88.8629
1374.82	103.242
1375.9	111.465
1376.98	106.249
1378.06	114.43
1379.14	111.51
1380.22	137.199
1381.3	136.898
1382.38	149.065
1383.46	170.375
1384.54	196.918
1385.61	292.527
1386.69	735.418
1387.77	4047.26
1388.85	1339.44
1389.93	280.345
1391	173.267
1392.08	130.08
1393.16	118.701
1394.23	112.5
1395.31	97.1286
1396.39	98.1682
1397.46	96.0558
1398.54	93.9741
1399.62	85.813
1400.69	96.0651
1401.77	96.0957
1402.84	89.0505
1403.92	97.3342
1404.99	86.9906
1406.07	101.272
1407.14	113.527
1408.22	177.113
1409.29	270.479
1410.37	189.488
1411.44	106.273
1412.51	84.7212
1413.59	75.698
1414.66	80.7221
1415.73	75.612
1416.81	75.6221
1417.88	74.6163
1418.95	74.6157
1420.02	77.6646
1421.1	74.5068
1422.17	68.3371
1423.24	74.6434
1424.31	78.4775
1425.38	75.3896
1426.45	65.1384
1427.52	67.1067
1428.59	64.9785
1429.67	67.0318
1430.74	65.0275
1431.81	63.0467
1432.87	62.996
1433.95	64.9328
1435.01	65.9663
1436.08	61.8528
1437.15	62.8429
1438.22	67.9319
1439.29	65.8928
1440.36	58.7521
1441.43	60.8055
1442.49	59.7587
1443.56	59.7406
1444.63	61.7637
1445.7	63.8518
1446.77	59.7131
1447.83	61.726
1448.9	58.6545
1449.97	53.5033
1451.03	48.3369
1452.1	59.5752
1453.17	55.4595
1454.23	58.5287
1455.3	58.5098
1456.36	57.4848
1457.43	61.544
1458.49	63.5677
1459.56	58.4419
1460.62	60.4675
1461.69	52.2331
1462.75	60.367
1463.82	56.2064
1464.88	56.2574
1465.94	58.1107
1467.01	60.1173
1468.07	54.9917
1469.13	48.8493
1470.2	53.8979
1471.26	53.8541
1472.32	60.9369
1473.39	45.6397
1474.45	55.7779
1475.51	56.7912
1476.57	54.7206
1477.63	59.7625
1478.69	53.6249
1479.76	47.4774
1480.82	55.5277
1481.88	47.3752
1482.94	54.5033
1484	55.5152
1485.06	59.4331
1486.12	58.3869
1487.18	59.3927
1488.24	57.3205
1489.3	60.2926
1490.36	56.214
1491.42	52.1232
1492.48	55.1362
1493.53	58.1472
1494.59	61.1635
1495.65	48.9965
1496.71	59.0264
1497.77	60.0036
1498.82	47.8751
1499.88	51.9101
1500.94	54.9285
1502	55.9
1503.05	54.8541
1504.11	59.8518
1505.17	53.7932
1506.22	53.7273
1507.28	53.7176
1508.34	53.7033
1509.39	54.6973
1510.45	49.6527
1511.5	50.5971
1512.56	50.4769
1513.61	51.4062
1514.67	58.4585
1515.72	50.3606
1516.78	56.3133
1517.83	56.2893
1518.88	55.2944
1519.94	49.2762
1520.99	54.2708
1522.05	50.2533
1523.1	47.2068
1524.15	52.1436
1525.2	58.1134
1526.26	50.1099
1527.31	51.1262
1528.36	55.099
1529.41	54.061
1530.47	51.0254
1531.52	57.0589
1532.57	55.0313
1533.62	56.082
1534.67	53.0675
1535.72	59.0422
1536.77	54.936
1537.82	54.8581
1538.87	45.8108
1539.92	57.8833
1540.97	53.9593
1542.02	56.9148
1543.07	57.8413
1544.12	51.756
1545.17	54.7778
1546.22	54.8201
1547.27	49.8088
1548.32	54.7731
1549.37	57.7266
1550.42	51.7267
1551.46	51.8752
1552.51	57.8865
1553.56	56.8227
1554.61	59.771
1555.65	59.6997
1556.7	60.6812
1557.75	60.6764
1558.79	53.6023
1559.84	57.5215
1560.89	54.4773
1561.93	55.4729
1562.98	61.4907
1564.02	58.4635
1565.07	61.5009
1566.11	60.0961
1567.16	55.3551
1568.2	52.3875
1569.25	48.3866
1570.29	59.3385
1571.34	54.3251
1572.38	48.2898
1573.43	55.2307
1574.47	50.2186
1575.51	59.2489
1576.56	56.245
1577.6	53.1642
1578.64	53.0828
1579.69	58.0484
1580.73	55.0602
1581.77	60.9992
1582.81	57.9587
1583.85	53.9474
1584.9	55.9276
1585.94	54.9134
1586.98	50.8721
1588.02	58.7954
1589.06	50.8405
1590.1	53.8334
1591.14	56.8229
1592.18	57.7908
1593.22	53.7383
1594.26	63.5729
1595.3	57.6091
1596.34	52.6065
1597.38	61.5379
1598.42	54.5727
1599.46	56.4901
1600.5	60.401
1601.54	48.4257
1602.58	54.296
1603.62	60.1631
1604.66	59.145
1605.69	54.1921
1606.73	55.1934
1607.77	61.0512
1608.81	57.9846
1609.84	61.7102
1610.88	54.2501
1611.92	64.3497
1612.95	55.5586
1613.99	55.3126
1615.03	57.1438
1616.06	56.9915
1617.1	55.2127
1618.13	57.8286
1619.17	58.5008
1620.2	52.7295
1621.24	57.7722
1622.27	57.0938
1623.31	58.0478
1624.34	57.8098
1625.38	55.6533
1626.41	58.7057
1627.45	58.4749
1628.48	60.0451
1629.51	56.7956
1630.55	59.8687
1631.53	47.5315
1632.57	60.3505
1633.62	58.3614
1634.66	58.362
1635.71	50.4592
1636.75	60.2768
1637.8	62.1996
1638.84	58.2308
1639.89	52.3115
1640.93	57.2295
1641.98	63.1234
1643.02	54.2383
1644.06	53.2322
1645.11	59.0995
1646.15	57.1355
1647.19	58.0844
1648.24	60.0197
1649.28	58.0911
1650.32	58.0763
1651.37	60.0855
1652.41	55.1564
1653.45	54.1455
1654.49	55.1291
1655.53	56.1254
1656.57	60.1174
1657.62	59.1186
1658.66	53.1647
1659.7	55.0936
1660.74	53.1002
1661.78	60.0315
1662.82	59.0974
1663.86	60.0793
1664.9	59.0396
1665.94	57.9649
1666.98	59.999
1668.02	57.9801
1669.06	60.9397
1670.1	56.0315
1671.14	55.0707
1672.18	56.0362
1673.21	58.9946
1674.25	56.0292
1675.29	56.0477
1676.33	60.0062
1677.37	46.1425
1678.4	56.9895
1679.44	56.9395
1680.48	56.9059
1681.52	58.8494
1682.55	56.8591
1683.59	58.8181
1684.63	57.8029
1685.66	56.7913
1686.7	48.8833
1687.73	55.7967
1688.77	59.7092
1689.81	50.7741
1690.84	48.7751
1691.88	56.6744
1692.91	55.668
1693.95	51.6576
1694.98	49.6361
1696.01	52.5858
1697.05	50.6163
1698.08	50.5632
1699.12	50.5158
1700.15	46.5645
1701.18	50.4743
1702.22	53.3855
1703.25	53.3396
1704.28	55.2778
1705.32	49.3797
1706.35	50.3379
1707.38	52.2407
1708.41	49.2288
1709.44	56.9891
1710.48	52.0686
1711.51	48.1559
1712.54	55.0011
1713.57	48.0603
1714.6	49.9511
1715.63	54.8218
1716.66	49.9231
1717.69	49.8474
1718.72	50.7274
1719.75	48.7477
1720.78	53.6
1721.81	52.568
1722.84	56.3905
1723.87	52.4515
1724.9	44.6557
1725.93	48.4589
1726.96	54.2421
1727.99	48.4003
1729.02	52.1594
1730.05	51.128
1731.07	49.1542
1732.1	54.0303
1733.13	56.8927
1734.16	48.1216
1735.18	49.0117
1736.21	50.8769
1737.24	54.6886
1738.26	49.8356
1739.29	44.9754
1740.32	49.6901
1741.34	50.5777
1742.37	53.4018
1743.4	49.5434
1744.42	51.4185
1745.45	51.3945
1746.47	47.5371
1747.5	51.2935
1748.52	45.5221
1749.55	48.3835
1750.57	48.4093
1751.6	48.4167
1752.62	52.1783
1753.64	49.2578
1754.67	44.4388
1755.69	40.5895
1756.71	48.1577
1757.74	51.8987
1758.76	52.8538
1759.78	49.0392
1760.81	49.9639
1761.83	51.8195
1762.85	49.9012
1763.87	52.7464
1764.89	50.8697
1765.92	46.1192
1766.94	47.0545
1767.96	55.592
1768.98	50.7987
1770	44.0464
1771.02	47.8567
1772.04	46.932
1773.06	47.8973
1774.08	49.8088
1775.1	44.0984
1776.12	48.8937
1777.14	49.8334
1778.16	48.8359
1779.18	42.1191
1780.2	52.5666
1781.22	50.667
1782.24	45.9074
1783.26	48.7836
1784.28	45.9354
1785.29	49.7697
1786.31	43.0663
1787.33	47.8454
1788.35	48.8794
1789.37	47.9806
1790.38	50.8859
1791.4	48.9494
1792.42	47.9402
1793.43	45.068
1794.45	45.0643
1795.47	45.0913
1796.48	47.0493
1797.5	48.034
1798.51	49.9681
1799.53	45.1431
1800.55	50.8639
1801.56	48.9144
1802.58	46.9897
1803.59	44.126
1804.61	47.9804
1805.62	48.9708
1806.64	47.07
1807.65	48.0334
1808.66	48.0231
1809.68	49.9448
1810.69	56.6874
1811.7	44.134
1812.72	51.8414
1813.73	44.1377
1814.74	47.062
1815.76	46.1187
1816.77	41.2825
1817.78	49.9392
1818.79	48.0017
1819.8	49.9361
1820.82	48.0122
1821.83	47.0558
1822.84	44.1587
1823.85	47.0494
1824.86	50.9104
1825.87	48.9792
1826.88	46.0636
1827.89	47.0328
1828.9	52.8307
1829.91	44.0844
1830.92	50.8303
1831.93	51.8056
1832.94	50.8545
1833.95	46.0086
1834.96	45.9642
1835.97	51.6839
1836.98	49.921
1837.99	43.942
1839	49.7317
1840	47.8494
1841.01	49.6758
1842.02	51.5017
1843.03	45.6559
1844.04	45.6424
1845.04	48.5245
1846.05	40.8059
1847.06	53.39
1848.07	48.3787
1849.07	51.263
1850.08	48.3237
1851.09	55.9375
1852.09	50.1255
1853.1	48.1887
1854.1	45.2762
1855.11	47.1325
1856.11	48.0312
1857.12	47.0527
1858.12	51.8087
1859.13	53.6656
1860.13	51.7021
1861.14	49.7984
1862.14	51.7267
1863.15	51.679
1864.15	57.3527
1865.15	48.7025
1866.16	48.6262
1867.16	52.3375
1868.16	57.0113
1869.17	51.2872
1870.17	51.2642
1871.17	55.9941
1872.17	54.0594
1873.18	54.0125
1874.18	55.8752
1875.18	50.1203
1876.18	54.7662
1877.18	54.6938
1878.18	54.6006
1879.19	54.6794
1880.19	56.6043
1881.19	54.6907
1882.19	62.1588
1883.19	52.5791
1884.19	59.105
1885.19	58.1798
1886.19	62.9628
1887.19	60.1093
1888.19	56.2649
1889.19	56.1744
1890.19	58.0115
1891.19	56.1512
1892.18	58.0091
1893.18	55.1457
1894.18	64.4451
1895.18	57.8256
1896.18	55.0122
1897.18	55.0361
1898.17	56.9193
1899.17	55.9321
1900.17	61.5168
1901.16	59.6229
1902.16	49.3146
1903.16	54.9641
1904.16	54.9296
1905.15	57.7273
1906.15	58.6306
1907.14	54.8189
1908.14	49.1775
1909.14	56.7034
1910.13	53.9218
1911.13	57.7428
1912.12	52.0949
1913.12	55.8405
1914.11	52.0856
1915.11	54.0111
1916.1	54.9625
1917.1	57.7511
1918.09	56.7665
1919.08	61.5085
1920.08	58.7493
1921.07	53.0783
1922.06	54.0553
1923.06	54.0344
1924.05	53.053
1925.04	58.682
1926.04	57.765
1927.03	56.8724
1928.02	53.1077
1929.01	55.0129
1930	51.2532
1931	58.8916
1931.99	56.0246
1932.98	54.0812
1933.97	55.9756
1934.96	50.4186
1935.95	57.1958
1936.94	51.4093
1937.93	55.1584
1938.92	55.1425
1939.91	50.3989
1940.9	47.5621
1941.89	55.2274
1942.88	48.5567
1943.87	50.4226
1944.86	48.5372
1945.85	51.4401
1946.84	57.201
1947.83	50.4854
1948.82	48.5537
1949.8	49.5297
1950.79	55.3372
1951.78	50.6141
1952.77	56.4064
1953.76	52.5582
1954.74	49.5547
1955.73	54.3054
1956.72	49.589
1957.7	46.7427
1958.69	43.8708
1959.68	45.7646
1960.66	50.5294
1961.65	51.4398
1962.63	45.6695
1963.62	57.1835
1964.61	46.6264
1965.59	53.329
1966.58	55.2673
1967.56	51.4369
1968.55	45.6652
1969.53	49.47
1970.52	53.2394
1971.5	49.3569
1972.48	48.3841
1973.47	49.3193
1974.45	53.1081
1975.44	54.0583
1976.42	51.197
1977.4	49.2696
1978.39	52.107
1979.37	51.1185
1980.35	51.1104
1981.33	51.0689
1982.31	49.1212
1983.3	50.0344
1984.28	50.942
1985.26	51.8608
1986.24	49.9186
1987.22	51.8361
1988.21	48.9173
1989.19	45.9918
1990.17	55.1086
1991.15	49.0657
1992.13	48.763
1993.11	47.3844
1994.09	47.8345
1995.07	52.4077
1996.05	52.8899
1997.03	50.8984
1998.01	49.1669
1998.99	52.3721
1999.97	50.7981
2000.95	49.8981
2001.92	48.1328
2002.9	48.816
2003.88	49.3015
2004.86	48.8736
2005.84	50.5364
2006.81	48.8619
2007.79	49.1488
2008.77	45.8066
2009.75	49.5464
2010.73	54.7132
2011.7	56.17
2012.68	53.8937
2013.67	56.6515
2014.66	48.1059
2015.64	47.1436
2016.63	48.0989
2017.62	44.3677
2018.61	49.9361
2019.6	51.7329
2020.58	54.5167
2021.57	49.8312
2022.56	54.4957
2023.55	50.6997
2024.54	52.5227
2025.52	49.65
2026.51	54.2695
2027.5	51.6007
2028.48	47.8015
2029.47	54.4214
2030.45	44.9269
2031.44	43.0762
2032.43	54.28
2033.41	49.672
2034.4	52.4783
2035.38	49.5955
2036.37	50.6319
2037.35	48.7433
2038.34	52.4651
2039.32	52.4291
2040.31	51.4478
2041.29	53.259
2042.27	52.2991
2043.26	50.4104
2044.24	52.3305
2045.23	46.7027
2046.21	50.5307
2047.19	51.414
2048.17	50.4137
2049.16	48.5579
2050.14	53.2755
2051.12	52.3778
2052.11	48.6096
2053.09	53.2922
2054.07	53.3461
2055.05	51.4891
2056.03	51.4611
2057.01	54.2454
2058	53.3198
2058.98	52.4215
2059.96	50.5705
2060.94	56.1638
2061.92	52.438
2062.9	55.256
2063.88	51.5382
2064.86	56.2422
2065.84	57.2307
2066.82	50.6893
2067.8	53.5262
2068.78	57.3074
2069.76	49.771
2070.73	53.5213
2071.71	52.612
2072.69	49.8569
2073.67	48.9031
2074.65	52.6783
2075.63	53.6827
2076.6	50.9056
2077.58	52.7639
2078.56	60.2944
2079.54	57.4928
2080.51	53.7673
2081.49	52.8173
2082.47	51.8688
2083.45	53.7622
2084.42	48.0852
2085.4	57.5338
2086.37	50.9315
2087.35	56.6435
2088.32	55.7098
2089.3	56.6623
2090.28	54.8029
2091.25	59.555
2092.23	52.9586
2093.2	50.1725
2094.18	53.068
2095.15	52.1241
2096.13	51.1409
2097.1	54.9234
2098.07	53.9367
2099.05	54.869
2100.02	55.8063
2101	52.0166
2101.97	52.9952
2102.94	52.0377
2103.92	52.0078
2104.89	51.0649
2105.86	53.9467
2106.83	60.6217
2107.8	52.0655
2108.78	54.8596
2109.75	53.9063
2110.72	55.8141
2111.69	44.407
2112.66	53.8861
2113.63	52.9625
2114.61	49.1654
2115.58	56.7642
2116.55	55.7851
2117.52	52.9117
2118.49	54.7862
2119.46	56.6246
2120.43	51.8411
2121.4	51.8493
2122.37	56.6352
2123.34	51.9183
2124.31	54.7586
2125.28	56.5799
2126.25	58.3916
2127.21	55.4982
2128.18	50.7447
2129.15	48.8421
2130.12	61.1126
2131.09	47.8644
2132.06	52.5548
2133.02	47.8014
2133.99	50.627
2134.96	55.3449
2135.93	52.4988
2136.89	57.1601
2137.86	49.6252
2138.83	50.5462
2139.79	50.5543
2140.76	55.2186
2141.73	49.5501
2142.69	54.2274
2143.66	51.4389
2144.62	57.9156
2145.59	54.1537
2146.55	49.4397
2147.52	56.9335
2148.48	50.3276
2149.45	53.1093
2150.42	50.2314
2151.38	55.8396
2152.34	53.0496
2153.31	53.9656
2154.27	49.2489
2155.24	51.0473
2156.2	54.7141
2157.16	49.0853
2158.13	50.9699
2159.09	50.0389
2160.05	50.0061
2161.01	51.8232
2161.98	55.5327
2162.94	55.5257
2163.9	49.9027
2164.86	55.4547
2165.83	47.9954
2166.79	55.4351
2167.75	55.3907
2168.71	56.2399
2169.67	52.5366
2170.63	51.6662
2171.59	54.4413
2172.56	57.1354
2173.51	56.1822
2174.48	54.3352
2175.44	51.5448
2176.4	53.388
2177.36	49.6523
2178.32	54.2962
2179.28	50.5465
2180.23	56.1169
2181.19	49.6052
2182.15	58.8659
2183.11	56.9847
2184.07	56.0014
2185.03	50.4204
2185.99	55.0699
2186.95	54.1828
2187.9	48.666
2188.86	53.2838
2189.82	49.5142
2190.78	52.2702
2191.73	54.1326
2192.69	51.3647
2193.65	52.3196
2194.6	57.0396
2195.56	61.6776
2196.52	53.2557
2197.47	52.2751
2198.43	50.4157
2199.38	52.3265
2200.34	63.5588
2201.3	50.6197
2202.25	56.9498
2203.21	56.1137
2204.16	55.3778
2205.12	51.546
2206.07	56.0683
2207.03	56.9896
2207.98	53.2995
2208.93	57.0632
2209.89	53.3526
2210.84	57.0903
2211.8	58.0558
2212.75	59.0234
2213.7	57.1301
2214.66	47.8251
2215.61	55.3211
2216.56	59.9894
2217.51	51.5772
2218.47	57.1793
2219.42	57.2023
2220.37	62.8366
2221.32	54.4105
2222.27	52.4903
2223.23	54.3576
2224.18	54.4003
2225.13	52.5837
2226.08	50.7586
2227.03	60.1679
2227.98	52.6953
2228.93	55.492
2229.88	49.8662
2230.83	50.845
2231.78	52.7657
2232.73	53.7442
2233.68	55.6622
2234.63	56.6219
2235.58	52.8151
2236.53	55.6261
2237.48	62.2305
2238.43	60.4299
2239.38	52.9528
2240.33	59.5277
2241.27	58.6078
2242.22	52.9585
2243.17	52.0294
2244.12	50.1182
2245.07	56.7466
2246.01	54.9212
2246.96	55.9018
2247.91	52.1381
2248.85	57.803
2249.8	54.9622
2250.75	54.9478
2251.69	53.957
2252.64	50.1844
2253.59	51.2007
2254.53	56.9324
2255.48	59.7799
2256.42	54.1019
2257.37	54.1364
2258.32	49.4116
2259.26	53.2255
2260.2	50.395
2261.15	56.12
2262.1	55.2014
2263.04	53.3232
2263.98	52.4281
2264.93	59.181
2265.87	54.4412
2266.81	54.4115
2267.76	57.2281
2268.7	58.1437
2269.65	56.2704
2270.59	53.4717
2271.53	55.4192
2272.47	56.4041
2273.42	51.6272
2274.36	55.4636
2275.3	53.5585
2276.24	54.5259
2277.18	52.6557
2278.13	52.7224
2279.07	50.8336
2280.01	52.7129
2280.95	54.5754
2281.89	55.5054
2282.83	58.4085
2283.77	55.5925
2284.71	51.8336
2285.65	57.6385
2286.59	54.7158
2287.54	63.4392
2288.47	59.6124
2289.41	58.6
2290.35	56.5994
2291.29	53.7159
2292.23	51.8418
2293.17	57.6617
2294.11	57.6876
2295.05	56.6901
2295.99	57.618
2296.93	61.416
2297.86	50.8627
2298.8	53.801
2299.74	49.9858
2300.68	54.809
2301.61	56.7656
2302.55	52.9002
2303.49	53.8557
2304.43	53.8673
2305.36	52.9311
2306.3	54.8806
2307.24	57.7869
2308.17	58.7313
2309.11	52.9235
2310.04	50.0664
2310.98	57.818
2311.92	50.9634
2312.85	57.6677
2313.79	59.6112
2314.72	53.8859
2315.66	53.9163
2316.59	50.9466
2317.52	56.7168
2318.46	61.5519
2319.39	58.6145
2320.33	64.3816
2321.26	64.3958
2322.2	60.584
2323.13	58.6859
2324.06	67.4
2325	70.2765
2325.93	79.8521
2326.86	99.0787
2327.79	179.977
2328.73	432.466
2329.66	166.332
2330.59	89.2613
2331.52	72.8732
2332.46	65.1837
2333.39	58.4005
2334.32	54.5201
2335.25	55.4408
2336.18	51.5913
2337.11	49.6519
2338.04	54.4441
2338.97	60.1968
2339.91	54.4279
2340.84	55.3551
2341.77	56.244
2342.7	50.4431
2343.63	56.1819
2344.56	55.2195
2345.49	53.2898
2346.41	48.4549
2347.34	52.2682
2348.27	57.0513
2349.2	52.2657
2350.13	53.1382
2351.06	52.8811
2351.99	56.9125
2352.91	53.0062
2353.84	56.7357
2354.77	53.876
2355.7	53.8754
2356.63	51.9293
2357.55	54.714
2358.48	52.7788
2359.41	48.0006
2360.33	55.5649
2361.26	62.149
2362.19	47.8684
2363.11	48.7643
2364.04	57.2483
2364.97	50.5927