File: Data/3-Raman/raw/bu02aw-a-ff1-fi02-v_1800 (450-850nm)_532nm_edge_100%_x100_vis_lwd_h100um_30sx2_01.txt
#Acq. time (s)=	30
#Accumulations=	2
#Range (cm-¹)=	1200...2365
#Windows=	3
#Auto scanning=	Off
#Autofocus=	Off
#Macrospot=	Off
#AutoExposure=	Off
#Spike filter=	Multiple accum.
#Delay time (s)=	2
#Binning=	1
#Readout mode=	Signal
#DeNoise=	Off
#ICS correction=	On
#Dark correction=	Off
#Inst. Process=	Off
#Detector Gain=	Best Dynamic
#Detector ADC=	50 kHz HS
#Detector temperature (°C)=	-60.09
#Instrument=	LabRAM HR Evol
#Detector=	SIN-EM FIVIS
#Objective=	x100_VIS_LWD
#Grating=	1800 (450-850nm)
#ND Filter=	100%
#Laser=	532nm_Edge
#Hole=	100.021
#Temperature=	0
#Range=	Visible
#StageXY=	75x50mm Scan+
#StageZ=	Z motor
#X (µm)=	0
#Y (µm)=	0
#Z (µm)=	-18
#Full time(mm:ss)=	3:18
#Project=	21_11_26
#Sample=	BU02Aw
#Site=
#Title=	BU02aW-A-FF1-FI02-V_1800 (450-850nm)_532nm_Edge_100%_x100_VIS_LWD_H100um_30sX2
#Remark=
#Date=	26.11.2021 11:26
#Acquired=	26.11.2021 11:26:23
1202.72	72.5908
1203.84	69.3904
1204.95	63.9628
1206.06	70.3083
1207.17	74.4584
1208.28	73.3071
1209.39	75.3667
1210.5	65.71
1211.61	68.8089
1212.72	70.8441
1213.83	70.776
1214.94	73.9587
1216.05	78.2002
1217.16	72.7696
1218.27	72.6853
1219.38	73.6981
1220.49	71.5421
1221.6	71.5151
1222.71	69.3
1223.81	67.055
1224.92	69.0869
1226.03	73.3114
1227.14	69.0719
1228.25	72.0729
1229.35	69.7978
1230.46	74.1982
1231.57	67.6834
1232.67	71.8835
1233.78	77.1178
1234.89	65.5853
1235.99	72.9717
1237.1	70.8504
1238.2	77.0558
1239.31	80.1079
1240.41	71.6919
1241.52	72.745
1242.62	79.0025
1243.73	77.9766
1244.83	83.2144
1245.94	83.1352
1247.04	82.0396
1248.14	75.7384
1249.25	78.8309
1250.35	80.9184
1251.45	81.8882
1252.56	87.0475
1253.66	76.5494
1254.76	82.8544
1255.87	81.8205
1256.97	82.88
1258.07	97.4769
1259.17	119.342
1260.27	105.84
1261.37	117.195
1262.48	142.54
1263.58	212.02
1264.68	268.135
1265.78	192.63
1266.88	125.745
1267.98	110.174
1269.08	99.8429
1270.18	109.268
1271.28	109.163
1272.38	112.312
1273.47	105.107
1274.57	109.401
1275.67	106.264
1276.77	107.392
1277.87	112.731
1278.97	118.09
1280.07	142.302
1281.16	204.363
1282.26	392.915
1283.36	1195.51
1284.45	3284.75
1285.55	1902.37
1286.65	430.993
1287.75	208.705
1288.84	153.924
1289.94	132.951
1291.03	123.505
1292.13	115.062
1293.22	107.681
1294.32	104.646
1295.42	101.504
1296.51	101.715
1297.61	103.811
1298.7	93.1874
1299.79	94.1901
1300.89	94.2155
1301.98	84.7216
1303.08	84.741
1304.17	89.9851
1305.26	83.6379
1306.35	88.8372
1307.45	89.8717
1308.54	83.5462
1309.63	79.3479
1310.73	90.9652
1311.82	88.865
1312.91	95.24
1314	78.317
1315.09	84.6553
1316.18	92.0895
1317.28	88.9027
1318.37	79.4198
1319.46	86.8155
1320.55	86.8133
1321.64	85.6939
1322.73	83.5035
1323.82	82.4161
1324.91	82.4174
1326	84.467
1327.09	85.3768
1328.18	82.3579
1329.27	80.3432
1330.35	84.5489
1331.44	74.9881
1332.53	79.0869
1333.62	85.2859
1334.71	86.2367
1335.79	75.671
1336.88	88.2022
1337.97	70.3471
1339.06	77.6192
1340.14	83.8961
1341.23	80.7576
1342.32	73.3955
1343.4	85.8794
1344.49	81.6847
1345.58	75.3705
1346.66	81.5252
1347.75	85.5945
1348.83	79.2983
1349.92	81.321
1351	80.2137
1352.09	72.8717
1353.17	82.2786
1354.25	84.441
1355.34	90.4763
1356.42	79.0341
1357.51	85.2228
1358.59	82.0519
1359.67	95.4734
1360.76	85.0176
1361.84	86.0232
1362.92	91.1646
1364	93.263
1365.09	106.719
1366.17	104.554
1367.25	102.37
1368.33	107.531
1369.41	131.337
1370.5	191.249
1371.58	98.1344
1372.66	108.301
1373.74	106.163
1374.82	108.186
1375.9	112.3
1376.98	112.245
1378.06	126.612
1379.14	129.907
1380.22	143.233
1381.3	148.077
1382.38	166.41
1383.46	197.968
1384.54	246.039
1385.61	396.093
1386.69	1071.19
1387.77	5958.65
1388.85	3560.18
1389.93	571.951
1391	246.047
1392.08	184.374
1393.16	147.372
1394.23	144.242
1395.31	122.742
1396.39	117.659
1397.46	109.411
1398.54	106.315
1399.62	105.334
1400.69	115.604
1401.77	116.678
1402.84	113.775
1403.92	119.012
1404.99	111.744
1406.07	123.973
1407.14	164.933
1408.22	229.571
1409.29	431.675
1410.37	334.319
1411.44	153.618
1412.51	114.652
1413.59	100.579
1414.66	98.4048
1415.73	87.1534
1416.81	83.0703
1417.88	86.1887
1418.95	86.2016
1420.02	73.8486
1421.1	80.9737
1422.17	79.9496
1423.24	80.114
1424.31	83.9498
1425.38	82.9249
1426.45	83.971
1427.52	79.7862
1428.59	69.4693
1429.67	70.5108
1430.74	72.6194
1431.81	65.5251
1432.87	68.5637
1433.95	65.3862
1435.01	69.5049
1436.08	70.5265
1437.15	65.3803
1438.22	66.3847
1439.29	67.4294
1440.36	63.3754
1441.43	64.4157
1442.49	63.3806
1443.56	62.3489
1444.63	63.3586
1445.7	62.3798
1446.77	60.3055
1447.83	60.2804
1448.9	62.3474
1449.97	62.3351
1451.03	59.2276
1452.1	56.1301
1453.17	58.174
1454.23	62.2797
1455.3	53.0503
1456.36	54.085
1457.43	50.9866
1458.49	57.1217
1459.56	55.0798
1460.62	54.0448
1461.69	59.138
1462.75	48.8614
1463.82	53.9269
1464.88	49.8899
1465.94	53.8227
1467.01	58.9041
1468.07	59.9116
1469.13	55.8208
1470.2	54.7626
1471.26	52.6939
1472.32	54.6992
1473.39	57.7416
1474.45	54.6578
1475.51	46.5217
1476.57	53.6248
1477.63	53.5955
1478.69	57.6393
1479.76	53.5349
1480.82	55.5043
1481.88	51.4228
1482.94	53.4872
1484	56.541
1485.06	49.3273
1486.12	54.3755
1487.18	51.3392
1488.24	51.3099
1489.3	52.2771
1490.36	49.225
1491.42	49.1957
1492.48	54.2431
1493.53	50.1899
1494.59	49.1747
1495.65	46.12
1496.71	51.1198
1497.77	50.0933
1498.82	48.0694
1499.88	54.1344
1500.94	50.0977
1502	54.1115
1503.05	55.0969
1504.11	49.0166
1505.17	52.044
1506.22	57.0318
1507.28	43.935
1508.34	48.9705
1509.39	46.9531
1510.45	51.9967
1511.5	48.9261
1512.56	50.8373
1513.61	53.7895
1514.67	50.8075
1515.72	45.7419
1516.78	56.7276
1517.83	46.6894
1518.88	56.7346
1519.94	47.7177
1520.99	54.731
1522.05	48.7181
1523.1	49.6972
1524.15	50.6396
1525.2	53.619
1526.26	47.6276
1527.31	52.6621
1528.36	45.6253
1529.41	48.6103
1530.47	46.5905
1531.52	54.6346
1532.57	49.614
1533.62	48.6611
1534.67	56.6907
1535.72	47.6376
1536.77	54.5776
1537.82	48.5144
1538.87	52.4802
1539.92	47.5501
1540.97	52.6397
1542.02	47.593
1543.07	56.5532
1544.12	52.4854
1545.17	53.5158
1546.22	46.5537
1547.27	52.5719
1548.32	48.5364
1549.37	47.5044
1550.42	52.5236
1551.46	51.6713
1552.51	54.6821
1553.56	50.6253
1554.61	52.59
1555.65	54.5435
1556.7	51.531
1557.75	53.5396
1558.79	53.493
1559.84	50.4293
1560.89	52.3993
1561.93	51.4064
1562.98	56.4316
1564.02	50.4182
1565.07	51.4565
1566.11	45.1728
1567.16	51.3532
1568.2	56.3884
1569.25	51.3994
1570.29	50.3711
1571.34	49.3673
1572.38	48.3423
1573.43	49.3076
1574.47	49.2993
1575.51	45.3477
1576.56	49.3481
1577.6	47.29
1578.64	47.2317
1579.69	44.2344
1580.73	52.2222
1581.77	53.1922
1582.81	52.1626
1583.85	50.1571
1584.9	53.1447
1585.94	46.1665
1586.98	52.0996
1588.02	50.0866
1589.06	52.0916
1590.1	55.0952
1591.14	52.1202
1592.18	49.1189
1593.22	50.0642
1594.26	53.9616
1595.3	50.9877
1596.34	48.9803
1597.38	49.976
1598.42	50.9688
1599.46	52.905
1600.5	49.89
1601.54	48.8411
1602.58	52.7476
1603.62	51.709
1604.66	46.7505
1605.69	51.696
1606.73	50.7275
1607.77	47.8169
1608.81	50.5085
1609.84	49.184
1610.88	50.7409
1611.92	48.3756
1612.95	48.9739
1613.99	53.5114
1615.03	50.411
1616.06	52.1785
1617.1	52.7254
1618.13	50.4576
1619.17	47.1675
1620.2	50.5471
1621.24	53.0234
1622.27	53.7645
1623.31	53.5174
1624.34	53.012
1625.38	46.5087
1626.41	51.5011
1627.45	50.7231
1628.48	54.8427
1629.51	48.9784
1630.55	50.6093
1631.53	48.9923
1632.57	50.9792
1633.62	53.9244
1634.66	47.0312
1635.71	52.9342
1636.75	51.9198
1637.8	57.7916
1638.84	52.846
1639.89	52.8395
1640.93	52.8418
1641.98	51.8507
1643.02	44.9429
1644.06	52.8024
1645.11	51.7894
1646.15	48.8461
1647.19	48.8206
1648.24	47.8149
1649.28	55.7261
1650.32	57.6866
1651.37	54.7772
1652.41	50.8395
1653.45	56.7325
1654.49	54.7673
1655.53	50.8411
1656.57	57.7965
1657.62	50.8822
1658.66	49.8708
1659.7	55.7519
1660.74	50.807
1661.78	48.8639
1662.82	52.8642
1663.86	47.9241
1664.9	45.9109
1665.94	54.719
1666.98	53.7951
1668.02	51.7856
1669.06	46.8544
1670.1	57.7477
1671.14	48.8875
1672.18	49.8605
1673.21	52.8249
1674.25	55.7976
1675.29	51.8659
1676.33	50.8821
1677.37	50.8806
1678.4	52.828
1679.44	52.7866
1680.48	49.796
1681.52	50.7602
1682.55	52.7283
1683.59	47.779
1684.63	46.7729
1685.66	51.6945
1686.7	49.7181
1687.73	47.7482
1688.77	49.6955
1689.81	52.614
1690.84	48.648
1691.88	49.6463
1692.91	47.6604
1693.95	50.5641
1694.98	44.6091
1696.01	41.6535
1697.05	50.5282
1698.08	53.4352
1699.12	48.4716
1700.15	50.4311
1701.18	55.3301
1702.22	47.429
1703.25	48.3755
1704.28	49.3389
1705.32	46.3943
1706.35	46.3772
1707.38	54.1783
1708.41	49.209
1709.44	52.079
1710.48	47.166
1711.51	48.1551
1712.54	49.1308
1713.57	48.0715
1714.6	46.0605
1715.63	51.9147
1716.66	46.0458
1717.69	53.7855
1718.72	49.7941
1719.75	48.7947
1720.78	50.7328
1721.81	49.7092
1722.84	46.7378
1723.87	47.6673
1724.9	46.6747
1725.93	46.603
1726.96	54.3312
1727.99	46.5582
1729.02	53.2265
1730.05	52.1998
1731.07	46.3704
1732.1	48.3516
1733.13	47.3584
1734.16	49.2179
1735.18	49.1487
1736.21	44.2815
1737.24	49.0647
1738.26	50.9523
1739.29	48.0186
1740.32	48.897
1741.34	48.8331
1742.37	47.8347
1743.4	46.8559
1744.42	43.9551
1745.45	44.8956
1746.47	50.6086
1747.5	49.592
1748.52	48.6006
1749.55	47.6505
1750.57	44.8161
1751.6	51.5211
1752.62	45.7346
1753.64	51.4144
1754.67	49.4605
1755.69	46.5679
1756.71	45.567
1757.74	40.756
1758.76	52.1809
1759.78	45.5181
1760.81	49.3044
1761.83	49.2651
1762.85	44.5014
1763.87	48.3035
1764.89	49.2852
1765.92	43.5889
1766.94	48.3389
1767.96	44.5106
1768.98	49.2412
1770	49.1442
1771.02	38.7132
1772.04	48.2476
1773.06	46.3663
1774.08	52.0916
1775.1	43.5323
1776.12	54.0533
1777.14	48.3274
1778.16	47.3372
1779.18	46.3387
1780.2	44.4208
1781.22	47.2851
1782.24	50.1493
1783.26	47.318
1784.28	48.2897
1785.29	47.3621
1786.31	46.3891
1787.33	48.3138
1788.35	49.3563
1789.37	52.2963
1790.38	54.2541
1791.4	47.5317
1792.42	53.2337
1793.43	49.4121
1794.45	43.6668
1795.47	46.5769
1796.48	46.6233
1797.5	49.5367
1798.51	46.671
1799.53	47.6215
1800.55	52.3862
1801.56	43.7194
1802.58	48.5253
1803.59	46.6311
1804.61	48.5697
1805.62	45.7169
1806.64	44.7838
1807.65	44.7895
1808.66	48.6411
1809.68	45.7496
1810.69	52.4983
1811.7	44.7722
1812.72	44.7727
1813.73	48.649
1814.74	50.6189
1815.76	45.8197
1816.77	51.6233
1817.78	45.7891
1818.79	50.6214
1819.8	46.7641
1820.82	43.8784
1821.83	45.8292
1822.84	48.7462
1823.85	47.7718
1824.86	49.7033
1825.87	46.8101
1826.88	52.6175
1827.89	49.7203
1828.9	43.8994
1829.91	45.8158
1830.92	47.7271
1831.93	44.8337
1832.94	43.8852
1833.95	48.7379
1834.96	50.6358
1835.97	51.5184
1836.98	48.7912
1837.99	45.7255
1839	45.7152
1840	48.6797
1841.01	48.5764
1842.02	48.4799
1843.03	49.3955
1844.04	46.4949
1845.04	48.4191
1846.05	48.4268
1847.06	44.6045
1848.07	45.4054
1849.07	50.2215
1850.08	48.2516
1851.09	43.3804
1852.09	49.1065
1853.1	49.0969
1854.1	50.0301
1855.11	50.9293
1856.11	52.7889
1857.12	51.8164
1858.12	49.8751
1859.13	53.6536
1860.13	50.7408
1861.14	49.7997
1862.14	51.7348
1863.15	56.4755
1864.15	52.5964
1865.15	51.5951
1866.16	52.4754
1867.16	48.5709
1868.16	56.1086
1869.17	49.4405
1870.17	58.9301
1871.17	55.1118
1872.17	56.0343
1873.18	54.094
1874.18	55.0143
1875.18	54.0081
1876.18	55.8146
1877.18	55.7478
1878.18	52.8265
1879.19	58.5853
1880.19	52.9451
1881.19	54.8256
1882.19	52.8467
1883.19	48.9538
1884.19	58.3175
1885.19	55.5127
1886.19	52.746
1887.19	54.6203
1888.19	47.0156
1889.19	53.5373
1890.19	65.7369
1891.19	51.6434
1892.18	59.1591
1893.18	53.4781
1894.18	55.2681
1895.18	61.8117
1896.18	49.6087
1897.18	61.8606
1898.17	51.5237
1899.17	58.0674
1900.17	55.2021
1901.16	53.315
1902.16	52.4103
1903.16	53.3646
1904.16	54.2778
1905.15	56.1422
1906.15	54.2337
1907.14	55.1273
1908.14	52.3103
1909.14	48.5684
1910.13	54.2504
1911.13	51.4861
1912.12	58.0887
1913.12	51.4798
1914.11	56.21
1915.11	57.2028
1916.1	51.5566
1917.1	52.4674
1918.09	54.3202
1919.08	52.4635
1920.08	52.5317
1921.07	55.37
1922.06	56.3553
1923.06	51.613
1924.05	50.6395
1925.04	57.2212
1926.04	53.4733
1927.03	55.4214
1928.02	54.5034
1929.01	48.8356
1930	58.3535
1931	55.5629
1931.99	54.6014
1932.98	54.5633
1933.97	60.26
1934.96	52.8174
1935.95	55.7903
1936.94	50.9652
1937.93	57.578
1938.92	55.6647
1939.91	56.6433
1940.9	53.8173
1941.89	54.8154
1942.88	57.697
1943.87	53.8403
1944.86	51.009
1945.85	54.8761
1946.84	44.3873
1947.83	55.8489
1948.82	54.8794
1949.8	48.2118
1950.79	54.0232
1951.78	54.1019
1952.77	53.1803
1953.76	49.3382
1954.74	54.9764
1955.73	52.0668
1956.72	52.1507
1957.7	55.0768
1958.69	45.4877
1959.68	52.192
1960.66	48.3173
1961.65	50.1961
1962.63	51.1508
1963.62	54.9927
1964.61	55.0043
1965.59	49.2305
1966.58	51.1728
1967.56	49.269
1968.55	50.2331
1969.53	49.2382
1970.52	50.1358
1971.5	50.0994
1972.48	52.0112
1973.47	49.116
1974.45	50.995
1975.44	53.8689
1976.42	49.0955
1977.4	56.7667
1978.39	47.1436
1979.37	49.039
1980.35	55.7472
1981.33	47.0877
1982.31	54.7259
1983.3	47.0282
1984.28	54.641
1985.26	48.8722
1986.24	46.9378
1987.22	48.8606
1988.21	49.7732
1989.19	47.7616
1990.17	46.7405
1991.15	48.5539
1992.13	51.2383
1993.11	47.6481
1994.09	52.6458
1995.07	51.8902
1996.05	48.5143
1997.03	47.7611
1998.01	48.6872
1998.99	48.9038
1999.97	52.4975
2000.95	48.7248
2001.92	53.3799
2002.9	52.3957
2003.88	48.1509
2004.86	48.1062
2005.84	51.5969
2006.81	49.7105
2007.79	51.3311
2008.77	51.8076
2009.75	49.1727
2010.73	48.1661
2011.7	48.7581
2012.68	52.3238
2013.67	50.3817
2014.66	49.359
2015.64	54.0294
2016.63	54.0508
2017.62	54.0846
2018.61	44.626
2019.6	52.0536
2020.58	50.1556
2021.57	52.9649
2022.56	48.2661
2023.55	44.4771
2024.54	50.9802
2025.52	53.7113
2026.51	53.6651
2027.5	52.8684
2028.48	48.1346
2029.47	50.0797
2030.45	52.7241
2031.44	51.8122
2032.43	51.8191
2033.41	55.6217
2034.4	55.6264
2035.38	54.6061
2036.37	53.7859
2037.35	50.0278
2038.34	49.0768
2039.32	55.5838
2040.31	53.6676
2041.29	53.6127
2042.27	51.722
2043.26	48.9033
2044.24	52.6897
2045.23	46.1307
2046.21	44.3549
2047.19	51.7788
2048.17	47.0503
2049.16	44.263
2050.14	47.1109
2051.12	48.079
2052.11	52.7182
2053.09	47.1295
2054.07	49.9841
2055.05	50.9341
2056.03	49.0379
2057.01	49.955
2058	50.9001
2058.98	48.1306
2059.96	47.2156
2060.94	55.6191
2061.92	51.895
2062.9	49.0958
2063.88	44.4389
2064.86	51.0168
2065.84	52.0024
2066.82	45.4597
2067.8	52.9935
2068.78	56.7764
2069.76	55.8196
2070.73	55.8126
2071.71	51.1459
2072.69	53.0992
2073.67	54.0295
2074.65	50.2741
2075.63	56.9353
2076.6	54.1642
2077.58	49.4176
2078.56	54.1205
2079.54	56.9806
2080.51	48.5324
2081.49	57.9775
2082.47	46.6373
2083.45	56.0917
2084.42	51.3613
2085.4	53.2517
2086.37	54.2126
2087.35	52.3605
2088.32	51.4273
2089.3	53.3274
2090.28	57.1511
2091.25	53.3777
2092.23	55.3135
2093.2	54.432
2094.18	58.2844
2095.15	52.5898
2096.13	54.4584
2097.1	47.7924
2098.07	50.6088
2099.05	54.3909
2100.02	55.3299
2101	57.2371
2101.97	55.3716
2102.94	54.4156
2103.92	50.5889
2104.89	49.6475
2105.86	52.5303
2106.83	54.4535
2107.8	55.4054
2108.78	58.1974
2109.75	53.447
2110.72	57.2564
2111.69	62.9494
2112.66	54.3815
2113.63	54.4103
2114.61	55.3671
2115.58	53.464
2116.55	48.6881
2117.52	54.3651
2118.49	54.3421
2119.46	52.3892
2120.43	56.1383
2121.4	56.1495
2122.37	50.5059
2123.34	49.5843
2124.31	51.4772
2125.28	50.46
2126.25	51.3347
2127.21	57.9069
2128.18	56.9356
2129.15	54.0884
2130.12	55.0187
2131.09	55.0009
2132.06	49.3019
2133.02	53.0452
2133.99	53.9851
2134.96	55.8736
2135.93	53.0291
2136.89	52.0351
2137.86	49.2153
2138.83	52.0231
2139.79	50.1478
2140.76	55.7559
2141.73	58.5649
2142.69	57.5913
2143.66	49.1552
2144.62	51.8766
2145.59	50.9367
2146.55	53.7455
2147.52	53.7216
2148.48	53.6935
2149.45	55.5359
2150.42	54.5316
2151.38	57.3283
2152.34	57.3545
2153.31	54.5205
2154.27	53.5532
2155.24	54.411
2156.2	55.2711
2157.16	51.5119
2158.13	53.3994
2159.09	49.6665
2160.05	54.3061
2161.01	52.3875
2161.98	54.2325
2162.94	54.2273
2163.9	53.2689
2164.86	56.0244
2165.83	49.4986
2166.79	56.9397
2167.75	56.8957
2168.71	60.533
2169.67	54.9731
2170.63	57.8328
2171.59	58.746
2172.56	57.7163
2173.51	55.8354
2174.48	55.8488
2175.44	57.7072
2176.4	60.4799
2177.36	56.7437
2178.32	56.745
2179.28	55.7806
2180.23	56.7106
2181.19	54.8423
2182.15	50.1819
2183.11	51.0886
2184.07	51.0391
2185.03	53.8004
2185.99	55.6723
2186.95	56.6431
2187.9	55.7749
2188.86	54.821
2189.82	51.9786
2190.78	50.1001
2191.73	54.7455
2192.69	51.0521
2193.65	59.4337
2194.6	52.0828
2195.56	54.8641
2196.52	55.7354
2197.47	54.754
2198.43	55.6792
2199.38	57.5982
2200.34	64.1899
2201.3	56.8444
2202.25	53.8684
2203.21	49.3081
2204.16	55.0856
2205.12	52.1875
2206.07	55.7795
2207.03	52.0543
2207.98	57.6652
2208.93	58.6416
2209.89	58.6585
2210.84	53.0837
2211.8	54.0484
2212.75	52.2166
2213.7	54.0576
2214.66	54.0824
2215.61	54.1158
2216.56	55.9848
2217.51	54.1096
2218.47	55.0454
2219.42	53.201
2220.37	56.9657
2221.32	59.7557
2222.27	57.8322
2223.23	56.9006
2224.18	63.489
2225.13	56.0712
2226.08	55.188
2227.03	66.4774
2227.98	50.5702
2228.93	62.7447
2229.88	56.1836
2230.83	55.293
2231.78	57.2199
2232.73	57.2637
2233.68	57.3046
2234.63	56.3844
2235.58	56.3415
2236.53	55.3919
2237.48	55.412
2238.43	53.6037
2239.38	56.4973
2240.33	52.6995
2241.27	48.9479
2242.22	64.0591
2243.17	54.6394
2244.12	56.5036
2245.07	54.6395
2246.01	57.5401
2246.96	58.5244
2247.91	56.6567
2248.85	52.8594
2249.8	57.591
2250.75	56.6316
2251.69	57.532
2252.64	58.4908
2253.59	54.7857
2254.53	53.8865
2255.48	58.6317
2256.42	52.0067
2257.37	59.6344
2258.32	53.9647
2259.26	58.7321
2260.2	54.0051
2261.15	52.1267
2262.1	55.9648
2263.04	58.849
2263.98	55.1029
2264.93	59.9526
2265.87	54.2599
2266.81	53.2771
2267.76	56.0962
2268.7	60.828
2269.65	51.3253
2270.59	59.0311
2271.53	58.1164
2272.47	59.1047
2273.42	56.2438
2274.36	57.2118
2275.3	55.309
2276.24	54.3634
2277.18	54.4119
2278.13	60.2416
2279.07	57.3995
2280.01	60.2355
2280.95	61.1334
2281.89	57.27
2282.83	59.2169
2283.77	58.324
2284.71	54.5715
2285.65	62.3048
2286.59	55.5339
2287.54	53.6682
2288.47	55.6186
2289.41	60.3866
2290.35	64.1539
2291.29	56.4653
2292.23	55.5584
2293.17	63.31
2294.11	56.5936
2295.05	55.5984
2295.99	59.417
2296.93	55.5187
2297.86	58.4411
2298.8	55.6068
2299.74	56.6177
2300.68	58.5494
2301.61	65.3357
2302.55	56.6461
2303.49	56.6379
2304.43	53.756
2305.36	55.7194
2306.3	54.7727
2307.24	56.7141
2308.17	64.4245
2309.11	58.6177
2310.04	57.7018
2310.98	61.5881
2311.92	58.5929
2312.85	56.6067
2313.79	58.5517
2314.72	56.693
2315.66	58.6615
2316.59	55.6874
2317.52	57.5949
2318.46	53.7397
2319.39	58.5305
2320.33	64.2993
2321.26	56.5936
2322.2	69.1997
2323.13	72.1424
2324.06	73.1263
2325	82.7696
2325.93	93.2989
2326.86	126.024
2327.79	280.171
2328.73	633.847
2329.66	242.364
2330.59	107.499
2331.52	78.5899
2332.46	68.0137
2333.39	63.156
2334.32	60.2374
2335.25	65.0027
2336.18	60.1936
2337.11	60.1769
2338.04	58.2395
2338.97	60.1486
2339.91	61.1097
2340.84	62.0351
2341.77	54.2819
2342.7	58.0719
2343.63	59.0181
2344.56	58.0574
2345.49	56.129
2346.41	56.0822
2347.34	58.9377
2348.27	65.6375
2349.2	56.0667
2350.13	55.9789
2351.06	62.371
2351.99	59.7545
2352.91	62.5237
2353.84	62.4306
2354.77	56.7148
2355.7	50.9997
2356.63	54.7697
2357.55	56.6018
2358.48	55.6176
2359.41	61.2893
2360.33	60.303
2361.26	53.6048
2362.19	56.3913
2363.11	56.334
2364.04	61.9769
2364.97	60.9943