File: Data/3-Raman/raw/bu02aw-a-ff1-fi02-v_150 (500nm)_532nm_edge_100%_x100_vis_lwd_h50um_30sx2_01.txt
#Acq. time (s)=	30
#Accumulations=	2
#Range (cm-¹)=	99...4000
#Windows=	1
#Auto scanning=	Off
#Autofocus=	Off
#Macrospot=	Off
#AutoExposure=	Off
#Spike filter=	Multiple accum.
#Delay time (s)=	2
#Binning=	1
#Readout mode=	Signal
#DeNoise=	Off
#ICS correction=	On
#Dark correction=	Off
#Inst. Process=	Off
#Detector Gain=	Best Dynamic
#Detector ADC=	50 kHz HS
#Detector temperature (°C)=	-60.09
#Instrument=	LabRAM HR Evol
#Detector=	SIN-EM FIVIS
#Objective=	x100_VIS_LWD
#Grating=	150 (500nm)
#ND Filter=	100%
#Laser=	532nm_Edge
#Hole=	49.98
#Temperature=	0
#Range=	Visible
#StageXY=	75x50mm Scan+
#StageZ=	Z motor
#X (µm)=	0
#Y (µm)=	0
#Z (µm)=	-17.7
#Full time(mm:ss)=	1:04
#Project=	21_11_26
#Sample=	BU02Aw
#Site=
#Title=	BU02aW-A-FF1-FI02-V_150 (500nm)_532nm_Edge_100%_x100_VIS_LWD_H50um_30sX2
#Remark=
#Date=	26.11.2021 11:19
#Acquired=	26.11.2021 11:19:12
102.91	8366.46
107.534	6666.62
112.156	5553.07
116.775	4401.05
121.392	3651.81
126.005	3195.07
130.617	2813.02
135.227	2595.75
139.835	2646.57
144.439	2621.41
149.042	2407.09
153.643	2451.11
158.242	2892.83
162.839	3046.44
167.431	2671.2
172.023	2165.7
176.613	1735.59
181.198	1473.53
185.783	1439.17
190.366	1546.78
194.947	1574.93
199.524	1506.46
204.1	1453.83
208.674	1517.32
213.243	1643.2
217.813	1754.4
222.38	1861.93
226.945	1892.2
231.506	1689.79
236.066	1756.17
240.625	1805.19
245.179	1535.4
249.732	1389.03
254.284	1352.41
258.831	1321.94
263.378	1486.03
267.923	1813.8
272.464	2009.98
277.004	1568.23
281.54	1185.65
286.076	1074.08
290.61	1145.12
295.139	1253.36
299.669	1312.21
304.196	1383.43
308.718	1620.04
313.241	1874.17
317.759	1725.05
322.278	1451.53
326.794	1239.53
331.305	1158.6
335.817	1064.8
340.324	1009.16
344.832	1021.59
349.334	1028.67
353.837	1111.74
358.338	1133.47
362.834	1135.45
367.33	1145.02
371.822	1136.34
376.314	1128.11
380.802	1161.11
385.289	1156.1
389.772	1223
394.255	1382.01
398.734	1490.42
403.213	1682.34
407.688	1763.1
412.162	1732.83
416.632	1550.47
421.102	1351.33
425.568	1248.8
430.033	1338.08
434.495	1528.36
438.956	1597.52
443.413	1493.47
447.87	1427.77
452.323	1365.37
456.776	1457.83
461.224	1433.62
465.673	1428.99
470.117	1434.8
474.561	1560.67
479.001	1825.41
483.438	2104.46
487.876	2332.66
492.309	2751.98
496.742	3389.78
501.172	4200.84
505.601	5005.61
510.025	5420.48
514.448	5687.06
518.871	5729.25
523.289	5560.72
527.707	5587.83
532.121	5494.66
536.533	5250.9
540.945	5005.82
545.353	4866.75
549.758	5117.47
554.164	5259.87
558.565	4756.23
562.965	4124.32
567.364	3870.97
571.759	3788.11
576.151	3704.38
580.544	3541.36
584.933	3542.69
589.319	3738.92
593.706	4276.19
598.088	5329.56
602.468	5800.92
606.848	4745.35
611.224	3584.63
615.598	2921.9
619.972	2403.17
624.341	2110.13
628.709	1955.92
633.074	1797.92
637.44	1611.72
641.801	1459.3
646.16	1419.51
650.517	1389.47
654.874	1471.82
659.227	1515.48
663.578	1457.59
667.927	1325.79
672.275	1142.42
676.62	1027.35
680.962	911.826
685.302	881.954
689.643	804.196
693.979	800.614
698.313	776.359
702.645	763.102
706.975	770.173
711.305	745.439
715.631	761.922
719.955	764.303
724.276	740.42
728.596	786.761
732.913	801.751
737.231	849.2
741.544	898.456
745.856	884.421
750.165	900.883
754.472	961.284
758.778	995.369
763.081	989.999
767.384	975.134
771.683	982.047
775.98	1004.14
780.275	1001.58
784.568	1055.8
788.859	1057.66
793.147	1041.07
797.434	1028.27
801.719	959.905
806.004	892.39
810.284	832.947
814.563	764.842
818.839	718.841
823.114	706.917
827.386	662.157
831.657	614.103
835.925	575.919
840.192	553.084
844.456	545.609
848.719	555.583
852.979	514.488
857.237	524.142
861.493	516.145
865.748	506.962
870	484.429
874.25	514.561
878.499	486.353
882.745	505.198
886.989	503.001
891.231	500.515
895.471	475.037
899.71	475.446
903.946	530.084
908.18	514.587
912.412	519.058
916.642	538.971
920.87	555.478
925.096	608.36
929.321	655.295
933.543	718.975
937.763	848.927
941.981	979.344
946.197	1049.34
950.412	1177.76
954.622	1307.16
958.832	1437.42
963.04	1671.72
967.246	1992.75
971.451	2491.63
975.653	3298.68
979.853	4207.83
984.052	4729.27
988.248	4170.37
992.442	3119.15
996.633	2535.97
1000.82	2322.38
1005.01	2412.25
1009.2	2880.97
1013.38	3695.83
1017.57	4667.33
1021.75	5253.85
1025.92	5048.37
1030.1	4548.07
1034.27	4073.68
1038.45	3822.71
1042.62	3385.55
1046.78	2948.42
1050.95	2595.67
1055.12	2428.12
1059.28	2477.38
1063.44	2554.11
1067.6	2491.89
1071.75	2395.11
1075.91	2261.07
1080.06	1990.26
1084.21	1766.31
1088.36	1510.98
1092.51	1325.71
1096.65	1195.49
1100.8	1135.14
1104.94	1104.87
1109.08	1240.68
1113.21	1360.32
1117.35	1512.54
1121.48	1607.64
1125.61	1605.55
1129.74	1458.92
1133.87	1248.73
1137.99	1078.46
1142.12	1024.67
1146.24	1089.25
1150.36	1047.56
1154.48	900.969
1158.59	710.476
1162.71	661.09
1166.82	597.033
1170.93	533.883
1175.04	502.574
1179.14	486.673
1183.25	441.969
1187.35	408.529
1191.45	404.705
1195.55	404.867
1199.65	395.702
1203.74	408.882
1207.83	397.582
1211.92	391.421
1216.01	383.294
1220.1	378.268
1224.19	407.489
1228.27	416.61
1232.35	427.851
1236.43	449.386
1240.51	511.12
1244.58	518.747
1248.66	527.564
1252.73	598.571
1256.8	837.573
1260.87	1139.94
1264.93	840.73
1269	733.409
1273.06	833.468
1277.12	3467.57
1281.18	7629.32
1285.23	3016.02
1289.29	906.131
1293.34	652.959
1297.39	618.006
1301.44	593.041
1305.49	585.083
1309.53	555.912
1313.58	539.78
1317.62	517.412
1321.66	553.361
1325.7	534.72
1329.73	533.128
1333.77	522.449
1337.8	546.701
1341.83	509.749
1345.86	519.808
1349.88	531.811
1353.91	561.693
1357.93	606.391
1361.95	677.647
1365.97	847.751
1369.99	802.002
1374	823.687
1378.02	1335.47
1382.03	8933.75
1386.04	10030.2
1390.05	2529.12
1394.05	872.565
1398.06	767.567
1402.06	1049.55
1406.06	1508.04
1410.06	905.392
1414.05	581.38
1418.05	535.305
1422.04	500.035
1426.03	454.791
1430.02	442.881
1434.01	405.336
1438	362.851
1441.98	367.767
1445.96	346.961
1449.94	348.84
1453.92	330.931
1457.9	320.892
1461.87	313.763
1465.85	305.563
1469.82	304.242
1473.78	285.289
1477.75	289.88
1481.72	275.807
1485.68	295.019
1489.65	298.524
1493.61	289.355
1497.56	279.242
1501.52	275.024
1505.47	283.506
1509.43	277.475
1513.38	281.186
1517.33	287.82
1521.27	288.657
1525.22	275.934
1529.16	283.604
1533.11	277.733
1537.05	290.288
1540.98	298.002
1544.92	280.522
1548.86	291.145
1552.79	290.139
1556.72	280.383
1560.65	298.666
1564.58	283.031
1568.5	272.221
1572.43	273.967
1576.35	309.505
1580.27	290.94
1584.19	276.252
1588.1	272.165
1592.02	270.965
1595.93	294.767
1599.84	275.289
1603.75	290.429
1607.66	285.444
1611.57	283.349
1615.47	303.319
1619.37	295.532
1623.27	291.564
1627.17	285.731
1631.07	304.822
1634.97	290.508
1638.86	298.196
1642.75	283.938
1646.64	289.85
1650.53	295.798
1654.42	293.133
1658.3	297.16
1662.18	293.494
1666.07	285.924
1669.94	298.505
1673.82	282.156
1677.7	280.209
1681.57	291.564
1685.44	274.99
1689.31	293.903
1693.18	283.023
1697.05	273.086
1700.92	279.367
1704.78	270.312
1708.64	285.024
1712.5	282.524
1716.36	285.721
1720.21	262.438
1724.07	290.221
1727.92	283.017
1731.77	278.617
1735.62	281.76
1739.47	282.05
1743.32	276.704
1747.16	276.054
1751.01	291.375
1754.85	280.766
1758.69	284.252
1762.52	278
1766.36	266.903
1770.19	275.403
1774.02	287.771
1777.85	271.32
1781.68	273.562
1785.51	284.258
1789.33	285.669
1793.16	281.479
1796.98	276.342
1800.8	270.234
1804.62	271.463
1808.43	275.497
1812.25	281.392
1816.06	267.435
1819.87	276.937
1823.68	282.594
1827.49	266.499
1831.3	280.515
1835.1	284.076
1838.9	280.053
1842.71	293.861
1846.51	291.601
1850.3	279.064
1854.1	289.844
1857.89	295.838
1861.69	299.847
1865.48	300.082
1869.27	307.773
1873.05	301.567
1876.84	307.47
1880.62	305.066
1884.4	331.373
1888.19	313.438
1891.96	328.102
1895.74	308.725
1899.52	308.675
1903.29	318.883
1907.06	309.827
1910.83	291.579
1914.6	301.997
1918.37	301.381
1922.13	337.016
1925.9	313.527
1929.66	315.992
1933.42	322.215
1937.18	308.886
1940.94	305.763
1944.69	311.039
1948.44	291.964
1952.2	321.393
1955.95	301.915
1959.69	301.046
1963.44	287.865
1967.19	299.087
1970.93	289.558
1974.67	295.876
1978.41	293.69
1982.15	297.073
1985.89	301.328
1989.62	317.664
1993.35	294.778
1997.09	305.38
2000.82	299.183
2004.55	314.32
2008.27	310.881
2012	310.146
2015.72	308.506
2019.44	309.775
2023.16	311.206
2026.88	320.152
2030.6	298.892
2034.31	334.54
2038.03	309.887
2041.74	322.735
2045.45	310.839
2049.16	317.261
2052.86	318.253
2056.57	302.774
2060.27	303.021
2063.98	331.922
2067.67	323.286
2071.37	306.355
2075.07	305.98
2078.77	311.176
2082.46	319.193
2086.15	296.567
2089.84	332.048
2093.53	306.092
2097.22	314.655
2100.9	338.983
2104.59	308.331
2108.27	321.336
2111.95	311.041
2115.63	308.177
2119.31	315.498
2122.98	327.327
2126.66	318.655
2130.33	311.804
2134	322.523
2137.67	332.269
2141.34	306.861
2145	319.261
2148.67	313.201
2152.33	317.256
2155.99	327.727
2159.65	310.719
2163.31	303.855
2166.96	321.699
2170.62	324.059
2174.27	321.084
2177.92	324.558
2181.57	334.443
2185.22	324.293
2188.87	315.144
2192.51	324.313
2196.15	338.176
2199.8	322.069
2203.44	324.209
2207.07	307.231
2210.71	337.804
2214.35	329.14
2217.98	329.637
2221.61	325.551
2225.24	337.107
2228.87	314.591
2232.5	316.923
2236.12	328.532
2239.75	324.433
2243.37	332.365
2246.99	326.38
2250.61	323.181
2254.23	320.007
2257.85	326.183
2261.46	321.155
2265.07	330.117
2268.68	328.825
2272.29	322.902
2275.9	325.343
2279.51	322.042
2283.11	338.338
2286.72	315.928
2290.32	325.616
2293.92	321.086
2297.52	347.79
2301.11	330.032
2304.71	351.044
2308.3	325.557
2311.9	327.502
2315.49	344.563
2319.08	399.47
2322.66	772.565
2326.25	1364.22
2329.84	674.493
2333.42	375.301
2337	342.728
2340.58	346.917
2344.16	336.018
2347.73	342.939
2351.31	333.888
2354.88	337.941
2358.45	329.828
2362.03	340.347
2365.59	333.162
2369.16	314.895
2372.73	322.7
2376.29	340.619
2379.85	350.18
2383.41	310.926
2386.97	315.059
2390.53	344.037
2394.09	335.391
2397.64	331.447
2401.2	323.954
2404.75	334.973
2408.3	354.287
2411.85	326.071
2415.39	338.285
2418.94	323.033
2422.48	332.641
2426.03	345.12
2429.57	323.569
2433.11	329.751
2436.64	328.616
2440.18	318.217
2443.72	338.528
2447.25	332.803
2450.78	331.799
2454.31	323.337
2457.84	348.482
2461.37	336.678
2464.89	358.755
2468.42	331.518
2471.94	323.394
2475.46	328.885
2478.98	342.803
2482.5	340.737
2486.01	336.662
2489.53	337.09
2493.04	328.306
2496.55	325.925
2500.06	330.223
2503.57	333.463
2507.08	335.703
2510.58	342.52
2514.09	328.868
2517.59	352.496
2521.09	325.101
2524.59	339.227
2528.09	343.477
2531.59	328.407
2535.08	331.871
2538.58	340.044
2542.07	329.839
2545.56	337.327
2549.05	329.268
2552.54	329.531
2556.02	341.913
2559.51	349.862
2562.99	328.137
2566.47	331.591
2569.95	337.029
2573.43	343.517
2576.91	345.418
2580.38	338.933
2583.85	333.373
2587.33	340.072
2590.8	343.877
2594.27	357.979
2597.74	323.488
2601.2	350.063
2604.67	338.438
2608.13	351.503
2611.59	347.986
2615.06	351.905
2618.51	349.234
2621.97	335.844
2625.43	332.954
2628.88	341.502
2632.33	339.425
2635.79	350.699
2639.24	335.969
2642.69	337.484
2646.13	336.061
2649.58	354.666
2653.02	351.21
2656.47	344.82
2659.91	346.926
2663.35	330.99
2666.79	364.226
2670.22	349.225
2673.66	357.782
2677.09	351.348
2680.52	361.845
2683.95	349.019
2687.39	337.294
2690.81	348.189
2694.24	355.465
2697.66	366.382
2701.09	348.521
2704.51	364.175
2707.93	345.427
2711.35	352.037
2714.77	341.045
2718.18	359.906
2721.6	349.043
2725.01	357.797
2728.42	358.193
2731.84	363.285
2735.24	350.582
2738.65	354.72
2742.06	346.653
2745.46	348.83
2748.86	369.754
2752.27	358.742
2755.67	353.328
2759.07	348.81
2762.46	372.552
2765.86	350.044
2769.25	356.686
2772.65	332.171
2776.04	353.8
2779.43	351.809
2782.82	352.596
2786.2	358.059
2789.59	341.873
2792.98	364.23
2796.36	374.336
2799.74	362.838
2803.12	359.738
2806.5	375.394
2809.88	357.3
2813.25	366.352
2816.63	351.058
2820	356.335
2823.37	358.858
2826.74	372.62
2830.11	370.546
2833.48	362.933
2836.84	378.682
2840.21	366.547
2843.57	370.32
2846.93	383.504
2850.29	370.727
2853.65	365.483
2857.01	363.923
2860.36	386.726
2863.72	381.535
2867.07	387.596
2870.42	377.72
2873.77	395.041
2877.12	372.886
2880.47	379.859
2883.81	372.697
2887.16	402.276
2890.5	377.144
2893.84	398.243
2897.18	383.35
2900.52	387.302
2903.86	375.113
2907.19	395.044
2910.53	373.307
2913.86	401.695
2917.19	392.203
2920.52	379.817
2923.85	407.138
2927.18	395.642
2930.51	396.383
2933.83	409.352
2937.15	394.878
2940.48	404.939
2943.8	401.797
2947.11	405.262
2950.43	404.971
2953.75	410.306
2957.06	394.041
2960.38	399.455
2963.69	406.776
2967	416.929
2970.31	422.513
2973.62	414.105
2976.92	412.277
2980.23	418.023
2983.53	432.168
2986.84	403.167
2990.14	435.206
2993.44	433.466
2996.73	412.957
3000.03	425.353
3003.33	442.456
3006.62	438.877
3009.91	445.684
3013.2	441.221
3016.49	448.069
3019.78	441.714
3023.07	457.041
3026.35	445.959
3029.64	458.48
3032.92	438.88
3036.2	462.723
3039.48	457.257
3042.76	448.005
3046.04	479.457
3049.32	461.695
3052.59	477.08
3055.86	465.948
3059.14	475.652
3062.41	471.929
3065.68	479.661
3068.94	480.693
3072.21	480.673
3075.48	491.614
3078.74	515.371
3082	486.817
3085.26	513.688
3088.52	532.022
3091.78	501.13
3095.04	527.266
3098.29	519.475
3101.55	524.378
3104.8	532.036
3108.05	570.394
3111.3	569.682
3114.55	544.037
3117.8	559.373
3121.04	572.826
3124.29	588.19
3127.53	603.549
3130.77	614.132
3134.02	614.244
3137.25	621.009
3140.49	643.949
3143.73	662.118
3146.96	665.992
3150.2	679.446
3153.43	676.704
3156.66	695.871
3159.89	701.707
3163.12	734.237
3166.35	723.834
3169.57	746.764
3172.8	764.868
3176.02	785.8
3179.24	811.431
3182.46	810.334
3185.68	845.496
3188.9	860.522
3192.12	885.047
3195.33	908.603
3198.55	892.12
3201.76	952.764
3204.97	952.482
3208.18	985.544
3211.39	1002.46
3214.6	1040.37
3217.8	1108.79
3221.01	1149.61
3224.21	1186.66
3227.41	1224.79
3230.61	1261.04
3233.81	1310.72
3237.01	1377.45
3240.21	1417.86
3243.4	1477.42
3246.59	1529.48
3249.79	1596.84
3252.98	1648.22
3256.17	1736.9
3259.36	1810.36
3262.54	1885.55
3265.73	1864.99
3268.92	1907.21
3272.1	1945.42
3275.28	2026.5
3278.46	2029.22
3281.64	2040.11
3284.82	2029.61
3288	2017.27
3291.17	2032.42
3294.35	2068.68
3297.52	2033.39
3300.69	2040.06
3303.86	1993.88
3307.03	1972.91
3310.2	2005.97
3313.36	1954.1
3316.53	1974.36
3319.69	1979.36
3322.85	1980.48
3326.02	1950.38
3329.18	1930.74
3332.33	1967.91
3335.49	1973.03
3338.65	1995.32
3341.8	2020.55
3344.95	2059.01
3348.11	2087.58
3351.26	2120.41
3354.41	2119.28
3357.56	2206.05
3360.7	2223.2
3363.85	2283.98
3366.99	2269.4
3370.13	2311.53
3373.28	2337.75
3376.42	2324.62
3379.56	2338.02
3382.69	2369.5
3385.83	2367.81
3388.97	2407
3392.1	2391.37
3395.23	2447.58
3398.36	2465.32
3401.49	2559.36
3404.62	2561.74
3407.75	2600.46
3410.88	2611.83
3414	2630.76
3417.13	2625.28
3420.25	2583.38
3423.37	2524.96
3426.49	2441.14
3429.61	2371.13
3432.73	2270.21
3435.84	2338.78
3438.96	2360.01
3442.07	2410.15
3445.18	2521.27
3448.29	2728.14
3451.4	2937.61
3454.51	3190.27
3457.62	3506.33
3460.72	3914.71
3463.83	4294.81
3466.93	4801.36
3470.03	5180.06
3473.13	5525.77
3476.23	5682.12
3479.33	5782.68
3482.43	5696.1
3485.53	5558.78
3488.62	5281.32
3491.71	4970.08
3494.81	4705.69
3497.9	4371.45
3500.99	3987.13
3504.07	3721.93
3507.16	3412.04
3510.25	3186.25
3513.33	2946.57
3516.41	2679.56
3519.5	2482.57
3522.58	2225.33
3525.66	2088.88
3528.73	1947.28
3531.81	1843.31
3534.89	1765.3
3537.96	1678.9
3541.03	1587.99
3544.11	1601.59
3547.18	1563.01
3550.25	1554.8
3553.32	1563.2
3556.38	1544.05
3559.45	1493.9
3562.51	1511.89
3565.58	1487.89
3568.64	1459.85
3571.7	1409.5
3574.76	1311.97
3577.82	1278.03
3580.87	1219.3
3583.93	1176.6
3586.98	1132.85
3590.04	1091.94
3593.09	1128.65
3596.14	1095.17
3599.19	1113.72
3602.24	1125.63
3605.29	1093.87
3608.33	1102.73
3611.38	1094.55
3614.42	1093.89
3617.46	1068.62
3620.5	1097.24
3623.54	1107.95
3626.58	1109.25
3629.62	1079.52
3632.65	1121.35
3635.69	1081.17
3638.72	1052.59
3641.76	1061.8
3644.79	1048.55
3647.82	1024.28
3650.84	1034.54
3653.87	1044.93
3656.9	1010.76
3659.92	1021.17
3662.95	1053.15
3665.97	1045.41
3668.99	1023.04
3672.01	1031.07
3675.03	970.293
3678.05	946.317
3681.07	891.194
3684.08	802.875
3687.1	758.908
3690.11	681.792
3693.12	635.843
3696.13	598.367
3699.14	552.199
3702.15	552.58
3705.16	539.67
3708.16	533.386
3711.17	530.833
3714.17	515.873
3717.17	500.837
3720.17	520.084
3723.17	517.385
3726.17	486.075
3729.17	482.327
3732.16	489.971
3735.16	468.998
3738.15	469.876
3741.14	455.481
3744.13	444.846
3747.13	438.938
3750.11	435.843
3753.1	439.369
3756.09	425.796
3759.07	396.12
3762.06	414.828
3765.04	429.686
3768.02	407.606
3771	401.674
3773.98	403.352
3776.96	405.058
3779.94	386.943
3782.91	405.707
3785.89	400.856
3788.86	405.472
3791.83	382.74
3794.8	405.377
3797.77	383.686
3800.74	371.456
3803.71	401.76
3806.68	387.71
3809.64	381.222
3812.61	377.588
3815.57	386.253
3818.53	375.071
3821.49	387.553
3824.45	375.44
3827.41	369.972
3830.36	372.086
3833.32	356.178
3836.27	368.76
3839.23	359.531
3842.18	374.054
3845.13	359.105
3848.08	353.662
3851.03	358.706
3853.98	356.15
3856.92	354.552
3859.87	361.552
3862.81	359.008
3865.75	356.437
3868.7	359.607
3871.64	331.126
3874.57	362.056
3877.51	336.389
3880.45	367.307
3883.39	355.946
3886.32	351.261
3889.25	313.862
3892.18	329.315
3895.12	347.642
3898.05	342.847
3900.97	336.09
3903.9	352.401
3906.83	333.095
3909.75	347.476
3912.68	347.405
3915.6	339.614
3918.52	334.688
3921.44	333.664
3924.36	324.896
3927.28	342.96
3930.2	335.084
3933.11	331.037
3936.03	319.411
3938.94	322.222
3941.86	327.005
3944.77	336.544
3947.68	325.996
3950.59	317.395
3953.49	310.731
3956.4	325.148
3959.31	333.853
3962.21	338.746
3965.12	319.693
3968.02	315.029
3970.92	317.093
3973.82	319.168
3976.72	314.515
3979.61	325.209
3982.51	333.967
3985.41	313.883
3988.3	311.081
3991.19	317.886
3994.09	313.112
3996.98	315.129
3999.87	302.705