File: Data/3-Raman/raw/bu02aw-a-ff1-fi01-v_1800 (450-850nm)_532nm_edge_100%_x100_vis_lwd_h50um_30sx2_edited.txt
#Acq. time (s)=	30
#Accumulations=	2
#Range (cm-¹)=	1200...2365
#Windows=	3
#Auto scanning=	Off
#Autofocus=	Off
#Macrospot=	Off
#AutoExposure=	Off
#Spike filter=	Multiple accum.
#Delay time (s)=	2
#Binning=	1
#Readout mode=	Signal
#DeNoise=	Off
#ICS correction=	On
#Dark correction=	Off
#Inst. Process=	Off
#Detector Gain=	Best Dynamic
#Detector ADC=	50 kHz HS
#Detector temperature (°C)=	-60.09
#Instrument=	LabRAM HR Evol
#Detector=	SIN-EM FIVIS
#Objective=	x100_VIS_LWD
#Grating=	1800 (450-850nm)
#ND Filter=	100%
#Laser=	532nm_Edge
#Hole=	49.98
#Temperature=	0
#Range=	Visible
#StageXY=	75x50mm Scan+
#StageZ=	Z motor
#X (µm)=	0
#Y (µm)=	0
#Z (µm)=	-10.3
#Full time(mm:ss)=	3:11
#Project=	21_11_26
#Sample=	BU02Aw
#Site=
#Title=	BU02aW-A-FF1-FI01-V_1800 (450-850nm)_532nm_Edge_100%_x100_VIS_LWD_H50um_30sX2
#Remark=
#Date=	26.11.2021 10:39
#Acquired=	26.11.2021 10:39:57
#Base:Fit=	26.11.2021 10:51:03
#Base:Fit=	26.11.2021 10:51:08
#Base:Fit=	26.11.2021 10:51:11
#Base:Fit=	26.11.2021 10:51:11
#Base:Fit=	26.11.2021 10:51:11
#Base:Fit=	26.11.2021 10:51:11
#Base:Fit=	26.11.2021 10:51:11
#Base:Fit=	26.11.2021 10:51:11
#Base:Fit=	26.11.2021 10:51:11
#Base:Fit=	26.11.2021 10:51:11
#Base:Fit=	26.11.2021 10:51:11
#Base:Fit=	26.11.2021 10:51:11
#Base:Fit=	26.11.2021 10:51:11
#Base:Fit=	26.11.2021 10:51:12
#Base:Fit=	26.11.2021 10:51:12
#Base:Fit=	26.11.2021 10:51:12
#Base:Edit=	26.11.2021 10:51:20
#Base:Edit=	26.11.2021 10:51:21
#Base:Edit=	26.11.2021 10:51:22
#Base:Edit=	26.11.2021 10:51:22
#Base:Edit=	26.11.2021 10:51:23
#Base:Fit=	26.11.2021 10:51:26
#Base:Edit=	26.11.2021 10:51:29
#Base:Edit=	26.11.2021 10:51:29
#Base:Edit=	26.11.2021 10:51:30
#Base:Edit=	26.11.2021 10:51:30
#Base:Edit=	26.11.2021 10:51:31
#Base:Edit=	26.11.2021 10:51:31
#Base:Sub=	26.11.2021 10:51:33
#Edit:Shape=	26.11.2021 10:52:28
#Edit:Shape=	26.11.2021 10:52:35
#Edit:Shape=	26.11.2021 10:53:25
1202.72	-1.16604
1203.84	1.1818
1204.95	-0.817142
1206.06	3.5974
1207.17	4.75672
1208.28	3.78494
1209.39	2.80365
1210.5	-0.309034
1211.61	-0.251455
1212.72	4.06247
1213.83	4.11035
1214.94	2.04284
1216.05	-1.09953
1217.16	2.10198
1218.27	1.04904
1219.38	-1.05816
1220.49	2.13728
1221.6	-1.03581
1222.71	1.06076
1223.81	4.18773
1224.92	4.15273
1226.03	2.03564
1227.14	3.0737
1228.25	0.887022
1229.35	5.00744
1230.46	0.848303
1231.57	1.79712
1232.67	2.81481
1233.78	2.77267
1234.89	3.79501
1235.99	2.71494
1237.1	3.71545
1238.2	7.83112
1239.31	0.40395
1240.41	1.393
1241.52	1.34418
1242.62	-0.814688
1243.73	3.33204
1244.83	1.1804
1245.94	3.19489
1247.04	3.12278
1248.14	4.106
1249.25	1.9409
1250.35	7.11325
1251.45	3.89254
1252.56	1.72658
1253.66	1.65167
1254.76	0.5681
1255.87	2.60646
1256.97	8.82614
1258.07	4.58815
1259.17	8.69569
1260.27	7.62351
1261.37	9.62332
1262.48	10.6992
1263.58	18.8958
1264.68	31.5482
1265.78	15.7733
1266.88	6.3267
1267.98	13.6417
1269.08	5.27726
1270.18	10.4789
1271.28	11.4565
1272.38	14.5682
1273.47	11.4434
1274.57	8.30518
1275.67	11.4304
1276.77	8.28614
1277.87	9.34401
1278.97	11.4608
1280.07	16.7101
1281.16	25.1108
1282.26	34.6067
1283.36	108.218
1284.45	335.206
1285.55	174.692
1286.65	32.4998
1287.75	15.6318
1288.84	8.25481
1289.94	6.17274
1291.03	5.13397
1292.13	8.29762
1293.22	5.14631
1294.32	4.14339
1295.42	5.21998
1296.51	4.24758
1297.61	6.37569
1298.7	5.32196
1299.79	0.0504227
1300.89	4.30777
1301.98	0.115858
1303.08	2.26558
1304.17	-0.881258
1305.26	2.31764
1306.35	4.43858
1307.45	4.47074
1308.54	3.45826
1309.63	4.56441
1310.73	2.50266
1311.82	8.88545
1312.91	2.61435
1314	5.8214
1315.09	3.76414
1316.18	5.94495
1317.28	8.10625
1318.37	7.11682
1319.46	6.11973
1320.55	1.95364
1321.64	6.21791
1322.73	0.977325
1323.82	1.0315
1324.91	4.26142
1326	3.25427
1327.09	4.32654
1328.18	2.33887
1329.27	3.49746
1330.35	3.56491
1331.44	3.61293
1332.53	2.59233
1333.62	8.93703
1334.71	3.72444
1335.79	4.82602
1336.88	5.93332
1337.97	4.951
1339.06	3.95938
1340.14	6.13216
1341.23	8.30944
1342.32	7.33091
1343.4	8.43065
1344.49	4.32616
1345.58	6.48596
1346.66	9.65773
1347.75	4.48721
1348.83	3.51548
1349.92	5.66286
1351	8.84604
1352.09	4.74697
1353.17	6.93057
1354.25	9.1292
1355.34	3.94283
1356.42	7.14199
1357.51	6.17358
1358.59	8.31571
1359.67	7.34147
1360.76	7.3973
1361.84	4.36507
1362.92	4.43929
1364	9.71151
1365.09	12.901
1366.17	15.0239
1367.25	14.0326
1368.33	15.1479
1369.41	16.2746
1370.5	21.5145
1371.58	11.2316
1372.66	13.744
1373.74	13.2879
1374.82	15.2074
1375.9	16.0106
1376.98	15.6065
1378.06	16.9608
1379.14	17.2296
1380.22	19.2043
1381.3	24.315
1382.38	33.0678
1383.46	37.0931
1384.54	45.047
1385.61	69.2955
1386.69	141.53
1387.77	609.303
1388.85	320.658
1389.93	62.6432
1391	37.9764
1392.08	26.7257
1393.16	18.5643
1394.23	20.6604
1395.31	16.6283
1396.39	18.7494
1397.46	17.7674
1398.54	11.6819
1399.62	12.7775
1400.69	12.8465
1401.77	3.70103
1402.84	17.1265
1403.92	14.1354
1404.99	13.1382
1406.07	13.1683
1407.14	18.3338
1408.22	22.4948
1409.29	44.092
1410.37	34.9207
1411.44	14.415
1412.51	14.4522
1413.59	9.45083
1414.66	9.45737
1415.73	12.5901
1416.81	3.39548
1417.88	8.58036
1418.95	7.5932
1420.02	6.59316
1421.1	10.7117
1422.17	11.7716
1423.24	5.69338
1424.31	6.66509
1425.38	8.74423
1426.45	9.80342
1427.52	8.77416
1428.59	6.72276
1429.67	9.82415
1430.74	5.769
1431.81	8.89853
1432.87	6.84863
1433.95	5.80164
1435.01	7.87392
1436.08	7.88673
1437.15	8.91443
1438.22	8.91733
1439.29	8.93575
1440.36	5.88799
1441.43	3.84984
1442.49	1.80115
1443.56	8.98076
1444.63	6.92669
1445.7	5.92163
1446.77	5.91277
1447.83	7.95203
1448.9	-0.247913
1449.97	3.84623
1451.03	8.95409
1452.1	5.8631
1453.17	5.8534
1454.23	3.79799
1455.3	6.85931
1456.36	2.75323
1457.43	3.7553
1458.49	5.78543
1459.56	1.67542
1460.62	6.77734
1461.69	5.72348
1462.75	5.6868
1463.82	1.55428
1464.88	4.62593
1465.94	0.450882
1467.01	2.461
1468.07	2.43209
1469.13	1.38281
1470.2	4.40009
1471.26	4.3595
1472.32	4.31721
1473.39	3.26464
1474.45	5.25748
1475.51	3.19357
1476.57	3.15219
1477.63	6.15766
1478.69	4.07964
1479.76	1.99608
1480.82	-2.12387
1481.88	0.875357
1482.94	1.86636
1484	4.87721
1485.06	0.73245
1486.12	1.69823
1487.18	9.76458
1488.24	0.592106
1489.3	3.56767
1490.36	1.49366
1491.42	7.50414
1492.48	2.40055
1493.53	2.35157
1494.59	4.32578
1495.65	6.28927
1496.71	2.17736
1497.77	6.15942
1498.82	3.08119
1499.88	-2.01048
1500.94	-0.0402966
1502	-0.0991745
1503.05	0.850611
1504.11	0.788164
1505.17	2.75503
1506.22	2.68152
1507.28	0.615393
1508.34	3.58509
1509.39	5.54712
1510.45	1.46603
1511.5	6.42622
1512.56	0.28842
1513.61	2.21774
1514.67	4.18668
1515.72	1.09836
1516.78	5.03358
1517.83	1.96591
1518.88	2.9219
1519.94	1.86925
1520.99	3.8166
1522.05	-0.248508
1523.1	-0.313877
1524.15	4.6148
1525.2	6.55
1526.26	2.49805
1527.31	-1.55511
1528.36	0.384886
1529.41	0.320295
1530.47	1.25879
1531.52	-0.786278
1532.57	-1.84753
1533.62	0.123758
1534.67	4.08374
1535.72	3.01313
1536.77	-4.08624
1537.82	2.84028
1538.87	1.77005
1539.92	0.749798
1540.97	-1.27226
1542.02	-0.338009
1543.07	7.59514
1544.12	0.506611
1545.17	-0.533354
1546.22	0.436533
1547.27	0.388514
1548.32	0.323925
1549.37	0.258287
1550.42	1.21557
1551.46	3.24299
1552.51	1.18467
1553.56	3.12283
1554.61	-0.956976
1555.65	2.98052
1556.7	1.92751
1557.75	1.88266
1558.79	-2.18986
1559.84	1.73794
1560.89	-1.32005
1561.93	4.63492
1562.98	-1.39662
1564.02	0.55356
1565.07	3.5302
1566.11	-1.65127
1567.16	-0.603897
1568.2	1.37033
1569.25	2.33386
1570.29	-2.71772
1571.34	1.2381
1572.38	4.18299
1573.43	1.13127
1574.47	0.0915031
1575.51	3.0741
1576.56	1.04188
1577.6	3.96986
1578.64	0.910538
1579.69	1.87044
1580.73	0.84646
1581.77	2.79499
1582.81	7.72799
1583.85	1.71346
1584.9	3.67557
1585.94	2.64757
1586.98	1.60205
1588.02	3.55315
1589.06	2.53957
1590.1	1.52696
1591.14	4.49582
1592.18	2.47282
1593.22	2.42294
1594.26	3.35359
1595.3	0.355129
1596.34	3.30412
1597.38	-0.687223
1598.42	1.28053
1599.46	1.23812
1600.5	-0.781694
1601.54	4.12852
1602.58	5.07271
1603.62	5.03094
1604.66	2.04328
1605.69	4.0096
1606.73	10.9347
1607.77	5.97738
1608.81	2.86982
1609.84	2.3505
1610.88	4.06187
1611.92	1.56546
1612.95	3.4505
1613.99	3.71847
1615.03	6.57015
1616.06	6.26627
1617.1	5.30703
1618.13	3.72603
1619.17	4.09435
1620.2	4.55742
1621.24	1.87329
1622.27	5.51345
1623.31	5.45907
1624.34	4.76602
1625.38	4.29361
1626.41	7.08837
1627.45	4.93513
1628.48	3.02113
1629.51	6.38815
1630.55	4.42443
1631.53	3.9838
1632.57	10.9055
1633.62	9.92758
1634.66	6.99081
1635.71	7.9861
1636.75	6.99993
1637.8	4.04186
1638.84	7.0011
1639.89	9.97027
1640.93	6.05527
1641.98	7.05772
1643.02	7.06973
1644.06	8.06828
1645.11	7.09073
1646.15	3.18566
1647.19	4.18056
1648.24	8.12785
1649.28	6.21377
1650.32	15.0966
1651.37	5.30721
1652.41	8.29612
1653.45	4.3748
1654.49	8.35131
1655.53	6.42333
1656.57	9.44731
1657.62	7.50479
1658.66	6.53797
1659.7	4.57962
1660.74	2.63614
1661.78	3.67673
1662.82	7.69532
1663.86	6.74663
1664.9	7.74893
1665.94	6.75705
1666.98	6.83501
1668.02	7.84281
1669.06	5.91433
1670.1	4.98867
1671.14	5.05112
1672.18	4.09839
1673.21	2.16612
1674.25	7.15878
1675.29	1.28382
1676.33	7.27118
1677.37	6.32885
1678.4	-1.5553
1679.44	4.40677
1680.48	3.45398
1681.52	7.44281
1682.55	5.5134
1683.59	8.52279
1684.63	4.61239
1685.66	3.6682
1686.7	3.72031
1687.73	0.813431
1688.77	4.80256
1689.81	-0.100452
1690.84	3.8905
1691.88	0.991896
1692.91	3.01469
1693.95	0.0836926
1694.98	1.10386
1696.01	1.16101
1697.05	5.16389
1698.08	3.22577
1699.12	2.27811
1700.15	-0.620037
1701.18	1.39692
1702.22	4.38979
1703.25	3.44608
1704.28	-0.434025
1705.32	1.59235
1706.35	1.6437
1707.38	3.64061
1708.41	0.727436
1709.44	-0.222982
1710.48	1.78784
1711.51	-0.104147
1712.54	2.89373
1713.57	2.9138
1714.6	2.94597
1715.63	0.0742111
1716.66	3.06341
1717.69	1.13936
1718.72	2.1345
1719.75	4.13205
1720.78	0.296101
1721.81	0.336555
1722.84	1.34611
1723.87	1.38883
1724.9	1.44156
1725.93	3.40827
1726.96	2.48992
1727.99	0.605438
1729.02	-1.3121
1730.05	1.62521
1731.07	0.706404
1732.1	0.792637
1733.13	4.70759
1734.16	2.80369
1735.18	-1.02075
1736.21	-0.0175762
1737.24	3.88113
1738.26	2.00316
1739.29	-2.76095
1740.32	3.02639
1741.34	1.14186
1742.37	-1.68656
1743.4	1.23836
1744.42	3.1997
1745.45	2.29706
1746.47	5.21552
1747.5	2.3809
1748.52	-1.39277
1749.55	-0.375549
1750.57	0.654064
1751.6	0.720736
1752.62	-0.196791
1753.64	-0.156721
1754.67	1.79187
1755.69	3.74289
1756.71	1.87355
1757.74	5.71144
1758.76	3.87244
1759.78	3.93023
1760.81	0.173273
1761.83	-0.73572
1762.85	3.12006
1763.87	1.27522
1764.89	5.15081
1765.92	2.35915
1766.94	3.36242
1767.96	5.31145
1768.98	0.596659
1770	1.56186
1771.02	1.62417
1772.04	0.741299
1773.06	4.60898
1774.08	1.81372
1775.1	3.77448
1776.12	2.89249
1777.14	1.03465
1778.16	2.02274
1779.18	4.90833
1780.2	-1.70994
1781.22	1.19817
1782.24	1.25017
1783.26	3.21496
1784.28	2.31791
1785.29	1.42253
1786.31	3.36921
1787.33	2.46882
1788.35	3.50761
1789.37	3.58217
1790.38	9.39483
1791.4	7.51589
1792.42	3.70589
1793.43	4.71099
1794.45	3.79723
1795.47	3.85575
1796.48	1.99838
1797.5	3.97388
1798.51	3.0607
1799.53	2.13398
1800.55	1.19573
1801.56	2.18596
1802.58	5.10693
1803.59	4.19613
1804.61	3.27777
1805.62	4.29124
1806.64	3.37762
1807.65	7.27018
1808.66	3.44724
1809.68	3.48067
1810.69	3.51319
1811.7	2.57544
1812.72	3.57119
1813.73	5.53954
1814.74	5.58769
1815.76	2.73259
1816.77	4.69619
1817.78	1.80997
1818.79	3.77007
1819.8	5.73339
1820.82	2.86614
1821.83	0.963631
1822.84	6.80091
1823.85	2.9502
1824.86	6.84371
1825.87	7.84086
1826.88	5.92465
1827.89	3.04354
1828.9	4.02946
1829.91	5.00849
1830.92	5.98441
1831.93	3.10363
1832.94	6.03805
1833.95	7.02835
1834.96	5.08864
1835.97	4.10097
1836.98	4.1906
1837.99	3.16829
1839	4.14559
1840	2.24669
1841.01	4.15354
1842.02	0.262627
1843.03	3.15021
1844.04	1.22872
1845.04	7.98908
1846.05	0.283167
1847.06	5.1353
1848.07	2.17766
1849.07	4.11139
1850.08	3.13723
1851.09	5.03793
1852.09	3.10577
1853.1	6.94752
1854.1	5.01975
1855.11	1.16233
1856.11	2.10322
1857.12	4.01551
1858.12	3.04918
1859.13	3.98795
1860.13	5.88314
1861.14	3.02064
1862.14	3.98494
1863.15	5.88002
1864.15	2.03335
1865.15	5.83333
1866.16	2.93797
1867.16	6.7064
1868.16	2.86669
1869.17	4.75834
1870.17	4.74631
1871.17	0.932465
1872.17	1.86669
1873.18	1.84556
1874.18	1.82775
1875.18	6.54103
1876.18	0.814356
1877.18	3.62136
1878.18	4.52419
1879.19	4.54676
1880.19	5.49743
1881.19	10.2148
1882.19	4.48861
1883.19	4.42897
1884.19	6.27559
1885.19	4.3861
1886.19	1.56493
1887.19	1.54589
1888.19	1.51106
1889.19	0.526844
1890.19	3.32292
1891.19	6.14295
1892.18	6.11925
1893.18	3.26594
1894.18	6.03492
1895.18	4.12547
1896.18	5.99158
1897.18	2.22463
1898.17	5.97138
1899.17	8.75693
1900.17	6.83848
1901.16	3.05783
1902.16	4.93155
1903.16	4.91726
1904.16	3.94555
1905.15	4.85865
1906.15	6.70571
1907.14	3.84753
1908.14	6.64365
1909.14	3.8106
1910.13	1.92416
1911.13	3.80602
1912.12	4.72884
1913.12	4.69965
1914.11	-0.0270748
1915.11	4.68016
1916.1	7.49314
1917.1	0.852133
1918.09	2.70186
1919.08	5.51839
1920.08	4.57901
1921.07	4.55593
1922.06	3.60101
1923.06	4.51593
1924.05	3.5337
1925.04	1.60603
1926.04	2.53671
1927.03	5.371
1928.02	3.46312
1929.01	5.33887
1930	4.38126
1931	5.32597
1931.99	5.2949
1932.98	3.35535
1933.97	2.38119
1934.96	7.16973
1935.95	6.24232
1936.94	6.19006
1937.93	4.2357
1938.92	5.15752
1939.91	3.23653
1940.9	2.26901
1941.89	-2.51225
1942.88	5.10214
1943.87	4.10536
1944.86	2.18275
1945.85	5.04073
1946.84	2.15838
1947.83	4.03869
1948.82	2.09464
1949.8	3.03576
1950.79	2.07889
1951.78	4.00113
1952.77	2.07002
1953.76	3.00437
1954.74	3.88866
1955.73	0.0162754
1956.72	5.77786
1957.7	3.8516
1958.69	2.87388
1959.68	3.7997
1960.66	0.879337
1961.65	4.67692
1962.63	3.69024
1963.62	6.54637
1964.61	-0.194599
1965.59	0.736315
1966.58	0.720011
1967.56	5.50863
1968.55	0.679661
1969.53	4.48621
1970.52	1.55457
1971.5	1.51652
1972.48	4.36852
1973.47	5.29714
1974.45	2.38096
1975.44	4.27494
1976.42	1.38498
1977.4	-0.556501
1978.39	4.20352
1979.37	0.338232
1980.35	1.27477
1981.33	3.1564
1982.31	1.20953
1983.3	3.08845
1984.28	4.9634
1985.26	5.88595
1986.24	2.98813
1987.22	5.84272
1988.21	3.89177
1989.19	3.81621
1990.17	3.68194
1991.15	2.66786
1992.13	2.58482
1993.11	2.0407
1994.09	3.7245
1995.07	2.05291
1996.05	1.59725
1997.03	3.18796
1998.01	3.64301
1998.99	3.42429
1999.97	2.92349
2000.95	1.39143
2001.92	1.08468
2002.9	1.53561
2003.88	1.6469
2004.86	2.01457
2005.84	2.46853
2006.81	3.18014
2007.79	2.71224
2008.77	2.45419
2009.75	0.261299
2010.73	2.67675
2011.7	2.51649
2012.68	1.46115
2013.67	1.42362
2014.66	4.19289
2015.64	4.1703
2016.63	4.16887
2017.62	1.35435
2018.61	0.375847
2019.6	3.14533
2020.58	1.25147
2021.57	2.1786
2022.56	2.16265
2023.55	4.00353
2024.54	3.03921
2025.52	2.06641
2026.51	2.0399
2027.5	2.0906
2028.48	2.99147
2029.47	-0.721212
2030.45	0.14566
2031.44	2.01485
2032.43	2.94623
2033.41	2.9706
2034.4	4.83783
2035.38	3.86138
2036.37	-1.70291
2037.35	5.76811
2038.34	-0.786402
2039.32	2.00093
2040.31	1.04568
2041.29	3.81969
2042.27	0.0782547
2043.26	2.86312
2044.24	1.02333
2045.23	1.00977
2046.21	2.9216
2047.19	1.96637
2048.17	2.87035
2049.16	0.0794659
2050.14	3.83718
2051.12	1.05402
2052.11	1.97698
2053.09	4.78844
2054.07	1.07763
2055.05	4.82892
2056.03	2.01471
2057.01	0.141264
2058	3.88942
2058.98	0.169193
2059.96	2.0554
2060.94	0.179863
2061.92	1.1291
2062.9	2.07552
2063.88	1.15758
2064.86	2.10898
2065.84	3.07473
2066.82	4.03436
2067.8	3.11195
2068.78	5.94936
2069.76	1.25067
2070.73	1.25569
2071.71	2.21725
2072.69	1.31475
2073.67	4.14313
2074.65	6.04065
2075.63	-0.51885
2076.6	3.28714
2077.58	4.22758
2078.56	2.34391
2079.54	6.14103
2080.51	0.507683
2081.49	4.29581
2082.47	0.525913
2083.45	0.538406
2084.42	3.38172
2085.4	3.3928
2086.37	4.35605
2087.35	1.54705
2088.32	4.40288
2089.3	-0.315134
2090.28	2.55081
2091.25	3.51661
2092.23	2.59733
2093.2	-3.06046
2094.18	2.66979
2095.15	-0.166664
2096.13	4.58423
2097.1	3.63908
2098.07	1.7372
2099.05	3.64155
2100.02	2.70057
2101	3.66574
2101.97	7.49148
2102.94	6.55126
2103.92	-0.0954533
2104.89	3.71808
2105.86	3.74608
2106.83	0.916664
2107.8	2.83091
2108.78	4.71946
2109.75	1.88193
2110.72	2.84816
2111.69	3.80785
2112.66	3.81215
2113.63	2.88682
2114.61	3.85208
2115.58	1.01221
2116.55	5.76383
2117.52	5.76538
2118.49	1.02055
2119.46	1.01087
2120.43	3.84907
2121.4	2.91761
2122.37	-0.84613
2123.34	3.92181
2124.31	2.03224
2125.28	3.91027
2126.25	2.94123
2127.21	4.82257
2128.18	2.9316
2129.15	3.88294
2130.12	0.10677
2131.09	2.94493
2132.06	2.94134
2133.02	1.99331
2133.99	2.94516
2134.96	3.89889
2135.93	4.846
2136.89	8.60244
2137.86	2.95915
2138.83	4.84404
2139.79	4.85752
2140.76	4.8446
2141.73	3.9038
2142.69	2.95737
2143.66	1.09723
2144.62	2.94353
2145.59	2.0106
2146.55	2.95269
2147.52	5.76839
2148.48	2.94393
2149.45	0.119406
2150.42	5.72711
2151.38	3.8509
2152.34	1.05317
2153.31	6.67556
2154.27	4.79179
2155.24	5.69679
2156.2	3.79772
2157.16	3.79205
2158.13	4.7384
2159.09	3.80963
2160.05	2.86398
2161.01	2.84524
2161.98	0.972748
2162.94	2.83844
2163.9	0.0319481
2164.86	3.74597
2165.83	3.74577
2166.79	2.80919
2167.75	4.65434
2168.71	5.54977
2169.67	-1.88248
2170.63	4.65603
2171.59	1.8548
2172.56	1.81729
2173.51	4.59451
2174.48	4.59839
2175.44	0.878441
2176.4	3.65813
2177.36	5.5052
2178.32	2.71565
2179.28	-0.0872021
2180.23	-1.94773
2181.19	5.47117
2182.15	1.74545
2183.11	4.51502
2184.07	-2.00117
2185.03	2.61983
2185.99	-0.159369
2186.95	2.63239
2187.9	2.64952
2188.86	0.776024
2189.82	3.52896
2190.78	4.43801
2191.73	2.58064
2192.69	4.43467
2193.65	-0.200611
2194.6	6.32486
2195.56	2.59524
2196.52	2.56332
2197.47	4.38813
2198.43	2.52241
2199.38	6.25188
2200.34	8.13844
2201.3	5.37976
2202.25	2.50025
2203.21	5.31746
2204.16	-0.20636
2205.12	5.33812
2206.07	8.05556
2207.03	3.39277
2207.98	1.53371
2208.93	3.40024
2209.89	5.25736
2210.84	-0.338249
2211.8	3.3898
2212.75	0.593075
2213.7	1.50341
2214.66	1.50011
2215.61	3.36721
2216.56	4.28843
2217.51	1.47098
2218.47	4.25926
2219.42	1.45383
2220.37	2.38522
2221.32	5.16959
2222.27	1.39789
2223.23	1.38463
2224.18	3.25703
2225.13	0.460468
2226.08	4.2114
2227.03	5.15319
2227.98	1.40109
2228.93	-0.493925
2229.88	2.30542
2230.83	3.24873
2231.78	2.31553
2232.73	1.37836
2233.68	0.438694
2234.63	4.1971
2235.58	6.04611
2236.53	4.14737
2237.48	4.14257
2238.43	-1.49094
2239.38	4.1776
2240.33	2.26732
2241.27	3.207
2242.22	5.08722
2243.17	6.02661
2244.12	2.22819
2245.07	2.22522
2246.01	4.12998
2246.96	1.29603
2247.91	0.346813
2248.85	0.330719
2249.8	3.15823
2250.75	-1.58918
2251.69	-0.669554
2252.64	4.05272
2253.59	4.07705
2254.53	2.19274
2255.48	1.23675
2256.42	4.07763
2257.37	3.13593
2258.32	0.289295
2259.26	1.23752
2260.2	1.23864
2261.15	2.19116
2262.1	2.19783
2263.04	4.10638
2263.98	4.12759
2264.93	2.24667
2265.87	1.30032
2266.81	1.28399
2267.76	3.16993
2268.7	1.24385
2269.65	1.25358
2270.59	3.1875
2271.53	-0.623194
2272.47	0.34165
2273.42	2.25671
2274.36	1.30264
2275.3	0.348852
2276.24	1.31049
2277.18	0.37146
2278.13	1.35891
2279.07	-2.46773
2280.01	1.35942
2280.95	-0.578058
2281.89	3.24866
2282.83	0.387129
2283.77	-1.50582
2284.71	-2.43287
2285.65	1.43265
2286.59	1.42471
2287.54	-0.471495
2288.47	2.43393
2289.41	-0.465204
2290.35	3.36231
2291.29	1.44879
2292.23	1.47897
2293.17	6.32261
2294.11	1.52615
2295.05	1.52428
2295.99	0.55958
2296.93	2.47753
2297.86	-1.34727
2298.8	0.61067
2299.74	2.56999
2300.68	0.655148
2301.61	4.54032
2302.55	-0.272369
2303.49	3.59969
2304.43	0.724857
2305.36	-0.213316
2306.3	1.74236
2307.24	0.795488
2308.17	3.70371
2309.11	1.78482
2310.04	0.854109
2310.98	2.81261
2311.92	-0.103258
2312.85	-0.104202
2313.79	-1.04616
2314.72	2.86263
2315.66	0.960733
2316.59	1.9185
2317.52	0.962633
2318.46	0.984562
2319.39	2.92045
2320.33	3.89645
2321.26	2.95617
2322.2	1.06211
2323.13	4.96038
2324.06	3.05084
2325	6.92859
2325.93	2.08872
2326.86	6.91187
2327.79	17.512
2328.73	51.2555
2329.66	20.4026
2330.59	10.7833
2331.52	0.200214
2332.46	2.14688
2333.39	-1.70404
2334.32	3.11208
2335.25	4.07029
2336.18	-3.61192
2337.11	4.08636
2338.04	4.09048
2338.97	6.97742
2339.91	3.14039
2340.84	6.01565
2341.77	2.151
2342.7	6.93051
2343.63	3.09265
2344.56	3.0923
2345.49	5.96206
2346.41	0.191641
2347.34	0.180677
2348.27	4.00267
2349.2	2.08021
2350.13	-1.78936
2351.06	3.8214
2351.99	3.89883
2352.91	1.93596
2353.84	1.88268
2354.77	4.71677
2355.7	2.78514
2356.63	0.834423
2357.55	0.775278
2358.48	-0.223757
2359.41	-0.273436
2360.33	2.51962
2361.26	2.45091
2362.19	3.32427
2363.11	3.24567
2364.04	0.334137
2364.97	0.258331