File: Data/3-Raman/raw/bu02aw-a-ff1-fi05-v_1800 (450-850nm)_532nm_edge_100%_x100_vis_lwd_h50um_30sx2_01.txt
#Acq. time (s)=	30
#Accumulations=	2
#Range (cm-¹)=	1200...2365
#Windows=	3
#Auto scanning=	Off
#Autofocus=	Off
#Macrospot=	Off
#AutoExposure=	Off
#Spike filter=	Multiple accum.
#Delay time (s)=	2
#Binning=	1
#Readout mode=	Signal
#DeNoise=	Off
#ICS correction=	On
#Dark correction=	Off
#Inst. Process=	Off
#Detector Gain=	Best Dynamic
#Detector ADC=	50 kHz HS
#Detector temperature (°C)=	-60.09
#Instrument=	LabRAM HR Evol
#Detector=	SIN-EM FIVIS
#Objective=	x100_VIS_LWD
#Grating=	1800 (450-850nm)
#ND Filter=	100%
#Laser=	532nm_Edge
#Hole=	49.98
#Temperature=	0
#Range=	Visible
#StageXY=	75x50mm Scan+
#StageZ=	Z motor
#X (µm)=	0
#Y (µm)=	0
#Z (µm)=	-17.2
#Full time(mm:ss)=	3:28
#Project=	21_11_26
#Sample=	BU02Aw
#Site=
#Title=	BU02aW-A-FF1-FI05-V_1800 (450-850nm)_532nm_Edge_100%_x100_VIS_LWD_H50um_30sX2
#Remark=
#Date=	26.11.2021 10:48
#Acquired=	26.11.2021 10:48:18
1202.72	36.0265
1203.84	34.9616
1204.95	39.2334
1206.06	35.9517
1207.17	34.8082
1208.28	36.9085
1209.39	35.7969
1210.5	38.983
1211.61	33.5838
1212.72	35.6658
1213.83	35.629
1214.94	34.5561
1216.05	34.5458
1217.16	35.5548
1218.27	32.3257
1219.38	32.3015
1220.49	38.6474
1221.6	41.8113
1222.71	35.3987
1223.81	32.1583
1224.92	32.1175
1226.03	34.2271
1227.14	34.2165
1228.25	35.1884
1229.35	28.7965
1230.46	38.353
1231.57	32.9881
1232.67	35.0855
1233.78	36.1247
1234.89	36.1347
1235.99	39.3013
1237.1	36.1352
1238.2	41.334
1239.31	36.0385
1240.41	33.9257
1241.52	38.1186
1242.62	37.0525
1243.73	33.9156
1244.83	34.9596
1245.94	37.018
1247.04	41.1805
1248.14	40.1202
1249.25	43.2315
1250.35	45.3186
1251.45	40.0492
1252.56	32.7068
1253.66	43.1151
1254.76	41.0475
1255.87	38.9615
1256.97	45.2331
1258.07	45.2183
1259.17	53.5409
1260.27	46.2609
1261.37	51.4218
1262.48	58.8488
1263.58	81.6275
1264.68	114.312
1265.78	80.7563
1266.88	61.9424
1267.98	51.5381
1269.08	48.4605
1270.18	49.5044
1271.28	53.6401
1272.38	48.4086
1273.47	56.8455
1274.57	44.3096
1275.67	52.7032
1276.77	51.6897
1277.87	54.8806
1278.97	63.3402
1280.07	55.9853
1281.16	80.1757
1282.26	141.277
1283.36	411.608
1284.45	1241.88
1285.55	557.36
1286.65	133.954
1287.75	68.6309
1288.84	61.2421
1289.94	49.6913
1291.03	49.7008
1292.13	50.7443
1293.22	46.5248
1294.32	46.5779
1295.42	45.5302
1296.51	41.3951
1297.61	42.4418
1298.7	44.5257
1299.79	41.331
1300.89	42.3954
1301.98	39.2293
1303.08	36.0668
1304.17	36.0488
1305.26	42.3759
1306.35	42.3351
1307.45	43.3775
1308.54	40.2121
1309.63	40.2203
1310.73	40.2225
1311.82	43.3909
1312.91	42.3517
1314	42.3341
1315.09	41.2782
1316.18	38.1268
1317.28	41.2845
1318.37	42.3497
1319.46	43.4041
1320.55	38.1182
1321.64	34.9202
1322.73	41.2127
1323.82	47.5202
1324.91	39.083
1326	37.999
1327.09	37.9318
1328.18	36.9392
1329.27	34.8695
1330.35	41.1902
1331.44	39.0431
1332.53	40.0348
1333.62	34.7215
1334.71	36.7779
1335.79	38.8412
1336.88	38.8128
1337.97	40.8891
1339.06	30.3804
1340.14	40.8469
1341.23	38.7515
1342.32	37.6855
1343.4	36.6022
1344.49	37.6404
1345.58	38.6636
1346.66	39.6488
1347.75	42.7245
1348.83	34.3629
1349.92	39.541
1351	43.6681
1352.09	47.7906
1353.17	35.3306
1354.25	37.4454
1355.34	42.549
1356.42	39.4232
1357.51	40.4379
1358.59	41.4457
1359.67	39.3378
1360.76	45.5125
1361.84	38.2431
1362.92	44.437
1364	44.4476
1365.09	42.3696
1366.17	49.5724
1367.25	43.3117
1368.33	37.1039
1369.41	66.0599
1370.5	69.1384
1371.58	50.4856
1372.66	47.3137
1373.74	48.3073
1374.82	44.1666
1375.9	51.3724
1376.98	54.4336
1378.06	61.6153
1379.14	65.8354
1380.22	63.7364
1381.3	70.7986
1382.38	77.9109
1383.46	91.13
1384.54	94.1493
1385.61	152.728
1386.69	375.722
1387.77	2233.94
1388.85	858.605
1389.93	167.192
1391	91.0591
1392.08	68.4414
1393.16	58.1461
1394.23	57.0963
1395.31	52.9957
1396.39	55.0555
1397.46	54
1398.54	42.7325
1399.62	44.7932
1400.69	47.8757
1401.77	43.7975
1402.84	42.8351
1403.92	52.1114
1404.99	45.915
1406.07	54.0832
1407.14	64.3133
1408.22	89.96
1409.29	162.799
1410.37	111.542
1411.44	59.1613
1412.51	46.8509
1413.59	39.7846
1414.66	38.7069
1415.73	40.7741
1416.81	34.6213
1417.88	36.6887
1418.95	41.8299
1420.02	37.7059
1421.1	33.5652
1422.17	33.5635
1423.24	35.6886
1424.31	37.6165
1425.38	42.7419
1426.45	34.5434
1427.52	34.5048
1428.59	32.42
1429.67	34.474
1430.74	35.5255
1431.81	34.5414
1432.87	33.4924
1433.95	33.438
1435.01	33.4459
1436.08	34.4665
1437.15	34.4519
1438.22	30.3425
1439.29	41.6184
1440.36	34.469
1441.43	33.4493
1442.49	26.2639
1443.56	31.3852
1444.63	30.3497
1445.7	28.3182
1446.77	30.3561
1447.83	32.3914
1448.9	31.372
1449.97	26.236
1451.03	29.2941
1452.1	32.3536
1453.17	30.2991
1454.23	35.424
1455.3	28.2447
1456.36	23.1229
1457.43	31.3056
1458.49	28.2233
1459.56	31.2982
1460.62	32.3142
1461.69	28.1998
1462.75	27.1527
1463.82	27.124
1464.88	31.2451
1465.94	31.1478
1467.01	30.1136
1468.07	28.0643
1469.13	27.0365
1470.2	31.0921
1471.26	25.9777
1472.32	32.0692
1473.39	27.9873
1474.45	28.9871
1475.51	30.0061
1476.57	25.9215
1477.63	23.8704
1478.69	27.9239
1479.76	28.9173
1480.82	26.8518
1481.88	25.8232
1482.94	21.777
1484	28.8856
1485.06	22.7401
1486.12	29.8211
1487.18	32.8604
1488.24	30.8138
1489.3	30.7843
1490.36	25.7135
1491.42	27.7177
1492.48	28.722
1493.53	28.7145
1494.59	29.7206
1495.65	24.6516
1496.71	29.6707
1497.77	30.6675
1498.82	25.6159
1499.88	25.618
1500.94	27.6353
1502	28.6292
1503.05	29.6229
1504.11	33.637
1505.17	28.5945
1506.22	30.5793
1507.28	26.5477
1508.34	24.5286
1509.39	28.5557
1510.45	25.5329
1511.5	27.5191
1512.56	27.4599
1513.61	31.4403
1514.67	31.4569
1515.72	29.4177
1516.78	30.3889
1517.83	31.3827
1518.88	27.379
1519.94	30.3927
1520.99	30.3848
1522.05	24.3664
1523.1	29.3664
1524.15	30.3302
1525.2	25.3057
1526.26	30.3219
1527.31	26.325
1528.36	21.3008
1529.41	23.2919
1530.47	26.285
1531.52	25.2968
1532.57	26.2908
1533.62	27.3186
1534.67	30.3284
1535.72	28.3047
1536.77	27.2593
1537.82	28.2253
1538.87	24.205
1539.92	28.2427
1540.97	26.2813
1542.02	28.2645
1543.07	34.2387
1544.12	25.1945
1545.17	30.2099
1546.22	27.2313
1547.27	25.2297
1548.32	24.2109
1549.37	24.1923
1550.42	30.2037
1551.46	28.2828
1552.51	31.2918
1553.56	26.2475
1554.61	32.239
1555.65	27.1971
1556.7	32.1989
1557.75	27.191
1558.79	29.1662
1559.84	29.128
1560.89	26.1106
1561.93	31.1094
1562.98	28.1222
1564.02	26.1128
1565.07	24.129
1566.11	25.9629
1567.16	26.0714
1568.2	30.0869
1569.25	30.0902
1570.29	27.0725
1571.34	27.0676
1572.38	32.0451
1573.43	30.0243
1574.47	29.0187
1575.51	25.0471
1576.56	29.0438
1577.6	31.9987
1578.64	29.9625
1579.69	27.9624
1580.73	28.9641
1581.77	30.94
1582.81	31.9141
1583.85	28.9155
1584.9	27.9168
1585.94	27.9112
1586.98	25.8945
1588.02	25.8801
1589.06	29.8665
1590.1	29.8741
1591.14	21.9115
1592.18	24.8897
1593.22	28.8404
1594.26	27.7997
1595.3	31.7752
1596.34	26.7936
1597.38	24.806
1598.42	30.7635
1599.46	27.7536
1600.5	26.738
1601.54	29.6758
1602.58	25.6816
1603.62	28.6209
1604.66	28.6101
1605.69	28.6089
1606.73	31.5862
1607.77	29.5733
1608.81	29.773
1609.84	31.5271
1610.88	31.3744
1611.92	28.1094
1612.95	28.6181
1613.99	29.1237
1615.03	31.4157
1616.06	29.9604
1617.1	28.819
1618.13	28.2123
1619.17	33.3122
1620.2	31.0101
1621.24	31.264
1622.27	29.884
1623.31	29.2903
1624.34	29.1814
1625.38	32.4217
1626.41	29.9718
1627.45	30.1522
1628.48	31.1781
1629.51	29.1176
1630.55	27.3518
1631.53	27.3094
1632.57	32.2423
1633.62	28.2912
1634.66	28.2911
1635.71	27.2965
1636.75	28.2635
1637.8	27.2564
1638.84	31.1789
1639.89	33.1409
1640.93	28.2171
1641.98	31.1639
1643.02	24.2604
1644.06	33.1075
1645.11	30.1355
1646.15	32.1059
1647.19	33.0706
1648.24	29.1197
1649.28	29.1389
1650.32	34.053
1651.37	30.1361
1652.41	33.0915
1653.45	31.1067
1654.49	28.1502
1655.53	29.1415
1656.57	26.2038
1657.62	30.1457
1658.66	28.155
1659.7	31.0905
1660.74	29.1071
1661.78	30.108
1662.82	29.1471
1663.86	25.1918
1664.9	31.0927
1665.94	29.0739
1666.98	28.1164
1668.02	29.0814
1669.06	34.0157
1670.1	29.0948
1671.14	30.098
1672.18	30.086
1673.21	33.0481
1674.25	33.0494
1675.29	22.1785
1676.33	28.1146
1677.37	27.1209
1678.4	24.1335
1679.44	30.0428
1680.48	29.0369
1681.52	26.0566
1682.55	25.0613
1683.59	30.9802
1684.63	28.9905
1685.66	27.9909
1686.7	27.9869
1687.73	26.0114
1688.77	25.9934
1689.81	29.9154
1690.84	27.9281
1691.88	27.9316
1692.91	27.9217
1693.95	27.8877
1694.98	26.8751
1696.01	27.8575
1697.05	31.8007
1698.08	31.7687
1699.12	28.7881
1700.15	23.8602
1701.18	29.7498
1702.22	27.7615
1703.25	25.7723
1704.28	25.759
1705.32	28.7052
1706.35	28.692
1707.38	28.6583
1708.41	23.7178
1709.44	26.6196
1710.48	25.628
1711.51	24.6507
1712.54	29.5423
1713.57	29.491
1714.6	26.5229
1715.63	27.4928
1716.66	28.4623
1717.69	27.444
1718.72	30.3144
1719.75	25.428
1720.78	26.3935
1721.81	26.364
1722.84	26.3313
1723.87	23.3918
1724.9	25.3192
1725.93	22.3692
1726.96	27.1993
1727.99	24.2782
1729.02	27.124
1730.05	26.124
1731.07	26.1018
1732.1	28.0585
1733.13	23.2097
1734.16	27.0312
1735.18	24.0998
1736.21	27.9203
1737.24	25.9761
1738.26	24.9926
1739.29	24.964
1740.32	26.8375
1741.34	26.7996
1742.37	28.689
1743.4	28.6734
1744.42	29.6087
1745.45	22.9002
1746.47	23.8408
1747.5	18.0776
1748.52	26.6508
1749.55	28.5598
1750.57	25.7095
1751.6	24.7578
1752.62	23.7724
1753.64	27.5625
1754.67	21.813
1755.69	27.5127
1756.71	23.6725
1757.74	25.5431
1758.76	26.4962
1759.78	26.492
1760.81	24.5752
1761.83	27.4045
1762.85	27.3958
1763.87	25.4907
1764.89	23.6001
1765.92	26.46
1766.94	27.4033
1767.96	26.4364
1768.98	25.467
1770	21.6156
1771.02	23.5204
1772.04	26.3858
1773.06	20.6857
1774.08	24.4955
1775.1	28.3057
1776.12	24.514
1777.14	21.6475
1778.16	23.532
1779.18	23.5054
1780.2	28.2527
1781.22	27.3035
1782.24	26.3526
1783.26	22.552
1784.28	27.3242
1785.29	23.5197
1786.31	25.4145
1787.33	21.6026
1788.35	25.462
1789.37	26.4508
1790.38	26.4678
1791.4	24.5409
1792.42	19.7264
1793.43	24.5158
1794.45	28.3472
1795.47	26.4478
1796.48	23.5905
1797.5	23.6024
1798.51	22.6462
1799.53	24.5601
1800.55	25.4974
1801.56	25.4829
1802.58	26.4421
1803.59	27.416
1804.61	22.6125
1805.62	26.476
1806.64	24.5637
1807.65	25.5275
1808.66	25.5223
1809.68	23.5913
1810.69	23.5876
1811.7	22.6136
1812.72	25.5031
1813.73	26.4747
1814.74	27.4582
1815.76	25.54
1816.77	23.6057
1817.78	24.5507
1818.79	24.5481
1819.8	25.5154
1820.82	25.5207
1821.83	24.5594
1822.84	22.6272
1823.85	25.5245
1824.86	25.5188
1825.87	22.6164
1826.88	23.5795
1827.89	27.455
1828.9	23.5722
1829.91	24.5264
1830.92	23.5417
1831.93	23.5442
1832.94	24.5208
1833.95	24.521
1834.96	24.4976
1835.97	30.2565
1836.98	25.5085
1837.99	27.3556
1839	22.5079
1840	24.4709
1841.01	25.3825
1842.02	26.294
1843.03	24.3349
1844.04	23.3635
1845.04	25.2867
1846.05	27.2174
1847.06	26.2719
1848.07	25.2108
1849.07	26.1716
1850.08	25.1823
1851.09	23.2222
1852.09	24.1601
1853.1	24.1518
1854.1	25.095
1855.11	24.1025
1856.11	23.1141
1857.12	27.8928
1858.12	24.0454
1859.13	26.8885
1860.13	24.9504
1861.14	23.9981
1862.14	24.0047
1863.15	24.9381
1864.15	24.9089
1865.15	24.883
1866.16	25.7974
1867.16	27.6501
1868.16	26.6569
1869.17	29.4991
1870.17	27.5857
1871.17	27.5742
1872.17	23.7566
1873.18	29.4318
1874.18	22.7691
1875.18	28.4301
1876.18	25.5401
1877.18	25.5055
1878.18	27.3501
1879.19	23.6054
1880.19	33.0865
1881.19	23.6083
1882.19	29.2381
1883.19	26.3383
1884.19	28.1873
1885.19	24.4238
1886.19	26.3373
1887.19	25.383
1888.19	29.1235
1889.19	27.1929
1890.19	25.2877
1891.19	29.0647
1892.18	25.2847
1893.18	30.9142
1894.18	24.2799
1895.18	27.0799
1896.18	27.0821
1897.18	25.213
1898.17	27.0945
1899.17	25.1912
1900.17	24.2272
1901.16	22.3407
1902.16	27.9932
1903.16	29.8786
1904.16	23.2785
1905.15	27.0281
1906.15	25.1308
1907.14	24.1667
1908.14	27.92
1909.14	24.1672
1910.13	27.9454
1911.13	27.0321
1912.12	26.0915
1913.12	24.1967
1914.11	28.9136
1915.11	23.2765
1916.1	28.9405
1917.1	25.1465
1918.09	26.0698
1919.08	30.7976
1920.08	24.2224
1921.07	22.3306
1922.06	26.1255
1923.06	27.0605
1924.05	27.9873
1925.04	24.1877
1926.04	25.1437
1927.03	24.2199
1928.02	25.1761
1929.01	23.2855
1930	25.1954
1931	28.0648
1931.99	26.1566
1932.98	25.1857
1933.97	24.2346
1934.96	25.2523
1935.95	24.3492
1936.94	21.4596
1937.93	25.2417
1938.92	27.1378
1939.91	28.0998
1940.9	23.3469
1941.89	25.2709
1942.88	27.1847
1943.87	25.2536
1944.86	25.2657
1945.85	24.3288
1946.84	23.3828
1947.83	28.1537
1948.82	28.1435
1949.8	25.2853
1950.79	26.2736
1951.78	25.3495
1952.77	24.404
1953.76	26.3215
1954.74	26.2569
1955.73	27.1942
1956.72	24.3564
1957.7	25.3344
1958.69	25.3412
1959.68	24.3651
1960.66	24.3456
1961.65	24.3213
1962.63	23.3555
1963.62	25.2727
1964.61	20.4731
1965.59	26.2249
1966.58	21.4295
1967.56	20.4723
1968.55	22.3922
1969.53	24.2946
1970.52	23.2999
1971.5	26.1568
1972.48	23.272
1973.47	24.2191
1974.45	28.9891
1975.44	22.2747
1976.42	22.2801
1977.4	21.316
1978.39	24.1742
1979.37	23.201
1980.35	27.0309
1981.33	21.2607
1982.31	23.1613
1983.3	27.9259
1984.28	24.0729
1985.26	25.0107
1986.24	24.9956
1987.22	25.9543
1988.21	23.0612
1989.19	23.9951
1990.17	24.8452
1991.15	25.0093
1992.13	24.8365
1993.11	22.9897
1994.09	23.0527
1995.07	25.4463
1996.05	24.336
1997.03	25.0975
1998.01	24.3391
1998.99	23.5365
1999.97	23.7655
2000.95	24.4409
2001.92	23.9276
2002.9	24.3466
2003.88	26.924
2004.86	24.6635
2005.84	24.3947
2006.81	24.9978
2007.79	24.8908
2008.77	25.9262
2009.75	25.0232
2010.73	24.8546
2011.7	21.5805
2012.68	22.2822
2013.67	22.2552
2014.66	23.1566
2015.64	22.2058
2016.63	26.9077
2017.62	25.9828
2018.61	25.9462
2019.6	22.1577
2020.58	24.0189
2021.57	23.0802
2022.56	25.8805
2023.55	23.0477
2024.54	23.026
2025.52	22.9937
2026.51	23.9054
2027.5	25.8341
2028.48	25.8022
2029.47	22.0969
2030.45	25.7601
2031.44	24.8355
2032.43	24.837
2033.41	25.7999
2034.4	22.9962
2035.38	26.6924
2036.37	23.0045
2037.35	22.9952
2038.34	27.6602
2039.32	23.9039
2040.31	22.948
2041.29	24.7883
2042.27	23.8425
2043.26	24.7618
2044.24	21.0562
2045.23	26.6351
2046.21	26.6863
2047.19	24.7927
2048.17	21.9628
2049.16	23.8305
2050.14	21.0534
2051.12	23.869
2052.11	27.588
2053.09	25.7264
2054.07	24.8161
2055.05	25.757
2056.03	25.7424
2057.01	21.9929
2058	19.1906
2058.98	26.688
2059.96	22.0171
2060.94	23.8784
2061.92	26.6941
2062.9	26.6977
2063.88	25.7744
2064.86	25.7817
2065.84	26.7419
2066.82	24.8776
2067.8	25.8252
2068.78	22.0748
2069.76	23.0061
2070.73	23.0014
2071.71	23.9537
2072.69	25.8673
2073.67	28.6848
2074.65	26.8058
2075.63	24.0072
2076.6	23.0865
2077.58	26.8468
2078.56	23.0646
2079.54	29.6817
2080.51	25.9292
2081.49	24.0362
2082.47	22.1439
2083.45	23.0892
2084.42	24.9749
2085.4	20.2484
2086.37	30.6509
2087.35	26.8874
2088.32	25.9461
2089.3	24.0548
2090.28	24.0683
2091.25	23.1258
2092.23	26.9339
2093.2	26.0152
2094.18	21.2846
2095.15	22.2368
2096.13	26.9727
2097.1	24.1132
2098.07	26.944
2099.05	25.9858
2100.02	26.9284
2101	24.0833
2101.97	26.945
2102.94	25.0408
2103.92	23.1272
2104.89	25.028
2105.86	22.1919
2106.83	26.0016
2107.8	24.0991
2108.78	25.9724
2109.75	30.7187
2110.72	23.1228
2111.69	23.1183
2112.66	26.9073
2113.63	20.2683
2114.61	23.1197
2115.58	25.0176
2116.55	22.154
2117.52	24.9919
2118.49	25.929
2119.46	26.8492
2120.43	22.0889
2121.4	26.8303
2122.37	26.8515
2123.34	25.9151
2124.31	24.0123
2125.28	28.7187
2126.25	21.1036
2127.21	27.7029
2128.18	24.8528
2129.15	25.7914
2130.12	26.7278
2131.09	22.9384
2132.06	23.8672
2133.02	24.7942
2133.99	24.7907
2134.96	22.902
2135.93	24.7816
2136.89	24.7563
2137.86	24.7588
2138.83	23.8048
2139.79	24.7505
2140.76	26.6115
2141.73	24.7185
2142.69	24.7033
2143.66	22.8352
2144.62	26.5489
2145.59	22.7866
2146.55	23.7199
2147.52	27.4665
2148.48	22.7545
2149.45	27.4315
2150.42	27.3974
2151.38	26.4507
2152.34	24.5852
2153.31	24.5744
2154.27	22.6851
2155.24	23.5866
2156.2	24.4875
2157.16	23.5418
2158.13	27.2864
2159.09	25.4184
2160.05	25.4011
2161.01	25.3754
2161.98	27.2296
2162.94	24.4267
2163.9	25.346
2164.86	25.3255
2165.83	25.3225
2166.79	21.588
2167.75	27.1556
2168.71	27.1156
2169.67	26.1927
2170.63	25.2909
2171.59	25.2814
2172.56	26.1665
2173.51	27.0836
2174.48	24.3003
2175.44	25.2278
2176.4	26.1488
2177.36	23.3514
2178.32	27.066
2179.28	23.3337
2180.23	24.2609
2181.19	27.0393
2182.15	26.0998
2183.11	23.3043
2184.07	24.2071
2185.03	19.5639
2185.99	23.2761
2186.95	24.2197
2187.9	26.1009
2188.86	25.159
2189.82	24.2026
2190.78	27.8976
2191.73	26.0468
2192.69	24.1979
2193.65	26.0658
2194.6	24.2419
2195.56	25.1664
2196.52	24.2102
2197.47	26.0407
2198.43	26.0378
2199.38	25.1358
2200.34	30.7495
2201.3	22.4137
2202.25	26.0524
2203.21	25.164
2204.16	23.3838
2205.12	24.271
2206.07	26.0705
2207.03	23.2768
2207.98	23.2881
2208.93	24.2352
2209.89	24.2403
2210.84	23.3129
2211.8	25.1896
2212.75	24.2706
2213.7	26.1229
2214.66	25.2001
2215.61	21.4795
2216.56	25.2129
2217.51	25.2075
2218.47	24.2731
2219.42	26.1499
2220.37	19.6187
2221.32	24.2844
2222.27	27.9943
2223.23	25.1926
2224.18	24.2768
2225.13	23.3644
2226.08	25.2574
2227.03	25.275
2227.98	28.0995
2228.93	27.1528
2229.88	27.152
2230.83	26.2348
2231.78	24.377
2232.73	24.3937
2233.68	27.2317
2234.63	24.4161
2235.58	25.3365
2236.53	23.4498
2237.48	27.2198
2238.43	22.5442
2239.38	26.3422
2240.33	25.3856
2241.27	21.6208
2242.22	23.5116
2243.17	27.2934
2244.12	25.3929
2245.07	21.6253
2246.01	23.5393
2246.96	25.445
2247.91	26.4005
2248.85	23.5543
2249.8	24.4988
2250.75	26.3837
2251.69	23.5248
2252.64	25.4197
2253.59	24.5067
2254.53	25.4747
2255.48	25.475
2256.42	26.4277
2257.37	25.4945
2258.32	21.7061
2259.26	23.6111
2260.2	22.6688
2261.15	26.4802
2262.1	26.4948
2263.04	24.6022
2263.98	23.6748
2264.93	27.524
2265.87	23.719
2266.81	22.7503
2267.76	22.7302
2268.7	25.5745
2269.65	27.497
2270.59	25.6183
2271.53	24.6783
2272.47	22.7765
2273.42	27.5625
2274.36	27.5662
2275.3	23.7409
2276.24	23.7442
2277.18	23.7634
2278.13	25.712
2279.07	24.7663
2280.01	25.7057
2280.95	22.8015
2281.89	24.7054
2282.83	24.716
2283.77	25.7021
2284.71	22.8566
2285.65	22.8691
2286.59	27.6622
2287.54	27.6903
2288.47	22.884
2289.41	23.8264
2290.35	27.6394
2291.29	23.793
2292.23	24.777
2293.17	27.6852
2294.11	23.8413
2295.05	24.7895
2295.99	24.7732
2296.93	26.6747
2297.86	23.8013
2298.8	23.8225
2299.74	26.734
2300.68	25.7688
2301.61	25.7802
2302.55	24.812
2303.49	21.9114
2304.43	24.811
2305.36	24.8237
2306.3	25.7971
2307.24	23.8661
2308.17	28.6873
2309.11	23.8504
2310.04	21.9351
2310.98	26.7765
2311.92	26.7324
2312.85	23.8101
2313.79	26.7102
2314.72	27.7089
2315.66	22.8879
2316.59	25.7543
2317.52	27.673
2318.46	23.8119
2319.39	22.8293
2320.33	27.6439
2321.26	23.7881
2322.2	20.9079
2323.13	30.5856
2324.06	30.5909
2325	34.446
2325.93	31.5088
2326.86	45.9525
2327.79	89.2958
2328.73	222.287
2329.66	79.5827
2330.59	42.9732
2331.52	31.4079
2332.46	28.5243
2333.39	25.6158
2334.32	25.6011
2335.25	24.6193
2336.18	25.5789
2337.11	25.57
2338.04	27.4845
2338.97	24.5932
2339.91	26.5137
2340.84	27.4573
2341.77	27.4215
2342.7	27.3972
2343.63	21.6379
2344.56	21.6352
2345.49	27.3799
2346.41	26.3977
2347.34	25.4306
2348.27	24.4702
2349.2	24.4701
2350.13	27.2985
2351.06	24.311
2351.99	25.3618
2352.91	23.4126
2353.84	26.2337
2354.77	28.1374
2355.7	27.1836
2356.63	25.2576
2357.55	24.2728
2358.48	27.1077
2359.41	24.2425
2360.33	19.4789
2361.26	25.1493
2362.19	25.1212
2363.11	26.0406
2364.04	26.0231
2364.97	23.1688