File: Data/3-Raman/raw/bu02aw-a-ff1-fi04-v_1800 (450-850nm)_532nm_edge_100%_x100_vis_lwd_h100um_30sx2_01.txt
#Acq. time (s)=	30
#Accumulations=	2
#Range (cm-¹)=	1200...2365
#Windows=	3
#Auto scanning=	Off
#Autofocus=	Off
#Macrospot=	Off
#AutoExposure=	Off
#Spike filter=	Multiple accum.
#Delay time (s)=	2
#Binning=	1
#Readout mode=	Signal
#DeNoise=	Off
#ICS correction=	On
#Dark correction=	Off
#Inst. Process=	Off
#Detector Gain=	Best Dynamic
#Detector ADC=	50 kHz HS
#Detector temperature (°C)=	-60.09
#Instrument=	LabRAM HR Evol
#Detector=	SIN-EM FIVIS
#Objective=	x100_VIS_LWD
#Grating=	1800 (450-850nm)
#ND Filter=	100%
#Laser=	532nm_Edge
#Hole=	100.021
#Temperature=	0
#Range=	Visible
#StageXY=	75x50mm Scan+
#StageZ=	Z motor
#X (µm)=	0
#Y (µm)=	0
#Z (µm)=	-16.5
#Full time(mm:ss)=	3:18
#Project=	21_11_26
#Sample=	BU02Aw
#Site=
#Title=	BU02aW-A-FF1-FI04-S_1800 (450-850nm)_532nm_Edge_100%_x100_VIS_LWD_H100um_30sX2
#Remark=
#Date=	26.11.2021 11:05
#Acquired=	26.11.2021 11:05:18
1202.72	67.2137
1203.84	65.0884
1204.95	70.4164
1206.06	67.0919
1207.17	65.892
1208.28	59.399
1209.39	65.7516
1210.5	57.1695
1211.61	66.686
1212.72	64.4625
1213.83	67.5961
1214.94	64.3926
1216.05	64.3793
1217.16	66.4107
1218.27	61.0261
1219.38	65.2309
1220.49	70.5045
1221.6	61.997
1222.71	66.1493
1223.81	63.9116
1224.92	70.1714
1226.03	57.5045
1227.14	63.8256
1228.25	59.4672
1229.35	68.7817
1230.46	64.7519
1231.57	66.6703
1232.67	61.4158
1233.78	65.6032
1234.89	63.5254
1235.99	57.2449
1237.1	63.5373
1238.2	67.6539
1239.31	61.2816
1240.41	62.3071
1241.52	69.6505
1242.62	71.719
1243.73	70.6921
1244.83	68.5936
1245.94	70.6238
1247.04	68.4898
1248.14	75.7975
1249.25	69.4783
1250.35	67.3838
1251.45	65.2322
1252.56	70.4048
1253.66	77.6592
1254.76	67.2607
1255.87	78.7569
1256.97	73.5502
1258.07	78.7524
1259.17	91.2352
1260.27	81.8933
1261.37	95.3634
1262.48	100.797
1263.58	149.535
1264.68	191.853
1265.78	134.189
1266.88	97.6119
1267.98	86.1987
1269.08	93.6444
1270.18	86.311
1271.28	89.3685
1272.38	92.5164
1273.47	82.1459
1274.57	85.3701
1275.67	85.3788
1276.77	88.5919
1277.87	91.8155
1278.97	97.1561
1280.07	107.692
1281.16	133.989
1282.26	249.865
1283.36	715.846
1284.45	1999.04
1285.55	995.668
1286.65	226.805
1287.75	127.762
1288.84	109.836
1289.94	94.1039
1291.03	84.6484
1292.13	86.7434
1293.22	81.4712
1294.32	82.6235
1295.42	79.4773
1296.51	75.4156
1297.61	74.3465
1298.7	80.6393
1299.79	73.2056
1300.89	75.3379
1301.98	64.7866
1303.08	73.2527
1304.17	71.1112
1305.26	72.1581
1306.35	71.0393
1307.45	71.0239
1308.54	65.7533
1309.63	65.7715
1310.73	70.0012
1311.82	74.2318
1312.91	70.0418
1314	77.407
1315.09	68.9669
1316.18	62.6633
1317.28	66.8753
1318.37	66.8945
1319.46	71.1217
1320.55	63.7256
1321.64	64.7351
1322.73	66.7843
1323.82	67.8131
1324.91	63.5973
1326	63.5533
1327.09	65.5511
1328.18	71.984
1329.27	60.4626
1330.35	67.8372
1331.44	74.1027
1332.53	70.8367
1333.62	60.2298
1334.71	68.5602
1335.79	64.3052
1336.88	68.4574
1337.97	68.4284
1339.06	61.0424
1340.14	64.1798
1341.23	70.4666
1342.32	71.4849
1343.4	66.1908
1344.49	67.2287
1345.58	71.3765
1346.66	66.0555
1347.75	68.0596
1348.83	59.6887
1349.92	72.1413
1351	65.8396
1352.09	68.9084
1353.17	71.0306
1354.25	67.9754
1355.34	63.6594
1356.42	70.9238
1357.51	64.656
1358.59	70.8403
1359.67	70.7887
1360.76	73.8277
1361.84	74.8383
1362.92	70.6668
1364	82.0816
1365.09	83.111
1366.17	84.0727
1367.25	77.7774
1368.33	73.6379
1369.41	107.776
1370.5	132.552
1371.58	96.2909
1372.66	90.9931
1373.74	86.8066
1374.82	98.1098
1375.9	101.195
1376.98	100.117
1378.06	105.226
1379.14	120.86
1380.22	134.192
1381.3	142.141
1382.38	141.991
1383.46	166.405
1384.54	189.889
1385.61	263.953
1386.69	689.371
1387.77	3611.07
1388.85	1743.42
1389.93	328.82
1391	176.57
1392.08	127.248
1393.16	105.649
1394.23	106.63
1395.31	91.273
1396.39	99.4886
1397.46	86.136
1398.54	84.0701
1399.62	85.1269
1400.69	81.06
1401.77	84.1682
1402.84	89.4227
1403.92	81.2914
1404.99	84.311
1406.07	89.3813
1407.14	113.954
1408.22	147.819
1409.29	259.649
1410.37	192.004
1411.44	104.703
1412.51	83.1655
1413.59	71.0622
1414.66	64.8197
1415.73	67.9277
1416.81	62.8128
1417.88	66.9505
1418.95	62.8505
1420.02	61.8063
1421.1	61.756
1422.17	61.7587
1423.24	60.8572
1424.31	69.8856
1425.38	58.6061
1426.45	62.7242
1427.52	61.6363
1428.59	63.6244
1429.67	60.5689
1430.74	60.62
1431.81	53.5115
1432.87	58.6097
1433.95	52.3758
1435.01	53.4171
1436.08	52.3908
1437.15	50.3247
1438.22	53.3826
1439.29	55.4485
1440.36	50.3617
1441.43	49.3487
1442.49	53.4436
1443.56	53.4392
1444.63	51.3767
1445.7	52.4415
1446.77	56.5258
1447.83	51.3772
1448.9	52.4172
1449.97	51.3824
1451.03	49.3065
1452.1	53.3863
1453.17	50.3088
1454.23	56.4641
1455.3	44.1625
1456.36	49.2962
1457.43	49.2749
1458.49	44.1435
1459.56	47.2235
1460.62	44.1421
1461.69	44.1212
1462.75	44.0894
1463.82	49.1608
1464.88	45.1196
1465.94	47.0275
1467.01	51.0922
1468.07	50.0623
1469.13	46.9941
1470.2	41.8658
1471.26	49.9935
1472.32	46.9103
1473.39	45.8829
1474.45	44.8417
1475.51	48.9192
1476.57	48.9006
1477.63	45.8242
1478.69	46.8225
1479.76	45.7746
1480.82	45.7241
1481.88	44.6914
1482.94	41.6758
1484	50.8215
1485.06	48.6887
1486.12	46.6467
1487.18	48.6771
1488.24	41.5616
1489.3	46.5861
1490.36	41.5136
1491.42	46.5457
1492.48	44.5176
1493.53	40.4669
1494.59	45.5188
1495.65	42.4672
1496.71	46.4627
1497.77	44.4297
1498.82	42.4075
1499.88	44.4348
1500.94	51.5037
1502	43.4086
1503.05	43.3907
1504.11	43.3675
1505.17	47.4041
1506.22	44.3377
1507.28	46.3553
1508.34	40.3083
1509.39	44.3381
1510.45	50.3904
1511.5	42.2884
1512.56	45.2196
1513.61	47.1759
1514.67	43.1863
1515.72	45.1548
1516.78	46.1149
1517.83	43.0983
1518.88	43.1132
1519.94	48.1401
1520.99	43.1166
1522.05	48.1399
1523.1	50.1239
1524.15	50.0658
1525.2	44.0343
1526.26	42.0476
1527.31	46.0779
1528.36	45.0571
1529.41	43.0357
1530.47	45.0245
1531.52	45.0525
1532.57	45.0442
1533.62	45.0904
1534.67	47.1023
1535.72	43.0683
1536.77	40.0037
1537.82	48.9613
1538.87	41.9325
1539.92	39.991
1540.97	36.0443
1542.02	47.0435
1543.07	47.9968
1544.12	47.9407
1545.17	39.9636
1546.22	44.0073
1547.27	48.0225
1548.32	45.9937
1549.37	46.9663
1550.42	48.9833
1551.46	45.1088
1552.51	48.1208
1553.56	44.0705
1554.61	49.0496
1555.65	49.0046
1556.7	48.9989
1557.75	48.003
1558.79	46.9617
1559.84	47.9068
1560.89	43.8834
1561.93	48.8877
1562.98	48.9122
1564.02	39.902
1565.07	41.9337
1566.11	48.6429
1567.16	47.845
1568.2	41.8826
1569.25	47.89
1570.29	44.8664
1571.34	46.8622
1572.38	50.8346
1573.43	42.8154
1574.47	42.8092
1575.51	44.8473
1576.56	48.849
1577.6	46.7935
1578.64	48.7318
1579.69	48.7267
1580.73	49.7365
1581.77	48.7157
1582.81	45.6978
1583.85	49.6714
1584.9	48.676
1585.94	44.6876
1586.98	48.633
1588.02	55.5773
1589.06	51.6139
1590.1	48.6447
1591.14	44.6733
1592.18	47.6493
1593.22	44.6187
1594.26	45.5459
1595.3	47.5396
1596.34	50.5011
1597.38	47.525
1598.42	50.5059
1599.46	49.4668
1600.5	46.456
1601.54	52.3483
1602.58	52.294
1603.62	43.3461
1604.66	50.2559
1605.69	45.3148
1606.73	49.291
1607.77	51.2028
1608.81	49.9976
1609.84	45.4291
1610.88	51.1541
1611.92	53.5528
1612.95	51.6832
1613.99	50.8124
1615.03	46.9183
1616.06	53.3324
1617.1	54.335
1618.13	50.9889
1619.17	50.8729
1620.2	52.1792
1621.24	49.0641
1622.27	50.7931
1623.31	50.8872
1624.34	51.4084
1625.38	51.2555
1626.41	52.6659
1627.45	54.0295
1628.48	52.1553
1629.51	55.5736
1630.55	53.4668
1631.53	52.4138
1632.57	51.4498
1633.62	49.4717
1634.66	50.4665
1635.71	58.344
1636.75	52.405
1637.8	56.3108
1638.84	53.3378
1639.89	49.3976
1640.93	58.2639
1641.98	48.4156
1643.02	49.3869
1644.06	50.3601
1645.11	49.3517
1646.15	53.3001
1647.19	48.3578
1648.24	56.2065
1649.28	51.3335
1650.32	54.282
1651.37	57.285
1652.41	53.3516
1653.45	48.4101
1654.49	43.4904
1655.53	52.3799
1656.57	53.4192
1657.62	52.4306
1658.66	52.4089
1659.7	51.3893
1660.74	40.5328
1661.78	51.4133
1662.82	52.4571
1663.86	51.4728
1664.9	51.4354
1665.94	53.337
1666.98	44.5168
1668.02	49.4235
1669.06	47.4567
1670.1	46.501
1671.14	50.4873
1672.18	49.4869
1673.21	47.5125
1674.25	49.4988
1675.29	51.5034
1676.33	54.4819
1677.37	53.4947
1678.4	44.5626
1679.44	50.4618
1680.48	46.4873
1681.52	47.4563
1682.55	45.4764
1683.59	48.4342
1684.63	51.382
1685.66	48.4069
1686.7	49.3966
1687.73	51.3817
1688.77	50.3688
1689.81	47.37
1690.84	44.3954
1691.88	46.3828
1692.91	44.4009
1693.95	43.3681
1694.98	49.2424
1696.01	45.3062
1697.05	41.3743
1698.08	46.2615
1699.12	48.1946
1700.15	41.3017
1701.18	44.2391
1702.22	47.1632
1703.25	42.2174
1704.28	44.1685
1705.32	45.157
1706.35	44.1614
1707.38	42.1533
1708.41	43.0832
1709.44	43.0267
1710.48	46.9299
1711.51	45.9641
1712.54	46.9434
1713.57	43.935
1714.6	43.8855
1715.63	48.7666
1716.66	38.0172
1717.69	42.8437
1718.72	42.7698
1719.75	46.6448
1720.78	49.5603
1721.81	44.6502
1722.84	44.6027
1723.87	41.6532
1724.9	37.7538
1725.93	43.5144
1726.96	44.4641
1727.99	42.5103
1729.02	48.2232
1730.05	38.5125
1731.07	46.2087
1732.1	38.5291
1733.13	43.3399
1734.16	38.455
1735.18	48.0383
1736.21	41.2505
1737.24	45.0766
1738.26	42.1622
1739.29	39.2399
1740.32	44.9316
1741.34	41.0434
1742.37	42.9264
1743.4	42.91
1744.42	38.1015
1745.45	49.5685
1746.47	39.9849
1747.5	43.759
1748.52	37.0475
1749.55	43.7365
1750.57	39.9471
1751.6	36.1374
1752.62	42.7855
1753.64	43.7
1754.67	38.895
1755.69	39.824
1756.71	40.7372
1757.74	42.5932
1758.76	40.7012
1759.78	43.5571
1760.81	44.4935
1761.83	44.4611
1762.85	42.5535
1763.87	43.5065
1764.89	42.5851
1765.92	35.9374
1766.94	40.6915
1767.96	44.4827
1768.98	43.5093
1770	42.4769
1771.02	40.5966
1772.04	40.6275
1773.06	40.6483
1774.08	42.5671
1775.1	42.5782
1776.12	41.6638
1777.14	36.8947
1778.16	44.4887
1779.18	43.4962
1780.2	43.4858
1781.22	43.4976
1782.24	39.6985
1783.26	41.6282
1784.28	38.7867
1785.29	41.6726
1786.31	40.7048
1787.33	43.5847
1788.35	43.6654
1789.37	37.0239
1790.38	42.8055
1791.4	42.7971
1792.42	40.8451
1793.43	39.897
1794.45	43.7355
1795.47	40.8947
1796.48	39.978
1797.5	36.1627
1798.51	40.0241
1799.53	38.0946
1800.55	38.0656
1801.56	40.9326
1802.58	40.938
1803.59	44.8104
1804.61	43.8662
1805.62	41.0128
1806.64	41.043
1807.65	33.341
1808.66	43.9425
1809.68	42.982
1810.69	38.1639
1811.7	46.8322
1812.72	37.1946
1813.73	42.0351
1814.74	44.0023
1815.76	38.235
1816.77	38.2406
1817.78	39.1807
1818.79	45.948
1819.8	40.1597
1820.82	45.9778
1821.83	41.1605
1822.84	40.2072
1823.85	38.2683
1824.86	40.2031
1825.87	37.3098
1826.88	38.2776
1827.89	44.0988
1828.9	41.1881
1829.91	41.1721
1830.92	39.2165
1831.93	44.0714
1832.94	41.1878
1833.95	44.1046
1834.96	41.1656
1835.97	42.0666
1836.98	44.1616
1837.99	38.2115
1839	46.9152
1840	41.1628
1841.01	42.0456
1842.02	37.1379
1843.03	43.8549
1844.04	44.8165
1845.04	41.9209
1846.05	44.8252
1847.06	37.139
1848.07	40.858
1849.07	41.8256
1850.08	39.866
1851.09	43.6572
1852.09	39.7842
1853.1	42.6595
1854.1	46.4787
1855.11	44.5089
1856.11	43.5048
1857.12	45.4108
1858.12	45.3906
1859.13	46.3067
1860.13	41.4909
1861.14	37.68
1862.14	46.3106
1863.15	43.4079
1864.15	40.4997
1865.15	46.195
1866.16	47.0863
1867.16	45.0992
1868.16	44.0881
1869.17	42.1786
1870.17	43.1182
1871.17	42.1574
1872.17	49.7389
1873.18	45.9073
1874.18	54.4275
1875.18	49.6329
1876.18	47.6627
1877.18	48.5545
1878.18	42.8143
1879.19	46.6671
1880.19	53.3297
1881.19	47.6399
1882.19	48.5119
1883.19	41.8025
1884.19	48.3508
1885.19	51.2015
1886.19	51.2647
1887.19	55.031
1888.19	44.6007
1889.19	48.3044
1890.19	51.0978
1891.19	51.127
1892.18	49.2295
1893.18	53.911
1894.18	48.1858
1895.18	47.221
1896.18	46.2937
1897.18	47.262
1898.17	56.6785
1899.17	44.4207
1900.17	50.9636
1901.16	47.2013
1902.16	51.9365
1903.16	40.6664
1904.16	52.8711
1905.15	46.2785
1906.15	43.4379
1907.14	49.0386
1908.14	47.1636
1909.14	38.7246
1910.13	52.8654
1911.13	55.7527
1912.12	47.2884
1913.12	49.1615
1914.11	44.4709
1915.11	49.2282
1916.1	44.526
1917.1	42.6146
1918.09	51.0752
1919.08	45.4462
1920.08	46.4521
1921.07	46.4581
1922.06	51.2219
1923.06	46.4841
1924.05	50.2424
1925.04	45.4915
1926.04	46.4657
1927.03	50.3018
1928.02	50.3309
1929.01	44.6647
1930	46.5958
1931	44.7448
1931.99	45.6866
1932.98	44.7087
1933.97	45.6625
1934.96	46.7446
1935.95	46.8451
1936.94	46.7971
1937.93	47.7053
1938.92	45.796
1939.91	42.9618
1940.9	46.8023
1941.89	41.1178
1942.88	48.7697
1943.87	52.5547
1944.86	47.8161
1945.85	44.9931
1946.84	49.8028
1947.83	45.0113
1948.82	44.0467
1949.8	45.0294
1950.79	42.2159
1951.78	44.1982
1952.77	45.1923
1953.76	45.195
1954.74	50.847
1955.73	44.1112
1956.72	47.0632
1957.7	46.1449
1958.69	42.3213
1959.68	50.9523
1960.66	43.2406
1961.65	41.2881
1962.63	45.1255
1963.62	44.1701
1964.61	44.1816
1965.59	42.2533
1966.58	44.195
1967.56	44.2136
1968.55	41.3347
1969.53	46.1138
1970.52	47.0193
1971.5	39.3144
1972.48	40.2705
1973.47	40.2589
1974.45	40.2304
1975.44	43.1068
1976.42	41.2084
1977.4	43.1271
1978.39	43.1024
1979.37	45.0028
1980.35	38.2942
1981.33	45.9353
1982.31	43.0425
1983.3	43.0134
1984.28	49.6765
1985.26	47.7385
1986.24	45.8084
1987.22	43.9095
1988.21	42.9188
1989.19	42.8617
1990.17	46.4647
1991.15	40.3432
1992.13	48.1549
1993.11	42.7142
1994.09	43.4288
1995.07	47.0032
1996.05	42.5773
1997.03	44.9511
1998.01	45.2077
1998.99	46.37
1999.97	43.0208
2000.95	43.7277
2001.92	41.5249
2002.9	43.4195
2003.88	44.6062
2004.86	45.0791
2005.84	43.6581
2006.81	48.8006
2007.79	45.766
2008.77	45.2335
2009.75	44.7703
2010.73	43.2156
2011.7	42.8396
2012.68	46.4366
2013.67	46.3826
2014.66	44.4278
2015.64	41.5918
2016.63	47.2426
2017.62	43.5137
2018.61	40.6386
2019.6	45.2615
2020.58	45.2403
2021.57	48.9866
2022.56	45.2259
2023.55	45.1822
2024.54	47.9463
2025.52	46.0144
2026.51	45.975
2027.5	41.4181
2028.48	46.0392
2029.47	39.5612
2030.45	44.1035
2031.44	42.2552
2032.43	46.9277
2033.41	45.1172
2034.4	49.7948
2035.38	44.1174
2036.37	49.8226
2037.35	43.261
2038.34	46.0516
2039.32	46.0215
2040.31	45.0473
2041.29	45.0014
2042.27	47.7755
2043.26	46.8224
2044.24	43.1446
2045.23	45.9145
2046.21	45.0736
2047.19	40.3634
2048.17	46.836
2049.16	47.7791
2050.14	42.2304
2051.12	41.3269
2052.11	42.2355
2053.09	46.9185
2054.07	42.2929
2055.05	41.37
2056.03	46.9588
2057.01	50.6813
2058	44.1476
2058.98	47.9234
2059.96	45.1367
2060.94	46.0547
2061.92	47.0085
2062.9	50.7642
2063.88	47.0463
2064.86	46.1261
2065.84	42.4155
2066.82	49.0138
2067.8	49.9737
2068.78	46.2363
2069.76	49.9813
2070.73	42.4584
2071.71	45.3055
2072.69	46.3097
2073.67	47.2417
2074.65	44.4269
2075.63	43.538
2076.6	47.3607
2077.58	44.505
2078.56	46.3796
2079.54	46.4043
2080.51	42.6703
2081.49	42.6677
2082.47	45.5008
2083.45	44.5606
2084.42	47.3911
2085.4	53.0619
2086.37	52.1328
2087.35	44.6032
2088.32	42.7219
2089.3	43.6745
2090.28	45.5976
2091.25	47.5063
2092.23	46.5933
2093.2	46.6509
2094.18	45.7439
2095.15	45.7516
2096.13	50.475
2097.1	43.8106
2098.07	50.4275
2099.05	48.5154
2100.02	50.4048
2101	44.7181
2101.97	44.7448
2102.94	44.7399
2103.92	43.7664
2104.89	46.6222
2105.86	48.5534
2106.83	50.4754
2107.8	43.8222
2108.78	45.6765
2109.75	49.4743
2110.72	43.7837
2111.69	49.4782
2112.66	44.7134
2113.63	48.5381
2114.61	48.5441
2115.58	50.4431
2116.55	48.519
2117.52	49.4487
2118.49	46.5805
2119.46	44.6357
2120.43	49.3388
2121.4	45.5576
2122.37	47.4945
2123.34	45.6226
2124.31	50.364
2125.28	45.5568
2126.25	42.6521
2127.21	49.2327
2128.18	50.1563
2129.15	44.475
2130.12	45.408
2131.09	47.2831
2132.06	45.366
2133.02	46.2811
2133.99	50.9965
2134.96	47.223
2135.93	46.2679
2136.89	42.4526
2137.86	53.7748
2138.83	47.156
2139.79	51.8798
2140.76	42.4146
2141.73	49.9365
2142.69	49.9091
2143.66	45.2359
2144.62	51.7261
2145.59	46.0858
2146.55	45.1357
2147.52	49.8143
2148.48	52.6064
2149.45	43.1859
2150.42	47.8219
2151.38	44.9967
2152.34	49.7065
2153.31	43.1255
2154.27	44.9758
2155.24	50.5248
2156.2	47.6526
2157.16	46.6992
2158.13	45.7818
2159.09	49.5258
2160.05	49.4953
2161.01	49.4482
2161.98	45.6971
2162.94	46.6258
2163.9	48.4688
2164.86	44.7054
2165.83	47.4987
2166.79	48.4191
2167.75	44.658
2168.71	51.1019
2169.67	43.679
2170.63	49.3189
2171.59	46.511
2172.56	49.2199
2173.51	48.2716
2174.48	45.4955
2175.44	49.2128
2176.4	48.2713
2177.36	45.4682
2178.32	44.5403
2179.28	47.2975
2180.23	44.5134
2181.19	44.5044
2182.15	41.7041
2183.11	44.4699
2184.07	48.1345
2185.03	47.191
2185.99	45.3533
2186.95	46.3162
2187.9	44.5084
2188.86	44.4882
2189.82	50.9311
2190.78	46.2727
2191.73	46.2817
2192.69	49.0788
2193.65	44.4661
2194.6	47.3183
2195.56	49.1712
2196.52	48.1918
2197.47	42.5796
2198.43	49.0714
2199.38	46.3398
2200.34	51.0556
2201.3	45.5514
2202.25	46.3277
2203.21	50.1273
2204.16	49.3733
2205.12	46.486
2206.07	51.9515
2207.03	51.0162
2207.98	46.3947
2208.93	39.9143
2209.89	47.3762
2210.84	49.2514
2211.8	47.4176
2212.75	47.4477
2213.7	47.4263
2214.66	49.3143
2215.61	47.478
2216.56	47.4798
2217.51	45.6061
2218.47	43.7408
2219.42	47.4962
2220.37	47.52
2221.32	50.3125
2222.27	44.6636
2223.23	45.5989
2224.18	46.5711
2225.13	48.4908
2226.08	52.283
2227.03	43.8887
2227.98	49.5381
2228.93	46.7124
2229.88	47.6518
2230.83	53.3237
2231.78	46.7951
2232.73	44.9509
2233.68	53.4508
2234.63	50.6471
2235.58	48.7277
2236.53	47.7797
2237.48	50.6199
2238.43	49.7477
2239.38	52.6372
2240.33	52.6136
2241.27	47.9192
2242.22	51.7062
2243.17	47.947
2244.12	47.9269
2245.07	46.0593
2246.01	53.6767
2246.96	48.0369
2247.91	43.3254
2248.85	46.1552
2249.8	42.3698
2250.75	50.8756
2251.69	51.781
2252.64	48.0102
2253.59	45.2375
2254.53	50.9662
2255.48	50.9709
2256.42	50.9833
2257.37	48.1707
2258.32	47.2438
2259.26	50.1093
2260.2	50.1311
2261.15	53.0058
2262.1	45.427
2263.04	53.0663
2263.98	47.4078
2264.93	46.5196
2265.87	49.4153
2266.81	46.5258
2267.76	43.6264
2268.7	46.4592
2269.65	50.3052
2270.59	47.5015
2271.53	49.447
2272.47	50.4309
2273.42	52.3531
2274.36	46.6212
2275.3	47.5883
2276.24	49.5141
2277.18	49.5587
2278.13	53.463
2279.07	47.7354
2280.01	47.6995
2280.95	48.6101
2281.89	51.4619
2282.83	46.6935
2283.77	49.6268
2284.71	44.8989
2285.65	51.6639
2286.59	44.8997
2287.54	48.8
2288.47	48.8219
2289.41	48.7826
2290.35	57.3721
2291.29	51.6066
2292.23	47.8078
2293.17	50.7367
2294.11	47.8698
2295.05	46.8797
2295.99	52.6293
2296.93	50.6611
2297.86	48.7674
2298.8	49.7787
2299.74	44.0333
2300.68	46.9291
2301.61	53.7096
2302.55	47.9162
2303.49	46.9444
2304.43	54.6793
2305.36	46.9841
2306.3	47.001
2307.24	47.9749
2308.17	49.8908
2309.11	49.8834
2310.04	47.0259
2310.98	50.9093
2311.92	45.0335
2312.85	49.8154
2313.79	50.7936
2314.72	47.9588
2315.66	55.7256
2316.59	45.9937
2317.52	49.8368
2318.46	48.8783
2319.39	45.9508
2320.33	50.7592
2321.26	51.7371
2322.2	49.8486
2323.13	54.7127
2324.06	56.6595
2325	66.3081
2325.93	65.2683
2326.86	92.2279
2327.79	173.134
2328.73	404.422
2329.66	167.205
2330.59	78.5785
2331.52	62.1941
2332.46	51.6137
2333.39	54.4689
2334.32	42.8937
2335.25	44.7863
2336.18	48.6327
2337.11	51.5038
2338.04	53.414
2338.97	56.2858
2339.91	49.5579
2340.84	49.5294
2341.77	48.5085
2342.7	48.4686
2343.63	48.4584
2344.56	48.4568
2345.49	45.5721
2346.41	49.3651
2347.34	46.478
2348.27	47.4335
2349.2	46.4795
2350.13	50.2315
2351.06	49.0389
2351.99	49.2354
2352.91	47.251
2353.84	47.1806
2354.77	47.1809
2355.7	52.8986
2356.63	48.0992
2357.55	48.0383
2358.48	48.9602
2359.41	47.9859
2360.33	48.9065
2361.26	49.8078
2362.19	49.756
2363.11	46.8656
2364.04	50.6222
2364.97	49.6465