File: Data/3-Raman/raw/bu02aw-a-ff1-host_1800 (450-850nm)_532nm_edge_100%_x100_vis_lwd_h100um_30sx2_01.txt
#Acq. time (s)=	30
#Accumulations=	2
#Range (cm-¹)=	3200...3799
#Windows=	2
#Auto scanning=	Off
#Autofocus=	Off
#Macrospot=	Off
#AutoExposure=	Off
#Spike filter=	Multiple accum.
#Delay time (s)=	2
#Binning=	1
#Readout mode=	Signal
#DeNoise=	Off
#ICS correction=	On
#Dark correction=	Off
#Inst. Process=	Off
#Detector Gain=	Best Dynamic
#Detector ADC=	50 kHz HS
#Detector temperature (°C)=	-60.09
#Instrument=	LabRAM HR Evol
#Detector=	SIN-EM FIVIS
#Objective=	x100_VIS_LWD
#Grating=	1800 (450-850nm)
#ND Filter=	100%
#Laser=	532nm_Edge
#Hole=	100.021
#Temperature=	0
#Range=	Visible
#StageXY=	75x50mm Scan+
#StageZ=	Z motor
#X (µm)=	0
#Y (µm)=	0
#Z (µm)=	-10.3
#Full time(mm:ss)=	2:17
#Project=	21_11_26
#Sample=	BU02Aw
#Site=
#Title=	BU02aW-A-FF1-host_1800 (450-850nm)_532nm_Edge_100%_x100_VIS_LWD_H100um_30sX2
#Remark=
#Date=	26.11.2021 10:44
#Acquired=	26.11.2021 10:44:29
3200.06	418.693
3200.67	413.097
3201.29	416.161
3201.9	430.782
3202.52	427.162
3203.14	421.398
3203.75	435.758
3204.37	436.723
3204.98	443.44
3205.59	444.596
3206.21	452.566
3206.82	447.895
3207.44	465.211
3208.05	461.569
3208.67	456.014
3209.28	457.266
3209.9	462.059
3210.51	480.051
3211.13	472.239
3211.74	501.144
3212.35	491.781
3212.97	511.071
3213.58	497.795
3214.2	494.963
3214.81	508.628
3215.42	523.231
3216.04	514.426
3216.65	532.384
3217.26	527.622
3217.88	526.331
3218.49	546.162
3219.1	553.121
3219.72	543.018
3220.33	546.626
3220.94	566.034
3221.56	556.966
3222.17	567.064
3222.78	586.428
3223.4	582.54
3224.01	571.009
3224.62	596.896
3225.23	588.965
3225.85	609.793
3226.46	596.395
3227.07	620.218
3227.68	633.809
3228.29	662.946
3228.91	648.692
3229.52	662.409
3230.13	657.955
3230.74	685.276
3231.35	667.765
3231.96	671.355
3232.57	680.503
3233.19	699.729
3233.8	699.855
3234.41	717.358
3235.02	709.911
3235.63	714.076
3236.24	739.983
3236.85	772.337
3237.46	772.993
3238.08	779.806
3238.69	783.156
3239.3	784.655
3239.91	801.972
3240.52	823.133
3241.13	818.584
3241.74	827.457
3242.35	841.938
3242.96	836.257
3243.57	841.862
3244.18	860.717
3244.79	853.012
3245.4	873.49
3246.01	874.004
3246.62	881.766
3247.23	908.885
3247.84	898.053
3248.45	932.144
3249.06	947.883
3249.66	946.495
3250.27	970.298
3250.88	965.241
3251.49	969.236
3252.1	995.786
3252.71	998.81
3253.32	1001.47
3253.93	998.258
3254.54	1030.92
3255.14	1023.69
3255.75	1052.71
3256.36	1045.04
3256.97	1057.16
3257.58	1055.97
3258.19	1074.98
3258.79	1104.6
3259.4	1117.15
3260.01	1103.14
3260.62	1110.82
3261.23	1124.32
3261.83	1096.96
3262.44	1149.89
3263.05	1154.17
3263.66	1155.79
3264.26	1182.75
3264.87	1195.84
3265.48	1192.17
3266.08	1181.97
3266.69	1215.77
3267.3	1212.42
3267.91	1221.24
3268.51	1208.35
3269.12	1182.96
3269.73	1213.3
3270.33	1213.4
3270.94	1271.93
3271.55	1234.08
3272.15	1252.96
3272.76	1250.24
3273.36	1264.02
3273.97	1235.49
3274.58	1292.71
3275.18	1290.6
3275.79	1287.22
3276.39	1316.12
3277	1310.7
3277.61	1305.18
3278.21	1322.39
3278.82	1326.93
3279.42	1305.5
3280.03	1290.21
3280.63	1321.39
3281.24	1306.48
3281.84	1311.5
3282.45	1348.82
3283.05	1303.36
3283.66	1321.36
3284.26	1309.37
3284.87	1340.35
3285.47	1333.31
3286.08	1320.9
3286.68	1310.81
3287.29	1345.39
3287.89	1309.53
3288.49	1339.76
3289.1	1300.16
3289.7	1318.2
3290.31	1355.81
3290.91	1333.19
3291.52	1316.24
3292.12	1315.65
3292.72	1320.24
3293.33	1342.77
3293.93	1320.63
3294.53	1353.11
3295.14	1336.36
3295.74	1334.15
3296.34	1332.64
3296.95	1340.15
3297.55	1328.82
3298.15	1311.13
3298.76	1325.14
3299.36	1339.06
3299.96	1340.62
3300.56	1300.98
3301.17	1322.68
3301.77	1329.38
3302.37	1314.58
3302.97	1313.14
3303.58	1343.39
3304.18	1309.57
3304.78	1291.91
3305.38	1278.89
3305.98	1309.3
3306.59	1291.71
3307.19	1289.93
3307.79	1307.2
3308.39	1286.43
3308.99	1288.09
3309.59	1277.99
3310.2	1285.42
3310.8	1255.93
3311.4	1285.73
3312	1296.25
3312.6	1258.63
3313.2	1278.85
3313.8	1267.3
3314.4	1232.97
3315	1262.78
3315.6	1260.89
3316.21	1265.97
3316.81	1248.17
3317.41	1239.03
3318.01	1241.44
3318.61	1287.96
3319.21	1276.28
3319.81	1254.88
3320.41	1242.37
3321.01	1249.69
3321.61	1245.82
3322.21	1224.09
3322.81	1241.52
3323.41	1204.77
3324.01	1258.45
3324.61	1265.78
3325.21	1245.25
3325.81	1235.41
3326.41	1217.66
3327	1218.12
3327.6	1252.5
3328.2	1244.78
3328.8	1237.31
3329.4	1240.99
3330	1237.83
3330.6	1237.13
3331.2	1235.89
3331.8	1228.13
3332.39	1217.86
3332.99	1245.91
3333.59	1249.05
3334.19	1213.76
3334.79	1230
3335.39	1263.05
3335.98	1245.16
3336.58	1261.19
3337.18	1267.33
3337.78	1228.12
3338.37	1239.94
3338.97	1255.71
3339.57	1278.54
3340.17	1235.56
3340.77	1292.75
3341.36	1261.22
3341.96	1263.98
3342.56	1269.13
3343.15	1259.39
3343.75	1299.43
3344.35	1309.94
3344.95	1295.2
3345.54	1283.1
3346.14	1322.07
3346.74	1305.83
3347.33	1300.42
3347.93	1316.17
3348.53	1303.97
3349.12	1327.67
3349.72	1318.02
3350.31	1339.67
3350.91	1322.78
3351.51	1332.13
3352.1	1376.63
3352.7	1311.2
3353.29	1363.24
3353.89	1339.44
3354.49	1358.57
3355.08	1371.96
3355.68	1355.91
3356.27	1390.49
3356.87	1387.33
3357.46	1418.54
3358.06	1372.08
3358.65	1413.33
3359.25	1412.11
3359.84	1413.22
3360.44	1418.52
3361.03	1440.15
3361.63	1451.22
3362.22	1416.79
3362.82	1433.31
3363.41	1460.92
3364.01	1459.62
3364.6	1465.84
3365.19	1440.71
3365.79	1483.13
3366.38	1463.35
3366.98	1464
3367.57	1471.13
3368.16	1476.62
3368.76	1463.58
3369.35	1507.45
3369.95	1500.71
3370.54	1471.42
3371.13	1505.02
3371.73	1512.68
3372.32	1518.49
3372.91	1513.33
3373.51	1491.68
3374.1	1496.68
3374.69	1477.64
3375.28	1552.09
3375.88	1531.51
3376.47	1506.28
3377.06	1486.06
3377.66	1544.76
3378.25	1525.55
3378.84	1502.51
3379.43	1467.8
3380.03	1503.67
3380.62	1521.23
3381.21	1525.18
3381.8	1508.82
3382.39	1497.12
3382.99	1507.64
3383.58	1532.8
3384.17	1508.19
3384.76	1537.83
3385.35	1550.47
3385.95	1528.77
3386.54	1505.65
3387.13	1521.27
3387.72	1557.96
3388.31	1548.89
3388.9	1559.08
3389.49	1552.42
3390.08	1527.05
3390.68	1548.8
3391.27	1549.32
3391.86	1558.28
3392.45	1558.27
3393.04	1558.07
3393.63	1550.22
3394.22	1545.93
3394.81	1573.62
3395.4	1540.72
3395.99	1568.11
3396.58	1568.87
3397.17	1588.15
3397.76	1600.44
3398.35	1574.5
3398.94	1612.68
3399.53	1599.21
3400.12	1621.42
3400.71	1653
3401.3	1636.79
3401.89	1663.74
3402.48	1689.19
3403.07	1681.44
3403.66	1697.42
3404.25	1661.75
3404.83	1678.64
3405.42	1701.22
3406.01	1742.5
3406.6	1729.87
3407.19	1729.45
3407.78	1743.32
3408.37	1750.44
3408.96	1756.86
3409.55	1763.4
3410.13	1764.77
3410.72	1790.04
3411.31	1774.83
3411.9	1786.6
3412.49	1766.52
3413.07	1787.61
3413.66	1792.62
3414.25	1780.67
3414.84	1774.78
3415.43	1816.85
3416.01	1772.67
3416.6	1795.42
3417.19	1764.23
3417.78	1768.9
3418.36	1749.28
3418.95	1774.41
3419.54	1733.74
3420.12	1757.69
3420.71	1725.41
3421.3	1718.13
3421.89	1722.19
3422.47	1696.07
3423.06	1700.32
3423.64	1673.6
3424.23	1659.62
3424.82	1648.79
3425.41	1611.82
3425.99	1566.06
3426.58	1616.41
3427.16	1571.38
3427.75	1557.47
3428.34	1576.24
3428.92	1518.11
3429.51	1530.55
3430.09	1494.95
3430.68	1468.13
3431.26	1487.14
3431.85	1472.8
3432.44	1456.39
3433.02	1434.78
3433.61	1419.82
3434.19	1449.5
3434.78	1432.34
3435.36	1418.46
3435.95	1412.39
3436.53	1387.93
3437.12	1428.05
3437.7	1416.22
3438.29	1422.9
3438.87	1387.92
3439.46	1393.99
3440.04	1395.25
3440.62	1440.66
3441.21	1443.65
3441.79	1433.47
3442.38	1419.12
3442.96	1450.12
3443.55	1432.99
3444.13	1477.23
3444.71	1462.97
3445.3	1484.47
3445.88	1478.61
3446.46	1500.07
3447.05	1576.92
3447.63	1556.8
3448.21	1529.84
3448.8	1609.62
3449.38	1616.94
3449.96	1632.68
3450.55	1682.43
3451.13	1706.1
3451.71	1744.87
3452.3	1755.18
3452.88	1783.9
3453.46	1841.98
3454.04	1865.01
3454.63	1900.41
3455.21	1922.43
3455.79	1982.81
3456.37	1993.65
3456.96	2078.05
3457.54	2083.56
3458.12	2173.93
3458.7	2171.59
3459.28	2264.96
3459.87	2332.68
3460.45	2386.85
3461.03	2409.92
3461.61	2504.06
3462.19	2533.35
3462.78	2624.72
3463.36	2660.94
3463.94	2715.57
3464.52	2789.92
3465.1	2878.48
3465.68	2905.63
3466.26	2961.77
3466.84	3032.66
3467.42	3097.28
3468	3138.35
3468.58	3222.18
3469.17	3283.55
3469.75	3355.34
3470.33	3381.29
3470.91	3443.95
3471.49	3513.53
3472.07	3522.04
3472.65	3609.66
3473.23	3689.47
3473.81	3621.53
3474.39	3707.25
3474.97	3708.43
3475.55	3797.71
3476.13	3786.9
3476.71	3861.37
3477.29	3845.01
3477.87	3949.45
3478.45	3857.99
3479.03	3908.86
3479.6	3866.63
3480.18	3950.56
3480.76	3946.99
3481.34	3950.13
3481.92	3868.93
3482.5	3977.33
3483.08	3904.91
3483.66	3925.4
3484.24	3847.62
3484.82	3797.42
3485.39	3811.91
3485.97	3843.61
3486.55	3718.64
3487.13	3739.34
3487.71	3654.03
3488.28	3706.83
3488.86	3561.08
3489.44	3583.89
3490.02	3509.77
3490.6	3473.25
3491.17	3481.36
3491.75	3379.61
3492.33	3347.94
3492.91	3302.43
3493.49	3292.86
3494.06	3204.34
3494.64	3163.77
3495.22	3130.05
3495.79	3088.12
3496.37	3029.52
3496.95	3022.64
3497.52	2956.19
3498.1	2904.83
3498.68	2892.16
3499.25	2787.49
3499.83	2801.04
3500.41	2742.7
3500.98	2708.66
3501.56	2656.62
3502.14	2618.62
3502.71	2564.88
3503.29	2556.09
3503.86	2466.83
3504.44	2441.39
3505.02	2399.46
3505.59	2327.22
3506.17	2299.52
3506.75	2292.42
3507.32	2231.81
3507.9	2204.36
3508.47	2155.48
3509.05	2120.11
3509.62	2084.06
3510.2	2053.51
3510.77	1986.9
3511.35	1986.52
3511.92	1941.56
3512.5	1894.25
3513.07	1855.1
3513.65	1802.97
3514.22	1760.66
3514.8	1738.26
3515.2	1740.83
3515.78	1646.05
3516.36	1679.3
3516.95	1590.99
3517.53	1593.02
3518.11	1522.75
3518.7	1518.49
3519.28	1472.19
3519.86	1438.1
3520.44	1446.37
3521.02	1406.77
3521.61	1404.26
3522.19	1342.1
3522.77	1303.13
3523.35	1308.41
3523.94	1297.32
3524.52	1233.52
3525.1	1232.54
3525.68	1218.83
3526.26	1193.87
3526.84	1184.25
3527.42	1152.92
3528.01	1123
3528.59	1092.74
3529.17	1095.46
3529.75	1067.97
3530.33	1064.87
3530.91	1032.39
3531.49	1018.08
3532.07	1018.33
3532.66	976.352
3533.24	950.306
3533.82	946.489
3534.4	948.553
3534.98	934.513
3535.56	937.454
3536.14	901.711
3536.72	919.459
3537.3	901.244
3537.88	922.625
3538.46	896.987
3539.04	850.156
3539.62	894.621
3540.2	866.447
3540.78	864.842
3541.36	858.417
3541.94	854.286
3542.52	870.102
3543.1	845.803
3543.68	867.178
3544.25	853.327
3544.83	860.311
3545.41	822.339
3545.99	840.995
3546.57	855.823
3547.15	865.07
3547.73	846.19
3548.31	860.617
3548.89	845.628
3549.47	851.66
3550.04	858.67
3550.62	859.772
3551.2	869.316
3551.78	854.898
3552.36	865.321
3552.94	871.887
3553.51	857.626
3554.09	879.866
3554.67	904.339
3555.25	873.209
3555.83	877.859
3556.4	879.02
3556.98	886.653
3557.56	898.034
3558.14	894.092
3558.71	884.398
3559.29	891.958
3559.87	891.863
3560.44	890.304
3561.02	896.709
3561.6	892.175
3562.18	900.346
3562.75	881.353
3563.33	874.266
3563.91	852.552
3564.48	892.425
3565.06	868.294
3565.64	906.279
3566.21	865.957
3566.79	878.772
3567.37	866.036
3567.94	859.977
3568.52	860.095
3569.1	847.047
3569.67	822.167
3570.25	841.746
3570.82	829.38
3571.4	824.724
3571.97	817.313
3572.55	803.525
3573.13	802.076
3573.7	802.667
3574.28	775.21
3574.85	772.898
3575.43	760.584
3576	754.001
3576.58	750.247
3577.15	740.658
3577.73	702.353
3578.3	723.612
3578.88	696.061
3579.45	692.105
3580.03	682.952
3580.6	686.285
3581.18	680.882
3581.75	657.094
3582.33	644.442
3582.9	646.283
3583.47	603.475
3584.05	632.943
3584.62	611.857
3585.2	601.498
3585.77	608.96
3586.34	626.206
3586.92	620.272
3587.49	605.734
3588.07	589.345
3588.64	605.408
3589.21	587.733
3589.79	587.532
3590.36	570.778
3590.93	572.556
3591.51	587.019
3592.08	590.247
3592.65	585.243
3593.23	573.885
3593.8	598.95
3594.37	583.668
3594.94	569.452
3595.52	572.505
3596.09	579.345
3596.66	586.086
3597.23	566.706
3597.81	565.482
3598.38	590.252
3598.95	582.608
3599.52	576.818
3600.1	588.028
3600.67	598.469
3601.24	584.338
3601.81	572.393
3602.38	590.414
3602.95	590.709
3603.53	577.417
3604.1	601.572
3604.67	578.965
3605.24	591.06
3605.81	609.551
3606.38	592.093
3606.96	602.765
3607.53	594.262
3608.1	600.039
3608.67	608.524
3609.24	599.708
3609.81	610.977
3610.38	595.426
3610.95	600.903
3611.52	606.528
3612.09	591.443
3612.66	605.177
3613.23	600.309
3613.8	596.082
3614.37	590.009
3614.94	609.623
3615.52	606.678
3616.08	599.245
3616.66	596.134
3617.22	591.697
3617.79	610.409
3618.36	576.811
3618.93	607.866
3619.5	611.773
3620.07	590.355
3620.64	606.89
3621.21	607.843
3621.78	617.402
3622.35	630.401
3622.92	626.305
3623.49	615.026
3624.06	626.412
3624.63	639.026
3625.2	634.651
3625.76	630.992
3626.33	630.785
3626.9	623.985
3627.47	631.404
3628.04	624.795
3628.61	633.198
3629.18	637.123
3629.75	633.347
3630.31	641.001
3630.88	638.202
3631.45	652.539
3632.02	647.806
3632.59	669.65
3633.15	632.336
3633.72	651.887
3634.29	662.122
3634.86	648.378
3635.42	640.439
3635.99	656.843
3636.56	633.773
3637.13	661.13
3637.69	654.441
3638.26	662.098
3638.83	641.989
3639.39	641.619
3639.96	643.127
3640.53	645.743
3641.09	609.594
3641.66	613.666
3642.23	649.419
3642.8	650.782
3643.36	641.058
3643.93	623.828
3644.49	642.945
3645.06	634.448
3645.63	632.421
3646.19	636.878
3646.76	625.554
3647.33	622.438
3647.89	659.896
3648.46	637.06
3649.02	640.866
3649.59	629.726
3650.16	629.958
3650.72	639.394
3651.29	644.772
3651.85	633.009
3652.42	644.967
3652.98	645.924
3653.55	655.102
3654.11	662.842
3654.68	655.933
3655.24	626.775
3655.81	644.683
3656.37	648.4
3656.94	671.625
3657.5	674.113
3658.07	653.168
3658.63	654.033
3659.19	675.935
3659.76	676.699
3660.32	679.334
3660.89	681.548
3661.45	685.916
3662.02	696.481
3662.58	697.8
3663.14	685.706
3663.71	667.537
3664.27	708.899
3664.84	723.764
3665.4	708.632
3665.96	693.072
3666.53	688.957
3667.09	710.158
3667.65	731.951
3668.22	665.722
3668.78	714.816
3669.34	713.014
3669.91	719.086
3670.47	707.023
3671.03	721.436
3671.59	713.903
3672.16	705.269
3672.72	722.161
3673.28	704.313
3673.85	692.142
3674.41	694.58
3674.97	696.581
3675.53	667.392
3676.09	677.18
3676.66	696.281
3677.22	663.807
3677.78	675.871
3678.34	653.486
3678.91	662.557
3679.47	649.747
3680.03	631.086
3680.59	616.925
3681.15	621.76
3681.71	591.236
3682.28	581.646
3682.84	552.154
3683.4	579.899
3683.96	556.288
3684.52	540.206
3685.08	543.732
3685.64	510.468
3686.2	499.601
3686.76	490.214
3687.33	487.902
3687.89	482.518
3688.45	447.589
3689.01	449.792
3689.57	436.532
3690.13	425.141
3690.69	412.848
3691.25	416.895
3691.81	379.964
3692.37	380.314
3692.93	375.778
3693.49	360.542
3694.05	354.799
3694.61	334.725
3695.17	341.351
3695.73	337.506
3696.29	325.111
3696.85	311.804
3697.41	311.932
3697.97	317.787
3698.53	308.182
3699.09	293.958
3699.65	292.971
3700.2	297.378
3700.76	286.768
3701.32	279.073
3701.88	292.493
3702.44	277.31
3703	273.693
3703.56	249.945
3704.12	262.52
3704.68	279.561
3705.23	270.507
3705.79	258.728
3706.35	264.652
3706.91	262.086
3707.47	257.323
3708.03	267.084
3708.58	260.92
3709.14	262.022
3709.7	258.603
3710.26	256.355
3710.81	254.206
3711.37	261.297
3711.93	251.228
3712.49	246.166
3713.05	244.465
3713.6	249.271
3714.16	240.712
3714.72	250.247
3715.27	255.944
3715.83	254.141
3716.39	240.032
3716.95	246.842
3717.5	253.697
3718.06	241.32
3718.62	248.115
3719.17	245.26
3719.73	248.144
3720.29	236.655
3720.84	237.663
3721.4	236.903
3721.96	235.087
3722.51	244.843
3723.07	233.391
3723.62	245.956
3724.18	254.471
3724.74	223.857
3725.29	244.08
3725.85	238.344
3726.4	230.59
3726.96	239.132
3727.51	227.483
3728.07	242.861
3728.63	238.272
3729.18	244.363
3729.74	233.664
3730.29	227.878
3730.85	238.593
3731.4	229.131
3731.96	232.14
3732.51	208.205
3733.07	225.522
3733.62	230.195
3734.18	224.252
3734.73	227.971
3735.28	208.818
3735.84	216.629
3736.39	199.408
3736.95	217.603
3737.5	221.539
3738.06	217.194
3738.61	201.301
3739.16	221.377
3739.72	213.106
3740.27	225.743
3740.83	209.35
3741.38	205.353
3741.94	207.294
3742.49	209.313
3743.04	213.223
3743.6	215.091
3744.15	208.326
3744.7	216.114
3745.26	201.428
3745.81	204.885
3746.36	195.481
3746.91	199.108
3747.47	202.088
3748.02	186.342
3748.57	201.319
3749.13	185.663
3749.68	189.95
3750.23	200.07
3750.78	198.072
3751.34	196.245
3751.89	192.405
3752.44	190.35
3752.99	190.234
3753.55	194.166
3754.1	191.417
3754.65	197.31
3755.2	182.023
3755.75	190.595
3756.31	200.338
3756.86	178.367
3757.41	192.608
3757.96	182.862
3758.51	185.914
3759.06	187.663
3759.61	183.228
3760.17	179.663
3760.72	179.656
3761.27	179.125
3761.82	179.484
3762.37	181.079
3762.92	179.338
3763.47	193.705
3764.02	177.394
3764.57	180.236
3765.13	164.922
3765.68	170.615
3766.23	179.353
3766.78	170.721
3767.33	186.002
3767.88	171.519
3768.43	184.892
3768.98	174.469
3769.53	172.644
3770.08	180.339
3770.63	172.687
3771.18	178.398
3771.73	165.033
3772.28	171.886
3772.83	168.672
3773.38	170.027
3773.93	164.557
3774.48	176.812
3775.02	180.618
3775.57	175.09
3776.12	164.673
3776.67	170.093
3777.22	170.551
3777.77	176.73
3778.32	171.846
3778.87	163.207
3779.42	175.539
3779.97	157.44
3780.51	164.51
3781.06	164.192
3781.61	161.214
3782.16	159.535
3782.71	176.771
3783.26	170.093
3783.8	168.199
3784.35	172.573
3784.9	162.537
3785.45	167.276
3786	175.868
3786.55	164.462
3787.09	165.43
3787.64	178.821
3788.19	164.667
3788.74	160.949
3789.28	172.413
3789.83	164.774
3790.38	163.783
3790.93	166.605
3791.47	161.861
3792.02	167.291
3792.57	167.507
3793.11	161.459
3793.66	160.874
3794.21	160.36
3794.75	169.102
3795.3	167.539
3795.85	163.439
3796.4	162.247
3796.94	165.022
3797.12	149.622