File: Data/3-Raman/raw/bu04w-a-ff3-fi09-v_150 (500nm)_633nm_edge_100%_x100_vis_lwd_h50um_45sx2_01.txt
#Acq. time (s)=	45
#Accumulations=	2
#Range (cm-¹)=	100...4000
#Windows=	1
#Auto scanning=	Off
#Autofocus=	Off
#Macrospot=	Off
#AutoExposure=	Off
#Spike filter=	Multiple accum.
#Delay time (s)=	2
#Binning=	1
#Readout mode=	Signal
#DeNoise=	Off
#ICS correction=	On
#Dark correction=	Off
#Inst. Process=	Off
#Detector Gain=	Best Dynamic
#Detector ADC=	50 kHz HS
#Detector temperature (°C)=	-60.09
#Instrument=	LabRAM HR Evol
#Detector=	SIN-EM FIVIS
#Objective=	x100_VIS_LWD
#Grating=	150 (500nm)
#ND Filter=	100%
#Laser=	633nm_Edge
#Hole=	49.98
#Temperature=	0
#Range=	Visible
#StageXY=	75x50mm Scan+
#StageZ=	Z motor
#X (µm)=	0
#Y (µm)=	0
#Z (µm)=	-9.5
#Full time(mm:ss)=	1:35
#Project=	21_11_22
#Sample=	BU04w
#Site=
#Title=	BU04w-A-FF3-FI09-V_150 (500nm)_633nm_Edge_100%_x100_VIS_LWD_H50um_45sX2
#Remark=
#Date=	22.11.2021 12:39
#Acquired=	22.11.2021 12:39:01
100.177	544.719
106.695	507.953
113.209	485.554
119.717	494.531
126.219	507.3
132.716	547.752
139.208	609.057
145.694	527.813
152.175	506.887
158.651	774.396
165.121	873.587
171.586	479.826
178.045	344.568
184.5	282.981
190.947	282.56
197.39	268.773
203.829	268.665
210.262	275.244
216.688	309.474
223.11	388.433
229.527	686.86
235.939	983.738
242.344	604.707
248.745	465.882
255.141	475.058
261.53	452.073
267.916	395.975
274.294	395.942
280.669	520.13
287.038	485.784
293.402	382.163
299.76	354.403
306.114	423.075
312.461	570.047
318.805	1033.93
325.142	1829.92
331.475	1375.8
337.802	764.372
344.123	516.213
350.441	416.072
356.752	470.355
363.058	543.271
369.36	491.965
375.656	367.523
381.947	301.504
388.232	282.744
394.512	308.404
400.789	330.707
407.059	356.854
413.324	420.806
419.584	530.162
425.839	737.455
432.089	902.936
438.333	784.003
444.573	592.277
450.807	613.951
457.037	626.347
463.261	454.598
469.48	339.59
475.695	315.305
481.904	334.942
488.108	343.359
494.307	365.814
500.502	420.895
506.691	531.171
512.874	600.603
519.053	541.442
525.227	498.399
531.396	468.603
537.559	422.869
543.718	373.781
549.873	346.776
556.022	300.786
562.165	293.926
568.304	259.478
574.437	237.145
580.567	230.748
586.691	251.627
592.81	301.561
598.924	415.034
605.033	362.384
611.138	370.507
617.236	359.298
623.332	344.426
629.42	311.481
635.506	299.494
641.585	273.818
647.659	278.042
653.73	320.657
659.794	336.655
665.854	267.596
671.91	203.709
677.96	176.72
684.005	145.068
690.045	151.826
696.082	132.506
702.113	133.729
708.139	141.482
714.16	138.649
720.176	133.865
726.187	120.617
732.194	124.152
738.196	122.992
744.193	118.118
750.185	126.363
756.173	116.974
762.155	118.053
768.133	122.112
774.107	118.712
780.075	114.288
786.039	122.935
791.998	123.057
797.952	124.031
803.902	115.464
809.845	118.155
815.786	114.175
821.721	119.537
827.652	131.395
833.576	141.532
839.498	136.951
845.415	138.144
851.327	141.252
857.233	143.488
863.135	152.373
869.032	159.415
874.925	182.453
880.813	200.646
886.697	199.758
892.576	192.091
898.45	207.982
904.318	193.315
910.184	196.586
916.044	211.132
921.9	239.994
927.75	284.163
933.596	341.913
939.439	463.715
945.275	617.878
951.107	771.554
956.936	749.514
962.759	651.148
968.577	603.581
974.391	671.482
980.201	900.537
986.006	1162.79
991.806	1163.67
997.602	936.251
1003.39	854.921
1009.18	810.657
1014.96	936.436
1020.74	1172.32
1026.51	1148.03
1032.28	789.219
1038.04	519.241
1043.8	404.989
1049.56	362.583
1055.31	304.144
1061.05	285.087
1066.8	287.016
1072.53	303.442
1078.26	374.064
1083.99	446.412
1089.72	549.754
1095.44	841.804
1101.15	851.878
1106.86	517.321
1112.56	345.325
1118.27	300.819
1123.96	271.355
1129.65	284.701
1135.34	371.583
1141.03	473.619
1146.7	645.485
1152.38	1088.38
1158.05	785.119
1163.71	369.125
1169.37	258.549
1175.03	201.242
1180.68	176.422
1186.33	163.575
1191.98	138.205
1197.61	124.693
1203.25	125.036
1208.88	112.691
1214.51	96.3398
1220.13	97.7768
1225.74	93.2636
1231.36	96.6922
1236.97	94.0381
1242.57	95.2946
1248.17	103.511
1253.77	100.537
1259.36	97.445
1264.94	94.2819
1270.53	90.1145
1276.11	125.092
1281.68	129.824
1287.25	89.5697
1292.81	86.4684
1298.38	82.4454
1303.93	84.4787
1309.48	77.6139
1315.03	83.8801
1320.58	81.1393
1326.12	81.453
1331.65	80.7677
1337.18	72.8956
1342.71	74.1228
1348.23	75.2991
1353.75	75.4303
1359.26	71.405
1364.77	76.5714
1370.28	80.6612
1375.78	82.6857
1381.28	185.323
1386.77	96.9784
1392.26	77.4641
1397.74	74.4686
1403.23	82.7979
1408.7	69.5418
1414.17	72.7765
1419.64	68.8031
1425.11	68.9753
1430.56	73.3139
1436.02	75.5847
1441.47	69.4948
1446.92	66.5264
1452.36	66.6238
1457.8	64.5726
1463.23	76.1305
1468.66	65.612
1474.09	65.5983
1479.51	68.7668
1484.93	63.5519
1490.34	66.7729
1495.75	67.9344
1501.16	69.1225
1506.56	70.3382
1511.96	66.2881
1517.35	64.3677
1522.74	63.5163
1528.13	63.738
1533.51	67.2065
1538.88	67.4142
1544.25	56.7595
1549.62	70.8568
1554.99	69.72
1560.35	56.6792
1565.71	68.4879
1571.06	71.6469
1576.41	62.9724
1581.75	64.0491
1587.09	67.2976
1592.43	58.7219
1597.76	63.1072
1603.09	53.484
1608.41	61.1856
1613.73	59.2044
1619.05	60.5184
1624.36	60.7505
1629.67	59.8801
1634.97	67.7946
1640.27	60.1818
1645.57	61.3835
1650.86	61.4612
1656.15	61.5158
1661.43	62.6477
1666.71	58.2231
1671.99	67.0978
1677.26	55.9987
1682.53	62.6305
1687.79	60.358
1693.05	60.3255
1698.31	59.2458
1703.56	60.5914
1708.81	63.0931
1714.06	58.5344
1719.3	60.9362
1724.53	59.9089
1729.77	56.668
1735	59.0329
1740.22	62.526
1745.44	63.7742
1750.66	64.9972
1755.87	68.4639
1761.08	62.8334
1766.29	61.7254
1771.49	57.2286
1776.69	60.6775
1781.88	60.7628
1787.07	60.8675
1792.26	63.2839
1797.44	63.4327
1802.62	55.5846
1807.79	63.7773
1812.96	62.7627
1818.13	55.9759
1823.29	60.7236
1828.45	62.0218
1833.61	63.3333
1838.76	62.3186
1843.91	56.5983
1849.05	53.1845
1854.19	52.0832
1859.33	55.6859
1864.46	59.3185
1869.59	57.088
1874.71	59.5271
1879.83	59.6013
1884.95	51.395
1890.06	56.1554
1895.17	56.1579
1900.28	58.5523
1905.38	51.5468
1910.48	55.2297
1915.57	56.6049
1920.66	55.5037
1925.75	59.1949
1930.83	53.3192
1935.91	53.4147
1940.99	48.6848
1946.06	51.147
1951.13	53.5972
1956.19	48.8002
1961.26	59.6594
1966.31	58.4571
1971.36	51.2024
1976.41	55.9897
1981.46	52.3476
1986.5	52.321
1991.54	55.9087
1996.58	48.6847
2001.61	55.9014
2006.63	48.7096
2011.66	49.9498
2016.68	51.1948
2021.69	47.6081
2026.71	51.2835
2031.72	44.1134
2036.72	52.6746
2041.72	50.3523
2046.72	52.8917
2051.71	56.6639
2056.71	55.5363
2061.69	55.6603
2066.68	55.7873
2071.66	54.6763
2076.63	57.2521
2081.6	52.4259
2086.57	57.4472
2091.54	55.0567
2096.5	53.9349
2101.46	60.2756
2106.41	54.2019
2111.36	63.103
2116.31	52.0182
2121.25	59.7229
2126.19	56.1161
2131.13	55.0053
2136.06	56.4076
2140.99	52.7221
2145.92	59.1955
2150.84	58.0134
2155.76	52.9778
2160.67	54.3027
2165.58	56.8858
2170.49	58.1828
2175.39	50.5496
2180.29	51.8481
2185.19	51.8418
2190.08	56.971
2194.98	59.5636
2199.86	46.8051
2204.74	44.3083
2209.62	55.9739
2214.5	52.2279
2219.37	51.0657
2224.24	51.1961
2229.11	47.4282
2233.97	46.2461
2238.83	54.199
2243.68	50.4079
2248.53	50.5377
2253.38	54.6105
2258.22	42.8769
2263.06	49.5948
2267.9	48.3679
2272.73	55.0795
2277.56	52.4888
2282.39	47.2107
2287.21	53.8755
2292.03	51.2292
2296.85	51.2452
2301.66	43.2942
2306.47	46.022
2311.28	48.7835
2316.08	48.8947
2320.88	50.3628
2325.68	59.919
2330.47	42.5313
2335.26	44.0156
2340.04	50.9473
2344.82	45.6688
2349.6	48.5723
2354.38	45.9889
2359.15	46.114
2363.92	48.9612
2368.68	46.3039
2373.44	43.6285
2378.2	46.4913
2382.95	45.1671
2387.71	49.381
2392.45	46.6218
2397.2	45.2362
2401.94	42.453
2406.68	43.8349
2411.41	46.6653
2416.14	46.8147
2420.87	40.0239
2425.59	48.5191
2430.31	47.2298
2435.03	43.1215
2439.75	47.5079
2444.46	43.3819
2449.16	42.0859
2453.87	43.6411
2458.57	42.3336
2463.27	41.0174
2467.96	44.0168
2472.65	51.3634
2477.34	42.7945
2482.02	45.812
2486.7	48.8279
2491.38	47.4675
2496.05	51.9585
2500.72	46.1938
2505.39	47.7453
2510.06	44.8769
2514.72	44.9353
2519.37	43.5215
2524.03	43.5925
2528.68	42.178
2533.33	40.7652
2537.97	39.3584
2542.61	49.8567
2547.25	44.0003
2551.88	48.5814
2556.51	45.6829
2561.14	39.7701
2565.77	45.881
2570.39	50.5237
2575.01	46.1181
2579.62	43.1909
2584.23	40.2256
2588.84	46.3523
2593.45	46.3885
2598.05	41.8911
2602.65	46.5245
2607.24	48.1063
2611.84	51.2063
2616.42	48.1872
2621.01	49.7617
2625.59	46.7476
2630.17	46.8151
2634.75	46.9204
2639.32	50.1505
2643.89	47.2122
2648.46	47.3643
2653.02	52.1857
2657.58	47.6038
2662.14	52.3701
2666.69	50.8683
2671.24	58.7986
2675.79	51.1042
2680.33	48.196
2684.88	48.4149
2689.41	51.8218
2693.95	45.615
2698.48	50.4962
2703.01	52.2116
2707.53	50.7012
2712.06	44.3389
2716.57	47.6693
2721.09	52.6165
2725.6	55.9408
2730.11	49.5139
2734.62	41.4308
2739.12	52.8368
2743.62	43.1336
2748.12	56.2407
2752.61	51.4928
2757.1	49.9705
2761.59	51.6845
2766.08	55.07
2770.56	48.585
2775.04	47.0428
2779.51	53.792
2783.98	47.3322
2788.45	52.4914
2792.92	44.2999
2797.38	54.4834
2801.84	52.9398
2806.3	56.4209
2810.75	49.7787
2815.2	44.788
2819.65	48.241
2824.09	41.5389
2828.53	50.099
2832.97	50.174
2837.41	50.2437
2841.84	53.7277
2846.27	48.6925
2850.69	52.2083
2855.12	45.4704
2859.54	50.7439
2863.95	54.3385
2868.37	52.78
2872.78	51.2064
2877.18	49.6264
2881.59	48.047
2885.99	44.7141
2890.39	50.1464
2894.78	48.5471
2899.18	55.8189
2903.57	56.0071
2907.95	54.393
2912.34	43.8052
2916.72	47.485
2921.09	45.806
2925.47	47.7281
2929.84	49.674
2934.21	49.8124
2938.57	51.735
2942.94	48.1942
2947.29	51.909
2951.65	57.4569
2956	53.8855
2960.36	48.4737
2964.7	50.381
2969.05	54.1412
2973.39	56.0809
2977.73	54.3443
2982.06	58.1442
2986.4	56.4356
2990.73	52.8766
2995.05	64.1892
2999.38	56.9214
3003.7	62.7267
3008.01	49.7881
3012.33	66.9028
3016.64	59.5704
3020.95	63.5844
3025.26	75.2138
3029.56	63.9576
3033.86	71.7584
3038.16	75.717
3042.45	68.2002
3046.74	76.0202
3051.03	85.7888
3055.32	80.1468
3059.6	82.2265
3063.88	72.68
3068.16	80.574
3072.43	92.3846
3076.7	100.35
3080.97	96.6326
3085.24	100.744
3089.5	100.997
3093.76	107.198
3098.02	101.631
3102.27	115.828
3106.52	104.33
3110.77	118.699
3115.01	111.153
3119.26	133.71
3123.5	134.279
3127.73	140.968
3131.97	135.54
3136.2	138.246
3140.43	149.169
3144.65	164.262
3148.87	158.687
3153.09	161.288
3157.31	176.381
3161.52	189.465
3165.73	211.003
3169.94	196.804
3174.15	193.135
3178.35	212.53
3182.55	214.964
3186.75	225.84
3190.94	232.458
3195.13	213.718
3199.32	227.067
3203.51	217.191
3207.69	226.627
3211.87	208.13
3216.05	198.202
3220.22	207.71
3224.39	193.255
3228.56	187.457
3232.73	172.78
3236.89	168.962
3241.05	162.976
3245.21	145.874
3249.36	144.186
3253.52	144.594
3257.66	124.699
3261.81	118.351
3265.95	127.865
3270.1	112.53
3274.23	108.432
3278.37	104.069
3282.5	111.156
3286.63	97.6017
3290.76	100.091
3294.88	88.7428
3299	98.1372
3303.12	93.714
3307.24	86.9448
3311.35	96.3943
3315.46	87.2602
3319.57	80.4336
3323.68	89.9693
3327.78	92.5449
3331.88	92.8307
3335.98	90.8057
3340.07	79.2557
3344.16	86.5418
3348.25	77.1905
3352.34	101.129
3356.42	79.8725
3360.5	72.882
3364.58	68.2555
3368.66	75.5987
3372.73	78.157
3376.8	71.0567
3380.87	78.3929
3384.93	76.0795
3388.99	66.4976
3393.05	76.2495
3397.11	69.0846
3401.16	66.7542
3405.21	69.2456
3409.26	62.0173
3413.31	64.4969
3417.35	64.549
3421.39	69.4716
3425.43	62.202
3429.46	59.8257
3433.5	57.4586
3437.53	64.8973
3441.55	60.1073
3445.58	57.7783
3449.6	57.9254
3453.62	63.0221
3457.64	55.7866
3461.65	58.4693
3465.66	53.6825
3469.67	46.3514
3473.68	56.527
3477.68	49.1406
3481.68	56.8713
3485.68	54.5004
3489.67	49.567
3493.67	59.8937
3497.66	62.5857
3501.64	49.9139
3505.63	57.689
3509.61	60.3184
3513.59	55.2212
3517.57	47.5443
3521.54	50.1426
3525.52	55.3233
3529.49	52.7808
3533.45	50.2763
3537.42	55.549
3541.38	53.0863
3545.34	53.1808
3549.29	53.26
3553.25	55.8856
3557.2	55.9355
3561.15	48.1901
3565.09	45.6565
3569.04	56.2163
3572.98	58.9487
3576.92	64.3406
3580.85	56.619
3584.79	62.0713
3588.72	54.3071
3592.64	62.4355
3596.57	54.6234
3600.49	46.7524
3604.41	49.5487
3608.33	46.9751
3612.25	41.6903
3616.16	39.0794
3620.07	33.7499
3623.98	44.5909
3627.88	55.4367
3631.79	39.2265
3635.69	44.6617
3639.58	50.1324
3643.48	39.3661
3647.37	44.8963
3651.26	39.479
3655.15	47.6959
3659.03	50.4667
3662.92	50.5044
3666.8	34.1572
3670.67	50.6038
3674.55	47.9266
3678.42	34.2932
3682.29	45.3659
3686.16	37.2169
3690.02	37.3213
3693.89	45.7398
3697.75	40.2993
3701.61	48.7691
3705.46	48.8951
3709.31	43.4284
3713.16	35.1183
3717.01	43.6476
3720.86	43.738
3724.7	46.6466
3728.54	43.8948
3732.38	46.8139
3736.21	44.0608
3740.04	44.1394
3743.87	38.5061
3747.7	41.4189
3751.53	50.0472
3755.35	38.6419
3759.17	38.6656
3762.99	35.8185
3766.81	41.5676
3770.62	44.4677
3774.43	41.6356
3778.24	47.4236
3782.04	53.2416
3785.85	47.561
3789.65	44.7406
3793.45	47.6986
3797.24	53.5835
3801.04	42.084
3804.83	39.2675
3808.62	45.1899
3812.4	42.3641
3816.19	45.3763
3819.97	42.5317
3823.75	51.4219
3827.52	45.6157
3831.3	48.6473
3835.07	42.8305
3838.84	42.9011
3842.61	45.9516
3846.37	46.0062
3850.13	46.0354
3853.89	46.0592
3857.65	37.1569
3861.41	46.0797
3865.16	40.1744
3868.91	40.2728
3872.66	43.3032
3876.4	34.3653
3880.14	43.3572
3883.89	40.3971
3887.62	46.4254
3891.36	46.4767
3895.09	40.5517
3898.82	43.6227
3902.55	49.7177
3906.28	40.7366
3910	40.7927
3913.73	40.8625
3917.45	50.0405
3921.16	37.9989
3924.88	50.278
3928.59	41.2249
3932.3	44.3629
3936.01	41.3641
3939.71	44.4967
3943.42	38.4375
3947.12	32.349
3950.81	44.7463
3954.51	44.8077
3958.2	41.7671
3961.9	38.7037
3965.58	44.9264
3969.27	44.9389
3972.96	41.853
3976.64	44.9683
3980.32	38.7695
3984	38.7651
3987.67	48.0654
3991.34	41.8702
3995.01	44.9961
3998.68	41.9318