File: Data/3-Raman/raw/bu04w-a-ff3-fi01-v_150 (500nm)_633nm_edge_100%_x100_vis_lwd_h100um_45sx2_01.txt
#Acq. time (s)=	45
#Accumulations=	2
#Range (cm-¹)=	100...4000
#Windows=	1
#Auto scanning=	Off
#Autofocus=	Off
#Macrospot=	Off
#AutoExposure=	Off
#Spike filter=	Multiple accum.
#Delay time (s)=	2
#Binning=	1
#Readout mode=	Signal
#DeNoise=	Off
#ICS correction=	On
#Dark correction=	Off
#Inst. Process=	Off
#Detector Gain=	Best Dynamic
#Detector ADC=	50 kHz HS
#Detector temperature (°C)=	-60.09
#Instrument=	LabRAM HR Evol
#Detector=	SIN-EM FIVIS
#Objective=	x100_VIS_LWD
#Grating=	150 (500nm)
#ND Filter=	100%
#Laser=	633nm_Edge
#Hole=	100.021
#Temperature=	0
#Range=	Visible
#StageXY=	75x50mm Scan+
#StageZ=	Z motor
#X (µm)=	0
#Y (µm)=	0
#Z (µm)=	14.3
#Full time(mm:ss)=	1:35
#Project=	21_11_22
#Sample=	BU04w
#Site=
#Title=	BU04w-A-FF3-V_150 (500nm)_633nm_Edge_100%_x100_VIS_LWD_H100um_45sX2
#Remark=
#Date=	22.11.2021 10:40
#Acquired=	22.11.2021 10:40:14
100.177	1412.08
106.695	1290.15
113.209	1252.32
119.717	1150.08
126.219	1105.92
132.716	1095.02
139.208	1040.61
145.694	1007.29
152.175	955.858
158.651	973.623
165.121	982.845
171.586	944.793
178.045	790.253
184.5	748.393
190.947	706.161
197.39	629.684
203.829	650.426
210.262	611.071
216.688	578.415
223.11	598.14
229.527	650.684
235.939	746.005
242.344	735.814
248.745	617.852
255.141	578.517
261.53	556.434
267.916	536.344
274.294	528.713
280.669	518.233
287.038	554.031
293.402	515.707
299.76	489.729
306.114	473.183
312.461	500.149
318.805	608.279
325.142	805.277
331.475	948.487
337.802	767.202
344.123	598.241
350.441	514.082
356.752	507.079
363.058	515.99
369.36	529.555
375.656	509.275
381.947	469.371
388.232	446.858
394.512	451.105
400.789	461.484
407.059	482.247
413.324	479.369
419.584	515.974
425.839	570.002
432.089	654.664
438.333	658.751
444.573	628.913
450.807	563.373
457.037	587.112
463.261	530.131
469.48	483.065
475.695	457.822
481.904	456.061
488.108	452.377
494.307	463.675
500.502	463.777
506.691	494.796
512.874	509.136
519.053	536.771
525.227	503.079
531.396	474.232
537.559	484.019
543.718	433.172
549.873	454.348
556.022	436.778
562.165	409.987
568.304	405.463
574.437	393.05
580.567	390.82
586.691	369.27
592.81	397.576
598.924	424.35
605.033	446.334
611.138	433.115
617.236	397.71
623.332	413.03
629.42	395.36
635.506	391.936
641.585	390.697
647.659	383.425
653.73	397.652
659.794	402.207
665.854	409.567
671.91	392.967
677.96	349.243
684.005	330.719
690.045	330.28
696.082	332.903
702.113	328.926
708.139	329.499
714.16	332.288
720.176	315.17
726.187	304.593
732.194	307.803
738.196	325.016
744.193	305.799
750.185	297.956
756.173	301.523
762.155	307.498
768.133	318.614
774.107	303.585
780.075	303.357
786.039	285.907
791.998	303.164
797.952	294.75
803.902	296.435
809.845	309.275
815.786	288.961
821.721	302.358
827.652	304.405
833.576	307.82
839.498	311.763
845.415	291.74
851.327	306.438
857.233	297.796
863.135	292.009
869.032	320.249
874.925	330.311
880.813	333.461
886.697	298.45
892.576	295.488
898.45	319.79
904.318	293.517
910.184	301.243
916.044	304.236
921.9	310.443
927.75	328.314
933.596	338.15
939.439	370.312
945.275	428.49
951.107	474.912
956.936	503.333
962.759	486.567
968.577	432.91
974.391	467.013
980.201	487.931
986.006	579.238
991.806	647.119
997.602	616.369
1003.39	546.902
1009.18	519.945
1014.96	519.5
1020.74	584.966
1026.51	652.255
1032.28	598.271
1038.04	489.405
1043.8	403.058
1049.56	361.614
1055.31	335.189
1061.05	326.855
1066.8	308.384
1072.53	326.746
1078.26	331.369
1083.99	358.196
1089.72	381.195
1095.44	452.609
1101.15	527.768
1106.86	505.707
1112.56	394.726
1118.27	324.146
1123.96	308.381
1129.65	304.235
1135.34	319.689
1141.03	355.828
1146.7	405.579
1152.38	484.872
1158.05	539.985
1163.71	443.834
1169.37	323.31
1175.03	289.377
1180.68	277.096
1186.33	263.185
1191.98	265.177
1197.61	260.633
1203.25	250.562
1208.88	260.322
1214.51	268.269
1220.13	251.639
1225.74	234.905
1231.36	241.981
1236.97	250.936
1242.57	237.48
1248.17	248.932
1253.77	230.881
1259.36	259.012
1264.94	247.553
1270.53	264.302
1276.11	281.833
1281.68	317.292
1287.25	248.694
1292.81	248.409
1298.38	251.333
1303.93	247.438
1309.48	227.834
1315.03	238.581
1320.58	228.299
1326.12	233.229
1331.65	234.176
1337.18	232.96
1342.71	222.368
1348.23	228.971
1353.75	239.632
1359.26	230.653
1364.77	237.937
1370.28	249.176
1375.78	285.034
1381.28	352.678
1386.77	331.984
1392.26	240.6
1397.74	232.65
1403.23	227.823
1408.7	236.442
1414.17	211.104
1419.64	209.513
1425.11	219.373
1430.56	224.101
1436.02	220.499
1441.47	228.34
1446.92	210.056
1452.36	220.855
1457.8	223.117
1463.23	215.791
1468.66	199.985
1474.09	214.638
1479.51	218.899
1484.93	216.917
1490.34	213.989
1495.75	221.708
1501.16	216.865
1506.56	206.784
1511.96	213.713
1517.35	202.679
1522.74	204.427
1528.13	212.639
1533.51	206.996
1538.88	214.107
1544.25	211.362
1549.62	207.161
1554.99	210.241
1560.35	213.222
1565.71	208.699
1571.06	212.786
1576.41	217.981
1581.75	219.059
1587.09	229.889
1592.43	210.645
1597.76	205.503
1603.09	210.154
1608.41	218.21
1613.73	224.325
1619.05	221.901
1624.36	210.711
1629.67	225.786
1634.97	227.635
1640.27	218.09
1645.57	228.391
1650.86	230.895
1656.15	218.908
1661.43	215.663
1666.71	231.229
1671.99	222.365
1677.26	215.678
1682.53	210.062
1687.79	208.761
1693.05	204.221
1698.31	204.315
1703.56	197.339
1708.81	201.563
1714.06	207.937
1719.3	202.934
1724.53	196.524
1729.77	204.79
1735	190.592
1740.22	192.084
1745.44	187.936
1750.66	197.252
1755.87	195.207
1761.08	186.236
1766.29	193.104
1771.49	181.885
1776.69	187.703
1781.88	193.646
1787.07	184.878
1792.26	181.87
1797.44	193.727
1802.62	174.776
1807.79	185.586
1812.96	190.591
1818.13	182.932
1823.29	193.737
1828.45	189.543
1833.61	187.676
1838.76	170.648
1843.91	188.466
1849.05	181.762
1854.19	176.147
1859.33	185.815
1864.46	174.432
1869.59	192.451
1874.71	177.403
1879.83	164.641
1884.95	196.719
1890.06	175.559
1895.17	181.479
1900.28	179.206
1905.38	168.86
1910.48	182.317
1915.57	174.581
1920.66	182.028
1925.75	181.172
1930.83	174.336
1935.91	172.247
1940.99	173.703
1946.06	169.086
1951.13	178.858
1956.19	174.114
1961.26	171.747
1966.31	182.603
1971.36	175.293
1976.41	180.01
1981.46	160.653
1986.5	167.788
1991.54	165.322
1996.58	165.288
2001.61	171.311
2006.63	172.589
2011.66	172.718
2016.68	174.062
2021.69	180.188
2026.71	171.951
2031.72	171.015
2036.72	174.976
2041.72	169.257
2046.72	181.777
2051.71	168.773
2056.71	171.491
2061.69	181.66
2066.68	173.492
2071.66	187.374
2076.63	179.144
2081.6	162.212
2086.57	174.812
2091.54	183.729
2096.5	170.484
2101.46	180.827
2106.41	153.883
2111.36	178.063
2116.31	174.856
2121.25	165.338
2126.19	159.521
2131.13	175.132
2136.06	164.153
2140.99	167.059
2145.92	164.856
2150.84	160.015
2155.76	172.976
2160.67	171.852
2165.58	161.709
2170.49	164.318
2175.39	179.803
2180.29	165.786
2185.19	167.046
2190.08	154.27
2194.98	164.6
2199.86	166.062
2204.74	166.317
2209.62	152.481
2214.5	167
2219.37	159.661
2224.24	157.477
2229.11	164.375
2233.97	163.49
2238.83	174.351
2243.68	170.863
2248.53	167.365
2253.38	158.568
2258.22	148.42
2263.06	158.042
2267.9	163.656
2272.73	162.584
2277.56	158.795
2282.39	156.261
2287.21	160.296
2292.03	161.671
2296.85	151.074
2301.66	161.854
2306.47	162.077
2311.28	166.399
2316.08	137.307
2320.88	165.862
2325.68	171.678
2330.47	168.1
2335.26	156.425
2340.04	159.635
2344.82	157.455
2349.6	158.031
2354.38	166.795
2359.15	158.99
2363.92	151.021
2368.68	152.734
2373.44	147.506
2378.2	156.127
2382.95	164.686
2387.71	155.098
2392.45	153.782
2397.2	149.627
2401.94	160.765
2406.68	144.029
2411.41	159.498
2416.14	146.034
2420.87	149.563
2425.59	149.776
2430.31	145.919
2435.03	150.572
2439.75	139.687
2444.46	157.17
2449.16	144.804
2453.87	159.54
2458.57	151.396
2463.27	140.323
2467.96	150.812
2472.65	142.515
2477.34	157.397
2482.02	144.708
2486.7	137.738
2491.38	148.245
2496.05	150.021
2500.72	154.713
2505.39	144.705
2510.06	158.173
2514.72	156.905
2519.37	146.793
2524.03	145.555
2528.68	150.213
2533.33	146.014
2537.97	141.839
2542.61	152.547
2547.25	148.408
2551.88	160.692
2556.51	144.538
2561.14	152.327
2565.77	149.677
2570.39	141.014
2575.01	141.378
2579.62	143.212
2584.23	158.626
2588.84	152.735
2593.45	137.645
2598.05	147
2602.65	145.675
2607.24	155.009
2611.84	152.09
2616.42	141.502
2621.01	153.878
2625.59	146.374
2630.17	135.841
2634.75	157.683
2639.32	135.021
2643.89	147.828
2648.46	138.987
2653.02	150.326
2657.58	139.69
2662.14	149.294
2666.69	138.518
2671.24	160.716
2675.79	147.023
2680.33	143.008
2684.88	134.133
2689.41	137.926
2693.95	143.247
2698.48	146.679
2703.01	127.718
2707.53	147.275
2712.06	147.528
2716.57	151.087
2721.09	138.422
2725.6	137.014
2730.11	148.542
2734.62	151.913
2739.12	150.382
2743.62	152.188
2748.12	141.009
2752.61	134.862
2757.1	128.613
2761.59	155.053
2766.08	137.264
2770.56	135.873
2775.04	151.032
2779.51	143.17
2783.98	146.979
2788.45	147.476
2792.92	146.273
2797.38	145.01
2801.84	147.055
2806.3	144
2810.75	139.212
2815.2	156.336
2819.65	139.645
2824.09	136.485
2828.53	141.806
2832.97	148.821
2837.41	137.106
2841.84	154.361
2846.27	154.62
2850.69	142.931
2855.12	143.275
2859.54	152.232
2863.95	137.14
2868.37	160.07
2872.78	146.676
2877.18	136.69
2881.59	159.865
2885.99	144.663
2890.39	162.756
2894.78	157.999
2899.18	151.508
2903.57	164.465
2907.95	154.262
2912.34	151.083
2916.72	158.582
2921.09	153.585
2925.47	144.985
2929.84	145.409
2934.21	147.626
2938.57	153.39
2942.94	159.132
2947.29	161.191
2951.65	150.482
2956	158.003
2960.36	152.738
2964.7	151.143
2969.05	166.094
2973.39	162.727
2977.73	168.559
2982.06	154.128
2986.4	156.354
2990.73	164.196
2995.05	166.52
2999.38	155.834
3003.7	156.349
3008.01	162.516
3012.33	166.786
3016.64	156.018
3020.95	179.365
3025.26	172.325
3029.56	182.327
3033.86	167.436
3038.16	165.811
3042.45	196.916
3046.74	193.418
3051.03	172.542
3055.32	186.366
3059.6	178.964
3063.88	208.349
3068.16	189.3
3072.43	197.411
3076.7	203.622
3080.97	205.954
3085.24	204.423
3089.5	216.702
3093.76	207.512
3098.02	216.089
3102.27	228.686
3106.52	219.59
3110.77	242.385
3115.01	265.366
3119.26	252.34
3123.5	243.318
3127.73	256.582
3131.97	255.793
3136.2	277.517
3140.43	268.505
3144.65	282.035
3148.87	297.667
3153.09	294.481
3157.31	303.709
3161.52	289.954
3165.73	315.98
3169.94	329.41
3174.15	319.78
3178.35	366.905
3182.55	346.272
3186.75	355.194
3190.94	351.34
3195.13	368.956
3199.32	374.181
3203.51	394.795
3207.69	394.18
3211.87	376.359
3216.05	386.656
3220.22	386.058
3224.39	372.317
3228.56	397.934
3232.73	386.28
3236.89	389.828
3241.05	380.276
3245.21	399.762
3249.36	349.848
3253.52	371.013
3257.66	356.123
3261.81	361.816
3265.95	370.016
3270.1	380.785
3274.23	382.364
3278.37	385.4
3282.5	351.802
3286.63	377.776
3290.76	373.902
3294.88	386.089
3299	365.994
3303.12	362.13
3307.24	367.487
3311.35	365.834
3315.46	364.166
3319.57	395.174
3323.68	384.414
3327.78	380.723
3331.88	377.198
3335.98	385.63
3340.07	391.547
3344.16	394.773
3348.25	378.827
3352.34	389.048
3356.42	411.284
3360.5	419.37
3364.58	408.335
3368.66	401.993
3372.73	407.619
3376.8	410.684
3380.87	396.789
3384.93	411.795
3388.99	434.048
3393.05	410.295
3397.11	427.84
3401.16	421.158
3405.21	433.696
3409.26	431.689
3413.31	417.405
3417.35	444.536
3421.39	437.549
3425.43	435.414
3429.46	426.105
3433.5	441.331
3437.53	415.098
3441.55	420.751
3445.58	438.869
3449.6	432.592
3453.62	441.155
3457.64	407.862
3461.65	399.333
3465.66	455.677
3469.67	424.679
3473.68	415.787
3477.68	389.345
3481.68	405.682
3485.68	404.317
3489.67	382.555
3493.67	403.964
3497.66	371.683
3501.64	374.994
3505.63	365.363
3509.61	376.027
3513.59	358.296
3517.57	340.52
3521.54	345.855
3525.52	328.08
3529.49	328.271
3533.45	308.104
3537.42	316.5
3541.38	314.633
3545.34	312.599
3549.29	305.271
3553.25	287.226
3557.2	277.076
3561.15	274.814
3565.09	277.852
3569.04	254.935
3572.98	276.404
3576.92	253.423
3580.85	277.828
3584.79	244.323
3588.72	247.693
3592.64	251.07
3596.57	222.49
3600.49	228.419
3604.41	212.926
3608.33	224.138
3612.25	213.831
3616.16	206.178
3620.07	211.949
3623.98	193.227
3627.88	198.761
3631.79	177.196
3635.69	174.587
3639.58	163.946
3643.48	164.252
3647.37	175.504
3651.26	167.446
3655.15	151.264
3659.03	167.768
3662.92	165.163
3666.8	157.123
3670.67	151.811
3674.55	157.473
3678.42	130.314
3682.29	155.344
3686.16	122.678
3690.02	136.845
3693.89	137.22
3697.75	126.456
3701.61	118.439
3705.46	135.509
3709.31	130.285
3713.16	116.593
3717.01	130.943
3720.86	122.749
3724.7	117.323
3728.54	123.189
3732.38	131.93
3736.21	117.969
3740.04	121.027
3743.87	124.075
3747.7	121.4
3751.53	115.824
3755.35	115.926
3759.17	110.269
3762.99	116.052
3766.81	124.703
3770.62	124.796
3774.43	119.164
3778.24	113.529
3782.04	116.556
3785.85	128.271
3789.65	125.562
3793.45	122.86
3797.24	111.512
3801.04	114.643
3804.83	123.62
3808.62	120.992
3812.4	127.092
3816.19	100.999
3819.97	133.462
3823.75	113.128
3827.52	107.418
3831.3	116.459
3835.07	122.584
3838.84	105.034
3842.61	114.138
3846.37	123.178
3850.13	117.316
3853.89	105.49
3857.65	123.361
3861.41	120.402
3865.16	105.644
3868.91	114.852
3872.66	114.977
3876.4	118.037
3880.14	112.131
3883.89	112.214
3887.62	103.334
3891.36	115.442
3895.09	109.64
3898.82	115.826
3902.55	94.9156
3906.28	104.105
3910	98.2046
3913.73	107.453
3917.45	107.663
3921.16	117.037
3924.88	102.08
3928.59	105.353
3932.3	96.3746
3936.01	111.836
3939.71	112.009
3943.42	115.312
3947.12	112.451
3950.81	109.551
3954.51	106.611
3958.2	97.4565
3961.9	85.1482
3965.58	109.992
3969.27	106.924
3972.96	103.857
3976.64	113.196
3980.32	100.801
3984	100.789
3987.67	110.085
3991.34	113.205
3995.01	103.956
3998.68	104.053