File: Data/3-Raman/raw/bu04w-a-ff3-fi03-l_150 (500nm)_633nm_edge_100%_x100_vis_lwd_h50um_45sx2_01.txt
#Acq. time (s)=	45
#Accumulations=	2
#Range (cm-¹)=	100...4000
#Windows=	1
#Auto scanning=	Off
#Autofocus=	Off
#Macrospot=	Off
#AutoExposure=	Off
#Spike filter=	Multiple accum.
#Delay time (s)=	2
#Binning=	1
#Readout mode=	Signal
#DeNoise=	Off
#ICS correction=	On
#Dark correction=	Off
#Inst. Process=	Off
#Detector Gain=	Best Dynamic
#Detector ADC=	50 kHz HS
#Detector temperature (°C)=	-60.28
#Instrument=	LabRAM HR Evol
#Detector=	SIN-EM FIVIS
#Objective=	x100_VIS_LWD
#Grating=	150 (500nm)
#ND Filter=	100%
#Laser=	633nm_Edge
#Hole=	49.98
#Temperature=	0
#Range=	Visible
#StageXY=	75x50mm Scan+
#StageZ=	Z motor
#X (µm)=	0
#Y (µm)=	0
#Z (µm)=	-19.3
#Full time(mm:ss)=	1:38
#Project=	21_11_22
#Sample=	BU04w
#Site=
#Title=	BU04w-A-FF3-FI03-L_150 (500nm)_633nm_Edge_100%_x100_VIS_LWD_H50um_45sX2
#Remark=
#Date=	22.11.2021 12:35
#Acquired=	22.11.2021 12:35:00
100.177	939.319
106.695	843.727
113.209	794.933
119.717	758.281
126.219	711.941
132.716	714.23
139.208	696.133
145.694	653.186
152.175	608.36
158.651	688.193
165.121	678.072
171.586	546.935
178.045	485.462
184.5	447.695
190.947	412.605
197.39	384.303
203.829	367.923
210.262	339.166
216.688	337.131
223.11	356.977
229.527	458.383
235.939	497.812
242.344	365.295
248.745	312.962
255.141	295.665
261.53	285.095
267.916	265.09
274.294	246.101
280.669	265.992
287.038	254.503
293.402	244.83
299.76	236.111
306.114	243.446
312.461	298.956
318.805	445.945
325.142	646.769
331.475	496.647
337.802	338.097
344.123	270.128
350.441	249.266
356.752	244.358
363.058	272.341
369.36	265.482
375.656	233.281
381.947	202.097
388.232	203.97
394.512	211.705
400.789	218.746
407.059	234.288
413.324	232.836
419.584	273.83
425.839	333.487
432.089	371.464
438.333	332.907
444.573	285.101
450.807	302.058
457.037	283.514
463.261	229.863
469.48	213.816
475.695	213.774
481.904	205.437
488.108	221.297
494.307	233.468
500.502	239.113
506.691	275.612
512.874	290.735
519.053	252.735
525.227	241.01
531.396	247.201
537.559	225.311
543.718	213.522
549.873	209.953
556.022	198.793
562.165	184.471
568.304	182.246
574.437	174.219
580.567	170.838
586.691	180.667
592.81	166.395
598.924	178.404
605.033	181.425
611.138	192.963
617.236	191.594
623.332	186.545
629.42	175.768
635.506	170.263
641.585	166.364
647.659	155.722
653.73	174.178
659.794	169.03
665.854	156.448
671.91	152.432
677.96	143.148
684.005	137.605
690.045	137.811
696.082	129.696
702.113	137.482
708.139	126.441
714.16	138.649
720.176	124.471
726.187	126.249
732.194	123.215
738.196	122.992
744.193	129.322
750.185	113.307
756.173	122.567
762.155	128.318
768.133	121.176
774.107	113.082
780.075	113.347
786.039	117.283
791.998	114.57
797.952	114.599
803.902	115.464
809.845	114.39
815.786	113.235
821.721	107.349
827.652	113.626
833.576	117.242
839.498	113.581
845.415	113.793
851.327	114.973
857.233	111.497
863.135	109.916
869.032	153.738
874.925	141.697
880.813	127.597
886.697	123.84
892.576	128.535
898.45	124.6
904.318	127.143
910.184	118.329
916.044	141.538
921.9	139.488
927.75	148.892
933.596	182.008
939.439	208.978
945.275	258.041
951.107	304.723
956.936	263.833
962.759	231.083
968.577	228.68
974.391	243.346
980.201	265.315
986.006	332.02
991.806	326.668
997.602	274.525
1003.39	264.63
1009.18	260.687
1014.96	291.473
1020.74	368.17
1026.51	378.528
1032.28	259.555
1038.04	200.671
1043.8	162.671
1049.56	152.488
1055.31	145.038
1061.05	141.329
1066.8	148.122
1072.53	144.196
1078.26	160.59
1083.99	181.764
1089.72	226.198
1095.44	328.686
1101.15	323.627
1106.86	213.413
1112.56	161.281
1118.27	143.363
1123.96	152.485
1129.65	147.967
1135.34	170.86
1141.03	207.607
1146.7	282.676
1152.38	409.065
1158.05	284.021
1163.71	167.605
1169.37	126.086
1175.03	115.065
1180.68	108.981
1186.33	110.841
1191.98	105.973
1197.61	104.155
1203.25	100.519
1208.88	91.0388
1214.51	94.3636
1220.13	90.8282
1225.74	88.2763
1231.36	88.6763
1236.97	94.0381
1242.57	94.2862
1248.17	92.4028
1253.77	92.4533
1259.36	95.4254
1264.94	119.491
1270.53	116.293
1276.11	99.9729
1281.68	104.762
1287.25	95.5744
1292.81	86.4684
1298.38	87.4421
1303.93	88.4777
1309.48	88.6301
1315.03	87.8983
1320.58	90.2108
1326.12	81.453
1331.65	83.8156
1337.18	85.1298
1342.71	78.2124
1348.23	88.6174
1353.75	89.7979
1359.26	90.9258
1364.77	105.35
1370.28	131.01
1375.78	179.238
1381.28	155.548
1386.77	110.319
1392.26	90.8023
1397.74	89.8759
1403.23	83.8264
1408.7	81.9047
1414.17	82.0672
1419.64	76.0455
1425.11	75.1987
1430.56	78.5135
1436.02	83.9251
1441.47	65.3147
1446.92	86.4319
1452.36	72.919
1457.8	81.372
1463.23	82.431
1468.66	86.6078
1474.09	73.9949
1479.51	81.3653
1484.93	77.2077
1490.34	81.4945
1495.75	78.4669
1501.16	86.0074
1506.56	78.7999
1511.96	79.0154
1517.35	83.5185
1522.74	80.5964
1528.13	81.9489
1533.51	70.4324
1538.88	92.2226
1544.25	79.4633
1549.62	83.8381
1554.99	77.2865
1560.35	79.3509
1565.71	83.5876
1571.06	89.9627
1576.41	86.6543
1581.75	102.802
1587.09	89.9096
1592.43	86.736
1597.76	86.8398
1603.09	98.8645
1608.41	96.9222
1613.73	96.1393
1619.05	94.3215
1624.36	88.1155
1629.67	93.9403
1634.97	88.7392
1640.27	105.456
1645.57	93.4577
1650.86	94.6835
1656.15	89.2256
1661.43	94.8032
1666.71	98.1474
1671.99	93.7151
1677.26	90.3741
1682.53	90.3431
1687.79	85.8302
1693.05	84.6771
1698.31	85.8234
1703.56	87.2738
1708.81	87.6603
1714.06	88.6378
1719.3	77.7076
1724.53	82.3047
1729.77	81.3551
1735	69.1528
1740.22	78.2983
1745.44	82.9629
1750.66	80.8226
1755.87	78.6487
1761.08	77.5511
1766.29	75.3163
1771.49	76.4937
1776.69	66.3483
1781.88	80.0706
1787.07	81.3463
1792.26	78.1072
1797.44	80.5766
1802.62	70.4836
1807.79	75.2687
1812.96	76.582
1818.13	75.5963
1823.29	76.9165
1828.45	75.9333
1833.61	65.6574
1838.76	78.6262
1843.91	72.9359
1849.05	78.9001
1854.19	74.321
1859.33	80.3049
1864.46	79.2872
1869.59	71.2128
1874.71	70.1359
1879.83	74.9442
1884.95	78.5694
1890.06	75.0709
1895.17	69.1629
1900.28	79.8441
1905.38	79.9864
1910.48	76.6089
1915.57	72.0968
1920.66	69.8272
1925.75	67.5658
1930.83	70.0937
1935.91	71.4196
1940.99	79.9393
1946.06	76.4197
1951.13	69.2548
1956.19	76.5139
1961.26	76.5327
1966.31	77.7419
1971.36	81.3214
1976.41	75.255
1981.46	80.0257
1986.5	79.985
1991.54	78.7532
1996.58	83.5454
2001.61	79.945
2006.63	81.1827
2011.66	84.8544
2016.68	82.5139
2021.69	75.3293
2026.71	85.0703
2031.72	82.7881
2036.72	79.3146
2041.72	83.1117
2046.72	79.6416
2051.71	76.1611
2056.71	84.8302
2061.69	88.6894
2066.68	88.8919
2071.66	75.5639
2076.63	81.8767
2081.6	78.3304
2086.57	77.2139
2091.54	77.3268
2096.5	86.1718
2101.46	91.3455
2106.41	85.3524
2111.36	83.096
2116.31	84.6079
2121.25	82.3548
2126.19	86.381
2131.13	80.2951
2136.06	80.4918
2140.99	81.9416
2145.92	87.2019
2150.84	87.3388
2155.76	88.7218
2160.67	78.5792
2165.58	79.8958
2170.49	79.9214
2175.39	78.7038
2180.29	76.1719
2185.19	86.403
2190.08	81.2957
2194.98	81.3395
2199.86	82.7103
2204.74	82.8372
2209.62	80.4223
2214.5	78.0194
2219.37	82.0929
2224.24	81.0065
2229.11	81.2127
2233.97	70.9976
2238.83	76.401
2243.68	79.2124
2248.53	85.9798
2253.38	83.5607
2258.22	77.1783
2263.06	81.3355
2267.9	73.5457
2272.73	82.951
2277.56	73.7502
2282.39	81.7876
2287.21	76.49
2292.03	72.5192
2296.85	73.873
2301.66	83.2582
2306.47	74.0353
2311.28	78.1873
2316.08	68.9884
2320.88	81.252
2325.68	76.0769
2330.47	78.9866
2335.26	79.2281
2340.04	74.0434
2344.82	87.9296
2349.6	84.1463
2354.38	73.4449
2359.15	84.657
2363.92	80.6826
2368.68	83.6234
2373.44	74.0992
2378.2	81.1863
2382.95	82.6905
2387.71	77.2013
2392.45	84.1976
2397.2	81.4251
2401.94	78.6424
2406.68	81.4077
2411.41	81.4902
2416.14	78.9561
2420.87	84.963
2425.59	79.4587
2430.31	82.476
2435.03	81.2947
2439.75	75.8708
2444.46	80.3631
2449.16	80.6053
2453.87	73.6891
2458.57	75.3394
2463.27	81.3151
2467.96	78.6531
2472.65	88.9817
2477.34	79.061
2482.02	74.899
2486.7	80.8939
2491.38	79.5994
2496.05	91.4763
2500.72	84.322
2505.39	84.4725
2510.06	66.9474
2514.72	77.3476
2519.37	84.8301
2524.03	83.4908
2528.68	79.1763
2533.33	74.8598
2537.97	80.9447
2542.61	82.5984
2547.25	75.3225
2551.88	81.4672
2556.51	87.6214
2561.14	84.7929
2565.77	78.9754
2570.39	76.1626
2575.01	79.3836
2579.62	75.0158
2584.23	78.1744
2588.84	82.8262
2593.45	82.8909
2598.05	89.1138
2602.65	81.6085
2607.24	90.8674
2611.84	84.8344
2616.42	83.3715
2621.01	78.8531
2625.59	72.8037
2630.17	83.6533
2634.75	77.6879
2639.32	84.0986
2643.89	92.1025
2648.46	90.8462
2653.02	86.4569
2657.58	86.6234
2662.14	77.3827
2666.69	88.4326
2671.24	82.318
2675.79	82.5529
2680.33	86.1207
2684.88	84.9245
2689.41	94.8738
2693.95	80.8267
2698.48	87.3665
2703.01	77.9158
2707.53	81.2829
2712.06	83.0347
2716.57	83.2192
2721.09	93.0908
2725.6	86.7488
2730.11	85.2289
2734.62	82.0491
2739.12	90.2289
2743.62	82.198
2748.12	87.2139
2752.61	85.8214
2757.1	79.4612
2761.59	77.9369
2766.08	84.6599
2770.56	86.4649
2775.04	81.706
2779.51	86.8948
2783.98	92.1732
2788.45	85.8193
2792.92	92.779
2797.38	94.7173
2801.84	96.6361
2806.3	93.4734
2810.75	83.527
2815.2	88.731
2819.65	90.5577
2824.09	83.9255
2828.53	94.254
2832.97	90.9935
2837.41	87.7136
2841.84	89.5462
2846.27	77.7371
2850.69	93.2902
2855.12	98.6623
2859.54	86.8667
2863.95	88.8391
2868.37	89.1203
2872.78	94.6016
2877.18	86.1932
2881.59	96.9676
2885.99	92.0584
2890.39	90.6154
2894.78	90.9155
2899.18	96.5756
2903.57	105.791
2907.95	97.1941
2912.34	95.6562
2916.72	88.6984
2921.09	88.9175
2925.47	101.76
2929.84	96.6385
2934.21	104.153
2938.57	95.3012
2942.94	97.2977
2947.29	101.086
2951.65	93.9375
2956	106.858
2960.36	105.179
2964.7	94.3499
2969.05	98.1883
2973.39	105.726
2977.73	94.8722
2982.06	111.674
2986.4	106.395
2990.73	114.102
2995.05	106.982
2999.38	111.043
3003.7	109.538
3008.01	113.667
3012.33	110.248
3016.64	120.086
3020.95	118.628
3025.26	134.242
3029.56	119.324
3033.86	127.252
3038.16	140.891
3042.45	133.519
3046.74	127.983
3051.03	137.841
3055.32	138.084
3059.6	128.66
3063.88	140.515
3068.16	142.703
3072.43	148.788
3076.7	145.166
3080.97	151.293
3085.24	161.387
3089.5	161.791
3093.76	166.206
3098.02	184.514
3102.27	187.107
3106.52	185.807
3110.77	196.501
3115.01	187.258
3119.26	179.956
3123.5	211.011
3127.73	216.016
3131.97	212.991
3136.2	216.074
3140.43	227.355
3144.65	230.38
3148.87	235.437
3153.09	267.426
3157.31	253.613
3161.52	279.487
3165.73	261.392
3169.94	285.208
3174.15	288.119
3178.35	278.087
3182.55	301.797
3186.75	321.265
3190.94	317.374
3195.13	320.045
3199.32	342.2
3203.51	334.88
3207.69	336.181
3211.87	348.321
3216.05	369.327
3220.22	336.034
3224.39	346.112
3228.56	343.122
3232.73	331.254
3236.89	332.403
3241.05	329.277
3245.21	337.403
3249.36	327.493
3253.52	308.244
3257.66	326.914
3261.81	321.239
3265.95	304.387
3270.1	339.865
3274.23	327.578
3278.37	312.208
3282.5	324.299
3286.63	320.363
3290.76	314.078
3294.88	321.549
3299	315.194
3303.12	329.735
3307.24	307.205
3311.35	330.993
3315.46	305.992
3319.57	320.569
3323.68	323.656
3327.78	343.236
3331.88	337.246
3335.98	321.948
3340.07	332.401
3344.16	333.126
3348.25	355.076
3352.34	343.837
3356.42	332.603
3360.5	338.125
3364.58	365.227
3368.66	370.794
3372.73	357.117
3376.8	369.736
3380.87	358.195
3384.93	358.661
3388.99	376.014
3393.05	361.883
3397.11	352.695
3401.16	379.892
3405.21	365.665
3409.26	366.024
3413.31	380.897
3417.35	381.205
3421.39	381.484
3425.43	376.871
3429.46	369.942
3433.5	377.76
3437.53	375.914
3441.55	371.684
3445.58	360.192
3449.6	373.434
3453.62	371.954
3457.64	370.671
3461.65	352.06
3465.66	355.803
3469.67	362.042
3473.68	345.443
3477.68	351.544
3481.68	337.436
3485.68	338.409
3489.67	331.717
3493.67	289.274
3497.66	300.156
3501.64	321.241
3505.63	306.392
3509.61	283.625
3513.59	299.222
3517.57	283.981
3521.54	268.713
3525.52	268.897
3529.49	276.777
3533.45	272.008
3537.42	269.994
3541.38	255.073
3545.34	221.803
3549.29	250.712
3553.25	240.438
3557.2	219.839
3561.15	212.297
3565.09	217.847
3569.04	223.558
3572.98	213.525
3576.92	214.031
3580.85	183.024
3584.79	188.855
3588.72	192.062
3592.64	176.679
3596.57	185.187
3600.49	174.988
3604.41	188.821
3608.33	165.084
3612.25	165.417
3616.16	154.97
3620.07	157.95
3623.98	155.393
3627.88	155.493
3631.79	155.554
3635.69	147.519
3639.58	134.138
3643.48	134.388
3647.37	134.689
3651.26	134.773
3655.15	129.46
3659.03	121.393
3662.92	118.753
3666.8	110.669
3670.67	108.046
3674.55	110.916
3678.42	102.879
3682.29	100.355
3686.16	92.353
3690.02	95.3768
3693.89	95.6379
3697.75	90.3259
3701.61	107.292
3705.46	90.8052
3709.31	91.0596
3713.16	88.4981
3717.01	97.1512
3720.86	97.3524
3724.7	89.0527
3728.54	92.0376
3732.38	92.2092
3736.21	69.6445
3740.04	72.6164
3743.87	78.4384
3747.7	78.553
3751.53	84.3653
3755.35	90.1645
3759.17	81.6274
3762.99	81.6662
3766.81	78.835
3770.62	81.7631
3774.43	70.3497
3778.24	90.536
3782.04	84.8988
3785.85	79.2684
3789.65	76.4919
3793.45	79.4976
3797.24	88.3403
3801.04	88.5215
3804.83	82.898
3808.62	68.5137
3812.4	86.189
3816.19	68.7964
3819.97	83.5968
3823.75	89.621
3827.52	75.0451
3831.3	75.1822
3835.07	84.184
3838.84	75.4468
3842.61	90.4209
3846.37	78.6558
3850.13	78.7057
3853.89	78.7463
3857.65	78.7727
3861.41	87.7001
3865.16	69.9333
3868.91	67.1214
3872.66	79.1403
3876.4	76.2012
3880.14	73.2586
3883.89	82.2904
3887.62	79.3725
3891.36	88.4556
3895.09	61.5784
3898.82	82.7328
3902.55	73.8233
3906.28	67.8943
3910	74.0311
3913.73	74.1579
3917.45	83.4009
3921.16	86.6375
3924.88	74.6552
3928.59	80.923
3932.3	68.839
3936.01	65.8761
3939.71	75.184
3943.42	78.4124
3947.12	75.4811
3950.81	69.434
3954.51	69.5292
3958.2	72.7057
3961.9	72.763
3965.58	72.8118
3969.27	72.832
3972.96	69.7549
3976.64	69.7785
3980.32	75.9881
3984	72.8784
3987.67	72.8734
3991.34	85.2912
3995.01	72.9247
3998.68	72.9923