File: Data/3-Raman/raw/bu04w-a-ff3-fi03-v_150 (500nm)_633nm_edge_100%_x100_vis_lwd_h50um_45sx2_01.txt
#Acq. time (s)=	45
#Accumulations=	2
#Range (cm-¹)=	100...4000
#Windows=	1
#Auto scanning=	Off
#Autofocus=	Off
#Macrospot=	Off
#AutoExposure=	Off
#Spike filter=	Multiple accum.
#Delay time (s)=	2
#Binning=	1
#Readout mode=	Signal
#DeNoise=	Off
#ICS correction=	On
#Dark correction=	Off
#Inst. Process=	Off
#Detector Gain=	Best Dynamic
#Detector ADC=	50 kHz HS
#Detector temperature (°C)=	-60.09
#Instrument=	LabRAM HR Evol
#Detector=	SIN-EM FIVIS
#Objective=	x100_VIS_LWD
#Grating=	150 (500nm)
#ND Filter=	100%
#Laser=	633nm_Edge
#Hole=	49.98
#Temperature=	0
#Range=	Visible
#StageXY=	75x50mm Scan+
#StageZ=	Z motor
#X (µm)=	0
#Y (µm)=	0
#Z (µm)=	57.9
#Full time(mm:ss)=	1:34
#Project=	21_11_22
#Sample=	BU04w
#Site=
#Title=	BU04w-A-FF3-FI03-V_150 (500nm)_633nm_Edge_100%_x100_VIS_LWD_H50um_45sX2
#Remark=
#Date=	22.11.2021 12:21
#Acquired=	22.11.2021 12:21:09
100.177	539
106.695	432.595
113.209	390.066
119.717	328.254
126.219	301.702
132.716	285.596
139.208	290.414
145.694	251.226
152.175	245.546
158.651	276.331
165.121	282.25
171.586	226.731
178.045	186.421
184.5	176.684
190.947	174.508
197.39	157.063
203.829	162.726
210.262	169.344
216.688	171.188
223.11	208.277
229.527	263.225
235.939	298.117
242.344	218.987
248.745	198.985
255.141	192.206
261.53	184.529
267.916	193.957
274.294	192.992
280.669	187.285
287.038	190.048
293.402	188.003
299.76	175.545
306.114	186.72
312.461	210.167
318.805	314.757
325.142	421.273
331.475	353.265
337.802	257.934
344.123	211.671
350.441	193.664
356.752	211.401
363.058	226.245
369.36	211.916
375.656	204.179
381.947	186.154
388.232	175.836
394.512	190.112
400.789	198.048
407.059	201.29
413.324	187.497
419.584	232.212
425.839	268.209
432.089	283.672
438.333	258.509
444.573	249.405
450.807	236.495
457.037	240.543
463.261	213.078
469.48	187.729
475.695	199.802
481.904	195.189
488.108	188.685
494.307	187.8
500.502	221.401
506.691	228.977
512.874	238.468
519.053	224.706
525.227	216.675
531.396	208.737
537.559	222.489
543.718	215.407
549.873	201.461
556.022	210.125
562.165	182.583
568.304	185.072
574.437	170.463
580.567	186.751
586.691	185.335
592.81	188.767
598.924	190.515
605.033	191.686
611.138	193.897
617.236	199.089
623.332	195.003
629.42	190.847
635.506	195.732
641.585	186.158
647.659	173.6
653.73	212.676
659.794	208.361
665.854	194.743
671.91	177.604
677.96	170.192
684.005	166.525
690.045	176.118
696.082	174.645
702.113	173.143
708.139	166.865
714.16	171.549
720.176	171.441
726.187	180.691
732.194	178.497
738.196	159.468
744.193	160.136
750.185	173.924
756.173	179.423
762.155	178.713
768.133	171.705
774.107	171.265
780.075	160.379
786.039	177.573
791.998	160.776
797.952	173.077
803.902	161.649
809.845	160.522
815.786	181.834
821.721	174.852
827.652	175.349
833.576	180.768
839.498	172.475
845.415	178.416
851.327	171.286
857.233	177.36
863.135	180.678
869.032	175.498
874.925	180.557
880.813	200.646
886.697	176.033
892.576	194.937
898.45	183.346
904.318	175.354
910.184	194.7
916.044	196.084
921.9	192.089
927.75	206.195
933.596	221.514
939.439	227.848
945.275	265.616
951.107	296.166
956.936	281.008
962.759	256.919
968.577	256.486
974.391	248.146
980.201	285.466
986.006	314.772
991.806	299.884
997.602	262.112
1003.39	267.491
1009.18	275.938
1014.96	300.06
1020.74	321.373
1026.51	342.159
1032.28	270.109
1038.04	222.807
1043.8	212.873
1049.56	199.929
1055.31	189.666
1061.05	189.896
1066.8	207.37
1072.53	190.804
1078.26	212.988
1083.99	216.663
1089.72	240.729
1095.44	307.387
1101.15	311.049
1106.86	242.449
1112.56	212.619
1118.27	192.932
1123.96	199.254
1129.65	194.847
1135.34	209.046
1141.03	239.018
1146.7	270.877
1152.38	359.839
1158.05	291.897
1163.71	207.909
1169.37	180.053
1175.03	179.697
1180.68	169.581
1186.33	166.505
1191.98	171.413
1197.61	167.725
1203.25	169.166
1208.88	170.759
1214.51	172.424
1220.13	158.329
1225.74	161.092
1231.36	164.828
1236.97	162.429
1242.57	171.934
1248.17	171.172
1253.77	174.297
1259.36	209.532
1264.94	182.009
1270.53	177.712
1276.11	407.427
1281.68	451.628
1287.25	185.645
1292.81	180.434
1298.38	173.385
1303.93	160.46
1309.48	157.731
1315.03	171.276
1320.58	164.799
1326.12	157.341
1331.65	175.251
1337.18	163.633
1342.71	149.779
1348.23	155.208
1353.75	166.768
1359.26	158.735
1364.77	188.602
1370.28	182.387
1375.78	196.699
1381.28	942.014
1386.77	308.381
1392.26	183.144
1397.74	175.13
1403.23	230.908
1408.7	172.567
1414.17	178.07
1419.64	163.989
1425.11	146.767
1430.56	157.547
1436.02	150.648
1441.47	149.962
1446.92	148.244
1452.36	142.166
1457.8	139.12
1463.23	143.335
1468.66	138.048
1474.09	150.614
1479.51	142.258
1484.93	131.831
1490.34	140.381
1495.75	151.141
1501.16	147.215
1506.56	140.148
1511.96	141.591
1517.35	152.674
1522.74	148.916
1528.13	152.65
1533.51	145.704
1538.88	163.412
1544.25	146.494
1549.62	148.745
1554.99	145.385
1560.35	140.888
1565.71	152.615
1571.06	140.6
1576.41	154.471
1581.75	135.095
1587.09	137.287
1592.43	139.532
1597.76	150.486
1603.09	147.486
1608.41	141.322
1613.73	136.333
1619.05	140.119
1624.36	135.183
1629.67	155.469
1634.97	151.573
1640.27	138.584
1645.57	136.592
1650.86	143.41
1656.15	137.995
1661.43	139.156
1666.71	149.162
1671.99	142.513
1677.26	144.709
1682.53	135.792
1687.79	144.527
1693.05	136.701
1698.31	138.978
1703.56	136.192
1708.81	137.911
1714.06	141.04
1719.3	141.439
1724.53	142.774
1729.77	137.462
1735	141.117
1740.22	128.995
1745.44	142.787
1750.66	132.82
1755.87	143.152
1761.08	137.554
1766.29	135.343
1771.49	145.621
1776.69	140.069
1781.88	142.537
1787.07	133.681
1792.26	137.4
1797.44	146.867
1802.62	128.933
1807.79	146.515
1812.96	141.072
1818.13	141.382
1823.29	137.062
1828.45	133.898
1833.61	141.193
1838.76	145.022
1843.91	138.287
1849.05	135.007
1854.19	123.478
1859.33	134.232
1864.46	125.098
1869.59	130.066
1874.71	136.146
1879.83	144.577
1884.95	148.278
1890.06	136.546
1895.17	128.276
1900.28	141.354
1905.38	135.681
1910.48	137.183
1915.57	136.448
1920.66	131.896
1925.75	136.925
1930.83	132.399
1935.91	124.234
1940.99	129.225
1946.06	135.389
1951.13	131.885
1956.19	129.531
1961.26	125.948
1966.31	119.927
1971.36	134.331
1976.41	119.806
1981.46	128.161
1986.5	124.488
1991.54	134.061
1996.58	130.427
2001.61	137.65
2006.63	131.696
2011.66	125.777
2016.68	135.516
2021.69	133.182
2026.71	133.337
2031.72	126.297
2036.72	131.384
2041.72	138.924
2046.72	119.766
2051.71	137.09
2056.71	136.094
2061.69	126.612
2066.68	135.483
2071.66	135.769
2076.63	137.282
2081.6	137.541
2086.57	120.454
2091.54	129.29
2096.5	127.088
2101.46	129.872
2106.41	131.455
2111.36	134.328
2116.31	138.506
2121.25	125.104
2126.19	143.128
2131.13	127.081
2136.06	138.801
2140.99	135.299
2145.92	136.85
2150.84	133.24
2155.76	109.147
2160.67	137.354
2165.58	116.967
2170.49	136.186
2175.39	127.334
2180.29	129.94
2185.19	142.725
2190.08	123.544
2194.98	126.172
2199.86	136.568
2204.74	129.072
2209.62	130.606
2214.5	130.892
2219.37	132.512
2224.24	126.37
2229.11	138.386
2233.97	136.133
2238.83	128.641
2243.68	118.491
2248.53	129.298
2253.38	136.197
2258.22	120.715
2263.06	124.979
2267.9	122.576
2272.73	133.385
2277.56	124.246
2282.39	129.663
2287.21	129.7
2292.03	123.083
2296.85	125.784
2301.66	132.547
2306.47	136.732
2311.28	126.303
2316.08	134.628
2320.88	136.315
2325.68	173.024
2330.47	124.893
2335.26	125.275
2340.04	129.746
2344.82	124.737
2349.6	116.984
2354.38	113.256
2359.15	114.941
2363.92	130.333
2368.68	116.796
2373.44	115.65
2378.2	128.371
2382.95	127.163
2387.71	111.977
2392.45	127.34
2397.2	119.006
2401.94	120.399
2406.68	113.414
2411.41	127.459
2416.14	113.892
2420.87	127.093
2425.59	118.837
2430.31	123.362
2435.03	112.399
2439.75	128.342
2444.46	128.723
2449.16	113.418
2453.87	120.907
2458.57	124.131
2463.27	114.417
2467.96	121.948
2472.65	129.494
2477.34	137.087
2482.02	119.984
2486.7	134.823
2491.38	120.494
2496.05	129.53
2500.72	116.584
2505.39	119.731
2510.06	122.86
2514.72	131.859
2519.37	114.336
2524.03	114.523
2528.68	122.094
2533.33	122.296
2537.97	107.679
2542.61	112.364
2547.25	126.035
2551.88	123.322
2556.51	125.066
2561.14	111.807
2565.77	119.591
2570.39	112.359
2575.01	129.282
2579.62	126.542
2584.23	126.749
2588.84	114.741
2593.45	119.393
2598.05	102.824
2602.65	109.066
2607.24	112.248
2611.84	113.877
2616.42	118.556
2621.01	115.6
2625.59	120.318
2630.17	122.026
2634.75	117.686
2639.32	110.331
2643.89	124.609
2648.46	121.905
2653.02	120.728
2657.58	120.961
2662.14	118.028
2666.69	116.606
2671.24	119.949
2675.79	115.574
2680.33	112.984
2684.88	116.672
2689.41	117.197
2693.95	108.036
2698.48	121.031
2703.01	119.685
2707.53	123.131
2712.06	113.669
2716.57	123.617
2721.09	109.28
2725.6	111.071
2730.11	104.71
2734.62	114.544
2739.12	116.241
2743.62	113.124
2748.12	121.447
2752.61	115.246
2757.1	115.505
2761.59	118.956
2766.08	119.181
2770.56	111.169
2775.04	109.767
2779.51	119.998
2783.98	110.442
2788.45	115.814
2792.92	106.153
2797.38	104.776
2801.84	121.846
2806.3	113.684
2810.75	117.275
2815.2	117.463
2819.65	119.333
2824.09	116.139
2828.53	112.935
2832.97	125.01
2837.41	109.855
2841.84	111.72
2846.27	105.073
2850.69	103.561
2855.12	115.821
2859.54	119.549
2863.95	114.715
2868.37	108.156
2872.78	117.167
2877.18	117.536
2881.59	110.945
2885.99	111.347
2890.39	109.97
2894.78	126.223
2899.18	112.524
2903.57	125.349
2907.95	115.028
2912.34	113.536
2916.72	106.617
2921.09	124.844
2925.47	114.367
2929.84	109.283
2934.21	122.267
2938.57	111.639
2942.94	113.666
2947.29	119.3
2951.65	115.826
2956	123.297
2960.36	123.471
2964.7	110.838
2969.05	116.541
2973.39	114.92
2977.73	109.61
2982.06	117.211
2986.4	106.395
2990.73	115.957
2995.05	112.564
2999.38	122.241
3003.7	107.665
3008.01	109.91
3012.33	119.671
3016.64	116.304
3020.95	122.424
3025.26	119.009
3029.56	117.415
3033.86	117.684
3038.16	104.47
3042.45	106.623
3046.74	110.662
3051.03	120.49
3055.32	118.772
3059.6	115.117
3063.88	111.443
3068.16	113.58
3072.43	125.449
3076.7	123.732
3080.97	125.915
3085.24	132.044
3089.5	124.53
3093.76	128.834
3098.02	133.205
3102.27	119.788
3106.52	132.152
3110.77	134.658
3115.01	135.187
3119.26	127.678
3123.5	128.222
3127.73	134.883
3131.97	131.463
3136.2	134.15
3140.43	136.824
3144.65	137.402
3148.87	137.943
3153.09	138.396
3157.31	132.546
3161.52	126.659
3165.73	141.719
3169.94	142.078
3174.15	153.03
3178.35	140.629
3182.55	145.074
3186.75	157.982
3190.94	162.402
3195.13	147.795
3199.32	141.784
3203.51	152.996
3207.69	168.627
3211.87	149.896
3216.05	165.71
3220.22	155.511
3224.39	153.949
3228.56	161.147
3232.73	139.765
3236.89	146.876
3241.05	143.019
3245.21	145.874
3249.36	137.48
3253.52	142.353
3257.66	138.18
3261.81	149.911
3265.95	125.602
3270.1	126.171
3274.23	124.411
3278.37	126.942
3282.5	134.074
3286.63	134.346
3290.76	123.1
3294.88	116.403
3299	123.537
3303.12	123.795
3307.24	119.404
3311.35	124.267
3315.46	122.164
3319.57	120.068
3323.68	118.012
3327.78	130.031
3331.88	116.332
3335.98	123.826
3340.07	124.207
3344.16	107.881
3348.25	119.942
3352.34	122.544
3356.42	118.021
3360.5	123.063
3364.58	128.129
3368.66	101.998
3372.73	119.039
3376.8	107.187
3380.87	121.811
3384.93	107.477
3388.99	117.278
3393.05	134.344
3397.11	117.565
3401.16	115.303
3405.21	115.409
3409.26	115.522
3413.31	122.909
3417.35	110.829
3421.39	123.099
3425.43	132.941
3429.46	118.43
3433.5	108.805
3437.53	116.325
3441.55	106.721
3445.58	109.41
3449.6	114.618
3453.62	105.037
3457.64	117.772
3461.65	118.183
3465.66	116.104
3469.67	108.988
3473.68	119.335
3477.68	99.5413
3481.68	125.117
3485.68	110.268
3489.67	108.031
3493.67	110.867
3497.66	113.676
3501.64	106.227
3505.63	98.7122
3509.61	109.086
3513.59	119.432
3517.57	109.223
3521.54	101.571
3525.52	96.4941
3529.49	106.849
3533.45	109.577
3537.42	112.39
3541.38	102.288
3545.34	107.659
3549.29	84.4366
3553.25	110.471
3557.2	105.367
3561.15	95.0777
3565.09	110.88
3569.04	82.3635
3572.98	98.2478
3576.92	87.9759
3580.85	101.388
3584.79	99.05
3588.72	94.0439
3592.64	96.9742
3596.57	105.25
3600.49	92.169
3604.41	92.4016
3608.33	84.5551
3612.25	98.174
3616.16	109.153
3620.07	95.8498
3623.98	93.2356
3627.88	79.7747
3631.79	96.0374
3635.69	85.2632
3639.58	93.4901
3643.48	90.9492
3647.37	93.874
3651.26	85.7648
3655.15	94.0291
3659.03	99.5695
3662.92	94.1838
3666.8	91.5413
3670.67	83.4279
3674.55	91.7453
3678.42	80.9318
3682.29	89.3571
3686.16	89.5962
3690.02	84.3186
3693.89	70.6889
3697.75	90.3259
3701.61	96.1447
3705.46	88.0112
3709.31	91.0596
3713.16	94.117
3717.01	83.0713
3720.86	88.887
3724.7	91.8798
3728.54	83.5418
3732.38	86.5348
3736.21	81.015
3740.04	81.1595
3743.87	92.7
3747.7	84.266
3751.53	84.3653
3755.35	90.1645
3759.17	84.4915
3762.99	70.2043
3766.81	84.5685
3770.62	87.5009
3774.43	87.5782
3778.24	87.6619
3782.04	90.6547
3785.85	85.0334
3789.65	82.2649
3793.45	82.3885
3797.24	94.1332
3801.04	74.0098
3804.83	77.0806
3808.62	71.4292
3812.4	71.5807
3816.19	77.5789
3819.97	77.7303
3823.75	86.6826
3827.52	86.8169
3831.3	89.9238
3835.07	78.2764
3838.84	78.4055
3842.61	87.4563
3846.37	93.4965
3850.13	81.6757
3853.89	81.7179
3857.65	72.8276
3861.41	81.7544
3865.16	84.8127
3868.91	79.0541
3872.66	82.1267
3876.4	79.1895
3880.14	94.1897
3883.89	61.3438
3887.62	64.3966
3891.36	88.4556
3895.09	79.6014
3898.82	82.7328
3902.55	85.8761
3906.28	79.9644
3910	67.9878
3913.73	86.2653
3917.45	71.2699
3921.16	71.4379
3924.88	68.5609
3928.59	80.923
3932.3	81.077
3936.01	68.9402
3939.71	78.2528
3943.42	75.3374
3947.12	66.2385
3950.81	78.6919
3954.51	75.7096
3958.2	81.9872
3961.9	82.0519
3965.58	72.8118
3969.27	69.7328
3972.96	79.0556
3976.64	75.981
3980.32	72.8866
3984	75.9796
3987.67	72.8734
3991.34	79.0882
3995.01	79.131
3998.68	72.9923