File: Data/3-Raman/raw/bu04w-a-ff3-fi05-l_150 (500nm)_633nm_edge_100%_x100_vis_lwd_h50um_45sx2_01.txt
#Acq. time (s)=	45
#Accumulations=	2
#Range (cm-¹)=	100...4000
#Windows=	1
#Auto scanning=	Off
#Autofocus=	Off
#Macrospot=	Off
#AutoExposure=	Off
#Spike filter=	Multiple accum.
#Delay time (s)=	2
#Binning=	1
#Readout mode=	Signal
#DeNoise=	Off
#ICS correction=	On
#Dark correction=	Off
#Inst. Process=	Off
#Detector Gain=	Best Dynamic
#Detector ADC=	50 kHz EM
#Detector EM gain=	100
#Detector temperature (°C)=	-60.09
#Instrument=	LabRAM HR Evol
#Detector=	SIN-EM FIVIS
#Objective=	x100_VIS_LWD
#Grating=	150 (500nm)
#ND Filter=	100%
#Laser=	633nm_Edge
#Hole=	49.98
#Temperature=	0
#Range=	Visible
#StageXY=	75x50mm Scan+
#StageZ=	Z motor
#X (µm)=	0
#Y (µm)=	0
#Z (µm)=	16.6
#Full time(mm:ss)=	1:34
#Project=	21_11_22
#Sample=	BU04w
#Site=
#Title=	BU04w-A-FF3-FI05-L_150 (500nm)_633nm_Edge_100%_x100_VIS_LWD_H50um_45sX2
#Remark=
#Date=	22.11.2021 11:45
#Acquired=	22.11.2021 11:45:51
100.177	1852.9
106.695	1729.43
113.209	1611.83
119.717	1626.46
126.219	1563.5
132.716	1563.36
139.208	1582.69
145.694	1555.21
152.175	1490.51
158.651	1667.56
165.121	1939.81
171.586	1588.56
178.045	1165.49
184.5	1023.71
190.947	1049.92
197.39	992.981
203.829	963.948
210.262	895.855
216.688	933.666
223.11	1024.7
229.527	1288.04
235.939	1860.97
242.344	1597.99
248.745	1125.53
255.141	1076.36
261.53	1068.28
267.916	1001.56
274.294	989.144
280.669	1054.48
287.038	1060.67
293.402	971.745
299.76	887.663
306.114	926.511
312.461	1046.58
318.805	1499.7
325.142	2552.17
331.475	2687.46
337.802	1751.31
344.123	1224.77
350.441	1015.91
356.752	980.259
363.058	1131.7
369.36	1102.34
375.656	965.041
381.947	861.842
388.232	775.553
394.512	854.33
400.789	874.985
407.059	898.498
413.324	964.405
419.584	1057.49
425.839	1335.84
432.089	1691.65
438.333	1668.77
444.573	1301.04
450.807	1222.28
457.037	1295.66
463.261	1141.39
469.48	914.889
475.695	828.084
481.904	851.563
488.108	877.733
494.307	849.061
500.502	922.893
506.691	1080.06
512.874	1212.41
519.053	1215.56
525.227	1080.1
531.396	1032.9
537.559	984.971
543.718	939.874
549.873	849.248
556.022	796.116
562.165	809.594
568.304	713.916
574.437	716.6
580.567	675.861
586.691	678.785
592.81	756.001
598.924	886.896
605.033	895.467
611.138	824.18
617.236	830.085
623.332	786.589
629.42	763.388
635.506	739.538
641.585	738.035
647.659	693.458
653.73	769.013
659.794	825.016
665.854	800.454
671.91	661.937
677.96	612.691
684.005	556.018
690.045	565.26
696.082	559.989
702.113	573.391
708.139	537.727
714.16	542.376
720.176	522.309
726.187	535.971
732.194	537.835
738.196	511.607
744.193	538.766
750.185	510.115
756.173	496.791
762.155	518.873
768.133	515.583
774.107	495.495
780.075	510.768
786.039	530.364
791.998	499.772
797.952	502.726
803.902	516.523
809.845	515.93
815.786	508.384
821.721	536.275
827.652	537.736
833.576	530.627
839.498	531.914
845.415	554.447
851.327	534.975
857.233	554.191
863.135	564.206
869.032	573.326
874.925	609.44
880.813	585.336
886.697	624.421
892.576	627.972
898.45	609.259
904.318	608.776
910.184	613.8
916.044	643.27
921.9	659.397
927.75	718.628
933.596	807.986
939.439	951.961
945.275	1136.33
951.107	1402.39
956.936	1496.16
962.759	1308.04
968.577	1176.48
974.391	1208.57
980.201	1493.06
986.006	1854.14
991.806	2026.01
997.602	1736.91
1003.39	1543.91
1009.18	1429.73
1014.96	1486.47
1020.74	1868.07
1026.51	2066.35
1032.28	1650.4
1038.04	1146.28
1043.8	995.336
1049.56	869.424
1055.31	787.767
1061.05	770.27
1066.8	721.668
1072.53	735.058
1078.26	823.814
1083.99	910.274
1089.72	1054.95
1095.44	1342.82
1101.15	1733.75
1106.86	1244.67
1112.56	938.624
1118.27	766.87
1123.96	686.914
1129.65	733.484
1135.34	809.748
1141.03	924.662
1146.7	1150.37
1152.38	1772.12
1158.05	1842.94
1163.71	1070.51
1169.37	729.041
1175.03	661.992
1180.68	615.768
1186.33	547.855
1191.98	563.562
1197.61	531.046
1203.25	504.067
1208.88	509.817
1214.51	508.872
1220.13	477.468
1225.74	500.731
1231.36	490.976
1236.97	484.774
1242.57	494.12
1248.17	479.687
1253.77	474.897
1259.36	490.759
1264.94	496.114
1270.53	480.275
1276.11	480.272
1281.68	477.191
1287.25	490.382
1292.81	466.83
1298.38	473.686
1303.93	466.883
1309.48	449.66
1315.03	468.121
1320.58	469.701
1326.12	459.375
1331.65	437.873
1337.18	468.978
1342.71	461.095
1348.23	446.672
1353.75	459.765
1359.26	467.471
1364.77	472.79
1370.28	484.995
1375.78	549.526
1381.28	541.08
1386.77	462.828
1392.26	481.201
1397.74	470.436
1403.23	443.303
1408.7	471.854
1414.17	455.24
1419.64	415.922
1425.11	448.08
1430.56	435.724
1436.02	469.147
1441.47	462.95
1446.92	446.303
1452.36	436.465
1457.8	453.583
1463.23	449.433
1468.66	433.564
1474.09	443.97
1479.51	440.948
1484.93	455.893
1490.34	464.782
1495.75	447.63
1501.16	446.394
1506.56	451.645
1511.96	434.85
1517.35	448.978
1522.74	447.283
1528.13	438.132
1533.51	475.284
1538.88	465.967
1544.25	459.482
1549.62	444.613
1554.99	478.852
1560.35	469.628
1565.71	465.934
1571.06	474.055
1576.41	460.721
1581.75	462.876
1587.09	441.472
1592.43	473.007
1597.76	467.101
1603.09	467.85
1608.41	481.904
1613.73	481.24
1619.05	478.695
1624.36	476.152
1629.67	460.363
1634.97	518.105
1640.27	473.724
1645.57	513.188
1650.86	483.938
1656.15	462.2
1661.43	506.726
1666.71	514.581
1671.99	486.875
1677.26	470.167
1682.53	487.742
1687.79	457.392
1693.05	475.963
1698.31	495.007
1703.56	470.278
1708.81	480.177
1714.06	477.195
1719.3	480.781
1724.53	478.151
1729.77	466.81
1735	472.263
1740.22	458.524
1745.44	469.559
1750.66	453.285
1755.87	473.024
1761.08	480.024
1766.29	466.621
1771.49	468.028
1776.69	476.347
1781.88	440.672
1787.07	478.976
1792.26	460.661
1797.44	472.03
1802.62	469.891
1807.79	473.446
1812.96	468.705
1818.13	469.736
1823.29	470.752
1828.45	501.971
1833.61	471.804
1838.76	470.592
1843.91	469.124
1849.05	462.881
1854.19	450.608
1859.33	458.383
1864.46	472.199
1869.59	477.891
1874.71	480.932
1879.83	433.142
1884.95	478.505
1890.06	487.074
1895.17	490.643
1900.28	499.174
1905.38	464.513
1910.48	490.535
1915.57	483.823
1920.66	465.515
1925.75	491.497
1930.83	475.679
1935.91	490.935
1940.99	492.859
1946.06	483.791
1951.13	491.408
1956.19	469.928
1961.26	497.764
1966.31	480.915
1971.36	481.904
1976.41	493.673
1981.46	476.544
1986.5	481.113
1991.54	485.745
1996.58	467.614
2001.61	462.839
2006.63	488.299
2011.66	479.036
2016.68	493.879
2021.69	484.518
2026.71	511.629
2031.72	484.643
2036.72	490.418
2041.72	470.764
2046.72	480.281
2051.71	513.021
2056.71	496.775
2061.69	489.321
2066.68	490.438
2071.66	524.647
2076.63	513.422
2081.6	506.989
2086.57	501.582
2091.54	528.297
2096.5	498.433
2101.46	533.159
2106.41	505.884
2111.36	493.578
2116.31	506.394
2121.25	511.731
2126.19	509.459
2131.13	514.647
2136.06	493.091
2140.99	524.68
2145.92	516.846
2150.84	524.033
2155.76	525.948
2160.67	509.806
2165.58	511.333
2170.49	503.824
2175.39	497.818
2180.29	491.597
2185.19	540.179
2190.08	510.818
2194.98	518.78
2199.86	519.344
2204.74	522.709
2209.62	528.857
2214.5	513.252
2219.37	505.485
2224.24	527.514
2229.11	509.366
2233.97	518.478
2238.83	504.116
2243.68	515.863
2248.53	531.631
2253.38	502.68
2258.22	535.631
2263.06	531.656
2267.9	522.108
2272.73	537.523
2277.56	520.902
2282.39	518.653
2287.21	521.462
2292.03	520.276
2296.85	509.79
2301.66	534.184
2306.47	517.58
2311.28	530.604
2316.08	538.511
2320.88	530.488
2325.68	523.786
2330.47	558.982
2335.26	549.857
2340.04	571.968
2344.82	594.377
2349.6	544.557
2354.38	547.748
2359.15	547.862
2363.92	553.055
2368.68	548.735
2373.44	526.312
2378.2	549.569
2382.95	536.446
2387.71	524.412
2392.45	538.586
2397.2	548.402
2401.94	531.706
2406.68	514.886
2411.41	553.019
2416.14	553.391
2420.87	537.865
2425.59	549.883
2430.31	523.053
2435.03	535.838
2439.75	541.731
2444.46	534.806
2449.16	540.697
2453.87	593.805
2458.57	559.664
2463.27	569.925
2467.96	554.179
2472.65	554.146
2477.34	555.603
2482.02	562.834
2486.7	550.953
2491.38	544.781
2496.05	583.985
2500.72	563.124
2505.39	564.129
2510.06	548.822
2514.72	579.002
2519.37	579.795
2524.03	557.098
2528.68	565.334
2533.33	566.266
2537.97	553.989
2542.61	568.515
2547.25	568.275
2551.88	588.956
2556.51	549.693
2561.14	577.792
2565.77	589.683
2570.39	564.056
2575.01	568.538
2579.62	574.363
2584.23	584.41
2588.84	589.662
2593.45	602.29
2598.05	586.476
2602.65	591.852
2607.24	606.292
2611.84	573.205
2616.42	575.187
2621.01	586.422
2625.59	577.831
2630.17	600.155
2634.75	586.12
2639.32	606.436
2643.89	603.697
2648.46	579.242
2653.02	604.419
2657.58	616.509
2662.14	598.739
2666.69	613.55
2671.24	578.578
2675.79	586.519
2680.33	613.116
2684.88	603.202
2689.41	601.133
2693.95	611.402
2698.48	604.351
2703.01	586.376
2707.53	635.777
2712.06	615.908
2716.57	628.588
2721.09	600.638
2725.6	622.645
2730.11	628.259
2734.62	606.026
2739.12	622.661
2743.62	636.424
2748.12	627.614
2752.61	604.836
2757.1	629.136
2761.59	643.185
2766.08	631.25
2770.56	642.31
2775.04	635.491
2779.51	635.574
2783.98	651.025
2788.45	651.56
2792.92	648.617
2797.38	608.538
2801.84	645.361
2806.3	626.525
2810.75	629.406
2815.2	640.554
2819.65	656.755
2824.09	657.84
2828.53	647.041
2832.97	642.907
2837.41	652.317
2841.84	653.261
2846.27	666.318
2850.69	672.717
2855.12	665.756
2859.54	648.49
2863.95	665.862
2868.37	666.239
2872.78	650.928
2877.18	646.014
2881.59	660.428
2885.99	654.053
2890.39	661.58
2894.78	631.995
2899.18	678.687
2903.57	688.088
2907.95	670.55
2912.34	690.155
2916.72	666.582
2921.09	668.228
2925.47	677.199
2929.84	664.728
2934.21	684.694
2938.57	684.354
2942.94	683.812
2947.29	695.763
2951.65	684.011
2956	708.732
2960.36	689.607
2964.7	716.326
2969.05	726.777
2973.39	711.584
2977.73	696.344
2982.06	714.344
2986.4	712.383
2990.73	738.417
2995.05	708.872
2999.38	716.65
3003.7	726.506
3008.01	725.216
3012.33	759.488
3016.64	714.844
3020.95	768.707
3025.26	771.18
3029.56	771.309
3033.86	746.287
3038.16	762.921
3042.45	766.532
3046.74	775.598
3051.03	786.558
3055.32	778.293
3059.6	773.897
3063.88	817.892
3068.16	797.974
3072.43	830.489
3076.7	824.232
3080.97	829.674
3085.24	860.729
3089.5	870.73
3093.76	869.386
3098.02	882.115
3102.27	869.206
3106.52	904.195
3110.77	905.701
3115.01	915.263
3119.26	912.848
3123.5	945.005
3127.73	935.053
3131.97	955.91
3136.2	944.171
3140.43	995.834
3144.65	956.646
3148.87	1014.35
3153.09	1048.89
3157.31	1102.12
3161.52	1082.36
3165.73	1043.47
3169.94	1130.31
3174.15	1169.36
3178.35	1141.95
3182.55	1128.83
3186.75	1202.36
3190.94	1258.88
3195.13	1188.74
3199.32	1223.82
3203.51	1249.65
3207.69	1183.61
3211.87	1242.31
3216.05	1210.87
3220.22	1215.81
3224.39	1205.39
3228.56	1229.98
3232.73	1135.73
3236.89	1177.21
3241.05	1204.02
3245.21	1064.55
3249.36	1146.78
3253.52	1098.47
3257.66	1141.39
3261.81	1104.61
3265.95	1084.02
3270.1	1079.84
3274.23	1038.66
3278.37	1084.15
3282.5	1072.59
3286.63	1028.84
3290.76	1044.62
3294.88	1076.44
3299	1059.88
3303.12	1006.56
3307.24	1036.38
3311.35	1061.5
3315.46	1030.83
3319.57	1037.48
3323.68	1028.22
3327.78	1044.94
3331.88	1003.51
3335.98	1004.76
3340.07	1059.9
3344.16	1069.32
3348.25	1066.42
3352.34	1092.19
3356.42	1006.16
3360.5	1072.92
3364.58	1041.79
3368.66	1048.78
3372.73	1089.39
3376.8	1009.25
3380.87	1058.91
3384.93	1111
3388.99	1061.54
3393.05	1036.03
3397.11	1042.33
3401.16	1097.2
3405.21	1039.9
3409.26	1019.03
3413.31	1085.5
3417.35	1110.73
3421.39	1077.42
3425.43	1102.56
3429.46	1096.4
3433.5	1009.8
3437.53	1082.44
3441.55	1054.95
3445.58	1042.47
3449.6	1069.77
3453.62	1065.2
3457.64	1085.98
3461.65	1072.35
3465.66	1043.69
3469.67	1034.76
3473.68	1082.81
3477.68	1050.85
3481.68	1089.4
3485.68	1011.43
3489.67	1044.72
3493.67	1024.57
3497.66	1014.14
3501.64	1069.95
3505.63	1058.91
3509.61	1011.3
3513.59	1019.67
3517.57	1027.98
3521.54	1041.42
3525.52	1018.98
3529.49	978.376
3533.45	1008.1
3537.42	1015.38
3541.38	955.552
3545.34	1024.7
3549.29	974.269
3553.25	1000.74
3557.2	980.822
3561.15	963.801
3565.09	952.263
3569.04	970.059
3572.98	1011.3
3576.92	984.804
3580.85	1013.88
3584.79	993.141
3588.72	980.176
3592.64	961.772
3596.57	967.233
3600.49	969.778
3604.41	953.478
3608.33	936.817
3612.25	1003.26
3616.16	943.296
3620.07	926.098
3623.98	951.273
3627.88	951.888
3631.79	957.669
3635.69	923.008
3639.58	959.289
3643.48	936.641
3647.37	927.856
3651.26	925.716
3655.15	896.683
3659.03	913.857
3662.92	909.078
3666.8	940.006
3670.67	940.957
3674.55	920.191
3678.42	919.057
3682.29	918.316
3686.16	915.26
3690.02	917.829
3693.89	920.341
3697.75	928.273
3701.61	900.138
3705.46	927.61
3709.31	907.794
3713.16	935.551
3717.01	926.456
3720.86	936.84
3724.7	938.587
3728.54	926.04
3732.38	919.255
3736.21	946.597
3740.04	911.264
3743.87	924.147
3747.7	936.923
3751.53	932.308
3755.35	941.718
3759.17	933.703
3762.99	937.012
3766.81	946.02
3770.62	938.124
3774.43	927.468
3778.24	951.347
3782.04	932.448
3785.85	942.573
3789.65	935.222
3793.45	945.299
3797.24	973.192
3801.04	934.555
3804.83	933.693
3808.62	956.276
3812.4	946.618
3816.19	954.367
3819.97	929.831
3823.75	963.793
3827.52	950.572
3831.3	925.773
3835.07	974.763
3838.84	952.701
3842.61	954.607
3846.37	949.806
3850.13	959.318
3853.89	944.956
3857.65	951.217
3861.41	972.134
3865.16	931.452
3868.91	963.565
3872.66	955.656
3876.4	974.181
3880.14	944.887
3883.89	972.523
3887.62	961.456
3891.36	953.521
3895.09	958.221
3898.82	983.768
3902.55	964.222
3906.28	965.608
3910	963.916
3913.73	956.486
3917.45	970.483
3921.16	963.652
3924.88	984.229
3928.59	955.808
3932.3	1006.58
3936.01	974.354
3939.71	994.27
3943.42	977.849
3947.12	970.471
3950.81	968.99
3954.51	979.589
3958.2	974.565
3961.9	990.816
3965.58	1000.78
3969.27	994.854
3972.96	985.87
3976.64	1004.81
3980.32	983.193
3984	973.779
3987.67	989.218
3991.34	998.682
3995.01	999.223
3998.68	987.726