File: Data/3-Raman/raw/bu04w-a-ff3-fi01-l_150 (500nm)_633nm_edge_100%_x100_vis_lwd_h50um_45sx2_01.txt
#Acq. time (s)=	45
#Accumulations=	2
#Range (cm-¹)=	100...4000
#Windows=	1
#Auto scanning=	Off
#Autofocus=	Off
#Macrospot=	Off
#AutoExposure=	Off
#Spike filter=	Multiple accum.
#Delay time (s)=	2
#Binning=	1
#Readout mode=	Signal
#DeNoise=	Off
#ICS correction=	On
#Dark correction=	Off
#Inst. Process=	Off
#Detector Gain=	Best Dynamic
#Detector ADC=	50 kHz HS
#Detector temperature (°C)=	-60.09
#Instrument=	LabRAM HR Evol
#Detector=	SIN-EM FIVIS
#Objective=	x100_VIS_LWD
#Grating=	150 (500nm)
#ND Filter=	100%
#Laser=	633nm_Edge
#Hole=	49.98
#Temperature=	0
#Range=	Visible
#StageXY=	75x50mm Scan+
#StageZ=	Z motor
#X (µm)=	0
#Y (µm)=	0
#Z (µm)=	14.5
#Full time(mm:ss)=	1:35
#Project=	21_11_22
#Sample=	BU04w
#Site=
#Title=	BU04w-A-FF3-L_150 (500nm)_633nm_Edge_100%_x100_VIS_LWD_H50um_45sX2
#Remark=
#Date=	22.11.2021 10:25
#Acquired=	22.11.2021 10:25:40
100.177	1187.13
106.695	1107
113.209	1019.33
119.717	1003.87
126.219	914.67
132.716	876.881
139.208	853.062
145.694	848.425
152.175	791.203
158.651	785.89
165.121	805.54
171.586	773.187
178.045	644.567
184.5	567.399
190.947	557.948
197.39	514.154
203.829	460.5
210.262	443.157
216.688	415.334
223.11	417.03
229.527	457.431
235.939	540.604
242.344	523.003
248.745	406.044
255.141	389.633
261.53	377.123
267.916	347.604
274.294	339.989
280.669	341.854
287.038	355.926
293.402	325.336
299.76	300.462
306.114	297.335
312.461	298.956
318.805	372.329
325.142	562.798
331.475	713.606
337.802	537.088
344.123	391.756
350.441	308.638
356.752	304.624
363.058	324.081
369.36	305.892
375.656	317.769
381.947	292.126
388.232	285.557
394.512	274.606
400.789	275.197
407.059	293.685
413.324	307.457
419.584	312.611
425.839	381.736
432.089	417.72
438.333	515.605
444.573	416.614
450.807	361.065
457.037	354.509
463.261	353.887
469.48	298.597
475.695	276.183
481.904	272.519
488.108	283.726
494.307	267.953
500.502	282.927
506.691	316.651
512.874	329.002
519.053	337.759
525.227	311.207
531.396	306.304
537.559	302.453
543.718	276.683
549.873	264.682
556.022	246.012
562.165	243.916
568.304	233.106
574.437	210.848
580.567	228.875
586.691	210.545
592.81	223.258
598.924	235.232
605.033	260.711
611.138	248.095
617.236	236.565
623.332	232.594
629.42	222.89
635.506	219.314
641.585	221.033
647.659	209.355
653.73	208.92
659.794	227.09
665.854	228.368
671.91	200.912
677.96	197.236
684.005	188.915
690.045	177.052
696.082	174.645
702.113	160.005
708.139	169.685
714.16	166.849
720.176	172.381
726.187	160.04
732.194	159.757
738.196	150.115
744.193	155.467
750.185	155.273
756.173	157.985
762.155	152.582
768.133	153.926
774.107	140.297
780.075	140.626
786.039	156.848
791.998	152.289
797.952	157.043
803.902	124.889
809.845	143.575
815.786	131.09
821.721	136.412
827.652	139.811
833.576	135.926
839.498	146.3
845.415	139.08
851.327	144.068
857.233	137.842
863.135	140.108
869.032	152.792
874.925	193.827
880.813	156.058
886.697	154.207
892.576	149.404
898.45	144.498
904.318	140.378
910.184	148.5
916.044	162.228
921.9	148.881
927.75	162.044
933.596	168.84
939.439	197.657
945.275	238.155
951.107	289.511
956.936	310.588
962.759	297.107
968.577	269.91
974.391	253.906
980.201	277.789
986.006	347.351
991.806	411.803
997.602	389.11
1003.39	339.966
1009.18	315.97
1014.96	319.142
1020.74	381.541
1026.51	430.211
1032.28	377.578
1038.04	274.779
1043.8	216.734
1049.56	197.024
1055.31	173.173
1061.05	166.584
1066.8	154.921
1072.53	153.906
1078.26	170.294
1083.99	193.397
1089.72	200.043
1095.44	250.266
1101.15	344.911
1106.86	305.36
1112.56	214.557
1118.27	177.381
1123.96	148.588
1129.65	154.803
1135.34	154.214
1141.03	172.27
1146.7	203.035
1152.38	277.14
1158.05	407.081
1163.71	272.789
1169.37	183.977
1175.03	144.443
1180.68	122.665
1186.33	126.466
1191.98	120.624
1197.61	113.935
1203.25	120.133
1208.88	106.786
1214.51	103.256
1220.13	117.63
1225.74	99.2485
1231.36	105.71
1236.97	115.159
1242.57	114.454
1248.17	117.649
1253.77	108.62
1259.36	114.611
1264.94	119.491
1270.53	130.389
1276.11	134.135
1281.68	118.797
1287.25	104.581
1292.81	110.46
1298.38	107.429
1303.93	101.474
1309.48	106.657
1315.03	95.9348
1320.58	97.2664
1326.12	100.678
1331.65	108.198
1337.18	111.637
1342.71	107.862
1348.23	102.96
1353.75	102.113
1359.26	106.337
1364.77	115.628
1370.28	113.542
1375.78	156.641
1381.28	225.365
1386.77	145.211
1392.26	124.661
1397.74	119.663
1403.23	108.511
1408.7	95.298
1414.17	102.713
1419.64	85.3572
1425.11	92.8315
1430.56	93.0723
1436.02	95.3932
1441.47	95.6207
1446.92	101.099
1452.36	97.0504
1457.8	85.5719
1463.23	95.0319
1468.66	93.9564
1474.09	90.7881
1479.51	84.515
1484.93	87.7121
1490.34	96.2161
1495.75	85.8396
1501.16	91.2839
1506.56	94.6657
1511.96	92.8033
1517.35	86.7103
1522.74	96.6089
1528.13	94.8036
1533.51	90.8632
1538.88	95.4585
1544.25	81.6255
1549.62	98.9831
1554.99	96.7432
1560.35	91.2266
1565.71	92.216
1571.06	103.969
1576.41	101.725
1581.75	104.954
1587.09	102.831
1592.43	101.821
1597.76	98.7061
1603.09	95.623
1608.41	96.9222
1613.73	109.175
1619.05	107.407
1624.36	112.197
1629.67	110.421
1634.97	111.889
1640.27	109.873
1645.57	115.578
1650.86	103.543
1656.15	115.827
1661.43	109.218
1666.71	107.02
1671.99	105.915
1677.26	101.463
1682.53	100.32
1687.79	94.6901
1693.05	96.8529
1698.31	96.8973
1703.56	93.9444
1708.81	101.061
1714.06	84.1781
1719.3	86.6524
1724.53	97.9818
1729.77	86.9658
1735	82.6461
1740.22	90.6909
1745.44	82.9629
1750.66	85.3441
1755.87	91.0966
1761.08	83.2118
1766.29	83.2444
1771.49	76.4937
1776.69	78.8241
1781.88	72.1204
1787.07	81.3463
1792.26	81.5279
1797.44	81.7196
1802.62	80.7983
1807.79	83.3127
1812.96	91.5529
1818.13	79.0588
1823.29	78.0732
1828.45	79.4111
1833.61	79.6024
1838.76	75.1317
1843.91	91.6075
1849.05	84.7445
1854.19	82.5139
1859.33	82.6496
1864.46	71.0648
1869.59	75.9211
1874.71	76.0297
1879.83	79.6651
1884.95	71.4804
1890.06	65.6131
1895.17	84.5324
1900.28	75.1126
1905.38	75.2464
1910.48	76.6089
1915.57	84.0136
1920.66	74.6017
1925.75	75.9368
1930.83	72.4901
1935.91	76.221
1940.99	82.3435
1946.06	84.8439
1951.13	69.2548
1956.19	78.9238
1961.26	69.3013
1966.31	86.179
1971.36	80.1166
1976.41	81.2754
1981.46	71.6019
1986.5	76.3767
1991.54	77.5508
1996.58	83.5454
2001.61	82.3493
2006.63	78.7773
2011.66	81.2436
2016.68	86.1277
2021.69	82.5609
2026.71	77.8303
2031.72	77.9538
2036.72	78.1037
2041.72	83.1117
2046.72	74.778
2051.71	81.0355
2056.71	78.7273
2061.69	83.7962
2066.68	79.0831
2071.66	76.7925
2076.63	81.8767
2081.6	80.7975
2086.57	80.9202
2091.54	90.9363
2096.5	81.2123
2101.46	82.6459
2106.41	80.3683
2111.36	79.3473
2116.31	77.0872
2121.25	79.8401
2126.19	86.381
2131.13	82.8241
2136.06	80.4918
2140.99	75.5896
2145.92	80.8368
2150.84	83.5138
2155.76	79.7858
2160.67	83.69
2165.58	79.8958
2170.49	85.0363
2175.39	81.2633
2180.29	78.7323
2185.19	76.1626
2190.08	81.2957
2194.98	80.0586
2199.86	77.581
2204.74	82.8372
2209.62	80.4223
2214.5	87.0464
2219.37	83.3857
2224.24	79.7104
2229.11	77.3145
2233.97	73.603
2238.83	80.319
2243.68	73.9752
2248.53	68.9151
2253.38	71.7175
2258.22	87.7326
2263.06	76.0454
2267.9	76.1959
2272.73	80.2966
2277.56	79.0655
2282.39	77.7979
2287.21	79.1505
2292.03	77.8417
2296.85	76.5351
2301.66	77.9296
2306.47	74.0353
2311.28	75.5142
2316.08	74.3467
2320.88	83.938
2325.68	85.5023
2330.47	76.2862
2335.26	73.8108
2340.04	76.7606
2344.82	75.6603
2349.6	67.7275
2354.38	73.4449
2359.15	69.5151
2363.92	64.1323
2368.68	85.0056
2373.44	72.7142
2378.2	71.4717
2382.95	70.1827
2387.71	67.4642
2392.45	86.981
2397.2	63.3306
2401.94	71.6829
2406.68	71.6666
2411.41	75.9182
2416.14	73.3663
2420.87	65.3022
2425.59	78.0524
2430.31	68.3775
2435.03	71.398
2439.75	71.6163
2444.46	78.9408
2449.16	63.4856
2453.87	69.3965
2458.57	63.8591
2463.27	71.2407
2467.96	81.5394
2472.65	78.8537
2477.34	76.1597
2482.02	79.2621
2486.7	75.0638
2491.38	73.7572
2496.05	87.0854
2500.72	74.0567
2505.39	62.4362
2510.06	74.3043
2514.72	80.2942
2519.37	71.5524
2524.03	73.1468
2528.68	86.576
2533.33	73.3774
2537.97	82.4299
2542.61	75.1571
2547.25	76.814
2551.88	76.9828
2556.51	69.6477
2561.14	75.7883
2565.77	69.9497
2570.39	82.1953
2575.01	68.7991
2579.62	70.4694
2584.23	75.1385
2588.84	75.2275
2593.45	73.7653
2598.05	79.9739
2602.65	80.0831
2607.24	77.1227
2611.84	72.606
2616.42	71.1335
2621.01	78.8531
2625.59	77.4018
2630.17	65.2342
2634.75	82.303
2639.32	68.6677
2643.89	73.5272
2648.46	73.764
2653.02	73.9946
2657.58	72.5763
2662.14	74.2561
2666.69	68.0853
2671.24	69.7743
2675.79	69.9734
2680.33	82.9604
2684.88	69.0508
2689.41	78.9286
2693.95	74.4246
2698.48	79.3512
2703.01	77.9158
2707.53	70.0159
2712.06	71.7484
2716.57	73.5238
2721.09	75.2821
2725.6	75.3985
2730.11	77.1119
2734.62	64.177
2739.12	62.5912
2743.62	80.5703
2748.12	72.5424
2752.61	72.7438
2757.1	79.4612
2761.59	79.5777
2766.08	76.4405
2770.56	81.524
2775.04	66.8503
2779.51	73.6537
2783.98	65.6007
2788.45	77.4873
2792.92	72.7187
2797.38	77.9532
2801.84	78.1492
2806.3	76.6314
2810.75	71.7151
2815.2	78.5903
2819.65	77.0164
2824.09	82.23
2828.53	78.9696
2832.97	75.6862
2837.41	84.3072
2841.84	74.1954
2846.27	72.6116
2850.69	84.7315
2855.12	90.0829
2859.54	86.8667
2863.95	87.1141
2868.37	83.9288
2872.78	77.2435
2877.18	82.7106
2881.59	98.7147
2885.99	78.0304
2890.39	80.0582
2894.78	78.5581
2899.18	80.6273
2903.57	88.0112
2907.95	81.1437
2912.34	79.5645
2916.72	83.3227
2921.09	85.3249
2925.47	85.5504
2929.84	82.1879
2934.21	95.0964
2938.57	84.4097
2942.94	93.6604
2947.29	90.1578
2951.65	88.4654
2956	88.5915
2960.36	96.0329
2964.7	87.0217
2969.05	92.6824
2973.39	100.21
2977.73	107.767
2982.06	87.6778
2986.4	95.2929
2990.73	104.826
2995.05	90.2369
2999.38	92.3807
3003.7	96.4305
3008.01	89.2429
3012.33	95.1715
3016.64	99.2839
3020.95	103.443
3025.26	105.68
3029.56	111.687
3033.86	117.684
3038.16	106.387
3042.45	106.623
3046.74	102.964
3051.03	116.634
3055.32	118.772
3059.6	120.921
3063.88	126.948
3068.16	131.054
3072.43	125.449
3076.7	143.218
3080.97	133.724
3085.24	147.693
3089.5	138.258
3093.76	154.404
3098.02	158.86
3102.27	153.447
3106.52	171.896
3110.77	164.582
3115.01	171.236
3119.26	183.977
3123.5	198.895
3127.73	193.704
3131.97	188.532
3136.2	187.401
3140.43	198.55
3144.65	211.784
3148.87	206.397
3153.09	227.885
3157.31	211.866
3161.52	229.242
3165.73	244.596
3169.94	255.74
3174.15	258.568
3178.35	269.628
3182.55	261.557
3186.75	261.889
3190.94	289.776
3195.13	290.274
3199.32	305.954
3203.51	283.525
3207.69	308.255
3211.87	300.871
3216.05	297.844
3220.22	316.459
3224.39	289.337
3228.56	297.081
3232.73	296.038
3236.89	310.316
3241.05	300.452
3245.21	301.77
3249.36	305.139
3253.52	297.035
3257.66	308.94
3261.81	287.424
3265.95	279.493
3270.1	283.031
3274.23	277.357
3278.37	287.049
3282.5	305.964
3286.63	276.729
3290.76	274.962
3294.88	289.279
3299	301.339
3303.12	299.654
3307.24	302.568
3311.35	275.246
3315.46	257.127
3319.57	276.272
3323.68	309.635
3327.78	305.749
3331.88	304.344
3335.98	310.155
3340.07	320.572
3344.16	314.158
3348.25	336.075
3352.34	324.801
3356.42	325.451
3360.5	307.06
3364.58	314.933
3368.66	339.594
3372.73	330.664
3376.8	314.336
3380.87	334.074
3384.93	349
3388.99	317.98
3393.05	366.724
3397.11	342.999
3401.16	338.626
3405.21	348.658
3409.26	329.543
3413.31	327.352
3417.35	376.333
3421.39	342.483
3425.43	367.113
3429.46	345.524
3433.5	355.755
3437.53	334.282
3441.55	347.151
3445.58	345.44
3449.6	353.714
3453.62	342.296
3457.64	345.877
3461.65	334.643
3465.66	345.815
3469.67	354.525
3473.68	307.758
3477.68	328.864
3481.68	322.271
3485.68	297.851
3489.67	285.963
3493.67	304.566
3497.66	282.274
3501.64	285.405
3505.63	296.137
3509.61	293.892
3513.59	283.811
3517.57	273.701
3521.54	260.999
3525.52	258.604
3529.49	258.755
3533.45	251.382
3537.42	257.076
3541.38	236.946
3545.34	219.209
3549.29	219.535
3553.25	206.647
3557.2	196.425
3561.15	196.668
3565.09	196.975
3569.04	192.181
3572.98	203.046
3576.92	195.648
3580.85	161.957
3584.79	178.29
3588.72	181.465
3592.64	176.679
3596.57	166.535
3600.49	161.63
3604.41	145.968
3608.33	151.662
3612.25	149.278
3616.16	146.885
3620.07	139.05
3623.98	155.393
3627.88	141.972
3631.79	142.027
3635.69	131.278
3639.58	131.428
3643.48	109.954
3647.37	110.2
3651.26	121.16
3655.15	113.107
3659.03	105.025
3662.92	99.6437
3666.8	110.669
3670.67	83.4279
3674.55	83.5293
3678.42	91.9057
3682.29	103.104
3686.16	92.353
3690.02	87.0831
3693.89	84.5494
3697.75	81.9882
3701.61	90.5711
3705.46	82.4232
3709.31	71.4468
3713.16	77.2602
3717.01	74.6234
3720.86	77.5997
3724.7	74.9173
3728.54	77.8779
3732.38	72.3488
3736.21	66.8019
3740.04	75.4641
3743.87	64.1769
3747.7	69.9836
3751.53	75.7858
3755.35	64.4032
3759.17	64.4427
3762.99	67.3388
3766.81	64.5014
3770.62	70.2876
3774.43	67.4783
3778.24	76.1652
3782.04	82.0209
3785.85	70.6209
3789.65	67.8325
3793.45	62.1527
3797.24	82.5475
3801.04	68.2051
3804.83	74.1719
3808.62	71.4292
3812.4	65.7374
3816.19	68.7964
3819.97	71.8639
3823.75	69.0523
3827.52	69.1592
3831.3	63.3889
3835.07	66.4611
3838.84	69.5294
3842.61	69.6686
3846.37	72.7195
3850.13	69.7956
3853.89	72.8032
3857.65	66.8824
3861.41	81.7544
3865.16	61.0056
3868.91	61.155
3872.66	61.2217
3876.4	67.2364
3880.14	64.2882
3883.89	70.3209
3887.62	64.3966
3891.36	61.4691
3895.09	73.5938
3898.82	70.6989
3902.55	73.8233
3906.28	70.9119
3910	71.0095
3913.73	55.9968
3917.45	68.2371
3921.16	74.4779
3924.88	62.4666
3928.59	62.6008
3932.3	68.839
3936.01	72.0042
3939.71	53.7029
3943.42	75.3374
3947.12	63.1576
3950.81	63.2621
3954.51	63.3488
3958.2	66.518
3961.9	69.6667
3965.58	75.9102
3969.27	66.6335
3972.96	69.7549
3976.64	69.7785
3980.32	66.6835
3984	69.7772
3987.67	60.4694
3991.34	66.6822
3995.01	63.6151
3998.68	72.9923