File: Data/3-Raman/raw/bu04w-a-ff3-fi02-v_1800 (450-850nm)_633nm_edge_100%_x100_vis_lwd_h50um_45sx2_01.txt
#Acq. time (s)=	45
#Accumulations=	2
#Range (cm-¹)=	1200...2355
#Windows=	5
#Auto scanning=	Off
#Autofocus=	Off
#Macrospot=	Off
#AutoExposure=	Off
#Spike filter=	Multiple accum.
#Delay time (s)=	2
#Binning=	1
#Readout mode=	Signal
#DeNoise=	Off
#ICS correction=	On
#Dark correction=	Off
#Inst. Process=	Off
#Detector Gain=	Best Dynamic
#Detector ADC=	50 kHz HS
#Detector temperature (°C)=	-60.28
#Instrument=	LabRAM HR Evol
#Detector=	SIN-EM FIVIS
#Objective=	x100_VIS_LWD
#Grating=	1800 (450-850nm)
#ND Filter=	100%
#Laser=	633nm_Edge
#Hole=	49.98
#Temperature=	0
#Range=	Visible
#StageXY=	75x50mm Scan+
#StageZ=	Z motor
#X (µm)=	0
#Y (µm)=	0
#Z (µm)=	5.3
#Full time(mm:ss)=	7:56
#Project=	21_11_22
#Sample=	BU04w
#Site=
#Title=	BU04w-A-FF3-FI02-L_1800 (450-850nm)_633nm_Edge_100%_x100_VIS_LWD_H50um_45sX2
#Remark=
#Date=	22.11.2021 10:49
#Acquired=	22.11.2021 10:49:33
1200.31	11.2819
1201.34	13.225
1202.37	12.2753
1203.4	11.2707
1204.44	13.2514
1205.47	14.2288
1206.5	13.2942
1207.53	11.2766
1208.56	14.2646
1209.59	12.3027
1210.62	11.3255
1211.65	11.3342
1212.68	12.3069
1213.71	11.3555
1214.74	12.3303
1215.77	11.3466
1216.8	14.3114
1217.83	10.3884
1218.86	11.3869
1219.89	13.395
1220.91	10.4358
1221.94	9.43898
1222.97	11.4317
1224	12.4335
1225.02	14.4152
1226.05	12.4247
1227.08	13.4823
1228.1	10.492
1229.13	12.4842
1230.15	14.497
1231.18	13.502
1232.2	12.5199
1233.23	11.5031
1234.25	14.5697
1235.28	13.58
1236.3	12.5832
1237.32	15.611
1238.35	10.5738
1239.37	12.5851
1240.39	12.619
1241.42	12.6184
1242.44	12.6127
1243.46	14.6786
1244.48	11.6811
1245.51	14.6917
1246.53	12.7296
1247.55	14.7371
1248.57	12.698
1249.59	14.7362
1250.61	11.6986
1251.63	12.7218
1252.65	12.7265
1253.67	11.7193
1254.69	12.7527
1255.71	12.7459
1256.73	12.7464
1257.75	15.7819
1258.76	12.7449
1259.78	10.6875
1260.8	10.7047
1261.82	15.807
1262.83	11.7566
1263.85	16.8606
1264.87	16.8476
1265.88	14.8088
1266.9	14.7827
1267.92	16.8291
1268.93	12.7404
1269.95	12.7372
1270.96	12.7347
1271.98	11.6987
1272.99	15.7713
1274.01	12.7218
1275.02	13.7258
1276.04	15.7657
1277.05	14.7366
1278.06	13.7268
1279.08	11.6808
1280.09	13.755
1281.1	15.7137
1282.12	18.7657
1283.13	29.8413
1284.14	95.5677
1285.15	56.2653
1286.16	22.791
1287.17	13.6782
1288.18	13.6427
1289.19	14.6541
1290.2	13.6488
1291.22	12.5863
1292.22	15.6306
1293.23	13.645
1294.24	10.6054
1295.25	12.6141
1296.26	16.6369
1297.27	12.6004
1298.28	8.55375
1299.29	13.5802
1300.29	13.5888
1301.3	14.5926
1302.31	11.626
1303.32	11.63
1304.32	12.6115
1305.33	13.6184
1306.34	10.5743
1307.34	11.5831
1308.35	11.6012
1309.35	14.6043
1310.36	18.6268
1311.36	11.5919
1312.37	12.6245
1313.37	13.6091
1314.38	10.5604
1315.38	13.6092
1316.38	11.6043
1317.39	10.6338
1318.39	10.5927
1319.39	12.6513
1320.4	12.6485
1321.4	11.6308
1322.4	9.61294
1323.4	13.6583
1324.4	12.6793
1325.41	11.6745
1326.41	12.7047
1327.41	11.7198
1328.41	13.7723
1329.41	14.8201
1330.41	11.7505
1331.41	10.7001
1332.41	15.7912
1333.41	13.7811
1334.41	10.7296
1335.41	13.8332
1336.4	12.7953
1337.4	12.8191
1338.4	11.792
1339.4	12.802
1340.4	13.8733
1341.39	14.904
1342.39	12.866
1343.39	11.8397
1344.38	12.8786
1345.38	13.9359
1346.38	12.8495
1347.37	10.8249
1348.37	13.9403
1349.36	12.9108
1350.36	12.931
1351.35	16.0221
1352.35	15.0194
1353.34	15.0048
1354.34	11.9116
1355.33	12.9229
1356.32	11.938
1357.32	14.0348
1358.31	11.9422
1359.3	16.0915
1360.29	12.9421
1361.29	11.9137
1362.28	13.0009
1363.27	13.0112
1364.26	12.9992
1365.25	15.034
1366.24	10.9166
1367.23	9.86504
1368.22	12.9821
1369.21	14.0852
1370.2	16.147
1371.19	14.0954
1372.18	14.0614
1373.17	14.0135
1374.16	12.9796
1375.15	14.0085
1376.14	15.065
1377.13	11.9882
1378.11	15.0832
1379.1	17.1485
1380.09	14.0605
1381.08	10.9095
1382.06	15.0653
1383.05	14.026
1384.04	14.0355
1385.02	16.1238
1386.01	24.4819
1386.99	77.2411
1387.98	181.142
1388.96	24.4316
1389.95	19.236
1390.93	15.0732
1391.92	11.9436
1392.9	15.097
1393.89	13.9978
1394.87	13.9845
1395.85	15.0574
1396.84	12.9762
1397.82	12.9789
1398.8	11.9466
1399.78	12.96
1400.77	10.9099
1401.75	14.0232
1402.73	12.9702
1403.71	11.9438
1404.69	15.0564
1405.67	14.0119
1406.65	12.9845
1407.63	15.0576
1408.61	23.3517
1409.59	19.2455
1410.57	14.026
1411.55	20.2783
1412.53	14.0327
1413.51	11.9606
1414.49	15.0736
1415.47	11.9774
1416.44	11.9915
1417.42	16.1595
1418.4	14.1122
1419.38	11.9978
1420.35	13.0291
1421.33	14.0969
1422.31	12.0377
1423.28	13.0877
1424.26	14.1409
1425.24	14.1193
1426.21	12.0498
1427.19	14.1546
1428.16	12.0473
1429.14	13.0685
1430.11	13.1229
1431.08	9.97484
1432.06	12.0817
1433.03	13.114
1434.01	15.209
1434.98	11.0164
1435.95	13.1445
1436.92	12.1049
1437.9	14.2211
1438.87	11.0379
1439.84	16.3163
1440.81	13.1542
1441.78	11.0751
1442.76	12.142
1443.73	14.2485
1444.7	11.077
1445.67	12.1168
1446.64	14.2274
1447.61	14.2462
1448.58	12.1469
1449.55	14.2702
1450.52	11.0867
1451.48	12.1865
1452.45	13.19
1453.42	13.0636
1454.39	12.976
1455.36	12.4596
1456.32	10.3848
1457.29	10.0865
1458.26	12.0939
1459.23	13.1399
1460.19	11.7535
1461.16	12.8131
1462.13	12.5611
1463.09	11.0602
1464.06	11.1774
1465.02	9.98534
1465.99	11.1941
1466.95	12.2055
1467.93	13.2329
1468.91	12.2061
1469.89	12.1891
1470.87	12.1801
1471.85	10.0675
1472.83	13.2492
1473.81	12.1901
1474.79	13.2476
1475.76	11.1165
1476.74	13.2479
1477.72	11.1258
1478.7	19.6088
1479.68	12.2073
1480.65	13.2737
1481.63	13.2422
1482.61	13.1903
1483.58	11.1309
1484.56	13.2659
1485.54	11.1161
1486.51	14.3069
1487.49	13.2397
1488.46	12.1745
1489.44	12.1634
1490.41	14.335
1491.39	12.2136
1492.36	11.1778
1493.34	13.2839
1494.31	13.2836
1495.28	13.2635
1496.26	11.1651
1497.23	10.1023
1498.2	13.2832
1499.18	13.296
1500.15	14.3573
1501.12	15.4179
1502.09	12.24
1503.06	13.3097
1504.04	12.27
1505.01	13.344
1505.98	11.2349
1506.95	11.2178
1507.92	10.1245
1508.89	13.3721
1509.86	13.3503
1510.83	14.4466
1511.8	14.4625
1512.77	11.2271
1513.74	12.2875
1514.7	11.2457
1515.67	12.3304
1516.64	11.2476
1517.61	14.5035
1518.58	11.298
1519.55	13.4051
1520.51	13.4575
1521.48	10.2318
1522.45	11.2931
1523.41	12.3753
1524.38	12.3862
1525.35	12.4014
1526.31	12.3894
1527.28	13.4729
1528.24	12.4167
1529.21	14.6133
1530.17	13.4699
1531.14	13.5308
1532.1	12.4142
1533.07	13.5363
1534.03	13.5705
1534.99	12.4759
1535.96	13.5688
1536.92	12.46
1537.88	12.4603
1538.84	11.4043
1539.81	14.6519
1540.77	11.4183
1541.73	11.4377
1542.69	12.5242
1543.65	13.625
1544.62	12.5015
1545.58	10.35
1546.54	10.36
1547.5	12.5527
1548.46	12.5451
1549.42	13.6415
1550.38	12.5541
1551.34	11.4543
1552.3	12.5593
1553.25	12.5404
1554.21	13.6738
1555.17	10.3836
1556.13	15.864
1557.09	11.5124
1558.05	10.3966
1559	13.6864
1559.96	13.6745
1560.92	13.6644
1561.88	11.4645
1562.83	11.4917
1563.79	12.6052
1564.74	10.392
1565.7	12.5706
1566.66	8.20392
1567.61	11.4817
1568.57	10.3958
1569.52	12.5997
1570.48	11.4589
1571.43	11.4585
1572.38	13.6933
1573.34	12.5831
1574.29	12.6147
1575.24	12.5992
1576.2	10.3887
1577.15	11.481
1578.1	13.6683
1579.06	12.6057
1580.01	11.5151
1580.96	14.7554
1581.91	12.57
1582.86	11.5062
1583.81	13.6975
1584.77	14.8055
1585.72	11.4883
1586.67	11.5001
1587.62	13.6873
1588.57	11.4971
1589.52	13.724
1590.47	12.5938
1591.42	11.4892
1592.36	12.5911
1593.31	13.6933
1594.26	13.6909
1595.21	12.6006
1596.16	9.29651
1597.11	13.6867
1598.05	11.4992
1599	10.4197
1599.95	10.4293
1600.9	12.604
1601.84	11.5245
1602.79	12.5938
1603.73	11.5162
1604.68	11.5156
1605.63	12.6196
1606.57	11.5112
1607.52	11.5061
1608.46	12.6104
1609.41	10.4534
1610.35	10.4341
1611.3	12.6447
1612.24	12.6894
1613.18	12.6752
1614.13	11.5759
1615.07	12.6894
1616.01	12.6841
1616.96	12.7289
1617.9	11.5987
1618.84	11.596
1619.78	13.8312
1620.72	13.8396
1621.67	11.621
1622.61	14.9798
1623.55	10.5268
1624.49	13.8719
1625.43	11.6677
1626.37	12.7979
1627.31	15.0403
1628.25	15.0135
1629.19	13.9027
1630.13	10.5684
1631.07	10.597
1632.01	12.8769
1632.95	11.7249
1633.88	11.7557
1634.82	12.8714
1635.76	11.7645
1636.7	14.0479
1637.64	14.0511
1638.57	9.57012
1639.51	12.9196
1640.45	11.7974
1641.38	10.6725
1642.32	11.8354
1643.25	12.9614
1644.19	12.9317
1645.13	12.9402
1646.06	12.9769
1647	12.9817
1647.93	14.108
1648.87	14.0701
1649.8	10.7099
1650.73	13.0027
1651.67	11.8804
1652.6	12.9668
1653.53	14.1104
1654.47	10.7218
1655.4	13.0011
1656.33	10.7145
1657.27	15.2355
1658.2	9.61617
1659.13	11.8508
1660.06	14.1393
1660.99	13.0233
1661.92	14.1768
1662.85	11.8926
1663.79	13.0167
1664.72	11.8846
1665.65	10.7757
1666.58	14.1232
1667.51	13.0186
1668.44	14.1502
1669.36	14.1797
1670.29	13.0355
1671.22	13.0612
1672.15	14.1565
1673.08	10.7624
1674.01	14.1706
1674.94	13.0563
1675.86	14.2092
1676.79	11.9011
1677.72	13.0063
1678.64	14.1388
1679.57	15.2884
1680.5	11.9093
1681.42	14.1325
1682.35	18.6279
1683.28	13.0245
1684.2	11.8924
1685.13	13.0239
1686.05	13.0365
1686.98	13.0316
1687.9	9.62577
1688.82	13.0147
1689.75	14.1849
1690.67	14.1583
1691.6	11.9455
1692.52	13.1138
1693.44	12.8099
1694.36	13.0901
1695.29	15.0651
1696.21	12.0567
1697.13	13.2043
1698.05	13.5434
1698.98	11.3112
1699.9	12.5062
1700.82	13.3796
1701.74	13.3257
1702.66	12.5896
1703.58	11.8721
1704.5	13.2304
1705.42	12.7429
1706.32	13.0587
1707.25	13.0382
1708.19	11.8894
1709.12	13.0468
1710.06	13.0472
1710.99	13.0439
1711.93	14.1831
1712.86	11.9008
1713.79	13.085
1714.73	11.9256
1715.66	10.8082
1716.59	17.6116
1717.52	13.0585
1718.46	11.9411
1719.39	13.0876
1720.32	15.3159
1721.25	13.0965
1722.18	13.1089
1723.11	14.2638
1724.04	13.0941
1724.98	10.8308
1725.91	14.261
1726.84	17.6518
1727.77	11.9855
1728.7	14.261
1729.62	9.70237
1730.55	11.9899
1731.48	12.0024
1732.41	14.2984
1733.34	12.0104
1734.27	10.8553
1735.2	10.8621
1736.12	14.3141
1737.05	12.0524
1737.98	14.327
1738.91	13.1909
1739.83	13.2156
1740.76	12.0796
1741.69	14.3836
1742.61	13.1968
1743.54	13.1647
1744.46	13.2292
1745.39	14.3822
1746.32	12.0679
1747.24	13.227
1748.17	12.0643
1749.09	12.069
1750.01	12.1284
1750.94	13.2836
1751.86	13.2599
1752.79	14.4097
1753.71	9.79273
1754.63	12.1248
1755.56	13.2883
1756.48	13.2788
1757.4	12.1301
1758.32	10.9689
1759.24	14.4253
1760.17	12.1301
1761.09	15.5989
1762.01	14.4422
1762.93	13.2921
1763.85	13.3099
1764.77	12.1659
1765.69	13.3249
1766.61	10.9801
1767.53	12.1465
1768.45	13.3522
1769.37	12.1793
1770.29	12.175
1771.21	12.1469
1772.13	14.48
1773.05	12.1455
1773.97	12.1847
1774.88	14.48
1775.8	14.4893
1776.72	15.6683
1777.64	13.3373
1778.55	14.4961
1779.47	14.4918
1780.39	12.1966
1781.3	14.5416
1782.22	13.3839
1783.13	13.3526
1784.05	11.0047
1784.97	9.87475
1785.88	14.5805
1786.8	13.3829
1787.71	11.0488
1788.63	13.3472
1789.54	13.3812
1790.45	14.5589
1791.37	13.3991
1792.28	11.0839
1793.19	8.73379
1794.11	13.3974
1795.02	13.4074
1795.93	9.90668
1796.85	12.2511
1797.76	13.3903
1798.67	13.3767
1799.58	12.2301
1800.49	13.4034
1801.41	11.0957
1802.32	15.7634
1803.23	9.94132
1804.14	12.2765
1805.05	9.93986
1805.96	12.2853
1806.87	13.4506
1807.78	12.2669
1808.69	11.1318
1809.6	11.14
1810.51	12.3237
1811.41	13.4925
1812.32	13.5061
1813.23	14.7148
1814.14	12.351
1815.05	14.6819
1815.95	14.713
1816.86	13.5511
1817.77	13.5383
1818.68	14.6921
1819.58	14.7043
1820.49	14.7557
1821.4	12.3858
1822.3	11.2306
1823.21	12.3851
1824.11	15.9093
1825.02	13.6006
1825.92	13.6231
1826.83	13.6384
1827.73	12.4271
1828.64	14.8249
1829.54	12.4534
1830.45	13.6481
1831.35	13.6391
1832.25	13.658
1833.16	13.6765
1834.06	14.8837
1834.96	14.8652
1835.86	16.0291
1836.77	14.8635
1837.67	12.5289
1838.57	13.7335
1839.47	13.7288
1840.37	14.9076
1841.28	12.5286
1842.18	13.7541
1843.08	13.7206
1843.98	13.7483
1844.88	14.9473
1845.78	12.583
1846.68	11.3819
1847.58	11.4011
1848.48	13.7703
1849.38	12.6164
1850.27	11.4289
1851.17	12.6181
1852.07	13.8546
1852.97	15.0332
1853.87	15.0635
1854.77	12.6522
1855.66	13.8663
1856.56	13.8819
1857.46	12.6543
1858.35	13.8907
1859.25	13.873
1860.15	17.5006
1861.04	15.1133
1861.94	13.9368
1862.83	11.5096
1863.73	11.471
1864.63	15.0866
1865.52	13.9281
1866.41	13.8995
1867.31	16.3426
1868.2	15.0923
1869.1	15.0653
1869.99	11.5131
1870.89	10.2894
1871.78	15.1468
1872.67	13.9105
1873.56	15.131
1874.46	11.5219
1875.35	16.3597
1876.24	13.9028
1877.13	12.7026
1878.03	13.9825
1878.92	13.9469
1879.81	15.1265
1880.7	12.7249
1881.59	13.967
1882.48	13.9305
1883.37	13.9444
1884.26	10.3785
1885.15	12.76
1886.04	14.0449
1886.93	15.229
1887.82	11.5814
1888.71	14.0026
1889.6	11.674
1890.49	14.0257
1891.38	15.2133
1892.26	13.9803
1893.15	15.2255
1894.04	14.0036
1894.93	15.2273
1895.81	12.8103
1896.7	14.034
1897.59	10.4193
1898.47	14.0113
1899.36	12.7993
1900.25	15.2599
1901.13	14.0551
1902.02	12.8452
1902.9	11.5603
1903.79	12.834
1904.67	15.31
1905.56	12.8419
1906.44	12.8017
1907.33	14.0495
1908.21	14.0757
1909.09	11.6593
1909.98	15.3192
1910.86	16.5309
1911.74	15.3239
1912.63	15.3771
1913.51	14.1373
1914.39	12.8861
1915.27	14.1136
1916.16	15.4373
1917.04	12.8956
1917.92	11.6364
1918.8	12.9288
1919.68	13.0677
1920.56	13.9126
1921.44	13.9308
1922.32	13.1695
1923.2	14.2003
1924.08	13.3597
1924.96	13.2651
1925.84	14.2884
1926.72	13.4384
1927.6	13.2315
1928.48	13.3771
1929.36	12.0271
1930.24	12.144
1931.12	11.0613
1931.99	12.399
1932.87	11.9169
1933.75	11.7674
1934.64	14.2824
1935.54	15.5116
1936.43	14.2754
1937.32	15.4622
1938.21	14.2697
1939.1	13.0478
1939.99	15.5272
1940.89	11.7788
1941.78	9.34039
1942.67	14.3115
1943.56	11.8126
1944.45	13.0527
1945.34	11.8259
1946.23	13.0963
1947.12	13.0757
1948	14.3077
1948.89	11.8305
1949.78	13.105
1950.67	15.586
1951.56	10.5863
1952.45	9.34972
1953.33	13.0935
1954.22	15.6235
1955.11	15.5709
1956	13.0884
1956.88	11.8682
1957.77	15.6391
1958.66	13.124
1959.54	14.371
1960.43	14.3741
1961.31	15.5979
1962.2	11.8731
1963.09	11.8555
1963.97	13.1355
1964.86	13.1617
1965.74	14.3786
1966.63	13.1261
1967.51	10.6527
1968.39	13.1497
1969.28	13.1387
1970.16	13.117
1971.04	13.1279
1971.93	14.3762
1972.81	13.1641
1973.69	11.8702
1974.58	14.3639
1975.46	15.647
1976.34	13.1673
1977.22	14.4291
1978.1	11.8777
1978.98	15.6412
1979.87	13.2032
1980.75	10.6932
1981.63	14.3463
1982.51	14.3842
1983.39	13.162
1984.27	15.6215
1985.15	11.8672
1986.03	11.865
1986.91	14.407
1987.79	14.4001
1988.67	10.6024
1989.54	13.1145
1990.42	11.9035
1991.3	16.863
1992.18	9.41515
1993.06	13.1258
1993.93	9.38983
1994.81	13.1318
1995.69	13.1226
1996.57	13.1174
1997.44	13.1544
1998.32	14.3859
1999.2	13.1232
2000.07	11.8414
2000.95	15.656
2001.82	14.3932
2002.7	14.3515
2003.57	14.3668
2004.45	14.3913
2005.32	13.095
2006.2	14.3553
2007.07	13.0911
2007.95	10.6049
2008.82	14.3584
2009.69	10.5979
2010.57	13.0945
2011.44	11.8799
2012.31	13.1087
2013.19	10.5994
2014.06	14.4105
2014.93	11.9062
2015.8	14.4138
2016.68	13.1344
2017.55	13.1048
2018.42	13.1348
2019.29	14.3517
2020.16	11.883
2021.03	10.6271
2021.9	11.8887
2022.77	10.6461
2023.64	13.1543
2024.51	15.6739
2025.38	11.9001
2026.25	10.6447
2027.12	13.1737
2027.99	13.1308
2028.86	14.4397
2029.73	13.1725
2030.6	13.1702
2031.46	13.1704
2032.33	11.9219
2033.2	15.7284
2034.07	13.1879
2034.93	14.4359
2035.8	16.968
2036.67	13.1801
2037.53	14.4771
2038.4	13.233
2039.27	14.5048
2040.13	14.4597
2041	9.44518
2041.86	14.4759
2042.73	14.4606
2043.59	13.2477
2044.46	14.4639
2045.32	14.4758
2046.19	13.2029
2047.05	12.0087
2047.92	13.2376
2048.78	13.2523
2049.64	12.0061
2050.51	15.7942
2051.37	14.5248
2052.23	14.5485
2053.1	10.7881
2053.96	13.2485
2054.82	13.2633
2055.68	13.2782
2056.54	10.7804
2057.41	13.2797
2058.27	14.5902
2059.13	13.3013
2059.99	14.5841
2060.85	14.6172
2061.71	13.3835
2062.57	14.6649
2063.43	13.2824
2064.29	12.0529
2065.15	14.615
2066.01	13.329
2066.87	13.3459
2067.73	14.5975
2068.59	13.3399
2069.44	8.26935
2070.3	12.0961
2071.16	13.3742
2072.02	17.1797
2072.88	13.3766
2073.73	15.9234
2074.59	15.9422
2075.45	13.4086
2076.3	10.8652
2077.16	12.1091
2078.02	14.676
2078.87	14.7244
2079.73	8.32419
2080.58	14.7517
2081.44	14.7196
2082.29	14.7136
2083.15	13.4209
2084	14.7273
2084.86	9.60834
2085.71	13.5055
2086.57	13.4735
2087.42	14.7698
2088.28	12.2086
2089.13	14.7867
2089.98	14.7498
2090.84	14.7831
2091.69	13.4932
2092.54	12.2228
2093.39	13.5232
2094.24	16.0894
2095.1	12.2669
2095.95	16.1196
2096.8	14.8446
2097.65	16.1382
2098.5	13.6022
2099.35	13.5734
2100.2	13.5686
2101.05	9.70542
2101.9	13.5395
2102.75	12.2879
2103.6	14.8759
2104.45	10.9818
2105.3	12.2996
2106.15	13.56
2107	14.9008
2107.85	13.658
2108.7	13.6344
2109.55	12.3226
2110.39	14.993
2111.24	13.6686
2112.09	13.7126
2112.94	13.6508
2113.78	16.2621
2114.63	16.2545
2115.48	13.6564
2116.32	12.3501
2117.17	15.0011
2118.02	16.3301
2118.86	17.6083
2119.71	12.3904
2120.55	16.3726
2121.4	17.6553
2122.24	16.3616
2123.09	15.0624
2123.93	12.4445
2124.78	11.1415
2125.62	15.0734
2126.46	15.1103
2127.31	13.7895
2128.15	15.0352
2129	13.786
2129.84	13.8078
2130.68	11.1668
2131.52	12.4903
2132.37	15.1224
2133.21	17.7955
2134.05	15.1008
2134.89	11.1845
2135.73	12.5038
2136.57	13.8724
2137.41	12.5036
2138.26	16.3223
2139.1	15.0738
2139.94	14.8925
2140.78	16.0659
2141.62	15.0631
2142.46	14.9405
2143.3	13.749
2144.14	15.132
2144.97	14.7122
2145.81	14.7268
2146.65	15.197
2147.49	15.5344
2148.33	13.0445
2149.17	15.6083
2150	13.6154
2150.77	15.2736
2151.62	11.2921
2152.48	16.5671
2153.33	13.9593
2154.18	13.9628
2155.03	12.6358
2155.88	16.5934
2156.74	16.6479
2157.59	12.661
2158.44	15.2802
2159.29	11.3155
2160.14	15.3178
2160.99	16.7007
2161.84	20.6375
2162.69	15.2967
2163.54	15.3176
2164.39	12.675
2165.24	19.3345
2166.08	14.0036
2166.93	11.3298
2167.78	15.3179
2168.63	13.9826
2169.48	15.3625
2170.33	16.6901
2171.17	12.6433
2172.02	16.6719
2172.87	16.7233
2173.71	15.3609
2174.56	15.3552
2175.41	12.6588
2176.25	14.0116
2177.1	13.99
2177.95	15.3017
2178.79	14.0279
2179.64	14.0071
2180.48	15.3518
2181.33	11.3158
2182.17	15.3312
2183.02	12.6687
2183.86	14.0426
2184.71	12.6314
2185.55	15.3247
2186.39	15.3614
2187.24	12.6788
2188.08	12.668
2188.92	15.3255
2189.77	12.6713
2190.61	12.6765
2191.45	12.6811
2192.29	15.3366
2193.13	15.3901
2193.98	14.0355
2194.82	14.0264
2195.66	14.0291
2196.5	15.3219
2197.34	15.3645
2198.18	12.6848
2199.02	12.7018
2199.86	15.3253
2200.7	16.6944
2201.54	14.0552
2202.38	12.6912
2203.22	14.0107
2204.06	14.0418
2204.9	12.6686
2205.74	14.0517
2206.58	14.0362
2207.42	12.7103
2208.26	12.7134
2209.09	14.0377
2209.93	16.7417
2210.77	14.0756
2211.61	16.7592
2212.44	16.7051
2213.28	14.0527
2214.12	16.7633
2214.96	14.1272
2215.79	14.1019
2216.63	14.1203
2217.46	12.7405
2218.3	16.7793
2219.13	15.458
2219.97	12.7648
2220.8	11.4345
2221.64	15.4633
2222.47	12.8084
2223.31	16.8687
2224.14	15.4553
2224.98	14.1821
2225.81	14.1814
2226.65	15.5428
2227.48	14.1783
2228.31	16.9005
2229.14	16.9062
2229.98	15.5307
2230.81	14.1983
2231.64	15.5739
2232.47	15.5717
2233.31	14.2082
2234.14	15.5762
2234.97	12.8819
2235.8	12.8749
2236.63	14.2409
2237.46	12.926
2238.29	15.6876
2239.12	15.6528
2239.95	15.6348
2240.78	15.6663
2241.61	14.3202
2242.44	15.6664
2243.27	14.3422
2244.1	15.7243
2244.93	14.3502
2245.76	14.3565
2246.59	12.9992
2247.42	17.0859
2248.25	14.3656
2249.07	14.4053
2249.9	19.9124
2250.73	13.0065
2251.56	14.3943
2252.38	15.7954
2253.21	14.4302
2254.04	15.7525
2254.86	17.1797
2255.69	13.1118
2256.52	14.4272
2257.34	17.2461
2258.17	15.8745
2258.99	19.9638
2259.82	13.0998
2260.64	14.4949
2261.47	14.5013
2262.29	15.8597
2263.12	14.5073
2263.94	13.1293
2264.76	13.1222
2265.59	15.9026
2266.41	14.5215
2267.24	14.5317
2268.06	14.4968
2268.88	18.7432
2269.7	15.9423
2270.53	13.1701
2271.35	15.9584
2272.17	16.0347
2272.99	14.5793
2273.81	15.9552
2274.64	15.9911
2275.46	16.0331
2276.28	17.3635
2277.1	13.204
2277.92	13.2329
2278.74	11.8308
2279.56	15.9653
2280.38	17.4054
2281.2	13.2282
2282.02	13.2448
2282.84	17.4107
2283.66	20.2245
2284.48	14.6281
2285.3	15.9948
2286.11	17.4682
2286.93	14.6425
2287.75	14.5877
2288.57	14.6153
2289.39	11.8579
2290.2	13.2163
2291.02	14.6066
2291.84	14.6799
2292.65	13.2402
2293.47	14.5948
2294.29	16.0251
2295.1	16.099
2295.92	14.6866
2296.74	16.0226
2297.55	13.2932
2298.37	16.0229
2299.18	16.0804
2300	18.8654
2300.81	14.6529
2301.63	14.6172
2302.44	14.6814
2303.25	14.6625
2304.07	16.0382
2304.88	17.4282
2305.7	17.5114
2306.51	16.0714
2307.32	16.0823
2308.14	14.7117
2308.95	14.6922
2309.76	14.688
2310.57	17.5007
2311.39	11.8924
2312.2	16.0946
2313.01	14.6737
2313.82	14.7117
2314.63	13.3235
2315.44	16.1116
2316.25	14.7011
2317.06	14.7509
2317.87	14.7544
2318.68	14.7218
2319.49	13.348
2320.3	17.544
2321.11	16.1427
2321.92	17.5397
2322.73	13.3581
2323.54	17.559
2324.35	16.1881
2325.16	16.1931
2325.97	14.7873
2326.77	17.6315
2327.58	18.9925
2328.39	23.2297
2329.2	16.1802
2330.01	17.5965
2330.81	16.1876
2331.62	14.8132
2332.43	16.2124
2333.23	14.8148
2334.04	12.0163
2334.84	13.456
2335.65	14.8586
2336.46	14.8796
2337.26	14.8468
2338.07	13.4972
2338.87	16.3148
2339.68	13.4594
2340.48	16.3703
2341.29	14.9306
2342.09	14.9105
2342.89	20.6181
2343.7	16.3759
2344.5	16.3793
2345.3	16.3528
2346.11	15.0123
2346.91	17.8482
2347.71	13.528
2348.52	16.4454
2349.32	13.5874
2350.12	14.9824
2350.92	14.9915
2351.72	16.4827
2352.52	17.8749
2353.33	16.4595
2354.13	13.6323
2354.93	13.6027