File: Data/3-Raman/raw/bu04w-a-ff3-fi02-l_150 (500nm)_633nm_edge_100%_x100_vis_lwd_h50um_45sx2_01.txt
#Acq. time (s)=	45
#Accumulations=	2
#Range (cm-¹)=	100...4000
#Windows=	1
#Auto scanning=	Off
#Autofocus=	Off
#Macrospot=	Off
#AutoExposure=	Off
#Spike filter=	Multiple accum.
#Delay time (s)=	2
#Binning=	1
#Readout mode=	Signal
#DeNoise=	Off
#ICS correction=	On
#Dark correction=	Off
#Inst. Process=	Off
#Detector Gain=	Best Dynamic
#Detector ADC=	50 kHz HS
#Detector temperature (°C)=	-60.09
#Instrument=	LabRAM HR Evol
#Detector=	SIN-EM FIVIS
#Objective=	x100_VIS_LWD
#Grating=	150 (500nm)
#ND Filter=	100%
#Laser=	633nm_Edge
#Hole=	49.98
#Temperature=	0
#Range=	Visible
#StageXY=	75x50mm Scan+
#StageZ=	Z motor
#X (µm)=	0
#Y (µm)=	0
#Z (µm)=	4
#Full time(mm:ss)=	1:34
#Project=	21_11_22
#Sample=	BU04w
#Site=
#Title=	BU04w-A-FF3-FI02-L_150 (500nm)_633nm_Edge_100%_x100_VIS_LWD_H50um_45sX2
#Remark=
#Date=	22.11.2021 10:46
#Acquired=	22.11.2021 10:46:02
100.177	1043.21
106.695	952.472
113.209	897.105
119.717	835.686
126.219	806.612
132.716	785.031
139.208	753.546
145.694	731.665
152.175	668.67
158.651	649.88
165.121	757.62
171.586	642.804
178.045	538.177
184.5	508.026
190.947	474.758
197.39	416.766
203.829	403.236
210.262	390.685
216.688	378.14
223.11	373.182
229.527	405.071
235.939	528.242
242.344	472.65
248.745	358.553
255.141	329.835
261.53	341.071
267.916	303.976
274.294	296.364
280.669	292.543
287.038	308.532
293.402	292.186
299.76	250.306
306.114	269.917
312.461	285.732
318.805	347.79
325.142	570.346
331.475	679.647
337.802	462.584
344.123	323.871
350.441	274.711
356.752	282.966
363.058	282.689
369.36	275.82
375.656	286.79
381.947	245.236
388.232	237.73
394.512	247.38
400.789	252.617
407.059	262.573
413.324	270.619
419.584	291.802
425.839	359.977
432.089	398.84
438.333	432.732
444.573	359.312
450.807	330.156
457.037	333.958
463.261	320.317
469.48	278.1
475.695	241.719
481.904	238.978
488.108	249.25
494.307	245.584
500.502	268.012
506.691	279.343
512.874	301.935
519.053	316.27
525.227	304.655
531.396	286.603
537.559	271.408
543.718	245.574
549.873	247.697
556.022	235.624
562.165	220.327
568.304	208.618
574.437	192.064
580.567	207.345
586.691	197.473
592.81	212.072
598.924	239.891
605.033	241.123
611.138	220.062
617.236	208.458
623.332	223.196
629.42	204.984
635.506	208.938
641.585	193.699
647.659	193.359
653.73	196.713
659.794	221.471
665.854	218.093
671.91	173.875
677.96	181.383
684.005	164.66
690.045	154.629
696.082	160.599
702.113	155.313
708.139	162.164
714.16	156.509
720.176	150.774
726.187	146.899
732.194	156.947
738.196	140.762
744.193	138.66
750.185	145.015
756.173	135.616
762.155	133.918
768.133	144.569
774.107	141.235
780.075	128.397
786.039	135.182
791.998	127.772
797.952	132.52
803.902	126.774
809.845	131.336
815.786	138.607
821.721	129.85
827.652	128.589
833.576	128.453
839.498	141.626
845.415	138.144
851.327	118.727
857.233	136.901
863.135	139.164
869.032	146.17
874.925	159.706
880.813	147.52
886.697	153.258
892.576	146.558
898.45	153.973
904.318	153.612
910.184	144.729
916.044	150.002
921.9	147.942
927.75	154.529
933.596	171.662
939.439	202.374
945.275	250.465
951.107	287.609
956.936	310.588
962.759	299.021
968.577	263.198
974.391	261.585
980.201	294.102
986.006	380.889
991.806	427.108
997.602	378.606
1003.39	317.079
1009.18	315.017
1014.96	306.739
1020.74	372.945
1026.51	437.868
1032.28	359.346
1038.04	259.38
1043.8	213.838
1049.56	186.374
1055.31	177.054
1061.05	161.728
1066.8	138.409
1072.53	154.877
1078.26	164.472
1083.99	188.55
1089.72	202.949
1095.44	282.215
1101.15	358.456
1106.86	288.906
1112.56	209.713
1118.27	166.69
1123.96	151.511
1129.65	157.733
1135.34	157.152
1141.03	178.159
1146.7	218.767
1152.38	305.691
1158.05	407.081
1163.71	232.485
1169.37	162.391
1175.03	144.443
1180.68	120.71
1186.33	116.7
1191.98	108.903
1197.61	115.891
1203.25	110.326
1208.88	109.739
1214.51	99.3041
1220.13	102.74
1225.74	105.233
1231.36	110.72
1236.97	112.142
1242.57	107.396
1248.17	105.531
1253.77	108.62
1259.36	117.641
1264.94	109.407
1270.53	129.382
1276.11	119.063
1281.68	111.779
1287.25	109.585
1292.81	109.46
1298.38	105.43
1303.93	94.4762
1309.48	94.6389
1315.03	100.958
1320.58	98.2744
1326.12	98.6543
1331.65	96.0069
1337.18	87.1688
1342.71	98.66
1348.23	98.8621
1353.75	105.192
1359.26	110.447
1364.77	113.572
1370.28	119.707
1375.78	173.075
1381.28	207.91
1386.77	137.001
1392.26	111.323
1397.74	103.229
1403.23	99.2546
1408.7	87.056
1414.17	93.4224
1419.64	92.5996
1425.11	81.422
1430.56	88.9126
1436.02	95.3932
1441.47	84.1253
1446.92	85.3843
1452.36	88.6569
1457.8	89.7717
1463.23	87.6814
1468.66	87.6576
1474.09	88.689
1479.51	87.6646
1484.93	87.7121
1490.34	86.7522
1495.75	93.2123
1501.16	94.4498
1506.56	88.3194
1511.96	90.6821
1517.35	90.966
1522.74	85.9339
1528.13	99.0885
1533.51	98.3903
1538.88	82.515
1544.25	100.005
1549.62	94.656
1554.99	92.4195
1560.35	91.2266
1565.71	91.1375
1571.06	93.1948
1576.41	97.4188
1581.75	98.4957
1587.09	93.1399
1592.43	102.898
1597.76	105.179
1603.09	99.9449
1608.41	109.917
1613.73	107.003
1619.05	112.859
1624.36	110.008
1629.67	117.013
1634.97	112.991
1640.27	107.665
1645.57	111.154
1650.86	111.295
1656.15	113.61
1661.43	109.218
1666.71	101.474
1671.99	102.588
1677.26	100.354
1682.53	101.428
1687.79	98.0126
1693.05	94.6391
1698.31	92.4677
1703.56	87.2738
1708.81	91.0103
1714.06	94.2125
1719.3	87.7705
1724.53	85.6641
1729.77	93.6986
1735	89.3927
1740.22	82.8047
1745.44	82.9629
1750.66	90.9961
1755.87	89.965
1761.08	85.476
1766.29	84.3769
1771.49	88.9594
1776.69	77.6899
1781.88	77.7991
1787.07	81.3463
1792.26	84.9487
1797.44	78.2908
1802.62	87.6747
1807.79	87.9092
1812.96	83.4916
1818.13	77.9046
1823.29	93.1095
1828.45	82.889
1833.61	81.9265
1838.76	82.1207
1843.91	89.2736
1849.05	85.9134
1854.19	79.0026
1859.33	82.6496
1864.46	76.9379
1869.59	81.8065
1874.71	79.5659
1879.83	82.0256
1884.95	82.1138
1890.06	77.4353
1895.17	85.7147
1900.28	82.2099
1905.38	84.7263
1910.48	77.7967
1915.57	88.7803
1920.66	84.1507
1925.75	83.112
1930.83	94.0574
1935.91	85.8236
1940.99	85.9498
1946.06	83.6404
1951.13	88.5257
1956.19	81.3337
1961.26	97.0218
1966.31	89.7949
1971.36	88.5499
1976.41	80.0713
1981.46	88.4494
1986.5	82.3906
1991.54	85.9672
1996.58	87.1516
2001.61	94.3711
2006.63	84.7909
2011.66	90.8725
2016.68	94.5598
2021.69	89.7925
2026.71	82.657
2031.72	88.831
2036.72	90.2128
2041.72	83.1117
2046.72	96.6642
2051.71	92.0027
2056.71	89.7125
2061.69	86.2428
2066.68	82.7614
2071.66	90.308
2076.63	92.9578
2081.6	89.4324
2086.57	92.039
2091.54	92.1736
2096.5	88.6516
2101.46	91.3455
2106.41	92.8285
2111.36	90.5934
2116.31	90.8752
2121.25	87.3841
2126.19	93.9473
2131.13	92.94
2136.06	93.1676
2140.99	95.9162
2145.92	92.294
2150.84	96.264
2155.76	88.7218
2160.67	86.2455
2165.58	92.6791
2170.49	88.8726
2175.39	81.2633
2180.29	92.8145
2185.19	94.0833
2190.08	92.8179
2194.98	82.6204
2199.86	86.5573
2204.74	81.5529
2209.62	86.8561
2214.5	88.336
2219.37	88.5569
2224.24	86.1909
2229.11	90.3085
2233.97	93.1436
2238.83	90.767
2243.68	87.0682
2248.53	84.6671
2253.38	88.8244
2258.22	94.3291
2263.06	78.6904
2267.9	88.1223
2272.73	92.2415
2277.56	85.7096
2282.39	91.0967
2287.21	87.1321
2292.03	84.4949
2296.85	89.8455
2301.66	95.2473
2306.47	91.3769
2311.28	98.2353
2316.08	87.7425
2320.88	75.88
2325.68	77.4234
2330.47	85.7376
2335.26	92.7714
2340.04	88.9879
2344.82	92.0193
2349.6	90.9875
2354.38	87.1729
2359.15	86.0336
2363.92	82.0618
2368.68	90.5344
2373.44	90.7196
2378.2	88.1253
2382.95	86.8597
2387.71	89.7204
2392.45	81.4142
2397.2	77.2495
2401.94	86.9938
2406.68	84.1908
2411.41	82.8832
2416.14	90.1357
2420.87	86.3674
2425.59	85.0841
2430.31	85.2957
2435.03	86.95
2439.75	90.0522
2444.46	87.4749
2449.16	82.0319
2453.87	92.2902
2458.57	91.1248
2463.27	84.1935
2467.96	87.3121
2472.65	88.9817
2477.34	93.5676
2482.02	80.7164
2486.7	89.6392
2491.38	82.5204
2496.05	106.112
2500.72	93.1208
2505.39	93.287
2510.06	89.018
2514.72	86.1873
2519.37	90.7314
2524.03	87.9239
2528.68	93.9756
2533.33	79.3069
2537.97	86.8856
2542.61	94.5045
2547.25	82.7802
2551.88	87.4465
2556.51	87.6214
2561.14	84.7929
2565.77	84.9926
2570.39	86.7198
2575.01	86.9439
2579.62	87.1395
2584.23	91.8359
2588.84	82.8262
2593.45	82.8909
2598.05	83.0206
2602.65	90.7608
2607.24	92.3945
2611.84	86.3629
2616.42	89.4906
2621.01	83.4465
2625.59	78.9345
2630.17	83.6533
2634.75	91.5332
2639.32	91.8141
2643.89	98.2942
2648.46	87.7404
2653.02	95.8036
2657.58	88.1841
2662.14	93.0155
2666.69	91.563
2671.24	87.0219
2675.79	87.2702
2680.33	90.8613
2684.88	88.0993
2689.41	91.6847
2693.95	87.2288
2698.48	93.7787
2703.01	85.9483
2707.53	103.817
2712.06	102.383
2716.57	94.5306
2721.09	89.8528
2725.6	85.1273
2730.11	93.3459
2734.62	88.5481
2739.12	91.8547
2743.62	88.7087
2748.12	93.7345
2752.61	92.3601
2757.1	90.9299
2761.59	95.9855
2766.08	91.2354
2770.56	91.4057
2775.04	93.2604
2779.51	86.8948
2783.98	87.1908
2788.45	85.8193
2792.92	97.7941
2797.38	88.0117
2801.84	86.5524
2806.3	85.0524
2810.75	91.9641
2815.2	105.632
2819.65	92.2504
2824.09	94.0982
2828.53	92.5557
2832.97	94.3951
2837.41	91.1199
2841.84	94.6631
2846.27	98.2392
2850.69	98.4255
2855.12	100.378
2859.54	85.1466
2863.95	100.914
2868.37	104.695
2872.78	101.545
2877.18	101.865
2881.59	100.462
2885.99	92.0584
2890.39	101.173
2894.78	99.7423
2899.18	93.0315
2903.57	104.013
2907.95	98.9775
2912.34	101.02
2916.72	103.033
2921.09	101.492
2925.47	90.9536
2929.84	102.057
2934.21	111.399
2938.57	106.193
2942.94	110.028
2947.29	102.907
2951.65	115.826
2956	101.378
2960.36	112.496
2964.7	114.502
2969.05	105.529
2973.39	109.404
2977.73	113.294
2982.06	109.828
2986.4	119.347
2990.73	119.668
2995.05	121.866
2999.38	107.311
3003.7	124.517
3008.01	132.455
3012.33	134.748
3016.64	133.324
3020.95	111.036
3025.26	122.817
3029.56	132.688
3033.86	134.906
3038.16	137.057
3042.45	116.229
3046.74	151.078
3051.03	139.768
3055.32	149.672
3059.6	142.204
3063.88	150.205
3068.16	150.47
3072.43	158.513
3076.7	162.703
3080.97	172.767
3085.24	171.168
3089.5	181.402
3093.76	172.107
3098.02	182.541
3102.27	183.147
3106.52	201.705
3110.77	194.506
3115.01	203.28
3119.26	208.105
3123.5	225.145
3127.73	226.157
3131.97	219.105
3136.2	242.699
3140.43	258.217
3144.65	248.976
3148.87	254.106
3153.09	248.696
3157.31	270.311
3161.52	302.515
3165.73	265.591
3169.94	285.208
3174.15	317.67
3178.35	314.037
3182.55	325.094
3186.75	342.471
3190.94	325.865
3195.13	341.311
3199.32	333.672
3203.51	347.719
3207.69	355.514
3211.87	356.948
3216.05	351.998
3220.22	368.658
3224.39	350.48
3228.56	356.277
3232.73	346.661
3236.89	347.863
3241.05	344.799
3245.21	357.447
3249.36	352.083
3253.52	362.046
3257.66	344.889
3261.81	355.053
3265.95	347.385
3270.1	353.505
3274.23	361.819
3278.37	344.23
3282.5	360.969
3286.63	336.439
3290.76	355.495
3294.88	363.039
3299	375.231
3303.12	336.676
3307.24	335.027
3311.35	335.638
3315.46	378.128
3319.57	341.551
3323.68	363.383
3327.78	371.351
3331.88	360.747
3335.98	357.326
3340.07	379.718
3344.16	378.176
3348.25	383.577
3352.34	348.596
3356.42	363.599
3360.5	395.475
3364.58	377.201
3368.66	375.594
3372.73	419.643
3376.8	369.736
3380.87	394.377
3384.93	402.135
3388.99	392.941
3393.05	415.136
3397.11	415.72
3401.16	413.876
3405.21	394.822
3409.26	417.097
3413.31	434.441
3417.35	420.178
3421.39	435.111
3425.43	423.217
3429.46	413.896
3433.5	407.101
3437.53	419.995
3441.55	408.485
3445.58	406.907
3449.6	407.943
3453.62	406.554
3457.64	420.259
3461.65	411.773
3465.66	403.243
3469.67	387.097
3473.68	378.103
3477.68	346.504
3481.68	375.351
3485.68	391.642
3489.67	354.595
3493.67	365.734
3497.66	343.583
3501.64	374.994
3505.63	337.16
3509.61	355.494
3513.59	330.043
3517.57	299.401
3521.54	320.141
3525.52	317.787
3529.49	302.524
3533.45	279.743
3537.42	259.659
3541.38	275.79
3545.34	278.875
3549.29	279.29
3553.25	248.236
3557.2	261.466
3561.15	259.184
3565.09	249.154
3569.04	239.246
3572.98	244.965
3576.92	227.162
3580.85	217.259
3584.79	228.475
3588.72	186.763
3592.64	211.218
3596.57	214.497
3600.49	220.404
3604.41	196.856
3608.33	191.927
3612.25	184.244
3616.16	190.007
3620.07	171.45
3623.98	171.608
3627.88	179.831
3631.79	150.143
3635.69	163.759
3639.58	144.977
3643.48	150.677
3647.37	148.294
3651.26	142.941
3655.15	140.362
3659.03	143.216
3662.92	121.483
3666.8	110.669
3670.67	129.929
3674.55	116.393
3678.42	116.597
3682.29	116.852
3686.16	114.407
3690.02	117.493
3693.89	103.954
3697.75	107.001
3701.61	96.1447
3705.46	93.5992
3709.31	91.0596
3713.16	88.4981
3717.01	91.5192
3720.86	100.174
3724.7	108.842
3728.54	94.8695
3732.38	89.372
3736.21	86.7003
3740.04	84.0072
3743.87	89.8477
3747.7	72.8401
3751.53	84.3653
3755.35	67.2656
3759.17	81.6274
3762.99	95.9936
3766.81	75.9683
3770.62	101.845
3774.43	81.8354
3778.24	96.2843
3782.04	96.4105
3785.85	87.9158
3789.65	70.719
3793.45	96.8426
3797.24	91.2367
3801.04	71.1074
3804.83	82.898
3808.62	83.0911
3812.4	68.659
3816.19	80.5064
3819.97	95.3297
3823.75	86.6826
3827.52	83.874
3831.3	84.0272
3835.07	84.184
3838.84	84.3229
3842.61	69.6686
3846.37	84.5921
3850.13	78.7057
3853.89	75.7748
3857.65	81.7452
3861.41	90.673
3865.16	69.9333
3868.91	90.9868
3872.66	91.0859
3876.4	76.2012
3880.14	73.2586
3883.89	82.2904
3887.62	73.3821
3891.36	82.4586
3895.09	88.6129
3898.82	94.7666
3902.55	73.8233
3906.28	82.982
3910	92.1612
3913.73	74.1579
3917.45	80.3681
3921.16	74.4779
3924.88	77.7023
3928.59	80.923
3932.3	78.0175
3936.01	78.1322
3939.71	69.0466
3943.42	75.3374
3947.12	87.8045
3950.81	81.7778
3954.51	63.3488
3958.2	81.9872
3961.9	82.0519
3965.58	88.3037
3969.27	85.2289
3972.96	88.3563
3976.64	75.981
3980.32	75.9881
3984	72.8784
3987.67	79.0754
3991.34	79.0882
3995.01	79.131
3998.68	76.0984