File: Data/3-Raman/raw/bu04w-a-ff3-fi06-v_150 (500nm)_633nm_edge_100%_x100_vis_lwd_h50um_45sx2_01.txt
#Acq. time (s)=	45
#Accumulations=	2
#Range (cm-¹)=	100...4000
#Windows=	1
#Auto scanning=	Off
#Autofocus=	Off
#Macrospot=	Off
#AutoExposure=	Off
#Spike filter=	Multiple accum.
#Delay time (s)=	2
#Binning=	1
#Readout mode=	Signal
#DeNoise=	Off
#ICS correction=	On
#Dark correction=	Off
#Inst. Process=	Off
#Detector Gain=	Best Dynamic
#Detector ADC=	50 kHz HS
#Detector temperature (°C)=	-60.09
#Instrument=	LabRAM HR Evol
#Detector=	SIN-EM FIVIS
#Objective=	x100_VIS_LWD
#Grating=	150 (500nm)
#ND Filter=	100%
#Laser=	633nm_Edge
#Hole=	49.98
#Temperature=	0
#Range=	Visible
#StageXY=	75x50mm Scan+
#StageZ=	Z motor
#X (µm)=	0
#Y (µm)=	0
#Z (µm)=	-8
#Full time(mm:ss)=	1:34
#Project=	21_11_22
#Sample=	BU04w
#Site=
#Title=	BU04w-A-FF3-FI06-V_150 (500nm)_633nm_Edge_100%_x100_VIS_LWD_H50um_45sX2
#Remark=
#Date=	22.11.2021 11:07
#Acquired=	22.11.2021 11:07:08
100.177	317.872
106.695	297.141
113.209	271.662
119.717	246.071
126.219	251.02
132.716	250.196
139.208	261.708
145.694	255.054
152.175	214.912
158.651	238.976
165.121	345.505
171.586	260.285
178.045	178.754
184.5	162.319
190.947	146.778
197.39	128.419
203.829	135.048
210.262	142.631
216.688	134.948
223.11	152.037
229.527	216.577
235.939	346.614
242.344	312.092
248.745	195.186
255.141	180.816
261.53	196.863
267.916	166.452
274.294	166.438
280.669	185.388
287.038	191.944
293.402	170.955
299.76	156.619
306.114	164.03
312.461	191.275
318.805	281.724
325.142	536.38
331.475	595.693
337.802	370.162
344.123	235.242
350.441	188.952
356.752	185.976
363.058	198.023
369.36	207.217
375.656	179.772
381.947	150.518
388.232	148.64
394.512	138.477
400.789	158.532
407.059	159.806
413.324	169.55
419.584	200.052
425.839	255.91
432.089	313.88
438.333	316.897
444.573	255.98
450.807	231.812
457.037	247.082
463.261	213.078
469.48	157.916
475.695	143.913
481.904	141.151
488.108	160.731
494.307	162.636
500.502	179.452
506.691	197.265
512.874	230.068
519.053	220.034
525.227	212.931
531.396	197.479
537.559	185.799
543.718	170.158
549.873	153.337
556.022	143.074
562.165	148.614
568.304	132.329
574.437	124.442
580.567	120.288
586.691	123.713
592.81	128.175
598.924	170.02
605.033	159.039
611.138	139.699
617.236	141.939
623.332	130.158
629.42	136.185
635.506	125.929
641.585	127.719
647.659	123.731
653.73	139.436
659.794	153.11
665.854	148.976
671.91	121.666
677.96	105.845
684.005	90.9593
690.045	94.8329
696.082	97.8576
702.113	99.0061
708.139	86.0175
714.16	98.2293
720.176	95.3495
726.187	94.3346
732.194	80.113
738.196	90.2561
744.193	90.1055
750.185	93.7232
756.173	80.6236
762.155	91.9227
768.133	94.0402
774.107	83.0518
780.075	89.8312
786.039	86.1959
791.998	83.4525
797.952	88.1893
803.902	75.8761
809.845	88.9696
815.786	86.9233
821.721	93.2855
827.652	91.1813
833.576	92.019
839.498	93.0148
845.415	91.3152
851.327	96.2017
857.233	98.3243
863.135	105.199
869.032	101.704
874.925	99.0459
880.813	113.367
886.697	110.555
892.576	111.46
898.45	112.282
904.318	110.128
910.184	107.957
916.044	117.086
921.9	118.823
927.75	131.044
933.596	153.79
939.439	178.787
945.275	228.686
951.107	282.856
956.936	290.55
962.759	269.358
968.577	245.939
974.391	246.226
980.201	272.992
986.006	355.017
991.806	407.02
997.602	359.509
1003.39	308.496
1009.18	295.954
1014.96	295.29
1020.74	376.766
1026.51	429.254
1032.28	357.427
1038.04	231.469
1043.8	192.599
1049.56	170.883
1055.31	145.038
1061.05	133.559
1066.8	135.495
1072.53	128.659
1078.26	151.857
1083.99	164.315
1089.72	191.324
1095.44	278.342
1101.15	362.326
1106.86	260.838
1112.56	183.56
1118.27	130.727
1123.96	131.05
1129.65	123.55
1135.34	133.653
1141.03	174.233
1146.7	208.934
1152.38	334.242
1158.05	398.22
1163.71	232.485
1169.37	138.842
1175.03	106.252
1180.68	108.004
1186.33	91.3092
1191.98	94.2526
1197.61	90.4637
1203.25	82.867
1208.88	85.1335
1214.51	76.5778
1220.13	77.9236
1225.74	80.2965
1231.36	77.6544
1236.97	75.9345
1242.57	85.2105
1248.17	78.2647
1253.77	83.3596
1259.36	90.3764
1264.94	87.2233
1270.53	83.0664
1276.11	86.9111
1281.68	307.267
1287.25	96.5752
1292.81	75.4725
1298.38	78.448
1303.93	88.4777
1309.48	75.611
1315.03	81.871
1320.58	77.1076
1326.12	72.3465
1331.65	72.6402
1337.18	76.9736
1342.71	70.0333
1348.23	76.3236
1353.75	76.4565
1359.26	70.3776
1364.77	82.7382
1370.28	79.6337
1375.78	83.7128
1381.28	127.826
1386.77	308.381
1392.26	84.6462
1397.74	72.4143
1403.23	83.8264
1408.7	81.9047
1414.17	75.8734
1419.64	75.0108
1425.11	66.9009
1430.56	67.0744
1436.02	68.2869
1441.47	64.2696
1446.92	73.86
1452.36	66.6238
1457.8	66.6726
1463.23	65.6298
1468.66	65.612
1474.09	73.9949
1479.51	64.5673
1484.93	65.6528
1490.34	68.876
1495.75	64.7747
1501.16	71.2331
1506.56	71.3959
1511.96	65.2275
1517.35	67.5595
1522.74	69.9214
1528.13	68.0229
1533.51	67.2065
1538.88	71.7287
1544.25	71.8954
1549.62	68.6932
1554.99	70.8009
1560.35	67.4753
1565.71	71.7236
1571.06	73.8017
1576.41	66.2017
1581.75	60.8198
1587.09	76.9885
1592.43	77.0388
1597.76	67.4222
1603.09	72.9328
1608.41	67.6831
1613.73	64.636
1619.05	71.4227
1624.36	73.8857
1629.67	69.7686
1634.97	73.3063
1640.27	67.9115
1645.57	66.9135
1650.86	68.1057
1656.15	70.3829
1661.43	68.1918
1666.71	70.4222
1671.99	73.7521
1677.26	69.3053
1682.53	70.39
1687.79	71.4329
1693.05	65.86
1698.31	70.3198
1703.56	69.4855
1708.81	70.9099
1714.06	65.2241
1719.3	68.7629
1724.53	69.987
1729.77	70.1337
1735	65.7795
1740.22	70.4122
1745.44	73.933
1750.66	72.9099
1755.87	65.069
1761.08	73.0226
1766.29	74.1838
1771.49	75.3605
1776.69	64.08
1781.88	64.1701
1787.07	67.6938
1792.26	66.7047
1797.44	65.7185
1802.62	63.6072
1807.79	69.523
1812.96	66.2175
1818.13	69.8256
1823.29	72.29
1828.45	68.9775
1833.61	69.1437
1838.76	71.6372
1843.91	57.7653
1849.05	68.3801
1854.19	71.9802
1859.33	72.0986
1864.46	72.2394
1869.59	70.0358
1874.71	71.3147
1879.83	70.2233
1884.95	71.4804
1890.06	76.2531
1895.17	67.9806
1900.28	73.9297
1905.38	74.0614
1910.48	71.858
1915.57	72.0968
1920.66	73.4081
1925.75	67.5658
1930.83	71.2919
1935.91	72.62
1940.99	64.312
1946.06	67.9955
1951.13	68.0504
1956.19	64.4645
1961.26	71.7118
1966.31	69.3048
1971.36	69.2738
1976.41	69.2346
1981.46	74.0087
1986.5	67.9572
1991.54	75.1462
1996.58	67.9182
2001.61	69.1254
2006.63	69.1557
2011.66	68.0039
2016.68	68.059
2021.69	75.3293
2026.71	71.7969
2031.72	74.328
2036.72	73.26
2041.72	69.7653
2046.72	75.9939
2051.71	67.6311
2056.71	75.0655
2061.69	71.5632
2066.68	75.4048
2071.66	68.1918
2076.63	68.3332
2081.6	64.7614
2086.57	75.9785
2091.54	74.8524
2096.5	76.2528
2101.46	70.2179
2106.41	71.6462
2111.36	73.0995
2116.31	65.8062
2121.25	82.3548
2126.19	76.2927
2131.13	70.1792
2136.06	70.3511
2140.99	66.6967
2145.92	75.7447
2150.84	69.4886
2155.76	73.4029
2160.67	77.3015
2165.58	72.2258
2170.49	78.6426
2175.39	71.0254
2180.29	72.3313
2185.19	71.0425
2190.08	74.8944
2194.98	74.9348
2199.86	67.3223
2204.74	68.71
2209.62	79.1355
2214.5	75.4403
2219.37	76.9217
2224.24	71.9337
2229.11	69.5181
2233.97	72.3003
2238.83	69.871
2243.68	68.738
2248.53	71.5404
2253.38	74.3493
2258.22	75.8591
2263.06	73.4003
2267.9	74.8708
2272.73	68.3516
2277.56	71.0925
2282.39	71.1485
2287.21	77.8202
2292.03	75.1805
2296.85	63.2246
2301.66	79.2618
2306.47	71.3674
2311.28	76.8508
2316.08	75.6863
2320.88	67.8219
2325.68	88.1953
2330.47	68.185
2335.26	64.3305
2340.04	69.9676
2344.82	74.2971
2349.6	74.5687
2354.38	70.6993
2359.15	64.009
2363.92	68.2699
2368.68	68.4191
2373.44	76.8693
2378.2	72.8595
2382.95	67.4031
2387.71	78.5923
2392.45	68.8889
2397.2	63.3306
2401.94	66.1153
2406.68	70.275
2411.41	70.3463
2416.14	60.7892
2420.87	75.1326
2425.59	71.0206
2430.31	71.1972
2435.03	72.8118
2439.75	75.8708
2444.46	76.0961
2449.16	70.6188
2453.87	69.3965
2458.57	81.0796
2463.27	79.8759
2467.96	67.1077
2472.65	65.832
2477.34	77.6104
2482.02	76.3534
2486.7	79.4364
2491.38	81.0599
2496.05	76.8401
2500.72	72.5902
2505.39	74.1889
2510.06	72.8329
2514.72	75.8743
2519.37	67.1264
2524.03	70.1913
2528.68	71.7766
2533.33	79.3069
2537.97	75.0038
2542.61	84.0867
2547.25	69.3564
2551.88	78.4776
2556.51	77.1367
2561.14	80.2906
2565.77	81.984
2570.39	73.1463
2575.01	77.8715
2579.62	78.0467
2584.23	73.6205
2588.84	70.6682
2593.45	73.7653
2598.05	73.8807
2602.65	72.4561
2607.24	75.5955
2611.84	83.3058
2616.42	84.9013
2621.01	74.2597
2625.59	75.8691
2630.17	75.9787
2634.75	77.6879
2639.32	73.2969
2643.89	78.171
2648.46	78.4228
2653.02	80.2258
2657.58	77.2587
2662.14	74.2561
2666.69	79.0415
2671.24	83.886
2675.79	79.4081
2680.33	78.2198
2684.88	78.575
2689.41	75.7396
2693.95	72.824
2698.48	79.3512
2703.01	76.3093
2707.53	76.4542
2712.06	74.9731
2716.57	79.9874
2721.09	80.139
2725.6	73.777
2730.11	81.9821
2734.62	73.9255
2739.12	80.4745
2743.62	78.9426
2748.12	75.8027
2752.61	71.1091
2757.1	74.5461
2761.59	81.2185
2766.08	73.1527
2770.56	69.9954
2775.04	78.4047
2779.51	76.964
2783.98	80.5477
2788.45	84.1529
2792.92	77.7338
2797.38	74.6004
2801.84	76.4686
2806.3	81.684
2810.75	64.9654
2815.2	87.0409
2819.65	73.6311
2824.09	75.4481
2828.53	78.9696
2832.97	79.0878
2837.41	82.6041
2841.84	79.3123
2846.27	77.7371
2850.69	76.1728
2855.12	83.2195
2859.54	71.3855
2863.95	81.939
2868.37	78.7373
2872.78	78.9793
2877.18	79.2281
2881.59	86.4846
2885.99	76.2769
2890.39	78.2987
2894.78	80.3234
2899.18	85.9434
2903.57	91.5672
2907.95	81.1437
2912.34	81.3524
2916.72	74.3633
2921.09	81.7322
2925.47	89.1525
2929.84	78.5752
2934.21	91.4737
2938.57	75.3334
2942.94	80.9299
2947.29	84.6937
2951.65	82.9933
2956	77.6317
2960.36	74.0825
2964.7	94.3499
2969.05	85.3412
2973.39	91.0166
2977.73	72.7661
2982.06	82.1403
2986.4	86.0411
2990.73	69.5745
2995.05	84.6553
2999.38	84.9156
3003.7	90.8132
3008.01	87.3641
3012.33	95.1715
3016.64	80.3727
3020.95	90.157
3025.26	94.2553
3029.56	75.4127
3033.86	85.1533
3038.16	83.3846
3042.45	95.0961
3046.74	97.1903
3051.03	85.7888
3055.32	91.7343
3059.6	101.574
3063.88	92.0613
3068.16	96.1063
3072.43	100.164
3076.7	96.4526
3080.97	98.5848
3085.24	102.701
3089.5	100.997
3093.76	107.198
3098.02	103.604
3102.27	105.928
3106.52	112.279
3110.77	108.724
3115.01	105.145
3119.26	109.582
3123.5	116.106
3127.73	114.6
3131.97	125.349
3136.2	113.669
3140.43	122.422
3144.65	114.673
3148.87	146.241
3153.09	148.801
3157.31	138.809
3161.52	143.407
3165.73	139.619
3169.94	150.497
3174.15	153.03
3178.35	159.662
3182.55	164.135
3186.75	168.585
3190.94	181.508
3195.13	149.922
3199.32	158.84
3203.51	165.835
3207.69	168.627
3211.87	173.621
3216.05	172.208
3220.22	177.261
3224.39	153.949
3228.56	143.607
3232.73	159.574
3236.89	142.458
3241.05	143.019
3245.21	139.193
3249.36	139.715
3253.52	146.836
3257.66	140.427
3261.81	129.623
3265.95	134.654
3270.1	121.624
3274.23	117.563
3278.37	113.218
3282.5	127.199
3286.63	122.863
3290.76	123.1
3294.88	123.318
3299	114.301
3303.12	107.598
3307.24	130.997
3311.35	117.299
3315.46	101.222
3319.57	124.73
3323.68	118.012
3327.78	111.288
3331.88	99.8812
3335.98	130.902
3340.07	102.914
3344.16	105.51
3348.25	100.941
3352.34	117.785
3356.42	113.252
3360.5	113.505
3364.58	104.179
3368.66	111.598
3372.73	107.015
3376.8	124.048
3380.87	116.986
3384.93	109.893
3388.99	112.441
3393.05	114.979
3397.11	98.1729
3401.16	112.875
3405.21	95.972
3409.26	113.09
3413.31	108.306
3417.35	118.137
3421.39	96.2851
3425.43	110.988
3429.46	103.779
3433.5	99.0245
3437.53	106.529
3441.55	89.5477
3445.58	111.869
3449.6	102.294
3453.62	105.037
3457.64	105.375
3461.65	103.254
3465.66	88.6385
3469.67	108.988
3473.68	109.285
3477.68	102.061
3481.68	99.8408
3485.68	107.733
3489.67	102.947
3493.67	93.0264
3497.66	98.349
3501.64	116.466
3505.63	98.7122
3509.61	93.686
3513.59	98.8845
3517.57	98.9436
3521.54	101.571
3525.52	91.3478
3529.49	96.5502
3533.45	99.2635
3537.42	91.7204
3541.38	94.5194
3545.34	86.9052
3549.29	87.0347
3553.25	100.074
3557.2	89.7569
3561.15	95.0777
3565.09	92.6174
3569.04	98.0517
3572.98	100.868
3576.92	82.7236
3580.85	93.4872
3584.79	96.4086
3588.72	91.3948
3592.64	99.6311
3596.57	89.2626
3600.49	81.4828
3604.41	79.0101
3608.33	81.8709
3612.25	92.7946
3616.16	76.8113
3620.07	95.8498
3623.98	74.3182
3627.88	90.5916
3631.79	90.6268
3635.69	74.4361
3639.58	74.5211
3643.48	77.3747
3647.37	82.9901
3651.26	77.5968
3655.15	85.8526
3659.03	66.8343
3662.92	77.804
3666.8	80.611
3670.67	75.2218
3674.55	89.0066
3678.42	80.9318
3682.29	59.1132
3686.16	73.0554
3690.02	70.4959
3693.89	70.6889
3697.75	68.0919
3701.61	68.2767
3705.46	65.6591
3709.31	82.6541
3713.16	71.6413
3717.01	77.4393
3720.86	80.4215
3724.7	80.5715
3728.54	69.3822
3732.38	72.3488
3736.21	78.1724
3740.04	69.7687
3743.87	78.4384
3747.7	69.9836
3751.53	64.3464
3755.35	61.5408
3759.17	75.8991
3762.99	73.0697
3766.81	70.2348
3770.62	73.1565
3774.43	70.3497
3778.24	76.1652
3782.04	73.3871
3785.85	76.3859
3789.65	70.719
3793.45	82.3885
3797.24	82.5475
3801.04	71.1074
3804.83	71.2632
3808.62	74.3446
3812.4	71.5807
3816.19	71.7239
3819.97	68.9307
3823.75	60.2371
3827.52	72.1022
3831.3	78.1305
3835.07	72.3687
3838.84	54.7359
3842.61	63.7393
3846.37	78.6558
3850.13	81.6757
3853.89	75.7748
3857.65	60.9373
3861.41	81.7544
3865.16	66.9574
3868.91	73.0877
3872.66	70.181
3876.4	58.2715
3880.14	64.2882
3883.89	55.359
3887.62	67.3917
3891.36	73.4631
3895.09	67.5861
3898.82	61.6735
3902.55	58.7573
3906.28	70.9119
3910	61.9444
3913.73	71.1311
3917.45	65.2043
3921.16	65.3581
3924.88	68.5609
3928.59	62.6008
3932.3	71.8985
3936.01	75.0682
3939.71	69.0466
3943.42	75.3374
3947.12	69.3193
3950.81	63.2621
3954.51	66.439
3958.2	66.518
3961.9	78.9556
3965.58	72.8118
3969.27	69.7328
3972.96	60.4543
3976.64	66.6772
3980.32	69.785
3984	69.7772
3987.67	60.4694
3991.34	57.3777
3995.01	60.512
3998.68	69.8863