File: Data/3-Raman/raw/bu04w-a-ff3-fi01-v_150 (500nm)_633nm_edge_100%_x100_vis_lwd_h100um_0_5sx60_01.txt
#Acq. time (s)=	0.5
#Accumulations=	60
#Range (cm-¹)=	100...4000
#Windows=	1
#Auto scanning=	Off
#Autofocus=	Off
#Macrospot=	Off
#AutoExposure=	Off
#Spike filter=	Multiple accum.
#Delay time (s)=	2
#Binning=	1
#Readout mode=	Signal
#DeNoise=	Off
#ICS correction=	On
#Dark correction=	Off
#Inst. Process=	Off
#Detector Gain=	Best Dynamic
#Detector ADC=	50 kHz HS
#Detector temperature (°C)=	-60.09
#Instrument=	LabRAM HR Evol
#Detector=	SIN-EM FIVIS
#Objective=	x100_VIS_LWD
#Grating=	150 (500nm)
#ND Filter=	100%
#Laser=	633nm_Edge
#Hole=	100.021
#Temperature=	0
#Range=	Visible
#StageXY=	75x50mm Scan+
#StageZ=	Z motor
#X (µm)=	0
#Y (µm)=	0
#Z (µm)=	14.3
#Full time(s)=	43
#Project=	21_11_22
#Sample=	BU04w
#Site=
#Title=	BU04w-A-FF3-V_150 (500nm)_633nm_Edge_100%_x100_VIS_LWD_H100um_0_5sX60
#Remark=
#Date=	22.11.2021 10:36
#Acquired=	22.11.2021 10:36:57
100.177	25.4359
106.695	23.694
113.209	22.9898
119.717	22.2302
126.219	20.8191
132.716	20.6192
139.208	20.1027
145.694	19.6033
152.175	19.4785
158.651	19.3106
165.121	19.2737
171.586	19.2795
178.045	17.098
184.5	16.7099
190.947	15.7451
197.39	15.7702
203.829	15.1977
210.262	14.8202
216.688	14.9116
223.11	14.4355
229.527	15.4335
235.939	16.9153
242.344	16.5132
248.745	15.4143
255.141	14.4225
261.53	14.6411
267.916	13.9132
274.294	13.8799
280.669	13.6054
287.038	14.4189
293.402	13.8135
299.76	13.5615
306.114	13.0516
312.461	13.9364
318.805	14.7889
325.142	17.7266
331.475	19.2577
337.802	17.8307
344.123	14.8699
350.441	13.9843
356.752	14.0689
363.058	13.4014
369.36	14.3433
375.656	13.6279
381.947	13.63
388.232	13.2324
394.512	12.9446
400.789	12.9725
407.059	13.1913
413.324	13.5842
419.584	13.0739
425.839	14.5357
432.089	15.288
438.333	15.8261
444.573	14.9584
450.807	14.5334
457.037	14.2735
463.261	14.043
469.48	13.5091
475.695	13.2223
481.904	12.9568
488.108	13.0054
494.307	12.9454
500.502	13.1221
506.691	14.0458
512.874	14.2927
519.053	13.7219
525.227	13.8094
531.396	13.778
537.559	13.2423
543.718	12.7904
549.873	13.0586
556.022	12.8772
562.165	12.3545
568.304	12.22
574.437	12.5039
580.567	12.4152
586.691	12.1458
592.81	12.5687
598.924	12.5136
605.033	13.2565
611.138	12.9951
617.236	12.7909
623.332	12.5595
629.42	12.803
635.506	12.9103
641.585	12.5011
647.659	12.0007
653.73	12.6919
659.794	12.4358
665.854	12.5143
671.91	12.4913
677.96	11.9415
684.005	11.5824
690.045	11.5047
696.082	11.6737
702.113	11.492
708.139	11.4642
714.16	11.8933
720.176	11.3604
726.187	11.8286
732.194	11.4742
738.196	11.3425
744.193	11.3394
750.185	11.4516
756.173	11.7614
762.155	10.8428
768.133	11.6014
774.107	11.3487
780.075	11.8537
786.039	11.0569
791.998	11.3236
797.952	11.2305
803.902	11.1909
809.845	11.2738
815.786	11.0934
821.721	10.9565
827.652	11.357
833.576	11.1708
839.498	11.1307
845.415	10.8499
851.327	11.1433
857.233	11.0436
863.135	11.2659
869.032	11.6496
874.925	11.7351
880.813	11.6173
886.697	11.6208
892.576	11.2465
898.45	11.0411
904.318	11.3677
910.184	11.1465
916.044	11.4687
921.9	11.2956
927.75	11.6149
933.596	11.7736
939.439	11.6654
945.275	13.2812
951.107	13.9313
956.936	13.9813
962.759	13.8583
968.577	13.578
974.391	13.4799
980.201	13.5231
986.006	15.0634
991.806	15.9293
997.602	15.8363
1003.39	14.7165
1009.18	14.2569
1014.96	14.6751
1020.74	15.4183
1026.51	16.0191
1032.28	15.442
1038.04	13.7434
1043.8	12.7876
1049.56	12.0694
1055.31	12.1763
1061.05	12.0429
1066.8	11.5814
1072.53	11.7262
1078.26	11.9647
1083.99	12.1833
1089.72	12.9793
1095.44	13.2669
1101.15	14.373
1106.86	13.3286
1112.56	12.847
1118.27	11.9847
1123.96	11.9151
1129.65	11.6622
1135.34	11.7248
1141.03	12.3032
1146.7	12.2903
1152.38	14.3255
1158.05	14.6086
1163.71	13.654
1169.37	12.1321
1175.03	10.8633
1180.68	11.4059
1186.33	11.1312
1191.98	10.7687
1197.61	11.1142
1203.25	11.0783
1208.88	10.7845
1214.51	11.0282
1220.13	10.9949
1225.74	10.8116
1231.36	10.9795
1236.97	10.9184
1242.57	11.2378
1248.17	10.8775
1253.77	11.1232
1259.36	11.5955
1264.94	11.1176
1270.53	11.2547
1276.11	11.759
1281.68	12.8201
1287.25	10.9831
1292.81	11.4111
1298.38	10.781
1303.93	11.1582
1309.48	10.7531
1315.03	10.7691
1320.58	10.7884
1326.12	11.0873
1331.65	10.7535
1337.18	10.8605
1342.71	11.5495
1348.23	10.8091
1353.75	11.1062
1359.26	11.4147
1364.77	11.3146
1370.28	11.5031
1375.78	11.7078
1381.28	13.1298
1386.77	14.0106
1392.26	11.6427
1397.74	10.8896
1403.23	11.1309
1408.7	11.1145
1414.17	11.014
1419.64	11.4423
1425.11	11.2424
1430.56	10.9191
1436.02	11.0528
1441.47	11.1323
1446.92	11.0892
1452.36	10.9098
1457.8	10.8466
1463.23	11.3284
1468.66	11.4143
1474.09	10.8782
1479.51	10.6322
1484.93	10.7626
1490.34	11.3442
1495.75	10.8984
1501.16	11.0092
1506.56	10.873
1511.96	10.9387
1517.35	11.1352
1522.74	11.1907
1528.13	11.1208
1533.51	11.0538
1538.88	11.2159
1544.25	11.3885
1549.62	11.4871
1554.99	11.4597
1560.35	10.915
1565.71	11.1968
1571.06	11.2761
1576.41	11.394
1581.75	11.321
1587.09	11.087
1592.43	11.1125
1597.76	11.2355
1603.09	11.5282
1608.41	11.2973
1613.73	11.6273
1619.05	11.2831
1624.36	11.6232
1629.67	11.5179
1634.97	12.0231
1640.27	11.5198
1645.57	11.4819
1650.86	11.7967
1656.15	11.2624
1661.43	11.2666
1666.71	11.7386
1671.99	11.8142
1677.26	11.7185
1682.53	11.5641
1687.79	11.8726
1693.05	11.1908
1698.31	11.684
1703.56	11.1836
1708.81	11.4981
1714.06	11.1967
1719.3	11.2852
1724.53	11.0556
1729.77	11.6874
1735	11.6351
1740.22	10.7027
1745.44	11.584
1750.66	11.2368
1755.87	11.1917
1761.08	11.2734
1766.29	11.5081
1771.49	11.2844
1776.69	11.0244
1781.88	11.7907
1787.07	11.5796
1792.26	11.4315
1797.44	11.6133
1802.62	11.1597
1807.79	11.7543
1812.96	11.3892
1818.13	11.6881
1823.29	11.5958
1828.45	11.5044
1833.61	11.6503
1838.76	11.7174
1843.91	11.7588
1849.05	12.1941
1854.19	11.6148
1859.33	11.5942
1864.46	11.3381
1869.59	11.641
1874.71	11.8775
1879.83	11.9523
1884.95	11.6848
1890.06	11.6519
1895.17	11.8127
1900.28	12.0994
1905.38	11.4783
1910.48	11.7264
1915.57	11.624
1920.66	11.8655
1925.75	11.8065
1930.83	11.9108
1935.91	11.3624
1940.99	12.1534
1946.06	11.8
1951.13	11.8504
1956.19	11.7737
1961.26	11.3681
1966.31	11.8181
1971.36	11.4657
1976.41	11.6224
1981.46	11.7178
1986.5	11.9565
1991.54	11.6668
1996.58	11.6032
2001.61	11.8079
2006.63	12.2819
2011.66	11.9035
2016.68	11.5456
2021.69	11.8382
2026.71	11.2793
2031.72	11.6659
2036.72	11.7705
2041.72	11.1357
2046.72	11.6541
2051.71	11.907
2056.71	12.3816
2061.69	11.5177
2066.68	12.0635
2071.66	11.7349
2076.63	11.9888
2081.6	12.0532
2086.57	12.0087
2091.54	11.9214
2096.5	12.4724
2101.46	12.3121
2106.41	12.0484
2111.36	12.0191
2116.31	12.2689
2121.25	12.2642
2126.19	12.4928
2131.13	12.1841
2136.06	12.2999
2140.99	12.2627
2145.92	12.0505
2150.84	11.983
2155.76	12.4087
2160.67	12.1599
2165.58	12.3392
2170.49	11.9747
2175.39	12.9817
2180.29	12.2053
2185.19	12.2472
2190.08	12.4444
2194.98	11.713
2199.86	12.2256
2204.74	12.4185
2209.62	12.2242
2214.5	12.2947
2219.37	12.435
2224.24	12.1372
2229.11	12.1241
2233.97	12.5303
2238.83	12.2963
2243.68	12.3717
2248.53	12.2924
2253.38	12.8581
2258.22	12.332
2263.06	12.6088
2267.9	12.1846
2272.73	12.0912
2277.56	12.5563
2282.39	12.7015
2287.21	12.1414
2292.03	12.3703
2296.85	12.6675
2301.66	13.1294
2306.47	12.4692
2311.28	12.6518
2316.08	13.0666
2320.88	12.2806
2325.68	12.746
2330.47	12.8498
2335.26	12.6595
2340.04	12.5382
2344.82	12.5119
2349.6	12.7431
2354.38	12.9718
2359.15	12.8905
2363.92	12.962
2368.68	13.0607
2373.44	13.2752
2378.2	12.7372
2382.95	12.7316
2387.71	12.9081
2392.45	12.7729
2397.2	13.1757
2401.94	13.0107
2406.68	12.6776
2411.41	12.714
2416.14	12.9916
2420.87	13.1033
2425.59	13.265
2430.31	12.9634
2435.03	13.0958
2439.75	12.9917
2444.46	13.3918
2449.16	13.3113
2453.87	12.9626
2458.57	13.3896
2463.27	13.1602
2467.96	13.4411
2472.65	13.7697
2477.34	13.5354
2482.02	13.4219
2486.7	13.0315
2491.38	13.281
2496.05	13.2346
2500.72	13.5338
2505.39	13.8567
2510.06	13.7287
2514.72	13.8214
2519.37	13.3403
2524.03	13.0615
2528.68	13.6831
2533.33	13.6303
2537.97	13.732
2542.61	13.6087
2547.25	13.5881
2551.88	14.2767
2556.51	14.0006
2561.14	13.7739
2565.77	13.7299
2570.39	13.6119
2575.01	14.2365
2579.62	13.8319
2584.23	13.7516
2588.84	14.283
2593.45	14.1911
2598.05	14.0326
2602.65	13.6639
2607.24	13.654
2611.84	14.029
2616.42	13.8585
2621.01	14.0786
2625.59	13.6775
2630.17	14.3476
2634.75	14.406
2639.32	14.2671
2643.89	13.5773
2648.46	13.9369
2653.02	14.0332
2657.58	13.7957
2662.14	14.0828
2666.69	14.0733
2671.24	14.6299
2675.79	14.2719
2680.33	14.5833
2684.88	14.3267
2689.41	14.4452
2693.95	14.9337
2698.48	14.3596
2703.01	14.4178
2707.53	14.9089
2712.06	14.7432
2716.57	14.3378
2721.09	14.804
2725.6	14.5795
2730.11	14.9271
2734.62	14.6088
2739.12	14.921
2743.62	14.5802
2748.12	15.0445
2752.61	15.0032
2757.1	15.1758
2761.59	14.3638
2766.08	14.7531
2770.56	14.9202
2775.04	15.2053
2779.51	14.6859
2783.98	15.327
2788.45	15.5483
2792.92	15.1727
2797.38	14.761
2801.84	15.026
2806.3	15.0009
2810.75	15.2868
2815.2	14.9389
2819.65	14.7893
2824.09	15.1586
2828.53	15.1261
2832.97	15.5524
2837.41	15.4585
2841.84	15.423
2846.27	15.3331
2850.69	15.3912
2855.12	15.5155
2859.54	15.35
2863.95	15.1306
2868.37	15.4131
2872.78	15.7253
2877.18	16.188
2881.59	16.065
2885.99	15.7071
2890.39	15.7015
2894.78	15.933
2899.18	15.7831
2903.57	15.987
2907.95	15.8842
2912.34	15.7129
2916.72	16.1422
2921.09	16.3038
2925.47	16.3469
2929.84	16.211
2934.21	16.379
2938.57	16.1374
2942.94	16.0134
2947.29	16.0064
2951.65	16.1226
2956	16.6099
2960.36	16.7263
2964.7	16.3796
2969.05	16.2532
2973.39	17.0315
2977.73	15.7834
2982.06	16.4406
2986.4	16.9511
2990.73	16.9337
2995.05	16.6662
2999.38	16.3062
3003.7	16.4235
3008.01	16.0016
3012.33	16.8814
3016.64	17.4208
3020.95	17.1628
3025.26	17.2826
3029.56	17.0694
3033.86	17.6923
3038.16	16.7484
3042.45	16.9809
3046.74	17.2721
3051.03	18.0204
3055.32	17.4631
3059.6	17.2323
3063.88	17.164
3068.16	17.9181
3072.43	18.0484
3076.7	17.8836
3080.97	17.7846
3085.24	17.9871
3089.5	17.7995
3093.76	18.0525
3098.02	17.6771
3102.27	18.1721
3106.52	19.0135
3110.77	18.8504
3115.01	18.9923
3119.26	18.9311
3123.5	18.3272
3127.73	19.4409
3131.97	19.2246
3136.2	19.7346
3140.43	19.4417
3144.65	19.6288
3148.87	20.0578
3153.09	20.4057
3157.31	20.2897
3161.52	20.3853
3165.73	20.5861
3169.94	21.1021
3174.15	20.1596
3178.35	21.1294
3182.55	20.3352
3186.75	21.3314
3190.94	20.4554
3195.13	20.9951
3199.32	21.2667
3203.51	21.3437
3207.69	20.6256
3211.87	20.8916
3216.05	21.9001
3220.22	21.7682
3224.39	22.6695
3228.56	21.9805
3232.73	22.8496
3236.89	22.7042
3241.05	21.5534
3245.21	21.1573
3249.36	21.5399
3253.52	22.1707
3257.66	21.9923
3261.81	21.798
3265.95	22.4967
3270.1	21.7894
3274.23	22.5375
3278.37	22.8918
3282.5	23.21
3286.63	21.8947
3290.76	22.5609
3294.88	22.718
3299	23.0324
3303.12	22.1392
3307.24	23.087
3311.35	22.5386
3315.46	22.3031
3319.57	23.4524
3323.68	22.7943
3327.78	22.4959
3331.88	22.7645
3335.98	24.0456
3340.07	23.0369
3344.16	23.2077
3348.25	23.2075
3352.34	23.2102
3356.42	23.2566
3360.5	22.8225
3364.58	23.3201
3368.66	23.4504
3372.73	23.4981
3376.8	24.1891
3380.87	23.6916
3384.93	24.1727
3388.99	23.7096
3393.05	24.4318
3397.11	24.1786
3401.16	23.8834
3405.21	24.5232
3409.26	24.6709
3413.31	24.9366
3417.35	24.5026
3421.39	24.2727
3425.43	24.0828
3429.46	24.5635
3433.5	24.1811
3437.53	24.3027
3441.55	24.7623
3445.58	23.9823
3449.6	24.1686
3453.62	24.3166
3457.64	24.6049
3461.65	24.2691
3465.66	24.355
3469.67	23.6747
3473.68	24.3353
3477.68	25.4352
3481.68	24.3122
3485.68	24.4682
3489.67	24.7943
3493.67	24.8171
3497.66	25.0906
3501.64	24.5773
3505.63	24.401
3509.61	24.6016
3513.59	24.6177
3517.57	25.4165
3521.54	24.6464
3525.52	24.9249
3529.49	23.8921
3533.45	24.1003
3537.42	23.9756
3541.38	24.0304
3545.34	24.4689
3549.29	25.1659
3553.25	23.9887
3557.2	23.7015
3561.15	24.393
3565.09	23.591
3569.04	24.0421
3572.98	24.2234
3576.92	24.0582
3580.85	24.5267
3584.79	24.824
3588.72	24.134
3592.64	24.1141
3596.57	24.2745
3600.49	24.1573
3604.41	24.6722
3608.33	23.9084
3612.25	24.3213
3616.16	23.1827
3620.07	24.4144
3623.98	24.3452
3627.88	22.6651
3631.79	23.4534
3635.69	24.338
3639.58	24.5495
3643.48	24.8252
3647.37	23.8663
3651.26	23.6044
3655.15	23.9981
3659.03	23.8347
3662.92	24.1301
3666.8	23.3658
3670.67	22.8795
3674.55	23.3251
3678.42	23.9703
3682.29	23.8829
3686.16	23.4329
3690.02	22.8895
3693.89	23.8918
3697.75	23.6237
3701.61	23.4517
3705.46	24.8856
3709.31	24.1005
3713.16	23.5947
3717.01	24.2699
3720.86	23.8419
3724.7	24.1738
3728.54	24.7913
3732.38	25.1261
3736.21	24.1624
3740.04	24.3502
3743.87	23.9545
3747.7	24.1832
3751.53	24.9872
3755.35	25.6885
3759.17	25.0732
3762.99	23.968
3766.81	23.6869
3770.62	23.7534
3774.43	23.7744
3778.24	25.0149
3782.04	23.6819
3785.85	24.5011
3789.65	24.9755
3793.45	24.67
3797.24	23.7358
3801.04	24.1288
3804.83	25.4142
3808.62	25.4734
3812.4	24.6856
3816.19	25.3304
3819.97	24.7832
3823.75	25.0262
3827.52	25.1148
3831.3	24.561
3835.07	25.2577
3838.84	24.6976
3842.61	24.7973
3846.37	25.9838
3850.13	25.6479
3853.89	25.2079
3857.65	26.0728
3861.41	25.2191
3865.16	25.0933
3868.91	25.812
3872.66	24.676
3876.4	25.2991
3880.14	24.8588
3883.89	25.9424
3887.62	25.6114
3891.36	25.7413
3895.09	25.3289
3898.82	26.2858
3902.55	26.0207
3906.28	25.9047
3910	25.5306
3913.73	25.4717
3917.45	25.3672
3921.16	25.9423
3924.88	25.1777
3928.59	26.267
3932.3	24.865
3936.01	25.7325
3939.71	25.3561
3943.42	25.8769
3947.12	25.874
3950.81	26.6491
3954.51	26.4237
3958.2	25.721
3961.9	27.4206
3965.58	26.2837
3969.27	26.5011
3972.96	25.1959
3976.64	26.5184
3980.32	26.5209
3984	26.8859
3987.67	25.6752
3991.34	26.9935
3995.01	26.0614
3998.68	26.5068