File: Data/3-Raman/raw/bu04w-a-ff3-fi06-v_1800 (450-850nm)_633nm_edge_100%_x100_vis_lwd_h50um_45sx2_01.txt
#Acq. time (s)=	45
#Accumulations=	2
#Range (cm-¹)=	1200...2380
#Windows=	6
#Auto scanning=	Off
#Autofocus=	Off
#Macrospot=	Off
#AutoExposure=	Off
#Spike filter=	Multiple accum.
#Delay time (s)=	2
#Binning=	1
#Readout mode=	Signal
#DeNoise=	Off
#ICS correction=	On
#Dark correction=	Off
#Inst. Process=	Off
#Detector Gain=	Best Dynamic
#Detector ADC=	50 kHz EM
#Detector EM gain=	100
#Detector temperature (°C)=	-60.09
#Instrument=	LabRAM HR Evol
#Detector=	SIN-EM FIVIS
#Objective=	x100_VIS_LWD
#Grating=	1800 (450-850nm)
#ND Filter=	100%
#Laser=	633nm_Edge
#Hole=	49.98
#Temperature=	0
#Range=	Visible
#StageXY=	75x50mm Scan+
#StageZ=	Z motor
#X (µm)=	0
#Y (µm)=	0
#Z (µm)=	-8.8
#Full time(mm:ss)=	9:33
#Project=	21_11_22
#Sample=	BU04w
#Site=
#Title=	BU04w-A-FF3-FI06-V_1800 (450-850nm)_633nm_Edge_100%_x100_VIS_LWD_H50um_45sX2
#Remark=
#Date=	22.11.2021 11:14
#Acquired=	22.11.2021 11:14:53
1200.03	294.495
1201.07	296.475
1202.1	295.643
1203.13	294.611
1204.16	293.76
1205.2	296.603
1206.23	297.222
1207.26	296.805
1208.29	290.835
1209.32	295.728
1210.35	295.028
1211.38	297.571
1212.41	293.489
1213.44	294.842
1214.47	301.863
1215.5	294.244
1216.53	296.757
1217.56	295.256
1218.58	296.088
1219.61	297.924
1220.64	299.728
1221.67	295.37
1222.7	296.589
1223.72	299.358
1224.75	295.145
1225.78	294.697
1226.8	310.064
1227.83	297.007
1228.85	298.336
1229.88	295.98
1230.91	297.434
1231.93	302.521
1232.96	302.309
1233.98	300.929
1235	301.558
1236.03	305.568
1237.05	301.042
1238.07	300.618
1239.1	300.041
1240.12	302.824
1241.14	304.658
1242.17	299.543
1243.19	299.867
1244.21	300.366
1245.23	302.344
1246.25	299.338
1247.27	301.262
1248.3	303.74
1249.32	302.797
1250.34	304.285
1251.36	309.601
1252.38	305.136
1253.4	304.646
1254.42	305.238
1255.43	304.793
1256.45	306.83
1257.47	305.606
1258.49	303.066
1259.51	305.856
1260.53	306.08
1261.54	308.61
1262.56	309.771
1263.58	310.535
1264.59	310.152
1265.61	307.403
1266.63	304.91
1267.64	305.038
1268.66	305.861
1269.67	305.364
1270.69	307.78
1271.7	306.526
1272.72	306.591
1273.73	306.274
1274.75	303.624
1275.76	304
1276.77	305.494
1277.79	304.458
1278.8	308.057
1279.82	303.281
1280.83	304.17
1281.84	307.717
1282.85	309.857
1283.86	351.366
1284.88	339.949
1285.89	303.687
1286.9	306.247
1287.91	302.329
1288.92	301.045
1289.93	305.771
1290.94	305.624
1291.95	303.137
1292.96	301.893
1293.97	300.048
1294.98	297.622
1295.99	299.748
1296.99	306.143
1298	299.286
1299.01	299.25
1300.02	300.532
1301.03	301.313
1302.03	302.355
1303.04	301.132
1304.05	299.654
1305.05	301.793
1306.06	303.132
1307.07	300.89
1308.07	308.283
1309.08	299.969
1310.08	302.094
1311.09	301.003
1312.09	301.546
1313.1	303.497
1314.1	299.985
1315.1	305.275
1316.11	302.854
1317.11	300.088
1318.12	301.499
1319.12	303.524
1320.12	302.974
1321.12	305.719
1322.12	303.289
1323.13	304.782
1324.13	300.991
1325.13	303.797
1326.13	302.648
1327.13	305.086
1328.13	307.207
1329.13	302.636
1330.13	305.793
1331.13	307.064
1332.13	306.102
1333.13	307.491
1334.13	309.966
1335.13	310.185
1336.13	304.212
1337.13	307.577
1338.12	311.935
1339.12	306.988
1340.12	307.578
1341.12	309.082
1342.11	305.481
1343.11	309.642
1344.11	306.882
1345.1	307.148
1346.1	308.343
1347.09	304.911
1348.09	308.984
1349.08	306.859
1350.08	307.522
1351.07	309.733
1352.07	310.078
1353.06	307.134
1354.06	307.095
1355.05	308.558
1356.04	310.666
1357.04	308.348
1358.03	308.028
1359.02	309.363
1360.02	314.06
1361.01	312.442
1362	313.584
1362.99	309.563
1363.98	310.679
1364.97	309.842
1365.97	309.273
1366.95	307.785
1367.95	310.635
1368.94	316.792
1369.93	310.272
1370.91	312.529
1371.91	311.824
1372.89	312.008
1373.88	311.026
1374.87	307.604
1375.86	311.895
1376.85	314.418
1377.84	312.688
1378.82	313.466
1379.81	309.585
1380.8	318.558
1381.78	315.395
1382.77	310.196
1383.76	310.699
1384.74	316.991
1385.73	322.252
1386.72	338.252
1387.7	459.125
1388.68	321.471
1389.67	313.534
1390.65	315.902
1391.64	313.682
1392.62	311.393
1393.61	310.71
1394.59	309.02
1395.57	314.488
1396.56	310.11
1397.54	314.104
1398.52	311.49
1399.5	305.603
1400.49	309.015
1401.47	310.251
1402.45	309.676
1403.43	313.046
1404.41	311.285
1405.39	308.16
1406.37	314.833
1407.35	311.043
1408.33	315.619
1409.31	313.875
1410.29	310.418
1411.27	307.753
1412.25	308.576
1413.23	310.464
1414.21	311.358
1415.19	306.984
1416.16	308.497
1417.14	308.482
1418.12	310.461
1419.1	312.767
1420.07	310.853
1421.05	313.343
1422.03	311.717
1423	310.387
1423.98	312.879
1424.95	313.044
1425.93	317.17
1426.9	312.221
1427.88	311.635
1428.85	314.007
1429.83	316.555
1430.8	317.693
1431.78	312.634
1432.75	312.964
1433.72	314.234
1434.7	313.062
1435.67	315.129
1436.64	313.881
1437.62	311.106
1438.59	314.211
1439.56	309.526
1440.53	325.113
1441.5	316.158
1442.47	311.395
1443.44	312.113
1444.42	318.147
1445.39	312.374
1446.36	315.266
1447.33	315.093
1448.29	316.141
1449.26	319.105
1450.23	315.01
1451.2	316.274
1452.17	314.506
1453.14	319.506
1454.11	314.86
1455.07	313.386
1456.04	317.275
1457.01	315.605
1457.98	316.319
1458.94	314.775
1459.91	314.729
1460.88	315.369
1461.84	314.813
1462.81	311.768
1463.77	315.652
1464.74	315.151
1465.61	314.509
1466.59	316.904
1467.57	316.408
1468.55	317.85
1469.53	316.214
1470.51	312.971
1471.49	316
1472.47	313.137
1473.45	315.631
1474.43	317.481
1475.4	317.19
1476.38	317.667
1477.36	314.392
1478.34	318.924
1479.32	316.698
1480.29	315.789
1481.27	315.17
1482.25	318.584
1483.22	316.144
1484.2	312.463
1485.18	315.197
1486.15	314.639
1487.13	312.91
1488.1	314.577
1489.08	317.308
1490.05	313.283
1491.03	316.676
1492	317.681
1492.98	319.549
1493.95	315.894
1494.92	321.722
1495.9	319.038
1496.87	314.096
1497.84	316.476
1498.82	315.845
1499.79	318.192
1500.76	317.187
1501.73	317.147
1502.7	311.75
1503.68	316.778
1504.65	314.75
1505.62	319.87
1506.59	316.674
1507.56	319.645
1508.53	320.518
1509.5	317.592
1510.47	323.189
1511.44	320.983
1512.41	318.931
1513.38	319.089
1514.35	318.865
1515.31	317.445
1516.28	323.972
1517.25	320.273
1518.22	316.294
1519.19	319.426
1520.15	317.937
1521.12	319.979
1522.09	322.796
1523.05	321.657
1524.02	321.058
1524.99	318.689
1525.95	322.3
1526.92	322.711
1527.88	326.96
1528.85	322.407
1529.81	323.387
1530.78	320.42
1531.74	321.835
1532.71	328.28
1533.67	324.951
1534.63	321.172
1535.6	322.61
1536.56	321.112
1537.52	324.874
1538.49	322.929
1539.45	321.726
1540.41	325.125
1541.37	320.849
1542.33	324.837
1543.29	329.245
1544.26	324.778
1545.22	324.716
1546.18	327.325
1547.14	325.146
1548.1	326.036
1549.06	323.518
1550.02	326.149
1550.98	328.231
1551.94	323.97
1552.9	323.462
1553.85	324.832
1554.81	325.496
1555.77	326.4
1556.73	320.67
1557.69	323.45
1558.64	325.093
1559.6	323.602
1560.56	325.387
1561.52	329.464
1562.47	327.401
1563.43	330.796
1564.38	322.39
1565.34	326.619
1566.3	324.343
1567.25	325.128
1568.21	322.454
1569.16	329.169
1570.12	332.371
1571.07	325.69
1572.02	325.906
1572.98	325.538
1573.93	329.24
1574.89	327.928
1575.84	327.458
1576.79	323.187
1577.74	332.759
1578.7	327.456
1579.65	325.692
1580.6	326.939
1581.55	322.815
1582.5	324.337
1583.46	326.341
1584.41	324.265
1585.36	326.086
1586.31	327.135
1587.26	327.666
1588.21	325.292
1589.16	328.254
1590.11	341.101
1591.06	327.495
1592.01	324.477
1592.95	324.657
1593.9	333.731
1594.85	327.86
1595.8	322.839
1596.75	324.336
1597.69	330.609
1598.64	326.333
1599.59	324.911
1600.54	328.282
1601.48	324.908
1602.43	325.608
1603.38	326.431
1604.32	323.306
1605.27	327.853
1606.21	325.211
1607.16	325.758
1608.1	329.417
1609.05	327.266
1609.99	327.059
1610.94	327.855
1611.88	326.605
1612.82	332.15
1613.77	325.751
1614.71	329.485
1615.65	327.111
1616.6	328.177
1617.54	327.984
1618.48	340.42
1619.42	332.251
1620.36	330.279
1621.3	332.67
1622.25	335.551
1623.19	333.652
1624.13	335.382
1625.07	329.063
1626.01	333.041
1626.95	328.996
1627.89	332.896
1628.83	336.907
1629.77	329.89
1630.71	334.322
1631.65	331.8
1632.58	331.204
1633.52	331.092
1634.46	332.887
1635.4	334.202
1636.34	333.163
1637.27	330.752
1638.21	331.203
1639.15	335.431
1640.09	333.252
1641.02	334.711
1641.96	335.519
1642.89	335.963
1643.83	334.901
1644.77	334.369
1645.7	336.314
1646.64	339.293
1647.57	331.298
1648.51	335.024
1649.44	338.641
1650.37	338.769
1651.31	340.66
1652.24	334.361
1653.17	335.101
1654.11	339.564
1655.04	335.745
1655.97	333.027
1656.91	339.542
1657.84	339.226
1658.77	336.797
1659.7	339.849
1660.63	338.392
1661.56	339.829
1662.49	336.385
1663.43	339.075
1664.36	337.36
1665.29	339.759
1666.22	337.222
1667.15	333.168
1668.07	338.529
1669.01	339.818
1669.93	341.001
1670.86	339.567
1671.79	338.756
1672.72	336.895
1673.65	343.043
1674.58	340.749
1675.5	338.835
1676.43	338.234
1677.36	335.033
1678.28	337.494
1679.21	334.097
1680.14	335.466
1681.06	336.02
1681.99	338.353
1682.92	338.734
1683.84	335.296
1684.77	338.213
1685.69	334.337
1686.61	344.14
1687.54	341.348
1688.46	337.114
1689.39	337.191
1690.31	340.393
1691.24	335.082
1692.16	334.814
1693.08	335.492
1694.01	337.94
1694.93	335.192
1695.85	336.185
1696.77	334.433
1697.69	336.015
1698.61	334.596
1699.54	335.28
1700.46	334.72
1701.38	335.652
1702.3	335.521
1703.22	334.661
1704.11	335.089
1705.04	343.31
1705.98	333.564
1706.92	335.922
1707.85	336.762
1708.78	335.412
1709.72	335.864
1710.65	334.571
1711.59	334.599
1712.52	335.004
1713.45	334.566
1714.39	337.877
1715.32	334.595
1716.25	337.739
1717.19	337.196
1718.12	336.445
1719.05	342.469
1719.98	340.357
1720.91	342.06
1721.84	339.742
1722.77	334.647
1723.7	337.281
1724.64	339.254
1725.57	339.382
1726.5	336.667
1727.43	339.742
1728.36	339.541
1729.29	337.16
1730.21	336.964
1731.14	338.705
1732.07	345.125
1733	341.568
1733.93	340.724
1734.86	338.368
1735.78	341.167
1736.71	345.099
1737.64	338.698
1738.57	343.164
1739.49	343.939
1740.42	339.209
1741.35	340.048
1742.27	343.18
1743.2	339.152
1744.12	339.011
1745.05	346.248
1745.97	344.28
1746.9	341.267
1747.82	346.236
1748.75	348.575
1749.67	344.326
1750.6	343.2
1751.52	340.873
1752.44	341.8
1753.37	344.42
1754.29	343.642
1755.21	344.835
1756.14	342.252
1757.06	340.041
1757.98	341.482
1758.9	342.751
1759.82	342.864
1760.75	343.977
1761.67	343.447
1762.59	338.807
1763.51	344.194
1764.43	343.928
1765.35	343.948
1766.27	342.542
1767.19	343.104
1768.11	344.835
1769.03	340.994
1769.95	345.714
1770.87	344.858
1771.79	345.343
1772.7	344.534
1773.62	343.875
1774.54	345.056
1775.46	342.701
1776.38	344.547
1777.29	343.312
1778.21	348.924
1779.13	349.215
1780.04	345.509
1780.96	344.973
1781.88	343.672
1782.79	345.416
1783.71	342.739
1784.62	346.027
1785.54	341.393
1786.45	347.108
1787.37	347.67
1788.28	344.326
1789.2	344.435
1790.11	347.068
1791.02	343.542
1791.94	350.67
1792.85	344.756
1793.76	344.132
1794.68	343.183
1795.59	345.134
1796.5	342.212
1797.42	343.589
1798.33	356.487
1799.24	346.611
1800.15	346.227
1801.06	346.712
1801.97	347.962
1802.88	345.972
1803.79	351.676
1804.71	351.125
1805.62	350.076
1806.53	348.62
1807.44	342.985
1808.34	347.913
1809.25	347.783
1810.16	344.824
1811.07	345.207
1811.98	350.004
1812.89	345.212
1813.8	347.536
1814.7	352.764
1815.61	355.401
1816.52	350.77
1817.43	352.512
1818.33	344.718
1819.24	349.793
1820.15	350.352
1821.05	345.487
1821.96	347.765
1822.86	351.799
1823.77	354.076
1824.67	347.437
1825.58	348.79
1826.48	350.418
1827.39	351.605
1828.29	352.638
1829.2	350.89
1830.1	353.142
1831	352.934
1831.91	353.263
1832.81	351.724
1833.71	357.019
1834.62	349.609
1835.52	349.231
1836.42	358.573
1837.32	355.033
1838.23	351.854
1839.13	355.208
1840.03	357.917
1840.93	355.471
1841.83	353.924
1842.73	354.179
1843.63	354.066
1844.53	357.389
1845.43	357.658
1846.33	358.006
1847.23	354.248
1848.13	355.89
1849.03	358.577
1849.93	358.677
1850.83	359.959
1851.73	360.048
1852.62	360.878
1853.52	358.071
1854.42	359.413
1855.32	356.222
1856.21	359.096
1857.11	353.942
1858.01	358.222
1858.91	356.702
1859.8	358.19
1860.7	362.926
1861.59	363.041
1862.49	357.207
1863.38	362.089
1864.28	360.934
1865.17	365.408
1866.07	355.465
1866.96	358.591
1867.86	359.577
1868.75	359.286
1869.65	362.798
1870.54	361.986
1871.43	360.034
1872.33	359.881
1873.22	358.263
1874.11	360.1
1875	357.895
1875.9	357.788
1876.79	360.696
1877.68	357.355
1878.57	357.581
1879.46	363.778
1880.35	360.756
1881.24	356.589
1882.13	360.918
1883.03	361.177
1883.91	362.49
1884.81	362.823
1885.7	359.18
1886.58	366.958
1887.47	364.258
1888.36	362.566
1889.25	363.192
1890.14	361.797
1891.03	365.521
1891.92	363.08
1892.8	358.981
1893.69	359.103
1894.58	360.432
1895.47	362.672
1896.35	361.199
1897.24	360.347
1898.13	364.037
1899.01	360.656
1899.9	364.948
1900.78	360.443
1901.67	361.862
1902.56	362.855
1903.44	360.184
1904.33	362.243
1905.21	363.902
1906.09	360.022
1906.98	362.234
1907.86	362.383
1908.75	362.107
1909.63	360.618
1910.51	367.036
1911.4	369.468
1912.28	361.259
1913.16	364.512
1914.04	362.412
1914.93	364.78
1915.81	362.757
1916.69	369.07
1917.57	368.708
1918.45	365.241
1919.33	363.182
1920.21	368.022
1921.09	368.879
1921.97	364.321
1922.86	368.954
1923.74	364.064
1924.61	365.513
1925.49	367.044
1926.37	367.532
1927.25	365.71
1928.13	365.738
1929.01	363.278
1929.89	364.663
1930.77	364.693
1931.55	370.187
1932.44	367.153
1933.33	369.061
1934.22	368.539
1935.12	367.063
1936.01	367.8
1936.9	366.607
1937.79	368.484
1938.68	364.039
1939.57	370.348
1940.46	367.904
1941.35	369.132
1942.25	367.488
1943.14	370.125
1944.03	368.897
1944.92	368.926
1945.8	377.995
1946.69	370.857
1947.58	368.13
1948.47	368.388
1949.36	369.278
1950.25	365.958
1951.14	369.225
1952.03	371.985
1952.91	366.985
1953.8	370.448
1954.69	366.624
1955.58	368.34
1956.46	367.534
1957.35	369.938
1958.24	368.188
1959.12	372.151
1960.01	369.832
1960.89	369.183
1961.78	372.735
1962.67	366.526
1963.55	372.192
1964.44	367.946
1965.32	367.339
1966.2	374.088
1967.09	383.565
1967.97	371.336
1968.86	367.576
1969.74	370.223
1970.62	368.702
1971.51	371.471
1972.39	364.725
1973.27	370.541
1974.16	371.52
1975.04	374.518
1975.92	373.155
1976.8	371.391
1977.68	372.512
1978.56	373.024
1979.45	371.135
1980.33	370.705
1981.21	376.419
1982.09	371.914
1982.97	371.686
1983.85	369.035
1984.73	371.167
1985.61	371.054
1986.49	367.032
1987.37	372.467
1988.24	374.534
1989.12	371.918
1990	370.333
1990.88	372.61
1991.76	370.91
1992.64	368.361
1993.51	375.027
1994.39	371.485
1995.27	372.174
1996.15	370.23
1997.02	367.813
1997.9	373.393
1998.77	366.288
1999.65	372.383
2000.53	369.862
2001.4	370.567
2002.28	368.825
2003.15	372.386
2004.03	369.943
2004.9	369.421
2005.78	371.599
2006.65	376.637
2007.52	370.184
2008.4	369.963
2009.27	367.457
2010.15	372.827
2011.02	369.66
2011.89	368.101
2012.77	375.416
2013.64	369.446
2014.51	372.18
2015.38	372.76
2016.25	369.783
2017.13	374.36
2018	369.852
2018.87	370.78
2019.74	371.097
2020.61	371.075
2021.48	372.97
2022.35	372.861
2023.22	367.81
2024.09	380.138
2024.96	371.961
2025.83	369.43
2026.7	378.545
2027.57	375.415
2028.44	372.5
2029.31	368.476
2030.17	369.915
2031.04	370.094
2031.91	371.795
2032.78	372.815
2033.64	378.869
2034.51	372.44
2035.38	373.296
2036.25	374.213
2037.11	372.748
2037.98	375.087
2038.85	373.625
2039.71	372.285
2040.58	375.813
2041.44	369.471
2042.31	379.529
2043.17	368.883
2044.04	375.843
2044.9	372.696
2045.77	378.613
2046.63	372.192
2047.49	376.338
2048.36	372.477
2049.22	376.249
2050.09	372.561
2050.95	376.681
2051.81	381.314
2052.67	374.848
2053.54	377.535
2054.4	378.355
2055.26	377.716
2056.12	379.848
2056.98	372.917
2057.84	378.403
2058.71	376.166
2059.57	376.204
2060.43	378.323
2061.29	381.243
2062.15	376.235
2063.01	379.433
2063.87	378.44
2064.73	372.56
2065.59	379.22
2066.45	380.305
2067.3	377.5
2068.16	378.44
2069.02	376.083
2069.88	375.019
2070.74	376.51
2071.6	377.064
2072.45	380.609
2073.31	378.234
2074.17	375.273
2075.02	377.935
2075.88	378.616
2076.74	376.452
2077.59	376.632
2078.45	376.145
2079.31	378.496
2080.16	380.771
2081.02	377.056
2081.87	376.768
2082.73	384.156
2083.58	379.993
2084.44	381.92
2085.29	380.77
2086.15	382.748
2087	382.387
2087.85	378.096
2088.71	381.329
2089.56	382.728
2090.41	387.879
2091.26	381.503
2092.12	377.76
2092.97	383.264
2093.82	380.868
2094.67	380.321
2095.53	380.829
2096.38	384.521
2097.23	381.712
2098.08	387.353
2098.93	382.847
2099.78	383.498
2100.63	379.637
2101.48	379.918
2102.33	388.942
2103.18	383.581
2104.03	383.188
2104.88	379.448
2105.73	384.544
2106.58	379.645
2107.43	381.284
2108.27	378.316
2109.12	381.991
2109.97	384.145
2110.82	380.995
2111.67	385.43
2112.51	388.688
2113.36	386.277
2114.21	382.171
2115.05	379.212
2115.9	385.698
2116.75	389.359
2117.59	386.482
2118.44	391.219
2119.28	391.082
2120.13	394.373
2120.98	391.772
2121.82	387.436
2122.66	386.551
2123.51	383.178
2124.35	386.355
2125.2	389.095
2126.04	386.109
2126.88	389.409
2127.73	390.512
2128.57	389.154
2129.41	391.957
2130.26	388.836
2131.1	391.006
2131.94	391.916
2132.78	389.45
2133.63	390.601
2134.47	393.159
2135.31	388.202
2136.15	390.637
2136.99	391.581
2137.83	391.559
2138.67	391.382
2139.51	391.468
2140.35	394.152
2141.19	392.873
2142.03	391.739
2142.87	390.673
2143.71	394.607
2144.55	390.89
2145.39	393.125
2146.23	391.224
2147.07	394.098
2147.9	396.041
2148.66	392.838
2149.51	396.961
2150.36	394.641
2151.22	392.641
2152.07	396.271
2152.92	395.826
2153.77	394.12
2154.62	393.488
2155.48	395.313
2156.33	395.49
2157.18	395.419
2158.03	394.71
2158.88	393.14
2159.73	394.714
2160.58	394.932
2161.43	396.158
2162.28	394.022
2163.13	395.874
2163.98	397.019
2164.83	396.825
2165.68	396.489
2166.52	391.735
2167.37	396.784
2168.22	395.217
2169.07	396.413
2169.91	391.293
2170.76	396.165
2171.61	395.744
2172.46	398.564
2173.3	392.666
2174.15	395.898
2175	398.723
2175.84	397.581
2176.69	391.847
2177.53	390.912
2178.38	400.071
2179.23	393.372
2180.07	396.95
2180.92	394.003
2181.76	402.264
2182.61	391.596
2183.45	397.948
2184.29	395.498
2185.14	393.668
2185.98	398.893
2186.82	398.803
2187.67	399.247
2188.51	393.967
2189.35	393.845
2190.2	397.027
2191.04	395.527
2191.88	393.431
2192.72	400.523
2193.56	394.452
2194.41	396.217
2195.25	393.06
2196.09	397.997
2196.93	394.6
2197.77	392.987
2198.61	401.088
2199.45	395.056
2200.29	395.372
2201.13	396.234
2201.97	395.624
2202.81	398.553
2203.65	398.323
2204.49	397.178
2205.33	392.112
2206.16	395.637
2207	397.27
2207.84	393.979
2208.68	395.142
2209.52	396.555
2210.35	398.094
2211.19	401.09
2212.03	392.03
2212.87	398.822
2213.7	398.731
2214.54	395.021
2215.38	401.69
2216.21	399.556
2217.05	395.384
2217.88	397.62
2218.72	400.893
2219.55	395.955
2220.39	399.445
2221.22	401.671
2222.06	397.981
2222.89	397.035
2223.73	398.189
2224.56	394.482
2225.39	397.066
2226.23	401.69
2227.06	399.339
2227.89	402.092
2228.73	398.693
2229.56	399.754
2230.39	406.632
2231.22	403.163
2232.06	403.651
2232.89	405.668
2233.72	402.407
2234.55	404.319
2235.38	401.031
2236.21	411.4
2237.04	403.225
2237.88	402.903
2238.71	405.381
2239.53	407.618
2240.37	403.801
2241.2	405.85
2242.02	402.281
2242.85	403.536
2243.68	404.181
2244.51	401.148
2245.34	401.972
2246.17	404.29
2247	402.471
2247.83	404.458
2248.65	405.351
2249.48	409.468
2250.31	411.253
2251.14	410.126
2251.96	404.547
2252.79	412.123
2253.62	404.848
2254.44	404.219
2255.27	407.729
2256.09	406.121
2256.92	407.728
2257.75	408.478
2258.57	409.101
2259.4	414.251
2260.22	409.065
2261.05	413.726
2261.87	408.502
2262.69	413.669
2263.52	408.523
2264.34	411.998
2265.17	410.817
2265.99	407.81
2266.81	407.765
2267.64	409.365
2268.46	405.433
2269.28	413.911
2270.1	410.818
2270.93	413.502
2271.75	409.465
2272.57	410.261
2273.39	410.99
2274.21	412.692
2275.03	405.991
2275.85	411.81
2276.67	410.901
2277.5	414.283
2278.32	411.209
2279.14	410.357
2279.96	415.019
2280.78	410.564
2281.59	408.834
2282.41	413.345
2283.23	416.653
2284.05	408.69
2284.87	412.035
2285.69	412.8
2286.51	408.986
2287.33	412.855
2288.14	408.23
2288.96	410.123
2289.78	413.086
2290.6	419.742
2291.41	413.731
2292.23	410.84
2293.05	417.238
2293.86	417.002
2294.68	410.282
2295.49	411.158
2296.31	409.94
2297.13	408.741
2297.94	409.815
2298.75	412.992
2299.57	414.343
2300.39	414.6
2301.2	415.015
2302.01	413.727
2302.83	414.746
2303.64	413.967
2304.46	414.321
2305.27	420.176
2306.08	415.55
2306.89	413.385
2307.71	409.733
2308.52	417.305
2309.33	413.516
2310.14	416.606
2310.96	414.018
2311.77	414.794
2312.58	415.996
2313.39	416.554
2314.2	414.855
2315.01	412.088
2315.82	412.127
2316.63	415.636
2317.44	416.032
2318.26	415.605
2319.06	416.461
2319.87	413.799
2320.68	418.682
2321.49	417.197
2322.3	417.427
2323.11	417.237
2323.92	416.082
2324.73	418.569
2325.54	415.868
2326.34	419.727
2327.15	420.136
2327.96	419.702
2328.77	419.16
2329.57	420.11
2330.38	422.115
2331.19	418.801
2331.99	418.799
2332.8	416.368
2333.61	420.729
2334.41	417.897
2335.22	415.994
2336.02	418.729
2336.83	422.054
2337.63	416.04
2338.44	424.483
2339.24	421.016
2340.05	421.397
2340.85	416.72
2341.66	426.897
2342.46	420.935
2343.26	420.343
2344.07	421.644
2344.87	425.205
2345.67	420.59
2346.48	420.97
2347.28	422.287
2348.08	422.179
2348.88	424.411
2349.69	423.379
2350.49	420.589
2351.29	420.936
2352.09	422.874
2352.89	422.08
2353.69	423.119
2354.49	425.053
2355.17	421.269
2355.99	423.662
2356.8	424.247
2357.62	430.092
2358.43	424.321
2359.25	427.677
2360.06	428.252
2360.88	423.722
2361.69	426.486
2362.5	426.448
2363.32	426.982
2364.13	427.342
2364.94	427.337
2365.76	426.246
2366.57	426.421
2367.38	426.853
2368.19	426.7
2369	428.192
2369.82	423.264
2370.63	428.914
2371.44	430.776
2372.25	430.308
2373.06	432.397
2373.87	429.01
2374.68	426.346
2375.49	427.809
2376.3	429.615
2377.11	427.836
2377.92	430.473
2378.73	429.113
2379.54	430.746
2379.94	434.27