File: Data/3-Raman/raw/bu04w-a-ff3-fi06-l_150 (500nm)_633nm_edge_100%_x100_vis_lwd_h50um_45sx2_01.txt
#Acq. time (s)=	45
#Accumulations=	2
#Range (cm-¹)=	100...4000
#Windows=	1
#Auto scanning=	Off
#Autofocus=	Off
#Macrospot=	Off
#AutoExposure=	Off
#Spike filter=	Multiple accum.
#Delay time (s)=	2
#Binning=	1
#Readout mode=	Signal
#DeNoise=	Off
#ICS correction=	On
#Dark correction=	Off
#Inst. Process=	Off
#Detector Gain=	Best Dynamic
#Detector ADC=	50 kHz HS
#Detector temperature (°C)=	-60.09
#Instrument=	LabRAM HR Evol
#Detector=	SIN-EM FIVIS
#Objective=	x100_VIS_LWD
#Grating=	150 (500nm)
#ND Filter=	100%
#Laser=	633nm_Edge
#Hole=	49.98
#Temperature=	0
#Range=	Visible
#StageXY=	75x50mm Scan+
#StageZ=	Z motor
#X (µm)=	0
#Y (µm)=	0
#Z (µm)=	-8.5
#Full time(mm:ss)=	1:35
#Project=	21_11_22
#Sample=	BU04w
#Site=
#Title=	BU04w-A-FF3-FI06-L_150 (500nm)_633nm_Edge_100%_x100_VIS_LWD_H50um_45sX2
#Remark=
#Date=	22.11.2021 11:04
#Acquired=	22.11.2021 11:04:57
100.177	592.376
106.695	550.879
113.209	522.794
119.717	509.821
126.219	491.043
132.716	483.648
139.208	477.007
145.694	470.39
152.175	437.962
158.651	477.473
165.121	575.522
171.586	459.694
178.045	357.986
184.5	315.541
190.947	295.947
197.39	280.231
203.829	261.029
210.262	246.623
216.688	247.484
223.11	271.188
229.527	332.72
235.939	494.008
242.344	426.098
248.745	295.866
255.141	270.987
261.53	288.89
267.916	243.276
274.294	232.824
280.669	267.888
287.038	281.992
293.402	235.359
299.76	217.184
306.114	226.428
312.461	267.785
318.805	369.497
325.142	668.469
331.475	752.281
337.802	436.178
344.123	312.556
350.441	251.151
356.752	248.125
363.058	264.815
369.36	267.362
375.656	249.24
381.947	215.226
388.232	203.97
394.512	205.133
400.789	208.397
407.059	216.375
413.324	239.448
419.584	268.155
425.839	321.188
432.089	413
438.333	419.547
444.573	333.949
450.807	307.678
457.037	328.353
463.261	293.274
469.48	227.791
475.695	205.391
481.904	220.344
488.108	205.457
494.307	220.42
500.502	253.097
506.691	272.814
512.874	317.802
519.053	311.598
525.227	271.897
531.396	255.644
537.559	248.83
543.718	231.433
549.873	209.953
556.022	194.071
562.165	199.568
568.304	175.654
574.437	185.49
580.567	167.093
586.691	169.463
592.81	171.988
598.924	211.011
605.033	226.199
611.138	212.586
617.236	203.774
623.332	195.942
629.42	187.077
635.506	184.413
641.585	171.077
647.659	168.895
653.73	183.568
659.794	208.361
665.854	195.677
671.91	171.078
677.96	139.417
684.005	140.404
690.045	134.074
696.082	136.252
702.113	127.16
708.139	138.662
714.16	138.649
720.176	133.865
726.187	132.819
732.194	123.215
738.196	122.992
744.193	129.322
750.185	131.026
756.173	124.431
762.155	119.919
768.133	119.305
774.107	125.281
780.075	122.754
786.039	114.457
791.998	113.627
797.952	113.656
803.902	118.291
809.845	117.214
815.786	128.271
821.721	126.1
827.652	121.107
833.576	121.913
839.498	121.06
845.415	127.841
851.327	118.727
857.233	118.083
863.135	119.351
869.032	136.709
874.925	143.593
880.813	141.828
886.697	144.718
892.576	137.072
898.45	136.918
904.318	141.323
910.184	140.014
916.044	141.538
921.9	154.517
927.75	162.044
933.596	194.236
939.439	216.526
945.275	280.767
951.107	364.622
956.936	363.068
962.759	321.986
968.577	287.168
974.391	291.343
980.201	347.836
986.006	447.005
991.806	492.155
997.602	429.214
1003.39	356.178
1009.18	361.722
1014.96	384.974
1020.74	470.36
1026.51	530.705
1032.28	430.352
1038.04	288.253
1043.8	228.319
1049.56	204.77
1055.31	174.143
1061.05	178.24
1066.8	165.605
1072.53	165.558
1078.26	180.967
1083.99	219.571
1089.72	251.385
1095.44	318.036
1101.15	428.116
1106.86	329.557
1112.56	226.18
1118.27	183.213
1123.96	165.152
1129.65	162.617
1135.34	180.651
1141.03	215.46
1146.7	271.861
1152.38	400.204
1158.05	478.947
1163.71	263.941
1169.37	173.184
1175.03	143.464
1180.68	123.642
1186.33	126.466
1191.98	110.857
1197.61	121.759
1203.25	110.326
1208.88	112.691
1214.51	97.3279
1220.13	104.725
1225.74	108.226
1231.36	96.6922
1236.97	111.136
1242.57	105.379
1248.17	105.531
1253.77	88.4117
1259.36	102.494
1264.94	107.391
1270.53	106.224
1276.11	99.9729
1281.68	100.752
1287.25	102.58
1292.81	105.462
1298.38	97.4354
1303.93	98.4752
1309.48	100.648
1315.03	99.953
1320.58	99.2823
1326.12	95.6188
1331.65	94.991
1337.18	91.2469
1342.71	100.705
1348.23	97.8377
1353.75	88.7717
1359.26	99.145
1364.77	93.0163
1370.28	86.8264
1375.78	143.288
1381.28	137.067
1386.77	107.241
1392.26	99.0104
1397.74	95.0116
1403.23	86.912
1408.7	82.935
1414.17	96.5192
1419.64	94.6689
1425.11	85.5709
1430.56	88.9126
1436.02	86.0102
1441.47	87.2604
1446.92	89.5749
1452.36	88.6569
1457.8	91.8716
1463.23	93.9818
1468.66	91.8568
1474.09	92.8872
1479.51	88.7145
1484.93	82.4599
1490.34	85.7007
1495.75	91.1058
1501.16	95.5051
1506.56	89.3771
1511.96	91.7427
1517.35	85.6463
1522.74	87.0014
1528.13	90.5187
1533.51	95.1644
1538.88	86.8295
1544.25	92.4369
1549.62	95.7377
1554.99	91.3386
1560.35	89.0674
1565.71	84.6662
1571.06	85.6531
1576.41	95.2659
1581.75	79.1195
1587.09	97.447
1592.43	94.2783
1597.76	99.7849
1603.09	103.186
1608.41	91.5076
1613.73	98.3119
1619.05	93.2311
1624.36	106.724
1629.67	97.2365
1634.97	94.251
1640.27	102.143
1645.57	101.2
1650.86	99.1132
1656.15	103.635
1661.43	101.456
1666.71	94.8204
1671.99	104.806
1677.26	98.1363
1682.53	88.1261
1687.79	98.0126
1693.05	95.746
1698.31	94.6825
1703.56	88.3856
1708.81	85.4269
1714.06	95.3275
1719.3	88.8886
1724.53	86.7839
1729.77	81.3551
1735	91.6416
1740.22	90.6909
1745.44	96.5079
1750.66	86.4745
1755.87	89.965
1761.08	87.7403
1766.29	86.6421
1771.49	85.5597
1776.69	86.7632
1781.88	85.7494
1787.07	85.8972
1792.26	91.7902
1797.44	96.5777
1802.62	87.6747
1807.79	91.3566
1812.96	92.7045
1818.13	91.7543
1823.29	95.4228
1828.45	92.1633
1833.61	84.2507
1838.76	87.9449
1843.91	91.6075
1849.05	80.069
1854.19	83.6843
1859.33	92.0283
1864.46	87.5095
1869.59	90.046
1874.71	98.426
1879.83	86.7465
1884.95	82.1138
1890.06	90.4397
1895.17	85.7147
1900.28	84.5756
1905.38	85.9113
1910.48	83.7353
1915.57	84.0136
1920.66	87.7316
1925.75	83.112
1930.83	90.4629
1935.91	77.4213
1940.99	91.9602
1946.06	92.0647
1951.13	88.5257
1956.19	89.7683
1961.26	90.9956
1966.31	86.179
1971.36	93.369
1976.41	92.1121
1981.46	90.8562
1986.5	88.4045
1991.54	93.1813
1996.58	88.3537
2001.61	83.5515
2006.63	88.399
2011.66	83.6508
2016.68	93.3552
2021.69	89.7925
2026.71	92.3103
2031.72	79.1624
2036.72	91.4237
2041.72	89.1783
2046.72	85.7211
2051.71	94.4398
2056.71	92.1536
2061.69	89.9127
2066.68	96.2484
2071.66	92.7654
2076.63	91.7265
2081.6	96.8337
2086.57	80.9202
2091.54	95.8852
2096.5	93.6111
2101.46	85.1315
2106.41	99.0586
2111.36	86.8447
2116.31	95.889
2121.25	91.1561
2126.19	90.1641
2131.13	95.469
2136.06	90.6325
2140.99	98.457
2145.92	92.294
2150.84	98.814
2155.76	95.1046
2160.67	92.634
2165.58	97.7924
2170.49	88.8726
2175.39	92.7809
2180.29	88.9739
2185.19	90.2431
2190.08	91.5377
2194.98	96.7107
2199.86	92.969
2204.74	87.9744
2209.62	86.8561
2214.5	107.68
2219.37	98.8993
2224.24	87.487
2229.11	86.4103
2233.97	94.4463
2238.83	89.461
2243.68	89.6868
2248.53	93.8558
2253.38	98.0358
2258.22	99.6062
2263.06	87.9481
2267.9	84.1468
2272.73	81.6238
2277.56	97.6691
2282.39	99.076
2287.21	92.4531
2292.03	92.4787
2296.85	93.8387
2301.66	85.9224
2306.47	75.3693
2311.28	91.5527
2316.08	87.7425
2320.88	78.566
2325.68	86.8488
2330.47	83.0372
2335.26	91.417
2340.04	88.9879
2344.82	93.3826
2349.6	96.4604
2354.38	99.5281
2359.15	92.9163
2363.92	98.612
2368.68	89.1522
2373.44	94.8747
2378.2	96.4521
2382.95	89.6392
2387.71	92.5025
2392.45	95.3311
2397.2	86.9926
2401.94	88.3857
2406.68	92.5403
2411.41	96.8132
2416.14	90.1357
2420.87	91.9848
2425.59	93.5222
2430.31	95.1646
2435.03	82.7085
2439.75	94.3066
2444.46	87.4749
2449.16	90.5918
2453.87	90.8593
2458.57	89.6898
2463.27	92.8288
2467.96	91.6416
2472.65	97.6628
2477.34	86.3143
2482.02	92.3512
2486.7	91.0968
2491.38	89.8231
2496.05	95.8671
2500.72	97.5202
2505.39	87.4107
2510.06	84.6039
2514.72	89.1339
2519.37	92.2067
2524.03	89.4016
2528.68	101.375
2533.33	100.06
2537.97	86.8856
2542.61	81.1102
2547.25	94.7125
2551.88	96.4154
2556.51	95.1104
2561.14	98.2997
2565.77	89.5055
2570.39	95.7688
2575.01	94.5042
2579.62	90.1705
2584.23	97.9077
2588.84	98.0237
2593.45	81.3699
2598.05	89.1138
2602.65	86.1847
2607.24	95.4489
2611.84	94.0056
2616.42	91.0203
2621.01	91.1021
2625.59	92.7289
2630.17	91.3279
2634.75	94.61
2639.32	96.4433
2643.89	93.6504
2648.46	86.1874
2653.02	102.035
2657.58	86.6234
2662.14	91.4522
2666.69	102.519
2671.24	93.2938
2675.79	95.1324
2680.33	105.083
2684.88	89.6866
2689.41	96.4683
2693.95	88.8293
2698.48	95.3817
2703.01	97.1939
2707.53	98.988
2712.06	86.2593
2716.57	92.9147
2721.09	99.5666
2725.6	96.4776
2730.11	80.3587
2734.62	98.2965
2739.12	95.1062
2743.62	96.8471
2748.12	96.9949
2752.61	97.2642
2757.1	92.5682
2761.59	89.4224
2766.08	97.8109
2770.56	79.8771
2775.04	89.9591
2779.51	101.791
2783.98	98.8163
2788.45	99.1504
2792.92	107.824
2797.38	98.0702
2801.84	94.9555
2806.3	101.894
2810.75	98.7137
2815.2	103.942
2819.65	92.2504
2824.09	92.4028
2828.53	102.745
2832.97	89.2927
2837.41	94.5263
2841.84	81.018
2846.27	94.8222
2850.69	103.561
2855.12	100.378
2859.54	93.7473
2863.95	102.639
2868.37	99.5032
2872.78	103.281
2877.18	96.6409
2881.59	89.9789
2885.99	90.3049
2890.39	101.173
2894.78	92.6809
2899.18	94.8035
2903.57	102.235
2907.95	106.111
2912.34	101.02
2916.72	97.6578
2921.09	99.6954
2925.47	108.964
2929.84	98.4448
2934.21	122.267
2938.57	97.1165
2942.94	99.1163
2947.29	110.193
2951.65	108.53
2956	101.378
2960.36	103.35
2964.7	107.174
2969.05	111.035
2973.39	107.565
2977.73	104.083
2982.06	102.445
2986.4	115.647
2990.73	99.2596
2995.05	106.982
2999.38	101.712
3003.7	113.282
3008.01	115.546
3012.33	125.325
3016.64	120.086
3020.95	128.118
3025.26	120.913
3029.56	136.506
3033.86	127.252
3038.16	125.556
3042.45	120.071
3046.74	124.134
3051.03	135.913
3055.32	128.428
3059.6	142.204
3063.88	148.267
3068.16	136.879
3072.43	141.008
3076.7	147.115
3080.97	139.58
3085.24	141.825
3089.5	153.947
3093.76	154.404
3098.02	168.727
3102.27	161.367
3106.52	175.871
3110.77	172.562
3115.01	171.236
3119.26	165.881
3123.5	178.703
3127.73	189.647
3131.97	178.341
3136.2	181.256
3140.43	198.55
3144.65	207.652
3148.87	200.174
3153.09	213.317
3157.31	228.564
3161.52	231.335
3165.73	225.7
3169.94	243.111
3174.15	243.793
3178.35	248.481
3182.55	272.147
3186.75	274.613
3190.94	274.916
3195.13	281.768
3199.32	273.973
3203.51	279.245
3207.69	306.107
3211.87	292.244
3216.05	276.183
3220.22	272.96
3224.39	278.419
3228.56	275.156
3232.73	280.631
3236.89	270.56
3241.05	276.061
3245.21	263.91
3249.36	273.842
3253.52	258.925
3257.66	252.769
3261.81	260.372
3265.95	250.072
3270.1	253.478
3274.23	231.701
3278.37	243.591
3282.5	253.251
3286.63	260.654
3290.76	217.438
3294.88	250.093
3299	232.066
3303.12	237.177
3307.24	242.286
3311.35	238.082
3315.46	243.165
3319.57	236.638
3323.68	251.213
3327.78	258.891
3331.88	254.991
3335.98	258.266
3340.07	251.962
3344.16	247.77
3348.25	248.197
3352.34	272.452
3356.42	246.77
3360.5	261.658
3364.58	271.824
3368.66	267.595
3372.73	251.305
3376.8	261.344
3380.87	283.421
3384.93	245.145
3388.99	264.781
3393.05	255.375
3397.11	265.43
3401.16	251.239
3405.21	253.901
3409.26	256.582
3413.31	264.072
3417.35	266.721
3421.39	252.291
3425.43	259.785
3429.46	272.268
3433.5	262.843
3437.53	270.609
3441.55	261.283
3445.58	259.388
3449.6	262.513
3453.62	278.039
3457.64	239.262
3461.65	247.561
3465.66	260.922
3469.67	259.317
3473.68	239.926
3477.68	265.863
3481.68	236.332
3485.68	239.548
3489.67	245.293
3493.67	228.106
3497.66	215.857
3501.64	234.211
3505.63	226.91
3509.61	229.723
3513.59	214.464
3517.57	224.872
3521.54	209.57
3525.52	209.714
3529.49	199.537
3533.45	197.238
3537.42	179.565
3541.38	182.565
3545.34	180.296
3549.29	185.761
3553.25	172.855
3557.2	167.806
3561.15	175.829
3565.09	170.886
3569.04	163.42
3572.98	163.746
3576.92	164.134
3580.85	143.523
3584.79	165.083
3588.72	139.079
3592.64	136.827
3596.57	153.212
3600.49	164.301
3604.41	148.646
3608.33	140.925
3612.25	151.968
3616.16	144.19
3620.07	125.55
3623.98	125.665
3627.88	112.225
3631.79	136.617
3635.69	112.331
3639.58	112.459
3643.48	112.668
3647.37	126.526
3651.26	126.605
3655.15	115.833
3659.03	115.937
3662.92	124.213
3666.8	107.937
3670.67	99.8399
3674.55	110.916
3678.42	102.879
3682.29	92.1065
3686.16	89.5962
3690.02	98.1413
3693.89	87.3215
3697.75	79.2089
3701.61	82.2107
3705.46	85.2172
3709.31	91.0596
3713.16	82.8792
3717.01	97.1512
3720.86	94.5306
3724.7	91.8798
3728.54	83.5418
3732.38	63.8371
3736.21	72.4871
3740.04	78.3118
3743.87	89.8477
3747.7	81.4095
3751.53	95.8047
3755.35	81.5774
3759.17	81.6274
3762.99	78.8007
3766.81	84.5685
3770.62	84.632
3774.43	87.5782
3778.24	81.9136
3782.04	105.044
3785.85	87.9158
3789.65	85.1514
3793.45	82.3885
3797.24	94.1332
3801.04	91.4238
3804.83	85.8067
3808.62	80.1756
3812.4	77.424
3816.19	86.3614
3819.97	80.6636
3823.75	83.7442
3827.52	83.874
3831.3	81.0789
3835.07	78.2764
3838.84	87.2816
3842.61	87.4563
3846.37	84.5921
3850.13	69.7956
3853.89	75.7748
3857.65	75.8001
3861.41	84.7272
3865.16	81.8368
3868.91	79.0541
3872.66	91.0859
3876.4	79.1895
3880.14	82.2291
3883.89	82.2904
3887.62	82.3677
3891.36	70.4646
3895.09	76.5976
3898.82	73.7074
3902.55	82.8629
3906.28	79.9644
3910	80.0745
3913.73	71.1311
3917.45	83.4009
3921.16	80.5577
3924.88	74.6552
3928.59	83.9767
3932.3	90.2555
3936.01	75.0682
3939.71	78.2528
3943.42	78.4124
3947.12	84.7236
3950.81	84.8638
3954.51	72.6194
3958.2	69.6118
3961.9	82.0519
3965.58	79.0086
3969.27	79.0305
3972.96	69.7549
3976.64	82.1835
3980.32	79.0897
3984	85.2832
3987.67	75.9744
3991.34	85.2912
3995.01	85.3374
3998.68	79.2044