File: Data/3-Raman/raw/bu04w-a-ff3-fi02-v_150 (500nm)_633nm_edge_100%_x100_vis_lwd_h50um_45sx2_01.txt
#Acq. time (s)=	45
#Accumulations=	2
#Range (cm-¹)=	100...4000
#Windows=	1
#Auto scanning=	Off
#Autofocus=	Off
#Macrospot=	Off
#AutoExposure=	Off
#Spike filter=	Multiple accum.
#Delay time (s)=	2
#Binning=	1
#Readout mode=	Signal
#DeNoise=	Off
#ICS correction=	On
#Dark correction=	Off
#Inst. Process=	Off
#Detector Gain=	Best Dynamic
#Detector ADC=	50 kHz HS
#Detector temperature (°C)=	-60.28
#Instrument=	LabRAM HR Evol
#Detector=	SIN-EM FIVIS
#Objective=	x100_VIS_LWD
#Grating=	150 (500nm)
#ND Filter=	100%
#Laser=	633nm_Edge
#Hole=	49.98
#Temperature=	0
#Range=	Visible
#StageXY=	75x50mm Scan+
#StageZ=	Z motor
#X (µm)=	0
#Y (µm)=	0
#Z (µm)=	5.5
#Full time(mm:ss)=	1:34
#Project=	21_11_22
#Sample=	BU04w
#Site=
#Title=	BU04w-A-FF3-FI02-V_150 (500nm)_633nm_Edge_100%_x100_VIS_LWD_H50um_45sX2
#Remark=
#Date=	22.11.2021 10:43
#Acquired=	22.11.2021 10:43:28
100.177	515.172
106.695	432.595
113.209	355.691
119.717	329.21
126.219	299.79
132.716	284.639
139.208	282.759
145.694	267.495
152.175	243.631
158.651	244.723
165.121	324.42
171.586	255.492
178.045	183.546
184.5	176.684
190.947	154.428
197.39	150.379
203.829	141.729
210.262	146.447
216.688	153.068
223.11	163.476
229.527	188.97
235.939	281
242.344	276.94
248.745	192.337
255.141	178.918
261.53	191.17
267.916	167.4
274.294	173.077
280.669	186.336
287.038	208.058
293.402	172.849
299.76	152.833
306.114	164.976
312.461	191.275
318.805	243.972
325.142	424.103
331.475	535.322
337.802	344.698
344.123	215.442
350.441	191.779
356.752	174.676
363.058	182.972
369.36	203.458
375.656	175.078
381.947	161.771
388.232	143.951
394.512	142.232
400.789	156.65
407.059	157.921
413.324	161.049
419.584	182.081
425.839	223.744
432.089	265.736
438.333	297.121
444.573	253.162
450.807	224.319
457.037	205.046
463.261	200.023
469.48	167.233
475.695	152.297
481.904	156.989
488.108	149.55
494.307	165.432
500.502	159.875
506.691	175.813
512.874	219.801
519.053	192.004
525.227	182.044
531.396	182.469
537.559	173.569
543.718	161.673
549.873	141.07
556.022	144.963
562.165	137.291
568.304	127.62
574.437	126.321
580.567	126.841
586.691	133.983
592.81	138.429
598.924	158.84
605.033	158.106
611.138	155.585
617.236	144.75
623.332	152.713
629.42	142.782
635.506	146.681
641.585	139.03
647.659	129.376
653.73	138.497
659.794	155.92
665.854	159.25
671.91	138.447
677.96	121.699
684.005	118.947
690.045	105.11
696.082	107.222
702.113	106.514
708.139	106.699
714.16	114.209
720.176	107.562
726.187	102.782
732.194	103.538
738.196	94.9326
744.193	105.045
750.185	98.3861
756.173	101.129
762.155	105.921
768.133	101.526
774.107	103.697
780.075	99.2376
786.039	89.9641
791.998	95.711
797.952	100.451
803.902	100.383
809.845	98.3844
815.786	95.3807
821.721	97.0357
827.652	93.0517
833.576	111.637
839.498	114.516
845.415	102.554
851.327	108.403
857.233	99.2652
863.135	105.199
869.032	114.003
874.925	121.793
880.813	119.059
886.697	112.453
892.576	115.255
898.45	117.967
904.318	113.909
910.184	116.443
916.044	112.384
921.9	131.973
927.75	129.165
933.596	139.681
939.439	163.692
945.275	203.118
951.107	245.775
956.936	260.016
962.759	239.695
968.577	218.133
974.391	233.747
980.201	240.367
986.006	309.981
991.806	334.321
997.602	296.487
1003.39	272.259
1009.18	245.437
1014.96	267.621
1020.74	303.227
1026.51	349.816
1032.28	317.127
1038.04	215.107
1043.8	170.395
1049.56	154.424
1055.31	141.158
1061.05	132.587
1066.8	123.839
1072.53	135.457
1078.26	142.154
1083.99	156.559
1089.72	175.824
1095.44	216.381
1101.15	287.829
1106.86	258.903
1112.56	175.81
1118.27	154.054
1123.96	131.05
1129.65	128.433
1135.34	129.736
1141.03	150.675
1146.7	179.438
1152.38	258.434
1158.05	337.183
1163.71	209.875
1169.37	139.823
1175.03	112.127
1180.68	111.913
1186.33	111.817
1191.98	109.88
1197.61	102.2
1203.25	98.5578
1208.88	86.1177
1214.51	96.3398
1220.13	93.8062
1225.74	92.2662
1231.36	93.6862
1236.97	107.113
1242.57	103.362
1248.17	94.4225
1253.77	102.558
1259.36	111.582
1264.94	122.516
1270.53	108.238
1276.11	122.077
1281.68	574.936
1287.25	163.627
1292.81	108.46
1298.38	107.429
1303.93	102.474
1309.48	96.6418
1315.03	89.9074
1320.58	98.2744
1326.12	95.6188
1331.65	94.991
1337.18	101.442
1342.71	100.705
1348.23	103.985
1353.75	103.139
1359.26	110.447
1364.77	109.461
1370.28	104.294
1375.78	115.555
1381.28	190.456
1386.77	777.366
1392.26	126.713
1397.74	113.5
1403.23	118.797
1408.7	130.326
1414.17	96.5192
1419.64	88.4611
1425.11	96.9804
1430.56	86.8328
1436.02	89.1379
1441.47	87.2604
1446.92	92.7179
1452.36	80.2633
1457.8	83.4719
1463.23	83.4811
1468.66	87.6576
1474.09	85.5402
1479.51	84.515
1484.93	80.359
1490.34	78.3399
1495.75	80.5734
1501.16	89.1733
1506.56	90.4348
1511.96	80.076
1517.35	80.3267
1522.74	82.7314
1528.13	87.305
1533.51	84.4113
1538.88	81.4363
1544.25	89.1935
1549.62	84.9199
1554.99	88.0958
1560.35	85.8286
1565.71	84.6662
1571.06	81.3435
1576.41	80.1956
1581.75	89.8841
1587.09	90.9864
1592.43	82.4261
1597.76	82.5248
1603.09	85.8986
1608.41	87.1759
1613.73	90.7077
1619.05	82.3269
1624.36	90.3047
1629.67	87.348
1634.97	86.5345
1640.27	92.2051
1645.57	81.2916
1650.86	78.0724
1656.15	89.2256
1661.43	87.0415
1666.71	74.8582
1671.99	90.3879
1677.26	91.483
1682.53	95.8856
1687.79	92.4752
1693.05	70.2875
1698.31	83.6086
1703.56	86.1621
1708.81	88.777
1714.06	83.0631
1719.3	85.5343
1724.53	76.7058
1729.77	83.5994
1735	79.2728
1740.22	86.1845
1745.44	89.7354
1750.66	78.5618
1755.87	84.3068
1761.08	85.476
1766.29	80.9792
1771.49	76.4937
1776.69	81.0924
1781.88	74.3919
1787.07	79.0709
1792.26	81.5279
1797.44	88.5771
1802.62	80.7983
1807.79	89.0583
1812.96	86.9464
1818.13	82.5212
1823.29	86.1696
1828.45	86.3668
1833.61	84.2507
1838.76	78.6262
1843.91	90.4405
1849.05	82.4068
1854.19	88.3659
1859.33	90.856
1864.46	78.1125
1869.59	87.6918
1874.71	80.7447
1879.83	93.8278
1884.95	80.9324
1890.06	79.7997
1895.17	84.5324
1900.28	78.6612
1905.38	84.7263
1910.48	71.858
1915.57	79.2469
1920.66	84.1507
1925.75	93.8747
1930.83	79.6792
1935.91	84.6233
1940.99	85.9498
1946.06	87.2508
1951.13	99.3656
1956.19	86.1534
1961.26	77.738
1966.31	87.3843
1971.36	92.1642
1976.41	86.0917
1981.46	83.6358
1986.5	85.9989
1991.54	83.5625
1996.58	91.96
2001.61	89.5624
2006.63	79.98
2011.66	78.8364
2016.68	86.1277
2021.69	97.0241
2026.71	83.8636
2031.72	80.3709
2036.72	86.5801
2041.72	85.5383
2046.72	88.1529
2051.71	84.6912
2056.71	82.389
2061.69	92.3593
2066.68	72.9526
2071.66	81.7073
2076.63	91.7265
2081.6	83.2646
2086.57	93.2744
2091.54	84.7502
2096.5	94.851
2101.46	83.8887
2106.41	77.8763
2111.36	85.5951
2116.31	78.3407
2121.25	97.4427
2126.19	101.513
2131.13	90.411
2136.06	89.3649
2140.99	76.86
2145.92	93.567
2150.84	80.9637
2155.76	101.488
2160.67	92.634
2165.58	99.0708
2170.49	93.9875
2175.39	90.2215
2180.29	90.2541
2185.19	91.5232
2190.08	88.9772
2194.98	94.1489
2199.86	87.8396
2204.74	95.6802
2209.62	95.8634
2214.5	84.4673
2219.37	88.5569
2224.24	91.3753
2229.11	90.3085
2233.97	91.8409
2238.83	89.461
2243.68	81.831
2248.53	91.2305
2253.38	82.2448
2258.22	86.4134
2263.06	94.5608
2267.9	89.4474
2272.73	90.9143
2277.56	89.6961
2282.39	93.7565
2287.21	93.7834
2292.03	87.1561
2296.85	92.5076
2301.66	89.9188
2306.47	88.709
2311.28	99.5719
2316.08	91.7613
2320.88	90.6531
2325.68	116.472
2330.47	85.7376
2335.26	90.0627
2340.04	94.4223
2344.82	96.109
2349.6	97.8287
2354.38	99.5281
2359.15	87.4101
2363.92	77.9242
2368.68	86.3878
2373.44	90.7196
2378.2	90.9009
2382.95	95.1983
2387.71	96.6755
2392.45	98.1145
2397.2	86.9926
2401.94	92.5614
2406.68	93.9319
2411.41	98.2062
2416.14	99.9179
2420.87	103.22
2425.59	93.5222
2430.31	93.7548
2435.03	89.7776
2439.75	107.07
2444.46	96.009
2449.16	90.5918
2453.87	96.5827
2458.57	92.5599
2463.27	92.8288
2467.96	91.6416
2472.65	104.897
2477.34	103.722
2482.02	99.623
2486.7	98.3845
2491.38	102.968
2496.05	109.04
2500.72	97.5202
2505.39	96.2252
2510.06	96.3749
2514.72	96.5004
2519.37	98.1079
2524.03	98.2679
2528.68	101.375
2533.33	101.543
2537.97	113.62
2542.61	97.481
2547.25	96.204
2551.88	100.9
2556.51	90.617
2561.14	93.7974
2565.77	106.053
2570.39	100.293
2575.01	100.553
2579.62	105.325
2584.23	97.9077
2588.84	101.063
2593.45	110.268
2598.05	105.87
2602.65	98.3878
2607.24	101.558
2611.84	104.705
2616.42	110.907
2621.01	100.289
2625.59	108.056
2630.17	95.9327
2634.75	103.84
2639.32	111.874
2643.89	104.486
2648.46	117.246
2653.02	105.15
2657.58	105.353
2662.14	105.522
2666.69	89.9978
2671.24	99.5656
2675.79	114.002
2680.33	94.0217
2684.88	100.798
2689.41	110.819
2693.95	108.036
2698.48	114.618
2703.01	113.259
2707.53	102.207
2712.06	105.607
2716.57	117.153
2721.09	112.518
2725.6	115.935
2730.11	111.203
2734.62	116.169
2739.12	109.738
2743.62	116.379
2748.12	110.036
2752.61	105.438
2757.1	117.144
2761.59	114.034
2766.08	109.318
2770.56	122.698
2775.04	121.321
2779.51	105.101
2783.98	113.763
2788.45	122.48
2792.92	114.511
2797.38	108.129
2801.84	116.804
2806.3	118.737
2810.75	115.588
2815.2	119.153
2819.65	115.948
2824.09	119.53
2828.53	119.728
2832.97	128.411
2837.41	106.449
2841.84	118.542
2846.27	117.033
2850.69	117.255
2855.12	124.4
2859.54	126.43
2863.95	116.44
2868.37	127.191
2872.78	117.167
2877.18	126.243
2881.59	126.669
2885.99	111.347
2890.39	132.844
2894.78	108.569
2899.18	121.384
2903.57	141.351
2907.95	127.512
2912.34	126.052
2916.72	131.704
2921.09	103.288
2925.47	128.776
2929.84	130.959
2934.21	131.324
2938.57	135.237
2942.94	130.033
2947.29	128.407
2951.65	123.122
2956	126.951
2960.36	125.3
2964.7	125.495
2969.05	133.059
2973.39	136.985
2977.73	135.4
2982.06	130.132
2986.4	126.749
2990.73	140.077
2995.05	133.03
2999.38	129.706
3003.7	137.624
3008.01	138.092
3012.33	140.402
3016.64	150.344
3020.95	143.302
3025.26	139.955
3029.56	142.234
3033.86	125.338
3038.16	140.891
3042.45	143.124
3046.74	127.983
3051.03	143.624
3055.32	145.809
3059.6	146.073
3063.88	148.267
3068.16	152.411
3072.43	156.568
3076.7	147.115
3080.97	143.485
3085.24	159.43
3089.5	140.219
3093.76	140.636
3098.02	162.806
3102.27	155.427
3106.52	169.909
3110.77	170.567
3115.01	153.211
3119.26	165.881
3123.5	174.664
3127.73	183.563
3131.97	182.418
3136.2	168.968
3140.43	171.802
3144.65	155.997
3148.87	187.728
3153.09	184.181
3157.31	188.905
3161.52	199.932
3165.73	198.406
3169.94	194.699
3174.15	207.91
3178.35	195.612
3182.55	212.846
3186.75	217.358
3190.94	209.106
3195.13	222.224
3199.32	201.482
3203.51	212.911
3207.69	213.738
3211.87	208.13
3216.05	222.03
3220.22	205.535
3224.39	206.357
3228.56	215.959
3232.73	223.404
3236.89	197.675
3241.05	213.975
3245.21	208.232
3249.36	209.014
3253.52	196.155
3257.66	207.832
3261.81	204.015
3265.95	186.706
3270.1	198.918
3274.23	202.025
3278.37	184.123
3282.5	209.706
3286.63	191.759
3290.76	180.623
3294.88	203.993
3299	176.647
3303.12	186.271
3307.24	188.96
3311.35	184.659
3315.46	178.011
3319.57	185.347
3323.68	188.118
3327.78	186.261
3331.88	191.537
3335.98	187.508
3340.07	185.719
3344.16	181.382
3348.25	193.57
3352.34	210.585
3356.42	194.317
3360.5	201.919
3364.58	188.002
3368.66	202.797
3372.73	200.803
3376.8	193.9
3380.87	198.997
3384.93	187.18
3388.99	172.894
3393.05	194.86
3397.11	199.982
3401.16	195.408
3405.21	190.729
3409.26	198.212
3413.31	198.358
3417.35	183.904
3421.39	215.727
3425.43	181.727
3429.46	194.128
3433.5	196.826
3437.53	187.345
3441.55	190.135
3445.58	200.38
3449.6	203.355
3453.62	184.123
3457.64	184.715
3461.65	185.36
3465.66	198.5
3469.67	199.186
3473.68	189.679
3477.68	192.782
3481.68	223.694
3485.68	201.525
3489.67	209.706
3493.67	187.327
3497.66	200.53
3501.64	183.018
3505.63	198.706
3509.61	193.789
3513.59	188.78
3517.57	188.892
3521.54	204.428
3525.52	189.129
3529.49	207.261
3533.45	184.347
3537.42	189.9
3541.38	182.565
3545.34	203.644
3549.29	198.751
3553.25	178.054
3557.2	170.408
3561.15	191.458
3565.09	196.975
3569.04	189.567
3572.98	205.665
3576.92	198.274
3580.85	188.291
3584.79	183.573
3588.72	184.114
3592.64	176.679
3596.57	201.174
3600.49	183.002
3604.41	167.394
3608.33	183.874
3612.25	178.865
3616.16	190.007
3620.07	171.45
3623.98	182.417
3627.88	171.718
3631.79	177.196
3635.69	171.88
3639.58	161.236
3643.48	188.686
3647.37	175.504
3651.26	181.059
3655.15	164.892
3659.03	162.312
3662.92	184.273
3666.8	189.914
3670.67	184.635
3674.55	160.212
3678.42	182.44
3682.29	180.089
3686.16	164.03
3690.02	156.197
3693.89	184.345
3697.75	184.821
3701.61	182.536
3705.46	157.861
3709.31	172.313
3713.16	184.02
3717.01	175.998
3720.86	184.828
3724.7	171.038
3728.54	174.163
3732.38	177.325
3736.21	154.923
3740.04	166.59
3743.87	172.565
3747.7	187.099
3751.53	164.441
3755.35	184.622
3759.17	187.6
3762.99	164.765
3766.81	193.504
3770.62	185.043
3774.43	185.206
3778.24	168.138
3782.04	191.382
3785.85	177.273
3789.65	157.314
3793.45	177.786
3797.24	195.507
3801.04	184.299
3804.83	184.703
3808.62	193.879
3812.4	188.447
3816.19	180.042
3819.97	183.326
3823.75	171.896
3827.52	186.877
3831.3	190.167
3835.07	172.799
3838.84	190.836
3842.61	182.324
3846.37	191.445
3850.13	185.627
3853.89	167.893
3857.65	167.949
3861.41	150.131
3865.16	162.186
3868.91	174.516
3872.66	192.624
3876.4	183.779
3880.14	186.884
3883.89	187.024
3887.62	190.194
3891.36	181.409
3895.09	190.743
3898.82	166.97
3902.55	191.338
3906.28	176.525
3910	170.725
3913.73	183.125
3917.45	189.548
3921.16	183.915
3924.88	199.588
3928.59	166.427
3932.3	166.743
3936.01	160.86
3939.71	182.59
3943.42	164.512
3947.12	174.069
3950.81	174.356
3954.51	183.866
3958.2	184.085
3961.9	174.941
3965.58	171.96
3969.27	178.206
3972.96	181.363
3976.64	169.019
3980.32	165.933
3984	169.016
3987.67	165.903
3991.34	190.742
3995.01	184.639
3998.68	166.174