File: Data/3-Raman/raw/bu04w-a-ff3-fi10-v_1800 (450-850nm)_633nm_edge_100%_x100_vis_lwd_h50um_45sx2_01.txt
#Acq. time (s)=	45
#Accumulations=	2
#Range (cm-¹)=	1200...2399
#Windows=	6
#Auto scanning=	Off
#Autofocus=	Off
#Macrospot=	Off
#AutoExposure=	Off
#Spike filter=	Multiple accum.
#Delay time (s)=	2
#Binning=	1
#Readout mode=	Signal
#DeNoise=	Off
#ICS correction=	On
#Dark correction=	Off
#Inst. Process=	Off
#Detector Gain=	Best Dynamic
#Detector ADC=	50 kHz EM
#Detector EM gain=	100
#Detector temperature (°C)=	-60.09
#Instrument=	LabRAM HR Evol
#Detector=	SIN-EM FIVIS
#Objective=	x100_VIS_LWD
#Grating=	1800 (450-850nm)
#ND Filter=	100%
#Laser=	633nm_Edge
#Hole=	49.98
#Temperature=	0
#Range=	Visible
#StageXY=	75x50mm Scan+
#StageZ=	Z motor
#X (µm)=	0
#Y (µm)=	0
#Z (µm)=	4.4
#Full time(mm:ss)=	9:31
#Project=	21_11_22
#Sample=	BU04w
#Site=
#Title=	BU04w-A-FF3-FI10-V_1800 (450-850nm)_633nm_Edge_100%_x100_VIS_LWD_H50um_45sX2
#Remark=
#Date=	22.11.2021 11:53
#Acquired=	22.11.2021 11:53:53
1201.04	292.519
1202.08	296.61
1203.11	299.538
1204.14	293.717
1205.17	293.716
1206.2	291.299
1207.24	293.934
1208.27	292.763
1209.3	294.807
1210.33	293.121
1211.36	295.62
1212.39	296.426
1213.42	296.734
1214.45	292.988
1215.48	298.091
1216.51	293.88
1217.54	295.186
1218.56	294.999
1219.59	295.906
1220.62	297.722
1221.65	293.346
1222.68	294.583
1223.7	297.397
1224.73	300.179
1225.76	296.625
1226.78	296.037
1227.81	298.055
1228.84	296.351
1229.86	297.953
1230.89	300.459
1231.91	300.549
1232.94	302.367
1233.96	300.995
1234.99	304.537
1236.01	299.476
1237.03	301.977
1238.06	301.56
1239.08	302.078
1240.1	302.858
1241.13	302.62
1242.15	301.497
1243.17	299.87
1244.19	301.33
1245.21	303.328
1246.24	303.302
1247.26	304.268
1248.28	305.751
1249.3	304.806
1250.32	303.235
1251.34	303.513
1252.36	303.098
1253.38	305.656
1254.4	307.21
1255.42	304.775
1256.44	304.838
1257.46	303.588
1258.47	310.161
1259.49	302.854
1260.51	307.046
1261.53	307.543
1262.55	304.765
1263.56	313.571
1264.58	305.039
1265.6	307.413
1266.61	312.016
1267.63	307.006
1268.65	310.968
1269.66	304.344
1270.68	302.642
1271.69	305.484
1272.71	305.645
1273.72	309.309
1274.74	305.712
1275.75	307.161
1276.76	307.592
1277.78	304.47
1278.79	304.984
1279.8	306.248
1280.82	307.278
1281.83	318.871
1282.84	341.285
1283.85	420.235
1284.86	386.591
1285.88	312.795
1286.89	311.304
1287.9	302.298
1288.91	302.084
1289.92	303.735
1290.93	301.608
1291.94	299.178
1292.95	303.881
1293.96	303.037
1294.97	306.67
1295.98	302.737
1296.99	303.126
1297.99	301.264
1299	299.287
1300.01	305.58
1301.02	300.288
1302.03	300.296
1303.03	302.083
1304.04	302.662
1305.05	302.774
1306.05	305.141
1307.06	297.873
1308.06	302.194
1309.07	301.963
1310.07	298.065
1311.08	312.093
1312.08	302.572
1313.09	303.503
1314.09	306.077
1315.1	300.222
1316.1	301.812
1317.1	304.149
1318.11	305.53
1319.11	301.489
1320.11	300.94
1321.12	299.641
1322.12	304.303
1323.12	303.776
1324.12	304.052
1325.12	301.783
1326.13	304.658
1327.13	305.076
1328.13	306.178
1329.13	304.687
1330.13	306.826
1331.13	306.04
1332.13	306.102
1333.13	306.473
1334.13	307.914
1335.13	305.07
1336.12	310.357
1337.12	306.549
1338.12	307.846
1339.12	304.945
1340.12	304.503
1341.11	304.967
1342.11	307.535
1343.11	309.641
1344.1	304.819
1345.1	307.144
1346.1	305.248
1347.09	306.972
1348.09	311.046
1349.08	307.887
1350.08	310.618
1351.07	308.701
1352.07	312.151
1353.06	307.139
1354.06	306.058
1355.05	312.714
1356.04	308.588
1357.04	311.462
1358.03	311.14
1359.02	310.401
1360.02	310.948
1361.01	311.404
1362	310.472
1362.99	312.679
1363.98	312.755
1364.98	315.035
1365.97	314.46
1366.96	309.849
1367.95	313.758
1368.94	309.5
1369.93	315.463
1370.92	311.486
1371.91	314.941
1372.9	307.843
1373.89	316.225
1374.87	306.555
1375.86	310.853
1376.85	314.416
1377.84	311.63
1378.83	314.523
1379.81	325.161
1380.8	317.502
1381.79	311.227
1382.78	317.473
1383.76	319.009
1384.75	319.078
1385.73	327.471
1386.72	382.871
1387.7	622.193
1388.69	345.401
1389.68	317.695
1390.66	314.865
1391.64	309.515
1392.63	314.506
1393.61	309.686
1394.6	316.236
1395.58	313.485
1396.56	313.237
1397.55	307.905
1398.53	308.437
1399.51	309.765
1400.49	307.996
1401.47	310.244
1402.46	311.778
1403.44	313.017
1404.42	314.399
1405.4	311.27
1406.38	311.75
1407.36	312.049
1408.34	314.563
1409.32	321.138
1410.3	313.554
1411.28	315.019
1412.26	322.046
1413.24	313.595
1414.22	309.242
1415.19	314.213
1416.17	312.715
1417.15	311.66
1418.13	318.834
1419.11	311.758
1420.08	310.866
1421.06	308.082
1422.04	311.695
1423.01	315.637
1423.99	310.854
1424.97	318.247
1425.94	310.886
1426.92	314.329
1427.89	312.684
1428.87	314.023
1429.84	316.589
1430.82	312.451
1431.79	310.537
1432.76	309.838
1433.74	313.211
1434.71	319.381
1435.68	310.939
1436.66	315.974
1437.63	316.364
1438.6	318.366
1439.57	314.753
1440.54	310.396
1441.52	319.365
1442.49	314.576
1443.46	313.134
1444.43	317.002
1445.4	312.332
1446.37	308.868
1447.34	316.195
1448.31	315.081
1449.28	312.799
1450.25	313.898
1451.22	314.241
1452.19	315.214
1453.16	315.289
1454.12	314.665
1455.09	317.12
1456.06	314.694
1457.03	313.32
1457.99	320.769
1458.96	313.857
1459.93	312.222
1460.9	315.361
1461.86	315.42
1462.83	317.633
1463.79	316.278
1464.76	314.937
1465.72	315.623
1466.69	316.467
1467.59	312.323
1468.57	316.786
1469.56	316.123
1470.53	318.262
1471.51	314.877
1472.49	314.302
1473.47	313.5
1474.45	317.281
1475.43	312.913
1476.41	322.989
1477.39	315.328
1478.36	332.636
1479.34	316.678
1480.32	320.067
1481.3	315.165
1482.27	315.36
1483.25	313.93
1484.23	315.515
1485.2	318.31
1486.18	312.554
1487.15	315.059
1488.13	313.503
1489.1	318.221
1490.08	316.522
1491.06	314.431
1492.03	315.509
1493	315.414
1493.98	315.871
1494.95	318.545
1495.92	318.039
1496.9	313.942
1497.87	315.442
1498.84	319.04
1499.82	320.223
1500.79	313.98
1501.76	315.14
1502.73	318.233
1503.7	316.929
1504.68	318.11
1505.65	316.561
1506.62	318.704
1507.59	320.61
1508.56	321.766
1509.53	316.64
1510.5	317.876
1511.47	318.898
1512.44	316.735
1513.4	318.935
1514.37	316.768
1515.34	318.559
1516.31	317.683
1517.28	318.332
1518.25	318.448
1519.21	318.446
1520.18	320.102
1521.15	322.304
1522.12	320.703
1523.08	324.884
1524.05	318.845
1525.02	321.93
1525.98	317.858
1526.95	317.59
1527.91	317.25
1528.88	320.29
1529.84	319.084
1530.81	320.406
1531.77	323.995
1532.74	319.693
1533.7	319.542
1534.66	323.569
1535.63	319.335
1536.59	330.798
1537.55	325.837
1538.52	325.172
1539.48	320.529
1540.44	320.872
1541.4	320.742
1542.36	320.378
1543.33	325.88
1544.29	326.827
1545.25	324.713
1546.21	324.231
1547.17	323.964
1548.13	323.873
1549.09	328.955
1550.05	319.604
1551.01	326.036
1551.97	325.272
1552.93	326.79
1553.89	324.747
1554.84	325.698
1555.8	328.685
1556.76	329.517
1557.72	324.649
1558.68	321.883
1559.63	323.415
1560.59	328.671
1561.55	326.217
1562.5	326.408
1563.46	331.99
1564.42	328.967
1565.37	325.432
1566.33	323.255
1567.28	327.31
1568.24	324.775
1569.19	328.16
1570.15	323.601
1571.1	329.105
1572.06	328.051
1573.01	323.385
1573.96	329.114
1574.92	330.044
1575.87	328.315
1576.82	320.94
1577.78	323.89
1578.73	323.113
1579.68	323.589
1580.63	326.862
1581.59	325.965
1582.54	324.137
1583.49	322.839
1584.44	326.588
1585.39	327.245
1586.34	323.955
1587.29	325.703
1588.24	326.262
1589.19	328.195
1590.14	324.729
1591.09	325.356
1592.04	325.58
1592.99	323.555
1593.94	322.84
1594.88	327.674
1595.83	324.964
1596.78	324.257
1597.73	322.923
1598.68	324.086
1599.62	323.704
1600.57	328.282
1601.52	327.951
1602.46	326.745
1603.41	330.667
1604.35	329.971
1605.3	324.549
1606.25	327.35
1607.19	333.314
1608.14	328.296
1609.08	327.389
1610.03	332.696
1610.97	325.641
1611.91	325.586
1612.86	325.726
1613.8	326.811
1614.75	328.225
1615.69	329.284
1616.63	328.312
1617.57	329.129
1618.52	328.372
1619.46	329.012
1620.4	333.715
1621.34	332.738
1622.28	328.969
1623.22	328.021
1624.16	329.928
1625.11	333.167
1626.05	334.084
1626.99	329.125
1627.93	333.738
1628.87	335.653
1629.8	328.754
1630.74	334.263
1631.68	332.937
1632.62	333.633
1633.56	333.143
1634.5	332.785
1635.44	330.721
1636.37	338.876
1637.31	332.045
1638.25	332.366
1639.19	334.363
1640.12	335.588
1641.06	334.878
1642	335.528
1642.93	337.336
1643.87	335.889
1644.8	334.416
1645.74	336.219
1646.67	330.297
1647.61	333.499
1648.54	335.097
1649.48	337.674
1650.41	336.658
1651.35	337.518
1652.28	337.63
1653.21	331.674
1654.15	339.383
1655.08	335.952
1656.01	333.066
1656.94	338.369
1657.88	341.616
1658.81	338.086
1659.74	336.408
1660.67	337.495
1661.6	340.006
1662.53	342.111
1663.46	335.568
1664.39	337.209
1665.33	338.651
1666.26	337.094
1667.18	335.271
1668.11	338.605
1669.04	337.432
1669.97	337.524
1670.9	337.259
1671.83	338.361
1672.76	336.973
1673.69	339.541
1674.61	339.813
1675.54	338.674
1676.47	337.089
1677.4	334.721
1678.32	336.227
1679.25	337.68
1680.18	338.881
1681.1	337.178
1682.03	346.382
1682.96	334.27
1683.88	333.007
1684.81	337.163
1685.73	335.543
1686.66	339.554
1687.58	336.72
1688.5	332.72
1689.43	333.973
1690.35	334.755
1691.28	336.817
1692.2	336.915
1693.12	338.685
1694.05	334.614
1694.97	336.252
1695.89	336.277
1696.81	335.823
1697.74	334.756
1698.66	336.305
1699.58	337.667
1700.5	338.743
1701.42	335.441
1702.34	336.893
1703.26	335.353
1704.18	336.656
1705.1	340.12
1705.94	335.933
1706.88	339.312
1707.81	335.923
1708.74	340.798
1709.68	342.647
1710.61	333.693
1711.55	336.909
1712.48	335.123
1713.41	342.598
1714.35	337.883
1715.28	335.784
1716.21	334.274
1717.14	336.986
1718.08	333.141
1719.01	341.559
1719.94	335.966
1720.87	339.766
1721.8	336.087
1722.73	339.164
1723.66	340.531
1724.6	339.244
1725.53	341.769
1726.45	337.671
1727.38	340.682
1728.31	339.363
1729.24	339.437
1730.17	340.464
1731.1	342.106
1732.03	339.367
1732.96	341.53
1733.89	341.032
1734.82	338.454
1735.74	339.805
1736.67	334.292
1737.6	346.801
1738.52	342.087
1739.45	338.385
1740.38	340.303
1741.3	343.441
1742.23	341.843
1743.16	336.876
1744.08	348.124
1745.01	341.395
1745.93	340.545
1746.86	341.449
1747.78	342.812
1748.71	341.773
1749.63	339.529
1750.55	345.582
1751.48	342.078
1752.4	342.078
1753.33	344.276
1754.25	345.879
1755.17	342.675
1756.09	345.822
1757.02	343.674
1757.94	343.878
1758.86	343.917
1759.78	340.504
1760.7	340.713
1761.62	343.398
1762.54	346.795
1763.47	344.141
1764.39	346.113
1765.31	342.703
1766.23	344.731
1767.15	341.746
1768.07	348.345
1768.99	342.248
1769.9	345.731
1770.82	340.334
1771.74	344.25
1772.66	351.486
1773.58	342.356
1774.5	347.35
1775.41	343.755
1776.33	340.959
1777.25	341.876
1778.17	348.693
1779.08	350.315
1780	347.894
1780.92	345.128
1781.83	344.606
1782.75	347.656
1783.66	346.176
1784.58	342.168
1785.49	346.216
1786.41	345.893
1787.32	346.531
1788.24	347.792
1789.15	343.972
1790.07	339.769
1790.98	342.204
1791.89	345.138
1792.81	343.57
1793.72	351
1794.63	344.254
1795.54	346.322
1796.46	345.617
1797.37	345.744
1798.28	343.639
1799.19	345.908
1800.1	349.443
1801.02	344.379
1801.93	350.236
1802.84	351.746
1803.75	349.523
1804.66	351.476
1805.57	351.206
1806.48	347.427
1807.39	350.01
1808.3	347.976
1809.21	351.197
1810.12	348.327
1811.02	351.224
1811.93	350.96
1812.84	347.591
1813.75	348.662
1814.66	351.895
1815.56	346.934
1816.47	346.914
1817.38	346.385
1818.29	345.782
1819.19	348.484
1820.1	347.819
1821.01	350.229
1821.91	347.887
1822.82	349.533
1823.72	350.711
1824.63	350.975
1825.53	350.881
1826.44	356.649
1827.34	356.614
1828.25	356.108
1829.15	351.71
1830.05	356.686
1830.96	350.452
1831.86	354.435
1832.76	354.971
1833.67	352.001
1834.57	354.571
1835.47	354.178
1836.37	355.073
1837.28	350.072
1838.18	353.078
1839.08	354.088
1839.98	354.398
1840.88	361.833
1841.78	353.368
1842.68	350.598
1843.58	362.401
1844.48	358.778
1845.38	353.033
1846.28	355.782
1847.18	354.123
1848.08	349.879
1848.98	354.013
1849.88	358.484
1850.78	353.962
1851.68	360.001
1852.57	356.071
1853.47	355.565
1854.37	354.395
1855.27	354.939
1856.16	360.218
1857.06	357.586
1857.96	359.341
1858.86	359.183
1859.75	357.345
1860.65	359.419
1861.54	359.237
1862.44	358.094
1863.33	357.173
1864.23	359.988
1865.12	361.959
1866.02	356.342
1866.91	358.751
1867.81	359.711
1868.7	357.6
1869.59	363.961
1870.49	357.295
1871.38	360.348
1872.27	355.982
1873.17	360.663
1874.06	362.606
1874.95	357.009
1875.84	356.763
1876.74	357.961
1877.63	354.751
1878.52	358.887
1879.41	354.167
1880.3	359.56
1881.19	361.197
1882.08	359.552
1882.97	361.475
1883.86	363.464
1884.75	363.883
1885.64	359.143
1886.53	356.767
1887.42	367.017
1888.31	357.635
1889.2	361.63
1890.09	364.341
1890.98	358.366
1891.86	359.444
1892.75	359.088
1893.64	356.52
1894.53	359.459
1895.41	367.653
1896.3	367.015
1897.19	363.561
1898.07	362.725
1898.96	362.251
1899.85	362.438
1900.73	357.862
1901.62	361.744
1902.5	360.724
1903.39	365.972
1904.27	362.968
1905.16	366.816
1906.04	367.658
1906.92	367.4
1907.81	366.801
1908.69	360.131
1909.58	363.071
1910.46	362.932
1911.34	365.863
1912.23	369.643
1913.11	365.933
1913.99	366.671
1914.87	362.37
1915.75	363.985
1916.64	368.89
1917.52	362.799
1918.4	370.478
1919.28	365.439
1920.16	361.199
1921.04	366.63
1921.92	364.195
1922.8	363.831
1923.68	365.249
1924.56	366.772
1925.44	365.416
1926.32	370.419
1927.2	366.288
1928.08	365.455
1928.95	368.486
1929.83	366.103
1930.64	369.922
1931.53	365.177
1932.43	368.427
1933.32	370.24
1934.21	362.453
1935.1	372.019
1935.99	374.017
1936.89	366.612
1937.78	366.063
1938.67	378.9
1939.56	372.902
1940.45	372.826
1941.34	366.586
1942.23	369.953
1943.12	368.904
1944.01	372.661
1944.9	368.886
1945.79	371.747
1946.68	372.253
1947.57	373.172
1948.46	369.646
1949.35	369.21
1950.23	369.717
1951.12	370.658
1952.01	369.516
1952.9	374.372
1953.79	371.606
1954.67	371.734
1955.56	367.084
1956.45	376.204
1957.33	368.714
1958.22	374.518
1959.1	372.192
1959.99	368.56
1960.88	369.07
1961.76	370.311
1962.65	374.069
1963.53	370.933
1964.42	369.224
1965.3	367.324
1966.19	372.906
1967.07	374.837
1967.95	373.719
1968.84	372.529
1969.72	369.097
1970.6	371.174
1971.49	369.916
1972.37	370.924
1973.25	371.783
1974.13	370.375
1975.02	374.467
1975.9	373.117
1976.78	368.915
1977.66	366.43
1978.54	370.387
1979.42	367.32
1980.3	371.932
1981.18	370.162
1982.06	377.003
1982.94	370.479
1983.82	376.666
1984.7	372.427
1985.58	370.997
1986.46	369.484
1987.34	371.35
1988.22	374.488
1989.1	371.89
1989.98	372.768
1990.85	373.805
1991.73	376.085
1992.61	370.922
1993.49	370.974
1994.36	368.968
1995.24	369.861
1996.12	372.832
1996.99	373.912
1997.87	370.845
1998.75	373.801
1999.62	369.945
2000.5	369.928
2001.37	372.997
2002.25	370.136
2003.12	373.476
2004	371.028
2004.87	373.159
2005.75	375.575
2006.62	375.299
2007.5	370.085
2008.37	372.484
2009.24	373.673
2010.12	373.855
2010.99	371.998
2011.86	369.265
2012.73	371.874
2013.61	371.796
2014.48	369.739
2015.35	373.915
2016.22	372.408
2017.09	369.406
2017.96	371.14
2018.84	369.524
2019.71	366.136
2020.58	370.112
2021.45	370.323
2022.32	368.985
2023.19	368.887
2024.06	373.867
2024.93	373.309
2025.8	376.731
2026.67	373.663
2027.53	367.854
2028.4	374.927
2029.27	371.008
2030.14	371.336
2031.01	373.837
2031.87	377.698
2032.74	371.584
2033.61	372.394
2034.48	373.776
2035.34	375.74
2036.21	374.46
2037.08	376.646
2037.94	372.626
2038.81	372.42
2039.67	376.165
2040.54	378.35
2041.41	373.328
2042.27	376.63
2043.13	371.326
2044	375.83
2044.86	371.37
2045.73	376.041
2046.59	378.512
2047.46	373.876
2048.32	373.65
2049.18	371.215
2050.05	375.101
2050.91	378.336
2051.77	378.309
2052.63	372.04
2053.49	376.598
2054.36	375.911
2055.22	372.612
2056.08	373.344
2056.94	375.532
2057.8	382.045
2058.66	376.114
2059.52	377.379
2060.39	379.474
2061.24	375.222
2062.1	376.041
2062.97	379.245
2063.83	379.796
2064.68	376.406
2065.54	381.854
2066.4	376.682
2067.26	379.986
2068.12	376.817
2068.98	377.419
2069.84	379.009
2070.69	376.684
2071.55	380.484
2072.41	380.862
2073.27	383.543
2074.12	376.504
2074.98	382.764
2075.84	379.821
2076.69	381.44
2077.55	376.443
2078.4	386.423
2079.26	379.606
2080.11	381.774
2080.97	387.479
2081.82	380.481
2082.68	383.063
2083.53	381.049
2084.39	381.898
2085.24	383.203
2086.1	383.62
2086.95	383.315
2087.8	377.092
2088.66	381.228
2089.51	385.434
2090.36	387.755
2091.22	378.814
2092.07	382.597
2092.92	380.9
2093.77	385.581
2094.62	378.839
2095.47	385.983
2096.33	383.367
2097.18	383.066
2098.03	380.805
2098.88	385.667
2099.73	382.262
2100.58	383.355
2101.43	382.596
2102.28	389.035
2103.13	382.098
2103.98	385.863
2104.83	387.377
2105.67	384.714
2106.52	384.912
2107.37	383.74
2108.22	382.489
2109.07	388.675
2109.92	386.477
2110.76	385.095
2111.61	388.218
2112.46	388.948
2113.31	388.739
2114.15	384.644
2115	392.477
2115.84	385.397
2116.69	387.64
2117.54	386.816
2118.38	388.714
2119.23	388.457
2120.07	388.849
2120.92	387.637
2121.76	401.639
2122.61	389.315
2123.45	386.836
2124.29	399.587
2125.14	389.444
2125.98	391.229
2126.83	391.001
2127.67	397.253
2128.51	393.05
2129.35	391.847
2130.2	387.442
2131.04	392.089
2131.88	391.529
2132.72	390.487
2133.57	395.634
2134.41	392.148
2135.25	390.609
2136.09	392.137
2136.93	393.15
2137.77	393.895
2138.61	391.729
2139.45	394.037
2140.29	391.638
2141.13	393.987
2141.97	392.725
2142.81	394.823
2143.65	394.318
2144.49	390.236
2145.33	393.403
2146.16	388.784
2147.01	396.868
2147.86	394.373
2148.72	391.479
2149.57	393.536
2150.42	390.545
2151.27	388.431
2152.12	395.889
2152.98	393.513
2153.83	395.494
2154.68	417.221
2155.53	394.89
2156.38	395.719
2157.23	397.032
2158.08	394.771
2158.93	396.292
2159.78	397.379
2160.63	395.141
2161.48	397.104
2162.33	393.948
2163.18	397.434
2164.03	395.853
2164.88	395.102
2165.73	396.415
2166.58	393.044
2167.42	394.284
2168.27	393.783
2169.12	393.9
2169.97	397.897
2170.81	396.06
2171.66	391.576
2172.51	394.456
2173.35	394.163
2174.2	394.504
2175.05	391.796
2175.89	400.389
2176.74	395.812
2177.58	396.194
2178.43	393.476
2179.27	397.532
2180.12	396.719
2180.96	395.505
2181.81	395.513
2182.65	397.328
2183.5	396.259
2184.34	399.009
2185.18	395.281
2186.03	400.679
2186.87	400.466
2187.71	399.412
2188.56	400.764
2189.4	393.761
2190.24	395.755
2191.08	400.749
2191.93	395.134
2192.77	395.123
2193.61	398.272
2194.45	392.669
2195.29	394.463
2196.13	392.844
2196.97	396.995
2197.81	395.866
2198.65	397.054
2199.49	397.868
2200.33	399.389
2201.17	395.995
2202.01	393.899
2202.85	397.009
2203.69	395.644
2204.53	393.135
2205.37	397.205
2206.21	394.422
2207.04	401.32
2207.88	392.862
2208.72	401.543
2209.56	399.262
2210.4	403.422
2211.23	397.351
2212.07	398.457
2212.91	396.133
2213.74	405.662
2214.58	401.874
2215.41	400.222
2216.25	397.07
2217.09	398.093
2217.92	397.806
2218.76	407.739
2219.59	398.635
2220.43	402.08
2221.26	397.703
2222.1	407.313
2222.93	401
2223.76	399.643
2224.6	397.276
2225.43	399.613
2226.26	404.474
2227.1	399.449
2227.93	403.647
2228.76	397.604
2229.6	395.704
2230.43	405.068
2231.26	401.796
2232.09	402.32
2232.92	404.381
2233.76	406.617
2234.59	401.632
2235.42	400.961
2236.25	403.286
2237.08	403.45
2237.91	402.92
2238.74	403.913
2239.57	403.514
2240.4	408.979
2241.23	404.567
2242.06	408.909
2242.89	403.662
2243.72	405.596
2244.54	403.669
2245.37	407.528
2246.2	406.942
2247.03	413.636
2247.86	404.617
2248.68	403.905
2249.51	409.063
2250.34	405.619
2251.17	407.719
2251.99	407.202
2252.82	409.412
2253.65	406.155
2254.47	404.298
2255.3	407.651
2256.12	413.035
2256.95	410.429
2257.77	411.35
2258.6	417.513
2259.42	411.699
2260.25	414.725
2261.07	413.649
2261.9	414.078
2262.72	408.043
2263.54	411.508
2264.37	409.476
2265.19	411.026
2266.02	409.249
2266.84	413.34
2267.66	407.815
2268.48	412.378
2269.31	409.853
2270.13	416.356
2270.95	409.109
2271.77	413.777
2272.59	412.95
2273.42	407.138
2274.24	415.608
2275.06	410.135
2275.88	411.658
2276.7	410.831
2277.52	413.043
2278.34	415.291
2279.16	414.474
2279.98	419.316
2280.8	416.172
2281.62	414.551
2282.44	423.062
2283.25	416.719
2284.07	411.601
2284.89	416.333
2285.71	421.068
2286.53	411.686
2287.35	413.007
2288.16	412.536
2288.98	415.672
2289.8	410.131
2290.61	421.019
2291.43	415.24
2292.25	412.176
2293.06	415.85
2293.88	412.861
2294.7	413.153
2295.51	413.855
2296.33	416.751
2297.14	412.998
2297.96	415.443
2298.77	418.474
2299.59	412.918
2300.4	414.46
2301.22	414.913
2302.03	415.064
2302.84	417.524
2303.66	414.008
2304.47	415.65
2305.28	414.524
2306.1	418.34
2306.91	409.137
2307.72	412.491
2308.53	410.275
2309.35	416.373
2310.16	420.782
2310.97	414.025
2311.78	414.743
2312.59	417.356
2313.4	412.382
2314.22	410.61
2315.03	417.739
2315.84	419.18
2316.65	419.876
2317.46	417.425
2318.27	417.018
2319.08	410.749
2319.89	423.647
2320.69	415.794
2321.5	417.361
2322.31	418.914
2323.12	419.927
2323.93	417.594
2324.74	424.239
2325.55	418.657
2326.35	421.159
2327.16	421.594
2327.97	426.75
2328.78	424.758
2329.58	417.311
2330.39	416.498
2331.2	417.355
2332	427.293
2332.81	417.777
2333.61	422.192
2334.42	417.875
2335.23	420.263
2336.03	420.181
2336.84	420.559
2337.64	420.37
2338.45	422.872
2339.25	420.213
2340.05	422.565
2340.86	421.813
2341.66	422.941
2342.47	420.18
2343.27	420.561
2344.07	423.08
2344.87	420.459
2345.68	424.107
2346.48	420.691
2347.28	423.731
2348.08	426.809
2348.89	426.322
2349.69	423.179
2350.49	424.594
2351.29	423.003
2352.09	427.84
2352.89	420.081
2353.71	427.922
2354.52	422.067
2355.34	428.797
2356.15	424.673
2356.96	422.107
2357.78	428.301
2358.59	429.539
2359.41	425.519
2360.22	428.345
2361.03	423.817
2361.85	426.209
2362.66	425.68
2363.47	432.532
2364.29	429.287
2365.1	431.44
2365.91	429.001
2366.72	428.066
2367.54	422.717
2368.35	428.797
2369.16	430.465
2369.97	429.243
2370.78	428.228
2371.59	433.878
2372.4	426.975
2373.21	430.867
2374.02	426.859
2374.83	433.239
2375.64	429.452
2376.45	429.75
2377.26	430.708
2378.07	425.924
2378.88	427.853
2379.69	435.475
2380.5	428.128
2381.31	431.606
2382.12	432.327
2382.92	426.04
2383.73	434.332
2384.54	433.197
2385.35	433.666
2386.15	430.667
2386.96	430.774
2387.77	435.218
2388.57	432.718
2389.38	432.346
2390.19	435.51
2390.99	434.066
2391.8	428.572
2392.6	432.899
2393.41	430.533
2394.22	435.356
2395.02	439.017
2395.83	431.364
2396.63	433.571
2397.44	436.046
2398.24	433.905
2399.04	430.811
2399.85	429.632
2399.98	434.333