File: Data/3-Raman/raw/bu04w-a-ff3-fi10-l_150 (500nm)_633nm_edge_100%_x100_vis_lwd_h50um_45sx2_01.txt
#Acq. time (s)=	45
#Accumulations=	2
#Range (cm-¹)=	100...4000
#Windows=	1
#Auto scanning=	Off
#Autofocus=	Off
#Macrospot=	Off
#AutoExposure=	Off
#Spike filter=	Multiple accum.
#Delay time (s)=	2
#Binning=	1
#Readout mode=	Signal
#DeNoise=	Off
#ICS correction=	On
#Dark correction=	Off
#Inst. Process=	Off
#Detector Gain=	Best Dynamic
#Detector ADC=	50 kHz EM
#Detector EM gain=	100
#Detector temperature (°C)=	-60.09
#Instrument=	LabRAM HR Evol
#Detector=	SIN-EM FIVIS
#Objective=	x100_VIS_LWD
#Grating=	150 (500nm)
#ND Filter=	100%
#Laser=	633nm_Edge
#Hole=	49.98
#Temperature=	0
#Range=	Visible
#StageXY=	75x50mm Scan+
#StageZ=	Z motor
#X (µm)=	0
#Y (µm)=	0
#Z (µm)=	4.3
#Full time(mm:ss)=	1:34
#Project=	21_11_22
#Sample=	BU04w
#Site=
#Title=	BU04w-A-FF3-FI10-L_150 (500nm)_633nm_Edge_100%_x100_VIS_LWD_H50um_45sX2
#Remark=
#Date=	22.11.2021 11:48
#Acquired=	22.11.2021 11:48:48
100.177	2001.59
106.695	1869.65
113.209	1825.72
119.717	1778.4
126.219	1705.03
132.716	1682
139.208	1744.4
145.694	1671.01
152.175	1561.35
158.651	1701.09
165.121	2060.57
171.586	1601.02
178.045	1291.05
184.5	1160.66
190.947	1084.34
197.39	1027.35
203.829	1004.03
210.262	964.547
216.688	978.49
223.11	1028.51
229.527	1249.96
235.939	1776.34
242.344	1487.78
248.745	1072.34
255.141	1026.05
261.53	1040.76
267.916	945.598
274.294	947.416
280.669	1019.4
287.038	1072.99
293.402	955.644
299.76	914.16
306.114	935.966
312.461	1030.52
318.805	1435.52
325.142	2448.38
331.475	2544.08
337.802	1655.12
344.123	1171.97
350.441	1013.09
356.752	1010.39
363.058	1058.32
369.36	1021.52
375.656	970.674
381.947	841.211
388.232	821.505
394.512	787.674
400.789	846.759
407.059	906.983
413.324	939.846
419.584	1048.97
425.839	1269.62
432.089	1562.32
438.333	1577.42
444.573	1210.86
450.807	1153.91
457.037	1200.38
463.261	1126.47
469.48	895.324
475.695	819.701
481.904	843.178
488.108	838.598
494.307	851.857
500.502	967.64
506.691	1058.61
512.874	1174.14
519.053	1126.8
525.227	1023.94
531.396	1034.77
537.559	968.978
543.718	898.395
549.873	847.361
556.022	811.226
562.165	792.61
568.304	751.59
574.437	680.911
580.567	655.267
586.691	714.265
592.81	735.493
598.924	816.094
605.033	864.685
611.138	780.261
617.236	781.367
623.332	747.119
629.42	724.747
635.506	681.997
641.585	660.744
647.659	703.808
653.73	757.745
659.794	771.638
665.854	727.601
671.91	661.937
677.96	565.13
684.005	550.42
690.045	583.946
696.082	543.133
702.113	539.607
708.139	545.248
714.16	567.756
720.176	544.854
726.187	517.198
732.194	505.04
738.196	515.348
744.193	518.223
750.185	510.115
756.173	512.636
762.155	529.139
768.133	537.105
774.107	499.249
780.075	513.59
786.039	494.567
791.998	504.487
797.952	490.465
803.902	507.097
809.845	518.754
815.786	494.288
821.721	507.211
827.652	518.097
833.576	558.653
839.498	533.784
845.415	539.462
851.327	559.378
857.233	544.782
863.135	538.731
869.032	563.865
874.925	604.701
880.813	628.975
886.697	603.543
892.576	602.36
898.45	585.571
904.318	592.706
910.184	584.572
916.044	590.604
921.9	623.703
927.75	711.113
933.596	739.321
939.439	872.709
945.275	1081.4
951.107	1284.5
956.936	1250.94
962.759	1201.82
968.577	1083.47
974.391	1119.3
980.201	1341.45
986.006	1683.58
991.806	1774.44
997.602	1526.84
1003.39	1416.13
1009.18	1271.51
1014.96	1337.63
1020.74	1663.69
1026.51	1822.3
1032.28	1406.68
1038.04	1043.29
1043.8	872.729
1049.56	814.237
1055.31	759.633
1061.05	721.703
1066.8	660.476
1072.53	668.058
1078.26	752.98
1083.99	854.048
1089.72	950.323
1095.44	1321.52
1101.15	1503.48
1106.86	1145.95
1112.56	857.257
1118.27	729.936
1123.96	683.017
1129.65	672.93
1135.34	741.208
1141.03	823.557
1146.7	1022.55
1152.38	1563.41
1158.05	1568.27
1163.71	945.667
1169.37	703.529
1175.03	621.841
1180.68	581.559
1186.33	555.668
1191.98	522.54
1197.61	518.332
1203.25	503.086
1208.88	492.101
1214.51	489.11
1220.13	498.314
1225.74	460.832
1231.36	487.97
1236.97	516.958
1242.57	503.196
1248.17	496.854
1253.77	489.043
1259.36	495.808
1264.94	511.24
1270.53	485.309
1276.11	484.291
1281.68	466.164
1287.25	495.386
1292.81	471.828
1298.38	451.701
1303.93	470.882
1309.48	463.68
1315.03	489.217
1320.58	462.645
1326.12	457.351
1331.65	458.192
1337.18	447.569
1342.71	455.983
1348.23	451.795
1353.75	475.159
1359.26	459.252
1364.77	489.235
1370.28	523.014
1375.78	599.856
1381.28	599.603
1386.77	493.615
1392.26	472.993
1397.74	485.843
1403.23	451.531
1408.7	472.884
1414.17	450.079
1419.64	456.273
1425.11	449.118
1430.56	455.482
1436.02	449.338
1441.47	463.995
1446.92	457.827
1452.36	450.104
1457.8	421.035
1463.23	465.184
1468.66	473.456
1474.09	450.267
1479.51	437.798
1484.93	453.792
1490.34	464.782
1495.75	465.535
1501.16	454.837
1506.56	469.627
1511.96	449.698
1517.35	475.577
1522.74	446.216
1528.13	464.912
1533.51	459.155
1538.88	479.989
1544.25	463.806
1549.62	457.594
1554.99	463.719
1560.35	467.469
1565.71	488.583
1571.06	481.596
1576.41	484.403
1581.75	466.105
1587.09	506.078
1592.43	482.705
1597.76	491.912
1603.09	481.897
1608.41	490.567
1613.73	491.017
1619.05	513.589
1624.36	504.612
1629.67	484.534
1634.97	492.751
1640.27	507.956
1645.57	518.718
1650.86	539.309
1656.15	509.861
1661.43	513.379
1666.71	513.472
1671.99	492.42
1677.26	489.018
1682.53	492.176
1687.79	496.154
1693.05	468.214
1698.31	486.148
1703.56	492.513
1708.81	471.244
1714.06	489.459
1719.3	470.718
1724.53	501.667
1729.77	464.566
1735	456.521
1740.22	466.41
1745.44	487.619
1750.66	491.718
1755.87	475.287
1761.08	466.439
1766.29	508.527
1771.49	451.03
1776.69	458.201
1781.88	497.46
1787.07	457.36
1792.26	475.485
1797.44	482.317
1802.62	472.183
1807.79	492.981
1812.96	460.643
1818.13	485.894
1823.29	481.162
1828.45	519.36
1833.61	478.776
1838.76	488.065
1843.91	481.961
1849.05	489.765
1854.19	484.549
1859.33	495.898
1864.46	498.041
1869.59	486.131
1874.71	480.932
1879.83	487.432
1884.95	471.416
1890.06	475.252
1895.17	470.544
1900.28	486.162
1905.38	477.548
1910.48	500.037
1915.57	493.357
1920.66	479.838
1925.75	498.672
1930.83	490.057
1935.91	500.538
1940.99	498.869
1946.06	499.436
1951.13	498.635
1956.19	507.281
1961.26	506.201
1966.31	496.584
1971.36	492.747
1976.41	493.673
1981.46	481.357
1986.5	490.735
1991.54	509.792
1996.58	502.474
2001.61	507.32
2006.63	505.137
2011.66	500.701
2016.68	481.833
2021.69	513.444
2026.71	495.942
2031.72	496.729
2036.72	487.997
2041.72	498.67
2046.72	490.009
2051.71	514.24
2056.71	502.878
2061.69	499.107
2066.68	523.542
2071.66	501.302
2076.63	498.648
2081.6	490.953
2086.57	523.819
2091.54	502.315
2096.5	540.589
2101.46	504.575
2106.41	525.82
2111.36	531.065
2116.31	513.915
2121.25	534.363
2126.19	553.595
2131.13	527.292
2136.06	524.781
2140.99	538.655
2145.92	530.85
2150.84	510.008
2155.76	514.459
2160.67	536.638
2165.58	522.838
2170.49	498.709
2175.39	537.49
2180.29	509.52
2185.19	536.339
2190.08	528.742
2194.98	534.151
2199.86	533.449
2204.74	534.268
2209.62	522.423
2214.5	549.36
2219.37	542.977
2224.24	514.553
2229.11	531.456
2233.97	527.596
2238.83	523.706
2243.68	531.574
2248.53	552.633
2253.38	522.419
2258.22	552.782
2263.06	527.689
2267.9	544.635
2272.73	505.669
2277.56	528.875
2282.39	547.91
2287.21	537.425
2292.03	546.888
2296.85	540.404
2301.66	548.838
2306.47	537.59
2311.28	538.624
2316.08	531.813
2320.88	533.174
2325.68	562.834
2330.47	542.78
2335.26	559.337
2340.04	547.513
2344.82	533.03
2349.6	567.817
2354.38	540.884
2359.15	534.096
2363.92	564.088
2368.68	566.704
2373.44	554.013
2378.2	566.222
2382.95	532.276
2387.71	559.188
2392.45	563.637
2397.2	555.361
2401.94	567.896
2406.68	562.2
2411.41	550.233
2416.14	556.186
2420.87	554.717
2425.59	585.041
2430.31	572.397
2435.03	538.666
2439.75	551.658
2444.46	550.452
2449.16	540.697
2453.87	559.464
2458.57	538.139
2463.27	559.851
2467.96	570.054
2472.65	580.19
2477.34	581.715
2482.02	555.562
2486.7	565.529
2491.38	573.992
2496.05	588.375
2500.72	583.655
2505.39	574.413
2510.06	587.078
2514.72	599.628
2519.37	579.795
2524.03	573.352
2528.68	580.133
2533.33	587.019
2537.97	570.326
2542.61	583.398
2547.25	581.699
2551.88	618.852
2556.51	576.653
2561.14	603.305
2565.77	571.632
2570.39	597.236
2575.01	585.17
2579.62	580.425
2584.23	608.698
2588.84	598.78
2593.45	576.434
2598.05	587.999
2602.65	596.428
2607.24	597.128
2611.84	602.247
2616.42	584.366
2621.01	597.14
2625.59	573.233
2630.17	595.55
2634.75	589.197
2639.32	589.462
2643.89	619.176
2648.46	610.3
2653.02	607.535
2657.58	619.63
2662.14	597.175
2666.69	605.724
2671.24	614.641
2675.79	595.954
2680.33	609.956
2684.88	612.726
2689.41	615.484
2693.95	632.209
2698.48	620.382
2703.01	621.72
2707.53	610.024
2712.06	612.683
2716.57	633.436
2721.09	652.445
2725.6	624.267
2730.11	618.518
2734.62	617.399
2739.12	635.667
2743.62	625.03
2748.12	640.655
2752.61	609.74
2757.1	632.413
2761.59	621.855
2766.08	644.401
2770.56	627.488
2775.04	638.792
2779.51	640.539
2783.98	646.043
2788.45	661.558
2792.92	645.274
2797.38	647.095
2801.84	655.445
2806.3	645.051
2810.75	629.406
2815.2	669.285
2819.65	648.292
2824.09	652.754
2828.53	645.343
2832.97	642.907
2837.41	676.161
2841.84	646.438
2846.27	662.901
2850.69	648.752
2855.12	629.723
2859.54	658.811
2863.95	690.012
2868.37	659.317
2872.78	678.701
2877.18	639.049
2881.59	683.141
2885.99	678.602
2890.39	716.125
2894.78	702.609
2899.18	703.495
2903.57	709.424
2907.95	697.301
2912.34	700.883
2916.72	707.795
2921.09	698.766
2925.47	697.011
2929.84	709.887
2934.21	706.43
2938.57	695.245
2942.94	681.993
2947.29	677.549
2951.65	727.787
2956	710.558
2960.36	718.875
2964.7	714.494
2969.05	699.247
2973.39	718.939
2977.73	690.817
2982.06	694.039
2986.4	716.084
2990.73	732.851
2995.05	747.943
2999.38	753.976
3003.7	741.485
3008.01	742.125
3012.33	765.142
3016.64	756.449
3020.95	799.076
3025.26	744.521
3029.56	796.129
3033.86	794.126
3038.16	787.84
3042.45	778.059
3046.74	825.637
3051.03	794.27
3055.32	853.612
3059.6	812.592
3063.88	835.335
3068.16	856.22
3072.43	875.223
3076.7	855.408
3080.97	890.191
3085.24	868.553
3089.5	911.913
3093.76	879.22
3098.02	939.344
3102.27	932.565
3106.52	971.762
3110.77	961.559
3115.01	919.268
3119.26	957.083
3123.5	995.486
3127.73	1048.64
3131.97	1000.75
3136.2	1044.53
3140.43	1034.93
3144.65	1084.75
3148.87	1089.03
3153.09	1080.11
3157.31	1129.25
3161.52	1124.23
3165.73	1079.16
3169.94	1157.67
3174.15	1171.47
3178.35	1213.85
3182.55	1219.9
3186.75	1263.85
3190.94	1252.51
3195.13	1261.04
3199.32	1313.37
3203.51	1322.4
3207.69	1299.61
3211.87	1317.79
3216.05	1349.51
3220.22	1339.79
3224.39	1290.55
3228.56	1221.21
3232.73	1300.81
3236.89	1261.14
3241.05	1248.37
3245.21	1251.62
3249.36	1269.73
3253.52	1286.78
3257.66	1305.41
3261.81	1228.6
3265.95	1256.02
3270.1	1245.79
3274.23	1239.54
3278.37	1285.43
3282.5	1310.95
3286.63	1265.38
3290.76	1251.71
3294.88	1214.74
3299	1226.14
3303.12	1268.03
3307.24	1254.32
3311.35	1245
3315.46	1249.57
3319.57	1200.68
3323.68	1280.6
3327.78	1265.17
3331.88	1222.08
3335.98	1224.11
3340.07	1216.04
3344.16	1275.6
3348.25	1325.3
3352.34	1353.93
3356.42	1325.65
3360.5	1330.99
3364.58	1341.16
3368.66	1310.38
3372.73	1293.8
3376.8	1351.28
3380.87	1307.35
3384.93	1275.24
3388.99	1351.72
3393.05	1316.82
3397.11	1267.76
3401.16	1349.65
3405.21	1312.02
3409.26	1400.86
3413.31	1299.67
3417.35	1368.93
3421.39	1330.93
3425.43	1341.61
3429.46	1269.77
3433.5	1413.24
3437.53	1327.33
3441.55	1312.55
3445.58	1403.89
3449.6	1328.59
3453.62	1361.77
3457.64	1338.88
3461.65	1276.37
3465.66	1250.93
3469.67	1315.38
3473.68	1293.84
3477.68	1292.78
3481.68	1314.36
3485.68	1333.36
3489.67	1283.66
3493.67	1243.75
3497.66	1279.81
3501.64	1236.33
3505.63	1279.41
3509.61	1234.6
3513.59	1237.98
3517.57	1210.45
3521.54	1270.28
3525.52	1152.78
3529.49	1220.39
3533.45	1227.26
3537.42	1211.74
3541.38	1183.43
3545.34	1175.17
3549.29	1150.94
3553.25	1135.91
3557.2	1118.71
3561.15	1125.3
3565.09	1140.11
3569.04	1171.39
3572.98	1113.48
3576.92	1100.35
3580.85	1124.48
3584.79	1162.19
3588.72	1133.83
3592.64	1062.73
3596.57	1092.47
3600.49	1114.04
3604.41	1036.51
3608.33	1060.29
3612.25	1043.6
3616.16	1051.1
3620.07	1061.1
3623.98	1040.45
3627.88	1035.72
3631.79	1006.36
3635.69	1020.45
3639.58	1002.65
3643.48	1031.66
3647.37	995.881
3651.26	1001.95
3655.15	997.526
3659.03	1014.79
3662.92	1018.28
3666.8	978.262
3670.67	954.634
3674.55	972.226
3678.42	1012.33
3682.29	976.054
3686.16	934.557
3690.02	992.471
3693.89	928.657
3697.75	906.039
3701.61	953.087
3705.46	955.55
3709.31	961.029
3713.16	966.455
3717.01	957.432
3720.86	1001.74
3724.7	986.647
3728.54	951.527
3732.38	936.278
3736.21	955.125
3740.04	991
3743.87	955.523
3747.7	979.77
3751.53	980.925
3755.35	973.204
3759.17	968.072
3762.99	965.667
3766.81	966.087
3770.62	992.633
3774.43	970.539
3778.24	954.221
3782.04	972.739
3785.85	962.751
3789.65	958.314
3793.45	965.535
3797.24	976.088
3801.04	960.676
3804.83	965.689
3808.62	944.614
3812.4	967.07
3816.19	960.222
3819.97	991.428
3823.75	975.547
3827.52	1003.54
3831.3	984.74
3835.07	980.67
3838.84	970.453
3842.61	1002.04
3846.37	1003.23
3850.13	1003.87
3853.89	995.473
3857.65	992.833
3861.41	966.188
3865.16	1008.83
3868.91	978.481
3872.66	967.602
3876.4	986.134
3880.14	1013.66
3883.89	951.577
3887.62	991.407
3891.36	971.512
3895.09	973.24
3898.82	1004.83
3902.55	970.249
3906.28	977.679
3910	985.067
3913.73	1004.92
3917.45	1015.97
3921.16	997.091
3924.88	1008.61
3928.59	1007.72
3932.3	972.924
3936.01	1011.12
3939.71	985.064
3943.42	987.074
3947.12	982.794
3950.81	965.904
3954.51	1022.85
3958.2	1017.88
3961.9	993.912
3965.58	1000.78
3969.27	1016.55
3972.96	1004.47
3976.64	1020.32
3980.32	1008.01
3984	1007.89
3987.67	1010.92
3991.34	1032.8
3995.01	1014.74
3998.68	997.044