File: Data/3-Raman/raw/bu04w-a-ff3-fi04-v_150 (500nm)_633nm_edge_100%_x100_vis_lwd_h50um_45sx2_01.txt
#Acq. time (s)=	45
#Accumulations=	2
#Range (cm-¹)=	100...4000
#Windows=	1
#Auto scanning=	Off
#Autofocus=	Off
#Macrospot=	Off
#AutoExposure=	Off
#Spike filter=	Multiple accum.
#Delay time (s)=	2
#Binning=	1
#Readout mode=	Signal
#DeNoise=	Off
#ICS correction=	On
#Dark correction=	Off
#Inst. Process=	Off
#Detector Gain=	Best Dynamic
#Detector ADC=	50 kHz HS
#Detector temperature (°C)=	-60.09
#Instrument=	LabRAM HR Evol
#Detector=	SIN-EM FIVIS
#Objective=	x100_VIS_LWD
#Grating=	150 (500nm)
#ND Filter=	100%
#Laser=	633nm_Edge
#Hole=	49.98
#Temperature=	0
#Range=	Visible
#StageXY=	75x50mm Scan+
#StageZ=	Z motor
#X (µm)=	0
#Y (µm)=	0
#Z (µm)=	5.7
#Full time(mm:ss)=	1:34
#Project=	21_11_22
#Sample=	BU04w
#Site=
#Title=	BU04w-A-FF3-FI04-V_150 (500nm)_633nm_Edge_100%_x100_VIS_LWD_H50um_45sX2
#Remark=
#Date=	22.11.2021 12:16
#Acquired=	22.11.2021 12:16:11
100.177	870.693
106.695	799.848
113.209	806.392
119.717	756.37
126.219	797.049
132.716	807.993
139.208	792.779
145.694	779.517
152.175	750.997
158.651	807.92
165.121	831.417
171.586	767.435
178.045	750.956
184.5	723.494
190.947	739.628
197.39	767.173
203.829	740.14
210.262	764.673
216.688	777.737
223.11	795.454
229.527	853.458
235.939	868.675
242.344	822.269
248.745	830.609
255.141	810.114
261.53	816.388
267.916	806.651
274.294	796.152
280.669	816.941
287.038	829.861
293.402	839.622
299.76	828.517
306.114	847.569
312.461	878.921
318.805	942.384
325.142	1066.63
331.475	1041.87
337.802	928.469
344.123	895.241
350.441	899.526
356.752	882.798
363.058	895.104
369.36	912.038
375.656	890.41
381.947	885.756
388.232	934.509
394.512	913.946
400.789	921.556
407.059	926.311
413.324	989.436
419.584	960.535
425.839	1003.3
432.089	1049.26
438.333	1036.39
444.573	1008.42
450.807	1008.27
457.037	1014.02
463.261	1015.97
469.48	964.733
475.695	995.285
481.904	1008.55
488.108	970.445
494.307	1024.74
500.502	1033.36
506.691	1030.16
512.874	1036.47
519.053	1021.69
525.227	1055.3
531.396	1019.29
537.559	1026.83
543.718	1016.7
549.873	1040.33
556.022	1028.91
562.165	1020.49
568.304	1004.47
574.437	1014.79
580.567	1000.22
586.691	993.902
592.81	1037.99
598.924	1083
605.033	1048.91
611.138	1045.18
617.236	1022.62
623.332	1011.66
629.42	1025.86
635.506	994.697
641.585	1018.45
647.659	995.023
653.73	1058.68
659.794	1028.69
665.854	1007.34
671.91	989.642
677.96	997.371
684.005	980.961
690.045	994.577
696.082	1007.14
702.113	985.838
708.139	958.414
714.16	971.483
720.176	978.389
726.187	941
732.194	954.328
738.196	967.564
744.193	962.215
750.185	931.17
756.173	939.056
762.155	944.89
768.133	941.805
774.107	937.031
780.075	944.873
786.039	928.373
791.998	927.407
797.952	917.263
803.902	927.95
809.845	926.885
815.786	911.05
821.721	892.072
827.652	906.67
833.576	878.618
839.498	915.659
845.415	907.064
851.327	911.804
857.233	878.332
863.135	878.859
869.032	882.222
874.925	885.726
880.813	879.901
886.697	901.994
892.576	841.881
898.45	849.457
904.318	871.098
910.184	839.615
916.044	852.52
921.9	857.122
927.75	871.278
933.596	873.359
939.439	865.633
945.275	894.384
951.107	917.023
956.936	915.542
962.759	879.839
968.577	876.846
974.391	892.269
980.201	882.305
986.006	960.606
991.806	941.742
997.602	903.785
1003.39	892.113
1009.18	886.909
1014.96	887.778
1020.74	906.816
1026.51	954.695
1032.28	866.941
1038.04	803.164
1043.8	809.495
1049.56	777.931
1055.31	778.551
1061.05	760.071
1066.8	772.66
1072.53	753.993
1078.26	768.99
1083.99	787.644
1089.72	776.436
1095.44	855.358
1101.15	852.846
1106.86	788.322
1112.56	749.253
1118.27	732.365
1123.96	742.939
1129.65	736.903
1135.34	748.552
1141.03	745.521
1146.7	777.236
1152.38	840.281
1158.05	816.622
1163.71	774.13
1169.37	737.381
1175.03	695.777
1180.68	720.839
1186.33	683.11
1191.98	701.767
1197.61	710.507
1203.25	699.711
1208.88	696.323
1214.51	655.605
1220.13	681.46
1225.74	663.818
1231.36	669.832
1236.97	654.244
1242.57	663.029
1248.17	659.948
1253.77	691.632
1259.36	693.223
1264.94	650.898
1270.53	670.069
1276.11	762.105
1281.68	727.316
1287.25	633.994
1292.81	597.282
1298.38	627.084
1303.93	638.339
1309.48	614.402
1315.03	634.375
1320.58	626.436
1326.12	630.881
1331.65	627.347
1337.18	624.455
1342.71	604.74
1348.23	620.321
1353.75	615.244
1359.26	613.877
1364.77	607.946
1370.28	607.785
1375.78	633.239
1381.28	931.747
1386.77	633.695
1392.26	602.784
1397.74	606.534
1403.23	622.784
1408.7	605.271
1414.17	579.632
1419.64	573.704
1425.11	580.326
1430.56	563.113
1436.02	569.753
1441.47	564.841
1446.92	545.307
1452.36	574.434
1457.8	533.905
1463.23	529.764
1468.66	561.114
1474.09	540.006
1479.51	527.562
1484.93	573.018
1490.34	555.74
1495.75	539.789
1501.16	556.673
1506.56	534.676
1511.96	547.805
1517.35	558.031
1522.74	508.665
1528.13	529.722
1533.51	525.286
1538.88	532.302
1544.25	506.511
1549.62	527.369
1554.99	535.601
1560.35	536.024
1565.71	508.536
1571.06	521.999
1576.41	504.317
1581.75	515.084
1587.09	527.075
1592.43	527.419
1597.76	526.972
1603.09	508.369
1608.41	507.353
1613.73	518.718
1619.05	506.501
1624.36	507.348
1629.67	499.367
1634.97	487.79
1640.27	505.195
1645.57	510.423
1650.86	485.599
1656.15	494.897
1661.43	503.954
1666.71	485.192
1671.99	474.121
1677.26	472.939
1682.53	476.103
1687.79	488.955
1693.05	495.333
1698.31	472.305
1703.56	498.628
1708.81	490.786
1714.06	473.293
1719.3	473.513
1724.53	466.394
1729.77	476.348
1735	477.323
1740.22	454.581
1745.44	471.252
1750.66	470.806
1755.87	474.721
1761.08	470.401
1766.29	450.199
1771.49	454.996
1776.69	445.158
1781.88	456.005
1787.07	448.827
1792.26	431.585
1797.44	448.6
1802.62	469.318
1807.79	461.38
1812.96	446.248
1818.13	461.08
1823.29	440.101
1828.45	453.861
1833.61	452.63
1838.76	445.549
1843.91	428.863
1849.05	438.918
1854.19	432.466
1859.33	443.729
1864.46	430.5
1869.59	399.616
1874.71	463.84
1879.83	440.814
1884.95	435.381
1890.06	423.825
1895.17	407.293
1900.28	427.61
1905.38	420.076
1910.48	411.55
1915.57	429.602
1920.66	417.173
1925.75	421.539
1930.83	384.018
1935.91	418.315
1940.99	415.324
1946.06	426.626
1951.13	401.678
1956.19	410.283
1961.26	429.668
1966.31	406.789
1971.36	388.535
1976.41	406.377
1981.46	386.891
1986.5	415.561
1991.54	384.147
1996.58	408.11
2001.61	378.086
2006.63	419.143
2011.66	390.571
2016.68	400.524
2021.69	369.415
2026.71	378.291
2031.72	395.812
2036.72	392.94
2041.72	385.226
2046.72	393.344
2051.71	395.429
2056.71	374.107
2061.69	385.952
2066.68	380.702
2071.66	377.819
2076.63	399.534
2081.6	353.412
2086.57	376.186
2091.54	377.973
2096.5	394.903
2101.46	362.275
2106.41	364.461
2111.36	356.75
2116.31	361.621
2121.25	366.51
2126.19	366.331
2131.13	366.07
2136.06	347.953
2140.99	360.162
2145.92	346.898
2150.84	367.843
2155.76	352.972
2160.67	355.842
2165.58	357.294
2170.49	367.638
2175.39	351.288
2180.29	355.256
2185.19	348.812
2190.08	345.027
2194.98	350.336
2199.86	337.894
2204.74	342.266
2209.62	339.06
2214.5	343.672
2219.37	341.946
2224.24	331.154
2229.11	319.004
2233.97	344.566
2238.83	333.683
2243.68	329.288
2248.53	311.759
2253.38	329.637
2258.22	329.162
2263.06	344.519
2267.9	345.201
2272.73	323.177
2277.56	312.94
2282.39	319.836
2287.21	318.597
2292.03	347.959
2296.85	321.447
2301.66	315.049
2306.47	326.156
2311.28	318.764
2316.08	322.169
2320.88	335.081
2325.68	329.218
2330.47	299.069
2335.26	309.464
2340.04	305.004
2344.82	318.319
2349.6	297.591
2354.38	324.668
2359.15	298.02
2363.92	317.903
2368.68	302.012
2373.44	301.244
2378.2	301.846
2382.95	312
2387.71	292.809
2392.45	290.168
2397.2	291.599
2401.94	273.509
2406.68	292.928
2411.41	290.44
2416.14	285.779
2420.87	294.211
2425.59	296.037
2430.31	288.314
2435.03	277.816
2439.75	292.847
2444.46	300.828
2449.16	278.909
2453.87	289.748
2458.57	286.29
2463.27	290
2467.96	277.811
2472.65	277.073
2477.34	279.252
2482.02	268.328
2486.7	284.951
2491.38	270.93
2496.05	281.747
2500.72	272.03
2505.39	282.799
2510.06	272.94
2514.72	264.455
2519.37	272.194
2524.03	275.593
2528.68	273.047
2533.33	260.156
2537.97	247.29
2542.61	255.237
2547.25	276.68
2551.88	277.288
2556.51	247.886
2561.14	254.379
2565.77	244.448
2570.39	252.619
2575.01	262.344
2579.62	268.996
2584.23	248.185
2588.84	272.795
2593.45	265.403
2598.05	264.295
2602.65	252.452
2607.24	255.803
2611.84	254.503
2616.42	251.644
2621.01	239.622
2625.59	255.196
2630.17	241.75
2634.75	249.986
2639.32	230.692
2643.89	239.157
2648.46	243.033
2653.02	225.099
2657.58	238.019
2662.14	235.275
2666.69	237.125
2671.24	228.139
2675.79	211.493
2680.33	223.598
2684.88	223.026
2689.41	241.569
2693.95	232.877
2698.48	239.657
2703.01	248.206
2707.53	242.239
2712.06	220.082
2716.57	239.962
2721.09	229.084
2725.6	224.574
2730.11	221.595
2734.62	229.9
2739.12	226.792
2743.62	220.551
2748.12	222.518
2752.61	226.405
2757.1	228.553
2761.59	227.248
2766.08	214.526
2770.56	223.162
2775.04	225.31
2779.51	199.444
2783.98	215.071
2788.45	219.131
2792.92	219.828
2797.38	217.096
2801.84	219.322
2806.3	211.368
2810.75	196.584
2815.2	201.969
2819.65	193.81
2824.09	200.912
2828.53	206.34
2832.97	208.35
2837.41	188.201
2841.84	203.824
2846.27	202.458
2850.69	211.401
2855.12	210.194
2859.54	217.597
2863.95	187.166
2868.37	205.063
2872.78	195.279
2877.18	194.152
2881.59	200.05
2885.99	202.528
2890.39	203.225
2894.78	182.714
2899.18	208.213
2903.57	198.247
2907.95	195.28
2912.34	204.722
2916.72	210.547
2921.09	211.067
2925.47	184.609
2929.84	206.824
2934.21	192.91
2938.57	200.586
2942.94	184.593
2947.29	197.619
2951.65	177.843
2956	201.842
2960.36	183.834
2964.7	193.28
2969.05	180.777
2973.39	173.759
2977.73	201.719
2982.06	176.279
2986.4	193.361
2990.73	182.749
2995.05	190.707
2999.38	183.828
3003.7	188.18
3008.01	181.304
3012.33	181.862
3016.64	191.949
3020.95	171.773
3025.26	193.271
3029.56	186.145
3033.86	173.177
3038.16	181.146
3042.45	179.626
3046.74	183.796
3051.03	178.325
3055.32	190.228
3059.6	184.768
3063.88	183.154
3068.16	175.71
3072.43	179.907
3076.7	189.982
3080.97	178.624
3085.24	182.905
3089.5	173.558
3093.76	185.875
3098.02	182.541
3102.27	177.207
3106.52	161.96
3110.77	174.557
3115.01	181.25
3119.26	179.956
3123.5	174.664
3127.73	175.449
3131.97	188.532
3136.2	197.641
3140.43	175.917
3144.65	182.858
3148.87	175.282
3153.09	182.1
3157.31	178.468
3161.52	187.371
3165.73	179.51
3169.94	201.014
3174.15	178.359
3178.35	185.039
3182.55	181.078
3186.75	189.79
3190.94	194.245
3195.13	171.187
3199.32	188.69
3203.51	182.954
3207.69	200.849
3211.87	193.032
3216.05	178.707
3220.22	172.911
3224.39	173.602
3228.56	202.804
3232.73	166.177
3236.89	175.588
3241.05	171.845
3245.21	179.28
3249.36	177.718
3253.52	160.287
3257.66	167.389
3261.81	158.929
3265.95	168.601
3270.1	160.271
3274.23	151.804
3278.37	152.101
3282.5	147.826
3286.63	173.386
3290.76	146.109
3294.88	153.283
3299	153.556
3303.12	156.19
3307.24	147.227
3311.35	154.463
3315.46	145.434
3319.57	157.37
3323.68	134.37
3327.78	155.803
3331.88	146.884
3335.98	173.356
3340.07	143.133
3344.16	160.043
3348.25	160.319
3352.34	174.893
3356.42	175.243
3360.5	144.569
3364.58	164.053
3368.66	142.798
3372.73	133.468
3376.8	148.135
3380.87	138.695
3384.93	136.46
3388.99	141.459
3393.05	141.606
3397.11	136.957
3401.16	132.295
3405.21	139.706
3409.26	144.707
3413.31	139.946
3417.35	135.188
3421.39	147.475
3425.43	135.381
3429.46	137.965
3433.5	135.7
3437.53	133.468
3441.55	131.255
3445.58	141.372
3449.6	141.732
3453.62	134.694
3457.64	137.607
3461.65	143.063
3465.66	136.079
3469.67	119.01
3473.68	136.921
3477.68	119.702
3481.68	107.424
3485.68	115.338
3489.67	130.908
3493.67	121.062
3497.66	139.221
3501.64	129.264
3505.63	137.172
3509.61	119.353
3513.59	134.843
3517.57	132.353
3521.54	129.857
3525.52	142.811
3529.49	132.596
3533.45	127.625
3537.42	125.308
3541.38	123.005
3545.34	131.006
3549.29	120.809
3553.25	120.869
3557.2	131.383
3561.15	126.336
3565.09	108.271
3569.04	111.125
3572.98	127.067
3576.92	127.368
3580.85	127.722
3584.79	133.387
3588.72	120.535
3592.64	126.199
3596.57	110.579
3600.49	118.885
3604.41	119.185
3608.33	116.767
3612.25	106.243
3616.16	106.458
3620.07	117.45
3623.98	114.855
3627.88	123.042
3631.79	112.269
3635.69	115.038
3639.58	112.459
3643.48	123.528
3647.37	110.2
3651.26	118.437
3655.15	102.206
3659.03	110.481
3662.92	121.483
3666.8	118.867
3670.67	102.575
3674.55	121.871
3678.42	124.827
3682.29	114.102
3686.16	111.651
3690.02	103.67
3693.89	98.41
3697.75	118.119
3701.61	110.079
3705.46	127.127
3709.31	99.4651
3713.16	119.402
3717.01	105.599
3720.86	111.461
3724.7	120.15
3728.54	126.021
3732.38	112.07
3736.21	115.127
3740.04	109.636
3743.87	112.666
3747.7	107.118
3751.53	107.244
3755.35	104.476
3759.17	98.8121
3762.99	116.052
3766.81	104.636
3770.62	110.452
3774.43	107.678
3778.24	113.529
3782.04	119.434
3785.85	102.328
3789.65	111.13
3793.45	105.515
3797.24	108.615
3801.04	94.3262
3804.83	94.5328
3808.62	109.33
3812.4	115.406
3816.19	98.0714
3819.97	107.063
3823.75	121.943
3827.52	92.7028
3831.3	107.614
3835.07	98.9532
3838.84	87.2816
3842.61	96.3501
3846.37	111.305
3850.13	102.466
3853.89	114.405
3857.65	96.608
3861.41	108.51
3865.16	99.6921
3868.91	90.9868
3872.66	94.0724
3876.4	94.131
3880.14	100.17
3883.89	91.2676
3887.62	94.3484
3891.36	109.445
3895.09	97.6244
3898.82	103.792
3902.55	103.955
3906.28	85.9995
3910	110.291
3913.73	101.4
3917.45	77.3354
3921.16	95.7572
3924.88	86.8438
3928.59	90.0841
3932.3	105.553
3936.01	87.3242
3939.71	105.871
3943.42	99.9374
3947.12	90.8854
3950.81	100.294
3954.51	88.0703
3958.2	97.4565
3961.9	88.2445
3965.58	103.796
3969.27	85.2289
3972.96	103.857
3976.64	85.2848
3980.32	82.1913
3984	94.5868
3987.67	88.3784
3991.34	94.5957
3995.01	88.4406
3998.68	91.6286