File: Data/3-Raman/raw/bu04w-a-ff3-fi08-v_150 (500nm)_633nm_edge_100%_x100_vis_lwd_h50um_45sx2_01.txt
#Acq. time (s)=	45
#Accumulations=	2
#Range (cm-¹)=	100...4000
#Windows=	1
#Auto scanning=	Off
#Autofocus=	Off
#Macrospot=	Off
#AutoExposure=	Off
#Spike filter=	Multiple accum.
#Delay time (s)=	2
#Binning=	1
#Readout mode=	Signal
#DeNoise=	Off
#ICS correction=	On
#Dark correction=	Off
#Inst. Process=	Off
#Detector Gain=	Best Dynamic
#Detector ADC=	50 kHz HS
#Detector temperature (°C)=	-60.09
#Instrument=	LabRAM HR Evol
#Detector=	SIN-EM FIVIS
#Objective=	x100_VIS_LWD
#Grating=	150 (500nm)
#ND Filter=	100%
#Laser=	633nm_Edge
#Hole=	49.98
#Temperature=	0
#Range=	Visible
#StageXY=	75x50mm Scan+
#StageZ=	Z motor
#X (µm)=	0
#Y (µm)=	0
#Z (µm)=	-40.5
#Full time(mm:ss)=	1:35
#Project=	21_11_22
#Sample=	BU04w
#Site=
#Title=	BU04w-A-FF3-FI08-V_150 (500nm)_633nm_Edge_100%_x100_VIS_LWD_H50um_45sX2
#Remark=
#Date=	22.11.2021 12:48
#Acquired=	22.11.2021 12:48:27
100.177	584.751
106.695	563.28
113.209	480.779
119.717	484.975
126.219	492
132.716	514.265
139.208	480.834
145.694	439.764
152.175	451.364
158.651	504.291
165.121	497.892
171.586	412.718
178.045	391.532
184.5	390.237
190.947	381.05
197.39	375.71
203.829	377.467
210.262	367.787
216.688	386.723
223.11	413.217
229.527	505.982
235.939	554.868
242.344	454.599
248.745	416.492
255.141	424.752
261.53	421.713
267.916	399.769
274.294	432.929
280.669	418.664
287.038	436.495
293.402	396.37
299.76	414.968
306.114	420.239
312.461	455.755
318.805	599.785
325.142	727.91
331.475	625.879
337.802	519.17
344.123	464.356
350.441	440.574
356.752	450.58
363.058	451.08
369.36	458.133
375.656	433.236
381.947	413.103
388.232	444.982
394.512	448.289
400.789	435.14
407.059	444.535
413.324	466.145
419.584	489.49
425.839	550.135
432.089	594.248
438.333	562.693
444.573	523.703
450.807	532.465
457.037	530.129
463.261	495.629
469.48	463.5
475.695	476.451
481.904	506.372
488.108	471.945
494.307	488.839
500.502	491.744
506.691	505.988
512.874	514.736
519.053	507.807
525.227	508.695
531.396	500.5
537.559	474.611
543.718	465.223
549.873	478.882
556.022	484.941
562.165	459.053
568.304	459.148
574.437	467.246
580.567	449.794
586.691	445.832
592.81	465.626
598.924	437.393
605.033	458.46
611.138	453.673
617.236	469.851
623.332	427.126
629.42	417.978
635.506	443.817
641.585	423.687
647.659	434.234
653.73	423.943
659.794	420
665.854	422.644
671.91	429.327
677.96	388.41
684.005	412.815
690.045	401.288
696.082	409.691
702.113	413.386
708.139	398.125
714.16	422.527
720.176	383.747
726.187	408.783
732.194	396.817
738.196	391.422
744.193	411.311
750.185	401.471
756.173	402.186
762.155	423.218
768.133	396.279
774.107	404.936
780.075	405.886
786.039	401.777
791.998	421.977
797.952	425.855
803.902	420.853
809.845	418.487
815.786	391.39
821.721	391.424
827.652	411.953
833.576	402.174
839.498	426.746
845.415	397.572
851.327	435.958
857.233	423.876
863.135	403.341
869.032	406.343
874.925	433.622
880.813	420.74
886.697	410.428
892.576	413.115
898.45	432.546
904.318	420.188
910.184	429.472
916.044	413.329
921.9	442.886
927.75	484.252
933.596	506.52
939.439	517.493
945.275	547.804
951.107	575.694
956.936	577.76
962.759	531.539
968.577	522.081
974.391	515.011
980.201	561.816
986.006	623.316
991.806	618.422
997.602	586.768
1003.39	570.742
1009.18	564.743
1014.96	597.735
1020.74	646.089
1026.51	635.028
1032.28	549.335
1038.04	497.105
1043.8	465.81
1049.56	443.909
1055.31	446.757
1061.05	461.87
1066.8	458.934
1072.53	425.79
1078.26	455.572
1083.99	487.127
1089.72	532.317
1095.44	623.003
1101.15	574.207
1106.86	510.546
1112.56	478.03
1118.27	445.64
1123.96	452.584
1129.65	461.48
1135.34	492.997
1141.03	495.214
1146.7	544.213
1152.38	656.177
1158.05	558.69
1163.71	478.24
1169.37	443.999
1175.03	417.662
1180.68	425.662
1186.33	434.085
1191.98	413.637
1197.61	394.617
1203.25	422.18
1208.88	425.668
1214.51	426.365
1220.13	409.471
1225.74	410.46
1231.36	410.316
1236.97	404.816
1242.57	409.918
1248.17	400.412
1253.77	417.808
1259.36	426.637
1264.94	394.774
1270.53	382.106
1276.11	558.14
1281.68	507.768
1287.25	395.808
1292.81	384.36
1298.38	396.237
1303.93	397.4
1309.48	403.092
1315.03	380.223
1320.58	378.482
1326.12	385.005
1331.65	391.647
1337.18	388.946
1342.71	370.614
1348.23	376.496
1353.75	395.624
1359.26	384.765
1364.77	390.052
1370.28	377.618
1375.78	404.184
1381.28	837.289
1386.77	442.817
1392.26	393.477
1397.74	379.533
1403.23	427.36
1408.7	371.405
1414.17	380.399
1419.64	363.673
1425.11	385.328
1430.56	385.288
1436.02	381.051
1441.47	380.915
1446.92	388.158
1452.36	367.742
1457.8	354.362
1463.23	356.501
1468.66	352.205
1474.09	374.173
1479.51	348.034
1484.93	369.231
1490.34	358.05
1495.75	345.991
1501.16	355.11
1506.56	385.538
1511.96	369.622
1517.35	384.611
1522.74	367.754
1528.13	382.964
1533.51	391.948
1538.88	358.643
1544.25	372.45
1549.62	368.347
1554.99	391.837
1560.35	355.73
1565.71	364.011
1571.06	370.086
1576.41	389.137
1581.75	382.68
1587.09	372.021
1592.43	367.955
1597.76	342.505
1603.09	367.905
1608.41	379.567
1613.73	388.359
1619.05	357.113
1624.36	372.712
1629.67	373.015
1634.97	364.327
1640.27	355.017
1645.57	357.794
1650.86	371.536
1656.15	356.348
1661.43	358.7
1666.71	354.329
1671.99	348.798
1677.26	350.962
1682.53	359.71
1687.79	351.627
1693.05	356.972
1698.31	339.418
1703.56	352.986
1708.81	340.032
1714.06	357.339
1719.3	335.988
1724.53	329.779
1729.77	342.814
1735	339.018
1740.22	330.656
1745.44	352.734
1750.66	348.724
1755.87	344.583
1761.08	335.677
1766.29	338.074
1771.49	345.072
1776.69	337.413
1781.88	341.294
1787.07	354.397
1792.26	340.365
1797.44	332.021
1802.62	350.126
1807.79	349.913
1812.96	337.997
1818.13	338.741
1823.29	352.197
1828.45	336.773
1833.61	341.07
1838.76	331.395
1843.91	339.006
1849.05	340.732
1854.19	316.596
1859.33	324.151
1864.46	335.355
1869.59	331.346
1874.71	335.356
1879.83	329.873
1884.95	338.498
1890.06	329.248
1895.17	338.721
1900.28	322.334
1905.38	332.388
1910.48	335.535
1915.57	311.625
1920.66	343.168
1925.75	317.5
1930.83	336.091
1935.91	321.088
1940.99	322.762
1946.06	314.705
1951.13	337.843
1956.19	333.167
1961.26	335.659
1966.31	326.034
1971.36	322.274
1976.41	326.908
1981.46	315.891
1986.5	316.933
1991.54	322.828
1996.58	302.326
2001.61	316.774
2006.63	327.738
2011.66	313.54
2016.68	340.295
2021.69	332.051
2026.71	327.611
2031.72	322.088
2036.72	310.598
2041.72	314.854
2046.72	326.47
2051.71	300.38
2056.71	300.872
2061.69	311.33
2066.68	305.911
2071.66	304.098
2076.63	308.423
2081.6	321.34
2086.57	326.769
2091.54	326.01
2096.5	322.989
2101.46	310.077
2106.41	307.144
2111.36	333.009
2116.31	321.51
2121.25	326.276
2126.19	341.11
2131.13	328.135
2136.06	320.066
2140.99	338.565
2145.92	315.073
2150.84	330.868
2155.76	346.589
2160.67	330.288
2165.58	331.727
2170.49	326.719
2175.39	330.812
2180.29	332.212
2185.19	334.732
2190.08	336.065
2194.98	332.403
2199.86	339.176
2204.74	353.824
2209.62	335.2
2214.5	338.514
2219.37	353.581
2224.24	319.489
2229.11	335.896
2233.97	361.501
2238.83	361.109
2243.68	363.33
2248.53	356.389
2253.38	349.376
2258.22	360.825
2263.06	348.486
2267.9	347.851
2272.73	357.685
2277.56	363.435
2282.39	354.413
2287.21	355.845
2292.03	354.612
2296.85	360.048
2301.66	352.349
2306.47	343.497
2311.28	353.514
2316.08	365.036
2320.88	357.912
2325.68	352.108
2330.47	322.022
2335.26	370.408
2340.04	349.838
2344.82	351.037
2349.6	322.219
2354.38	338.396
2359.15	337.94
2363.92	327.557
2368.68	325.509
2373.44	330.33
2378.2	322.663
2382.95	314.78
2387.71	305.328
2392.45	302.694
2397.2	291.599
2401.94	315.266
2406.68	320.76
2411.41	307.155
2416.14	288.574
2420.87	308.254
2425.59	298.849
2430.31	299.592
2435.03	301.851
2439.75	294.265
2444.46	290.872
2449.16	290.322
2453.87	298.333
2458.57	274.81
2463.27	262.655
2467.96	305.232
2472.65	294.435
2477.34	277.802
2482.02	288.689
2486.7	276.205
2491.38	294.299
2496.05	293.456
2500.72	289.628
2505.39	273.985
2510.06	275.882
2514.72	276.241
2519.37	275.145
2524.03	274.116
2528.68	277.487
2533.33	288.321
2537.97	266.598
2542.61	265.654
2547.25	273.697
2551.88	265.329
2556.51	264.362
2561.14	254.379
2565.77	280.551
2570.39	260.159
2575.01	263.856
2579.62	261.419
2584.23	266.4
2588.84	266.716
2593.45	265.403
2598.05	262.772
2602.65	270.757
2607.24	257.33
2611.84	265.203
2616.42	265.412
2621.01	276.369
2625.59	258.261
2630.17	264.774
2634.75	265.369
2639.32	264.641
2643.89	251.54
2648.46	257.009
2653.02	274.948
2657.58	242.701
2662.14	258.724
2666.69	246.516
2671.24	223.435
2675.79	253.949
2680.33	240.98
2684.88	261.123
2689.41	271.865
2693.95	248.882
2698.48	238.054
2703.01	240.173
2707.53	245.458
2712.06	255.553
2716.57	249.658
2721.09	248.512
2725.6	227.817
2730.11	231.336
2734.62	234.774
2739.12	239.798
2743.62	238.456
2748.12	251.861
2752.61	244.387
2757.1	248.214
2761.59	246.937
2766.08	230.965
2770.56	209.986
2775.04	228.612
2779.51	234.202
2783.98	246.626
2788.45	237.461
2792.92	248.247
2797.38	238.889
2801.84	224.364
2806.3	241.684
2810.75	238.769
2815.2	242.531
2819.65	217.508
2824.09	228.04
2828.53	231.814
2832.97	233.862
2837.41	220.561
2841.84	249.876
2846.27	231.503
2850.69	214.824
2855.12	229.068
2859.54	217.597
2863.95	237.192
2868.37	218.907
2872.78	243.881
2877.18	242.908
2881.59	250.718
2885.99	228.831
2890.39	231.377
2894.78	219.786
2899.18	234.794
2903.57	233.808
2907.95	205.98
2912.34	208.298
2916.72	232.049
2921.09	221.845
2925.47	233.237
2929.84	219.469
2934.21	229.137
2938.57	213.293
2942.94	211.873
2947.29	214.011
2951.65	245.332
2956	207.322
2960.36	225.906
2964.7	224.424
2969.05	228.494
2973.39	219.727
2977.73	220.14
2982.06	222.425
2986.4	210.014
2990.73	216.145
2995.05	224.197
2999.38	223.02
3003.7	223.756
3008.01	228.274
3012.33	210.131
3016.64	227.88
3020.95	228.714
3025.26	218.025
3029.56	214.783
3033.86	215.275
3038.16	229.068
3042.45	214.206
3046.74	212.664
3051.03	226.521
3055.32	223.059
3059.6	215.724
3063.88	212.226
3068.16	208.716
3072.43	228.53
3076.7	223.108
3080.97	207.906
3085.24	222.029
3089.5	218.663
3093.76	242.917
3098.02	204.248
3102.27	230.666
3106.52	237.476
3110.77	226.425
3115.01	231.319
3119.26	212.127
3123.5	223.126
3127.73	230.214
3131.97	233.373
3136.2	234.507
3140.43	239.7
3144.65	238.645
3148.87	235.437
3153.09	232.047
3157.31	264.049
3161.52	256.458
3165.73	259.292
3169.94	234.691
3174.15	248.015
3178.35	271.743
3182.55	253.086
3186.75	257.648
3190.94	243.072
3195.13	232.857
3199.32	233.463
3203.51	245.008
3207.69	267.441
3211.87	246.952
3216.05	265.352
3220.22	262.085
3224.39	250.031
3228.56	253.231
3232.73	232.208
3236.89	241.848
3241.05	251.67
3245.21	243.866
3249.36	204.543
3253.52	216.331
3257.66	210.079
3261.81	199.506
3265.95	207.073
3270.1	214.831
3274.23	208.874
3278.37	200.134
3282.5	211.998
3286.63	226.206
3290.76	222.04
3294.88	208.603
3299	206.665
3303.12	197.841
3307.24	184.323
3311.35	186.982
3315.46	198.953
3319.57	185.347
3323.68	209.149
3327.78	195.633
3331.88	189.187
3335.98	206.377
3340.07	190.45
3344.16	202.721
3348.25	184.07
3352.34	203.447
3356.42	191.932
3360.5	192.361
3364.58	207.161
3368.66	185.997
3372.73	174.35
3376.8	193.9
3380.87	194.173
3384.93	199.256
3388.99	177.73
3393.05	187.598
3397.11	175.742
3401.16	185.698
3405.21	183.44
3409.26	193.348
3413.31	149.682
3417.35	186.34
3421.39	166.976
3425.43	198.802
3429.46	181.919
3433.5	174.821
3437.53	167.753
3441.55	160.695
3445.58	185.628
3449.6	173.776
3453.62	186.595
3457.64	184.715
3461.65	165.456
3465.66	176.029
3469.67	181.647
3473.68	167.069
3477.68	177.662
3481.68	195.89
3485.68	163.501
3489.67	153.785
3493.67	164.389
3497.66	187.757
3501.64	177.898
3505.63	170.503
3509.61	170.688
3513.59	173.369
3517.57	140.063
3521.54	173.571
3525.52	150.531
3529.49	171.216
3533.45	171.455
3537.42	166.647
3541.38	154.08
3545.34	154.354
3549.29	180.564
3553.25	152.061
3557.2	160.001
3561.15	144.57
3565.09	170.886
3569.04	158.19
3572.98	171.606
3576.92	156.256
3580.85	156.69
3584.79	149.235
3588.72	162.921
3592.64	155.424
3596.57	137.225
3600.49	166.973
3604.41	154.003
3608.33	143.61
3612.25	157.347
3616.16	154.97
3620.07	147.15
3623.98	155.393
3627.88	147.38
3631.79	155.554
3635.69	158.346
3639.58	147.687
3643.48	142.532
3647.37	159.178
3651.26	145.664
3655.15	151.264
3659.03	156.856
3662.92	137.863
3666.8	143.46
3670.67	135.399
3674.55	146.519
3678.42	144.031
3682.29	144.346
3686.16	139.219
3690.02	147.903
3693.89	128.903
3697.75	137.573
3701.61	124.013
3705.46	155.067
3709.31	147.096
3713.16	150.306
3717.01	136.575
3720.86	128.392
3724.7	156.902
3728.54	128.853
3732.38	126.256
3736.21	129.34
3740.04	143.809
3743.87	144.041
3747.7	144.252
3751.53	150.142
3755.35	118.788
3759.17	138.91
3762.99	147.572
3766.81	136.17
3770.62	116.19
3774.43	127.778
3778.24	116.403
3782.04	133.824
3785.85	131.153
3789.65	125.562
3793.45	137.314
3797.24	143.372
3801.04	140.764
3804.83	132.346
3808.62	126.823
3812.4	141.701
3816.19	136.129
3819.97	136.395
3823.75	133.697
3827.52	133.904
3831.3	140.045
3835.07	131.445
3838.84	137.58
3842.61	123.032
3846.37	120.21
3850.13	111.376
3853.89	123.32
3857.65	132.279
3861.41	135.266
3865.16	117.547
3868.91	135.734
3872.66	132.896
3876.4	129.99
3880.14	118.111
3883.89	124.184
3887.62	121.305
3891.36	121.439
3895.09	118.651
3898.82	127.86
3902.55	109.982
3906.28	125.227
3910	107.27
3913.73	119.561
3917.45	131.925
3921.16	123.116
3924.88	138.645
3928.59	141.997
3932.3	133.089
3936.01	124.092
3939.71	133.49
3943.42	124.537
3947.12	109.371
3950.81	121.895
3954.51	122.062
3958.2	134.583
3961.9	125.4
3965.58	119.287
3969.27	134.817
3972.96	113.158
3976.64	119.399
3980.32	110.105
3984	122.498
3987.67	110.085
3991.34	125.611
3995.01	122.576
3998.68	100.947