File: Data/3-Raman/raw/bu04w-a-ff3-fi05-v_150 (500nm)_633nm_edge_100%_x100_vis_lwd_h50um_45sx2_02.txt
#Acq. time (s)=	45
#Accumulations=	2
#Range (cm-¹)=	100...4000
#Windows=	1
#Auto scanning=	Off
#Autofocus=	Off
#Macrospot=	Off
#AutoExposure=	Off
#Spike filter=	Multiple accum.
#Delay time (s)=	2
#Binning=	1
#Readout mode=	Signal
#DeNoise=	Off
#ICS correction=	On
#Dark correction=	Off
#Inst. Process=	Off
#Detector Gain=	Best Dynamic
#Detector ADC=	50 kHz EM
#Detector EM gain=	100
#Detector temperature (°C)=	-60.09
#Instrument=	LabRAM HR Evol
#Detector=	SIN-EM FIVIS
#Objective=	x100_VIS_LWD
#Grating=	150 (500nm)
#ND Filter=	100%
#Laser=	633nm_Edge
#Hole=	49.98
#Temperature=	0
#Range=	Visible
#StageXY=	75x50mm Scan+
#StageZ=	Z motor
#X (µm)=	0
#Y (µm)=	0
#Z (µm)=	16.6
#Full time(mm:ss)=	1:36
#Project=	21_11_22
#Sample=	BU04w
#Site=
#Title=	BU04w-A-FF3-FI05-V_150 (500nm)_633nm_Edge_100%_x100_VIS_LWD_H50um_45sX2
#Remark=
#Date=	22.11.2021 11:43
#Acquired=	22.11.2021 11:43:04
100.177	1339.16
106.695	1172.35
113.209	1100.97
119.717	1029.2
126.219	1017.47
132.716	991.215
139.208	1022.91
145.694	977.148
152.175	904.643
158.651	1009.54
165.121	1133.79
171.586	959.653
178.045	788.816
184.5	735.465
190.947	747.756
197.39	682.674
203.829	689.08
210.262	650.664
216.688	648.512
223.11	680.592
229.527	822.518
235.939	1007.99
242.344	871.197
248.745	736.103
255.141	725.163
261.53	714.399
267.916	667.704
274.294	653.423
280.669	721.639
287.038	721.33
293.402	659.195
299.76	623.635
306.114	627.759
312.461	693.314
318.805	867.352
325.142	1257.69
331.475	1308.36
337.802	980.811
344.123	735.427
350.441	665.338
356.752	708.122
363.058	722.48
369.36	738.652
375.656	650.558
381.947	630.205
388.232	601.124
394.512	583.01
400.789	623.779
407.059	641.111
413.324	620.582
419.584	685.758
425.839	771.987
432.089	843.936
438.333	847.571
444.573	776.865
450.807	715.573
457.037	757.594
463.261	732.952
469.48	611.168
475.695	580.311
481.904	600.007
488.108	628.017
494.307	600.214
500.502	628.313
506.691	694.859
512.874	740.138
519.053	725.038
525.227	657.045
531.396	667.959
537.559	695.218
543.718	661.777
549.873	591.643
556.022	598.739
562.165	577.473
568.304	551.919
574.437	564.452
580.567	536.383
586.691	532.198
592.81	563.039
598.924	577.601
605.033	616.566
611.138	587.765
617.236	567.756
623.332	572.321
629.42	573.955
635.506	557.483
641.585	551.405
647.659	540.088
653.73	553.051
659.794	589.966
665.854	537.061
671.91	522.091
677.96	507.312
684.005	492.579
690.045	487.712
696.082	489.756
702.113	477.669
708.139	470.041
714.16	485.037
720.176	451.853
726.187	459.94
732.194	479.741
738.196	463.907
744.193	459.398
750.185	444.836
756.173	461.372
762.155	475.945
768.133	451.954
774.107	453.266
780.075	447.745
786.039	460.654
791.998	443.194
797.952	456.509
803.902	469.395
809.845	457.558
815.786	461.398
821.721	441.583
827.652	448.893
833.576	468.97
839.498	459.933
845.415	459.854
851.327	479.601
857.233	479.86
863.135	492.5
869.032	486.287
874.925	474.851
880.813	493.314
886.697	475.433
892.576	507.5
898.45	475.658
904.318	493.449
910.184	471.429
916.044	504.083
921.9	517.561
927.75	526.994
933.596	553.08
939.439	588.725
945.275	680.849
951.107	774.882
956.936	786.25
962.759	721.477
968.577	660.631
974.391	697.88
980.201	754.205
986.006	937.13
991.806	952.743
997.602	879.436
1003.39	779.109
1009.18	794.93
1014.96	786.167
1020.74	931.17
1026.51	949.431
1032.28	857.825
1038.04	649.653
1043.8	632.343
1049.56	565.416
1055.31	552.019
1061.05	547.834
1066.8	526.439
1072.53	524.348
1078.26	543.387
1083.99	573.889
1089.72	629.674
1095.44	734.824
1101.15	877.517
1106.86	694.924
1112.56	583.129
1118.27	519.022
1123.96	526.147
1129.65	525.452
1135.34	565.943
1141.03	592.883
1146.7	653.842
1152.38	907.72
1158.05	905.717
1163.71	659.608
1169.37	517.099
1175.03	506.287
1180.68	488.705
1186.33	464.847
1191.98	460.031
1197.61	445.961
1203.25	448.168
1208.88	422.223
1214.51	462.431
1220.13	449.674
1225.74	429.91
1231.36	448.892
1236.97	441.527
1242.57	452.775
1248.17	440.302
1253.77	449.636
1259.36	459.456
1264.94	450.738
1270.53	449.062
1276.11	457.163
1281.68	755.887
1287.25	446.348
1292.81	456.833
1298.38	460.695
1303.93	442.889
1309.48	447.657
1315.03	449.035
1320.58	444.502
1326.12	458.363
1331.65	458.192
1337.18	426.159
1342.71	438.603
1348.23	430.281
1353.75	434.109
1359.26	438.704
1364.77	465.595
1370.28	471.637
1375.78	504.331
1381.28	568.802
1386.77	671.152
1392.26	435.03
1397.74	457.083
1403.23	461.817
1408.7	460.521
1414.17	425.304
1419.64	434.546
1425.11	423.187
1430.56	449.243
1436.02	432.658
1441.47	439.96
1446.92	436.874
1452.36	441.711
1457.8	435.734
1463.23	444.182
1468.66	453.51
1474.09	426.127
1479.51	426.249
1484.93	445.389
1490.34	432.184
1495.75	442.364
1501.16	468.555
1506.56	427.318
1511.96	438.032
1517.35	454.298
1522.74	428.068
1528.13	429.562
1533.51	434.423
1538.88	428.215
1544.25	442.183
1549.62	452.185
1554.99	441.019
1560.35	434.001
1565.71	444.363
1571.06	446.042
1576.41	444.574
1581.75	433.812
1587.09	453.317
1592.43	448.226
1597.76	455.235
1603.09	440.838
1608.41	432.089
1613.73	455.168
1619.05	447.073
1624.36	444.409
1629.67	448.277
1634.97	459.68
1640.27	462.682
1645.57	451.252
1650.86	455.145
1656.15	453.333
1661.43	451.285
1666.71	432.514
1671.99	449.167
1677.26	430.247
1682.53	430.1
1687.79	449.64
1693.05	443.863
1698.31	429.67
1703.56	439.149
1708.81	451.143
1714.06	447.091
1719.3	439.411
1724.53	459.115
1729.77	443.245
1735	437.406
1740.22	440.499
1745.44	448.113
1750.66	441.981
1755.87	453.786
1761.08	439.268
1766.29	436.042
1771.49	440.831
1776.69	444.591
1781.88	438.401
1787.07	447.12
1792.26	444.698
1797.44	440.028
1802.62	448.115
1807.79	469.998
1812.96	441.066
1818.13	466.274
1823.29	452.246
1828.45	448.644
1833.61	448.562
1838.76	426.329
1843.91	458.621
1849.05	444.178
1854.19	454.119
1859.33	437.281
1864.46	439.31
1869.59	448.464
1874.71	464.429
1879.83	429.602
1884.95	454.875
1890.06	425.599
1895.17	455.175
1900.28	451.858
1905.38	443.184
1910.48	443.025
1915.57	457.606
1920.66	448.804
1925.75	461.6
1930.83	444.526
1935.91	454.925
1940.99	455.594
1946.06	458.518
1951.13	457.684
1956.19	453.059
1961.26	473.659
1966.31	455.604
1971.36	466.243
1976.41	457.55
1981.46	451.272
1986.5	458.26
1991.54	450.877
1996.58	438.763
2001.61	450.818
2006.63	451.015
2011.66	442.928
2016.68	449.31
2021.69	444.744
2026.71	447.675
2031.72	448.385
2036.72	460.146
2041.72	451.351
2046.72	451.1
2051.71	461.841
2056.71	457.717
2061.69	455.069
2066.68	469.594
2071.66	477.957
2076.63	461.711
2081.6	467.515
2086.57	462.048
2091.54	468.91
2096.5	455.037
2101.46	454.863
2106.41	453.551
2111.36	471.085
2116.31	485.085
2121.25	472.754
2126.19	453.973
2131.13	456.481
2136.06	463.937
2140.99	473.864
2145.92	471.018
2150.84	467.932
2155.76	460.843
2160.67	461.253
2165.58	478.096
2170.49	471.856
2175.39	485.02
2180.29	477.515
2185.19	471.056
2190.08	480.093
2194.98	473.947
2199.86	460.357
2204.74	480.328
2209.62	465.806
2214.5	468.116
2219.37	471.872
2224.24	480.854
2229.11	463.887
2233.97	471.58
2238.83	477.996
2243.68	467.419
2248.53	479.124
2253.38	469.782
2258.22	481.54
2263.06	488.013
2267.9	491.63
2272.73	491.07
2277.56	478.379
2282.39	492.055
2287.21	474.903
2292.03	489.671
2296.85	473.852
2301.66	462.249
2306.47	469.557
2311.28	465.114
2316.08	483.589
2320.88	476.768
2325.68	479.352
2330.47	472.57
2335.26	474.014
2340.04	490.452
2344.82	486.68
2349.6	478.882
2354.38	474.989
2359.15	490.047
2363.92	471.683
2368.68	489.3
2373.44	493.071
2378.2	474.628
2382.95	482.245
2387.71	493.81
2392.45	475.96
2397.2	489.943
2401.94	481.598
2406.68	503.753
2411.41	494.513
2416.14	489.109
2420.87	488.713
2425.59	493.629
2430.31	487.807
2435.03	483.527
2439.75	482.169
2444.46	509.203
2449.16	503.605
2453.87	486.491
2458.57	508.003
2463.27	499.404
2467.96	509.441
2472.65	499.166
2477.34	514.985
2482.02	506.114
2486.7	510.142
2491.38	521.412
2496.05	523.976
2500.72	514.731
2505.39	517.119
2510.06	513.509
2514.72	512.704
2519.37	497.178
2524.03	523.11
2528.68	501.697
2533.33	520.313
2537.97	519.828
2542.61	517.914
2547.25	508.613
2551.88	541.122
2556.51	515.244
2561.14	514.76
2565.77	512.964
2570.39	515.794
2575.01	527.712
2579.62	506.167
2584.23	520.656
2588.84	521.273
2593.45	552.099
2598.05	536.206
2602.65	524.735
2607.24	532.987
2611.84	525.82
2616.42	509.408
2621.01	517.521
2625.59	521.121
2630.17	529.548
2634.75	530.739
2639.32	526.195
2643.89	518.56
2648.46	527.995
2653.02	543.666
2657.58	549.395
2662.14	529.954
2666.69	552.508
2671.24	508.02
2675.79	537.773
2680.33	519.885
2684.88	538.12
2689.41	546.919
2693.95	548.981
2698.48	561.069
2703.01	552.64
2707.53	547.251
2712.06	551.415
2716.57	549.409
2721.09	535.879
2725.6	552.922
2730.11	537.348
2734.62	567.033
2739.12	549.502
2743.62	555.04
2748.12	552.626
2752.61	547.622
2757.1	542.302
2761.59	552.942
2766.08	545.768
2770.56	548.434
2775.04	559.562
2779.51	564.403
2783.98	563.004
2788.45	574.906
2792.92	565.033
2797.38	571.657
2801.84	583.178
2806.3	569.262
2810.75	563.596
2815.2	564.498
2819.65	575.507
2824.09	583.24
2828.53	563.826
2832.97	569.772
2837.41	562.048
2841.84	571.39
2846.27	584.31
2850.69	576.859
2855.12	571.383
2859.54	583.125
2863.95	596.861
2868.37	597.019
2872.78	581.496
2877.18	569.398
2881.59	581.805
2885.99	594.434
2890.39	577.123
2894.78	584.331
2899.18	593.63
2903.57	624.08
2907.95	606.349
2912.34	598.969
2916.72	602.074
2921.09	598.172
2925.47	614.162
2929.84	608.732
2934.21	614.051
2938.57	611.743
2942.94	589.242
2947.29	606.516
2951.65	607.402
2956	621.054
2960.36	614.61
2964.7	604.572
2969.05	633.177
2973.39	606.777
2977.73	618.972
2982.06	636.818
2986.4	614.315
2990.73	614.111
2995.05	634.449
2999.38	638.266
3003.7	629.139
3008.01	665.094
3012.33	627.567
3016.64	641.091
3020.95	643.437
3025.26	645.506
3029.56	656.758
3033.86	644.869
3038.16	657.492
3042.45	662.791
3046.74	675.521
3051.03	667.032
3055.32	683.662
3059.6	679.094
3063.88	691.913
3068.16	685.364
3072.43	671.004
3076.7	676.143
3080.97	691.069
3085.24	698.364
3089.5	692.269
3093.76	700.229
3098.02	722.269
3102.27	734.568
3106.52	735.28
3110.77	736.131
3115.01	731.008
3119.26	745.962
3123.5	735.004
3127.73	740.335
3131.97	741.901
3136.2	751.651
3140.43	790.083
3144.65	758.291
3148.87	765.431
3153.09	824.13
3157.31	805.716
3161.52	820.664
3165.73	825.117
3169.94	833.522
3174.15	848.526
3178.35	824.744
3182.55	832.324
3186.75	863.069
3190.94	830.054
3195.13	886.77
3199.32	863.495
3203.51	883.741
3207.69	844.211
3211.87	882.125
3216.05	823.134
3220.22	872.165
3224.39	842.898
3228.56	863.836
3232.73	891.415
3236.89	852.541
3241.05	915.767
3245.21	828.476
3249.36	851.706
3253.52	856.357
3257.66	876.265
3261.81	870.162
3265.95	846.398
3270.1	861.597
3274.23	892.563
3278.37	885.162
3282.5	886.953
3286.63	838.226
3290.76	862.851
3294.88	832.108
3299	872.844
3303.12	865.409
3307.24	876.404
3311.35	891.938
3315.46	865.621
3319.57	843.97
3323.68	869.314
3327.78	899.677
3331.88	900.106
3335.98	896.264
3340.07	896.654
3344.16	898.612
3348.25	876.409
3352.34	913.727
3356.42	889.327
3360.5	874.584
3364.58	905.283
3368.66	892.785
3372.73	897.002
3376.8	934.576
3380.87	899.71
3384.93	946.767
3388.99	911.622
3393.05	910.153
3397.11	909.008
3401.16	905.43
3405.21	915.986
3409.26	926.612
3413.31	958.935
3417.35	935.352
3421.39	933.6
3425.43	929.37
3429.46	954.769
3433.5	938.899
3437.53	884.072
3441.55	934.731
3445.58	907.242
3449.6	904.622
3453.62	916.909
3457.64	932.255
3461.65	975.317
3465.66	928.832
3469.67	927.028
3473.68	894.382
3477.68	927.372
3481.68	980.714
3485.68	940.448
3489.67	902.373
3493.67	927.716
3497.66	919.627
3501.64	913.809
3505.63	907.64
3509.61	931.727
3513.59	929.771
3517.57	881.497
3521.54	897.424
3525.52	903.185
3529.49	895.986
3533.45	879.191
3537.42	927.539
3541.38	854.559
3545.34	900.182
3549.29	888.533
3553.25	881.172
3557.2	905.374
3561.15	890.865
3565.09	863.559
3569.04	875.929
3572.98	903.88
3576.92	890.263
3580.85	895.37
3584.79	911.26
3588.72	879.51
3592.64	911.292
3596.57	887.297
3600.49	905.661
3604.41	875.807
3608.33	899.237
3612.25	871.463
3616.16	881.308
3620.07	904.498
3623.98	862.091
3627.88	859.944
3631.79	873.805
3635.69	863.459
3639.58	896.963
3643.48	879.628
3647.37	857.111
3651.26	868.539
3655.15	883.056
3659.03	864.754
3662.92	851.749
3666.8	863.494
3670.67	869.838
3674.55	862.679
3678.42	866.931
3682.29	852.329
3686.16	873.908
3690.02	881.89
3693.89	873.215
3697.75	864.35
3701.61	866.696
3705.46	877.318
3709.31	871.37
3713.16	859.696
3717.01	875.768
3720.86	877.582
3724.7	893.354
3728.54	900.552
3732.38	871.022
3736.21	881.216
3740.04	899.873
3743.87	881.363
3747.7	885.507
3751.53	895.13
3755.35	878.746
3759.17	879.284
3762.99	891.164
3766.81	868.619
3770.62	883.615
3774.43	875.782
3778.24	890.989
3782.04	903.669
3785.85	902.218
3789.65	889.038
3793.45	904.828
3797.24	906.575
3801.04	899.727
3804.83	895.88
3808.62	897.967
3812.4	899.872
3816.19	907.527
3819.97	903.432
3823.75	902.087
3827.52	906.427
3831.3	902.187
3835.07	895.009
3838.84	899.445
3842.61	910.138
3846.37	914.188
3850.13	911.798
3853.89	906.326
3857.65	924.464
3861.41	936.459
3865.16	907.645
3868.91	915.834
3872.66	925.792
3876.4	908.438
3880.14	929.936
3883.89	927.638
3887.62	934.499
3891.36	929.533
3895.09	931.186
3898.82	941.649
3902.55	919.024
3906.28	929.398
3910	939.742
3913.73	938.325
3917.45	940.156
3921.16	933.253
3924.88	941.569
3928.59	958.862
3932.3	939.269
3936.01	940.65
3939.71	939.033
3943.42	937.874
3947.12	939.662
3950.81	947.388
3954.51	945.597
3958.2	949.814
3961.9	956.756
3965.58	966.693
3969.27	957.663
3972.96	942.467
3976.64	948.987
3980.32	955.279
3984	936.565
3987.67	958.208
3991.34	949.058
3995.01	961.985
3998.68	947.347