File: Data/3-Raman/raw/bu04w-a-ff3-fi05-v_1800 (450-850nm)_633nm_edge_100%_x100_vis_lwd_h50um_45sx2_01.txt
#Acq. time (s)=	45
#Accumulations=	2
#Range (cm-¹)=	1200...2380
#Windows=	6
#Auto scanning=	Off
#Autofocus=	Off
#Macrospot=	Off
#AutoExposure=	Off
#Spike filter=	Multiple accum.
#Delay time (s)=	2
#Binning=	1
#Readout mode=	Signal
#DeNoise=	Off
#ICS correction=	On
#Dark correction=	Off
#Inst. Process=	Off
#Detector Gain=	Best Dynamic
#Detector ADC=	50 kHz EM
#Detector EM gain=	100
#Detector temperature (°C)=	-60.09
#Instrument=	LabRAM HR Evol
#Detector=	SIN-EM FIVIS
#Objective=	x100_VIS_LWD
#Grating=	1800 (450-850nm)
#ND Filter=	100%
#Laser=	633nm_Edge
#Hole=	49.98
#Temperature=	0
#Range=	Visible
#StageXY=	75x50mm Scan+
#StageZ=	Z motor
#X (µm)=	0
#Y (µm)=	0
#Z (µm)=	16.9
#Full time(mm:ss)=	9:36
#Project=	21_11_22
#Sample=	BU04w
#Site=
#Title=	BU04w-A-FF3-FI05-V_1800 (450-850nm)_633nm_Edge_100%_x100_VIS_LWD_H50um_45sX2
#Remark=
#Date=	22.11.2021 11:27
#Acquired=	22.11.2021 11:27:50
1200.03	305.294
1201.07	299.42
1202.1	301.536
1203.13	296.575
1204.16	299.635
1205.2	299.55
1206.23	297.222
1207.26	304.667
1208.29	300.661
1209.32	298.675
1210.35	302.895
1211.38	297.571
1212.41	302.353
1213.44	298.786
1214.47	297.917
1215.5	302.143
1216.53	298.729
1217.56	296.246
1218.58	303.02
1219.61	298.914
1220.64	304.691
1221.67	302.308
1222.7	298.58
1223.72	303.336
1224.75	299.133
1225.78	298.68
1226.8	319.037
1227.83	306.974
1228.85	302.327
1229.88	306.98
1230.91	304.444
1231.93	305.526
1232.96	306.313
1233.98	301.932
1235	301.558
1236.03	304.563
1237.05	304.063
1238.07	307.656
1239.1	303.061
1240.12	301.818
1241.14	305.667
1242.17	305.594
1243.19	307.972
1244.21	308.484
1245.23	304.373
1246.25	305.426
1247.27	301.262
1248.3	307.804
1249.32	307.877
1250.34	307.338
1251.36	311.638
1252.38	312.256
1253.4	304.646
1254.42	311.343
1255.43	305.812
1256.45	312.946
1257.47	315.792
1258.49	308.168
1259.51	309.934
1260.53	310.161
1261.54	310.647
1262.56	310.79
1263.58	312.578
1264.59	315.253
1265.61	313.531
1266.63	315.108
1267.64	310.139
1268.66	317.076
1269.67	309.436
1270.69	315.933
1271.7	310.6
1272.72	306.591
1273.73	306.274
1274.75	313.813
1275.76	309.1
1276.77	310.586
1277.79	310.567
1278.8	310.091
1279.82	305.31
1280.83	307.212
1281.84	311.766
1282.85	308.844
1283.86	325.039
1284.88	318.639
1285.89	307.737
1286.9	306.247
1287.91	306.373
1288.92	305.086
1289.93	305.771
1290.94	306.633
1291.95	306.169
1292.96	307.951
1293.97	304.089
1294.98	305.693
1295.99	310.85
1296.99	306.143
1298	304.308
1299.01	306.303
1300.02	308.6
1301.03	304.336
1302.03	306.387
1303.04	309.19
1304.05	306.716
1305.05	299.781
1306.06	312.195
1307.07	305.922
1308.07	309.294
1309.08	303.996
1310.08	306.122
1311.09	301.003
1312.09	301.546
1313.1	309.547
1314.1	308.065
1315.1	310.312
1316.11	303.863
1317.11	307.184
1318.12	306.558
1319.12	303.524
1320.12	306.003
1321.12	308.756
1322.12	304.3
1323.13	302.757
1324.13	300.991
1325.13	309.893
1326.13	301.633
1327.13	306.103
1328.13	307.207
1329.13	305.683
1330.13	310.89
1331.13	306.044
1332.13	308.143
1333.13	307.491
1334.13	316.104
1335.13	311.208
1336.13	314.455
1337.13	314.754
1338.12	318.092
1339.12	311.095
1340.12	307.578
1341.12	310.108
1342.11	316.795
1343.11	306.556
1344.11	316.151
1345.1	310.24
1346.1	312.468
1347.09	309.032
1348.09	310.018
1349.08	314.091
1350.08	308.554
1351.07	311.798
1352.07	314.212
1353.06	310.237
1354.06	313.32
1355.05	316.869
1356.04	318.978
1357.04	313.539
1358.03	316.325
1359.02	316.63
1360.02	321.315
1361.01	313.48
1362	316.699
1362.99	313.718
1363.98	308.601
1364.97	319.2
1365.97	317.576
1366.95	315.063
1367.95	315.847
1368.94	316.792
1369.93	315.461
1370.91	312.529
1371.91	312.864
1372.89	312.008
1373.88	322.469
1374.87	319.036
1375.86	319.197
1376.85	319.624
1377.84	326.238
1378.82	319.694
1379.81	311.662
1380.8	316.476
1381.78	317.47
1382.77	323.728
1383.76	320.051
1384.74	319.07
1385.73	319.134
1386.72	333.065
1387.7	369.793
1388.68	323.552
1389.67	317.687
1390.65	316.941
1391.64	320.952
1392.62	311.393
1393.61	322.141
1394.59	321.464
1395.57	317.612
1396.56	317.395
1397.54	320.324
1398.52	309.42
1399.5	311.819
1400.49	313.162
1401.47	317.514
1402.45	314.872
1403.43	317.206
1404.41	313.361
1405.39	312.311
1406.37	314.833
1407.35	315.191
1408.33	315.619
1409.31	308.678
1410.29	318.724
1411.27	313.991
1412.25	309.615
1413.23	312.541
1414.21	315.523
1415.19	316.349
1416.16	315.793
1417.14	312.65
1418.12	311.503
1419.1	315.895
1420.07	315.026
1421.05	317.52
1422.03	315.901
1423	316.657
1423.98	317.064
1424.95	313.044
1425.93	314.03
1426.9	318.507
1427.88	313.733
1428.85	318.208
1429.83	316.555
1430.8	317.693
1431.78	313.683
1432.75	317.151
1433.72	314.234
1434.7	317.264
1435.67	319.345
1436.64	318.094
1437.62	317.434
1438.59	315.262
1439.56	322.16
1440.53	314.558
1441.5	321.427
1442.47	317.707
1443.44	319.469
1444.42	314.987
1445.39	320.817
1446.36	316.321
1447.33	319.322
1448.29	325.657
1449.26	315.936
1450.23	318.168
1451.2	320.214
1452.17	323.896
1453.14	321.4
1454.11	318.247
1455.07	321.495
1456.04	322.108
1457.01	319.671
1457.98	324.968
1458.94	317.383
1459.91	319.428
1460.88	313.994
1461.84	319.418
1462.81	315.571
1463.77	315.395
1464.74	318.005
1465.61	319.822
1466.59	317.964
1467.57	315.349
1468.55	315.731
1469.53	314.091
1470.51	312.971
1471.49	317.06
1472.47	318.426
1473.45	321.986
1474.43	319.605
1475.4	317.19
1476.38	321.916
1477.36	317.578
1478.34	312.566
1479.32	321.994
1480.29	318.968
1481.27	321.537
1482.25	324.955
1483.22	317.205
1484.2	319.902
1485.18	318.38
1486.15	316.758
1487.13	317.138
1488.1	317.755
1489.08	321.553
1490.05	318.593
1491.03	318.802
1492	320.869
1492.98	316.364
1493.95	319.074
1494.92	317.475
1495.9	321.165
1496.87	321.549
1497.84	318.6
1498.82	316.908
1499.79	317.128
1500.76	317.187
1501.73	318.211
1502.7	320.262
1503.68	319.977
1504.65	316.884
1505.62	316.672
1506.59	317.744
1507.56	318.576
1508.53	319.45
1509.5	320.8
1510.47	322.122
1511.44	317.784
1512.41	315.72
1513.38	323.372
1514.35	319.935
1515.31	315.3
1516.28	322.899
1517.25	320.273
1518.22	324.872
1519.19	318.354
1520.15	322.233
1521.12	327.52
1522.09	323.872
1523.05	321.657
1524.02	321.058
1524.99	322.995
1525.95	321.222
1526.92	320.56
1527.88	323.723
1528.85	321.325
1529.81	323.387
1530.78	322.577
1531.74	321.835
1532.71	323.946
1533.67	326.034
1534.63	323.342
1535.6	325.858
1536.56	323.275
1537.52	323.787
1538.49	324.016
1539.45	327.16
1540.41	324.038
1541.37	323.024
1542.33	327.01
1543.29	325.974
1544.26	325.868
1545.22	329.075
1546.18	326.234
1547.14	325.146
1548.1	330.398
1549.06	324.611
1550.02	325.058
1550.98	327.137
1551.94	323.97
1552.9	322.373
1553.85	328.114
1554.81	334.264
1555.77	326.4
1556.73	331.615
1557.69	325.636
1558.64	331.66
1559.6	329.087
1560.56	326.482
1561.52	328.369
1562.47	332.876
1563.43	324.224
1564.38	323.483
1565.34	328.811
1566.3	325.439
1567.25	329.506
1568.21	331.198
1569.16	325.889
1570.12	326.904
1571.07	330.061
1572.02	323.718
1572.98	327.73
1573.93	327.052
1574.89	327.928
1575.84	324.172
1576.79	325.378
1577.74	332.759
1578.7	328.551
1579.65	324.599
1580.6	329.125
1581.55	327.192
1582.5	325.432
1583.46	325.246
1584.41	331.934
1585.36	330.463
1586.31	328.229
1587.26	328.762
1588.21	331.864
1589.16	326.058
1590.11	347.682
1591.06	327.495
1592.01	323.381
1592.95	329.044
1593.9	328.26
1594.85	331.149
1595.8	329.405
1596.75	330.911
1597.69	324.041
1598.64	335.123
1599.59	330.4
1600.54	327.184
1601.48	330.396
1602.43	328.897
1603.38	331.927
1604.32	328.804
1605.27	326.756
1606.21	332.902
1607.16	330.146
1608.1	326.123
1609.05	331.659
1609.99	328.16
1610.94	330.055
1611.88	325.505
1612.82	329.943
1613.77	329.052
1614.71	329.485
1615.65	330.426
1616.6	328.177
1617.54	330.192
1618.48	342.63
1619.42	331.144
1620.36	332.496
1621.3	337.105
1622.25	332.229
1623.19	335.869
1624.13	333.161
1625.07	335.733
1626.01	333.041
1626.95	330.103
1627.89	330.67
1628.83	336.907
1629.77	329.89
1630.71	332.085
1631.65	336.268
1632.58	334.55
1633.52	335.566
1634.46	334.008
1635.4	336.445
1636.34	335.407
1637.27	337.479
1638.21	330.084
1639.15	336.552
1640.09	336.619
1641.02	332.464
1641.96	342.274
1642.89	337.087
1643.83	337.148
1644.77	334.369
1645.7	338.571
1646.64	338.166
1647.57	336.932
1648.51	338.408
1649.44	352.187
1650.37	345.545
1651.31	339.532
1652.24	339.99
1653.17	339.614
1654.11	341.827
1655.04	340.267
1655.97	338.671
1656.91	341.798
1657.84	336.964
1658.77	337.927
1659.7	335.318
1660.63	348.578
1661.56	339.829
1662.49	339.783
1663.43	336.807
1664.36	338.492
1665.29	342.024
1666.22	337.222
1667.15	337.701
1668.07	340.794
1669.01	342.091
1669.93	341.001
1670.86	338.435
1671.79	343.288
1672.72	341.433
1673.65	339.635
1674.58	343.02
1675.5	339.968
1676.43	335.964
1677.36	342.956
1678.28	338.63
1679.21	334.097
1680.14	341.133
1681.06	336.02
1681.99	339.485
1682.92	342.133
1683.84	340.96
1684.77	340.475
1685.69	338.87
1686.61	344.14
1687.54	341.348
1688.46	338.245
1689.39	338.305
1690.31	341.243
1691.24	336.531
1692.16	340.096
1693.08	339.828
1694.01	337.487
1694.93	338.645
1695.85	336.666
1696.77	336.715
1697.69	335.502
1698.61	337.688
1699.54	334.618
1700.46	334.799
1701.38	340.977
1702.3	336.887
1703.22	337.591
1704.11	337.353
1705.04	339.899
1705.98	343.775
1706.92	341.596
1707.85	336.762
1708.78	342.234
1709.72	336.999
1710.65	341.376
1711.59	334.599
1712.52	336.136
1713.45	333.432
1714.39	339.015
1715.32	342.561
1716.25	343.425
1717.19	334.925
1718.12	337.578
1719.05	347.02
1719.98	340.357
1720.91	339.779
1721.84	336.322
1722.77	338.061
1723.7	337.281
1724.64	340.392
1725.57	341.668
1726.5	337.808
1727.43	339.742
1728.36	337.262
1729.29	339.446
1730.21	338.106
1731.14	340.993
1732.07	334.84
1733	342.71
1733.93	343.011
1734.86	338.368
1735.78	340.022
1736.71	338.22
1737.64	343.291
1738.57	343.164
1739.49	342.789
1740.42	341.501
1741.35	338.899
1742.27	343.18
1743.2	339.152
1744.12	342.459
1745.05	343.947
1745.97	341.978
1746.9	344.715
1747.82	342.785
1748.75	343.974
1749.67	338.549
1750.6	339.745
1751.52	339.721
1752.44	340.649
1753.37	345.576
1754.29	347.113
1755.21	341.375
1756.14	341.099
1757.06	343.499
1757.98	342.636
1758.9	348.521
1759.82	344.015
1760.75	342.823
1761.67	343.447
1762.59	343.432
1763.51	345.353
1764.43	346.244
1765.35	347.422
1766.27	344.856
1767.19	351.218
1768.11	344.835
1769.03	344.461
1769.95	344.558
1770.87	344.858
1771.79	345.343
1772.7	344.534
1773.62	348.506
1774.54	345.056
1775.46	341.543
1776.38	342.227
1777.29	345.631
1778.21	346.598
1779.13	353.855
1780.04	347.836
1780.96	346.134
1781.88	344.833
1782.79	344.253
1783.71	347.386
1784.62	348.349
1785.54	347.199
1786.45	344.778
1787.37	349.995
1788.28	346.653
1789.2	343.267
1790.11	344.739
1791.02	347.035
1791.94	347.187
1792.85	345.92
1793.76	347.62
1794.68	345.51
1795.59	347.466
1796.5	353.852
1797.42	344.754
1798.33	351.827
1799.24	344.285
1800.15	348.558
1801.06	345.549
1801.97	345.627
1802.88	349.478
1803.79	344.666
1804.71	347.626
1805.62	348.905
1806.53	347.451
1807.44	351.179
1808.34	349.084
1809.25	352.467
1810.16	348.342
1811.07	351.077
1811.98	350.004
1812.89	353.431
1813.8	348.71
1814.7	348.061
1815.61	353.047
1816.52	348.416
1817.43	348.987
1818.33	351.777
1819.24	349.793
1820.15	349.172
1821.05	349.024
1821.96	353.659
1822.86	349.438
1823.77	352.896
1824.67	355.71
1825.58	349.972
1826.48	351.598
1827.39	356.34
1828.29	350.264
1829.2	353.261
1830.1	350.772
1831	355.31
1831.91	356.832
1832.81	352.916
1833.71	358.209
1834.62	355.555
1835.52	350.418
1836.42	358.573
1837.32	352.651
1838.23	354.231
1839.13	358.784
1840.03	354.338
1840.93	356.668
1841.83	351.541
1842.73	351.794
1843.63	351.673
1844.53	352.592
1845.43	360.05
1846.33	354.426
1847.23	355.445
1848.13	355.89
1849.03	354.979
1849.93	357.478
1850.83	359.959
1851.73	358.843
1852.62	358.472
1853.52	355.667
1854.42	357.009
1855.32	357.425
1856.21	357.891
1857.11	355.15
1858.01	358.222
1858.91	356.702
1859.8	364.22
1860.7	362.926
1861.59	355.78
1862.49	358.414
1863.38	363.3
1864.28	358.512
1865.17	359.358
1866.07	355.465
1866.96	362.214
1867.86	355.945
1868.75	362.915
1869.65	359.158
1870.54	358.354
1871.43	360.034
1872.33	361.093
1873.22	360.684
1874.11	356.475
1875	357.895
1875.9	361.427
1876.79	363.117
1877.68	360.989
1878.57	362.446
1879.46	357.715
1880.35	365.614
1881.24	357.802
1882.13	358.496
1883.03	359.961
1883.91	366.164
1884.81	365.258
1885.7	361.607
1886.58	360.923
1887.47	365.48
1888.36	360.132
1889.25	361.969
1890.14	363.015
1891.03	365.521
1891.92	363.08
1892.8	366.282
1893.69	362.755
1894.58	357.997
1895.47	357.787
1896.35	362.415
1897.24	361.569
1898.13	360.372
1899.01	361.878
1899.9	363.727
1900.78	364.096
1901.67	360.64
1902.56	362.855
1903.44	362.626
1904.33	359.796
1905.21	362.68
1906.09	361.242
1906.98	363.458
1907.86	363.608
1908.75	360.884
1909.63	364.285
1910.51	364.581
1911.4	365.785
1912.28	369.832
1913.16	369.422
1914.04	366.097
1914.93	368.478
1915.81	363.987
1916.69	367.836
1917.57	366.345
1918.45	368.777
1919.33	364.767
1920.21	366.335
1921.09	367.42
1921.97	368.151
1922.86	364.584
1923.74	364.634
1924.61	367.29
1925.49	370.273
1926.37	368.39
1927.25	368.328
1928.13	368.36
1929.01	367.173
1929.89	366.871
1930.77	366.31
1931.55	367.719
1932.44	367.153
1933.33	371.538
1934.22	366.065
1935.12	367.063
1936.01	374.013
1936.9	371.578
1937.79	366.003
1938.68	368.992
1939.57	370.348
1940.46	371.633
1941.35	366.646
1942.25	371.212
1943.14	371.371
1944.03	372.636
1944.92	366.433
1945.8	370.51
1946.69	369.612
1947.58	368.13
1948.47	370.886
1949.36	371.773
1950.25	368.447
1951.14	367.982
1952.03	371.985
1952.91	363.253
1953.8	367.962
1954.69	370.365
1955.58	372.086
1956.46	373.784
1957.35	374.921
1958.24	369.436
1959.12	373.404
1960.01	369.832
1960.89	369.183
1961.78	371.488
1962.67	367.777
1963.55	368.445
1964.44	371.688
1965.32	367.339
1966.2	370.335
1967.09	378.551
1967.97	372.586
1968.86	368.826
1969.74	371.474
1970.62	373.718
1971.51	371.471
1972.39	367.214
1973.27	370.541
1974.16	374.022
1975.04	373.266
1975.92	369.398
1976.8	373.9
1977.68	372.512
1978.56	370.521
1979.45	376.133
1980.33	370.705
1981.21	371.4
1982.09	368.157
1982.97	372.938
1983.85	369.035
1984.73	371.167
1985.61	371.054
1986.49	370.777
1987.37	374.967
1988.24	374.534
1989.12	370.666
1990	367.831
1990.88	372.61
1991.76	373.425
1992.64	372.12
1993.51	373.777
1994.39	373.978
1995.27	370.925
1996.15	370.23
1997.02	369.064
1997.9	370.887
1998.77	370.038
1999.65	368.634
2000.53	366.113
2001.4	373.071
2002.28	368.825
2003.15	371.137
2004.03	369.943
2004.9	370.669
2005.78	369.105
2006.65	370.401
2007.52	373.936
2008.4	368.717
2009.27	369.956
2010.15	369.073
2011.02	369.66
2011.89	370.597
2012.77	369.18
2013.64	369.446
2014.51	373.433
2015.38	376.513
2016.25	369.783
2017.13	370.604
2018	369.852
2018.87	369.532
2019.74	368.598
2020.61	368.576
2021.48	370.467
2022.35	374.113
2023.22	372.814
2024.09	378.883
2024.96	373.213
2025.83	371.935
2026.7	373.531
2027.57	370.392
2028.44	368.737
2029.31	373.49
2030.17	368.661
2031.04	370.094
2031.91	371.795
2032.78	374.071
2033.64	372.576
2034.51	373.698
2035.38	370.782
2036.25	371.702
2037.11	374.007
2037.98	373.828
2038.85	376.15
2039.71	378.595
2040.58	373.3
2041.44	371.984
2042.31	371.963
2043.17	372.66
2044.04	370.798
2044.9	371.442
2045.77	374.84
2046.63	373.453
2047.49	382.653
2048.36	377.527
2049.22	373.723
2050.09	375.087
2050.95	375.417
2051.81	377.513
2052.67	374.848
2053.54	377.535
2054.4	380.886
2055.26	376.453
2056.12	374.784
2056.98	376.709
2057.84	380.942
2058.71	374.9
2059.57	378.738
2060.43	373.245
2061.29	379.973
2062.15	376.235
2063.01	378.16
2063.87	375.9
2064.73	380.19
2065.59	377.952
2066.45	379.033
2067.3	377.5
2068.16	377.166
2069.02	374.813
2069.88	375.019
2070.74	376.51
2071.6	382.159
2072.45	381.881
2073.31	379.508
2074.17	377.825
2075.02	375.381
2075.88	379.891
2076.74	381.557
2077.59	379.186
2078.45	379.983
2079.31	378.496
2080.16	383.335
2081.02	378.334
2081.87	380.613
2082.73	376.473
2083.58	377.435
2084.44	378.075
2085.29	375.642
2086.15	386.614
2087	383.67
2087.85	378.096
2088.71	377.478
2089.56	381.444
2090.41	385.302
2091.26	377.65
2092.12	381.615
2092.97	379.406
2093.82	386.032
2094.67	385.478
2095.53	379.543
2096.38	383.231
2097.23	388.16
2098.08	383.479
2098.93	381.558
2099.78	384.789
2100.63	384.802
2101.48	387.671
2102.33	379.897
2103.18	382.285
2104.03	387.071
2104.88	383.32
2105.73	384.544
2106.58	383.532
2107.43	385.162
2108.27	383.498
2109.12	384.589
2109.97	382.847
2110.82	382.291
2111.67	386.732
2112.51	387.383
2113.36	384.977
2114.21	384.771
2115.05	390.9
2115.9	387.001
2116.75	386.746
2117.59	386.482
2118.44	389.91
2119.28	388.466
2120.13	390.456
2120.98	387.854
2121.82	390.063
2122.66	391.792
2123.51	385.793
2124.35	387.665
2125.2	389.095
2126.04	391.344
2126.88	390.72
2127.73	390.512
2128.57	387.843
2129.41	390.641
2130.26	386.208
2131.1	391.006
2131.94	394.546
2132.78	388.134
2133.63	390.601
2134.47	394.464
2135.31	392.149
2136.15	391.771
2136.99	390.795
2137.83	397.485
2138.67	392.234
2139.51	393.13
2140.35	394.347
2141.19	392.92
2142.03	391.739
2142.87	393.096
2143.71	392.716
2144.55	394.119
2145.39	390.944
2146.23	391.185
2147.07	391.686
2147.9	393.385
2148.66	394.165
2149.51	399.616
2150.36	390.668
2151.22	389.988
2152.07	390.951
2152.92	393.16
2153.77	391.465
2154.62	396.147
2155.48	391.319
2156.33	399.485
2157.18	391.438
2158.03	392.052
2158.88	391.807
2159.73	396.047
2160.58	392.273
2161.43	397.492
2162.28	398.029
2163.13	391.876
2163.98	397.019
2164.83	395.489
2165.68	396.489
2166.52	394.4
2167.37	395.453
2168.22	397.887
2169.07	392.409
2169.91	391.293
2170.76	397.499
2171.61	393.079
2172.46	395.889
2173.3	392.666
2174.15	399.91
2175	398.723
2175.84	396.242
2176.69	399.844
2177.53	396.249
2178.38	398.733
2179.23	400.039
2180.07	392.954
2180.92	394.003
2181.76	403.601
2182.61	394.26
2183.45	392.606
2184.29	395.498
2185.14	397.671
2185.98	393.556
2186.82	394.788
2187.67	401.917
2188.51	399.309
2189.35	393.845
2190.2	397.027
2191.04	396.863
2191.88	402.767
2192.72	396.518
2193.56	394.452
2194.41	394.883
2195.25	394.392
2196.09	396.662
2196.93	397.276
2197.77	398.334
2198.61	395.74
2199.45	393.716
2200.29	396.707
2201.13	394.9
2201.97	396.96
2202.81	398.553
2203.65	394.313
2204.49	394.513
2205.33	396.113
2206.16	392.955
2207	399.946
2207.84	395.315
2208.68	397.821
2209.52	399.234
2210.35	398.094
2211.19	397.065
2212.03	396.044
2212.87	394.794
2213.7	398.731
2214.54	399.051
2215.38	400.347
2216.21	400.897
2217.05	395.384
2217.88	397.62
2218.72	396.857
2219.55	397.297
2220.39	398.1
2221.22	404.366
2222.06	396.637
2222.89	401.072
2223.73	400.888
2224.56	397.175
2225.39	398.416
2226.23	398.994
2227.06	395.292
2227.89	396.695
2228.73	400.04
2229.56	402.455
2230.39	399.854
2231.22	403.163
2232.06	400.942
2232.89	401.598
2233.72	399.697
2234.55	402.962
2235.38	399.676
2236.21	412.757
2237.04	405.94
2237.88	397.477
2238.71	406.741
2239.53	404.891
2240.37	402.442
2241.2	407.212
2242.02	400.918
2242.85	404.899
2243.68	402.815
2244.51	405.241
2245.34	410.176
2246.17	401.559
2247	407.947
2247.83	403.087
2248.65	403.982
2249.48	403.99
2250.31	405.77
2251.14	405.997
2251.96	410.032
2252.79	406.628
2253.62	410.356
2254.44	408.344
2255.27	406.357
2256.09	403.377
2256.92	410.483
2257.75	405.727
2258.57	407.724
2259.4	408.728
2260.22	409.065
2261.05	406.83
2261.87	407.122
2262.69	410.911
2263.52	405.762
2264.34	409.233
2265.17	410.817
2265.99	407.81
2266.81	409.147
2267.64	413.514
2268.46	406.817
2269.28	404.22
2270.1	410.818
2270.93	412.11
2271.75	406.689
2272.57	415.823
2273.39	415.155
2274.21	409.913
2275.03	410.148
2275.85	409.028
2276.67	412.294
2277.5	412.892
2278.32	409.82
2279.14	411.748
2279.96	408.056
2280.78	409.172
2281.59	408.834
2282.41	410.552
2283.23	415.259
2284.05	407.3
2284.87	413.431
2285.69	408.631
2286.51	411.768
2287.33	412.855
2288.14	411.017
2288.96	414.293
2289.78	413.086
2290.6	414.164
2291.41	409.552
2292.23	415.004
2293.05	415.843
2293.86	417.002
2294.68	413.064
2295.49	411.158
2296.31	411.339
2297.13	410.136
2297.94	412.603
2298.75	418.592
2299.57	415.738
2300.39	411.808
2301.2	419.207
2302.01	416.523
2302.83	414.746
2303.64	413.967
2304.46	412.922
2305.27	415.974
2306.08	412.761
2306.89	411.988
2307.71	409.733
2308.52	414.514
2309.33	416.31
2310.14	418.009
2310.96	415.416
2311.77	407.811
2312.58	411.794
2313.39	409.565
2314.2	412.051
2315.01	419.096
2315.82	414.93
2316.63	415.636
2317.44	413.221
2318.26	417.009
2319.06	413.657
2319.87	418.008
2320.68	413.062
2321.49	414.387
2322.3	423.049
2323.11	421.451
2323.92	414.672
2324.73	415.76
2325.54	415.868
2326.34	421.136
2327.15	417.325
2327.96	414.069
2328.77	414.941
2329.57	418.7
2330.38	420.708
2331.19	418.801
2331.99	414.554
2332.8	416.368
2333.61	420.729
2334.41	420.73
2335.22	417.409
2336.02	418.729
2336.83	423.475
2337.63	424.559
2338.44	425.903
2339.24	432.395
2340.05	422.82
2340.85	425.224
2341.66	425.474
2342.46	423.818
2343.26	420.203
2344.07	418.708
2344.87	422.439
2345.67	425.15
2346.48	421.313
2347.28	421.476
2348.08	426.179
2348.88	424.137
2349.69	425.063
2350.49	425.28
2351.29	424.072
2352.09	423.503
2352.89	426.927
2353.69	423.254
2354.49	425.293
2355.17	424.135
2355.99	420.8
2356.8	431.413
2357.62	431.531
2358.43	424.321
2359.25	420.501
2360.06	422.504
2360.88	422.285
2361.69	425.05
2362.5	426.448
2363.32	425.54
2364.13	423.025
2364.94	421.582
2365.76	430.581
2366.57	424.98
2367.38	428.295
2368.19	426.7
2369	425.299
2369.82	424.708
2370.63	427.47
2371.44	423.524
2372.25	431.757
2373.06	430.946
2373.87	429.01
2374.68	427.796
2375.49	433.61
2376.3	428.164
2377.11	433.637
2377.92	426.125
2378.73	424.749
2379.54	427.836
2379.94	429.913