File: Data/3-Raman/raw/bu04w-a-ff3-fi07-v_150 (500nm)_633nm_edge_100%_x100_vis_lwd_h50um_45sx2_01.txt
#Acq. time (s)=	45
#Accumulations=	2
#Range (cm-¹)=	100...4000
#Windows=	1
#Auto scanning=	Off
#Autofocus=	Off
#Macrospot=	Off
#AutoExposure=	Off
#Spike filter=	Multiple accum.
#Delay time (s)=	2
#Binning=	1
#Readout mode=	Signal
#DeNoise=	Off
#ICS correction=	On
#Dark correction=	Off
#Inst. Process=	Off
#Detector Gain=	Best Dynamic
#Detector ADC=	50 kHz HS
#Detector temperature (°C)=	-60.09
#Instrument=	LabRAM HR Evol
#Detector=	SIN-EM FIVIS
#Objective=	x100_VIS_LWD
#Grating=	150 (500nm)
#ND Filter=	100%
#Laser=	633nm_Edge
#Hole=	49.98
#Temperature=	0
#Range=	Visible
#StageXY=	75x50mm Scan+
#StageZ=	Z motor
#X (µm)=	0
#Y (µm)=	0
#Z (µm)=	-18
#Full time(mm:ss)=	1:34
#Project=	21_11_22
#Sample=	BU04w
#Site=
#Title=	BU04w-A-FF3-FI07-V_150 (500nm)_633nm_Edge_100%_x100_VIS_LWD_H50um_45sX2
#Remark=
#Date=	22.11.2021 12:42
#Acquired=	22.11.2021 12:42:14
100.177	416.998
106.695	403.978
113.209	384.337
119.717	374.124
126.219	372.466
132.716	383.187
139.208	414.809
145.694	367.986
152.175	347.019
158.651	482.262
165.121	522.81
171.586	325.477
178.045	278.434
184.5	256.168
190.947	254.83
197.39	249.677
203.829	261.029
210.262	255.209
216.688	269.418
223.11	319.802
229.527	458.383
235.939	568.181
242.344	406.147
248.745	334.808
255.141	364.005
261.53	371.43
267.916	319.151
274.294	324.815
280.669	365.561
287.038	382.466
293.402	319.653
299.76	302.354
306.114	300.171
312.461	397.191
318.805	624.323
325.142	1018.51
331.475	756.997
337.802	480.503
344.123	323.871
350.441	323.716
356.752	346.057
363.058	360.77
369.36	358.519
375.656	274.586
381.947	268.681
388.232	248.984
394.512	289.627
400.789	303.422
407.059	310.656
413.324	344.295
419.584	406.253
425.839	523.645
432.089	661.272
438.333	559.867
444.573	449.492
450.807	447.233
457.037	419.9
463.261	326.844
469.48	275.305
475.695	272.457
481.904	287.426
488.108	296.771
494.307	276.341
500.502	324.877
506.691	376.343
512.874	388.736
519.053	373.264
525.227	345.838
531.396	334.448
537.559	312.801
543.718	296.48
549.873	271.288
556.022	269.622
562.165	242.973
568.304	226.513
574.437	209.908
580.567	226.067
586.691	242.29
592.81	333.256
598.924	417.829
605.033	354.922
611.138	313.506
617.236	319.011
623.332	305.896
629.42	288.862
635.506	304.21
641.585	270.99
647.659	285.569
653.73	303.755
659.794	305.752
665.854	266.662
671.91	218.626
677.96	186.045
684.005	182.385
690.045	163.038
696.082	168.09
702.113	169.39
708.139	162.164
714.16	157.449
720.176	169.562
726.187	172.243
732.194	152.262
738.196	167.886
744.193	153.6
750.185	169.261
756.173	168.238
762.155	160.981
768.133	170.769
774.107	152.496
780.075	155.676
786.039	164.385
791.998	171.148
797.952	158.929
803.902	155.994
809.845	164.288
815.786	166.799
821.721	163.601
827.652	153.839
833.576	147.137
839.498	165.931
845.415	169.05
851.327	160.962
857.233	173.596
863.135	174.073
869.032	176.444
874.925	185.296
880.813	211.081
886.697	208.298
892.576	200.629
898.45	198.507
904.318	181.971
910.184	175.843
916.044	205.489
921.9	218.39
927.75	236.255
933.596	263.842
939.439	311.817
945.275	382.09
951.107	446.389
956.936	468.983
962.759	416.715
968.577	443.457
974.391	517.891
980.201	651.054
986.006	817.833
991.806	801.126
997.602	682.255
1003.39	583.139
1009.18	576.181
1014.96	644.485
1020.74	760.694
1026.51	741.264
1032.28	509.034
1038.04	364.287
1043.8	302.656
1049.56	265.765
1055.31	272.129
1061.05	254.004
1066.8	253.021
1072.53	257.804
1078.26	308.081
1083.99	347.533
1089.72	377.32
1095.44	516.507
1101.15	500.678
1106.86	336.332
1112.56	253.303
1118.27	233.754
1123.96	219.715
1129.65	241.728
1135.34	251.149
1141.03	336.196
1146.7	402.629
1152.38	580.37
1158.05	419.879
1163.71	260.009
1169.37	214.395
1175.03	190.469
1180.68	178.377
1186.33	158.692
1191.98	156.762
1197.61	159.901
1203.25	145.63
1208.88	137.296
1214.51	134.876
1220.13	127.557
1225.74	139.147
1231.36	142.784
1236.97	137.286
1242.57	133.614
1248.17	137.847
1253.77	134.891
1259.36	144.905
1264.94	144.7
1270.53	133.41
1276.11	204.467
1281.68	184.962
1287.25	137.607
1292.81	131.452
1298.38	124.418
1303.93	124.469
1309.48	136.701
1315.03	129.085
1320.58	123.473
1326.12	127.998
1331.65	115.31
1337.18	114.696
1342.71	118.085
1348.23	122.425
1353.75	132.901
1359.26	125.858
1364.77	122.823
1370.28	119.707
1375.78	143.288
1381.28	313.662
1386.77	153.421
1392.26	124.661
1397.74	123.772
1403.23	133.197
1408.7	120.024
1414.17	127.488
1419.64	122.604
1425.11	118.762
1430.56	111.791
1436.02	114.159
1441.47	118.611
1446.92	105.29
1452.36	120.133
1457.8	107.621
1463.23	111.833
1468.66	104.454
1474.09	110.73
1479.51	108.662
1484.93	117.125
1490.34	116.195
1495.75	109.011
1501.16	115.556
1506.56	111.589
1511.96	97.0457
1517.35	106.925
1522.74	110.486
1528.13	109.801
1533.51	106.993
1538.88	108.402
1544.25	104.329
1549.62	108.719
1554.99	110.795
1560.35	103.102
1565.71	103.002
1571.06	103.969
1576.41	106.03
1581.75	108.184
1587.09	108.215
1592.43	110.44
1597.76	100.864
1603.09	112.911
1608.41	100.171
1613.73	104.83
1619.05	112.859
1624.36	106.724
1629.67	102.73
1634.97	112.991
1640.27	98.8306
1645.57	114.472
1650.86	110.187
1656.15	103.635
1661.43	107
1666.71	98.1474
1671.99	102.588
1677.26	99.2452
1682.53	105.862
1687.79	102.443
1693.05	111.242
1698.31	100.22
1703.56	102.839
1708.81	109.994
1714.06	95.3275
1719.3	107.896
1724.53	108.06
1729.77	97.065
1735	114.13
1740.22	108.716
1745.44	107.795
1750.66	111.343
1755.87	100.15
1761.08	103.59
1766.29	102.498
1771.49	90.0926
1776.69	101.507
1781.88	101.65
1787.07	91.5857
1792.26	95.211
1797.44	104.578
1802.62	101.428
1807.79	87.9092
1812.96	109.979
1818.13	99.8333
1823.29	91.9528
1828.45	102.597
1833.61	97.0336
1838.76	97.2635
1843.91	95.1084
1849.05	97.6023
1854.19	91.8771
1859.33	99.0623
1864.46	100.43
1869.59	100.64
1874.71	88.996
1879.83	91.4674
1884.95	96.2918
1890.06	91.6219
1895.17	102.266
1900.28	91.6729
1905.38	96.5761
1910.48	84.9231
1915.57	93.5471
1920.66	93.6997
1925.75	95.0705
1930.83	89.2647
1935.91	89.4246
1940.99	93.1623
1946.06	86.0474
1951.13	94.5479
1956.19	84.9485
1961.26	95.8166
1966.31	84.9737
1971.36	90.9595
1976.41	96.9284
1981.46	81.229
1986.5	84.7962
1991.54	93.1813
1996.58	83.5454
2001.61	87.1581
2006.63	94.4125
2011.66	88.4652
2016.68	86.1277
2021.69	94.6136
2026.71	80.2436
2031.72	90.0396
2036.72	85.3691
2041.72	79.4718
2046.72	91.8006
2051.71	89.5655
2056.71	89.7125
2061.69	82.5729
2066.68	88.8919
2071.66	86.622
2076.63	88.0329
2081.6	89.4324
2086.57	90.8036
2091.54	81.0385
2096.5	79.9724
2101.46	88.8599
2106.41	94.0745
2111.36	83.096
2116.31	88.3683
2121.25	82.3548
2126.19	86.381
2131.13	86.6176
2136.06	85.5621
2140.99	75.5896
2145.92	77.0177
2150.84	87.3388
2155.76	91.2749
2160.67	83.69
2165.58	85.0091
2170.49	74.8064
2175.39	87.662
2180.29	92.8145
2185.19	73.6025
2190.08	83.8562
2194.98	86.4632
2199.86	80.1457
2204.74	89.2587
2209.62	76.562
2214.5	79.309
2219.37	73.0433
2224.24	83.5987
2229.11	82.5121
2233.97	90.5382
2238.83	81.625
2243.68	80.5217
2248.53	80.7291
2253.38	76.9811
2258.22	77.1783
2263.06	78.6904
2267.9	81.4965
2272.73	69.6789
2277.56	77.7367
2282.39	73.8083
2287.21	79.1505
2292.03	69.858
2296.85	84.5214
2301.66	84.5903
2306.47	80.7052
2311.28	82.1969
2316.08	78.3655
2320.88	70.5079
2325.68	72.0374
2330.47	76.2862
2335.26	67.0392
2340.04	67.2504
2344.82	70.2073
2349.6	73.2005
2354.38	83.0545
2359.15	70.8917
2363.92	79.3034
2368.68	73.9479
2373.44	72.7142
2378.2	70.0839
2382.95	75.7417
2387.71	68.8552
2392.45	77.2391
2397.2	80.0332
2401.94	68.8991
2406.68	61.9255
2411.41	70.3463
2416.14	76.1612
2420.87	73.7282
2425.59	69.6143
2430.31	69.7874
2435.03	69.9841
2439.75	61.6893
2444.46	73.2513
2449.16	70.6188
2453.87	69.3965
2458.57	72.4694
2463.27	61.1662
2467.96	72.8804
2472.65	75.96
2477.34	73.2584
2482.02	76.3534
2486.7	69.2336
2491.38	72.2967
2496.05	79.7673
2500.72	68.1908
2505.39	68.3126
2510.06	68.4188
2514.72	72.9277
2519.37	64.1758
2524.03	74.6245
2528.68	61.4171
2533.33	70.4127
2537.97	66.0925
2542.61	64.7393
2547.25	63.3902
2551.88	73.9932
2556.51	63.6565
2561.14	66.7838
2565.77	63.9325
2570.39	68.6218
2575.01	67.287
2579.62	65.923
2584.23	66.0308
2588.84	75.2275
2593.45	66.1606
2598.05	66.2641
2602.65	69.4053
2607.24	66.4324
2611.84	66.4918
2616.42	63.4848
2621.01	62.0107
2625.59	60.542
2630.17	66.7691
2634.75	65.3809
2639.32	57.866
2643.89	71.9792
2648.46	69.1052
2653.02	61.5324
2657.58	69.4548
2662.14	74.2561
2666.69	55.5638
2671.24	68.2064
2675.79	66.8286
2680.33	62.4178
2684.88	64.2886
2689.41	61.3889
2693.95	68.0224
2698.48	68.1298
2703.01	69.8832
2707.53	65.1872
2712.06	62.0745
2716.57	65.4443
2721.09	65.5683
2725.6	67.2911
2730.11	68.9948
2734.62	67.4265
2739.12	62.5912
2743.62	59.4104
2748.12	69.2821
2752.61	71.1091
2757.1	58.1623
2761.59	68.0923
2766.08	66.5772
2770.56	68.3484
2775.04	63.5491
2779.51	67.0332
2783.98	57.2968
2788.45	65.8225
2792.92	66.0319
2797.38	61.1891
2801.84	64.7042
2806.3	61.4735
2810.75	59.9032
2815.2	61.6892
2819.65	70.2457
2824.09	61.8844
2828.53	60.2886
2832.97	68.8829
2837.41	63.8691
2841.84	63.9615
2846.27	60.652
2850.69	69.3258
2855.12	67.7767
2859.54	57.6245
2863.95	62.9636
2868.37	63.1629
2872.78	58.1496
2877.18	61.8153
2881.59	63.7715
2885.99	65.756
2890.39	62.463
2894.78	62.6699
2899.18	54.0469
2903.57	82.6772
2907.95	63.3099
2912.34	68.8367
2916.72	56.4444
2921.09	60.1765
2925.47	65.7387
2929.84	62.3183
2934.21	66.1146
2938.57	66.257
2942.94	55.4688
2947.29	61.0159
2951.65	70.2251
2956	57.5388
2960.36	59.4489
2964.7	68.7014
2969.05	63.3177
2973.39	67.1133
2977.73	69.0817
2982.06	58.1442
2986.4	60.1363
2990.73	65.8639
2995.05	64.1892
2999.38	62.5202
3003.7	53.3645
3008.01	66.6973
3012.33	70.6719
3016.64	67.1348
3020.95	71.1766
3025.26	73.3097
3029.56	65.8668
3033.86	60.2771
3038.16	69.9664
3042.45	73.9636
3046.74	64.4728
3051.03	68.4383
3055.32	74.3531
3059.6	82.2265
3063.88	70.7419
3068.16	80.574
3072.43	78.7701
3076.7	82.8129
3080.97	81.0152
3085.24	79.2262
3089.5	77.4636
3093.76	89.4956
3098.02	99.6573
3102.27	98.0084
3106.52	88.4323
3110.77	92.7645
3115.01	103.142
3119.26	97.5179
3123.5	101.972
3127.73	96.345
3131.97	107.005
3136.2	101.381
3140.43	97.7317
3144.65	129.137
3148.87	119.274
3153.09	115.503
3157.31	134.634
3161.52	128.752
3165.73	127.022
3169.94	131.553
3174.15	134.033
3178.35	138.515
3182.55	140.839
3186.75	145.258
3190.94	134.804
3195.13	145.668
3199.32	146.048
3203.51	148.717
3207.69	142.85
3211.87	134.799
3216.05	124.553
3220.22	144.636
3224.39	127.745
3228.56	126.067
3232.73	128.76
3236.89	120.372
3241.05	107.542
3245.21	114.695
3249.36	103.948
3253.52	95.2753
3257.66	99.9841
3261.81	100.317
3265.95	80.34
3270.1	89.7971
3274.23	92.4522
3278.37	83.4843
3282.5	83.6532
3286.63	83.8226
3290.76	77.0813
3294.88	77.2178
3299	86.5917
3303.12	79.8305
3307.24	79.9893
3311.35	75.4895
3315.46	84.9333
3319.57	75.7708
3323.68	89.9693
3327.78	78.4874
3331.88	78.7299
3335.98	88.4471
3340.07	79.2557
3344.16	72.3157
3348.25	70.0652
3352.34	86.8516
3356.42	75.104
3360.5	70.4925
3364.58	82.625
3368.66	80.3986
3372.73	63.728
3376.8	68.648
3380.87	66.3325
3384.93	68.8338
3388.99	81.0062
3393.05	61.7258
3397.11	64.2366
3401.16	69.1816
3405.21	71.6753
3409.26	62.0173
3413.31	62.0631
3417.35	69.4206
3421.39	59.7212
3425.43	67.0805
3429.46	74.4768
3433.5	62.3487
3437.53	59.9993
3441.55	60.1073
3445.58	65.1542
3449.6	67.785
3453.62	67.965
3457.64	63.2248
3461.65	53.4932
3465.66	53.6825
3469.67	61.3843
3473.68	56.527
3477.68	51.6607
3481.68	59.3989
3485.68	59.5702
3489.67	62.2765
3493.67	57.3451
3497.66	60.0312
3501.64	57.593
3505.63	52.5611
3509.61	60.3184
3513.59	65.4949
3517.57	52.6842
3521.54	60.4283
3525.52	57.8965
3529.49	57.9301
3533.45	63.1677
3537.42	55.549
3541.38	58.2654
3545.34	60.9634
3549.29	58.4561
3553.25	53.2862
3557.2	55.9355
3561.15	56.0047
3565.09	56.0922
3569.04	69.2899
3572.98	53.7088
3576.92	56.4621
3580.85	64.5193
3584.79	67.354
3588.72	70.2018
3592.64	57.1218
3596.57	57.2879
3600.49	60.1102
3604.41	57.5836
3608.33	49.6594
3612.25	49.7594
3616.16	49.8599
3620.07	52.6499
3623.98	47.2934
3627.88	52.7324
3631.79	52.7529
3635.69	50.0752
3639.58	52.8422
3643.48	58.3704
3647.37	55.7802
3651.26	53.0925
3655.15	47.6959
3659.03	45.0109
3662.92	50.5044
3666.8	50.5526
3670.67	45.1331
3674.55	45.188
3678.42	45.267
3682.29	45.3659
3686.16	59.2713
3690.02	56.6732
3693.89	42.9677
3697.75	54.1956
3701.61	54.3427
3705.46	48.8951
3709.31	54.6358
3713.16	54.7845
3717.01	49.2796
3720.86	55.0253
3724.7	43.8196
3728.54	55.2225
3732.38	52.4883
3736.21	46.9034
3740.04	58.3779
3743.87	49.9154
3747.7	47.1318
3751.53	52.907
3755.35	52.9537
3759.17	52.9862
3762.99	50.1459
3766.81	53.0345
3770.62	47.3365
3774.43	50.2498
3778.24	53.172
3782.04	64.7533
3785.85	47.561
3789.65	41.8541
3793.45	50.5894
3797.24	65.1691
3801.04	47.8887
3804.83	53.811
3808.62	48.1054
3812.4	51.1291
3816.19	48.3038
3819.97	51.3314
3823.75	51.4219
3827.52	45.6157
3831.3	48.6473
3835.07	51.692
3838.84	51.7772
3842.61	54.8455
3846.37	57.8788
3850.13	46.0354
3853.89	54.9739
3857.65	52.0197
3861.41	52.0255
3865.16	49.1021
3868.91	43.256
3872.66	52.2624
3876.4	52.295
3880.14	46.3473
3883.89	52.3666
3887.62	46.4254
3891.36	52.4737
3895.09	49.5631
3898.82	58.6651
3902.55	49.7177
3906.28	43.7541
3910	52.8794
3913.73	40.8625
3917.45	56.1061
3921.16	47.1186
3924.88	44.1837
3928.59	44.2786
3932.3	47.4224
3936.01	38.3001
3939.71	47.5654
3943.42	44.5875
3947.12	47.7533
3950.81	50.9183
3954.51	50.9881
3958.2	47.9548
3961.9	51.0889
3965.58	44.9264
3969.27	51.1374
3972.96	54.2538
3976.64	54.2721
3980.32	44.9726
3984	48.0687
3987.67	51.1664
3991.34	44.9717
3995.01	44.9961
3998.68	48.1439