File: Data/3-Raman/raw/bu04w-a-ff3-fi03-v_1800 (450-850nm)_633nm_edge_100%_x100_vis_lwd_h50um_45sx2_01.txt
#Acq. time (s)=	45
#Accumulations=	2
#Range (cm-¹)=	1200...2399
#Windows=	6
#Auto scanning=	Off
#Autofocus=	Off
#Macrospot=	Off
#AutoExposure=	Off
#Spike filter=	Multiple accum.
#Delay time (s)=	2
#Binning=	1
#Readout mode=	Signal
#DeNoise=	Off
#ICS correction=	On
#Dark correction=	Off
#Inst. Process=	Off
#Detector Gain=	Best Dynamic
#Detector ADC=	50 kHz EM
#Detector EM gain=	100
#Detector temperature (°C)=	-60.09
#Instrument=	LabRAM HR Evol
#Detector=	SIN-EM FIVIS
#Objective=	x100_VIS_LWD
#Grating=	1800 (450-850nm)
#ND Filter=	100%
#Laser=	633nm_Edge
#Hole=	49.98
#Temperature=	0
#Range=	Visible
#StageXY=	75x50mm Scan+
#StageZ=	Z motor
#X (µm)=	0
#Y (µm)=	0
#Z (µm)=	57.9
#Full time(mm:ss)=	9:32
#Project=	21_11_22
#Sample=	BU04w
#Site=
#Title=	BU04w-A-FF3-FI03-V_1800 (450-850nm)_633nm_Edge_100%_x100_VIS_LWD_H50um_45sX2
#Remark=
#Date=	22.11.2021 12:24
#Acquired=	22.11.2021 12:24:12
1201.04	302.335
1202.08	309.375
1203.11	299.532
1204.14	307.415
1205.17	297.633
1206.2	301.093
1207.24	303.747
1208.27	303.55
1209.3	302.646
1210.33	300.965
1211.36	307.377
1212.39	304.273
1213.42	301.629
1214.45	305.775
1215.48	300.025
1216.51	304.685
1217.54	302.074
1218.56	306.83
1219.59	311.689
1220.62	312.554
1221.65	301.217
1222.68	306.466
1223.7	302.308
1224.73	311.084
1225.76	303.525
1226.78	305.934
1227.81	304.959
1228.84	306.252
1229.86	307.872
1230.89	309.39
1231.91	306.475
1232.94	303.279
1233.96	304.917
1234.99	308.463
1236.01	308.424
1237.03	310.937
1238.06	304.473
1239.08	310.028
1240.1	302.749
1241.13	307.552
1242.15	312.475
1243.17	308.871
1244.19	314.4
1245.21	309.293
1246.24	311.292
1247.26	314.282
1248.28	308.667
1249.3	306.704
1250.32	315.308
1251.34	312.539
1252.36	311.092
1253.38	314.68
1254.4	317.234
1255.42	310.74
1256.44	312.841
1257.46	315.656
1258.47	310.001
1259.49	309.829
1260.51	309.941
1261.53	313.485
1262.55	319.883
1263.56	321.568
1264.58	333.428
1265.6	317.446
1266.61	314.892
1267.63	308.861
1268.65	327.092
1269.66	318.403
1270.68	307.543
1271.69	316.488
1272.71	312.553
1273.72	314.194
1274.74	311.621
1275.75	314.096
1276.76	313.492
1277.78	308.329
1278.79	317.983
1279.8	310.085
1280.82	312.127
1281.83	324.72
1282.84	369.413
1283.85	510.126
1284.86	521.308
1285.88	330.78
1286.89	318.163
1287.9	319.243
1288.91	310.931
1289.92	313.611
1290.93	307.41
1291.94	316.106
1292.95	310.691
1293.96	313.889
1294.97	308.425
1295.98	313.572
1296.99	308.9
1297.99	306.014
1299	310.098
1300.01	305.303
1301.02	303.032
1302.03	306.06
1303.03	309.854
1304.04	309.436
1305.05	311.536
1306.05	311.897
1307.06	314.684
1308.06	321.098
1309.07	317.765
1310.07	306.823
1311.08	316.835
1312.08	312.347
1313.09	305.206
1314.09	309.801
1315.1	308.97
1316.1	311.583
1317.1	305.852
1318.11	314.307
1319.11	312.287
1320.11	311.715
1321.12	310.44
1322.12	313.063
1323.12	312.547
1324.12	311.814
1325.12	309.563
1326.13	317.509
1327.13	309.806
1328.13	311.945
1329.13	312.452
1330.13	312.58
1331.13	311.795
1332.13	313.897
1333.13	310.188
1334.13	320.839
1335.13	310.836
1336.12	322.269
1337.12	316.419
1338.12	311.566
1339.12	322.012
1340.12	316.456
1341.11	319.976
1342.11	321.538
1343.11	314.385
1344.1	316.774
1345.1	317.046
1346.1	319.278
1347.09	319.953
1348.09	314.766
1349.08	318.835
1350.08	313.295
1351.07	312.408
1352.07	321.028
1353.06	314.984
1354.06	320.152
1355.05	314.358
1356.04	320.62
1357.04	324.52
1358.03	320.032
1359.02	324.49
1360.02	316.719
1361.01	321.333
1362	320.402
1362.99	315.339
1363.98	323.725
1364.98	320.811
1365.97	318.147
1366.96	316.66
1367.95	323.711
1368.94	322.573
1369.93	325.364
1370.92	317.237
1371.91	314.459
1372.9	316.718
1373.89	326.14
1374.87	319.573
1375.86	322.877
1376.85	318.084
1377.84	318.426
1378.83	318.173
1379.81	326.734
1380.8	324.281
1381.79	326.278
1382.78	323.205
1383.76	324.727
1384.75	329.992
1385.73	342.543
1386.72	451.864
1387.7	997.682
1388.69	370.879
1389.68	333.773
1390.66	319.525
1391.64	328.71
1392.63	320.192
1393.61	320.572
1394.6	323.983
1395.58	321.266
1396.56	321.009
1397.55	319.789
1398.53	308.912
1399.51	322.671
1400.49	316.765
1401.47	323.165
1402.46	323.678
1403.44	317.644
1404.42	317.973
1405.4	320.029
1406.38	315.325
1407.36	327.015
1408.34	333.7
1409.32	350.687
1410.3	331.65
1411.28	318.581
1412.26	329.758
1413.24	320.262
1414.22	316.967
1415.19	317.767
1416.17	326.698
1417.15	318.343
1418.13	330.721
1419.11	321.566
1420.08	320.675
1421.06	326.255
1422.04	320.481
1423.01	321.278
1423.99	319.64
1424.97	314.48
1425.94	324.901
1426.92	322.069
1427.89	317.286
1428.87	315.476
1429.84	321.198
1430.82	324.38
1431.79	321.421
1432.76	318.6
1433.74	327.264
1434.71	317.666
1435.68	317.649
1436.66	321.623
1437.63	326.236
1438.6	317.69
1439.57	318.285
1440.54	323.44
1441.52	325.004
1442.49	319.149
1443.46	322.951
1444.43	322.628
1445.4	326.409
1446.37	322.928
1447.34	320.781
1448.31	317.548
1449.28	323.716
1450.25	321.642
1451.22	319.876
1452.19	323.766
1453.16	327.975
1454.12	327.027
1455.09	326.699
1456.06	320.969
1457.03	327.034
1457.99	323.524
1458.96	322.411
1459.93	323.331
1460.9	321.556
1461.86	320.726
1462.83	321.385
1463.79	323.457
1464.76	323.437
1465.72	320.691
1466.69	327.42
1467.59	323.895
1468.57	320.943
1469.56	322.399
1470.53	323.472
1471.51	319.017
1472.49	324.781
1473.47	322.921
1474.45	325.651
1475.43	321.274
1476.41	323.919
1477.39	318.376
1478.36	338.851
1479.34	320.767
1480.32	317.794
1481.3	322.432
1482.27	330.057
1483.25	319.06
1484.23	323.833
1485.2	328.735
1486.18	319.781
1487.15	322.266
1488.13	320.715
1489.1	324.376
1490.08	324.803
1491.06	322.707
1492.03	323.779
1493	323.675
1493.98	324.113
1494.95	320.422
1495.92	316.721
1496.9	319.002
1497.87	319.426
1498.84	326.212
1499.82	324.201
1500.79	323.274
1501.76	323.366
1502.73	320.065
1503.7	324.093
1504.68	323.136
1505.65	322.64
1506.62	325.864
1507.59	323.485
1508.56	324.636
1509.53	325.923
1510.5	331.395
1511.47	321.745
1512.44	323.863
1513.4	329.269
1514.37	324.955
1515.34	322.467
1516.31	326.952
1517.28	327.584
1518.25	328.769
1519.21	326.617
1520.18	326.132
1521.15	328.347
1522.12	328.884
1523.08	324.449
1524.05	333.483
1525.02	327.943
1525.98	323.869
1526.95	331.126
1527.91	326.494
1528.88	325.224
1529.84	325.091
1530.81	326.393
1531.77	326.742
1532.74	325.693
1533.7	326.617
1534.66	330.653
1535.63	330.723
1536.59	328.112
1537.55	323.13
1538.52	331.155
1539.48	327.587
1540.44	330.107
1541.4	325.618
1542.36	327.415
1543.33	335.115
1544.29	329.515
1545.25	329.575
1546.21	325.82
1547.17	326.63
1548.13	329.811
1549.09	332.713
1550.05	328.804
1551.01	330.88
1551.97	331.191
1552.93	330.513
1553.89	335.036
1554.84	333.818
1555.8	341.174
1556.76	325.569
1557.72	331.632
1558.68	328.872
1559.63	336.984
1560.59	330.174
1561.55	332.092
1562.5	332.28
1563.46	335.666
1564.42	331.536
1565.37	329.097
1566.33	326.914
1567.28	329.864
1568.24	333.882
1569.19	331.795
1570.15	340.347
1571.1	330.539
1572.06	333.853
1573.01	330.291
1573.96	330.531
1574.92	333.64
1575.87	333.003
1576.82	333.294
1577.78	336.226
1578.73	329.977
1579.68	331.528
1580.63	332.609
1581.59	328.428
1582.54	329.881
1583.49	334.046
1584.44	338.901
1585.39	330.779
1586.34	331.861
1587.29	331.425
1588.24	334.159
1589.19	333.91
1590.14	330.435
1591.09	333.239
1592.04	327.981
1592.99	330.339
1593.94	328.508
1594.88	333.344
1595.83	333.901
1596.78	331.009
1597.73	334.042
1598.68	331.943
1599.62	332.643
1600.57	329.534
1601.52	334.68
1602.46	333.467
1603.41	338.494
1604.35	332.301
1605.3	336.734
1606.25	336.256
1607.19	327.944
1608.14	328.402
1609.08	330.786
1610.03	343.807
1610.97	330.13
1611.91	330.068
1612.86	337.948
1613.8	335.684
1614.75	329.391
1615.69	335.973
1616.63	330.575
1617.57	332.489
1618.52	335.046
1619.46	334.586
1620.4	338.178
1621.34	334.978
1622.28	338.954
1623.22	339.114
1624.16	349.928
1625.11	345.382
1626.05	331.85
1626.99	337.976
1627.93	337.056
1628.87	337.857
1629.8	336.523
1630.74	336.462
1631.68	330.659
1632.62	336.931
1633.56	336.441
1634.5	339.446
1635.44	342.985
1636.37	334.314
1637.31	342.061
1638.25	340.114
1639.19	341.004
1640.12	337.735
1641.06	348.259
1642	341.048
1642.93	339.469
1643.87	342.508
1644.8	345.548
1645.74	342.855
1646.67	339.175
1647.61	340.113
1648.54	340.587
1649.48	340.905
1650.41	346.662
1651.35	338.477
1652.28	339.705
1653.21	340.518
1654.15	343.72
1655.08	342.545
1656.01	341.898
1656.94	341.547
1657.88	341.405
1658.81	343.521
1659.74	337.317
1660.67	339.531
1661.6	340.903
1662.53	344.135
1663.46	344.39
1664.39	340.35
1665.33	346.319
1666.26	344.747
1667.18	340.662
1668.11	347.387
1669.04	342.829
1669.97	342.916
1670.9	338.095
1671.83	342.585
1672.76	344.607
1673.69	344.905
1674.61	340.63
1675.54	339.481
1676.47	342.432
1677.4	344.56
1678.32	342.699
1679.25	346.395
1680.18	350.993
1681.1	344.736
1682.03	348.278
1682.96	340.694
1683.88	347.351
1684.81	340.171
1685.73	337.418
1686.66	342.551
1687.58	340.851
1688.5	342.437
1689.43	342.533
1690.35	342.472
1691.28	340.556
1692.2	340.548
1693.12	345.436
1694.05	338.997
1694.97	343.003
1695.89	339.42
1696.81	342.679
1697.74	341.656
1698.66	342.078
1699.58	342.101
1700.5	340.447
1701.42	343.901
1702.34	338.358
1703.26	340.269
1704.18	341.805
1705.1	344.935
1705.94	343.731
1706.88	347.105
1707.81	343.71
1708.74	344.042
1709.68	344.748
1710.61	346.005
1711.55	340.133
1712.48	346.263
1713.41	339.006
1714.35	343.373
1715.28	351.516
1716.21	345.436
1717.14	342.447
1718.08	347.656
1719.01	344.748
1719.94	347.122
1720.87	353.209
1721.8	344.958
1722.73	343.468
1723.66	342.554
1724.6	341.262
1725.53	346.072
1726.45	345.384
1727.38	344.963
1728.31	342.497
1729.24	340.288
1730.17	345.88
1731.1	345.235
1732.03	343.63
1732.96	343.501
1733.89	340.711
1734.82	346.133
1735.74	345.195
1736.67	346.548
1737.6	348.752
1738.52	349.772
1739.45	346.082
1740.38	343.38
1741.3	348.816
1742.23	343.765
1743.16	344.52
1744.08	346.59
1745.01	341.004
1745.93	348.2
1746.86	344.495
1747.78	352.756
1748.71	345.962
1749.63	351.809
1750.55	349.763
1751.48	348.556
1752.4	345.095
1753.33	353.072
1754.25	351.209
1755.17	342.218
1756.09	346.514
1757.02	347.821
1757.94	341.098
1758.86	345.746
1759.78	348.077
1760.7	350.617
1761.62	352.151
1762.54	352.073
1763.47	354.059
1764.39	352.544
1765.31	352.602
1766.23	346.52
1767.15	344.69
1768.07	347.805
1768.99	346.331
1769.9	349.809
1770.82	349.041
1771.74	348.326
1772.66	353.239
1773.58	347.57
1774.5	345.617
1775.41	348.961
1776.33	347.329
1777.25	349.395
1778.17	351.578
1779.08	353.19
1780	354.261
1780.92	347.996
1781.83	348.625
1782.75	348.188
1783.66	350.189
1784.58	350.809
1785.49	353.703
1786.41	351.063
1787.32	345.873
1788.24	347.129
1789.15	357.292
1790.07	349.566
1790.98	354.327
1791.89	350.264
1792.81	348.701
1793.72	347.98
1794.63	349.368
1795.54	356.106
1796.46	348.394
1797.37	352.009
1798.28	351.068
1799.19	351
1800.1	347.542
1801.02	351.782
1801.93	358.826
1802.84	355.664
1803.75	353.436
1804.66	355.38
1805.57	352.771
1806.48	351.326
1807.39	352.736
1808.3	351.87
1809.21	353.912
1810.12	351.04
1811.02	351.586
1811.93	353.665
1812.84	356.162
1813.75	344.312
1814.66	353.412
1815.56	351.973
1816.47	350.771
1817.38	351.405
1818.29	353.157
1819.19	359.392
1820.1	359.917
1821.01	352.889
1821.91	355.259
1822.82	354.548
1823.72	353.358
1824.63	355.981
1825.53	357.063
1826.44	356.918
1827.34	358.062
1828.25	358.74
1829.15	349.594
1830.05	356.932
1830.96	356.633
1831.86	358.239
1832.76	363.539
1833.67	360.55
1834.57	359.549
1835.47	357.958
1836.37	361.259
1837.28	357.419
1838.18	356.842
1839.08	354.28
1839.98	362.937
1840.88	356.023
1841.78	355.923
1842.68	356.73
1843.58	367.349
1844.48	360.137
1845.38	360.366
1846.28	355.93
1847.18	363.836
1848.08	363.196
1848.98	363.745
1849.88	359.809
1850.78	368.53
1851.68	363.728
1852.57	360.992
1853.47	358.071
1854.37	361.701
1855.27	363.454
1856.16	359.101
1857.06	356.46
1857.96	361.82
1858.86	361.664
1859.75	363.447
1860.65	369.16
1861.54	362.92
1862.44	370.2
1863.33	364.481
1864.23	368.51
1865.12	366.833
1866.02	363.616
1866.91	363.604
1867.81	363.36
1868.7	368.483
1869.59	363.966
1870.49	362.139
1871.38	366.408
1872.27	363.236
1873.17	364.277
1874.06	366.209
1874.95	366.695
1875.84	367.651
1876.74	361.55
1877.63	360.76
1878.52	372.219
1879.41	368.666
1880.3	371.646
1881.19	367.191
1882.08	357.058
1882.97	373.568
1883.86	367.052
1884.75	371.096
1885.64	361.475
1886.53	366.31
1887.42	369.358
1888.31	363.606
1889.2	363.957
1890.09	364.22
1890.98	366.772
1891.86	365.404
1892.75	366.253
1893.64	366.11
1894.53	371.495
1895.41	365.055
1896.3	365.639
1897.19	375.595
1898.07	369.882
1898.96	362.074
1899.85	363.476
1900.73	373.498
1901.62	362.773
1902.5	376.422
1903.39	365.767
1904.27	363.98
1905.16	373.937
1906.04	368.659
1906.92	372.073
1907.81	369.014
1908.69	374.594
1909.58	371.385
1910.46	372.492
1911.34	371.748
1912.23	375.504
1913.11	370.58
1913.99	366.401
1914.87	371.619
1915.75	370.283
1916.64	370.477
1917.52	369.073
1918.4	372.176
1919.28	372.847
1920.16	364.476
1921.04	371.05
1921.92	371.278
1922.8	372.231
1923.68	371.199
1924.56	371.62
1925.44	372.888
1926.32	374.28
1927.2	373.178
1928.08	368.178
1928.95	370.677
1929.83	372.216
1930.64	374.437
1931.53	373.391
1932.43	369.233
1933.32	371.042
1934.21	373.147
1935.1	375.292
1935.99	372.321
1936.89	374.853
1937.78	373.048
1938.67	393.297
1939.56	379.889
1940.45	376.078
1941.34	369.833
1942.23	370.711
1943.12	374.643
1944.01	380.888
1944.9	378.355
1945.79	378.725
1946.68	375.479
1947.57	371.408
1948.46	376.617
1949.35	371.18
1950.23	372.926
1951.12	375.104
1952.01	373.971
1952.9	375.077
1953.79	377.278
1954.67	373.678
1955.56	376.516
1956.45	373.142
1957.33	373.134
1958.22	375.196
1959.1	376.626
1959.99	375.476
1960.88	375.97
1961.76	368.478
1962.65	380.981
1963.53	370.337
1964.42	376.108
1965.3	382.961
1966.19	376.048
1967.07	374.218
1967.95	380.599
1968.84	374.404
1969.72	377.226
1970.6	375.553
1971.49	376.777
1972.37	371.533
1973.25	376.13
1974.13	377.231
1975.02	373.81
1975.9	377.464
1976.78	373.266
1977.66	379.518
1978.54	373.467
1979.42	369.142
1980.3	375.014
1981.18	375.745
1982.06	375.057
1982.94	376.041
1983.82	373.463
1984.7	374.223
1985.58	376.536
1986.46	375.015
1987.34	374.384
1988.22	375.017
1989.1	376.171
1989.98	375.79
1990.85	376.821
1991.73	374.081
1992.61	382.707
1993.49	376.473
1994.36	374.452
1995.24	376.602
1996.12	378.326
1996.99	370.646
1997.87	372.579
1998.75	380.528
1999.62	374.166
2000.5	371.645
2001.37	382.222
2002.25	379.348
2003.12	373.93
2004	375.226
2004.87	378.597
2005.75	377.263
2006.62	375.735
2007.5	369.267
2008.37	380.386
2009.24	381.595
2010.12	379.276
2010.99	376.17
2011.86	370.923
2012.73	377.271
2013.61	384.716
2014.48	375.149
2015.35	378.059
2016.22	377.812
2017.09	374.798
2017.96	379.016
2018.84	379.886
2019.71	371.505
2020.58	375.479
2021.45	373.187
2022.32	375.596
2023.19	371.74
2024.06	384.252
2024.93	373.653
2025.8	374.568
2026.67	380.268
2027.53	380.739
2028.4	374
2029.27	382.61
2030.14	372.908
2031.01	379.168
2031.87	374.242
2032.74	374.399
2033.61	375.21
2034.48	376.589
2035.34	384.827
2036.21	377.26
2037.08	375.668
2037.94	379.199
2038.81	380.268
2039.67	384.007
2040.54	374.843
2041.41	378.617
2042.27	378.146
2043.13	376.613
2044	377.338
2044.86	371.613
2045.73	377.537
2046.59	386.316
2047.46	382.947
2048.32	382.711
2049.18	379.011
2050.05	376.58
2050.91	378.548
2051.77	379.782
2052.63	378.549
2053.49	378.065
2054.36	376.105
2055.22	381.644
2056.08	378.592
2056.94	375.713
2057.8	380.953
2058.66	380.086
2059.52	378.813
2060.39	380.906
2061.24	383.012
2062.1	380.007
2062.97	385.758
2063.83	377.401
2064.68	386.721
2065.54	387.065
2066.4	381.905
2067.26	383.939
2068.12	382.033
2068.98	381.351
2069.84	381.667
2070.69	384.456
2071.55	376.773
2072.41	380.964
2073.27	383.64
2074.12	386.807
2074.98	379.025
2075.84	378.63
2076.69	384.071
2077.55	385.451
2078.4	381.375
2079.26	384.785
2080.11	388.242
2080.97	381.142
2081.82	392.063
2082.68	385.674
2083.53	387.487
2084.39	390.909
2085.24	383.238
2086.1	383.651
2086.95	383.342
2087.8	387.376
2088.66	382.529
2089.51	386.732
2090.36	389.052
2091.22	391.66
2092.07	386.449
2092.92	387.33
2093.77	390.73
2094.62	387.846
2095.47	384.679
2096.33	388.508
2097.18	388.199
2098.03	384.647
2098.88	384.342
2099.73	384.805
2100.58	387.183
2101.43	392.889
2102.28	392.859
2103.13	392.403
2103.98	390.981
2104.83	384.728
2105.67	385.939
2106.52	393.909
2107.37	393.997
2108.22	392.778
2109.07	392.487
2109.92	388.979
2110.76	387.591
2111.61	395.933
2112.46	391.453
2113.31	389.929
2114.15	392.327
2115	400.156
2115.84	393.086
2116.69	391.428
2117.54	391.893
2118.38	388.577
2119.23	390.932
2120.07	397.838
2120.92	395.318
2121.76	398.86
2122.61	394.4
2123.45	395.821
2124.29	399.419
2125.14	391.895
2125.98	389.745
2126.83	393.444
2127.67	395.753
2128.51	387.62
2129.35	396.913
2130.2	395.124
2131.04	395.834
2131.88	394.158
2132.72	399.076
2133.57	396.798
2134.41	394.809
2135.25	390.714
2136.09	396.629
2136.93	396.491
2137.77	401.674
2138.61	393.22
2139.45	398.401
2140.29	396.295
2141.13	398.109
2141.97	397.27
2142.81	396.071
2143.65	396.369
2144.49	396.749
2145.33	397.748
2146.16	404.134
2147.01	398.947
2147.86	400.432
2148.72	397.532
2149.57	399.596
2150.42	399.227
2151.27	394.47
2152.12	396.622
2152.98	396.911
2153.83	396.22
2154.68	415.287
2155.53	399.6
2156.38	405.764
2157.23	404.386
2158.08	395.483
2158.93	405.006
2159.78	400.751
2160.63	399.835
2161.48	400.469
2162.33	395.98
2163.18	394.126
2164.03	395.206
2164.88	398.459
2165.73	399.769
2166.58	403.052
2167.42	400.29
2168.27	398.463
2169.12	394.572
2169.97	397.235
2170.81	396.727
2171.66	400.23
2172.51	408.488
2173.35	396.151
2174.2	401.845
2175.05	403.144
2175.89	403.715
2176.74	401.788
2177.58	399.504
2178.43	403.483
2179.27	399.502
2180.12	401.346
2180.96	401.48
2181.81	402.821
2182.65	395.286
2183.5	399.548
2184.34	400.962
2185.18	401.238
2186.03	399.955
2186.87	407.771
2187.71	402.69
2188.56	398.695
2189.4	405.039
2190.24	401.7
2191.08	394.664
2191.93	397.059
2192.77	398.38
2193.61	404.202
2194.45	398.593
2195.29	401.705
2196.13	401.437
2196.97	402.914
2197.81	401.785
2198.65	404.305
2199.49	399.771
2200.33	402.621
2201.17	399.219
2202.01	399.794
2202.85	409.591
2203.69	398.865
2204.53	401.677
2205.37	396.414
2206.21	408.377
2207.04	400.519
2207.88	397.404
2208.72	402.073
2209.56	401.128
2210.4	401.274
2211.23	400.557
2212.07	400.312
2212.91	403.362
2213.74	402.157
2214.58	403.727
2215.41	395.355
2216.25	401.598
2217.09	402.614
2217.92	399.647
2218.76	398.813
2219.59	401.81
2220.43	402.568
2221.26	400.884
2222.1	405.106
2222.93	401.478
2223.76	404.169
2224.6	404.482
2225.43	410.883
2226.26	408.985
2227.1	410.708
2227.93	408.157
2228.76	400.757
2229.6	405.612
2230.43	401.455
2231.26	403.597
2232.09	404.12
2232.92	408.894
2233.76	402.99
2234.59	410.209
2235.42	409.522
2236.25	409.148
2237.08	402.519
2237.91	406.058
2238.74	408.414
2239.57	409.385
2240.4	413.47
2241.23	402.254
2242.06	409.318
2242.89	408.16
2243.72	403.268
2244.54	405.433
2245.37	409.292
2246.2	412.799
2247.03	419.505
2247.86	407.748
2248.68	408.397
2249.51	409.444
2250.34	416.961
2251.17	413.605
2251.99	403.461
2252.82	416.651
2253.65	410.652
2254.47	407.412
2255.3	412.129
2256.12	413.392
2256.95	410.784
2257.77	408.951
2258.6	409.593
2259.42	407.9
2260.25	416.45
2261.07	407.094
2261.9	411.654
2262.72	411.134
2263.54	417.362
2264.37	415.336
2265.19	409.966
2266.02	413.718
2266.84	410.893
2267.66	412.278
2268.48	419.61
2269.31	412.932
2270.13	418.05
2270.95	414.979
2271.77	421.019
2272.59	418.809
2273.42	418.548
2274.24	415.899
2275.06	415.965
2275.88	411.943
2276.7	409.721
2277.52	417.494
2278.34	419.733
2279.16	411.965
2279.98	416.8
2280.8	417.831
2281.62	416.206
2282.44	428.908
2283.25	415.583
2284.07	411.856
2284.89	419.379
2285.71	417.148
2286.53	413.322
2287.35	417.436
2288.16	421.138
2288.98	411.738
2289.8	418.735
2290.61	419.857
2291.43	421.043
2292.25	415.178
2293.06	416.074
2293.88	411.688
2294.7	414.763
2295.51	422.432
2296.33	418.363
2297.14	418.791
2297.96	415.652
2298.77	418.681
2299.59	411.727
2300.4	420.244
2301.22	422.097
2302.03	420.851
2302.84	419.115
2303.66	414.2
2304.47	425.636
2305.28	427.315
2306.1	415.736
2306.91	416.301
2307.72	419.662
2308.53	421.615
2309.35	416.547
2310.16	425.162
2310.97	418.391
2311.78	413.513
2312.59	417.521
2313.4	420.931
2314.22	421.981
2315.03	423.503
2315.84	416.531
2316.65	418.629
2317.46	418.98
2318.27	418.57
2319.08	419.305
2319.89	420.984
2320.69	421.553
2321.5	420.309
2322.31	420.455
2323.12	421.464
2323.93	424.777
2324.74	420.152
2325.55	415.972
2326.35	418.465
2327.16	430.146
2327.97	442.361
2328.78	431.906
2329.58	425.882
2330.39	430.679
2331.2	420.282
2332	427.399
2332.81	424.937
2333.61	429.353
2334.42	426.472
2335.23	424.604
2336.03	425.933
2336.84	424.912
2337.64	421.905
2338.45	425.76
2339.25	427.921
2340.05	426.397
2340.86	424.321
2341.66	425.32
2342.47	425.526
2343.27	424.225
2344.07	425.856
2344.87	426.831
2345.68	425.119
2346.48	427.069
2347.28	428.932
2348.08	427.361
2348.89	430.055
2349.69	430.162
2350.49	425.971
2351.29	426.356
2352.09	432.525
2352.89	427.809
2353.71	429.928
2354.52	425.492
2355.34	433.653
2356.15	425.217
2356.96	429.795
2357.78	431.7
2358.59	427.18
2359.41	427.456
2360.22	428.839
2361.03	428.611
2361.85	431.002
2362.66	433.335
2363.47	435.87
2364.29	425.409
2365.1	431.874
2365.91	433.759
2366.72	434.265
2367.54	430.335
2368.35	427.747
2369.16	433.738
2369.97	432.507
2370.78	434.379
2371.59	429.878
2372.4	443.24
2373.21	429.755
2374.02	432.991
2374.83	437.914
2375.64	432.657
2376.45	432.948
2377.26	430.992
2378.07	434.89
2378.88	435.393
2379.69	434.272
2380.5	434.177
2381.31	431.84
2382.12	439.853
2382.92	433.524
2383.73	441.823
2384.54	431.932
2385.35	436.77
2386.15	442.519
2386.96	433.848
2387.77	436.836
2388.57	434.324
2389.38	435.391
2390.19	432.711
2390.99	432.718
2391.8	440.337
2392.6	434.455
2393.41	437.913
2394.22	438.351
2395.02	436.163
2395.83	434.342
2396.63	439.473
2397.44	433.153
2398.24	435.395
2399.04	430.825
2399.85	436.942
2399.98	435.797