File: Data/3-Raman/raw/bu04w-a-ff3-fi10-v_150 (500nm)_633nm_edge_100%_x100_vis_lwd_h50um_45sx2_01.txt
#Acq. time (s)=	45
#Accumulations=	2
#Range (cm-¹)=	100...4000
#Windows=	1
#Auto scanning=	Off
#Autofocus=	Off
#Macrospot=	Off
#AutoExposure=	Off
#Spike filter=	Multiple accum.
#Delay time (s)=	2
#Binning=	1
#Readout mode=	Signal
#DeNoise=	Off
#ICS correction=	On
#Dark correction=	Off
#Inst. Process=	Off
#Detector Gain=	Best Dynamic
#Detector ADC=	50 kHz EM
#Detector EM gain=	100
#Detector temperature (°C)=	-60.09
#Instrument=	LabRAM HR Evol
#Detector=	SIN-EM FIVIS
#Objective=	x100_VIS_LWD
#Grating=	150 (500nm)
#ND Filter=	100%
#Laser=	633nm_Edge
#Hole=	49.98
#Temperature=	0
#Range=	Visible
#StageXY=	75x50mm Scan+
#StageZ=	Z motor
#X (µm)=	0
#Y (µm)=	0
#Z (µm)=	4.4
#Full time(mm:ss)=	1:34
#Project=	21_11_22
#Sample=	BU04w
#Site=
#Title=	BU04w-A-FF3-FI10-V_150 (500nm)_633nm_Edge_100%_x100_VIS_LWD_H50um_45sX2
#Remark=
#Date=	22.11.2021 11:50
#Acquired=	22.11.2021 11:50:46
100.177	1321.05
106.695	1229.58
113.209	1084.74
119.717	1001.49
126.219	944.792
132.716	916.587
139.208	958.798
145.694	908.24
152.175	851.034
158.651	906.096
165.121	1129.96
171.586	830.229
178.045	671.883
184.5	634.913
190.947	610.062
197.39	578.602
203.829	553.554
210.262	555.259
216.688	571.263
223.11	589.084
229.527	797.767
235.939	1086.91
242.344	887.348
248.745	697.161
255.141	674.858
261.53	647.038
267.916	611.746
274.294	628.766
280.669	636.294
287.038	699.529
293.402	631.729
299.76	574.426
306.114	613.577
312.461	746.21
318.805	943.799
325.142	1515.26
331.475	1597.01
337.802	1032.68
344.123	771.255
350.441	640.835
356.752	651.622
363.058	671.681
369.36	711.399
375.656	634.599
381.947	542.989
388.232	572.99
394.512	547.335
400.789	593.672
407.059	619.426
413.324	629.083
419.584	699.001
425.839	794.692
432.089	980.816
438.333	1003.9
444.573	791.895
450.807	769.897
457.037	824.853
463.261	709.639
469.48	610.237
475.695	576.585
481.904	576.715
488.108	569.315
494.307	599.282
500.502	605.94
506.691	706.984
512.874	787.738
519.053	721.3
525.227	718.818
531.396	688.598
537.559	623.721
543.718	622.183
549.873	562.391
556.022	558.131
562.165	542.56
568.304	509.537
574.437	511.857
580.567	484.898
586.691	475.243
592.81	502.447
598.924	590.643
605.033	550.339
611.138	535.436
617.236	547.144
623.332	521.573
629.42	527.774
635.506	500.886
641.585	506.162
647.659	517.506
653.73	539.905
659.794	544.08
665.854	528.655
671.91	475.476
677.96	441.1
684.005	434.739
690.045	440.062
696.082	419.524
702.113	427.932
708.139	432.438
714.16	443.677
720.176	444.338
726.187	429.903
732.194	417.899
738.196	407.789
744.193	400.573
750.185	432.712
756.173	409.177
762.155	423.684
768.133	409.847
774.107	419.482
780.075	404.475
786.039	422.03
791.998	421.506
797.952	412.179
803.902	424.152
809.845	430.255
815.786	432.267
821.721	424.707
827.652	423.642
833.576	432.536
839.498	426.279
845.415	410.216
851.327	427.98
857.233	439.401
863.135	419.852
869.032	456.012
874.925	448.313
880.813	455.366
886.697	442.219
892.576	467.659
898.45	462.393
904.318	453.746
910.184	454.457
916.044	493.738
921.9	474.353
927.75	521.358
933.596	558.724
939.439	639.672
945.275	715.886
951.107	888.024
956.936	908.386
962.759	801.854
968.577	762.267
974.391	788.115
980.201	902.936
986.006	1048.28
991.806	1147.88
997.602	989.246
1003.39	877.332
1009.18	876.901
1014.96	935.005
1020.74	1052.46
1026.51	1169.56
1032.28	963.374
1038.04	709.325
1043.8	631.377
1049.56	597.366
1055.31	562.691
1061.05	553.662
1066.8	530.324
1072.53	518.522
1078.26	581.23
1083.99	612.666
1089.72	687.798
1095.44	912.963
1101.15	1002.32
1106.86	784.935
1112.56	621.875
1118.27	556.928
1123.96	529.07
1129.65	525.452
1135.34	518.944
1141.03	588.956
1146.7	737.416
1152.38	996.326
1158.05	1087.85
1163.71	710.725
1169.37	559.291
1175.03	474.95
1180.68	444.721
1186.33	425.784
1191.98	453.194
1197.61	428.358
1203.25	429.535
1208.88	403.523
1214.51	421.919
1220.13	409.968
1225.74	421.931
1231.36	423.843
1236.97	435.492
1242.57	419.498
1248.17	448.381
1253.77	468.834
1259.36	496.818
1264.94	477.964
1270.53	449.062
1276.11	529.505
1281.68	1203
1287.25	438.341
1292.81	448.836
1298.38	425.718
1303.93	436.89
1309.48	436.641
1315.03	422.917
1320.58	425.352
1326.12	401.7
1331.65	430.761
1337.18	405.768
1342.71	413.043
1348.23	423.109
1353.75	432.056
1359.26	436.649
1364.77	458.401
1370.28	455.197
1375.78	474.544
1381.28	932.26
1386.77	949.259
1392.26	469.915
1397.74	475.572
1403.23	493.702
1408.7	466.703
1414.17	457.305
1419.64	424.199
1425.11	419.038
1430.56	414.926
1436.02	427.445
1441.47	419.059
1446.92	412.778
1452.36	413.382
1457.8	416.835
1463.23	401.129
1468.66	407.319
1474.09	411.433
1479.51	397.903
1484.93	398.118
1490.34	423.771
1495.75	425.512
1501.16	421.067
1506.56	425.202
1511.96	408.335
1517.35	424.508
1522.74	427.001
1528.13	404.924
1533.51	419.368
1538.88	427.136
1544.25	443.265
1549.62	419.732
1554.99	408.591
1560.35	417.807
1565.71	415.242
1571.06	429.881
1576.41	429.504
1581.75	425.2
1587.09	446.856
1592.43	429.909
1597.76	420.715
1603.09	413.826
1608.41	420.177
1613.73	437.787
1619.05	427.445
1624.36	436.747
1629.67	443.882
1634.97	439.838
1640.27	432.867
1645.57	441.297
1650.86	438.534
1656.15	443.357
1661.43	450.177
1666.71	435.841
1671.99	417.004
1677.26	433.574
1682.53	441.185
1687.79	434.135
1693.05	436.115
1698.31	435.207
1703.56	426.919
1708.81	422.109
1714.06	430.367
1719.3	420.404
1724.53	447.917
1729.77	435.39
1735	444.152
1740.22	433.739
1745.44	451.499
1750.66	435.199
1755.87	451.522
1761.08	420.021
1766.29	437.174
1771.49	421.565
1776.69	429.847
1781.88	427.043
1787.07	422.091
1792.26	442.417
1797.44	438.885
1802.62	453.846
1807.79	444.717
1812.96	452.582
1818.13	457.04
1823.29	448.776
1828.45	447.485
1833.61	435.779
1838.76	449.626
1843.91	442.283
1849.05	459.374
1854.19	464.652
1859.33	458.383
1864.46	453.405
1869.59	456.704
1874.71	454.999
1879.83	463.828
1884.95	463.146
1890.06	453.972
1895.17	461.086
1900.28	444.761
1905.38	441.999
1910.48	463.217
1915.57	448.073
1920.66	447.61
1925.75	478.342
1930.83	468.49
1935.91	474.13
1940.99	466.413
1946.06	469.349
1951.13	479.364
1956.19	465.108
1961.26	457.991
1966.31	453.193
1971.36	463.833
1976.41	470.795
1981.46	459.696
1986.5	485.924
1991.54	446.068
1996.58	465.209
2001.61	465.244
2006.63	465.448
2011.66	480.24
2016.68	456.537
2021.69	462.823
2026.71	486.288
2031.72	461.68
2036.72	468.622
2041.72	462.271
2046.72	464.475
2051.71	464.278
2056.71	468.702
2061.69	491.768
2066.68	491.664
2071.66	477.957
2076.63	498.648
2081.6	494.654
2086.57	464.519
2091.54	478.808
2096.5	473.635
2101.46	503.332
2106.41	468.504
2111.36	496.077
2116.31	471.298
2121.25	500.415
2126.19	506.937
2131.13	503.267
2136.06	498.162
2140.99	481.486
2145.92	487.567
2150.84	492.158
2155.76	473.608
2160.67	505.973
2165.58	480.653
2170.49	479.528
2175.39	511.895
2180.29	501.839
2185.19	477.457
2190.08	476.252
2194.98	493.161
2199.86	484.721
2204.74	473.906
2209.62	501.835
2214.5	487.46
2219.37	522.292
2224.24	493.815
2229.11	488.576
2233.97	501.542
2238.83	504.116
2243.68	483.13
2248.53	500.127
2253.38	521.103
2258.22	506.607
2263.06	518.431
2267.9	522.108
2272.73	513.633
2277.56	495.654
2282.39	521.313
2287.21	517.471
2292.03	517.614
2296.85	496.48
2301.66	511.538
2306.47	502.907
2311.28	506.547
2316.08	511.72
2320.88	494.227
2325.68	578.992
2330.47	503.624
2335.26	518.707
2340.04	517.624
2344.82	486.68
2349.6	504.878
2354.38	523.037
2359.15	560.251
2363.92	522.713
2368.68	540.442
2373.44	523.542
2378.2	537.079
2382.95	518.379
2387.71	532.759
2392.45	524.669
2397.2	510.821
2401.94	528.922
2406.68	530.194
2411.41	537.696
2416.14	528.237
2420.87	518.204
2425.59	542.851
2430.31	521.643
2435.03	538.666
2439.75	543.15
2444.46	551.874
2449.16	532.138
2453.87	539.433
2458.57	539.574
2463.27	536.824
2467.96	551.293
2472.65	578.743
2477.34	533.843
2482.02	549.744
2486.7	550.953
2491.38	565.229
2496.05	575.203
2500.72	564.591
2505.39	553.846
2510.06	559.122
2514.72	577.529
2519.37	560.616
2524.03	542.32
2528.68	560.894
2533.33	584.055
2537.97	567.356
2542.61	574.468
2547.25	542.919
2551.88	579.987
2556.51	566.169
2561.14	567.287
2565.77	571.632
2570.39	547.466
2575.01	559.465
2579.62	563.755
2584.23	566.195
2588.84	559.267
2593.45	579.476
2598.05	556.009
2602.65	585.751
2607.24	595.601
2611.84	568.619
2616.42	564.479
2621.01	554.268
2625.59	591.626
2630.17	584.805
2634.75	578.428
2639.32	558.6
2643.89	597.505
2648.46	594.771
2653.02	585.726
2657.58	574.367
2662.14	603.429
2666.69	594.768
2671.24	589.554
2675.79	592.809
2680.33	614.697
2684.88	588.916
2689.41	589.971
2693.95	596.997
2698.48	599.542
2703.01	596.016
2707.53	600.367
2712.06	588.498
2716.57	599.502
2721.09	603.876
2725.6	617.781
2730.11	610.401
2734.62	623.898
2739.12	588.52
2743.62	597.36
2748.12	622.723
2752.61	601.567
2757.1	616.029
2761.59	608.729
2766.08	623.031
2770.56	630.782
2775.04	605.78
2779.51	630.608
2783.98	594.558
2788.45	633.229
2792.92	621.87
2797.38	611.891
2801.84	645.361
2806.3	614.735
2810.75	620.968
2815.2	642.244
2819.65	604.282
2824.09	640.885
2828.53	614.774
2832.97	631.002
2837.41	642.097
2841.84	619.148
2846.27	615.063
2850.69	650.464
2855.12	652.029
2859.54	643.33
2863.95	633.086
2868.37	612.594
2872.78	643.985
2877.18	630.342
2881.59	651.692
2885.99	636.518
2890.39	656.302
2894.78	640.822
2899.18	636.158
2903.57	661.418
2907.95	672.333
2912.34	661.547
2916.72	657.622
2921.09	630.506
2925.47	675.398
2929.84	661.116
2934.21	691.94
2938.57	640.787
2942.94	661.988
2947.29	670.264
2951.65	691.307
2956	677.679
2960.36	693.266
2964.7	690.678
2969.05	690.071
2973.39	684.004
2977.73	681.606
2982.06	694.039
2986.4	699.431
2990.73	675.336
2995.05	723.756
2999.38	666.261
3003.7	677.822
3008.01	708.307
3012.33	734.988
3016.64	743.211
3020.95	715.562
3025.26	719.768
3029.56	704.488
3033.86	732.892
3038.16	736.084
3042.45	749.242
3046.74	723.635
3051.03	721.012
3055.32	728.081
3059.6	706.181
3063.88	742.305
3068.16	730.02
3072.43	754.637
3076.7	752.136
3080.97	737.922
3085.24	782.481
3089.5	760.908
3093.76	743.502
3098.02	779.498
3102.27	766.247
3106.52	796.884
3110.77	748.101
3115.01	793.094
3119.26	826.389
3123.5	809.716
3127.73	809.298
3131.97	894.765
3136.2	813.093
3140.43	847.693
3144.65	859.535
3148.87	881.593
3153.09	869.915
3157.31	851.637
3161.52	889.751
3165.73	888.103
3169.94	955.604
3174.15	882.299
3178.35	915.678
3182.55	944.572
3186.75	945.771
3190.94	951.059
3195.13	899.53
3199.32	872.023
3203.51	922.258
3207.69	955.914
3211.87	972.709
3216.05	911.946
3220.22	987.439
3224.39	917.143
3228.56	947.15
3232.73	911.224
3236.89	934.261
3241.05	906.898
3245.21	906.424
3249.36	938.888
3253.52	905.676
3257.66	889.746
3261.81	903.977
3265.95	871.293
3270.1	920.704
3274.23	910.826
3278.37	905.747
3282.5	898.413
3286.63	920.9
3290.76	867.453
3294.88	852.853
3299	861.299
3303.12	897.804
3307.24	911.182
3311.35	915.166
3315.46	881.91
3319.57	916.244
3323.68	873.988
3327.78	894.991
3331.88	900.106
3335.98	891.547
3340.07	880.093
3344.16	886.757
3348.25	928.661
3352.34	935.142
3356.42	863.1
3360.5	912.818
3364.58	926.837
3368.66	854.385
3372.73	884.978
3376.8	912.898
3380.87	938.303
3384.93	864.65
3388.99	892.277
3393.05	902.891
3397.11	884.768
3401.16	864.164
3405.21	923.275
3409.26	919.316
3413.31	917.56
3417.35	913.43
3421.39	916.537
3425.43	895.22
3429.46	910.815
3433.5	907.113
3437.53	893.868
3441.55	902.837
3445.58	941.663
3449.6	946.525
3453.62	889.723
3457.64	900.023
3461.65	893.212
3465.66	911.354
3469.67	891.951
3473.68	899.407
3477.68	929.892
3481.68	914.996
3485.68	930.309
3489.67	907.457
3493.67	925.167
3497.66	942.618
3501.64	906.13
3505.63	923.023
3509.61	947.127
3513.59	914.361
3517.57	920.047
3521.54	930.853
3525.52	923.771
3529.49	926.882
3533.45	889.504
3537.42	922.371
3541.38	898.582
3545.34	907.965
3549.29	904.121
3553.25	912.364
3557.2	905.374
3561.15	909.099
3565.09	897.476
3569.04	904.691
3572.98	914.36
3576.92	921.777
3580.85	900.637
3584.79	916.542
3588.72	913.948
3592.64	948.488
3596.57	900.62
3600.49	945.734
3604.41	881.164
3608.33	918.027
3612.25	927.946
3616.16	908.259
3620.07	936.898
3623.98	916.141
3627.88	914.029
3631.79	903.563
3635.69	906.767
3639.58	910.512
3643.48	898.633
3647.37	927.856
3651.26	917.548
3655.15	937.565
3659.03	932.952
3662.92	922.728
3666.8	912.68
3670.67	910.868
3674.55	939.362
3678.42	905.339
3682.29	912.817
3686.16	895.962
3690.02	942.71
3693.89	903.708
3697.75	936.61
3701.61	936.366
3705.46	938.786
3709.31	913.398
3713.16	946.789
3717.01	951.8
3720.86	925.553
3724.7	947.068
3728.54	940.199
3732.38	933.441
3736.21	932.384
3740.04	945.437
3743.87	932.704
3747.7	939.78
3751.53	938.028
3755.35	947.443
3759.17	950.887
3762.99	945.608
3766.81	931.687
3770.62	946.731
3774.43	959.053
3778.24	928.354
3782.04	946.838
3785.85	948.338
3789.65	935.222
3793.45	959.753
3797.24	978.985
3801.04	931.652
3804.83	942.419
3808.62	976.685
3812.4	964.148
3816.19	945.584
3819.97	962.096
3823.75	952.04
3827.52	947.629
3831.3	981.791
3835.07	948.178
3838.84	970.453
3842.61	939.784
3846.37	1003.23
3850.13	968.228
3853.89	980.615
3857.65	983.915
3861.41	975.107
3865.16	985.018
3868.91	954.615
3872.66	979.547
3876.4	986.134
3880.14	962.828
3883.89	963.546
3887.62	961.456
3891.36	983.506
3895.09	997.27
3898.82	1004.83
3902.55	970.249
3906.28	989.749
3910	969.959
3913.73	989.781
3917.45	973.516
3921.16	1006.21
3924.88	996.418
3928.59	983.291
3932.3	985.162
3936.01	980.482
3939.71	991.202
3943.42	1033.2
3947.12	1007.44
3950.81	1012.19
3954.51	1016.67
3958.2	1017.88
3961.9	981.527
3965.58	988.382
3969.27	994.854
3972.96	970.369
3976.64	1017.21
3980.32	989.397
3984	1017.2
3987.67	1032.63
3991.34	1020.39
3995.01	1002.33
3998.68	1000.15