File: Data/3-Raman/raw/bu19(2)w-a-ff1-fi04-l_150 (500nm)_532nm_edge_100%_x100_vis_lwd_h50um_30sx2_01.txt
#Acq. time (s)=	30
#Accumulations=	2
#Range (cm-¹)=	99...4000
#Windows=	1
#Auto scanning=	Off
#Autofocus=	Off
#Macrospot=	Off
#AutoExposure=	Off
#Spike filter=	Multiple accum.
#Delay time (s)=	2
#Binning=	1
#Readout mode=	Signal
#DeNoise=	Off
#ICS correction=	On
#Dark correction=	Off
#Inst. Process=	Off
#Detector Gain=	Best Dynamic
#Detector ADC=	50 kHz HS
#Detector temperature (°C)=	-60.09
#Instrument=	LabRAM HR Evol
#Detector=	SIN-EM FIVIS
#Objective=	x100_VIS_LWD
#Grating=	150 (500nm)
#ND Filter=	100%
#Laser=	532nm_Edge
#Hole=	49.98
#Temperature=	0
#Range=	Visible
#StageXY=	75x50mm Scan+
#StageZ=	Z motor
#X (µm)=	0
#Y (µm)=	0
#Z (µm)=	-14.5
#Full time(mm:ss)=	1:04
#Project=	21_11_26
#Sample=	BU19(2)w
#Site=
#Title=	BU19(2)w-A-FF1-FI04-L_150 (500nm)_532nm_Edge_100%_x100_VIS_LWD_H50um_30sX2
#Remark=
#Date=	26.11.2021 13:24
#Acquired=	26.11.2021 13:24:10
102.91	7712.96
107.534	9100.01
112.156	9235.21
116.775	8071.18
121.392	6725.45
126.005	6474.85
130.617	6987.17
135.227	8735.32
139.835	12081.7
144.439	15975
149.042	15911.1
153.643	12012.6
158.242	8378.12
162.839	6306.68
167.431	5192.4
172.023	4493.56
176.613	3969.78
181.198	3686.58
185.783	3413.52
190.366	3267.88
194.947	3274.02
199.524	3601.92
204.1	4818.99
208.674	6512.68
213.243	5069.02
217.813	3318.63
222.38	2925.88
226.945	3449.97
231.506	4965.47
236.066	5274.62
240.625	3525.53
245.179	2423.57
249.732	1996.08
254.284	1867.56
258.831	1795.23
263.378	1735.22
267.923	1689.93
272.464	1665.38
277.004	1777.97
281.54	1882.37
286.076	1591.43
290.61	1462.78
295.139	1400.25
299.669	1411.89
304.196	1394.39
308.718	1465.29
313.241	1533.3
317.759	1630.19
322.278	1816.39
326.794	2303.72
331.305	2905.27
335.817	3064.22
340.324	2733.82
344.832	2802.35
349.334	3282.07
353.837	3191.53
358.338	2515.17
362.834	2069.19
367.33	1974.6
371.822	1982.77
376.314	2224.43
380.802	2618.66
385.289	3814.94
389.772	5682.2
394.255	6675.19
398.734	5892.71
403.213	4977.64
407.688	4264.26
412.162	3736.14
416.632	3633.56
421.102	3841.28
425.568	4258.42
430.033	4439.27
434.495	4357.1
438.956	4270.04
443.413	4554.35
447.87	4986.95
452.323	4926.96
456.776	4266.64
461.224	3249.02
465.673	2608.93
470.117	2230.66
474.561	2086.57
479.001	2184.99
483.438	2383.5
487.876	2796.52
492.309	3543.41
496.742	4662.33
501.172	6123.21
505.601	7737.73
510.025	8439.76
514.448	7992.17
518.871	6934.62
523.289	5979.09
527.707	5254.88
532.121	4912.86
536.533	4855.04
540.945	4930.53
545.353	5037.15
549.758	4933.02
554.164	4612.18
558.565	4122.46
562.965	3602.05
567.364	3136.67
571.759	2721.93
576.151	2466.34
580.544	2372.13
584.933	2394.63
589.319	2680.4
593.706	3036.6
598.088	3505.59
602.468	4125.54
606.848	5331.8
611.224	7807.98
615.598	12692.6
619.972	16295
624.341	12995.5
628.709	7989.86
633.074	4977.85
637.44	3501.68
641.801	2640.23
646.16	2178.71
650.517	1883.31
654.874	1627.17
659.227	1455.11
663.578	1321.21
667.927	1209.03
672.275	1153.73
676.62	1092.73
680.962	1097.22
685.302	1135.06
689.643	1171.41
693.979	1264.16
698.313	1448.2
702.645	1582.67
706.975	1530.85
711.305	1390.63
715.631	1208.86
719.955	1128.74
724.276	1100.78
728.596	1051.09
732.913	965.604
737.231	928.406
741.544	886.017
745.856	859.587
750.165	844.402
754.472	847.262
758.778	810.812
763.081	814.996
767.384	837.665
771.683	790.21
775.98	821.874
780.275	826.427
784.568	833.468
788.859	865.458
793.147	895.417
797.434	866.348
801.719	908.197
806.004	939.676
810.284	958.301
814.563	1004.58
818.839	1106.04
823.114	1271.35
827.386	1434.95
831.657	1704.62
835.925	2080.47
840.192	2365.08
844.456	2572.47
848.719	2502.05
852.979	2239.37
857.237	2070.67
861.493	1921.91
865.748	1701.43
870	1621.54
874.25	1724.9
878.499	1830.81
882.745	1733.44
886.989	1409.6
891.231	1179.12
895.471	1011.42
899.71	913.486
903.946	848.026
908.18	820.411
912.412	774.527
916.642	769.264
920.87	763.849
925.096	767.859
929.321	776.785
933.543	760.857
937.763	775.994
941.981	761.95
946.197	741.434
950.412	771.121
954.622	762.556
958.832	781.771
963.04	795.727
967.246	809.736
971.451	817.457
975.653	835.935
979.853	879.92
984.052	898.619
988.248	979.738
992.442	1123.32
996.633	1207.38
1000.82	1313.52
1005.01	1247.24
1009.2	1152.28
1013.38	1044.32
1017.57	1027.42
1021.75	1034.99
1025.92	1071.16
1030.1	1112.32
1034.27	1276
1038.45	1490.55
1042.62	1783.63
1046.78	1949.12
1050.95	1902.01
1055.12	1853.56
1059.28	1914.75
1063.44	2016.18
1067.6	2264.73
1071.75	2580.68
1075.91	3178.67
1080.06	4201.89
1084.21	5847.06
1088.36	8266.67
1092.51	10846.5
1096.65	10915.7
1100.8	8196.29
1104.94	5296.12
1109.08	3429.88
1113.21	2575.26
1117.35	2146.28
1121.48	2033.63
1125.61	1989.21
1129.74	2185.57
1133.87	2594.22
1137.99	3231.27
1142.12	3980.04
1146.24	4187.72
1150.36	3705.36
1154.48	2924.67
1158.59	2217.08
1162.71	1772.71
1166.82	1453.62
1170.93	1220.97
1175.04	1063.4
1179.14	948.111
1183.25	858.727
1187.35	797.018
1191.45	745.294
1195.55	704.806
1199.65	684.692
1203.74	631.908
1207.83	586.471
1211.92	600.044
1216.01	602.464
1220.1	589.817
1224.19	583.348
1228.27	581.048
1232.35	564.963
1236.43	550.36
1240.51	581.068
1244.58	619.601
1248.66	608.421
1252.73	646.496
1256.8	652.778
1260.87	653.179
1264.93	642.676
1269	598.241
1273.06	553.807
1277.12	519.308
1281.18	513.845
1285.23	489.18
1289.29	484.511
1293.34	478.769
1297.39	477.985
1301.44	472.115
1305.49	469.175
1309.53	453.096
1313.58	473.252
1317.62	466.023
1321.66	458.701
1325.7	437.132
1329.73	448.712
1333.77	479.288
1337.8	441.47
1341.83	483.736
1345.86	500.834
1349.88	533.805
1353.91	579.603
1357.93	696.779
1361.95	928.481
1365.97	1149.64
1369.99	997.685
1374	715.112
1378.02	548.681
1382.03	488.083
1386.04	475.05
1390.05	435.546
1394.05	394.204
1398.06	381.568
1402.06	371.848
1406.06	372.947
1410.06	360.284
1414.05	373.287
1418.05	353.745
1422.04	367.745
1426.03	361.957
1430.02	375.733
1434.01	376.701
1438	365.813
1441.98	357.894
1445.96	362.754
1449.94	337.985
1453.92	349.672
1457.9	357.368
1461.87	354.154
1465.85	354.768
1469.82	355.358
1473.78	347.158
1477.75	346.777
1481.72	349.29
1485.68	359.6
1489.65	343.474
1493.61	342.054
1497.56	364.038
1501.52	348.039
1505.47	345.751
1509.43	359.114
1513.38	351.118
1517.33	348.975
1521.27	345.903
1525.22	372.924
1529.16	363.109
1533.11	363.04
1537.05	359.104
1540.98	373.593
1544.92	363.855
1548.86	387.062
1552.79	396.702
1556.72	369.486
1560.65	403.223
1564.58	413.661
1568.5	411.474
1572.43	401.528
1576.35	416.697
1580.27	446.301
1584.19	454.635
1588.1	472.556
1592.02	479.844
1595.93	514.04
1599.84	505.897
1603.75	524.693
1607.66	520.515
1611.57	548.959
1615.47	554.409
1619.37	567.595
1623.27	589.353
1627.17	576.726
1631.07	580.453
1634.97	561.394
1638.86	577.724
1642.75	559.737
1646.64	536.102
1650.53	540.298
1654.42	517.66
1658.3	508.389
1662.18	495.242
1666.07	472.375
1669.94	454.247
1673.82	449.43
1677.7	441.702
1681.57	405.883
1685.44	395.928
1689.31	381.163
1693.18	370.181
1697.05	361.085
1700.92	377.742
1704.78	351.358
1708.64	362.109
1712.5	351.849
1716.36	353.953
1720.21	343.77
1724.07	337.411
1727.92	336.701
1731.77	345.335
1735.62	331.455
1739.47	326.954
1743.32	344.83
1747.16	346.813
1751.01	347.14
1754.85	345.737
1758.69	345.461
1762.52	349.472
1766.36	342.099
1770.19	357.142
1774.02	326.822
1777.85	316.928
1781.68	304.32
1785.51	305.729
1789.33	298.76
1793.16	296.466
1796.98	295.109
1800.8	297.493
1804.62	286.518
1808.43	297.16
1812.25	296.475
1816.06	291.018
1819.87	289.203
1823.68	270.328
1827.49	276.876
1831.3	289.001
1835.1	276.539
1838.9	277.229
1842.71	284.457
1846.51	278.453
1850.3	272.498
1854.1	268.305
1857.89	276.209
1861.69	274.665
1865.48	296.36
1869.27	274.35
1873.05	278.405
1876.84	289.9
1880.62	287.528
1884.4	272.38
1888.19	286.743
1891.96	294.05
1895.74	287.561
1899.52	301.315
1903.29	287.593
1907.06	304.302
1910.83	285.13
1914.6	290.932
1918.37	293.996
1922.13	278.766
1925.9	296.855
1929.66	279.799
1933.42	289.668
1937.18	294.91
1940.94	299.228
1944.69	288.588
1948.44	302.274
1952.2	320.454
1955.95	330.087
1959.69	338.618
1963.44	341.4
1967.19	360.125
1970.93	379.664
1974.67	373.714
1978.41	405.171
1982.15	423.387
1985.89	444.284
1989.62	424.951
1993.35	458.699
1997.09	423.442
2000.82	450.399
2004.55	412.458
2008.27	430.984
2012	403.236
2015.72	405.058
2019.44	393.299
2023.16	372.622
2026.88	372.366
2030.6	365.719
2034.31	362.914
2038.03	365.73
2041.74	382.247
2045.45	358.449
2049.16	348.392
2052.86	331.075
2056.57	339.419
2060.27	325.026
2063.98	336.513
2067.67	319.607
2071.37	332.153
2075.07	316.134
2078.77	321.348
2082.46	310.854
2086.15	323.485
2089.84	295.825
2093.53	307.949
2097.22	308.148
2100.9	312.943
2104.59	305.541
2108.27	303.665
2111.95	307.321
2115.63	304.459
2119.31	316.427
2122.98	298.54
2126.66	304.74
2130.33	296.052
2134	297.536
2137.67	282.36
2141.34	290.249
2145	288.855
2148.67	294.804
2152.33	283.281
2155.99	285.558
2159.65	286.923
2163.31	279.181
2166.96	278.806
2170.62	273.923
2174.27	278.273
2177.92	265.382
2181.57	257.999
2185.22	256.978
2188.87	249.66
2192.51	266.091
2196.15	252.608
2199.8	259.204
2203.44	245.779
2207.07	245.146
2210.71	253.696
2214.35	245.825
2217.98	244.362
2221.61	253.002
2225.24	239.608
2228.87	240.894
2232.5	248.649
2236.12	240.739
2239.75	248.531
2243.37	229.457
2246.99	232.598
2250.61	227.389
2254.23	221.257
2257.85	221.655
2261.46	222.05
2265.07	228.975
2268.68	226.565
2272.29	228.898
2275.9	218.935
2279.51	227.739
2283.11	209.986
2286.72	227.147
2290.32	220.701
2293.92	214.215
2297.52	215.298
2301.11	216.391
2304.71	222.186
2308.3	211.826
2311.9	223.232
2315.49	229.866
2319.08	227.93
2322.66	215.522
2326.25	203.947
2329.84	214.117
2333.42	205.353
2337	196.585
2340.58	223.59
2344.16	212.89
2347.73	212.519
2351.31	211.197
2354.88	220.152
2358.45	215.064
2362.03	207.188
2365.59	214.208
2369.16	197.1
2372.73	206.954
2376.29	207.514
2379.85	213.615
2383.41	191.162
2386.97	201.914
2390.53	194.296
2394.09	190.406
2397.64	205.836
2401.2	203.903
2404.75	200.251
2408.3	212.205
2411.85	204.998
2415.39	199.666
2418.94	194.371
2422.48	204.738
2426.03	207.809
2429.57	198.942
2433.11	188.231
2436.64	196.057
2440.18	201.151
2443.72	198.833
2447.25	190.907
2450.78	186.725
2454.31	193.814
2457.84	197.99
2461.37	188.822
2464.89	189.042
2468.42	195.704
2471.94	194.036
2475.46	195.821
2478.98	186.255
2482.5	180.501
2486.01	192.58
2489.53	196.988
2493.04	186.463
2496.55	184.3
2500.06	191.576
2503.57	192.221
2507.08	192.831
2510.58	176.619
2514.09	186.529
2517.59	198.308
2521.09	196.173
2524.59	188.356
2528.09	189.074
2531.59	182.448
2535.08	180.475
2538.58	185.017
2542.07	186.832
2545.56	191.506
2549.05	183.337
2552.54	189.03
2556.02	192.008
2559.51	193.235
2562.99	187.043
2566.47	194.862
2569.95	180.402
2573.43	179.937
2576.91	187.004
2580.38	191.326
2583.85	190.027
2587.33	185.881
2590.8	182.611
2594.27	186.834
2597.74	188.185
2601.2	184.822
2604.67	175.681
2608.13	192.296
2611.59	180.953
2615.06	180.993
2618.51	182.063
2621.97	187.861
2625.43	184.975
2628.88	173.393
2632.33	172.353
2635.79	179.907
2639.24	181.644
2642.69	167.067
2646.13	191.693
2649.58	182.823
2653.02	182.515
2656.47	176.452
2659.91	182.718
2663.35	183.252
2666.79	189.435
2670.22	185.216
2673.66	179.126
2677.09	175.908
2680.52	175.539
2683.95	178.014
2687.39	173.079
2690.81	185.048
2694.24	178.431
2697.66	192.269
2701.09	182.869
2704.51	179.995
2707.93	176.2
2711.35	189.272
2714.77	180.991
2718.18	185.773
2721.6	185.007
2725.01	187.995
2728.42	177.929
2731.84	171.59
2735.24	192.375
2738.65	190.714
2742.06	189.041
2745.46	182.631
2748.86	178.065
2752.27	194.181
2755.67	183.016
2759.07	195.352
2762.46	181.331
2765.86	182.324
2769.25	203.08
2772.65	199.303
2776.04	186.086
2779.43	191.682
2782.82	190.656
2786.2	197.144
2789.59	202.678
2792.98	195.039
2796.36	199.615
2799.74	196.674
2803.12	200.272
2806.5	202.928
2809.88	204.64
2813.25	195.107
2816.63	199.603
2820	209.691
2823.37	205.795
2826.74	218.722
2830.11	207.412
2833.48	220.369
2836.84	211
2840.21	223.095
2843.57	211.944
2846.93	223.206
2850.29	221.504
2853.65	238.521
2857.01	219.101
2860.36	231.475
2863.72	232.666
2867.07	239.494
2870.42	234.139
2873.77	248.486
2877.12	242.164
2880.47	255.593
2883.81	252.077
2887.16	268.341
2890.5	256.307
2893.84	251.795
2897.18	269.905
2900.52	273.807
2903.86	260.64
2907.19	290.014
2910.53	295.712
2913.86	289.088
2917.19	307.045
2920.52	315.49
2923.85	321.076
2927.18	306.776
2930.51	326.461
2933.83	333.808
2937.15	332.603
2940.48	342.713
2943.8	356.577
2947.11	362.9
2950.43	356.055
2953.75	372.706
2957.06	360.226
2960.38	385.373
2963.69	385.194
2967	377.534
2970.31	400.942
2973.62	412.229
2976.92	401.02
2980.23	421.776
2983.53	447.184
2986.84	451.04
2990.14	452.107
2993.44	483.247
2996.73	471.213
3000.03	479.874
3003.33	498.88
3006.62	516.963
3009.91	531.339
3013.2	541.991
3016.49	553.608
3019.78	564.281
3023.07	593.823
3026.35	618.679
3029.64	620.907
3032.92	652.415
3036.2	655.563
3039.48	688.013
3042.76	697.79
3046.04	713.269
3049.32	752.445
3052.59	771.761
3055.86	775.001
3059.14	783.901
3062.41	825.757
3065.68	866.806
3068.94	892.581
3072.21	902.034
3075.48	941.035
3078.74	961.994
3082	1001.6
3085.26	1033.54
3088.52	1060.72
3091.78	1081.59
3095.04	1152
3098.29	1182.01
3101.55	1190.9
3104.8	1232.86
3108.05	1304.91
3111.3	1344.49
3114.55	1364.61
3117.8	1400.1
3121.04	1460.4
3124.29	1561.68
3127.53	1555.32
3130.77	1622.28
3134.02	1670.23
3137.25	1730.53
3140.49	1764.07
3143.73	1831.91
3146.96	1883.56
3150.2	1961.1
3153.43	1991.96
3156.66	2102.88
3159.89	2157.59
3163.12	2197.94
3166.35	2284.11
3169.57	2290.87
3172.8	2439.66
3176.02	2469.04
3179.24	2544.97
3182.46	2596.98
3185.68	2604.21
3188.9	2782.75
3192.12	2744.74
3195.33	2879.23
3198.55	2857.36
3201.76	2950.66
3204.97	3025
3208.18	3093.69
3211.39	3108.25
3214.6	3144.9
3217.8	3232.18
3221.01	3284.26
3224.21	3314.57
3227.41	3357.58
3230.61	3390.2
3233.81	3415.47
3237.01	3510.95
3240.21	3570.11
3243.4	3624.75
3246.59	3607.22
3249.79	3654.49
3252.98	3715.52
3256.17	3770.03
3259.36	3798.76
3262.54	3826
3265.73	3954.93
3268.92	3925.71
3272.1	3972.53
3275.28	4029.61
3278.46	4071.33
3281.64	4158.99
3284.82	4199.06
3288	4245.85
3291.17	4303.69
3294.35	4366.58
3297.52	4421.63
3300.69	4439.57
3303.86	4508
3307.03	4611.38
3310.2	4701.83
3313.36	4695.46
3316.53	4892.94
3319.69	4918.28
3322.85	5017.32
3326.02	5058.48
3329.18	5169.61
3332.33	5270.28
3335.49	5408.01
3338.65	5443.11
3341.8	5542.71
3344.95	5755.51
3348.11	5826.27
3351.26	5980.42
3354.41	6088.28
3357.56	6203.43
3360.7	6323.64
3363.85	6481.41
3366.99	6513.98
3370.13	6728.96
3373.28	6823.6
3376.42	6984.23
3379.56	7079.22
3382.69	7131.17
3385.83	7357.75
3388.97	7565.33
3392.1	7658.72
3395.23	7876.85
3398.36	7980.44
3401.49	8164.45
3404.62	8379.86
3407.75	8649.68
3410.88	8778.86
3414	8984.2
3417.13	9302.1
3420.25	9505.46
3423.37	9852.27
3426.49	10199.3
3429.61	10505.6
3432.73	10885.1
3435.84	11357.8
3438.96	11650.2
3442.07	12300.8
3445.18	13167.4
3448.29	14480.9
3451.4	16614.7
3454.51	19658.5
3457.62	21969.7
3460.72	21661
3463.83	19026.9
3466.93	16650.6
3470.03	14890.1
3473.13	13764.9
3476.23	13131
3479.33	12798.9
3482.43	12538.8
3485.53	12471.2
3488.62	12202.5
3491.71	12258.8
3494.81	12229.7
3497.9	12176.6
3500.99	12139.6
3504.07	12123.7
3507.16	12181.3
3510.25	12395
3513.33	12739.3
3516.41	12980.1
3519.5	13312.4
3522.58	13964.5
3525.66	14516.6
3528.73	15175.8
3531.81	15916.6
3534.89	16374.9
3537.96	16544
3541.03	16331.5
3544.11	15445.2
3547.18	14042.6
3550.25	12512.6
3553.32	11018.1
3556.38	9575
3559.45	8354.41
3562.51	7447.69
3565.58	6656.89
3568.64	6032.26
3571.7	5478.25
3574.76	5127.94
3577.82	4798.65
3580.87	4476.47
3583.93	4254.46
3586.98	4057.67
3590.04	3813.49
3593.09	3661.82
3596.14	3503.5
3599.19	3369.59
3602.24	3227.26
3605.29	3106.46
3608.33	2951.49
3611.38	2917.71
3614.42	2803.47
3617.46	2665.65
3620.5	2606.47
3623.54	2546.53
3626.58	2452.8
3629.62	2308.41
3632.65	2238.45
3635.69	2115.74
3638.72	2023.77
3641.76	1936.83
3644.79	1827.55
3647.82	1657.57
3650.84	1594.38
3653.87	1543.64
3656.9	1439.31
3659.92	1336.32
3662.95	1255.59
3665.97	1177.32
3668.99	1121.06
3672.01	1057.48
3675.03	1003.31
3678.05	929.326
3681.07	917.642
3684.08	864.307
3687.1	818.486
3690.11	788.721
3693.12	753.259
3696.13	714.914
3699.14	677.332
3702.15	655.032
3705.16	640.295
3708.16	633.129
3711.17	592.613
3714.17	573.88
3717.17	559.815
3720.17	517.229
3723.17	507.865
3726.17	493.692
3729.17	488.992
3732.16	460.449
3735.16	458.523
3738.15	432.743
3741.14	428.828
3744.13	417.251
3747.13	415.16
3750.11	394.968
3753.1	385.22
3756.09	384.023
3759.07	369.554
3762.06	356.989
3765.04	352.939
3768.02	342.276
3771	325.976
3773.98	337.151
3776.96	330.38
3779.94	316.075
3782.91	320.692
3785.89	314.925
3788.86	307.29
3791.83	313.837
3794.8	315.713
3797.77	286.467
3800.74	310.097
3803.71	285.622
3806.68	288.539
3809.64	274.461
3812.61	279.293
3815.57	271.843
3818.53	282.367
3821.49	271.145
3824.45	283.592
3827.41	279.966
3830.36	269.703
3833.32	270.809
3836.27	272.892
3839.23	283.54
3842.18	265.687
3845.13	276.344
3848.08	259.416
3851.03	274.865
3853.98	272.238
3856.92	274.384
3859.87	279.403
3862.81	276.785
3865.75	277.016
3868.7	278.205
3871.64	284.164
3874.57	266.147
3877.51	277.844
3880.45	278.001
3883.39	281.971
3886.32	266.689
3889.25	274.449
3892.18	286.047
3895.12	285.134
3898.05	285.145
3900.97	288.97
3903.9	276.44
3906.83	270.609
3909.75	273.463
3912.68	279.173
3915.6	268.521
3918.52	277.066
3921.44	250.128
3924.36	268.267
3927.28	262.376
3930.2	261.26
3933.11	270.674
3936.03	272.481
3938.94	265.725
3941.86	265.722
3944.77	283.884
3947.68	275.253
3950.59	258.033
3953.49	276.258
3956.4	269.6
3959.31	276.375
3962.21	266.876
3965.12	271.763
3968.02	261.326
3970.92	264.324
3973.82	267.334
3976.72	280.903
3979.61	264.683
3982.51	272.459
3985.41	285.042
3988.3	272.617
3991.19	270.756
3994.09	279.444
3996.98	271.829
3999.87	274.793