File: Data/3-Raman/raw/bu19w-e-ff11b-fi08-v_1800 (450-850nm)_532nm_edge_100%_x100_vis_h50um_30sx2_01.txt
#Acq. time (s)=	30
#Accumulations=	2
#Range (cm-¹)=	1200...2400
#Windows=	4
#Auto scanning=	Off
#Autofocus=	Off
#Macrospot=	Off
#AutoExposure=	Off
#Spike filter=	Multiple accum.
#Delay time (s)=	2
#Binning=	1
#Readout mode=	Signal
#DeNoise=	Off
#ICS correction=	On
#Dark correction=	Off
#Inst. Process=	Off
#Detector Gain=	Best Dynamic
#Detector ADC=	50 kHz HS
#Detector temperature (°C)=	-60.09
#Instrument=	LabRAM HR Evol
#Detector=	SIN-EM FIVIS
#Objective=	x100_VIS
#Grating=	1800 (450-850nm)
#ND Filter=	100%
#Laser=	532nm_Edge
#Hole=	49.98
#Temperature=	0
#Range=	Visible
#StageXY=	75x50mm Scan+
#StageZ=	Z motor
#X (µm)=	0
#Y (µm)=	0
#Z (µm)=	-249
#Full time(mm:ss)=	4:28
#Project=	21_11_04
#Sample=	BU19w
#Site=
#Title=	BU19w-E-FF11b-FI08-V_1800 (450-850nm)_532nm_Edge_100%_x100_VIS_H50um_30sX2
#Remark=
#Date=	04.11.2021 17:37
#Acquired=	04.11.2021 17:37:20
1200.19	25.3215
1201.3	24.1951
1202.41	26.4062
1203.52	27.4203
1204.63	25.2574
1205.74	31.6487
1206.85	36.9489
1207.97	30.4972
1209.08	29.4017
1210.19	25.1027
1211.3	31.4682
1212.41	32.4923
1213.52	31.4051
1214.63	31.4068
1215.74	30.3255
1216.85	30.281
1217.95	31.3119
1219.06	27.0545
1220.17	30.2278
1221.28	28.0899
1222.39	31.2153
1223.5	33.2768
1224.61	35.3616
1225.71	33.2622
1226.82	32.1846
1227.93	33.1455
1229.03	37.4267
1230.14	31.0719
1231.25	30.9997
1232.35	35.1956
1233.46	33.0921
1234.57	36.2617
1235.67	36.2745
1236.78	35.2
1237.88	34.1004
1238.99	34.0716
1240.1	36.1627
1241.2	35.1125
1242.3	38.2521
1243.41	35.118
1244.51	36.1596
1245.62	41.3505
1246.72	37.1572
1247.82	37.1317
1248.93	38.1783
1250.03	35.0265
1251.13	38.1319
1252.24	32.884
1253.34	37.0467
1254.44	39.1569
1255.54	40.203
1256.65	42.3036
1257.75	40.1994
1258.85	41.2283
1259.95	46.4603
1261.05	55.8026
1262.15	76.8377
1263.25	75.6959
1264.35	54.8756
1265.45	56.9444
1266.55	48.6093
1267.66	40.2938
1268.75	48.7195
1269.85	49.7364
1270.95	54.937
1272.05	46.5956
1273.15	55.0349
1274.25	44.5798
1275.35	48.7913
1276.45	46.7291
1277.54	48.8731
1278.64	63.6406
1279.74	86.7666
1280.84	175.206
1281.94	538.495
1283.03	699.438
1284.13	212.302
1285.23	93.1727
1286.32	63.6997
1287.42	59.4613
1288.52	54.2045
1289.61	47.9261
1290.71	51.0817
1291.8	45.8148
1292.9	43.7086
1293.99	46.9255
1295.09	36.4079
1296.18	40.6946
1297.28	45.9545
1298.37	36.4313
1299.47	41.6966
1300.56	35.3701
1301.65	35.3842
1302.75	35.3831
1303.84	39.598
1304.94	41.6938
1306.03	35.3312
1307.12	32.1694
1308.21	34.2789
1309.31	37.4633
1310.4	35.3521
1311.49	36.4177
1312.58	39.5931
1313.67	34.3042
1314.76	37.4837
1315.86	37.4941
1316.95	37.4921
1318.04	37.5039
1319.13	34.3326
1320.22	38.5565
1321.31	36.4087
1322.4	37.4373
1323.49	34.2698
1324.58	37.4338
1325.67	33.1641
1326.76	32.1069
1327.85	36.3765
1328.93	38.508
1330.02	35.3335
1331.11	33.184
1332.2	39.4534
1333.29	39.402
1334.37	37.2619
1335.46	36.1856
1336.55	37.2146
1337.64	36.1441
1338.72	39.2658
1339.81	37.176
1340.9	35.0811
1341.98	36.1059
1343.07	32.9445
1344.16	38.173
1345.24	35.005
1346.33	33.9124
1347.41	34.9209
1348.5	38.0307
1349.58	33.8381
1350.67	35.8902
1351.75	35.8757
1352.84	39.0369
1353.92	40.0218
1355.01	33.7534
1356.09	37.9144
1357.17	43.09
1358.26	37.8728
1359.34	34.7374
1360.42	40.9176
1361.5	44.0181
1362.59	41.9332
1363.67	48.1701
1364.75	40.8997
1365.83	41.897
1366.92	41.8564
1368	47.035
1369.08	66.691
1370.16	48.0494
1371.24	42.8397
1372.32	45.877
1373.4	47.9153
1374.48	55.1113
1375.56	52.026
1376.64	59.1802
1377.72	60.2525
1378.8	68.5574
1379.88	69.5063
1380.96	76.6214
1382.04	86.7605
1383.12	105.111
1384.2	147.146
1385.28	376.246
1386.36	1678.91
1387.43	466.576
1388.51	146.274
1389.59	86.7269
1390.67	66.1054
1391.74	61.9632
1392.82	59.8802
1393.9	57.8145
1394.97	56.8057
1396.05	51.6867
1397.13	54.7237
1398.2	45.5251
1399.28	40.4268
1400.35	48.6386
1401.43	49.6765
1402.5	48.7474
1403.58	47.7189
1404.65	51.8004
1405.73	58.9419
1406.8	81.495
1407.88	110.227
1408.95	79.4919
1410.03	53.8402
1411.1	45.5937
1412.17	45.6159
1413.25	43.6031
1414.32	35.4193
1415.39	38.5028
1416.47	39.5457
1417.54	33.3956
1418.61	35.4565
1419.68	35.4373
1420.75	36.4369
1421.83	35.4361
1422.9	34.5037
1423.97	31.2366
1425.04	40.4956
1426.11	31.2794
1427.18	36.3605
1428.25	33.277
1429.32	31.2442
1430.39	34.3547
1431.46	35.4091
1432.53	36.4007
1433.6	33.2804
1434.67	31.2543
1435.74	31.2501
1436.81	28.1675
1437.88	33.2874
1438.95	34.3237
1440.01	33.325
1441.08	24.0965
1442.15	34.355
1443.22	29.2178
1444.29	34.3559
1445.35	28.2109
1446.42	25.1259
1447.49	28.1923
1448.56	30.2572
1449.62	30.2443
1450.69	31.2586
1451.75	30.2238
1452.82	28.1807
1453.89	30.229
1454.95	29.2017
1456.02	27.1607
1457.08	29.1968
1458.15	31.2453
1459.21	25.1024
1460.28	29.1931
1461.34	28.1543
1462.41	28.1327
1463.47	25.0496
1464.53	26.118
1465.6	26.0263
1466.66	23.9752
1467.72	26.0116
1468.79	22.9465
1469.85	24.9678
1470.91	29.0306
1471.97	24.947
1473.04	25.9572
1474.1	26.968
1475.16	29.0069
1476.22	27.9775
1477.29	26.9493
1478.34	27.952
1479.41	28.9474
1480.47	28.9185
1481.53	21.8178
1482.59	26.9058
1483.65	28.936
1484.71	19.7319
1485.77	21.7916
1486.83	21.7858
1487.89	30.8812
1488.95	28.8361
1490.01	27.8194
1491.07	23.7592
1492.12	26.7914
1493.18	24.7658
1494.24	28.8132
1495.3	29.7962
1496.36	28.7669
1497.42	24.7255
1498.47	26.7458
1499.53	28.7727
1500.59	30.7897
1501.64	28.76
1502.7	27.7357
1503.76	26.723
1504.81	26.7189
1505.87	28.7122
1506.93	24.6881
1507.98	27.7084
1509.04	27.7098
1510.09	27.7081
1511.15	27.6747
1512.21	27.6233
1513.26	27.6054
1514.31	25.6116
1515.37	31.6035
1516.42	26.5712
1517.48	28.579
1518.53	26.5825
1519.58	28.5928
1520.64	28.5945
1521.69	27.5894
1522.75	29.5795
1523.8	27.5434
1524.85	23.5349
1525.9	27.56
1526.95	32.572
1528.01	29.5548
1529.06	27.5444
1530.11	26.5406
1531.16	29.5598
1532.21	26.5554
1533.27	29.5917
1534.32	26.5792
1535.37	20.542
1536.42	31.5254
1537.47	28.5053
1538.52	27.4896
1539.57	25.5445
1540.62	28.5767
1541.67	19.535
1542.72	28.5244
1543.77	24.5023
1544.81	22.5228
1545.86	26.545
1546.91	27.5551
1547.96	26.5344
1549.01	26.4895
1550.06	29.5863
1551.1	28.6161
1552.15	26.6166
1553.2	24.577
1554.25	25.5541
1555.3	31.5545
1556.34	30.5511
1557.39	26.5452
1558.43	25.5144
1559.48	29.49
1560.53	28.4806
1561.57	26.4991
1562.62	24.5011
1563.66	33.5135
1564.71	29.4886
1565.76	25.4819
1566.8	33.5002
1567.84	30.4939
1568.89	30.4825
1569.93	32.4808
1570.98	27.4784
1572.02	28.4634
1573.07	29.4435
1574.11	31.4529
1575.15	29.481
1576.2	28.4739
1577.24	24.4434
1578.28	28.4127
1579.32	30.4096
1580.37	29.4158
1581.41	30.3934
1582.45	29.3858
1583.49	29.3799
1584.53	27.3935
1585.58	27.3864
1586.62	25.3756
1587.66	30.3459
1588.7	31.3558
1589.74	31.3631
1590.78	27.3869
1591.82	30.3593
1592.86	29.3322
1593.9	31.287
1594.94	28.3215
1595.98	33.2728
1597.02	27.3199
1598.06	30.2901
1599.1	32.2495
1600.14	34.2097
1601.17	27.2353
1602.21	34.1093
1603.25	29.9854
1604.29	29.0571
1605.33	31.534
1606.37	29.2323
1607.4	30.1777
1608.44	30.8616
1609.48	27.3645
1610.51	29.7972
1611.55	29.3391
1612.59	30.1321
1613.62	29.7768
1614.66	31.737
1615.7	33.3794
1616.73	31.038
1617.77	29.6442
1618.8	29.4702
1619.84	30.0145
1620.87	30.2437
1621.91	30.5622
1622.94	29.9334
1623.98	30.8873
1625.01	30.5715
1626.04	26.9688
1627.08	28.4159
1628.11	28.9158
1629.07	27.096
1630.12	28.0749
1631.16	31.0343
1632.21	32.0418
1633.25	33.0086
1634.3	34.0064
1635.34	27.1009
1636.39	32.0125
1637.43	31.9984
1638.48	27.0696
1639.52	31.0062
1640.57	30.0331
1641.61	30.026
1642.65	30.0213
1643.7	32.9658
1644.74	28.0418
1645.78	32.9628
1646.83	27.0483
1647.87	28.0287
1648.91	30.0266
1649.95	31.0195
1651	29.0697
1652.04	32.0293
1653.08	26.1092
1654.12	24.1455
1655.16	30.0827
1656.21	30.1065
1657.25	26.1528
1658.29	28.1153
1659.33	29.0841
1660.37	27.12
1661.41	25.1651
1662.45	28.1793
1663.49	30.0822
1664.53	29.1458
1665.57	29.1683
1666.61	30.0577
1667.65	29.1065
1668.69	24.1976
1669.72	30.122
1670.76	28.1701
1671.8	22.241
1672.84	25.2082
1673.88	31.1521
1674.92	32.1607
1675.95	29.1955
1676.99	28.2055
1678.03	29.1752
1679.07	30.1496
1680.1	26.1855
1681.14	28.1555
1682.18	23.2166
1683.21	28.1542
1684.25	27.1573
1685.29	28.1425
1686.32	26.177
1687.36	27.1615
1688.39	25.1738
1689.43	28.1141
1690.46	26.1458
1691.5	24.1806
1692.53	27.1292
1693.57	23.1602
1694.6	29.0585
1695.64	26.1103
1696.67	28.0833
1697.7	22.1502
1698.74	19.1872
1699.77	27.06
1700.81	22.133
1701.84	24.0844
1702.87	23.0914
1703.9	27.02
1704.94	24.0729
1705.97	22.0983
1707	26.0019
1708.03	24.9893
1709.06	23.0064
1710.1	23.9856
1711.13	29.8726
1712.16	24.9647
1713.19	21.9918
1714.22	24.9072
1715.25	21.9847
1716.28	25.8796
1717.31	24.8622
1718.34	25.8039
1719.37	21.9051
1720.4	24.8209
1721.43	26.7429
1722.46	22.8301
1723.49	21.8488
1724.52	25.7164
1725.55	22.7744
1726.58	24.7054
1727.6	20.8265
1728.63	26.5415
1729.66	22.7032
1730.69	22.7103
1731.72	27.5415
1732.74	22.6956
1733.77	23.6274
1734.8	21.6707
1735.82	22.6185
1736.85	22.6064
1737.88	16.8234
1738.91	23.5297
1739.93	21.5733
1740.96	24.426
1741.98	22.4992
1743.01	27.2791
1744.03	19.6088
1745.06	18.652
1746.09	21.5065
1747.11	25.3038
1748.13	23.387
1749.16	22.4422
1750.18	26.2857
1751.21	22.4625
1752.23	24.3489
1753.26	21.4672
1754.28	23.3579
1755.3	23.3447
1756.33	21.4159
1757.35	20.4485
1758.37	21.4099
1759.39	21.411
1760.42	21.4028
1761.44	22.3397
1762.46	20.4427
1763.48	26.1505
1764.5	23.3182
1765.53	22.3736
1766.55	22.3698
1767.57	23.3123
1768.59	20.4413
1769.61	21.3659
1770.63	23.2792
1771.65	22.3475
1772.67	23.3143
1773.69	23.3238
1774.71	19.5227
1775.73	22.4031
1776.75	20.4893
1777.77	19.5236
1778.79	23.3113
1779.81	25.2207
1780.83	22.3721
1781.85	25.2408
1782.86	24.3033
1783.88	23.3652
1784.9	23.3757
1785.92	23.3709
1786.94	23.3902
1787.95	22.488
1788.97	23.4731
1789.99	22.5289
1791	20.5932
1792.02	21.549
1793.04	21.5553
1794.05	23.475
1795.07	24.4719
1796.09	22.5704
1797.1	20.6654
1798.12	22.5968
1799.13	22.589
1800.15	27.3783
1801.16	18.7299
1802.18	21.6197
1803.19	23.5599
1804.21	22.6096
1805.22	24.557
1806.24	22.6466
1807.25	24.5771
1808.26	24.5798
1809.28	28.4405
1810.29	20.7284
1811.3	18.7989
1812.32	19.7702
1813.33	20.7461
1814.34	26.5657
1815.36	22.7124
1816.37	22.7177
1817.38	22.6954
1818.39	20.7775
1819.4	20.7842
1820.42	27.5642
1821.43	22.7413
1822.44	20.813
1823.45	25.6486
1824.46	20.8153
1825.47	25.6638
1826.48	20.8234
1827.49	24.7074
1828.5	23.7312
1829.51	21.7896
1830.52	21.7831
1831.53	21.7949
1832.54	25.6858
1833.55	22.7821
1834.56	23.7206
1835.57	24.6658
1836.58	24.7179
1837.58	22.7156
1838.59	24.6981
1839.6	23.7487
1840.61	18.8493
1841.62	23.643
1842.62	20.7374
1843.63	19.7727
1844.64	18.8081
1845.65	22.6887
1846.65	23.6233
1847.66	22.6353
1848.67	24.5516
1849.67	24.5237
1850.68	23.5361
1851.68	20.645
1852.69	23.5249
1853.69	22.5491
1854.7	23.4876
1855.71	21.5515
1856.71	22.5074
1857.72	24.4106
1858.72	25.3447
1859.72	24.3785
1860.73	19.6106
1861.73	22.4876
1862.74	22.4683
1863.74	24.3607
1864.74	21.4769
1865.75	24.305
1866.75	21.4097
1867.75	20.4397
1868.76	21.3907
1869.76	16.6336
1870.76	22.334
1871.76	22.3231
1872.77	19.4613
1873.77	22.2989
1874.77	24.1722
1875.77	26.9736
1876.77	23.1593
1877.77	19.4416
1878.78	25.099
1879.78	20.3562
1880.78	19.4066
1881.78	19.3677
1882.78	23.1156
1883.78	24.9774
1884.78	25.0001
1885.78	20.3036
1886.78	25.0091
1887.78	23.0975
1888.77	23.0667
1889.77	24.9478
1890.77	24.0172
1891.77	17.4208
1892.77	23.0515
1893.77	23.0289
1894.76	22.0779
1895.76	25.8476
1896.76	26.8055
1897.76	23.9852
1898.75	23.0263
1899.75	22.0752
1900.75	23.0221
1901.75	23.0423
1902.74	19.2799
1903.74	22.0949
1904.74	20.2115
1905.73	21.1366
1906.73	22.067
1907.72	25.8343
1908.72	23.9658
1909.71	22.1111
1910.71	24.0176
1911.7	21.1929
1912.7	25.9009
1913.69	23.0952
1914.69	25.9454
1915.68	21.2295
1916.68	20.2742
1917.67	24.9832
1918.66	19.3457
1919.66	21.2603
1920.65	25.9924
1921.64	21.2799
1922.64	23.1625
1923.63	19.373
1924.62	21.2577
1925.61	21.2784
1926.61	21.3011
1927.6	24.1544
1928.59	25.1132
1929.58	23.2408
1930.57	23.2612
1931.57	23.2537
1932.56	21.3459
1933.55	22.3126
1934.54	23.3363
1935.53	24.303
1936.52	25.2458
1937.51	26.1768
1938.5	24.2806
1939.49	20.485
1940.48	23.3732
1941.47	23.3676
1942.46	24.3487
1943.45	19.552
1944.44	21.4881
1945.42	26.2888
1946.41	21.5199
1947.4	20.5589
1948.39	23.4273
1949.38	23.448
1950.37	20.6084
1951.35	19.6792
1952.34	21.6095
1953.33	21.6028
1954.32	21.5571
1955.3	26.3557
1956.29	22.5613
1957.28	23.5407
1958.26	24.5104
1959.25	21.618
1960.23	25.4453
1961.22	22.5517
1962.21	21.5962
1963.19	27.3599
1964.18	26.4069
1965.16	24.4856
1966.15	26.4263
1967.13	22.5886
1968.12	25.4761
1969.1	23.5333
1970.09	24.4721
1971.07	25.4186
1972.05	19.6669
1973.04	22.5335
1974.02	26.3585
1975.01	22.531
1975.99	24.4599
1976.97	23.4993
1977.95	28.2793
1978.94	20.6081
1979.92	26.3581
1980.9	24.4273
1981.88	22.5064
1982.87	25.3574
1983.85	20.5638
1984.83	20.5509
1985.81	23.382
1986.79	20.6507
1987.77	26.8579
1988.75	24.3589
1989.73	22.1828
1990.72	23.1209
1991.7	21.7139
1992.68	21.8386
1993.66	25.0779
1994.63	21.3859
1995.61	23.7403
1996.59	23.4632
1997.57	21.2868
1998.55	22.3094
1999.53	21.1323
2000.51	22.919
2001.49	23.5019
2002.47	23.4095
2003.45	23.2213
2004.42	21.3928
2005.4	21.2879
2006.38	20.6084
2007.36	21.1018
2008.31	21.2331
2009.3	20.2665
2010.29	20.2502
2011.28	21.1898
2012.27	21.1841
2013.26	21.1548
2014.24	22.9939
2015.23	20.1845
2016.22	20.2058
2017.21	22.0765
2018.2	21.1055
2019.18	18.2679
2020.17	23.8822
2021.16	20.138
2022.15	23.8726
2023.14	21.0436
2024.12	21.0228
2025.11	23.7952
2026.1	21.9291
2027.08	21.0535
2028.07	21.9021
2029.06	21.0644
2030.04	22.8469
2031.03	20.9936
2032.01	23.8104
2033	24.7732
2033.98	22.8799
2034.97	22.8752
2035.95	24.7818
2036.94	23.8437
2037.92	21.9641
2038.91	25.6858
2039.89	22.8615
2040.87	23.774
2041.86	22.8329
2042.84	21.8975
2043.83	24.724
2044.81	21.8847
2045.79	19.1882
2046.78	21.9352
2047.76	20.9753
2048.74	22.8517
2049.72	21.9449
2050.71	22.8872
2051.69	21.9437
2052.67	22.8892
2053.65	23.8506
2054.63	22.917
2055.62	22.9061
2056.6	21.9658
2057.58	21.0404
2058.56	20.1228
2059.54	21.0642
2060.52	21.9959
2061.5	22.0027
2062.48	22.9483
2063.46	23.8994
2064.44	24.8481
2065.42	21.1208
2066.4	23.0098
2067.38	19.2632
2068.36	25.8534
2069.34	18.3146
2070.31	24.9151
2071.29	21.1865
2072.27	24.0107
2073.25	23.0674
2074.23	22.1358
2075.21	20.2855
2076.18	19.3527
2077.16	24.9917
2078.14	23.114
2079.12	24.0813
2080.09	21.2624
2081.07	25.0378
2082.05	21.2613
2083.02	22.2066
2084	22.2063
2084.98	20.3179
2085.95	23.1698
2086.93	22.2379
2087.9	22.2411
2088.88	25.0892
2089.85	24.1565
2090.83	24.1666
2091.8	21.3457
2092.78	23.2714
2093.75	25.1937
2094.73	20.4383
2095.7	23.2764
2096.68	24.2192
2097.65	24.2071
2098.62	21.3547
2099.6	24.1999
2100.57	20.4137
2101.54	22.3207
2102.52	20.4157
2103.49	23.2562
2104.46	26.1156
2105.44	25.1849
2106.41	21.3903
2107.38	22.3362
2108.35	18.5157
2109.32	24.2241
2110.3	20.4247
2111.27	19.4702
2112.24	22.3193
2113.21	19.4836
2114.18	20.4323
2115.15	20.4308
2116.12	21.369
2117.09	19.4677
2118.06	23.249
2119.03	20.3831
2120	21.3194
2120.97	22.2796
2121.94	24.1968
2122.91	20.4112
2123.88	22.3019
2124.85	22.2662
2125.82	19.4007
2126.79	20.3301
2127.76	24.1052
2128.72	20.3223
2129.69	22.2076
2130.66	23.1442
2131.63	21.2436
2132.6	24.0619
2133.56	21.2332
2134.53	25.9523
2135.5	23.1125
2136.47	22.1545
2137.43	20.2776
2138.4	21.2128
2139.37	19.3195
2140.33	23.0766
2141.3	22.1265
2142.26	21.1844
2143.23	22.0726
2144.19	23.9841
2145.16	22.0966
2146.13	20.2097
2147.09	23.9586
2148.06	21.1302
2149.02	22.0523
2149.98	22.9658
2150.95	23.9072
2151.91	23.9179
2152.88	22.0281
2153.84	19.204
2154.8	23.8491
2155.77	22.8899
2156.73	23.8209
2157.69	21.9652
2158.66	21.0281
2159.62	21.946
2160.58	21.9295
2161.54	22.8565
2162.51	20.9882
2163.47	21.9112
2164.43	20.9628
2165.39	21.8988
2166.35	21.8903
2167.32	25.5932
2168.28	22.7767
2169.24	22.7934
2170.2	22.8168
2171.16	20.9365
2172.12	22.7661
2173.08	22.7625
2174.04	23.6997
2175	21.8391
2175.96	19.0465
2176.92	20.9014
2177.88	19.0417
2178.84	22.7478
2179.8	22.7483
2180.76	21.8158
2181.72	22.736
2182.68	21.7967
2183.63	20.8507
2184.59	21.777
2185.55	23.6416
2186.51	24.5927
2187.47	20.898
2188.43	22.7395
2189.38	15.2974
2190.34	21.7869
2191.3	23.6465
2192.25	25.5105
2193.21	24.6018
2194.17	21.8479
2195.12	20.9085
2196.08	21.812
2197.04	27.361
2197.99	20.878
2198.95	24.6196
2199.9	20.9399
2200.86	21.9014
2201.81	20.8606
2202.77	21.854
2203.72	21.9128
2204.68	20.9477
2205.63	21.8492
2206.59	20.9186
2207.54	23.7265
2208.49	21.8822
2209.45	21.8854
2210.4	22.8284
2211.36	24.7102
2212.31	20.9877
2213.26	22.8416
2214.22	20.0667
2215.17	21.0068
2216.12	21.9404
2217.07	21.0064
2218.03	22.8758
2218.98	19.1533
2219.93	20.0938
2220.88	18.2168
2221.83	20.0698
2222.78	19.1437
2223.74	18.2292
2224.69	20.1188
2225.64	22.949
2226.59	22.03
2227.54	22.9749
2228.49	22.0316
2229.44	19.2275
2230.39	20.1824
2231.34	23.9591
2232.29	22.0978
2233.24	23.0559
2234.19	20.2351
2235.14	21.1571
2236.09	21.1619
2237.04	22.1157
2237.98	23.0912
2238.93	20.284
2239.88	24.0401
2240.83	24.0594
2241.78	22.1797
2242.73	25.0168
2243.67	22.1766
2244.62	22.1981
2245.57	18.4385
2246.52	20.3429
2247.46	23.1882
2248.41	24.1296
2249.36	21.2959
2250.3	23.1763
2251.25	21.272
2252.2	18.446
2253.14	21.3177
2254.09	22.2822
2255.03	21.3338
2255.98	20.3956
2256.92	19.4605
2257.87	22.317
2258.81	22.3281
2259.76	18.5355
2260.7	19.5001
2261.65	21.4113
2262.59	26.1879
2263.54	18.5951
2264.48	20.5285
2265.42	22.4486
2266.37	21.4766
2267.31	20.5084
2268.26	17.6404
2269.2	19.566
2270.14	22.4557
2271.08	22.4712
2272.03	26.3087
2272.97	18.6598
2273.91	22.4927
2274.85	20.584
2275.79	21.5514
2276.74	23.4891
2277.68	22.5654
2278.62	19.6888
2279.56	22.5478
2280.5	21.5709
2281.44	19.6502
2282.38	24.4599
2283.32	17.7709
2284.26	23.5651
2285.2	23.5783
2286.14	20.6807
2287.08	18.7796
2288.02	23.5989
2288.96	23.5752
2289.9	28.3594
2290.84	19.7172
2291.78	22.6236
2292.72	22.6431
2293.66	21.685
2294.6	25.5251
2295.54	19.7357
2296.47	22.6108
2297.41	24.557
2298.35	24.5798
2299.29	20.7399
2300.23	22.6721
2301.16	20.7529
2302.1	17.8546
2303.04	18.8188
2303.97	22.6901
2304.91	17.8729
2305.85	20.7798
2306.78	17.8809
2307.72	23.6714
2308.65	23.6752
2309.59	19.8294
2310.53	22.7311
2311.46	22.6899
2312.4	19.7801
2313.33	23.6599
2314.27	20.7902
2315.2	23.6904
2316.14	20.7627
2317.07	22.6938
2318	23.6584
2318.94	25.5745
2319.87	25.5714
2320.81	22.6866
2321.74	27.5422
2322.67	23.6854
2323.61	27.5594
2324.54	26.5751
2325.47	32.3419
2326.41	53.5361
2327.34	168.199
2328.27	102.655
2329.2	33.2293
2330.13	26.4858
2331.07	23.5993
2332	23.5976
2332.93	22.6225
2333.86	24.5355
2334.79	22.5992
2335.72	21.6383
2336.66	17.7873
2337.59	22.5893
2338.52	23.5491
2339.45	21.6249
2340.38	24.4914
2341.31	25.4196
2342.24	23.4872
2343.17	21.5677
2344.1	21.5699
2345.02	21.5621
2345.95	20.5896
2346.88	25.3712
2347.81	23.4434
2348.74	22.3167
2349.67	23.1178
2350.6	20.449
2351.53	20.1033
2352.45	21.0596
2353.38	22.9616
2354.31	21.4658
2355.24	21.101
2356.17	22.6703
2357.09	23.0627
2358.02	22.0047
2358.95	22.1267
2359.87	19.3407
2360.8	19.889
2361.73	19.4731
2362.65	22.2336
2363.58	21.4055
2364.5	19.4143
2365.43	21.715
2366.36	21.2969
2367.28	18.1484
2368.2	22.4759
2368.98	22.1784
2369.92	21.2141
2370.86	21.1975
2371.79	22.1279
2372.73	19.2918
2373.67	23.0445
2374.6	23.0282
2375.54	21.1355
2376.48	22.0634
2377.41	21.1152
2378.35	22.0368
2379.28	21.0745
2380.22	19.1916
2381.15	18.2533
2382.09	22.9319
2383.02	19.1831
2383.96	19.1818
2384.89	20.111
2385.83	18.2237
2386.76	22.8702
2387.69	18.1906
2388.63	22.8511
2389.56	20.0485
2390.5	20.05
2391.43	22.8505
2392.36	18.1804
2393.3	20.0146
2394.23	17.2081
2395.16	20.0056
2396.09	20.0629
2397.02	20.0516
2397.96	18.1861
2398.89	20.9823
2399.82	16.3208