File: Data/3-Raman/raw/bu19(2)w-a-ff2b-fi05-v_1800 (450-850nm)_532nm_edge_100%_x100_vis_lwd_h100um_30sx2_01.txt
#Acq. time (s)=	30
#Accumulations=	2
#Range (cm-¹)=	1200...2365
#Windows=	3
#Auto scanning=	Off
#Autofocus=	Off
#Macrospot=	Off
#AutoExposure=	Off
#Spike filter=	Multiple accum.
#Delay time (s)=	2
#Binning=	1
#Readout mode=	Signal
#DeNoise=	Off
#ICS correction=	On
#Dark correction=	Off
#Inst. Process=	Off
#Detector Gain=	Best Dynamic
#Detector ADC=	50 kHz HS
#Detector temperature (°C)=	-60.09
#Instrument=	LabRAM HR Evol
#Detector=	SIN-EM FIVIS
#Objective=	x50_VIS_LWD
#Grating=	1800 (450-850nm)
#ND Filter=	100%
#Laser=	532nm_Edge
#Hole=	100.021
#Temperature=	0
#Range=	Visible
#StageXY=	75x50mm Scan+
#StageZ=	Z motor
#X (µm)=	0
#Y (µm)=	0
#Z (µm)=	2.5
#Full time(mm:ss)=	3:18
#Project=	21_11_26
#Sample=	BU19(2)w
#Site=
#Title=	BU19(2)w-A-FF2b-FI05-V_1800 (450-850nm)_532nm_Edge_100%_x50_VIS_LWD_H100um_30sX2
#Remark=
#Date=	26.11.2021 14:50
#Acquired=	26.11.2021 14:50:13
1202.72	100.552
1203.84	94.1335
1204.95	95.1372
1206.06	97.1414
1207.17	91.5952
1208.28	88.2833
1209.39	86.0482
1210.5	88.1418
1211.61	86.936
1212.72	93.2077
1213.83	84.599
1214.94	80.3255
1216.05	87.7573
1217.16	85.4998
1218.27	88.5847
1219.38	80.0358
1220.49	86.3603
1221.6	82.0854
1222.71	81.9721
1223.81	82.8727
1224.92	83.8288
1226.03	84.8849
1227.14	81.6969
1228.25	83.6142
1229.35	79.2084
1230.46	81.5253
1231.57	83.3932
1232.67	77.0848
1233.78	85.4674
1234.89	79.1906
1235.99	76.068
1237.1	84.4552
1238.2	89.5915
1239.31	81.0929
1240.41	87.3493
1241.52	80.0158
1242.62	84.1729
1243.73	88.3879
1244.83	87.3343
1245.94	84.1074
1247.04	88.243
1248.14	92.4032
1249.25	97.5764
1250.35	93.3863
1251.45	91.2081
1252.56	90.0935
1253.66	92.1133
1254.76	97.3813
1255.87	104.702
1256.97	128.744
1258.07	134.974
1259.17	123.419
1260.27	148.56
1261.37	202.64
1262.48	246.988
1263.58	230.683
1264.68	165.513
1265.78	137.132
1266.88	130.859
1267.98	134.121
1269.08	121.725
1270.18	130.101
1271.28	116.37
1272.38	120.564
1273.47	120.702
1274.57	131.303
1275.67	148.098
1276.77	154.506
1277.87	165.135
1278.97	219.968
1280.07	386.2
1281.16	1088.86
1282.26	2885.34
1283.36	2497.91
1284.45	813.901
1285.55	327.686
1286.65	196.009
1287.75	166.451
1288.84	144.302
1289.94	139.117
1291.03	120.191
1292.13	121.226
1293.22	123.32
1294.32	108.704
1295.42	113.998
1296.51	112.12
1297.61	105.759
1298.7	107.806
1299.79	101.41
1300.89	97.2118
1301.98	91.9405
1303.08	89.8474
1304.17	103.535
1305.26	91.9054
1306.35	94.9857
1307.45	88.634
1308.54	89.69
1309.63	84.4366
1310.73	85.5002
1311.82	89.7298
1312.91	84.4882
1314	84.4561
1315.09	80.2361
1316.18	81.3288
1317.28	85.5343
1318.37	71.8229
1319.46	85.5549
1320.55	81.325
1321.64	86.5416
1322.73	82.2389
1323.82	83.2587
1324.91	79.0403
1326	81.09
1327.09	84.1071
1328.18	85.2998
1329.27	76.9566
1330.35	82.2156
1331.44	78.979
1332.53	83.0698
1333.62	81.9033
1334.71	74.456
1335.79	76.4871
1336.88	83.7735
1337.97	73.2544
1339.06	69.0027
1340.14	79.4667
1341.23	74.2314
1342.32	84.6665
1343.4	75.1734
1344.49	81.4363
1345.58	71.9841
1346.66	75.0096
1347.75	76.9991
1348.83	82.1687
1349.92	77.9387
1351	82.035
1352.09	87.1677
1353.17	86.1768
1354.25	93.549
1355.34	85.0131
1356.42	86.0376
1357.51	92.2208
1358.59	86.9678
1359.67	85.864
1360.76	97.1738
1361.84	90.923
1362.92	103.309
1364	108.516
1365.09	106.434
1366.17	106.337
1367.25	97.9462
1368.33	150.653
1369.41	177.571
1370.5	116.532
1371.58	107.133
1372.66	104.909
1373.74	117.199
1374.82	123.337
1375.9	127.449
1376.98	125.325
1378.06	141.745
1379.14	153.31
1380.22	165.592
1381.3	191.983
1382.38	250.333
1383.46	336.138
1384.54	680.425
1385.61	2301.44
1386.69	7108.94
1387.77	2122.11
1388.85	567.386
1389.93	285.114
1391	208.803
1392.08	176.869
1393.16	163.417
1394.23	141.859
1395.31	131.613
1396.39	123.46
1397.46	122.368
1398.54	125.406
1399.62	118.29
1400.69	125.492
1401.77	114.279
1402.84	121.628
1403.92	138.164
1404.99	150.374
1406.07	199.485
1407.14	265.022
1408.22	345.065
1409.29	264.141
1410.37	152.383
1411.44	112.259
1412.51	100.962
1413.59	89.9331
1414.66	81.612
1415.73	80.6179
1416.81	74.4769
1417.88	73.4795
1418.95	82.7373
1420.02	74.4928
1421.1	77.5087
1422.17	64.162
1423.24	68.4078
1424.31	75.355
1425.38	56.8937
1426.45	59.9823
1427.52	64.0172
1428.59	64.9752
1429.67	60.8927
1430.74	61.9664
1431.81	61.0153
1432.87	55.8476
1433.95	57.8078
1435.01	56.7987
1436.08	55.769
1437.15	55.747
1438.22	50.6071
1439.29	53.6934
1440.36	51.6781
1441.43	48.6113
1442.49	54.7536
1443.56	48.5936
1444.63	50.6292
1445.7	56.8205
1446.77	52.6946
1447.83	51.6449
1448.9	51.6562
1449.97	46.5162
1451.03	47.5138
1452.1	48.5168
1453.17	43.3869
1454.23	49.5378
1455.3	39.2825
1456.36	45.4368
1457.43	44.3888
1458.49	47.4498
1459.56	42.3306
1460.62	40.2708
1461.69	51.5118
1462.75	42.2614
1463.82	45.2855
1464.88	45.3317
1465.94	42.1303
1467.01	39.0511
1468.07	39.0396
1469.13	38.0094
1470.2	40.0182
1471.26	39.9924
1472.32	42.0021
1473.39	38.9358
1474.45	41.9646
1475.51	36.8779
1476.57	36.8598
1477.63	39.8874
1478.69	40.8841
1479.76	37.8041
1480.82	34.713
1481.88	37.7388
1482.94	32.6849
1484	38.7793
1485.06	35.6524
1486.12	36.6499
1487.18	42.7288
1488.24	39.6634
1489.3	34.566
1490.36	39.6097
1491.42	38.5721
1492.48	34.5191
1493.53	40.5755
1494.59	34.504
1495.65	38.5266
1496.71	37.4739
1497.77	44.5232
1498.82	33.4145
1499.88	37.4554
1500.94	38.4631
1502	34.406
1503.05	39.4317
1504.11	35.3734
1505.17	39.4058
1506.22	37.3498
1507.28	33.3178
1508.34	34.3207
1509.39	40.3623
1510.45	39.356
1511.5	37.3011
1512.56	39.2316
1513.61	35.1666
1514.67	37.1939
1515.72	34.1449
1516.78	35.1106
1517.83	38.1079
1518.88	33.1028
1519.94	36.1172
1520.99	33.098
1522.05	34.1028
1523.1	39.0977
1524.15	33.0363
1525.2	33.0167
1526.26	37.0335
1527.31	33.0393
1528.36	37.0296
1529.41	34.0057
1530.47	35.9933
1531.52	36.0127
1532.57	28.9891
1533.62	35.0337
1534.67	34.0314
1535.72	36.0154
1536.77	35.9594
1537.82	36.9149
1538.87	39.8857
1539.92	30.9316
1540.97	33.9877
1542.02	41.9777
1543.07	42.9316
1544.12	33.8763
1545.17	37.8956
1546.22	33.9221
1547.27	33.9246
1548.32	33.9017
1549.37	35.8779
1550.42	38.8892
1551.46	40.0053
1552.51	38.9976
1553.56	36.9564
1554.61	40.9338
1555.65	36.8847
1556.7	34.8732
1557.75	33.8719
1558.79	35.8406
1559.84	33.7938
1560.89	30.7729
1561.93	32.7729
1562.98	35.7864
1564.02	36.7742
1565.07	39.8017
1566.11	35.571
1567.16	29.7262
1568.2	34.7433
1569.25	33.747
1570.29	34.7238
1571.34	33.7184
1572.38	39.6906
1573.43	34.669
1574.47	33.662
1575.51	34.6899
1576.56	33.6905
1577.6	36.6386
1578.64	36.5897
1579.69	32.5943
1580.73	32.5992
1581.77	35.5691
1582.81	33.5508
1583.85	37.523
1584.9	32.5394
1585.94	32.5326
1586.98	35.4875
1588.02	39.4481
1589.06	37.4667
1590.1	36.4806
1591.14	32.5027
1592.18	37.469
1593.22	38.4225
1594.26	32.3997
1595.3	34.3879
1596.34	33.3772
1597.38	37.3494
1598.42	40.3264
1599.46	31.3517
1600.5	35.2917
1601.54	39.2097
1602.58	38.174
1603.62	31.2117
1604.66	34.1656
1605.69	40.0969
1606.73	31.2073
1607.77	35.1136
1608.81	35.0903
1609.84	36.8252
1610.88	31.0782
1611.92	35.9133
1612.95	36.1714
1613.99	34.798
1615.03	32.0542
1616.06	35.8946
1617.1	34.3713
1618.13	35.1787
1619.17	35.6797
1620.2	34.7012
1621.24	35.7568
1622.27	33.7446
1623.31	36.2123
1624.34	36.4227
1625.38	35.1272
1626.41	38.734
1627.45	34.9346
1628.48	36.8873
1629.51	39.1442
1630.55	37.2282
1631.53	38.4546
1632.57	31.5677
1633.62	34.5153
1634.66	37.4744
1635.71	36.4798
1636.75	36.4585
1637.8	35.4477
1638.84	33.4626
1639.89	32.4723
1640.93	32.4716
1641.98	36.4037
1643.02	35.406
1644.06	35.3943
1645.11	37.3411
1646.15	36.3621
1647.19	40.2771
1648.24	40.2584
1649.28	34.3825
1650.32	36.3442
1651.37	37.3561
1652.41	35.3863
1653.45	33.4018
1654.49	39.3157
1655.53	34.3971
1656.57	40.3483
1657.62	33.4341
1658.66	37.3632
1659.7	32.4054
1660.74	33.3805
1661.78	34.3849
1662.82	33.4293
1663.86	37.3794
1664.9	39.3237
1665.94	38.2812
1666.98	36.3488
1668.02	37.3101
1669.06	36.3247
1670.1	35.3571
1671.14	34.3885
1672.18	29.4345
1673.21	39.3168
1674.25	37.3428
1675.29	39.3368
1676.33	32.4128
1677.37	34.3894
1678.4	37.335
1679.44	36.3162
1680.48	33.3325
1681.52	36.279
1682.55	35.2843
1683.59	35.2761
1684.63	31.311
1685.66	36.2364
1686.7	36.2341
1687.73	35.2492
1688.77	32.2658
1689.81	33.2242
1690.84	33.2098
1691.88	36.1765
1692.91	34.1929
1693.95	37.111
1694.98	35.1074
1696.01	37.0771
1697.05	34.1251
1698.08	37.0463
1699.12	36.0312
1700.15	34.0558
1701.18	33.0573
1702.22	37.951
1703.25	37.9217
1704.28	37.9062
1705.32	33.9773
1706.35	36.911
1707.38	39.8149
1708.41	39.7649
1709.44	32.8562
1710.48	33.822
1711.51	35.7862
1712.54	31.8648
1713.57	35.7228
1714.6	34.7029
1715.63	35.6735
1716.66	30.7825
1717.69	38.5429
1718.72	38.4742
1719.75	36.5064
1720.78	34.5515
1721.81	35.4886
1722.84	39.335
1723.87	35.4158
1724.9	38.311
1725.93	38.2523
1726.96	34.356
1727.99	34.3399
1729.02	37.167
1730.05	35.1919
1731.07	44.8181
1732.1	37.1333
1733.13	40.976
1734.16	42.8454
1735.18	37.0044
1736.21	36.9631
1737.24	36.94
1738.26	38.8357
1739.29	38.7961
1740.32	36.8123
1741.34	37.7221
1742.37	41.5198
1743.4	39.5867
1744.42	38.6041
1745.45	38.59
1746.47	42.3941
1747.5	36.612
1748.52	38.4931
1749.55	38.496
1750.57	38.5212
1751.6	40.4439
1752.62	34.6691
1753.64	36.5424
1754.67	39.3689
1755.69	39.3419
1756.71	36.4443
1757.74	41.1561
1758.76	41.1636
1759.78	41.1617
1760.81	43.9987
1761.83	40.161
1762.85	39.2016
1763.87	39.2003
1764.89	45.885
1765.92	44.9478
1766.94	43.9868
1767.96	44.9191
1768.98	47.748
1770	41.9581
1771.02	46.7249
1772.04	44.856
1773.06	43.9247
1774.08	47.7458
1775.1	46.8034
1776.12	43.0305
1777.14	45.884
1778.16	45.849
1779.18	42.9493
1780.2	41.9845
1781.22	41.9927
1782.24	40.0947
1783.26	43.9274
1784.28	41.0841
1785.29	39.1979
1786.31	39.1818
1787.33	42.0578
1788.35	36.3948
1789.37	39.3154
1790.38	42.2202
1791.4	37.4169
1792.42	35.4665
1793.43	35.4717
1794.45	40.2644
1795.47	39.3354
1796.48	38.4136
1797.5	35.5549
1798.51	34.6054
1799.53	37.4805
1800.55	34.567
1801.56	35.5112
1802.58	38.3947
1803.59	33.6092
1804.61	35.5423
1805.62	43.2684
1806.64	36.5527
1807.65	34.6292
1808.66	35.5892
1809.68	34.6244
1810.69	34.623
1811.7	31.7203
1812.72	35.5762
1813.73	37.5185
1814.74	36.5813
1815.76	37.57
1816.77	32.7392
1817.78	30.7816
1818.79	33.6794
1819.8	38.5165
1820.82	34.6604
1821.83	36.607
1822.84	32.7447
1823.85	37.5788
1824.86	34.6703
1825.87	34.6772
1826.88	33.7049
1827.89	36.6153
1828.9	34.6707
1829.91	32.7169
1830.92	32.698
1831.93	36.5788
1832.94	33.6874
1833.95	36.5991
1834.96	41.4124
1835.97	30.7032
1836.98	30.8102
1837.99	35.5462
1839	41.344
1840	35.5805
1841.01	37.4391
1842.02	36.3992
1843.03	34.4326
1844.04	31.5326
1845.04	30.5629
1846.05	34.4257
1847.06	32.5217
1848.07	33.3666
1849.07	34.3297
1850.08	35.2593
1851.09	36.1708
1852.09	31.3397
1853.1	33.2522
1854.1	33.2328
1855.11	29.3565
1856.11	29.3221
1857.12	33.1429
1858.12	36.9542
1859.13	33.091
1860.13	32.1056
1861.14	35.9392
1862.14	29.2541
1863.15	27.316
1864.15	33.0189
1865.15	33.9429
1866.16	31.9862
1867.16	30.974
1868.16	32.8303
1869.17	30.9191
1870.17	29.0062
1871.17	35.648
1872.17	33.7284
1873.18	32.7522
1874.18	34.631
1875.18	31.7482
1876.18	33.589
1877.18	31.6553
1878.18	29.7145
1879.19	28.8119
1880.19	33.5633
1881.19	34.5
1882.19	32.5524
1883.19	31.5341
1884.19	32.4363
1885.19	33.39
1886.19	30.5947
1887.19	31.5286
1888.19	31.4919
1889.19	35.2104
1890.19	35.1844
1891.19	31.4329
1892.18	29.5366
1893.18	33.2825
1894.18	35.1048
1895.18	36.9614
1896.18	33.2085
1897.18	35.1054
1898.17	36.0496
1899.17	35.0823
1900.17	39.7496
1901.16	36.9241
1902.16	34.1264
1903.16	36.9553
1904.16	30.3535
1905.15	32.2225
1906.15	37.8422
1907.14	36.8702
1908.14	35.9298
1909.14	41.5776
1910.13	33.1455
1911.13	29.4136
1912.12	37.8941
1913.12	30.3472
1914.11	36.9522
1915.11	35.0963
1916.1	35.1038
1917.1	30.3645
1918.09	34.1144
1919.08	31.3011
1920.08	34.1736
1921.07	31.3395
1922.06	39.8705
1923.06	36.0768
1924.05	32.275
1925.04	37.9217
1926.04	33.2153
1927.03	37.9798
1928.02	36.1039
1929.01	33.2711
1930	37.0863
1931	32.374
1931.99	34.2633
1932.98	38.0326
1933.97	34.2377
1934.96	35.2837
1935.95	35.3561
1936.94	30.5516
1937.93	35.279
1938.92	33.3673
1939.91	35.286
1940.9	32.4451
1941.89	31.5152
1942.88	29.6139
1943.87	35.3149
1944.86	32.4704
1945.85	33.4523
1946.84	37.2948
1947.83	34.4146
1948.82	31.536
1949.8	33.4643
1950.79	36.3805
1951.78	33.5527
1952.77	37.4165
1953.76	33.573
1954.74	30.6194
1955.73	33.4715
1956.72	30.6443
1957.7	39.3137
1958.69	36.4448
1959.68	31.6228
1960.66	30.6403
1961.65	36.3712
1962.63	31.5674
1963.62	33.4867
1964.61	35.4123
1965.59	38.2829
1966.58	31.5731
1967.56	31.5826
1968.55	35.4281
1969.53	38.2855
1970.52	36.317
1971.5	40.1267
1972.48	35.3242
1973.47	41.0653
1974.45	37.1993
1975.44	40.0725
1976.42	38.1696
1977.4	41.0445
1978.39	41.0178
1979.37	40.999
1980.35	44.8314
1981.33	45.7596
1982.31	43.8217
1983.3	43.7891
1984.28	48.5356
1985.26	46.5951
1986.24	47.53
1987.22	49.4537
1988.21	47.5006
1989.19	51.1669
1990.17	49.946
1991.15	47.7533
1992.13	49.6826
1993.11	47.7136
1994.09	49.4598
1995.07	52.6969
1996.05	53.7355
1997.03	53.8078
1998.01	53.8612
1998.99	56.9886
1999.97	51.8741
2000.95	57.121
2001.92	50.9932
2002.9	55.8338
2003.88	56.4769
2004.86	56.5273
2005.84	56.0176
2006.81	54.0031
2007.79	59.591
2008.77	53.2526
2009.75	56.1171
2010.73	56.685
2011.7	53.7463
2012.68	51.4952
2013.67	56.1377
2014.66	53.2275
2015.64	56.0188
2016.63	51.3454
2017.62	53.2564
2018.61	53.183
2019.6	53.1014
2020.58	52.1394
2021.57	53.0751
2022.56	49.3124
2023.55	49.2643
2024.54	45.4812
2025.52	50.0864
2026.51	47.2449
2027.5	51.1064
2028.48	48.2427
2029.47	45.5093
2030.45	46.3023
2031.44	48.1867
2032.43	44.4591
2033.41	44.5132
2034.4	48.255
2035.38	46.3126
2036.37	47.3442
2037.35	43.5877
2038.34	43.573
2039.32	38.8725
2040.31	38.8372
2041.29	43.4593
2042.27	34.1163
2043.26	38.7581
2044.24	41.599
2045.23	44.369
2046.21	42.589
2047.19	38.8138
2048.17	37.8304
2049.16	37.8376
2050.14	37.8771
2051.12	39.7717
2052.11	38.813
2053.09	35.0872
2054.07	35.1225
2055.05	37.0023
2056.03	37.9174
2057.01	38.8377
2058	38.8445
2058.98	36.0649
2059.96	35.1435
2060.94	39.8076
2061.92	37.9488
2062.9	37.0187
2063.88	33.2907
2064.86	37.0511
2065.84	34.2687
2066.82	37.1045
2067.8	33.3603
2068.78	37.1331
2069.76	28.6635
2070.73	31.4772
2071.71	31.4949
2072.69	34.361
2073.67	30.5866
2074.65	30.5915
2075.63	33.4553
2076.6	37.2652
2077.58	36.3008
2078.56	34.4031
2079.54	33.4757
2080.51	29.7271
2081.49	33.5031
2082.47	33.5005
2083.45	32.5575
2084.42	32.5528
2085.4	33.4967
2086.37	37.2864
2087.35	31.636
2088.32	32.5888
2089.3	31.6453
2090.28	30.7169
2091.25	32.6194
2092.23	28.8483
2093.2	30.7807
2094.18	32.7083
2095.15	33.6629
2096.13	28.8905
2097.1	32.68
2098.07	28.8601
2099.05	30.7487
2100.02	30.7416
2101	30.7449
2101.97	26.0123
2102.94	30.7564
2103.92	33.5863
2104.89	31.6914
2105.86	29.8101
2106.83	27.9196
2107.8	30.7707
2108.78	33.587
2109.75	34.5344
2110.72	31.6892
2111.69	29.7843
2112.66	30.7223
2113.63	28.8364
2114.61	27.8878
2115.58	31.6864
2116.55	27.8699
2117.52	30.7056
2118.49	26.8943
2119.46	28.7617
2120.43	26.8427
2121.4	30.6375
2122.37	29.7133
2123.34	30.6772
2124.31	32.5709
2125.28	28.7344
2126.25	27.7458
2127.21	31.5016
2128.18	27.7045
2129.15	26.752
2130.12	30.5233
2131.09	27.6777
2132.06	26.7151
2133.02	30.4716
2133.99	28.5806
2134.96	31.4107
2135.93	30.4579
2136.89	32.3127
2137.86	28.5452
2138.83	30.4175
2139.79	32.3076
2140.76	31.3362
2141.73	29.4421
2142.69	29.4243
2143.66	30.3861
2144.62	27.5035
2145.59	25.6217
2146.55	28.4345
2147.52	29.3601
2148.48	31.2219
2149.45	31.2003
2150.42	29.2866
2151.38	27.4021
2152.34	32.1019
2153.31	31.151
2154.27	33.0065
2155.24	26.4075
2156.2	27.3046
2157.16	29.1602
2158.13	27.2999
2159.09	28.2359
2160.05	28.2169
2161.01	29.1219
2161.98	30.0418
2162.94	30.0374
2163.9	25.3591
2164.86	29.066
2165.83	29.9947
2166.79	30.9176
2167.75	30.8924
2168.71	28.9878
2169.67	30.8557
2170.63	25.3036
2171.59	29.9489
2172.56	28.9673
2173.51	26.1671
2174.48	27.1009
2175.44	26.1696
2176.4	28.0195
2177.36	26.1505
2178.32	26.1493
2179.28	27.0596
2180.23	31.7011
2181.19	27.0514
2182.15	30.7522
2183.11	29.8103
2184.07	24.219
2185.03	31.6212
2185.99	26.9956
2186.95	28.8699
2187.9	29.8276
2188.86	27.0273
2189.82	30.7058
2190.78	29.7631
2191.73	28.8399
2192.69	28.847
2193.65	27.9333
2194.6	29.8301
2195.56	32.613
2196.52	27.9353
2197.47	27.9069
2198.43	26.9764
2199.38	30.7191
2200.34	31.6904
2201.3	29.8782
2202.25	26.0631
2203.21	25.1746
2204.16	25.2616
2205.12	28.0093
2206.07	27.0106
2207.03	32.5836
2207.98	28.8797
2208.93	27.0385
2209.89	30.7697
2210.84	27.0494
2211.8	29.8608
2212.75	29.8778
2213.7	29.8627
2214.66	27.0759
2215.61	27.0908
2216.56	25.2226
2217.51	28.0179
2218.47	28.0174
2219.42	23.3572
2220.37	26.1706
2221.32	27.0972
2222.27	28.0037
2223.23	27.0693
2224.18	27.0896
2225.13	24.3092
2226.08	30.8854
2227.03	27.1585
2227.98	25.2952
2228.93	27.1618
2229.88	29.0362
2230.83	30.9361
2231.78	26.2645
2232.73	25.3425
2233.68	29.1221
2234.63	22.5422
2235.58	27.2262
2236.53	27.2201
2237.48	24.4056
2238.43	22.5526
2239.38	25.4072
2240.33	29.1658
2241.27	25.4027
2242.22	26.3508
2243.17	25.4134
2244.12	26.3446
2245.07	26.354
2246.01	26.3832
2246.96	26.3988
2247.91	27.3547
2248.85	28.2935
2249.8	27.3455
2250.75	25.4451
2251.69	27.3142
2252.64	26.3728
2253.59	27.3555
2254.53	24.5339
2255.48	29.2749
2256.42	27.3833
2257.37	28.349
2258.32	26.4612
2259.26	25.5181
2260.2	25.527
2261.15	27.438
2262.1	30.3077
2263.04	25.561
2263.98	23.6815
2264.93	25.6215
2265.87	25.636
2266.81	22.7568
2267.76	29.415
2268.7	30.3483
2269.65	21.7785
2270.59	26.5799
2271.53	30.4209
2272.47	25.6526
2273.42	24.698
2274.36	28.5292
2275.3	23.7468
2276.24	24.7076
2277.18	25.6862
2278.13	26.6775
2279.07	22.8511
2280.01	25.7114
2280.95	21.8482
2281.89	27.5862
2282.83	26.6394
2283.77	24.7474
2284.71	25.747
2285.65	23.8367
2286.59	26.7056
2287.54	26.7326
2288.47	26.7426
2289.41	28.6446
2290.35	29.5672
2291.29	26.6825
2292.23	25.7444
2293.17	31.5433
2294.11	27.7014
2295.05	24.7941
2295.99	27.6663
2296.93	27.6413
2297.86	29.582
2298.8	29.609
2299.74	23.8447
2300.68	24.8085
2301.61	27.7148
2302.55	26.7465
2303.49	27.7059
2304.43	22.8843
2305.36	24.8277
2306.3	27.7337
2307.24	25.8031
2308.17	26.7586
2309.11	25.7865
2310.04	25.807
2310.98	26.7801
2311.92	26.736
2312.85	27.6737
2313.79	28.6442
2314.72	26.7457
2315.66	28.6944
2316.59	25.7576
2317.52	24.7792
2318.46	29.6099
2319.39	26.6932
2320.33	32.4715
2321.26	29.5823
2322.2	32.5035
2323.13	35.4218
2324.06	35.4284
2325	47.9823
2325.93	67.2398
2326.86	209.977
2327.79	281.147
2328.73	82.5294
2329.66	53.5771
2330.59	37.1963
2331.52	29.484
2332.46	28.5264
2333.39	30.4318
2334.32	28.4902
2335.25	23.6596
2336.18	26.5426
2337.11	24.6104
2338.04	26.525
2338.97	24.595
2339.91	26.5154
2340.84	26.4982
2341.77	26.4635
2342.7	27.3987
2343.63	31.2255
2344.56	27.3883
2345.49	23.5473
2346.41	24.4835
2347.34	26.3892
2348.27	28.3012
2349.2	27.344
2350.13	29.2118
2351.06	26.2152
2351.99	27.2736
2352.91	26.2755
2353.84	28.1397
2354.77	26.2327
2355.7	26.2315
2356.63	26.2102
2357.55	23.3224
2358.48	24.257
2359.41	26.1428
2360.33	28.9735
2361.26	26.0981
2362.19	22.2786
2363.11	27.9341
2364.04	30.754
2364.97	23.1689