File: Data/3-Raman/raw/bu19(2)w-a-ff2-fi03-v_1800 (450-850nm)_532nm_edge_100%_x100_vis_lwd_h100um_30sx2_01.txt
#Acq. time (s)=	30
#Accumulations=	2
#Range (cm-¹)=	1200...2365
#Windows=	3
#Auto scanning=	Off
#Autofocus=	Off
#Macrospot=	Off
#AutoExposure=	Off
#Spike filter=	Multiple accum.
#Delay time (s)=	2
#Binning=	1
#Readout mode=	Signal
#DeNoise=	Off
#ICS correction=	On
#Dark correction=	Off
#Inst. Process=	Off
#Detector Gain=	Best Dynamic
#Detector ADC=	50 kHz HS
#Detector temperature (°C)=	-60.09
#Instrument=	LabRAM HR Evol
#Detector=	SIN-EM FIVIS
#Objective=	x100_VIS_LWD
#Grating=	1800 (450-850nm)
#ND Filter=	100%
#Laser=	532nm_Edge
#Hole=	100.021
#Temperature=	0
#Range=	Visible
#StageXY=	75x50mm Scan+
#StageZ=	Z motor
#X (µm)=	0
#Y (µm)=	0
#Z (µm)=	-43.7
#Full time(mm:ss)=	3:22
#Project=	21_11_26
#Sample=	BU19(2)w
#Site=
#Title=	BU19(2)w-A-FF2-FI03-V_1800 (450-850nm)_532nm_Edge_100%_x100_VIS_LWD_H100um_30sX2
#Remark=
#Date=	26.11.2021 15:16
#Acquired=	26.11.2021 15:16:39
1202.72	358.652
1203.84	349.011
1204.95	336.831
1206.06	335.16
1207.17	325.846
1208.28	339.313
1209.39	328.16
1210.5	330.04
1211.61	328.363
1212.72	316.086
1213.83	330.594
1214.94	326.189
1216.05	340.925
1217.16	320.127
1218.27	333.463
1219.38	306.62
1220.49	319.107
1221.6	325.254
1222.71	321.539
1223.81	314.492
1224.92	319.301
1226.03	335.051
1227.14	332.768
1228.25	310.84
1229.35	305.789
1230.46	319.159
1231.57	322.353
1232.67	319.095
1233.78	323.122
1234.89	309.48
1235.99	310.567
1237.1	315.646
1238.2	310.933
1239.31	319.893
1240.41	307.096
1241.52	321.699
1242.62	318.326
1243.73	321.466
1244.83	314.019
1245.94	320.951
1247.04	299.73
1248.14	315.248
1249.25	320.192
1250.35	335.767
1251.45	329.087
1252.56	309.944
1253.66	332.576
1254.76	323.263
1255.87	324.252
1256.97	331.528
1258.07	332.385
1259.17	315.405
1260.27	317.594
1261.37	331.735
1262.48	373.136
1263.58	374.103
1264.68	342.779
1265.78	332.93
1266.88	323.422
1267.98	324.682
1269.08	348.06
1270.18	327.005
1271.28	330.772
1272.38	326.513
1273.47	326.802
1274.57	322.819
1275.67	345.829
1276.77	322.894
1277.87	320.957
1278.97	343.233
1280.07	352.66
1281.16	394.634
1282.26	568.478
1283.36	1036.31
1284.45	729.494
1285.55	396.809
1286.65	341.895
1287.75	332.172
1288.84	325.66
1289.94	320.483
1291.03	318.359
1292.13	328.745
1293.22	301.236
1294.32	337.356
1295.42	318.346
1296.51	312.585
1297.61	308.204
1298.7	305.803
1299.79	298.138
1300.89	307.626
1301.98	306.507
1303.08	307.539
1304.17	299.919
1305.26	306.114
1306.35	286.745
1307.45	306.619
1308.54	300.205
1309.63	314.961
1310.73	318.07
1311.82	309.568
1312.91	314.892
1314	316.791
1315.09	307.212
1316.18	314.661
1317.28	306.05
1318.37	310.265
1319.46	289.043
1320.55	307.955
1321.64	307.624
1322.73	323.049
1323.82	289.081
1324.91	297.424
1326	309.756
1327.09	302.808
1328.18	313.773
1329.27	301.392
1330.35	307.571
1331.44	293.492
1332.53	304.522
1333.62	297.688
1334.71	300.382
1335.79	320.997
1336.88	307.052
1337.97	316.248
1339.06	302.268
1340.14	303.194
1341.23	307.299
1342.32	307.069
1343.4	303.543
1344.49	300.267
1345.58	295.828
1346.66	321.386
1347.75	295.851
1348.83	289.346
1349.92	312.973
1351	301.163
1352.09	303.94
1353.17	297.787
1354.25	290.699
1355.34	297.158
1356.42	293.898
1357.51	312.331
1358.59	299.561
1359.67	316.863
1360.76	306.076
1361.84	300.687
1362.92	293.212
1364	307.706
1365.09	304.472
1366.17	308.228
1367.25	301.566
1368.33	311.781
1369.41	334.507
1370.5	306.394
1371.58	298.784
1372.66	314.719
1373.74	289.65
1374.82	316.23
1375.9	319.201
1376.98	314.819
1378.06	326.944
1379.14	325.327
1380.22	316.799
1381.3	343.77
1382.38	333.011
1383.46	338.554
1384.54	375.151
1385.61	523.185
1386.69	1458.15
1387.77	1152.99
1388.85	438.089
1389.93	351.625
1391	325.326
1392.08	312.647
1393.16	311.257
1394.23	304.883
1395.31	307.827
1396.39	303.725
1397.46	308.568
1398.54	313.504
1399.62	298.185
1400.69	294.092
1401.77	289.007
1402.84	298.597
1403.92	291.599
1404.99	313.845
1406.07	310.447
1407.14	337.919
1408.22	373.798
1409.29	376.883
1410.37	307.111
1411.44	311.801
1412.51	292.164
1413.59	300.1
1414.66	294.485
1415.73	307.867
1416.81	298.621
1417.88	291.469
1418.95	267.783
1420.02	307.675
1421.1	283.697
1422.17	299.011
1423.24	295.454
1424.31	302.516
1425.38	284.988
1426.45	297.276
1427.52	285.583
1428.59	275.973
1429.67	286.193
1430.74	274.052
1431.81	282.533
1432.87	289.44
1433.95	254.048
1435.01	266.332
1436.08	303.113
1437.15	277.298
1438.22	273.018
1439.29	291.453
1440.36	275.173
1441.43	293.608
1442.49	276.035
1443.56	300.521
1444.63	277.796
1445.7	287.158
1446.77	285.926
1447.83	292.883
1448.9	281.592
1449.97	278.363
1451.03	277.088
1452.1	291.222
1453.17	276.757
1454.23	277.724
1455.3	287.844
1456.36	265.262
1457.43	280.407
1458.49	284.349
1459.56	300.689
1460.62	262.633
1461.69	276.737
1462.75	291.774
1463.82	281.164
1464.88	275.253
1465.94	279.377
1467.01	277.134
1468.07	275.958
1469.13	272.751
1470.2	258.183
1471.26	270.158
1472.32	277.021
1473.39	264.647
1474.45	274.577
1475.51	285.718
1476.57	280.415
1477.63	272.023
1478.69	302.306
1479.76	280.652
1480.82	268.039
1481.88	298.262
1482.94	282.14
1484	287.17
1485.06	270.206
1486.12	265.96
1487.18	292.231
1488.24	255.504
1489.3	288.563
1490.36	290.394
1491.42	275.964
1492.48	275.827
1493.53	273.662
1494.59	282.645
1495.65	270.286
1496.71	284.026
1497.77	280.805
1498.82	274.627
1499.88	273.581
1500.94	278.546
1502	290.428
1503.05	287.176
1504.11	274.812
1505.17	276.754
1506.22	279.398
1507.28	274.28
1508.34	268.129
1509.39	288.18
1510.45	292.154
1511.5	287.734
1512.56	263.899
1513.61	278.529
1514.67	281.631
1515.72	280.253
1516.78	277.859
1517.83	270.686
1518.88	302.79
1519.94	276.688
1520.99	285.572
1522.05	270.473
1523.1	277.259
1524.15	268.792
1525.2	277.57
1526.26	284.604
1527.31	273.638
1528.36	282.436
1529.41	272.198
1530.47	285.022
1531.52	286.123
1532.57	289.977
1533.62	281.181
1534.67	265.074
1535.72	269.844
1536.77	276.334
1537.82	287.901
1538.87	284.602
1539.92	287.965
1540.97	268.326
1542.02	275.047
1543.07	272.637
1544.12	268.185
1545.17	263.259
1546.22	268.445
1547.27	265.397
1548.32	266.139
1549.37	275.868
1550.42	285.878
1551.46	279.669
1552.51	267.524
1553.56	273.216
1554.61	279.903
1555.65	287.534
1556.7	279.386
1557.75	278.325
1558.79	263.953
1559.84	275.509
1560.89	268.25
1561.93	280.192
1562.98	281.252
1564.02	268.086
1565.07	273.221
1566.11	277.243
1567.16	285.419
1568.2	277.56
1569.25	275.526
1570.29	265.271
1571.34	280.145
1572.38	273.899
1573.43	272.605
1574.47	263.481
1575.51	258.665
1576.56	268.59
1577.6	280.103
1578.64	282.624
1579.69	283.491
1580.73	263.531
1581.77	269.27
1582.81	270.983
1583.85	275.796
1584.9	268.73
1585.94	272.59
1586.98	268.267
1588.02	290.927
1589.06	282.97
1590.1	270.039
1591.14	259.063
1592.18	268.85
1593.22	271.442
1594.26	266.917
1595.3	287.729
1596.34	271.617
1597.38	280.483
1598.42	273.438
1599.46	290.92
1600.5	283.647
1601.54	269.319
1602.58	264.945
1603.62	269.518
1604.66	278.241
1605.69	280.14
1606.73	274.241
1607.77	261.878
1608.81	276.655
1609.84	284.193
1610.88	272.559
1611.92	256.555
1612.95	275.716
1613.99	281.116
1615.03	262.184
1616.06	265.555
1617.1	277.597
1618.13	282.062
1619.17	266.15
1620.2	271.041
1621.24	267.007
1622.27	268.479
1623.31	266.926
1624.34	276.197
1625.38	278.53
1626.41	284.708
1627.45	268.395
1628.48	269.697
1629.51	277.381
1630.55	268.724
1631.53	256.289
1632.57	284.859
1633.62	260.081
1634.66	266.92
1635.71	277.62
1636.75	276.402
1637.8	259.395
1638.84	266.091
1639.89	266.956
1640.93	276.724
1641.98	262.82
1643.02	272.492
1644.06	275.282
1645.11	280.952
1646.15	253.359
1647.19	267.901
1648.24	273.599
1649.28	274.701
1650.32	280.479
1651.37	285.532
1652.41	264.771
1653.45	282.326
1654.49	266.498
1655.53	274.377
1656.57	294.272
1657.62	273.431
1658.66	267.298
1659.7	268.016
1660.74	260.954
1661.78	264.963
1662.82	269.083
1663.86	278.875
1664.9	264.754
1665.94	258.386
1666.98	264.507
1668.02	244.512
1669.06	271.09
1670.1	255.357
1671.14	251.466
1672.18	267.117
1673.21	263.071
1674.25	254.114
1675.29	261.061
1676.33	266.939
1677.37	260.906
1678.4	267.59
1679.44	263.346
1680.48	255.227
1681.52	259.962
1682.55	268.728
1683.59	265.628
1684.63	254.58
1685.66	269.225
1686.7	261.231
1687.73	252.283
1688.77	256.007
1689.81	257.685
1690.84	242.704
1691.88	248.592
1692.91	254.365
1693.95	266.817
1694.98	249.756
1696.01	242.776
1697.05	248.636
1698.08	243.399
1699.12	253.941
1700.15	257.747
1701.18	247.724
1702.22	262.23
1703.25	263.916
1704.28	268.643
1705.32	250.888
1706.35	264.467
1707.38	250.362
1708.41	258.792
1709.44	257.381
1710.48	240.563
1711.51	268.925
1712.54	238.46
1713.57	255.588
1714.6	263.998
1715.63	238.478
1716.66	249.098
1717.69	253.546
1718.72	246.2
1719.75	259.618
1720.78	250.723
1721.81	259.144
1722.84	250.026
1723.87	252.637
1724.9	255.351
1725.93	267.484
1726.96	245.946
1727.99	236.067
1729.02	256.756
1730.05	252.516
1731.07	243.561
1732.1	241.791
1733.13	250.265
1734.16	247.887
1735.18	248.421
1736.21	248.065
1737.24	269.959
1738.26	233.142
1739.29	262.604
1740.32	249.614
1741.34	250.165
1742.37	251.787
1743.4	264.99
1744.42	248.472
1745.45	238.735
1746.47	244.262
1747.5	242.925
1748.52	246.478
1749.55	241.64
1750.57	257.005
1751.6	267.512
1752.62	248.037
1753.64	252.478
1754.67	249.302
1755.69	241.424
1756.71	243.945
1757.74	249.276
1758.76	258.752
1759.78	252.948
1760.81	253.71
1761.83	251.522
1762.85	258.99
1763.87	258.901
1764.89	248.51
1765.92	257.07
1766.94	244.556
1767.96	248.168
1768.98	251.747
1770	243.572
1771.02	244.532
1772.04	239.861
1773.06	255.104
1774.08	250.337
1775.1	254.108
1776.12	267.581
1777.14	248.397
1778.16	230.972
1779.18	239.223
1780.2	253.336
1781.22	254.254
1782.24	247.544
1783.26	244.732
1784.28	239.974
1785.29	240.018
1786.31	254.143
1787.33	243.649
1788.35	241.129
1789.37	238.495
1790.38	235.715
1791.4	240.357
1792.42	242.921
1793.43	255.332
1794.45	243.769
1795.47	247.706
1796.48	241.148
1797.5	243.142
1798.51	250.839
1799.53	239.158
1800.55	242.718
1801.56	232.919
1802.58	234.769
1803.59	239.628
1804.61	229.038
1805.62	241.632
1806.64	234.965
1807.65	236.837
1808.66	237.696
1809.68	236.647
1810.69	226.918
1811.7	252.796
1812.72	229.576
1813.73	241.156
1814.74	248.022
1815.76	242.299
1816.77	235.467
1817.78	226.509
1818.79	239.955
1819.8	248.608
1820.82	237.003
1821.83	239.908
1822.84	230.212
1823.85	219.445
1824.86	246.44
1825.87	247.382
1826.88	239.53
1827.89	221.076
1828.9	237.417
1829.91	244.001
1830.92	235.069
1831.93	241.823
1832.94	229.253
1833.95	235.015
1834.96	246.359
1835.97	229.409
1836.98	240.839
1837.99	246.712
1839	233.992
1840	239.05
1841.01	227.807
1842.02	246.566
1843.03	233.687
1844.04	234.53
1845.04	242.135
1846.05	231.474
1847.06	228.691
1848.07	251.824
1849.07	230.571
1850.08	235.078
1851.09	224.089
1852.09	231.498
1853.1	231.363
1854.1	223.468
1855.11	234.611
1856.11	204.56
1857.12	225.479
1858.12	249.207
1859.13	224.001
1860.13	242.836
1861.14	227.521
1862.14	246.671
1863.15	226.299
1864.15	241.259
1865.15	231.402
1866.16	229.067
1867.16	221.879
1868.16	214.81
1869.17	237.481
1870.17	226.859
1871.17	251.409
1872.17	234.089
1873.18	223.375
1874.18	239.294
1875.18	242.736
1876.18	219.518
1877.18	226.719
1878.18	230.979
1879.19	237.883
1880.19	225.654
1881.19	217.931
1882.19	230.709
1883.19	232.909
1884.19	235.353
1885.19	217.445
1886.19	223.283
1887.19	236.348
1888.19	227.5
1889.19	230.823
1890.19	236.213
1891.19	247.551
1892.18	221.949
1893.18	238.667
1894.18	219.364
1895.18	228.531
1896.18	238.827
1897.18	222.887
1898.17	229.415
1899.17	230.093
1900.17	232.624
1901.16	229.679
1902.16	221.286
1903.16	238.186
1904.16	227.628
1905.15	244.389
1906.15	232.89
1907.14	224.144
1908.14	227.811
1909.14	239.073
1910.13	237.305
1911.13	222.426
1912.12	231.795
1913.12	224.1
1914.11	232.576
1915.11	227.983
1916.1	234.561
1917.1	222.056
1918.09	229.362
1919.08	231.291
1920.08	240.019
1921.07	222.94
1922.06	217.342
1923.06	226.645
1924.05	224.533
1925.04	236.579
1926.04	230.016
1927.03	220.711
1928.02	230.212
1929.01	218.828
1930	220.799
1931	233.277
1931.99	224.589
1932.98	214.844
1933.97	220.458
1934.96	219.123
1935.95	230.967
1936.94	224.893
1937.93	228.371
1938.92	217.766
1939.91	221.592
1940.9	227.359
1941.89	229.374
1942.88	229.362
1943.87	206.201
1944.86	232.021
1945.85	225.456
1946.84	233.152
1947.83	229.17
1948.82	218.503
1949.8	219.494
1950.79	220.667
1951.78	218.999
1952.77	221.957
1953.76	214.182
1954.74	208.775
1955.73	230.573
1956.72	219.362
1957.7	213.706
1958.69	234.852
1959.68	232.728
1960.66	224.799
1961.65	212.993
1962.63	224.397
1963.62	233.917
1964.61	213.714
1965.59	225.09
1966.58	221.261
1967.56	231.831
1968.55	222.144
1969.53	216.128
1970.52	231.104
1971.5	223.162
1972.48	232.634
1973.47	221.91
1974.45	226.43
1975.44	232.084
1976.42	220.587
1977.4	233.916
1978.39	233.668
1979.37	208.548
1980.35	223.788
1981.33	224.495
1982.31	223.329
1983.3	214.446
1984.28	219.903
1985.26	236.882
1986.24	237.635
1987.22	229.958
1988.21	236.343
1989.19	230.018
1990.17	238.387
1991.15	228.618
1992.13	222.623
1993.11	228.312
1994.09	238.569
1995.07	236.633
1996.05	239.259
1997.03	235.709
1998.01	234.313
1998.99	234.415
1999.97	239.934
2000.95	230.123
2001.92	225.32
2002.9	238.066
2003.88	235.358
2004.86	238.629
2005.84	232.567
2006.81	239.562
2007.79	241.711
2008.77	234.304
2009.75	238.488
2010.73	234.206
2011.7	229.402
2012.68	241.523
2013.67	234.644
2014.66	241.757
2015.64	248.197
2016.63	230.426
2017.62	221.143
2018.61	227.396
2019.6	247.651
2020.58	229.718
2021.57	228.755
2022.56	238.025
2023.55	236.843
2024.54	231.942
2025.52	231.614
2026.51	230.465
2027.5	234.754
2028.48	225.118
2029.47	225.427
2030.45	222.871
2031.44	231.332
2032.43	228.537
2033.41	231.59
2034.4	219.432
2035.38	229.343
2036.37	230.719
2037.35	220.335
2038.34	221.177
2039.32	227.552
2040.31	217.064
2041.29	223.354
2042.27	240.932
2043.26	220.305
2044.24	226.117
2045.23	235.278
2046.21	220.766
2047.19	210.269
2048.17	231.42
2049.16	234.243
2050.14	224.195
2051.12	213.116
2052.11	226.972
2053.09	210.2
2054.07	217.869
2055.05	216.034
2056.03	230.863
2057.01	214.869
2058	215.822
2058.98	216.886
2059.96	213.21
2060.94	215.91
2061.92	215.026
2062.9	208.487
2063.88	221.699
2064.86	227.376
2065.84	218.171
2066.82	216.391
2067.8	221.148
2068.78	219.337
2069.76	223.006
2070.73	228.592
2071.71	211.779
2072.69	215.8
2073.67	210.082
2074.65	217.634
2075.63	208.434
2076.6	211.454
2077.58	211.32
2078.56	214.069
2079.54	219.815
2080.51	225.666
2081.49	219.958
2082.47	211.421
2083.45	219.922
2084.42	209.48
2085.4	203.786
2086.37	221.78
2087.35	218.129
2088.32	220.996
2089.3	214.375
2090.28	222.063
2091.25	208.834
2092.23	223.182
2093.2	229.12
2094.18	214.092
2095.15	204.594
2096.13	208.249
2097.1	222.412
2098.07	223.195
2099.05	232.6
2100.02	207.86
2101	217.359
2101.97	226.007
2102.94	221.208
2103.92	227.712
2104.89	222.976
2105.86	220.242
2106.83	220.307
2107.8	218.385
2108.78	204.845
2109.75	218.109
2110.72	229.522
2111.69	215.222
2112.66	219.874
2113.63	215.211
2114.61	201.905
2115.58	211.374
2116.55	221.698
2117.52	220.634
2118.49	227.163
2119.46	224.064
2120.43	215.341
2121.4	217.252
2122.37	218.357
2123.34	221.297
2124.31	226.944
2125.28	219.988
2126.25	213.032
2127.21	227.945
2128.18	203.24
2129.15	206.01
2130.12	215.38
2131.09	211.508
2132.06	218.912
2133.02	205.54
2133.99	225.317
2134.96	210.197
2135.93	217.669
2136.89	202.356
2137.86	205.193
2138.83	214.513
2139.79	216.416
2140.76	216.206
2141.73	212.352
2142.69	207.506
2143.66	226.468
2144.62	197.794
2145.59	214.694
2146.55	213.682
2147.52	222.022
2148.48	212.491
2149.45	221.718
2150.42	215.808
2151.38	210.1
2152.34	212.042
2153.31	212.877
2154.27	220.233
2155.24	221.767
2156.2	213.971
2157.16	214.795
2158.13	218.583
2159.09	205.496
2160.05	205.346
2161.01	209.795
2161.98	215.286
2162.94	221.771
2163.9	209.52
2164.86	219.592
2165.83	219.555
2166.79	207.367
2167.75	221.149
2168.71	208.729
2169.67	213.421
2170.63	211.783
2171.59	200.522
2172.56	215.962
2173.51	200.059
2174.48	206.585
2175.44	219.569
2176.4	208.338
2177.36	221.247
2178.32	214.724
2179.28	220.136
2180.23	219.188
2181.19	213.549
2182.15	208.807
2183.11	204.986
2184.07	205.693
2185.03	204.669
2185.99	215.834
2186.95	203.911
2187.9	208.742
2188.86	220.691
2189.82	211.155
2190.78	211.96
2191.73	209.192
2192.69	209.229
2193.65	219.528
2194.6	210.515
2195.56	208.603
2196.52	204.651
2197.47	214.636
2198.43	213.674
2199.38	188.804
2200.34	207.637
2201.3	211.679
2202.25	212.817
2203.21	200.121
2204.16	205.461
2205.12	204.13
2206.07	225.003
2207.03	220.303
2207.98	205.518
2208.93	221.477
2209.89	196.369
2210.84	203.843
2211.8	211.397
2212.75	214.3
2213.7	202.057
2214.66	213.317
2215.61	199.418
2216.56	215.27
2217.51	202.144
2218.47	216.131
2219.42	204.054
2220.37	220.016
2221.32	202.186
2222.27	206.64
2223.23	208.488
2224.18	199.286
2225.13	201.334
2226.08	204.305
2227.03	216.617
2227.98	207.324
2228.93	207.244
2229.88	206.287
2230.83	213.003
2231.78	214.099
2232.73	207.654
2233.68	209.655
2234.63	219.117
2235.58	223.631
2236.53	205.701
2237.48	202.926
2238.43	202.232
2239.38	211.875
2240.33	213.64
2241.27	213.704
2242.22	207.124
2243.17	210.94
2244.12	213.658
2245.07	215.61
2246.01	211.11
2246.96	203.654
2247.91	223.59
2248.85	197.967
2249.8	214.975
2250.75	206.385
2251.69	207.143
2252.64	211.892
2253.59	202.692
2254.53	209.481
2255.48	213.265
2256.42	208.547
2257.37	196.321
2258.32	205.88
2259.26	204.021
2260.2	205.981
2261.15	197.486
2262.1	198.531
2263.04	209.076
2263.98	213.095
2264.93	199.045
2265.87	215.383
2266.81	217.158
2267.76	203.603
2268.7	208.217
2269.65	203.55
2270.59	206.638
2271.53	213.447
2272.47	208.753
2273.42	209.717
2274.36	201.118
2275.3	199.218
2276.24	211.683
2277.18	208.01
2278.13	209.213
2279.07	203.558
2280.01	198.581
2280.95	205.068
2281.89	205.901
2282.83	207.896
2283.77	204.263
2284.71	206.486
2285.65	214.289
2286.59	201.628
2287.54	197.004
2288.47	215.368
2289.41	202.655
2290.35	193.715
2291.29	194.66
2292.23	202.523
2293.17	208.439
2294.11	207.548
2295.05	208.37
2295.99	191.854
2296.93	207.06
2297.86	202.348
2298.8	198.661
2299.74	199.764
2300.68	210.357
2301.61	204.647
2302.55	204.61
2303.49	214.205
2304.43	206.51
2305.36	203.707
2306.3	207.618
2307.24	210.523
2308.17	203.66
2309.11	225.824
2310.04	205.686
2310.98	203.785
2311.92	202.472
2312.85	209.973
2313.79	197.451
2314.72	198.641
2315.66	186.159
2316.59	197.484
2317.52	199.306
2318.46	211.862
2319.39	198.186
2320.33	198.089
2321.26	205.832
2322.2	205.011
2323.13	211.876
2324.06	204.162
2325	215.669
2325.93	229.884
2326.86	232.555
2327.79	253.544
2328.73	234.177
2329.66	210.878
2330.59	212.756
2331.52	203.062
2332.46	202.124
2333.39	200.041
2334.32	207.613
2335.25	212.247
2336.18	206.448
2337.11	199.634
2338.04	209.172
2338.97	209.099
2339.91	209.072
2340.84	208.925
2341.77	193.288
2342.7	195.019
2343.63	204.537
2344.56	210.255
2345.49	204.437
2346.41	201.368
2347.34	198.409
2348.27	205.076
2349.2	206.022
2350.13	202.806
2351.06	205.614
2351.99	202.588
2352.91	197.477
2353.84	199.061
2354.77	207.609
2355.7	202.824
2356.63	205.504
2357.55	198.56
2358.48	211.721
2359.41	200.19
2360.33	210.486
2361.26	201.719
2362.19	209.063
2363.11	194.624
2364.04	201.104
2364.97	204.739