File: Data/3-Raman/raw/bu19w-ff07a-fi02-v_150 (500nm)_532nm_edge_10%_x100_vis_lwd_h50um_20sx2_01.txt
#Acq. time (s)=	20
#Accumulations=	2
#Range (cm-¹)=	50...5000
#Windows=	1
#Auto scanning=	Off
#Autofocus=	Off
#Macrospot=	Off
#AutoExposure=	Off
#Spike filter=	Multiple accum.
#Delay time (s)=	2
#Binning=	1
#Readout mode=	Signal
#DeNoise=	Off
#ICS correction=	On
#Dark correction=	Off
#Inst. Process=	Off
#Detector Gain=	Best Dynamic
#Detector ADC=	50 kHz HS
#Detector temperature (°C)=	-60.09
#Instrument=	LabRAM HR Evol
#Detector=	SIN-EM FIVIS
#Objective=	x100_VIS_LWD
#Grating=	150 (500nm)
#ND Filter=	10%
#Laser=	532nm_Edge
#Hole=	49.98
#Temperature=	0
#Range=	Visible
#StageXY=	75x50mm Scan+
#StageZ=	Z motor
#X (µm)=	0
#Y (µm)=	0
#Z (µm)=	-12.5
#Full time(s)=	45
#Project=	21_05_28
#Sample=	BU19w
#Site=
#Title=	BU19w-FF07a-FI02-V_150 (500nm)_532nm_Edge_10%_x100_VIS_LWD_H50um_20sX2
#Remark=
#Date=	28.05.2021 17:41
#Acquired=	28.05.2021 17:41:38
51.5961	3341.92
56.2453	2541.76
60.8921	2406.01
65.5367	1980.49
70.1768	1184.53
74.8167	831.317
79.4543	644.436
84.0897	533.486
88.7227	444.034
93.3513	400.447
97.9798	367.427
102.606	318.642
107.23	310.869
111.851	290.558
116.469	266.405
121.086	237.334
125.7	225.697
130.313	220.371
134.921	220.06
139.529	213.62
144.134	204.766
148.738	202.073
153.337	198.173
157.936	266.661
162.532	373.069
167.126	344.689
171.716	234.377
176.306	206.166
180.894	223.262
185.477	367.591
190.06	651.374
194.64	521.715
199.219	311.323
203.793	219.573
208.367	181.638
212.939	180.403
217.506	180.393
222.073	180.384
226.638	176.686
231.199	182.728
235.759	215.626
240.318	226.487
244.872	270.233
249.425	339.483
253.977	324.551
258.524	254.895
263.071	221.839
267.616	216.78
272.156	265.123
276.697	417.666
281.233	651.286
285.769	544.614
290.303	387.371
294.832	285.88
299.361	308.152
303.886	386.49
308.411	416.133
312.934	319.555
317.452	242.615
321.97	230.467
326.484	255.421
330.998	301.576
335.507	288.64
340.017	240.102
344.524	221.078
349.027	258.82
353.53	268.804
358.028	229.083
362.527	210.098
367.021	195.718
371.515	218.183
376.004	217.718
380.494	203.839
384.979	232.91
389.465	263.407
393.946	289.642
398.427	293.27
402.903	286.468
407.38	239.247
411.852	263.334
416.324	341.838
420.792	411.832
425.26	342.722
429.723	236.056
434.187	182.744
438.646	175.544
443.105	167.245
447.56	184.7
452.015	242.335
456.466	296.496
460.914	308.855
465.362	251.409
469.807	212.189
474.251	188.405
478.69	179.784
483.13	201.391
487.566	208.033
491.999	228.697
496.432	226.986
500.861	253.028
505.29	234.231
509.715	209.88
514.138	206.35
518.56	198.197
522.979	188.96
527.395	186.705
531.811	189.113
536.223	195.037
540.635	198.659
545.042	196.48
549.448	204.747
553.853	207.192
558.255	210.678
562.654	209.017
567.053	215.665
571.448	188.445
575.841	194.293
580.232	186.683
584.622	202.158
589.009	295.039
593.393	336.256
597.777	301.166
602.157	240.873
606.535	231.521
610.913	282.809
615.287	305.094
619.659	272.717
624.029	232.054
628.398	194.739
632.763	191.389
637.127	187.968
641.488	210.922
645.849	191.516
650.206	191.474
654.561	181.049
658.914	194.201
663.267	226.731
667.615	228.423
671.962	242.496
676.307	240.629
680.649	270.225
684.991	257.018
689.33	210.391
693.666	197.792
698	182.772
702.332	177.215
706.662	174.815
710.992	170.822
715.318	173.499
719.641	174.908
723.963	169.486
728.283	158.708
732.6	161.031
736.918	156.714
741.231	174.711
745.542	173.273
749.852	180.177
754.159	193.606
758.464	197.493
762.767	194.627
767.068	215.141
771.369	242.575
775.666	283.953
779.961	371.912
784.254	365.57
788.545	295.479
792.834	252.125
797.12	220.852
801.405	197.481
805.688	194.093
809.968	184.183
814.247	195.197
818.524	171.048
822.798	176.593
827.071	178.888
831.341	175.695
835.612	185.728
839.878	179.216
844.142	187.019
848.405	173.791
852.665	165.981
856.923	178.02
861.18	179.025
865.434	161.28
869.686	184.202
873.936	176.277
878.185	166.136
882.431	188.83
886.675	181.863
890.915	167.196
895.155	171.01
899.393	177.278
903.63	187.184
907.864	169.718
912.096	168.327
916.326	172.447
920.554	179.759
924.78	177.277
929.004	182.233
933.227	186.32
937.447	179.651
941.665	192.225
945.881	195.111
950.095	213.99
954.305	238.196
958.516	208.08
962.724	220.59
966.93	212.919
971.134	236.058
975.337	222.102
979.537	201.835
983.735	204.929
987.93	196.37
992.124	196.303
996.316	190.027
1000.51	190.222
1004.7	175.602
1008.88	186.471
1013.06	188.863
1017.25	195.473
1021.43	202.094
1025.61	200.143
1029.78	199.183
1033.96	216.315
1038.13	223.607
1042.3	236.074
1046.47	261.262
1050.63	354.263
1054.8	466.958
1058.96	462.682
1063.12	354.92
1067.28	290.774
1071.44	259.476
1075.59	269.106
1079.74	280.743
1083.89	310.899
1088.04	413.296
1092.19	516.141
1096.33	505.436
1100.48	422.143
1104.62	405.812
1108.76	448.97
1112.89	496.276
1117.03	467.157
1121.16	403.061
1125.29	382.132
1129.42	368.441
1133.55	382.457
1137.68	406.67
1141.8	328.208
1145.92	301.002
1150.04	283.92
1154.16	292.417
1158.27	341.05
1162.39	356.607
1166.5	330.767
1170.61	285.252
1174.72	269.584
1178.82	246.682
1182.93	207.348
1187.03	202.977
1191.13	209.787
1195.23	208.316
1199.33	207.803
1203.42	205.2
1207.51	223.92
1211.6	212.163
1215.69	195.43
1219.78	212.048
1223.86	235.646
1227.95	242.141
1232.03	228.684
1236.11	233.44
1240.18	264.302
1244.26	257.125
1248.33	251.055
1252.41	232.14
1256.48	228.248
1260.54	226.39
1264.61	213.56
1268.67	209.762
1272.74	326.273
1276.8	450.071
1280.86	305.899
1284.91	208.644
1288.97	192.699
1293.02	199.866
1297.07	199.958
1301.12	212.125
1305.17	186.964
1309.21	197.064
1313.25	199.078
1317.3	197.996
1321.34	201.908
1325.37	190.646
1329.41	194.457
1333.44	193.219
1337.48	201.941
1341.5	205.598
1345.53	199.232
1349.56	193.882
1353.59	192.535
1357.61	202.128
1361.63	199.772
1365.65	207.358
1369.66	200.128
1373.68	240.343
1377.69	515.154
1381.7	526.497
1385.72	279.122
1389.72	203.254
1393.73	197.348
1397.73	213.187
1401.74	227.049
1405.74	208.397
1409.73	186.796
1413.73	205.629
1417.73	185.014
1421.72	198.929
1425.71	205.916
1429.7	178.238
1433.69	192.053
1437.67	192.039
1441.66	189.067
1445.64	181.13
1449.62	183.054
1453.6	194.809
1457.57	186.816
1461.55	185.696
1465.52	184.517
1469.49	201.024
1473.46	190.027
1477.43	188.837
1481.39	186.645
1485.36	190.317
1489.32	193.965
1493.28	182.004
1497.24	185.672
1501.19	173.775
1505.15	194.028
1509.1	187.089
1513.05	188.913
1517	188.805
1520.95	185.807
1524.9	183.794
1528.84	183.736
1532.78	197.273
1536.72	186.579
1540.66	194.307
1544.6	185.561
1548.53	192.32
1552.46	182.609
1556.4	179.658
1560.32	183.459
1564.25	189.171
1568.18	188.088
1572.1	184.093
1576.02	194.586
1579.94	184.792
1583.86	207.791
1587.78	180.639
1591.69	186.257
1595.61	195.709
1599.52	178.24
1603.43	204.98
1607.34	184.698
1611.24	186.501
1615.15	196.941
1619.05	192.072
1622.95	191.024
1626.85	175.65
1630.74	197.631
1634.64	189.046
1638.53	199.595
1642.42	195.837
1646.31	193.074
1650.2	197.04
1654.09	187.587
1657.97	191.547
1661.86	188.779
1665.74	188.854
1669.62	197.562
1673.49	192.75
1677.37	195.618
1681.24	192.614
1685.12	185.725
1688.99	202.806
1692.86	204.484
1696.72	182.215
1700.59	193.406
1704.45	191.171
1708.31	187.952
1712.17	175.21
1716.03	191.9
1719.89	192.451
1723.74	184.512
1727.6	177.53
1731.45	193.102
1735.3	202.058
1739.14	196.918
1742.99	188.044
1746.83	182.016
1750.68	177.054
1754.52	187.949
1758.36	181.309
1762.19	196.319
1766.03	186.135
1769.86	184.377
1773.69	185.495
1777.53	192.206
1781.35	192.474
1785.18	190.908
1789	183.747
1792.83	195.304
1796.65	182.51
1800.47	185.641
1804.29	192.425
1808.1	183.195
1811.92	200.322
1815.73	206.119
1819.54	181.637
1823.35	196.73
1827.16	188.2
1830.97	185.281
1834.77	187.028
1838.58	184.034
1842.38	186.659
1846.18	176.086
1849.97	183.383
1853.77	186.828
1857.56	193.951
1861.36	200.983
1865.15	190.281
1868.93	192.646
1872.72	181.123
1876.51	193.727
1880.29	185.991
1884.07	203.247
1887.86	185.484
1891.63	197.414
1895.41	190.02
1899.19	193.67
1902.96	196.484
1906.73	175.4
1910.5	186.556
1914.27	196.876
1918.04	179.537
1921.8	196.479
1925.57	182.932
1929.33	195.351
1933.09	190.169
1936.85	184.961
1940.6	184.394
1944.36	193.174
1948.11	184.178
1951.87	205.974
1955.61	207.068
1959.36	187.39
1963.11	188.31
1966.86	187.34
1970.6	186.311
1974.34	184.277
1978.08	182.209
1981.82	194.148
1985.56	190.139
1989.29	193.582
1993.02	191.394
1996.75	189.176
2000.49	186.929
2004.21	198.589
2007.94	200.014
2011.67	186.638
2015.39	197.239
2019.11	195.96
2022.83	204.872
2026.55	189.16
2030.27	199.108
2033.98	183.517
2037.69	189.96
2041.41	192.726
2045.12	178.08
2048.82	186.328
2052.53	190.036
2056.24	198.338
2059.94	189.332
2063.64	191.442
2067.34	191.766
2071.04	200.399
2074.74	183.221
2078.43	179.864
2082.13	178.361
2085.82	212.101
2089.51	191.798
2093.2	184.398
2096.88	199.391
2100.57	191.114
2104.25	185.557
2107.94	199.498
2111.62	195.737
2115.3	183.605
2118.97	190.042
2122.65	195.466
2126.32	189.708
2129.99	189.49
2133.66	187.405
2137.33	185.312
2141	193.344
2144.67	195.793
2148.33	189.942
2151.99	189.617
2155.66	196.635
2159.31	184.416
2162.97	185.967
2166.63	179.329
2170.28	175.474
2173.94	174.432
2177.59	190.729
2181.24	187.015
2184.89	192.392
2188.53	192.361
2192.18	190.586
2195.82	182.516
2199.46	187.229
2203.1	190.149
2206.74	191.279
2210.38	197.93
2214.01	186.316
2217.65	193.015
2221.28	192.393
2224.91	195.459
2228.54	188.387
2232.16	195.138
2235.79	197.306
2239.41	186.516
2243.04	190.52
2246.66	177.815
2250.28	182.75
2253.89	185.857
2257.51	191.792
2261.12	185.589
2264.74	187.77
2268.35	188.103
2271.96	192.239
2275.57	190.687
2279.17	184.362
2282.78	186.393
2286.38	185.591
2289.98	178.168
2293.58	194.354
2297.18	185.015
2300.78	204.081
2304.37	177.654
2307.97	182.445
2311.56	185.316
2315.15	187.211
2318.74	200.446
2322.33	229.732
2325.91	200.16
2329.5	179.139
2333.08	181.748
2336.66	185.27
2340.24	175.575
2343.82	177.172
2347.4	186.246
2350.97	174.669
2354.54	187.432
2358.12	185.206
2361.69	197.875
2365.26	187.257
2368.82	177.62
2372.39	188.433
2375.95	183.48
2379.52	190.545
2383.08	188.397
2386.64	188.114
2390.19	180.515
2393.75	178.477
2397.31	176.496
2400.86	189.24
2404.41	181.005
2407.96	168.206
2411.51	184.82
2415.06	183.143
2418.6	183.344
2422.15	182.655
2425.69	165.419
2429.23	174.941
2432.77	190.083
2436.31	181.227
2439.84	180.712
2443.38	184.865
2446.91	192.776
2450.44	168.943
2453.97	185.37
2457.5	192.348
2461.03	175.638
2464.55	183.386
2468.08	190.045
2471.6	175.153
2475.12	177.889
2478.64	175.881
2482.16	180.5
2485.67	171.862
2489.19	186.644
2492.7	181.765
2496.21	185.237
2499.72	179.397
2503.23	182.866
2506.74	185.359
2510.25	191.53
2513.75	180.946
2517.25	184.374
2520.75	174.839
2524.25	179.1
2527.75	180.752
2531.25	176.905
2534.74	187.86
2538.24	184.094
2541.73	189.6
2545.22	176.74
2548.71	189.803
2552.2	183.484
2555.68	172.577
2559.17	179.334
2562.65	182.403
2566.13	180.912
2569.61	184.133
2573.09	173.396
2576.57	189.818
2580.04	184.747
2583.51	180.598
2586.99	161.288
2590.46	178.818
2593.93	164.966
2597.4	167.224
2600.86	197.241
2604.33	177.597
2607.79	176.951
2611.25	180.953
2614.71	177.153
2618.17	189.749
2621.63	169.604
2625.09	177.287
2628.54	182.038
2631.99	176.194
2635.45	177.028
2638.9	174.933
2642.34	187.171
2645.79	182.132
2649.24	192.368
2652.68	180.607
2656.12	171.695
2659.56	185.564
2663.01	177.569
2666.44	171.483
2669.88	173.904
2673.32	182.886
2676.75	168.402
2680.18	180.219
2683.61	175.21
2687.04	174.011
2690.47	182.251
2693.9	170.977
2697.32	187.614
2700.75	173.562
2704.17	167.902
2707.59	166.902
2711.01	170.671
2714.43	174.478
2717.84	170.875
2721.26	181.279
2724.67	173.068
2728.08	173.259
2731.49	177.202
2734.9	177.398
2738.31	174.783
2741.71	163.711
2745.12	166.669
2748.52	179.944
2751.92	175.375
2755.32	171.724
2758.72	174.64
2762.12	157.781
2765.52	177.613
2768.91	176.694
2772.3	171.975
2775.7	162.531
2779.09	175.669
2782.47	179.357
2785.86	167.031
2789.25	168.82
2792.63	172.48
2796.01	175.191
2799.4	167.572
2802.78	171.192
2806.15	166.373
2809.53	165.303
2812.91	160.483
2816.28	173.425
2819.65	168.593
2823.03	160.063
2826.4	165.557
2829.76	176.65
2833.13	173.779
2836.5	159.764
2839.86	156.027
2843.22	164.432
2846.59	169.152
2849.95	174.872
2853.3	172.24
2856.66	164.91
2860.02	172.554
2863.37	158.7
2866.72	157.945
2870.08	162.819
2873.43	180.845
2876.77	164.108
2880.12	164.277
2883.47	166.324
2886.81	166.476
2890.15	170.4
2893.5	173.375
2896.84	168.75
2900.17	163.149
2903.51	157.519
2906.85	166.06
2910.18	147.147
2913.52	172.696
2916.85	172.683
2920.18	173.59
2923.51	164.084
2926.83	158.351
2930.16	164.884
2933.48	181.776
2936.81	168.424
2940.13	160.75
2943.45	157.798
2946.77	164.27
2950.09	176.381
2953.4	164.028
2956.72	163.91
2960.03	169.452
2963.34	169.372
2966.65	168.366
2969.96	163.659
2973.27	169.3
2976.58	157.125
2979.88	171.244
2983.19	174.087
2986.49	157.23
2989.79	166.665
2993.09	160.143
2996.39	161.143
2999.68	163.091
3002.98	163.159
3006.27	163.227
3009.57	173.662
3012.86	171.874
3016.15	174.799
3019.43	159.809
3022.72	174.987
3026.01	171.305
3029.29	160.067
3032.57	165.82
3035.86	166.845
3039.14	158.409
3042.41	154.697
3045.69	170.863
3048.97	157.687
3052.24	154.921
3055.52	154.052
3058.79	169.3
3062.06	169.325
3065.33	161.785
3068.6	165.609
3071.86	165.602
3075.13	174.933
3078.39	151.245
3081.65	154.056
3084.91	163.64
3088.17	164.685
3091.43	162.927
3094.69	172.586
3097.95	154.464
3101.2	164.017
3104.45	164.984
3107.7	156.514
3110.95	163.242
3114.2	172.778
3117.45	162.337
3120.7	158.563
3123.94	170.98
3127.18	174.825
3130.43	158.655
3133.67	166.308
3136.91	160.614
3140.14	174.929
3143.38	171.131
3146.61	160.658
3149.85	149.24
3153.08	162.619
3156.31	155.009
3159.54	164.574
3162.77	168.412
3166	161.753
3169.22	148.398
3172.45	169.387
3175.67	171.282
3178.89	176.979
3182.11	165.501
3185.33	175.012
3188.55	173.058
3191.77	172.053
3194.98	171.048
3198.2	166.231
3201.41	176.649
3204.62	168.981
3207.83	171.792
3211.04	170.804
3214.25	168.876
3217.45	169.814
3220.66	175.509
3223.86	165.039
3227.06	172.659
3230.26	167.917
3233.46	180.313
3236.66	182.233
3239.85	180.386
3243.05	163.311
3246.24	163.38
3249.44	170.12
3252.63	170.209
3255.82	170.303
3259.01	176.12
3262.19	180.963
3265.38	165.724
3268.56	157.143
3271.75	179.115
3274.93	179.104
3278.11	194.373
3281.29	172.356
3284.47	173.231
3287.64	176.016
3290.82	180.691
3293.99	179.658
3297.17	183.381
3300.34	179.487
3303.51	192.772
3306.68	176.501
3309.84	178.298
3313.01	172.463
3316.18	170.425
3319.34	170.283
3322.5	189.092
3325.66	187.035
3328.82	175.522
3331.98	186.722
3335.14	175.244
3338.29	188.345
3341.45	199.555
3344.6	192.841
3347.75	189.008
3350.9	179.568
3354.05	183.322
3357.2	175.787
3360.35	189.94
3363.49	183.378
3366.64	189.077
3369.78	194.79
3372.92	198.626
3376.06	182.665
3379.2	194.087
3382.34	194.19
3385.48	192.393
3388.61	198.179
3391.75	195.455
3394.88	204.083
3398.01	208.877
3401.14	190.091
3404.27	202.605
3407.4	237.01
3410.52	241.07
3413.65	288.922
3416.77	388.242
3419.89	659.313
3423.01	1197.84
3426.13	1304.32
3429.25	806.29
3432.37	432.081
3435.49	306.967
3438.6	241.966
3441.72	226.652
3444.83	214.201
3447.94	200.76
3451.05	193.045
3454.16	191.978
3457.26	189.004
3460.37	190.764
3463.47	195.37
3466.58	192.359
3469.68	193.12
3472.78	199.532
3475.88	191.788
3478.98	196.368
3482.07	197.168
3485.17	200.806
3488.26	223.341
3491.36	231.726
3494.45	250.549
3497.54	275.958
3500.63	309.822
3503.72	363.472
3506.81	393.462
3509.89	362.192
3512.98	316.729
3516.06	285.5
3519.14	243.223
3522.22	225.498
3525.3	206.013
3528.38	186.377
3531.45	187.399
3534.53	175.161
3537.61	178.888
3540.68	178.855
3543.75	159.074
3546.82	173.248
3549.89	163.936
3552.96	167.807
3556.03	156.533
3559.09	143.381
3562.16	159.57
3565.22	153.005
3568.28	162.522
3571.34	150.29
3574.4	146.513
3577.46	152.225
3580.52	145.596
3583.57	148.439
3586.63	142.732
3589.68	143.664
3592.73	137.941
3595.78	143.59
3598.83	146.381
3601.88	148.222
3604.93	150.046
3607.97	145.233
3611.02	144.207
3614.06	140.339
3617.1	141.192
3620.14	135.444
3623.18	128.765
3626.22	137.183
3629.26	136.177
3632.3	128.571
3635.33	146.384
3638.36	135.985
3641.4	135.959
3644.43	142.535
3647.46	132.211
3650.49	132.198
3653.51	136.91
3656.54	132.043
3659.57	115.24
3662.59	117.226
3665.61	132.384
3668.63	130.531
3671.65	136.251
3674.67	129.718
3677.69	135.458
3680.71	132.711
3683.72	114.831
3686.74	119.628
3689.75	118.757
3692.76	127.358
3695.77	133.128
3698.78	111.388
3701.79	127.591
3704.79	121.983
3707.8	128.716
3710.81	114.53
3713.81	118.389
3716.81	124.139
3719.81	112.772
3722.81	128.989
3725.81	117.591
3728.81	122.367
3731.8	119.517
3734.8	119.511
3737.79	120.444
3740.78	110.896
3743.77	123.225
3746.76	122.218
3749.75	124.051
3752.74	111.624
3755.73	114.4
3758.71	127.613
3761.7	109.515
3764.68	115.12
3767.66	110.305
3770.64	117.806
3773.62	115.851
3776.6	111.072
3779.58	114.807
3782.55	107.212
3785.53	116.621
3788.5	121.311
3791.47	107.129
3794.44	109.957
3797.41	111.85
3800.38	118.469
3803.35	112.833
3806.32	115.699
3809.28	116.681
3812.24	107.275
3815.21	112.992
3818.17	119.663
3821.13	113.095
3824.09	104.631
3827.04	115.113
3830	101.909
3832.96	106.711
3835.91	110.58
3838.86	115.411
3841.82	118.347
3844.77	107.018
3847.72	106.146
3850.67	111.946
3853.61	107.274
3856.56	115.002
3859.5	112.239
3862.45	105.646
3865.39	103.821
3868.33	102.95
3871.27	107.819
3874.21	102.143
3877.15	107.97
3880.09	119.555
3883.02	110.963
3885.96	115.805
3888.89	114.874
3891.82	104.323
3894.75	107.226
3897.68	112.038
3900.61	112.992
3903.54	113.941
3906.47	111.032
3909.39	104.291
3912.31	111.958
3915.24	112.885
3918.16	109.002
3921.08	108.021
3924	108.939
3926.92	109.843
3929.83	109.778
3932.75	109.707
3935.67	112.536
3938.58	111.557
3941.49	104.852
3944.4	110.586
3947.31	96.2189
3950.22	101.011
3953.13	107.726
3956.04	99.1246
3958.94	101.066
3961.85	103.971
3964.75	102.091
3967.65	95.4196
3970.55	100.261
3973.45	101.27
3976.35	102.277
3979.25	106.161
3982.15	107.158
3985.04	103.346
3987.94	104.335
3990.83	102.435
3993.72	104.37
3996.61	103.439
3999.5	97.6933
4002.39	99.6513
4005.28	95.8332
4008.16	100.689
4011.05	94.9468
4013.93	108.485
4016.81	105.634
4019.7	103.747
4022.58	97.9954
4025.46	102.864
4028.33	103.874
4031.21	102.952
4034.09	91.3939
4036.96	104.983
4039.84	100.196
4042.71	94.4335
4045.58	102.214
4048.45	99.3436
4051.32	100.355
4054.19	96.5221
4057.05	101.43
4059.92	99.5422
4062.78	99.5914
4065.65	89.92
4068.51	91.9095
4071.37	96.8185
4074.23	102.705
4077.09	94.9599
4079.95	100.848
4082.81	96.9926
4085.66	92.1595
4088.52	97.0737
4091.37	88.3277
4094.22	103.992
4097.07	85.4719
4099.92	99.191
4102.77	92.3886
4105.62	97.314
4108.47	104.187
4111.31	98.3442
4114.16	92.487
4117	96.4068
4119.84	98.3551
4122.69	95.4117
4125.53	97.373
4128.36	92.4862
4131.2	95.4549
4134.04	94.5221
4136.88	90.6767
4139.71	90.6346
4142.54	100.297
4145.38	88.5483
4148.21	95.4284
4151.04	97.4256
4153.87	101.36
4156.69	89.5913
4159.52	93.4505
4162.35	83.6443
4165.17	99.2853
4168	95.3598
4170.82	93.3957
4173.64	100.239
4176.46	91.4371
4179.28	94.3708
4182.1	89.4886
4184.91	96.346
4187.73	91.4714
4190.54	87.5758
4193.36	96.4169
4196.17	82.7515
4198.98	89.6615
4201.79	93.6349
4204.6	91.7308
4207.41	93.7471
4210.22	84.9632
4213.02	95.8217
4215.83	93.9081
4218.63	92.0475
4221.44	87.2203
4224.24	87.3075
4227.04	85.4083
4229.84	91.4277
4232.64	82.621
4235.43	87.6741
4238.23	91.753
4241.02	82.9328
4243.82	87.0205
4246.61	86.1452
4249.4	94.237
4252.19	91.3576
4254.98	87.4687
4257.77	88.5663
4260.56	81.6503
4263.35	82.7466
4266.13	91.8819
4268.92	84.9591
4271.7	87.0777
4274.48	92.2224
4277.26	85.2526
4280.04	87.3454
4282.82	83.3721
4285.6	93.5415
4288.38	85.4987
4291.15	84.5242
4293.93	78.4818
4296.7	87.643
4299.47	90.7391
4302.25	93.8298
4305.02	82.714
4307.79	81.7408
4310.55	87.8824
4313.32	79.8069
4316.09	82.8974
4318.85	85.9829
4321.62	79.9035
4324.38	85.0133
4327.14	89.1026
4329.9	91.1599
4332.66	86.0769
4335.42	84.0543
4338.18	89.1548
4340.94	88.1594
4343.69	84.1054
4346.45	79.0379
4349.2	78.0547
4351.95	81.1543
4354.7	81.2153
4357.45	81.2669
4360.2	82.3414
4362.95	79.3184
4365.7	79.372
4368.44	80.4432
4371.19	76.3969
4373.93	78.4874
4376.68	76.4722
4379.42	79.583
4382.16	77.5578
4384.9	80.6748
4387.64	72.5012
4390.37	71.549
4393.11	89.1595
4395.85	76.9459
4398.58	80.1456
4401.31	82.314
4404.05	88.625
4406.78	71.0868
4409.51	79.4854
4412.24	69.1709
4414.96	75.4834
4417.69	81.8042
4420.42	71.4174
4423.14	86.0723
4425.87	79.8715
4428.59	82.021
4431.31	79.9911
4434.03	81.0955
4436.75	84.2916
4439.47	84.3444
4442.19	73.9055
4444.91	77.0928
4447.62	69.7845
4450.34	77.1677
4453.05	80.3492
4455.76	73.0248
4458.47	79.3516
4461.19	84.6271
4463.89	79.4005
4466.6	75.22
4469.31	79.4607
4472.02	78.444
4474.72	73.2192
4477.43	73.2659
4480.13	69.0988
4482.83	74.4314
4485.53	71.3194
4488.23	72.4261
4490.93	76.7053
4493.63	74.6193
4496.33	72.5196
4499.02	74.6689
4501.72	76.8156
4504.41	74.718
4507.11	73.6868
4509.8	76.8998
4512.49	59.9542
4515.18	69.5356
4517.87	73.8172
4520.56	68.5424
4523.24	65.3955
4525.93	72.8843
4528.61	63.3467
4531.3	80.4324
4533.98	67.6934
4536.66	72.0078
4539.34	70.9932
4542.02	68.9132
4544.7	74.3138
4547.38	76.5153
4550.05	73.3662
4552.73	67.0027
4555.4	69.2237
4558.08	68.2367
4560.75	67.2673
4563.42	69.5411
4566.09	74.0067
4568.76	70.9314
4571.43	71.0538
4574.1	67.8406
4576.77	72.196
4579.43	65.7267
4582.1	66.8871
4584.76	72.4183
4587.42	69.2007
4590.08	71.4268
4592.74	69.2837
4595.4	78.0607
4598.06	62.8224
4600.72	70.5153
4603.38	60.7264
4606.03	62.9714
4608.69	67.4134
4611.34	72.9619
4613.99	68.6344
4616.64	68.6949
4619.29	69.8592
4621.94	75.4347
4624.59	61.1769
4627.24	70.0563
4629.89	61.281
4632.53	60.2245
4635.18	65.792
4637.82	68.0426
4640.46	64.7598
4643.1	62.5819
4645.74	63.7416
4648.38	66.0298
4651.02	65.0064
4653.66	65.1174
4656.3	58.5124
4658.93	58.5233
4661.57	69.735
4664.2	58.6415
4666.83	60.9336
4669.46	68.8094
4672.09	64.386
4674.72	65.5572
4677.35	71.2157
4679.98	66.78
4682.61	72.4445
4685.23	59.0096
4687.86	57.928
4690.48	68.1023
4693.1	62.5217
4695.73	67.073
4698.34	67.1174
4700.96	68.2922
4703.58	63.8185
4706.2	67.2448
4708.82	65.0189
4711.43	63.9196
4714.05	70.7413
4716.66	63.978
4719.28	57.2061
4721.89	69.6913
4724.5	59.5107
4727.11	67.4753
4729.72	56.1633
4732.33	61.8682
4734.93	68.715
4737.54	57.3845
4740.14	61.9556
4742.75	59.7047
4745.35	69.9607
4747.95	57.4603
4750.55	66.5684
4753.15	60.8857
4755.75	63.1678
4758.35	56.3438
4760.95	63.185
4763.54	66.6175
4766.14	63.2215
4768.73	55.278
4771.33	55.3129
4773.92	64.4639
4776.51	59.9266
4779.1	63.3794
4781.69	54.2673
4784.28	61.1493
4786.87	60.0337
4789.45	63.4936
4792.04	60.0916
4794.63	54.3981
4797.21	50.9921
4799.79	57.9072
4802.37	60.2459
4804.95	63.7419
4807.53	59.2051
4810.11	55.8145
4812.69	58.1762
4815.27	55.9333
4817.84	60.6169
4820.42	60.6923
4822.99	59.6101
4825.57	59.6853
4828.14	52.7972
4830.71	57.5111
4833.28	62.2433
4835.85	55.3404
4838.42	54.2584
4840.98	56.6842
4843.55	53.2622
4846.12	59.1985
4848.68	53.4066
4851.24	51.1096
4853.81	52.3012
4856.37	58.2069
4858.93	53.5825
4861.49	60.734
4864.05	52.5383
4866.61	62.0319
4869.16	54.9893
4871.72	52.6807
4874.27	51.5398
4876.83	51.5769
4879.38	55.1735
4881.93	59.9587
4884.49	56.4302
4887.04	61.218
4889.58	56.4975
4892.13	58.9125
4894.68	55.3737
4897.23	53.0207
4899.77	57.816
4902.32	60.2294
4904.86	48.3258
4907.4	50.734
4909.95	56.7251
4912.49	48.3737
4915.03	55.5453
4917.57	54.3504
4920.1	56.7455
4922.64	57.946
4925.18	51.9781
4927.71	61.5487
4930.25	43.6243
4932.78	61.5722
4935.31	56.8193
4937.84	48.4654
4940.38	58.0612
4942.9	53.2692
4945.43	54.4833
4947.96	49.7173
4950.49	53.3347
4953.01	47.367
4955.54	48.5855
4958.06	53.4154
4960.59	57.0546
4963.11	52.29
4965.63	48.7348
4968.15	51.2049
4970.67	47.6353
4973.19	48.8851
4975.71	50.1357
4978.22	61.0602
4980.74	58.6948
4983.25	53.903
4985.77	46.6794
4988.28	52.7929
4990.79	55.275
4993.3	51.6796
4995.81	45.6418
4998.32	53.0027