File: Data/3-Raman/raw/bu19w-e-ff11-fi04-v_150 (500nm)_633nm_edge_100%_x100_vis_h50um_60sx2_01.txt
#Acq. time (s)=	60
#Accumulations=	2
#Range (cm-¹)=	100...4000
#Windows=	1
#Auto scanning=	Off
#Autofocus=	Off
#Macrospot=	Off
#AutoExposure=	Off
#Spike filter=	Multiple accum.
#Delay time (s)=	2
#Binning=	1
#Readout mode=	Signal
#DeNoise=	Off
#ICS correction=	On
#Dark correction=	Off
#Inst. Process=	Off
#Detector Gain=	Best Dynamic
#Detector ADC=	50 kHz HS
#Detector temperature (°C)=	-60.28
#Instrument=	LabRAM HR Evol
#Detector=	SIN-EM FIVIS
#Objective=	x100_VIS
#Grating=	150 (500nm)
#ND Filter=	100%
#Laser=	633nm_Edge
#Hole=	49.98
#Temperature=	0
#Range=	Visible
#StageXY=	75x50mm Scan+
#StageZ=	Z motor
#X (µm)=	0
#Y (µm)=	0
#Z (µm)=	-244.4
#Full time(mm:ss)=	2:04
#Project=	21_11_04
#Sample=	BU19w
#Site=
#Title=	BU19w-E-FF11-FI04-V_150 (500nm)_633nm_Edge_100%_x100_VIS_H50um_60sX2
#Remark=
#Date=	04.11.2021 16:32
#Acquired=	04.11.2021 16:32:58
102.881	536.289
109.397	504.355
115.908	458.041
122.414	446.897
128.914	407.009
135.409	416.724
141.898	365.061
148.383	382.366
154.861	416.044
161.335	538.912
167.801	377.195
174.264	319.717
180.721	341.61
187.173	411.086
193.62	365.511
200.061	285.853
206.496	274.358
212.926	262.795
219.352	261.74
225.772	259.652
232.185	331.601
238.595	328.418
244.999	449.834
251.397	339.47
257.791	260.493
264.178	249.005
270.561	347.587
276.939	662.438
283.31	542.804
289.678	304.655
296.039	260.841
302.396	290.888
308.746	277.374
315.093	250.697
321.433	311.879
327.768	397.631
334.099	340.03
340.423	301.289
346.743	414.294
353.058	428.192
359.367	301.681
365.671	275.984
371.971	294.495
378.265	234.123
384.553	259.255
390.837	288.474
397.116	269.16
403.389	219.872
409.657	195.8
415.92	257.519
422.178	234.174
428.431	205.595
434.678	189.089
440.921	192.393
447.158	179.679
453.391	209.092
459.618	208.604
465.84	204.611
472.057	194.214
478.27	207.284
484.477	211.967
490.679	234.359
496.876	267.035
503.068	239.169
509.255	221.569
515.436	194.668
521.613	190.266
527.785	170.965
533.952	179.862
540.113	185.971
546.27	180.638
552.423	198.711
558.568	192.156
564.711	182.467
570.848	172.642
576.979	173.977
583.107	208.052
589.228	265.409
595.345	223.158
601.458	200.842
607.565	250.613
613.667	221.196
619.764	189.944
625.856	167.998
631.944	173.982
638.026	191.927
644.104	196.355
650.177	173.48
656.244	210.563
662.308	243.668
668.365	249.594
674.418	258.775
680.467	257.846
686.511	191.801
692.549	168.801
698.582	147.624
704.611	143.228
710.635	147.184
716.655	138.623
722.669	159.209
728.679	153.359
734.683	148.403
740.683	144.4
746.678	157.25
752.669	152.449
758.654	166.424
764.635	182.631
770.611	221.558
776.582	314.244
782.549	288.506
788.511	218.184
794.466	179.669
800.419	160.782
806.366	151.209
812.309	163.229
818.247	143.172
824.18	147.511
830.108	142.51
836.033	141.543
841.952	139.881
847.865	142.006
853.776	136.695
859.681	134.23
865.58	160.104
871.476	150.09
877.366	142.704
883.253	139.012
889.134	142.806
895.012	140.825
900.883	132.057
906.751	127.958
912.614	136.096
918.473	148.034
924.326	141.358
930.174	139.585
936.019	142.653
941.859	149.766
947.693	149.396
953.525	159.502
959.35	161.933
965.171	156.58
970.988	163.577
976.801	163.678
982.608	162.559
988.411	171.881
994.209	146.719
1000	141.715
1005.79	138.708
1011.58	145.411
1017.36	150.322
1023.13	157.227
1028.9	142.275
1034.67	155.153
1040.43	172.981
1046.19	210.259
1051.94	312.519
1057.69	304.333
1063.44	217.137
1069.17	179.183
1074.91	176.199
1080.64	193.505
1086.37	258.247
1092.09	308.458
1097.8	276.321
1103.52	263.61
1109.22	343.111
1114.93	316.694
1120.63	267.101
1126.32	270.621
1132.01	282.058
1137.7	236.693
1143.38	208.767
1149.06	188.418
1154.73	238.773
1160.4	221.919
1166.06	183.193
1171.72	179.909
1177.38	159.969
1183.03	133.341
1188.67	140.141
1194.31	146.097
1199.95	152.221
1205.58	143.867
1211.21	131.59
1216.84	145.026
1222.46	166.604
1228.07	155.41
1233.68	145.024
1239.29	168.677
1244.89	170.039
1250.49	145.958
1256.08	144.973
1261.67	142.798
1267.26	140.592
1272.84	181.583
1278.42	152.075
1283.99	126.718
1289.56	122.528
1295.12	129.429
1300.68	119.421
1306.23	120.538
1311.78	122.833
1317.33	114.17
1322.87	113.568
1328.41	118.077
1333.94	109.376
1339.47	115.868
1345	125.354
1350.52	120.469
1356.04	127.838
1361.55	126.918
1367.06	145.423
1372.56	158.726
1378.06	294.231
1383.56	143.199
1389.05	126.714
1394.53	118.524
1400.02	130.007
1405.5	115.787
1410.97	107.745
1416.44	111.077
1421.91	125.834
1427.37	117.847
1432.83	124.4
1438.28	115.321
1443.73	119.793
1449.17	120.043
1454.62	106.536
1460.05	109.733
1465.48	116.023
1470.91	108.641
1476.34	115.983
1481.76	121.282
1487.17	115.067
1492.59	112.056
1497.99	113.308
1503.4	116.716
1508.8	115.95
1514.19	108.85
1519.59	112.401
1524.97	115.998
1530.36	119.622
1535.74	124.375
1541.11	119.325
1546.48	118.431
1551.85	117.356
1557.21	108.567
1562.57	113.854
1567.93	116.971
1573.28	122.233
1578.62	135.093
1583.97	117.882
1589.3	123.316
1594.64	126.656
1599.97	113.874
1605.3	129.225
1610.62	113.3
1615.94	134.364
1621.25	139.251
1626.56	122.239
1631.87	134.792
1637.17	117.527
1642.47	119.887
1647.76	134.456
1653.05	129.07
1658.34	132.478
1663.62	124.756
1668.9	123.658
1674.18	124.769
1679.45	120.312
1684.71	116.903
1689.98	120.127
1695.23	124.53
1700.49	120.251
1705.74	111.94
1710.99	119.9
1716.23	117.715
1721.47	113.575
1726.7	121.603
1731.94	119.611
1737.16	110.845
1742.39	118.95
1747.61	120.29
1752.82	115.922
1758.03	118.285
1763.24	116.059
1768.44	114.983
1773.64	120.724
1778.84	116.313
1784.03	101.719
1789.22	119.002
1794.41	122.693
1799.59	114.997
1804.76	113.02
1809.94	113.291
1815.11	116.992
1820.27	116.09
1825.43	119.825
1830.59	111.985
1835.74	119.246
1840.89	117.158
1846.04	119.7
1851.18	116.385
1856.32	131.758
1861.45	119.091
1866.58	111.107
1871.71	121.906
1876.83	113.814
1881.95	124.578
1887.07	115.243
1892.18	125.91
1897.29	124.745
1902.39	126.059
1907.49	131.047
1912.59	126.658
1917.68	119.911
1922.77	102.128
1927.86	121.478
1932.94	118.113
1938.02	123.114
1943.09	108.845
1948.16	124.609
1953.23	123.479
1958.29	128.341
1963.35	131.979
1968.41	119.91
1973.46	124.662
1978.51	128.206
1983.55	122.117
1988.59	124.468
1993.63	128.035
1998.66	117.205
2003.69	118.43
2008.72	119.699
2013.74	129.43
2018.76	125.903
2023.77	126.006
2028.78	124.965
2033.79	121.561
2038.79	129.066
2043.79	134.186
2048.79	122.312
2053.78	120.09
2058.77	116.673
2063.76	130.403
2068.74	128.239
2073.72	124.822
2078.69	132.463
2083.66	115.414
2088.63	136.582
2093.59	133.11
2098.55	127.209
2103.51	120.056
2108.46	124.122
2113.41	128.245
2118.36	136.175
2123.3	129.035
2128.24	128.144
2133.17	136.075
2138.11	122.437
2143.03	130.335
2147.96	144.591
2152.88	133.312
2157.79	118.131
2162.71	132.276
2167.62	127.205
2172.52	129.835
2177.43	145.287
2182.32	119.702
2187.22	142.727
2192.11	118.448
2197	127.504
2201.89	140.498
2206.77	144.591
2211.64	130.724
2216.52	136.189
2221.39	140.418
2226.26	136.883
2231.12	135.931
2235.98	137.58
2240.84	132.695
2245.69	140.9
2250.54	134.689
2255.39	133.702
2260.23	128.767
2265.07	133.029
2269.9	129.291
2274.74	128.144
2279.57	128.282
2284.39	136.335
2289.21	140.362
2294.03	131.078
2298.84	132.482
2303.66	133.945
2308.46	146.177
2313.27	145.143
2318.07	137.455
2322.87	137.798
2327.66	142.215
2332.45	134.514
2337.24	141.712
2342.02	135.37
2346.8	139.958
2351.58	134.966
2356.35	127.13
2361.12	132.928
2365.89	129.072
2370.65	145.948
2375.41	130.993
2380.17	139.558
2384.92	132.772
2389.67	132.878
2394.42	148.235
2399.16	135.707
2403.9	132.911
2408.64	157.975
2413.37	130.366
2418.1	135.192
2422.83	151.089
2427.55	155.557
2432.27	139.025
2436.99	135.194
2441.7	137.019
2446.41	153.093
2451.11	127.845
2455.82	148.271
2460.51	137.209
2465.21	157.776
2469.9	155.309
2474.59	129.631
2479.28	127.071
2483.96	141.937
2488.64	146.611
2493.32	138.136
2497.99	134.031
2502.66	125.479
2507.32	144.802
2511.99	152.373
2516.65	143.719
2521.3	139.513
2525.96	148.6
2530.61	151.788
2535.25	135.743
2539.89	144.931
2544.53	149.699
2549.17	142.57
2553.8	142.882
2558.43	147.641
2563.06	153.967
2567.68	140.796
2572.3	157.776
2576.92	143.031
2581.53	147.875
2586.14	140.486
2590.75	136.041
2595.35	139.243
2599.96	151.659
2604.55	147.274
2609.15	138.275
2613.74	142.967
2618.33	147.682
2622.91	144.749
2627.49	146.445
2632.07	151.323
2636.64	144.007
2641.22	152.186
2645.78	149.586
2650.35	145.383
2654.91	150.455
2659.47	146.035
2664.03	147.81
2668.58	148.017
2673.13	164.023
2677.67	150.445
2682.22	143.277
2686.76	148.7
2691.29	152.515
2695.83	151.311
2700.36	140.398
2704.89	156.758
2709.41	140.938
2713.93	160.551
2718.45	143.115
2722.96	156.344
2727.47	150.068
2731.98	143.711
2736.49	147.079
2740.99	143.949
2745.49	150.649
2749.98	154.179
2754.47	159.548
2758.96	159.852
2763.45	135.464
2767.93	157.127
2772.41	152.475
2776.89	159.464
2781.36	159.953
2785.84	152.178
2790.3	162.691
2794.77	156.499
2799.23	148.525
2803.69	142.143
2808.14	152.544
2812.59	147.757
2817.04	163.196
2821.49	163.451
2825.93	163.728
2830.37	150.392
2834.81	169.326
2839.24	157.637
2843.67	168.112
2848.1	154.735
2852.53	153.347
2856.95	157.166
2861.37	157.571
2865.78	166.685
2870.19	160.276
2874.6	164.246
2879.01	170.007
2883.41	168.851
2887.81	164.188
2892.21	161.218
2896.6	179.463
2901	157.059
2905.38	148.651
2909.77	168.73
2914.15	174.488
2918.53	155.155
2922.91	157.341
2927.28	172.209
2931.65	165.486
2936.02	167.712
2940.38	153.505
2944.74	162.884
2949.1	161.286
2953.46	163.348
2957.81	169.059
2962.16	156.496
2966.5	160.42
2970.85	158.874
2975.19	184.936
2979.52	168.69
2983.86	169.062
2988.19	163.935
2992.52	164.392
2996.85	163.002
3001.17	167.255
3005.49	175.322
3009.8	179.669
3014.12	167.021
3018.43	180.877
3022.74	179.616
3027.04	183.957
3031.34	169.133
3035.64	177.144
3039.94	165.978
3044.23	172.071
3048.52	189.704
3052.81	178.449
3057.09	178.778
3061.38	194.583
3065.65	189.107
3069.93	177.78
3074.2	183.937
3078.47	192.081
3082.74	200.251
3087	190.913
3091.27	195.362
3095.52	184.161
3099.78	184.761
3104.03	203.249
3108.28	196.05
3112.53	192.832
3116.77	197.596
3121.01	202.427
3125.25	209.374
3129.49	208.311
3133.72	207.294
3137.95	216.495
3142.18	219.517
3146.4	228.688
3150.62	227.47
3154.84	219.837
3159.06	212.124
3163.27	221.142
3167.48	230.148
3171.69	228.671
3175.89	241.882
3180.09	233.829
3184.29	242.628
3188.49	221.663
3192.68	228.37
3196.87	224.564
3201.06	253.049
3205.24	256.097
3209.42	233.455
3213.6	245.223
3217.78	265.815
3221.95	260.343
3226.12	261.392
3230.29	266.806
3234.45	256.784
3238.61	253.288
3242.77	278.749
3246.93	273.233
3251.08	278.636
3255.23	279.359
3259.38	257.621
3263.53	265.278
3267.67	262.097
3271.81	276.837
3275.95	275.271
3280.08	275.841
3284.21	274.11
3288.34	297.639
3292.47	275.166
3296.59	254.884
3300.71	290.075
3304.83	281.376
3308.95	279.6
3313.06	296.35
3317.17	313.198
3321.27	269.516
3325.38	281.875
3329.48	292.009
3333.58	262.443
3337.67	301.164
3341.77	306.675
3345.86	302.56
3349.95	272.171
3354.03	313.121
3358.11	306.662
3362.19	312.145
3366.27	312.806
3370.34	291.858
3374.42	326.087
3378.48	307.29
3382.55	327.017
3386.61	327.428
3390.68	315.696
3394.73	345.126
3398.79	338.363
3402.84	329.045
3406.89	370.68
3410.94	344.231
3414.98	415.104
3419.03	629.857
3423.06	925.317
3427.1	596.653
3431.14	421.44
3435.17	365.766
3439.2	351.686
3443.22	322.882
3447.25	333.507
3451.27	336.808
3455.28	345.203
3459.3	346.373
3463.31	327.658
3467.32	331.319
3471.33	327.411
3475.34	353.433
3479.34	349.463
3483.34	345.435
3487.33	351.49
3491.33	405.89
3495.32	432.419
3499.31	479.389
3503.3	567.355
3507.28	501.52
3511.26	471.125
3515.24	402.063
3519.22	358.596
3523.19	333.081
3527.16	299.877
3531.13	279.482
3535.1	272.224
3539.06	293.553
3543.02	268.228
3546.98	273.867
3550.93	269.015
3554.89	256.116
3558.84	248.577
3562.78	254.131
3566.73	254.575
3570.67	255.138
3574.61	239.95
3578.55	261.593
3582.48	233.348
3586.41	228.756
3590.35	224.121
3594.27	222.111
3598.2	222.745
3602.12	209.94
3606.04	229.213
3609.95	216.265
3613.87	205.953
3617.78	217.136
3621.69	201.244
3625.6	201.388
3629.5	185.281
3633.4	196.168
3637.3	204.442
3641.2	193.897
3645.09	188.841
3648.98	200.001
3652.87	183.871
3656.76	184.041
3660.64	189.657
3664.53	187.07
3668.4	176.331
3672.28	179.237
3676.16	171.281
3680.03	166.12
3683.9	185.783
3687.76	175.259
3691.63	164.687
3695.49	165.101
3699.35	173.895
3703.2	163.185
3707.06	141.262
3710.91	158.482
3714.76	158.892
3718.6	147.968
3722.45	165.208
3726.29	173.986
3730.13	151.618
3733.97	163.268
3737.8	157.885
3741.63	146.754
3745.46	155.549
3749.29	152.902
3753.11	170.228
3756.93	153.179
3760.75	164.719
3764.57	164.792
3768.39	162.016
3772.2	153.543
3776.01	168.038
3779.81	156.721
3783.62	151.191
3787.42	160.075
3791.22	151.627
3795.02	157.671
3798.81	157.985
3802.61	158.317
3806.4	158.677
3810.18	164.874
3813.97	153.516
3817.75	162.611
3821.53	157.046
3825.31	142.599
3829.09	151.67
3832.86	157.861
3836.63	161.097
3840.4	173.195
3844.17	161.665
3847.93	149.924
3851.69	141.117
3855.45	141.182
3859.21	144.165
3862.96	153.134
3866.71	162.331
3870.46	150.771
3874.21	141.891
3877.95	150.946
3881.69	148.055
3885.44	157.158
3889.17	154.319
3892.91	148.516
3896.64	154.799
3900.37	133.965
3904.1	149.236
3907.82	164.54
3911.55	158.754
3915.27	137.828
3918.99	141.153
3922.7	147.586
3926.42	132.672
3930.13	160.455
3933.84	148.476
3937.54	139.491
3941.25	167.375
3944.95	140.022
3948.65	152.616
3952.35	152.846
3956.04	137.588
3959.73	140.817
3963.42	137.829
3967.11	156.494
3970.8	150.33
3974.48	144.182
3978.16	141.12
3981.84	147.315
3985.52	134.902
3989.19	147.3
3992.86	141.145
3996.53	150.558
3998.37	125.785