File: Data/3-Raman/raw/bu19w-e-ff11-fi03-v_150 (500nm)_633nm_edge_100%_x100_vis_h50um_60sx2_01.txt
#Acq. time (s)=	60
#Accumulations=	2
#Range (cm-¹)=	100...4000
#Windows=	1
#Auto scanning=	Off
#Autofocus=	Off
#Macrospot=	Off
#AutoExposure=	Off
#Spike filter=	Multiple accum.
#Delay time (s)=	2
#Binning=	1
#Readout mode=	Signal
#DeNoise=	Off
#ICS correction=	On
#Dark correction=	Off
#Inst. Process=	Off
#Detector Gain=	Best Dynamic
#Detector ADC=	50 kHz HS
#Detector temperature (°C)=	-60.09
#Instrument=	LabRAM HR Evol
#Detector=	SIN-EM FIVIS
#Objective=	x100_VIS
#Grating=	150 (500nm)
#ND Filter=	100%
#Laser=	633nm_Edge
#Hole=	49.98
#Temperature=	0
#Range=	Visible
#StageXY=	75x50mm Scan+
#StageZ=	Z motor
#X (µm)=	0
#Y (µm)=	0
#Z (µm)=	-257.1
#Full time(mm:ss)=	2:04
#Project=	21_11_04
#Sample=	BU19w
#Site=
#Title=	BU19w-E-FF11-FI03-V_150 (500nm)_633nm_Edge_100%_x100_VIS_H50um_60sX2
#Remark=
#Date=	04.11.2021 16:50
#Acquired=	04.11.2021 16:50:57
102.881	379.931
109.397	347.848
115.908	330.993
122.414	336.965
128.914	378.313
135.409	392.802
141.898	388.027
148.383	414.908
154.861	561.588
161.335	544.66
167.801	338.852
174.264	255.486
180.721	237.163
187.173	206.261
193.62	207.84
200.061	225.724
206.496	229.506
212.926	262.795
219.352	348.51
225.772	611.253
232.185	727.429
238.595	452.941
244.999	339.632
251.397	353.714
257.791	383.86
264.178	360.939
270.561	347.587
276.939	378.875
283.31	332.319
289.678	299.917
296.039	302.5
302.396	344.809
308.746	501.353
315.093	922.998
321.433	1172.5
327.768	755.169
334.099	461.706
340.423	397.475
346.743	393.555
353.058	444.208
359.367	437.226
365.671	354.03
371.971	269.132
378.265	234.123
384.553	230.189
390.837	208.734
397.116	214.67
403.389	217.989
409.657	247.699
415.92	270.749
422.178	307.974
428.431	352.111
434.678	348.471
440.921	360.796
447.158	426.443
453.391	448.589
459.618	359.807
465.84	281.049
472.057	257.555
478.27	262.249
484.477	247.372
490.679	256.723
496.876	293.133
503.068	350.129
509.255	383.897
515.436	372.064
521.613	377.26
527.785	377.059
533.952	342.349
540.113	299.908
546.27	257.987
552.423	262.903
558.568	221.428
564.711	219.244
570.848	236.619
576.979	214.306
583.107	254.806
589.228	278.47
595.345	279.996
601.458	285.653
607.565	314.083
613.667	310.049
619.764	302.503
625.856	247.997
631.944	219.246
638.026	214.562
644.104	229.316
650.177	218.613
656.244	205.874
662.308	171.643
668.365	160.02
674.418	131.952
680.467	131.954
686.511	121.8
692.549	135.134
698.582	135.439
704.611	133.836
710.635	139.66
716.655	131.104
722.669	124.455
728.679	119.592
734.683	124.996
740.683	128.512
746.678	119.921
752.669	133.801
758.654	140.318
764.635	117.239
770.611	131.624
776.582	125.416
782.549	119.073
788.511	138.073
794.466	124.967
800.419	129.663
806.366	117.293
812.309	129.36
818.247	139.416
824.18	125.033
830.108	141.576
836.033	130.332
841.952	141.753
847.865	140.131
853.776	144.211
859.681	165.315
865.58	192.22
871.476	204.066
877.366	228.042
883.253	223.462
889.134	225.358
895.012	217.639
900.883	212.522
906.751	224.281
912.614	234.989
918.473	217.586
924.326	251.252
930.174	279.639
936.019	344.157
941.859	422.841
947.693	479.49
953.525	485.172
959.35	488.664
965.171	514.752
970.988	604.901
976.801	775.189
982.608	855.954
988.411	752.158
994.209	593.088
1000	518.666
1005.79	541.01
1011.58	602.145
1017.36	672.393
1023.13	609.314
1028.9	469.94
1034.67	396.289
1040.43	365.718
1046.19	341.731
1051.94	290.231
1057.69	280.064
1063.44	256.97
1069.17	263.676
1074.91	309.198
1080.64	370.035
1086.37	497.597
1092.09	713.278
1097.8	694.433
1103.52	531.573
1109.22	436.027
1114.93	372.952
1120.63	349.81
1126.32	382.77
1132.01	423.821
1137.7	527.781
1143.38	693.106
1149.06	865.346
1154.73	583.395
1160.4	347.886
1166.06	255.881
1171.72	232.852
1177.38	199.105
1183.03	182.183
1188.67	176.275
1194.31	153.915
1199.95	146.347
1205.58	131.101
1211.21	125.676
1216.84	119.288
1222.46	105.93
1228.07	117.432
1233.68	111.904
1239.29	117.318
1244.89	116.555
1250.49	108.585
1256.08	115.676
1261.67	119.587
1267.26	125.474
1272.84	245.967
1278.42	145.049
1283.99	109.689
1289.56	118.527
1295.12	114.437
1300.68	112.426
1306.23	109.535
1311.78	109.798
1317.33	105.117
1322.87	98.4254
1328.41	101.86
1333.94	102.254
1339.47	99.5344
1345	98.7482
1350.52	107.14
1356.04	100.114
1361.55	112.53
1367.06	107.397
1372.56	135.097
1378.06	363.039
1383.56	113.43
1389.05	114.402
1394.53	115.446
1400.02	126.924
1405.5	112.699
1410.97	96.4033
1416.44	102.811
1421.91	95.7993
1427.37	105.388
1432.83	108.785
1438.28	102.798
1443.73	103.053
1449.17	106.414
1454.62	99.1885
1460.05	105.532
1465.48	99.2233
1470.91	99.1944
1476.34	107.586
1481.76	108.681
1487.17	94.05
1492.59	105.743
1497.99	97.4975
1503.4	95.5911
1508.8	107.479
1514.19	99.2926
1519.59	101.747
1524.97	108.514
1530.36	101.383
1535.74	113.607
1541.11	102.047
1546.48	102.207
1551.85	104.377
1557.21	97.7644
1562.57	110.617
1567.93	104.035
1573.28	106.079
1578.62	101.723
1583.97	104.963
1589.3	103.93
1594.64	101.864
1599.97	114.953
1605.3	115.167
1610.62	113.3
1615.94	108.252
1621.25	110.855
1626.56	106.89
1631.87	102.882
1637.17	108.699
1642.47	105.522
1647.76	109.004
1653.05	105.804
1658.34	115.849
1663.62	113.666
1668.9	115.895
1674.18	107.024
1679.45	114.768
1684.71	110.254
1689.98	103.52
1695.23	101.285
1700.49	102.518
1705.74	114.168
1710.99	104.285
1716.23	114.368
1721.47	112.456
1726.7	120.482
1731.94	103.888
1737.16	115.346
1742.39	115.567
1747.61	118.031
1752.82	119.314
1758.03	108.098
1763.24	117.192
1768.44	114.983
1773.64	107.121
1778.84	116.313
1784.03	113.084
1789.22	122.418
1794.41	112.421
1799.59	117.285
1804.76	116.462
1809.94	129.394
1815.11	121.603
1820.27	110.314
1825.43	117.509
1830.59	122.429
1835.74	114.592
1840.89	108.997
1846.04	109.189
1851.18	126.913
1856.32	121.218
1861.45	114.398
1866.58	121.689
1871.71	123.084
1876.83	123.249
1881.95	122.217
1887.07	116.425
1892.18	127.092
1897.29	123.563
1902.39	123.692
1907.49	116.815
1912.59	129.037
1917.68	121.104
1922.77	116.462
1927.86	121.478
1932.94	124.109
1938.02	117.108
1943.09	114.858
1948.16	125.812
1953.23	121.069
1958.29	125.931
1963.35	125.953
1968.41	124.73
1973.46	116.231
1978.51	124.594
1983.55	130.539
1988.59	122.063
1993.63	138.855
1998.66	128.023
2003.69	129.251
2008.72	123.308
2013.74	127.022
2018.76	128.313
2023.77	134.447
2028.78	127.38
2033.79	130.028
2038.79	113.312
2043.79	131.757
2048.79	128.397
2053.78	128.624
2058.77	125.225
2063.76	147.545
2068.74	139.283
2073.72	137.119
2078.69	133.696
2083.66	138.868
2088.63	145.234
2093.59	143.015
2098.55	132.173
2103.51	154.891
2108.46	139.091
2113.41	162.026
2118.36	151.236
2123.3	154.213
2128.24	145.819
2133.17	139.872
2138.11	145.275
2143.03	140.507
2147.96	149.687
2152.88	154.999
2157.79	151.335
2162.71	154.002
2167.62	139.989
2172.52	151.581
2177.43	140.166
2182.32	154.269
2187.22	141.447
2192.11	144.059
2197	149.288
2201.89	136.649
2206.77	148.447
2211.64	147.466
2216.52	134.898
2221.39	144.3
2226.26	145.965
2231.12	143.735
2235.98	153.229
2240.84	134.002
2245.69	152.697
2250.54	145.201
2255.39	144.24
2260.23	151.219
2265.07	140.971
2269.9	147.855
2274.74	145.407
2279.57	148.223
2284.39	144.315
2289.21	144.353
2294.03	147.047
2298.84	144.465
2303.66	145.94
2308.46	151.517
2313.27	151.831
2318.07	157.57
2322.87	157.964
2327.66	150.303
2332.45	156.144
2337.24	148.492
2342.02	146.254
2346.8	150.882
2351.58	154.149
2356.35	142.248
2361.12	149.458
2365.89	158.061
2370.65	144.565
2375.41	162.875
2380.17	142.336
2384.92	152.236
2389.67	159.314
2394.42	159.371
2399.16	156.585
2403.9	149.612
2408.64	148.232
2413.37	144.308
2418.1	153.405
2422.83	145.467
2427.55	141.48
2432.27	144.671
2436.99	160.675
2441.7	159.738
2446.41	163.062
2451.11	156.413
2455.82	145.406
2460.51	155.887
2465.21	164.981
2469.9	162.533
2474.59	164.393
2479.28	157.568
2483.96	146.304
2488.64	178.704
2493.32	162.986
2497.99	157.468
2502.66	163.636
2507.32	171.264
2511.99	167.095
2516.65	161.407
2521.3	167.563
2525.96	163.386
2530.61	168.077
2535.25	165.413
2539.89	174.661
2544.53	172.042
2549.17	164.963
2553.8	160.836
2558.43	159.632
2563.06	179.503
2567.68	155.855
2572.3	181.933
2576.92	168.761
2581.53	169.108
2586.14	189.087
2590.75	166.441
2595.35	175.766
2599.96	176.047
2604.55	177.798
2609.15	178
2613.74	165.903
2618.33	179.82
2622.91	169.257
2627.49	190.915
2632.07	182.049
2636.64	179.432
2641.22	186.177
2645.78	186.789
2650.35	185.811
2654.91	192.551
2659.47	191.329
2664.03	182.221
2668.58	184.043
2673.13	196.984
2677.67	192.979
2682.22	198.688
2686.76	196.412
2691.29	202.023
2695.83	181.733
2700.36	182.116
2704.89	192.129
2709.41	194.092
2713.93	183.141
2718.45	180.308
2722.96	182.266
2727.47	201.983
2731.98	207.041
2736.49	205.585
2740.99	194.372
2745.49	199.509
2749.98	183.547
2754.47	198.822
2758.96	200.839
2763.45	189.65
2767.93	201.55
2772.41	200.278
2776.89	187.556
2781.36	191.447
2785.84	205.398
2790.3	189.389
2794.77	203.366
2799.23	200.551
2803.69	211.112
2808.14	203.111
2812.59	188.285
2817.04	197.019
2821.49	187.164
2825.93	190.875
2830.37	199.674
2834.81	194.852
2839.24	200.242
2843.67	200.54
2848.1	199.189
2852.53	192.755
2856.95	198.39
2861.37	212.677
2865.78	202.958
2870.19	191.465
2874.6	207.697
2879.01	180.469
2883.41	196.846
2887.81	199.308
2892.21	187.647
2896.6	207.753
2901	196.102
2905.38	180.695
2909.77	202.655
2914.15	206.701
2918.53	207.173
2922.91	182.515
2927.28	186.635
2931.65	212.509
2936.02	207.6
2940.38	204.37
2944.74	202.923
2949.1	205.025
2953.46	216.276
2957.81	200.129
2962.16	204.085
2966.5	202.587
2970.85	212.139
2975.19	207.018
2979.52	211.093
2983.86	218.949
2988.19	219.506
2992.52	236.837
2996.85	207.712
3001.17	240.137
3005.49	220.325
3009.8	226.703
3014.12	229.3
3018.43	241.485
3022.74	225.233
3027.04	235.426
3031.34	258.955
3035.64	238.426
3039.94	250.406
3044.23	243.206
3048.52	253.26
3052.81	265.262
3057.09	263.819
3061.38	277.837
3065.65	278.327
3069.93	267.155
3074.2	277.365
3078.47	279.833
3082.74	288.166
3087	273.153
3091.27	291.571
3095.52	316.127
3099.78	307.277
3104.03	316.276
3108.28	313.482
3112.53	344.699
3116.77	329.996
3121.01	357.521
3125.25	342.888
3129.49	360.733
3133.72	335.959
3137.95	356.037
3142.18	361.739
3146.4	354.933
3150.62	374.962
3154.84	376.119
3159.06	393.944
3163.27	422.371
3167.48	406.699
3171.69	433.105
3175.89	404.545
3180.09	407.35
3184.29	412.15
3188.49	433.782
3192.68	419.563
3196.87	411.877
3201.06	396.124
3205.24	416.827
3209.42	399.133
3213.6	383.498
3217.78	380.821
3221.95	371.451
3226.12	375.136
3230.29	365.623
3234.45	369.196
3238.61	355.045
3242.77	329.834
3246.93	337.916
3251.08	287.588
3255.23	317.505
3259.38	289.12
3263.53	310.431
3267.67	291.597
3271.81	295.065
3275.95	291.262
3280.08	271.263
3284.21	276.403
3288.34	290.744
3292.47	286.68
3296.59	261.804
3300.71	278.518
3304.83	267.481
3308.95	270.319
3313.06	261.486
3317.17	268.954
3321.27	262.516
3325.38	270.179
3329.48	245.1
3333.58	264.797
3337.67	253.922
3341.77	273.521
3345.86	262.219
3349.95	253.154
3354.03	248.83
3358.11	268.479
3362.19	254.739
3366.27	240.897
3370.34	251.022
3374.42	239.451
3378.48	251.857
3382.55	237.721
3386.61	223.521
3390.68	233.446
3394.73	238.561
3398.79	231.639
3402.84	224.624
3406.89	236.992
3410.94	203.133
3414.98	208.161
3419.03	218.074
3423.06	223.1
3427.1	225.727
3431.14	213.774
3435.17	223.863
3439.2	221.795
3443.22	214.846
3447.25	220.287
3451.27	223.305
3455.28	223.949
3459.3	214.776
3463.31	200.582
3467.32	216.295
3471.33	206.984
3475.34	215.079
3479.34	203.118
3483.34	211.31
3487.33	201.758
3491.33	209.943
3495.32	207.918
3499.31	213.488
3503.3	211.317
3507.28	201.377
3511.26	198.977
3515.24	206.812
3519.22	212.073
3523.19	196.762
3527.16	199.489
3531.13	209.934
3535.1	199.975
3539.06	218.548
3543.02	211.213
3546.98	198.586
3550.93	201.436
3554.89	219.714
3558.84	209.534
3562.78	215.034
3566.73	231.075
3570.67	205.419
3574.61	229.46
3578.55	216.899
3582.48	241.258
3586.41	228.756
3590.35	229.426
3594.27	208.811
3598.2	209.407
3602.12	204.591
3606.04	199.724
3609.95	173.281
3613.87	214.029
3617.78	192.86
3621.69	209.348
3625.6	195.981
3629.5	185.281
3633.4	201.579
3637.3	193.611
3641.2	188.473
3645.09	194.275
3648.98	180.954
3652.87	194.767
3656.76	192.22
3660.64	206.03
3664.53	178.877
3668.4	200.935
3672.28	203.865
3676.16	201.427
3680.03	182.595
3683.9	202.297
3687.76	186.299
3691.63	178.527
3695.49	195.624
3699.35	173.895
3703.2	193.87
3707.06	197.207
3710.91	180.922
3714.76	178.578
3718.6	184.608
3722.45	193.449
3726.29	205.106
3730.13	185.626
3733.97	183.144
3737.8	177.799
3741.63	186.649
3745.46	184.09
3749.29	190.055
3753.11	187.394
3756.93	187.537
3760.75	187.636
3764.57	190.586
3768.39	173.486
3772.2	182.242
3776.01	179.527
3779.81	185.477
3783.62	188.628
3787.42	188.917
3791.22	186.284
3795.02	177.922
3798.81	195.67
3802.61	190.271
3806.4	181.97
3810.18	182.383
3813.97	182.757
3817.75	191.91
3821.53	192.271
3825.31	186.702
3829.09	172.286
3832.86	181.466
3836.63	199.524
3840.4	182.077
3844.17	170.564
3847.93	179.613
3851.69	179.738
3855.45	179.822
3859.21	173.889
3862.96	182.869
3866.71	186.16
3870.46	183.613
3874.21	180.724
3877.95	171.87
3881.69	160.019
3885.44	172.126
3889.17	178.29
3892.91	172.518
3896.64	178.845
3900.37	179.122
3904.1	164.311
3907.82	188.693
3911.55	167.826
3915.27	171.149
3918.99	174.544
3922.7	181.059
3926.42	166.221
3930.13	187.961
3933.84	163.783
3937.54	173.214
3941.25	170.447
3944.95	183.106
3948.65	168.031
3952.35	177.548
3956.04	187.058
3959.73	184.145
3963.42	184.289
3967.11	165.79
3970.8	184.426
3974.48	175.189
3978.16	172.135
3981.84	193.836
3985.52	187.622
3989.19	159.704
3992.86	162.86
3996.53	181.601
3998.37	156.843