File: Data/3-Raman/raw/bu19w-ff1-fi04-l_150 (500nm)_532nm_edge_100%_x100_vis_h50um_15sx2_01.txt
#Acq. time (s)=	15
#Accumulations=	2
#Range (cm-¹)=	100...5000
#Windows=	1
#Auto scanning=	Off
#Autofocus=	Off
#Macrospot=	Off
#AutoExposure=	Off
#Spike filter=	Multiple accum.
#Delay time (s)=	2
#Binning=	1
#Readout mode=	Signal
#DeNoise=	Off
#ICS correction=	On
#Dark correction=	Off
#Inst. Process=	Off
#Detector Gain=	Best Dynamic
#Detector ADC=	50 kHz HS
#Detector temperature (°C)=	-60.09
#Instrument=	LabRAM HR Evol
#Detector=	SIN-EM FIVIS
#Objective=	x100_VIS
#Grating=	150 (500nm)
#ND Filter=	100%
#Laser=	532nm_Edge
#Hole=	49.98
#Temperature=	0
#Range=	Visible
#StageXY=	75x50mm Scan+
#StageZ=	Z motor
#X (µm)=	0
#Y (µm)=	0
#Z (µm)=	-140.4
#Full time(s)=	34
#Project=	21_05_14
#Sample=	BU19w
#Site=
#Title=	BU19w-FF1-FI04-L_150 (500nm)_532nm_Edge_100%_x100_VIS_H50um_15sX2
#Remark=
#Date=	14.05.2021 14:23
#Acquired=	14.05.2021 14:23:02
102.699	6906.87
107.322	6718.54
111.942	6491.07
116.56	6141.8
121.173	5835.76
125.787	5670.3
130.398	5583.25
135.006	5409.28
139.613	5212.35
144.215	5006.1
148.817	4930.27
153.417	4859.46
158.014	5012.75
162.607	5453.05
167.2	5382.82
171.79	4581.88
176.379	4282.49
180.963	4356.74
185.547	5508.83
190.128	7353.53
194.705	6203.75
199.282	4181.81
203.857	3533.17
208.43	3235.7
212.998	3158.47
217.566	3070.25
222.132	2995.43
226.693	2883.25
231.254	2835.37
235.813	2893.88
240.368	2911.16
244.923	3057.65
249.475	3253.3
254.023	3154.17
258.571	2965.09
263.117	2734.07
267.658	2706.06
272.199	2941.51
276.738	3876.06
281.273	5064.75
285.807	4716.02
290.34	3429.61
294.868	2913.97
299.396	3074.05
303.919	3758.74
308.443	3859.96
312.964	2994.97
317.481	2674.53
321.998	2496.48
326.51	2647.85
331.023	2967.53
335.533	2854.94
340.039	2591.63
344.544	2465.19
349.046	2528.18
353.547	2551.51
358.045	2411.22
362.542	2332.75
367.036	2252.58
371.527	2311.76
376.017	2340.28
380.503	2376.96
384.99	2529.08
389.471	2722.57
393.953	2835.74
398.43	2928.08
402.908	2818.43
407.381	2630.11
411.854	2558.31
416.323	2752.61
420.791	3006.86
425.256	2766.57
429.72	2442.44
434.18	2342.53
438.64	2328.22
443.095	2324.72
447.551	2343.37
452.003	2684.43
456.454	3241.86
460.901	3421.3
465.348	2804.81
469.791	2486.85
474.231	2342.08
478.672	2354.83
483.108	2433.34
487.544	2449.98
491.976	2515.59
496.408	2667.7
500.836	2646.07
505.261	2584.28
509.687	2450.38
514.108	2490.22
518.529	2336
522.946	2425.75
527.361	2381.55
531.776	2434.1
536.187	2403.51
540.595	2419.18
545.003	2495.08
549.408	2457.44
553.812	2487.19
558.212	2443.83
562.61	2590.74
567.007	2439.71
571.401	2424.09
575.792	2398.65
580.184	2395.42
584.571	2540.7
588.956	2881.13
593.341	3215.98
597.722	2897.12
602.101	2624.16
606.48	2542.1
610.854	2826.09
615.227	3045.66
619.597	2848.97
623.967	2568.68
628.334	2317.02
632.698	2308.5
637.06	2315.07
641.422	2364.01
645.779	2415.11
650.135	2341.93
654.491	2349.8
658.842	2291.43
663.192	2367.53
667.539	2408.83
671.884	2453.57
676.23	2527.08
680.571	2585.14
684.91	2514.8
689.247	2381.36
693.583	2285.93
697.916	2219.37
702.247	2191.65
706.576	2181.53
710.902	2158.24
715.229	2224.49
719.551	2172.16
723.872	2168.02
728.19	2150.26
732.506	2217.79
736.82	2177.45
741.134	2210.08
745.444	2130.73
749.752	2238.48
754.058	2228.9
758.362	2211.22
762.664	2295.03
766.964	2375.34
771.264	2610.76
775.559	2934.16
779.853	3368.73
784.144	3304.64
788.434	2958.13
792.722	2607.11
797.007	2407.39
801.29	2307.9
805.572	2255.84
809.851	2261.37
814.13	2204.76
818.406	2186.46
822.679	2174.27
826.95	2142.53
831.219	2157.16
835.486	2155.13
839.752	2116.52
844.015	2124.89
848.276	2157.06
852.535	2131.69
856.792	2162.54
861.047	2162.31
865.3	2295.52
869.551	2355.44
873.8	2276.26
878.047	2172.84
882.292	2154.22
886.534	2133.62
890.775	2111.16
895.014	2140.65
899.251	2146.73
903.486	2121.95
907.719	2120.01
911.95	2123.96
916.179	2106.9
920.406	2159
924.63	2131.52
928.853	2123.43
933.074	2159.64
937.293	2226.08
941.51	2198.97
945.723	2275.12
949.936	2306.93
954.147	2379.37
958.356	2370.06
962.563	2357.88
966.768	2429.73
970.971	2514.8
975.172	2453.7
979.371	2354.1
983.568	2267.44
987.761	2249.24
991.954	2236.76
996.145	2246.2
1000.33	2223.41
1004.52	2225.26
1008.71	2241.44
1012.89	2209.99
1017.07	2210.4
1021.25	2225.65
1025.43	2286.66
1029.6	2341.37
1033.77	2356.31
1037.95	2367.79
1042.11	2474.26
1046.28	2637.88
1050.45	3110.16
1054.61	3767.85
1058.77	3837.57
1062.93	3304.14
1067.09	2919.57
1071.24	2719.69
1075.4	2632.18
1079.55	2696.69
1083.7	2916.23
1087.85	3384.7
1091.99	3810.95
1096.14	3888.79
1100.28	3495.58
1104.42	3322.05
1108.55	3437.33
1112.69	3658.76
1116.82	3509.89
1120.96	3443.58
1125.09	3257.38
1129.21	3284.33
1133.34	3408.01
1137.46	3365.63
1141.59	3197.9
1145.71	2906.56
1149.83	2852.99
1153.94	2989.57
1158.06	3187.83
1162.17	3281.6
1166.28	3104.42
1170.39	2870.47
1174.5	2757.71
1178.6	2598.66
1182.7	2503.58
1186.8	2452.05
1190.9	2450.17
1195	2438.32
1199.1	2489.91
1203.19	2505.3
1207.28	2468.91
1211.37	2383.37
1215.46	2428.41
1219.54	2473.71
1223.63	2583.21
1227.71	2605.2
1231.79	2527.12
1235.87	2542.29
1239.95	2676.24
1244.02	2790.45
1248.09	2701.95
1252.16	2616.09
1256.23	2546.61
1260.3	2569.42
1264.36	2545.64
1268.43	2594.57
1272.49	2572.44
1276.55	2499.96
1280.6	2476.41
1284.66	2407.83
1288.71	2440.75
1292.76	2406.66
1296.81	2453.04
1300.86	2398.23
1304.91	2430.66
1308.95	2390.62
1312.99	2408.2
1317.03	2452.14
1321.07	2428.29
1325.11	2435.31
1329.14	2427.76
1333.18	2425.24
1337.21	2449.24
1341.24	2497.84
1345.26	2477.26
1349.29	2504.61
1353.31	2518.02
1357.33	2541.31
1361.35	2557.51
1365.37	2662.42
1369.39	2948.01
1373.4	3282.03
1377.41	3223.49
1381.43	2924.92
1385.43	2643.57
1389.44	2553.57
1393.45	2537.53
1397.45	2445.15
1401.45	2456.6
1405.45	2416.14
1409.45	2457.69
1413.44	2488.6
1417.44	2407.93
1421.43	2448.5
1425.42	2457.65
1429.41	2423.51
1433.39	2394.97
1437.38	2436.14
1441.36	2465.54
1445.34	2448.01
1449.32	2449.17
1453.3	2473.47
1457.27	2500.5
1461.24	2462.75
1465.22	2500.27
1469.19	2498.68
1473.15	2445.16
1477.12	2426.51
1481.09	2456.72
1485.05	2483.73
1489.01	2463.79
1492.97	2474.35
1496.93	2459.64
1500.88	2531
1504.83	2486.15
1508.79	2472.97
1512.74	2528.74
1516.68	2494.47
1520.63	2523.52
1524.57	2552.7
1528.52	2513.3
1532.46	2543.93
1536.4	2507.68
1540.33	2487.02
1544.27	2559.37
1548.2	2538.72
1552.14	2602.18
1556.07	2570.29
1559.99	2576.81
1563.92	2577.26
1567.84	2585.22
1571.77	2580.5
1575.69	2627.86
1579.61	2582.44
1583.52	2624.68
1587.44	2653.2
1591.35	2641.25
1595.27	2705.22
1599.18	2702.94
1603.09	2716.38
1606.99	2751.17
1610.9	2770.64
1614.8	2768.4
1618.7	2791.19
1622.6	2784.32
1626.5	2786.61
1630.39	2756.95
1634.29	2835.92
1638.18	2824.06
1642.07	2815.01
1645.96	2801.47
1649.85	2766.05
1653.73	2856.25
1657.62	2804.17
1661.5	2735.4
1665.38	2800.67
1669.26	2768.32
1673.13	2770.92
1677.01	2727.64
1680.88	2711.91
1684.75	2658.53
1688.62	2691.1
1692.49	2672.36
1696.35	2671.44
1700.22	2666.17
1704.08	2628.92
1707.94	2653.02
1711.8	2637.9
1715.66	2690.18
1719.51	2618.6
1723.37	2652.77
1727.22	2680.78
1731.07	2630.69
1734.92	2641.69
1738.76	2624.2
1742.61	2624.46
1746.45	2619.21
1750.29	2614.44
1754.13	2663.7
1757.97	2623.35
1761.81	2635.26
1765.64	2603.38
1769.47	2594.5
1773.31	2610.31
1777.14	2644.28
1780.96	2624.05
1784.79	2651.7
1788.61	2666.54
1792.43	2634.62
1796.25	2640.11
1800.07	2623.9
1803.89	2639.6
1807.71	2692.92
1811.52	2615.73
1815.33	2630.04
1819.14	2633.97
1822.95	2591.16
1826.76	2639.23
1830.56	2639.4
1834.37	2655.04
1838.17	2637.31
1841.97	2632.24
1845.77	2631.78
1849.56	2653.32
1853.36	2656.89
1857.15	2667.2
1860.94	2657.36
1864.73	2640.19
1868.52	2672.55
1872.31	2646.92
1876.09	2618.06
1879.87	2688.66
1883.66	2650.08
1887.43	2668.54
1891.21	2649.88
1894.99	2656.78
1898.76	2694.77
1902.53	2677.48
1906.31	2671.56
1910.08	2701.34
1913.84	2665.3
1917.61	2669.95
1921.37	2659.84
1925.14	2700.04
1928.9	2688.74
1932.66	2695.12
1936.41	2731.27
1940.17	2731.96
1943.92	2708.84
1947.68	2702.03
1951.43	2697.92
1955.18	2763.94
1958.92	2725.24
1962.67	2742.66
1966.41	2728.77
1970.16	2685.36
1973.9	2714.6
1977.64	2719.82
1981.37	2706.87
1985.11	2750.4
1988.84	2748.85
1992.57	2726.15
1996.31	2749.52
2000.03	2745.55
2003.76	2767.89
2007.49	2789.1
2011.21	2823.9
2014.93	3101.7
2018.65	2965.23
2022.37	2836.81
2026.09	2813.59
2029.81	2813.65
2033.52	2807.27
2037.23	2791.84
2040.94	2781.16
2044.65	2790.2
2048.36	2787.95
2052.07	2830.03
2055.77	2789.24
2059.47	2825.91
2063.17	2780
2066.87	2758.19
2070.57	2777.89
2074.27	2835.62
2077.96	2790.18
2081.65	2817.75
2085.34	2811.18
2089.03	2734.01
2092.72	2815.26
2096.41	2815.34
2100.09	2886.53
2103.77	2795.43
2107.46	2787.54
2111.14	2761.73
2114.81	2799.99
2118.49	2783.48
2122.16	2820.66
2125.84	2854.76
2129.51	2852.14
2133.18	2793.06
2136.85	2811.31
2140.51	2816.07
2144.18	2832.49
2147.84	2804.68
2151.5	2802.68
2155.16	2830.15
2158.82	2820.21
2162.48	2816.28
2166.13	2786.35
2169.79	2785.54
2173.44	2794.08
2177.09	2759.12
2180.74	2776.31
2184.38	2786.24
2188.03	2798.4
2191.67	2791.52
2195.32	2863.09
2198.96	2819.26
2202.6	2814.09
2206.23	2787.45
2209.87	2833.48
2213.5	2867.98
2217.14	2785.16
2220.77	2829.97
2224.4	2801.28
2228.03	2824.87
2231.65	2807.26
2235.28	2794.29
2238.9	2832.99
2242.52	2819.81
2246.14	2819.56
2249.76	2779.58
2253.38	2785.44
2256.99	2828.78
2260.6	2773.73
2264.21	2749.33
2267.82	2818.48
2271.44	2757.06
2275.04	2771.57
2278.65	2794.46
2282.25	2782.96
2285.85	2795.65
2289.45	2752.07
2293.05	2781.18
2296.65	2823.76
2300.25	2784.72
2303.84	2788.57
2307.43	2794.79
2311.02	2755.13
2314.62	2800.31
2318.2	2785.22
2321.79	2805.88
2325.38	2773.23
2328.96	2839
2332.54	2772.91
2336.12	2729.32
2339.7	2812.45
2343.28	2755.12
2346.85	2824.2
2350.43	2769.42
2354	2799.64
2357.57	2803.47
2361.14	2836.92
2364.71	2762.66
2368.27	2816.08
2371.84	2789.17
2375.4	2765.74
2378.96	2857.05
2382.52	2795.61
2386.08	2780.66
2389.64	2822.31
2393.19	2703.17
2396.75	2765.68
2400.3	2786.32
2403.85	2743.83
2407.4	2744.93
2410.95	2755.43
2414.49	2746.24
2418.04	2787.29
2421.58	2740.53
2425.12	2731.25
2428.66	2735.49
2432.2	2756.96
2435.74	2739.06
2439.27	2805.01
2442.81	2770.68
2446.34	2772.01
2449.87	2784.28
2453.4	2722.51
2456.93	2776.67
2460.45	2784.46
2463.98	2737.46
2467.5	2738.2
2471.02	2833.73
2474.54	2753.81
2478.06	2744.78
2481.58	2788.96
2485.09	2734.56
2488.61	2718.78
2492.12	2781.26
2495.63	2770.66
2499.14	2745.57
2502.65	2794.23
2506.15	2799.44
2509.66	2737.36
2513.16	2725.32
2516.66	2755.67
2520.16	2729.03
2523.66	2764.97
2527.16	2779.09
2530.66	2757.54
2534.15	2757.13
2537.64	2757.26
2541.13	2689.35
2544.62	2788.09
2548.11	2759.72
2551.6	2777.95
2555.08	2687.61
2558.57	2690.7
2562.05	2728.3
2565.53	2694.34
2569.01	2731.03
2572.49	2712.27
2575.96	2713.7
2579.44	2684.3
2582.91	2775.77
2586.38	2716.73
2589.85	2697.73
2593.32	2703.37
2596.79	2749.87
2600.25	2665.75
2603.72	2741.08
2607.18	2753.21
2610.64	2731.7
2614.1	2709.43
2617.56	2715.95
2621.02	2768.04
2624.47	2711.71
2627.92	2750.99
2631.38	2736.87
2634.83	2689.26
2638.28	2757.17
2641.72	2690.3
2645.17	2700.88
2648.61	2777.63
2652.06	2738.21
2655.5	2700.17
2658.94	2698.93
2662.38	2707.74
2665.82	2699.53
2669.25	2723.02
2672.69	2745.85
2676.12	2753.02
2679.55	2734.53
2682.98	2695.31
2686.41	2718.47
2689.84	2733.99
2693.26	2651.83
2696.69	2629.88
2700.11	2683.75
2703.53	2712.72
2706.95	2722.44
2710.37	2730.11
2713.79	2630.34
2717.2	2683.77
2720.62	2676.17
2724.03	2690.23
2727.44	2670.97
2730.85	2680.5
2734.26	2690.96
2737.66	2710.84
2741.07	2672.08
2744.47	2714.42
2747.87	2641.22
2751.28	2688.27
2754.67	2718.79
2758.07	2656.49
2761.47	2713.93
2764.86	2709.77
2768.26	2684.29
2771.65	2724.62
2775.04	2677.8
2778.43	2744.51
2781.82	2631.14
2785.2	2712.48
2788.59	2712.84
2791.97	2685.71
2795.35	2713.34
2798.73	2673.69
2802.11	2687.56
2805.49	2696.71
2808.87	2703.8
2812.24	2705.16
2815.62	2727.75
2818.99	2719.86
2822.36	2648.08
2825.73	2654.89
2829.1	2666.62
2832.46	2717.06
2835.83	2657.07
2839.19	2700.07
2842.55	2622.5
2845.91	2723.74
2849.27	2704.16
2852.63	2717.56
2855.99	2711.65
2859.34	2720.21
2862.69	2664.25
2866.05	2643.94
2869.4	2691.92
2872.75	2722.99
2876.09	2735.21
2879.44	2718.22
2882.78	2735.86
2886.13	2687.26
2889.47	2723.78
2892.81	2722.67
2896.15	2775.09
2899.49	2720.22
2902.82	2786.96
2906.16	2740.9
2909.49	2743.74
2912.82	2716.28
2916.16	2724.26
2919.49	2746.22
2922.81	2724.6
2926.14	2749.7
2929.46	2733.08
2932.79	2784.74
2936.11	2775.01
2939.43	2767.18
2942.75	2803.65
2946.07	2799.79
2949.39	2839.09
2952.7	2766.42
2956.02	2844.52
2959.33	2782.23
2962.64	2820.29
2965.95	2882.4
2969.26	2845.32
2972.57	2844.29
2975.87	2836.87
2979.17	2870.13
2982.48	2856.62
2985.78	2861.16
2989.08	2907.11
2992.38	2912.81
2995.68	2960.09
2998.97	2960.44
3002.27	2925.82
3005.56	2882.99
3008.85	2941.96
3012.14	3010.56
3015.43	2983.95
3018.72	3030.81
3022	3017.3
3025.29	3033.12
3028.57	3064.05
3031.85	3059.91
3035.14	3111.39
3038.41	3131.73
3041.69	3201.32
3044.97	3203.88
3048.24	3182.62
3051.52	3238.31
3054.79	3276.9
3058.06	3261.04
3061.33	3317.44
3064.6	3311.53
3067.87	3329.82
3071.13	3448.86
3074.4	3441.6
3077.66	3514
3080.92	3509.66
3084.18	3561.05
3087.44	3610.31
3090.7	3626.25
3093.95	3653.75
3097.21	3723.57
3100.46	3779.16
3103.71	3778.9
3106.96	3860.68
3110.21	3916.62
3113.46	3922.96
3116.71	4056.14
3119.95	4056.06
3123.2	4123.58
3126.44	4144.3
3129.68	4212.71
3132.92	4274.41
3136.16	4348.3
3139.4	4404.93
3142.63	4421.51
3145.87	4551.79
3149.1	4647.95
3152.33	4652.42
3155.56	4778.12
3158.79	4862.73
3162.02	4914.91
3165.25	4996.36
3168.47	5009.65
3171.69	5121.95
3174.92	5186.12
3178.14	5244.35
3181.36	5384.73
3184.58	5433.03
3187.79	5461
3191.01	5584.2
3194.22	5668.21
3197.43	5686.3
3200.65	5749.28
3203.86	5770.55
3207.07	5840.57
3210.27	5881.44
3213.48	6001.7
3216.69	6052.6
3219.89	6101.7
3223.09	6081.93
3226.29	6151.79
3229.49	6205.04
3232.69	6216.03
3235.89	6385.1
3239.08	6375.89
3242.28	6408.97
3245.47	6487.83
3248.66	6476.74
3251.85	6493.6
3255.04	6593.57
3258.23	6641.33
3261.42	6635.64
3264.6	6679.6
3267.79	6688.43
3270.97	6688.12
3274.15	6726.02
3277.33	6747.55
3280.51	6826.77
3283.68	6746.53
3286.86	6831.71
3290.04	6939.15
3293.21	6947.33
3296.38	6959.96
3299.55	7026.75
3302.72	7049.44
3305.89	7110.25
3309.06	7124.25
3312.22	7240.17
3315.39	7211.45
3318.55	7216.61
3321.71	7325.97
3324.87	7324.44
3328.03	7460.14
3331.19	7490.22
3334.34	7595.46
3337.5	7643.69
3340.65	7813.53
3343.81	7761.26
3346.96	7844.22
3350.11	7912.21
3353.25	7936.69
3356.4	8001.16
3359.55	8135.47
3362.69	8170.17
3365.84	8204.38
3368.98	8304.89
3372.12	8410.22
3375.26	8408.44
3378.4	8511.19
3381.53	8599.38
3384.67	8581.43
3387.8	8707.47
3390.94	8763.08
3394.07	8825.65
3397.2	8938.15
3400.33	8968.92
3403.46	9107.95
3406.58	9280.21
3409.71	9333.28
3412.83	9587.14
3415.96	10075.9
3419.08	11390.8
3422.2	14065.1
3425.32	15603.8
3428.44	13745.6
3431.55	11168.6
3434.67	9940.6
3437.78	9676.02
3440.89	9367.22
3444	9322.61
3447.12	9155.82
3450.22	9036.28
3453.33	9107.26
3456.44	9028.3
3459.54	8987.18
3462.65	8899.21
3465.75	8845.75
3468.85	8827.57
3471.95	8721.06
3475.05	8584.33
3478.15	8618.53
3481.24	8590.47
3484.34	8487.37
3487.43	8417.24
3490.53	8375.42
3493.62	8345.23
3496.71	8484.84
3499.79	8428.98
3502.88	8521.22
3505.97	8556.56
3509.05	8359.27
3512.14	8070.11
3515.22	7856.09
3518.3	7558.77
3521.38	7332.79
3524.46	7212.41
3527.54	6974.36
3530.61	6852.24
3533.69	6688.59
3536.76	6602.08
3539.83	6453.19
3542.9	6291.81
3545.97	6270.16
3549.04	6080.25
3552.11	5952.3
3555.18	5889.5
3558.24	5776.15
3561.3	5671.76
3564.37	5665.36
3567.43	5466.78
3570.49	5403.69
3573.55	5240.36
3576.61	5193.44
3579.66	5112.89
3582.72	5013.84
3585.77	4954.5
3588.82	4862.47
3591.87	4810.04
3594.92	4660.61
3597.97	4628.65
3601.02	4589.72
3604.07	4521.08
3607.11	4471.31
3610.16	4293.79
3613.2	4255.16
3616.24	4193.99
3619.28	4173.66
3622.32	4066.74
3625.36	4054.43
3628.39	3908.26
3631.43	3869.31
3634.46	3786.8
3637.5	3665.48
3640.53	3618.92
3643.56	3525.29
3646.59	3521.43
3649.62	3360.87
3652.64	3325.56
3655.67	3254.29
3658.69	3120.83
3661.72	3053.59
3664.74	3034.9
3667.76	2906.97
3670.78	2851.85
3673.79	2803.43
3676.81	2756.09
3679.83	2619.78
3682.84	2630.79
3685.86	2502.81
3688.87	2550.82
3691.88	2489.09
3694.89	2401.27
3697.9	2373.37
3700.91	2405.38
3703.91	2312.07
3706.92	2303
3709.92	2329.85
3712.92	2249.9
3715.92	2248.94
3718.92	2205.92
3721.92	2216.94
3724.92	2206.81
3727.92	2223.18
3730.91	2207.92
3733.91	2158.14
3736.9	2147.21
3739.89	2099.87
3742.88	2123.71
3745.87	2116.91
3748.86	2147.93
3751.85	2127.56
3754.83	2076.89
3757.82	2052.82
3760.8	2075.06
3763.78	2049.9
3766.76	2076.95
3769.74	2043.61
3772.72	2012.37
3775.7	2003.97
3778.67	2028.77
3781.65	1994.11
3784.62	2045.48
3787.6	2033.68
3790.57	1999.53
3793.54	2003.34
3796.51	2038.42
3799.47	1982.18
3802.44	1998.78
3805.41	1992.79
3808.37	1999.19
3811.33	1968.8
3814.3	1997.06
3817.26	1962.98
3820.22	1983.83
3823.18	2010.51
3826.13	1986.1
3829.09	1953.1
3832.04	1932.54
3835	1981.42
3837.95	1932.5
3840.9	1954.83
3843.85	1949.61
3846.8	1977.79
3849.75	1959.42
3852.69	1941.08
3855.64	1930.37
3858.58	1958.87
3861.53	1933.75
3864.47	1950.7
3867.41	1881.31
3870.35	1902.83
3873.29	1932.95
3876.22	1918.75
3879.16	1911.06
3882.1	1914.66
3885.03	1915.21
3887.96	1919.5
3890.89	1923.72
3893.82	1857.53
3896.75	1926.68
3899.68	1901.53
3902.61	1880.93
3905.53	1873
3908.46	1875.57
3911.38	1906.78
3914.3	1887.79
3917.23	1907.58
3920.15	1841.68
3923.06	1898.39
3925.98	1859.92
3928.9	1894.14
3931.81	1867.37
3934.73	1887.92
3937.64	1850.51
3940.55	1838.85
3943.46	1847.32
3946.37	1833.94
3949.28	1883.93
3952.19	1868.87
3955.09	1813.74
3958	1869.84
3960.9	1810.08
3963.8	1852.97
3966.71	1828.85
3969.61	1841.26
3972.51	1852.71
3975.4	1843.89
3978.3	1821.47
3981.2	1847.06
3984.09	1813.91
3986.99	1824.02
3989.88	1821.31
3992.77	1824.68
3995.66	1791.5
3998.55	1839.24
4001.43	1778.22
4004.32	1775.05
4007.21	1823.97
4010.09	1815.05
4012.98	1793.6
4015.86	1784.68
4018.74	1815.32
4021.62	1794.79
4024.5	1789.75
4027.37	1773.11
4030.25	1771.98
4033.13	1772.79
4036	1777.56
4038.87	1779.45
4041.75	1792.67
4044.62	1770.99
4047.49	1794.97
4050.35	1768.62
4053.22	1762.77
4056.09	1725.9
4058.95	1735.51
4061.82	1764.55
4064.68	1752.79
4067.54	1727.36
4070.4	1722.34
4073.26	1732.87
4076.12	1761.89
4078.98	1750.96
4081.83	1684.45
4084.69	1755.39
4087.54	1752.16
4090.4	1749.01
4093.25	1713.62
4096.1	1727.01
4098.95	1711.15
4101.8	1686.39
4104.64	1718.22
4107.49	1691.25
4110.33	1695.52
4113.18	1702.51
4116.02	1663.3
4118.86	1661.18
4121.7	1705.21
4124.54	1713.16
4127.38	1704.73
4130.22	1671.22
4133.05	1694.89
4135.89	1667.65
4138.72	1702.03
4141.56	1672.47
4144.39	1645.58
4147.22	1646.2
4150.05	1664.29
4152.88	1689.66
4155.7	1643.86
4158.53	1697.92
4161.36	1664.44
4164.18	1673.03
4167	1613.2
4169.82	1612.14
4172.65	1631.69
4175.46	1615.06
4178.28	1634.7
4181.1	1654.44
4183.92	1660.56
4186.73	1611.96
4189.55	1625.16
4192.36	1606.28
4195.17	1615.02
4197.98	1582.66
4200.79	1612.04
4203.6	1625.77
4206.41	1613.96
4209.21	1590.33
4212.02	1608.91
4214.83	1585.75
4217.63	1599.44
4220.43	1572.47
4223.23	1584.77
4226.03	1601.11
4228.83	1573.16
4231.63	1545.27
4234.42	1601.74
4237.22	1537.28
4240.01	1603.91
4242.81	1582.21
4245.6	1555.44
4248.39	1571.38
4251.18	1543.3
4253.97	1550.07
4256.76	1556.77
4259.55	1555.51
4262.33	1547.29
4265.12	1556.22
4267.9	1509.87
4270.68	1565.11
4273.47	1563.78
4276.25	1552.07
4279.03	1505.84
4281.8	1509.97
4284.58	1527.06
4287.36	1546.01
4290.13	1561.83
4292.91	1533.2
4295.68	1478.37
4298.45	1483.26
4301.22	1468.8
4303.99	1503.05
4306.76	1497.77
4309.53	1466.17
4312.3	1505.65
4315.06	1488.98
4317.83	1486.45
4320.59	1492.96
4323.35	1454.57
4326.11	1466.08
4328.87	1432.7
4331.63	1460.41
4334.39	1473.83
4337.15	1456.77
4339.9	1457.18
4342.66	1416.88
4345.41	1419.54
4348.17	1483.5
4350.92	1434.4
4353.67	1425.19
4356.42	1463.92
4359.17	1435.12
4361.91	1469.82
4364.66	1409.27
4367.41	1462.46
4370.15	1416.13
4372.89	1416.81
4375.63	1411.26
4378.38	1411.78
4381.12	1427.77
4383.86	1425.51
4386.59	1439.17
4389.33	1426.45
4392.07	1405.15
4394.8	1415.69
4397.53	1370.79
4400.27	1419.01
4403	1413.37
4405.73	1370.41
4408.46	1400.06
4411.19	1387.92
4413.92	1426.7
4416.64	1381.75
4419.37	1387.76
4422.09	1361.64
4424.82	1380.41
4427.54	1384.58
4430.26	1379.32
4432.98	1382.38
4435.7	1381.17
4438.42	1373.56
4441.13	1328.15
4443.85	1382.34
4446.57	1366.21
4449.28	1344.75
4451.99	1328.45
4454.71	1345.7
4457.42	1341.83
4460.13	1355.93
4462.83	1337.49
4465.54	1301.18
4468.25	1318.6
4470.95	1340.34
4473.66	1340.1
4476.36	1391.65
4479.07	1368.43
4481.77	1343.08
4484.47	1332.43
4487.17	1352.41
4489.87	1333.02
4492.56	1308.87
4495.26	1336.95
4497.96	1344.95
4500.65	1308.19
4503.34	1301.26
4506.04	1308.17
4508.73	1271.58
4511.42	1286.99
4514.11	1258.94
4516.8	1283.96
4519.48	1273.07
4522.17	1268.56
4524.85	1292.73
4527.54	1258.4
4530.22	1284.8
4532.9	1286.76
4535.58	1283.39
4538.27	1274.82
4540.94	1269.39
4543.62	1282.2
4546.3	1269.34
4548.98	1277.93
4551.65	1237.49
4554.33	1259.31
4557	1282.71
4559.67	1290.26
4562.34	1262.44
4565.01	1263.38
4567.68	1259.57
4570.35	1237.96
4573.02	1255.31
4575.68	1209.34
4578.35	1231.03
4581.01	1260.2
4583.67	1237.14
4586.34	1229.28
4589	1217.98
4591.66	1231.69
4594.31	1230.54
4596.97	1225.75
4599.63	1224.54
4602.29	1226.74
4604.94	1216.88
4607.59	1197.19
4610.25	1211.44
4612.9	1200.41
4615.55	1161.9
4618.2	1198.29
4620.85	1191.75
4623.5	1201.65
4626.14	1213.67
4628.79	1198.13
4631.43	1223.27
4634.08	1218.43
4636.72	1162.71
4639.36	1225.3
4642	1168.56
4644.64	1191.91
4647.28	1167.84
4649.92	1182.96
4652.56	1174.22
4655.19	1175.14
4657.83	1164.97
4660.46	1186.34
4663.1	1135.12
4665.73	1156.01
4668.36	1128.97
4670.99	1178.03
4673.62	1158.77
4676.24	1155.17
4678.87	1131.31
4681.5	1153.48
4684.12	1147.59
4686.75	1145.04
4689.37	1150.46
4691.99	1163.65
4694.61	1110.28
4697.23	1121.19
4699.85	1128.74
4702.47	1139.55
4705.09	1169.57
4707.7	1122.65
4710.32	1143.56
4712.93	1099.94
4715.55	1129.8
4718.16	1082.67
4720.77	1157.74
4723.38	1106.06
4725.99	1122.5
4728.6	1091.29
4731.21	1135.01
4733.81	1115.15
4736.42	1108.78
4739.02	1088.79
4741.63	1123.23
4744.23	1112.2
4746.83	1141.86
4749.43	1121.5
4752.03	1107.98
4754.63	1120.56
4757.23	1108.2
4759.82	1125.57
4762.42	1115.61
4765.01	1111.54
4767.61	1083.86
4770.2	1074.05
4772.79	1106.47
4775.38	1110.4
4777.97	1109.74
4780.56	1059.94
4783.15	1121.03
4785.74	1073.49
4788.32	1046.54
4790.91	1057.42
4793.49	1047.68
4796.07	1051.81
4798.66	1084.7
4801.24	1077.53
4803.82	1048.64
4806.4	1023.29
4808.98	1076.15
4811.55	1058.87
4814.13	1066.97
4816.71	1047.51
4819.28	1051.11
4821.85	1048.96
4824.43	1039.85
4827	1042.26
4829.57	1043.69
4832.14	1063.74
4834.71	1025.68
4837.28	999.289
4839.84	1007.97
4842.41	1042.23
4844.97	1022.51
4847.54	1041.36
4850.1	1037.25
4852.66	1036.03
4855.22	1037.56
4857.78	1000.19
4860.34	1022.71
4862.9	1040.13
4865.46	1037.28
4868.01	1000.62
4870.57	1011
4873.12	982.085
4875.68	1012.46
4878.23	1006.03
4880.78	956.747
4883.33	1009.59
4885.88	991.166
4888.43	982.274
4890.98	1006.65
4893.53	965.523
4896.07	971.972
4898.62	976.044
4901.16	1001.54
4903.7	986.53
4906.25	1005.98
4908.79	1000.27
4911.33	949.02
4913.87	987.273
4916.41	929.989
4918.94	986.244
4921.48	966.038
4924.02	959.021
4926.55	971.077
4929.08	992.801
4931.62	965.749
4934.15	949.438
4936.68	973.742
4939.21	966.668
4941.74	936.873
4944.27	916.92
4946.79	1004.82
4949.32	934.576
4951.85	937.399
4954.37	937.872
4956.9	963.698
4959.42	972.815
4961.94	967.718
4964.46	930.322
4966.98	921.669
4969.5	923.704
4972.02	900.363
4974.53	915.638
4977.05	926.121
4979.57	935.44
4982.08	899.951
4984.59	925.083
4987.1	919.923
4989.62	939.048
4992.13	922.89
4994.64	911.661
4997.15	915.141
4999.65	934.512