File: Data/3-Raman/raw/bu19w-ff-ore1-fi04-v_150 (500nm)_532nm_edge_100%_x100_vis_h50um_15sx2_01.txt
#Acq. time (s)=	15
#Accumulations=	2
#Range (cm-¹)=	100...5000
#Windows=	1
#Auto scanning=	Off
#Autofocus=	Off
#Macrospot=	Off
#AutoExposure=	Off
#Spike filter=	Multiple accum.
#Delay time (s)=	2
#Binning=	1
#Readout mode=	Signal
#DeNoise=	Off
#ICS correction=	On
#Dark correction=	Off
#Inst. Process=	Off
#Detector Gain=	Best Dynamic
#Detector ADC=	50 kHz HS
#Detector temperature (°C)=	-60.09
#Instrument=	LabRAM HR Evol
#Detector=	SIN-EM FIVIS
#Objective=	x100_VIS
#Grating=	150 (500nm)
#ND Filter=	100%
#Laser=	532nm_Edge
#Hole=	49.98
#Temperature=	0
#Range=	Visible
#StageXY=	75x50mm Scan+
#StageZ=	Z motor
#X (µm)=	0
#Y (µm)=	0
#Z (µm)=	-4.5
#Full time(s)=	35
#Project=	21_05_14
#Sample=	BU19w
#Site=
#Title=	BU19w-FF-ore1-FI04-V_150 (500nm)_532nm_Edge_100%_x100_VIS_H50um_15sX2
#Remark=
#Date=	14.05.2021 18:39
#Acquired=	14.05.2021 18:39:22
102.699	2745.17
107.322	2466.14
111.942	2190.62
116.56	1972.84
121.173	1852.02
125.787	1715.11
130.398	1655.92
135.006	1513.22
139.613	1383.52
144.215	1325.42
148.817	1514.13
153.417	2209.29
158.014	2376.78
162.607	1604.99
167.2	1326.27
171.79	1330.7
176.379	1861.39
180.963	3532.24
185.547	3699.67
190.128	1910.09
194.705	1137.02
199.282	981.688
203.857	938.795
208.43	933.835
212.998	948.459
217.566	878.7
222.132	896.977
226.693	972.492
231.254	1025.77
235.813	997.194
240.368	1106.25
244.923	1073.68
249.475	1019.06
254.023	967.002
258.571	932.024
263.117	1103.71
267.658	1571.2
272.199	2621.34
276.738	2770.86
281.273	1837.27
285.807	1291.25
290.34	1348.67
294.868	1861.85
299.396	2218.69
303.919	1717.05
308.443	1152.2
312.964	1004.81
317.481	1066.28
321.998	1216.95
326.51	1290.94
331.023	1099.33
335.533	942.015
340.039	986.056
344.544	1008.41
349.046	964.456
353.547	916.342
358.045	838.814
362.542	898.226
367.036	917.41
371.527	909.025
376.017	980.98
380.503	1203.21
384.99	1282.92
389.471	1313.37
393.953	1316.61
398.43	1175.42
402.908	1025.92
407.381	1085.02
411.854	1204.71
416.323	1070.89
420.791	892.911
425.256	784.304
429.72	768.295
434.18	794.546
438.64	828.11
443.095	979.046
447.551	1451.05
452.003	1895.13
456.454	1454.99
460.901	1041.06
465.348	852.205
469.791	856.745
474.231	848.309
478.672	910.02
483.108	901.646
487.544	984.768
491.976	991.941
496.408	989.303
500.836	964.151
505.261	939.686
509.687	888.474
514.108	895.186
518.529	861.484
522.946	874.474
527.361	938.395
531.776	1005
536.187	998.808
540.595	1008.81
545.003	981.682
549.408	1002.12
553.812	997.777
558.212	1040.73
562.61	952.232
567.007	912.942
571.401	881.539
575.792	926.426
580.184	1140.43
584.571	1511.23
588.956	1367.61
593.341	1048.95
597.722	966.084
602.101	1064.95
606.48	1120.7
610.854	1042.69
615.227	900.67
619.597	823.518
623.967	821.225
628.334	833.669
632.698	874.615
637.06	950.374
641.422	871.855
645.779	835.143
650.135	806.163
654.491	803.415
658.842	826.37
663.192	823.218
667.539	898.008
671.884	952.88
676.23	958.974
680.571	881.895
684.91	814.056
689.247	798.243
693.583	760.114
697.916	759.922
702.247	746.558
706.576	736.875
710.902	764.669
715.229	745.995
719.551	738.68
723.872	767.076
728.19	751.772
732.506	783.382
736.82	758.629
741.134	793.144
745.444	831.849
749.752	843.313
754.058	924.343
758.362	978.959
762.664	1105.84
766.964	1457.58
771.264	1913.15
775.559	2119.76
779.853	1754.93
784.144	1327.71
788.434	1075.83
792.722	970.432
797.007	888.67
801.29	857.281
805.572	872.537
809.851	775.783
814.13	805.68
818.406	788.226
822.679	786.39
826.95	786.861
831.219	776.357
835.486	752.559
839.752	757.359
844.015	757.589
848.276	771.6
852.535	751.354
856.792	774.108
861.047	809.97
865.3	777.277
869.551	762.069
873.8	755.463
878.047	760.795
882.292	740.666
886.534	760.644
890.775	747.194
895.014	749.687
899.251	790.444
903.486	742.763
907.719	747.823
911.95	745.845
916.179	762.07
920.406	756.701
924.63	782.579
928.853	766.541
933.074	779.616
937.293	790.244
941.51	817.862
945.723	838.819
949.936	848.237
954.147	879.021
958.356	898.144
962.563	968.328
966.768	940.796
970.971	906.134
975.172	844.038
979.371	847.9
983.568	781.932
987.761	817.474
991.954	800.618
996.145	790.75
1000.33	801.235
1004.52	781.044
1008.71	810.959
1012.89	820.426
1017.07	867.21
1021.25	859.633
1025.43	892.134
1029.6	895.841
1033.77	966.979
1037.95	1091.39
1042.11	1413.64
1046.28	1902.27
1050.45	2138.34
1054.61	1755.58
1058.77	1386.89
1062.93	1182.8
1067.09	1073.26
1071.24	1068.73
1075.4	1147.9
1079.55	1286.24
1083.7	1543.83
1087.85	1617.24
1091.99	1582.53
1096.14	1498.53
1100.28	1660.98
1104.42	1970.95
1108.55	2023.61
1112.69	1814.35
1116.82	1627.35
1120.96	1597.62
1125.09	1680.52
1129.21	1700.24
1133.34	1565.87
1137.46	1312.48
1141.59	1189.38
1145.71	1200.64
1149.83	1225.66
1153.94	1344.92
1158.06	1259.75
1162.17	1127.58
1166.28	1003.51
1170.39	930.697
1174.5	898.973
1178.6	911.512
1182.7	892.116
1186.8	922.406
1190.9	921.568
1195	951.104
1199.1	907.786
1203.19	889.994
1207.28	882.441
1211.37	913.414
1215.46	938.193
1219.54	1004.27
1223.63	1025.96
1227.71	1023.95
1231.79	1103.33
1235.87	1219.92
1239.95	1221.01
1244.02	1217.3
1248.09	1255.39
1252.16	1064.11
1256.23	1049.72
1260.3	1068.47
1264.36	2125.29
1268.43	4369.03
1272.49	1974.6
1276.55	1083.03
1280.6	973.576
1284.66	970.275
1288.71	905.529
1292.76	936.176
1296.81	923.48
1300.86	922.706
1304.91	920.758
1308.95	902.718
1312.99	906.538
1317.03	908.031
1321.07	908.407
1325.11	909.282
1329.14	876.202
1333.18	906.02
1337.21	933.544
1341.24	895.904
1345.26	928.162
1349.29	1009.11
1353.31	1082.84
1357.33	1027.34
1361.35	1027.46
1365.37	1269.16
1369.39	4257.35
1373.4	5892.86
1377.41	1905.13
1381.43	1113.15
1385.43	1048.86
1389.44	1147.11
1393.45	1338.42
1397.45	1070.15
1401.45	955.154
1405.45	896.381
1409.45	894.826
1413.44	880.504
1417.44	848.376
1421.43	855.667
1425.42	833.043
1429.41	845.687
1433.39	844.732
1437.38	825.869
1441.36	805.063
1445.34	800.872
1449.32	845.987
1453.3	800.167
1457.27	818.389
1461.24	786.131
1465.22	799.005
1469.19	805.06
1473.15	824.868
1477.12	815.046
1481.09	806.18
1485.05	813.896
1489.01	810.849
1492.97	815.682
1496.93	818.58
1500.88	794.373
1504.83	822.883
1508.79	813.636
1512.74	804.401
1516.68	791.38
1520.63	793.965
1524.57	805.323
1528.52	824.518
1532.46	818.574
1536.4	834.924
1540.33	820.287
1544.27	794.02
1548.2	815.237
1552.14	817.993
1556.07	810.931
1559.99	803.771
1563.92	828.457
1567.84	850.139
1571.77	817.664
1575.69	819.004
1579.61	802.945
1583.52	855.299
1587.44	824.703
1591.35	823.016
1595.27	832.855
1599.18	864.807
1603.09	835.402
1606.99	850.238
1610.9	843.988
1614.8	832.102
1618.7	840.374
1622.6	844.821
1626.5	866.66
1630.39	843.69
1634.29	853.41
1638.18	826.777
1642.07	837.748
1645.96	876.628
1649.85	839.838
1653.73	841.371
1657.62	843.797
1661.5	854.784
1665.38	864.666
1669.26	837.85
1673.13	852.186
1677.01	833.619
1680.88	807.956
1684.75	830.22
1688.62	843.693
1692.49	824.435
1696.35	824.223
1700.22	841.974
1704.08	828.054
1707.94	815.913
1711.8	799.004
1715.66	856.03
1719.51	813.677
1723.37	824.25
1727.22	808.326
1731.07	825.286
1734.92	820.641
1738.76	805.615
1742.61	799.965
1746.45	829.051
1750.29	842.694
1754.13	833.479
1757.97	832.699
1761.81	833.237
1765.64	829.72
1769.47	809.997
1773.31	817.379
1777.14	816.527
1780.96	818.704
1784.79	816.304
1788.61	836.425
1792.43	812.564
1796.25	808.333
1800.07	818.824
1803.89	831.847
1807.71	836.384
1811.52	808.72
1815.33	831.706
1819.14	841.192
1822.95	842.963
1826.76	828.502
1830.56	853.411
1834.37	847.032
1838.17	856.526
1841.97	826.362
1845.77	842.226
1849.56	831.652
1853.36	831.068
1857.15	844.265
1860.94	850.708
1864.73	835.774
1868.52	847.892
1872.31	849.921
1876.09	828.043
1879.87	828.593
1883.66	833.015
1887.43	834.294
1891.21	827.77
1894.99	825.788
1898.76	809.304
1902.53	840.942
1906.31	842.316
1910.08	835.613
1913.84	839.222
1917.61	850.56
1921.37	819.657
1925.14	843.445
1928.9	824.694
1932.66	831.952
1936.41	828.011
1940.17	843.659
1943.92	850.173
1947.68	835.327
1951.43	812.617
1955.18	836.462
1958.92	836.405
1962.67	830.639
1966.41	836.048
1970.16	827.887
1973.9	842.074
1977.64	835.463
1981.37	839.965
1985.11	842.435
1988.84	853.219
1992.57	829.333
1996.31	836.972
2000.03	838.907
2003.76	828.009
2007.49	831.612
2011.21	824.116
2014.93	840.743
2018.65	844.13
2022.37	869.87
2026.09	819.124
2029.81	848.809
2033.52	837.191
2037.23	819.838
2040.94	842.817
2044.65	846.445
2048.36	831.943
2052.07	837.696
2055.77	832.603
2059.47	833.686
2063.17	841.49
2066.87	844.812
2070.57	854.63
2074.27	843.247
2077.96	852.284
2081.65	876.169
2085.34	836.434
2089.03	854.059
2092.72	853.546
2096.41	855.993
2100.09	884.98
2103.77	849.651
2107.46	825.334
2111.14	836.283
2114.81	830.469
2118.49	844.843
2122.16	831.025
2125.84	833.855
2129.51	826.34
2133.18	836.391
2136.85	849.071
2140.51	879.992
2144.18	834.332
2147.84	839.338
2151.5	855.343
2155.16	863.1
2158.82	856.258
2162.48	852.326
2166.13	850.359
2169.79	884.177
2173.44	826.34
2177.09	869.649
2180.74	849.317
2184.38	852.652
2188.03	844.567
2191.67	889.556
2195.32	838.387
2198.96	836.433
2202.6	869.278
2206.23	850.262
2209.87	847.801
2213.5	877.486
2217.14	853.125
2220.77	825.964
2224.4	833.71
2228.03	864.474
2231.65	831.695
2235.28	846.936
2238.9	817.699
2242.52	841.257
2246.14	851.863
2249.76	845.837
2253.38	825.884
2256.99	842.328
2260.6	851.259
2264.21	826.441
2267.82	830.844
2271.44	816.435
2275.04	821.433
2278.65	857.258
2282.25	812.462
2285.85	832.034
2289.45	850.536
2293.05	827.4
2296.65	832.691
2300.25	837.926
2303.84	850.549
2307.43	865.878
2311.02	918.062
2314.62	1207.99
2318.2	945.146
2321.79	856.393
2325.38	826.058
2328.96	861.949
2332.54	857.955
2336.12	835.986
2339.7	864.754
2343.28	849.211
2346.85	830.814
2350.43	830.219
2354	845.448
2357.57	840.063
2361.14	857.911
2364.71	829.31
2368.27	833.382
2371.84	854.185
2375.4	855.437
2378.96	838.358
2382.52	818.665
2386.08	814.76
2389.64	833.978
2393.19	851.531
2396.75	806.104
2400.3	827.052
2403.85	847.394
2407.4	797.299
2410.95	806.211
2414.49	803.34
2418.04	808.918
2421.58	821.099
2425.12	825.234
2428.66	807.382
2432.2	817.409
2435.74	820.188
2439.27	796.979
2442.81	792.356
2446.34	850.446
2449.87	837.768
2453.4	815.39
2456.93	821.375
2460.45	805.322
2463.98	815.344
2467.5	834.719
2471.02	809.57
2474.54	842.791
2478.06	823.482
2481.58	798.392
2485.09	821.825
2488.61	822.635
2492.12	835.739
2495.63	818.594
2499.14	822.22
2502.65	818.975
2506.15	827.755
2509.66	808.502
2513.16	822.941
2516.66	820.808
2520.16	803.472
2523.66	806.971
2527.16	819.174
2530.66	820.384
2534.15	807.989
2537.64	830.823
2541.13	834.626
2544.62	813.021
2548.11	845.058
2551.6	822.703
2555.08	771.131
2558.57	810.317
2562.05	812.775
2565.53	821.11
2569.01	827.853
2572.49	806.704
2575.96	817.538
2579.44	820.975
2582.91	824.464
2586.38	817.435
2589.85	827.989
2593.32	813.534
2596.79	787.79
2600.25	787.814
2603.72	795.148
2607.18	807.678
2610.64	816.485
2614.1	805.482
2617.56	808.588
2621.02	814.413
2624.47	791.176
2627.92	805.274
2631.38	810.551
2634.83	791.58
2638.28	819.439
2641.72	783.894
2645.17	840.114
2648.61	810.163
2652.06	788.67
2655.5	826.911
2658.94	805.178
2662.38	814.639
2665.82	788.208
2669.25	807.918
2672.69	812.63
2676.12	820.237
2679.55	816.76
2682.98	796.692
2686.41	780.902
2689.84	793.588
2693.26	806.026
2696.69	784.171
2700.11	823.871
2703.53	785.224
2706.95	780.695
2710.37	810.798
2713.79	787.099
2717.2	798.003
2720.62	792.266
2724.03	770.705
2727.44	800.589
2730.85	811.775
2734.26	782.696
2737.66	792.01
2741.07	788.999
2744.47	818.694
2747.87	779.816
2751.28	783.197
2754.67	797.707
2758.07	780.322
2761.47	780.59
2764.86	770.382
2768.26	770.372
2771.65	811.779
2775.04	793.683
2778.43	784.887
2781.82	807.084
2785.2	799.117
2788.59	793.969
2791.97	793.451
2795.35	792.075
2798.73	781.135
2802.11	780.53
2805.49	778.049
2808.87	775.524
2812.24	796.351
2815.62	783.427
2818.99	785.571
2822.36	785.049
2825.73	742.622
2829.1	777.667
2832.46	778.366
2835.83	766.15
2839.19	768.986
2842.55	776.641
2845.91	770.553
2849.27	804.015
2852.63	793.457
2855.99	783.905
2859.34	783.822
2862.69	779.083
2866.05	779.064
2869.4	780.859
2872.75	781.691
2876.09	792.849
2879.44	774.818
2882.78	783.089
2886.13	764.889
2889.47	776.94
2892.81	743.406
2896.15	747.559
2899.49	790.382
2902.82	776.336
2906.16	757.498
2909.49	801.025
2912.82	779.257
2916.16	778.158
2919.49	808.214
2922.81	795.68
2926.14	777.326
2929.46	784.457
2932.79	768.741
2936.11	764.366
2939.43	782.614
2942.75	804.607
2946.07	780.516
2949.39	763.015
2952.7	757.723
2956.02	795.753
2959.33	794.454
2962.64	768.742
2965.95	770.422
2969.26	780.856
2972.57	748.941
2975.87	783.929
2979.17	783.104
2982.48	785.136
2985.78	797.557
2989.08	802.495
2992.38	783.045
2995.68	785.253
2998.97	785.595
3002.27	824.46
3005.56	782.507
3008.85	791.396
3012.14	788.088
3015.43	795.122
3018.72	779.512
3022	774.259
3025.29	795.456
3028.57	772.272
3031.85	788.725
3035.14	799.478
3038.41	810.25
3041.69	787.909
3044.97	797.774
3048.24	808.564
3051.52	808.984
3054.79	819.817
3058.06	815.38
3061.33	825.92
3064.6	809.02
3067.87	802.441
3071.13	831.273
3074.4	797.936
3077.66	840.459
3080.92	794.308
3084.18	848.863
3087.44	825.771
3090.7	831.342
3093.95	855.093
3097.21	837.125
3100.46	846.734
3103.71	829.028
3106.96	867.5
3110.21	853.384
3113.46	864.946
3116.71	843.223
3119.95	861.502
3123.2	900.737
3126.44	882.79
3129.68	870.56
3132.92	873.563
3136.16	894.635
3139.4	885.181
3142.63	890.022
3145.87	915.888
3149.1	963.733
3152.33	942.885
3155.56	942.078
3158.79	932.663
3162.02	950.92
3165.25	942.395
3168.47	952.879
3171.69	962.364
3174.92	990.855
3178.14	1014.53
3181.36	982.9
3184.58	1015.09
3187.79	1014.79
3191.01	1001.14
3194.22	1021.79
3197.43	1007.16
3200.65	997.329
3203.86	1026.56
3207.07	1026.32
3210.27	1031.86
3213.48	1032.71
3216.69	1042.14
3219.89	1023.05
3223.09	1061.14
3226.29	1050.75
3229.49	1094.67
3232.69	1045.28
3235.89	1088.37
3239.08	1069.71
3242.28	1079.67
3245.47	1081.07
3248.66	1094.95
3251.85	1067.88
3255.04	1071.33
3258.23	1106.17
3261.42	1087.39
3264.6	1111.44
3267.79	1093.32
3270.97	1112.38
3274.15	1110.42
3277.33	1104.46
3280.51	1156.49
3283.68	1112.1
3286.86	1131.54
3290.04	1136.75
3293.21	1160.98
3296.38	1146.11
3299.55	1150.58
3302.72	1187.2
3305.89	1131.38
3309.06	1186.66
3312.22	1177.17
3315.39	1182.85
3318.55	1203.64
3321.71	1188.39
3324.87	1200.63
3328.03	1162.74
3331.19	1217.58
3334.34	1220.51
3337.5	1215.99
3340.65	1244.49
3343.81	1228.89
3346.96	1243.82
3350.11	1236.15
3353.25	1257.82
3356.4	1284.28
3359.55	1271.3
3362.69	1316.83
3365.84	1301.14
3368.98	1310.01
3372.12	1311.49
3375.26	1317.76
3378.4	1326.02
3381.53	1302.08
3384.67	1348.19
3387.8	1403.85
3390.94	1390.52
3394.07	1382.31
3397.2	1466.71
3400.33	1528.73
3403.46	1647.06
3406.58	1827.52
3409.71	2264.45
3412.83	3244.61
3415.96	5844.6
3419.08	7774.62
3422.2	5624.61
3425.32	3117.51
3428.44	2144.13
3431.55	1755.53
3434.67	1544.05
3437.78	1538.94
3440.89	1380.3
3444	1388.35
3447.12	1343.93
3450.22	1355.56
3453.33	1310.97
3456.44	1354.74
3459.54	1330.89
3462.65	1326.02
3465.75	1327.69
3468.85	1301.45
3471.95	1299.33
3475.05	1273.66
3478.15	1267.03
3481.24	1343.6
3484.34	1321.92
3487.43	1327.75
3490.53	1377.42
3493.62	1429.95
3496.71	1493.61
3499.79	1578.1
3502.88	1522.71
3505.97	1498.56
3509.05	1380.74
3512.14	1287.4
3515.22	1235.73
3518.3	1194.78
3521.38	1155.92
3524.46	1110
3527.54	1095.45
3530.61	1110.01
3533.69	1051.27
3536.76	1032.95
3539.83	1041.78
3542.9	1001.05
3545.97	997.086
3549.04	973.124
3552.11	974.477
3555.18	990.178
3558.24	950.146
3561.3	942.057
3564.37	949.044
3567.43	911.526
3570.49	918.394
3573.55	911.882
3576.61	921.454
3579.66	879.734
3582.72	884.405
3585.77	847.325
3588.82	841.464
3591.87	862.101
3594.92	833.386
3597.97	864.349
3601.02	816.634
3604.07	835.134
3607.11	808.193
3610.16	841.744
3613.2	814.757
3616.24	783.099
3619.28	785.481
3622.32	762.425
3625.36	759.233
3628.39	751.317
3631.43	746.181
3634.46	731.761
3637.5	725.003
3640.53	749.375
3643.56	716.538
3646.59	701.463
3649.62	709.063
3652.64	691.435
3655.67	671.923
3658.69	662.193
3661.72	667.428
3664.74	678.034
3667.76	635.884
3670.78	640.923
3673.79	655.439
3676.81	654.907
3679.83	608.999
3682.84	625.433
3685.86	607.845
3688.87	611.079
3691.88	600.129
3694.89	620.339
3697.9	611.245
3700.91	605.023
3703.91	601.641
3706.92	615.304
3709.92	599.458
3712.92	586.372
3715.92	591.374
3718.92	560.166
3721.92	600.292
3724.92	614.668
3727.92	567.102
3730.91	605.189
3733.91	586.072
3736.9	591.66
3739.89	589.561
3742.88	575.044
3745.87	590.909
3748.86	576.297
3751.85	586.373
3754.83	579.366
3757.82	567.62
3760.8	586.172
3763.78	603.746
3766.76	577.797
3769.74	552.878
3772.72	593.265
3775.7	552.379
3778.67	586.195
3781.65	587.891
3784.62	581.118
3787.6	568.714
3790.57	557.338
3793.54	564.9
3796.51	567.775
3799.47	568.833
3802.44	550.103
3805.41	551.217
3808.37	528.739
3811.33	554.477
3814.3	555.659
3817.26	567.273
3820.22	544.83
3823.18	569.762
3826.13	553.985
3829.09	565.683
3832.04	534.735
3835	542.717
3837.95	545.967
3840.9	571.09
3843.85	542.96
3846.8	523.379
3849.75	554.319
3852.69	541.442
3855.64	530.459
3858.58	559.61
3861.53	540.953
3864.47	532.793
3867.41	547.578
3870.35	528.803
3873.29	559.879
3876.22	529.494
3879.16	523.033
3882.1	528.034
3885.03	526.261
3887.96	528.307
3890.89	526.487
3893.82	561.154
3896.75	561.127
3899.68	535.122
3902.61	516.738
3905.53	519.558
3908.46	532.924
3911.38	535.667
3914.3	547.945
3917.23	538.233
3920.15	555.335
3923.06	505.182
3925.98	531.749
3928.9	517.019
3931.81	533.054
3934.73	518.544
3937.64	519.484
3940.55	517.52
3943.46	518.436
3946.37	506.956
3949.28	520.413
3952.19	523.36
3955.09	520.607
3958	538.961
3960.9	534.349
3963.8	509.627
3966.71	521.365
3969.61	508.182
3972.51	520.909
3975.4	528.815
3978.3	530.921
3981.2	510.908
3984.09	501.433
3986.99	521.766
3989.88	533.358
3992.77	498.864
3995.66	526.91
3998.55	516.49
4001.43	507.995
4004.32	489.886
4007.21	518.037
4010.09	527.884
4012.98	502.054
4015.86	523.486
4018.74	501.493
4021.62	515.212
4024.5	518.328
4027.37	499.216
4030.25	482.037
4033.13	504.508
4036	501.859
4038.87	490.498
4041.75	489.703
4044.62	482.115
4047.49	501.698
4050.35	481.558
4053.22	489.578
4056.09	485.969
4058.95	485.242
4061.82	482.567
4064.68	488.641
4067.54	522.928
4070.4	499.814
4073.26	477.647
4076.12	482.728
4078.98	494.635
4081.83	470.476
4084.69	484.329
4087.54	489.394
4090.4	480.819
4093.25	482.978
4096.1	482.195
4098.95	467.743
4101.8	473.793
4104.64	496.439
4107.49	449.598
4110.33	476.117
4113.18	483.986
4116.02	485.925
4118.86	469.241
4121.7	467.281
4124.54	464.378
4127.38	462.522
4130.22	488.195
4133.05	466.964
4135.89	479.763
4138.72	468.462
4141.56	466.18
4144.39	469.256
4147.22	470.413
4150.05	470.546
4152.88	484.229
4155.7	485.964
4158.53	458.354
4161.36	465.143
4164.18	473.888
4167	462.1
4169.82	476.748
4172.65	450.339
4175.46	464.031
4178.28	471.876
4181.1	458.235
4183.92	451.457
4186.73	454.481
4189.55	447.763
4192.36	453.833
4195.17	471.72
4197.98	463.182
4200.79	493.863
4203.6	480.42
4206.41	483.647
4209.21	469.19
4212.02	466.5
4214.83	455.11
4217.63	452.689
4220.43	461.041
4223.23	444.684
4226.03	447.085
4228.83	449.546
4231.63	475.81
4234.42	458.56
4237.22	441.28
4240.01	438.877
4242.81	444.451
4245.6	448.044
4248.39	435.635
4251.18	463.14
4253.97	443.663
4256.76	457.167
4259.55	440.636
4262.33	429.106
4265.12	434.657
4267.9	440.232
4270.68	437.746
4273.47	458.393
4276.25	433.571
4279.03	442.004
4281.8	430.191
4284.58	439.553
4287.36	428.631
4290.13	447.031
4292.91	447.245
4295.68	414.064
4298.45	416.328
4301.22	439.879
4303.99	440.104
4306.76	445.419
4309.53	423.334
4312.3	434.761
4315.06	432.909
4317.83	415.758
4320.59	421.979
4323.35	425.12
4326.11	427.245
4328.87	424.259
4331.63	430.431
4334.39	415.199
4337.15	411.197
4339.9	409.275
4342.66	417.568
4345.41	418.772
4348.17	438.365
4350.92	404.942
4353.67	432.82
4356.42	407.525
4359.17	418.003
4361.91	418.266
4364.66	397.014
4367.41	430.075
4370.15	414.94
4372.89	406.928
4375.63	408.13
4378.38	408.282
4381.12	409.476
4383.86	394.29
4386.59	396.71
4389.33	396.15
4392.07	401.987
4394.8	417.11
4397.53	410.358
4400.27	410.835
4403	412.341
4405.73	411.798
4408.46	382.117
4411.19	391.866
4413.92	387.015
4416.64	409.157
4419.37	403.134
4422.09	403.43
4424.82	404.775
4427.54	392.534
4430.26	385.499
4432.98	401.47
4435.7	382.872
4438.42	395.665
4441.13	388.535
4443.85	379.292
4446.57	391.022
4449.28	389.09
4451.99	387.138
4454.71	391.466
4457.42	394.719
4460.13	389.587
4462.83	384.471
4465.54	376.199
4468.25	385.841
4470.95	375.505
4473.66	375.733
4476.36	393.922
4479.07	386.832
4481.77	389.246
4484.47	370.501
4487.17	385.571
4489.87	388.951
4492.56	392.185
4495.26	363.758
4497.96	366.034
4500.65	404.273
4503.34	364.14
4506.04	387.625
4508.73	371.872
4511.42	394.324
4514.11	367.964
4516.8	370.262
4519.48	366.239
4522.17	368.602
4524.85	369.884
4527.54	386.095
4530.22	358.635
4532.9	397.281
4535.58	371.942
4538.27	353.019
4540.94	355.428
4543.62	350.372
4546.3	352.803
4548.98	374.537
4551.65	354.564
4554.33	365.709
4557	366.259
4559.67	341.015
4562.34	363.243
4565.01	359.805
4567.68	341.054
4570.35	348.974
4573.02	346.797
4575.68	344.827
4578.35	353.818
4581.01	343.492
4583.67	342.651
4586.34	372.328
4589	349.631
4591.66	341.076
4594.31	354.469
4596.97	355.758
4599.63	346.196
4602.29	347.604
4604.94	338.053
4607.59	355.921
4610.25	337.579
4612.9	349.96
4615.55	334.878
4618.2	347.322
4620.85	353.172
4623.5	335.844
4626.14	339.43
4628.79	347.451
4631.43	334.423
4634.08	327.976
4636.72	345.879
4639.36	351.59
4642	336.328
4644.64	337.774
4647.28	339.3
4649.92	342.041
4652.56	332.705
4655.19	333.765
4657.83	345.198
4660.46	335.523
4663.1	350.427
4665.73	332.764
4668.36	330.798
4670.99	316.494
4673.62	338.044
4676.24	323.717
4678.87	313.847
4681.5	325.312
4684.12	332.3
4686.75	323.536
4689.37	327.175
4691.99	328.527
4694.61	333.253
4697.23	321.065
4699.85	317.901
4702.47	323.73
4705.09	318.255
4707.7	347.823
4710.32	319.699
4712.93	318.716
4715.55	324.499
4718.16	332.564
4720.77	315.646
4723.38	305.57
4725.99	320.471
4728.6	329.715
4731.21	308.31
4733.81	335.737
4736.42	315.415
4739.02	306.453
4741.63	314.504
4744.23	314.602
4746.83	320.313
4749.43	328.315
4752.03	312.418
4754.63	312.436
4757.23	322.727
4759.82	292.066
4762.42	312.644
4765.01	309.362
4767.61	306.173
4770.2	316.568
4772.79	306.433
4775.38	311.141
4777.97	303.28
4780.56	321.697
4783.15	322.988
4785.74	297.971
4788.32	292.39
4790.91	297.131
4793.49	295
4796.07	298.634
4798.66	304.589
4801.24	311.721
4803.82	298.215
4806.4	291.63
4808.98	308.046
4811.55	299.157
4814.13	296.029
4816.71	304.488
4819.28	297.922
4821.85	290.187
4824.43	298.674
4827	290.903
4829.57	291.303
4832.14	285.876
4834.71	278.14
4837.28	294.939
4839.84	289.578
4842.41	285.31
4844.97	293.905
4847.54	293.086
4850.1	287.374
4852.66	300.289
4855.22	274.838
4857.78	281.138
4860.34	292.12
4862.9	299.459
4865.46	292.566
4868.01	283.439
4870.57	289.618
4873.12	275.6
4875.68	272.243
4878.23	289.048
4880.78	278.532
4883.33	292.955
4885.88	274.102
4888.43	302.833
4890.98	279.196
4893.53	279.353
4896.07	272.343
4898.62	284.406
4901.16	283.342
4903.7	283.486
4906.25	275.227
4908.79	282.465
4911.33	284.885
4913.87	288.477
4916.41	278.937
4918.94	286.136
4921.48	269.439
4924.02	277.847
4926.55	268.316
4929.08	269.568
4931.62	260.124
4934.15	260.243
4936.68	274.707
4939.21	261.569
4941.74	287.946
4944.27	260.523
4946.79	267.833
4949.32	279.953
4951.85	268.085
4954.37	262.22
4956.9	250.381
4959.42	283.012
4961.94	258.018
4964.46	269.161
4966.98	277.887
4969.5	278.137
4972.02	265.097
4974.53	259.28
4977.05	263.137
4979.57	269.431
4982.08	267.258
4984.59	277.222
4987.1	273.852
4989.62	254.667
4992.13	278.023
4994.64	271.001
4997.15	265.214
4999.65	265.521