File: Data/3-Raman/raw/bu19w-ff2-fi04-v_150 (500nm)_532nm_edge_100%_x100_vis_h50um_15sx2_01.txt
#Acq. time (s)=	15
#Accumulations=	2
#Range (cm-¹)=	100...5000
#Windows=	1
#Auto scanning=	Off
#Autofocus=	Off
#Macrospot=	Off
#AutoExposure=	Off
#Spike filter=	Multiple accum.
#Delay time (s)=	2
#Binning=	1
#Readout mode=	Signal
#DeNoise=	Off
#ICS correction=	On
#Dark correction=	Off
#Inst. Process=	Off
#Detector Gain=	Best Dynamic
#Detector ADC=	50 kHz HS
#Detector temperature (°C)=	-60.09
#Instrument=	LabRAM HR Evol
#Detector=	SIN-EM FIVIS
#Objective=	x100_VIS
#Grating=	150 (500nm)
#ND Filter=	100%
#Laser=	532nm_Edge
#Hole=	49.98
#Temperature=	0
#Range=	Visible
#StageXY=	75x50mm Scan+
#StageZ=	Z motor
#X (µm)=	0
#Y (µm)=	0
#Z (µm)=	-18.2
#Full time(s)=	38
#Project=	21_05_14
#Sample=	BU19w
#Site=
#Title=	BU19w-FF2-FI04-V_150 (500nm)_532nm_Edge_100%_x100_VIS_H50um_15sX2
#Remark=
#Date=	14.05.2021 17:49
#Acquired=	14.05.2021 17:49:54
102.699	1569.83
107.322	1413.94
111.942	1330.53
116.56	1269.54
121.173	1270.36
125.787	1221.02
130.398	1190.9
135.006	1172.02
139.613	1064.86
144.215	1093.15
148.817	1264.94
153.417	1843.84
158.014	1947.87
162.607	1273.09
167.2	1012.91
171.79	955.042
176.379	1033.16
180.963	1622.69
185.547	1809.77
190.128	1380.43
194.705	1003.68
199.282	843.456
203.857	822.592
208.43	784.617
212.998	769.896
217.566	760.073
222.132	835.833
226.693	1087.41
231.254	1161.39
235.813	1286.64
240.368	1821.38
244.923	1672.41
249.475	1164.03
254.023	920.752
258.571	863.931
263.117	1022.31
267.658	1653.73
272.199	3116.14
276.738	3390.11
281.273	2098.96
285.807	1287.62
290.34	1034.4
294.868	1100.1
299.396	1167.44
303.919	1042.17
308.443	890.198
312.964	882.019
317.481	1065.07
321.998	1429.6
326.51	1556.03
331.023	1217.53
335.533	1046.75
340.039	1327.36
344.544	1732.02
349.046	1638.56
353.547	1235.95
358.045	975.129
362.542	1061.21
367.036	1084.76
371.527	904.237
376.017	789.716
380.503	832.807
384.99	928.594
389.471	1031.28
393.953	935.631
398.43	772.247
402.908	723.579
407.381	856.467
411.854	1135.91
416.323	1070.89
420.791	752.453
425.256	624.026
429.72	597.824
434.18	594.882
438.64	579.266
443.095	620.043
447.551	634.942
452.003	740.553
456.454	694.893
460.901	665.171
465.348	636.948
469.791	647.697
474.231	699.4
478.672	782.605
483.108	842.197
487.544	1019.71
491.976	1045.4
496.408	1049.58
500.836	897.06
505.261	793.962
509.687	679.217
514.108	640.905
518.529	601.479
522.946	607.45
527.361	583.389
531.776	605.777
536.187	620.13
540.595	621.744
545.003	643.051
549.408	673.693
553.812	670.409
558.212	675.461
562.61	649.276
567.007	619.599
571.401	633.444
575.792	718.394
580.184	977.431
584.571	1366.76
588.956	1255.21
593.341	873.272
597.722	803.841
602.101	951.719
606.48	1116.17
610.854	985.925
615.227	760.705
619.597	637.728
623.967	624.907
628.334	647.393
632.698	671.243
637.06	720.638
641.422	669.47
645.779	678.518
650.135	737.602
654.491	858.154
658.842	1024.29
663.192	1079.66
667.539	1153.77
671.884	1230.45
676.23	1163.71
680.571	944.687
684.91	719.073
689.247	613.305
693.583	562.406
697.916	549.671
702.247	518.738
706.576	518.666
710.902	520.065
715.229	520.004
719.551	500.142
723.872	519.851
728.19	505.512
732.506	517.541
736.82	515.37
741.134	519.918
745.444	539.318
749.752	546.205
754.058	592.008
758.362	625.119
762.664	732.194
766.964	891.521
771.264	1151.01
775.559	1290.94
779.853	1110.73
784.144	838.178
788.434	723.662
792.722	621.054
797.007	584.926
801.29	553.741
805.572	561.349
809.851	539.365
814.13	513.105
818.406	503.298
822.679	529.947
826.95	509.34
831.219	490.94
835.486	494.539
839.752	504.722
844.015	509.289
848.276	503.553
852.535	509.907
856.792	540.498
861.047	535.759
865.3	523.135
869.551	506.031
873.8	497.607
878.047	490.217
882.292	487.036
886.534	500.007
890.775	496.137
895.014	502.501
899.251	496.401
903.486	500.782
907.719	492.231
911.95	501.377
916.179	511.467
920.406	546.357
924.63	556.68
928.853	554.896
933.074	585.383
937.293	662.734
941.51	775.07
945.723	864.448
949.936	826.911
954.147	739.527
958.356	672.677
962.563	689.993
966.768	660.626
970.971	588.006
975.172	592.893
979.371	549.202
983.568	537.346
987.761	547.628
991.954	532.863
996.145	524.872
1000.33	522.314
1004.52	545.297
1008.71	545.071
1012.89	545.708
1017.07	556.997
1021.25	576.824
1025.43	609.171
1029.6	647.976
1033.77	694.666
1037.95	809.878
1042.11	1094.17
1046.28	1582.3
1050.45	1829.6
1054.61	1478.24
1058.77	1090.19
1062.93	885.912
1067.09	820.293
1071.24	821.818
1075.4	938.24
1079.55	1220.76
1083.7	1632.9
1087.85	1845.4
1091.99	1670.02
1096.14	1416.39
1100.28	1415.14
1104.42	1711.36
1108.55	1811.3
1112.69	1603.42
1116.82	1421.58
1120.96	1456.88
1125.09	1561.03
1129.21	1604.05
1133.34	1420.3
1137.46	1172.86
1141.59	999.12
1145.71	1016.24
1149.83	1145.22
1153.94	1334.6
1158.06	1233.95
1162.17	1109
1166.28	1039.62
1170.39	900.791
1174.5	749.573
1178.6	655.198
1182.7	604.171
1186.8	638.036
1190.9	630.601
1195	608.686
1199.1	601.962
1203.19	585.027
1207.28	591.504
1211.37	633.375
1215.46	727.465
1219.54	813.17
1223.63	752.035
1227.71	672.455
1231.79	730.389
1235.87	799.121
1239.95	780.55
1244.02	681.267
1248.09	635.43
1252.16	606.71
1256.23	581.069
1260.3	581.483
1264.36	632.032
1268.43	1008.47
1272.49	726.744
1276.55	559.842
1280.6	533.281
1284.66	541.724
1288.71	541.103
1292.76	524.238
1296.81	529.502
1300.86	525.605
1304.91	522.62
1308.95	534.776
1312.99	513.487
1317.03	520.242
1321.07	525.92
1325.11	547.379
1329.14	536.768
1333.18	526.966
1337.21	533.096
1341.24	523.152
1345.26	547.122
1349.29	520.238
1353.31	565.026
1357.33	578.9
1361.35	578.843
1365.37	657.076
1369.39	995.834
1373.4	1274.84
1377.41	727.662
1381.43	549.929
1385.43	550.764
1389.44	542.799
1393.45	569.528
1397.45	561.917
1401.45	505.901
1405.45	534.675
1409.45	513.231
1413.44	524.356
1417.44	494.022
1421.43	495.23
1425.42	498.246
1429.41	519.853
1433.39	522.835
1437.38	509.936
1441.36	523.711
1445.34	515.657
1449.32	516.472
1453.3	514.217
1457.27	496.158
1461.24	497.669
1465.22	501.037
1469.19	503.469
1473.15	509.838
1477.12	505.299
1481.09	490.952
1485.05	498.114
1489.01	501.35
1492.97	491.945
1496.93	503.03
1500.88	512.232
1504.83	507.923
1508.79	501.783
1512.74	521.866
1516.68	507.046
1520.63	514.598
1524.57	495.024
1528.52	508.477
1532.46	501.613
1536.4	519.95
1540.33	521.825
1544.27	503.348
1548.2	517.818
1552.14	520.629
1556.07	520.448
1559.99	524.072
1563.92	520.869
1567.84	515.69
1571.77	524.986
1575.69	517.85
1579.61	514.56
1583.52	525.708
1587.44	516.583
1591.35	544.027
1595.27	539.698
1599.18	530.6
1603.09	559.014
1606.99	544.287
1610.9	535.341
1614.8	563.836
1618.7	553.067
1622.6	549.014
1626.5	546.029
1630.39	541.244
1634.29	557.612
1638.18	529.003
1642.07	554.188
1645.96	543.998
1649.85	562.61
1653.73	521.717
1657.62	536.438
1661.5	531.898
1665.38	548.407
1669.26	536.935
1673.13	528.23
1677.01	547.258
1680.88	515.114
1684.75	529.02
1688.62	525.572
1692.49	525.859
1696.35	528.936
1700.22	533.807
1704.08	524.259
1707.94	524.142
1711.8	545.788
1715.66	519.107
1719.51	523.719
1723.37	513.212
1727.22	519.605
1731.07	523.135
1734.92	547.25
1738.76	543.148
1742.61	517.624
1746.45	515.658
1750.29	537.188
1754.13	515.3
1757.97	517.247
1761.81	518.51
1765.64	499.132
1769.47	499.568
1773.31	533.599
1777.14	524.012
1780.96	527.609
1784.79	506.977
1788.61	511.591
1792.43	511.545
1796.25	523.702
1800.07	527.227
1803.89	539.971
1807.71	527.275
1811.52	527.672
1815.33	526.008
1819.14	523.209
1822.95	510.872
1826.76	529.543
1830.56	523.545
1834.37	510.856
1838.17	511.282
1841.97	520.059
1845.77	517.535
1849.56	542.097
1853.36	532.688
1857.15	532.507
1860.94	528.491
1864.73	535.657
1868.52	547.491
1872.31	535.307
1876.09	524.166
1879.87	520.58
1883.66	519.886
1887.43	526.898
1891.21	539.73
1894.99	528.596
1898.76	510.243
1902.53	529.789
1906.31	536.522
1910.08	518.513
1913.84	528.263
1917.61	522.533
1921.37	536.41
1925.14	533.703
1928.9	544.066
1932.66	537.72
1936.41	546.254
1940.17	536.109
1943.92	510.104
1947.68	511.702
1951.43	528.13
1955.18	549.031
1958.92	534.905
1962.67	538.577
1966.41	533.738
1970.16	545.514
1973.9	530.924
1977.64	543.402
1981.37	559.509
1985.11	561.467
1988.84	550.328
1992.57	545.602
1996.31	537.092
2000.03	549.852
2003.76	521.956
2007.49	541.032
2011.21	561.834
2014.93	531.261
2018.65	536.007
2022.37	551.971
2026.09	549.898
2029.81	542.231
2033.52	533.257
2037.23	536.946
2040.94	546.16
2044.65	554.378
2048.36	549.897
2052.07	547.319
2055.77	538.42
2059.47	550.132
2063.17	538.168
2066.87	538.194
2070.57	552.996
2074.27	555.85
2077.96	562.48
2081.65	532.009
2085.34	556.848
2089.03	551.26
2092.72	530.155
2096.41	537.03
2100.09	541.777
2103.77	565.039
2107.46	558.438
2111.14	544.351
2114.81	551.632
2118.49	542.019
2122.16	547.984
2125.84	581.706
2129.51	544.875
2133.18	562.68
2136.85	547.118
2140.51	565.61
2144.18	562.817
2147.84	560.018
2151.5	561.821
2155.16	577.384
2158.82	564.591
2162.48	548.282
2166.13	535.749
2169.79	558.02
2173.44	584.129
2177.09	556.557
2180.74	548.166
2184.38	566.161
2188.03	572.596
2191.67	567.405
2195.32	563.327
2198.96	564.763
2202.6	571.761
2206.23	578.873
2209.87	587.925
2213.5	576.896
2217.14	542.898
2220.77	575.003
2224.4	554.732
2228.03	584.154
2231.65	558.312
2235.28	571.254
2238.9	577.717
2242.52	570.273
2246.14	564.655
2249.76	551.633
2253.38	591.783
2256.99	568.56
2260.6	550.814
2264.21	571.43
2267.82	541.528
2271.44	544.447
2275.04	548.093
2278.65	560.968
2282.25	561.312
2285.85	542.877
2289.45	540.391
2293.05	553.019
2296.65	561.913
2300.25	560.354
2303.84	543.498
2307.43	568.247
2311.02	580.602
2314.62	660.152
2318.2	597.408
2321.79	538.264
2325.38	544.243
2328.96	557.787
2332.54	546.657
2336.12	541.154
2339.7	547.819
2343.28	532.811
2346.85	552.47
2350.43	569.226
2354	531.731
2357.57	517.643
2361.14	551.016
2364.71	555.503
2368.27	548.022
2371.84	552.654
2375.4	547.978
2378.96	574.729
2382.52	556.361
2386.08	550.985
2389.64	534.719
2393.19	570.897
2396.75	542.138
2400.3	553.964
2403.85	554.999
2407.4	546.051
2410.95	553.84
2414.49	546.124
2418.04	538.512
2421.58	539.263
2425.12	545.697
2428.66	548.576
2432.2	546.947
2435.74	551.898
2439.27	539.229
2442.81	560.106
2446.34	548.418
2449.87	557.418
2453.4	556.909
2456.93	546.485
2460.45	566.882
2463.98	550.322
2467.5	546.885
2471.02	544.276
2474.54	552.271
2478.06	558.573
2481.58	539.327
2485.09	546.159
2488.61	552.025
2492.12	539.171
2495.63	548.697
2499.14	557.35
2502.65	540.533
2506.15	524.633
2509.66	573.91
2513.16	564.581
2516.66	555.402
2520.16	533.95
2523.66	539.676
2527.16	548.426
2530.66	549.847
2534.15	550.503
2537.64	543.887
2541.13	561.492
2544.62	549.863
2548.11	527.179
2551.6	540.607
2555.08	538.634
2558.57	548.715
2562.05	538.597
2565.53	526.759
2569.01	544.898
2572.49	536.086
2575.96	530.155
2579.44	553.44
2582.91	535.311
2586.38	557.752
2589.85	526.816
2593.32	534.581
2596.79	553.982
2600.25	552.474
2603.72	548.791
2607.18	536.052
2610.64	555.364
2614.1	565.326
2617.56	538.578
2621.02	553.032
2624.47	537.539
2627.92	541.171
2631.38	528.37
2634.83	520.209
2638.28	536.874
2641.72	561.018
2645.17	535.399
2648.61	539.314
2652.06	525.939
2655.5	550.483
2658.94	561.587
2662.38	543.251
2665.82	557.076
2669.25	543.474
2672.69	546.917
2676.12	537.3
2679.55	537.182
2682.98	537.195
2686.41	553.391
2689.84	541.019
2693.26	545.267
2696.69	560.787
2700.11	544.751
2703.53	548.122
2706.95	557.507
2710.37	534.485
2713.79	545.989
2717.2	540.853
2720.62	525.535
2724.03	554.105
2727.44	545.41
2730.85	515.138
2734.26	542.875
2737.66	511.595
2741.07	545.869
2744.47	543.448
2747.87	553.251
2751.28	536.713
2754.67	542.629
2758.07	554.279
2761.47	541.278
2764.86	547.042
2768.26	536.669
2771.65	550.766
2775.04	545.922
2778.43	524.984
2781.82	535.075
2785.2	540.427
2788.59	553.287
2791.97	551.047
2795.35	560.133
2798.73	527.794
2802.11	556.45
2805.49	538.217
2808.87	547.126
2812.24	541.968
2815.62	550.781
2818.99	548.453
2822.36	548.088
2825.73	522.586
2829.1	526.987
2832.46	554.778
2835.83	538.867
2839.19	534.238
2842.55	533.446
2845.91	562.648
2849.27	543.632
2852.63	550.61
2855.99	532.419
2859.34	546.102
2862.69	539.221
2866.05	547.362
2869.4	539.511
2872.75	546.667
2876.09	548.172
2879.44	556.268
2882.78	561.505
2886.13	545.001
2889.47	537.009
2892.81	537.35
2896.15	560.314
2899.49	555.774
2902.82	555.877
2906.16	561.618
2909.49	552.154
2912.82	546.473
2916.16	539.744
2919.49	559.46
2922.81	563.075
2926.14	545.782
2929.46	558.707
2932.79	562.045
2936.11	551.23
2939.43	578.126
2942.75	551.314
2946.07	560.334
2949.39	558.98
2952.7	567.94
2956.02	558.201
2959.33	557.01
2962.64	563.307
2965.95	562.225
2969.26	572.628
2972.57	561.354
2975.87	576.57
2979.17	554.132
2982.48	563.627
2985.78	572.232
2989.08	570.528
2992.38	582.939
2995.68	567.206
2998.97	574.034
3002.27	593.066
3005.56	596.173
3008.85	569.183
3012.14	568.573
3015.43	593.396
3018.72	589.939
3022	592.136
3025.29	600.959
3028.57	593.728
3031.85	596.86
3035.14	604.691
3038.41	587.939
3041.69	595.782
3044.97	606.498
3048.24	617.199
3051.52	627.946
3054.79	622.568
3058.06	641.773
3061.33	637.111
3064.6	648.64
3067.87	635.404
3071.13	652.974
3074.4	644.323
3077.66	657.483
3080.92	661.528
3084.18	658.118
3087.44	681.415
3090.7	652.62
3093.95	686.831
3097.21	676.45
3100.46	699.352
3103.71	701.558
3106.96	705.706
3110.21	699.175
3113.46	727.849
3116.71	721.334
3119.95	721.49
3123.2	762.602
3126.44	728.433
3129.68	767.637
3132.92	760.138
3136.16	773.571
3139.4	766.013
3142.63	803.26
3145.87	798.601
3149.1	813.046
3152.33	816.022
3155.56	826.643
3158.79	859.195
3162.02	844.043
3165.25	887.044
3168.47	861.265
3171.69	874.573
3174.92	898.305
3178.14	901.962
3181.36	910.411
3184.58	949.291
3187.79	933.761
3191.01	951.588
3194.22	951.292
3197.43	962.4
3200.65	935.442
3203.86	967.548
3207.07	960.661
3210.27	963.351
3213.48	982.287
3216.69	1012.65
3219.89	975.493
3223.09	1015.48
3226.29	1030.77
3229.49	1024.26
3232.69	1015.78
3235.89	1013.18
3239.08	1013.53
3242.28	1055.86
3245.47	1061.06
3248.66	1054.91
3251.85	1073.6
3255.04	1076.1
3258.23	1068.93
3261.42	1080.71
3264.6	1051.26
3267.79	1071.35
3270.97	1077.99
3274.15	1070.3
3277.33	1099.68
3280.51	1067.71
3283.68	1123.55
3286.86	1111.52
3290.04	1113.87
3293.21	1113.34
3296.38	1103.25
3299.55	1111.54
3302.72	1138.66
3305.89	1139.94
3309.06	1150.54
3312.22	1142.03
3315.39	1153.43
3318.55	1164.77
3321.71	1174.18
3324.87	1175.07
3328.03	1188.27
3331.19	1205.3
3334.34	1225.23
3337.5	1215.04
3340.65	1238.83
3343.81	1243.03
3346.96	1252.3
3350.11	1272.91
3353.25	1271.96
3356.4	1252.23
3359.55	1291.1
3362.69	1298.91
3365.84	1294.54
3368.98	1312.84
3372.12	1319.98
3375.26	1354.59
3378.4	1339.25
3381.53	1367.3
3384.67	1376.57
3387.8	1417.1
3390.94	1429.35
3394.07	1448.61
3397.2	1421.21
3400.33	1510.71
3403.46	1584.38
3406.58	1737.22
3409.71	2042.71
3412.83	2952.2
3415.96	5148.76
3419.08	6648.08
3422.2	4977.54
3425.32	2857.84
3428.44	2017.13
3431.55	1744.07
3434.67	1628.05
3437.78	1555.17
3440.89	1508.16
3444	1498.05
3447.12	1477.42
3450.22	1458.48
3453.33	1452.88
3456.44	1475.61
3459.54	1445.96
3462.65	1442.9
3465.75	1445.42
3468.85	1490.15
3471.95	1489.75
3475.05	1559.54
3478.15	1591.47
3481.24	1688.6
3484.34	1776.25
3487.43	2028.2
3490.53	2271.16
3493.62	2688.64
3496.71	3174.45
3499.79	3627.24
3502.88	3613.31
3505.97	3159.66
3509.05	2588.71
3512.14	2143.47
3515.22	1810.56
3518.3	1648.41
3521.38	1512.17
3524.46	1360.02
3527.54	1295.57
3530.61	1222.38
3533.69	1174.95
3536.76	1135.82
3539.83	1141.85
3542.9	1069.95
3545.97	1049.99
3549.04	1042.13
3552.11	980.15
3555.18	995.855
3558.24	952.987
3561.3	931.637
3564.37	921.562
3567.43	910.578
3570.49	888.05
3573.55	870.153
3576.61	859.803
3579.66	866.455
3582.72	822.758
3585.77	840.686
3588.82	807.331
3591.87	808.071
3594.92	783.165
3597.97	777.203
3601.02	782.548
3604.07	757.535
3607.11	757.119
3610.16	730.205
3613.2	741.075
3616.24	699.077
3619.28	715.66
3622.32	675.668
3625.36	697.024
3628.39	683.487
3631.43	677.447
3634.46	653.643
3637.5	637.494
3640.53	618.599
3643.56	611.151
3646.59	604.547
3649.62	576.378
3652.64	588.966
3655.67	583.524
3658.69	568.065
3661.72	560.037
3664.74	534.794
3667.76	548.209
3670.78	537.168
3673.79	510.101
3676.81	508.533
3679.83	501.278
3682.84	494.957
3685.86	496.209
3688.87	486.118
3691.88	494.029
3694.89	481.959
3697.9	473.726
3700.91	460.766
3703.91	461.084
3706.92	468.011
3709.92	451.138
3712.92	438.947
3715.92	462.918
3718.92	426.906
3721.92	445.101
3724.92	445.17
3727.92	429.017
3730.91	463.296
3733.91	434.674
3736.9	441.246
3739.89	435.39
3742.88	438.06
3745.87	443.538
3748.86	441.369
3751.85	430.64
3754.83	437.964
3757.82	435.792
3760.8	446.856
3763.78	442.747
3766.76	434.886
3769.74	427.073
3772.72	429.704
3775.7	441.809
3778.67	424.649
3781.65	415.066
3784.62	427.223
3787.6	425.237
3790.57	424.257
3793.54	422.377
3796.51	427.129
3799.47	406.444
3802.44	416
3805.41	411.405
3808.37	404.941
3811.33	426.848
3814.3	414.734
3817.26	410.197
3820.22	429.332
3823.18	410.627
3826.13	408.025
3829.09	418.691
3832.04	432.248
3835	408.818
3837.95	409.119
3840.9	398.954
3843.85	410.67
3846.8	410.988
3849.75	406.564
3852.69	391.651
3855.64	403.454
3858.58	389.481
3861.53	412.769
3864.47	403.544
3867.41	414.397
3870.35	415.659
3873.29	394.842
3876.22	416.202
3879.16	393.356
3882.1	398.308
3885.03	405.149
3887.96	393.706
3890.89	400.515
3893.82	399.588
3896.75	389.952
3899.68	413.001
3902.61	422.523
3905.53	410.936
3908.46	387.8
3911.38	404.993
3914.3	394.271
3917.23	394.192
3920.15	396.942
3923.06	389.081
3925.98	390.78
3928.9	397.228
3931.81	378.837
3934.73	403.631
3937.64	405.533
3940.55	396.877
3943.46	382.485
3946.37	381.533
3949.28	386.36
3952.19	405.568
3955.09	378.841
3958	397.155
3960.9	388.661
3963.8	396.483
3966.71	384.189
3969.61	388.215
3972.51	381.68
3975.4	398.172
3978.3	388.701
3981.2	382.1
3984.09	375.474
3986.99	390.002
3989.88	391.963
3992.77	391.106
3995.66	365.228
3998.55	383.637
4001.43	387.617
4004.32	386.803
4007.21	377.324
4010.09	378.438
4012.98	388.236
4015.86	371.024
4018.74	390.479
4021.62	389.668
4024.5	385.968
4027.37	388.065
4030.25	382.439
4033.13	368.102
4036	390.55
4038.87	382.037
4041.75	388.953
4044.62	377.455
4047.49	359.187
4050.35	381.658
4053.22	386.714
4056.09	380.134
4058.95	376.439
4061.82	380.513
4064.68	368.061
4067.54	376.994
4070.4	381.066
4073.26	360.791
4076.12	365.821
4078.98	363.058
4081.83	371.018
4084.69	378.976
4087.54	380.098
4090.4	369.523
4093.25	363.821
4096.1	364.944
4098.95	363.148
4101.8	360.357
4104.64	373.185
4107.49	359.581
4110.33	367.486
4113.18	352.835
4116.02	359.673
4118.86	344.958
4121.7	366.485
4124.54	359.66
4127.38	363.655
4130.22	360.883
4133.05	365.045
4135.89	362.15
4138.72	375.455
4141.56	361.497
4144.39	356.713
4147.22	361.743
4150.05	371.639
4152.88	341.262
4155.7	354.807
4158.53	350.736
4161.36	343.844
4164.18	355.538
4167	365.279
4169.82	348.637
4172.65	362.325
4175.46	347.656
4178.28	345.717
4181.1	349.667
4183.92	353.633
4186.73	372.293
4189.55	351.849
4192.36	360.814
4195.17	362.974
4197.98	374.957
4200.79	371.256
4203.6	366.572
4206.41	354.02
4209.21	364.052
4212.02	350.489
4214.83	342.932
4217.63	337.423
4220.43	355.519
4223.23	331.168
4226.03	343.341
4228.83	349.647
4231.63	349.059
4234.42	345.531
4237.22	329.099
4240.01	345.435
4242.81	340.928
4245.6	347.371
4248.39	348.808
4251.18	337.238
4253.97	357.632
4256.76	340.997
4259.55	353.411
4262.33	337.764
4265.12	337.173
4267.9	334.576
4270.68	340.021
4273.47	330.305
4276.25	325.556
4279.03	344.005
4281.8	342.232
4284.58	331.309
4287.36	325.395
4290.13	328.566
4292.91	322.645
4295.68	336.015
4298.45	333.164
4301.22	327.245
4303.99	331.474
4306.76	330.636
4309.53	326.776
4312.3	316.791
4315.06	316.924
4317.83	326.194
4320.59	319.156
4323.35	341.623
4326.11	330.491
4328.87	325.452
4331.63	329.573
4334.39	318.404
4337.15	327.633
4339.9	324.668
4342.66	320.697
4345.41	335.12
4348.17	312.826
4350.92	313.026
4353.67	308.135
4356.42	326.735
4359.17	312.607
4361.91	322.019
4364.66	309.927
4367.41	321.403
4370.15	323.643
4372.89	303.272
4375.63	329.071
4378.38	319.949
4381.12	327.273
4383.86	322.321
4386.59	328.791
4389.33	310.635
4392.07	303.941
4394.8	319.94
4397.53	304.793
4400.27	313.437
4403	322.093
4405.73	324.557
4408.46	308.293
4411.19	321.091
4413.92	310.967
4416.64	304.913
4419.37	300.917
4422.09	317.838
4424.82	296.139
4427.54	322.494
4430.26	327.962
4432.98	314.581
4435.7	296.975
4438.42	308.671
4441.13	299.398
4443.85	297.453
4446.57	312.292
4449.28	305.076
4451.99	299.94
4454.71	314.749
4457.42	293.805
4460.13	289.693
4462.83	311.889
4465.54	297.277
4468.25	301.619
4470.95	321.786
4473.66	309.334
4476.36	289.509
4479.07	296.061
4481.77	298.404
4484.47	286.993
4487.17	305.177
4489.87	304.281
4492.56	300.093
4495.26	295.983
4497.96	281.279
4500.65	307.841
4503.34	296.295
4506.04	299.6
4508.73	295.482
4511.42	292.426
4514.11	289.38
4516.8	303.328
4519.48	305.642
4522.17	300.519
4524.85	287.924
4527.54	300.888
4530.22	284.03
4532.9	293.828
4535.58	298.301
4538.27	301.748
4540.94	277.394
4543.62	288.321
4546.3	282.135
4548.98	293.093
4551.65	283.759
4554.33	276.564
4557	286.661
4559.67	280.678
4562.34	282.282
4565.01	279.728
4567.68	274.904
4570.35	292.53
4573.02	267.56
4575.68	289.438
4578.35	287.511
4581.01	294.499
4583.67	278.37
4586.34	277.474
4589	266.723
4591.66	295.235
4594.31	287.835
4596.97	274.879
4599.63	275.097
4602.29	277.535
4604.94	288.742
4607.59	286.82
4610.25	273.906
4612.9	289.527
4615.55	268.893
4618.2	263.657
4620.85	261.711
4623.5	275.182
4626.14	276.511
4628.79	265.698
4631.43	276.936
4634.08	271.562
4636.72	292.752
4639.36	260.786
4642	264.298
4644.64	274.545
4647.28	261.555
4649.92	273.076
4652.56	280.319
4655.19	270.244
4657.83	269.355
4660.46	267.414
4663.1	250.944
4665.73	266.771
4668.36	270.347
4670.99	267.2
4673.62	276.378
4676.24	272.102
4678.87	261.072
4681.5	261.261
4684.12	287.319
4686.75	266.144
4689.37	264.105
4691.99	263.16
4694.61	271.226
4697.23	254.482
4699.85	250.142
4702.47	257.063
4705.09	267.379
4707.7	273.168
4710.32	273.3
4712.93	254.181
4715.55	253.143
4718.16	264.578
4720.77	257.843
4723.38	265.886
4725.99	256.944
4728.6	260.481
4731.21	257.209
4733.81	264.159
4736.42	250.627
4739.02	263.243
4741.63	233.745
4744.23	261.126
4746.83	254.316
4749.43	240.688
4752.03	246.406
4754.63	265.77
4757.23	248.733
4759.82	264.739
4762.42	271.641
4765.01	259.226
4767.61	254.859
4770.2	248.12
4772.79	250.51
4775.38	235.782
4777.97	251.876
4780.56	250.844
4783.15	260.105
4785.74	251.073
4788.32	247.759
4790.91	246.75
4793.49	244.592
4796.07	251.632
4798.66	251.816
4801.24	257.758
4803.82	241.905
4806.4	242.162
4808.98	256.225
4811.55	240.363
4814.13	242.94
4816.71	238.622
4819.28	241.23
4821.85	247.325
4824.43	232.56
4827	239.807
4829.57	252.927
4832.14	242.79
4834.71	233.824
4837.28	241.208
4839.84	239.268
4842.41	234.927
4844.97	244.627
4847.54	244.923
4850.1	228.606
4852.66	222.72
4855.22	247.766
4857.78	239.881
4860.34	233.106
4862.9	234.488
4865.46	242.919
4868.01	230.184
4870.57	237.499
4873.12	238.854
4875.68	233.097
4878.23	239.192
4880.78	231.021
4883.33	241.851
4885.88	232.481
4888.43	220.729
4890.98	229.191
4893.53	225.745
4896.07	233.011
4898.62	241.477
4901.16	232.042
4903.7	224.998
4906.25	233.435
4908.79	241.857
4911.33	237.106
4913.87	246.669
4916.41	222.791
4918.94	239.542
4921.48	232.399
4924.02	238.411
4926.55	233.656
4929.08	218.165
4931.62	229.029
4934.15	218.365
4936.68	235.206
4939.21	236.43
4941.74	224.49
4944.27	215.006
4946.79	217.502
4949.32	214.011
4951.85	224.904
4954.37	221.417
4956.9	226.364
4959.42	220.521
4961.94	218.323
4964.46	225.806
4966.98	213.991
4969.5	206.943
4972.02	213.164
4974.53	226.643
4977.05	218.373
4979.57	220.994
4982.08	226.048
4984.59	225.053
4987.1	215.56
4989.62	226.709
4992.13	218.403
4994.64	213.756
4997.15	218.878
4999.65	211.807