File: Data/3-Raman/raw/bu19w-e-ff11-fi05-v_150 (500nm)_633nm_edge_100%_x100_vis_h50um_60sx2_01.txt
#Acq. time (s)=	60
#Accumulations=	2
#Range (cm-¹)=	100...4000
#Windows=	1
#Auto scanning=	Off
#Autofocus=	Off
#Macrospot=	Off
#AutoExposure=	Off
#Spike filter=	Multiple accum.
#Delay time (s)=	2
#Binning=	1
#Readout mode=	Signal
#DeNoise=	Off
#ICS correction=	On
#Dark correction=	Off
#Inst. Process=	Off
#Detector Gain=	Best Dynamic
#Detector ADC=	50 kHz HS
#Detector temperature (°C)=	-60.09
#Instrument=	LabRAM HR Evol
#Detector=	SIN-EM FIVIS
#Objective=	x100_VIS
#Grating=	150 (500nm)
#ND Filter=	100%
#Laser=	633nm_Edge
#Hole=	49.98
#Temperature=	0
#Range=	Visible
#StageXY=	75x50mm Scan+
#StageZ=	Z motor
#X (µm)=	0
#Y (µm)=	0
#Z (µm)=	-290.2
#Full time(mm:ss)=	2:04
#Project=	21_11_04
#Sample=	BU19w
#Site=
#Title=	BU19w-E-FF11-FI05-V_150 (500nm)_633nm_Edge_100%_x100_VIS_H50um_60sX2
#Remark=
#Date=	04.11.2021 16:47
#Acquired=	04.11.2021 16:47:03
102.881	223.573
109.397	211.381
115.908	190.572
122.414	198.355
128.914	192.744
135.409	191.856
141.898	188.033
148.383	187.116
154.861	194.856
161.335	214.128
167.801	175.896
174.264	171.123
180.721	172.961
187.173	169.89
193.62	169.616
200.061	159.868
206.496	168.432
212.926	160.73
219.352	179.738
225.772	226.302
232.185	260.238
238.595	211.499
244.999	199.029
251.397	188.489
257.791	187.422
264.178	201.576
270.561	207.224
276.939	241.361
283.31	235.61
289.678	189.047
296.039	165.215
302.396	194.398
308.746	202.715
315.093	263.916
321.433	305.273
327.768	254.239
334.099	202.32
340.423	198.502
346.743	207.854
353.058	210.563
359.367	198.14
365.671	199.818
371.971	174.254
378.265	169.376
384.553	160.804
390.837	169.332
397.116	160.18
403.389	152.074
409.657	158.999
415.92	167.742
422.178	182.135
428.431	197.087
434.678	191.919
440.921	204.623
447.158	183.432
453.391	209.092
459.618	180.604
465.84	159.867
472.057	161.612
478.27	156.977
484.477	169.108
490.679	163.539
496.876	187.81
503.068	179.493
509.255	179.587
515.436	171.327
521.613	164.087
527.785	176.586
533.952	177.045
540.113	171.847
546.27	157.999
552.423	157.175
558.568	157.219
564.711	158.893
570.848	148.181
576.979	168.35
583.107	155.689
589.228	173.985
595.345	185.888
601.458	192.454
607.565	194.61
613.667	195.008
619.764	176.812
625.856	172.704
631.944	157.008
638.026	154.202
644.104	162.452
650.177	177.241
656.244	164.605
662.308	157.613
668.365	160.953
674.418	158.063
680.467	142.211
686.511	136.734
692.549	151.967
698.582	135.439
704.611	140.41
710.635	132.137
716.655	139.562
722.669	141.362
728.679	143.042
734.683	136.231
740.683	135.054
746.678	138.586
752.669	148.719
758.654	154.304
764.635	137.79
770.611	140.055
776.582	153.599
782.549	161.432
788.511	145.613
794.466	150.431
800.419	143.808
806.366	152.151
812.309	143.472
818.247	143.172
824.18	148.448
830.108	148.117
836.033	147.149
841.952	151.109
847.865	143.881
853.776	150.788
859.681	156.838
865.58	157.271
871.476	154.825
877.366	146.497
883.253	154.194
889.134	150.397
895.012	154.102
900.883	162.35
906.751	144.012
912.614	159.642
918.473	151.793
924.326	159.204
930.174	163.084
936.019	165.252
941.859	172.443
947.693	197.772
953.525	194.735
959.35	202.058
965.171	200.633
970.988	253.761
976.801	267.356
982.608	306.417
988.411	259.976
994.209	234.654
1000	225.694
1005.79	214.021
1011.58	235.041
1017.36	237.175
1023.13	218.397
1028.9	199.76
1034.67	188.778
1040.43	184.546
1046.19	182.224
1051.94	183.635
1057.69	182.017
1063.44	170.504
1069.17	173.356
1074.91	172.316
1080.64	180.895
1086.37	214.64
1092.09	226.138
1097.8	231.8
1103.52	187.187
1109.22	179.54
1114.93	187.689
1120.63	170.77
1126.32	175.05
1132.01	203.845
1137.7	201.409
1143.38	218.591
1149.06	216.951
1154.73	193.48
1160.4	166.808
1166.06	163.548
1171.72	150.496
1177.38	149.207
1183.03	146.04
1188.67	158.696
1194.31	141.211
1199.95	134.6
1205.58	138.957
1211.21	142.433
1216.84	140.076
1222.46	129.802
1228.07	128.425
1233.68	126.959
1239.29	140.48
1244.89	138.756
1250.49	137.877
1256.08	129.819
1261.67	138.762
1267.26	134.545
1272.84	177.559
1278.42	140.03
1283.99	136.736
1289.56	129.53
1295.12	120.434
1300.68	127.416
1306.23	140.544
1311.78	125.841
1317.33	123.223
1322.87	132.748
1328.41	126.185
1333.94	126.672
1339.47	134.244
1345	132.517
1350.52	135.848
1356.04	145.293
1361.55	134.111
1367.06	130.007
1372.56	144.343
1378.06	213.099
1383.56	140.119
1389.05	129.792
1394.53	127.76
1400.02	138.229
1405.5	129.166
1410.97	134.552
1416.44	126.576
1421.91	127.905
1427.37	124.077
1432.83	129.605
1438.28	127.845
1443.73	142.81
1449.17	117.946
1454.62	124.379
1460.05	124.434
1465.48	124.423
1470.91	128.585
1476.34	124.38
1481.76	144.383
1487.17	136.083
1492.59	126.786
1497.99	127.01
1503.4	120.941
1508.8	124.422
1514.19	140.709
1519.59	125.186
1524.97	135.242
1530.36	138.933
1535.74	120.068
1541.11	135.523
1546.48	126.002
1551.85	131.417
1557.21	133.413
1562.57	138.675
1567.93	146.08
1573.28	140.541
1578.62	148.01
1583.97	128.647
1589.3	133.008
1594.64	136.357
1599.97	135.462
1605.3	137.876
1610.62	130.648
1615.94	127.836
1621.25	135.975
1626.56	143.069
1631.87	132.592
1637.17	132.977
1642.47	133.146
1647.76	131.136
1653.05	140.149
1658.34	124.717
1663.62	138.063
1668.9	131.421
1674.18	142.514
1679.45	143.598
1684.71	143.497
1689.98	133.413
1695.23	147.776
1700.49	126.901
1705.74	147.583
1710.99	127.707
1716.23	138.915
1721.47	131.479
1726.7	136.173
1731.94	135.335
1737.16	135.602
1742.39	136.989
1747.61	134.973
1752.82	136.279
1758.03	143.187
1763.24	140.97
1768.44	126.311
1773.64	138.86
1778.84	149.221
1784.03	132.405
1789.22	139.5
1794.41	139.813
1799.59	139.026
1804.76	146.295
1809.94	140.896
1815.11	148.113
1820.27	134.572
1825.43	147.61
1830.59	137.515
1835.74	143.677
1840.89	138.141
1846.04	138.385
1851.18	136.27
1856.32	146.984
1861.45	139.037
1866.58	133.447
1871.71	143.107
1876.83	138.582
1881.95	145.833
1887.07	144.793
1892.18	137.732
1897.29	144.846
1902.39	141.446
1907.49	142.906
1912.59	136.172
1917.68	150.933
1922.77	146.324
1927.86	144.218
1932.94	133.701
1938.02	139.929
1943.09	134.102
1948.16	149.891
1953.23	148.777
1958.29	135.572
1963.35	138.005
1968.41	148.833
1973.46	146.342
1978.51	136.632
1983.55	143.773
1988.59	136.494
1993.63	137.653
1998.66	148.459
2003.69	142.476
2008.72	143.76
2013.74	135.45
2018.76	141.566
2023.77	148.916
2028.78	149.113
2033.79	140.914
2038.79	143.609
2043.79	147.544
2048.79	162.474
2053.78	143.254
2058.77	149.659
2063.76	157.34
2068.74	155.237
2073.72	154.336
2078.69	148.482
2083.66	132.696
2088.63	155.122
2093.59	147.968
2098.55	156.994
2103.51	141.206
2108.46	145.328
2113.41	158.273
2118.36	151.236
2123.3	151.695
2128.24	152.132
2133.17	148.733
2138.11	137.663
2143.03	154.494
2147.96	152.235
2152.88	152.448
2157.79	143.673
2162.71	148.89
2167.62	139.989
2172.52	140.068
2177.43	152.967
2182.32	155.549
2187.22	152.968
2192.11	158.144
2197	150.57
2201.89	150.763
2206.77	154.873
2211.64	155.194
2216.52	146.516
2221.39	139.123
2226.26	148.56
2231.12	161.946
2235.98	140.188
2240.84	148.383
2245.69	154.007
2250.54	154.399
2255.39	148.192
2260.23	144.615
2265.07	164.797
2269.9	157.138
2274.74	162.67
2279.57	146.893
2284.39	150.966
2289.21	153.666
2294.03	157.693
2298.84	151.122
2303.66	168.598
2308.46	164.866
2313.27	155.845
2318.07	172.322
2322.87	145.865
2327.66	155.695
2332.45	146.681
2337.24	159.341
2342.02	157.138
2346.8	164.536
2351.58	154.149
2356.35	146.371
2361.12	152.213
2365.89	166.344
2370.65	172.233
2375.41	161.489
2380.17	152.056
2384.92	148.065
2389.67	157.923
2394.42	156.587
2399.16	151.018
2403.9	169.096
2408.64	160.759
2413.37	156.857
2418.1	167.414
2422.83	155.305
2427.55	156.965
2432.27	158.785
2436.99	166.338
2441.7	151.218
2446.41	164.486
2451.11	162.127
2455.82	159.731
2460.51	161.634
2465.21	156.335
2469.9	174.091
2474.59	155.702
2479.28	160.472
2483.96	163.774
2488.64	167.034
2493.32	152.754
2497.99	164.792
2502.66	178.312
2507.32	172.734
2511.99	161.206
2516.65	173.199
2521.3	158.705
2525.96	178.172
2530.61	169.558
2535.25	152.061
2539.89	159.796
2544.53	170.553
2549.17	164.963
2553.8	166.821
2558.43	173.122
2563.06	182.507
2567.68	173.925
2572.3	190.992
2576.92	180.87
2581.53	182.758
2586.14	187.568
2590.75	157.321
2595.35	169.679
2599.96	165.377
2604.55	162.536
2609.15	168.833
2613.74	173.548
2618.33	173.698
2622.91	149.344
2627.49	174.047
2632.07	175.904
2636.64	168.65
2641.22	179.997
2645.78	169.737
2650.35	165.597
2654.91	167.605
2659.47	181.958
2664.03	165.016
2668.58	177.778
2673.13	181.288
2677.67	170.924
2682.22	168.608
2686.76	167.785
2691.29	147.724
2695.83	180.132
2700.36	183.721
2704.89	176.051
2709.41	163.488
2713.93	186.368
2718.45	181.926
2722.96	161.204
2727.47	179.27
2731.98	166.445
2736.49	173.082
2740.99	181.359
2745.49	188.108
2749.98	181.915
2754.47	180.821
2758.96	169.689
2763.45	166.662
2767.93	171.935
2772.41	188.74
2776.89	175.989
2781.36	161.611
2785.84	167.146
2790.3	176.04
2794.77	181.606
2799.23	185.447
2803.69	185.88
2808.14	172.771
2812.59	181.531
2817.04	178.416
2821.49	171.919
2825.93	182.392
2830.37	184.379
2834.81	189.747
2839.24	176.384
2843.67	178.353
2848.1	183.801
2852.53	163.627
2856.95	186.367
2861.37	179.958
2865.78	182.23
2870.19	177.603
2874.6	183.364
2879.01	187.444
2883.41	195.097
2887.81	174.724
2892.21	168.266
2896.6	174.159
2901	169.482
2905.38	187.816
2909.77	168.73
2914.15	183.436
2918.53	182.061
2922.91	180.717
2927.28	174.012
2931.65	179.955
2936.02	182.217
2940.38	191.654
2944.74	177.444
2949.1	195.912
2953.46	174.298
2957.81	178.197
2962.16	191.273
2966.5	191.587
2970.85	175.405
2975.19	170.215
2979.52	187.126
2983.86	193.081
2988.19	171.344
2992.52	195.971
2996.85	164.865
3001.17	185.943
3005.49	190.323
3009.8	196.601
3014.12	189.668
3018.43	186.559
3022.74	189.119
3027.04	172.519
3031.34	211.178
3035.64	186.719
3039.94	190.922
3044.23	185.529
3048.52	205.112
3052.81	188.095
3057.09	196.173
3061.38	188.774
3065.65	204.624
3069.93	189.437
3074.2	211.187
3078.47	213.531
3082.74	196.344
3087	192.871
3091.27	211.07
3095.52	194.009
3099.78	214.402
3104.03	207.215
3108.28	190.079
3112.53	198.826
3116.77	203.614
3121.01	212.498
3125.25	205.328
3129.49	202.214
3133.72	197.082
3137.95	206.235
3142.18	198.905
3146.4	222.48
3150.62	235.78
3154.84	213.586
3159.06	230.933
3163.27	227.431
3167.48	215.435
3171.69	205.488
3175.89	229.207
3180.09	229.597
3184.29	234.152
3188.49	232.269
3192.68	219.872
3196.87	224.564
3201.06	218.882
3205.24	206.806
3209.42	220.545
3213.6	221.457
3217.78	228.927
3221.95	240.735
3226.12	235.143
3230.29	218.495
3234.45	221.518
3238.61	197.985
3242.77	212.115
3246.93	199.627
3251.08	211.495
3255.23	214.288
3259.38	223.871
3263.53	211.093
3267.67	207.635
3271.81	213.039
3275.95	215.877
3280.08	193.432
3284.21	209.883
3288.34	214.898
3292.47	196.876
3296.59	211.058
3300.71	202.243
3304.83	200.321
3308.95	216.951
3313.06	217.324
3317.17	227.039
3321.27	218.18
3325.38	214.038
3329.48	212.264
3333.58	208.307
3337.67	206.681
3341.77	204.845
3345.86	191.028
3349.95	219.876
3354.03	203.588
3358.11	215.976
3362.19	216.468
3366.27	214.53
3370.34	229.403
3374.42	205.759
3378.48	222.936
3382.55	223.24
3386.61	218.688
3390.68	211.673
3394.73	209.497
3398.79	217.086
3402.84	231.91
3406.89	200.532
3410.94	222.595
3414.98	210.595
3419.03	240.004
3423.06	252.359
3427.1	255.011
3431.14	218.66
3435.17	206.737
3439.2	199.738
3443.22	217.301
3447.25	217.826
3451.27	208.5
3455.28	196.728
3459.3	199.878
3463.31	213.04
3467.32	221.296
3471.33	199.457
3475.34	197.47
3479.34	218.257
3483.34	208.779
3487.33	209.371
3491.33	215.033
3495.32	215.572
3499.31	200.704
3503.3	239.493
3507.28	206.508
3511.26	206.679
3515.24	217.088
3519.22	199.22
3523.19	204.478
3527.16	196.915
3531.13	204.782
3535.1	207.716
3539.06	203.03
3543.02	203.439
3546.98	206.373
3550.93	201.436
3554.89	193.712
3558.84	191.313
3562.78	194.182
3566.73	204.965
3570.67	197.569
3574.61	205.859
3578.55	198.495
3582.48	209.618
3586.41	202.311
3590.35	210.86
3594.27	192.851
3598.2	198.737
3602.12	185.87
3606.04	186.319
3609.95	192.086
3613.87	203.26
3617.78	192.86
3621.69	182.335
3625.6	190.575
3629.5	190.69
3633.4	209.697
3637.3	177.364
3641.2	193.897
3645.09	177.972
3648.98	200.001
3652.87	175.699
3656.76	184.041
3660.64	195.115
3664.53	187.07
3668.4	206.402
3672.28	190.183
3676.16	179.503
3680.03	188.087
3683.9	158.259
3687.76	175.259
3691.63	195.134
3695.49	176.2
3699.35	185.024
3703.2	179.922
3707.06	191.613
3710.91	161.287
3714.76	189.827
3718.6	178.971
3722.45	179.328
3726.29	193.789
3730.13	171.456
3733.97	174.626
3737.8	174.954
3741.63	166.702
3745.46	178.381
3749.29	181.482
3753.11	193.116
3756.93	167.495
3760.75	190.501
3764.57	173.39
3768.39	176.354
3772.2	190.852
3776.01	170.91
3779.81	176.85
3783.62	174.229
3787.42	174.496
3791.22	183.396
3795.02	177.922
3798.81	172.479
3802.61	175.747
3806.4	167.412
3810.18	164.874
3813.97	165.212
3817.75	186.05
3821.53	154.11
3825.31	169.061
3829.09	166.395
3832.86	184.417
3836.63	167.009
3840.4	173.195
3844.17	191.328
3847.93	173.675
3851.69	167.855
3855.45	179.822
3859.21	164.972
3862.96	162.054
3866.71	156.374
3870.46	171.67
3874.21	174.749
3877.95	174.859
3881.69	166.001
3885.44	172.126
3889.17	163.308
3892.91	187.52
3896.64	157.804
3900.37	164.07
3904.1	158.281
3907.82	167.559
3911.55	158.754
3915.27	149.945
3918.99	156.331
3922.7	162.801
3926.42	169.271
3930.13	160.455
3933.84	169.906
3937.54	173.214
3941.25	167.375
3944.95	170.797
3948.65	164.948
3952.35	177.548
3956.04	149.956
3959.73	156.291
3963.42	159.51
3967.11	153.395
3970.8	144.131
3974.48	165.887
3978.16	165.932
3981.84	169.025
3985.52	150.408
3989.19	162.805
3992.86	162.86
3996.53	150.558
3998.37	153.737