File: Data/3-Raman/raw/bu19w-e-ff11-fi09-l_150 (500nm)_633nm_edge_100%_x100_vis_h50um_60sx2_01.txt
#Acq. time (s)=	60
#Accumulations=	2
#Range (cm-¹)=	100...4000
#Windows=	1
#Auto scanning=	Off
#Autofocus=	Off
#Macrospot=	Off
#AutoExposure=	Off
#Spike filter=	Multiple accum.
#Delay time (s)=	2
#Binning=	1
#Readout mode=	Signal
#DeNoise=	Off
#ICS correction=	On
#Dark correction=	Off
#Inst. Process=	Off
#Detector Gain=	Best Dynamic
#Detector ADC=	50 kHz HS
#Detector temperature (°C)=	-60.09
#Instrument=	LabRAM HR Evol
#Detector=	SIN-EM FIVIS
#Objective=	x100_VIS
#Grating=	150 (500nm)
#ND Filter=	100%
#Laser=	633nm_Edge
#Hole=	49.98
#Temperature=	0
#Range=	Visible
#StageXY=	75x50mm Scan+
#StageZ=	Z motor
#X (µm)=	0
#Y (µm)=	0
#Z (µm)=	-270
#Full time(mm:ss)=	2:04
#Project=	21_11_04
#Sample=	BU19w
#Site=
#Title=	BU19w-E-FF11-FI09-L_150 (500nm)_633nm_Edge_100%_x100_VIS_H50um_60sX2
#Remark=
#Date=	04.11.2021 16:16
#Acquired=	04.11.2021 16:16:57
102.881	405.673
109.397	357.391
115.908	350.098
122.414	333.142
128.914	360.139
135.409	335.388
141.898	350.707
148.383	353.653
154.861	394.979
161.335	402.866
167.801	308.178
174.264	263.156
180.721	224.706
187.173	218.704
193.62	218.351
200.061	219.997
206.496	209.466
212.926	219.87
219.352	265.554
225.772	381.616
232.185	459.103
238.595	325.566
244.999	253.18
251.397	247.362
257.791	251.003
264.178	256.594
270.561	254.644
276.939	270.76
283.31	277.328
289.678	220.318
296.039	221.076
302.396	213.318
308.746	277.374
315.093	468.817
321.433	679.906
327.768	479.705
334.099	297.586
340.423	254.139
346.743	241.789
353.058	265.206
359.367	284.738
365.671	249.655
371.971	207.133
378.265	177.821
384.553	167.367
390.837	169.332
397.116	164.878
403.389	155.841
409.657	170.322
415.92	178.137
422.178	207.681
428.431	250.022
434.678	241.902
440.921	236.61
447.158	254.74
453.391	278.322
459.618	234.738
465.84	186.9
472.057	173.722
478.27	168.156
484.477	170.039
490.679	181.244
496.876	194.335
503.068	213.061
509.255	245.825
515.436	245.086
521.613	238.885
527.785	231.856
533.952	210.857
540.113	193.504
546.27	181.581
552.423	169.447
558.568	155.33
564.711	147.577
570.848	147.24
576.979	162.722
583.107	163.169
589.228	187.979
595.345	204.523
601.458	207.366
607.565	217.944
613.667	216.52
619.764	196.51
625.856	168.939
631.944	159.837
638.026	160.804
644.104	161.51
650.177	170.659
656.244	164.605
662.308	141.711
668.365	127.363
674.418	116.099
680.467	107.708
686.511	106.867
692.549	101.467
698.582	104.508
704.611	102.842
710.635	96.3986
716.655	99.1504
722.669	91.5801
728.679	93.3287
734.683	94.0979
740.683	92.9957
746.678	95.6567
752.669	100.234
758.654	96.498
764.635	97.621
770.611	103.519
776.582	93.4748
782.549	93.6586
788.511	98.4892
794.466	89.1271
800.419	104.202
806.366	101.277
812.309	96.4321
818.247	98.1078
824.18	97.8724
830.108	105.13
836.033	106.041
841.952	101.519
847.865	107.325
853.776	112.269
859.681	120.101
865.58	130.823
871.476	137.78
877.366	141.756
883.253	145.654
889.134	151.346
895.012	143.67
900.883	135.844
906.751	135.513
912.614	129.503
918.473	137.695
924.326	148.872
930.174	168.723
936.019	190.675
941.859	231.027
947.693	262.273
953.525	276.629
959.35	278.486
965.171	291.613
970.988	384.239
976.801	483.353
982.608	524.122
988.411	477.341
994.209	363.691
1000	328.759
1005.79	323.652
1011.58	345.649
1017.36	374.612
1023.13	346.473
1028.9	284.072
1034.67	232.009
1040.43	232.73
1046.19	202.525
1051.94	198.171
1057.69	178.134
1063.44	172.447
1069.17	169.471
1074.91	188.819
1080.64	223.573
1086.37	271.813
1092.09	370.44
1097.8	388.592
1103.52	289.729
1109.22	231.806
1114.93	198.358
1120.63	203.853
1126.32	188.703
1132.01	244.907
1137.7	277.857
1143.38	338.448
1149.06	411.765
1154.73	321.482
1160.4	190.427
1166.06	166.495
1171.72	140.692
1177.38	127.682
1183.03	109.896
1188.67	101.077
1194.31	108.962
1199.95	95.4439
1205.58	85.9274
1211.21	87.2341
1216.84	88.5995
1222.46	86.0374
1228.07	84.451
1233.68	78.7847
1239.29	76.0304
1244.89	85.2717
1250.49	82.3223
1256.08	91.4292
1261.67	79.2203
1267.26	85.1612
1272.84	82.9951
1278.42	85.8247
1283.99	84.6458
1289.56	85.5198
1295.12	76.4578
1300.68	80.447
1306.23	80.5254
1311.78	77.7107
1317.33	79.9695
1322.87	76.2166
1328.41	75.5082
1333.94	76.8174
1339.47	87.284
1345	80.3288
1350.52	80.4834
1356.04	81.6313
1361.55	79.6447
1367.06	101.231
1372.56	108.386
1378.06	94.9959
1383.56	91.873
1389.05	77.4647
1394.53	82.6078
1400.02	74.51
1405.5	81.8226
1410.97	75.7823
1416.44	80.0787
1421.91	79.2286
1427.37	77.3535
1432.83	77.5549
1438.28	79.8378
1443.73	77.9438
1449.17	77.0581
1454.62	78.1963
1460.05	87.6811
1465.48	80.3236
1470.91	78.2009
1476.34	76.0977
1481.76	77.1792
1487.17	85.6433
1492.59	77.3342
1497.99	80.6331
1503.4	80.8036
1508.8	90.5366
1514.19	76.9916
1519.59	79.3733
1524.97	75.372
1530.36	80.9995
1535.74	92.0702
1541.11	86.929
1546.48	88.1472
1551.85	84.9074
1557.21	89.1223
1562.57	87.9536
1567.93	88.9414
1573.28	85.6171
1578.62	87.7294
1583.97	84.509
1589.3	87.7748
1594.64	77.0716
1599.97	93.3659
1605.3	97.8649
1610.62	95.953
1615.94	93.0209
1621.25	91.1958
1626.56	93.7346
1631.87	94.0797
1637.17	94.3526
1642.47	97.7878
1647.76	99.044
1653.05	89.186
1658.34	88.1337
1663.62	90.3787
1668.9	97.041
1674.18	92.6065
1679.45	85.9373
1684.71	90.3086
1689.98	95.7694
1695.23	85.7875
1700.49	93.6517
1705.74	94.1191
1710.99	93.1315
1716.23	89.8208
1721.47	94.5526
1726.7	92.463
1731.94	87.041
1737.16	93.965
1742.39	91.8899
1747.61	84.1465
1752.82	89.9099
1758.03	85.4593
1763.24	90.0167
1768.44	94.5917
1773.64	90.1176
1778.84	87.9438
1784.03	91.49
1789.22	98.5038
1794.41	94.1601
1799.59	92.1117
1804.76	91.2194
1809.94	94.8888
1815.11	97.3975
1820.27	96.453
1825.43	98.9857
1830.59	100.38
1835.74	88.9981
1840.89	102.003
1846.04	96.3437
1851.18	90.652
1856.32	88.4245
1861.45	95.6247
1866.58	95.8229
1871.71	88.9267
1876.83	100.84
1881.95	89.1531
1887.07	102.241
1892.18	99.9003
1897.29	95.1846
1902.39	96.4675
1907.49	104.956
1912.59	99.3047
1917.68	102.014
1922.77	97.3503
1927.86	95.1478
1932.94	101.325
1938.02	87.0805
1943.09	94.4123
1948.16	106.549
1953.23	105.409
1958.29	107.855
1963.35	100.642
1968.41	89.7817
1973.46	107.799
1978.51	105.333
1983.55	110.086
1988.59	105.226
1993.63	112.407
1998.66	107.588
2003.69	102.799
2008.72	100.451
2013.74	102.942
2018.76	98.1926
2023.77	93.4494
2028.78	100.817
2033.79	113.094
2038.79	109.676
2043.79	106.256
2048.79	100.405
2053.78	111.555
2058.77	108.121
2063.76	114.485
2068.74	109.831
2073.72	111.294
2078.69	110.284
2083.66	112.946
2088.63	118.041
2093.59	120.727
2098.55	108.593
2103.51	107.615
2108.46	115.389
2113.41	119.486
2118.36	112.329
2123.3	121.482
2128.24	110.469
2133.17	120.885
2138.11	121.169
2143.03	120.162
2147.96	107.647
2152.88	119.279
2157.79	116.854
2162.71	114.384
2167.62	109.307
2172.52	123.439
2177.43	118.405
2182.32	112.021
2187.22	127.366
2192.11	114.607
2197	115.971
2201.89	117.403
2206.77	117.601
2211.64	115.269
2216.52	119.408
2221.39	133.947
2226.26	113.529
2231.12	119.021
2235.98	121.931
2240.84	113.085
2245.69	113.376
2250.54	125.49
2255.39	124.481
2260.23	124.805
2265.07	114.497
2269.9	135.921
2274.74	118.849
2279.57	130.941
2284.39	129.684
2289.21	132.379
2294.03	128.417
2298.84	128.487
2303.66	124.616
2308.46	120.813
2313.27	118.388
2318.07	125.386
2322.87	125.699
2327.66	126.039
2332.45	118.291
2337.24	130.863
2342.02	123.126
2346.8	131.766
2351.58	134.966
2356.35	136.75
2361.12	124.663
2365.89	131.833
2370.65	136.265
2375.41	125.448
2380.17	117.34
2384.92	129.992
2389.67	131.486
2394.42	135.709
2399.16	127.356
2403.9	124.56
2408.64	132.922
2413.37	138.731
2418.1	123.985
2422.83	139.845
2427.55	140.072
2432.27	139.025
2436.99	136.609
2441.7	134.179
2446.41	134.58
2451.11	140.7
2455.82	136.81
2460.51	137.209
2465.21	141.926
2469.9	130.749
2474.59	139.77
2479.28	134.332
2483.96	136.114
2488.64	133.481
2493.32	138.136
2497.99	139.89
2502.66	144.557
2507.32	135.982
2511.99	134.706
2516.65	155.511
2521.3	139.513
2525.96	150.078
2530.61	144.384
2535.25	144.644
2539.89	150.877
2544.53	131.825
2549.17	135.105
2553.8	145.875
2558.43	138.647
2563.06	153.967
2567.68	143.808
2572.3	145.697
2576.92	141.517
2581.53	141.808
2586.14	145.043
2590.75	148.201
2595.35	151.418
2599.96	140.99
2604.55	159.484
2609.15	145.915
2613.74	158.257
2618.33	153.803
2622.91	147.813
2627.49	158.713
2632.07	140.569
2636.64	160.95
2641.22	150.641
2645.78	168.187
2650.35	165.597
2654.91	166.046
2659.47	156.968
2664.03	160.323
2668.58	157.415
2673.13	162.453
2677.67	172.499
2682.22	165.441
2686.76	166.195
2691.29	162.097
2695.83	157.716
2700.36	167.675
2704.89	166.405
2709.41	171.542
2713.93	168.619
2718.45	164.137
2722.96	157.964
2727.47	153.312
2731.98	155.078
2736.49	179.582
2740.99	176.48
2745.49	166.936
2749.98	170.494
2754.47	153.003
2758.96	168.049
2763.45	176.514
2767.93	157.127
2772.41	165.662
2776.89	167.726
2781.36	171.556
2785.84	163.82
2790.3	172.703
2794.77	169.89
2799.23	175.377
2803.69	170.74
2808.14	169.4
2812.59	164.644
2817.04	171.652
2821.49	175.307
2825.93	160.335
2830.37	175.883
2834.81	160.817
2839.24	174.679
2843.67	164.699
2848.1	166.704
2852.53	172.194
2856.95	162.319
2861.37	176.514
2865.78	151.139
2870.19	167.207
2874.6	165.984
2879.01	163.033
2883.41	177.599
2887.81	174.724
2892.21	191.171
2896.6	160.014
2901	183.679
2905.38	175.355
2909.77	179.443
2914.15	158.382
2918.53	167.711
2922.91	169.928
2927.28	170.406
2931.65	188.998
2936.02	180.404
2940.38	186.204
2944.74	182.903
2949.1	181.333
2953.46	168.823
2957.81	176.37
2962.16	187.612
2966.5	180.587
2970.85	179.078
2975.19	199.657
2979.52	194.501
2983.86	209.71
2988.19	193.573
2992.52	201.543
2996.85	181.631
3001.17	212.106
3005.49	194.073
3009.8	190.957
3014.12	202.878
3018.43	203.605
3022.74	213.828
3027.04	206.832
3031.34	207.355
3035.64	215.445
3039.94	212.029
3044.23	195.142
3048.52	216.667
3052.81	218.962
3057.09	213.567
3061.38	241.05
3065.65	227.898
3069.93	239.954
3074.2	205.347
3078.47	248.632
3082.74	247.139
3087	247.698
3091.27	240.521
3095.52	253.098
3099.78	257.875
3104.03	264.72
3108.28	277.655
3112.53	262.771
3116.77	285.863
3121.01	285.01
3125.25	278.154
3129.49	301.796
3133.72	276.732
3137.95	290.37
3142.18	301.964
3146.4	299.054
3150.62	318.874
3154.84	313.606
3159.06	327.068
3163.27	319.661
3167.48	335.238
3171.69	340.372
3175.89	311.595
3180.09	343.867
3184.29	340.103
3188.49	346.813
3192.68	338.837
3196.87	350.149
3201.06	359.821
3205.24	350.392
3209.42	353.948
3213.6	364.053
3217.78	328.743
3221.95	369.273
3226.12	346.7
3230.29	359.035
3234.45	344.951
3238.61	348.409
3242.77	329.834
3246.93	335.686
3251.08	325.635
3255.23	321.992
3259.38	318.37
3263.53	321.72
3267.67	316.558
3271.81	340.634
3275.95	325.529
3280.08	310.178
3284.21	324.573
3288.34	316.026
3292.47	330.43
3296.59	340.23
3300.71	320.122
3304.83	302.219
3308.95	337.609
3313.06	317.269
3317.17	327.169
3321.27	318.519
3325.38	312.284
3329.48	317.809
3333.58	333.056
3337.67	357.853
3341.77	325.62
3345.86	345.275
3349.95	336.351
3354.03	320.265
3358.11	359.165
3362.19	357.591
3366.27	341.57
3370.34	344.705
3374.42	347.746
3378.48	336.212
3382.55	353.564
3386.61	339.511
3390.68	354.402
3394.73	347.548
3398.79	338.363
3402.84	360.613
3406.89	365.818
3410.94	356.395
3414.98	339.63
3419.03	374.016
3423.06	366.957
3427.1	347.742
3431.14	343.26
3435.17	353.533
3439.2	346.785
3443.22	337.615
3447.25	353.198
3451.27	344.21
3455.28	332.83
3459.3	331.475
3463.31	337.625
3467.32	333.819
3471.33	339.955
3475.34	350.918
3479.34	339.37
3483.34	325.189
3487.33	338.8
3491.33	321.913
3495.32	327.822
3499.31	313.201
3503.3	311.213
3507.28	327.078
3511.26	293.972
3515.24	291.592
3519.22	286.62
3523.19	286.784
3527.16	271.563
3531.13	297.513
3535.1	295.447
3539.06	272.862
3543.02	291.552
3546.98	279.059
3550.93	269.015
3554.89	261.316
3558.84	256.386
3562.78	280.196
3566.73	251.964
3570.67	270.839
3574.61	271.419
3578.55	287.884
3582.48	288.719
3586.41	263.136
3590.35	253.297
3594.27	246.052
3598.2	254.757
3602.12	244.707
3606.04	229.213
3609.95	237.757
3613.87	232.874
3617.78	238.715
3621.69	228.256
3625.6	206.794
3629.5	225.853
3633.4	228.637
3637.3	204.442
3641.2	210.168
3645.09	207.861
3648.98	216.328
3652.87	194.767
3656.76	192.22
3660.64	192.386
3664.53	195.262
3668.4	200.935
3672.28	192.919
3676.16	182.244
3680.03	188.087
3683.9	188.535
3687.76	191.819
3691.63	175.759
3695.49	184.525
3699.35	173.895
3703.2	177.133
3707.06	169.235
3710.91	186.532
3714.76	175.766
3718.6	164.879
3722.45	162.384
3726.29	159.841
3730.13	177.124
3733.97	151.91
3737.8	157.885
3741.63	180.95
3745.46	172.673
3749.29	158.618
3753.11	178.811
3756.93	170.358
3760.75	193.366
3764.57	187.72
3768.39	164.884
3772.2	190.852
3776.01	176.655
3779.81	156.721
3783.62	191.508
3787.42	177.38
3791.22	154.515
3795.02	172.136
3798.81	172.479
3802.61	158.317
3806.4	161.589
3810.18	170.71
3813.97	165.212
3817.75	177.261
3821.53	177.594
3825.31	172.001
3829.09	163.45
3832.86	175.565
3836.63	178.833
3840.4	176.156
3844.17	182.429
3847.93	149.924
3851.69	173.797
3855.45	164.96
3859.21	164.972
3862.96	185.842
3866.71	168.288
3870.46	177.642
3874.21	174.749
3877.95	171.87
3881.69	166.001
3885.44	169.132
3889.17	163.308
3892.91	157.517
3896.64	169.828
3900.37	142.997
3904.1	176.37
3907.82	167.559
3911.55	176.898
3915.27	156.003
3918.99	153.295
3922.7	153.672
3926.42	160.122
3930.13	169.623
3933.84	154.599
3937.54	145.622
3941.25	158.162
3944.95	164.642
3948.65	155.699
3952.35	162.109
3956.04	146.864
3959.73	143.912
3963.42	147.121
3967.11	162.691
3970.8	162.729
3974.48	165.887
3978.16	159.729
3981.84	169.025
3985.52	165.914
3989.19	169.007
3992.86	169.064
3996.53	159.871
3998.37	153.737