File: Data/3-Raman/raw/bu19w-e-ff11-fi03-l_150 (500nm)_633nm_edge_100%_x100_vis_h50um_60sx2_01.txt
#Acq. time (s)=	60
#Accumulations=	2
#Range (cm-¹)=	100...4000
#Windows=	1
#Auto scanning=	Off
#Autofocus=	Off
#Macrospot=	Off
#AutoExposure=	Off
#Spike filter=	Multiple accum.
#Delay time (s)=	2
#Binning=	1
#Readout mode=	Signal
#DeNoise=	Off
#ICS correction=	On
#Dark correction=	Off
#Inst. Process=	Off
#Detector Gain=	Best Dynamic
#Detector ADC=	50 kHz HS
#Detector temperature (°C)=	-60.09
#Instrument=	LabRAM HR Evol
#Detector=	SIN-EM FIVIS
#Objective=	x100_VIS
#Grating=	150 (500nm)
#ND Filter=	100%
#Laser=	633nm_Edge
#Hole=	49.98
#Temperature=	0
#Range=	Visible
#StageXY=	75x50mm Scan+
#StageZ=	Z motor
#X (µm)=	0
#Y (µm)=	0
#Z (µm)=	-256.5
#Full time(mm:ss)=	2:04
#Project=	21_11_04
#Sample=	BU19w
#Site=
#Title=	BU19w-E-FF11-FI03-L_150 (500nm)_633nm_Edge_100%_x100_VIS_H50um_60sX2
#Remark=
#Date=	04.11.2021 16:54
#Acquired=	04.11.2021 16:54:35
102.881	490.525
109.397	470
115.908	440.846
122.414	444.03
128.914	515.099
135.409	562.17
141.898	548.788
148.383	563.261
154.861	780.861
161.335	758.308
167.801	479.761
174.264	358.064
180.721	316.696
187.173	306.759
193.62	297.665
200.061	291.58
206.496	289.626
212.926	346.737
219.352	460.071
225.772	780.861
232.185	971.967
238.595	604.08
244.999	475.484
251.397	454.368
257.791	511.971
264.178	488.05
270.561	431.994
276.939	480.351
283.31	454.628
289.678	387.097
296.039	373.509
302.396	438.46
308.746	639.331
315.093	1168.5
321.433	1594.31
327.768	1003.28
334.099	620.167
340.423	493.661
346.743	496.304
353.058	556.32
359.367	582.183
365.671	457.465
371.971	334.888
378.265	273.535
384.553	276.133
390.837	269.712
397.116	265.402
403.389	272.604
409.657	306.203
415.92	339.736
422.178	381.774
428.431	474.995
434.678	479.561
440.921	473.691
447.158	556.863
453.391	599.21
459.618	446.609
465.84	330.454
472.057	302.266
478.27	318.146
484.477	326.569
490.679	344.316
496.876	368.63
503.068	432.183
509.255	484.652
515.436	509.312
521.613	516.571
527.785	474.486
533.952	439.09
540.113	389.362
546.27	340.995
552.423	335.59
558.568	291.303
564.711	264.507
570.848	262.962
576.979	287.46
583.107	312.78
589.228	328.846
595.345	348.015
601.458	368.599
607.565	418.621
613.667	410.125
619.764	360.659
625.856	304.467
631.944	253.194
638.026	251.344
644.104	262.277
650.177	277.85
656.244	255.584
662.308	210.929
668.365	184.28
674.418	153.4
680.467	143.144
686.511	133
692.549	143.551
698.582	140.125
704.611	135.714
710.635	134.018
716.655	132.044
722.669	134.787
728.679	132.724
734.683	134.359
740.683	138.793
746.678	120.854
752.669	138.463
758.654	135.657
764.635	143.395
770.611	136.308
776.582	130.113
782.549	124.721
788.511	135.246
794.466	139.114
800.419	140.036
806.366	136.135
812.309	135.005
818.247	138.478
824.18	146.574
830.108	140.641
836.033	154.623
841.952	152.045
847.865	172.001
853.776	174.275
859.681	200.168
865.58	227.169
871.476	255.201
877.366	265.97
883.253	285.14
889.134	280.393
895.012	260.313
900.883	257.015
906.751	261.11
912.614	251.942
918.473	275.859
924.326	301.032
930.174	355.776
936.019	424.194
941.859	545.677
947.693	626.515
953.525	667.052
959.35	614.771
965.171	639.25
970.988	789.105
976.801	1006.55
982.608	1148.46
988.411	1009.74
994.209	814.839
1000	700.938
1005.79	691.634
1011.58	807.15
1017.36	916.726
1023.13	788.047
1028.9	624.191
1034.67	503.887
1040.43	464.014
1046.19	416.167
1051.94	361.941
1057.69	344.134
1063.44	323.034
1069.17	329.716
1074.91	388.803
1080.64	476.73
1086.37	653.611
1092.09	938.932
1097.8	924.781
1103.52	667.973
1109.22	520.232
1114.93	446.67
1120.63	416.95
1126.32	456.886
1132.01	545.052
1137.7	660.094
1143.38	902.364
1149.06	1134.94
1154.73	756.69
1160.4	442.362
1166.06	323.658
1171.72	266.187
1177.38	236.284
1183.03	197.813
1188.67	193.854
1194.31	171.505
1199.95	142.432
1205.58	136.011
1211.21	129.619
1216.84	127.207
1222.46	112.893
1228.07	120.43
1233.68	111.904
1239.29	117.318
1244.89	106.464
1250.49	117.675
1256.08	106.583
1261.67	110.505
1267.26	113.38
1272.84	108.145
1278.42	105.901
1283.99	104.68
1289.56	108.525
1295.12	111.438
1300.68	103.432
1306.23	101.532
1311.78	97.7651
1317.33	91.0345
1322.87	98.4254
1328.41	103.887
1333.94	101.236
1339.47	88.3049
1345	98.7482
1350.52	93.8119
1356.04	89.8457
1361.55	101.226
1367.06	110.48
1372.56	105.304
1378.06	109.374
1383.56	103.165
1389.05	106.193
1394.53	93.8959
1400.02	90.9535
1405.5	99.3192
1410.97	92.2791
1416.44	91.4447
1421.91	95.7993
1427.37	99.1578
1432.83	94.211
1438.28	100.71
1443.73	97.8221
1449.17	96.9779
1454.62	98.1389
1460.05	101.332
1465.48	93.9734
1470.91	102.343
1476.34	94.991
1481.76	80.3293
1487.17	100.355
1492.59	98.3776
1497.99	93.2814
1503.4	94.5349
1508.8	105.361
1514.19	93.9829
1519.59	103.878
1524.97	97.8232
1530.36	102.456
1535.74	109.3
1541.11	97.7276
1546.48	102.207
1551.85	102.213
1557.21	103.166
1562.57	103.062
1567.93	98.6441
1573.28	101.771
1578.62	107.105
1583.97	95.2744
1589.3	111.469
1594.64	104.02
1599.97	98.7628
1605.3	105.435
1610.62	104.627
1615.94	107.164
1621.25	111.947
1626.56	106.89
1631.87	114.986
1637.17	109.802
1642.47	107.732
1647.76	112.324
1653.05	108.02
1658.34	106.98
1663.62	105.904
1668.9	119.222
1674.18	105.915
1679.45	110.332
1684.71	114.686
1689.98	109.055
1695.23	96.8569
1700.49	109.168
1705.74	110.827
1710.99	98.7083
1716.23	107.673
1721.47	113.575
1726.7	104.791
1731.94	111.749
1737.16	110.845
1742.39	111.057
1747.61	116.902
1752.82	114.791
1758.03	118.285
1763.24	117.192
1768.44	108.186
1773.64	102.587
1778.84	109.504
1784.03	115.357
1789.22	108.753
1794.41	118.128
1799.59	106.987
1804.76	109.578
1809.94	119.042
1815.11	114.687
1820.27	118.4
1825.43	108.247
1830.59	123.589
1835.74	112.266
1840.89	117.158
1846.04	117.364
1851.18	116.385
1856.32	115.362
1861.45	116.744
1866.58	116.986
1871.71	111.306
1876.83	118.532
1881.95	116.312
1887.07	119.971
1892.18	116.452
1897.29	117.651
1902.39	118.957
1907.49	114.443
1912.59	106.44
1917.68	118.718
1922.77	109.295
1927.86	122.675
1932.94	125.308
1938.02	117.108
1943.09	114.858
1948.16	113.773
1953.23	113.841
1958.29	117.496
1963.35	107.873
1968.41	117.5
1973.46	127.071
1978.51	122.187
1983.55	123.32
1988.59	119.657
1993.63	120.822
1998.66	122.013
2003.69	116.025
2008.72	126.918
2013.74	127.022
2018.76	119.879
2023.77	129.623
2028.78	123.757
2033.79	134.866
2038.79	123.007
2043.79	130.543
2048.79	132.048
2053.78	124.966
2058.77	137.442
2063.76	130.403
2068.74	129.466
2073.72	130.971
2078.69	142.321
2083.66	135.164
2088.63	134.11
2093.59	141.777
2098.55	153.271
2103.51	154.891
2108.46	152.813
2113.41	163.277
2118.36	148.726
2123.3	142.883
2128.24	149.607
2133.17	152.53
2138.11	149.082
2143.03	148.136
2147.96	147.139
2152.88	153.723
2157.79	147.504
2162.71	141.222
2167.62	148.939
2172.52	142.626
2177.43	149.127
2182.32	149.148
2187.22	138.887
2192.11	155.583
2197	156.977
2201.89	145.631
2206.77	147.162
2211.64	144.891
2216.52	142.644
2221.39	143.006
2226.26	147.263
2231.12	141.134
2235.98	145.404
2240.84	144.461
2245.69	143.522
2250.54	134.689
2255.39	157.412
2260.23	140.653
2265.07	147.589
2269.9	130.617
2274.74	140.095
2279.57	141.576
2284.39	150.966
2289.21	145.683
2294.03	140.393
2298.84	139.139
2303.66	148.606
2308.46	135.497
2313.27	147.818
2318.07	145.501
2322.87	168.719
2327.66	152.999
2332.45	139.922
2337.24	151.204
2342.02	138.091
2346.8	152.247
2351.58	151.409
2356.35	155.992
2361.12	139.815
2365.89	149.779
2370.65	157.016
2375.41	144.855
2380.17	140.947
2384.92	149.455
2389.67	146.791
2394.42	151.019
2399.16	138.491
2403.9	144.045
2408.64	146.84
2413.37	151.28
2418.1	147.801
2422.83	138.439
2427.55	159.781
2432.27	151.728
2436.99	149.35
2441.7	144.119
2446.41	158.79
2451.11	154.985
2455.82	156.866
2460.51	153.014
2465.21	167.862
2469.9	139.417
2474.59	155.702
2479.28	163.377
2483.96	162.318
2488.64	158.281
2493.32	164.448
2497.99	169.187
2502.66	156.298
2507.32	160.973
2511.99	153.845
2516.65	165.829
2521.3	149.847
2525.96	169.3
2530.61	172.52
2535.25	174.314
2539.89	173.174
2544.53	158.637
2549.17	163.47
2553.8	159.34
2558.43	168.625
2563.06	164.482
2567.68	151.337
2572.3	174.384
2576.92	171.788
2581.53	167.592
2586.14	167.824
2590.75	164.921
2595.35	181.853
2599.96	165.377
2604.55	173.219
2609.15	184.112
2613.74	165.903
2618.33	192.063
2622.91	181.511
2627.49	183.248
2632.07	182.049
2636.64	182.512
2641.22	195.448
2645.78	183.688
2650.35	188.921
2654.91	195.669
2659.47	186.644
2664.03	186.914
2668.58	195.007
2673.13	192.275
2677.67	189.828
2682.22	193.938
2686.76	201.183
2691.29	190.844
2695.83	197.745
2700.36	185.325
2704.89	193.737
2709.41	202.146
2713.93	202.504
2718.45	202.948
2722.96	196.847
2727.47	184.137
2731.98	203.794
2736.49	197.459
2740.99	191.118
2745.49	183.222
2749.98	198.23
2754.47	198.822
2758.96	195.921
2763.45	201.144
2767.93	201.55
2772.41	211.817
2776.89	187.556
2781.36	198.077
2785.84	200.409
2790.3	199.401
2794.77	193.323
2799.23	195.516
2803.69	197.655
2808.14	191.312
2812.59	205.172
2817.04	197.019
2821.49	195.633
2825.93	197.662
2830.37	201.373
2834.81	191.449
2839.24	193.425
2843.67	198.833
2848.1	202.609
2852.53	192.755
2856.95	193.237
2861.37	192.012
2865.78	204.685
2870.19	193.197
2874.6	197.269
2879.01	187.444
2883.41	203.845
2887.81	204.577
2892.21	219.362
2896.6	204.216
2901	204.975
2905.38	198.498
2909.77	193.727
2914.15	192.384
2918.53	203.585
2922.91	191.506
2927.28	199.257
2931.65	214.318
2936.02	207.6
2940.38	208.003
2944.74	210.202
2949.1	223.249
2953.46	214.451
2957.81	218.406
2962.16	207.746
2966.5	222.754
2970.85	212.139
2975.19	229.1
2979.52	235.06
2983.86	217.101
2988.19	226.916
2992.52	231.264
2996.85	230.066
3001.17	223.318
3005.49	227.825
3009.8	249.279
3014.12	267.044
3018.43	250.955
3022.74	255.644
3027.04	248.77
3031.34	272.333
3035.64	253.746
3039.94	269.594
3044.23	262.432
3048.52	268.667
3052.81	284.554
3057.09	292.81
3061.38	303.007
3065.65	299.662
3069.93	298.243
3074.2	294.883
3078.47	326.635
3082.74	335.054
3087	322.105
3091.27	348.511
3095.52	373.246
3099.78	356.678
3104.03	377.746
3108.28	359.26
3112.53	402.648
3116.77	374.129
3121.01	395.791
3125.25	399.53
3129.49	427.799
3133.72	433.989
3137.95	429.912
3142.18	429.758
3146.4	408.742
3150.62	460.134
3154.84	482.391
3159.06	483.809
3163.27	491.544
3167.48	505.484
3171.69	483.687
3175.89	510.17
3180.09	508.923
3184.29	513.863
3188.49	497.417
3192.68	515.16
3196.87	522.563
3201.06	500.76
3205.24	517.551
3209.42	534.687
3213.6	485.044
3217.78	467.618
3221.95	478.202
3226.12	464.819
3230.29	442.48
3234.45	430.913
3238.61	459.015
3242.77	423.12
3246.93	418.213
3251.08	392.776
3255.23	375.845
3259.38	399.368
3263.53	371.389
3267.67	371.02
3271.81	379.369
3275.95	357.51
3280.08	344.515
3284.21	361.274
3288.34	343.606
3292.47	341.943
3296.59	333.31
3300.71	345.547
3304.83	348.536
3308.95	326.007
3313.06	342.837
3317.17	320.184
3321.27	316.185
3325.38	330.998
3329.48	336.573
3333.58	323.641
3337.67	308.25
3341.77	313.779
3345.86	304.933
3349.95	319.711
3354.03	327.408
3358.11	299.503
3362.19	302.577
3366.27	317.6
3370.34	320.684
3374.42	282.769
3378.48	324.161
3382.55	288.402
3386.61	291.182
3390.68	291.505
3394.73	279.734
3398.79	311.682
3402.84	295.047
3406.89	300.19
3410.94	290.711
3414.98	300.676
3419.03	286.299
3423.06	286.495
3427.1	301.377
3431.14	287.068
3435.17	272.795
3439.2	275.712
3443.22	268.864
3447.25	299.049
3451.27	282.524
3455.28	263.542
3459.3	281.816
3463.31	290.283
3467.32	276.307
3471.33	252.144
3475.34	267.905
3479.34	256.105
3483.34	269.515
3487.33	249.976
3491.33	273.562
3495.32	269.146
3499.31	251.839
3503.3	267.669
3507.28	242.423
3511.26	242.623
3515.24	237.641
3519.22	227.497
3523.19	245.631
3527.16	227.804
3531.13	248.572
3535.1	259.323
3539.06	246.998
3543.02	239.721
3546.98	247.908
3550.93	235.225
3554.89	237.915
3558.84	251.18
3562.78	235.886
3566.73	244.131
3570.67	262.989
3574.61	271.419
3578.55	253.706
3582.48	267.625
3586.41	268.425
3590.35	255.949
3594.27	240.731
3598.2	238.751
3602.12	223.312
3606.04	213.128
3609.95	208.206
3613.87	219.414
3617.78	214.439
3621.69	201.244
3625.6	223.013
3629.5	215.034
3633.4	204.285
3637.3	228.813
3641.2	204.744
3645.09	205.144
3648.98	200.001
3652.87	202.939
3656.76	189.494
3660.64	197.843
3664.53	189.8
3668.4	195.467
3672.28	195.656
3676.16	198.687
3680.03	185.341
3683.9	191.288
3687.76	189.059
3691.63	186.83
3695.49	178.975
3699.35	185.024
3703.2	171.554
3707.06	200.005
3710.91	197.752
3714.76	201.076
3718.6	170.516
3722.45	184.976
3726.29	185.302
3730.13	179.958
3733.97	200.181
3737.8	209.092
3741.63	186.649
3745.46	186.944
3749.29	187.198
3753.11	187.394
3756.93	193.263
3760.75	181.907
3764.57	176.256
3768.39	193.559
3772.2	202.332
3776.01	191.017
3779.81	196.979
3783.62	191.508
3787.42	174.496
3791.22	171.843
3795.02	160.564
3798.81	181.176
3802.61	184.461
3806.4	176.147
3810.18	176.547
3813.97	173.985
3817.75	186.05
3821.53	177.594
3825.31	183.761
3829.09	195.846
3832.86	190.318
3836.63	184.744
3840.4	164.313
3844.17	185.395
3847.93	158.831
3851.69	191.622
3855.45	188.739
3859.21	173.889
3862.96	176.922
3866.71	189.138
3870.46	174.656
3874.21	180.724
3877.95	177.848
3881.69	174.974
3885.44	169.132
3889.17	178.29
3892.91	193.521
3896.64	145.781
3900.37	170.091
3904.1	173.355
3907.82	188.693
3911.55	161.778
3915.27	195.382
3918.99	174.544
3922.7	187.145
3926.42	187.571
3930.13	178.792
3933.84	182.151
3937.54	167.083
3941.25	188.873
3944.95	173.874
3948.65	155.699
3952.35	168.285
3956.04	171.599
3959.73	177.956
3963.42	178.094
3967.11	165.79
3970.8	175.127
3974.48	178.29
3978.16	181.44
3981.84	156.619
3985.52	159.711
3989.19	162.805
3992.86	175.268
3996.53	181.601
3998.37	181.689