File: Data/3-Raman/raw/bu19w-e-ff11b-fi01-v_1800 (450-850nm)_532nm_edge_100%_x100_vis_h50um_30sx2_01.txt
#Acq. time (s)=	30
#Accumulations=	2
#Range (cm-¹)=	1200...2365
#Windows=	3
#Auto scanning=	Off
#Autofocus=	Off
#Macrospot=	Off
#AutoExposure=	Off
#Spike filter=	Multiple accum.
#Delay time (s)=	2
#Binning=	1
#Readout mode=	Signal
#DeNoise=	Off
#ICS correction=	On
#Dark correction=	Off
#Inst. Process=	Off
#Detector Gain=	Best Dynamic
#Detector ADC=	50 kHz HS
#Detector temperature (°C)=	-60.09
#Instrument=	LabRAM HR Evol
#Detector=	SIN-EM FIVIS
#Objective=	x100_VIS
#Grating=	1800 (450-850nm)
#ND Filter=	100%
#Laser=	532nm_Edge
#Hole=	49.98
#Temperature=	0
#Range=	Visible
#StageXY=	75x50mm Scan+
#StageZ=	Z motor
#X (µm)=	0
#Y (µm)=	0
#Z (µm)=	-245.6
#Full time(mm:ss)=	3:23
#Project=	21_11_04
#Sample=	BU19w
#Site=
#Title=	BU19w-E-FF11b-FI01-V_1800 (450-850nm)_532nm_Edge_100%_x100_VIS_H50um_30sX2
#Remark=
#Date=	04.11.2021 18:28
#Acquired=	04.11.2021 18:28:15
1202.73	34.9979
1203.85	37.08
1204.96	34.9126
1206.07	32.7036
1207.18	29.4442
1208.29	35.8349
1209.4	33.6761
1210.51	33.6341
1211.62	28.2549
1212.73	29.2877
1213.84	31.4067
1214.95	35.6635
1216.06	32.4384
1217.17	35.5812
1218.28	33.4282
1219.39	32.3522
1220.5	36.5893
1221.61	34.4362
1222.72	32.257
1223.82	36.4329
1224.93	38.5295
1226.04	37.4825
1227.15	39.5368
1228.25	36.2653
1229.36	38.5078
1230.47	36.3305
1231.57	36.253
1232.68	38.3436
1233.79	32.045
1234.89	36.2652
1236	34.1686
1237.1	29.9339
1238.21	34.0867
1239.31	34.068
1240.42	31.9714
1241.52	38.2496
1242.63	35.1166
1243.74	31.975
1244.84	37.1959
1245.94	35.0665
1247.05	34.0143
1248.15	36.0821
1249.25	37.129
1250.36	35.0163
1251.46	34.9905
1252.56	36.0072
1253.66	36.0106
1254.77	36.0261
1255.87	36.0286
1256.97	36.0319
1258.07	41.2394
1259.18	40.1879
1260.28	36.0057
1261.38	44.358
1262.48	44.3593
1263.58	49.6371
1264.68	39.1921
1265.78	43.363
1266.88	45.4868
1267.98	47.6472
1269.08	40.3407
1270.18	57.0519
1271.28	47.609
1272.38	49.7567
1273.48	47.7118
1274.58	50.8722
1275.68	46.7043
1276.78	40.4379
1277.87	49.9354
1278.97	45.7608
1280.07	53.1134
1281.17	56.3135
1282.26	73.1664
1283.36	167.618
1284.46	103.804
1285.55	52.1244
1286.65	39.4823
1287.75	44.7246
1288.84	35.2666
1289.94	37.398
1291.04	38.4426
1292.13	35.2844
1293.23	36.3558
1294.32	33.2174
1295.42	38.5475
1296.51	34.3516
1297.61	34.3239
1298.7	36.4247
1299.79	40.6489
1300.89	31.147
1301.98	36.443
1303.08	34.3211
1304.17	35.3741
1305.26	35.3512
1306.36	33.22
1307.45	33.2235
1308.54	34.2836
1309.63	32.1881
1310.73	34.2989
1311.82	37.4811
1312.91	36.4214
1314	36.4167
1315.09	33.2652
1316.18	36.4356
1317.28	36.4417
1318.37	31.1658
1319.46	36.4461
1320.55	33.2676
1321.64	32.1782
1322.73	35.32
1323.82	34.2692
1324.91	35.3211
1325.99	36.3012
1327.08	34.232
1328.17	36.3924
1329.26	37.4539
1330.35	32.1615
1331.44	33.1678
1332.53	33.1265
1333.62	34.1367
1334.7	36.2038
1335.79	33.0327
1336.88	36.1625
1337.96	35.0897
1339.05	34.0305
1340.14	29.8473
1341.23	37.1715
1342.31	36.0942
1343.4	33.9897
1344.48	36.0756
1345.57	34.9933
1346.66	33.9
1347.74	31.7896
1348.83	34.897
1349.91	31.7489
1351	35.8811
1352.08	34.8427
1353.17	36.9984
1354.25	33.7671
1355.33	36.874
1356.42	36.8716
1357.5	36.8528
1358.58	36.8254
1359.67	35.7604
1360.75	42.9874
1361.83	34.691
1362.92	38.8327
1364	40.9155
1365.08	35.7125
1366.16	46.0207
1367.24	42.89
1368.33	47.0386
1369.41	47.0382
1370.49	45.9746
1371.57	44.8832
1372.65	49.9917
1373.73	58.2143
1374.81	50.9881
1375.89	60.2604
1376.97	79.7509
1378.05	89.1515
1379.13	96.3773
1380.21	112.672
1381.29	113.596
1382.37	109.296
1383.45	104.061
1384.53	101.026
1385.61	113.457
1386.68	307.608
1387.76	142.643
1388.84	71.3522
1389.92	57.9243
1390.99	55.8546
1392.07	49.6614
1393.15	46.5681
1394.23	41.4396
1395.3	40.4339
1396.38	36.3286
1397.46	39.3782
1398.53	37.3436
1399.61	40.4292
1400.68	41.4731
1401.76	43.5549
1402.83	35.4165
1403.91	41.5515
1404.99	36.4062
1406.06	34.336
1407.13	39.4698
1408.21	46.658
1409.28	42.5703
1410.36	36.393
1411.43	37.3927
1412.5	36.4348
1413.58	34.3485
1414.65	36.4463
1415.72	28.2385
1416.8	34.4151
1417.87	28.2586
1418.94	32.372
1420.01	30.2946
1421.08	33.3569
1422.16	33.4004
1423.23	32.2751
1424.3	31.2617
1425.37	30.2647
1426.44	30.2445
1427.51	31.2314
1428.58	33.2802
1429.65	32.2786
1430.72	30.269
1431.79	28.2165
1432.86	29.2094
1433.93	32.2617
1435	29.2047
1436.07	32.2718
1437.14	27.1416
1438.21	32.2684
1439.28	36.3817
1440.35	32.3014
1441.41	30.2442
1442.48	30.2547
1443.55	32.2908
1444.62	27.1873
1445.69	28.2081
1446.75	29.2252
1447.82	31.2711
1448.89	27.1788
1449.95	29.2148
1451.02	32.2799
1452.09	31.248
1453.15	31.2575
1454.22	27.1551
1455.28	30.231
1456.35	30.2308
1457.41	28.1703
1458.48	29.1986
1459.54	29.199
1460.61	30.213
1461.67	30.1957
1462.74	30.1702
1463.8	27.1101
1464.86	32.1878
1465.93	26.0322
1466.99	32.1366
1468.05	27.0312
1469.12	30.0803
1470.18	31.0778
1471.24	33.0981
1472.31	33.092
1473.37	26.9708
1474.43	31.0429
1475.49	26.9674
1476.55	30.0056
1477.62	24.9138
1478.68	30.9953
1479.74	29.9528
1480.8	29.9286
1481.86	26.8982
1482.92	26.9091
1483.98	26.8897
1485.04	31.8478
1486.1	25.8341
1487.16	31.9083
1488.22	31.8846
1489.28	25.7982
1490.34	30.8481
1491.4	26.7914
1492.46	25.779
1493.52	29.8195
1494.57	28.8099
1495.63	33.8265
1496.69	27.7552
1497.75	28.7622
1498.81	31.7943
1499.86	26.7542
1500.92	33.8107
1501.98	31.7855
1503.03	29.7461
1504.09	25.7157
1505.15	26.713
1506.2	28.711
1507.26	27.7121
1508.32	30.7325
1509.37	27.7107
1510.43	28.708
1511.48	28.6617
1512.54	30.6275
1513.59	28.6239
1514.65	29.6187
1515.7	24.5718
1516.76	28.5747
1517.81	26.5777
1518.86	28.5918
1519.92	26.5835
1520.97	28.5969
1522.02	27.5854
1523.08	27.5622
1524.13	28.5391
1525.18	28.5456
1526.24	25.5603
1527.29	26.5563
1528.34	29.5512
1529.39	31.5464
1530.44	31.5565
1531.5	28.5573
1532.55	34.5858
1533.6	28.5901
1534.65	31.5905
1535.7	27.5475
1536.75	27.5145
1537.8	30.4952
1538.85	29.5041
1539.9	30.5704
1540.95	28.5695
1542	27.5407
1543.05	33.5171
1544.1	30.5077
1545.15	32.5459
1546.2	28.5481
1547.25	30.561
1548.29	30.5533
1549.34	30.4941
1550.39	34.6602
1551.44	32.6164
1552.49	31.6348
1553.53	33.5995
1554.58	31.5574
1555.63	31.5579
1556.68	31.5554
1557.72	33.545
1558.77	32.5063
1559.82	27.4863
1560.86	34.4771
1561.91	30.5046
1562.95	29.5005
1564	32.524
1565.04	32.4002
1566.09	32.4917
1567.13	27.5127
1568.18	34.4981
1569.22	33.4762
1570.27	29.4825
1571.31	36.4631
1572.36	32.4512
1573.4	33.4329
1574.44	33.4604
1575.49	33.4777
1576.53	25.4652
1577.57	32.4119
1578.62	35.3907
1579.66	33.4055
1580.7	33.3984
1581.74	33.3768
1582.79	39.3448
1583.83	35.3576
1584.87	34.3647
1585.91	29.3688
1586.95	31.3424
1587.99	38.3101
1589.03	33.3516
1590.07	35.3501
1591.12	37.344
1592.16	36.3181
1593.2	39.254
1594.24	40.2286
1595.28	37.2507
1596.32	36.2534
1597.35	37.2561
1598.39	38.2221
1599.43	39.1869
1600.47	38.1625
1601.51	40.0979
1602.55	39.0739
1603.59	34.1109
1604.63	38.0681
1605.66	43.0258
1606.7	40.074
1607.74	41.3601
1608.78	39.8906
1609.81	38.9135
1610.85	45.2012
1611.89	43.206
1612.92	43.0122
1613.96	40.6078
1615	46.2499
1616.03	47.1213
1617.07	43.7681
1618.1	46.8308
1619.14	50.4783
1620.17	48.083
1621.21	48.3394
1622.24	52.4813
1623.28	47.404
1624.31	50.5816
1625.35	50.4526
1626.38	52.8801
1627.41	54.5873
1628.45	54.021
1629.48	54.8502
1630.51	54.3344
1631.3	49.7585
1632.34	57.6913
1633.39	56.6614
1634.43	56.677
1635.48	58.6334
1636.52	55.648
1637.57	51.6873
1638.61	56.6005
1639.66	53.6446
1640.7	58.5909
1641.75	46.7605
1642.79	57.5812
1643.83	58.5463
1644.88	53.6273
1645.92	54.6066
1646.96	50.6516
1648.01	52.6224
1649.05	58.574
1650.09	51.704
1651.13	62.5752
1652.18	60.6043
1653.22	53.698
1654.26	55.6848
1655.3	58.6976
1656.34	55.7725
1657.38	56.7449
1658.42	57.706
1659.47	55.6969
1660.51	54.7385
1661.55	52.8039
1662.59	49.915
1663.63	53.7888
1664.67	52.8681
1665.71	49.9404
1666.75	54.7915
1667.79	50.8084
1668.83	49.8798
1669.86	43.9492
1670.9	53.8671
1671.94	48.9312
1672.98	46.9576
1674.02	47.9675
1675.06	49.975
1676.1	48.0008
1677.13	41.0689
1678.17	48.9506
1679.21	42.0093
1680.25	46.9338
1681.28	40.9983
1682.32	43.9622
1683.35	44.9473
1684.39	39.0067
1685.43	39.0047
1686.46	40.9968
1687.5	42.9618
1688.54	38.9899
1689.57	40.9329
1690.6	40.9473
1691.64	40.9588
1692.68	40.9351
1693.71	38.9243
1694.74	38.9104
1695.78	35.9665
1696.81	42.859
1697.85	39.8667
1698.88	39.8499
1699.92	36.8957
1700.95	35.9028
1701.98	39.8086
1703.01	34.8816
1704.05	34.8831
1705.08	39.794
1706.11	38.7898
1707.14	33.8467
1708.18	31.8426
1709.21	35.7319
1710.24	37.6931
1711.27	31.8328
1712.3	35.7255
1713.33	31.7591
1714.36	34.6737
1715.4	37.6181
1716.43	31.734
1717.46	31.6797
1718.49	35.5391
1719.52	30.6691
1720.55	30.656
1721.58	34.5176
1722.61	33.5126
1723.64	32.5282
1724.66	30.5611
1725.69	34.4019
1726.72	31.4803
1727.75	36.3216
1728.78	30.3933
1729.81	31.3866
1730.83	27.5434
1731.86	25.6073
1732.89	31.3823
1733.92	29.4084
1734.95	31.297
1735.97	30.3166
1737	30.2999
1738.03	35.0845
1739.05	29.2856
1740.08	28.2799
1741.1	28.2542
1742.13	31.1144
1743.16	29.1915
1744.18	29.1732
1745.21	29.1727
1746.23	30.1037
1747.26	29.1191
1748.28	23.3877
1749.31	28.1756
1750.33	32.0217
1751.36	27.2368
1752.38	32.9383
1753.4	29.0973
1754.43	29.0758
1755.45	30.0109
1756.47	28.0734
1757.5	29.9604
1758.52	26.1679
1759.54	30.9257
1760.57	29.9612
1761.59	26.1411
1762.61	28.05
1763.63	28.0541
1764.66	29.9831
1765.68	30.9423
1766.7	30.9368
1767.72	28.0681
1768.74	28.9884
1769.76	25.1679
1770.78	27.0844
1771.8	29.0076
1772.82	28.0743
1773.84	25.2286
1774.86	27.1446
1775.88	25.2635
1776.9	27.1587
1777.92	26.1873
1778.94	28.066
1779.96	23.3183
1780.98	26.1809
1782	26.1972
1783.02	28.1179
1784.04	29.0921
1785.05	26.2374
1786.07	25.28
1787.09	28.1696
1788.11	27.2807
1789.12	25.3936
1790.14	27.3227
1791.16	26.3389
1792.18	26.3384
1793.19	26.3453
1794.21	28.2631
1795.23	25.4359
1796.24	26.4155
1797.26	30.2798
1798.27	26.4433
1799.29	27.3918
1800.3	24.4951
1801.32	27.3752
1802.33	26.427
1803.35	25.4846
1804.36	29.3478
1805.38	25.5234
1806.39	29.3939
1807.41	26.505
1808.42	28.4362
1809.43	26.513
1810.45	28.4406
1811.46	26.5115
1812.47	26.524
1813.49	27.5044
1814.5	23.6706
1815.51	27.5457
1816.53	28.5169
1817.54	24.6276
1818.55	23.6759
1819.56	28.5196
1820.57	26.5987
1821.58	25.6465
1822.6	27.5902
1823.61	28.5519
1824.62	26.626
1825.63	27.6006
1826.64	27.6044
1827.65	24.7074
1828.66	23.7299
1829.67	27.5979
1830.68	35.3399
1831.69	29.5468
1832.7	26.6552
1833.71	25.6918
1834.72	28.5532
1835.73	31.4308
1836.74	26.6517
1837.75	26.5736
1838.75	23.735
1839.76	27.6064
1840.77	27.5406
1841.78	26.5325
1842.79	30.3854
1843.79	26.5244
1844.8	19.7732
1845.81	27.523
1846.81	28.4128
1847.82	25.5334
1848.83	24.5486
1849.83	25.4792
1850.84	21.6121
1851.85	27.3665
1852.85	25.4443
1853.86	26.3817
1854.86	27.3171
1855.87	24.4243
1856.87	24.4215
1857.88	27.2789
1858.88	26.2967
1859.89	25.3357
1860.89	22.4833
1861.9	24.399
1862.9	27.2446
1863.9	27.2236
1864.91	25.29
1865.91	24.2981
1866.92	27.1123
1867.92	29.9454
1868.92	22.3407
1869.92	24.2368
1870.93	26.1341
1871.93	27.071
1872.93	23.2582
1873.93	27.0394
1874.93	25.1155
1875.94	31.6996
1876.94	23.1499
1877.94	24.1476
1878.94	24.1579
1879.94	26.9826
1880.94	26.0255
1881.94	23.1378
1882.94	25.1196
1883.94	28.7593
1884.94	25.9459
1885.94	24.0836
1886.94	26.8925
1887.94	23.0914
1888.94	24.0052
1889.94	24.9516
1890.94	29.6662
1891.94	24.9537
1892.94	25.8644
1893.93	24.9024
1894.93	23.0186
1895.93	27.7305
1896.93	26.8074
1897.93	27.7455
1898.92	26.7822
1899.92	24.8927
1900.92	23.9653
1901.91	23.0459
1902.91	27.742
1903.91	26.7954
1904.9	26.7918
1905.9	22.0739
1906.9	25.8233
1907.89	25.8359
1908.89	30.5489
1909.88	27.7632
1910.88	24.9613
1911.87	27.785
1912.87	26.8435
1913.86	23.0989
1914.86	27.8351
1915.85	23.1158
1916.85	26.8724
1917.84	29.7001
1918.84	30.6771
1919.83	28.8203
1920.82	28.8333
1921.82	25.063
1922.81	26.9425
1923.8	28.8197
1924.79	22.2047
1925.79	26.0117
1926.78	25.0907
1927.77	23.209
1928.76	29.855
1929.75	27.0412
1930.75	26.1101
1931.74	27.9967
1932.73	25.1381
1933.72	26.1228
1934.71	30.9693
1935.7	25.2563
1936.69	29.0515
1937.68	27.1248
1938.67	29.0449
1939.66	30.9663
1940.65	27.1959
1941.64	23.3575
1942.63	28.1688
1943.62	28.1502
1944.61	26.2679
1945.6	31.0728
1946.59	26.3017
1947.58	30.121
1948.57	26.2995
1949.55	31.1104
1950.54	24.4494
1951.53	25.4425
1952.52	27.3757
1953.5	27.351
1954.49	28.261
1955.48	25.4053
1956.47	27.365
1957.45	28.348
1958.44	33.1593
1959.43	28.3406
1960.41	31.2024
1961.4	27.3507
1962.38	25.4364
1963.37	29.281
1964.36	29.286
1965.34	26.4079
1966.33	28.3515
1967.31	27.3965
1968.3	28.3583
1969.28	30.2502
1970.26	27.3477
1971.25	29.2538
1972.23	25.4228
1973.22	30.2007
1974.2	25.4002
1975.18	25.4102
1976.17	27.3383
1977.15	29.2519
1978.13	26.36
1979.12	29.2349
1980.1	24.438
1981.08	26.3413
1982.06	25.3765
1983.05	22.4833
1984.03	29.1697
1985.01	25.3282
1985.99	30.1176
1986.97	30.1185
1987.95	31.0311
1988.93	29.051
1989.91	26.1674
1990.89	32.4393
1991.88	29.901
1992.86	28.1116
1993.84	31.0565
1994.82	29.1765
1995.8	28.6974
1996.78	30.208
1997.76	27.6001
1998.73	28.3405
1999.71	27.7054
2000.69	27.4142
2001.67	31.1885
2002.65	28.5687
2003.63	28.0467
2004.6	27.8851
2005.58	28.0936
2006.56	29.3841
2007.54	28.0406
2008.52	25.1461
2009.49	29.3202
2010.47	26.721
2011.45	25.5832
2012.42	27.7711
2013.41	28.6699
2014.4	28.6225
2015.39	30.5139
2016.38	27.7269
2017.37	25.829
2018.35	30.4784
2019.34	28.5702
2020.33	28.5643
2021.32	30.4402
2022.31	31.3569
2023.29	32.2624
2024.28	26.623
2025.27	30.322
2026.25	29.4069
2027.24	28.5362
2028.23	28.4749
2029.21	32.2612
2030.2	29.3554
2031.19	26.5921
2032.17	30.3541
2033.16	34.1278
2034.14	30.3292
2035.13	29.4216
2036.11	25.7078
2037.1	29.4531
2038.08	30.3728
2039.07	28.4848
2040.05	29.3883
2041.03	28.4342
2042.02	25.6249
2043	24.6977
2043.99	28.4546
2044.97	31.2323
2045.95	27.5884
2046.94	29.3956
2047.92	29.3664
2048.9	29.3851
2049.88	24.7512
2050.87	25.6862
2051.85	30.3509
2052.83	30.3672
2053.81	27.5945
2054.79	34.1405
2055.78	33.1885
2056.76	28.5097
2057.74	27.5888
2058.72	32.2939
2059.7	28.5514
2060.68	29.4868
2061.66	29.4937
2062.64	32.3189
2063.62	27.65
2064.6	27.6655
2065.58	31.4508
2066.56	28.647
2067.54	30.542
2068.52	33.3741
2069.5	26.7654
2070.48	29.6266
2071.46	31.5482
2072.43	32.483
2073.41	28.7173
2074.39	28.7348
2075.37	35.3902
2076.35	28.791
2077.32	31.5906
2078.3	32.5503
2079.28	27.8628
2080.26	28.8231
2081.23	25.9827
2082.21	32.6022
2083.19	33.5452
2084.16	26.9314
2085.14	32.6034
2086.12	26.9571
2087.09	33.5958
2088.07	33.5993
2089.04	33.6138
2090.02	31.7367
2090.99	29.855
2091.97	28.9417
2092.94	29.9256
2093.92	32.8006
2094.89	30.8916
2095.87	28.9754
2096.84	32.7629
2097.81	28.9529
2098.79	30.8444
2099.76	31.7926
2100.74	29.9127
2101.71	27.0693
2102.68	30.8566
2103.65	32.7489
2104.63	31.8166
2105.6	33.7409
2106.57	31.8499
2107.54	29.9347
2108.52	32.7568
2109.49	28.9742
2110.46	34.6745
2111.43	30.8653
2112.4	28.9697
2113.38	31.8412
2114.35	30.8873
2115.32	28.9818
2116.29	31.8144
2117.26	31.8102
2118.23	28.9367
2119.2	28.9115
2120.17	33.6381
2121.14	31.7658
2122.11	29.8934
2123.08	32.7539
2124.05	30.8378
2125.02	30.7863
2125.98	31.6989
2126.95	31.6752
2127.92	30.7209
2128.89	26.9375
2129.86	33.5464
2130.83	29.7538
2131.79	30.6829
2132.76	28.7797
2133.73	30.6711
2134.7	31.6141
2135.67	26.8802
2136.63	33.4684
2137.6	31.593
2138.57	29.7047
2139.53	24.0288
2140.5	28.7266
2141.46	29.6545
2142.43	31.5444
2143.4	29.5966
2144.36	31.5125
2145.33	27.7371
2146.29	29.6079
2147.26	33.3513
2148.22	30.5187
2149.19	27.6745
2150.15	28.588
2151.12	32.3474
2152.08	28.6047
2153.05	29.5253
2154.01	29.5018
2154.97	35.0642
2155.94	25.6907
2156.9	30.3614
2157.86	26.6396
2158.83	26.6333
2159.79	31.2791
2160.75	28.4607
2161.72	28.454
2162.68	29.3807
2163.64	29.3678
2164.6	31.2122
2165.56	25.6264
2166.53	29.338
2167.49	31.1658
2168.45	29.2857
2169.41	26.5215
2170.37	28.403
2171.33	29.2961
2172.29	30.1971
2173.25	31.1258
2174.21	29.2765
2175.17	29.2724
2176.13	26.4762
2177.09	27.4046
2178.05	23.6813
2179.01	30.1761
2179.97	32.9613
2180.93	30.1696
2181.89	31.0851
2182.85	30.1399
2183.81	28.2611
2184.76	30.1189
2185.72	28.2812
2186.68	27.3827
2187.64	32.0414
2188.6	22.7357
2189.55	27.3473
2190.51	28.2785
2191.47	29.2124
2192.42	24.5859
2193.38	23.6809
2194.34	29.2843
2195.3	27.4092
2196.25	31.0883
2197.21	26.4339
2198.16	29.2347
2199.12	25.5549
2200.07	28.3948
2201.03	30.2787
2201.99	27.3676
2202.94	27.4297
2203.9	23.7751
2204.85	23.7268
2205.8	28.3622
2206.76	27.4296
2207.71	27.4527
2208.67	25.6089
2209.62	26.5424
2210.58	26.5588
2211.53	26.5795
2212.48	25.6499
2213.44	29.3689
2214.39	29.4025
2215.34	26.6092
2216.29	26.6078
2217.25	26.6091
2218.2	25.6789
2219.15	26.6301
2220.1	25.7006
2221.06	21.9493
2222.01	29.4041
2222.96	27.5518
2223.91	23.8433
2224.86	26.6741
2225.81	25.7633
2226.76	27.6581
2227.72	27.6621
2228.67	27.6557
2229.62	27.6739
2230.57	25.8189
2231.52	26.782
2232.47	23.0415
2233.42	28.7053
2234.37	25.8798
2235.31	24.9194
2236.26	24.9249
2237.21	28.7119
2238.16	26.8666
2239.11	29.7167
2240.06	25.9234
2241.01	25.9478
2241.96	25.0133
2242.9	28.7902
2243.85	25.0085
2244.8	25.0388
2245.75	27.8985
2246.69	24.1305
2247.64	30.7588
2248.59	28.8598
2249.53	23.1887
2250.48	26.0096
2251.43	27.891
2252.37	26.9664
2253.32	27.0073
2254.26	26.0752
2255.21	27.0238
2256.16	27.0397
2257.1	21.3617
2258.05	25.1674
2258.99	27.0807
2259.94	24.2406
2260.88	28.0655
2261.83	26.1712
2262.77	27.1459
2263.71	24.3238
2264.66	28.1717
2265.6	28.1786
2266.55	28.1537
2267.49	24.3199
2268.43	26.225
2269.38	24.3439
2270.32	28.1919
2271.26	28.2116
2272.2	27.2664
2273.15	27.2732
2274.09	26.3225
2275.03	24.4151
2275.97	24.4298
2276.92	23.4952
2277.86	24.4889
2278.8	24.4901
2279.74	25.421
2280.68	23.4868
2281.62	27.3199
2282.56	27.3424
2283.5	24.5029
2284.44	23.5693
2285.38	23.5753
2286.32	25.4926
2287.26	27.4488
2288.2	22.6332
2289.14	24.5316
2290.08	27.3983
2291.02	25.495
2291.96	23.5898
2292.9	24.5733
2293.84	22.6469
2294.78	26.4856
2295.72	28.396
2296.65	25.5002
2297.59	21.674
2298.53	28.4414
2299.47	21.7042
2300.41	24.6052
2301.34	26.5451
2302.28	25.5762
2303.22	26.5397
2304.15	21.7266
2305.09	22.7044
2306.03	24.6468
2306.97	25.6117
2307.9	22.7036
2308.84	27.5443
2309.77	22.7332
2310.71	23.6943
2311.64	24.6159
2312.58	22.6745
2313.51	27.5294
2314.45	25.6324
2315.39	18.8527
2316.32	25.5886
2317.25	18.8353
2318.19	22.6904
2319.12	24.6074
2320.06	23.6415
2320.99	21.7245
2321.92	23.6816
2322.86	27.5542
2323.79	23.6907
2324.72	26.5676
2325.66	28.4757
2326.59	26.5224
2327.52	30.3601
2328.46	38.0675
2329.39	28.4126
2330.32	28.41
2331.25	24.5659
2332.18	29.3734
2333.12	25.5083
2334.05	21.6444
2334.98	24.5215
2335.91	24.5214
2336.84	23.5552
2337.77	26.4335
2338.7	22.5884
2339.63	23.5448
2340.56	23.5257
2341.49	23.4978
2342.42	25.4034
2343.35	25.4013
2344.28	22.5281
2345.21	25.39
2346.14	21.5463
2347.07	26.3284
2348	19.6324
2348.93	24.4059
2349.85	24.3519
2350.78	27.2444
2351.71	26.247
2352.64	24.2899
2353.57	25.2402
2354.5	22.3929
2355.42	23.3378
2356.35	24.258
2357.28	20.4387
2358.21	23.2782
2359.13	25.17
2360.06	22.302
2360.99	20.3846
2361.91	25.0986
2362.84	22.2401
2363.77	21.2835
2364.69	24.1072
2364.92	25.0486