File: Data/3-Raman/raw/bu19w-ff2-fi03-v_150 (500nm)_532nm_edge_100%_x100_vis_h50um_15sx2_03.txt
#Acq. time (s)=	15
#Accumulations=	2
#Range (cm-¹)=	100...5000
#Windows=	1
#Auto scanning=	Off
#Autofocus=	Off
#Macrospot=	Off
#AutoExposure=	Off
#Spike filter=	Multiple accum.
#Delay time (s)=	2
#Binning=	1
#Readout mode=	Signal
#DeNoise=	Off
#ICS correction=	On
#Dark correction=	Off
#Inst. Process=	Off
#Detector Gain=	Best Dynamic
#Detector ADC=	50 kHz HS
#Detector temperature (°C)=	-60.09
#Instrument=	LabRAM HR Evol
#Detector=	SIN-EM FIVIS
#Objective=	x100_VIS
#Grating=	150 (500nm)
#ND Filter=	100%
#Laser=	532nm_Edge
#Hole=	49.98
#Temperature=	0
#Range=	Visible
#StageXY=	75x50mm Scan+
#StageZ=	Z motor
#X (µm)=	0
#Y (µm)=	0
#Z (µm)=	-214.6
#Full time(s)=	38
#Project=	21_05_14
#Sample=	BU19w
#Site=
#Title=	BU19w-FF2-FI03-V_150 (500nm)_532nm_Edge_100%_x100_VIS_H50um_15sX2
#Remark=
#Date=	14.05.2021 17:30
#Acquired=	14.05.2021 17:30:18
102.699	1400.32
107.322	1345.45
111.942	1264.65
116.56	1212.48
121.173	1173.83
125.787	1141.97
130.398	1098.4
135.006	1084.56
139.613	976.277
144.215	993.601
148.817	1053.81
153.417	1273.58
158.014	1625.58
162.607	1395.57
167.2	1015.36
171.79	898.755
176.379	918.157
180.963	1096.68
185.547	1428.13
190.128	1360.86
194.705	1081.97
199.282	859.359
203.857	815.253
208.43	812.748
212.998	829.825
217.566	802.876
222.132	794.255
226.693	924.815
231.254	1096.63
235.813	1137.64
240.368	1383.27
244.923	1665.09
249.475	1290.72
254.023	1007.17
258.571	910.137
263.117	927.555
267.658	1136.68
272.199	1857.31
276.738	2795.1
281.273	2388.51
285.807	1502.12
290.34	1164.23
294.868	1025.99
299.396	1088.36
303.919	1140.84
308.443	1013.28
312.964	954.963
317.481	999.374
321.998	1244.9
326.51	1494.29
331.023	1380.34
335.533	1192.42
340.039	1251.65
344.544	1588.73
349.046	1755.9
353.547	1519.66
358.045	1171.23
362.542	1105.55
367.036	1191.14
371.527	1130.45
376.017	928.051
380.503	914.585
384.99	928.594
389.471	1034.9
393.953	1058.22
398.43	954.093
402.908	850.25
407.381	845.754
411.854	1039.81
416.323	1253.02
420.791	1055.8
425.256	836.159
429.72	754.187
434.18	748.74
438.64	722.469
443.095	743.23
447.551	758.061
452.003	826.295
456.454	813.548
460.901	823.069
465.348	789.862
469.791	800.372
474.231	792.028
478.672	867.938
483.108	964.592
487.544	1082.6
491.976	1117.46
496.408	1152.74
500.836	1027.77
505.261	918.868
509.687	881.537
514.108	822.369
518.529	809.483
522.946	771.594
527.361	756.845
531.776	770.095
536.187	779.939
540.595	797.895
545.003	840.199
549.408	828.044
553.812	836.415
558.212	840.122
562.61	825.037
567.007	793.988
571.401	794.246
575.792	836.126
580.184	914.739
584.571	1116.5
588.956	1326.74
593.341	1155.48
597.722	926.374
602.101	961.91
606.48	1060.67
610.854	1136.91
615.227	970.083
619.597	825.798
623.967	767.58
628.334	754.816
632.698	791.21
637.06	825.791
641.422	843.269
645.779	822.567
650.135	830.159
654.491	887.805
658.842	1003.82
663.192	1109.16
667.539	1149.25
671.884	1162.75
676.23	1188.45
680.571	1073.64
684.91	886.69
689.247	787.102
693.583	724.37
697.916	690.584
702.247	663.917
706.576	663.02
710.902	654.709
715.229	658.297
719.551	699.299
723.872	669.992
728.19	667.049
732.506	667.996
736.82	697.531
741.134	681.37
745.444	686.148
749.752	706.621
754.058	720.435
758.362	793.614
762.664	822.809
766.964	908.269
771.264	1098.71
775.559	1312.02
779.853	1253.52
784.144	1079.08
788.434	941.147
792.722	865.729
797.007	831.443
801.29	817.689
805.572	786.768
809.851	766.986
814.13	731.986
818.406	709.018
822.679	734.661
826.95	714.177
831.219	736.685
835.486	752.559
839.752	789.352
844.015	834.837
848.276	883.01
852.535	825.222
856.792	750.968
861.047	740.592
865.3	717.867
869.551	723.609
873.8	685.238
878.047	691.782
882.292	681.632
886.534	698.483
890.775	697.2
895.014	700.9
899.251	700.387
903.486	691.762
907.719	725.08
911.95	725.293
916.179	718.863
920.406	709.239
924.63	734.172
928.853	725.716
933.074	797.859
937.293	795.602
941.51	857.444
945.723	939.199
949.936	984.722
954.147	971.661
958.356	913.033
962.563	890.776
966.768	869.692
970.971	877.502
975.172	835.561
979.371	822.479
983.568	822.166
987.761	829.115
991.954	805.909
996.145	806.64
1000.33	836.233
1004.52	818.211
1008.71	814.15
1012.89	835.333
1017.07	850.153
1021.25	855.364
1025.43	885.727
1029.6	893.705
1033.77	895.43
1037.95	948.501
1042.11	1081.39
1046.28	1345.25
1050.45	1685.31
1054.61	1656.08
1058.77	1402.73
1062.93	1143.84
1067.09	1037.57
1071.24	1053.04
1075.4	1079.05
1079.55	1191.66
1083.7	1449.57
1087.85	1757.65
1091.99	1790.45
1096.14	1639.19
1100.28	1520.64
1104.42	1630.62
1108.55	1811.3
1112.69	1694.11
1116.82	1537.71
1120.96	1476.26
1125.09	1499.75
1129.21	1540.6
1133.34	1586.37
1137.46	1411.03
1141.59	1252.11
1145.71	1140.89
1149.83	1205.03
1153.94	1335.63
1158.06	1344.39
1162.17	1203.96
1166.28	1172.73
1170.39	1082.29
1174.5	977.279
1178.6	887.836
1182.7	833.498
1186.8	846.437
1190.9	809.894
1195	799.827
1199.1	828.271
1203.19	781.222
1207.28	802.358
1211.37	792.098
1215.46	861.565
1219.54	904.696
1223.63	929.633
1227.71	891.767
1231.79	854.37
1235.87	882.081
1239.95	935.362
1244.02	904.862
1248.09	796.16
1252.16	805.451
1256.23	819.892
1260.3	797.476
1264.36	762.142
1268.43	881.221
1272.49	1023.66
1276.55	868.131
1280.6	752.423
1284.66	748.958
1288.71	724.322
1292.76	741.79
1296.81	715.911
1300.86	731.211
1304.91	727.233
1308.95	750.501
1312.99	735.208
1317.03	748.886
1321.07	722.196
1325.11	731.347
1329.14	745.65
1333.18	755.601
1337.21	738.326
1341.24	735.011
1345.26	726.669
1349.29	761.19
1353.31	742.933
1357.33	740.615
1361.35	729.372
1365.37	738.16
1369.39	771.685
1373.4	1014.45
1377.41	1153.32
1381.43	868.957
1385.43	771.266
1389.44	777.044
1393.45	743.783
1397.45	758.907
1401.45	740.38
1405.45	726.862
1409.45	772.558
1413.44	776.916
1417.44	760.528
1421.43	755.93
1425.42	813.291
1429.41	844.7
1433.39	891.14
1437.38	898.929
1441.36	911.681
1445.34	896.602
1449.32	880.518
1453.3	828.762
1457.27	815.433
1461.24	798.929
1465.22	747.868
1469.19	776.571
1473.15	745.374
1477.12	745.451
1481.09	736.673
1485.05	762.08
1489.01	747.387
1492.97	747.424
1496.93	743.588
1500.88	742.809
1504.83	727.618
1508.79	722.314
1512.74	742.263
1516.68	742.859
1520.63	738.674
1524.57	759.748
1528.52	714.001
1532.46	750.723
1536.4	750.608
1540.33	711.755
1544.27	742.668
1548.2	764.86
1552.14	732.755
1556.07	759.612
1559.99	770.865
1563.92	753.011
1567.84	774.743
1571.77	734.594
1575.69	763.985
1579.61	744.111
1583.52	772.42
1587.44	765.005
1591.35	732.585
1595.27	774.224
1599.18	768.77
1603.09	739.434
1606.99	783.102
1610.9	777.849
1614.8	763.119
1618.7	767.589
1622.6	754.834
1626.5	752.764
1630.39	756.593
1634.29	762.469
1638.18	790.393
1642.07	748.656
1645.96	745.302
1649.85	768.852
1653.73	771.297
1657.62	764.076
1661.5	782.711
1665.38	748.351
1669.26	750.364
1673.13	764.708
1677.01	754.822
1680.88	764.749
1684.75	758.277
1688.62	745.957
1692.49	781.371
1696.35	768.797
1700.22	763.74
1704.08	790.913
1707.94	796.905
1711.8	834.094
1715.66	823.852
1719.51	840.123
1723.37	835.56
1727.22	843.123
1731.07	853.437
1734.92	858.091
1738.76	813.088
1742.61	828.851
1746.45	847.65
1750.29	817.622
1754.13	824.202
1757.97	840.121
1761.81	814.669
1765.64	787.932
1769.47	811.856
1773.31	801.562
1777.14	799.758
1780.96	790.714
1784.79	795.744
1788.61	795.235
1792.43	780.68
1796.25	813.969
1800.07	796.248
1803.89	792.303
1807.71	843.923
1811.52	815.322
1815.33	814.723
1819.14	791.183
1822.95	803.338
1826.76	818.128
1830.56	794.035
1834.37	815.957
1838.17	810.431
1841.97	840.456
1845.77	824.396
1849.56	855.079
1853.36	820.779
1857.15	816.262
1860.94	860.02
1864.73	826.482
1868.52	850.674
1872.31	843.443
1876.09	864.989
1879.87	847.037
1883.66	861.565
1887.43	849.94
1891.21	840.654
1894.99	846.03
1898.76	820.346
1902.53	840.942
1906.31	869.948
1910.08	871.563
1913.84	842.913
1917.61	849.635
1921.37	840.947
1925.14	906.506
1928.9	859.076
1932.66	851.506
1936.41	853.201
1940.17	869.834
1943.92	863.289
1947.68	875.663
1951.43	879.278
1955.18	859.945
1958.92	916.242
1962.67	890.742
1966.41	912.095
1970.16	901.06
1973.9	887.997
1977.64	902.862
1981.37	876.425
1985.11	901.242
1988.84	896.089
1992.57	944.686
1996.31	926.101
2000.03	947.302
2003.76	919.548
2007.49	922.937
2011.21	921.666
2014.93	930.74
2018.65	939.502
2022.37	934.915
2026.09	941.832
2029.81	922.937
2033.52	941.554
2037.23	935.192
2040.94	905.994
2044.65	961.807
2048.36	934.505
2052.07	930.214
2055.77	970.072
2059.47	963.993
2063.17	939.84
2066.87	956.226
2070.57	950.562
2074.27	971.698
2077.96	1010.61
2081.65	1012.53
2085.34	998.054
2089.03	985.024
2092.72	995.726
2096.41	975.953
2100.09	1016.12
2103.77	1002.19
2107.46	1014.12
2111.14	1000.84
2114.81	1022.87
2118.49	1040.84
2122.16	1027.76
2125.84	1014.62
2129.51	1020.77
2133.18	1022.26
2136.85	1049.45
2140.51	1028.42
2144.18	1049.7
2147.84	1067.2
2151.5	1076.4
2155.16	1069.15
2158.82	1082.09
2162.48	1049.54
2166.13	1041.86
2169.79	1055.45
2173.44	1067.64
2177.09	1090.82
2180.74	1074.04
2184.38	1080.03
2188.03	1074.7
2191.67	1090.67
2195.32	1100.7
2198.96	1083.49
2202.6	1102
2206.23	1091.5
2209.87	1132.38
2213.5	1109.34
2217.14	1126.64
2220.77	1131.16
2224.4	1144.91
2228.03	1261.9
2231.65	1283.33
2235.28	1431.6
2238.9	1546.91
2242.52	1515.93
2246.14	1407.69
2249.76	1303.9
2253.38	1260.51
2256.99	1196.45
2260.6	1193.82
2264.21	1183.64
2267.82	1168.07
2271.44	1156.18
2275.04	1184.31
2278.65	1188.46
2282.25	1169.36
2285.85	1207.18
2289.45	1206.07
2293.05	1185.04
2296.65	1219.92
2300.25	1202.65
2303.84	1195.51
2307.43	1206.16
2311.02	1211.92
2314.62	1225.05
2318.2	1300.46
2321.79	1288.14
2325.38	1239.32
2328.96	1231.29
2332.54	1259.81
2336.12	1269.29
2339.7	1245.64
2343.28	1251.99
2346.85	1249.73
2350.43	1263.34
2354	1275.88
2357.57	1277.1
2361.14	1303.37
2364.71	1285.04
2368.27	1286.44
2371.84	1304.63
2375.4	1312.47
2378.96	1351.79
2382.52	1332.23
2386.08	1334.04
2389.64	1324.18
2393.19	1277.98
2396.75	1328.54
2400.3	1334.74
2403.85	1330.44
2407.4	1329.14
2410.95	1371.52
2414.49	1362.78
2418.04	1324.9
2421.58	1351.61
2425.12	1329.88
2428.66	1349.95
2432.2	1416.69
2435.74	1381.83
2439.27	1333.88
2442.81	1399.56
2446.34	1364.73
2449.87	1378.78
2453.4	1429.16
2456.93	1373.04
2460.45	1408.49
2463.98	1422.73
2467.5	1442.47
2471.02	1389.25
2474.54	1429.49
2478.06	1429.66
2481.58	1440.87
2485.09	1435.25
2488.61	1426.81
2492.12	1465.48
2495.63	1438.05
2499.14	1443.68
2502.65	1489.85
2506.15	1456.38
2509.66	1464.8
2513.16	1479.06
2516.66	1475.04
2520.16	1472.18
2523.66	1523.76
2527.16	1492.81
2530.66	1499.04
2534.15	1489.08
2537.64	1491.42
2541.13	1488.85
2544.62	1481.54
2548.11	1501.14
2551.6	1545.05
2555.08	1519.57
2558.57	1532.97
2562.05	1497.76
2565.53	1523.46
2569.01	1549.71
2572.49	1497.76
2575.96	1532.24
2579.44	1541.62
2582.91	1505.77
2586.38	1536.78
2589.85	1577.6
2593.32	1550.43
2596.79	1572.24
2600.25	1552.19
2603.72	1549.56
2607.18	1546.73
2610.64	1596.97
2614.1	1592.23
2617.56	1622.46
2621.02	1571.65
2624.47	1554.01
2627.92	1576.46
2631.38	1617.74
2634.83	1615.28
2638.28	1565.6
2641.72	1600.79
2645.17	1611.93
2648.61	1610.31
2652.06	1616.85
2655.5	1627.7
2658.94	1615.57
2662.38	1622.19
2665.82	1642.93
2669.25	1626.66
2672.69	1617.28
2676.12	1659.68
2679.55	1624.64
2682.98	1633.99
2686.41	1669.5
2689.84	1596.03
2693.26	1619.97
2696.69	1631.17
2700.11	1643.56
2703.53	1681.56
2706.95	1676.24
2710.37	1683.46
2713.79	1708.72
2717.2	1720.39
2720.62	1751.01
2724.03	1694.99
2727.44	1664.27
2730.85	1685.78
2734.26	1699.82
2737.66	1728.92
2741.07	1702.38
2744.47	1693.28
2747.87	1701.12
2751.28	1722.09
2754.67	1706.01
2758.07	1716.52
2761.47	1696.38
2764.86	1708.03
2768.26	1706.13
2771.65	1732.39
2775.04	1730.09
2778.43	1729.39
2781.82	1737.94
2785.2	1702.18
2788.59	1732.25
2791.97	1740.52
2795.35	1702.94
2798.73	1732.57
2802.11	1744.36
2805.49	1775.79
2808.87	1720.01
2812.24	1740.94
2815.62	1704.67
2818.99	1742.45
2822.36	1717.03
2825.73	1751.43
2829.1	1785.05
2832.46	1789.17
2835.83	1761.91
2839.19	1765.73
2842.55	1762.47
2845.91	1749.48
2849.27	1766.22
2852.63	1788.2
2855.99	1775.82
2859.34	1787.11
2862.69	1878.14
2866.05	1861.59
2869.4	1881.48
2872.75	1866.56
2876.09	1879.78
2879.44	1858.15
2882.78	1792.01
2886.13	1904.91
2889.47	1864.18
2892.81	1905.07
2896.15	1901.29
2899.49	1848.01
2902.82	1913.64
2906.16	1934.67
2909.49	1944.13
2912.82	1992.38
2916.16	2053.49
2919.49	2124.81
2922.81	2185.64
2926.14	2257.32
2929.46	2332.59
2932.79	2293.01
2936.11	2414.76
2939.43	2391.19
2942.75	2329.08
2946.07	2246.51
2949.39	2250.5
2952.7	2198.95
2956.02	2126.23
2959.33	2156.24
2962.64	2144.88
2965.95	2120.89
2969.26	2150.28
2972.57	2163.35
2975.87	2148.18
2979.17	2143.8
2982.48	2125.45
2985.78	2097.87
2989.08	2107.9
2992.38	2028.78
2995.68	2009.89
2998.97	1966.57
3002.27	1961.68
3005.56	1913.68
3008.85	1870.44
3012.14	1895.09
3015.43	1864.08
3018.72	1862.25
3022	1842.46
3025.29	1869.91
3028.57	1886.04
3031.85	1835
3035.14	1813.13
3038.41	1827.2
3041.69	1818.58
3044.97	1787.3
3048.24	1801.39
3051.52	1790.95
3054.79	1807.96
3058.06	1749.82
3061.33	1729.17
3064.6	1789.33
3067.87	1755.31
3071.13	1770.19
3074.4	1762.29
3077.66	1815.07
3080.92	1758.86
3084.18	1750.39
3087.44	1768.83
3090.7	1773.44
3093.95	1733.48
3097.21	1713.71
3100.46	1764.31
3103.71	1792.66
3106.96	1788.77
3110.21	1792.92
3113.46	1795.11
3116.71	1795.48
3119.95	1741.58
3123.2	1768.61
3126.44	1797.5
3129.68	1761.61
3132.92	1755.23
3136.16	1770.68
3139.4	1778.46
3142.63	1748.1
3145.87	1722.59
3149.1	1789.65
3152.33	1725.05
3155.56	1775.88
3158.79	1718.87
3162.02	1734.37
3165.25	1729.71
3168.47	1726.82
3171.69	1718.13
3174.92	1736.02
3178.14	1765.29
3181.36	1707.79
3184.58	1774.14
3187.79	1700.22
3191.01	1750.22
3194.22	1772.54
3197.43	1687.18
3200.65	1731.4
3203.86	1719.5
3207.07	1767.64
3210.27	1760.67
3213.48	1729.11
3216.69	1720.41
3219.89	1765.97
3223.09	1713.71
3226.29	1723.34
3229.49	1725.5
3232.69	1721.84
3235.89	1740.35
3239.08	1731.44
3242.28	1742.62
3245.47	1739.52
3248.66	1745.15
3251.85	1742.28
3255.04	1750.87
3258.23	1714.4
3261.42	1771.25
3264.6	1746.68
3267.79	1745.78
3270.97	1740.93
3274.15	1788.61
3277.33	1750.99
3280.51	1748.34
3283.68	1743.76
3286.86	1757.16
3290.04	1729.66
3293.21	1725.04
3296.38	1718.44
3299.55	1730.39
3302.72	1734.41
3305.89	1731.55
3309.06	1751.24
3312.22	1789.74
3315.39	1729.44
3318.55	1744.07
3321.71	1716.04
3324.87	1770.42
3328.03	1725.43
3331.19	1762.82
3334.34	1754.98
3337.5	1718.05
3340.65	1750.96
3343.81	1725.72
3346.96	1762.27
3350.11	1701.77
3353.25	1743.23
3356.4	1713.15
3359.55	1728.53
3362.69	1701.55
3365.84	1719.92
3368.98	1711.93
3372.12	1694.69
3375.26	1746.47
3378.4	1745.51
3381.53	1732.16
3384.67	1789.87
3387.8	1780.48
3390.94	1783.49
3394.07	1776.31
3397.2	1788.01
3400.33	1771.59
3403.46	1864.51
3406.58	1857.94
3409.71	2060.79
3412.83	2351.19
3415.96	3171.8
3419.08	5101.84
3422.2	5701.91
3425.32	4007.27
3428.44	2625.37
3431.55	2104.05
3434.67	1939.25
3437.78	1893.97
3440.89	1803.98
3444	1781.35
3447.12	1849.28
3450.22	1811.07
3453.33	1789.07
3456.44	1775.4
3459.54	1783.55
3462.65	1751.71
3465.75	1812.82
3468.85	1854.27
3471.95	1860.17
3475.05	1873.81
3478.15	1900.78
3481.24	1963.66
3484.34	2048.29
3487.43	2199.07
3490.53	2388.19
3493.62	2648.07
3496.71	3039.57
3499.79	3427.32
3502.88	3773.54
3505.97	3691.06
3509.05	3222.35
3512.14	2853.72
3515.22	2466.29
3518.3	2252.62
3521.38	2116.29
3524.46	1997.81
3527.54	1894.98
3530.61	1914.55
3533.69	1842.44
3536.76	1775.69
3539.83	1761.16
3542.9	1765.63
3545.97	1793.43
3549.04	1755.78
3552.11	1754.63
3555.18	1784.97
3558.24	1719.92
3561.3	1707.45
3564.37	1718.51
3567.43	1719.24
3570.49	1735.8
3573.55	1699.05
3576.61	1699.21
3579.66	1716.31
3582.72	1749.37
3585.77	1709.35
3588.82	1662.54
3591.87	1713.3
3594.92	1651.14
3597.97	1685.6
3601.02	1699.07
3604.07	1721.84
3607.11	1680.23
3610.16	1680.18
3613.2	1683.83
3616.24	1703.56
3619.28	1722.4
3622.32	1669.6
3625.36	1680.11
3628.39	1732.03
3631.43	1691.5
3634.46	1693.64
3637.5	1642.43
3640.53	1704.32
3643.56	1719.6
3646.59	1719.55
3649.62	1644.44
3652.64	1712.37
3655.67	1710.14
3658.69	1668.43
3661.72	1645.25
3664.74	1696.73
3667.76	1676.68
3670.78	1691.68
3673.79	1696.4
3676.81	1688.03
3679.83	1690.93
3682.84	1687.2
3685.86	1694.87
3688.87	1712.06
3691.88	1684.81
3694.89	1677.14
3697.9	1638.36
3700.91	1666.07
3703.91	1667.22
3706.92	1681.52
3709.92	1655.76
3712.92	1703.95
3715.92	1717.98
3718.92	1659.56
3721.92	1664.73
3724.92	1685.93
3727.92	1646.07
3730.91	1680.34
3733.91	1671.57
3736.9	1676.92
3739.89	1702.07
3742.88	1706.11
3745.87	1680.5
3748.86	1699.44
3751.85	1673.66
3754.83	1688.75
3757.82	1718.03
3760.8	1688.39
3763.78	1669.18
3766.76	1705.94
3769.74	1675.66
3772.72	1689.98
3775.7	1654.3
3778.67	1706.62
3781.65	1715.51
3784.62	1667.82
3787.6	1673.1
3790.57	1655.97
3793.54	1689.04
3796.51	1674.06
3799.47	1673.45
3802.44	1677.69
3805.41	1684.83
3808.37	1677.88
3811.33	1696.52
3814.3	1675.49
3817.26	1653.56
3820.22	1677.09
3823.18	1691.29
3826.13	1683.75
3829.09	1679.03
3832.04	1696.25
3835	1688.93
3837.95	1708.22
3840.9	1683.79
3843.85	1658.38
3846.8	1700.62
3849.75	1701.09
3852.69	1695.88
3855.64	1675.41
3858.58	1689.34
3861.53	1703.21
3864.47	1688.38
3867.41	1712.68
3870.35	1689.01
3873.29	1648.93
3876.22	1675.85
3879.16	1674.76
3882.1	1719.59
3885.03	1702.78
3887.96	1674.33
3890.89	1721.78
3893.82	1705.58
3896.75	1652.61
3899.68	1674.6
3902.61	1678.08
3905.53	1724.01
3908.46	1694.88
3911.38	1708.85
3914.3	1644.8
3917.23	1752.98
3920.15	1707.28
3923.06	1725.68
3925.98	1739.09
3928.9	1720.68
3931.81	1732.31
3934.73	1661.93
3937.64	1717.41
3940.55	1725.86
3943.46	1717.11
3946.37	1709.48
3949.28	1714.44
3952.19	1715.64
3955.09	1685.39
3958	1695.45
3960.9	1699.85
3963.8	1709.14
3966.71	1696.47
3969.61	1719.37
3972.51	1730.76
3975.4	1721.89
3978.3	1710.96
3981.2	1711.52
3984.09	1685.06
3986.99	1723.99
3989.88	1710.69
3992.77	1720.77
3995.66	1706.8
3998.55	1717.94
4001.43	1714.66
4004.32	1708.58
4007.21	1701.57
4010.09	1669.46
4012.98	1697.14
4015.86	1697.83
4018.74	1691.75
4021.62	1707.88
4024.5	1725.02
4027.37	1736.38
4030.25	1791.32
4033.13	1709.91
4036	1724.32
4038.87	1701.01
4041.75	1730.67
4044.62	1707.03
4047.49	1727.1
4050.35	1712.37
4053.22	1733.66
4056.09	1685.11
4058.95	1678.19
4061.82	1709.15
4064.68	1753.76
4067.54	1697.2
4070.4	1739.86
4073.26	1690.02
4076.12	1736.56
4078.98	1712.95
4081.83	1756.61
4084.69	1745.63
4087.54	1749.23
4090.4	1711.91
4093.25	1728.27
4096.1	1728.97
4098.95	1671.07
4101.8	1761.69
4104.64	1714.3
4107.49	1677.55
4110.33	1683.78
4113.18	1714.26
4116.02	1741.6
4118.86	1720.88
4121.7	1732.61
4124.54	1704.35
4127.38	1776.18
4130.22	1732.92
4133.05	1732.13
4135.89	1683.34
4138.72	1687.34
4141.56	1739.98
4144.39	1747.36
4147.22	1726.48
4150.05	1773
4152.88	1694.56
4155.7	1732.93
4158.53	1709.66
4161.36	1731.94
4164.18	1703.36
4167	1681.65
4169.82	1740.25
4172.65	1707.96
4175.46	1742.19
4178.28	1711.96
4181.1	1758.12
4183.92	1683.06
4186.73	1718.61
4189.55	1718.14
4192.36	1729.66
4195.17	1726.7
4197.98	1702.25
4200.79	1703.26
4203.6	1715.08
4206.41	1734.75
4209.21	1739.69
4212.02	1753.43
4214.83	1749.1
4217.63	1726.52
4220.43	1715.47
4223.23	1683.48
4226.03	1720.66
4228.83	1739.33
4231.63	1695.78
4234.42	1709.81
4237.22	1725.91
4240.01	1684.43
4242.81	1681.75
4245.6	1672.07
4248.39	1715.1
4251.18	1710.17
4253.97	1719.13
4256.76	1733.03
4259.55	1692.87
4262.33	1714.92
4265.12	1690.89
4267.9	1721.18
4270.68	1702.12
4273.47	1698.93
4276.25	1703.49
4279.03	1725.08
4281.8	1667.69
4284.58	1668.68
4287.36	1682.64
4290.13	1666.12
4292.91	1691.23
4295.68	1676.02
4298.45	1704.36
4301.22	1688.99
4303.99	1682.75
4306.76	1709.05
4309.53	1726.37
4312.3	1693.79
4315.06	1750.46
4317.83	1651.33
4320.59	1696.57
4323.35	1688.77
4326.11	1679.95
4328.87	1688.38
4331.63	1677.41
4334.39	1700.03
4337.15	1693.19
4339.9	1650.86
4342.66	1680.98
4345.41	1674.58
4348.17	1686.61
4350.92	1689.73
4353.67	1662.3
4356.42	1699.13
4359.17	1679.68
4361.91	1654.12
4364.66	1631.6
4367.41	1659.3
4370.15	1665.4
4372.89	1692.88
4375.63	1685.4
4378.38	1669.59
4381.12	1644.58
4383.86	1684.6
4386.59	1639.84
4389.33	1643.84
4392.07	1656.97
4394.8	1661.72
4397.53	1688.52
4400.27	1645.93
4403	1650.92
4405.73	1656.02
4408.46	1696.39
4411.19	1640.84
4413.92	1635.05
4416.64	1639.23
4419.37	1679.81
4422.09	1666.43
4424.82	1640.51
4427.54	1616.65
4430.26	1692.12
4432.98	1658.75
4435.7	1639.91
4438.42	1638.73
4441.13	1632.27
4443.85	1633.11
4446.57	1639.14
4449.28	1652.45
4451.99	1617.36
4454.71	1621.04
4457.42	1651.93
4460.13	1617.76
4462.83	1596.26
4465.54	1608.45
4468.25	1614.42
4470.95	1618.41
4473.66	1630.99
4476.36	1577.27
4479.07	1610.13
4481.77	1611.38
4484.47	1617.84
4487.17	1626.38
4489.87	1652.64
4492.56	1605.26
4495.26	1641.94
4497.96	1611.93
4500.65	1628.22
4503.34	1588.54
4506.04	1629.51
4508.73	1621.7
4511.42	1607.55
4514.11	1611.5
4516.8	1592.07
4519.48	1653.66
4522.17	1567.49
4524.85	1606.73
4527.54	1579
4530.22	1569.36
4532.9	1599.25
4535.58	1595.03
4538.27	1595.26
4540.94	1571.9
4543.62	1577.48
4546.3	1568.07
4548.98	1591.92
4551.65	1587.22
4554.33	1554.67
4557	1588.2
4559.67	1532.68
4562.34	1532.31
4565.01	1547.97
4567.68	1564.29
4570.35	1539.72
4573.02	1548.37
4575.68	1548.19
4578.35	1512.56
4581.01	1532.38
4583.67	1575.98
4586.34	1519.29
4589	1555.07
4591.66	1496.91
4594.31	1542.95
4596.97	1554.73
4599.63	1516.59
4602.29	1563.94
4604.94	1512.75
4607.59	1513.07
4610.25	1545.18
4612.9	1545.43
4615.55	1535.82
4618.2	1501.03
4620.85	1503.6
4623.5	1513.78
4626.14	1561.38
4628.79	1500.84
4631.43	1491.91
4634.08	1512.67
4636.72	1498.07
4639.36	1516.54
4642	1516.53
4644.64	1540.23
4647.28	1495.47
4649.92	1489.96
4652.56	1506.37
4655.19	1477.15
4657.83	1496.23
4660.46	1524.65
4663.1	1454.8
4665.73	1498.28
4668.36	1507.34
4670.99	1467.08
4673.62	1494.01
4676.24	1490.67
4678.87	1455.83
4681.5	1551.27
4684.12	1493.95
4686.75	1479.26
4689.37	1491.72
4691.99	1458.93
4694.61	1493.72
4697.23	1503.76
4699.85	1488.99
4702.47	1446.9
4705.09	1480.48
4707.7	1450.68
4710.32	1485.33
4712.93	1523.39
4715.55	1477.52
4718.16	1439.6
4720.77	1484.16
4723.38	1475.7
4725.99	1423.12
4728.6	1469.25
4731.21	1429.13
4733.81	1482.13
4736.42	1480.46
4739.02	1493.6
4741.63	1403.04
4744.23	1481.99
4746.83	1443.4
4749.43	1448.11
4752.03	1424.38
4754.63	1434.7
4757.23	1473.62
4759.82	1443.25
4762.42	1410.6
4765.01	1407.8
4767.61	1439.64
4770.2	1458.49
4772.79	1414.61
4775.38	1438.1
4777.97	1442.15
4780.56	1419.92
4783.15	1435.44
4785.74	1445.24
4788.32	1389.86
4790.91	1392.91
4793.49	1408.55
4796.07	1409.48
4798.66	1410.51
4801.24	1407.05
4803.82	1414.08
4806.4	1430.54
4808.98	1427.38
4811.55	1379.35
4814.13	1438.6
4816.71	1406.89
4819.28	1383.17
4821.85	1413.87
4824.43	1387.82
4827	1386
4829.57	1403.02
4832.14	1390.95
4834.71	1375.54
4837.28	1360.22
4839.84	1405.77
4842.41	1382.03
4844.97	1380.35
4847.54	1367.93
4850.1	1380.45
4852.66	1376.87
4855.22	1354.18
4857.78	1350.29
4860.34	1343.75
4862.9	1369.71
4865.46	1383.63
4868.01	1382.88
4870.57	1346.22
4873.12	1347.18
4875.68	1348.17
4878.23	1349.09
4880.78	1343.96
4883.33	1339.98
4885.88	1374.08
4888.43	1371.38
4890.98	1315.02
4893.53	1356.26
4896.07	1340.26
4898.62	1339.75
4901.16	1340.35
4903.7	1364.91
4906.25	1331.96
4908.79	1315.58
4911.33	1365.9
4913.87	1362.35
4916.41	1366.01
4918.94	1323.16
4921.48	1359.14
4924.02	1310.36
4926.55	1315.29
4929.08	1316.76
4931.62	1304.21
4934.15	1325.14
4936.68	1324.46
4939.21	1309.04
4941.74	1318.81
4944.27	1322.98
4946.79	1297.22
4949.32	1318.24
4951.85	1314.04
4954.37	1307.5
4956.9	1292.74
4959.42	1290.08
4961.94	1292.5
4964.46	1255.48
4966.98	1320.72
4969.5	1256.74
4972.02	1271.14
4974.53	1275.85
4977.05	1262.45
4979.57	1290.24
4982.08	1309.63
4984.59	1268.43
4987.1	1236.89
4989.62	1284.28
4992.13	1248.97
4994.64	1274.62
4997.15	1250.47
4999.65	1261.68