File: Data/3-Raman/raw/bu19w-ff07b-fi04-s_150 (500nm)_532nm_edge_100%_x100_vis_lwd_h50um_15sx2_01.txt
#Acq. time (s)=	15
#Accumulations=	2
#Range (cm-¹)=	50...5000
#Windows=	1
#Auto scanning=	Off
#Autofocus=	Off
#Macrospot=	Off
#AutoExposure=	Off
#Spike filter=	Multiple accum.
#Delay time (s)=	2
#Binning=	1
#Readout mode=	Signal
#DeNoise=	Off
#ICS correction=	On
#Dark correction=	Off
#Inst. Process=	Off
#Detector Gain=	Best Dynamic
#Detector ADC=	50 kHz HS
#Detector temperature (°C)=	-60.09
#Instrument=	LabRAM HR Evol
#Detector=	SIN-EM FIVIS
#Objective=	x100_VIS_LWD
#Grating=	150 (500nm)
#ND Filter=	100%
#Laser=	532nm_Edge
#Hole=	49.98
#Temperature=	0
#Range=	Visible
#StageXY=	75x50mm Scan+
#StageZ=	Z motor
#X (µm)=	0
#Y (µm)=	0
#Z (µm)=	-40
#Full time(s)=	34
#Project=	21_05_28
#Sample=	BU19w
#Site=
#Title=	BU19w-FF07b-FI04-S_150 (500nm)_532nm_Edge_100%_x100_VIS_LWD_H50um_15sX2
#Remark=
#Date=	28.05.2021 16:13
#Acquired=	28.05.2021 16:13:37
51.5961	6294.05
56.2453	5476.6
60.8921	4838.58
65.5367	7624.9
70.1768	10761.2
74.8167	6074.62
79.4543	3351.7
84.0897	2824.52
88.7227	2599.7
93.3513	2387.06
97.9798	2318.72
102.606	2240.47
107.23	2186.05
111.851	2269.09
116.469	2210.11
121.086	2159.56
125.7	2089.4
130.313	2389.51
134.921	2853.38
139.529	2363.36
144.134	2106.08
148.738	1942.73
153.337	1868.23
157.936	2023.56
162.532	2709.5
167.126	4169.94
171.716	4074.97
176.306	2696.07
180.894	2218.55
185.477	2256.31
190.06	3214.06
194.64	6651.41
199.219	6557.35
203.793	3309.5
208.367	2131.34
212.939	1772.84
217.506	1720.16
222.073	1866.82
226.638	1821.27
231.199	1700.78
235.759	1693.86
240.318	2040.82
244.872	2179.55
249.425	2425.14
253.977	3271.7
258.524	3110.45
263.071	2650.52
267.616	2685.76
272.156	3720.83
276.697	3879.02
281.233	4428.14
285.769	7466.48
290.303	9498.78
294.832	8561.22
299.361	5498.73
303.886	4059.05
308.411	4672.51
312.934	4714.19
317.452	3599.1
321.97	2689.59
326.484	2229.62
330.998	2414.42
335.507	3014.75
340.017	3301.86
344.524	2503.75
349.027	2048.45
353.53	2335.42
358.028	2783.09
362.527	2612.75
367.021	2020.03
371.515	1762.8
376.004	1898.29
380.494	1962.03
384.979	1845.82
389.465	1894.48
393.946	2206.94
398.427	2406.74
402.903	2560.27
407.38	2371.59
411.852	2012.16
416.324	1820.57
420.792	2166.7
425.26	2773.04
429.723	2120.98
434.187	1467.24
438.646	1323.92
443.105	1289.25
447.56	1257.72
452.015	1361.88
456.466	1592.86
460.914	2333.77
465.362	2940.96
469.807	2473.97
474.251	2293.14
478.69	2563.24
483.13	2528.19
487.566	2478.33
491.999	2487.73
496.432	2486.4
500.861	2376.84
505.29	2260.76
509.715	2050.81
514.138	1797.04
518.56	1512.19
522.979	1433.67
527.395	1383.23
531.811	1338.83
536.223	1338.63
540.635	1389.45
545.042	1386.95
549.448	1416.99
553.853	1442.22
558.255	1486.36
562.654	1460.8
567.053	1478.43
571.448	1482.78
575.841	1388.71
580.232	1338.75
584.622	1435.61
589.009	1809.46
593.393	2969.6
597.777	4286.09
602.157	3558.68
606.535	2251.24
610.913	1986.47
615.287	2265.2
619.659	2928.15
624.029	3113.63
628.398	2456.22
632.763	1988.73
637.127	2428.73
641.488	3505.65
645.849	3291.22
650.206	2239.95
654.561	1661.42
658.914	1466.47
663.267	1460.97
667.615	1632.97
671.962	1806
676.307	1844.45
680.649	1947.75
684.991	2094.78
689.33	1992.86
693.666	1584.01
698	1304
702.332	1204.73
706.662	1122.06
710.992	1099.42
715.318	1077.49
719.641	1030.89
723.963	1043.38
728.283	1046.57
732.6	1052.63
736.918	1091.34
741.231	1071.45
745.542	1093.26
749.852	1074.85
754.159	1132.85
758.464	1184.4
762.767	1279.38
767.068	1345.05
771.369	1495.05
775.666	1845.42
779.961	2464.82
784.254	3305.62
788.545	3931.81
792.834	3716.78
797.12	3081.47
801.405	2392.32
805.688	1900.79
809.968	1594.97
814.247	1410.37
818.524	1241.34
822.798	1205.34
827.071	1136.63
831.341	1098.78
835.612	1144.68
839.878	1084.67
844.142	1053.15
848.405	1096.26
852.665	1078.05
856.923	1066.47
861.18	1112.16
865.434	1164.19
869.686	1203.64
873.936	1274.58
878.185	1198.04
882.431	1141.19
886.675	1116.84
890.915	1105.02
895.155	1114.55
899.393	1084.81
903.63	1103.03
907.864	1067.65
912.096	1067.87
916.326	1074.15
920.554	1048.86
924.78	1088.99
929.004	1082.11
933.227	1094.83
937.447	1124.56
941.665	1148.53
945.881	1206.48
950.095	1304.75
954.305	1399.87
958.516	1514.03
962.724	1533.5
966.93	1488.31
971.134	1617.4
975.337	1742.36
979.537	1757.19
983.735	1674.91
987.93	1720.75
992.124	1866.2
996.316	2276.62
1000.51	3062.1
1004.7	4318.97
1008.88	5275.92
1013.06	4297.03
1017.25	2964.05
1021.43	2280.62
1025.61	2016.9
1029.78	2136.54
1033.96	2570.68
1038.13	3547.29
1042.3	4486.48
1046.47	4329.72
1050.63	4654.29
1054.8	6119.22
1058.96	6668.44
1063.12	5466.19
1067.28	3890.48
1071.44	2807.06
1075.59	2222.35
1079.74	2036.03
1083.89	2072.49
1088.04	2358.22
1092.19	3100.46
1096.33	4192.09
1100.48	5034.42
1104.62	5095.42
1108.76	4462.63
1112.89	3851.37
1117.03	3866.15
1121.16	3691.75
1125.29	3313.68
1129.42	3056.38
1133.55	3130.82
1137.68	3337.97
1141.8	3356.56
1145.92	3012.59
1150.04	2449.13
1154.16	2198.54
1158.27	2288.29
1162.39	2700.61
1166.5	3062.56
1170.61	2846.85
1174.72	2379.86
1178.82	2187.18
1182.93	2169.7
1187.03	2039.54
1191.13	1814.22
1195.23	1661.92
1199.33	1558.78
1203.42	1489.36
1207.51	1474.01
1211.6	1418.3
1215.69	1341.75
1219.78	1344.31
1223.86	1357.1
1227.95	1522.53
1232.03	1643.83
1236.11	1525.11
1240.18	1514.37
1244.26	1678.06
1248.33	1896.14
1252.41	1826.67
1256.48	1560.78
1260.54	1347.84
1264.61	1245.85
1268.67	1225.03
1272.74	1215.38
1276.8	1171.59
1280.86	1162.82
1284.91	1133.72
1288.97	1115.44
1293.02	1116.13
1297.07	1112.62
1301.12	1126.13
1305.17	1130.35
1309.21	1120.39
1313.25	1105.26
1317.3	1105.86
1321.34	1088.09
1325.37	1120.23
1329.41	1094.89
1333.44	1091.56
1337.48	1073.85
1341.5	1106.03
1345.53	1110.01
1349.56	1083.05
1353.59	1132.82
1357.61	1112.94
1361.63	1087.1
1365.65	1086.28
1369.66	1139
1373.68	1226.39
1377.69	1252.64
1381.7	1261.33
1385.72	1190.82
1389.72	1138.32
1393.73	1096
1397.73	1097.44
1401.74	1088.95
1405.74	1053.81
1409.73	1101.56
1413.73	1059.7
1417.73	1043.48
1421.72	1067.7
1425.71	1044.39
1429.7	1048.2
1433.69	1087.64
1437.67	1060.91
1441.66	1112.19
1445.64	1096.16
1449.62	1067.24
1453.6	1080.58
1457.57	1075.06
1461.55	1093.98
1465.52	1047.57
1469.49	1077.86
1473.46	1095.48
1477.43	1060.92
1481.39	1065.5
1485.36	1070.96
1489.32	1067.54
1493.28	1083.73
1497.24	1095.03
1501.19	1074.29
1505.15	1060.59
1509.1	1055.96
1513.05	1051.41
1517	1076.04
1520.95	1062.93
1524.9	1072.21
1528.84	1096.11
1532.78	1083.3
1536.72	1091.85
1540.66	1074.26
1544.6	1075.09
1548.53	1057.52
1552.46	1115.51
1556.4	1096.83
1560.32	1116.73
1564.25	1153.89
1568.18	1130.94
1572.1	1142.73
1576.02	1166.07
1579.94	1158.45
1583.86	1190.34
1587.78	1134.41
1591.69	1163.27
1595.61	1183.39
1599.52	1153.52
1603.43	1160.27
1607.34	1181.59
1611.24	1121.41
1615.15	1200.34
1619.05	1160.57
1622.95	1177.27
1626.85	1158.72
1630.74	1168.08
1634.64	1159.64
1638.53	1146.35
1642.42	1165.92
1646.31	1146.47
1650.2	1165.46
1654.09	1148.07
1657.97	1147.84
1661.86	1168.7
1665.74	1142.26
1669.62	1173.35
1673.49	1144.48
1677.37	1175.15
1681.24	1127.34
1685.12	1135.95
1688.99	1117.59
1692.86	1123.94
1696.72	1104.29
1700.59	1145.63
1704.45	1160.85
1708.31	1168.16
1712.17	1141
1716.03	1168.93
1719.89	1140.05
1723.74	1129.25
1727.6	1110.86
1731.45	1129.95
1735.3	1143.43
1739.14	1144.55
1742.99	1129.66
1746.83	1113.97
1750.68	1152.94
1754.52	1143.01
1758.36	1102.23
1762.19	1157.03
1766.03	1138.63
1769.86	1152.24
1773.69	1137.61
1777.53	1128.57
1781.35	1105.91
1785.18	1145.91
1789	1149.7
1792.83	1142.32
1796.65	1138.69
1800.47	1164.13
1804.29	1171.02
1808.1	1156.15
1811.92	1131.7
1815.73	1163.61
1819.54	1146.91
1823.35	1170.48
1827.16	1121.18
1830.97	1165.9
1834.77	1156.56
1838.58	1171.51
1842.38	1149.58
1846.18	1143.38
1849.97	1178.63
1853.77	1157.96
1857.56	1181.93
1861.36	1170.93
1865.15	1169.14
1868.93	1199.97
1872.72	1165.03
1876.51	1163.75
1880.29	1167.17
1884.07	1146.2
1887.86	1176.88
1891.63	1191.38
1895.41	1168.19
1899.19	1160.64
1902.96	1177.52
1906.73	1153.22
1910.5	1181.52
1914.27	1163.27
1918.04	1198.61
1921.8	1185.81
1925.57	1167.52
1929.33	1175.36
1933.09	1200.07
1936.85	1165.21
1940.6	1212.33
1944.36	1190.38
1948.11	1203.95
1951.87	1194.09
1955.61	1145.21
1959.36	1139.84
1963.11	1199.83
1966.86	1169.58
1970.6	1176.53
1974.34	1180.22
1978.08	1182.72
1981.82	1219.63
1985.56	1186.15
1989.29	1229.13
1993.02	1204.71
1996.75	1212.68
2000.49	1203.68
2004.21	1229.03
2007.94	1198.7
2011.67	1191.26
2015.39	1211.48
2019.11	1213.85
2022.83	1237.94
2026.55	1239.84
2030.27	1232.64
2033.98	1223.29
2037.69	1197.89
2041.41	1240.13
2045.12	1225.5
2048.82	1236.54
2052.53	1235.92
2056.24	1216.14
2059.94	1227.22
2063.64	1232.67
2067.34	1203.48
2071.04	1221.28
2074.74	1229.01
2078.43	1261.82
2082.13	1221.66
2085.82	1253.58
2089.51	1201.41
2093.2	1224.83
2096.88	1262.81
2100.57	1253.17
2104.25	1242.16
2107.94	1275.58
2111.62	1238.12
2115.3	1276.87
2118.97	1255.95
2122.65	1267.98
2126.32	1240.75
2129.99	1262.5
2133.66	1264.63
2137.33	1290.71
2141	1242.66
2144.67	1267.36
2148.33	1284.53
2151.99	1317.22
2155.66	1251.77
2159.31	1280.85
2162.97	1283.49
2166.63	1298.2
2170.28	1283.01
2173.94	1266.57
2177.59	1287.76
2181.24	1287.26
2184.89	1308.54
2188.53	1314.69
2192.18	1311.36
2195.82	1295.81
2199.46	1305.14
2203.1	1317.36
2206.74	1321.6
2210.38	1320.6
2214.01	1319.77
2217.65	1345.61
2221.28	1334.82
2224.91	1325.9
2228.54	1342.66
2232.16	1334.59
2235.79	1322.92
2239.41	1320.42
2243.04	1374.43
2246.66	1369.13
2250.28	1375.04
2253.89	1339.2
2257.51	1389.21
2261.12	1351.48
2264.74	1302.22
2268.35	1352.37
2271.96	1354.13
2275.57	1341.4
2279.17	1369.75
2282.78	1339.67
2286.38	1342.58
2289.98	1309.56
2293.58	1343.46
2297.18	1364.19
2300.78	1349.02
2304.37	1335.49
2307.97	1370
2311.56	1317.12
2315.15	1346.5
2318.74	1331.09
2322.33	1362.76
2325.91	1372.73
2329.5	1388.21
2333.08	1343.05
2336.66	1374.2
2340.24	1344.82
2343.82	1348.29
2347.4	1381.6
2350.97	1379.09
2354.54	1357.83
2358.12	1401.87
2361.69	1337.63
2365.26	1390.72
2368.82	1378.76
2372.39	1362.55
2375.95	1369.4
2379.52	1326.43
2383.08	1395.24
2386.64	1342.56
2390.19	1360.98
2393.75	1370.46
2397.31	1396.84
2400.86	1353.09
2404.41	1377.01
2407.96	1355.27
2411.51	1365.28
2415.06	1362.78
2418.6	1356.01
2422.15	1361.4
2425.69	1367.13
2429.23	1393.53
2432.77	1359.25
2436.31	1325.14
2439.84	1359.75
2443.38	1377.87
2446.91	1369.03
2450.44	1365.12
2453.97	1369.86
2457.5	1368.07
2461.03	1366.02
2464.55	1330.84
2468.08	1377.47
2471.6	1393.2
2475.12	1352.81
2478.64	1384.88
2482.16	1377.55
2485.67	1362.18
2489.19	1364.8
2492.7	1367.23
2496.21	1367
2499.72	1405.67
2503.23	1390.43
2506.74	1406.77
2510.25	1389.18
2513.75	1362.44
2517.25	1378.86
2520.75	1378.77
2524.25	1378.65
2527.75	1390.08
2531.25	1379.67
2534.74	1401.8
2538.24	1403.08
2541.73	1385.32
2545.22	1386.69
2548.71	1389.58
2552.2	1404.55
2555.68	1375.53
2559.17	1387.87
2562.65	1367.79
2566.13	1378
2569.61	1399.87
2573.09	1408.2
2576.57	1406.53
2580.04	1442.72
2583.51	1372.64
2586.99	1391.99
2590.46	1394.02
2593.93	1407.68
2597.4	1419.26
2600.86	1393.1
2604.33	1364.77
2607.79	1401.7
2611.25	1361.71
2614.71	1400.42
2618.17	1394.54
2621.63	1372.68
2625.09	1383.22
2628.54	1366.49
2631.99	1422.51
2635.45	1421.5
2638.9	1393.23
2642.34	1409.77
2645.79	1395.39
2649.24	1416.27
2652.68	1436.76
2656.12	1444.43
2659.56	1412.85
2663.01	1424.81
2666.44	1412.96
2669.88	1427.52
2673.32	1395.86
2676.75	1412.42
2680.18	1450.65
2683.61	1418.03
2687.04	1409.35
2690.47	1402.54
2693.9	1390.64
2697.32	1389.64
2700.75	1388.03
2704.17	1413.44
2707.59	1426.8
2711.01	1411.4
2714.43	1437.23
2717.84	1400.99
2721.26	1391.05
2724.67	1401.8
2728.08	1422.03
2731.49	1427.43
2734.9	1388.76
2738.31	1387.49
2741.71	1432.12
2745.12	1382.65
2748.52	1409.02
2751.92	1392.18
2755.32	1426.02
2758.72	1416.42
2762.12	1416.26
2765.52	1427.03
2768.91	1407.42
2772.3	1397.95
2775.7	1442.99
2779.09	1383.22
2782.47	1418.38
2785.86	1394.12
2789.25	1414.98
2792.63	1377.49
2796.01	1418.91
2799.4	1359.82
2802.78	1388.77
2806.15	1406.44
2809.53	1441.84
2812.91	1407.85
2816.28	1430.87
2819.65	1435.14
2823.03	1389.23
2826.4	1429.38
2829.76	1428.58
2833.13	1430.77
2836.5	1382.91
2839.86	1418.22
2843.22	1436.1
2846.59	1429.17
2849.95	1421.82
2853.3	1393.32
2856.66	1421.59
2860.02	1420.18
2863.37	1425.49
2866.72	1415.88
2870.08	1425.02
2873.43	1435.96
2876.77	1391.39
2880.12	1459.66
2883.47	1417.76
2886.81	1398.3
2890.15	1430.7
2893.5	1419.6
2896.84	1411.92
2900.17	1442.81
2903.51	1426.19
2906.85	1418.85
2910.18	1438.82
2913.52	1414.21
2916.85	1441.55
2920.18	1415.68
2923.51	1403.94
2926.83	1472.43
2930.16	1445.21
2933.48	1456.57
2936.81	1471.47
2940.13	1472.2
2943.45	1435.26
2946.77	1430.42
2950.09	1477.37
2953.4	1501.63
2956.72	1496.79
2960.03	1474.37
2963.34	1462.42
2966.65	1449.64
2969.96	1456.99
2973.27	1471.17
2976.58	1460.09
2979.88	1433.29
2983.19	1473.88
2986.49	1467.64
2989.79	1474.63
2993.09	1491.07
2996.39	1464.38
2999.68	1479.1
3002.98	1468.43
3006.27	1451.17
3009.57	1468.83
3012.86	1497.89
3016.15	1479.9
3019.43	1471.28
3022.72	1425.84
3026.01	1494.55
3029.29	1467.99
3032.57	1498.05
3035.86	1527.13
3039.14	1465.4
3042.41	1478.37
3045.69	1467.72
3048.97	1494.95
3052.24	1497.57
3055.52	1522.98
3058.79	1500.94
3062.06	1500.21
3065.33	1546.21
3068.6	1547.43
3071.86	1535.02
3075.13	1552.59
3078.39	1545.16
3081.65	1565.68
3084.91	1569.52
3088.17	1596.07
3091.43	1596.49
3094.69	1612.23
3097.95	1630.67
3101.2	1609.27
3104.45	1662.67
3107.7	1681.69
3110.95	1651.94
3114.2	1676.85
3117.45	1675.26
3120.7	1709.91
3123.94	1691.22
3127.18	1702.99
3130.43	1749.01
3133.67	1747.43
3136.91	1745.78
3140.14	1802.2
3143.38	1734.66
3146.61	1773.91
3149.85	1764.65
3153.08	1831.73
3156.31	1868.22
3159.54	1856.11
3162.77	1844.9
3166	1897.62
3169.22	1860.47
3172.45	1914.79
3175.67	1895.56
3178.89	1975.39
3182.11	1970.27
3185.33	2010.97
3188.55	2011.38
3191.77	2065.11
3194.98	2031.13
3198.2	2044.78
3201.41	2102.17
3204.62	2128.21
3207.83	2113.38
3211.04	2146.23
3214.25	2158.28
3217.45	2198.07
3220.66	2215.98
3223.86	2170.24
3227.06	2220.79
3230.26	2191.48
3233.46	2258.43
3236.66	2255.78
3239.85	2237.45
3243.05	2307.79
3246.24	2275.41
3249.44	2311.64
3252.63	2299.49
3255.82	2334.15
3259.01	2283.84
3262.19	2342.01
3265.38	2295.78
3268.56	2322.76
3271.75	2337.09
3274.93	2373.25
3278.11	2341.55
3281.29	2368.58
3284.47	2361.76
3287.64	2391.24
3290.82	2316.56
3293.99	2394.64
3297.17	2363.95
3300.34	2379.04
3303.51	2407.03
3306.68	2366.82
3309.84	2448.15
3313.01	2433.01
3316.18	2472.82
3319.34	2521.04
3322.5	2443.97
3325.66	2534.68
3328.82	2619.58
3331.98	2656.18
3335.14	2712.75
3338.29	2761.92
3341.45	2861.23
3344.6	2974.65
3347.75	3150.93
3350.9	3383.51
3354.05	3683.88
3357.2	4190.13
3360.35	4888.02
3363.49	5749.78
3366.64	6818.57
3369.78	8176.91
3372.92	9894.05
3376.06	11565.5
3379.2	11199
3382.34	9129.77
3385.48	6948.38
3388.61	5647.86
3391.75	4819.18
3394.88	4438.21
3398.01	4215.91
3401.14	4040.27
3404.27	3949.13
3407.4	3887.63
3410.52	3946.04
3413.65	4149.15
3416.77	4565.06
3419.89	5526.69
3423.01	7842.03
3426.13	13293.8
3429.25	15571.6
3432.37	10331.3
3435.49	6036.71
3438.6	4312.92
3441.72	3708.99
3444.83	3380.94
3447.94	3151.59
3451.05	3064.4
3454.16	2991.15
3457.26	3026.44
3460.37	2952.8
3463.47	2901.08
3466.58	2859.73
3469.68	2893.95
3472.78	2849.85
3475.88	2877.76
3478.98	2897.25
3482.07	2989.66
3485.17	2996.03
3488.26	3126.3
3491.36	3268.24
3494.45	3422.28
3497.54	3695
3500.63	4103.13
3503.72	4683.65
3506.81	5395.85
3509.89	5924.59
3512.98	5702.54
3516.06	5148.88
3519.14	4352.14
3522.22	3790.16
3525.3	3322.13
3528.38	3079.7
3531.45	2839.3
3534.53	2656.69
3537.61	2520
3540.68	2455.36
3543.75	2397.43
3546.82	2262.61
3549.89	2241.73
3552.96	2204.18
3556.03	2156.94
3559.09	2110.96
3562.16	2070.62
3565.22	2027.9
3568.28	1984.85
3571.34	1976.53
3574.4	1896.13
3577.46	1914.43
3580.52	1902.23
3583.57	1846.24
3586.63	1874.49
3589.68	1790.82
3592.73	1781.85
3595.78	1754.83
3598.83	1742.83
3601.88	1774.4
3604.93	1699.73
3607.97	1667.58
3611.02	1678
3614.06	1582.47
3617.1	1623
3620.14	1600.32
3623.18	1546.6
3626.22	1555.21
3629.26	1575.23
3632.3	1549.92
3635.33	1531.15
3638.36	1530.65
3641.4	1517.19
3644.43	1450.28
3647.46	1418.56
3650.49	1441.95
3653.51	1395.91
3656.54	1387.62
3659.57	1387.11
3662.59	1358.22
3665.61	1310.18
3668.63	1282.22
3671.65	1286.6
3674.67	1304.26
3677.69	1255.93
3680.71	1269.96
3683.72	1225.34
3686.74	1206.21
3689.75	1194.67
3692.76	1168.95
3695.77	1176.36
3698.78	1181.66
3701.79	1174.88
3704.79	1151.96
3707.8	1144.19
3710.81	1121.07
3713.81	1129.22
3716.81	1110.59
3719.81	1109.16
3722.81	1111.4
3725.81	1084.03
3728.81	1107.97
3731.8	1096.6
3734.8	1133.69
3737.79	1102.09
3740.78	1096.11
3743.77	1058.59
3746.76	1092.35
3749.75	1074.64
3752.74	1042.61
3755.73	1061.88
3758.71	1041.3
3761.7	1052.95
3764.68	1046.5
3767.66	1065.65
3770.64	1076.34
3773.62	1046.45
3776.6	1049.75
3779.58	1027.6
3782.55	1043.31
3785.53	1042.04
3788.5	1014.39
3791.47	1040.62
3794.44	1037.75
3797.41	1033.07
3800.38	1069.06
3803.35	1019.27
3806.32	1017.68
3809.28	1015.17
3812.24	1062.82
3815.21	1037.73
3818.17	1033.45
3821.13	1023.54
3824.09	1032.58
3827.04	1010.43
3830	1043.26
3832.96	1007.82
3835.91	1016.1
3838.86	1028.25
3841.82	997.633
3844.77	1015.48
3847.72	1020.05
3850.67	989.416
3853.61	1002.65
3856.56	1019.75
3859.5	983.401
3862.45	1016.79
3865.39	1025.29
3868.33	989.756
3871.27	1024.04
3874.21	1003.68
3877.15	1035.08
3880.09	1011.65
3883.02	992.902
3885.96	1002.85
3888.89	988.688
3891.82	1018.71
3894.75	1009.27
3897.68	994.882
3900.61	1010.19
3903.54	989.897
3906.47	1014.66
3909.39	995.331
3912.31	996.088
3915.24	948.712
3918.16	981.976
3921.08	1003.87
3924	980.448
3926.92	1001.06
3929.83	1009.09
3932.75	966.285
3935.67	971.643
3938.58	1010.71
3941.49	967.61
3944.4	999.101
3947.31	971.285
3950.22	980.907
3953.13	958.046
3956.04	962.035
3958.94	953.66
3961.85	964.49
3964.75	959.078
3967.65	947.963
3970.55	942.643
3973.45	941.185
3976.35	966.593
3979.25	937.196
3982.15	952.886
3985.04	967.605
3987.94	950.552
3990.83	962.314
3993.72	959.535
3996.61	963.669
3999.5	996.665
4002.39	952.705
4005.28	970.372
4008.16	966.904
4011.05	929.707
4013.93	928.146
4016.81	942.992
4019.7	940.478
4022.58	948.576
4025.46	943.164
4028.33	939.7
4031.21	904.337
4034.09	941.502
4036.96	969.035
4039.84	932.746
4042.71	910.92
4045.58	898.611
4048.45	935.768
4051.32	907.072
4054.19	892.95
4057.05	906.08
4059.92	942.494
4062.78	914.783
4065.65	918.156
4068.51	920.554
4071.37	911.262
4074.23	910.719
4077.09	915.023
4079.95	916.4
4082.81	910.951
4085.66	916.232
4088.52	894.151
4091.37	928.661
4094.22	930.067
4097.07	903.072
4099.92	890.765
4102.77	904.822
4105.62	894.408
4108.47	880.943
4111.31	893.905
4114.16	913.615
4117	888.215
4119.84	914.556
4122.69	910.57
4125.53	886.144
4128.36	877.396
4131.2	877.696
4134.04	888.9
4136.88	840.597
4139.71	868.622
4142.54	873.32
4145.38	889.886
4148.21	854.941
4151.04	887.601
4153.87	891.675
4156.69	886.611
4159.52	903.681
4162.35	856.498
4165.17	876.939
4168	861.172
4170.82	855.231
4173.64	875.743
4176.46	894.323
4179.28	850.315
4182.1	887.551
4184.91	858.311
4187.73	862.375
4190.54	865.484
4193.36	859.922
4196.17	864.24
4198.98	874.568
4201.79	872.128
4204.6	903.083
4207.41	922.255
4210.22	911.022
4213.02	912.517
4215.83	884.506
4218.63	889.464
4221.44	864.811
4224.24	888.366
4227.04	867.412
4229.84	852.502
4232.64	860.347
4235.43	841.572
4238.23	854.543
4241.02	852.669
4243.82	854.79
4246.61	826.097
4249.4	856.111
4252.19	839.192
4254.98	827.204
4257.77	830.121
4260.56	842.05
4263.35	843.012
4266.13	849.029
4268.92	835.012
4271.7	807.859
4274.48	828.993
4277.26	819.737
4280.04	783.08
4282.82	821.088
4285.6	812.547
4288.38	803.89
4291.15	801.208
4293.93	806.59
4296.7	783.721
4299.47	808.541
4302.25	780.562
4305.02	799.231
4307.79	814.869
4310.55	800.085
4313.32	807.727
4316.09	812.191
4318.85	811.495
4321.62	798.526
4324.38	772.246
4327.14	779.521
4329.9	774.604
4332.66	797.103
4335.42	754.451
4338.18	808.506
4340.94	811.78
4343.69	756.949
4346.45	776.611
4349.2	779.017
4351.95	786.533
4354.7	777.93
4357.45	775.357
4360.2	780.965
4362.95	766.062
4365.7	748.145
4368.44	784.449
4371.19	769.609
4373.93	766.919
4376.68	749.839
4379.42	758.349
4382.16	797.664
4384.9	753.821
4387.64	753.293
4390.37	741.741
4393.11	756.052
4395.85	763.778
4398.58	730.618
4401.31	754.287
4404.05	754.09
4406.78	742.52
4409.51	760.047
4412.24	751.519
4414.96	722.037
4417.69	729.985
4420.42	744.93
4423.14	748.568
4425.87	758.518
4428.59	728.786
4431.31	735.604
4434.03	719.396
4436.75	725.118
4439.47	718.237
4442.19	754.255
4444.91	755.719
4447.62	713.061
4450.34	762.753
4453.05	737.847
4455.76	727.621
4458.47	723.624
4461.19	709.08
4463.89	736.689
4466.6	730.634
4469.31	717.251
4472.02	697.573
4474.72	725.344
4477.43	711.049
4480.13	702.064
4482.83	700.5
4485.53	709.496
4488.23	678.268
4490.93	704.102
4493.63	694.859
4496.33	707.728
4499.02	730.272
4501.72	683.923
4504.41	675.642
4507.11	674.844
4509.8	691.037
4512.49	683.902
4515.18	701.195
4517.87	695.157
4520.56	678.517
4523.24	656.613
4525.93	633.615
4528.61	690.425
4531.3	677.017
4533.98	661.477
4536.66	676.873
4539.34	675.236
4542.02	680.05
4544.7	687.001
4547.38	660.814
4550.05	666.722
4552.73	667.347
4555.4	665.943
4558.08	685.054
4560.75	647.381
4563.42	693.794
4566.09	672.543
4568.76	692.529
4571.43	651.417
4574.1	661.582
4576.77	657.364
4579.43	658.897
4582.1	656.364
4584.76	664.833
4587.42	664.218
4590.08	659.199
4592.74	645.375
4595.4	646.867
4598.06	644.066
4600.72	666.342
4603.38	638.448
4606.03	648.879
4608.69	651.663
4611.34	634.714
4613.99	655.046
4616.64	631.443
4619.29	626.533
4621.94	642.571
4624.59	609.013
4627.24	636.023
4629.89	636.55
4632.53	632.633
4635.18	627.512
4637.82	621.235
4640.46	618.262
4643.1	602.005
4645.74	611.365
4648.38	596.488
4651.02	627.284
4653.66	614.997
4656.3	609.087
4658.93	628.151
4661.57	623.152
4664.2	623.834
4666.83	630.02
4669.46	624.879
4672.09	606.348
4674.72	615.79
4677.35	587.109
4679.98	586.43
4682.61	620.552
4685.23	580.542
4687.86	591.09
4690.48	590.407
4693.1	593.111
4695.73	585.621
4698.34	597.288
4700.96	599.955
4703.58	611.641
4706.2	611.984
4708.82	578.386
4711.43	585.458
4714.05	603.848
4716.66	591.655
4719.28	602.08
4721.89	570.562
4724.5	599.074
4727.11	567.587
4729.72	555.393
4732.33	581.788
4734.93	596.855
4737.54	581.231
4740.14	565.558
4742.75	599.89
4745.35	577.318
4747.95	554.691
4750.55	555.875
4753.15	583.251
4755.75	577.615
4758.35	571.975
4760.95	575.496
4763.54	542.62
4766.14	550.767
4768.73	560.188
4771.33	566.244
4773.92	577.893
4776.51	595.271
4779.1	554.427
4781.69	563.808
4784.28	577.775
4786.87	566.604
4789.45	560.002
4792.04	540.824
4794.63	549.135
4797.21	560.913
4799.79	531.485
4802.37	558.279
4804.95	553.004
4807.53	559.287
4810.11	549.513
4812.69	553.538
4815.27	546.07
4817.84	520.151
4820.42	525.422
4822.99	549.223
4825.57	534.85
4828.14	525.071
4830.71	531.542
4833.28	520.633
4835.85	535.346
4838.42	511.663
4840.98	527.689
4843.55	557.79
4846.12	538.648
4848.68	514.699
4851.24	524.607
4853.81	513.022
4856.37	528.566
4858.93	519.927
4861.49	540.71
4864.05	542.502
4866.61	534.656
4869.16	538.659
4871.72	504.906
4874.27	525.469
4876.83	511.62
4879.38	494.188
4881.93	492.136
4884.49	499.556
4887.04	506.98
4889.58	526.319
4892.13	513.55
4894.68	535.279
4897.23	505.781
4899.77	490.542
4902.32	519.404
4904.86	473.116
4907.4	491.224
4909.95	486.641
4912.49	495.084
4915.03	521.409
4917.57	479.598
4920.1	483.233
4922.64	492.84
4925.18	512.014
4927.71	510.914
4930.25	489.428
4932.78	494.371
4935.31	486.254
4937.84	486.449
4940.38	474.665
4942.9	478.226
4945.43	493.942
4947.96	477.406
4950.49	472.821
4953.01	449.087
4955.54	496.052
4958.06	483.139
4960.59	487.066
4963.11	446.568
4965.63	483.136
4968.15	482.531
4970.67	460.072
4973.19	448.415
4975.71	492.296
4978.22	469.741
4980.74	466.533
4983.25	460.901
4985.77	464.975
4988.28	467.854
4990.79	462.245
4993.3	467.548
4995.81	459.461
4998.32	477.024