File: Data/3-Raman/raw/bu19w-ff-ore2-fi07-v_150 (500nm)_532nm_edge_100%_x100_vis_lwd_h50um_15sx2_01.txt
#Acq. time (s)=	15
#Accumulations=	2
#Range (cm-¹)=	50...5000
#Windows=	1
#Auto scanning=	Off
#Autofocus=	Off
#Macrospot=	Off
#AutoExposure=	Off
#Spike filter=	Multiple accum.
#Delay time (s)=	2
#Binning=	1
#Readout mode=	Signal
#DeNoise=	Off
#ICS correction=	On
#Dark correction=	Off
#Inst. Process=	Off
#Detector Gain=	Best Dynamic
#Detector ADC=	50 kHz HS
#Detector temperature (°C)=	-60.09
#Instrument=	LabRAM HR Evol
#Detector=	SIN-EM FIVIS
#Objective=	x100_VIS_LWD
#Grating=	150 (500nm)
#ND Filter=	100%
#Laser=	532nm_Edge
#Hole=	49.98
#Temperature=	0
#Range=	Visible
#StageXY=	75x50mm Scan+
#StageZ=	Z motor
#X (µm)=	0
#Y (µm)=	0
#Z (µm)=	-21.5
#Full time(s)=	34
#Project=	21_05_28
#Sample=	BU19w
#Site=
#Title=	BU19w-FF-ore2-FI07-V_150 (500nm)_532nm_Edge_100%_x100_VIS_LWD_H50um_15sX2
#Remark=
#Date=	28.05.2021 15:10
#Acquired=	28.05.2021 15:10:09
51.5961	20021.4
56.2453	20619.9
60.8921	18667.6
65.5367	14903.4
70.1768	11876.9
74.8167	9645.18
79.4543	7893.56
84.0897	6567.1
88.7227	5648.44
93.3513	4878.45
97.9798	4273.76
102.606	3854.26
107.23	3593.99
111.851	3262.09
116.469	3080.74
121.086	3239.02
125.7	4351.31
130.313	5350.02
134.921	4097.3
139.529	2825.07
144.134	2488.56
148.738	2419.35
153.337	2363.97
157.936	2235.66
162.532	2133.66
167.126	2112.83
171.716	2231.78
176.306	2266.61
180.894	2351.9
185.477	2608.61
190.06	3028.12
194.64	3786.56
199.219	4899.81
203.793	5883.22
208.367	6491.88
212.939	5890.92
217.506	4906.08
222.073	3719.57
226.638	3020.78
231.199	2511.14
235.759	2116.56
240.318	1908.96
244.872	1789.15
249.425	1654.75
253.977	1586.22
258.524	1622.45
263.071	1888.36
267.616	2090.68
272.156	1594.99
276.697	1346.35
281.233	1234.11
285.769	1203.72
290.303	1136.65
294.832	1150.2
299.361	1154.2
303.886	1119.3
308.411	1086.33
312.934	1077.96
317.452	1108.49
321.97	1075.72
326.484	1104.8
330.998	1083.62
335.507	1103.34
340.017	1057.29
344.524	1065.85
349.027	1118.37
353.53	1532
358.028	1936.14
362.527	1619.13
367.021	1292.22
371.515	1205.68
376.004	1189.35
380.494	1162.3
384.979	1141.68
389.465	1169.96
393.946	1180.85
398.427	1258.84
402.903	1508.89
407.38	1461.14
411.852	1291.7
416.324	1232.87
420.792	1229.59
425.26	1273.56
429.723	1268.58
434.187	1354.42
438.646	1428.43
443.105	1507.55
447.56	1872.21
452.015	2461.48
456.466	3833.31
460.914	8519.1
465.362	16335.7
469.807	15311.1
474.251	7975.8
478.69	4084.66
483.13	2897.11
487.566	2297.69
491.999	2011.72
496.432	1810.66
500.861	1661.19
505.29	1610.7
509.715	1646.08
514.138	1642.13
518.56	1585
522.979	1545.77
527.395	1454.91
531.811	1408.23
536.223	1338.63
540.635	1336.17
545.042	1346.38
549.448	1339.26
553.853	1338.91
558.255	1285.54
562.654	1302.16
567.053	1286.47
571.448	1287.99
575.841	1261.47
580.232	1270.24
584.622	1295.52
589.009	1272.82
593.393	1276.41
597.777	1314.13
602.157	1308.65
606.535	1285.54
610.913	1332.43
615.287	1292.53
619.659	1281.6
624.029	1254.92
628.398	1294.64
632.763	1248.31
637.127	1286.07
641.488	1316.41
645.849	1266.29
650.206	1243.15
654.561	1250.21
658.914	1273.98
663.267	1299.58
667.615	1245.27
671.962	1261.09
676.307	1251.61
680.649	1278.09
684.991	1303.01
689.33	1330.99
693.666	1342.2
698	1457.15
702.332	1416.05
706.662	1315.3
710.992	1285.37
715.318	1252.67
719.641	1327.84
723.963	1335.06
728.283	1340.26
732.6	1296.72
736.918	1302.94
741.231	1282.91
745.542	1264.84
749.852	1279.31
754.159	1298.8
758.464	1302.55
762.767	1295.08
767.068	1313.76
771.369	1267.53
775.666	1287.52
779.961	1311.95
784.254	1368.81
788.545	1328.28
792.834	1405.17
797.12	1494.2
801.405	1553.99
805.688	1703.95
809.968	1785.2
814.247	1727.08
818.524	1520.73
822.798	1429.79
827.071	1403.03
831.341	1338.92
835.612	1347.49
839.878	1375.82
844.142	1365.41
848.405	1393.09
852.665	1362.59
856.923	1342.04
861.18	1369.95
865.434	1375.55
869.686	1357.6
873.936	1382.21
878.185	1445.88
882.431	1394.06
886.675	1364.79
890.915	1370.79
895.155	1368.62
899.393	1343.95
903.63	1334.16
907.864	1363.71
912.096	1353.65
916.326	1401.74
920.554	1354.4
924.78	1360.56
929.004	1326.16
933.227	1357.93
937.447	1357.3
941.665	1368.06
945.881	1364.71
950.095	1336.77
954.305	1405.2
958.516	1359.7
962.724	1366.6
966.93	1344.95
971.134	1400.97
975.337	1345.86
979.537	1396.95
983.735	1392.14
987.93	1394.7
992.124	1392.11
996.316	1369.36
1000.51	1414.21
1004.7	1398.98
1008.88	1384.99
1013.06	1389.07
1017.25	1399.2
1021.43	1418.92
1025.61	1411.67
1029.78	1447.68
1033.96	1349.7
1038.13	1409.42
1042.3	1399.93
1046.47	1414.86
1050.63	1385.72
1054.8	1407.23
1058.96	1415.54
1063.12	1431.81
1067.28	1493.83
1071.44	1467.22
1075.59	1530.51
1079.74	1620.39
1083.89	1768.34
1088.04	1684.74
1092.19	1524.71
1096.33	1489.57
1100.48	1456.21
1104.62	1463.07
1108.76	1465.41
1112.89	1403.14
1117.03	1435.1
1121.16	1421.16
1125.29	1448.43
1129.42	1412.95
1133.55	1439.21
1137.68	1464.11
1141.8	1458.19
1145.92	1459.73
1150.04	1470.1
1154.16	1548.72
1158.27	1608.25
1162.39	1667.43
1166.5	1564.05
1170.61	1510.86
1174.72	1474.72
1178.82	1449.71
1182.93	1439.09
1187.03	1433.17
1191.13	1449.02
1195.23	1444.9
1199.33	1456.66
1203.42	1475.1
1207.51	1495.34
1211.6	1483.12
1215.69	1504.36
1219.78	1497.43
1223.86	1491.75
1227.95	1481.42
1232.03	1517.72
1236.11	1518.11
1240.18	1542.34
1244.26	1495.32
1248.33	1523.8
1252.41	1584.05
1256.48	1558.78
1260.54	1580.73
1264.61	1724.98
1268.67	1704.63
1272.74	1619.34
1276.8	1639.22
1280.86	1844.94
1284.91	3048.22
1288.97	2359.17
1293.02	1701.12
1297.07	1623.34
1301.12	1575.57
1305.17	1546.61
1309.21	1584.08
1313.25	1538.7
1317.3	1558.27
1321.34	1566.42
1325.37	1582.01
1329.41	1564.2
1333.44	1508.11
1337.48	1595.99
1341.5	1566.24
1345.53	1608.34
1349.56	1556.53
1353.59	1591.52
1357.61	1602.62
1361.63	1594.7
1365.65	1648.47
1369.66	1659.82
1373.68	1719.91
1377.69	1741.66
1381.7	1879.92
1385.72	2735.59
1389.72	4163.02
1393.73	2339.15
1397.73	1720.76
1401.74	1656.33
1405.74	1693.29
1409.73	1850.71
1413.73	1736.26
1417.73	1630.59
1421.72	1632.4
1425.71	1601.4
1429.7	1610.07
1433.69	1608.01
1437.67	1597.04
1441.66	1615.71
1445.64	1586.74
1449.62	1602.1
1453.6	1603.35
1457.57	1605.44
1461.55	1595.41
1465.52	1594.72
1469.49	1598.85
1473.46	1577.67
1477.43	1601.44
1481.39	1609.27
1485.36	1613.05
1489.32	1616.7
1493.28	1585.34
1497.24	1555.07
1501.19	1576.63
1505.15	1611.06
1509.1	1578.83
1513.05	1646.8
1517	1602.17
1520.95	1619.87
1524.9	1625.05
1528.84	1607.08
1532.78	1598.05
1536.72	1636.56
1540.66	1621.81
1544.6	1642.92
1548.53	1609.77
1552.46	1624.1
1556.4	1629.51
1560.32	1603.69
1564.25	1629
1568.18	1633.8
1572.1	1677.13
1576.02	1640.22
1579.94	1657.34
1583.86	1633.88
1587.78	1645.02
1591.69	1667.65
1595.61	1645.97
1599.52	1659.89
1603.43	1676.8
1607.34	1734.24
1611.24	1676.59
1615.15	1724.55
1619.05	1748.76
1622.95	1691.45
1626.85	1699.54
1630.74	1708.82
1634.64	1716.73
1638.53	1743.7
1642.42	1723.27
1646.31	1733.84
1650.2	1705.28
1654.09	1696.92
1657.97	1742.16
1661.86	1693.24
1665.74	1709.3
1669.62	1692.49
1673.49	1705.91
1677.37	1695.19
1681.24	1687.41
1685.12	1695.52
1688.99	1645.94
1692.86	1698.6
1696.72	1716.46
1700.59	1668.06
1704.45	1694.8
1708.31	1682.05
1712.17	1687.99
1716.03	1671.19
1719.89	1674.38
1723.74	1671.93
1727.6	1692.9
1731.45	1654.29
1735.3	1721.95
1739.14	1652.52
1742.99	1700.79
1746.83	1664.21
1750.68	1705.01
1754.52	1659.99
1758.36	1663.31
1762.19	1681.47
1766.03	1666.86
1769.86	1727.2
1773.69	1709.44
1777.53	1658.18
1781.35	1716.42
1785.18	1694.83
1789	1686.45
1792.83	1722.15
1796.65	1685.75
1800.47	1703.67
1804.29	1708.3
1808.1	1705.27
1811.92	1710.51
1815.73	1682.44
1819.54	1738.52
1823.35	1683.77
1827.16	1685.31
1830.97	1713.73
1834.77	1720
1838.58	1675.13
1842.38	1690.28
1846.18	1713.43
1849.97	1702.98
1853.77	1721.72
1857.56	1702.57
1861.36	1703.46
1865.15	1682.76
1868.93	1718.03
1872.72	1729.24
1876.51	1738.92
1880.29	1708.99
1884.07	1716.77
1887.86	1724.59
1891.63	1740.83
1895.41	1718.46
1899.19	1737.51
1902.96	1744.43
1906.73	1715.79
1910.5	1677.16
1914.27	1785.71
1918.04	1738.6
1921.8	1784.03
1925.57	1725.11
1929.33	1753.52
1933.09	1728.26
1936.85	1741.06
1940.6	1718.36
1944.36	1720.79
1948.11	1722.27
1951.87	1745.85
1955.61	1751.86
1959.36	1774.81
1963.11	1722.02
1966.86	1764
1970.6	1756.58
1974.34	1719.45
1978.08	1757.92
1981.82	1721.14
1985.56	1769.18
1989.29	1730.11
1993.02	1736.52
1996.75	1721.17
2000.49	1767.71
2004.21	1766
2007.94	1772.41
2011.67	1764.54
2015.39	1775.15
2019.11	1786.58
2022.83	1760.43
2026.55	1774.8
2030.27	1773.66
2033.98	1810.91
2037.69	1761.82
2041.41	1762.91
2045.12	1773.02
2048.82	1752.95
2052.53	1805.57
2056.24	1765.8
2059.94	1770.92
2063.64	1774.4
2067.34	1800.4
2071.04	1769.5
2074.74	1756.06
2078.43	1800.03
2082.13	1787.78
2085.82	1787.31
2089.51	1762.41
2093.2	1779.42
2096.88	1810.32
2100.57	1787.91
2104.25	1768.6
2107.94	1772.23
2111.62	1808.13
2115.3	1755.63
2118.97	1748.48
2122.65	1823.27
2126.32	1788.07
2129.99	1797.15
2133.66	1769.01
2137.33	1782.41
2141	1796.39
2144.67	1775.96
2148.33	1798.7
2151.99	1783.69
2155.66	1763.29
2159.31	1818.08
2162.97	1819
2166.63	1788.27
2170.28	1824.48
2173.94	1781.21
2177.59	1812.15
2181.24	1796.89
2184.89	1822.49
2188.53	1777.63
2192.18	1799.87
2195.82	1789.2
2199.46	1789.84
2203.1	1808.92
2206.74	1783.6
2210.38	1790.51
2214.01	1815.09
2217.65	1782.07
2221.28	1811.44
2224.91	1730.62
2228.54	1759.97
2232.16	1795.91
2235.79	1810.87
2239.41	1781.39
2243.04	1832.42
2246.66	1832.47
2250.28	1796.34
2253.89	1805.93
2257.51	1800.79
2261.12	1792.78
2264.74	1796.7
2268.35	1797.06
2271.96	1792.19
2275.57	1793.4
2279.17	1798.82
2282.78	1847.41
2286.38	1809.15
2289.98	1818.07
2293.58	1768.1
2297.18	1791
2300.78	1778.01
2304.37	1799.76
2307.97	1817.34
2311.56	1805.29
2315.15	1794.85
2318.74	1775.58
2322.33	1747.39
2325.91	1842.14
2329.5	2068.85
2333.08	1952.03
2336.66	1781.51
2340.24	1769.41
2343.82	1816.36
2347.4	1744.71
2350.97	1761.21
2354.54	1785.04
2358.12	1763.89
2361.69	1789.25
2365.26	1742.93
2368.82	1770.17
2372.39	1803.31
2375.95	1785.35
2379.52	1748.12
2383.08	1786.78
2386.64	1763.86
2390.19	1805.61
2393.75	1813.67
2397.31	1770.92
2400.86	1796.64
2404.41	1762.85
2407.96	1750.35
2411.51	1775.28
2415.06	1817.2
2418.6	1808.17
2422.15	1819.65
2425.69	1736.67
2429.23	1780.33
2432.77	1798.62
2436.31	1790.49
2439.84	1766.7
2443.38	1796.03
2446.91	1775.12
2450.44	1820.94
2453.97	1803.48
2457.5	1772.52
2461.03	1776.63
2464.55	1756.07
2468.08	1781.14
2471.6	1804.88
2475.12	1763.32
2478.64	1798.89
2482.16	1742.32
2485.67	1805.73
2489.19	1733.39
2492.7	1791.82
2496.21	1756.23
2499.72	1774.76
2503.23	1748.68
2506.74	1800.83
2510.25	1771.3
2513.75	1775.5
2517.25	1791.27
2520.75	1782.25
2524.25	1795.16
2527.75	1762.68
2531.25	1776.9
2534.74	1751.67
2538.24	1795.26
2541.73	1726.7
2545.22	1773.4
2548.71	1771.03
2552.2	1768.75
2555.68	1767.87
2559.17	1773.42
2562.65	1763.23
2566.13	1730.52
2569.61	1764.41
2573.09	1762.47
2576.57	1779.6
2580.04	1789.64
2583.51	1747.99
2586.99	1772.27
2590.46	1768.73
2593.93	1750.93
2597.4	1800.4
2600.86	1788.54
2604.33	1750.6
2607.79	1792.05
2611.25	1748.57
2614.71	1740.33
2618.17	1752.9
2621.63	1758.98
2625.09	1720.5
2628.54	1719.04
2631.99	1767.22
2635.45	1763.09
2638.9	1778.57
2642.34	1728.58
2645.79	1703.24
2649.24	1751.36
2652.68	1733.16
2656.12	1714.57
2659.56	1734.62
2663.01	1697.56
2666.44	1733.25
2669.88	1724.43
2673.32	1759.75
2676.75	1723.89
2680.18	1757.72
2683.61	1711.45
2687.04	1754.57
2690.47	1745.6
2693.9	1727.01
2697.32	1767.66
2700.75	1729.57
2704.17	1741.8
2707.59	1751.31
2711.01	1781.58
2714.43	1784.32
2717.84	1738.08
2721.26	1756.41
2724.67	1744.21
2728.08	1777.89
2731.49	1726.66
2734.9	1737.94
2738.31	1717.37
2741.71	1721.07
2745.12	1753.54
2748.52	1700.31
2751.92	1725.07
2755.32	1730.89
2758.72	1738.4
2762.12	1762.91
2765.52	1747.39
2768.91	1708.98
2772.3	1745.66
2775.7	1720.94
2779.09	1771.29
2782.47	1757.33
2785.86	1744.18
2789.25	1739.46
2792.63	1730.91
2796.01	1713.87
2799.4	1723.12
2802.78	1761.17
2806.15	1728.87
2809.53	1712.51
2812.91	1724.14
2816.28	1709.48
2819.65	1745.24
2823.03	1702.82
2826.4	1706.4
2829.76	1714.76
2833.13	1698.19
2836.5	1755.54
2839.86	1713.5
2843.22	1710.93
2846.59	1707.83
2849.95	1735.19
2853.3	1721.93
2856.66	1688.81
2860.02	1711.98
2863.37	1739.15
2866.72	1725.21
2870.08	1690.59
2873.43	1707.46
2876.77	1691.39
2880.12	1694.07
2883.47	1757.01
2886.81	1705.79
2890.15	1713.91
2893.5	1715.33
2896.84	1748.47
2900.17	1690.61
2903.51	1712.84
2906.85	1658.24
2910.18	1718.92
2913.52	1717.97
2916.85	1662.01
2920.18	1694.75
2923.51	1666.85
2926.83	1730.52
2930.16	1722.07
2933.48	1712.48
2936.81	1742.27
2940.13	1710.74
2943.45	1684.91
2946.77	1703.41
2950.09	1733.24
2953.4	1698.09
2956.72	1712.83
2960.03	1690.29
2963.34	1704.52
2966.65	1768.55
2969.96	1731.79
2973.27	1735.67
2976.58	1753.7
2979.88	1772.96
2983.19	1687.85
2986.49	1719.21
2989.79	1716.88
2993.09	1676.1
2996.39	1751.9
2999.68	1705.64
3002.98	1723.28
3006.27	1755.04
3009.57	1755.91
3012.86	1717.33
3016.15	1753.17
3019.43	1756.96
3022.72	1733.36
3026.01	1751.27
3029.29	1740.9
3032.57	1772.06
3035.86	1752.11
3039.14	1752.9
3042.41	1766
3045.69	1710.99
3048.97	1759.18
3052.24	1790.35
3055.52	1800.75
3058.79	1753.23
3062.06	1799.02
3065.33	1791.02
3068.6	1804.62
3071.86	1773.22
3075.13	1761.18
3078.39	1819.21
3081.65	1787.52
3084.91	1795.3
3088.17	1823.88
3091.43	1802.65
3094.69	1846.14
3097.95	1814.12
3101.2	1860.28
3104.45	1830.04
3107.7	1878.64
3110.95	1831.84
3114.2	1922.45
3117.45	1849.5
3120.7	1895.61
3123.94	1905.54
3127.18	1895.44
3130.43	1960.55
3133.67	1964.72
3136.91	1962.16
3140.14	1967.12
3143.38	1964.43
3146.61	1997.98
3149.85	1984.94
3153.08	2003.41
3156.31	1996.99
3159.54	1996.36
3162.77	2073.9
3166	2064.62
3169.22	2127.68
3172.45	2064.62
3175.67	2091.17
3178.89	2099.42
3182.11	2166.77
3185.33	2141.64
3188.55	2206.84
3191.77	2178.54
3194.98	2258.88
3198.2	2232.44
3201.41	2240.26
3204.62	2237.69
3207.83	2255.19
3211.04	2229.01
3214.25	2239.15
3217.45	2280.84
3220.66	2320.62
3223.86	2343.36
3227.06	2325.43
3230.26	2353.21
3233.46	2356.44
3236.66	2341.43
3239.85	2384.99
3243.05	2398.25
3246.24	2408.78
3249.44	2390.74
3252.63	2400.57
3255.82	2420.02
3259.01	2389.8
3262.19	2386.9
3265.38	2418.04
3268.56	2464.14
3271.75	2443.12
3274.93	2477.37
3278.11	2454.26
3281.29	2508
3284.47	2539.29
3287.64	2463.75
3290.82	2492.96
3293.99	2460.4
3297.17	2503.03
3300.34	2461.88
3303.51	2515.55
3306.68	2534.28
3309.84	2545.14
3313.01	2537.53
3316.18	2538.33
3319.34	2546.65
3322.5	2571.93
3325.66	2573.51
3328.82	2598.76
3331.98	2614.58
3335.14	2630.56
3338.29	2637.3
3341.45	2648.94
3344.6	2684.21
3347.75	2646.59
3350.9	2647.33
3354.05	2705.54
3357.2	2731.06
3360.35	2734.1
3363.49	2731.82
3366.64	2736.2
3369.78	2780.35
3372.92	2798.23
3376.06	2798.51
3379.2	2825.36
3382.34	2788.12
3385.48	2818.78
3388.61	2890.38
3391.75	2942.24
3394.88	2901.2
3398.01	2929.49
3401.14	2919.63
3404.27	2965.05
3407.4	2980.44
3410.52	2957.03
3413.65	2982.04
3416.77	2987.32
3419.89	2965.72
3423.01	3000.09
3426.13	3028.15
3429.25	3007.95
3432.37	2988.28
3435.49	2988.99
3438.6	2943.21
3441.72	2990.38
3444.83	3023.14
3447.94	3015.21
3451.05	3005.3
3454.16	3018.78
3457.26	2957.89
3460.37	3022.26
3463.47	2932.45
3466.58	2986.07
3469.68	2901.54
3472.78	2897.25
3475.88	2901.44
3478.98	2821.55
3482.07	2849.71
3485.17	2886.41
3488.26	2845.83
3491.36	2817.05
3494.45	2769.25
3497.54	2801.56
3500.63	2734.64
3503.72	2684.79
3506.81	2687.32
3509.89	2643.67
3512.98	2591.72
3516.06	2553.51
3519.14	2579.48
3522.22	2544.51
3525.3	2517.88
3528.38	2463.48
3531.45	2501.33
3534.53	2432.9
3537.61	2403.89
3540.68	2375.14
3543.75	2335.13
3546.82	2293.77
3549.89	2276.69
3552.96	2264.68
3556.03	2229.77
3559.09	2201.81
3562.16	2156.79
3565.22	2200.33
3568.28	2125.1
3571.34	2084.63
3574.4	2038.37
3577.46	2046.26
3580.52	2035.97
3583.57	2011.28
3586.63	2006.31
3589.68	1967.2
3592.73	1917.42
3595.78	1915.96
3598.83	1900.11
3601.88	1877.64
3604.93	1872.97
3607.97	1839.78
3611.02	1826.46
3614.06	1822.52
3617.1	1779.78
3620.14	1800.42
3623.18	1744.7
3626.22	1740.01
3629.26	1719.41
3632.3	1702.51
3635.33	1668.59
3638.36	1695.34
3641.4	1681.85
3644.43	1633.74
3647.46	1640.64
3650.49	1595.32
3653.51	1572.81
3656.54	1521.07
3659.57	1548.92
3662.59	1525.82
3665.61	1488.26
3668.63	1473.54
3671.65	1478.01
3674.67	1438.22
3677.69	1463.6
3680.71	1421.09
3683.72	1411.53
3686.74	1374.54
3689.75	1403.8
3692.76	1344.12
3695.77	1332.7
3698.78	1355.14
3701.79	1379.79
3704.79	1335.17
3707.8	1360.78
3710.81	1348.23
3713.81	1302.28
3716.81	1311.31
3719.81	1296.64
3722.81	1273.23
3725.81	1284.93
3728.81	1294.62
3731.8	1275.64
3734.8	1285.1
3737.79	1265.86
3740.78	1257.93
3743.77	1238.43
3746.76	1240.73
3749.75	1233.39
3752.74	1268.71
3755.73	1262.2
3758.71	1242.44
3761.7	1230.26
3764.68	1260.63
3767.66	1269.22
3770.64	1239.09
3773.62	1228.97
3776.6	1238.81
3779.58	1230.76
3782.55	1236.01
3785.53	1243.17
3788.5	1220.19
3791.47	1248.27
3794.44	1212.36
3797.41	1211.47
3800.38	1206.88
3803.35	1205.28
3806.32	1209.41
3809.28	1239.09
3812.24	1200.81
3815.21	1213.6
3818.17	1205.62
3821.13	1184.43
3824.09	1157.57
3827.04	1209.39
3830	1217.69
3832.96	1166.23
3835.91	1194.55
3838.86	1208.72
3841.82	1187.75
3844.77	1192.42
3847.72	1160.94
3850.67	1198.07
3853.61	1179.06
3856.56	1120.92
3859.5	1182.09
3862.45	1151.59
3865.39	1147.77
3868.33	1195.66
3871.27	1194.64
3874.21	1204.13
3877.15	1160.8
3880.09	1162.42
3883.02	1185.05
3885.96	1171.03
3888.89	1172.3
3891.82	1162.94
3894.75	1134.28
3897.68	1133.37
3900.61	1151.55
3903.54	1159.13
3906.47	1154.06
3909.39	1151.05
3912.31	1146.97
3915.24	1163.91
3918.16	1126.03
3921.08	1104.69
3924	1170.49
3926.92	1139.2
3929.83	1144.28
3932.75	1125.34
3935.67	1108.6
3938.58	1134.24
3941.49	1131.35
3944.4	1114
3947.31	1109.15
3950.22	1118.78
3953.13	1102.64
3956.04	1133.47
3958.94	1129.93
3961.85	1097.69
3964.75	1130.67
3967.65	1102.36
3970.55	1068.33
3973.45	1125.49
3976.35	1111.61
3979.25	1113.97
3982.15	1089.36
3985.04	1146.42
3987.94	1142.87
3990.83	1101.78
3993.72	1093.24
3996.61	1082.02
3999.5	1132.38
4002.39	1080.76
4005.28	1138.92
4008.16	1069.04
4011.05	1102.25
4013.93	1055.44
4016.81	1103.13
4019.7	1060.15
4022.58	1107.88
4025.46	1056.17
4028.33	1088.51
4031.21	1069.64
4034.09	1074
4036.96	1072.57
4039.84	1075.05
4042.71	1062.98
4045.58	1080.76
4048.45	1095.69
4051.32	1062.21
4054.19	1041.37
4057.05	1058.47
4059.92	1076.51
4062.78	1039.15
4065.65	1036.75
4068.51	1090.76
4071.37	1023.16
4074.23	1039.22
4077.09	1003.65
4079.95	1034.3
4082.81	1021.1
4085.66	1017.66
4088.52	1036.59
4091.37	1011.62
4094.22	1038.45
4097.07	1039.83
4099.92	1029.53
4102.77	1033.87
4105.62	1023.51
4108.47	1037.47
4111.31	1012.31
4114.16	1022.25
4117	1031.11
4119.84	1005.57
4122.69	1035.83
4125.53	1021.19
4128.36	1010.5
4131.2	982.451
4134.04	1021.13
4136.88	1021.95
4139.71	984.243
4142.54	1013.25
4145.38	995.557
4148.21	978.264
4151.04	985.516
4153.87	989.607
4156.69	1043.27
4159.52	992.728
4162.35	968.023
4165.17	990.407
4168	993.209
4170.82	1010.73
4173.64	969.625
4176.46	973.536
4179.28	988.204
4182.1	1006.87
4184.91	979.599
4187.73	953.357
4190.54	968.227
4193.36	932.357
4196.17	973.922
4198.98	955.9
4201.79	971.156
4204.6	955.08
4207.41	981.154
4210.22	973.885
4213.02	954.777
4215.83	963.172
4218.63	963.299
4221.44	950.553
4224.24	970.248
4227.04	959.239
4229.84	937.505
4232.64	962.263
4235.43	939.648
4238.23	946.792
4241.02	920.207
4243.82	948.275
4246.61	938.634
4249.4	933.893
4252.19	931.048
4254.98	923.17
4257.77	946.208
4260.56	927.207
4263.35	929.269
4266.13	953.463
4268.92	938.572
4271.7	930.674
4274.48	899.546
4277.26	916.592
4280.04	930.506
4282.82	900.924
4285.6	936.932
4288.38	936.438
4291.15	907.496
4293.93	924.059
4296.7	943.809
4299.47	891.676
4302.25	910.403
4305.02	898.691
4307.79	906.256
4310.55	891.523
4313.32	891.092
4316.09	910.854
4318.85	900.022
4321.62	893.189
4324.38	889.33
4327.14	878.297
4329.9	881.552
4332.66	894.894
4335.42	904.22
4338.18	896.133
4340.94	860.701
4343.69	908.848
4346.45	884.715
4349.2	884.11
4351.95	872.281
4354.7	867.829
4357.45	869.402
4360.2	874.047
4362.95	873.526
4365.7	875.14
4368.44	837.737
4371.19	869.079
4373.93	863.361
4376.68	868.909
4379.42	863.09
4382.16	842.863
4384.9	861.73
4387.64	872.586
4390.37	843.66
4393.11	861.188
4395.85	862.93
4398.58	818.519
4401.31	867.145
4404.05	827.685
4406.78	825.541
4409.51	846.286
4412.24	862.816
4414.96	830.317
4417.69	807.1
4420.42	839.806
4423.14	846.638
4425.87	839.956
4428.59	819.688
4431.31	841.213
4434.03	831.36
4436.75	819.357
4439.47	816.726
4442.19	805.622
4444.91	814.457
4447.62	820.099
4450.34	833.097
4453.05	826.073
4455.76	796.969
4458.47	795.093
4461.19	813.156
4463.89	808.202
4466.6	793.755
4469.31	806.71
4472.02	813.396
4474.72	808.572
4477.43	799.6
4480.13	791.735
4482.83	793.407
4485.53	763.381
4488.23	814.662
4490.93	805.671
4493.63	765.774
4496.33	788.188
4499.02	803.353
4501.72	787.757
4504.41	802.821
4507.11	756.482
4509.8	769.528
4512.49	763.488
4515.18	785.063
4517.87	772.691
4520.56	774.157
4523.24	760.82
4525.93	770.871
4528.61	755.369
4531.3	751.59
4533.98	760.618
4536.66	748.348
4539.34	785.196
4542.02	768.729
4544.7	769.334
4547.38	748.566
4550.05	734.198
4552.73	719.877
4555.4	785.072
4558.08	720.515
4560.75	732.406
4563.42	752.015
4566.09	722.241
4568.76	751.007
4571.43	771.828
4574.1	750.589
4576.77	748.559
4579.43	733.858
4582.1	727.057
4584.76	727.995
4587.42	721.976
4590.08	744.257
4592.74	705.385
4595.4	726.565
4598.06	739.119
4600.72	708.979
4603.38	730.358
4606.03	695.971
4608.69	722.913
4611.34	721.39
4613.99	693.482
4616.64	706.183
4619.29	723.346
4621.94	730.67
4624.59	724.753
4627.24	696.701
4629.89	669.675
4632.53	716.616
4635.18	694.963
4637.82	692.043
4640.46	713.464
4643.1	691.724
4645.74	678.986
4648.38	675.28
4651.02	691.735
4653.66	688.463
4656.3	702.707
4658.93	701.723
4661.57	675.592
4664.2	699.789
4666.83	690.394
4669.46	708.793
4672.09	670.174
4674.72	668.46
4677.35	661.128
4679.98	681.829
4682.61	690.189
4685.23	674.957
4687.86	657.454
4690.48	665.826
4693.1	664.081
4695.73	661.148
4698.34	661.586
4700.96	693.645
4703.58	625.195
4706.2	682.054
4708.82	676.762
4711.43	664.65
4714.05	664.968
4716.66	676.582
4719.28	658.72
4721.89	681.615
4724.5	664.819
4727.11	670.784
4729.72	658.643
4732.33	627.195
4734.93	657.051
4737.54	651.683
4740.14	648.544
4742.75	653.339
4745.35	652.398
4747.95	666.198
4750.55	650.323
4753.15	625.359
4755.75	625.418
4758.35	623.196
4760.95	622.173
4763.54	637.137
4766.14	647.593
4768.73	620.595
4771.33	633.532
4773.92	613.263
4776.51	639.788
4779.1	634.365
4781.69	618.647
4784.28	630.352
4786.87	640.931
4789.45	628.643
4792.04	628.959
4794.63	616.703
4797.21	618.208
4799.79	636.979
4802.37	615.656
4804.95	623.062
4807.53	617.917
4810.11	609.356
4812.69	585.794
4815.27	622.186
4817.84	647.157
4820.42	609.813
4822.99	611.727
4825.57	617.135
4828.14	621.382
4830.71	609.385
4833.28	613.707
4835.85	613.405
4838.42	580.507
4840.98	604.826
4843.55	605.784
4846.12	619.533
4848.68	608.601
4851.24	581.004
4853.81	584.716
4856.37	590.889
4858.93	589.407
4861.49	589.061
4864.05	599.173
4866.61	603.186
4869.16	576.501
4871.72	574.752
4874.27	581.155
4876.83	575.646
4879.38	600.975
4881.93	597.806
4884.49	591.032
4887.04	552.15
4889.58	569.138
4892.13	539.733
4894.68	592.439
4897.23	572.504
4899.77	584.716
4902.32	582.615
4904.86	568.574
4907.4	566.43
4909.95	539.187
4912.49	565.554
4915.03	551.272
4917.57	575.159
4920.1	566.857
4922.64	548.994
4925.18	563.395
4927.71	538.402
4930.25	545.602
4932.78	532.629
4935.31	555.633
4937.84	547.479
4940.38	517.762
4942.9	550.049
4945.43	559.801
4947.96	561.267
4950.49	518.366
4953.01	525.834
4955.54	528.443
4958.06	547.958
4960.59	538.715
4963.11	531.915
4965.63	563.76
4968.15	535.543
4970.67	538.459
4973.19	535.322
4975.71	556.325
4978.22	537.451
4980.74	514.941
4983.25	520.255
4985.77	547.422
4988.28	527.322
4990.79	521.772
4993.3	523.484
4995.81	528.836
4998.32	507.485