File: Data/3-Raman/raw/bu19(2)w-a-ff1-fi06-v_1800 (450-850nm)_532nm_edge_100%_x100_vis_lwd_h100um_30sx2_01.txt
#Acq. time (s)=	30
#Accumulations=	2
#Range (cm-¹)=	1200...2365
#Windows=	3
#Auto scanning=	Off
#Autofocus=	Off
#Macrospot=	Off
#AutoExposure=	Off
#Spike filter=	Multiple accum.
#Delay time (s)=	2
#Binning=	1
#Readout mode=	Signal
#DeNoise=	Off
#ICS correction=	On
#Dark correction=	Off
#Inst. Process=	Off
#Detector Gain=	Best Dynamic
#Detector ADC=	50 kHz HS
#Detector temperature (°C)=	-60.09
#Instrument=	LabRAM HR Evol
#Detector=	SIN-EM FIVIS
#Objective=	x100_VIS_LWD
#Grating=	1800 (450-850nm)
#ND Filter=	100%
#Laser=	532nm_Edge
#Hole=	100.021
#Temperature=	0
#Range=	Visible
#StageXY=	75x50mm Scan+
#StageZ=	Z motor
#X (µm)=	0
#Y (µm)=	0
#Z (µm)=	-16.9
#Full time(mm:ss)=	3:18
#Project=	21_11_26
#Sample=	BU19(2)w
#Site=
#Title=	BU19(2)w-A-FF1-FI06-V_1800 (450-850nm)_532nm_Edge_100%_x100_VIS_LWD_H100um_30sX2
#Remark=
#Date=	26.11.2021 13:46
#Acquired=	26.11.2021 13:46:13
1202.72	180.133
1203.84	174.825
1204.95	171.473
1206.06	164.78
1207.17	170.894
1208.28	164.29
1209.39	167.324
1210.5	167.245
1211.61	156.316
1212.72	157.167
1213.83	151.696
1214.94	155.933
1216.05	156.966
1217.16	154.611
1218.27	156.558
1219.38	150.091
1220.49	151.084
1221.6	143.608
1222.71	159.299
1223.81	149.489
1224.92	144.037
1226.03	141.931
1227.14	152.456
1228.25	152.11
1229.35	144.391
1230.46	155.315
1231.57	158.029
1232.67	150.672
1233.78	156.94
1234.89	148.591
1235.99	147.605
1237.1	158.08
1238.2	149.477
1239.31	146.153
1240.41	148.196
1241.52	151.354
1242.62	145.007
1243.73	152.388
1244.83	141.902
1245.94	151.194
1247.04	146.921
1248.14	163.627
1249.25	143.66
1250.35	148.884
1251.45	153.973
1252.56	150.726
1253.66	149.576
1254.76	150.702
1255.87	155.944
1256.97	145.53
1258.07	162.2
1259.17	152.721
1260.27	154.905
1261.37	162.034
1262.48	182.248
1263.58	209.912
1264.68	168.736
1265.78	171.705
1266.88	165.435
1267.98	154.086
1269.08	157.431
1270.18	152.191
1271.28	155.185
1272.38	152.059
1273.47	153.284
1274.57	154.477
1275.67	152.395
1276.77	157.757
1277.87	158.935
1278.97	167.49
1280.07	171.726
1281.16	218.009
1282.26	410.78
1283.36	876.688
1284.45	656.309
1285.55	243.544
1286.65	185.594
1287.75	167.62
1288.84	155.997
1289.94	150.82
1291.03	157.178
1292.13	145.572
1293.22	153.985
1294.32	153.115
1295.42	147.875
1296.51	151.353
1297.61	151.328
1298.7	147.014
1299.79	147.988
1300.89	144.862
1301.98	144.879
1303.08	147.027
1304.17	153.303
1305.26	142.726
1306.35	146.819
1307.45	137.295
1308.54	141.52
1309.63	140.504
1310.73	141.578
1311.82	144.762
1312.91	140.604
1314	142.667
1315.09	145.844
1316.18	136.41
1317.28	143.776
1318.37	146.986
1319.46	135.369
1320.55	144.875
1321.64	142.659
1322.73	136.198
1323.82	151.961
1324.91	140.367
1326	143.432
1327.09	144.244
1328.18	145.54
1329.27	134.105
1330.35	140.413
1331.44	147.67
1332.53	143.243
1333.62	144.102
1334.71	134.487
1335.79	133.323
1336.88	142.672
1337.97	131.083
1339.06	137.26
1340.14	146.676
1341.23	141.448
1342.32	142.437
1343.4	141.263
1344.49	141.246
1345.58	145.357
1346.66	151.414
1347.75	139.759
1348.83	145.943
1349.92	130.214
1351	137.393
1352.09	143.526
1353.17	140.49
1354.25	142.711
1355.34	147.572
1356.42	136.123
1357.51	143.321
1358.59	145.303
1359.67	141.048
1360.76	135.729
1361.84	134.647
1362.92	151.159
1364	148.098
1365.09	132.551
1366.17	143.816
1367.25	142.623
1368.33	149.849
1369.41	174.7
1370.5	147.773
1371.58	139.383
1372.66	147.427
1373.74	147.322
1374.82	151.392
1375.9	145.202
1376.98	146.161
1378.06	146.105
1379.14	154.586
1380.22	161.716
1381.3	161.379
1382.38	172.507
1383.46	176.358
1384.54	217.264
1385.61	358.055
1386.69	1272.43
1387.77	1183.03
1388.85	281.721
1389.93	192.952
1391	165.999
1392.08	157.665
1393.16	162.657
1394.23	141.101
1395.31	151.322
1396.39	150.342
1397.46	145.147
1398.54	135.906
1399.62	151.309
1400.69	143.169
1401.77	157.569
1402.84	140.369
1403.92	148.71
1404.99	147.577
1406.07	151.579
1407.14	172.032
1408.22	200.786
1409.29	205.97
1410.37	153.697
1411.44	138.169
1412.51	139.164
1413.59	146.733
1414.66	136.295
1415.73	143.541
1416.81	134.341
1417.88	138.51
1418.95	142.643
1420.02	127.194
1421.1	139.41
1422.17	143.523
1423.24	140.733
1424.31	140.269
1425.38	136.17
1426.45	135.179
1427.52	126.844
1428.59	145.151
1429.67	133.925
1430.74	138.138
1431.81	131.127
1432.87	130.026
1433.95	137.002
1435.01	137.046
1436.08	130.895
1437.15	134.95
1438.22	127.744
1439.29	135.981
1440.36	130.952
1441.43	135.087
1442.49	129.943
1443.56	137.11
1444.63	142.206
1445.7	131.029
1446.77	129.958
1447.83	132.984
1448.9	133.022
1449.97	134.024
1451.03	140.108
1452.1	131.859
1453.17	135.949
1454.23	135.968
1455.3	133.907
1456.36	135.986
1457.43	144.125
1458.49	138.977
1459.56	132.851
1460.62	134.878
1461.69	125.601
1462.75	136.768
1463.82	136.644
1464.88	128.604
1465.94	125.165
1467.01	131.244
1468.07	130.2
1469.13	129.159
1470.2	118.881
1471.26	132.062
1472.32	128.933
1473.39	132.982
1474.45	124.774
1475.51	121.739
1476.57	131.868
1477.63	129.767
1478.69	126.667
1479.76	149.95
1480.82	128.474
1481.88	119.293
1482.94	120.39
1484	125.488
1485.06	129.281
1486.12	127.214
1487.18	126.212
1488.24	131.209
1489.3	123.005
1490.36	122.968
1491.42	124.923
1492.48	132.996
1493.53	121.857
1494.59	136.003
1495.65	130.893
1496.71	132.782
1497.77	123.659
1498.82	127.687
1499.88	125.695
1500.94	127.721
1502	124.64
1503.05	121.564
1504.11	118.476
1505.17	131.595
1506.22	134.497
1507.28	132.491
1508.34	125.435
1509.39	135.511
1510.45	122.428
1511.5	129.364
1512.56	134.135
1513.61	125.954
1514.67	131.054
1515.72	131.941
1516.78	136.833
1517.83	139.816
1518.88	125.824
1519.94	128.866
1520.99	135.869
1522.05	131.878
1523.1	136.834
1524.15	129.664
1525.2	131.609
1526.26	129.657
1527.31	137.742
1528.36	129.672
1529.41	117.601
1530.47	127.578
1531.52	127.659
1532.57	122.627
1533.62	115.733
1534.67	128.789
1535.72	135.745
1536.77	131.551
1537.82	133.408
1538.87	128.326
1539.92	130.515
1540.97	119.696
1542.02	129.639
1543.07	136.517
1544.12	125.359
1545.17	135.44
1546.22	134.566
1547.27	131.587
1548.32	131.516
1549.37	128.435
1550.42	134.483
1551.46	132.864
1552.51	137.885
1553.56	145.808
1554.61	128.654
1555.65	120.524
1556.7	140.543
1557.75	127.538
1558.79	131.437
1559.84	134.285
1560.89	139.211
1561.93	129.237
1562.98	133.304
1564.02	121.276
1565.07	129.375
1566.11	128.596
1567.16	133.123
1568.2	132.222
1569.25	125.251
1570.29	129.183
1571.34	127.178
1572.38	130.113
1573.43	131.028
1574.47	137
1575.51	130.135
1576.56	133.147
1577.6	139.974
1578.64	132.831
1579.69	129.828
1580.73	129.862
1581.77	129.801
1582.81	125.739
1583.85	142.644
1584.9	130.695
1585.94	131.68
1586.98	130.582
1588.02	132.519
1589.06	138.533
1590.1	128.625
1591.14	143.597
1592.18	134.602
1593.22	134.474
1594.26	133.283
1595.3	133.304
1596.34	143.187
1597.38	131.28
1598.42	135.256
1599.46	134.141
1600.5	135.038
1601.54	137.86
1602.58	133.76
1603.62	133.64
1604.66	128.663
1605.69	127.683
1606.73	134.663
1607.77	139.471
1608.81	136.515
1609.84	127.703
1610.88	136.725
1611.92	136.327
1612.95	131.647
1613.99	134.086
1615.03	128.808
1616.06	130.256
1617.1	133.461
1618.13	130.047
1619.17	132.336
1620.2	137.273
1621.24	132.96
1622.27	135.159
1623.31	130.841
1624.34	138.636
1625.38	136.36
1626.41	133.991
1627.45	129.897
1628.48	135.192
1629.51	133.704
1630.55	127.252
1631.53	135.145
1632.57	128.305
1633.62	136.174
1634.66	139.16
1635.71	129.289
1636.75	139.081
1637.8	137.029
1638.84	134.031
1639.89	142.886
1640.93	140.938
1641.98	132.073
1643.02	128.104
1644.06	133.985
1645.11	136.874
1646.15	134.944
1647.19	132.92
1648.24	141.724
1649.28	140.866
1650.32	135.937
1651.37	137.044
1652.41	136.081
1653.45	132.105
1654.49	131.145
1655.53	133.171
1656.57	144.164
1657.62	137.255
1658.66	131.282
1659.7	141.063
1660.74	138.079
1661.78	133.243
1662.82	131.416
1663.86	128.465
1664.9	135.287
1665.94	138.063
1666.98	132.314
1668.02	139.145
1669.06	133.248
1670.1	136.306
1671.14	133.439
1672.18	140.33
1673.21	141.331
1674.25	134.441
1675.29	123.632
1676.33	143.451
1677.37	136.533
1678.4	141.41
1679.44	125.495
1680.48	145.21
1681.52	141.204
1682.55	147.125
1683.59	148.1
1684.63	131.27
1685.66	128.278
1686.7	135.201
1687.73	146.097
1688.77	132.206
1689.81	137.042
1690.84	137.003
1691.88	135.077
1692.91	138.018
1693.95	137.877
1694.98	133.828
1696.01	135.815
1697.05	134.865
1698.08	131.799
1699.12	140.56
1700.15	140.551
1701.18	139.526
1702.22	135.518
1703.25	142.308
1704.28	144.233
1705.32	139.345
1706.35	135.38
1707.38	138.192
1708.41	138.032
1709.44	131.982
1710.48	140.759
1711.51	132.971
1712.54	137.872
1713.57	140.591
1714.6	138.485
1715.63	132.619
1716.66	143.358
1717.69	147.074
1718.72	142.931
1719.75	147.74
1720.78	133.125
1721.81	147.596
1722.84	139.671
1723.87	148.302
1724.9	141.456
1725.93	149.01
1726.96	151.857
1727.99	143.089
1729.02	143.766
1730.05	139.752
1731.07	151.249
1732.1	147.559
1733.13	137.832
1734.16	144.397
1735.18	148.064
1736.21	154.655
1737.24	156.502
1738.26	142.944
1739.29	143.776
1740.32	148.345
1741.34	143.377
1742.37	148.06
1743.4	141.31
1744.42	148.888
1745.45	147.896
1746.47	145.923
1747.5	140.986
1748.52	158.078
1749.55	139.016
1750.57	147.726
1751.6	146.831
1752.62	147.642
1753.64	156.101
1754.67	142.625
1755.69	148.263
1756.71	143.364
1757.74	153.672
1758.76	153.719
1759.78	149.924
1760.81	151.782
1761.83	151.678
1762.85	151.664
1763.87	146.924
1764.89	152.742
1765.92	154.713
1766.94	149.938
1767.96	146.082
1768.98	151.723
1770	159.038
1771.02	149.619
1772.04	164.004
1773.06	156.485
1774.08	147.032
1775.1	160.408
1776.12	154.843
1777.14	152.933
1778.16	156.642
1779.18	154.602
1780.2	146.008
1781.22	150.814
1782.24	147.046
1783.26	158.577
1784.28	154.843
1785.29	151.129
1786.31	155.856
1787.33	147.339
1788.35	148.574
1789.37	151.664
1790.38	159.466
1791.4	145.066
1792.42	154.526
1793.43	149.781
1794.45	143.102
1795.47	148.982
1796.48	154.909
1797.5	149.263
1798.51	150.297
1799.53	151.241
1800.55	139.605
1801.56	141.481
1802.58	141.507
1803.59	138.721
1804.61	146.476
1805.62	155.263
1806.64	152.494
1807.65	140.967
1808.66	161.214
1809.68	157.378
1810.69	145.826
1811.7	150.623
1812.72	149.679
1813.73	159.403
1814.74	144.096
1815.76	152.902
1816.77	151
1817.78	143.177
1818.79	148.029
1819.8	145.171
1820.82	149.104
1821.83	145.306
1822.84	161.82
1823.85	150.201
1824.86	153.108
1825.87	155.099
1826.88	136.704
1827.89	145.46
1828.9	142.546
1829.91	145.403
1830.92	151.15
1831.93	157.017
1832.94	156.139
1833.95	151.333
1834.96	150.259
1835.97	150.026
1836.98	151.548
1837.99	150.097
1839	149.114
1840	151.255
1841.01	139.348
1842.02	153.57
1843.03	159.222
1844.04	142.819
1845.04	151.502
1846.05	154.438
1847.06	158.45
1848.07	153.089
1849.07	153.114
1850.08	144.334
1851.09	144.153
1852.09	147.895
1853.1	138.281
1854.1	149.74
1855.11	142.867
1856.11	142.725
1857.12	146.531
1858.12	148.387
1859.13	142.521
1860.13	146.241
1861.14	152.039
1862.14	143.506
1863.15	152.972
1864.15	144.233
1865.15	148.896
1866.16	154.423
1867.16	137.974
1868.16	137.796
1869.17	152.988
1870.17	145.352
1871.17	146.274
1872.17	149.065
1873.18	141.374
1874.18	149.855
1875.18	155.403
1876.18	149.489
1877.18	150.272
1878.18	139.662
1879.19	146.513
1880.19	137.158
1881.19	150.393
1882.19	143.551
1883.19	148.905
1884.19	148.741
1885.19	146.928
1886.19	149.945
1887.19	144.258
1888.19	153.546
1889.19	151.452
1890.19	147.597
1891.19	155.221
1892.18	147.65
1893.18	158.876
1894.18	148.291
1895.18	152.916
1896.18	141.685
1897.18	148.358
1898.17	152.157
1899.17	150.184
1900.17	147.259
1901.16	150.07
1902.16	153.004
1903.16	153.999
1904.16	151.117
1905.15	155.788
1906.15	147.266
1907.14	144.341
1908.14	150.931
1909.14	137.838
1910.13	142.664
1911.13	148.485
1912.12	151.351
1913.12	152.265
1914.11	149.508
1915.11	144.935
1916.1	158.197
1917.1	142.082
1918.09	154.264
1919.08	148.703
1920.08	149.853
1921.07	148.933
1922.06	155.671
1923.06	154.7
1924.05	154.633
1925.04	142.273
1926.04	155.604
1927.03	153.884
1928.02	145.454
1929.01	152.146
1930	148.475
1931	150.531
1931.99	151.461
1932.98	156.115
1933.97	150.446
1934.96	151.83
1935.95	147.391
1936.94	145.341
1937.93	155.684
1938.92	154.721
1939.91	147.186
1940.9	148.239
1941.89	157.913
1942.88	148.433
1943.87	147.389
1944.86	152.266
1945.85	147.633
1946.84	150.598
1947.83	141.01
1948.82	145.771
1949.8	154.473
1950.79	153.728
1951.78	156.842
1952.77	144.482
1953.76	153.141
1954.74	150.897
1955.73	155.606
1956.72	142.432
1957.7	155.052
1958.69	137.828
1959.68	155.075
1960.66	160.757
1961.65	148.166
1962.63	161.604
1963.62	149.148
1964.61	149.193
1965.59	158.775
1966.58	155.015
1967.56	161.815
1968.55	150.305
1969.53	154.064
1970.52	159.65
1971.5	159.554
1972.48	160.509
1973.47	155.676
1974.45	146.949
1975.44	162.296
1976.42	162.378
1977.4	166.224
1978.39	160.386
1979.37	154.582
1980.35	169.93
1981.33	169.837
1982.31	164.984
1983.3	171.583
1984.28	158.07
1985.26	165.644
1986.24	152.206
1987.22	164.687
1988.21	166.475
1989.19	157.675
1990.17	171.089
1991.15	170.769
1992.13	175.117
1993.11	176.989
1994.09	171.093
1995.07	168.933
1996.05	167.815
1997.03	172.034
1998.01	174.213
1998.99	172.901
1999.97	176.067
2000.95	172.224
2001.92	171.073
2002.9	175.076
2003.88	178.058
2004.86	180.794
2005.84	174.429
2006.81	175.228
2007.79	178.589
2008.77	173.411
2009.75	176.092
2010.73	177.863
2011.7	176.619
2012.68	176.118
2013.67	174.035
2014.66	172.809
2015.64	164.287
2016.63	177.504
2017.62	170.103
2018.61	167.995
2019.6	168.677
2020.58	169.538
2021.57	175.161
2022.56	158.254
2023.55	175.879
2024.54	171.052
2025.52	169.889
2026.51	162.284
2027.5	162.712
2028.48	166.256
2029.47	164.648
2030.45	169.739
2031.44	164.214
2032.43	162.374
2033.41	160.713
2034.4	158.861
2035.38	167.947
2036.37	171.115
2037.35	162.647
2038.34	176.621
2039.32	170.903
2040.31	164.22
2041.29	171.515
2042.27	163.046
2043.26	164.839
2044.24	163.166
2045.23	159.339
2046.21	168.076
2047.19	167.917
2048.17	150.922
2049.16	166.811
2050.14	167.931
2051.12	164.322
2052.11	163.292
2053.09	156.808
2054.07	159.784
2055.05	161.707
2056.03	154.147
2057.01	158.77
2058	159.742
2058.98	161.737
2059.96	163.687
2060.94	151.459
2061.92	154.329
2062.9	152.491
2063.88	159.146
2064.86	161.082
2065.84	151.853
2066.82	160.399
2067.8	155.771
2068.78	160.544
2069.76	152.981
2070.73	157.664
2071.71	149.304
2072.69	161.755
2073.67	163.608
2074.65	165.531
2075.63	155.366
2076.6	157.425
2077.58	153.57
2078.56	158.248
2079.54	149.841
2080.51	166.054
2081.49	158.489
2082.47	164.157
2083.45	159.453
2084.42	149.991
2085.4	163.227
2086.37	162.334
2087.35	148.268
2088.32	156.827
2089.3	157.799
2090.28	156.012
2091.25	153.22
2092.23	160.924
2093.2	158.278
2094.18	166.034
2095.15	157.509
2096.13	162.169
2097.1	163.073
2098.07	155.375
2099.05	167.673
2100.02	169.545
2101	152.491
2101.97	149.737
2102.94	150.673
2103.92	157.239
2104.89	149.673
2105.86	147.875
2106.83	154.596
2107.8	167.913
2108.78	152.547
2109.75	155.395
2110.72	167.776
2111.69	155.412
2112.66	151.564
2113.63	152.599
2114.61	156.422
2115.58	157.37
2116.55	155.397
2117.52	157.234
2118.49	157.172
2119.46	155.115
2120.43	151.206
2121.4	159.77
2122.37	153.272
2123.34	156.209
2124.31	151.45
2125.28	156.937
2126.25	160.503
2127.21	157.518
2128.18	149.887
2129.15	148.915
2130.12	162.108
2131.09	164.894
2132.06	156.299
2133.02	158.091
2133.99	147.703
2134.96	168.472
2135.93	162.773
2136.89	146.593
2137.86	165.48
2138.83	158.82
2139.79	156.028
2140.76	156.837
2141.73	163.387
2142.69	167.065
2143.66	160.598
2144.62	153.696
2145.59	162.163
2146.55	158.371
2147.52	170.52
2148.48	165.739
2149.45	155.31
2150.42	163.564
2151.38	152.274
2152.34	153.285
2153.31	156.044
2154.27	155.96
2155.24	159.479
2156.2	157.395
2157.16	156.4
2158.13	161.133
2159.09	152.743
2160.05	156.388
2161.01	152.508
2161.98	150.585
2162.94	161.769
2163.9	149.573
2164.86	163.442
2165.83	154.119
2166.79	158.743
2167.75	152.107
2168.71	147.243
2169.67	170.547
2170.63	159.583
2171.59	159.537
2172.56	161.126
2173.51	160.137
2174.48	149.027
2175.44	150.888
2176.4	162.003
2177.36	152.662
2178.32	157.314
2179.28	153.503
2180.23	153.511
2181.19	158.125
2182.15	154.359
2183.11	163.575
2184.07	161.567
2185.03	162.44
2185.99	163.425
2186.95	160.774
2187.9	160.021
2188.86	166.451
2189.82	156.997
2190.78	155.073
2191.73	165.306
2192.69	157.941
2193.65	158.962
2194.6	159.194
2195.56	151.742
2196.52	155.301
2197.47	155.154
2198.43	164.427
2199.38	162.756
2200.34	162.06
2201.3	159.542
2202.25	167.367
2203.21	162.074
2204.16	156.124
2205.12	159.565
2206.07	159.18
2207.03	158.235
2207.98	158.33
2208.93	149.148
2209.89	167.821
2210.84	160.414
2211.8	171.704
2212.75	155.959
2213.7	161.486
2214.66	159.698
2215.61	149.532
2216.56	157.944
2217.51	152.323
2218.47	160.736
2219.42	156.139
2220.37	161.828
2221.32	163.663
2222.27	165.379
2223.23	155.118
2224.18	153.381
2225.13	153.545
2226.08	164.932
2227.03	159.441
2227.98	166.092
2228.93	158.551
2229.88	158.56
2230.83	168.084
2231.78	165.417
2232.73	160.848
2233.68	157.204
2234.63	154.441
2235.58	160.911
2236.53	160.889
2237.48	159.07
2238.43	160.235
2239.38	159.486
2240.33	162.246
2241.27	157.601
2242.22	165.194
2243.17	173.748
2244.12	152.917
2245.07	152.986
2246.01	168.297
2246.96	166.521
2247.91	145.775
2248.85	152.371
2249.8	158.053
2250.75	163.697
2251.69	165.461
2252.64	152.262
2253.59	173.32
2254.53	163.052
2255.48	156.433
2256.42	149.834
2257.37	164.176
2258.32	157.609
2259.26	160.514
2260.2	160.587
2261.15	161.611
2262.1	157.91
2263.04	158.945
2263.98	168.66
2264.93	162.219
2265.87	156.596
2266.81	152.7
2267.76	156.396
2268.7	163.928
2269.65	158.311
2270.59	168.064
2271.53	165.317
2272.47	172.108
2273.42	161.615
2274.36	176.006
2275.3	161.688
2276.24	160.769
2277.18	159.959
2278.13	158.252
2279.07	156.438
2280.01	164.961
2280.95	160.003
2281.89	150.344
2282.83	165.767
2283.77	162.119
2284.71	160.462
2285.65	161.53
2286.59	168.166
2287.54	156.798
2288.47	159.762
2289.41	163.486
2290.35	154.624
2291.29	161.366
2292.23	154.792
2293.17	159.737
2294.11	158.854
2295.05	153.951
2295.99	171.195
2296.93	159.51
2297.86	157.687
2298.8	164.59
2299.74	161.838
2300.68	157.99
2301.61	167.726
2302.55	159.035
2303.49	155.155
2304.43	170.644
2305.36	154.327
2306.3	163.082
2307.24	164.078
2308.17	162.092
2309.11	162.07
2310.04	165.116
2310.98	161.299
2311.92	162.012
2312.85	165.721
2313.79	172.524
2314.72	164.049
2315.66	163.184
2316.59	163.942
2317.52	168.704
2318.46	162.937
2319.39	153.181
2320.33	160.85
2321.26	169.579
2322.2	162.963
2323.13	152.433
2324.06	179.545
2325	167.89
2325.93	185.085
2326.86	198.436
2327.79	294.68
2328.73	225.216
2329.66	175.945
2330.59	178.82
2331.52	161.458
2332.46	170.173
2333.39	160.439
2334.32	154.587
2335.25	164.096
2336.18	172.754
2337.11	156.364
2338.04	164.981
2338.97	163.986
2339.91	158.222
2340.84	162.937
2341.77	160.819
2342.7	159.731
2343.63	161.617
2344.56	157.781
2345.49	165.421
2346.41	159.541
2347.34	160.454
2348.27	154.705
2349.2	154.72
2350.13	159.262
2351.06	165.161
2351.99	161.049
2352.91	162.71
2353.84	170.092
2354.77	160.57
2355.7	158.672
2356.63	163.318
2357.55	164.065
2358.48	156.368
2359.41	163.892
2360.33	155.252
2361.26	157.002
2362.19	169.16
2363.11	155.739
2364.04	165.11
2364.97	174.471