File: Data/3-Raman/raw/bu19w-e-ff11-fi06-v_150 (500nm)_633nm_edge_100%_x100_vis_h50um_60sx2_01.txt
#Acq. time (s)=	60
#Accumulations=	2
#Range (cm-¹)=	100...4000
#Windows=	1
#Auto scanning=	Off
#Autofocus=	Off
#Macrospot=	Off
#AutoExposure=	Off
#Spike filter=	Multiple accum.
#Delay time (s)=	2
#Binning=	1
#Readout mode=	Signal
#DeNoise=	Off
#ICS correction=	On
#Dark correction=	Off
#Inst. Process=	Off
#Detector Gain=	Best Dynamic
#Detector ADC=	50 kHz HS
#Detector temperature (°C)=	-60.09
#Instrument=	LabRAM HR Evol
#Detector=	SIN-EM FIVIS
#Objective=	x100_VIS
#Grating=	150 (500nm)
#ND Filter=	100%
#Laser=	633nm_Edge
#Hole=	49.98
#Temperature=	0
#Range=	Visible
#StageXY=	75x50mm Scan+
#StageZ=	Z motor
#X (µm)=	0
#Y (µm)=	0
#Z (µm)=	-272.4
#Full time(mm:ss)=	2:04
#Project=	21_11_04
#Sample=	BU19w
#Site=
#Title=	BU19w-E-FF11-FI06-V_150 (500nm)_633nm_Edge_100%_x100_VIS_H50um_60sX2
#Remark=
#Date=	04.11.2021 15:52
#Acquired=	04.11.2021 15:52:12
102.881	186.39
109.397	173.208
115.908	156.183
122.414	164.898
128.914	166.917
135.409	189.942
141.898	180.378
148.383	179.459
154.861	219.752
161.335	244.786
167.801	166.311
174.264	128.942
180.721	115.467
187.173	111.505
193.62	110.37
200.061	109.283
206.496	112.129
212.926	121.62
219.352	152.086
225.772	255.84
232.185	320.183
238.595	210.549
244.999	168.628
251.397	153.355
257.791	159.902
264.178	159.838
270.561	161.701
276.939	192.994
283.31	173.982
289.678	152.091
296.039	140.599
302.396	166.019
308.746	202.715
315.093	375.337
321.433	527.033
327.768	371.217
334.099	230.617
340.423	185.3
346.743	185.23
353.058	202.084
359.367	192.492
365.671	162.205
371.971	131.983
378.265	116.827
384.553	110.172
390.837	119.611
397.116	120.723
403.389	127.592
409.657	134.465
415.92	152.621
422.178	173.62
428.431	212.212
434.678	222.097
440.921	191.452
447.158	184.37
453.391	205.35
459.618	166.603
465.84	125.377
472.057	113.175
478.27	104.806
484.477	109.477
490.679	122.537
496.876	128.158
503.068	147.791
509.255	170.258
515.436	174.128
521.613	169.697
527.785	173.775
533.952	165.774
540.113	141.715
546.27	113.665
552.423	113.751
558.568	107.173
564.711	96.6558
570.848	95.4943
576.979	96.1327
583.107	107.065
589.228	131.072
595.345	161.662
601.458	141.195
607.565	133.94
613.667	140.761
619.764	143.044
625.856	111.528
631.944	112.688
638.026	107.988
644.104	116.306
650.177	118.004
656.244	107.392
662.308	91.2001
668.365	80.7098
674.418	74.1356
680.467	76.0015
686.511	66.7335
692.549	62.1897
698.582	61.3927
704.611	72.7878
710.635	68.1844
716.655	65.3171
722.669	63.4016
728.679	65.1894
734.683	60.3912
740.683	57.4798
746.678	62.9934
752.669	70.3969
758.654	62.9335
764.635	66.7933
770.611	70.7301
776.582	62.4731
782.549	65.4198
788.511	71.1572
794.466	69.3211
800.419	68.3676
806.366	63.5927
812.309	63.504
818.247	66.1876
824.18	65.0922
830.108	62.1438
836.033	69.6037
841.952	69.7068
847.865	68.894
853.776	78.4472
859.681	80.5383
865.58	88.3171
871.476	97.0615
877.366	95.2939
883.253	97.2607
889.134	105.8
895.012	108.582
900.883	100.818
906.751	100.572
912.614	105.015
918.473	104.798
924.326	109.424
930.174	114.206
936.019	141.712
941.859	171.499
947.693	197.772
953.525	214.733
959.35	212.566
965.171	224.575
970.988	297.893
976.801	353.755
982.608	424.38
988.411	394.991
994.209	281.49
1000	245.734
1005.79	234.994
1011.58	256.019
1017.36	290.623
1023.13	273.833
1028.9	211.257
1034.67	178.21
1040.43	153.708
1046.19	155.156
1051.94	140.997
1057.69	123.772
1063.44	119.984
1069.17	126.739
1074.91	133.484
1080.64	162.466
1086.37	209.795
1092.09	261.003
1097.8	285.032
1103.52	208.469
1109.22	165.99
1114.93	144.04
1120.63	141.578
1126.32	131.166
1132.01	152.028
1137.7	178.867
1143.38	224.486
1149.06	304.519
1154.73	214.158
1160.4	139.253
1166.06	107.558
1171.72	93.6312
1177.38	90.5023
1183.03	76.683
1188.67	72.7562
1194.31	71.827
1199.95	64.1187
1205.58	59.4126
1211.21	60.6203
1216.84	63.851
1222.46	57.1925
1228.07	56.4672
1233.68	60.7195
1239.29	55.8899
1244.89	52.9795
1250.49	56.06
1256.08	61.1212
1261.67	58.0276
1267.26	53.9186
1272.84	84.0011
1278.42	81.8095
1283.99	58.6009
1289.56	52.5121
1295.12	55.4694
1300.68	57.4622
1306.23	61.5194
1311.78	58.659
1317.33	51.8041
1322.87	56.0268
1328.41	48.1428
1333.94	52.3986
1339.47	53.5954
1345	51.6765
1350.52	50.7507
1356.04	54.9343
1361.55	50.8698
1367.06	54.9831
1372.56	59.0727
1378.06	129.913
1383.56	70.3162
1389.05	58.9963
1394.53	57.9794
1400.02	65.2604
1405.5	56.0922
1410.97	58.2544
1416.44	55.2801
1421.91	54.3726
1427.37	56.5874
1432.83	50.4888
1438.28	53.747
1443.73	58.0655
1449.17	56.0899
1454.62	51.9559
1460.05	51.9786
1465.48	58.274
1470.91	56.1577
1476.34	45.6586
1481.76	57.2281
1487.17	52.0165
1492.59	59.4474
1497.99	53.2284
1503.4	55.4534
1508.8	57.7104
1514.19	55.7526
1519.59	55.9342
1524.97	57.1972
1530.36	53.1056
1535.74	54.3806
1541.11	57.7727
1546.48	62.1897
1551.85	58.9484
1557.21	61.0352
1562.57	60.974
1567.93	58.7552
1573.28	57.6165
1578.62	60.8186
1583.97	59.7484
1589.3	53.3111
1594.64	65.2144
1599.97	56.6672
1605.3	61.0979
1610.62	55.8371
1615.94	60.382
1621.25	58.4309
1626.56	58.6527
1631.87	67.6713
1637.17	59.0394
1642.47	59.1147
1647.76	63.6316
1653.05	60.3806
1658.34	62.6359
1663.62	60.4373
1668.9	60.4427
1674.18	61.5529
1679.45	61.5422
1684.71	63.7147
1689.98	60.3403
1695.23	58.1141
1700.49	59.2943
1705.74	66.2732
1710.99	66.3632
1716.23	61.9261
1721.47	64.3406
1726.7	63.3232
1731.94	64.5788
1737.16	63.5811
1742.39	60.3204
1747.61	64.9453
1752.82	71.8148
1758.03	65.0849
1763.24	67.371
1768.44	68.5365
1773.64	64.0459
1778.84	65.2487
1784.03	61.9404
1789.22	71.1732
1794.41	73.6161
1799.59	70.3711
1804.76	67.1237
1809.94	69.5851
1815.11	70.8869
1820.27	66.4197
1825.43	72.3579
1830.59	70.2079
1835.74	68.0574
1840.89	74.0249
1846.04	65.9808
1851.18	66.0882
1856.32	67.3431
1861.45	74.5051
1866.58	68.7808
1871.71	72.437
1876.83	65.4578
1881.95	74.9831
1887.07	75.0559
1892.18	66.7973
1897.29	69.1714
1902.39	75.1618
1907.49	70.5635
1912.59	75.5191
1917.68	74.5715
1922.77	71.0717
1927.86	77.1953
1932.94	76.1439
1938.02	72.6671
1943.09	65.5474
1948.16	71.6349
1953.23	71.6779
1958.29	76.5229
1963.35	72.9199
1968.41	77.7305
1973.46	75.2789
1978.51	71.6266
1983.55	81.2109
1988.59	65.541
1993.63	72.7336
1998.66	67.9185
2003.69	78.7526
2008.72	83.6092
2013.74	75.2499
2018.76	69.277
2023.77	81.3914
2028.78	82.7062
2033.79	75.5978
2038.79	84.2262
2043.79	75.8972
2048.79	83.3667
2053.78	81.0757
2058.77	82.4651
2063.76	75.3029
2068.74	80.3794
2073.72	85.4691
2078.69	79.4781
2083.66	83.3206
2088.63	87.1405
2093.59	79.8658
2098.55	86.2538
2103.51	86.4651
2108.46	85.4505
2113.41	84.4538
2118.36	85.9722
2123.3	84.9744
2128.24	90.2691
2133.17	80.379
2138.11	90.7178
2143.03	83.287
2147.96	87.2644
2152.88	92.4892
2157.79	87.4808
2162.71	91.379
2167.62	82.4595
2172.52	82.5059
2177.43	87.684
2182.32	87.6963
2187.22	88.9645
2192.11	83.8741
2197	87.7789
2201.89	87.8916
2206.77	90.6106
2211.64	83.0706
2216.52	89.717
2221.39	89.9449
2226.26	84.9842
2231.12	90.4036
2235.98	91.9371
2240.84	90.8601
2245.69	91.0937
2250.54	88.6975
2255.39	91.5494
2260.23	90.4671
2265.07	93.3187
2269.9	92.161
2274.74	92.2903
2279.57	84.4138
2284.39	87.1211
2289.21	92.4658
2294.03	92.4867
2298.84	89.8745
2303.66	95.2944
2308.46	100.789
2313.27	95.6471
2318.07	99.9063
2322.87	100.156
2327.66	92.3385
2332.45	92.6051
2337.24	94.2484
2342.02	104.079
2346.8	94.8985
2351.58	88.3787
2356.35	90.0216
2361.12	99.868
2365.89	101.463
2370.65	104.446
2375.41	103.27
2380.17	93.7332
2384.92	102.186
2389.67	103.658
2394.42	113.438
2399.16	96.7348
2403.9	92.5505
2408.64	89.7745
2413.37	99.6913
2418.1	98.7674
2422.83	99.0861
2427.55	106.286
2432.27	99.5053
2436.99	108.296
2441.7	101.522
2446.41	97.5524
2451.11	102.133
2455.82	95.2658
2460.51	95.5438
2465.21	107.345
2469.9	116.301
2474.59	99.2149
2479.28	98.0259
2483.96	99.72
2488.64	97.011
2493.32	94.2835
2497.99	100.34
2502.66	100.53
2507.32	112.461
2511.99	102.318
2516.65	114.238
2521.3	107.033
2525.96	108.677
2530.61	114.766
2535.25	119.424
2539.89	116.688
2544.53	109.482
2549.17	105.248
2553.8	109.967
2558.43	101.175
2563.06	110.406
2567.68	107.668
2572.3	109.462
2576.92	112.76
2581.53	108.442
2586.14	110.111
2590.75	114.761
2595.35	114.895
2599.96	113.554
2604.55	106.068
2609.15	113.829
2613.74	118.502
2618.33	123.196
2622.91	117.178
2627.49	112.709
2632.07	120.598
2636.64	110.123
2641.22	113.56
2645.78	118.584
2650.35	128.28
2654.91	117.713
2659.47	111.674
2664.03	127.477
2668.58	116.691
2673.13	116.935
2677.67	107.911
2682.22	113.197
2686.76	118.483
2691.29	117.381
2695.83	125.692
2700.36	125.957
2704.89	118.172
2709.41	129.663
2713.93	129.893
2718.45	107.538
2722.96	135.282
2727.47	122.488
2731.98	129.096
2736.49	114.575
2740.99	119.551
2745.49	124.591
2749.98	131.338
2754.47	120.275
2758.96	140.178
2763.45	137.106
2767.93	140.674
2772.41	126.101
2776.89	129.719
2781.36	131.775
2785.84	127.231
2790.3	130.987
2794.77	121.35
2799.23	133.421
2803.69	130.368
2808.14	140.745
2812.59	122.428
2817.04	120.917
2821.49	131.269
2825.93	124.705
2830.37	130
2834.81	128.483
2839.24	133.779
2843.67	125.444
2848.1	132.508
2852.53	139.64
2856.95	126.248
2861.37	130.017
2865.78	123.502
2870.19	136.018
2874.6	127.747
2879.01	126.416
2883.41	133.856
2887.81	130.824
2892.21	124.217
2896.6	135.26
2901	144.636
2905.38	127.288
2909.77	133.02
2914.15	138.696
2918.53	130.044
2922.91	130.368
2927.28	137.947
2931.65	134.74
2936.02	126.011
2940.38	138.972
2944.74	131.945
2949.1	121.192
2953.46	126.845
2957.81	137.989
2962.16	121.719
2966.5	142.086
2970.85	142.344
2975.19	142.612
2979.52	150.254
2983.86	132.108
2988.19	141.706
2992.52	129.099
2996.85	142.511
3001.17	146.699
3005.49	139.695
3009.8	155.212
3014.12	144.374
3018.43	148.679
3022.74	151.105
3027.04	153.456
3031.34	153.844
3035.64	152.248
3039.94	144.871
3044.23	143.232
3048.52	141.556
3052.81	157.228
3057.09	159.451
3061.38	159.732
3065.65	181.349
3069.93	156.407
3074.2	164.472
3078.47	160.88
3082.74	157.27
3087	171.332
3091.27	171.801
3095.52	168.404
3099.78	161.049
3104.03	179.454
3108.28	180.128
3112.53	180.842
3116.77	199.602
3121.01	184.299
3125.25	195.213
3129.49	187.988
3133.72	178.701
3137.95	202.13
3142.18	188.599
3146.4	179.019
3150.62	194.233
3154.84	205.251
3159.06	193.315
3163.27	202.277
3167.48	204.926
3171.69	201.273
3175.89	212.307
3180.09	219.017
3184.29	208.724
3188.49	208.936
3192.68	198.629
3196.87	235.206
3201.06	227.424
3205.24	211.092
3209.42	196.877
3213.6	206.333
3217.78	202.887
3221.95	208.056
3226.12	193.583
3230.29	189.948
3234.45	192.864
3238.61	182.5
3242.77	194.347
3246.93	179.553
3251.08	184.638
3255.23	162.679
3259.38	190.122
3263.53	177.228
3267.67	173.596
3271.81	165.191
3275.95	170.189
3280.08	172.83
3284.21	168.595
3288.34	173.527
3292.47	171.547
3296.59	178.765
3300.71	165.262
3304.83	163.268
3308.95	177.506
3313.06	156.891
3317.17	175.81
3321.27	173.844
3325.38	174.271
3329.48	151.282
3333.58	161.232
3337.67	164.164
3341.77	171.691
3345.86	155.433
3349.95	155.696
3354.03	163.109
3358.11	168.247
3362.19	175.806
3366.27	178.575
3370.34	152.535
3374.42	157.629
3378.48	167.503
3382.55	160.492
3386.61	141.362
3390.68	127.004
3394.73	168.325
3398.79	146.745
3402.84	156.63
3406.89	147.057
3410.94	152.046
3414.98	154.599
3419.03	154.723
3423.06	149.953
3427.1	164.72
3431.14	150.252
3435.17	157.805
3439.2	150.723
3443.22	163.283
3447.25	146.448
3451.27	144.346
3455.28	159.61
3459.3	152.702
3463.31	150.748
3467.32	143.78
3471.33	149.279
3475.34	162.252
3479.34	160.223
3483.34	137.921
3487.33	148.463
3491.33	161.593
3495.32	151.793
3499.31	149.569
3503.3	147.282
3507.28	150.071
3511.26	145.06
3515.24	147.723
3519.22	158.091
3523.19	147.893
3527.16	150.582
3531.13	158.416
3535.1	148.369
3539.06	161.648
3543.02	141.241
3546.98	144.072
3550.93	159.849
3554.89	133.908
3558.84	147.064
3562.78	149.872
3566.73	152.745
3570.67	163.55
3574.61	156.033
3578.55	153.801
3582.48	162.157
3586.41	144.13
3590.35	152.509
3594.27	139.651
3598.2	140.049
3602.12	148.429
3606.04	121.979
3609.95	151.789
3613.87	138.648
3617.78	136.216
3621.69	141.816
3625.6	141.918
3629.5	128.479
3633.4	142.053
3637.3	142.162
3641.2	145.084
3645.09	139.932
3648.98	142.858
3652.87	126.666
3656.76	134.963
3660.64	140.537
3664.53	124.258
3668.4	127.122
3672.28	138.19
3676.16	141.136
3680.03	141.408
3683.9	122.479
3687.76	158.699
3691.63	139.777
3695.49	134.578
3699.35	148.854
3703.2	138.08
3707.06	138.465
3710.91	141.652
3714.76	133.582
3718.6	133.876
3722.45	128.495
3726.29	140.038
3730.13	137.448
3733.97	143.392
3737.8	132.282
3741.63	138.206
3745.46	121.299
3749.29	132.896
3753.11	133.036
3756.93	138.863
3760.75	130.343
3764.57	124.669
3768.39	133.341
3772.2	127.713
3776.01	142.186
3779.81	139.467
3783.62	133.912
3787.42	134.117
3791.22	125.633
3795.02	143.206
3798.81	126.098
3802.61	140.888
3806.4	132.474
3810.18	124.02
3813.97	133.047
3817.75	142.101
3821.53	139.433
3825.31	133.778
3829.09	145.78
3832.86	140.157
3836.63	131.538
3840.4	131.747
3844.17	140.901
3847.93	146.956
3851.69	114.379
3855.45	132.266
3859.21	138.22
3862.96	126.373
3866.71	123.61
3870.46	138.829
3874.21	138.903
3877.95	115.078
3881.69	133.1
3885.44	136.204
3889.17	127.35
3892.91	145.515
3896.64	109.712
3900.37	121.923
3904.1	131.147
3907.82	155.483
3911.55	140.611
3915.27	131.77
3918.99	129.011
3922.7	135.414
3926.42	129.622
3930.13	123.779
3933.84	139.292
3937.54	124.162
3941.25	127.451
3944.95	112.326
3948.65	137.2
3952.35	128.143
3956.04	131.404
3959.73	131.532
3963.42	128.537
3967.11	116.208
3970.8	141.032
3974.48	137.981
3978.16	125.612
3981.84	134.91
3985.52	128.7
3989.19	131.795
3992.86	128.737
3996.53	138.141
3998.37	125.785