File: Data/3-Raman/raw/bu19(2)w-a-ff2b-fi04-v_1800 (450-850nm)_532nm_edge_100%_x100_vis_lwd_h50um_30sx2_01.txt
#Acq. time (s)=	30
#Accumulations=	2
#Range (cm-¹)=	1200...2365
#Windows=	3
#Auto scanning=	Off
#Autofocus=	Off
#Macrospot=	Off
#AutoExposure=	Off
#Spike filter=	Multiple accum.
#Delay time (s)=	2
#Binning=	1
#Readout mode=	Signal
#DeNoise=	Off
#ICS correction=	On
#Dark correction=	Off
#Inst. Process=	Off
#Detector Gain=	Best Dynamic
#Detector ADC=	50 kHz HS
#Detector temperature (°C)=	-60.09
#Instrument=	LabRAM HR Evol
#Detector=	SIN-EM FIVIS
#Objective=	x50_VIS_LWD
#Grating=	1800 (450-850nm)
#ND Filter=	100%
#Laser=	532nm_Edge
#Hole=	49.98
#Temperature=	0
#Range=	Visible
#StageXY=	75x50mm Scan+
#StageZ=	Z motor
#X (µm)=	0
#Y (µm)=	0
#Z (µm)=	1.4
#Full time(mm:ss)=	3:22
#Project=	21_11_26
#Sample=	BU19(2)w
#Site=
#Title=	BU19(2)w-A-FF2b-FI01-V_1800 (450-850nm)_532nm_Edge_100%_x50_VIS_LWD_H50um_30sX2
#Remark=
#Date=	26.11.2021 14:41
#Acquired=	26.11.2021 14:41:45
1202.72	45.7053
1203.84	41.4143
1204.95	49.9795
1206.06	44.5326
1207.17	48.728
1208.28	45.4592
1209.39	40.059
1210.5	44.3095
1211.61	38.8997
1212.72	44.1691
1213.83	39.8629
1214.94	40.9163
1216.05	40.9023
1217.16	44.0255
1218.27	37.5992
1219.38	41.8135
1220.49	38.607
1221.6	39.6479
1222.71	40.6478
1223.81	35.2813
1224.92	39.4573
1226.03	39.4532
1227.14	42.6059
1228.25	40.3966
1229.35	37.142
1230.46	36.1827
1231.57	39.2264
1232.67	43.4227
1233.78	41.3063
1234.89	38.1633
1235.99	40.277
1237.1	36.0571
1238.2	39.1537
1239.31	40.1495
1240.41	45.3701
1241.52	34.8854
1242.62	42.2013
1243.73	43.2566
1244.83	40.1051
1245.94	47.3927
1247.04	40.0328
1248.14	53.6211
1249.25	45.2174
1250.35	46.256
1251.45	45.1631
1252.56	50.345
1253.66	53.4341
1254.76	43.0171
1255.87	45.1061
1256.97	57.6435
1258.07	56.579
1259.17	59.6746
1260.27	63.8846
1261.37	75.2829
1262.48	102.624
1263.58	127.369
1264.68	81.7431
1265.78	67.0268
1266.88	60.751
1267.98	55.5737
1269.08	52.4992
1270.18	50.398
1271.28	58.7164
1272.38	59.7628
1273.47	58.7799
1274.57	54.6346
1275.67	55.6838
1276.77	63.0689
1277.87	63.1147
1278.97	83.1477
1280.07	102.091
1281.16	189.393
1282.26	607.398
1283.36	1618.22
1284.45	630.852
1285.55	167.486
1286.65	95.8513
1287.75	75.8053
1288.84	65.2549
1289.94	65.2871
1291.03	60.032
1292.13	58.9654
1293.22	56.8492
1294.32	57.967
1295.42	49.537
1296.51	49.6357
1297.61	49.622
1298.7	48.5308
1299.79	49.5536
1300.89	48.5063
1301.98	44.2825
1303.08	45.3442
1304.17	48.4878
1305.26	50.5878
1306.35	45.2627
1307.45	42.0832
1308.54	43.1343
1309.63	45.2511
1310.73	45.2517
1311.82	47.3629
1312.91	42.0995
1314	39.9681
1315.09	36.7982
1316.18	37.8671
1317.28	39.9661
1318.37	35.7466
1319.46	39.9674
1320.55	36.7919
1321.64	42.0378
1322.73	44.1021
1323.82	44.0795
1324.91	47.2386
1326	44.039
1327.09	45.011
1328.18	39.8131
1329.27	46.1853
1330.35	43.0075
1331.44	40.8561
1332.53	37.6321
1333.62	43.8817
1334.71	38.5752
1335.79	34.3396
1336.88	43.7474
1337.97	41.6269
1339.06	43.6816
1340.14	41.5788
1341.23	40.5282
1342.32	34.2246
1343.4	45.6929
1344.49	37.315
1345.58	40.4264
1346.66	40.3623
1347.75	40.3062
1348.83	37.1539
1349.92	39.203
1351	41.2464
1352.09	45.3679
1353.17	40.1876
1354.25	39.1804
1355.34	34.9245
1356.42	40.109
1357.51	45.2747
1358.59	40.0497
1359.67	38.9771
1360.76	42.0409
1361.84	43.0564
1362.92	45.1041
1364	43.0411
1365.09	49.2462
1366.17	52.301
1367.25	51.2029
1368.33	54.2951
1369.41	97.7282
1370.5	55.3151
1371.58	46.9988
1372.66	47.954
1373.74	48.9444
1374.82	50.9823
1375.9	61.276
1376.98	51.973
1378.06	54.0062
1379.14	58.2122
1380.22	72.6022
1381.3	71.4159
1382.38	87.7703
1383.46	114.308
1384.54	180.877
1385.61	489.93
1386.69	2644.07
1387.77	1371
1388.85	248.411
1389.93	127.739
1391	96.7775
1392.08	81.3241
1393.16	62.8259
1394.23	59.7249
1395.31	57.6683
1396.39	58.7035
1397.46	58.6665
1398.54	49.4412
1399.62	56.6189
1400.69	52.5375
1401.77	54.6039
1402.84	56.7331
1403.92	55.7538
1404.99	59.8115
1406.07	74.1196
1407.14	116.116
1408.22	198.166
1409.29	158.22
1410.37	75.1589
1411.44	51.5059
1412.51	46.3666
1413.59	44.4349
1414.66	43.3486
1415.73	35.1489
1416.81	38.2349
1417.88	32.0819
1418.95	38.2475
1420.02	40.2863
1421.1	42.3004
1422.17	36.1367
1423.24	38.2656
1424.31	44.2829
1425.38	39.1507
1426.45	35.0521
1427.52	37.0597
1428.59	35.9933
1429.67	33.9493
1430.74	29.8731
1431.81	32.9854
1432.87	41.1667
1433.95	27.7817
1435.01	29.8346
1436.08	31.8774
1437.15	32.8853
1438.22	26.7253
1439.29	34.9243
1440.36	32.8939
1441.43	27.7693
1442.49	29.8106
1443.56	32.8785
1444.63	29.7897
1445.7	31.8596
1446.77	23.6373
1447.83	33.8744
1448.9	29.7764
1449.97	28.7398
1451.03	32.8189
1452.1	27.6775
1453.17	26.6452
1454.23	30.7423
1455.3	24.5854
1456.36	29.7098
1457.43	23.5436
1458.49	25.5818
1459.56	26.6047
1460.62	25.5698
1461.69	27.5995
1462.75	27.5732
1463.82	27.5411
1464.88	26.543
1465.94	25.4345
1467.01	26.4399
1468.07	21.3282
1469.13	24.3786
1470.2	27.4136
1471.26	22.2983
1472.32	26.3522
1473.39	20.2323
1474.45	30.3918
1475.51	27.3373
1476.57	20.1984
1477.63	21.1983
1478.69	26.2666
1479.76	22.1782
1480.82	20.1166
1481.88	30.2477
1482.94	23.1568
1484	24.1704
1485.06	24.1112
1486.12	24.0972
1487.18	27.1334
1488.24	24.0741
1489.3	27.0826
1490.36	24.0334
1491.42	20.98
1492.48	21.9823
1493.53	26.0166
1494.59	23.9875
1495.65	24.9811
1496.71	22.9299
1497.77	25.9444
1498.82	22.9088
1499.88	23.9174
1500.94	23.913
1502	22.8872
1503.05	24.8891
1504.11	26.886
1505.17	22.8488
1506.22	23.8279
1507.28	19.7932
1508.34	30.8708
1509.39	21.796
1510.45	23.8088
1511.5	24.7864
1512.56	19.7036
1513.61	20.6774
1514.67	22.6942
1515.72	19.6556
1516.78	19.6295
1517.83	23.6302
1518.88	23.6334
1519.94	26.6438
1520.99	18.6082
1522.05	20.6122
1523.1	25.611
1524.15	27.5774
1525.2	24.5541
1526.26	26.5622
1527.31	20.5564
1528.36	23.5476
1529.41	22.5302
1530.47	20.5139
1531.52	24.5301
1532.57	21.514
1533.62	24.5409
1534.67	25.5417
1535.72	25.5225
1536.77	24.4773
1537.82	24.4426
1538.87	23.4205
1539.92	22.4503
1540.97	24.489
1542.02	24.4661
1543.07	27.4372
1544.12	20.3973
1545.17	24.4071
1546.22	20.4195
1547.27	25.4269
1548.32	21.4011
1549.37	22.3819
1550.42	21.3827
1551.46	23.452
1552.51	23.4463
1553.56	20.4112
1554.61	23.396
1555.65	24.3688
1556.7	25.3617
1557.75	19.3486
1558.79	18.3238
1559.84	22.2938
1560.89	21.2756
1561.93	25.2716
1562.98	18.2788
1564.02	24.2679
1565.07	26.2836
1566.11	28.0972
1567.16	20.2246
1568.2	21.2347
1569.25	22.2335
1570.29	21.2155
1571.34	22.2076
1572.38	25.1866
1573.43	21.1702
1574.47	22.1593
1575.51	23.1752
1576.56	25.1707
1577.6	24.134
1578.64	22.1033
1579.69	22.0949
1580.73	24.0899
1581.77	21.0812
1582.81	23.054
1583.85	18.0623
1584.9	21.0449
1585.94	23.0291
1586.98	23.0034
1588.02	20.0025
1589.06	14.0321
1590.1	25.9791
1591.14	19.0091
1592.18	23.9766
1593.22	17.9769
1594.26	22.9081
1595.3	23.8996
1596.34	23.884
1597.38	22.8869
1598.42	16.9213
1599.46	22.8528
1600.5	26.7966
1601.54	16.8507
1602.58	24.7433
1603.62	21.7463
1604.66	22.7231
1605.69	22.7189
1606.73	21.7344
1607.77	20.7184
1608.81	25.4405
1609.84	24.3917
1610.88	25.1729
1611.92	22.2891
1612.95	22.42
1613.99	20.1216
1615.03	24.3304
1616.06	19.1287
1617.1	22.8676
1618.13	22.2051
1619.17	23.8212
1620.2	23.028
1621.24	22.2611
1622.27	21.8871
1623.31	21.4833
1624.34	23.2694
1625.38	22.9792
1626.41	19.762
1627.45	22.1206
1628.48	22.043
1629.51	22.5704
1630.55	21.9381
1631.53	22.5962
1632.57	20.6293
1633.62	20.6217
1634.66	17.6636
1635.71	21.5986
1636.75	22.569
1637.8	20.5816
1638.84	21.5542
1639.89	24.5013
1640.93	22.5304
1641.98	25.4781
1643.02	22.5141
1644.06	26.4414
1645.11	18.5544
1646.15	22.4901
1647.19	23.4596
1648.24	22.463
1649.28	23.461
1650.32	28.376
1651.37	22.484
1652.41	20.5114
1653.45	24.4419
1654.49	19.5138
1655.53	21.4879
1656.57	20.5165
1657.62	24.4592
1658.66	20.4982
1659.7	23.4392
1660.74	23.4298
1661.78	19.4936
1662.82	22.4724
1663.86	17.5291
1664.9	22.4489
1665.94	18.4705
1666.98	23.4238
1668.02	23.4056
1669.06	20.4433
1670.1	25.3907
1671.14	24.4147
1672.18	20.4511
1673.21	21.4358
1674.25	23.4125
1675.29	20.4516
1676.33	19.4608
1677.37	22.4259
1678.4	24.3881
1679.44	21.4009
1680.48	22.3757
1681.52	20.3865
1682.55	21.3681
1683.59	22.3487
1684.63	25.3004
1685.66	23.3149
1686.7	20.3486
1687.73	22.3233
1688.77	21.3205
1689.81	23.2735
1690.84	21.2889
1691.88	22.2775
1692.91	18.3221
1693.95	22.2419
1694.98	23.2048
1696.01	23.2024
1697.05	21.2319
1698.08	22.1943
1699.12	22.1736
1700.15	23.1509
1701.18	19.204
1702.22	22.1384
1703.25	22.1192
1704.28	24.0726
1705.32	23.0888
1706.35	21.1131
1707.38	25.0137
1708.41	20.0786
1709.44	23.9653
1710.48	21.9963
1711.51	22.9772
1712.54	19.0551
1713.57	22.9328
1714.6	22.9034
1715.63	19.9668
1716.66	21.9142
1717.69	18.9543
1718.72	23.7882
1719.75	21.8262
1720.78	22.7928
1721.81	20.8221
1722.84	18.8526
1723.87	23.6884
1724.9	23.6751
1725.93	24.6065
1726.96	22.6535
1727.99	20.7035
1729.02	23.558
1730.05	22.5628
1731.07	22.5439
1732.1	23.5304
1733.13	21.5827
1734.16	20.584
1735.18	21.5162
1736.21	21.49
1737.24	19.55
1738.26	23.3792
1739.29	24.3141
1740.32	19.4751
1741.34	23.2797
1742.37	22.3003
1743.4	19.4161
1744.42	23.2274
1745.45	22.2602
1746.47	23.2021
1747.5	26.9921
1748.52	26.0156
1749.55	22.1966
1750.57	22.2084
1751.6	20.2999
1752.62	25.0507
1753.64	25.0238
1754.67	24.0452
1755.69	19.2613
1756.71	23.9995
1757.74	25.871
1758.76	20.1644
1759.78	21.1121
1760.81	22.0519
1761.83	25.8348
1762.85	23.9257
1763.87	22.9718
1764.89	23.9347
1765.92	19.1794
1766.94	17.2681
1767.96	22.9671
1768.98	22.0003
1770	24.8035
1771.02	24.8108
1772.04	22.9235
1773.06	25.7852
1774.08	24.8387
1775.1	25.7931
1776.12	21.9995
1777.14	21.9935
1778.16	20.0687
1779.18	22.9015
1780.2	21.9401
1781.22	22.8935
1782.24	22.8943
1783.26	20.0449
1784.28	24.8165
1785.29	20.0568
1786.31	20.9996
1787.33	19.095
1788.35	20.0812
1789.37	23.9352
1790.38	24.9091
1791.4	22.9834
1792.42	20.0867
1793.43	20.087
1794.45	25.8347
1795.47	22.0154
1796.48	22.9944
1797.5	22.0455
1798.51	19.1662
1799.53	23.0042
1800.55	18.179
1801.56	23.9307
1802.58	22.0083
1803.59	18.1725
1804.61	20.0985
1805.62	20.1096
1806.64	23.9738
1807.65	23.9745
1808.66	22.0423
1809.68	23.0037
1810.69	23.965
1811.7	22.9919
1812.72	21.0613
1813.73	22.9959
1814.74	20.1141
1815.76	23.0229
1816.77	19.1555
1817.78	20.1044
1818.79	23.0006
1819.8	23.9682
1820.82	22.0394
1821.83	23.9797
1822.84	16.2402
1823.85	21.0743
1824.86	20.1013
1825.87	22.0396
1826.88	23.0036
1827.89	20.0982
1828.9	22.998
1829.91	21.0479
1830.92	23.9381
1831.93	20.0675
1832.94	24.9192
1833.95	22.0121
1834.96	19.0853
1835.97	21.9522
1836.98	22.9979
1837.99	19.0484
1839	22.912
1840	20.0304
1841.01	21.9196
1842.02	24.77
1843.03	22.8135
1844.04	22.8076
1845.04	23.7671
1846.05	20.8733
1847.06	17.9901
1848.07	20.8103
1849.07	19.8455
1850.08	21.7485
1851.09	21.7158
1852.09	19.7751
1853.1	21.6885
1854.1	23.5936
1855.11	23.5629
1856.11	21.6184
1857.12	19.6936
1858.12	20.6377
1859.13	22.5282
1860.13	20.5943
1861.14	20.5973
1862.14	18.6887
1863.15	19.6268
1864.15	18.648
1865.15	21.4925
1866.16	19.5518
1867.16	19.5127
1868.16	22.3345
1869.17	18.5232
1870.17	20.4149
1871.17	19.4551
1872.17	18.4917
1873.18	23.2218
1874.18	21.3082
1875.18	15.5931
1876.18	18.4046
1877.18	21.2164
1878.18	20.2353
1879.19	18.371
1880.19	21.2205
1881.19	18.3717
1882.19	19.284
1883.19	20.1805
1884.19	23.9222
1885.19	16.3857
1886.19	18.2892
1887.19	22.0568
1888.19	20.1432
1889.19	20.1099
1890.19	18.2099
1891.19	19.1573
1892.18	20.0889
1893.18	21.0152
1894.18	20.9768
1895.18	18.1427
1896.18	20.9621
1897.18	21.9106
1898.17	23.792
1899.17	20.0116
1900.17	22.8103
1901.16	22.8037
1902.16	20.9353
1903.16	20.9375
1904.16	18.1028
1905.15	20.9141
1906.15	19.9601
1907.14	22.7572
1908.14	22.7543
1909.14	21.8189
1910.13	19.0117
1911.13	20.9128
1912.12	19.9711
1913.12	21.8456
1914.11	25.6197
1915.11	21.8663
1916.1	20.9252
1917.1	20.9089
1918.09	19.9499
1919.08	19.9574
1920.08	20.9247
1921.07	20.9228
1922.06	19.9887
1923.06	21.8711
1924.05	20.9108
1925.04	19.9499
1926.04	16.1765
1927.03	18.0823
1928.02	21.8764
1929.01	23.7752
1930	20.9444
1931	18.1134
1931.99	19.0549
1932.98	19.0379
1933.97	20.9333
1934.96	20.9892
1935.95	18.169
1936.94	21.9569
1937.93	20.0274
1938.92	20.0206
1939.91	21.9316
1940.9	20.9881
1941.89	19.0936
1942.88	21.9601
1943.87	20.0331
1944.86	19.0872
1945.85	20.0561
1946.84	21.9769
1947.83	20.0552
1948.82	22.9153
1949.8	21.9678
1950.79	19.1191
1951.78	21.0629
1952.77	18.1934
1953.76	19.1504
1954.74	17.1858
1955.73	20.0449
1956.72	20.0741
1957.7	22.9697
1958.69	20.0925
1959.68	17.1975
1960.66	24.8657
1961.65	21.9631
1962.63	23.8775
1963.62	19.076
1964.61	20.0367
1965.59	20.0285
1966.58	18.1124
1967.56	21.9603
1968.55	22.9199
1969.53	18.0971
1970.52	20.95
1971.5	23.8094
1972.48	21.8849
1973.47	23.7925
1974.45	22.8128
1975.44	21.8504
1976.42	21.8563
1977.4	21.8522
1978.39	24.7114
1979.37	20.8638
1980.35	22.7771
1981.33	22.7588
1982.31	19.8713
1983.3	23.6818
1984.28	21.7462
1985.26	21.7301
1986.24	23.6287
1987.22	18.8505
1988.21	24.5635
1989.19	24.5266
1990.17	25.387
1991.15	25.4194
1992.13	23.1927
1993.11	23.8192
1994.09	26.4431
1995.07	23.1938
1996.05	24.5611
1997.03	25.6983
1998.01	25.5139
1998.99	26.9559
1999.97	26.0089
2000.95	26.3031
2001.92	28.1368
2002.9	26.742
2003.88	26.6099
2004.86	26.185
2005.84	26.1827
2006.81	27.3409
2007.79	26.2305
2008.77	26.7838
2009.75	27.6608
2010.73	27.4993
2011.7	31.128
2012.68	26.6806
2013.67	27.5896
2014.66	24.7265
2015.64	25.6531
2016.63	27.5403
2017.62	28.4963
2018.61	26.5799
2019.6	26.5389
2020.58	25.5891
2021.57	26.5246
2022.56	22.7699
2023.55	26.4893
2024.54	23.661
2025.52	20.8279
2026.51	23.6074
2027.5	25.5369
2028.48	24.5718
2029.47	25.5439
2030.45	23.6
2031.44	23.6085
2032.43	22.6773
2033.41	24.5732
2034.4	20.8355
2035.38	25.4687
2036.37	20.8443
2037.35	24.5766
2038.34	19.8939
2039.32	20.8142
2040.31	22.6617
2041.29	23.5704
2042.27	25.4221
2043.26	22.6147
2044.24	21.7062
2045.23	18.8949
2046.21	22.6681
2047.19	20.7788
2048.17	19.8189
2049.16	18.8896
2050.14	19.842
2051.12	21.7235
2052.11	21.7095
2053.09	19.8467
2054.07	21.7363
2055.05	18.9353
2056.03	21.7296
2057.01	22.6557
2058	16.1146
2058.98	20.8035
2059.96	20.8115
2060.94	23.6098
2061.92	20.8088
2062.9	18.9388
2063.88	18.0115
2064.86	22.704
2065.84	19.9085
2066.82	18.9799
2067.8	21.8047
2068.78	20.8731
2069.76	20.8658
2070.73	20.862
2071.71	17.1126
2072.69	19.0175
2073.67	19.9539
2074.65	19.9569
2075.63	20.9225
2076.6	17.1673
2077.58	18.1006
2078.56	19.0378
2079.54	19.9904
2080.51	20.0083
2081.49	17.1714
2082.47	18.1144
2083.45	20.9499
2084.42	17.1669
2085.4	19.0558
2086.37	20.0055
2087.35	20.0189
2088.32	21.9155
2089.3	15.2914
2090.28	21.9305
2091.25	18.1455
2092.23	18.1573
2093.2	19.1275
2094.18	19.1437
2095.15	20.0963
2096.13	16.2825
2097.1	20.0761
2098.07	17.2139
2099.05	17.2079
2100.02	17.2035
2101	21.0017
2101.97	20.0631
2102.94	17.2104
2103.92	19.0985
2104.89	20.0499
2105.86	17.2112
2106.83	19.1182
2107.8	21.9695
2108.78	18.1471
2109.75	18.1453
2110.72	20.9972
2111.69	17.194
2112.66	21.9351
2113.63	18.1448
2114.61	20.0463
2115.58	16.2429
2116.55	16.2338
2117.52	18.125
2118.49	19.0655
2119.46	16.2
2120.43	20.9241
2121.4	18.0836
2122.37	18.0977
2123.34	19.0555
2124.31	19.0523
2125.28	19.026
2126.25	18.9981
2127.21	17.0878
2128.18	21.806
2129.15	18.0195
2130.12	19.9036
2131.09	17.0617
2132.06	19.883
2133.02	20.8131
2133.99	20.8105
2134.96	19.8661
2135.93	17.0294
2136.89	19.84
2137.86	18.8993
2138.83	17.0056
2139.79	16.0648
2140.76	19.8178
2141.73	16.0437
2142.69	16.0336
2143.66	18.87
2144.62	18.8313
2145.59	17.8901
2146.55	16.9449
2147.52	16.9361
2148.48	18.8047
2149.45	16.9141
2150.42	17.8304
2151.38	17.8241
2152.34	16.893
2153.31	15.948
2154.27	19.6862
2155.24	19.6567
2156.2	18.6946
2157.16	15.8834
2158.13	17.7567
2159.09	18.6921
2160.05	17.7453
2161.01	15.8607
2161.98	14.9202
2162.94	15.8503
2163.9	19.5716
2164.86	20.4877
2165.83	16.7582
2166.79	18.6162
2167.75	17.6698
2168.71	18.5733
2169.67	18.5781
2170.63	17.6677
2171.59	19.5229
2172.56	15.7712
2173.51	16.6928
2174.48	17.6247
2175.44	16.6939
2176.4	15.7592
2177.36	18.5392
2178.32	17.6094
2179.28	19.454
2180.23	16.6678
2181.19	16.6631
2182.15	18.5119
2183.11	18.5031
2184.07	19.4111
2185.03	18.4765
2185.99	19.4083
2186.95	15.7111
2187.9	18.5125
2188.86	17.5746
2189.82	17.5542
2190.78	17.5448
2191.73	17.5468
2192.69	21.2611
2193.65	13.8468
2194.6	15.7238
2195.56	19.4381
2196.52	19.4169
2197.47	19.3972
2198.43	17.5399
2199.38	16.629
2200.34	24.0914
2201.3	18.5403
2202.25	16.6205
2203.21	15.7167
2204.16	18.5715
2205.12	18.5362
2206.07	20.3499
2207.03	14.7685
2207.98	20.3567
2208.93	20.3714
2209.89	17.5821
2210.84	18.5167
2211.8	18.5267
2212.75	18.537
2213.7	17.595
2214.66	17.6017
2215.61	20.4119
2216.56	16.6768
2217.51	15.7395
2218.47	17.6061
2219.42	20.4147
2220.37	18.5543
2221.32	17.6143
2222.27	17.5966
2223.23	17.5959
2224.18	16.6744
2225.13	17.6258
2226.08	15.7681
2227.03	16.716
2227.98	17.661
2228.93	17.655
2229.88	14.8413
2230.83	16.7294
2231.78	16.7425
2232.73	19.5742
2233.68	20.5277
2234.63	16.769
2235.58	18.6362
2236.53	15.8106
2237.48	18.6375
2238.43	16.7772
2239.38	20.5691
2240.33	15.8437
2241.27	19.6226
2242.22	20.57
2243.17	19.6314
2244.12	18.6782
2245.07	17.7407
2246.01	14.9243
2246.96	17.7707
2247.91	18.7234
2248.85	18.7182
2249.8	20.6097
2250.75	18.7115
2251.69	15.8591
2252.64	17.7527
2253.59	16.8293
2254.53	17.7909
2255.48	17.7911
2256.42	18.7425
2257.37	17.8046
2258.32	16.862
2259.26	16.8661
2260.2	17.8223
2261.15	16.8778
2262.1	16.8869
2263.04	14.9899
2263.98	17.8647
2264.93	19.7973
2265.87	16.9431
2266.81	16.9331
2267.76	18.8264
2268.7	17.8598
2269.65	15.0073
2270.59	16.9349
2271.53	20.7696
2272.47	16.9531
2273.42	19.8251
2274.36	15.0423
2275.3	18.8733
2276.24	18.8761
2277.18	15.0577
2278.13	16.9954
2279.07	15.0841
2280.01	18.9105
2280.95	15.0548
2281.89	18.8798
2282.83	15.0522
2283.77	14.1076
2284.71	18.9372
2285.65	17.9856
2286.59	18.935
2287.54	17.9913
2288.47	17.0346
2289.41	19.9075
2290.35	16.0348
2291.29	16.9957
2292.23	18.9361
2293.17	25.6935
2294.11	20.8856
2295.05	17.0193
2295.99	16.0452
2296.93	17.9545
2297.86	15.0762
2298.8	18.9441
2299.74	15.1004
2300.68	17.9935
2301.61	18.9666
2302.55	15.1037
2303.49	17.9953
2304.43	18.9639
2305.36	17.0418
2306.3	18.9793
2307.24	18.9809
2308.17	18.0068
2309.11	18.0027
2310.04	18.9841
2310.98	18.9884
2311.92	17.9912
2312.85	17.0078
2313.79	18.9413
2314.72	17.0309
2315.66	19.9414
2316.59	17.9824
2317.52	18.9392
2318.46	17.9748
2319.39	16.9965
2320.33	21.8138
2321.26	18.9224
2322.2	22.8012
2323.13	22.8139
2324.06	30.5537
2325	33.4429
2325.93	41.1296
2326.86	91.2651
2327.79	310.033
2328.73	87.3133
2329.66	32.3508
2330.59	21.7515
2331.52	20.7836
2332.46	15.9708
2333.39	21.7358
2334.32	15.9497
2335.25	18.822
2336.18	16.897
2337.11	18.814
2338.04	16.8855
2338.97	15.9192
2339.91	18.8013
2340.84	16.8678
2341.77	14.9265
2342.7	17.789
2343.63	15.8667
2344.56	18.7406
2345.49	18.7357
2346.41	16.8034
2347.34	16.797
2348.27	16.7949
2349.2	17.7524
2350.13	21.548
2351.06	18.5886
2351.99	16.7508
2352.91	18.6314
2353.84	18.6024
2354.77	18.6012
2355.7	18.6003
2356.63	14.777
2357.55	17.6095
2358.48	20.4489
2359.41	16.6376
2360.33	16.6262
2361.26	17.5573
2362.19	15.6424
2363.11	18.4652
2364.04	17.5066
2364.97	16.5492