File: Data/3-Raman/raw/bu19w-ff2-fi05-v_150 (500nm)_532nm_edge_100%_x100_vis_h50um_15sx2_01.txt
#Acq. time (s)=	15
#Accumulations=	2
#Range (cm-¹)=	100...5000
#Windows=	1
#Auto scanning=	Off
#Autofocus=	Off
#Macrospot=	Off
#AutoExposure=	Off
#Spike filter=	Multiple accum.
#Delay time (s)=	2
#Binning=	1
#Readout mode=	Signal
#DeNoise=	Off
#ICS correction=	On
#Dark correction=	Off
#Inst. Process=	Off
#Detector Gain=	Best Dynamic
#Detector ADC=	50 kHz HS
#Detector temperature (°C)=	-60.09
#Instrument=	LabRAM HR Evol
#Detector=	SIN-EM FIVIS
#Objective=	x100_VIS
#Grating=	150 (500nm)
#ND Filter=	100%
#Laser=	532nm_Edge
#Hole=	49.98
#Temperature=	0
#Range=	Visible
#StageXY=	75x50mm Scan+
#StageZ=	Z motor
#X (µm)=	0
#Y (µm)=	0
#Z (µm)=	-14.8
#Full time(s)=	34
#Project=	21_05_14
#Sample=	BU19w
#Site=
#Title=	BU19w-FF2-FI05-V_150 (500nm)_532nm_Edge_100%_x100_VIS_H50um_15sX2
#Remark=
#Date=	14.05.2021 17:54
#Acquired=	14.05.2021 17:54:31
102.699	1892.64
107.322	1677.92
111.942	1493.35
116.56	1394.82
121.173	1339.67
125.787	1260.55
130.398	1240.24
135.006	1128.91
139.613	1091.93
144.215	1066.11
148.817	1181.47
153.417	1620.64
158.014	1730.97
162.607	1188.59
167.2	919.884
171.79	909.768
176.379	979.326
180.963	1409.84
185.547	1642.19
190.128	1184.71
194.705	919.277
199.282	809.204
203.857	768.772
208.43	740.585
212.998	698.961
217.566	717.269
222.132	758.792
226.693	940.707
231.254	1051.43
235.813	1108.33
240.368	1579.75
244.923	1439.5
249.475	1023.93
254.023	870.85
258.571	800.702
263.117	922.695
267.658	1352.72
272.199	2507.34
276.738	2827.82
281.273	1882.09
285.807	1193.09
290.34	948.254
294.868	983.472
299.396	1087.14
303.919	955.675
308.443	856.077
312.964	834.605
317.481	960.445
321.998	1237.61
326.51	1347.83
331.023	1052.29
335.533	942.015
340.039	1131.47
344.544	1481.27
349.046	1417.05
353.547	1074.35
358.045	881.861
362.542	977.323
367.036	1038.14
371.527	857.559
376.017	756.034
380.503	783.5
384.99	830.974
389.471	930.024
393.953	856.31
398.43	753.106
402.908	711.629
407.381	781.474
411.854	992.362
416.323	1033.04
420.791	777.24
425.256	636.989
429.72	616.635
434.18	597.231
438.64	576.919
443.095	603.618
447.551	675.982
452.003	725.284
456.454	689.02
460.901	688.738
465.348	640.477
469.791	660.615
474.231	667.743
478.672	724.158
483.108	850.357
487.544	923.038
491.976	983.805
496.408	952.212
500.836	819.557
505.261	780.084
509.687	712.744
514.108	672.112
518.529	644.235
522.946	622.477
527.361	620.393
531.776	606.934
536.187	593.495
540.595	627.539
545.003	656.967
549.408	674.853
553.812	714.522
558.212	656.907
562.61	645.807
567.007	602.276
571.401	666.753
575.792	698.963
580.184	910.179
584.571	1239.35
588.956	1147.34
593.341	839.271
597.722	757.324
602.101	898.5
606.48	1065.2
610.854	972.303
615.227	791.429
619.597	686.74
623.967	637.463
628.334	641.679
632.698	697.522
637.06	714.924
641.422	714.063
645.779	694.523
650.135	710.178
654.491	821.661
658.842	971.966
663.192	1059.23
667.539	1089.27
671.884	1110.85
676.23	1057.96
680.571	881.895
684.91	725.778
689.247	664.553
693.583	618.255
697.916	574.275
702.247	575.693
706.576	594.759
710.902	579.533
715.229	572.848
719.551	583.405
723.872	563.877
728.19	556.345
732.506	574.103
736.82	558.365
741.134	543.628
745.444	592.403
749.752	584.614
754.058	606.653
758.362	670.051
762.664	729.956
766.964	870.308
771.264	1074.23
775.559	1167.78
779.853	1002.26
784.144	837.073
788.434	698.271
792.722	666.242
797.007	630.048
801.29	597.732
805.572	594.337
809.851	575.652
814.13	601.098
818.406	597.908
822.679	542.053
826.95	573.214
831.219	589.017
835.486	559.596
839.752	598.495
844.015	593.159
848.276	571.943
852.535	562.827
856.792	596.697
861.047	589.72
865.3	591.346
869.551	574.162
873.8	587.582
878.047	582.236
882.292	584.334
886.534	576.344
890.775	578.736
895.014	575.139
899.251	560.418
903.486	563.718
907.719	570.208
911.95	588.996
916.179	605.443
920.406	585.189
924.63	601.86
928.853	658.032
933.074	655.135
937.293	699.165
941.51	799.675
945.723	886.873
949.936	878.093
954.147	756.565
958.356	718.409
962.563	727.175
966.768	702.015
970.971	676.021
975.172	663.892
979.371	638.176
983.568	616.757
987.761	631.228
991.954	588.954
996.145	611.733
1000.33	613.52
1004.52	620.693
1008.71	612.075
1012.89	633.021
1017.07	649.741
1021.25	651.528
1025.43	663.628
1029.6	692.848
1033.77	733.11
1037.95	844
1042.11	1041.99
1046.28	1460.05
1050.45	1626.96
1054.61	1345.93
1058.77	1051.12
1062.93	881.701
1067.09	831.839
1071.24	878.314
1075.4	949.714
1079.55	1165.67
1083.7	1505.5
1087.85	1660.6
1091.99	1539.3
1096.14	1334.25
1100.28	1291.19
1104.42	1554.99
1108.55	1618.38
1112.69	1446.49
1116.82	1320.73
1120.96	1318.18
1125.09	1454.82
1129.21	1497.62
1133.34	1375.2
1137.46	1141.04
1141.59	1064.94
1145.71	1044.05
1149.83	1111.19
1153.94	1283.01
1158.06	1218.47
1162.17	1088.36
1166.28	1041.69
1170.39	960.603
1174.5	833.031
1178.6	717.989
1182.7	709.065
1186.8	667.807
1190.9	706.416
1195	683.303
1199.1	676.379
1203.19	678.55
1207.28	680.711
1211.37	700.099
1215.46	795.019
1219.54	848.372
1223.63	825.282
1227.71	763.585
1231.79	799.379
1235.87	880.082
1239.95	831.488
1244.02	811.032
1248.09	883.014
1252.16	801.456
1256.23	734.955
1260.3	737.478
1264.36	912.268
1268.43	2110.62
1272.49	1571.35
1276.55	819.93
1280.6	675.02
1284.66	674.515
1288.71	663.92
1292.76	668.265
1296.81	669.561
1300.86	662.675
1304.91	667.764
1308.95	653.727
1312.99	653.574
1317.03	654.205
1321.07	662.81
1325.11	667.008
1329.14	696.442
1333.18	664.348
1337.21	668.247
1341.24	670.055
1345.26	668.815
1349.29	701.45
1353.31	740.945
1357.33	728.709
1361.35	784.83
1365.37	855.83
1369.39	1628.78
1373.4	3208.06
1377.41	1505.08
1381.43	776.4
1385.43	707.281
1389.44	741.612
1393.45	867.829
1397.45	766.787
1401.45	697.031
1405.45	658.857
1409.45	644.374
1413.44	658.529
1417.44	637.146
1421.43	641.38
1425.42	631.572
1429.41	620.565
1433.39	622.564
1437.38	629.398
1441.36	607.623
1445.34	627.177
1449.32	645.713
1453.3	620.709
1457.27	623.277
1461.24	636.485
1465.22	609.21
1469.19	627.249
1473.15	594.238
1477.12	636.648
1481.09	615.281
1485.05	623.254
1489.01	619.487
1492.97	607.983
1496.93	633.535
1500.88	628.007
1504.83	615.826
1508.79	657.224
1512.74	654.881
1516.68	624.468
1520.63	633.911
1524.57	611.386
1528.52	631.597
1532.46	637.315
1536.4	636.248
1540.33	629.387
1544.27	638.995
1548.2	629.229
1552.14	634.925
1556.07	626.958
1559.99	657.63
1563.92	663.056
1567.84	652.95
1571.77	642.83
1575.69	652.018
1579.61	672.738
1583.52	654.846
1587.44	660.052
1591.35	646.003
1595.27	643.505
1599.18	638.161
1603.09	641.547
1606.99	652.664
1610.9	652.281
1614.8	658.687
1618.7	674.693
1622.6	681.122
1626.5	655.139
1630.39	675.239
1634.29	665.784
1638.18	658.262
1642.07	649.985
1645.96	672.449
1649.85	654.7
1653.73	659.946
1657.62	639.211
1661.5	660.668
1665.38	647.418
1669.26	668.646
1673.13	663.772
1677.01	654.883
1680.88	647.613
1684.75	633.576
1688.62	660.678
1692.49	645.481
1696.35	645.522
1700.22	691.23
1704.08	651.872
1707.94	658.147
1711.8	660.541
1715.66	636.463
1719.51	673.893
1723.37	659.306
1727.22	658.793
1731.07	645.121
1734.92	653.985
1738.76	655.234
1742.61	667.647
1746.45	657.01
1750.29	670.905
1754.13	640.531
1757.97	655.489
1761.81	635.488
1765.64	635.639
1769.47	679.877
1773.31	655.485
1777.14	650.706
1780.96	649.832
1784.79	665.846
1788.61	665.115
1792.43	667.212
1796.25	669.305
1800.07	627.875
1803.89	647.306
1807.71	663.924
1811.52	671.968
1815.33	659.987
1819.14	638.325
1822.95	653.332
1826.76	683.266
1830.56	700.73
1834.37	676.589
1838.17	655.212
1841.97	670.392
1845.77	666.743
1849.56	665.79
1853.36	659.897
1857.15	677.185
1860.94	654.212
1864.73	666.668
1868.52	671.731
1872.31	675.032
1876.09	667.33
1879.87	690.264
1883.66	653.426
1887.43	666.791
1891.21	685.13
1894.99	675.812
1898.76	669.436
1902.53	685.365
1906.31	661.787
1910.08	682.594
1913.84	654.677
1917.61	690.704
1921.37	665.075
1925.14	677.445
1928.9	672.3
1932.66	686.698
1936.41	688.998
1940.17	697.83
1943.92	656.25
1947.68	656.161
1951.43	674.599
1955.18	673.021
1958.92	684.246
1962.67	676.626
1966.41	676.443
1970.16	657.15
1973.9	674.315
1977.64	687.561
1981.37	667.952
1985.11	699.617
1988.84	691.988
1992.57	694.444
1996.31	683.782
2000.03	678.63
2003.76	675.445
2007.49	701.543
2011.21	676.87
2014.93	702.991
2018.65	687.317
2022.37	683.894
2026.09	710.152
2029.81	693.233
2033.52	694.379
2037.23	668.779
2040.94	696.32
2044.65	661.5
2048.36	694.583
2052.07	671.898
2055.77	696.051
2059.47	692.368
2063.17	717.404
2066.87	700.25
2070.57	682.136
2074.27	693.542
2077.96	694.883
2081.65	695.276
2085.34	689.675
2089.03	698.944
2092.72	705.79
2096.41	717.435
2100.09	682.22
2103.77	685.953
2107.46	675.612
2111.14	697.755
2114.81	704.992
2118.49	692.502
2122.16	711.312
2125.84	676.262
2129.51	718.013
2133.18	682.891
2136.85	671.778
2140.51	707.589
2144.18	686.149
2147.84	720.811
2151.5	712.251
2155.16	679.033
2158.82	707.224
2162.48	692.543
2166.13	715.396
2169.79	709.255
2173.44	681.56
2177.09	710.373
2180.74	720.122
2184.38	706.224
2188.03	687.206
2191.67	695.719
2195.32	718.162
2198.96	727.036
2202.6	695.879
2206.23	695.835
2209.87	731.589
2213.5	678.62
2217.14	704.436
2220.77	723.006
2224.4	699.285
2228.03	694.806
2231.65	699.621
2235.28	708.169
2238.9	707.437
2242.52	719.685
2246.14	710.583
2249.76	696.872
2253.38	691.579
2256.99	694.698
2260.6	694.953
2264.21	700.811
2267.82	716.245
2271.44	705.381
2275.04	719.637
2278.65	720.436
2282.25	682.166
2285.85	720.529
2289.45	697.355
2293.05	696.832
2296.65	732.333
2300.25	719.508
2303.84	693.233
2307.43	712.323
2311.02	747.436
2314.62	1026.01
2318.2	907.245
2321.79	715.318
2325.38	703.119
2328.96	727.816
2332.54	691.929
2336.12	707.88
2339.7	703.935
2343.28	720.585
2346.85	711.791
2350.43	705.803
2354	686.723
2357.57	702.149
2361.14	718.413
2364.71	717.003
2368.27	695.334
2371.84	724.693
2375.4	705.863
2378.96	709.309
2382.52	715.584
2386.08	704.471
2389.64	697.2
2393.19	694.706
2396.75	685.12
2400.3	727.164
2403.85	742.902
2407.4	706.52
2410.95	708.016
2414.49	695.861
2418.04	693.949
2421.58	702.286
2425.12	702.533
2428.66	704.784
2432.2	723.859
2435.74	716.214
2439.27	729.052
2442.81	717.738
2446.34	690.549
2449.87	697.124
2453.4	720.457
2456.93	707.465
2460.45	711.077
2463.98	693.679
2467.5	715.811
2471.02	726.488
2474.54	713.566
2478.06	733.922
2481.58	724.912
2485.09	689.167
2488.61	726.794
2492.12	695.902
2495.63	702.389
2499.14	718.331
2502.65	701.244
2506.15	688.785
2509.66	713.548
2513.16	677.962
2516.66	705.737
2520.16	697.886
2523.66	696.908
2527.16	705.516
2530.66	713.277
2534.15	701.857
2537.64	685.971
2541.13	696.214
2544.62	693.907
2548.11	697.207
2551.6	692.292
2555.08	714.628
2558.57	689.72
2562.05	684.516
2565.53	698.153
2569.01	713.924
2572.49	713.064
2575.96	682.299
2579.44	702.279
2582.91	696.896
2586.38	719.817
2589.85	696.879
2593.32	722.136
2596.79	711.445
2600.25	689.277
2603.72	673.407
2607.18	684.822
2610.64	678.245
2614.1	710.38
2617.56	716.343
2621.02	715.434
2624.47	689.337
2627.92	704.435
2631.38	684.817
2634.83	708.155
2638.28	693.003
2641.72	709.283
2645.17	713.07
2648.61	696.673
2652.06	696.334
2655.5	709.12
2658.94	709.448
2662.38	696.439
2665.82	715.567
2669.25	697.812
2672.69	697.143
2676.12	716.244
2679.55	701.75
2682.98	681.878
2686.41	705.376
2689.84	683.613
2693.26	673.784
2696.69	705.056
2700.11	704.78
2703.53	684.804
2706.95	696.07
2710.37	687.992
2713.79	683.766
2717.2	684.335
2720.62	711.127
2724.03	692.281
2727.44	712.725
2730.85	674.218
2734.26	674.027
2737.66	692.599
2741.07	696.065
2744.47	695.632
2747.87	702.727
2751.28	688.179
2754.67	708.289
2758.07	688.963
2761.47	684.488
2764.86	681.8
2768.26	674.252
2771.65	700.589
2775.04	685.347
2778.43	678.477
2781.82	668.727
2785.2	696.582
2788.59	711.234
2791.97	703.254
2795.35	675.635
2798.73	684.49
2802.11	713.025
2805.49	698.418
2808.87	683.791
2812.24	680.382
2815.62	708.682
2818.99	681.015
2822.36	710.415
2825.73	688.546
2829.1	713.366
2832.46	689.862
2835.83	703.74
2839.19	670.243
2842.55	707.689
2845.91	671.728
2849.27	701.355
2852.63	681.374
2855.99	693.22
2859.34	711.757
2862.69	688.198
2866.05	681.505
2869.4	708.549
2872.75	687.681
2876.09	690.273
2879.44	708.876
2882.78	692.569
2886.13	682.785
2889.47	679.645
2892.81	691.419
2896.15	697.438
2899.49	688.214
2902.82	682.665
2906.16	701.667
2909.49	680.848
2912.82	694.092
2916.16	691.118
2919.49	719.306
2922.81	690.724
2926.14	698.885
2929.46	704.169
2932.79	692.292
2936.11	693.635
2939.43	698.745
2942.75	713.271
2946.07	723.118
2949.39	700.018
2952.7	685.38
2956.02	653.973
2959.33	683.709
2962.64	702.14
2965.95	694.458
2969.26	701.129
2972.57	711.423
2975.87	709.805
2979.17	721.169
2982.48	687.522
2985.78	711.182
2989.08	717.973
2992.38	683.462
2995.68	685.628
2998.97	706.612
3002.27	715.347
3005.56	710.985
3008.85	717.953
3012.14	729.676
3015.43	717.825
3018.72	708.776
3022	703.486
3025.29	710.481
3028.57	698.587
3031.85	701.771
3035.14	708.704
3038.41	709.973
3041.69	727.337
3044.97	720.127
3048.24	722.355
3051.52	728.418
3054.79	733.52
3058.06	723.359
3061.33	694.988
3064.6	752.08
3067.87	754.038
3071.13	729.794
3074.4	744.835
3077.66	782.627
3080.92	744.041
3084.18	744.475
3087.44	749.794
3090.7	767.649
3093.95	749.573
3097.21	784.835
3100.46	764.01
3103.71	772.903
3106.96	792.313
3110.21	758.193
3113.46	780.212
3116.71	813.703
3119.95	801.497
3123.2	793.087
3126.44	836.102
3129.68	826.722
3132.92	832.577
3136.16	798.356
3139.4	817.493
3142.63	856.652
3145.87	843.418
3149.1	840.703
3152.33	851.315
3155.56	874.343
3158.79	874.461
3162.02	891.756
3165.25	883.227
3168.47	912.798
3171.69	931.828
3174.92	930.745
3178.14	907.686
3181.36	934.256
3184.58	945.476
3187.79	984.286
3191.01	942.057
3194.22	957.961
3197.43	950.019
3200.65	937.346
3203.86	940.896
3207.07	1000.63
3210.27	970.962
3213.48	989.898
3216.69	960.33
3219.89	999.274
3223.09	982.184
3226.29	999.374
3229.49	1018.55
3232.69	1004.37
3235.89	1000.81
3239.08	1033.53
3242.28	1037.76
3245.47	1025.8
3248.66	1029.17
3251.85	1019.23
3255.04	1038.88
3258.23	1026.92
3261.42	1032.95
3264.6	1014
3267.79	1012.12
3270.97	1037.87
3274.15	1036.87
3277.33	1054.8
3280.51	1042.89
3283.68	1060.57
3286.86	1060.02
3290.04	1079.55
3293.21	1026.64
3296.38	1089.92
3299.55	1063.94
3302.72	1053.02
3305.89	1067.65
3309.06	1084.96
3312.22	1079.35
3315.39	1116.43
3318.55	1114.51
3321.71	1096.5
3324.87	1121.12
3328.03	1139.09
3331.19	1119.3
3334.34	1123.24
3337.5	1109.35
3340.65	1143.57
3343.81	1146.87
3346.96	1159.92
3350.11	1124.93
3353.25	1156.03
3356.4	1150.43
3359.55	1172.31
3362.69	1178.21
3365.84	1197.39
3368.98	1212.83
3372.12	1232.2
3375.26	1236.55
3378.4	1214.53
3381.53	1257.65
3384.67	1275.37
3387.8	1272.31
3390.94	1278.79
3394.07	1279.07
3397.2	1304.64
3400.33	1332.37
3403.46	1417.26
3406.58	1483.41
3409.71	1690.6
3412.83	2298.8
3415.96	3831.42
3419.08	5325.05
3422.2	4127.19
3425.32	2435.87
3428.44	1719.22
3431.55	1518.72
3434.67	1425.68
3437.78	1380.52
3440.89	1299.19
3444	1291.06
3447.12	1292.45
3450.22	1279.33
3453.33	1288.11
3456.44	1281.46
3459.54	1312.82
3462.65	1277.56
3465.75	1290.67
3468.85	1299.55
3471.95	1305.96
3475.05	1376.84
3478.15	1404.18
3481.24	1459.86
3484.34	1556.17
3487.43	1706.29
3490.53	1926.69
3493.62	2246.12
3496.71	2647.18
3499.79	2904.9
3502.88	2940.32
3505.97	2565.13
3509.05	2168.79
3512.14	1813.27
3515.22	1582.88
3518.3	1415.95
3521.38	1315.2
3524.46	1229.82
3527.54	1140.76
3530.61	1132.68
3533.69	1092.81
3536.76	1078.25
3539.83	1040.84
3542.9	1006.71
3545.97	997.086
3549.04	944.767
3552.11	939.488
3555.18	940.976
3558.24	879.134
3561.3	919.323
3564.37	905.453
3567.43	882.137
3570.49	868.136
3573.55	867.308
3576.61	842.73
3579.66	817.133
3582.72	818.016
3585.77	818.875
3588.82	820.605
3591.87	827.029
3594.92	775.585
3597.97	762.995
3601.02	792.963
3604.07	776.462
3607.11	735.366
3610.16	755.727
3613.2	747.687
3616.24	750.057
3619.28	728.87
3622.32	715.275
3625.36	678.172
3628.39	708.923
3631.43	713.226
3634.46	706.349
3637.5	650.668
3640.53	650.587
3643.56	676.076
3646.59	667.59
3649.62	639.427
3652.64	641.611
3655.67	652.174
3658.69	624.542
3661.72	633.515
3664.74	617.723
3667.76	616.086
3670.78	585.272
3673.79	595.983
3676.81	585.969
3679.83	577.817
3682.84	569.65
3685.86	570.002
3688.87	571.319
3691.88	553.71
3694.89	574.844
3697.9	569.515
3700.91	547.13
3703.91	538.96
3706.92	558.288
3709.92	528.15
3712.92	539.767
3715.92	547.604
3718.92	543.032
3721.92	507.939
3724.92	535.633
3727.92	527.105
3730.91	525.196
3733.91	507.041
3736.9	510.741
3739.89	501.056
3742.88	537.944
3745.87	500.585
3748.86	498.381
3751.85	505.658
3754.83	497.751
3757.82	515.458
3760.8	502.772
3763.78	514.723
3766.76	511.547
3769.74	509.366
3772.72	508.175
3775.7	531.588
3778.67	517.231
3781.65	501.006
3784.62	528.246
3787.6	518.686
3790.57	504.483
3793.54	496.942
3796.51	488.484
3799.47	508.409
3802.44	467.941
3805.41	498.315
3808.37	484.323
3811.33	510.989
3814.3	486.615
3817.26	493.466
3820.22	483.294
3823.18	489.247
3826.13	478.162
3829.09	494.558
3832.04	489.185
3835	492.386
3837.95	472.791
3840.9	472.183
3843.85	500.132
3846.8	484.328
3849.75	475.199
3852.69	473.702
3855.64	476.028
3858.58	470.722
3861.53	495.993
3864.47	490.668
3867.41	492.006
3870.35	483.737
3873.29	468.725
3876.22	478.608
3879.16	467.32
3882.1	476.143
3885.03	485.89
3887.96	483.12
3890.89	490.907
3893.82	480.371
3896.75	487.079
3899.68	477.427
3902.61	477.321
3905.53	486.875
3908.46	494.481
3911.38	470.33
3914.3	478.792
3917.23	472.935
3920.15	476.618
3923.06	477.356
3925.98	469.416
3928.9	468.144
3931.81	459.298
3934.73	458.215
3937.64	463.945
3940.55	484.008
3943.46	475.353
3946.37	466.744
3949.28	463.92
3952.19	477.393
3955.09	482.292
3958	463.267
3960.9	466.297
3963.8	483.738
3966.71	464.768
3969.61	476.511
3972.51	479.62
3975.4	458.691
3978.3	462.694
3981.2	471.497
3984.09	428.357
3986.99	456.365
3989.88	466.989
3992.77	451.72
3995.66	455.693
3998.55	457.765
4001.43	452.139
4004.32	454.24
4007.21	439.97
4010.09	465.213
4012.98	447.074
4015.86	465.589
4018.74	436.815
4021.62	442.783
4024.5	451.665
4027.37	448.957
4030.25	439.49
4033.13	436.789
4036	455.399
4038.87	444.983
4041.75	452.89
4044.62	448.197
4047.49	415.416
4050.35	441.792
4053.22	439.116
4056.09	441.305
4058.95	430.841
4061.82	445.633
4064.68	450.716
4067.54	435.368
4070.4	444.334
4073.26	441.616
4076.12	446.682
4078.98	451.751
4081.83	447.074
4084.69	432.628
4087.54	425.963
4090.4	445.673
4093.25	437.073
4096.1	411.845
4098.95	443.305
4101.8	438.589
4104.64	434.812
4107.49	422.202
4110.33	434.035
4113.18	430.155
4116.02	424.267
4118.86	437.925
4121.7	427.159
4124.54	419.359
4127.38	425.325
4130.22	428.456
4133.05	422.865
4135.89	420.956
4138.72	421.469
4141.56	424.111
4144.39	438.919
4147.22	443
4150.05	428.437
4152.88	420.579
4155.7	419.407
4158.53	414.329
4161.36	425.036
4164.18	412.268
4167	424.937
4169.82	425.895
4172.65	421.979
4175.46	426.869
4178.28	393.638
4181.1	410.309
4183.92	408.415
4186.73	430.999
4189.55	436.018
4192.36	413.688
4195.17	431.552
4197.98	411.227
4200.79	442.859
4203.6	433.31
4206.41	429.636
4209.21	426.938
4212.02	404.562
4214.83	408.861
4217.63	404.416
4220.43	420.607
4223.23	418.032
4226.03	408.551
4228.83	399.102
4231.63	418.376
4234.42	412.952
4237.22	394.621
4240.01	406.073
4242.81	417.575
4245.6	402.193
4248.39	411.683
4251.18	403.187
4253.97	411.652
4256.76	409.097
4259.55	369.453
4262.33	397.99
4265.12	383.403
4267.9	398.976
4270.68	394.425
4273.47	398.888
4276.25	379.059
4279.03	394.52
4281.8	382.673
4284.58	395.042
4287.36	391.183
4290.13	383.242
4292.91	390.517
4295.68	389.737
4298.45	414.299
4301.22	403.349
4303.99	391.372
4306.76	385.488
4309.53	393.859
4312.3	386.962
4315.06	381.021
4317.83	394.385
4320.59	383.293
4323.35	382.353
4326.11	387.525
4328.87	396.756
4331.63	377.455
4334.39	378.519
4337.15	381.644
4339.9	373.597
4342.66	386.977
4345.41	383.067
4348.17	376.106
4350.92	378.388
4353.67	374.566
4356.42	370.709
4359.17	372.979
4361.91	361.951
4364.66	376.523
4367.41	363.436
4370.15	360.573
4372.89	372.034
4375.63	372.194
4378.38	381.577
4381.12	378.65
4383.86	374.756
4386.59	381.274
4389.33	370.392
4392.07	386.506
4394.8	379.896
4397.53	368.96
4400.27	355.919
4403	367.736
4405.73	371.293
4408.46	369.639
4411.19	386.662
4413.92	377.64
4416.64	377.884
4419.37	365.585
4422.09	376.291
4424.82	374.482
4427.54	371.627
4430.26	355.161
4432.98	374.251
4435.7	378.682
4438.42	348.499
4441.13	366.513
4443.85	355.16
4446.57	343.784
4449.28	379.639
4451.99	353.519
4454.71	363.091
4457.42	344.262
4460.13	340.166
4462.83	350.81
4465.54	347.787
4468.25	353.205
4470.95	343.906
4473.66	353.6
4476.36	374.937
4479.07	354.112
4481.77	354.388
4484.47	337.732
4487.17	350.663
4489.87	361.433
4492.56	339.258
4495.26	351.05
4497.96	345.905
4500.65	352.348
4503.34	350.359
4506.04	351.566
4508.73	348.531
4511.42	339.129
4514.11	337.167
4516.8	333.076
4519.48	344.977
4522.17	344.135
4524.85	332.63
4527.54	337.101
4530.22	337.319
4532.9	332.223
4535.58	333.521
4538.27	322.043
4540.94	332.98
4543.62	348.232
4546.3	329.247
4548.98	348.818
4551.65	327.744
4554.33	325.97
4557	329.687
4559.67	322.699
4562.34	329.779
4565.01	340.327
4567.68	342.139
4570.35	330.521
4573.02	325.088
4575.68	318.762
4578.35	337.513
4581.01	307.564
4583.67	308.877
4586.34	316.724
4589	326.722
4591.66	313.79
4594.31	322.79
4596.97	319.691
4599.63	301.349
4602.29	331.181
4604.94	322.712
4607.59	308.757
4610.25	323.307
4612.9	319.194
4615.55	316.182
4618.2	303.288
4620.85	320.114
4623.5	319.3
4626.14	309.627
4628.79	302.156
4631.43	313.418
4634.08	320.233
4636.72	309.354
4639.36	307.295
4642	301.975
4644.64	313.37
4647.28	310.423
4649.92	317.569
4652.56	322.674
4655.19	303.676
4657.83	300.584
4660.46	317.659
4663.1	316.893
4665.73	314.868
4668.36	305.05
4670.99	289.606
4673.62	302.166
4676.24	305.764
4678.87	291.39
4681.5	291.601
4684.12	294.066
4686.75	310.032
4689.37	302.398
4691.99	301.479
4694.61	309.57
4697.23	312.037
4699.85	282.892
4702.47	301.132
4705.09	302.427
4707.7	298.053
4710.32	306.118
4712.93	305.13
4715.55	315.438
4718.16	291.772
4720.77	295.245
4723.38	285.161
4725.99	301.186
4728.6	307.015
4731.21	301.497
4733.81	305.061
4736.42	304.048
4739.02	295.082
4741.63	305.405
4744.23	274.779
4746.83	297.555
4749.43	299.864
4752.03	294.208
4754.63	294.225
4757.23	285.161
4759.82	287.512
4762.42	279.614
4765.01	269.481
4767.61	293.629
4770.2	288.048
4772.79	290.455
4775.38	287.163
4777.97	285.003
4780.56	291.984
4783.15	285.258
4785.74	281.957
4788.32	303.834
4790.91	275.376
4793.49	277.815
4796.07	277.999
4798.66	289.675
4801.24	296.795
4803.82	277.529
4806.4	269.772
4808.98	282.712
4811.55	285.323
4814.13	278.717
4816.71	274.444
4819.28	264.369
4821.85	275.128
4824.43	262.718
4827	271.161
4829.57	264.556
4832.14	278.889
4834.71	282.805
4837.28	272.746
4839.84	259.158
4842.41	266.563
4844.97	255.187
4847.54	264.893
4850.1	274.445
4852.66	277.959
4855.22	263.067
4857.78	269.35
4860.34	273.235
4862.9	269.927
4865.46	259.468
4868.01	271.605
4870.57	281.326
4873.12	273.229
4875.68	279.361
4878.23	279.552
4880.78	261.903
4883.33	256.112
4885.88	264.588
4888.43	277.845
4890.98	263.718
4893.53	265.057
4896.07	260.424
4898.62	261.749
4901.16	261.867
4903.7	278.711
4906.25	256.122
4908.79	245.44
4911.33	259.801
4913.87	259.809
4916.41	253.851
4918.94	262.242
4921.48	251.516
4924.02	277.847
4926.55	258.755
4929.08	258.81
4931.62	251.753
4934.15	250.671
4936.68	255.555
4939.21	247.204
4941.74	236.463
4944.27	261.721
4946.79	260.642
4949.32	247.582
4951.85	268.085
4954.37	252.62
4956.9	252.783
4959.42	244.556
4961.94	239.975
4964.46	243.871
4966.98	247.748
4969.5	241.937
4972.02	254.227
4974.53	254.445
4977.05	242.57
4979.57	231.892
4982.08	246.653
4984.59	235.972
4987.1	237.419
4989.62	248.589
4992.13	258.555
4994.64	245.424
4997.15	244.485
4999.65	254.534