File: Data/3-Raman/raw/bu19(2)w-a-ff1-fi08-v_150 (500nm)_532nm_edge_100%_x100_vis_lwd_h50um_30sx2_01.txt
#Acq. time (s)=	30
#Accumulations=	2
#Range (cm-¹)=	99...4000
#Windows=	1
#Auto scanning=	Off
#Autofocus=	Off
#Macrospot=	Off
#AutoExposure=	Off
#Spike filter=	Multiple accum.
#Delay time (s)=	2
#Binning=	1
#Readout mode=	Signal
#DeNoise=	Off
#ICS correction=	On
#Dark correction=	Off
#Inst. Process=	Off
#Detector Gain=	Best Dynamic
#Detector ADC=	50 kHz HS
#Detector temperature (°C)=	-60.09
#Instrument=	LabRAM HR Evol
#Detector=	SIN-EM FIVIS
#Objective=	x100_VIS_LWD
#Grating=	150 (500nm)
#ND Filter=	100%
#Laser=	532nm_Edge
#Hole=	49.98
#Temperature=	0
#Range=	Visible
#StageXY=	75x50mm Scan+
#StageZ=	Z motor
#X (µm)=	0
#Y (µm)=	0
#Z (µm)=	-65.3
#Full time(mm:ss)=	1:04
#Project=	21_11_26
#Sample=	BU19(2)w
#Site=
#Title=	BU19(2)w-A-FF1-FI08-V_150 (500nm)_532nm_Edge_100%_x100_VIS_LWD_H50um_30sX2
#Remark=
#Date=	26.11.2021 16:23
#Acquired=	26.11.2021 16:23:51
102.91	5481.82
107.534	5634.94
112.156	6185.22
116.775	5641.82
121.392	4441.29
126.005	3532.69
130.617	3285.86
135.227	3667.1
139.835	4893.61
144.439	7593.66
149.042	10194.1
153.643	9446.76
158.242	6471.64
162.839	4103.79
167.431	2711.61
172.023	2064.11
176.613	1679.31
181.198	1446.62
185.783	1280.15
190.366	1154.12
194.947	1139.46
199.524	1205.53
204.1	1499.09
208.674	2685.43
213.243	3761.56
217.813	2464.97
222.38	1421.67
226.945	1405.54
231.506	2019.8
236.066	3420.11
240.625	3405.88
245.179	1941.67
249.732	1053.81
254.284	840.918
258.831	720.892
263.378	682.54
267.923	656.418
272.464	688.598
277.004	703.794
281.54	851.219
286.076	877.802
290.61	706.231
295.139	660.975
299.669	630.275
304.196	629.94
308.718	619.625
313.241	679.91
317.759	731.488
322.278	815.458
326.794	982.283
331.305	1371.35
335.817	1797.56
340.324	1721.65
344.832	1536.89
349.334	1677.8
353.837	2221.68
358.338	2091.69
362.834	1471.83
367.33	1111.5
371.822	1013.2
376.314	1069.33
380.802	1134.65
385.289	1487.1
389.772	2262.15
394.255	3506.51
398.734	3835.51
403.213	3456.18
407.688	2981.47
412.162	2551.99
416.632	2180.85
421.102	2134.83
425.568	2314.14
430.033	2564.9
434.495	2705.93
438.956	2688.37
443.413	2496.94
447.87	2633.32
452.323	2770.06
456.776	2823.48
461.224	2359.56
465.673	1756.36
470.117	1339.57
474.561	1140.42
479.001	1105.09
483.438	1145.92
487.876	1338.53
492.309	1613.71
496.742	2133.49
501.172	2829.7
505.601	3829.25
510.025	4835.36
514.448	5273.2
518.871	4948.02
523.289	4275.57
527.707	3734.66
532.121	3278.52
536.533	3240.36
540.945	3303.04
545.353	3428.23
549.758	3489.95
554.164	3441
558.565	3232.15
562.965	2813.43
567.364	2374.62
571.759	1971.57
576.151	1673.07
580.544	1476.95
584.933	1427.67
589.319	1501.37
593.706	1617.82
598.088	1925.49
602.468	2260.86
606.848	2674.67
611.224	3592.56
615.598	5605.75
619.972	9262.55
624.341	11230.3
628.709	8361.05
633.074	4884.15
637.44	2979.48
641.801	2118.93
646.16	1601.3
650.517	1255.73
654.874	1030.9
659.227	941.407
663.578	814.32
667.927	727.23
672.275	700.375
676.62	646.393
680.962	611.816
685.302	618.768
689.643	601.055
693.979	634.585
698.313	779.712
702.645	861.494
706.975	896.395
711.305	876.493
715.631	734.971
719.955	702.439
724.276	668.349
728.596	638.784
732.913	617.557
737.231	569.716
741.544	519.623
745.856	491.596
750.165	523.585
754.472	493.907
758.778	499.091
763.081	488.549
767.384	505.728
771.683	496.879
775.98	490.679
780.275	535.986
784.568	489.462
788.859	519.717
793.147	572.118
797.434	579.952
801.719	603.448
806.004	597.676
810.284	635.019
814.563	647.174
818.839	689.141
823.114	768.532
827.386	873.519
831.657	1013.96
835.925	1196.48
840.192	1426.55
844.456	1663.31
848.719	1766.06
852.979	1679.12
857.237	1466.61
861.493	1296.15
865.748	1142.18
870	1070.58
874.25	1103.26
878.499	1203.54
882.745	1330.59
886.989	1215.18
891.231	1005.93
895.471	793.176
899.71	711.814
903.946	621.234
908.18	631.711
912.412	565.605
916.642	583.3
920.87	582.469
925.096	556.631
929.321	566.058
933.543	556.816
937.763	538.959
941.981	561.69
946.197	571.444
950.412	558.729
954.622	536.614
958.832	572.093
963.04	567.161
967.246	610.09
971.451	601.024
975.653	594.219
979.853	610.806
984.052	646.561
988.248	688.622
992.442	757.167
996.633	833.679
1000.82	952.159
1005.01	967.128
1009.2	927.032
1013.38	827.265
1017.57	804.786
1021.75	803.568
1025.92	788.291
1030.1	809.009
1034.27	845.501
1038.45	960.079
1042.62	1124.96
1046.78	1393.6
1050.95	1476.03
1055.12	1439.06
1059.28	1357.41
1063.44	1387.54
1067.6	1444.44
1071.75	1667.51
1075.91	1890.06
1080.06	2301.74
1084.21	3013.06
1088.36	4227.74
1092.51	6027.3
1096.65	7541.6
1100.8	7387.9
1104.94	5314.55
1109.08	3459.51
1113.21	2342.68
1117.35	1758.09
1121.48	1465.99
1125.61	1407.6
1129.74	1373.07
1133.87	1491.41
1137.99	1724.61
1142.12	2189.56
1146.24	2652.38
1150.36	2708.81
1154.48	2375.94
1158.59	1853.84
1162.71	1397.01
1166.82	1179.1
1170.93	971.306
1175.04	853.087
1179.14	728.722
1183.25	683.792
1187.35	626.412
1191.45	597.569
1195.55	552.277
1199.65	535.602
1203.74	512.757
1207.83	521.477
1211.92	550.42
1216.01	534.794
1220.1	557.581
1224.19	553.201
1228.27	553.976
1232.35	572.97
1236.43	639.337
1240.51	643.022
1244.58	727.444
1248.66	1025.68
1252.73	1154.71
1256.8	861.547
1260.87	856.079
1264.93	1100.8
1269	5642.49
1273.06	7187.47
1277.12	2188.12
1281.18	886.546
1285.23	768.711
1289.29	666.643
1293.34	627.787
1297.39	623.042
1301.44	604.126
1305.49	608.264
1309.53	559.944
1313.58	558.932
1317.62	559.732
1321.66	553.361
1325.7	542.768
1329.73	570.311
1333.77	572.636
1337.8	588.794
1341.83	616.801
1345.86	623.67
1349.88	671.368
1353.91	763.683
1357.93	899.406
1361.95	858.089
1365.97	927.924
1369.99	2086.79
1374	12454
1378.02	8643.33
1382.03	1928.2
1386.04	877.735
1390.05	851.898
1394.05	1333.21
1398.06	1457.84
1402.06	805.261
1406.06	580.851
1410.06	552.501
1414.05	509.386
1418.05	452.419
1422.04	422.043
1426.03	410.349
1430.02	407.332
1434.01	404.348
1438	377.662
1441.98	354.932
1445.96	348.935
1449.94	316.275
1453.92	327.971
1457.9	334.694
1461.87	313.763
1465.85	324.261
1469.82	311.123
1473.78	308.858
1477.75	307.537
1481.72	317.937
1485.68	312.632
1489.65	307.319
1493.61	292.283
1497.56	313.355
1501.52	297.415
1505.47	295.177
1509.43	305.66
1513.38	305.468
1517.33	294.615
1521.27	299.33
1525.22	301.152
1529.16	285.543
1533.11	311.662
1537.05	295.134
1540.98	294.125
1544.92	304.746
1548.86	306.646
1552.79	294.983
1556.72	291.037
1560.65	295.761
1564.58	278.193
1568.5	299.298
1572.43	301.025
1576.35	280.534
1580.27	291.905
1584.19	304.215
1588.1	276.982
1592.02	290.217
1595.93	295.729
1599.84	296.428
1603.75	304.831
1607.66	293.12
1611.57	296.773
1615.47	308.111
1619.37	308.944
1623.27	303.055
1627.17	299.132
1631.07	278.981
1634.97	293.38
1638.86	283.836
1642.75	295.43
1646.64	294.641
1650.53	311.139
1654.42	299.849
1658.3	292.359
1662.18	308.865
1666.07	300.34
1669.94	296.582
1673.82	294.653
1677.7	297.512
1681.57	306.934
1685.44	312.423
1689.31	305.41
1693.18	283.981
1697.05	291.259
1700.92	298.468
1704.78	312.266
1708.64	309.768
1712.5	300.567
1716.36	301.832
1720.21	293.646
1724.07	296.827
1727.92	300.911
1731.77	298.35
1735.62	293.012
1739.47	308.244
1743.32	314.967
1747.16	318.882
1751.01	315.54
1754.85	329.03
1758.69	342.679
1762.52	340.19
1766.36	329.102
1770.19	324.632
1774.02	318.454
1777.85	302.966
1781.68	302.456
1785.51	296.394
1789.33	309.046
1793.16	303.023
1796.98	291.355
1800.8	298.433
1804.62	288.4
1808.43	297.16
1812.25	289.876
1816.06	310.828
1819.87	280.711
1823.68	301.465
1827.49	302.347
1831.3	274.858
1835.1	288.788
1838.9	295.115
1842.71	278.815
1846.51	301.931
1850.3	284.692
1854.1	285.162
1857.89	295.838
1861.69	282.126
1865.48	290.777
1869.27	277.135
1873.05	289.523
1876.84	282.502
1880.62	284.759
1884.4	300.955
1888.19	299.63
1891.96	288.528
1895.74	300.444
1899.52	292.115
1903.29	285.753
1907.06	288.65
1910.83	301.713
1914.6	282.633
1918.37	286.612
1922.13	290.786
1925.9	296.855
1929.66	288.151
1933.42	280.369
1937.18	266.956
1940.94	282.423
1944.69	293.265
1948.44	291.027
1952.2	295.118
1955.95	282.194
1959.69	301.046
1963.44	328.251
1967.19	310.356
1970.93	328.041
1974.67	359.647
1978.41	360.204
1982.15	362.569
1985.89	372.339
1989.62	388.567
1993.35	382.327
1997.09	397.413
2000.82	389.17
2004.55	393.941
2008.27	356.15
2012	366.369
2015.72	357.242
2019.44	348.325
2023.16	338.706
2026.88	332.976
2030.6	326.355
2034.31	325.387
2038.03	325.45
2041.74	309.917
2045.45	309.924
2049.16	303.527
2052.86	289.862
2056.57	296.361
2060.27	303.021
2063.98	280.504
2067.67	293.855
2071.37	278.714
2075.07	289.366
2078.77	279.735
2082.46	283.058
2086.15	290.069
2089.84	298.611
2093.53	270.791
2097.22	282.121
2100.9	296.203
2104.59	286.009
2108.27	277.623
2111.95	274.776
2115.63	274.71
2119.31	275.538
2122.98	293.898
2126.66	282.476
2130.33	274.74
2134	270.697
2137.67	276.814
2141.34	279.174
2145	275.956
2148.67	273.648
2152.33	264.916
2155.99	288.308
2159.65	262.212
2163.31	280.095
2166.96	273.33
2170.62	259.339
2174.27	267.342
2177.92	255.368
2181.57	262.549
2185.22	276.081
2188.87	269.669
2192.51	281.557
2196.15	257.159
2199.8	262.848
2203.44	267.666
2207.07	273.449
2210.71	263.752
2214.35	255.896
2217.98	263.618
2221.61	275.042
2225.24	273.641
2228.87	274.979
2232.5	253.262
2236.12	258.298
2239.75	267.97
2243.37	249.853
2246.99	247.454
2250.61	260.87
2254.23	278.085
2257.85	268.32
2261.46	273.472
2265.07	257.07
2268.68	253.772
2272.29	259.919
2275.9	264.135
2279.51	287.15
2283.11	282.656
2286.72	254.537
2290.32	276.466
2293.92	274.744
2297.52	269.241
2301.11	274.159
2304.71	276.193
2308.3	270.587
2311.9	321.814
2315.49	764.483
2319.08	1009.81
2322.66	462.781
2326.25	294.8
2329.84	285.017
2333.42	278.997
2337	269.185
2340.58	289.49
2344.16	276.804
2347.73	269.754
2351.31	274.884
2354.88	281.851
2358.45	285.042
2362.03	299.375
2365.59	269.968
2369.16	276.867
2372.73	276.401
2376.29	303.646
2379.85	284.666
2383.41	269.469
2386.97	284.703
2390.53	284.324
2394.09	274.828
2397.64	281.936
2401.2	283.632
2404.75	277.235
2408.3	275.454
2411.85	292.134
2415.39	276.778
2418.94	286.273
2422.48	280.192
2426.03	274.16
2429.57	259.87
2433.11	272.403
2436.64	273.924
2440.18	278.266
2443.72	277.993
2447.25	276.792
2450.78	249.434
2454.31	271.716
2457.84	264.771
2461.37	281.114
2464.89	275.784
2468.42	272.099
2471.94	284.681
2475.46	276.037
2478.98	274.902
2482.5	275.7
2486.01	282.043
2489.53	259.047
2493.04	271.944
2496.55	273.402
2500.06	272.141
2503.57	281.082
2507.08	262.866
2510.58	280.074
2514.09	263.746
2517.59	271.687
2521.09	267.593
2524.59	251.296
2528.09	270.436
2531.59	275.751
2535.08	270.02
2538.58	289.291
2542.07	267.1
2545.56	280.106
2549.05	262.768
2552.54	264.826
2556.02	275.289
2559.51	269.232
2562.99	251.092
2566.47	290.666
2569.95	263.377
2573.43	250.043
2576.91	279.802
2580.38	268.42
2583.85	256.984
2587.33	288.99
2590.8	277.473
2594.27	277.16
2597.74	268.223
2601.2	265.055
2604.67	275.25
2608.13	267.104
2611.59	262.55
2615.06	263.569
2618.51	269.492
2621.97	286.836
2625.43	277.222
2628.88	267.534
2632.33	279.894
2635.79	283.534
2639.24	271.747
2642.69	273.338
2646.13	278.696
2649.58	279.246
2653.02	280.682
2656.47	277.282
2659.91	275.737
2663.35	262.804
2666.79	293.365
2670.22	270.991
2673.66	267.514
2677.09	276.293
2680.52	278.523
2683.95	248.098
2687.39	264.517
2690.81	255.898
2694.24	279.061
2697.66	262.101
2701.09	274.07
2704.51	265.573
2707.93	254.305
2711.35	273.91
2714.77	267.532
2718.18	274.237
2721.6	282.87
2725.01	282.226
2728.42	261.056
2731.84	265.1
2735.24	268.202
2738.65	259.128
2742.06	260.341
2745.46	262.444
2748.86	289.884
2752.27	267.528
2755.67	267.701
2759.07	273.493
2762.46	275.528
2765.86	265.242
2769.25	271.873
2772.65	269.035
2776.04	285.961
2779.43	267.036
2782.82	276.333
2786.2	279.954
2789.59	267.573
2792.98	269.295
2796.36	248.462
2799.74	257.695
2803.12	272.501
2806.5	277.914
2809.88	269.263
2813.25	265.289
2816.63	279.07
2820	261.063
2823.37	286.06
2826.74	265.357
2830.11	290.377
2833.48	266.959
2836.84	264.1
2840.21	284.575
2843.57	288.338
2846.93	282.852
2850.29	282.126
2853.65	287.999
2857.01	277.03
2860.36	281.978
2863.72	271.99
2867.07	284.487
2870.42	277.307
2873.77	289.822
2877.12	271.318
2880.47	272.538
2883.81	291.656
2887.16	276.83
2890.5	286.516
2893.84	288.643
2897.18	279.358
2900.52	270.97
2903.86	286.184
2907.19	283.391
2910.53	296.659
2913.86	289.088
2917.19	297.583
2920.52	294.678
2923.85	299.324
2927.18	289.759
2930.51	300.004
2933.83	295.092
2937.15	291.087
2940.48	333.285
2943.8	306.647
2947.11	296.062
2950.43	309.02
2953.75	289.047
2957.06	281.324
2960.38	298.066
2963.69	294.173
2967	303.434
2970.31	291.211
2973.62	298.737
2976.92	298.772
2980.23	294.164
2983.53	299.843
2986.84	303.666
2990.14	295.302
2993.44	318.877
2996.73	295.506
3000.03	304.092
3003.33	305.158
3006.62	312.812
3009.91	330.851
3013.2	312.198
3016.49	313.319
3019.78	306.89
3023.07	317.429
3026.35	314.767
3029.64	293.219
3032.92	312.271
3036.2	299.186
3039.48	301.213
3042.76	323.112
3046.04	298.655
3049.32	295.959
3052.59	317.895
3055.86	303.838
3059.14	313.466
3062.41	312.564
3065.68	306.964
3068.94	292.782
3072.21	318.393
3075.48	319.999
3078.74	298.223
3082	336.079
3085.26	328.703
3088.52	318.454
3091.78	338.678
3095.04	307.612
3098.29	332.217
3101.55	323.755
3104.8	331.393
3108.05	325.872
3111.3	325.057
3114.55	335.561
3117.8	343.241
3121.04	323.316
3124.29	326.243
3127.53	352.031
3130.77	336.843
3134.02	328.327
3137.25	339.815
3140.49	350.335
3143.73	342.738
3146.96	347.536
3150.2	335.193
3153.43	347.651
3156.66	359.144
3159.89	349.661
3163.12	364.972
3166.35	353.567
3169.57	376.483
3172.8	367.881
3176.02	354.493
3179.24	385.919
3182.46	382.989
3185.68	402.004
3188.9	402.848
3192.12	402.728
3195.33	384.501
3198.55	412.957
3201.76	387.105
3204.97	396.51
3208.18	406.876
3211.39	424.868
3214.6	429.564
3217.8	421.92
3221.01	432.352
3224.21	432.335
3227.41	426.653
3230.61	442.862
3233.81	445.786
3237.01	443.924
3240.21	445.014
3243.4	447.083
3246.59	462.512
3249.79	487.488
3252.98	486.789
3256.17	476.561
3259.36	480.632
3262.54	493.231
3265.73	514.365
3268.92	535.433
3272.1	509.641
3275.28	526.805
3278.46	538.228
3281.64	559.083
3284.82	546.416
3288	600.554
3291.17	585.934
3294.35	592.346
3297.52	607.301
3300.69	626.062
3303.86	652.568
3307.03	657.001
3310.2	683.237
3313.36	689.377
3316.53	717.303
3319.69	736.628
3322.85	756.84
3326.02	777.972
3329.18	807.589
3332.33	821.103
3335.49	842.212
3338.65	864.308
3341.8	896.817
3344.95	943.457
3348.11	992.176
3351.26	1012.84
3354.41	1051.39
3357.56	1090.07
3360.7	1125.03
3363.85	1169.57
3366.99	1206.61
3370.13	1250.33
3373.28	1282.82
3376.42	1326.8
3379.56	1441.72
3382.69	1468.95
3385.83	1548.13
3388.97	1633.2
3392.1	1648.35
3395.23	1768.56
3398.36	1815.48
3401.49	1903.28
3404.62	2059.73
3407.75	2158.74
3410.88	2260.93
3414	2401.34
3417.13	2570.02
3420.25	2769.31
3423.37	2924.72
3426.49	3131.24
3429.61	3351.66
3432.73	3591.76
3435.84	3897.96
3438.96	4132.52
3442.07	4502.03
3445.18	5061.15
3448.29	5678.97
3451.4	6942.45
3454.51	8617.11
3457.62	11094.1
3460.72	12607.1
3463.83	12045.9
3466.93	10097.2
3470.03	8228.22
3473.13	7071.79
3476.23	6326.14
3479.33	5869.74
3482.43	5669.63
3485.53	5537.99
3488.62	5424.87
3491.71	5443.91
3494.81	5510.66
3497.9	5453.58
3500.99	5520.67
3504.07	5576.54
3507.16	5677.63
3510.25	5805.9
3513.33	6061.15
3516.41	6202.46
3519.5	6596.2
3522.58	6875.6
3525.66	7387.7
3528.73	7798.1
3531.81	8365.92
3534.89	8835.94
3537.96	9316.79
3541.03	9437.79
3544.11	9229.57
3547.18	8648.74
3550.25	7727.7
3553.32	6692.89
3556.38	5680.12
3559.45	4725.88
3562.51	3971.25
3565.58	3374.15
3568.64	2963.77
3571.7	2536.92
3574.76	2248.9
3577.82	2001.69
3580.87	1843.42
3583.93	1677.41
3586.98	1570.05
3590.04	1441.85
3593.09	1354.28
3596.14	1254.4
3599.19	1220.79
3602.24	1186.25
3605.29	1123.21
3608.33	1085.7
3611.38	1065.24
3614.42	994.657
3617.46	963.791
3620.5	943.389
3623.54	945.693
3626.58	910.311
3629.62	889.157
3632.65	877.391
3635.69	838.293
3638.72	827.671
3641.76	787.998
3644.79	725.847
3647.82	730.687
3650.84	708.979
3653.87	674.196
3656.9	663.033
3659.92	625.119
3662.95	620.968
3665.97	576.178
3668.99	586.683
3672.01	576.59
3675.03	565.572
3678.05	530.976
3681.07	516.203
3684.08	500.438
3687.1	520.597
3690.11	496.322
3693.12	474.87
3696.13	476.135
3699.14	481.1
3702.15	465.305
3705.16	473.22
3708.16	461.192
3711.17	457.647
3714.17	431.242
3717.17	414.273
3720.17	424.918
3723.17	421.238
3726.17	424.185
3729.17	397.574
3732.16	397.596
3735.16	393.768
3738.15	396.562
3741.14	380.281
3744.13	381.093
3747.13	369.506
3750.11	366.45
3753.1	354.82
3756.09	378.327
3759.07	377.144
3762.06	357.937
3765.04	345.359
3768.02	352.691
3771	328.814
3773.98	340.934
3776.96	338.888
3779.94	352.926
3782.91	341.474
3785.89	334.755
3788.86	343.164
3791.83	328.939
3794.8	338.365
3797.77	329.885
3800.74	341.248
3803.71	332.833
3806.68	313.096
3809.64	332.093
3812.61	317.099
3815.57	312.501
3818.53	327.773
3821.49	335.501
3824.45	319.574
3827.41	303.652
3830.36	312.363
3833.32	306.854
3836.27	320.351
3839.23	297.789
3842.18	320.821
3845.13	315.346
3848.08	303.207
3851.03	312.022
3853.98	328.498
3856.92	311.605
3859.87	325.254
3862.81	321.721
3865.75	315.291
3868.7	305.978
3871.64	304.291
3874.57	318.897
3877.51	322.952
3880.45	326.015
3883.39	310.793
3886.32	330.118
3889.25	336.933
3892.18	316.815
3895.12	313.984
3898.05	312.073
3900.97	315.896
3903.9	319.709
3906.83	313.868
3909.75	309.989
3912.68	311.848
3915.6	323.282
3918.52	316.441
3921.44	312.54
3924.36	312.418
3927.28	318.017
3930.2	311.116
3933.11	327.204
3936.03	319.411
3938.94	287.749
3941.86	306.896
3944.77	314.523
3947.68	307.805
3950.59	315.48
3953.49	305.943
3956.4	295.459
3959.31	305.114
3962.21	318.622
3965.12	313.942
3968.02	321.742
3970.92	294.067
3973.82	322.048
3976.72	316.436
3979.61	307.916
3982.51	307.057
3985.41	325.419
3988.3	300.504
3991.19	333.275
3994.09	314.074
3996.98	308.394
3999.87	327.73