File: Data/3-Raman/raw/bu19w-e-ff11-fi07-s_150 (500nm)_633nm_edge_100%_x100_vis_h50um_60sx2_01.txt
#Acq. time (s)=	60
#Accumulations=	2
#Range (cm-¹)=	100...4000
#Windows=	1
#Auto scanning=	Off
#Autofocus=	Off
#Macrospot=	Off
#AutoExposure=	Off
#Spike filter=	Multiple accum.
#Delay time (s)=	2
#Binning=	1
#Readout mode=	Signal
#DeNoise=	Off
#ICS correction=	On
#Dark correction=	Off
#Inst. Process=	Off
#Detector Gain=	Best Dynamic
#Detector ADC=	50 kHz HS
#Detector temperature (°C)=	-60.09
#Instrument=	LabRAM HR Evol
#Detector=	SIN-EM FIVIS
#Objective=	x100_VIS
#Grating=	150 (500nm)
#ND Filter=	100%
#Laser=	633nm_Edge
#Hole=	49.98
#Temperature=	0
#Range=	Visible
#StageXY=	75x50mm Scan+
#StageZ=	Z motor
#X (µm)=	0
#Y (µm)=	0
#Z (µm)=	-310.5
#Full time(mm:ss)=	2:04
#Project=	21_11_04
#Sample=	BU19w
#Site=
#Title=	BU19w-E-FF11-FI07-S_150 (500nm)_633nm_Edge_100%_x100_VIS_H50um_60sX2
#Remark=
#Date=	04.11.2021 16:58
#Acquired=	04.11.2021 16:58:36
102.881	289.358
109.397	261.005
115.908	249.797
122.414	242.328
128.914	245.354
135.409	237.786
141.898	232.051
148.383	228.271
154.861	236.03
161.335	245.744
167.801	198.902
174.264	182.627
180.721	167.212
187.173	169.89
193.62	152.416
200.061	155.096
206.496	145.529
212.926	167.407
219.352	183.552
225.772	230.113
232.185	250.723
238.595	195.34
244.999	170.528
251.397	197.035
257.791	193.116
264.178	199.678
270.561	177.824
276.939	193.942
283.31	195.789
289.678	177.676
296.039	200.246
302.396	194.398
308.746	244.297
315.093	327.18
321.433	446.822
327.768	340.086
334.099	229.674
340.423	206.046
346.743	200.313
353.058	228.463
359.367	223.555
365.671	192.295
371.971	197.739
378.265	187.205
384.553	155.178
390.837	121.488
397.116	125.42
403.389	121.942
409.657	135.409
415.92	138.446
422.178	147.127
428.431	164.003
434.678	151.366
440.921	155.702
447.158	158.098
453.391	164.186
459.618	146.07
465.84	128.173
472.057	121.559
478.27	121.575
484.477	127.18
490.679	122.537
496.876	139.343
503.068	136.601
509.255	141.338
515.436	148.919
521.613	144.453
527.785	142.861
533.952	141.354
540.113	136.065
546.27	119.325
552.423	123.191
558.568	116.616
564.711	110.801
570.848	110.548
576.979	106.449
583.107	113.611
589.228	126.408
595.345	123.459
601.458	140.263
607.565	128.34
613.667	143.567
619.764	131.788
625.856	117.175
631.944	116.46
638.026	119.306
644.104	114.422
650.177	123.646
656.244	123.337
662.308	101.489
668.365	105.902
674.418	99.3137
680.467	95.5847
686.511	94.7336
692.549	88.3748
698.582	96.0726
704.611	98.1462
710.635	92.6367
716.655	87.8726
722.669	89.7016
728.679	88.6388
734.683	85.6713
740.683	84.584
746.678	90.9905
752.669	97.4367
758.654	93.7009
764.635	92.9501
770.611	87.5929
776.582	81.262
782.549	96.4825
788.511	81.5245
794.466	91.9566
800.419	81.5696
806.366	85.2613
812.309	87.9649
818.247	95.2913
824.18	88.5066
830.108	88.3096
836.033	90.1578
841.952	95.9053
847.865	89.5153
853.776	87.8421
859.681	97.4937
865.58	98.7074
871.476	108.425
877.366	103.828
883.253	102.954
889.134	117.186
895.012	113.324
900.883	98.9247
906.751	104.35
912.614	105.015
918.473	106.678
924.326	112.241
930.174	117.965
936.019	125.705
941.859	140.317
947.693	157.933
953.525	155.693
959.35	161.933
965.171	168.072
970.988	202.913
976.801	230.877
982.608	248.874
988.411	218.801
994.209	192.598
1000	177.024
1005.79	170.168
1011.58	179.738
1017.36	208.542
1023.13	165.829
1028.9	152.814
1034.67	146.507
1040.43	128.652
1046.19	124.222
1051.94	119.678
1057.69	110.181
1063.44	114.155
1069.17	100.517
1074.91	124.747
1080.64	139.188
1086.37	170.065
1092.09	190.304
1097.8	196.958
1103.52	153.329
1109.22	139.858
1114.93	127.551
1120.63	123.09
1126.32	131.166
1132.01	135.408
1137.7	152.405
1143.38	180.276
1149.06	213.016
1154.73	167.88
1160.4	119.57
1166.06	111.488
1171.72	107.357
1177.38	97.3511
1183.03	98.1738
1188.67	91.3114
1194.31	78.6677
1199.95	78.8024
1205.58	86.9094
1211.21	73.4343
1216.84	80.68
1222.46	83.0535
1228.07	75.4562
1233.68	69.7521
1239.29	82.0725
1244.89	78.2078
1250.49	80.3021
1256.08	77.2854
1261.67	86.2846
1267.26	82.1377
1272.84	78.9711
1278.42	83.8171
1283.99	81.6406
1289.56	79.5184
1295.12	78.4567
1300.68	73.4516
1306.23	80.5254
1311.78	79.7161
1317.33	76.9518
1322.87	77.2261
1328.41	74.4947
1333.94	78.8523
1339.47	70.9502
1345	87.4919
1350.52	83.5592
1356.04	77.524
1361.55	84.7831
1367.06	90.9534
1372.56	104.276
1378.06	88.834
1383.56	76.4753
1389.05	78.4908
1394.53	78.5031
1400.02	78.6208
1405.5	82.8518
1410.97	87.1239
1416.44	78.0121
1421.91	69.9076
1427.37	77.3535
1432.83	75.4729
1438.28	78.7942
1443.73	75.8513
1449.17	78.1065
1454.62	81.3451
1460.05	83.4808
1465.48	84.5236
1470.91	88.6976
1476.34	88.6932
1481.76	80.3293
1487.17	77.2366
1492.59	80.4907
1497.99	83.7951
1503.4	78.691
1508.8	86.3009
1514.19	80.1775
1519.59	74.0462
1524.97	81.7866
1530.36	90.655
1535.74	83.4554
1541.11	83.6894
1546.48	87.0656
1551.85	92.4788
1557.21	84.8012
1562.57	84.7161
1567.93	94.3318
1573.28	85.6171
1578.62	88.8059
1583.97	89.8917
1589.3	92.0828
1594.64	87.8509
1599.97	89.0484
1605.3	84.8883
1610.62	92.7004
1615.94	97.3728
1621.25	96.6567
1626.56	88.2531
1631.87	88.5779
1637.17	98.7668
1642.47	96.6829
1647.76	91.2975
1653.05	98.0492
1658.34	93.6767
1663.62	98.1413
1668.9	79.2963
1674.18	91.4975
1679.45	87.0462
1684.71	91.4167
1689.98	101.305
1695.23	92.4291
1700.49	91.4351
1705.74	98.5745
1710.99	93.1315
1716.23	92.0524
1721.47	93.4337
1726.7	98.0668
1731.94	90.4103
1737.16	83.8371
1742.39	96.3999
1747.61	92.0529
1752.82	91.0408
1758.03	91.1189
1763.24	97.9427
1768.44	85.529
1773.64	92.3847
1778.84	98.1567
1784.03	93.763
1789.22	99.6425
1794.41	98.7254
1799.59	102.41
1804.76	91.2194
1809.94	102.94
1815.11	98.5501
1820.27	102.229
1825.43	97.8279
1830.59	95.738
1835.74	100.632
1840.89	97.3398
1846.04	104.518
1851.18	95.3308
1856.32	95.4516
1861.45	103.838
1866.58	107.58
1871.71	106.594
1876.83	96.1228
1881.95	111.589
1887.07	109.333
1892.18	98.7181
1897.29	101.097
1902.39	95.2839
1907.49	106.142
1912.59	107.63
1917.68	100.821
1922.77	106.906
1927.86	96.3446
1932.94	108.52
1938.02	103.896
1943.09	107.642
1948.16	101.734
1953.23	110.227
1958.29	105.445
1963.35	101.847
1968.41	106.653
1973.46	101.777
1978.51	106.537
1983.55	113.695
1988.59	104.024
1993.63	114.811
1998.66	112.396
2003.69	110.013
2008.72	102.857
2013.74	114.982
2018.76	99.3975
2023.77	105.507
2028.78	110.476
2033.79	110.675
2038.79	112.1
2043.79	114.757
2048.79	116.227
2053.78	113.994
2058.77	106.899
2063.76	114.485
2068.74	122.103
2073.72	116.213
2078.69	112.748
2083.66	122.821
2088.63	111.861
2093.59	108.345
2098.55	133.414
2103.51	110.103
2108.46	119.132
2113.41	129.496
2118.36	117.349
2123.3	112.67
2128.24	111.732
2133.17	113.29
2138.11	126.244
2143.03	120.162
2147.96	122.935
2152.88	129.485
2157.79	120.685
2162.71	125.886
2167.62	131.04
2172.52	122.16
2177.43	120.966
2182.32	135.065
2187.22	117.126
2192.11	124.851
2197	127.504
2201.89	116.12
2206.77	129.168
2211.64	124.284
2216.52	121.989
2221.39	140.418
2226.26	123.908
2231.12	125.524
2235.98	125.843
2240.84	126.158
2245.69	136.968
2250.54	132.061
2255.39	129.75
2260.23	127.446
2265.07	127.734
2269.9	135.921
2274.74	125.488
2279.57	132.27
2284.39	132.344
2289.21	133.709
2294.03	132.409
2298.84	132.482
2303.66	125.949
2308.46	139.502
2313.27	138.454
2318.07	133.432
2322.87	123.01
2327.66	146.259
2332.45	135.866
2337.24	141.712
2342.02	135.37
2346.8	130.4
2351.58	133.596
2356.35	140.874
2361.12	141.193
2365.89	142.876
2370.65	137.648
2375.41	137.924
2380.17	138.17
2384.92	131.382
2389.67	137.052
2394.42	145.452
2399.16	127.356
2403.9	139.87
2408.64	135.706
2413.37	137.337
2418.1	144.999
2422.83	135.629
2427.55	138.664
2432.27	136.202
2436.99	142.272
2441.7	145.539
2446.41	138.852
2451.11	139.272
2455.82	149.703
2460.51	140.083
2465.21	141.926
2469.9	149.53
2474.59	142.667
2479.28	150.306
2483.96	157.951
2488.64	139.317
2493.32	149.83
2497.99	148.679
2502.66	160.701
2507.32	153.623
2511.99	153.845
2516.65	143.719
2521.3	154.276
2525.96	155.993
2530.61	159.192
2535.25	157.995
2539.89	152.364
2544.53	148.21
2549.17	161.977
2553.8	145.875
2558.43	147.641
2563.06	149.461
2567.68	151.337
2572.3	145.697
2576.92	161.193
2581.53	137.258
2586.14	145.043
2590.75	158.841
2595.35	163.592
2599.96	157.756
2604.55	150.327
2609.15	164.249
2613.74	165.903
2618.33	166.046
2622.91	155.471
2627.49	163.313
2632.07	168.222
2636.64	164.03
2641.22	170.727
2645.78	155.786
2650.35	171.817
2654.91	162.928
2659.47	158.53
2664.03	166.58
2668.58	169.946
2673.13	168.732
2677.67	148.869
2682.22	160.692
2686.76	172.556
2691.29	168.485
2695.83	162.519
2700.36	161.257
2704.89	163.189
2709.41	184.428
2713.93	173.46
2718.45	168.989
2722.96	180.646
2727.47	177.648
2731.98	172.94
2736.49	155.205
2740.99	179.733
2745.49	168.564
2749.98	175.389
2754.47	179.185
2758.96	177.886
2763.45	171.588
2767.93	165.354
2772.41	173.904
2776.89	187.556
2781.36	158.296
2785.84	172.135
2790.3	167.697
2794.77	169.89
2799.23	168.664
2803.69	175.787
2808.14	167.714
2812.59	171.399
2817.04	175.034
2821.49	166.838
2825.93	170.515
2830.37	187.778
2834.81	174.431
2839.24	188.313
2843.67	181.766
2848.1	171.833
2852.53	167.054
2856.95	186.367
2861.37	186.846
2865.78	180.503
2870.19	172.405
2874.6	167.722
2879.01	189.188
2883.41	193.347
2887.81	167.7
2892.21	171.789
2896.6	182.999
2901	183.679
2905.38	182.476
2909.77	175.872
2914.15	178.068
2918.53	173.093
2922.91	164.533
2927.28	179.422
2931.65	183.572
2936.02	180.404
2940.38	180.754
2944.74	179.264
2949.1	179.51
2953.46	194.375
2957.81	189.163
2962.16	171.139
2966.5	176.92
2970.85	190.098
2975.19	192.297
2979.52	200.032
2983.86	187.538
2988.19	193.573
2992.52	199.686
2996.85	189.083
3001.17	189.68
3005.49	201.574
3009.8	206.008
3014.12	182.119
3018.43	196.029
3022.74	206.226
3027.04	189.676
3031.34	209.267
3035.64	203.955
3039.94	208.192
3044.23	206.677
3048.52	183.926
3052.81	209.316
3057.09	215.5
3061.38	217.817
3065.65	229.838
3069.93	208.867
3074.2	226.758
3078.47	213.531
3082.74	208.066
3087	241.823
3091.27	230.704
3095.52	225.523
3099.78	230.211
3104.03	201.267
3108.28	243.819
3112.53	236.793
3116.77	227.687
3121.01	234.654
3125.25	227.58
3129.49	234.73
3133.72	250.182
3137.95	243.172
3142.18	254.557
3146.4	272.15
3150.62	277.327
3154.84	263.596
3159.06	264.371
3163.27	256.777
3167.48	253.268
3171.69	245.532
3175.89	263.007
3180.09	284.616
3184.29	265.937
3188.49	272.572
3192.68	266.609
3196.87	301.192
3201.06	276.539
3205.24	273.241
3209.42	291.55
3213.6	281.952
3217.78	304.874
3221.95	273.414
3226.12	294.203
3230.29	282.177
3234.45	285.438
3238.61	284.257
3242.77	283.191
3246.93	268.772
3251.08	285.35
3255.23	308.529
3259.38	284.62
3263.53	256.247
3267.67	277.981
3271.81	281.394
3275.95	272.987
3280.08	289.576
3284.21	271.816
3288.34	288.445
3292.47	268.258
3296.59	275.644
3300.71	257.716
3304.83	288.324
3308.95	254.077
3313.06	296.35
3317.17	296.897
3321.27	281.183
3325.38	295.91
3329.48	289.664
3333.58	304.811
3337.67	289.353
3341.77	278.257
3345.86	297.814
3349.95	305.449
3354.03	303.597
3358.11	294.73
3362.19	285.834
3366.27	288.836
3370.34	308.673
3374.42	297.208
3378.48	328.981
3382.55	288.402
3386.61	303.264
3390.68	296.343
3394.73	299.109
3398.79	321.384
3402.84	319.331
3406.89	297.759
3410.94	300.442
3414.98	325.023
3419.03	310.664
3423.06	310.877
3427.1	306.257
3431.14	301.726
3435.17	309.494
3439.2	302.671
3443.22	295.873
3447.25	296.587
3451.27	314.601
3455.28	268.491
3459.3	299.196
3463.31	310.216
3467.32	298.812
3471.33	297.304
3475.34	275.451
3479.34	291.43
3483.34	325.189
3487.33	288.044
3491.33	304.099
3495.32	287.004
3499.31	290.19
3503.3	288.16
3507.28	293.729
3511.26	291.404
3515.24	271.039
3519.22	273.767
3523.19	284.212
3527.16	299.877
3531.13	274.33
3535.1	261.903
3539.06	270.275
3543.02	257.862
3546.98	266.079
3550.93	271.614
3554.89	261.316
3558.84	261.592
3562.78	246.311
3566.73	236.297
3570.67	262.989
3574.61	245.195
3578.55	264.222
3582.48	259.715
3586.41	263.136
3590.35	216.164
3594.27	243.392
3598.2	236.083
3602.12	247.382
3606.04	231.894
3609.95	235.071
3613.87	246.335
3617.78	233.321
3621.69	233.659
3625.6	231.123
3629.5	231.263
3633.4	201.579
3637.3	215.274
3641.2	223.727
3645.09	221.446
3648.98	232.655
3652.87	208.387
3656.76	230.392
3660.64	208.759
3664.53	208.917
3668.4	211.87
3672.28	198.392
3676.16	193.206
3680.03	210.053
3683.9	205.049
3687.76	216.659
3691.63	195.134
3695.49	215.048
3699.35	193.371
3703.2	196.659
3707.06	200.005
3710.91	208.972
3714.76	201.076
3718.6	187.426
3722.45	204.745
3726.29	213.593
3730.13	199.796
3733.97	194.502
3737.8	172.109
3741.63	183.799
3745.46	212.631
3749.29	207.203
3753.11	204.56
3756.93	190.4
3760.75	184.772
3764.57	204.916
3768.39	187.824
3772.2	199.462
3776.01	196.762
3779.81	202.73
3783.62	194.388
3787.42	186.033
3791.22	180.508
3795.02	206.853
3798.81	215.961
3802.61	181.557
3806.4	187.793
3810.18	211.564
3813.97	203.226
3817.75	186.05
3821.53	186.4
3825.31	189.642
3829.09	192.901
3832.86	199.17
3836.63	214.304
3840.4	182.077
3844.17	197.261
3847.93	206.332
3851.69	197.564
3855.45	194.683
3859.21	203.614
3862.96	194.762
3866.71	201.053
3870.46	183.613
3874.21	189.685
3877.95	183.826
3881.69	189.929
3885.44	196.073
3889.17	163.308
3892.91	196.521
3896.64	187.862
3900.37	197.185
3904.1	194.459
3907.82	176.617
3911.55	185.969
3915.27	198.412
3918.99	201.864
3922.7	178.016
3926.42	190.621
3930.13	191.017
3933.84	194.397
3937.54	179.346
3941.25	185.802
3944.95	183.106
3948.65	189.613
3952.35	186.811
3956.04	183.966
3959.73	187.24
3963.42	184.289
3967.11	187.482
3970.8	190.625
3974.48	196.894
3978.16	203.15
3981.84	187.633
3985.52	178.319
3989.19	178.31
3992.86	178.371
3996.53	190.914
3998.37	181.689