File: Data/3-Raman/raw/bu19(2)w-a-ff1-fi01-s_1800 (450-850nm)_532nm_edge_10%_x100_vis_lwd_h50um_30sx2_01.txt
#Acq. time (s)=	30
#Accumulations=	2
#Range (cm-¹)=	99...1000
#Windows=	2
#Auto scanning=	Off
#Autofocus=	Off
#Macrospot=	Off
#AutoExposure=	Off
#Spike filter=	Multiple accum.
#Delay time (s)=	2
#Binning=	1
#Readout mode=	Signal
#DeNoise=	Off
#ICS correction=	On
#Dark correction=	Off
#Inst. Process=	Off
#Detector Gain=	Best Dynamic
#Detector ADC=	50 kHz HS
#Detector temperature (°C)=	-60.09
#Instrument=	LabRAM HR Evol
#Detector=	SIN-EM FIVIS
#Objective=	x100_VIS_LWD
#Grating=	1800 (450-850nm)
#ND Filter=	10%
#Laser=	532nm_Edge
#Hole=	49.98
#Temperature=	0
#Range=	Visible
#StageXY=	75x50mm Scan+
#StageZ=	Z motor
#X (µm)=	0
#Y (µm)=	0
#Z (µm)=	-45.7
#Full time(mm:ss)=	2:09
#Project=	21_11_26
#Sample=	BU19(2)w
#Site=
#Title=	BU19(2)w-A-FF1-FI01-S_1800 (450-850nm)_532nm_Edge_10%_x100_VIS_LWD_H50um_30sX2
#Remark=
#Date=	26.11.2021 11:52
#Acquired=	26.11.2021 11:52:27
102.198	132.882
102.842	140.106
103.486	151.584
104.128	148.725
104.772	148.738
105.415	145.935
106.057	153.046
106.701	150.26
107.344	130.326
107.986	151.652
108.629	144.354
109.271	152.765
109.914	152.682
110.558	139.851
111.199	139.863
111.843	139.835
112.484	152.529
113.127	135.409
113.768	131.045
114.411	160.593
115.052	143.422
115.695	140.452
116.336	148.736
116.979	134.465
117.62	149.731
118.263	131.288
118.904	143.79
119.547	142.274
120.187	154.796
120.83	147.769
121.471	135.142
122.113	135.106
122.754	150.464
123.397	144.783
124.037	140.501
124.677	139.076
125.32	158.586
125.96	145.905
126.602	130.403
127.243	147.007
127.883	146.885
128.525	138.484
129.165	153.853
129.805	142.746
130.447	134.404
131.087	138.559
131.727	142.683
132.369	137.085
133.009	141.237
133.648	146.818
134.29	144.01
134.93	135.598
135.57	136.975
136.209	135.598
136.851	146.736
137.49	149.54
138.13	135.604
138.769	149.457
139.411	148.114
140.05	146.869
140.689	147.087
141.328	147.229
141.968	145.959
142.609	151.487
143.248	141.595
143.887	155.374
144.526	135.808
145.165	127.523
145.804	134.539
146.445	138.871
147.084	117.939
147.722	133.281
148.361	126.275
149	137.372
149.638	124.737
150.277	126.058
150.916	132.962
151.554	132.924
152.195	119.024
152.833	125.995
153.472	125.925
154.11	118.864
154.748	124.313
155.387	117.298
156.025	124.254
156.663	125.713
157.301	136.825
157.939	117.368
158.577	114.571
159.215	128.427
159.853	125.576
160.491	122.753
161.129	122.737
161.767	133.759
162.404	122.634
163.042	128.115
163.678	122.505
164.315	132.097
164.953	123.751
165.591	122.357
166.228	125.116
166.866	126.478
167.503	116.769
168.14	129.157
168.778	123.59
169.413	122.161
170.05	119.241
170.687	124.679
171.325	123.329
171.962	123.374
172.599	119.332
173.234	116.583
173.871	115.189
174.508	116.555
175.145	122.056
175.781	123.402
176.416	123.404
177.053	115.157
177.69	122.094
178.326	130.373
178.961	124.769
179.597	119.175
180.234	121.85
180.868	128.658
181.505	120.341
182.141	128.621
182.778	128.773
183.412	133.199
184.048	127.69
184.684	126.219
185.318	123.284
185.955	137.152
186.591	138.562
187.225	131.676
187.861	133.057
188.495	119.298
189.131	127.566
189.767	130.19
190.4	141.158
191.036	141.333
191.67	132.04
192.305	144.464
192.939	127.98
193.575	139.019
194.21	127.908
194.844	133.398
195.479	137.504
196.113	137.465
196.748	129.176
197.381	133.348
198.017	143.04
198.65	136.168
199.285	140.292
199.918	133.387
200.553	141.615
201.186	141.55
201.819	145.618
202.454	155.185
203.087	149.565
203.722	145.318
204.355	141.145
204.99	131.488
205.623	154.914
206.255	145.345
206.89	144.042
207.523	156.507
208.157	153.748
208.79	144.035
209.422	141.188
210.057	145.236
210.689	136.908
211.321	153.35
211.956	145.091
212.588	151.945
213.22	144.998
213.852	147.683
214.487	144.887
215.119	154.402
215.751	152.929
216.385	156.921
217.017	140.447
217.649	137.633
218.281	166.253
218.914	142.958
219.546	152.992
220.178	151.486
220.81	146
221.441	156.896
222.075	165.021
222.706	159.488
223.338	158.075
223.969	155.374
224.601	158.183
225.232	174.708
225.866	167.958
226.497	162.542
227.128	152.93
227.759	154.22
228.391	152.781
229.022	155.476
229.653	169.097
230.284	160.88
230.915	162.254
231.546	163.653
232.179	162.225
232.81	171.603
233.44	170.125
234.071	165.993
234.702	172.923
235.333	162.198
235.963	158.175
236.594	161.005
237.224	162.482
237.855	169.41
238.485	165.328
239.116	158.553
239.746	154.513
240.377	165.568
241.005	162.874
241.635	168.364
242.265	154.548
242.896	169.546
243.526	176.348
244.156	150.247
244.786	155.705
245.416	159.812
246.046	151.647
246.676	168.122
247.306	172.331
247.933	173.694
248.563	162.663
249.193	173.505
249.823	162.482
250.452	165.188
251.082	152.798
251.709	173.286
252.339	176.144
252.968	162.515
253.598	158.422
254.225	165.263
254.854	165.191
255.484	163.731
256.113	156.863
256.742	159.623
257.369	158.416
257.999	158.479
258.628	151.641
259.255	166.638
259.884	161.017
260.513	152.733
261.14	151.325
261.768	159.454
262.397	158.061
263.026	149.79
263.653	166.205
264.281	157.97
264.908	156.649
265.537	156.822
266.165	159.864
266.792	162.308
267.42	148.035
268.047	147.958
268.675	145.322
269.303	154.903
269.93	149.332
270.558	147.977
271.184	147.958
271.812	145.2
272.438	138.332
273.067	134.145
273.693	155.768
274.321	152.944
274.949	141.98
275.575	143.211
276.2	147.188
276.828	145.785
277.454	144.422
278.082	149.815
278.707	145.697
279.335	136.235
279.961	153.877
280.588	149.824
281.214	140.325
281.841	140.283
282.467	141.573
283.092	137.463
283.719	144.189
284.345	146.848
284.97	149.521
285.597	138.729
286.222	149.547
286.85	133.344
287.475	134.713
288.1	136.066
288.727	137.437
289.352	141.549
289.977	144.312
290.601	137.549
291.228	148.389
291.853	138.958
292.478	143.06
293.105	134.986
293.729	137.703
294.354	135.106
294.978	124.338
295.605	146.027
296.229	131.067
296.854	139.159
297.478	150.009
298.103	141.898
298.729	141.889
299.353	124.335
299.978	144.687
300.602	143.379
301.226	133.924
301.85	135.273
302.476	144.723
303.1	144.747
303.724	139.361
304.348	148.845
304.972	143.452
305.596	136.718
306.219	129.998
306.843	134.156
307.467	146.473
308.093	142.486
308.716	146.573
309.34	139.804
309.963	152.126
310.587	130.409
311.21	134.512
311.834	138.583
312.457	142.68
313.081	139.991
313.704	145.404
314.327	138.547
314.95	141.174
315.573	150.692
316.197	130.289
316.82	126.231
317.443	143.973
318.064	135.905
318.687	142.858
319.309	142.983
319.932	140.289
320.555	129.383
321.178	125.249
321.801	130.626
322.423	138.715
323.046	112.766
323.669	124.934
324.289	126.206
324.912	139.707
325.534	128.758
326.157	130.028
326.779	128.579
327.401	140.705
328.022	133.897
328.644	132.482
329.266	128.351
329.888	132.314
330.509	129.515
331.131	133.449
331.753	142.773
332.375	137.255
332.995	143.954
333.617	145.335
334.238	138.648
334.86	133.329
335.48	123.966
336.102	137.347
336.724	130.307
337.343	136.589
337.965	134.995
338.587	147.113
339.206	144.504
339.828	139.142
340.449	133.782
341.068	136.432
341.69	134.97
342.309	145.596
342.93	126.825
343.552	138.818
344.171	138.808
344.792	137.409
345.411	134.613
346.032	130.474
346.653	143.649
347.272	142.14
347.893	143.332
348.512	129.918
349.133	137.797
349.752	136.433
350.373	132.441
350.991	140.35
351.612	141.588
352.231	150.767
352.851	144.075
353.47	133.428
354.088	132.059
354.709	140.046
355.327	128.202
355.948	140.125
356.566	134.828
357.186	145.401
357.805	145.427
358.423	144.126
359.043	148.082
359.661	136.128
360.281	141.397
360.899	144.071
361.517	138.835
362.137	145.473
362.755	142.858
363.373	142.898
363.993	140.254
364.611	140.134
365.229	153.14
365.846	137.344
366.466	145.377
367.084	134.884
367.701	134.914
368.321	148.288
368.938	158.883
369.556	141.619
370.173	142.94
370.793	138.98
371.41	129.78
372.027	156.405
372.645	156.538
373.262	153.903
373.881	156.502
374.498	149.709
375.115	149.853
375.732	147.986
376.349	147.873
376.966	143.699
377.583	160.748
378.202	155.742
378.819	146.388
379.436	163.594
380.053	148.977
380.669	141.044
381.286	154.406
381.903	154.408
382.519	149.145
383.136	157.219
383.752	154.598
384.369	159.964
384.985	138.669
385.602	157.359
386.218	161.394
386.834	152.015
387.45	157.381
388.067	160.105
388.683	176.187
389.299	165.582
389.915	165.647
390.531	171.015
391.147	172.293
391.763	158.911
392.379	174.906
392.995	170.961
393.611	167.007
394.227	167.069
394.842	165.746
395.458	177.721
396.072	166.969
396.687	177.627
397.303	184.289
397.918	178.882
398.534	185.491
399.149	174.711
399.765	167.94
400.378	193.167
400.994	197.048
401.609	192.912
402.224	200.793
402.839	195.36
403.453	187.337
404.068	183.276
404.683	207.189
405.298	195.262
405.911	207.28
406.526	207.284
407.141	212.571
407.754	213.794
408.368	204.314
408.983	210.74
409.598	211.87
410.211	211.677
410.825	227.375
411.44	228.583
412.053	229.905
412.667	220.605
413.282	227.151
413.894	224.441
414.509	226.968
415.121	228.206
415.735	230.662
416.35	243.625
416.962	231.608
417.576	236.797
418.188	232.688
418.802	250.814
419.414	249.265
420.029	242.402
420.643	266.904
421.254	232.672
421.868	239.118
422.48	247.054
423.094	257.712
423.706	247.336
424.32	248.611
424.931	266.751
425.545	259.984
426.157	272.709
426.768	261.928
427.382	251.308
427.993	272.006
428.607	261.448
429.218	282.152
429.832	267.803
430.443	271.621
431.054	271.541
431.668	268.746
432.279	275.06
432.89	265.892
433.503	276.208
434.114	260.524
434.727	263.049
435.338	266.946
435.949	261.728
436.56	278.503
437.173	274.509
437.784	269.238
438.395	278.268
439.008	283.43
439.618	289.775
440.229	267.628
440.84	276.579
441.452	264.866
442.063	272.544
442.673	249.287
443.284	281.593
443.896	261.048
444.507	279.258
445.117	265.043
445.727	256.021
446.338	254.724
446.95	262.433
447.56	263.624
448.17	245.437
448.78	264.794
449.39	255.608
450	236.175
450.61	242.56
451.22	241.487
451.832	243.337
452.442	247.562
453.052	221.444
453.662	231.234
454.272	244.137
454.881	233.81
455.491	232.509
456.101	211.858
456.71	228.707
457.32	218.494
457.929	219.931
458.539	212.35
459.148	211.248
459.757	211.365
460.367	212.704
460.976	199.574
461.585	203.278
462.194	201.904
462.804	207.143
463.413	189.052
464.022	207.29
464.631	189.253
465.24	202.229
465.847	178.902
466.456	204.927
467.065	174.027
467.674	194.915
468.282	185.855
468.891	182.998
469.5	188.082
470.108	194.541
470.715	172.48
471.324	186.691
471.932	178.917
472.541	182.816
473.149	167.385
473.756	176.602
474.364	175.405
474.972	176.739
475.581	185.771
476.187	166.228
476.795	170.003
477.403	162.125
478.012	161.989
478.618	165.779
479.226	165.772
479.834	164.483
480.44	172.217
481.048	163.162
481.656	156.762
482.261	164.548
482.869	164.411
483.477	152.777
484.083	168.287
484.691	156.649
485.298	159.178
485.904	151.346
486.511	162.766
487.119	144.601
487.724	163.804
488.332	135.344
488.937	155.762
489.545	156.87
490.15	143.952
490.757	160.558
491.363	164.366
491.97	155.448
492.575	151.673
493.182	145.366
493.787	154.4
494.394	149.177
494.999	158.011
495.606	146.322
496.211	143.629
496.818	149.85
497.423	140.729
498.03	157.116
498.634	144.254
499.241	143.065
499.846	144.586
500.451	136.451
501.057	144.209
501.662	145.307
502.268	136.211
502.873	136.096
503.477	155.231
504.084	149.222
504.688	137.711
505.292	137.697
505.899	136.411
506.503	141.394
507.107	137.535
507.713	131.105
508.317	147.523
508.921	152.531
509.525	139.807
510.131	134.727
510.735	144.855
511.339	147.362
511.943	148.559
512.549	139.624
513.153	134.495
513.757	133.148
514.36	143.216
514.966	135.649
515.57	142.02
516.173	139.599
516.777	154.815
517.38	152.282
517.984	154.783
518.589	144.473
519.193	144.454
519.796	130.601
520.399	139.543
521.003	142.182
521.606	139.753
522.209	141.024
522.812	139.634
523.415	143.336
524.018	147.042
524.621	140.58
525.224	150.661
525.829	144.455
526.432	152.182
527.035	143.456
527.638	153.635
528.241	137.155
528.844	152.211
529.446	136.997
530.049	139.477
530.652	153.382
531.252	145.925
531.855	135.867
532.457	143.518
533.06	139.789
533.662	137.267
534.264	138.488
534.867	153.651
535.469	121.982
536.071	142.236
536.674	137.202
537.276	147.392
537.876	151.27
538.478	139.957
539.08	140.117
539.682	143.987
540.284	140.167
540.886	145.196
541.486	135.011
542.088	140.029
542.69	136.207
543.292	143.833
543.893	142.586
544.493	142.613
545.095	149.023
545.696	145.253
546.298	145.212
546.898	142.609
547.499	143.887
548.101	151.543
548.7	138.987
549.301	147.95
549.903	142.904
550.502	156.896
551.103	145.407
551.705	138.97
552.304	146.529
552.905	142.71
553.506	142.69
554.105	150.273
554.706	143.83
555.307	152.838
555.906	146.414
556.507	153.996
557.106	140.038
557.707	150.179
558.305	165.393
558.906	161.521
559.507	156.398
560.106	157.651
560.706	153.825
561.305	167.743
561.906	158.847
562.504	155.045
563.104	172.842
563.703	167.825
564.303	172.861
564.902	167.706
565.5	165.137
566.1	170.161
566.699	172.676
567.299	166.27
567.897	171.313
568.497	175.019
569.095	175.921
569.693	162.282
570.293	180.57
570.891	164.766
571.491	174.42
572.089	185.893
572.687	177.626
573.287	178.206
573.884	185.85
574.482	192.671
575.082	196.763
575.679	199.023
576.277	193.715
576.875	195.549
577.474	190.125
578.072	199.624
578.669	207.081
579.266	203.785
579.866	194.259
580.463	211.055
581.06	205.225
581.658	204.331
582.257	206.982
582.854	211.264
583.451	205.944
584.048	205.235
584.645	205.838
585.242	220.371
585.841	221.07
586.438	219.607
587.035	222.611
587.632	226.933
588.229	229.189
588.826	230.115
589.422	233.118
590.019	234.961
590.616	221.335
591.214	237.297
591.811	246.188
592.408	233.904
593.004	250.99
593.601	245.35
594.197	253.96
594.793	253.644
595.39	264.467
595.986	259.348
596.582	261.519
597.179	262.814
597.492	262.179
598.094	283.194
598.698	269.348
599.3	273.696
599.903	278.837
600.507	291.518
601.109	279.181
601.711	296.445
602.315	285.129
602.917	297.259
603.518	286.001
604.12	297
604.724	290.775
605.326	288.386
605.928	299.527
606.529	288.471
607.133	303.281
607.734	292.205
608.336	324.343
608.938	315.585
609.541	301.841
610.143	310.302
610.744	311.381
611.345	324.794
611.947	323.485
612.548	322.266
613.151	318.665
613.752	330.964
614.353	318.605
614.955	325.955
615.556	312.418
616.157	322.321
616.758	335.958
617.359	313.794
617.962	319.003
618.563	322.917
619.163	328.126
619.764	308.607
620.365	313.67
620.966	333.377
621.566	297.499
622.167	334.409
622.768	303.471
623.368	305.936
623.969	307.195
624.569	314.697
625.17	300.096
625.77	313.934
626.37	281.809
626.971	297.846
627.571	278.093
628.171	300.649
628.771	296.816
629.372	291.955
629.972	282.182
630.57	279.823
631.17	291.072
631.77	278.616
632.37	255.01
632.97	260.036
633.57	265.073
634.169	270.055
634.769	262.57
635.369	260.071
635.967	272.468
636.566	263.75
637.166	259.989
637.766	233.992
638.365	237.812
638.963	245.275
639.562	240.248
640.162	240.204
640.761	232.746
641.361	237.786
641.958	235.42
642.557	236.797
643.156	220.828
643.756	217.249
644.353	224.801
644.952	221.01
645.551	224.621
646.148	218.322
646.747	203.382
647.346	207.091
647.945	208.318
648.542	213.289
649.141	207.057
649.74	204.506
650.336	192.027
650.935	205.616
651.532	206.808
652.13	195.588
652.729	193.089
653.326	193.101
653.924	176.997
654.523	196.91
655.119	205.606
655.718	186.948
656.314	179.472
656.912	188.127
657.509	190.512
658.107	194.087
658.703	187.821
659.301	179.132
659.897	161.725
660.496	176.529
661.092	171.557
661.69	174.093
662.286	167.877
662.884	176.378
663.479	172.49
664.077	152.596
664.673	173.688
665.271	153.864
665.867	161.204
666.464	163.597
667.06	147.472
667.656	160.96
668.253	144.847
668.849	162.001
669.446	155.723
670.042	155.622
670.637	166.615
671.235	150.557
671.83	151.777
672.425	159.11
673.023	157.808
673.618	154.03
674.213	155.123
674.81	150.101
675.405	151.251
676.001	147.516
676.598	147.473
677.193	144.968
677.788	146.127
678.383	138.728
678.979	154.444
679.574	137.233
680.169	139.623
680.764	141.992
681.361	137.131
681.955	140.511
682.55	134.302
683.145	137.887
683.739	130.569
684.336	126.93
684.93	133.037
685.525	140.365
686.119	129.431
686.713	140.335
687.308	125.72
687.904	119.591
688.498	123.185
689.093	129.208
689.687	123.079
690.281	130.323
690.875	114.527
691.469	113.251
692.063	126.463
692.657	122.811
693.251	114.28
693.845	117.968
694.439	124.267
695.033	120.573
695.626	121.711
696.22	121.638
696.814	116.711
697.408	113.015
698.001	123.776
698.595	116.404
699.188	118.73
699.782	125.937
700.375	116.347
700.969	115.185
701.562	118.888
702.156	109.274
702.749	122.562
703.342	117.725
703.936	121.334
704.529	110.427
705.122	113.967
705.715	106.654
706.306	117.518
706.899	109.155
707.492	110.442
708.085	108.147
708.678	104.534
709.271	104.545
709.864	108.18
710.455	108.19
711.048	105.772
711.64	108.179
712.233	100.894
712.824	103.29
713.416	99.6716
714.009	111.776
714.601	94.8095
715.194	103.248
715.784	95.935
716.377	99.5429
716.969	111.65
717.56	104.501
718.152	99.7217
718.744	104.673
719.336	105.996
719.927	104.872
720.519	95.1981
721.111	103.74
721.701	97.6924
722.293	95.2839
722.883	91.653
723.475	90.4296
724.067	89.1755
724.657	97.6446
725.249	95.1718
725.841	92.7307
726.43	95.2139
727.022	88.0262
727.612	85.665
728.203	90.6363
728.793	88.2324
729.385	93.1146
729.976	93.1022
730.566	90.6167
731.157	91.7899
731.747	88.0889
732.338	94.1447
732.927	91.7355
733.519	94.2071
734.108	90.589
734.699	89.4189
735.288	80.8992
735.878	85.8169
736.469	83.4048
737.058	82.2314
737.649	83.475
738.238	90.8187
738.829	84.7036
739.418	85.9093
740.007	91.9906
740.598	87.0748
741.186	76.0294
741.777	89.4263
742.366	89.4145
742.955	80.886
743.545	78.4633
744.134	84.5933
744.722	82.1729
745.313	87.0857
745.901	82.1906
746.49	76.0721
747.08	76.0465
747.669	76.0366
748.257	74.8197
748.845	87.0075
749.436	86.9664
750.024	75.9499
750.612	77.1384
751.2	75.8899
751.79	78.2673
752.379	74.6155
752.967	77.097
753.555	80.8229
754.143	79.66
754.733	82.111
755.32	77.1867
755.908	75.8109
756.496	78.1137
757.084	82.9064
757.672	80.5508
758.261	72.0118
758.849	78.0625
759.437	73.1129
760.024	77.911
760.612	79.1126
761.199	73.0604
761.787	73.0426
762.374	77.9565
762.962	71.8582
763.549	79.0455
764.136	79.0305
764.724	77.7987
765.311	75.3503
765.9	72.894
766.487	77.7052
767.074	77.6726
767.661	77.6357
768.249	76.4057
768.836	78.7947
769.421	81.2204
770.008	77.5666
770.594	71.4583
771.181	72.5897
771.768	79.7509
772.355	68.8618
772.942	76.0323
773.528	76.0203
774.115	78.4436
774.702	78.446
775.288	74.8451
775.875	72.4226
776.461	71.2297
777.046	74.7168
777.632	79.0926
778.219	76.7521
778.805	83.9302
779.391	80.3946
779.978	80.3602
780.562	73.1811
781.148	76.771
781.734	80.3237
782.32	69.5135
782.907	74.2442
783.491	76.5925
784.077	80.1845
784.663	80.1599
785.249	74.1589
785.833	76.5123
786.418	77.6691
787.004	70.4778
787.588	74.0106
788.174	75.1464
788.76	73.8658
789.345	74.9472
789.929	78.7055
790.515	69.1801
791.1	72.7746
791.684	72.5263
792.269	77.2478
792.855	78.4441
793.438	76.0253
794.023	77.1869
794.607	74.8748
795.192	77.3033
795.777	77.3641
796.361	79.419
796.946	75.0812
797.529	79.7184
798.114	81.5222
798.697	80.3445
799.282	80.3955
799.865	76.9448
800.45	78.1379
801.033	81.6477
801.618	80.4426
802.201	78.056
802.786	70.9738
803.369	79.2531
803.953	72.1726
804.536	76.9115
805.121	74.5803
805.703	80.4757
806.288	86.3469
806.87	75.6816
807.455	72.1148
808.037	83.9564
808.62	75.7118
809.204	83.9664
809.787	72.1428
810.371	75.6611
810.953	78.0036
811.536	81.5308
812.12	85.0622
812.702	80.3717
813.284	74.4886
813.868	80.4416
814.45	68.6317
815.032	78.0482
815.616	74.4522
816.198	80.3025
816.78	81.4363
817.362	73.1525
817.946	79.0383
818.528	73.2089
819.11	81.4807
819.691	79.1153
820.275	68.4842
820.857	74.3493
821.438	77.866
822.02	75.5484
822.603	77.9681
823.185	75.6388
823.766	70.9132
824.348	74.4504
824.929	79.1758
825.511	76.7948
826.094	72.0525
826.675	86.2192
827.256	79.1348
827.838	68.5169
828.419	77.9826
829	76.8481
829.581	82.805
830.162	72.181
830.743	81.6371
831.324	73.3579
831.907	80.4706
832.488	81.6534
833.069	76.9334
833.65	76.9491
834.23	75.8027
834.811	74.659
835.392	77.035
835.973	78.203
836.553	80.5571
837.134	82.9032
837.714	74.5861
838.295	74.5791
838.875	68.6639
839.456	78.1469
840.034	72.2471
840.615	74.6244
841.195	80.5175
841.775	75.7479
842.356	85.1828
842.936	76.879
843.516	73.3351
844.096	67.4476
844.676	72.2037
845.256	68.6534
845.835	69.8187
846.415	70.9911
846.995	75.7554
847.574	71.0735
848.154	73.4902
848.732	72.3178
849.312	79.3662
849.892	69.8852
850.472	69.8838
851.051	65.1435
851.629	67.511
852.209	72.2509
852.788	75.8192
853.368	68.6885
853.945	72.2051
854.525	67.432
855.104	68.631
855.684	69.8259
856.261	62.7108
856.841	60.3393
857.42	73.3142
857.997	70.8964
858.576	60.2494
859.156	56.7013
859.733	57.8688
860.312	67.2805
860.889	62.5303
861.468	67.2824
862.047	59.0235
862.624	62.549
863.203	61.3368
863.78	61.2642
864.359	62.4378
864.938	61.2484
865.514	62.4314
866.093	53.0091
866.67	51.8497
867.248	51.8302
867.825	49.4383
868.404	58.8448
868.98	56.4679
869.559	55.2819
870.135	63.5257
870.714	44.6646
871.29	50.5447
871.869	57.6025
872.445	48.172
873.023	48.1518
873.6	49.3146
874.176	49.3041
874.754	50.4809
875.33	52.8206
875.908	48.0945
876.484	49.247
877.06	41.0079
877.638	51.5584
878.214	44.4881
878.792	50.3419
879.368	49.158
879.944	49.1537
880.522	47.9707
881.098	45.6401
881.674	49.1794
882.251	46.8435
882.827	43.3133
883.403	50.3315
883.978	45.5939
884.556	43.203
885.131	48.9978
885.707	39.5807
886.282	41.8657
886.86	43.0107
887.435	48.8925
888.011	44.2521
888.586	45.4263
889.163	45.4188
889.738	46.5984
890.314	44.2525
890.889	48.9163
891.464	50.0584
892.039	41.8544
892.616	38.3276
893.191	40.6282
893.766	41.7449
894.341	42.8679
894.916	44.0074
895.491	41.6637
896.066	41.6603
896.641	41.6757
897.215	42.8763
897.79	46.4061
898.367	40.5842
898.941	41.7334
899.516	40.5328
900.091	39.3306
900.665	40.4614
901.24	39.2856
901.814	40.4505
902.389	38.1364
902.963	41.6524
903.537	35.8408
904.112	37.0084
904.686	45.1197
905.26	43.8899
905.833	36.8827
906.407	38.0133
906.981	36.8488
907.555	39.2039
908.129	40.4033
908.703	38.0998
909.277	38.0965
909.851	36.9132
910.425	41.5288
910.999	39.1643
911.571	34.4857
912.145	35.6229
912.718	40.2386
913.292	35.5962
913.866	36.7369
914.44	37.88
915.011	36.7164
915.585	37.8676
916.158	37.8777
916.732	41.3493
917.303	41.3499
917.877	35.567
918.45	35.5498
919.024	40.1579
919.595	36.6799
920.168	40.1182
920.742	38.9521
921.315	37.8035
921.886	34.3364
922.459	34.3247
923.032	35.4656
923.604	35.4529
924.177	38.8996
924.75	36.5911
925.321	34.2778
925.894	33.1194
926.466	35.4112
927.037	36.5366
927.61	41.1099
928.181	31.89
928.754	35.3227
929.326	34.1735
929.897	35.3394
930.47	35.3364
931.041	34.1771
931.613	38.7603
932.184	31.8462
932.756	38.7238
933.327	35.263
933.899	37.5457
934.47	38.6811
935.042	36.3668
935.612	34.0505
936.185	34.0282
936.755	32.8729
937.327	34.0184
937.897	39.7578
938.469	35.1991
939.04	38.6371
939.612	36.2976
940.182	31.7153
940.752	34.0051
941.324	39.6774
941.894	38.4461
942.466	33.9158
943.035	31.5781
943.605	37.3237
944.177	35.0659
944.747	31.6309
945.317	35.0354
945.888	33.8677
946.458	34.9891
947.028	36.119
947.599	31.5605
948.169	31.5661
948.738	29.2826
949.308	36.1237
949.879	31.5498
950.448	37.226
951.018	36.0644
951.587	32.6265
952.158	31.4713
952.728	34.877
953.297	30.3222
953.866	30.3204
954.435	32.5934
955.006	34.8758
955.576	36.0135
956.145	38.2791
956.714	34.8521
957.283	32.5608
957.852	32.547
958.42	32.5278
958.991	32.5162
959.56	35.9191
960.129	31.3757
960.698	33.6325
961.266	32.4612
961.835	33.5809
962.404	34.7124
962.972	33.5823
963.541	32.4628
964.109	31.3198
964.678	30.1203
965.246	34.6057
965.815	32.3442
966.383	32.5243
966.952	31.3066
967.52	34.7323
968.088	31.2539
968.657	36.854
969.225	34.5778
969.793	33.4404
970.361	35.6943
970.929	35.6953
971.497	32.2981
972.065	34.5504
972.633	31.1499
973.201	30.0106
973.769	31.1255
974.335	33.3809
974.903	35.6573
975.471	31.1386
976.039	34.519
976.606	32.2517
977.174	25.4732
977.742	32.2283
978.307	28.8317
978.875	35.5923
979.443	31.0786
980.01	31.0768
980.576	31.0792
981.143	33.351
981.711	29.9687
982.278	32.2213
982.845	31.073
983.411	31.038
983.978	27.6451
984.545	32.1273
985.111	34.3433
985.678	29.827
986.245	30.9393
986.81	35.4329
987.377	35.4155
987.944	28.666
988.509	29.7769
989.076	28.6424
989.643	32.0016
990.208	34.2404
990.775	34.2483
991.342	26.4128
991.907	30.9265
992.473	30.9237
993.038	32.0353
993.605	33.1506
994.169	32.0033
994.736	33.1032
995.303	26.3979
995.867	27.5509
996.434	29.8433
996.998	33.2462
997.565	33.2478
998.129	33.1767
998.695	28.6222
999.26	29.7596
999.826	28.7288