File: Data/3-Raman/raw/bu19w-ff07b-fi05-s_150 (500nm)_532nm_edge_100%_x100_vis_lwd_h50um_15sx2_01.txt
#Acq. time (s)=	15
#Accumulations=	2
#Range (cm-¹)=	50...5000
#Windows=	1
#Auto scanning=	Off
#Autofocus=	Off
#Macrospot=	Off
#AutoExposure=	Off
#Spike filter=	Multiple accum.
#Delay time (s)=	2
#Binning=	1
#Readout mode=	Signal
#DeNoise=	Off
#ICS correction=	On
#Dark correction=	Off
#Inst. Process=	Off
#Detector Gain=	Best Dynamic
#Detector ADC=	50 kHz HS
#Detector temperature (°C)=	-60.09
#Instrument=	LabRAM HR Evol
#Detector=	SIN-EM FIVIS
#Objective=	x100_VIS_LWD
#Grating=	150 (500nm)
#ND Filter=	100%
#Laser=	532nm_Edge
#Hole=	49.98
#Temperature=	0
#Range=	Visible
#StageXY=	75x50mm Scan+
#StageZ=	Z motor
#X (µm)=	0
#Y (µm)=	0
#Z (µm)=	-51.3
#Full time(s)=	34
#Project=	21_05_28
#Sample=	BU19w
#Site=
#Title=	BU19w-FF07b-FI05-S_150 (500nm)_532nm_Edge_100%_x100_VIS_LWD_H50um_15sX2
#Remark=
#Date=	28.05.2021 16:20
#Acquired=	28.05.2021 16:20:52
51.5961	4229.2
56.2453	3353.53
60.8921	3132.19
65.5367	6203.12
70.1768	9021.36
74.8167	4744.51
79.4543	2296.71
84.0897	1783.94
88.7227	1633.97
93.3513	1533.69
97.9798	1538.95
102.606	1461.01
107.23	1510.74
111.851	1635.71
116.469	1654.94
121.086	1580.78
125.7	1600.9
130.313	2399.39
134.921	2938.44
139.529	2104.8
144.134	1612.92
148.738	1548.41
153.337	1552.87
157.936	1805.33
162.532	2604.13
167.126	4078.1
171.716	3652.73
176.306	2387.74
180.894	1975.1
185.477	2121.75
190.06	3258.09
194.64	6653.85
199.219	6612.39
203.793	3263.02
208.367	1944.2
212.939	1663.99
217.506	1599.08
222.073	1724.96
226.638	1700.22
231.199	1549.22
235.759	1655.99
240.318	1971.23
244.872	2191.75
249.425	2433.67
253.977	3331.37
258.524	3263.76
263.071	2865.67
267.616	3186.12
272.156	4195.26
276.697	3853.56
281.233	4674.11
285.769	8407.89
290.303	11587.8
294.832	9925.68
299.361	5401.48
303.886	4323.21
308.411	4897.94
312.934	4899.23
317.452	3888.53
321.97	2953.51
326.484	2410.42
330.998	2524.41
335.507	3171.43
340.017	3431.84
344.524	2519.33
349.027	2109.42
353.53	2367.75
358.028	2839.31
362.527	2669.02
367.021	2033.19
371.515	1790.3
376.004	2023.04
380.494	2048.61
384.979	1937.3
389.465	1972.84
393.946	2276.79
398.427	2529.08
402.903	2581.8
407.38	2362.05
411.852	2151.26
416.324	1890.48
420.792	2310.87
425.26	2832.03
429.723	2079.77
434.187	1463.71
438.646	1320.4
443.105	1279.86
447.56	1289.38
452.015	1372.45
456.466	1671.53
460.914	2446.72
465.362	3065.78
469.807	2540.98
474.251	2404.66
478.69	2596.03
483.13	2528.19
487.566	2495.82
491.999	2504.03
496.432	2450.4
500.861	2419.69
505.29	2317.44
509.715	2054.28
514.138	1803.97
518.56	1605.8
522.979	1444.07
527.395	1397.11
531.811	1371.22
536.223	1364.1
540.635	1375.55
545.042	1429.84
549.448	1407.71
553.853	1431.77
558.255	1473.59
562.654	1478.17
567.053	1540.88
571.448	1539.25
575.841	1415.07
580.232	1395.84
584.622	1521.03
589.009	2006.15
593.393	3269
597.777	4488
602.157	3615.36
606.535	2376.91
610.913	2011.4
615.287	2410.64
619.659	3053.41
624.029	3273.28
628.398	2527.04
632.763	2297.24
637.127	3503.97
641.488	4957.53
645.849	3527.89
650.206	2266.25
654.561	1809.91
658.914	1620.24
663.267	1580.3
667.615	1700.98
671.962	1898.7
676.307	1962.79
680.649	2030.9
684.991	2118.3
689.33	2024.11
693.666	1698.79
698	1390.08
702.332	1269.58
706.662	1171.21
710.992	1117.35
715.318	1098.83
719.641	1087.13
723.963	1101.94
728.283	1131.29
732.6	1085.4
736.918	1101.53
741.231	1123.47
745.542	1105.68
749.852	1169.74
754.159	1190.42
758.464	1240.66
762.767	1350.05
767.068	1418.81
771.369	1583.15
775.666	1934.33
779.961	2628.88
784.254	3535.69
788.545	4184.76
792.834	3955.11
797.12	3177.3
801.405	2492.44
805.688	1996.47
809.968	1697.23
814.247	1468.65
818.524	1346.94
822.798	1279.06
827.071	1274.23
831.341	1228.76
835.612	1175.54
839.878	1168.49
844.142	1186.66
848.405	1191.16
852.665	1198.26
856.923	1216.38
861.18	1224.53
865.434	1318.31
869.686	1370.79
873.936	1366.83
878.185	1338.41
882.431	1276.93
886.675	1279.59
890.915	1246.62
895.155	1252.44
899.393	1202.99
903.63	1224.56
907.864	1206.46
912.096	1203.18
916.326	1200.64
920.554	1195.69
924.78	1190.29
929.004	1226.18
933.227	1224.77
937.447	1244.68
941.665	1249.19
945.881	1334.77
950.095	1446.7
954.305	1570.39
958.516	1764.16
962.724	1686.58
966.93	1679.46
971.134	1826.4
975.337	1934.25
979.537	1938.36
983.735	1843.3
987.93	1925.06
992.124	2067.26
996.316	2501.06
1000.51	3341.87
1004.7	4761.42
1008.88	5115.48
1013.06	3918.24
1017.25	2778.69
1021.43	2333.94
1025.61	2356.35
1029.78	2644.91
1033.96	3585.49
1038.13	5572.02
1042.3	6589.3
1046.47	5663.17
1050.63	6121.26
1054.8	6915.32
1058.96	6485.48
1063.12	5476.73
1067.28	4082.93
1071.44	2927.62
1075.59	2342.53
1079.74	2224.59
1083.89	2291.52
1088.04	2636.51
1092.19	3470.68
1096.33	4769
1100.48	5894.1
1104.62	5684.95
1108.76	4558.65
1112.89	3965.62
1117.03	4038.34
1121.16	3925.13
1125.29	3563.67
1129.42	3206.62
1133.55	3253.7
1137.68	3545.16
1141.8	3594.88
1145.92	3244.13
1150.04	2702.65
1154.16	2420.3
1158.27	2507.06
1162.39	2982.39
1166.5	3417.58
1170.61	3170.78
1174.72	2754.09
1178.82	2528.1
1182.93	2439.3
1187.03	2258.44
1191.13	1979.38
1195.23	1865.63
1199.33	1729.31
1203.42	1656.37
1207.51	1647.67
1211.6	1599.58
1215.69	1525.57
1219.78	1445.05
1223.86	1502.81
1227.95	1661.9
1232.03	1812.96
1236.11	1708.06
1240.18	1683.24
1244.26	1778.91
1248.33	2029.9
1252.41	1954.47
1256.48	1695.63
1260.54	1466.79
1264.61	1381.89
1268.67	1333.16
1272.74	1324.64
1276.8	1325.12
1280.86	1293.41
1284.91	1277.51
1288.97	1269.4
1293.02	1266.15
1297.07	1213.35
1301.12	1251.08
1305.17	1271.46
1309.21	1275.63
1313.25	1238.32
1317.3	1275.13
1321.34	1236.12
1325.37	1233.92
1329.41	1205.43
1333.44	1214.02
1337.48	1161.04
1341.5	1237.09
1345.53	1235.84
1349.56	1230.57
1353.59	1225.36
1357.61	1218.23
1361.63	1224.9
1365.65	1224.85
1369.66	1223
1373.68	1271.79
1377.69	1331.51
1381.7	1301.71
1385.72	1245.96
1389.72	1242.66
1393.73	1234.78
1397.73	1223.48
1401.74	1237.69
1405.74	1201.61
1409.73	1219.84
1413.73	1217.5
1417.73	1237.87
1421.72	1228.62
1425.71	1202.41
1429.7	1211.13
1433.69	1232.79
1437.67	1217.9
1441.66	1245.47
1445.64	1267.91
1449.62	1241.91
1453.6	1245.3
1457.57	1251.52
1461.55	1270.32
1465.52	1248.32
1469.49	1254.8
1473.46	1259.48
1477.43	1217.88
1481.39	1301.62
1485.36	1220.67
1489.32	1260.04
1493.28	1207.67
1497.24	1265.59
1501.19	1265.1
1505.15	1271.64
1509.1	1248.39
1513.05	1249.55
1517	1249.8
1520.95	1300.65
1524.9	1242.91
1528.84	1269.67
1532.78	1271.37
1536.72	1276.97
1540.66	1257.42
1544.6	1254.35
1548.53	1302.64
1552.46	1285.04
1556.4	1284.72
1560.32	1290.02
1564.25	1284.52
1568.18	1326.28
1572.1	1305.08
1576.02	1346.65
1579.94	1335.04
1583.86	1326.29
1587.78	1309.76
1591.69	1310.54
1595.61	1324.76
1599.52	1299.57
1603.43	1308.12
1607.34	1292.89
1611.24	1321.81
1615.15	1295.21
1619.05	1307.14
1622.95	1330.47
1626.85	1318.57
1630.74	1303.03
1634.64	1303.22
1638.53	1301.43
1642.42	1306.7
1646.31	1285.41
1650.2	1295.86
1654.09	1293.92
1657.97	1298.58
1661.86	1326.25
1665.74	1284.5
1669.62	1308.91
1673.49	1292.53
1677.37	1310.69
1681.24	1295.46
1685.12	1307.76
1688.99	1285.4
1692.86	1303.05
1696.72	1315.68
1700.59	1318.5
1704.45	1334.38
1708.31	1320.42
1712.17	1310.04
1716.03	1305.39
1719.89	1315.95
1723.74	1345.38
1727.6	1300.16
1731.45	1288.76
1735.3	1340.33
1739.14	1345.68
1742.99	1306.97
1746.83	1349.52
1750.68	1346.26
1754.52	1341.63
1758.36	1334.08
1762.19	1329.68
1766.03	1352.15
1769.86	1351.01
1773.69	1319.85
1777.53	1340.79
1781.35	1312.83
1785.18	1314.88
1789	1322.7
1792.83	1364.32
1796.65	1317.92
1800.47	1327.69
1804.29	1332.86
1808.1	1332.28
1811.92	1347.58
1815.73	1323.03
1819.54	1371.48
1823.35	1380.89
1827.16	1337.21
1830.97	1355.43
1834.77	1362.9
1838.58	1346.6
1842.38	1381.84
1846.18	1376.29
1849.97	1371.86
1853.77	1383.65
1857.56	1347.38
1861.36	1370.51
1865.15	1370.12
1868.93	1386.58
1872.72	1377.19
1876.51	1408.8
1880.29	1404.39
1884.07	1362.81
1887.86	1415.29
1891.63	1407.66
1895.41	1425.84
1899.19	1406.29
1902.96	1383.67
1906.73	1418.39
1910.5	1397.1
1914.27	1389.2
1918.04	1414.61
1921.8	1412.34
1925.57	1397.23
1929.33	1407.36
1933.09	1398.14
1936.85	1411.2
1940.6	1393.46
1944.36	1442.02
1948.11	1400.78
1951.87	1415.54
1955.61	1374.35
1959.36	1422.57
1963.11	1439.33
1966.86	1437.21
1970.6	1422.44
1974.34	1404.35
1978.08	1402.87
1981.82	1441.38
1985.56	1430.01
1989.29	1431.57
1993.02	1452.45
1996.75	1456.23
2000.49	1434.67
2004.21	1466.96
2007.94	1417.65
2011.67	1447.48
2015.39	1464.35
2019.11	1471.76
2022.83	1441.44
2026.55	1413.89
2030.27	1482.55
2033.98	1486.9
2037.69	1427.68
2041.41	1482.75
2045.12	1472.71
2048.82	1470.02
2052.53	1452.98
2056.24	1500.13
2059.94	1473.86
2063.64	1497.11
2067.34	1461.01
2071.04	1506.91
2074.74	1482.84
2078.43	1486.54
2082.13	1458.85
2085.82	1513.48
2089.51	1519.99
2093.2	1519.31
2096.88	1550.04
2100.57	1483.81
2104.25	1485.85
2107.94	1522.97
2111.62	1571.01
2115.3	1526.94
2118.97	1496.64
2122.65	1519.62
2126.32	1561.72
2129.99	1592.37
2133.66	1581.14
2137.33	1531.94
2141	1552.75
2144.67	1554.83
2148.33	1530.12
2151.99	1552.29
2155.66	1539.62
2159.31	1587.45
2162.97	1560.39
2166.63	1571.98
2170.28	1614.82
2173.94	1558.05
2177.59	1580
2181.24	1584.85
2184.89	1619.64
2188.53	1614.83
2192.18	1567.9
2195.82	1625.34
2199.46	1593.04
2203.1	1608.28
2206.74	1597.34
2210.38	1598.52
2214.01	1610
2217.65	1621.6
2221.28	1628.69
2224.91	1611.96
2228.54	1660.48
2232.16	1616
2235.79	1669.48
2239.41	1634.21
2243.04	1705.41
2246.66	1689.48
2250.28	1701.48
2253.89	1692.28
2257.51	1686.93
2261.12	1651.6
2264.74	1689.93
2268.35	1631.94
2271.96	1659.65
2275.57	1627.67
2279.17	1665.86
2282.78	1691.69
2286.38	1673.15
2289.98	1671.56
2293.58	1685.82
2297.18	1648.1
2300.78	1642.59
2304.37	1671.85
2307.97	1642
2311.56	1677.32
2315.15	1700.06
2318.74	1695.97
2322.33	1703.81
2325.91	1687.87
2329.5	1673.7
2333.08	1670.67
2336.66	1684.4
2340.24	1705.39
2343.82	1680.08
2347.4	1722.19
2350.97	1750.91
2354.54	1732.69
2358.12	1758.29
2361.69	1737.11
2365.26	1712.26
2368.82	1721.94
2372.39	1716.27
2375.95	1673.51
2379.52	1736.12
2383.08	1739.79
2386.64	1714.18
2390.19	1768.86
2393.75	1724.66
2397.31	1766.33
2400.86	1760.9
2404.41	1764.68
2407.96	1729.27
2411.51	1726.67
2415.06	1741
2418.6	1738.32
2422.15	1744.19
2425.69	1731.14
2429.23	1735.1
2432.77	1740.34
2436.31	1788.63
2439.84	1729.54
2443.38	1717.8
2446.91	1716.31
2450.44	1737.64
2453.97	1735.9
2457.5	1741.48
2461.03	1758.74
2464.55	1747.58
2468.08	1754.73
2471.6	1747.28
2475.12	1739.73
2478.64	1738.53
2482.16	1746.09
2485.67	1800.08
2489.19	1779.46
2492.7	1765.52
2496.21	1791.87
2499.72	1801.93
2503.23	1759.91
2506.74	1797.1
2510.25	1780.62
2513.75	1776.43
2517.25	1804.27
2520.75	1810.07
2524.25	1777.58
2527.75	1765.45
2531.25	1830.48
2534.74	1787.67
2538.24	1767.58
2541.73	1803.28
2545.22	1801.08
2548.71	1783.04
2552.2	1839
2555.68	1821.54
2559.17	1824.39
2562.65	1807.78
2566.13	1802.14
2569.61	1793.31
2573.09	1824.16
2576.57	1849.9
2580.04	1788.7
2583.51	1781.94
2586.99	1803.49
2590.46	1789.6
2593.93	1806.07
2597.4	1814.69
2600.86	1841.07
2604.33	1811.88
2607.79	1837.13
2611.25	1809.05
2614.71	1844.03
2618.17	1865.31
2621.63	1839.69
2625.09	1800.26
2628.54	1820.86
2631.99	1832.51
2635.45	1793.79
2638.9	1860.04
2642.34	1869.32
2645.79	1871.51
2649.24	1858.29
2652.68	1851.34
2656.12	1839.18
2659.56	1841.87
2663.01	1880.33
2666.44	1840.01
2669.88	1833.77
2673.32	1842.5
2676.75	1844.92
2680.18	1856.03
2683.61	1840.4
2687.04	1846.01
2690.47	1856.54
2693.9	1882.61
2697.32	1909.19
2700.75	1884.99
2704.17	1843.2
2707.59	1830.34
2711.01	1828.08
2714.43	1879.24
2717.84	1847.03
2721.26	1871.05
2724.67	1863.63
2728.08	1873.16
2731.49	1836.07
2734.9	1867.12
2738.31	1824.21
2741.71	1857.11
2745.12	1873.73
2748.52	1845.02
2751.92	1868
2755.32	1868.27
2758.72	1842.9
2762.12	1865.59
2765.52	1869.89
2768.91	1904.99
2772.3	1866.28
2775.7	1863.22
2779.09	1891.86
2782.47	1876.9
2785.86	1859.93
2789.25	1899.34
2792.63	1886
2796.01	1868.86
2799.4	1864.88
2802.78	1849.34
2806.15	1876.97
2809.53	1876.4
2812.91	1850.47
2816.28	1859.06
2819.65	1858.26
2823.03	1887.62
2826.4	1878.95
2829.76	1900.27
2833.13	1861.25
2836.5	1887.82
2839.86	1873.72
2843.22	1886.07
2846.59	1846.69
2849.95	1907.73
2853.3	1875.03
2856.66	1877.55
2860.02	1854.14
2863.37	1896.45
2866.72	1868.62
2870.08	1897.99
2873.43	1890.66
2876.77	1881.36
2880.12	1936.02
2883.47	1878.57
2886.81	1855.75
2890.15	1886.67
2893.5	1893.9
2896.84	1888.39
2900.17	1870.31
2903.51	1858.54
2906.85	1821.93
2910.18	1913.85
2913.52	1877.89
2916.85	1897.62
2920.18	1855.57
2923.51	1918.42
2926.83	1907.31
2930.16	1931.83
2933.48	1951.38
2936.81	1951.74
2940.13	1955.87
2943.45	1936.44
2946.77	1946.29
2950.09	1995.69
2953.4	1944.37
2956.72	1925.12
2960.03	1924.99
2963.34	1879.99
2966.65	1958.02
2969.96	1935.31
2973.27	1923.26
2976.58	1883.15
2979.88	1898.7
2983.19	1953.44
2986.49	1913.52
2989.79	1886.83
2993.09	1890.25
2996.39	1937.94
2999.68	1912.45
3002.98	1864.34
3006.27	1892.4
3009.57	1910.28
3012.86	1932.99
3016.15	1898.29
3019.43	1874.81
3022.72	1860.71
3026.01	1859.81
3029.29	1855.17
3032.57	1876.94
3035.86	1898.63
3039.14	1888.14
3042.41	1860.62
3045.69	1882.33
3048.97	1883.25
3052.24	1895.53
3055.52	1831.09
3058.79	1873.68
3062.06	1879.65
3065.33	1902.04
3068.6	1874.85
3071.86	1891.85
3075.13	1880.65
3078.39	1943.43
3081.65	1906.03
3084.91	1895.86
3088.17	1943.47
3091.43	1899.55
3094.69	1926.97
3097.95	1918.68
3101.2	1913.53
3104.45	1927.03
3107.7	1899.57
3110.95	1903.22
3114.2	1941.49
3117.45	1943.76
3120.7	1918.47
3123.94	1912.21
3127.18	1950.7
3130.43	1959.6
3133.67	1960.91
3136.91	1946.91
3140.14	1969.03
3143.38	1901.5
3146.61	1953.16
3149.85	1970.63
3153.08	1957.62
3156.31	1968.38
3159.54	1955.33
3162.77	1983.25
3166	1951.06
3169.22	1970.22
3172.45	1951.06
3175.67	2011.97
3178.89	2017.37
3182.11	2009.38
3185.33	2024.33
3188.55	2038.08
3191.77	2021.26
3194.98	1986.35
3198.2	2061.93
3201.41	2014.56
3204.62	2091.08
3207.83	2099.1
3211.04	2096.75
3214.25	2131.64
3217.45	2105.79
3220.66	2112.29
3223.86	2103.65
3227.06	2139.93
3230.26	2146.76
3233.46	2125.22
3236.66	2124.46
3239.85	2132.74
3243.05	2094.48
3246.24	2177.29
3249.44	2139.13
3252.63	2145.97
3255.82	2151.92
3259.01	2175.97
3262.19	2177.76
3265.38	2134.35
3268.56	2191.88
3271.75	2158.45
3274.93	2142.09
3278.11	2151.48
3281.29	2124.13
3284.47	2160.37
3287.64	2135.57
3290.82	2145.88
3293.99	2182.1
3297.17	2158.18
3300.34	2172.41
3303.51	2175.7
3306.68	2186.04
3309.84	2155.26
3313.01	2240.12
3316.18	2247.8
3319.34	2266.8
3322.5	2319.81
3325.66	2304.56
3328.82	2323.41
3331.98	2386.73
3335.14	2467.12
3338.29	2568.38
3341.45	2664.98
3344.6	2780.39
3347.75	3016.12
3350.9	3233.64
3354.05	3642.41
3357.2	4052.52
3360.35	4742.85
3363.49	5758.27
3366.64	6871.38
3369.78	8301.43
3372.92	10186.6
3376.06	11827.9
3379.2	11582.4
3382.34	9331.05
3385.48	7066.56
3388.61	5452.05
3391.75	4677.2
3394.88	4185.36
3398.01	3953.51
3401.14	3734.04
3404.27	3581.88
3407.4	3555.15
3410.52	3569.46
3413.65	3766.46
3416.77	4217.31
3419.89	5285.47
3423.01	7994.68
3426.13	13558.2
3429.25	14826.9
3432.37	9468.06
3435.49	5431.37
3438.6	3795.58
3441.72	3219.42
3444.83	2864.76
3447.94	2639.44
3451.05	2574.4
3454.16	2511.92
3457.26	2471.33
3460.37	2427.61
3463.47	2479.92
3466.58	2500.66
3469.68	2429.89
3472.78	2438.47
3475.88	2451.57
3478.98	2509.25
3482.07	2569.8
3485.17	2652.06
3488.26	2767.44
3491.36	2917.11
3494.45	3108.98
3497.54	3481.78
3500.63	3944.69
3503.72	4510.16
3506.81	5266.73
3509.89	5720.18
3512.98	5675.24
3516.06	4987.08
3519.14	4228.89
3522.22	3556.66
3525.3	3161.84
3528.38	2897.57
3531.45	2711.85
3534.53	2510.32
3537.61	2374.63
3540.68	2292.08
3543.75	2219.95
3546.82	2222.02
3549.89	2145.35
3552.96	2105.86
3556.03	2104.92
3559.09	2037.14
3562.16	2015.69
3565.22	1990.01
3568.28	1986.74
3571.34	1975.58
3574.4	1898.02
3577.46	1914.43
3580.52	1902.23
3583.57	1911.68
3586.63	1835.6
3589.68	1888.49
3592.73	1888.98
3595.78	1825.92
3598.83	1864.1
3601.88	1757.35
3604.93	1798.18
3607.97	1788.69
3611.02	1766.89
3614.06	1769.59
3617.1	1725
3620.14	1716.41
3623.18	1727.72
3626.22	1710.78
3629.26	1740.15
3632.3	1743.01
3635.33	1727.89
3638.36	1695.34
3641.4	1674.32
3644.43	1692.08
3647.46	1662.28
3650.49	1658.36
3653.51	1663.15
3656.54	1654.53
3659.57	1651.46
3662.59	1642.57
3665.61	1616.41
3668.63	1606.43
3671.65	1646.79
3674.67	1587.28
3677.69	1573.1
3680.71	1599.61
3683.72	1542.9
3686.74	1554.22
3689.75	1574.13
3692.76	1571.38
3695.77	1542.11
3698.78	1535.25
3701.79	1542
3704.79	1527.88
3707.8	1530.81
3710.81	1522.16
3713.81	1510.53
3716.81	1521.54
3719.81	1547.88
3722.81	1524.55
3725.81	1487.74
3728.81	1502.21
3731.8	1462.29
3734.8	1486.99
3737.79	1506.74
3740.78	1471.15
3743.77	1538.17
3746.76	1492.77
3749.75	1503.35
3752.74	1477.71
3755.73	1480.56
3758.71	1519.49
3761.7	1473
3764.68	1488.98
3767.66	1469.94
3770.64	1455.77
3773.62	1472.02
3776.6	1448.66
3779.58	1472.65
3782.55	1464.61
3785.53	1450.92
3788.5	1495.86
3791.47	1476.69
3794.44	1454.92
3797.41	1458.76
3800.38	1456.09
3803.35	1447
3806.32	1471.97
3809.28	1427.1
3812.24	1452.23
3815.21	1443.37
3818.17	1466.7
3821.13	1432.38
3824.09	1446.36
3827.04	1416.88
3830	1434.78
3832.96	1479.25
3835.91	1417.61
3838.86	1446.2
3841.82	1431.1
3844.77	1451.16
3847.72	1400.84
3850.67	1414.34
3853.61	1439.38
3856.56	1438.72
3859.5	1440.95
3862.45	1408.78
3865.39	1472.15
3868.33	1441.78
3871.27	1439.03
3874.21	1411.3
3877.15	1415.13
3880.09	1426.49
3883.02	1392.56
3885.96	1438.2
3888.89	1391.47
3891.82	1410.04
3894.75	1425.67
3897.68	1412.26
3900.61	1422.73
3903.54	1398.55
3906.47	1399.19
3909.39	1385.58
3912.31	1379.53
3915.24	1407.94
3918.16	1405.5
3921.08	1424.44
3924	1381.65
3926.92	1389.59
3929.83	1380.13
3932.75	1408.95
3935.67	1357.62
3938.58	1409.06
3941.49	1400.43
3944.4	1395.49
3947.31	1412.65
3950.22	1342.82
3953.13	1328.62
3956.04	1372.9
3958.94	1382.83
3961.85	1371.75
3964.75	1370.32
3967.65	1413.07
3970.55	1374.39
3973.45	1380.82
3976.35	1356.49
3979.25	1397.39
3982.15	1367.1
3985.04	1357.92
3987.94	1404.43
3990.83	1337.43
3993.72	1363.55
3996.61	1352.41
3999.5	1390.33
4002.39	1386.93
4005.28	1374.89
4008.16	1353.28
4011.05	1359.62
4013.93	1347.62
4016.81	1345.27
4019.7	1332.3
4022.58	1344.42
4025.46	1333.37
4028.33	1351.33
4031.21	1348.05
4034.09	1334.16
4036.96	1363.81
4039.84	1311.27
4042.71	1312.87
4045.58	1335.56
4048.45	1344.77
4051.32	1327.88
4054.19	1349.85
4057.05	1358.39
4059.92	1318.33
4062.78	1342.3
4065.65	1291.45
4068.51	1321.26
4071.37	1314.1
4074.23	1335.17
4077.09	1284.15
4079.95	1293.48
4082.81	1317.44
4085.66	1289.75
4088.52	1333.18
4091.37	1309.3
4094.22	1323.58
4097.07	1297.71
4099.92	1283.62
4102.77	1299.8
4105.62	1280.73
4108.47	1329.97
4111.31	1286.3
4114.16	1309.01
4117	1266.01
4119.84	1259.04
4122.69	1260.9
4125.53	1271.72
4128.36	1260.06
4131.2	1274.2
4134.04	1296.37
4136.88	1278.79
4139.71	1267.41
4142.54	1316.59
4145.38	1291.04
4148.21	1267
4151.04	1243.03
4153.87	1258.92
4156.69	1263.58
4159.52	1228.56
4162.35	1269.34
4165.17	1251.58
4168	1264.13
4170.82	1268.91
4173.64	1226.82
4176.46	1267.89
4179.28	1286.47
4182.1	1276.8
4184.91	1271.08
4187.73	1273.26
4190.54	1242.21
4193.36	1224.05
4196.17	1265.76
4198.98	1241.05
4201.79	1285.89
4204.6	1266.08
4207.41	1324.73
4210.22	1268.56
4213.02	1292.86
4215.83	1260.14
4218.63	1271.44
4221.44	1272.82
4224.24	1230.69
4227.04	1219.91
4229.84	1236.99
4232.64	1243.27
4235.43	1248.74
4238.23	1210.64
4241.02	1217.18
4243.82	1256.58
4246.61	1219.48
4249.4	1190.18
4252.19	1202.63
4254.98	1192.07
4257.77	1207.4
4260.56	1204.72
4263.35	1248.22
4266.13	1237.64
4268.92	1186.91
4271.7	1208.52
4274.48	1191.84
4277.26	1189
4280.04	1167.8
4282.82	1167.71
4285.6	1170.53
4288.38	1177.25
4291.15	1208.14
4293.93	1182.29
4296.7	1199.14
4299.47	1173.52
4302.25	1182.26
4305.02	1160.53
4307.79	1172.29
4310.55	1159.74
4313.32	1159.49
4316.09	1152.94
4318.85	1148.3
4321.62	1186.34
4324.38	1159.13
4327.14	1140
4329.9	1188.13
4332.66	1159.75
4335.42	1154.86
4338.18	1150.86
4340.94	1174.61
4343.69	1138.23
4346.45	1162.11
4349.2	1141.23
4351.95	1146.88
4354.7	1149.78
4357.45	1130.07
4360.2	1115.45
4362.95	1125.3
4365.7	1155.76
4368.44	1120.57
4371.19	1131.6
4373.93	1107.54
4376.68	1165.56
4379.42	1132.13
4382.16	1104.81
4384.9	1117.63
4387.64	1117.34
4390.37	1076.32
4393.11	1084.86
4395.85	1083.96
4398.58	1115.32
4401.31	1093.9
4404.05	1099.26
4406.78	1086.02
4409.51	1067.6
4412.24	1078.13
4414.96	1066.66
4417.69	1073.87
4420.42	1094.2
4423.14	1098.07
4425.87	1102.02
4428.59	1076.72
4431.31	1077.53
4434.03	1061.57
4436.75	1070.66
4439.47	1059.81
4442.19	1062.46
4444.91	1089.26
4447.62	1080.35
4450.34	1089.27
4453.05	1048.74
4455.76	1043.89
4458.47	1053.64
4461.19	1041.28
4463.89	1114.24
4466.6	1053.61
4469.31	1070.88
4472.02	1023.98
4474.72	1023.49
4477.43	1020.98
4480.13	1062.85
4482.83	1040.46
4485.53	1023.3
4488.23	1037.76
4490.93	1071.23
4493.63	1037.79
4496.33	1059.21
4499.02	1032.13
4501.72	1056.88
4504.41	1020.09
4507.11	1039.57
4509.8	1005
4512.49	1022.4
4515.18	1039.85
4517.87	1047.78
4520.56	985.629
4523.24	985.185
4525.93	965.584
4528.61	1000.24
4531.3	988.093
4533.98	1017.53
4536.66	978.773
4539.34	973.087
4542.02	1009.12
4544.7	997.087
4547.38	1010.75
4550.05	971.968
4552.73	962.159
4555.4	964.302
4558.08	976.269
4560.75	1002.55
4563.42	949.317
4566.09	957.766
4568.76	974.089
4571.43	970.345
4574.1	967.679
4576.77	934.206
4579.43	979.382
4582.1	931.525
4584.76	953.417
4587.42	1012.95
4590.08	959.082
4592.74	938.877
4595.4	920.898
4598.06	965.28
4600.72	940.75
4603.38	947.004
4606.03	922.668
4608.69	931.182
4611.34	930.95
4613.99	943.86
4616.64	904.025
4619.29	933.473
4621.94	924.488
4624.59	907.732
4627.24	908.525
4629.89	902.653
4632.53	918.838
4635.18	926.064
4637.82	895.618
4640.46	881.729
4643.1	880.024
4645.74	951.689
4648.38	924.972
4651.02	922.868
4653.66	898.843
4656.3	915.581
4658.93	895.686
4661.57	902.092
4664.2	914.249
4666.83	921.83
4669.46	911.305
4672.09	904.203
4674.72	895.949
4677.35	883.186
4679.98	909.667
4682.61	856.418
4685.23	891.888
4687.86	880.168
4690.48	862.816
4693.1	865.728
4695.73	884.349
4698.34	895.087
4700.96	888.927
4703.58	879.34
4706.2	865.141
4708.82	873.515
4711.43	903.359
4714.05	878.89
4716.66	844.17
4719.28	854.693
4721.89	849.327
4724.5	832.583
4727.11	842.024
4729.72	866.277
4732.33	851.964
4734.93	838.777
4737.54	834.632
4740.14	829.295
4742.75	835.297
4745.35	825.309
4747.95	882.386
4750.55	854.011
4753.15	856.383
4755.75	839.391
4758.35	818.977
4760.95	846.452
4763.54	859.195
4766.14	835.548
4768.73	824.611
4771.33	811.446
4773.92	806.084
4776.51	805.299
4779.1	813.655
4781.69	833.431
4784.28	824.658
4786.87	817.03
4789.45	791.095
4792.04	815.529
4794.63	795.358
4797.21	810.718
4799.79	806.687
4802.37	809.59
4804.95	782.704
4807.53	771.965
4810.11	786.581
4812.69	806.979
4815.27	805.555
4817.84	788.019
4820.42	810.964
4822.99	799.238
4825.57	768.956
4828.14	774.552
4830.71	754.615
4833.28	782.404
4835.85	773.018
4838.42	795.207
4840.98	776.632
4843.55	784.885
4846.12	781.303
4848.68	772.929
4851.24	756.069
4853.81	810.375
4856.37	763.746
4858.93	728.369
4861.49	780.108
4864.05	759.739
4866.61	753.244
4869.16	753.886
4871.72	741.673
4874.27	739.922
4876.83	755.869
4879.38	725.561
4881.93	758.092
4884.49	719.337
4887.04	741.153
4889.58	739.225
4892.13	738.488
4894.68	727.003
4897.23	761.949
4899.77	756.376
4902.32	740.047
4904.86	693.863
4907.4	716.841
4909.95	713.542
4912.49	741.133
4915.03	741.201
4917.57	734.029
4920.1	737.691
4922.64	725.819
4925.18	707.978
4927.71	745.158
4930.25	708.147
4932.78	709.574
4935.31	727.885
4937.84	731.767
4940.38	704.516
4942.9	740.382
4945.43	719.06
4947.96	695.444
4950.49	695.749
4953.01	698.514
4955.54	690.394
4958.06	711.205
4960.59	703.273
4963.11	686.982
4965.63	704.549
4968.15	694.579
4970.67	709.705
4973.19	686.201
4975.71	689.215
4978.22	676.499
4980.74	679.528
4983.25	683.781
4985.77	662.604
4988.28	674.171
4990.79	677.27
4993.3	653.595
4995.81	683.41
4998.32	676.85