File: Data/3-Raman/raw/bu19w-e-ff11b-fi10-v_1800 (450-850nm)_532nm_edge_100%_x100_vis_h50um_30sx2_01.txt
#Acq. time (s)=	30
#Accumulations=	2
#Range (cm-¹)=	1200...2400
#Windows=	4
#Auto scanning=	Off
#Autofocus=	Off
#Macrospot=	Off
#AutoExposure=	Off
#Spike filter=	Multiple accum.
#Delay time (s)=	2
#Binning=	1
#Readout mode=	Signal
#DeNoise=	Off
#ICS correction=	On
#Dark correction=	Off
#Inst. Process=	Off
#Detector Gain=	Best Dynamic
#Detector ADC=	50 kHz HS
#Detector temperature (°C)=	-60.09
#Instrument=	LabRAM HR Evol
#Detector=	SIN-EM FIVIS
#Objective=	x100_VIS
#Grating=	1800 (450-850nm)
#ND Filter=	100%
#Laser=	532nm_Edge
#Hole=	49.98
#Temperature=	0
#Range=	Visible
#StageXY=	75x50mm Scan+
#StageZ=	Z motor
#X (µm)=	0
#Y (µm)=	0
#Z (µm)=	-270.7
#Full time(mm:ss)=	4:20
#Project=	21_11_04
#Sample=	BU19w
#Site=
#Title=	BU19w-E-FF11b-FI10-V_1800 (450-850nm)_532nm_Edge_100%_x100_VIS_H50um_30sX2
#Remark=
#Date=	04.11.2021 17:12
#Acquired=	04.11.2021 17:12:18
1200.19	25.3215
1201.3	27.4211
1202.41	26.4062
1203.52	23.1191
1204.63	26.3322
1205.74	23.066
1206.85	24.0971
1207.97	24.0767
1209.08	25.1251
1210.19	25.1027
1211.3	25.0679
1212.41	25.035
1213.52	26.0822
1214.63	27.1483
1215.74	26.0693
1216.85	23.9061
1217.95	27.0662
1219.06	25.9936
1220.17	27.0459
1221.28	28.0899
1222.39	25.9246
1223.5	27.9948
1224.61	25.8615
1225.71	26.9265
1226.82	33.2398
1227.93	26.8321
1229.03	30.0468
1230.14	31.0719
1231.25	32.0505
1232.35	27.8413
1233.46	28.8899
1234.57	29.9553
1235.67	34.1717
1236.78	33.0985
1237.88	25.7065
1238.99	29.8781
1240.1	27.7772
1241.2	28.8237
1242.3	28.8201
1243.41	28.8282
1244.51	28.8229
1245.62	36.1163
1246.72	24.5971
1247.82	32.9479
1248.93	30.8564
1250.03	32.9353
1251.13	29.7742
1252.24	29.7522
1253.34	31.8288
1254.44	33.936
1255.54	29.7607
1256.65	27.6801
1257.75	37.067
1258.85	28.7032
1259.95	31.8436
1261.05	42.2431
1262.15	54.8841
1263.25	61.0788
1264.35	44.4231
1265.45	36.0473
1266.55	33.9742
1267.66	35.0609
1268.75	31.9558
1269.85	32.9831
1270.95	37.1479
1272.05	37.1718
1273.15	36.1658
1274.25	30.9437
1275.35	36.2
1276.45	34.128
1277.54	42.5669
1278.64	39.4467
1279.74	47.8531
1280.84	77.3434
1281.94	196.343
1283.03	551.247
1284.13	262.876
1285.23	79.4863
1286.32	50.0122
1287.42	40.5179
1288.52	34.2067
1289.61	33.1796
1290.71	33.1767
1291.8	32.1231
1292.9	32.1232
1293.99	28.9989
1295.09	30.0761
1296.18	30.1245
1297.28	30.1081
1298.37	27.9835
1299.47	27.9737
1300.56	27.9793
1301.65	32.2155
1302.75	32.2144
1303.84	26.9267
1304.94	32.1939
1306.03	29.0032
1307.12	27.9505
1308.21	29.0052
1309.31	22.689
1310.4	30.0756
1311.49	24.8063
1312.58	29.035
1313.67	31.1377
1314.76	26.9249
1315.86	26.9324
1316.95	25.8748
1318.04	26.9394
1319.13	29.0507
1320.22	24.8241
1321.31	25.8554
1322.4	30.0553
1323.49	26.8886
1324.58	33.216
1325.67	28.9528
1326.76	31.0542
1327.85	30.0501
1328.93	25.8479
1330.02	31.1146
1331.11	23.7028
1332.2	28.9325
1333.29	23.6412
1334.37	28.8648
1335.46	24.6481
1336.55	30.9248
1337.64	27.7629
1338.72	27.7478
1339.81	22.515
1340.9	23.562
1341.98	28.7801
1343.07	28.7611
1344.16	29.8063
1345.24	30.8253
1346.33	28.6951
1347.41	27.624
1348.5	26.5694
1349.58	25.5087
1350.67	27.5678
1351.75	26.5168
1352.84	28.6271
1353.92	29.6265
1355.01	28.5606
1356.09	28.5656
1357.17	30.6302
1358.26	24.3838
1359.34	29.5527
1360.42	23.3075
1361.5	27.4466
1362.59	30.5439
1363.67	30.5595
1364.75	32.6163
1365.83	28.4486
1366.92	32.555
1368	33.5965
1369.08	47.0456
1370.16	27.383
1371.24	30.4523
1372.32	35.5676
1373.4	34.5196
1374.48	40.6896
1375.56	34.5123
1376.64	31.3912
1377.72	36.5635
1378.8	40.7221
1379.88	44.7929
1380.96	50.9095
1382.04	46.7172
1383.12	56.9138
1384.2	78.4436
1385.28	181.194
1386.36	935.241
1387.43	476.797
1388.51	97.003
1389.59	51.8309
1390.67	42.5329
1391.74	42.5037
1392.82	35.314
1393.9	41.4423
1394.97	33.2646
1396.05	31.2167
1397.13	35.2891
1398.2	36.3178
1399.28	34.286
1400.35	30.2071
1401.43	34.3126
1402.5	30.2747
1403.58	33.3519
1404.65	36.4141
1405.73	37.4153
1406.8	54.8426
1407.88	80.4911
1408.95	67.1835
1410.03	38.4573
1411.1	32.2742
1412.17	31.2648
1413.25	31.2916
1414.32	30.2861
1415.39	23.1017
1416.47	26.1926
1417.54	28.2578
1418.61	24.1515
1419.68	28.2471
1420.75	26.173
1421.83	30.3005
1422.9	26.264
1423.97	30.2125
1425.04	29.2183
1426.11	24.1005
1427.18	26.1181
1428.25	24.0618
1429.32	24.0734
1430.39	23.0741
1431.46	25.1456
1432.53	24.0963
1433.6	26.1123
1434.67	28.1801
1435.74	25.1026
1436.81	24.0704
1437.88	25.0936
1438.95	26.127
1440.01	25.1219
1441.08	21.0204
1442.15	25.1253
1443.22	25.1171
1444.29	22.0493
1445.35	27.185
1446.42	23.0748
1447.49	25.1167
1448.56	22.0519
1449.62	21.0172
1450.69	23.0596
1451.75	18.9539
1452.82	19.9827
1453.89	21.0066
1454.95	19.9801
1456.02	26.1357
1457.08	21.0012
1458.15	19.9765
1459.21	21.004
1460.28	22.0229
1461.34	22.0116
1462.41	25.0637
1463.47	23.0047
1464.53	24.0695
1465.6	23.985
1466.66	18.8741
1467.72	24.9915
1468.79	22.9465
1469.85	22.9296
1470.91	20.8817
1471.97	21.8923
1473.04	23.9213
1474.1	20.862
1475.16	21.8824
1476.22	22.8907
1477.29	22.8815
1478.34	19.8205
1479.41	22.8532
1480.47	22.8304
1481.53	25.8769
1482.59	25.8905
1483.65	21.8289
1484.71	22.7676
1485.77	24.8323
1486.83	21.7858
1487.89	21.7687
1488.95	21.7535
1490.01	21.7497
1491.07	21.7371
1492.12	22.7474
1493.18	24.7658
1494.24	18.7033
1495.3	23.736
1496.36	20.692
1497.42	19.6795
1498.47	20.6902
1499.53	22.7153
1500.59	19.6852
1501.64	21.6962
1502.7	25.7186
1503.76	24.7062
1504.81	17.6446
1505.87	20.6526
1506.93	21.665
1507.98	22.6705
1509.04	21.664
1510.09	20.6551
1511.15	19.6239
1512.21	21.5964
1513.26	18.5709
1514.31	23.6029
1515.37	22.574
1516.42	20.555
1517.48	23.5652
1518.53	22.5701
1519.58	21.57
1520.64	24.5812
1521.69	19.5634
1522.75	20.5552
1523.8	21.5339
1524.85	22.5334
1525.9	22.5491
1526.95	20.5454
1528.01	19.5362
1529.06	20.5331
1530.11	22.5345
1531.16	21.5435
1532.21	18.5387
1533.27	21.5669
1534.32	22.5673
1535.37	19.54
1536.42	20.5165
1537.47	22.5042
1538.52	21.4918
1539.57	21.5375
1540.62	22.5606
1541.67	22.5404
1542.72	21.5184
1543.77	22.5021
1544.81	19.5198
1545.86	21.5365
1546.91	20.5411
1547.96	23.5305
1549.01	24.4903
1550.06	24.5717
1551.1	23.5958
1552.15	23.6034
1553.2	22.5707
1554.25	24.5519
1555.3	22.5389
1556.34	21.536
1557.39	19.5333
1558.43	23.5132
1559.48	23.492
1560.53	21.4854
1561.57	21.4992
1562.62	23.5011
1563.66	22.5091
1564.71	23.4909
1565.76	23.4833
1566.8	23.5002
1567.84	20.4959
1568.89	23.4865
1569.93	22.4867
1570.98	24.4808
1572.02	24.4685
1573.07	25.4512
1574.11	22.4663
1575.15	25.4836
1576.2	22.4794
1577.24	26.4387
1578.28	21.4341
1579.32	20.4392
1580.37	18.4472
1581.41	19.4318
1582.45	24.4052
1583.49	22.4084
1584.53	25.4012
1585.58	23.4029
1586.62	23.3854
1587.66	20.3964
1588.7	20.4062
1589.74	23.3978
1590.78	20.4157
1591.82	23.3916
1592.86	22.372
1593.9	23.3411
1594.94	23.3528
1595.98	21.3542
1597.02	24.3396
1598.06	22.3452
1599.1	23.3189
1600.14	22.3107
1601.17	25.2546
1602.21	24.2142
1603.25	21.3023
1604.29	22.017
1605.33	22.1312
1606.37	19.7121
1607.4	23.5883
1608.44	23.5303
1609.48	23.163
1610.51	25.4758
1611.55	23.4586
1612.59	22.1489
1613.62	22.0673
1614.66	23.3021
1615.7	24.4635
1616.73	23.1878
1617.77	23.2181
1618.8	21.9128
1619.84	21.199
1620.87	20.9758
1621.91	22.4222
1622.94	23.089
1623.98	22.366
1625.01	21.8713
1626.04	22.9885
1627.08	22.0007
1628.11	21.5897
1629.07	19.2135
1630.12	22.1644
1631.16	18.2265
1632.21	26.1264
1633.25	24.1406
1634.3	22.1781
1635.34	20.2025
1636.39	18.2225
1637.43	23.1373
1638.48	21.1635
1639.52	20.1786
1640.57	19.2015
1641.61	19.1969
1642.65	20.1783
1643.7	20.1731
1644.74	22.1382
1645.78	23.1231
1646.83	20.1633
1647.87	20.161
1648.91	20.1818
1649.95	22.1568
1651	21.1864
1652.04	20.2031
1653.08	20.1977
1654.12	19.2178
1655.16	20.2195
1656.21	22.2097
1657.25	21.2183
1658.29	23.1828
1659.33	20.211
1660.37	17.2582
1661.41	20.2308
1662.45	26.2018
1663.49	21.2055
1664.53	24.2058
1665.57	21.2583
1666.61	20.2027
1667.65	18.2532
1668.69	20.247
1669.72	18.2707
1670.76	20.2627
1671.8	20.2641
1672.84	20.2654
1673.88	20.2736
1674.92	22.2651
1675.95	17.3194
1676.99	23.2571
1678.03	19.2853
1679.07	20.2645
1680.1	21.2449
1681.14	21.2401
1682.18	20.2527
1683.21	19.2634
1684.25	21.2321
1685.29	23.2052
1686.32	17.2867
1687.36	22.223
1688.39	19.2506
1689.43	20.2224
1690.46	21.2127
1691.5	20.2327
1692.53	20.2236
1693.57	19.2181
1694.6	18.2231
1695.64	20.1985
1696.67	22.171
1697.7	21.1658
1698.74	18.2032
1699.77	19.188
1700.81	20.1656
1701.84	22.1183
1702.87	20.1436
1703.9	20.1422
1704.94	21.1252
1705.97	18.1697
1707	20.1147
1708.03	20.0894
1709.06	17.1325
1710.1	21.0485
1711.13	17.14
1712.16	19.0907
1713.19	21.9918
1714.22	18.07
1715.25	19.0534
1716.28	19.0435
1717.31	17.0623
1718.34	17.0403
1719.37	23.8522
1720.4	16.0606
1721.43	21.8805
1722.46	19.9156
1723.49	18.9356
1724.52	19.8938
1725.55	16.9597
1726.58	18.8923
1727.6	18.8891
1728.63	18.8203
1729.66	15.9405
1730.69	19.8112
1731.72	17.8778
1732.74	17.8668
1733.77	20.7342
1734.8	14.9287
1735.82	18.7685
1736.85	21.6445
1737.88	20.6687
1738.91	15.8465
1739.93	17.738
1740.96	17.7208
1741.98	18.6696
1743.01	18.6646
1744.03	15.7827
1745.06	15.7825
1746.09	19.5948
1747.11	19.5746
1748.13	16.705
1749.16	19.5773
1750.18	19.5948
1751.21	16.7274
1752.23	18.6198
1753.26	17.6508
1754.28	19.5444
1755.3	23.3447
1756.33	19.5123
1757.35	17.5952
1758.37	16.6522
1759.39	21.411
1760.42	15.6954
1761.44	21.3891
1762.46	19.4919
1763.48	19.494
1764.5	17.6076
1765.53	18.5653
1766.55	18.5622
1767.57	21.4093
1768.59	16.6382
1769.61	18.5171
1770.63	13.7775
1771.65	18.5437
1772.67	17.6047
1773.69	21.4198
1774.71	19.5227
1775.73	22.4031
1776.75	18.5833
1777.77	18.5712
1778.79	20.4568
1779.81	17.6069
1780.83	16.6601
1781.85	21.4309
1782.86	19.538
1783.88	20.5042
1784.9	18.6052
1785.92	18.6013
1786.94	15.7526
1787.95	16.7464
1788.97	21.557
1789.99	18.6942
1791	15.8041
1792.02	18.6758
1793.04	20.5973
1794.05	20.6005
1795.07	19.6735
1796.09	16.8077
1797.1	19.7042
1798.12	16.8274
1799.13	17.7828
1800.15	16.8112
1801.16	18.7299
1802.18	20.6588
1803.19	21.6367
1804.21	19.7232
1805.22	17.8158
1806.24	20.7192
1807.25	18.7942
1808.26	18.7963
1809.28	17.8355
1810.29	18.8002
1811.3	18.7989
1812.32	18.8058
1813.33	18.8162
1814.34	18.8375
1815.36	19.813
1816.37	19.8176
1817.38	18.8324
1818.39	17.8783
1819.4	17.8841
1820.42	20.7941
1821.43	17.9028
1822.44	17.9088
1823.45	19.8414
1824.46	18.879
1825.47	18.8847
1826.48	19.8549
1827.49	19.8628
1828.5	20.8253
1829.51	19.8527
1830.52	16.9424
1831.53	16.9516
1832.54	18.9009
1833.55	19.8738
1834.56	18.8796
1835.57	15.9602
1836.58	17.9326
1837.58	15.9493
1838.59	18.8868
1839.6	18.902
1840.61	15.9494
1841.62	17.8529
1842.62	17.8438
1843.63	18.8082
1844.64	15.9145
1845.65	18.8268
1846.65	20.7306
1847.66	16.8561
1848.67	17.8119
1849.67	17.7917
1850.68	19.6935
1851.68	17.7643
1852.69	16.8035
1853.69	16.7919
1854.7	17.7355
1855.71	20.5937
1856.71	16.7608
1857.72	15.7951
1858.72	17.6935
1859.72	17.6864
1860.73	19.6106
1861.73	17.703
1862.74	18.6439
1863.74	18.6288
1864.74	20.5223
1865.75	20.4924
1866.75	17.6036
1867.75	17.5877
1868.76	17.5879
1869.76	15.6831
1870.76	18.5325
1871.76	16.6236
1872.77	19.4613
1873.77	16.6056
1874.77	22.2764
1875.77	16.5628
1876.77	18.4329
1877.77	20.39
1878.78	20.3633
1879.78	19.4094
1880.78	16.5666
1881.78	24.0916
1882.78	19.3416
1883.78	17.4371
1884.78	16.5095
1885.78	20.3036
1886.78	18.4029
1887.78	19.3265
1888.77	17.4177
1889.77	20.2407
1890.77	19.3079
1891.77	16.4791
1892.77	18.3471
1893.77	19.2691
1894.76	19.2595
1895.76	15.5086
1896.76	18.3406
1897.76	18.3416
1898.75	20.2068
1899.75	16.439
1900.75	20.2031
1901.75	17.3993
1902.74	17.3989
1903.74	20.2144
1904.74	16.4512
1905.73	18.3183
1906.73	19.25
1907.72	19.2583
1908.72	22.0861
1909.71	16.4657
1910.71	16.4827
1911.7	18.3672
1912.7	17.4243
1913.69	18.3819
1914.69	17.4542
1915.68	19.3424
1916.68	17.4452
1917.67	18.3839
1918.66	16.5147
1919.66	16.5358
1920.65	18.431
1921.64	18.4426
1922.64	15.5992
1923.63	18.428
1924.62	16.5338
1925.61	17.4956
1926.61	17.5143
1927.6	16.5765
1928.59	20.3748
1929.58	17.5492
1930.57	18.5141
1931.57	21.3555
1932.56	18.4998
1933.55	18.5147
1934.54	19.5263
1935.53	17.6316
1936.52	12.861
1937.51	16.658
1938.5	18.5675
1939.49	16.6738
1940.48	17.6492
1941.47	16.6912
1942.46	18.6196
1943.45	18.5982
1944.44	18.623
1945.42	20.5531
1946.41	18.6506
1947.4	19.6026
1948.39	17.69
1949.38	19.6198
1950.37	21.5669
1951.35	17.7593
1952.34	16.8074
1953.33	18.7224
1954.32	17.7247
1955.3	18.6886
1956.29	19.6811
1957.28	17.7757
1958.26	21.6268
1959.25	18.7356
1960.23	16.8035
1961.22	16.7938
1962.21	17.7569
1963.19	16.7999
1964.18	19.6852
1965.16	21.6049
1966.15	17.7777
1967.13	18.7438
1968.12	15.8625
1969.1	15.8489
1970.09	16.7946
1971.07	16.7858
1972.05	17.7482
1973.04	16.7803
1974.02	18.6905
1975.01	20.6135
1975.99	17.7454
1976.97	18.7035
1977.95	19.6517
1978.94	22.5251
1979.92	18.6903
1980.9	20.5956
1981.88	17.7178
1982.87	21.5299
1983.85	20.5638
1984.83	16.7275
1985.81	16.7308
1986.79	16.7473
1987.77	20.3514
1988.75	17.8464
1989.73	18.9501
1990.72	18.3539
1991.7	19.5172
1992.68	18.6435
1993.66	17.8617
1994.63	16.6304
1995.61	18.8389
1996.59	18.181
1997.57	17.4877
1998.55	15.4203
1999.53	16.7151
2000.51	17.2344
2001.49	17.7566
2002.47	15.0167
2003.45	18.4407
2004.42	16.5387
2005.4	17.3652
2006.38	17.1928
2007.36	19.7153
2008.31	17.4583
2009.3	18.3812
2010.29	16.4828
2011.28	17.4228
2012.27	16.4765
2013.26	18.3342
2014.24	19.2398
2015.23	18.3069
2016.22	20.2058
2017.21	18.3188
2018.2	19.2294
2019.18	17.3311
2020.17	17.3263
2021.16	17.3281
2022.15	15.447
2023.14	15.432
2024.12	15.4167
2025.11	17.2632
2026.1	17.2633
2027.08	17.3106
2028.07	19.1061
2029.06	15.4472
2030.04	17.2517
2031.03	18.1944
2032.01	16.3405
2033	17.2945
2033.98	21.0121
2034.97	15.4058
2035.95	15.4302
2036.94	18.2334
2037.92	19.1602
2038.91	18.2136
2039.89	13.5303
2040.87	18.1801
2041.86	16.3092
2042.84	19.1021
2043.83	19.1261
2044.81	14.4346
2045.79	15.4442
2046.78	19.1349
2047.76	20.0431
2048.74	18.1881
2049.72	18.2096
2050.71	15.4139
2051.69	19.1424
2052.67	15.4151
2053.65	20.1093
2054.63	19.1754
2055.62	15.4266
2056.6	20.0964
2057.58	18.235
2058.56	19.1869
2059.54	18.2557
2060.52	18.2519
2061.5	15.4487
2062.48	16.3916
2063.46	16.4015
2064.44	17.3468
2065.42	17.366
2066.4	17.3748
2067.38	18.3235
2068.36	17.3923
2069.34	15.497
2070.31	16.4534
2071.29	17.42
2072.27	16.4779
2073.25	16.4767
2074.23	18.368
2075.21	18.3985
2076.18	20.2967
2077.16	16.5039
2078.14	19.3403
2079.12	15.582
2080.09	19.3724
2081.07	15.5896
2082.05	19.3714
2083.02	20.3167
2084	18.4265
2084.98	18.4278
2085.95	16.5499
2086.93	16.5602
2087.9	18.4554
2088.88	16.5683
2089.85	16.578
2090.83	17.5326
2091.8	15.6535
2092.78	18.5221
2093.75	16.6373
2094.73	19.4877
2095.7	19.4762
2096.68	14.7215
2097.65	18.5113
2098.62	16.6092
2099.6	18.5058
2100.57	18.5147
2101.54	18.5214
2102.52	17.567
2103.49	13.7639
2104.46	18.5183
2105.44	19.4827
2106.41	17.5876
2107.38	17.5838
2108.35	17.5662
2109.32	16.6244
2110.3	19.4747
2111.27	17.5707
2112.24	17.5705
2113.21	16.6324
2114.18	15.6806
2115.15	17.58
2116.12	17.5701
2117.09	16.6187
2118.06	18.5043
2119.03	20.3831
2120	16.5817
2120.97	15.6431
2121.94	17.5546
2122.91	17.5631
2123.88	20.4039
2124.85	17.5287
2125.82	17.5079
2126.79	19.3845
2127.76	17.4881
2128.72	16.5414
2129.69	15.5926
2130.66	18.4209
2131.63	18.4111
2132.6	21.2311
2133.56	18.4021
2134.53	17.4588
2135.5	17.4523
2136.47	16.4981
2137.43	21.2207
2138.4	20.27
2139.37	18.3771
2140.33	17.4252
2141.3	18.3603
2142.26	19.3013
2143.23	17.3763
2144.19	20.2218
2145.16	17.3952
2146.13	20.2097
2147.09	17.3817
2148.06	20.1911
2149.02	19.2372
2149.98	18.2789
2150.95	16.4069
2151.91	17.3522
2152.88	15.4665
2153.84	16.3937
2154.8	16.367
2155.77	20.0871
2156.73	17.2818
2157.69	19.1611
2158.66	15.4206
2159.62	19.1444
2160.58	18.1969
2161.54	15.3931
2162.51	16.3242
2163.47	19.114
2164.43	14.441
2165.39	18.1713
2166.35	15.3698
2167.32	20.0092
2168.28	16.2691
2169.24	18.1417
2170.2	13.5038
2171.16	19.0754
2172.12	17.1907
2173.08	18.1171
2174.04	15.3351
2175	16.2632
2175.96	16.2592
2176.92	17.1856
2177.88	17.184
2178.84	20.8909
2179.8	18.1058
2180.76	17.1741
2181.72	17.168
2182.68	18.0866
2183.63	16.2172
2184.59	20.8503
2185.55	19.9331
2186.51	19.9526
2187.47	18.1116
2188.43	19.9551
2189.38	17.1516
2190.34	14.3701
2191.3	19.0099
2192.25	18.0893
2193.21	16.2465
2194.17	14.4103
2195.12	18.1207
2196.08	18.0993
2197.04	19.9411
2197.99	19.0222
2198.95	16.2582
2199.9	20.9399
2200.86	20.0375
2201.81	17.152
2202.77	19.9941
2203.72	17.2505
2204.68	18.1547
2205.63	17.2004
2206.59	14.4106
2207.54	17.2134
2208.49	17.2264
2209.45	18.1602
2210.4	17.2378
2211.36	17.2505
2212.31	17.2566
2213.26	17.2477
2214.22	12.6
2215.17	15.405
2216.12	18.2059
2217.07	19.1392
2218.03	18.2073
2218.98	20.0876
2219.93	15.4208
2220.88	18.2168
2221.83	18.2028
2222.78	15.4083
2223.74	21.0337
2224.69	17.3115
2225.64	19.2022
2226.59	17.3428
2227.54	16.4106
2228.49	17.344
2229.44	18.2896
2230.39	17.3662
2231.34	16.4425
2232.29	20.2171
2233.24	20.2328
2234.19	19.2939
2235.14	16.4555
2236.09	20.2214
2237.04	17.4102
2237.98	16.4937
2238.93	16.5102
2239.88	21.2118
2240.83	15.5679
2241.78	17.4606
2242.73	17.4646
2243.67	19.3456
2244.62	15.5859
2245.57	16.5474
2246.52	15.612
2247.46	18.4559
2248.41	16.5595
2249.36	17.51
2250.3	14.6625
2251.25	17.4903
2252.2	17.5001
2253.14	17.5279
2254.09	15.6449
2255.03	17.5411
2255.98	17.5497
2256.92	16.6126
2257.87	18.5184
2258.81	15.6772
2259.76	20.4365
2260.7	18.5489
2261.65	16.6532
2262.59	16.6651
2263.54	15.7343
2264.48	18.6189
2265.42	17.6723
2266.37	16.7041
2267.31	17.6467
2268.26	16.6868
2269.2	13.8394
2270.14	18.6335
2271.08	17.6901
2272.03	18.6552
2272.97	15.789
2273.91	17.707
2274.85	17.7118
2275.79	16.7622
2276.74	17.7367
2277.68	16.804
2278.62	17.768
2279.56	15.8314
2280.5	17.7361
2281.44	16.7745
2282.38	19.6638
2283.32	16.8103
2284.26	15.8704
2285.2	17.804
2286.14	15.8712
2287.08	18.7796
2288.02	17.8196
2288.96	18.7639
2289.9	17.7847
2290.84	16.8318
2291.78	15.8847
2292.72	13.0078
2293.66	15.9023
2294.6	19.7459
2295.54	18.7729
2296.47	14.9135
2297.41	20.7049
2298.35	21.6881
2299.29	17.8459
2300.23	16.8835
2301.16	15.9267
2302.1	15.9244
2303.04	15.9236
2303.97	15.9314
2304.91	14.9746
2305.85	19.8133
2306.78	19.814
2307.72	17.8743
2308.65	19.8099
2309.59	19.8294
2310.53	17.8947
2311.46	19.7933
2312.4	19.7801
2313.33	15.9342
2314.27	16.9223
2315.2	15.9548
2316.14	16.8999
2317.07	16.8997
2318	16.8989
2318.94	16.8888
2319.87	15.9218
2320.81	17.8597
2321.74	23.6766
2322.67	18.8517
2323.61	20.7905
2324.54	25.6087
2325.47	23.6531
2326.41	33.2792
2327.34	100.727
2328.27	72.7739
2329.2	33.2293
2330.13	22.6333
2331.07	17.8199
2332	17.8186
2332.93	18.7719
2333.86	13.9516
2334.79	19.7142
2335.72	18.7532
2336.66	18.7487
2337.59	17.7831
2338.52	16.8208
2339.45	19.7027
2340.38	20.6496
2341.31	20.6234
2342.24	19.6525
2343.17	18.6921
2344.1	15.8179
2345.02	16.7705
2345.95	19.6319
2346.88	15.7972
2347.81	19.5619
2348.74	19.5315
2349.67	19.3933
2350.6	18.1736
2351.53	18.4305
2352.45	20.023
2353.38	17.9309
2354.31	17.7259
2355.24	16.2658
2356.17	16.8989
2357.09	18.2438
2358.02	16.189
2358.95	16.0337
2359.87	16.0732
2360.8	20.0198
2361.73	15.752
2362.65	17.7903
2363.58	15.0222
2364.5	17.9197
2365.43	16.8967
2366.36	14.6877
2367.28	15.668
2368.2	17.8254
2368.98	15.5721
2369.92	16.4999
2370.86	15.5448
2371.79	19.303
2372.73	18.3507
2373.67	18.3416
2374.6	16.4487
2375.54	15.4994
2376.48	19.2468
2377.41	16.4229
2378.35	18.2859
2379.28	18.2646
2380.22	19.1916
2381.15	16.3811
2382.09	18.2519
2383.02	16.3758
2383.96	15.439
2384.89	20.111
2385.83	13.551
2386.76	16.3359
2387.69	18.1906
2388.63	21.9184
2389.56	18.1836
2390.5	17.2524
2391.43	17.2545
2392.36	19.1128
2393.3	17.2218
2394.23	19.0685
2395.16	16.2836
2396.09	17.2634
2397.02	17.2537
2397.96	15.3882
2398.89	17.2521
2399.82	15.3882