File: Data/3-Raman/raw/bu19(2)w-a-ff1-fi04-v_1800 (450-850nm)_532nm_edge_100%_x100_vis_lwd_h100um_30sx2_01.txt
#Acq. time (s)=	30
#Accumulations=	2
#Range (cm-¹)=	1200...2365
#Windows=	3
#Auto scanning=	Off
#Autofocus=	Off
#Macrospot=	Off
#AutoExposure=	Off
#Spike filter=	Multiple accum.
#Delay time (s)=	2
#Binning=	1
#Readout mode=	Signal
#DeNoise=	Off
#ICS correction=	On
#Dark correction=	Off
#Inst. Process=	Off
#Detector Gain=	Best Dynamic
#Detector ADC=	50 kHz HS
#Detector temperature (°C)=	-60.09
#Instrument=	LabRAM HR Evol
#Detector=	SIN-EM FIVIS
#Objective=	x100_VIS_LWD
#Grating=	1800 (450-850nm)
#ND Filter=	100%
#Laser=	532nm_Edge
#Hole=	100.021
#Temperature=	0
#Range=	Visible
#StageXY=	75x50mm Scan+
#StageZ=	Z motor
#X (µm)=	0
#Y (µm)=	0
#Z (µm)=	-14.5
#Full time(mm:ss)=	3:20
#Project=	21_11_26
#Sample=	BU19(2)w
#Site=
#Title=	BU19(2)w-A-FF1-FI04-V_1800 (450-850nm)_532nm_Edge_100%_x100_VIS_LWD_H100um_30sX2
#Remark=
#Date=	26.11.2021 13:26
#Acquired=	26.11.2021 13:26:35
1202.72	409.197
1203.84	384.619
1204.95	398.319
1206.06	421.355
1207.17	380.908
1208.28	379.436
1209.39	407.909
1210.5	379.931
1211.61	391.09
1212.72	393.753
1213.83	388.063
1214.94	376.303
1216.05	390.069
1217.16	401.194
1218.27	386.939
1219.38	380.328
1220.49	381.221
1221.6	404.416
1222.71	403.879
1223.81	407.357
1224.92	393.163
1226.03	397.407
1227.14	381.493
1228.25	396.428
1229.35	399.69
1230.46	400.767
1231.57	388.084
1232.67	402.792
1233.78	389.049
1234.89	386.043
1235.99	401.986
1237.1	390.331
1238.2	390.88
1239.31	415.583
1240.41	399.713
1241.52	393.463
1242.62	391.217
1243.73	396.58
1244.83	393.429
1245.94	388.876
1247.04	403.312
1248.14	404.259
1249.25	394.617
1250.35	398.79
1251.45	397.386
1252.56	410.672
1253.66	385.34
1254.76	397.04
1255.87	396.056
1256.97	401.361
1258.07	425.28
1259.17	425.059
1260.27	408.62
1261.37	448.851
1262.48	468.643
1263.58	510.141
1264.68	491.888
1265.78	441.248
1266.88	411.99
1267.98	420.757
1269.08	401.411
1270.18	397.219
1271.28	412.543
1272.38	409.443
1273.47	426.692
1274.57	416.609
1275.67	433.439
1276.77	424.318
1277.87	432.018
1278.97	437.667
1280.07	467.199
1281.16	532.42
1282.26	849.61
1283.36	1800.35
1284.45	2008.26
1285.55	695.259
1286.65	500.356
1287.75	458.043
1288.84	440.028
1289.94	438.177
1291.03	425.653
1292.13	421.387
1293.22	409.774
1294.32	414.488
1295.42	417.745
1296.51	419.676
1297.61	415.385
1298.7	402.471
1299.79	417.03
1300.89	398.146
1301.98	411.927
1303.08	397.243
1304.17	398.143
1305.26	403.377
1306.35	394.586
1307.45	415.599
1308.54	389.254
1309.63	410.469
1310.73	384.147
1311.82	411.642
1312.91	395.995
1314	393.753
1315.09	395.896
1316.18	406.658
1317.28	404.473
1318.37	402.481
1319.46	403.552
1320.55	389.818
1321.64	377.929
1322.73	412.389
1323.82	412.238
1324.91	395.384
1326	400.386
1327.09	411.296
1328.18	411.991
1329.27	413.533
1330.35	390.264
1331.44	401.526
1332.53	420.942
1333.62	399.359
1334.71	429.355
1335.79	412.21
1336.88	399.368
1337.97	409.685
1339.06	411.454
1340.14	405.149
1341.23	406.223
1342.32	417.579
1343.4	403.612
1344.49	408.799
1345.58	406.509
1346.66	412.201
1347.75	408.573
1348.83	415.673
1349.92	393.501
1351	407.758
1352.09	413.69
1353.17	410.821
1354.25	402.894
1355.34	418.582
1356.42	406.063
1357.51	411.051
1358.59	413.899
1359.67	414.641
1360.76	401.807
1361.84	420.319
1362.92	423.263
1364	431.683
1365.09	420.261
1366.17	414.722
1367.25	422.536
1368.33	428.716
1369.41	510.506
1370.5	426.636
1371.58	436.599
1372.66	427.711
1373.74	442.871
1374.82	444.785
1375.9	441.675
1376.98	443.525
1378.06	449.538
1379.14	457.474
1380.22	475.784
1381.3	473.772
1382.38	470.189
1383.46	508.49
1384.54	526.649
1385.61	817.556
1386.69	2338.27
1387.77	3854.31
1388.85	809.255
1389.93	543.908
1391	490.791
1392.08	457.606
1393.16	459.292
1394.23	424.318
1395.31	428.383
1396.39	457.172
1397.46	421.127
1398.54	439.444
1399.62	443.716
1400.69	431.58
1401.77	437.92
1402.84	413.962
1403.92	444.117
1404.99	432.518
1406.07	445.564
1407.14	472.082
1408.22	574.742
1409.29	617.98
1410.37	468.35
1411.44	444.309
1412.51	419.632
1413.59	419.745
1414.66	426.431
1415.73	436.888
1416.81	421.618
1417.88	440.305
1418.95	409.552
1420.02	400.203
1421.1	422.471
1422.17	407.095
1423.24	423.371
1424.31	429.163
1425.38	413.795
1426.45	419.036
1427.52	426.821
1428.59	411.058
1429.67	431.658
1430.74	406.401
1431.81	423.338
1432.87	402.588
1433.95	410.187
1435.01	405.203
1436.08	408.272
1437.15	421.463
1438.22	413.159
1439.29	410.225
1440.36	402.321
1441.43	403.455
1442.49	413.664
1443.56	423.892
1444.63	403.302
1445.7	411.822
1446.77	407.585
1447.83	409.484
1448.9	426.017
1449.97	402.365
1451.03	396.021
1452.1	402.029
1453.17	414.305
1454.23	400.023
1455.3	404.092
1456.36	412.384
1457.43	414.265
1458.49	400.879
1459.56	417.34
1460.62	406.01
1461.69	393.543
1462.75	404.528
1463.82	414.393
1464.88	411.776
1465.94	403.434
1467.01	416.569
1468.07	402.216
1469.13	403.18
1470.2	406.997
1471.26	403.732
1472.32	408.605
1473.39	397.336
1474.45	400.196
1475.51	407.386
1476.57	404.19
1477.63	415.177
1478.69	415.023
1479.76	391.385
1480.82	414.31
1481.88	396.91
1482.94	397.186
1484	396.244
1485.06	417.726
1486.12	401.392
1487.18	395.356
1488.24	415.407
1489.3	424.178
1490.36	403.828
1491.42	417.768
1492.48	394.471
1493.53	399.476
1494.59	398.451
1495.65	423.549
1496.71	411.025
1497.77	405.862
1498.82	416.941
1499.88	414.006
1500.94	425.141
1502	407.816
1503.05	408.67
1504.11	419.556
1505.17	398.419
1506.22	422.244
1507.28	418.247
1508.34	415.225
1509.39	416.237
1510.45	428.393
1511.5	417.94
1512.56	412.106
1513.61	419.682
1514.67	415.927
1515.72	408.542
1516.78	421.206
1517.83	415.122
1518.88	410.261
1519.94	406.358
1520.99	421.352
1522.05	430.457
1523.1	422.249
1524.15	417.766
1525.2	420.589
1526.26	415.752
1527.31	407.949
1528.36	428.838
1529.41	425.674
1530.47	417.538
1531.52	413.799
1532.57	416.74
1533.62	423.193
1534.67	405.201
1535.72	410.025
1536.77	431.492
1537.82	412.025
1538.87	420.77
1539.92	419.384
1540.97	416.054
1542.02	423.81
1543.07	411.38
1544.12	395.912
1545.17	414.164
1546.22	397.531
1547.27	423.66
1548.32	422.441
1549.37	407.184
1550.42	418.333
1551.46	411.511
1552.51	423.569
1553.56	407.203
1554.61	417.932
1555.65	418.563
1556.7	409.51
1557.75	422.592
1558.79	425.254
1559.84	438.771
1560.89	412.563
1561.93	413.634
1562.98	423.851
1564.02	410.768
1565.07	430.103
1566.11	408.634
1567.16	416.312
1568.2	430.622
1569.25	424.72
1570.29	421.508
1571.34	419.494
1572.38	413.305
1573.43	426.028
1574.47	425.979
1575.51	437.374
1576.56	419.443
1577.6	424.937
1578.64	426.441
1579.69	429.398
1580.73	424.532
1581.77	427.329
1582.81	404.172
1583.85	438.951
1584.9	433.988
1585.94	442.925
1586.98	430.643
1588.02	426.497
1589.06	417.682
1590.1	417.834
1591.14	416.952
1592.18	433.788
1593.22	429.402
1594.26	410.903
1595.3	413.954
1596.34	419.766
1597.38	410.868
1598.42	415.851
1599.46	407.541
1600.5	419.164
1601.54	408.799
1602.58	425.214
1603.62	432.752
1604.66	431.664
1605.69	419.834
1606.73	416.063
1607.77	404.269
1608.81	419.945
1609.84	411.189
1610.88	428.5
1611.92	424.768
1612.95	414.526
1613.99	435.738
1615.03	416.009
1616.06	430.65
1617.1	425.044
1618.13	424.475
1619.17	422.134
1620.2	428.271
1621.24	426.093
1622.27	426.415
1623.31	424.721
1624.34	428.718
1625.38	421.985
1626.41	425.035
1627.45	427.586
1628.48	424.501
1629.51	428.197
1630.55	429.715
1631.53	422.366
1632.57	426.546
1633.62	416.697
1634.66	421.768
1635.71	422.759
1636.75	436.41
1637.8	432.263
1638.84	427.251
1639.89	435.167
1640.93	409.685
1641.98	421.54
1643.02	431.336
1644.06	435.243
1645.11	440.015
1646.15	432.318
1647.19	419.401
1648.24	430.123
1649.28	422.685
1650.32	441.416
1651.37	429.057
1652.41	423.27
1653.45	438.976
1654.49	431.23
1655.53	429.491
1656.57	426.038
1657.62	423.128
1658.66	426.964
1659.7	444.505
1660.74	427.717
1661.78	448.793
1662.82	419.714
1663.86	422.771
1664.9	435.364
1665.94	413.139
1666.98	432.473
1668.02	428.33
1669.06	444.252
1670.1	429.806
1671.14	434.125
1672.18	442.984
1673.21	419.35
1674.25	439.27
1675.29	429.674
1676.33	416.954
1677.37	430.893
1678.4	427.758
1679.44	415.653
1680.48	413.565
1681.52	429.27
1682.55	425.35
1683.59	445.122
1684.63	422.337
1685.66	432.171
1686.7	418.431
1687.73	443.273
1688.77	432.259
1689.81	421.139
1690.84	421.072
1691.88	415.35
1692.91	434.091
1693.95	429.759
1694.98	450.161
1696.01	420.715
1697.05	445.515
1698.08	436.335
1699.12	438.043
1700.15	436.099
1701.18	439.961
1702.22	423.062
1703.25	419.891
1704.28	427.684
1705.32	446.481
1706.35	434.633
1707.38	436.224
1708.41	430.874
1709.44	442.132
1710.48	429.349
1711.51	433.457
1712.54	439.401
1713.57	435.84
1714.6	437.377
1715.63	422.763
1716.66	434.517
1717.69	431.079
1718.72	440.15
1719.75	440.996
1720.78	423.491
1721.81	434.837
1722.84	433.476
1723.87	429.31
1724.9	428.244
1725.93	439.323
1726.96	436.293
1727.99	426.517
1729.02	429.578
1730.05	415.661
1731.07	424.144
1732.1	437.249
1733.13	450.631
1734.16	424.988
1735.18	449.544
1736.21	430.863
1737.24	430.703
1738.26	436.261
1739.29	434
1740.32	437.211
1741.34	441.536
1742.37	454.673
1743.4	430.644
1744.42	438.12
1745.45	427.548
1746.47	443.68
1747.5	424.142
1748.52	426.791
1749.55	431.705
1750.57	435.919
1751.6	447.621
1752.62	431.002
1753.64	440.219
1754.67	427.523
1755.69	444.49
1756.71	423.186
1757.74	440.855
1758.76	440.089
1759.78	427.802
1760.81	441.046
1761.83	436.996
1762.85	437.957
1763.87	445.658
1764.89	443.18
1765.92	429.141
1766.94	462.47
1767.96	440.482
1768.98	439.385
1770	434.833
1771.02	440.805
1772.04	451.67
1773.06	441.507
1774.08	441.742
1775.1	436.214
1776.12	454.789
1777.14	443.39
1778.16	443.151
1779.18	435.209
1780.2	432.321
1781.22	444.883
1782.24	436.485
1783.26	435.865
1784.28	439.945
1785.29	446.009
1786.31	444.981
1787.33	435.692
1788.35	434.645
1789.37	438.196
1790.38	434.793
1791.4	440.531
1792.42	443.104
1793.43	426.04
1794.45	437.671
1795.47	441.937
1796.48	429.03
1797.5	431.327
1798.51	430.624
1799.53	434.472
1800.55	429.419
1801.56	437.018
1802.58	453.48
1803.59	443.269
1804.61	436.778
1805.62	442.964
1806.64	441.431
1807.65	430.026
1808.66	436.841
1809.68	437.91
1810.69	457.292
1811.7	421.604
1812.72	438.103
1813.73	423.902
1814.74	455.229
1815.76	435.323
1816.77	445.127
1817.78	428.483
1818.79	439.223
1819.8	430.697
1820.82	439.64
1821.83	433.127
1822.84	435.286
1823.85	448.881
1824.86	426.677
1825.87	427.842
1826.88	429.848
1827.89	430.015
1828.9	435.855
1829.91	431.888
1830.92	429.826
1831.93	431.969
1832.94	436.142
1833.95	438.242
1834.96	437.995
1835.97	438.347
1836.98	438.035
1837.99	433.816
1839	450.275
1840	444.144
1841.01	446.23
1842.02	424.23
1843.03	427.771
1844.04	431.669
1845.04	445.229
1846.05	431.89
1847.06	434.278
1848.07	456.923
1849.07	432.979
1850.08	429.807
1851.09	431.252
1852.09	432.936
1853.1	431.992
1854.1	431.863
1855.11	432.419
1856.11	439.716
1857.12	406.169
1858.12	442.443
1859.13	429.691
1860.13	424.656
1861.14	431.57
1862.14	431.843
1863.15	428.737
1864.15	434.142
1865.15	439.593
1866.16	430.503
1867.16	429.833
1868.16	439.802
1869.17	437.892
1870.17	411.239
1871.17	425.468
1872.17	427.252
1873.18	446.027
1874.18	424.062
1875.18	437.944
1876.18	426.94
1877.18	438.834
1878.18	448.647
1879.19	436.171
1880.19	440.34
1881.19	416.661
1882.19	440.685
1883.19	436.991
1884.19	433.747
1885.19	434.005
1886.19	443.085
1887.19	415.694
1888.19	435.15
1889.19	426.142
1890.19	435.361
1891.19	425.305
1892.18	432.79
1893.18	444.881
1894.18	424.52
1895.18	420.612
1896.18	434.883
1897.18	427.681
1898.17	432.537
1899.17	437.973
1900.17	445.238
1901.16	444.328
1902.16	410.858
1903.16	444.912
1904.16	431.626
1905.15	420.315
1906.15	424.894
1907.14	419.948
1908.14	436.009
1909.14	429.658
1910.13	445.131
1911.13	436.285
1912.12	441.16
1913.12	437.365
1914.11	437.611
1915.11	446.558
1916.1	436.385
1917.1	426.786
1918.09	431.339
1919.08	437.317
1920.08	426.617
1921.07	434.297
1922.06	431.846
1923.06	424.264
1924.05	430.751
1925.04	423.978
1926.04	427.14
1927.03	445.634
1928.02	421.324
1929.01	448.071
1930	431.403
1931	432.845
1931.99	431.895
1932.98	435.493
1933.97	426.119
1934.96	436.871
1935.95	445.472
1936.94	442.243
1937.93	452.385
1938.92	438.126
1939.91	440.316
1940.9	425.403
1941.89	441.09
1942.88	417.452
1943.87	431.571
1944.86	433.822
1945.85	436.185
1946.84	422.166
1947.83	445.097
1948.82	439.351
1949.8	412.878
1950.79	431.683
1951.78	446.765
1952.77	422.191
1953.76	443.415
1954.74	432.965
1955.73	437.581
1956.72	428.745
1957.7	436.865
1958.69	429.435
1959.68	421.656
1960.66	420.533
1961.65	430.852
1962.63	428.986
1963.62	434.856
1964.61	433.113
1965.59	426.387
1966.58	422.809
1967.56	444.192
1968.55	426.047
1969.53	436.438
1970.52	449.453
1971.5	420.463
1972.48	424.34
1973.47	442.517
1974.45	435.582
1975.44	429.908
1976.42	428.248
1977.4	433.118
1978.39	431.034
1979.37	438.614
1980.35	433.903
1981.33	424.142
1982.31	428.826
1983.3	422.876
1984.28	435.074
1985.26	435.88
1986.24	429.097
1987.22	422.591
1988.21	451.958
1989.19	455.663
1990.17	436.624
1991.15	438.463
1992.13	449.842
1993.11	444.177
1994.09	434.368
1995.07	449.625
1996.05	437.896
1997.03	442.666
1998.01	451.929
1998.99	436.07
1999.97	438.17
2000.95	446.098
2001.92	440.517
2002.9	448.27
2003.88	440.144
2004.86	436.115
2005.84	449.806
2006.81	441.323
2007.79	443.527
2008.77	437.117
2009.75	435.704
2010.73	427.95
2011.7	445.894
2012.68	447.278
2013.67	447.716
2014.66	424.45
2015.64	441.177
2016.63	431.997
2017.62	433.246
2018.61	425.158
2019.6	429.207
2020.58	430.902
2021.57	432.803
2022.56	438.312
2023.55	437.908
2024.54	439.409
2025.52	428.56
2026.51	423.55
2027.5	434.055
2028.48	448.5
2029.47	439.885
2030.45	428.271
2031.44	435.946
2032.43	422.971
2033.41	418.868
2034.4	419.869
2035.38	424.825
2036.37	422.968
2037.35	421.92
2038.34	440.508
2039.32	432.768
2040.31	423.071
2041.29	446.904
2042.27	421.543
2043.26	412.061
2044.24	425.629
2045.23	412.336
2046.21	417.892
2047.19	433.377
2048.17	422.576
2049.16	411.513
2050.14	412.001
2051.12	440.366
2052.11	426.118
2053.09	416.005
2054.07	431.447
2055.05	419.448
2056.03	422.998
2057.01	419.137
2058	433.281
2058.98	431.77
2059.96	431.999
2060.94	428.11
2061.92	430.178
2062.9	439.662
2063.88	410.909
2064.86	428.903
2065.84	418.08
2066.82	432.448
2067.8	424.204
2068.78	415.026
2069.76	413.048
2070.73	422.42
2071.71	409.555
2072.69	413.927
2073.67	431.756
2074.65	413.047
2075.63	443.763
2076.6	422.567
2077.58	416.706
2078.56	406.243
2079.54	429.144
2080.51	427.712
2081.49	405.983
2082.47	423.951
2083.45	427.806
2084.42	422.122
2085.4	421.212
2086.37	432.713
2087.35	426.448
2088.32	411.447
2089.3	428.574
2090.28	415.629
2091.25	414.836
2092.23	410.435
2093.2	427.123
2094.18	425.656
2095.15	409.595
2096.13	428.377
2097.1	416.876
2098.07	425.172
2099.05	415.589
2100.02	417.439
2101	411.842
2101.97	418.77
2102.94	421.601
2103.92	413.803
2104.89	417.701
2105.86	391.406
2106.83	413.467
2107.8	418.26
2108.78	412.151
2109.75	424.514
2110.72	406.573
2111.69	419.853
2112.66	389.349
2113.63	403.841
2114.61	420.075
2115.58	406.782
2116.55	404.709
2117.52	396.021
2118.49	408.219
2119.46	402.128
2120.43	405.626
2121.4	416.163
2122.37	408.969
2123.34	394.99
2124.31	423.453
2125.28	391.621
2126.25	401.495
2127.21	397.358
2128.18	403.823
2129.15	398.098
2130.12	399.906
2131.09	398.859
2132.06	412.805
2133.02	410.681
2133.99	407.85
2134.96	417.326
2135.93	406.871
2136.89	421.583
2137.86	413.202
2138.83	423.433
2139.79	412.236
2140.76	407.189
2141.73	406.155
2142.69	407.838
2143.66	402.519
2144.62	397.023
2145.59	423.383
2146.55	416.738
2147.52	401.544
2148.48	412.632
2149.45	424.592
2150.42	408.164
2151.38	413.701
2152.34	411.109
2153.31	414.732
2154.27	403.284
2155.24	395.231
2156.2	393.776
2157.16	399.246
2158.13	394.749
2159.09	398.561
2160.05	395.536
2161.01	398.913
2161.98	410.91
2162.94	401.571
2163.9	397.676
2164.86	403.924
2165.83	397.409
2166.79	415.042
2167.75	407.298
2168.71	399.298
2169.67	404.111
2170.63	394.39
2171.59	410.121
2172.56	397.357
2173.51	404.659
2174.48	414.08
2175.44	403.883
2176.4	397.302
2177.36	395.335
2178.32	396.301
2179.28	391.432
2180.23	398.9
2181.19	409.986
2182.15	399.655
2183.11	410.648
2184.07	412.129
2185.03	384.212
2185.99	408.472
2186.95	398.617
2187.9	390.718
2188.86	394.279
2189.82	400.36
2190.78	393.71
2191.73	384.543
2192.69	388.401
2193.65	385.866
2194.6	405.973
2195.56	398.512
2196.52	396.264
2197.47	391.267
2198.43	392.206
2199.38	395.459
2200.34	406.281
2201.3	400.478
2202.25	396.365
2203.21	392.42
2204.16	396.669
2205.12	399.68
2206.07	387.57
2207.03	386.622
2207.98	391.525
2208.93	402.105
2209.89	392.006
2210.84	392.133
2211.8	390.541
2212.75	405.744
2213.7	396.261
2214.66	388.077
2215.61	371.544
2216.56	382.788
2217.51	403.299
2218.47	388.406
2219.42	389.538
2220.37	380.415
2221.32	408.386
2222.27	390.287
2223.23	387.527
2224.18	396.288
2225.13	384.571
2226.08	401.825
2227.03	410.602
2227.98	407.095
2228.93	391.074
2229.88	380.802
2230.83	387.727
2231.78	387.157
2232.73	380.903
2233.68	393.436
2234.63	395.492
2235.58	389.573
2236.53	368.847
2237.48	380.3
2238.43	392.162
2239.38	384.169
2240.33	395.336
2241.27	387.042
2242.22	383.392
2243.17	374.103
2244.12	392.845
2245.07	384.545
2246.01	382.197
2246.96	383.426
2247.91	392.138
2248.85	384.512
2249.8	397.788
2250.75	374.069
2251.69	383.251
2252.64	399.443
2253.59	375.421
2254.53	385.266
2255.48	381.534
2256.42	402.518
2257.37	380.041
2258.32	364.104
2259.26	365.201
2260.2	374.888
2261.15	383.638
2262.1	366.777
2263.04	411.736
2263.98	388.404
2264.93	363.206
2265.87	383.527
2266.81	394.813
2267.76	380.21
2268.7	391.436
2269.65	374.538
2270.59	388.405
2271.53	362.892
2272.47	361.204
2273.42	387.124
2274.36	370.957
2275.3	386.379
2276.24	392.237
2277.18	386.867
2278.13	362.449
2279.07	382.882
2280.01	371.101
2280.95	370.749
2281.89	385.928
2282.83	372.727
2283.77	380.859
2284.71	379.582
2285.65	370.228
2286.59	375.795
2287.54	363.714
2288.47	382.207
2289.41	374.222
2290.35	372.797
2291.29	370.92
2292.23	367.464
2293.17	378.387
2294.11	380.524
2295.05	381.299
2295.99	370.51
2296.93	369.26
2297.86	357.001
2298.8	382.432
2299.74	363.489
2300.68	374.142
2301.61	371.466
2302.55	388.846
2303.49	373.376
2304.43	363.843
2305.36	354.425
2306.3	362.308
2307.24	370.123
2308.17	378.716
2309.11	365.157
2310.04	368.404
2310.98	384.016
2311.92	352.523
2312.85	377.3
2313.79	374.527
2314.72	370.199
2315.66	360.777
2316.59	365.163
2317.52	368.896
2318.46	374.769
2319.39	381.306
2320.33	356.109
2321.26	358.152
2322.2	368.14
2323.13	359.69
2324.06	378.17
2325	380.971
2325.93	389.256
2326.86	398.592
2327.79	492.76
2328.73	470.496
2329.66	374.848
2330.59	390.245
2331.52	378.648
2332.46	355.65
2333.39	363.146
2334.32	358.177
2335.25	360.83
2336.18	361.813
2337.11	359.815
2338.04	356.868
2338.97	378.919
2339.91	367.41
2340.84	372.987
2341.77	361.034
2342.7	352.132
2343.63	339.62
2344.56	353.054
2345.49	366.428
2346.41	354.656
2347.34	348.83
2348.27	341.18
2349.2	372.831
2350.13	356.019
2351.06	340.059
2351.99	355.778
2352.91	355.25
2353.84	348.076
2354.77	358.581
2355.7	350.994
2356.63	369.8
2357.55	360.797
2358.48	345.402
2359.41	358.553
2360.33	347.919
2361.26	338.121
2362.19	354.849
2363.11	359.247
2364.04	357.165
2364.97	356.03