File: Data/3-Raman/raw/bu19w-e-ff11b-fi06-v_1800 (450-850nm)_532nm_edge_100%_x100_vis_h50um_30sx2_01.txt
#Acq. time (s)=	30
#Accumulations=	2
#Range (cm-¹)=	1200...2400
#Windows=	4
#Auto scanning=	Off
#Autofocus=	Off
#Macrospot=	Off
#AutoExposure=	Off
#Spike filter=	Multiple accum.
#Delay time (s)=	2
#Binning=	1
#Readout mode=	Signal
#DeNoise=	Off
#ICS correction=	On
#Dark correction=	Off
#Inst. Process=	Off
#Detector Gain=	Best Dynamic
#Detector ADC=	50 kHz HS
#Detector temperature (°C)=	-60.09
#Instrument=	LabRAM HR Evol
#Detector=	SIN-EM FIVIS
#Objective=	x100_VIS
#Grating=	1800 (450-850nm)
#ND Filter=	100%
#Laser=	532nm_Edge
#Hole=	49.98
#Temperature=	0
#Range=	Visible
#StageXY=	75x50mm Scan+
#StageZ=	Z motor
#X (µm)=	0
#Y (µm)=	0
#Z (µm)=	-245.5
#Full time(mm:ss)=	4:27
#Project=	21_11_04
#Sample=	BU19w
#Site=
#Title=	BU19w-E-FF11b-FI06-V_1800 (450-850nm)_532nm_Edge_100%_x100_VIS_H50um_30sX2
#Remark=
#Date=	04.11.2021 18:08
#Acquired=	04.11.2021 18:08:13
1200.19	30.709
1201.3	26.3457
1202.41	26.4062
1203.52	31.7215
1204.63	28.4817
1205.74	29.503
1206.85	32.665
1207.97	26.2169
1209.08	30.4709
1210.19	27.2391
1211.3	31.4682
1212.41	30.3616
1213.52	26.0822
1214.63	26.0836
1215.74	28.1974
1216.85	29.2185
1217.95	27.0662
1219.06	30.2374
1220.17	33.4097
1221.28	30.2099
1222.39	33.3316
1223.5	31.164
1224.61	29.0282
1225.71	35.374
1226.82	31.1293
1227.93	37.3545
1229.03	31.1011
1230.14	33.1785
1231.25	33.1013
1232.35	30.9932
1233.46	30.991
1234.57	33.1085
1235.67	33.1202
1236.78	33.0985
1237.88	30.9527
1238.99	30.9265
1240.1	28.8254
1241.2	31.9681
1242.3	31.9641
1243.41	30.9248
1244.51	27.7748
1245.62	37.1631
1246.72	26.6904
1247.82	35.0398
1248.93	27.7185
1250.03	32.9353
1251.13	28.7295
1252.24	33.928
1253.34	31.8288
1254.44	31.8476
1255.54	32.8934
1256.65	29.7692
1257.75	32.8904
1258.85	30.7907
1259.95	31.8436
1261.05	40.157
1262.15	41.2938
1263.25	38.109
1264.35	38.1516
1265.45	39.1819
1266.55	37.1103
1267.66	35.0609
1268.75	41.3854
1269.85	38.2185
1270.95	40.2872
1272.05	34.0305
1273.15	37.214
1274.25	34.0905
1275.35	39.3478
1276.45	41.4787
1277.54	38.3627
1278.64	36.2909
1279.74	40.4911
1280.84	45.7747
1281.94	73.168
1283.03	137.155
1284.13	121.692
1285.23	53.1664
1286.32	36.3246
1287.42	37.3607
1288.52	32.1017
1289.61	36.3395
1290.71	35.2832
1291.8	30.0166
1292.9	32.1232
1293.99	34.2714
1295.09	31.1314
1296.18	32.2385
1297.28	30.1081
1298.37	33.2634
1299.47	30.0849
1300.56	30.091
1301.65	26.9343
1302.75	30.102
1303.84	27.9826
1304.94	32.1939
1306.03	23.7299
1307.12	27.9505
1308.21	25.841
1309.31	25.8549
1310.4	24.7992
1311.49	31.1398
1312.58	26.9233
1313.67	29.0266
1314.76	27.9808
1315.86	30.1009
1316.95	30.0993
1318.04	24.8265
1319.13	29.0507
1320.22	29.0495
1321.31	25.8554
1322.4	29.0007
1323.49	28.9975
1324.58	28.9981
1325.67	28.9528
1326.76	30.0015
1327.85	30.0501
1328.93	26.9029
1330.02	25.841
1331.11	27.9167
1332.2	29.9846
1333.29	25.7426
1334.37	28.8648
1335.46	27.7947
1336.55	27.7799
1337.64	26.7152
1338.72	27.7478
1339.81	30.8927
1340.9	27.7508
1341.98	26.687
1343.07	26.6693
1344.16	28.7605
1345.24	30.8253
1346.33	31.8255
1347.41	28.6664
1348.5	29.6952
1349.58	25.5087
1350.67	30.6887
1351.75	27.5567
1352.84	27.5861
1353.92	26.5079
1355.01	29.5991
1356.09	29.6044
1357.17	31.6685
1358.26	30.6095
1359.34	34.7374
1360.42	31.5946
1361.5	31.5894
1362.59	32.6147
1363.67	35.7391
1364.75	33.6517
1365.83	32.5866
1366.92	33.5885
1368	35.6639
1369.08	41.8757
1370.16	36.6829
1371.24	43.872
1372.32	41.7532
1373.4	42.7631
1374.48	41.7197
1375.56	57.1771
1376.64	63.2971
1377.72	61.2825
1378.8	62.3718
1379.88	77.7441
1380.96	81.7637
1382.04	90.8675
1383.12	83.5761
1384.2	75.3673
1385.28	87.7737
1386.36	175.133
1387.43	271.36
1388.51	73.3938
1389.59	50.8045
1390.67	47.6573
1391.74	37.3828
1392.82	37.3612
1393.9	37.3492
1394.97	36.3352
1396.05	33.2637
1397.13	35.2891
1398.2	37.3408
1399.28	32.2391
1400.35	33.2791
1401.43	30.2156
1402.5	34.3797
1403.58	28.2209
1404.65	31.2854
1405.73	33.315
1406.8	30.2403
1407.88	38.4512
1408.95	39.4895
1410.03	34.3552
1411.1	30.2251
1412.17	28.1896
1413.25	26.1618
1414.32	27.2061
1415.39	25.1552
1416.47	24.1383
1417.54	26.2027
1418.61	26.207
1419.68	30.3014
1420.75	22.0674
1421.83	27.2191
1422.9	27.294
1423.97	26.1159
1425.04	28.1931
1426.11	25.1261
1427.18	25.0939
1428.25	23.0379
1429.32	28.171
1430.39	23.0741
1431.46	27.1983
1432.53	22.0455
1433.6	26.1123
1434.67	25.1059
1435.74	22.0288
1436.81	25.0947
1437.88	26.1178
1438.95	26.127
1440.01	23.0712
1441.08	16.9188
1442.15	24.0998
1443.22	23.0667
1444.29	26.1515
1445.35	25.1333
1446.42	25.1259
1447.49	15.8902
1448.56	25.1289
1449.62	23.0677
1450.69	25.1093
1451.75	26.1256
1452.82	27.156
1453.89	22.0313
1454.95	24.0786
1456.02	25.1108
1457.08	26.1234
1458.15	25.0986
1459.21	23.0532
1460.28	25.0958
1461.34	20.9878
1462.41	21.9947
1463.47	19.9374
1464.53	24.0695
1465.6	27.0469
1466.66	20.9146
1467.72	21.9313
1468.79	26.006
1469.85	23.9487
1470.91	23.9375
1471.97	18.8376
1473.04	23.9213
1474.1	22.8974
1475.16	22.9001
1476.22	20.856
1477.29	21.8645
1478.34	22.8698
1479.41	24.8846
1480.47	20.8011
1481.53	22.8326
1482.59	26.9058
1483.65	18.783
1484.71	22.7676
1485.77	18.7509
1486.83	22.7991
1487.89	19.7437
1488.95	24.7889
1490.01	18.7149
1491.07	21.7371
1492.12	20.7254
1493.18	23.7549
1494.24	23.7582
1495.3	19.6958
1496.36	22.7107
1497.42	23.7163
1498.47	24.7273
1499.53	21.7057
1500.59	23.7232
1501.64	21.6962
1502.7	22.6929
1503.76	20.6725
1504.81	25.7107
1505.87	23.675
1506.93	23.6804
1507.98	21.6629
1509.04	22.6716
1510.09	20.6551
1511.15	25.662
1512.21	24.6099
1513.26	26.6016
1514.31	24.6073
1515.37	23.5772
1516.42	23.5631
1517.48	24.5679
1518.53	23.5732
1519.58	21.57
1520.64	22.5746
1521.69	21.5699
1522.75	22.5606
1523.8	20.5324
1524.85	21.5319
1525.9	27.56
1526.95	23.552
1528.01	23.5437
1529.06	21.5347
1530.11	22.5345
1531.16	24.5496
1532.21	21.5449
1533.27	19.5606
1534.32	25.5762
1535.37	22.5461
1536.42	24.5197
1537.47	21.504
1538.52	23.4911
1539.57	23.541
1540.62	22.5606
1541.67	24.544
1542.72	24.521
1543.77	25.5024
1544.81	21.5218
1545.86	24.5416
1546.91	24.5491
1547.96	24.5318
1549.01	25.4899
1550.06	24.5717
1551.1	29.6202
1552.15	23.6034
1553.2	27.5864
1554.25	23.5498
1555.3	22.5389
1556.34	25.5427
1557.39	27.547
1558.43	25.5144
1559.48	23.492
1560.53	28.4806
1561.57	23.4992
1562.62	26.5012
1563.66	29.5119
1564.71	26.4898
1565.76	27.4805
1566.8	26.5002
1567.84	26.4947
1568.89	25.4854
1569.93	25.4849
1570.98	30.4761
1572.02	26.4659
1573.07	26.4493
1574.11	26.4604
1575.15	31.4798
1576.2	30.472
1577.24	29.4318
1578.28	25.4218
1579.32	25.4244
1580.37	26.4244
1581.41	30.3934
1582.45	29.3858
1583.49	29.3799
1584.53	28.3896
1585.58	33.3616
1586.62	28.361
1587.66	31.3409
1588.7	26.3787
1589.74	30.3674
1590.78	31.3705
1591.82	33.3454
1592.86	33.3094
1593.9	27.314
1594.94	26.334
1595.98	29.3
1597.02	30.3003
1598.06	31.2832
1599.1	29.2726
1600.14	32.2265
1601.17	29.2161
1602.21	37.1019
1603.25	34.1566
1604.29	34.0308
1605.33	36.3012
1606.37	34.3378
1607.4	36.4618
1608.44	36.2304
1609.48	37.2123
1610.51	34.5665
1611.55	34.3785
1612.59	35.5088
1613.62	38.6837
1614.66	39.5156
1615.7	39.318
1616.73	35.3929
1617.77	37.1568
1618.8	38.8754
1619.84	38.5223
1620.87	39.9518
1621.91	40.7748
1622.94	41.6094
1623.98	37.1106
1625.01	40.3884
1626.04	40.2294
1627.08	39.11
1628.11	35.0601
1629.07	33.9931
1630.12	39.8958
1631.16	36.9456
1632.21	44.8585
1633.25	39.906
1634.3	43.8633
1635.34	40.8977
1636.39	40.8775
1637.43	37.9058
1638.48	40.8505
1639.52	38.8807
1640.57	38.8954
1641.61	41.8395
1642.65	36.9114
1643.7	43.7904
1644.74	38.8649
1645.78	38.8666
1646.83	42.7855
1647.87	43.7641
1648.91	38.887
1649.95	40.8669
1651	40.8947
1652.04	37.9424
1653.08	42.8585
1654.12	40.8995
1655.16	39.9458
1656.21	46.8872
1657.25	41.9432
1658.29	39.9533
1659.33	42.8867
1660.37	38.9542
1661.41	33.0601
1662.45	36.0892
1663.49	40.9315
1664.53	35.0738
1665.57	34.1121
1666.61	39.9126
1667.65	36.9998
1668.69	39.0125
1669.72	34.0724
1670.76	34.1006
1671.8	36.0799
1672.84	37.0708
1673.88	37.0858
1674.92	27.2129
1675.95	28.2058
1676.99	37.1125
1678.03	31.1532
1679.07	32.1266
1680.1	29.1499
1681.14	34.083
1682.18	31.1201
1683.21	29.142
1684.25	30.12
1685.29	34.0673
1686.32	28.1527
1687.36	31.1123
1688.39	31.097
1689.43	32.06
1690.46	27.1325
1691.5	27.1415
1692.53	31.0753
1693.57	30.059
1694.6	25.1184
1695.64	23.1544
1696.67	30.054
1697.7	23.1347
1698.74	25.0909
1699.77	24.108
1700.81	24.1003
1701.84	27.0335
1702.87	23.0914
1703.9	24.0724
1704.94	24.0729
1705.97	23.0805
1707	22.0771
1708.03	24.0093
1709.06	22.0275
1710.1	25.9436
1711.13	23.996
1712.16	25.9437
1713.19	21.9918
1714.22	24.9072
1715.25	21.9847
1716.28	20.02
1717.31	21.9373
1718.34	22.8827
1719.37	18.0108
1720.4	22.8741
1721.43	19.9356
1722.46	22.8301
1723.49	23.7909
1724.52	21.8346
1725.55	18.8979
1726.58	24.7054
1727.6	21.7952
1728.63	19.7855
1729.66	21.7371
1730.69	17.8784
1731.72	18.8442
1732.74	22.6956
1733.77	21.6986
1734.8	18.7813
1735.82	18.7685
1736.85	20.6825
1737.88	18.746
1738.91	22.5693
1739.93	21.5733
1740.96	16.7629
1741.98	17.7121
1743.01	17.7075
1744.03	20.5653
1745.06	16.739
1746.09	22.4623
1747.11	16.7101
1748.13	20.5233
1749.16	15.7573
1750.18	19.5948
1751.21	19.595
1752.23	19.5746
1753.26	17.6508
1754.28	17.6376
1755.3	18.5805
1756.33	18.5604
1757.35	18.5463
1758.37	18.5553
1759.39	19.5078
1760.42	18.5491
1761.44	20.4385
1762.46	19.4919
1763.48	16.6413
1764.5	18.5594
1765.53	19.5174
1766.55	18.5622
1767.57	17.6032
1768.59	20.4413
1769.61	18.5171
1770.63	22.329
1771.65	17.5927
1772.67	19.5079
1773.69	19.5158
1774.71	18.5703
1775.73	16.6831
1776.75	15.7243
1777.77	15.7141
1778.79	16.6509
1779.81	15.7034
1780.83	14.7561
1781.85	19.5259
1782.86	13.8195
1783.88	16.6895
1784.9	15.7428
1785.92	18.6013
1786.94	20.5261
1787.95	18.6603
1788.97	21.557
1789.99	15.8181
1791	18.6776
1792.02	18.6758
1793.04	17.7233
1794.05	17.726
1795.07	17.7541
1796.09	17.7682
1797.1	17.7819
1798.12	15.8659
1799.13	18.744
1800.15	16.8112
1801.16	15.8484
1802.18	15.8545
1803.19	16.8285
1804.21	17.799
1805.22	21.6679
1806.24	16.8645
1807.25	18.7942
1808.26	15.9046
1809.28	18.7996
1810.29	19.7643
1811.3	19.7629
1812.32	17.8414
1813.33	15.9214
1814.34	20.7696
1815.36	17.88
1816.37	18.8509
1817.38	18.8324
1818.39	16.9119
1819.4	15.9507
1820.42	19.8269
1821.43	18.8705
1822.44	19.8449
1823.45	15.002
1824.46	16.9427
1825.47	17.9162
1826.48	17.9178
1827.49	18.8939
1828.5	15.9822
1829.51	17.9159
1830.52	15.0061
1831.53	17.9203
1832.54	18.9009
1833.55	18.9043
1834.56	17.9114
1835.57	16.9275
1836.58	16.9633
1837.58	17.8825
1838.59	15.9811
1839.6	15.994
1840.61	18.8493
1841.62	15.9229
1842.62	16.8793
1843.63	15.9146
1844.64	17.8435
1845.65	17.8613
1846.65	15.9096
1847.66	15.8929
1848.67	17.8119
1849.67	16.83
1850.68	15.8508
1851.68	16.8041
1852.69	14.8831
1853.69	17.7514
1854.7	17.7355
1855.71	16.7623
1856.71	14.8453
1857.72	16.7524
1858.72	18.6499
1859.72	18.6424
1860.73	15.7842
1861.73	15.7892
1862.74	17.6878
1863.74	14.8075
1864.74	14.7952
1865.75	19.5393
1866.75	15.7005
1867.75	16.637
1868.76	17.5879
1869.76	16.6336
1870.76	19.4828
1871.76	15.6737
1872.77	17.5626
1873.77	18.5034
1874.77	19.4326
1875.77	17.5092
1876.77	16.5423
1877.77	19.4416
1878.78	20.3633
1879.78	16.569
1880.78	16.5666
1881.78	19.3677
1882.78	14.6241
1883.78	16.4945
1884.78	17.4529
1885.78	13.6931
1886.78	17.4592
1887.78	14.6127
1888.77	15.5347
1889.77	16.475
1890.77	20.2498
1891.77	17.4208
1892.77	17.4062
1893.77	20.209
1894.76	18.32
1895.76	14.5687
1896.76	18.3406
1897.76	18.3416
1898.75	15.5075
1899.75	17.3783
1900.75	18.3237
1901.75	20.2208
1902.74	19.2799
1903.74	17.3938
1904.74	18.3314
1905.73	18.3183
1906.73	13.6158
1907.72	16.44
1908.72	17.3869
1909.71	17.4066
1910.71	16.4827
1911.7	18.3672
1912.7	18.3661
1913.69	17.4392
1914.69	17.4542
1915.68	17.4554
1916.68	18.3882
1917.67	18.3839
1918.66	15.571
1919.66	17.4807
1920.65	18.431
1921.64	19.3884
1922.64	16.5446
1923.63	18.428
1924.62	20.3129
1925.61	19.387
1926.61	19.4077
1927.6	18.471
1928.59	19.4272
1929.58	19.4464
1930.57	18.5141
1931.57	17.5589
1932.56	17.5511
1933.55	14.7168
1934.54	20.4788
1935.53	19.5377
1936.52	16.6717
1937.51	15.7061
1938.5	22.3762
1939.49	19.5322
1940.48	18.6032
1941.47	16.6912
1942.46	20.5293
1943.45	19.552
1944.44	18.623
1945.42	18.6412
1946.41	18.6506
1947.4	20.5589
1948.39	18.6462
1949.38	16.7486
1950.37	14.8572
1951.35	16.7993
1952.34	19.6886
1953.33	17.7623
1954.32	16.7666
1955.3	16.7718
1956.29	19.6811
1957.28	17.7757
1958.26	23.5492
1959.25	20.6572
1960.23	17.7637
1961.22	17.7535
1962.21	17.7569
1963.19	19.6799
1964.18	23.5262
1965.16	17.764
1966.15	17.7777
1967.13	18.7438
1968.12	18.7466
1969.1	18.7306
1970.09	18.714
1971.07	20.6226
1972.05	20.6263
1973.04	19.6569
1974.02	17.7321
1975.01	20.6135
1975.99	18.7046
1976.97	15.8261
1977.95	18.6931
1978.94	20.6081
1979.92	21.5658
1980.9	16.7638
1981.88	19.6333
1982.87	20.573
1983.85	19.6073
1984.83	21.5067
1985.81	17.6594
1986.79	19.5788
1987.77	19.4801
1988.75	18.6735
1989.73	18.6641
1990.72	19.8092
1991.7	19.9806
1992.68	19.5968
1993.66	17.712
1994.63	18.6071
1995.61	20.0821
1996.59	19.0712
1997.57	19.5542
1998.55	19.4648
1999.53	18.4255
2000.51	19.7504
2001.49	18.4963
2002.47	18.8287
2003.45	19.1523
2004.42	20.8444
2005.4	18.8641
2006.38	16.9556
2007.36	20.8644
2008.31	23.1204
2009.3	21.2091
2010.29	18.3665
2011.28	16.481
2012.27	21.1841
2013.26	19.2744
2014.24	18.3013
2015.23	20.1845
2016.22	16.4466
2017.21	21.137
2018.2	16.4154
2019.18	20.1415
2020.17	18.2628
2021.16	18.2647
2022.15	21.064
2023.14	21.0436
2024.12	18.2198
2025.11	19.1295
2026.1	19.1297
2027.08	18.2464
2028.07	18.1741
2029.06	20.1282
2030.04	19.1168
2031.03	17.2614
2032.01	21.0092
2033	21.0338
2033.98	20.0783
2034.97	18.2068
2035.95	19.1708
2036.94	19.1685
2037.92	19.1602
2038.91	20.0816
2039.89	20.9952
2040.87	19.1124
2041.86	18.1731
2042.84	19.1021
2043.83	19.1261
2044.81	22.8159
2045.79	20.1242
2046.78	21.0018
2047.76	19.1108
2048.74	20.9862
2049.72	20.0773
2050.71	18.2164
2051.69	20.0761
2052.67	20.0864
2053.65	17.3034
2054.63	21.9816
2055.62	21.9712
2056.6	21.9658
2057.58	20.1052
2058.56	20.1228
2059.54	21.0642
2060.52	21.9959
2061.5	22.0027
2062.48	17.3283
2063.46	19.2132
2064.44	20.1598
2065.42	19.2434
2066.4	20.1923
2067.38	20.2028
2068.36	23.033
2069.34	20.193
2070.31	18.3338
2071.29	20.2449
2072.27	21.1859
2073.25	22.1259
2074.23	19.31
2075.21	17.455
2076.18	19.3527
2077.16	17.447
2078.14	20.2837
2079.12	23.137
2080.09	21.2624
2081.07	18.424
2082.05	20.3164
2083.02	21.2616
2084	20.3164
2084.98	19.3729
2085.95	18.4413
2086.93	19.399
2087.9	19.4018
2088.88	18.4618
2089.85	21.3145
2090.83	19.428
2091.8	20.397
2092.78	20.4218
2093.75	21.3909
2094.73	20.4383
2095.7	22.3264
2096.68	20.4201
2097.65	19.4606
2098.62	22.3038
2099.6	19.4548
2100.57	19.4642
2101.54	19.4713
2102.52	17.567
2103.49	20.4085
2104.46	21.3673
2105.44	20.433
2106.41	20.4396
2107.38	20.4352
2108.35	18.5157
2109.32	20.4242
2110.3	22.3246
2111.27	18.5204
2112.24	19.47
2113.21	19.4836
2114.18	20.4323
2115.15	18.5303
2116.12	21.369
2117.09	22.3166
2118.06	18.5043
2119.03	17.5389
2120	18.4768
2120.97	18.4873
2121.94	20.4013
2122.91	18.5125
2123.88	18.5058
2124.85	25.1087
2125.82	19.4007
2126.79	20.3301
2127.76	18.4334
2128.72	15.5962
2129.69	22.2076
2130.66	20.3102
2131.63	21.2436
2132.6	20.2875
2133.56	21.2332
2134.53	22.1774
2135.5	21.2258
2136.47	17.4408
2137.43	19.3344
2138.4	23.0984
2139.37	18.3771
2140.33	21.1928
2141.3	17.4188
2142.26	20.2428
2143.23	20.1941
2144.19	23.0435
2145.16	20.2161
2146.13	19.2697
2147.09	19.2608
2148.06	18.3129
2149.02	18.2988
2149.98	20.1537
2150.95	20.1571
2151.91	19.2282
2152.88	20.1534
2153.84	19.204
2154.8	21.0433
2155.77	19.1528
2156.73	18.216
2157.69	17.2917
2158.66	19.1589
2159.62	20.0782
2160.58	20.0632
2161.54	20.0577
2162.51	19.1226
2163.47	18.1816
2164.43	21.8945
2165.39	18.1713
2166.35	19.0958
2167.32	15.3559
2168.28	18.1284
2169.24	18.1417
2170.2	21.8855
2171.16	20.9365
2172.12	18.12
2173.08	20.9043
2174.04	17.1939
2175	19.9805
2175.96	18.1174
2176.92	19.9724
2177.88	15.3263
2178.84	19.9624
2179.8	18.1058
2180.76	16.2458
2181.72	21.808
2182.68	19.0142
2183.63	18.0706
2184.59	18.0703
2185.55	18.0789
2186.51	18.0965
2187.47	17.1828
2188.43	18.0988
2189.38	19.0058
2190.34	19.9327
2191.3	19.9372
2192.25	16.234
2193.21	18.1032
2194.17	20.9182
2195.12	15.3329
2196.08	16.243
2197.04	22.7236
2197.99	16.2385
2198.95	19.0453
2199.9	17.2173
2200.86	19.1055
2201.81	13.4435
2202.77	20.9241
2203.72	17.2505
2204.68	18.1547
2205.63	19.9897
2206.59	19.9889
2207.54	19.0743
2208.49	18.1575
2209.45	18.1602
2210.4	15.3743
2211.36	17.2505
2212.31	17.2566
2213.26	19.1124
2214.22	18.2001
2215.17	20.0731
2216.12	19.1395
2217.07	16.3383
2218.03	16.3399
2218.98	18.219
2219.93	20.0938
2220.88	16.3484
2221.83	15.4024
2222.78	19.1437
2223.74	17.2943
2224.69	19.183
2225.64	16.3921
2226.59	19.2176
2227.54	18.2861
2228.49	15.469
2229.44	15.4758
2230.39	20.1824
2231.34	16.4425
2232.29	18.3365
2233.24	17.4096
2234.19	17.4116
2235.14	19.2765
2236.09	16.4593
2237.04	16.4691
2237.98	18.3787
2238.93	18.3971
2239.88	20.2691
2240.83	18.3984
2241.78	16.5168
2242.73	14.6325
2243.67	20.2893
2244.62	18.4197
2245.57	18.4385
2246.52	13.7196
2247.46	17.5095
2248.41	17.5058
2249.36	18.4565
2250.3	16.5545
2251.25	14.654
2252.2	16.5541
2253.14	15.633
2254.09	18.4895
2255.03	14.6966
2255.98	18.4983
2256.92	17.5619
2257.87	17.5687
2258.81	15.6772
2259.76	17.5849
2260.7	15.6952
2261.65	15.7016
2262.59	19.5219
2263.54	17.6415
2264.48	16.7093
2265.42	15.7618
2266.37	16.7041
2267.31	16.6928
2268.26	19.5474
2269.2	19.566
2270.14	14.8112
2271.08	19.6025
2272.03	17.6985
2272.97	17.7028
2273.91	17.707
2274.85	17.7118
2275.79	19.6357
2276.74	16.778
2277.68	14.8835
2278.62	14.8867
2279.56	15.8314
2280.5	18.6948
2281.44	17.7331
2282.38	17.7454
2283.32	18.7315
2284.26	15.8704
2285.2	17.804
2286.14	17.795
2287.08	17.8165
2288.02	16.8564
2288.96	16.8394
2289.9	22.5914
2290.84	15.87
2291.78	15.8847
2292.72	17.8254
2293.66	16.8661
2294.6	17.8194
2295.54	19.7357
2296.47	17.8
2297.41	17.8159
2298.35	18.7963
2299.29	17.8459
2300.23	15.9187
2301.16	14.9614
2302.1	14.9593
2303.04	17.8537
2303.97	15.9314
2304.91	14.0085
2305.85	14.0143
2306.78	18.8475
2307.72	15.942
2308.65	15.9445
2309.59	17.8948
2310.53	20.7965
2311.46	17.8623
2312.4	15.9206
2313.33	16.9
2314.27	15.9553
2315.2	15.9548
2316.14	17.8656
2317.07	15.934
2318	15.9332
2318.94	15.9237
2319.87	15.9218
2320.81	15.9289
2321.74	16.9119
2322.67	16.9182
2323.61	19.8235
2324.54	19.8105
2325.47	17.8605
2326.41	18.81
2327.34	24.5793
2328.27	50.6044
2329.2	23.5976
2330.13	20.7071
2331.07	16.8567
2332	17.8186
2332.93	15.8839
2333.86	18.7624
2334.79	15.8675
2335.72	14.9064
2336.66	14.9028
2337.59	16.8218
2338.52	13.9372
2339.45	12.9749
2340.38	15.8474
2341.31	15.8273
2342.24	16.7766
2343.17	15.8163
2344.1	16.7766
2345.02	14.8539
2345.95	13.886
2346.88	16.7546
2347.81	12.9587
2348.74	19.3703
2349.67	14.1051
2350.6	13.9609
2351.53	15.968
2352.45	15.6982
2353.38	16.2451
2354.31	15.3234
2355.24	16.1362
2356.17	15.1335
2357.09	17.4342
2358.02	15.0808
2358.95	15.1784
2359.87	14.8554
2360.8	16.0669
2361.73	15.6461
2362.65	14.4619
2363.58	17.0338
2364.5	12.9466
2365.43	14.5065
2366.36	17.3345
2367.28	15.1301
2368.2	15.2157
2368.98	15.5721
2369.92	17.4427
2370.86	13.6606
2371.79	15.5366
2372.73	14.5865
2373.67	17.401
2374.6	13.6289
2375.54	15.4994
2376.48	19.2468
2377.41	15.4845
2378.35	14.5349
2379.28	14.518
2380.22	14.5107
2381.15	14.509
2382.09	15.4439
2383.02	16.3758
2383.96	16.3747
2384.89	12.6279
2385.83	14.4855
2386.76	14.4689
2387.69	15.3921
2388.63	17.2549
2389.56	12.5886
2390.5	14.4547
2391.43	13.5238
2392.36	17.2481
2393.3	12.5673
2394.23	15.3478
2395.16	14.4226
2396.09	17.2634
2397.02	15.3884
2397.96	15.3882
2398.89	12.5894
2399.82	12.5903