File: Data/3-Raman/raw/bu19w-e-ff11b-fi04-v_1800 (450-850nm)_532nm_edge_100%_x100_vis_h50um_30sx2_01.txt
#Acq. time (s)=	30
#Accumulations=	2
#Range (cm-¹)=	1200...2365
#Windows=	3
#Auto scanning=	Off
#Autofocus=	Off
#Macrospot=	Off
#AutoExposure=	Off
#Spike filter=	Multiple accum.
#Delay time (s)=	2
#Binning=	1
#Readout mode=	Signal
#DeNoise=	Off
#ICS correction=	On
#Dark correction=	Off
#Inst. Process=	Off
#Detector Gain=	Best Dynamic
#Detector ADC=	50 kHz HS
#Detector temperature (°C)=	-60.09
#Instrument=	LabRAM HR Evol
#Detector=	SIN-EM FIVIS
#Objective=	x100_VIS
#Grating=	1800 (450-850nm)
#ND Filter=	100%
#Laser=	532nm_Edge
#Hole=	49.98
#Temperature=	0
#Range=	Visible
#StageXY=	75x50mm Scan+
#StageZ=	Z motor
#X (µm)=	0
#Y (µm)=	0
#Z (µm)=	-244.7
#Full time(mm:ss)=	3:22
#Project=	21_11_04
#Sample=	BU19w
#Site=
#Title=	BU19w-E-FF11b-FI04-V_1800 (450-850nm)_532nm_Edge_100%_x100_VIS_H50um_30sX2
#Remark=
#Date=	04.11.2021 18:47
#Acquired=	04.11.2021 18:47:44
1202.73	25.3062
1203.85	25.2574
1204.96	23.096
1206.07	25.1978
1207.18	24.0907
1208.29	27.2773
1209.4	29.3998
1210.51	26.1598
1211.62	28.2549
1212.73	25.0277
1213.84	26.0835
1214.95	30.3406
1216.06	27.1206
1217.17	34.519
1218.28	27.0609
1219.39	28.1093
1220.5	25.9837
1221.61	25.9596
1222.72	29.0842
1223.82	32.2088
1224.93	30.0847
1226.04	31.1474
1227.15	34.2652
1228.25	31.0094
1229.36	33.2327
1230.47	32.1183
1231.57	32.0497
1232.68	36.2426
1233.79	32.045
1234.89	26.8047
1236	28.9119
1237.1	33.0848
1238.21	30.9402
1239.31	29.875
1240.42	27.7785
1241.52	28.8182
1242.63	28.8271
1243.74	26.7332
1244.84	29.8615
1245.94	27.7392
1247.05	29.828
1248.15	31.8987
1249.25	28.7619
1250.36	29.79
1251.46	33.946
1252.56	29.7451
1253.66	32.8793
1254.77	33.9376
1255.87	34.9843
1256.97	34.9875
1258.07	39.1513
1259.18	36.0125
1260.28	39.1367
1261.38	49.5765
1262.48	66.278
1263.58	62.177
1264.68	41.2823
1265.78	38.1385
1266.88	36.0757
1267.98	36.1281
1269.08	38.2451
1270.18	37.1623
1271.28	38.1918
1272.38	38.2341
1273.48	38.2743
1274.58	38.2852
1275.68	36.209
1276.78	38.3373
1277.87	34.1663
1278.97	47.8648
1280.07	62.5791
1281.17	102.627
1282.26	312.141
1283.36	668.895
1284.46	175.466
1285.55	60.5486
1286.65	44.7466
1287.75	38.4105
1288.84	39.4775
1289.94	35.2911
1291.04	34.2297
1292.13	30.018
1293.23	34.2482
1294.32	33.2174
1295.42	34.3231
1296.51	29.0667
1297.61	30.0994
1298.7	32.2015
1299.79	32.2024
1300.89	31.147
1301.98	30.1051
1303.08	30.0969
1304.17	25.8706
1305.26	26.9091
1306.36	27.947
1307.45	30.0594
1308.54	27.9543
1309.63	30.0774
1310.73	30.0775
1311.82	30.0904
1312.91	29.0315
1314	27.9723
1315.09	30.0971
1316.18	25.8746
1317.28	26.9351
1318.37	30.1093
1319.46	27.9949
1320.55	26.9309
1321.64	32.1782
1322.73	30.0483
1323.82	28.997
1324.91	27.9406
1325.99	28.9358
1327.08	26.859
1328.17	25.8439
1329.26	27.9586
1330.35	31.107
1331.44	28.9561
1332.53	29.9716
1333.62	29.9353
1334.7	26.7593
1335.79	26.7407
1336.88	27.777
1337.96	27.7575
1339.05	30.8893
1340.14	29.8473
1341.23	30.889
1342.31	29.8169
1343.4	26.6688
1344.48	31.8929
1345.57	26.6367
1346.66	27.6415
1347.74	28.6627
1348.83	31.7719
1349.91	27.5851
1351	31.721
1352.08	27.5622
1353.17	31.7873
1354.25	25.4552
1355.33	26.4869
1356.42	28.5625
1357.5	25.4336
1358.58	27.4894
1359.67	29.5412
1360.75	30.5573
1361.83	31.5844
1362.92	32.6195
1364	37.808
1365.08	38.818
1366.16	30.5081
1367.24	33.5885
1368.33	51.1738
1369.41	34.6325
1370.49	35.6433
1371.57	38.6924
1372.65	33.4996
1373.73	44.8198
1374.81	45.8378
1375.89	46.8692
1376.97	47.8505
1378.05	45.8641
1379.13	52.0541
1380.21	60.1945
1381.29	61.167
1382.37	73.3773
1383.45	72.2789
1384.53	113.334
1385.61	301.353
1386.68	1455.87
1387.76	273.526
1388.84	87.7786
1389.92	57.9243
1390.99	48.6806
1392.07	35.3262
1393.15	40.4273
1394.23	37.3468
1395.3	37.363
1396.38	36.3286
1397.46	30.1729
1398.53	31.205
1399.61	37.3586
1400.68	32.2569
1401.76	35.3563
1402.83	34.3899
1403.91	31.2919
1404.99	40.5083
1406.06	43.5606
1407.13	56.898
1408.21	93.8288
1409.28	56.9314
1410.36	36.393
1411.43	31.246
1412.5	38.4875
1413.58	33.3232
1414.65	34.393
1415.72	28.2385
1416.8	32.3605
1417.87	27.231
1418.94	32.372
1420.01	27.2138
1421.08	29.2514
1422.16	28.2619
1423.23	28.1767
1424.3	30.2367
1425.37	27.1869
1426.44	28.194
1427.51	29.1834
1428.58	26.1122
1429.65	25.1056
1430.72	24.1126
1431.79	29.2426
1432.86	27.1596
1433.93	28.1649
1435	25.1058
1436.07	26.1248
1437.14	23.0448
1438.21	26.1221
1439.28	29.2079
1440.35	25.1233
1441.41	27.1685
1442.48	25.1268
1443.55	23.0649
1444.62	23.0836
1445.69	26.1566
1446.75	26.1488
1447.82	26.1447
1448.89	24.102
1449.95	23.0643
1451.02	23.0571
1452.09	22.0273
1453.15	25.1085
1454.22	23.0562
1455.28	25.1071
1456.35	23.0574
1457.41	25.0972
1458.48	24.076
1459.54	21.0028
1460.61	20.9955
1461.67	25.0778
1462.74	24.0339
1463.8	20.9719
1464.86	21.9694
1465.93	25.0114
1466.99	23.9749
1468.05	26.0112
1469.12	26.0016
1470.18	23.9452
1471.24	25.9693
1472.31	23.9281
1473.37	23.9175
1474.43	23.9183
1475.49	18.8263
1476.55	21.8685
1477.62	23.8969
1478.68	21.8492
1479.74	18.7839
1480.8	20.7978
1481.86	19.793
1482.92	20.8165
1483.98	20.8015
1485.04	23.7594
1486.1	20.7686
1487.16	24.8176
1488.22	21.7625
1489.28	22.7631
1490.34	19.7226
1491.4	21.7364
1492.46	18.7024
1493.52	21.7328
1494.57	24.7664
1495.63	24.7388
1496.69	22.7088
1497.75	20.6886
1498.81	23.7196
1499.86	20.6966
1500.92	24.7273
1501.98	21.6949
1503.03	21.6794
1504.09	23.6987
1505.15	23.6889
1506.2	22.6666
1507.26	22.6736
1508.32	22.6715
1509.37	23.68
1510.43	21.6569
1511.48	20.6163
1512.54	21.5898
1513.59	23.6022
1514.65	21.5865
1515.7	20.5601
1516.76	24.5642
1517.81	22.566
1518.86	21.5693
1519.92	23.5741
1520.97	23.5799
1522.02	22.5699
1523.08	24.5555
1524.13	22.5308
1525.18	23.5376
1526.24	23.5556
1527.29	23.5499
1528.34	23.5408
1529.39	21.5317
1530.44	20.5368
1531.5	23.5473
1532.55	24.5609
1533.6	17.5553
1534.65	24.5704
1535.7	21.5372
1536.75	25.5134
1537.8	20.4967
1538.85	18.5026
1539.9	22.5519
1540.95	22.5548
1542	20.5303
1543.05	21.511
1544.1	22.5057
1545.15	23.5332
1546.2	24.5413
1547.25	18.537
1548.29	20.5358
1549.34	22.4957
1550.39	23.6091
1551.44	21.577
1552.49	26.6134
1553.53	24.5728
1554.58	23.5429
1555.63	21.5395
1556.68	22.5396
1557.72	24.5329
1558.77	21.5042
1559.82	25.4873
1560.86	25.4831
1561.91	22.5034
1562.95	26.5004
1564	23.5174
1565.04	23.4279
1566.09	23.494
1567.13	26.5123
1568.18	23.4987
1569.22	24.4826
1570.27	24.4855
1571.31	21.4783
1572.36	26.4602
1573.4	24.4509
1574.44	26.4687
1575.49	25.483
1576.53	25.4652
1577.57	21.4417
1578.62	23.4277
1579.66	24.4309
1580.7	22.4317
1581.74	26.4026
1582.79	23.4076
1583.83	25.3977
1584.87	23.4078
1585.91	21.4044
1586.95	28.3574
1587.99	26.3693
1589.03	26.3826
1590.07	23.4008
1591.12	24.3981
1592.16	26.368
1593.2	26.335
1594.24	25.3291
1595.28	26.3238
1596.32	22.348
1597.35	26.3276
1598.39	26.3087
1599.43	28.2741
1600.47	26.2677
1601.51	29.2071
1602.55	30.171
1603.59	28.1786
1604.63	28.1803
1605.66	26.2111
1606.7	27.2107
1607.74	26.1809
1608.78	27.0644
1609.81	25.9586
1610.85	29.0456
1611.89	27.7425
1612.92	21.9668
1613.96	28.7636
1615	27.6659
1616.03	27.6246
1617.07	28.4488
1618.1	28.3798
1619.14	27.3899
1620.17	26.0533
1621.21	29.2342
1622.24	26.7516
1623.28	26.7136
1624.31	26.6416
1625.35	25.0666
1626.38	27.9662
1627.41	27.8148
1628.45	29.7475
1629.48	28.5004
1630.51	29.0926
1631.3	28.0815
1632.34	27.1199
1633.39	28.0843
1634.43	28.0921
1635.48	28.0849
1636.52	27.0853
1637.57	27.0743
1638.61	27.0698
1639.66	28.0527
1640.7	28.0646
1641.75	27.0719
1642.79	28.0524
1643.83	29.0272
1644.88	27.0596
1645.92	26.0734
1646.96	25.0799
1648.01	28.0325
1649.05	28.0565
1650.09	28.0679
1651.13	30.0558
1652.18	28.0849
1653.22	28.0806
1654.26	27.1032
1655.3	28.1157
1656.34	27.1459
1657.38	27.1389
1658.42	25.1539
1659.47	27.1091
1660.51	29.0952
1661.55	27.1422
1662.59	27.1815
1663.63	27.1411
1664.67	29.1516
1665.71	25.2174
1666.75	25.1745
1667.79	25.1576
1668.83	28.15
1669.86	24.1967
1670.9	23.2271
1671.94	22.2415
1672.98	27.186
1674.02	24.231
1675.06	25.2349
1676.1	26.2272
1677.13	23.2559
1678.17	22.2503
1679.21	25.2056
1680.25	26.1841
1681.28	25.1917
1682.32	23.216
1683.35	22.2267
1684.39	25.1816
1685.43	24.1928
1686.46	24.2029
1687.5	19.2587
1688.54	24.1836
1689.57	21.2062
1690.6	23.187
1691.64	21.2196
1692.68	22.1937
1693.71	24.1429
1694.74	26.1044
1695.78	25.1273
1696.81	25.1242
1697.85	23.1326
1698.88	21.1549
1699.92	24.1052
1700.95	22.1319
1701.98	23.0988
1703.01	19.1603
1704.05	17.1959
1705.08	21.1252
1706.11	20.1314
1707.14	19.1307
1708.18	21.0651
1709.21	21.0475
1710.24	23.9865
1711.27	20.0792
1712.3	21.0438
1713.33	19.0555
1714.36	23.9297
1715.4	19.0533
1716.43	21.9697
1717.46	21.9321
1718.49	19.9603
1719.52	15.0911
1720.55	20.9239
1721.58	20.905
1722.61	20.8846
1723.64	20.8763
1724.66	19.889
1725.69	20.835
1726.72	15.9823
1727.75	18.8872
1728.78	21.7095
1729.81	17.8662
1730.83	20.7784
1731.86	19.8094
1732.89	19.795
1733.92	18.8021
1734.95	23.5931
1735.97	17.805
1737	18.7571
1738.03	18.7438
1739.05	19.6838
1740.08	21.5694
1741.1	18.6765
1742.13	20.5834
1743.16	16.7492
1744.18	17.6952
1745.21	17.6949
1746.23	20.547
1747.26	19.5718
1748.28	18.6147
1749.31	18.6245
1750.33	18.6395
1751.36	20.5471
1752.38	16.7078
1753.4	19.5572
1754.43	22.4027
1755.45	18.5782
1756.47	15.7021
1757.5	16.6447
1758.52	19.507
1759.54	20.4586
1760.57	20.4497
1761.59	17.5858
1762.61	19.4924
1763.63	15.6913
1764.66	18.561
1765.68	18.5654
1766.7	17.6102
1767.72	20.4564
1768.74	17.5831
1769.76	19.4695
1770.78	18.5314
1771.8	23.3012
1772.82	19.5093
1773.84	17.6124
1774.86	21.43
1775.88	21.4501
1776.9	21.4411
1777.92	19.5215
1778.94	17.6007
1779.96	18.5595
1780.98	18.5646
1782	18.5762
1783.02	18.5864
1784.04	16.6922
1785.05	18.6047
1786.07	17.6483
1787.09	19.5755
1788.11	17.7086
1789.12	19.6441
1790.14	17.7358
1791.16	17.7189
1792.18	17.7185
1793.19	19.6393
1794.21	17.7243
1795.23	19.6768
1796.24	17.7704
1797.26	19.7059
1798.27	19.7123
1799.29	17.7807
1800.3	18.7316
1801.32	19.6909
1802.33	16.8172
1803.35	17.7911
1804.36	18.7633
1805.38	17.8182
1806.39	20.7203
1807.41	16.8668
1808.42	19.7607
1809.43	15.9078
1810.45	18.7997
1811.46	15.9069
1812.47	18.808
1813.49	18.8188
1814.5	15.9414
1815.51	18.8471
1816.53	18.8501
1817.54	16.9013
1818.55	18.8441
1819.56	17.8852
1820.57	17.8937
1821.58	16.9363
1822.6	21.7817
1823.61	16.9376
1824.62	16.9438
1825.63	17.9162
1826.64	16.9501
1827.65	15.9871
1828.66	14.0442
1829.67	20.8195
1830.68	23.7213
1831.69	18.8906
1832.7	18.9009
1833.71	19.8748
1834.72	20.81
1835.73	18.8585
1836.74	19.8677
1837.75	16.9105
1838.75	15.9848
1839.76	20.8259
1840.77	16.9109
1841.78	17.8491
1842.79	18.81
1843.79	14.9501
1844.8	18.8086
1845.81	17.8658
1846.81	17.8182
1847.82	19.7523
1848.83	16.8471
1849.83	16.8259
1850.84	15.8489
1851.85	18.7244
1852.85	17.763
1853.86	17.7477
1854.86	18.6906
1855.87	19.6352
1856.87	16.7599
1857.88	16.7502
1858.88	14.8218
1859.89	20.5554
1860.89	17.6997
1861.9	15.7876
1862.9	18.6411
1863.9	16.7162
1864.91	19.564
1865.91	19.5338
1866.92	20.4531
1867.92	17.587
1868.92	19.4887
1869.92	20.4349
1870.93	16.6308
1871.93	18.5223
1872.93	19.4609
1873.93	18.5006
1874.93	16.5857
1875.94	22.237
1876.94	17.4805
1877.94	21.3067
1878.94	18.4737
1879.94	15.6215
1880.94	18.4544
1881.94	17.4714
1882.94	14.6926
1883.94	18.3871
1884.94	16.511
1885.94	18.4169
1886.94	16.5129
1887.94	15.5514
1888.94	18.3569
1889.94	19.3022
1890.94	17.423
1891.94	17.4205
1892.94	18.3402
1893.93	14.5656
1894.93	18.3209
1895.93	18.3303
1896.93	16.4607
1897.93	19.2808
1898.92	20.2041
1899.92	18.3173
1900.92	17.3866
1901.91	16.4613
1902.91	19.2783
1903.91	17.3935
1904.9	19.2713
1905.9	19.256
1906.9	18.3111
1907.89	17.3805
1908.89	15.5095
1909.88	17.4108
1910.88	20.2516
1911.87	20.2501
1912.87	19.3085
1913.86	18.3848
1914.86	17.4559
1915.85	16.5113
1916.85	19.3293
1917.84	18.3858
1918.84	19.3501
1919.83	18.4261
1920.82	19.3797
1921.82	18.4426
1922.81	17.489
1923.8	17.4808
1924.79	18.4252
1925.79	17.4988
1926.78	18.4629
1927.77	19.4198
1928.76	22.2728
1929.75	20.3995
1930.75	18.5145
1931.74	20.4044
1932.73	15.652
1933.72	17.5735
1934.71	19.5345
1935.7	16.6787
1936.69	15.7164
1937.68	21.4143
1938.67	20.4743
1939.66	18.5798
1940.65	16.6993
1941.64	19.544
1942.63	17.6652
1943.62	19.562
1944.61	20.5367
1945.6	17.6876
1946.59	18.6503
1947.58	19.6026
1948.57	17.6924
1949.55	20.5807
1950.54	17.7378
1951.53	17.7618
1952.52	20.6519
1953.5	16.7945
1954.49	18.681
1955.48	17.7358
1956.47	19.6836
1957.45	20.6604
1958.44	15.8588
1959.43	18.7336
1960.41	16.8013
1961.4	19.6733
1962.38	16.7976
1963.37	18.7206
1964.36	17.7636
1965.34	17.7653
1966.33	16.8187
1967.31	18.745
1968.3	19.7066
1969.28	19.6867
1970.26	17.752
1971.25	20.6215
1972.23	16.7887
1973.22	18.6957
1974.2	18.6907
1975.18	19.657
1976.17	17.7459
1977.15	16.7839
1978.13	17.7331
1979.12	16.7741
1980.1	19.6462
1981.08	18.6783
1982.06	19.6309
1983.05	19.6131
1984.03	18.6495
1985.01	19.5935
1985.99	20.5565
1986.97	17.6887
1987.95	16.7091
1988.93	19.5192
1989.91	18.4619
1990.89	19.3099
1991.88	16.5728
1992.86	19.2141
1993.84	17.0608
1994.82	19.3446
1995.8	17.7186
1996.78	17.721
1997.76	19.7831
1998.73	18.804
1999.71	15.6895
2000.69	17.5468
2001.67	19.6931
2002.65	17.2145
2003.63	18.5187
2004.6	19.4469
2005.58	20.8039
2006.56	18.6762
2007.54	19.9252
2008.52	18.4187
2009.49	19.2761
2010.47	18.4228
2011.45	16.7504
2012.42	20.24
2013.41	17.39
2014.4	20.1765
2015.39	19.2472
2016.38	14.5684
2017.37	17.3759
2018.35	15.4737
2019.34	15.456
2020.33	19.199
2021.32	20.1374
2022.31	18.2525
2023.29	19.1704
2024.28	19.1499
2025.27	17.2602
2026.25	18.2043
2027.24	21.0513
2028.23	15.4045
2029.21	16.3644
2030.2	18.1724
2031.19	18.1946
2032.17	18.2124
2033.16	18.2327
2034.14	18.1975
2035.13	17.2794
2036.11	19.164
2037.1	21.0379
2038.08	20.0928
2039.07	16.3437
2040.05	17.2598
2041.03	18.1792
2042.02	19.1022
2043	16.3098
2043.99	20.0582
2044.97	19.1123
2045.95	17.3012
2046.94	19.1305
2047.92	15.3824
2048.9	17.2579
2049.88	19.1471
2050.87	18.2138
2051.85	21.0122
2052.83	19.1547
2053.81	20.1113
2054.79	18.2395
2055.78	19.1652
2056.76	15.4233
2057.74	18.2366
2058.72	17.317
2059.7	16.3819
2060.68	21.062
2061.66	18.258
2062.64	19.204
2063.62	18.2771
2064.6	19.2252
2065.58	18.3072
2066.56	16.4368
2067.54	17.3855
2068.52	16.452
2069.5	17.374
2070.48	21.1619
2071.46	21.1891
2072.43	19.3015
2073.41	15.5356
2074.39	19.3136
2075.37	19.3466
2076.35	20.2953
2077.32	18.3886
2078.3	18.398
2079.28	20.3068
2080.26	19.3729
2081.23	20.3137
2082.21	16.5373
2083.19	18.4262
2084.16	16.5368
2085.14	16.5379
2086.12	20.3361
2087.09	21.2931
2088.07	16.5631
2089.04	19.4108
2090.02	15.6315
2090.99	22.2728
2091.97	20.4015
2092.94	19.4754
2093.92	18.5395
2094.89	18.535
2095.87	20.4252
2096.84	17.5685
2097.81	18.5109
2098.79	18.5066
2099.76	20.4042
2100.74	17.5678
2101.71	17.5713
2102.68	17.5645
2103.65	18.5102
2104.63	18.5201
2105.6	16.6328
2106.57	18.5395
2107.54	19.4813
2108.52	17.5652
2109.49	15.6746
2110.46	15.6748
2111.43	20.4186
2112.4	17.5718
2113.38	15.683
2114.35	18.5324
2115.32	20.4298
2116.29	17.5691
2117.26	17.5668
2118.23	16.603
2119.2	18.4844
2120.17	17.5297
2121.14	17.5423
2122.11	22.3014
2123.08	18.5131
2124.05	20.4004
2125.02	17.5245
2125.98	20.3441
2126.95	18.4378
2127.92	16.542
2128.89	20.3212
2129.86	17.4819
2130.83	19.3636
2131.79	17.4656
2132.76	21.2309
2133.73	18.4027
2134.7	16.5148
2135.67	18.3917
2136.63	22.1551
2137.6	20.2761
2138.57	16.5026
2139.53	18.375
2140.5	20.2499
2141.46	19.299
2142.43	16.4784
2143.4	18.3217
2144.36	18.3431
2145.33	16.4542
2146.29	21.1485
2147.26	18.3197
2148.22	21.1283
2149.19	18.2933
2150.15	20.1522
2151.12	18.2833
2152.08	20.164
2153.05	18.2776
2154.01	18.263
2154.97	19.1684
2155.94	16.3486
2156.9	19.1511
2157.86	15.4229
2158.83	17.2883
2159.79	18.2072
2160.75	18.1962
2161.72	17.259
2162.68	20.0535
2163.64	17.2478
2164.6	18.1683
2165.56	19.1033
2166.53	19.093
2167.49	17.2109
2168.45	17.1995
2169.41	16.2852
2170.37	18.1593
2171.33	16.2756
2172.29	19.0474
2173.25	19.0472
2174.21	21.8412
2175.17	18.121
2176.13	18.1153
2177.09	18.1149
2178.05	19.9666
2179.01	18.1057
2179.97	17.177
2180.93	18.1018
2181.89	18.0943
2182.85	19.0113
2183.81	19.9218
2184.76	18.0713
2185.72	16.2269
2186.68	19.0287
2187.64	17.1816
2188.6	13.4558
2189.55	19.9311
2190.51	19.0069
2191.47	19.0112
2192.42	21.8026
2193.38	20.8949
2194.34	19.9877
2195.3	19.0471
2196.25	19.9522
2197.21	15.3038
2198.16	19.0257
2199.12	17.1915
2200.07	20.016
2201.03	18.1672
2201.99	17.1627
2202.94	17.2017
2203.9	19.1133
2204.85	19.0745
2205.8	19.0631
2206.76	16.2718
2207.71	20.9385
2208.67	20.0215
2209.62	15.3667
2210.58	19.1037
2211.53	18.186
2212.48	16.3227
2213.44	18.1807
2214.39	15.4013
2215.34	17.2726
2216.29	17.2717
2217.25	18.2062
2218.2	17.2749
2219.15	16.3518
2220.1	20.0932
2221.06	16.3452
2222.01	20.0695
2222.96	16.3443
2223.91	19.1681
2224.86	17.3148
2225.81	15.458
2226.76	16.4073
2227.72	17.3474
2228.67	16.4059
2229.62	19.231
2230.57	17.3691
2231.52	18.3245
2232.47	17.3987
2233.42	17.4114
2234.37	18.3511
2235.31	18.3369
2236.26	20.2221
2237.21	16.4741
2238.16	17.4397
2239.11	17.4526
2240.06	19.3247
2241.01	15.5687
2241.96	16.5182
2242.9	18.4068
2243.85	19.3462
2244.8	18.4248
2245.75	17.4957
2246.69	18.4527
2247.64	17.5088
2248.59	18.4513
2249.53	20.3493
2250.48	14.66
2251.43	19.3819
2252.37	14.6659
2253.32	18.4786
2254.26	18.4897
2255.21	17.5417
2256.16	16.6033
2257.1	19.4629
2258.05	19.4691
2258.99	16.6285
2259.94	18.537
2260.88	19.5031
2261.83	15.7027
2262.77	17.621
2263.71	17.6467
2264.66	14.8021
2265.6	18.6265
2266.55	17.6557
2267.49	19.5513
2268.43	17.6423
2269.38	16.7066
2270.32	18.6353
2271.26	18.6483
2272.2	17.6993
2273.15	18.6606
2274.09	16.7507
2275.03	18.6703
2275.97	17.7236
2276.92	19.6592
2277.86	17.7665
2278.8	17.7673
2279.74	15.8282
2280.68	20.6108
2281.62	16.7754
2282.56	17.7486
2283.5	18.7375
2284.44	13.9492
2285.38	16.8395
2286.32	17.7967
2287.26	18.7807
2288.2	19.7439
2289.14	18.7594
2290.08	18.7462
2291.02	17.7984
2291.96	19.7384
2292.9	19.755
2293.84	15.901
2294.78	16.8545
2295.72	19.7328
2296.65	17.802
2297.59	15.8943
2298.53	13.0155
2299.47	17.8457
2300.41	13.9912
2301.34	16.8924
2302.28	15.9248
2303.22	20.7493
2304.15	20.761
2305.09	20.7721
2306.03	16.9145
2306.97	14.9804
2307.9	15.9408
2308.84	20.7791
2309.77	16.9289
2310.71	15.9574
2311.64	15.928
2312.58	17.8501
2313.51	14.9721
2314.45	15.9598
2315.39	18.8527
2316.32	19.7949
2317.25	18.8353
2318.19	15.9316
2319.12	17.8524
2320.06	19.7816
2320.99	18.8279
2321.92	22.715
2322.86	18.8529
2323.79	23.6907
2324.72	23.6693
2325.66	28.4757
2326.59	40.9891
2327.52	130.597
2328.46	92.0365
2329.39	37.0808
2330.32	26.4839
2331.25	20.7124
2332.18	18.7797
2333.12	18.7703
2334.05	17.7965
2334.98	17.7901
2335.91	14.9051
2336.84	16.8252
2337.77	15.8601
2338.7	17.7824
2339.63	18.7397
2340.56	19.6848
2341.49	19.6615
2342.42	18.6931
2343.35	18.6915
2344.28	19.6521
2345.21	19.6413
2346.14	15.8006
2347.07	17.7118
2348	18.6747
2348.93	17.7063
2349.85	19.577
2350.78	17.685
2351.71	19.566
2352.64	18.5747
2353.57	19.5254
2354.5	17.6284
2355.42	17.6224
2356.35	18.5502
2357.28	19.4881
2358.21	17.5774
2359.13	20.421
2360.06	17.5569
2360.99	16.5921
2361.91	17.5217
2362.84	21.2938
2363.77	20.3376
2364.69	17.4895
2364.92	19.3772