File: Data/3-Raman/raw/bu19w-e-ff11b-fi02-v_1800 (450-850nm)_532nm_edge_100%_x100_vis_h50um_30sx2_01.txt
#Acq. time (s)=	30
#Accumulations=	2
#Range (cm-¹)=	1200...2365
#Windows=	3
#Auto scanning=	Off
#Autofocus=	Off
#Macrospot=	Off
#AutoExposure=	Off
#Spike filter=	Multiple accum.
#Delay time (s)=	2
#Binning=	1
#Readout mode=	Signal
#DeNoise=	Off
#ICS correction=	On
#Dark correction=	Off
#Inst. Process=	Off
#Detector Gain=	Best Dynamic
#Detector ADC=	50 kHz HS
#Detector temperature (°C)=	-60.09
#Instrument=	LabRAM HR Evol
#Detector=	SIN-EM FIVIS
#Objective=	x100_VIS
#Grating=	1800 (450-850nm)
#ND Filter=	100%
#Laser=	532nm_Edge
#Hole=	49.98
#Temperature=	0
#Range=	Visible
#StageXY=	75x50mm Scan+
#StageZ=	Z motor
#X (µm)=	0
#Y (µm)=	0
#Z (µm)=	-251.2
#Full time(mm:ss)=	3:17
#Project=	21_11_04
#Sample=	BU19w
#Site=
#Title=	BU19w-E-FF11b-FI02-V_1800 (450-850nm)_532nm_Edge_100%_x100_VIS_H50um_30sX2
#Remark=
#Date=	04.11.2021 18:23
#Acquired=	04.11.2021 18:23:01
1202.73	32.8442
1203.85	32.7809
1204.96	32.7641
1206.07	28.4146
1207.18	28.3735
1208.29	32.6258
1209.4	31.538
1210.51	33.6341
1211.62	27.1886
1212.73	32.4828
1213.84	29.2774
1214.95	35.6635
1216.06	32.4384
1217.17	31.3327
1218.28	32.367
1219.39	32.3522
1220.5	34.4682
1221.61	33.3766
1222.72	33.3146
1223.82	31.1528
1224.93	33.2515
1226.04	34.315
1227.15	32.1566
1228.25	38.3676
1229.36	34.2877
1230.47	39.4897
1231.57	34.1513
1232.68	34.1416
1233.79	38.3489
1234.89	36.2652
1236	37.3226
1237.1	37.2861
1238.21	38.282
1239.31	37.2128
1240.42	35.1162
1241.52	37.2016
1242.63	36.1649
1243.74	39.3135
1244.84	37.1959
1245.94	38.2068
1247.05	36.1075
1248.15	35.0362
1249.25	33.9914
1250.36	44.4237
1251.46	36.0349
1252.56	40.1819
1253.66	40.1858
1254.77	39.1588
1255.87	37.073
1256.97	44.3872
1258.07	50.6357
1259.18	43.3194
1260.28	45.3985
1261.38	56.8826
1262.48	70.453
1263.58	78.8969
1264.68	66.3653
1265.78	49.6323
1266.88	47.5781
1267.98	42.4113
1269.08	49.7711
1270.18	48.6773
1271.28	41.3309
1272.38	45.5667
1273.48	46.6632
1274.58	47.7254
1275.68	53.0015
1276.78	49.891
1277.87	52.0379
1278.97	62.5924
1280.07	65.7344
1281.17	107.89
1282.26	322.669
1283.36	879.074
1284.46	353.566
1285.55	100.563
1286.65	62.6452
1287.75	56.3004
1288.84	52.1103
1289.94	52.1466
1291.04	47.9216
1292.13	43.7105
1293.23	42.6785
1294.32	43.7626
1295.42	44.8841
1296.51	43.8643
1297.61	46.9973
1298.7	42.7594
1299.79	42.7606
1300.89	44.8728
1301.98	40.6683
1303.08	40.6573
1304.17	39.5979
1305.26	42.738
1306.36	38.493
1307.45	43.7707
1308.54	43.7775
1309.63	37.4649
1310.73	41.6864
1311.82	46.9833
1312.91	42.7555
1314	36.4167
1315.09	41.7135
1316.18	41.7162
1317.28	38.5542
1318.37	41.7305
1319.46	36.4461
1320.55	42.7727
1321.64	35.3433
1322.73	43.7546
1323.82	40.5959
1324.91	38.4842
1325.99	38.4056
1327.08	37.3919
1328.17	42.7215
1329.26	43.7842
1330.35	35.3249
1331.44	40.5385
1332.53	42.5912
1333.62	40.4389
1334.7	44.5989
1335.79	37.2273
1336.88	42.4517
1337.96	43.4693
1339.05	39.266
1340.14	38.2255
1341.23	45.5482
1342.31	38.1866
1343.4	41.3105
1344.48	44.441
1345.57	39.1716
1346.66	42.2446
1347.74	42.2124
1348.83	38.0221
1349.91	41.1175
1351	37.9612
1352.08	33.8026
1353.17	45.336
1354.25	46.235
1355.33	37.9127
1356.42	41.0262
1357.5	43.0814
1358.58	40.9747
1359.67	41.9796
1360.75	42.9874
1361.83	44.011
1362.92	46.0815
1364	49.2022
1365.08	47.0991
1366.16	44.9865
1367.24	45.9904
1368.33	54.2753
1369.41	68.7482
1370.49	47.0078
1371.57	47.9785
1372.65	47.9302
1373.73	52.0322
1374.81	48.9279
1375.89	48.9294
1376.97	50.9377
1378.05	55.1399
1379.13	58.2387
1380.21	60.1945
1381.29	63.2231
1382.37	68.246
1383.45	84.5817
1384.53	111.283
1385.61	292.112
1386.68	1555.5
1387.76	606.87
1388.84	130.898
1389.92	81.5041
1390.99	71.2274
1392.07	56.8291
1393.15	56.8029
1394.23	49.6252
1395.3	49.6467
1396.38	54.7488
1397.46	50.6292
1398.53	45.5286
1399.61	49.6409
1400.68	50.6894
1401.76	49.7038
1402.83	49.7884
1403.91	50.7851
1404.99	55.8912
1406.06	60.9849
1407.13	87.6537
1408.21	126.643
1409.28	97.9631
1410.36	57.9212
1411.43	52.7596
1412.5	48.7508
1413.58	47.6778
1414.65	41.5796
1415.72	45.6951
1416.8	41.6063
1417.87	43.6724
1418.94	43.6765
1420.01	44.6717
1421.08	39.5151
1422.16	39.5666
1423.23	47.6442
1424.3	39.4615
1425.37	39.498
1426.44	39.4716
1427.51	42.4951
1428.58	38.4003
1429.65	39.4517
1430.72	35.3994
1431.79	37.451
1432.86	37.4085
1433.93	37.3825
1435	40.4766
1436.07	38.4188
1437.14	39.4322
1438.21	34.3172
1439.28	45.6053
1440.35	34.3523
1441.41	37.4208
1442.48	34.357
1443.55	39.4665
1444.62	39.4985
1445.69	39.4914
1446.75	39.4796
1447.82	39.4734
1448.89	38.4606
1449.95	40.4907
1451.02	33.3047
1452.09	38.4196
1453.15	41.5058
1454.22	31.254
1455.28	36.3797
1456.35	33.3051
1457.41	36.3653
1458.48	37.3947
1459.54	34.3216
1460.61	37.3822
1461.67	38.3843
1462.74	35.2838
1463.8	38.3633
1464.86	36.2751
1465.93	38.2827
1466.99	32.1366
1468.05	37.2317
1469.12	39.2573
1470.18	30.0588
1471.24	35.1349
1472.31	36.1467
1473.37	36.1307
1474.43	31.0429
1475.49	33.0732
1476.55	34.0741
1477.62	38.1333
1478.68	34.044
1479.74	32.9988
1480.8	37.0303
1481.86	30.9583
1482.92	37.0635
1483.98	36.0221
1485.04	38.925
1486.1	33.939
1487.16	38.999
1488.22	35.9334
1489.28	33.8917
1490.34	27.8139
1491.4	34.8794
1492.46	37.9103
1493.52	32.852
1494.57	35.8861
1495.63	35.846
1496.69	30.783
1497.75	30.7806
1498.81	35.8317
1499.86	34.8309
1500.92	35.8293
1501.98	35.8218
1503.03	36.8045
1504.09	36.8087
1505.15	30.7452
1506.2	37.7776
1507.26	36.7816
1508.32	32.7478
1509.37	34.7643
1510.43	34.7518
1511.48	36.7071
1512.54	35.6483
1513.59	32.6413
1514.65	36.6469
1515.7	35.6041
1516.76	32.5852
1517.81	33.5982
1518.86	37.6208
1519.92	31.5993
1520.97	31.6071
1522.02	30.5948
1523.08	32.5736
1524.13	33.5459
1525.18	36.5583
1526.24	34.5816
1527.29	36.5775
1528.34	34.5599
1529.39	33.5494
1530.44	38.569
1531.5	37.5754
1532.55	36.5908
1533.6	33.6059
1534.65	37.6077
1535.7	32.5562
1536.75	35.5187
1537.8	32.4948
1538.85	31.5044
1539.9	37.5866
1540.95	36.589
1542	36.554
1543.05	39.5202
1544.1	35.5089
1545.15	33.5473
1546.2	35.5599
1547.25	34.569
1548.29	40.5708
1549.34	36.493
1550.39	41.6927
1551.44	37.6343
1552.49	33.6434
1553.53	34.6025
1554.58	32.5593
1555.63	34.5634
1556.68	36.5642
1557.72	29.5396
1558.77	34.5067
1559.82	34.4828
1560.86	34.4771
1561.91	34.5052
1562.95	34.5006
1564	29.5218
1565.04	36.3879
1566.09	33.4915
1567.13	35.5164
1568.18	37.4979
1569.22	33.4762
1570.27	36.4784
1571.31	33.4662
1572.36	36.4452
1573.4	31.4369
1574.44	35.4581
1575.49	32.4783
1576.53	32.4557
1577.57	36.401
1578.62	33.3969
1579.66	35.3998
1580.7	29.4105
1581.74	31.3842
1582.79	38.3487
1583.83	30.3776
1584.87	34.3647
1585.91	34.3466
1586.95	39.3023
1587.99	35.3249
1589.03	34.3471
1590.07	37.3416
1591.12	33.3607
1592.16	33.3331
1593.2	32.2976
1594.24	31.2889
1595.28	37.2507
1596.32	37.2466
1597.35	33.2821
1598.39	30.2799
1599.43	33.2345
1600.47	33.2063
1601.51	38.1177
1602.55	30.171
1603.59	27.1898
1604.63	32.1354
1605.66	34.1239
1606.7	34.1371
1607.74	33.0355
1608.78	33.125
1609.81	33.9664
1610.85	32.2281
1611.89	31.2865
1612.92	35.2539
1613.96	32.1768
1615	29.472
1616.03	33.3144
1617.07	31.896
1618.1	33.3202
1619.14	30.6943
1620.17	31.086
1621.21	30.2167
1622.24	31.1738
1623.28	31.0409
1624.31	29.0175
1625.35	30.6742
1626.38	31.3375
1627.41	30.1927
1628.45	31.0696
1629.48	28.5004
1630.51	34.7646
1631.3	28.0815
1632.34	26.1337
1633.39	25.1281
1634.43	29.0778
1635.48	28.0849
1636.52	31.025
1637.57	28.0588
1638.61	29.0385
1639.66	31.0056
1640.7	27.0798
1641.75	26.0875
1642.79	34.9425
1643.83	30.9951
1644.88	30.0116
1645.92	28.0412
1646.96	30.9811
1648.01	29.0161
1649.05	27.072
1650.09	26.0982
1651.13	28.0849
1652.18	26.114
1653.22	28.0806
1654.26	32.0311
1655.3	28.1157
1656.34	25.1717
1657.38	29.1126
1658.42	31.0724
1659.47	27.1091
1660.51	26.1364
1661.55	23.1942
1662.59	28.1699
1663.63	30.102
1664.67	22.2342
1665.71	28.1842
1666.75	28.1362
1667.79	29.1038
1668.83	24.1991
1669.86	27.1596
1670.9	26.1922
1671.94	22.2415
1672.98	24.2202
1674.02	25.22
1675.06	21.2765
1676.1	25.2375
1677.13	25.2351
1678.17	26.2059
1679.21	26.194
1680.25	24.208
1681.28	28.1554
1682.32	24.2039
1683.35	26.1781
1684.39	23.2065
1685.43	22.2179
1686.46	21.2393
1687.5	26.1721
1688.54	25.1707
1689.57	22.1926
1690.6	25.1604
1691.64	28.1283
1692.68	25.1529
1693.71	26.1138
1694.74	22.1641
1695.78	25.1273
1696.81	26.1095
1697.85	28.0544
1698.88	25.0907
1699.92	23.1213
1700.95	26.0664
1701.98	23.0988
1703.01	24.0732
1704.05	26.0395
1705.08	23.0904
1706.11	22.0954
1707.14	27.9603
1708.18	25.9639
1709.21	23.0055
1710.24	24.9656
1711.27	21.0587
1712.3	20.065
1713.33	21.9871
1714.36	20.9995
1715.4	23.9388
1716.43	21.9697
1717.46	27.7807
1718.49	26.776
1719.52	21.9065
1720.55	25.7899
1721.58	24.7943
1722.61	22.8274
1723.64	25.7313
1724.66	21.8294
1725.69	22.7731
1726.72	26.6372
1727.75	27.6044
1728.78	24.6041
1729.81	20.7634
1730.83	27.5434
1731.86	18.8431
1732.89	24.623
1733.92	22.6589
1734.95	23.5931
1735.97	25.5045
1737	20.6809
1738.03	24.5111
1739.05	23.5245
1740.08	22.5281
1741.1	21.5498
1742.13	23.4555
1743.16	21.5347
1744.18	22.4777
1745.21	22.4773
1746.23	24.3697
1747.26	20.5266
1748.28	22.4331
1749.31	21.4899
1750.33	22.463
1751.36	20.5471
1752.38	21.4815
1753.4	25.2813
1754.43	27.1692
1755.45	18.5782
1756.47	23.3152
1757.5	20.4492
1758.52	28.071
1759.54	22.3617
1760.57	25.2055
1761.59	25.1905
1762.61	17.5907
1763.63	21.3972
1764.66	23.3202
1765.68	21.4216
1766.7	21.4178
1767.72	22.3593
1768.74	19.484
1769.76	21.3689
1770.78	23.2831
1771.8	22.3501
1772.82	23.316
1773.84	22.3725
1774.86	27.1446
1775.88	26.2168
1776.9	20.4881
1777.92	20.4737
1778.94	20.4549
1779.96	20.463
1780.98	18.5646
1782	19.5288
1783.02	19.5395
1784.04	25.2768
1785.05	21.4669
1786.07	21.4641
1787.09	22.4402
1788.11	24.4091
1789.12	26.3519
1790.14	17.7358
1791.16	20.5922
1792.18	19.6341
1793.19	21.5553
1794.21	19.6405
1795.23	23.5162
1796.24	22.5732
1797.26	22.5897
1798.27	21.6354
1799.29	23.5474
1800.3	21.6133
1801.32	23.5331
1802.33	23.544
1803.35	22.5995
1804.36	19.7256
1805.38	20.7077
1806.39	22.6477
1807.41	18.7944
1808.42	24.5804
1809.43	21.6925
1810.45	23.6202
1811.46	23.6193
1812.47	23.6305
1813.49	20.7489
1814.5	20.7722
1815.51	23.6797
1816.53	20.7835
1817.54	21.7303
1818.55	20.7768
1819.56	22.719
1820.57	23.697
1821.58	23.7109
1822.6	21.7817
1823.61	23.7126
1824.62	22.7531
1825.63	25.6638
1826.64	21.7929
1827.65	22.7696
1828.66	24.6985
1829.67	22.7562
1830.68	23.7213
1831.69	23.7343
1832.7	25.6859
1833.71	23.7528
1834.72	18.8741
1835.73	22.7269
1836.74	26.6517
1837.75	18.8431
1838.75	19.8599
1839.76	20.8259
1840.77	20.7762
1841.78	21.7084
1842.79	19.7746
1843.79	20.7373
1844.8	19.7732
1845.81	21.7287
1846.81	26.4865
1847.82	15.8982
1848.83	23.5859
1849.83	23.5562
1850.84	24.4938
1851.85	23.5256
1852.85	20.6434
1853.86	23.5037
1854.86	22.5246
1855.87	23.4664
1856.87	23.4638
1857.88	25.3646
1858.88	25.3405
1859.89	22.4675
1860.89	28.2238
1861.9	20.5717
1862.9	19.597
1863.9	24.358
1864.91	20.5183
1865.91	24.2981
1866.92	25.2097
1867.92	20.4389
1868.92	25.1927
1869.92	24.2368
1870.93	19.4818
1871.93	24.2214
1872.93	21.3595
1873.93	23.2444
1874.93	20.3767
1875.94	24.1296
1876.94	24.0948
1877.94	18.4658
1878.94	22.2632
1879.94	22.2488
1880.94	20.3472
1881.94	25.0266
1882.94	26.0675
1883.94	19.33
1884.94	23.1154
1885.94	20.3058
1886.94	20.2873
1887.94	22.1489
1888.94	22.1224
1889.94	23.0684
1890.94	23.0737
1891.94	24.0121
1892.94	21.1618
1893.93	21.1436
1894.93	21.1395
1895.93	21.1504
1896.93	21.1637
1897.93	23.0429
1898.92	23.0233
1899.92	20.196
1900.92	21.1458
1901.91	23.9865
1902.91	23.9804
1903.91	21.1542
1904.9	20.2114
1905.9	21.1346
1906.9	20.1892
1907.89	20.199
1908.89	18.3294
1909.88	23.0576
1910.88	20.2516
1911.87	20.2501
1912.87	21.1923
1913.86	25.9273
1914.86	21.2302
1915.85	21.2288
1916.85	22.158
1917.84	23.1001
1918.84	24.0697
1919.83	25.0406
1920.82	25.0518
1921.82	20.3342
1922.81	23.1611
1923.8	22.2054
1924.79	21.2598
1925.79	23.1741
1926.78	23.197
1927.77	21.3144
1928.76	23.2206
1929.75	21.3483
1930.75	23.2617
1931.74	18.5063
1932.73	22.2923
1933.72	21.3732
1934.71	23.3461
1935.7	22.3971
1936.69	23.3365
1937.68	24.2695
1938.67	24.2834
1939.66	23.3438
1940.65	22.4247
1941.64	23.3575
1942.63	19.5749
1943.62	26.2417
1944.61	24.3575
1945.6	22.468
1946.59	21.5195
1947.58	25.3399
1948.57	23.4304
1949.55	24.4097
1950.54	22.5318
1951.53	21.6021
1952.52	22.573
1953.5	23.5123
1954.49	20.597
1955.48	25.4053
1956.47	24.4845
1957.45	24.5042
1958.44	24.5091
1959.43	24.4978
1960.41	23.5218
1961.4	22.5523
1962.38	21.5969
1963.37	26.4009
1964.36	24.485
1965.34	23.527
1966.33	21.6241
1967.31	25.474
1968.3	25.4744
1969.28	21.6073
1970.26	21.5903
1971.25	23.4989
1972.23	23.5041
1973.22	21.5719
1974.2	22.5247
1975.18	20.6159
1976.17	21.5828
1977.15	22.5383
1978.13	23.4844
1979.12	22.5252
1980.1	21.5629
1981.08	25.3834
1982.06	26.3341
1983.05	20.5699
1984.03	24.3878
1985.01	21.505
1985.99	22.4687
1986.97	20.5571
1987.95	22.4379
1988.93	20.4807
1989.91	25.9818
1990.89	22.4133
1991.88	19.8064
1992.86	25.7208
1993.84	23.1214
1994.82	19.4734
1995.8	23.9253
1996.78	21.7356
1997.76	20.1699
1998.73	23.391
1999.71	21.4653
2000.69	23.3807
2001.67	21.4739
2002.65	21.8009
2003.63	21.132
2004.6	22.5929
2005.58	21.7779
2006.56	21.9678
2007.54	19.9415
2008.52	20.4377
2009.49	21.4166
2010.47	22.2071
2011.45	20.5195
2012.42	19.2986
2013.41	23.03
2014.4	21.115
2015.39	23.9417
2016.38	21.1477
2017.37	20.1936
2018.35	19.2249
2019.34	16.3927
2020.33	20.1355
2021.32	22.9472
2022.31	21.9966
2023.29	21.9758
2024.28	20.084
2025.27	20.0591
2026.25	19.1378
2027.24	21.9869
2028.23	21.9397
2029.21	21.975
2030.2	22.832
2031.19	20.0607
2032.17	21.9483
2033.16	21.0377
2034.14	20.9971
2035.13	20.0814
2036.11	18.2292
2037.1	26.6481
2038.08	21.0273
2039.07	20.0794
2040.05	23.7906
2041.03	21.9083
2042.02	18.1704
2043	22.8337
2043.99	20.9911
2044.97	20.0446
2045.95	21.042
2046.94	22.8632
2047.92	19.1115
2048.9	20.9893
2049.88	23.8171
2050.87	23.8181
2051.85	21.0122
2052.83	21.9578
2053.81	20.1113
2054.79	20.1102
2055.78	17.2954
2056.76	22.9013
2057.74	22.9127
2058.72	22.9333
2059.7	22.9347
2060.68	21.062
2061.66	20.1307
2062.64	19.204
2063.62	22.0262
2064.6	19.2252
2065.58	26.7567
2066.56	22.0723
2067.54	23.024
2068.52	22.0927
2069.5	21.1306
2070.48	21.1619
2071.46	24.0143
2072.43	21.1845
2073.41	23.068
2074.39	21.1978
2075.37	22.1778
2076.35	24.0712
2077.32	20.2746
2078.3	24.0589
2079.28	23.1403
2080.26	24.098
2081.23	25.0378
2082.21	19.3723
2083.19	20.3161
2084.16	22.2066
2085.14	25.0432
2086.12	23.1737
2087.09	21.2931
2088.07	20.3489
2089.04	19.4108
2090.02	22.263
2090.99	21.325
2091.97	21.3505
2092.94	22.3255
2093.92	22.3424
2094.89	23.2875
2095.87	21.3753
2096.84	23.2664
2097.81	20.4094
2098.79	22.3029
2099.76	22.3023
2100.74	23.2654
2101.71	21.3705
2102.68	22.3117
2103.65	22.3072
2104.63	24.2186
2105.6	24.2364
2106.57	17.5887
2107.54	24.2329
2108.52	24.2115
2109.49	22.3244
2110.46	18.5248
2111.43	23.2677
2112.4	23.2707
2113.38	22.3363
2114.35	19.4827
2115.32	23.2804
2116.29	22.3176
2117.26	22.3146
2118.23	20.398
2119.2	20.3802
2120.17	19.4248
2121.14	22.2834
2122.11	22.3014
2123.08	21.3613
2124.05	20.4004
2125.02	18.4718
2125.98	24.129
2126.95	24.111
2127.92	23.1588
2128.89	25.0471
2129.86	23.1517
2130.83	18.419
2131.79	26.9065
2132.76	23.1181
2133.73	25.9525
2134.7	22.177
2135.67	23.1075
2136.63	19.3268
2137.6	22.1622
2138.57	22.1607
2139.53	22.1442
2140.5	23.0754
2141.46	20.2404
2142.43	24.0114
2143.4	20.2009
2144.36	24.9278
2145.33	19.2749
2146.29	26.7881
2147.26	20.1987
2148.22	23.0064
2149.19	23.922
2150.15	21.0895
2151.12	21.0961
2152.08	19.2261
2153.05	23.9014
2154.01	18.263
2154.97	19.1684
2155.94	24.7565
2156.9	20.0853
2157.86	21.966
2158.83	24.7643
2159.79	21.9421
2160.75	21.9288
2161.72	21.9235
2162.68	18.1881
2163.64	20.0447
2164.6	20.9634
2165.56	21.8989
2166.53	21.8871
2167.49	20.9322
2168.45	20.9184
2169.41	21.8686
2170.37	22.8155
2171.33	22.7859
2172.29	25.5514
2173.25	20.9054
2174.21	19.0529
2175.17	19.0503
2176.13	19.9733
2177.09	19.0439
2178.05	21.824
2179.01	22.7481
2179.97	23.6764
2180.93	19.9584
2181.89	21.806
2182.85	22.7208
2183.81	22.7015
2184.76	21.7783
2185.72	24.5722
2186.68	20.8851
2187.64	23.6827
2188.6	19.9517
2189.55	25.4932
2190.51	20.8612
2191.47	23.6481
2192.42	24.5859
2193.38	23.6809
2194.34	22.7767
2195.3	21.8344
2196.25	21.8082
2197.21	19.9414
2198.16	22.7381
2199.12	22.7671
2200.07	20.016
2201.03	22.8255
2201.99	18.0905
2202.94	21.8508
2203.9	22.8428
2204.85	20.9354
2205.8	21.8529
2206.76	21.8507
2207.71	22.7997
2208.67	22.8152
2209.62	20.9546
2210.58	19.1037
2211.53	21.9164
2212.48	21.919
2213.44	21.9101
2214.39	23.8021
2215.34	23.8082
2216.29	23.807
2217.25	18.2062
2218.2	18.2087
2219.15	22.8925
2220.1	22.8969
2221.06	19.1472
2222.01	22.8698
2222.96	21.0141
2223.91	21.0382
2224.86	22.9304
2225.81	20.1422
2226.76	22.9703
2227.72	22.9736
2228.67	24.8433
2229.62	22.0453
2230.57	19.2468
2231.52	18.3245
2232.47	25.8629
2233.42	22.1172
2234.37	23.9976
2235.31	23.0386
2236.26	24.9249
2237.21	22.1223
2238.16	22.1531
2239.11	18.396
2240.06	25.9234
2241.01	22.1736
2241.96	24.0694
2242.9	23.1265
2243.85	25.9522
2244.8	19.3697
2245.75	24.1157
2246.69	23.1842
2247.64	19.4017
2248.59	25.0749
2249.53	23.1887
2250.48	19.389
2251.43	19.3819
2252.37	19.3969
2253.32	23.2168
2254.26	21.3343
2255.21	21.3345
2256.16	20.3984
2257.1	21.3617
2258.05	21.3685
2258.99	20.4293
2259.94	22.3394
2260.88	23.3086
2261.83	24.2678
2262.77	23.3359
2263.71	24.3238
2264.66	23.3968
2265.6	23.4025
2266.55	22.4275
2267.49	21.4587
2268.43	21.4568
2269.38	23.3893
2270.32	23.4136
2271.26	23.43
2272.2	20.5694
2273.15	20.5745
2274.09	23.4509
2275.03	22.5002
2275.97	23.4718
2276.92	21.5772
2277.86	22.5682
2278.8	22.5693
2279.74	21.5839
2280.68	24.4454
2281.62	24.4441
2282.56	19.6674
2283.5	23.542
2284.44	23.5693
2285.38	20.6885
2286.32	23.5686
2287.26	19.7439
2288.2	22.6332
2289.14	26.4556
2290.08	21.6302
2291.02	21.6467
2291.96	23.5898
2292.9	24.5733
2293.84	24.5742
2294.78	23.5963
2295.72	22.6205
2296.65	24.5379
2297.59	20.7107
2298.53	21.6926
2299.47	20.7396
2300.41	20.7455
2301.34	20.7535
2302.28	23.6459
2303.22	21.7143
2304.15	21.7266
2305.09	20.7721
2306.03	23.6803
2306.97	18.8463
2307.9	23.6697
2308.84	19.8126
2309.77	21.7658
2310.71	25.6286
2311.64	20.7546
2312.58	19.7799
2313.51	22.6996
2314.45	22.7306
2315.39	19.8195
2316.32	21.7261
2317.25	24.6308
2318.19	19.7938
2319.12	23.6424
2320.06	23.6415
2320.99	21.7245
2321.92	24.6482
2322.86	22.7201
2323.79	23.6907
2324.72	28.4998
2325.66	31.3715
2326.59	45.8114
2327.52	126.741
2328.46	127.695
2329.39	39.9702
2330.32	32.2622
2331.25	27.456
2332.18	22.6319
2333.12	22.6206
2334.05	22.6064
2334.98	23.5599
2335.91	21.6365
2336.84	24.5167
2337.77	25.4723
2338.7	21.6272
2339.63	23.5448
2340.56	22.5655
2341.49	21.5797
2342.42	21.5689
2343.35	23.4842
2344.28	23.4867
2345.21	21.5575
2346.14	19.6311
2347.07	19.6266
2348	21.5477
2348.93	25.363
2349.85	25.3069
2350.78	23.4206
2351.71	25.2926
2352.64	26.195
2353.57	22.3828
2354.5	23.3458
2355.42	23.3378
2356.35	23.3067
2357.28	26.1425
2358.21	22.328
2359.13	24.2202
2360.06	25.149
2360.99	23.2289
2361.91	21.3102
2362.84	22.2401
2363.77	22.2294
2364.69	19.3803
2364.92	23.1581