File: Data/3-Raman/raw/bu19(2)w-a-ff2b-fi02-v_1800 (450-850nm)_532nm_edge_100%_x100_vis_lwd_h100um_30sx2_01.txt
#Acq. time (s)=	30
#Accumulations=	2
#Range (cm-¹)=	1200...2365
#Windows=	3
#Auto scanning=	Off
#Autofocus=	Off
#Macrospot=	Off
#AutoExposure=	Off
#Spike filter=	Multiple accum.
#Delay time (s)=	2
#Binning=	1
#Readout mode=	Signal
#DeNoise=	Off
#ICS correction=	On
#Dark correction=	Off
#Inst. Process=	Off
#Detector Gain=	Best Dynamic
#Detector ADC=	50 kHz HS
#Detector temperature (°C)=	-60.09
#Instrument=	LabRAM HR Evol
#Detector=	SIN-EM FIVIS
#Objective=	x100_VIS_LWD
#Grating=	1800 (450-850nm)
#ND Filter=	100%
#Laser=	532nm_Edge
#Hole=	100.021
#Temperature=	0
#Range=	Visible
#StageXY=	75x50mm Scan+
#StageZ=	Z motor
#X (µm)=	0
#Y (µm)=	0
#Z (µm)=	-48.5
#Full time(mm:ss)=	3:23
#Project=	21_11_26
#Sample=	BU19(2)w
#Site=
#Title=	BU19(2)w-A-FF2b-FI02-V_1800 (450-850nm)_532nm_Edge_100%_x100_VIS_LWD_H100um_30sX2
#Remark=
#Date=	26.11.2021 16:13
#Acquired=	26.11.2021 16:13:37
1202.72	91.9483
1203.84	91.9826
1204.95	87.6132
1206.06	83.1877
1207.17	87.3125
1208.28	85.0763
1209.39	94.6078
1210.5	79.5972
1211.61	84.8084
1212.72	78.2948
1213.83	80.3484
1214.94	79.2703
1216.05	80.3163
1217.16	73.8186
1218.27	75.8556
1219.38	71.5599
1220.49	78.9495
1221.6	77.8588
1222.71	79.8698
1223.81	78.6612
1224.92	71.177
1226.03	76.4565
1227.14	78.549
1228.25	74.1548
1229.35	72.9245
1230.46	76.2787
1231.57	76.0609
1232.67	67.652
1233.78	77.0879
1234.89	80.2664
1235.99	81.3504
1237.1	81.3285
1238.2	78.0714
1239.31	77.9755
1240.41	77.9447
1241.52	81.0941
1242.62	78.9641
1243.73	76.8888
1244.83	80.0291
1245.94	67.384
1247.04	85.1371
1248.14	83.02
1249.25	81.9238
1250.35	88.1937
1251.45	81.8412
1252.56	82.8225
1253.66	83.8048
1254.76	84.8924
1255.87	83.8578
1256.97	91.1837
1258.07	109.955
1259.17	98.4133
1260.27	95.34
1261.37	116.095
1262.48	164.438
1263.58	216.132
1264.68	174.975
1265.78	124.64
1266.88	108.962
1267.98	100.696
1269.08	98.7314
1270.18	98.728
1271.28	98.6318
1272.38	96.5449
1273.47	101.895
1274.57	105.136
1275.67	111.439
1276.77	111.52
1277.87	108.456
1278.97	120.119
1280.07	154.85
1281.16	288.438
1282.26	819.142
1283.36	2262.3
1284.45	1637.18
1285.55	375.145
1286.65	167.641
1287.75	126.516
1288.84	104.378
1289.94	111.807
1291.03	100.247
1292.13	103.391
1293.22	88.6373
1294.32	84.524
1295.42	95.0864
1296.51	83.6573
1297.61	91.0383
1298.7	85.7016
1299.79	85.6516
1300.89	86.7293
1301.98	82.5134
1303.08	83.5876
1304.17	76.16
1305.26	75.0922
1306.35	77.1329
1307.45	75.0044
1308.54	77.115
1309.63	71.8587
1310.73	68.7
1311.82	78.2051
1312.91	67.6791
1314	70.82
1315.09	72.9338
1316.18	74.0235
1317.28	75.0629
1318.37	67.6874
1319.46	64.517
1320.55	60.2877
1321.64	76.0771
1322.73	63.3465
1323.82	75.9723
1324.91	63.3187
1326	75.9174
1327.09	76.8399
1328.18	74.8594
1329.27	74.9451
1330.35	72.8208
1331.44	70.647
1332.53	68.4355
1333.62	67.2893
1334.71	73.5089
1335.79	68.1981
1336.88	67.1029
1337.97	69.1678
1339.06	69.1091
1340.14	69.1021
1341.23	76.4341
1342.32	65.9319
1343.4	63.7778
1344.49	72.1343
1345.58	68.9596
1346.66	66.7707
1347.75	72.9417
1348.83	65.608
1349.92	65.5565
1351	69.6634
1352.09	65.4476
1353.17	71.7274
1354.25	75.9614
1355.34	72.6628
1356.42	74.7286
1357.51	74.6873
1358.59	70.4841
1359.67	82.8753
1360.76	80.7193
1361.84	79.6535
1362.92	83.7609
1364	79.6413
1365.09	92.061
1366.17	83.6988
1367.25	90.839
1368.33	93.932
1369.41	188.04
1370.5	90.822
1371.58	93.8389
1372.66	97.8231
1373.74	93.6292
1374.82	90.5041
1375.9	99.7687
1376.98	107.956
1378.06	102.766
1379.14	118.394
1380.22	140.999
1381.3	140.704
1382.38	156.989
1383.46	195.74
1384.54	297.124
1385.61	649.389
1386.69	3235.02
1387.77	3611.67
1388.85	531.663
1389.93	215.431
1391	149.479
1392.08	138.084
1393.16	117.497
1394.23	106.191
1395.31	104.134
1396.39	94.9501
1397.46	91.828
1398.54	89.7582
1399.62	93.8851
1400.69	78.5585
1401.77	90.8805
1402.84	91.0149
1403.92	93.1494
1404.99	105.391
1406.07	113.521
1407.14	168.834
1408.22	279.609
1409.29	279.687
1410.37	133.056
1411.44	95.0008
1412.51	80.6345
1413.59	76.7424
1414.66	68.4378
1415.73	68.4651
1416.81	64.375
1417.88	64.4012
1418.95	70.5751
1420.02	62.3344
1421.1	61.2542
1422.17	63.3078
1423.24	55.2062
1424.31	66.2998
1425.38	69.3752
1426.45	62.2099
1427.52	62.1442
1428.59	57.9857
1429.67	55.9504
1430.74	57.0204
1431.81	55.0373
1432.87	55.0028
1433.95	57.9897
1435.01	53.9074
1436.08	53.9032
1437.15	54.9071
1438.22	46.6959
1439.29	60.0264
1440.36	54.9408
1441.43	48.7992
1442.49	47.7645
1443.56	50.834
1444.63	50.8197
1445.7	49.8301
1446.77	48.7842
1447.83	54.9138
1448.9	49.7989
1449.97	50.8128
1451.03	46.6845
1452.1	48.7132
1453.17	49.7318
1454.23	41.5379
1455.3	52.8027
1456.36	50.7614
1457.43	45.6141
1458.49	43.5538
1459.56	44.5822
1460.62	47.6451
1461.69	39.428
1462.75	40.4198
1463.82	38.3345
1464.88	42.4678
1465.94	44.3791
1467.01	41.3001
1468.07	40.2691
1469.13	43.3195
1470.2	42.2679
1471.26	39.1855
1472.32	45.2698
1473.39	40.1675
1474.45	41.1614
1475.51	40.1468
1476.57	44.1984
1477.63	40.1044
1478.69	39.0688
1479.76	40.0549
1480.82	37.9774
1481.88	39.9884
1482.94	37.9826
1484	42.0479
1485.06	40.9425
1486.12	41.9394
1487.18	47.0065
1488.24	34.8253
1489.3	42.8879
1490.36	41.8604
1491.42	45.8783
1492.48	35.7593
1493.53	37.7727
1494.59	37.7675
1495.65	44.8213
1496.71	43.7637
1497.77	38.7009
1498.82	34.658
1499.88	40.7189
1500.94	38.6991
1502	38.6795
1503.05	43.7045
1504.11	39.6451
1505.17	38.6368
1506.22	37.59
1507.28	41.6198
1508.34	38.5932
1509.39	39.5974
1510.45	37.5841
1511.5	38.5525
1512.56	36.462
1513.61	38.4246
1514.67	42.4637
1515.72	34.3928
1516.78	42.3789
1517.83	42.3681
1518.88	41.3775
1519.94	39.3785
1520.99	40.3726
1522.05	36.3627
1523.1	37.3457
1524.15	37.2985
1525.2	41.2838
1526.26	41.2974
1527.31	37.3062
1528.36	43.2999
1529.41	37.2697
1530.47	38.256
1531.52	40.2817
1532.57	35.262
1533.62	38.305
1534.67	42.3196
1535.72	40.2903
1536.77	36.2245
1537.82	39.1813
1538.87	36.154
1539.92	34.2026
1540.97	37.2645
1542.02	36.2344
1543.07	40.1984
1544.12	42.1477
1545.17	38.1676
1546.22	38.2014
1547.27	40.2093
1548.32	38.1815
1549.37	40.1564
1550.42	41.1676
1551.46	34.2584
1552.51	38.2715
1553.56	40.2451
1554.61	39.2083
1555.65	39.1687
1556.7	42.1661
1557.75	39.1632
1558.79	42.1297
1559.84	39.0772
1560.89	40.0522
1561.93	40.0556
1562.98	39.0733
1564.02	36.0617
1565.07	33.085
1566.11	36.8549
1567.16	37.0083
1568.2	38.0331
1569.25	41.0378
1570.29	41.0127
1571.34	37.0099
1572.38	38.986
1573.43	37.9591
1574.47	36.9526
1575.51	34.9867
1576.56	38.9847
1577.6	40.9297
1578.64	33.8982
1579.69	37.8792
1580.73	35.892
1581.77	40.855
1582.81	39.831
1583.85	37.8268
1584.9	40.8127
1585.94	35.8261
1586.98	37.7844
1588.02	38.7604
1589.06	37.7747
1590.1	42.7633
1591.14	37.792
1592.18	39.771
1593.22	37.7391
1594.26	39.6657
1595.3	44.6367
1596.34	35.6777
1597.38	44.6175
1598.42	40.6421
1599.46	37.6234
1600.5	38.5847
1601.54	45.4727
1602.58	48.3912
1603.62	38.4544
1604.66	40.4189
1605.69	36.4633
1606.73	41.4226
1607.77	42.4373
1608.81	40.4255
1609.84	39.097
1610.88	45.4135
1611.92	39.0357
1612.95	39.775
1613.99	42.7712
1615.03	39.673
1616.06	37.9212
1617.1	45.0374
1618.13	41.3296
1619.17	43.7986
1620.2	43.1759
1621.24	43.7375
1622.27	42.9519
1623.31	42.7627
1624.34	42.5557
1625.38	43.4796
1626.41	43.2312
1627.45	43.2266
1628.48	41.311
1629.51	41.2815
1630.55	43.894
1631.53	39.2709
1632.57	49.1385
1633.62	45.1877
1634.66	39.2795
1635.71	42.2279
1636.75	47.1308
1637.8	44.1455
1638.84	44.1272
1639.89	37.2318
1640.93	40.1864
1641.98	41.1658
1643.02	44.1053
1644.06	45.0773
1645.11	40.1342
1646.15	48.0138
1647.19	43.0717
1648.24	41.0861
1649.28	48.0082
1650.32	44.0646
1651.37	45.0847
1652.41	38.1902
1653.45	40.1468
1654.49	46.0631
1655.53	45.0922
1656.57	41.186
1657.62	38.2208
1658.66	40.1756
1659.7	41.1335
1660.74	43.0941
1661.78	42.1334
1662.82	44.1515
1663.86	45.1399
1664.9	42.143
1665.94	41.0974
1666.98	41.1443
1668.02	40.1302
1669.06	41.1203
1670.1	44.1085
1671.14	41.1705
1672.18	45.1116
1673.21	40.169
1674.25	40.1736
1675.29	42.1702
1676.33	41.1856
1677.37	39.2051
1678.4	40.1705
1679.44	36.1848
1680.48	44.0727
1681.52	37.1371
1682.55	37.1312
1683.59	42.063
1684.63	41.06
1685.66	35.1223
1686.7	43.0214
1687.73	39.0755
1688.77	39.0535
1689.81	39.0211
1690.84	39.9926
1691.88	40.9891
1692.91	38.019
1693.95	41.9198
1694.98	35.9732
1696.01	38.929
1697.05	34.9929
1698.08	42.8378
1699.12	36.8992
1700.15	37.8766
1701.18	42.7805
1702.22	42.7537
1703.25	40.7569
1704.28	34.847
1705.32	37.7966
1706.35	44.66
1707.38	41.6683
1708.41	37.6954
1709.44	30.79
1710.48	32.7359
1711.51	38.6178
1712.54	40.5738
1713.57	40.5075
1714.6	38.5064
1715.63	42.4086
1716.66	40.4488
1717.69	39.4171
1718.72	30.5816
1719.75	38.3539
1720.78	40.294
1721.81	37.3359
1722.84	42.1529
1723.87	37.2613
1724.9	36.2737
1725.93	37.1879
1726.96	38.138
1727.99	38.1216
1729.02	37.0744
1730.05	40.8953
1731.07	43.7619
1732.1	41.8754
1733.13	37.9885
1734.16	36.0036
1735.18	37.8803
1736.21	39.764
1737.24	37.8161
1738.26	38.7505
1739.29	36.7901
1740.32	41.525
1741.34	33.8067
1742.37	34.7355
1743.4	37.5911
1744.42	38.5237
1745.45	35.6409
1746.47	35.6222
1747.5	41.3096
1748.52	39.3705
1749.55	37.4649
1750.57	31.7566
1751.6	40.3692
1752.62	41.281
1753.64	38.3779
1754.67	41.2037
1755.69	37.3643
1756.71	39.2303
1757.74	39.1838
1758.76	42.0461
1759.78	41.0935
1760.81	42.0285
1761.83	39.1437
1762.85	41.9879
1763.87	41.037
1764.89	43.9176
1765.92	41.0764
1766.94	40.1163
1767.96	41.0507
1768.98	40.0768
1770	39.9988
1771.02	44.7654
1772.04	42.8958
1773.06	42.9156
1774.08	41.9775
1775.1	41.034
1776.12	42.9752
1777.14	42.0168
1778.16	41.985
1779.18	44.8001
1780.2	37.1743
1781.22	37.1817
1782.24	43.8534
1783.26	38.1603
1784.28	40.0819
1785.29	44.8746
1786.31	39.1347
1787.33	37.2397
1788.35	36.3492
1789.37	42.1436
1790.38	44.0933
1791.4	38.3322
1792.42	39.2549
1793.43	36.3882
1794.45	41.1819
1795.47	38.3364
1796.48	42.2154
1797.5	34.5556
1798.51	33.6065
1799.53	36.4825
1800.55	39.3351
1801.56	30.6737
1802.58	37.3997
1803.59	31.653
1804.61	36.4716
1805.62	37.4603
1806.64	34.5947
1807.65	38.4542
1808.66	35.5598
1809.68	35.5599
1810.69	35.5595
1811.7	37.4777
1812.72	38.4427
1813.73	39.4227
1814.74	36.5569
1815.76	39.4792
1816.77	34.6497
1817.78	36.556
1818.79	33.6582
1819.8	37.5295
1820.82	31.7397
1821.83	33.6855
1822.84	35.6306
1823.85	34.6576
1824.86	35.622
1825.87	39.5037
1826.88	34.6587
1827.89	40.4766
1828.9	32.72
1829.91	37.547
1830.92	41.3995
1831.93	36.5681
1832.94	40.4613
1833.95	36.59
1834.96	33.6541
1835.97	39.4013
1836.98	32.7454
1837.99	43.2829
1839	32.6292
1840	37.5145
1841.01	41.3045
1842.02	31.5694
1843.03	40.2185
1844.04	37.3194
1845.04	43.1035
1846.05	35.3913
1847.06	39.2847
1848.07	32.4062
1849.07	34.3327
1850.08	34.3011
1851.09	31.371
1852.09	34.226
1853.1	35.179
1854.1	32.2801
1855.11	33.1999
1856.11	33.1627
1857.12	35.068
1858.12	34.0922
1859.13	38.8423
1860.13	33.0736
1861.14	31.1698
1862.14	33.0956
1863.15	32.1123
1864.15	33.9897
1865.15	34.9138
1866.16	38.6784
1867.16	34.7997
1868.16	35.7013
1869.17	36.6427
1870.17	33.7791
1871.17	29.9665
1872.17	32.8001
1873.18	36.5727
1874.18	33.7053
1875.18	28.9277
1876.18	30.7734
1877.18	32.627
1878.18	35.4081
1879.19	31.6776
1880.19	38.3258
1881.19	37.3693
1882.19	38.2544
1883.19	31.5648
1884.19	33.4102
1885.19	35.308
1886.19	29.6836
1887.19	35.3384
1888.19	37.1852
1889.19	34.3041
1890.19	32.3968
1891.19	33.3538
1892.18	35.2248
1893.18	32.3799
1894.18	34.2045
1895.18	33.244
1896.18	35.1292
1897.18	36.0878
1898.17	32.3297
1899.17	39.8266
1900.17	37.915
1901.16	34.1509
1902.16	36.0529
1903.16	37.9428
1904.16	32.2817
1905.15	36.0314
1906.15	38.8312
1907.14	32.2249
1908.14	33.1631
1909.14	31.2932
1910.13	36.0196
1911.13	35.1171
1912.12	34.1803
1913.12	36.0532
1914.11	34.181
1915.11	37.9826
1916.1	37.992
1917.1	36.0817
1918.09	34.1734
1919.08	37.9645
1920.08	36.1236
1921.07	35.1805
1922.06	35.2044
1923.06	37.0854
1924.05	34.2292
1925.04	34.2074
1926.04	35.1716
1927.03	31.4207
1928.02	35.2239
1929.01	35.2341
1930	40.9483
1931	40.0384
1931.99	39.08
1932.98	32.4113
1933.97	36.2075
1934.96	38.2116
1935.95	36.3835
1936.94	34.4376
1937.93	37.2584
1938.92	32.4913
1939.91	33.4576
1940.9	34.4293
1941.89	34.4562
1942.88	28.7386
1943.87	39.2113
1944.86	33.5061
1945.85	36.4012
1946.84	35.4646
1947.83	32.5854
1948.82	37.357
1949.8	30.6789
1950.79	34.5499
1951.78	36.5182
1952.77	34.6226
1953.76	38.464
1954.74	28.7912
1955.73	36.4355
1956.72	34.5737
1957.7	37.4838
1958.69	36.537
1959.68	33.6375
1960.66	36.4964
1961.65	37.4256
1962.63	33.5825
1963.62	37.4228
1964.61	40.3107
1965.59	36.4604
1966.58	35.5147
1967.56	42.2552
1968.55	37.4512
1969.53	41.2693
1970.52	40.2583
1971.5	35.433
1972.48	38.3057
1973.47	41.1697
1974.45	43.0556
1975.44	41.1371
1976.42	41.1538
1977.4	40.1929
1978.39	36.3324
1979.37	39.1913
1980.35	43.0243
1981.33	42.0381
1982.31	43.9333
1983.3	43.9016
1984.28	36.2137
1985.26	49.5776
1986.24	49.5566
1987.22	42.8761
1988.21	41.884
1989.19	42.8451
1990.17	43.7695
1991.15	50.1674
1992.13	46.7084
1993.11	50.1275
1994.09	45.313
1995.07	54.4334
1996.05	52.076
1997.03	49.6409
1998.01	49.3143
1998.99	46.279
1999.97	52.0911
2000.95	52.526
2001.92	54.6708
2002.9	49.9445
2003.88	51.3451
2004.86	49.9442
2005.84	48.8538
2006.81	54.0934
2007.79	53.8068
2008.77	55.3299
2009.75	50.4217
2010.73	54.7996
2011.7	55.7148
2012.68	51.3407
2013.67	53.162
2014.66	53.0738
2015.64	53.9883
2016.63	54.0098
2017.62	54.0437
2018.61	54.9079
2019.6	47.3278
2020.58	47.3053
2021.57	41.6847
2022.56	51.0349
2023.55	44.4369
2024.54	40.6582
2025.52	49.0039
2026.51	46.1636
2027.5	47.2174
2028.48	45.2926
2029.47	46.2976
2030.45	45.2227
2031.44	43.3743
2032.43	47.1131
2033.41	44.3675
2034.4	43.4361
2035.38	43.3679
2036.37	47.1998
2037.35	45.3139
2038.34	41.5598
2039.32	43.4005
2040.31	41.4947
2041.29	40.5195
2042.27	38.6348
2043.26	41.4118
2044.24	43.3236
2045.23	44.2284
2046.21	41.5146
2047.19	36.8073
2048.17	34.8945
2049.16	39.5635
2050.14	38.6721
2051.12	38.6994
2052.11	33.0729
2053.09	38.6862
2054.07	35.9208
2055.05	37.8014
2056.03	36.8464
2057.01	40.5715
2058	41.5143
2058.98	34.9945
2059.96	37.8177
2060.94	35.9302
2061.92	37.8153
2062.9	37.8221
2063.88	35.9694
2064.86	36.9189
2065.84	36.0138
2066.82	36.9731
2067.8	34.1688
2068.78	32.3029
2069.76	40.7495
2070.73	37.9248
2071.71	38.8877
2072.69	35.1737
2073.67	39.8729
2074.65	37.0556
2075.63	38.0424
2076.6	34.306
2077.58	37.1176
2078.56	39.9367
2079.54	39.0131
2080.51	34.3259
2081.49	35.2677
2082.47	37.1553
2083.45	34.3233
2084.42	35.2638
2085.4	37.1533
2086.37	35.2727
2087.35	29.6212
2088.32	36.2522
2089.3	35.3098
2090.28	35.3318
2091.25	33.4461
2092.23	32.5212
2093.2	32.5598
2094.18	36.3907
2095.15	37.3465
2096.13	33.5226
2097.1	33.5116
2098.07	34.4382
2099.05	32.5294
2100.02	32.5225
2101	33.4758
2101.97	34.4444
2102.94	33.4898
2103.92	33.4708
2104.89	32.5258
2105.86	32.546
2106.83	31.6079
2107.8	35.4104
2108.78	36.3229
2109.75	33.4716
2110.72	28.7267
2111.69	30.6221
2112.66	32.5099
2113.63	33.4762
2114.61	33.4791
2115.58	31.576
2116.55	33.4595
2117.52	32.4952
2118.49	33.4298
2119.46	34.3427
2120.43	35.2626
2121.4	35.2686
2122.37	33.4006
2123.34	34.3673
2124.31	35.3119
2125.28	33.368
2126.25	33.3199
2127.21	33.2878
2128.18	26.6541
2129.15	33.2644
2130.12	29.4742
2131.09	33.2427
2132.06	36.9987
2133.02	36.9746
2133.99	28.4781
2134.96	32.2525
2135.93	34.1306
2136.89	32.2115
2137.86	33.159
2138.83	32.2023
2139.79	35.0361
2140.76	31.2367
2141.73	31.2265
2142.69	33.0909
2143.66	34.9981
2144.62	32.1066
2145.59	32.1059
2146.55	33.0379
2147.52	36.7811
2148.48	32.065
2149.45	34.8593
2150.42	32.004
2151.38	34.8061
2152.34	32.9452
2153.31	30.1194
2154.27	31.9758
2155.24	36.6072
2156.2	32.8187
2157.16	35.6068
2158.13	27.208
2159.09	31.8831
2160.05	34.6648
2161.01	33.6976
2161.98	30.8845
2162.94	27.1488
2163.9	30.8647
2164.86	35.4999
2165.83	25.2469
2166.79	29.8978
2167.75	32.6666
2168.71	27.0411
2169.67	30.7688
2170.63	30.8044
2171.59	34.5177
2172.56	29.8111
2173.51	29.7982
2174.48	32.5922
2175.44	31.6615
2176.4	32.5815
2177.36	34.4272
2178.32	33.498
2179.28	28.8337
2180.23	32.5473
2181.19	36.2531
2182.15	34.3829
2183.11	31.5847
2184.07	27.8458
2185.03	35.2473
2185.99	33.4043
2186.95	29.7182
2187.9	31.6061
2188.86	31.5907
2189.82	31.5551
2190.78	25.9774
2191.73	30.617
2192.69	30.6253
2193.65	34.3537
2194.6	33.4722
2195.56	29.7491
2196.52	32.5026
2197.47	34.3257
2198.43	33.3957
2199.38	33.4314
2200.34	35.3373
2201.3	29.8051
2202.25	34.348
2203.21	30.6838
2204.16	33.5926
2205.12	33.5295
2206.07	32.5179
2207.03	34.3723
2207.98	33.4607
2208.93	32.5548
2209.89	30.7004
2210.84	28.8437
2211.8	30.7245
2212.75	33.5412
2213.7	30.7276
2214.66	26.0757
2215.61	31.6919
2216.56	33.5592
2217.51	30.7527
2218.47	32.6201
2219.42	30.7649
2220.37	29.8444
2221.32	32.6396
2222.27	33.5414
2223.23	27.0058
2224.18	31.6991
2225.13	30.7953
2226.08	31.7597
2227.03	28.034
2227.98	28.9849
2228.93	33.6638
2229.88	28.0381
2230.83	31.8146
2231.78	26.2049
2232.73	28.1037
2233.68	31.8858
2234.63	29.0725
2235.58	35.6333
2236.53	28.103
2237.48	28.1119
2238.43	31.9178
2239.38	32.8978
2240.33	25.3379
2241.27	29.1209
2242.22	33.8455
2243.17	35.7434
2244.12	28.1778
2245.07	31.021
2246.01	31.0564
2246.96	28.2378
2247.91	29.1951
2248.85	32.973
2249.8	27.2938
2250.75	32.0171
2251.69	30.0997
2252.64	29.1596
2253.59	31.094
2254.53	31.1205
2255.48	26.3812
2256.42	30.1798
2257.37	25.4533
2258.32	29.2621
2259.26	29.2704
2260.2	26.4304
2261.15	28.3422
2262.1	35.9705
2263.04	28.3713
2263.98	29.3551
2264.93	29.3947
2265.87	31.3227
2266.81	28.4412
2267.76	25.5551
2268.7	27.4445
2269.65	30.3228
2270.59	26.5375
2271.53	29.4228
2272.47	28.4809
2273.42	31.3547
2274.36	28.4884
2275.3	28.493
2276.24	26.5828
2277.18	28.5221
2278.13	31.4374
2279.07	29.5357
2280.01	33.3513
2280.95	31.3989
2281.89	26.5903
2282.83	27.5613
2283.77	28.5512
2284.71	28.5959
2285.65	29.5751
2286.59	24.7466
2287.54	27.6606
2288.47	28.6349
2289.41	35.3489
2290.35	29.5335
2291.29	27.6108
2292.23	28.5991
2293.17	32.4743
2294.11	30.561
2295.05	30.5427
2295.99	28.598
2296.93	27.6106
2297.86	30.5144
2298.8	27.6517
2299.74	30.5671
2300.68	29.6026
2301.61	26.721
2302.55	27.6834
2303.49	25.748
2304.43	31.5452
2305.36	32.5286
2306.3	30.6063
2307.24	30.6098
2308.17	29.6317
2309.11	30.5921
2310.04	29.6504
2310.98	29.6578
2311.92	27.6779
2312.85	28.6151
2313.79	28.6211
2314.72	26.723
2315.66	31.5737
2316.59	30.5656
2317.52	32.4828
2318.46	30.5546
2319.39	29.5682
2320.33	30.5215
2321.26	29.5625
2322.2	31.5181
2323.13	39.2697
2324.06	40.2447
2325	49.8975
2325.93	65.2908
2326.86	122.16
2327.79	429.596
2328.73	245.406
2329.66	82.4588
2330.59	49.7023
2331.52	36.2103
2332.46	31.4018
2333.39	32.343
2334.32	30.4009
2335.25	34.2247
2336.18	26.5294
2337.11	33.2513
2338.04	26.5128
2338.97	30.35
2339.91	28.4263
2340.84	29.3692
2341.77	29.3315
2342.7	29.306
2343.63	33.133
2344.56	31.2135
2345.49	28.3308
2346.41	30.2213
2347.34	28.2961
2348.27	31.166
2349.2	31.1671
2350.13	32.0734
2351.06	29.0635
2351.99	31.0894
2352.91	30.0859
2353.84	32.8977
2354.77	28.1333
2355.7	29.0855
2356.63	30.0147
2357.55	24.2698
2358.48	30.9067
2359.41	28.0401
2360.33	33.7185
2361.26	30.839
2362.19	32.7008
2363.11	31.7199
2364.04	28.8612
2364.97	25.06