File: Data/3-Raman/raw/bu19(2)w-a-ff1-fi02-v_1800 (450-850nm)_532nm_edge_100%_x100_vis_lwd_h50um_30sx2_01.txt
#Acq. time (s)=	30
#Accumulations=	2
#Range (cm-¹)=	1200...2365
#Windows=	3
#Auto scanning=	Off
#Autofocus=	Off
#Macrospot=	Off
#AutoExposure=	Off
#Spike filter=	Multiple accum.
#Delay time (s)=	2
#Binning=	1
#Readout mode=	Signal
#DeNoise=	Off
#ICS correction=	On
#Dark correction=	Off
#Inst. Process=	Off
#Detector Gain=	Best Dynamic
#Detector ADC=	50 kHz HS
#Detector temperature (°C)=	-60.09
#Instrument=	LabRAM HR Evol
#Detector=	SIN-EM FIVIS
#Objective=	x100_VIS_LWD
#Grating=	1800 (450-850nm)
#ND Filter=	100%
#Laser=	532nm_Edge
#Hole=	49.98
#Temperature=	0
#Range=	Visible
#StageXY=	75x50mm Scan+
#StageZ=	Z motor
#X (µm)=	0
#Y (µm)=	0
#Z (µm)=	-9.4
#Full time(mm:ss)=	3:15
#Project=	21_11_26
#Sample=	BU19(2)w
#Site=
#Title=	BU19(2)w-A-FF1-FI02-V_1800 (450-850nm)_532nm_Edge_100%_x100_VIS_LWD_H50um_30sX2
#Remark=
#Date=	26.11.2021 11:57
#Acquired=	26.11.2021 11:57:19
1202.72	769.462
1203.84	778.214
1204.95	772.112
1206.06	795.507
1207.17	775.61
1208.28	770.341
1209.39	790.751
1210.5	784.87
1211.61	757.889
1212.72	783.328
1213.83	783.496
1214.94	764.065
1216.05	794.619
1217.16	762.468
1218.27	767.809
1219.38	780.948
1220.49	798.465
1221.6	768.334
1222.71	767.141
1223.81	782.454
1224.92	802.495
1226.03	766.472
1227.14	786.206
1228.25	794.782
1229.35	795.87
1230.46	783.108
1231.57	789.133
1232.67	816.279
1233.78	772.865
1234.89	781.398
1235.99	804.711
1237.1	783.335
1238.2	776.906
1239.31	803.074
1240.41	796.332
1241.52	787.857
1242.62	798.914
1243.73	814.719
1244.83	797.766
1245.94	796.854
1247.04	796.235
1248.14	828.311
1249.25	815.12
1250.35	803.425
1251.45	774.313
1252.56	809.08
1253.66	826.08
1254.76	806.539
1255.87	819.026
1256.97	801.275
1258.07	819.703
1259.17	852.503
1260.27	847.664
1261.37	828.806
1262.48	873.318
1263.58	869.745
1264.68	860.865
1265.78	850.445
1266.88	853.419
1267.98	843.626
1269.08	828.874
1270.18	849.654
1271.28	846.583
1272.38	840.218
1273.47	829.526
1274.57	830.157
1275.67	838.475
1276.77	847.346
1277.87	831.066
1278.97	862.157
1280.07	889.496
1281.16	1006.1
1282.26	1471.86
1283.36	2274.85
1284.45	1555.97
1285.55	992.965
1286.65	908.428
1287.75	858.405
1288.84	872.732
1289.94	850.964
1291.03	866.823
1292.13	821.259
1293.22	826.3
1294.32	833.475
1295.42	830.334
1296.51	832.99
1297.61	845.374
1298.7	843.652
1299.79	836.684
1300.89	815.647
1301.98	814.532
1303.08	843.096
1304.17	858.43
1305.26	811.708
1306.35	831.917
1307.45	831.577
1308.54	832.514
1309.63	829.427
1310.73	823.051
1311.82	808.224
1312.91	812.665
1314	840.725
1315.09	823.735
1316.18	869.409
1317.28	828.952
1318.37	852.279
1319.46	821.506
1320.55	823.451
1321.64	839.579
1322.73	817.53
1323.82	800.184
1324.91	819.031
1326	805.653
1327.09	820.954
1328.18	821.152
1329.27	829.364
1330.35	816.412
1331.44	795.505
1332.53	846.783
1333.62	811.825
1334.71	813.864
1335.79	829.782
1336.88	802.866
1337.97	809.697
1339.06	830.861
1340.14	825.414
1341.23	858.814
1342.32	831.082
1343.4	848.987
1344.49	838.269
1345.58	840.82
1346.66	831.087
1347.75	841.354
1348.83	843.901
1349.92	830.606
1351	838.089
1352.09	843.511
1353.17	853.237
1354.25	852.893
1355.34	862.117
1356.42	841.062
1357.51	833.189
1358.59	842.847
1359.67	829.615
1360.76	833.803
1361.84	825.067
1362.92	856.668
1364	877.495
1365.09	903.16
1366.17	862.863
1367.25	866.889
1368.33	869.776
1369.41	921.535
1370.5	870.449
1371.58	885.005
1372.66	856.694
1373.74	855.911
1374.82	861.633
1375.9	874.818
1376.98	872.164
1378.06	899.457
1379.14	887.368
1380.22	897.027
1381.3	902.146
1382.38	939.004
1383.46	953.851
1384.54	1004.38
1385.61	1241.19
1386.69	2501.24
1387.77	3434.76
1388.85	1290.17
1389.93	1004.13
1391	932.673
1392.08	932.746
1393.16	908.273
1394.23	892.388
1395.31	868.623
1396.39	884.078
1397.46	881.39
1398.54	881.017
1399.62	864.848
1400.69	859.861
1401.77	871.36
1402.84	908.448
1403.92	881.428
1404.99	880.617
1406.07	888.056
1407.14	883.516
1408.22	949.221
1409.29	995.483
1410.37	929.892
1411.44	882.642
1412.51	862.83
1413.59	872.285
1414.66	852.576
1415.73	892.843
1416.81	832.368
1417.88	856.228
1418.95	843.883
1420.02	868.154
1421.1	866.245
1422.17	855.864
1423.24	835.934
1424.31	869.835
1425.38	863.546
1426.45	850.284
1427.52	866.666
1428.59	840.048
1429.67	855.49
1430.74	832.509
1431.81	845.757
1432.87	862.541
1433.95	865.144
1435.01	837.616
1436.08	857.933
1437.15	828.807
1438.22	828.412
1439.29	860.295
1440.36	845.4
1441.43	865.981
1442.49	868.788
1443.56	860.363
1444.63	873.338
1445.7	844.124
1446.77	843.668
1447.83	851.376
1448.9	822.759
1449.97	845.016
1451.03	846.475
1452.1	858.291
1453.17	851.933
1454.23	840.632
1455.3	836.3
1456.36	836.334
1457.43	859.375
1458.49	855.984
1459.56	840.6
1460.62	814.693
1461.69	869.443
1462.75	864.558
1463.82	855.408
1464.88	858.268
1465.94	838.138
1467.01	839.73
1468.07	852.674
1469.13	855.442
1470.2	845.524
1471.26	863.24
1472.32	847.31
1473.39	840.882
1474.45	833.163
1475.51	876.906
1476.57	861.152
1477.63	836.131
1478.69	846.821
1479.76	856.234
1480.82	857.136
1481.88	814.026
1482.94	831.716
1484	840.849
1485.06	851.029
1486.12	832.359
1487.18	841.407
1488.24	841.797
1489.3	845.972
1490.36	858.71
1491.42	840.872
1492.48	834.546
1493.53	854.486
1494.59	864.397
1495.65	851.729
1496.71	834.542
1497.77	851.283
1498.82	866.204
1499.88	859.174
1500.94	859.074
1502	869.647
1503.05	846.938
1504.11	838.255
1505.17	850.274
1506.22	854.343
1507.28	860.294
1508.34	854.082
1509.39	823.694
1510.45	868
1511.5	859.964
1512.56	851.005
1513.61	842.82
1514.67	867.32
1515.72	844.28
1516.78	817.226
1517.83	849.003
1518.88	857.194
1519.94	877.335
1520.99	846.951
1522.05	860.99
1523.1	830.344
1524.15	850.223
1525.2	844.66
1526.26	841.853
1527.31	857.184
1528.36	869.701
1529.41	884.217
1530.47	835.71
1531.52	834.11
1532.57	876.886
1533.62	855.623
1534.67	852.583
1535.72	888.089
1536.77	822.553
1537.82	843.454
1538.87	846.738
1539.92	855.896
1540.97	860.211
1542.02	864.482
1543.07	861.412
1544.12	846.207
1545.17	887.611
1546.22	861.297
1547.27	852.302
1548.32	844.658
1549.37	848.973
1550.42	882.147
1551.46	875.65
1552.51	857.432
1553.56	896.724
1554.61	861.77
1555.65	852.778
1556.7	864.546
1557.75	869.521
1558.79	895.634
1559.84	847.396
1560.89	859.76
1561.93	866.749
1562.98	871.064
1564.02	875.712
1565.07	860.263
1566.11	869.545
1567.16	862.207
1568.2	842.743
1569.25	847.777
1570.29	862.145
1571.34	852.95
1572.38	876.332
1573.43	863.61
1574.47	854.353
1575.51	855.051
1576.56	863.994
1577.6	856.751
1578.64	851.541
1579.69	879.214
1580.73	866.347
1581.77	877.719
1582.81	862.075
1583.85	840.803
1584.9	848.639
1585.94	885.268
1586.98	855.516
1588.02	856.984
1589.06	862.1
1590.1	882.181
1591.14	837.455
1592.18	858.996
1593.22	869.905
1594.26	869.39
1595.3	863.421
1596.34	834.123
1597.38	850.932
1598.42	873.648
1599.46	875.626
1600.5	848.038
1601.54	869.666
1602.58	854.703
1603.62	871.534
1604.66	838.522
1605.69	870.073
1606.73	853.502
1607.77	844.985
1608.81	865.438
1609.84	852.812
1610.88	882.032
1611.92	862.122
1612.95	854.935
1613.99	876.112
1615.03	863.125
1616.06	853.984
1617.1	870.533
1618.13	857.163
1619.17	862.567
1620.2	873.981
1621.24	857.231
1622.27	850.708
1623.31	865.877
1624.34	860.23
1625.38	855.596
1626.41	870.175
1627.45	858.742
1628.48	864.636
1629.51	847.193
1630.55	850.131
1631.53	863.989
1632.57	851.426
1633.62	857.119
1634.66	852.249
1635.71	883.57
1636.75	853.494
1637.8	885.36
1638.84	877.075
1639.89	826.727
1640.93	846.409
1641.98	864.968
1643.02	853.815
1644.06	883.055
1645.11	876.63
1646.15	858.048
1647.19	838.881
1648.24	857.15
1649.28	843.011
1650.32	867.448
1651.37	858.238
1652.41	859.242
1653.45	856.927
1654.49	869.776
1655.53	833.529
1656.57	838.196
1657.62	855.835
1658.66	875.12
1659.7	853.76
1660.74	861.37
1661.78	849.02
1662.82	832.051
1663.86	868.562
1664.9	846.119
1665.94	859.665
1666.98	844.815
1668.02	841.25
1669.06	872.86
1670.1	879.278
1671.14	857.05
1672.18	847.855
1673.21	868.561
1674.25	868.626
1675.29	859.086
1676.33	853.207
1677.37	856.113
1678.4	858.524
1679.44	855.837
1680.48	869.215
1681.52	856.916
1682.55	885.401
1683.59	860.501
1684.63	868.043
1685.66	867.73
1686.7	865.698
1687.73	857.864
1688.77	844.507
1689.81	868.434
1690.84	848.336
1691.88	858.373
1692.91	885.756
1693.95	858.12
1694.98	859.298
1696.01	872.089
1697.05	857.41
1698.08	866.424
1699.12	860.762
1700.15	857.629
1701.18	878.902
1702.22	856.674
1703.25	870.735
1704.28	876.261
1705.32	846.811
1706.35	870.052
1707.38	855.34
1708.41	860.118
1709.44	860.868
1710.48	860.53
1711.51	871.455
1712.54	851.774
1713.57	858.156
1714.6	854.176
1715.63	880.4
1716.66	853.859
1717.69	841.895
1718.72	889.062
1719.75	840.866
1720.78	859.176
1721.81	852.445
1722.84	883.521
1723.87	863.294
1724.9	848.312
1725.93	872.188
1726.96	853.302
1727.99	853.87
1729.02	863.623
1730.05	871.29
1731.07	857.111
1732.1	867.644
1733.13	854.572
1734.16	863.895
1735.18	856.87
1736.21	871.296
1737.24	884.209
1738.26	887.388
1739.29	879.737
1740.32	865.76
1741.34	839.69
1742.37	855.23
1743.4	860.559
1744.42	855.189
1745.45	858.688
1746.47	862.035
1747.5	864.775
1748.52	859.33
1749.55	865.112
1750.57	858.985
1751.6	864.949
1752.62	868.751
1753.64	868.813
1754.67	860.359
1755.69	874.995
1756.71	876.916
1757.74	861.57
1758.76	854.094
1759.78	888.291
1760.81	849.845
1761.83	852.939
1762.85	858.436
1763.87	888.82
1764.89	875.078
1765.92	846.77
1766.94	857.985
1767.96	871.849
1768.98	850.4
1770	879.077
1771.02	849.002
1772.04	866.682
1773.06	874.655
1774.08	859.667
1775.1	889.324
1776.12	890.053
1777.14	881.325
1778.16	855.846
1779.18	857.829
1780.2	853.728
1781.22	850.064
1782.24	857.79
1783.26	858.225
1784.28	855.671
1785.29	850.388
1786.31	869.096
1787.33	839.788
1788.35	869.944
1789.37	849.071
1790.38	868.863
1791.4	863.815
1792.42	864.903
1793.43	863.117
1794.45	866.99
1795.47	875.301
1796.48	873.274
1797.5	841.149
1798.51	837.588
1799.53	844.094
1800.55	847.214
1801.56	847.772
1802.58	869.898
1803.59	854.041
1804.61	856.213
1805.62	859.695
1806.64	876.628
1807.65	852.63
1808.66	856.392
1809.68	844.804
1810.69	865.984
1811.7	841.619
1812.72	857.035
1813.73	861.207
1814.74	861.862
1815.76	860.457
1816.77	837.306
1817.78	861.772
1818.79	871.433
1819.8	842.558
1820.82	857.316
1821.83	824.711
1822.84	858.799
1823.85	870.272
1824.86	864.356
1825.87	831.608
1826.88	875.098
1827.89	853.901
1828.9	866.322
1829.91	844.594
1830.92	856.695
1831.93	859.794
1832.94	853.387
1833.95	840.881
1834.96	853.726
1835.97	845.488
1836.98	879.571
1837.99	839.836
1839	833.816
1840	846.466
1841.01	840.765
1842.02	841.954
1843.03	860.363
1844.04	838.028
1845.04	851.413
1846.05	828.361
1847.06	865.745
1848.07	832.741
1849.07	850.085
1850.08	819.45
1851.09	832.693
1852.09	847.355
1853.1	841.395
1854.1	862.022
1855.11	845.616
1856.11	852.305
1857.12	831.913
1858.12	838.149
1859.13	864.089
1860.13	833.688
1861.14	859.728
1862.14	839.007
1863.15	834.474
1864.15	853.644
1865.15	849.982
1866.16	843.01
1867.16	825.23
1868.16	823.072
1869.17	841.842
1870.17	832.982
1871.17	835.542
1872.17	817.024
1873.18	829.659
1874.18	847.202
1875.18	832.984
1876.18	858.099
1877.18	840.943
1878.18	848.063
1879.19	838.943
1880.19	837.586
1881.19	817.456
1882.19	831.21
1883.19	817.016
1884.19	810.318
1885.19	835.11
1886.19	820.949
1887.19	830.132
1888.19	841.428
1889.19	842.006
1890.19	822.547
1891.19	830.458
1892.18	834.837
1893.18	847.489
1894.18	826.279
1895.18	840.773
1896.18	812.712
1897.18	835.684
1898.17	810.368
1899.17	831.361
1900.17	840.027
1901.16	831.401
1902.16	839.437
1903.16	833.033
1904.16	820.341
1905.15	808.771
1906.15	825.213
1907.14	824.471
1908.14	837.582
1909.14	836.87
1910.13	823.402
1911.13	825.228
1912.12	822.502
1913.12	839.172
1914.11	811.171
1915.11	817.499
1916.1	827.106
1917.1	821.827
1918.09	818.442
1919.08	815.076
1920.08	847.275
1921.07	822.728
1922.06	825.163
1923.06	830.572
1924.05	840.469
1925.04	833.294
1926.04	813.886
1927.03	813.739
1928.02	841.587
1929.01	835.179
1930	819.621
1931	839.369
1931.99	843.883
1932.98	817.628
1933.97	836.606
1934.96	833.236
1935.95	817.799
1936.94	795.888
1937.93	822.641
1938.92	830.071
1939.91	803.741
1940.9	812.752
1941.89	809.558
1942.88	822.184
1943.87	828.228
1944.86	806.734
1945.85	802.62
1946.84	821.204
1947.83	797.983
1948.82	825.466
1949.8	794.297
1950.79	802.007
1951.78	793.544
1952.77	808.476
1953.76	819.959
1954.74	801.733
1955.73	781.041
1956.72	821.614
1957.7	808.824
1958.69	820.64
1959.68	825.027
1960.66	806.207
1961.65	829.481
1962.63	786.171
1963.62	811.117
1964.61	800.678
1965.59	822.524
1966.58	810.35
1967.56	803.879
1968.55	818.306
1969.53	788.881
1970.52	797.433
1971.5	806.399
1972.48	824.476
1973.47	803.049
1974.45	798.549
1975.44	780.26
1976.42	796.842
1977.4	826.497
1978.39	790.45
1979.37	798.675
1980.35	795.732
1981.33	788.441
1982.31	803.327
1983.3	818.953
1984.28	797.182
1985.26	806.22
1986.24	790.513
1987.22	795.437
1988.21	796.603
1989.19	800.297
1990.17	806.056
1991.15	820.828
1992.13	797.544
1993.11	813.989
1994.09	797.599
1995.07	796.389
1996.05	783.392
1997.03	796.92
1998.01	792.905
1998.99	799.181
1999.97	798.47
2000.95	812.436
2001.92	787.142
2002.9	806.35
2003.88	797.267
2004.86	790.249
2005.84	797.29
2006.81	812.525
2007.79	792.607
2008.77	798.565
2009.75	801.406
2010.73	800.868
2011.7	791.781
2012.68	800.648
2013.67	821.345
2014.66	808.713
2015.64	790.507
2016.63	784.24
2017.62	757.472
2018.61	792.086
2019.6	817.109
2020.58	813.908
2021.57	794.226
2022.56	793.034
2023.55	801.618
2024.54	796.227
2025.52	796.076
2026.51	796.32
2027.5	776.856
2028.48	770.32
2029.47	796.76
2030.45	770.061
2031.44	773.166
2032.43	802.197
2033.41	784.495
2034.4	768.665
2035.38	791.723
2036.37	790.576
2037.35	774.412
2038.34	780.702
2039.32	799.801
2040.31	800.953
2041.29	768.426
2042.27	784.818
2043.26	777.935
2044.24	801.195
2045.23	769.925
2046.21	787.354
2047.19	794.991
2048.17	779.968
2049.16	768.013
2050.14	773.505
2051.12	771.257
2052.11	775.451
2053.09	789.688
2054.07	781.163
2055.05	798.225
2056.03	772.566
2057.01	775.091
2058	761.221
2058.98	782.363
2059.96	778.025
2060.94	774.901
2061.92	768.631
2062.9	774.396
2063.88	773.909
2064.86	771.367
2065.84	772.075
2066.82	777.217
2067.8	773.769
2068.78	772.22
2069.76	789.834
2070.73	774.694
2071.71	788.329
2072.69	770.571
2073.67	784.526
2074.65	765.852
2075.63	762.057
2076.6	780.796
2077.58	765.278
2078.56	786.758
2079.54	774.894
2080.51	747.294
2081.49	792.591
2082.47	761.377
2083.45	743.492
2084.42	760.417
2085.4	779.317
2086.37	771.976
2087.35	779.162
2088.32	791.656
2089.3	727.392
2090.28	749.643
2091.25	765.015
2092.23	762.724
2093.2	771.247
2094.18	782.408
2095.15	780.627
2096.13	774.45
2097.1	789.408
2098.07	769.899
2099.05	763.981
2100.02	774.272
2101	770.591
2101.97	750.145
2102.94	784.243
2103.92	759.13
2104.89	750.702
2105.86	780.64
2106.83	757.195
2107.8	773.367
2108.78	774.462
2109.75	762.083
2110.72	741.313
2111.69	762.117
2112.66	765.647
2113.63	761.294
2114.61	768.979
2115.58	765.137
2116.55	782.806
2117.52	757.785
2118.49	759.357
2119.46	771.839
2120.43	748.487
2121.4	781.799
2122.37	740.723
2123.34	771.499
2124.31	749.578
2125.28	746.671
2126.25	761.695
2127.21	729.763
2128.18	749.281
2129.15	745.341
2130.12	747.019
2131.09	731.653
2132.06	753.862
2133.02	725.066
2133.99	765.585
2134.96	750.493
2135.93	756.903
2136.89	753.338
2137.86	705.372
2138.83	760.693
2139.79	750.467
2140.76	752.631
2141.73	748.635
2142.69	721.856
2143.66	734.62
2144.62	737.836
2145.59	739.716
2146.55	748.945
2147.52	732.63
2148.48	773.567
2149.45	750.53
2150.42	727.119
2151.38	740.966
2152.34	717.847
2153.31	745.696
2154.27	739.652
2155.24	724.534
2156.2	745.03
2157.16	746.586
2158.13	768.341
2159.09	758.137
2160.05	728.701
2161.01	747.594
2161.98	728.63
2162.94	764.002
2163.9	730.061
2164.86	723.914
2165.83	736.913
2166.79	747.906
2167.75	727.769
2168.71	743.455
2169.67	750.202
2170.63	746.437
2171.59	739.681
2172.56	743.987
2173.51	719.528
2174.48	726.196
2175.44	725.251
2176.4	728.771
2177.36	718.294
2178.32	730.375
2179.28	729.904
2180.23	739.198
2181.19	750.178
2182.15	728.55
2183.11	735.662
2184.07	722.894
2185.03	747.644
2185.99	711.736
2186.95	744.744
2187.9	725.096
2188.86	717.329
2189.82	716.532
2190.78	725.458
2191.73	724.658
2192.69	704.465
2193.65	722.483
2194.6	732.798
2195.56	728.045
2196.52	743.064
2197.47	715.437
2198.43	711.686
2199.38	729.176
2200.34	714.377
2201.3	717.424
2202.25	717.806
2203.21	721.796
2204.16	713.155
2205.12	723.007
2206.07	718.457
2207.03	731.376
2207.98	724.342
2208.93	712.796
2209.89	703.676
2210.84	715.018
2211.8	730.362
2212.75	731.743
2213.7	719.279
2214.66	708.403
2215.61	713.498
2216.56	706.975
2217.51	730.202
2218.47	726.487
2219.42	721.186
2220.37	712.187
2221.32	697.059
2222.27	718.796
2223.23	713.208
2224.18	716.586
2225.13	727.61
2226.08	717.051
2227.03	728.84
2227.98	703.886
2228.93	699.936
2229.88	736.516
2230.83	739.01
2231.78	718.977
2232.73	705.413
2233.68	694.614
2234.63	706.15
2235.58	707.484
2236.53	685.728
2237.48	684.083
2238.43	701.968
2239.38	706.561
2240.33	721.315
2241.27	713.118
2242.22	692.522
2243.17	696.508
2244.12	701.865
2245.07	700.265
2246.01	706.752
2246.96	708.155
2247.91	714.127
2248.85	684.629
2249.8	707.328
2250.75	703.369
2251.69	711.308
2252.64	680.248
2253.59	723.824
2254.53	723.511
2255.48	697.961
2256.42	695.268
2257.37	704.266
2258.32	719.775
2259.26	690.551
2260.2	712.692
2261.15	677.807
2262.1	700.098
2263.04	691.869
2263.98	703.122
2264.93	697.409
2265.87	684.47
2266.81	683.151
2267.76	701.67
2268.7	685.959
2269.65	695.919
2270.59	688.165
2271.53	686.72
2272.47	682.297
2273.42	694.834
2274.36	671.03
2275.3	663.496
2276.24	684.694
2277.18	696.794
2278.13	696.732
2279.07	696.21
2280.01	693.753
2280.95	666.191
2281.89	697.48
2282.83	690.149
2283.77	680.355
2284.71	687.21
2285.65	684.746
2286.59	698.737
2287.54	671.557
2288.47	702.669
2289.41	701.126
2290.35	682.897
2291.29	698.302
2292.23	653.739
2293.17	699.53
2294.11	687.322
2295.05	680.18
2295.99	697.099
2296.93	673.409
2297.86	671.887
2298.8	665.779
2299.74	674.037
2300.68	661.512
2301.61	688.862
2302.55	674.335
2303.49	670.364
2304.43	682.103
2305.36	660.273
2306.3	692.383
2307.24	664.446
2308.17	665.167
2309.11	677.609
2310.04	656.91
2310.98	666.761
2311.92	667.622
2312.85	688.199
2313.79	674.846
2314.72	668.924
2315.66	662.542
2316.59	671.328
2317.52	662.339
2318.46	688.494
2319.39	646.527
2320.33	656.896
2321.26	656.076
2322.2	674.966
2323.13	655.061
2324.06	683.236
2325	653.029
2325.93	678.347
2326.86	709.584
2327.79	827.553
2328.73	746.369
2329.66	689.025
2330.59	681.232
2331.52	660.876
2332.46	646.578
2333.39	654.809
2334.32	658.314
2335.25	680.907
2336.18	659.727
2337.11	668.182
2338.04	659.351
2338.97	659.188
2339.91	676.472
2340.84	642.443
2341.77	665.617
2342.7	645.877
2343.63	671.606
2344.56	667.734
2345.49	645.544
2346.41	649.78
2347.34	656.272
2348.27	633.248
2349.2	669.668
2350.13	642.791
2351.06	631.125
2351.99	662.297
2352.91	668.885
2353.84	641.2
2354.77	629.753
2355.7	652.618
2356.63	666.399
2357.55	632.256
2358.48	667.028
2359.41	617.282
2360.33	645.375
2361.26	650.425
2362.19	653.521
2363.11	672.723
2364.04	641.081
2364.97	638.789