File: Data/3-Raman/raw/bu19(2)w-a-ff2-fi02-v_1800 (450-850nm)_532nm_edge_100%_x100_vis_lwd_h50um_30sx2_01.txt
#Acq. time (s)=	30
#Accumulations=	2
#Range (cm-¹)=	1200...2365
#Windows=	3
#Auto scanning=	Off
#Autofocus=	Off
#Macrospot=	Off
#AutoExposure=	Off
#Spike filter=	Multiple accum.
#Delay time (s)=	2
#Binning=	1
#Readout mode=	Signal
#DeNoise=	Off
#ICS correction=	On
#Dark correction=	Off
#Inst. Process=	Off
#Detector Gain=	Best Dynamic
#Detector ADC=	50 kHz HS
#Detector temperature (°C)=	-60.09
#Instrument=	LabRAM HR Evol
#Detector=	SIN-EM FIVIS
#Objective=	x50_VIS_LWD
#Grating=	1800 (450-850nm)
#ND Filter=	100%
#Laser=	532nm_Edge
#Hole=	49.98
#Temperature=	0
#Range=	Visible
#StageXY=	75x50mm Scan+
#StageZ=	Z motor
#X (µm)=	0
#Y (µm)=	0
#Z (µm)=	-0.3
#Full time(mm:ss)=	3:18
#Project=	21_11_26
#Sample=	BU19(2)w
#Site=
#Title=	BU19(2)w-A-FF02-FI02-V_1800 (450-850nm)_532nm_Edge_100%_x50_VIS_LWD_H50um_30sX2
#Remark=
#Date=	26.11.2021 14:34
#Acquired=	26.11.2021 14:34:04
1202.72	30.6494
1203.84	32.8132
1204.95	28.4888
1206.06	24.1524
1207.17	30.5352
1208.28	27.2912
1209.39	27.2621
1210.5	27.249
1211.61	33.6101
1212.72	25.0377
1213.83	29.273
1214.94	26.0748
1216.05	26.0693
1217.16	22.8421
1218.27	26.001
1219.38	22.8008
1220.49	27.0327
1221.6	23.8421
1222.71	26.9865
1223.81	27.9928
1224.92	25.8486
1226.03	26.9052
1227.14	25.8437
1228.25	32.1041
1229.35	25.7229
1230.46	30.0061
1231.57	27.82
1232.67	27.8194
1233.78	25.712
1234.89	26.772
1235.99	23.6295
1237.1	29.9302
1238.2	27.7917
1239.31	27.7583
1240.41	24.6034
1241.52	29.8469
1242.62	32.9788
1243.73	30.8921
1244.83	30.8911
1245.94	32.9567
1247.04	32.9377
1248.14	31.8827
1249.25	31.8642
1250.35	25.5876
1251.45	31.8337
1252.56	29.7217
1253.66	30.7439
1254.76	30.7606
1255.87	26.5877
1256.97	37.0378
1258.07	37.0282
1259.17	34.9211
1260.27	39.1206
1261.37	51.5956
1262.48	60.0713
1263.58	67.2095
1264.68	56.9624
1265.78	42.276
1266.88	45.4113
1267.98	39.1783
1269.08	38.1823
1270.18	39.2293
1271.28	38.1454
1272.38	42.3352
1273.47	40.2891
1274.57	40.3271
1275.67	42.4292
1276.77	39.3114
1277.87	49.85
1278.97	47.7915
1280.07	60.4222
1281.16	109.861
1282.26	307.824
1283.36	710.653
1284.45	353.721
1285.55	98.41
1286.65	63.6465
1287.75	50.9881
1288.84	44.6596
1289.94	35.2081
1291.03	39.4301
1292.13	43.6375
1293.22	37.3155
1294.32	34.1971
1295.42	35.259
1296.51	32.1619
1297.61	34.27
1298.7	31.0813
1299.79	34.2305
1300.89	39.5195
1301.98	39.5244
1303.08	36.3651
1304.17	30.0149
1305.26	32.1227
1306.35	34.204
1307.45	31.0325
1308.54	32.0886
1309.63	33.1526
1310.73	37.378
1311.82	29.9949
1312.91	25.7847
1314	31.0536
1315.09	27.8886
1316.18	28.9584
1317.28	27.8966
1318.37	28.9609
1319.46	30.0178
1320.55	32.1303
1321.64	25.7727
1322.73	25.7485
1323.82	27.8473
1324.91	27.8479
1326	25.7211
1327.09	29.886
1328.18	28.8823
1329.27	29.9711
1330.35	31.0212
1331.44	32.0483
1332.53	28.8437
1333.62	31.9582
1334.71	27.7215
1335.79	29.7959
1336.88	32.922
1337.97	24.5237
1339.06	27.6453
1340.14	26.5961
1341.23	31.8337
1342.32	29.7269
1343.4	30.746
1344.49	25.513
1345.58	28.6361
1346.66	28.5953
1347.75	28.56
1348.83	25.4193
1349.92	30.6074
1351	26.4202
1352.09	29.5192
1353.17	29.5368
1354.25	29.5655
1355.34	31.5743
1356.42	27.414
1357.51	31.5536
1358.59	33.6084
1359.67	30.4726
1360.76	32.5148
1361.84	30.4321
1362.92	33.526
1364	31.4647
1365.09	34.5692
1366.17	34.5387
1367.25	31.3992
1368.33	39.6662
1369.41	58.2868
1370.5	36.5634
1371.58	37.5644
1372.66	39.5716
1373.74	36.4518
1374.82	39.5301
1375.9	36.4372
1376.98	35.3898
1378.06	41.5524
1379.14	42.6497
1380.22	49.8405
1381.3	52.8221
1382.38	54.8205
1383.46	64.9992
1384.54	104.946
1385.61	243.582
1386.69	1117.81
1387.77	773.757
1388.85	147.94
1389.93	74.3044
1391	64.9635
1392.08	50.5668
1393.16	41.3128
1394.23	41.2962
1395.31	42.3163
1396.39	44.3759
1397.46	39.237
1398.54	34.1133
1399.62	37.1968
1400.69	39.2561
1401.77	36.201
1402.84	40.3579
1403.92	36.2883
1404.99	39.34
1406.07	42.3897
1407.14	61.8514
1408.22	98.7786
1409.29	88.551
1410.37	42.4089
1411.44	40.3162
1412.51	37.2342
1413.59	29.1159
1414.66	27.0284
1415.73	30.12
1416.81	31.1558
1417.88	27.0597
1418.95	27.0639
1420.02	27.0565
1421.1	22.9279
1422.17	30.1157
1423.24	28.1201
1424.31	25.9762
1425.38	28.0276
1426.45	25.983
1427.52	25.9567
1428.59	23.8837
1429.67	25.9383
1430.74	19.8097
1431.81	24.9662
1432.87	22.9002
1433.95	23.8899
1435.01	22.8728
1436.08	21.8473
1437.15	23.8887
1438.22	22.8577
1439.29	27.9872
1440.36	21.8557
1441.43	24.9376
1442.49	21.858
1443.56	19.8054
1444.63	23.9013
1445.7	21.8674
1446.77	22.8853
1447.83	19.8003
1448.9	22.8825
1449.97	21.8529
1451.03	24.9167
1452.1	20.8088
1453.17	22.8563
1454.23	21.8346
1455.3	20.8077
1456.36	17.737
1457.43	20.8028
1458.49	16.7011
1459.56	17.7279
1460.62	19.7735
1461.69	17.7161
1462.75	19.7498
1463.82	20.7539
1464.88	18.7291
1465.94	19.6942
1467.01	17.6467
1468.07	19.6832
1469.13	18.6599
1470.2	18.6471
1471.26	20.6745
1472.32	18.6261
1473.39	16.586
1474.45	16.5772
1475.51	20.6506
1476.57	14.5378
1477.63	18.5978
1478.69	17.5736
1479.76	14.5135
1480.82	19.5717
1481.88	15.5056
1482.94	16.5311
1484	17.549
1485.06	16.4986
1486.12	18.5193
1487.18	19.5339
1488.24	16.485
1489.3	15.4589
1490.36	20.5122
1491.42	16.4561
1492.48	16.4537
1493.53	17.4619
1494.59	15.4388
1495.65	16.4422
1496.71	17.435
1497.77	18.4387
1498.82	16.4185
1499.88	15.4121
1500.94	19.4508
1502	17.4241
1503.05	15.3991
1504.11	14.3823
1505.17	15.3915
1506.22	18.3994
1507.28	16.3851
1508.34	19.4073
1509.39	17.3916
1510.45	17.3936
1511.5	14.3564
1512.56	18.3476
1513.61	16.3187
1514.67	17.3329
1515.72	13.3024
1516.78	20.3089
1517.83	18.2997
1518.88	16.2999
1519.94	20.3169
1520.99	17.304
1522.05	15.2997
1523.1	16.2954
1524.15	20.2835
1525.2	16.2684
1526.26	17.2763
1527.31	17.2847
1528.36	19.2815
1529.41	15.2671
1530.47	15.2618
1531.52	16.2732
1532.57	17.2718
1533.62	14.2806
1534.67	17.2914
1535.72	14.2747
1536.77	17.258
1537.82	15.2382
1538.87	17.2274
1539.92	14.2489
1540.97	16.2772
1542.02	17.2684
1543.07	22.2563
1544.12	16.23
1545.17	15.2387
1546.22	15.2528
1547.27	15.2553
1548.32	14.2453
1549.37	16.2378
1550.42	14.2404
1551.46	18.2976
1552.51	17.2933
1553.56	18.2831
1554.61	17.2663
1555.65	21.257
1556.7	15.2446
1557.75	13.2426
1558.79	17.235
1559.84	16.2147
1560.89	16.2057
1561.93	15.2083
1562.98	19.2161
1564.02	15.2119
1565.07	17.2248
1566.11	16.1252
1567.16	18.1897
1568.2	19.2026
1569.25	20.2062
1570.29	15.1984
1571.34	13.1985
1572.38	17.1871
1573.43	18.1741
1574.47	19.1695
1575.51	18.1881
1576.56	14.1927
1577.6	18.1675
1578.64	16.1517
1579.69	15.1528
1580.73	17.1509
1581.77	17.1423
1582.81	17.1317
1583.85	15.1355
1584.9	15.1354
1585.94	17.1258
1586.98	18.1072
1588.02	15.1147
1589.06	16.1144
1590.1	17.1154
1591.14	19.1113
1592.18	20.1021
1593.22	15.1085
1594.26	15.0857
1595.3	17.0748
1596.34	17.068
1597.38	18.0624
1598.42	16.0757
1599.46	15.068
1600.5	15.0569
1601.54	17.0211
1602.58	17.003
1603.62	18.9652
1604.66	18.9601
1605.69	18.9611
1606.73	16.9904
1607.77	17.0059
1608.81	18.8408
1609.84	17.6039
1610.88	17.8367
1611.92	15.5229
1612.95	15.8272
1613.99	14.5051
1615.03	15.275
1616.06	17.1146
1617.1	15.7559
1618.13	16.864
1619.17	17.3597
1620.2	18.9918
1621.24	17.1926
1622.27	16.9167
1623.31	15.1183
1624.34	17.4598
1625.38	16.5474
1626.41	16.8676
1627.45	17.6009
1628.48	16.9056
1629.51	14.6689
1630.55	17.0884
1631.53	14.7701
1632.57	15.7615
1633.62	15.7594
1634.66	17.7337
1635.71	14.7747
1636.75	17.7232
1637.8	14.7586
1638.84	19.6751
1639.89	16.7214
1640.93	16.7234
1641.98	16.7226
1643.02	15.7341
1644.06	17.6991
1645.11	14.7395
1646.15	17.6954
1647.19	18.6716
1648.24	20.6317
1649.28	16.7123
1650.32	18.6797
1651.37	14.755
1652.41	18.6988
1653.45	17.7085
1654.49	15.7407
1655.53	15.7467
1656.57	16.7492
1657.62	15.7618
1658.66	15.7555
1659.7	15.7457
1660.74	13.7706
1661.78	14.7664
1662.82	15.77
1663.86	16.7592
1664.9	16.7474
1665.94	17.711
1666.98	19.7075
1668.02	15.7488
1669.06	16.7383
1670.1	16.7497
1671.14	17.7499
1672.18	15.7692
1673.21	16.7587
1674.25	17.7507
1675.29	16.7708
1676.33	17.7637
1677.37	18.7544
1678.4	14.7876
1679.44	17.7431
1680.48	17.7359
1681.52	17.7291
1682.55	15.7522
1683.59	18.714
1684.63	15.7458
1685.66	18.7044
1686.7	16.7304
1687.73	16.7338
1688.77	14.7509
1689.81	13.7532
1690.84	16.7083
1691.88	16.7137
1692.91	14.7375
1693.95	18.6655
1694.98	20.6208
1696.01	16.6824
1697.05	20.6284
1698.08	16.6724
1699.12	15.6762
1700.15	13.7068
1701.18	17.6375
1702.22	15.6613
1703.25	17.6162
1704.28	15.6462
1705.32	18.5964
1706.35	14.6618
1707.38	18.5733
1708.41	14.6303
1709.44	14.6117
1710.48	15.5867
1711.51	14.6119
1712.54	16.5708
1713.57	19.4788
1714.6	15.5503
1715.63	18.48
1716.66	14.5714
1717.69	19.4304
1718.72	18.4239
1719.75	14.5216
1720.78	18.4145
1721.81	18.3979
1722.84	19.3508
1723.87	20.3068
1724.9	16.4167
1725.93	17.3627
1726.96	17.3555
1727.99	12.5058
1729.02	16.3478
1730.05	17.2965
1731.07	17.2855
1732.1	16.3386
1733.13	12.4668
1734.16	18.2382
1735.18	18.2145
1736.21	16.2711
1737.24	17.225
1738.26	17.2142
1739.29	15.277
1740.32	18.1307
1741.34	18.109
1742.37	17.1382
1743.4	19.0466
1744.42	19.0362
1745.45	15.2054
1746.47	17.1112
1747.5	14.2268
1748.52	18.0357
1749.55	18.0391
1750.57	19.9641
1751.6	18.06
1752.62	17.0871
1753.64	15.1632
1754.67	17.0579
1755.69	18.0011
1756.71	17.0322
1757.74	14.16
1758.76	17.9698
1759.78	17.0192
1760.81	17.9652
1761.83	13.199
1762.85	16.0493
1763.87	17.9522
1764.89	18.9165
1765.92	19.8763
1766.94	18.9222
1767.96	18.9157
1768.98	18.9069
1770	18.8719
1771.02	18.8812
1772.04	17.9452
1773.06	20.8092
1774.08	20.8176
1775.1	17.967
1776.12	17.9837
1777.14	17.0297
1778.16	19.8759
1779.18	16.0515
1780.2	17.9513
1781.22	16.0526
1782.24	16.0565
1783.26	15.1135
1784.28	19.8878
1785.29	17.9923
1786.31	18.9408
1787.33	17.9948
1788.35	16.1156
1789.37	18.0538
1790.38	18.0691
1791.4	14.2324
1792.42	18.0514
1793.43	15.1823
1794.45	21.8923
1795.47	16.1565
1796.48	17.134
1797.5	15.2246
1798.51	16.193
1799.53	17.1522
1800.55	16.1792
1801.56	15.2131
1802.58	19.0583
1803.59	14.2641
1804.61	20.041
1805.62	18.1318
1806.64	15.255
1807.65	16.2222
1808.66	12.3669
1809.68	17.188
1810.69	16.2254
1811.7	18.1506
1812.72	15.26
1813.73	17.1967
1814.74	15.2803
1815.76	16.2576
1816.77	16.2605
1817.78	17.2162
1818.79	17.2183
1819.8	16.2561
1820.82	20.131
1821.83	15.3027
1822.84	17.2443
1823.85	16.2756
1824.86	17.2436
1825.87	16.2807
1826.88	15.3125
1827.89	15.3162
1828.9	15.315
1829.91	13.3725
1830.92	17.239
1831.93	18.2134
1832.94	18.2235
1833.95	14.3502
1834.96	15.3087
1835.97	22.0558
1836.98	17.2815
1837.99	17.2268
1839	16.257
1840	18.2166
1841.01	16.246
1842.02	17.1813
1843.03	16.2013
1844.04	15.2359
1845.04	16.2002
1846.05	19.0991
1847.06	15.2532
1848.07	14.2381
1849.07	15.2027
1850.08	16.1525
1851.09	14.2103
1852.09	16.1209
1853.1	17.0794
1854.1	14.1923
1855.11	16.0945
1856.11	17.0364
1857.12	15.1174
1858.12	17.0259
1859.13	14.1413
1860.13	17.9547
1861.14	15.0923
1862.14	16.0566
1863.15	14.1327
1864.15	13.1641
1865.15	15.0632
1866.16	15.0434
1867.16	14.0656
1868.16	14.0473
1869.17	17.8477
1870.17	14.9921
1871.17	17.8399
1872.17	14.9824
1873.18	16.8715
1874.18	18.7622
1875.18	17.796
1876.18	16.8225
1877.18	15.8582
1878.18	16.7794
1879.19	15.86
1880.19	15.8718
1881.19	15.8692
1882.19	14.9
1883.19	13.9249
1884.19	13.9093
1885.19	14.8584
1886.19	13.9323
1887.19	18.6497
1888.19	16.7449
1889.19	17.6637
1890.19	14.8291
1891.19	12.9536
1892.18	14.8335
1893.18	16.7088
1894.18	16.6827
1895.18	15.7349
1896.18	17.6187
1897.18	16.689
1898.17	13.8707
1899.17	18.5626
1900.17	15.7308
1901.16	16.669
1902.16	15.7409
1903.16	15.746
1904.16	13.8588
1905.15	12.9156
1906.15	15.729
1907.14	14.7782
1908.14	18.5362
1909.14	14.7849
1910.13	16.6786
1911.13	15.7563
1912.12	13.8761
1913.12	16.6986
1914.11	15.7635
1915.11	14.8348
1916.1	15.7832
1917.1	18.6042
1918.09	14.8236
1919.08	12.9458
1920.08	15.7969
1921.07	17.6889
1922.06	18.6482
1923.06	15.8082
1924.05	16.7462
1925.04	14.8479
1926.04	15.8027
1927.03	15.8196
1928.02	16.7759
1929.01	16.7822
1930	17.7435
1931	16.8124
1931.99	15.8607
1932.98	18.6973
1933.97	16.8019
1934.96	16.8493
1935.95	14.0237
1936.94	15.9155
1937.93	17.8052
1938.92	13.9955
1939.91	16.8604
1940.9	17.8246
1941.89	15.9318
1942.88	18.8017
1943.87	18.7902
1944.86	14.9838
1945.85	15.9532
1946.84	14.0503
1947.83	15.96
1948.82	15.9574
1949.8	16.9236
1950.79	17.9045
1951.78	16.9716
1952.77	14.1033
1953.76	16.0254
1954.74	15.0326
1955.73	15.0242
1956.72	16.9681
1957.7	17.944
1958.69	16.9912
1959.68	18.9068
1960.66	16.9759
1961.65	13.1246
1962.63	15.0438
1963.62	18.8853
1964.61	16.0098
1965.59	14.0869
1966.58	16.0151
1967.56	17.9444
1968.55	18.9083
1969.53	16.0149
1970.52	17.9163
1971.5	16.946
1972.48	16.9451
1973.47	15.9817
1974.45	18.8467
1975.44	16.9303
1976.42	20.7749
1977.4	15.9797
1978.39	16.9298
1979.37	15.9654
1980.35	16.9247
1981.33	18.8312
1982.31	15.9506
1983.3	19.7691
1984.28	16.8853
1985.26	18.7892
1986.24	16.8708
1987.22	19.7446
1988.21	15.9076
1989.19	21.5523
1990.17	21.6743
1991.15	19.4215
1992.13	19.7258
1993.11	18.6074
1994.09	19.5197
1995.07	17.6166
1996.05	20.1485
1997.03	19.2227
1998.01	18.3638
1998.99	19.7662
1999.97	18.5881
2000.95	19.3218
2001.92	21.5319
2002.9	20.0931
2003.88	21.6572
2004.86	18.3318
2005.84	21.7908
2006.81	20.1633
2007.79	19.3378
2008.77	19.9102
2009.75	17.702
2010.73	20.8259
2011.7	20.652
2012.68	22.5359
2013.67	19.688
2014.66	19.6553
2015.64	20.5849
2016.63	17.7758
2017.62	21.5455
2018.61	19.639
2019.6	19.6089
2020.58	17.7263
2021.57	23.3457
2022.56	17.7201
2023.55	19.5738
2024.54	18.6216
2025.52	19.5297
2026.51	17.6474
2027.5	17.6925
2028.48	18.6054
2029.47	14.8913
2030.45	15.7783
2031.44	19.5171
2032.43	16.7195
2033.41	14.8707
2034.4	15.8063
2035.38	16.7147
2036.37	16.7495
2037.35	22.354
2038.34	17.6729
2039.32	17.6611
2040.31	16.7118
2041.29	17.627
2042.27	18.5502
2043.26	14.8148
2044.24	18.5624
2045.23	19.4829
2046.21	16.7194
2047.19	16.7031
2048.17	15.749
2049.16	14.8197
2050.14	19.5029
2051.12	17.6484
2052.11	16.7038
2053.09	16.7085
2054.07	15.7907
2055.05	14.8595
2056.03	14.8516
2057.01	15.7808
2058	15.7837
2058.98	16.7307
2059.96	13.9294
2060.94	17.6668
2061.92	16.737
2062.9	15.8035
2063.88	13.9383
2064.86	17.6928
2065.84	15.8321
2066.82	14.902
2067.8	14.9077
2068.78	17.7336
2069.76	14.909
2070.73	15.8463
2071.71	17.7363
2072.69	18.702
2073.67	14.932
2074.65	13.9931
2075.63	17.7812
2076.6	15.9119
2077.58	15.9032
2078.56	14.9552
2079.54	14.9626
2080.51	14.0319
2081.49	14.9754
2082.47	17.8091
2083.45	14.0307
2084.42	14.0289
2085.4	15.9186
2086.37	18.759
2087.35	14.9882
2088.32	14.0453
2089.3	14.9934
2090.28	15.0027
2091.25	14.0591
2092.23	13.1206
2093.2	14.0857
2094.18	14.0982
2095.15	14.1001
2096.13	15.9916
2097.1	15.9865
2098.07	12.1784
2099.05	12.1745
2100.02	11.2228
2101	14.0716
2101.97	15.9791
2102.94	15.0272
2103.92	13.1202
2104.89	14.0713
2105.86	17.8808
2106.83	15.9868
2107.8	12.1841
2108.78	14.0706
2109.75	14.0697
2110.72	15.9718
2111.69	13.1199
2112.66	16.9135
2113.63	15.972
2114.61	15.9736
2115.58	16.9229
2116.55	16.9144
2117.52	15.9576
2118.49	14.0521
2119.46	14.0372
2120.43	14.0259
2121.4	15.9238
2122.37	15.9372
2123.34	14.9964
2124.31	15.9436
2125.28	14.0261
2126.25	14.9525
2127.21	14.9382
2128.18	14.9311
2129.15	13.9825
2130.12	13.0332
2131.09	13.9734
2132.06	13.9645
2133.02	14.899
2133.99	15.8413
2134.96	14.8975
2135.93	12.0628
2136.89	13.9361
2137.86	15.8239
2138.83	16.7599
2139.79	13.9345
2140.76	14.864
2141.73	13.9176
2142.69	13.9095
2143.66	15.8033
2144.62	13.8909
2145.59	12.9504
2146.55	14.8272
2147.52	14.8203
2148.48	14.8122
2149.45	13.8636
2150.42	14.7842
2151.38	18.5292
2152.34	15.7239
2153.31	12.9051
2154.27	13.8346
2155.24	12.8784
2156.2	17.5329
2157.16	15.6572
2158.13	15.6625
2159.09	15.6639
2160.05	15.6539
2161.01	14.7053
2161.98	16.5651
2162.94	14.6974
2163.9	14.69
2164.86	15.6105
2165.83	15.6094
2166.79	15.6053
2167.75	13.731
2168.71	15.5704
2169.67	14.6451
2170.63	16.5247
2171.59	12.7954
2172.56	14.632
2173.51	14.6259
2174.48	16.4877
2175.44	13.6991
2176.4	14.6243
2177.36	13.69
2178.32	11.8319
2179.28	12.7524
2180.23	13.6807
2181.19	14.6059
2182.15	14.6002
2183.11	13.666
2184.07	14.5793
2185.03	14.5738
2185.99	13.6513
2186.95	13.6614
2187.9	15.5329
2188.86	11.812
2189.82	14.5808
2190.78	14.5736
2191.73	14.576
2192.69	17.3627
2193.65	14.5878
2194.6	13.6787
2195.56	13.6764
2196.52	12.7333
2197.47	14.5759
2198.43	14.5749
2199.38	16.448
2200.34	20.1911
2201.3	14.6345
2202.25	17.3712
2203.21	16.47
2204.16	16.5284
2205.12	16.4975
2206.07	17.387
2207.03	15.5254
2207.98	15.5339
2208.93	16.4767
2209.89	14.6184
2210.84	16.4848
2211.8	16.4947
2212.75	11.8404
2213.7	14.6319
2214.66	13.7053
2215.61	14.6469
2216.56	13.7133
2217.51	14.6445
2218.47	13.711
2219.42	16.5188
2220.37	13.7228
2221.32	16.5225
2222.27	13.7058
2223.23	14.6395
2224.18	13.7166
2225.13	16.537
2226.08	14.6794
2227.03	14.6903
2227.98	13.7597
2228.93	13.7556
2229.88	13.7556
2230.83	14.7053
2231.78	16.5964
2232.73	17.5489
2233.68	13.7977
2234.63	14.7435
2235.58	16.6131
2236.53	12.8483
2237.48	15.675
2238.43	15.6961
2239.38	11.9408
2240.33	12.8779
2241.27	13.8262
2242.22	16.6604
2243.17	14.7773
2244.12	12.8832
2245.07	14.7766
2246.01	14.7936
2246.96	12.911
2247.91	13.8625
2248.85	15.7517
2249.8	13.8586
2250.75	12.9088
2251.69	12.8981
2252.64	15.7377
2253.59	13.8655
2254.53	13.8774
2255.48	12.93
2256.42	13.8809
2257.37	13.8898
2258.32	14.8454
2259.26	14.8499
2260.2	13.9054
2261.15	13.911
2262.1	15.8221
2263.04	14.8777
2263.98	12.0345
2264.93	12.0507
2265.87	13.9683
2266.81	13.9607
2267.76	13.9491
2268.7	13.9398
2269.65	14.9023
2270.59	15.8756
2271.53	13.9741
2272.47	13.9813
2273.42	12.0694
2274.36	14.9424
2275.3	13.0305
2276.24	12.0753
2277.18	16.8779
2278.13	14.0203
2279.07	15.9498
2280.01	13.0581
2280.95	13.0444
2281.89	13.0376
2282.83	14.9616
2283.77	13.0579
2284.71	15.0019
2285.65	12.1239
2286.59	14.0395
2287.54	12.1284
2288.47	13.0966
2289.41	16.9361
2290.35	12.1067
2291.29	14.0298
2292.23	15.0057
2293.17	17.9074
2294.11	16.9519
2295.05	16.9421
2295.99	13.0805
2296.93	11.1449
2297.86	15.9647
2298.8	15.9798
2299.74	15.0283
2300.68	15.0285
2301.61	16.9662
2302.55	15.9998
2303.49	13.1019
2304.43	11.174
2305.36	14.0779
2306.3	12.1497
2307.24	15.0507
2308.17	15.0451
2309.11	16.0085
2310.04	15.055
2310.98	16.0264
2311.92	12.1371
2312.85	15.02
2313.79	14.0581
2314.72	16.0086
2315.66	14.0835
2316.59	15.0308
2317.52	15.9897
2318.46	13.0941
2319.39	14.0503
2320.33	16.9396
2321.26	14.0478
2322.2	15.9912
2323.13	15.0339
2324.06	16.9708
2325	21.7983
2325.93	24.6704
2326.86	38.1567
2327.79	103.682
2328.73	37.1522
2329.66	24.6055
2330.59	16.8973
2331.52	14.0048
2332.46	14.0079
2333.39	13.9983
2334.32	13.0285
2335.25	13.0187
2336.18	15.9032
2337.11	14.9369
2338.04	16.8554
2338.97	13.0067
2339.91	14.9286
2340.84	13.9588
2341.77	15.8601
2342.7	15.8466
2343.63	16.8014
2344.56	14.8833
2345.49	14.88
2346.41	15.8249
2347.34	11.9898
2348.27	15.8187
2349.2	15.8195
2350.13	14.8383
2351.06	13.815
2351.99	13.8698
2352.91	14.8018
2353.84	13.8267
2354.77	14.7789
2355.7	12.8734
2356.63	13.8154
2357.55	14.7483
2358.48	14.7391
2359.41	13.7813
2360.33	14.722
2361.26	15.6558
2362.19	13.7439
2363.11	14.6761
2364.04	13.7207
2364.97	16.5489