File: Data/3-Raman/raw/bu19w-e-ff11-fi08-v_150 (500nm)_633nm_edge_100%_x100_vis_h50um_60sx2_01.txt
#Acq. time (s)=	60
#Accumulations=	2
#Range (cm-¹)=	100...4000
#Windows=	1
#Auto scanning=	Off
#Autofocus=	Off
#Macrospot=	Off
#AutoExposure=	Off
#Spike filter=	Multiple accum.
#Delay time (s)=	2
#Binning=	1
#Readout mode=	Signal
#DeNoise=	Off
#ICS correction=	On
#Dark correction=	Off
#Inst. Process=	Off
#Detector Gain=	Best Dynamic
#Detector ADC=	50 kHz HS
#Detector temperature (°C)=	-60.09
#Instrument=	LabRAM HR Evol
#Detector=	SIN-EM FIVIS
#Objective=	x100_VIS
#Grating=	150 (500nm)
#ND Filter=	100%
#Laser=	633nm_Edge
#Hole=	49.98
#Temperature=	0
#Range=	Visible
#StageXY=	75x50mm Scan+
#StageZ=	Z motor
#X (µm)=	0
#Y (µm)=	0
#Z (µm)=	-268.8
#Full time(mm:ss)=	2:04
#Project=	21_11_04
#Sample=	BU19w
#Site=
#Title=	BU19w-E-FF11-FI08-V_150 (500nm)_633nm_Edge_100%_x100_VIS_H50um_60sX2
#Remark=
#Date=	04.11.2021 16:22
#Acquired=	04.11.2021 16:22:51
102.881	253.128
109.397	243.827
115.908	228.782
122.414	209.827
128.914	238.658
135.409	270.32
141.898	265.542
148.383	262.727
154.861	331.782
161.335	354.963
167.801	237.244
174.264	201.801
180.721	176.794
187.173	160.319
193.62	165.794
200.061	154.141
206.496	158.889
212.926	179.807
219.352	235.995
225.772	377.805
232.185	461.958
238.595	306.555
244.999	242.73
251.397	238.816
257.791	260.493
264.178	249.005
270.561	233.779
276.939	238.516
283.31	223.284
289.678	213.685
296.039	202.14
302.396	239.805
308.746	332.188
315.093	552.855
321.433	702.553
327.768	482.535
334.099	302.302
340.423	271.113
346.743	277.61
353.058	304.775
359.367	287.562
365.671	224.266
371.971	184.588
378.265	168.437
384.553	154.241
390.837	159.951
397.116	164.878
403.389	170.907
409.657	174.097
415.92	179.082
422.178	196.327
428.431	245.296
434.678	243.788
440.921	243.196
447.158	281.012
453.391	297.032
459.618	243.138
465.84	198.086
472.057	166.27
478.27	170.951
484.477	170.971
490.679	172.857
496.876	202.723
503.068	227.98
509.255	243.026
515.436	253.489
521.613	255.714
527.785	256.213
533.952	235.277
540.113	202.92
546.27	196.674
552.423	173.223
558.568	167.605
564.711	155.121
570.848	152.885
576.979	158.033
583.107	172.52
589.228	201.039
595.345	204.523
601.458	194.318
607.565	224.478
613.667	225.873
619.764	217.146
625.856	167.057
631.944	153.236
638.026	152.315
644.104	155.859
650.177	166.898
656.244	146.785
662.308	141.711
668.365	115.233
674.418	108.639
680.467	110.505
686.511	105.934
692.549	105.208
698.582	111.069
704.611	104.721
710.635	108.625
716.655	101.97
722.669	92.5194
728.679	106.46
734.683	93.1616
740.683	105.146
746.678	104.056
752.669	99.3015
758.654	116.077
764.635	105.094
770.611	111.95
776.582	102.869
782.549	106.837
788.511	111.684
794.466	110.819
800.419	106.088
806.366	111.64
812.309	119.011
818.247	112.19
824.18	106.302
830.108	121.017
836.033	120.055
841.952	115.554
847.865	123.259
853.776	132.938
859.681	137.998
865.58	138.379
871.476	151.037
877.366	149.341
883.253	157.04
889.134	167.476
895.012	162.636
900.883	161.403
906.751	159.122
912.614	151.165
918.473	160.252
924.326	175.172
930.174	190.343
936.019	211.391
941.859	248.035
947.693	297.369
953.525	307.101
959.35	301.414
965.171	349.073
970.988	409.184
976.801	497.753
982.608	526.999
988.411	482.128
994.209	380.895
1000	332.576
1005.79	342.719
1011.58	356.138
1017.36	389.883
1023.13	356.987
1028.9	286.946
1034.67	262.751
1040.43	249.113
1046.19	217.026
1051.94	215.614
1057.69	199.491
1063.44	186.048
1069.17	200.549
1074.91	214.06
1080.64	267.221
1086.37	325.11
1092.09	432.422
1097.8	440.856
1103.52	338.098
1109.22	274.392
1114.93	260.436
1120.63	237.91
1126.32	259.893
1132.01	283.036
1137.7	339.603
1143.38	419.007
1149.06	508.188
1154.73	359.883
1160.4	223.887
1166.06	187.122
1171.72	163.242
1177.38	157.034
1183.03	134.317
1188.67	121.586
1194.31	123.621
1199.95	110.128
1205.58	111.46
1211.21	102.02
1216.84	97.5089
1222.46	101.952
1228.07	85.4504
1233.68	93.8391
1239.29	94.1569
1244.89	102.427
1250.49	87.3727
1256.08	102.542
1261.67	97.3855
1267.26	94.2316
1272.84	164.481
1278.42	122.965
1283.99	89.6544
1289.56	96.5223
1295.12	86.4523
1300.68	95.4372
1306.23	91.5289
1311.78	87.7379
1317.33	99.0817
1322.87	97.4159
1328.41	82.6029
1333.94	89.0268
1339.47	83.2006
1345	79.3055
1350.52	96.8877
1356.04	90.8726
1361.55	97.1151
1367.06	99.1751
1372.56	104.276
1378.06	273.691
1383.56	104.191
1389.05	95.9332
1394.53	92.8697
1400.02	100.203
1405.5	99.3192
1410.97	80.9376
1416.44	90.4114
1421.91	94.7636
1427.37	97.0812
1432.83	85.883
1438.28	96.5359
1443.73	93.6372
1449.17	87.5422
1454.62	90.7916
1460.05	87.6811
1465.48	99.2233
1470.91	90.797
1476.34	94.991
1481.76	92.93
1487.17	87.7449
1492.59	80.4907
1497.99	90.1193
1503.4	90.3099
1508.8	92.6544
1514.19	89.7351
1519.59	92.1583
1524.97	93.5468
1530.36	88.5093
1535.74	89.9165
1541.11	84.7692
1546.48	84.9025
1551.85	93.5604
1557.21	95.6039
1562.57	96.5871
1567.93	102.956
1573.28	89.9249
1578.62	95.2645
1583.97	93.1213
1589.3	93.1598
1594.64	94.3184
1599.97	95.5247
1605.3	97.8649
1610.62	99.2057
1615.94	98.4608
1621.25	97.7488
1626.56	99.2162
1631.87	95.18
1637.17	89.9385
1642.47	95.578
1647.76	99.044
1653.05	101.373
1658.34	93.6767
1663.62	99.2503
1668.9	99.259
1674.18	100.37
1679.45	102.57
1684.71	95.849
1689.98	95.7694
1695.23	100.178
1700.49	96.9766
1705.74	96.3468
1710.99	103.17
1716.23	97.6313
1721.47	96.7906
1726.7	98.0668
1731.94	98.2721
1737.16	100.717
1742.39	100.91
1747.61	110.125
1752.82	103.481
1758.03	103.57
1763.24	104.736
1768.44	99.123
1773.64	99.1861
1778.84	109.504
1784.03	94.8995
1789.22	101.92
1794.41	116.987
1799.59	103.554
1804.76	113.02
1809.94	105.24
1815.11	108.924
1820.27	99.9184
1825.43	103.617
1830.59	103.861
1835.74	99.4684
1840.89	100.837
1846.04	103.35
1851.18	108.197
1856.32	100.136
1861.45	107.358
1866.58	105.229
1871.71	113.661
1876.83	111.455
1881.95	108.046
1887.07	111.697
1892.18	110.541
1897.29	108.191
1902.39	109.488
1907.49	104.956
1912.59	106.44
1917.68	109.173
1922.77	100.934
1927.86	115.494
1932.94	104.923
1938.02	106.298
1943.09	108.845
1948.16	104.141
1953.23	109.023
1958.29	110.265
1963.35	111.489
1968.41	115.089
1973.46	118.64
1978.51	120.983
1983.55	107.68
1988.59	108.834
1993.63	113.609
1998.66	117.205
2003.69	113.62
2008.72	113.684
2013.74	117.39
2018.76	107.831
2023.77	113.948
2028.78	120.135
2033.79	110.675
2038.79	113.312
2043.79	107.47
2048.79	128.397
2053.78	118.87
2058.77	119.116
2063.76	119.383
2068.74	115.967
2073.72	116.213
2078.69	127.535
2083.66	114.18
2088.63	124.222
2093.59	117.013
2098.55	122.245
2103.51	130.009
2108.46	126.616
2113.41	138.254
2118.36	128.644
2123.3	121.482
2128.24	126.882
2133.17	118.353
2138.11	116.093
2143.03	130.335
2147.96	124.208
2152.88	133.312
2157.79	129.625
2162.71	133.554
2167.62	125.927
2172.52	123.439
2177.43	127.366
2182.32	123.543
2187.22	135.047
2192.11	117.168
2197	121.096
2201.89	123.818
2206.77	126.598
2211.64	128.148
2216.52	120.698
2221.39	119.711
2226.26	123.908
2231.12	130.727
2235.98	128.451
2240.84	130.08
2245.69	143.522
2250.54	122.862
2255.39	137.653
2260.23	130.088
2265.07	129.058
2269.9	137.247
2274.74	134.784
2279.57	128.282
2284.39	131.014
2289.21	139.031
2294.03	132.409
2298.84	135.145
2303.66	128.614
2308.46	128.823
2313.27	135.779
2318.07	136.114
2322.87	137.798
2327.66	124.691
2332.45	142.625
2337.24	137.643
2342.02	124.486
2346.8	145.42
2351.58	140.447
2356.35	135.376
2361.12	126.04
2365.89	135.974
2370.65	144.565
2375.41	125.448
2380.17	142.336
2384.92	153.626
2389.67	145.4
2394.42	145.452
2399.16	139.883
2403.9	135.694
2408.64	135.706
2413.37	138.731
2418.1	142.197
2422.83	146.872
2427.55	147.111
2432.27	143.259
2436.99	128.115
2441.7	127.08
2446.41	141.7
2451.11	134.987
2455.82	141.108
2460.51	131.462
2465.21	141.926
2469.9	143.751
2474.59	147.012
2479.28	150.306
2483.96	140.481
2488.64	145.152
2493.32	132.289
2497.99	142.82
2502.66	150.428
2507.32	138.922
2511.99	136.178
2516.65	151.089
2521.3	142.465
2525.96	144.164
2530.61	144.384
2535.25	147.611
2539.89	150.877
2544.53	157.147
2549.17	148.541
2553.8	132.409
2558.43	146.142
2563.06	146.456
2567.68	139.29
2572.3	156.266
2576.92	156.653
2581.53	149.392
2586.14	152.637
2590.75	151.241
2595.35	151.418
2599.96	140.99
2604.55	144.222
2609.15	153.554
2613.74	156.728
2618.33	176.759
2622.91	157.003
2627.49	186.315
2632.07	148.251
2636.64	150.168
2641.22	164.547
2645.78	155.786
2650.35	167.152
2654.91	162.928
2659.47	169.463
2664.03	157.195
2668.58	163.681
2673.13	164.023
2677.67	172.499
2682.22	163.858
2686.76	174.146
2691.29	186.053
2695.83	173.728
2700.36	178.907
2704.89	171.228
2709.41	169.931
2713.93	162.165
2718.45	160.903
2722.96	169.305
2727.47	167.914
2731.98	171.316
2736.49	182.833
2740.99	165.094
2745.49	157.164
2749.98	162.337
2754.47	167.73
2758.96	176.247
2763.45	179.798
2767.93	163.708
2772.41	178.849
2776.89	172.684
2781.36	174.871
2785.84	183.777
2790.3	182.714
2794.77	161.521
2799.23	180.412
2803.69	160.647
2808.14	166.028
2812.59	168.021
2817.04	178.416
2821.49	173.613
2825.93	162.032
2830.37	158.889
2834.81	176.133
2839.24	166.158
2843.67	169.819
2848.1	176.962
2852.53	163.627
2856.95	160.602
2861.37	161.015
2865.78	161.503
2870.19	175.87
2874.6	172.936
2879.01	173.495
2883.41	170.6
2887.81	187.016
2892.21	177.075
2896.6	175.927
2901	178.355
2905.38	180.695
2909.77	179.443
2914.15	178.068
2918.53	171.299
2922.91	175.322
2927.28	190.241
2931.65	172.72
2936.02	176.777
2940.38	171.671
2944.74	193.823
2949.1	184.978
2953.46	185.249
2957.81	167.231
2962.16	191.273
2966.5	184.253
2970.85	199.282
2975.19	175.735
2979.52	192.657
2983.86	191.234
2988.19	182.459
2992.52	192.256
2996.85	187.22
3001.17	195.287
3005.49	197.823
3009.8	192.839
3014.12	185.893
3018.43	201.711
3022.74	211.928
3027.04	199.207
3031.34	192.067
3035.64	188.634
3039.94	198.598
3044.23	202.832
3048.52	212.815
3052.81	217.033
3057.09	209.702
3061.38	213.944
3065.65	220.14
3069.93	224.411
3074.2	220.919
3078.47	213.531
3082.74	237.371
3087	235.949
3091.27	236.595
3095.52	233.402
3099.78	222.306
3104.03	258.771
3108.28	249.79
3112.53	262.771
3116.77	263.796
3121.01	268.896
3125.25	261.97
3129.49	281.473
3133.72	276.732
3137.95	284.214
3142.18	289.597
3146.4	282.497
3150.62	281.482
3154.84	294.852
3159.06	295.719
3163.27	298.699
3167.48	274.286
3171.69	298.221
3175.89	282.019
3180.09	271.919
3184.29	299.842
3188.49	293.784
3192.68	292.101
3196.87	292.678
3201.06	293.623
3205.24	283.957
3209.42	272.185
3213.6	273.31
3217.78	274.495
3221.95	273.414
3226.12	287.641
3230.29	271.198
3234.45	272.213
3238.61	266.56
3242.77	247.653
3246.93	259.85
3251.08	251.779
3255.23	247.945
3259.38	259.871
3263.53	215.609
3267.67	255.289
3271.81	226.71
3275.95	252.427
3280.08	239.215
3284.21	225.94
3288.34	230.986
3292.47	229.113
3296.59	259.498
3300.71	227.668
3304.83	218.848
3308.95	216.951
3313.06	228.945
3317.17	220.053
3321.27	215.846
3325.38	237.43
3329.48	233.373
3333.58	215.368
3337.67	220.853
3341.77	200.108
3345.86	205.266
3349.95	207.991
3354.03	222.638
3358.11	184.952
3362.19	214.076
3366.27	226.515
3370.34	224.599
3374.42	210.573
3378.48	208.475
3382.55	216
3386.61	196.94
3390.68	226.188
3394.73	187.7
3398.79	204.958
3402.84	207.626
3406.89	207.824
3410.94	195.835
3414.98	198.422
3419.03	193.708
3423.06	171.897
3427.1	186.683
3431.14	204.001
3435.17	201.844
3439.2	194.837
3443.22	195.203
3447.25	198.135
3451.27	188.76
3455.28	196.728
3459.3	182.497
3463.31	173.173
3467.32	181.288
3471.33	204.475
3475.34	167.283
3479.34	182.932
3483.34	196.126
3487.33	181.455
3491.33	194.675
3495.32	197.714
3499.31	203.261
3503.3	198.51
3507.28	196.247
3511.26	198.977
3515.24	181.121
3519.22	196.65
3523.19	196.762
3527.16	191.767
3531.13	173.871
3535.1	189.654
3539.06	187.512
3543.02	182.706
3546.98	162.243
3550.93	198.837
3554.89	188.512
3558.84	196.519
3562.78	204.608
3566.73	173.633
3570.67	187.101
3574.61	195.369
3578.55	201.124
3582.48	199.071
3586.41	199.666
3590.35	189.641
3594.27	187.531
3598.2	188.066
3602.12	196.568
3606.04	186.319
3609.95	200.146
3613.87	181.723
3617.78	182.071
3621.69	185.036
3625.6	177.059
3629.5	177.166
3633.4	169.11
3637.3	185.487
3641.2	177.626
3645.09	177.972
3648.98	156.464
3652.87	175.699
3656.76	175.861
3660.64	176.012
3664.53	181.608
3668.4	195.467
3672.28	190.183
3676.16	184.984
3680.03	177.104
3683.9	174.774
3687.76	178.019
3691.63	159.152
3695.49	170.651
3699.35	173.895
3703.2	177.133
3707.06	158.046
3710.91	178.117
3714.76	172.953
3718.6	167.697
3722.45	173.68
3726.29	185.302
3730.13	162.954
3733.97	185.984
3737.8	183.489
3741.63	163.852
3745.46	172.673
3749.29	155.76
3753.11	170.228
3756.93	178.947
3760.75	170.448
3764.57	161.926
3768.39	179.221
3772.2	165.022
3776.01	176.655
3779.81	159.596
3783.62	165.59
3787.42	168.728
3791.22	177.62
3795.02	163.457
3798.81	178.277
3802.61	181.557
3806.4	167.412
3810.18	164.874
3813.97	162.288
3817.75	165.541
3821.53	180.529
3825.31	180.821
3829.09	169.34
3832.86	157.861
3836.63	169.965
3840.4	170.235
3844.17	155.732
3847.93	176.644
3851.69	164.884
3855.45	173.877
3859.21	179.834
3862.96	173.948
3866.71	150.417
3870.46	165.699
3874.21	156.826
3877.95	174.859
3881.69	154.037
3885.44	184.099
3889.17	166.305
3892.91	169.518
3896.64	169.828
3900.37	161.059
3904.1	155.266
3907.82	164.54
3911.55	161.778
3915.27	162.061
3918.99	165.437
3922.7	174.973
3926.42	166.221
3930.13	151.286
3933.84	154.599
3937.54	151.754
3941.25	145.878
3944.95	155.41
3948.65	146.449
3952.35	171.372
3956.04	171.599
3959.73	156.291
3963.42	156.413
3967.11	162.691
3970.8	168.928
3974.48	172.088
3978.16	165.932
3981.84	172.126
3985.52	162.813
3989.19	131.795
3992.86	178.371
3996.53	153.663
3998.37	153.737