File: Data/3-Raman/raw/bu19w-ff-ore1-fi10-v_150 (500nm)_532nm_edge_100%_x50_vis_lwd_h50um_15sx2_01.txt
#Acq. time (s)=	15
#Accumulations=	2
#Range (cm-¹)=	50...5000
#Windows=	1
#Auto scanning=	Off
#Autofocus=	Off
#Macrospot=	Off
#AutoExposure=	Off
#Spike filter=	Multiple accum.
#Delay time (s)=	2
#Binning=	1
#Readout mode=	Signal
#DeNoise=	Off
#ICS correction=	On
#Dark correction=	Off
#Inst. Process=	Off
#Detector Gain=	Best Dynamic
#Detector ADC=	50 kHz HS
#Detector temperature (°C)=	-60.09
#Instrument=	LabRAM HR Evol
#Detector=	SIN-EM FIVIS
#Objective=	x50_VIS_LWD
#Grating=	150 (500nm)
#ND Filter=	100%
#Laser=	532nm_Edge
#Hole=	49.98
#Temperature=	0
#Range=	Visible
#StageXY=	75x50mm Scan+
#StageZ=	Z motor
#X (µm)=	0
#Y (µm)=	0
#Z (µm)=	-21.1
#Full time(s)=	34
#Project=	21_05_28
#Sample=	BU19w
#Site=
#Title=	BU19w-FF-ore1-FI10-V_150 (500nm)_532nm_Edge_100%_x50_VIS_LWD_H50um_15sX2
#Remark=
#Date=	28.05.2021 15:23
#Acquired=	28.05.2021 15:23:57
51.5961	17003.5
56.2453	18426.4
60.8921	16126
65.5367	12521.7
70.1768	9871.96
74.8167	7931.97
79.4543	6492.77
84.0897	5526.52
88.7227	4800.45
93.3513	4132.54
97.9798	3654.94
102.606	3250.65
107.23	2887.53
111.851	2787.99
116.469	2664.67
121.086	2879.61
125.7	4039.66
130.313	4641.37
134.921	3307.06
139.529	2524.65
144.134	2371.72
148.738	2407.06
153.337	2246.17
157.936	2126.54
162.532	2083.43
167.126	2182.62
171.716	2237.9
176.306	2373.05
180.894	2635.71
185.477	3018.41
190.06	3721.7
194.64	4798.19
199.219	6461.93
203.793	7965.19
208.367	8514.97
212.939	7560.42
217.506	6061.82
222.073	4556.06
226.638	3586.91
231.199	2861.93
235.759	2561.25
240.318	2178.79
244.872	2049.01
249.425	1929.02
253.977	1884.59
258.524	1953.39
263.071	2530.18
267.616	2548.53
272.156	1849.8
276.697	1502.75
281.233	1430.41
285.769	1361.23
290.303	1324.58
294.832	1264.31
299.361	1273.33
303.886	1259.29
308.411	1244.74
312.934	1214.31
317.452	1220.37
321.97	1219.23
326.484	1246.77
330.998	1225.04
335.507	1239.53
340.017	1243.84
344.524	1264.76
349.027	1396.91
353.53	2151.03
358.028	2601.26
362.527	1839.4
367.021	1438.26
371.515	1361.1
376.004	1378.88
380.494	1367.95
384.979	1302.97
389.465	1382.14
393.946	1466.28
398.427	1491.54
402.903	1539.99
407.38	1489.78
411.852	1407.03
416.324	1383.35
420.792	1458.84
425.26	1480.02
429.723	1496.99
434.187	1584.76
438.646	1736.07
443.105	1935.93
447.56	2411.65
452.015	3395.62
456.466	5910.55
460.914	14415
465.362	24641
469.807	19372.7
474.251	9283.49
478.69	5041.56
483.13	3536.89
487.566	2851.28
491.999	2524.97
496.432	2293.66
500.861	2032.91
505.29	1958.87
509.715	2019.59
514.138	2058.3
518.56	1863.52
522.979	1833.55
527.395	1671.09
531.811	1654.6
536.223	1602.54
540.635	1616.49
545.042	1581.69
549.448	1611.87
553.853	1562.94
558.255	1518.86
562.654	1519.86
567.053	1525.84
571.448	1500.07
575.841	1526.26
580.232	1526
584.622	1510.78
589.009	1540
593.393	1537.25
597.777	1521.71
602.157	1561.42
606.535	1516.49
610.913	1482.06
615.287	1542.51
619.659	1526.42
624.029	1547.98
628.398	1571.05
632.763	1524.83
637.127	1561.45
641.488	1613.64
645.849	1531.56
650.206	1512.93
654.561	1574.61
658.914	1524.56
663.267	1547.34
667.615	1519.61
671.962	1508.68
676.307	1573.95
680.649	1551.12
684.991	1588.58
689.33	1554.22
693.666	1620.78
698	1662.84
702.332	1653.08
706.662	1568.87
710.992	1558.68
715.318	1598.55
719.641	1613.54
723.963	1588.44
728.283	1593.29
732.6	1569.06
736.918	1573.37
741.231	1546.39
745.542	1576.39
749.852	1591.09
754.159	1578.76
758.464	1582.76
762.767	1601.32
767.068	1654.63
771.369	1637.8
775.666	1618.7
779.961	1650.05
784.254	1679.63
788.545	1711.57
792.834	1804.6
797.12	1843.37
801.405	1946.76
805.688	2196.61
809.968	2385.58
814.247	2153.77
818.524	1850.73
822.798	1768.68
827.071	1683.75
831.341	1728.86
835.612	1720.05
839.878	1681.32
844.142	1728.41
848.405	1689.91
852.665	1709.99
856.923	1685.96
861.18	1711.48
865.434	1714.63
869.686	1720.5
873.936	1721.58
878.185	1762.8
882.431	1730.12
886.675	1760.19
890.915	1723.7
895.155	1772.53
899.393	1697.42
903.63	1723.72
907.864	1754.12
912.096	1736.85
916.326	1750.96
920.554	1743.07
924.78	1733.43
929.004	1730.41
933.227	1721.98
937.447	1715.53
941.665	1748.23
945.881	1699.34
950.095	1716.72
954.305	1740.91
958.516	1731.16
962.724	1725.92
966.93	1725.12
971.134	1772.29
975.337	1776.28
979.537	1707.39
983.735	1741.63
987.93	1737.69
992.124	1791.06
996.316	1754.71
1000.51	1777.7
1004.7	1705.62
1008.88	1841.87
1013.06	1758.29
1017.25	1770.97
1021.43	1742.06
1025.61	1756.45
1029.78	1764.88
1033.96	1796.21
1038.13	1797.93
1042.3	1781.48
1046.47	1764.98
1050.63	1781.94
1054.8	1794.16
1058.96	1848.08
1063.12	1883.24
1067.28	1930.26
1071.44	1958.91
1075.59	1927.64
1079.74	2167.29
1083.89	2405.71
1088.04	2150.28
1092.19	2002.18
1096.33	1924.57
1100.48	1831.68
1104.62	1892.94
1108.76	1851.55
1112.89	1841.78
1117.03	1846.72
1121.16	1827.79
1125.29	1854.54
1129.42	1851.41
1133.55	1827.29
1137.68	1871.3
1141.8	1853.68
1145.92	1902.23
1150.04	1876.14
1154.16	1954.09
1158.27	2009.67
1162.39	2051.39
1166.5	2019.18
1170.61	1956.53
1174.72	1906.68
1178.82	1885.39
1182.93	1875.4
1187.03	1893.6
1191.13	1925.01
1195.23	1953.66
1199.33	1929.45
1203.42	1903.83
1207.51	1899.51
1211.6	1911.49
1215.69	1959.86
1219.78	1935.63
1223.86	1979.12
1227.95	2046.92
1232.03	2041.15
1236.11	2050.97
1240.18	2029.98
1244.26	2015.56
1248.33	2032.9
1252.41	2022.37
1256.48	1982.31
1260.54	2067.49
1264.61	2190.11
1268.67	2076.09
1272.74	2111.5
1276.8	2084.78
1280.86	2481.85
1284.91	3609.29
1288.97	2554.39
1293.02	2092.8
1297.07	2069.6
1301.12	2028.03
1305.17	2015.29
1309.21	2067.92
1313.25	2055.8
1317.3	2017.75
1321.34	2022.6
1325.37	2032.72
1329.41	2006.38
1333.44	2064.18
1337.48	2072.03
1341.5	2079.49
1345.53	2058.73
1349.56	2081.86
1353.59	2061.17
1357.61	2067.46
1361.63	2080.5
1365.65	2103.76
1369.66	2148.04
1373.68	2194.67
1377.69	2227.73
1381.7	2286.74
1385.72	3643.35
1389.72	4274.25
1393.73	2517.3
1397.73	2204.24
1401.74	2104.52
1405.74	2238.18
1409.73	2315.98
1413.73	2237.26
1417.73	2129.88
1421.72	2079.62
1425.71	2111.01
1429.7	2129.47
1433.69	2088.89
1437.67	2109.47
1441.66	2119.23
1445.64	2152.34
1449.62	2058
1453.6	2092.6
1457.57	2096.39
1461.55	2127.37
1465.52	2134
1469.49	2070.69
1473.46	2088.34
1477.43	2088
1481.39	2171.65
1485.36	2053.37
1489.32	2113.1
1493.28	2136.72
1497.24	2106.72
1501.19	2141.27
1505.15	2137.22
1509.1	2094.91
1513.05	2218.88
1517	2147.72
1520.95	2146.73
1524.9	2154.61
1528.84	2142.29
1532.78	2176.79
1536.72	2168.67
1540.66	2153.85
1544.6	2154.54
1548.53	2157.18
1552.46	2135.6
1556.4	2198.03
1560.32	2185.53
1564.25	2158.29
1568.18	2229.49
1572.1	2178.68
1576.02	2162.66
1579.94	2237.28
1583.86	2198.92
1587.78	2224.03
1591.69	2246.16
1595.61	2254.74
1599.52	2246.98
1603.43	2281.66
1607.34	2225.49
1611.24	2279.73
1615.15	2257.4
1619.05	2263.19
1622.95	2242.98
1626.85	2303.55
1630.74	2273.48
1634.64	2243.19
1638.53	2267.34
1642.42	2289.23
1646.31	2295.33
1650.2	2299.75
1654.09	2279.35
1657.97	2293.28
1661.86	2272.55
1665.74	2280.19
1669.62	2303.92
1673.49	2293.29
1677.37	2220.05
1681.24	2242.67
1685.12	2320.37
1688.99	2257.72
1692.86	2285.72
1696.72	2301.84
1700.59	2252.58
1704.45	2259.25
1708.31	2275.88
1712.17	2207.45
1716.03	2285.26
1719.89	2293.81
1723.74	2278.79
1727.6	2287.18
1731.45	2264.14
1735.3	2248.89
1739.14	2240.93
1742.99	2266.32
1746.83	2273.1
1750.68	2285.9
1754.52	2276.27
1758.36	2280.04
1762.19	2305.24
1766.03	2317.64
1769.86	2305.87
1773.69	2351
1777.53	2331.13
1781.35	2271.94
1785.18	2286.69
1789	2328.86
1792.83	2331.01
1796.65	2334.15
1800.47	2304.3
1804.29	2322.74
1808.1	2312.78
1811.92	2351.54
1815.73	2315.42
1819.54	2305.61
1823.35	2337.65
1827.16	2327.74
1830.97	2329.45
1834.77	2299.45
1838.58	2303.95
1842.38	2309.03
1846.18	2312.59
1849.97	2360.53
1853.77	2293.91
1857.56	2371.81
1861.36	2349.78
1865.15	2331.3
1868.93	2370.7
1872.72	2365.72
1876.51	2356.62
1880.29	2342.19
1884.07	2374.9
1887.86	2346.86
1891.63	2383.23
1895.41	2371.8
1899.19	2387.06
1902.96	2383.12
1906.73	2389.77
1910.5	2348.76
1914.27	2367.58
1918.04	2377.37
1921.8	2407.21
1925.57	2347.54
1929.33	2348.39
1933.09	2391.3
1936.85	2410.09
1940.6	2375.65
1944.36	2374.68
1948.11	2437.43
1951.87	2398.97
1955.61	2432.7
1959.36	2390.05
1963.11	2402.01
1966.86	2378.14
1970.6	2415.48
1974.34	2397.48
1978.08	2389.32
1981.82	2369.55
1985.56	2388.65
1989.29	2369.16
1993.02	2389.4
1996.75	2392.35
2000.49	2408.74
2004.21	2417.78
2007.94	2403.41
2011.67	2418.92
2015.39	2411.46
2019.11	2407.96
2022.83	2397.51
2026.55	2422.43
2030.27	2401.65
2033.98	2409.52
2037.69	2433.78
2041.41	2422.12
2045.12	2415.75
2048.82	2424.1
2052.53	2444.83
2056.24	2441.89
2059.94	2460.4
2063.64	2422.64
2067.34	2499.4
2071.04	2440.26
2074.74	2451.1
2078.43	2414.07
2082.13	2487.32
2085.82	2479.77
2089.51	2459.01
2093.2	2445.49
2096.88	2408.96
2100.57	2452.86
2104.25	2455.03
2107.94	2429.78
2111.62	2484.14
2115.3	2417.54
2118.97	2464.96
2122.65	2446.35
2126.32	2495.88
2129.99	2499.51
2133.66	2462.17
2137.33	2463.58
2141	2502.4
2144.67	2473.44
2148.33	2483.97
2151.99	2441.15
2155.66	2468.24
2159.31	2475.21
2162.97	2508.04
2166.63	2495.55
2170.28	2475.32
2173.94	2488.05
2177.59	2464.91
2181.24	2484.88
2184.89	2493.82
2188.53	2467.95
2192.18	2495.81
2195.82	2542.93
2199.46	2453.11
2203.1	2457.34
2206.74	2506.71
2210.38	2544.74
2214.01	2464.22
2217.65	2499.11
2221.28	2479.99
2224.91	2460.95
2228.54	2501.54
2232.16	2498.96
2235.79	2504.91
2239.41	2505.24
2243.04	2499.94
2246.66	2535.38
2250.28	2500.37
2253.89	2496.26
2257.51	2477.43
2261.12	2522.98
2264.74	2496.27
2268.35	2488.49
2271.96	2537.65
2275.57	2480.81
2279.17	2462.71
2282.78	2492
2286.38	2483.51
2289.98	2518.45
2293.58	2526.61
2297.18	2492.26
2300.78	2473.12
2304.37	2529.32
2307.97	2450.45
2311.56	2511.48
2315.15	2460.28
2318.74	2511.02
2322.33	2481.58
2325.91	2564.23
2329.5	2775.95
2333.08	2600.65
2336.66	2482.05
2340.24	2509.36
2343.82	2445.16
2347.4	2491.57
2350.97	2523.57
2354.54	2502.99
2358.12	2472.05
2361.69	2508.12
2365.26	2497.53
2368.82	2450.97
2372.39	2542.23
2375.95	2456.42
2379.52	2492.77
2383.08	2510.88
2386.64	2526.43
2390.19	2473.47
2393.75	2449.58
2397.31	2512.66
2400.86	2488.53
2404.41	2481.37
2407.96	2449.76
2411.51	2469.62
2415.06	2491.93
2418.6	2513.06
2422.15	2453.65
2425.69	2552.24
2429.23	2493.02
2432.77	2492.35
2436.31	2486.66
2439.84	2509.99
2443.38	2488.92
2446.91	2528.49
2450.44	2455.53
2453.97	2499.91
2457.5	2528.75
2461.03	2496.14
2464.55	2490.55
2468.08	2511.14
2471.6	2543.26
2475.12	2442.79
2478.64	2452.43
2482.16	2497.32
2485.67	2523.31
2489.19	2520.4
2492.7	2536.73
2496.21	2498.12
2499.72	2466.12
2503.23	2523.17
2506.74	2473.17
2510.25	2499.21
2513.75	2484.4
2517.25	2495.33
2520.75	2476.97
2524.25	2482.87
2527.75	2526.37
2531.25	2493.76
2534.74	2547.42
2538.24	2529.79
2541.73	2523.85
2545.22	2502.5
2548.71	2493.3
2552.2	2527.64
2555.68	2520.18
2559.17	2537.09
2562.65	2541.11
2566.13	2495.09
2569.61	2502.8
2573.09	2509.33
2576.57	2501.38
2580.04	2522.05
2583.51	2525.08
2586.99	2474.18
2590.46	2484
2593.93	2502.07
2597.4	2493.11
2600.86	2471.48
2604.33	2481.1
2607.79	2530.55
2611.25	2445.5
2614.71	2495.99
2618.17	2509.97
2621.63	2516.19
2625.09	2488.27
2628.54	2508.67
2631.99	2476.79
2635.45	2445.29
2638.9	2484.05
2642.34	2508.86
2645.79	2437.5
2649.24	2481.7
2652.68	2513.73
2656.12	2490.77
2659.56	2462.64
2663.01	2476.96
2666.44	2496.65
2669.88	2467.17
2673.32	2484.71
2676.75	2465.99
2680.18	2514.18
2683.61	2466.48
2687.04	2459.95
2690.47	2491.39
2693.9	2479.86
2697.32	2473.43
2700.75	2501.99
2704.17	2445.04
2707.59	2498.88
2711.01	2484.72
2714.43	2490.61
2717.84	2463.48
2721.26	2476.86
2724.67	2467.27
2728.08	2448.51
2731.49	2478.48
2734.9	2481.23
2738.31	2501.79
2741.71	2505.38
2745.12	2449.33
2748.52	2490.56
2751.92	2471.7
2755.32	2527.88
2758.72	2449.2
2762.12	2432.66
2765.52	2441.83
2768.91	2454.39
2772.3	2450.53
2775.7	2464.35
2779.09	2427.81
2782.47	2474.76
2785.86	2463.12
2789.25	2467.41
2792.63	2492.27
2796.01	2428.72
2799.4	2419.7
2802.78	2476.89
2806.15	2481.53
2809.53	2441.15
2812.91	2459.65
2816.28	2458.34
2819.65	2448.57
2823.03	2470.94
2826.4	2443.24
2829.76	2433.48
2833.13	2419.4
2836.5	2428.13
2839.86	2427.03
2843.22	2451.57
2846.59	2445.95
2849.95	2477.58
2853.3	2476.24
2856.66	2435.35
2860.02	2426.51
2863.37	2428.26
2866.72	2492.9
2870.08	2379.41
2873.43	2416.75
2876.77	2408.95
2880.12	2415.19
2883.47	2451.51
2886.81	2437.71
2890.15	2432.32
2893.5	2395.6
2896.84	2459.4
2900.17	2407.52
2903.51	2421.45
2906.85	2469.14
2910.18	2446.61
2913.52	2413.48
2916.85	2425.6
2920.18	2417.49
2923.51	2450.86
2926.83	2462.24
2930.16	2413.73
2933.48	2453.75
2936.81	2373.51
2940.13	2424.45
2943.45	2449.87
2946.77	2412.27
2950.09	2450.99
2953.4	2407.78
2956.72	2476.49
2960.03	2431.93
2963.34	2425.17
2966.65	2405.43
2969.96	2400.5
2973.27	2448.52
2976.58	2453.49
2979.88	2437.29
2983.19	2430.19
2986.49	2426.04
2989.79	2442.7
2993.09	2456.62
2996.39	2461.3
2999.68	2452.01
3002.98	2380.61
3006.27	2428.65
3009.57	2456.21
3012.86	2418.01
3016.15	2442
3019.43	2420.71
3022.72	2426.7
3026.01	2408.18
3029.29	2406.67
3032.57	2422.11
3035.86	2435.56
3039.14	2453.68
3042.41	2463.32
3045.69	2380.25
3048.97	2442.96
3052.24	2423.3
3055.52	2466.26
3058.79	2484.49
3062.06	2460.2
3065.33	2501.73
3068.6	2453.77
3071.86	2540.97
3075.13	2459.02
3078.39	2447.89
3081.65	2486.23
3084.91	2433.73
3088.17	2449.39
3091.43	2473.35
3094.69	2469.92
3097.95	2496.62
3101.2	2530.61
3104.45	2461.44
3107.7	2502.79
3110.95	2505.75
3114.2	2522.18
3117.45	2552.17
3120.7	2527.96
3123.94	2537.08
3127.18	2558.54
3130.43	2521.8
3133.67	2546.08
3136.91	2575.07
3140.14	2555.3
3143.38	2577.45
3146.61	2578.63
3149.85	2619.09
3153.08	2630.99
3156.31	2636.11
3159.54	2658.47
3162.77	2624.46
3166	2626.7
3169.22	2705.05
3172.45	2641.01
3175.67	2694.24
3178.89	2682.35
3182.11	2771.54
3185.33	2686.23
3188.55	2733.17
3191.77	2739.02
3194.98	2775.36
3198.2	2787.81
3201.41	2704.02
3204.62	2777.48
3207.83	2759.62
3211.04	2713.35
3214.25	2808.1
3217.45	2806.93
3220.66	2863.8
3223.86	2799
3227.06	2762.07
3230.26	2818.43
3233.46	2846.47
3236.66	2839.12
3239.85	2857.14
3243.05	2842.95
3246.24	2912.73
3249.44	2845.35
3252.63	2866.86
3255.82	2904.69
3259.01	2892.86
3262.19	2848.14
3265.38	2890.85
3268.56	2891.15
3271.75	2851.03
3274.93	2859.46
3278.11	2945.21
3281.29	2910.96
3284.47	2882.88
3287.64	2913.09
3290.82	2977.35
3293.99	2916.93
3297.17	2900.28
3300.34	2950.35
3303.51	2861.11
3306.68	2878.72
3309.84	2949.28
3313.01	2910.02
3316.18	2973.17
3319.34	2918.53
3322.5	2949.16
3325.66	2941.9
3328.82	2962.1
3331.98	2974.79
3335.14	2979.15
3338.29	2939.4
3341.45	2993.32
3344.6	3009.54
3347.75	2978.41
3350.9	2968.76
3354.05	3006.2
3357.2	3064.72
3360.35	3045.17
3363.49	3060.86
3366.64	3052.11
3369.78	3045.41
3372.92	3097.34
3376.06	3043.95
3379.2	3091.7
3382.34	3114.13
3385.48	3094.84
3388.61	3121.2
3391.75	3087.05
3394.88	3170.15
3398.01	3141.69
3401.14	3150.02
3404.27	3147.25
3407.4	3170.43
3410.52	3151.03
3413.65	3138.16
3416.77	3193.12
3419.89	3158.32
3423.01	3216.67
3426.13	3175.15
3429.25	3178.85
3432.37	3144.88
3435.49	3140.81
3438.6	3162.74
3441.72	3207.01
3444.83	3168.17
3447.94	3100.09
3451.05	3108.26
3454.16	3203.61
3457.26	3167.36
3460.37	3202.08
3463.47	3150.16
3466.58	3135.21
3469.68	3149.23
3472.78	3092.52
3475.88	3069.07
3478.98	3117.75
3482.07	3056.81
3485.17	3048.95
3488.26	3029.03
3491.36	3038.87
3494.45	3011.78
3497.54	2953.46
3500.63	2949.67
3503.72	2933.7
3506.81	2967.22
3509.89	2940.39
3512.98	2904.21
3516.06	2843.24
3519.14	2803.42
3522.22	2837.33
3525.3	2817.71
3528.38	2862.65
3531.45	2769.44
3534.53	2703.9
3537.61	2726.74
3540.68	2668.67
3543.75	2641
3546.82	2600.61
3549.89	2648.02
3552.96	2635.28
3556.03	2592.96
3559.09	2556.72
3562.16	2581.05
3565.22	2551.81
3568.28	2497.53
3571.34	2486.66
3574.4	2480.28
3577.46	2461.68
3580.52	2419.16
3583.57	2389.72
3586.63	2423.6
3589.68	2374.01
3592.73	2387.65
3595.78	2388.9
3598.83	2371.93
3601.88	2278.26
3604.93	2339.67
3607.97	2277.84
3611.02	2295.49
3614.06	2247.78
3617.1	2315.27
3620.14	2259.13
3623.18	2272.02
3626.22	2225.57
3629.26	2212.29
3632.3	2177.23
3635.33	2172.22
3638.36	2166.81
3641.4	2157.94
3644.43	2122.03
3647.46	2164.77
3650.49	2091.18
3653.51	2079.99
3656.54	2072.74
3659.57	2039.98
3662.59	2045.57
3665.61	2036.64
3668.63	2056.92
3671.65	1994.73
3674.67	2037.28
3677.69	1963.9
3680.71	1969.88
3683.72	1945.52
3686.74	1933.44
3689.75	1943.18
3692.76	1931.2
3695.77	1927.75
3698.78	1906.86
3701.79	1896.79
3704.79	1888.61
3707.8	1923.13
3710.81	1892.84
3713.81	1875.69
3716.81	1872.55
3719.81	1873.35
3722.81	1888.19
3725.81	1856.23
3728.81	1865.98
3731.8	1862.27
3734.8	1876.47
3737.79	1847.61
3740.78	1822.4
3743.77	1839.81
3746.76	1832.32
3749.75	1835.11
3752.74	1814
3755.73	1825.18
3758.71	1795.59
3761.7	1832.36
3764.68	1800.7
3767.66	1796.6
3770.64	1783.17
3773.62	1786
3776.6	1791.8
3779.58	1831.72
3782.55	1795.22
3785.53	1771.04
3788.5	1815.89
3791.47	1802.32
3794.44	1780.55
3797.41	1762.69
3800.38	1760.99
3803.35	1745.36
3806.32	1783.65
3809.28	1771
3812.24	1753.73
3815.21	1800.78
3818.17	1774.13
3821.13	1735.23
3824.09	1798.61
3827.04	1694.48
3830	1739.08
3832.96	1749.58
3835.91	1756.47
3838.86	1754.91
3841.82	1755.24
3844.77	1743.2
3847.72	1753.07
3850.67	1730.64
3853.61	1751.19
3856.56	1757.49
3859.5	1752.35
3862.45	1706.12
3865.39	1729.55
3868.33	1708.97
3871.27	1719.84
3874.21	1696.14
3877.15	1714.57
3880.09	1689.61
3883.02	1686.54
3885.96	1705.37
3888.89	1710.62
3891.82	1728.3
3894.75	1671.85
3897.68	1700.77
3900.61	1696.8
3903.54	1683.16
3906.47	1699.12
3909.39	1686.44
3912.31	1720.69
3915.24	1663.49
3918.16	1708.97
3921.08	1682.73
3924	1662.87
3926.92	1651.49
3929.83	1622.7
3932.75	1674.35
3935.67	1664.1
3938.58	1627.39
3941.49	1629.28
3944.4	1637.72
3947.31	1681.68
3950.22	1596.55
3953.13	1676.22
3956.04	1632.44
3958.94	1642.44
3961.85	1653.48
3964.75	1605.17
3967.65	1607.75
3970.55	1625.76
3973.45	1651.51
3976.35	1635
3979.25	1627
3982.15	1637.16
3985.04	1616.52
3987.94	1625.6
3990.83	1632.71
3993.72	1632.89
3996.61	1614.13
3999.5	1639.61
4002.39	1621.86
4005.28	1601.23
4008.16	1602.84
4011.05	1642.05
4013.93	1578.09
4016.81	1645.29
4019.7	1620.87
4022.58	1581.93
4025.46	1595.12
4028.33	1568.74
4031.21	1572.32
4034.09	1538.22
4036.96	1572.81
4039.84	1569.74
4042.71	1575.34
4045.58	1560.34
4048.45	1585.14
4051.32	1540.23
4054.19	1564.24
4057.05	1537.96
4059.92	1584.42
4062.78	1514.27
4065.65	1522.81
4068.51	1543.98
4071.37	1538.88
4074.23	1530.84
4077.09	1521.79
4079.95	1578.97
4082.81	1521.18
4085.66	1509.17
4088.52	1483.42
4091.37	1544.51
4094.22	1538.39
4097.07	1527.26
4099.92	1500.57
4102.77	1544.21
4105.62	1536
4108.47	1572.59
4111.31	1506.48
4114.16	1496.92
4117	1490.15
4119.84	1510.56
4122.69	1524.14
4125.53	1490.93
4128.36	1491.03
4131.2	1521.89
4134.04	1474.64
4136.88	1479.74
4139.71	1523.15
4142.54	1470.21
4145.38	1502.39
4148.21	1481.34
4151.04	1476.07
4153.87	1485.15
4156.69	1477.03
4159.52	1440.9
4162.35	1490.43
4165.17	1439.39
4168	1461.69
4170.82	1456.68
4173.64	1486.95
4176.46	1434.14
4179.28	1469.35
4182.1	1476.32
4184.91	1488.23
4187.73	1437.62
4190.54	1434.97
4193.36	1450.17
4196.17	1429.3
4198.98	1448.79
4201.79	1472.18
4204.6	1432.86
4207.41	1427.8
4210.22	1389.37
4213.02	1416.69
4215.83	1412.55
4218.63	1422.06
4221.44	1439.38
4224.24	1418.13
4227.04	1421.33
4229.84	1421.82
4232.64	1425.34
4235.43	1412.2
4238.23	1379.27
4241.02	1389.99
4243.82	1368.96
4246.61	1408.7
4249.4	1381.64
4252.19	1385.34
4254.98	1418.99
4257.77	1408.55
4260.56	1364.01
4263.35	1382.62
4266.13	1369.19
4268.92	1349.79
4271.7	1383.68
4274.48	1368.22
4277.26	1394.81
4280.04	1357.64
4282.82	1367.81
4285.6	1325.26
4288.38	1367.47
4291.15	1403.51
4293.93	1337.23
4296.7	1316.67
4299.47	1361.09
4302.25	1322.24
4305.02	1334.08
4307.79	1341.87
4310.55	1349.73
4313.32	1382.13
4316.09	1329.92
4318.85	1289.74
4321.62	1340.04
4324.38	1365.81
4327.14	1347.74
4329.9	1296.1
4332.66	1293.19
4335.42	1325
4338.18	1327.13
4340.94	1321.37
4343.69	1374.74
4346.45	1312.03
4349.2	1295.3
4351.95	1313.27
4354.7	1306.08
4357.45	1315.09
4360.2	1315.93
4362.95	1259.37
4365.7	1281.73
4368.44	1286.58
4371.19	1292.6
4373.93	1288.12
4376.68	1271.29
4379.42	1292.32
4382.16	1292.8
4384.9	1280.01
4387.64	1267.49
4390.37	1266.78
4393.11	1293.07
4395.85	1298.78
4398.58	1272.51
4401.31	1246.1
4404.05	1262
4406.78	1228.19
4409.51	1295.14
4412.24	1235.19
4414.96	1284.26
4417.69	1256.24
4420.42	1262.06
4423.14	1261.87
4425.87	1249.23
4428.59	1219.87
4431.31	1223.92
4434.03	1244.69
4436.75	1229.82
4439.47	1204.4
4442.19	1237.52
4444.91	1240.3
4447.62	1267.14
4450.34	1214.21
4453.05	1213.64
4455.76	1185.73
4458.47	1190.27
4461.19	1200.02
4463.89	1202.58
4466.6	1171.43
4469.31	1215.06
4472.02	1225.1
4474.72	1172.03
4477.43	1199.14
4480.13	1220.04
4482.83	1195.65
4485.53	1194.47
4488.23	1161.46
4490.93	1180.2
4493.63	1185.97
4496.33	1190.49
4499.02	1170.87
4501.72	1162.83
4504.41	1183.3
4507.11	1188
4509.8	1160.92
4512.49	1122.15
4515.18	1166.18
4517.87	1144.43
4520.56	1160.97
4523.24	1140.43
4525.93	1158.17
4528.61	1140.77
4531.3	1135.11
4533.98	1130.53
4536.66	1159.06
4539.34	1104.4
4542.02	1121.31
4544.7	1114.71
4547.38	1154.15
4550.05	1120.84
4552.73	1125.11
4555.4	1138.17
4558.08	1092.32
4560.75	1133.86
4563.42	1126.14
4566.09	1102.54
4568.76	1093.21
4571.43	1115.71
4574.1	1081.65
4576.77	1098.14
4579.43	1099.97
4582.1	1093.58
4584.76	1073.21
4587.42	1093.59
4590.08	1089.94
4592.74	1095.99
4595.4	1098.85
4598.06	1039.57
4600.72	1082.87
4603.38	1062.99
4606.03	1074.89
4608.69	1062.72
4611.34	1072.48
4613.99	1061.36
4616.64	1048.01
4619.29	1079.79
4621.94	1057.74
4624.59	1067.56
4627.24	1054.15
4629.89	1068.28
4632.53	1039.29
4635.18	1058.75
4637.82	1081.49
4640.46	1048.89
4643.1	1037.31
4645.74	1040.37
4648.38	1035.95
4651.02	1038.44
4653.66	1045.77
4656.3	1027.03
4658.93	1040.6
4661.57	1012.55
4664.2	1048.29
4666.83	1052.64
4669.46	1019.83
4672.09	1008.34
4674.72	1023.7
4677.35	999.823
4679.98	1009.56
4682.61	1020.4
4685.23	1000.92
4687.86	1029.77
4690.48	1000.15
4693.1	1015.55
4695.73	1000.46
4698.34	989.841
4700.96	1010.84
4703.58	1030.7
4706.2	1007.54
4708.82	1015.99
4711.43	970.107
4714.05	1006.79
4716.66	989.111
4719.28	1007.62
4721.89	1017.04
4724.5	990.145
4727.11	1006.46
4729.72	992.219
4732.33	981.377
4734.93	996.651
4737.54	972.127
4740.14	973.669
4742.75	1004.74
4745.35	960.68
4747.95	969.999
4750.55	980.32
4753.15	1005.47
4755.75	974.832
4758.35	954.429
4760.95	963.714
4763.54	937.77
4766.14	942.626
4768.73	948.844
4771.33	958.567
4773.92	964.677
4776.51	935.425
4779.1	938.13
4781.69	941.965
4784.28	920.668
4786.87	901.649
4789.45	939.819
4792.04	979.207
4794.63	916.752
4797.21	940.203
4799.79	922.502
4802.37	920.901
4804.95	934.306
4807.53	926.013
4810.11	899.361
4812.69	912.963
4815.27	933.567
4817.84	896.553
4820.42	942.753
4822.99	897.624
4825.57	919.618
4828.14	906.835
4830.71	884.741
4833.28	924.342
4835.85	907
4838.42	904.891
4840.98	893.506
4843.55	931.21
4846.12	856.327
4848.68	892.654
4851.24	904.11
4853.81	892.647
4856.37	873.104
4858.93	869.685
4861.49	890.963
4864.05	874.261
4866.61	872.582
4869.16	857.951
4871.72	860.056
4874.27	895.133
4876.83	836.495
4879.38	848.959
4881.93	888.695
4884.49	867.837
4887.04	868.344
4889.58	864.115
4892.13	850.363
4894.68	885.384
4897.23	873.948
4899.77	856.511
4902.32	861.698
4904.86	837.051
4907.4	842.184
4909.95	861.624
4912.49	839.075
4915.03	822.429
4917.57	851.092
4920.1	849.988
4922.64	817.816
4925.18	804.765
4927.71	820.451
4930.25	828.861
4932.78	833.914
4935.31	833.15
4937.84	816.731
4940.38	815.849
4942.9	821.782
4945.43	805.276
4947.96	806.858
4950.49	807.212
4953.01	794.447
4955.54	819.956
4958.06	812.034
4960.59	794.56
4963.11	796.37
4965.63	816.459
4968.15	780.121
4970.67	770.003
4973.19	792.421
4975.71	778.613
4978.22	802.247
4980.74	789.656
4983.25	768.572
4985.77	785.062
4988.28	788.252
4990.79	770.813
4993.3	794.649
4995.81	781.996
4998.32	781.637