File: Data/3-Raman/raw/bu19w-e-ff11b-fi10-v_150 (500nm)_633nm_edge_100%_x100_vis_h50um_60sx2_01.txt
#Acq. time (s)=	60
#Accumulations=	2
#Range (cm-¹)=	100...4000
#Windows=	1
#Auto scanning=	Off
#Autofocus=	Off
#Macrospot=	Off
#AutoExposure=	Off
#Spike filter=	Multiple accum.
#Delay time (s)=	2
#Binning=	1
#Readout mode=	Signal
#DeNoise=	Off
#ICS correction=	On
#Dark correction=	Off
#Inst. Process=	Off
#Detector Gain=	Best Dynamic
#Detector ADC=	50 kHz HS
#Detector temperature (°C)=	-60.09
#Instrument=	LabRAM HR Evol
#Detector=	SIN-EM FIVIS
#Objective=	x100_VIS
#Grating=	150 (500nm)
#ND Filter=	100%
#Laser=	633nm_Edge
#Hole=	49.98
#Temperature=	0
#Range=	Visible
#StageXY=	75x50mm Scan+
#StageZ=	Z motor
#X (µm)=	0
#Y (µm)=	0
#Z (µm)=	-271.2
#Full time(mm:ss)=	2:04
#Project=	21_11_04
#Sample=	BU19w
#Site=
#Title=	BU19w-E-FF11b-FI10-V_150 (500nm)_633nm_Edge_100%_x100_VIS_H50um_60sX2
#Remark=
#Date=	04.11.2021 17:04
#Acquired=	04.11.2021 17:04:15
102.881	265.522
109.397	305.858
115.908	577.447
122.414	325.494
128.914	244.397
135.409	235.872
141.898	213.869
148.383	214.872
154.861	214.007
161.335	214.128
167.801	214.239
174.264	257.404
180.721	347.359
187.173	481.914
193.62	600.585
200.061	518.735
206.496	386.01
212.926	265.657
219.352	215.018
225.772	188.188
232.185	171.747
238.595	151.614
244.999	157.228
251.397	204.632
257.791	159.902
264.178	128.534
270.561	124.714
276.939	122.814
283.31	116.146
289.678	108.501
296.039	106.514
302.396	115.882
308.746	113.879
315.093	110.004
321.433	109.936
327.768	105.186
334.099	112.715
340.423	151.352
346.743	161.664
353.058	107.872
359.367	109.659
365.671	107.667
371.971	108.498
378.265	114.012
384.553	129.862
390.837	148.693
397.116	111.328
403.389	110.642
409.657	108.044
415.92	111.985
422.178	127.258
428.431	135.645
434.678	171.171
440.921	255.426
447.158	671.332
453.391	1579.65
459.618	783.55
465.84	322.997
472.057	206.324
478.27	177.472
484.477	146.746
490.679	138.379
496.876	133.751
503.068	131.939
509.255	116.149
515.436	116.241
521.613	111.729
527.785	106.326
533.952	106.603
540.113	102.166
546.27	107.062
552.423	103.367
558.568	93.9535
564.711	100.428
570.848	96.4352
576.979	100.822
583.107	92.1041
589.228	101.219
595.345	94.5744
601.458	88.0723
607.565	103.139
613.667	89.3203
619.764	96.1445
625.856	90.8226
631.944	97.5998
638.026	98.557
644.104	100.296
650.177	94.4972
656.244	90.5094
662.308	96.8124
668.365	91.9065
674.418	92.7861
680.467	96.5173
686.511	111.534
692.549	92.1156
698.582	91.3861
704.611	92.511
710.635	86.9939
716.655	90.6921
722.669	88.7623
728.679	81.135
734.683	90.3527
740.683	93.9303
746.678	83.5246
752.669	90.9099
758.654	92.7686
764.635	85.4768
770.611	92.277
776.582	94.4142
782.549	106.837
788.511	117.339
794.466	123.08
800.419	113.632
806.366	108.814
812.309	96.4321
818.247	88.7195
824.18	89.4432
830.108	80.8336
836.033	89.2235
841.952	87.4844
847.865	85.766
853.776	86.9026
859.681	93.7258
865.58	98.7074
871.476	90.4329
877.366	90.553
883.253	85.8741
889.134	89.6687
895.012	86.771
900.883	78.0984
906.751	85.4629
912.614	86.1784
918.473	86.9403
924.326	90.6384
930.174	86.0067
936.019	79.5658
941.859	82.6784
947.693	80.1521
953.525	87.131
959.35	80.7275
965.171	81.8814
970.988	82.0286
976.801	77.2789
982.608	72.4084
988.411	77.0831
994.209	75.0321
1000	79.6846
1005.79	73.8824
1011.58	71.0369
1017.36	76.8313
1023.13	73.1177
1028.9	72.3353
1034.67	77.3363
1040.43	76.613
1046.19	73.9531
1051.94	79.9467
1057.69	89.7953
1063.44	86.9521
1069.17	94.6902
1074.91	99.5064
1080.64	79.0508
1086.37	80.914
1092.09	76.9934
1097.8	74.0406
1103.52	75.939
1109.22	74.0423
1114.93	72.2625
1120.63	84.1685
1126.32	84.3557
1132.01	68.9259
1137.7	75.9573
1143.38	84.9804
1149.06	97.8987
1154.73	86.1553
1160.4	77.2534
1166.06	81.0372
1171.72	77.9443
1177.38	70.9342
1183.03	67.8914
1188.67	83.4987
1194.31	77.6905
1199.95	76.8446
1205.58	80.0352
1211.21	79.3485
1216.84	80.68
1222.46	88.0267
1228.07	75.4562
1233.68	73.7666
1239.29	79.0515
1244.89	72.153
1250.49	77.2718
1256.08	81.3265
1261.67	76.1928
1267.26	81.1299
1272.84	141.343
1278.42	82.8133
1283.99	74.6286
1289.56	73.517
1295.12	77.4572
1300.68	70.4536
1306.23	71.5226
1311.78	72.6971
1317.33	70.9164
1322.87	71.1691
1328.41	75.5082
1333.94	76.8174
1339.47	71.971
1345	69.0726
1350.52	79.4581
1356.04	87.7921
1361.55	83.7554
1367.06	82.7316
1372.56	104.276
1378.06	176.128
1383.56	76.4753
1389.05	75.4127
1394.53	78.5031
1400.02	74.51
1405.5	79.7642
1410.97	78.8755
1416.44	78.0121
1421.91	71.9789
1427.37	74.2386
1432.83	84.842
1438.28	74.6196
1443.73	86.3136
1449.17	82.3002
1454.62	78.1963
1460.05	70.88
1465.48	72.9738
1470.91	82.3996
1476.34	71.8992
1481.76	79.2793
1487.17	89.8466
1492.59	81.5429
1497.99	80.6331
1503.4	77.6348
1508.8	79.9475
1514.19	72.7438
1519.59	86.8312
1524.97	79.6484
1530.36	74.5624
1535.74	75.9175
1541.11	83.6894
1546.48	81.6578
1551.85	80.5809
1557.21	83.7209
1562.57	80.3993
1567.93	85.7072
1573.28	75.9246
1578.62	80.1944
1583.97	86.6621
1589.3	84.5438
1594.64	81.3833
1599.97	80.4134
1605.3	94.6207
1610.62	82.9425
1615.94	96.2848
1621.25	89.0115
1626.56	80.5789
1631.87	88.5779
1637.17	83.3172
1642.47	91.1582
1647.76	81.3378
1653.05	72.5675
1658.34	87.0251
1663.62	81.5072
1668.9	88.1687
1674.18	84.8431
1679.45	91.4817
1684.71	83.6601
1689.98	89.1265
1695.23	84.6806
1700.49	77.0271
1705.74	80.7531
1710.99	87.5548
1716.23	83.1261
1721.47	77.7682
1726.7	86.8592
1731.94	80.3024
1737.16	80.4611
1742.39	83.9975
1747.61	83.017
1752.82	85.3861
1758.03	74.1402
1763.24	90.0167
1768.44	75.3335
1773.64	71.9807
1778.84	81.1353
1784.03	83.5343
1789.22	75.7283
1794.41	89.5947
1799.59	87.5347
1804.76	75.1556
1809.94	81.0868
1815.11	84.7185
1820.27	83.7466
1825.43	90.8816
1830.59	85.2939
1835.74	78.5277
1840.89	91.5111
1846.04	83.4978
1851.18	88.3126
1856.32	87.2533
1861.45	96.798
1866.58	89.9442
1871.71	85.3932
1876.83	86.6874
1881.95	84.4298
1887.07	90.4216
1892.18	82.1665
1897.29	84.5429
1902.39	79.8964
1907.49	84.7948
1912.59	90.9798
1917.68	94.8549
1922.77	90.1834
1927.86	84.3763
1932.94	89.3342
1938.02	97.8904
1943.09	83.588
1948.16	93.3059
1953.23	94.5666
1958.29	83.7533
1963.35	87.3833
1968.41	89.7817
1973.46	88.528
1978.51	83.6647
1983.55	87.2265
1988.59	90.7954
1993.63	88.3624
1998.66	88.3542
2003.69	85.9666
2008.72	100.451
2013.74	90.9019
2018.76	95.783
2023.77	91.0378
2028.78	95.9875
2033.79	94.9508
2038.79	91.4975
2043.79	90.4694
2048.79	95.5371
2053.78	92.0483
2058.77	98.3472
2063.76	91.2206
2068.74	95.1054
2073.72	92.8477
2078.69	100.426
2083.66	90.7268
2088.63	89.6126
2093.59	92.2481
2098.55	93.7002
2103.51	97.662
2108.46	100.42
2113.41	106.975
2118.36	89.7374
2123.3	96.3044
2128.24	97.8441
2133.17	100.632
2138.11	98.3305
2143.03	99.8172
2147.96	96.1819
2152.88	111.625
2157.79	97.6976
2162.71	99.0472
2167.62	95.244
2172.52	101.693
2177.43	100.485
2182.32	97.9382
2187.22	95.3648
2192.11	103.082
2197	96.749
2201.89	99.4394
2206.77	95.7516
2211.64	102.389
2216.52	111.662
2221.39	100.298
2226.26	103.149
2231.12	104.712
2235.98	106.282
2240.84	100.012
2245.69	98.9579
2250.54	95.2677
2255.39	107.357
2260.23	99.712
2265.07	106.555
2269.9	98.7913
2274.74	92.2903
2279.57	108.342
2284.39	105.742
2289.21	104.44
2294.03	112.448
2298.84	112.51
2303.66	108.622
2308.46	104.794
2313.27	110.362
2318.07	109.293
2322.87	114.944
2327.66	108.515
2332.45	120.995
2337.24	115.946
2342.02	110.881
2346.8	114.015
2351.58	107.562
2356.35	109.263
2361.12	115.02
2365.89	111.126
2370.65	116.897
2375.41	124.062
2380.17	107.62
2384.92	100.796
2389.67	117.572
2394.42	119.006
2399.16	110.654
2403.9	105.076
2408.64	112.044
2413.37	106.663
2418.1	121.183
2422.83	110.33
2427.55	99.247
2432.27	115.031
2436.99	115.375
2441.7	117.141
2446.41	126.035
2451.11	124.988
2455.82	109.591
2460.51	111.348
2465.21	103.023
2469.9	107.633
2474.59	120.941
2479.28	125.618
2483.96	114.278
2488.64	110.14
2493.32	114.748
2497.99	120.848
2502.66	118.141
2507.32	121.281
2511.99	119.984
2516.65	133.4
2521.3	124.749
2525.96	120.506
2530.61	111.805
2535.25	126.841
2539.89	127.093
2544.53	127.356
2549.17	121.669
2553.8	124.928
2558.43	125.157
2563.06	128.431
2567.68	125.738
2572.3	123.05
2576.92	129.409
2581.53	123.608
2586.14	125.299
2590.75	111.721
2595.35	114.895
2599.96	124.223
2604.55	124.382
2609.15	122.996
2613.74	123.089
2618.33	121.665
2622.91	140.154
2627.49	112.709
2632.07	119.061
2636.64	116.284
2641.22	112.015
2645.78	124.784
2650.35	123.615
2654.91	127.068
2659.47	124.169
2664.03	125.913
2668.58	124.523
2673.13	121.644
2677.67	122.089
2682.22	119.529
2686.76	131.206
2691.29	131.754
2695.83	132.097
2700.36	135.584
2704.89	127.818
2709.41	129.663
2713.93	128.28
2718.45	141.498
2722.96	135.282
2727.47	119.243
2731.98	130.72
2736.49	138.953
2740.99	139.069
2745.49	131.106
2749.98	136.232
2754.47	128.457
2758.96	128.701
2763.45	127.254
2767.93	143.965
2772.41	140.937
2776.89	137.982
2781.36	133.432
2785.84	135.546
2790.3	135.993
2794.77	136.414
2799.23	138.456
2803.69	137.097
2808.14	137.374
2812.59	137.626
2817.04	149.667
2821.49	134.656
2825.93	119.615
2830.37	130
2834.81	135.291
2839.24	140.596
2843.67	125.444
2848.1	127.379
2852.53	136.213
2856.95	141.707
2861.37	135.184
2865.78	142.502
2870.19	136.018
2874.6	146.865
2879.01	149.083
2883.41	139.105
2887.81	136.092
2892.21	143.598
2896.6	121.115
2901	139.312
2905.38	139.75
2909.77	141.948
2914.15	136.906
2918.53	128.25
2922.91	135.762
2927.28	125.325
2931.65	138.357
2936.02	136.889
2940.38	135.338
2944.74	150.145
2949.1	143.062
2953.46	139.621
2957.81	158.093
2962.16	147.344
2966.5	140.253
2970.85	142.344
2975.19	140.772
2979.52	153.941
2983.86	135.804
2988.19	136.149
2992.52	153.247
2996.85	144.373
3001.17	148.567
3005.49	165.947
3009.8	145.805
3014.12	138.712
3018.43	154.361
3022.74	143.503
3027.04	147.737
3031.34	142.378
3035.64	152.248
3039.94	152.546
3044.23	149
3048.52	143.482
3052.81	145.653
3057.09	143.989
3061.38	163.604
3065.65	165.832
3069.93	166.122
3074.2	148.901
3078.47	162.83
3082.74	153.363
3087	153.71
3091.27	150.203
3095.52	144.768
3099.78	157.096
3104.03	155.659
3108.28	180.128
3112.53	164.856
3116.77	153.463
3121.01	160.129
3125.25	156.777
3129.49	163.6
3133.72	168.49
3137.95	159.037
3142.18	167.987
3146.4	168.671
3150.62	154.763
3154.84	165.659
3159.06	176.596
3163.27	170.835
3167.48	167.094
3171.69	178.09
3175.89	165.832
3180.09	183.043
3184.29	157.867
3188.49	185.603
3192.68	183.758
3196.87	173.478
3201.06	180.445
3205.24	189.662
3209.42	190.422
3213.6	197.69
3217.78	189.868
3221.95	210.235
3226.12	182.646
3230.29	189.948
3234.45	190.66
3238.61	193.56
3242.77	189.904
3246.93	192.936
3251.08	193.59
3255.23	189.605
3259.38	203.622
3263.53	188.517
3267.67	209.904
3271.81	187.976
3275.95	181.611
3280.08	193.432
3284.21	200.708
3288.34	224.091
3292.47	233.719
3296.59	201.831
3300.71	188.375
3304.83	193.374
3308.95	196.068
3313.06	194.081
3317.17	196.767
3321.27	194.845
3325.38	209.359
3329.48	193.5
3333.58	224.783
3337.67	213.767
3341.77	202.476
3345.86	217.131
3349.95	219.876
3354.03	217.875
3358.11	227.908
3362.19	211.685
3366.27	233.706
3370.34	219.795
3374.42	220.199
3378.48	225.346
3382.55	225.654
3386.61	223.521
3390.68	209.254
3394.73	240.983
3398.79	226.788
3402.84	217.339
3406.89	222.408
3410.94	229.893
3414.98	222.768
3419.03	237.567
3423.06	245.044
3427.1	255.011
3431.14	230.876
3435.17	226.31
3439.2	214.443
3443.22	212.39
3447.25	217.826
3451.27	228.24
3455.28	223.949
3459.3	252.02
3463.31	227.99
3467.32	241.3
3471.33	229.564
3475.34	194.954
3479.34	238.442
3483.34	229.024
3487.33	206.833
3491.33	222.667
3495.32	218.123
3499.31	205.818
3503.3	208.756
3507.28	227.031
3511.26	222.084
3515.24	209.381
3519.22	191.508
3523.19	214.767
3527.16	209.785
3531.13	209.934
3535.1	212.877
3539.06	195.271
3543.02	206.03
3546.98	208.969
3550.93	193.639
3554.89	193.712
3558.84	180.902
3562.78	188.969
3566.73	181.466
3570.67	208.036
3574.61	169.145
3578.55	190.608
3582.48	185.887
3586.41	189.088
3590.35	181.684
3594.27	176.891
3598.2	177.396
3602.12	167.15
3606.04	170.234
3609.95	167.908
3613.87	176.338
3617.78	165.887
3621.69	168.829
3625.6	163.543
3629.5	155.528
3633.4	158.287
3637.3	166.532
3641.2	166.778
3645.09	167.104
3648.98	153.743
3652.87	167.527
3656.76	154.049
3660.64	145.995
3664.53	167.953
3668.4	168.129
3672.28	149.136
3676.16	160.319
3680.03	155.137
3683.9	147.25
3687.76	155.939
3691.63	150.848
3695.49	159.552
3699.35	143.289
3703.2	140.869
3707.06	149.654
3710.91	158.482
3714.76	156.08
3718.6	145.15
3722.45	139.791
3726.29	159.841
3730.13	137.448
3733.97	154.75
3737.8	160.73
3741.63	163.852
3745.46	146.986
3749.29	138.612
3753.11	147.34
3756.93	147.452
3760.75	147.531
3764.57	136.133
3768.39	156.281
3772.2	153.543
3776.01	150.803
3779.81	133.716
3783.62	148.311
3787.42	142.769
3791.22	142.962
3795.02	146.099
3798.81	149.289
3802.61	137.983
3806.4	141.208
3810.18	153.202
3813.97	147.668
3817.75	156.751
3821.53	142.369
3825.31	145.539
3829.09	145.78
3832.86	143.107
3836.63	158.141
3840.4	146.55
3844.17	132.002
3847.93	135.08
3851.69	147.059
3855.45	156.044
3859.21	147.137
3862.96	132.32
3866.71	141.481
3870.46	117.93
3874.21	141.891
3877.95	144.968
3881.69	139.082
3885.44	136.204
3889.17	136.34
3892.91	133.514
3896.64	124.741
3900.37	139.986
3904.1	131.147
3907.82	146.426
3911.55	134.563
3915.27	137.828
3918.99	129.011
3922.7	147.586
3926.42	135.722
3930.13	132.948
3933.84	148.476
3937.54	145.622
3941.25	139.735
3944.95	133.868
3948.65	143.366
3952.35	162.109
3956.04	143.772
3959.73	147.007
3963.42	128.537
3967.11	156.494
3970.8	137.932
3974.48	137.981
3978.16	134.917
3981.84	119.403
3985.52	119.396
3989.19	141.098
3992.86	147.35
3996.53	131.932
3998.37	147.525