File: Data/3-Raman/raw/bu19w-e-ff11b-fi08-l_150 (500nm)_532nm_edge_100%_x100_vis_h50um_30sx2_01.txt
#Acq. time (s)=	30
#Accumulations=	2
#Range (cm-¹)=	100...5000
#Windows=	1
#Auto scanning=	Off
#Autofocus=	Off
#Macrospot=	Off
#AutoExposure=	Off
#Spike filter=	Multiple accum.
#Delay time (s)=	2
#Binning=	1
#Readout mode=	Signal
#DeNoise=	Off
#ICS correction=	On
#Dark correction=	Off
#Inst. Process=	Off
#Detector Gain=	Best Dynamic
#Detector ADC=	50 kHz HS
#Detector temperature (°C)=	-60.09
#Instrument=	LabRAM HR Evol
#Detector=	SIN-EM FIVIS
#Objective=	x100_VIS
#Grating=	150 (500nm)
#ND Filter=	100%
#Laser=	532nm_Edge
#Hole=	49.98
#Temperature=	0
#Range=	Visible
#StageXY=	75x50mm Scan+
#StageZ=	Z motor
#X (µm)=	0
#Y (µm)=	0
#Z (µm)=	-249
#Full time(mm:ss)=	1:04
#Project=	21_11_04
#Sample=	BU19w
#Site=
#Title=	BU19w-E-FF11b-FI08-L_150 (500nm)_532nm_Edge_100%_x100_VIS_H50um_30sX2
#Remark=
#Date=	04.11.2021 17:44
#Acquired=	04.11.2021 17:44:42
101.869	8530.42
106.493	8784.12
111.113	10639.1
115.732	15337.9
120.349	18987.3
124.964	14139.5
129.577	9361.02
134.185	7828.74
138.793	7380.13
143.399	7024.82
148.003	6651.86
152.602	6482.55
157.201	6470.76
161.798	6651.26
166.392	6973.07
170.982	7656.33
175.572	8725.81
180.16	10577.8
184.745	13544.7
189.326	17410.9
193.907	20721.2
198.486	21615.8
203.06	19265.7
207.634	15275.4
212.206	11441.3
216.776	8746.36
221.341	6973.84
225.906	5784.31
230.469	4888.64
235.028	4297.41
239.586	3942.1
244.142	3729.21
248.694	3888.22
253.246	4676.21
257.795	4831.23
262.341	3420.21
266.886	2514.72
271.428	2148.43
275.967	2032.7
280.505	1893.32
285.041	1773.15
289.573	1700.26
294.105	1607.68
298.632	1547.86
303.159	1540.32
307.685	1511.51
312.205	1510.48
316.726	1502.41
321.242	1501.47
325.758	1471.72
330.272	1497.48
334.782	1620.63
339.292	2140.59
343.797	3435.87
348.302	3849.03
352.803	2634.76
357.304	1849.09
361.802	1643.84
366.297	1570.34
370.791	1575.04
375.281	1603.59
379.77	1754.09
384.256	2130.67
388.741	2579.06
393.223	3010.87
397.704	2661
402.18	2012.55
406.657	1806.58
411.13	1803.43
415.602	1868.48
420.07	1968.51
424.538	2164.51
429.002	2481.8
433.465	3196.24
437.925	4596.7
442.384	7961.66
446.839	16506.8
451.294	36707.7
455.745	38141.6
460.196	38202.7
464.642	25396.1
469.089	12670.1
473.531	7890.96
477.971	5737.5
482.411	4556.21
486.846	3783.8
491.282	3242.44
495.713	3037.41
500.144	2966.9
504.572	2741.98
508.997	2535.41
513.421	2363.53
517.842	2204.51
522.263	2064.64
526.679	1979.72
531.093	1880.04
535.507	1774.9
539.917	1714.85
544.327	1647.67
548.733	1554.93
553.137	1506
557.54	1480.59
561.94	1449.67
566.337	1424.07
570.734	1436.17
575.127	1416.86
579.518	1408.74
583.909	1398.28
588.295	1396.91
592.68	1384.51
597.064	1318.42
601.445	1302.11
605.823	1290.11
610.201	1263.06
614.575	1249.08
618.947	1239.28
623.317	1220.59
627.686	1205.37
632.052	1228.93
636.415	1211.76
640.777	1182.59
645.138	1156.54
649.495	1147.15
653.85	1074.39
658.205	1086.23
662.556	1117.98
666.905	1093.61
671.252	1158.51
675.597	1126.79
679.941	1251.46
684.282	1440.05
688.62	1619.34
692.957	1493.29
697.293	1252.51
701.625	1098.68
705.955	1034.69
710.283	1012.95
714.609	990.866
718.933	966.731
723.257	973.256
727.577	949.418
731.894	916.901
736.21	951.043
740.524	943.862
744.835	923.868
749.147	877.156
753.454	917.474
757.759	938.169
762.063	911.758
766.364	935.007
770.663	951.081
774.96	1002.11
779.257	1074.93
783.55	1286.02
787.841	1615.59
792.13	1842.38
796.417	2207.13
800.702	2303.32
804.985	1701.77
809.266	1260.69
813.545	1045.24
817.821	963.026
822.096	917.034
826.371	899.899
830.641	861.906
834.91	877.895
839.176	885.013
843.441	884.321
847.703	832.578
851.964	850.895
856.222	885.729
860.479	910.595
864.733	1121.34
868.986	1219.15
873.236	1117.66
877.485	934.984
881.731	834.825
885.975	806.806
890.218	780.653
894.458	703.176
898.696	718.262
902.933	696.109
907.167	725.087
911.399	706.388
915.63	697.979
919.858	677.545
924.084	673.162
928.308	649.973
932.531	622.376
936.749	624.832
940.967	591.745
945.184	598.251
949.398	570.53
953.61	562.247
957.821	555.112
962.029	542.753
966.236	543.228
970.44	531.031
974.642	511.552
978.843	529.24
983.041	496.187
987.236	486.449
991.43	521.176
995.623	514.993
999.813	523.987
1004	495.984
1008.19	509.412
1012.37	513.34
1016.55	505.412
1020.73	498.524
1024.91	502.203
1029.09	488.59
1033.27	498.345
1037.44	511.848
1041.61	518.568
1045.78	545.483
1049.94	595.49
1054.11	720.446
1058.27	884.828
1062.43	927.865
1066.59	961.943
1070.75	1262.07
1074.9	1421.12
1079.05	1076.92
1083.2	733.597
1087.35	581.044
1091.5	525.551
1095.65	508.623
1099.79	479.682
1103.93	486.757
1108.07	491.924
1112.21	462.677
1116.34	450.868
1120.48	438.689
1124.61	447.387
1128.74	478.743
1132.86	492.976
1136.99	533.79
1141.11	640.4
1145.23	845.262
1149.35	1173.19
1153.47	1368.17
1157.59	1137.66
1161.7	761.21
1165.82	553.696
1169.92	485.416
1174.03	429.406
1178.14	455.804
1182.24	434.795
1186.35	416.803
1190.45	406.817
1194.55	419.269
1198.64	416.206
1202.74	411.003
1206.83	402.741
1210.92	450.248
1215.01	453.073
1219.1	506.296
1223.18	515.105
1227.27	504.917
1231.35	495.967
1235.43	461.392
1239.5	467.178
1243.58	462.85
1247.65	462.676
1251.72	501.708
1255.8	509.915
1259.86	566.193
1263.93	573.622
1267.99	586.179
1272.06	556.769
1276.12	463.075
1280.18	464.584
1284.23	430.837
1288.29	429.144
1292.34	408.274
1296.39	417.531
1300.44	387.459
1304.49	386.526
1308.53	367.412
1312.58	394.634
1316.62	384.422
1320.66	389.233
1324.7	374.793
1328.73	381.406
1332.77	377.948
1336.8	396.418
1340.83	386.738
1344.86	402.019
1348.88	424.209
1352.91	450.309
1356.93	498.188
1360.95	561.727
1364.97	698.37
1368.99	953.315
1373.01	1260.06
1377.02	1166.96
1381.03	847.671
1385.04	601.085
1389.05	491.66
1393.06	441.445
1397.06	394.353
1401.06	384.648
1405.06	358.158
1409.06	347.459
1413.06	337.769
1417.05	328.078
1421.05	337.129
1425.04	322.445
1429.03	351.055
1433.01	333.251
1437	314.475
1440.99	316.428
1444.97	338.085
1448.95	331.083
1452.93	318.12
1456.9	318.933
1460.88	316.738
1464.85	311.494
1468.82	317.045
1472.79	303.968
1476.76	316.394
1480.73	309.147
1484.69	307.769
1488.65	305.395
1492.61	307.925
1496.57	314.359
1500.53	305.228
1504.48	303.951
1508.43	320.253
1512.39	320.052
1516.33	315.983
1520.28	326.508
1524.23	334.137
1528.17	336.938
1532.11	342.687
1536.05	329.061
1539.99	344.522
1543.93	359.013
1547.86	367.688
1551.8	363.768
1555.73	386.928
1559.66	384.841
1563.58	399.162
1567.51	413.427
1571.44	420.877
1575.36	420.581
1579.28	455.011
1583.2	468.161
1587.11	451.389
1591.03	483.725
1594.94	530.423
1598.85	518.422
1602.76	546.806
1606.67	579.068
1610.58	585.423
1614.48	595.64
1618.38	625.089
1622.29	625.761
1626.18	643.743
1630.08	630.227
1633.98	651.359
1637.87	650.476
1641.76	658.351
1645.65	625.186
1649.54	631.355
1653.43	606.863
1657.31	581.333
1661.2	582.64
1665.08	539.638
1668.96	513.841
1672.83	509.038
1676.71	461.891
1680.58	449.139
1684.46	425.711
1688.33	418.59
1692.2	381.708
1696.06	361.12
1699.93	350.083
1703.79	338.052
1707.66	330.751
1711.52	312.961
1715.37	305.668
1719.23	295.581
1723.08	282.712
1726.94	281.177
1730.79	265.506
1734.64	264.924
1738.49	251.221
1742.33	245.017
1746.18	250.958
1750.02	243.072
1753.86	241.807
1757.7	237.893
1761.54	251.987
1765.37	247.409
1769.21	241.024
1773.04	226.387
1776.87	229.418
1780.7	225.07
1784.53	223.553
1788.35	214.576
1792.17	228.058
1796	222.828
1799.82	222.27
1803.64	221.578
1807.45	230.271
1811.27	223.875
1815.08	207.995
1818.89	208.054
1822.7	219.377
1826.51	209.901
1830.32	211.691
1834.12	218.134
1837.92	221.704
1841.72	212.067
1845.52	208.977
1849.32	208.729
1853.12	208.396
1856.91	207.068
1860.7	222.473
1864.5	221.027
1868.28	209.393
1872.07	214.511
1875.86	216.876
1879.64	223.867
1883.42	220.783
1887.21	224.169
1890.98	214.9
1894.76	217.629
1898.54	212.993
1902.31	222.247
1906.08	209.459
1909.85	223.396
1913.62	218.068
1917.39	215.52
1921.16	225.111
1924.92	225.507
1928.68	225.014
1932.44	231.979
1936.2	230.583
1939.96	227.306
1943.71	232.428
1947.47	229.143
1951.22	236.922
1954.97	238.048
1958.72	243.749
1962.46	236.212
1966.21	252.138
1969.95	235.132
1973.7	248.065
1977.43	242.186
1981.17	251.249
1984.91	254.638
1988.65	257.985
1992.38	257.557
1996.11	266.374
1999.84	245.415
2003.57	276.398
2007.3	268.428
2011.02	260.421
2014.75	272.688
2018.47	266.665
2022.19	273.645
2025.91	278.937
2029.62	270.531
2033.34	281.444
2037.05	273.267
2040.76	283.363
2044.47	271.471
2048.18	286.127
2051.89	276.118
2055.59	270.705
2059.3	261.74
2063	289.652
2066.7	292.898
2070.4	287.89
2074.1	287.483
2077.79	283.394
2081.49	269.122
2085.18	290.033
2088.87	284.682
2092.56	281.002
2096.25	268.161
2099.93	284.109
2103.61	273.916
2107.3	277.626
2110.98	289.659
2114.66	287.73
2118.33	267.183
2122.01	285.56
2125.68	272.291
2129.36	285.885
2133.03	283.679
2136.7	283.312
2140.36	281.975
2144.03	266.774
2147.7	272.762
2151.36	265.867
2155.02	265.422
2158.68	255.835
2162.34	253.619
2165.99	250.538
2169.65	250.243
2173.3	247.313
2176.95	241.721
2180.6	244.354
2184.25	249.71
2187.9	244.202
2191.54	243.343
2195.18	238.029
2198.83	237.323
2202.47	233.905
2206.11	228.692
2209.74	235.388
2213.38	229.32
2217.01	243.419
2220.64	236.446
2224.27	234.062
2227.9	223.368
2231.53	232.015
2235.16	212.989
2238.78	218.886
2242.4	230.357
2246.02	215.86
2249.64	220.853
2253.26	216.571
2256.88	218.827
2260.49	226.696
2264.11	229.885
2267.72	211.527
2271.33	226.044
2274.93	205.729
2278.54	218.287
2282.15	209.035
2285.75	203.522
2289.35	208.403
2292.95	204.749
2296.55	213.395
2300.15	216.381
2303.74	199.44
2307.34	209.926
2310.93	207.116
2314.52	205.222
2318.11	213.718
2321.7	223.109
2325.28	206.805
2328.87	205.625
2332.45	203.485
2336.03	199.434
2339.61	199.135
2343.19	192.235
2346.77	205.978
2350.34	198.111
2353.92	192.134
2357.49	201.097
2361.06	194.18
2364.63	197.509
2368.2	199.91
2371.76	187.53
2375.33	185.355
2378.89	199.798
2382.45	198.555
2386.01	189.055
2389.57	196.151
2393.13	178.491
2396.68	180.173
2400.23	191.995
2403.79	191.082
2407.34	185.62
2410.88	177.472
2414.43	189.556
2417.98	181.49
2421.52	187.237
2425.06	192.121
2428.61	180.455
2432.14	195.603
2435.68	183.05
2439.22	191.828
2442.75	190.418
2446.29	189.941
2449.82	180.138
2453.35	176.884
2456.88	187.618
2460.4	179.391
2463.93	189.968
2467.45	184.386
2470.98	183.63
2474.5	176.961
2478.02	175.888
2481.54	180.508
2485.05	171.875
2488.57	182.906
2492.08	172.382
2495.59	184.324
2499.1	172.853
2502.61	182.889
2506.12	171.374
2509.63	175.712
2513.13	171.666
2516.63	175.106
2520.13	169.292
2523.63	184.67
2527.13	174.292
2530.63	179.687
2534.12	184.173
2537.62	181.329
2541.11	176.68
2544.6	176.73
2548.09	169.474
2551.58	164.985
2555.06	177.182
2558.55	168.194
2562.03	173.094
2565.51	168.791
2568.99	171.979
2572.47	180.836
2575.95	172.906
2579.43	177.184
2582.9	170.185
2586.37	170.709
2589.84	182.579
2593.31	172.546
2596.78	172.91
2600.25	176.194
2603.71	175.657
2607.18	173.099
2610.64	175.192
2614.1	163.702
2617.56	168.61
2621.02	180.173
2624.47	171.525
2627.93	165.713
2631.38	178.122
2634.83	172.243
2638.28	181.658
2641.73	173.786
2645.18	167.808
2648.62	163.748
2652.07	173.007
2655.51	165.063
2658.95	171.355
2662.39	178.547
2665.83	175.293
2669.27	168.28
2672.7	172.573
2676.14	162.799
2679.57	170.882
2683	174.297
2686.43	163.761
2689.86	165.476
2693.29	181.237
2696.71	172.723
2700.13	174.498
2703.56	170.701
2706.98	179.916
2710.4	177.175
2713.82	169.817
2717.23	176.45
2720.65	178.47
2724.06	173.054
2727.47	184.451
2730.88	184.667
2734.29	174.575
2737.7	169.146
2741.11	181.523
2744.51	189.194
2747.91	194.028
2751.32	187.589
2754.72	191.477
2758.11	190.636
2761.51	181.326
2764.91	186.091
2768.3	186.118
2771.7	188.938
2775.09	193.628
2778.48	194.514
2781.87	188.78
2785.25	197.152
2788.64	202.687
2792.03	196.928
2795.41	199.623
2798.79	214.523
2802.17	210.602
2805.55	200.128
2808.93	200.905
2812.3	221.322
2815.68	220.187
2819.05	208.77
2822.42	225.405
2825.79	215.933
2829.16	228.861
2832.53	221.305
2835.89	225.907
2839.26	226.82
2842.62	230.572
2845.98	235.312
2849.34	237.341
2852.7	230.106
2856.06	248.049
2859.41	238.003
2862.77	250.435
2866.12	260.094
2869.47	253.827
2872.82	269.133
2876.17	265.656
2879.52	277.225
2882.87	276.559
2886.21	281.529
2889.55	272.337
2892.89	286.74
2896.23	295.419
2899.57	295.553
2902.91	286.18
2906.25	305.151
2909.58	309.907
2912.91	323.154
2916.25	329.758
2919.58	321.172
2922.91	329.595
2926.23	346.495
2929.56	352.932
2932.88	357.436
2936.21	369.423
2939.53	378.562
2942.85	372.613
2946.17	400.575
2949.49	389.941
2952.8	407.509
2956.12	415.664
2959.43	439.838
2962.74	443.387
2966.06	460.084
2969.37	450.644
2972.67	466.631
2975.98	491.061
2979.28	500.59
2982.59	510.055
2985.89	530.818
2989.19	542.235
2992.49	575.28
2995.79	552.002
2999.09	571.036
3002.38	598.546
3005.68	617.606
3008.97	636.735
3012.26	661.568
3015.55	663.832
3018.84	694.364
3022.13	711.711
3025.41	714.922
3028.7	767.251
3031.98	804.506
3035.26	817.183
3038.54	819.442
3041.82	875.638
3045.1	884.573
3048.38	916.258
3051.65	947.018
3054.92	959.829
3058.2	1002.96
3061.47	1051.5
3064.73	1102.11
3068	1123.2
3071.27	1161.2
3074.54	1179.01
3077.8	1229.43
3081.06	1281.21
3084.32	1352.23
3087.58	1368.18
3090.84	1432.98
3094.1	1455.37
3097.35	1510.86
3100.61	1535.1
3103.86	1625.52
3107.11	1669.26
3110.36	1763.29
3113.61	1812
3116.86	1867.56
3120.11	1880.35
3123.35	2012.2
3126.59	2080.24
3129.84	2107.27
3133.08	2184.85
3136.32	2259.54
3139.55	2350.33
3142.79	2427.75
3146.03	2528.07
3149.26	2615.24
3152.49	2722.53
3155.72	2788.7
3158.95	2816.82
3162.18	2909.73
3165.41	3064.71
3168.64	3090.61
3171.86	3183.07
3175.08	3347.92
3178.31	3374.09
3181.53	3474.6
3184.75	3574.23
3187.96	3623.81
3191.18	3707.56
3194.4	3831.28
3197.61	3922.47
3200.82	4063.02
3204.03	4131.31
3207.24	4200.65
3210.45	4306.3
3213.66	4363.69
3216.86	4449.92
3220.07	4517.12
3223.27	4604.42
3226.48	4640.84
3229.68	4740.13
3232.87	4750.44
3236.07	4861.17
3239.27	4862.67
3242.47	4921.57
3245.66	5061.77
3248.85	5090.55
3252.04	5139.92
3255.23	5204.76
3258.42	5199.93
3261.61	5264.06
3264.8	5315.06
3267.98	5351.94
3271.16	5415.02
3274.35	5407.05
3277.53	5489.83
3280.71	5566.67
3283.89	5618.48
3287.06	5721.94
3290.24	5702.67
3293.41	5802.14
3296.58	5823.16
3299.76	5931.72
3302.93	5980.89
3306.1	6030.29
3309.26	6109.52
3312.43	6071.71
3315.59	6222.53
3318.76	6253.42
3321.92	6337.09
3325.08	6483.18
3328.24	6509.83
3331.4	6661.37
3334.56	6731.89
3337.71	6838.76
3340.87	6913.95
3344.02	7020.24
3347.17	7097.98
3350.33	7253.95
3353.47	7268.32
3356.62	7464.55
3359.77	7533.88
3362.92	7600.42
3366.06	7703.93
3369.2	7899.42
3372.34	7912.26
3375.49	8086.56
3378.62	8165.98
3381.76	8266.74
3384.9	8329.3
3388.04	8401.21
3391.17	8499.78
3394.3	8582.29
3397.43	8683.77
3400.56	8703.34
3403.69	8844.21
3406.82	8943.48
3409.95	8985.46
3413.07	8966.53
3416.2	8889.08
3419.32	9136.97
3422.44	9058.16
3425.56	9169.22
3428.68	9291.08
3431.8	9291.41
3434.91	9268.92
3438.03	9273.6
3441.14	9214.59
3444.25	9256.71
3447.36	9133.64
3450.47	9231.73
3453.58	9108.15
3456.69	9130.28
3459.79	8988.29
3462.9	9016.54
3466	8808.69
3469.11	8880.02
3472.21	8723.56
3475.31	8655.55
3478.4	8549.32
3481.5	8402.04
3484.6	8282.58
3487.69	8112.85
3490.79	8062.4
3493.88	7957.77
3496.97	7744.46
3500.06	7608.91
3503.15	7506.83
3506.23	7343.09
3509.32	7199.48
3512.4	7059.29
3515.49	6895.67
3518.57	6696.69
3521.65	6604.65
3524.73	6457.58
3527.81	6321.99
3530.89	6140.58
3533.96	6011.76
3537.03	5839.27
3540.11	5665.15
3543.18	5565.77
3546.25	5466.67
3549.32	5284.01
3552.39	5146.09
3555.46	5021.61
3558.52	4874.23
3561.59	4702.19
3564.65	4628.39
3567.71	4484.6
3570.77	4374.48
3573.83	4263.99
3576.89	4117.64
3579.95	4005.06
3583	3854.22
3586.06	3818.71
3589.11	3681.74
3592.16	3617.33
3595.21	3502.64
3598.27	3394.31
3601.31	3282.3
3604.36	3186.11
3607.41	3084.08
3610.45	2971.73
3613.5	2874.48
3616.54	2788.55
3619.58	2688.69
3622.62	2579.65
3625.66	2522.65
3628.69	2387.66
3631.73	2359.12
3634.77	2214.63
3637.8	2137.67
3640.83	2061.04
3643.86	1934.78
3646.89	1832.61
3649.92	1735.49
3652.95	1670.84
3655.98	1598.97
3659	1476.39
3662.02	1411.82
3665.05	1296.03
3668.07	1226.57
3671.09	1136.64
3674.11	1063.65
3677.13	1019.9
3680.14	945.939
3683.16	875.611
3686.17	842.09
3689.19	782.06
3692.2	725.763
3695.21	698.783
3698.22	664.028
3701.23	617.056
3704.23	599.446
3707.24	570.411
3710.24	554.575
3713.25	500.646
3716.25	488.455
3719.25	471.539
3722.25	445.981
3725.25	444.176
3728.25	413.761
3731.24	430.928
3734.24	372.822
3737.23	385.143
3740.22	362.205
3743.21	375.395
3746.21	349.547
3749.19	349.356
3752.18	334.886
3755.17	324.226
3758.15	311.692
3761.14	323.82
3764.12	304.633
3767.1	311.992
3770.08	306.117
3773.06	303.115
3776.04	284.069
3779.02	288.679
3781.99	294.25
3784.97	273.381
3787.94	278.973
3790.91	267.588
3793.88	258.138
3796.85	280.802
3799.82	256.286
3802.79	268.621
3805.76	263.033
3808.72	252.724
3811.69	266.998
3814.65	241.578
3817.61	251.142
3820.57	261.672
3823.53	249.494
3826.49	250.585
3829.45	260.213
3832.4	255.62
3835.36	242.505
3838.31	239.833
3841.26	238.108
3844.21	258.256
3847.16	243.218
3850.11	249.126
3853.06	228.361
3856	245.737
3858.95	245.954
3861.89	243.307
3864.84	253.079
3867.78	241.8
3870.72	255.399
3873.66	244.076
3876.6	243.284
3879.53	253.985
3882.47	235.851
3885.4	259.957
3888.34	258.103
3891.27	256.237
3894.2	254.359
3897.13	249.563
3900.06	256.276
3902.99	252.406
3905.91	247.539
3908.84	241.747
3911.76	258.997
3914.69	255.078
3917.61	258.822
3920.53	233.811
3923.45	248.12
3926.37	247.037
3929.28	254.562
3932.2	245.77
3935.11	260.035
3938.03	259.022
3940.94	243.7
3943.85	239.843
3946.76	260.892
3949.67	250.371
3952.58	251.359
3955.49	243.737
3958.39	257.21
3961.3	240.997
3964.2	263.128
3967.1	244.056
3970	248.005
3972.9	238.528
3975.8	243.442
3978.7	246.423
3981.6	244.583
3984.49	244.661
3987.39	230.301
3990.28	239.014
3993.17	235.189
3996.06	248.731
3998.95	247.837
4001.84	250.808
4004.73	248.967
4007.61	244.248
4010.5	253.988
4013.38	232.874
4016.27	235.862
4019.15	239.818
4022.03	237.983
4024.91	240.01
4027.79	233.348
4030.66	239.248
4033.54	237.423
4036.42	234.631
4039.29	231.847
4042.16	245.521
4045.03	238.817
4047.9	228.242
4050.77	234.155
4053.64	228.444
4056.51	226.632
4059.38	220.927
4062.24	228.81
4065.1	227.952
4067.97	222.229
4070.83	234.011
4073.69	220.493
4076.55	226.436
4079.41	211.92
4082.26	218.836
4085.12	221.859
4087.97	214.142
4090.83	211.298
4093.68	208.465
4096.53	221.245
4099.38	220.363
4102.23	214.59
4105.08	200.98
4107.93	224.512
4110.77	212.83
4113.62	216.78
4116.46	211.899
4119.3	206.009
4122.14	203.057
4124.98	219.7
4127.82	193.29
4130.66	231.533
4133.5	209.117
4136.33	208.299
4139.17	205.286
4142	210.89
4144.83	190.302
4147.67	204.065
4150.5	203.168
4153.33	200.27
4156.15	207.092
4158.98	190.335
4161.81	202.998
4164.63	179.497
4167.45	201.969
4170.28	196.083
4173.1	191.187
4175.92	201.944
4178.74	196.076
4181.56	199.025
4184.37	191.223
4187.19	186.365
4190	185.423
4192.82	195.276
4195.63	190.469
4198.44	186.665
4201.25	191.675
4204.06	181.001
4206.87	191.904
4209.68	188.09
4212.48	188.197
4215.29	190.268
4218.1	180.634
4220.9	194.631
4223.7	180.029
4226.5	192.035
4229.3	184.325
4232.1	194.418
4234.9	177.81
4237.69	185.97
4240.49	174.293
4243.28	178.501
4246.07	166.798
4248.87	180.979
4251.66	173.216
4254.45	167.427
4257.24	170.616
4260.03	168.799
4262.81	180.023
4265.6	161.157
4268.38	182.471
4271.17	180.684
4273.95	168.809
4276.73	172.008
4279.51	174.176
4282.29	175.325
4285.07	169.379
4287.84	172.509
4290.62	182.709
4293.39	177.719
4296.17	172.747
4298.94	167.784
4301.71	172.945
4304.48	171.004
4307.25	167.03
4310.02	169.155
4312.79	168.248
4315.55	179.521
4318.32	178.575
4321.08	169.473
4323.85	170.533
4326.61	167.511
4329.37	169.585
4332.13	161.457
4334.89	162.503
4337.65	163.535
4340.4	161.537
4343.16	161.582
4345.91	152.463
4348.67	165.797
4351.42	165.876
4354.17	169.062
4356.92	159.972
4359.67	164.165
4362.42	148.908
4365.17	162.321
4367.91	163.442
4370.66	158.427
4373.4	167.742
4376.14	153.453
4378.89	150.434
4381.63	161.789
4384.37	156.72
4387.11	157.85
4389.84	156.985
4392.58	161.299
4395.32	155.42
4398.05	162.865
4400.78	170.309
4403.52	149.771
4406.25	157.209
4408.98	164.672
4411.71	149.253
4414.44	152.519
4417.16	157.868
4419.89	158.991
4422.62	166.399
4425.34	153.993
4428.06	161.422
4430.78	165.725
4433.51	166.892
4436.22	160.723
4438.94	154.538
4441.66	155.668
4444.38	153.656
4447.1	163.175
4449.81	161.155
4452.52	165.421
4455.24	152.876
4457.95	152.92
4460.66	152.957
4463.37	154.065
4466.08	162.535
4468.78	148.919
4471.49	155.304
4474.2	153.281
4476.9	144.945
4479.6	164.036
4482.31	159.94
4485.01	152.669
4487.71	149.604
4490.41	150.761
4493.11	147.65
4495.8	151.917
4498.5	155.159
4501.19	160.516
4503.89	154.202
4506.58	142.599
4509.27	146.901
4511.96	140.597
4514.66	154.46
4517.34	152.409
4520.03	149.3
4522.72	146.203
4525.41	152.679
4528.09	148.513
4530.77	160.326
4533.46	154.036
4536.14	152.01
4538.82	148.918
4541.5	139.422
4544.18	153.431
4546.86	138.577
4549.53	152.615
4552.21	155.972
4554.88	151.852
4557.56	142.37
4560.23	149.049
4562.9	151.463
4565.57	152.852
4568.24	149.965
4570.91	157.828
4573.58	162.275
4576.24	150.358
4578.91	150.457
4581.58	158.229
4584.24	144.286
4586.9	146.568
4589.56	145.575
4592.22	142.382
4594.88	142.467
4597.54	138.204
4600.2	140.477
4602.86	134.028
4605.51	152.766
4608.17	145.232
4610.82	146.464
4613.47	147.693
4616.13	143.427
4618.78	140.26
4621.43	147.006
4624.07	143.84
4626.72	150.586
4629.37	146.294
4632.01	150.831
4634.66	143.189
4637.3	147.697
4639.94	143.353
4642.59	143.434
4645.23	141.331
4647.87	148.14
4650.5	146.112
4653.14	147.469
4655.78	146.561
4658.42	138.777
4661.05	140.018
4663.68	151.341
4666.31	145.899
4668.95	139.29
4671.58	129.326
4674.21	147.357
4676.84	153.078
4679.46	145.338
4682.09	149.937
4684.72	147.798
4687.34	150.156
4689.97	142.389
4692.59	145.878
4695.21	143.722
4697.83	132.537
4700.45	147.302
4703.07	138.363
4705.69	138.44
4708.3	150.952
4710.92	147.633
4713.54	140.913
4716.15	136.446
4718.76	139.896
4721.37	143.347
4723.99	149.056
4726.59	142.318
4729.2	148.062
4731.81	154.949
4734.42	135.722
4737.03	151.696
4739.63	139.254
4742.23	139.308
4744.84	142.763
4747.44	143.935
4750.04	138.257
4752.64	137.134
4755.24	142.838
4757.84	147.403
4760.44	146.291
4763.03	140.635
4765.63	131.566
4768.22	138.473
4770.82	137.423
4773.41	143.186
4776	137.542
4778.59	145.598
4781.18	138.806
4783.77	143.44
4786.36	142.362
4788.94	138.995
4791.53	142.498
4794.11	139.14
4796.7	141.512
4799.28	140.462
4801.86	137.125
4804.44	144.129
4807.02	143.118
4809.6	152.474
4812.18	138.807
4814.76	129.733
4817.33	129.883
4819.91	138.137
4822.48	133.679
4825.06	139.641
4827.63	136.334
4830.2	135.343
4832.77	135.528
4835.34	145.037
4837.91	139.425
4840.48	132.639
4843.04	139.874
4845.61	136.556
4848.17	140.255
4850.74	138.05
4853.3	136.924
4855.86	139.332
4858.42	127.762
4860.98	136.199
4863.54	151.704
4866.1	129.376
4868.66	141.307
4871.21	139.093
4873.77	132.102
4876.32	140.497
4878.88	135.852
4881.43	139.503
4883.98	150.277
4886.53	134.912
4889.08	130.237
4891.63	126.747
4894.18	142.3
4896.72	137.611
4899.27	141.257
4901.81	123.437
4904.36	140.2
4906.9	147.424
4909.44	133.151
4911.98	136.759
4914.52	137.967
4917.06	136.772
4919.6	135.591
4922.14	136.8
4924.67	139.205
4927.21	130.864
4929.74	135.653
4932.28	135.695
4934.81	136.96
4937.34	132.23
4939.87	135.872
4942.4	140.656
4944.93	127.524
4947.46	135.97
4949.99	142.023
4952.51	137.3
4955.04	136.156
4957.56	123.031
4960.08	131.521
4962.61	131.62
4965.13	131.756
4967.65	127.099
4970.17	134.457
4972.69	122.508
4975.2	131.071
4977.72	133.6
4980.24	127.669
4982.75	132.631
4985.27	136.393
4987.78	125.603
4990.29	129.372
4992.8	124.632
4995.31	130.833
4997.82	122.446