File: Data/3-Raman/raw/bu19w-d-ffore2-fi11-v_1800 (450-850nm)_532nm_edge_100%_x100_vis_lwd_h50um_30sx2_01.txt
#Acq. time (s)=	30
#Accumulations=	2
#Range (cm-¹)=	1200...2365
#Windows=	3
#Auto scanning=	Off
#Autofocus=	Off
#Macrospot=	Off
#AutoExposure=	Off
#Spike filter=	Multiple accum.
#Delay time (s)=	2
#Binning=	1
#Readout mode=	Signal
#DeNoise=	Off
#ICS correction=	On
#Dark correction=	Off
#Inst. Process=	Off
#Detector Gain=	Best Dynamic
#Detector ADC=	50 kHz HS
#Detector temperature (°C)=	-60.09
#Instrument=	LabRAM HR Evol
#Detector=	SIN-EM FIVIS
#Objective=	x100_VIS_LWD
#Grating=	1800 (450-850nm)
#ND Filter=	100%
#Laser=	532nm_Edge
#Hole=	49.98
#Temperature=	0
#Range=	Visible
#StageXY=	75x50mm Scan+
#StageZ=	Z motor
#X (µm)=	0
#Y (µm)=	0
#Z (µm)=	37.7
#Full time(mm:ss)=	3:18
#Project=	21_11_22
#Sample=	BU19w
#Site=
#Title=	BU19w-D-FFore2-FI11-V_1800 (450-850nm)_532nm_Edge_100%_x100_VIS_LWD_H50um_30sX2
#Remark=
#Date=	22.11.2021 14:18
#Acquired=	22.11.2021 14:18:37
1202.84	29.525
1203.95	26.2532
1205.06	25.153
1206.17	25.1264
1207.29	27.2515
1208.39	24.008
1209.51	27.1714
1210.62	25.0154
1211.72	27.1402
1212.84	27.1352
1213.94	27.0954
1215.05	24.9402
1216.16	28.1065
1217.27	28.0929
1218.38	29.1435
1219.49	26.9876
1220.6	29.05
1221.71	26.9039
1222.81	26.9034
1223.92	31.121
1225.03	28.9449
1226.14	27.8225
1227.24	32.1144
1228.35	34.1248
1229.46	34.1207
1230.56	34.1123
1231.67	35.1747
1232.78	30.985
1233.88	29.9272
1234.99	34.0882
1236.09	30.9004
1237.2	31.9365
1238.3	28.7939
1239.41	28.7819
1240.51	25.6459
1241.62	31.9344
1242.72	30.8582
1243.83	28.7449
1244.93	31.8774
1246.03	25.5823
1247.14	31.8564
1248.24	28.693
1249.34	29.7155
1250.45	28.6502
1251.55	30.7524
1252.65	29.713
1253.75	26.5847
1254.86	29.7107
1255.96	30.7382
1257.06	29.7136
1258.16	33.8524
1259.26	33.9166
1260.36	33.8281
1261.46	38.1279
1262.56	44.3582
1263.66	49.5807
1264.76	41.2589
1265.86	36.0762
1266.96	31.8872
1268.06	31.8561
1269.16	34.9967
1270.26	38.1809
1271.36	37.1682
1272.46	36.1229
1273.56	37.1991
1274.66	34.0765
1275.76	39.365
1276.85	37.2694
1277.95	37.2673
1279.05	41.5028
1280.15	46.7499
1281.24	68.7637
1282.34	161.598
1283.44	408.006
1284.53	188.877
1285.63	58.3262
1286.73	42.5636
1287.82	38.3625
1288.92	35.1974
1290.01	30.9818
1291.11	34.1799
1292.21	33.1328
1293.3	28.9745
1294.4	28.9708
1295.49	35.2885
1296.58	32.1035
1297.68	31.0556
1298.77	28.9464
1299.87	30.0101
1300.96	29.9976
1302.05	31.0497
1303.15	24.6926
1304.24	24.686
1305.33	24.687
1306.42	25.7479
1307.52	28.9171
1308.61	24.6986
1309.7	27.8772
1310.79	24.7009
1311.88	29.9799
1312.98	25.7694
1314.07	27.8766
1315.16	25.7712
1316.25	23.6587
1317.34	24.7143
1318.43	23.641
1319.52	26.7825
1320.61	28.88
1321.7	25.7175
1322.79	26.7544
1323.88	26.7072
1324.97	27.805
1326.06	22.5637
1327.15	27.8339
1328.23	24.6478
1329.32	26.7162
1330.41	27.7311
1331.5	24.5486
1332.59	27.6743
1333.67	23.462
1334.76	26.5957
1335.85	26.5739
1336.94	26.5712
1338.02	22.3833
1339.11	27.6084
1340.2	26.537
1341.28	28.6248
1342.37	27.5655
1343.45	24.3948
1344.54	29.5771
1345.63	22.2663
1346.71	30.5811
1347.8	26.3938
1348.88	24.2928
1349.96	29.5087
1351.05	25.3753
1352.13	28.4298
1353.22	29.4647
1354.3	29.4485
1355.39	32.5425
1356.47	26.2955
1357.55	30.4143
1358.63	29.3671
1359.72	27.2842
1360.8	27.2917
1361.88	31.4325
1362.97	30.3698
1364.05	29.3023
1365.13	31.3662
1366.21	31.3735
1367.29	26.1961
1368.37	33.4028
1369.45	37.4787
1370.54	28.1757
1371.62	33.3168
1372.7	33.3142
1373.78	37.4179
1374.86	43.577
1375.94	33.3376
1377.02	43.6256
1378.09	49.7023
1379.18	53.7617
1380.25	47.5276
1381.33	52.624
1382.41	66.0118
1383.49	70.1744
1384.57	78.1966
1385.65	157.111
1386.72	660.642
1387.8	364.355
1388.88	77.1711
1389.96	57.6575
1391.03	44.3305
1392.11	37.1629
1393.19	37.1742
1394.26	35.1085
1395.34	35.099
1396.42	33.0658
1397.49	34.0999
1398.57	28.9941
1399.64	31.0873
1400.72	29.0639
1401.79	28.0167
1402.87	31.0735
1403.94	31.063
1405.02	34.1468
1406.09	36.2069
1407.17	43.3959
1408.24	67.9471
1409.31	54.6118
1410.39	36.2688
1411.46	32.1172
1412.53	25.9727
1413.61	23.9258
1414.68	25.991
1415.75	25.995
1416.82	23.9332
1417.9	24.9399
1418.97	23.9127
1420.04	23.9605
1421.11	25.9356
1422.18	29.0069
1423.26	25.9403
1424.33	23.8645
1425.4	25.8883
1426.47	26.9187
1427.54	23.866
1428.61	24.922
1429.68	27.9853
1430.75	21.7975
1431.82	22.8281
1432.89	19.7532
1433.96	22.8194
1435.02	22.8124
1436.09	22.8193
1437.16	26.9356
1438.23	22.8405
1439.3	27.964
1440.37	24.886
1441.43	22.8291
1442.5	24.8986
1443.57	20.787
1444.64	26.9302
1445.7	23.8605
1446.77	21.8054
1447.84	24.8688
1448.9	25.8838
1449.97	21.7832
1451.04	22.8108
1452.1	19.7342
1453.17	23.8376
1454.23	21.7781
1455.3	24.8466
1456.36	22.8009
1457.43	22.7969
1458.49	22.786
1459.56	24.8162
1460.62	21.7259
1461.69	21.7484
1462.75	22.7056
1463.81	20.6567
1464.88	22.6921
1465.94	23.7081
1467	22.6728
1468.07	24.6976
1469.13	21.6286
1470.19	21.6241
1471.25	24.6656
1472.32	19.5797
1473.38	25.6768
1474.44	17.5273
1475.5	23.6199
1476.56	21.5716
1477.62	23.5774
1478.68	19.5092
1479.75	22.5678
1480.81	18.5096
1481.87	22.5252
1482.93	18.4631
1483.99	23.531
1485.05	23.5185
1486.11	20.4626
1487.17	26.526
1488.22	20.4442
1489.28	24.4854
1490.34	20.4378
1491.4	20.436
1492.46	23.4588
1493.52	22.4252
1494.58	20.3994
1495.63	23.425
1496.69	20.401
1497.75	21.4114
1498.81	21.402
1499.86	21.3932
1500.92	24.406
1501.98	22.391
1503.03	24.385
1504.09	17.3328
1505.15	18.3397
1506.2	21.3619
1507.26	23.3801
1508.31	21.3444
1509.37	23.312
1510.42	21.2772
1511.48	24.3034
1512.53	25.2853
1513.59	24.2583
1514.64	20.2429
1515.7	20.2496
1516.75	21.2576
1517.8	21.2539
1518.86	22.2604
1519.91	20.2441
1520.96	24.2277
1522.02	22.2131
1523.07	21.2196
1524.12	21.2302
1525.17	22.2233
1526.23	22.214
1527.28	22.2066
1528.33	24.2243
1529.38	22.2159
1530.43	24.2444
1531.48	23.2444
1532.53	20.225
1533.59	21.1973
1534.64	19.1727
1535.69	18.1605
1536.74	23.1917
1537.79	20.221
1538.84	23.214
1539.89	24.1913
1540.94	22.1625
1541.98	21.1745
1543.03	28.2054
1544.08	20.196
1545.13	26.1926
1546.18	23.175
1547.23	22.1792
1548.28	21.2402
1549.33	23.2477
1550.37	24.2333
1551.42	23.212
1552.47	27.1971
1553.52	23.1873
1554.56	22.1881
1555.61	19.1663
1556.65	22.143
1557.7	22.1307
1558.75	23.1332
1559.79	22.1447
1560.84	23.1391
1561.88	24.1577
1562.93	22.0193
1563.98	23.1109
1565.02	24.1278
1566.07	25.1326
1567.11	23.1201
1568.15	22.1191
1569.2	26.1035
1570.24	22.0933
1571.29	21.0916
1572.33	22.1102
1573.37	25.1102
1574.42	24.0816
1575.46	25.0495
1576.5	26.0436
1577.55	22.0614
1578.59	24.044
1579.63	23.0331
1580.67	25.0196
1581.72	23.0276
1582.76	21.0333
1583.8	25.9926
1584.84	22.002
1585.88	23.9991
1586.92	27.9897
1587.96	24.013
1589	26.9941
1590.04	22.9887
1591.08	25.9344
1592.12	21.9638
1593.16	23.9416
1594.2	21.9565
1595.24	23.9434
1596.28	29.8761
1597.32	27.8711
1598.36	21.895
1599.4	25.831
1600.44	28.7742
1601.48	27.778
1602.51	28.7684
1603.55	24.8234
1604.59	28.7853
1605.63	26.803
1606.66	29.7434
1607.7	27.7138
1608.74	28.6014
1609.77	27.7433
1610.81	26.5253
1611.85	24.5968
1612.88	25.7376
1613.92	28.6209
1614.95	23.3952
1615.99	29.7776
1617.03	26.1696
1618.06	27.3511
1619.1	26.9211
1620.13	25.881
1621.17	28.7448
1622.2	28.4586
1623.23	28.0612
1624.27	28.8588
1625.3	29.9073
1626.34	23.899
1627.37	27.4848
1628.4	28.5412
1629.44	29.509
1630.47	26.0387
1631.29	32.6232
1632.33	26.7086
1633.38	28.6683
1634.42	30.62
1635.47	30.6097
1636.51	26.6701
1637.56	29.6232
1638.6	26.6751
1639.65	24.6988
1640.69	28.6319
1641.73	27.6339
1642.78	30.5935
1643.82	27.6306
1644.86	27.6197
1645.91	28.6156
1646.95	27.6418
1647.99	28.6485
1649.03	26.6863
1650.08	26.6802
1651.12	27.6689
1652.16	31.6199
1653.2	29.6802
1654.24	25.7372
1655.28	26.7144
1656.33	25.7127
1657.37	27.6745
1658.41	28.6789
1659.45	29.6619
1660.49	29.7151
1661.53	28.6955
1662.57	27.6834
1663.61	24.7846
1664.65	27.6959
1665.69	26.7004
1666.72	28.7043
1667.76	27.7329
1668.8	27.7301
1669.84	25.7569
1670.88	26.7491
1671.92	24.7835
1672.96	24.7927
1674	25.7843
1675.03	27.7535
1676.07	26.7441
1677.11	23.7677
1678.15	24.7463
1679.18	22.7682
1680.22	20.7906
1681.25	23.75
1682.29	21.7675
1683.33	24.7297
1684.36	25.726
1685.4	21.7647
1686.43	23.7234
1687.47	25.6827
1688.51	23.7192
1689.54	23.721
1690.58	23.6992
1691.61	19.7371
1692.64	23.6771
1693.68	19.7426
1694.71	22.6841
1695.75	22.6657
1696.78	25.6138
1697.81	23.6397
1698.85	17.7291
1699.88	18.6982
1700.91	22.6225
1701.95	20.6608
1702.98	22.622
1704.01	21.6197
1705.04	20.6154
1706.08	20.5879
1707.11	21.5579
1708.14	22.5427
1709.17	21.5674
1710.2	22.5161
1711.23	20.5338
1712.27	17.5976
1713.3	21.509
1714.33	21.4855
1715.36	21.4475
1716.39	20.4606
1717.42	18.5129
1718.45	20.4432
1719.48	16.535
1720.51	18.4625
1721.54	19.428
1722.56	19.4031
1723.59	17.4529
1724.62	17.4423
1725.65	19.3644
1726.68	18.3513
1727.71	15.4516
1728.74	20.3003
1729.76	21.259
1730.79	21.2339
1731.82	21.2052
1732.85	16.3679
1733.87	18.2839
1734.9	19.2348
1735.93	17.2963
1736.95	19.1903
1737.98	22.0397
1739.01	22.0215
1740.03	22.9705
1741.06	20.0893
1742.08	22.9513
1743.11	19.1205
1744.13	21.0113
1745.16	20.0387
1746.18	21.9499
1747.21	18.1435
1748.23	18.1534
1749.26	18.1383
1750.28	18.1217
1751.31	19.0611
1752.33	20.9552
1753.35	21.8902
1754.38	19.0104
1755.4	17.1099
1756.42	18.0628
1757.44	19.0104
1758.47	18.9982
1759.49	19.9421
1760.51	17.093
1761.53	19.0038
1762.56	19.0153
1763.58	19.0151
1764.6	18.0576
1765.62	15.1947
1766.64	16.1177
1767.66	19.9223
1768.68	18.0356
1769.7	19.9469
1770.72	20.9073
1771.74	20.9123
1772.76	18.0718
1773.78	19.0286
1774.8	20.9217
1775.82	18.0489
1776.84	19.9407
1777.86	18.0455
1778.88	19.9538
1779.9	18.0609
1780.92	18.069
1781.94	19.0352
1782.95	19.0318
1783.97	19.9901
1784.99	19.0651
1786.01	17.1825
1787.03	15.2814
1788.04	17.2006
1789.06	19.0979
1790.08	18.1442
1791.09	20.064
1792.11	21.0299
1793.13	19.1406
1794.14	16.2721
1795.16	21.0876
1796.17	15.3189
1797.19	18.1907
1798.21	18.1831
1799.22	16.263
1800.24	20.1175
1801.25	20.1265
1802.27	19.1789
1803.28	18.2312
1804.29	19.2009
1805.31	22.0925
1806.32	20.1668
1807.34	17.2766
1808.35	18.2379
1809.36	17.274
1810.38	20.1768
1811.39	21.1566
1812.4	15.3769
1813.41	20.2123
1814.43	20.2074
1815.44	20.1994
1816.45	19.2403
1817.46	17.3143
1818.47	18.2892
1819.49	21.2011
1820.5	19.2664
1821.51	20.2321
1822.52	16.3656
1823.53	20.2401
1824.54	21.2126
1825.55	16.3703
1826.56	20.2376
1827.57	21.198
1828.58	18.2965
1829.59	17.3364
1830.6	22.1883
1831.61	17.3375
1832.62	15.3722
1833.63	18.3577
1834.64	18.2858
1835.65	18.2514
1836.65	20.2368
1837.66	18.2715
1838.67	18.2354
1839.68	20.1404
1840.69	19.1779
1841.7	17.2481
1842.7	18.2123
1843.71	17.2747
1844.72	17.2087
1845.72	19.1403
1846.73	17.2011
1847.74	21.0229
1848.74	18.1252
1849.75	15.2415
1850.75	22.9168
1851.76	20.0141
1852.76	18.0783
1853.77	19.031
1854.78	18.0669
1855.78	18.0527
1856.79	20.9044
1857.79	19.9542
1858.79	18.0519
1859.8	22.8251
1860.8	17.0697
1861.81	18.0116
1862.81	19.8979
1863.81	18.9119
1864.82	19.8348
1865.82	15.0759
1866.82	19.8262
1867.83	17.9208
1868.83	19.8156
1869.83	16.9542
1870.83	15.9968
1871.84	17.8792
1872.84	18.8036
1873.84	17.8313
1874.84	18.7339
1875.84	19.7257
1876.84	15.0075
1877.84	17.8454
1878.84	18.7671
1879.84	17.7808
1880.84	17.7875
1881.84	19.6468
1882.85	18.7258
1883.85	20.6221
1884.84	18.713
1885.84	14.9199
1886.84	19.6145
1887.84	19.6246
1888.84	16.796
1889.84	16.7894
1890.84	17.7007
1891.84	20.5108
1892.83	15.8158
1893.83	21.4665
1894.83	18.6519
1895.83	19.5833
1896.83	17.6888
1897.82	19.5634
1898.82	20.5166
1899.82	19.5866
1900.81	16.7573
1901.81	18.6339
1902.81	17.6896
1903.8	17.6732
1904.8	16.7323
1905.79	13.9206
1906.79	18.6322
1907.79	19.5967
1908.78	16.7784
1909.78	16.7746
1910.77	16.7783
1911.77	18.681
1912.76	19.6339
1913.76	18.6823
1914.75	15.8423
1915.74	18.6779
1916.74	16.8137
1917.73	20.5961
1918.72	19.6669
1919.72	16.8306
1920.71	17.7673
1921.7	17.757
1922.7	20.5999
1923.69	18.7297
1924.68	19.69
1925.67	18.7498
1926.66	16.8659
1927.66	17.8327
1928.65	23.5309
1929.64	17.8241
1930.63	18.7696
1931.62	19.7673
1932.61	15.048
1933.61	18.8492
1934.6	18.8331
1935.59	19.776
1936.58	23.5999
1937.57	21.7074
1938.56	17.9146
1939.55	16.9537
1940.54	18.8682
1941.52	19.8275
1942.51	17.9343
1943.5	19.8595
1944.49	18.9022
1945.48	18.8989
1946.47	19.8633
1947.46	18.929
1948.44	17.0393
1949.43	16.0942
1950.42	18.0214
1951.41	16.0679
1952.39	13.1784
1953.38	17.9959
1954.37	18.9732
1955.36	21.867
1956.34	19.9397
1957.33	20.8902
1958.31	18.9555
1959.3	21.8323
1960.29	20.8752
1961.27	17.0393
1962.26	19.9187
1963.24	18.9647
1964.23	18.0147
1965.21	18.0162
1966.2	18.9705
1967.18	12.2285
1968.17	17.976
1969.15	18.9322
1970.14	17.9714
1971.12	16.9997
1972.1	18.9156
1973.09	18.9246
1974.07	20.8453
1975.05	21.7946
1976.04	18.9094
1977.02	18.9105
1978	17.9423
1978.98	19.8503
1979.97	18.8833
1980.95	17.9109
1981.93	17.9033
1982.91	16.938
1983.89	18.857
1984.88	18.8459
1985.86	17.8534
1986.84	18.7692
1987.82	20.6819
1988.8	16.9104
1989.78	18.7855
1990.76	17.7965
1991.74	19.7844
1992.72	19.0034
1993.7	20.3557
1994.68	20.7097
1995.66	17.2489
1996.64	20.422
1997.62	18.3242
1998.6	18.4344
1999.57	18.7148
2000.55	18.6935
2001.53	20.5707
2002.51	19.0521
2003.49	19.9017
2004.47	18.7169
2005.44	21.2867
2006.42	18.5956
2007.4	20.0535
2008.38	18.6728
2009.35	18.1862
2010.33	17.9947
2011.3	19.2175
2012.18	20.5068
2013.17	20.514
2014.16	17.715
2015.15	17.696
2016.14	16.7306
2017.13	20.4626
2018.11	20.4605
2019.1	16.7127
2020.09	16.6981
2021.08	18.5526
2022.06	17.5961
2023.05	17.5738
2024.04	20.406
2025.02	20.4219
2026.01	18.5918
2027	18.5286
2027.98	20.3647
2028.97	19.4418
2029.96	19.4667
2030.94	17.6152
2031.93	21.2999
2032.91	19.4734
2033.9	21.3423
2034.88	20.41
2035.87	19.4631
2036.85	17.5811
2037.83	17.5617
2038.82	19.4159
2039.8	21.2677
2040.79	14.7554
2041.77	21.2892
2042.75	20.3591
2043.74	20.3858
2044.72	20.3484
2045.7	20.3443
2046.69	21.2938
2047.67	16.6456
2048.65	16.6374
2049.63	22.2431
2050.62	19.4544
2051.6	17.5998
2052.58	18.5277
2053.56	18.5202
2054.54	20.3898
2055.52	17.5963
2056.5	22.2882
2057.48	19.4759
2058.46	22.2883
2059.45	21.3552
2060.43	19.4934
2061.4	19.501
2062.39	17.6393
2063.37	17.6542
2064.34	20.4778
2065.32	18.6087
2066.3	17.6702
2067.28	17.6548
2068.26	21.4415
2069.24	17.6993
2070.22	18.6364
2071.2	20.5205
2072.18	19.5955
2073.15	18.6813
2074.13	21.5082
2075.11	22.4351
2076.09	18.6721
2077.06	19.6365
2078.04	19.6405
2079.02	21.5261
2080	22.4758
2080.97	17.7483
2081.95	18.6935
2082.93	21.5292
2083.9	21.5486
2084.88	19.664
2085.85	20.6127
2086.83	19.6776
2087.8	21.5786
2088.78	15.9021
2089.75	19.7188
2090.73	21.6392
2091.7	20.6983
2092.68	20.6883
2093.65	16.8799
2094.63	21.6169
2095.6	19.7106
2096.57	23.5035
2097.55	19.7082
2098.52	20.6704
2099.5	20.671
2100.47	17.8113
2101.44	16.8613
2102.41	18.7709
2103.39	18.7824
2104.36	17.8354
2105.33	19.7202
2106.3	17.8095
2107.27	17.8175
2108.25	20.6666
2109.22	18.7591
2110.19	15.9142
2111.16	16.8722
2112.13	17.821
2113.1	20.6655
2114.07	17.8048
2115.04	19.6985
2116.01	18.7306
2116.99	19.6624
2117.96	21.5564
2118.92	18.7272
2119.9	19.6886
2120.86	17.7929
2121.83	17.7761
2122.8	22.4821
2123.77	17.7291
2124.74	20.5545
2125.71	20.549
2126.68	17.7094
2127.65	16.7597
2128.61	21.4724
2129.58	21.46
2130.55	17.6787
2131.52	20.5117
2132.48	18.621
2133.45	18.6042
2134.42	19.545
2135.39	19.5441
2136.35	22.3827
2137.32	17.6449
2138.28	18.5789
2139.25	19.5101
2140.22	21.4153
2141.18	16.6586
2142.15	20.4252
2143.12	19.483
2144.08	20.4154
2145.05	19.465
2146.01	19.4542
2146.98	20.3702
2147.94	17.545
2148.9	18.4909
2149.87	22.24
2150.83	19.4158
2151.8	17.5201
2152.76	16.5588
2153.72	19.3503
2154.69	17.4843
2155.65	18.4252
2156.61	18.4169
2157.58	19.3327
2158.54	21.1891
2159.5	19.3195
2160.47	20.2448
2161.43	20.2333
2162.39	20.2262
2163.35	19.2924
2164.31	18.3487
2165.27	16.4617
2166.24	20.1798
2167.2	17.4104
2168.16	18.3423
2169.12	19.2426
2170.08	16.444
2171.04	17.3751
2172	18.3064
2172.96	19.2316
2173.92	18.2951
2174.88	17.3658
2175.84	17.356
2176.8	16.4274
2177.76	19.2103
2178.72	19.2044
2179.68	18.2682
2180.64	20.1071
2181.59	18.2416
2182.55	18.246
2183.51	18.257
2184.47	17.3492
2185.43	20.1346
2186.38	15.4768
2187.34	18.2446
2188.3	21.956
2189.26	20.1075
2190.21	17.3333
2191.17	21.0716
2192.13	19.2196
2193.08	18.2758
2194.04	18.2547
2195	19.1762
2195.95	17.3358
2196.91	18.2873
2197.86	17.3899
2198.82	19.2365
2199.78	15.4929
2200.73	19.2286
2201.69	20.2064
2202.64	19.2163
2203.59	15.4987
2204.55	16.4278
2205.5	19.2334
2206.46	14.586
2207.41	17.3817
2208.37	18.324
2209.32	19.27
2210.27	17.4008
2211.23	18.331
2212.18	16.4819
2213.13	16.4837
2214.09	20.2154
2215.04	14.6145
2215.99	17.4195
2216.94	19.2985
2217.9	17.429
2218.85	16.4804
2219.8	18.3422
2220.75	16.486
2221.7	14.6337
2222.65	16.5197
2223.6	17.4697
2224.55	20.2944
2225.5	19.3543
2226.46	19.3503
2227.41	16.5514
2228.36	18.443
2229.31	19.3979
2230.26	18.4715
2231.21	17.5414
2232.16	14.7108
2233.11	18.4637
2234.05	16.5858
2235	19.4312
2235.95	16.6258
2236.9	16.6291
2237.85	18.5104
2238.8	18.5215
2239.75	19.4722
2240.69	20.4099
2241.64	17.5793
2242.59	19.4921
2243.54	19.507
2244.48	16.6773
2245.43	17.6219
2246.38	19.51
2247.32	14.781
2248.27	18.5508
2249.22	16.6581
2250.16	17.6244
2251.11	15.748
2252.06	16.6998
2253	17.6497
2253.95	20.5084
2254.89	18.6213
2255.84	13.8767
2256.78	16.7337
2257.73	15.7895
2258.67	17.7035
2259.62	18.6615
2260.56	18.6799
2261.51	19.6613
2262.45	18.724
2263.39	18.7196
2264.34	17.7487
2265.28	14.8752
2266.22	17.741
2267.17	14.8967
2268.11	15.8649
2269.05	16.8312
2270	17.7914
2270.94	17.7949
2271.88	16.841
2272.82	18.7581
2273.77	16.8573
2274.71	17.8353
2275.65	16.8934
2276.59	17.8487
2277.53	17.8259
2278.47	17.8154
2279.41	15.9015
2280.36	15.9161
2281.3	17.8666
2282.24	16.9191
2283.18	15.9486
2284.12	18.8464
2285.06	15.9734
2286	16.927
2286.94	19.7868
2287.88	14.9752
2288.82	19.801
2289.75	21.7423
2290.69	16.9376
2291.63	19.8229
2292.57	17.8843
2293.51	19.7919
2294.45	16.9111
2295.39	17.8924
2296.32	17.9066
2297.26	18.8757
2298.2	16.9526
2299.14	16.9552
2300.07	15.9869
2301.01	17.9175
2301.95	15.0303
2302.89	19.8676
2303.82	16.9738
2304.76	16.0025
2305.69	17.9302
2306.63	18.9075
2307.57	16.9848
2308.5	13.1023
2309.44	17.9092
2310.37	17.905
2311.31	17.9277
2312.24	18.9162
2313.18	15.9974
2314.11	17.912
2315.05	18.8877
2315.98	20.8028
2316.92	15.9674
2317.85	17.8989
2318.78	18.8772
2319.72	17.9282
2320.65	17.9301
2321.58	16.9629
2322.52	20.806
2323.45	18.8583
2324.38	20.7695
2325.32	22.6887
2326.25	25.5704
2327.18	52.5343
2328.11	66.0015
2329.05	29.4254
2329.98	24.588
2330.91	18.8011
2331.84	18.7869
2332.77	18.7834
2333.7	19.7419
2334.63	20.6992
2335.56	16.8488
2336.5	19.7323
2337.43	17.802
2338.36	16.8236
2339.29	16.8058
2340.22	15.8408
2341.15	17.7562
2342.08	15.8386
2343.01	16.7845
2343.93	17.7353
2344.86	14.8595
2345.79	18.6934
2346.72	18.6717
2347.65	18.6121
2348.58	15.8135
2349.51	18.6296
2350.44	17.6393
2351.36	20.4904
2352.29	17.6395
2353.22	16.678
2354.15	15.7032
2355.07	18.5441
2356	16.6341
2356.93	16.6263
2357.86	16.6104
2358.78	15.6455
2359.71	18.4691
2360.63	19.4026
2361.56	19.3917
2362.49	14.6526
2363.41	16.5143
2364.34	14.6422
2364.8	16.537