File: Data/3-Raman/raw/bu19w-ff07b-fi06-s1_150 (500nm)_532nm_edge_100%_x100_vis_lwd_h50um_15sx2_01.txt
#Acq. time (s)=	15
#Accumulations=	2
#Range (cm-¹)=	50...5000
#Windows=	1
#Auto scanning=	Off
#Autofocus=	Off
#Macrospot=	Off
#AutoExposure=	Off
#Spike filter=	Multiple accum.
#Delay time (s)=	2
#Binning=	1
#Readout mode=	Signal
#DeNoise=	Off
#ICS correction=	On
#Dark correction=	Off
#Inst. Process=	Off
#Detector Gain=	Best Dynamic
#Detector ADC=	50 kHz HS
#Detector temperature (°C)=	-60.09
#Instrument=	LabRAM HR Evol
#Detector=	SIN-EM FIVIS
#Objective=	x100_VIS_LWD
#Grating=	150 (500nm)
#ND Filter=	100%
#Laser=	532nm_Edge
#Hole=	49.98
#Temperature=	0
#Range=	Visible
#StageXY=	75x50mm Scan+
#StageZ=	Z motor
#X (µm)=	0
#Y (µm)=	0
#Z (µm)=	-25.6
#Full time(s)=	41
#Project=	21_05_28
#Sample=	BU19w
#Site=
#Title=	BU19w-FF07b-FI06-S1_150 (500nm)_532nm_Edge_100%_x100_VIS_LWD_H50um_15sX2
#Remark=
#Date=	28.05.2021 16:34
#Acquired=	28.05.2021 16:34:12
51.5961	3250.63
56.2453	2351.23
60.8921	3305.85
65.5367	8348.48
70.1768	7531.21
74.8167	2788.55
79.4543	1329.74
84.0897	1038.7
88.7227	965.101
93.3513	956.449
97.9798	938.843
102.606	1008.31
107.23	1120.75
111.851	1279.83
116.469	1195.41
121.086	1107.35
125.7	1333.78
130.313	2269.76
134.921	2060.67
139.529	1373.44
144.134	1271.03
148.738	1102.5
153.337	1281.68
157.936	1795.52
162.532	3372.32
167.126	4725.85
171.716	3318.6
176.306	2064.72
180.894	1911.49
185.477	2553.57
190.06	5281.33
194.64	8311.36
199.219	5504.11
203.793	2537.63
208.367	1726.48
212.939	1578.37
217.506	1645.55
222.073	1717.62
226.638	1621.96
231.199	1528.44
235.759	1752.5
240.318	2204.43
244.872	2349.13
249.425	3314.99
253.977	4068.16
258.524	3351.36
263.071	2961.7
267.616	3673.11
272.156	4770.4
276.697	4648.88
281.233	7112.04
285.769	11977.3
290.303	14880.7
294.832	10410
299.361	5841.53
303.886	5419.98
308.411	5891.06
312.934	4805.49
317.452	3280.48
321.97	2458.52
326.484	2337.61
330.998	2966.8
335.507	3813.78
340.017	3327.13
344.524	2357.57
349.027	2293.52
353.53	2985.58
358.028	3298.67
362.527	2652.26
367.021	1981.72
371.515	1864.42
376.004	2090.21
380.494	2087.1
384.979	1916.84
389.465	2134.38
393.946	2458.65
398.427	2704.2
402.903	2679.88
407.38	2223.63
411.852	1811.24
416.324	1968.68
420.792	2995.09
425.26	2756.52
429.723	1692.42
434.187	1191.07
438.646	1085.56
443.105	1041.61
447.56	1091.19
452.015	1221.06
456.466	1734.94
460.914	2749.1
465.362	2876.19
469.807	2522.17
474.251	2910.59
478.69	3024.7
483.13	2849.24
487.566	2762.71
491.999	2714.68
496.432	2614.11
500.861	2450.96
505.29	2291.99
509.715	1961.77
514.138	1609.76
518.56	1352.71
522.979	1207.15
527.395	1110.4
531.811	1149.14
536.223	1136.07
540.635	1238.87
545.042	1266.39
549.448	1220.94
553.853	1220.52
558.255	1241.43
562.654	1234.99
567.053	1252.94
571.448	1259.18
575.841	1188.11
580.232	1241.7
584.622	1517.61
589.009	2614.42
593.393	4962.19
597.777	5485.08
602.157	3422.66
606.535	2217.28
610.913	2283.44
615.287	3235.59
619.659	4620.25
624.029	4265.35
628.398	2763.46
632.763	2621.74
637.127	4468.38
641.488	4883.22
645.849	3095.7
650.206	1980.47
654.561	1477.52
658.914	1302.45
663.267	1449.6
667.615	1700.98
671.962	1990.28
676.307	1984.21
680.649	2115.17
684.991	2201.17
689.33	1831.02
693.666	1322.15
698	1026.77
702.332	853.653
706.662	807.055
710.992	738.736
715.318	732.738
719.641	708.066
723.963	712.292
728.283	722.375
732.6	722.66
736.918	743.969
741.231	762.737
745.542	759.129
749.852	813.902
754.159	846.108
758.464	870.433
762.767	1003.42
767.068	1189.7
771.369	1478.32
775.666	2046.58
779.961	3044.58
784.254	4128.56
788.545	4425.56
792.834	3795.12
797.12	3033
801.405	2286.71
805.688	1710.55
809.968	1376.15
814.247	1154.14
818.524	1020.24
822.798	902.768
827.071	847.104
831.341	820.094
835.612	788.655
839.878	808.952
844.142	786.142
848.405	779.578
852.665	756.012
856.923	787.588
861.18	863.175
865.434	936.302
869.686	999.089
873.936	943.989
878.185	871.254
882.431	837.967
886.675	872.176
890.915	857.767
895.155	808.361
899.393	775.793
903.63	775.322
907.864	781.355
912.096	783.18
916.326	814.664
920.554	811.344
924.78	799.092
929.004	799.354
933.227	855.352
937.447	895.035
941.665	971.834
945.881	1092.09
950.095	1282.34
954.305	1492.59
958.516	1577.89
962.724	1536.69
966.93	1559.46
971.134	1727.73
975.337	1874.88
979.537	1844.06
983.735	1928.03
987.93	2186.54
992.124	2922.32
996.316	4434.15
1000.51	7215.19
1004.7	10203.5
1008.88	9425.04
1013.06	5832.41
1017.25	3526.5
1021.43	2626.15
1025.61	2330.73
1029.78	2573.36
1033.96	3375.05
1038.13	4852.64
1042.3	5704.69
1046.47	6417.69
1050.63	9114.71
1054.8	10392.3
1058.96	8343.61
1063.12	5845.89
1067.28	3897.84
1071.44	2735.77
1075.59	2174.27
1079.74	2074.58
1083.89	2275.95
1088.04	2902.38
1092.19	4217.3
1096.33	5667.78
1100.48	6552.7
1104.62	6117.88
1108.76	5044.91
1112.89	4657.24
1117.03	4645.59
1121.16	4140.16
1125.29	3594.29
1129.42	3414.09
1133.55	3590.59
1137.68	3769.77
1141.8	3638.03
1145.92	2948.79
1150.04	2391.42
1154.16	2235.67
1158.27	2636.05
1162.39	3329.19
1166.5	3496.02
1170.61	3002.63
1174.72	2532.44
1178.82	2401.42
1182.93	2217.03
1187.03	1909.01
1191.13	1647.01
1195.23	1449
1199.33	1331.06
1203.42	1255.13
1207.51	1194.75
1211.6	1126.64
1215.69	1072.09
1219.78	1029.01
1223.86	1165.17
1227.95	1448.34
1232.03	1440.66
1236.11	1285.17
1240.18	1305.52
1244.26	1594.18
1248.33	1790.33
1252.41	1462.23
1256.48	1134.25
1260.54	942.042
1264.61	832.733
1268.67	829.535
1272.74	766.316
1276.8	711.985
1280.86	742.897
1284.91	735.534
1288.97	710.922
1293.02	715.388
1297.07	706.654
1301.12	705.906
1305.17	716.109
1309.21	696.026
1313.25	677.874
1317.3	680.643
1321.34	681.25
1325.37	659.464
1329.41	649.698
1333.44	651.925
1337.48	652.926
1341.5	618.794
1345.53	663.607
1349.56	643.447
1353.59	616.41
1357.61	622.275
1361.63	635.006
1365.65	629.001
1369.66	637.938
1373.68	630.221
1377.69	612.762
1381.7	633.864
1385.72	617.81
1389.72	603.857
1393.73	615.668
1397.73	630.698
1401.74	604.316
1405.74	637.016
1409.73	610.661
1413.73	609.983
1417.73	625.101
1421.72	614.557
1425.71	621.697
1429.7	612.724
1433.69	603.808
1437.67	636.347
1441.66	621.502
1445.64	652.956
1449.62	617.253
1453.6	592.319
1457.57	606.784
1461.55	597.477
1465.52	618.502
1469.49	589.31
1473.46	593.651
1477.43	589.074
1481.39	623.621
1485.36	609.113
1489.32	595.577
1493.28	600.663
1497.24	592.105
1501.19	603.1
1505.15	607.37
1509.1	614.72
1513.05	593.936
1517	596.508
1520.95	623.4
1524.9	611.515
1528.84	639.44
1532.78	611.206
1536.72	607.229
1540.66	621.685
1544.6	602.225
1548.53	615.714
1552.46	626.294
1556.4	663.911
1560.32	606.527
1564.25	666.21
1568.18	684.175
1572.1	673.075
1576.02	699.641
1579.94	692.366
1583.86	686.047
1587.78	691.246
1591.69	670.43
1595.61	660.217
1599.52	667.319
1603.43	647.582
1607.34	666.353
1611.24	648.68
1615.15	643.533
1619.05	635.608
1622.95	636.269
1626.85	653.303
1630.74	631.176
1634.64	615.956
1638.53	633.247
1642.42	639.223
1646.31	647.254
1650.2	586.325
1654.09	630.886
1657.97	611.125
1661.86	623.978
1665.74	617.5
1669.62	589.801
1673.49	646.506
1677.37	623.382
1681.24	627.795
1685.12	621.484
1688.99	602.665
1692.86	618.24
1696.72	622.209
1700.59	643.253
1704.45	620.234
1708.31	622.858
1712.17	618.694
1716.03	636.349
1719.89	622.748
1723.74	635.645
1727.6	639.015
1731.45	620.653
1735.3	652.118
1739.14	626.301
1742.99	648.121
1746.83	624.254
1750.68	626.89
1754.52	632.53
1758.36	646.868
1762.19	640.009
1766.03	604.824
1769.86	629.297
1773.69	631.799
1777.53	608.264
1781.35	612.841
1785.18	655.807
1789	627.918
1792.83	620.572
1796.65	621.659
1800.47	631.18
1804.29	643.141
1808.1	618.342
1811.92	632.075
1815.73	636.281
1819.54	621.339
1823.35	645.861
1827.16	646.672
1830.97	655.791
1834.77	642.113
1838.58	634.94
1842.38	638.026
1846.18	660.674
1849.97	628.006
1853.77	631.657
1857.56	652.892
1861.36	659.84
1865.15	647.143
1868.93	639.212
1872.72	644.354
1876.51	617.244
1880.29	682.582
1884.07	659.515
1887.86	637.458
1891.63	659.426
1895.41	653.798
1899.19	650.932
1902.96	682.403
1906.73	645.896
1910.5	665.613
1914.27	624.746
1918.04	682.611
1921.8	642.14
1925.57	659.017
1929.33	643.592
1933.09	651.412
1936.85	640.609
1940.6	655.882
1944.36	630.036
1948.11	673.444
1951.87	646.074
1955.61	660.646
1959.36	658.919
1963.11	650.396
1966.86	644.657
1970.6	659.364
1974.34	664.429
1978.08	665.6
1981.82	663.847
1985.56	684.406
1989.29	668.441
1993.02	670.113
1996.75	660.488
2000.49	661.906
2004.21	657.796
2007.94	668.408
2011.67	652.082
2015.39	670.796
2019.11	668.649
2022.83	665.949
2026.55	676.486
2030.27	648.588
2033.98	661.301
2037.69	670.582
2041.41	688.045
2045.12	700.876
2048.82	678.015
2052.53	685.504
2056.24	682.045
2059.94	671.602
2063.64	690.019
2067.34	679.23
2071.04	658.323
2074.74	679.809
2078.43	695.876
2082.13	670.359
2085.82	689.211
2089.51	710.071
2093.2	709.261
2096.88	680.904
2100.57	670.991
2104.25	678.515
2107.94	723.122
2111.62	705.304
2115.3	713.501
2118.97	713.237
2122.65	715.472
2126.32	692.502
2129.99	717.654
2133.66	691.778
2137.33	702.89
2141	697.238
2144.67	728.351
2148.33	712.399
2151.99	712.098
2155.66	732.911
2159.31	728.971
2162.97	732.445
2166.63	730.549
2170.28	752.488
2173.94	730.066
2177.59	756.087
2181.24	745.784
2184.89	772.751
2188.53	751.708
2192.18	744.603
2195.82	768.75
2199.46	748.461
2203.1	773.819
2206.74	776.528
2210.38	739.151
2214.01	772.271
2217.65	769.769
2221.28	798.502
2224.91	763.901
2228.54	786.252
2232.16	765.327
2235.79	799.851
2239.41	770.592
2243.04	819.098
2246.66	789.723
2250.28	782.615
2253.89	805.38
2257.51	800.3
2261.12	778.352
2264.74	774.026
2268.35	758.508
2271.96	775.065
2275.57	784.877
2279.17	790.728
2282.78	790.4
2286.38	779.669
2289.98	802.936
2293.58	811.938
2297.18	802.048
2300.78	767.553
2304.37	800.155
2307.97	789.015
2311.56	803.351
2315.15	773.962
2318.74	805.1
2322.33	792.458
2325.91	801.113
2329.5	814.398
2333.08	801.109
2336.66	846.207
2340.24	826.099
2343.82	824.766
2347.4	796.119
2350.97	796.549
2354.54	844.612
2358.12	819.664
2361.69	818.968
2365.26	812.684
2368.82	826.884
2372.39	831.05
2375.95	806.481
2379.52	830.922
2383.08	826.828
2386.64	799.83
2390.19	798.767
2393.75	806.127
2397.31	807.296
2400.86	790.41
2404.41	787.714
2407.96	807.114
2411.51	809.447
2415.06	814.732
2418.6	773.354
2422.15	757.764
2425.69	823.408
2429.23	759.307
2432.77	776.517
2436.31	801.385
2439.84	804.145
2443.38	807.911
2446.91	788.374
2450.44	837.229
2453.97	776.675
2457.5	778.329
2461.03	779.307
2464.55	810.385
2468.08	816.298
2471.6	794.562
2475.12	794.132
2478.64	813.389
2482.16	812.017
2485.67	827.291
2489.19	807.224
2492.7	813.012
2496.21	809.884
2499.72	835.155
2503.23	825.468
2506.74	820.342
2510.25	824.371
2513.75	807.977
2517.25	828.989
2520.75	823.182
2524.25	801.089
2527.75	825.173
2531.25	803.232
2534.74	813.752
2538.24	806.046
2541.73	828.981
2545.22	809.864
2548.71	825.25
2552.2	817.591
2555.68	855.482
2559.17	801.212
2562.65	851.676
2566.13	817.126
2569.61	800.394
2573.09	797.807
2576.57	837.542
2580.04	830.654
2583.51	818.116
2586.99	817.79
2590.46	827.683
2593.93	836.242
2597.4	838.025
2600.86	832.423
2604.33	834.372
2607.79	820.497
2611.25	827.968
2614.71	856.961
2618.17	838.259
2621.63	830.721
2625.09	797.071
2628.54	846.79
2631.99	836.799
2635.45	849.64
2638.9	836.324
2642.34	836.287
2645.79	827.48
2649.24	816.73
2652.68	882.069
2656.12	863.232
2659.56	831.952
2663.01	855.644
2666.44	846.075
2669.88	872.347
2673.32	842.028
2676.75	861.711
2680.18	858.967
2683.61	839.604
2687.04	871.922
2690.47	842.27
2693.9	799.911
2697.32	855.201
2700.75	838.961
2704.17	856.252
2707.59	837.3
2711.01	853.353
2714.43	856.569
2717.84	868.341
2721.26	848.611
2724.67	849.479
2728.08	852.287
2731.49	856.084
2734.9	839.246
2738.31	825.183
2741.71	840.131
2745.12	861.514
2748.52	830.188
2751.92	862.768
2755.32	862.385
2758.72	843.076
2762.12	850.135
2765.52	877.702
2768.91	850.486
2772.3	847.625
2775.7	857.881
2779.09	857.623
2782.47	875.133
2785.86	841.744
2789.25	842.219
2792.63	873.68
2796.01	859.986
2799.4	851
2802.78	837.199
2806.15	844.987
2809.53	862.106
2812.91	850.14
2816.28	865.256
2819.65	853.241
2823.03	867.512
2826.4	852.034
2829.76	827.318
2833.13	856.783
2836.5	890.113
2839.86	881.669
2843.22	891.099
2846.59	856.013
2849.95	851.975
2853.3	863.998
2856.66	875.006
2860.02	848.742
2863.37	859.042
2866.72	897.52
2870.08	876.969
2873.43	856.315
2876.77	869.442
2880.12	864.688
2883.47	868.372
2886.81	849.356
2890.15	882.207
2893.5	870.655
2896.84	881.564
2900.17	871.549
2903.51	852.875
2906.85	893.698
2910.18	879.567
2913.52	889.028
2916.85	866.253
2920.18	883.087
2923.51	865.818
2926.83	916.546
2930.16	908.514
2933.48	900.384
2936.81	914.775
2940.13	947.057
2943.45	927.476
2946.77	900.423
2950.09	897.896
2953.4	915.079
2956.72	928.509
2960.03	898.891
2963.34	871.259
2966.65	880.287
2969.96	876.446
2973.27	900.9
2976.58	885.997
2979.88	854.343
2983.19	883.576
2986.49	887.53
2989.79	875.577
2993.09	883.37
2996.39	880.882
2999.68	864.337
3002.98	854.35
3006.27	869.759
3009.57	877.722
3012.86	894.215
3016.15	881.533
3019.43	853.729
3022.72	851.351
3026.01	871.626
3029.29	863.605
3032.57	868.785
3035.86	887.162
3039.14	869.592
3042.41	851.067
3045.69	859.994
3048.97	862.306
3052.24	855.144
3055.52	879.283
3058.79	868.315
3062.06	893.108
3065.33	853.521
3068.6	878.345
3071.86	846.99
3075.13	883.198
3078.39	874.755
3081.65	866.98
3084.91	886.503
3088.17	882.276
3091.43	893.485
3094.69	893.357
3097.95	879.734
3101.2	879.986
3104.45	886.728
3107.7	866.296
3110.95	885.697
3114.2	884.834
3117.45	880.239
3120.7	887.095
3123.94	895.859
3127.18	888.414
3130.43	873.315
3133.67	915.409
3136.91	875.513
3140.14	879.413
3143.38	877.58
3146.61	896.729
3149.85	872.075
3153.08	913.24
3156.31	906.684
3159.54	916.369
3162.77	907.897
3166	906.105
3169.22	881.324
3172.45	887.972
3175.67	914.619
3178.89	902.067
3182.11	931.479
3185.33	920.842
3188.55	908.196
3191.77	923.175
3194.98	935.284
3198.2	917.84
3201.41	940.384
3204.62	958.194
3207.83	965.557
3211.04	967.254
3214.25	964.258
3217.45	966.087
3220.66	986.942
3223.86	989.757
3227.06	986.963
3230.26	1016.54
3233.46	985.297
3236.66	1001.57
3239.85	1010.44
3243.05	1037.48
3246.24	1038.87
3249.44	1045.03
3252.63	1009.34
3255.82	1033.74
3259.01	1033.33
3262.19	1027.05
3265.38	1015.83
3268.56	1023.58
3271.75	1009.25
3274.93	977.67
3278.11	1003.39
3281.29	1008.83
3284.47	1027.45
3287.64	968.804
3290.82	975.922
3293.99	978.347
3297.17	977.874
3300.34	1022.17
3303.51	1008.6
3306.68	1044.26
3309.84	1033.18
3313.01	1021
3316.18	1053.4
3319.34	1079.09
3322.5	1105.64
3325.66	1151.1
3328.82	1205
3331.98	1232.36
3335.14	1316.46
3338.29	1437.37
3341.45	1547.85
3344.6	1777.06
3347.75	2037.61
3350.9	2456.92
3354.05	3012.8
3357.2	3734.88
3360.35	4824.86
3363.49	6108.06
3366.64	7580.54
3369.78	9391.87
3372.92	10964.1
3376.06	11253
3379.2	9794.55
3382.34	7365.52
3385.48	5336.44
3388.61	4133.38
3391.75	3470.39
3394.88	3084.92
3398.01	2835.71
3401.14	2699.68
3404.27	2586.41
3407.4	2600.46
3410.52	2721.19
3413.65	3064.86
3416.77	3828.59
3419.89	5628.71
3423.01	10221.5
3426.13	16290.9
3429.25	14455.5
3432.37	7942.17
3435.49	4096.56
3438.6	2669.27
3441.72	2012.2
3444.83	1720.76
3447.94	1541.7
3451.05	1421.86
3454.16	1396.25
3457.26	1334.45
3460.37	1316.32
3463.47	1279.17
3466.58	1293.31
3469.68	1286.36
3472.78	1319
3475.88	1382.29
3478.98	1449.34
3482.07	1522.02
3485.17	1698.58
3488.26	1883.52
3491.36	2102.53
3494.45	2483.31
3497.54	3022.33
3500.63	3742.85
3503.72	4747.76
3506.81	5799.2
3509.89	6202.47
3512.98	5583.94
3516.06	4518.62
3519.14	3520.39
3522.22	2794.01
3525.3	2334.02
3528.38	2010.51
3531.45	1741.35
3534.53	1555.67
3537.61	1453.29
3540.68	1346.37
3543.75	1233.41
3546.82	1199.52
3549.89	1162.67
3552.96	1120.76
3556.03	1079.65
3559.09	1041.52
3562.16	1035.54
3565.22	1024.61
3568.28	1004.98
3571.34	981.865
3574.4	990.501
3577.46	956.504
3580.52	945.185
3583.57	967.935
3586.63	929.893
3589.68	937.371
3592.73	920.078
3595.78	928.36
3598.83	942.236
3601.88	906.853
3604.93	896.014
3607.97	885.118
3611.02	874.225
3614.06	846.286
3617.1	868.404
3620.14	855.61
3623.18	853.247
3626.22	857.513
3629.26	834.498
3632.3	835.006
3635.33	843.001
3638.36	850.257
3641.4	847.275
3644.43	814.285
3647.46	813.495
3650.49	829.416
3653.51	795.581
3656.54	805.882
3659.57	802.917
3662.59	788.568
3665.61	808.91
3668.63	808.162
3671.65	801.945
3674.67	796.706
3677.69	776.404
3680.71	768.4
3683.72	786.807
3686.74	769.31
3689.75	782.096
3692.76	775.037
3695.77	764.185
3698.78	762.649
3701.79	770.764
3704.79	767.498
3707.8	762.319
3710.81	764.646
3713.81	754.553
3716.81	736.748
3719.81	746.58
3722.81	754.42
3725.81	737.444
3728.81	722.299
3731.8	745.194
3734.8	753.73
3737.79	754.563
3740.78	738.194
3743.77	732.212
3746.76	718.565
3749.75	736.229
3752.74	733.866
3755.73	712.509
3758.71	747.174
3761.7	736.262
3764.68	719.618
3767.66	717.218
3770.64	728.124
3773.62	727.736
3776.6	733.075
3779.58	697.822
3782.55	728.761
3785.53	739.861
3788.5	735.892
3791.47	731.028
3794.44	710.236
3797.41	720.651
3800.38	706.568
3803.35	720.901
3806.32	731.501
3809.28	701.504
3812.24	728.239
3815.21	687.88
3818.17	711.829
3821.13	726.366
3824.09	714.424
3827.04	711.047
3830	707.673
3832.96	717.571
3835.91	717.11
3838.86	703.388
3841.82	709.607
3844.77	710.122
3847.72	723.03
3850.67	715.028
3853.61	705.147
3856.56	721.032
3859.5	713.073
3862.45	706.062
3865.39	720.049
3868.33	705.327
3871.27	714.482
3874.21	675.677
3877.15	696.289
3880.09	706.285
3883.02	715.254
3885.96	705.885
3888.89	704.146
3891.82	698.532
3894.75	713.075
3897.68	694.831
3900.61	688.047
3903.54	700.476
3906.47	706.084
3909.39	707.93
3912.31	704.901
3915.24	685.474
3918.16	700.589
3921.08	679.331
3924	686.746
3926.92	688.32
3929.83	703.248
3932.75	687.466
3935.67	687.189
3938.58	693.758
3941.49	679.386
3944.4	699.419
3947.31	677.362
3950.22	671.651
3953.13	699.503
3956.04	689.083
3958.94	653.815
3961.85	672.22
3964.75	679.167
3967.65	681.363
3970.55	677.839
3973.45	648.415
3976.35	703.457
3979.25	660.505
3982.15	696.284
3985.04	677.276
3987.94	665.915
3990.83	671.84
3993.72	660.372
3996.61	667.304
3999.5	665.566
4002.39	671.563
4005.28	672.759
4008.16	672.063
4011.05	675.231
4013.93	658.14
4016.81	668.053
4019.7	673.149
4022.58	646.384
4025.46	666.928
4028.33	664.312
4031.21	664.598
4034.09	672.64
4036.96	639.089
4039.84	647.162
4042.71	668.783
4045.58	654.46
4048.45	655.668
4051.32	654.973
4054.19	633.941
4057.05	632.363
4059.92	654.065
4062.78	660.218
4065.65	679.989
4068.51	656.01
4071.37	662.161
4074.23	674.156
4077.09	644.266
4079.95	652.344
4082.81	625.334
4085.66	622.686
4088.52	643.418
4091.37	654.406
4094.22	651.779
4097.07	629.562
4099.92	645.474
4102.77	633.033
4105.62	636.209
4108.47	636.372
4111.31	639.482
4114.16	640.558
4117	652.337
4119.84	652.276
4122.69	650.267
4125.53	636.595
4128.36	637.617
4131.2	646.646
4134.04	640.106
4136.88	627.875
4139.71	650.119
4142.54	640.435
4145.38	615.925
4148.21	617.104
4151.04	607.564
4153.87	630.195
4156.69	641.826
4159.52	635.561
4162.35	626.598
4165.17	631.415
4168	619.594
4170.82	632.255
4173.64	626.369
4176.46	611.699
4179.28	632.235
4182.1	624.464
4184.91	632.362
4187.73	642.256
4190.54	639.45
4193.36	642.616
4196.17	656.626
4198.98	660.948
4201.79	672.112
4204.6	676.453
4207.41	722
4210.22	722.433
4213.02	704.166
4215.83	689.806
4218.63	664.022
4221.44	652.92
4224.24	638.775
4227.04	635.378
4229.84	655.809
4232.64	632.768
4235.43	625.606
4238.23	630.368
4241.02	642.109
4243.82	624.061
4246.61	619.946
4249.4	608.801
4252.19	628.52
4254.98	614.28
4257.77	617.962
4260.56	607.618
4263.35	615.334
4266.13	605.015
4268.92	593.708
4271.7	612.564
4274.48	602.217
4277.26	614.929
4280.04	617.477
4282.82	593.71
4285.6	598.16
4288.38	593.432
4291.15	610.902
4293.93	585.828
4296.7	612.488
4299.47	583.467
4302.25	585.802
4305.02	596.251
4307.79	591.478
4310.55	580.633
4313.32	568.815
4316.09	576.213
4318.85	579.494
4321.62	578.664
4324.38	598.147
4327.14	581.968
4329.9	590.248
4332.66	592.352
4335.42	591.437
4338.18	580.27
4340.94	575.329
4343.69	587.718
4346.45	580.801
4349.2	578.013
4351.95	578.288
4354.7	563.399
4357.45	589.313
4360.2	568.207
4362.95	560.346
4365.7	590.425
4368.44	581.548
4371.19	547.084
4373.93	555.568
4376.68	590.735
4379.42	579.672
4382.16	573.722
4384.9	562.668
4387.64	571.269
4390.37	583.201
4393.11	565.364
4395.85	551.015
4398.58	571.36
4401.31	546.172
4404.05	560.255
4406.78	550.533
4409.51	567.827
4412.24	540.365
4414.96	560.659
4417.69	565.334
4420.42	562.477
4423.14	564.947
4425.87	543.44
4428.59	546.981
4431.31	560.983
4434.03	536.277
4436.75	529.31
4439.47	551.643
4442.19	541.449
4444.91	550.138
4447.62	543.06
4450.34	559.072
4453.05	546.689
4455.76	538.492
4458.47	543.9
4461.19	560.851
4463.89	531.615
4466.6	549.685
4469.31	536.228
4472.02	542.79
4474.72	537.819
4477.43	542.379
4480.13	548.043
4482.83	540.023
4485.53	551.008
4488.23	538.702
4490.93	537.995
4493.63	558.321
4496.33	535.163
4499.02	547.042
4501.72	529.233
4504.41	498.65
4507.11	525.35
4509.8	537.238
4512.49	516.243
4515.18	516.475
4517.87	515.659
4520.56	512.74
4523.24	536.455
4525.93	534.662
4528.61	532.857
4531.3	520.414
4533.98	537.816
4536.66	525.39
4539.34	510.831
4542.02	511.24
4544.7	500.95
4547.38	523.836
4550.05	525.345
4552.73	515.117
4555.4	522.129
4558.08	480.881
4560.75	494.549
4563.42	510.507
4566.09	508.324
4568.76	496.52
4571.43	501.716
4574.1	503.106
4576.77	516.229
4579.43	504.629
4582.1	508.451
4584.76	492.771
4587.42	502.931
4590.08	503.259
4592.74	491.533
4595.4	518.039
4598.06	517.329
4600.72	488.141
4603.38	468.852
4606.03	488.987
4608.69	463.125
4611.34	494.276
4613.99	476.048
4616.64	496.252
4619.29	493.415
4621.94	471.88
4624.59	487.761
4627.24	474.948
4629.89	479.759
4632.53	482.348
4635.18	479.342
4637.82	474.086
4640.46	479.886
4643.1	466.872
4645.74	465.036
4648.38	473.306
4651.02	499.493
4653.66	481.423
4656.3	461.97
4658.93	462.056
4661.57	479.219
4664.2	456.287
4666.83	481.319
4669.46	486.141
4672.09	488.774
4674.72	454.418
4677.35	474.958
4679.98	434.912
4682.61	448.707
4685.23	456.903
4687.86	476.359
4690.48	469.962
4693.1	461.309
4695.73	472.893
4698.34	454.029
4700.96	444.181
4703.58	441.082
4706.2	462.802
4708.82	465.309
4711.43	449.7
4714.05	465.761
4716.66	453.508
4719.28	438.958
4721.89	436.846
4724.5	438.112
4727.11	443.976
4729.72	451.008
4732.33	434.212
4734.93	462.832
4737.54	446.008
4740.14	454.151
4742.75	425.893
4745.35	449.91
4747.95	440.908
4750.55	443.221
4753.15	455.789
4755.75	443.312
4758.35	422.863
4760.95	429.772
4763.54	448.102
4766.14	435.715
4768.73	422.278
4771.33	421.404
4773.92	418.16
4776.51	422.91
4779.1	433.378
4781.69	442.707
4784.28	433.76
4786.87	453.398
4789.45	434.159
4792.04	425.22
4794.63	436.903
4797.21	424.552
4799.79	446.631
4802.37	418.279
4804.95	431.262
4807.53	422.483
4810.11	424.075
4812.69	426.817
4815.27	419.211
4817.84	431.246
4820.42	416.754
4822.99	427.688
4825.57	420.115
4828.14	419.476
4830.71	416.52
4833.28	385.676
4835.85	414.179
4838.42	425.316
4840.98	390.946
4843.55	410.294
4846.12	429.629
4848.68	414.928
4851.24	393.015
4853.81	408.42
4856.37	390.986
4858.93	428.071
4861.49	394.476
4864.05	398.465
4866.61	399.958
4869.16	406.211
4871.72	395.993
4874.27	429.498
4876.83	388.309
4879.38	401.639
4881.93	404.276
4884.49	396.2
4887.04	386.921
4889.58	371.694
4892.13	389.774
4894.68	401.906
4897.23	408.08
4899.77	393.983
4902.32	379.863
4904.86	391.976
4907.4	399.306
4909.95	381.551
4912.49	388.781
4915.03	401.957
4917.57	372.091
4920.1	390.051
4922.64	355.442
4925.18	391.33
4927.71	389.012
4930.25	368.715
4932.78	368.835
4935.31	390.558
4937.84	361.995
4940.38	382.486
4942.9	386.052
4945.43	387.371
4947.96	365.991
4950.49	372.145
4953.01	398.722
4955.54	373.689
4958.06	361.904
4960.59	384.968
4963.11	391.273
4965.63	370.024
4968.15	384.94
4970.67	369.626
4973.19	363.922
4975.71	382.36
4978.22	385.103
4980.74	368.506
4983.25	372.476
4985.77	381.316
4988.28	363.482
4990.79	363.843
4993.3	367.837
4995.81	358.44
4998.32	366.145