File: Data/3-Raman/raw/bu19w-ff07b-fi09-v_150 (500nm)_532nm_edge_100%_x100_vis_lwd_h50um_15sx2_01.txt
#Acq. time (s)=	15
#Accumulations=	2
#Range (cm-¹)=	50...5000
#Windows=	1
#Auto scanning=	Off
#Autofocus=	Off
#Macrospot=	Off
#AutoExposure=	Off
#Spike filter=	Multiple accum.
#Delay time (s)=	2
#Binning=	1
#Readout mode=	Signal
#DeNoise=	Off
#ICS correction=	On
#Dark correction=	Off
#Inst. Process=	Off
#Detector Gain=	Best Dynamic
#Detector ADC=	50 kHz HS
#Detector temperature (°C)=	-60.09
#Instrument=	LabRAM HR Evol
#Detector=	SIN-EM FIVIS
#Objective=	x100_VIS_LWD
#Grating=	150 (500nm)
#ND Filter=	100%
#Laser=	532nm_Edge
#Hole=	49.98
#Temperature=	0
#Range=	Visible
#StageXY=	75x50mm Scan+
#StageZ=	Z motor
#X (µm)=	0
#Y (µm)=	0
#Z (µm)=	-17.5
#Full time(s)=	34
#Project=	21_05_28
#Sample=	BU19w
#Site=
#Title=	BU19w-FF07b-FI09-V_150 (500nm)_532nm_Edge_100%_x100_VIS_LWD_H50um_15sX2
#Remark=
#Date=	28.05.2021 16:51
#Acquired=	28.05.2021 16:51:51
51.5961	51894.2
56.2453	40468.9
60.8921	31579.6
65.5367	29437.6
70.1768	21910.3
74.8167	13983.2
79.4543	10143.1
84.0897	7925.64
88.7227	6532.75
93.3513	5232.05
97.9798	4306.2
102.606	3698.37
107.23	3248.86
111.851	2970.91
116.469	2552.89
121.086	2170.71
125.7	1948.41
130.313	1852.48
134.921	1693.29
139.529	1599.99
144.134	1459.19
148.738	1342.03
153.337	1258.37
157.936	1443.65
162.532	2459.56
167.126	3283.42
171.716	2225.66
176.306	1386.88
180.894	1327.95
185.477	1831.84
190.06	4724.75
194.64	7462.42
199.219	4458.21
203.793	2038.54
208.367	1266.57
212.939	998.638
217.506	1021.82
222.073	1014.43
226.638	945.789
231.199	982.088
235.759	1278.49
240.318	1676.98
244.872	1795.25
249.425	2746.95
253.977	3279
258.524	2488.73
263.071	1957.65
267.616	1561.18
272.156	1554.94
276.697	2523.58
281.233	5459.29
285.769	7787.55
290.303	5513.52
294.832	3028.14
299.361	2251.88
303.886	2681.08
308.411	3785.41
312.934	3381.19
317.452	2159.22
321.97	1657.05
326.484	1710.29
330.998	2339.48
335.507	3095.5
340.017	2562.9
344.524	1786
349.027	1749.58
353.53	2288.73
358.028	2480.43
362.527	1847.78
367.021	1350.87
371.515	1279.81
376.004	1388.48
380.494	1310.22
384.979	1151.31
389.465	1467.73
393.946	1801.08
398.427	2056.49
402.903	2005.28
407.38	1584.04
411.852	1202.54
416.324	1235.24
420.792	1651.46
425.26	1744.28
429.723	1195.59
434.187	844.381
438.646	739.166
443.105	757.589
447.56	799.193
452.015	938.239
456.466	1494.22
460.914	2445.54
465.362	2162.59
469.807	1323.1
474.251	976.066
478.69	879.008
483.13	929.901
487.566	1055.32
491.999	1234.26
496.432	1466.99
500.861	1653.08
505.29	1636.15
509.715	1474.94
514.138	1224.8
518.56	980.585
522.979	936.71
527.395	875.72
531.811	891.203
536.223	896.474
540.635	936.535
545.042	980.08
549.448	1001.69
553.853	983.728
558.255	1017.41
562.654	1009.19
567.053	1063.29
571.448	990.632
575.841	891.228
580.232	862.622
584.622	988.013
589.009	1469.51
593.393	2704.22
597.777	3113.18
602.157	2054.5
606.535	1468.94
610.913	1493.39
615.287	2031.12
619.659	2223.3
624.029	1680.26
628.398	1115.32
632.763	889.53
637.127	859.853
641.488	938.003
645.849	1066.2
650.206	1024.81
654.561	925.803
658.914	931.137
663.267	1080.24
667.615	1367.7
671.962	1553.9
676.307	1612.27
680.649	1748.88
684.991	1799.13
689.33	1472.74
693.666	1064.74
698	832.257
702.332	708.303
706.662	648.437
710.992	608.799
715.318	586.752
719.641	583.213
723.963	565.892
728.283	593.601
732.6	573.495
736.918	596.872
741.231	602.161
745.542	590.936
749.852	651.235
754.159	660.969
758.464	717.39
762.767	807.111
767.068	949.415
771.369	1147.08
775.666	1638.71
779.961	2474.79
784.254	3262.48
788.545	2916.69
792.834	2008.72
797.12	1396.16
801.405	1086.42
805.688	905.585
809.968	786.764
814.247	717.556
818.524	682.543
822.798	660.709
827.071	653.354
831.341	613.005
835.612	597.967
839.878	589.482
844.142	584.228
848.405	572.132
852.665	567.423
856.923	558.311
861.18	577.837
865.434	557.598
869.686	532.811
873.936	561.78
878.185	535.693
882.431	541.313
886.675	552.141
890.915	545.158
895.155	551.032
899.393	560.024
903.63	591.936
907.864	561.209
912.096	554.775
916.326	557.345
920.554	557.63
924.78	586.791
929.004	602.607
933.227	613.727
937.447	644.061
941.665	692.331
945.881	774.565
950.095	918.396
954.305	1116.38
958.516	1140.45
962.724	1093.38
966.93	1075.21
971.134	1159.07
975.337	1167.76
979.537	1007.06
983.735	874.257
987.93	787.069
992.124	740.236
996.316	695.003
1000.51	684.057
1004.7	684.902
1008.88	674.166
1013.06	695.335
1017.25	683.355
1021.43	707.594
1025.61	745.598
1029.78	788.721
1033.96	835.883
1038.13	919.509
1042.3	1080.19
1046.47	1302.05
1050.63	1813.81
1054.8	3025.95
1058.96	4168.37
1063.12	3617.23
1067.28	2534.94
1071.44	1832.06
1075.59	1526.33
1079.74	1488.09
1083.89	1738.23
1088.04	2303.39
1092.19	3337.65
1096.33	4229.11
1100.48	3967.52
1104.62	3149.78
1108.76	2876.17
1112.89	3230.13
1117.03	3609.39
1121.16	3309.58
1125.29	2932.06
1129.42	2828.47
1133.55	3094.98
1137.68	3208.74
1141.8	3105.91
1145.92	2472.33
1150.04	1965.8
1154.16	1882.91
1158.27	2242.88
1162.39	2819.31
1166.5	2849.96
1170.61	2369.19
1174.72	1885.03
1178.82	1551.68
1182.93	1233.29
1187.03	1008.72
1191.13	952.505
1195.23	916.691
1199.33	946.09
1203.42	956.753
1207.51	960.166
1211.6	910.934
1215.69	846.865
1219.78	881.938
1223.86	1019.46
1227.95	1248.81
1232.03	1276.53
1236.11	1166.2
1240.18	1197.6
1244.26	1518.29
1248.33	1649.58
1252.41	1403.33
1256.48	1348.01
1260.54	1177.93
1264.61	972.772
1268.67	886.606
1272.74	1232.42
1276.8	3890.08
1280.86	3697.41
1284.91	1354.93
1288.97	831.673
1293.02	747.608
1297.07	741.911
1301.12	731.099
1305.17	681.841
1309.21	699.049
1313.25	731.297
1317.3	671.574
1321.34	700.383
1325.37	683.609
1329.41	691.906
1333.44	693.078
1337.48	704.038
1341.5	658.813
1345.53	663.607
1349.56	711.231
1353.59	717.902
1357.61	707.695
1361.63	803.548
1365.65	814.089
1369.66	835.595
1373.68	881.914
1377.69	2173.51
1381.7	7051.31
1385.72	4183.88
1389.72	1207.22
1393.73	834.179
1397.73	822.714
1401.74	1072.21
1405.74	1073.52
1409.73	776.264
1413.73	665.212
1417.73	651.743
1421.72	644.174
1425.71	632.561
1429.7	588.037
1433.69	607.758
1437.67	575.131
1441.66	553.378
1445.64	554.248
1449.62	580.741
1453.6	562.728
1457.57	570.308
1461.55	565.953
1465.52	549.615
1469.49	550.973
1473.46	555.351
1477.43	548.854
1481.39	542.301
1485.36	523.006
1489.32	534.993
1493.28	555.772
1497.24	531.676
1501.19	516.456
1505.15	532.482
1509.1	557.378
1513.05	539.545
1517	553.796
1520.95	548.689
1524.9	524.225
1528.84	533.755
1532.78	545.287
1536.72	533.566
1540.66	549.001
1544.6	537.303
1548.53	531.423
1552.46	574.95
1556.4	553.501
1560.32	556.185
1564.25	552.03
1568.18	565.23
1572.1	537.784
1576.02	548.994
1579.94	548.585
1583.86	530.807
1587.78	534.211
1591.69	537.596
1595.61	571.739
1599.52	556.82
1603.43	532.371
1607.34	538.743
1611.24	545.121
1615.15	539.073
1619.05	548.434
1622.95	541.475
1626.85	542.265
1630.74	559.397
1634.64	533.637
1638.53	554.749
1642.42	528.137
1646.31	542.812
1650.2	545.095
1654.09	551.246
1657.97	565.038
1661.86	552.886
1665.74	550.224
1669.62	535.964
1673.49	520.569
1677.37	548.403
1681.24	573.998
1685.12	537.02
1688.99	513.488
1692.86	537.787
1696.72	536.123
1700.59	522.912
1704.45	538.235
1708.31	516.273
1712.17	542.722
1716.03	550.112
1719.89	536.689
1723.74	562.973
1727.6	542.009
1731.45	547.358
1735.3	539.603
1739.14	542.108
1742.99	565.998
1746.83	552.565
1750.68	543.243
1754.52	544.357
1758.36	567.111
1762.19	541.617
1766.03	556.549
1769.86	532.696
1773.69	540.679
1777.53	576.617
1781.35	562.508
1785.18	575.523
1789	557.786
1792.83	575.61
1796.65	542.837
1800.47	560.683
1804.29	547.164
1808.1	542.05
1811.92	549.118
1815.73	537.231
1819.54	565.669
1823.35	543.014
1827.16	559.883
1830.97	569.986
1834.77	562.968
1838.58	546.454
1842.38	538.35
1846.18	554.553
1849.97	546.398
1853.77	536.136
1857.56	565.964
1861.36	548.857
1865.15	562.47
1868.93	553.798
1872.72	590.619
1876.51	578.406
1880.29	559.819
1884.07	575.635
1887.86	547.247
1891.63	564.63
1895.41	559.018
1899.19	548.807
1902.96	561.844
1906.73	560.268
1910.5	558.746
1914.27	572.184
1918.04	582.919
1921.8	568.171
1925.57	574.729
1929.33	590.694
1933.09	576.088
1936.85	566.065
1940.6	571.854
1944.36	553.328
1948.11	564.718
1951.87	574.757
1955.61	580.824
1959.36	575.321
1963.11	565.868
1966.86	582.68
1970.6	574.89
1974.34	556.582
1978.08	577.54
1981.82	566.539
1985.56	563.876
1989.29	577.015
1993.02	571.389
1996.75	579.612
2000.49	573.775
2004.21	575.398
2007.94	568.632
2011.67	582.035
2015.39	599.992
2019.11	583.29
2022.83	577.033
2026.55	577.555
2030.27	576.268
2033.98	602.722
2037.69	579.951
2041.41	580.008
2045.12	563.539
2048.82	578.212
2052.53	570.109
2056.24	589.517
2059.94	578.082
2063.64	583.509
2067.34	597.373
2071.04	587.377
2074.74	598.583
2078.43	586.755
2082.13	575.851
2085.82	573.182
2089.51	603.259
2093.2	594.999
2096.88	595.384
2100.57	589.151
2104.25	593.875
2107.94	587.333
2111.62	587.211
2115.3	569.407
2118.97	574.771
2122.65	589.185
2126.32	607.157
2129.99	597.196
2133.66	614.965
2137.33	585.511
2141	602.182
2144.67	614.099
2148.33	601.101
2151.99	596.399
2155.66	605.488
2159.31	611.823
2162.97	614.559
2166.63	602.783
2170.28	614.843
2173.94	630.781
2177.59	629.541
2181.24	628.388
2184.89	645.4
2188.53	647.115
2192.18	622.701
2195.82	653.141
2199.46	640.952
2203.1	631.549
2206.74	627.705
2210.38	641.329
2214.01	612.049
2217.65	630.395
2221.28	635.955
2224.91	632.368
2228.54	643.464
2232.16	626.932
2235.79	649.215
2239.41	661.367
2243.04	643.875
2246.66	657.871
2250.28	653.342
2253.89	625.579
2257.51	646.306
2261.12	633.433
2264.74	630.74
2268.35	631.856
2271.96	653.8
2275.57	614.436
2279.17	642.673
2282.78	646.949
2286.38	626.663
2289.98	620.515
2293.58	621.839
2297.18	617.506
2300.78	632.13
2304.37	663.716
2307.97	630.738
2311.56	651.686
2315.15	644.1
2318.74	696.11
2322.33	1072.87
2325.91	1039.6
2329.5	748.225
2333.08	645.325
2336.66	629.351
2340.24	643.463
2343.82	644.304
2347.4	671.329
2350.97	655.127
2354.54	627.733
2358.12	628.393
2361.69	631.802
2365.26	640.761
2368.82	631.177
2372.39	645.858
2375.95	649.344
2379.52	652.835
2383.08	641.655
2386.64	639.772
2390.19	649.027
2393.75	664.814
2397.31	634.01
2400.86	650.198
2404.41	630.079
2407.96	653.116
2411.51	637.01
2415.06	647.654
2418.6	655.72
2422.15	663.906
2425.69	640.941
2429.23	618.062
2432.77	639.621
2436.31	647.504
2439.84	652.7
2443.38	629.1
2446.91	654.878
2450.44	621.019
2453.97	648.089
2457.5	651.351
2461.03	670.062
2464.55	632.185
2468.08	653.133
2471.6	661.427
2475.12	625.208
2478.64	668.158
2482.16	649.896
2485.67	663.434
2489.19	666.183
2492.7	664.594
2496.21	666.384
2499.72	656.227
2503.23	661.778
2506.74	657.861
2510.25	658.472
2513.75	634.009
2517.25	652.509
2520.75	670.14
2524.25	652.997
2527.75	651.355
2531.25	662.816
2534.74	672.511
2538.24	648.251
2541.73	657.372
2545.22	660.351
2548.71	664.541
2552.2	649.358
2555.68	668.563
2559.17	670.534
2562.65	646.531
2566.13	683.186
2569.61	655.885
2573.09	685.637
2576.57	664.128
2580.04	649.199
2583.51	684.2
2586.99	652.246
2590.46	676.85
2593.93	666.046
2597.4	669.372
2600.86	648.077
2604.33	652.467
2607.79	657.453
2611.25	683.973
2614.71	672.606
2618.17	674.931
2621.63	671.207
2625.09	675.036
2628.54	673.878
2631.99	657.245
2635.45	700.917
2638.9	665.704
2642.34	672.572
2645.79	705.103
2649.24	653.48
2652.68	695.267
2656.12	681.549
2659.56	681.033
2663.01	675.708
2666.44	670.341
2669.88	689.489
2673.32	677.478
2676.75	691.902
2680.18	701.685
2683.61	664.862
2687.04	688.114
2690.47	662.35
2693.9	691.828
2697.32	683.881
2700.75	681.685
2704.17	707.419
2707.59	669.933
2711.01	680.357
2714.43	693.723
2717.84	676.514
2721.26	667.798
2724.67	688.074
2728.08	720.591
2731.49	688.701
2734.9	725.038
2738.31	662.114
2741.71	681.58
2745.12	684.047
2748.52	661.989
2751.92	665.296
2755.32	672.312
2758.72	665.14
2762.12	680.579
2765.52	686.426
2768.91	663.897
2772.3	698.737
2775.7	702.417
2779.09	663.586
2782.47	697.188
2785.86	688.357
2789.25	675.751
2792.63	685.691
2796.01	665.538
2799.4	688.592
2802.78	673.043
2806.15	687.518
2809.53	701.954
2812.91	680.767
2816.28	656.772
2819.65	685.115
2823.03	682.716
2826.4	680.415
2829.76	687.489
2833.13	665.765
2836.5	696.347
2839.86	687.916
2843.22	684.278
2846.59	698.51
2849.95	680.368
2853.3	675.422
2856.66	675.992
2860.02	667.303
2863.37	688.638
2866.72	674.429
2870.08	694.913
2873.43	679.697
2876.77	696.4
2880.12	676.405
2883.47	693.096
2886.81	687.125
2890.15	683.958
2893.5	696.807
2896.84	696.27
2900.17	687.119
2903.51	687.314
2906.85	686.477
2910.18	695.043
2913.52	679.901
2916.85	692.151
2920.18	708.078
2923.51	702.206
2926.83	720.853
2930.16	694.969
2933.48	724.745
2936.81	701.532
2940.13	715.125
2943.45	707.03
2946.77	699.911
2950.09	706.935
2953.4	713.921
2956.72	716.225
2960.03	714.888
2963.34	707.048
2966.65	685.189
2969.96	703.876
2973.27	680.482
2976.58	704.014
2979.88	708.903
2983.19	717.466
2986.49	713.873
2989.79	699.992
2993.09	697.398
2996.39	722.088
2999.68	697.956
3002.98	686.019
3006.27	667.49
3009.57	670.645
3012.86	682.315
3016.15	702.494
3019.43	665.164
3022.72	685.326
3026.01	684.748
3029.29	683.235
3032.57	673.202
3035.86	683.923
3039.14	680.448
3042.41	679.813
3045.69	653.633
3048.97	678.574
3052.24	707.329
3055.52	663.136
3058.79	674.829
3062.06	694.85
3065.33	664.693
3068.6	673.351
3071.86	672.373
3075.13	668.917
3078.39	640.539
3081.65	675.476
3084.91	667.368
3088.17	662.063
3091.43	660.732
3094.69	678.457
3097.95	676.316
3101.2	658.444
3104.45	678.478
3107.7	658.879
3110.95	671.531
3114.2	673.502
3117.45	673.628
3120.7	703.296
3123.94	672.966
3127.18	674.051
3130.43	666.54
3133.67	668.568
3136.91	645.792
3140.14	678.268
3143.38	661.165
3146.61	666.945
3149.85	663.235
3153.08	668.12
3156.31	658.669
3159.54	656.867
3162.77	667.445
3166	685.662
3169.22	644.65
3172.45	663.712
3175.67	657.934
3178.89	675.954
3182.11	680.604
3185.33	690.036
3188.55	675.545
3191.77	655.326
3194.98	667.516
3198.2	670.161
3201.41	653.745
3204.62	665.928
3207.83	700.017
3211.04	671.321
3214.25	661.709
3217.45	670.22
3220.66	693.951
3223.86	679.655
3227.06	658.768
3230.26	662.628
3233.46	683.666
3236.66	661.842
3239.85	676.327
3243.05	673.719
3246.24	687.338
3249.44	669.522
3252.63	693.71
3255.82	698.861
3259.01	712.595
3262.19	666.077
3265.38	691.073
3268.56	694.964
3271.75	685.412
3274.93	688.238
3278.11	693.918
3281.29	701.36
3284.47	684.81
3287.64	695.955
3290.82	708.938
3293.99	716.247
3297.17	693.038
3300.34	704.141
3303.51	720.157
3306.68	720.751
3309.84	710.813
3313.01	715.032
3316.18	715.404
3319.34	689.195
3322.5	729.353
3325.66	735.356
3328.82	724.322
3331.98	752.087
3335.14	744.907
3338.29	725.528
3341.45	745.853
3344.6	734.114
3347.75	729.167
3350.9	726.284
3354.05	745.071
3357.2	721.527
3360.35	733.839
3363.49	740.585
3366.64	746.408
3369.78	740.955
3372.92	746.854
3376.06	778.333
3379.2	761.709
3382.34	775.343
3385.48	803.136
3388.61	841.432
3391.75	879.785
3394.88	898.25
3398.01	904.188
3401.14	963.73
3404.27	1030.1
3407.4	1145.15
3410.52	1330.88
3413.65	1655
3416.77	2424.25
3419.89	4185.19
3423.01	9007.91
3426.13	15125.5
3429.25	12305.3
3432.37	6063.93
3435.49	3042.46
3438.6	1906.62
3441.72	1434.83
3444.83	1196.95
3447.94	1090.59
3451.05	959.503
3454.16	961.797
3457.26	907.885
3460.37	904.346
3463.47	888.435
3466.58	906.698
3469.68	889.679
3472.78	902.873
3475.88	926.736
3478.98	961.02
3482.07	1054.87
3485.17	1168.46
3488.26	1275.36
3491.36	1429.53
3494.45	1759.5
3497.54	2143.04
3500.63	2761.99
3503.72	3485.28
3506.81	4204.62
3509.89	4493.72
3512.98	3968.76
3516.06	3130.15
3519.14	2458.11
3522.22	1882.61
3525.3	1549.57
3528.38	1339.55
3531.45	1114.48
3534.53	1057.1
3537.61	935.975
3540.68	880.117
3543.75	808.585
3546.82	821.868
3549.89	776.218
3552.96	762.457
3556.03	757.127
3559.09	718.796
3562.16	698.413
3565.22	725.232
3568.28	711.21
3571.34	673.699
3574.4	682.303
3577.46	664.384
3580.52	654.943
3583.57	654.933
3586.63	659.603
3589.68	670.906
3592.73	633.768
3595.78	655.397
3598.83	611.577
3601.88	620.828
3604.93	645.149
3607.97	630.605
3611.02	634.038
3614.06	627.981
3617.1	607.741
3620.14	606.431
3623.18	619.3
3626.22	618.974
3629.26	617.745
3632.3	606.121
3635.33	611.422
3638.36	608.402
3641.4	619.578
3644.43	615.771
3647.46	596.124
3650.49	597.951
3653.51	578.219
3656.54	576.57
3659.57	567.734
3662.59	584.246
3665.61	594.08
3668.63	571.603
3671.65	567.161
3674.67	559.911
3677.69	560.238
3680.71	570.987
3683.72	584.553
3686.74	565.989
3689.75	548.366
3692.76	561.984
3695.77	555.727
3698.78	562.626
3701.79	544.99
3704.79	545.365
3707.8	544.785
3710.81	532.733
3713.81	563.419
3716.81	556.961
3719.81	539.117
3722.81	533.568
3725.81	554.63
3728.81	562.317
3731.8	541.397
3734.8	556.608
3737.79	542.238
3740.78	547.815
3743.77	541.904
3746.76	536.903
3749.75	554.667
3752.74	547.668
3755.73	552.064
3758.71	533.696
3761.7	523.87
3764.68	525.383
3767.66	522.172
3770.64	536.039
3773.62	519.677
3776.6	538.345
3779.58	548.525
3782.55	523.782
3785.53	541.557
3788.5	512.151
3791.47	511.106
3794.44	505.424
3797.41	521.492
3800.38	536.652
3803.35	535.837
3806.32	549.216
3809.28	521.05
3812.24	527.867
3815.21	521.465
3818.17	517.909
3821.13	530.46
3824.09	518.419
3827.04	501.664
3830	507.648
3832.96	525.966
3835.91	539.612
3838.86	497.263
3841.82	529.948
3844.77	525.576
3847.72	512.642
3850.67	504.474
3853.61	518.252
3856.56	533.974
3859.5	511.521
3862.45	535.881
3865.39	523.889
3868.33	508.046
3871.27	519.929
3874.21	497.286
3877.15	518.738
3880.09	510.388
3883.02	505.818
3885.96	505.988
3888.89	520.539
3891.82	522.577
3894.75	507.278
3897.68	514.031
3900.61	523.608
3903.54	505.285
3906.47	502.286
3909.39	480.123
3912.31	495.401
3915.24	499.094
3918.16	521
3921.08	518.98
3924	487.105
3926.92	501.25
3929.83	493.28
3932.75	469.968
3935.67	506.174
3938.58	516.608
3941.49	521.389
3944.4	474.418
3947.31	498.328
3950.22	496.438
3953.13	494.583
3956.04	486.046
3958.94	496.708
3961.85	472.902
3964.75	486.489
3967.65	514.499
3970.55	494.588
3973.45	489.071
3976.35	498.902
3979.25	499.101
3982.15	484.852
3985.04	489.811
3987.94	468.785
3990.83	475.626
3993.72	478.565
3996.61	468.123
3999.5	497.129
4002.39	483.814
4005.28	484.945
4008.16	488.992
4011.05	480.517
4013.93	493.244
4016.81	461.608
4019.7	481.096
4022.58	483.219
4025.46	476.653
4028.33	475.889
4031.21	481.894
4034.09	473.411
4036.96	492.016
4039.84	472.908
4042.71	484.759
4045.58	483.942
4048.45	470.549
4051.32	494.017
4054.19	468.059
4057.05	482.887
4059.92	494.797
4062.78	475.61
4065.65	461.265
4068.51	462.465
4071.37	479.227
4074.23	468.745
4077.09	488.435
4079.95	475.008
4082.81	468.391
4085.66	453.971
4088.52	464.881
4091.37	468.966
4094.22	476.019
4097.07	482.062
4099.92	467.615
4102.77	452.166
4105.62	442.559
4108.47	468.108
4111.31	458.45
4114.16	467.329
4117	447.778
4119.84	447.736
4122.69	468.251
4125.53	448.699
4128.36	467.325
4131.2	440.072
4134.04	449.102
4136.88	454.364
4139.71	464.931
4142.54	451.583
4145.38	465.246
4148.21	458.546
4151.04	450.899
4153.87	462.731
4156.69	453.831
4159.52	455.51
4162.35	438.765
4165.17	461.212
4168	459.194
4170.82	466.979
4173.64	446.429
4176.46	470.876
4179.28	449.361
4182.1	441.575
4184.91	431.845
4187.73	472.032
4190.54	435.922
4193.36	454.677
4196.17	464.682
4198.98	468.886
4201.79	483.862
4204.6	484.162
4207.41	508.983
4210.22	498.484
4213.02	510.558
4215.83	485.274
4218.63	453.346
4221.44	438.072
4224.24	459.228
4227.04	439.877
4229.84	441.324
4232.64	435.863
4235.43	461.156
4238.23	453.805
4241.02	459.358
4243.82	448.031
4246.61	457.615
4249.4	466.199
4252.19	439.814
4254.98	446.34
4257.77	442.831
4260.56	455.338
4263.35	437.805
4266.13	425.268
4268.92	446.915
4271.7	450.489
4274.48	411.725
4277.26	419.201
4280.04	434.708
4282.82	427.977
4285.6	435.347
4288.38	446.718
4291.15	416.547
4293.93	412.662
4296.7	408.832
4299.47	418.211
4302.25	415.387
4305.02	422.704
4307.79	400.581
4310.55	438.396
4313.32	415.301
4316.09	415.504
4318.85	410.581
4321.62	433.107
4324.38	397.577
4327.14	411.909
4329.9	422.187
4332.66	413.067
4335.42	418.234
4338.18	425.396
4340.94	414.298
4343.69	411.352
4346.45	412.527
4349.2	398.436
4351.95	402.709
4354.7	412.206
4357.45	397.134
4360.2	408.639
4362.95	416.038
4365.7	411.198
4368.44	399.142
4371.19	413.774
4373.93	408.853
4376.68	422.394
4379.42	400.995
4382.16	370.326
4384.9	398.235
4387.64	385.131
4390.37	404.072
4393.11	407.66
4395.85	390.926
4398.58	409.001
4401.31	401.216
4404.05	394.407
4406.78	382.416
4409.51	376.646
4412.24	410.345
4414.96	404.487
4417.69	382.969
4420.42	394.62
4423.14	395.932
4425.87	378.476
4428.59	402.791
4431.31	388.453
4434.03	386.643
4436.75	399.469
4439.47	385.05
4442.19	393.638
4444.91	376.024
4447.62	395.095
4450.34	392.138
4453.05	376.538
4455.76	388.24
4458.47	378.891
4461.19	386.341
4463.89	369.659
4466.6	396.089
4469.31	364.677
4472.02	365.897
4474.72	359.775
4477.43	370.546
4480.13	384.527
4482.83	391.161
4485.53	379.842
4488.23	364.245
4490.93	372.947
4493.63	376.272
4496.33	375.302
4499.02	370.167
4501.72	370.304
4504.41	369.351
4507.11	364.193
4509.8	379.195
4512.49	364.5
4515.18	374.219
4517.87	374.397
4520.56	369.279
4523.24	372.701
4525.93	363.358
4528.61	366.772
4531.3	373.398
4533.98	373.646
4536.66	358.972
4539.34	377.385
4542.02	341.361
4544.7	360.876
4547.38	356.893
4550.05	377.541
4552.73	354.31
4555.4	355.778
4558.08	366.974
4560.75	350.328
4563.42	369.269
4566.09	343.024
4568.76	363.321
4571.43	345.506
4574.1	343.545
4576.77	362.066
4579.43	369.916
4582.1	328.998
4584.76	369.715
4587.42	347.093
4590.08	350.591
4592.74	348.601
4595.4	351
4598.06	329.408
4600.72	351.483
4603.38	335.363
4606.03	346.617
4608.69	340.355
4611.34	356.032
4613.99	351.957
4616.64	339.078
4619.29	345.996
4621.94	326.517
4624.59	341.157
4627.24	341.455
4629.89	337.322
4632.53	321.013
4635.18	335.595
4637.82	312.554
4640.46	340.404
4643.1	332.847
4645.74	326.468
4648.38	331.259
4651.02	335.033
4653.66	326.7
4656.3	323.769
4658.93	336.091
4661.57	337.517
4664.2	302.143
4666.83	324.793
4669.46	309.363
4672.09	335.367
4674.72	333.389
4677.35	310.097
4679.98	327.166
4682.61	326.281
4685.23	331.016
4687.86	327.884
4690.48	305.616
4693.1	326.127
4695.73	325.22
4698.34	323.179
4700.96	307.597
4703.58	311.186
4706.2	331.703
4708.82	313.787
4711.43	316.204
4714.05	315.223
4716.66	330.081
4719.28	326.811
4721.89	317.86
4724.5	313.423
4727.11	302.221
4729.72	315.99
4732.33	311.611
4734.93	309.501
4737.54	290.331
4740.14	323.42
4742.75	289.425
4745.35	287.237
4747.95	321.436
4750.55	314.635
4753.15	318.085
4755.75	316.977
4758.35	301.069
4760.95	305.679
4763.54	301.202
4766.14	301.299
4768.73	303.744
4771.33	287.969
4773.92	300.641
4776.51	295.067
4779.1	315.755
4781.69	310.18
4784.28	305.746
4786.87	307.03
4789.45	298.019
4792.04	285.578
4794.63	306.347
4797.21	280.17
4799.79	286.096
4802.37	304.672
4804.95	280.809
4807.53	278.781
4810.11	300.938
4812.69	290.881
4815.27	280.82
4817.84	289.229
4820.42	280.341
4822.99	284.161
4825.57	296.109
4828.14	297.637
4830.71	289.879
4833.28	276.314
4835.85	284.858
4838.42	288.795
4840.98	292.771
4843.55	272.164
4846.12	276.064
4848.68	291.682
4851.24	288.446
4853.81	283.837
4856.37	280.452
4858.93	266.735
4861.49	275.367
4864.05	261.511
4866.61	277.076
4869.16	284.407
4871.72	269.322
4874.27	269.547
4876.83	260.256
4879.38	284.173
4881.93	265.362
4884.49	266.707
4887.04	273.995
4889.58	275.351
4892.13	274.33
4894.68	274.487
4897.23	268.678
4899.77	279.543
4902.32	258.211
4904.86	277.426
4907.4	256.057
4909.95	256.158
4912.49	271.729
4915.03	253.836
4917.57	265.779
4920.1	257.445
4922.64	257.472
4925.18	264.67
4927.71	257.549
4930.25	276.685
4932.78	274.385
4935.31	249.407
4937.84	272.244
4940.38	265.166
4942.9	251.981
4945.43	250.863
4947.96	256.973
4950.49	240.306
4953.01	234.437
4955.54	253.724
4958.06	247.871
4960.59	242.032
4963.11	260.248
4965.63	249.691
4968.15	265.663
4970.67	268.325
4973.19	242.011
4975.71	260.343
4978.22	244.845
4980.74	258.378
4983.25	253.768
4985.77	246.734
4988.28	240.905
4990.79	241.145
4993.3	252.318
4995.81	258.637
4998.32	244.3