File: Data/3-Raman/raw/bu19(2)w-a-ff1-fi06-s_150 (500nm)_532nm_edge_100%_x100_vis_lwd_h50um_30sx2_01.txt
#Acq. time (s)=	30
#Accumulations=	2
#Range (cm-¹)=	99...4000
#Windows=	1
#Auto scanning=	Off
#Autofocus=	Off
#Macrospot=	Off
#AutoExposure=	Off
#Spike filter=	Multiple accum.
#Delay time (s)=	2
#Binning=	1
#Readout mode=	Signal
#DeNoise=	Off
#ICS correction=	On
#Dark correction=	Off
#Inst. Process=	Off
#Detector Gain=	Best Dynamic
#Detector ADC=	50 kHz HS
#Detector temperature (°C)=	-60.09
#Instrument=	LabRAM HR Evol
#Detector=	SIN-EM FIVIS
#Objective=	x100_VIS_LWD
#Grating=	150 (500nm)
#ND Filter=	100%
#Laser=	532nm_Edge
#Hole=	49.98
#Temperature=	0
#Range=	Visible
#StageXY=	75x50mm Scan+
#StageZ=	Z motor
#X (µm)=	0
#Y (µm)=	0
#Z (µm)=	-18.5
#Full time(mm:ss)=	1:05
#Project=	21_11_26
#Sample=	BU19(2)w
#Site=
#Title=	BU19(2)w-A-FF1-FI06-S_150 (500nm)_532nm_Edge_100%_x100_VIS_LWD_H50um_30sX2
#Remark=
#Date=	26.11.2021 13:59
#Acquired=	26.11.2021 13:59:31
102.91	6225.12
107.534	9532.37
112.156	9026.15
116.775	6318.71
121.392	4647.03
126.005	5084.77
130.617	7276.06
135.227	12073.9
139.835	20998.4
144.439	28314.1
149.042	24438.9
153.643	15400.6
158.242	9309.91
162.839	6001.61
167.431	4289.96
172.023	3279.45
176.613	2636.12
181.198	2277.27
185.783	2120.53
190.366	2096.02
194.947	2470.35
199.524	3767.06
204.1	7604.33
208.674	9785.84
213.243	5694.01
217.813	3137.62
222.38	3153.35
226.945	5466.28
231.506	9139.52
236.066	7648.36
240.625	3829.55
245.179	2079.53
249.732	1495.08
254.284	1281.78
258.831	1151.6
263.378	1128.65
267.923	1099.7
272.464	1277.09
277.004	1791.31
281.54	1829.06
286.076	1289.74
290.61	1028.73
295.139	1016.65
299.669	1013.18
304.196	1099.81
308.718	1236.2
313.241	1365.3
317.759	1621.68
322.278	2305.3
326.794	3519.6
331.305	4516.56
335.817	4376.69
340.324	3815.79
344.832	4417.72
349.334	5394.41
353.837	4372.11
358.338	3037.94
362.834	2418.74
367.33	2271.48
371.822	2432.28
376.314	2982.5
380.802	4380.47
385.289	7658.16
389.772	11726.7
394.255	12204.4
398.734	10317.8
403.213	8467.9
407.688	6862.08
412.162	5945.13
416.632	6057.91
421.102	6685.75
425.568	7494.56
430.033	7664.09
434.495	7261.05
438.956	7043.55
443.413	7409.85
447.87	8128.64
452.323	7853.69
456.776	6249.95
461.224	4412.63
465.673	3195.37
470.117	2709.13
474.561	2592.51
479.001	2846.75
483.438	3384.07
487.876	4605.31
492.309	6261.06
496.742	8960.66
501.172	12425.3
505.601	15281.7
510.025	16150.4
514.448	14605.8
518.871	12183.7
523.289	10307.2
527.707	9210.93
532.121	8646.53
536.533	8776.58
540.945	9128.4
545.353	9388.65
549.758	8942.09
554.164	8132.69
558.565	7071.96
562.965	5777.98
567.364	4787.98
571.759	3980.6
576.151	3468.23
580.544	3365.52
584.933	3644.05
589.319	4239.19
593.706	5126.78
598.088	6250.62
602.468	7961.46
606.848	11158.9
611.224	18139.6
615.598	29577.5
619.972	32120.3
624.341	22177.2
628.709	12833.7
633.074	7740.71
637.44	5269.37
641.801	3823.44
646.16	2876.17
650.517	2346.27
654.874	1935.58
659.227	1630.52
663.578	1397.36
667.927	1243.04
672.275	1123.2
676.62	1071.31
680.962	1039.92
685.302	1117.14
689.643	1317.63
693.979	1637.44
698.313	2010.48
702.645	2119.35
706.975	1931.86
711.305	1652.73
715.631	1382.91
719.955	1297.46
724.276	1219.02
728.596	1117.73
732.913	943.003
737.231	841.279
741.544	801.203
745.856	772.669
750.165	775.494
754.472	784.042
758.778	755.67
763.081	779.098
767.384	785.136
771.683	811.401
775.98	819.651
780.275	850.815
784.568	904.26
788.859	936.153
793.147	991.414
797.434	1039.29
801.719	1098.53
806.004	1192.6
810.284	1291.48
814.563	1487.34
818.839	1682.43
823.114	2093.25
827.386	2599.64
831.657	3317.26
835.925	4028.13
840.192	4729.62
844.456	4831.04
848.719	4459.56
852.979	3827.5
857.237	3224.77
861.493	2871.58
865.748	2647.1
870	2749.86
874.25	3131.85
878.499	3292.61
882.745	2809.52
886.989	2154.55
891.231	1692.17
895.471	1438.14
899.71	1222.5
903.946	1154.03
908.18	1096.95
912.412	1061.39
916.642	1051.45
920.87	1037
925.096	1004.95
929.321	1042.34
933.543	1050.81
937.763	1029.12
941.981	1083.22
946.197	1039.72
950.412	1101.98
954.622	1079.09
958.832	1091.5
963.04	1117.84
967.246	1115.58
971.451	1149.53
975.653	1192.15
979.853	1262.4
984.052	1369.9
988.248	1631.84
992.442	1822.81
996.633	2127.34
1000.82	2176.14
1005.01	2000.57
1009.2	1801.47
1013.38	1674.21
1017.57	1628.21
1021.75	1632.2
1025.92	1728.69
1030.1	1938.95
1034.27	2250.22
1038.45	2835.41
1042.62	3478.27
1046.78	3647.62
1050.95	3490.11
1055.12	3429.9
1059.28	3533.91
1063.44	3885.23
1067.6	4435.34
1071.75	5335.92
1075.91	6866.82
1080.06	9212.69
1084.21	13316.1
1088.36	19146.1
1092.51	23198.1
1096.65	21009.2
1100.8	14537.3
1104.94	8977.67
1109.08	5952.11
1113.21	4480.83
1117.35	3850.88
1121.48	3597.96
1125.61	3762.61
1129.74	4306.25
1133.87	5323.09
1137.99	6846.64
1142.12	8195.84
1146.24	8044.6
1150.36	6702.21
1154.48	5060.8
1158.59	3751.54
1162.71	2893.62
1166.82	2315.37
1170.93	1922.49
1175.04	1684.01
1179.14	1425
1183.25	1220.95
1187.35	1084.79
1191.45	1032.54
1195.55	945.372
1199.65	886.883
1203.74	846.788
1207.83	818.013
1211.92	775.247
1216.01	767.094
1220.1	736.893
1224.19	717
1228.27	710.393
1232.35	658.039
1236.43	690.324
1240.51	683.992
1244.58	646.562
1248.66	622.396
1252.73	615.544
1256.8	589.847
1260.87	590.21
1264.93	541.648
1269	548.179
1273.06	521.732
1277.12	523.322
1281.18	500.785
1285.23	516.329
1289.29	498.598
1293.34	473.735
1297.39	483.021
1301.44	480.177
1305.49	469.175
1309.53	460.152
1313.58	433.941
1317.62	450.909
1321.66	469.778
1325.7	451.217
1329.73	436.652
1333.77	428.097
1337.8	443.475
1341.83	446.718
1345.86	427.931
1349.88	432.128
1353.91	421.394
1357.93	413.697
1361.95	393.105
1365.97	397.399
1369.99	398.777
1374	385.44
1378.02	370.224
1382.03	379.73
1386.04	372.656
1390.05	350.897
1394.05	344.006
1398.06	353.012
1402.06	354.118
1406.06	326.636
1410.06	332.684
1414.05	337.782
1418.05	359.666
1422.04	325.294
1426.03	339.242
1430.02	351.046
1434.01	354.977
1438	348.041
1441.98	342.097
1445.96	339.064
1449.94	336.011
1453.92	330.931
1457.9	345.538
1461.87	323.615
1465.85	338.038
1469.82	323.902
1473.78	314.75
1477.75	314.404
1481.72	327.735
1485.68	311.654
1489.65	316.113
1493.61	328.392
1497.56	334.798
1501.52	328.568
1505.47	330.19
1509.43	300.801
1513.38	307.411
1517.33	303.351
1521.27	303.211
1525.22	304.061
1529.16	310.752
1533.11	310.693
1537.05	311.611
1540.98	300.909
1544.92	314.436
1548.86	299.864
1552.79	308.546
1556.72	312.344
1560.65	285.112
1564.58	312.06
1568.5	313.803
1572.43	299.092
1576.35	302.745
1580.27	324.714
1584.19	307.108
1588.1	302.994
1592.02	309.468
1595.93	316.887
1599.84	311.802
1603.75	306.751
1607.66	310.39
1611.57	328.416
1615.47	314.82
1619.37	310.86
1623.27	323.163
1627.17	303.918
1631.07	312.478
1634.97	302.952
1638.86	327.871
1642.75	305.006
1646.64	315.721
1650.53	324.562
1654.42	308.485
1658.3	325.004
1662.18	311.748
1666.07	331.095
1669.94	317.732
1673.82	299.46
1677.7	312.893
1681.57	316.541
1685.44	292.267
1689.31	308.286
1693.18	313.672
1697.05	317.085
1700.92	326.166
1704.78	333.242
1708.64	337.366
1712.5	354.698
1716.36	356.796
1720.21	359.847
1724.07	351.568
1727.92	374.373
1731.77	367.887
1735.62	378.337
1739.47	374.664
1743.32	385.892
1747.16	403.606
1751.01	436.365
1754.85	452.474
1758.69	465.098
1762.52	440.437
1766.36	427.508
1770.19	412.873
1774.02	384.47
1777.85	345.782
1781.68	343.467
1785.51	336.535
1789.33	328.683
1793.16	328.314
1796.98	340.149
1800.8	323.811
1804.62	319.452
1808.43	323.533
1812.25	305.902
1816.06	324.978
1819.87	315.623
1823.68	302.408
1827.49	311.78
1831.3	300.316
1835.1	312.343
1838.9	301.704
1842.71	296.682
1846.51	302.87
1850.3	299.701
1854.1	287.035
1857.89	304.25
1861.69	289.588
1865.48	300.082
1869.27	288.276
1873.05	297.861
1876.84	315.792
1880.62	311.527
1884.4	320.312
1888.19	325.405
1891.96	320.74
1895.74	325.289
1899.52	331.677
1903.29	332.688
1907.06	318.113
1910.83	306.319
1914.6	321.362
1918.37	317.996
1922.13	313.901
1925.9	304.265
1929.66	308.568
1933.42	316.635
1937.18	309.818
1940.94	324.436
1944.69	321.329
1948.44	337.891
1952.2	336.407
1955.95	365.772
1959.69	389.34
1963.44	409.022
1967.19	435.249
1970.93	488.541
1974.67	515.322
1978.41	542.882
1982.15	551.573
1985.89	583.502
1989.62	606.873
1993.35	603.061
1997.09	597.281
2000.82	580.277
2004.55	562.442
2008.27	539.076
2012	512.916
2015.72	486.897
2019.44	463.974
2023.16	431.288
2026.88	423.663
2030.6	404.168
2034.31	397.695
2038.03	384.955
2041.74	358.442
2045.45	366.689
2049.16	343.814
2052.86	332.906
2056.57	327.509
2060.27	313.107
2063.98	326.413
2067.67	315.929
2071.37	294.377
2075.07	306.903
2078.77	297.305
2082.46	291.397
2086.15	292.854
2089.84	296.753
2093.53	278.223
2097.22	276.543
2100.9	271.093
2104.59	271.127
2108.27	282.274
2111.95	278.495
2115.63	270.991
2119.31	268.103
2122.98	279.04
2126.66	271.344
2130.33	280.299
2134	261.443
2137.67	279.587
2141.34	270.868
2145	270.427
2148.67	261.69
2152.33	270.425
2155.99	267.224
2159.65	276.856
2163.31	259.99
2166.96	266.942
2170.62	261.162
2174.27	260.055
2177.92	248.995
2181.57	257.999
2185.22	247.881
2188.87	246.022
2192.51	252.446
2196.15	243.505
2199.8	233.694
2203.44	237.571
2207.07	247.885
2210.71	245.468
2214.35	241.247
2217.98	248.03
2221.61	241.064
2225.24	248.806
2228.87	234.446
2232.5	231.119
2236.12	223.18
2239.75	222.614
2243.37	237.801
2246.99	233.526
2250.61	232.039
2254.23	232.436
2257.85	228.188
2261.46	236.075
2265.07	233.657
2268.68	217.184
2272.29	213.858
2275.9	222.702
2279.51	219.252
2283.11	209.986
2286.72	235.647
2290.32	230.152
2293.92	229.347
2297.52	228.548
2301.11	226.809
2304.71	218.396
2308.3	231.729
2311.9	234.607
2315.49	232.71
2319.08	237.408
2322.66	227.838
2326.25	219.089
2329.84	229.243
2333.42	237.455
2337	215.442
2340.58	224.531
2344.16	221.349
2347.73	217.21
2351.31	226.182
2354.88	231.37
2358.45	229.993
2362.03	223.949
2365.59	243.947
2369.16	222.143
2372.73	229.177
2376.29	216.758
2379.85	223.765
2383.41	239.068
2386.97	239.629
2390.53	229.205
2394.09	234.452
2397.64	234.259
2401.2	229.563
2404.75	229.578
2408.3	235.122
2411.85	231.597
2415.39	230.878
2418.94	211.833
2422.48	235.103
2426.03	208.731
2429.57	230.329
2433.11	218.755
2436.64	235.917
2440.18	226.236
2443.72	228.634
2447.25	226.381
2450.78	220.419
2454.31	233.234
2457.84	219.623
2461.37	234.968
2464.89	231.47
2468.42	214.567
2471.94	227.084
2475.46	226.02
2478.98	226.806
2482.5	221.974
2486.01	234.957
2489.53	228.018
2493.04	238.127
2496.55	230.258
2500.06	239.353
2503.57	240.86
2507.08	226.448
2510.58	231.609
2514.09	218.16
2517.59	227.102
2521.09	244.405
2524.59	228.157
2528.09	236.227
2531.59	224.019
2535.08	208.17
2538.58	233.924
2542.07	218.201
2545.56	228.423
2549.05	231.365
2552.54	223.231
2556.02	228.096
2559.51	238.648
2562.99	242.738
2566.47	236.718
2569.95	240.069
2573.43	222.935
2576.91	235.746
2580.38	228.933
2583.85	225.863
2587.33	228.449
2590.8	230.991
2594.27	223.915
2597.74	231.063
2601.2	231.624
2604.67	237.912
2608.13	232.577
2611.59	227.991
2615.06	232.843
2618.51	232.983
2621.97	237.829
2625.43	228.215
2628.88	223.345
2632.33	229.964
2635.79	226.923
2639.24	234.363
2642.69	213.022
2646.13	225.156
2649.58	229.602
2653.02	225.403
2656.47	229.721
2659.91	235.872
2663.35	226.816
2666.79	231.952
2670.22	228.575
2673.66	228.022
2677.09	229.385
2680.52	223.286
2683.95	227.54
2687.39	231.86
2690.81	229.795
2694.24	229.678
2697.66	237.892
2701.09	227.539
2704.51	218.133
2707.93	224.551
2711.35	234.846
2714.77	222.866
2718.18	224.883
2721.6	226.016
2725.01	236.51
2728.42	232.101
2731.84	234.242
2735.24	229.821
2738.65	228.201
2742.06	217.186
2745.46	225.824
2748.86	224.108
2752.27	234.616
2755.67	218.772
2759.07	220.771
2762.46	224.661
2765.86	226.61
2769.25	214.388
2772.65	220.976
2776.04	232.255
2779.43	230.301
2782.82	232.082
2786.2	229.139
2789.59	228.072
2792.98	230.757
2796.36	214.644
2799.74	246.429
2803.12	248.112
2806.5	236.672
2809.88	228.054
2813.25	227.859
2816.63	224.846
2820	231.174
2823.37	216.995
2826.74	234.578
2830.11	238.175
2833.48	233.414
2836.84	215.658
2840.21	227.753
2843.57	239.893
2846.93	223.206
2850.29	232.695
2853.65	229.186
2857.01	230.313
2860.36	219.316
2863.72	229.857
2867.07	231.058
2870.42	242.585
2873.77	241.909
2877.12	231.819
2880.47	245.237
2883.81	241.711
2887.16	253.25
2890.5	254.419
2893.84	241.402
2897.18	252.888
2900.52	248.271
2903.86	255.91
2907.19	237.026
2910.53	251.237
2913.86	245.559
2917.19	244.595
2920.52	249.27
2923.85	250.146
2927.18	257.616
2930.51	257.484
2933.83	264.875
2937.15	266.554
2940.48	267.288
2943.8	262.369
2947.11	267.821
2950.43	257.281
2953.75	264.607
2957.06	260.659
2960.38	265.208
2963.69	235.057
2967	259.349
2970.31	239.627
2973.62	249.025
2976.92	244.364
2980.23	251.001
2983.53	258.55
2986.84	267.996
2990.14	264.316
2993.44	263.461
2996.73	264.499
3000.03	260.852
3003.33	269.423
3006.62	268.595
3009.91	257.433
3013.2	260.4
3016.49	282.222
3019.78	268.234
3023.07	286.299
3026.35	275.126
3029.64	273.388
3032.92	271.643
3036.2	279.335
3039.48	263.384
3042.76	275.804
3046.04	282.562
3049.32	273.229
3052.59	280.942
3055.86	286.774
3059.14	290.703
3062.41	288.849
3065.68	274.702
3068.94	288.986
3072.21	281.381
3075.48	305.777
3078.74	280.206
3082	287.729
3085.26	296.449
3088.52	290.928
3091.78	307.328
3095.04	293.348
3098.29	315.107
3101.55	304.738
3104.8	304.768
3108.05	303.988
3111.3	300.309
3114.55	307.002
3117.8	313.725
3121.04	328.078
3124.29	321.48
3127.53	331.071
3130.77	315.88
3134.02	327.374
3137.25	332.19
3140.49	332.223
3143.73	338.924
3146.96	341.815
3150.2	334.24
3153.43	344.79
3156.66	341.974
3159.89	350.615
3163.12	362.109
3166.35	365.973
3169.57	382.209
3172.8	364.064
3176.02	384.073
3179.24	385.919
3182.46	382.989
3185.68	396.282
3188.9	403.802
3192.12	401.774
3195.33	411.182
3198.55	424.388
3201.76	431.862
3204.97	427.927
3208.18	437.332
3211.39	445.803
3214.6	461.912
3217.8	467.584
3221.01	480.867
3224.21	479.897
3227.41	469.461
3230.61	487.576
3233.81	487.653
3237.01	503.875
3240.21	531.637
3243.4	542.308
3246.59	558.73
3249.79	584.699
3252.98	597.401
3256.17	621.581
3259.36	645.774
3262.54	667.032
3265.73	702.535
3268.92	732.22
3272.1	737.953
3275.28	777.074
3278.46	795.164
3281.64	846.503
3284.82	860.427
3288	937.322
3291.17	936.828
3294.35	945.942
3297.52	1004.55
3300.69	1031.69
3303.86	1088.56
3307.03	1062.33
3310.2	1148.24
3313.36	1201.54
3316.53	1248.99
3319.69	1327.64
3322.85	1351.13
3326.02	1456.98
3329.18	1529.55
3332.33	1589.74
3335.49	1679.23
3338.65	1790.45
3341.8	1841.28
3344.95	1978.85
3348.11	2085.69
3351.26	2196.76
3354.41	2325.7
3357.56	2454.89
3360.7	2561.6
3363.85	2628.11
3366.99	2753.17
3370.13	2920.9
3373.28	3069.04
3376.42	3202.54
3379.56	3411.87
3382.69	3571.49
3385.83	3729.22
3388.97	3963.1
3392.1	4173.65
3395.23	4385.18
3398.36	4768.18
3401.49	5027.23
3404.62	5383.97
3407.75	5768.51
3410.88	6095.23
3414	6600.47
3417.13	7172.72
3420.25	7714.87
3423.37	8339.11
3426.49	8989.01
3429.61	9625.35
3432.73	10486.9
3435.84	11446.6
3438.96	12484.4
3442.07	13883.1
3445.18	15866.6
3448.29	19105.6
3451.4	24443.2
3454.51	30945.2
3457.62	30926.2
3460.72	30902.8
3463.83	29061.6
3466.93	23725.6
3470.03	20104.8
3473.13	18057.9
3476.23	16755.6
3479.33	16230.4
3482.43	15841.9
3485.53	15822.1
3488.62	15684.4
3491.71	15843.7
3494.81	15876.1
3497.9	16068.3
3500.99	16182.9
3504.07	16439.2
3507.16	16831.2
3510.25	17435.6
3513.33	18076.1
3516.41	19045.7
3519.5	20140.5
3522.58	21588.1
3525.66	23174.8
3528.73	24606.9
3531.81	26165.5
3534.89	27329.3
3537.96	27774.8
3541.03	27177
3544.11	25178.5
3547.18	22559.6
3550.25	19430
3553.32	16291.4
3556.38	13640.1
3559.45	11271.2
3562.51	9439.23
3565.58	8048.61
3568.64	6963.8
3571.7	6010.19
3574.76	5319.5
3577.82	4729.41
3580.87	4299.1
3583.93	3899.72
3586.98	3620.47
3590.04	3349.78
3593.09	3111.01
3596.14	2902.6
3599.19	2680.8
3602.24	2594.59
3605.29	2494.92
3608.33	2384.75
3611.38	2307.78
3614.42	2234.55
3617.46	2141.49
3620.5	2111.89
3623.54	2028.64
3626.58	1943.66
3629.62	1897.53
3632.65	1808
3635.69	1737.3
3638.72	1666.16
3641.76	1597.17
3644.79	1528.37
3647.82	1438.32
3650.84	1394.91
3653.87	1298.05
3656.9	1250.41
3659.92	1195.21
3662.95	1146.37
3665.97	1104.77
3668.99	1029.64
3672.01	1009.39
3675.03	972.18
3678.05	933.102
3681.07	931.811
3684.08	894.551
3687.1	873.336
3690.11	844.551
3693.12	833.745
3696.13	810.615
3699.14	795.83
3702.15	770.765
3705.16	729.528
3708.16	724.323
3711.17	719.975
3714.17	716.517
3717.17	673.966
3720.17	657.124
3723.17	644.946
3726.17	624.138
3729.17	592.79
3732.16	599.488
3735.16	586.129
3738.15	586.987
3741.14	555.43
3744.13	542.855
3747.13	552.12
3750.11	530.902
3753.1	518.218
3756.09	501.746
3759.07	504.282
3762.06	484.993
3765.04	464.743
3768.02	455.894
3771	480.211
3773.98	438.344
3776.96	447.596
3779.94	441.749
3782.91	431.211
3785.89	427.297
3788.86	405.472
3791.83	407.28
3794.8	399.714
3797.77	417.666
3800.74	401.663
3803.71	406.481
3806.68	398.099
3809.64	387.835
3812.61	392.711
3815.57	390.036
3818.53	380.746
3821.49	366.732
3824.45	365.024
3827.41	373.762
3830.36	370.19
3833.32	354.281
3836.27	365.912
3839.23	350.982
3842.18	371.202
3845.13	380.984
3848.08	353.662
3851.03	367.281
3853.98	371.407
3856.92	375.548
3859.87	368.239
3862.81	362.832
3865.75	378.445
3868.7	373.973
3871.64	368.503
3874.57	376.442
3877.51	388.214
3880.45	361.545
3883.39	388.611
3886.32	373.365
3889.25	378.269
3892.18	405.274
3895.12	360.144
3898.05	373.622
3900.97	363.977
3903.9	374.516
3906.83	378.276
3909.75	377.274
3912.68	377.196
3915.6	357.868
3918.52	375.024
3921.44	365.35
3924.36	367.128
3927.28	359.268
3930.2	362.888
3933.11	345.409
3936.03	343.355
3938.94	356.694
3941.86	345.199
3944.77	335.587
3947.68	350.888
3950.59	341.331
3953.49	344.246
3956.4	353.88
3959.31	349.181
3962.21	356.953
3965.12	361.872
3968.02	353.389
3970.92	366.024
3973.82	371.963
3976.72	369.255
3979.61	366.521
3982.51	372.409
3985.41	378.294
3988.3	368.778
3991.19	375.596
3994.09	378.524
3996.98	359.392
3999.87	387.405