File: Data/3-Raman/raw/bu19w-e-ff11-fi07-v_150 (500nm)_633nm_edge_100%_x100_vis_h50um_60sx2_01.txt
#Acq. time (s)=	60
#Accumulations=	2
#Range (cm-¹)=	100...4000
#Windows=	1
#Auto scanning=	Off
#Autofocus=	Off
#Macrospot=	Off
#AutoExposure=	Off
#Spike filter=	Multiple accum.
#Delay time (s)=	2
#Binning=	1
#Readout mode=	Signal
#DeNoise=	Off
#ICS correction=	On
#Dark correction=	Off
#Inst. Process=	Off
#Detector Gain=	Best Dynamic
#Detector ADC=	50 kHz HS
#Detector temperature (°C)=	-60.09
#Instrument=	LabRAM HR Evol
#Detector=	SIN-EM FIVIS
#Objective=	x100_VIS
#Grating=	150 (500nm)
#ND Filter=	100%
#Laser=	633nm_Edge
#Hole=	49.98
#Temperature=	0
#Range=	Visible
#StageXY=	75x50mm Scan+
#StageZ=	Z motor
#X (µm)=	0
#Y (µm)=	0
#Z (µm)=	-271
#Full time(mm:ss)=	2:04
#Project=	21_11_04
#Sample=	BU19w
#Site=
#Title=	BU19w-E-FF11-FI07-V_150 (500nm)_633nm_Edge_100%_x100_VIS_H50um_60sX2
#Remark=
#Date=	04.11.2021 16:01
#Acquired=	04.11.2021 16:01:34
102.881	320.82
109.397	261.959
115.908	231.647
122.414	226.077
128.914	212.831
135.409	214.821
141.898	187.076
148.383	202.429
154.861	234.115
161.335	240.953
167.801	177.813
174.264	133.735
180.721	118.342
187.173	113.42
193.62	112.281
200.061	116.918
206.496	110.22
212.926	119.713
219.352	149.225
225.772	234.878
232.185	299.25
238.595	202.944
244.999	150.578
251.397	155.254
257.791	165.596
264.178	162.683
270.561	160.753
276.939	176.871
283.31	177.774
289.678	146.405
296.039	145.332
302.396	152.775
308.746	198.935
315.093	322.459
321.433	482.681
327.768	330.652
334.099	211.753
340.423	176.813
346.743	164.492
353.058	181.358
359.367	185.903
365.671	166.907
371.971	118.831
378.265	115.889
384.553	104.546
390.837	113.044
397.116	116.965
403.389	117.234
409.657	141.07
415.92	145.061
422.178	173.62
428.431	198.033
434.678	196.634
440.921	182.985
447.158	181.555
453.391	189.446
459.618	154.47
465.84	122.58
472.057	113.175
478.27	108.533
484.477	113.204
490.679	113.219
496.876	121.634
503.068	144.061
509.255	158.13
515.436	168.526
521.613	167.827
527.785	162.534
533.952	153.564
540.113	132.298
546.27	122.155
552.423	108.087
558.568	104.34
564.711	95.7129
570.848	94.5535
576.979	99.8842
583.107	107.065
589.228	126.408
595.345	146.753
601.458	144.923
607.565	153.541
613.667	146.373
619.764	138.354
625.856	119.058
631.944	115.517
638.026	108.931
644.104	110.655
650.177	111.422
656.244	108.33
662.308	96.8124
668.365	82.5759
674.418	71.338
680.467	67.6087
686.511	67.6669
692.549	68.736
698.582	72.6403
704.611	59.6391
710.635	65.363
716.655	62.4977
722.669	68.098
728.679	67.0654
734.683	61.3275
740.683	64.9568
746.678	66.7264
752.669	69.4644
758.654	65.7305
764.635	63.0566
770.611	66.046
776.582	69.9886
782.549	64.4785
788.511	66.4448
794.466	63.6622
800.419	66.4816
806.366	60.7663
812.309	63.504
818.247	67.1264
824.18	74.4579
830.108	73.3577
836.033	66.8009
841.952	75.3208
847.865	76.3926
853.776	75.6288
859.681	73.0025
865.58	81.7052
871.476	86.6451
877.366	96.2421
883.253	92.5163
889.134	100.106
895.012	94.3576
900.883	97.978
906.751	94.9063
912.614	104.073
918.473	96.3393
924.326	103.788
930.174	126.425
936.019	132.296
941.859	163.939
947.693	191.132
953.525	199.497
959.35	196.325
965.171	218.829
970.988	273.908
976.801	348.955
982.608	402.322
988.411	360.519
994.209	285.313
1000	250.506
1005.79	241.667
1011.58	263.647
1017.36	269.625
1023.13	255.673
1028.9	195.928
1034.67	173.406
1040.43	149.853
1046.19	139.689
1051.94	132.276
1057.69	120.86
1063.44	120.956
1069.17	109.258
1074.91	127.659
1080.64	156.647
1086.37	180.724
1092.09	252.286
1097.8	243.414
1103.52	187.187
1109.22	151.472
1114.93	123.671
1120.63	128.929
1126.32	130.191
1132.01	142.251
1137.7	167.106
1143.38	207.784
1149.06	275.986
1154.73	205.296
1160.4	125.475
1166.06	103.629
1171.72	90.6899
1177.38	81.6967
1183.03	79.6136
1188.67	77.6391
1194.31	70.8498
1199.95	66.0765
1205.58	61.3767
1211.21	64.5631
1216.84	58.9013
1222.46	64.1551
1228.07	57.4666
1233.68	60.7195
1239.29	64.9531
1244.89	62.0617
1250.49	70.2012
1256.08	81.3265
1261.67	72.1561
1267.26	69.036
1272.84	192.649
1278.42	170.144
1283.99	74.6286
1289.56	67.5156
1295.12	62.4655
1300.68	62.4589
1306.23	60.5191
1311.78	57.6563
1317.33	61.8632
1322.87	64.1027
1328.41	56.2511
1333.94	58.5033
1339.47	59.7206
1345	63.9561
1350.52	65.1044
1356.04	66.2291
1361.55	68.3403
1367.06	67.3158
1372.56	76.5377
1378.06	395.902
1383.56	132.934
1389.05	69.2566
1394.53	65.1627
1400.02	83.7595
1405.5	68.4428
1410.97	59.2855
1416.44	57.3467
1421.91	58.5152
1427.37	62.8173
1432.83	58.8168
1438.28	52.7034
1443.73	61.2042
1449.17	56.0899
1454.62	55.1047
1460.05	55.1289
1465.48	55.1241
1470.91	55.108
1476.34	53.006
1481.76	50.9277
1487.17	58.3215
1492.59	57.3431
1497.99	54.2824
1503.4	54.3972
1508.8	57.7104
1514.19	52.5667
1519.59	56.9996
1524.97	49.7134
1530.36	58.4698
1535.74	59.7648
1541.11	58.8525
1546.48	58.945
1551.85	60.0301
1557.21	58.8747
1562.57	62.0532
1567.93	64.1456
1573.28	55.4627
1578.62	60.8186
1583.97	60.8249
1589.3	55.4651
1594.64	63.0586
1599.97	62.064
1605.3	56.7724
1610.62	61.2582
1615.94	60.382
1621.25	60.6152
1626.56	59.749
1631.87	56.6679
1637.17	59.0394
1642.47	62.4295
1647.76	59.2051
1653.05	52.6253
1658.34	57.0929
1663.62	64.8731
1668.9	67.0969
1674.18	61.5529
1679.45	67.0865
1684.71	59.2824
1689.98	64.7689
1695.23	62.5419
1700.49	61.5109
1705.74	55.1349
1710.99	66.3632
1716.23	63.0419
1721.47	63.2216
1726.7	66.6855
1731.94	65.7019
1737.16	65.8318
1742.39	70.4677
1747.61	52.521
1752.82	66.1601
1758.03	66.2168
1763.24	65.1064
1768.44	58.341
1773.64	65.1794
1778.84	59.5749
1784.03	64.2135
1789.22	60.9243
1794.41	74.7574
1799.59	65.7941
1804.76	69.4185
1809.94	76.4861
1815.11	61.6659
1820.27	61.7992
1825.43	61.9384
1830.59	57.4428
1835.74	68.0574
1840.89	75.1906
1846.04	70.652
1851.18	62.5791
1856.32	73.1991
1861.45	66.292
1866.58	72.308
1871.71	74.7926
1876.83	70.1755
1881.95	74.9831
1887.07	70.3279
1892.18	72.7085
1897.29	69.1714
1902.39	69.2436
1907.49	77.6792
1912.59	71.9513
1917.68	72.1852
1922.77	72.2662
1927.86	70.0144
1932.94	76.1439
1938.02	71.466
1943.09	69.1555
1948.16	72.8388
1953.23	82.5199
1958.29	76.5229
1963.35	78.9463
1968.41	82.5509
1973.46	80.0968
1978.51	71.6266
1983.55	73.9921
1988.59	73.9592
1993.63	70.3292
1998.66	71.5248
2003.69	71.5387
2008.72	72.7821
2013.74	77.6579
2018.76	77.7107
2023.77	81.3914
2028.78	76.6693
2033.79	70.7595
2038.79	78.1668
2043.79	80.7546
2048.79	80.9327
2053.78	87.1716
2058.77	82.4651
2063.76	81.4251
2068.74	81.6066
2073.72	83.0095
2078.69	77.0136
2083.66	75.9143
2088.63	84.6684
2093.59	88.5334
2098.55	73.8432
2103.51	82.7328
2108.46	79.2133
2113.41	88.2073
2118.36	79.6968
2123.3	84.9744
2128.24	80.169
2133.17	89.2397
2138.11	78.03
2143.03	83.287
2147.96	85.9905
2152.88	87.3864
2157.79	83.6496
2162.71	79.8768
2167.62	87.5733
2172.52	79.9476
2177.43	85.1239
2182.32	90.2568
2187.22	83.8442
2192.11	87.7156
2197	82.6532
2201.89	82.7593
2206.77	90.6106
2211.64	75.3431
2216.52	80.6808
2221.39	84.7682
2226.26	90.1741
2231.12	86.5013
2235.98	86.7208
2240.84	97.3968
2245.69	92.4044
2250.54	90.0115
2255.39	90.2322
2260.23	87.8258
2265.07	86.7003
2269.9	84.2046
2274.74	90.9624
2279.57	89.7312
2284.39	93.7715
2289.21	87.144
2294.03	91.156
2298.84	92.5374
2303.66	95.2944
2308.46	86.1042
2313.27	92.9716
2318.07	97.2242
2322.87	108.222
2327.66	84.2505
2332.45	95.3089
2337.24	98.3167
2342.02	95.9156
2346.8	96.264
2351.58	89.749
2356.35	81.7754
2361.12	87.4706
2365.89	90.4193
2370.65	90.6125
2375.41	96.3388
2380.17	96.5105
2384.92	95.2344
2389.67	93.9187
2394.42	102.303
2399.16	100.91
2403.9	96.7257
2408.64	96.7337
2413.37	99.6913
2418.1	104.371
2422.83	97.6806
2427.55	89.3927
2432.27	95.2711
2436.99	104.049
2441.7	95.8425
2446.41	91.8559
2451.11	102.133
2455.82	95.2658
2460.51	92.6703
2465.21	94.3775
2469.9	98.9645
2474.59	93.4214
2479.28	95.1214
2483.96	98.2642
2488.64	99.9286
2493.32	95.7452
2497.99	101.805
2502.66	107.868
2507.32	99.23
2511.99	97.9012
2516.65	102.446
2521.3	109.986
2525.96	107.199
2530.61	107.362
2535.25	94.2038
2539.89	97.364
2544.53	110.971
2549.17	108.233
2553.8	106.975
2558.43	107.171
2563.06	111.908
2567.68	103.15
2572.3	109.462
2576.92	109.733
2581.53	108.442
2586.14	107.073
2590.75	116.281
2595.35	105.764
2599.96	113.554
2604.55	107.594
2609.15	100.077
2613.74	110.857
2618.33	114.013
2622.91	112.583
2627.49	114.242
2632.07	117.525
2636.64	110.123
2641.22	101.2
2645.78	110.833
2650.35	118.95
2654.91	122.391
2659.47	117.921
2664.03	110.271
2668.58	115.125
2673.13	113.796
2677.67	115.787
2682.22	119.529
2686.76	121.664
2691.29	110.993
2695.83	124.091
2700.36	114.725
2704.89	118.172
2709.41	121.609
2713.93	110.53
2718.45	130.178
2722.96	115.84
2727.47	128.977
2731.98	96.6192
2736.49	114.575
2740.99	117.924
2745.49	121.334
2749.98	124.812
2754.47	121.911
2758.96	112.306
2763.45	117.402
2767.93	115.994
2772.41	129.398
2776.89	114.847
2781.36	118.515
2785.84	123.904
2790.3	120.975
2794.77	118.002
2799.23	109.926
2803.69	123.639
2808.14	122.204
2812.59	122.428
2817.04	119.226
2821.49	129.575
2825.93	121.312
2830.37	124.902
2834.81	119.975
2839.24	126.962
2843.67	115.204
2848.1	120.54
2852.53	117.366
2856.95	122.813
2861.37	126.573
2865.78	137.32
2870.19	106.562
2874.6	134.699
2879.01	128.159
2883.41	121.607
2887.81	125.556
2892.21	111.883
2896.6	112.275
2901	118.016
2905.38	130.848
2909.77	116.951
2914.15	131.537
2918.53	124.662
2922.91	132.166
2927.28	130.734
2931.65	129.314
2936.02	140.515
2940.38	111.722
2944.74	133.765
2949.1	115.725
2953.46	134.146
2957.81	106.918
2962.16	134.531
2966.5	132.919
2970.85	127.651
2975.19	122.371
2979.52	141.036
2983.86	141.347
2988.19	126.887
2992.52	129.099
2996.85	118.293
3001.17	141.092
3005.49	130.32
3009.8	130.754
3014.12	144.374
3018.43	141.103
3022.74	135.9
3027.04	134.393
3031.34	140.467
3035.64	131.182
3039.94	121.845
3044.23	143.232
3048.52	145.408
3052.81	136.007
3057.09	153.653
3061.38	150.051
3065.65	148.376
3069.93	154.464
3074.2	164.472
3078.47	174.53
3082.74	149.456
3087	143.919
3091.27	160.02
3095.52	158.556
3099.78	165.001
3104.03	169.54
3108.28	154.253
3112.53	166.854
3116.77	171.518
3121.01	158.115
3125.25	164.869
3129.49	167.665
3133.72	174.617
3137.95	187.766
3142.18	192.721
3146.4	172.81
3150.62	194.233
3154.84	190.664
3159.06	184.955
3163.27	191.796
3167.48	192.315
3171.69	178.09
3175.89	199.632
3180.09	187.275
3184.29	189.653
3188.49	204.694
3192.68	173.136
3196.87	203.278
3201.06	201.799
3205.24	189.662
3209.42	190.422
3213.6	176.085
3217.78	192.038
3221.95	186.27
3226.12	182.646
3230.29	183.36
3234.45	175.23
3238.61	175.863
3242.77	169.914
3246.93	168.4
3251.08	171.21
3255.23	169.411
3259.38	165.372
3263.53	170.455
3267.67	171.327
3271.81	149.241
3275.95	165.62
3280.08	161.384
3284.21	159.419
3288.34	164.333
3292.47	146.218
3296.59	158.005
3300.71	149.082
3304.83	147.057
3308.95	145.021
3313.06	152.243
3317.17	159.51
3321.27	162.176
3325.38	155.557
3329.48	148.936
3333.58	168.293
3337.67	147.629
3341.77	155.114
3345.86	172.044
3349.95	155.696
3354.03	155.965
3358.11	149.155
3362.19	156.67
3366.27	161.796
3370.34	154.937
3374.42	152.816
3378.48	143.402
3382.55	148.425
3386.61	143.778
3390.68	131.842
3394.73	158.637
3398.79	139.469
3402.84	156.63
3406.89	147.057
3410.94	137.449
3414.98	139.991
3419.03	154.723
3423.06	159.706
3427.1	140.317
3431.14	145.366
3435.17	150.466
3439.2	145.821
3443.22	151.006
3447.25	134.141
3451.27	139.411
3455.28	142.288
3459.3	152.702
3463.31	143.273
3467.32	123.776
3471.33	149.279
3475.34	127.035
3479.34	134.991
3483.34	137.921
3487.33	153.539
3491.33	125.966
3495.32	131.384
3499.31	139.342
3503.3	142.159
3507.28	144.94
3511.26	142.493
3515.24	129.739
3519.22	137.526
3523.19	140.177
3527.16	124.842
3531.13	124.93
3535.1	145.788
3539.06	133.198
3543.02	125.691
3546.98	136.284
3550.93	136.457
3554.89	136.509
3558.84	149.667
3562.78	134.233
3566.73	137.079
3570.67	150.466
3574.61	150.788
3578.55	138.027
3582.48	154.247
3586.41	146.774
3590.35	155.161
3594.27	136.991
3598.2	132.047
3602.12	140.406
3606.04	119.298
3609.95	130.296
3613.87	135.956
3617.78	133.519
3621.69	136.414
3625.6	136.511
3629.5	128.479
3633.4	139.347
3637.3	139.454
3641.2	136.948
3645.09	123.63
3648.98	134.695
3652.87	129.39
3656.76	124.057
3660.64	126.893
3664.53	135.182
3668.4	132.59
3672.28	127.245
3676.16	124.693
3680.03	135.917
3683.9	125.231
3687.76	106.26
3691.63	142.545
3695.49	134.578
3699.35	129.378
3703.2	135.29
3707.06	135.668
3710.91	127.627
3714.76	144.831
3718.6	131.057
3722.45	122.847
3726.29	137.209
3730.13	131.78
3733.97	140.552
3737.8	123.748
3741.63	126.807
3745.46	129.862
3749.29	124.322
3753.11	133.036
3756.93	118.821
3760.75	136.072
3764.57	138.999
3768.39	121.87
3772.2	127.713
3776.01	127.824
3779.81	125.089
3783.62	128.152
3787.42	139.885
3791.22	131.41
3795.02	120.061
3798.81	126.098
3802.61	120.554
3806.4	123.739
3810.18	126.939
3813.97	118.426
3817.75	121.592
3821.53	130.627
3825.31	127.898
3829.09	125.165
3832.86	128.354
3836.63	110.847
3840.4	119.904
3844.17	108.271
3847.93	138.049
3851.69	135.175
3855.45	117.404
3859.21	129.302
3862.96	123.399
3866.71	123.61
3870.46	123.901
3874.21	117.993
3877.95	130.023
3881.69	124.127
3885.44	121.236
3889.17	127.35
3892.91	127.514
3896.64	130.752
3900.37	130.955
3904.1	119.087
3907.82	122.273
3911.55	113.396
3915.27	113.594
3918.99	116.868
3922.7	135.414
3926.42	105.223
3930.13	123.779
3933.84	130.108
3937.54	124.162
3941.25	112.095
3944.95	121.558
3948.65	121.784
3952.35	125.056
3956.04	115.945
3959.73	131.532
3963.42	116.148
3967.11	128.604
3970.8	125.534
3974.48	119.377
3978.16	110.104
3981.84	119.403
3985.52	103.89
3989.19	116.289
3992.86	119.431
3996.53	113.307
3998.37	110.256