File: Data/3-Raman/raw/bu19w-ff1-fi02-v_150 (500nm)_532nm_edge_100%_x100_vis_h50um_15sx2_01.txt
#Acq. time (s)=	15
#Accumulations=	2
#Range (cm-¹)=	100...5000
#Windows=	1
#Auto scanning=	Off
#Autofocus=	Off
#Macrospot=	Off
#AutoExposure=	Off
#Spike filter=	Multiple accum.
#Delay time (s)=	2
#Binning=	1
#Readout mode=	Signal
#DeNoise=	Off
#ICS correction=	On
#Dark correction=	Off
#Inst. Process=	Off
#Detector Gain=	Best Dynamic
#Detector ADC=	50 kHz HS
#Detector temperature (°C)=	-60.09
#Instrument=	LabRAM HR Evol
#Detector=	SIN-EM FIVIS
#Objective=	x100_VIS
#Grating=	150 (500nm)
#ND Filter=	100%
#Laser=	532nm_Edge
#Hole=	49.98
#Temperature=	0
#Range=	Visible
#StageXY=	75x50mm Scan+
#StageZ=	Z motor
#X (µm)=	0
#Y (µm)=	0
#Z (µm)=	-136.1
#Full time(s)=	34
#Project=	21_05_14
#Sample=	BU19w
#Site=
#Title=	BU19w-FF1-FI02-V_150 (500nm)_532nm_Edge_100%_x100_VIS_H50um_15sX2
#Remark=
#Date=	14.05.2021 11:59
#Acquired=	14.05.2021 11:59:42
102.699	12100.6
107.322	10108
111.942	8427.51
116.56	7219.71
121.173	6198.36
125.787	5366.44
130.398	4619.92
135.006	4088.83
139.613	3636.28
144.215	3257.32
148.817	2953.99
153.417	2795.49
158.014	2495.65
162.607	2292.06
167.2	2188.01
171.79	2463.78
176.379	3182.66
180.963	2896.13
185.547	2184.08
190.128	1897.86
194.705	2125.41
199.282	3703.5
203.857	6237.63
208.43	5038.55
212.998	2543.29
217.566	1744.56
222.132	1502.3
226.693	1523.84
231.254	1494.97
235.813	1471.06
240.368	1388.16
244.923	1468.77
249.475	1590.41
254.023	1585.3
258.571	1808.72
263.117	2093.83
267.658	2051.85
272.199	1943.42
276.738	1715.35
281.273	1718.54
285.807	2024.44
290.34	3320.41
294.868	4789.79
299.396	4366.2
303.919	2852.41
308.443	2136.84
312.964	2396.83
317.481	3384.98
321.998	3469.79
326.51	2474.75
331.023	1863.98
335.533	1766.66
340.039	1875.37
344.544	2249.06
349.046	2128.27
353.547	1821.31
358.045	1594.52
362.542	1704.77
367.036	1721.86
371.527	1581.67
376.017	1511.47
380.503	1467.79
384.99	1501.06
389.471	1494.19
393.953	1549.77
398.43	1735.31
402.908	1974.75
407.381	2074.21
411.854	2134.79
416.323	1998.08
420.791	1798.22
425.256	1714.16
429.72	1899.28
434.18	2141.69
438.64	1760.1
443.095	1503.47
447.551	1429.94
452.003	1457.03
456.454	1464.39
460.901	1587.81
465.348	1961.42
469.791	2695.9
474.231	2933.03
478.672	2111.69
483.108	1612.71
487.544	1620.7
491.976	1553.29
496.408	1570.02
500.836	1644.32
505.261	1740.01
509.687	1820.3
514.108	1846.43
518.529	1779.01
522.946	1689.42
527.361	1642.63
531.776	1578.95
536.187	1598.67
540.595	1639.25
545.003	1628.79
549.408	1661.31
553.812	1743.06
558.212	1746.92
562.61	1748.94
567.007	1728.3
571.401	1718.86
575.792	1782.55
580.184	1730.88
584.571	1697.78
588.956	1620.81
593.341	1670.04
597.722	1824.95
602.101	2351.27
606.48	2786.74
610.854	2326.6
615.227	1921.39
619.597	1894.95
623.967	2132.67
628.334	2415.3
632.698	2281.08
637.06	1893.32
641.422	1720.27
645.779	1581.68
650.135	1630.04
654.491	1719.16
658.842	1699.95
663.192	1656.08
667.539	1641.54
671.884	1641.16
676.23	1698.03
680.571	1732.95
684.91	1779.53
689.247	1861.08
693.583	1922.9
697.916	1859.26
702.247	1748.3
706.576	1639.92
710.902	1624.15
715.229	1593.74
719.551	1583.69
723.872	1561.81
728.19	1586.57
732.506	1517.56
736.82	1547.24
741.134	1560.88
745.444	1581.81
749.752	1571.96
754.058	1560.85
758.362	1620.37
762.664	1628.28
766.964	1656.32
771.264	1705.09
775.559	1785.79
779.853	1909.89
784.144	2157.6
788.434	2596.02
792.722	3150.46
797.007	3188.76
801.29	2755.51
805.572	2288.83
809.851	2002.96
814.13	1842.89
818.406	1753.02
822.679	1731.82
826.95	1714.14
831.219	1657.95
835.486	1679.89
839.752	1639.93
844.015	1686.78
848.276	1634.2
852.535	1699.5
856.792	1677.69
861.047	1657.93
865.3	1647.52
869.551	1645.56
873.8	1696.91
878.047	1662.36
882.292	1671.01
886.534	1685.41
890.775	1706.86
895.014	1670.13
899.251	1687.76
903.486	1640.15
907.719	1680.3
911.95	1699.92
916.179	1708.31
920.406	1653.09
924.63	1700.16
928.853	1688.32
933.074	1686.4
937.293	1683.89
941.51	1737.89
945.723	1719.82
949.936	1735.39
954.147	1784.13
958.356	1788.31
962.563	1852.2
966.768	1907.59
970.971	1901.87
975.172	1947.17
979.371	2053.28
983.568	2132.97
987.761	2078.87
991.954	1942.54
996.145	1896.64
1000.33	1846.92
1004.52	1801.55
1008.71	1808.57
1012.89	1829.85
1017.07	1771.2
1021.25	1826.52
1025.43	1828.58
1029.6	1837.09
1033.77	1837.31
1037.95	1845.28
1042.11	1933.3
1046.28	1988.37
1050.45	2013.14
1054.61	2090.07
1058.77	2367.8
1062.93	2833.55
1067.09	3625.98
1071.24	3794.17
1075.4	3174.58
1079.55	2553.26
1083.7	2308.23
1087.85	2297.59
1091.99	2341.12
1096.14	2559.16
1100.28	2967.02
1104.42	3473.31
1108.55	3663.93
1112.69	3233.84
1116.82	2999.52
1120.96	3087.65
1125.09	3334.99
1129.21	3412.25
1133.34	3168.14
1137.46	3008.38
1141.59	3120.77
1145.71	3264.02
1149.83	3277.87
1153.94	3005.04
1158.06	2635.63
1162.17	2477.59
1166.28	2597.76
1170.39	2861.18
1174.5	3045.17
1178.6	2907.47
1182.7	2516.95
1186.8	2316.54
1190.9	2217.6
1195	2113.28
1199.1	2061.76
1203.19	2062.08
1207.28	2062.41
1211.37	2129.61
1215.46	2134
1219.54	2021.11
1223.63	2091.55
1227.71	2055.42
1231.79	2109.18
1235.87	2207.45
1239.95	2281.72
1244.02	2299.34
1248.09	2366.52
1252.16	2493.25
1256.23	2632.55
1260.3	2636.42
1264.36	2873.92
1268.43	2896.16
1272.49	2552.38
1276.55	2503.97
1280.6	2879.51
1284.66	7618.85
1288.71	9179.62
1292.76	3800.6
1296.81	2542.72
1300.86	2336.75
1304.91	2303.66
1308.95	2243.44
1312.99	2225.78
1317.03	2210.4
1321.07	2222.95
1325.11	2134.73
1329.14	2173.68
1333.18	2196.61
1337.21	2156.91
1341.24	2187.05
1345.26	2188.99
1349.29	2208.89
1353.31	2207.93
1357.33	2258.55
1361.35	2258.43
1365.37	2283.7
1369.39	2407.88
1373.4	2601.46
1377.41	2561.35
1381.43	2672.84
1385.43	3949.85
1389.44	14131
1393.45	11650
1397.45	3834.92
1401.45	2662.51
1405.45	2608.33
1409.45	2944.79
1413.44	3260.09
1417.44	2551.05
1421.43	2287.54
1425.42	2230.5
1429.41	2207.28
1433.39	2134.29
1437.38	2098.49
1441.36	2105.21
1445.34	2058.19
1449.32	2056.51
1453.3	2034.68
1457.27	2038.34
1461.24	2075.84
1465.22	2038.08
1469.19	2038.93
1473.15	2047.69
1477.12	2044.23
1481.09	2029.89
1485.05	2018.36
1489.01	2013.7
1492.97	1999.47
1496.93	2021.37
1500.88	2017.31
1504.83	2010.79
1508.79	2000.82
1512.74	2051.05
1516.68	2033.52
1520.63	2029.78
1524.57	1985.43
1528.52	2018.88
1532.46	2108.71
1536.4	2072.53
1540.33	2043.21
1544.27	2037.13
1548.2	2052.38
1552.14	2029.73
1556.07	2097.77
1559.99	2025.15
1563.92	2042.37
1567.84	2070.98
1571.77	2084.97
1575.69	2042.92
1579.61	2053.9
1583.52	2046.45
1587.44	2078.37
1591.35	2056.34
1595.27	2048.74
1599.18	2084.47
1603.09	2075.31
1606.99	2085.55
1610.9	2059.41
1614.8	2028.76
1618.7	2093.03
1622.6	2071.13
1626.5	2124.3
1630.39	2086.01
1634.29	2096.91
1638.18	2115.53
1642.07	2115.68
1645.96	2110.33
1649.85	2113.74
1653.73	2137.27
1657.62	2093.4
1661.5	2073.3
1665.38	2084.52
1669.26	2092.46
1673.13	2113.4
1677.01	2094.38
1680.88	2082.06
1684.75	2103.13
1688.62	2099.89
1692.49	2069.46
1696.35	2110.49
1700.22	2127.12
1704.08	2106.08
1707.94	2069.48
1711.8	2100.17
1715.66	2119.49
1719.51	2109.52
1723.37	2149.46
1727.22	2110.86
1731.07	2120.22
1734.92	2122.99
1738.76	2080.59
1742.61	2125.94
1746.45	2110.52
1750.29	2118.57
1754.13	2158.14
1757.97	2094.5
1761.81	2128.35
1765.64	2143.71
1769.47	2136.29
1773.31	2112.53
1777.14	2106.76
1780.96	2154.75
1784.79	2145.19
1788.61	2208.78
1792.43	2136.67
1796.25	2155.4
1800.07	2140.42
1803.89	2163.18
1807.71	2146.33
1811.52	2129.08
1815.33	2114.88
1819.14	2157.47
1822.95	2179.82
1826.76	2131.85
1830.56	2138
1834.37	2155.95
1838.17	2182.94
1841.97	2172.78
1845.77	2148.5
1849.56	2156.67
1853.36	2183.6
1857.15	2152.9
1860.94	2213.14
1864.73	2169.11
1868.52	2129.23
1872.31	2145.39
1876.09	2194.11
1879.87	2166.7
1883.66	2179.47
1887.43	2181.68
1891.21	2183.31
1894.99	2193.97
1898.76	2179.46
1902.53	2174.85
1906.31	2150.23
1910.08	2131.67
1913.84	2230.7
1917.61	2187.61
1921.37	2195.16
1925.14	2232.65
1928.9	2172.08
1932.66	2140.17
1936.41	2196.68
1940.17	2243.99
1943.92	2172.98
1947.68	2203.93
1951.43	2215.33
1955.18	2185.32
1958.92	2198.32
1962.67	2220.52
1966.41	2207.71
1970.16	2234.12
1973.9	2199.14
1977.64	2203.1
1981.37	2202.98
1985.11	2159.53
1988.84	2209.24
1992.57	2183.8
1996.31	2182.25
2000.03	2162.81
2003.76	2219.58
2007.49	2154.44
2011.21	2236.75
2014.93	2197.13
2018.65	2177.5
2022.37	2150.63
2026.09	2244.92
2029.81	2202.33
2033.52	2237.85
2037.23	2194.02
2040.94	2196.09
2044.65	2187.76
2048.36	2229.35
2052.07	2229.12
2055.77	2213.71
2059.47	2227.6
2063.17	2231.26
2066.87	2192.83
2070.57	2229.97
2074.27	2220.17
2077.96	2237.42
2081.65	2202.71
2085.34	2259.44
2089.03	2202.72
2092.72	2263.27
2096.41	2261.1
2100.09	2213.15
2103.77	2216.91
2107.46	2221.2
2111.14	2127.66
2114.81	2188.4
2118.49	2212.2
2122.16	2269.43
2125.84	2222.53
2129.51	2273.48
2133.18	2222.52
2136.85	2219.41
2140.51	2256.45
2144.18	2280.26
2147.84	2200.1
2151.5	2204.63
2155.16	2208.35
2158.82	2235.96
2162.48	2243.8
2166.13	2283.89
2169.79	2196.09
2173.44	2242.27
2177.09	2219.4
2180.74	2244.07
2184.38	2213.26
2188.03	2216.25
2191.67	2265.52
2195.32	2251.03
2198.96	2249.48
2202.6	2162.47
2206.23	2304.07
2209.87	2225.88
2213.5	2281.46
2217.14	2219.78
2220.77	2303.23
2224.4	2288.44
2228.03	2245.79
2231.65	2260.49
2235.28	2305.83
2238.9	2271.49
2242.52	2224.02
2246.14	2273.03
2249.76	2318.72
2253.38	2232.36
2256.99	2248.54
2260.6	2223.38
2264.21	2198.06
2267.82	2258.64
2271.44	2277.08
2275.04	2231.49
2278.65	2237.74
2282.25	2224
2285.85	2257.97
2289.45	2261.32
2293.05	2238.09
2296.65	2281.26
2300.25	2261.78
2303.84	2228.49
2307.43	2249.77
2311.02	2230.93
2314.62	2239.21
2318.2	2263.14
2321.79	2261.46
2325.38	2277.69
2328.96	2630.24
2332.54	3039.87
2336.12	2490.06
2339.7	2266.04
2343.28	2232.17
2346.85	2253.46
2350.43	2217.5
2354	2231.03
2357.57	2218.27
2361.14	2217.55
2364.71	2179.78
2368.27	2251.85
2371.84	2243.45
2375.4	2235.77
2378.96	2169.41
2382.52	2207.5
2386.08	2228.3
2389.64	2204.51
2393.19	2232.69
2396.75	2191.01
2400.3	2193.41
2403.85	2207.62
2407.4	2230.51
2410.95	2249.77
2414.49	2260.28
2418.04	2222.57
2421.58	2250.54
2425.12	2213.69
2428.66	2236.36
2432.2	2217.89
2435.74	2203.41
2439.27	2203.9
2442.81	2212.91
2446.34	2245.57
2449.87	2230.14
2453.4	2228.11
2456.93	2241.95
2460.45	2218.99
2463.98	2185.73
2467.5	2146.49
2471.02	2212.51
2474.54	2205.78
2478.06	2200.82
2481.58	2188.87
2485.09	2191.69
2488.61	2219.85
2492.12	2204.08
2495.63	2191.51
2499.14	2200.85
2502.65	2144.84
2506.15	2172.68
2509.66	2171.36
2513.16	2206.75
2516.66	2172.89
2520.16	2178.87
2523.66	2180.44
2527.16	2199.71
2530.66	2198
2534.15	2178.48
2537.64	2177.85
2541.13	2201.22
2544.62	2207.3
2548.11	2208.98
2551.6	2216.54
2555.08	2216.13
2558.57	2179.55
2562.05	2200.39
2565.53	2182.95
2569.01	2215.55
2572.49	2199.12
2575.96	2190.59
2579.44	2201.04
2582.91	2204.08
2586.38	2232.43
2589.85	2163.79
2593.32	2208.3
2596.79	2186.82
2600.25	2168.28
2603.72	2188.93
2607.18	2158.13
2610.64	2176.81
2614.1	2184.94
2617.56	2190.35
2621.02	2166.48
2624.47	2198.67
2627.92	2117.15
2631.38	2150.43
2634.83	2130.22
2638.28	2156.6
2641.72	2194.81
2645.17	2198.43
2648.61	2131.03
2652.06	2125.17
2655.5	2132.11
2658.94	2192.8
2662.38	2160.24
2665.82	2101.42
2669.25	2162.13
2672.69	2104.57
2676.12	2140.3
2679.55	2150.13
2682.98	2159.52
2686.41	2168.34
2689.84	2144.04
2693.26	2178.74
2696.69	2191.49
2700.11	2149.7
2703.53	2147.39
2706.95	2133.78
2710.37	2119.8
2713.79	2133.22
2717.2	2109.84
2720.62	2163.23
2724.03	2133.79
2727.44	2143.78
2730.85	2135.88
2734.26	2144.8
2737.66	2130.32
2741.07	2137.01
2744.47	2178.02
2747.87	2101.6
2751.28	2107.81
2754.67	2099.45
2758.07	2144.12
2761.47	2125.07
2764.86	2109.48
2768.26	2116.05
2771.65	2136.63
2775.04	2115.39
2778.43	2099.47
2781.82	2135.13
2785.2	2079.4
2788.59	2147.81
2791.97	2081.58
2795.35	2097.33
2798.73	2101.32
2802.11	2125.01
2805.49	2108.37
2808.87	2130.94
2812.24	2095.39
2815.62	2126.04
2818.99	2119.6
2822.36	2122.85
2825.73	2110.39
2829.1	2114.94
2832.46	2088.22
2835.83	2072.1
2839.19	2148.6
2842.55	2114.68
2845.91	2041.29
2849.27	2089.13
2852.63	2154.34
2855.99	2096.49
2859.34	2125.91
2862.69	2084.27
2866.05	2094.23
2869.4	2101.23
2872.75	2066.8
2876.09	2070.82
2879.44	2103.08
2882.78	2106.94
2886.13	2065.34
2889.47	2035.16
2892.81	2054.41
2896.15	2103.66
2899.49	2126.13
2902.82	2111.39
2906.16	2065.26
2909.49	2070.93
2912.82	2081.33
2916.16	2084.71
2919.49	2035.9
2922.81	2042.86
2926.14	2062.63
2929.46	2090.78
2932.79	2069.32
2936.11	2064.87
2939.43	2065.14
2942.75	2017.4
2946.07	2089.37
2949.39	2036.12
2952.7	2042.05
2956.02	2100.88
2959.33	2069.9
2962.64	2083.91
2965.95	2031.79
2969.26	1973.01
2972.57	2076.12
2975.87	2065.61
2979.17	2048.08
2982.48	2033.47
2985.78	2071.58
2989.08	2044.04
2992.38	1997.77
2995.68	2039.97
2998.97	2047.44
3002.27	2058.56
3005.56	2061.43
3008.85	2038.99
3012.14	2007.2
3015.43	2012.08
3018.72	2054.65
3022	2002.88
3025.29	2035.14
3028.57	2081.59
3031.85	2014.58
3035.14	2010.75
3038.41	2041.94
3041.69	2047.62
3044.97	2001.3
3048.24	2024.01
3051.52	2011.8
3054.79	1986.24
3058.06	2058.13
3061.33	2023.29
3064.6	2055.05
3067.87	1998.27
3071.13	2031.95
3074.4	1993.65
3077.66	2010.37
3080.92	2012.09
3084.18	2019.91
3087.44	2003.41
3090.7	2008.25
3093.95	2020.57
3097.21	1998.93
3100.46	1998.22
3103.71	1983.86
3106.96	2025.75
3110.21	2069.92
3113.46	2005.51
3116.71	1975.46
3119.95	2007.31
3123.2	1989.62
3126.44	2030.94
3129.68	1971.27
3132.92	1987.8
3136.16	2031.87
3139.4	1982.48
3142.63	2004.58
3145.87	1971.47
3149.1	1990.89
3152.33	2006.43
3155.56	2059.21
3158.79	2024.19
3162.02	1989.15
3165.25	2003.6
3168.47	2027.43
3171.69	1981.51
3174.92	1997.45
3178.14	2041.94
3181.36	2031.14
3184.58	2008.72
3187.79	2051.03
3191.01	2025.64
3194.22	1997.38
3197.43	2015.75
3200.65	2064.64
3203.86	2035.52
3207.07	2031.23
3210.27	2009.95
3213.48	2001.2
3216.69	1990.58
3219.89	2038.02
3223.09	2033.34
3226.29	2005.88
3229.49	2020.46
3232.69	2044.41
3235.89	2032.55
3239.08	2067.53
3242.28	2015.04
3245.47	2037.78
3248.66	2052.13
3251.85	2052.29
3255.04	2020.02
3258.23	2028.54
3261.42	2007.17
3264.6	2073.38
3267.79	2007.53
3270.97	2032.27
3274.15	2036
3277.33	2019.35
3280.51	2041.4
3283.68	2036.7
3286.86	2054.71
3290.04	2018.5
3293.21	2040.42
3296.38	2018.42
3299.55	2071.23
3302.72	2067.49
3305.89	1976.94
3309.06	2054.44
3312.22	2064.21
3315.39	2035
3318.55	2088.23
3321.71	1984.13
3324.87	2011.77
3328.03	1997.79
3331.19	2014.18
3334.34	2075.09
3337.5	2018.15
3340.65	2059.37
3343.81	2079.25
3346.96	2068.63
3350.11	2039.2
3353.25	2087.26
3356.4	2034.58
3359.55	2066.98
3362.69	2040.07
3365.84	2053.81
3368.98	2069.5
3372.12	2064.68
3375.26	2103.41
3378.4	2082.8
3381.53	2058.27
3384.67	2093.46
3387.8	2056.8
3390.94	2025.89
3394.07	2076.54
3397.2	2145.33
3400.33	2133.97
3403.46	2158.88
3406.58	2191.6
3409.71	2188.31
3412.83	2270.22
3415.96	2346.32
3419.08	2479.62
3422.2	2746.21
3425.32	3440.19
3428.44	5299.92
3431.55	9167.22
3434.67	10720.5
3437.78	7097.27
3440.89	4117.03
3444	2959.37
3447.12	2521.49
3450.22	2336.14
3453.33	2250.03
3456.44	2121.81
3459.54	2104.98
3462.65	2139.4
3465.75	2086.24
3468.85	2047.71
3471.95	2099.86
3475.05	2063.14
3478.15	2054.96
3481.24	2008.08
3484.34	2065.29
3487.43	2048.97
3490.53	2089.02
3493.62	2084.77
3496.71	2165.19
3499.79	2185.39
3502.88	2285.24
3505.97	2402.13
3509.05	2542.57
3512.14	2738.01
3515.22	2904.7
3518.3	2884.13
3521.38	2753.39
3524.46	2487.48
3527.54	2337.69
3530.61	2226.16
3533.69	2109.63
3536.76	2058.82
3539.83	2021.73
3542.9	1960.09
3545.97	1951.19
3549.04	1966.57
3552.11	1929.57
3555.18	1873.91
3558.24	1870.47
3561.3	1897.85
3564.37	1845.49
3567.43	1813.1
3570.49	1855.28
3573.55	1847.95
3576.61	1820.62
3579.66	1825.39
3582.72	1802.48
3585.77	1815.56
3588.82	1832.26
3591.87	1796.71
3594.92	1792.33
3597.97	1784.11
3601.02	1794.7
3604.07	1762.54
3607.11	1727.52
3610.16	1769.03
3613.2	1754.68
3616.24	1808.35
3619.28	1736.55
3622.32	1740.33
3625.36	1744.21
3628.39	1715.08
3631.43	1728.22
3634.46	1706.81
3637.5	1679.13
3640.53	1726.9
3643.56	1719.6
3646.59	1716.73
3649.62	1731.02
3652.64	1720.83
3655.67	1705.43
3658.69	1747.49
3661.72	1649.96
3664.74	1699.56
3667.76	1671.97
3670.78	1694.51
3673.79	1641.67
3676.81	1660.64
3679.83	1669.2
3682.84	1630.47
3685.86	1657.03
3688.87	1615.5
3691.88	1645.02
3694.89	1588.05
3697.9	1635.52
3700.91	1643.29
3703.91	1637.77
3706.92	1600.74
3709.92	1615.83
3712.92	1619.3
3715.92	1608.56
3718.92	1607.2
3721.92	1632.36
3724.92	1624.04
3727.92	1603.22
3730.91	1607.01
3733.91	1623.96
3736.9	1594.1
3739.89	1583.11
3742.88	1603.37
3745.87	1581.62
3748.86	1617.72
3751.85	1576.8
3754.83	1569.17
3757.82	1546.37
3760.8	1575.6
3763.78	1599.1
3766.76	1587.64
3769.74	1560.26
3772.72	1551
3775.7	1571.14
3778.67	1557.36
3781.65	1575.74
3784.62	1558.3
3787.6	1544.73
3790.57	1567.25
3793.54	1574.83
3796.51	1526.81
3799.47	1566.77
3802.44	1552.09
3805.41	1511.95
3808.37	1532.35
3811.33	1518.79
3814.3	1530.78
3817.26	1535.28
3820.22	1533.19
3823.18	1517.95
3826.13	1524.53
3829.09	1528.24
3832.04	1537.78
3835	1510.4
3837.95	1524.81
3840.9	1530.67
3843.85	1543.22
3846.8	1493.94
3849.75	1496.14
3852.69	1558.49
3855.64	1491.11
3858.58	1482.89
3861.53	1506.15
3864.47	1482.53
3867.41	1496.14
3870.35	1513.54
3873.29	1479.1
3876.22	1485.75
3879.16	1495.14
3882.1	1512.99
3885.03	1474.97
3887.96	1475.32
3890.89	1473.68
3893.82	1486.31
3896.75	1490.09
3899.68	1464.98
3902.61	1500.22
3905.53	1518.3
3908.46	1467.1
3911.38	1484.01
3914.3	1479.6
3917.23	1466.82
3920.15	1470.17
3923.06	1426.31
3925.98	1453.32
3928.9	1444.68
3931.81	1466.02
3934.73	1420.61
3937.64	1442.59
3940.55	1447.24
3943.46	1434.68
3946.37	1458.63
3949.28	1403.25
3952.19	1472.4
3955.09	1427.72
3958	1426.21
3960.9	1413.27
3963.8	1430.12
3966.71	1459.53
3969.61	1470.8
3972.51	1459.98
3975.4	1445.24
3978.3	1442.86
3981.2	1434.68
3984.09	1405.26
3986.99	1398.91
3989.88	1404.81
3992.77	1424.43
3995.66	1413.27
3998.55	1411.8
4001.43	1414.2
4004.32	1434.01
4007.21	1420.14
4010.09	1391.78
4012.98	1417.42
4015.86	1375.54
4018.74	1410.84
4021.62	1407.54
4024.5	1374.32
4027.37	1380.7
4030.25	1404.53
4033.13	1420.65
4036	1397.17
4038.87	1401.77
4041.75	1384.83
4044.62	1409.52
4047.49	1398.45
4050.35	1387.45
4053.22	1392.07
4056.09	1374.41
4058.95	1342.07
4061.82	1387.44
4064.68	1383.27
4067.54	1357.67
4070.4	1364.15
4073.26	1358.93
4076.12	1376.09
4078.98	1393.26
4081.83	1350
4084.69	1333.98
4087.54	1358.89
4090.4	1370.21
4093.25	1354.19
4096.1	1305.88
4098.95	1364.13
4101.8	1344.13
4104.64	1349.43
4107.49	1322.38
4110.33	1324.61
4113.18	1353.1
4116.02	1339.35
4118.86	1347.05
4121.7	1324.53
4124.54	1360.84
4127.38	1303.38
4130.22	1343.15
4133.05	1344.05
4135.89	1330.5
4138.72	1314.34
4141.56	1306.57
4144.39	1284.46
4147.22	1320.19
4150.05	1300.98
4152.88	1310.7
4155.7	1279.75
4158.53	1325.17
4161.36	1281.96
4164.18	1278.86
4167	1328.6
4169.82	1304.09
4172.65	1287.45
4175.46	1308.97
4178.28	1287.51
4181.1	1310.15
4183.92	1317.2
4186.73	1302.78
4189.55	1268.91
4192.36	1253.79
4195.17	1296.62
4197.98	1291.52
4200.79	1290.32
4203.6	1319.56
4206.41	1299.71
4209.21	1286.71
4212.02	1293.32
4214.83	1313.18
4217.63	1320.63
4220.43	1263.79
4223.23	1281.74
4226.03	1274.07
4228.83	1284.35
4231.63	1309.59
4234.42	1255.71
4237.22	1285.12
4240.01	1264.94
4242.81	1274.62
4245.6	1255.42
4248.39	1268.98
4251.18	1276.51
4253.97	1252.96
4256.76	1289.38
4259.55	1262.76
4262.33	1276.28
4265.12	1236.64
4267.9	1252.27
4270.68	1217.53
4273.47	1281.38
4276.25	1228.03
4279.03	1240.14
4281.8	1232.95
4284.58	1241.78
4287.36	1217.07
4290.13	1251.99
4292.91	1250.56
4295.68	1197.59
4298.45	1222.61
4301.22	1225.27
4303.99	1219.8
4306.76	1260.07
4309.53	1239.51
4312.3	1215.8
4315.06	1218.35
4317.83	1205.55
4320.59	1204.85
4323.35	1217.32
4326.11	1216.55
4328.87	1173.97
4331.63	1208.77
4334.39	1202.8
4337.15	1197.92
4339.9	1181.95
4342.66	1191.52
4345.41	1237.95
4348.17	1167.1
4350.92	1206.66
4353.67	1181.95
4356.42	1169.4
4359.17	1166.01
4361.91	1182.1
4364.66	1190.02
4367.41	1162.07
4370.15	1179.17
4372.89	1160.23
4375.63	1173.05
4378.38	1143.7
4381.12	1157.53
4383.86	1168.48
4386.59	1192.19
4389.33	1146.21
4392.07	1153.33
4394.8	1144.86
4397.53	1152.42
4400.27	1151.69
4403	1159.22
4405.73	1147.11
4408.46	1165.07
4411.19	1127.72
4413.92	1160
4416.64	1150.33
4419.37	1131.18
4422.09	1165.41
4424.82	1171.5
4427.54	1137.88
4430.26	1174.28
4432.98	1158.35
4435.7	1126.62
4438.42	1129.35
4441.13	1137.29
4443.85	1134.73
4446.57	1127.93
4449.28	1112.66
4451.99	1122.54
4454.71	1101.89
4457.42	1127.39
4460.13	1120.39
4462.83	1130.27
4465.54	1131.76
4468.25	1097.51
4470.95	1145.47
4473.66	1097.69
4476.36	1129.03
4479.07	1111.94
4481.77	1136.05
4484.47	1135.82
4487.17	1087.95
4489.87	1119.23
4492.56	1121.51
4495.26	1103.98
4497.96	1094.92
4500.65	1068.7
4503.34	1088.18
4506.04	1089.7
4508.73	1094.4
4511.42	1086.38
4514.11	1096.46
4516.8	1076.79
4519.48	1125.3
4522.17	1083.47
4524.85	1086.24
4527.54	1072.01
4530.22	1070.58
4532.9	1064.93
4535.58	1036.85
4538.27	1077.21
4540.94	1075.91
4543.62	1042.56
4546.3	1080.89
4548.98	1034.67
4551.65	1010.05
4554.33	1031.61
4557	1026.71
4559.67	1049.98
4562.34	1054.11
4565.01	1056.69
4567.68	1024.25
4570.35	1026.3
4573.02	1055.59
4575.68	1020.36
4578.35	1036.45
4581.01	1018.5
4583.67	1060.64
4586.34	1041.75
4589	999.802
4591.66	1042.87
4594.31	1007.7
4596.97	1008.25
4599.63	1052.81
4602.29	1008.87
4604.94	1037.17
4607.59	997.565
4610.25	1010.54
4612.9	990.546
4615.55	1015.63
4618.2	1014.44
4620.85	1029.76
4623.5	968.929
4626.14	984.072
4628.79	1003.69
4631.43	995.531
4634.08	994.988
4636.72	1011.07
4639.36	994.972
4642	1000.12
4644.64	976.715
4647.28	1000.13
4649.92	1009.44
4652.56	997
4655.19	980.122
4657.83	978.711
4660.46	986.473
4663.1	1004.33
4665.73	981.515
4668.36	1006.95
4670.99	959.566
4673.62	1002.92
4676.24	961.053
4678.87	974.106
4681.5	952.34
4684.12	971.036
4686.75	976.236
4689.37	964.632
4691.99	958.533
4694.61	963.67
4697.23	965.453
4699.85	972.9
4702.47	965.542
4705.09	970.593
4707.7	956.372
4710.32	978.334
4712.93	972
4715.55	961.038
4718.16	961.432
4720.77	967.337
4723.38	970.002
4725.99	933.054
4728.6	983.47
4731.21	961.269
4733.81	884.505
4736.42	918.965
4739.02	940.965
4741.63	977.636
4744.23	917.638
4746.83	950.697
4749.43	950.803
4752.03	955.465
4754.63	907.716
4757.23	945.414
4759.82	935.409
4762.42	915.152
4765.01	909.854
4767.61	932.202
4770.2	928.028
4772.79	931.853
4775.38	927.713
4777.97	940.681
4780.56	896.524
4783.15	916.371
4785.74	895.056
4788.32	889.76
4790.91	909.713
4793.49	897.601
4796.07	894.756
4798.66	912.618
4801.24	889.237
4803.82	878.556
4806.4	899.049
4808.98	902.259
4811.55	879.026
4814.13	885.779
4816.71	886.887
4819.28	887.98
4821.85	922.691
4824.43	913.422
4827	892.452
4829.57	882.048
4832.14	885.574
4834.71	898.561
4837.28	849.775
4839.84	893.305
4842.41	877.022
4844.97	875.848
4847.54	829.92
4850.1	885.629
4852.66	853.856
4855.22	838.637
4857.78	859.917
4860.34	881.081
4862.9	888.927
4865.46	839.873
4868.01	844.401
4870.57	875.962
4873.12	871.845
4875.68	859.435
4878.23	865.957
4880.78	875.979
4883.33	814.687
4885.88	850.845
4888.43	846.623
4890.98	804.252
4893.53	827.336
4896.07	845.633
4898.62	862.758
4901.16	841.674
4903.7	850.457
4906.25	837.621
4908.79	839.036
4911.33	859.434
4913.87	843.93
4916.41	830.838
4918.94	845.266
4921.48	805.928
4924.02	841.906
4926.55	871.877
4929.08	815.878
4931.62	812.665
4934.15	809.445
4936.68	802.574
4939.21	797.875
4941.74	801.581
4944.27	797.14
4946.79	802.299
4949.32	814.682
4951.85	787.463
4954.37	804.662
4956.9	814.79
4959.42	828.605
4961.94	814.952
4964.46	793.031
4966.98	791.466
4969.5	807.864
4972.02	815.822
4974.53	818.937
4977.05	786.991
4979.57	819.191
4982.08	800.562
4984.59	792.842
4987.1	779.05
4989.62	817.488
4992.13	779.315
4994.64	798.388
4997.15	771.255
4999.65	797.784