File: Data/3-Raman/raw/bu19(2)w-a-ff2-fi01-v_1800 (450-850nm)_532nm_edge_100%_x100_vis_lwd_h100um_30sx2_01.txt
#Acq. time (s)=	30
#Accumulations=	2
#Range (cm-¹)=	1200...2365
#Windows=	3
#Auto scanning=	Off
#Autofocus=	Off
#Macrospot=	Off
#AutoExposure=	Off
#Spike filter=	Multiple accum.
#Delay time (s)=	2
#Binning=	1
#Readout mode=	Signal
#DeNoise=	Off
#ICS correction=	On
#Dark correction=	Off
#Inst. Process=	Off
#Detector Gain=	Best Dynamic
#Detector ADC=	50 kHz HS
#Detector temperature (°C)=	-60.09
#Instrument=	LabRAM HR Evol
#Detector=	SIN-EM FIVIS
#Objective=	x100_VIS_LWD
#Grating=	1800 (450-850nm)
#ND Filter=	100%
#Laser=	532nm_Edge
#Hole=	100.021
#Temperature=	0
#Range=	Visible
#StageXY=	75x50mm Scan+
#StageZ=	Z motor
#X (µm)=	0
#Y (µm)=	0
#Z (µm)=	12.5
#Full time(mm:ss)=	3:23
#Project=	21_11_26
#Sample=	BU19(2)w
#Site=
#Title=	BU19(2)w-A-FF2-FI01-V_1800 (450-850nm)_532nm_Edge_100%_x100_VIS_LWD_H100um_30sX2
#Remark=
#Date=	26.11.2021 14:18
#Acquired=	26.11.2021 14:18:21
1202.72	97.3254
1203.84	100.579
1204.95	96.1933
1206.06	107.848
1207.17	108.702
1208.28	102.151
1209.39	96.6842
1210.5	99.8322
1211.61	103.935
1212.72	96.3194
1213.83	102.605
1214.94	101.514
1216.05	95.0945
1217.16	96.0056
1218.27	91.6367
1219.38	103.237
1220.49	95.7538
1221.6	88.2853
1222.71	92.3898
1223.81	91.1474
1224.92	98.4189
1226.03	96.299
1227.14	84.6544
1228.25	103.407
1229.35	92.6398
1230.46	94.9842
1231.57	98.9055
1232.67	96.7904
1233.78	105.159
1234.89	99.9318
1235.99	93.6553
1237.1	102.029
1238.2	103.984
1239.31	102.798
1240.41	100.652
1241.52	101.697
1242.62	105.837
1243.73	107.953
1244.83	110.034
1245.94	115.155
1247.04	121.358
1248.14	121.315
1249.25	116.003
1250.35	113.895
1251.45	116.914
1252.56	123.08
1253.66	124.024
1254.76	131.389
1255.87	138.706
1256.97	151.256
1258.07	181.489
1259.17	166.77
1260.27	177.308
1261.37	258.471
1262.48	359.391
1263.58	378.229
1264.68	257.033
1265.78	186.752
1266.88	166.885
1267.98	152.389
1269.08	169.339
1270.18	158.851
1271.28	150.315
1272.38	163.923
1273.47	168.296
1274.57	174.738
1275.67	174.745
1276.77	178.014
1277.87	213.871
1278.97	280.308
1280.07	426.557
1281.16	1027.18
1282.26	3287.8
1283.36	5071.79
1284.45	1899.26
1285.55	536.56
1286.65	292.17
1287.75	222.562
1288.84	203.546
1289.94	189.963
1291.03	173.148
1292.13	164.688
1293.22	147.814
1294.32	146.927
1295.42	151.166
1296.51	143.017
1297.61	141.926
1298.7	149.223
1299.79	140.684
1300.89	134.377
1301.98	125.933
1303.08	129.122
1304.17	117.442
1305.26	118.472
1306.35	120.464
1307.45	119.371
1308.54	118.31
1309.63	113.056
1310.73	108.839
1311.82	104.619
1312.91	110.991
1314	109.885
1315.09	106.714
1316.18	113.092
1317.28	103.554
1318.37	104.628
1319.46	103.562
1320.55	109.888
1321.64	114.018
1322.73	106.516
1323.82	109.626
1324.91	102.236
1326	100.046
1327.09	123.009
1328.18	110.56
1329.27	115.955
1330.35	105.375
1331.44	106.325
1332.53	106.155
1333.62	108.101
1334.71	112.163
1335.79	115.202
1336.88	115.115
1337.97	107.717
1339.06	118.089
1340.14	104.457
1341.23	108.639
1342.32	100.208
1343.4	102.196
1344.49	102.172
1345.58	111.516
1346.66	109.256
1347.75	107.023
1348.83	108
1349.92	113.114
1351	110.928
1352.09	108.75
1353.17	111.926
1354.25	117.233
1355.34	113.825
1356.42	116.915
1357.51	118.919
1358.59	120.903
1359.67	129.099
1360.76	114.454
1361.84	120.617
1362.92	131.946
1364	150.619
1365.09	149.561
1366.17	143.207
1367.25	139.934
1368.33	210.202
1369.41	273.314
1370.5	136.783
1371.58	149.044
1372.66	150.873
1373.74	155.906
1374.82	167.174
1375.9	167.154
1376.98	184.567
1378.06	183.456
1379.14	207.454
1380.22	233.094
1381.3	266.533
1382.38	321.711
1383.46	436.125
1384.54	801.875
1385.61	2556.41
1386.69	10937.2
1387.77	4423.26
1388.85	909.082
1389.93	429.308
1391	304.576
1392.08	229.523
1393.16	210.901
1394.23	188.291
1395.31	170.87
1396.39	166.815
1397.46	166.714
1398.54	156.434
1399.62	156.486
1400.69	161.645
1401.77	169.899
1402.84	159.889
1403.92	176.452
1404.99	202.988
1406.07	271.535
1407.14	406.74
1408.22	641.633
1409.29	466.433
1410.37	238.796
1411.44	170.904
1412.51	129.874
1413.59	116.864
1414.66	119.788
1415.73	102.376
1416.81	96.2329
1417.88	104.484
1418.95	107.573
1420.02	102.395
1421.1	98.1914
1422.17	90.9971
1423.24	106.61
1424.31	105.213
1425.38	99.0506
1426.45	86.7547
1427.52	86.6528
1428.59	87.5783
1429.67	85.5419
1430.74	80.4788
1431.81	87.7553
1432.87	82.5626
1433.95	69.1066
1435.01	81.4133
1436.08	66.0287
1437.15	86.481
1438.22	75.1786
1439.29	77.2403
1440.36	67.0326
1441.43	72.1652
1442.49	70.0922
1443.56	64.9472
1444.63	78.2465
1445.7	68.0361
1446.77	59.7939
1447.83	63.8578
1448.9	65.9153
1449.97	60.7634
1451.03	70.9686
1452.1	65.8056
1453.17	63.7393
1454.23	58.612
1455.3	62.6923
1456.36	66.7934
1457.43	60.6039
1458.49	55.4574
1459.56	68.7728
1460.62	67.7241
1461.69	61.535
1462.75	56.36
1463.82	56.2931
1464.88	62.4856
1465.94	54.1157
1467.01	52.0428
1468.07	58.1401
1469.13	56.0776
1470.2	55.0061
1471.26	47.8303
1472.32	57.9715
1473.39	48.7839
1474.45	52.8152
1475.51	60.9531
1476.57	56.8465
1477.63	52.7349
1478.69	55.7499
1479.76	48.5855
1480.82	50.5455
1481.88	55.5843
1482.94	57.6422
1484	51.5468
1485.06	56.4867
1486.12	54.4287
1487.18	58.474
1488.24	46.2754
1489.3	47.2328
1490.36	49.228
1491.42	47.1635
1492.48	54.2215
1493.53	51.1674
1494.59	51.1515
1495.65	56.1675
1496.71	53.0669
1497.77	51.0184
1498.82	51.0013
1499.88	49.9901
1500.94	53.0087
1502	49.9446
1503.05	42.8486
1504.11	52.894
1505.17	44.8182
1506.22	56.8509
1507.28	53.819
1508.34	50.7822
1509.39	51.7764
1510.45	49.7552
1511.5	52.7138
1512.56	56.6101
1513.61	52.5137
1514.67	48.517
1515.72	52.4723
1516.78	55.4152
1517.83	53.3864
1518.88	56.4028
1519.94	54.3985
1520.99	52.3705
1522.05	48.353
1523.1	52.3284
1524.15	48.2434
1525.2	52.2124
1526.26	47.2123
1527.31	46.2226
1528.36	52.2016
1529.41	45.1551
1530.47	51.1348
1531.52	55.1645
1532.57	51.1339
1533.62	49.1718
1534.67	47.1597
1535.72	50.1296
1536.77	51.0423
1537.82	48.9686
1538.87	51.9209
1539.92	51.9893
1540.97	45.0476
1542.02	45.0026
1543.07	49.9457
1544.12	51.8701
1545.17	43.885
1546.22	47.9235
1547.27	45.9166
1548.32	48.8806
1549.37	46.8341
1550.42	56.8484
1551.46	51.9918
1552.51	52.9832
1553.56	51.9234
1554.61	54.8757
1555.65	50.8023
1556.7	50.7832
1557.75	48.7736
1558.79	49.7174
1559.84	58.6409
1560.89	54.5972
1561.93	49.5956
1562.98	46.6096
1564.02	46.5854
1565.07	58.62
1566.11	52.2596
1567.16	51.4816
1568.2	51.5102
1569.25	46.5095
1570.29	51.4666
1571.34	45.4544
1572.38	44.418
1573.43	50.3634
1574.47	51.3413
1575.51	48.3831
1576.56	56.3703
1577.6	53.2898
1578.64	50.2177
1579.69	46.2116
1580.73	48.2064
1581.77	45.1778
1582.81	47.1276
1583.85	43.1188
1584.9	48.087
1585.94	51.0578
1586.98	54.9821
1588.02	51.9602
1589.06	48.9795
1590.1	45.0026
1591.14	48.9859
1592.18	45.9729
1593.22	43.9214
1594.26	45.8235
1595.3	56.7472
1596.34	46.7793
1597.38	51.7371
1598.42	52.7187
1599.46	49.6757
1600.5	47.6405
1601.54	55.4951
1602.58	46.5118
1603.62	46.4525
1604.66	50.3814
1605.69	45.4279
1606.73	51.372
1607.77	43.6691
1608.81	47.6393
1609.84	50.7116
1610.88	54.3849
1611.92	45.33
1612.95	45.3473
1613.99	50.1818
1615.03	53.757
1616.06	48.7767
1617.1	50.115
1618.13	50.2264
1619.17	50.8848
1620.2	51.0061
1621.24	48.8407
1622.27	51.3778
1623.31	49.6682
1624.34	50.9817
1625.38	48.1079
1626.41	46.0413
1627.45	47.6691
1628.48	49.9744
1629.51	48.0323
1630.55	49.4145
1631.53	47.7858
1632.57	51.7341
1633.62	49.7444
1634.66	47.77
1635.71	45.7802
1636.75	50.6727
1637.8	50.6304
1638.84	48.6324
1639.89	53.5394
1640.93	51.5645
1641.98	50.5653
1643.02	52.5092
1644.06	50.5179
1645.11	48.5148
1646.15	49.4983
1647.19	51.4326
1648.24	49.4351
1649.28	46.5107
1650.32	54.3692
1651.37	50.4619
1652.41	47.5003
1653.45	52.4012
1654.49	49.4411
1655.53	48.4615
1656.57	50.4697
1657.62	45.521
1658.66	51.4108
1659.7	48.409
1660.74	50.3591
1661.78	51.3666
1662.82	45.4813
1663.86	51.4
1664.9	47.4028
1665.94	44.3702
1666.98	50.3343
1668.02	50.293
1669.06	46.3402
1670.1	47.3461
1671.14	47.3657
1672.18	45.366
1673.21	49.3102
1674.25	52.2735
1675.29	49.3202
1676.33	49.317
1677.37	43.3687
1678.4	48.2801
1679.44	49.2233
1680.48	54.1325
1681.52	48.1722
1682.55	50.1323
1683.59	54.066
1684.63	46.1372
1685.66	49.0764
1686.7	48.079
1687.73	50.0517
1688.77	49.0283
1689.81	44.0464
1690.84	45.0072
1691.88	45.0087
1692.91	46.9625
1693.95	46.9027
1694.98	44.8835
1696.01	49.8014
1697.05	50.7862
1698.08	49.7471
1699.12	46.7469
1700.15	45.7464
1701.18	53.5902
1702.22	48.6324
1703.25	47.6055
1704.28	49.5439
1705.32	50.5215
1706.35	49.5133
1707.38	53.3787
1708.41	42.5213
1709.44	47.3513
1710.48	44.3894
1711.51	50.2657
1712.54	52.2128
1713.57	48.2088
1714.6	48.1445
1715.63	49.1065
1716.66	48.1139
1717.69	49.9905
1718.72	46.9732
1719.75	46.9409
1720.78	49.8447
1721.81	51.733
1722.84	48.7527
1723.87	47.7313
1724.9	48.6725
1725.93	48.5914
1726.96	44.6827
1727.99	51.4363
1729.02	52.2878
1730.05	48.3575
1731.07	46.3841
1732.1	48.3561
1733.13	46.3892
1734.16	53.0671
1735.18	44.3144
1736.21	48.1081
1737.24	49.0334
1738.26	52.8367
1739.29	54.698
1740.32	53.6408
1741.34	53.5645
1742.37	49.6829
1743.4	50.6102
1744.42	51.5268
1745.45	49.5884
1746.47	50.5112
1747.5	52.353
1748.52	49.4433
1749.55	51.3495
1750.57	53.2875
1751.6	49.4717
1752.62	51.3208
1753.64	47.4455
1754.67	50.2551
1755.69	49.2606
1756.71	49.2022
1757.74	48.1849
1758.76	51.0404
1759.78	51.9824
1760.81	47.1967
1761.83	52.8559
1762.85	49.0347
1763.87	57.5834
1764.89	53.806
1765.92	53.8156
1766.94	48.0853
1767.96	58.5246
1768.98	53.7287
1770	56.4653
1771.02	54.5807
1772.04	58.4148
1773.06	55.5797
1774.08	55.5896
1775.1	55.5932
1776.12	54.6796
1777.14	53.7116
1778.16	46.9948
1779.18	51.6998
1780.2	50.7248
1781.22	45.9673
1782.24	49.7752
1783.26	47.8881
1784.28	46.9449
1785.29	55.5491
1786.31	53.6124
1787.33	47.8975
1788.35	49.8864
1789.37	48.03
1790.38	52.851
1791.4	48.9961
1792.42	46.0702
1793.43	52.7761
1794.45	43.1905
1795.47	50.8873
1796.48	44.2087
1797.5	45.1897
1798.51	50.0054
1799.53	43.2563
1800.55	50.8985
1801.56	49.9082
1802.58	48.9431
1803.59	44.1567
1804.61	44.1621
1805.62	42.2598
1806.64	47.0966
1807.65	42.2759
1808.66	40.336
1809.68	46.1113
1810.69	38.3895
1811.7	46.082
1812.72	47.0389
1813.73	47.0492
1814.74	43.2153
1815.76	41.3012
1816.77	48.0623
1817.78	48.0189
1818.79	46.0797
1819.8	48.0122
1820.82	47.0531
1821.83	44.1597
1822.84	44.1639
1823.85	50.9252
1824.86	44.1366
1825.87	47.0436
1826.88	49.9374
1827.89	45.0937
1828.9	48.9527
1829.91	45.0487
1830.92	43.0799
1831.93	45.0191
1832.94	44.0625
1833.95	45.9991
1834.96	46.9221
1835.97	44.9007
1836.98	46.9947
1837.99	45.8628
1839	52.6188
1840	48.801
1841.01	45.788
1842.02	48.5851
1843.03	46.5989
1844.04	41.761
1845.04	46.5709
1846.05	43.6752
1847.06	44.6697
1848.07	42.5747
1849.07	39.6797
1850.08	48.2927
1851.09	41.4917
1852.09	43.3699
1853.1	45.273
1854.1	42.3603
1855.11	48.0537
1856.11	43.2025
1857.12	44.1389
1858.12	46.0222
1859.13	45.0125
1860.13	37.3175
1861.14	47.8398
1862.14	45.9378
1863.15	40.1543
1864.15	42.97
1865.15	45.787
1866.16	47.6202
1867.16	40.8597
1868.16	48.399
1869.17	46.4772
1870.17	40.7505
1871.17	46.431
1872.17	48.2987
1873.18	46.355
1874.18	43.4738
1875.18	44.3664
1876.18	45.232
1877.18	47.0599
1878.18	46.0317
1879.19	41.3645
1880.19	44.2241
1881.19	42.3105
1882.19	41.2869
1883.19	46.8436
1884.19	43.008
1885.19	46.7874
1886.19	48.7221
1887.19	44.925
1888.19	48.6383
1889.19	38.1966
1890.19	42.8661
1891.19	47.5882
1892.18	40.0294
1893.18	44.7028
1894.18	40.8585
1895.18	47.4005
1896.18	42.7027
1897.18	47.419
1898.17	45.536
1899.17	47.3744
1900.17	42.629
1901.16	44.492
1902.16	47.3335
1903.16	44.5155
1904.16	44.4835
1905.15	44.4611
1906.15	49.1271
1907.14	42.5033
1908.14	50.0081
1909.14	49.0762
1910.13	46.2863
1911.13	41.6213
1912.12	47.271
1913.12	50.0741
1914.11	45.3727
1915.11	46.3471
1916.1	40.6888
1917.1	48.1987
1918.09	50.9881
1919.08	46.2914
1920.08	49.1777
1921.07	51.0625
1922.06	47.3082
1923.06	45.3956
1924.05	47.2519
1925.04	44.3795
1926.04	44.3966
1927.03	43.4875
1928.02	37.8186
1929.01	42.5584
1930	42.5802
1931	43.5624
1931.99	44.4925
1932.98	43.5029
1933.97	45.3939
1934.96	38.8535
1935.95	42.7427
1936.94	47.4502
1937.93	40.7284
1938.92	46.424
1939.91	39.7687
1940.9	47.4092
1941.89	46.4856
1942.88	42.6735
1943.87	46.4495
1944.86	48.379
1945.85	44.5905
1946.84	46.52
1947.83	43.6295
1948.82	44.5655
1949.8	41.7106
1950.79	46.5477
1951.78	44.6887
1952.77	41.831
1953.76	47.5851
1954.74	44.5904
1955.73	45.5098
1956.72	41.737
1957.7	49.449
1958.69	46.5773
1959.68	38.8603
1960.66	43.6271
1961.65	45.5005
1962.63	44.5275
1963.62	48.3603
1964.61	41.6401
1965.59	43.5409
1966.58	47.3939
1967.56	47.4031
1968.55	55.0887
1969.53	50.2392
1970.52	42.4882
1971.5	52.0404
1972.48	47.2291
1973.47	46.245
1974.45	42.366
1975.44	51.9414
1976.42	49.0777
1977.4	56.741
1978.39	49.027
1979.37	49.955
1980.35	51.8626
1981.33	51.8193
1982.31	52.7432
1983.3	55.5672
1984.28	52.6434
1985.26	60.2528
1986.24	57.3509
1987.22	55.4451
1988.21	51.5667
1989.19	61.8102
1990.17	58.8965
1991.15	53.565
1992.13	57.913
1993.11	57.071
1994.09	59.4499
1995.07	61.3457
1996.05	59.0621
1997.03	60.7414
1998.01	63.3897
1998.99	61.2569
1999.97	62.0962
2000.95	59.2275
2001.92	61.2214
2002.9	64.1201
2003.88	61.9798
2004.86	62.8427
2005.84	64.3129
2006.81	63.5757
2007.79	60.9788
2008.77	66.2912
2009.75	63.8178
2010.73	63.5844
2011.7	61.225
2012.68	64.6513
2013.67	67.3963
2014.66	62.5887
2015.64	63.4967
2016.63	61.641
2017.62	63.556
2018.61	63.4674
2019.6	62.4322
2020.58	61.4641
2021.57	59.5877
2022.56	61.4394
2023.55	53.8941
2024.54	57.5831
2025.52	60.3039
2026.51	47.1924
2027.5	55.725
2028.48	51.9204
2029.47	54.8028
2030.45	55.5674
2031.44	55.5868
2032.43	57.4581
2033.41	53.7873
2034.4	50.0501
2035.38	52.7701
2036.37	56.6176
2037.35	55.6613
2038.34	53.7715
2039.32	49.0627
2040.31	58.3512
2041.29	46.1673
2042.27	48.938
2043.26	47.9814
2044.24	48.9643
2045.23	51.728
2046.21	49.9593
2047.19	50.8424
2048.17	44.2491
2049.16	45.1878
2050.14	49.9
2051.12	46.1954
2052.11	45.231
2053.09	52.7134
2054.07	45.2843
2055.05	50.9067
2056.03	45.2681
2057.01	46.1839
2058	47.125
2058.98	43.4132
2059.96	49.0458
2060.94	48.0877
2061.92	48.1022
2062.9	45.299
2063.88	39.6992
2064.86	47.2095
2065.84	44.4339
2066.82	49.1513
2067.8	40.7126
2068.78	45.4261
2069.76	45.4093
2070.73	46.34
2071.71	43.544
2072.69	43.5991
2073.67	44.5282
2074.65	47.3594
2075.63	43.6407
2076.6	46.5148
2077.58	39.8825
2078.56	45.5282
2079.54	47.4361
2080.51	41.809
2081.49	45.5823
2082.47	45.5775
2083.45	44.6337
2084.42	40.8461
2085.4	43.678
2086.37	44.6325
2087.35	43.7154
2088.32	38.9909
2089.3	38.9925
2090.28	39.9609
2091.25	44.7066
2092.23	42.8388
2093.2	40.9877
2094.18	41.9717
2095.15	41.9749
2096.13	40.9965
2097.1	44.7806
2098.07	40.9512
2099.05	37.1399
2100.02	41.8745
2101	40.9283
2101.97	43.798
2102.94	47.5888
2103.92	44.7123
2104.89	43.7667
2105.86	40.941
2106.83	40.9542
2107.8	40.9516
2108.78	42.8063
2109.75	45.6508
2110.72	41.8556
2111.69	42.7973
2112.66	40.8802
2113.63	42.7983
2114.61	41.8494
2115.58	38.0428
2116.55	42.7707
2117.52	42.7498
2118.49	42.7287
2119.46	40.7853
2120.43	40.7505
2121.4	36.9636
2122.37	37.9396
2123.34	42.7027
2124.31	44.5933
2125.28	40.7393
2126.25	42.5724
2127.21	41.584
2128.18	42.5076
2129.15	38.7147
2130.12	38.7007
2131.09	39.6296
2132.06	40.5467
2133.02	36.7432
2133.99	38.6243
2134.96	39.5652
2135.93	37.6648
2136.89	36.6829
2137.86	40.457
2138.83	39.4951
2139.79	45.1561
2140.76	40.4039
2141.73	38.5052
2142.69	36.598
2143.66	38.5046
2144.62	40.3054
2145.59	40.3023
2146.55	39.35
2147.52	44.0277
2148.48	44.941
2149.45	43.9703
2150.42	35.4767
2151.38	41.0874
2152.34	41.1022
2153.31	42.0211
2154.27	37.3095
2155.24	36.317
2156.2	43.7405
2157.16	40.9172
2158.13	43.7317
2159.09	35.321
2160.05	36.2299
2161.01	42.7252
2161.98	41.7721
2162.94	40.8318
2163.9	41.7417
2164.86	40.7756
2165.83	38.9063
2166.79	41.6884
2167.75	40.7222
2168.71	43.4505
2169.67	37.881
2170.63	42.578
2171.59	38.8377
2172.56	41.5572
2173.51	43.3957
2174.48	42.4731
2175.44	35.0342
2176.4	45.2427
2177.36	43.3662
2178.32	38.7187
2179.28	36.8341
2180.23	36.8313
2181.19	34.0351
2182.15	37.7313
2183.11	40.4955
2184.07	40.4534
2185.03	37.6559
2185.99	44.1532
2186.95	37.6895
2187.9	34.0103
2188.86	33.9912
2189.82	36.7329
2190.78	39.4933
2191.73	41.3516
2192.69	37.6504
2193.65	40.4518
2194.6	37.7166
2195.56	39.5669
2196.52	43.2368
2197.47	39.4816
2198.43	37.6211
2199.38	42.3018
2200.34	45.1472
2201.3	39.6283
2202.25	39.4942
2203.21	42.347
2204.16	42.4927
2205.12	40.5476
2206.07	41.3768
2207.03	43.2277
2207.98	38.5975
2208.93	36.7617
2209.89	44.2188
2210.84	40.4999
2211.8	42.3853
2212.75	44.2738
2213.7	40.5206
2214.66	41.4684
2215.61	37.7559
2216.56	40.5544
2217.51	37.7444
2218.47	39.6095
2219.42	35.8864
2220.37	38.7039
2221.32	39.6258
2222.27	42.386
2223.23	35.8482
2224.18	39.6115
2225.13	39.6484
2226.08	34.9996
2227.03	39.7085
2227.98	38.7874
2228.93	38.7735
2229.88	38.7711
2230.83	40.677
2231.78	38.8297
2232.73	40.7356
2233.68	36.9974
2234.63	38.8894
2235.58	37.916
2236.53	36.9658
2237.48	39.7979
2238.43	37.9639
2239.38	39.8913
2240.33	36.0978
2241.27	37.9959
2242.22	38.9453
2243.17	38.0099
2244.12	40.8214
2245.07	38.9468
2246.01	36.1527
2246.96	35.2266
2247.91	38.0771
2248.85	34.2801
2249.8	36.1689
2250.75	38.9954
2251.69	37.0702
2252.64	36.1289
2253.59	34.2817
2254.53	37.1521
2255.48	39.0478
2256.42	40.0017
2257.37	36.2283
2258.32	36.2411
2259.26	39.099
2260.2	37.211
2261.15	38.1741
2262.1	35.3392
2263.04	41.0652
2263.98	40.1544
2264.93	39.2518
2265.87	36.4074
2266.81	38.2946
2267.76	37.3064
2268.7	39.1862
2269.65	42.0694
2270.59	35.4298
2271.53	35.4504
2272.47	39.2922
2273.42	38.338
2274.36	43.1271
2275.3	36.4312
2276.24	39.308
2277.18	37.4222
2278.13	35.5474
2279.07	38.4478
2280.01	36.4957
2280.95	39.3318
2281.89	36.4338
2282.83	35.4893
2283.77	37.4455
2284.71	42.3102
2285.65	34.6345
2286.59	32.6858
2287.54	38.4942
2288.47	47.1778
2289.41	47.1366
2290.35	36.4966
2291.29	35.5331
2292.23	36.5265
2293.17	43.2954
2294.11	34.6379
2295.05	40.3948
2295.99	44.219
2296.93	35.5198
2297.86	39.3887
2298.8	39.423
2299.74	36.5584
2300.68	42.344
2301.61	40.4317
2302.55	37.5305
2303.49	40.4165
2304.43	37.5269
2305.36	40.4431
2306.3	37.5546
2307.24	41.4229
2308.17	42.3712
2309.11	36.5641
2310.04	37.5589
2310.98	39.5009
2311.92	34.6054
2312.85	37.4636
2313.79	35.5387
2314.72	40.4126
2315.66	37.5316
2316.59	37.4794
2317.52	40.3567
2318.46	44.2219
2319.39	41.294
2320.33	44.1705
2321.26	48.0386
2322.2	50.0076
2323.13	51.0014
2324.06	52.9437
2325	68.3901
2325.93	110.798
2326.86	305.598
2327.79	760.388
2328.73	236.845
2329.66	97.9821
2330.59	63.2953
2331.52	47.8726
2332.46	45.9547
2333.39	41.1076
2334.32	41.0833
2335.25	42.9737
2336.18	40.0845
2337.11	41.0312
2338.04	41.9788
2338.97	42.9269
2339.91	38.1173
2340.84	40.9735
2341.77	40.9191
2342.7	40.8817
2343.63	41.828
2344.56	37.9884
2345.49	37.0188
2346.41	38.8997
2347.34	40.7993
2348.27	37.9214
2349.2	41.7508
2350.13	37.8575
2351.06	40.527
2351.99	36.8635
2352.91	41.5725
2353.84	40.5543
2354.77	39.5981
2355.7	36.7372
2356.63	38.6102
2357.55	42.3611
2358.48	38.5308
2359.41	39.4577
2360.33	39.4303
2361.26	33.697
2362.19	41.2387
2363.11	43.0866
2364.04	38.3264
2364.97	42.0822