File: Data/3-Raman/raw/bu19(2)w-a-ff1-fi03-v_1800 (450-850nm)_532nm_edge_100%_x100_vis_lwd_h100um_30sx2_01.txt
#Acq. time (s)=	30
#Accumulations=	2
#Range (cm-¹)=	1200...2365
#Windows=	3
#Auto scanning=	Off
#Autofocus=	Off
#Macrospot=	Off
#AutoExposure=	Off
#Spike filter=	Multiple accum.
#Delay time (s)=	2
#Binning=	1
#Readout mode=	Signal
#DeNoise=	Off
#ICS correction=	On
#Dark correction=	Off
#Inst. Process=	Off
#Detector Gain=	Best Dynamic
#Detector ADC=	50 kHz HS
#Detector temperature (°C)=	-60.09
#Instrument=	LabRAM HR Evol
#Detector=	SIN-EM FIVIS
#Objective=	x100_VIS_LWD
#Grating=	1800 (450-850nm)
#ND Filter=	100%
#Laser=	532nm_Edge
#Hole=	100.021
#Temperature=	0
#Range=	Visible
#StageXY=	75x50mm Scan+
#StageZ=	Z motor
#X (µm)=	0
#Y (µm)=	0
#Z (µm)=	-10.9
#Full time(mm:ss)=	3:18
#Project=	21_11_26
#Sample=	BU19(2)w
#Site=
#Title=	BU19(2)w-A-FF1-FI03-L_1800 (450-850nm)_532nm_Edge_100%_x100_VIS_LWD_H100um_30sX2
#Remark=
#Date=	26.11.2021 12:23
#Acquired=	26.11.2021 12:23:13
1202.72	1566.35
1203.84	1559.54
1204.95	1612.26
1206.06	1568.11
1207.17	1577
1208.28	1593.62
1209.39	1605.93
1210.5	1624.51
1211.61	1567.68
1212.72	1616.78
1213.83	1583.42
1214.94	1551.36
1216.05	1594.79
1217.16	1623.38
1218.27	1573.86
1219.38	1571.88
1220.49	1632.79
1221.6	1630.19
1222.71	1602.7
1223.81	1598.75
1224.92	1593.83
1226.03	1616.16
1227.14	1609.59
1228.25	1578.65
1229.35	1596
1230.46	1619.35
1231.57	1616.99
1232.67	1634.92
1233.78	1574.78
1234.89	1640.61
1235.99	1578.34
1237.1	1584.37
1238.2	1619.16
1239.31	1628.87
1240.41	1590.64
1241.52	1643.29
1242.62	1614.46
1243.73	1634.96
1244.83	1641.31
1245.94	1616.83
1247.04	1613.91
1248.14	1638.72
1249.25	1655.66
1250.35	1654.65
1251.45	1655.33
1252.56	1650.04
1253.66	1639.58
1254.76	1641.62
1255.87	1681.63
1256.97	1620.44
1258.07	1701.57
1259.17	1712.25
1260.27	1718.65
1261.37	1726.21
1262.48	1806.34
1263.58	1844.35
1264.68	1796.94
1265.78	1728.39
1266.88	1713.86
1267.98	1721.87
1269.08	1682.32
1270.18	1683.45
1271.28	1671.49
1272.38	1707.31
1273.47	1709.4
1274.57	1696.42
1275.67	1720.82
1276.77	1742.14
1277.87	1756.25
1278.97	1789.46
1280.07	1854.03
1281.16	2165.49
1282.26	3332.25
1283.36	4898.51
1284.45	3340.03
1285.55	2106.3
1286.65	1866.03
1287.75	1780.07
1288.84	1781.78
1289.94	1722.87
1291.03	1762.37
1292.13	1752.76
1293.22	1745.35
1294.32	1709.58
1295.42	1743.79
1296.51	1708.41
1297.61	1695.55
1298.7	1708.39
1299.79	1688.54
1300.89	1722.9
1301.98	1708.43
1303.08	1706.83
1304.17	1723.14
1305.26	1700.86
1306.35	1684.7
1307.45	1717.13
1308.54	1704.66
1309.63	1708.4
1310.73	1729.84
1311.82	1718.55
1312.91	1721.54
1314	1698.9
1315.09	1738.18
1316.18	1726.45
1317.28	1738.9
1318.37	1720.49
1319.46	1725.92
1320.55	1702.76
1321.64	1724.87
1322.73	1715.99
1323.82	1710.18
1324.91	1700.84
1326	1709.27
1327.09	1714.96
1328.18	1725.3
1329.27	1752.73
1330.35	1719.86
1331.44	1744.83
1332.53	1748.72
1333.62	1732.82
1334.71	1715.2
1335.79	1746.38
1336.88	1704.47
1337.97	1748.93
1339.06	1719.36
1340.14	1747.63
1341.23	1767.72
1342.32	1756.64
1343.4	1752.04
1344.49	1741.48
1345.58	1751.18
1346.66	1742.55
1347.75	1715.51
1348.83	1726.25
1349.92	1754.24
1351	1748.78
1352.09	1788.11
1353.17	1772.63
1354.25	1747.37
1355.34	1759
1356.42	1753.68
1357.51	1763.27
1358.59	1771.56
1359.67	1776.61
1360.76	1762.56
1361.84	1793.14
1362.92	1795.64
1364	1812.86
1365.09	1828.36
1366.17	1777.19
1367.25	1809.45
1368.33	1834.25
1369.41	1953.7
1370.5	1819.89
1371.58	1821.53
1372.66	1815.87
1373.74	1797.18
1374.82	1843.03
1375.9	1849.21
1376.98	1827.84
1378.06	1799.45
1379.14	1910.65
1380.22	1894.29
1381.3	1928.53
1382.38	1918.37
1383.46	2035.71
1384.54	2173.03
1385.61	2696.43
1386.69	6095.19
1387.77	7623.98
1388.85	2867.19
1389.93	2149.11
1391	1983.95
1392.08	1936.33
1393.16	1895.99
1394.23	1818.59
1395.31	1889.16
1396.39	1859.09
1397.46	1844.92
1398.54	1849.7
1399.62	1838.26
1400.69	1879.89
1401.77	1859.31
1402.84	1854.99
1403.92	1833.16
1404.99	1859.66
1406.07	1924.15
1407.14	1965.7
1408.22	2062.7
1409.29	2112.59
1410.37	1961.32
1411.44	1869.27
1412.51	1881.29
1413.59	1880.28
1414.66	1814.53
1415.73	1824.66
1416.81	1825.3
1417.88	1801.55
1418.95	1827.63
1420.02	1866.31
1421.1	1847.47
1422.17	1827.13
1423.24	1853.6
1424.31	1843.57
1425.38	1856.02
1426.45	1859.68
1427.52	1849.74
1428.59	1825.57
1429.67	1796.46
1430.74	1827.79
1431.81	1836.33
1432.87	1822.07
1433.95	1808.22
1435.01	1820.18
1436.08	1799.76
1437.15	1837.19
1438.22	1825.53
1439.29	1840.57
1440.36	1780.46
1441.43	1832.3
1442.49	1829.1
1443.56	1840.35
1444.63	1858.51
1445.7	1804.62
1446.77	1842.07
1447.83	1819.95
1448.9	1830.83
1449.97	1822.43
1451.03	1844.19
1452.1	1839.53
1453.17	1813.92
1454.23	1851.17
1455.3	1863.42
1456.36	1845.47
1457.43	1838.67
1458.49	1803.62
1459.56	1819.37
1460.62	1854.03
1461.69	1811.32
1462.75	1806.08
1463.82	1812.75
1464.88	1832.2
1465.94	1801.5
1467.01	1869.37
1468.07	1825.28
1469.13	1869.99
1470.2	1871.94
1471.26	1848.66
1472.32	1826.37
1473.39	1812.91
1474.45	1850.8
1475.51	1847.11
1476.57	1834.34
1477.63	1808.1
1478.69	1857.34
1479.76	1805.43
1480.82	1880.74
1481.88	1851.73
1482.94	1852.08
1484	1858.59
1485.06	1869.1
1486.12	1840.27
1487.18	1845.61
1488.24	1847.8
1489.3	1842.36
1490.36	1863.18
1491.42	1854.2
1492.48	1883.41
1493.53	1825.64
1494.59	1869.13
1495.65	1881.59
1496.71	1880.88
1497.77	1851.17
1498.82	1885.47
1499.88	1861.74
1500.94	1897.3
1502	1868.38
1503.05	1890.96
1504.11	1863.89
1505.17	1869.2
1506.22	1892.82
1507.28	1882.98
1508.34	1856.87
1509.39	1909.37
1510.45	1861.36
1511.5	1896.05
1512.56	1852.31
1513.61	1890.53
1514.67	1885.76
1515.72	1867.17
1516.78	1858.56
1517.83	1883.41
1518.88	1886.19
1519.94	1864.7
1520.99	1887.62
1522.05	1867.97
1523.1	1884.31
1524.15	1906.34
1525.2	1895.6
1526.26	1875.41
1527.31	1889.49
1528.36	1877.85
1529.41	1904.29
1530.47	1902.82
1531.52	1878.06
1532.57	1865.84
1533.62	1941.06
1534.67	1903.31
1535.72	1886.48
1536.77	1907.04
1537.82	1896.11
1538.87	1886.06
1539.92	1923.9
1540.97	1921.05
1542.02	1929.97
1543.07	1903.16
1544.12	1909.11
1545.17	1898.33
1546.22	1934.25
1547.27	1909.69
1548.32	1931.83
1549.37	1913.8
1550.42	1907.51
1551.46	1941.14
1552.51	1902.12
1553.56	1926.9
1554.61	1948.65
1555.65	1951.04
1556.7	1911.88
1557.75	1879.18
1558.79	1910.8
1559.84	1907.75
1560.89	1922.87
1561.93	1896.3
1562.98	1908.36
1564.02	1909.07
1565.07	1921.63
1566.11	1954.18
1567.16	1924.25
1568.2	1935.76
1569.25	1925.28
1570.29	1896.43
1571.34	1939.41
1572.38	1897.65
1573.43	1901.58
1574.47	1908.43
1575.51	1901.31
1576.56	1938.61
1577.6	1951.41
1578.64	1888.46
1579.69	1948.21
1580.73	1938.87
1581.77	1955.02
1582.81	1913.17
1583.85	1978.61
1584.9	1957.85
1585.94	1920.96
1586.98	1914.62
1588.02	1935.87
1589.06	1959.48
1590.1	1905.51
1591.14	1929.01
1592.18	1950.58
1593.22	1919.03
1594.26	1974
1595.3	1939.65
1596.34	1926.14
1597.38	1937.34
1598.42	1967.31
1599.46	1968.65
1600.5	1982.28
1601.54	1945.56
1602.58	1914.02
1603.62	1934.22
1604.66	1967.48
1605.69	1967.73
1606.73	1952.84
1607.77	1953.67
1608.81	1985.73
1609.84	1926.98
1610.88	1922.92
1611.92	1970.22
1612.95	1928.75
1613.99	1922.4
1615.03	1943.99
1616.06	1952.3
1617.1	1939.68
1618.13	1938.88
1619.17	1932.11
1620.2	1961.53
1621.24	1903.53
1622.27	1963.4
1623.31	1957.48
1624.34	1952.7
1625.38	1926.92
1626.41	1961.46
1627.45	1946.3
1628.48	1970.61
1629.51	1961.56
1630.55	1930.15
1631.53	1993.32
1632.57	1969.68
1633.62	1944.92
1634.66	1959.25
1635.71	1930.55
1636.75	1983.94
1637.8	1972.01
1638.84	1969.49
1639.89	1940.01
1640.93	1943.35
1641.98	1939.46
1643.02	1972.57
1644.06	1966.39
1645.11	1956.72
1646.15	1979.03
1647.19	1945.83
1648.24	1952.13
1649.28	1972.69
1650.32	1977.61
1651.37	1949.95
1652.41	1960.25
1653.45	1950.96
1654.49	1968.2
1655.53	1941.53
1656.57	1975.24
1657.62	1985.21
1658.66	1933.23
1659.7	1987.36
1660.74	1976.25
1661.78	1964.95
1662.82	1964.32
1663.86	1972.52
1664.9	1997.89
1665.94	1990.35
1666.98	1998.93
1668.02	1958.4
1669.06	1981.56
1670.1	1958.4
1671.14	1952.04
1672.18	1968.53
1673.21	1957.94
1674.25	1993.08
1675.29	1981.45
1676.33	1974.07
1677.37	2015.89
1678.4	1981.32
1679.44	1993.88
1680.48	1954.65
1681.52	2002.43
1682.55	1989.59
1683.59	1982.6
1684.63	1963.38
1685.66	1975.89
1686.7	1919.86
1687.73	1977.69
1688.77	1982.79
1689.81	2002.13
1690.84	1966.15
1691.88	1997.54
1692.91	1962.82
1693.95	1944.14
1694.98	1939.74
1696.01	1967.68
1697.05	1988.01
1698.08	1968.72
1699.12	1967.39
1700.15	2021.48
1701.18	1977.71
1702.22	1987.55
1703.25	2006.98
1704.28	2003.57
1705.32	2000.09
1706.35	2033.09
1707.38	2017.44
1708.41	1993.63
1709.44	1936.34
1710.48	1983.92
1711.51	2008.18
1712.54	1989.75
1713.57	1996.5
1714.6	1995.4
1715.63	1980.79
1716.66	1984.7
1717.69	1958.77
1718.72	2008.15
1719.75	2017.15
1720.78	1986.92
1721.81	1974.51
1722.84	1990.07
1723.87	1986.67
1724.9	1981.23
1725.93	1999.81
1726.96	2044.65
1727.99	1998.55
1729.02	1991.66
1730.05	2000.28
1731.07	2022.3
1732.1	2039.27
1733.13	1994.98
1734.16	2002.94
1735.18	1993.67
1736.21	2020.65
1737.24	2015.89
1738.26	1991.66
1739.29	2005.32
1740.32	1976.33
1741.34	2002.79
1742.37	1999.51
1743.4	2018.07
1744.42	2014.21
1745.45	2021.48
1746.47	2020.75
1747.5	2009.99
1748.52	1979.22
1749.55	2032.25
1750.57	2011.05
1751.6	2023.46
1752.62	2048.3
1753.64	2041.81
1754.67	2009.74
1755.69	2026.8
1756.71	1993.59
1757.74	2006.72
1758.76	2013.15
1759.78	2001.98
1760.81	2013.84
1761.83	1979.28
1762.85	1982.04
1763.87	2026.07
1764.89	1999.13
1765.92	2047.7
1766.94	2042.84
1767.96	2025.13
1768.98	2060.46
1770	2023.47
1771.02	1986.62
1772.04	2035.88
1773.06	2005.74
1774.08	2082.84
1775.1	2042.64
1776.12	2054.24
1777.14	2030.46
1778.16	2001.58
1779.18	2031.33
1780.2	2031.03
1781.22	2026.07
1782.24	2010.54
1783.26	2015.77
1784.28	2021.66
1785.29	2004.02
1786.31	1982.56
1787.33	2017.94
1788.35	2040.05
1789.37	2030.7
1790.38	2044.1
1791.4	2033.35
1792.42	2017.43
1793.43	2021.96
1794.45	2008.08
1795.47	1980.22
1796.48	2038.22
1797.5	2029.33
1798.51	2035.23
1799.53	2044.71
1800.55	2037.6
1801.56	2004.38
1802.58	1999.09
1803.59	2043.86
1804.61	2003.49
1805.62	2013.94
1806.64	2044.53
1807.65	2052.86
1808.66	2006.78
1809.68	1997.49
1810.69	2026.73
1811.7	1961.92
1812.72	2022.07
1813.73	1992.33
1814.74	2017.41
1815.76	2003.57
1816.77	2036.94
1817.78	2000.99
1818.79	2014.9
1819.8	2034.9
1820.82	2003.04
1821.83	1981.85
1822.84	2009.86
1823.85	2032.18
1824.86	2022.65
1825.87	1981.81
1826.88	1989.74
1827.89	1990.39
1828.9	2006.84
1829.91	2014.98
1830.92	2013.26
1831.93	2014.11
1832.94	2048.33
1833.95	1993.7
1834.96	2017.6
1835.97	1962.32
1836.98	1999.75
1837.99	1998.29
1839	2008.84
1840	2033.97
1841.01	1993.25
1842.02	1995.42
1843.03	1994.71
1844.04	2042.99
1845.04	2015.13
1846.05	2022.53
1847.06	2018.78
1848.07	2033.04
1849.07	2003.63
1850.08	2015.61
1851.09	1988.18
1852.09	2008.05
1853.1	2035.83
1854.1	2025.46
1855.11	2064.61
1856.11	2017.64
1857.12	1974.28
1858.12	2008.05
1859.13	2022.71
1860.13	1990.74
1861.14	1997.38
1862.14	2006.19
1863.15	1986.75
1864.15	2043.32
1865.15	2039.93
1866.16	2017.34
1867.16	1988.26
1868.16	1979.14
1869.17	1995.12
1870.17	2007.16
1871.17	2041.09
1872.17	2028.97
1873.18	2010.68
1874.18	2008.96
1875.18	2013.79
1876.18	1986.25
1877.18	2020.12
1878.18	2037.09
1879.19	2010.26
1880.19	2017.6
1881.19	1997.53
1882.19	1996.53
1883.19	2001.8
1884.19	2021.37
1885.19	2013.98
1886.19	2041.16
1887.19	2030.56
1888.19	2022.05
1889.19	2002.41
1890.19	1995.68
1891.19	2022.41
1892.18	2006.95
1893.18	1989.17
1894.18	1978.64
1895.18	1961.81
1896.18	2008.55
1897.18	2003.35
1898.17	1987
1899.17	2007.52
1900.17	2008.07
1901.16	1982.7
1902.16	2042.59
1903.16	1989.81
1904.16	2007.91
1905.15	1993.52
1906.15	2017.22
1907.14	1980.16
1908.14	1985.16
1909.14	1996.42
1910.13	1997.37
1911.13	1953.72
1912.12	2022.16
1913.12	1997.4
1914.11	2002.19
1915.11	1991.94
1916.1	1979.54
1917.1	2025.77
1918.09	2024.84
1919.08	2002.65
1920.08	2028.18
1921.07	1989.88
1922.06	2003.85
1923.06	2006.46
1924.05	1959.37
1925.04	2014.22
1926.04	1992.97
1927.03	1978.25
1928.02	2003.23
1929.01	2037.3
1930	1956.54
1931	1999.52
1931.99	1963.3
1932.98	1948.01
1933.97	2015.77
1934.96	1970.27
1935.95	1999.44
1936.94	1981.38
1937.93	1987.33
1938.92	1960.64
1939.91	1978.01
1940.9	1988.02
1941.89	2005.17
1942.88	1976.5
1943.87	1976.36
1944.86	2000.75
1945.85	1982.68
1946.84	1951.56
1947.83	1986.71
1948.82	2022.86
1949.8	1972.55
1950.79	1961
1951.78	1986.15
1952.77	1948.46
1953.76	1983.33
1954.74	1996.45
1955.73	1942.79
1956.72	1948.06
1957.7	1978.78
1958.69	1983.69
1959.68	1978.3
1960.66	2001.38
1961.65	1997.17
1962.63	1950.26
1963.62	1969.83
1964.61	1968.6
1965.59	1982.84
1966.58	1991.65
1967.56	1970.55
1968.55	1949.82
1969.53	1986.3
1970.52	1995.69
1971.5	1956.21
1972.48	1963.93
1973.47	1977.95
1974.45	1976.77
1975.44	1996.17
1976.42	1969.45
1977.4	1961.02
1978.39	1974.48
1979.37	1995.01
1980.35	1965.53
1981.33	1977
1982.31	1956.23
1983.3	1945.54
1984.28	1949.05
1985.26	1938.65
1986.24	1964.85
1987.22	1964.64
1988.21	1947.98
1989.19	1989.93
1990.17	1968.67
1991.15	1983.44
1992.13	1945.38
1993.11	1988.49
1994.09	1946.26
1995.07	1972.46
1996.05	1986.11
1997.03	1940.5
1998.01	1971.26
1998.99	1966.27
1999.97	1953.44
2000.95	1977.28
2001.92	1978.68
2002.9	1968.16
2003.88	1979.83
2004.86	1964.63
2005.84	1987.06
2006.81	1958.06
2007.79	1981.34
2008.77	1958.72
2009.75	1966.57
2010.73	1994.87
2011.7	1991.27
2012.68	1996.24
2013.67	1978.92
2014.66	1977.55
2015.64	1982.36
2016.63	1937.25
2017.62	1970.53
2018.61	1920.94
2019.6	1961.15
2020.58	1971.54
2021.57	1972.56
2022.56	2004.79
2023.55	1972.04
2024.54	1944.18
2025.52	1984.53
2026.51	1958.64
2027.5	1985.39
2028.48	1958.79
2029.47	1934.83
2030.45	1957.79
2031.44	1973.63
2032.43	1946
2033.41	1959.77
2034.4	1927.32
2035.38	1951.41
2036.37	1960.36
2037.35	1937.36
2038.34	1943.36
2039.32	1956.17
2040.31	1917.16
2041.29	1945.1
2042.27	1935.83
2043.26	1966.71
2044.24	1954.15
2045.23	1917.58
2046.21	1942.17
2047.19	1969.3
2048.17	1950.94
2049.16	1961.73
2050.14	1945.32
2051.12	1930.97
2052.11	1900
2053.09	1947.37
2054.07	1930.85
2055.05	1946.5
2056.03	1949.32
2057.01	1912.26
2058	1922.11
2058.98	1921.78
2059.96	1954.58
2060.94	1929.55
2061.92	1962.21
2062.9	1929.93
2063.88	1920.88
2064.86	1949.8
2065.84	1932.96
2066.82	1906.98
2067.8	1948.26
2068.78	1930.43
2069.76	1901.74
2070.73	1898.76
2071.71	1914.15
2072.69	1917.86
2073.67	1957.09
2074.65	1902.99
2075.63	1947.86
2076.6	1938.73
2077.58	1908.53
2078.56	1928.84
2079.54	1911.09
2080.51	1899.84
2081.49	1921.55
2082.47	1893.22
2083.45	1918.08
2084.42	1904.75
2085.4	1909.58
2086.37	1904.57
2087.35	1890.96
2088.32	1917.09
2089.3	1929.76
2090.28	1891.35
2091.25	1913.8
2092.23	1938.08
2093.2	1942.48
2094.18	1935.85
2095.15	1917.25
2096.13	1906.67
2097.1	1921.37
2098.07	1940.13
2099.05	1920.69
2100.02	1934.66
2101	1931.27
2101.97	1900.23
2102.94	1943.79
2103.92	1900.1
2104.89	1897.66
2105.86	1929.42
2106.83	1896.11
2107.8	1909.56
2108.78	1882.01
2109.75	1930.48
2110.72	1911.92
2111.69	1898.49
2112.66	1901.72
2113.63	1889.53
2114.61	1887
2115.58	1880.36
2116.55	1881.42
2117.52	1883.56
2118.49	1900.89
2119.46	1878.12
2120.43	1896.62
2121.4	1890.45
2122.37	1866.58
2123.34	1905.69
2124.31	1893.23
2125.28	1897.39
2126.25	1894.75
2127.21	1912.9
2128.18	1871.47
2129.15	1895.76
2130.12	1881.15
2131.09	1855.11
2132.06	1889.94
2133.02	1889.76
2133.99	1893.5
2134.96	1921
2135.93	1885.69
2136.89	1895.25
2137.86	1875.88
2138.83	1896.89
2139.79	1876.63
2140.76	1835.49
2141.73	1878.36
2142.69	1904.69
2143.66	1909.02
2144.62	1876.08
2145.59	1866.79
2146.55	1904.06
2147.52	1880.75
2148.48	1866.7
2149.45	1865.56
2150.42	1866.2
2151.38	1853.57
2152.34	1879.83
2153.31	1870.77
2154.27	1879.19
2155.24	1856.86
2156.2	1845.04
2157.16	1835.03
2158.13	1849.8
2159.09	1830.47
2160.05	1881.72
2161.01	1911.72
2161.98	1841.08
2162.94	1879.24
2163.9	1849.51
2164.86	1829.56
2165.83	1870.56
2166.79	1837.58
2167.75	1866.02
2168.71	1855.05
2169.67	1799.02
2170.63	1844.13
2171.59	1835.26
2172.56	1809.88
2173.51	1864.06
2174.48	1825.56
2175.44	1859.09
2176.4	1829.89
2177.36	1805.19
2178.32	1821.11
2179.28	1849.74
2180.23	1847.09
2181.19	1861.65
2182.15	1824.86
2183.11	1811.2
2184.07	1801.18
2185.03	1836.75
2185.99	1816.14
2186.95	1862.17
2187.9	1854.98
2188.86	1831
2189.82	1821.64
2190.78	1832.92
2191.73	1825.01
2192.69	1838.65
2193.65	1816.58
2194.6	1822.07
2195.56	1847.01
2196.52	1837.73
2197.47	1859.22
2198.43	1811.92
2199.38	1822.38
2200.34	1825.05
2201.3	1854.31
2202.25	1824
2203.21	1825.33
2204.16	1821.72
2205.12	1851.95
2206.07	1834.49
2207.03	1825.06
2207.98	1795.5
2208.93	1798.87
2209.89	1869.32
2210.84	1820.5
2211.8	1821.72
2212.75	1823.89
2213.7	1811.02
2214.66	1804.48
2215.61	1848.64
2216.56	1805.84
2217.51	1785.12
2218.47	1823.56
2219.42	1839.39
2220.37	1788.05
2221.32	1797.06
2222.27	1807.57
2223.23	1803.98
2224.18	1828.93
2225.13	1786.96
2226.08	1804.67
2227.03	1756.48
2227.98	1764.04
2228.93	1752.4
2229.88	1833.18
2230.83	1773.83
2231.78	1772.65
2232.73	1780.68
2233.68	1754.76
2234.63	1774.31
2235.58	1749.52
2236.53	1757.78
2237.48	1782.97
2238.43	1777.04
2239.38	1799.06
2240.33	1791.71
2241.27	1770.86
2242.22	1754.4
2243.17	1808.86
2244.12	1797.79
2245.07	1763.72
2246.01	1784.8
2246.96	1750.13
2247.91	1800.19
2248.85	1806.51
2249.8	1797.13
2250.75	1753.27
2251.69	1748.17
2252.64	1746.75
2253.59	1798.59
2254.53	1778.48
2255.48	1737.95
2256.42	1765.94
2257.37	1749.19
2258.32	1738.69
2259.26	1776.39
2260.2	1785.79
2261.15	1741.01
2262.1	1786.9
2263.04	1759.32
2263.98	1733.76
2264.93	1774.45
2265.87	1781.41
2266.81	1751.93
2267.76	1742.96
2268.7	1750.51
2269.65	1743.12
2270.59	1761.59
2271.53	1746.66
2272.47	1773.52
2273.42	1743.27
2274.36	1752.31
2275.3	1704.89
2276.24	1744.6
2277.18	1740.5
2278.13	1708.31
2279.07	1761.36
2280.01	1728.44
2280.95	1722.92
2281.89	1725.99
2282.83	1749.96
2283.77	1796.19
2284.71	1751.1
2285.65	1741.71
2286.59	1735.9
2287.54	1735.95
2288.47	1736.8
2289.41	1775.9
2290.35	1733.28
2291.29	1753.64
2292.23	1732.35
2293.17	1747.32
2294.11	1730.89
2295.05	1703.02
2295.99	1723.28
2296.93	1727.67
2297.86	1698.01
2298.8	1715.16
2299.74	1730.18
2300.68	1722.62
2301.61	1729.37
2302.55	1701.37
2303.49	1733.05
2304.43	1744.19
2305.36	1749.16
2306.3	1688.98
2307.24	1737.64
2308.17	1723.58
2309.11	1712.77
2310.04	1733.68
2310.98	1731.36
2311.92	1685.22
2312.85	1703.94
2313.79	1702.52
2314.72	1708.64
2315.66	1706.84
2316.59	1716.29
2317.52	1720.47
2318.46	1714.99
2319.39	1688.85
2320.33	1718.23
2321.26	1680.12
2322.2	1672.91
2323.13	1665.31
2324.06	1676.4
2325	1713.61
2325.93	1723.33
2326.86	1736.38
2327.79	1974.08
2328.73	1765.46
2329.66	1702.71
2330.59	1703.56
2331.52	1688.9
2332.46	1666.28
2333.39	1708.6
2334.32	1674.13
2335.25	1664.34
2336.18	1686.52
2337.11	1659.2
2338.04	1677.13
2338.97	1669.13
2339.91	1637.48
2340.84	1671.19
2341.77	1666.31
2342.7	1722.53
2343.63	1626.37
2344.56	1639.81
2345.49	1668.31
2346.41	1684.24
2347.34	1653.17
2348.27	1669.44
2349.2	1673.47
2350.13	1674.75
2351.06	1663.92
2351.99	1682.12
2352.91	1640.47
2353.84	1656.19
2354.77	1655.32
2355.7	1621.13
2356.63	1658.08
2357.55	1647.49
2358.48	1663.69
2359.41	1621.13
2360.33	1643.96
2361.26	1669.94
2362.19	1631.31
2363.11	1666.65
2364.04	1665.72
2364.97	1634.53