File: Data/3-Raman/raw/bu19(2)w-a-ff1-fi02-v_150 (500nm)_532nm_edge_100%_x100_vis_lwd_h50um_30sx2_01.txt
#Acq. time (s)=	30
#Accumulations=	2
#Range (cm-¹)=	99...4000
#Windows=	1
#Auto scanning=	Off
#Autofocus=	Off
#Macrospot=	Off
#AutoExposure=	Off
#Spike filter=	Multiple accum.
#Delay time (s)=	2
#Binning=	1
#Readout mode=	Signal
#DeNoise=	Off
#ICS correction=	On
#Dark correction=	Off
#Inst. Process=	Off
#Detector Gain=	Best Dynamic
#Detector ADC=	50 kHz HS
#Detector temperature (°C)=	-60.09
#Instrument=	LabRAM HR Evol
#Detector=	SIN-EM FIVIS
#Objective=	x100_VIS_LWD
#Grating=	150 (500nm)
#ND Filter=	100%
#Laser=	532nm_Edge
#Hole=	49.98
#Temperature=	0
#Range=	Visible
#StageXY=	75x50mm Scan+
#StageZ=	Z motor
#X (µm)=	0
#Y (µm)=	0
#Z (µm)=	-9.4
#Full time(mm:ss)=	1:05
#Project=	21_11_26
#Sample=	BU19(2)w
#Site=
#Title=	BU19(2)w-A-FF1-FI02-V_150 (500nm)_532nm_Edge_100%_x100_VIS_LWD_H50um_30sX2
#Remark=
#Date=	26.11.2021 12:02
#Acquired=	26.11.2021 12:02:57
102.91	14744.4
107.534	13189.3
112.156	12281.5
116.775	12634.3
121.392	12220.8
126.005	10532.5
130.617	8656.33
135.227	7872.33
139.835	7816.6
144.439	9032.58
149.042	12002.3
153.643	15943
158.242	16725
162.839	12980.3
167.431	9009.1
172.023	6807.96
176.613	5515.11
181.198	4814.51
185.783	4329.75
190.366	4103.35
194.947	3905.22
199.524	3760.95
204.1	3814.7
208.674	4137.32
213.243	5242.7
217.813	6931.39
222.38	6137.32
226.945	4378.03
231.506	3926.54
236.066	4501.3
240.625	5967.46
245.179	6812
249.732	5259.3
254.284	3943.97
258.831	3493.74
263.378	3366.51
267.923	3325.81
272.464	3267.05
277.004	3229.21
281.54	3352.17
286.076	3473.04
290.61	3677.86
295.139	3535.52
299.669	3333.71
304.196	3367.59
308.718	3335.74
313.241	3410.51
317.759	3501.78
322.278	3626.08
326.794	3759.86
331.305	3983.49
335.817	4403.2
340.324	4963.96
344.832	5058.84
349.334	4946.12
353.837	4931.27
358.338	5456.81
362.834	5570.7
367.33	4985.27
371.822	4560.3
376.314	4324.72
380.802	4455.03
385.289	4646.65
389.772	5039.66
394.255	5982.68
398.734	7852.75
403.213	9020.51
407.688	8634.14
412.162	7811.71
416.632	7079.31
421.102	6611.3
425.568	6387.92
430.033	6544.41
434.495	7060.09
438.956	7189.15
443.413	7207.98
447.87	7161.16
452.323	7108.51
456.776	7419.5
461.224	7619.88
465.673	7186.19
470.117	6353.43
474.561	5736.15
479.001	5473.9
483.438	5347.84
487.876	5498.05
492.309	5590.67
496.742	6008.03
501.172	6790.24
505.601	7840.68
510.025	9353.29
514.448	10808.2
518.871	11872.8
523.289	11605.1
527.707	10785.5
532.121	9715.27
536.533	8976.83
540.945	8749.62
545.353	8723.29
549.758	8858.56
554.164	9121.64
558.565	9094.01
562.965	8800.44
567.364	8472.2
571.759	7896.08
576.151	7343.99
580.544	7109.55
584.933	6730.59
589.319	6645.01
593.706	6725.89
598.088	7031.02
602.468	7317.61
606.848	7883.64
611.224	8551.54
615.598	9733.79
619.972	12022.7
624.341	16621.6
628.709	20993.2
633.074	18701.9
637.44	13507.9
641.801	10147.6
646.16	8619.37
650.517	7811.57
654.874	7361.38
659.227	6979.4
663.578	6857.22
667.927	6707.18
672.275	6625.58
676.62	6654.97
680.962	6509.75
685.302	6594.78
689.643	6623.88
693.979	6594.9
698.313	6655.22
702.645	6852.26
706.975	7027.62
711.305	7292.53
715.631	7258.19
719.955	7244.29
724.276	7135.62
728.596	7115.87
732.913	7150.21
737.231	7099.67
741.544	7114.71
745.856	7064.64
750.165	7020.11
754.472	7204.27
758.778	7241.04
763.081	7247.46
767.384	7267.4
771.683	7392.95
775.98	7397.97
780.275	7487.73
784.568	7528.86
788.859	7536.17
793.147	7631.74
797.434	7624.19
801.719	7729.3
806.004	7811.57
810.284	7830.8
814.563	8036.06
818.839	8041.45
823.114	8313.02
827.386	8298.71
831.657	8519.78
835.925	8773.26
840.192	9042.9
844.456	9440.86
848.719	9820.08
852.979	10260.5
857.237	10178.1
861.493	10052.4
865.748	9680.72
870	9560.46
874.25	9410.91
878.499	9468.8
882.745	9550.6
886.989	9806.06
891.231	9728.73
895.471	9557.75
899.71	9278.52
903.946	9272.94
908.18	9203.46
912.412	9080.54
916.642	9238.2
920.87	9225.03
925.096	9211.62
929.321	9159.61
933.543	9260.76
937.763	9357.51
941.981	9322.78
946.197	9541.35
950.412	9591.25
954.622	9631.87
958.832	9630.85
963.04	9883.06
967.246	9760.9
971.451	9783.49
975.653	9798.51
979.853	9929.17
984.052	9886.92
988.248	9997.99
992.442	10224.1
996.633	10128.5
1000.82	10318
1005.01	10423
1009.2	10535.2
1013.38	10641.7
1017.57	10645.4
1021.75	10740.7
1025.92	10664.1
1030.1	10518.2
1034.27	10717
1038.45	10933.4
1042.62	10942.1
1046.78	11367.5
1050.95	11601.7
1055.12	11904.2
1059.28	11949.1
1063.44	11886.7
1067.6	11944.1
1071.75	12043.7
1075.91	12465.4
1080.06	12728.6
1084.21	13318.2
1088.36	14255.7
1092.51	15864.7
1096.65	18182.2
1100.8	20729.5
1104.94	21391.8
1109.08	19095.5
1113.21	16090.7
1117.35	14223.1
1121.48	13336.5
1125.61	12864.3
1129.74	12578.4
1133.87	12747.9
1137.99	12866.1
1142.12	13208.8
1146.24	13897.8
1150.36	14607.6
1154.48	14820.4
1158.59	14554.7
1162.71	13797.2
1166.82	13200.3
1170.93	12748.7
1175.04	12588.1
1179.14	12342.9
1183.25	12376.7
1187.35	12289.3
1191.45	12194
1195.55	12277.6
1199.65	12229
1203.74	12214
1207.83	12294.6
1211.92	12323.4
1216.01	12292.2
1220.1	12364
1224.19	12400
1228.27	12438.6
1232.35	12561.8
1236.43	12653.3
1240.51	12742
1244.58	12843.9
1248.66	13044.4
1252.73	13640.3
1256.8	14028
1260.87	13419.9
1264.93	13383.2
1269	14003.9
1273.06	21022.1
1277.12	26520.8
1281.18	16687.7
1285.23	13812.2
1289.29	13527.6
1293.34	13463.4
1297.39	13260.2
1301.44	13283.2
1305.49	13173.7
1309.53	13237.6
1313.58	13369.5
1317.62	13453.2
1321.66	13383.9
1325.7	13480.7
1329.73	13442.8
1333.77	13301.1
1337.8	13473.1
1341.83	13548.1
1345.86	13600.4
1349.88	13743.9
1353.91	13876.1
1357.93	13966.9
1361.95	14353.5
1365.97	14313.8
1369.99	14515.6
1374	15834.6
1378.02	32023.6
1382.03	31993.8
1386.04	17526.6
1390.05	14690.9
1394.05	14583.6
1398.06	15129.3
1402.06	15732.4
1406.06	14672
1410.06	14142.7
1414.05	14090.7
1418.05	13892.8
1422.04	13991.6
1426.03	13848.7
1430.02	13740.2
1434.01	13782.9
1438	13749.3
1441.98	13718.9
1445.96	13714.1
1449.94	13770.5
1453.92	13902.5
1457.9	13831.9
1461.87	13812
1465.85	13786.8
1469.82	13936.6
1473.78	13850.5
1477.75	13882.3
1481.72	13779.1
1485.68	13919.7
1489.65	14033.6
1493.61	13817.3
1497.56	14053.2
1501.52	14018.4
1505.47	13999.8
1509.43	13986
1513.38	13929.6
1517.33	13921.6
1521.27	14033.6
1525.22	14068.8
1529.16	14058.5
1533.11	14070.4
1537.05	14006
1540.98	14127.2
1544.92	14016.9
1548.86	14048.1
1552.79	14334.1
1556.72	14183.3
1560.65	14270.6
1564.58	14169.5
1568.5	14357.1
1572.43	14331.8
1576.35	14303.4
1580.27	14224.2
1584.19	14257.6
1588.1	14280.2
1592.02	14281.3
1595.93	14284
1599.84	14378.9
1603.75	14281
1607.66	14370.5
1611.57	14341.5
1615.47	14414.1
1619.37	14425.5
1623.27	14359.4
1627.17	14468.9
1631.07	14367.8
1634.97	14573.8
1638.86	14507.2
1642.75	14557.5
1646.64	14460.4
1650.53	14501.8
1654.42	14491.1
1658.3	14469.6
1662.18	14518.6
1666.07	14426.4
1669.94	14600.8
1673.82	14535.1
1677.7	14435.8
1681.57	14404.8
1685.44	14626.3
1689.31	14436.7
1693.18	14568.3
1697.05	14487.9
1700.92	14509.4
1704.78	14526.8
1708.64	14592.4
1712.5	14579.6
1716.36	14522.5
1720.21	14470.9
1724.07	14526.6
1727.92	14513.9
1731.77	14625.7
1735.62	14615.4
1739.47	14615.6
1743.32	14547.7
1747.16	14629.9
1751.01	14530.2
1754.85	14541.8
1758.69	14623.9
1762.52	14535.4
1766.36	14681.5
1770.19	14525.8
1774.02	14539.6
1777.85	14525.2
1781.68	14438.2
1785.51	14527
1789.33	14491.5
1793.16	14425.7
1796.98	14434.1
1800.8	14463.4
1804.62	14490.1
1808.43	14488.3
1812.25	14360.4
1816.06	14534.4
1819.87	14330.4
1823.68	14407.6
1827.49	14394.3
1831.3	14478.8
1835.1	14495.4
1838.9	14356.1
1842.71	14292.9
1846.51	14404.9
1850.3	14368.3
1854.1	14551.7
1857.89	14494.2
1861.69	14506
1865.48	14364.4
1869.27	14441.2
1873.05	14454.4
1876.84	14367.9
1880.62	14406.4
1884.4	14297
1888.19	14269.5
1891.96	14402.9
1895.74	14334.3
1899.52	14329.3
1903.29	14294.5
1907.06	14230.4
1910.83	14140.9
1914.6	14139.5
1918.37	14191.7
1922.13	14120.9
1925.9	14097.6
1929.66	14019.2
1933.42	14137.9
1937.18	14185.9
1940.94	14122.5
1944.69	14162.3
1948.44	14079.4
1952.2	14149.3
1955.95	14039.7
1959.69	14018.6
1963.44	14156.1
1967.19	14077.8
1970.93	14038.2
1974.67	14088.1
1978.41	14099.5
1982.15	14099
1985.89	14030.7
1989.62	13990.7
1993.35	13976.6
1997.09	14132.6
2000.82	14117.3
2004.55	14008.3
2008.27	14047.8
2012	13981.5
2015.72	13904.8
2019.44	13831.6
2023.16	13834.7
2026.88	13867.3
2030.6	13808.1
2034.31	13767.4
2038.03	13757.2
2041.74	13635.9
2045.45	13697.5
2049.16	13611.1
2052.86	13575
2056.57	13572.6
2060.27	13544.3
2063.98	13594.1
2067.67	13581.2
2071.37	13467.2
2075.07	13393.4
2078.77	13410.1
2082.46	13457.5
2086.15	13301
2089.84	13379.9
2093.53	13409
2097.22	13366.6
2100.9	13347.7
2104.59	13327.1
2108.27	13333.8
2111.95	13251.1
2115.63	13237.7
2119.31	13254.2
2122.98	13322
2126.66	13209.6
2130.33	12992.4
2134	13221.6
2137.67	13048.2
2141.34	13106.4
2145	13008.6
2148.67	13064.7
2152.33	13033.2
2155.99	12994.9
2159.65	13038.8
2163.31	12899.4
2166.96	12867.5
2170.62	12853.4
2174.27	12904.8
2177.92	12849
2181.57	12809.4
2185.22	12669.2
2188.87	12686.3
2192.51	12684.6
2196.15	12640.9
2199.8	12698.3
2203.44	12628.6
2207.07	12593.7
2210.71	12678.8
2214.35	12515.1
2217.98	12529.4
2221.61	12412.7
2225.24	12360.7
2228.87	12307.7
2232.5	12278.8
2236.12	12345.1
2239.75	12194.7
2243.37	12177
2246.99	12267.3
2250.61	12275.8
2254.23	12191.5
2257.85	12049.2
2261.46	12036.1
2265.07	12074.8
2268.68	12057.7
2272.29	11958.6
2275.9	12013.2
2279.51	12014.6
2283.11	11942.8
2286.72	11906.6
2290.32	11745.3
2293.92	11866
2297.52	11794.1
2301.11	11733
2304.71	11751.2
2308.3	11649.5
2311.9	11734.6
2315.49	11740.2
2319.08	12370.3
2322.66	13379.9
2326.25	12039.5
2329.84	11613.9
2333.42	11467.2
2337	11491
2340.58	11494.4
2344.16	11406.3
2347.73	11373.3
2351.31	11409.8
2354.88	11352.1
2358.45	11242.6
2362.03	11320.8
2365.59	11253.6
2369.16	11219.8
2372.73	11098.2
2376.29	11162.8
2379.85	11102
2383.41	11026.1
2386.97	11026.1
2390.53	10962.8
2394.09	10977
2397.64	10800.2
2401.2	10937
2404.75	10787.4
2408.3	10789.5
2411.85	10766.8
2415.39	10758.6
2418.94	10666.5
2422.48	10638.5
2426.03	10469.2
2429.57	10557.8
2433.11	10570.1
2436.64	10510.6
2440.18	10547.6
2443.72	10575.4
2447.25	10418.7
2450.78	10443.9
2454.31	10519
2457.84	10284.7
2461.37	10240.2
2464.89	10343.6
2468.42	10208.2
2471.94	10249.9
2475.46	10256.8
2478.98	10194
2482.5	10133
2486.01	10038.2
2489.53	10053.9
2493.04	10129.6
2496.55	10035.2
2500.06	10050.5
2503.57	10037.1
2507.08	9977.24
2510.58	10011.4
2514.09	9940.01
2517.59	9943.74
2521.09	9888.9
2524.59	9729.28
2528.09	9842.47
2531.59	9701.16
2535.08	9686.11
2538.58	9626.89
2542.07	9503.52
2545.56	9567.45
2549.05	9605.11
2552.54	9443.62
2556.02	9429.68
2559.51	9354.52
2562.99	9396.22
2566.47	9401.29
2569.95	9354.31
2573.43	9320.75
2576.91	9272.85
2580.38	9195.39
2583.85	9255.68
2587.33	9248.17
2590.8	9057.96
2594.27	9120.62
2597.74	9051.46
2601.2	8996.1
2604.67	9011.46
2608.13	8976.52
2611.59	8958.85
2615.06	8947.42
2618.51	8843.27
2621.97	8890.97
2625.43	8882.14
2628.88	8840.16
2632.33	8857.22
2635.79	8615.88
2639.24	8792.22
2642.69	8653.48
2646.13	8660.61
2649.58	8597.43
2653.02	8572.47
2656.47	8634.76
2659.91	8582.03
2663.35	8617.59
2666.79	8578.45
2670.22	8548.7
2673.66	8442.44
2677.09	8481.6
2680.52	8282.18
2683.95	8416.18
2687.39	8279.33
2690.81	8289.87
2694.24	8233.47
2697.66	8216.37
2701.09	8201.17
2704.51	8127.66
2707.93	8130.78
2711.35	8056.85
2714.77	8078.53
2718.18	8109.3
2721.6	8043.84
2725.01	7990.49
2728.42	7960.09
2731.84	7958.15
2735.24	7865.86
2738.65	7861.47
2742.06	7871.69
2745.46	7696.33
2748.86	7704.7
2752.27	7791.23
2755.67	7742.64
2759.07	7662.04
2762.46	7611.64
2765.86	7630.77
2769.25	7548.83
2772.65	7581.51
2776.04	7585.26
2779.43	7534.94
2782.82	7505.25
2786.2	7476.9
2789.59	7463.36
2792.98	7496.55
2796.36	7347.23
2799.74	7451.55
2803.12	7383.78
2806.5	7324.64
2809.88	7299.12
2813.25	7256.39
2816.63	7307.72
2820	7186.01
2823.37	7158.97
2826.74	7118.95
2830.11	7114.01
2833.48	7132.41
2836.84	7010.52
2840.21	7017.49
2843.57	6927.09
2846.93	6913.79
2850.29	6929.1
2853.65	6888.17
2857.01	6791.21
2860.36	6870.82
2863.72	6752
2867.07	6800.98
2870.42	6834.15
2873.77	6749.51
2877.12	6717.12
2880.47	6680.72
2883.81	6676.98
2887.16	6617.04
2890.5	6633.29
2893.84	6594.39
2897.18	6559.49
2900.52	6547.25
2903.86	6515.05
2907.19	6535.96
2910.53	6441.8
2913.86	6450.3
2917.19	6412.93
2920.52	6313.1
2923.85	6436.18
2927.18	6373.29
2930.51	6316.14
2933.83	6318.75
2937.15	6282.66
2940.48	6289.99
2943.8	6205.95
2947.11	6172.12
2950.43	6165.81
2953.75	6157.4
2957.06	6100.36
2960.38	6135.46
2963.69	5989.03
2967	5992.24
2970.31	6020.7
2973.62	5959.26
2976.92	5938.38
2980.23	6012.3
2983.53	5956.98
2986.84	5891.68
2990.14	5914.01
2993.44	5853.91
2996.73	5853.28
3000.03	5948.83
3003.33	5765.1
3006.62	5810.78
3009.91	5794.84
3013.2	5793.32
3016.49	5731.61
3019.78	5708.34
3023.07	5655.7
3026.35	5665.33
3029.64	5679.77
3032.92	5643.08
3036.2	5632.55
3039.48	5604.83
3042.76	5544.94
3046.04	5611.02
3049.32	5546.5
3052.59	5574.78
3055.86	5451.55
3059.14	5443.68
3062.41	5505.2
3065.68	5435.68
3068.94	5492.62
3072.21	5499.04
3075.48	5466.54
3078.74	5381.76
3082	5404.28
3085.26	5354.59
3088.52	5395.69
3091.78	5335.73
3095.04	5356.82
3098.29	5300.74
3101.55	5295.6
3104.8	5252.37
3108.05	5249.63
3111.3	5186.16
3114.55	5282.82
3117.8	5245.73
3121.04	5147.82
3124.29	5187.02
3127.53	5187.1
3130.77	5122.21
3134.02	5167.94
3137.25	5143.94
3140.49	5153.98
3143.73	5184.92
3146.96	5152.97
3150.2	5182.38
3153.43	5129.88
3156.66	5140.1
3159.89	5162.87
3163.12	5106.26
3166.35	5085.92
3169.57	5112.83
3172.8	5098.32
3176.02	5147.54
3179.24	4991.19
3182.46	5120.99
3185.68	5110.65
3188.9	5086.38
3192.12	5127.75
3195.33	5083.32
3198.55	5089.32
3201.76	5021.89
3204.97	5039.44
3208.18	4992.44
3211.39	4997.08
3214.6	4990.64
3217.8	5083.49
3221.01	5021.28
3224.21	5002.05
3227.41	5014.72
3230.61	4988.5
3233.81	4982.63
3237.01	4907.91
3240.21	5009.39
3243.4	4987.43
3246.59	4976.18
3249.79	4889.65
3252.98	4965.63
3256.17	4975.99
3259.36	4933.75
3262.54	5032.1
3265.73	4959.78
3268.92	4906.78
3272.1	4948.82
3275.28	4952.35
3278.46	4893.72
3281.64	4920.03
3284.82	4908.2
3288	4895.54
3291.17	4886.28
3294.35	4939.39
3297.52	4929.38
3300.69	4898.52
3303.86	4926.86
3307.03	4926.32
3310.2	4929.1
3313.36	4975.77
3316.53	5007.83
3319.69	4968.56
3322.85	4975.62
3326.02	5027.22
3329.18	5082.56
3332.33	5074.58
3335.49	5100.04
3338.65	5172.16
3341.8	5104.92
3344.95	5198.21
3348.11	5222
3351.26	5271.57
3354.41	5256.97
3357.56	5408.86
3360.7	5402.69
3363.85	5463.17
3366.99	5477.59
3370.13	5582.87
3373.28	5587.49
3376.42	5648.46
3379.56	5703.14
3382.69	5754.36
3385.83	5834.67
3388.97	5864.49
3392.1	6049.64
3395.23	6063.3
3398.36	6208.06
3401.49	6287.24
3404.62	6336.73
3407.75	6498.07
3410.88	6733.33
3414	6822.28
3417.13	6897.38
3420.25	7179.03
3423.37	7437.5
3426.49	7679.44
3429.61	7956.44
3432.73	8212.4
3435.84	8449.48
3438.96	8829.63
3442.07	9358.6
3445.18	9844.17
3448.29	10492.4
3451.4	11505
3454.51	12878.7
3457.62	15160.8
3460.72	18425.1
3463.83	20718.2
3466.93	20340.1
3470.03	17721.9
3473.13	15129.9
3476.23	13361.2
3479.33	12295.5
3482.43	11627.2
3485.53	11289.1
3488.62	11062.7
3491.71	10972.3
3494.81	10880.2
3497.9	10852
3500.99	10895.6
3504.07	10907.5
3507.16	10916.6
3510.25	11084.8
3513.33	11134.5
3516.41	11353.7
3519.5	11550
3522.58	11975
3525.66	12402.7
3528.73	12895.9
3531.81	13515.9
3534.89	14354.2
3537.96	14846.7
3541.03	15642.5
3544.11	15899.3
3547.18	15758.1
3550.25	15078.9
3553.32	14032.9
3556.38	12573.2
3559.45	11102.8
3562.51	9731.86
3565.58	8538.42
3568.64	7671.69
3571.7	6899.6
3574.76	6290.56
3577.82	5871.33
3580.87	5484.73
3583.93	5102.41
3586.98	4851.47
3590.04	4635.65
3593.09	4458.18
3596.14	4303.44
3599.19	4128.5
3602.24	4036.09
3605.29	3943.31
3608.33	3894.8
3611.38	3764.03
3614.42	3683.3
3617.46	3617.64
3620.5	3572.04
3623.54	3520.05
3626.58	3426.75
3629.62	3446.84
3632.65	3329.19
3635.69	3321.64
3638.72	3265.98
3641.76	3178.81
3644.79	3133.42
3647.82	3006.97
3650.84	3028.33
3653.87	2936.26
3656.9	2908.23
3659.92	2824.56
3662.95	2768.7
3665.97	2769.7
3668.99	2721.36
3672.01	2682.11
3675.03	2624.08
3678.05	2566.15
3681.07	2528.12
3684.08	2537.16
3687.1	2438.44
3690.11	2420.1
3693.12	2392.34
3696.13	2399.63
3699.14	2361.89
3702.15	2340.76
3705.16	2345.22
3708.16	2297.41
3711.17	2283.48
3714.17	2287.44
3717.17	2233.08
3720.17	2218.8
3723.17	2169.97
3726.17	2134.26
3729.17	2142.14
3732.16	2125.11
3735.16	2103.11
3738.15	2073.26
3741.14	2062.28
3744.13	2063.42
3747.13	2013.03
3750.11	2015.71
3753.1	1999.25
3756.09	1973.28
3759.07	1956.88
3762.06	1978.37
3765.04	1927.66
3768.02	1937.67
3771	1921.32
3773.98	1928.81
3776.96	1878.77
3779.94	1895.98
3782.91	1863.23
3785.89	1822.97
3788.86	1863.09
3791.83	1789.11
3794.8	1825.85
3797.77	1812.72
3800.74	1807.25
3803.71	1795.41
3806.68	1808.21
3809.64	1749.28
3812.61	1725.38
3815.57	1727.98
3818.53	1729.68
3821.49	1687.92
3824.45	1718.12
3827.41	1769.33
3830.36	1720.13
3833.32	1742
3836.27	1661.55
3839.23	1650.42
3842.18	1647.83
3845.13	1641.42
3848.08	1651.22
3851.03	1638.23
3853.98	1624.37
3856.92	1582.84
3859.87	1595.7
3862.81	1572.27
3865.75	1608.99
3868.7	1568.2
3871.64	1575.12
3874.57	1568.59
3877.51	1538.94
3880.45	1510.04
3883.39	1553.96
3886.32	1552.56
3889.25	1514.52
3892.18	1543.69
3895.12	1496.83
3898.05	1488.24
3900.97	1471.78
3903.9	1512.01
3906.83	1441.49
3909.75	1470.17
3912.68	1494.85
3915.6	1477.11
3918.52	1464.08
3921.44	1420.59
3924.36	1439.24
3927.28	1418.37
3930.2	1414.64
3933.11	1418.52
3936.03	1393.05
3938.94	1385.12
3941.86	1411.92
3944.77	1397.4
3947.68	1396.37
3950.59	1389.74
3953.49	1366.93
3956.4	1359.49
3959.31	1369.42
3962.21	1325.76
3965.12	1347.31
3968.02	1351.7
3970.92	1357.12
3973.82	1333.79
3976.72	1328.65
3979.61	1297.47
3982.51	1312.32
3985.41	1326.19
3988.3	1305.39
3991.19	1294.15
3994.09	1309.68
3996.98	1261.96
3999.87	1295.04