File: Data/3-Raman/raw/bu19w-ff1-fi02-s_150 (500nm)_532nm_edge_100%_x100_vis_h50um_15sx2_01.txt
#Acq. time (s)=	15
#Accumulations=	2
#Range (cm-¹)=	100...5000
#Windows=	1
#Auto scanning=	Off
#Autofocus=	Off
#Macrospot=	Off
#AutoExposure=	Off
#Spike filter=	Multiple accum.
#Delay time (s)=	2
#Binning=	1
#Readout mode=	Signal
#DeNoise=	Off
#ICS correction=	On
#Dark correction=	Off
#Inst. Process=	Off
#Detector Gain=	Best Dynamic
#Detector ADC=	50 kHz HS
#Detector temperature (°C)=	-60.09
#Instrument=	LabRAM HR Evol
#Detector=	SIN-EM FIVIS
#Objective=	x100_VIS
#Grating=	150 (500nm)
#ND Filter=	100%
#Laser=	532nm_Edge
#Hole=	49.98
#Temperature=	0
#Range=	Visible
#StageXY=	75x50mm Scan+
#StageZ=	Z motor
#X (µm)=	0
#Y (µm)=	0
#Z (µm)=	-134.5
#Full time(s)=	34
#Project=	21_05_14
#Sample=	BU19w
#Site=
#Title=	BU19w-FF1-FI02-S_150 (500nm)_532nm_Edge_100%_x100_VIS_H50um_15sX2
#Remark=
#Date=	14.05.2021 12:05
#Acquired=	14.05.2021 12:05:43
102.699	5144.47
107.322	4837.02
111.942	4840.49
116.56	4691.79
121.173	4721.94
125.787	4680.89
130.398	4679.13
135.006	5527.52
139.613	7546.31
144.215	9631.85
148.817	9774
153.417	7286.43
158.014	5234.56
162.607	4289.57
167.2	4130.6
171.79	4911.03
176.379	6408.75
180.963	5792.88
185.547	4420.15
190.128	4119.27
194.705	4762.75
199.282	7997.24
203.857	13781
208.43	10229.4
212.998	4920.85
217.566	3402.9
222.132	3084.69
226.693	3115.52
231.254	3099.29
235.813	2931.74
240.368	2763.5
244.923	2693.05
249.475	2910.98
254.023	2902.22
258.571	3307.99
263.117	3846.89
267.658	3918.59
272.199	3762.53
276.738	3907.56
281.273	4363.29
285.807	4645.73
290.34	7265.09
294.868	12901.8
299.396	16434.9
303.919	11716
308.443	7492.65
312.964	7731.49
317.481	8800.94
321.998	7907.43
326.51	5803.48
331.023	4370.19
335.533	3661.52
340.039	3640.77
344.544	4181.1
349.046	4063.17
353.547	3339.17
358.045	2980.39
362.542	3103.34
367.036	3233.94
371.527	3069.38
376.017	2980.23
380.503	3120.17
384.99	3547.46
389.471	3929.25
393.953	4298.38
398.43	4799.18
402.908	4943.16
407.381	4801.33
411.854	4621.33
416.323	4287.69
420.791	3656.04
425.256	3398.26
429.72	4198.88
434.18	4460.14
438.64	3281.33
443.095	2584
447.551	2348.06
452.003	2359.08
456.454	2330.21
460.901	2513.98
465.348	3168.27
469.791	4695.95
474.231	5167.82
478.672	3832.37
483.108	3164.21
487.544	3039.33
491.976	3073.45
496.408	3244.94
500.836	3388.7
505.261	3617.07
509.687	3782.23
514.108	3903.8
518.529	3891.41
522.946	3615.22
527.361	3262.7
531.776	2994.17
536.187	2787.98
540.595	2734.4
545.003	2725.86
549.408	2839.26
553.812	2805.27
558.212	2714.02
562.61	2632.37
567.007	2548.27
571.401	2596.38
575.792	2656.97
580.184	2653.03
584.571	2536.15
588.956	2474.65
593.341	2728.62
597.722	3819.52
602.101	6059.63
606.48	6633.02
610.854	4744.59
615.227	3538.39
619.597	3569.34
623.967	4580.94
628.334	6316.8
632.698	5803.54
637.06	4454.7
641.422	4367.28
645.779	6199.27
650.135	6671.56
654.491	4577.01
658.842	3374.3
663.192	2715.88
667.539	2480.13
671.884	2317.04
676.23	2326.85
680.571	2407.97
684.91	2417.58
689.247	2476.06
693.583	2572.99
697.916	2539.22
702.247	2236.32
706.576	2058.44
710.902	1939.44
715.229	1880.45
719.551	1798.6
723.872	1823.71
728.19	1817.02
732.506	1839.96
736.82	1778.05
741.134	1807.01
745.444	1830.29
749.752	1839.7
754.058	1830.1
758.362	1909.05
762.664	1922.5
766.964	2040.39
771.264	2131.22
775.559	2315.04
779.853	2537.48
784.144	3119
788.434	4104.07
792.722	5546.51
797.007	6015.99
801.29	5386.19
805.572	4247.23
809.851	3344.5
814.13	2826.2
818.406	2444.99
822.679	2222.69
826.95	2110.59
831.219	1968.72
835.486	1996.35
839.752	1947.73
844.015	1950.53
848.276	1925.41
852.535	1904.57
856.792	1893.67
861.047	2012.54
865.3	2089.79
869.551	2267.53
873.8	2545.09
878.047	2686.61
882.292	2545.6
886.534	2281.93
890.775	2083.99
895.014	2108.12
899.251	2053.42
903.486	1981.97
907.719	1978.13
911.95	1936.82
916.179	1893.02
920.406	1855.89
924.63	1869.05
928.853	1819.39
933.074	1901.02
937.293	1887.48
941.51	1918.69
945.723	1936.6
949.936	2004.1
954.147	2114.23
958.356	2131.83
962.563	2324.94
966.768	2442.46
970.971	2510.56
975.172	2694.25
979.371	2945.14
983.568	3212.96
987.761	3386.83
991.954	3439.01
996.145	3865.83
1000.33	4712.49
1004.52	6455.96
1008.71	9763.95
1012.89	13667.2
1017.07	12763
1021.25	8391.96
1025.43	5575.43
1029.6	4252.71
1033.77	3827.87
1037.95	3874.51
1042.11	4596.58
1046.28	5955.56
1050.45	6460.63
1054.61	7054.6
1058.77	9652.27
1062.93	10376.7
1067.09	9030.57
1071.24	7304.29
1075.4	5236.72
1079.55	3967.86
1083.7	3228
1087.85	3005.81
1091.99	3151.17
1096.14	3709.11
1100.28	4791.38
1104.42	6318.6
1108.55	7335.52
1112.69	6583.33
1116.82	5214.15
1120.96	4890.77
1125.09	5094.66
1129.21	4946.2
1133.34	4505.92
1137.46	4222.82
1141.59	4330.2
1145.71	4603.21
1149.83	4633.98
1153.94	4033.72
1158.06	3503.67
1162.17	3138.14
1166.28	3370.64
1170.39	3981.12
1174.5	4214.61
1178.6	3853.47
1182.7	3248.12
1186.8	2881.17
1190.9	2706.31
1195	2510.89
1199.1	2316.61
1203.19	2296.91
1207.28	2197.23
1211.37	2229.7
1215.46	2280.2
1219.54	2119.67
1223.63	2090.55
1227.71	2027.38
1231.79	2083.18
1235.87	2178.47
1239.95	2341.65
1244.02	2260.41
1248.09	2295.64
1252.16	2575.15
1256.23	2839.39
1260.3	2707.42
1264.36	2265.41
1268.43	2175.75
1272.49	2058.86
1276.55	2042.04
1280.6	2008.98
1284.66	2035.62
1288.71	1956.53
1292.76	1890.98
1296.81	1906.91
1300.86	1876.15
1304.91	1862.18
1308.95	1903.72
1312.99	1863.97
1317.03	1853.83
1321.07	1859.59
1325.11	1848.22
1329.14	1848.31
1333.18	1832.6
1337.21	1834.55
1341.24	1815.29
1345.26	1810.94
1349.29	1837.51
1353.31	1829.25
1357.33	1799.2
1361.35	1825.66
1365.37	1847.62
1369.39	1890.46
1373.4	1862.7
1377.41	1927.79
1381.43	2070.24
1385.43	2188.78
1389.44	2190.39
1393.45	2017.72
1397.45	1912.29
1401.45	1873.36
1405.45	1871.11
1409.45	1800.99
1413.44	1811.82
1417.44	1760.42
1421.43	1815.51
1425.42	1814.72
1429.41	1795.54
1433.39	1815.36
1437.38	1824.02
1441.36	1838.66
1445.34	1766.06
1449.32	1809.87
1453.3	1784.23
1457.27	1785.08
1461.24	1773.59
1465.22	1808.95
1469.19	1795.3
1473.15	1777.81
1477.12	1791.34
1481.09	1794.94
1485.05	1802.3
1489.01	1795.97
1492.97	1783.97
1496.93	1817.82
1500.88	1827.59
1504.83	1805.68
1508.79	1776.4
1512.74	1851.04
1516.68	1813.24
1520.63	1845.47
1524.57	1853.55
1528.52	1848.26
1532.46	1818.89
1536.4	1813.77
1540.33	1844.56
1544.27	1853.04
1548.2	1811.15
1552.14	1843.75
1556.07	1854.73
1559.99	1900.31
1563.92	1898.25
1567.84	1934.68
1571.77	1914.97
1575.69	1890.42
1579.61	1936.23
1583.52	1899.01
1587.44	1916.6
1591.35	1957.25
1595.27	1955.5
1599.18	1947.14
1603.09	1919.84
1606.99	1927.3
1610.9	1951.09
1614.8	1983.73
1618.7	1952.25
1622.6	1980.18
1626.5	2006.57
1630.39	1966.38
1634.29	1974.38
1638.18	1978.62
1642.07	1976.78
1645.96	1970.38
1649.85	2015.9
1653.73	2011.52
1657.62	1981.99
1661.5	2027.17
1665.38	1999.93
1669.26	1979.02
1673.13	2044.19
1677.01	1979.06
1680.88	1912.11
1684.75	1954.45
1688.62	1948.5
1692.49	1921.13
1696.35	1911.72
1700.22	1915.31
1704.08	1926.09
1707.94	1930.72
1711.8	1926.62
1715.66	1888.57
1719.51	1885.67
1723.37	1883.66
1727.22	1915.25
1731.07	1958.82
1734.92	1916.08
1738.76	1928.34
1742.61	1917.21
1746.45	1915.23
1750.29	1849.28
1754.13	1869.65
1757.97	1874.62
1761.81	1848.9
1765.64	1905.06
1769.47	1872.33
1773.31	1897.6
1777.14	1878.52
1780.96	1817.94
1784.79	1871.38
1788.61	1875.52
1792.43	1880.67
1796.25	1880.16
1800.07	1904.32
1803.89	1862.83
1807.71	1918.26
1811.52	1904.62
1815.33	1861.08
1819.14	1897.05
1822.95	1910.94
1826.76	1903.62
1830.56	1865.63
1834.37	1892.28
1838.17	1902.61
1841.97	1899.37
1845.77	1921.4
1849.56	1908.35
1853.36	1892.7
1857.15	1875.68
1860.94	1902.1
1864.73	1904.3
1868.52	1886.32
1872.31	1907.58
1876.09	1894.85
1879.87	1935.23
1883.66	1912.39
1887.43	1913.86
1891.21	1917.35
1894.99	1923.46
1898.76	1916.29
1902.53	1910.65
1906.31	1951.28
1910.08	1930.71
1913.84	1913.28
1917.61	1923.35
1921.37	1934.13
1925.14	1981.33
1928.9	1930.48
1932.66	1941.84
1936.41	1905.59
1940.17	1934.57
1943.92	1917.22
1947.68	1921.58
1951.43	1930.84
1955.18	1944.86
1958.92	1925
1962.67	1922.82
1966.41	1954.22
1970.16	1939.55
1973.9	1946.1
1977.64	1974.69
1981.37	1930.94
1985.11	1926.16
1988.84	1899.82
1992.57	1935.42
1996.31	1922.3
2000.03	1941.39
2003.76	1929.25
2007.49	1908.14
2011.21	1985.52
2014.93	1966.63
2018.65	1923.48
2022.37	1910.6
2026.09	1928.99
2029.81	1928.7
2033.52	1962.3
2037.23	1967.89
2040.94	1966.27
2044.65	1935.97
2048.36	1967.45
2052.07	1958.9
2055.77	1945.18
2059.47	1975.24
2063.17	1959.19
2066.87	1991.18
2070.57	1938.48
2074.27	2009.47
2077.96	2011.5
2081.65	1995.85
2085.34	1948.27
2089.03	2021.6
2092.72	2004.93
2096.41	1999.8
2100.09	1978.76
2103.77	1974.15
2107.46	1968.25
2111.14	1970.54
2114.81	2013.67
2118.49	1976.25
2122.16	1980.82
2125.84	1946.28
2129.51	1994.79
2133.18	2017.23
2136.85	1976.55
2140.51	1966.04
2144.18	1989.42
2147.84	1986.94
2151.5	2002.83
2155.16	1982.15
2158.82	1990.01
2162.48	2024.67
2166.13	1984.78
2169.79	1992.02
2173.44	1964.55
2177.09	1962.74
2180.74	2028.44
2184.38	2004.98
2188.03	2008.86
2191.67	2017.99
2195.32	1982.35
2198.96	2004.25
2202.6	2039.27
2206.23	2015.32
2209.87	2054.76
2213.5	2039.53
2217.14	2022.44
2220.77	2060.54
2224.4	2051.82
2228.03	2033.7
2231.65	2020.36
2235.28	2021.82
2238.9	2009.27
2242.52	2001.29
2246.14	2043.45
2249.76	2018.93
2253.38	1963.75
2256.99	2045.79
2260.6	1970.67
2264.21	1998.37
2267.82	1974.96
2271.44	2021.09
2275.04	1975.11
2278.65	1993.35
2282.25	2026.67
2285.85	1999.05
2289.45	1982.38
2293.05	1978.85
2296.65	1998.17
2300.25	1981.37
2303.84	1968.82
2307.43	2009.96
2311.02	2002.48
2314.62	2012.68
2318.2	2021.52
2321.79	2001.09
2325.38	1996.82
2328.96	2006.81
2332.54	2001.27
2336.12	1964.45
2339.7	1989.55
2343.28	1968.35
2346.85	1979.8
2350.43	1961.19
2354	1990.14
2357.57	1999.28
2361.14	1994.35
2364.71	1999.72
2368.27	2007.25
2371.84	1952.09
2375.4	1955.09
2378.96	1959.24
2382.52	1950.71
2386.08	1971.88
2389.64	1960.33
2393.19	1944.72
2396.75	1961.87
2400.3	1972.55
2403.85	1936.31
2407.4	1918.74
2410.95	1946.93
2414.49	1968.16
2418.04	1957.68
2421.58	1971.47
2425.12	1964.6
2428.66	1946.13
2432.2	1946.5
2435.74	1960.19
2439.27	1982.44
2442.81	1924.69
2446.34	1996.84
2449.87	1903.85
2453.4	2026.02
2456.93	1950.12
2460.45	1940.03
2463.98	1864.11
2467.5	1964.35
2471.02	1965.15
2474.54	1910.55
2478.06	1884.06
2481.58	1959
2485.09	1932.96
2488.61	1910.71
2492.12	1891.56
2495.63	1917.86
2499.14	1950.02
2502.65	1925.27
2506.15	1942.31
2509.66	1918.15
2513.16	1881.47
2516.66	1909.34
2520.16	1888.97
2523.66	1912.22
2527.16	1948.37
2530.66	1908.07
2534.15	1906.23
2537.64	1935.2
2541.13	1922.55
2544.62	1912.75
2548.11	1928.06
2551.6	1927.04
2555.08	1924.35
2558.57	1910.53
2562.05	1892.76
2565.53	1889.53
2569.01	1917.65
2572.49	1914.46
2575.96	1930.44
2579.44	1917.49
2582.91	1921.54
2586.38	1931.04
2589.85	1942.43
2593.32	1893.17
2596.79	1910.07
2600.25	1950.16
2603.72	1905.19
2607.18	1891.3
2610.64	1937.77
2614.1	1878.5
2617.56	1897.28
2621.02	1858.02
2624.47	1863.37
2627.92	1917.39
2631.38	1879.77
2634.83	1893.37
2638.28	1873.07
2641.72	1869.58
2645.17	1864.11
2648.61	1890.7
2652.06	1890.05
2655.5	1914.58
2658.94	1887.6
2662.38	1872.77
2665.82	1916.51
2669.25	1903.34
2672.69	1931.81
2676.12	1886.41
2679.55	1866.81
2682.98	1880.42
2686.41	1883.02
2689.84	1885.88
2693.26	1862.1
2696.69	1882.48
2700.11	1871.5
2703.53	1871.24
2706.95	1884.55
2710.37	1852.79
2713.79	1870.7
2717.2	1908.59
2720.62	1875.04
2724.03	1868.64
2727.44	1877.39
2730.85	1872
2734.26	1906.85
2737.66	1890.23
2741.07	1860.08
2744.47	1886.8
2747.87	1867.52
2751.28	1856.62
2754.67	1921.56
2758.07	1863.45
2761.47	1865.97
2764.86	1894.62
2768.26	1878.58
2771.65	1893.52
2775.04	1908.14
2778.43	1858.4
2781.82	1853.7
2785.2	1848.93
2788.59	1856.35
2791.97	1882.39
2795.35	1901.07
2798.73	1862.06
2802.11	1907.49
2805.49	1847.93
2808.87	1861.35
2812.24	1874.68
2815.62	1913.95
2818.99	1821.8
2822.36	1836.44
2825.73	1863.32
2829.1	1870.78
2832.46	1835.75
2835.83	1843.88
2839.19	1829.08
2842.55	1867.76
2845.91	1883.73
2849.27	1888.48
2852.63	1866.66
2855.99	1900.16
2859.34	1896.62
2862.69	1851.9
2866.05	1896.3
2869.4	1852.37
2872.75	1907.93
2876.09	1902.37
2879.44	1898.66
2882.78	1907.98
2886.13	1860.55
2889.47	1869.85
2892.81	1859.7
2896.15	1852.11
2899.49	1842.33
2902.82	1907.96
2906.16	1862.75
2909.49	1865.59
2912.82	1865.58
2916.16	1883.19
2919.49	1858.09
2922.81	1875.5
2926.14	1873.62
2929.46	1872.59
2932.79	1870.18
2936.11	1914.92
2939.43	1922.85
2942.75	1897.82
2946.07	1941.64
2949.39	1897.9
2952.7	1935.88
2956.02	1904.64
2959.33	1926.31
2962.64	1894.42
2965.95	1910.82
2969.26	1948.62
2972.57	1927.92
2975.87	1925.81
2979.17	1918.58
2982.48	1920.84
2985.78	1963.61
2989.08	1914.44
2992.38	1939.53
2995.68	1955.38
2998.97	1945.89
3002.27	1962.62
3005.56	1970.15
3008.85	1941.06
3012.14	1968.57
3015.43	1969.66
3018.72	2018.81
3022	1979.29
3025.29	2018.14
3028.57	2003.18
3031.85	2023.09
3035.14	2010.75
3038.41	2042.89
3041.69	2067.49
3044.97	2037.28
3048.24	2042.01
3051.52	2078.15
3054.79	2107.63
3058.06	2132.13
3061.33	2096.35
3064.6	2179.37
3067.87	2169.11
3071.13	2159.03
3074.4	2165.28
3077.66	2199.98
3080.92	2220.74
3084.18	2177.44
3087.44	2159.16
3090.7	2289.64
3093.95	2311.46
3097.21	2286.05
3100.46	2322.46
3103.71	2394.81
3106.96	2396.93
3110.21	2380.24
3113.46	2387.29
3116.71	2422.06
3119.95	2465.45
3123.2	2471.67
3126.44	2485.44
3129.68	2510.66
3132.92	2588.28
3136.16	2547.59
3139.4	2601.2
3142.63	2621.44
3145.87	2720.97
3149.1	2755.77
3152.33	2801.95
3155.56	2812.88
3158.79	2824.7
3162.02	2829.86
3165.25	2916.89
3168.47	2911.12
3171.69	2944.35
3174.92	2980.2
3178.14	3065.53
3181.36	3082.23
3184.58	3119.64
3187.79	3207.39
3191.01	3197.85
3194.22	3249.26
3197.43	3308.16
3200.65	3318.56
3203.86	3372.85
3207.07	3386.34
3210.27	3421.92
3213.48	3425.4
3216.69	3505.99
3219.89	3498.17
3223.09	3534.44
3226.29	3575.58
3229.49	3625.59
3232.69	3679.18
3235.89	3662.97
3239.08	3687.1
3242.28	3745.75
3245.47	3852.11
3248.66	3795.85
3251.85	3804.59
3255.04	3784.73
3258.23	3918.15
3261.42	3853.4
3264.6	3894.09
3267.79	3871.29
3270.97	3925.56
3274.15	3920.61
3277.33	3940.81
3280.51	3929.58
3283.68	3943.15
3286.86	3988.78
3290.04	3955.49
3293.21	4034.62
3296.38	4095.41
3299.55	4063.91
3302.72	4081.21
3305.89	4054.23
3309.06	4169.24
3312.22	4157.39
3315.39	4230.84
3318.55	4253.74
3321.71	4327.76
3324.87	4377.06
3328.03	4430.12
3331.19	4454.06
3334.34	4466.06
3337.5	4420.87
3340.65	4538.91
3343.81	4671.84
3346.96	4838.12
3350.11	4925.28
3353.25	5022.34
3356.4	5148.89
3359.55	5391.12
3362.69	5578.95
3365.84	5976.56
3368.98	6444.37
3372.12	7032.19
3375.26	8102.49
3378.4	9477.71
3381.53	11093.9
3384.67	11345.9
3387.8	9782.47
3390.94	8163.7
3394.07	7172.94
3397.2	6709.89
3400.33	6380.08
3403.46	6277.24
3406.58	6190.77
3409.71	6144.31
3412.83	6088.7
3415.96	6200.14
3419.08	6433.46
3422.2	6815.67
3425.32	7891.87
3428.44	11038.6
3431.55	17433.5
3434.67	20755.1
3437.78	14626.4
3440.89	9015.11
3444	6870.22
3447.12	6189.53
3450.22	5867.75
3453.33	5731.03
3456.44	5490.83
3459.54	5463.82
3462.65	5452.79
3465.75	5345.43
3468.85	5282.13
3471.95	5298.2
3475.05	5274.98
3478.15	5252.09
3481.24	5159.38
3484.34	5134.17
3487.43	5077.35
3490.53	5126.99
3493.62	5145.65
3496.71	5116.56
3499.79	5226.56
3502.88	5270.33
3505.97	5360.63
3509.05	5549.78
3512.14	5786
3515.22	5992.38
3518.3	5948.48
3521.38	5592.07
3524.46	5291.49
3527.54	4921.27
3530.61	4655.82
3533.69	4458.59
3536.76	4337.06
3539.83	4264.84
3542.9	4124.53
3545.97	4037.94
3549.04	4011.12
3552.11	3861.5
3555.18	3811.69
3558.24	3715.84
3561.3	3610.51
3564.37	3595.75
3567.43	3520.49
3570.49	3500.52
3573.55	3394.78
3576.61	3368.55
3579.66	3340.14
3582.72	3259.26
3585.77	3168.81
3588.82	3185.24
3591.87	3050.77
3594.92	3074.39
3597.97	2970.04
3601.02	2963.08
3604.07	2914.22
3607.11	2872.89
3610.16	2821.1
3613.2	2794.74
3616.24	2700.49
3619.28	2719.7
3622.32	2663.54
3625.36	2654.72
3628.39	2573.32
3631.43	2524.77
3634.46	2493.63
3637.5	2434.71
3640.53	2437.23
3643.56	2407.43
3646.59	2301.98
3649.62	2295.63
3652.64	2230.36
3655.67	2196.33
3658.69	2194.6
3661.72	2109.68
3664.74	2075.57
3667.76	2024.55
3670.78	1973.7
3673.79	1966.32
3676.81	1932.61
3679.83	1827
3682.84	1834.7
3685.86	1798.94
3688.87	1787.8
3691.88	1738.81
3694.89	1691.36
3697.9	1663.97
3700.91	1674.61
3703.91	1623.53
3706.92	1619.75
3709.92	1600.61
3712.92	1612.64
3715.92	1548.61
3718.92	1514.87
3721.92	1556.19
3724.92	1541.19
3727.92	1548.94
3730.91	1493.69
3733.91	1532.55
3736.9	1495.09
3739.89	1461.29
3742.88	1480.65
3745.87	1473.23
3748.86	1465.69
3751.85	1455.25
3754.83	1423.03
3757.82	1410.75
3760.8	1416.39
3763.78	1422.95
3766.76	1428.64
3769.74	1427.83
3772.72	1416.75
3775.7	1414.26
3778.67	1399.59
3781.65	1376.47
3784.62	1361.92
3787.6	1369.16
3790.57	1399.24
3793.54	1370.01
3796.51	1372
3799.47	1344.9
3802.44	1373.6
3805.41	1376.86
3808.37	1357.52
3811.33	1341.05
3814.3	1350.13
3817.26	1346.98
3820.22	1353.32
3823.18	1337.02
3826.13	1360.56
3829.09	1362.29
3832.04	1350.83
3835	1373.65
3837.95	1302.43
3840.9	1330.01
3843.85	1366.2
3846.8	1333.93
3849.75	1354.1
3852.69	1319.97
3855.64	1300.13
3858.58	1344.31
3861.53	1288.05
3864.47	1313.07
3867.41	1301.64
3870.35	1283.41
3873.29	1305.43
3876.22	1323.49
3879.16	1318.39
3882.1	1340.98
3885.03	1291.38
3887.96	1311.87
3890.89	1321.75
3893.82	1291.09
3896.75	1289.1
3899.68	1289.97
3902.61	1279.11
3905.53	1318.36
3908.46	1292.19
3911.38	1297.61
3914.3	1273.1
3917.23	1321.82
3920.15	1287.78
3923.06	1260.32
3925.98	1269.2
3928.9	1259.73
3931.81	1290.73
3934.73	1266.44
3937.64	1262.56
3940.55	1293.08
3943.46	1246.07
3946.37	1285.34
3949.28	1249.09
3952.19	1269.38
3955.09	1253.38
3958	1258.53
3960.9	1248.41
3963.8	1269.03
3966.71	1247.53
3969.61	1304.77
3972.51	1279.47
3975.4	1238.71
3978.3	1244.9
3981.2	1225.12
3984.09	1248.53
3986.99	1239.25
3989.88	1215.33
3992.77	1239.7
3995.66	1231.38
3998.55	1205.78
4001.43	1272.64
4004.32	1223.03
4007.21	1245.7
4010.09	1223.05
4012.98	1249.59
4015.86	1242.38
4018.74	1230.32
4021.62	1205.7
4024.5	1239.06
4027.37	1218.32
4030.25	1234.34
4033.13	1236.84
4036	1202.62
4038.87	1215.84
4041.75	1202.7
4044.62	1206.01
4047.49	1195.84
4050.35	1203.17
4053.22	1200.9
4056.09	1152.05
4058.95	1175.95
4061.82	1220.27
4064.68	1210.18
4067.54	1176.71
4070.4	1164.61
4073.26	1174.88
4076.12	1170.53
4078.98	1195.41
4081.83	1179.36
4084.69	1153.51
4087.54	1169.57
4090.4	1159.34
4093.25	1141.27
4096.1	1163.23
4098.95	1149.07
4101.8	1171.04
4104.64	1144.01
4107.49	1180.5
4110.33	1136.71
4113.18	1139.74
4116.02	1125.02
4118.86	1170.9
4121.7	1133.71
4124.54	1143.57
4127.38	1128.16
4130.22	1109.09
4133.05	1123.56
4135.89	1154.08
4138.72	1121.47
4141.56	1135.37
4144.39	1135.71
4147.22	1156.7
4150.05	1113.94
4152.88	1108
4155.7	1132.94
4158.53	1107.97
4161.36	1123.48
4164.18	1125.3
4167	1099.75
4169.82	1117.3
4172.65	1150.54
4175.46	1120.23
4178.28	1070.4
4181.1	1083.24
4183.92	1099.05
4186.73	1067.96
4189.55	1079.04
4192.36	1085.38
4195.17	1102.64
4197.98	1118.99
4200.79	1146.14
4203.6	1125.23
4206.41	1118.04
4209.21	1125.56
4212.02	1132.09
4214.83	1156.72
4217.63	1202.41
4220.43	1125.73
4223.23	1119.85
4226.03	1085.35
4228.83	1087.52
4231.63	1079.86
4234.42	1083.19
4237.22	1090.54
4240.01	1041.28
4242.81	1060.61
4245.6	1079.99
4248.39	1100.32
4251.18	1062.67
4253.97	1048.89
4256.76	1068.06
4259.55	1066.25
4262.33	1074.52
4265.12	1041.67
4267.9	1074.17
4270.68	1083.53
4273.47	1048.4
4276.25	1049.35
4279.03	1066.37
4281.8	1004.45
4284.58	1043.5
4287.36	1017.68
4290.13	1012.02
4292.91	1042.9
4295.68	1009.06
4298.45	1042.09
4301.22	1063.93
4303.99	1018.79
4306.76	1006.13
4309.53	1028.1
4312.3	1015.46
4315.06	1019.96
4317.83	985.708
4320.59	1001.24
4323.35	1016.72
4326.11	998.603
4328.87	999.784
4331.63	979.55
4334.39	1011.25
4337.15	974.745
4339.9	978.081
4342.66	1007.98
4345.41	997.198
4348.17	999.716
4350.92	1015.67
4353.67	982.661
4356.42	983.274
4359.17	998.192
4361.91	969.127
4364.66	975.885
4367.41	975.485
4370.15	984.266
4372.89	961.13
4375.63	976.944
4378.38	972.173
4381.12	953.047
4383.86	985.469
4386.59	957.558
4389.33	962.814
4392.07	944.85
4394.8	944.313
4397.53	992.002
4400.27	965.178
4403	966.279
4405.73	966.401
4408.46	960.231
4411.19	958.068
4413.92	929.775
4416.64	940.801
4419.37	944.471
4422.09	957.689
4424.82	919.754
4427.54	939.259
4430.26	948.317
4432.98	936.414
4435.7	949.586
4438.42	918.676
4441.13	939.091
4443.85	949.017
4446.57	940.027
4449.28	937.282
4451.99	929.235
4454.71	938.993
4457.42	936.077
4460.13	918.501
4462.83	894.643
4465.54	960.229
4468.25	920.648
4470.95	914.8
4473.66	944.865
4476.36	933.916
4479.07	887.128
4481.77	880.425
4484.47	904.318
4487.17	927.168
4489.87	907.552
4492.56	896.044
4495.26	879.478
4497.96	906.344
4500.65	887.494
4503.34	892.064
4506.04	861.682
4508.73	879.019
4511.42	902.752
4514.11	892.564
4516.8	897.235
4519.48	881.845
4522.17	891.984
4524.85	895.705
4527.54	882.428
4530.22	868.077
4532.9	869.751
4535.58	867.153
4538.27	860.383
4540.94	871.734
4543.62	836.078
4546.3	850.688
4548.98	889.995
4551.65	854.494
4554.33	840.433
4557	880.419
4559.67	849.575
4562.34	834.973
4565.01	848.923
4567.68	867.004
4570.35	841.77
4573.02	861.293
4575.68	850.936
4578.35	847.315
4581.01	822.53
4583.67	871.065
4586.34	834.602
4589	845.987
4591.66	844.231
4594.31	831.827
4596.97	836.66
4599.63	844.981
4602.29	834.796
4604.94	818.012
4607.59	816.588
4610.25	843.673
4612.9	852.1
4615.55	815.476
4618.2	828.399
4620.85	830.312
4623.5	800.18
4626.14	848.3
4628.79	788.256
4631.43	814.224
4634.08	789.243
4636.72	839.516
4639.36	813.363
4642	811.732
4644.64	819.199
4647.28	776.891
4649.92	818.117
4652.56	814.208
4655.19	791.787
4657.83	794.68
4660.46	793.309
4663.1	816.546
4665.73	808.142
4668.36	789.772
4670.99	783.673
4673.62	825.77
4676.24	778.155
4678.87	800.058
4681.5	748.949
4684.12	768.62
4686.75	795.056
4689.37	783.306
4691.99	774.828
4694.61	769.696
4697.23	769.089
4699.85	774.142
4702.47	733.902
4705.09	764.83
4707.7	761.817
4710.32	770.106
4712.93	781.789
4715.55	790.011
4718.16	773.338
4720.77	799.598
4723.38	794.256
4725.99	790.118
4728.6	759.877
4731.21	775.034
4733.81	742.485
4736.42	776.886
4739.02	756.752
4741.63	768.345
4744.23	770.861
4746.83	769.775
4749.43	752.791
4752.03	792.712
4754.63	735.847
4757.23	749.615
4759.82	750.946
4762.42	745.448
4765.01	753.749
4767.61	752.033
4770.2	751.206
4772.79	733.271
4775.38	780.421
4777.97	727.072
4780.56	763.959
4783.15	731.153
4785.74	741.781
4788.32	719.246
4790.91	740.251
4793.49	744.086
4796.07	728.53
4798.66	734.798
4801.24	739.978
4803.82	741.802
4806.4	734.54
4808.98	745.645
4811.55	730.312
4814.13	721.896
4816.71	744.754
4819.28	702.863
4821.85	717.648
4824.43	738.277
4827	743.807
4829.57	729.71
4832.14	724.878
4834.71	706.137
4837.28	734.136
4839.84	706.103
4842.41	718.842
4844.97	710.416
4847.54	711.276
4850.1	697.573
4852.66	705.768
4855.22	700.924
4857.78	709.034
4860.34	721.743
4862.9	708.188
4865.46	698.022
4868.01	718.954
4870.57	713.681
4873.12	713.004
4875.68	696.919
4878.23	681.964
4880.78	676.434
4883.33	676.826
4885.88	699.822
4888.43	700.264
4890.98	694.716
4893.53	702.253
4896.07	689.498
4898.62	663.614
4901.16	694.932
4903.7	672.607
4906.25	665.679
4908.79	688.547
4911.33	689.816
4913.87	683.864
4916.41	648.066
4918.94	681.589
4921.48	674.494
4924.02	691.331
4926.55	690.211
4929.08	681.99
4931.62	636.856
4934.15	652.701
4936.68	675.695
4939.21	668.587
4941.74	636.356
4944.27	630.645
4946.79	650.108
4949.32	656.421
4951.85	629.131
4954.37	635.449
4956.9	662.28
4959.42	661.562
4961.94	658.577
4964.46	637.677
4966.98	655.235
4969.5	617.21
4972.02	660.024
4974.53	632.787
4977.05	667.219
4979.57	673.88
4982.08	647.843
4984.59	669.093
4987.1	646.679
4989.62	640.011
4992.13	634.525
4994.64	624.217
4997.15	668.827
4999.65	663.498