File: Data/3-Raman/raw/bu19w-ff1-fi01-l_150 (500nm)_532nm_edge_100%_x100_vis_h50um_15sx2_01.txt
#Acq. time (s)=	15
#Accumulations=	2
#Range (cm-¹)=	100...5000
#Windows=	1
#Auto scanning=	Off
#Autofocus=	Off
#Macrospot=	Off
#AutoExposure=	Off
#Spike filter=	Multiple accum.
#Delay time (s)=	2
#Binning=	1
#Readout mode=	Signal
#DeNoise=	Off
#ICS correction=	On
#Dark correction=	Off
#Inst. Process=	Off
#Detector Gain=	Best Dynamic
#Detector ADC=	50 kHz HS
#Detector temperature (°C)=	-60.28
#Instrument=	LabRAM HR Evol
#Detector=	SIN-EM FIVIS
#Objective=	x100_VIS
#Grating=	150 (500nm)
#ND Filter=	100%
#Laser=	532nm_Edge
#Hole=	49.98
#Temperature=	0
#Range=	Visible
#StageXY=	75x50mm Scan+
#StageZ=	Z motor
#X (µm)=	0
#Y (µm)=	0
#Z (µm)=	-137.5
#Full time(s)=	35
#Project=	21_05_14
#Sample=	BU19w
#Site=
#Title=	BU19w-FF1-FI01-L_150 (500nm)_532nm_Edge_100%_x100_VIS_H50um_15sX2
#Remark=
#Date=	14.05.2021 11:29
#Acquired=	14.05.2021 11:29:41
102.699	6606.49
107.322	6169.4
111.942	5983.96
116.56	5721.31
121.173	5663.73
125.787	5409.67
130.398	5123.17
135.006	4869.76
139.613	4830.94
144.215	4666.92
148.817	4612.35
153.417	4557.78
158.014	4476
162.607	4239.36
167.2	4239.55
171.79	4880.44
176.379	6707.25
180.963	6589.24
185.547	4910.67
190.128	4300.31
194.705	4502.2
199.282	7046.74
203.857	13569.4
208.43	12112.9
212.998	6178.13
217.566	3837.05
222.132	3264.46
226.693	3073.96
231.254	3131.06
235.813	2917.08
240.368	2833.06
244.923	2857.67
249.475	3115.64
254.023	3162.69
258.571	3652.1
263.117	4614.69
267.658	4425.94
272.199	3902
276.738	3367.08
281.273	3140.86
285.807	3778.02
290.34	6000.75
294.868	10171.9
299.396	9811.03
303.919	6068.44
308.443	4276.73
312.964	4441.7
317.481	6375.19
321.998	7224.53
326.51	5056.63
331.023	3601.92
335.533	3181.18
340.039	3460.51
344.544	4282.6
349.046	4332.57
353.547	3416.98
358.045	2863.21
362.542	3036.23
367.036	3195.69
371.527	2903.01
376.017	2503.87
380.503	2434.68
384.99	2467.61
389.471	2555.01
393.953	2499.22
398.43	2923.29
402.908	3470.91
407.381	3826.42
411.854	3928.52
416.323	3698.73
420.791	3265.35
425.256	2955.14
429.72	3348.87
434.18	4015.01
438.64	3442.14
443.095	2598.08
447.551	2270.67
452.003	2236.93
456.454	2321.99
460.901	2458.6
465.348	3010.65
469.791	4660.71
474.231	5469.16
478.672	3936.41
483.108	2792.36
487.544	2447.65
491.976	2393.56
496.408	2453.26
500.836	2621.77
505.261	2880.35
509.687	3108.21
514.108	3128.24
518.529	3031.66
522.946	2811.84
527.361	2642.89
531.776	2541.72
536.187	2476.47
540.595	2478.28
545.003	2417.39
549.408	2500.38
553.812	2603.28
558.212	2674.59
562.61	2646.25
567.007	2718.04
571.401	2661.84
575.792	2715.27
580.184	2724.84
584.571	2620.33
588.956	2398.58
593.341	2460.01
597.722	2717.86
602.101	3908.22
606.48	5113.08
610.854	4229.2
615.227	3200.42
619.597	2974.35
623.967	3566.25
628.334	4254.05
632.698	4001.75
637.06	3038.57
641.422	2432.62
645.779	2241.34
650.135	2315.65
654.491	2447.88
658.842	2496.17
663.192	2387.96
667.539	2260.58
671.884	2233.54
676.23	2367.34
680.571	2601.96
684.91	2660.07
689.247	2776.86
693.583	3037.66
697.916	2919.46
702.247	2547.9
706.576	2257.62
710.902	2109.99
715.229	2025.49
719.551	1993.25
723.872	1988.53
728.19	1987.59
732.506	1928.19
736.82	1939.85
741.134	1893.95
745.444	1886.77
749.752	1944.76
754.058	1928.11
758.362	1958.48
762.664	1982.91
766.964	2060.49
771.264	2176.84
775.559	2271.77
779.853	2469.96
784.144	2991.91
788.434	4106.27
792.722	5330.49
797.007	5529.56
801.29	4410.68
805.572	3315.86
809.851	2646.24
814.13	2326.85
818.406	2218.36
822.679	2128.04
826.95	2053.33
831.219	1962.11
835.486	1957.76
839.752	1945.52
844.015	1937.29
848.276	1933.14
852.535	1907.88
856.792	1906.9
861.047	1846.25
865.3	1871.96
869.551	1854.35
873.8	1910.88
878.047	1913.22
882.292	2000.07
886.534	1958.04
890.775	1922.05
895.014	1832.75
899.251	1815.8
903.486	1831.14
907.719	1808.1
911.95	1873
916.179	1842.25
920.406	1834.31
924.63	1833.55
928.853	1829.06
933.074	1872.04
937.293	1885.34
941.51	1904.78
945.723	1923.78
949.936	1991.3
954.147	2072.7
958.356	2143.53
962.563	2347.25
966.768	2430.79
970.971	2451.17
975.172	2464.3
979.371	2624.2
983.568	2762.97
987.761	2694.75
991.954	2451.59
996.145	2222.89
1000.33	2095.09
1004.52	2111.63
1008.71	2041.49
1012.89	2067.3
1017.07	2046.23
1021.25	2066.64
1025.43	2069.9
1029.6	2026.19
1033.77	2133.12
1037.95	2188.64
1042.11	2193.13
1046.28	2290.27
1050.45	2431.16
1054.61	2609.81
1058.77	3150.2
1062.93	4209.53
1067.09	6032.8
1071.24	6647.25
1075.4	5311.82
1079.55	3992.81
1083.7	3263.22
1087.85	3070.85
1091.99	3136.76
1096.14	3694.73
1100.28	4658.22
1104.42	6009.95
1108.55	6497.49
1112.69	5677.43
1116.82	4865.76
1120.96	5006.02
1125.09	5602.24
1129.21	5764.85
1133.34	5226.58
1137.46	4938.34
1141.59	4925.66
1145.71	5358.31
1149.83	5448.68
1153.94	4796.2
1158.06	4026.98
1162.17	3614.97
1166.28	3737.99
1170.39	4364.74
1174.5	4905.97
1178.6	4477.27
1182.7	3631.71
1186.8	3265.12
1190.9	2858.96
1195	2648.88
1199.1	2470.54
1203.19	2409.74
1207.28	2410.11
1211.37	2456.16
1215.46	2439.5
1219.54	2389.22
1223.63	2310.29
1227.71	2283.74
1231.79	2268.16
1235.87	2470.33
1239.95	2701.21
1244.02	2670.67
1248.09	2597.13
1252.16	2906.71
1256.23	3228.1
1260.3	3057.41
1264.36	2654.74
1268.43	2396.18
1272.49	2278.54
1276.55	2243.89
1280.6	2196.96
1284.66	2198.59
1288.71	2189.07
1292.76	2120.62
1296.81	2071.15
1300.86	2003.14
1304.91	2035.55
1308.95	2038.8
1312.99	2040.34
1317.03	2080.46
1321.07	2066.94
1325.11	2051.29
1329.14	2071.25
1333.18	2056.22
1337.21	2013.75
1341.24	2034.15
1345.26	2013.43
1349.29	2072.49
1353.31	2052.88
1357.33	2043.26
1361.35	2031.65
1365.37	2021.66
1369.39	2091.89
1373.4	2105.33
1377.41	2193.83
1381.43	2372.52
1385.43	2583.52
1389.44	2562.42
1393.45	2331.77
1397.45	2183.15
1401.45	2104.88
1405.45	2073.16
1409.45	2037.64
1413.44	2003.21
1417.44	2030.87
1421.43	2031.78
1425.42	2031
1429.41	2006.84
1433.39	1967.42
1437.38	1982.97
1441.36	1992.67
1445.34	2028.58
1449.32	2025.93
1453.3	2017.92
1457.27	2006.8
1461.24	2019.72
1465.22	2017.43
1469.19	2033.03
1473.15	2035.92
1477.12	2024.63
1481.09	1997.58
1485.05	2010.54
1489.01	1970.74
1492.97	1995.57
1496.93	2008.71
1500.88	2037.74
1504.83	2023.43
1508.79	1986.24
1512.74	2012.22
1516.68	2053.9
1520.63	2042.39
1524.57	2040.7
1528.52	2041.18
1532.46	2014.69
1536.4	2039.58
1540.33	2067.43
1544.27	2075.89
1548.2	2064.98
1552.14	2093.65
1556.07	2068.72
1559.99	2086.13
1563.92	2071.38
1567.84	2099.97
1571.77	2124.58
1575.69	2128.83
1579.61	2073.19
1583.52	2099.46
1587.44	2127.47
1591.35	2117.91
1595.27	2159.27
1599.18	2183.38
1603.09	2154.96
1606.99	2154.61
1610.9	2222.36
1614.8	2192.59
1618.7	2164.86
1622.6	2216.64
1626.5	2187.47
1630.39	2177.9
1634.29	2231.88
1638.18	2257.24
1642.07	2272.79
1645.96	2279.04
1649.85	2247.08
1653.73	2281.25
1657.62	2313.36
1661.5	2255.88
1665.38	2265.24
1669.26	2258.78
1673.13	2287.39
1677.01	2281.76
1680.88	2209.76
1684.75	2209.6
1688.62	2189
1692.49	2171.86
1696.35	2202.23
1700.22	2194.86
1704.08	2163.22
1707.94	2161.67
1711.8	2152.33
1715.66	2142.21
1719.51	2142.57
1723.37	2149.46
1727.22	2113.69
1731.07	2123.03
1734.92	2142.65
1738.76	2131.03
1742.61	2140.85
1746.45	2120.75
1750.29	2126
1754.13	2129.38
1757.97	2129.76
1761.81	2172.91
1765.64	2121.43
1769.47	2125.14
1773.31	2144.17
1777.14	2144.02
1780.96	2157.55
1784.79	2167.62
1788.61	2099.25
1792.43	2175.12
1796.25	2091.52
1800.07	2134.77
1803.89	2142.47
1807.71	2126.54
1811.52	2152.66
1815.33	2129.04
1819.14	2176.34
1822.95	2117.55
1826.76	2117.7
1830.56	2149.31
1834.37	2155.95
1838.17	2134.97
1841.97	2108.89
1845.77	2106.27
1849.56	2148.24
1853.36	2114.38
1857.15	2151.03
1860.94	2160.99
1864.73	2168.18
1868.52	2145
1872.31	2151.87
1876.09	2172.86
1879.87	2172.23
1883.66	2179.47
1887.43	2113.58
1891.21	2178.71
1894.99	2188.45
1898.76	2168.42
1902.53	2196.02
1906.31	2180.63
1910.08	2224.77
1913.84	2215.93
1917.61	2170.06
1921.37	2189.61
1925.14	2198.34
1928.9	2179.52
1932.66	2164.38
1936.41	2176.15
1940.17	2209.41
1943.92	2196.4
1947.68	2209.56
1951.43	2232.23
1955.18	2216.32
1958.92	2158.87
1962.67	2245.87
1966.41	2242.45
1970.16	2195.66
1973.9	2201.95
1977.64	2216.2
1981.37	2265.62
1985.11	2192.2
1988.84	2221.35
1992.57	2180.08
1996.31	2224.03
2000.03	2210.06
2003.76	2233.45
2007.49	2223.63
2011.21	2198.1
2014.93	2244.89
2018.65	2235.27
2022.37	2248.65
2026.09	2264.15
2029.81	2267.31
2033.52	2210.39
2037.23	2210.5
2040.94	2245.53
2044.65	2279.31
2048.36	2204.63
2052.07	2291.41
2055.77	2294.36
2059.47	2212.92
2063.17	2221.15
2066.87	2271.1
2070.57	2292.7
2074.27	2245.12
2077.96	2245.75
2081.65	2256.52
2085.34	2265.01
2089.03	2255.66
2092.72	2271.63
2096.41	2295.51
2100.09	2289.41
2103.77	2277.36
2107.46	2253.74
2111.14	2278.28
2114.81	2291.57
2118.49	2256.79
2122.16	2251.79
2125.84	2285.57
2129.51	2290.14
2133.18	2228.99
2136.85	2248.95
2140.51	2273.04
2144.18	2284.86
2147.84	2280.04
2151.5	2295.44
2155.16	2272.45
2158.82	2279.85
2162.48	2273.02
2166.13	2293.92
2169.79	2266.24
2173.44	2265.04
2177.09	2287.66
2180.74	2279.55
2184.38	2276.01
2188.03	2279.01
2191.67	2301.92
2195.32	2322.98
2198.96	2305.09
2202.6	2325.83
2206.23	2313.21
2209.87	2303.66
2213.5	2236.56
2217.14	2304.22
2220.77	2297.71
2224.4	2317.91
2228.03	2307.57
2231.65	2308.52
2235.28	2290.1
2238.9	2316.89
2242.52	2277.84
2246.14	2260.95
2249.76	2275.89
2253.38	2304.18
2256.99	2331.7
2260.6	2345.06
2264.21	2331.19
2267.82	2291.51
2271.44	2325.07
2275.04	2223.95
2278.65	2274.54
2282.25	2296.71
2285.85	2289.16
2289.45	2310.49
2293.05	2235.26
2296.65	2262.33
2300.25	2284.52
2303.84	2258.81
2307.43	2298.11
2311.02	2276.43
2314.62	2285.65
2318.2	2235.66
2321.79	2214.12
2325.38	2266.34
2328.96	2260.9
2332.54	2253.13
2336.12	2243.27
2339.7	2265.1
2343.28	2246.25
2346.85	2243.15
2350.43	2228.73
2354	2270.25
2357.57	2206.15
2361.14	2226.85
2364.71	2250.32
2368.27	2204.59
2371.84	2235.13
2375.4	2235.77
2378.96	2267.11
2382.52	2262.72
2386.08	2257.71
2389.64	2256.84
2393.19	2261.12
2396.75	2235
2400.3	2291.46
2403.85	2236.04
2407.4	2249.77
2410.95	2232.34
2414.49	2251.1
2418.04	2246.48
2421.58	2241.33
2425.12	2216.46
2428.66	2244.68
2432.2	2191.03
2435.74	2226.62
2439.27	2207.63
2442.81	2212.91
2446.34	2180.11
2449.87	2264.83
2453.4	2254.42
2456.93	2240.07
2460.45	2262.35
2463.98	2262.12
2467.5	2266.34
2471.02	2245.55
2474.54	2227.48
2478.06	2253.62
2481.58	2211.48
2485.09	2224.62
2488.61	2275.28
2492.12	2288.54
2495.63	2289.91
2499.14	2233.61
2502.65	2213.99
2506.15	2205.32
2509.66	2239.32
2513.16	2184.44
2516.66	2188.67
2520.16	2207.58
2523.66	2218.36
2527.16	2222.81
2530.66	2184.15
2534.15	2254.16
2537.64	2186.16
2541.13	2201.22
2544.62	2246.08
2548.11	2237.62
2551.6	2201.74
2555.08	2215.21
2558.57	2199.03
2562.05	2210.62
2565.53	2185.75
2569.01	2220.22
2572.49	2247.81
2575.96	2206.55
2579.44	2232.13
2582.91	2226.76
2586.38	2237.17
2589.85	2208.45
2593.32	2237.81
2596.79	2198.27
2600.25	2214.2
2603.72	2189.89
2607.18	2163.88
2610.64	2181.61
2614.1	2214.71
2617.56	2194.19
2621.02	2226.06
2624.47	2207.32
2627.92	2210.3
2631.38	2171.55
2634.83	2178.16
2638.28	2201.61
2641.72	2188.11
2645.17	2189.84
2648.61	2190.16
2652.06	2207.99
2655.5	2188.16
2658.94	2175.73
2662.38	2225.48
2665.82	2230.66
2669.25	2195.07
2672.69	2203.16
2676.12	2188.08
2679.55	2193.14
2682.98	2157.65
2686.41	2170.21
2689.84	2159.88
2693.26	2177.81
2696.69	2215.69
2700.11	2186.91
2703.53	2179.01
2706.95	2210.96
2710.37	2126.31
2713.79	2192.8
2717.2	2211.39
2720.62	2192.14
2724.03	2214.08
2727.44	2188.65
2730.85	2177.99
2734.26	2211.31
2737.66	2225.04
2741.07	2184.88
2744.47	2165.81
2747.87	2197.49
2751.28	2170.84
2754.67	2210.52
2758.07	2198.75
2761.47	2155.22
2764.86	2188.64
2768.26	2196.15
2771.65	2138.52
2775.04	2165.32
2778.43	2218.12
2781.82	2159.6
2785.2	2184.75
2788.59	2185.41
2791.97	2154.86
2795.35	2218.47
2798.73	2174.51
2802.11	2150.33
2805.49	2180.51
2808.87	2162.76
2812.24	2221.65
2815.62	2143.8
2818.99	2184.94
2822.36	2168.56
2825.73	2138.36
2829.1	2168.06
2832.46	2182.31
2835.83	2181.08
2839.19	2136.49
2842.55	2229.29
2845.91	2210.04
2849.27	2153.53
2852.63	2174.88
2855.99	2170.35
2859.34	2172.71
2862.69	2206.07
2866.05	2199.3
2869.4	2214.86
2872.75	2190.9
2876.09	2153.63
2879.44	2177.5
2882.78	2200.29
2886.13	2189.91
2889.47	2206.13
2892.81	2230.22
2896.15	2193.5
2899.49	2198.97
2902.82	2230.61
2906.16	2185.44
2909.49	2177.86
2912.82	2195.83
2916.16	2194.45
2919.49	2164.54
2922.81	2231.97
2926.14	2209.12
2929.46	2208.85
2932.79	2219.39
2936.11	2225.2
2939.43	2257.38
2942.75	2203.84
2946.07	2215.46
2949.39	2229.81
2952.7	2194.25
2956.02	2271.77
2959.33	2236.02
2962.64	2274.33
2965.95	2235.3
2969.26	2277.85
2972.57	2295.59
2975.87	2287.98
2979.17	2300.51
2982.48	2269.06
2985.78	2315.69
2989.08	2321.08
2992.38	2282.43
2995.68	2336.02
2998.97	2316.35
3002.27	2347.34
3005.56	2306.11
3008.85	2349.71
3012.14	2355.78
3015.43	2373.11
3018.72	2391.35
3022	2344.48
3025.29	2353.32
3028.57	2405.62
3031.85	2386.02
3035.14	2405.05
3038.41	2442.1
3041.69	2450.8
3044.97	2507.9
3048.24	2414.32
3051.52	2497.09
3054.79	2441.43
3058.06	2485.03
3061.33	2497.69
3064.6	2559.92
3067.87	2501.28
3071.13	2521.32
3074.4	2595.78
3077.66	2593.43
3080.92	2615.29
3084.18	2581.7
3087.44	2644.46
3090.7	2669.9
3093.95	2694.56
3097.21	2687.26
3100.46	2721.82
3103.71	2763.9
3106.96	2798.56
3110.21	2817.17
3113.46	2839.52
3116.71	2926.76
3119.95	2896.91
3123.2	2922.28
3126.44	2968.52
3129.68	3015.75
3132.92	3034.36
3136.16	3079.51
3139.4	3118.87
3142.63	3156.31
3145.87	3213
3149.1	3135.35
3152.33	3233.09
3155.56	3314.68
3158.79	3323.71
3162.02	3423.41
3165.25	3456.08
3168.47	3525.7
3171.69	3523.58
3174.92	3550.76
3178.14	3640.76
3181.36	3685.99
3184.58	3740.42
3187.79	3766.98
3191.01	3766.8
3194.22	3873.29
3197.43	3870.08
3200.65	3912.67
3203.86	3972.51
3207.07	4048.67
3210.27	4102.21
3213.48	4033.32
3216.69	4112.91
3219.89	4254.4
3223.09	4226.96
3226.29	4352.82
3229.49	4288.77
3232.69	4296.74
3235.89	4358.73
3239.08	4401.19
3242.28	4427.75
3245.47	4527.71
3248.66	4492.77
3251.85	4537.18
3255.04	4550.17
3258.23	4564.57
3261.42	4642.32
3264.6	4636.32
3267.79	4632.65
3270.97	4664.92
3274.15	4680.94
3277.33	4741.1
3280.51	4777.26
3283.68	4711.26
3286.86	4789.87
3290.04	4805.79
3293.21	4905.48
3296.38	4832.5
3299.55	4896.02
3302.72	4949.12
3305.89	4916.92
3309.06	4960.98
3312.22	5003.58
3315.39	5077.29
3318.55	5084.29
3321.71	5096.97
3324.87	5138.04
3328.03	5076.98
3331.19	5233.65
3334.34	5225.27
3337.5	5327.79
3340.65	5312.29
3343.81	5322.34
3346.96	5477.24
3350.11	5528.51
3353.25	5536.97
3356.4	5574.94
3359.55	5597.58
3362.69	5662.87
3365.84	5677.56
3368.98	5724.5
3372.12	5837.27
3375.26	5747.43
3378.4	5934.73
3381.53	6011.29
3384.67	6000.43
3387.8	6018.05
3390.94	6109.87
3394.07	6239.09
3397.2	6292.86
3400.33	6369.65
3403.46	6433.92
3406.58	6481.65
3409.71	6591.59
3412.83	6717.33
3415.96	6941.74
3419.08	7277.65
3422.2	7818.72
3425.32	9197.87
3428.44	12572.1
3431.55	21179.5
3434.67	28209.5
3437.78	21707.9
3440.89	12948.5
3444	9152.83
3447.12	7909.62
3450.22	7336.23
3453.33	6987.23
3456.44	6754.69
3459.54	6639.22
3462.65	6635.8
3465.75	6572.01
3468.85	6542.33
3471.95	6399.99
3475.05	6358.85
3478.15	6451.48
3481.24	6321.98
3484.34	6298.82
3487.43	6216.76
3490.53	6281.21
3493.62	6319.42
3496.71	6328.62
3499.79	6403.42
3502.88	6616.31
3505.97	6867.2
3509.05	7352.79
3512.14	7842.45
3515.22	8270.98
3518.3	8325.8
3521.38	7785.17
3524.46	6961.44
3527.54	6440.08
3530.61	6031.65
3533.69	5572.65
3536.76	5413.89
3539.83	5123.94
3542.9	4975.02
3545.97	4905.13
3549.04	4790.95
3552.11	4656.78
3555.18	4657.57
3558.24	4480.88
3561.3	4356.01
3564.37	4244.87
3567.43	4272.27
3570.49	4195.6
3573.55	4030.21
3576.61	4029.64
3579.66	3960.46
3582.72	3831.16
3585.77	3842.12
3588.82	3704.81
3591.87	3642.25
3594.92	3605.97
3597.97	3574.38
3601.02	3502.77
3604.07	3464.03
3607.11	3433.76
3610.16	3391.08
3613.2	3290.67
3616.24	3215.94
3619.28	3184.85
3622.32	3152.96
3625.36	3189.15
3628.39	3090.53
3631.43	3004.02
3634.46	2935.04
3637.5	2907.07
3640.53	2851.2
3643.56	2811.1
3646.59	2753.63
3649.62	2746.38
3652.64	2648.7
3655.67	2591.3
3658.69	2529.7
3661.72	2489.31
3664.74	2425.19
3667.76	2377.14
3670.78	2367.97
3673.79	2290.97
3676.81	2251.8
3679.83	2174.73
3682.84	2199.65
3685.86	2165.06
3688.87	2113.45
3691.88	2099.74
3694.89	2052.47
3697.9	2017.72
3700.91	1973.56
3703.91	1968.27
3706.92	1931.44
3709.92	1914.37
3712.92	1908.44
3715.92	1889.26
3718.92	1884.19
3721.92	1846.58
3724.92	1850.67
3727.92	1841.3
3730.91	1815.57
3733.91	1821.06
3736.9	1797.83
3739.89	1795.33
3742.88	1818.36
3745.87	1778.43
3748.86	1765.95
3751.85	1817.04
3754.83	1733.35
3757.82	1758.82
3760.8	1735.77
3763.78	1741.16
3766.76	1765.57
3769.74	1708.77
3772.72	1663.51
3775.7	1730.85
3778.67	1717.96
3781.65	1689.07
3784.62	1662.16
3787.6	1677.82
3790.57	1683.34
3793.54	1644.67
3796.51	1725.98
3799.47	1691.39
3802.44	1704.14
3805.41	1649.87
3808.37	1690.17
3811.33	1658.71
3814.3	1665.09
3817.26	1683.84
3820.22	1667.63
3823.18	1669.5
3826.13	1646.79
3829.09	1645.84
3832.04	1625.08
3835	1624.35
3837.95	1651.2
3840.9	1633.38
3843.85	1647.91
3846.8	1628.24
3849.75	1584.79
3852.69	1619.56
3855.64	1621.93
3858.58	1633.91
3861.53	1617.12
3864.47	1638.59
3867.41	1598.66
3870.35	1624.76
3873.29	1642.22
3876.22	1599.04
3879.16	1597.92
3882.1	1606.2
3885.03	1612.43
3887.96	1638.76
3890.89	1597.73
3893.82	1587.29
3896.75	1626.64
3899.68	1586.13
3902.61	1603.09
3905.53	1597.12
3908.46	1615.11
3911.38	1562.8
3914.3	1614.06
3917.23	1590.69
3920.15	1591.13
3923.06	1567.36
3925.98	1581.82
3928.9	1584.6
3931.81	1558.93
3934.73	1584.36
3937.64	1609.2
3940.55	1529.58
3943.46	1553.39
3946.37	1591.72
3949.28	1561.24
3952.19	1599.77
3955.09	1576.19
3958	1528.73
3960.9	1566.62
3963.8	1572.99
3966.71	1541.07
3969.61	1553.34
3972.51	1580.01
3975.4	1517.28
3978.3	1551.44
3981.2	1529.84
3984.09	1545.64
3986.99	1566.26
3989.88	1507.74
3992.77	1545.66
3995.66	1481.6
3998.55	1501.33
4001.43	1501.83
4004.32	1573.7
4007.21	1561.82
4010.09	1543.16
4012.98	1546.67
4015.86	1494.23
4018.74	1498.69
4021.62	1498.32
4024.5	1505.71
4027.37	1559.51
4030.25	1488.66
4033.13	1514.49
4036	1509.45
4038.87	1451.16
4041.75	1493.33
4044.62	1511.27
4047.49	1496.37
4050.35	1481.53
4053.22	1487.17
4056.09	1488.98
4058.95	1447.96
4061.82	1455.48
4064.68	1465.92
4067.54	1474.41
4070.4	1457.59
4073.26	1437.81
4076.12	1468.64
4078.98	1493.65
4081.83	1464.08
4084.69	1501.76
4087.54	1448.67
4090.4	1424.89
4093.25	1507.54
4096.1	1464.17
4098.95	1461.88
4101.8	1415.51
4104.64	1432.58
4107.49	1430.01
4110.33	1399.97
4113.18	1445.11
4116.02	1450.92
4118.86	1437.08
4121.7	1427.29
4124.54	1385.3
4127.38	1414.98
4130.22	1423.45
4133.05	1402.85
4135.89	1409.89
4138.72	1401.47
4141.56	1417.13
4144.39	1420.49
4147.22	1404.38
4150.05	1379.32
4152.88	1420.37
4155.7	1375.67
4158.53	1401.48
4161.36	1371.95
4164.18	1379.61
4167	1354.03
4169.82	1401.88
4172.65	1364.71
4175.46	1393.07
4178.28	1392.16
4181.1	1403.07
4183.92	1386.65
4186.73	1364.42
4189.55	1372.65
4192.36	1393.81
4195.17	1361.28
4197.98	1392.49
4200.79	1359.96
4203.6	1394.15
4206.41	1417.55
4209.21	1427.22
4212.02	1446.69
4214.83	1422.4
4217.63	1416.19
4220.43	1389.04
4223.23	1397.22
4226.03	1376.82
4228.83	1378.31
4231.63	1380.89
4234.42	1353.87
4237.22	1328.8
4240.01	1402.12
4242.81	1365.21
4245.6	1350.11
4248.39	1340.84
4251.18	1356.45
4253.97	1349
4256.76	1356.48
4259.55	1326.92
4262.33	1333.49
4265.12	1344.17
4267.9	1356.92
4270.68	1326.33
4273.47	1346.94
4276.25	1295.66
4279.03	1287.62
4281.8	1292.6
4284.58	1319.67
4287.36	1308.16
4290.13	1269.2
4292.91	1281.97
4295.68	1279.7
4298.45	1262.17
4301.22	1280.06
4303.99	1274.63
4306.76	1268.2
4309.53	1268.99
4312.3	1239.2
4315.06	1250.91
4317.83	1272.72
4320.59	1285.28
4323.35	1265.18
4326.11	1268.5
4328.87	1252.4
4331.63	1307.59
4334.39	1255.79
4337.15	1268.24
4339.9	1254.33
4342.66	1253.72
4345.41	1271.62
4348.17	1207.93
4350.92	1240.36
4353.67	1236.12
4356.42	1222.57
4359.17	1263.22
4361.91	1233.3
4364.66	1225.88
4367.41	1241.01
4370.15	1237.64
4372.89	1219.76
4375.63	1216.18
4378.38	1213.55
4381.12	1214.04
4383.86	1244.56
4386.59	1231.29
4389.33	1222.45
4392.07	1212.15
4394.8	1237.89
4397.53	1225.9
4400.27	1202.46
4403	1218.35
4405.73	1189.7
4408.46	1164.03
4411.19	1213.07
4413.92	1211.05
4416.64	1171.18
4419.37	1208.36
4422.09	1226.99
4424.82	1175.68
4427.54	1177.6
4430.26	1188.93
4432.98	1205.46
4435.7	1171.66
4438.42	1197.47
4441.13	1158.27
4443.85	1157.81
4446.57	1191.96
4449.28	1172.52
4451.99	1184.53
4454.71	1161.79
4457.42	1153.67
4460.13	1178.23
4462.83	1195.49
4465.54	1152.8
4468.25	1163.84
4470.95	1166.54
4473.66	1158.82
4476.36	1149.07
4479.07	1152.05
4481.77	1124.43
4484.47	1131.59
4487.17	1164.12
4489.87	1126.63
4492.56	1136.33
4495.26	1185.52
4497.96	1147.89
4500.65	1160.9
4503.34	1164.51
4506.04	1144.84
4508.73	1119.86
4511.42	1127.78
4514.11	1140
4516.8	1135.22
4519.48	1116.79
4522.17	1157.93
4524.85	1142.65
4527.54	1114.62
4530.22	1120.67
4532.9	1108.65
4535.58	1136.1
4538.27	1118.87
4540.94	1102.63
4543.62	1118.52
4546.3	1101.24
4548.98	1111.82
4551.65	1116.26
4554.33	1128.27
4557	1097.7
4559.67	1110.32
4562.34	1126.43
4565.01	1092.4
4567.68	1112.09
4570.35	1110.96
4573.02	1087.06
4575.68	1050.77
4578.35	1074.5
4581.01	1101.24
4583.67	1060.64
4586.34	1062.47
4589	1040.17
4591.66	1091.99
4594.31	1077.61
4596.97	1065.09
4599.63	1079.06
4602.29	1072.37
4604.94	1053.61
4607.59	1046.92
4610.25	1039.08
4612.9	1056.47
4615.55	1034.33
4618.2	1072.79
4620.85	1051.8
4623.5	1049.44
4626.14	1054.72
4628.79	1055.61
4631.43	1041.96
4634.08	1051.4
4636.72	1039.85
4639.36	1058.09
4642	1054.42
4644.64	1033.29
4647.28	1029.01
4649.92	1008.32
4652.56	1029.32
4655.19	1028.04
4657.83	1001.02
4660.46	1047.88
4663.1	1025.57
4665.73	997.175
4668.36	1008.07
4670.99	985.334
4673.62	1050.01
4676.24	991.349
4678.87	985.335
4681.5	1000.66
4684.12	1018.27
4686.75	984.113
4689.37	998.419
4691.99	1004.74
4694.61	996.375
4697.23	1015.11
4699.85	989.84
4702.47	993.79
4705.09	979.638
4707.7	1005.01
4710.32	980.598
4712.93	1002.57
4715.55	995.017
4718.16	961.432
4720.77	1005.87
4723.38	984.742
4725.99	994.312
4728.6	974.39
4731.21	997.608
4733.81	1001.53
4736.42	951.927
4739.02	969.393
4741.63	976.498
4744.23	971.114
4746.83	957.525
4749.43	990.634
4752.03	950.912
4754.63	980.561
4757.23	936.307
4759.82	968.431
4762.42	955.016
4765.01	967.966
4767.61	957.288
4770.2	958.829
4772.79	970.657
4775.38	977.953
4777.97	934.97
4780.56	954.806
4783.15	923.231
4785.74	970.549
4788.32	944.69
4790.91	969.253
4793.49	917.077
4796.07	947.49
4798.66	967.685
4801.24	942.052
4803.82	939.463
4806.4	927.81
4808.98	950.625
4811.55	948.195
4814.13	925.019
4816.71	908.842
4819.28	920.375
4821.85	894.888
4824.43	943.579
4827	916.839
4829.57	929.726
4832.14	884.409
4834.71	939.379
4837.28	921.028
4839.84	899.155
4842.41	903.971
4844.97	914.566
4847.54	916.848
4850.1	895.032
4852.66	898.518
4855.22	905.728
4857.78	888.208
4860.34	909.408
4862.9	943.266
4865.46	895.431
4868.01	914.226
4870.57	898.468
4873.12	878.957
4875.68	891.463
4878.23	851.713
4880.78	892.608
4883.33	851.529
4885.88	859.169
4888.43	837.104
4890.98	869.735
4893.53	896.43
4896.07	869.471
4898.62	855.603
4901.16	869.113
4903.7	887.459
4906.25	874.637
4908.79	854.562
4911.33	839.127
4913.87	892.906
4916.41	876.232
4918.94	888.276
4921.48	846.553
4924.02	813.226
4926.55	852.755
4929.08	873.258
4931.62	853.328
4934.15	862.092
4936.68	850.454
4939.21	858.928
4941.74	826.723
4944.27	854.634
4946.79	825.068
4949.32	862.64
4951.85	865.43
4954.37	839.465
4956.9	835.205
4959.42	838.219
4961.94	876.299
4964.46	862.881
4966.98	842.101
4969.5	821.137
4972.02	819.445
4974.53	799.597
4977.05	857.161
4979.57	840.987
4982.08	802.986
4984.59	784.349
4987.1	851.916
4989.62	808.979
4992.13	812.167
4994.64	849.544
4997.15	810.275
4999.65	800.226