File: Data/3-Raman/raw/bu19w-ff2-fi03-v_150 (500nm)_532nm_edge_100%_x100_vis_h50um_15sx2_04.txt
#Acq. time (s)=	15
#Accumulations=	2
#Range (cm-¹)=	100...5000
#Windows=	1
#Auto scanning=	Off
#Autofocus=	Off
#Macrospot=	Off
#AutoExposure=	Off
#Spike filter=	Multiple accum.
#Delay time (s)=	2
#Binning=	1
#Readout mode=	Signal
#DeNoise=	Off
#ICS correction=	On
#Dark correction=	Off
#Inst. Process=	Off
#Detector Gain=	Best Dynamic
#Detector ADC=	50 kHz HS
#Detector temperature (°C)=	-60.09
#Instrument=	LabRAM HR Evol
#Detector=	SIN-EM FIVIS
#Objective=	x100_VIS
#Grating=	150 (500nm)
#ND Filter=	100%
#Laser=	532nm_Edge
#Hole=	49.98
#Temperature=	0
#Range=	Visible
#StageXY=	75x50mm Scan+
#StageZ=	Z motor
#X (µm)=	0
#Y (µm)=	0
#Z (µm)=	-210.3
#Full time(s)=	36
#Project=	21_05_14
#Sample=	BU19w
#Site=
#Title=	BU19w-FF2-FI03-V_150 (500nm)_532nm_Edge_100%_x100_VIS_H50um_15sX2
#Remark=
#Date=	14.05.2021 17:31
#Acquired=	14.05.2021 17:31:19
102.699	1390.35
107.322	1356.66
111.942	1239.8
116.56	1146.74
121.173	1120.62
125.787	1057.97
130.398	1029.32
135.006	1059.93
139.613	936.906
144.215	922.323
148.817	994.892
153.417	1334.9
158.014	1813.07
162.607	1475.17
167.2	987.208
171.79	846.139
176.379	849.647
180.963	1070.99
185.547	1540.66
190.128	1428.14
194.705	1051.39
199.282	858.136
203.857	769.995
208.43	782.171
212.998	791.911
217.566	764.964
222.132	794.255
226.693	895.475
231.254	1129.63
235.813	1152.3
240.368	1479.68
244.923	1818.74
249.475	1372.34
254.023	1027.86
258.571	883.386
263.117	931.199
267.658	1171.88
272.199	2137.46
276.738	3260.44
281.273	2782.25
285.807	1634.21
290.34	1177.58
294.868	1070.95
299.396	1171.09
303.919	1190.79
308.443	1054.71
312.964	954.963
317.481	1032.22
321.998	1258.26
326.51	1609.29
331.023	1502.16
335.533	1247.79
340.039	1281.69
344.544	1625.75
349.046	1842.1
353.547	1511.28
358.045	1216.67
362.542	1055.22
367.036	1194.72
371.527	1123.26
376.017	937.675
380.503	889.33
384.99	945.466
389.471	1044.54
393.953	1089.47
398.43	949.308
402.908	864.59
407.381	849.325
411.854	1058.8
416.323	1204.53
420.791	1066.42
425.256	827.909
429.72	700.107
434.18	712.331
438.64	708.383
443.095	676.357
447.551	700.606
452.003	791.058
456.454	786.528
460.901	768.865
465.348	727.52
469.791	749.872
474.231	818.996
478.672	824.687
483.108	957.598
487.544	1073.29
491.976	1132.57
496.408	1186.35
500.836	1055.53
505.261	926.964
509.687	857.259
514.108	757.643
518.529	760.949
522.946	710.329
527.361	720.997
531.776	716.865
536.187	733.618
540.595	755.016
545.003	783.374
549.408	825.723
553.812	801.588
558.212	822.729
562.61	840.069
567.007	803.227
571.401	788.503
575.792	773.26
580.184	881.683
584.571	1176.79
588.956	1413.03
593.341	1119.22
597.722	919.567
602.101	960.777
606.48	1145.62
610.854	1151.66
615.227	970.083
619.597	828.077
623.967	784.701
628.334	709.104
632.698	738.653
637.06	791.502
641.422	803.25
645.779	805.419
650.135	801.592
654.491	888.945
658.842	1027.7
663.192	1211.28
667.539	1225.07
671.884	1241.73
676.23	1236.82
680.571	1122.97
684.91	933.622
689.247	768.163
693.583	717.668
697.916	664.862
702.247	633.765
706.576	622.735
710.902	639.001
715.229	634.686
719.551	636.289
723.872	647.415
728.19	647.846
732.506	646.502
736.82	651.142
741.134	680.241
745.444	708.737
749.752	677.249
754.058	688.892
758.362	753.175
762.664	770.23
766.964	908.269
771.264	1086.47
775.559	1328.67
779.853	1286.73
784.144	1090.13
788.434	935.628
792.722	822.746
797.007	809.432
801.29	804.492
805.572	742.784
809.851	715.304
814.13	678.091
818.406	706.818
822.679	697.24
826.95	705.367
831.219	684.891
835.486	695.222
839.752	747.43
844.015	754.278
848.276	803.589
852.535	759.072
856.792	736.643
861.047	702.048
865.3	692.563
869.551	681.851
873.8	652.32
878.047	637.009
882.292	683.818
886.534	679.944
890.775	637.424
895.014	654.282
899.251	706.897
903.486	680.911
907.719	687.174
911.95	682.024
916.179	691.858
920.406	694.137
924.63	710.506
928.853	710.675
933.074	737.764
937.293	782.744
941.51	836.048
945.723	977.643
949.936	997.518
954.147	970.596
958.356	866.238
962.563	882.278
966.768	836.793
970.971	812.816
975.172	788.935
979.371	783.288
983.568	779.814
987.761	764.563
991.954	762.518
996.145	745.202
1000.33	771.54
1004.52	792.725
1008.71	748.21
1012.89	818.296
1017.07	800.05
1021.25	828.684
1025.43	836.609
1029.6	856.311
1033.77	897.566
1037.95	971.96
1042.11	1126.12
1046.28	1432.42
1050.45	1890.08
1054.61	1874.13
1058.77	1500.92
1062.93	1164.9
1067.09	1081.65
1071.24	1019.56
1075.4	1080.1
1079.55	1252.98
1083.7	1559.36
1087.85	1869.15
1091.99	1938.67
1096.14	1675.13
1100.28	1604.64
1104.42	1782.9
1108.55	1965.43
1112.69	1896.89
1116.82	1672.17
1120.96	1593.54
1125.09	1573.28
1129.21	1718.66
1133.34	1732.97
1137.46	1506.5
1141.59	1276.8
1145.71	1165.61
1149.83	1242.16
1153.94	1389.28
1158.06	1403.22
1162.17	1341.23
1166.28	1180.99
1170.39	1143.13
1174.5	1040.13
1178.6	855.926
1182.7	830.413
1186.8	795.107
1190.9	783.256
1195	803.916
1199.1	787.495
1203.19	786.305
1207.28	752.685
1211.37	796.141
1215.46	826.276
1219.54	923.805
1223.63	948.698
1227.71	861.724
1231.79	857.37
1235.87	889.078
1239.95	929.369
1244.02	913.846
1248.09	827.108
1252.16	830.418
1256.23	755.939
1260.3	760.477
1264.36	752.133
1268.43	987.429
1272.49	1288.48
1276.55	936.417
1280.6	756.444
1284.66	720.79
1288.71	720.296
1292.76	728.696
1296.81	704.827
1300.86	691.904
1304.91	723.201
1308.95	725.3
1312.99	745.286
1317.03	712.625
1321.07	741.32
1325.11	717.273
1329.14	733.599
1333.18	711.479
1337.21	722.308
1341.24	731.014
1345.26	714.7
1349.29	736.298
1353.31	725.043
1357.33	749.544
1361.35	730.362
1365.37	763.869
1369.39	765.76
1373.4	1410.95
1377.41	1496.22
1381.43	912.282
1385.43	745.672
1389.44	769.17
1393.45	763.473
1397.45	784.516
1401.45	752.202
1405.45	726.862
1409.45	741.991
1413.44	726.601
1417.44	751.644
1421.43	758.892
1425.42	777.737
1429.41	792.369
1433.39	823.996
1437.38	809.085
1441.36	801.115
1445.34	828.505
1449.32	814.417
1453.3	770.586
1457.27	736.6
1461.24	720.168
1465.22	737.051
1469.19	742.188
1473.15	746.356
1477.12	692.52
1481.09	684.788
1485.05	761.103
1489.01	730.789
1492.97	695.743
1496.93	699.762
1500.88	722.378
1504.83	733.45
1508.79	717.457
1512.74	725.757
1516.68	718.599
1520.63	706.663
1524.57	710.294
1528.52	699.459
1532.46	721.644
1536.4	704.089
1540.33	727.26
1544.27	711.663
1548.2	729.984
1552.14	726.943
1556.07	725.722
1559.99	712.796
1563.92	718.19
1567.84	731.245
1571.77	717.207
1575.69	732.132
1579.61	719.034
1583.52	717.488
1587.44	716.861
1591.35	723.927
1595.27	719.437
1599.18	743.801
1603.09	749.991
1606.99	739.942
1610.9	735.674
1614.8	713.299
1618.7	733.112
1622.6	741.432
1626.5	762.335
1630.39	752.765
1634.29	735.665
1638.18	739.647
1642.07	750.572
1645.96	720.378
1649.85	759.26
1653.73	745.379
1657.62	736.221
1661.5	726.014
1665.38	758.925
1669.26	765.746
1673.13	742.598
1677.01	749.056
1680.88	757.068
1684.75	723.745
1688.62	742.124
1692.49	751.705
1696.35	763.064
1700.22	732.255
1704.08	743.296
1707.94	776.946
1711.8	770.553
1715.66	800.192
1719.51	783.454
1723.37	786.548
1727.22	825.254
1731.07	820.594
1734.92	800.979
1738.76	799.077
1742.61	810.215
1746.45	824.401
1750.29	811.122
1754.13	794.518
1757.97	772.392
1761.81	771.962
1765.64	800.933
1769.47	767.243
1773.31	796.91
1777.14	763.427
1780.96	789.781
1784.79	762.101
1788.61	778.385
1792.43	755.361
1796.25	789.545
1800.07	780.258
1803.89	799.835
1807.71	779.84
1811.52	793.63
1815.33	778.87
1819.14	787.409
1822.95	817.49
1826.76	776.632
1830.56	815.712
1834.37	806.54
1838.17	803.846
1841.97	827.302
1845.77	821.581
1849.56	786.673
1853.36	815.167
1857.15	826.53
1860.94	807.87
1864.73	813.474
1868.52	831.203
1872.31	836.041
1876.09	842.822
1879.87	823.06
1883.66	845.908
1887.43	822.329
1891.21	853.537
1894.99	831.308
1898.76	849.792
1902.53	834.498
1906.31	827.579
1910.08	851.283
1913.84	843.836
1917.61	823.763
1921.37	859.46
1925.14	838.808
1928.9	851.642
1932.66	831.952
1936.41	845.737
1940.17	853.942
1943.92	875.468
1947.68	822.194
1951.43	846.417
1955.18	861.823
1958.92	863.643
1962.67	865.386
1966.41	869.847
1970.16	909.503
1973.9	859.881
1977.64	886.948
1981.37	897.926
1985.11	889.107
1988.84	897.953
1992.57	887.01
1996.31	896.391
2000.03	922.288
2003.76	913.075
2007.49	903.565
2011.21	913.383
2014.93	900.435
2018.65	942.253
2022.37	907.431
2026.09	911.613
2029.81	924.768
2033.52	933.315
2037.23	931.53
2040.94	921.56
2044.65	917.859
2048.36	930.842
2052.07	943.954
2055.77	924.249
2059.47	963.075
2063.17	922.376
2066.87	924.92
2070.57	945.028
2074.27	931.037
2077.96	962.466
2081.65	977.283
2085.34	981.335
2089.03	988.739
2092.72	938.11
2096.41	981.533
2100.09	974.268
2103.77	975.216
2107.46	1002.96
2111.14	992.476
2114.81	968.958
2118.49	1038.99
2122.16	1005.49
2125.84	1014.62
2129.51	996.7
2133.18	1008.39
2136.85	1021.75
2140.51	1042.25
2144.18	1005.52
2147.84	1037.8
2151.5	998.435
2155.16	1048.08
2158.82	1066.55
2162.48	1028.54
2166.13	1066.48
2169.79	1016.28
2173.44	1093.14
2177.09	1040.76
2180.74	1046.75
2184.38	1075.48
2188.03	1064.69
2191.67	1082.48
2195.32	1082.48
2198.96	1088.96
2202.6	1097.43
2206.23	1074.14
2209.87	1103.1
2213.5	1105.68
2217.14	1097.27
2220.77	1116.45
2224.4	1149.52
2228.03	1159.55
2231.65	1218.68
2235.28	1327.99
2238.9	1381.98
2242.52	1436.12
2246.14	1315.67
2249.76	1237.8
2253.38	1181.23
2256.99	1169.35
2260.6	1150.77
2264.21	1141.45
2267.82	1159.61
2271.44	1152.42
2275.04	1128.7
2278.65	1151.66
2282.25	1141.98
2285.85	1190.17
2289.45	1168.25
2293.05	1173.69
2296.65	1147.02
2300.25	1176.13
2303.84	1178.45
2307.43	1170.14
2311.02	1184.43
2314.62	1265.8
2318.2	1337.42
2321.79	1305.18
2325.38	1206.22
2328.96	1202.95
2332.54	1206.04
2336.12	1211.83
2339.7	1209.9
2343.28	1210.68
2346.85	1230.99
2350.43	1235.27
2354	1221.72
2357.57	1261.26
2361.14	1243.85
2364.71	1263.69
2368.27	1266.05
2371.84	1291.68
2375.4	1300.47
2378.96	1297.4
2382.52	1260.44
2386.08	1284.41
2389.64	1287.46
2393.19	1264.23
2396.75	1289.12
2400.3	1315.49
2403.85	1272.69
2407.4	1314.47
2410.95	1304.53
2414.49	1304.91
2418.04	1283.51
2421.58	1304.64
2425.12	1308.66
2428.66	1299.11
2432.2	1365.75
2435.74	1327.06
2439.27	1324.58
2442.81	1324.95
2446.34	1327.33
2449.87	1315.02
2453.4	1353.03
2456.93	1335.38
2460.45	1352.88
2463.98	1368.97
2467.5	1337.72
2471.02	1399.63
2474.54	1398.36
2478.06	1365.56
2481.58	1396.6
2485.09	1382.57
2488.61	1378.89
2492.12	1418.55
2495.63	1393.06
2499.14	1417.47
2502.65	1400.15
2506.15	1420.94
2509.66	1439.66
2513.16	1401.93
2516.66	1413.79
2520.16	1436.99
2523.66	1431.27
2527.16	1453.08
2530.66	1451.95
2534.15	1443.86
2537.64	1418.53
2541.13	1441.79
2544.62	1455.68
2548.11	1460.48
2551.6	1463.66
2555.08	1438.06
2558.57	1461.54
2562.05	1493.11
2565.53	1449.87
2569.01	1445.12
2572.49	1464.05
2575.96	1469.31
2579.44	1461.55
2582.91	1505.77
2586.38	1469.49
2589.85	1513.94
2593.32	1497.11
2596.79	1483.49
2600.25	1454.61
2603.72	1519.84
2607.18	1530.41
2610.64	1526.89
2614.1	1522.11
2617.56	1503.31
2621.02	1497.66
2624.47	1514.62
2627.92	1533.24
2631.38	1536.16
2634.83	1534.74
2638.28	1526.33
2641.72	1554.87
2645.17	1551.75
2648.61	1527.34
2652.06	1581.62
2655.5	1521.31
2658.94	1570.07
2662.38	1577.74
2665.82	1553.3
2669.25	1593.72
2672.69	1583.48
2676.12	1571.61
2679.55	1590.04
2682.98	1570.51
2686.41	1593.04
2689.84	1563.41
2693.26	1610.66
2696.69	1573.46
2700.11	1606.34
2703.53	1561.61
2706.95	1575.8
2710.37	1576.47
2713.79	1575.59
2717.2	1589.95
2720.62	1603.65
2724.03	1606.3
2727.44	1594.17
2730.85	1605.3
2734.26	1567.73
2737.66	1586.37
2741.07	1601.94
2744.47	1573.04
2747.87	1564.8
2751.28	1654.36
2754.67	1612.83
2758.07	1615.74
2761.47	1609.7
2764.86	1619.45
2768.26	1670.32
2771.65	1602.36
2775.04	1633.06
2778.43	1644.64
2781.82	1633.46
2785.2	1657.03
2788.59	1619.43
2791.97	1634.35
2795.35	1676.64
2798.73	1673.46
2802.11	1638.41
2805.49	1679.29
2808.87	1646.06
2812.24	1662.38
2815.62	1628.05
2818.99	1670.56
2822.36	1661.06
2825.73	1662.86
2829.1	1683.47
2832.46	1693.21
2835.83	1666.9
2839.19	1658.61
2842.55	1681.4
2845.91	1686.08
2849.27	1700.89
2852.63	1692.93
2855.99	1675.79
2859.34	1701.95
2862.69	1741.34
2866.05	1712.44
2869.4	1766.91
2872.75	1754.69
2876.09	1771.56
2879.44	1746.99
2882.78	1733.55
2886.13	1741.64
2889.47	1804.67
2892.81	1765.17
2896.15	1750.92
2899.49	1792.19
2902.82	1759.41
2906.16	1811.65
2909.49	1848.56
2912.82	1822.05
2916.16	1851.97
2919.49	1888.35
2922.81	1941.69
2926.14	2013.49
2929.46	2040.72
2932.79	2073.1
2936.11	2131.83
2939.43	2174.45
2942.75	2055.07
2946.07	2008.45
2949.39	1975
2952.7	1949.97
2956.02	1952.53
2959.33	1913.17
2962.64	1946.01
2965.95	1972.71
2969.26	1950.5
2972.57	1965.44
2975.87	1981.17
2979.17	1950.49
2982.48	1886.11
2985.78	1912.92
2989.08	1890.96
2992.38	1872.83
2995.68	1834.14
2998.97	1801.09
3002.27	1779.2
3005.56	1754.64
3008.85	1773.46
3012.14	1752.82
3015.43	1707.6
3018.72	1693.42
3022	1709.41
3025.29	1743.39
3028.57	1697.11
3031.85	1720.64
3035.14	1694.93
3038.41	1675.84
3041.69	1686.08
3044.97	1701.13
3048.24	1694.34
3051.52	1689.53
3054.79	1633.47
3058.06	1702.38
3061.33	1698.81
3064.6	1655.53
3067.87	1686.03
3071.13	1659.23
3074.4	1663.67
3077.66	1686.13
3080.92	1684.88
3084.18	1623.23
3087.44	1691.9
3090.7	1652.7
3093.95	1640.31
3097.21	1636.7
3100.46	1675.88
3103.71	1643.31
3106.96	1645.06
3110.21	1652.99
3113.46	1636.11
3116.71	1628.83
3119.95	1653.95
3123.2	1667.63
3126.44	1664.11
3129.68	1681.56
3132.92	1639.9
3136.16	1645.8
3139.4	1698.38
3142.63	1664.2
3145.87	1666.33
3149.1	1606.54
3152.33	1629.66
3155.56	1639.45
3158.79	1611.05
3162.02	1629.4
3165.25	1704.9
3168.47	1679.11
3171.69	1650.38
3174.92	1678.78
3178.14	1663.22
3181.36	1654.38
3184.58	1628.24
3187.79	1578.19
3191.01	1607.26
3194.22	1620.1
3197.43	1674.79
3200.65	1648.57
3203.86	1636.69
3207.07	1620.13
3210.27	1595.12
3213.48	1642.54
3216.69	1665.24
3219.89	1630.89
3223.09	1623.34
3226.29	1643.43
3229.49	1612.27
3232.69	1656.18
3235.89	1629.94
3239.08	1608.61
3242.28	1614.98
3245.47	1629.94
3248.66	1646
3251.85	1663.11
3255.04	1631.57
3258.23	1589.32
3261.42	1618.44
3264.6	1645.42
3267.79	1627.33
3270.97	1640.63
3274.15	1644.37
3277.33	1607.74
3280.51	1643.33
3283.68	1645.48
3286.86	1639.86
3290.04	1632.43
3293.21	1651.68
3296.38	1607.02
3299.55	1611.38
3302.72	1620.21
3305.89	1623.12
3309.06	1629.58
3312.22	1625.44
3315.39	1627.9
3318.55	1627.45
3321.71	1606.15
3324.87	1614.25
3328.03	1621.4
3331.19	1655.1
3334.34	1601.06
3337.5	1637.83
3340.65	1639.67
3343.81	1589.96
3346.96	1657.64
3350.11	1648.98
3353.25	1641.44
3356.4	1621.72
3359.55	1615.4
3362.69	1593.11
3365.84	1624.65
3368.98	1638.33
3372.12	1644.67
3375.26	1661.48
3378.4	1611.35
3381.53	1633.86
3384.67	1665.97
3387.8	1650.84
3390.94	1671.75
3394.07	1704.33
3397.2	1694.18
3400.33	1721.31
3403.46	1738.22
3406.58	1847.49
3409.71	1951.35
3412.83	2415.95
3415.96	3458.72
3419.08	5804.85
3422.2	6600.93
3425.32	4472.2
3428.44	2737.09
3431.55	2111.69
3434.67	1934.47
3437.78	1812.85
3440.89	1781.07
3444	1748.91
3447.12	1763.47
3450.22	1660.5
3453.33	1723.36
3456.44	1704.97
3459.54	1693.21
3462.65	1706.1
3465.75	1753.96
3468.85	1720.57
3471.95	1766.38
3475.05	1798.08
3478.15	1887.53
3481.24	1906
3484.34	2038.84
3487.43	2191.51
3490.53	2408.95
3493.62	2756.58
3496.71	3208.4
3499.79	3709.28
3502.88	4041.23
3505.97	3981.25
3509.05	3469.97
3512.14	2975.08
3515.22	2518.97
3518.3	2325.09
3521.38	2052.2
3524.46	1973.28
3527.54	1872.32
3530.61	1822.01
3533.69	1788.63
3536.76	1763.42
3539.83	1678.08
3542.9	1716.55
3545.97	1664.96
3549.04	1662.2
3552.11	1661.95
3555.18	1674.27
3558.24	1647.01
3561.3	1598.51
3564.37	1641.76
3567.43	1630.13
3570.49	1599.25
3573.55	1619.39
3576.61	1622.39
3579.66	1600.59
3582.72	1624.18
3585.77	1633.48
3588.82	1625.57
3591.87	1592.92
3594.92	1590.49
3597.97	1622.13
3601.02	1592.08
3604.07	1599.77
3607.11	1644.29
3610.16	1606.45
3613.2	1606.37
3616.24	1576.11
3619.28	1609.17
3622.32	1609.25
3625.36	1585.86
3628.39	1615.21
3631.43	1561.57
3634.46	1587.29
3637.5	1595.38
3640.53	1620.59
3643.56	1599.15
3646.59	1582.17
3649.62	1583.28
3652.64	1585.46
3655.67	1592.58
3658.69	1551.71
3661.72	1585.91
3664.74	1565.75
3667.76	1535.27
3670.78	1537.93
3673.79	1592.59
3676.81	1569.04
3679.83	1613.45
3682.84	1589.82
3685.86	1554.85
3688.87	1534.09
3691.88	1585.34
3694.89	1584.26
3697.9	1574.82
3700.91	1550.28
3703.91	1592.19
3706.92	1529.47
3709.92	1557.83
3712.92	1557.48
3715.92	1567.64
3718.92	1591.02
3721.92	1574.28
3724.92	1592.61
3727.92	1530.84
3730.91	1545.11
3733.91	1662.05
3736.9	1554.12
3739.89	1550.75
3742.88	1539.63
3745.87	1591.13
3748.86	1567.36
3751.85	1599.59
3754.83	1563.48
3757.82	1557.75
3760.8	1622.99
3763.78	1589.63
3766.76	1563.98
3769.74	1566.88
3772.72	1600.16
3775.7	1592.87
3778.67	1561.14
3781.65	1581.4
3784.62	1590.4
3787.6	1579.66
3790.57	1598.4
3793.54	1572
3796.51	1610.82
3799.47	1562.05
3802.44	1571.92
3805.41	1607.36
3808.37	1556.92
3811.33	1581.18
3814.3	1560.1
3817.26	1603.41
3820.22	1567.27
3823.18	1566.25
3826.13	1600.35
3829.09	1624.97
3832.04	1579.53
3835	1574.02
3837.95	1595.14
3840.9	1562.06
3843.85	1586.05
3846.8	1623.47
3849.75	1581.93
3852.69	1572.81
3855.64	1585.65
3858.58	1595.68
3861.53	1595.12
3864.47	1595.51
3867.41	1640.82
3870.35	1573.94
3873.29	1574.09
3876.22	1627.84
3879.16	1610.4
3882.1	1580.26
3885.03	1632.61
3887.96	1560.88
3890.89	1578.5
3893.82	1594.99
3896.75	1611.26
3899.68	1616.91
3902.61	1595.4
3905.53	1596.16
3908.46	1608.38
3911.38	1581.06
3914.3	1633.27
3917.23	1596.45
3920.15	1608.41
3923.06	1590.39
3925.98	1609.63
3928.9	1607.6
3931.81	1575.22
3934.73	1574.78
3937.64	1563.24
3940.55	1615.75
3943.46	1598.39
3946.37	1614.69
3949.28	1570.82
3952.19	1605.51
3955.09	1631.75
3958	1600.6
3960.9	1598.25
3963.8	1577.78
3966.71	1608.22
3969.61	1624.36
3972.51	1597.29
3975.4	1585.49
3978.3	1544.72
3981.2	1598.09
3984.09	1635.06
3986.99	1618.19
3989.88	1570.26
3992.77	1604.35
3995.66	1607.68
3998.55	1622.63
4001.43	1603.91
4004.32	1595.86
4007.21	1600.37
4010.09	1602.94
4012.98	1588.15
4015.86	1584.93
4018.74	1582.67
4021.62	1617.1
4024.5	1603.29
4027.37	1657.13
4030.25	1609.53
4033.13	1605.43
4036	1588.82
4038.87	1566.4
4041.75	1627.98
4044.62	1598.49
4047.49	1603.98
4050.35	1632.84
4053.22	1625.94
4056.09	1605.5
4058.95	1594.65
4061.82	1607.1
4064.68	1633.18
4067.54	1601.86
4070.4	1619.17
4073.26	1615.04
4076.12	1610.88
4078.98	1585.27
4081.83	1577.19
4084.69	1566.14
4087.54	1574.55
4090.4	1662.12
4093.25	1571.02
4096.1	1577.52
4098.95	1591.89
4101.8	1634.56
4104.64	1601.81
4107.49	1592.43
4110.33	1540.9
4113.18	1612.47
4116.02	1590.88
4118.86	1594.64
4121.7	1590.71
4124.54	1616.27
4127.38	1575.51
4130.22	1614.42
4133.05	1580.23
4135.89	1601.99
4138.72	1566.92
4141.56	1611.82
4144.39	1607.41
4147.22	1630.54
4150.05	1605.54
4152.88	1603.49
4155.7	1614.5
4158.53	1586.38
4161.36	1597.92
4164.18	1624.13
4167	1606.35
4169.82	1585.74
4172.65	1617.02
4175.46	1601.37
4178.28	1598.51
4181.1	1595.75
4183.92	1592.08
4186.73	1655.99
4189.55	1563.5
4192.36	1582.78
4195.17	1610.12
4197.98	1609.13
4200.79	1613.03
4203.6	1586.51
4206.41	1594.32
4209.21	1601.14
4212.02	1617.76
4214.83	1587.72
4217.63	1583.67
4220.43	1553.73
4223.23	1582.8
4226.03	1571.47
4228.83	1598.88
4231.63	1570.02
4234.42	1591.82
4237.22	1569.05
4240.01	1554.21
4242.81	1590.17
4245.6	1580.36
4248.39	1568.39
4251.18	1525.31
4253.97	1555.07
4256.76	1575.8
4259.55	1576.57
4262.33	1579.41
4265.12	1549.19
4267.9	1625.59
4270.68	1568.13
4273.47	1548.65
4276.25	1567.21
4279.03	1578.59
4281.8	1585.79
4284.58	1545.27
4287.36	1563.21
4290.13	1564.86
4292.91	1563.59
4295.68	1568.58
4298.45	1564.4
4301.22	1536.78
4303.99	1561.94
4306.76	1541.44
4309.53	1556.63
4312.3	1578.87
4315.06	1594.79
4317.83	1556.68
4320.59	1573.38
4323.35	1582.87
4326.11	1575.05
4328.87	1544.75
4331.63	1517.46
4334.39	1508.47
4337.15	1527.08
4339.9	1503.05
4342.66	1563.71
4345.41	1513.39
4348.17	1510.04
4350.92	1568.19
4353.67	1544.77
4356.42	1522.21
4359.17	1546.66
4361.91	1540.47
4364.66	1545.54
4367.41	1518.85
4370.15	1560.77
4372.89	1561.52
4375.63	1549.87
4378.38	1521.68
4381.12	1575.74
4383.86	1563.28
4386.59	1540.02
4389.33	1525.36
4392.07	1478.42
4394.8	1517
4397.53	1545.7
4400.27	1496.72
4403	1519.18
4405.73	1525.16
4408.46	1566.42
4411.19	1486.8
4413.92	1531.91
4416.64	1497.46
4419.37	1559.86
4422.09	1517.17
4424.82	1506.81
4427.54	1488.07
4430.26	1552.98
4432.98	1540.45
4435.7	1516.3
4438.42	1522.39
4441.13	1505.38
4443.85	1478.87
4446.57	1477.48
4449.28	1515.93
4451.99	1527.01
4454.71	1506.49
4457.42	1500.56
4460.13	1464.24
4462.83	1505.8
4465.54	1483.23
4468.25	1520.73
4470.95	1504.65
4473.66	1510.84
4476.36	1471.8
4479.07	1527.8
4481.77	1462.45
4484.47	1497.33
4487.17	1465.59
4489.87	1468.49
4492.56	1485.64
4495.26	1505.33
4497.96	1445.59
4500.65	1489.4
4503.34	1487.83
4506.04	1514.97
4508.73	1436.03
4511.42	1507.77
4514.11	1447.96
4516.8	1447.58
4519.48	1442.1
4522.17	1467.49
4524.85	1474.75
4527.54	1443.73
4530.22	1437.2
4532.9	1413.68
4535.58	1498.97
4538.27	1440.38
4540.94	1461.8
4543.62	1423.42
4546.3	1442.8
4548.98	1440.82
4551.65	1429.52
4554.33	1449.41
4557	1422.55
4559.67	1440.02
4562.34	1466.47
4565.01	1430.02
4567.68	1437.42
4570.35	1431.17
4573.02	1432.23
4575.68	1435.24
4578.35	1400.6
4581.01	1433.3
4583.67	1380.96
4586.34	1404.81
4589	1416.52
4591.66	1429.24
4594.31	1403.13
4596.97	1398.44
4599.63	1419.24
4602.29	1367.97
4604.94	1396.59
4607.59	1380.36
4610.25	1447.47
4612.9	1367.43
4615.55	1413.75
4618.2	1426.17
4620.85	1375.77
4623.5	1416.72
4626.14	1382.56
4628.79	1393.67
4631.43	1410.1
4634.08	1398.74
4636.72	1402.88
4639.36	1384.77
4642	1403.49
4644.64	1359.41
4647.28	1371.08
4649.92	1389.85
4652.56	1330.26
4655.19	1345.65
4657.83	1337.85
4660.46	1368.33
4663.1	1377.68
4665.73	1362.94
4668.36	1371.89
4670.99	1337.12
4673.62	1368.43
4676.24	1380.71
4678.87	1382.84
4681.5	1338.89
4684.12	1361.25
4686.75	1379.11
4689.37	1389.23
4691.99	1310.16
4694.61	1380.94
4697.23	1408.96
4699.85	1342.18
4702.47	1346.33
4705.09	1309.76
4707.7	1353.4
4710.32	1339.34
4712.93	1349.03
4715.55	1369.92
4718.16	1327.42
4720.77	1324.35
4723.38	1323.76
4725.99	1332.37
4728.6	1354.61
4731.21	1311.03
4733.81	1326.47
4736.42	1345.2
4739.02	1291.2
4741.63	1327.97
4744.23	1347.73
4746.83	1305.72
4749.43	1295.62
4752.03	1302.6
4754.63	1322.02
4757.23	1310.83
4759.82	1319.14
4762.42	1289.87
4765.01	1307.52
4767.61	1295.96
4770.2	1326.16
4772.79	1300.49
4775.38	1270.25
4777.97	1319.92
4780.56	1306.79
4783.15	1299.38
4785.74	1279.39
4788.32	1331.49
4790.91	1286.42
4793.49	1318.05
4796.07	1278.8
4798.66	1301.53
4801.24	1264.68
4803.82	1281.92
4806.4	1307.45
4808.98	1258.1
4811.55	1257.15
4814.13	1308.18
4816.71	1305.2
4819.28	1231.6
4821.85	1264.43
4824.43	1263.71
4827	1281.48
4829.57	1223.94
4832.14	1262.86
4834.71	1302.07
4837.28	1276.12
4839.84	1222.08
4842.41	1223.85
4844.97	1266.55
4847.54	1264.56
4850.1	1274.67
4852.66	1271.09
4855.22	1261.19
4857.78	1267.77
4860.34	1236.35
4862.9	1206.7
4865.46	1251.24
4868.01	1256.25
4870.57	1180.39
4873.12	1232.2
4875.68	1227.17
4878.23	1265.99
4880.78	1185.99
4883.33	1254.42
4885.88	1220.67
4888.43	1251.19
4890.98	1237.63
4893.53	1255
4896.07	1241.33
4898.62	1214.54
4901.16	1234.18
4903.7	1188.25
4906.25	1189.86
4908.79	1215.26
4911.33	1203.45
4913.87	1192.73
4916.41	1195.19
4918.94	1170.23
4921.48	1220.54
4924.02	1188.47
4926.55	1212.5
4929.08	1205.59
4931.62	1172.65
4934.15	1179.17
4936.68	1201.17
4939.21	1179.75
4941.74	1182.32
4944.27	1215.17
4946.79	1218.13
4949.32	1195.95
4951.85	1213.28
4954.37	1209.09
4956.9	1173.85
4959.42	1168.7
4961.94	1196.27
4964.46	1161.55
4966.98	1174.84
4969.5	1166.24
4972.02	1180.56
4974.53	1168.27
4977.05	1140.26
4979.57	1173.99
4982.08	1167.81
4984.59	1187.14
4987.1	1204.1
4989.62	1145.7
4992.13	1166.24
4994.64	1116.28
4997.15	1141.94
4999.65	1139.6