File: Data/3-Raman/raw/bu19w-ff2-fi01-v_150 (500nm)_532nm_edge_100%_x100_vis_h50um_15sx2_01.txt
#Acq. time (s)=	15
#Accumulations=	2
#Range (cm-¹)=	100...5000
#Windows=	1
#Auto scanning=	Off
#Autofocus=	Off
#Macrospot=	Off
#AutoExposure=	Off
#Spike filter=	Multiple accum.
#Delay time (s)=	2
#Binning=	1
#Readout mode=	Signal
#DeNoise=	Off
#ICS correction=	On
#Dark correction=	Off
#Inst. Process=	Off
#Detector Gain=	Best Dynamic
#Detector ADC=	50 kHz HS
#Detector temperature (°C)=	-60.09
#Instrument=	LabRAM HR Evol
#Detector=	SIN-EM FIVIS
#Objective=	x100_VIS
#Grating=	150 (500nm)
#ND Filter=	100%
#Laser=	532nm_Edge
#Hole=	49.98
#Temperature=	0
#Range=	Visible
#StageXY=	75x50mm Scan+
#StageZ=	Z motor
#X (µm)=	0
#Y (µm)=	0
#Z (µm)=	-175.5
#Full time(s)=	34
#Project=	21_05_14
#Sample=	BU19w
#Site=
#Title=	BU19w-FF2-FI01-V_150 (500nm)_532nm_Edge_100%_x100_VIS_H50um_15sX2
#Remark=
#Date=	14.05.2021 16:35
#Acquired=	14.05.2021 16:35:59
102.699	1679.51
107.322	1543.44
111.942	1422.5
116.56	1332.8
121.173	1260.46
125.787	1249.43
130.398	1177.34
135.006	1185.57
139.613	1157.14
144.215	1095.6
148.817	1177.79
153.417	1407.25
158.014	1771.41
162.607	1608.67
167.2	1185.51
171.79	1045.59
176.379	1088.21
180.963	1277.72
185.547	1817.11
190.128	1667.89
194.705	1267.91
199.282	1106.46
203.857	1072.12
208.43	1069.6
212.998	1070.76
217.566	1070.71
222.132	1052.28
226.693	1113.08
231.254	1257.92
235.813	1342.82
240.368	1599.28
244.923	1804.11
249.475	1598.94
254.023	1302.93
258.571	1210.48
263.117	1219.12
267.658	1395.21
272.199	2116.84
276.738	3088.36
281.273	2799.21
285.807	1909.31
290.34	1417.83
294.868	1372.24
299.396	1422.96
303.919	1509.95
308.443	1355.71
312.964	1274.7
317.481	1269.44
321.998	1435.67
326.51	1698.86
331.023	1673.42
335.533	1403.09
340.039	1422.3
344.544	1624.56
349.046	1890
353.547	1668.09
358.045	1398.42
362.542	1356.03
367.036	1424.23
371.527	1403.33
376.017	1284.12
380.503	1229.67
384.99	1293.76
389.471	1333.86
393.953	1388.72
398.43	1362.05
402.908	1227.87
407.381	1242.14
411.854	1373.17
416.323	1619.64
420.791	1440.58
425.256	1180.29
429.72	1142.16
434.18	1108.14
438.64	1127.43
443.095	1117.49
447.551	1114.52
452.003	1188.06
456.454	1237.65
460.901	1176.57
465.348	1198.03
469.791	1205.55
474.231	1161.37
478.672	1226.8
483.108	1265.34
487.544	1358.64
491.976	1497.5
496.408	1464.54
500.836	1458.08
505.261	1331.75
509.687	1275.77
514.108	1199.17
518.529	1159.62
522.946	1215.48
527.361	1166.2
531.776	1191.3
536.187	1197.99
540.595	1188.44
545.003	1235.66
549.408	1305.03
553.812	1262.46
558.212	1290.04
562.61	1256.35
567.007	1218.99
571.401	1206.59
575.792	1252.19
580.184	1326.23
584.571	1593.13
588.956	1747.98
593.341	1539.7
597.722	1391.55
602.101	1420.5
606.48	1572.6
610.854	1613.69
615.227	1475.32
619.597	1317.06
623.967	1267.51
628.334	1214.22
632.698	1253.94
637.06	1308.12
641.422	1326.93
645.779	1300.45
650.135	1319.23
654.491	1333.7
658.842	1489.51
663.192	1577.79
667.539	1577.03
671.884	1651.32
676.23	1660.91
680.571	1611.86
684.91	1410.77
689.247	1363.09
693.583	1248.24
697.916	1227.39
702.247	1226.77
706.576	1200.15
710.902	1238.17
715.229	1226.09
719.551	1233.76
723.872	1226.53
728.19	1238.64
732.506	1231.35
736.82	1250.8
741.134	1268.47
745.444	1277.99
749.752	1236.45
754.058	1306.25
758.362	1306.96
762.664	1365.38
766.964	1441.95
771.264	1560.45
775.559	1754.73
779.853	1753.82
784.144	1585.19
788.434	1441.25
792.722	1392.55
797.007	1347.59
801.29	1326.89
805.572	1337.67
809.851	1325.59
814.13	1306.14
818.406	1295.37
822.679	1305.88
826.95	1263.71
831.219	1314.13
835.486	1321.53
839.752	1285.8
844.015	1298.33
848.276	1320.93
852.535	1353.32
856.792	1328.38
861.047	1311.04
865.3	1321.87
869.551	1301.62
873.8	1323.84
878.047	1297.57
882.292	1316.8
886.534	1323.36
890.775	1310.17
895.014	1299.35
899.251	1342.72
903.486	1337.41
907.719	1356.48
911.95	1355.93
916.179	1350.77
920.406	1330.56
924.63	1355.93
928.853	1383.21
933.074	1361.24
937.293	1463.16
941.51	1491.84
945.723	1585.27
949.936	1636.23
954.147	1564.77
958.356	1500.1
962.563	1514.37
966.768	1487.34
970.971	1437.41
975.172	1440.64
979.371	1394.45
983.568	1398.16
987.761	1392.09
991.954	1400.68
996.145	1416.78
1000.33	1385.59
1004.52	1386.34
1008.71	1407.61
1012.89	1428.42
1017.07	1424.74
1021.25	1425.25
1025.43	1455.92
1029.6	1478.11
1033.77	1527.62
1037.95	1510.46
1042.11	1687.31
1046.28	1950.11
1050.45	2265.65
1054.61	2302.84
1058.77	2067.93
1062.93	1815.52
1067.09	1653.71
1071.24	1676.59
1075.4	1678.82
1079.55	1838.16
1083.7	2018.21
1087.85	2325.46
1091.99	2388.47
1096.14	2253.19
1100.28	2088.13
1104.42	2190.68
1108.55	2355.35
1112.69	2325.9
1116.82	2158.09
1120.96	2077.98
1125.09	2101.29
1129.21	2177.11
1133.34	2220.92
1137.46	2043.4
1141.59	1913.39
1145.71	1772.37
1149.83	1852.66
1153.94	1967.08
1158.06	1990.52
1162.17	1897.54
1166.28	1827.98
1170.39	1804.16
1174.5	1708.82
1178.6	1554.87
1182.7	1561.59
1186.8	1543.5
1190.9	1527.07
1195	1537.81
1199.1	1540.84
1203.19	1537.54
1207.28	1541.36
1211.37	1512.92
1215.46	1579.45
1219.54	1711.33
1223.63	1690.2
1227.71	1597.77
1231.79	1625.25
1235.87	1716.69
1239.95	1718.41
1244.02	1683.45
1248.09	1679.67
1252.16	1651.35
1256.23	1592.32
1260.3	1529.45
1264.36	1608.85
1268.43	2025.46
1272.49	2771.06
1276.55	2057.1
1280.6	1567.67
1284.66	1563.81
1288.71	1517.6
1292.76	1553.58
1296.81	1517.97
1300.86	1521.38
1304.91	1549.72
1308.95	1542.84
1312.99	1556.58
1317.03	1581.88
1321.07	1551.59
1325.11	1574.78
1329.14	1545.03
1333.18	1576.89
1337.21	1530.21
1341.24	1560.46
1345.26	1563.56
1349.29	1577.64
1353.31	1552.95
1357.33	1612.68
1361.35	1629.57
1365.37	1586.57
1369.39	1690.99
1373.4	2939.77
1377.41	3324.98
1381.43	2021
1385.43	1649.34
1389.44	1609.7
1393.45	1617.03
1397.45	1731.06
1401.45	1635.93
1405.45	1592.2
1409.45	1554.48
1413.44	1544.46
1417.44	1569.92
1421.43	1595.3
1425.42	1555.97
1429.41	1565.48
1433.39	1559.62
1437.38	1549.55
1441.36	1602.72
1445.34	1557.83
1449.32	1538.56
1453.3	1557.44
1457.27	1535.77
1461.24	1550.11
1465.22	1579.82
1469.19	1577.21
1473.15	1545.22
1477.12	1560.01
1481.09	1627.53
1485.05	1552.02
1489.01	1540.17
1492.97	1578.22
1496.93	1534.41
1500.88	1575.61
1504.83	1535.43
1508.79	1581.13
1512.74	1581.13
1516.68	1570.63
1520.63	1559.31
1524.57	1570.4
1528.52	1608.8
1532.46	1548.46
1536.4	1586.02
1540.33	1546.09
1544.27	1586.59
1548.2	1579.61
1552.14	1561.89
1556.07	1600.08
1559.99	1600.28
1563.92	1611.94
1567.84	1594.43
1571.77	1605.87
1575.69	1607.6
1579.61	1585.15
1583.52	1606.04
1587.44	1598.86
1591.35	1632.08
1595.27	1580.65
1599.18	1620.61
1603.09	1594.51
1606.99	1612.72
1610.9	1620.4
1614.8	1608.16
1618.7	1606.53
1622.6	1594.39
1626.5	1599.8
1630.39	1609.38
1634.29	1638.37
1638.18	1623.39
1642.07	1617.54
1645.96	1672.26
1649.85	1596.7
1653.73	1597.79
1657.62	1612.2
1661.5	1630.29
1665.38	1650.03
1669.26	1608.88
1673.13	1612.57
1677.01	1598.53
1680.88	1625.99
1684.75	1648.45
1688.62	1656.25
1692.49	1716.34
1696.35	1646.06
1700.22	1686.33
1704.08	1650.87
1707.94	1677.92
1711.8	1624.09
1715.66	1681.3
1719.51	1659.94
1723.37	1673.48
1727.22	1631.23
1731.07	1683.88
1734.92	1623.96
1738.76	1682.69
1742.61	1679.6
1746.45	1670.66
1750.29	1634.78
1754.13	1629.39
1757.97	1707.61
1761.81	1703.14
1765.64	1677.55
1769.47	1703.18
1773.31	1684.54
1777.14	1687.55
1780.96	1658.4
1784.79	1675.13
1788.61	1646.17
1792.43	1621.85
1796.25	1676.32
1800.07	1684.21
1803.89	1702.77
1807.71	1649.68
1811.52	1671.67
1815.33	1644.07
1819.14	1703.61
1822.95	1689.23
1826.76	1698.97
1830.56	1724.26
1834.37	1713.37
1838.17	1730.46
1841.97	1728.36
1845.77	1684.92
1849.56	1718.12
1853.36	1671.96
1857.15	1699.26
1860.94	1719.58
1864.73	1696.17
1868.52	1724.99
1872.31	1698.45
1876.09	1707.35
1879.87	1669.64
1883.66	1670.17
1887.43	1681.93
1891.21	1683.61
1894.99	1699.88
1898.76	1734.09
1902.53	1743.1
1906.31	1736.67
1910.08	1753.73
1913.84	1707.51
1917.61	1710.82
1921.37	1705.5
1925.14	1724.45
1928.9	1745.56
1932.66	1750.96
1936.41	1651.82
1940.17	1730.79
1943.92	1709.25
1947.68	1695.51
1951.43	1744.94
1955.18	1763.57
1958.92	1753.12
1962.67	1730.3
1966.41	1771.15
1970.16	1756.62
1973.9	1752.1
1977.64	1772.49
1981.37	1759.86
1985.11	1761.88
1988.84	1791.71
1992.57	1763.32
1996.31	1724.54
2000.03	1769.07
2003.76	1799.8
2007.49	1763.31
2011.21	1745.32
2014.93	1768.27
2018.65	1790.51
2022.37	1765.85
2026.09	1812.7
2029.81	1759.39
2033.52	1758.15
2037.23	1759.15
2040.94	1732.79
2044.65	1800.47
2048.36	1751.34
2052.07	1772.95
2055.77	1762.81
2059.47	1762.35
2063.17	1741.35
2066.87	1775.72
2070.57	1757.69
2074.27	1795.08
2077.96	1766.14
2081.65	1784.34
2085.34	1795.01
2089.03	1797.75
2092.72	1793.98
2096.41	1742.21
2100.09	1776.93
2103.77	1806.73
2107.46	1825.04
2111.14	1787.39
2114.81	1804.54
2118.49	1833.2
2122.16	1806.35
2125.84	1808.15
2129.51	1808.69
2133.18	1810.1
2136.85	1860.2
2140.51	1816.68
2144.18	1831.11
2147.84	1861.98
2151.5	1831.31
2155.16	1848.45
2158.82	1802.58
2162.48	1811.02
2166.13	1814.25
2169.79	1859
2173.44	1836.16
2177.09	1831.68
2180.74	1804.63
2184.38	1852.19
2188.03	1870.6
2191.67	1842.36
2195.32	1845.73
2198.96	1831.95
2202.6	1859.48
2206.23	1854.49
2209.87	1795.8
2213.5	1817.75
2217.14	1829.7
2220.77	1802.23
2224.4	1826.24
2228.03	1845.59
2231.65	1846.72
2235.28	1876.58
2238.9	1887.89
2242.52	1885.29
2246.14	1857.55
2249.76	1802.93
2253.38	1844.37
2256.99	1823.41
2260.6	1867.71
2264.21	1888.67
2267.82	1841.57
2271.44	1844.15
2275.04	1892.17
2278.65	1890.5
2282.25	1846.33
2285.85	1838.41
2289.45	1840.54
2293.05	1831.25
2296.65	1887.4
2300.25	1874.32
2303.84	1844.67
2307.43	1865.88
2311.02	1874.52
2314.62	1987.09
2318.2	2087.85
2321.79	1969.85
2325.38	1871.99
2328.96	1865.12
2332.54	1844.67
2336.12	1893.8
2339.7	1919.95
2343.28	1851.93
2346.85	1863.59
2350.43	1878.87
2354	1881.83
2357.57	1896.78
2361.14	1915.3
2364.71	1892.98
2368.27	1921.09
2371.84	1892.9
2375.4	1896.92
2378.96	1914.99
2382.52	1860.52
2386.08	1865.26
2389.64	1856.6
2393.19	1886.94
2396.75	1897.71
2400.3	1850.67
2403.85	1895.06
2407.4	1902.24
2410.95	1872.59
2414.49	1878.13
2418.04	1860.19
2421.58	1875.68
2425.12	1897.25
2428.66	1872.18
2432.2	1900.19
2435.74	1878.49
2439.27	1891.25
2442.81	1884.59
2446.34	1881.83
2449.87	1903.85
2453.4	1893.49
2456.93	1887.99
2460.45	1939.09
2463.98	1907.5
2467.5	1876.59
2471.02	1900.95
2474.54	1921.86
2478.06	1927.43
2481.58	1894.94
2485.09	1928.26
2488.61	1912.59
2492.12	1918.77
2495.63	1946.91
2499.14	1894.8
2502.65	1929.94
2506.15	1902.2
2509.66	1910.71
2513.16	1891.7
2516.66	1880.57
2520.16	1924.16
2523.66	1922.39
2527.16	1913.25
2530.66	1909
2534.15	1881.31
2537.64	1913.98
2541.13	1902.25
2544.62	1934.91
2548.11	1941.92
2551.6	1906.69
2555.08	1908.61
2558.57	1890.12
2562.05	1933.65
2565.53	1936.11
2569.01	1935.39
2572.49	1914.46
2575.96	1933.26
2579.44	1930.68
2582.91	1915.87
2586.38	1883.66
2589.85	1928.17
2593.32	1931.25
2596.79	1925.34
2600.25	1903.29
2603.72	1912.86
2607.18	1953.69
2610.64	1909.93
2614.1	1905.39
2617.56	1942.44
2621.02	1914.71
2624.47	1921.98
2627.92	1918.35
2631.38	1945.99
2634.83	1926.93
2638.28	1911.39
2641.72	1976.71
2645.17	1967.27
2648.61	1953.64
2652.06	1934.79
2655.5	1951.62
2658.94	1985.22
2662.38	1886.01
2665.82	1963.68
2669.25	1939.1
2672.69	1913.98
2676.12	1943.55
2679.55	1931.33
2682.98	1911.22
2686.41	1944.56
2689.84	1975.35
2693.26	1922.64
2696.69	1948.56
2700.11	1918.96
2703.53	1918.66
2706.95	1905.94
2710.37	1932.8
2713.79	1930.28
2717.2	1938.41
2720.62	1925.41
2724.03	1919.99
2727.44	1941.88
2730.85	1935.63
2734.26	1917.16
2737.66	1919.3
2741.07	1944.57
2744.47	1954.44
2747.87	1922.98
2751.28	1914.95
2754.67	1930.97
2758.07	1911.48
2761.47	1928.16
2764.86	1943.62
2768.26	1939.83
2771.65	1934.98
2775.04	1955.24
2778.43	1940.32
2781.82	1900.76
2785.2	1958.99
2788.59	1938.15
2791.97	1915.27
2795.35	1904.83
2798.73	1913.66
2802.11	1951.56
2805.49	1918.19
2808.87	1907.22
2812.24	1908.34
2815.62	1911.15
2818.99	1915.15
2822.36	1899.88
2825.73	1967.74
2829.1	1881.03
2832.46	1913.07
2835.83	1883.01
2839.19	1930.62
2842.55	1919.01
2845.91	1900.51
2849.27	1929.54
2852.63	1889.07
2855.99	1875.86
2859.34	1888.19
2862.69	1906.25
2866.05	1917.88
2869.4	1884.3
2872.75	1914.51
2876.09	1908.95
2879.44	1901.48
2882.78	1929.67
2886.13	1926.61
2889.47	1867.96
2892.81	1911.68
2896.15	1897.5
2899.49	1899.09
2902.82	1908.91
2906.16	1837.2
2909.49	1852.34
2912.82	1893.97
2916.16	1915.36
2919.49	1908.22
2922.81	1895.36
2926.14	1904.8
2929.46	1910.37
2932.79	1922.09
2936.11	1885.69
2939.43	1919.08
2942.75	1947.72
2946.07	1929.41
2949.39	1888.5
2952.7	1886.09
2956.02	1907.46
2959.33	1883.13
2962.64	1869.09
2965.95	1877.05
2969.26	1853.89
2972.57	1911.04
2975.87	1906.11
2979.17	1863.22
2982.48	1817.59
2985.78	1836.87
2989.08	1852.45
2992.38	1897.25
2995.68	1836.02
2998.97	1883.83
3002.27	1829.99
3005.56	1859.1
3008.85	1853.49
3012.14	1846.09
3015.43	1817.89
3018.72	1833.01
3022	1838.69
3025.29	1870.86
3028.57	1827.47
3031.85	1820.83
3035.14	1767.74
3038.41	1843.28
3041.69	1836.56
3044.97	1800.55
3048.24	1829.81
3051.52	1797.59
3054.79	1793.73
3058.06	1848.48
3061.33	1799.38
3064.6	1824.45
3067.87	1797.07
3071.13	1788.21
3074.4	1835.3
3077.66	1807.49
3080.92	1741.79
3084.18	1813.03
3087.44	1801.12
3090.7	1815.26
3093.95	1787.66
3097.21	1783.11
3100.46	1780.47
3103.71	1793.61
3106.96	1769.74
3110.21	1770.07
3113.46	1767.5
3116.71	1794.53
3119.95	1788.25
3123.2	1799.09
3126.44	1776.54
3129.68	1777.81
3132.92	1731.4
3136.16	1786.89
3139.4	1778.46
3142.63	1767.17
3145.87	1775.99
3149.1	1770.58
3152.33	1746.03
3155.56	1804.5
3158.79	1760.85
3162.02	1720.05
3165.25	1740.21
3168.47	1756.41
3171.69	1762.98
3174.92	1674.96
3178.14	1729.04
3181.36	1754.53
3184.58	1735.04
3187.79	1752.65
3191.01	1761.65
3194.22	1737.29
3197.43	1779.56
3200.65	1759.96
3203.86	1728.07
3207.07	1739.09
3210.27	1734.03
3213.48	1759.55
3216.69	1744.2
3219.89	1735.53
3223.09	1743.2
3226.29	1747.12
3229.49	1696
3232.69	1717.08
3235.89	1753.68
3239.08	1700.02
3242.28	1697.85
3245.47	1750.96
3248.66	1684.13
3251.85	1711.76
3255.04	1726.06
3258.23	1725.86
3261.42	1693.89
3264.6	1694.14
3267.79	1701.84
3270.97	1713.22
3274.15	1736.07
3277.33	1711.84
3280.51	1724.47
3283.68	1704.64
3286.86	1720.92
3290.04	1697.25
3293.21	1709.8
3296.38	1673.69
3299.55	1634.23
3302.72	1686.82
3305.89	1661.17
3309.06	1666.65
3312.22	1675.78
3315.39	1681.04
3318.55	1663.48
3321.71	1688.57
3324.87	1683.34
3328.03	1676.25
3331.19	1649.43
3334.34	1669.05
3337.5	1679.36
3340.65	1679.28
3343.81	1681.41
3346.96	1701
3350.11	1648.98
3353.25	1624.47
3356.4	1659.43
3359.55	1684.22
3362.69	1639.31
3365.84	1675.59
3368.98	1637.39
3372.12	1704.13
3375.26	1654.87
3378.4	1667.09
3381.53	1662.22
3384.67	1665.97
3387.8	1668.82
3390.94	1665.12
3394.07	1688.22
3397.2	1710.29
3400.33	1745.02
3403.46	1778.1
3406.58	1826.57
3409.71	1977.05
3412.83	2174.98
3415.96	2972.58
3419.08	4698.35
3422.2	5793.53
3425.32	4255.49
3428.44	2670.25
3431.55	2106.92
3434.67	1877.2
3437.78	1774.68
3440.89	1743.86
3444	1740.33
3447.12	1672.89
3450.22	1646.21
3453.33	1673.83
3456.44	1653.58
3459.54	1677.99
3462.65	1684.25
3465.75	1681.81
3468.85	1703.5
3471.95	1698.17
3475.05	1763.06
3478.15	1783.49
3481.24	1830.38
3484.34	1887.71
3487.43	1958.34
3490.53	2128.66
3493.62	2373.5
3496.71	2689.63
3499.79	3065.21
3502.88	3314.52
3505.97	3333.96
3509.05	2993.56
3512.14	2520.7
3515.22	2287.54
3518.3	2036.16
3521.38	1947.59
3524.46	1834.59
3527.54	1759.99
3530.61	1711.53
3533.69	1726.32
3536.76	1658.66
3539.83	1637.49
3542.9	1621.21
3545.97	1601.67
3549.04	1614.94
3552.11	1558.88
3555.18	1556.94
3558.24	1558.01
3561.3	1546.41
3564.37	1563.1
3567.43	1577.04
3570.49	1566.06
3573.55	1527.39
3576.61	1545.56
3579.66	1537.99
3582.72	1535.02
3585.77	1535.81
3588.82	1522.22
3591.87	1528.46
3594.92	1552.59
3597.97	1529.3
3601.02	1516.34
3604.07	1502.3
3607.11	1497.69
3610.16	1539.34
3613.2	1528.91
3616.24	1501.53
3619.28	1488.4
3622.32	1480.06
3625.36	1468.04
3628.39	1459.77
3631.43	1510.72
3634.46	1505.4
3637.5	1474.94
3640.53	1489.81
3643.56	1484.36
3646.59	1477.73
3649.62	1472.23
3652.64	1486.75
3655.67	1457.17
3658.69	1482.05
3661.72	1437.07
3664.74	1487.53
3667.76	1467.39
3670.78	1446.44
3673.79	1466.13
3676.81	1446.27
3679.83	1460.37
3682.84	1454.62
3685.86	1457.41
3688.87	1464.98
3691.88	1439.46
3694.89	1434.5
3697.9	1455.32
3700.91	1422.16
3703.91	1439.29
3706.92	1439.19
3709.92	1458
3712.92	1425.27
3715.92	1428.72
3718.92	1378.76
3721.92	1401
3724.92	1407.88
3727.92	1414.66
3730.91	1415.6
3733.91	1418.29
3736.9	1365.62
3739.89	1408.95
3742.88	1424.53
3745.87	1425.69
3748.86	1417.23
3751.85	1448.6
3754.83	1446.75
3757.82	1417.39
3760.8	1441.03
3763.78	1410.64
3766.76	1412.55
3769.74	1419.32
3772.72	1377.04
3775.7	1390.63
3778.67	1373.14
3781.65	1432.19
3784.62	1374.2
3787.6	1407.86
3790.57	1413.4
3793.54	1363.4
3796.51	1357.84
3799.47	1362.84
3802.44	1389.66
3805.41	1352.3
3808.37	1399.1
3811.33	1379.81
3814.3	1385.13
3817.26	1378.2
3820.22	1359
3823.18	1378.7
3826.13	1349.18
3829.09	1342.37
3832.04	1387.84
3835	1413.53
3837.95	1386.06
3840.9	1322.4
3843.85	1380.48
3846.8	1380.6
3849.75	1375.07
3852.69	1364.82
3855.64	1362.19
3858.58	1372.02
3861.53	1365.53
3864.47	1362.86
3867.41	1314.09
3870.35	1349.57
3873.29	1345.72
3876.22	1349.42
3879.16	1374.1
3882.1	1384.23
3885.03	1342.33
3887.96	1350.33
3890.89	1341.94
3893.82	1325.71
3896.75	1345.84
3899.68	1339.97
3902.61	1299.3
3905.53	1363.54
3908.46	1345.05
3911.38	1340.85
3914.3	1370.1
3917.23	1336.22
3920.15	1330.98
3923.06	1341.88
3925.98	1308.51
3928.9	1329.68
3931.81	1329.04
3934.73	1304.74
3937.64	1311.4
3940.55	1325.64
3943.46	1327.45
3946.37	1301.62
3949.28	1341.97
3952.19	1322.05
3955.09	1280.21
3958	1311.23
3960.9	1326.05
3963.8	1294.92
3966.71	1291.66
3969.61	1293.25
3972.51	1277.55
3975.4	1307.87
3978.3	1304.48
3981.2	1308.75
3984.09	1312.96
3986.99	1289.27
3989.88	1293.24
3992.77	1311.86
3995.66	1294.9
3998.55	1280.87
4001.43	1289.97
4004.32	1279.87
4007.21	1299.67
4010.09	1309.83
4012.98	1251.52
4015.86	1265.53
4018.74	1251.56
4021.62	1291.65
4024.5	1299.93
4027.37	1264.71
4030.25	1271.09
4033.13	1288.12
4036	1239.4
4038.87	1265.22
4041.75	1257.92
4044.62	1261.25
4047.49	1276.3
4050.35	1291.43
4053.22	1259.12
4056.09	1264.69
4058.95	1238.12
4061.82	1249.42
4064.68	1254.91
4067.54	1237.03
4070.4	1258.05
4073.26	1243.05
4076.12	1229.96
4078.98	1277.28
4081.83	1260.29
4084.69	1281.3
4087.54	1245.69
4090.4	1223.77
4093.25	1239.92
4096.1	1269.73
4098.95	1227.27
4101.8	1220.91
4104.64	1204.66
4107.49	1252.91
4110.33	1237.51
4113.18	1249.36
4116.02	1241.48
4118.86	1245.27
4121.7	1226.67
4124.54	1237.52
4127.38	1249.54
4130.22	1240.32
4133.05	1234.29
4135.89	1174.66
4138.72	1229.16
4141.56	1224.39
4144.39	1207.15
4147.22	1229.14
4150.05	1234.39
4152.88	1186.34
4155.7	1222.98
4158.53	1246.9
4161.36	1211.52
4164.18	1210.39
4167	1186.79
4169.82	1203.36
4172.65	1173.03
4175.46	1209.22
4178.28	1207.32
4181.1	1203.54
4183.92	1201.77
4186.73	1185.37
4189.55	1201.37
4192.36	1201.9
4195.17	1195.71
4197.98	1205.25
4200.79	1200.08
4203.6	1208.66
4206.41	1192.67
4209.21	1180.59
4212.02	1182.23
4214.83	1201.98
4217.63	1194.53
4220.43	1166.16
4223.23	1222.51
4226.03	1185.14
4228.83	1172.58
4231.63	1138.28
4234.42	1181.35
4237.22	1212.65
4240.01	1189.39
4242.81	1190.01
4245.6	1139.8
4248.39	1174.17
4251.18	1188.58
4253.97	1179.93
4256.76	1123.14
4259.55	1162.5
4262.33	1167.87
4265.12	1162.27
4267.9	1149.63
4270.68	1179.24
4273.47	1137.16
4276.25	1164.43
4279.03	1156.28
4281.8	1142.96
4284.58	1149.72
4287.36	1116.87
4290.13	1135.55
4292.91	1122.93
4295.68	1125.63
4298.45	1170.89
4301.22	1124.81
4303.99	1122.34
4306.76	1128.02
4309.53	1135.84
4312.3	1134.45
4315.06	1129.84
4317.83	1125.14
4320.59	1112.21
4323.35	1116.51
4326.11	1115.73
4328.87	1140.36
4331.63	1130.33
4334.39	1115.18
4337.15	1099.07
4339.9	1104.48
4342.66	1131.36
4345.41	1092.07
4348.17	1121.17
4350.92	1084.1
4353.67	1076.69
4356.42	1085.54
4359.17	1130.19
4361.91	1058.21
4364.66	1096.78
4367.41	1095.43
4370.15	1108.39
4372.89	1102.76
4375.63	1044.71
4378.38	1067.7
4381.12	1076.35
4383.86	1076.97
4386.59	1099.57
4389.33	1035.97
4392.07	1080.05
4394.8	1092.14
4397.53	1045.82
4400.27	1095.73
4403	1082.46
4405.73	1082.72
4408.46	1063.17
4411.19	1112.11
4413.92	1066.25
4416.64	1045.04
4419.37	1081.11
4422.09	1052.67
4424.82	1044.06
4427.54	1050.07
4430.26	1065.48
4432.98	1022.26
4435.7	1062.72
4438.42	1059.12
4441.13	1038.72
4443.85	1053.94
4446.57	1017.71
4449.28	1039.15
4451.99	1059.51
4454.71	1048.29
4457.42	1010.71
4460.13	1044.68
4462.83	1020.87
4465.54	1069.67
4468.25	1035.4
4470.95	1044.36
4473.66	1020.75
4476.36	980.322
4479.07	1028.56
4481.77	1021.97
4484.47	1030.11
4487.17	1021.31
4489.87	1015.51
4492.56	1052.71
4495.26	989.611
4497.96	1032.42
4500.65	996.642
4503.34	1050.02
4506.04	1015.46
4508.73	973.446
4511.42	1019.51
4514.11	996.635
4516.8	982.23
4519.48	974.335
4522.17	984.534
4524.85	998.954
4527.54	975.091
4530.22	972.523
4532.9	977.47
4535.58	970.678
4538.27	963.992
4540.94	952.975
4543.62	983.716
4546.3	995.235
4548.98	998.231
4551.65	949.974
4554.33	937.096
4557	952.488
4559.67	959.476
4562.34	947.238
4565.01	925.754
4567.68	937.492
4570.35	948.144
4573.02	949.214
4575.68	949.768
4578.35	921.231
4581.01	924.87
4583.67	927.719
4586.34	954.532
4589	962.712
4591.66	988.301
4594.31	942.154
4596.97	949.235
4599.63	946.707
4602.29	909.243
4604.94	916.633
4607.59	933.949
4610.25	955.651
4612.9	940.002
4615.55	908.956
4618.2	925.275
4620.85	937.201
4623.5	904.958
4626.14	920.049
4628.79	898.734
4631.43	921.46
4634.08	951.848
4636.72	912.566
4639.36	918.563
4642	899.277
4644.64	911.268
4647.28	932.38
4649.92	878.182
4652.56	890
4655.19	870.91
4657.83	892.83
4660.46	879.284
4663.1	920.5
4665.73	912.166
4668.36	921.867
4670.99	895.707
4673.62	894.164
4676.24	892.606
4678.87	869.677
4681.5	923.123
4684.12	904.689
4686.75	852.448
4689.37	872.279
4691.99	912.325
4694.61	901.643
4697.23	883.07
4699.85	907.4
4702.47	892.095
4705.09	872.234
4707.7	887.373
4710.32	900.249
4712.93	888.217
4715.55	863.632
4718.16	854.921
4720.77	890.268
4723.38	847.547
4725.99	883.14
4728.6	863.161
4731.21	857.932
4733.81	862.918
4736.42	886.003
4739.02	851.133
4741.63	840.005
4744.23	881.228
4746.83	836.909
4749.43	859.763
4752.03	850.757
4754.63	838.286
4757.23	858.898
4759.82	872.783
4762.42	876.428
4765.01	834.65
4767.61	867.204
4770.2	837.906
4772.79	832.562
4775.38	835.228
4777.97	827.594
4780.56	821.099
4783.15	814.615
4785.74	848.158
4788.32	845.129
4790.91	823.837
4793.49	859.795
4796.07	830.559
4798.66	808.221
4801.24	810.015
4803.82	810.754
4806.4	810.467
4808.98	779.04
4811.55	819.079
4814.13	825.765
4816.71	812.932
4819.28	794.265
4821.85	795.263
4824.43	789.313
4827	793.742
4829.57	837.858
4832.14	778.443
4834.71	805.265
4837.28	792.539
4839.84	791.514
4842.41	820.78
4844.97	810.145
4847.54	818.173
4850.1	823.336
4852.66	777.462
4855.22	823.336
4857.78	778.581
4860.34	779.577
4862.9	805.055
4865.46	812.685
4868.01	767.476
4870.57	806.074
4873.12	780.571
4875.68	760.976
4878.23	760.309
4880.78	785.709
4883.33	783.787
4885.88	759.28
4888.43	757.38
4890.98	751.865
4893.53	772.538
4896.07	762.202
4898.62	753.05
4901.16	771.286
4903.7	790.776
4906.25	779.113
4908.79	755.431
4911.33	759.097
4913.87	788.982
4916.41	767.525
4918.94	756.857
4921.48	747.38
4924.02	785.74
4926.55	740.409
4929.08	757.302
4931.62	764.826
4934.15	746.03
4936.68	741.529
4939.21	727.246
4941.74	741.716
4944.27	760.008
4946.79	731.596
4949.32	729.557
4951.85	737.084
4954.37	715.855
4956.9	754.747
4959.42	724.053
4961.94	719.924
4964.46	729.204
4966.98	732.392
4969.5	740.29
4972.02	699.88
4974.53	723.445
4977.05	753.116
4979.57	740.481
4982.08	719.355
4984.59	730.967
4987.1	718.329
4989.62	732.397
4992.13	695.361
4994.64	697.296
4997.15	722.48
4999.65	678.147