File: Data/3-Raman/raw/bu19w-e-ff11b-fi05-v_1800 (450-850nm)_532nm_edge_100%_x100_vis_h50um_30sx2_01.txt
#Acq. time (s)=	30
#Accumulations=	2
#Range (cm-¹)=	1200...2365
#Windows=	3
#Auto scanning=	Off
#Autofocus=	Off
#Macrospot=	Off
#AutoExposure=	Off
#Spike filter=	Multiple accum.
#Delay time (s)=	2
#Binning=	1
#Readout mode=	Signal
#DeNoise=	Off
#ICS correction=	On
#Dark correction=	Off
#Inst. Process=	Off
#Detector Gain=	Best Dynamic
#Detector ADC=	50 kHz HS
#Detector temperature (°C)=	-60.28
#Instrument=	LabRAM HR Evol
#Detector=	SIN-EM FIVIS
#Objective=	x100_VIS
#Grating=	1800 (450-850nm)
#ND Filter=	100%
#Laser=	532nm_Edge
#Hole=	49.98
#Temperature=	0
#Range=	Visible
#StageXY=	75x50mm Scan+
#StageZ=	Z motor
#X (µm)=	0
#Y (µm)=	0
#Z (µm)=	-263.7
#Full time(mm:ss)=	3:18
#Project=	21_11_04
#Sample=	BU19w
#Site=
#Title=	BU19w-E-FF11b-FI05-V_1800 (450-850nm)_532nm_Edge_100%_x100_VIS_H50um_30sX2
#Remark=
#Date=	04.11.2021 18:58
#Acquired=	04.11.2021 18:58:56
1202.73	20.9987
1203.85	20.9583
1204.96	20.9476
1206.07	18.7644
1207.18	19.8079
1208.29	20.8591
1209.4	17.6399
1210.51	20.8211
1211.62	19.7251
1212.73	23.9627
1213.84	18.6311
1214.95	19.6948
1216.06	20.7393
1217.17	20.7114
1218.28	21.7549
1219.39	18.5627
1220.5	20.6809
1221.61	21.7213
1222.72	24.8537
1223.82	23.7606
1224.93	21.6399
1226.04	23.7565
1227.15	24.7764
1228.25	25.7536
1229.36	21.6277
1230.47	28.9591
1231.57	23.6432
1232.68	24.687
1233.79	23.6397
1234.89	24.7024
1236	21.5525
1237.1	24.6823
1238.21	22.5496
1239.31	19.3926
1240.42	20.4408
1241.52	24.6264
1242.63	22.5375
1243.74	23.5881
1244.84	21.4793
1245.94	20.4119
1247.05	23.5484
1248.15	21.4401
1249.25	20.3948
1250.36	22.4732
1251.46	23.5011
1252.56	22.4393
1253.66	19.31
1254.77	20.3626
1255.87	22.4526
1256.97	24.5435
1258.07	25.5789
1259.18	22.4426
1260.28	29.7439
1261.38	32.8771
1262.48	37.0531
1263.58	44.4121
1264.68	30.8311
1265.78	27.6896
1266.88	22.482
1267.98	24.609
1269.08	30.9104
1270.18	25.6472
1271.28	22.4966
1272.38	24.6165
1273.48	26.7396
1274.58	27.7961
1275.68	28.8622
1276.78	28.8842
1277.87	32.0638
1278.97	31.0332
1280.07	37.3371
1281.17	73.1549
1282.26	178.442
1283.36	440.851
1284.46	139.635
1285.55	39.4882
1286.65	32.1122
1287.75	28.9394
1288.84	30.0029
1289.94	21.5961
1291.04	22.6443
1292.13	24.7517
1293.23	23.7103
1294.32	25.8357
1295.42	24.8183
1296.51	22.7249
1297.61	24.8188
1298.7	25.8668
1299.79	25.8675
1300.89	22.7003
1301.98	22.7109
1303.08	21.6487
1304.17	22.7028
1305.26	23.7433
1306.36	21.6194
1307.45	23.7311
1308.54	22.6799
1309.63	22.69
1310.73	22.6901
1311.82	25.8672
1312.91	21.6417
1314	21.6389
1315.09	24.8169
1316.18	19.538
1317.28	19.5412
1318.37	21.6576
1319.46	23.7692
1320.55	18.482
1321.64	21.628
1322.73	22.668
1323.82	20.5615
1324.91	23.7232
1325.99	20.5181
1327.08	21.5925
1328.17	17.405
1329.26	21.6283
1330.35	18.4533
1331.44	21.5854
1332.53	24.7134
1333.62	20.482
1334.7	20.463
1335.79	21.4975
1336.88	21.4879
1337.96	22.5202
1339.05	21.4654
1340.14	23.5636
1341.23	21.4652
1342.31	22.4935
1343.4	24.5772
1344.48	22.4819
1345.57	19.3246
1346.66	21.383
1347.74	20.3245
1348.83	24.48
1349.91	21.3394
1351	23.4007
1352.08	22.3617
1353.17	21.3653
1354.25	21.2993
1355.33	24.4095
1356.42	24.408
1357.5	25.4336
1358.58	22.3027
1359.67	26.4316
1360.75	21.2347
1361.83	23.2999
1362.92	25.3707
1364	25.378
1365.08	25.3611
1366.16	24.3031
1367.24	23.2536
1368.33	36.7004
1369.41	31.5311
1370.49	28.4113
1371.57	23.2154
1372.65	26.2843
1373.73	26.2737
1374.81	30.3868
1375.89	29.3576
1376.97	34.473
1378.05	36.5882
1379.13	37.6232
1380.21	40.6442
1381.29	42.6627
1382.37	46.6946
1383.45	51.7743
1384.53	70.2569
1385.61	169.928
1386.68	917.688
1387.76	180.476
1388.84	54.9258
1389.92	40.4958
1390.99	31.2581
1392.07	27.1346
1393.15	28.1456
1394.23	28.138
1395.3	26.1029
1396.38	25.0719
1397.46	24.0361
1398.53	26.0894
1399.61	20.9822
1400.68	24.0646
1401.76	25.1081
1402.83	25.1509
1403.91	25.1361
1404.99	24.0999
1406.06	30.2362
1407.13	37.4194
1408.21	64.0907
1409.28	34.364
1410.36	23.066
1411.43	24.0748
1412.5	25.1451
1413.58	19.9939
1414.65	21.0465
1415.72	22.0774
1416.8	21.06
1417.87	20.0379
1418.94	19.0121
1420.01	24.133
1421.08	21.0405
1422.16	20.0402
1423.23	24.0783
1424.3	16.9121
1425.37	17.9536
1426.44	22.0426
1427.51	20.9916
1428.58	22.0162
1429.65	21.0067
1430.72	20.0083
1431.79	18.982
1432.86	19.9854
1433.93	22.0199
1435	17.9327
1436.07	21.0023
1437.14	18.9479
1438.21	17.9269
1439.28	23.0588
1440.35	22.047
1441.41	22.0424
1442.48	18.9733
1443.55	16.9142
1444.62	18.9798
1445.69	23.0794
1446.75	18.9707
1447.82	17.9425
1448.89	17.9483
1449.95	17.9389
1451.02	19.9828
1452.09	18.9537
1453.15	17.9346
1454.22	16.9079
1455.28	19.9832
1456.35	17.9335
1457.41	19.9753
1458.48	18.9535
1459.54	16.9047
1460.61	18.9471
1461.67	16.8891
1462.74	16.8749
1463.8	15.8568
1464.86	16.8603
1465.93	19.907
1466.99	16.8334
1468.05	18.8708
1469.12	17.8442
1470.18	18.8505
1471.24	21.8957
1472.31	20.8734
1473.37	18.8287
1474.43	18.8293
1475.49	15.7734
1476.55	20.8513
1477.62	14.7449
1478.68	18.8004
1479.74	15.7379
1480.8	18.7688
1481.86	15.7329
1482.92	13.7084
1483.98	19.7868
1485.04	17.6932
1486.1	19.7555
1487.16	23.8046
1488.22	20.7503
1489.28	17.7046
1490.34	17.6997
1491.4	18.7034
1492.46	18.7024
1493.52	15.6679
1494.57	16.6794
1495.63	15.6511
1496.69	17.6624
1497.75	17.661
1498.81	17.6635
1499.86	18.6774
1500.92	14.6345
1501.98	15.6405
1503.03	16.6377
1504.09	17.648
1505.15	17.6407
1506.2	15.6147
1507.26	18.6427
1508.32	18.641
1509.37	16.6264
1510.43	17.6277
1511.48	19.6106
1512.54	17.5731
1513.59	15.5674
1514.65	19.5785
1515.7	16.5484
1516.76	19.5511
1517.81	17.5513
1518.86	15.5499
1519.92	19.5615
1520.97	19.5663
1522.02	17.5544
1523.08	17.5396
1524.13	21.5295
1525.18	17.528
1526.24	18.5438
1527.29	16.535
1528.34	16.5286
1529.39	15.5228
1530.44	18.5332
1531.5	16.5332
1532.55	17.5435
1533.6	16.5521
1534.65	20.5589
1535.7	16.5285
1536.75	17.5092
1537.8	18.4971
1538.85	17.5025
1539.9	18.5427
1540.95	20.55
1542	18.5274
1543.05	20.5105
1544.1	17.5044
1545.15	18.5261
1546.2	17.5295
1547.25	16.533
1548.29	19.5341
1549.34	16.4968
1550.39	18.5859
1551.44	19.5699
1552.49	18.5792
1553.53	17.552
1554.58	19.5356
1555.63	17.5322
1556.68	19.5343
1557.72	20.5275
1558.77	20.504
1559.82	21.4893
1560.86	17.4884
1561.91	19.503
1562.95	19.5003
1564	19.5144
1565.04	16.4493
1566.09	20.4948
1567.13	17.5081
1568.18	16.4991
1569.22	17.4876
1570.27	18.489
1571.31	17.4823
1572.36	20.4692
1573.4	19.4609
1574.44	21.4746
1575.49	19.487
1576.53	18.4748
1577.57	20.4444
1578.62	19.44
1579.66	16.4534
1580.7	19.4408
1581.74	19.4283
1582.79	18.4273
1583.83	19.4218
1584.87	21.4157
1585.91	18.4177
1586.95	21.3924
1587.99	23.3841
1589.03	16.4269
1590.07	19.4177
1591.12	17.4272
1592.16	21.3929
1593.2	20.3724
1594.24	18.376
1595.28	18.377
1596.32	18.375
1597.35	18.3797
1598.39	23.3304
1599.43	19.3454
1600.47	19.3291
1601.51	18.3163
1602.55	19.2897
1603.59	21.2575
1604.63	22.2476
1605.66	22.2547
1606.7	17.3159
1607.74	23.2226
1608.78	21.3316
1609.81	21.7854
1610.85	20.2324
1611.89	19.3114
1612.92	20.2351
1613.96	20.3525
1615	20.5705
1616.03	19.3715
1617.07	21.7679
1618.1	21.6635
1619.14	19.4423
1620.17	21.637
1621.21	19.0169
1622.24	20.8142
1623.28	21.1188
1624.31	21.6656
1625.35	19.9517
1626.38	21.0253
1627.41	23.3935
1628.45	19.9172
1629.48	19.469
1630.51	20.1287
1631.3	19.2137
1632.34	20.2166
1633.39	23.1573
1634.43	22.178
1635.48	19.216
1636.52	20.1909
1637.57	23.1362
1638.61	20.1793
1639.66	22.1468
1640.7	17.2326
1641.75	20.1809
1642.79	18.2095
1643.83	20.1714
1644.88	19.1877
1645.92	20.17
1646.96	21.1458
1648.01	19.1801
1649.05	19.1965
1650.09	20.1892
1651.13	21.1869
1652.18	18.2306
1653.22	22.1689
1654.26	19.2187
1655.3	20.2236
1656.34	20.236
1657.38	19.2439
1658.42	23.181
1659.47	17.2512
1660.51	21.205
1661.55	20.2333
1662.59	21.251
1663.63	21.2194
1664.67	20.2579
1665.71	16.3172
1666.75	20.2383
1667.79	17.265
1668.83	17.2851
1669.86	20.2463
1670.9	19.2735
1671.94	20.2644
1672.98	20.2659
1674.02	21.2639
1675.06	19.2973
1676.1	22.2684
1677.13	18.3078
1678.17	19.2836
1679.21	17.2979
1680.25	17.2914
1681.28	19.2643
1682.32	17.2885
1683.35	20.251
1684.39	19.2565
1685.43	17.2806
1686.46	17.2878
1687.5	18.2711
1688.54	16.2869
1689.57	18.2472
1690.6	19.2403
1691.64	21.2196
1692.68	16.2754
1693.71	20.2012
1694.74	17.2388
1695.78	17.2442
1696.81	17.2421
1697.85	17.2264
1698.88	15.2512
1699.92	20.1696
1700.95	17.2137
1701.98	15.2354
1703.01	17.1951
1704.05	16.2133
1705.08	17.195
1706.11	18.1674
1707.14	15.2065
1708.18	16.1662
1709.21	17.1317
1710.24	18.1123
1711.27	17.1408
1712.3	20.065
1713.33	15.1467
1714.36	18.0694
1715.4	17.0991
1716.43	15.1347
1717.46	15.1088
1718.49	18.013
1719.52	16.0647
1720.55	16.0579
1721.58	18.9604
1722.61	16.9991
1723.64	16.0214
1724.66	16.9784
1725.69	17.9277
1726.72	17.9196
1727.75	17.9187
1728.78	15.9203
1729.81	14.969
1730.83	14.9798
1731.86	17.8768
1732.89	17.8637
1733.92	15.9095
1734.95	14.9262
1735.97	15.8801
1737	16.8333
1738.03	16.8213
1739.05	17.7634
1740.08	13.9003
1741.1	16.761
1742.13	15.7965
1743.16	15.7921
1744.18	13.8692
1745.21	15.7819
1746.23	17.6799
1747.26	16.7077
1748.28	16.7055
1749.31	12.8939
1750.33	14.816
1751.36	14.813
1752.38	17.6625
1753.4	16.6952
1754.43	15.7295
1755.45	13.8145
1756.47	15.7021
1757.5	15.6935
1758.52	17.6039
1759.54	16.6523
1760.57	14.7428
1761.59	14.7341
1762.61	16.6398
1763.63	13.7893
1764.66	14.7536
1765.68	18.5654
1766.7	15.7064
1767.72	15.6991
1768.74	16.6327
1769.76	16.6203
1770.78	15.6804
1771.8	14.7416
1772.82	14.7509
1773.84	17.6124
1774.86	16.6678
1775.88	14.7768
1776.9	16.6764
1777.92	19.5215
1778.94	15.6979
1779.96	16.6559
1780.98	14.7565
1782	15.7183
1783.02	14.7738
1784.04	14.7845
1785.05	15.7424
1786.07	15.7404
1787.09	14.801
1788.11	14.8369
1789.12	17.7276
1790.14	14.8597
1791.16	14.8456
1792.18	15.803
1793.19	12.9332
1794.21	15.8082
1795.23	14.8776
1796.24	14.8887
1797.26	18.7446
1798.27	17.7891
1799.29	14.8973
1800.3	14.8892
1801.32	15.8488
1802.33	15.8562
1803.35	16.8294
1804.36	13.9522
1805.38	13.9656
1806.39	16.8653
1807.41	16.8668
1808.42	16.8689
1809.43	16.8719
1810.45	14.9434
1811.46	12.0507
1812.47	15.9144
1813.49	13.0284
1814.5	16.9076
1815.51	14.981
1816.53	14.0168
1817.54	12.0724
1818.55	15.945
1819.56	15.9516
1820.57	15.9592
1821.58	13.0652
1822.6	15.0052
1823.61	17.9054
1824.62	15.0074
1825.63	14.0424
1826.64	15.0129
1827.65	15.9871
1828.66	15.9814
1829.67	15.9777
1830.68	21.7848
1831.69	17.9218
1832.7	15.9931
1833.71	18.9053
1834.72	15.0025
1835.73	14.023
1836.74	16.9602
1837.75	15.9442
1838.75	15.016
1839.76	12.1081
1840.77	14.9782
1841.78	15.9195
1842.79	14.9515
1843.79	15.9146
1844.8	16.8796
1845.81	14.9687
1846.81	12.0393
1847.82	14.9346
1848.83	17.8098
1849.83	14.9029
1850.84	15.8489
1851.85	17.7642
1852.85	16.8028
1853.86	14.8697
1854.86	18.6906
1855.87	14.8461
1856.87	13.8867
1857.88	17.7074
1858.88	14.8218
1859.89	13.863
1860.89	14.8294
1861.9	13.8739
1862.9	17.6851
1863.9	15.761
1864.91	14.7923
1865.91	16.6752
1866.92	16.6479
1867.92	15.6857
1868.92	15.686
1869.92	16.6331
1870.93	13.7798
1871.93	14.7228
1872.93	15.6637
1873.93	18.5006
1874.93	15.638
1875.94	18.452
1876.94	15.5907
1877.94	10.8901
1878.94	17.5263
1879.94	14.6747
1880.94	14.6689
1881.94	15.5826
1882.94	16.5884
1883.94	12.7295
1884.94	17.4545
1885.94	15.5835
1886.94	15.5693
1887.94	14.6088
1888.94	14.5914
1889.94	14.5943
1890.94	16.4812
1891.94	15.5372
1892.94	16.4592
1893.93	15.5053
1894.93	14.5628
1895.93	16.4503
1896.93	14.5794
1897.93	12.6971
1898.92	14.5658
1899.92	14.5599
1900.92	16.4468
1901.91	15.5207
1902.91	17.3975
1903.91	14.5729
1904.9	16.4511
1905.9	17.3773
1906.9	13.6159
1907.89	13.6226
1908.89	13.6295
1909.88	13.6463
1910.88	13.658
1911.87	15.5408
1912.87	16.4829
1913.86	17.442
1914.86	15.5688
1915.85	14.6243
1916.85	15.5577
1917.84	15.5572
1918.84	17.4623
1919.83	13.7015
1920.82	17.489
1921.82	14.6595
1922.81	14.6529
1923.8	15.591
1924.79	15.5905
1925.79	16.5529
1926.78	17.5161
1927.77	15.6305
1928.76	20.3773
1929.75	14.7066
1930.75	15.6661
1931.74	16.6082
1932.73	15.652
1933.72	18.5234
1934.71	12.8642
1935.7	14.7725
1936.69	15.7164
1937.68	16.6556
1938.67	16.6651
1939.66	12.8629
1940.65	19.562
1941.64	17.6373
1942.63	14.8005
1943.62	13.8365
1944.61	18.6263
1945.6	17.6876
1946.59	15.781
1947.58	15.7777
1948.57	14.8233
1949.55	16.7518
1950.54	13.9026
1951.53	14.8815
1952.52	13.928
1953.5	16.7945
1954.49	13.891
1955.48	13.901
1956.47	13.9225
1957.45	14.8947
1958.44	16.8199
1959.43	16.8122
1960.41	14.8812
1961.4	14.8749
1962.38	12.9582
1963.37	17.7606
1964.36	15.8432
1965.34	14.8845
1966.33	14.8966
1967.31	16.8224
1968.3	17.784
1969.28	16.8057
1970.26	14.8733
1971.25	16.785
1972.23	13.9106
1973.22	14.8607
1974.2	16.7737
1975.18	15.8215
1976.17	16.7867
1977.15	18.702
1978.13	14.8575
1979.12	16.7741
1980.1	13.8961
1981.08	16.7626
1982.06	15.8005
1983.05	14.8294
1984.03	16.7367
1985.01	15.7704
1985.99	14.8198
1986.97	19.6009
1987.95	15.7543
1988.93	16.6521
1989.91	16.6138
1990.89	17.5463
1991.88	13.8438
1992.86	17.143
1993.84	18.2901
1994.82	15.896
1995.8	15.4599
1996.78	14.8412
1997.76	13.6664
1998.73	14.9391
1999.71	15.8458
2000.69	15.7465
2001.67	15.7665
2002.65	16.4435
2003.63	16.0546
2004.6	15.8378
2005.58	16.2949
2006.56	15.8273
2007.54	14.8358
2008.52	14.7767
2009.49	15.9857
2010.47	14.8363
2011.45	15.5888
2012.42	16.4744
2013.41	16.45
2014.4	14.5459
2015.39	17.3694
2016.38	17.3881
2017.37	14.5582
2018.35	14.5359
2019.34	14.5193
2020.33	14.5163
2021.32	17.3275
2022.31	16.3805
2023.29	13.5595
2024.28	17.2816
2025.27	15.3942
2026.25	15.4036
2027.24	16.3732
2028.23	17.2717
2029.21	16.3644
2030.2	14.4447
2031.19	15.3954
2032.17	13.5426
2033.16	17.2977
2034.14	12.5983
2035.13	14.4773
2036.11	18.2292
2037.1	16.3628
2038.08	14.4855
2039.07	14.4759
2040.05	14.4609
2041.03	18.1792
2042.02	15.375
2043	16.3098
2043.99	15.3935
2044.97	13.5184
2045.95	14.4956
2046.94	14.4645
2047.92	16.3147
2048.9	18.1907
2049.88	12.6091
2050.87	16.3458
2051.85	16.3428
2052.83	14.4828
2053.81	15.4342
2054.79	14.498
2055.78	13.5559
2056.76	16.3581
2057.74	17.3014
2058.72	14.5088
2059.7	16.3819
2060.68	14.5094
2061.66	14.5128
2062.64	16.3936
2063.62	15.4652
2064.6	11.7227
2065.58	17.3684
2066.56	18.3153
2067.54	15.5059
2068.52	13.6317
2069.5	14.5566
2070.48	16.4592
2071.46	16.4804
2072.43	16.4769
2073.41	15.5356
2074.39	15.5451
2075.37	14.6279
2076.35	15.5755
2077.32	14.6166
2078.3	15.5675
2079.28	16.5288
2080.26	16.5379
2081.23	14.6448
2082.21	14.6473
2083.19	14.6465
2084.16	17.4818
2085.14	15.5929
2086.12	14.6609
2087.09	17.5077
2088.07	18.456
2089.04	13.7296
2090.02	16.5789
2090.99	12.795
2091.97	14.7081
2092.94	14.7253
2093.92	10.9335
2094.89	15.6834
2095.87	14.7252
2096.84	17.5685
2097.81	14.7138
2098.79	14.7104
2099.76	15.6591
2100.74	14.7189
2101.71	14.7219
2102.68	16.6151
2103.65	17.561
2104.63	14.7211
2105.6	15.6824
2106.57	15.6872
2107.54	15.6801
2108.52	14.7168
2109.49	16.6245
2110.46	17.5748
2111.43	16.6198
2112.4	15.6721
2113.38	18.5344
2114.35	13.7805
2115.32	14.7284
2116.29	16.6195
2117.26	13.7686
2118.23	17.5518
2119.2	14.6927
2120.17	15.6346
2121.14	16.594
2122.11	15.6585
2123.08	17.5637
2124.05	12.8095
2125.02	13.7354
2125.98	15.6129
2126.95	17.4923
2127.92	16.542
2128.89	17.4857
2129.86	15.592
2130.83	18.419
2131.79	18.4097
2132.76	15.5694
2133.73	16.5152
2134.7	14.6274
2135.67	16.5054
2136.63	15.5557
2137.6	14.6176
2138.57	14.6166
2139.53	18.375
2140.5	14.5987
2141.46	15.5333
2142.43	16.4784
2143.4	16.4426
2144.36	14.5804
2145.33	16.4542
2146.29	17.3888
2147.26	15.5013
2148.22	16.4331
2149.19	14.5408
2150.15	17.3402
2151.12	14.5329
2152.08	17.3504
2153.05	15.4656
2154.01	15.4533
2154.97	14.4932
2155.94	15.4144
2156.9	14.4801
2157.86	18.2271
2158.83	17.2883
2159.79	14.4724
2160.75	16.3299
2161.72	16.326
2162.68	15.3899
2163.64	17.2478
2164.6	15.3732
2165.56	16.3077
2166.53	16.2989
2167.49	14.42
2168.45	18.1293
2169.41	17.2157
2170.37	15.3656
2171.33	13.4855
2172.29	18.1182
2173.25	17.1889
2174.21	19.0529
2175.17	17.1917
2176.13	15.3283
2177.09	15.328
2178.05	16.2519
2179.01	14.3917
2179.97	15.32
2180.93	15.3169
2181.89	14.3827
2182.85	16.2292
2183.81	14.3622
2184.76	17.1446
2185.72	13.4451
2186.68	16.244
2187.64	14.3954
2188.6	15.3118
2189.55	15.2959
2190.51	16.2254
2191.47	14.3743
2192.42	15.3082
2193.38	17.1803
2194.34	15.3394
2195.3	14.4014
2196.25	16.2401
2197.21	17.1588
2198.16	16.2415
2199.12	16.2622
2200.07	15.3611
2201.03	14.4406
2201.99	15.3073
2202.94	13.4824
2203.9	14.4516
2204.85	15.3526
2205.8	14.4136
2206.76	17.2016
2207.71	17.2161
2208.67	16.2966
2209.62	17.2293
2210.58	10.7167
2211.53	16.3207
2212.48	13.5245
2213.44	15.3837
2214.39	13.5345
2215.34	14.4717
2216.29	13.5373
2217.25	12.6043
2218.2	16.3411
2219.15	13.5486
2220.1	15.4204
2221.06	16.3452
2222.01	16.3356
2222.96	13.5424
2223.91	14.493
2224.86	15.4429
2225.81	11.7106
2226.76	12.6571
2227.72	16.4097
2228.67	14.531
2229.62	14.5405
2230.57	14.5525
2231.52	17.3848
2232.47	16.4582
2233.42	15.5291
2234.37	15.5279
2235.31	12.6948
2236.26	14.5787
2237.21	13.6499
2238.16	16.497
2239.11	13.6791
2240.06	14.6114
2241.01	15.5687
2241.96	17.4621
2242.9	16.519
2243.85	16.515
2244.8	14.6453
2245.75	16.55
2246.69	13.7212
2247.64	16.5624
2248.59	12.774
2249.53	16.5634
2250.48	16.5516
2251.43	18.4364
2252.37	13.7197
2253.32	12.7929
2254.26	13.7487
2255.21	16.5935
2256.16	16.6033
2257.1	16.6147
2258.05	12.8211
2258.99	13.7779
2259.94	15.6851
2260.88	15.6976
2261.83	12.8477
2262.77	17.621
2263.71	16.6928
2264.66	16.712
2265.6	17.6713
2266.55	16.7013
2267.49	14.7827
2268.43	14.7814
2269.38	14.7973
2270.32	14.8127
2271.26	13.8667
2272.2	16.7425
2273.15	17.7037
2274.09	14.8363
2275.03	11.0107
2275.97	13.8914
2276.92	13.9053
2277.86	14.8854
2278.8	18.7277
2279.74	13.9096
2280.68	11.983
2281.62	13.8996
2282.56	16.7892
2283.5	15.8548
2284.44	13.9492
2285.38	15.8772
2286.32	15.8728
2287.26	17.8176
2288.2	14.9283
2289.14	17.7974
2290.08	14.9008
2291.02	16.8363
2291.96	14.9242
2292.9	14.9367
2293.84	18.7921
2294.78	13.002
2295.72	16.8451
2296.65	15.8775
2297.59	17.8209
2298.53	13.9797
2299.47	12.0579
2300.41	14.9561
2301.34	13.9965
2302.28	13.9945
2303.22	13.9937
2304.15	15.9329
2305.09	18.8398
2306.03	15.9479
2306.97	14.9804
2307.9	15.9408
2308.84	16.9132
2309.77	16.9289
2310.71	15.9574
2311.64	15.928
2312.58	13.9906
2313.51	15.938
2314.45	16.9271
2315.39	13.0519
2316.32	17.8637
2317.25	14.9717
2318.19	15.9316
2319.12	15.9224
2320.06	14.9568
2320.99	14.0003
2321.92	17.882
2322.86	15.9524
2323.79	16.9219
2324.72	16.9066
2325.66	21.7187
2326.59	32.3091
2327.52	84.3336
2328.46	54.4509
2329.39	25.5231
2330.32	21.6686
2331.25	14.9322
2332.18	17.8166
2333.12	17.8077
2334.05	13.9486
2334.98	13.9436
2335.91	13.9435
2336.84	15.8637
2337.77	12.9764
2338.7	13.9375
2339.63	14.8957
2340.56	17.7643
2341.49	15.8251
2342.42	13.9
2343.35	17.733
2344.28	14.8589
2345.21	13.8926
2346.14	14.843
2347.07	15.797
2348	16.7593
2348.93	13.8779
2349.85	16.7121
2350.78	14.8171
2351.71	13.8393
2352.64	16.6696
2353.57	14.7631
2354.5	14.7698
2355.42	14.7647
2356.35	15.6963
2357.28	14.7349
2358.21	15.6771
2359.13	15.6719
2360.06	16.6079
2360.99	17.5402
2361.91	15.6275
2362.84	16.5618
2363.77	13.716
2364.69	13.708
2364.92	15.5963