File: Data/3-Raman/raw/bu19w-d-ff2-fi07-v_1800 (450-850nm)_532nm_edge_100%_x100_vis_lwd_h50um_30sx2_01.txt
#Acq. time (s)=	30
#Accumulations=	2
#Range (cm-¹)=	1200...2365
#Windows=	3
#Auto scanning=	Off
#Autofocus=	Off
#Macrospot=	Off
#AutoExposure=	Off
#Spike filter=	Multiple accum.
#Delay time (s)=	2
#Binning=	1
#Readout mode=	Signal
#DeNoise=	Off
#ICS correction=	On
#Dark correction=	Off
#Inst. Process=	Off
#Detector Gain=	Best Dynamic
#Detector ADC=	50 kHz HS
#Detector temperature (°C)=	-60.09
#Instrument=	LabRAM HR Evol
#Detector=	SIN-EM FIVIS
#Objective=	x100_VIS_LWD
#Grating=	1800 (450-850nm)
#ND Filter=	100%
#Laser=	532nm_Edge
#Hole=	49.98
#Temperature=	0
#Range=	Visible
#StageXY=	75x50mm Scan+
#StageZ=	Z motor
#X (µm)=	0
#Y (µm)=	0
#Z (µm)=	58.6
#Full time(mm:ss)=	3:23
#Project=	21_11_22
#Sample=	BU19w
#Site=
#Title=	BU19w-D-FF2-FI07-V_1800 (450-850nm)_532nm_Edge_100%_x100_VIS_LWD_H50um_30sX2
#Remark=
#Date=	22.11.2021 13:19
#Acquired=	22.11.2021 13:19:23
1202.84	47.7768
1203.95	41.2565
1205.06	43.3519
1206.17	48.6542
1207.29	48.6316
1208.39	49.6262
1209.51	50.6236
1210.62	44.1871
1211.72	46.3102
1212.84	40.9805
1213.94	44.1107
1215.05	44.0607
1216.16	39.7878
1217.27	40.8303
1218.38	42.9382
1219.49	45.0014
1220.6	40.6889
1221.71	39.5859
1222.81	41.6982
1223.92	48.0256
1225.03	43.7065
1226.14	46.752
1227.24	48.9903
1228.35	56.208
1229.46	66.7094
1230.56	75.0982
1231.67	80.3799
1232.78	95.1362
1233.88	100.374
1234.99	93.9504
1236.09	83.3515
1237.2	67.5984
1238.3	66.5571
1239.41	56.0524
1240.51	56.0713
1241.62	48.733
1242.72	47.643
1243.83	57.0342
1244.93	50.7431
1246.03	66.4015
1247.14	69.5385
1248.24	71.5684
1249.34	84.0478
1250.45	91.2934
1251.55	88.209
1252.65	83.0046
1253.75	75.7101
1254.86	74.6494
1255.96	64.1737
1257.06	65.2613
1258.16	65.1883
1259.26	63.2229
1260.36	58.8894
1261.46	60.1373
1262.56	71.5712
1263.66	98.7397
1264.76	68.4986
1265.86	52.8787
1266.96	52.8815
1268.06	44.4591
1269.16	43.4147
1270.26	45.5617
1271.36	47.7036
1272.46	45.6114
1273.56	38.297
1274.66	46.7333
1275.76	49.9309
1276.85	47.8385
1277.95	46.7851
1279.05	57.3435
1280.15	66.7954
1281.24	90.888
1282.34	213.262
1283.44	796.662
1284.53	492.106
1285.63	105.74
1286.73	67.8923
1287.82	56.3266
1288.92	46.8411
1290.01	47.8911
1291.11	45.8379
1292.21	50.0675
1293.3	40.6614
1294.4	41.7142
1295.49	43.8004
1296.58	41.6677
1297.68	37.4556
1298.77	38.5159
1299.87	37.4704
1300.96	39.5678
1302.05	38.5081
1303.15	35.3103
1304.24	36.3568
1305.33	38.4692
1306.42	38.4795
1307.52	39.5412
1308.61	36.3804
1309.7	37.4535
1310.79	37.4419
1311.88	40.6111
1312.98	32.1819
1314.07	32.1767
1315.16	35.3553
1316.25	32.1877
1317.34	37.4699
1318.43	33.2218
1319.52	35.3004
1320.61	34.2324
1321.7	38.4522
1322.79	33.1592
1323.88	29.9459
1324.97	34.2111
1326.06	35.3091
1327.15	33.1936
1328.23	35.2743
1329.32	28.9078
1330.41	30.9718
1331.5	35.1366
1332.59	31.9595
1333.67	29.8423
1334.76	34.0223
1335.85	33.9956
1336.94	27.71
1338.02	32.9484
1339.11	30.8423
1340.2	32.9067
1341.28	28.7195
1342.37	34.9786
1343.45	32.8427
1344.54	33.8448
1345.63	29.6593
1346.71	34.8453
1347.8	29.6149
1348.88	35.8312
1349.96	32.7308
1351.05	34.8518
1352.13	30.6104
1353.22	31.6458
1354.3	33.7062
1355.39	32.6469
1356.47	33.6607
1357.55	36.7372
1358.63	34.6529
1359.72	37.746
1360.8	31.5429
1361.88	33.6129
1362.97	39.7931
1364.05	32.514
1365.13	40.7802
1366.21	39.7568
1367.29	40.78
1368.37	44.8771
1369.45	48.9374
1370.54	34.4742
1371.62	39.614
1372.7	42.7026
1373.78	35.4756
1374.86	42.6657
1375.94	44.7976
1377.02	40.6535
1378.09	41.5957
1379.18	51.828
1380.25	51.7528
1381.33	51.7212
1382.41	58.9518
1383.49	71.3254
1384.57	98.8119
1385.65	200.274
1386.72	1260.49
1387.8	632.117
1388.88	117.257
1389.96	75.1899
1391.03	58.7869
1392.11	48.5491
1393.19	48.5649
1394.26	44.4481
1395.34	44.4372
1396.42	42.4085
1397.49	38.3283
1398.57	37.3217
1399.64	34.2995
1400.72	44.5996
1401.79	39.4388
1402.87	45.5651
1403.94	41.451
1405.02	40.4375
1406.09	46.6024
1407.17	66.1048
1408.24	126.503
1409.31	86.5164
1410.39	45.6586
1411.46	32.2608
1412.53	37.4104
1413.61	29.2058
1414.68	29.2192
1415.75	32.3076
1416.82	29.2178
1417.9	29.1946
1418.97	32.2749
1420.04	31.3113
1421.11	31.2137
1422.18	29.1579
1423.26	32.2471
1424.33	31.191
1425.4	29.1132
1426.47	26.0486
1427.54	27.0959
1428.61	30.2094
1429.68	25.0641
1430.75	25.0276
1431.82	24.0106
1432.89	26.0598
1433.96	25.0275
1435.02	21.9484
1436.09	24.0046
1437.16	19.9207
1438.23	20.9519
1439.3	29.1525
1440.37	25.0499
1441.43	24.0188
1442.5	19.9341
1443.57	21.9788
1444.64	20.9453
1445.7	20.9513
1446.77	22.9992
1447.84	18.888
1448.9	20.9305
1449.97	22.9784
1451.04	18.8831
1452.1	17.8569
1453.17	18.8857
1454.23	17.8535
1455.3	18.8747
1456.36	18.8778
1457.43	21.9484
1458.49	18.8667
1459.56	20.9003
1460.62	14.7471
1461.69	19.8803
1462.75	19.8233
1463.81	17.7762
1464.88	19.8129
1465.94	17.7701
1467	18.778
1468.07	20.8057
1469.13	16.7212
1470.19	15.7002
1471.25	16.71
1472.32	17.7304
1473.38	16.7066
1474.44	14.6642
1475.5	17.7086
1476.56	14.649
1477.62	16.6631
1478.68	17.671
1479.75	13.6221
1480.81	17.6865
1481.87	17.6511
1482.93	17.6439
1483.99	15.6198
1485.05	17.6374
1486.11	16.611
1487.17	18.6296
1488.22	16.5973
1489.28	17.6064
1490.34	14.5713
1491.4	18.6141
1492.46	15.5752
1493.52	15.5598
1494.58	15.5552
1495.63	17.5726
1496.69	13.5385
1497.75	18.5872
1498.81	17.5705
1499.86	15.5463
1500.92	16.5463
1501.98	15.5395
1503.03	18.548
1504.09	17.5417
1505.15	16.5341
1506.2	17.5417
1507.26	16.5366
1508.31	14.5078
1509.37	15.4846
1510.42	17.475
1511.48	13.4676
1512.53	17.4706
1513.59	14.446
1514.64	14.4435
1515.7	14.4487
1516.75	17.4623
1517.8	13.4472
1518.86	16.4596
1519.91	15.4495
1520.96	15.432
1522.02	16.4263
1523.07	15.431
1524.12	18.4463
1525.17	16.4352
1526.23	15.4272
1527.28	15.4225
1528.33	16.4343
1529.38	15.4297
1530.43	17.4516
1531.48	19.4604
1532.53	17.4462
1533.59	20.426
1534.64	17.403
1535.69	13.3938
1536.74	15.4152
1537.79	15.4403
1538.84	16.4328
1539.89	15.4153
1540.94	15.3975
1541.98	16.4073
1543.03	19.4277
1544.08	16.4262
1545.13	16.4176
1546.18	14.4069
1547.23	16.4126
1548.28	17.4647
1549.33	14.4527
1550.37	17.4521
1551.42	20.447
1552.47	20.4286
1553.52	20.4266
1554.56	19.4277
1555.61	14.407
1556.65	15.3903
1557.7	13.3835
1558.75	16.3843
1559.79	20.3932
1560.84	15.3893
1561.88	19.4044
1562.93	20.281
1563.98	19.3673
1565.02	21.3814
1566.07	16.387
1567.11	16.3785
1568.15	18.3765
1569.2	15.3711
1570.24	15.3615
1571.29	18.354
1572.33	18.3714
1573.37	18.3737
1574.42	18.352
1575.46	19.3276
1576.5	15.3382
1577.55	17.3368
1578.59	18.3256
1579.63	15.3263
1580.67	19.3072
1581.72	18.3117
1582.76	18.3105
1583.8	15.3105
1584.84	16.2993
1585.88	15.3093
1586.92	18.3017
1587.96	16.3148
1589	14.3197
1590.04	18.2853
1591.08	19.2521
1592.12	16.2745
1593.16	19.2483
1594.2	17.2635
1595.24	18.2574
1596.28	18.241
1597.32	17.2366
1598.36	18.2084
1599.4	17.2001
1600.44	16.1959
1601.48	18.1695
1602.51	15.2044
1603.55	14.2217
1604.59	17.1927
1605.63	17.1909
1606.66	18.1638
1607.7	16.2134
1608.74	16.2069
1609.77	13.6401
1610.81	17.2361
1611.85	15.4279
1612.88	18.4698
1613.92	19.6116
1614.95	16.4038
1615.99	16.7198
1617.03	17.5358
1618.06	16.8596
1619.1	14.8343
1620.13	16.9552
1621.17	17.9609
1622.2	15.4155
1623.23	16.0388
1624.27	16.2409
1625.3	15.6478
1626.34	17.3029
1627.37	18.0433
1628.4	20.0145
1629.44	17.3272
1630.47	17.9355
1631.29	17.675
1632.33	16.6879
1633.38	18.6508
1634.42	18.6384
1635.47	14.6936
1636.51	14.6915
1637.56	15.6748
1638.6	16.6615
1639.65	18.6246
1640.69	15.668
1641.73	13.6917
1642.78	17.6306
1643.82	14.6717
1644.86	15.6483
1645.91	17.6218
1646.95	16.6431
1647.99	17.6401
1649.03	15.6736
1650.08	15.6691
1651.12	19.6118
1652.16	17.6451
1653.2	15.6893
1654.24	18.6523
1655.28	16.671
1656.33	17.6467
1657.37	15.6673
1658.41	15.6763
1659.45	17.6464
1660.49	16.6886
1661.53	17.6568
1662.57	17.6401
1663.61	14.7157
1664.65	16.6593
1665.69	13.6931
1666.72	16.6698
1667.76	16.6786
1668.8	16.676
1669.84	15.6888
1670.88	14.7013
1671.92	14.7073
1672.96	16.691
1674	14.7119
1675.03	16.6843
1676.07	15.6822
1677.11	15.6745
1678.15	16.6554
1679.18	18.6289
1680.22	14.6751
1681.25	16.6471
1682.29	14.6659
1683.33	14.6649
1684.36	16.6446
1685.4	15.6489
1686.43	15.6373
1687.47	15.6276
1688.51	17.6063
1689.54	17.6068
1690.58	13.6458
1691.61	16.5878
1692.64	14.6163
1693.68	14.62
1694.71	13.6245
1695.75	14.5966
1696.78	17.5453
1697.81	17.5399
1698.85	13.5979
1699.88	15.5521
1700.91	15.5467
1701.95	15.5483
1702.98	14.5621
1704.01	13.5662
1705.04	15.5117
1706.08	16.4694
1707.11	14.5036
1708.14	15.4857
1709.17	13.5288
1710.2	13.5094
1711.23	13.4914
1712.27	16.4166
1713.3	15.4424
1714.33	15.4246
1715.36	15.3964
1716.39	17.3333
1717.42	17.3323
1718.45	14.3984
1719.48	16.327
1720.51	15.3406
1721.54	16.3063
1722.56	13.3755
1723.59	13.3664
1724.62	14.326
1725.65	16.2498
1726.68	14.2778
1727.71	15.2395
1728.74	15.2554
1729.76	14.2828
1730.79	15.23
1731.82	16.1723
1732.85	15.1905
1733.87	15.182
1734.9	16.1339
1735.93	16.1191
1736.95	15.1354
1737.98	17.031
1739.01	17.016
1740.03	13.18
1741.06	15.0864
1742.08	14.1235
1743.11	15.0754
1744.13	15.0589
1745.16	14.0905
1746.18	14.0909
1747.21	15.0553
1748.23	16.9749
1749.26	16.0048
1750.28	14.0805
1751.31	15.976
1752.33	12.1524
1753.35	14.9985
1754.38	18.7848
1755.4	15.9323
1756.42	14.0298
1757.44	15.9289
1758.47	13.0653
1759.49	11.1586
1760.51	14.9627
1761.53	13.0666
1762.56	14.0257
1763.58	11.1687
1764.6	12.1161
1765.62	12.1093
1766.64	14.9361
1767.66	14.9398
1768.68	15.9011
1769.7	14.9568
1770.72	15.9143
1771.74	14.0131
1772.76	13.0717
1773.78	14.9801
1774.8	13.0642
1775.82	14.0046
1776.84	14.9466
1777.86	14.9523
1778.88	15.9071
1779.9	14.0109
1780.92	14.0165
1781.94	14.0253
1782.95	14.022
1783.97	16.8868
1784.99	14.0452
1786.01	12.1534
1787.03	11.2054
1788.04	15.0407
1789.06	13.1086
1790.08	13.1108
1791.09	14.0706
1792.11	15.0336
1793.13	11.2147
1794.14	14.1046
1795.16	15.0727
1796.17	15.0721
1797.19	15.0607
1798.21	15.0536
1799.22	14.0933
1800.24	14.1009
1801.25	13.1447
1802.27	14.1162
1803.28	13.1636
1804.29	14.131
1805.31	13.1664
1806.32	12.2028
1807.34	15.0957
1808.35	13.1645
1809.36	12.1997
1810.38	13.1698
1811.39	13.1783
1812.4	13.1891
1813.41	12.2239
1814.43	15.1192
1815.44	15.1123
1816.45	15.1171
1817.46	15.1227
1818.47	14.1612
1819.49	14.1668
1820.5	17.071
1821.51	11.2604
1822.52	15.1369
1823.53	14.1684
1824.54	14.1702
1825.55	17.0773
1826.56	18.0382
1827.57	16.0941
1828.58	14.1594
1829.59	13.1966
1830.6	20.9545
1831.61	15.1342
1832.62	15.1067
1833.63	12.2596
1834.64	15.1147
1835.65	12.1859
1836.65	16.0932
1837.66	13.1654
1838.67	13.1383
1839.68	13.12
1840.69	15.0497
1841.7	13.1193
1842.7	15.0475
1843.71	15.0709
1844.72	14.0492
1845.72	12.1272
1846.73	15.0037
1847.74	12.1001
1848.74	14.01
1849.75	13.0467
1850.75	13.0419
1851.76	13.0261
1852.76	15.8864
1853.77	12.0499
1854.78	14.9174
1855.78	14.9047
1856.79	15.8464
1857.79	14.894
1858.79	12.9881
1859.8	12.9804
1860.8	13.9227
1861.81	13.9111
1862.81	14.8475
1863.81	12.9167
1864.82	13.8473
1865.82	14.7932
1866.82	11.9384
1867.83	13.8355
1868.83	15.7307
1869.83	13.8206
1870.83	14.7623
1871.84	13.7999
1872.84	12.834
1873.84	13.7608
1874.84	16.559
1875.84	16.5994
1876.84	15.6662
1877.84	13.7688
1878.84	12.8036
1879.84	13.7167
1880.84	12.7772
1881.84	14.6427
1882.85	14.6591
1883.85	14.6647
1884.84	14.6475
1885.84	12.7429
1886.84	10.8491
1887.84	14.6213
1888.84	13.6761
1889.84	12.7286
1890.84	13.6456
1891.84	14.5778
1892.83	14.5794
1893.83	15.5276
1894.83	12.7102
1895.83	12.7032
1896.83	14.5714
1897.82	15.5065
1898.82	13.6361
1899.82	14.5831
1900.81	13.6356
1901.81	13.6318
1902.81	15.5078
1903.8	13.6143
1904.8	15.4903
1905.79	13.6172
1906.79	14.567
1907.79	12.7013
1908.78	16.4734
1909.78	14.5854
1910.77	13.6459
1911.77	13.6589
1912.76	13.665
1913.76	11.7717
1914.75	13.6488
1915.74	14.5966
1916.74	15.5601
1917.73	13.6731
1918.72	15.5744
1919.72	11.7916
1920.71	15.5656
1921.7	14.6111
1922.7	15.5617
1923.69	12.7393
1924.68	13.6946
1925.67	13.6989
1926.66	14.6553
1927.66	16.5687
1928.65	17.5194
1929.64	12.7641
1930.63	14.6584
1931.62	13.7434
1932.61	16.6378
1933.61	12.8134
1934.6	13.7536
1935.59	13.7462
1936.58	15.6602
1937.57	16.6217
1938.56	14.7313
1939.55	13.7708
1940.54	15.6836
1941.52	12.823
1942.51	14.745
1943.5	13.7986
1944.49	12.8407
1945.48	14.75
1946.47	11.8854
1947.46	14.7724
1948.44	14.7948
1949.43	14.8077
1950.42	14.8124
1951.41	15.7406
1952.39	13.8086
1953.38	13.8294
1954.37	13.8418
1955.36	12.8877
1956.34	14.8053
1957.33	14.797
1958.31	12.8657
1959.3	16.7021
1960.29	13.8237
1961.27	13.8262
1962.26	14.7847
1963.24	15.7495
1964.23	13.8359
1965.21	14.7977
1966.2	14.7913
1967.18	13.8129
1968.17	16.6806
1969.15	15.7179
1970.14	10.9198
1971.12	11.8692
1972.1	13.7846
1973.09	12.8314
1974.07	13.7913
1975.05	14.7429
1976.04	13.7768
1977.02	14.7354
1978	12.8104
1978.98	16.6352
1979.97	12.7968
1980.95	12.7851
1981.93	11.8225
1982.91	10.8594
1983.89	14.6877
1984.88	14.6781
1985.86	12.7391
1986.84	14.6157
1987.82	13.6689
1988.8	12.7418
1989.78	12.7788
1990.76	15.5766
1991.74	11.9206
1992.72	12.1378
1993.7	14.4749
1994.68	13.2173
1995.66	12.2625
1996.64	14.5239
1997.62	13.8611
1998.6	12.7
1999.57	12.3243
2000.55	14.3003
2001.53	14.7196
2002.51	14.7977
2003.49	14.0461
2004.47	13.5682
2005.44	13.3995
2006.42	12.9756
2007.4	13.6464
2008.38	12.5025
2009.35	13.8731
2010.33	13.1645
2011.3	15.1934
2012.18	15.8408
2013.17	13.0295
2014.16	12.1022
2015.15	14.9056
2016.14	17.6942
2017.13	13.9323
2018.11	14.867
2019.1	15.8021
2020.09	13.9167
2021.08	13.9037
2022.06	11.0852
2023.05	12.9362
2024.04	13.8916
2025.02	16.7071
2026.01	15.8057
2027	13.8841
2027.98	12.9297
2028.97	15.7348
2029.96	14.8204
2030.94	13.8991
2031.93	13.8624
2032.91	12.955
2033.9	14.8237
2034.88	13.8903
2035.87	12.9471
2036.85	16.672
2037.83	11.0572
2038.82	13.8471
2039.8	13.8386
2040.79	12.915
2041.77	11.9862
2042.75	11.0544
2043.74	12.9365
2044.72	12.9126
2045.7	11.9773
2046.69	13.8526
2047.67	12.9328
2048.65	14.7937
2049.63	11.0596
2050.62	15.7396
2051.6	12.946
2052.58	12.0054
2053.56	12.9349
2054.54	14.8042
2055.52	15.7487
2056.5	12.9502
2057.48	11.0753
2058.46	12.9494
2059.45	10.1416
2060.43	12.0206
2061.4	13.8996
2062.39	11.0952
2063.37	14.86
2064.34	10.1678
2065.32	13.9319
2066.3	14.8727
2067.28	13.9204
2068.26	12.9987
2069.24	12.0713
2070.22	13.951
2071.2	13.0098
2072.18	13.0203
2073.15	13.0395
2074.13	13.0361
2075.11	14.9122
2076.09	10.2013
2077.06	13.0455
2078.04	15.8824
2079.02	15.8791
2080	14.9372
2080.97	13.99
2081.95	14.9349
2082.93	11.1548
2083.9	13.0561
2084.88	14.9533
2085.85	14.0081
2086.83	13.0688
2087.8	13.0723
2088.78	13.0789
2089.75	13.0947
2090.73	13.1075
2091.7	15.0144
2092.68	15.0069
2093.65	12.1505
2094.63	12.1429
2095.6	13.087
2096.57	14.0336
2097.55	14.0338
2098.52	14.9921
2099.5	14.0424
2100.47	12.1354
2101.44	16.8812
2102.41	14.991
2103.39	14.0493
2104.36	14.0519
2105.33	12.1396
2106.3	14.9806
2107.27	14.037
2108.25	12.1362
2109.22	13.0806
2110.19	14.0336
2111.16	13.0895
2112.13	14.9889
2113.1	13.0834
2114.07	14.0252
2115.04	15.9198
2116.01	12.1099
2116.99	14.9425
2117.96	14.9411
2118.92	12.1066
2119.9	14.0123
2120.86	14.9634
2121.83	14.0007
2122.8	13.0308
2123.77	13.9633
2124.74	16.7908
2125.71	13.005
2126.68	13.947
2127.65	14.8879
2128.61	13.935
2129.58	13.9266
2130.55	16.7529
2131.52	12.9792
2132.48	13.9203
2133.45	16.736
2134.42	14.8485
2135.39	14.8476
2136.35	10.1376
2137.32	11.0671
2138.28	14.829
2139.25	14.8207
2140.22	14.8359
2141.18	13.8561
2142.15	14.8008
2143.12	13.8589
2144.08	13.8533
2145.05	13.8455
2146.01	16.6542
2146.98	12.8839
2147.94	12.875
2148.9	16.6318
2149.87	12.8791
2150.83	14.7459
2151.8	12.8557
2152.76	11.9012
2153.72	17.498
2154.69	14.6972
2155.65	14.7022
2156.61	13.761
2157.58	13.7476
2158.54	11.8743
2159.5	14.6705
2160.47	13.7321
2161.43	12.7918
2162.39	16.5143
2163.35	12.7853
2164.31	13.7079
2165.27	16.4769
2166.24	15.5457
2167.2	14.6325
2168.16	14.633
2169.12	14.6095
2170.08	16.4588
2171.04	14.6021
2172	15.5329
2172.96	15.5293
2173.92	14.5939
2174.88	15.5223
2175.84	14.585
2176.8	14.5847
2177.76	15.5109
2178.72	17.3622
2179.68	17.3545
2180.64	13.6316
2181.59	13.6229
2182.55	16.4063
2183.51	15.4885
2184.47	15.5058
2185.43	17.3626
2186.38	15.4904
2187.34	16.4042
2188.3	19.188
2189.26	16.411
2190.21	15.4907
2191.17	16.439
2192.13	15.5146
2193.08	10.8581
2194.04	16.4121
2195	18.2617
2195.95	18.277
2196.91	18.3001
2197.86	16.4712
2198.82	15.5266
2199.78	14.5761
2200.73	18.3108
2201.69	18.3536
2202.64	16.4392
2203.59	19.231
2204.55	16.44
2205.5	14.5915
2206.46	17.392
2207.41	16.4623
2208.37	18.3359
2209.32	18.3491
2210.27	18.3452
2211.23	18.3427
2212.18	17.4271
2213.13	14.628
2214.09	15.559
2215.04	19.2943
2215.99	17.4309
2216.94	15.5717
2217.9	16.5057
2218.85	17.4254
2219.8	15.5527
2220.75	16.497
2221.7	16.5152
2222.65	16.5306
2223.6	15.6064
2224.55	16.5543
2225.5	17.4897
2226.46	16.5485
2227.41	17.5002
2228.36	16.5752
2229.31	18.4684
2230.26	16.6005
2231.21	16.6103
2232.16	17.5437
2233.11	16.5929
2234.05	16.5958
2235	17.5575
2235.95	17.5787
2236.9	16.6389
2237.85	18.5202
2238.8	13.8129
2239.75	16.6497
2240.69	15.7005
2241.64	17.5888
2242.59	15.7209
2243.54	19.5163
2244.48	20.4722
2245.43	17.6311
2246.38	16.6806
2247.32	17.6291
2248.27	14.7773
2249.22	13.8302
2250.16	14.793
2251.11	18.6003
2252.06	14.8122
2253	14.8136
2253.95	15.7722
2254.89	12.9325
2255.84	18.6342
2256.78	15.7917
2257.73	14.847
2258.67	13.9058
2259.62	14.8622
2260.56	15.8294
2261.51	16.8065
2262.45	15.8663
2263.39	14.9074
2264.34	13.9397
2265.28	13.9293
2266.22	14.887
2267.17	13.9492
2268.11	15.8724
2269.05	14.9255
2270	16.8419
2270.94	12.06
2271.88	15.8909
2272.82	15.8929
2273.77	16.8643
2274.71	14.0046
2275.65	14.0189
2276.59	15.9351
2277.53	15.9146
2278.47	13.988
2279.41	12.073
2280.36	15.9226
2281.3	15.9502
2282.24	14.0387
2283.18	13.0694
2284.12	15.0026
2285.06	13.0892
2286	16.9331
2286.94	14.985
2287.88	15.9425
2288.82	14.9952
2289.75	15.0063
2290.69	16.9433
2291.63	14.0473
2292.57	15.964
2293.51	14.9868
2294.45	14.0291
2295.39	12.1165
2296.32	13.0901
2297.26	14.0577
2298.2	14.0626
2299.14	15.995
2300.07	14.0616
2301.01	15.0268
2301.95	12.1378
2302.89	15.0412
2303.82	17.9451
2304.76	15.0408
2305.69	13.1041
2306.63	16.9786
2307.57	14.087
2308.5	13.1067
2309.44	12.1224
2310.37	15.9792
2311.31	16.9656
2312.24	16.0179
2313.18	16.0014
2314.11	15.0192
2315.05	15.027
2315.98	12.1182
2316.92	15.0062
2317.85	13.0772
2318.78	15.9834
2319.72	15.0315
2320.65	16.9666
2321.58	15.9993
2322.52	17.9118
2323.45	18.8615
2324.38	19.8085
2325.32	26.5472
2326.25	36.1721
2327.18	84.325
2328.11	173.861
2329.05	49.6645
2329.98	26.5165
2330.91	16.8788
2331.84	14.9423
2332.77	14.9393
2333.7	14.9366
2334.63	13.9718
2335.56	12.0453
2336.5	15.8897
2337.43	14.9216
2338.36	15.8658
2339.29	17.7667
2340.22	13.9255
2341.15	15.841
2342.08	15.8404
2343.01	12.9546
2343.93	16.7793
2344.86	12.9462
2345.79	17.7372
2346.72	13.8901
2347.65	11.9382
2348.58	12.9424
2349.51	12.9032
2350.44	14.7823
2351.36	12.8721
2352.29	12.8764
2353.22	13.8218
2354.15	12.8508
2355.07	15.6934
2356	14.7347
2356.93	14.7277
2357.86	13.7646
2358.78	11.8546
2359.71	12.7883
2360.63	10.8866
2361.56	14.6631
2362.49	9.92694
2363.41	10.8529
2364.34	13.6976
2364.8	16.537