File: Data/3-Raman/raw/bu19w-e-ff11-fi10-s1_150 (500nm)_633nm_edge_100%_x100_vis_h50um_60sx2_01.txt
#Acq. time (s)=	60
#Accumulations=	2
#Range (cm-¹)=	100...4000
#Windows=	1
#Auto scanning=	Off
#Autofocus=	Off
#Macrospot=	Off
#AutoExposure=	Off
#Spike filter=	Multiple accum.
#Delay time (s)=	2
#Binning=	1
#Readout mode=	Signal
#DeNoise=	Off
#ICS correction=	On
#Dark correction=	Off
#Inst. Process=	Off
#Detector Gain=	Best Dynamic
#Detector ADC=	50 kHz HS
#Detector temperature (°C)=	-60.28
#Instrument=	LabRAM HR Evol
#Detector=	SIN-EM FIVIS
#Objective=	x100_VIS
#Grating=	150 (500nm)
#ND Filter=	100%
#Laser=	633nm_Edge
#Hole=	49.98
#Temperature=	0
#Range=	Visible
#StageXY=	75x50mm Scan+
#StageZ=	Z motor
#X (µm)=	0
#Y (µm)=	0
#Z (µm)=	-267.6
#Full time(mm:ss)=	2:04
#Project=	21_11_04
#Sample=	BU19w
#Site=
#Title=	BU19w-E-FF11-FI10-S1_150 (500nm)_633nm_Edge_100%_x100_VIS_H50um_60sX2
#Remark=
#Date=	04.11.2021 11:57
#Acquired=	04.11.2021 11:57:47
102.881	1131.21
109.397	1121.8
115.908	1090.41
122.414	1124.65
128.914	1251.64
135.409	1339.16
141.898	1428.19
148.383	1450.5
154.861	1454.96
161.335	1533.38
167.801	1609.91
174.264	1436.57
180.721	1359.25
187.173	1293.56
193.62	1151.96
200.061	1048.45
206.496	966.217
212.926	957.224
219.352	964.481
225.772	1020.03
232.185	1065.21
238.595	1101.22
244.999	1059.75
251.397	973.781
257.791	935.213
264.178	881.716
270.561	861.617
276.939	898.583
283.31	954.292
289.678	1015.36
296.039	1073.19
302.396	1123.35
308.746	1184.63
315.093	1298.81
321.433	1573.55
327.768	1806.09
334.099	1708.64
340.423	1462.12
346.743	1375.79
353.058	1320.38
359.367	1284.38
365.671	1226.65
371.971	1113.63
378.265	1066.46
384.553	973.731
390.837	922.649
397.116	863.847
403.389	957.174
409.657	862.935
415.92	852.883
422.178	864.313
428.431	868.225
434.678	906.78
440.921	894.227
447.158	834.591
453.391	801.285
459.618	828.351
465.84	819.843
472.057	795.953
478.27	801.652
484.477	846.47
490.679	952.811
496.876	1074.2
503.068	1250.86
509.255	1314.95
515.436	1213.29
521.613	1108.41
527.785	1030.94
533.952	963.18
540.113	934.563
546.27	916.395
552.423	918.979
558.568	841.804
564.711	792.578
570.848	673.164
576.979	689.811
583.107	689.612
589.228	751.449
595.345	780.355
601.458	815.951
607.565	779.84
613.667	796.4
619.764	785.571
625.856	781.639
631.944	745.436
638.026	767.236
644.104	752.928
650.177	748.925
656.244	753.62
662.308	721.65
668.365	688.133
674.418	616.864
680.467	596.355
686.511	586.602
692.549	610.207
698.582	632.205
704.611	643.82
710.635	639.052
716.655	634.845
722.669	600.672
728.679	560.441
734.683	530.413
740.683	550.03
746.678	540.81
752.669	541.263
758.654	549.619
764.635	546.024
770.611	552.257
776.582	562.258
782.549	546.42
788.511	548.052
794.466	540.893
800.419	559.671
806.366	556.318
812.309	543.312
818.247	537.481
824.18	565.225
830.108	539.67
836.033	553.56
841.952	545.023
847.865	538.498
853.776	529.401
859.681	545.87
865.58	502.983
871.476	521.291
877.366	507.76
883.253	515.719
889.134	512.867
895.012	517.307
900.883	485.157
906.751	483.975
912.614	482.693
918.473	500.494
924.326	490.762
930.174	498.651
936.019	498.581
941.859	501.267
947.693	552.528
953.525	556.591
959.35	584.199
965.171	603.816
970.988	626.008
976.801	649.43
982.608	764.844
988.411	851.744
994.209	872.188
1000	833.587
1005.79	834.632
1011.58	818.593
1017.36	794.56
1023.13	822.455
1028.9	860.838
1034.67	969.826
1040.43	1084.63
1046.19	1121.86
1051.94	1025.74
1057.69	947.947
1063.44	904.982
1069.17	858.039
1074.91	839.252
1080.64	809.422
1086.37	839.665
1092.09	864.36
1097.8	936.395
1103.52	959.153
1109.22	898.67
1114.93	903.524
1120.63	907.366
1126.32	889.879
1132.01	889.193
1137.7	869.834
1143.38	885.662
1149.06	876.169
1154.73	900.446
1160.4	821.247
1166.06	717.548
1171.72	691.694
1177.38	662.868
1183.03	637.397
1188.67	613.789
1194.31	626.898
1199.95	616.225
1205.58	575.959
1211.21	540.654
1216.84	503.384
1222.46	456.048
1228.07	414.259
1233.68	434.069
1239.29	395.257
1244.89	400.121
1250.49	411.611
1256.08	400.571
1261.67	412.248
1267.26	392.548
1272.84	396.868
1278.42	390.979
1283.99	394.179
1289.56	388.59
1295.12	399.28
1300.68	399.237
1306.23	391.624
1311.78	387.551
1317.33	387.777
1322.87	397.235
1328.41	402.879
1333.94	395.279
1339.47	399.669
1345	381.178
1350.52	401.392
1356.04	392.754
1361.55	408.5
1367.06	414.686
1372.56	402.208
1378.06	400.01
1383.56	417.278
1389.05	414
1394.53	407.908
1400.02	405.437
1405.5	403.967
1410.97	401.595
1416.44	414.859
1421.91	394.072
1427.37	403.38
1432.83	385.693
1438.28	403.363
1443.73	394.95
1449.17	401.017
1454.62	392.031
1460.05	390.102
1465.48	413.168
1470.91	380.508
1476.34	396.233
1481.76	395.346
1487.17	399.844
1492.59	381.41
1497.99	396.841
1503.4	377.611
1508.8	402.914
1514.19	391.33
1519.59	369.166
1524.97	395.035
1530.36	397.487
1535.74	390.356
1541.11	392.53
1546.48	398.555
1551.85	373.701
1557.21	392.678
1562.57	383.651
1567.93	376.788
1573.28	386.085
1578.62	390.208
1583.97	371.947
1589.3	369.947
1594.64	367.033
1599.97	362.13
1605.3	356.315
1610.62	380.017
1615.94	366.1
1621.25	375.159
1626.56	344.79
1631.87	359.263
1637.17	366.927
1642.47	374.025
1647.76	350.25
1653.05	376.132
1658.34	370.827
1663.62	368.723
1668.9	345.466
1674.18	366.544
1679.45	352.066
1684.71	355.14
1689.98	351.524
1695.23	352.559
1700.49	335.262
1705.74	364.781
1710.99	336.277
1716.23	336.41
1721.47	349.677
1726.7	332.306
1731.94	346.479
1737.16	322.407
1742.39	337.681
1747.61	341.669
1752.82	336.455
1758.03	327.688
1763.24	340.252
1768.44	329.088
1773.64	315.695
1778.84	326.243
1784.03	330.159
1789.22	316.009
1794.41	314.438
1799.59	327.826
1804.76	304.638
1809.94	315.721
1815.11	331.382
1820.27	317.082
1825.43	315.481
1830.59	304.621
1835.74	327.49
1840.89	322.329
1846.04	303.045
1851.18	297.689
1856.32	302.751
1861.45	298.607
1866.58	305.105
1871.71	300.937
1876.83	295.445
1881.95	305.246
1887.07	291.359
1892.18	298.519
1897.29	299.743
1902.39	296.505
1907.49	306.566
1912.59	288.4
1917.68	301.269
1922.77	313.552
1927.86	301.002
1932.94	300.379
1938.02	284.062
1943.09	303.683
1948.16	291.957
1953.23	293.337
1958.29	294.643
1963.35	311.567
1968.41	291.037
1973.46	286.06
1978.51	296.739
1983.55	298.976
1988.59	282.007
1993.63	292.738
1998.66	277.084
2003.69	292.767
2008.72	284.512
2013.74	285.95
2018.76	295.783
2023.77	294.818
2028.78	290.377
2033.79	284.852
2038.79	293.883
2043.79	302.982
2048.79	287.828
2053.78	285.898
2058.77	288.933
2063.76	299.375
2068.74	296.361
2073.72	287.151
2078.69	296.348
2083.66	293.165
2088.63	293.558
2093.59	302.747
2098.55	297.234
2103.51	295.474
2108.46	288.785
2113.41	300.906
2118.36	304.354
2123.3	296.466
2128.24	282.17
2133.17	291.769
2138.11	286.11
2143.03	291.822
2147.96	297.463
2152.88	301.706
2157.79	295.647
2162.71	312.478
2167.62	297.238
2172.52	287.172
2177.43	291.213
2182.32	286.133
2187.22	301.455
2192.11	291.318
2197	288.966
2201.89	295.752
2206.77	305.248
2211.64	286.562
2216.52	297.551
2221.39	285.365
2226.26	291.282
2231.12	281.617
2235.98	291.46
2240.84	292.19
2245.69	281.145
2250.54	301.571
2255.39	297.042
2260.23	283.288
2265.07	289.222
2269.9	288.417
2274.74	283.51
2279.57	293.122
2284.39	270.674
2289.21	272.075
2294.03	270.806
2298.84	290.927
2303.66	273.888
2308.46	271.662
2313.27	286.941
2318.07	271.557
2322.87	274.925
2327.66	263.536
2332.45	283.223
2337.24	289.526
2342.02	261.897
2346.8	279.234
2351.58	271.987
2356.35	268.691
2361.12	272.054
2365.89	254.693
2370.65	260.77
2375.41	280.699
2380.17	275.645
2384.92	267.63
2389.67	267.842
2394.42	249.843
2399.16	259.583
2403.9	256.775
2408.64	256.797
2413.37	271.188
2418.1	264.08
2422.83	269.149
2427.55	251.285
2432.27	268.876
2436.99	268.264
2441.7	259.13
2446.41	257.054
2451.11	249.261
2455.82	245.685
2460.51	257.896
2465.21	260.078
2469.9	253.551
2474.59	246.951
2479.28	260.676
2483.96	267.133
2488.64	250.186
2493.32	266.771
2497.99	261.471
2502.66	250.223
2507.32	256.528
2511.99	259.843
2516.65	266.064
2521.3	267.953
2525.96	250.623
2530.61	259.891
2535.25	252.941
2539.89	250.471
2544.53	270.352
2549.17	264.985
2553.8	262.574
2558.43	249.565
2563.06	260.617
2567.68	252.228
2572.3	258.934
2576.92	256.547
2581.53	228.258
2586.14	255.913
2590.75	257.641
2595.35	267.073
2599.96	264.451
2604.55	240.37
2609.15	252.868
2613.74	256.117
2618.33	219.61
2622.91	232.058
2627.49	258.387
2632.07	254.254
2636.64	259.522
2641.22	266.519
2645.78	253.443
2650.35	263.556
2654.91	245.561
2659.47	255.366
2664.03	252.607
2668.58	248.262
2673.13	255.059
2677.67	241.814
2682.22	260.432
2686.76	261.617
2691.29	256.322
2695.83	245.78
2700.36	262.343
2704.89	256.44
2709.41	248.857
2713.93	263.82
2718.45	241.759
2722.96	251.932
2727.47	253.898
2731.98	237.894
2736.49	238.089
2740.99	261.06
2745.49	253.254
2749.98	261.86
2754.47	264.277
2758.96	245.106
2763.45	253.687
2767.93	269.008
2772.41	236.543
2776.89	247.045
2781.36	251.118
2785.84	250.303
2790.3	244.453
2794.77	233.494
2799.23	252.577
2803.69	251.484
2808.14	257.049
2812.59	255.831
2817.04	249.444
2821.49	249.834
2825.93	265.528
2830.37	252.353
2834.81	256.116
2839.24	236.03
2843.67	258.569
2848.1	243.644
2852.53	252.723
2856.95	229.308
2861.37	250.563
2865.78	251.322
2870.19	245.179
2874.6	230.292
2879.01	251.96
2883.41	254.588
2887.81	237.941
2892.21	244.029
2896.6	273.173
2901	233.37
2905.38	248.345
2909.77	234.794
2914.15	240.704
2918.53	250.222
2922.91	240.057
2927.28	242.535
2931.65	246.872
2936.02	243.862
2940.38	240.702
2944.74	252.061
2949.1	241.473
2953.46	236.352
2957.81	251.304
2962.16	248.014
2966.5	263.088
2970.85	250.709
2975.19	230.94
2979.52	242.435
2983.86	250.359
2988.19	256.554
2992.52	238.694
2996.85	233.792
3001.17	236.4
3005.49	246.576
3009.8	241.754
3014.12	242.51
3018.43	256.637
3022.74	263.247
3027.04	239.239
3031.34	253.222
3035.64	238.426
3039.94	261.919
3044.23	254.742
3048.52	270.593
3052.81	255.616
3057.09	250.289
3061.38	256.539
3065.65	251.173
3069.93	261.327
3074.2	255.954
3078.47	260.333
3082.74	268.629
3087	275.111
3091.27	269.973
3095.52	272.795
3099.78	257.875
3104.03	296.447
3108.28	273.674
3112.53	276.758
3116.77	273.826
3121.01	264.868
3125.25	270.062
3129.49	295.699
3133.72	297.155
3137.95	294.474
3142.18	291.658
3146.4	311.472
3150.62	291.868
3154.84	307.355
3159.06	287.36
3163.27	309.18
3167.48	295.304
3171.69	329.835
3175.89	326.382
3180.09	269.803
3184.29	308.318
3188.49	310.753
3192.68	330.34
3196.87	311.835
3201.06	314.977
3205.24	305.387
3209.42	310.915
3213.6	316.521
3217.78	309.214
3221.95	325.701
3226.12	320.451
3230.29	295.353
3234.45	311.888
3238.61	326.288
3242.77	320.949
3246.93	299.998
3251.08	327.873
3255.23	319.748
3259.38	293.62
3263.53	303.658
3267.67	291.597
3271.81	306.457
3275.95	325.529
3280.08	296.443
3284.21	294.754
3288.34	322.921
3292.47	295.89
3296.59	314.857
3300.71	287.763
3304.83	302.219
3308.95	300.483
3313.06	300.999
3317.17	289.912
3321.27	295.184
3325.38	295.91
3329.48	317.809
3333.58	323.641
3337.67	308.25
3341.77	323.252
3345.86	283.576
3349.95	317.334
3354.03	355.982
3358.11	335.3
3362.19	336.064
3366.27	360.746
3370.34	373.531
3374.42	357.372
3378.48	353.082
3382.55	348.738
3386.61	351.593
3390.68	315.696
3394.73	333.016
3398.79	348.065
3402.84	324.188
3406.89	324.497
3410.94	324.769
3414.98	325.023
3419.03	325.284
3423.06	337.698
3427.1	330.66
3431.14	340.817
3435.17	316.834
3439.2	319.826
3443.22	325.338
3447.25	321.201
3451.27	331.873
3455.28	327.881
3459.3	346.373
3463.31	307.724
3467.32	311.315
3471.33	299.813
3475.34	325.762
3479.34	306.569
3483.34	330.251
3487.33	318.498
3491.33	306.644
3495.32	284.452
3499.31	325.985
3503.3	298.406
3507.28	319.382
3511.26	299.107
3515.24	312.144
3519.22	304.614
3523.19	302.216
3527.16	302.451
3531.13	279.482
3535.1	287.706
3539.06	280.621
3543.02	273.411
3546.98	276.463
3550.93	276.812
3554.89	276.917
3558.84	287.621
3562.78	259.344
3566.73	270.241
3570.67	276.073
3574.61	274.041
3578.55	272.11
3582.48	270.262
3586.41	265.781
3590.35	253.297
3594.27	259.352
3598.2	270.762
3602.12	223.312
3606.04	245.298
3609.95	256.563
3613.87	238.259
3617.78	246.807
3621.69	252.568
3625.6	225.716
3629.5	225.853
3633.4	220.52
3637.3	223.397
3641.2	239.998
3645.09	216.012
3648.98	202.723
3652.87	205.663
3656.76	211.306
3660.64	233.319
3664.53	225.303
3668.4	214.604
3672.28	214.811
3676.16	220.611
3680.03	221.036
3683.9	205.049
3687.76	205.619
3691.63	197.902
3695.49	192.849
3699.35	201.718
3703.2	188.291
3707.06	208.397
3710.91	211.777
3714.76	181.39
3718.6	204.337
3722.45	201.921
3726.29	227.738
3730.13	202.63
3733.97	205.86
3737.8	192.023
3741.63	209.446
3745.46	195.506
3749.29	198.629
3753.11	207.421
3756.93	221.894
3760.75	216.283
3764.57	184.854
3768.39	199.294
3772.2	202.332
3776.01	208.252
3779.81	194.104
3783.62	185.749
3787.42	194.686
3791.22	192.06
3795.02	198.174
3798.81	201.467
3802.61	204.796
3806.4	205.262
3810.18	194.056
3813.97	179.833
3817.75	191.91
3821.53	180.529
3825.31	198.462
3829.09	210.571
3832.86	181.466
3836.63	187.7
3840.4	211.683
3844.17	179.463
3847.93	179.613
3851.69	218.36
3855.45	197.655
3859.21	179.834
3862.96	197.736
3866.71	186.16
3870.46	192.569
3874.21	192.672
3877.95	186.815
3881.69	177.965
3885.44	181.106
3889.17	184.283
3892.91	205.522
3896.64	193.874
3900.37	176.112
3904.1	185.415
3907.82	188.693
3911.55	176.898
3915.27	180.236
3918.99	186.686
3922.7	199.317
3926.42	187.571
3930.13	181.849
3933.84	179.09
3937.54	185.477
3941.25	170.447
3944.95	183.106
3948.65	168.031
3952.35	186.811
3956.04	168.507
3959.73	181.051
3963.42	171.899
3967.11	175.087
3970.8	178.227
3974.48	190.693
3978.16	193.846
3981.84	187.633
3985.52	162.813
3989.19	172.108
3992.86	184.575
3996.53	172.288
3998.37	172.372