File: Data/3-Raman/raw/bu19w-e-ff11b-fi03-v_150 (500nm)_532nm_edge_100%_x100_vis_h50um_30sx2_01.txt
#Acq. time (s)=	30
#Accumulations=	2
#Range (cm-¹)=	100...5000
#Windows=	1
#Auto scanning=	Off
#Autofocus=	Off
#Macrospot=	Off
#AutoExposure=	Off
#Spike filter=	Multiple accum.
#Delay time (s)=	2
#Binning=	1
#Readout mode=	Signal
#DeNoise=	Off
#ICS correction=	On
#Dark correction=	Off
#Inst. Process=	Off
#Detector Gain=	Best Dynamic
#Detector ADC=	50 kHz HS
#Detector temperature (°C)=	-60.09
#Instrument=	LabRAM HR Evol
#Detector=	SIN-EM FIVIS
#Objective=	x100_VIS
#Grating=	150 (500nm)
#ND Filter=	100%
#Laser=	532nm_Edge
#Hole=	49.98
#Temperature=	0
#Range=	Visible
#StageXY=	75x50mm Scan+
#StageZ=	Z motor
#X (µm)=	0
#Y (µm)=	0
#Z (µm)=	-250.4
#Full time(mm:ss)=	1:04
#Project=	21_11_04
#Sample=	BU19w
#Site=
#Title=	BU19w-E-FF11b-FI03-V_150 (500nm)_532nm_Edge_100%_x100_VIS_H50um_30sX2
#Remark=
#Date=	04.11.2021 18:40
#Acquired=	04.11.2021 18:40:58
101.869	4311.05
106.493	4845.32
111.113	7896.07
115.732	11334.4
120.349	8102.51
124.964	4321.08
129.577	3208.42
134.185	2852.48
138.793	2604.93
143.399	2326.44
148.003	2160.37
152.602	2224.25
157.201	2381.71
161.798	2647.15
166.392	3192.95
170.982	3946.58
175.572	5385.49
180.16	7660.08
184.745	10765.4
189.326	13853.8
193.907	15297.3
198.486	14036.4
203.06	10992.8
207.634	7940.14
212.206	5760.08
216.776	4224.89
221.341	3296.45
225.906	2640.57
230.469	2246
235.028	1966.36
239.586	1806.52
244.142	1980.82
248.694	2764.24
253.246	3184.25
257.795	2054.54
262.341	1140.88
266.886	859.292
271.428	723.83
275.967	621.388
280.505	573.753
285.041	563.991
289.573	515.836
294.105	511.618
298.632	498.938
303.159	491.125
307.685	474.593
312.205	453.569
316.726	468.78
321.242	462.787
325.758	453.349
330.272	474.574
334.782	745.526
339.292	1741
343.797	2574.95
348.302	1659.49
352.803	862.687
357.304	657.44
361.802	547.548
366.297	553.78
370.791	501.503
375.281	601.272
379.77	811.197
384.256	1071.65
388.741	1342.27
393.223	1307.58
397.704	801
402.18	665.666
406.657	685.75
411.13	696.278
415.602	755.568
420.07	905.952
424.538	1119.13
429.002	1584.47
433.465	2476.95
437.925	4622.53
442.384	9300.82
446.839	23101.5
451.294	38109.3
455.745	38141.6
460.196	21597.8
464.642	9979.53
469.089	5668.73
473.531	4030.89
477.971	3023.1
482.411	2310.51
486.846	1898.02
491.282	1660.51
495.713	1610.16
500.144	1552.66
504.572	1422.17
508.997	1252.96
513.421	1105.75
517.842	963.279
522.263	890.457
526.679	829.458
531.093	767.399
535.507	725.121
539.917	679.336
544.327	635.771
548.733	584.041
553.137	565.839
557.54	548.472
561.94	528.784
566.337	510.536
570.734	517.159
575.127	539.564
579.518	543.053
583.909	501.787
588.295	525.902
592.68	480.411
597.064	437.204
601.445	442.73
605.823	435.321
610.201	422.154
614.575	433.402
618.947	427.515
623.317	408.763
627.686	409.403
632.052	427.926
636.415	399.351
640.777	388.101
645.138	390.467
649.495	384.671
653.85	376.406
658.205	369.672
662.556	385.921
666.905	417.827
671.252	421.224
675.597	488.708
679.941	597.35
684.282	763.433
688.62	716.171
692.957	543.064
697.293	432.034
701.625	415.429
705.955	374.678
710.283	375.727
714.609	373.329
718.933	352.612
723.257	361.946
727.577	371.069
731.894	367.777
736.21	358.126
740.524	367.026
744.835	366.274
749.147	382.379
753.454	390.138
757.759	402.394
762.063	416.884
766.364	449.899
770.663	494.785
774.96	563.028
779.257	702.391
783.55	951.928
787.841	1098.6
792.13	1409.79
796.417	1786.3
800.702	1416.54
804.985	889.097
809.266	630.619
813.545	540.492
817.821	514.237
822.096	490.148
826.371	463.985
830.641	473.084
834.91	467.88
839.176	464.839
843.441	439.678
847.703	438.635
851.964	421.863
856.222	420.542
860.479	409.299
864.733	425.527
868.986	429.48
873.236	444.317
877.485	434.864
881.731	410.022
885.975	429.896
890.218	432.001
894.458	417.562
898.696	412.526
902.933	387.933
907.167	393.185
911.399	405.429
915.63	387.646
919.858	366.576
924.084	367.032
928.308	351.061
932.531	329.177
936.749	330.92
940.967	332.556
945.184	326.659
949.398	289.802
953.61	311.768
957.821	300.708
962.029	267.39
966.236	270.286
970.44	271.086
974.642	268.764
978.843	262.236
983.041	252.594
987.236	250.37
991.43	240.746
995.623	249.293
999.813	228.35
1004	250.91
1008.19	228.943
1012.37	239.913
1016.55	259.363
1020.73	237.265
1024.91	247.099
1029.09	250.436
1033.27	267.6
1037.44	264.197
1041.61	272.342
1045.78	306.003
1049.94	404.253
1054.11	500.972
1058.27	548.456
1062.43	616.642
1066.59	869.378
1070.75	1133.08
1074.9	943.408
1079.05	538.2
1083.2	371.212
1087.35	297.507
1091.5	277.99
1095.65	245.312
1099.79	228.298
1103.93	235.957
1108.07	243.663
1112.21	222.922
1116.34	229.764
1120.48	231.828
1124.61	224.969
1128.74	254.955
1132.86	260.566
1136.99	325.607
1141.11	458.602
1145.23	662.113
1149.35	826.953
1153.47	693.623
1157.59	443.197
1161.7	278.164
1165.82	253.369
1169.92	229.554
1174.03	217.023
1178.14	214.769
1182.24	204.277
1186.35	211.228
1190.45	198.535
1194.55	223.712
1198.64	227.253
1202.74	243.953
1206.83	230.065
1210.92	277.037
1215.01	302.554
1219.1	311.838
1223.18	328.16
1227.27	321.402
1231.35	338.819
1235.43	347.419
1239.5	337.268
1243.58	378.968
1247.65	511.589
1251.72	733.342
1255.8	607.803
1259.86	473.243
1263.93	535.614
1267.99	1911.72
1272.06	5358.71
1276.12	2450.84
1280.18	693.612
1284.23	436.87
1288.29	391.915
1292.34	361.959
1296.39	348.026
1300.44	320.951
1304.49	306.902
1308.53	306.933
1312.58	318.026
1316.62	313.886
1320.66	301.618
1324.7	308.387
1328.73	309.044
1332.77	314.705
1336.8	304.204
1340.83	332.705
1344.86	335.099
1348.88	364.391
1352.91	422.444
1356.93	532.957
1360.95	499.258
1364.97	519.199
1368.99	890.057
1373.01	5068.38
1377.02	7844.34
1381.03	2235.67
1385.04	642.438
1389.05	501.503
1393.06	645.188
1397.06	993.021
1401.06	624.991
1405.06	377.864
1409.06	313.945
1413.06	313.114
1417.05	287.624
1421.05	261.114
1425.04	247.389
1429.03	242.431
1433.01	215.749
1437	202.903
1440.99	196.965
1444.97	201.864
1448.95	186.018
1452.93	181.994
1456.9	191.754
1460.88	180.782
1464.85	167.803
1468.82	167.616
1472.79	173.345
1476.76	167.272
1480.73	172.946
1484.69	154.129
1488.65	159.783
1492.61	158.599
1496.57	160.348
1500.53	167.948
1504.48	166.808
1508.43	166.687
1512.39	171.439
1516.33	159.69
1520.28	157.675
1524.23	166.341
1528.17	162.409
1532.11	166.254
1536.05	171.073
1539.99	165.235
1543.93	167.152
1547.86	182.633
1551.8	171.954
1555.73	179.662
1559.66	178.624
1563.58	185.308
1567.51	189.064
1571.44	175.406
1575.36	183.008
1579.28	194.453
1583.2	178.875
1587.11	197.031
1591.03	195.897
1594.94	192.837
1598.85	199.393
1602.76	204.992
1606.67	198.14
1610.58	212.402
1614.48	180.657
1618.38	191.119
1622.29	196.777
1626.18	207.242
1630.08	207.204
1633.98	206.272
1637.87	198.637
1641.76	188.169
1645.65	190.191
1649.54	184.565
1653.43	189.495
1657.31	188.657
1661.2	191.652
1665.08	182.122
1668.96	174.485
1672.83	163.911
1676.71	163.897
1680.58	167.647
1684.46	163.661
1688.33	157.75
1692.2	149.905
1696.06	148.753
1699.93	162.862
1703.79	150.192
1707.66	164.186
1711.52	148.645
1715.37	143.593
1719.23	150.865
1723.08	154.335
1726.94	153.069
1730.79	155.544
1734.64	147.701
1738.49	144.558
1742.33	151.677
1746.18	143.87
1750.02	152.908
1753.86	139.7
1757.7	143.292
1761.54	148.037
1765.37	147.146
1769.21	150.001
1773.04	155.728
1776.87	129.833
1780.7	141.193
1784.53	134.879
1788.35	142.583
1792.17	143.766
1796	137.45
1799.82	142.384
1803.64	152.894
1807.45	138.916
1811.27	139.038
1815.08	137.249
1818.89	142.005
1822.7	137.287
1826.51	135.374
1830.32	146.628
1834.12	133.33
1837.92	145.449
1841.72	147.177
1845.52	144.171
1849.32	151.504
1853.12	147.516
1856.91	150.043
1860.7	147.849
1864.5	153.091
1868.28	145.322
1872.07	156.134
1875.86	145.663
1879.64	146.321
1883.42	128.598
1887.21	152.362
1890.98	144.954
1894.76	141.252
1898.54	148.589
1902.31	140.342
1906.08	135.803
1909.85	146.014
1913.62	146.147
1917.39	147.218
1921.16	137.285
1924.92	144.01
1928.68	150.782
1932.44	148.299
1936.2	150.461
1939.96	139.558
1943.71	142.637
1947.47	149.482
1951.22	144.03
1954.97	139.448
1958.72	147.001
1962.46	146.047
1966.21	146.024
1969.95	145.96
1973.7	147.714
1977.43	146.623
1981.17	151.124
1984.91	154.652
1988.65	155.351
1992.38	161.614
1996.11	163.171
1999.84	147.991
2003.57	145.838
2007.3	142.761
2011.02	148.878
2014.75	161.406
2018.47	157.429
2022.19	147.136
2025.91	145.194
2029.62	146.022
2033.34	142.324
2037.05	143.271
2040.76	144.199
2044.47	157.938
2048.18	148.786
2051.89	151.567
2055.59	156.193
2059.3	143.475
2063	149.187
2066.7	149.438
2070.4	145.097
2074.1	137.973
2077.79	145.627
2081.49	153.321
2085.18	143.392
2088.87	155.577
2092.56	150.022
2096.25	147.326
2099.93	161.351
2103.61	143.701
2107.3	163.227
2110.98	144.597
2114.66	151.999
2118.33	162.168
2122.01	149.977
2125.68	150.757
2129.36	157.074
2133.03	156.88
2136.7	143.736
2140.36	154.602
2144.03	156.194
2147.7	154.09
2151.36	145.561
2155.02	147.151
2158.68	156.064
2162.34	148.516
2165.99	152.878
2169.65	146.317
2173.3	143.469
2176.95	146.125
2180.6	145.156
2184.25	156.921
2187.9	153.252
2191.54	143.277
2195.18	150.645
2198.83	144.398
2202.47	139.978
2206.11	147.44
2209.74	143.061
2213.38	150.591
2217.01	144.401
2220.64	152.886
2224.27	145.771
2227.9	150.601
2231.53	135.15
2235.16	145.535
2238.78	125.408
2242.4	139.512
2246.02	157.369
2249.64	142.741
2253.26	144.846
2256.88	149.773
2260.49	144.431
2264.11	153.1
2267.72	140.236
2271.33	153.672
2274.93	150.177
2278.54	159.826
2282.15	157.13
2285.75	153.468
2289.35	143.188
2292.95	149.897
2296.55	155.67
2300.15	153.881
2303.74	162.489
2307.34	162.539
2310.93	193.845
2314.52	446.938
2318.11	1119.77
2321.7	551.852
2325.28	218.162
2328.87	156.464
2332.45	162.882
2336.03	169.26
2339.61	169.947
2343.19	164.974
2346.77	153.428
2350.34	153.15
2353.92	161.28
2357.49	152.573
2361.06	152.27
2364.63	153.825
2368.2	164.659
2371.76	168.082
2375.33	167.79
2378.89	165.652
2382.45	150.644
2386.01	155.936
2389.57	162.158
2393.13	151.878
2396.68	160.918
2400.23	147.089
2403.79	161.756
2407.34	149.871
2410.88	148.122
2414.43	157.428
2417.98	159.435
2421.52	146.753
2425.06	158.028
2428.61	153.687
2432.14	146.586
2435.68	157.098
2439.22	136.091
2442.75	160.622
2446.29	148.872
2449.82	134.285
2453.35	148.733
2456.88	150.001
2460.4	158.674
2463.93	151.315
2467.45	147.603
2470.98	148.698
2474.5	162.804
2478.02	152.31
2481.54	153.172
2485.05	151.156
2488.57	144.35
2492.08	148.896
2495.59	147.74
2499.1	158.8
2502.61	143.598
2506.12	149.894
2509.63	144.951
2513.13	156.779
2516.63	146.309
2520.13	155.377
2523.63	147.643
2527.13	141.93
2530.63	140.885
2534.12	145.4
2537.62	147.186
2541.11	144.389
2544.6	147.198
2548.09	145.461
2551.58	151.121
2555.06	147.575
2558.55	145.027
2562.03	147.107
2565.51	149.261
2568.99	144.947
2572.47	149.061
2575.95	142.917
2579.43	140.525
2582.9	151.328
2586.37	152.74
2589.84	152.228
2593.31	136.421
2596.78	146.235
2600.25	140.86
2603.71	142.153
2607.18	147.206
2610.64	143.514
2614.1	140.659
2617.56	155.159
2621.02	143.658
2624.47	141.736
2627.93	152.264
2631.38	137.793
2634.83	136.739
2638.28	141.396
2641.73	152.721
2645.18	141.035
2648.62	146.562
2652.07	151.084
2655.51	151.744
2658.95	159.014
2662.39	142.554
2665.83	139.384
2669.27	149.425
2672.7	154.704
2676.14	134.65
2679.57	152.155
2683	145.326
2686.43	139.5
2689.86	140.305
2693.29	149.555
2696.71	152.238
2700.13	145.647
2703.56	139.072
2706.98	150.163
2710.4	149.274
2713.82	145.624
2717.23	150.379
2720.65	149.579
2724.06	134.805
2727.47	146.16
2730.88	146.331
2734.29	137.133
2737.7	153.215
2741.11	138.37
2744.51	147.881
2747.91	141.411
2751.32	143.395
2754.72	135.963
2758.11	139.8
2761.51	148.358
2764.91	149.344
2768.3	142.769
2771.7	144.648
2775.09	149.343
2778.48	153.068
2781.87	148.293
2785.25	140.689
2788.64	161.303
2792.03	147.109
2795.41	140.44
2798.79	151.621
2802.17	143.997
2805.55	135.449
2808.93	150.328
2812.3	153.007
2815.68	154.738
2819.05	137.779
2822.42	144.203
2825.79	140.38
2829.16	155.215
2832.53	157.01
2835.89	145.792
2839.26	155.095
2842.62	151.386
2845.98	159.826
2849.34	146.881
2852.7	161.027
2856.06	149.016
2859.41	151.966
2862.77	152.134
2866.12	153.244
2869.47	153.422
2872.82	174.255
2876.17	156.572
2879.52	152.968
2882.87	148.409
2886.21	150.432
2889.55	157.172
2892.89	158.25
2896.23	151.727
2899.57	157.471
2902.91	155.625
2906.25	160.382
2909.58	156.609
2912.91	160.394
2916.25	152.815
2919.58	161.296
2922.91	164.088
2926.23	152.685
2929.56	166.78
2932.88	159.123
2936.21	160.885
2939.53	168.302
2942.85	169.113
2946.17	166.161
2949.49	167.924
2952.8	174.378
2956.12	162.039
2959.43	170.396
2962.74	160.933
2966.06	179.625
2969.37	180.539
2972.67	175.866
2975.98	159.935
2979.28	166.551
2982.59	188.162
2985.89	175.062
2989.19	173.234
2992.49	174.228
2995.79	171.473
2999.09	175.306
3002.38	190.425
3005.68	181.095
3008.97	177.42
3012.26	192.585
3015.55	187.041
3018.84	189.029
3022.13	172.15
3025.41	192.061
3028.7	195
3031.98	191.324
3035.26	182.909
3038.54	204.742
3041.82	199.159
3045.1	204.933
3048.38	204.086
3051.65	210.817
3054.92	207.133
3058.2	209.129
3061.47	201.573
3064.73	225.357
3068	214.959
3071.27	224.457
3074.54	220.442
3077.8	229.954
3081.06	235.576
3084.32	226.241
3087.58	223.521
3090.84	243.659
3094.1	225.842
3097.35	244.761
3100.61	249.59
3103.86	247.703
3107.11	254.505
3110.36	257.474
3113.61	266.065
3116.86	272.78
3120.11	268.077
3123.35	279.565
3126.59	283.431
3129.84	298.724
3133.08	298.779
3136.32	300.732
3139.55	304.575
3142.79	323.668
3146.03	323.696
3149.26	306.581
3152.49	321.896
3155.72	326.707
3158.95	348.704
3162.18	348.747
3165.41	360.246
3168.64	356.443
3171.86	374.563
3175.08	361.176
3178.31	362.072
3181.53	382.993
3184.75	399.151
3187.96	404.764
3191.18	398.923
3194.4	410.239
3197.61	410.109
3200.82	401.398
3204.03	438.407
3207.24	433.532
3210.45	432.486
3213.66	438.129
3216.86	451.414
3220.07	429.5
3223.27	440.894
3226.48	450.433
3229.68	464.738
3232.87	482.894
3236.07	461.043
3239.27	490.693
3242.47	478.493
3245.66	475.836
3248.85	485.564
3252.04	490.584
3255.23	504.21
3258.42	494.936
3261.61	510.411
3264.8	509.585
3267.98	514.416
3271.16	513.464
3274.35	505.792
3277.53	521.045
3280.71	530.455
3283.89	528.298
3287.06	520.437
3290.24	539.229
3293.41	523.741
3296.58	556.833
3299.76	538.468
3302.93	538.352
3306.1	558.069
3309.26	557.745
3312.43	553.529
3315.59	580.618
3318.76	561.162
3321.92	564.466
3325.08	589.552
3328.24	580.534
3331.4	599.907
3334.56	614.567
3337.71	604.711
3340.87	593.972
3344.02	613.428
3347.17	635.844
3350.33	626.372
3353.47	624.426
3356.62	656.488
3359.77	665.017
3362.92	653.835
3366.06	665.294
3369.2	654.158
3372.34	677.951
3375.49	672.582
3378.62	689.903
3381.76	690.273
3384.9	701.002
3388.04	703.294
3391.17	710.327
3394.3	707.891
3397.43	725.108
3400.56	710.545
3403.69	732.076
3406.82	739.472
3409.95	744.074
3413.07	735.352
3416.2	754.055
3419.32	724.112
3422.44	763.712
3425.56	765.016
3428.68	762.362
3431.8	754.829
3434.91	757.65
3438.03	766.953
3441.14	734.362
3444.25	764.753
3447.36	758.712
3450.47	745.994
3453.58	745.554
3456.69	749.867
3459.79	755.011
3462.9	720.201
3466	735.759
3469.11	730.313
3472.21	718.076
3475.31	728.834
3478.4	705.542
3481.5	681.374
3484.6	670.488
3487.69	684.216
3490.79	690.47
3493.88	660.12
3496.97	647.691
3500.06	628.614
3503.15	621.837
3506.23	625.315
3509.32	636.343
3512.4	587.843
3515.49	573.345
3518.57	579.109
3521.65	580.396
3524.73	538.799
3527.81	537.409
3530.89	543.302
3533.96	532.102
3537.03	519.686
3540.11	513.898
3543.18	503.662
3546.25	498.944
3549.32	471.947
3552.39	475.045
3555.46	469.579
3558.52	469.868
3561.59	454.073
3564.65	447.633
3567.71	420.268
3570.77	429.056
3573.83	424.36
3576.89	406.405
3579.95	399.795
3583	391.255
3586.06	406.387
3589.11	383.584
3592.16	381.595
3595.21	386.234
3598.27	379.462
3601.31	359.438
3604.36	355.485
3607.41	340.152
3610.45	339.965
3613.5	335.033
3616.54	326.315
3619.58	328.949
3622.62	323.104
3625.66	325.762
3628.69	315.245
3631.73	299.07
3634.77	291.362
3637.8	292.206
3640.83	290.268
3643.86	265.779
3646.89	260.189
3649.92	265.805
3652.95	262.083
3655.98	246.681
3659	249.749
3662.02	231.144
3665.05	230.373
3668.07	222.885
3671.09	211.676
3674.11	205.182
3677.13	209.077
3680.14	191.266
3683.16	195.158
3686.17	186.763
3689.19	185.934
3692.2	181.322
3695.21	186.184
3698.22	178.686
3701.23	164.58
3704.23	174.186
3707.24	181.904
3710.24	170.602
3713.25	168.784
3716.25	148.867
3719.25	163.207
3722.25	171.824
3725.25	167.102
3728.25	163.314
3731.24	160.467
3734.24	154.747
3737.23	161.389
3740.22	164.206
3743.21	160.34
3746.21	162.171
3749.19	163.033
3752.18	151.53
3755.17	160.926
3758.15	150.39
3761.14	152.191
3764.12	159.66
3767.1	156.706
3770.08	151.876
3773.06	155.577
3776.04	146.052
3779.02	156.387
3781.99	148.778
3784.97	148.73
3787.94	152.467
3790.91	142.997
3793.88	153.373
3796.85	145.828
3799.82	146.786
3802.79	151.542
3805.76	144.975
3808.72	144.076
3811.69	150.747
3814.65	142.299
3817.61	149.929
3820.57	151.893
3823.53	151.022
3826.49	154.899
3829.45	151.198
3832.4	148.44
3835.36	145.693
3838.31	153.398
3841.26	155.412
3844.21	138.403
3847.16	148.025
3850.11	143.378
3853.06	148.268
3856	156.031
3858.95	155.214
3861.89	148.661
3864.84	154.526
3867.78	154.656
3870.72	150.939
3873.66	154.885
3876.6	146.354
3879.53	156.04
3882.47	158.995
3885.4	158.088
3888.34	143.711
3891.27	155.281
3894.2	148.577
3897.13	152.431
3900.06	158.189
3902.99	147.598
3905.91	149.485
3908.84	157.16
3911.76	156.167
3914.69	159.004
3917.61	154.141
3920.53	152.193
3923.45	157.894
3926.37	156.857
3929.28	155.805
3932.2	157.619
3935.11	154.68
3938.03	161.35
3940.94	153.689
3943.85	154.629
3946.76	140.259
3949.67	147.925
3952.58	147.943
3955.49	147.966
3958.39	148.961
3961.3	145.173
3964.2	147.141
3967.1	146.242
3970	151.106
3972.9	150.22
3975.8	155.092
3978.7	150.352
3981.6	151.363
3984.49	143.72
3987.39	151.451
3990.28	162.068
3993.17	141.883
3996.06	156.359
3998.95	156.402
4001.84	149.714
4004.73	150.729
4007.61	149.825
4010.5	146.031
4013.38	152.839
4016.27	153.865
4019.15	139.451
4022.03	144.334
4024.91	136.665
4027.79	150.251
4030.66	141.615
4033.54	157.154
4036.42	156.259
4039.29	152.467
4042.16	138.984
4045.03	160.342
4047.9	152.646
4050.77	147.862
4053.64	151.811
4056.51	128.603
4059.38	149.065
4062.24	160.798
4065.1	145.325
4067.97	160.958
4070.83	137.682
4073.69	158.19
4076.55	148.523
4079.41	146.639
4082.26	156.451
4085.12	151.644
4087.97	151.704
4090.83	146.884
4093.68	153.786
4096.53	152.869
4099.38	138.277
4102.23	161.798
4105.08	152.08
4107.93	148.207
4110.77	156.076
4113.62	152.186
4116.46	146.323
4119.3	145.332
4122.14	149.234
4124.98	144.346
4127.82	155.122
4130.66	158.108
4133.5	144.472
4136.33	142.624
4139.17	158.251
4142	150.216
4144.83	157.036
4147.67	153.171
4150.5	144.421
4153.33	149.346
4156.15	154.217
4158.98	142.384
4161.81	152.126
4164.63	146.239
4167.45	158.934
4170.28	159.898
4173.1	148.158
4175.92	143.268
4178.74	139.356
4181.56	157.949
4184.37	155.033
4187.19	141.363
4190	141.391
4192.82	153.186
4195.63	145.423
4198.44	149.43
4201.25	140.692
4204.06	146.665
4206.87	156.567
4209.68	139.963
4212.48	146.921
4215.29	150.936
4218.1	145.196
4220.9	148.314
4223.7	154.381
4226.5	146.618
4229.3	144.791
4232.1	143.958
4234.9	148.093
4237.69	152.248
4240.49	151.451
4243.28	146.679
4246.07	136.923
4248.87	148.074
4251.66	146.26
4254.45	141.438
4257.24	150.602
4260.03	139.747
4262.81	143.918
4265.6	156.137
4268.38	153.316
4271.17	158.539
4273.95	151.676
4276.73	145.778
4279.51	149.943
4282.29	145.009
4285.07	146.121
4287.84	147.214
4290.62	153.354
4293.39	142.276
4296.17	148.43
4298.94	151.563
4301.71	154.687
4304.48	155.781
4307.25	144.692
4310.02	146.804
4312.79	157.065
4315.55	147.99
4318.32	137.874
4321.08	156.241
4323.85	146.098
4326.61	156.31
4329.37	136.992
4332.13	138.028
4334.89	149.258
4337.65	153.346
4340.4	146.25
4343.16	137.115
4345.91	138.185
4348.67	151.513
4351.42	138.315
4354.17	154.761
4356.92	151.794
4359.67	150.868
4362.42	155.049
4365.17	147.984
4367.91	142.948
4370.66	140.995
4373.4	145.172
4376.14	141.136
4378.89	136.058
4381.63	150.489
4384.37	147.471
4387.11	148.595
4389.84	151.837
4392.58	142.747
4395.32	148.191
4398.05	153.558
4400.78	150.638
4403.52	151.844
4406.25	137.493
4408.98	150.127
4411.71	150.293
4414.44	151.478
4417.16	152.658
4419.89	139.182
4422.62	148.663
4425.34	146.685
4428.06	140.526
4430.78	152.133
4433.51	140.733
4436.22	151.3
4438.94	150.347
4441.66	146.234
4444.38	153.656
4447.1	146.386
4449.81	146.457
4452.52	149.666
4455.24	151.825
4457.95	153.971
4460.66	143.496
4463.37	151.961
4466.08	141.495
4468.78	149.971
4471.49	140.563
4474.2	145.907
4476.9	135.457
4479.6	145.048
4482.31	129.325
4485.01	142.103
4487.71	140.088
4490.41	152.877
4493.11	151.883
4495.8	146.623
4498.5	147.745
4501.19	160.516
4503.89	142.544
4506.58	150.02
4509.27	150.083
4511.96	146.963
4514.66	144.906
4517.34	150.285
4520.03	139.736
4522.72	149.393
4525.41	143.103
4528.09	146.383
4530.77	144.346
4533.46	140.178
4536.14	150.943
4538.82	151.053
4541.5	146.901
4544.18	145.947
4546.86	141.787
4549.53	152.615
4552.21	134.532
4554.88	140.047
4557.56	132.7
4560.23	155.506
4562.9	140.683
4565.57	139.889
4568.24	139.137
4570.91	154.574
4573.58	145.993
4576.24	151.443
4578.91	148.285
4581.58	144.092
4584.24	144.286
4586.9	136.761
4589.56	147.756
4592.22	147.837
4594.88	141.375
4597.54	140.389
4600.2	137.197
4602.86	143.875
4605.51	147.29
4608.17	156.193
4610.82	151.95
4613.47	132.32
4616.13	140.13
4618.78	154.561
4621.43	144.804
4624.07	144.942
4626.72	147.276
4629.37	146.294
4632.01	144.201
4634.66	148.718
4637.3	152.122
4639.94	136.711
4642.59	151.187
4645.23	145.765
4647.87	144.811
4650.5	151.667
4653.14	145.243
4655.78	142.103
4658.42	137.662
4661.05	150.06
4663.68	144.639
4666.31	141.427
4668.95	140.409
4671.58	142.762
4674.21	147.357
4676.84	139.621
4679.46	147.583
4682.09	130.844
4684.72	143.302
4687.34	143.408
4689.97	136.761
4692.59	141.372
4695.21	138.086
4697.83	146.073
4700.45	139.4
4703.07	146.269
4705.69	140.701
4708.3	139.645
4710.92	145.37
4713.54	146.572
4716.15	135.313
4718.76	143.295
4721.37	143.347
4723.99	143.389
4726.59	134.379
4729.2	140.12
4731.81	145.868
4734.42	153.894
4737.03	152.832
4739.63	143.801
4742.23	139.308
4744.84	149.588
4747.44	141.659
4750.04	138.257
4752.64	146.239
4755.24	143.976
4757.84	148.541
4760.44	139.46
4763.03	134.941
4765.63	133.844
4768.22	141.893
4770.82	139.704
4773.41	151.172
4776	134.118
4778.59	135.32
4781.18	142.234
4783.77	138.868
4786.36	137.788
4788.94	142.427
4791.53	131.053
4794.11	132.269
4796.7	139.22
4799.28	139.315
4801.86	135.977
4804.44	141.832
4807.02	127.024
4809.6	137.514
4812.18	138.807
4814.76	144.725
4817.33	144.892
4819.91	142.761
4822.48	140.623
4825.06	143.118
4827.63	122.411
4830.2	138.828
4832.77	136.691
4835.34	133.387
4837.91	134.758
4840.48	118.616
4843.04	130.51
4845.61	136.556
4848.17	137.908
4850.74	138.05
4853.3	128.697
4855.86	135.804
4858.42	140.715
4860.98	143.274
4863.54	133.995
4866.1	128.194
4868.66	144.854
4871.21	143.828
4873.77	147.504
4876.32	129.826
4878.88	139.411
4881.43	144.252
4883.98	140.774
4886.53	128.969
4889.08	132.615
4891.63	146.979
4894.18	141.109
4896.72	130.463
4899.27	146.026
4901.81	147.29
4904.36	134.234
4906.9	134.294
4909.44	137.928
4911.98	121.232
4914.52	126.022
4917.06	139.161
4919.6	132.007
4922.14	128.436
4924.67	136.815
4927.21	132.059
4929.74	128.482
4932.28	130.913
4934.81	140.549
4937.34	134.623
4939.87	135.872
4942.4	138.262
4944.93	137.103
4947.46	137.168
4949.99	128.839
4952.51	130.105
4955.04	138.556
4957.56	138.635
4960.08	135.124
4962.61	138.833
4965.13	142.585
4967.65	130.713
4970.17	140.486
4972.69	124.922
4975.2	125.031
4977.72	123.928
4980.24	125.249
4982.75	126.574
4985.27	131.544
4987.78	136.525
4990.29	123.299
4992.8	128.28
4995.31	140.569
4997.82	126.101