File: Data/3-Raman/raw/bu19w-e-ff11b-fi03-l_150 (500nm)_532nm_edge_100%_x100_vis_h50um_30sx2_01.txt
#Acq. time (s)=	30
#Accumulations=	2
#Range (cm-¹)=	100...5000
#Windows=	1
#Auto scanning=	Off
#Autofocus=	Off
#Macrospot=	Off
#AutoExposure=	Off
#Spike filter=	Multiple accum.
#Delay time (s)=	2
#Binning=	1
#Readout mode=	Signal
#DeNoise=	Off
#ICS correction=	On
#Dark correction=	Off
#Inst. Process=	Off
#Detector Gain=	Best Dynamic
#Detector ADC=	50 kHz HS
#Detector temperature (°C)=	-60.09
#Instrument=	LabRAM HR Evol
#Detector=	SIN-EM FIVIS
#Objective=	x100_VIS
#Grating=	150 (500nm)
#ND Filter=	100%
#Laser=	532nm_Edge
#Hole=	49.98
#Temperature=	0
#Range=	Visible
#StageXY=	75x50mm Scan+
#StageZ=	Z motor
#X (µm)=	0
#Y (µm)=	0
#Z (µm)=	-250.5
#Full time(mm:ss)=	1:05
#Project=	21_11_04
#Sample=	BU19w
#Site=
#Title=	BU19w-E-FF11b-FI03-L_150 (500nm)_532nm_Edge_100%_x100_VIS_H50um_30sX2
#Remark=
#Date=	04.11.2021 18:39
#Acquired=	04.11.2021 18:39:02
101.869	6551.07
106.493	7910.63
111.113	13037.3
115.732	19701.7
120.349	16043.3
124.964	8928.5
129.577	6894.05
134.185	6482.34
138.793	6045.34
143.399	5644.83
148.003	5350.85
152.602	5502.04
157.201	5673.79
161.798	6173.41
166.392	6976.74
170.982	8254.84
175.572	10287.1
180.16	13811.1
184.745	18644.5
189.326	23717.9
193.907	26057
198.486	23925.3
203.06	19281.6
207.634	14266.3
212.206	10566.8
216.776	8106.72
221.341	6351.36
225.906	5280.53
230.469	4614.85
235.028	4077.5
239.586	3777.26
244.142	3932.96
248.694	5118.26
253.246	6097.52
257.795	4334.79
262.341	2682.32
266.886	2070.2
271.428	1832.93
275.967	1661.68
280.505	1552.83
285.041	1496.91
289.573	1381.42
294.105	1345.5
298.632	1332.73
303.159	1343.14
307.685	1303.15
312.205	1291.3
316.726	1281.09
321.242	1243.63
325.758	1244.74
330.272	1354.8
334.782	1719.47
339.292	3299.66
343.797	4681.67
348.302	3314.79
352.803	1958.26
357.304	1563.14
361.802	1467.91
366.297	1427.85
370.791	1442.34
375.281	1534.05
379.77	1851.5
384.256	2319.61
388.741	2839.44
393.223	2854.28
397.704	2032.2
402.18	1681.21
406.657	1646.64
411.13	1732.07
415.602	1816.33
420.07	2047.7
424.538	2347.39
429.002	2994.06
433.465	4484.37
437.925	7680.34
442.384	15229.1
446.839	36527.8
451.294	38109.3
455.745	38141.6
460.196	37098.8
464.642	17359.2
469.089	10015.4
473.531	7093.83
477.971	5485.62
482.411	4313.31
486.846	3583.33
491.282	3249.43
495.713	3174.44
500.144	2951.84
504.572	2778.99
508.997	2558.54
513.421	2331.16
517.842	2128.23
522.263	1927.11
526.679	1787.81
531.093	1705.4
535.507	1651.05
539.917	1571.22
544.327	1496.99
548.733	1420.37
553.137	1323.77
557.54	1319.24
561.94	1337.31
566.337	1304.96
570.734	1320.86
575.127	1317.09
579.518	1268.26
583.909	1328.8
588.295	1266.14
592.68	1221.16
597.064	1175.52
601.445	1145.66
605.823	1124.82
610.201	1118
614.575	1097.99
618.947	1114.04
623.317	1078.06
627.686	1063.76
632.052	1049.53
636.415	1081.5
640.777	1030.55
645.138	998.749
649.495	991.685
653.85	968.147
658.205	958.641
662.556	1009.99
666.905	1025.58
671.252	1021.68
675.597	1091.84
679.941	1322.26
684.282	1615.92
688.62	1546.77
692.957	1257.12
697.293	1064.72
701.625	971.199
705.955	945.35
710.283	917.759
714.609	895.428
718.933	870.001
723.257	880.941
727.577	875.995
731.894	861.537
736.21	874.1
740.524	834.15
744.835	861.788
749.147	845.526
753.454	831.655
757.759	868.383
762.063	906.147
766.364	936.125
770.663	954.427
774.96	1086.59
779.257	1300
783.55	1707.5
787.841	1995.6
792.13	2453.75
796.417	3052.08
800.702	2470.55
804.985	1607.19
809.266	1174.92
813.545	1022.15
817.821	970.726
822.096	932.437
826.371	949.435
830.641	908.168
834.91	888.917
839.176	875.088
843.441	866.668
847.703	848.027
851.964	836.557
856.222	868.091
860.479	962.377
864.733	1060.79
868.986	1020.08
873.236	866.116
877.485	836.276
881.731	796.505
885.975	752.181
890.218	781.742
894.458	723.81
898.696	747.534
902.933	731.918
907.167	735.934
911.399	715.048
915.63	693.654
919.858	702.38
924.084	664.539
928.308	634.92
932.531	622.376
936.749	598.015
940.967	600.314
945.184	608.944
949.398	582.272
953.61	560.116
957.821	550.854
962.029	539.564
966.236	532.607
970.44	489.652
974.642	503.07
978.843	497.454
983.041	483.477
987.236	469.51
991.43	491.546
995.623	502.29
999.813	483.721
1004	485.375
1008.19	490.289
1012.37	492.062
1016.55	508.607
1020.73	479.329
1024.91	484.057
1029.09	485.386
1033.27	506.891
1037.44	495.837
1041.61	563.337
1045.78	584.864
1049.94	725.106
1054.11	916.594
1058.27	1038.21
1062.43	1084
1066.59	1500.51
1070.75	1976.21
1074.9	1597.78
1079.05	963.342
1083.2	653.644
1087.35	559.313
1091.5	557.527
1095.65	513.766
1099.79	505.333
1103.93	480.615
1108.07	459.232
1112.21	454.515
1116.34	451.887
1120.48	437.67
1124.61	465.751
1128.74	487.94
1132.86	514.477
1136.99	600.449
1141.11	801.655
1145.23	1161.14
1149.35	1528.7
1153.47	1282.56
1157.59	821.9
1161.7	579.552
1165.82	486.612
1169.92	442.085
1174.03	434.561
1178.14	416.661
1182.24	408.039
1186.35	418.859
1190.45	409.895
1194.55	384.458
1198.64	396.8
1202.74	429.338
1206.83	444.387
1210.92	450.248
1215.01	479.338
1219.1	525.439
1223.18	524.151
1227.27	473.83
1231.35	458.932
1235.43	451.395
1239.5	454.187
1243.58	427.899
1247.65	446.704
1251.72	483.736
1255.8	505.92
1259.86	527.214
1263.93	529.612
1267.99	503.083
1272.06	460.549
1276.12	433.976
1280.18	410.341
1284.23	380.565
1288.29	381.853
1292.34	366.993
1296.39	371.194
1300.44	342.113
1304.49	371.407
1308.53	345.236
1312.58	364.394
1316.62	351.169
1320.66	360.028
1324.7	361.713
1328.73	361.305
1332.77	370.921
1336.8	339.286
1340.83	375.731
1344.86	374.053
1348.88	388.319
1352.91	403.536
1356.93	453.485
1360.95	538.921
1364.97	712.229
1368.99	983.956
1373.01	936.286
1377.02	730.153
1381.03	539.338
1385.04	439.614
1389.05	403.073
1393.06	381.404
1397.06	356.936
1401.06	347.217
1405.06	332.54
1409.06	334.644
1413.06	327.907
1417.05	306.371
1421.05	318.372
1425.04	325.408
1429.03	325.38
1433.01	329.301
1437	317.437
1440.99	319.389
1444.97	324.266
1448.95	327.136
1452.93	302.338
1456.9	303.159
1460.88	301.96
1464.85	315.431
1468.82	304.265
1472.79	307.896
1476.76	297.753
1480.73	312.087
1484.69	298.962
1488.65	312.236
1492.61	315.733
1496.57	315.334
1500.53	305.228
1504.48	320.486
1508.43	313.449
1512.39	318.11
1516.33	298.51
1520.28	304.191
1524.23	322.498
1528.17	338.877
1532.11	325.237
1536.05	319.369
1539.99	338.707
1543.93	359.982
1547.86	367.688
1551.8	352.142
1555.73	359.809
1559.66	394.523
1563.58	379.809
1567.51	396.987
1571.44	398.649
1575.36	423.478
1579.28	436.675
1583.2	440.196
1587.11	452.352
1591.03	462.547
1594.94	471.754
1598.85	496.32
1602.76	505.519
1606.67	507.105
1610.58	512.545
1614.48	523.761
1618.38	533.122
1622.29	522.345
1626.18	552.805
1630.08	542.177
1633.98	545.112
1637.87	544.217
1641.76	523.329
1645.65	510.209
1649.54	505.755
1653.43	513.795
1657.31	480.524
1661.2	467.361
1665.08	444.492
1668.96	437.895
1672.83	431.168
1676.71	398.447
1680.58	393.417
1684.46	369.077
1688.33	370.641
1692.2	333.815
1696.06	315.203
1699.93	320.471
1703.79	306.583
1707.66	310.763
1711.52	277.819
1715.37	283.869
1719.23	280.447
1723.08	271.384
1726.94	282.119
1730.79	269.265
1734.64	260.235
1738.49	242.801
1742.33	264.618
1746.18	251.889
1750.02	241.213
1753.86	238.094
1757.7	244.385
1761.54	229.712
1765.37	239.054
1769.21	243.81
1773.04	231.965
1776.87	235.933
1780.7	236.254
1784.53	227.287
1788.35	232.341
1792.17	228.995
1796	220.952
1799.82	219.45
1803.64	221.578
1807.45	212.377
1811.27	235.186
1815.08	231.577
1818.89	238.248
1822.7	222.207
1826.51	215.561
1830.32	212.634
1834.12	225.672
1837.92	230.177
1841.72	225.233
1845.52	217.43
1849.32	217.172
1853.12	213.079
1856.91	204.264
1860.7	227.137
1864.5	238.71
1868.28	219.607
1872.07	225.63
1875.86	213.177
1879.64	230.329
1883.42	218.017
1887.21	211.281
1890.98	233.307
1894.76	231.432
1898.54	214.833
1902.31	223.167
1906.08	226.032
1909.85	218.79
1913.62	224.522
1917.39	234.903
1921.16	228.809
1924.92	247.734
1928.68	213.879
1932.44	239.417
1936.2	236.173
1939.96	239.442
1943.71	246.458
1947.47	242.264
1951.22	249.12
1954.97	236.17
1958.72	243.749
1962.46	241.847
1966.21	251.199
1969.95	259.537
1973.7	241.5
1977.43	261.861
1981.17	260.606
1984.91	257.442
1988.65	257.052
1992.38	266.872
1996.11	250.568
1999.84	249.127
2003.57	269.917
2007.3	264.732
2011.02	272.405
2014.75	259.813
2018.47	265.747
2022.19	269.062
2025.91	273.441
2029.62	271.446
2033.34	276.868
2037.05	268.69
2040.76	268.714
2044.47	275.133
2048.18	279.718
2051.89	270.623
2055.59	250.551
2059.3	279.158
2063	277.717
2066.7	268.988
2070.4	251.961
2074.1	264.41
2077.79	273.223
2081.49	284.871
2085.18	278.896
2088.87	262.39
2092.56	271.712
2096.25	279.315
2099.93	265.509
2103.61	282.287
2107.3	266.465
2110.98	264.552
2114.66	285.87
2118.33	283.911
2122.01	271.631
2125.68	269.508
2129.36	272.911
2133.03	275.349
2136.7	276.841
2140.36	271.822
2144.03	293.498
2147.7	269.082
2151.36	265.867
2155.02	251.669
2158.68	252.174
2162.34	246.308
2165.99	255.102
2169.65	249.331
2173.3	245.491
2176.95	244.452
2180.6	251.634
2184.25	244.252
2187.9	256.026
2191.54	240.614
2195.18	246.221
2198.83	235.501
2202.47	245.76
2206.11	239.647
2209.74	241.787
2213.38	252.206
2217.01	246.169
2220.64	230.018
2224.27	235.901
2227.9	229.816
2231.53	238.472
2235.16	231.47
2238.78	227.216
2242.4	237.773
2246.02	218.646
2249.64	215.273
2253.26	217.503
2256.88	228.158
2260.49	227.631
2264.11	228.948
2267.72	225.597
2271.33	228.864
2274.93	228.326
2278.54	220.173
2282.15	235.46
2285.75	221.466
2289.35	227.306
2292.95	217.043
2296.55	227.59
2300.15	219.222
2303.74	218.389
2307.34	225.09
2310.93	218.491
2314.52	233.659
2318.11	226.986
2321.7	238.267
2325.28	225.734
2328.87	211.298
2332.45	233.701
2336.03	225.837
2339.61	227.381
2343.19	223.255
2346.77	218.177
2350.34	214.035
2353.92	208.963
2357.49	226.293
2361.06	210.943
2364.63	227.252
2368.2	223.101
2371.76	229.203
2375.33	202.92
2378.89	208.104
2382.45	229.881
2386.01	212.975
2389.57	217.282
2393.13	217.034
2396.68	208.598
2400.23	209.408
2403.79	216.743
2407.34	209.453
2410.88	198.566
2414.43	218.012
2417.98	207.22
2421.52	216.68
2425.06	205.943
2428.61	206.3
2432.14	199.302
2435.68	193.245
2439.22	217.838
2442.75	193.211
2446.29	212.341
2449.82	205.404
2453.35	203.159
2456.88	221.474
2460.4	201.05
2463.93	192.796
2467.45	205.135
2470.98	206.289
2474.5	215.657
2478.02	202.295
2481.54	206.9
2485.05	205.779
2488.57	209.237
2492.08	204.322
2495.59	195.58
2499.1	184.095
2502.61	199.728
2506.12	205.929
2509.63	198.084
2513.13	205.162
2516.63	212.264
2520.13	212.89
2523.63	199.48
2527.13	194.633
2530.63	197.24
2534.12	209.099
2537.62	195.171
2541.11	192.365
2544.6	193.341
2548.09	202.722
2551.58	186.244
2555.06	191.986
2558.55	200.628
2562.03	193.513
2565.51	200.41
2568.99	188.758
2572.47	204.2
2575.95	196.335
2579.43	186.584
2582.9	193.756
2586.37	199.082
2589.84	198.703
2593.31	200.116
2596.78	206.253
2600.25	205.799
2603.71	200.546
2607.18	199.951
2610.64	179.992
2614.1	197.306
2617.56	206.079
2621.02	204.196
2624.47	195.548
2627.93	196.454
2631.38	199.247
2634.83	201.03
2638.28	193.162
2641.73	197.723
2645.18	190.756
2648.62	195.256
2652.07	196.838
2655.51	199.312
2658.95	204.582
2662.39	212.647
2665.83	189.467
2669.27	194.677
2672.7	209.25
2676.14	209.716
2679.57	183.055
2683	196.727
2686.43	206.684
2689.86	195.308
2693.29	212.919
2696.71	190.414
2700.13	201.487
2703.56	201.399
2706.98	205.021
2710.4	201.357
2713.82	196.801
2717.23	203.453
2720.65	197.109
2724.06	213.169
2727.47	207.799
2730.88	204.302
2734.29	202.657
2737.7	192.573
2741.11	217.171
2744.51	207.973
2747.91	209.062
2751.32	196.992
2754.72	202.768
2758.11	206.64
2761.51	217.121
2764.91	211.531
2768.3	215.331
2771.7	214.381
2775.09	220.01
2778.48	205.817
2781.87	227.383
2785.25	219.738
2788.64	227.141
2792.03	225.128
2795.41	228.744
2798.79	214.523
2802.17	226.549
2805.55	222.624
2808.93	216.828
2812.3	238.167
2815.68	228.601
2819.05	245.199
2822.42	227.272
2825.79	244.848
2829.16	223.268
2832.53	235.283
2835.89	231.497
2839.26	251.971
2842.62	241.752
2845.98	250.223
2849.34	234.543
2852.7	256.244
2856.06	250.852
2859.41	238.003
2862.77	249.499
2866.12	242.286
2869.47	259.457
2872.82	249.406
2876.17	260.013
2879.52	274.401
2882.87	253.002
2886.21	274.927
2889.55	277.057
2892.89	273.514
2896.23	288.802
2899.57	268.126
2902.91	288.072
2906.25	302.312
2909.58	291.927
2912.91	295.712
2916.25	296.64
2919.58	313.604
2922.91	323.92
2926.23	309.624
2929.56	324.584
2932.88	315.885
2936.21	333.566
2939.53	336.133
2942.85	337.754
2946.17	350.68
2949.49	346.666
2952.8	346.406
2956.12	362.121
2959.43	382.57
2962.74	393.653
2966.06	368.161
2969.37	406.565
2972.67	427.237
2975.98	405.7
2979.28	415.204
2982.59	434.978
2985.89	434.135
2989.19	454.914
2992.49	449.423
2995.79	453.346
2999.09	480.798
3002.38	480.059
3005.68	516.004
3008.97	522.848
3012.26	520.308
3015.55	550.759
3018.84	563.317
3022.13	548.522
3025.41	591.285
3028.7	594.442
3031.98	597.593
3035.26	643.254
3038.54	640.706
3041.82	663.706
3045.1	683.899
3048.38	697.492
3051.65	726.252
3054.92	745.585
3058.2	757.321
3061.47	786.847
3064.73	826.941
3068	843.228
3071.27	854.645
3074.54	892.671
3077.8	907.015
3081.06	935.195
3084.32	970.892
3087.58	986.626
3090.84	1066.31
3094.1	1042.68
3097.35	1096.43
3100.61	1097.72
3103.86	1126.31
3107.11	1196.41
3110.36	1227.4
3113.61	1292.25
3116.86	1298.2
3120.11	1376.57
3123.35	1386.39
3126.59	1441.93
3129.84	1473.61
3133.08	1552.98
3136.32	1599.93
3139.55	1632.5
3142.79	1670.78
3146.03	1723.36
3149.26	1764.63
3152.49	1863.18
3155.72	1877.73
3158.95	1945.78
3162.18	1997.54
3165.41	2072.25
3168.64	2143.91
3171.86	2202.05
3175.08	2219.06
3178.31	2305.53
3181.53	2371.89
3184.75	2416.36
3187.96	2424.29
3191.18	2489.34
3194.4	2557.2
3197.61	2678.33
3200.82	2648.85
3204.03	2692.8
3207.24	2765.37
3210.45	2794.27
3213.66	2876.62
3216.86	2908.74
3220.07	2954.18
3223.27	2990.19
3226.48	3046.49
3229.68	3034.35
3232.87	3126.2
3236.07	3101.69
3239.27	3178.79
3242.47	3232.33
3245.66	3228.92
3248.85	3275.05
3252.04	3266.27
3255.23	3358.7
3258.42	3355.73
3261.61	3373.29
3264.8	3406.62
3267.98	3471
3271.16	3467.2
3274.35	3449.8
3277.53	3505.95
3280.71	3558.49
3283.89	3532.96
3287.06	3647.83
3290.24	3724.07
3293.41	3664.28
3296.58	3683.48
3299.76	3745.47
3302.93	3692.3
3306.1	3764.71
3309.26	3822.43
3312.43	3918.41
3315.59	3909.56
3318.76	4034.39
3321.92	4039.41
3325.08	4060.57
3328.24	4194.32
3331.4	4234.33
3334.56	4317.08
3337.71	4352.88
3340.87	4304.06
3344.02	4418.48
3347.17	4503.7
3350.33	4514.69
3353.47	4630.18
3356.62	4691.56
3359.77	4722.05
3362.92	4767.29
3366.06	4856.04
3369.2	4906.42
3372.34	4928.71
3375.49	5063.95
3378.62	5082.43
3381.76	5108.78
3384.9	5206.7
3388.04	5216.29
3391.17	5324.37
3394.3	5318.89
3397.43	5319.19
3400.56	5366.3
3403.69	5546.79
3406.82	5479.31
3409.95	5477.62
3413.07	5526.32
3416.2	5582.29
3419.32	5637.02
3422.44	5641.73
3425.56	5614.73
3428.68	5591.45
3431.8	5675.3
3434.91	5624.37
3438.03	5672.21
3441.14	5606.25
3444.25	5587.99
3447.36	5628.59
3450.47	5539.42
3453.58	5568.55
3456.69	5424.27
3459.79	5477.28
3462.9	5437.87
3466	5339.36
3469.11	5276.38
3472.21	5255.94
3475.31	5165.3
3478.4	5130.92
3481.5	5067.51
3484.6	4982.59
3487.69	4914.17
3490.79	4865.38
3493.88	4743.52
3496.97	4674.42
3500.06	4586.1
3503.15	4493.35
3506.23	4422.44
3509.32	4310.27
3512.4	4209.97
3515.49	4170.51
3518.57	4018.01
3521.65	3965.81
3524.73	3869.64
3527.81	3744.88
3530.89	3684.16
3533.96	3632.17
3537.03	3544.34
3540.11	3447.22
3543.18	3328.32
3546.25	3257.53
3549.32	3192.14
3552.39	3072.9
3555.46	3026.02
3558.52	2965.42
3561.59	2867.9
3564.65	2790.48
3567.71	2686.97
3570.77	2626.96
3573.83	2568.45
3576.89	2499.61
3579.95	2432.44
3583	2401.12
3586.06	2353.44
3589.11	2264.05
3592.16	2151.63
3595.21	2137.79
3598.27	2045.12
3601.31	2028.29
3604.36	1982.86
3607.41	1885.26
3610.45	1887.06
3613.5	1835.83
3616.54	1764.74
3619.58	1719.31
3622.62	1657.97
3625.66	1608.06
3628.69	1557.38
3631.73	1496.29
3634.77	1444.57
3637.8	1404.57
3640.83	1317.73
3643.86	1252.69
3646.89	1180.5
3649.92	1138.02
3652.95	1080.8
3655.98	996.593
3659	967.485
3662.02	878.913
3665.05	838.106
3668.07	795.883
3671.09	716.115
3674.11	698.564
3677.13	659.324
3680.14	650.304
3683.16	588.309
3686.17	565.964
3689.19	547.395
3692.2	520.296
3695.21	503.598
3698.22	473.493
3701.23	462.436
3704.23	439.973
3707.24	429.826
3710.24	413.911
3713.25	378.932
3716.25	383.82
3719.25	367.81
3722.25	356.499
3725.25	348.962
3728.25	332.818
3731.24	322.363
3734.24	314.732
3737.23	314.684
3740.22	311.753
3743.21	296.415
3746.21	309.599
3749.19	315.133
3752.18	287.384
3755.17	283.401
3758.15	296.511
3761.14	278.305
3764.12	285.682
3767.1	249.499
3770.08	267.32
3773.06	265.285
3776.04	265.162
3779.02	261.276
3781.99	260.244
3784.97	265.826
3787.94	242.154
3790.91	245.879
3793.88	243.037
3796.85	243.047
3799.82	245.902
3802.79	259.179
3805.76	254.532
3808.72	248
3811.69	239.589
3814.65	250.088
3817.61	229.386
3820.57	232.335
3823.53	245.707
3826.49	243.006
3829.45	236.514
3832.4	259.414
3835.36	233.963
3838.31	236.984
3841.26	247.614
3844.21	242.086
3847.16	252.738
3850.11	238.646
3853.06	239.803
3856	247.646
3858.95	249.775
3861.89	235.659
3864.84	235.856
3867.78	230.309
3870.72	234.316
3873.66	231.608
3876.6	231.767
3879.53	222.297
3882.47	248.34
3885.4	253.23
3888.34	237.916
3891.27	252.391
3894.2	245.704
3897.13	225.521
3900.06	241.852
3902.99	238.945
3905.91	241.772
3908.84	255.204
3911.76	246.504
3914.69	243.549
3917.61	235.773
3920.53	237.652
3923.45	248.12
3926.37	239.362
3929.28	242.097
3932.2	237.147
3935.11	243.753
3938.03	231.253
3940.94	235.082
3943.85	241.758
3946.76	245.573
3949.67	242.712
3952.58	236.038
3955.49	234.16
3958.39	245.715
3961.3	260.162
3964.2	249.708
3967.1	234.466
3970	241.289
3972.9	233.729
3975.8	233.839
3978.7	250.266
3981.6	246.505
3984.49	232.163
3987.39	228.378
3990.28	232.282
3993.17	249.618
3996.06	233.336
3998.95	243.025
4001.84	241.18
4004.73	249.93
4007.61	232.686
4010.5	246.277
4013.38	239.624
4016.27	230.074
4019.15	238.853
4022.03	237.017
4024.91	237.112
4027.79	235.281
4030.66	214.115
4033.54	225.818
4036.42	235.599
4039.29	217.327
4042.16	224.214
4045.03	234.942
4047.9	233.088
4050.77	218.641
4053.64	231.354
4056.51	214.985
4059.38	229.667
4062.24	225.895
4065.1	219.203
4067.97	226.119
4070.83	223.308
4073.69	220.493
4076.55	226.436
4079.41	225.561
4082.26	205.189
4085.12	217.958
4087.97	220.971
4090.83	206.418
4093.68	220.182
4096.53	204.639
4099.38	226.227
4102.23	209.702
4105.08	210.76
4107.93	202.012
4110.77	218.702
4113.62	214.823
4116.46	203.09
4119.3	217.753
4122.14	224.585
4124.98	204.042
4127.82	213.843
4130.66	204.121
4133.5	199.322
4136.33	213.2
4139.17	214.105
4142	213.826
4144.83	215.741
4147.67	210.917
4150.5	215.897
4153.33	214.96
4156.15	196.321
4158.98	206.971
4161.81	207.89
4164.63	210.799
4167.45	205.881
4170.28	214.664
4173.1	212.702
4175.92	198.032
4178.74	202.922
4181.56	212.717
4184.37	219.589
4187.19	212.778
4190	199.122
4192.82	216.81
4195.63	201.241
4198.44	205.282
4201.25	200.499
4204.06	201.603
4206.87	195.831
4209.68	214.61
4212.48	185.248
4215.29	198.134
4218.1	193.431
4220.9	202.514
4223.7	200.745
4226.5	198.946
4229.3	202.115
4232.1	195.407
4234.9	197.622
4237.69	203.823
4240.49	194.156
4243.28	201.373
4246.07	199.659
4248.87	191.948
4251.66	195.18
4254.45	195.415
4257.24	206.64
4260.03	189.836
4262.81	208.105
4265.6	197.305
4268.38	187.498
4271.17	196.79
4273.95	197.028
4276.73	201.264
4279.51	189.322
4282.29	197.556
4285.07	187.581
4287.84	192.745
4290.62	198.905
4293.39	196.959
4296.17	199.089
4298.94	181.978
4301.71	171.931
4304.48	197.391
4307.25	186.322
4310.02	177.282
4312.79	189.597
4315.55	187.658
4318.32	195.873
4321.08	185.759
4323.85	197.004
4326.61	188.895
4329.37	187.919
4332.13	185.905
4334.89	187.974
4337.65	177.8
4340.4	191.093
4343.16	188.087
4345.91	183.057
4348.67	187.223
4351.42	183.23
4354.17	180.299
4356.92	177.349
4359.67	193.827
4362.42	177.564
4365.17	183.827
4367.91	180.862
4370.66	174.833
4373.4	170.82
4376.14	186.299
4378.89	191.508
4381.63	189.524
4384.37	194.744
4387.11	186.644
4389.84	182.72
4392.58	167.483
4395.32	170.91
4398.05	193.887
4400.78	199.298
4403.52	180.865
4406.25	186.264
4408.98	183.373
4411.71	186.697
4414.44	183.752
4417.16	189.129
4419.89	180.885
4422.62	184.134
4425.34	189.49
4428.06	191.722
4430.78	183.5
4433.51	193.051
4436.22	184.805
4438.94	188.065
4441.66	189.213
4444.38	174.633
4447.1	185.212
4449.81	181.102
4452.52	172.773
4455.24	183.346
4457.95	189.705
4460.66	170.828
4463.37	176.149
4466.08	182.523
4468.78	187.859
4471.49	183.733
4474.2	174.35
4476.9	190.273
4479.6	176.695
4482.31	179.999
4485.01	185.421
4487.71	181.322
4490.41	192.021
4493.11	187.869
4495.8	183.676
4498.5	184.814
4501.19	184.884
4503.89	176.458
4506.58	176.526
4509.27	184.024
4511.96	174.552
4514.66	175.692
4517.34	186.396
4520.03	186.492
4522.72	177.039
4525.41	179.278
4528.09	184.709
4530.77	184.827
4533.46	170.025
4536.14	169.078
4538.82	185.213
4541.5	175.747
4544.18	179.092
4546.86	170.679
4549.53	170.822
4552.21	177.411
4554.88	166.876
4557.56	177.828
4560.23	165.191
4562.9	173.024
4565.57	165.814
4568.24	190.027
4570.91	187.115
4573.58	168.788
4576.24	184.012
4578.91	176.529
4581.58	166.929
4584.24	182.399
4586.9	177.081
4589.56	176.107
4592.22	170.749
4594.88	182.86
4597.54	178.628
4600.2	161.248
4602.86	173.416
4605.51	156.051
4608.17	172.634
4610.82	181.572
4613.47	177.342
4616.13	184.092
4618.78	173.262
4621.43	169.03
4624.07	173.6
4626.72	171.546
4629.37	179.417
4632.01	170.721
4634.66	181.889
4637.3	165.398
4639.94	177.669
4642.59	162.263
4645.23	170.152
4647.87	179.21
4650.5	163.89
4653.14	164.164
4655.78	177.768
4658.42	172.217
4661.05	173.489
4663.68	181.497
4666.31	178.321
4668.95	168.379
4671.58	164.036
4674.21	163.045
4676.84	173.265
4679.46	167.784
4682.09	171.276
4684.72	166.905
4687.34	158.029
4689.97	171.654
4692.59	158.269
4695.21	164.012
4697.83	173.144
4700.45	175.52
4703.07	172.247
4705.69	175.735
4708.3	166.782
4710.92	167.996
4713.54	165.813
4716.15	178.342
4718.76	175.012
4721.37	176.209
4723.99	183.062
4726.59	175.204
4729.2	170.754
4731.81	176.517
4734.42	169.794
4737.03	169.877
4739.63	161.99
4742.23	176.836
4744.84	166.651
4747.44	170.105
4750.04	171.256
4752.64	170.137
4755.24	169.016
4757.84	167.892
4760.44	161.091
4763.03	167.965
4765.63	173.712
4768.22	182.922
4770.82	165.934
4773.41	164.863
4776	168.36
4778.59	162.727
4781.18	166.225
4783.77	166.298
4786.36	164.088
4788.94	163.019
4791.53	168.823
4794.11	171.205
4796.7	156.408
4799.28	161.101
4801.86	164.664
4804.44	165.949
4807.02	162.66
4809.6	154.775
4812.18	164.15
4814.76	168.942
4817.33	162.21
4819.91	165.88
4822.48	156.826
4825.06	166.295
4827.63	158.38
4830.2	164.387
4832.77	176.245
4835.34	163.676
4837.91	166.26
4840.48	160.686
4843.04	185.523
4845.61	152.966
4848.17	171.945
4850.74	170.947
4853.3	161.606
4855.86	162.847
4858.42	163.088
4860.98	173.933
4863.54	165.871
4866.1	168.366
4868.66	149.584
4871.21	169.871
4873.77	161.721
4876.32	153.538
4878.88	171.446
4881.43	165.623
4883.98	160.969
4886.53	149.176
4889.08	152.835
4891.63	157.689
4894.18	170.879
4896.72	167.397
4899.27	161.522
4901.81	160.409
4904.36	159.291
4906.9	160.555
4909.44	146.287
4911.98	151.092
4914.52	163.052
4917.06	169.024
4919.6	164.262
4922.14	170.253
4924.67	159.518
4927.21	157.157
4929.74	160.752
4932.28	165.584
4934.81	144.137
4937.34	154.966
4939.87	169.391
4942.4	150.232
4944.93	157.459
4947.46	155.138
4949.99	155.206
4952.51	156.486
4955.04	155.35
4957.56	153.039
4960.08	150.738
4962.61	153.257
4965.13	160.634
4967.65	146.375
4970.17	154.957
4972.69	157.51
4975.2	155.232
4977.72	157.781
4980.24	150.662
4982.75	159.278
4985.27	164.278
4987.78	145.02
4990.29	150.023
4992.8	156.246
4995.31	153.957
4997.82	155.342