File: Data/3-Raman/raw/bu19w-e-ff11-fi10-v_150 (500nm)_633nm_edge_100%_x100_vis_h50um_30sx2_01.txt
#Acq. time (s)=	30
#Accumulations=	2
#Range (cm-¹)=	100...4000
#Windows=	1
#Auto scanning=	Off
#Autofocus=	Off
#Macrospot=	Off
#AutoExposure=	Off
#Spike filter=	Multiple accum.
#Delay time (s)=	2
#Binning=	1
#Readout mode=	Signal
#DeNoise=	Off
#ICS correction=	On
#Dark correction=	Off
#Inst. Process=	Off
#Detector Gain=	Best Dynamic
#Detector ADC=	50 kHz HS
#Detector temperature (°C)=	-60.09
#Instrument=	LabRAM HR Evol
#Detector=	SIN-EM FIVIS
#Objective=	x100_VIS
#Grating=	150 (500nm)
#ND Filter=	100%
#Laser=	633nm_Edge
#Hole=	49.98
#Temperature=	0
#Range=	Visible
#StageXY=	75x50mm Scan+
#StageZ=	Z motor
#X (µm)=	0
#Y (µm)=	0
#Z (µm)=	-270.9
#Full time(mm:ss)=	1:04
#Project=	21_11_04
#Sample=	BU19w
#Site=
#Title=	BU19w-E-FF11-FI10-V_150 (500nm)_633nm_Edge_100%_x100_VIS_H50um_30sX2
#Remark=
#Date=	04.11.2021 11:51
#Acquired=	04.11.2021 11:51:31
102.881	137.767
109.397	128.355
115.908	117.973
122.414	107.542
128.914	98.0457
135.409	96.167
141.898	101.911
148.383	102.89
154.861	96.2312
161.335	106.824
167.801	106.88
174.264	102.099
180.721	82.8871
187.173	78.963
193.62	73.1022
200.061	73.0142
206.496	72.0488
212.926	72.0183
219.352	73.8975
225.772	78.6101
232.185	98.4812
238.595	118.344
244.999	101.177
251.397	82.1375
257.791	78.2903
264.178	82.0531
270.561	79.191
276.939	77.2923
283.31	88.6501
289.678	92.3915
296.039	75.2699
302.396	76.1512
308.746	76.0771
315.093	79.7886
321.433	97.6686
327.768	139.147
334.099	125.92
340.423	88.1706
346.743	77.7684
353.058	80.551
359.367	83.3035
365.671	75.6957
371.971	75.6199
378.265	67.0934
384.553	63.2902
390.837	68.0143
397.116	64.354
403.389	58.8523
409.657	61.8067
415.92	57.1739
422.178	63.8655
428.431	69.4769
434.678	77.8048
440.921	74.7934
447.158	78.3455
453.391	81.8593
459.618	74.2015
465.84	83.4291
472.057	62.8751
478.27	58.2258
484.477	64.7547
490.679	61.9676
496.876	64.7782
503.068	62.0068
509.255	72.3014
515.436	69.5577
521.613	78.07
527.785	73.5383
533.952	82.1826
540.113	71.0927
546.27	73.1041
552.423	63.7197
558.568	63.7373
564.711	65.5374
570.848	65.3877
576.979	57.6796
583.107	60.3118
589.228	61.1048
595.345	58.2355
601.458	64.7728
607.565	65.8034
613.667	73.4203
619.764	78.3226
625.856	63.5287
631.944	66.481
638.026	60.8319
644.104	65.4515
650.177	55.0058
656.244	58.6201
662.308	50.0431
668.365	55.5171
674.418	52.6876
680.467	54.5532
686.511	48.0668
692.549	52.8379
698.582	50.1452
704.611	49.3079
710.635	48.4344
716.655	51.2199
722.669	46.4945
728.679	54.8717
734.683	49.1556
740.683	47.1988
746.678	49.9281
752.669	46.1542
758.654	50.8129
764.635	50.9124
770.611	57.6146
776.582	52.1392
782.549	45.6527
788.511	50.4227
794.466	53.2876
800.419	49.5075
806.366	47.5767
812.309	52.2144
818.247	51.1663
824.18	43.5509
830.108	47.1919
836.033	53.721
841.952	50.9936
847.865	50.1473
853.776	44.6257
859.681	55.1051
865.58	49.5898
871.476	52.5552
877.366	57.366
883.253	54.5609
889.134	57.4069
895.012	61.1665
900.883	62.0054
906.751	59.0214
912.614	54.1558
918.473	55.9238
924.326	54.0073
930.174	55.9278
936.019	57.9088
941.859	61.8907
947.693	65.9239
953.525	74.7517
959.35	80.7275
965.171	78.0507
970.988	84.9068
976.801	84.9588
982.608	110.77
988.411	132.621
994.209	117.088
1000	108.314
1005.79	87.2289
1011.58	89.1536
1017.36	90.1933
1023.13	91.2777
1028.9	89.5808
1034.67	78.297
1040.43	71.7945
1046.19	67.1861
1051.94	69.2872
1057.69	67.4678
1063.44	65.5784
1069.17	54.8718
1074.91	60.6746
1080.64	63.5316
1086.37	74.1308
1092.09	77.9618
1097.8	86.6226
1103.52	105.928
1109.22	91.464
1114.93	79.0523
1120.63	73.465
1126.32	67.7771
1132.01	65.9929
1137.7	73.017
1143.38	74.1736
1149.06	80.1884
1154.73	101.909
1160.4	94.9675
1166.06	64.3386
1171.72	60.2965
1177.38	49.4094
1183.03	58.1228
1188.67	51.2711
1194.31	52.2823
1199.95	46.4983
1205.58	51.5564
1211.21	46.8206
1216.84	49.0019
1222.46	45.2567
1228.07	39.4771
1233.68	41.6505
1239.29	43.8056
1244.89	51.9704
1250.49	44.949
1256.08	41.9261
1261.67	48.945
1267.26	43.8404
1272.84	44.7671
1278.42	50.6918
1283.99	92.6596
1289.56	47.511
1295.12	42.4766
1300.68	39.474
1306.23	46.5147
1311.78	45.6237
1317.33	45.7687
1322.87	42.9034
1328.41	46.1158
1333.94	44.259
1339.47	44.4077
1345	44.5134
1350.52	42.5486
1356.04	48.7734
1361.55	39.5654
1367.06	44.7059
1372.56	50.8539
1378.06	46.7277
1383.56	74.4222
1389.05	73.3606
1394.53	48.7438
1400.02	45.7337
1405.5	49.9169
1410.97	48.975
1416.44	40.8143
1421.91	44.0159
1427.37	49.3193
1432.83	41.1197
1438.28	48.5289
1443.73	49.6957
1449.17	44.5574
1454.62	46.7078
1460.05	44.6281
1465.48	45.6742
1470.91	44.6112
1476.34	43.5594
1481.76	43.5774
1487.17	47.8131
1492.59	45.7692
1497.99	47.9582
1503.4	50.1721
1508.8	47.1214
1514.19	45.133
1519.59	43.1493
1524.97	45.437
1530.36	45.5957
1535.74	46.8427
1541.11	49.1338
1546.48	40.5585
1551.85	50.2955
1557.21	45.9115
1562.57	43.707
1567.93	47.9745
1573.28	49.001
1578.62	47.9014
1583.97	44.6767
1589.3	49.0031
1594.64	49.0456
1599.97	53.429
1605.3	51.3655
1610.62	47.1634
1615.94	47.3264
1621.25	49.6935
1626.56	47.6896
1631.87	43.4637
1637.17	45.7969
1642.47	50.2751
1647.76	52.5652
1653.05	51.5174
1658.34	49.3327
1663.62	53.7837
1668.9	54.8975
1674.18	50.4622
1679.45	50.4535
1684.71	50.4177
1689.98	50.3758
1695.23	50.3656
1700.49	50.4278
1705.74	42.8827
1710.99	52.979
1716.23	50.7683
1721.47	52.0319
1726.7	54.357
1731.94	47.7322
1737.16	48.9519
1742.39	50.173
1747.61	52.521
1752.82	52.5888
1758.03	49.2382
1763.24	50.3867
1768.44	51.544
1773.64	53.8439
1778.84	55.0358
1784.03	50.5752
1789.22	54.0917
1794.41	47.3654
1799.59	46.3419
1804.76	51.0599
1809.94	51.1825
1815.11	57.0553
1820.27	58.3338
1825.43	54.992
1830.59	53.9614
1835.74	50.6068
1840.89	56.5387
1846.04	54.3028
1851.18	55.5609
1856.32	47.433
1861.45	51.0389
1866.58	49.969
1871.71	52.4137
1876.83	48.9459
1881.95	49.0047
1887.07	57.3261
1892.18	49.0635
1897.29	53.8
1902.39	52.6725
1907.49	51.5885
1912.59	54.1121
1917.68	50.7086
1922.77	49.571
1927.86	56.8493
1932.94	50.9624
1938.02	47.4438
1943.09	53.5204
1948.16	52.3717
1953.23	48.7891
1958.29	52.4212
1963.35	58.4564
1968.41	56.0382
1973.46	52.3941
1978.51	55.9771
1983.55	52.3359
1988.59	53.5152
1993.63	55.9027
1998.66	55.8976
2003.69	59.5154
2008.72	51.1279
2013.74	54.7819
2018.76	57.2288
2023.77	54.8639
2028.78	56.1436
2033.79	56.2447
2038.79	57.5647
2043.79	54.0388
2048.79	56.592
2053.78	53.0345
2058.77	53.1442
2063.76	61.8341
2068.74	59.5176
2073.72	54.7248
2078.69	62.227
2083.66	62.3361
2088.63	59.9477
2093.59	60.0541
2098.55	57.7094
2103.51	57.8507
2108.46	58.0066
2113.41	69.4398
2118.36	68.4012
2123.3	61.0557
2128.24	59.969
2133.17	52.5312
2138.11	57.7295
2143.03	59.1274
2147.96	63.0597
2152.88	68.2507
2157.79	55.5535
2162.71	61.9844
2167.62	65.8398
2172.52	58.2018
2177.43	58.2427
2182.32	56.9706
2187.22	62.0831
2192.11	60.8247
2197	60.8686
2201.89	60.9468
2206.77	57.1939
2211.64	57.3123
2216.52	63.8992
2221.39	58.8848
2226.26	62.9273
2231.12	64.3882
2235.98	60.6394
2240.84	64.7133
2245.69	63.569
2250.54	58.4746
2255.39	61.2525
2260.23	64.0534
2265.07	66.8453
2269.9	61.6617
2274.74	63.0761
2279.57	56.4974
2284.39	57.859
2289.21	64.5265
2294.03	63.2103
2298.84	72.5653
2303.66	63.3075
2308.46	63.4101
2313.27	67.5549
2318.07	67.7217
2322.87	62.5134
2327.66	65.3784
2332.45	64.2152
2337.24	72.5509
2342.02	56.461
2346.8	59.3969
2351.58	60.9745
2356.35	70.7804
2361.12	59.9208
2365.89	60.0495
2370.65	67.0947
2375.41	57.526
2380.17	52.074
2384.92	59.087
2389.67	61.9168
2394.42	67.5063
2399.16	73.0731
2403.9	63.324
2408.64	60.5456
2413.37	67.6228
2418.1	59.5406
2422.83	68.1656
2427.55	68.2763
2432.27	62.8083
2436.99	64.4116
2441.7	67.4447
2446.41	59.1011
2451.11	73.5642
2455.82	70.9121
2460.51	75.4293
2465.21	69.8826
2469.9	65.7355
2474.59	63.0051
2479.28	67.529
2483.96	72.0604
2488.64	66.3759
2493.32	66.51
2497.99	72.5086
2502.66	71.1779
2507.32	62.4782
2511.99	59.6241
2516.65	64.1206
2521.3	81.9359
2525.96	73.1909
2530.61	70.3408
2535.25	70.4674
2539.89	70.6075
2544.53	70.7534
2549.17	70.9115
2553.8	75.5555
2558.43	60.7051
2563.06	59.3336
2567.68	74.5391
2572.3	70.2065
2576.92	70.3802
2581.53	69.0083
2586.14	69.1041
2590.75	69.1604
2595.35	78.372
2599.96	73.9244
2604.55	74.0188
2609.15	67.9916
2613.74	77.2174
2618.33	72.6931
2622.91	72.7575
2627.49	72.8392
2632.07	63.7554
2636.64	76.2393
2641.22	71.8444
2645.78	72.0802
2650.35	67.6383
2654.91	75.6171
2659.47	77.3127
2664.03	75.8603
2668.58	74.4003
2673.13	74.5558
2677.67	79.5545
2682.22	83.1165
2686.76	73.9526
2691.29	69.4703
2695.83	76.0558
2700.36	77.8205
2704.89	76.3694
2709.41	68.4557
2713.93	73.4179
2718.45	88.1328
2722.96	68.856
2727.47	77.0618
2731.98	75.5092
2736.49	77.1961
2740.99	87.0199
2745.49	80.6178
2749.98	74.2344
2754.47	79.365
2758.96	77.8765
2763.45	84.5624
2767.93	74.8616
2772.41	79.9465
2776.89	65.2728
2781.36	77.0759
2785.84	83.9888
2790.3	77.591
2794.77	77.8313
2799.23	74.6822
2803.69	84.9496
2808.14	76.6933
2812.59	71.7679
2817.04	78.6384
2821.49	85.5363
2825.93	80.5916
2830.37	79.0198
2834.81	77.4305
2839.24	86.0615
2843.67	77.656
2848.1	74.3755
2852.53	77.9585
2856.95	78.1538
2861.37	81.799
2865.78	75.1376
2870.19	80.5711
2874.6	86.0336
2879.01	81.0805
2883.41	79.6135
2887.81	86.9231
2892.21	81.9304
2896.6	89.2895
2901	84.2971
2905.38	93.4632
2909.77	83.026
2914.15	88.5863
2918.53	81.6136
2922.91	85.4135
2927.28	92.8665
2931.65	76.865
2936.02	89.7485
2940.38	82.6563
2944.74	88.2668
2949.1	77.4537
2953.46	84.8678
2957.81	83.1587
2962.16	75.9599
2966.5	87.0849
2970.85	83.5698
2975.19	91.0878
2979.52	89.415
2983.86	82.2212
2988.19	87.9877
2992.52	90.0908
2996.85	92.2127
3001.17	85.0291
3005.49	83.4421
3009.8	78.0762
3014.12	89.6438
3018.43	91.8592
3022.74	90.2831
3027.04	82.9235
3031.34	81.2222
3035.64	90.9657
3039.94	94.9815
3044.23	91.3226
3048.52	89.5558
3052.81	95.4944
3057.09	68.6122
3061.38	84.2224
3065.65	86.3104
3069.93	86.4612
3074.2	94.4014
3078.47	98.478
3082.74	96.7066
3087	93.009
3091.27	91.3
3095.52	101.436
3099.78	101.767
3104.03	104.103
3108.28	98.5228
3112.53	90.9206
3116.77	97.2936
3121.01	101.717
3125.25	96.0894
3129.49	94.5019
3133.72	94.967
3137.95	115.943
3142.18	102.029
3146.4	108.653
3150.62	102.829
3154.84	101.062
3159.06	105.539
3163.27	101.663
3167.48	116.65
3171.69	95.8944
3175.89	115.132
3180.09	121.676
3184.29	109.13
3188.49	102.877
3192.68	111.529
3196.87	109.621
3201.06	118.517
3205.24	118.94
3209.42	106.507
3213.6	119.911
3217.78	111.751
3221.95	125.269
3226.12	117.025
3230.29	119.678
3234.45	117.922
3238.61	111.712
3242.77	105.502
3246.93	110.408
3251.08	108.545
3255.23	113.314
3259.38	106.873
3263.53	102.725
3267.67	112.327
3271.81	108.228
3275.95	117.647
3280.08	111.023
3284.21	118.131
3288.34	106.874
3292.47	107.073
3296.59	109.566
3300.71	112.101
3304.83	98.4237
3308.95	107.896
3313.06	110.405
3317.17	112.937
3321.27	108.506
3325.38	106.434
3329.48	116.1
3333.58	114.157
3337.67	119.284
3341.77	107.751
3345.86	115.092
3349.95	112.909
3354.03	117.867
3358.11	106.198
3362.19	120.792
3366.27	121.048
3370.34	118.905
3374.42	109.498
3378.48	124.121
3382.55	109.81
3386.61	124.447
3390.68	112.489
3394.73	119.886
3398.79	122.49
3402.84	117.776
3406.89	117.888
3410.94	132.584
3414.98	108.341
3419.03	120.611
3423.06	123.132
3427.1	123.235
3431.14	116.049
3435.17	113.767
3439.2	118.863
3443.22	123.997
3447.25	126.757
3451.27	124.607
3455.28	115.068
3459.3	112.975
3463.31	128.322
3467.32	118.775
3471.33	116.664
3475.34	104.395
3479.34	117.329
3483.34	122.737
3487.33	115.471
3491.33	118.332
3495.32	110.975
3499.31	116.332
3503.3	116.545
3507.28	114.157
3511.26	106.549
3515.24	114.325
3519.22	101.538
3523.19	114.456
3527.16	119.693
3531.13	104.323
3535.1	107.084
3539.06	107.334
3543.02	97.1841
3546.98	102.538
3550.93	97.469
3554.89	102.706
3558.84	102.815
3562.78	115.988
3566.73	113.579
3570.67	105.98
3574.61	108.83
3578.55	109.107
3582.48	104.15
3586.41	99.1719
3590.35	91.5051
3594.27	105.071
3598.2	121.376
3602.12	113.662
3606.04	103.213
3609.95	87.312
3613.87	109.034
3617.78	98.4532
3621.69	93.1935
3625.6	98.6665
3629.5	93.3166
3633.4	87.9373
3637.3	104.252
3641.2	98.9823
3645.09	88.3068
3648.98	99.3205
3652.87	99.4263
3656.76	80.4327
3660.64	88.6884
3664.53	99.6794
3668.4	88.8488
3672.28	91.6709
3676.16	89.0664
3680.03	83.7467
3683.9	78.4417
3687.76	86.9396
3691.63	95.491
3695.49	87.4065
3699.35	87.6429
3703.2	90.6585
3707.06	85.3167
3710.91	85.5523
3714.76	94.2104
3718.6	91.5993
3722.45	88.9581
3726.29	91.9439
3730.13	80.7685
3733.97	86.603
3737.8	95.3002
3741.63	95.4616
3745.46	92.7583
3749.29	87.1683
3753.11	84.3989
3756.93	81.5999
3760.75	78.7785
3764.57	93.1435
3768.39	87.46
3772.2	87.5336
3776.01	90.4818
3779.81	84.8305
3783.62	82.075
3787.42	90.8533
3791.22	79.4235
3795.02	88.2379
3798.81	88.4138
3802.61	91.5045
3806.4	88.8012
3810.18	89.0029
3813.97	92.1095
3817.75	77.6431
3821.53	83.66
3825.31	92.6158
3829.09	86.879
3832.86	87.0447
3836.63	81.2876
3840.4	90.2983
3844.17	90.473
3847.93	87.5797
3851.69	78.7284
3855.45	84.7094
3859.21	84.7152
3862.96	93.6644
3866.71	84.8889
3870.46	88.0744
3874.21	85.1344
3877.95	94.1546
3881.69	88.2348
3885.44	76.3339
3889.17	67.4208
3892.91	79.5084
3896.64	85.6652
3900.37	79.7771
3904.1	73.8644
3907.82	83.025
3911.55	83.1571
3915.27	89.361
3918.99	83.4775
3922.7	83.6826
3926.42	89.973
3930.13	93.2165
3933.84	84.1875
3937.54	93.505
3941.25	90.5977
3944.95	87.7063
3948.65	81.7033
3952.35	78.7387
3956.04	81.9345
3959.73	88.2041
3963.42	82.0781
3967.11	79.0215
3970.8	103.836
3974.48	91.4705
3978.16	75.9875
3981.84	88.3892
3985.52	91.4852
3989.19	79.0767
3992.86	82.2055
3996.53	72.9509
3998.37	85.4095