File: Data/3-Raman/raw/bu19w-e-ff11-fi10-l_150 (500nm)_633nm_edge_100%_x100_vis_h50um_60sx2_01.txt
#Acq. time (s)=	60
#Accumulations=	2
#Range (cm-¹)=	100...4000
#Windows=	1
#Auto scanning=	Off
#Autofocus=	Off
#Macrospot=	Off
#AutoExposure=	Off
#Spike filter=	Multiple accum.
#Delay time (s)=	2
#Binning=	1
#Readout mode=	Signal
#DeNoise=	Off
#ICS correction=	On
#Dark correction=	Off
#Inst. Process=	Off
#Detector Gain=	Best Dynamic
#Detector ADC=	50 kHz HS
#Detector temperature (°C)=	-60.09
#Instrument=	LabRAM HR Evol
#Detector=	SIN-EM FIVIS
#Objective=	x100_VIS
#Grating=	150 (500nm)
#ND Filter=	100%
#Laser=	633nm_Edge
#Hole=	49.98
#Temperature=	0
#Range=	Visible
#StageXY=	75x50mm Scan+
#StageZ=	Z motor
#X (µm)=	0
#Y (µm)=	0
#Z (µm)=	-266.5
#Full time(mm:ss)=	2:04
#Project=	21_11_04
#Sample=	BU19w
#Site=
#Title=	BU19w-E-FF11-FI10-L_150 (500nm)_633nm_Edge_100%_x100_VIS_H50um_60sX2
#Remark=
#Date=	04.11.2021 12:03
#Acquired=	04.11.2021 12:03:28
102.881	712.668
109.397	673.269
115.908	627.12
122.414	583.595
128.914	573.448
135.409	543.033
141.898	559.314
148.383	529.762
154.861	512.754
161.335	538.912
167.801	564.114
174.264	478.857
180.721	421.143
187.173	392.901
193.62	359.778
200.061	348.846
206.496	335.432
212.926	323.844
219.352	321.812
225.772	322.54
232.185	389.643
238.595	503.321
244.999	403.283
251.397	324.277
257.791	304.146
264.178	304.023
270.561	317.238
276.939	306.798
283.31	332.319
289.678	318.869
296.039	275.043
302.396	258.725
308.746	260.363
315.093	293.188
321.433	397.752
327.768	591.966
334.099	502.264
340.423	355.04
346.743	296.463
353.058	293.47
359.367	313.918
365.671	321.119
371.971	278.525
378.265	236.938
384.553	224.563
390.837	231.249
397.116	231.581
403.389	232.114
409.657	225.052
415.92	235.783
422.178	258.774
428.431	269.873
434.678	300.374
440.921	297.762
447.158	297.901
453.391	287.677
459.618	298.206
465.84	293.167
472.057	239.857
478.27	233.369
484.477	222.216
490.679	232.495
496.876	237.209
503.068	231.71
509.255	245.825
515.436	252.555
521.613	266.934
527.785	265.581
533.952	278.482
540.113	260.359
546.27	244.781
552.423	232.695
558.568	227.094
564.711	212.643
570.848	217.802
576.979	196.486
583.107	208.988
589.228	204.771
595.345	226.885
601.458	238.122
607.565	244.079
613.667	257.673
619.764	251.852
625.856	242.35
631.944	229.619
638.026	212.676
644.104	210.481
650.177	203.569
656.244	230.26
662.308	203.446
668.365	187.079
674.418	176.713
680.467	174.85
686.511	166.601
692.549	151.967
698.582	156.059
704.611	152.62
710.635	152.827
716.655	147.081
722.669	157.33
728.679	158.987
734.683	147.467
740.683	152.812
746.678	147.918
752.669	135.665
758.654	157.101
764.635	142.461
770.611	136.308
776.582	140.447
782.549	130.369
788.511	141.843
794.466	137.227
800.419	140.979
806.366	145.557
812.309	141.591
818.247	141.294
824.18	138.145
830.108	137.838
836.033	135.003
841.952	136.139
847.865	133.57
853.776	146.09
859.681	137.056
865.58	146.88
871.476	166.188
877.366	169.253
883.253	170.325
889.134	172.221
895.012	181.603
900.883	169.923
906.751	162.899
912.614	166.235
918.473	150.853
924.326	156.386
930.174	177.183
936.019	180.318
941.859	190.396
947.693	212.949
953.525	240.443
959.35	260.334
965.171	248.517
970.988	278.705
976.801	320.155
982.608	406.158
988.411	491.704
994.209	462.14
1000	377.428
1005.79	314.119
1011.58	313.23
1017.36	317.347
1023.13	338.827
1028.9	331.976
1034.67	299.258
1040.43	246.222
1046.19	227.659
1051.94	215.614
1057.69	209.199
1063.44	188.963
1069.17	194.722
1074.91	181.053
1080.64	195.445
1086.37	228.207
1092.09	260.034
1097.8	306.325
1103.52	352.608
1109.22	284.071
1114.93	238.127
1120.63	222.341
1126.32	221.86
1132.01	199.934
1137.7	225.912
1143.38	260.836
1149.06	284.841
1154.73	357.914
1160.4	311.474
1166.06	228.378
1171.72	175.987
1177.38	169.753
1183.03	150.924
1188.67	140.141
1194.31	149.029
1199.95	134.6
1205.58	128.155
1211.21	116.805
1216.84	129.187
1222.46	121.845
1228.07	125.427
1233.68	122.944
1239.29	118.325
1244.89	112.518
1250.49	113.635
1256.08	120.727
1261.67	116.56
1267.26	117.412
1272.84	127.259
1278.42	125.977
1283.99	117.703
1289.56	116.527
1295.12	118.435
1300.68	121.42
1306.23	126.54
1311.78	113.809
1317.33	124.229
1322.87	120.634
1328.41	109.968
1333.94	120.568
1339.47	119.952
1345	113.074
1350.52	115.342
1356.04	120.65
1361.55	120.752
1367.06	125.896
1372.56	134.069
1378.06	155.588
1383.56	136.013
1389.05	123.636
1394.53	114.42
1400.02	117.674
1405.5	103.436
1410.97	119.086
1416.44	118.31
1421.91	120.655
1427.37	107.464
1432.83	121.277
1438.28	111.147
1443.73	116.654
1449.17	109.559
1454.62	112.834
1460.05	120.233
1465.48	118.123
1470.91	109.691
1476.34	115.983
1481.76	118.131
1487.17	107.711
1492.59	115.212
1497.99	117.524
1503.4	107.21
1508.8	117.009
1514.19	118.408
1519.59	107.074
1524.97	115.998
1530.36	111.039
1535.74	120.068
1541.11	120.405
1546.48	122.757
1551.85	118.438
1557.21	120.45
1562.57	119.25
1567.93	116.971
1573.28	125.464
1578.62	124.328
1583.97	117.882
1589.3	122.239
1594.64	123.422
1599.97	119.271
1605.3	125.981
1610.62	125.227
1615.94	136.54
1621.25	133.79
1626.56	146.358
1631.87	138.094
1637.17	137.391
1642.47	143.091
1647.76	148.843
1653.05	135.718
1658.34	144.672
1663.62	146.935
1668.9	138.075
1674.18	134.751
1679.45	136.945
1684.71	125.767
1689.98	117.913
1695.23	127.851
1700.49	140.2
1705.74	126.42
1710.99	124.361
1716.23	121.063
1721.47	128.122
1726.7	128.327
1731.94	139.827
1737.16	128.85
1742.39	132.479
1747.61	119.16
1752.82	122.707
1758.03	116.021
1763.24	117.192
1768.44	116.116
1773.64	135.46
1778.84	124.256
1784.03	125.586
1789.22	129.251
1794.41	134.107
1799.59	125.295
1804.76	122.2
1809.94	123.643
1815.11	123.908
1820.27	128.796
1825.43	134.875
1830.59	127.071
1835.74	119.246
1840.89	132.312
1846.04	131.378
1851.18	132.761
1856.32	127.074
1861.45	127.304
1866.58	129.919
1871.71	138.396
1876.83	125.608
1881.95	124.578
1887.07	135.337
1892.18	133.003
1897.29	130.657
1902.39	124.875
1907.49	129.861
1912.59	134.983
1917.68	135.422
1922.77	130.796
1927.86	128.659
1932.94	132.502
1938.02	129.119
1943.09	140.115
1948.16	127.016
1953.23	134.321
1958.29	133.162
1963.35	135.595
1968.41	140.397
1973.46	139.115
1978.51	136.632
1983.55	136.555
1988.59	134.089
1993.63	135.249
1998.66	141.247
2003.69	138.869
2008.72	129.324
2013.74	136.654
2018.76	141.566
2023.77	135.652
2028.78	140.661
2033.79	132.447
2038.79	130.278
2043.79	141.472
2048.79	123.529
2053.78	145.692
2058.77	128.89
2063.76	143.871
2068.74	147.874
2073.72	145.728
2078.69	146.018
2083.66	151.211
2088.63	137.818
2093.59	151.683
2098.55	150.789
2103.51	130.009
2108.46	157.803
2113.41	149.515
2118.36	148.726
2123.3	156.731
2128.24	154.657
2133.17	143.67
2138.11	156.694
2143.03	141.779
2147.96	142.044
2152.88	144.793
2157.79	152.613
2162.71	146.334
2167.62	147.66
2172.52	164.372
2177.43	152.967
2182.32	149.148
2187.22	149.128
2192.11	149.181
2197	148.007
2201.89	148.197
2206.77	162.585
2211.64	153.906
2216.52	142.644
2221.39	146.888
2226.26	147.263
2231.12	161.946
2235.98	144.1
2240.84	137.924
2245.69	154.007
2250.54	147.829
2255.39	137.653
2260.23	157.822
2265.07	137
2269.9	155.812
2274.74	145.407
2279.57	152.211
2284.39	156.286
2289.21	148.344
2294.03	148.378
2298.84	159.111
2303.66	160.601
2308.46	154.187
2313.27	153.169
2318.07	137.455
2322.87	170.063
2327.66	157.043
2332.45	154.792
2337.24	162.053
2342.02	150.336
2346.8	153.613
2351.58	152.779
2356.35	146.371
2361.12	156.345
2365.89	152.539
2370.65	157.016
2375.41	165.647
2380.17	165.942
2384.92	159.187
2389.67	155.14
2394.42	155.195
2399.16	155.193
2403.9	149.612
2408.64	141.273
2413.37	162.434
2418.1	164.612
2422.83	167.954
2427.55	159.781
2432.27	148.905
2436.99	156.428
2441.7	148.378
2446.41	164.486
2451.11	163.555
2455.82	156.866
2460.51	147.267
2465.21	166.421
2469.9	159.643
2474.59	162.944
2479.28	157.568
2483.96	165.229
2488.64	174.328
2493.32	170.295
2497.99	167.722
2502.66	172.441
2507.32	163.913
2511.99	159.734
2516.65	173.199
2521.3	173.468
2525.96	160.429
2530.61	166.597
2535.25	172.831
2539.89	170.201
2544.53	169.063
2549.17	175.413
2553.8	175.798
2558.43	171.623
2563.06	165.984
2567.68	175.431
2572.3	172.874
2576.92	165.734
2581.53	176.692
2586.14	170.862
2590.75	160.361
2595.35	171.201
2599.96	168.426
2604.55	165.588
2609.15	171.889
2613.74	167.432
2618.33	169.107
2622.91	172.32
2627.49	181.715
2632.07	177.44
2636.64	190.213
2641.22	173.817
2645.78	166.637
2650.35	173.372
2654.91	172.282
2659.47	171.025
2664.03	185.349
2668.58	184.043
2673.13	167.162
2677.67	181.951
2682.22	184.439
2686.76	186.87
2691.29	182.859
2695.83	178.531
2700.36	191.743
2704.89	164.797
2709.41	195.703
2713.93	178.301
2718.45	186.777
2722.96	170.925
2727.47	190.626
2731.98	179.436
2736.49	177.957
2740.99	182.986
2745.49	183.222
2749.98	178.652
2754.47	184.094
2758.96	181.165
2763.45	178.156
2767.93	198.26
2772.41	180.498
2776.89	187.556
2781.36	186.474
2785.84	187.104
2790.3	182.714
2794.77	176.585
2799.23	173.699
2803.69	184.198
2808.14	181.198
2812.59	186.597
2817.04	186.872
2821.49	200.714
2825.93	180.695
2830.37	204.772
2834.81	171.028
2839.24	188.313
2843.67	190.3
2848.1	178.672
2852.53	173.908
2856.95	196.673
2861.37	183.402
2865.78	185.685
2870.19	203.594
2874.6	193.793
2879.01	190.931
2883.41	189.847
2887.81	187.016
2892.21	184.123
2896.6	182.999
2901	169.482
2905.38	193.157
2909.77	188.371
2914.15	197.753
2918.53	198.204
2922.91	184.313
2927.28	190.241
2931.65	188.998
2936.02	196.722
2940.38	200.737
2944.74	204.743
2949.1	206.847
2953.46	199.85
2957.81	178.197
2962.16	200.424
2966.5	202.587
2970.85	195.608
2975.19	203.337
2979.52	220.311
2983.86	211.558
2988.19	210.244
2992.52	210.831
2996.85	220.752
3001.17	213.974
3005.49	216.574
3009.8	217.296
3014.12	225.525
3018.43	203.605
3022.74	210.027
3027.04	214.457
3031.34	234.111
3035.64	226.935
3039.94	223.542
3044.23	222.058
3048.52	232.075
3052.81	238.254
3057.09	258.02
3061.38	237.178
3065.65	227.898
3069.93	245.783
3074.2	234.544
3078.47	233.032
3082.74	251.046
3087	277.069
3091.27	256.229
3095.52	257.038
3099.78	269.732
3104.03	276.618
3108.28	271.684
3112.53	286.75
3116.77	299.905
3121.01	282.995
3125.25	300.406
3129.49	295.699
3133.72	284.901
3137.95	288.318
3142.18	306.087
3146.4	317.68
3150.62	323.029
3154.84	332.36
3159.06	324.978
3163.27	338.526
3167.48	364.663
3171.69	348.803
3175.89	341.17
3180.09	341.751
3184.29	367.65
3188.49	374.388
3192.68	364.33
3196.87	369.306
3201.06	383.311
3205.24	380.395
3209.42	371.161
3213.6	374.856
3217.78	363.462
3221.95	382.344
3226.12	401.384
3230.29	385.386
3234.45	389.034
3238.61	397.075
3242.77	407.573
3246.93	402.6
3251.08	372.634
3255.23	382.576
3259.38	397.118
3263.53	416.543
3267.67	425.481
3271.81	402.154
3275.95	394.061
3280.08	426.924
3284.21	397.975
3288.34	410.259
3292.47	390.299
3296.59	423.269
3300.71	391.774
3304.83	399.484
3308.95	423.461
3313.06	454.404
3317.17	406.342
3321.27	418.858
3325.38	424.566
3329.48	409.282
3333.58	446.036
3337.67	447.612
3341.77	446.395
3345.86	468.672
3349.95	459.956
3354.03	429.798
3358.11	457.01
3362.19	470.011
3366.27	473.404
3370.34	484.029
3374.42	480.105
3378.48	507.33
3382.55	498.369
3386.61	506.245
3390.68	492.292
3394.73	502.552
3398.79	534.832
3402.84	511.172
3406.89	540.828
3410.94	533.984
3414.98	517.358
3419.03	532.394
3423.06	576.647
3427.1	552.727
3431.14	580.243
3435.17	537.027
3439.2	586.961
3443.22	538.956
3447.25	532.873
3451.27	519.4
3455.28	535.745
3459.3	530.111
3463.31	554.402
3467.32	528.86
3471.33	555.72
3475.34	532.036
3479.34	546.273
3483.34	502.335
3487.33	518.986
3491.33	497.502
3495.32	526.811
3499.31	502.4
3503.3	480.266
3507.28	460.475
3511.26	504.502
3515.24	453.444
3519.22	440.855
3523.19	407.671
3527.16	438.876
3531.13	405.7
3535.1	421.883
3539.06	412.525
3543.02	408.173
3546.98	403.661
3550.93	398.973
3554.89	378.324
3558.84	386.531
3562.78	397.487
3566.73	372.071
3570.67	372.894
3574.61	357.958
3578.55	348.353
3582.48	325.633
3586.41	347.763
3590.35	348.78
3594.27	323.192
3598.2	313.444
3602.12	311.567
3606.04	320.362
3609.95	299.547
3613.87	286.718
3617.78	287.267
3621.69	266.074
3625.6	274.374
3629.5	271.835
3633.4	277.341
3637.3	274.846
3641.2	258.981
3645.09	243.183
3648.98	251.703
3652.87	238.351
3656.76	244.025
3660.64	249.692
3664.53	228.034
3668.4	225.539
3672.28	225.757
3676.16	206.908
3680.03	207.307
3683.9	227.068
3687.76	213.899
3691.63	200.669
3695.49	201.174
3699.35	221.194
3703.2	205.028
3707.06	200.005
3710.91	197.752
3714.76	198.264
3718.6	173.334
3722.45	196.273
3726.29	202.277
3730.13	194.128
3733.97	197.341
3737.8	180.644
3741.63	178.1
3745.46	198.36
3749.29	184.34
3753.11	181.672
3756.93	187.537
3760.75	184.772
3764.57	190.586
3768.39	179.221
3772.2	210.942
3776.01	176.655
3779.81	202.73
3783.62	185.749
3787.42	191.801
3791.22	189.172
3795.02	169.243
3798.81	172.479
3802.61	181.557
3806.4	193.616
3810.18	196.974
3813.97	179.833
3817.75	162.611
3821.53	177.594
3825.31	174.941
3829.09	184.066
3832.86	181.466
3836.63	184.744
3840.4	187.998
3844.17	164.631
3847.93	176.644
3851.69	191.622
3855.45	197.655
3859.21	197.669
3862.96	197.736
3866.71	186.16
3870.46	183.613
3874.21	171.762
3877.95	156.924
3881.69	168.992
3885.44	181.106
3889.17	181.287
3892.91	172.518
3896.64	157.804
3900.37	176.112
3904.1	173.355
3907.82	161.521
3911.55	161.778
3915.27	180.236
3918.99	189.722
3922.7	178.016
3926.42	160.122
3930.13	181.849
3933.84	176.028
3937.54	170.148
3941.25	195.015
3944.95	198.493
3948.65	171.114
3952.35	168.285
3956.04	177.782
3959.73	174.861
3963.42	168.802
3967.11	168.889
3970.8	178.227
3974.48	178.29
3978.16	172.135
3981.84	175.228
3985.52	172.116
3989.19	175.209
3992.86	156.656
3996.53	166.08
3998.37	166.16