File: Data/3-Raman/raw/bu19w-d-ff2-fi08-v_1800 (450-850nm)_532nm_edge_100%_x100_vis_lwd_h50um_30sx2_01.txt
#Acq. time (s)=	30
#Accumulations=	2
#Range (cm-¹)=	1200...2365
#Windows=	3
#Auto scanning=	Off
#Autofocus=	Off
#Macrospot=	Off
#AutoExposure=	Off
#Spike filter=	Multiple accum.
#Delay time (s)=	2
#Binning=	1
#Readout mode=	Signal
#DeNoise=	Off
#ICS correction=	On
#Dark correction=	Off
#Inst. Process=	Off
#Detector Gain=	Best Dynamic
#Detector ADC=	50 kHz HS
#Detector temperature (°C)=	-60.09
#Instrument=	LabRAM HR Evol
#Detector=	SIN-EM FIVIS
#Objective=	x100_VIS_LWD
#Grating=	1800 (450-850nm)
#ND Filter=	100%
#Laser=	532nm_Edge
#Hole=	49.98
#Temperature=	0
#Range=	Visible
#StageXY=	75x50mm Scan+
#StageZ=	Z motor
#X (µm)=	0
#Y (µm)=	0
#Z (µm)=	12.2
#Full time(mm:ss)=	3:18
#Project=	21_11_22
#Sample=	BU19w
#Site=
#Title=	BU19w-D-FF2-FI08-V_1800 (450-850nm)_532nm_Edge_100%_x100_VIS_LWD_H50um_30sX2
#Remark=
#Date=	22.11.2021 13:45
#Acquired=	22.11.2021 13:45:11
1202.84	31.6723
1203.95	27.3254
1205.06	28.3655
1206.17	28.3362
1207.29	27.2538
1208.39	27.2127
1209.51	27.1749
1210.62	29.2786
1211.72	25.0156
1212.84	27.1404
1213.94	24.9752
1215.05	29.1937
1216.16	21.7468
1217.27	28.1004
1218.38	23.8501
1219.49	24.8784
1220.6	24.8313
1221.71	24.8022
1222.81	22.6907
1223.92	22.6868
1225.03	30.0098
1226.14	26.7839
1227.24	28.966
1228.35	29.9351
1229.46	33.0839
1230.56	39.379
1231.67	44.6472
1232.78	49.9245
1233.88	44.6593
1234.99	44.6033
1236.09	43.5006
1237.2	37.1954
1238.3	28.8125
1239.41	30.8968
1240.51	34.0518
1241.62	27.7616
1242.72	30.879
1243.83	29.813
1244.93	33.9925
1246.03	25.6049
1247.14	29.7878
1248.24	31.8517
1249.34	34.9611
1250.45	37.0232
1251.55	38.0863
1252.65	38.0932
1253.75	29.7448
1254.86	31.8265
1255.96	29.7223
1257.06	29.742
1258.16	27.6217
1259.26	23.4933
1260.36	26.56
1261.46	25.6046
1262.56	30.8032
1263.66	32.8917
1264.76	28.7386
1265.86	21.4446
1266.96	23.5405
1268.06	21.4248
1269.16	21.4255
1270.26	20.4026
1271.36	19.3732
1272.46	23.5712
1273.56	25.6882
1274.66	21.5061
1275.76	20.4738
1276.85	23.6337
1277.95	23.6326
1279.05	24.7013
1280.15	22.5885
1281.24	30.9688
1282.34	54.2068
1283.44	159.511
1284.53	108.916
1285.63	31.0077
1286.73	26.8129
1287.82	21.5542
1288.92	21.5512
1290.01	19.4432
1291.11	20.5197
1292.21	21.579
1293.3	21.6241
1294.4	19.5082
1295.49	18.4396
1296.58	19.4857
1297.68	17.379
1298.77	20.5487
1299.87	21.6105
1300.96	19.4899
1302.05	15.2644
1303.15	18.4157
1304.24	14.1923
1305.33	23.6861
1306.42	18.4168
1307.52	19.4748
1308.61	17.3663
1309.7	16.3182
1310.79	21.5908
1311.88	17.3691
1312.98	17.3775
1314.07	17.3744
1315.16	19.4919
1316.25	14.2104
1317.34	15.2664
1318.43	15.2558
1319.52	18.4056
1320.61	19.4525
1321.7	18.3989
1322.79	19.4409
1323.88	20.4589
1324.97	18.3853
1326.06	15.2428
1327.15	14.1851
1328.23	18.3893
1329.32	18.3623
1330.41	17.2864
1331.5	18.3164
1332.59	18.3005
1333.67	17.2401
1334.76	19.3288
1335.85	19.3133
1336.94	18.2644
1338.02	19.3128
1339.11	19.3052
1340.2	11.9659
1341.28	22.4226
1342.37	21.3667
1343.45	18.2051
1344.54	18.1823
1345.63	18.1729
1346.71	17.1182
1347.8	13.9825
1348.88	16.051
1349.96	16.0601
1351.05	18.1617
1352.13	18.117
1353.22	16.0365
1354.3	20.1818
1355.39	16.0172
1356.47	18.0796
1357.55	18.0621
1358.63	18.0554
1359.72	18.0482
1360.8	17.0176
1361.88	18.0522
1362.97	15.9667
1364.05	16.9828
1365.13	15.9472
1366.21	16.9849
1367.29	19.0474
1368.37	21.0967
1369.45	25.1909
1370.54	17.9585
1371.62	18.9824
1372.7	16.9207
1373.78	15.8832
1374.86	19.9933
1375.94	22.0878
1377.02	21.0461
1378.09	18.9443
1379.18	17.8978
1380.25	21.9748
1381.33	22.9863
1382.41	24.0331
1383.49	21.9987
1384.57	29.1157
1385.65	49.6142
1386.72	226.352
1387.8	163.47
1388.88	41.4097
1389.96	21.925
1391.03	22.9395
1392.11	17.8207
1393.19	17.8262
1394.26	18.8399
1395.34	15.7663
1396.42	15.7723
1397.49	17.8246
1398.57	18.8566
1399.64	15.8071
1400.72	18.9022
1401.79	16.8367
1402.87	16.8255
1403.94	17.8448
1405.02	17.8495
1406.09	18.8798
1407.17	22.9875
1408.24	31.1626
1409.31	29.1063
1410.39	24.0496
1411.46	17.8618
1412.53	18.8972
1413.61	15.8216
1414.68	16.8561
1415.75	17.8865
1416.82	14.7997
1417.9	17.8675
1418.97	16.8407
1420.04	13.7883
1421.11	16.8214
1422.18	18.8692
1423.26	14.7732
1424.33	9.63423
1425.4	14.7438
1426.47	15.7717
1427.54	14.7599
1428.61	15.8047
1429.68	14.7701
1430.75	16.7968
1431.82	15.777
1432.89	15.7767
1433.96	15.7715
1435.02	14.7429
1436.09	14.7475
1437.16	13.7325
1438.23	16.8126
1439.3	18.8611
1440.37	13.7332
1441.43	11.6793
1442.5	15.7923
1443.57	14.7611
1444.64	12.7047
1445.7	17.8361
1446.77	14.7569
1447.84	15.7743
1448.9	15.7684
1449.97	14.7426
1451.04	12.6952
1452.1	15.768
1453.17	13.7214
1454.23	14.7401
1455.3	14.7372
1456.36	16.7885
1457.43	13.7125
1458.49	15.7542
1459.56	14.7197
1460.62	12.6614
1461.69	12.6746
1462.75	15.6997
1463.81	14.6739
1464.88	14.6708
1465.94	15.6884
1467	14.6587
1468.07	15.6695
1469.13	14.6424
1470.19	14.6396
1471.25	15.6497
1472.32	11.5807
1473.38	16.6637
1474.44	13.6041
1475.5	13.5988
1476.56	13.5895
1477.62	13.5747
1478.68	15.5981
1479.75	17.6392
1480.81	14.5959
1481.87	16.5933
1482.93	14.5602
1483.99	11.5223
1485.05	10.5034
1486.11	16.566
1487.17	17.5727
1488.22	15.5408
1489.28	14.5278
1490.34	14.5256
1491.4	14.5247
1492.46	11.4871
1493.52	12.485
1494.58	12.481
1495.63	12.4799
1496.69	17.5296
1497.75	12.483
1498.81	13.4868
1499.86	15.499
1500.92	14.4823
1501.98	11.4583
1503.03	12.4551
1504.09	13.4634
1505.15	13.4631
1506.2	15.4782
1507.26	13.4647
1508.31	12.4453
1509.37	13.4258
1510.42	17.426
1511.48	13.4184
1512.53	15.4139
1513.59	11.3882
1514.64	14.3938
1515.7	13.3958
1516.75	12.3958
1517.8	16.4066
1518.86	15.4059
1519.91	13.393
1520.96	16.3831
1522.02	14.3726
1523.07	13.3763
1524.12	15.3879
1525.17	13.3777
1526.23	17.379
1527.28	16.3721
1528.33	14.3784
1529.38	15.3777
1530.43	13.3876
1531.48	14.3925
1532.53	16.391
1533.59	13.3641
1534.64	14.3494
1535.69	12.3411
1536.74	14.3608
1537.79	14.3841
1538.84	12.3707
1539.89	15.3615
1540.94	12.3434
1541.98	13.3512
1543.03	16.3686
1544.08	13.3662
1545.13	14.3603
1546.18	15.3528
1547.23	13.3544
1548.28	15.4015
1549.33	16.4054
1550.37	16.3933
1551.42	13.3731
1552.47	15.3642
1553.52	15.3624
1554.56	14.3625
1555.61	14.3507
1556.65	10.3343
1557.7	11.328
1558.75	12.3291
1559.79	15.3356
1560.84	16.332
1561.88	14.3434
1562.93	16.2447
1563.98	15.3142
1565.02	17.325
1566.07	15.3291
1567.11	15.3209
1568.15	14.3206
1569.2	10.318
1570.24	15.3027
1571.29	15.3005
1572.33	13.3165
1573.37	16.3158
1574.42	12.3037
1575.46	17.2739
1576.5	12.2876
1577.55	15.2824
1578.59	14.2783
1579.63	14.2698
1580.67	13.2705
1581.72	15.2628
1582.76	16.2576
1583.8	15.2495
1584.84	15.2432
1585.88	15.248
1586.92	15.2533
1587.96	14.2612
1589	14.2578
1590.04	11.2596
1591.08	13.2296
1592.12	17.2057
1593.16	15.2129
1594.2	13.2274
1595.24	13.2276
1596.28	15.2004
1597.32	13.2059
1598.36	14.1818
1599.4	13.1773
1600.44	13.1653
1601.48	14.1506
1602.51	15.1403
1603.55	16.136
1604.59	15.1493
1605.63	13.1687
1606.66	13.1564
1607.7	11.2585
1608.74	15.145
1609.77	16.8599
1610.81	16.5417
1611.85	14.3405
1612.88	14.9481
1613.92	14.9949
1614.95	14.5167
1615.99	15.22
1617.03	14.744
1618.06	14.4088
1619.1	15.5117
1620.13	14.7875
1621.17	15.4671
1622.2	15.692
1623.23	14.1289
1624.27	16.1218
1625.3	13.9907
1626.34	15.5768
1627.37	15.7272
1628.4	13.7725
1629.44	13.9876
1630.47	15.4683
1631.29	14.7181
1632.33	12.7449
1633.38	14.7087
1634.42	14.6981
1635.47	13.7071
1636.51	14.6889
1637.56	17.6404
1638.6	16.6578
1639.65	16.6516
1640.69	11.7262
1641.73	13.6864
1642.78	14.6725
1643.82	13.6816
1644.86	16.6248
1645.91	16.6305
1646.95	16.6351
1647.99	15.6615
1649.03	16.6501
1650.08	13.6891
1651.12	16.6454
1652.16	12.7057
1653.2	14.6913
1654.24	15.6794
1655.28	14.6853
1656.33	16.6478
1657.37	13.6823
1658.41	18.6222
1659.45	15.6591
1660.49	15.6855
1661.53	12.7052
1662.57	14.665
1663.61	13.7104
1664.65	15.6554
1665.69	15.6489
1666.72	15.664
1667.76	16.6601
1668.8	15.6686
1669.84	14.6807
1670.88	18.6359
1671.92	12.7082
1672.96	15.6802
1674	16.6697
1675.03	14.6832
1676.07	15.6594
1677.11	13.6746
1678.15	12.6798
1679.18	18.6045
1680.22	15.6381
1681.25	12.6707
1682.29	14.64
1683.33	14.6384
1684.36	13.654
1685.4	16.6089
1686.43	13.6355
1687.47	13.6264
1688.51	15.6036
1689.54	15.6034
1690.58	15.5876
1691.61	13.6017
1692.64	14.585
1693.68	12.6172
1694.71	14.5771
1695.75	13.5796
1696.78	14.5599
1697.81	13.5708
1698.85	13.5635
1699.88	12.569
1700.91	11.5814
1701.95	10.599
1702.98	13.5431
1704.01	14.5108
1705.04	13.5129
1706.08	12.514
1707.11	13.486
1708.14	15.4465
1709.17	13.489
1710.2	16.4036
1711.23	13.4506
1712.27	13.4451
1713.3	13.4466
1714.33	13.4303
1715.36	16.3277
1716.39	13.3953
1717.42	13.3936
1718.45	13.381
1719.48	13.3661
1720.51	12.3817
1721.54	15.2894
1722.56	15.2683
1723.59	12.3501
1724.62	13.3098
1725.65	15.2337
1726.68	13.2636
1727.71	13.2596
1728.74	12.3062
1729.76	12.3002
1730.79	13.2491
1731.82	13.2297
1732.85	14.1759
1733.87	16.0918
1734.9	15.1192
1735.93	9.33916
1736.95	13.1622
1737.98	16.0181
1739.01	14.0883
1740.03	12.1671
1741.06	10.2462
1742.08	15.0233
1743.11	14.0619
1744.13	14.0458
1745.16	13.0777
1746.18	12.1227
1747.21	13.0851
1748.23	13.091
1749.26	14.9892
1750.28	15.9285
1751.31	14.0071
1752.33	13.9967
1753.35	13.9836
1754.38	12.0628
1755.4	12.063
1756.42	14.9173
1757.44	16.8157
1758.47	13.0002
1759.49	13.9447
1760.51	14.8965
1761.53	13.9512
1762.56	13.9584
1763.58	13.9569
1764.6	13.9513
1765.62	13.9432
1766.64	13.917
1767.66	11.0696
1768.68	12.0273
1769.7	13.9345
1770.72	14.8909
1771.74	13.9411
1772.76	13.9522
1773.78	13.0004
1774.8	15.8486
1775.82	12.9785
1776.84	12.9691
1777.86	12.9733
1778.88	13.927
1779.9	14.8875
1780.92	12.9864
1781.94	15.8561
1782.95	12.9902
1783.97	14.9
1784.99	13.9663
1786.01	13.0315
1787.03	12.0839
1788.04	13.0429
1789.06	11.1123
1790.08	13.0292
1791.09	13.9885
1792.11	13.9923
1793.13	14.0118
1794.14	14.0209
1795.16	13.0656
1796.17	11.1413
1797.19	13.0537
1798.21	12.0863
1799.22	13.0463
1800.24	14.9753
1801.25	13.0573
1802.27	10.1781
1803.28	15.002
1804.29	15.0058
1805.31	12.113
1806.32	12.1127
1807.34	14.041
1808.35	13.0734
1809.36	14.0364
1810.38	12.1129
1811.39	12.1202
1812.4	14.0622
1813.41	11.1636
1814.43	14.0585
1815.44	15.0175
1816.45	13.0888
1817.46	15.9938
1818.47	15.9997
1819.49	14.0699
1820.5	13.1014
1821.51	13.0984
1822.52	14.07
1823.53	14.0693
1824.54	14.0706
1825.55	11.164
1826.56	13.0949
1827.57	13.0884
1828.58	13.0893
1829.59	13.0944
1830.6	16.9744
1831.61	11.1544
1832.62	13.0679
1833.63	13.1272
1834.64	13.0734
1835.65	14.9797
1836.65	14.0492
1837.66	13.059
1838.67	14.9627
1839.68	13.9769
1840.69	14.9417
1841.7	9.15209
1842.7	13.9737
1843.71	12.0623
1844.72	13.939
1845.72	12.0165
1846.73	13.9302
1847.74	14.8715
1848.74	10.0564
1849.75	12.9339
1850.75	12.9286
1851.76	12.9122
1852.76	13.8559
1853.77	12.8927
1854.78	12.8868
1855.78	15.7456
1856.79	10.9498
1857.79	11.9079
1858.79	13.8275
1859.8	11.9058
1860.8	12.8484
1861.81	11.882
1862.81	13.7739
1863.81	11.8442
1864.82	10.8739
1865.82	9.91854
1866.82	12.7672
1867.83	14.6635
1868.83	13.7075
1869.83	12.7476
1870.83	11.7908
1871.84	14.6238
1872.84	13.6562
1873.84	12.6894
1874.84	12.6579
1875.84	14.5805
1876.84	11.7509
1877.84	13.6412
1878.84	14.5667
1879.84	14.5315
1880.84	9.81604
1881.84	12.6277
1882.85	9.80989
1883.85	11.7011
1884.84	12.6296
1885.84	10.7269
1886.84	12.5993
1887.84	11.6627
1888.84	15.4261
1889.84	12.5945
1890.84	11.6313
1891.84	11.6243
1892.83	13.5042
1893.83	10.69
1894.83	10.6921
1895.83	12.566
1896.83	11.6149
1897.82	10.6712
1898.82	15.3775
1899.82	11.6218
1900.81	13.4958
1901.81	15.3718
1902.81	11.607
1903.8	12.5337
1904.8	12.531
1905.79	13.4747
1906.79	9.72226
1907.79	11.6162
1908.78	16.3293
1909.78	12.5572
1910.77	12.5587
1911.77	13.5132
1912.76	13.5188
1913.76	14.4548
1914.75	12.5587
1915.74	12.5625
1916.74	13.5228
1917.73	12.5795
1918.72	11.6428
1919.72	11.6417
1920.71	12.5795
1921.7	13.5154
1922.7	12.5746
1923.69	11.641
1924.68	13.542
1925.67	12.5984
1926.66	14.5017
1927.66	12.6178
1928.65	17.3647
1929.64	13.5577
1930.63	13.5539
1931.62	13.5872
1932.61	12.6666
1933.61	13.6091
1934.6	13.5958
1935.59	12.636
1936.58	14.5487
1937.57	13.6029
1938.56	11.7085
1939.55	16.4721
1940.54	11.7052
1941.52	11.7068
1942.51	13.6273
1943.5	14.5923
1944.49	11.7213
1945.48	12.6739
1946.47	14.5912
1947.46	16.5234
1948.44	12.7107
1949.43	11.7609
1950.42	10.8031
1951.41	12.6971
1952.39	10.7672
1953.38	13.6615
1954.37	13.6734
1955.36	12.7187
1956.34	12.714
1957.33	13.6665
1958.31	11.7353
1959.3	13.6517
1960.29	9.81241
1961.27	14.6143
1962.26	14.612
1963.24	10.7734
1964.23	13.6621
1965.21	11.7393
1966.2	13.6554
1967.18	12.6776
1968.17	12.6673
1969.15	11.7045
1970.14	10.7428
1971.12	11.6917
1972.1	13.6066
1973.09	13.612
1974.07	13.6123
1975.05	12.6456
1976.04	13.5967
1977.02	11.679
1978	15.5037
1978.98	11.6647
1979.97	12.6146
1980.95	12.6023
1981.93	11.6392
1982.91	13.543
1983.89	15.4596
1984.88	13.5375
1985.86	13.5075
1986.84	13.4779
1987.82	13.4825
1988.8	12.5462
1989.78	12.5792
1990.76	13.3385
1991.74	11.7232
1992.72	14.3857
1993.7	12.9287
1994.68	11.9036
1995.66	13.5206
1996.64	12.2864
1997.62	12.6281
1998.6	14.2453
1999.57	11.9032
2000.55	13.766
2001.53	13.3005
2002.51	13.2683
2003.49	12.7444
2004.47	13.6396
2005.44	12.9546
2006.42	12.2271
2007.4	12.7723
2008.38	12.3809
2009.35	12.7864
2010.33	11.0566
2011.3	12.7542
2012.18	13.1007
2013.17	13.1047
2014.16	12.1771
2015.15	12.1637
2016.14	13.0816
2017.13	12.1333
2018.11	11.1949
2019.1	12.1299
2020.09	12.1189
2021.08	13.0423
2022.06	10.2246
2023.05	13.0093
2024.04	12.0959
2025.02	13.0395
2026.01	14.0039
2027	12.0884
2027.98	12.0692
2028.97	12.0745
2029.96	13.9577
2030.94	13.9706
2031.93	13.9336
2032.91	16.7651
2033.9	13.025
2034.88	13.026
2035.87	12.0831
2036.85	11.1399
2037.83	13.9254
2038.82	12.0524
2039.8	13.9082
2040.79	13.9168
2041.77	12.0554
2042.75	12.0563
2043.74	12.0711
2044.72	12.0487
2045.7	13.9103
2046.69	15.7871
2047.67	13.0007
2048.65	12.9939
2049.63	12.0611
2050.62	12.0684
2051.6	13.0132
2052.58	13.0075
2053.56	13.0017
2054.54	14.8708
2055.52	13.0086
2056.5	12.0802
2057.48	11.1412
2058.46	12.0789
2059.45	13.9527
2060.43	13.0229
2061.4	11.1526
2062.39	15.8507
2063.37	13.0467
2064.34	12.111
2065.32	13.9962
2066.3	10.2368
2067.28	13.0451
2068.26	12.1218
2069.24	9.30966
2070.22	11.1898
2071.2	13.0728
2072.18	13.0832
2073.15	14.0462
2074.13	13.0986
2075.11	14.9744
2076.09	11.207
2077.06	14.9967
2078.04	12.1644
2079.02	12.1614
2080	14.0534
2080.97	12.1611
2081.95	13.1057
2082.93	12.1604
2083.9	12.1705
2084.88	10.2816
2085.85	15.0146
2086.83	15.0228
2087.8	13.1319
2088.78	13.1383
2089.75	13.1539
2090.73	13.1665
2091.7	12.221
2092.68	15.0655
2093.65	12.2089
2094.63	14.1
2095.6	12.1959
2096.57	14.0914
2097.55	14.0914
2098.52	11.2505
2099.5	12.1999
2100.47	13.1417
2101.44	14.09
2102.41	11.2478
2103.39	14.1056
2104.36	13.1572
2105.33	13.1455
2106.3	13.1373
2107.27	14.0926
2108.25	12.1915
2109.22	12.1861
2110.19	15.0384
2111.16	12.1938
2112.13	13.1426
2113.1	12.1876
2114.07	14.0793
2115.04	12.176
2116.01	15.0091
2116.99	14.9959
2117.96	13.099
2118.92	13.1081
2119.9	12.1669
2120.86	13.1174
2121.83	14.0531
2122.8	14.03
2123.77	13.0693
2124.74	13.0607
2125.71	14.0019
2126.68	12.1082
2127.65	12.1045
2128.61	13.986
2129.58	13.9775
2130.55	12.0853
2131.52	13.9733
2132.48	13.9705
2133.45	13.9575
2134.42	13.0128
2135.39	13.0116
2136.35	13.9601
2137.32	14.8849
2138.28	11.1108
2139.25	13.9282
2140.22	12.0574
2141.18	13.9045
2142.15	12.0283
2143.12	12.0265
2144.08	11.0815
2145.05	12.9537
2146.01	12.946
2146.98	13.8689
2147.94	14.7965
2148.9	13.8652
2149.87	12.9256
2150.83	11.9805
2151.8	11.9656
2152.76	14.7513
2153.72	12.8729
2154.69	12.8741
2155.65	13.8128
2156.61	11.9374
2157.58	14.726
2158.54	12.852
2159.5	14.715
2160.47	14.709
2161.43	14.7001
2162.39	11.899
2163.35	13.7607
2164.31	13.7513
2165.27	15.5903
2166.24	13.7291
2167.2	10.9515
2168.16	14.6757
2169.12	12.7927
2170.08	12.7846
2171.04	13.7149
2172	12.7865
2172.96	15.5709
2173.92	14.6353
2174.88	14.6346
2175.84	14.626
2176.8	13.697
2177.76	13.6946
2178.72	15.5462
2179.68	14.6112
2180.64	14.5987
2181.59	12.7361
2182.55	11.8118
2183.51	13.6731
2184.47	13.688
2185.43	12.7587
2186.38	14.6015
2187.34	12.7349
2188.3	14.5906
2189.26	14.5942
2190.21	13.6727
2191.17	13.6892
2192.13	15.5522
2193.08	12.7532
2194.04	12.738
2195	16.4435
2195.95	14.6002
2196.91	14.6181
2197.86	13.7133
2198.82	14.632
2199.78	15.5414
2200.73	15.5554
2201.69	15.5913
2202.64	14.6148
2203.59	15.5461
2204.55	12.7549
2205.5	12.7646
2206.46	11.8387
2207.41	13.7022
2208.37	15.5738
2209.32	14.6518
2210.27	12.7831
2211.23	14.646
2212.18	15.5933
2213.13	14.661
2214.09	15.5919
2215.04	12.7913
2215.99	12.7937
2216.94	13.7349
2217.9	11.8651
2218.85	15.5896
2219.8	11.8502
2220.75	13.7258
2221.7	12.8052
2222.65	12.8166
2223.6	14.7002
2224.55	9.08329
2225.5	12.832
2226.46	16.5787
2227.41	13.777
2228.36	13.7877
2229.31	13.7983
2230.26	15.6892
2231.21	11.9331
2232.16	12.8681
2233.11	11.9197
2234.05	12.8618
2235	14.7604
2235.95	13.8348
2236.9	14.7803
2237.85	16.6618
2238.8	12.8968
2239.75	12.9009
2240.69	13.8401
2241.64	12.8963
2242.59	13.8574
2243.54	14.8133
2244.48	13.8736
2245.43	13.8717
2246.38	14.8141
2247.32	13.8694
2248.27	14.8028
2249.22	13.8555
2250.16	13.8713
2251.11	13.886
2252.06	15.785
2253	12.9415
2253.95	13.8986
2254.89	13.9061
2255.84	12.9591
2256.78	14.865
2257.73	12.969
2258.67	14.8805
2259.62	12.0298
2260.56	11.0881
2261.51	16.8291
2262.45	13.9784
2263.39	11.1096
2264.34	14.9159
2265.28	12.0441
2266.22	13.9547
2267.17	14.9256
2268.11	13.0259
2269.05	13.0334
2270	15.9059
2270.94	12.0806
2271.88	15.9112
2272.82	13.0408
2273.77	14.0094
2274.71	12.1056
2275.65	11.1571
2276.59	14.9942
2277.53	13.0566
2278.47	13.0484
2279.41	12.0918
2280.36	14.9815
2281.3	13.0842
2282.24	14.0568
2283.18	12.1255
2284.12	15.0203
2285.06	13.1067
2286	14.0616
2286.94	15.0021
2287.88	15.9594
2288.82	15.0119
2289.75	14.0597
2290.69	12.1406
2291.63	11.1728
2292.57	12.128
2293.51	14.0404
2294.45	13.0821
2295.39	14.0588
2296.32	12.1408
2297.26	12.1432
2298.2	13.1122
2299.14	16.0094
2300.07	11.1805
2301.01	13.1105
2301.95	13.1174
2302.89	14.0886
2303.82	14.0922
2304.76	12.155
2305.69	12.151
2306.63	11.1909
2307.57	15.0671
2308.5	12.1526
2309.44	14.065
2310.37	11.1662
2311.31	13.1123
2312.24	13.1271
2313.18	12.1467
2314.11	15.0304
2315.05	14.0719
2315.98	13.0943
2316.92	13.0869
2317.85	13.0876
2318.78	13.0962
2319.72	13.108
2320.65	14.0757
2321.58	14.075
2322.52	12.1263
2323.45	12.1154
2324.38	15.9606
2325.32	16.9174
2326.25	17.8738
2327.18	25.5742
2328.11	52.5304
2329.05	21.7271
2329.98	17.858
2330.91	13.0364
2331.84	11.1025
2332.77	13.9847
2333.7	12.0588
2334.63	13.0171
2335.56	13.9741
2336.5	10.1287
2337.43	13.006
2338.36	12.992
2339.29	15.8545
2340.22	13.9309
2341.15	12.9706
2342.08	13.9283
2343.01	13.9173
2343.93	12.9537
2344.86	13.908
2345.79	15.8261
2346.72	13.8941
2347.65	13.8493
2348.58	13.9035
2349.51	14.8158
2350.44	10.9746
2351.36	12.8751
2352.29	12.8792
2353.22	10.9673
2354.15	12.8532
2355.07	11.8936
2356	16.6367
2356.93	9.98133
2357.86	11.8687
2358.78	11.856
2359.71	12.7895
2360.63	11.8338
2361.56	10.8808
2362.49	11.8178
2363.41	13.6841
2364.34	12.7532
2364.8	12.7572