File: Data/3-Raman/raw/bu19w-ff1-fi01-v_1800 (450-850nm)_532nm_edge_100%_x100_vis_h30um_30sx2_01.txt
#Acq. time (s)=	30
#Accumulations=	2
#Range (cm-¹)=	1230...2360
#Windows=	3
#Auto scanning=	Off
#Autofocus=	Off
#Macrospot=	Off
#AutoExposure=	Off
#Spike filter=	Multiple accum.
#Delay time (s)=	2
#Binning=	1
#Readout mode=	Signal
#DeNoise=	Off
#ICS correction=	On
#Dark correction=	Off
#Inst. Process=	Off
#Detector Gain=	Best Dynamic
#Detector ADC=	50 kHz HS
#Detector temperature (°C)=	-60.09
#Instrument=	LabRAM HR Evol
#Detector=	SIN-EM FIVIS
#Objective=	x100_VIS
#Grating=	1800 (450-850nm)
#ND Filter=	100%
#Laser=	532nm_Edge
#Hole=	30.0125
#Temperature=	0
#Range=	Visible
#StageXY=	75x50mm Scan+
#StageZ=	Z motor
#X (µm)=	0
#Y (µm)=	0
#Z (µm)=	-137.6
#Full time(mm:ss)=	3:18
#Project=	21_05_14
#Sample=	BU19w
#Site=
#Title=	BU19w-FF1-FI01-V_1800 (450-850nm)_532nm_Edge_100%_x100_VIS_H30um_30sX2
#Remark=
#Date=	14.05.2021 11:21
#Acquired=	14.05.2021 11:21:13
1231.3	63.5642
1232.13	58.3347
1232.96	67.8153
1233.79	75.1605
1234.62	80.3504
1235.45	72.9189
1236.28	76.0138
1237.11	71.802
1237.94	74.9492
1238.76	74.9396
1239.59	73.8822
1240.42	80.1943
1241.25	68.6677
1242.08	77.0325
1242.91	74.867
1243.74	68.5593
1244.57	64.3656
1245.4	65.3716
1246.22	70.6018
1247.05	83.1478
1247.88	74.7366
1248.71	76.7839
1249.54	83.0065
1250.36	75.6568
1251.19	76.7183
1252.02	84.0568
1252.85	75.707
1253.67	86.1663
1254.5	86.1633
1255.33	89.2725
1256.16	81.9294
1256.98	81.9807
1257.81	76.7074
1258.63	77.7048
1259.46	69.6007
1260.29	83.9154
1261.11	88.3031
1261.94	75.7747
1262.77	82.0236
1263.59	84.1235
1264.42	91.4973
1265.24	90.5396
1266.07	100.046
1266.89	102.141
1267.72	75.8938
1268.55	79.0019
1269.37	79.0358
1270.2	71.7737
1271.02	73.9282
1271.85	73.9493
1272.67	73.9644
1273.5	70.8591
1274.32	78.2512
1275.14	67.7952
1275.97	72.0462
1276.79	81.5221
1277.62	76.2524
1278.44	73.1409
1279.26	82.6332
1280.09	77.3524
1280.91	83.5469
1281.73	87.9807
1282.56	93.1794
1283.38	119.536
1284.2	213.203
1285.03	379.382
1285.85	623.559
1286.67	542.792
1287.5	237.553
1288.32	127.967
1289.14	96.365
1289.96	94.255
1290.78	86.9413
1291.61	75.3982
1292.43	77.5392
1293.25	73.4469
1294.07	78.743
1294.89	74.4725
1295.72	78.6789
1296.54	76.5321
1297.36	72.3243
1298.18	77.6022
1299	67.0662
1299.82	62.8513
1300.64	79.7284
1301.46	73.3884
1302.28	67.0357
1303.11	75.4304
1303.92	75.404
1304.75	65.9206
1305.57	63.8107
1306.39	70.1614
1307.21	69.1252
1308.03	70.1775
1308.85	68.0778
1309.66	65.9952
1310.48	68.0921
1311.3	73.3586
1312.12	64.9315
1312.94	75.5187
1313.76	70.2305
1314.58	70.2359
1315.4	75.5345
1316.22	70.2538
1317.04	69.1958
1317.85	69.1867
1318.67	75.4649
1319.49	72.2537
1320.31	68.0008
1321.13	75.3944
1321.95	75.3898
1322.76	69.0281
1323.58	60.498
1324.4	62.6535
1325.22	64.8297
1326.03	68.0555
1326.85	66.9943
1327.67	69.0795
1328.49	58.4822
1329.3	66.8394
1330.12	69.9283
1330.94	75.1171
1331.75	65.6101
1332.57	70.8168
1333.39	67.6361
1334.2	72.8538
1335.02	68.6336
1335.83	72.7842
1336.65	70.68
1337.47	68.5941
1338.28	70.6877
1339.1	70.6653
1339.91	72.7065
1340.73	67.4571
1341.54	68.5037
1342.36	71.6097
1343.17	68.413
1343.99	64.1634
1344.8	67.2406
1345.62	64.0941
1346.43	70.3109
1347.25	64.0265
1348.06	72.3071
1348.88	74.3496
1349.69	68.1296
1350.5	65.0887
1351.32	71.2479
1352.13	68.0651
1352.95	69.085
1353.76	72.1897
1354.57	76.3212
1355.39	75.2451
1356.2	71.0538
1357.01	73.0912
1357.83	71.9985
1358.64	70.9529
1359.45	75.0754
1360.26	70.9276
1361.08	64.7422
1361.89	69.9103
1362.7	74.007
1363.51	81.1972
1364.32	67.6968
1365.14	70.8047
1365.95	69.7839
1366.76	72.889
1367.57	76.988
1368.38	70.7462
1369.19	74.7952
1370.01	69.5821
1370.82	74.7094
1371.63	95.2981
1372.44	73.6504
1373.25	81.9055
1374.06	74.6326
1374.87	68.4521
1375.68	80.9214
1376.49	71.6446
1377.3	72.6209
1378.11	77.6423
1378.92	77.6008
1379.73	82.6345
1380.54	86.6581
1381.35	77.4063
1382.16	67.1903
1382.97	82.65
1383.78	85.7675
1384.59	97.8261
1385.4	88.5097
1386.21	95.9966
1387.02	140.126
1387.83	200.458
1388.64	484.204
1389.44	1285.7
1390.25	941.228
1391.06	261.468
1391.87	124.318
1392.68	107.99
1393.49	96.7239
1394.3	91.5668
1395.1	91.5417
1395.91	89.5197
1396.72	78.2924
1397.53	75.2398
1398.33	78.337
1399.14	85.5462
1399.95	77.4748
1400.76	77.5107
1401.56	74.386
1402.37	76.4092
1403.18	79.4459
1403.98	86.6115
1404.79	77.4041
1405.6	81.5202
1406.4	75.3872
1407.21	84.6291
1408.01	78.4138
1408.82	87.5944
1409.63	95.8329
1410.43	118.662
1411.24	128.71
1412.04	114.469
1412.85	95.9982
1413.65	78.5665
1414.46	78.5948
1415.27	74.4992
1416.07	80.6746
1416.87	66.2679
1417.68	77.525
1418.48	70.3057
1419.29	70.3549
1420.09	77.6883
1420.9	75.3655
1421.7	68.1392
1422.51	69.2216
1423.31	70.2684
1424.11	62.0173
1424.92	61.9556
1425.72	71.1609
1426.52	70.157
1427.33	73.2788
1428.13	73.3519
1428.93	76.4645
1429.74	76.4218
1430.54	69.1631
1431.34	68.0936
1432.15	71.2185
1432.95	74.2883
1433.75	60.9547
1434.55	68.1137
1435.36	67.0849
1436.16	76.3239
1436.96	69.1864
1437.76	69.2167
1438.56	75.3678
1439.37	71.2665
1440.17	71.2721
1440.97	71.2458
1441.77	73.324
1442.57	68.2258
1443.37	71.2865
1444.18	67.169
1444.98	64.0736
1445.78	72.3059
1446.58	71.276
1447.38	68.17
1448.18	63.0302
1448.98	60.9642
1449.78	64.0339
1450.58	66.101
1451.38	67.1185
1452.18	72.24
1452.98	71.2287
1453.78	73.2754
1454.58	69.1507
1455.38	69.1461
1456.18	60.9599
1456.98	69.1569
1457.78	67.0936
1458.58	67.0694
1459.38	63.9659
1460.17	64.9477
1460.97	64.9236
1461.77	72.1662
1462.57	73.0108
1463.37	68.9075
1464.17	67.8436
1464.97	67.8362
1465.76	71.9119
1466.56	64.7526
1467.36	71.8469
1468.16	71.8266
1468.95	64.6641
1469.75	66.6937
1470.55	69.7286
1471.35	62.5847
1472.15	70.7388
1472.94	65.6403
1473.74	69.6899
1474.54	66.6123
1475.33	69.6493
1476.13	69.6158
1476.93	70.5914
1477.72	64.443
1478.52	70.5068
1479.32	70.5405
1480.11	65.4877
1480.91	63.4663
1481.7	62.3683
1482.5	62.1932
1483.3	67.4018
1484.09	65.3582
1484.89	73.4298
1485.68	65.2914
1486.48	69.3077
1487.27	69.299
1488.07	70.2826
1488.86	69.2534
1489.66	69.2532
1490.45	69.247
1491.25	69.2441
1492.04	68.2362
1492.84	70.1973
1493.63	66.1223
1494.42	79.2286
1495.22	65.0932
1496.01	67.117
1496.81	69.151
1497.6	66.1268
1498.39	65.1014
1499.19	61.0519
1499.98	70.1042
1500.77	61.001
1501.57	67.0621
1502.36	70.0735
1503.15	60.9529
1503.95	57.9344
1504.74	66.005
1505.53	72.0419
1506.33	67.0087
1507.12	67.0217
1507.91	72.0246
1508.7	66.9196
1509.49	76.8649
1510.29	73.7941
1511.08	64.7761
1511.87	70.8075
1512.66	70.7508
1513.45	63.68
1514.24	69.6825
1515.04	70.697
1515.83	71.7182
1516.62	70.731
1517.41	70.7229
1518.2	72.7412
1518.99	71.7383
1519.78	64.6942
1520.57	67.6561
1521.36	65.6017
1522.15	66.5963
1522.94	63.611
1523.73	66.6567
1524.52	53.618
1525.31	67.6318
1526.1	68.6148
1526.89	68.602
1527.68	62.5979
1528.47	70.6439
1529.26	64.625
1530.05	67.6656
1530.84	74.7329
1531.63	68.7098
1532.42	66.6831
1533.21	73.6282
1534	65.5483
1534.78	71.5182
1535.57	64.4798
1536.36	68.507
1537.15	64.6182
1537.94	70.7013
1538.73	67.6515
1539.51	69.6039
1540.3	68.5553
1541.09	68.5042
1541.88	63.5339
1542.66	67.5945
1543.45	66.6118
1544.24	64.6221
1545.03	59.5875
1545.81	64.6114
1546.6	60.4699
1547.39	72.6502
1548.18	74.8081
1548.96	70.7533
1549.75	71.812
1550.53	66.7128
1551.32	60.664
1552.11	63.6159
1552.89	61.6073
1553.68	68.612
1554.46	69.6252
1555.25	60.5811
1556.04	64.5306
1556.82	67.4846
1557.61	73.4572
1558.39	72.4519
1559.18	71.5051
1559.96	66.503
1560.75	67.4942
1561.53	61.5457
1562.32	69.4381
1563.1	65.3399
1563.89	69.4297
1564.67	59.5272
1565.46	73.4887
1566.24	63.4759
1567.03	67.4566
1567.81	59.4647
1568.59	67.4437
1569.38	69.4185
1570.16	66.3903
1570.94	64.3708
1571.73	72.3973
1572.51	62.4555
1573.29	67.4532
1574.08	71.4007
1574.86	65.3412
1575.64	64.3033
1576.43	68.2892
1577.21	69.3043
1577.99	67.3047
1578.77	70.2635
1579.56	68.243
1580.34	68.2306
1581.12	71.2084
1581.9	69.2303
1582.68	66.2373
1583.47	71.1802
1584.25	64.1826
1585.03	71.1362
1585.81	71.1586
1586.59	70.1884
1587.38	68.2042
1588.16	63.2389
1588.94	63.2304
1589.72	72.1362
1590.5	71.0817
1591.28	66.0516
1592.06	65.0756
1592.84	75.9852
1593.62	72.0084
1594.4	68.0473
1595.18	70.0358
1595.96	68.9957
1596.74	68.9592
1597.52	67.9321
1598.3	64.9013
1599.08	73.7577
1599.86	65.7951
1600.64	78.6133
1601.42	67.7278
1602.2	65.7543
1602.98	65.7683
1603.76	70.7391
1604.54	69.7584
1605.32	74.7006
1606.09	71.711
1606.87	67.6977
1607.65	69.6176
1608.43	67.6034
1609.21	71.5553
1609.99	66.6267
1610.77	63.6591
1611.54	69.5596
1612.32	66.5977
1613.1	71.5184
1613.88	69.5638
1614.65	75.4779
1615.43	67.5767
1616.21	78.3941
1616.99	59.6337
1617.76	71.4481
1618.54	65.549
1619.32	70.4891
1620.09	73.4732
1620.87	77.4578
1621.65	65.5658
1622.42	70.4556
1623.2	70.4456
1623.98	59.6159
1624.75	69.4687
1625.53	63.5635
1626.3	70.4564
1627.08	73.398
1627.86	73.3792
1628.63	68.4697
1629.41	72.4326
1630.18	66.5494
1630.96	63.561
1631.73	68.4692
1632.51	61.5549
1633.28	63.2086
1634.06	70.1377
1634.83	65.2567
1635.61	68.9806
1636.38	62.4638
1637.16	69.431
1637.93	67.6773
1638.7	60.2214
1639.48	68.4724
1640.25	67.2061
1641.03	69.0743
1641.8	63.4584
1642.58	63.5402
1643.35	60.7792
1644.12	62.6367
1644.9	64.9821
1645.67	62.143
1646.44	64.4709
1647.21	63.005
1647.99	59.9576
1648.76	66.653
1649.53	62.7749
1650.31	60.554
1651.08	63.1706
1651.85	58.5308
1652.62	62.8849
1653.39	65.9858
1654.17	61.8759
1654.94	61.1418
1655.71	59.708
1656.48	61.3063
1657.25	55.8647
1658.03	61.8424
1658.75	57.7253
1659.53	54.7848
1660.31	53.8609
1661.09	56.7332
1661.87	63.7034
1662.65	56.6735
1663.43	65.7445
1664.22	62.6625
1665	63.648
1665.77	60.6837
1666.55	54.8191
1667.34	57.7709
1668.12	60.7928
1668.89	56.829
1669.67	61.7829
1670.45	56.8428
1671.23	60.8145
1672.01	59.8516
1672.79	62.8422
1673.57	66.8045
1674.35	57.8979
1675.13	51.9405
1675.91	57.8438
1676.68	62.7681
1677.46	64.7272
1678.24	60.7587
1679.02	59.7686
1679.8	59.7694
1680.58	51.8633
1681.35	59.7552
1682.13	62.7052
1682.91	57.7664
1683.69	54.8182
1684.46	58.7781
1685.24	64.6847
1686.02	55.7724
1686.8	60.6757
1687.57	57.7056
1688.35	63.6446
1689.13	64.646
1689.91	55.7446
1690.68	61.6175
1691.46	59.6075
1692.23	62.5514
1693.01	58.6224
1693.79	61.5946
1694.56	58.611
1695.34	55.6178
1696.12	59.5312
1696.89	63.4687
1697.67	54.6017
1698.44	63.4454
1699.22	60.4632
1699.99	56.5037
1700.77	57.4764
1701.54	59.4477
1702.32	56.4985
1703.09	57.4743
1703.87	59.3989
1704.65	55.4315
1705.42	62.2406
1706.19	55.3258
1706.97	61.1833
1707.74	58.252
1708.52	68.0671
1709.29	57.2977
1710.07	56.2585
1710.84	55.2131
1711.61	68.8635
1712.39	58.1182
1713.16	60.0873
1713.93	58.099
1714.71	62.9041
1715.48	59.9049
1716.25	61.8258
1717.03	59.877
1717.8	63.7622
1718.57	61.7729
1719.35	60.7558
1720.12	66.5402
1720.89	62.6326
1721.66	57.7631
1722.44	62.5554
1723.21	56.6907
1723.98	62.4967
1724.75	62.482
1725.52	63.4213
1726.3	58.3756
1727.07	62.3167
1727.84	62.2608
1728.61	61.3708
1729.38	62.3274
1730.15	54.5732
1730.93	54.5119
1731.7	62.1718
1732.47	58.2608
1733.24	65.933
1734.01	58.2118
1734.78	59.15
1735.55	61.9988
1736.32	60.0332
1737.09	62.8363
1737.86	60.8583
1738.63	57.945
1739.4	65.5839
1740.17	56.9531
1740.94	57.8932
1741.71	66.4767
1742.48	60.739
1743.25	63.5868
1744.02	61.6251
1744.79	61.5793
1745.56	62.5238
1746.33	66.3564
1747.1	65.4399
1747.87	57.8303
1748.63	56.8774
1749.4	65.4274
1750.17	61.5659
1750.94	61.5334
1751.71	60.5431
1752.48	64.3322
1753.25	60.483
1754.02	58.5249
1754.78	62.2964
1755.55	66.1303
1756.32	60.425
1757.09	58.5208
1757.85	65.1632
1758.62	61.3249
1759.39	58.4568
1760.16	63.2311
1760.92	63.2345
1761.69	64.2302
1762.46	61.4006
1763.22	56.6481
1763.99	61.3976
1764.76	62.3364
1765.52	59.4592
1766.29	59.4001
1767.06	63.1463
1767.82	63.1795
1768.59	55.618
1769.36	59.4429
1770.12	62.3277
1770.89	68.0598
1771.65	65.2174
1772.42	64.2913
1773.18	58.6277
1773.95	70.0596
1774.71	62.4059
1775.48	53.802
1776.24	61.374
1777.01	55.6696
1777.77	52.8286
1778.54	66.1667
1779.3	57.6215
1780.07	62.4166
1780.83	62.4409
1781.6	59.6169
1782.36	64.4032
1783.13	59.6174
1783.89	64.4045
1784.65	62.5516
1785.42	60.7582
1786.18	61.7681
1786.95	62.7753
1787.71	59.9176
1788.47	58.907
1789.24	62.7282
1790	62.7434
1790.76	63.7099
1791.53	63.7208
1792.29	62.8215
1793.05	62.8819
1793.81	60.9981
1794.58	66.8
1795.34	62.0164
1796.1	57.2104
1796.86	62.9507
1797.63	59.0807
1798.39	59.0707
1799.15	64.8415
1799.91	60.0635
1800.67	60.1002
1801.44	57.2322
1802.2	66.8926
1802.96	60.1992
1803.72	66.0108
1804.48	68.9116
1805.24	61.2041
1806	64.1025
1806.77	58.3266
1807.53	61.2248
1808.29	69.8951
1809.05	68.9304
1809.81	62.2021
1810.57	65.1211
1811.33	64.1987
1812.09	64.2517
1812.85	64.271
1813.61	63.3166
1814.37	60.4066
1815.13	59.3982
1815.89	63.2999
1816.65	61.3779
1817.41	67.2005
1818.17	64.3226
1818.93	70.1584
1819.69	67.2745
1820.44	59.5358
1821.2	54.6851
1821.96	57.6046
1822.72	64.4003
1823.48	62.4663
1824.24	64.4119
1825	62.4947
1825.76	66.3604
1826.51	62.4696
1827.27	60.5192
1828.03	57.6039
1828.79	59.5645
1829.55	65.4027
1830.3	68.3339
1831.06	57.6823
1831.82	67.3234
1832.58	50.7944
1833.33	63.3389
1834.09	66.4036
1834.85	68.2254
1835.6	63.2803
1836.36	66.3687
1837.12	63.4944
1837.88	64.3136
1838.63	66.155
1839.39	57.4002
1840.14	61.2474
1840.9	70.8993
1841.66	67.0436
1842.41	56.4265
1843.17	60.3418
1843.93	65.1836
1844.68	60.162
1845.44	69.8514
1846.19	60.1754
1846.95	62.0506
1847.7	71.6018
1848.46	63.8722
1849.21	65.7759
1849.97	66.7361
1850.72	64.8011
1851.48	66.6652
1852.23	65.669
1852.99	55.0807
1853.74	65.6106
1854.5	65.5999
1855.25	59.8296
1856.01	57.8762
1856.76	71.2233
1857.51	66.4502
1858.27	55.0058
1859.02	66.5104
1859.78	64.5662
1860.53	62.6092
1861.28	67.3495
1862.04	61.5826
1862.79	57.7104
1863.54	61.449
1864.3	64.2274
1865.05	62.2759
1865.8	60.3675
1866.56	67.0203
1867.31	65.1084
1868.06	67.0027
1868.81	66.9878
1869.57	66.962
1870.32	59.3328
1871.07	67.8578
1871.82	66.863
1872.57	66.8077
1873.33	60.0973
1874.08	59.1098
1874.83	64.6441
1875.58	59.1447
1876.33	65.8287
1877.08	62.9635
1877.83	64.8647
1878.59	65.7591
1879.34	61.8775
1880.09	58.9492
1880.84	64.6652
1881.59	57.9874
1882.34	66.5109
1883.09	61.8434
1883.84	65.6257
1884.59	62.7417
1885.34	63.632
1886.09	65.4494
1886.84	59.7738
1887.59	61.6814
1888.34	65.4572
1889.09	69.214
1889.84	64.4885
1890.59	66.2884
1891.34	61.5622
1892.09	67.1707
1892.84	63.429
1893.59	59.6973
1894.34	65.3693
1895.09	64.4346
1895.84	70.05
1896.58	69.066
1897.33	56.8312
1898.08	62.4786
1898.83	54.0562
1899.58	57.8525
1900.33	67.2425
1901.07	65.3462
1901.82	63.4594
1902.57	65.3338
1903.32	67.1649
1904.06	56.8134
1904.81	64.3293
1905.56	61.5379
1906.31	64.3816
1907.05	60.6722
1907.8	65.44
1908.55	60.7575
1909.3	65.4607
1910.04	59.8074
1910.79	63.5936
1911.54	63.6468
1912.28	58.9699
1913.03	70.2982
1913.78	62.7279
1914.52	57.0406
1915.27	62.6954
1916.02	62.7417
1916.76	68.4795
1917.51	71.341
1918.25	60.0238
1919	66.6745
1919.74	65.7226
1920.49	64.7533
1921.24	64.7308
1921.98	66.6044
1922.73	66.6388
1923.47	65.7501
1924.22	64.8534
1924.96	63.933
1925.7	63.0052
1926.45	63.0356
1927.19	64.9863
1927.94	60.2878
1928.68	65.0297
1929.43	64.0546
1930.17	64.0343
1930.92	65.9657
1931.66	60.4067
1932.4	60.5309
1933.15	57.6603
1933.89	64.314
1934.63	71.8892
1935.38	71.8535
1936.12	69.9896
1936.86	68.1173
1937.61	67.1988
1938.35	61.5532
1939.09	62.4574
1939.84	65.4015
1940.58	63.4587
1941.32	62.5189
1942.06	67.3362
1942.81	67.3861
1943.55	60.7267
1944.29	67.4247
1945.03	66.4576
1945.77	64.5415
1946.52	62.663
1947.26	60.8019
1948	67.5879
1948.74	62.8669
1949.48	72.5076
1950.22	73.4953
1950.97	66.7099
1951.71	60.8521
1952.45	60.8343
1953.19	67.6203
1953.93	59.0481
1954.67	63.8899
1955.41	63.9143
1956.15	64.8687
1956.89	67.7317
1957.63	63.8592
1958.37	66.7056
1959.11	62.8613
1959.85	62.8704
1960.59	63.8383
1961.33	67.6967
1962.07	61.9334
1962.81	62.8974
1963.55	67.7404
1964.29	62.9587
1965.03	62.9669
1965.77	63.9278
1966.51	67.7292
1967.25	72.4728
1967.99	65.7219
1968.73	62.8246
1969.47	66.6741
1970.2	65.7033
1970.94	68.543
1971.68	62.7813
1972.42	65.6711
1973.16	68.576
1973.9	62.831
1974.63	66.6574
1975.37	63.7517
1976.11	67.5722
1976.85	69.4944
1977.59	60.8573
1978.32	66.5813
1979.06	60.8181
1979.8	65.5863
1980.53	68.4088
1981.27	66.4764
1982.01	66.4552
1982.75	63.5586
1983.48	65.4922
1984.22	67.4142
1984.95	69.2817
1985.69	71.0939
1986.43	70.0064
1987.16	63.2906
1987.9	57.6222
1988.64	63.392
1989.37	66.2806
1990.11	58.6305
1990.84	63.3374
1991.58	64.2136
1992.32	66.0298
1993.05	65.0277
1993.79	64.0868
1994.52	66.9609
1995.26	60.3107
1995.99	63.1378
1996.73	67.7524
1997.46	67.6897
1998.2	66.868
1998.93	75.4017
1999.67	61.0862
2000.4	61.0202
2001.14	65.7162
2001.87	65.6975
2002.6	62.8526
2003.34	61.8998
2004.07	60.0212
2004.81	66.6156
2005.54	67.4951
2006.27	72.1588
2007.01	66.4417
2007.74	62.6351
2008.48	59.8043
2009.21	59.7694
2009.94	66.1298
2010.67	61.2674
2011.41	64.227
2012.14	67.5805
2012.87	66.4904
2013.61	57.9383
2014.34	59.9939
2015.07	59.0048
2015.8	64.4718
2016.54	62.8889
2017.27	68.8743
2018	59.7171
2018.73	59.5404
2019.46	64.8138
2020.2	63.4008
2020.93	60.8548
2021.66	62.6752
2022.39	63.4022
2023.12	62.1081
2023.85	61.5742
2024.58	60.0441
2025.32	59.7117
2026.05	59.627
2026.78	62.6941
2027.51	61.6161
2028.24	59.6228
2028.97	57.1837
2029.7	60.7338
2030.43	59.3428
2031.16	60.6917
2031.89	60.4452
2032.62	58.4327
2033.35	62.204
2034.08	57.6291
2034.81	59.6669
2035.36	59.3531
2036.1	60.2591
2036.84	55.5575
2037.58	57.3774
2038.32	60.1376
2039.05	60.121
2039.79	54.5043
2040.53	55.4533
2041.27	60.1758
2042.01	57.3397
2042.74	56.4404
2043.48	61.2551
2044.22	60.2038
2044.96	62.9238
2045.69	61.0676
2046.43	52.7067
2047.17	56.4914
2047.91	56.5221
2048.64	63.9636
2049.38	54.6318
2050.12	57.453
2050.86	52.8309
2051.59	65.9498
2052.33	61.2658
2053.07	58.4356
2053.8	67.7667
2054.54	54.6871
2055.28	59.3865
2056.01	55.6855
2056.75	59.4471
2057.49	60.3704
2058.22	62.2504
2058.96	52.8997
2059.69	56.6571
2060.43	61.3708
2061.16	62.3299
2061.9	55.7887
2062.63	56.7733
2063.37	55.8695
2064.11	56.8247
2064.84	63.4244
2065.58	60.626
2066.31	59.6891
2067.05	63.3915
2067.78	60.6345
2068.51	63.4697
2069.25	54.1479
2069.98	57.904
2070.72	60.7277
2071.45	59.799
2072.19	58.9049
2072.92	58.9855
2073.65	62.7792
2074.39	60.8596
2075.12	57.0576
2075.85	61.799
2076.59	59.02
2077.32	65.667
2078.06	62.8368
2078.79	62.8303
2079.52	60.9482
2080.25	64.733
2080.99	58.1137
2081.72	62.8402
2082.45	62.8433
2083.19	60.0285
2083.92	61.0155
2084.65	53.4695
2085.38	61.0441
2086.12	59.1608
2086.85	56.3551
2087.58	57.3161
2088.31	62.0735
2089.04	58.3222
2089.78	60.2801
2090.51	63.1788
2091.24	67.974
2091.97	67.0251
2092.7	58.4442
2093.43	55.5751
2094.16	60.3127
2094.89	58.3851
2095.63	59.3201
2096.36	64.061
2097.09	52.67
2097.82	58.3757
2098.55	58.41
2099.28	64.1117
2100.01	58.4005
2100.74	57.4315
2101.47	65.0297
2102.2	62.2105
2102.93	67.0003
2103.66	60.3645
2104.39	63.2278
2105.12	69.8439
2105.85	53.649
2106.58	57.4614
2107.31	57.4739
2108.04	55.5743
2108.77	59.3614
2109.5	64.1006
2110.22	57.4726
2110.95	65.109
2111.68	64.148
2112.41	56.5464
2113.14	60.3332
2113.87	59.3544
2114.6	63.1507
2115.33	62.174
2116.05	60.2278
2116.78	63.0336
2117.51	60.1678
2118.24	65.8736
2118.97	56.4358
2119.69	61.2126
2120.42	62.1827
2121.15	60.2743
2121.88	62.1195
2122.6	60.147
2123.33	56.3101
2124.06	61.0029
2124.78	64.7647
2125.51	60.0239
2126.24	57.1864
2126.97	64.7362
2127.69	60.9447
2128.42	59.033
2129.15	60.8985
2129.87	56.1495
2130.6	61.809
2131.32	60.8719
2132.05	57.0952
2132.78	55.1975
2133.5	61.7531
2134.23	66.4653
2134.95	60.8323
2135.68	59.8517
2136.4	59.8997
2137.13	64.5449
2137.85	61.6947
2138.58	54.1531
2139.31	59.7722
2140.03	60.7371
2140.76	65.2798
2141.48	63.4656
2142.21	59.6947
2142.93	63.4648
2143.65	60.6291
2144.38	65.3075
2145.1	58.7088
2145.83	57.7481
2146.55	60.5263
2147.28	67.9726
2148	66.0793
2148.72	52.9773
2149.45	69.8777
2150.17	62.3442
2150.89	60.4487
2151.62	59.4632
2152.34	54.7118
2153.06	59.337
2153.79	62.1214
2154.51	63.0611
2155.23	60.2876
2155.96	63.0899
2156.68	59.3276
2157.4	64.8873
2158.13	60.1894
2158.85	55.5101
2159.57	61.1065
2160.29	67.6195
2161.01	61.071
2161.74	55.4424
2162.46	62.8988
2163.18	61.0375
2163.9	62.8755
2164.62	65.6302
2165.35	58.1102
2166.07	64.6167
2166.79	62.8003
2167.51	62.8588
2168.23	62.8444
2168.95	64.624
2169.67	59.0052
2170.39	63.6419
2171.12	62.7268
2171.84	58.0882
2172.56	61.7997
2173.28	59.0029
2174	65.4886
2174.72	57.131
2175.44	68.2691
2176.16	65.4557
2176.88	55.2463
2177.6	56.1721
2178.32	60.8054
2179.04	68.2124
2179.76	57.9873
2180.48	61.6625
2181.2	62.5505
2181.92	54.2064
2182.64	57.9281
2183.35	61.6657
2184.07	58.0044
2184.79	59.907
2185.51	64.5309
2186.23	62.6317
2186.95	62.5787
2187.67	59.7911
2188.39	57.0213
2189.1	60.7457
2189.82	56.1243
2190.54	64.5086
2191.26	64.5881
2191.98	62.7467
2192.7	64.5821
2193.41	58.0246
2194.13	60.7675
2194.85	57.0439
2195.57	58.9256
2196.28	61.7677
2197	59.9686
2197.72	60.9921
2198.44	64.7705
2199.15	58.928
2199.87	59.9749
2200.59	62.756
2201.3	64.8026
2202.02	59.1597
2202.74	64.6199
2203.45	55.337
2204.17	59.0389
2204.89	60.9342
2205.6	60.9735
2206.32	61.9296
2207.03	62.8621
2207.75	61.9549
2208.47	62.9176
2209.18	62.0235
2209.9	54.567
2210.61	61.0705
2211.33	65.7517
2212.04	63.0089
2212.76	66.7555
2213.47	63.0215
2214.19	60.2147
2214.9	53.6862
2215.62	63.0266
2216.33	63.9915
2217.05	64.0193
2217.76	64.0173
2218.48	55.5798
2219.19	57.4125
2219.91	55.5483
2220.62	57.4451
2221.33	62.1718
2222.05	71.5742
2222.76	65.0767
2223.48	67.9293
2224.19	61.4059
2224.9	64.2379
2225.62	62.3503
2226.33	65.154
2227.04	66.1291
2227.76	66.1698
2228.47	68.0941
2229.18	64.3785
2229.9	63.4766
2230.61	64.4541
2231.32	67.3018
2232.03	60.6943
2232.75	62.5321
2233.46	66.3046
2234.17	56.9137
2234.88	60.7341
2235.6	71.1654
2236.31	58.0224
2237.02	59.8919
2237.73	61.7434
2238.44	68.4059
2239.16	60.8715
2239.87	59.9496
2240.58	59.9335
2241.29	63.6992
2242	61.8539
2242.71	47.7342
2243.42	64.7893
2244.14	60.0866
2244.85	64.8333
2245.56	67.6631
2246.27	64.8144
2246.98	61.9951
2247.69	59.1303
2248.4	64.769
2249.11	70.4408
2249.82	65.7521
2250.53	61.0999
2251.24	62.0897
2251.95	57.3634
2252.66	60.2097
2253.37	61.1799
2254.08	59.3147
2254.79	67.8889
2255.5	61.2549
2256.21	64.128
2256.92	61.2983
2257.63	59.4175
2258.33	65.1647
2259.05	63.279
2259.75	60.4487
2260.46	61.4484
2261.17	62.4714
2261.88	66.3508
2262.59	57.7897
2263.3	63.513
2264	69.1956
2264.71	61.5305
2265.42	66.2685
2266.13	60.565
2266.84	65.3886
2267.54	62.5834
2268.25	64.5301
2268.96	62.6484
2269.67	60.7506
2270.38	65.5463
2271.08	58.859
2271.79	63.6554
2272.5	59.8395
2273.2	65.6038
2273.91	63.7339
2274.62	64.7499
2275.32	57.1384
2276.03	61.9488
2276.74	67.6757
2277.45	59.9446
2278.15	60.8752
2278.86	63.7402
2279.56	65.6832
2280.27	60.9337
2280.98	65.815
2281.68	64.9189
2282.39	66.8818
2283.09	62.0438
2283.8	66.8552
2284.5	71.7443
2285.21	63.1033
2285.92	61.1507
2286.62	63.9794
2287.33	63.9295
2288.03	65.8593
2288.74	63.0287
2289.44	63.0639
2290.15	59.2531
2290.85	60.2412
2291.56	63.1155
2292.26	62.1225
2292.97	61.1353
2293.67	51.4696
2294.37	61.1132
2295.08	62.1289
2295.78	66.0209
2296.48	56.4227
2297.19	63.1861
2297.89	68.0244
2298.6	62.2577
2299.3	67.0818
2300	63.217
2300.71	62.247
2301.41	62.2742
2302.11	63.2686
2302.82	61.3543
2303.52	67.1742
2304.22	63.3094
2304.93	64.2582
2305.63	60.3826
2306.33	58.4697
2307.03	59.4851
2307.74	61.4303
2308.44	62.3553
2309.14	60.3341
2309.84	66.0962
2310.54	71.9061
2311.25	68.1165
2311.95	69.1575
2312.65	62.3729
2313.35	67.1474
2314.05	62.2792
2314.75	65.1965
2315.46	63.2514
2316.16	63.2247
2316.86	61.2731
2317.56	65.1347
2318.26	67.0906
2318.96	60.3744
2319.66	58.4865
2320.36	56.5581
2321.06	69.1398
2321.76	66.2223
2322.46	63.264
2323.17	65.1573
2323.86	68.9742
2324.57	67.9685
2325.27	64.0948
2325.97	73.727
2326.67	65.9779
2327.36	69.8338
2328.06	65.9662
2328.76	71.7701
2329.46	89.0968
2330.16	128.535
2330.86	163.143
2331.56	93.7941
2332.26	67.7979
2332.96	63.9543
2333.66	62.0204
2334.36	63.9357
2335.06	66.8078
2335.75	61.0329
2336.45	67.7655
2337.15	60.0635
2337.85	67.7151
2338.55	59.0143
2339.25	69.5233
2339.94	57.0379
2340.64	59.9112
2341.34	70.4578
2342.04	61.8289
2342.74	57.966
2343.43	63.6847
2344.13	71.3334
2344.83	62.7107
2345.53	63.6854
2346.22	61.7565
2346.92	66.4568
2347.62	58.6586
2348.31	62.616
2349.01	65.3828
2349.71	60.5847
2350.4	63.3522
2351.1	64.291
2351.8	62.4156
2352.49	66.2162
2353.19	62.3827
2353.89	62.3093
2354.58	60.3741
2355.28	64.1513
2355.97	61.2769
2356.67	62.2124
2357.36	64.0731
2358.06	66.8744
2358.76	68.7207
2359.45	63.9298
2359.92	61.0622