File: Data/3-Raman/raw/bu19(2)w-a-ff2-fi05-v_1800 (450-850nm)_532nm_edge_100%_x100_vis_lwd_h100um_30sx2_01.txt
#Acq. time (s)=	30
#Accumulations=	2
#Range (cm-¹)=	1200...2365
#Windows=	3
#Auto scanning=	Off
#Autofocus=	Off
#Macrospot=	Off
#AutoExposure=	Off
#Spike filter=	Multiple accum.
#Delay time (s)=	2
#Binning=	1
#Readout mode=	Signal
#DeNoise=	Off
#ICS correction=	On
#Dark correction=	Off
#Inst. Process=	Off
#Detector Gain=	Best Dynamic
#Detector ADC=	50 kHz HS
#Detector temperature (°C)=	-60.09
#Instrument=	LabRAM HR Evol
#Detector=	SIN-EM FIVIS
#Objective=	x100_VIS_LWD
#Grating=	1800 (450-850nm)
#ND Filter=	100%
#Laser=	532nm_Edge
#Hole=	100.021
#Temperature=	0
#Range=	Visible
#StageXY=	75x50mm Scan+
#StageZ=	Z motor
#X (µm)=	0
#Y (µm)=	0
#Z (µm)=	-51.2
#Full time(mm:ss)=	3:17
#Project=	21_11_26
#Sample=	BU19(2)w
#Site=
#Title=	BU19(2)w-A-FF2-FI05-V_1800 (450-850nm)_532nm_Edge_100%_x100_VIS_LWD_H100um_30sX2
#Remark=
#Date=	26.11.2021 15:09
#Acquired=	26.11.2021 15:09:56
1202.72	210.244
1203.84	200.639
1204.95	196.186
1206.06	214.141
1207.17	198.724
1208.28	208.139
1209.39	201.497
1210.5	193.912
1211.61	204.28
1212.72	193.334
1213.83	199.535
1214.94	220.794
1216.05	214.357
1217.16	214.036
1218.27	193.613
1219.38	209.398
1220.49	202.934
1221.6	207.096
1222.71	208.93
1223.81	200.078
1224.92	205.117
1226.03	194.561
1227.14	202.958
1228.25	209.863
1229.35	209.355
1230.46	209.912
1231.57	206.161
1232.67	199.848
1233.78	213.451
1234.89	204.066
1235.99	198.892
1237.1	209.349
1238.2	211.171
1239.31	206.718
1240.41	203.492
1241.52	197.213
1242.62	215.992
1243.73	207.664
1244.83	223.377
1245.94	220.019
1247.04	211.513
1248.14	207.267
1249.25	209.233
1250.35	222.815
1251.45	219.471
1252.56	211.993
1253.66	212.879
1254.76	218.21
1255.87	207.792
1256.97	234.984
1258.07	247.448
1259.17	250.442
1260.27	229.707
1261.37	254.48
1262.48	301.026
1263.58	325.237
1264.68	284.423
1265.78	256.966
1266.88	242.329
1267.98	249.879
1269.08	254.391
1270.18	246.002
1271.28	246.809
1272.38	242.638
1273.47	245.012
1274.57	258.873
1275.67	248.403
1276.77	265.38
1277.87	247.726
1278.97	290.009
1280.07	330.025
1281.16	467.817
1282.26	1123.9
1283.36	2270.21
1284.45	1239.25
1285.55	448.347
1286.65	325.076
1287.75	278.616
1288.84	248.013
1289.94	257.626
1291.03	246.099
1292.13	251.326
1293.22	248.142
1294.32	225.237
1295.42	237.936
1296.51	231.029
1297.61	240.496
1298.7	231.899
1299.79	232.819
1300.89	228.655
1301.98	213.893
1303.08	219.22
1304.17	225.461
1305.26	228.594
1306.35	215.727
1307.45	210.401
1308.54	217.788
1309.63	217.843
1310.73	218.922
1311.82	217.889
1312.91	238.045
1314	217.901
1315.09	217.911
1316.18	214.843
1317.28	221.133
1318.37	222.247
1319.46	207.456
1320.55	215.899
1321.64	203.069
1322.73	214.476
1323.82	210.17
1324.91	204.898
1326	213.181
1327.09	217.026
1328.18	222.655
1329.27	212.36
1330.35	221.815
1331.44	216.346
1332.53	210.76
1333.62	206.265
1334.71	214.421
1335.79	217.379
1336.88	221.427
1337.97	210.846
1339.06	204.386
1340.14	231.594
1341.23	217.986
1342.32	216.845
1343.4	228.149
1344.49	214.52
1345.58	222.77
1346.66	215.139
1347.75	216.953
1348.83	207.461
1349.92	205.218
1351	221.696
1352.09	220.479
1353.17	204.999
1354.25	238.523
1355.34	234.839
1356.42	210.905
1357.51	222.213
1358.59	226.212
1359.67	223.967
1360.76	225.813
1361.84	221.587
1362.92	235.988
1364	238.126
1365.09	242.244
1366.17	235.815
1367.25	240.715
1368.33	255.165
1369.41	316.225
1370.5	239.637
1371.58	244.586
1372.66	247.313
1373.74	244.039
1374.82	237.768
1375.9	252.172
1376.98	267.49
1378.06	264.294
1379.14	281.207
1380.22	292.387
1381.3	294.857
1382.38	330.491
1383.46	356.675
1384.54	471.288
1385.61	924.278
1386.69	3689.87
1387.77	2536.97
1388.85	613.492
1389.93	361.091
1391	318.494
1392.08	285.441
1393.16	258.589
1394.23	256.432
1395.31	269.709
1396.39	266.711
1397.46	254.287
1398.54	242.969
1399.62	244.084
1400.69	246.205
1401.77	251.429
1402.84	239.493
1403.92	265.373
1404.99	262.099
1406.07	307.031
1407.14	323.331
1408.22	435.17
1409.29	376.829
1410.37	276.376
1411.44	238.17
1412.51	243.239
1413.59	222.32
1414.66	217.942
1415.73	222.138
1416.81	213.982
1417.88	223.319
1418.95	217.184
1420.02	226.367
1421.1	221.045
1422.17	207.702
1423.24	217.387
1424.31	228.967
1425.38	216.66
1426.45	207.478
1427.52	194.965
1428.59	212.175
1429.67	194.816
1430.74	210.352
1431.81	211.638
1432.87	206.382
1433.95	204.017
1435.01	210.226
1436.08	207.141
1437.15	205.02
1438.22	208.029
1439.29	197.846
1440.36	200.033
1441.43	195.977
1442.49	202.098
1443.56	203.102
1444.63	202.026
1445.7	192.942
1446.77	189.792
1447.83	197.914
1448.9	197.966
1449.97	191.773
1451.03	192.696
1452.1	202.865
1453.17	199.772
1454.23	186.473
1455.3	199.771
1456.36	175.21
1457.43	193.571
1458.49	185.334
1459.56	202.774
1460.62	188.394
1461.69	192.397
1462.75	193.277
1463.82	182.871
1464.88	188.182
1465.94	186.599
1467.01	189.591
1468.07	186.489
1469.13	196.653
1470.2	195.497
1471.26	187.236
1472.32	201.381
1473.39	188.102
1474.45	180.877
1475.51	171.738
1476.57	207.279
1477.63	198.014
1478.69	180.648
1479.76	192.712
1480.82	192.495
1481.88	185.312
1482.94	193.557
1484	179.367
1485.06	179.999
1486.12	193.106
1487.18	199.198
1488.24	191.997
1489.3	166.532
1490.36	187.721
1491.42	196.711
1492.48	181.516
1493.53	186.539
1494.59	194.61
1495.65	192.499
1496.71	190.283
1497.77	188.201
1498.82	177.08
1499.88	191.244
1500.94	181.153
1502	178.044
1503.05	193.098
1504.11	182.908
1505.17	189.976
1506.22	185.765
1507.28	194.839
1508.34	204.907
1509.39	187.77
1510.45	187.79
1511.5	194.659
1512.56	195.273
1513.61	192.035
1514.67	180.093
1515.72	204.015
1516.78	177.745
1517.83	176.705
1518.88	187.795
1519.94	186.834
1520.99	185.797
1522.05	184.818
1523.1	199.773
1524.15	190.52
1525.2	201.443
1526.26	201.518
1527.31	192.594
1528.36	183.493
1529.41	211.461
1530.47	186.356
1531.52	203.503
1532.57	195.447
1533.62	196.648
1534.67	199.679
1535.72	197.57
1536.77	205.297
1537.82	182.061
1538.87	199.932
1539.92	176.193
1540.97	178.48
1542.02	187.377
1543.07	203.2
1544.12	191.957
1545.17	206.075
1546.22	198.252
1547.27	189.269
1548.32	196.17
1549.37	186.038
1550.42	189.096
1551.46	200.686
1552.51	195.662
1553.56	189.487
1554.61	191.341
1555.65	194.166
1556.7	201.15
1557.75	198.165
1558.79	192.989
1559.84	193.758
1560.89	185.654
1561.93	198.672
1562.98	202.769
1564.02	180.721
1565.07	193.865
1566.11	177.759
1567.16	198.473
1568.2	200.616
1569.25	202.653
1570.29	191.547
1571.34	189.533
1572.38	198.424
1573.43	187.31
1574.47	189.275
1575.51	179.457
1576.56	184.468
1577.6	198.212
1578.64	195.977
1579.69	202.931
1580.73	179.046
1581.77	185.932
1582.81	184.819
1583.85	189.752
1584.9	198.715
1585.94	195.705
1586.98	185.592
1588.02	193.469
1589.06	174.616
1590.1	191.597
1591.14	189.65
1592.18	194.577
1593.22	194.383
1594.26	196.076
1595.3	203.056
1596.34	185.096
1597.38	185.106
1598.42	197.025
1599.46	201.801
1600.5	189.749
1601.54	203.401
1602.58	209.123
1603.62	204.972
1604.66	205.904
1605.69	183.17
1606.73	202.04
1607.77	199.135
1608.81	194.08
1609.84	198.666
1610.88	202.014
1611.92	199.292
1612.95	193.642
1613.99	191.637
1615.03	189.476
1616.06	199.094
1617.1	192.58
1618.13	201.108
1619.17	191.343
1620.2	190.771
1621.24	197.081
1622.27	198.66
1623.31	198.642
1624.34	191.053
1625.38	200.75
1626.41	201.075
1627.45	197.39
1628.48	198.034
1629.51	189.37
1630.55	197.125
1631.53	196.297
1632.57	196.348
1633.62	196.292
1634.66	206.156
1635.71	185.403
1636.75	203.018
1637.8	194.003
1638.84	197.844
1639.89	195.836
1640.93	193.861
1641.98	194.806
1643.02	211.46
1644.06	193.672
1645.11	197.485
1646.15	195.537
1647.19	194.439
1648.24	201.221
1649.28	201.364
1650.32	190.492
1651.37	197.522
1652.41	188.653
1653.45	188.57
1654.49	200.397
1655.53	210.304
1656.57	197.654
1657.62	198.607
1658.66	184.684
1659.7	211.163
1660.74	189.4
1661.78	193.445
1662.82	191.649
1663.86	191.634
1664.9	189.493
1665.94	194.138
1666.98	210.144
1668.02	193.215
1669.06	200.124
1670.1	203.195
1671.14	201.331
1672.18	204.221
1673.21	195.308
1674.25	188.395
1675.29	210.23
1676.33	200.346
1677.37	208.244
1678.4	191.288
1679.44	184.203
1680.48	196.944
1681.52	181.031
1682.55	192.842
1683.59	188.84
1684.63	195.667
1685.66	200.528
1686.7	195.572
1687.73	184.715
1688.77	201.381
1689.81	187.386
1690.84	185.326
1691.88	206.08
1692.91	182.335
1693.95	179.158
1694.98	197.7
1696.01	188.824
1697.05	192.781
1698.08	192.587
1699.12	190.447
1700.15	187.449
1701.18	189.328
1702.22	185.259
1703.25	191.983
1704.28	198.772
1705.32	196.807
1706.35	189.847
1707.38	194.535
1708.41	189.376
1709.44	191.061
1710.48	207.621
1711.51	194.924
1712.54	177.267
1713.57	198.472
1714.6	184.547
1715.63	206.975
1716.66	193.256
1717.69	193.946
1718.72	193.586
1719.75	191.525
1720.78	186.609
1721.81	191.27
1722.84	182.295
1723.87	185.033
1724.9	192.701
1725.93	186.576
1726.96	187.435
1727.99	208.653
1729.02	200.462
1730.05	197.321
1731.07	187.511
1732.1	193.493
1733.13	200.135
1734.16	195.968
1735.18	204.351
1736.21	202.189
1737.24	189.546
1738.26	196.126
1739.29	183.424
1740.32	185.979
1741.34	197.219
1742.37	187.466
1743.4	198.854
1744.42	189.146
1745.45	186.197
1746.47	197.56
1747.5	182.024
1748.52	190.465
1749.55	187.606
1750.57	193.455
1751.6	193.5
1752.62	182.769
1753.64	194.024
1754.67	184.297
1755.69	187.017
1756.71	195.378
1757.74	179.912
1758.76	195.156
1759.78	196.088
1760.81	201.703
1761.83	199.629
1762.85	187.216
1763.87	187.2
1764.89	198.723
1765.92	194.015
1766.94	188.249
1767.96	186.249
1768.98	204.203
1770	190.494
1771.02	189.608
1772.04	184.974
1773.06	192.655
1774.08	203.173
1775.1	197.488
1776.12	196.691
1777.14	191.886
1778.16	193.628
1779.18	189.617
1780.2	186.69
1781.22	196.234
1782.24	184.827
1783.26	182.055
1784.28	204.041
1785.29	186.015
1786.31	180.204
1787.33	178.344
1788.35	200.643
1789.37	205.693
1790.38	190.504
1791.4	180.857
1792.42	187.378
1793.43	190.273
1794.45	203.69
1795.47	178.9
1796.48	184.827
1797.5	183.014
1798.51	176.339
1799.53	189.743
1800.55	199.182
1801.56	181.793
1802.58	192.36
1803.59	186.693
1804.61	186.741
1805.62	182.05
1806.64	189.868
1807.65	191.809
1808.66	184.071
1809.68	185.024
1810.69	195.616
1811.7	190.73
1812.72	174.33
1813.73	182.102
1814.74	189.959
1815.76	199.734
1816.77	176.54
1817.78	196.682
1818.79	185.081
1819.8	180.266
1820.82	180.313
1821.83	183.269
1822.84	192.021
1823.85	184.239
1824.86	196.792
1825.87	176.491
1826.88	195.833
1827.89	191.978
1828.9	179.339
1829.91	178.274
1830.92	180.099
1831.93	191.754
1832.94	192.801
1833.95	180.215
1834.96	173.271
1835.97	177.798
1836.98	177.458
1837.99	180.718
1839	189.374
1840	182.818
1841.01	173.708
1842.02	177.205
1843.03	191.479
1844.04	184.687
1845.04	176.936
1846.05	185.635
1847.06	197.373
1848.07	193.754
1849.07	182.199
1850.08	183.941
1851.09	179.826
1852.09	180.627
1853.1	191.139
1854.1	187.182
1855.11	183.106
1856.11	173.307
1857.12	179.946
1858.12	186.539
1859.13	170.079
1860.13	176.609
1861.14	186.212
1862.14	181.492
1863.15	179.418
1864.15	178.261
1865.15	184.768
1866.16	174.951
1867.16	186.984
1868.16	177.195
1869.17	192.346
1870.17	182.765
1871.17	180.793
1872.17	178.784
1873.18	188.127
1874.18	195.602
1875.18	183.051
1876.18	190.31
1877.18	175.875
1878.18	187.854
1879.19	190.973
1880.19	197.719
1881.19	193.868
1882.19	179.356
1883.19	191.193
1884.19	193.77
1885.19	190.061
1886.19	185.552
1887.19	189.264
1888.19	178.663
1889.19	193.444
1890.19	178.232
1891.19	183.958
1892.18	186.703
1893.18	193.168
1894.18	167.448
1895.18	196.451
1896.18	172.984
1897.18	191.871
1898.17	195.647
1899.17	184.209
1900.17	193.435
1901.16	185.874
1902.16	197.267
1903.16	186.959
1904.16	197.189
1905.15	176.434
1906.15	187.599
1907.14	178.972
1908.14	188.349
1909.14	186.515
1910.13	191.356
1911.13	184.966
1912.12	185.925
1913.12	189.622
1914.11	185.908
1915.11	174.739
1916.1	192.697
1917.1	173.697
1918.09	187.711
1919.08	183.083
1920.08	192.756
1921.07	173.858
1922.06	181.531
1923.06	194.704
1924.05	176.623
1925.04	184.053
1926.04	180.365
1927.03	190.002
1928.02	175.881
1929.01	177.815
1930	184.567
1931	188.532
1931.99	188.473
1932.98	186.426
1933.97	185.471
1934.96	177.424
1935.95	190.188
1936.94	181.385
1937.93	182.135
1938.92	183.039
1939.91	192.635
1940.9	172.717
1941.89	189.064
1942.88	184.337
1943.87	183.233
1944.86	182.377
1945.85	178.7
1946.84	176.874
1947.83	184.457
1948.82	179.615
1949.8	195.005
1950.79	185.669
1951.78	186.889
1952.77	169.722
1953.76	183.152
1954.74	173.125
1955.73	191.196
1956.72	190.536
1957.7	188.764
1958.69	182.098
1959.68	185.841
1960.66	189.547
1961.65	177.855
1962.63	190.299
1963.62	178.773
1964.61	184.556
1965.59	174.894
1966.58	173.994
1967.56	191.344
1968.55	191.341
1969.53	187.352
1970.52	187.098
1971.5	191.742
1972.48	189.783
1973.47	185.866
1974.45	187.623
1975.44	198.146
1976.42	186.705
1977.4	182.845
1978.39	186.545
1979.37	181.653
1980.35	188.343
1981.33	191.073
1982.31	189.048
1983.3	192.719
1984.28	187.759
1985.26	182.85
1986.24	188.485
1987.22	184.691
1988.21	200.755
1989.19	178.562
1990.17	188.975
1991.15	201.322
1992.13	188.72
1993.11	188.784
1994.09	190.472
1995.07	191.617
1996.05	188.288
1997.03	188.847
1998.01	201.458
1998.99	197.158
1999.97	191.569
2000.95	194.807
2001.92	193.09
2002.9	198.088
2003.88	196.4
2004.86	198.505
2005.84	196.142
2006.81	196.482
2007.79	189.957
2008.77	195.462
2009.75	195.808
2010.73	198.721
2011.7	203.094
2012.68	197.614
2013.67	205.844
2014.66	208.316
2015.64	196.012
2016.63	195.14
2017.62	200.889
2018.61	194.039
2019.6	191.864
2020.58	193.639
2021.57	194.565
2022.56	202.922
2023.55	181.203
2024.54	197.86
2025.52	191.052
2026.51	194.612
2027.5	201.644
2028.48	188.32
2029.47	191.403
2030.45	179.623
2031.44	186.217
2032.43	189.032
2033.41	178.038
2034.4	182.716
2035.38	189.892
2036.37	181.858
2037.35	191.139
2038.34	175.178
2039.32	193.739
2040.31	180.493
2041.29	187.762
2042.27	191.389
2043.26	171.729
2044.24	185.901
2045.23	184.845
2046.21	179.598
2047.19	174.751
2048.17	176.382
2049.16	191.329
2050.14	194.325
2051.12	186.046
2052.11	191.528
2053.09	181.3
2054.07	177.738
2055.05	199.295
2056.03	199.185
2057.01	178.543
2058	184.179
2058.98	180.561
2059.96	185.311
2060.94	185.229
2061.92	171.244
2062.9	180.632
2063.88	191.035
2064.86	183.593
2065.84	186.567
2066.82	176.336
2067.8	175.457
2068.78	183.981
2069.76	180.158
2070.73	173.548
2071.71	175.524
2072.69	182.342
2073.67	179.47
2074.65	192.682
2075.63	183.474
2076.6	189.321
2077.58	188.268
2078.56	172.171
2079.54	176.969
2080.51	179.018
2081.49	170.493
2082.47	184.65
2083.45	178.044
2084.42	173.291
2085.4	181.787
2086.37	180.885
2087.35	183.845
2088.32	181.988
2089.3	179.163
2090.28	194.424
2091.25	172.677
2092.23	185.12
2093.2	185.334
2094.18	189.295
2095.15	179.809
2096.13	177.792
2097.1	174.879
2098.07	173.807
2099.05	187.036
2100.02	182.248
2101	187.962
2101.97	185.213
2102.94	184.233
2103.92	178.428
2104.89	180.346
2105.86	170.001
2106.83	189.073
2107.8	166.251
2108.78	175.569
2109.75	185.051
2110.72	186.024
2111.69	177.444
2112.66	179.273
2113.63	179.357
2114.61	182.219
2115.58	180.301
2116.55	167.855
2117.52	179.17
2118.49	177.187
2119.46	184.582
2120.43	170.216
2121.4	185.404
2122.37	179.86
2123.34	176.151
2124.31	187.513
2125.28	167.347
2126.25	168.049
2127.21	181.124
2128.18	176.307
2129.15	185.714
2130.12	177.149
2131.09	177.082
2132.06	185.464
2133.02	181.564
2133.99	186.26
2134.96	180.591
2135.93	178.65
2136.89	186.954
2137.86	180.376
2138.83	179.352
2139.79	184.092
2140.76	185.807
2141.73	181.977
2142.69	174.337
2143.66	189.525
2144.62	175.036
2145.59	168.446
2146.55	178.739
2147.52	173.012
2148.48	187.002
2149.45	185.933
2150.42	181.015
2151.38	187.516
2152.34	180.088
2153.31	178.137
2154.27	193.022
2155.24	179.635
2156.2	167.234
2157.16	182.102
2158.13	178.419
2159.09	171.886
2160.05	165.231
2161.01	186.529
2161.98	174.318
2162.94	178.023
2163.9	189.119
2164.86	181.515
2165.83	177.768
2166.79	179.579
2167.75	184.086
2168.71	178.238
2169.67	186.656
2170.63	182.212
2171.59	182.146
2172.56	174.393
2173.51	177.102
2174.48	183.639
2175.44	167.828
2176.4	177.067
2177.36	180.712
2178.32	172.345
2179.28	181.511
2180.23	177.792
2181.19	178.674
2182.15	179.527
2183.11	189.649
2184.07	179.262
2185.03	171.776
2185.99	176.457
2186.95	181.221
2187.9	171.186
2188.86	183.167
2189.82	179.248
2190.78	169.885
2191.73	169.906
2192.69	176.441
2193.65	185.81
2194.6	178.627
2195.56	168.37
2196.52	180.256
2197.47	178.219
2198.43	185.622
2199.38	182.1
2200.34	176.763
2201.3	170.524
2202.25	186.665
2203.21	175.805
2204.16	185.752
2205.12	177.945
2206.07	170.999
2207.03	180.265
2207.98	158.032
2208.93	179.556
2209.89	173.078
2210.84	171.247
2211.8	174.137
2212.75	175.168
2213.7	178.809
2214.66	163.953
2215.61	178.98
2216.56	164.037
2217.51	170.538
2218.47	165.866
2219.42	176.201
2220.37	180.016
2221.32	179.03
2222.27	168.582
2223.23	170.444
2224.18	160.293
2225.13	173.544
2226.08	173.697
2227.03	162.573
2227.98	166.396
2228.93	171.966
2229.88	183.213
2230.83	174.912
2231.78	175.992
2232.73	165.773
2233.68	173.407
2234.63	179.106
2235.58	180.842
2236.53	175.16
2237.48	171.45
2238.43	166.962
2239.38	186.958
2240.33	171.776
2241.27	175.611
2242.22	168.094
2243.17	170.969
2244.12	172.774
2245.07	167.172
2246.01	165.467
2246.96	175.025
2247.91	167.517
2248.85	179.773
2249.8	174.085
2250.75	172.142
2251.69	177.668
2252.64	177.698
2253.59	176.992
2254.53	172.399
2255.48	166.714
2256.42	173.381
2257.37	174.435
2258.32	172.606
2259.26	175.502
2260.2	169.863
2261.15	177.533
2262.1	170.019
2263.04	164.381
2263.98	166.461
2264.93	182.908
2265.87	174.418
2266.81	162.861
2267.76	189.433
2268.7	165.467
2269.65	174.147
2270.59	172.439
2271.53	180.197
2272.47	169.761
2273.42	173.605
2274.36	175.542
2275.3	170.781
2276.24	164.104
2277.18	169.99
2278.13	175.959
2279.07	180.864
2280.01	176.879
2280.95	169.019
2281.89	169.885
2282.83	174.754
2283.77	181.661
2284.71	178.096
2285.65	172.424
2286.59	167.498
2287.54	169.594
2288.47	174.475
2289.41	187.801
2290.35	173.126
2291.29	173.124
2292.23	162.695
2293.17	181.119
2294.11	174.448
2295.05	177.23
2295.99	174.227
2296.93	168.298
2297.86	174.167
2298.8	176.252
2299.74	173.495
2300.68	167.704
2301.61	172.604
2302.55	174.515
2303.49	179.304
2304.43	176.443
2305.36	164.944
2306.3	183.352
2307.24	174.671
2308.17	169.768
2309.11	163.934
2310.04	169.868
2310.98	172.808
2311.92	169.627
2312.85	174.279
2313.79	178.174
2314.72	178.389
2315.66	173.65
2316.59	176.312
2317.52	171.399
2318.46	173.344
2319.39	177.081
2320.33	176.043
2321.26	167.388
2322.2	176.211
2323.13	172.441
2324.06	173.436
2325	176.268
2325.93	189.577
2326.86	266.589
2327.79	441.818
2328.73	254.717
2329.66	202.523
2330.59	185.154
2331.52	173.555
2332.46	169.735
2333.39	179.242
2334.32	174.33
2335.25	174.194
2336.18	172.258
2337.11	163.546
2338.04	173.107
2338.97	175.941
2339.91	166.318
2340.84	163.328
2341.77	165.034
2342.7	172.556
2343.63	162.923
2344.56	176.326
2345.49	172.447
2346.41	166.547
2347.34	167.443
2348.27	171.255
2349.2	167.426
2350.13	158.548
2351.06	172.05
2351.99	160.306
2352.91	165.77
2353.84	177.896
2354.77	169.312
2355.7	171.21
2356.63	170.12
2357.55	159.433
2358.48	175.484
2359.41	166.835
2360.33	163.875
2361.26	167.499
2362.19	161.628
2363.11	164.292
2364.04	155.667
2364.97	160.29