File: Data/3-Raman/raw/bu19(2)w-a-ff2b-fi03-v_1800 (450-850nm)_532nm_edge_100%_x100_vis_lwd_h100um_30sx2_01.txt
#Acq. time (s)=	30
#Accumulations=	2
#Range (cm-¹)=	1200...2365
#Windows=	3
#Auto scanning=	Off
#Autofocus=	Off
#Macrospot=	Off
#AutoExposure=	Off
#Spike filter=	Multiple accum.
#Delay time (s)=	2
#Binning=	1
#Readout mode=	Signal
#DeNoise=	Off
#ICS correction=	On
#Dark correction=	Off
#Inst. Process=	Off
#Detector Gain=	Best Dynamic
#Detector ADC=	50 kHz HS
#Detector temperature (°C)=	-60.09
#Instrument=	LabRAM HR Evol
#Detector=	SIN-EM FIVIS
#Objective=	x50_VIS_LWD
#Grating=	1800 (450-850nm)
#ND Filter=	100%
#Laser=	532nm_Edge
#Hole=	100.021
#Temperature=	0
#Range=	Visible
#StageXY=	75x50mm Scan+
#StageZ=	Z motor
#X (µm)=	0
#Y (µm)=	0
#Z (µm)=	-10.1
#Full time(mm:ss)=	3:23
#Project=	21_11_26
#Sample=	BU19(2)w
#Site=
#Title=	BU19(2)w-A-FF2b-FI03-V_1800 (450-850nm)_532nm_Edge_100%_x50_VIS_LWD_H100um_30sX2
#Remark=
#Date=	26.11.2021 14:57
#Acquired=	26.11.2021 14:57:04
1202.72	93.0237
1203.84	99.5091
1204.95	86.5288
1206.06	89.6151
1207.17	89.437
1208.28	89.3348
1209.39	79.6097
1210.5	83.84
1211.61	84.7713
1212.72	81.4503
1213.83	78.1724
1214.94	76.0253
1216.05	67.487
1217.16	79.073
1218.27	83.2229
1219.38	85.2846
1220.49	76.7539
1221.6	69.2975
1222.71	71.315
1223.81	75.4022
1224.92	72.1399
1226.03	79.5264
1227.14	75.28
1228.25	72.9948
1229.35	75.9653
1230.46	65.6267
1231.57	72.7883
1232.67	73.8307
1233.78	70.6552
1234.89	68.5723
1235.99	69.6465
1237.1	75.929
1238.2	80.0224
1239.31	79.9195
1240.41	74.6423
1241.52	74.6418
1242.62	72.5095
1243.73	68.331
1244.83	77.7562
1245.94	78.7233
1247.04	77.6244
1248.14	76.5508
1249.25	73.3616
1250.35	78.5811
1251.45	76.4122
1252.56	84.7021
1253.66	85.6783
1254.76	83.6302
1255.87	78.4137
1256.97	98.2678
1258.07	90.9259
1259.17	89.8269
1260.27	97.1875
1261.37	122.109
1262.48	144.323
1263.58	148.099
1264.68	118.228
1265.78	99.2943
1266.88	86.7464
1267.98	94.1456
1269.08	89.0255
1270.18	87.9699
1271.28	88.9252
1272.38	92.0659
1273.47	87.9757
1274.57	89.1009
1275.67	89.103
1276.77	87.063
1277.87	97.6335
1278.97	130.316
1280.07	174.511
1281.16	361.741
1282.26	1112.48
1283.36	1358.18
1284.45	481.39
1285.55	192.593
1286.65	127.271
1287.75	111.421
1288.84	100.859
1289.94	88.274
1291.03	89.3428
1292.13	89.3238
1293.22	87.2036
1294.32	89.4108
1295.42	80.986
1296.51	80.0922
1297.61	71.6181
1298.7	85.2978
1299.79	76.7987
1300.89	69.4221
1301.98	78.9276
1303.08	75.771
1304.17	69.3975
1305.26	71.4931
1306.35	70.3672
1307.45	62.9617
1308.54	72.4504
1309.63	61.9126
1310.73	62.9689
1311.82	75.6348
1312.91	65.1031
1314	66.1289
1315.09	69.2933
1316.18	70.3767
1317.28	66.1317
1318.37	72.482
1319.46	67.1944
1320.55	66.1299
1321.64	69.2415
1322.73	64.9502
1323.82	65.9722
1324.91	58.5858
1326	62.7525
1327.09	65.7952
1328.18	66.9537
1329.27	71.2461
1330.35	67.0078
1331.44	66.9418
1332.53	64.7303
1333.62	62.5324
1334.71	69.8021
1335.79	61.3419
1336.88	64.4397
1337.97	62.3087
1339.06	63.2975
1340.14	58.0501
1341.23	65.3766
1342.32	66.3893
1343.4	65.2756
1344.49	60.0312
1345.58	65.2202
1346.66	61.9871
1347.75	55.6466
1348.83	64.9908
1349.92	72.2246
1351	59.6712
1352.09	66.8961
1353.17	65.8891
1354.25	62.8225
1355.34	70.9786
1356.42	65.7667
1357.51	57.4169
1358.59	63.5979
1359.67	72.8776
1360.76	65.5452
1361.84	62.4077
1362.92	70.6583
1364	74.816
1365.09	74.8029
1366.17	66.4503
1367.25	70.5027
1368.33	93.2312
1369.41	109.791
1370.5	76.6746
1371.58	77.6326
1372.66	76.4781
1373.74	78.4771
1374.82	82.5638
1375.9	81.5218
1376.98	88.6829
1378.06	83.4949
1379.14	92.9017
1380.22	101.089
1381.3	110.125
1382.38	124.381
1383.46	167.277
1384.54	283.025
1385.61	857.96
1386.69	3203.43
1387.77	1144.23
1388.85	287.993
1389.93	160.212
1391	129.199
1392.08	99.3734
1393.16	91.0961
1394.23	86.9586
1395.31	83.8748
1396.39	93.105
1397.46	78.7247
1398.54	73.5842
1399.62	78.7234
1400.69	81.8131
1401.77	81.8427
1402.84	76.8317
1403.92	85.109
1404.99	96.3253
1406.07	113.683
1407.14	148.491
1408.22	206.967
1409.29	160.868
1410.37	102.425
1411.44	79.7671
1412.51	72.5711
1413.59	71.737
1414.66	65.485
1415.73	57.2934
1416.81	55.2493
1417.88	62.4594
1418.95	55.2687
1420.02	52.1639
1421.1	61.3526
1422.17	50.0545
1423.24	60.4417
1424.31	57.1537
1425.38	55.0965
1426.45	53.0519
1427.52	51.9647
1428.59	53.9534
1429.67	50.8883
1430.74	49.9001
1431.81	46.8781
1432.87	47.8687
1433.95	51.8843
1435.01	53.9435
1436.08	44.7126
1437.15	43.6656
1438.22	51.8381
1439.29	49.799
1440.36	44.7021
1441.43	49.8338
1442.49	45.7181
1443.56	46.7322
1444.63	46.7139
1445.7	48.7951
1446.77	48.7703
1447.83	49.7684
1448.9	43.6221
1449.97	43.6066
1451.03	49.7262
1452.1	40.478
1453.17	47.6397
1454.23	50.7134
1455.3	48.6518
1456.36	41.4805
1457.43	39.4054
1458.49	45.5363
1459.56	44.5115
1460.62	38.3498
1461.69	42.4194
1462.75	40.3339
1463.82	45.4
1464.88	42.3729
1465.94	42.2354
1467.01	38.1318
1468.07	35.0562
1469.13	47.2823
1470.2	37.0488
1471.26	39.058
1472.32	38.009
1473.39	39.0119
1474.45	36.9482
1475.51	39.9997
1476.57	43.0288
1477.63	41.9812
1478.69	45.0064
1479.76	36.8394
1480.82	38.8191
1481.88	35.752
1482.94	39.8311
1484	35.7685
1485.06	39.7358
1486.12	35.6625
1487.18	42.7508
1488.24	38.6684
1489.3	42.6746
1490.36	36.5838
1491.42	39.5881
1492.48	38.5643
1493.53	35.5179
1494.59	39.5518
1495.65	36.4946
1496.71	38.4677
1497.77	41.4756
1498.82	41.4648
1499.88	31.3715
1500.94	35.4037
1502	36.3894
1503.05	36.3662
1504.11	33.3134
1505.17	40.3672
1506.22	37.298
1507.28	43.3385
1508.34	44.3378
1509.39	40.2993
1510.45	41.3051
1511.5	41.2575
1512.56	37.1446
1513.61	33.077
1514.67	37.1089
1515.72	38.07
1516.78	36.019
1517.83	39.0123
1518.88	37.0132
1519.94	30.9955
1520.99	39.0081
1522.05	38.0037
1523.1	29.9542
1524.15	39.9275
1525.2	37.8979
1526.26	35.9023
1527.31	30.902
1528.36	37.8949
1529.41	37.8714
1530.47	36.8498
1531.52	36.8667
1532.57	36.8522
1533.62	34.879
1534.67	36.8824
1535.72	38.8608
1536.77	39.7969
1537.82	33.7417
1538.87	36.7099
1539.92	34.7568
1540.97	37.8173
1542.02	34.7771
1543.07	43.7422
1544.12	32.6808
1545.17	33.6944
1546.22	33.7206
1547.27	37.727
1548.32	37.6977
1549.37	38.6666
1550.42	36.6699
1551.46	39.7873
1552.51	36.7678
1553.56	39.7401
1554.61	32.6823
1555.65	41.6579
1556.7	35.6356
1557.75	37.6363
1558.79	35.5932
1559.84	35.5412
1560.89	37.512
1561.93	32.5127
1562.98	30.5224
1564.02	30.5073
1565.07	38.5305
1566.11	38.2751
1567.16	30.4452
1568.2	36.4598
1569.25	35.4603
1570.29	38.4307
1571.34	30.4259
1572.38	40.3908
1573.43	36.3625
1574.47	30.3604
1575.51	28.3852
1576.56	33.3771
1577.6	36.3202
1578.64	33.2754
1579.69	35.2579
1580.73	35.2602
1581.77	34.2375
1582.81	33.2116
1583.85	28.2155
1584.9	38.169
1585.94	34.1739
1586.98	36.1275
1588.02	38.0938
1589.06	33.1228
1590.1	32.1318
1591.14	29.1452
1592.18	33.1124
1593.22	36.0544
1594.26	38.9697
1595.3	38.9684
1596.34	34.9723
1597.38	38.9409
1598.42	36.9474
1599.46	31.9407
1600.5	32.9001
1601.54	37.8062
1602.58	36.7667
1603.62	32.7675
1604.66	35.7169
1605.69	36.7005
1606.73	39.6776
1607.77	36.6896
1608.81	36.6277
1609.84	36.4017
1610.88	34.2636
1611.92	33.3114
1612.95	33.1984
1613.99	34.2236
1615.03	31.6222
1616.06	34.3423
1617.1	34.6572
1618.13	35.098
1619.17	36.012
1620.2	36.1854
1621.24	36.528
1622.27	35.6759
1623.31	36.8642
1624.34	36.0372
1625.38	36.639
1626.41	35.7927
1627.45	36.8155
1628.48	33.936
1629.51	32.3977
1630.55	35.2606
1631.53	40.5907
1632.57	35.6739
1633.62	30.7362
1634.66	30.7355
1635.71	33.682
1636.75	33.6603
1637.8	34.6187
1638.84	38.5381
1639.89	33.6087
1640.93	34.591
1641.98	31.6296
1643.02	37.5215
1644.06	38.492
1645.11	31.5818
1646.15	32.5673
1647.19	30.5798
1648.24	33.5127
1649.28	37.4719
1650.32	41.4004
1651.37	34.5332
1652.41	35.5175
1653.45	29.5903
1654.49	30.5741
1655.53	35.5089
1656.57	36.5245
1657.62	37.5046
1658.66	33.5372
1659.7	35.4827
1660.74	33.4977
1661.78	39.434
1662.82	37.4946
1663.86	30.5753
1664.9	33.5098
1665.94	32.4734
1666.98	30.5314
1668.02	34.4547
1669.06	33.4668
1670.1	32.4953
1671.14	35.4769
1672.18	36.4513
1673.21	32.4935
1674.25	35.4598
1675.29	31.5147
1676.33	36.4624
1677.37	34.4788
1678.4	33.4655
1679.44	35.4135
1680.48	30.4518
1681.52	30.4338
1682.55	30.4253
1683.59	34.3671
1684.63	37.314
1685.66	33.3494
1686.7	32.3575
1687.73	29.394
1688.77	35.2982
1689.81	33.2926
1690.84	39.1953
1691.88	34.2677
1692.91	34.2561
1693.95	31.2578
1694.98	35.1671
1696.01	32.209
1697.05	33.1958
1698.08	38.0855
1699.12	32.1478
1700.15	35.0908
1701.18	32.1228
1702.22	34.0654
1703.25	34.0368
1704.28	36.9678
1705.32	33.0369
1706.35	33.0219
1707.38	31.0203
1708.41	36.8608
1709.44	33.8707
1710.48	33.8555
1711.51	32.8801
1712.54	33.8537
1713.57	29.8837
1714.6	35.7063
1715.63	36.6753
1716.66	32.7593
1717.69	38.5643
1718.72	40.4419
1719.75	38.4716
1720.78	35.5412
1721.81	36.4757
1722.84	37.4041
1723.87	36.3978
1724.9	36.3787
1725.93	35.3515
1726.96	39.2069
1727.99	37.2502
1729.02	34.2687
1730.05	39.0558
1731.07	36.1293
1732.1	37.1302
1733.13	38.0731
1734.16	36.0856
1735.18	28.3244
1736.21	37.9157
1737.24	37.8904
1738.26	34.0143
1739.29	38.7808
1740.32	32.9583
1741.34	38.6615
1742.37	39.5844
1743.4	36.6929
1744.42	37.6234
1745.45	34.7383
1746.47	40.4543
1747.5	35.6277
1748.52	37.5077
1749.55	39.4182
1750.57	32.7533
1751.6	37.5397
1752.62	30.8108
1753.64	39.3656
1754.67	38.374
1755.69	38.3457
1756.71	38.3039
1757.74	37.3047
1758.76	32.5515
1759.78	42.0633
1760.81	38.2386
1761.83	42.009
1762.85	43.8998
1763.87	39.1433
1764.89	42.9715
1765.92	36.3191
1766.94	37.2607
1767.96	37.2417
1768.98	43.8771
1770	37.1428
1771.02	41.9053
1772.04	42.8833
1773.06	43.852
1774.08	43.8638
1775.1	41.9661
1776.12	42.9525
1777.14	43.898
1778.16	42.9098
1779.18	40.0108
1780.2	36.1898
1781.22	38.0982
1782.24	36.1972
1783.26	38.1197
1784.28	36.225
1785.29	35.2878
1786.31	38.1326
1787.33	37.1889
1788.35	40.1207
1789.37	40.1724
1790.38	38.2837
1791.4	32.5207
1792.42	42.0644
1793.43	37.2801
1794.45	34.4057
1795.47	33.4697
1796.48	36.3804
1797.5	34.4793
1798.51	40.2581
1799.53	33.5168
1800.55	35.408
1801.56	32.5082
1802.58	37.3107
1803.59	35.4071
1804.61	34.4537
1805.62	33.5127
1806.64	32.5684
1807.65	34.4972
1808.66	30.6361
1809.68	33.5249
1810.69	32.5575
1811.7	34.4735
1812.72	34.4712
1813.73	36.4113
1814.74	33.5402
1815.76	36.4577
1816.77	35.4915
1817.78	33.5304
1818.79	31.5957
1819.8	38.3636
1820.82	30.6376
1821.83	38.3857
1822.84	34.5225
1823.85	31.611
1824.86	34.5087
1825.87	36.4507
1826.88	30.6344
1827.89	33.5421
1828.9	34.5021
1829.91	28.6726
1830.92	32.5259
1831.93	35.4365
1832.94	32.5428
1833.95	36.4218
1834.96	33.4833
1835.97	38.2606
1836.98	35.4821
1837.99	36.3297
1839	30.5127
1840	34.4237
1841.01	37.2496
1842.02	35.2425
1843.03	34.2396
1844.04	31.3379
1845.04	30.3664
1846.05	35.1925
1847.06	34.2536
1848.07	31.2396
1849.07	34.1262
1850.08	34.0921
1851.09	32.1203
1852.09	32.0913
1853.1	35.9225
1854.1	27.2616
1855.11	34.8958
1856.11	31.0224
1857.12	32.9255
1858.12	32.9052
1859.13	30.0001
1860.13	33.7951
1861.14	31.8891
1862.14	30.942
1863.15	30.9137
1864.15	30.8783
1865.15	31.802
1866.16	30.7996
1867.16	29.7872
1868.16	35.4462
1869.17	34.4837
1870.17	30.6673
1871.17	29.7038
1872.17	32.5349
1873.18	31.5575
1874.18	32.4858
1875.18	32.4477
1876.18	32.3916
1877.18	33.2948
1878.18	32.2941
1879.19	31.3945
1880.19	27.6247
1881.19	32.3473
1882.19	32.2914
1883.19	35.9884
1884.19	32.1719
1885.19	32.1809
1886.19	30.3268
1887.19	31.2589
1888.19	33.1067
1889.19	33.9955
1890.19	33.9682
1891.19	31.1563
1892.18	32.0833
1893.18	32.0611
1894.18	35.7629
1895.18	33.8595
1896.18	31.0437
1897.18	26.3548
1898.17	30.1168
1899.17	31.0313
1900.17	36.6388
1901.16	31.9327
1902.16	31.9502
1903.16	30.0736
1904.16	35.6958
1905.15	30.9814
1906.15	34.7202
1907.14	31.8703
1908.14	31.8667
1909.14	33.7524
1910.13	32.8358
1911.13	32.8689
1912.12	30.987
1913.12	32.8578
1914.11	31.9239
1915.11	35.7211
1916.1	34.7836
1917.1	32.8721
1918.09	34.7335
1919.08	30.9757
1920.08	31.957
1921.07	33.8453
1922.06	35.7572
1923.06	31.9622
1924.05	30.0505
1925.04	30.9727
1926.04	38.5501
1927.03	32.908
1928.02	31.0273
1929.01	31.9808
1930	34.8451
1931	33.9264
1931.99	32.9659
1932.98	28.1953
1933.97	31.0393
1934.96	32.0754
1935.95	31.1859
1936.94	33.0535
1937.93	35.8726
1938.92	31.103
1939.91	32.0661
1940.9	34.9412
1941.89	34.0123
1942.88	31.1559
1943.87	34.946
1944.86	25.4163
1945.85	32.1241
1946.84	29.2696
1947.83	33.0824
1948.82	31.1583
1949.8	32.1281
1950.79	32.1668
1951.78	28.3717
1952.77	32.2297
1953.76	30.3049
1954.74	32.1483
1955.73	32.1235
1956.72	30.2526
1957.7	34.1171
1958.69	33.1663
1959.68	36.0302
1960.66	33.1228
1961.65	31.1721
1962.63	33.0849
1963.62	35.0028
1964.61	34.0464
1965.59	33.0747
1966.58	35.9676
1967.56	30.2106
1968.55	35.9769
1969.53	34.0277
1970.52	32.0616
1971.5	33.9532
1972.48	33.9454
1973.47	35.8485
1974.45	37.7348
1975.44	38.6891
1976.42	31.9883
1977.4	37.7386
1978.39	40.5878
1979.37	36.7334
1980.35	40.5636
1981.33	36.7016
1982.31	39.5537
1983.3	43.3504
1984.28	44.269
1985.26	41.3723
1986.24	39.4394
1987.22	42.3147
1988.21	45.1422
1989.19	45.9308
1990.17	40.3731
1991.15	46.0698
1992.13	47.1718
1993.11	45.2646
1994.09	39.8772
1995.07	44.2812
1996.05	45.1875
1997.03	48.6589
1998.01	45.9302
1998.99	48.9032
1999.97	44.4325
2000.95	51.1045
2001.92	50.7853
2002.9	50.0504
2003.88	48.7641
2004.86	48.4419
2005.84	48.3375
2006.81	46.6235
2007.79	49.4685
2008.77	51.0372
2009.75	49.583
2010.73	46.8527
2011.7	46.2863
2012.68	51.513
2013.67	43.9283
2014.66	48.5501
2015.64	55.0978
2016.63	42.9116
2017.62	47.6358
2018.61	44.7546
2019.6	44.6858
2020.58	39.9809
2021.57	45.5993
2022.56	47.4569
2023.55	47.4105
2024.54	46.4331
2025.52	46.3697
2026.51	42.5984
2027.5	43.6418
2028.48	41.7209
2029.47	42.7194
2030.45	40.7227
2031.44	41.6712
2032.43	43.5425
2033.41	37.9878
2034.4	37.0551
2035.38	38.863
2036.37	37.0723
2037.35	38.929
2038.34	37.9807
2039.32	37.9548
2040.31	37.9202
2041.29	42.5432
2042.27	36.9288
2043.26	37.8427
2044.24	34.1527
2045.23	39.7239
2046.21	34.197
2047.19	38.8299
2048.17	37.8464
2049.16	40.6509
2050.14	33.2255
2051.12	30.445
2052.11	36.0277
2053.09	36.0371
2054.07	37.0085
2055.05	32.3409
2056.03	33.2581
2057.01	30.4409
2058	35.1203
2058.98	37.0162
2059.96	29.5418
2060.94	34.2079
2061.92	26.7291
2062.9	32.3515
2063.88	32.3689
2064.86	36.1289
2065.84	31.4686
2066.82	26.7902
2067.8	31.4965
2068.78	29.6286
2069.76	27.7388
2070.73	34.311
2071.71	32.45
2072.69	28.726
2073.67	32.4844
2074.65	32.4897
2075.63	31.5842
2076.6	30.6719
2077.58	26.88
2078.56	28.7577
2079.54	30.6586
2080.51	29.7416
2081.49	31.6278
2082.47	27.8457
2083.45	33.5168
2084.42	27.8423
2085.4	30.6759
2086.37	34.4646
2087.35	28.8118
2088.32	29.7637
2089.3	29.7661
2090.28	30.7309
2091.25	30.7382
2092.23	28.8622
2093.2	31.7441
2094.18	29.8706
2095.15	32.7259
2096.13	27.9541
2097.1	32.6937
2098.07	30.7724
2099.05	29.8131
2100.02	31.7041
2101	29.8092
2101.97	28.8752
2102.94	31.7195
2103.92	27.9039
2104.89	29.8057
2105.86	30.7735
2106.83	26.9822
2107.8	31.7345
2108.78	32.6503
2109.75	26.9493
2110.72	26.9522
2111.69	30.7471
2112.66	28.8359
2113.63	28.8493
2114.61	28.8509
2115.58	28.848
2116.55	29.7824
2117.52	25.9702
2118.49	32.6023
2119.46	27.826
2120.43	27.8028
2121.4	27.8065
2122.37	29.7257
2123.34	27.8418
2124.31	25.9387
2125.28	31.5905
2126.25	23.9713
2127.21	27.7306
2128.18	29.6074
2129.15	28.6546
2130.12	28.6452
2131.09	27.6896
2132.06	26.727
2133.02	24.8212
2133.99	28.5924
2134.96	24.8162
2135.93	27.639
2136.89	31.3817
2137.86	27.6139
2138.83	27.6014
2139.79	26.6623
2140.76	29.4636
2141.73	29.4535
2142.69	26.6118
2143.66	30.3974
2144.62	28.455
2145.59	31.2743
2146.55	29.3858
2147.52	30.3109
2148.48	27.476
2149.45	30.2727
2150.42	28.3599
2151.38	27.413
2152.34	27.4236
2153.31	28.3492
2154.27	29.2691
2155.24	29.2254
2156.2	24.5119
2157.16	29.1709
2158.13	28.2451
2159.09	28.2465
2160.05	24.4909
2161.01	28.199
2161.98	31.9181
2162.94	27.249
2163.9	26.302
2164.86	30.9399
2165.83	27.2094
2166.79	30.9278
2167.75	26.2476
2168.71	28.0682
2169.67	23.4254
2170.63	27.176
2171.59	31.8208
2172.56	30.836
2173.51	28.0351
2174.48	28.9694
2175.44	25.2499
2176.4	26.1708
2177.36	25.2312
2178.32	28.9458
2179.28	25.2122
2180.23	28.9251
2181.19	27.9892
2182.15	22.4089
2183.11	27.0365
2184.07	28.8626
2185.03	26.071
2185.99	29.7856
2186.95	26.0959
2187.9	25.1929
2188.86	27.0364
2189.82	29.7874
2190.78	27.918
2191.73	25.1399
2192.69	27.9283
2193.65	28.8702
2194.6	28.9094
2195.56	22.3979
2196.52	26.087
2197.47	26.9879
2198.43	24.2021
2199.38	25.1552
2200.34	34.4892
2201.3	26.1598
2202.25	27.9287
2203.21	28.9039
2204.16	30.8718
2205.12	25.2217
2206.07	33.5267
2207.03	27.0139
2207.98	27.0274
2208.93	28.9086
2209.89	29.8464
2210.84	27.9889
2211.8	26.1398
2212.75	28.0199
2213.7	27.0731
2214.66	28.9495
2215.61	22.4306
2216.56	27.0976
2217.51	23.3577
2218.47	26.1576
2219.42	30.8375
2220.37	23.3742
2221.32	26.1701
2222.27	23.343
2223.23	26.1429
2224.18	24.2934
2225.13	24.3164
2226.08	27.1467
2227.03	27.1657
2227.98	26.24
2228.93	24.3561
2229.88	29.9808
2230.83	24.3736
2231.78	27.2108
2232.73	28.1698
2233.68	28.188
2234.63	25.3727
2235.58	29.114
2236.53	28.1672
2237.48	23.4714
2238.43	29.1545
2239.38	26.357
2240.33	25.4003
2241.27	25.409
2242.22	26.3572
2243.17	30.14
2244.12	30.1257
2245.07	25.416
2246.01	22.608
2246.96	26.4049
2247.91	26.4143
2248.85	27.3532
2249.8	26.4051
2250.75	27.3434
2251.69	28.2655
2252.64	25.4329
2253.59	22.6256
2254.53	23.5916
2255.48	23.5916
2256.42	22.6467
2257.37	28.3545
2258.32	29.3155
2259.26	23.6236
2260.2	29.3341
2261.15	20.7872
2262.1	28.41
2263.04	24.6142
2263.98	27.4994
2264.93	26.5812
2265.87	25.6411
2266.81	25.6262
2267.76	22.7417
2268.7	28.4463
2269.65	25.6
2270.59	27.5402
2271.53	26.6014
2272.47	25.6574
2273.42	23.7459
2274.36	25.6627
2275.3	25.6661
2276.24	27.585
2277.18	26.6492
2278.13	27.6418
2279.07	24.7765
2280.01	27.6353
2280.95	25.688
2281.89	25.6737
2282.83	22.8078
2283.77	25.7117
2284.71	26.7129
2285.65	23.8408
2286.59	26.7096
2287.54	28.6624
2288.47	24.8198
2289.41	28.6485
2290.35	25.7254
2291.29	26.6863
2292.23	24.7856
2293.17	28.657
2294.11	26.7413
2295.05	29.6145
2295.99	27.6699
2296.93	26.6828
2297.86	26.6974
2298.8	25.7577
2299.74	25.7772
2300.68	28.6704
2301.61	28.6833
2302.55	22.889
2303.49	26.744
2304.43	27.7143
2305.36	26.7628
2306.3	20.9722
2307.24	26.7727
2308.17	29.6604
2309.11	25.7894
2310.04	26.7769
2310.98	23.8807
2311.92	24.807
2312.85	27.6764
2313.79	25.751
2314.72	24.8152
2315.66	23.8609
2316.59	29.6241
2317.52	26.713
2318.46	27.6807
2319.39	25.7304
2320.33	25.7194
2321.26	25.7238
2322.2	28.6415
2323.13	30.5906
2324.06	30.5958
2325	34.4508
2325.93	46.9636
2326.86	92.2691
2327.79	214.629
2328.73	72.8927
2329.66	44.9096
2330.59	36.2349
2331.52	27.5596
2332.46	27.5648
2333.39	25.6195
2334.32	25.6048
2335.25	28.4696
2336.18	26.5441
2337.11	23.6503
2338.04	23.6425
2338.97	25.5575
2339.91	27.4779
2340.84	26.4995
2341.77	23.5862
2342.7	26.4411
2343.63	24.5163
2344.56	29.3066
2345.49	26.4237
2346.41	27.3576
2347.34	26.3902
2348.27	29.2596
2349.2	29.26
2350.13	24.4319
2351.06	27.1675
2351.99	29.1852
2352.91	23.4141
2353.84	30.0456
2354.77	24.3279
2355.7	24.3265
2356.63	24.3065
2357.55	25.2246
2358.48	23.3069
2359.41	26.1431
2360.33	23.2772
2361.26	22.3041
2362.19	24.1739
2363.11	26.9875
2364.04	20.3463
2364.97	26.9514