File: Data/3-Raman/raw/bu19w-e-ff11-fi10-s2_150 (500nm)_633nm_edge_100%_x100_vis_h50um_60sx2_01.txt
#Acq. time (s)=	60
#Accumulations=	2
#Range (cm-¹)=	100...4000
#Windows=	1
#Auto scanning=	Off
#Autofocus=	Off
#Macrospot=	Off
#AutoExposure=	Off
#Spike filter=	Multiple accum.
#Delay time (s)=	2
#Binning=	1
#Readout mode=	Signal
#DeNoise=	Off
#ICS correction=	On
#Dark correction=	Off
#Inst. Process=	Off
#Detector Gain=	Best Dynamic
#Detector ADC=	50 kHz HS
#Detector temperature (°C)=	-60.09
#Instrument=	LabRAM HR Evol
#Detector=	SIN-EM FIVIS
#Objective=	x100_VIS
#Grating=	150 (500nm)
#ND Filter=	100%
#Laser=	633nm_Edge
#Hole=	49.98
#Temperature=	0
#Range=	Visible
#StageXY=	75x50mm Scan+
#StageZ=	Z motor
#X (µm)=	0
#Y (µm)=	0
#Z (µm)=	-266.9
#Full time(mm:ss)=	2:04
#Project=	21_11_04
#Sample=	BU19w
#Site=
#Title=	BU19w-E-FF11-FI10-S2_150 (500nm)_633nm_Edge_100%_x100_VIS_H50um_60sX2
#Remark=
#Date=	04.11.2021 12:00
#Acquired=	04.11.2021 12:00:45
102.881	498.153
109.397	475.726
115.908	439.891
122.414	425.867
128.914	401.27
135.409	410.982
141.898	435.872
148.383	456.064
154.861	441.898
161.335	494.841
167.801	563.156
174.264	432.841
180.721	351.192
187.173	301.017
193.62	303.398
200.061	280.127
206.496	265.769
212.926	277.104
219.352	276.996
225.772	329.21
232.185	477.182
238.595	692.482
244.999	531.535
251.397	371.755
257.791	346.85
264.178	366.63
270.561	373.193
276.939	365.598
283.31	383.518
289.678	388.044
296.039	329.01
302.396	289.942
308.746	313.286
315.093	377.225
321.433	608.188
327.768	942.9
334.099	753.16
340.423	463.485
346.743	385.072
353.058	365.07
359.367	400.516
365.671	413.27
371.971	348.979
378.265	277.288
384.553	238.627
390.837	224.682
397.116	222.186
403.389	235.88
409.657	220.334
415.92	239.563
422.178	261.612
428.431	279.325
434.678	327.723
440.921	363.618
447.158	328.863
453.391	378.424
459.618	412.075
465.84	359.351
472.057	289.226
478.27	238.959
484.477	232.465
490.679	244.609
496.876	238.141
503.068	256.885
509.255	284.074
515.436	321.646
521.613	331.447
527.785	350.829
533.952	337.653
540.113	326.273
546.27	291.945
552.423	260.071
558.568	236.536
564.711	217.358
570.848	215.921
576.979	219.933
583.107	209.923
589.228	235.557
595.345	264.156
601.458	307.088
607.565	298.215
613.667	326.884
619.764	323.139
625.856	289.409
631.944	254.137
638.026	250.401
644.104	224.607
650.177	228.016
656.244	237.763
662.308	216.542
668.365	194.543
674.418	172.983
680.467	146.874
686.511	150.734
692.549	143.551
698.582	130.752
704.611	140.41
710.635	140.601
716.655	127.345
722.669	136.666
728.679	124.282
734.683	124.996
740.683	128.512
746.678	142.319
752.669	131.003
758.654	130.995
764.635	135.922
770.611	125.066
776.582	125.416
782.549	136.017
788.511	125.821
794.466	124.967
800.419	121.176
806.366	130.483
812.309	121.834
818.247	124.395
824.18	139.082
830.108	136.903
836.033	135.003
841.952	139.881
847.865	144.818
853.776	143.272
859.681	149.302
865.58	159.16
871.476	185.127
877.366	200.544
883.253	200.689
889.134	211.125
895.012	215.742
900.883	212.522
906.751	205.394
912.614	202.967
918.473	181.87
924.326	205.228
930.174	208.202
936.019	223.632
941.859	261.264
947.693	297.369
953.525	349
959.35	397.905
965.171	423.772
970.988	439.884
976.801	527.512
982.608	698.669
988.411	819.187
994.209	764.18
1000	602.645
1005.79	483.81
1011.58	481.048
1017.36	504.414
1023.13	533.807
1028.9	522.634
1034.67	414.542
1040.43	367.646
1046.19	340.764
1051.94	325.117
1057.69	300.45
1063.44	258.913
1069.17	249.108
1074.91	255.804
1080.64	286.62
1086.37	343.521
1092.09	419.832
1097.8	533.769
1103.52	591.55
1109.22	504.746
1114.93	392.352
1120.63	356.621
1126.32	327.183
1132.01	339.741
1137.7	348.424
1143.38	413.113
1149.06	496.381
1154.73	606.041
1160.4	554.551
1166.06	367.86
1171.72	252.461
1177.38	224.544
1183.03	191.952
1188.67	180.181
1194.31	158.801
1199.95	149.284
1205.58	130.119
1211.21	134.547
1216.84	118.298
1222.46	117.866
1228.07	119.431
1233.68	126.959
1239.29	108.255
1244.89	110.5
1250.49	110.605
1256.08	114.665
1261.67	111.514
1267.26	114.388
1272.84	111.163
1278.42	110.92
1283.99	111.692
1289.56	110.526
1295.12	99.4451
1300.68	110.427
1306.23	108.534
1311.78	110.8
1317.33	105.117
1322.87	102.463
1328.41	104.901
1333.94	111.411
1339.47	110.764
1345	101.818
1350.52	105.09
1356.04	109.355
1361.55	104.309
1367.06	100.203
1372.56	109.413
1378.06	111.428
1383.56	112.403
1389.05	109.271
1394.53	90.8173
1400.02	102.258
1405.5	100.348
1410.97	109.807
1416.44	103.844
1421.91	102.013
1427.37	100.196
1432.83	112.949
1438.28	104.885
1443.73	111.423
1449.17	100.123
1454.62	109.685
1460.05	104.482
1465.48	105.523
1470.91	105.492
1476.34	105.487
1481.76	102.381
1487.17	104.558
1492.59	101.534
1497.99	110.146
1503.4	110.379
1508.8	111.715
1514.19	102.479
1519.59	112.401
1524.97	113.86
1530.36	104.602
1535.74	120.068
1541.11	105.287
1546.48	114.105
1551.85	102.213
1557.21	118.29
1562.57	111.696
1567.93	114.815
1573.28	106.079
1578.62	107.105
1583.97	113.576
1589.3	119.008
1594.64	111.565
1599.97	109.557
1605.3	122.737
1610.62	119.806
1615.94	114.78
1621.25	119.592
1626.56	122.239
1631.87	116.087
1637.17	120.838
1642.47	120.992
1647.76	117.857
1653.05	121.315
1658.34	124.717
1663.62	105.904
1668.9	125.876
1674.18	135.86
1679.45	121.421
1684.71	115.795
1689.98	124.556
1695.23	122.316
1700.49	121.359
1705.74	115.282
1710.99	115.438
1716.23	113.252
1721.47	130.36
1726.7	115.999
1731.94	108.38
1737.16	126.6
1742.39	115.567
1747.61	120.29
1752.82	117.053
1758.03	122.812
1763.24	121.721
1768.44	116.116
1773.64	112.789
1778.84	101.561
1784.03	116.493
1789.22	117.863
1794.41	128.4
1799.59	125.295
1804.76	122.2
1809.94	117.892
1815.11	121.603
1820.27	119.555
1825.43	114.036
1830.59	124.75
1835.74	119.246
1840.89	125.318
1846.04	126.707
1851.18	126.913
1856.32	110.677
1861.45	123.784
1866.58	121.689
1871.71	118.373
1876.83	126.788
1881.95	126.94
1887.07	124.699
1892.18	122.363
1897.29	116.468
1902.39	116.59
1907.49	120.373
1912.59	114.765
1917.68	122.297
1922.77	129.601
1927.86	123.872
1932.94	119.312
1938.02	123.114
1943.09	131.696
1948.16	135.444
1953.23	129.502
1958.29	116.291
1963.35	139.211
1968.41	129.551
1973.46	135.502
1978.51	123.39
1983.55	126.93
1988.59	130.481
1993.63	128.035
1998.66	128.023
2003.69	130.453
2008.72	131.73
2013.74	129.43
2018.76	137.952
2023.77	138.064
2028.78	138.246
2033.79	137.286
2038.79	139.973
2043.79	142.687
2048.79	144.218
2053.78	124.966
2058.77	138.663
2063.76	135.3
2068.74	138.056
2073.72	127.281
2078.69	143.553
2083.66	141.336
2088.63	146.47
2093.59	146.73
2098.55	143.343
2103.51	154.891
2108.46	150.318
2113.41	158.273
2118.36	146.215
2123.3	145.401
2128.24	153.394
2133.17	149.999
2138.11	147.813
2143.03	150.68
2147.96	153.509
2152.88	149.896
2157.79	148.781
2162.71	148.89
2167.62	147.66
2172.52	160.535
2177.43	145.287
2182.32	154.269
2187.22	140.167
2192.11	146.62
2197	150.57
2201.89	152.046
2206.77	151.018
2211.64	153.906
2216.52	151.68
2221.39	150.771
2226.26	152.453
2231.12	139.833
2235.98	133.667
2240.84	145.768
2245.69	148.765
2250.54	158.341
2255.39	152.143
2260.23	143.295
2265.07	151.56
2269.9	158.464
2274.74	158.686
2279.57	142.905
2284.39	142.985
2289.21	148.344
2294.03	145.716
2298.84	145.796
2303.66	152.604
2308.46	151.517
2313.27	157.182
2318.07	152.206
2322.87	152.587
2327.66	150.303
2332.45	149.385
2337.24	156.629
2342.02	155.778
2346.8	156.344
2351.58	151.409
2356.35	150.494
2361.12	161.855
2365.89	148.398
2370.65	157.016
2375.41	150.399
2380.17	152.056
2384.92	145.285
2389.67	148.183
2394.42	169.114
2399.16	157.977
2403.9	157.962
2408.64	149.624
2413.37	163.828
2418.1	163.211
2422.83	152.494
2427.55	154.15
2432.27	163.019
2436.99	150.766
2441.7	166.837
2446.41	158.79
2451.11	159.27
2455.82	164.029
2460.51	165.944
2465.21	166.421
2469.9	155.309
2474.59	161.496
2479.28	160.472
2483.96	162.318
2488.64	153.905
2493.32	167.371
2497.99	172.116
2502.66	153.363
2507.32	172.734
2511.99	156.789
2516.65	167.303
2521.3	170.515
2525.96	170.779
2530.61	159.192
2535.25	162.446
2539.89	176.147
2544.53	178.001
2549.17	170.934
2553.8	162.332
2558.43	168.625
2563.06	158.473
2567.68	172.419
2572.3	169.854
2576.92	177.842
2581.53	173.658
2586.14	175.418
2590.75	172.521
2595.35	174.244
2599.96	189.765
2604.55	176.271
2609.15	188.696
2613.74	173.548
2618.33	181.35
2622.91	181.511
2627.49	178.648
2632.07	200.484
2636.64	187.133
2641.22	181.542
2645.78	186.789
2650.35	188.921
2654.91	195.669
2659.47	183.52
2664.03	182.221
2668.58	188.742
2673.13	196.984
2677.67	199.28
2682.22	184.439
2686.76	193.231
2691.29	194.038
2695.83	183.335
2700.36	194.952
2704.89	204.991
2709.41	198.924
2713.93	196.05
2718.45	181.926
2722.96	196.847
2727.47	195.494
2731.98	195.674
2736.49	184.458
2740.99	197.625
2745.49	215.795
2749.98	175.389
2754.47	195.549
2758.96	195.921
2763.45	194.576
2767.93	209.777
2772.41	187.091
2776.89	177.641
2781.36	199.734
2785.84	202.072
2790.3	196.063
2794.77	186.628
2799.23	187.125
2803.69	204.384
2808.14	194.683
2812.59	201.794
2817.04	191.945
2821.49	197.326
2825.93	192.572
2830.37	187.778
2834.81	191.449
2839.24	184.904
2843.67	193.713
2848.1	192.35
2852.53	182.474
2856.95	186.367
2861.37	204.067
2865.78	189.14
2870.19	186.267
2874.6	190.317
2879.01	213.599
2883.41	198.596
2887.81	216.869
2892.21	201.743
2896.6	198.912
2901	196.102
2905.38	193.157
2909.77	199.084
2914.15	194.174
2918.53	198.204
2922.91	200.497
2927.28	197.454
2931.65	190.806
2936.02	200.348
2940.38	209.82
2944.74	206.563
2949.1	210.492
2953.46	214.451
2957.81	201.957
2962.16	183.951
2966.5	202.587
2970.85	213.975
2975.19	201.497
2979.52	205.562
2983.86	209.71
2988.19	226.916
2992.52	231.264
2996.85	217.026
3001.17	227.056
3005.49	227.825
3009.8	228.584
3014.12	225.525
3018.43	222.545
3022.74	229.034
3027.04	227.801
3031.34	234.111
3035.64	230.766
3039.94	231.217
3044.23	239.361
3048.52	243.63
3052.81	249.829
3057.09	258.02
3061.38	254.603
3065.65	255.052
3069.93	263.27
3074.2	279.311
3078.47	250.583
3082.74	295.981
3087	279.027
3091.27	279.79
3095.52	292.491
3099.78	283.564
3104.03	306.361
3108.28	301.539
3112.53	300.737
3116.77	297.899
3121.01	325.294
3125.25	342.888
3129.49	322.119
3133.72	327.789
3137.95	331.412
3142.18	337.004
3146.4	344.585
3150.62	352.112
3154.84	342.779
3159.06	364.686
3163.27	342.718
3167.48	354.154
3171.69	355.125
3175.89	370.745
3180.09	371.376
3184.29	369.769
3188.49	389.237
3192.68	391.946
3196.87	399.106
3201.06	370.499
3205.24	376.109
3209.42	373.313
3213.6	402.943
3217.78	391.671
3221.95	380.165
3226.12	368.574
3230.29	385.386
3234.45	375.809
3238.61	352.833
3242.77	329.834
3246.93	357.99
3251.08	361.443
3255.23	351.162
3259.38	334.119
3263.53	346.554
3267.67	343.789
3271.81	352.027
3275.95	325.529
3280.08	326.202
3284.21	338.336
3288.34	322.921
3292.47	330.43
3296.59	324.084
3300.71	313.188
3304.83	336.956
3308.95	339.929
3313.06	314.945
3317.17	329.498
3321.27	320.852
3325.38	321.641
3329.48	317.809
3333.58	335.409
3337.67	327.147
3341.77	332.724
3345.86	293.068
3349.95	333.974
3354.03	327.408
3358.11	337.686
3362.19	314.537
3366.27	341.57
3370.34	323.086
3374.42	326.087
3378.48	343.442
3382.55	346.324
3386.61	354.009
3390.68	332.63
3394.73	342.704
3398.79	335.938
3402.84	329.045
3406.89	314.774
3410.94	310.173
3414.98	344.5
3419.03	352.086
3423.06	354.766
3427.1	340.421
3431.14	326.158
3435.17	324.174
3439.2	324.728
3443.22	317.972
3447.25	313.817
3451.27	336.808
3455.28	327.881
3459.3	321.543
3463.31	327.658
3467.32	333.819
3471.33	304.831
3475.34	293.06
3479.34	309.092
3483.34	302.413
3487.33	277.892
3491.33	306.644
3495.32	315.066
3499.31	292.747
3503.3	288.16
3507.28	309.121
3511.26	296.539
3515.24	301.868
3519.22	271.197
3523.19	273.924
3527.16	276.711
3531.13	294.937
3535.1	254.162
3539.06	288.38
3543.02	276.003
3546.98	276.463
3550.93	227.428
3554.89	263.917
3558.84	264.195
3562.78	267.163
3566.73	267.63
3570.67	278.689
3574.61	289.776
3578.55	256.335
3582.48	286.082
3586.41	279.004
3590.35	266.558
3594.27	275.312
3598.2	246.754
3602.12	250.056
3606.04	253.341
3609.95	251.19
3613.87	230.182
3617.78	217.136
3621.69	225.555
3625.6	223.013
3629.5	233.968
3633.4	204.285
3637.3	204.442
3641.2	221.015
3645.09	210.578
3648.98	197.28
3652.87	208.387
3656.76	200.4
3660.64	225.132
3664.53	208.917
3668.4	203.669
3672.28	195.656
3676.16	193.206
3680.03	207.307
3683.9	213.306
3687.76	194.579
3691.63	186.83
3695.49	184.525
3699.35	207.283
3703.2	177.133
3707.06	186.018
3710.91	194.947
3714.76	189.827
3718.6	181.789
3722.45	179.328
3726.29	205.106
3730.13	188.46
3733.97	177.465
3737.8	192.023
3741.63	189.498
3745.46	186.944
3749.29	201.487
3753.11	181.672
3756.93	196.126
3760.75	190.501
3764.57	193.452
3768.39	193.559
3772.2	190.852
3776.01	196.762
3779.81	188.352
3783.62	185.749
3787.42	191.801
3791.22	183.396
3795.02	192.388
3798.81	181.176
3802.61	196.081
3806.4	193.616
3810.18	179.465
3813.97	200.302
3817.75	174.331
3821.53	189.336
3825.31	174.941
3829.09	166.395
3832.86	190.318
3836.63	193.612
3840.4	176.156
3844.17	164.631
3847.93	194.457
3851.69	161.913
3855.45	185.766
3859.21	188.751
3862.96	188.815
3866.71	183.181
3870.46	180.627
3874.21	189.685
3877.95	162.902
3881.69	207.875
3885.44	175.119
3889.17	193.273
3892.91	172.518
3896.64	181.851
3900.37	161.059
3904.1	191.444
3907.82	197.75
3911.55	176.898
3915.27	177.207
3918.99	177.579
3922.7	184.102
3926.42	178.421
3930.13	184.905
3933.84	194.397
3937.54	154.82
3941.25	167.375
3944.95	176.951
3948.65	168.031
3952.35	171.372
3956.04	177.782
3959.73	187.24
3963.42	168.802
3967.11	181.285
3970.8	168.928
3974.48	156.585
3978.16	159.729
3981.84	175.228
3985.52	175.217
3989.19	175.209
3992.86	169.064
3996.53	153.663
3998.37	163.054