File: Data/3-Raman/raw/bu19w-ff07a-fi06-v_150 (500nm)_532nm_edge_100%_x100_vis_lwd_h50um_30sx2_01.txt
#Acq. time (s)=	30
#Accumulations=	2
#Range (cm-¹)=	50...5000
#Windows=	1
#Auto scanning=	Off
#Autofocus=	Off
#Macrospot=	Off
#AutoExposure=	Off
#Spike filter=	Multiple accum.
#Delay time (s)=	2
#Binning=	1
#Readout mode=	Signal
#DeNoise=	Off
#ICS correction=	On
#Dark correction=	Off
#Inst. Process=	Off
#Detector Gain=	Best Dynamic
#Detector ADC=	50 kHz HS
#Detector temperature (°C)=	-60.09
#Instrument=	LabRAM HR Evol
#Detector=	SIN-EM FIVIS
#Objective=	x100_VIS_LWD
#Grating=	150 (500nm)
#ND Filter=	100%
#Laser=	532nm_Edge
#Hole=	49.98
#Temperature=	0
#Range=	Visible
#StageXY=	75x50mm Scan+
#StageZ=	Z motor
#X (µm)=	0
#Y (µm)=	0
#Z (µm)=	-21.4
#Full time(mm:ss)=	1:04
#Project=	21_05_28
#Sample=	BU19w
#Site=
#Title=	BU19w-FF07a-FI06-V_150 (500nm)_532nm_Edge_100%_x100_VIS_LWD_H50um_30sX2
#Remark=
#Date=	28.05.2021 19:32
#Acquired=	28.05.2021 19:32:09
51.5961	48545.9
56.2453	39067.9
60.8921	27264.1
65.5367	17355.8
70.1768	12181.8
74.8167	9616.1
79.4543	7908.64
84.0897	6633.71
88.7227	5664.72
93.3513	4988.41
97.9798	4469.64
102.606	4245.86
107.23	3741.02
111.851	3365.38
116.469	3140.35
121.086	2997.35
125.7	2837.6
130.313	2743.84
134.921	2615.44
139.529	2428.61
144.134	2360.65
148.738	2689.6
153.337	3784.92
157.936	4351.78
162.532	3368.65
167.126	2493.64
171.716	2479.01
176.306	3413.06
180.894	6117.38
185.477	7887.01
190.06	5525.97
194.64	3099.1
199.219	2160.91
203.793	1959.03
208.367	1936.86
212.939	1907.38
217.506	1864.47
222.073	1902.28
226.638	2235.78
231.199	2619.92
235.759	2974.18
240.318	3965.05
244.872	4260.9
249.425	3432.01
253.977	2857.63
258.524	2530.09
263.071	2634.71
267.616	4048.38
272.156	6893.81
276.697	8672.78
281.233	6463.79
285.769	4000.09
290.303	3249.92
294.832	3828.12
299.361	4625.93
303.886	4135.74
308.411	3067.69
312.934	2600.87
317.452	2778.22
321.97	3519.03
326.484	4061.85
330.998	3501.06
335.507	2759.25
340.017	2908.31
344.524	3356.91
349.027	3417.27
353.53	2805.98
358.028	2272.29
362.527	2200.94
367.021	2355.2
371.515	2162.1
376.004	2142.99
380.494	2445.47
384.979	2854.5
389.465	3093.98
393.946	2943.99
398.427	2517.09
402.903	2157.18
407.38	2196.18
411.852	2512.67
416.324	2460.41
420.792	2049.7
425.26	1734.85
429.723	1697.13
434.187	1604.74
438.646	1652.7
443.105	1992.27
447.56	2600.46
452.015	3217.24
456.466	2944.41
460.914	2237.29
465.362	1889.4
469.807	1815.66
474.251	1852.94
478.69	1995.19
483.13	2205.96
487.566	2442.21
491.999	2653
496.432	2636.17
500.861	2428.96
505.29	2148.56
509.715	1925.92
514.138	1855.99
518.56	1809.2
522.979	1771.14
527.395	1785.54
531.811	1853.54
536.223	1871.08
540.635	1885.23
545.042	1996.67
549.448	1950.6
553.853	2015.63
558.255	2035.4
562.654	1981.89
567.053	1887.79
571.448	1820.48
575.841	2048.96
580.232	2665.51
584.622	3826.2
589.009	4041.3
593.393	3085.28
597.777	2517.66
602.157	2719.88
606.535	3036.94
610.913	3176.64
615.287	2681.08
619.659	2083.24
624.029	1861.57
628.398	1792.63
632.763	1943.03
637.127	2057.36
641.488	2046.92
645.849	1947.75
650.206	1963.32
654.561	2138.89
658.914	2409.57
663.267	2652.02
667.615	2735.97
671.962	2870.95
676.307	2864.45
680.649	2438.77
684.991	2074.62
689.33	1795.3
693.666	1651.98
698	1595.77
702.332	1517.79
706.662	1475.04
710.992	1529.56
715.318	1526.68
719.641	1506.68
723.963	1519.74
728.283	1542.46
732.6	1566.8
736.918	1556.39
741.231	1637.99
745.542	1622.67
749.852	1731.17
754.159	1846.31
758.464	2018.26
762.767	2331.59
767.068	2917.54
771.369	3846.08
775.666	4530.48
779.961	4026.73
784.254	3020.24
788.545	2343.4
792.834	2039.62
797.12	1824.65
801.405	1761.93
805.688	1720.45
809.968	1644.45
814.247	1627.01
818.524	1606.53
822.798	1573.93
827.071	1501.01
831.341	1517.37
835.612	1565.74
839.878	1554.49
844.142	1527.6
848.405	1545.36
852.665	1545.66
856.923	1572.42
861.18	1544.02
865.434	1556.1
869.686	1548.95
873.936	1552.45
878.185	1545.67
882.431	1509
886.675	1550.47
890.915	1468.82
895.155	1570.58
899.393	1561.89
903.63	1541.42
907.864	1529.63
912.096	1580.97
916.326	1596.35
920.554	1617.83
924.78	1642.91
929.004	1613.22
933.227	1708.02
937.447	1815.28
941.665	1985.97
945.881	2191.13
950.095	2219.41
954.305	2167.21
958.516	2145.19
962.724	2213.87
966.93	2255.03
971.134	2072.54
975.337	1901.38
979.537	1815.46
983.735	1752.22
987.93	1749.34
992.124	1726.51
996.316	1734.59
1000.51	1722.59
1004.7	1725.78
1008.88	1779.18
1013.06	1721.05
1017.25	1775.23
1021.43	1899.89
1025.61	1930.44
1029.78	2022.27
1033.96	2197.87
1038.13	2519.44
1042.3	3251.22
1046.47	4614.92
1050.63	5403.18
1054.8	4822.76
1058.96	3670.26
1063.12	3030.79
1067.28	2685.32
1071.44	2699.08
1075.59	3023.92
1079.74	3779.87
1083.89	4796.36
1088.04	5564.23
1092.19	5350.65
1096.33	4607.54
1100.48	4407.62
1104.62	4914.26
1108.76	5062.28
1112.89	4761.29
1117.03	4313.44
1121.16	4198.25
1125.29	4384.06
1129.42	4544.45
1133.55	4211.12
1137.68	3633.36
1141.8	3155.22
1145.92	3130.93
1150.04	3514.74
1154.16	4067.53
1158.27	3998.18
1162.39	3562.45
1166.5	3047.08
1170.61	2640.52
1174.72	2382.96
1178.82	2147.01
1182.93	2130.59
1187.03	2077.56
1191.13	2123
1195.23	2137.92
1199.33	2125.51
1203.42	2048.44
1207.51	2014.27
1211.6	2004.66
1215.69	2231.54
1219.78	2441.32
1223.86	2434.34
1227.95	2370.78
1232.03	2448.47
1236.11	2704.81
1240.18	2810.4
1244.26	2580.74
1248.33	2562.96
1252.41	2313.91
1256.48	2170.11
1260.54	2078.49
1264.61	2701.26
1268.67	5482.34
1272.74	5240.92
1276.8	2643.73
1280.86	2015.72
1284.91	1934.11
1288.97	1938.56
1293.02	1871.29
1297.07	1901.37
1301.12	1862.77
1305.17	1817.74
1309.21	1863.29
1313.25	1857.22
1317.3	1852.5
1321.34	1857.45
1325.37	1845.59
1329.41	1870.71
1333.44	1830.31
1337.48	1890.63
1341.5	1833.37
1345.53	1938.89
1349.56	1938.32
1353.59	2029.33
1357.61	2047.6
1361.63	2034.9
1365.65	2231.45
1369.66	4425.05
1373.68	8757.46
1377.69	5541.48
1381.7	2494.58
1385.72	2037.54
1389.72	2104.89
1393.73	2351.94
1397.73	2321.42
1401.74	1945.93
1405.74	1869.67
1409.73	1830.01
1413.73	1831.92
1417.73	1802.28
1421.72	1820.96
1425.71	1796.95
1429.7	1809.54
1433.69	1782.79
1437.67	1757.98
1441.66	1785.52
1445.64	1780.21
1449.62	1778.74
1453.6	1733.56
1457.57	1751.34
1461.55	1800.31
1465.52	1741.35
1469.49	1727.63
1473.46	1743.64
1477.43	1777.03
1481.39	1785.62
1485.36	1740.25
1489.32	1776.96
1493.28	1774.66
1497.24	1750
1501.19	1797.62
1505.15	1786.13
1509.1	1761.55
1513.05	1705.08
1517	1811.85
1520.95	1770.26
1524.9	1762.77
1528.84	1797.12
1532.78	1752.19
1536.72	1755.78
1540.66	1763.3
1544.6	1760.16
1548.53	1778.35
1552.46	1771.35
1556.4	1795.13
1560.32	1812.8
1564.25	1809.94
1568.18	1789.49
1572.1	1800.83
1576.02	1815.01
1579.94	1787.61
1583.86	1847.94
1587.78	1788.57
1591.69	1844.77
1595.61	1814.27
1599.52	1834.77
1603.43	1800.65
1607.34	1827.31
1611.24	1822.34
1615.15	1825.18
1619.05	1821.57
1622.95	1863.8
1626.85	1833.56
1630.74	1852.38
1634.64	1851.7
1638.53	1849
1642.42	1827.65
1646.31	1821.99
1650.2	1848.14
1654.09	1840.84
1657.97	1842.98
1661.86	1850.8
1665.74	1867.88
1669.62	1819.39
1673.49	1846.27
1677.37	1874.95
1681.24	1874.74
1685.12	1838.54
1688.99	1905.8
1692.86	1858.55
1696.72	1831.24
1700.59	1839.98
1704.45	1846.4
1708.31	1875.24
1712.17	1819.05
1716.03	1888.2
1719.89	1885.27
1723.74	1900.33
1727.6	1914.22
1731.45	1866.66
1735.3	1897.28
1739.14	1877.97
1742.99	1897.7
1746.83	1871.83
1750.68	1855.58
1754.52	1904.09
1758.36	1890.52
1762.19	1880.11
1766.03	1843.25
1769.86	1844.23
1773.69	1901.91
1777.53	1901.11
1781.35	1875.8
1785.18	1907.68
1789	1867.86
1792.83	1866.4
1796.65	1945.68
1800.47	1899.18
1804.29	1902.14
1808.1	1867.27
1811.92	1910.36
1815.73	1862.62
1819.54	1854.58
1823.35	1900.78
1827.16	1920.21
1830.97	1905.14
1834.77	1946.13
1838.58	1946.24
1842.38	1925.36
1846.18	1962.3
1849.97	1923.42
1853.77	1927.75
1857.56	1965.22
1861.36	1922.63
1865.15	1958.18
1868.93	1944.56
1872.72	1969.19
1876.51	1961.77
1880.29	1969.29
1884.07	1938.91
1887.86	1932.62
1891.63	1921.22
1895.41	1966.91
1899.19	1943.6
1902.96	1936.77
1906.73	1967.15
1910.5	1971.96
1914.27	1947.09
1918.04	1972.14
1921.8	1936.59
1925.57	1935.37
1929.33	1977.18
1933.09	1971.9
1936.85	1995.44
1940.6	1949.91
1944.36	2003.3
1948.11	1962.22
1951.87	1999.22
1955.61	1986.63
1959.36	1983.33
1963.11	2002.85
1966.86	1993.13
1970.6	2039.1
1974.34	2012.04
1978.08	2008.98
1981.82	2043.94
1985.56	1999.96
1989.29	2044.51
1993.02	2028.03
1996.75	2075.36
2000.49	2007.98
2004.21	2047.45
2007.94	2040.33
2011.67	2081.59
2015.39	1993.08
2019.11	2087.64
2022.83	2064.76
2026.55	2050.53
2030.27	2021.74
2033.98	2013.19
2037.69	2033.72
2041.41	2072.37
2045.12	2042.2
2048.82	2007.49
2052.53	2043.69
2056.24	2071.79
2059.94	2092.74
2063.64	2029.66
2067.34	2081.84
2071.04	2091.98
2074.74	2034.81
2078.43	2095.95
2082.13	2059.26
2085.82	2101.05
2089.51	2067.98
2093.2	2089.69
2096.88	2130.09
2100.57	2118.99
2104.25	2104.37
2107.94	2126.58
2111.62	2167.98
2115.3	2094.02
2118.97	2097.89
2122.65	2164.06
2126.32	2128.53
2129.99	2140.92
2133.66	2143.82
2137.33	2136.4
2141	2170.16
2144.67	2122.4
2148.33	2183.19
2151.99	2144.56
2155.66	2186.81
2159.31	2151.22
2162.97	2182.71
2166.63	2214.46
2170.28	2180.89
2173.94	2208.42
2177.59	2164.47
2181.24	2176.38
2184.89	2220.01
2188.53	2230.57
2192.18	2163.76
2195.82	2201.56
2199.46	2174.32
2203.1	2219.31
2206.74	2191.72
2210.38	2212.88
2214.01	2244.48
2217.65	2202.03
2221.28	2206.33
2224.91	2218.12
2228.54	2227.02
2232.16	2257.23
2235.79	2247.07
2239.41	2264.57
2243.04	2292.27
2246.66	2252.17
2250.28	2215.78
2253.89	2266.15
2257.51	2209.57
2261.12	2211.64
2264.74	2235.92
2268.35	2253.01
2271.96	2273.49
2275.57	2264.23
2279.17	2284.48
2282.78	2293.81
2286.38	2250.23
2289.98	2277.43
2293.58	2233.42
2297.18	2295.42
2300.78	2246.78
2304.37	2284.87
2307.97	2288.38
2311.56	2403.42
2315.15	2850.82
2318.74	2793.45
2322.33	2409.58
2325.91	2276.52
2329.5	2294.78
2333.08	2306.08
2336.66	2321.76
2340.24	2294.72
2343.82	2336.13
2347.4	2302.97
2350.97	2334.39
2354.54	2330.98
2358.12	2333.03
2361.69	2330.26
2365.26	2325.61
2368.82	2338.74
2372.39	2295.92
2375.95	2362.13
2379.52	2350.67
2383.08	2326.63
2386.64	2315.78
2390.19	2357.72
2393.75	2397.27
2397.31	2335.7
2400.86	2357.48
2404.41	2298.99
2407.96	2372.76
2411.51	2377.89
2415.06	2367.08
2418.6	2341.2
2422.15	2325.74
2425.69	2354.11
2429.23	2340.7
2432.77	2368.4
2436.31	2311.46
2439.84	2308.38
2443.38	2314.77
2446.91	2365.12
2450.44	2346.95
2453.97	2380.71
2457.5	2377.31
2461.03	2414.2
2464.55	2425.5
2468.08	2370.61
2471.6	2355.36
2475.12	2354.09
2478.64	2375.09
2482.16	2404.95
2485.67	2393.35
2489.19	2372.78
2492.7	2396.76
2496.21	2445.6
2499.72	2433.33
2503.23	2409.99
2506.74	2456.36
2510.25	2420.92
2513.75	2433.23
2517.25	2468.39
2520.75	2452.85
2524.25	2472.69
2527.75	2401.55
2531.25	2431.87
2534.74	2433.87
2538.24	2443.05
2541.73	2407.6
2545.22	2401.91
2548.71	2511.77
2552.2	2432.44
2555.68	2388.78
2559.17	2424.95
2562.65	2405.58
2566.13	2406.73
2569.61	2406.78
2573.09	2408.38
2576.57	2449.82
2580.04	2444.95
2583.51	2419.45
2586.99	2441.07
2590.46	2510.56
2593.93	2424.1
2597.4	2476.92
2600.86	2468.61
2604.33	2465.78
2607.79	2478.75
2611.25	2490.62
2614.71	2463.34
2618.17	2505.17
2621.63	2498.89
2625.09	2481.54
2628.54	2478.89
2631.99	2475.83
2635.45	2491.35
2638.9	2491.72
2642.34	2542.37
2645.79	2523.55
2649.24	2514.15
2652.68	2492.76
2656.12	2499.33
2659.56	2517.69
2663.01	2565.04
2666.44	2535.39
2669.88	2512.42
2673.32	2567.46
2676.75	2540.1
2680.18	2483.28
2683.61	2555.26
2687.04	2493.54
2690.47	2541.73
2693.9	2464.03
2697.32	2465.98
2700.75	2518.74
2704.17	2532.48
2707.59	2505.39
2711.01	2487.51
2714.43	2456.18
2717.84	2475.59
2721.26	2451.7
2724.67	2526.98
2728.08	2473.73
2731.49	2463.52
2734.9	2539.27
2738.31	2497.1
2741.71	2552.29
2745.12	2497.22
2748.52	2477.41
2751.92	2481.11
2755.32	2519.41
2758.72	2516.99
2762.12	2521.2
2765.52	2520.98
2768.91	2501.51
2772.3	2529.68
2775.7	2464.35
2779.09	2530.48
2782.47	2497.35
2785.86	2536.52
2789.25	2532.3
2792.63	2517.65
2796.01	2524.53
2799.4	2516.39
2802.78	2536.92
2806.15	2539.65
2809.53	2537.62
2812.91	2540.13
2816.28	2549.96
2819.65	2494.34
2823.03	2569.87
2826.4	2524.39
2829.76	2523.9
2833.13	2523.76
2836.5	2513.84
2839.86	2533.23
2843.22	2526.1
2846.59	2480.43
2849.95	2491.57
2853.3	2503.31
2856.66	2532.52
2860.02	2536.87
2863.37	2530.31
2866.72	2521.02
2870.08	2491.08
2873.43	2517.27
2876.77	2505.82
2880.12	2511.22
2883.47	2507.11
2886.81	2471.67
2890.15	2515.4
2893.5	2556.22
2896.84	2560.55
2900.17	2568.3
2903.51	2565.25
2906.85	2577.01
2910.18	2553.54
2913.52	2567.72
2916.85	2538.2
2920.18	2576.42
2923.51	2602.18
2926.83	2565.29
2930.16	2558.3
2933.48	2588.78
2936.81	2618.83
2940.13	2636.58
2943.45	2592.13
2946.77	2566.65
2950.09	2573.28
2953.4	2564.76
2956.72	2617.39
2960.03	2592.47
2963.34	2561.23
2966.65	2560.19
2969.96	2519.61
2973.27	2547.94
2976.58	2567.94
2979.88	2558.34
2983.19	2516.53
2986.49	2576.23
2989.79	2550.68
2993.09	2502.65
2996.39	2526.13
2999.68	2545.07
3002.98	2532.02
3006.27	2484.15
3009.57	2470.33
3012.86	2487.7
3016.15	2533.41
3019.43	2508.39
3022.72	2521.04
3026.01	2529.93
3029.29	2523.77
3032.57	2503.37
3035.86	2512.13
3039.14	2502.86
3042.41	2506.84
3045.69	2531.7
3048.97	2479.9
3052.24	2552.17
3055.52	2563.9
3058.79	2565.11
3062.06	2508.57
3065.33	2577.64
3068.6	2535.39
3071.86	2554.26
3075.13	2531.08
3078.39	2566.42
3081.65	2522.25
3084.91	2545.67
3088.17	2528.18
3091.43	2566.45
3094.69	2552.65
3097.95	2569.81
3101.2	2542.97
3104.45	2526.1
3107.7	2535.14
3110.95	2585.7
3114.2	2598.34
3117.45	2612.15
3120.7	2567.01
3123.94	2589.46
3127.18	2601.41
3130.43	2621.85
3133.67	2589.93
3136.91	2660.86
3140.14	2622.99
3143.38	2648.95
3146.61	2611.05
3149.85	2613.36
3153.08	2666.28
3156.31	2675.22
3159.54	2651.79
3162.77	2651.17
3166	2663.92
3169.22	2656.38
3172.45	2713.54
3175.67	2636.99
3178.89	2746.27
3182.11	2685.69
3185.33	2725.33
3188.55	2712.19
3191.77	2718.05
3194.98	2785.84
3198.2	2780.19
3201.41	2771.63
3204.62	2807.94
3207.83	2830.05
3211.04	2764.74
3214.25	2787.17
3217.45	2805.03
3220.66	2788.65
3223.86	2818.98
3227.06	2795.36
3230.26	2793.69
3233.46	2820.78
3236.66	2871.47
3239.85	2828.58
3243.05	2815.34
3246.24	2809.85
3249.44	2773.87
3252.63	2853.51
3255.82	2835.04
3259.01	2828.9
3262.19	2858.64
3265.38	2878.44
3268.56	2863.44
3271.75	2791.8
3274.93	2804.06
3278.11	2831.55
3281.29	2862.26
3284.47	2860.93
3287.64	2888.29
3290.82	2871.51
3293.99	2872.14
3297.17	2926.95
3300.34	2899.88
3303.51	2825.89
3306.68	2918.68
3309.84	2951.18
3313.01	2856.8
3316.18	2921.9
3319.34	2953.63
3322.5	2939.69
3325.66	2937.16
3328.82	2960.21
3331.98	2910.5
3335.14	2995.22
3338.29	2996.05
3341.45	2979.17
3344.6	2937.87
3347.75	2993.5
3350.9	2996.1
3354.05	2901.58
3357.2	2996.86
3360.35	2946.19
3363.49	2990.15
3366.64	2990.82
3369.78	3027.49
3372.92	3036.01
3376.06	3040.17
3379.2	3087.92
3382.34	3110.35
3385.48	3216.8
3388.61	3199.71
3391.75	3199.69
3394.88	3231.71
3398.01	3325.46
3401.14	3494.17
3404.27	3766.93
3407.4	4130.81
3410.52	5046.31
3413.65	7535.3
3416.77	13539.9
3419.89	19472.9
3423.01	16231.2
3426.13	9292.54
3429.25	5686.99
3432.37	4288.82
3435.49	3810.12
3438.6	3552.18
3441.72	3392.15
3444.83	3274.08
3447.94	3240.29
3451.05	3225.51
3454.16	3226.47
3457.26	3183.55
3460.37	3163.07
3463.47	3155.87
3466.58	3123.81
3469.68	3185.29
3472.78	3283.99
3475.88	3387.3
3478.98	3489.67
3482.07	3662.02
3485.17	3855.95
3488.26	4223.65
3491.36	4769.03
3494.45	5398.36
3497.54	6363.07
3500.63	7218.33
3503.72	7351.94
3506.81	6714.3
3509.89	5647.65
3512.98	4804.59
3516.06	4185.61
3519.14	3759.38
3522.22	3459.68
3525.3	3274.99
3528.38	3120.28
3531.45	3023.4
3534.53	2899.36
3537.61	2840.02
3540.68	2801.75
3543.75	2716.52
3546.82	2757.34
3549.89	2663.14
3552.96	2629.6
3556.03	2655.38
3559.09	2611.61
3562.16	2617.04
3565.22	2571.71
3568.28	2512.69
3571.34	2496.15
3574.4	2525.8
3577.46	2519.54
3580.52	2480.82
3583.57	2458.01
3586.63	2435.93
3589.68	2414.79
3592.73	2413.25
3595.78	2370.9
3598.83	2421.2
3601.88	2402.33
3604.93	2366.18
3607.97	2371.51
3611.02	2370.19
3614.06	2320.55
3617.1	2312.44
3620.14	2297.83
3623.18	2258.82
3626.22	2261.4
3629.26	2246.22
3632.3	2243.17
3635.33	2215.52
3638.36	2205.4
3641.4	2241.68
3644.43	2198.24
3647.46	2215.59
3650.49	2147.64
3653.51	2143.03
3656.54	2130.07
3659.57	2112.42
3662.59	2062.52
3665.61	2096.95
3668.63	2087.08
3671.65	2067.33
3674.67	2064.64
3677.69	2024.31
3680.71	2092.68
3683.72	2113.75
3686.74	2065.83
3689.75	2002.79
3692.76	1991.8
3695.77	2035.77
3698.78	2019.67
3701.79	2002.09
3704.79	1972.14
3707.8	2063.72
3710.81	2005
3713.81	1990.75
3716.81	1972.43
3719.81	2008.48
3722.81	1965.3
3725.81	1980.96
3728.81	1941.21
3731.8	1960.36
3734.8	2009.79
3737.79	2018.99
3740.78	1960.43
3743.77	1999.67
3746.76	2034.9
3749.75	1923.51
3752.74	1995.45
3755.73	1995.12
3758.71	1954.04
3761.7	1964.16
3764.68	1941.88
3767.66	1942.41
3770.64	1975.25
3773.62	1912.73
3776.6	1995.04
3779.58	1960.23
3782.55	1923.68
3785.53	1928.74
3788.5	1910.3
3791.47	1883.49
3794.44	1913.63
3797.41	1917.49
3800.38	1892.2
3803.35	1904.93
3806.32	1922.49
3809.28	1932.56
3812.24	1901.17
3815.21	1907.63
3818.17	1888.59
3821.13	1925.46
3824.09	1926.43
3827.04	1883.02
3830	1948.59
3832.96	1935.5
3835.91	1912.14
3838.86	1922.09
3841.82	1913.99
3844.77	1874.48
3847.72	1911.1
3850.67	1850.69
3853.61	1891.36
3856.56	1835.74
3859.5	1869.85
3862.45	1905.94
3865.39	1899.88
3868.33	1904.33
3871.27	1869.35
3874.21	1911.94
3877.15	1888.28
3880.09	1923.92
3883.02	1888.29
3885.96	1888.93
3888.89	1873.08
3891.82	1835.99
3894.75	1822.84
3897.68	1897.92
3900.61	1891.05
3903.54	1838.93
3906.47	1844.28
3909.39	1892.14
3912.31	1865.8
3915.24	1819.12
3918.16	1839.59
3921.08	1870.92
3924	1862.52
3926.92	1886.52
3929.83	1837.46
3932.75	1830.53
3935.67	1853.73
3938.58	1844.76
3941.49	1831.33
3944.4	1868.47
3947.31	1842.52
3950.22	1805.27
3953.13	1839.01
3956.04	1809.62
3958.94	1792.84
3961.85	1813.51
3964.75	1796.89
3967.65	1835.03
3970.55	1803.25
3973.45	1830.06
3976.35	1781.93
3979.25	1796.09
3982.15	1806.3
3985.04	1797.26
3987.94	1799.65
3990.83	1818.34
3993.72	1822.39
3996.61	1824.86
3999.5	1779.17
4002.39	1831.75
4005.28	1810.24
4008.16	1809.99
4011.05	1785.67
4013.93	1751.67
4016.81	1762.02
4019.7	1795.55
4022.58	1757.64
4025.46	1790.22
4028.33	1740.74
4031.21	1764.69
4034.09	1766.46
4036.96	1745.04
4039.84	1757.55
4042.71	1764.21
4045.58	1750.23
4048.45	1755.72
4051.32	1778.75
4054.19	1722.36
4057.05	1717.52
4059.92	1722.32
4062.78	1725.12
4065.65	1738.61
4068.51	1746.28
4071.37	1758.79
4074.23	1756.7
4077.09	1733.14
4079.95	1744.62
4082.81	1721.98
4085.66	1720.8
4088.52	1739.03
4091.37	1737.76
4094.22	1720.01
4097.07	1695.27
4099.92	1730.22
4102.77	1726.05
4105.62	1696.39
4108.47	1653.79
4111.31	1713.93
4114.16	1714.19
4117	1712.32
4119.84	1704.33
4122.69	1668.97
4125.53	1704.27
4128.36	1675.03
4131.2	1679.52
4134.04	1688.17
4136.88	1684.63
4139.71	1690.7
4142.54	1687.44
4145.38	1703.94
4148.21	1666.33
4151.04	1642.53
4153.87	1691.78
4156.69	1673.84
4159.52	1693.36
4162.35	1655.76
4165.17	1687.85
4168	1646.55
4170.82	1640.54
4173.64	1664.94
4176.46	1671.78
4179.28	1661.02
4182.1	1667.03
4184.91	1632.99
4187.73	1639.15
4190.54	1648.28
4193.36	1718.37
4196.17	1692.73
4198.98	1715.33
4201.79	1736.9
4204.6	1707.57
4207.41	1668.31
4210.22	1652.61
4213.02	1606.36
4215.83	1622
4218.63	1613.05
4221.44	1621.71
4224.24	1639.11
4227.04	1572.4
4229.84	1610.61
4232.64	1595.53
4235.43	1628.16
4238.23	1601.46
4241.02	1586.65
4243.82	1600.68
4246.61	1586.96
4249.4	1647.9
4252.19	1610.99
4254.98	1631.92
4257.77	1598.7
4260.56	1609.46
4263.35	1616.32
4266.13	1591.11
4268.92	1610.2
4271.7	1594.08
4274.48	1617.17
4277.26	1571.37
4280.04	1567.67
4282.82	1548.7
4285.6	1576.05
4288.38	1569.84
4291.15	1561.42
4293.93	1554.95
4296.7	1578.08
4299.47	1538.51
4302.25	1565.69
4305.02	1550.25
4307.79	1534.8
4310.55	1540.74
4313.32	1541.75
4316.09	1543.52
4318.85	1579.74
4321.62	1548.7
4324.38	1509.37
4327.14	1550.39
4329.9	1471.29
4332.66	1541.74
4335.42	1522.66
4338.18	1477.93
4340.94	1522.15
4343.69	1502.17
4346.45	1504.78
4349.2	1471.82
4351.95	1528.66
4354.7	1506.31
4357.45	1490.91
4360.2	1530.73
4362.95	1534.68
4365.7	1518.31
4368.44	1487.43
4371.19	1505.89
4373.93	1507.68
4376.68	1466.32
4379.42	1456.62
4382.16	1462.3
4384.9	1479.38
4387.64	1463.91
4390.37	1478.85
4393.11	1443.56
4395.85	1473.33
4398.58	1467.96
4401.31	1461.46
4404.05	1428.88
4406.78	1495.94
4409.51	1418.79
4412.24	1452.59
4414.96	1473.75
4417.69	1452.15
4420.42	1440.34
4423.14	1404.8
4425.87	1420.46
4428.59	1425.7
4431.31	1424.68
4434.03	1443.5
4436.75	1424.58
4439.47	1435.95
4442.19	1439.85
4444.91	1401.83
4447.62	1405.66
4450.34	1405.29
4453.05	1400.6
4455.76	1393.78
4458.47	1404.68
4461.19	1398.71
4463.89	1424.48
4466.6	1391.31
4469.31	1383.46
4472.02	1399.88
4474.72	1359.56
4477.43	1405.76
4480.13	1401.49
4482.83	1395.19
4485.53	1355.07
4488.23	1363.41
4490.93	1355.83
4493.63	1361.67
4496.33	1359.88
4499.02	1335.04
4501.72	1396.98
4504.41	1359.23
4507.11	1380.96
4509.8	1329.57
4512.49	1326.95
4515.18	1365.76
4517.87	1327.12
4520.56	1355.44
4523.24	1361.61
4525.93	1337.99
4528.61	1347.31
4531.3	1352.44
4533.98	1292.57
4536.66	1338.28
4539.34	1309.37
4542.02	1311.49
4544.7	1311.45
4547.38	1339.29
4550.05	1328.62
4552.73	1280.56
4555.4	1300.22
4558.08	1277.16
4560.75	1257.63
4563.42	1310.5
4566.09	1262.44
4568.76	1269.73
4571.43	1303.38
4574.1	1275.95
4576.77	1288.13
4579.43	1306.39
4582.1	1290.43
4584.76	1255.07
4587.42	1233.08
4590.08	1267.69
4592.74	1250.93
4595.4	1288.82
4598.06	1247.16
4600.72	1240.3
4603.38	1263.22
4606.03	1258.88
4608.69	1247.97
4611.34	1272.17
4613.99	1230.48
4616.64	1243.65
4619.29	1244.81
4621.94	1272.48
4624.59	1217.47
4627.24	1235.09
4629.89	1217.34
4632.53	1199.52
4635.18	1238.99
4637.82	1214.26
4640.46	1234.86
4643.1	1183.52
4645.74	1175.62
4648.38	1211.29
4651.02	1179.56
4653.66	1223.87
4656.3	1200.9
4658.93	1171.02
4661.57	1195.54
4664.2	1180.09
4666.83	1215.88
4669.46	1161.93
4672.09	1186.38
4674.72	1209.73
4677.35	1182.63
4679.98	1194.74
4682.61	1169.78
4685.23	1163.89
4687.86	1183.87
4690.48	1155.49
4693.1	1113.56
4695.73	1144.75
4698.34	1172.58
4700.96	1201.6
4703.58	1121.06
4706.2	1152.2
4708.82	1176.56
4711.43	1126.23
4714.05	1146.01
4716.66	1137.45
4719.28	1127.7
4721.89	1125.83
4724.5	1147.71
4727.11	1127.8
4729.72	1164.68
4732.33	1166.41
4734.93	1148.85
4737.54	1124.39
4740.14	1121.45
4742.75	1109.37
4745.35	1124.49
4747.95	1114.5
4750.55	1111.18
4753.15	1129.52
4755.75	1104.58
4758.35	1077.36
4760.95	1126.51
4763.54	1122.25
4766.14	1146.53
4768.73	1070.8
4771.33	1080.6
4773.92	1087.9
4776.51	1092.95
4779.1	1100.29
4781.69	1117.91
4784.28	1118.4
4786.87	1078.89
4789.45	1079.39
4792.04	1100.53
4794.63	1043.87
4797.21	1057.08
4799.79	1072.72
4802.37	1091.89
4804.95	1068.68
4807.53	1042.12
4810.11	1061.63
4812.69	1047.75
4815.27	1068.5
4817.84	1060.51
4820.42	1027.14
4822.99	1043.47
4825.57	1065.64
4828.14	1054.2
4830.71	1057.86
4833.28	1027.89
4835.85	1060.79
4838.42	1037.91
4840.98	1020.9
4843.55	1019
4846.12	1016.92
4848.68	1048.77
4851.24	1036.88
4853.81	1016.05
4856.37	1029.5
4858.93	992.159
4861.49	980.589
4864.05	1006.49
4866.61	976.559
4869.16	1021.15
4871.72	986.727
4874.27	999.398
4876.83	968.105
4879.38	1000.83
4881.93	983.679
4884.49	967.63
4887.04	995.535
4889.58	1033.01
4892.13	982.469
4894.68	1012.8
4897.23	987.138
4899.77	986.448
4902.32	1014.36
4904.86	980.238
4907.4	975.882
4909.95	973.88
4912.49	984.793
4915.03	952.632
4917.57	974.127
4920.1	947.948
4922.64	951.629
4925.18	946.958
4927.71	939.963
4930.25	981.845
4932.78	973.796
4935.31	955.162
4937.84	928.022
4940.38	922.395
4942.9	946.276
4945.43	936.994
4947.96	923.065
4950.49	918.676
4953.01	940.745
4955.54	935.121
4958.06	904.461
4960.59	957.916
4963.11	904.556
4965.63	922.351
4968.15	894.579
4970.67	931.601
4973.19	903.468
4975.71	900.63
4978.22	897.767
4980.74	890.103
4983.25	934.52
4985.77	928.131
4988.28	919.324
4990.79	906.874
4993.3	918.68
4995.81	904.925
4998.32	899.827