File: Data/3-Raman/raw/bu19w-d-ff2-fi06-v_1800 (450-850nm)_532nm_edge_100%_x100_vis_lwd_h50um_30sx2_01.txt
#Acq. time (s)=	30
#Accumulations=	2
#Range (cm-¹)=	1200...2365
#Windows=	3
#Auto scanning=	Off
#Autofocus=	Off
#Macrospot=	Off
#AutoExposure=	Off
#Spike filter=	Multiple accum.
#Delay time (s)=	2
#Binning=	1
#Readout mode=	Signal
#DeNoise=	Off
#ICS correction=	On
#Dark correction=	Off
#Inst. Process=	Off
#Detector Gain=	Best Dynamic
#Detector ADC=	50 kHz HS
#Detector temperature (°C)=	-60.09
#Instrument=	LabRAM HR Evol
#Detector=	SIN-EM FIVIS
#Objective=	x100_VIS_LWD
#Grating=	1800 (450-850nm)
#ND Filter=	100%
#Laser=	532nm_Edge
#Hole=	49.98
#Temperature=	0
#Range=	Visible
#StageXY=	75x50mm Scan+
#StageZ=	Z motor
#X (µm)=	0
#Y (µm)=	0
#Z (µm)=	58.8
#Full time(mm:ss)=	3:12
#Project=	21_11_22
#Sample=	BU19w
#Site=
#Title=	BU19w-D-FF2-FI06-V_1800 (450-850nm)_532nm_Edge_100%_x100_VIS_LWD_H50um_30sX2
#Remark=
#Date=	22.11.2021 13:14
#Acquired=	22.11.2021 13:14:09
1202.84	37.0405
1203.95	36.9652
1205.06	41.2013
1206.17	39.0156
1207.29	37.9236
1208.39	42.1311
1209.51	37.8049
1210.62	39.894
1211.72	35.6248
1212.84	38.8078
1213.94	33.4323
1215.05	37.6366
1216.16	38.6685
1217.27	40.7673
1218.38	34.3877
1219.49	35.3979
1220.6	36.3834
1221.71	34.2246
1222.81	38.4435
1223.92	35.2657
1225.03	34.1296
1226.14	39.2949
1227.24	36.2391
1228.35	47.6904
1229.46	44.529
1230.56	55.0186
1231.67	59.2372
1232.78	61.3628
1233.88	60.2954
1234.99	59.1653
1236.09	51.7489
1237.2	51.7252
1238.3	41.2425
1239.41	42.2695
1240.51	46.472
1241.62	44.3702
1242.72	43.279
1243.83	46.3876
1244.93	45.3263
1246.03	48.4322
1247.14	49.4727
1248.24	56.7397
1249.34	61.915
1250.45	58.7359
1251.55	67.1144
1252.65	56.6796
1253.75	57.7308
1254.86	58.7575
1255.96	43.0663
1257.06	47.2683
1258.16	49.2967
1259.26	46.2511
1260.36	47.1687
1261.46	49.4186
1262.56	47.2722
1263.66	58.7609
1264.76	47.3058
1265.86	41.08
1266.96	40.0298
1268.06	37.8937
1269.16	38.9373
1270.26	44.2181
1271.36	39.012
1272.46	43.2079
1273.56	44.2855
1274.66	44.3168
1275.76	42.2494
1276.85	39.0986
1277.95	43.2998
1279.05	46.483
1280.15	42.254
1281.24	59.0138
1282.34	114.959
1283.44	342.413
1284.53	126.465
1285.63	49.5998
1286.73	40.1463
1287.82	36.9937
1288.92	34.8778
1290.01	38.0299
1291.11	34.9064
1292.21	31.7463
1293.3	31.809
1294.4	34.9712
1295.49	37.0565
1296.58	35.9776
1297.68	32.815
1298.77	27.5339
1299.87	32.8184
1300.96	30.6889
1302.05	30.6809
1303.15	28.5394
1304.24	30.6372
1305.33	27.4703
1306.42	26.4178
1307.52	34.8595
1308.61	29.5824
1309.7	29.5916
1310.79	26.4106
1311.88	32.7413
1312.98	29.5845
1314.07	28.5188
1315.16	29.5788
1316.25	32.7447
1317.34	28.514
1318.43	28.4896
1319.52	30.5673
1320.61	27.3872
1321.7	31.6017
1322.79	27.3616
1323.88	32.5685
1324.97	26.2964
1326.06	29.4905
1327.15	27.3709
1328.23	27.3429
1329.32	26.245
1330.41	27.2558
1331.5	30.3692
1332.59	30.3382
1333.67	27.1683
1334.76	27.1521
1335.85	28.1726
1336.94	26.0713
1338.02	22.9266
1339.11	27.1003
1340.2	29.1627
1341.28	31.2461
1342.37	29.1359
1343.45	25.9582
1344.54	29.0485
1345.63	26.9446
1346.71	32.1272
1347.8	32.0968
1348.88	28.9471
1349.96	25.8382
1351.05	28.9888
1352.13	26.8334
1353.22	27.8643
1354.3	29.9215
1355.39	28.8593
1356.47	26.759
1357.55	28.8004
1358.63	30.8569
1359.72	28.7692
1360.8	30.8446
1361.88	27.7312
1362.97	34.9458
1364.05	30.7675
1365.13	32.827
1366.21	33.8647
1367.29	28.6825
1368.37	40.0137
1369.45	36.8559
1370.54	36.8241
1371.62	36.8068
1372.7	37.8301
1373.78	39.868
1374.86	41.9044
1375.94	43.0005
1377.02	49.1573
1378.09	49.0468
1379.18	59.2661
1380.25	67.3811
1381.33	68.36
1382.41	74.5755
1383.49	66.4171
1384.57	81.6146
1385.65	130.809
1386.72	577.8
1387.8	171.908
1388.88	61.106
1389.96	46.7193
1391.03	41.579
1392.11	38.5006
1393.19	40.5558
1394.26	34.3914
1395.34	34.3779
1396.42	32.3405
1397.49	30.2996
1398.57	27.2366
1399.64	25.2216
1400.72	29.3489
1401.79	32.4006
1402.87	27.2478
1403.94	32.359
1405.02	29.2877
1406.09	30.3169
1407.17	42.6297
1408.24	52.8294
1409.31	41.5422
1410.39	30.3531
1411.46	29.2823
1412.53	29.2927
1413.61	26.216
1414.68	26.2236
1415.75	26.2237
1416.82	27.2399
1417.9	23.1061
1418.97	23.1015
1420.04	21.0876
1421.11	25.1161
1422.18	24.0817
1423.26	24.0868
1424.33	24.0576
1425.4	21.9808
1426.47	23.0062
1427.54	24.0469
1428.61	23.0475
1429.68	22.0039
1430.75	24.0141
1431.82	20.9429
1432.89	22.9873
1433.96	20.9263
1435.02	21.9397
1436.09	18.869
1437.16	18.8782
1438.23	21.9555
1439.3	26.0495
1440.37	19.8913
1441.43	20.9066
1442.5	21.9452
1443.57	22.9585
1444.64	17.8183
1445.7	27.0491
1446.77	19.8621
1447.84	20.872
1448.9	24.9578
1449.97	19.8285
1451.04	18.8023
1452.1	17.7712
1453.17	17.7705
1454.23	24.9298
1455.3	17.7497
1456.36	17.7479
1457.43	20.8137
1458.49	20.7991
1459.56	16.686
1460.62	16.6651
1461.69	19.7497
1462.75	17.6438
1463.81	18.653
1464.88	19.6644
1465.94	18.6366
1467	16.5803
1468.07	19.6225
1469.13	14.5149
1470.19	18.5798
1471.25	17.5476
1472.32	22.6348
1473.38	17.5342
1474.44	18.5369
1475.5	17.5082
1476.56	17.491
1477.62	17.4661
1478.68	18.4684
1479.75	16.4467
1480.81	18.4761
1481.87	20.4587
1482.93	19.4321
1483.99	19.4301
1485.05	16.3767
1486.11	18.3812
1487.17	20.3941
1488.22	19.3666
1489.28	16.3263
1490.34	18.341
1491.4	18.3352
1492.46	16.3016
1493.52	17.2889
1494.58	17.2787
1495.63	18.2818
1496.69	14.2433
1497.75	18.2778
1498.81	15.2376
1499.86	16.2352
1500.92	18.2377
1501.98	15.2096
1503.03	19.2199
1504.09	15.1861
1505.15	18.2041
1506.2	19.207
1507.26	20.2131
1508.31	19.182
1509.37	21.1475
1510.42	20.1135
1511.48	18.1129
1512.53	20.0986
1513.59	18.0683
1514.64	17.0575
1515.7	15.0534
1516.75	16.0561
1517.8	17.052
1518.86	18.0538
1519.91	15.0317
1520.96	18.0138
1522.02	18.0001
1523.07	17.0012
1524.12	19.0109
1525.17	21.0022
1526.23	16.9823
1527.28	16.9719
1528.33	18.9829
1529.38	20.9785
1530.43	19.9941
1531.48	18.9894
1532.53	18.9753
1533.59	16.9396
1534.64	17.9148
1535.69	16.8985
1536.74	16.9201
1537.79	18.9508
1538.84	18.9333
1539.89	14.9036
1540.94	15.8798
1541.98	18.8873
1543.03	20.9051
1544.08	17.8994
1545.13	19.8871
1546.18	17.8688
1547.23	16.8678
1548.28	17.921
1549.33	20.9284
1550.37	17.8974
1551.42	20.8859
1552.47	21.8627
1553.52	18.8507
1554.56	19.8505
1555.61	17.8264
1556.65	20.7991
1557.7	20.7827
1558.75	18.7824
1559.79	20.7884
1560.84	18.779
1561.88	20.7918
1562.93	18.6614
1563.98	19.7406
1565.02	17.7529
1566.07	19.7523
1567.11	20.7358
1568.15	22.7288
1569.2	16.7191
1570.24	19.6978
1571.29	18.692
1572.33	21.7039
1573.37	16.7057
1574.42	19.6735
1575.46	19.6438
1576.5	20.6341
1577.55	22.6299
1578.59	21.6172
1579.63	22.5952
1580.67	18.6012
1581.72	17.6009
1582.76	19.5869
1583.8	20.561
1584.84	21.5423
1585.88	19.5546
1586.92	22.5444
1587.96	20.5543
1589	24.5274
1590.04	23.5032
1591.08	23.4619
1592.12	21.4741
1593.16	23.4474
1594.2	24.4384
1595.24	19.4677
1596.28	23.4139
1597.32	18.4325
1598.36	21.3779
1599.4	24.319
1600.44	24.2913
1601.48	23.2916
1602.51	26.2553
1603.55	23.2951
1604.59	24.2845
1605.63	25.2664
1606.66	24.2487
1607.7	22.2947
1608.74	25.1376
1609.77	21.6419
1610.81	24.1612
1611.85	20.9052
1612.88	24.9282
1613.92	23.7348
1614.95	25.6464
1615.99	28.9676
1617.03	27.5417
1618.06	24.5091
1619.1	26.6026
1620.13	25.058
1621.17	25.3457
1622.2	25.3181
1623.23	28.5927
1624.27	26.4548
1625.3	28.2249
1626.34	28.5504
1627.37	28.0711
1628.4	26.5098
1629.44	23.742
1630.47	28.4277
1631.29	25.3242
1632.33	28.2784
1633.38	26.2947
1634.42	23.3228
1635.47	28.2348
1636.51	32.1682
1637.56	27.2444
1638.6	31.1861
1639.65	27.2381
1640.69	27.232
1641.73	27.2168
1642.78	29.19
1643.82	27.2096
1644.86	27.1972
1645.91	31.1423
1646.95	29.1831
1647.99	31.1737
1649.03	25.2685
1650.08	30.1872
1651.12	27.2327
1652.16	32.1672
1653.2	26.2781
1654.24	28.2548
1655.28	28.2427
1656.33	28.2248
1657.37	29.198
1658.41	25.2684
1659.45	25.2633
1660.49	28.2703
1661.53	24.2891
1662.57	23.2794
1663.61	28.2774
1664.65	28.22
1665.69	26.2359
1666.72	25.2735
1667.76	28.2512
1668.8	27.2581
1669.84	26.2713
1670.88	22.3181
1671.92	25.294
1672.96	26.2909
1674	24.3115
1675.03	22.3217
1676.07	23.2921
1677.11	23.2803
1678.15	26.2332
1679.18	24.2531
1680.22	19.3099
1681.25	22.2677
1682.29	24.2336
1683.33	22.2565
1684.36	23.2496
1685.4	21.2626
1686.43	21.2463
1687.47	23.2053
1688.51	23.212
1689.54	23.2117
1690.58	21.2169
1691.61	22.1811
1692.64	21.1935
1693.68	18.2415
1694.71	22.1672
1695.75	19.1952
1696.78	20.1739
1697.81	23.1181
1698.85	21.1396
1699.88	21.1219
1700.91	21.114
1701.95	18.1672
1702.98	21.1095
1704.01	19.1253
1705.04	18.1222
1706.08	19.076
1707.11	17.108
1708.14	15.1515
1709.17	20.0493
1710.2	20.0206
1711.23	18.04
1712.27	18.0326
1713.3	19.0113
1714.33	15.0852
1715.36	18.9542
1716.39	13.0988
1717.42	17.9646
1718.45	19.8938
1719.48	18.9005
1720.51	17.9109
1721.54	16.933
1722.56	16.9098
1723.59	19.805
1724.62	18.8228
1725.65	17.8386
1726.68	17.7938
1727.71	16.823
1728.74	15.8721
1729.76	17.7966
1730.79	14.8789
1731.82	15.821
1732.85	16.7643
1733.87	17.7161
1734.9	18.6656
1735.93	17.6869
1736.95	20.5385
1737.98	14.76
1739.01	17.6186
1740.03	17.61
1741.06	16.6429
1742.08	15.6783
1743.11	16.6286
1744.13	14.699
1745.16	16.5937
1746.18	13.7289
1747.21	16.6019
1748.23	17.5647
1749.26	14.6827
1750.28	16.5764
1751.31	15.6079
1752.33	16.5491
1753.35	16.5336
1754.38	15.561
1755.4	13.6579
1756.42	16.5115
1757.44	14.6031
1758.47	15.5427
1759.49	13.634
1760.51	16.4864
1761.53	17.4434
1762.56	15.5477
1763.58	16.4974
1764.6	13.6351
1765.62	16.4805
1766.64	17.3999
1767.66	16.4527
1768.68	15.5117
1769.7	15.5169
1770.72	16.4729
1771.74	14.5704
1772.76	14.5806
1773.78	14.5812
1774.8	17.428
1775.82	16.4601
1776.84	14.5453
1777.86	14.5492
1778.88	12.6458
1779.9	15.5097
1780.92	13.6077
1781.94	15.5224
1782.95	15.5176
1783.97	13.6103
1784.99	12.6725
1786.01	14.6058
1787.03	16.5336
1788.04	14.6166
1789.06	12.6842
1790.08	14.6005
1791.09	12.6846
1792.11	15.5625
1793.13	14.6224
1794.14	13.6698
1795.16	13.6745
1796.17	14.6338
1797.19	15.5826
1798.21	13.653
1799.22	14.6123
1800.24	14.6185
1801.25	15.5844
1802.27	12.7059
1803.28	14.6404
1804.29	16.5705
1805.31	15.6046
1806.32	12.7119
1807.34	13.6751
1808.35	15.5989
1809.36	15.597
1810.38	16.5673
1811.39	14.6458
1812.4	14.656
1813.41	13.6897
1814.43	16.5834
1815.44	13.6765
1816.45	16.5786
1817.46	14.6493
1818.47	15.6208
1819.49	12.7216
1820.5	13.6881
1821.51	15.6202
1822.52	15.6233
1823.53	12.7164
1824.54	13.6851
1825.55	14.6529
1826.56	11.7393
1827.57	15.6053
1828.58	17.5426
1829.59	12.7042
1830.6	18.5216
1831.61	14.6388
1832.62	13.644
1833.63	14.6745
1834.64	14.616
1835.65	13.6204
1836.65	15.5908
1837.66	15.5658
1838.67	13.602
1839.68	12.6179
1840.69	13.5814
1841.7	15.5082
1842.7	13.5762
1843.71	14.5613
1844.72	15.4671
1845.72	13.544
1846.73	14.4939
1847.74	14.4732
1848.74	14.4597
1849.75	13.4949
1850.75	14.4487
1851.76	15.3893
1852.76	13.4562
1853.77	13.4502
1854.78	13.4434
1855.78	13.4308
1856.79	14.3727
1857.79	15.3309
1858.79	17.2514
1859.8	15.3275
1860.8	15.311
1861.81	16.2523
1862.81	15.2773
1863.81	16.2019
1864.82	15.2252
1865.82	14.2681
1866.82	14.2637
1867.83	16.159
1868.83	12.3514
1869.83	11.3917
1870.83	15.1808
1871.84	12.3201
1872.84	15.1441
1873.84	12.2832
1874.84	15.0843
1875.84	16.0646
1876.84	12.288
1877.84	14.1774
1878.84	15.1021
1879.84	14.1224
1880.84	14.1255
1881.84	13.1603
1882.85	13.173
1883.85	15.0647
1884.84	14.1029
1885.84	14.0821
1886.84	15.0102
1887.84	14.0738
1888.84	14.0691
1889.84	15.003
1890.84	12.156
1891.84	13.0876
1892.83	14.0271
1893.83	15.9135
1894.83	12.154
1895.83	15.9071
1896.83	15.8926
1897.82	14.0079
1898.82	13.0748
1899.82	14.0198
1900.81	12.131
1901.81	14.9466
1902.81	14.941
1903.8	13.986
1904.8	15.8606
1905.79	12.107
1906.79	14.9345
1907.79	11.1842
1908.78	14.9541
1909.78	14.9487
1910.77	14.9499
1911.77	14.0193
1912.76	14.9677
1913.76	14.0158
1914.75	14.9477
1915.74	15.8945
1916.74	15.9135
1917.73	16.8593
1918.72	12.1426
1919.72	16.869
1920.71	13.0776
1921.7	15.9021
1922.7	15.9065
1923.69	13.0827
1924.68	15.9306
1925.67	12.1446
1926.66	12.1502
1927.66	14.0589
1928.65	18.8051
1929.64	15.9455
1930.63	16.8893
1931.62	15.0267
1932.61	16.0149
1933.61	16.0016
1934.6	12.1771
1935.59	14.0727
1936.58	14.0801
1937.57	14.0859
1938.56	16.0077
1939.55	14.0915
1940.54	17.9116
1941.52	13.1409
1942.51	13.1504
1943.5	13.1574
1944.49	15.067
1945.48	11.2374
1946.47	13.1529
1947.46	13.1662
1948.44	17.981
1949.43	16.0746
1950.42	16.0783
1951.41	14.1266
1952.39	14.1109
1953.38	13.1708
1954.37	17.0229
1955.36	14.1469
1956.34	14.1411
1957.33	17.0132
1958.31	15.0792
1959.3	16.9945
1960.29	12.1949
1961.27	15.076
1962.26	14.1127
1963.24	15.0757
1964.23	15.0824
1965.21	16.0429
1966.2	15.0738
1967.18	15.0539
1968.17	10.2448
1969.15	14.0777
1970.14	14.0743
1971.12	14.0618
1972.1	14.0586
1973.09	15.0222
1974.07	17.8995
1975.05	14.0538
1976.04	15.9621
1977.02	12.1266
1978	13.076
1978.98	14.026
1979.97	14.0169
1980.95	16.8727
1981.93	13.0386
1982.91	13.0294
1983.89	15.901
1984.88	17.8009
1985.86	15.8546
1986.84	13.9166
1987.82	16.7774
1988.8	14.8722
1989.78	14.832
1990.76	15.6725
1991.74	16.47
1992.72	16.5272
1993.7	15.1365
1994.68	13.3892
1995.66	15.7605
1996.64	12.9689
1997.62	13.3775
1998.6	15.5204
1999.57	13.4898
2000.55	15.346
2001.53	14.9276
2002.51	15.2054
2003.49	15.8107
2004.47	14.8232
2005.44	14.484
2006.42	16.2722
2007.4	14.1249
2008.38	15.8241
2009.35	14.2882
2010.33	13.6061
2011.3	15.2068
2012.18	16.7495
2013.17	12.9998
2014.16	13.9523
2015.15	13.9372
2016.14	14.8525
2017.13	15.7761
2018.11	12.9646
2019.1	16.7094
2020.09	12.9518
2021.08	16.6795
2022.06	12.9238
2023.05	14.7726
2024.04	12.9285
2025.02	13.8732
2026.01	13.9028
2027	12.9216
2027.98	12.9012
2028.97	14.7734
2029.96	15.7263
2030.94	16.6767
2031.93	15.6999
2032.91	16.6659
2033.9	18.5349
2034.88	14.7973
2035.87	15.7224
2036.85	14.7768
2037.83	14.7604
2038.82	15.6839
2039.8	16.6061
2040.79	13.8199
2041.77	14.757
2042.75	14.7587
2043.74	16.646
2044.72	15.683
2045.7	11.0179
2046.69	14.7588
2047.67	12.9059
2048.65	17.5682
2049.63	14.7686
2050.62	15.7129
2051.6	14.7904
2052.58	15.7194
2053.56	14.7781
2054.54	16.6475
2055.52	14.787
2056.5	14.7963
2057.48	13.8572
2058.46	15.732
2059.45	15.734
2060.43	15.7426
2061.4	16.686
2062.39	16.6983
2063.37	14.8344
2064.34	14.839
2065.32	16.7261
2066.3	14.8474
2067.28	14.8344
2068.26	18.617
2069.24	17.6964
2070.22	15.8091
2071.2	16.7513
2072.18	15.8229
2073.15	14.9027
2074.13	15.8428
2075.11	14.8876
2076.09	14.8949
2077.06	14.9104
2078.04	15.8581
2079.02	13.9652
2080	17.748
2080.97	13.9658
2081.95	15.8559
2082.93	17.7463
2083.9	15.8701
2084.88	15.8759
2085.85	13.9844
2086.83	14.9394
2087.8	15.8912
2088.78	14.9515
2089.75	14.9699
2090.73	15.935
2091.7	16.8927
2092.68	13.0831
2093.65	16.8773
2094.63	15.9177
2095.6	14.0133
2096.57	14.9598
2097.55	13.062
2098.52	17.8187
2099.5	16.8692
2100.47	14.9608
2101.44	16.8588
2102.41	16.8685
2103.39	13.0765
2104.36	15.9313
2105.33	17.8176
2106.3	14.9585
2107.27	15.9151
2108.25	14.0143
2109.22	14.9581
2110.19	18.7616
2111.16	16.8697
2112.13	16.8682
2113.1	16.8626
2114.07	15.9031
2115.04	15.8985
2116.01	17.7797
2116.99	15.8691
2117.96	16.8155
2118.92	16.8279
2119.9	12.0932
2120.86	18.7399
2121.83	13.9799
2122.8	13.9571
2123.77	16.7808
2124.74	14.8793
2125.71	17.7109
2126.68	16.762
2127.65	14.8677
2128.61	12.9704
2129.58	12.9627
2130.55	14.8456
2131.52	17.6781
2132.48	16.7314
2133.45	18.602
2134.42	15.7716
2135.39	13.8852
2136.35	14.8344
2137.32	16.7006
2138.28	15.7514
2139.25	13.8601
2140.22	17.6437
2141.18	15.7167
2142.15	15.722
2143.12	16.6604
2144.08	12.8946
2145.05	15.7054
2146.01	13.8188
2146.98	16.6167
2147.94	13.7938
2148.9	15.6756
2149.87	14.7361
2150.83	12.8531
2151.8	17.5181
2152.76	13.7525
2153.72	14.6775
2154.69	14.6793
2155.65	14.6843
2156.61	12.8089
2157.58	12.7964
2158.54	16.5219
2159.5	13.72
2160.47	13.7146
2161.43	16.5029
2162.39	16.497
2163.35	14.6316
2164.31	16.4843
2165.27	17.3896
2166.24	16.4585
2167.2	14.6156
2168.16	14.6162
2169.12	17.3815
2170.08	14.5839
2171.04	15.5147
2172	15.5164
2172.96	13.6543
2173.92	15.5065
2174.88	17.3639
2175.84	17.3541
2176.8	15.4971
2177.76	15.4948
2178.72	16.4181
2179.68	15.483
2180.64	15.4699
2181.59	17.3133
2182.55	17.3174
2183.51	15.473
2184.47	13.6333
2185.43	17.3472
2186.38	19.186
2187.34	17.3159
2188.3	17.3185
2189.26	15.4684
2190.21	17.3316
2191.17	13.6365
2192.13	14.5703
2193.08	18.2741
2194.04	16.3974
2195	18.2471
2195.95	16.4058
2196.91	13.6376
2197.86	16.4569
2198.82	16.443
2199.78	15.4913
2200.73	16.4359
2201.69	19.2722
2202.64	14.5655
2203.59	16.4271
2204.55	14.5662
2205.5	17.3703
2206.46	15.5158
2207.41	15.5173
2208.37	15.5263
2209.32	15.5374
2210.27	16.4666
2211.23	13.6668
2212.18	17.4139
2213.13	12.7476
2214.09	15.5461
2215.04	16.4804
2215.99	16.4842
2216.94	17.428
2217.9	17.4276
2218.85	14.6114
2219.8	13.6731
2220.75	15.5504
2221.7	15.5676
2222.65	15.5821
2223.6	15.5943
2224.55	15.6045
2225.5	18.4153
2226.46	17.474
2227.41	14.6734
2228.36	15.6244
2229.31	15.6369
2230.26	17.5295
2231.21	14.7162
2232.16	14.7095
2233.11	14.7008
2234.05	15.6439
2235	13.7791
2235.95	15.6815
2236.9	15.6846
2237.85	18.5092
2238.8	16.633
2239.75	16.6389
2240.69	15.6898
2241.64	18.522
2242.59	16.6555
2243.54	14.7763
2244.48	15.7297
2245.43	12.8889
2246.38	14.778
2247.32	13.8335
2248.27	14.7672
2249.22	12.8747
2250.16	13.8363
2251.11	13.8513
2252.06	14.8025
2253	11.9591
2253.95	13.8647
2254.89	15.7716
2255.84	16.7251
2256.78	13.8817
2257.73	14.8377
2258.67	13.8967
2259.62	12.9495
2260.56	14.8676
2261.51	12.9805
2262.45	13.9471
2263.39	15.8536
2264.34	12.9768
2265.28	12.9672
2266.22	12.0168
2267.17	12.0307
2268.11	14.9081
2269.05	13.9607
2270	14.9201
2270.94	14.923
2271.88	13.0111
2272.82	13.0126
2273.77	12.065
2274.71	13.0374
2275.65	15.932
2276.59	15.9274
2277.53	14.948
2278.47	14.939
2279.41	13.9831
2280.36	13.0362
2281.3	12.0972
2282.24	14.0315
2283.18	12.1005
2284.12	15.9581
2285.06	13.0823
2286	15.9633
2286.94	12.0936
2287.88	14.013
2288.82	13.0639
2289.75	15.9629
2290.69	14.0455
2291.63	13.0774
2292.57	13.0688
2293.51	12.0943
2294.45	14.023
2295.39	15.0011
2296.32	13.0842
2297.26	15.0165
2298.2	14.0568
2299.14	15.024
2300.07	15.9863
2301.01	15.0213
2301.95	14.0639
2302.89	14.0695
2303.82	14.0735
2304.76	14.0692
2305.69	14.0651
2306.63	15.04
2307.57	15.0495
2308.5	14.0683
2309.44	13.0828
2310.37	12.1145
2311.31	15.0284
2312.24	13.1109
2313.18	13.0974
2314.11	15.0148
2315.05	13.0904
2315.98	10.1832
2316.92	14.0371
2317.85	14.0382
2318.78	13.082
2319.72	15.9943
2320.65	15.9959
2321.58	13.0948
2322.52	15.0107
2323.45	15.9628
2324.38	16.9123
2325.32	20.7606
2326.25	26.5336
2327.18	52.534
2328.11	81.4092
2329.05	27.4978
2329.98	23.6247
2330.91	16.8758
2331.84	14.9394
2332.77	13.9748
2333.7	13.9723
2334.63	15.892
2335.56	13.0039
2336.5	14.926
2337.43	14.9192
2338.36	13.9437
2339.29	14.8877
2340.22	12.0061
2341.15	14.8803
2342.08	13.9213
2343.01	12.9527
2343.93	16.7775
2344.86	13.9018
2345.79	16.7779
2346.72	15.8017
2347.65	12.8903
2348.58	15.8133
2349.51	10.9927
2350.44	10.9701
2351.36	14.7757
2352.29	11.9224
2353.22	13.8208
2354.15	11.8988
2355.07	12.8411
2356	13.7839
2356.93	12.8277
2357.86	12.8152
2358.78	13.7497
2359.71	12.7879
2360.63	15.6175
2361.56	13.717
2362.49	13.7074
2363.41	12.74
2364.34	13.6976
2364.8	13.7021