File: Data/3-Raman/raw/bu19w-e-ff11b-fi03-v_1800 (450-850nm)_532nm_edge_100%_x100_vis_h50um_30sx2_01.txt
#Acq. time (s)=	30
#Accumulations=	2
#Range (cm-¹)=	1200...2365
#Windows=	3
#Auto scanning=	Off
#Autofocus=	Off
#Macrospot=	Off
#AutoExposure=	Off
#Spike filter=	Multiple accum.
#Delay time (s)=	2
#Binning=	1
#Readout mode=	Signal
#DeNoise=	Off
#ICS correction=	On
#Dark correction=	Off
#Inst. Process=	Off
#Detector Gain=	Best Dynamic
#Detector ADC=	50 kHz HS
#Detector temperature (°C)=	-60.09
#Instrument=	LabRAM HR Evol
#Detector=	SIN-EM FIVIS
#Objective=	x100_VIS
#Grating=	1800 (450-850nm)
#ND Filter=	100%
#Laser=	532nm_Edge
#Hole=	49.98
#Temperature=	0
#Range=	Visible
#StageXY=	75x50mm Scan+
#StageZ=	Z motor
#X (µm)=	0
#Y (µm)=	0
#Z (µm)=	-250.4
#Full time(mm:ss)=	3:18
#Project=	21_11_04
#Sample=	BU19w
#Site=
#Title=	BU19w-E-FF11b-FI03-V_1800 (450-850nm)_532nm_Edge_100%_x100_VIS_H50um_30sX2
#Remark=
#Date=	04.11.2021 18:43
#Acquired=	04.11.2021 18:43:09
1202.73	19.9219
1203.85	20.9583
1204.96	17.7249
1206.07	18.7644
1207.18	16.5958
1208.29	19.7894
1209.4	21.9162
1210.51	17.6179
1211.62	20.7913
1212.73	19.7027
1213.84	17.5664
1214.95	19.6948
1216.06	18.6122
1217.17	20.7114
1218.28	19.6325
1219.39	16.4413
1220.5	19.6203
1221.61	23.8404
1222.72	22.7385
1223.82	20.5925
1224.93	21.6399
1226.04	27.9799
1227.15	23.7221
1228.25	23.6513
1229.36	29.0127
1230.47	22.6407
1231.57	19.44
1232.68	24.687
1233.79	22.5891
1234.89	21.5489
1236	19.4498
1237.1	23.632
1238.21	24.6473
1239.31	22.5373
1240.42	20.4408
1241.52	24.6264
1242.63	20.441
1243.74	24.6364
1244.84	25.6704
1245.94	23.5522
1247.05	25.6416
1248.15	27.7152
1249.25	26.6701
1250.36	27.6995
1251.46	22.4566
1252.56	28.7014
1253.66	30.7917
1254.77	26.628
1255.87	25.5856
1256.97	28.7211
1258.07	34.9752
1259.18	29.7495
1260.28	34.9621
1261.38	41.2268
1262.48	64.1905
1263.58	69.4919
1264.68	41.2823
1265.78	31.8692
1266.88	28.756
1267.98	31.9394
1269.08	30.9104
1270.18	32.975
1271.28	30.8674
1272.38	27.759
1273.48	30.934
1274.58	29.894
1275.68	32.0108
1276.78	33.0856
1277.87	41.5252
1278.97	41.553
1280.07	56.2686
1281.17	123.679
1282.26	434.261
1283.36	912.703
1284.46	248.181
1285.55	76.3438
1286.65	52.1166
1287.75	41.5676
1288.84	34.2139
1289.94	38.4515
1291.04	28.9636
1292.13	33.1778
1293.23	28.9792
1294.32	27.9448
1295.42	26.9305
1296.51	30.1237
1297.61	32.2117
1298.7	30.09
1299.79	27.9791
1300.89	30.0912
1301.98	26.9361
1303.08	24.8168
1304.17	25.8706
1305.26	27.9644
1306.36	23.7286
1307.45	26.8952
1308.54	26.8994
1309.63	24.8007
1310.73	26.9115
1311.82	27.9788
1312.91	22.6974
1314	25.8611
1315.09	22.7048
1316.18	23.7624
1317.28	25.8789
1318.37	24.827
1319.46	24.8256
1320.55	23.7626
1321.64	22.683
1322.73	26.8853
1323.82	23.7249
1324.91	20.5601
1325.99	25.7791
1327.08	26.859
1328.17	20.5696
1329.26	21.6283
1330.35	22.6712
1331.44	23.6913
1332.53	23.6618
1333.62	25.7338
1334.7	23.6112
1335.79	22.5461
1336.88	24.6324
1337.96	24.6151
1339.05	22.5125
1340.14	22.5164
1341.23	25.6536
1342.31	24.5859
1343.4	21.4396
1344.48	21.4362
1345.57	23.5029
1346.66	24.5123
1347.74	22.409
1348.83	23.4383
1349.91	24.4623
1351	24.4408
1352.08	21.3217
1353.17	24.4919
1354.25	20.2603
1355.33	23.3708
1356.42	24.408
1357.5	28.5479
1358.58	25.4147
1359.67	27.4681
1360.75	27.4498
1361.83	27.4421
1362.92	29.5128
1364	31.593
1365.08	26.3962
1366.16	31.5423
1367.24	30.488
1368.33	52.2077
1369.41	32.5649
1370.49	26.345
1371.57	31.4698
1372.65	29.3765
1373.73	34.5164
1374.81	32.447
1375.89	34.5081
1376.97	34.473
1378.05	38.6495
1379.13	42.7771
1380.21	43.7311
1381.29	43.6908
1382.37	56.9572
1383.45	71.2537
1384.53	130.77
1385.61	405.055
1386.68	2115.25
1387.76	364.531
1388.84	98.0451
1389.92	55.8739
1390.99	45.606
1392.07	45.5656
1393.15	35.3099
1394.23	34.2772
1395.3	31.2211
1396.38	28.1419
1397.46	30.1729
1398.53	31.205
1399.61	29.1704
1400.68	33.2809
1401.76	31.257
1402.83	33.3634
1403.91	31.2919
1404.99	37.4317
1406.06	45.6106
1407.13	73.301
1408.21	119.465
1409.28	63.0862
1410.36	37.4181
1411.43	35.3438
1412.5	29.2505
1413.58	30.2472
1414.65	25.1531
1415.72	21.0505
1416.8	26.1966
1417.87	22.0931
1418.94	24.1505
1420.01	24.133
1421.08	25.146
1422.16	26.2065
1423.23	22.0291
1424.3	25.1119
1425.37	26.161
1426.44	24.093
1427.51	22.0156
1428.58	18.9441
1429.65	21.0067
1430.72	21.0344
1431.79	20.0081
1432.86	22.0352
1433.93	24.0682
1435	19.9821
1436.07	21.0023
1437.14	18.9479
1438.21	21.0001
1439.28	26.1334
1440.35	21.0216
1441.41	23.0676
1442.48	18.9733
1443.55	17.9393
1444.62	15.902
1445.69	24.1051
1446.75	16.9198
1447.82	21.0183
1448.89	17.9483
1449.95	18.964
1451.02	15.8838
1452.09	14.8556
1453.15	17.9346
1454.22	16.9079
1455.28	21.008
1456.35	16.9087
1457.41	19.9753
1458.48	18.9535
1459.54	19.9783
1460.61	17.923
1461.67	16.8891
1462.74	17.8976
1463.8	17.9029
1464.86	14.8166
1465.93	16.8444
1466.99	16.8334
1468.05	16.8308
1469.12	16.8246
1470.18	16.8126
1471.24	16.8036
1472.31	19.8552
1473.37	18.8287
1474.43	15.7759
1475.49	16.791
1476.55	16.7828
1477.62	16.7787
1478.68	16.768
1479.74	14.7225
1480.8	17.7542
1481.86	13.7029
1482.92	15.7393
1483.98	13.6986
1485.04	15.6711
1486.1	15.7031
1487.16	20.7657
1488.22	16.7015
1489.28	15.6812
1490.34	14.6655
1491.4	17.6924
1492.46	15.6696
1493.52	15.6679
1494.57	16.6794
1495.63	15.6511
1496.69	16.6531
1497.75	14.6334
1498.81	15.6448
1499.86	16.6583
1500.92	17.6623
1501.98	17.6586
1503.03	16.6377
1504.09	16.6395
1505.15	16.6327
1506.2	15.6147
1507.26	18.6427
1508.32	15.6182
1509.37	14.6111
1510.43	15.6131
1511.48	17.5993
1512.54	15.5648
1513.59	15.5674
1514.65	15.5624
1515.7	13.5396
1516.76	14.538
1517.81	15.5454
1518.86	16.5532
1519.92	14.5457
1520.97	16.5561
1522.02	16.5513
1523.08	17.5396
1524.13	13.5185
1525.18	15.5248
1526.24	12.5296
1527.29	14.5308
1528.34	15.5269
1529.39	15.5228
1530.44	16.5296
1531.5	16.5332
1532.55	9.52362
1533.6	15.549
1534.65	16.5474
1535.7	14.5251
1536.75	15.5082
1537.8	13.4979
1538.85	16.5023
1539.9	17.5404
1540.95	13.5329
1542	19.5289
1543.05	20.5105
1544.1	16.5042
1545.15	18.5261
1546.2	17.5295
1547.25	16.533
1548.29	15.5271
1549.34	16.4968
1550.39	18.5859
1551.44	17.5627
1552.49	18.5792
1553.53	16.549
1554.58	14.5264
1555.63	13.5248
1556.68	15.5273
1557.72	18.5249
1558.77	14.5028
1559.82	15.4923
1560.86	16.489
1561.91	16.5025
1562.95	16.5003
1564	18.5137
1565.04	17.4463
1566.09	15.4961
1567.13	17.5081
1568.18	17.499
1569.22	13.4904
1570.27	16.4902
1571.31	18.4813
1572.36	18.4722
1573.4	16.467
1574.44	16.4805
1575.49	18.4877
1576.53	15.4789
1577.57	17.4525
1578.62	17.4461
1579.66	15.4563
1580.7	16.4499
1581.74	15.443
1582.79	15.4391
1583.83	20.4178
1584.87	17.4314
1585.91	17.4222
1586.95	21.3924
1587.99	18.4087
1589.03	16.4269
1590.07	17.4261
1591.12	16.4314
1592.16	17.4128
1593.2	17.391
1594.24	18.376
1595.28	17.3837
1596.32	17.3818
1597.35	19.3732
1598.39	16.3809
1599.43	15.3771
1600.47	17.3466
1601.51	20.2965
1602.55	18.3005
1603.59	15.3252
1604.63	18.2925
1605.66	18.2983
1606.7	19.2949
1607.74	14.4015
1608.78	18.0254
1609.81	16.5156
1610.85	18.0969
1611.89	15.8395
1612.92	16.6726
1613.96	15.2478
1615	15.9316
1616.03	17.0564
1617.07	19.0141
1618.1	18.0606
1619.14	18.467
1620.17	17.239
1621.21	16.1108
1622.24	18.4782
1623.28	17.543
1624.31	16.1115
1625.35	17.7196
1626.38	17.9564
1627.41	20.4374
1628.45	17.1264
1629.48	17.37
1630.51	17.1525
1631.3	19.2137
1632.34	18.2443
1633.39	16.2593
1634.43	19.2209
1635.48	17.2451
1636.52	17.2361
1637.57	17.2291
1638.61	18.2106
1639.66	14.2724
1640.7	17.2326
1641.75	18.212
1642.79	16.2409
1643.83	16.2355
1644.88	15.2518
1645.92	17.2183
1646.96	15.2447
1648.01	16.2293
1649.05	16.2432
1650.09	18.2195
1651.13	16.2597
1652.18	17.2451
1653.22	17.2425
1654.26	18.2331
1655.3	16.2775
1656.34	19.2489
1657.38	16.2833
1658.42	17.2625
1659.47	18.237
1660.51	16.2736
1661.55	11.3504
1662.59	17.2973
1663.63	17.2716
1664.67	15.3169
1665.71	15.3282
1666.75	17.2766
1667.79	16.2784
1668.83	16.2974
1669.86	15.3081
1670.9	18.2851
1671.94	18.2874
1672.98	15.323
1674.02	17.3078
1675.06	16.3285
1676.1	15.3405
1677.13	14.3494
1678.17	14.3391
1679.21	16.3095
1680.25	14.3272
1681.28	18.2763
1682.32	15.3127
1683.35	14.3239
1684.39	18.269
1685.43	15.3057
1686.46	14.3242
1687.5	17.2835
1688.54	16.2869
1689.57	13.3155
1690.6	16.2803
1691.64	14.3109
1692.68	14.3026
1693.71	17.245
1694.74	17.2388
1695.78	15.2735
1696.81	16.2569
1697.85	16.242
1698.88	14.2672
1699.92	15.2502
1700.95	15.2464
1701.98	13.2695
1703.01	14.2474
1704.05	14.248
1705.08	16.2124
1706.11	12.2752
1707.14	18.1497
1708.18	16.1662
1709.21	16.1528
1710.24	16.1542
1711.27	15.1818
1712.3	15.1711
1713.33	15.1467
1714.36	14.1625
1715.4	13.1907
1716.43	14.1582
1717.46	13.1593
1718.49	17.0393
1719.52	14.1175
1720.55	16.0579
1721.58	16.0434
1722.61	13.1136
1723.64	15.0504
1724.66	16.9784
1725.69	12.1133
1726.72	13.0764
1727.75	15.9815
1728.78	14.9554
1729.81	13.0375
1730.83	14.9798
1731.86	14.9779
1732.89	14.0013
1733.92	13.0168
1734.95	11.0743
1735.97	16.8426
1737	12.0238
1738.03	15.8601
1739.05	12.9625
1740.08	12.9417
1741.1	13.8876
1742.13	14.8392
1743.16	14.835
1744.18	14.8257
1745.21	15.7819
1746.23	14.8129
1747.26	13.8435
1748.28	14.7963
1749.31	15.7592
1750.33	11.9484
1751.36	12.9017
1752.38	12.8889
1753.4	18.6032
1754.43	12.8696
1755.45	14.7673
1756.47	13.7988
1757.5	12.8402
1758.52	16.6523
1759.54	12.8461
1760.57	12.8405
1761.59	13.7835
1762.61	12.8364
1763.63	14.7403
1764.66	14.7536
1765.68	12.853
1766.7	11.8988
1767.72	14.7477
1768.74	14.7318
1769.76	14.7208
1770.78	12.8295
1771.8	13.7905
1772.82	13.7992
1773.84	14.7564
1774.86	17.6202
1775.88	11.9167
1776.9	13.8176
1777.92	15.7124
1778.94	13.7952
1779.96	15.7042
1780.98	10.9484
1782	13.813
1783.02	13.8207
1784.04	12.8768
1785.05	16.6965
1786.07	13.8324
1787.09	12.8912
1788.11	13.8797
1789.12	13.8946
1790.14	15.8184
1791.16	12.93
1792.18	12.9297
1793.19	11.0171
1794.21	13.892
1795.23	12.9579
1796.24	14.8887
1797.26	13.9383
1798.27	14.9044
1799.29	14.8973
1800.3	11.0468
1801.32	14.8883
1802.33	12.9732
1803.35	13.9444
1804.36	12.0278
1805.38	14.9288
1806.39	13.0104
1807.41	13.9754
1808.42	13.9771
1809.43	13.0155
1810.45	14.9434
1811.46	13.0147
1812.47	14.9499
1813.49	12.0633
1814.5	13.043
1815.51	14.0145
1816.53	14.9834
1817.54	13.0382
1818.55	15.945
1819.56	14.9849
1820.57	15.9592
1821.58	14.033
1822.6	14.0371
1823.61	13.0661
1824.62	13.0709
1825.63	15.0109
1826.64	14.0443
1827.65	15.0182
1828.66	13.0757
1829.67	15.0094
1830.68	18.8802
1831.69	13.0781
1832.7	15.0238
1833.71	13.0883
1834.72	16.9383
1835.73	16.9243
1836.74	15.0219
1837.75	14.9779
1838.75	14.0472
1839.76	15.014
1840.77	14.9782
1841.78	13.9898
1842.79	15.9162
1843.79	15.9146
1844.8	13.9859
1845.81	12.0715
1846.81	13.9656
1847.82	13.0076
1848.83	11.0709
1849.83	12.0185
1850.84	14.8884
1851.85	14.8835
1852.85	14.8825
1853.86	12.951
1854.86	14.8567
1855.87	11.9727
1856.87	13.8867
1857.88	13.8788
1858.88	11.9531
1859.89	13.863
1860.89	12.916
1861.9	11.0035
1862.9	12.9054
1863.9	11.9402
1864.91	13.8379
1865.91	13.8166
1866.92	14.7453
1867.92	13.7844
1868.92	14.7353
1869.92	14.7322
1870.93	12.8295
1871.93	12.8231
1872.93	16.613
1873.93	14.7056
1874.93	13.7424
1875.94	15.6132
1876.94	11.8112
1877.94	13.731
1878.94	14.6842
1879.94	15.6215
1880.94	12.7761
1881.94	13.6938
1882.94	11.8489
1883.94	13.6725
1884.94	14.624
1885.94	15.5835
1886.94	15.5693
1887.94	13.6663
1888.94	14.5914
1889.94	13.6527
1890.94	12.7141
1891.94	14.5956
1892.94	13.6376
1893.93	13.6258
1894.93	12.6837
1895.93	14.5703
1896.93	13.6388
1897.93	14.5781
1898.92	14.5658
1899.92	16.4386
1900.92	13.6273
1901.91	13.6394
1902.91	15.5167
1903.91	11.7524
1904.9	13.6309
1905.9	17.3773
1906.9	13.6159
1907.89	12.6831
1908.89	13.6295
1909.88	15.5286
1910.88	13.658
1911.87	13.657
1912.87	13.6572
1913.86	14.6136
1914.86	13.6817
1915.85	12.7373
1916.85	9.90037
1917.84	14.6143
1918.84	13.6867
1919.83	13.7015
1920.82	13.7076
1921.82	12.768
1922.81	14.6529
1923.8	11.8114
1924.79	13.7008
1925.79	11.8235
1926.78	15.6225
1927.77	12.7886
1928.76	19.4295
1929.75	13.7578
1930.75	15.6661
1931.74	13.7611
1932.73	18.4978
1933.72	15.6737
1934.71	12.8642
1935.7	14.7725
1936.69	16.6689
1937.68	16.6556
1938.67	14.7605
1939.66	12.8629
1940.65	14.7908
1941.64	12.8704
1942.63	13.8457
1943.62	13.8365
1944.61	10.9848
1945.6	13.8632
1946.59	15.781
1947.58	11.9528
1948.57	10.998
1949.55	15.7945
1950.54	14.8614
1951.53	14.8815
1952.52	14.8886
1953.5	13.9154
1954.49	12.933
1955.48	12.9423
1956.47	15.8429
1957.45	14.8947
1958.44	13.9365
1959.43	12.0087
1960.41	13.9211
1961.4	12.9556
1962.38	14.8779
1963.37	15.8405
1964.36	12.0025
1965.34	14.8845
1966.33	12.9744
1967.31	12.9773
1968.3	13.9388
1969.28	12.9644
1970.26	12.9542
1971.25	12.9484
1972.23	14.87
1973.22	14.8607
1974.2	14.8567
1975.18	12.9448
1976.17	12.9497
1977.15	13.9066
1978.13	12.9404
1979.12	11.9815
1980.1	13.8961
1981.08	13.889
1982.06	13.8853
1983.05	13.8727
1984.03	16.7367
1985.01	12.903
1985.99	11.9514
1986.97	12.9079
1987.95	16.7091
1988.93	12.8762
1989.91	11.0189
1990.89	15.4715
1991.88	12.2857
1992.86	14.4464
1993.84	12.6919
1994.82	12.6027
1995.8	12.3302
1996.78	12.2533
1997.76	14.6362
1998.73	14.0826
1999.71	14.6718
2000.69	13.2836
2001.67	14.5683
2002.65	14.3836
2003.63	13.7601
2004.6	14.4501
2005.58	15.217
2006.56	12.9189
2007.54	12.5612
2008.52	13.5239
2009.49	14.0155
2010.47	12.4124
2011.45	10.1927
2012.42	13.6502
2013.41	12.69
2014.4	16.4228
2015.39	12.675
2016.38	13.6285
2017.37	11.7405
2018.35	15.4737
2019.34	15.456
2020.33	14.5163
2021.32	11.7078
2022.31	11.7003
2023.29	15.4298
2024.28	12.6109
2025.27	11.6623
2026.25	14.4701
2027.24	15.4376
2028.23	12.6036
2029.21	11.6888
2030.2	15.3767
2031.19	12.5962
2032.17	15.4105
2033.16	10.7526
2034.14	15.3979
2035.13	14.4773
2036.11	14.4899
2037.1	12.6228
2038.08	15.42
2039.07	11.6741
2040.05	15.3939
2041.03	14.4502
2042.02	12.5795
2043	14.4458
2043.99	14.4605
2044.97	13.5184
2045.95	14.4956
2046.94	15.3977
2047.92	12.5856
2048.9	13.5265
2049.88	13.5431
2050.87	11.6755
2051.85	14.475
2052.83	11.6797
2053.81	11.6926
2054.79	11.692
2055.78	13.5559
2056.76	13.5538
2057.74	15.431
2058.72	11.7007
2059.7	12.6375
2060.68	14.5094
2061.66	12.6402
2062.64	12.6465
2063.62	13.5907
2064.6	13.5983
2065.58	12.6742
2066.56	10.8013
2067.54	10.8072
2068.52	13.6317
2069.5	13.6175
2070.48	14.5782
2071.46	17.4222
2072.43	14.5938
2073.41	15.5356
2074.39	10.8344
2075.37	15.5717
2076.35	12.7436
2077.32	11.7875
2078.3	14.624
2079.28	13.6953
2080.26	13.7028
2081.23	13.7
2082.21	14.6473
2083.19	14.6465
2084.16	13.7019
2085.14	12.7578
2086.12	15.6068
2087.09	14.6686
2088.07	12.7772
2089.04	13.7296
2090.02	15.6315
2090.99	14.6906
2091.97	12.8103
2092.94	13.7753
2093.92	14.7365
2094.89	15.6834
2095.87	14.7252
2096.84	13.7699
2097.81	13.7645
2098.79	11.8632
2099.76	16.6081
2100.74	11.8701
2101.71	14.7219
2102.68	10.9185
2103.65	13.764
2104.63	12.8216
2105.6	13.7815
2106.57	12.835
2107.54	12.8292
2108.52	15.6663
2109.49	14.7246
2110.46	12.8248
2111.43	15.6701
2112.4	14.7223
2113.38	12.8315
2114.35	13.7805
2115.32	12.828
2116.29	13.7704
2117.26	12.819
2118.23	14.7055
2119.2	15.6406
2120.17	14.6871
2121.14	15.6458
2122.11	14.7095
2123.08	13.7661
2124.05	15.6561
2125.02	17.5245
2125.98	15.6129
2126.95	14.6557
2127.92	13.7063
2128.89	13.705
2129.86	12.7571
2130.83	13.6962
2131.79	14.6334
2132.76	16.513
2133.73	14.6278
2134.7	14.6274
2135.67	13.6759
2136.63	14.613
2137.6	14.6176
2138.57	13.6736
2139.53	16.4904
2140.5	14.5987
2141.46	14.5919
2142.43	15.5368
2143.4	12.6843
2144.36	12.6991
2145.33	14.5737
2146.29	13.629
2147.26	14.5618
2148.22	14.5551
2149.19	13.6027
2150.15	14.5283
2151.12	13.5953
2152.08	13.599
2153.05	15.4656
2154.01	13.5802
2154.97	14.4932
2155.94	12.6118
2156.9	12.6117
2157.86	14.4882
2158.83	14.4848
2159.79	14.4724
2160.75	13.5305
2161.72	16.326
2162.68	14.4572
2163.64	12.5862
2164.6	13.5097
2165.56	14.444
2166.53	12.5734
2167.49	13.4897
2168.45	14.4104
2169.41	13.4934
2170.37	12.5718
2171.33	15.3456
2172.29	11.6143
2173.25	14.4015
2174.21	15.3353
2175.17	11.616
2176.13	14.3993
2177.09	13.47
2178.05	14.3945
2179.01	14.3917
2179.97	15.32
2180.93	13.4603
2181.89	14.3827
2182.85	13.447
2183.81	14.3622
2184.76	13.4377
2185.72	11.5906
2186.68	13.4593
2187.64	13.4667
2188.6	14.3838
2189.55	16.223
2190.51	13.4439
2191.47	12.5196
2192.42	11.5971
2193.38	14.3943
2194.34	14.4097
2195.3	13.4723
2196.25	14.3841
2197.21	13.4488
2198.16	14.3853
2199.12	17.1915
2200.07	13.4992
2201.03	13.5089
2201.99	15.3073
2202.94	11.6228
2203.9	13.5192
2204.85	15.3526
2205.8	14.4136
2206.76	14.4122
2207.71	14.4243
2208.67	13.5029
2209.62	13.5041
2210.58	17.2399
2211.53	12.5903
2212.48	14.4572
2213.44	15.3837
2214.39	13.5345
2215.34	15.4053
2216.29	15.4045
2217.25	14.4716
2218.2	14.4736
2219.15	15.4174
2220.1	15.4204
2221.06	13.5432
2222.01	16.3356
2222.96	15.4103
2223.91	16.363
2224.86	14.507
2225.81	14.5211
2226.76	11.7195
2227.72	14.5343
2228.67	16.4059
2229.62	18.2929
2230.57	12.6747
2231.52	14.5656
2232.47	11.7559
2233.42	13.6468
2234.37	10.8225
2235.31	13.6351
2236.26	15.5193
2237.21	13.6499
2238.16	15.5543
2239.11	12.7357
2240.06	14.6114
2241.01	14.6251
2241.96	14.6304
2242.9	12.7432
2243.85	12.7402
2244.8	13.7005
2245.75	14.6585
2246.69	13.7212
2247.64	13.7231
2248.59	13.7202
2249.53	14.6704
2250.48	15.6058
2251.43	14.6546
2252.37	13.7197
2253.32	13.7405
2254.26	11.8524
2255.21	12.8007
2256.16	15.6546
2257.1	14.7159
2258.05	14.7206
2258.99	12.8277
2259.94	13.7839
2260.88	12.8435
2261.83	11.896
2262.77	12.8586
2263.71	15.7389
2264.66	13.8471
2265.6	12.8953
2266.55	14.7926
2267.49	14.7827
2268.43	11.9205
2269.38	11.9333
2270.32	15.7683
2271.26	14.823
2272.2	14.8291
2273.15	15.7898
2274.09	14.8363
2275.03	12.9256
2275.97	15.8075
2276.92	14.8643
2277.86	12.9647
2278.8	15.8465
2279.74	12.9503
2280.68	15.8176
2281.62	12.941
2282.56	12.9517
2283.5	13.933
2284.44	16.8352
2285.38	12.9905
2286.32	15.8728
2287.26	14.9283
2288.2	13.0021
2289.14	14.9113
2290.08	13.9395
2291.02	15.8743
2291.96	14.9242
2292.9	15.9003
2293.84	15.901
2294.78	14.9283
2295.72	13.9573
2296.65	14.9152
2297.59	14.931
2298.53	15.9079
2299.47	15.9164
2300.41	14.9561
2301.34	14.9618
2302.28	15.9248
2303.22	13.0286
2304.15	13.036
2305.09	13.0429
2306.03	14.0149
2306.97	14.9804
2307.9	16.9069
2308.84	16.9132
2309.77	15.9616
2310.71	16.9245
2311.64	13.032
2312.58	13.9906
2313.51	15.938
2314.45	15.9598
2315.39	14.9855
2316.32	15.9325
2317.25	12.0739
2318.19	14.0005
2319.12	14.9574
2320.06	16.8868
2320.99	14.0003
2321.92	16.9154
2322.86	18.8529
2323.79	17.8889
2324.72	22.7032
2325.66	27.5104
2326.59	55.4559
2327.52	169.149
2328.46	99.7464
2329.39	34.1914
2330.32	22.6317
2331.25	18.7857
2332.18	15.8905
2333.12	13.9574
2334.05	17.7965
2334.98	15.8668
2335.91	15.8668
2336.84	15.8637
2337.77	15.8601
2338.7	13.9375
2339.63	14.8957
2340.56	14.8836
2341.49	13.9069
2342.42	14.8586
2343.35	14.8574
2344.28	12.9417
2345.21	15.8089
2346.14	12.9278
2347.07	14.8396
2348	16.7593
2348.93	12.9208
2349.85	14.8021
2350.78	15.7731
2351.71	15.7482
2352.64	13.8119
2353.57	11.9057
2354.5	14.7698
2355.42	14.7647
2356.35	15.6963
2357.28	15.6855
2358.21	13.7769
2359.13	13.7723
2360.06	16.6079
2360.99	12.7996
2361.91	11.839
2362.84	11.8299
2363.77	14.662
2364.69	14.6534
2364.92	13.7058