File: Data/3-Raman/raw/bu19(2)w-a-ff1-fi01-v_1800 (450-850nm)_532nm_edge_100%_x100_vis_lwd_h100um_30sx2_01.txt
#Acq. time (s)=	30
#Accumulations=	2
#Range (cm-¹)=	1200...2365
#Windows=	3
#Auto scanning=	Off
#Autofocus=	Off
#Macrospot=	Off
#AutoExposure=	Off
#Spike filter=	Multiple accum.
#Delay time (s)=	2
#Binning=	1
#Readout mode=	Signal
#DeNoise=	Off
#ICS correction=	On
#Dark correction=	Off
#Inst. Process=	Off
#Detector Gain=	Best Dynamic
#Detector ADC=	50 kHz HS
#Detector temperature (°C)=	-60.09
#Instrument=	LabRAM HR Evol
#Detector=	SIN-EM FIVIS
#Objective=	x100_VIS_LWD
#Grating=	1800 (450-850nm)
#ND Filter=	100%
#Laser=	532nm_Edge
#Hole=	100.021
#Temperature=	0
#Range=	Visible
#StageXY=	75x50mm Scan+
#StageZ=	Z motor
#X (µm)=	0
#Y (µm)=	0
#Z (µm)=	-47.2
#Full time(mm:ss)=	3:22
#Project=	21_11_26
#Sample=	BU19(2)w
#Site=
#Title=	BU19(2)w-A-FF1-FI01-V_1800 (450-850nm)_532nm_Edge_100%_x100_VIS_LWD_H100um_30sX2
#Remark=
#Date=	26.11.2021 11:36
#Acquired=	26.11.2021 11:36:17
1202.72	63.9874
1203.84	62.9284
1204.95	76.8505
1206.06	61.6993
1207.17	59.4297
1208.28	67.9209
1209.39	65.7019
1210.5	66.7309
1211.61	61.2837
1212.72	61.1907
1213.83	66.4485
1214.94	56.8488
1216.05	58.9576
1217.16	67.3659
1218.27	57.7249
1219.38	58.7401
1220.49	61.8868
1221.6	61.8562
1222.71	60.7056
1223.81	59.5264
1224.92	60.5041
1226.03	62.6096
1227.14	63.6433
1228.25	57.1701
1229.35	64.3798
1230.46	60.3304
1231.57	61.2016
1232.67	66.4454
1233.78	68.5226
1234.89	64.336
1235.99	61.2017
1237.1	65.3827
1238.2	65.2892
1239.31	67.2994
1240.41	62.0254
1241.52	68.3122
1242.62	65.1331
1243.73	69.3372
1244.83	68.2787
1245.94	66.1114
1247.04	69.2051
1248.14	72.3183
1249.25	79.5894
1250.35	76.4405
1251.45	69.0475
1252.56	79.43
1253.66	75.1911
1254.76	77.3123
1255.87	78.3592
1256.97	85.6782
1258.07	95.0462
1259.17	98.1188
1260.27	98.1729
1261.37	113.703
1262.48	144.262
1263.58	184.533
1264.68	188.251
1265.78	134.762
1266.88	105.492
1267.98	102.447
1269.08	102.575
1270.18	93.1382
1271.28	102.46
1272.38	102.461
1273.47	101.526
1274.57	102.663
1275.67	111.058
1276.77	102.734
1277.87	126.976
1278.97	124.979
1280.07	154.446
1281.16	249.108
1282.26	634.52
1283.36	1700.04
1284.45	2164.54
1285.55	760.183
1286.65	244.077
1287.75	166.072
1288.84	134.447
1289.94	117.669
1291.03	111.371
1292.13	111.349
1293.22	100.801
1294.32	93.5342
1295.42	97.7652
1296.51	94.792
1297.61	87.3714
1298.7	85.1991
1299.79	79.8655
1300.89	81.9917
1301.98	77.7694
1303.08	75.6677
1304.17	80.9082
1305.26	89.3364
1306.35	80.8096
1307.45	74.4557
1308.54	74.451
1309.63	75.5188
1310.73	72.355
1311.82	80.7995
1312.91	78.7167
1314	68.1255
1315.09	73.4003
1316.18	76.5973
1317.28	73.4061
1318.37	71.3065
1319.46	74.4692
1320.55	78.6859
1321.64	68.0632
1322.73	76.4289
1323.82	70.065
1324.91	72.1677
1326	67.8942
1327.09	66.719
1328.18	78.4162
1329.27	69.0055
1330.35	74.2606
1331.44	62.5928
1332.53	74.0692
1333.62	70.8065
1334.71	69.6659
1335.79	62.2536
1336.88	67.4466
1337.97	65.3132
1339.06	63.1567
1340.14	70.4744
1341.23	72.5645
1342.32	74.6201
1343.4	64.0844
1344.49	71.3892
1345.58	69.2541
1346.66	75.4092
1347.75	60.71
1348.83	70.0507
1349.92	67.9068
1351	61.5993
1352.09	63.6222
1353.17	70.9361
1354.25	72.0397
1355.34	71.8599
1356.42	68.7249
1357.51	79.0653
1358.59	77.9666
1359.67	72.7153
1360.76	81.9598
1361.84	80.8876
1362.92	83.953
1364	88.114
1365.09	83.9562
1366.17	90.0819
1367.25	88.9389
1368.33	88.9252
1369.41	152.009
1370.5	131.284
1371.58	89.8511
1372.66	95.8965
1373.74	90.6669
1374.82	99.8997
1375.9	99.8863
1376.98	118.365
1378.06	104.93
1379.14	119.526
1380.22	125.637
1381.3	138.734
1382.38	158.096
1383.46	183.503
1384.54	263.357
1385.61	473.968
1386.69	1667.79
1387.77	4982.31
1388.85	1552.42
1389.93	375.668
1391	202.83
1392.08	162.699
1393.16	135.943
1394.23	121.554
1395.31	103.118
1396.39	111.329
1397.46	103.077
1398.54	94.8616
1399.62	95.9153
1400.69	101.057
1401.77	95.9741
1402.84	109.446
1403.92	100.3
1404.99	114.582
1406.07	114.497
1407.14	147.254
1408.22	223.158
1409.29	306.286
1410.37	205.817
1411.44	111.319
1412.51	82.5993
1413.59	84.8742
1414.66	77.5793
1415.73	73.4988
1416.81	75.5669
1417.88	68.4007
1418.95	66.3484
1420.02	70.4318
1421.1	64.2055
1422.17	71.3871
1423.24	64.3278
1424.31	71.2802
1425.38	61.0181
1426.45	64.1033
1427.52	60.9544
1428.59	59.8617
1429.67	63.9665
1430.74	54.7882
1431.81	50.7452
1432.87	53.7841
1433.95	55.7409
1435.01	52.6771
1436.08	54.7165
1437.15	51.6165
1438.22	49.5448
1439.29	57.7485
1440.36	47.5303
1441.43	48.5597
1442.49	46.4938
1443.56	45.456
1444.63	48.5122
1445.7	51.6199
1446.77	46.4647
1447.83	43.3614
1448.9	45.4167
1449.97	44.3744
1451.03	45.3675
1452.1	40.2181
1453.17	44.3049
1454.23	46.3522
1455.3	43.265
1456.36	45.3158
1457.43	51.4343
1458.49	40.1477
1459.56	43.219
1460.62	36.0319
1461.69	40.1013
1462.75	45.1792
1463.82	37.9707
1464.88	44.1464
1465.94	45.0225
1467.01	39.8965
1468.07	38.8597
1469.13	37.8244
1470.2	37.789
1471.26	38.7776
1472.32	43.8373
1473.39	43.8199
1474.45	40.7351
1475.51	39.7148
1476.57	43.7603
1477.63	38.6431
1478.69	38.6183
1479.76	42.6459
1480.82	40.5584
1481.88	33.4312
1482.94	29.3855
1484	40.5519
1485.06	35.3871
1486.12	35.3662
1487.18	40.427
1488.24	41.4081
1489.3	43.3869
1490.36	37.2947
1491.42	38.2751
1492.48	40.2833
1493.53	33.1919
1494.59	37.2247
1495.65	34.1672
1496.71	36.1411
1497.77	37.1298
1498.82	32.0719
1499.88	37.1173
1500.94	35.0916
1502	30.0211
1503.05	37.0606
1504.11	39.0476
1505.17	39.0421
1506.22	40.0028
1507.28	37.9815
1508.34	35.9567
1509.39	35.9475
1510.45	44.0062
1511.5	36.9064
1512.56	37.8251
1513.61	41.7864
1514.67	38.7911
1515.72	30.7162
1516.78	38.6983
1517.83	37.6794
1518.88	32.6697
1519.94	36.6828
1520.99	31.6521
1522.05	36.6655
1523.1	38.6449
1524.15	35.5831
1525.2	41.5654
1526.26	41.574
1527.31	37.5781
1528.36	34.5472
1529.41	40.5336
1530.47	33.5018
1531.52	37.5237
1532.57	34.5022
1533.62	36.5376
1534.67	41.5494
1535.72	34.5006
1536.77	33.4384
1537.82	38.391
1538.87	34.3576
1539.92	38.4071
1540.97	38.4648
1542.02	31.4143
1543.07	35.3755
1544.12	30.3221
1545.17	36.3366
1546.22	37.3662
1547.27	35.3613
1548.32	37.3345
1549.37	34.2992
1550.42	39.3078
1551.46	38.4167
1552.51	42.4243
1553.56	37.3646
1554.61	40.3331
1555.65	36.2782
1556.7	34.2617
1557.75	35.2593
1558.79	38.2216
1559.84	40.165
1560.89	35.1364
1561.93	37.1326
1562.98	30.1433
1564.02	33.1268
1565.07	36.1478
1566.11	36.8979
1567.16	33.0582
1568.2	39.0739
1569.25	37.0742
1570.29	29.0492
1571.34	39.0319
1572.38	30.0125
1573.43	32.9772
1574.47	29.9688
1575.51	32.9882
1576.56	36.9804
1577.6	38.9196
1578.64	34.8733
1579.69	41.8392
1580.73	36.8563
1581.77	37.8251
1582.81	32.8109
1583.85	31.7979
1584.9	37.7661
1585.94	37.754
1586.98	28.7553
1588.02	35.6976
1589.06	36.6964
1590.1	38.6927
1591.14	36.7028
1592.18	33.6973
1593.22	37.632
1594.26	32.5963
1595.3	37.5606
1596.34	30.584
1597.38	41.5044
1598.42	37.5231
1599.46	36.4845
1600.5	32.4801
1601.54	30.4496
1602.58	35.3547
1603.62	34.3221
1604.66	33.315
1605.69	41.2191
1606.73	33.3152
1607.77	37.2131
1608.81	37.9873
1609.84	41.4299
1610.88	35.1897
1611.92	35.3902
1612.95	36.6288
1613.99	35.8503
1615.03	36.4887
1616.06	38.0942
1617.1	34.5239
1618.13	37.3075
1619.17	35.0887
1620.2	35.1146
1621.24	37.2357
1622.27	35.171
1623.31	37.0548
1624.34	36.8863
1625.38	34.6714
1626.41	34.6577
1627.45	38.5898
1628.48	36.5565
1629.51	37.0608
1630.55	35.5824
1631.53	37.108
1632.57	34.1578
1633.62	40.0571
1634.66	30.1996
1635.71	37.086
1636.75	37.0604
1637.8	40.9684
1638.84	36.0246
1639.89	33.0613
1640.93	34.0409
1641.98	36.9841
1643.02	34.0134
1644.06	37.9345
1645.11	37.9086
1646.15	37.9094
1647.19	36.9012
1648.24	37.8628
1649.28	34.9328
1650.32	39.8432
1651.37	41.8388
1652.41	32.9674
1653.45	38.8612
1654.49	37.8736
1655.53	37.8794
1656.57	32.9726
1657.62	33.9501
1658.66	36.8882
1659.7	35.8711
1660.74	35.8555
1661.78	34.8837
1662.82	35.8996
1663.86	33.9176
1664.9	36.8475
1665.94	37.7768
1666.98	34.8514
1668.02	37.7832
1669.06	33.8323
1670.1	33.846
1671.14	35.8372
1672.18	35.8207
1673.21	34.8258
1674.25	40.7564
1675.29	38.7904
1676.33	37.7996
1677.37	35.8135
1678.4	37.7651
1679.44	35.7534
1680.48	34.7422
1681.52	36.6962
1682.55	34.7093
1683.59	32.7211
1684.63	35.6659
1685.66	33.674
1686.7	30.7044
1687.73	34.6527
1688.77	37.59
1689.81	32.6203
1690.84	31.6154
1691.88	34.577
1692.91	33.5761
1693.95	38.4625
1694.98	34.4837
1696.01	34.4785
1697.05	27.5794
1698.08	31.4865
1699.12	36.3754
1700.15	36.3637
1701.18	32.4091
1702.22	34.3492
1703.25	34.3181
1704.28	36.2641
1705.32	38.2262
1706.35	35.2603
1707.38	36.1988
1708.41	34.1881
1709.44	37.0741
1710.48	34.1189
1711.51	34.1202
1712.54	35.0913
1713.57	31.1173
1714.6	30.0983
1715.63	33.9953
1716.66	33.9842
1717.69	38.8098
1718.72	31.9188
1719.75	37.7383
1720.78	32.8583
1721.81	32.82
1722.84	29.8626
1723.87	30.8016
1724.9	33.694
1725.93	36.546
1726.96	33.6152
1727.99	33.5951
1729.02	29.6519
1730.05	36.3731
1731.07	36.3416
1732.1	33.4742
1733.13	37.3142
1734.16	35.3255
1735.18	35.2712
1736.21	33.3023
1737.24	34.2388
1738.26	34.2087
1739.29	36.0905
1740.32	38.9032
1741.34	33.0994
1742.37	36.8962
1743.4	33.0459
1744.42	37.8026
1745.45	34.9149
1746.47	34.8914
1747.5	33.8889
1748.52	33.8584
1749.55	36.7202
1750.57	36.7395
1751.6	35.789
1752.62	30.9695
1753.64	32.8417
1754.67	35.6669
1755.69	36.5907
1756.71	34.6436
1757.74	35.5483
1758.76	35.5495
1759.78	38.3976
1760.81	36.4742
1761.83	41.194
1762.85	38.3287
1763.87	40.2248
1764.89	36.4385
1765.92	36.4446
1766.94	38.3357
1767.96	38.3138
1768.98	35.4334
1770	33.46
1771.02	36.3176
1772.04	37.2882
1773.06	41.1053
1774.08	38.2575
1775.1	32.5464
1776.12	38.2867
1777.14	33.5104
1778.16	39.1944
1779.18	34.3924
1780.2	39.1345
1781.22	34.3775
1782.24	40.091
1783.26	29.6255
1784.28	35.3511
1785.29	35.3649
1786.31	39.1609
1787.33	30.5804
1788.35	40.1901
1789.37	34.4933
1790.38	35.4724
1791.4	32.5824
1792.42	32.5468
1793.43	35.4207
1794.45	32.5433
1795.47	34.4803
1796.48	30.6681
1797.5	30.6818
1798.51	31.6485
1799.53	30.6739
1800.55	34.486
1801.56	33.5049
1802.58	33.5015
1803.59	31.5925
1804.61	31.5966
1805.62	31.6132
1806.64	34.5189
1807.65	31.6267
1808.66	32.5822
1809.68	34.5047
1810.69	34.499
1811.7	34.4842
1812.72	31.5867
1813.73	35.4521
1814.74	35.4745
1815.76	34.5253
1816.77	33.5561
1817.78	35.458
1818.79	35.4536
1819.8	36.4207
1820.82	31.5923
1821.83	36.4357
1822.84	25.7934
1823.85	34.495
1824.86	33.5182
1825.87	28.6783
1826.88	34.4807
1827.89	33.5119
1828.9	31.563
1829.91	33.4798
1830.92	33.4562
1831.93	35.3961
1832.94	35.4072
1833.95	29.5905
1834.96	31.4978
1835.97	33.3737
1836.98	31.5455
1837.99	33.3706
1839	33.3577
1840	33.3938
1841.01	35.2519
1842.02	28.4185
1843.03	36.1004
1844.04	33.1961
1845.04	31.2576
1846.05	31.2565
1847.06	32.2431
1848.07	35.0089
1849.07	32.1169
1850.08	29.1954
1851.09	30.1097
1852.09	31.0396
1853.1	31.9876
1854.1	31.9643
1855.11	31.9201
1856.11	28.0469
1857.12	32.8213
1858.12	34.7134
1859.13	31.8042
1860.13	34.6392
1861.14	32.7311
1862.14	29.868
1863.15	28.8814
1864.15	29.8007
1865.15	32.6322
1866.16	36.3941
1867.16	32.5135
1868.16	28.6583
1869.17	35.2996
1870.17	27.6783
1871.17	29.5639
1872.17	29.5423
1873.18	28.564
1874.18	34.2365
1875.18	33.2459
1876.18	28.4516
1877.18	32.1937
1878.18	33.0808
1879.19	30.2881
1880.19	32.1961
1881.19	30.2884
1882.19	29.2873
1883.19	32.9877
1884.19	28.2293
1885.19	34.8339
1886.19	33.925
1887.19	31.0782
1888.19	31.9803
1889.19	31.926
1890.19	31.8972
1891.19	30.9653
1892.18	29.0647
1893.18	29.0411
1894.18	31.8048
1895.18	28.0217
1896.18	33.6592
1897.18	29.9101
1898.17	29.908
1899.17	33.6403
1900.17	28.9089
1901.16	35.4741
1902.16	31.7312
1903.16	31.7332
1904.16	27.9496
1905.15	30.7547
1906.15	33.5512
1907.14	32.5776
1908.14	34.45
1909.14	34.4552
1910.13	33.5368
1911.13	34.5103
1912.12	31.6844
1913.12	28.8433
1914.11	30.7319
1915.11	31.6959
1916.1	28.8671
1917.1	30.7284
1918.09	31.6454
1919.08	33.5434
1920.08	35.4708
1921.07	29.7982
1922.06	35.4871
1923.06	30.744
1924.05	32.6109
1925.04	32.5844
1926.04	29.7612
1927.03	30.7322
1928.02	29.7948
1929.01	29.7978
1930	32.6579
1931	33.6333
1931.99	32.6703
1932.98	28.8459
1933.97	30.7386
1934.96	33.6755
1935.95	31.8339
1936.94	31.7922
1937.93	33.6575
1938.92	30.7895
1939.91	31.7501
1940.9	32.7161
1941.89	31.7828
1942.88	33.696
1943.87	27.9412
1944.86	33.6804
1945.85	31.7928
1946.84	27.9793
1947.83	30.8334
1948.82	33.6877
1949.8	27.9595
1950.79	32.7808
1951.78	28.9846
1952.77	32.8409
1953.76	33.7954
1954.74	28.9183
1955.73	32.7247
1956.72	31.8126
1957.7	31.8338
1958.69	37.6075
1959.68	33.7414
1960.66	34.6739
1961.65	26.961
1962.63	33.67
1963.62	28.8658
1964.61	31.746
1965.59	31.7321
1966.58	37.5041
1967.56	33.6679
1968.55	32.7027
1969.53	32.6742
1970.52	32.6263
1971.5	37.3927
1972.48	35.4637
1973.47	35.4457
1974.45	33.4953
1975.44	35.4053
1976.42	32.537
1977.4	39.244
1978.39	35.3784
1979.37	36.3152
1980.35	35.3501
1981.33	32.446
1982.31	40.0857
1983.3	30.4785
1984.28	38.0987
1985.26	33.2898
1986.24	35.1801
1987.22	37.0952
1988.21	33.2349
1989.19	36.0322
1990.17	35.7409
1991.15	34.4321
1992.13	38.1986
1993.11	32.7374
1994.09	38.585
1995.07	39.8922
1996.05	36.467
1997.03	36.8418
1998.01	40.0158
1998.99	39.5128
1999.97	36.8743
2000.95	40.0332
2001.92	38.8935
2002.9	38.6951
2003.88	42.7003
2004.86	38.094
2005.84	37.1058
2006.81	41.0531
2007.79	40.7717
2008.77	43.0038
2009.75	38.9491
2010.73	37.2748
2011.7	35.2629
2012.68	32.9557
2013.67	35.7377
2014.66	33.7996
2015.64	40.3527
2016.63	38.4885
2017.62	37.5705
2018.61	33.7641
2019.6	33.7115
2020.58	36.5036
2021.57	33.6913
2022.56	38.3606
2023.55	37.3867
2024.54	38.2868
2025.52	35.4334
2026.51	35.4015
2027.5	33.6185
2028.48	37.3135
2029.47	34.5611
2030.45	37.2534
2031.44	35.3999
2032.43	37.2692
2033.41	40.1164
2034.4	34.5096
2035.38	29.7882
2036.37	33.5882
2037.35	35.4452
2038.34	33.5624
2039.32	32.6044
2040.31	35.3741
2041.29	34.4041
2042.27	33.4532
2043.26	34.3679
2044.24	31.6054
2045.23	32.5161
2046.21	31.644
2047.19	30.6785
2048.17	33.4337
2049.16	30.6415
2050.14	33.4722
2051.12	30.691
2052.11	27.8693
2053.09	29.7431
2054.07	32.5766
2055.05	31.6484
2056.03	31.6303
2057.01	27.8782
2058	31.6212
2058.98	33.5133
2059.96	34.462
2060.94	30.703
2061.92	34.4569
2062.9	34.4615
2063.88	27.9196
2064.86	28.8644
2065.84	35.4571
2066.82	29.8413
2067.8	29.8508
2068.78	30.8011
2069.76	30.7897
2070.73	27.9646
2071.71	30.7998
2072.69	35.5469
2073.67	32.7131
2074.65	30.8343
2075.63	32.7544
2076.6	29.9544
2077.58	28.9929
2078.56	30.8694
2079.54	30.8829
2080.51	30.91
2081.49	31.8506
2082.47	29.9575
2083.45	29.9581
2084.42	33.7326
2085.4	29.0057
2086.37	37.5197
2087.35	34.7067
2088.32	30.9277
2089.3	29.0364
2090.28	30.947
2091.25	31.9011
2092.23	32.8701
2093.2	31.0084
2094.18	30.0837
2095.15	32.9382
2096.13	29.1158
2097.1	29.1048
2098.07	30.0331
2099.05	29.0734
2100.02	30.9637
2101	31.9154
2101.97	28.1325
2102.94	30.9762
2103.92	29.0588
2104.89	30.96
2105.86	29.0773
2106.83	34.7905
2107.8	29.085
2108.78	31.9025
2109.75	29.0499
2110.72	31.9026
2111.69	29.9968
2112.66	31.8837
2113.63	29.0474
2114.61	30.949
2115.58	29.9951
2116.55	29.9784
2117.52	32.8125
2118.49	29.949
2119.46	33.7093
2120.43	28.9433
2121.4	28.9465
2122.37	32.7632
2123.34	28.0325
2124.31	28.9763
2125.28	30.8317
2126.25	30.7864
2127.21	28.8641
2128.18	29.7944
2129.15	30.7314
2130.12	31.6659
2131.09	26.9295
2132.06	31.6323
2133.02	31.6103
2133.99	30.6622
2134.96	29.7167
2135.93	28.7635
2136.89	27.7912
2137.86	24.9647
2138.83	31.5504
2139.79	30.6115
2140.76	33.409
2141.73	26.8046
2142.69	28.6701
2143.66	27.7462
2144.62	30.5096
2145.59	23.9259
2146.55	31.4387
2147.52	32.3623
2148.48	30.465
2149.45	30.4432
2150.42	26.6545
2151.38	27.582
2152.34	25.7161
2153.31	24.7666
2154.27	23.8135
2155.24	26.5842
2156.2	32.153
2157.16	28.4013
2158.13	28.4089
2159.09	30.2789
2160.05	25.5873
2161.01	29.2939
2161.98	28.3471
2162.94	31.1407
2163.9	27.3938
2164.86	31.0985
2165.83	27.3672
2166.79	27.3582
2167.75	26.404
2168.71	26.3644
2169.67	31.0206
2170.63	31.0549
2171.59	30.1122
2172.56	26.3416
2173.51	30.0451
2174.48	31.9085
2175.44	28.1884
2176.4	32.8248
2177.36	30.9536
2178.32	26.3069
2179.28	30.9302
2180.23	28.1432
2181.19	28.135
2182.15	27.1944
2183.11	28.1085
2184.07	29.0062
2185.03	30.8468
2185.99	30.8546
2186.95	29.9481
2187.9	28.1198
2188.86	26.2479
2189.82	24.3622
2190.78	27.1294
2191.73	30.8408
2192.69	28.0652
2193.65	32.7189
2194.6	28.1153
2195.56	29.0386
2196.52	27.1494
2197.47	28.0487
2198.43	26.1898
2199.38	24.3582
2200.34	31.8298
2201.3	27.2216
2202.25	31.7726
2203.21	29.9628
2204.16	28.1988
2205.12	30.9405
2206.07	29.9344
2207.03	27.1395
2207.98	29.0127
2208.93	28.1018
2209.89	27.1759
2210.84	29.0432
2211.8	28.1262
2212.75	28.1411
2213.7	24.3961
2214.66	33.734
2215.61	23.4831
2216.56	26.2821
2217.51	30.9437
2218.47	28.1416
2219.42	24.4148
2220.37	26.2933
2221.32	29.088
2222.27	28.1248
2223.23	29.9906
2224.18	27.2091
2225.13	28.17
2226.08	26.321
2227.03	27.2757
2227.98	27.2871
2228.93	26.3397
2229.88	29.151
2230.83	28.2346
2231.78	30.1351
2232.73	31.0957
2233.68	28.2927
2234.63	30.183
2235.58	28.2767
2236.53	32.0316
2237.48	29.2183
2238.43	29.2555
2239.38	25.5139
2240.33	29.2718
2241.27	28.3381
2242.22	29.2864
2243.17	29.2932
2244.12	26.4474
2245.07	32.121
2246.01	26.4844
2246.96	26.4992
2247.91	26.5079
2248.85	30.285
2249.8	32.1753
2250.75	26.4885
2251.69	24.5742
2252.64	27.4142
2253.59	28.3975
2254.53	25.576
2255.48	30.3163
2256.42	26.5273
2257.37	31.288
2258.32	23.7032
2259.26	29.408
2260.2	28.4676
2261.15	25.6247
2262.1	27.5408
2263.04	26.6
2263.98	26.6271
2264.93	27.6159
2265.87	27.6309
2266.81	31.4334
2267.76	25.6817
2268.7	27.57
2269.65	29.4929
2270.59	26.6605
2271.53	29.5446
2272.47	27.6448
2273.42	24.7762
2274.36	29.5637
2275.3	26.6953
2276.24	26.6985
2277.18	26.7196
2278.13	25.7919
2279.07	30.6082
2280.01	26.7437
2280.95	31.5085
2281.89	27.6572
2282.83	32.4633
2283.77	31.5375
2284.71	30.6241
2285.65	28.7163
2286.59	28.6962
2287.54	28.7246
2288.47	30.6615
2289.41	31.5971
2290.35	31.5539
2291.29	29.6301
2292.23	27.7316
2293.17	33.5315
2294.11	27.7621
2295.05	30.6341
2295.99	29.651
2296.93	29.6237
2297.86	29.6395
2298.8	25.8109
2299.74	30.6524
2300.68	28.7221
2301.61	34.5253
2302.55	27.7651
2303.49	27.7586
2304.43	24.8669
2305.36	26.8108
2306.3	23.9185
2307.24	29.7189
2308.17	25.841
2309.11	28.7329
2310.04	27.7883
2310.98	24.8916
2311.92	27.7474
2312.85	29.6484
2313.79	29.6535
2314.72	31.6218
2315.66	28.7368
2316.59	30.6291
2317.52	33.5107
2318.46	30.6156
2319.39	29.6281
2320.33	26.7204
2321.26	32.5155
2322.2	31.5743
2323.13	31.5911
2324.06	37.3976
2325	39.3165
2325.93	51.8233
2326.86	74.9329
2327.79	207.91
2328.73	347.623
2329.66	114.293
2330.59	60.3428
2331.52	43.959
2332.46	30.4812
2333.39	32.3846
2334.32	33.3284
2335.25	33.3022
2336.18	28.4909
2337.11	32.3265
2338.04	27.5096
2338.97	31.3454
2339.91	27.4982
2340.84	26.5191
2341.77	24.5646
2342.7	25.5004
2343.63	32.2026
2344.56	28.3646
2345.49	27.3981
2346.41	27.3728
2347.34	30.2345
2348.27	27.3583
2349.2	26.4001
2350.13	30.1809
2351.06	30.0337
2351.99	32.0622
2352.91	30.102
2353.84	25.2916
2354.77	26.2417
2355.7	29.0979
2356.63	28.1218
2357.55	27.1326
2358.48	29.0147
2359.41	27.0977
2360.33	28.0283
2361.26	28.9471
2362.19	28.9144
2363.11	26.0425
2364.04	29.8089
2364.97	24.1147