File: Data/3-Raman/raw/bu19w-d-ffore2-fi13-v_1800 (450-850nm)_532nm_edge_100%_x100_vis_lwd_h50um_30sx2_01.txt
#Acq. time (s)=	30
#Accumulations=	2
#Range (cm-¹)=	1200...2365
#Windows=	3
#Auto scanning=	Off
#Autofocus=	Off
#Macrospot=	Off
#AutoExposure=	Off
#Spike filter=	Multiple accum.
#Delay time (s)=	2
#Binning=	1
#Readout mode=	Signal
#DeNoise=	Off
#ICS correction=	On
#Dark correction=	Off
#Inst. Process=	Off
#Detector Gain=	Best Dynamic
#Detector ADC=	50 kHz HS
#Detector temperature (°C)=	-60.09
#Instrument=	LabRAM HR Evol
#Detector=	SIN-EM FIVIS
#Objective=	x100_VIS_LWD
#Grating=	1800 (450-850nm)
#ND Filter=	100%
#Laser=	532nm_Edge
#Hole=	49.98
#Temperature=	0
#Range=	Visible
#StageXY=	75x50mm Scan+
#StageZ=	Z motor
#X (µm)=	0
#Y (µm)=	0
#Z (µm)=	14.4
#Full time(mm:ss)=	3:22
#Project=	21_11_22
#Sample=	BU19w
#Site=
#Title=	BU19w-D-FFore2-FI13-V_1800 (450-850nm)_532nm_Edge_100%_x100_VIS_LWD_H50um_30sX2
#Remark=
#Date=	22.11.2021 14:06
#Acquired=	22.11.2021 14:06:00
1202.84	31.6723
1203.95	30.5325
1205.06	28.35
1206.17	31.521
1207.29	27.2228
1208.39	28.2413
1209.51	29.2601
1210.62	29.2245
1211.72	28.1476
1212.84	33.4577
1213.94	28.0868
1215.05	26.985
1216.16	30.1428
1217.27	27.9998
1218.38	20.5608
1219.49	31.1161
1220.6	27.8784
1221.71	29.9495
1222.81	30.9978
1223.92	28.8737
1225.03	26.695
1226.14	29.7737
1227.24	31.9569
1228.35	35.0109
1229.46	28.6955
1230.56	29.7315
1231.67	31.836
1232.78	28.689
1233.88	28.6756
1234.99	28.6314
1236.09	25.4428
1237.2	27.5217
1238.3	29.6131
1239.41	28.5456
1240.51	28.5473
1241.62	29.5873
1242.72	32.6952
1243.83	29.5267
1244.93	29.5124
1246.03	28.4408
1247.14	31.57
1248.24	27.3544
1249.34	28.3706
1250.45	28.3423
1251.55	25.217
1252.65	29.3909
1253.75	31.4778
1254.86	26.2414
1255.96	27.2633
1257.06	28.3183
1258.16	24.105
1259.26	26.2345
1260.36	28.2428
1261.46	34.6099
1262.56	29.3402
1263.66	30.376
1264.76	32.4895
1265.86	31.4783
1266.96	27.2818
1268.06	32.4803
1269.16	30.3807
1270.26	33.5527
1271.36	26.2355
1272.46	31.4758
1273.56	30.442
1274.66	28.3578
1275.76	29.4277
1276.85	31.5303
1277.95	28.3656
1279.05	30.4829
1280.15	29.4126
1281.24	35.6744
1282.34	66.2888
1283.44	99.9715
1284.53	49.3928
1285.63	34.6368
1286.73	30.4367
1287.82	30.4381
1288.92	28.3199
1290.01	25.1505
1291.11	28.3354
1292.21	31.4983
1293.3	29.4443
1294.4	28.3766
1295.49	27.2944
1296.58	29.3838
1297.68	30.4399
1298.77	25.1555
1299.87	26.2111
1300.96	28.3045
1302.05	29.3495
1303.15	27.2058
1304.24	25.082
1305.33	29.2952
1306.42	26.13
1307.52	27.1817
1308.61	24.0113
1309.7	28.2387
1310.79	28.2217
1311.88	28.2155
1312.98	23.9972
1314.07	19.761
1315.16	29.2664
1316.25	30.3164
1317.34	26.0826
1318.43	28.1681
1319.52	28.1331
1320.61	27.0596
1321.7	27.0532
1322.79	24.9203
1323.88	25.9197
1324.97	32.2792
1326.06	27.0373
1327.15	31.2447
1328.23	25.9398
1329.32	23.7877
1330.41	30.0541
1331.5	22.6609
1332.59	25.7804
1333.67	26.804
1334.76	25.7366
1335.85	25.7076
1336.94	28.8392
1338.02	25.6918
1339.11	25.6738
1340.2	26.688
1341.28	26.6768
1342.37	27.7016
1343.45	23.4784
1344.54	25.5255
1345.63	24.4621
1346.71	26.5189
1347.8	29.6113
1348.88	25.4203
1349.96	26.4684
1351.05	24.4087
1352.13	27.4562
1353.22	27.4448
1354.3	27.422
1355.39	30.5095
1356.47	30.4789
1357.55	26.2963
1358.63	29.3863
1359.72	26.2604
1360.8	27.2964
1361.88	28.3229
1362.97	33.4639
1364.05	28.2499
1365.13	29.2729
1366.21	26.1711
1367.29	24.0885
1368.37	27.1578
1369.45	33.2965
1370.54	33.2639
1371.62	31.184
1372.7	31.1743
1373.78	28.0629
1374.86	30.101
1375.94	33.2374
1377.02	39.3957
1378.09	40.33
1379.18	40.2809
1380.25	45.3419
1381.33	42.2298
1382.41	41.2354
1383.49	38.1817
1384.57	46.2725
1385.65	55.4948
1386.72	180.894
1387.8	68.8488
1388.88	38.045
1389.96	33.9106
1391.03	31.8421
1392.11	26.7148
1393.19	30.8104
1394.26	29.7631
1395.34	28.7246
1396.42	22.5889
1397.49	29.7546
1398.57	24.6402
1399.64	27.7474
1400.72	29.8213
1401.79	28.7655
1402.87	25.6622
1403.94	27.6957
1405.02	30.7717
1406.09	25.6451
1407.17	29.7471
1408.24	39.9559
1409.31	32.7667
1410.39	27.7164
1411.46	25.619
1412.53	27.6781
1413.61	31.787
1414.68	26.657
1415.75	26.6543
1416.82	24.5849
1417.9	26.6095
1418.97	28.6552
1420.04	23.5645
1421.11	28.606
1422.18	29.6186
1423.26	21.4166
1424.33	24.4608
1425.4	28.5232
1426.47	26.4752
1427.54	25.4663
1428.61	23.44
1429.68	26.4961
1430.75	27.4715
1431.82	28.4973
1432.89	23.3659
1433.96	26.4235
1435.02	21.2875
1436.09	24.3606
1437.16	26.4215
1438.23	29.4982
1439.3	34.6136
1440.37	29.4775
1441.43	30.4875
1442.5	29.4794
1443.57	26.3844
1444.64	24.3155
1445.7	28.4175
1446.77	25.329
1447.84	27.3579
1448.9	25.2904
1449.97	22.2072
1451.04	27.327
1452.1	24.2429
1453.17	24.2408
1454.23	27.2961
1455.3	25.2344
1456.36	23.1819
1457.43	23.1705
1458.49	25.1996
1459.56	27.2198
1460.62	26.1636
1461.69	27.2091
1462.75	28.1388
1463.81	27.1008
1464.88	20.9667
1465.94	27.0755
1467	23.9911
1468.07	23.9696
1469.13	25.9843
1470.19	23.9354
1471.25	24.9325
1472.32	22.8933
1473.38	25.9291
1474.44	25.9074
1475.5	27.9227
1476.56	25.8633
1477.62	25.8258
1478.68	25.8071
1479.75	22.7727
1480.81	25.816
1481.87	22.7122
1482.93	27.7598
1483.99	26.7429
1485.05	23.6825
1486.11	20.6179
1487.17	22.6269
1488.22	25.6393
1489.28	26.6395
1490.34	24.6061
1491.4	23.5861
1492.46	22.5577
1493.52	26.5638
1494.58	20.4921
1495.63	23.5104
1496.69	28.5554
1497.75	24.5118
1498.81	20.4566
1499.86	24.4755
1500.92	26.4703
1501.98	22.4318
1503.03	25.4244
1504.09	23.4034
1505.15	18.3575
1506.2	26.4108
1507.26	20.3605
1508.31	25.3671
1509.37	25.306
1510.42	26.2713
1511.48	23.2675
1512.53	23.2377
1513.59	24.2091
1514.64	24.1968
1515.7	29.2138
1516.75	25.2012
1517.8	23.1833
1518.86	21.1732
1519.91	21.1552
1520.96	23.1247
1522.02	20.1011
1523.07	24.1096
1524.12	28.1252
1525.17	26.1019
1526.23	26.0833
1527.28	26.0669
1528.33	25.0754
1529.38	26.0651
1530.43	25.0839
1531.48	22.071
1532.53	23.0547
1533.59	26.0157
1534.64	21.976
1535.69	25.9518
1536.74	21.9805
1537.79	22.0125
1538.84	25.9981
1539.89	24.961
1540.94	22.9217
1541.98	23.9297
1543.03	28.9551
1544.08	24.9464
1545.13	23.9231
1546.18	20.8983
1547.23	19.8953
1548.28	25.9772
1549.33	25.9696
1550.37	19.9214
1551.42	23.9073
1552.47	26.8809
1553.52	15.8523
1554.56	23.8613
1555.61	30.8393
1556.65	24.7942
1557.7	23.7728
1558.75	25.7684
1559.79	24.7754
1560.84	27.7616
1561.88	27.778
1562.93	23.6068
1563.98	23.7091
1565.02	25.7208
1566.07	22.7199
1567.11	28.6953
1568.15	23.6895
1569.2	23.6693
1570.24	26.6401
1571.29	22.6358
1572.33	28.6468
1573.37	23.6467
1574.42	27.6004
1575.46	23.5694
1576.5	21.5654
1577.55	24.556
1578.59	26.5293
1579.63	22.5197
1580.67	26.4908
1581.72	26.484
1582.76	24.4822
1583.8	29.4299
1584.84	22.4451
1585.88	23.4409
1586.92	25.4338
1587.96	30.4132
1589	29.4025
1590.04	26.3801
1591.08	22.3565
1592.12	30.3012
1593.16	24.3224
1594.2	24.3172
1595.24	30.2707
1596.28	32.2184
1597.32	22.268
1598.36	27.1866
1599.4	28.1382
1600.44	26.1252
1601.48	28.088
1602.51	26.1051
1603.55	24.1315
1604.59	31.0551
1605.63	24.1182
1606.66	29.0285
1607.7	20.2535
1608.74	28.6415
1609.77	28.2603
1610.81	24.1662
1611.85	27.9688
1612.88	28.236
1613.92	25.6173
1614.95	24.9036
1615.99	28.3341
1617.03	26.697
1618.06	24.0561
1619.1	25.6044
1620.13	26.1247
1621.17	24.9988
1622.2	25.9444
1623.23	25.6651
1624.27	29.1879
1625.3	28.3997
1626.34	25.323
1627.37	25.1577
1628.4	26.7512
1629.44	27.5055
1630.47	28.5007
1631.29	26.8146
1632.33	22.8639
1633.38	28.7593
1634.42	24.7962
1635.47	27.7339
1636.51	28.7089
1637.56	24.7641
1638.6	24.7612
1639.65	26.7159
1640.69	27.6888
1641.73	20.7817
1642.78	25.6998
1643.82	23.7155
1644.86	23.6991
1645.91	26.6531
1646.95	25.6709
1647.99	25.6827
1649.03	27.6537
1650.08	25.6698
1651.12	28.6218
1652.16	27.6368
1653.2	26.6712
1654.24	28.6425
1655.28	24.6781
1656.33	25.6432
1657.37	27.598
1658.41	25.6348
1659.45	23.6515
1660.49	25.6612
1661.53	25.6269
1662.57	29.5429
1663.61	21.6949
1664.65	25.5938
1665.69	26.5651
1666.72	23.6219
1667.76	24.6163
1668.8	25.5947
1669.84	24.6023
1670.88	27.5642
1671.92	25.5913
1672.96	22.6244
1674	25.5879
1675.03	23.5925
1676.07	24.5568
1677.11	22.5627
1678.15	27.4866
1679.18	25.5011
1680.22	22.5283
1681.25	26.4681
1682.29	27.4401
1683.33	28.4203
1684.36	27.4347
1685.4	24.4533
1686.43	27.3903
1687.47	23.4228
1688.51	25.3978
1689.54	19.4711
1690.58	20.4325
1691.61	22.3774
1692.64	23.3548
1693.68	21.3837
1694.71	23.3324
1695.75	24.2909
1696.78	21.3276
1697.81	23.2825
1698.85	21.2986
1699.88	25.2064
1700.91	23.2273
1701.95	22.2409
1702.98	22.2298
1704.01	25.1477
1705.04	22.1718
1706.08	22.1358
1707.11	20.1613
1708.14	19.1797
1709.17	22.1141
1710.2	24.0338
1711.23	22.043
1712.27	20.076
1713.3	21.0498
1714.33	22.9719
1715.36	22.9249
1716.39	21.9303
1717.42	22.8963
1718.45	21.8976
1719.48	23.8129
1720.51	19.9006
1721.54	25.7132
1722.56	22.7646
1723.59	21.7746
1724.62	20.786
1725.65	18.8273
1726.68	20.7057
1727.71	20.6945
1728.74	21.6757
1729.76	19.7284
1730.79	21.6283
1731.82	22.5562
1732.85	22.524
1733.87	20.5811
1734.9	20.5619
1735.93	21.4981
1736.95	20.5008
1737.98	24.3
1739.01	26.1881
1740.03	22.3424
1741.06	18.4976
1742.08	20.3965
1743.11	22.2968
1744.13	21.3115
1745.16	18.4225
1746.18	18.4167
1747.21	21.2881
1748.23	21.2926
1749.26	18.4022
1750.28	23.1505
1751.31	19.3105
1752.33	23.1036
1753.35	20.2203
1754.38	21.1406
1755.4	21.1361
1756.42	23.9855
1757.44	20.1677
1758.47	23.0003
1759.49	18.2322
1760.51	21.0804
1761.53	23.9374
1762.56	21.0889
1763.58	20.1295
1764.6	18.2127
1765.62	20.0994
1766.64	21.9565
1767.66	17.2055
1768.68	21.965
1769.7	21.0171
1770.72	21.0188
1771.74	21.9687
1772.76	20.0749
1773.78	20.0717
1774.8	24.8151
1775.82	19.0762
1776.84	22.8631
1777.86	19.0582
1778.88	16.1987
1779.9	23.8242
1780.92	19.0614
1781.94	22.8832
1782.95	20.9642
1783.97	20.0073
1784.99	20.0309
1786.01	14.3128
1787.03	19.1106
1788.04	21.0234
1789.06	20.9942
1790.08	20.9918
1791.09	19.0723
1792.11	20.0306
1793.13	18.1326
1794.14	21.982
1795.16	21.0251
1796.17	20.0566
1797.19	22.918
1798.21	19.0593
1799.22	23.8566
1800.24	21.9412
1801.25	20.9822
1802.27	21.9533
1803.28	19.0741
1804.29	22.9283
1805.31	21.9575
1806.32	19.0606
1807.34	21.9479
1808.35	19.0452
1809.36	19.0383
1810.38	22.8996
1811.39	21.9435
1812.4	20.9893
1813.41	20.0193
1814.43	23.8727
1815.44	21.9239
1816.45	19.992
1817.46	18.0592
1818.47	19.9948
1819.49	19.9966
1820.5	19.9906
1821.51	20.949
1822.52	16.1073
1823.53	19.006
1824.54	23.8459
1825.55	21.9034
1826.56	20.9188
1827.57	19.9352
1828.58	19.9315
1829.59	20.9031
1830.6	25.7492
1831.61	22.8288
1832.62	20.8462
1833.63	21.9077
1834.64	17.9405
1835.65	18.8651
1836.65	23.753
1837.66	18.872
1838.67	22.6896
1839.68	20.7232
1840.69	19.7536
1841.7	19.746
1842.7	21.6676
1843.71	19.763
1844.72	17.7534
1845.72	19.6781
1846.73	19.6555
1847.74	19.6222
1848.74	18.6386
1849.75	21.509
1850.75	17.6553
1851.76	15.7096
1852.76	17.6024
1853.77	15.6744
1854.78	18.5341
1855.78	20.4255
1856.79	17.5315
1857.79	16.573
1858.79	21.3604
1859.8	19.4289
1860.8	19.4027
1861.81	13.6505
1862.81	17.4418
1863.81	18.3562
1864.82	20.2227
1865.82	18.3083
1866.82	18.2982
1867.83	19.2369
1868.83	17.3233
1869.83	18.2541
1870.83	18.2379
1871.84	18.2139
1872.84	19.1299
1873.84	16.2572
1874.84	23.7609
1875.84	23.8137
1876.84	17.1986
1877.84	20.9758
1878.84	21.8853
1879.84	19.9397
1880.84	18.0524
1881.84	20.8458
1882.85	18.0323
1883.85	19.9214
1884.84	18.005
1885.84	21.7409
1886.84	18.892
1887.84	18.8949
1888.84	21.7094
1889.84	15.1037
1890.84	19.7687
1891.84	15.0546
1892.83	18.8085
1893.83	17.8723
1894.83	21.634
1895.83	17.8552
1896.83	18.7729
1897.82	17.8217
1898.82	19.707
1899.82	21.5917
1900.81	23.4555
1901.81	19.6828
1902.81	17.791
1903.8	19.6449
1904.8	20.5748
1905.79	15.879
1906.79	19.6453
1907.79	18.7219
1908.78	17.7803
1909.78	16.8271
1910.77	18.708
1911.77	21.5496
1912.76	21.5538
1913.76	17.7639
1914.75	22.4587
1915.74	21.5178
1916.74	18.7072
1917.73	19.6487
1918.72	17.7667
1919.72	21.5427
1920.71	16.7982
1921.7	20.5596
1922.7	15.8355
1923.69	19.6314
1924.68	19.6389
1925.67	20.5867
1926.66	19.6457
1927.66	17.7619
1928.65	25.3518
1929.64	16.7897
1930.63	19.6254
1931.62	21.5719
1932.61	19.7134
1933.61	20.6447
1934.6	20.6191
1935.59	23.4571
1936.58	16.7995
1937.57	22.5212
1938.56	16.8149
1939.55	16.8007
1940.54	19.6627
1941.52	18.7061
1942.51	18.7167
1943.5	13.9421
1944.49	21.5842
1945.48	19.6608
1946.47	18.7056
1947.46	19.6798
1948.44	17.7859
1949.43	20.6768
1950.42	18.7561
1951.41	17.7505
1952.39	19.6411
1953.38	17.747
1954.37	18.718
1955.36	18.7218
1956.34	18.7095
1957.33	19.6527
1958.31	19.6305
1959.3	19.6205
1960.29	19.6159
1961.27	19.6136
1962.26	17.6847
1963.24	18.6443
1964.23	18.6489
1965.21	19.6048
1966.2	18.6287
1967.18	20.5181
1968.17	18.5775
1969.15	17.6077
1970.14	18.5581
1971.12	15.6606
1972.1	17.5693
1973.09	19.4892
1974.07	16.6067
1975.05	19.4677
1976.04	19.451
1977.02	18.4865
1978	19.4269
1978.98	16.5377
1979.97	18.4363
1980.95	19.3691
1981.93	19.3533
1982.91	17.4236
1983.89	16.4675
1984.88	20.2725
1985.86	18.3132
1986.84	20.1698
1987.82	23.029
1988.8	18.2825
1989.78	20.1622
1990.76	18.4112
1991.74	22.5225
1992.72	19.2624
1993.7	16.7129
1994.68	18.2005
1995.66	19.0899
1996.64	19.9667
1997.62	19.8979
1998.6	18.3398
1999.57	19.5721
2000.55	20.1708
2001.53	20.0294
2002.51	19.0702
2003.49	19.3416
2004.47	19.823
2005.44	18.4231
2006.42	17.9677
2007.4	20.1603
2008.38	18.783
2009.35	19.0706
2010.33	19.8135
2011.3	18.6024
2012.18	15.5388
2013.17	17.4197
2014.16	22.1337
2015.15	19.2924
2016.14	20.1985
2017.13	15.4967
2018.11	22.0492
2019.1	19.2361
2020.09	21.0897
2021.08	22.0041
2022.06	17.3072
2023.05	16.3516
2024.04	16.3759
2025.02	17.3212
2026.01	18.2924
2027	18.2306
2027.98	20.0663
2028.97	17.275
2029.96	18.2287
2030.94	20.1145
2031.93	18.1956
2032.91	19.1638
2033.9	18.2266
2034.88	20.0966
2035.87	18.2141
2036.85	21.0002
2037.83	19.1106
2038.82	17.2336
2039.8	18.1535
2040.79	18.1633
2041.77	19.1
2042.75	18.1676
2043.74	20.9911
2044.72	19.087
2045.7	20.0137
2046.69	18.1612
2047.67	19.1122
2048.65	20.0351
2049.63	20.9698
2050.62	20.0472
2051.6	19.1262
2052.58	19.1169
2053.56	18.1728
2054.54	19.1057
2055.52	16.3092
2056.5	18.1896
2057.48	20.0561
2058.46	20.0581
2059.45	18.1863
2060.43	20.0682
2061.4	20.074
2062.39	20.0868
2063.37	19.1626
2064.34	19.1668
2065.32	21.0543
2066.3	22.9341
2067.28	18.217
2068.26	19.1802
2069.24	18.2579
2070.22	21.0763
2071.2	20.1339
2072.18	17.3214
2073.15	20.1767
2074.13	21.1141
2075.11	17.3244
2076.09	17.3309
2077.06	21.1255
2078.04	22.0728
2079.02	16.3982
2080	17.3446
2080.97	19.2303
2081.95	20.1738
2082.93	19.2275
2083.9	21.1343
2084.88	19.2475
2085.85	23.0338
2086.83	19.2568
2087.8	17.3657
2088.78	17.3728
2089.75	18.3412
2090.73	20.2578
2091.7	19.3141
2092.68	21.2038
2093.65	22.1434
2094.63	18.331
2095.6	18.3224
2096.57	18.3177
2097.55	20.2147
2098.52	16.4264
2099.5	16.4248
2100.47	18.3124
2101.44	21.1579
2102.41	18.3185
2103.39	18.3275
2104.36	19.2801
2105.33	20.2123
2106.3	19.2493
2107.27	17.356
2108.25	17.3534
2109.22	19.244
2110.19	19.2472
2111.16	18.3039
2112.13	18.3005
2113.1	20.1931
2114.07	18.2807
2115.04	18.2738
2116.01	18.2544
2116.99	19.1852
2117.96	18.2343
2118.92	21.0911
2119.9	18.2555
2120.86	20.1549
2121.83	19.1861
2122.8	20.1009
2123.77	21.9711
2124.74	21.0107
2125.71	20.0581
2126.68	21.9423
2127.65	18.1554
2128.61	20.9769
2129.58	19.0755
2130.55	19.0678
2131.52	21.899
2132.48	17.1754
2133.45	21.8727
2134.42	19.0404
2135.39	19.9805
2136.35	21.8741
2137.32	15.2513
2138.28	18.0681
2139.25	17.1154
2140.22	15.2462
2141.18	18.9639
2142.15	18.0283
2143.12	20.8452
2144.08	18.9559
2145.05	19.8834
2146.01	21.7486
2146.98	19.8472
2147.94	17.0207
2148.9	18.9022
2149.87	18.8985
2150.83	16.0745
2151.8	16.9898
2152.76	20.7017
2153.72	18.8184
2154.69	19.7534
2155.65	19.7586
2156.61	16.9451
2157.58	18.7943
2158.54	16.9171
2159.5	16.9122
2160.47	17.8366
2161.43	20.6211
2162.39	17.8168
2163.35	17.8131
2164.31	19.6623
2165.27	17.7722
2166.24	17.7691
2167.2	18.7184
2168.16	18.7176
2169.12	18.6865
2170.08	17.7447
2171.04	20.5327
2172	20.5333
2172.96	16.8102
2173.92	18.6595
2174.88	20.5153
2175.84	16.7884
2176.8	18.6435
2177.76	19.5676
2178.72	16.7753
2179.68	16.7663
2180.64	17.6778
2181.59	18.5917
2182.55	19.5211
2183.51	18.6035
2184.47	16.7653
2185.43	19.5489
2186.38	16.7457
2187.34	19.5109
2188.3	17.6578
2189.26	17.6608
2190.21	18.5952
2191.17	19.5454
2192.13	19.5499
2193.08	21.3909
2194.04	19.5093
2195	19.5012
2195.95	17.6589
2196.91	19.5382
2197.86	17.7094
2198.82	14.901
2199.78	14.8794
2200.73	19.5428
2201.69	20.5187
2202.64	17.6672
2203.59	18.5975
2204.55	16.7347
2205.5	19.5386
2206.46	18.6146
2207.41	17.6833
2208.37	17.6917
2209.32	18.6352
2210.27	19.5622
2211.23	18.6254
2212.18	13.9739
2213.13	16.7745
2214.09	16.7701
2215.04	18.6363
2215.99	18.6388
2216.94	20.5166
2217.9	20.5145
2218.85	16.7604
2219.8	17.6868
2220.75	19.565
2221.7	19.5848
2222.65	17.7287
2223.6	19.6147
2224.55	17.7505
2225.5	17.7464
2226.46	16.8035
2227.41	21.5067
2228.36	17.7659
2229.31	17.7783
2230.26	17.7892
2231.21	16.8567
2232.16	18.7292
2233.11	17.7763
2234.05	18.7182
2235	18.7388
2235.95	17.8164
2236.9	17.8181
2237.85	17.8114
2238.8	17.8201
2239.75	16.8806
2240.69	19.7048
2241.64	17.8162
2242.59	18.782
2243.54	15.0107
2244.48	16.9087
2245.43	19.7443
2246.38	21.6303
2247.32	19.7389
2248.27	17.8294
2249.22	17.8261
2250.16	17.8451
2251.11	20.7061
2252.06	17.865
2253	17.865
2253.95	16.9261
2254.89	17.8834
2255.84	16.9361
2256.78	15.0411
2257.73	19.7986
2258.67	16.9565
2259.62	18.8642
2260.56	16.0223
2261.51	17.9519
2262.45	16.0557
2263.39	16.0501
2264.34	18.8966
2265.28	18.8813
2266.22	18.8849
2267.17	19.8602
2268.11	18.9191
2269.05	18.929
2270	18.9311
2270.94	17.9761
2271.88	19.892
2272.82	18.9356
2273.77	16.0747
2274.71	17.0498
2275.65	19.9468
2276.59	18.9793
2277.53	17.0354
2278.47	18.9406
2279.41	19.9014
2280.36	18.9584
2281.3	18.0279
2282.24	16.1164
2283.18	18.9919
2284.12	18.0398
2285.06	20.9447
2286	19.9682
2286.94	15.1296
2287.88	16.0853
2288.82	17.0609
2289.75	19.9613
2290.69	20.9361
2291.63	19.9644
2292.57	21.876
2293.51	19.9299
2294.45	18.9722
2295.39	17.0632
2296.32	15.1461
2297.26	16.1126
2298.2	16.1166
2299.14	16.1171
2300.07	19.0077
2301.01	17.0759
2301.95	19.0152
2302.89	17.0889
2303.82	19.9917
2304.76	18.0516
2305.69	18.0448
2306.63	19.9871
2307.57	17.0959
2308.5	19.9772
2309.44	17.0514
2310.37	21.8706
2311.31	12.2339
2312.24	20.9532
2313.18	17.0642
2314.11	16.0793
2315.05	17.0521
2315.98	18.0015
2316.92	20.885
2317.85	17.025
2318.78	18.0008
2319.72	20.916
2320.65	19.9497
2321.58	16.08
2322.52	18.9566
2323.45	17.9737
2324.38	16.0271
2325.32	23.7294
2326.25	24.682
2327.18	30.4525
2328.11	37.1827
2329.05	23.7133
2329.98	21.7671
2330.91	19.8297
2331.84	17.8894
2332.77	15.9609
2333.7	18.841
2334.63	20.7581
2335.56	17.8671
2336.5	18.8264
2337.43	16.8946
2338.36	17.8352
2339.29	20.6913
2340.22	17.806
2341.15	19.7196
2342.08	19.7174
2343.01	13.9535
2343.93	21.6064
2344.86	20.6431
2345.79	19.6884
2346.72	18.7072
2347.65	17.6922
2348.58	19.6751
2349.51	17.7051
2350.44	15.7622
2351.36	20.517
2352.29	20.5227
2353.22	16.7009
2354.15	20.4796
2355.07	17.6129
2356	18.5516
2356.93	12.8435
2357.86	19.4706
2358.78	18.5011
2359.71	18.4795
2360.63	14.6798
2361.56	17.5069
2362.49	21.2737
2363.41	15.5739
2364.34	15.5882
2364.8	17.4824