File: Data/3-Raman/raw/bu19(2)w-a-ff2b-fi01-v_1800 (450-850nm)_532nm_edge_100%_x100_vis_lwd_h100um_30sx2_01.txt
#Acq. time (s)=	30
#Accumulations=	2
#Range (cm-¹)=	1200...2365
#Windows=	3
#Auto scanning=	Off
#Autofocus=	Off
#Macrospot=	Off
#AutoExposure=	Off
#Spike filter=	Multiple accum.
#Delay time (s)=	2
#Binning=	1
#Readout mode=	Signal
#DeNoise=	Off
#ICS correction=	On
#Dark correction=	Off
#Inst. Process=	Off
#Detector Gain=	Best Dynamic
#Detector ADC=	50 kHz HS
#Detector temperature (°C)=	-60.09
#Instrument=	LabRAM HR Evol
#Detector=	SIN-EM FIVIS
#Objective=	x100_VIS_LWD
#Grating=	1800 (450-850nm)
#ND Filter=	100%
#Laser=	532nm_Edge
#Hole=	100.021
#Temperature=	0
#Range=	Visible
#StageXY=	75x50mm Scan+
#StageZ=	Z motor
#X (µm)=	0
#Y (µm)=	0
#Z (µm)=	-56.4
#Full time(mm:ss)=	3:17
#Project=	21_11_26
#Sample=	BU19(2)w
#Site=
#Title=	BU19(2)w-A-FF2b-FI01-V_1800 (450-850nm)_532nm_Edge_100%_x100_VIS_LWD_H100um_30sX2
#Remark=
#Date=	26.11.2021 16:06
#Acquired=	26.11.2021 16:06:58
1202.72	91.9483
1203.84	86.5996
1204.95	86.5307
1206.06	93.9123
1207.17	88.3694
1208.28	88.2693
1209.39	78.5463
1210.5	82.7781
1211.61	76.2415
1212.72	72.9331
1213.83	81.3767
1214.94	74.9714
1216.05	85.5948
1217.16	82.2747
1218.27	80.0515
1219.38	73.6273
1220.49	79.9517
1221.6	73.5555
1222.71	87.2163
1223.81	85.9904
1224.92	79.5499
1226.03	77.4355
1227.14	74.2461
1228.25	74.0708
1229.35	74.9383
1230.46	76.1874
1231.57	82.2698
1232.67	80.1613
1233.78	78.036
1234.89	74.9061
1235.99	69.6761
1237.1	81.2152
1238.2	86.3527
1239.31	70.5151
1240.41	75.7241
1241.52	77.8213
1242.62	75.6888
1243.73	83.0432
1244.83	78.842
1245.94	87.1403
1247.04	86.0377
1248.14	89.1491
1249.25	95.3672
1250.35	88.0366
1251.45	90.0401
1252.56	93.1003
1253.66	86.7672
1254.76	94.1176
1255.87	95.1694
1256.97	100.405
1258.07	125.436
1259.17	98.227
1260.27	117.082
1261.37	133.637
1262.48	168.423
1263.58	231.572
1264.68	186.278
1265.78	138.018
1266.88	116.066
1267.98	108.849
1269.08	106.892
1270.18	105.838
1271.28	95.2656
1272.38	102.595
1273.47	104.805
1274.57	105.948
1275.67	113.296
1276.77	108.126
1277.87	120.816
1278.97	137.746
1280.07	172.476
1281.16	294.49
1282.26	782.037
1283.36	2254.67
1284.45	1764.13
1285.55	412.786
1286.65	197.903
1287.75	146.235
1288.84	118.827
1289.94	120.995
1291.03	109.434
1292.13	105.201
1293.22	97.8158
1294.32	110.581
1295.42	90.5609
1296.51	92.8586
1297.61	98.1211
1298.7	91.7205
1299.79	85.33
1300.89	88.5159
1301.98	92.7449
1303.08	83.255
1304.17	90.6067
1305.26	76.864
1306.35	81.009
1307.45	84.1496
1308.54	78.8738
1309.63	91.5511
1310.73	70.4525
1311.82	86.2868
1312.91	82.0967
1314	77.8401
1315.09	69.394
1316.18	85.2657
1317.28	78.9071
1318.37	81.0368
1319.46	74.6941
1320.55	69.4049
1321.64	73.571
1322.73	76.6602
1323.82	73.4616
1324.91	79.7844
1326	75.5081
1327.09	75.375
1328.18	77.6044
1329.27	80.8553
1330.35	74.5068
1331.44	67.0573
1332.53	73.267
1333.62	74.2125
1334.71	72.0205
1335.79	76.1488
1336.88	64.5602
1337.97	76.0546
1339.06	77.0338
1340.14	77.0228
1341.23	80.1627
1342.32	82.2177
1343.4	64.356
1344.49	73.7546
1345.58	73.7114
1346.66	77.775
1347.75	71.4167
1348.83	81.7968
1349.92	77.564
1351	78.5356
1352.09	80.5484
1353.17	81.6318
1354.25	79.6233
1355.34	73.194
1356.42	81.4901
1357.51	84.5571
1358.59	84.495
1359.67	82.3528
1360.76	90.5544
1361.84	82.2311
1362.92	86.3336
1364	86.3544
1365.09	102.913
1366.17	95.5722
1367.25	92.3583
1368.33	96.4812
1369.41	208.164
1370.5	102.667
1371.58	95.3418
1372.66	98.288
1373.74	104.395
1374.82	106.414
1375.9	114.645
1376.98	103.256
1378.06	121.739
1379.14	128.116
1380.22	143.499
1381.3	152.449
1382.38	168.717
1383.46	205.396
1384.54	300.618
1385.61	634.411
1386.69	3033.11
1387.77	4080.21
1388.85	619.176
1389.93	262.044
1391	170.383
1392.08	139.501
1393.16	130.17
1394.23	110.669
1395.31	110.654
1396.39	103.516
1397.46	104.478
1398.54	106.493
1399.62	110.624
1400.69	99.3941
1401.77	98.4086
1402.84	94.449
1403.92	101.717
1404.99	104.715
1406.07	128.221
1407.14	183.525
1408.22	296.351
1409.29	312.84
1410.37	159.033
1411.44	102.501
1412.51	93.253
1413.59	85.2838
1414.66	76.9648
1415.73	76.9927
1416.81	78.0369
1417.88	70.8738
1418.95	71.907
1420.02	72.909
1421.1	76.9495
1422.17	68.7336
1423.24	76.0737
1424.31	72.7365
1425.38	68.6298
1426.45	62.4867
1427.52	65.4908
1428.59	55.1816
1429.67	67.4804
1430.74	61.382
1431.81	56.3227
1432.87	61.4125
1433.95	54.1422
1435.01	61.3265
1436.08	59.2693
1437.15	55.1459
1438.22	56.1478
1439.29	60.258
1440.36	58.2452
1441.43	57.2286
1442.49	55.164
1443.56	68.483
1444.63	61.2853
1445.7	61.3269
1446.77	56.1709
1447.83	56.1422
1448.9	57.178
1449.97	57.1615
1451.03	60.201
1452.1	51.975
1453.17	52.9897
1454.23	52.991
1455.3	55.029
1456.36	50.935
1457.43	51.9309
1458.49	46.7927
1459.56	44.7444
1460.62	51.9013
1461.69	47.7743
1462.75	46.7097
1463.82	42.5696
1464.88	49.7756
1465.94	48.5978
1467.01	46.5338
1468.07	48.5585
1469.13	46.5042
1470.2	45.4464
1471.26	49.4901
1472.32	50.4734
1473.39	52.4934
1474.45	53.4774
1475.51	41.2653
1476.57	50.4
1477.63	51.3839
1478.69	51.3569
1479.76	47.251
1480.82	45.1613
1481.88	48.1803
1482.94	45.1621
1484	46.1789
1485.06	41.0059
1486.12	47.0644
1487.18	48.0757
1488.24	45.0044
1489.3	41.9233
1490.36	47.9738
1491.42	47.9398
1492.48	46.9162
1493.53	43.8699
1494.59	44.8719
1495.65	44.8452
1496.71	44.7925
1497.77	41.7441
1498.82	45.7712
1499.88	49.8124
1500.94	45.7707
1502	43.726
1503.05	46.7275
1504.11	43.6708
1505.17	49.7182
1506.22	47.6496
1507.28	38.5778
1508.34	39.578
1509.39	43.6016
1510.45	49.6479
1511.5	44.5596
1512.56	45.4669
1513.61	44.4032
1514.67	44.425
1515.72	45.3811
1516.78	47.336
1517.83	43.3101
1518.88	45.3257
1519.94	50.3475
1520.99	40.3015
1522.05	42.3084
1523.1	48.2997
1524.15	39.2189
1525.2	42.1978
1526.26	45.2141
1527.31	42.2242
1528.36	43.2021
1529.41	42.1762
1530.47	48.164
1531.52	43.179
1532.57	47.1721
1533.62	46.2134
1534.67	46.2133
1535.72	44.1781
1536.77	44.1071
1537.82	48.051
1538.87	45.014
1539.92	49.0803
1540.97	48.1536
1542.02	43.1041
1543.07	44.0532
1544.12	47.9933
1545.17	49.0171
1546.22	47.0555
1547.27	46.0565
1548.32	44.0216
1549.37	49.9918
1550.42	43.9955
1551.46	45.1262
1552.51	46.124
1553.56	50.0941
1554.61	49.0456
1555.65	49.9945
1556.7	39.9659
1557.75	44.9736
1558.79	39.9229
1559.84	45.8668
1560.89	42.8367
1561.93	44.8363
1562.98	39.8531
1564.02	45.8368
1565.07	51.8715
1566.11	43.5817
1567.16	43.7642
1568.2	42.7922
1569.25	46.7945
1570.29	50.7599
1571.34	47.7525
1572.38	45.724
1573.43	43.6902
1574.47	50.665
1575.51	45.7123
1576.56	43.7126
1577.6	42.6525
1578.64	46.5809
1579.69	44.5758
1580.73	46.5761
1581.77	39.5689
1582.81	44.5185
1583.85	48.4857
1584.9	46.4882
1585.94	49.4658
1586.98	45.4376
1588.02	47.4014
1589.06	48.4061
1590.1	49.413
1591.14	47.428
1592.18	42.4312
1593.22	45.3659
1594.26	50.2562
1595.3	45.2901
1596.34	43.2794
1597.38	41.2899
1598.42	47.2445
1599.46	48.1852
1600.5	45.1675
1601.54	35.2001
1602.58	43.0728
1603.62	46.981
1604.66	47.9509
1605.69	45.9702
1606.73	49.9415
1607.77	41.2016
1608.81	44.3642
1609.84	48.3816
1610.88	48.6972
1611.92	41.4449
1612.95	48.492
1613.99	43.4579
1615.03	43.0967
1616.06	46.923
1617.1	46.2937
1618.13	50.2593
1619.17	51.8809
1620.2	48.5527
1621.24	48.6379
1622.27	49.3402
1623.31	49.4189
1624.34	46.7921
1625.38	46.5962
1626.41	46.9571
1627.45	48.462
1628.48	47.8295
1629.51	49.4042
1630.55	49.8052
1631.53	52.5433
1632.57	45.6602
1633.62	51.5602
1634.66	52.5496
1635.71	51.5511
1636.75	52.506
1637.8	44.5911
1638.84	51.4596
1639.89	51.451
1640.93	52.4356
1641.98	45.5352
1643.02	50.439
1644.06	53.3749
1645.11	46.4573
1646.15	49.4147
1647.19	49.3872
1648.24	45.4293
1649.28	49.3985
1650.32	50.3728
1651.37	49.4245
1652.41	50.4108
1653.45	48.4202
1654.49	45.4655
1655.53	55.3357
1656.57	49.4626
1657.62	52.4162
1658.66	49.4292
1659.7	49.3923
1660.74	48.3903
1661.78	45.4563
1662.82	50.4378
1663.86	48.4594
1664.9	50.3936
1665.94	51.3062
1666.98	49.3878
1668.02	47.379
1669.06	43.4318
1670.1	47.4056
1671.14	48.4206
1672.18	43.4615
1673.21	46.4231
1674.25	48.4032
1675.29	46.4435
1676.33	46.4459
1677.37	47.4315
1678.4	42.454
1679.44	41.4292
1680.48	49.3118
1681.52	48.2985
1682.55	49.2768
1683.59	39.3864
1684.63	42.3309
1685.66	45.2766
1686.7	46.2602
1687.73	42.3116
1688.77	43.2721
1689.81	46.1934
1690.84	45.1866
1691.88	43.2209
1692.91	47.1543
1693.95	47.0996
1694.98	43.1157
1696.01	47.0543
1697.05	43.117
1698.08	44.0589
1699.12	45.9884
1700.15	45.9779
1701.18	41.0386
1702.22	48.8753
1703.25	48.8365
1704.28	47.8332
1705.32	41.9383
1706.35	45.8499
1707.38	45.7982
1708.41	48.68
1709.44	47.6325
1710.48	47.6134
1711.51	39.7867
1712.54	44.6773
1713.57	42.6456
1714.6	40.6388
1715.63	44.5374
1716.66	43.5509
1717.69	46.4142
1718.72	36.5899
1719.75	46.3036
1720.78	45.3191
1721.81	42.3531
1722.84	48.1335
1723.87	46.1471
1724.9	44.1825
1725.93	43.1434
1726.96	44.0877
1727.99	38.2535
1729.02	44.9373
1730.05	45.8491
1731.07	46.7787
1732.1	45.8586
1733.13	45.8307
1734.16	45.7613
1735.18	40.8774
1736.21	44.68
1737.24	44.6505
1738.26	44.6157
1739.29	42.6468
1740.32	47.3691
1741.34	45.3893
1742.37	46.3065
1743.4	44.3691
1744.42	47.2081
1745.45	46.2331
1746.47	45.2507
1747.5	42.328
1748.52	44.2029
1749.55	38.4757
1750.57	46.1429
1751.6	48.0662
1752.62	48.0121
1753.64	52.734
1754.67	46.0096
1755.69	45.9762
1756.71	45.9265
1757.74	43.0158
1758.76	45.8757
1759.78	45.8716
1760.81	42.0449
1761.83	40.1072
1762.85	45.7998
1763.87	44.8459
1764.89	43.9196
1765.92	43.9308
1766.94	42.015
1767.96	48.6553
1768.98	45.772
1770	49.4782
1771.02	43.7956
1772.04	51.4304
1773.06	42.8887
1774.08	46.7065
1775.1	46.7132
1776.12	47.7034
1777.14	50.5542
1778.16	44.7978
1779.18	48.5587
1780.2	53.2999
1781.22	46.6456
1782.24	49.5076
1783.26	45.7207
1784.28	44.7825
1785.29	40.0339
1786.31	38.107
1787.33	44.7971
1788.35	42.9617
1789.37	45.8896
1790.38	39.2124
1791.4	43.0325
1792.42	43.9479
1793.43	46.8271
1794.45	41.0792
1795.47	46.8621
1796.48	39.2249
1797.5	41.1691
1798.51	40.2198
1799.53	41.1689
1800.55	41.1323
1801.56	43.0323
1802.58	42.0718
1803.59	40.1707
1804.61	44.0279
1805.62	43.0943
1806.64	40.2299
1807.65	38.3046
1808.66	45.0454
1809.68	45.0434
1810.69	36.3633
1811.7	40.2059
1812.72	41.1678
1813.73	42.1457
1814.74	40.2447
1815.76	46.0657
1816.77	43.1675
1817.78	44.0991
1818.79	43.1316
1819.8	41.2029
1820.82	45.0817
1821.83	35.4206
1822.84	47.0426
1823.85	40.2583
1824.86	45.0916
1825.87	40.2577
1826.88	40.2516
1827.89	35.4109
1828.9	43.1513
1829.91	40.2235
1830.92	38.2626
1831.93	42.143
1832.94	42.1598
1833.95	41.1936
1834.96	45.0322
1835.97	43.0198
1836.98	42.2
1837.99	43.0251
1839	40.1098
1840	40.1569
1841.01	42.9703
1842.02	44.8134
1843.03	43.8011
1844.04	43.7924
1845.04	39.9264
1846.05	42.8245
1847.06	38.0285
1848.07	45.5889
1849.07	38.8493
1850.08	37.8484
1851.09	39.7145
1852.09	39.6794
1853.1	43.5092
1854.1	36.7639
1855.11	33.8396
1856.11	40.5035
1857.12	38.573
1858.12	38.5495
1859.13	40.4221
1860.13	41.3407
1861.14	39.437
1862.14	39.4502
1863.15	36.5461
1864.15	40.3268
1865.15	41.2423
1866.16	40.2268
1867.16	41.1013
1868.16	40.0893
1869.17	40.0759
1870.17	37.208
1871.17	40.0441
1872.17	40.9701
1873.18	41.8855
1874.18	43.7577
1875.18	38.0188
1876.18	41.7407
1877.18	38.8494
1878.18	34.0615
1879.19	37.8944
1880.19	39.8102
1881.19	38.8499
1882.19	42.5647
1883.19	41.5219
1884.19	36.756
1885.19	37.7093
1886.19	41.526
1887.19	39.6238
1888.19	39.5763
1889.19	38.5715
1890.19	37.5993
1891.19	39.4981
1892.18	41.3642
1893.18	40.3955
1894.18	35.6245
1895.18	36.5384
1896.18	43.1201
1897.18	45.0212
1898.17	41.2622
1899.17	39.3487
1900.17	39.3126
1901.16	34.6053
1902.16	43.0861
1903.16	44.9753
1904.16	35.5468
1905.15	40.2325
1906.15	40.2076
1907.14	35.4745
1908.14	41.1058
1909.14	40.1758
1910.13	41.1453
1911.13	42.1295
1912.12	36.4815
1913.12	40.2341
1914.11	41.1876
1915.11	40.2768
1916.1	42.171
1917.1	44.0275
1918.09	36.4552
1919.08	40.2446
1920.08	36.5147
1921.07	38.4029
1922.06	35.5893
1923.06	44.0855
1924.05	44.0582
1925.04	41.1937
1926.04	39.3234
1927.03	43.1462
1928.02	46.0067
1929.01	38.4381
1930	37.5137
1931	41.3438
1931.99	44.1788
1932.98	39.4007
1933.97	46.0416
1934.96	42.3623
1935.95	41.4949
1936.94	43.3516
1937.93	42.3524
1938.92	39.4855
1939.91	36.6423
1940.9	40.473
1941.89	37.64
1942.88	41.4665
1943.87	38.5711
1944.86	39.5457
1945.85	37.6652
1946.84	40.5518
1947.83	34.7995
1948.82	37.6549
1949.8	37.6714
1950.79	41.5496
1951.78	43.5262
1952.77	36.8312
1953.76	41.63
1954.74	39.614
1955.73	42.4585
1956.72	47.3227
1957.7	46.3995
1958.69	43.5319
1959.68	39.6656
1960.66	40.5968
1961.65	45.3581
1962.63	46.3107
1963.62	35.7505
1964.61	39.5948
1965.59	39.5816
1966.58	40.5558
1967.56	38.6449
1968.55	38.6436
1969.53	41.4962
1970.52	42.4003
1971.5	44.2848
1972.48	50.9911
1973.47	39.4622
1974.45	49.0133
1975.44	46.1332
1976.42	47.1086
1977.4	43.267
1978.39	48.9887
1979.37	48.006
1980.35	51.8365
1981.33	47.9674
1982.31	46.0258
1983.3	52.6891
1984.28	47.8608
1985.26	57.3912
1986.24	53.5406
1987.22	55.4639
1988.21	48.7256
1989.19	50.4955
1990.17	53.0067
1991.15	55.7051
1992.13	53.0998
1993.11	57.726
1994.09	53.4409
1995.07	58.3173
1996.05	51.6228
1997.03	54.6944
1998.01	60.2185
1998.99	55.1615
1999.97	56.8471
2000.95	57.3124
2001.92	58.9835
2002.9	57.602
2003.88	58.2951
2004.86	59.1772
2005.84	57.9375
2006.81	59.2637
2007.79	55.5278
2008.77	59.2581
2009.75	60.1735
2010.73	61.3121
2011.7	54.642
2012.68	60.9694
2013.67	51.4928
2014.66	55.1632
2015.64	54.1991
2016.63	58.9152
2017.62	60.8312
2018.61	56.9937
2019.6	54.0954
2020.58	56.8792
2021.57	55.9417
2022.56	58.7328
2023.55	50.2561
2024.54	52.0804
2025.52	54.8097
2026.51	55.695
2027.5	47.4212
2028.48	51.1006
2029.47	48.3715
2030.45	49.1558
2031.44	49.1749
2032.43	51.0475
2033.41	52.0446
2034.4	46.4401
2035.38	46.367
2036.37	48.3338
2037.35	50.1872
2038.34	48.3009
2039.32	47.3343
2040.31	51.0253
2041.29	50.0402
2042.27	45.3545
2043.26	41.6064
2044.24	45.3833
2045.23	39.7605
2046.21	46.3786
2047.19	39.7997
2048.17	45.3402
2049.16	47.2142
2050.14	49.1314
2051.12	43.5606
2052.11	44.4671
2053.09	43.5453
2054.07	42.6548
2055.05	44.5371
2056.03	41.7085
2057.01	46.3663
2058	40.7652
2058.98	44.537
2059.96	43.6196
2060.94	39.8579
2061.92	41.744
2062.9	40.8147
2063.88	36.1519
2064.86	43.6633
2065.84	41.8257
2066.82	40.91
2067.8	43.7438
2068.78	46.5816
2069.76	40.9285
2070.73	42.8014
2071.71	44.7072
2072.69	41.0007
2073.67	40.0496
2074.65	42.8821
2075.63	42.9326
2076.6	41.089
2077.58	38.2355
2078.56	44.8271
2079.54	41.0741
2080.51	41.1126
2081.49	43.9434
2082.47	39.2165
2083.45	38.2742
2084.42	38.2691
2085.4	42.0482
2086.37	42.0593
2087.35	39.2508
2088.32	37.3667
2089.3	43.0499
2090.28	34.5515
2091.25	37.4027
2092.23	37.4286
2093.2	40.3215
2094.18	39.4068
2095.15	41.3133
2096.13	37.4868
2097.1	41.2739
2098.07	39.3473
2099.05	43.1315
2100.02	41.2246
2101	43.1283
2101.97	36.504
2102.94	33.6492
2103.92	34.5789
2104.89	37.4315
2105.86	37.4545
2106.83	39.37
2107.8	43.1724
2108.78	38.3783
2109.75	39.3256
2110.72	42.1813
2111.69	38.3756
2112.66	38.3613
2113.63	39.3304
2114.61	36.4826
2115.58	43.1323
2116.55	40.2604
2117.52	33.5955
2118.49	40.2245
2119.46	36.3888
2120.43	40.1495
2121.4	39.2083
2122.37	35.4458
2123.34	38.3116
2124.31	34.5094
2125.28	37.306
2126.25	37.252
2127.21	40.0534
2128.18	35.3073
2129.15	39.0798
2130.12	40.9581
2131.09	39.999
2132.06	38.0851
2133.02	39.0035
2133.99	34.2811
2134.96	36.1678
2135.93	34.2704
2136.89	42.7203
2137.86	34.2405
2138.83	40.8234
2139.79	38.9448
2140.76	40.7938
2141.73	40.7807
2142.69	37.9331
2143.66	38.9014
2144.62	38.8224
2145.59	35.0606
2146.55	35.0515
2147.52	39.733
2148.48	30.3188
2149.45	34.0523
2150.42	34.9479
2151.38	40.5608
2152.34	41.5158
2153.31	37.7491
2154.27	35.8529
2155.24	36.7355
2156.2	40.4222
2157.16	40.4046
2158.13	37.6143
2159.09	38.5518
2160.05	39.4608
2161.01	34.7556
2161.98	37.5393
2162.94	38.4673
2163.9	38.4478
2164.86	34.6905
2165.83	37.4828
2166.79	38.4041
2167.75	37.4423
2168.71	31.8096
2169.67	32.7485
2170.63	35.5795
2171.59	38.36
2172.56	33.6465
2173.51	38.2772
2174.48	39.2144
2175.44	44.7891
2176.4	33.6263
2177.36	38.2579
2178.32	36.3993
2179.28	35.4466
2180.23	38.2316
2181.19	37.2941
2182.15	37.2792
2183.11	38.1903
2184.07	38.1523
2185.03	34.4311
2185.99	41.8566
2186.95	38.1768
2187.9	36.3585
2188.86	35.4122
2189.82	42.7912
2190.78	38.1352
2191.73	29.7961
2192.69	35.3688
2193.65	34.4589
2194.6	39.1538
2195.56	39.1474
2196.52	38.1771
2197.47	39.0668
2198.43	33.4979
2199.38	40.0342
2200.34	48.4597
2201.3	38.2911
2202.25	41.8769
2203.21	32.6437
2204.16	42.0942
2205.12	37.3555
2206.07	40.9829
2207.03	43.7657
2207.98	37.2781
2208.93	41.9607
2209.89	37.315
2210.84	39.186
2211.8	37.3443
2212.75	35.5005
2213.7	33.618
2214.66	36.4307
2215.61	33.6509
2216.56	34.5841
2217.51	37.3784
2218.47	38.3122
2219.42	35.525
2220.37	37.4103
2221.32	36.4658
2222.27	39.2309
2223.23	36.4299
2224.18	31.7858
2225.13	36.4945
2226.08	35.5911
2227.03	34.6796
2227.98	35.6337
2228.93	31.8725
2229.88	38.4354
2230.83	42.2206
2231.78	34.7412
2232.73	37.5865
2233.68	35.7301
2234.63	31.9766
2235.58	38.5348
2236.53	31.944
2237.48	37.5991
2238.43	34.8225
2239.38	36.7488
2240.33	38.6166
2241.27	34.8578
2242.22	32.9775
2243.17	37.7067
2244.12	36.7458
2245.07	32.0392
2246.01	35.8565
2246.96	33.0407
2247.91	36.8391
2248.85	37.7762
2249.8	35.8821
2250.75	38.7109
2251.69	37.7335
2252.64	34.9034
2253.59	36.8456
2254.53	36.8769
2255.48	34.9823
2256.42	33.0921
2257.37	36.9092
2258.32	33.1264
2259.26	34.0856
2260.2	35.0489
2261.15	35.0625
2262.1	36.0341
2263.04	35.0987
2263.98	32.2771
2264.93	38.0476
2265.87	34.2497
2266.81	34.2306
2267.76	33.2476
2268.7	33.225
2269.65	33.2442
2270.59	36.1495
2271.53	39.0414
2272.47	35.2346
2273.42	32.3683
2274.36	39.0724
2275.3	30.4632
2276.24	33.3409
2277.18	37.2029
2278.13	37.2499
2279.07	35.3517
2280.01	38.2029
2280.95	35.2864
2281.89	37.1845
2282.83	31.4481
2283.77	35.3222
2284.71	36.3393
2285.65	38.2855
2286.59	35.3751
2287.54	34.4489
2288.47	31.5724
2289.41	33.4705
2290.35	35.3484
2291.29	37.2717
2292.23	38.2694
2293.17	36.3722
2294.11	36.3881
2295.05	36.3662
2295.99	33.455
2296.93	31.5011
2297.86	35.3697
2298.8	38.2935
2299.74	34.4658
2300.68	34.4657
2301.61	36.4121
2302.55	38.3391
2303.49	37.3671
2304.43	33.5136
2305.36	35.4636
2306.3	34.5083
2307.24	38.3783
2308.17	36.431
2309.11	34.4915
2310.04	33.5528
2310.98	34.5284
2311.92	35.438
2312.85	36.3676
2313.79	40.2366
2314.72	31.5872
2315.66	35.4732
2316.59	35.4258
2317.52	35.4092
2318.46	37.3443
2319.39	34.4228
2320.33	37.3038
2321.26	36.3462
2322.2	39.2733
2323.13	41.2292
2324.06	47.0389
2325	47.0224
2325.93	67.2465
2326.86	127.973
2327.79	378.524
2328.73	206.874
2329.66	84.4074
2330.59	54.5398
2331.52	42.0097
2332.46	34.3122
2333.39	35.2511
2334.32	36.1942
2335.25	35.205
2336.18	31.3561
2337.11	37.1147
2338.04	39.0267
2338.97	37.0943
2339.91	39.9763
2340.84	38.0304
2341.77	36.0627
2342.7	40.8253
2343.63	33.1464
2344.56	39.8539
2345.49	33.1354
2346.41	35.0217
2347.34	32.1372
2348.27	33.0915
2349.2	33.0923
2350.13	37.8197
2351.06	34.7819
2351.99	34.9194
2352.91	33.9096
2353.84	34.8101
2354.77	29.0925
2355.7	37.6661
2356.63	35.7325
2357.55	34.7346
2358.48	39.4644
2359.41	32.7935
2360.33	37.5192
2361.26	39.3785
2362.19	33.6503
2363.11	32.6678
2364.04	34.5389
2364.97	35.4622