File: Data/3-Raman/raw/bu19(2)w-a-ff1b-fi01-v_1800 (450-850nm)_532nm_edge_100%_x100_vis_lwd_h100um_30sx2_02.txt
#Acq. time (s)=	30
#Accumulations=	2
#Range (cm-¹)=	1200...2365
#Windows=	3
#Auto scanning=	Off
#Autofocus=	Off
#Macrospot=	Off
#AutoExposure=	Off
#Spike filter=	Multiple accum.
#Delay time (s)=	2
#Binning=	1
#Readout mode=	Signal
#DeNoise=	Off
#ICS correction=	On
#Dark correction=	Off
#Inst. Process=	Off
#Detector Gain=	Best Dynamic
#Detector ADC=	50 kHz HS
#Detector temperature (°C)=	-60.09
#Instrument=	LabRAM HR Evol
#Detector=	SIN-EM FIVIS
#Objective=	x100_VIS_LWD
#Grating=	1800 (450-850nm)
#ND Filter=	100%
#Laser=	532nm_Edge
#Hole=	100.021
#Temperature=	0
#Range=	Visible
#StageXY=	75x50mm Scan+
#StageZ=	Z motor
#X (µm)=	0
#Y (µm)=	0
#Z (µm)=	-1.6
#Full time(mm:ss)=	3:11
#Project=	21_11_26
#Sample=	BU19(2)w
#Site=
#Title=	BU19(2)w-A-FF1b-FI01-V_1800 (450-850nm)_532nm_Edge_100%_x100_VIS_LWD_H100um_30sX2
#Remark=
#Date=	26.11.2021 14:10
#Acquired=	26.11.2021 14:10:41
1202.72	54.3086
1203.84	61.8593
1204.95	55.3618
1206.06	53.1313
1207.17	56.2423
1208.28	57.2508
1209.39	60.3963
1210.5	59.2969
1211.61	58.1367
1212.72	59.1205
1213.83	57.9984
1214.94	55.8592
1216.05	59.0394
1217.16	60.014
1218.27	49.3263
1219.38	57.7812
1220.49	55.632
1221.6	52.4294
1222.71	62.9462
1223.81	60.7129
1224.92	58.5289
1226.03	59.5853
1227.14	63.7933
1228.25	58.3802
1229.35	59.2897
1230.46	56.2864
1231.57	57.1763
1232.67	58.2242
1233.78	56.1081
1234.89	60.3303
1235.99	63.5089
1237.1	61.3896
1238.2	69.7065
1239.31	67.5245
1240.41	58.0645
1241.52	66.4543
1242.62	68.5224
1243.73	64.3482
1244.83	66.4413
1245.94	77.8977
1247.04	73.6648
1248.14	79.9233
1249.25	79.8758
1250.35	78.8255
1251.45	77.7072
1252.56	77.6484
1253.66	74.4612
1254.76	75.5446
1255.87	80.775
1256.97	95.4128
1258.07	120.449
1259.17	101.598
1260.27	105.838
1261.37	130.756
1262.48	172.859
1263.58	246.429
1264.68	215.83
1265.78	136.195
1266.88	115.293
1267.98	93.4348
1269.08	104.031
1270.18	108.219
1271.28	107.069
1272.38	109.17
1273.47	106.154
1274.57	108.351
1275.67	118.851
1276.77	114.739
1277.87	128.49
1278.97	143.328
1280.07	172.805
1281.16	310.602
1282.26	844.479
1283.36	2466.49
1284.45	2427.89
1285.55	519.511
1286.65	214.056
1287.75	158.176
1288.84	129.717
1289.94	120.313
1291.03	115.077
1292.13	107.688
1293.22	97.1478
1294.32	108.862
1295.42	84.6274
1296.51	87.9734
1297.61	93.2414
1298.7	87.9046
1299.79	92.0767
1300.89	85.7662
1301.98	93.1676
1303.08	84.7387
1304.17	84.7032
1305.26	79.4124
1306.35	81.4505
1307.45	78.2675
1308.54	77.2151
1309.63	79.3455
1310.73	73.0232
1311.82	71.9757
1312.91	79.3986
1314	77.2589
1315.09	74.0958
1316.18	75.1871
1317.28	75.1713
1318.37	75.1916
1319.46	76.2484
1320.55	64.6251
1321.64	71.9668
1322.73	76.1174
1323.82	73.9782
1324.91	71.8701
1326	70.7654
1327.09	64.3334
1328.18	76.0321
1329.27	71.8997
1330.35	71.8868
1331.44	74.9851
1332.53	69.6111
1333.62	69.5157
1334.71	75.734
1335.79	67.2751
1336.88	67.23
1337.97	69.296
1339.06	69.2383
1340.14	72.374
1341.23	68.1873
1342.32	70.2517
1343.4	77.5086
1344.49	71.2229
1345.58	72.2312
1346.66	75.2585
1347.75	69.9513
1348.83	67.831
1349.92	66.7377
1351	80.2103
1352.09	78.0676
1353.17	77.0727
1354.25	74.0222
1355.34	78.0033
1356.42	76.9525
1357.51	70.6803
1358.59	78.9349
1359.67	73.6904
1360.76	78.7972
1361.84	86.0195
1362.92	87.0193
1364	89.1163
1365.09	99.4652
1366.17	90.0631
1367.25	95.1302
1368.33	110.628
1369.41	219.217
1370.5	113.722
1371.58	102.262
1372.66	110.36
1373.74	113.373
1374.82	119.515
1375.9	118.477
1376.98	124.598
1378.06	138.961
1379.14	147.43
1380.22	172.083
1381.3	180.981
1382.38	195.17
1383.46	236.946
1384.54	343.433
1385.61	763.472
1386.69	3647.05
1387.77	4933.27
1388.85	710.159
1389.93	286.466
1391	184.521
1392.08	165.927
1393.16	138.154
1394.23	122.747
1395.31	118.644
1396.39	113.56
1397.46	99.1753
1398.54	106.311
1399.62	106.352
1400.69	101.268
1401.77	95.1668
1402.84	100.437
1403.92	104.634
1404.99	113.792
1406.07	135.246
1407.14	181.328
1408.22	330.043
1409.29	345.521
1410.37	151.718
1411.44	108.522
1412.51	90.0562
1413.59	77.971
1414.66	74.7972
1415.73	76.8818
1416.81	72.7953
1417.88	66.6616
1418.95	61.5325
1420.02	70.7613
1421.1	67.6225
1422.17	67.6241
1423.24	67.7628
1424.31	60.3585
1425.38	69.5879
1426.45	59.3461
1427.52	60.3093
1428.59	54.106
1429.67	54.1189
1430.74	50.0629
1431.81	59.3617
1432.87	54.197
1433.95	51.0406
1435.01	51.0554
1436.08	53.1016
1437.15	50.0094
1438.22	52.0417
1439.29	57.1792
1440.36	51.0672
1441.43	50.053
1442.49	47.9939
1443.56	44.9122
1444.63	45.9253
1445.7	48.0106
1446.77	39.7869
1447.83	43.8703
1448.9	44.9065
1449.97	42.8458
1451.03	47.9471
1452.1	38.7057
1453.17	35.6273
1454.23	39.7292
1455.3	42.7975
1456.36	41.7798
1457.43	40.7354
1458.49	34.5794
1459.56	33.558
1460.62	37.6479
1461.69	40.7002
1462.75	37.5991
1463.82	36.5399
1464.88	34.5308
1465.94	37.4873
1467.01	34.4116
1468.07	35.4229
1469.13	38.475
1470.2	32.331
1471.26	36.3865
1472.32	31.2722
1473.39	32.2821
1474.45	30.2279
1475.51	32.2658
1476.57	36.3212
1477.63	36.3002
1478.69	35.267
1479.76	31.1769
1480.82	35.1996
1481.88	32.1399
1482.94	30.1294
1484	35.2096
1485.06	28.0393
1486.12	32.0803
1487.18	37.1472
1488.24	32.0613
1489.3	30.008
1490.36	32.02
1491.42	33.0108
1492.48	31.9934
1493.53	30.9755
1494.59	27.9389
1495.65	28.9346
1496.71	30.9221
1497.77	32.9288
1498.82	34.9426
1499.88	36.9667
1500.94	32.9285
1502	32.9122
1503.05	36.9317
1504.11	32.8768
1505.17	27.8352
1506.22	33.8518
1507.28	24.7833
1508.34	33.849
1509.39	34.8542
1510.45	28.8098
1511.5	31.8012
1512.56	31.7352
1513.61	32.7004
1514.67	32.7185
1515.72	29.6757
1516.78	30.6477
1517.83	29.6372
1518.88	33.6577
1519.94	29.6509
1520.99	33.6568
1522.05	32.6567
1523.1	31.6366
1524.15	29.5934
1525.2	29.5774
1526.26	33.5943
1527.31	31.6047
1528.36	33.5936
1529.41	33.578
1530.47	31.5623
1531.52	31.5803
1532.57	30.5706
1533.62	31.6035
1534.67	32.6086
1535.72	32.5902
1536.77	34.5441
1537.82	32.5029
1538.87	33.4793
1539.92	32.5257
1540.97	27.5634
1542.02	31.5511
1543.07	34.5199
1544.12	28.4766
1545.17	32.4942
1546.22	27.5151
1547.27	32.5272
1548.32	32.5072
1549.37	33.4857
1550.42	29.49
1551.46	34.5951
1552.51	32.585
1553.56	34.5641
1554.61	32.53
1555.65	36.5044
1556.7	37.4998
1557.75	30.49
1558.79	34.4657
1559.84	36.4226
1560.89	30.4045
1561.93	30.407
1562.98	32.4207
1564.02	30.4114
1565.07	33.4352
1566.11	35.2166
1567.16	30.3686
1568.2	36.3872
1569.25	30.3937
1570.29	33.3731
1571.34	30.371
1572.38	35.348
1573.43	35.3228
1574.47	31.3231
1575.51	35.3475
1576.56	32.3514
1577.6	31.3112
1578.64	34.262
1579.69	33.2594
1580.73	33.2662
1581.77	30.2574
1582.81	39.2028
1583.85	39.1918
1584.9	37.1985
1585.94	35.2012
1586.98	34.1754
1588.02	38.1387
1589.06	35.1632
1590.1	36.1692
1591.14	43.148
1592.18	35.1699
1593.22	34.1384
1594.26	38.0584
1595.3	37.0687
1596.34	39.0389
1597.38	38.0468
1598.42	42.0191
1599.46	39.9931
1600.5	35.003
1601.54	35.9517
1602.58	36.9014
1603.62	31.9206
1604.66	34.8764
1605.69	41.7984
1606.73	43.7932
1607.77	36.0706
1608.81	44.4624
1609.84	38.3585
1610.88	39.7018
1611.92	40.313
1612.95	37.0739
1613.99	41.9677
1615.03	43.445
1616.06	41.8006
1617.1	40.1891
1618.13	43.0513
1619.17	45.1099
1620.2	42.4874
1621.24	43.8155
1622.27	40.9622
1623.31	45.5377
1624.34	44.7335
1625.38	42.5436
1626.41	45.5121
1627.45	48.0349
1628.48	43.6954
1629.51	43.179
1630.55	45.1386
1631.53	46.9164
1632.57	45.9493
1633.62	41.0152
1634.66	42.9931
1635.71	41.0151
1636.75	40.0093
1637.8	43.9221
1638.84	44.8901
1639.89	47.8399
1640.93	46.8604
1641.98	44.8881
1643.02	39.9539
1644.06	40.9284
1645.11	40.9077
1646.15	47.8054
1647.19	44.8326
1648.24	44.8151
1649.28	39.9307
1650.32	54.6911
1651.37	43.9004
1652.41	48.833
1653.45	48.8186
1654.49	45.8696
1655.53	47.8584
1656.57	45.9312
1657.62	44.9421
1658.66	43.9363
1659.7	43.9078
1660.74	43.8979
1661.78	42.9398
1662.82	42.9852
1663.86	47.9273
1664.9	42.9556
1665.94	45.8548
1666.98	48.8722
1668.02	46.8688
1669.06	38.979
1670.1	44.9309
1671.14	42.9841
1672.18	45.9384
1673.21	41.9863
1674.25	39.027
1675.29	42.0142
1676.33	40.0418
1677.37	41.0322
1678.4	44.9664
1679.44	41.968
1680.48	38.9847
1681.52	38.9682
1682.55	39.952
1683.59	37.9705
1684.63	38.9455
1685.66	38.9349
1686.7	37.948
1687.73	33.015
1688.77	36.947
1689.81	40.8647
1690.84	35.9187
1691.88	33.955
1692.91	33.9478
1693.95	32.9255
1694.98	31.9125
1696.01	36.84
1697.05	32.9052
1698.08	34.8452
1699.12	34.8181
1700.15	31.8614
1701.18	35.7849
1702.22	39.6965
1703.25	32.7901
1704.28	27.8664
1705.32	35.7296
1706.35	34.7359
1707.38	35.6814
1708.41	29.7562
1709.44	32.654
1710.48	36.5593
1711.51	33.6307
1712.54	28.7325
1713.57	36.5092
1714.6	32.5603
1715.63	31.5799
1716.66	34.5065
1717.69	29.5816
1718.72	31.4782
1719.75	33.4101
1720.78	33.4052
1721.81	33.373
1722.84	37.2241
1723.87	32.3379
1724.9	31.3537
1725.93	33.246
1726.96	33.2303
1727.99	29.3421
1729.02	33.1484
1730.05	38.9067
1731.07	31.1583
1732.1	30.2249
1733.13	31.175
1734.16	35.9542
1735.18	29.161
1736.21	32.0176
1737.24	31.0372
1738.26	29.0926
1739.29	32.9071
1740.32	30.935
1741.34	32.8122
1742.37	28.9562
1743.4	30.8583
1744.42	34.6662
1745.45	30.8295
1746.47	32.7268
1747.5	30.7782
1748.52	31.7109
1749.55	31.7149
1750.57	32.6927
1751.6	34.6155
1752.62	29.8039
1753.64	30.7296
1754.67	32.6097
1755.69	33.542
1756.71	27.7956
1757.74	28.7144
1758.76	29.6718
1759.78	34.4295
1760.81	28.7085
1761.83	29.6372
1762.85	35.336
1763.87	30.5827
1764.89	33.4571
1765.92	30.6127
1766.94	31.5591
1767.96	27.7394
1768.98	30.5782
1770	34.3177
1771.02	30.5323
1772.04	31.505
1773.06	28.6655
1774.08	30.5784
1775.1	31.5373
1776.12	31.5645
1777.14	37.2801
1778.16	34.3955
1779.18	30.5562
1780.2	29.5961
1781.22	31.5065
1782.24	29.6079
1783.26	32.4831
1784.28	33.4501
1785.29	27.7447
1786.31	31.5497
1787.33	30.6071
1788.35	30.6617
1789.37	31.6611
1790.38	34.5615
1791.4	30.7202
1792.42	32.6084
1793.43	26.8673
1794.45	26.8696
1795.47	25.931
1796.48	29.7974
1797.5	25.9734
1798.51	25.983
1799.53	28.8615
1800.55	30.7603
1801.56	30.7479
1802.58	25.9472
1803.59	29.808
1804.61	30.78
1805.62	25.0265
1806.64	29.8606
1807.65	28.9016
1808.66	28.9
1809.68	27.9367
1810.69	25.0446
1811.7	26.9659
1812.72	29.8594
1813.73	30.8365
1814.74	27.9644
1815.76	26.0496
1816.77	27.9853
1817.78	27.9653
1818.79	30.8653
1819.8	31.8378
1820.82	28.9482
1821.83	27.9918
1822.84	33.8081
1823.85	28.965
1824.86	28.9628
1825.87	30.907
1826.88	31.8741
1827.89	28.005
1828.9	28.0007
1829.91	29.9256
1830.92	31.8467
1831.93	27.9817
1832.94	27.995
1833.95	29.9382
1834.96	27.9774
1835.97	31.8007
1836.98	28.0305
1837.99	30.8427
1839	28.9015
1840	25.0613
1841.01	25.9763
1842.02	26.8911
1843.03	27.8293
1844.04	28.7904
1845.04	24.9293
1846.05	25.8981
1847.06	30.7496
1848.07	27.7533
1849.07	26.7923
1850.08	27.7305
1851.09	26.7323
1852.09	26.7115
1853.1	25.7462
1854.1	25.7325
1855.11	26.6611
1856.11	25.6742
1857.12	23.7513
1858.12	26.6114
1859.13	22.7595
1860.13	25.6081
1861.14	25.6156
1862.14	26.5831
1863.15	25.606
1864.15	27.4911
1865.15	27.4672
1866.16	26.4753
1867.16	26.4274
1868.16	23.5383
1869.17	27.335
1870.17	26.376
1871.17	28.2689
1872.17	26.3548
1873.18	29.1838
1874.18	28.2195
1875.18	28.1901
1876.18	28.1454
1877.18	26.2205
1878.18	25.235
1879.19	23.381
1880.19	27.1836
1881.19	26.2302
1882.19	24.2977
1883.19	25.1867
1884.19	25.1563
1885.19	23.28
1886.19	28.0267
1887.19	28.9636
1888.19	26.1031
1889.19	27.0064
1890.19	28.8704
1891.19	26.0592
1892.18	29.817
1893.18	27.9178
1894.18	28.8116
1895.18	30.6738
1896.18	25.9816
1897.18	24.1145
1898.17	27.8801
1899.17	30.6809
1900.17	28.7776
1901.16	26.8944
1902.16	26.9119
1903.16	29.7405
1904.16	28.7856
1905.15	28.7774
1906.15	27.8229
1907.14	28.739
1908.14	26.8609
1909.14	26.8692
1910.13	26.8905
1911.13	31.6284
1912.12	28.8083
1913.12	25.9747
1914.11	29.7531
1915.11	26.9491
1916.1	25.0687
1917.1	27.8825
1918.09	28.8082
1919.08	26.9372
1920.08	28.8609
1921.07	27.9181
1922.06	27.9376
1923.06	29.8214
1924.05	27.9154
1925.04	25.0643
1926.04	26.969
1927.03	26.9962
1928.02	26.0628
1929.01	26.0706
1930	28.9337
1931	27.0629
1931.99	27.0568
1932.98	25.1405
1933.97	25.1414
1934.96	30.921
1935.95	26.2166
1936.94	31.9056
1937.93	27.1141
1938.92	26.1574
1939.91	29.9795
1940.9	29.0438
1941.89	24.2963
1942.88	24.3035
1943.87	25.2401
1944.86	25.2548
1945.85	28.1433
1946.84	25.2899
1947.83	27.1952
1948.82	31.9693
1949.8	30.0732
1950.79	30.1122
1951.78	32.0748
1952.77	30.177
1953.76	28.2563
1954.74	28.1931
1955.73	27.217
1956.72	30.1393
1957.7	26.3221
1958.69	27.2934
1959.68	30.1638
1960.66	26.3038
1961.65	25.3225
1962.63	30.1187
1963.62	29.1604
1964.61	31.0871
1965.59	30.1201
1966.58	32.0546
1967.56	27.2608
1968.55	30.1466
1969.53	31.088
1970.52	30.0904
1971.5	29.1102
1972.48	31.0253
1973.47	30.0562
1974.45	28.117
1975.44	31.9505
1976.42	31.964
1977.4	31.9632
1978.39	28.1088
1979.37	34.806
1980.35	33.8475
1981.33	29.9938
1982.31	34.7685
1983.3	32.8299
1984.28	32.804
1985.26	34.6979
1986.24	31.8159
1987.22	32.7801
1988.21	32.7529
1989.19	34.5793
1990.17	32.731
1991.15	33.6997
1992.13	32.228
1993.11	36.0232
1994.09	34.8773
1995.07	33.7596
1996.05	36.3357
1997.03	35.9611
1998.01	30.0661
1998.99	34.5763
1999.97	34.9531
2000.95	36.738
2001.92	36.9616
2002.9	36.8361
2003.88	36.693
2004.86	38.5558
2005.84	34.1805
2006.81	37.0316
2007.79	36.4313
2008.77	36.9568
2009.75	32.5655
2010.73	38.3714
2011.7	40.1099
2012.68	35.9414
2013.67	34.959
2014.66	33.962
2015.64	35.8238
2016.63	35.8381
2017.62	40.5591
2018.61	35.8113
2019.6	32.9456
2020.58	37.613
2021.57	34.8028
2022.56	33.8555
2023.55	33.8227
2024.54	36.5967
2025.52	33.7467
2026.51	32.7849
2027.5	34.7399
2028.48	32.8302
2029.47	31.0095
2030.45	36.5107
2031.44	30.9266
2032.43	31.864
2033.41	27.2305
2034.4	32.8407
2035.38	33.7225
2036.37	33.7936
2037.35	31.9122
2038.34	33.7715
2039.32	31.8808
2040.31	28.1187
2041.29	33.6848
2042.27	30.8719
2043.26	29.926
2044.24	29.9597
2045.23	33.6698
2046.21	30.001
2047.19	32.7721
2048.17	31.7971
2049.16	29.9392
2050.14	29.9714
2051.12	31.8614
2052.11	28.1071
2053.09	28.1152
2054.07	30.9498
2055.05	29.0879
2056.03	27.2028
2057.01	33.7358
2058	28.1331
2058.98	30.025
2059.96	29.1021
2060.94	32.8336
2061.92	30.9734
2062.9	29.1064
2063.88	25.3749
2064.86	30.071
2065.84	30.0987
2066.82	32.9333
2067.8	31.0677
2068.78	32.961
2069.76	33.8907
2070.73	31.0674
2071.71	29.206
2072.69	27.3625
2073.67	30.1809
2074.65	30.1871
2075.63	29.2805
2076.6	24.5914
2077.58	29.2956
2078.56	30.2306
2079.54	31.1902
2080.51	25.5512
2081.49	28.3837
2082.47	31.217
2083.45	28.385
2084.42	26.4919
2085.4	31.2168
2086.37	35.0072
2087.35	31.2488
2088.32	28.4174
2089.3	29.3676
2090.28	28.4392
2091.25	29.3948
2092.23	28.4678
2093.2	28.5023
2094.18	28.5284
2095.15	29.4834
2096.13	30.4156
2097.1	30.4062
2098.07	25.6394
2099.05	28.4792
2100.02	28.4736
2101	27.5287
2101.97	29.4443
2102.94	30.3904
2103.92	27.5259
2104.89	27.5301
2105.86	29.4481
2106.83	26.6083
2107.8	26.6085
2108.78	28.4803
2109.75	28.4791
2110.72	30.3838
2111.69	27.5303
2112.66	28.4702
2113.63	30.3854
2114.61	29.4384
2115.58	28.4865
2116.55	29.4223
2117.52	29.4099
2118.49	26.5495
2119.46	31.2631
2120.43	28.3957
2121.4	31.2445
2122.37	29.3738
2123.34	33.1869
2124.31	25.5896
2125.28	29.3468
2126.25	27.4116
2127.21	30.223
2128.18	32.1
2129.15	25.4765
2130.12	29.2494
2131.09	27.3501
2132.06	27.3332
2133.02	26.3718
2133.99	27.3133
2134.96	26.3697
2135.93	26.3628
2136.89	30.1077
2137.86	28.2269
2138.83	29.158
2139.79	28.2207
2140.76	28.1958
2141.73	29.1291
2142.69	29.1126
2143.66	25.3655
2144.62	24.374
2145.59	29.0749
2146.55	28.1281
2147.52	29.055
2148.48	29.0397
2149.45	29.0206
2150.42	26.1727
2151.38	32.7265
2152.34	26.1764
2153.31	26.1662
2154.27	28.9625
2155.24	27.9845
2156.2	27.0115
2157.16	27.9343
2158.13	24.2059
2159.09	26.0774
2160.05	28.8632
2161.01	27.9021
2161.98	27.8907
2162.94	30.6864
2163.9	24.1441
2164.86	24.1256
2165.83	27.8512
2166.79	26.9124
2167.75	26.8913
2168.71	26.8525
2169.67	28.7211
2170.63	25.9616
2171.59	25.9531
2172.56	24.9791
2173.51	28.6851
2174.48	25.9036
2175.44	24.9735
2176.4	29.6126
2177.36	24.9576
2178.32	27.7446
2179.28	31.4404
2180.23	28.6556
2181.19	28.6494
2182.15	26.7825
2183.11	23.9879
2184.07	25.818
2185.03	28.5881
2185.99	29.5243
2186.95	29.5469
2187.9	27.7206
2188.86	25.8509
2189.82	25.8221
2190.78	25.8096
2191.73	27.6685
2192.69	25.8216
2193.65	29.5481
2194.6	25.872
2195.56	24.9387
2196.52	26.7693
2197.47	32.309
2198.43	27.6693
2199.38	25.8419
2200.34	32.3883
2201.3	28.7156
2202.25	26.7622
2203.21	28.6674
2204.16	31.5702
2205.12	25.9199
2206.07	29.5755
2207.03	29.5717
2207.98	25.8675
2208.93	26.8183
2209.89	25.8942
2210.84	24.9686
2211.8	24.9834
2212.75	24.9986
2213.7	28.7166
2214.66	26.8636
2215.61	27.8134
2216.56	31.5486
2217.51	25.9424
2218.47	25.0094
2219.42	25.0197
2220.37	25.0316
2221.32	21.2875
2222.27	27.802
2223.23	26.8689
2224.18	26.8905
2225.13	22.2404
2226.08	26.0066
2227.03	21.34
2227.98	27.9148
2228.93	24.1566
2229.88	26.9698
2230.83	26.9924
2231.78	23.258
2232.73	26.0955
2233.68	27.0545
2234.63	27.064
2235.58	22.3402
2236.53	25.1573
2237.48	20.4617
2238.43	22.3734
2239.38	22.3992
2240.33	22.3883
2241.27	25.2274
2242.22	25.2332
2243.17	27.1289
2244.12	22.3985
2245.07	25.2399
2246.01	24.3239
2246.96	17.7174
2247.91	26.2423
2248.85	24.3437
2249.8	23.3967
2250.75	28.1217
2251.69	28.099
2252.64	21.4849
2253.59	28.1446
2254.53	26.2733
2255.48	24.3788
2256.42	25.3324
2257.37	23.4507
2258.32	25.3602
2259.26	24.418
2260.2	25.3783
2261.15	28.2414
2262.1	23.501
2263.04	26.3683
2263.98	25.4444
2264.93	25.4794
2265.87	25.4952
2266.81	23.5721
2267.76	26.4147
2268.7	22.5836
2269.65	24.5055
2270.59	20.7136
2271.53	23.5955
2272.47	25.5211
2273.42	23.611
2274.36	28.4004
2275.3	24.5766
2276.24	24.5814
2277.18	24.6028
2278.13	25.5942
2279.07	22.7289
2280.01	20.7916
2280.95	20.7698
2281.89	22.6758
2282.83	24.6046
2283.77	21.7515
2284.71	22.7476
2285.65	26.6108
2286.59	27.5558
2287.54	23.7336
2288.47	25.6703
2289.41	23.7237
2290.35	26.5766
2291.29	26.5775
2292.23	21.7906
2293.17	27.5876
2294.11	23.745
2295.05	25.6578
2295.99	26.6051
2296.93	23.696
2297.86	24.6728
2298.8	23.7325
2299.74	23.7517
2300.68	26.646
2301.61	28.5896
2302.55	25.6922
2303.49	23.7578
2304.43	24.7286
2305.36	22.8106
2306.3	24.7508
2307.24	25.7206
2308.17	23.7786
2309.11	24.7405
2310.04	21.8603
2310.98	20.8986
2311.92	27.626
2312.85	25.6691
2313.79	24.7098
2314.72	26.6738
2315.66	26.6894
2316.59	25.6883
2317.52	22.7801
2318.46	26.6459
2319.39	28.5584
2320.33	29.5128
2321.26	26.6241
2322.2	26.6459
2323.13	27.6283
2324.06	33.4359
2325	38.2581
2325.93	46.9055
2326.86	75.8103
2327.79	215.538
2328.73	165.37
2329.66	57.3794
2330.59	40.9998
2331.52	28.4729
2332.46	27.5164
2333.39	25.5725
2334.32	29.4085
2335.25	23.6169
2336.18	26.5012
2337.11	25.5318
2338.04	26.4863
2338.97	21.6741
2339.91	26.4793
2340.84	27.4241
2341.77	23.5515
2342.7	24.4902
2343.63	24.4844
2344.56	23.5243
2345.49	23.5191
2346.41	24.4567
2347.34	24.4488
2348.27	24.4471
2349.2	22.5331
2350.13	25.3657
2351.06	24.2918
2351.99	23.4329
2352.91	26.2579
2353.84	27.1709
2354.77	25.2651
2355.7	24.3125
2356.63	27.1501
2357.55	27.1151
2358.48	25.1978
2359.41	27.0845
2360.33	25.1688
2361.26	23.2468
2362.19	24.1695
2363.11	24.1443
2364.04	24.1292
2364.97	22.2229