File: Data/3-Raman/raw/bu19w-ff07a-fi05-v_150 (500nm)_532nm_edge_100%_x100_vis_lwd_h50um_30sx2_01.txt
#Acq. time (s)=	30
#Accumulations=	2
#Range (cm-¹)=	50...5000
#Windows=	1
#Auto scanning=	Off
#Autofocus=	Off
#Macrospot=	Off
#AutoExposure=	Off
#Spike filter=	Multiple accum.
#Delay time (s)=	2
#Binning=	1
#Readout mode=	Signal
#DeNoise=	Off
#ICS correction=	On
#Dark correction=	Off
#Inst. Process=	Off
#Detector Gain=	Best Dynamic
#Detector ADC=	50 kHz HS
#Detector temperature (°C)=	-60.09
#Instrument=	LabRAM HR Evol
#Detector=	SIN-EM FIVIS
#Objective=	x100_VIS_LWD
#Grating=	150 (500nm)
#ND Filter=	100%
#Laser=	532nm_Edge
#Hole=	49.98
#Temperature=	0
#Range=	Visible
#StageXY=	75x50mm Scan+
#StageZ=	Z motor
#X (µm)=	0
#Y (µm)=	0
#Z (µm)=	-14.1
#Full time(mm:ss)=	1:05
#Project=	21_05_28
#Sample=	BU19w
#Site=
#Title=	BU19w-FF07a-FI05-V_150 (500nm)_532nm_Edge_100%_x100_VIS_LWD_H50um_30sX2
#Remark=
#Date=	28.05.2021 19:30
#Acquired=	28.05.2021 19:30:06
51.5961	52188.1
56.2453	46426.6
60.8921	31750.3
65.5367	18359.7
70.1768	12176.7
74.8167	9257.02
79.4543	7422.02
84.0897	6213.95
88.7227	5285.2
93.3513	4668.55
97.9798	4327.41
102.606	3986.45
107.23	3524.22
111.851	3226.01
116.469	2877.05
121.086	2759.4
125.7	2621.17
130.313	2558.65
134.921	2462.57
139.529	2289.49
144.134	2297.93
148.738	2776.81
153.337	4529.76
157.936	5704.09
162.532	3993.49
167.126	2749.55
171.716	2629.55
176.306	4101.91
180.894	8844.23
185.477	11584.9
190.06	7547.99
194.64	3773.11
199.219	2385.99
203.793	2077.69
208.367	2079.97
212.939	2040.7
217.506	1951.3
222.073	2052.7
226.638	2508.45
231.199	3074.6
235.759	3478.73
240.318	4911.29
244.872	5424.79
249.425	4279.2
253.977	3355.73
258.524	2896.32
263.071	3288.68
267.616	5278.62
272.156	9761.02
276.697	12456.6
281.233	9179.2
285.769	5507.32
290.303	4239.26
294.832	5162.23
299.361	6512.53
303.886	5661.01
308.411	4014.5
312.934	3126.77
317.452	3419.11
321.97	4493.2
326.484	5454.84
330.998	4511.55
335.507	3448.62
340.017	3486
344.524	4243.62
349.027	4322.24
353.53	3471.71
358.028	2616.81
362.527	2524.17
367.021	2692.77
371.515	2561.41
376.004	2546.04
380.494	3004.67
384.979	3585.12
389.465	3939.06
393.946	3744.88
398.427	3058.05
402.903	2559.08
407.38	2597.12
411.852	2991.79
416.324	2910.66
420.792	2208.06
425.26	1787.93
429.723	1648.86
434.187	1636.47
438.646	1751.34
443.105	2167.14
447.56	3195.01
452.015	4444.76
456.466	3828.62
460.914	2662.04
465.362	2067.21
469.807	1948.49
474.251	2023.15
478.69	2241.15
483.13	2488.49
487.566	2879.25
491.999	3130.18
496.432	3095.95
500.861	2789.1
505.29	2421.54
509.715	2145.63
514.138	1954.25
518.56	1909.74
522.979	1885.56
527.395	1970.51
531.811	2006.22
536.223	2071.32
540.635	2140.07
545.042	2125.34
549.448	2306.74
553.853	2279.11
558.255	2334.87
562.654	2145.17
567.053	1994.18
571.448	1992.21
575.841	2220.9
580.232	3240.97
584.622	4863.76
589.009	5243.06
593.393	3868.93
597.777	2948.71
602.157	3147.21
606.535	3796.6
610.913	3813.67
615.287	3081.05
619.659	2211.91
624.029	1898.06
628.398	1910.27
632.763	2055
637.127	2279.04
641.488	2180.67
645.849	2097.53
650.206	2054.77
654.561	2290.81
658.914	2696.6
663.267	3007.74
667.615	3119.13
671.962	3346.9
676.307	3375.01
680.649	2932.02
684.991	2241.49
689.33	1837.72
693.666	1656.44
698	1573.41
702.332	1508.85
706.662	1476.16
710.992	1434.35
715.318	1377.32
719.641	1469.56
723.963	1442.04
728.283	1471.29
732.6	1471.88
736.918	1479.45
741.231	1561.09
745.542	1642.99
749.852	1692.76
754.159	1918.56
758.464	2147.67
762.767	2682.71
767.068	3611.58
771.369	5191.11
775.666	6138.62
779.961	5518.82
784.254	3940.53
788.545	2827.21
792.834	2223.89
797.12	1935.9
801.405	1783.93
805.688	1681.96
809.968	1598.27
814.247	1567.63
818.524	1508.63
822.798	1532.12
827.071	1440.46
831.341	1450.17
835.612	1446.69
839.878	1462.95
844.142	1419.47
848.405	1422.88
852.665	1411.11
856.923	1472.11
861.18	1400.8
865.434	1407.48
869.686	1429.08
873.936	1441.52
878.185	1459.04
882.431	1450.98
886.675	1434.69
890.915	1445.95
895.155	1459.83
899.393	1456.71
903.63	1454.61
907.864	1486.26
912.096	1457.57
916.326	1465.53
920.554	1472.08
924.78	1548.07
929.004	1589.57
933.227	1660.77
937.447	1801.33
941.665	1987.04
945.881	2232.82
950.095	2321.87
954.305	2172.54
958.516	2169.67
962.724	2342.51
966.93	2364.41
971.134	2144.68
975.337	1963.93
979.537	1808.04
983.735	1667.5
987.93	1723.93
992.124	1634.45
996.316	1648.84
1000.51	1646.29
1004.7	1670.61
1008.88	1702.68
1013.06	1679.55
1017.25	1773.1
1021.43	1833.77
1025.61	1942.18
1029.78	2123.73
1033.96	2343.14
1038.13	2818.3
1042.3	3983.42
1046.47	5909
1050.63	7325.86
1054.8	6594.12
1058.96	4779.64
1063.12	3550.78
1067.28	3081.78
1071.44	2952.79
1075.59	3447.17
1079.74	4444.48
1083.89	6104.32
1088.04	7091.2
1092.19	6715
1096.33	5757.24
1100.48	5573
1104.62	6195.67
1108.76	6628.31
1112.89	6244.51
1117.03	5618.63
1121.16	5451.77
1125.29	5806.47
1129.42	5952.81
1133.55	5480.86
1137.68	4525.68
1141.8	3801.36
1145.92	3750.43
1150.04	4289.72
1154.16	5044.31
1158.27	4989.86
1162.39	4183.8
1166.5	3500.15
1170.61	2964.45
1174.72	2560.27
1178.82	2231.47
1182.93	2191.31
1187.03	2144.36
1191.13	2144.55
1195.23	2237.22
1199.33	2139.81
1203.42	2054.55
1207.51	2018.33
1211.6	2067.45
1215.69	2304.26
1219.78	2571.27
1223.86	2646.37
1227.95	2476.06
1232.03	2640.63
1236.11	3027.72
1240.18	3190.11
1244.26	2830.38
1248.33	2578.93
1252.41	2322.9
1256.48	2059.23
1260.54	1945.55
1264.61	2542.21
1268.67	5557.43
1272.74	5231.9
1276.8	2574.49
1280.86	1866.03
1284.91	1777.25
1288.97	1767.49
1293.02	1712.2
1297.07	1698.89
1301.12	1696.49
1305.17	1696.79
1309.21	1703.02
1313.25	1680.82
1317.3	1706.39
1321.34	1701.36
1325.37	1672.55
1329.41	1693.84
1333.44	1700.83
1337.48	1705.23
1341.5	1678.3
1345.53	1749.15
1349.56	1750.91
1353.59	1832.32
1357.61	1783.39
1361.63	1847.52
1365.65	2018.64
1369.66	4069.26
1373.68	9102.92
1377.69	5427.11
1381.7	2319.24
1385.72	1881
1389.72	1874.57
1393.73	2224.97
1397.73	2150.08
1401.74	1766.65
1405.74	1694.28
1409.73	1681.17
1413.73	1655.39
1417.73	1591.12
1421.72	1583.04
1425.71	1566.84
1429.7	1540.94
1433.69	1575.43
1437.67	1576.3
1441.66	1544.62
1445.64	1606.48
1449.62	1539.93
1453.6	1558.97
1457.57	1521.64
1461.55	1583.58
1465.52	1542.56
1469.49	1542.82
1473.46	1522.67
1477.43	1586.72
1481.39	1539.7
1485.36	1565.1
1489.32	1570.78
1493.28	1547.28
1497.24	1540.45
1501.19	1547.42
1505.15	1563.41
1509.1	1524.41
1513.05	1553.56
1517	1524.52
1520.95	1550.01
1524.9	1538.73
1528.84	1574.12
1532.78	1588.36
1536.72	1568.71
1540.66	1583.04
1544.6	1559.58
1548.53	1572.95
1552.46	1564.04
1556.4	1568.5
1560.32	1545.6
1564.25	1576.74
1568.18	1543.87
1572.1	1590.16
1576.02	1550.41
1579.94	1525.13
1583.86	1578.92
1587.78	1579.51
1591.69	1624.34
1595.61	1564.23
1599.52	1563.8
1603.43	1607.67
1607.34	1595.12
1611.24	1589.34
1615.15	1552.05
1619.05	1586.87
1622.95	1588.04
1626.85	1595.21
1630.74	1594.93
1634.64	1594.21
1638.53	1612.55
1642.42	1556.64
1646.31	1599.69
1650.2	1590.22
1654.09	1610.56
1657.97	1578.94
1661.86	1580.84
1665.74	1575.71
1669.62	1618.47
1673.49	1591.51
1677.37	1612.53
1681.24	1632.65
1685.12	1599.54
1688.99	1600.87
1692.86	1584.63
1696.72	1659.06
1700.59	1641.32
1704.45	1599.45
1708.31	1628.76
1712.17	1611.07
1716.03	1644.65
1719.89	1605.34
1723.74	1642.67
1727.6	1599.66
1731.45	1613.88
1735.3	1662.88
1739.14	1626.32
1742.99	1657.86
1746.83	1613
1750.68	1652.96
1754.52	1631.21
1758.36	1606.74
1762.19	1606.29
1766.03	1601.88
1769.86	1635.24
1773.69	1653.65
1777.53	1632.12
1781.35	1635.33
1785.18	1609.88
1789	1644.37
1792.83	1652.83
1796.65	1651.97
1800.47	1624.71
1804.29	1651.84
1808.1	1703.38
1811.92	1655.84
1815.73	1668.29
1819.54	1671.53
1823.35	1667.73
1827.16	1681.54
1830.97	1667.53
1834.77	1671
1838.58	1675.13
1842.38	1684.63
1846.18	1697.47
1849.97	1722.68
1853.77	1713.29
1857.56	1705.37
1861.36	1709.06
1865.15	1694.85
1868.93	1710.6
1872.72	1712.56
1876.51	1648.3
1880.29	1707.15
1884.07	1713.08
1887.86	1685.01
1891.63	1699.41
1895.41	1724.9
1899.19	1672.18
1902.96	1730.63
1906.73	1723.16
1910.5	1656.89
1914.27	1710.1
1918.04	1742.3
1921.8	1707.29
1925.57	1677.88
1929.33	1714.54
1933.09	1703.16
1936.85	1733.6
1940.6	1699.69
1944.36	1721.72
1948.11	1717.59
1951.87	1725.21
1955.61	1728.39
1959.36	1709.06
1963.11	1740.81
1966.86	1748.04
1970.6	1701.21
1974.34	1726.01
1978.08	1728.87
1981.82	1752.01
1985.56	1767.31
1989.29	1741.31
1993.02	1753.28
1996.75	1742.55
2000.49	1739.88
2004.21	1740.08
2007.94	1778.88
2011.67	1790.34
2015.39	1754
2019.11	1740.69
2022.83	1722.85
2026.55	1762.89
2030.27	1761.76
2033.98	1795.35
2037.69	1769.15
2041.41	1766.58
2045.12	1743.72
2048.82	1790.49
2052.53	1779.93
2056.24	1725.5
2059.94	1746.17
2063.64	1747.77
2067.34	1733.26
2071.04	1767.66
2074.74	1821.59
2078.43	1756.57
2082.13	1775.73
2085.82	1804.02
2089.51	1798.63
2093.2	1809.15
2096.88	1809.39
2100.57	1788.84
2104.25	1805.81
2107.94	1805.71
2111.62	1811.84
2115.3	1801.18
2118.97	1807.95
2122.65	1828.84
2126.32	1848.37
2129.99	1813.83
2133.66	1836.57
2137.33	1858.2
2141	1827.77
2144.67	1827.56
2148.33	1901.72
2151.99	1857.15
2155.66	1843.05
2159.31	1846.45
2162.97	1875.66
2166.63	1864.02
2170.28	1889.2
2173.94	1881.41
2177.59	1884.07
2181.24	1878.79
2184.89	1856.15
2188.53	1894.96
2192.18	1867.19
2195.82	1925.74
2199.46	1900.08
2203.1	1866.38
2206.74	1915.07
2210.38	1927.64
2214.01	1892.91
2217.65	1923.28
2221.28	1928.07
2224.91	1955.05
2228.54	1937.76
2232.16	1954.61
2235.79	1943.95
2239.41	1922.08
2243.04	1962.22
2246.66	1944.83
2250.28	1919.1
2253.89	1920.52
2257.51	1910.92
2261.12	1905.91
2264.74	1881.92
2268.35	1876.8
2271.96	1915.34
2275.57	1890.39
2279.17	1937.45
2282.78	1916.31
2286.38	1924.38
2289.98	1901.24
2293.58	1900.51
2297.18	1946.21
2300.78	1967.42
2304.37	1927.67
2307.97	1957.61
2311.56	2046.06
2315.15	2501.04
2318.74	2487.33
2322.33	2084.64
2325.91	1965.16
2329.5	1951.63
2333.08	1959.58
2336.66	1923.88
2340.24	1958.63
2343.82	1962.05
2347.4	1985.84
2350.97	1936.35
2354.54	2000.05
2358.12	1949.56
2361.69	1984.8
2365.26	1976.18
2368.82	1966.81
2372.39	1984.8
2375.95	1967.44
2379.52	1938.2
2383.08	1975.63
2386.64	1951.51
2390.19	1966.37
2393.75	1990.77
2397.31	1935.95
2400.86	2003.75
2404.41	1985.55
2407.96	1962.1
2411.51	2020.18
2415.06	1988.86
2418.6	1998.41
2422.15	1996.32
2425.69	1929.27
2429.23	1990.82
2432.77	1963.26
2436.31	1966.61
2439.84	1969.25
2443.38	1991.61
2446.91	1988.9
2450.44	1954.78
2453.97	2004.34
2457.5	1982.27
2461.03	1982.88
2464.55	1982.36
2468.08	1997.12
2471.6	2009.77
2475.12	2036.05
2478.64	2028.99
2482.16	2014.72
2485.67	2070.35
2489.19	2043.68
2492.7	1990.02
2496.21	2042.3
2499.72	2043.62
2503.23	2057.36
2506.74	2041.75
2510.25	2040.66
2513.75	2061.11
2517.25	1993.75
2520.75	2054.94
2524.25	2000.64
2527.75	2059.47
2531.25	2072.51
2534.74	2079.38
2538.24	2000.12
2541.73	2047.77
2545.22	2050.27
2548.71	2058.28
2552.2	2085.8
2555.68	2033.45
2559.17	2046.82
2562.65	2033.35
2566.13	2029.1
2569.61	2042.24
2573.09	2078.41
2576.57	2030.82
2580.04	2069.82
2583.51	1998.84
2586.99	2034.31
2590.46	2031.5
2593.93	2102.73
2597.4	2048.14
2600.86	2087.5
2604.33	2056.97
2607.79	2060.59
2611.25	2050
2614.71	2078.31
2618.17	2071.87
2621.63	2068.39
2625.09	2133.69
2628.54	2059.1
2631.99	2141.69
2635.45	2115.22
2638.9	2062.29
2642.34	2101.01
2645.79	2122.96
2649.24	2040.63
2652.68	2108.67
2656.12	2107.43
2659.56	2121.88
2663.01	2098.15
2666.44	2055.43
2669.88	2129.73
2673.32	2108.6
2676.75	2127.31
2680.18	2105.99
2683.61	2107.65
2687.04	2110.99
2690.47	2094.26
2693.9	2090.39
2697.32	2084.23
2700.75	2085.07
2704.17	2095.28
2707.59	2108.36
2711.01	2092.23
2714.43	2042.09
2717.84	2088.21
2721.26	2068.63
2724.67	2037.16
2728.08	2114.14
2731.49	2089.48
2734.9	2103.03
2738.31	2094.12
2741.71	2089.77
2745.12	2093.46
2748.52	2098.73
2751.92	2091.8
2755.32	2073.39
2758.72	2123.46
2762.12	2076.59
2765.52	2104.51
2768.91	2116.08
2772.3	2106.58
2775.7	2088.41
2779.09	2090.6
2782.47	2113.22
2785.86	2120.59
2789.25	2150.46
2792.63	2119.11
2796.01	2123.43
2799.4	2069.53
2802.78	2159.83
2806.15	2119.73
2809.53	2107.74
2812.91	2091.9
2816.28	2133.92
2819.65	2103.91
2823.03	2105.08
2826.4	2123.32
2829.76	2106.28
2833.13	2123.09
2836.5	2123.51
2839.86	2117.78
2843.22	2097.55
2846.59	2112.31
2849.95	2103.59
2853.3	2134.56
2856.66	2114.87
2860.02	2075.79
2863.37	2136.14
2866.72	2105.77
2870.08	2158.87
2873.43	2126.46
2876.77	2086.38
2880.12	2113
2883.47	2148.08
2886.81	2101.93
2890.15	2098.13
2893.5	2111.21
2896.84	2130.41
2900.17	2115.27
2903.51	2145.2
2906.85	2159.73
2910.18	2122.98
2913.52	2135.28
2916.85	2137.96
2920.18	2128.02
2923.51	2117.97
2926.83	2128.52
2930.16	2134.98
2933.48	2126.08
2936.81	2168.76
2940.13	2156.69
2943.45	2174.79
2946.77	2142.09
2950.09	2082.24
2953.4	2103.22
2956.72	2130.83
2960.03	2108.05
2963.34	2118.33
2966.65	2114.66
2969.96	2133.2
2973.27	2080.84
2976.58	2062.32
2979.88	2155.8
2983.19	2083.89
2986.49	2129.42
2989.79	2118.76
2993.09	2060.26
2996.39	2123.04
2999.68	2075.07
3002.98	2084.39
3006.27	2092.78
3009.57	2043.94
3012.86	2118.52
3016.15	2059.42
3019.43	2040.75
3022.72	2087.11
3026.01	2072.18
3029.29	2090.31
3032.57	2080.08
3035.86	2056.49
3039.14	2032.83
3042.41	2057.42
3045.69	2077.33
3048.97	2062.24
3052.24	2018.71
3055.52	2082.31
3058.79	2055.79
3062.06	2016.25
3065.33	2020.65
3068.6	2031.44
3071.86	2063.62
3075.13	2014.34
3078.39	2079.03
3081.65	2051.08
3084.91	2046.69
3088.17	2052.63
3091.43	2040.15
3094.69	2015.4
3097.95	2010.89
3101.2	2055.2
3104.45	2081.08
3107.7	2055.61
3110.95	2056.47
3114.2	2011.94
3117.45	2051.35
3120.7	2028.94
3123.94	2039.85
3127.18	2025.96
3130.43	2067.28
3133.67	2021.91
3136.91	2083.22
3140.14	2050.06
3143.38	2061.67
3146.61	2008.46
3149.85	2046.92
3153.08	2024.39
3156.31	2012.26
3159.54	2048.83
3162.77	2030.01
3166	2032.18
3169.22	2013.16
3172.45	2051.26
3175.67	2078.77
3178.89	2035.49
3182.11	2072.34
3185.33	2048.17
3188.55	2079.08
3191.77	2083.22
3194.98	2057.82
3198.2	2082.88
3201.41	2089.8
3204.62	2055.86
3207.83	2066.74
3211.04	2052.02
3214.25	2036.5
3217.45	2094.38
3220.66	2098.02
3223.86	2101.75
3227.06	2055.26
3230.26	2075.41
3233.46	2042.43
3236.66	2081.64
3239.85	2072.77
3243.05	2092.58
3246.24	2044.87
3249.44	2077.18
3252.63	2099.25
3255.82	2116.62
3259.01	2092.92
3262.19	2048.84
3265.38	2044.56
3268.56	2083.94
3271.75	2095.4
3274.93	2064.71
3278.11	2036.86
3281.29	2064.93
3284.47	2084.97
3287.64	2077.37
3290.82	2081.04
3293.99	2107.76
3297.17	2127.7
3300.34	2106.71
3303.51	2121.44
3306.68	2077.57
3309.84	2124.83
3313.01	2134.64
3316.18	2140.51
3319.34	2138.73
3322.5	2151.09
3325.66	2164.4
3328.82	2183.38
3331.98	2141.86
3335.14	2136.47
3338.29	2132.21
3341.45	2152.64
3344.6	2152.36
3347.75	2155.45
3350.9	2169.43
3354.05	2158.87
3357.2	2177.78
3360.35	2145.9
3363.49	2168.01
3366.64	2194.9
3369.78	2175.7
3372.92	2205.65
3376.06	2189.62
3379.2	2274.74
3382.34	2314.69
3385.48	2307.3
3388.61	2453.35
3391.75	2430.17
3394.88	2500.61
3398.01	2587.52
3401.14	2825.77
3404.27	3169.08
3407.4	3788.84
3410.52	5295.46
3413.65	8958.49
3416.77	18562.8
3419.89	28108.3
3423.01	22873.5
3426.13	11945.1
3429.25	6151.96
3432.37	4003.31
3435.49	3284.98
3438.6	2863.98
3441.72	2653.5
3444.83	2505.05
3447.94	2421.99
3451.05	2420.92
3454.16	2343.28
3457.26	2338.03
3460.37	2328.66
3463.47	2383.89
3466.58	2465.51
3469.68	2465.95
3472.78	2549.37
3475.88	2663.72
3478.98	2827.22
3482.07	3018.98
3485.17	3343.78
3488.26	3856.29
3491.36	4530.22
3494.45	5606.92
3497.54	6914.98
3500.63	8185.99
3503.72	8463.57
3506.81	7748.13
3509.89	6249.57
3512.98	4998.48
3516.06	4039.8
3519.14	3481.81
3522.22	3030.34
3525.3	2778.11
3528.38	2639
3531.45	2403.14
3534.53	2347.91
3537.61	2284.95
3540.68	2184.48
3543.75	2123.66
3546.82	2107.78
3549.89	2115.11
3552.96	2037.79
3556.03	2065.19
3559.09	2048.5
3562.16	1983.49
3565.22	1956.85
3568.28	2014.23
3571.34	1982.22
3574.4	1921.73
3577.46	1957.11
3580.52	1960.09
3583.57	1869
3586.63	1900.09
3589.68	1897.03
3592.73	1860.54
3595.78	1897
3598.83	1859.36
3601.88	1808.5
3604.93	1830.37
3607.97	1814.23
3611.02	1808.5
3614.06	1789.44
3617.1	1804.33
3620.14	1818.35
3623.18	1828.66
3626.22	1787.15
3629.26	1811.77
3632.3	1811.77
3635.33	1763.66
3638.36	1795.09
3641.4	1756.18
3644.43	1792.74
3647.46	1757.32
3650.49	1749.63
3653.51	1719.6
3656.54	1725.01
3659.57	1713.55
3662.59	1708.48
3665.61	1745.49
3668.63	1673.34
3671.65	1708.08
3674.67	1721.24
3677.69	1674.11
3680.71	1701.63
3683.72	1709.24
3686.74	1704.59
3689.75	1691.47
3692.76	1663.23
3695.77	1682.34
3698.78	1610.14
3701.79	1690.94
3704.79	1669.32
3707.8	1675.2
3710.81	1681.84
3713.81	1658.88
3716.81	1693.71
3719.81	1660.18
3722.81	1662.58
3725.81	1632.47
3728.81	1658.38
3731.8	1685.14
3734.8	1679.35
3737.79	1631.47
3740.78	1649.16
3743.77	1668.53
3746.76	1653.51
3749.75	1649.74
3752.74	1641.11
3755.73	1628.66
3758.71	1615.32
3761.7	1639.88
3764.68	1579.94
3767.66	1649.84
3770.64	1636.5
3773.62	1650.77
3776.6	1626.38
3779.58	1652.19
3782.55	1630.86
3785.53	1631.28
3788.5	1624.25
3791.47	1604.11
3794.44	1624.81
3797.41	1613.56
3800.38	1609.01
3803.35	1579.18
3806.32	1573.98
3809.28	1609.44
3812.24	1603.45
3815.21	1624.91
3818.17	1630.35
3821.13	1589.49
3824.09	1632.9
3827.04	1608.26
3830	1591.2
3832.96	1594.97
3835.91	1593.21
3838.86	1566.83
3841.82	1608.85
3844.77	1553.9
3847.72	1576.01
3850.67	1549.62
3853.61	1588.13
3856.56	1580.93
3859.5	1566.09
3862.45	1561.75
3865.39	1584.11
3868.33	1559.57
3871.27	1578
3874.21	1542.69
3877.15	1568.69
3880.09	1573.42
3883.02	1568.37
3885.96	1570.82
3888.89	1581.81
3891.82	1572.54
3894.75	1542.03
3897.68	1538.24
3900.61	1541.01
3903.54	1528.35
3906.47	1554.92
3909.39	1557.64
3912.31	1555.4
3915.24	1572.22
3918.16	1532.27
3921.08	1559.82
3924	1541.94
3926.92	1562.27
3929.83	1511.48
3932.75	1551.71
3935.67	1520.44
3938.58	1542.16
3941.49	1536.4
3944.4	1540.06
3947.31	1530.41
3950.22	1507.5
3953.13	1520.14
3956.04	1533.8
3958.94	1506.41
3961.85	1510.7
3964.75	1505.48
3967.65	1525.28
3970.55	1500.07
3973.45	1479.69
3976.35	1497.67
3979.25	1529.01
3982.15	1513.18
3985.04	1483.85
3987.94	1506.36
3990.83	1474.97
3993.72	1502.07
3996.61	1496.74
3999.5	1478.88
4002.39	1504.4
4005.28	1490.47
4008.16	1472.76
4011.05	1504.21
4013.93	1489.37
4016.81	1488.05
4019.7	1471.28
4022.58	1442.9
4025.46	1476.32
4028.33	1518.5
4031.21	1518.18
4034.09	1484.06
4036.96	1473.15
4039.84	1514.56
4042.71	1441.68
4045.58	1458.61
4048.45	1478.52
4051.32	1436.48
4054.19	1429.4
4057.05	1485.54
4059.92	1456.23
4062.78	1484.15
4065.65	1457.68
4068.51	1484.65
4071.37	1434.76
4074.23	1433.49
4077.09	1434.14
4079.95	1427.95
4082.81	1424.67
4085.66	1483.82
4088.52	1433.67
4091.37	1449.84
4094.22	1459.3
4097.07	1415.9
4099.92	1446.82
4102.77	1436.67
4105.62	1456.78
4108.47	1435.63
4111.31	1482.99
4114.16	1414.71
4117	1430.44
4119.84	1421.5
4122.69	1427.26
4125.53	1403.84
4128.36	1457.76
4131.2	1386.79
4134.04	1451.13
4136.88	1418.97
4139.71	1406.55
4142.54	1412.48
4145.38	1400.63
4148.21	1412.83
4151.04	1391.86
4153.87	1403.86
4156.69	1379.12
4159.52	1389.04
4162.35	1397.49
4165.17	1381.68
4168	1399.1
4170.82	1406.8
4173.64	1389.16
4176.46	1388.18
4179.28	1416.54
4182.1	1394.16
4184.91	1364
4187.73	1455.23
4190.54	1386.05
4193.36	1444.3
4196.17	1443.99
4198.98	1437.03
4201.79	1458.45
4204.6	1461.32
4207.41	1431.73
4210.22	1442.41
4213.02	1420.62
4215.83	1363.39
4218.63	1371.85
4221.44	1418.68
4224.24	1373.74
4227.04	1360.11
4229.84	1346.71
4232.64	1361.02
4235.43	1347.8
4238.23	1351.5
4241.02	1375.1
4243.82	1387.85
4246.61	1386.79
4249.4	1369.68
4252.19	1349.4
4254.98	1380.01
4257.77	1364.52
4260.56	1363.01
4263.35	1339.49
4266.13	1349.11
4268.92	1356.83
4271.7	1272.94
4274.48	1325.89
4277.26	1318.14
4280.04	1344.51
4282.82	1300.1
4285.6	1330.31
4288.38	1324.98
4291.15	1283.05
4293.93	1317.99
4296.7	1270.06
4299.47	1277.95
4302.25	1283.69
4305.02	1293.49
4307.79	1276.88
4310.55	1278.61
4313.32	1310.97
4316.09	1261.77
4318.85	1298.9
4321.62	1291.18
4324.38	1281.31
4327.14	1263.22
4329.9	1274.71
4332.66	1277.91
4335.42	1255.72
4338.18	1264.98
4340.94	1268.37
4343.69	1241.19
4346.45	1280.41
4349.2	1258.57
4351.95	1272.44
4354.7	1300.98
4357.45	1272.16
4360.2	1252.51
4362.95	1257.32
4365.7	1264.32
4368.44	1253.79
4371.19	1242.35
4373.93	1268.62
4376.68	1246.65
4379.42	1244.06
4382.16	1246.57
4384.9	1249.17
4387.64	1226.35
4390.37	1218.39
4393.11	1240.5
4395.85	1206.86
4398.58	1204.25
4401.31	1228.5
4404.05	1229.87
4406.78	1212.63
4409.51	1178.77
4412.24	1203.99
4414.96	1198.88
4417.69	1243.74
4420.42	1197.41
4423.14	1184.67
4425.87	1169.88
4428.59	1180.16
4431.31	1172.68
4434.03	1198.64
4436.75	1193.17
4439.47	1171.92
4442.19	1163.09
4444.91	1187.86
4447.62	1191.58
4450.34	1211.06
4453.05	1169.53
4455.76	1179.43
4458.47	1153.49
4461.19	1184.25
4463.89	1168.92
4466.6	1180.9
4469.31	1181.39
4472.02	1191.4
4474.72	1164.66
4477.43	1144.32
4480.13	1141.98
4482.83	1178.76
4485.53	1165.94
4488.23	1159.35
4490.93	1120.96
4493.63	1143.63
4496.33	1153.43
4499.02	1114.74
4501.72	1146.94
4504.41	1115.47
4507.11	1138.17
4509.8	1152.44
4512.49	1137.01
4515.18	1110.98
4517.87	1127.44
4520.56	1113.15
4523.24	1129.8
4525.93	1133.7
4528.61	1117.35
4531.3	1136.17
4533.98	1131.6
4536.66	1127.06
4539.34	1097.99
4542.02	1119.17
4544.7	1086.91
4547.38	1114.56
4550.05	1097.28
4552.73	1090.8
4555.4	1115.63
4558.08	1077.28
4560.75	1058.52
4563.42	1059.29
4566.09	1075.53
4568.76	1088.88
4571.43	1097.27
4574.1	1081.65
4576.77	1064.48
4579.43	1060.86
4582.1	1094.66
4584.76	1036.18
4587.42	1070.7
4590.08	1076.85
4592.74	1070.9
4595.4	1083.57
4598.06	1075.63
4600.72	1069.76
4603.38	1076.12
4606.03	1056.28
4608.69	1036.41
4611.34	1043.96
4613.99	1013.04
4616.64	1024.93
4619.29	1051.19
4621.94	1050.03
4624.59	1041.11
4627.24	1042.02
4629.89	1050.61
4632.53	1054.76
4635.18	1030
4637.82	1040.55
4640.46	1006.82
4643.1	1037.31
4645.74	1006.01
4648.38	1018.19
4651.02	1003.99
4653.66	1043.55
4656.3	1044.87
4658.93	1021.65
4661.57	984.658
4664.2	989.087
4666.83	1009.04
4669.46	979.555
4672.09	989.305
4674.72	1005.77
4677.35	1003.19
4679.98	1016.29
4682.61	1002.43
4685.23	942.468
4687.86	984.775
4690.48	985.513
4693.1	995.277
4695.73	963.259
4698.34	996.609
4700.96	1002.94
4703.58	958.407
4706.2	1001.89
4708.82	974.153
4711.43	957.662
4714.05	993.208
4716.66	964.199
4719.28	979.3
4721.89	984.177
4724.5	959.539
4727.11	975.841
4729.72	975.2
4732.33	956.402
4734.93	935.318
4737.54	952.809
4740.14	941.839
4742.75	960.392
4745.35	961.817
4747.95	956.345
4750.55	943.906
4753.15	912.148
4755.75	942.964
4758.35	933.941
4760.95	926.144
4763.54	921.827
4766.14	938.07
4768.73	938.586
4771.33	898.122
4773.92	925.884
4776.51	944.557
4779.1	910.723
4781.69	924.828
4784.28	921.811
4786.87	911.941
4789.45	904.354
4792.04	923.121
4794.63	898.428
4797.21	890.93
4799.79	917.915
4802.37	904.836
4804.95	892.96
4807.53	904.171
4810.11	899.361
4812.69	896.835
4815.27	904.735
4817.84	876.924
4820.42	890.731
4822.99	917.301
4825.57	881.373
4828.14	884.788
4830.71	907.978
4833.28	889.439
4835.85	886.029
4838.42	861.717
4840.98	849.094
4843.55	882.045
4846.12	877.427
4848.68	909.086
4851.24	857.113
4853.81	875.017
4856.37	873.104
4858.93	844.955
4861.49	844.97
4864.05	884.886
4866.61	858.403
4869.16	895.793
4871.72	868.343
4874.27	869.067
4876.83	861.394
4879.38	844.213
4881.93	850.701
4884.49	855.957
4887.04	837.438
4889.58	793.939
4892.13	825.369
4894.68	884.193
4897.23	853.692
4899.77	835.053
4902.32	837.845
4904.86	814.379
4907.4	812.34
4909.95	840.128
4912.49	841.463
4915.03	846.32
4917.57	852.286
4920.1	849.988
4922.64	816.621
4925.18	826.273
4927.71	790.573
4930.25	797.786
4932.78	807.611
4935.31	786.499
4937.84	811.945
4940.38	797.892
4942.9	808.614
4945.43	769.353
4947.96	780.502
4950.49	813.205
4953.01	796.845
4955.54	816.357
4958.06	813.235
4960.59	788.554
4963.11	786.754
4965.63	789.985
4968.15	778.916
4970.67	785.68
4973.19	764.659
4975.71	793.11
4978.22	772.019
4980.74	787.236
4983.25	767.361
4985.77	782.637
4988.28	799.175
4990.79	789.035
4993.3	792.217
4995.81	768.608
4998.32	762.142