File: Data/3-Raman/raw/bu19w-d-ffore2-fi13-v_150 (500nm)_532nm_edge_100%_x100_vis_lwd_h50um_30sx2_01.txt
#Acq. time (s)=	30
#Accumulations=	2
#Range (cm-¹)=	100...4000
#Windows=	1
#Auto scanning=	Off
#Autofocus=	Off
#Macrospot=	Off
#AutoExposure=	Off
#Spike filter=	Multiple accum.
#Delay time (s)=	2
#Binning=	1
#Readout mode=	Signal
#DeNoise=	Off
#ICS correction=	On
#Dark correction=	Off
#Inst. Process=	Off
#Detector Gain=	Best Dynamic
#Detector ADC=	50 kHz HS
#Detector temperature (°C)=	-60.09
#Instrument=	LabRAM HR Evol
#Detector=	SIN-EM FIVIS
#Objective=	x100_VIS_LWD
#Grating=	150 (500nm)
#ND Filter=	100%
#Laser=	532nm_Edge
#Hole=	49.98
#Temperature=	0
#Range=	Visible
#StageXY=	75x50mm Scan+
#StageZ=	Z motor
#X (µm)=	0
#Y (µm)=	0
#Z (µm)=	14.4
#Full time(mm:ss)=	1:05
#Project=	21_11_22
#Sample=	BU19w
#Site=
#Title=	BU19w-D-FFore2-FI13-V_150 (500nm)_532nm_Edge_100%_x100_VIS_LWD_H50um_30sX2
#Remark=
#Date=	22.11.2021 14:10
#Acquired=	22.11.2021 14:10:01
103.97	2593.71
108.592	4548.31
113.209	5791.84
117.826	3987.21
122.441	2415.08
127.054	2041.64
131.664	1930.24
136.27	1803.34
140.876	1667.21
145.48	1651.78
150.081	1649.95
154.678	1785.83
159.275	1985.53
163.869	2286.82
168.461	2796.09
173.049	3703.11
177.637	5065.34
182.222	6859.49
186.806	8691.71
191.384	9411.05
195.963	8422.81
200.54	6817.83
205.112	4931.17
209.684	3601.35
214.253	2735.26
218.821	2219.03
223.384	1768.74
227.947	1554.18
232.507	1401.93
237.064	1298.58
241.62	1483.03
246.174	1963.33
250.724	2082.06
255.273	1457.11
259.82	878.31
264.363	695.336
268.906	637.68
273.447	570.469
277.983	516.803
282.519	488.872
287.051	477.035
291.583	460.632
296.112	441.805
300.637	436.347
305.162	461.186
309.685	421.923
314.204	411.623
318.722	412.924
323.236	418.167
327.75	449.202
332.262	616.563
336.77	1260.78
341.277	1907.24
345.78	1406.06
350.283	775.28
354.782	549.772
359.28	497.264
363.775	493.929
368.269	474.005
372.761	512.517
377.249	599.533
381.736	666.082
386.22	876.957
390.703	836.61
395.182	634.238
399.661	528.11
404.136	566.411
408.61	575
413.08	620.477
417.551	671.944
422.017	824.165
426.482	1133.48
430.944	1696.57
435.406	2904.59
439.863	5921.82
444.32	14711.4
448.773	25619.3
453.226	23462.3
457.674	12404.1
462.121	5829.31
466.567	3463.14
471.009	2442.52
475.452	1823.52
479.889	1522.3
484.327	1238.35
488.761	1123.91
493.194	1170.05
497.623	1244.59
502.051	1127.21
506.478	889.856
510.9	760.099
515.323	685.913
519.742	655.85
524.158	590.156
528.574	604.315
532.987	578.124
537.397	532.229
541.807	514.061
546.212	497.039
550.618	504.32
555.019	475.344
559.419	484.787
563.818	470.062
568.213	472.217
572.606	481.107
576.999	488.249
581.388	477.877
585.775	454.273
590.161	447.529
594.544	449.668
598.924	426.87
603.304	420.605
607.68	423.277
612.055	419.758
616.426	409.291
620.798	427.001
625.166	407.111
629.532	378.793
633.897	410.776
638.258	396.1
642.618	379.033
646.975	381.243
651.332	358.132
655.685	370.82
660.036	379.111
664.385	387.224
668.734	388.443
673.079	403.042
677.421	460.251
681.762	536.048
686.1	502.955
690.439	431.649
694.773	379.494
699.105	360.643
703.435	336.697
707.763	329.801
712.091	344.129
716.415	345.862
720.737	328.158
725.057	348.478
729.375	341.784
733.692	318.523
738.006	338.759
742.317	334.666
746.627	333.805
750.934	356.275
755.24	352.88
759.543	356.304
763.846	369.426
768.146	405.55
772.443	430.759
776.738	520.57
781.031	607.895
785.322	688.771
789.611	935.281
793.898	1265.25
798.183	1064.47
802.466	738.441
806.748	482.173
811.027	432.722
815.304	391.04
819.579	380.124
823.851	390.229
828.122	372.847
832.391	375.294
836.657	371.097
840.922	372.374
845.184	353.668
849.445	361.205
853.703	358.813
857.96	377.351
862.214	390.3
866.467	384.393
870.717	357.546
874.965	351.517
879.212	354.193
883.456	340.321
887.699	313.254
891.939	327.433
896.177	310.611
900.414	320.655
904.648	330.283
908.88	313.413
913.111	316.285
917.339	290.998
921.565	291.587
925.79	265.046
930.012	260.445
934.232	271.927
938.451	280.08
942.667	252.885
946.881	249.244
951.094	257.412
955.302	243.231
959.511	253.571
963.717	237.366
967.921	247.746
972.124	256.043
976.324	242.106
980.523	243.064
984.719	236.609
988.914	229.105
993.104	232.353
997.295	229.407
1001.48	227.566
1005.67	241.688
1009.85	232.463
1014.04	223.145
1018.22	247.926
1022.4	246.03
1026.57	244.026
1030.75	251.577
1034.92	259.932
1039.09	273.411
1043.26	282.592
1047.42	337.328
1051.59	374.811
1055.75	399.321
1059.91	446.803
1064.07	664.283
1068.23	919.188
1072.38	801.271
1076.54	466.32
1080.69	334.882
1084.84	301.657
1088.98	281.094
1093.13	270.005
1097.27	271.399
1101.41	251.319
1105.55	245.71
1109.69	234.149
1113.83	228.746
1117.96	235.901
1122.09	245.37
1126.22	243.709
1130.35	253.394
1134.47	279.453
1138.6	338.424
1142.72	473.811
1146.84	550.78
1150.96	435.768
1155.07	320.4
1159.19	250.296
1163.3	236.856
1167.41	236.777
1171.52	221.149
1175.62	228.162
1179.73	213.541
1183.83	218.427
1187.93	215.982
1192.03	224.742
1196.13	231.346
1200.22	227.663
1204.31	236.167
1208.4	241.592
1212.49	269.225
1216.58	276.581
1220.67	268.867
1224.75	265.25
1228.83	256.746
1232.91	241.444
1236.99	237.338
1241.06	244.159
1245.14	257.042
1249.21	278.06
1253.28	280.177
1257.35	257.358
1261.41	272.555
1265.48	344.895
1269.54	623.914
1273.6	552.372
1277.66	287.788
1281.72	233.766
1285.77	232.933
1289.82	215.966
1293.88	217.075
1297.92	222.196
1301.97	219.216
1306.02	215.205
1310.06	215.21
1314.1	213.121
1318.14	210.983
1322.18	206.768
1326.22	226.635
1330.25	217.336
1334.28	221.016
1338.31	224.643
1342.34	221.24
1346.37	228.808
1350.39	227.398
1354.42	249.844
1358.44	273.184
1362.46	296.478
1366.47	366.21
1370.49	674.707
1374.5	976.672
1378.51	612.24
1382.52	272.237
1386.53	240.663
1390.54	236.716
1394.54	278.162
1398.55	273.341
1402.55	224.155
1406.55	219.317
1410.54	216.467
1414.54	211.646
1418.53	205.83
1422.52	203.935
1426.51	197.994
1430.5	218.711
1434.49	204.878
1438.47	208.813
1442.45	200.878
1446.43	212.664
1450.41	209.615
1454.39	198.656
1458.36	193.591
1462.34	199.3
1466.31	196.128
1470.28	194.954
1474.24	188.858
1478.21	193.526
1482.17	185.447
1486.14	197.899
1490.1	189.833
1494.05	197.391
1498.01	192.291
1501.97	197.935
1505.92	203.622
1509.87	189.896
1513.82	181.048
1517.77	203.28
1521.71	192.53
1525.66	202.163
1529.6	208.908
1533.54	198.213
1537.48	194.309
1541.41	208.819
1545.35	210.731
1549.28	207.798
1553.21	213.561
1557.14	221.224
1561.07	217.242
1565	231.618
1568.92	212.131
1572.84	223.571
1576.76	241.742
1580.68	217.448
1584.6	232.682
1588.51	220.927
1592.43	220.731
1596.34	255.129
1600.25	252.042
1604.16	257.632
1608.06	248.842
1611.97	239.12
1615.87	258.18
1619.77	257.104
1623.67	250.319
1627.57	246.444
1631.46	243.601
1635.36	261.818
1639.25	256.157
1643.14	257.259
1647.03	247.842
1650.91	254.736
1654.8	240.5
1658.68	231.037
1662.56	236.901
1666.44	231.204
1670.32	221.593
1674.2	226.38
1678.07	211.842
1681.94	201.099
1685.81	215.291
1689.68	215.043
1693.55	207.109
1697.41	192.477
1701.28	191.201
1705.14	190.84
1709	198.989
1712.86	205.205
1716.72	188.703
1720.57	187.377
1724.42	185.1
1728.28	192.203
1732.13	191.781
1735.97	185.731
1739.82	182.484
1743.66	178.329
1747.51	184.515
1751.35	173.119
1755.19	181.319
1759.02	179.591
1762.86	177.782
1766.69	194.582
1770.53	185.477
1774.36	163.336
1778.18	190.584
1782.01	190.88
1785.84	171.564
1789.66	189.655
1793.48	181.543
1797.3	169.636
1801.12	170.769
1804.94	186.004
1808.75	175.799
1812.57	183.468
1816.38	182.578
1820.19	173.143
1824	172.167
1827.8	182.461
1831.61	187.041
1835.41	174.635
1839.21	171.63
1843.01	174.229
1846.81	178.712
1850.6	180.301
1854.4	175.287
1858.19	186.099
1861.98	181.014
1865.77	192.683
1869.56	170.037
1873.34	176.187
1877.13	187.867
1880.91	179.302
1884.69	173.538
1888.47	172.564
1892.25	190.023
1896.02	177.111
1899.8	180.834
1903.57	179.996
1907.34	173.649
1911.11	184.872
1914.88	171.214
1918.64	167.79
1922.41	193.09
1926.17	187.894
1929.93	170.61
1933.69	173.749
1937.44	165.692
1941.2	187.528
1944.95	181.344
1948.7	179.684
1952.46	173.253
1956.2	181.755
1959.95	193.008
1963.7	187.343
1967.44	173.183
1971.18	194.609
1974.92	175.669
1978.66	182.942
1982.4	192.968
1986.13	191.742
1989.87	190.493
1993.6	178.981
1997.33	184.182
2001.06	183.806
2004.78	188.967
2008.51	194.975
2012.23	186.242
2015.96	195.068
2019.67	192.975
2023.39	182.753
2027.11	183.56
2030.83	187.171
2034.54	188.129
2038.25	185.399
2041.96	187.237
2045.67	180.832
2049.38	191.863
2053.08	193.753
2056.79	192.979
2060.49	190.497
2064.19	177.023
2067.89	182.864
2071.58	184.115
2075.28	199.25
2078.97	195.005
2082.67	187.01
2086.36	184.37
2090.05	184.392
2093.73	179.857
2097.42	194.83
2101.1	190.206
2104.78	185.549
2108.47	189.232
2112.14	198.483
2115.82	186.332
2119.5	191.769
2123.17	200.857
2126.84	185.804
2130.52	184.648
2134.18	194.577
2137.85	195.217
2141.52	177.392
2145.18	184.451
2148.84	185.973
2152.51	186.578
2156.17	177.12
2159.82	198.786
2163.48	185.738
2167.14	184.607
2170.79	188.105
2174.44	198.931
2178.09	179.739
2181.74	176.936
2185.38	175.989
2189.03	184.212
2192.67	183.413
2196.32	182.659
2199.96	188.308
2203.59	182.129
2207.23	202.476
2210.87	175.306
2214.5	182.905
2218.13	185.022
2221.76	191.753
2225.39	179.152
2229.02	190.498
2232.65	181.569
2236.27	180.011
2239.89	182.151
2243.51	181.505
2247.13	181.794
2250.75	169.994
2254.37	176.831
2257.98	175.277
2261.59	181.189
2265.2	174.94
2268.81	183.745
2272.42	170.889
2276.03	175.853
2279.64	171.285
2283.24	178.965
2286.84	179.102
2290.44	186.779
2294.04	179.327
2297.64	181.342
2301.23	179.543
2304.83	167.277
2308.42	178.679
2312.01	201.43
2315.6	259.21
2319.19	244.9
2322.77	209.647
2326.36	192.392
2329.94	180.825
2333.52	180.578
2337.1	185.957
2340.68	172.497
2344.26	182.521
2347.83	170.014
2351.41	173.438
2354.98	182.438
2358.55	172.763
2362.12	176.136
2365.69	165.59
2369.25	182.903
2372.82	187.207
2376.38	182.267
2379.94	181.052
2383.5	180.779
2387.06	190.641
2390.61	176.658
2394.17	188.427
2397.72	180.082
2401.27	187.416
2404.82	166.37
2408.37	176.553
2411.92	180.375
2415.47	183.325
2419.01	170.673
2422.55	175.532
2426.09	173.99
2429.63	170.628
2433.17	175.631
2436.71	177.889
2440.24	185.758
2443.78	183.402
2447.31	174.518
2450.84	175.002
2454.37	173.508
2457.89	168.089
2461.42	168.282
2464.94	167.409
2468.47	169.466
2471.99	176.02
2475.51	169.287
2479.03	172.968
2482.54	169.052
2486.06	178.208
2489.57	173.323
2493.08	159.938
2496.59	170.044
2500.1	180.086
2503.61	175.113
2507.12	167.326
2510.62	175.392
2514.12	183.47
2517.62	180.426
2521.12	176.341
2524.62	177.067
2528.12	176.917
2531.61	180.482
2535.11	181.33
2538.6	172.067
2542.09	166.577
2545.58	182.402
2549.07	169.605
2552.55	171.628
2556.04	173.751
2559.52	165.666
2563	165.067
2566.48	177.567
2569.96	175.223
2573.44	168.215
2576.91	173.418
2580.39	166.408
2583.86	166.921
2587.33	180.678
2590.8	170.641
2594.27	171
2597.74	171.415
2601.2	156.508
2604.67	175.015
2608.13	176.152
2611.59	175.222
2615.05	172.452
2618.51	167.681
2621.96	162.877
2625.42	170.517
2628.87	170.442
2632.32	159.771
2635.77	174.95
2639.22	169.958
2642.67	175.46
2646.11	170.435
2649.56	161.572
2653	176.484
2656.44	161.866
2659.88	176.658
2663.32	174.352
2666.76	166.399
2670.19	162.232
2673.63	160.926
2677.06	174.631
2680.49	169.628
2683.92	174.96
2687.35	158.951
2690.78	166.329
2694.2	170.862
2697.63	163.33
2701.05	166.981
2704.47	168.758
2707.89	172.524
2711.31	163.302
2714.72	175.518
2718.14	157.965
2721.55	174.918
2724.96	163.903
2728.37	172.51
2731.78	171.765
2735.19	170.081
2738.6	152.441
2742	160.086
2745.41	170.537
2748.81	169.722
2752.21	179.244
2755.61	164.275
2759	174.732
2762.4	174.784
2765.8	174.809
2769.19	167.264
2772.58	177.61
2775.97	169.082
2779.36	169.95
2782.75	165.157
2786.13	169.769
2789.52	170.61
2792.9	176.139
2796.28	167.583
2799.66	176.832
2803.04	187.006
2806.42	159.696
2809.79	179.212
2813.17	167.83
2816.54	176.078
2819.91	168.472
2823.28	178.624
2826.65	180.386
2830.02	174.715
2833.38	176.534
2836.75	170.93
2840.11	175.607
2843.47	179.395
2846.83	173.924
2850.19	177.829
2853.55	175.174
2856.91	179.084
2860.26	177.409
2863.61	179.486
2866.96	173.125
2870.31	189.283
2873.66	192.304
2877.01	193.443
2880.36	177.618
2883.7	185.326
2887.05	189.265
2890.39	183.758
2893.73	196.157
2897.07	195.301
2900.4	195.359
2903.74	184.983
2907.07	180.266
2910.41	189.729
2913.74	194.449
2917.07	180.216
2920.4	200.027
2923.73	185.775
2927.05	197.019
2930.38	196.898
2933.7	191.082
2937.02	196.59
2940.34	204.915
2943.66	189.698
2946.98	199.911
2950.3	207.281
2953.61	214.644
2956.92	205.133
2960.24	204.1
2963.55	202.138
2966.86	213.364
2970.16	208.694
2973.47	211.526
2976.78	201.268
2980.08	209.746
2983.38	225.749
2986.68	232.386
2989.98	218.371
2993.28	230.665
2996.58	229.823
2999.87	229.92
3003.17	225.31
3006.46	242.363
3009.75	236.845
3013.04	237.923
3016.33	242.767
3019.62	248.555
3022.91	239.25
3026.19	257.323
3029.47	255.57
3032.75	255.693
3036.03	263.374
3039.31	270.117
3042.59	289.177
3045.87	271.325
3049.14	278.087
3052.42	283.918
3055.69	274.569
3058.96	303.072
3062.23	298.419
3065.49	309.863
3068.76	307.028
3072.03	311.464
3075.29	306.764
3078.55	317.102
3081.81	331.534
3085.07	349.753
3088.33	350.048
3091.59	356.119
3094.85	355.021
3098.1	373.196
3101.35	357.051
3104.61	384.847
3107.85	392.635
3111.1	408.854
3114.35	421.308
3117.6	418.541
3120.84	422.442
3124.09	436.817
3127.33	442.606
3130.57	464.608
3133.81	464.681
3137.05	476.167
3140.28	499.088
3143.52	514.385
3146.75	511.603
3149.99	540.308
3153.22	553.732
3156.45	545.236
3159.68	560.571
3162.9	574.962
3166.13	610.296
3169.35	615.047
3172.58	611.186
3175.8	639.709
3179.02	623.378
3182.24	670.976
3185.46	705.121
3188.67	709.676
3191.89	689.451
3195.1	714.955
3198.32	723.281
3201.53	736.393
3204.74	744.764
3207.95	743.649
3211.15	773.98
3214.36	769.164
3217.56	800.497
3220.77	812.824
3223.97	783.382
3227.17	807.225
3230.37	822.584
3233.57	839.771
3236.76	831.462
3239.96	867.948
3243.15	841.639
3246.35	865.814
3249.54	872.938
3252.73	895.36
3255.92	886.299
3259.1	896.2
3262.29	904.07
3265.47	924.23
3268.66	928.058
3271.84	929.913
3275.02	935.591
3278.2	959.216
3281.38	955.904
3284.55	983.159
3287.73	948.304
3290.9	965.042
3294.08	996.969
3297.25	986.004
3300.42	993.409
3303.59	1011.95
3306.76	1014.22
3309.92	1018.22
3313.09	1030.69
3316.25	1045.96
3319.41	1084.87
3322.58	1088.67
3325.74	1099.1
3328.9	1093.46
3332.05	1137.03
3335.21	1128.71
3338.36	1134.64
3341.52	1186.78
3344.67	1168.46
3347.82	1207.03
3350.97	1207.85
3354.12	1222.96
3357.26	1238.13
3360.41	1239.31
3363.55	1249.96
3366.7	1278.6
3369.84	1310.13
3372.98	1319.2
3376.12	1309.44
3379.26	1358.33
3382.39	1328.73
3385.53	1356.92
3388.66	1375.69
3391.8	1372.69
3394.93	1381.53
3398.06	1433.87
3401.19	1401.03
3404.31	1436.66
3407.44	1451.52
3410.56	1471.17
3413.69	1448.55
3416.81	1444.88
3419.93	1490.68
3423.05	1472.28
3426.17	1467.91
3429.29	1482.44
3432.41	1447.99
3435.52	1501.93
3438.63	1469.2
3441.75	1486.1
3444.86	1500.74
3447.97	1440.04
3451.08	1450.62
3454.18	1425
3457.29	1445.81
3460.39	1434.23
3463.5	1433.06
3466.6	1435.5
3469.7	1407.25
3472.8	1372.91
3475.9	1344.37
3479	1379.31
3482.09	1318.78
3485.19	1330.19
3488.28	1278.53
3491.37	1282.97
3494.46	1259.06
3497.55	1230.35
3500.64	1245.09
3503.73	1213.41
3506.81	1155.41
3509.9	1133.81
3512.98	1149.98
3516.06	1099.41
3519.14	1084.99
3522.22	1088.43
3525.3	1023.38
3528.38	1016.27
3531.46	978.749
3534.53	964.325
3537.6	954.648
3540.67	936.992
3543.75	919.049
3546.82	863.105
3549.88	865.477
3552.95	864.909
3556.02	833.263
3559.08	820.547
3562.14	787.737
3565.21	764.255
3568.27	747.643
3571.33	731.606
3574.39	718.44
3577.44	709.955
3580.5	690.98
3583.55	683.319
3586.61	666.176
3589.66	646.106
3592.71	627.928
3595.76	623.912
3598.81	604.749
3601.85	577.961
3604.9	582.378
3607.95	576.383
3610.99	553.352
3614.03	531.268
3617.07	539.441
3620.11	495.744
3623.15	494.538
3626.19	479.232
3629.22	452.611
3632.26	452.343
3635.29	431.488
3638.33	433.285
3641.36	400.315
3644.39	391.931
3647.42	365.54
3650.44	367.487
3653.47	355.687
3656.5	349.457
3659.52	329.06
3662.54	308.577
3665.56	290.739
3668.58	297.476
3671.6	277.82
3674.62	267.598
3677.64	256.436
3680.65	244.3
3683.67	241.609
3686.68	238.922
3689.69	237.185
3692.7	229.768
3695.71	210.914
3698.72	215.802
3701.73	214.052
3704.73	201.851
3707.74	208.618
3710.74	197.31
3713.74	193.574
3716.75	200.32
3719.75	189.91
3722.74	189.953
3725.74	183.312
3728.74	185.228
3731.73	174.746
3734.73	177.575
3737.72	182.293
3740.71	186.985
3743.7	180.244
3746.69	177.293
3749.68	175.282
3752.66	186.562
3755.65	168.419
3758.63	169.26
3761.62	166.294
3764.6	178.485
3767.58	177.426
3770.56	170.71
3773.54	165.904
3776.51	163.003
3779.49	169.561
3782.46	161.951
3785.44	160.02
3788.41	154.324
3791.38	162.811
3794.35	156.211
3797.32	162.833
3800.29	159.095
3803.25	155.363
3806.22	158.247
3809.18	168.704
3812.14	170.664
3815.11	166.008
3818.07	159.463
3821.03	161.436
3823.98	155.845
3826.94	163.521
3829.9	156.027
3832.85	165.623
3835.8	159.096
3838.76	165.866
3841.71	162.182
3844.66	163.255
3847.61	156.714
3850.55	165.429
3853.5	173.207
3856.45	161.898
3859.39	164.912
3862.33	155.482
3865.27	156.57
3868.21	157.647
3871.15	167.351
3874.09	158.829
3877.03	163.721
3879.96	167.641
3882.9	150.4
3885.83	155.246
3888.77	157.203
3891.7	150.5
3894.63	156.278
3897.56	168.767
3900.48	162.983
3903.41	164.866
3906.34	164.85
3909.26	165.778
3912.18	164.769
3915.1	157.982
3918.02	158.915
3920.94	160.775
3923.86	150.142
3926.78	155.806
3929.7	157.62
3932.61	162.343
3935.52	166.138
3938.44	166.137
3941.35	149.842
3944.26	159.407
3947.17	156.542
3950.08	150.815
3952.98	163.289
3955.89	162.372
3958.79	165.296
3961.7	163.436
3964.6	151.995
3967.5	153.983
3970.4	155.978
3973.3	165.655
3976.2	160.919
3979.09	160.012
3981.99	164.869
3984.88	156.258
3987.78	162.068
3990.67	164.969
3993.56	160.207
3996.45	161.214
3999.34	157.416