File: Data/3-Raman/raw/bu19w-ff1-fi06-v_150 (500nm)_532nm_edge_100%_x100_vis_h50um_15sx2_01.txt
#Acq. time (s)=	15
#Accumulations=	2
#Range (cm-¹)=	100...5000
#Windows=	1
#Auto scanning=	Off
#Autofocus=	Off
#Macrospot=	Off
#AutoExposure=	Off
#Spike filter=	Multiple accum.
#Delay time (s)=	2
#Binning=	1
#Readout mode=	Signal
#DeNoise=	Off
#ICS correction=	On
#Dark correction=	Off
#Inst. Process=	Off
#Detector Gain=	Best Dynamic
#Detector ADC=	50 kHz HS
#Detector temperature (°C)=	-60.09
#Instrument=	LabRAM HR Evol
#Detector=	SIN-EM FIVIS
#Objective=	x100_VIS
#Grating=	150 (500nm)
#ND Filter=	100%
#Laser=	532nm_Edge
#Hole=	49.98
#Temperature=	0
#Range=	Visible
#StageXY=	75x50mm Scan+
#StageZ=	Z motor
#X (µm)=	0
#Y (µm)=	0
#Z (µm)=	-144.5
#Full time(s)=	34
#Project=	21_05_14
#Sample=	BU19w
#Site=
#Title=	BU19w-FF1-FI06-V_150 (500nm)_532nm_Edge_100%_x100_VIS_H50um_15sX2
#Remark=
#Date=	14.05.2021 15:42
#Acquired=	14.05.2021 15:42:00
102.699	2023.51
107.322	1888.36
111.942	1615.15
116.56	1461.8
121.173	1405.26
125.787	1333.43
130.398	1342.62
135.006	1337.08
139.613	1228.5
144.215	1196.38
148.817	1237.94
153.417	1679.5
158.014	3014.02
162.607	3133.44
167.2	1910.15
171.79	1457.95
176.379	1551.87
180.963	2893.69
185.547	7062.34
190.128	6863.01
194.705	3215.33
199.282	1595.78
203.857	1269.05
208.43	1179.68
212.998	1217.52
217.566	1163.65
222.132	1119.54
226.693	1181.54
231.254	1562.17
235.813	1670.13
240.368	2176.51
244.923	3167.4
249.475	2779.41
254.023	2255.93
258.571	1746.71
263.117	1601.81
267.658	2004.51
272.199	3641.26
276.738	6830.51
281.273	6773
285.807	3962.23
290.34	2498.95
294.868	2418.28
299.396	3531.53
303.919	4230.19
308.443	3026.43
312.964	2030.89
317.481	1808.36
321.998	2065.11
326.51	2876.62
331.023	2963.91
335.533	2189.21
340.039	1770.81
344.544	1976.81
349.046	2337.8
353.547	2043.96
358.045	1496.47
362.542	1245.77
367.036	1327.41
371.527	1348.28
376.017	1272.09
380.503	1470.19
384.99	1913.23
389.471	2231.94
393.953	2425.91
398.43	2108.58
402.908	1726.19
407.381	1487.36
411.854	1689.92
416.323	2242.89
420.791	1867.85
425.256	1222.71
429.72	990.495
434.18	976.592
438.64	1001.83
443.095	1055.3
447.551	1401.8
452.003	2235.75
456.454	2858.87
460.901	2067.39
465.348	1365.06
469.791	1177.36
474.231	1134.4
478.672	1190.57
483.108	1314.29
487.544	1569.46
491.976	1720.64
496.408	1789.09
500.836	1720.67
505.261	1566.53
509.687	1357.86
514.108	1228.06
518.529	1159.62
522.946	1124.16
527.361	1133.82
531.776	1145.02
536.187	1232.73
540.595	1241.75
545.003	1287.84
549.408	1270.21
553.812	1278.71
558.212	1348.02
562.61	1353.48
567.007	1261.72
571.401	1107.81
575.792	1135.6
580.184	1410.58
584.571	2171
588.956	3099.13
593.341	2606.22
597.722	1736.45
602.101	1603.94
606.48	2103.79
610.854	2625.16
615.227	2359.49
619.597	1575.8
623.967	1180.76
628.334	1091.94
632.698	1108.84
637.06	1223.54
641.422	1276.62
645.779	1212.42
650.135	1129.54
654.491	1143.26
658.842	1398.52
663.192	1618.64
667.539	1695.86
671.884	1813.8
676.23	1950.01
680.571	1857.42
684.91	1410.77
689.247	1151.41
693.583	1000.27
697.916	946.687
702.247	882.803
706.576	865.562
710.902	845.456
715.229	860.677
719.551	832.07
723.872	841.583
728.19	850.05
732.506	877.275
736.82	888.744
741.134	936.531
745.444	933.5
749.752	1002.6
754.058	1068.54
758.362	1180.03
762.664	1355.31
766.964	1630.64
771.264	2358.2
775.559	3211.55
779.853	3540.29
784.144	2869.25
788.434	1998.77
792.722	1482.93
797.007	1266.15
801.29	1126.73
805.572	1058.37
809.851	1012.2
814.13	958.566
818.406	977.444
822.679	938.275
826.95	906.9
831.219	924.025
835.486	942.215
839.752	901.88
844.015	894.429
848.276	902.865
852.535	879.244
856.792	876.588
861.047	888.159
865.3	860.891
869.551	879.649
873.8	848.73
878.047	881.296
882.292	860.922
886.534	879.511
890.775	883.047
895.014	900.383
899.251	906.542
903.486	906.615
907.719	901.612
911.95	927.574
916.179	913.296
920.406	921.741
924.63	919.194
928.853	977.111
933.074	971.703
937.293	1089.2
941.51	1166.62
945.723	1333.25
949.936	1477.35
954.147	1465.74
958.356	1392.68
962.563	1424.07
966.768	1595.59
970.971	1495.73
975.172	1320.9
979.371	1206.97
983.568	1084.75
987.761	1059.81
991.954	1047.21
996.145	1019.55
1000.33	1001.68
1004.52	1034.84
1008.71	1060.89
1012.89	1075.98
1017.07	1062.29
1021.25	1122.16
1025.43	1182.57
1029.6	1220.63
1033.77	1365.3
1037.95	1500.86
1042.11	1831.07
1046.28	2641.07
1050.45	4042.73
1054.61	4446.37
1058.77	3513.42
1062.93	2491.4
1067.09	1987.49
1071.24	1828.3
1075.4	1867.61
1079.55	2261.19
1083.7	3029.13
1087.85	4045.43
1091.99	4456.31
1096.14	3831.29
1100.28	3240.52
1104.42	3329.21
1108.55	3838.48
1112.69	3947.14
1116.82	3502.75
1120.96	3148.84
1125.09	3187.93
1129.21	3391.78
1133.34	3497.2
1137.46	3089.48
1141.59	2462.57
1145.71	2202.97
1149.83	2264.14
1153.94	2749.16
1158.06	3120.74
1162.17	2840.89
1166.28	2267.56
1170.39	2023.82
1174.5	1709.85
1178.6	1469.43
1182.7	1360.03
1186.8	1280.69
1190.9	1304.74
1195	1342.58
1199.1	1331.86
1203.19	1300.68
1207.28	1202.78
1211.37	1230.86
1215.46	1240.67
1219.54	1401.55
1223.63	1576.81
1227.71	1510.65
1231.79	1456.28
1235.87	1613.73
1239.95	1892.2
1244.02	1783.27
1248.09	1538.91
1252.16	1407.67
1256.23	1260.56
1260.3	1164.47
1264.36	1132.45
1268.43	1502.43
1272.49	2985.72
1276.55	2082.21
1280.6	1196.74
1284.66	1058.8
1288.71	1084.72
1292.76	1043.94
1296.81	1038.35
1300.86	1044.66
1304.91	1043.73
1308.95	1045.86
1312.99	1034.53
1317.03	1003.72
1321.07	1023.15
1325.11	1020.87
1329.14	1030.85
1333.18	1028.36
1337.21	1031.65
1341.24	1017.82
1345.26	1030.9
1349.29	1062.88
1353.31	1056.01
1357.33	1088.85
1361.35	1108.67
1365.37	1105.01
1369.39	1206.16
1373.4	2498.88
1377.41	4243.3
1381.43	1969.8
1385.43	1155.18
1389.44	1085.11
1393.45	1116.91
1397.45	1269.11
1401.45	1138.4
1405.45	1031.4
1409.45	1043.72
1413.44	1018.62
1417.44	993.474
1421.43	1001.82
1425.42	952.543
1429.41	993.793
1433.39	990.869
1437.38	941.382
1441.36	970.913
1445.34	946.934
1449.32	950.564
1453.3	960.89
1457.27	954.377
1461.24	977.125
1465.22	968.148
1469.19	965.188
1473.15	995.632
1477.12	957.177
1481.09	967.71
1485.05	990.851
1489.01	941.678
1492.97	974.626
1496.93	976.355
1500.88	963.658
1504.83	979.392
1508.79	967.134
1512.74	971.398
1516.68	959.264
1520.63	967.6
1524.57	975.018
1528.52	975.752
1532.46	991.11
1536.4	975.451
1540.33	944.323
1544.27	983.926
1548.2	974.119
1552.14	983.625
1556.07	966.823
1559.99	1056.37
1563.92	959.037
1567.84	1011.56
1571.77	999.26
1575.69	1010.12
1579.61	1008.38
1583.52	981.546
1587.44	990.318
1591.35	1018.31
1595.27	1028.93
1599.18	1020.39
1603.09	996.629
1606.99	990.266
1610.9	1008.86
1614.8	1011.26
1618.7	1001.27
1622.6	1009.48
1626.5	1002.57
1630.39	1058.08
1634.29	989.343
1638.18	1025.93
1642.07	1018.8
1645.96	1036.71
1649.85	1056.63
1653.73	1024.72
1657.62	1005.16
1661.5	984.515
1665.38	1008.86
1669.26	991.672
1673.13	977.154
1677.01	1045.99
1680.88	1015.35
1684.75	1040.29
1688.62	1008.5
1692.49	1039.75
1696.35	1020.13
1700.22	1015.62
1704.08	1048.04
1707.94	1068.72
1711.8	1029.46
1715.66	1063.29
1719.51	1033.74
1723.37	1018.41
1727.22	1076.36
1731.07	1027.97
1734.92	1021
1738.76	1037.26
1742.61	1050.62
1746.45	1029.92
1750.29	1033.98
1754.13	1050.54
1757.97	1020.11
1761.81	982.708
1765.64	1030.3
1769.47	1046.07
1773.31	1035.1
1777.14	1025.2
1780.96	1055.69
1784.79	1026.57
1788.61	1031.14
1792.43	1004.8
1796.25	1032.84
1800.07	1074.68
1803.89	1049.34
1807.71	1045.6
1811.52	1062.42
1815.33	1069.47
1819.14	1039.34
1822.95	1037.31
1826.76	1056.73
1830.56	1053.22
1834.37	1054.2
1838.17	1042.79
1841.97	1073.47
1845.77	1049.62
1849.56	1068.73
1853.36	1055.55
1857.15	1056.15
1860.94	1065.83
1864.73	1051.34
1868.52	1095.45
1872.31	1092.36
1876.09	1078.35
1879.87	1084.04
1883.66	1069.7
1887.43	1072.66
1891.21	1065.2
1894.99	1095.38
1898.76	1090.88
1902.53	1054.51
1906.31	1059.69
1910.08	1063.3
1913.84	1092.97
1917.61	1121.3
1921.37	1096.42
1925.14	1091.05
1928.9	1086.74
1932.66	1083.35
1936.41	1076.18
1940.17	1047.45
1943.92	1058.15
1947.68	1097.98
1951.43	1112.13
1955.18	1085.38
1958.92	1089.06
1962.67	1056.02
1966.41	1107.38
1970.16	1094.31
1973.9	1063.25
1977.64	1105.06
1981.37	1082.09
1985.11	1098.2
1988.84	1093.67
1992.57	1133.53
1996.31	1077.43
2000.03	1104.8
2003.76	1099.85
2007.49	1109.28
2011.21	1097.44
2014.93	1094.21
2018.65	1087.14
2022.37	1101.65
2026.09	1128.64
2029.81	1084.01
2033.52	1102.68
2037.23	1075.26
2040.94	1122.99
2044.65	1079.92
2048.36	1113.99
2052.07	1131.74
2055.77	1103.88
2059.47	1065.85
2063.17	1102.53
2066.87	1088.82
2070.57	1079.7
2074.27	1095.53
2077.96	1118.02
2081.65	1123.85
2085.34	1113.23
2089.03	1142.92
2092.72	1101.66
2096.41	1134.04
2100.09	1111.92
2103.77	1137.98
2107.46	1091.3
2111.14	1141.23
2114.81	1143.7
2118.49	1146.74
2122.16	1128.91
2125.84	1118.45
2129.51	1142.99
2133.18	1143.39
2136.85	1149.18
2140.51	1140.9
2144.18	1150.02
2147.84	1115.9
2151.5	1129.6
2155.16	1128.67
2158.82	1142.44
2162.48	1163.67
2166.13	1116.64
2169.79	1146.56
2173.44	1176
2177.09	1133.59
2180.74	1141.37
2184.38	1155.51
2188.03	1161.11
2191.67	1160.75
2195.32	1161.72
2198.96	1163.71
2202.6	1154.02
2206.23	1142.67
2209.87	1167.16
2213.5	1158.83
2217.14	1155.09
2220.77	1152.3
2224.4	1151.36
2228.03	1179.83
2231.65	1196.51
2235.28	1158.7
2238.9	1189.25
2242.52	1171.63
2246.14	1157.66
2249.76	1189.38
2253.38	1141.13
2256.99	1149.73
2260.6	1158.25
2264.21	1146.14
2267.82	1168.07
2271.44	1140.19
2275.04	1140.02
2278.65	1155.43
2282.25	1148.59
2285.85	1139.14
2289.45	1153.12
2293.05	1164.23
2296.65	1150.81
2300.25	1142.97
2303.84	1170.87
2307.43	1209.95
2311.02	1194.86
2314.62	1181.45
2318.2	1404.69
2321.79	1336.43
2325.38	1199.6
2328.96	1132.11
2332.54	1173.97
2336.12	1137.41
2339.7	1190.15
2343.28	1171.24
2346.85	1168.2
2350.43	1159.5
2354	1172.24
2357.57	1179.26
2361.14	1180.62
2364.71	1175.51
2368.27	1169.7
2371.84	1136.29
2375.4	1144.43
2378.96	1154.53
2382.52	1143.55
2386.08	1177.79
2389.64	1165.37
2393.19	1162.43
2396.75	1191.05
2400.3	1174.37
2403.85	1175.54
2407.4	1142.99
2410.95	1171.46
2414.49	1145.99
2418.04	1147.38
2421.58	1165.56
2425.12	1154.59
2428.66	1143.83
2432.2	1168.46
2435.74	1170.17
2439.27	1180.35
2442.81	1159.85
2446.34	1159.02
2449.87	1162.19
2453.4	1175.38
2456.93	1216.76
2460.45	1193.61
2463.98	1157.7
2467.5	1162.19
2471.02	1147.56
2474.54	1198.39
2478.06	1175.12
2481.58	1162.03
2485.09	1170.88
2488.61	1181.57
2492.12	1149.2
2495.63	1170.02
2499.14	1158.22
2502.65	1180.58
2506.15	1188.7
2509.66	1162.25
2513.16	1181.67
2516.66	1187.36
2520.16	1176.73
2523.66	1178.78
2527.16	1157.38
2530.66	1202.65
2534.15	1197.45
2537.64	1210.94
2541.13	1183.42
2544.62	1163.9
2548.11	1169.4
2551.6	1176.02
2555.08	1137.94
2558.57	1194.37
2562.05	1139.93
2565.53	1180.67
2569.01	1150.03
2572.49	1164.41
2575.96	1163.15
2579.44	1160.1
2582.91	1151.41
2586.38	1146.31
2589.85	1157.66
2593.32	1154.37
2596.79	1187.65
2600.25	1163.78
2603.72	1185.29
2607.18	1157.05
2610.64	1160.17
2614.1	1149.38
2617.56	1185.26
2621.02	1161.32
2624.47	1167.79
2627.92	1212.47
2631.38	1187.75
2634.83	1155.97
2638.28	1161.39
2641.72	1187.56
2645.17	1204.05
2648.61	1178.29
2652.06	1182.77
2655.5	1151.79
2658.94	1174.83
2662.38	1193.83
2665.82	1170.28
2669.25	1182.47
2672.69	1188.2
2676.12	1162.2
2679.55	1181.43
2682.98	1181.27
2686.41	1187.44
2689.84	1183.16
2693.26	1149.67
2696.69	1138.79
2700.11	1143
2703.53	1163.66
2706.95	1183.36
2710.37	1156.89
2713.79	1155.75
2717.2	1194.91
2720.62	1183.97
2724.03	1160.96
2727.44	1169.8
2730.85	1161.75
2734.26	1178.02
2737.66	1173.71
2741.07	1182.32
2744.47	1171.91
2747.87	1116.37
2751.28	1161.39
2754.67	1168.56
2758.07	1175.9
2761.47	1158.4
2764.86	1193.5
2768.26	1164.28
2771.65	1178.33
2775.04	1188.41
2778.43	1154.97
2781.82	1182.62
2785.2	1181.04
2788.59	1180.38
2791.97	1213.43
2795.35	1193.04
2798.73	1158.33
2802.11	1147.12
2805.49	1172.46
2808.87	1158.37
2812.24	1178.86
2815.62	1163.7
2818.99	1197.26
2822.36	1162.88
2825.73	1173.37
2829.1	1186.77
2832.46	1188.28
2835.83	1184.39
2839.19	1166.75
2842.55	1157.74
2845.91	1182.63
2849.27	1163.33
2852.63	1127.84
2855.99	1199.93
2859.34	1147.89
2862.69	1176.35
2866.05	1148.66
2869.4	1160.25
2872.75	1180.29
2876.09	1152.34
2879.44	1166.7
2882.78	1172.51
2886.13	1149.93
2889.47	1150.06
2892.81	1147.95
2896.15	1131.5
2899.49	1149.86
2902.82	1166.16
2906.16	1173.86
2909.49	1141.69
2912.82	1167.23
2916.16	1162.27
2919.49	1161.96
2922.81	1166.34
2926.14	1166.7
2929.46	1172.67
2932.79	1194.4
2936.11	1175.55
2939.43	1219.86
2942.75	1178.43
2946.07	1176.65
2949.39	1156.04
2952.7	1163.6
2956.02	1166.64
2959.33	1166.11
2962.64	1143.03
2965.95	1164.31
2969.26	1166.36
2972.57	1146.63
2975.87	1167.68
2979.17	1165.98
2982.48	1177.47
2985.78	1190.94
2989.08	1168.76
2992.38	1171.04
2995.68	1158.38
2998.97	1192.73
3002.27	1163.09
3005.56	1139.18
3008.85	1152.02
3012.14	1173.42
3015.43	1119.39
3018.72	1151.11
3022	1155.49
3025.29	1141.02
3028.57	1157.7
3031.85	1147.88
3035.14	1163.52
3038.41	1167.84
3041.69	1144.72
3044.97	1168.02
3048.24	1142.98
3051.52	1186.23
3054.79	1160.26
3058.06	1158.8
3061.33	1161.79
3064.6	1166.79
3067.87	1162.14
3071.13	1192.61
3074.4	1172.49
3077.66	1150.48
3080.92	1131
3084.18	1154.43
3087.44	1138.22
3090.7	1129.85
3093.95	1133.63
3097.21	1142.31
3100.46	1138.65
3103.71	1183.85
3106.96	1131.13
3110.21	1123.73
3113.46	1162.94
3116.71	1136.52
3119.95	1181.53
3123.2	1129.38
3126.44	1172.45
3129.68	1174.57
3132.92	1161.41
3136.16	1152.02
3139.4	1152.12
3142.63	1163.65
3145.87	1175.25
3149.1	1156.38
3152.33	1145.1
3155.56	1172.95
3158.79	1158.79
3162.02	1167.54
3165.25	1192.43
3168.47	1149.47
3171.69	1149.4
3174.92	1188.36
3178.14	1193.87
3181.36	1166.03
3184.58	1177.2
3187.79	1156.83
3191.01	1158.39
3194.22	1173.28
3197.43	1172.88
3200.65	1156.33
3203.86	1187.42
3207.07	1198.57
3210.27	1160.3
3213.48	1157.34
3216.69	1196.25
3219.89	1152.42
3223.09	1187.66
3226.29	1163.95
3229.49	1154.61
3232.69	1173.74
3235.89	1162.61
3239.08	1204.91
3242.28	1201.59
3245.47	1217.33
3248.66	1188.38
3251.85	1185.21
3255.04	1195.4
3258.23	1196.88
3261.42	1138.02
3264.6	1199.32
3267.79	1198.41
3270.97	1164.92
3274.15	1175.37
3277.33	1155.07
3280.51	1187.04
3283.68	1203.7
3286.86	1200.21
3290.04	1191.08
3293.21	1183.85
3296.38	1188.01
3299.55	1238.17
3302.72	1189.1
3305.89	1195.11
3309.06	1218.03
3312.22	1197.12
3315.39	1188.54
3318.55	1227.34
3321.71	1229.13
3324.87	1262.15
3328.03	1231.77
3331.19	1236.48
3334.34	1250.72
3337.5	1242.41
3340.65	1254.86
3343.81	1266.6
3346.96	1261.73
3350.11	1222.01
3353.25	1241.8
3356.4	1248.46
3359.55	1228.88
3362.69	1235.73
3365.84	1232.28
3368.98	1253.4
3372.12	1252.02
3375.26	1268.65
3378.4	1270.28
3381.53	1303.02
3384.67	1288.61
3387.8	1387.76
3390.94	1427.45
3394.07	1426.82
3397.2	1449.65
3400.33	1520.2
3403.46	1681.24
3406.58	1896.92
3409.71	2239.7
3412.83	2999.82
3415.96	5019.12
3419.08	10249.9
3422.2	15769.6
3425.32	12531.6
3428.44	6261.46
3431.55	3410.32
3434.67	2275.26
3437.78	1874.89
3440.89	1654.16
3444	1495.19
3447.12	1464.07
3450.22	1382.24
3453.33	1352.87
3456.44	1395.67
3459.54	1375.58
3462.65	1345.97
3465.75	1314.4
3468.85	1372.57
3471.95	1391.22
3475.05	1412.81
3478.15	1453.37
3481.24	1583.69
3484.34	1676.13
3487.43	1837.51
3490.53	2106
3493.62	2490.5
3496.71	3012.21
3499.79	3571.6
3502.88	4176.02
3505.97	4204.55
3509.05	3716.64
3512.14	3036.23
3515.22	2481.34
3518.3	2077.57
3521.38	1830.72
3524.46	1641.18
3527.54	1505.13
3530.61	1428.24
3533.69	1364.72
3536.76	1354.77
3539.83	1277.8
3542.9	1254.96
3545.97	1217.19
3549.04	1248.19
3552.11	1208.99
3555.18	1212.53
3558.24	1169.81
3561.3	1180.77
3564.37	1179.32
3567.43	1131.47
3570.49	1179.17
3573.55	1156.57
3576.61	1136.76
3579.66	1138.67
3582.72	1140.48
3585.77	1128.03
3588.82	1096.51
3591.87	1123.72
3594.92	1118.6
3597.97	1107.79
3601.02	1078.9
3604.07	1077.39
3607.11	1090.99
3610.16	1105.47
3613.2	1055.64
3616.24	1079.53
3619.28	1067.59
3622.32	1079.28
3625.36	1057.08
3628.39	1054.67
3631.43	1072.9
3634.46	1065.88
3637.5	1049.63
3640.53	1056.09
3643.56	1093.86
3646.59	1087.24
3649.62	1040.3
3652.64	1064.65
3655.67	1038.68
3658.69	1040.59
3661.72	1014.09
3664.74	1015.4
3667.76	1037.5
3670.78	1026.7
3673.79	1016.9
3676.81	1020.37
3679.83	1040.83
3682.84	1053.73
3685.86	1020.33
3688.87	1020.99
3691.88	1022.63
3694.89	994.723
3697.9	1044.66
3700.91	1029.25
3703.91	1004.32
3706.92	1001.12
3709.92	1030.15
3712.92	1025.79
3715.92	1002.43
3718.92	964.703
3721.92	997.312
3724.92	993.658
3727.92	1017.55
3730.91	989.92
3733.91	988.848
3736.9	998.158
3739.89	1011.15
3742.88	1018.34
3745.87	986.432
3748.86	975.382
3751.85	978.554
3754.83	990.283
3757.82	980.176
3760.8	981.377
3763.78	1004.35
3766.76	1009.37
3769.74	994.612
3772.72	973.333
3775.7	982.374
3778.67	982.03
3781.65	969.431
3784.62	972.936
3787.6	972.713
3790.57	980.179
3793.54	958.489
3796.51	1001.98
3799.47	967.252
3802.44	963.742
3805.41	996.158
3808.37	962.503
3811.33	1000.71
3814.3	970.866
3817.26	965.642
3820.22	976.529
3823.18	971.39
3826.13	958.693
3829.09	940.276
3832.04	952.274
3835	990.945
3837.95	953.66
3840.9	943.891
3843.85	958.864
3846.8	956.75
3849.75	978.519
3852.69	938.34
3855.64	954.444
3858.58	952.436
3861.53	986.724
3864.47	938.731
3867.41	962.454
3870.35	954.53
3873.29	936.01
3876.22	960.577
3879.16	953.371
3882.1	939.314
3885.03	964.572
3887.96	938.838
3890.89	950.562
3893.82	941.027
3896.75	934.249
3899.68	944.758
3902.61	935.896
3905.53	940.588
3908.46	901.983
3911.38	961.317
3914.3	942.696
3917.23	951.151
3920.15	936.438
3923.06	916.812
3925.98	929.721
3928.9	929.101
3931.81	920.034
3934.73	921.697
3937.64	921.665
3940.55	923.493
3943.46	939.696
3946.37	917.69
3949.28	920.658
3952.19	913.127
3955.09	923.874
3958	950.967
3960.9	902.402
3963.8	936.314
3966.71	883.97
3969.61	929.508
3972.51	925.153
3975.4	914.019
3978.3	915.298
3981.2	942.513
3984.09	941.809
3986.99	901.669
3989.88	910.412
3992.77	917.391
3995.66	906.093
3998.55	922.75
4001.43	919.206
4004.32	913.779
4007.21	918.01
4010.09	912.589
4012.98	907.169
4015.86	915.257
4018.74	907.9
4021.62	885.083
4024.5	921.203
4027.37	914.828
4030.25	889.134
4033.13	880.833
4036	881.278
4038.87	842.999
4041.75	915.952
4044.62	885.251
4047.49	882.698
4050.35	893.768
4053.22	852.516
4056.09	894.747
4058.95	896.168
4061.82	881.061
4064.68	902.891
4067.54	876.087
4070.4	876.5
4073.26	911.96
4076.12	838.321
4078.98	873.775
4081.83	883.91
4084.69	905.739
4087.54	879.739
4090.4	880.119
4093.25	885.378
4096.1	892.574
4098.95	884.166
4101.8	876.688
4104.64	886.742
4107.49	871.311
4110.33	888.132
4113.18	884.289
4116.02	835.322
4118.86	891.998
4121.7	848.935
4124.54	885.204
4127.38	870.717
4130.22	861.32
4133.05	839.359
4135.89	849.263
4138.72	848.322
4141.56	876.105
4144.39	875.391
4147.22	847.33
4150.05	868.136
4152.88	852.42
4155.7	865.73
4158.53	858.497
4161.36	869.147
4164.18	842.63
4167	834.715
4169.82	846.411
4172.65	836.624
4175.46	860.095
4178.28	884.585
4181.1	844.581
4183.92	863.296
4186.73	859.551
4189.55	830.441
4192.36	838.636
4195.17	881.229
4197.98	864.116
4200.79	867.571
4203.6	877.908
4206.41	898.062
4209.21	844.541
4212.02	856.806
4214.83	833.959
4217.63	813.265
4220.43	833.818
4223.23	831.623
4226.03	792.896
4228.83	816.503
4231.63	848.14
4234.42	831.357
4237.22	811.579
4240.01	842.465
4242.81	816.735
4245.6	844.754
4248.39	823.865
4251.18	832.853
4253.97	831.806
4256.76	829.71
4259.55	798.559
4262.33	827.598
4265.12	815.547
4267.9	822.604
4270.68	799.428
4273.47	807.357
4276.25	807.077
4279.03	807.731
4281.8	814.381
4284.58	791.601
4287.36	805.138
4290.13	823.692
4292.91	809.904
4295.68	815.458
4298.45	795.637
4301.22	798.073
4303.99	792.389
4306.76	806.021
4309.53	822.783
4312.3	822.232
4315.06	797.142
4317.83	786.225
4320.59	775.239
4323.35	776.416
4326.11	774.541
4328.87	786.891
4331.63	809.415
4334.39	787.096
4337.15	788.255
4339.9	804.789
4342.66	748.972
4345.41	762.563
4348.17	762.928
4350.92	796.096
4353.67	773.149
4356.42	764.428
4359.17	779.214
4361.91	781.753
4364.66	799.662
4367.41	745.839
4370.15	772.948
4372.89	739.449
4375.63	759.275
4378.38	770.857
4381.12	786.585
4383.86	779.841
4386.59	763.062
4389.33	787.663
4392.07	767.336
4394.8	771.68
4397.53	758.102
4400.27	764.164
4403	773.334
4405.73	752.453
4408.46	732.521
4411.19	767.6
4413.92	757.883
4416.64	764.629
4419.37	745.251
4422.09	782.33
4424.82	764.111
4427.54	744.821
4430.26	746.414
4432.98	781.479
4435.7	753.698
4438.42	745.736
4441.13	751.378
4443.85	753.862
4446.57	759.474
4449.28	762.953
4451.99	738.03
4454.71	748.778
4457.42	738.455
4460.13	735.537
4462.83	761.052
4465.54	725.565
4468.25	744.835
4470.95	718.884
4473.66	742.507
4476.36	739.855
4479.07	726.695
4481.77	747.331
4484.47	728.846
4487.17	713.491
4489.87	723.396
4492.56	758.436
4495.26	718.514
4497.96	735.776
4500.65	737.017
4503.34	707.609
4506.04	708.966
4508.73	710.324
4511.42	710.632
4514.11	732.211
4516.8	719.806
4519.48	701.117
4522.17	707.949
4524.85	731.785
4527.54	731.185
4530.22	718.868
4532.9	705.506
4535.58	692.122
4538.27	702.299
4540.94	704.977
4543.62	686.301
4546.3	689.009
4548.98	702.459
4551.65	694.645
4554.33	701.882
4557	686.802
4559.67	701.964
4562.34	705.436
4565.01	715.823
4567.68	694.579
4570.35	685.464
4573.02	690.88
4575.68	676.079
4578.35	684.266
4581.01	683.173
4583.67	661.878
4586.34	674.333
4589	667.08
4591.66	679.423
4594.31	683.267
4596.97	679.274
4599.63	668.875
4602.29	691.375
4604.94	672.271
4607.59	704.712
4610.25	679.001
4612.9	680.691
4615.55	687.903
4618.2	685.287
4620.85	688.162
4623.5	653.489
4626.14	647.401
4628.79	682.198
4631.43	666.082
4634.08	674.203
4636.72	655.786
4639.36	687.123
4642	692.05
4644.64	663.9
4647.28	658.053
4649.92	656.829
4652.56	683.801
4655.19	652.486
4657.83	650.801
4660.46	673.838
4663.1	677.94
4665.73	633.651
4668.36	665.513
4670.99	640.271
4673.62	662.074
4676.24	661.46
4678.87	655.206
4681.5	620.847
4684.12	656.167
4686.75	652.137
4689.37	654.913
4691.99	630.569
4694.61	640.003
4697.23	640.438
4699.85	628.461
4702.47	641.246
4705.09	654.034
4707.7	637.393
4710.32	638.831
4712.93	614.223
4715.55	648.432
4718.16	648.698
4720.77	643.191
4723.38	624.18
4725.99	638.107
4728.6	657.728
4731.21	636.493
4733.81	631.14
4736.42	655.267
4739.02	628.258
4741.63	618.202
4744.23	628.636
4746.83	644.608
4749.43	635.576
4752.03	620.853
4754.63	624.304
4757.23	627.81
4759.82	623.417
4762.42	615.607
4765.01	605.62
4767.61	609.495
4770.2	609.749
4772.79	612.295
4775.38	633.129
4777.97	623.123
4780.56	597.111
4783.15	600.815
4785.74	604.52
4788.32	612.818
4790.91	603.994
4793.49	613.485
4796.07	586.378
4798.66	587.953
4801.24	606.794
4803.82	591.258
4806.4	601.092
4808.98	609.759
4811.55	600.043
4814.13	601.868
4816.71	579.51
4819.28	588.323
4821.85	613.389
4824.43	609.528
4827	590.516
4829.57	593.653
4832.14	610.761
4834.71	580.187
4837.28	603.311
4839.84	566.871
4842.41	582.924
4844.97	584.876
4847.54	606.729
4850.1	578.862
4852.66	592.94
4855.22	596.168
4857.78	587.62
4860.34	576.568
4862.9	556.982
4865.46	607.002
4868.01	586.406
4870.57	584.567
4873.12	592.096
4875.68	575.922
4878.23	584.625
4880.78	570.723
4883.33	556.792
4885.88	540.474
4888.43	566.994
4890.98	563.75
4893.53	545.005
4896.07	536.938
4898.62	569.408
4901.16	575.631
4903.7	532.953
4906.25	564.185
4908.79	576.277
4911.33	562.006
4913.87	562.023
4916.41	575.196
4918.94	566.896
4921.48	566.957
4924.02	551.511
4926.55	549.181
4929.08	552.884
4931.62	532.807
4934.15	555.783
4936.68	569.164
4939.21	551.27
4941.74	575.294
4944.27	552.787
4946.79	537.463
4949.32	562.904
4951.85	537.97
4954.37	568.244
4956.9	553.001
4959.42	564.22
4961.94	563.55
4964.46	543.741
4966.98	556.377
4969.5	546.017
4972.02	535.628
4974.53	525.207
4977.05	532.928
4979.57	528.569
4982.08	554.515
4984.59	536.851
4987.1	550.739
4989.62	531.823
4992.13	546.92
4994.64	553.574
4997.15	549.328
4999.65	547.523