File: Data/3-Raman/raw/bu19(2)w-a-ff1-fi07-v_150 (500nm)_532nm_edge_100%_x100_vis_lwd_h50um_30sx2_01.txt
#Acq. time (s)=	30
#Accumulations=	2
#Range (cm-¹)=	99...4000
#Windows=	1
#Auto scanning=	Off
#Autofocus=	Off
#Macrospot=	Off
#AutoExposure=	Off
#Spike filter=	Multiple accum.
#Delay time (s)=	2
#Binning=	1
#Readout mode=	Signal
#DeNoise=	Off
#ICS correction=	On
#Dark correction=	Off
#Inst. Process=	Off
#Detector Gain=	Best Dynamic
#Detector ADC=	50 kHz HS
#Detector temperature (°C)=	-60.28
#Instrument=	LabRAM HR Evol
#Detector=	SIN-EM FIVIS
#Objective=	x100_VIS_LWD
#Grating=	150 (500nm)
#ND Filter=	100%
#Laser=	532nm_Edge
#Hole=	49.98
#Temperature=	0
#Range=	Visible
#StageXY=	75x50mm Scan+
#StageZ=	Z motor
#X (µm)=	0
#Y (µm)=	0
#Z (µm)=	-69
#Full time(mm:ss)=	1:04
#Project=	21_11_26
#Sample=	BU19(2)w
#Site=
#Title=	BU19(2)w-A-FF1-FI07-V_150 (500nm)_532nm_Edge_100%_x100_VIS_LWD_H50um_30sX2
#Remark=
#Date=	26.11.2021 16:22
#Acquired=	26.11.2021 16:22:06
102.91	4068.81
107.534	4469.95
112.156	5317.88
116.775	5128.87
121.392	3926.95
126.005	3122.1
130.617	2895.73
135.227	3487.1
139.835	5054.9
144.439	8096.67
149.042	11268.9
153.643	10267.7
158.242	6904.43
162.839	4321.87
167.431	3034.87
172.023	2195.07
176.613	1752.72
181.198	1444.17
185.783	1267.92
190.366	1216.51
194.947	1184.72
199.524	1234.89
204.1	1554.14
208.674	2901.93
213.243	4091.79
217.813	2633.74
222.38	1554.97
226.945	1535.15
231.506	2291.14
236.066	4001.63
240.625	3889.38
245.179	2163.71
249.732	1240.31
254.284	937.127
258.831	838.912
263.378	751.827
267.923	742.645
272.464	684.958
277.004	748.653
281.54	903.322
286.076	928.689
290.61	760.79
295.139	686.467
299.669	650.939
304.196	662.806
308.718	692.738
313.241	746.866
317.759	823.912
322.278	933.429
326.794	1142.46
331.305	1604.64
335.817	2024.14
340.324	1980.41
344.832	1792.13
349.334	1968.29
353.837	2586.87
358.338	2394.35
362.834	1646.61
367.33	1273.1
371.822	1169.81
376.314	1197.68
380.802	1331.88
385.289	1742.27
389.772	2817.9
394.255	4264.05
398.734	4707.57
403.213	4086.53
407.688	3474.3
412.162	2895.58
416.632	2557.65
421.102	2431.45
425.568	2676.33
430.033	3011.12
434.495	3106.68
438.956	3079.39
443.413	2945.28
447.87	3071.92
452.323	3285.23
456.776	3290.84
461.224	2698.4
465.673	2011.9
470.117	1542.95
474.561	1294.2
479.001	1223.38
483.438	1256.84
487.876	1505.19
492.309	1809.24
496.742	2451.63
501.172	3375.15
505.601	4581.1
510.025	5718.82
514.448	6238.48
518.871	5817.08
523.289	4980.55
527.707	4177.43
532.121	3751.59
536.533	3643.16
540.945	3664.45
545.353	3820.03
549.758	3884.36
554.164	3836.81
558.565	3578.06
562.965	3098.31
567.364	2675.28
571.759	2221.69
576.151	1820.95
580.544	1655.07
584.933	1624.7
589.319	1635.53
593.706	1831.03
598.088	2125.13
602.468	2579.39
606.848	3168.29
611.224	4212.58
615.598	6505.67
619.972	10893.1
624.341	12914.5
628.709	9583.15
633.074	5622.29
637.44	3369.13
641.801	2377.29
646.16	1794.53
650.517	1422.62
654.874	1170.26
659.227	1008.61
663.578	896.15
667.927	829.258
672.275	737.683
676.62	675.698
680.962	667.998
685.302	651.246
689.643	661.327
693.979	714.814
698.313	802.07
702.645	946.47
706.975	1075.12
711.305	1022.11
715.631	895.553
719.955	795.797
724.276	690.871
728.596	681.709
732.913	635.637
737.231	592.347
741.544	530.931
745.856	569.483
750.165	537.141
754.472	533.42
758.778	542.98
763.081	534.543
767.384	532.552
771.683	549.299
775.98	572.922
780.275	535.986
784.568	570.209
788.859	584.888
793.147	611.841
797.434	621.81
801.719	647.455
806.004	661.457
810.284	687.8
814.563	729.651
818.839	765.041
823.114	838.949
827.386	961.587
831.657	1160.46
835.925	1381.65
840.192	1692.34
844.456	1930.32
848.719	2076.13
852.979	1953.73
857.237	1754.31
861.493	1495.55
865.748	1350.25
870	1247.64
874.25	1261.41
878.499	1393.26
882.745	1517.78
886.989	1397.59
891.231	1176.95
895.471	907.185
899.71	789.881
903.946	725.407
908.18	679.428
912.412	620.813
916.642	630.872
920.87	615.938
925.096	608.36
929.321	624.116
933.543	596.551
937.763	611.893
941.981	622.732
946.197	631.315
950.412	622.767
954.622	621.875
958.832	633.826
963.04	639.452
967.246	670.621
971.451	671.047
975.653	644.046
979.853	680.733
984.052	702.691
988.248	753.197
992.442	825.952
996.633	955.422
1000.82	1045.41
1005.01	1107.18
1009.2	1046.03
1013.38	977.29
1017.57	887.874
1021.75	910.212
1025.92	877.955
1030.1	910.469
1034.27	956.596
1038.45	1109.51
1042.62	1284.83
1046.78	1580.9
1050.95	1673.62
1055.12	1598.08
1059.28	1537.19
1063.44	1594.28
1067.6	1671.6
1071.75	1924.37
1075.91	2218.22
1080.06	2693.44
1084.21	3536.26
1088.36	4938.48
1092.51	7034.86
1096.65	8678.98
1100.8	8347.1
1104.94	5974.71
1109.08	3817.05
1113.21	2512.02
1117.35	1849.79
1121.48	1603.57
1125.61	1525.96
1129.74	1528.42
1133.87	1665.48
1137.99	2045.63
1142.12	2591.21
1146.24	3098.99
1150.36	3193.17
1154.48	2760.67
1158.59	2131.43
1162.71	1620.99
1166.82	1309.14
1170.93	1105.42
1175.04	907.726
1179.14	794.641
1183.25	744.505
1187.35	667.522
1191.45	626.293
1195.55	604.485
1199.65	560.11
1203.74	538.217
1207.83	525.539
1211.92	530.166
1216.01	521.664
1220.1	517.286
1224.19	520.039
1228.27	543.949
1232.35	568.966
1236.43	558.358
1240.51	570.076
1244.58	641.569
1248.66	850.991
1252.73	952.022
1256.8	745.675
1260.87	697.157
1264.93	852.733
1269	3960.41
1273.06	4794.82
1277.12	1390.34
1281.18	697.684
1285.23	628.946
1289.29	588.155
1293.34	572.409
1297.39	528.352
1301.44	527.539
1305.49	506.467
1309.53	527.688
1313.58	522.644
1317.62	518.419
1321.66	520.129
1325.7	487.435
1329.73	514.034
1333.77	502.374
1337.8	524.653
1341.83	509.749
1345.86	534.788
1349.88	558.726
1353.91	636.32
1357.93	762.335
1361.95	680.621
1365.97	768.569
1369.99	1458.23
1374	8798
1378.02	5221.1
1382.03	1231.78
1386.04	695.591
1390.05	643.23
1394.05	962.134
1398.06	1052.14
1402.06	622.045
1406.06	499.069
1410.06	462.8
1414.05	458.102
1418.05	434.658
1422.04	381.567
1426.03	408.374
1430.02	374.745
1434.01	377.688
1438	351.99
1441.98	352.958
1445.96	351.896
1449.94	347.853
1453.92	326.985
1457.9	336.665
1461.87	318.689
1465.85	337.054
1469.82	334.715
1473.78	312.786
1477.75	321.271
1481.72	312.058
1485.68	299.912
1489.65	303.41
1493.61	319.608
1497.56	313.355
1501.52	310.071
1505.47	309.766
1509.43	309.548
1513.38	299.64
1517.33	320.824
1521.27	306.122
1525.22	296.302
1529.16	308.813
1533.11	310.693
1537.05	302.888
1540.98	311.569
1544.92	298.932
1548.86	290.176
1552.79	314.358
1556.72	293.942
1560.65	294.793
1564.58	279.161
1568.5	305.1
1572.43	282.664
1576.35	281.499
1580.27	321.819
1584.19	307.108
1588.1	285.653
1592.02	308.506
1595.93	311.117
1599.84	319.489
1603.75	309.631
1607.66	304.633
1611.57	312.116
1615.47	304.278
1619.37	310.86
1623.27	312.63
1627.17	293.389
1631.07	315.349
1634.97	322.096
1638.86	312.555
1642.75	328.947
1646.64	312.846
1650.53	319.768
1654.42	309.445
1658.3	306.761
1662.18	304.062
1666.07	306.107
1669.94	307.157
1673.82	286.001
1677.7	297.512
1681.57	308.856
1685.44	309.544
1689.31	308.286
1693.18	312.714
1697.05	321.868
1700.92	323.301
1704.78	322.754
1708.64	326.898
1712.5	309.114
1716.36	323.628
1720.21	315.398
1724.07	310.041
1727.92	327.282
1731.77	334.058
1735.62	343.644
1739.47	340.05
1743.32	330.831
1747.16	325.399
1751.01	340.634
1754.85	334.599
1758.69	363.082
1762.52	355.97
1766.36	347.67
1770.19	343.209
1774.02	315.665
1777.85	335.543
1781.68	329.486
1785.51	321.599
1789.33	309.046
1793.16	314.263
1796.98	301.677
1800.8	298.433
1804.62	305.337
1808.43	314.114
1812.25	305.902
1816.06	307.055
1819.87	318.454
1823.68	318.449
1827.49	318.384
1831.3	308.803
1835.1	306.69
1838.9	303.587
1842.71	313.608
1846.51	309.444
1850.3	290.32
1854.1	300.146
1857.89	284.621
1861.69	289.588
1865.48	315.9
1869.27	312.415
1873.05	302.494
1876.84	336.136
1880.62	314.296
1884.4	304.642
1888.19	300.551
1891.96	318.899
1895.74	306.885
1899.52	319.716
1903.29	307.84
1907.06	311.668
1910.83	306.319
1914.6	310.296
1918.37	313.381
1922.13	317.599
1925.9	301.487
1929.66	311.352
1933.42	305.476
1937.18	305.159
1940.94	306.697
1944.69	321.329
1948.44	300.4
1952.2	302.625
1955.95	331.965
1959.69	315.135
1963.44	329.19
1967.19	353.552
1970.93	357.137
1974.67	370.9
1978.41	394.866
1982.15	384.089
1985.89	401.304
1989.62	418.421
1993.35	442.866
1997.09	429.02
2000.82	412.363
2004.55	423.568
2008.27	413.43
2012	405.079
2015.72	384.828
2019.44	379.532
2023.16	366.205
2026.88	369.617
2030.6	360.227
2034.31	357.422
2038.03	345.59
2041.74	339.215
2045.45	347.462
2049.16	342.898
2052.86	311.842
2056.57	319.264
2060.27	316.774
2063.98	308.05
2067.67	330.644
2071.37	310.04
2075.07	295.827
2078.77	309.326
2082.46	316.413
2086.15	297.495
2089.84	301.397
2093.53	297.731
2097.22	304.43
2100.9	286.903
2104.59	294.38
2108.27	309.245
2111.95	308.251
2115.63	294.232
2119.31	305.275
2122.98	284.612
2126.66	289.897
2130.33	284.006
2134	303.089
2137.67	298.996
2141.34	291.172
2145	275.956
2148.67	294.804
2152.33	297.054
2155.99	296.559
2159.65	288.754
2163.31	287.406
2166.96	281.544
2170.62	280.304
2174.27	294.669
2177.92	294.515
2181.57	280.75
2185.22	283.358
2188.87	286.95
2192.51	277.008
2196.15	278.096
2199.8	269.226
2203.44	274.962
2207.07	286.232
2210.71	271.98
2214.35	277.869
2217.98	266.368
2221.61	268.614
2225.24	275.48
2228.87	276.821
2232.5	286.476
2236.12	273.084
2239.75	268.895
2243.37	276.739
2246.99	273.453
2250.61	286.91
2254.23	277.153
2257.85	287.919
2261.46	289.367
2265.07	288.911
2268.68	290.36
2272.29	273.08
2275.9	258.485
2279.51	268.289
2283.11	274.162
2286.72	270.593
2290.32	280.247
2293.92	274.744
2297.52	277.759
2301.11	275.106
2304.71	286.615
2308.3	281.96
2311.9	301.908
2315.49	591.017
2319.08	751.08
2322.66	383.204
2326.25	303.318
2329.84	284.072
2333.42	285.606
2337	292.756
2340.58	291.373
2344.16	286.203
2347.73	285.704
2351.31	290.806
2354.88	288.395
2358.45	289.707
2362.03	294.719
2365.59	297.847
2369.16	300.983
2372.73	293.995
2376.29	290.705
2379.85	306.811
2383.41	294.344
2386.97	279.184
2390.53	299.941
2394.09	301.439
2397.64	310.359
2401.2	301.044
2404.75	286.399
2408.3	297.454
2411.85	298.554
2415.39	295.138
2418.94	298.22
2422.48	300.435
2426.03	285.219
2429.57	299.566
2433.11	296.452
2436.64	289.682
2440.18	306.139
2443.72	290.1
2447.25	301.997
2450.78	297.168
2454.31	298.934
2457.84	303.334
2461.37	299.949
2464.89	293.698
2468.42	302.28
2471.94	284.681
2475.46	284.53
2478.98	293.764
2482.5	282.298
2486.01	282.985
2489.53	300.419
2493.04	289.792
2496.55	281.843
2500.06	302.119
2503.57	289.5
2507.08	282.476
2510.58	281.938
2514.09	279.561
2517.59	284.691
2521.09	280.579
2524.59	290.171
2528.09	300.946
2531.59	283.141
2535.08	288.483
2538.58	282.832
2542.07	289.243
2545.56	278.26
2549.05	276.622
2552.54	283.313
2556.02	277.139
2559.51	286.841
2562.99	295.648
2566.47	309.268
2569.95	290.414
2573.43	289.302
2576.91	292.925
2580.38	289.104
2583.85	279.618
2587.33	281.423
2590.8	286.96
2594.27	295.226
2597.74	278.704
2601.2	269.831
2604.67	280.037
2608.13	290.122
2611.59	296.148
2615.06	283.733
2618.51	283.903
2621.97	292.602
2625.43	294.518
2628.88	306.92
2632.33	277.013
2635.79	297.926
2639.24	275.581
2642.69	289.614
2646.13	289.213
2649.58	288.793
2653.02	284.494
2656.47	294.405
2659.91	289.026
2663.35	293.109
2666.79	293.365
2670.22	289.842
2673.66	283.499
2677.09	293.181
2680.52	291.629
2683.95	284.542
2687.39	271.048
2690.81	292.255
2694.24	280.925
2697.66	290.964
2701.09	281.515
2704.51	290.689
2707.93	271.971
2711.35	302.742
2714.77	310.337
2718.18	291.929
2721.6	277.277
2725.01	268.231
2728.42	295.614
2731.84	267.905
2735.24	283.18
2738.65	290.055
2742.06	295.054
2745.46	280.285
2748.86	281.427
2752.27	288.216
2755.67	273.347
2759.07	294.205
2762.46	298.136
2765.86	297.278
2769.25	295.432
2772.65	282.228
2776.04	278.423
2779.43	293.41
2782.82	276.333
2786.2	288.424
2789.59	298.61
2792.98	288.094
2796.36	294.49
2799.74	294.307
2803.12	306.27
2806.5	290.099
2809.88	291.74
2813.25	295.234
2816.63	290.289
2820	294.689
2823.37	304.726
2826.74	302.666
2830.11	295.97
2833.48	304.23
2836.84	295.773
2840.21	301.342
2843.57	298.585
2846.93	290.308
2850.29	293.318
2853.65	304.803
2857.01	294.782
2860.36	293.201
2863.72	293.525
2867.07	287.299
2870.42	302.645
2873.77	285.124
2877.12	294.829
2880.47	308.312
2883.81	296.367
2887.16	307.956
2890.5	291.236
2893.84	296.202
2897.18	308.665
2900.52	305.018
2903.86	316.458
2907.19	316.508
2910.53	311.799
2913.86	309.906
2917.19	317.453
2920.52	322.112
2923.85	311.619
2927.18	314.339
2930.51	317.957
2933.83	330.975
2937.15	303.353
2940.48	319.143
2943.8	333.025
2947.11	334.659
2950.43	337.241
2953.75	338.866
2957.06	331.108
2960.38	306.515
2963.69	320.447
2967	325.007
2970.31	305.279
2973.62	317.496
2976.92	298.772
2980.23	319.499
2983.53	333.628
2986.84	326.194
2990.14	331.921
2993.44	325.452
2996.73	320.876
3000.03	323.832
3003.33	323.026
3006.62	343.858
3009.91	347.794
3013.2	345.16
3016.49	328.396
3019.78	325.746
3023.07	329.692
3026.35	327.036
3029.64	320.605
3032.92	319.83
3036.2	339.834
3039.48	326.747
3042.76	315.543
3046.04	320.427
3049.32	337.63
3052.59	324.528
3055.86	349.343
3059.14	334.332
3062.41	334.382
3065.68	347.766
3068.94	339.285
3072.21	376.282
3075.48	343.703
3078.74	361.755
3082	358.832
3085.26	340.087
3088.52	355.473
3091.78	368.129
3095.04	377.026
3098.29	367.387
3101.55	367.493
3104.8	359.921
3108.05	366.784
3111.3	358.372
3114.55	379.35
3117.8	359.427
3121.04	374.742
3124.29	380.537
3127.53	392.045
3130.77	375.911
3134.02	376.933
3137.25	376.99
3140.49	405.626
3143.73	393.267
3146.96	414.278
3150.2	395.271
3153.43	419.184
3156.66	416.378
3159.89	419.307
3163.12	423.176
3166.35	432.774
3169.57	444.241
3172.8	449.95
3176.02	446.098
3179.24	457.474
3182.46	457.393
3185.68	463.044
3188.9	463.871
3192.12	455.154
3195.33	473.121
3198.55	447.251
3201.76	479.477
3204.97	475.527
3208.18	482.065
3211.39	505.751
3214.6	492.357
3217.8	519.908
3221.01	511.307
3224.21	503.677
3227.41	500.854
3230.61	524.68
3233.81	512.393
3237.01	523.859
3240.21	531.637
3243.4	538.499
3246.59	547.298
3249.79	556.108
3252.98	581.191
3256.17	581.51
3259.36	600.909
3262.54	591.591
3265.73	626.121
3268.92	618.542
3272.1	635.738
3275.28	653.85
3278.46	661.443
3281.64	675.579
3284.82	699.127
3288	718.852
3291.17	707.984
3294.35	716.247
3297.52	745.432
3300.69	747.942
3303.86	746.812
3307.03	749.295
3310.2	820.169
3313.36	847.111
3316.53	840.73
3319.69	886.515
3322.85	934.084
3326.02	924.759
3329.18	1000.62
3332.33	1013.02
3335.49	1044.38
3338.65	1076.73
3341.8	1112.88
3344.95	1118.85
3348.11	1204.28
3351.26	1244.72
3354.41	1283.26
3357.56	1327.59
3360.7	1370.11
3363.85	1414.7
3366.99	1463.11
3370.13	1528.6
3373.28	1615.9
3376.42	1680.8
3379.56	1734.51
3382.69	1795.9
3385.83	1828.92
3388.97	1994.56
3392.1	2083.75
3395.23	2157.79
3398.36	2288.18
3401.49	2397.24
3404.62	2525.68
3407.75	2699.26
3410.88	2861.94
3414	2991.56
3417.13	3220.75
3420.25	3433.86
3423.37	3729.96
3426.49	3957.84
3429.61	4235.77
3432.73	4555.23
3435.84	4853.71
3438.96	5264.56
3442.07	5715.94
3445.18	6217.55
3448.29	7054.25
3451.4	8521.13
3454.51	10623.6
3457.62	13367.8
3460.72	14813.5
3463.83	13515.7
3466.93	11324.4
3470.03	9427.74
3473.13	8074.66
3476.23	7442.77
3479.33	7072.55
3482.43	6850.74
3485.53	6731.49
3488.62	6593.04
3491.71	6565.26
3494.81	6616.66
3497.9	6711.2
3500.99	6673.19
3504.07	6791.88
3507.16	6903.72
3510.25	7138.8
3513.33	7392.07
3516.41	7637.95
3519.5	8046.13
3522.58	8450.79
3525.66	9154.6
3528.73	9707.17
3531.81	10377.7
3534.89	11025.7
3537.96	11474.8
3541.03	11621.8
3544.11	11361.3
3547.18	10621
3550.25	9510.68
3553.32	8196.06
3556.38	6970.21
3559.45	5756.52
3562.51	4922.04
3565.58	4142.49
3568.64	3571.21
3571.7	3100.15
3574.76	2733.48
3577.82	2483.5
3580.87	2238
3583.93	2025.5
3586.98	1925.7
3590.04	1770.91
3593.09	1687.99
3596.14	1582.33
3599.19	1513.55
3602.24	1415.45
3605.29	1367.45
3608.33	1328.86
3611.38	1240.18
3614.42	1231.86
3617.46	1211.23
3620.5	1138.77
3623.54	1085.31
3626.58	1130.94
3629.62	1081.41
3632.65	1065.77
3635.69	1006.8
3638.72	980.124
3641.76	952.655
3644.79	904.604
3647.82	885.011
3650.84	853.88
3653.87	848.273
3656.9	772.051
3659.92	755.882
3662.95	733.016
3665.97	723.166
3668.99	677.16
3672.01	669.938
3675.03	647.648
3678.05	638.587
3681.07	612.549
3684.08	606.291
3687.1	612.328
3690.11	609.875
3693.12	587.551
3696.13	576.574
3699.14	570.21
3702.15	568.706
3705.16	570.048
3708.16	540.986
3711.17	512.774
3714.17	498.757
3717.17	546.497
3720.17	484.873
3723.17	514.529
3726.17	496.549
3729.17	490.897
3732.16	488.066
3735.16	471.855
3738.15	457.498
3741.14	475.471
3744.13	458.168
3747.13	448.449
3750.11	439.645
3753.1	443.169
3756.09	425.796
3759.07	434.072
3762.06	422.414
3765.04	430.633
3768.02	419.915
3771	437.631
3773.98	400.515
3776.96	420.183
3779.94	433.244
3782.91	411.374
3785.89	409.355
3788.86	418.689
3791.83	397.842
3794.8	396.883
3797.77	397.845
3800.74	394.111
3803.71	385.708
3806.68	393.377
3809.64	373.664
3812.61	380.424
3815.57	404.219
3818.53	376.963
3821.49	382.821
3824.45	365.971
3827.41	377.552
3830.36	373.034
3833.32	371.355
3836.27	385.845
3839.23	404.176
3842.18	374.054
3845.13	372.423
3848.08	392.693
3851.03	393.957
3853.98	376.175
3856.92	395.59
3859.87	387.344
3862.81	380.041
3865.75	389.928
3868.7	387.38
3871.64	380.004
3874.57	378.361
3877.51	380.536
3880.45	379.791
3883.39	377.082
3886.32	368.56
3889.25	382.114
3892.18	385.082
3895.12	383.224
3898.05	391.894
3900.97	392.826
3903.9	394.708
3906.83	377.315
3909.75	385.925
3912.68	378.157
3915.6	368.436
3918.52	362.539
3921.44	374.952
3924.36	381.525
3927.28	375.577
3930.2	360.012
3933.11	377.028
3936.03	386.454
3938.94	360.525
3941.86	385.416
3944.77	363.353
3947.68	378.653
3950.59	364.31
3953.49	358.609
3956.4	380.696
3959.31	366.424
3962.21	374.202
3965.12	363.789
3968.02	376.405
3970.92	380.416
3973.82	376.763
3976.72	381.74
3979.61	391.5
3982.51	371.448
3985.41	373.487
3988.3	387.049
3991.19	384.252
3994.09	372.752
3996.98	369.014
3999.87	373.93