File: Data/3-Raman/raw/bu19w-e-ff11b-fi09-v_1800 (450-850nm)_532nm_edge_100%_x100_vis_h50um_30sx2_01.txt
#Acq. time (s)=	30
#Accumulations=	2
#Range (cm-¹)=	1200...2400
#Windows=	4
#Auto scanning=	Off
#Autofocus=	Off
#Macrospot=	Off
#AutoExposure=	Off
#Spike filter=	Multiple accum.
#Delay time (s)=	2
#Binning=	1
#Readout mode=	Signal
#DeNoise=	Off
#ICS correction=	On
#Dark correction=	Off
#Inst. Process=	Off
#Detector Gain=	Best Dynamic
#Detector ADC=	50 kHz HS
#Detector temperature (°C)=	-60.09
#Instrument=	LabRAM HR Evol
#Detector=	SIN-EM FIVIS
#Objective=	x100_VIS
#Grating=	1800 (450-850nm)
#ND Filter=	100%
#Laser=	532nm_Edge
#Hole=	49.98
#Temperature=	0
#Range=	Visible
#StageXY=	75x50mm Scan+
#StageZ=	Z motor
#X (µm)=	0
#Y (µm)=	0
#Z (µm)=	-293.2
#Full time(mm:ss)=	4:21
#Project=	21_11_04
#Sample=	BU19w
#Site=
#Title=	BU19w-E-FF11b-FI09-V_1800 (450-850nm)_532nm_Edge_100%_x100_VIS_H50um_30sX2
#Remark=
#Date=	04.11.2021 17:31
#Acquired=	04.11.2021 17:31:01
1200.19	16.7014
1201.3	20.9691
1202.41	19.9394
1203.52	19.8932
1204.63	20.9583
1205.74	21.9931
1206.85	20.8842
1207.97	19.7964
1209.08	18.7102
1210.19	18.6935
1211.3	21.8677
1212.41	19.7084
1213.52	22.8885
1214.63	17.5665
1215.74	22.8771
1216.85	19.6561
1217.95	19.6363
1219.06	16.4449
1220.17	19.6215
1221.28	23.8499
1222.39	18.5176
1223.5	24.8256
1224.61	20.5836
1225.71	25.8706
1226.82	23.7427
1227.93	22.6231
1229.03	23.7212
1230.14	24.7522
1231.25	21.5421
1232.35	22.5882
1233.46	21.5361
1234.57	21.5468
1235.67	24.7087
1236.78	23.6418
1237.88	18.3618
1238.99	20.4429
1240.1	23.5844
1241.2	20.4386
1242.3	21.484
1243.41	21.4901
1244.51	19.3899
1245.62	28.7883
1246.72	21.457
1247.82	20.3963
1248.93	25.6265
1250.03	21.4341
1251.13	22.4613
1252.24	22.4447
1253.34	23.4803
1254.44	20.3616
1255.54	25.5837
1256.65	25.591
1257.75	28.7138
1258.85	26.6157
1259.95	30.7995
1261.05	28.6836
1262.15	38.1575
1263.25	47.5057
1264.35	37.1064
1265.45	28.7334
1266.55	25.6113
1267.66	25.6415
1268.75	25.6694
1269.85	25.6535
1270.95	29.823
1272.05	28.795
1273.15	27.7795
1274.25	26.7479
1275.35	27.8058
1276.45	30.9777
1277.54	31.0055
1278.64	33.1352
1279.74	42.5945
1280.84	72.0819
1281.94	221.609
1283.03	462.964
1284.13	189.123
1285.23	61.5887
1286.32	44.7477
1287.42	34.2034
1288.52	33.1542
1289.61	26.8597
1290.71	27.9106
1291.8	22.6441
1292.9	26.8571
1293.99	22.6719
1295.09	32.1867
1296.18	23.7825
1297.28	24.826
1298.37	21.6476
1299.47	24.8069
1300.56	24.8119
1301.65	21.653
1302.75	21.6523
1303.84	24.8148
1304.94	22.6941
1306.03	26.8939
1307.12	22.6768
1308.21	21.6221
1309.31	20.5784
1310.4	25.8545
1311.49	22.6951
1312.58	21.6442
1313.67	21.638
1314.76	23.7573
1315.86	22.7077
1316.95	20.5943
1318.04	21.6572
1319.13	23.7687
1320.22	20.5987
1321.31	22.6895
1322.4	21.6187
1323.49	22.6708
1324.58	24.7802
1325.67	18.4245
1326.76	21.58
1327.85	20.5606
1328.93	22.6828
1330.02	25.841
1331.11	17.3821
1332.2	23.672
1333.29	22.5905
1334.37	20.4678
1335.46	19.4039
1336.55	22.5384
1337.64	22.5246
1338.72	19.3711
1339.81	21.4678
1340.9	18.326
1341.98	23.5473
1343.07	21.4401
1344.16	21.4396
1345.24	23.5108
1346.33	24.5213
1347.41	25.5391
1348.5	22.4017
1349.58	22.3852
1350.67	22.3663
1351.75	21.3174
1352.84	25.5041
1353.92	21.3103
1355.01	17.1363
1356.09	25.4494
1357.17	22.3237
1358.26	21.271
1359.34	22.2942
1360.42	21.2357
1361.5	24.3394
1362.59	24.3316
1363.67	25.3799
1364.75	27.4391
1365.83	22.2416
1366.92	26.3541
1368	28.4278
1369.08	40.8418
1370.16	24.283
1371.24	24.2586
1372.32	23.1962
1373.4	29.3675
1374.48	27.2981
1375.56	28.331
1376.64	27.2744
1377.72	29.3538
1378.8	32.4746
1379.88	34.4957
1380.96	32.397
1382.04	35.4229
1383.12	47.6845
1384.2	69.2149
1385.28	166.821
1386.36	811.98
1387.43	458.4
1388.51	102.135
1389.59	51.8309
1390.67	42.5329
1391.74	34.3102
1392.82	33.2668
1393.9	30.1864
1394.97	26.0999
1396.05	27.1227
1397.13	27.1061
1398.2	30.1796
1399.28	27.1218
1400.35	24.0633
1401.43	28.1671
1402.5	27.1959
1403.58	27.1946
1404.65	30.2596
1405.73	33.315
1406.8	40.4912
1407.88	68.1867
1408.95	53.8493
1410.03	34.3552
1411.1	25.1022
1412.17	24.0893
1413.25	23.084
1414.32	22.0729
1415.39	24.1284
1416.47	20.0296
1417.54	20.0374
1418.61	22.0961
1419.68	21.0569
1420.75	18.9882
1421.83	22.0834
1422.9	21.1142
1423.97	20.9951
1425.04	22.0419
1426.11	22.0494
1427.18	18.9484
1428.25	16.8945
1429.32	23.049
1430.39	21.023
1431.46	18.9875
1432.53	21.0201
1433.6	19.9683
1434.67	22.0317
1435.74	18.955
1436.81	20.9976
1437.88	19.9724
1438.95	21.0041
1440.01	19.995
1441.08	21.0204
1442.15	18.9722
1443.22	18.966
1444.29	16.9216
1445.35	23.0816
1446.42	19.9982
1447.49	23.0664
1448.56	20.0005
1449.62	18.9667
1450.69	18.9601
1451.75	16.9048
1452.82	16.9084
1453.89	18.9571
1454.95	18.9555
1456.02	18.9612
1457.08	17.9278
1458.15	22.0253
1459.21	17.9303
1460.28	18.9499
1461.34	19.964
1462.41	20.9717
1463.47	16.8701
1464.53	16.8999
1465.6	17.8612
1466.66	16.8337
1467.72	16.831
1468.79	16.8274
1469.85	16.8151
1470.91	20.8817
1471.97	18.8376
1473.04	20.8675
1474.1	17.809
1475.16	14.7579
1476.22	19.8386
1477.29	17.7967
1478.34	19.8205
1479.41	16.759
1480.47	15.7276
1481.53	15.7291
1482.59	16.7527
1483.65	18.783
1484.71	23.7795
1485.77	19.7645
1486.83	19.7592
1487.89	19.7437
1488.95	17.7064
1490.01	17.7032
1491.07	19.7151
1492.12	17.6924
1493.18	17.6898
1494.24	14.6593
1495.3	16.6657
1496.36	20.692
1497.42	18.6703
1498.47	17.6623
1499.53	17.6674
1500.59	17.6662
1501.64	14.6323
1502.7	15.6329
1503.76	18.6557
1504.81	17.6446
1505.87	18.6378
1506.93	18.642
1507.98	19.6478
1509.04	15.6182
1510.09	18.64
1511.15	18.6176
1512.21	16.574
1513.26	15.5594
1514.31	17.5766
1515.37	17.5575
1516.42	16.5443
1517.48	19.5541
1518.53	20.5638
1519.58	17.557
1520.64	16.5547
1521.69	17.5569
1522.75	21.5579
1523.8	16.526
1524.85	17.526
1525.9	17.5382
1526.95	17.5388
1528.01	19.5362
1529.06	14.5234
1530.11	18.5283
1531.16	18.5375
1532.21	20.5428
1533.27	14.5451
1534.32	17.5523
1535.37	18.5379
1536.42	20.5165
1537.47	16.5031
1538.52	17.4934
1539.57	19.5341
1540.62	18.5498
1541.67	18.5332
1542.72	16.5141
1543.77	18.5017
1544.81	18.5188
1545.86	19.5331
1546.91	19.5391
1547.96	16.5214
1549.01	17.4931
1550.06	20.56
1551.1	18.5754
1552.15	17.577
1553.2	15.5487
1554.25	19.5413
1555.3	17.5303
1556.34	21.536
1557.39	17.5299
1558.43	16.5093
1559.48	20.4931
1560.53	18.4874
1561.57	19.4993
1562.62	17.5008
1563.66	17.5071
1564.71	18.4929
1565.76	16.4883
1566.8	17.5001
1567.84	18.4963
1568.89	19.4888
1569.93	16.4902
1570.98	20.4839
1572.02	19.4749
1573.07	19.4627
1574.11	17.4738
1575.15	17.4888
1576.2	15.4858
1577.24	18.4572
1578.28	16.4494
1579.32	19.4422
1580.37	17.4501
1581.41	17.4388
1582.45	17.4323
1583.49	16.4328
1584.53	20.4206
1585.58	19.4194
1586.62	19.4049
1587.66	20.3964
1588.7	17.4199
1589.74	18.4196
1590.78	18.4239
1591.82	20.4054
1592.86	18.3948
1593.9	17.3816
1594.94	19.3779
1595.98	18.3745
1597.02	20.3658
1598.06	18.3727
1599.1	20.342
1600.14	17.3527
1601.17	20.3027
1602.21	16.3317
1603.25	20.0759
1604.29	17.3703
1605.33	17.3065
1606.37	19.0212
1607.4	18.8893
1608.44	17.6086
1609.48	17.0083
1610.51	20.6543
1611.55	19.7589
1612.59	17.4136
1613.62	18.6633
1614.66	20.7365
1615.7	18.7147
1616.73	18.6897
1617.77	15.5908
1618.8	18.105
1619.84	17.4781
1620.87	16.9185
1621.91	18.2389
1622.94	17.1106
1623.98	16.8426
1625.01	17.9516
1626.04	17.7293
1627.08	14.8931
1628.11	17.6501
1629.07	17.2429
1630.12	14.2837
1631.16	16.2561
1632.21	17.2533
1633.25	17.2433
1634.3	17.2496
1635.34	19.217
1636.39	17.2375
1637.43	16.2453
1638.48	15.2574
1639.52	17.2256
1640.57	17.2321
1641.61	18.2125
1642.65	14.2724
1643.7	16.2369
1644.74	18.2025
1645.78	18.2033
1646.83	18.1961
1647.87	17.2106
1648.91	17.2284
1649.95	16.2483
1651	17.2448
1652.04	14.29
1653.08	19.2124
1654.12	17.2468
1655.16	17.2605
1656.21	14.3129
1657.25	17.2707
1658.29	16.2773
1659.33	17.2533
1660.37	14.2996
1661.41	15.2965
1662.45	16.3143
1663.49	14.3014
1664.53	16.3019
1665.57	20.2695
1666.61	17.2462
1667.65	16.2799
1668.69	16.2964
1669.72	15.3079
1670.76	16.309
1671.8	16.3101
1672.84	16.3112
1673.88	18.2957
1674.92	14.3486
1675.95	17.3194
1676.99	18.3088
1678.03	17.3074
1679.07	16.3104
1680.1	17.2923
1681.14	16.3006
1682.18	14.3251
1683.21	16.2998
1684.25	17.2819
1685.29	14.3181
1686.32	15.3111
1687.36	17.2846
1688.39	16.2889
1689.43	14.3037
1690.46	16.2795
1691.5	13.324
1692.53	16.2775
1693.57	18.2325
1694.6	15.268
1695.64	17.2427
1696.67	18.2295
1697.7	17.228
1698.74	17.2192
1699.77	17.22
1700.81	16.2308
1701.84	16.2201
1702.87	18.1784
1703.9	15.2295
1704.94	15.2298
1705.97	15.2233
1707	17.1711
1708.03	17.1495
1709.06	15.1745
1710.1	17.1325
1711.13	15.1811
1712.16	17.1326
1713.19	18.0821
1714.22	19.0467
1715.25	16.1221
1716.28	14.1605
1717.31	11.2124
1718.34	16.0666
1719.37	17.0373
1720.4	19.954
1721.43	14.1008
1722.46	17.0011
1723.49	17.9645
1724.52	15.0416
1725.55	18.8979
1726.58	16.9547
1727.6	17.9205
1728.63	15.9249
1729.66	13.0422
1730.69	16.912
1731.72	14.9787
1732.74	15.9352
1733.77	17.8411
1734.8	13.9656
1735.82	14.9186
1736.85	14.9106
1737.88	12.978
1738.91	14.8861
1739.93	15.8204
1740.96	17.7208
1741.98	15.7973
1743.01	16.7503
1744.03	14.8262
1745.06	18.652
1746.09	16.7272
1747.11	15.7552
1748.13	14.7959
1749.16	18.6223
1750.18	17.6831
1751.21	15.7716
1752.23	15.7552
1753.26	15.7426
1754.28	17.6376
1755.3	15.722
1756.33	16.6568
1757.35	14.7419
1758.37	14.7491
1759.39	16.653
1760.42	16.6466
1761.44	15.6853
1762.46	16.6394
1763.48	13.7885
1764.5	14.7523
1765.53	17.6132
1766.55	16.6583
1767.57	15.7001
1768.59	14.7367
1769.61	13.7691
1770.63	16.628
1771.65	15.6908
1772.67	16.6531
1773.69	13.8039
1774.71	17.618
1775.73	16.6831
1776.75	17.6303
1777.77	15.7141
1778.79	15.6994
1779.81	18.5586
1780.83	15.7081
1781.85	16.6684
1782.86	17.6318
1783.88	16.6895
1784.9	13.8346
1785.92	16.6935
1786.94	12.8885
1787.95	18.6603
1788.97	17.7246
1789.99	16.7768
1791	16.7619
1792.02	15.8026
1793.04	13.8912
1794.05	16.7679
1795.07	17.7541
1796.09	16.8077
1797.1	20.6654
1798.12	17.789
1799.13	15.8603
1800.15	16.8112
1801.16	12.9669
1802.18	18.7371
1803.19	13.9436
1804.21	14.9127
1805.22	17.8158
1806.24	15.9008
1807.25	16.8666
1808.26	14.9407
1809.28	15.9074
1810.29	12.0514
1811.3	13.9787
1812.32	16.877
1813.33	12.0617
1814.34	16.9055
1815.36	16.9135
1816.37	14.984
1817.38	14.0036
1818.39	15.9455
1819.4	17.8841
1820.42	15.9582
1821.43	16.935
1822.44	15.0047
1823.45	15.002
1824.46	18.879
1825.47	14.0424
1826.48	18.8864
1827.49	15.0182
1828.5	15.0136
1829.51	17.9159
1830.52	15.9743
1831.53	15.9829
1832.54	15.993
1833.55	14.0571
1834.56	16.9433
1835.57	15.9602
1836.58	17.9326
1837.58	16.9159
1838.59	15.9811
1839.6	15.994
1840.61	17.8826
1841.62	16.8879
1842.62	17.8438
1843.63	17.8437
1844.64	14.95
1845.65	14.9649
1846.65	17.838
1847.66	16.8561
1848.67	13.9607
1849.67	15.8683
1850.68	17.7721
1851.68	16.8041
1852.69	15.8433
1853.69	16.7919
1854.7	16.7768
1855.71	19.6358
1856.71	16.7608
1857.72	16.7524
1858.72	16.7371
1859.72	16.7304
1860.73	16.7408
1861.73	14.8322
1862.74	15.7756
1863.74	16.7181
1864.74	16.7042
1865.75	17.633
1866.75	17.6036
1867.75	14.7356
1868.76	17.5879
1869.76	16.6336
1870.76	18.5325
1871.76	16.6236
1872.77	14.7146
1873.77	13.7589
1874.77	18.4846
1875.77	15.6163
1876.77	17.4876
1877.77	14.6998
1878.78	16.5748
1879.78	14.6754
1880.78	15.6199
1881.78	16.5334
1882.78	15.5676
1883.78	15.552
1884.78	18.3963
1885.78	14.6375
1886.78	17.4592
1887.78	13.67
1888.77	17.4177
1889.77	15.5336
1890.77	15.5405
1891.77	16.4791
1892.77	12.7018
1893.77	17.3891
1894.76	14.562
1895.76	15.5086
1896.76	13.6379
1897.76	19.2822
1898.75	15.5075
1899.75	13.6209
1900.75	14.565
1901.75	20.2208
1902.74	16.4584
1903.74	15.5134
1904.74	15.5112
1905.73	17.3789
1906.73	11.7378
1907.72	17.3795
1908.72	13.6276
1909.71	13.643
1910.71	15.5408
1911.7	15.5415
1912.7	15.5406
1913.69	16.4966
1914.69	13.6803
1915.68	13.6812
1916.68	18.3882
1917.67	16.4984
1918.66	15.571
1919.66	11.8113
1920.65	17.4858
1921.64	15.6053
1922.64	19.3809
1923.63	18.428
1924.62	16.5338
1925.61	17.4956
1926.61	16.5676
1927.6	11.8404
1928.59	15.6365
1929.58	17.5492
1930.57	18.5141
1931.57	16.6098
1932.56	17.5511
1933.55	16.6157
1934.54	13.8113
1935.53	13.8193
1936.52	18.5771
1937.51	13.8023
1938.5	18.5675
1939.49	15.721
1940.48	16.6952
1941.47	14.7836
1942.46	15.755
1943.45	17.6445
1944.44	18.623
1945.42	16.7293
1946.41	16.7377
1947.4	15.7777
1948.39	16.7338
1949.38	16.7486
1950.37	14.8572
1951.35	15.8393
1952.34	13.9261
1953.33	14.8819
1954.32	15.8085
1955.3	15.8134
1956.29	17.761
1957.28	15.854
1958.26	16.8209
1959.25	15.8532
1960.23	15.8433
1961.22	16.7938
1962.21	16.7971
1963.19	15.8399
1964.18	17.7647
1965.16	13.9232
1966.15	16.8167
1967.13	14.8989
1968.12	16.8238
1969.1	17.77
1970.09	16.7946
1971.07	15.8266
1972.05	11.992
1973.04	17.7392
1974.02	15.8151
1975.01	14.8609
1975.99	16.7862
1976.97	14.8669
1977.95	19.6517
1978.94	14.857
1979.92	17.7318
1980.9	15.8059
1981.88	12.9292
1982.87	16.7455
1983.85	15.7815
1984.83	17.6833
1985.81	13.8694
1986.79	16.71
1987.77	13.9329
1988.75	14.0038
1989.73	17.5728
1990.72	14.9899
1991.7	16.4221
1992.68	16.3458
1993.66	15.7554
1994.63	15.9193
1995.61	16.0745
1996.59	17.0929
1997.57	15.2472
1998.55	15.4431
1999.53	15.8693
2000.51	15.3168
2001.49	16.0691
2002.47	15.2464
2003.45	15.5627
2004.42	15.6372
2005.4	14.9448
2006.38	18.3107
2007.36	17.149
2008.31	16.5146
2009.3	15.5534
2010.29	16.4828
2011.28	13.6557
2012.27	16.4765
2013.26	14.5733
2014.24	15.4857
2015.23	11.7352
2016.22	12.6874
2017.21	14.5611
2018.2	16.4154
2019.18	14.5206
2020.17	14.5166
2021.16	17.3281
2022.15	13.5746
2023.14	17.3025
2024.12	13.548
2025.11	13.5306
2026.1	15.397
2027.08	15.4392
2028.07	15.3781
2029.06	16.3834
2030.04	18.1842
2031.03	13.5292
2032.01	12.6055
2033	14.49
2033.98	16.3428
2034.97	17.2731
2035.95	16.3653
2036.94	14.4932
2037.92	15.4216
2038.91	13.5434
2039.89	13.5303
2040.87	14.4508
2041.86	16.3092
2042.84	16.3066
2043.83	14.4612
2044.81	15.3658
2045.79	14.5081
2046.78	15.4013
2047.76	13.5174
2048.74	16.3226
2049.72	16.342
2050.71	13.5455
2051.69	16.3411
2052.67	15.4151
2053.65	12.6268
2054.63	14.4985
2055.62	15.4266
2056.6	16.3575
2057.58	13.5593
2058.56	12.6353
2059.54	14.5109
2060.52	14.5079
2061.5	16.385
2062.48	15.455
2063.46	19.2132
2064.44	18.2845
2065.42	13.6112
2066.4	16.4356
2067.38	14.5648
2068.36	16.4522
2069.34	15.497
2070.31	11.7524
2071.29	15.5367
2072.27	15.5363
2073.25	14.5937
2074.23	15.5422
2075.21	15.5679
2076.18	15.5765
2077.16	13.6747
2078.14	17.4534
2079.12	11.8046
2080.09	17.4824
2081.07	13.6999
2082.05	17.4815
2083.02	17.4818
2084	13.7018
2084.98	16.5378
2085.95	13.7128
2086.93	17.5065
2087.9	16.5625
2088.88	15.6215
2089.85	16.578
2090.83	14.6895
2091.8	14.7048
2092.78	16.6224
2093.75	12.8345
2094.73	15.6852
2095.7	14.7259
2096.68	17.5708
2097.65	14.7141
2098.62	15.6601
2099.6	16.6077
2100.57	17.5652
2101.54	14.7222
2102.52	11.8696
2103.49	15.6623
2104.46	16.619
2105.44	15.6812
2106.41	14.7355
2107.38	14.7324
2108.35	16.6167
2109.32	19.4743
2110.3	16.6247
2111.27	12.8218
2112.24	15.671
2113.21	14.7315
2114.18	14.7303
2115.15	15.6795
2116.12	15.6706
2117.09	11.8705
2118.06	13.7596
2119.03	17.5389
2120	15.6342
2120.97	15.6431
2121.94	17.5546
2122.91	16.6138
2123.88	17.5568
2124.85	15.6337
2125.82	19.4007
2126.79	16.5478
2127.76	15.5975
2128.72	15.5962
2129.69	16.5376
2130.66	15.5869
2131.63	18.4111
2132.6	15.5695
2133.56	15.571
2134.53	15.5714
2135.5	14.6222
2136.47	14.6126
2137.43	16.505
2138.4	14.6133
2139.37	14.6075
2140.33	15.5414
2141.3	17.4188
2142.26	13.6521
2143.23	14.5585
2144.19	14.5785
2145.16	14.5744
2146.13	19.2697
2147.09	16.4422
2148.06	17.3737
2149.02	14.5452
2149.98	17.3415
2150.95	16.4069
2151.91	15.4763
2152.88	12.6545
2153.84	15.4569
2154.8	14.4965
2155.77	17.2842
2156.73	13.5452
2157.69	12.6183
2158.66	16.3552
2159.62	16.3428
2160.58	16.3305
2161.54	12.5944
2162.51	15.3914
2163.47	14.452
2164.43	16.3044
2165.39	17.2395
2166.35	13.5068
2167.32	15.3559
2168.28	16.2691
2169.24	16.281
2170.2	14.4351
2171.16	15.3534
2172.12	15.3323
2173.08	16.2589
2174.04	14.4057
2175	16.2632
2175.96	16.2592
2176.92	15.3277
2177.88	14.3974
2178.84	17.1769
2179.8	17.1773
2180.76	17.1741
2181.72	16.24
2182.68	12.5215
2183.63	15.2905
2184.59	15.2902
2185.55	14.3704
2186.51	16.2405
2187.47	12.5388
2188.43	12.5299
2189.38	17.1516
2190.34	16.2243
2191.3	16.228
2192.25	15.3063
2193.21	17.1749
2194.17	16.2697
2195.12	14.4037
2196.08	13.4585
2197.04	19.0136
2197.99	17.1664
2198.95	16.2582
2199.9	17.2173
2200.86	14.4456
2201.81	15.2978
2202.77	16.2743
2203.72	16.318
2204.68	15.3617
2205.63	15.3409
2206.59	15.3403
2207.54	11.6306
2208.49	11.6394
2209.45	14.435
2210.4	16.306
2211.36	15.3856
2212.31	15.391
2213.26	19.1124
2214.22	14.4667
2215.17	15.405
2216.12	17.2722
2217.07	16.3383
2218.03	17.2736
2218.98	14.4818
2219.93	11.6824
2220.88	15.4142
2221.83	16.3358
2222.78	15.4083
2223.74	15.4247
2224.69	15.44
2225.64	15.4554
2226.59	15.4679
2227.54	15.4729
2228.49	13.594
2229.44	15.4758
2230.39	15.4888
2231.34	15.5029
2232.29	13.6348
2233.24	15.5275
2234.19	15.5292
2235.14	15.5152
2236.09	16.4593
2237.04	16.4691
2237.98	15.5512
2238.93	13.6799
2239.88	17.4408
2240.83	16.5114
2241.78	14.6292
2242.73	17.4646
2243.67	18.4019
2244.62	15.5859
2245.57	15.6018
2246.52	15.612
2247.46	16.563
2248.41	14.667
2249.36	14.6705
2250.3	16.5545
2251.25	13.7086
2252.2	17.5001
2253.14	14.6855
2254.09	17.5413
2255.03	16.5929
2255.98	12.8065
2256.92	14.7141
2257.87	13.7701
2258.81	15.6772
2259.76	17.5849
2260.7	15.6952
2261.65	14.75
2262.59	17.6173
2263.54	15.7343
2264.48	17.6641
2265.42	16.717
2266.37	15.7495
2267.31	17.6467
2268.26	13.8262
2269.2	16.7027
2270.14	17.6779
2271.08	14.8214
2272.03	14.8285
2272.97	17.7028
2273.91	15.7928
2274.85	15.797
2275.79	16.7622
2276.74	14.8605
2277.68	14.8835
2278.62	14.8867
2279.56	16.7909
2280.5	14.86
2281.44	13.8989
2282.38	14.8678
2283.32	16.8103
2284.26	15.8704
2285.2	16.8417
2286.14	15.8712
2287.08	14.9274
2288.02	14.9299
2288.96	15.8772
2289.9	21.63
2290.84	15.87
2291.78	15.8847
2292.72	17.8254
2293.66	14.9386
2294.6	16.8562
2295.54	16.8475
2296.47	13.9514
2297.41	14.9268
2298.35	18.7963
2299.29	14.952
2300.23	15.9187
2301.16	15.9267
2302.1	16.8895
2303.04	16.8887
2303.97	14.0003
2304.91	15.9407
2305.85	15.9473
2306.78	15.9479
2307.72	14.9758
2308.65	15.9445
2309.59	17.8948
2310.53	15.9601
2311.46	16.8968
2312.4	15.9206
2313.33	14.9685
2314.27	16.9223
2315.2	14.0208
2316.14	17.8656
2317.07	15.934
2318	17.8645
2318.94	14.9586
2319.87	14.9569
2320.81	16.8943
2321.74	19.8111
2322.67	18.8517
2323.61	17.8895
2324.54	18.8441
2325.47	22.6876
2326.41	28.4561
2327.34	80.4851
2328.27	85.3045
2329.2	26.4871
2330.13	22.6333
2331.07	18.7831
2332	18.7818
2332.93	15.8839
2333.86	15.8759
2334.79	16.8292
2335.72	16.8298
2336.66	16.8258
2337.59	14.8993
2338.52	17.782
2339.45	15.8582
2340.38	18.7287
2341.31	14.868
2342.24	16.7766
2343.17	13.8992
2344.1	14.8593
2345.02	17.7288
2345.95	13.886
2346.88	15.7972
2347.81	15.8187
2348.74	19.4182
2349.67	16.429
2350.6	16.4975
2351.53	15.3878
2352.45	14.5526
2353.38	15.7501
2354.31	16.348
2355.24	16.1242
2356.17	14.7794
2357.09	15.3282
2358.02	15.5426
2358.95	16.067
2359.87	13.5533
2360.8	14.3368
2361.73	15.3364
2362.65	13.2542
2363.58	14.0762
2364.5	14.8229
2365.43	14.1321
2366.36	15.508
2367.28	16.6914
2368.2	15.2713
2368.98	16.5158
2369.92	13.6713
2370.86	17.429
2371.79	15.5366
2372.73	16.4686
2373.67	15.5198
2374.6	15.5088
2375.54	17.3781
2376.48	16.4302
2377.41	14.546
2378.35	14.5349
2379.28	16.3913
2380.22	16.3831
2381.15	15.4451
2382.09	16.3799
2383.02	13.5685
2383.96	16.3747
2384.89	16.3694
2385.83	15.4201
2386.76	13.5354
2387.69	13.5264
2388.63	14.4568
2389.56	13.5211
2390.5	16.3198
2391.43	14.4564
2392.36	16.3158
2393.3	15.36
2394.23	13.4875
2395.16	15.3531
2396.09	16.3303
2397.02	16.3211
2397.96	16.3209
2398.89	17.2521
2399.82	15.3882