File: Data/3-Raman/raw/bu19(2)w-a-ff2-fi05-v_150 (500nm)_532nm_edge_100%_x100_vis_lwd_h50um_30sx2_01.txt
#Acq. time (s)=	30
#Accumulations=	2
#Range (cm-¹)=	99...4000
#Windows=	1
#Auto scanning=	Off
#Autofocus=	Off
#Macrospot=	Off
#AutoExposure=	Off
#Spike filter=	Multiple accum.
#Delay time (s)=	2
#Binning=	1
#Readout mode=	Signal
#DeNoise=	Off
#ICS correction=	On
#Dark correction=	Off
#Inst. Process=	Off
#Detector Gain=	Best Dynamic
#Detector ADC=	50 kHz HS
#Detector temperature (°C)=	-60.09
#Instrument=	LabRAM HR Evol
#Detector=	SIN-EM FIVIS
#Objective=	x50_VIS_LWD
#Grating=	150 (500nm)
#ND Filter=	100%
#Laser=	532nm_Edge
#Hole=	49.98
#Temperature=	0
#Range=	Visible
#StageXY=	75x50mm Scan+
#StageZ=	Z motor
#X (µm)=	0
#Y (µm)=	0
#Z (µm)=	-51.2
#Full time(mm:ss)=	1:04
#Project=	21_11_26
#Sample=	BU19(2)w
#Site=
#Title=	BU19(2)w-A-FF2-FI05-V_150 (500nm)_532nm_Edge_100%_x50_VIS_LWD_H50um_30sX2
#Remark=
#Date=	26.11.2021 15:07
#Acquired=	26.11.2021 15:07:46
102.91	6521.94
107.534	6672.85
112.156	6399.25
116.775	5573.51
121.392	4607.37
126.005	4012.54
130.617	3967.36
135.227	4420.37
139.835	5853.99
144.439	8078.22
149.042	8841.57
153.643	6901.77
158.242	4709.82
162.839	3319.66
167.431	2556.1
172.023	2153.46
176.613	1909.34
181.198	1719.42
185.783	1588.41
190.366	1508.86
194.947	1503.98
199.524	1672.82
204.1	2208.58
208.674	3262.76
213.243	3058.29
217.813	1855.91
222.38	1481.59
226.945	1675.77
231.506	2568.6
236.066	3240.52
240.625	2320.44
245.179	1393.88
249.732	1091.6
254.284	972.445
258.831	924.081
263.378	904.988
267.923	851.947
272.464	871.82
277.004	952.335
281.54	1060.84
286.076	938.381
290.61	846.871
295.139	834.565
299.669	798.024
304.196	845.398
308.718	846.273
313.241	909.996
317.759	956.468
322.278	1055.05
326.794	1249.24
331.305	1549.03
335.817	1702.35
340.324	1533.9
344.832	1509.32
349.334	1884.61
353.837	2082.78
358.338	1657.44
362.834	1234.81
367.33	1123.47
371.822	1139.93
376.314	1177.29
380.802	1353.53
385.289	1747.08
389.772	2575.59
394.255	3310.19
398.734	3204.56
403.213	2806.69
407.688	2553.07
412.162	2162.03
416.632	1992.44
421.102	2104.11
425.568	2262.23
430.033	2387.12
434.495	2381.57
438.956	2262.13
443.413	2234.04
447.87	2439.82
452.323	2490.77
456.776	2313.86
461.224	1828.94
465.673	1461.97
470.117	1303.13
474.561	1215.55
479.001	1226.9
483.438	1329.23
487.876	1500.53
492.309	1830.19
496.742	2257.73
501.172	2951.3
505.601	3741.34
510.025	4295.33
514.448	4332.2
518.871	3823.55
523.289	3324.41
527.707	2973.97
532.121	2814.7
536.533	2819.04
540.945	2818.85
545.353	2928.63
549.758	2983.02
554.164	2831.61
558.565	2589.09
562.965	2264.52
567.364	1944.45
571.759	1677.65
576.151	1567.61
580.544	1459.82
584.933	1473.22
589.319	1537.75
593.706	1684.73
598.088	1957.25
602.468	2281.26
606.848	2793.55
611.224	3881.6
615.598	6109.11
619.972	8808.22
624.341	8124.09
628.709	5224.73
633.074	3186.21
637.44	2256.18
641.801	1779.4
646.16	1481.25
650.517	1288.88
654.874	1166.83
659.227	1045.06
663.578	995.028
667.927	950.557
672.275	910.657
676.62	906.754
680.962	870.251
685.302	872.994
689.643	881.212
693.979	936.556
698.313	1044.65
702.645	1113.07
706.975	1094.1
711.305	1009.79
715.631	978.652
719.955	942.022
724.276	903.707
728.596	956.2
732.913	853.732
737.231	780.178
741.544	807.988
745.856	794.116
750.165	807.124
754.472	786.3
758.778	788.305
763.081	771.246
767.384	795.195
771.683	822.555
775.98	822.985
780.275	795.388
784.568	812.451
788.859	813.541
793.147	871.142
797.434	872.957
801.719	859.789
806.004	875.895
810.284	874.732
814.563	919.9
818.839	958.638
823.114	1035.9
827.386	1126.71
831.657	1293.75
835.925	1408.11
840.192	1611.83
844.456	1770.33
848.719	1739.58
852.979	1669.19
857.237	1529.44
861.493	1429.45
865.748	1352.45
870	1287.23
874.25	1327.31
878.499	1394.36
882.745	1437.87
886.989	1267.61
891.231	1112.68
895.471	1021.19
899.71	918.907
903.946	893.601
908.18	891.987
912.412	867.622
916.642	849.272
920.87	885.849
925.096	844.376
929.321	868.171
933.543	836.03
937.763	856.435
941.981	833.701
946.197	867.59
950.412	812.745
954.622	877.659
958.832	862.663
963.04	853.134
967.246	877.701
971.451	876.87
975.653	879.401
979.853	878.861
984.052	935.686
988.248	971.269
992.442	1047.12
996.633	1114.22
1000.82	1203.31
1005.01	1171.91
1009.2	1125.72
1013.38	1078.37
1017.57	1025.29
1021.75	1027.52
1025.92	1024.19
1030.1	1071.74
1034.27	1123.24
1038.45	1236.52
1042.62	1373.3
1046.78	1519.18
1050.95	1538.71
1055.12	1411.5
1059.28	1453.65
1063.44	1522.55
1067.6	1594.83
1071.75	1779.69
1075.91	2032.19
1080.06	2452.79
1084.21	3204.07
1088.36	4238.08
1092.51	5634.38
1096.65	6352.79
1100.8	5336.13
1104.94	3753.7
1109.08	2585.05
1113.21	1970.34
1117.35	1704.09
1121.48	1605.6
1125.61	1587.18
1129.74	1591.78
1133.87	1770.95
1137.99	1978.97
1142.12	2329.27
1146.24	2454.8
1150.36	2331.63
1154.48	1923.13
1158.59	1605.15
1162.71	1410.43
1166.82	1238.96
1170.93	1140.5
1175.04	1088.14
1179.14	1002.7
1183.25	967.805
1187.35	924.459
1191.45	889.942
1195.55	897.259
1199.65	934.878
1203.74	907.891
1207.83	927.691
1211.92	902.851
1216.01	930.713
1220.1	968.589
1224.19	981.291
1228.27	995.152
1232.35	1055.36
1236.43	1082.22
1240.51	1110.67
1244.58	1373.51
1248.66	1944.05
1252.73	1589.03
1256.8	1338.02
1260.87	1461.78
1264.93	3756.53
1269	11132.3
1273.06	5195.77
1277.12	1732.53
1281.18	1266.28
1285.23	1172.93
1289.29	1136.56
1293.34	1152.37
1297.39	1083.4
1301.44	1069.69
1305.49	1030.57
1309.53	1053.86
1313.58	1080.06
1317.62	1037.34
1321.66	1053.85
1325.7	1075.98
1329.73	1077.81
1333.77	1075.51
1337.8	1111.94
1341.83	1106.04
1345.86	1144.98
1349.88	1234.58
1353.91	1503.98
1357.93	1470.54
1361.95	1501.53
1365.97	1979.08
1369.99	9584
1374	16767.4
1378.02	5157.01
1382.03	1702.63
1386.04	1397.58
1390.05	1651.14
1394.05	2393.28
1398.06	1684.31
1402.06	1140.17
1406.06	1058.73
1410.06	1029.59
1414.05	1011.37
1418.05	936.907
1422.04	938.368
1426.03	868.597
1430.02	864.531
1434.01	845.725
1438	859.489
1441.98	830.808
1445.96	793.124
1449.94	808.697
1453.92	812.284
1457.9	787.196
1461.87	804.357
1465.85	816.311
1469.82	782.967
1473.78	799.888
1477.75	773.503
1481.72	781.371
1485.68	765.68
1489.65	767.563
1493.61	777.307
1497.56	766.576
1501.52	796.839
1505.47	759.096
1509.43	775.085
1513.38	794.023
1517.33	790.655
1521.27	792.23
1525.22	767.67
1529.16	772.274
1533.11	787.638
1537.05	790.416
1540.98	792.249
1544.92	768.891
1548.86	751.356
1552.79	795.825
1556.72	784.008
1560.65	778.855
1564.58	792.972
1568.5	813.761
1572.43	817.068
1576.35	798.145
1580.27	791.762
1584.19	795.009
1588.1	803.971
1592.02	814.821
1595.93	809.288
1599.84	824.905
1603.75	845.365
1607.66	821.79
1611.57	828.952
1615.47	843.832
1619.37	825.287
1623.27	848.84
1627.17	861.021
1631.07	829.287
1634.97	834.195
1638.86	833.32
1642.75	809.679
1646.64	821.641
1650.53	826.028
1654.42	818.949
1658.3	819.47
1662.18	822.841
1666.07	810.678
1669.94	808.992
1673.82	827.24
1677.7	805.061
1681.57	813.208
1685.44	802.895
1689.31	830.887
1693.18	809.8
1697.05	786.735
1700.92	811.357
1704.78	803.309
1708.64	805.586
1712.5	786.793
1716.36	799.356
1720.21	806.227
1724.07	802.708
1727.92	810.436
1731.77	830.213
1735.62	789.022
1739.47	785.343
1743.32	809.581
1747.16	785.333
1751.01	841.594
1754.85	822.807
1758.69	825.862
1762.52	795.943
1766.36	817.418
1770.19	813.206
1774.02	782.421
1777.85	831.645
1781.68	796.452
1785.51	796.763
1789.33	786.876
1793.16	786.361
1796.98	809.32
1800.8	786.264
1804.62	798.394
1808.43	792.585
1812.25	782.901
1816.06	789.099
1819.87	784.576
1823.68	789.281
1827.49	788.177
1831.3	818.916
1835.1	795.697
1838.9	808.154
1842.71	804.473
1846.51	800.61
1850.3	809.989
1854.1	815.216
1857.89	788.433
1861.69	770.835
1865.48	800.683
1869.27	785.912
1873.05	790.745
1876.84	783.701
1880.62	804.432
1884.4	819.907
1888.19	777.382
1891.96	812.203
1895.74	801.95
1899.52	818.381
1903.29	794.678
1907.06	790.449
1910.83	778.004
1914.6	810.09
1918.37	791.528
1922.13	790.993
1925.9	796.091
1929.66	818.98
1933.42	793.68
1937.18	813.913
1940.94	785.649
1944.69	816.185
1948.44	824.342
1952.2	830.93
1955.95	834.374
1959.69	796.057
1963.44	847.629
1967.19	842.797
1970.93	827.376
1974.67	857.619
1978.41	875.451
1982.15	882.798
1985.89	870.348
1989.62	902.613
1993.35	910.413
1997.09	885.464
2000.82	891.057
2004.55	898.519
2008.27	874.439
2012	877.902
2015.72	860.231
2019.44	865.993
2023.16	842.868
2026.88	863.357
2030.6	868.297
2034.31	839.782
2038.03	818.888
2041.74	809.814
2045.45	851.031
2049.16	853.812
2052.86	811.888
2056.57	846.943
2060.27	798.124
2063.98	817.64
2067.67	793.27
2071.37	835.219
2075.07	832.1
2078.77	818.859
2082.46	808.406
2086.15	829.366
2089.84	824.315
2093.53	811.445
2097.22	821.264
2100.9	812.349
2104.59	831.053
2108.27	806.828
2111.95	808.52
2115.63	825.989
2119.31	809.886
2122.98	802.763
2126.66	819.597
2130.33	801.053
2134	820.422
2137.67	811.957
2141.34	814.451
2145	820.495
2148.67	817.265
2152.33	804.848
2155.99	821.839
2159.65	795.789
2163.31	798.247
2166.96	798.088
2170.62	799.893
2174.27	821.156
2177.92	819.817
2181.57	815.859
2185.22	782.76
2188.87	814.464
2192.51	789.177
2196.15	809.71
2199.8	817.7
2203.44	802.086
2207.07	769.219
2210.71	767.486
2214.35	793.323
2217.98	800.939
2221.61	812.271
2225.24	794.248
2228.87	786.246
2232.5	814.221
2236.12	798.92
2239.75	788.173
2243.37	769.955
2246.99	786.932
2250.61	780.749
2254.23	771.836
2257.85	772.294
2261.46	791.434
2265.07	772.147
2268.68	787.584
2272.29	770.358
2275.9	819.713
2279.51	802.982
2283.11	764.917
2286.72	802.334
2290.32	784.03
2293.92	782.617
2297.52	781.226
2301.11	801.643
2304.71	839
2308.3	833.559
2311.9	1036.54
2315.49	1865
2319.08	1287.5
2322.66	861.616
2326.25	820.992
2329.84	806.84
2333.42	789.784
2337	799.069
2340.58	778.092
2344.16	786.236
2347.73	789.557
2351.31	805.921
2354.88	791.333
2358.45	771.153
2362.03	820.837
2365.59	793.175
2369.16	797.21
2372.73	826.426
2376.29	779.681
2379.85	806.014
2383.41	805.645
2386.97	798.916
2390.53	775.806
2394.09	764.838
2397.64	785.294
2401.2	784.913
2404.75	788.63
2408.3	786.947
2411.85	788.349
2415.39	767.911
2418.94	782.54
2422.48	792.726
2426.03	762.581
2429.57	774.072
2433.11	780.211
2436.64	766.152
2440.18	781.839
2443.72	784.621
2447.25	784.632
2450.78	742.687
2454.31	771.034
2457.84	767.977
2461.37	759.526
2464.89	783.039
2468.42	738.959
2471.94	795.501
2475.46	782.811
2478.98	768.123
2482.5	780.914
2486.01	760.433
2489.53	775.26
2493.04	797.984
2496.55	783.628
2500.06	792.066
2503.57	782.446
2507.08	759.65
2510.58	756.34
2514.09	752.164
2517.59	775.12
2521.09	796.288
2524.59	780.731
2528.09	763.23
2531.59	768.13
2535.08	751.903
2538.58	786.669
2542.07	755.17
2545.56	778.483
2549.05	782.761
2552.54	759.354
2556.02	784.226
2559.51	761.355
2562.99	774.625
2566.47	738.988
2569.95	764.959
2573.43	755.736
2576.91	767.23
2580.38	768.594
2583.85	753.035
2587.33	756.294
2590.8	747.992
2594.27	744.007
2597.74	771.32
2601.2	771.286
2604.67	813.305
2608.13	755.277
2611.59	764.61
2615.06	782.065
2618.51	767.163
2621.97	753.847
2625.43	736.535
2628.88	751.689
2632.33	759.026
2635.79	767.125
2639.24	754.852
2642.69	774.06
2646.13	758.646
2649.58	768.046
2653.02	791.532
2656.47	769.066
2659.91	754.125
2663.35	756.211
2666.79	732.704
2670.22	756.418
2673.66	760.229
2677.09	744.444
2680.52	779.395
2683.95	748.967
2687.39	765.559
2690.81	729.471
2694.24	768.233
2697.66	755.576
2701.09	752.414
2704.51	739.978
2707.93	746.177
2711.35	764.064
2714.77	739.318
2718.18	757.526
2721.6	739.562
2725.01	741.251
2728.42	763.553
2731.84	763.507
2735.24	753.12
2738.65	758.641
2742.06	761.323
2745.46	750.713
2748.86	730.582
2752.27	763.09
2755.67	746.647
2759.07	724.451
2762.46	729.561
2765.86	733.538
2769.25	731.748
2772.65	763.758
2776.04	730.683
2779.43	745.535
2782.82	756.504
2786.2	763.64
2789.59	767.921
2792.98	772.167
2796.36	742.567
2799.74	770.267
2803.12	755.591
2806.5	758.755
2809.88	744.101
2813.25	744.401
2816.63	728.762
2820	756.103
2823.37	751.782
2826.74	759.696
2830.11	745.286
2833.48	758.013
2836.84	785.778
2840.21	768.957
2843.57	731.791
2846.93	766.543
2850.29	743.786
2853.65	765.041
2857.01	743.263
2860.36	742.122
2863.72	724.215
2867.07	754.102
2870.42	738.079
2873.77	768.004
2877.12	757.527
2880.47	734.771
2883.81	736.442
2887.16	748.431
2890.5	764.2
2893.84	757.275
2897.18	715.177
2900.52	758.999
2903.86	739.347
2907.19	736.626
2910.53	756.551
2913.86	744.247
2917.19	763.117
2920.52	748.756
2923.85	773.136
2927.18	749.215
2930.51	771.506
2933.83	770.073
2937.15	756.26
2940.48	762.266
2943.8	756.961
2947.11	777.105
2950.43	772.785
2953.75	756.222
2957.06	769.766
2960.38	750.563
2963.69	783.993
2967	788.366
2970.31	779.844
2973.62	734.883
2976.92	771.553
2980.23	798.982
2983.53	782.22
2986.84	767.378
2990.14	794.826
2993.44	804.472
2996.73	790.679
3000.03	810.756
3003.33	791.343
3006.62	794.495
3009.91	818.422
3013.2	807.571
3016.49	761.859
3019.78	786.788
3023.07	812.674
3026.35	827.265
3029.64	819.22
3032.92	820.598
3036.2	830.443
3039.48	837.437
3042.76	819.844
3046.04	828.755
3049.32	847.152
3052.59	879.779
3055.86	904.878
3059.14	876.85
3062.41	841.883
3065.68	852.572
3068.94	907.766
3072.21	879.258
3075.48	907.85
3078.74	906.048
3082	893.524
3085.26	919.705
3088.52	928.785
3091.78	945.734
3095.04	919.982
3098.29	953.876
3101.55	948.445
3104.8	992.279
3108.05	952.877
3111.3	1016.1
3114.55	1002.87
3117.8	974.5
3121.04	1038.52
3124.29	1026.36
3127.53	1027.51
3130.77	1038.16
3134.02	1057.41
3137.25	1068.06
3140.49	1094.86
3143.73	1099.72
3146.96	1125.56
3150.2	1124.78
3153.43	1148.82
3156.66	1169.96
3159.89	1172.06
3163.12	1185.56
3166.35	1190.49
3169.57	1257.33
3172.8	1260.15
3176.02	1286.77
3179.24	1279.88
3182.46	1262.48
3185.68	1326.18
3188.9	1320.1
3192.12	1294.92
3195.33	1317.4
3198.55	1345.56
3201.76	1368.91
3204.97	1385.64
3208.18	1399.56
3211.39	1402.11
3214.6	1454.24
3217.8	1434.15
3221.01	1447.36
3224.21	1457.76
3227.41	1453.09
3230.61	1475.1
3233.81	1521.95
3237.01	1493.55
3240.21	1506.39
3243.4	1508.84
3246.59	1564.73
3249.79	1531.08
3252.98	1541.42
3256.17	1583.29
3259.36	1591.76
3262.54	1606.7
3265.73	1533.54
3268.92	1612.03
3272.1	1646.42
3275.28	1614.8
3278.46	1654.8
3281.64	1645.74
3284.82	1667.88
3288	1711.98
3291.17	1689.15
3294.35	1748.44
3297.52	1744.74
3300.69	1762.97
3303.86	1773.98
3307.03	1774.05
3310.2	1792.96
3313.36	1847.68
3316.53	1836.69
3319.69	1878.8
3322.85	1945.42
3326.02	1909.65
3329.18	1977.1
3332.33	2035.98
3335.49	2018.38
3338.65	2034.97
3341.8	2093.2
3344.95	2092.01
3348.11	2146.02
3351.26	2209.96
3354.41	2226.73
3357.56	2281.46
3360.7	2313.69
3363.85	2340.55
3366.99	2407.08
3370.13	2453.03
3373.28	2482.12
3376.42	2543.63
3379.56	2591.13
3382.69	2597.23
3385.83	2745.98
3388.97	2757.95
3392.1	2839.07
3395.23	2874.68
3398.36	2970.23
3401.49	3059
3404.62	3119.73
3407.75	3239.77
3410.88	3274.66
3414	3385.67
3417.13	3522.77
3420.25	3687.48
3423.37	3772.9
3426.49	3991.25
3429.61	4099.24
3432.73	4307.92
3435.84	4525.26
3438.96	4765.35
3442.07	5092.76
3445.18	5634.58
3448.29	6378.06
3451.4	7690.8
3454.51	9224.96
3457.62	10494.2
3460.72	10352.2
3463.83	9088.26
3466.93	7748.01
3470.03	6751.59
3473.13	6283.14
3476.23	5934.04
3479.33	5683.31
3482.43	5630.85
3485.53	5526.65
3488.62	5412.59
3491.71	5469.4
3494.81	5487.07
3497.9	5551.7
3500.99	5498.04
3504.07	5469.05
3507.16	5606
3510.25	5674.02
3513.33	5711
3516.41	5840.29
3519.5	6169.97
3522.58	6427.42
3525.66	6713.56
3528.73	7071.47
3531.81	7478.49
3534.89	7707.55
3537.96	8006.52
3541.03	7946.54
3544.11	7675.66
3547.18	7072.98
3550.25	6311.32
3553.32	5550.86
3556.38	4809.96
3559.45	4260.25
3562.51	3768.59
3565.58	3242.47
3568.64	2989.36
3571.7	2666.82
3574.76	2502.09
3577.82	2301.4
3580.87	2173.5
3583.93	2055.85
3586.98	1953.2
3590.04	1837.28
3593.09	1772.37
3596.14	1723.55
3599.19	1664.19
3602.24	1605.82
3605.29	1591.81
3608.33	1481.19
3611.38	1464.29
3614.42	1437.88
3617.46	1467.17
3620.5	1438.92
3623.54	1355.1
3626.58	1383.62
3629.62	1310.41
3632.65	1302.19
3635.69	1267.56
3638.72	1233.27
3641.76	1169.06
3644.79	1132.28
3647.82	1110.85
3650.84	1101.34
3653.87	1046.81
3656.9	1013.58
3659.92	996.71
3662.95	903.441
3665.97	934.227
3668.99	915.603
3672.01	870.779
3675.03	873.123
3678.05	856.641
3681.07	850.578
3684.08	814.216
3687.1	806.192
3690.11	782.097
3693.12	766.516
3696.13	765.133
3699.14	745.587
3702.15	760.33
3705.16	771.297
3708.16	721.473
3711.17	712.371
3714.17	689.892
3717.17	700.601
3720.17	698.045
3723.17	684.928
3726.17	658.415
3729.17	672.781
3732.16	660.437
3735.16	652.788
3738.15	647.924
3741.14	672.513
3744.13	647.524
3747.13	661.497
3750.11	648.774
3753.1	638.866
3756.09	629.912
3759.07	627.625
3762.06	631.961
3765.04	603.076
3768.02	617.801
3771	637.285
3773.98	613.303
3776.96	597.898
3779.94	578.761
3782.91	607.851
3785.89	582.162
3788.86	591.451
3791.83	593.223
3794.8	587.538
3797.77	589.452
3800.74	582.907
3803.71	574.55
3806.68	575.662
3809.64	564.511
3812.61	585.522
3815.57	569.688
3818.53	568.991
3821.49	571.156
3824.45	532.623
3827.41	591.671
3830.36	580.644
3833.32	546.835
3836.27	565.242
3839.23	544.759
3842.18	545.158
3845.13	547.457
3848.08	561.195
3851.03	577.836
3853.98	562.117
3856.92	543.519
3859.87	558.329
3862.81	568.389
3865.75	553.554
3868.7	553.058
3871.64	544.848
3874.57	572.096
3877.51	582.082
3880.45	549.76
3883.39	541.365
3886.32	539.625
3889.25	550.34
3892.18	540.846
3895.12	554.4
3898.05	576.541
3900.97	554.38
3903.9	568.745
3906.83	554.196
3909.75	562.787
3912.68	538.646
3915.6	529.837
3918.52	528.682
3921.44	562.188
3924.36	533.175
3927.28	547.297
3930.2	540.258
3933.11	523.623
3936.03	520.539
3938.94	538.632
3941.86	541.497
3944.77	532.822
3947.68	539.496
3950.59	503.14
3953.49	513.735
3956.4	525.313
3959.31	515.868
3962.21	521.774
3965.12	522.916
3968.02	529.844
3970.92	526.25
3973.82	509.23
3976.72	523.872
3979.61	521.199
3982.51	530.983
3985.41	525.382
3988.3	518.789
3991.19	518.909
3994.09	521.853
3996.98	544.139
3999.87	520.23