File: Data/3-Raman/raw/bu19w-e-ff11-fi07-l_150 (500nm)_633nm_edge_100%_x100_vis_h50um_60sx2_01.txt
#Acq. time (s)=	60
#Accumulations=	2
#Range (cm-¹)=	100...4000
#Windows=	1
#Auto scanning=	Off
#Autofocus=	Off
#Macrospot=	Off
#AutoExposure=	Off
#Spike filter=	Multiple accum.
#Delay time (s)=	2
#Binning=	1
#Readout mode=	Signal
#DeNoise=	Off
#ICS correction=	On
#Dark correction=	Off
#Inst. Process=	Off
#Detector Gain=	Best Dynamic
#Detector ADC=	50 kHz HS
#Detector temperature (°C)=	-60.09
#Instrument=	LabRAM HR Evol
#Detector=	SIN-EM FIVIS
#Objective=	x100_VIS
#Grating=	150 (500nm)
#ND Filter=	100%
#Laser=	633nm_Edge
#Hole=	49.98
#Temperature=	0
#Range=	Visible
#StageXY=	75x50mm Scan+
#StageZ=	Z motor
#X (µm)=	0
#Y (µm)=	0
#Z (µm)=	-268.8
#Full time(mm:ss)=	2:05
#Project=	21_11_04
#Sample=	BU19w
#Site=
#Title=	BU19w-E-FF11-FI07-L_150 (500nm)_633nm_Edge_100%_x100_VIS_H50um_60sX2
#Remark=
#Date=	04.11.2021 16:06
#Acquired=	04.11.2021 16:06:32
102.881	387.558
109.397	365.025
115.908	356.785
122.414	339.833
128.914	349.617
135.409	360.268
141.898	368.889
148.383	378.538
154.861	438.068
161.335	496.757
167.801	357.065
174.264	270.825
180.721	251.536
187.173	232.104
193.62	225.04
200.061	222.86
206.496	212.329
212.926	226.548
219.352	262.694
225.772	412.108
232.185	591.363
238.595	438.683
244.999	311.131
251.397	282.496
257.791	321.227
264.178	333.43
270.561	299.219
276.939	330.508
283.31	323.786
289.678	261.065
296.039	245.692
302.396	259.671
308.746	344.473
315.093	557.576
321.433	864.863
327.768	674.039
334.099	398.51
340.423	313.548
346.743	319.086
353.058	323.617
359.367	343.098
365.671	287.268
371.971	237.193
378.265	195.65
384.553	168.305
390.837	174.023
397.116	175.212
403.389	179.382
409.657	201.462
415.92	208.377
422.178	225.658
428.431	292.559
434.678	303.203
440.921	280.828
447.158	312.913
453.391	337.26
459.618	301.94
465.84	219.526
472.057	197.009
478.27	195.173
484.477	195.196
490.679	193.358
496.876	222.296
503.068	246.628
509.255	277.544
515.436	291.769
521.613	284.698
527.785	281.506
533.952	259.697
540.113	231.169
546.27	211.766
552.423	202.487
558.568	183.658
564.711	168.323
570.848	154.767
576.979	171.163
583.107	189.351
589.228	209.435
595.345	233.408
601.458	235.326
607.565	247.813
613.667	256.737
619.764	242.472
625.856	199.057
631.944	174.925
638.026	176.837
644.104	179.403
650.177	173.48
656.244	181.488
662.308	150.129
668.365	122.698
674.418	108.639
680.467	103.978
686.511	108.734
692.549	95.8563
698.582	108.257
704.611	103.781
710.635	100.161
716.655	94.4513
722.669	99.0944
728.679	88.6388
734.683	91.289
740.683	92.0611
746.678	94.7235
752.669	94.6395
758.654	97.4303
764.635	96.6868
770.611	94.1506
776.582	97.2326
782.549	93.6586
788.511	91.8918
794.466	94.786
800.419	90.9996
806.366	99.393
812.309	104.899
818.247	95.2913
824.18	103.492
830.108	97.6545
836.033	102.303
841.952	103.391
847.865	108.262
853.776	118.845
859.681	118.217
865.58	137.435
871.476	150.09
877.366	155.03
883.253	180.763
889.134	186.454
895.012	171.171
900.883	166.137
906.751	161.955
912.614	153.991
918.473	169.651
924.326	173.293
930.174	199.742
936.019	228.34
941.859	275.437
947.693	322.031
953.525	361.379
959.35	350.138
965.171	387.38
970.988	467.707
976.801	596.631
982.608	688.12
988.411	647.785
994.209	519.49
1000	427.052
1005.79	431.378
1011.58	425.744
1017.36	499.642
1023.13	457.344
1028.9	371.257
1034.67	319.433
1040.43	287.66
1046.19	258.594
1051.94	245.655
1057.69	210.169
1063.44	195.764
1069.17	197.635
1074.91	221.826
1080.64	268.191
1086.37	351.274
1092.09	484.719
1097.8	532.802
1103.52	426.129
1109.22	329.561
1114.93	280.805
1120.63	264.182
1126.32	257.943
1132.01	289.88
1137.7	361.165
1143.38	463.217
1149.06	587.884
1154.73	465.239
1160.4	280.966
1166.06	208.732
1171.72	173.046
1177.38	152.142
1183.03	142.132
1188.67	124.516
1194.31	100.167
1199.95	105.233
1205.58	96.7296
1211.21	80.3342
1216.84	82.6599
1222.46	83.0535
1228.07	81.4527
1233.68	83.8029
1239.29	80.0585
1244.89	85.2717
1250.49	80.3021
1256.08	84.3573
1261.67	81.2387
1267.26	76.0908
1272.84	84.0011
1278.42	77.7943
1283.99	72.6251
1289.56	72.5168
1295.12	77.4572
1300.68	78.4483
1306.23	70.5222
1311.78	77.7107
1317.33	76.9518
1322.87	69.1502
1328.41	76.5217
1333.94	75.8
1339.47	71.971
1345	69.0726
1350.52	75.3571
1356.04	70.3364
1361.55	77.5893
1367.06	83.7593
1372.56	84.7565
1378.06	83.6991
1383.56	75.4488
1389.05	79.5168
1394.53	75.4246
1400.02	75.5377
1405.5	71.5304
1410.97	77.8444
1416.44	73.8791
1421.91	77.1573
1427.37	72.162
1432.83	75.4729
1438.28	69.4015
1443.73	74.8051
1449.17	76.0097
1454.62	70.849
1460.05	70.88
1465.48	74.0237
1470.91	67.7041
1476.34	76.0977
1481.76	70.8788
1487.17	74.084
1492.59	73.1256
1497.99	81.6871
1503.4	78.691
1508.8	82.0653
1514.19	78.0536
1519.59	74.0462
1524.97	71.0955
1530.36	78.8538
1535.74	75.9175
1541.11	73.9706
1546.48	74.0869
1551.85	79.4993
1557.21	76.159
1562.57	78.241
1567.93	76.0045
1573.28	77.0016
1578.62	78.0415
1583.97	85.5855
1589.3	80.2359
1594.64	81.3833
1599.97	87.969
1605.3	82.7255
1610.62	86.1951
1615.94	89.757
1621.25	75.9055
1626.56	92.6383
1631.87	83.0762
1637.17	93.2491
1642.47	88.9483
1647.76	87.9776
1653.05	88.0781
1658.34	89.2423
1663.62	89.2698
1668.9	88.1687
1674.18	83.7341
1679.45	88.155
1684.71	93.6329
1689.98	82.4835
1695.23	88.0014
1700.49	87.0019
1705.74	84.0946
1710.99	77.5167
1716.23	92.0524
1721.47	85.6009
1726.7	85.7384
1731.94	82.5486
1737.16	82.7118
1742.39	76.1052
1747.61	87.535
1752.82	92.1718
1758.03	84.3274
1763.24	83.223
1768.44	79.8648
1773.64	90.1176
1778.84	90.2134
1784.03	85.8074
1789.22	87.1161
1794.41	93.0187
1799.59	93.256
1804.76	92.3668
1809.94	89.138
1815.11	95.0922
1820.27	90.6774
1825.43	81.6198
1830.59	85.2939
1835.74	86.6713
1840.89	84.5166
1846.04	90.5047
1851.18	88.3126
1856.32	94.2804
1861.45	90.9315
1866.58	81.714
1871.71	91.2823
1876.83	94.9433
1881.95	84.4298
1887.07	95.1495
1892.18	93.9891
1897.29	91.6374
1902.39	96.4675
1907.49	94.2824
1912.59	90.9798
1917.68	93.6618
1922.77	93.7668
1927.86	96.3446
1932.94	96.5289
1938.02	94.2871
1943.09	100.426
1948.16	101.734
1953.23	93.3619
1958.29	82.5483
1963.35	105.463
1968.41	98.2176
1973.46	98.1637
1978.51	100.518
1983.55	96.8515
1988.59	95.6057
1993.63	96.7778
1998.66	100.375
2003.69	108.811
2008.72	96.8423
2013.74	102.942
2018.76	111.446
2023.77	109.125
2028.78	109.269
2033.79	108.256
2038.79	104.828
2043.79	106.256
2048.79	105.273
2053.78	107.898
2058.77	108.121
2063.76	108.363
2068.74	111.059
2073.72	110.064
2078.69	110.284
2083.66	108.008
2088.63	120.513
2093.59	115.774
2098.55	119.762
2103.51	113.835
2108.46	102.915
2113.41	121.989
2118.36	122.369
2123.3	120.223
2128.24	119.307
2133.17	129.746
2138.11	124.975
2143.03	127.791
2147.96	129.304
2152.88	123.106
2157.79	116.854
2162.71	118.218
2167.62	114.421
2172.52	119.602
2177.43	115.845
2182.32	118.422
2187.22	115.846
2192.11	122.29
2197	122.378
2201.89	118.686
2206.77	111.175
2211.64	128.148
2216.52	116.826
2221.39	117.122
2226.26	120.016
2231.12	119.021
2235.98	112.802
2240.84	123.544
2245.69	123.861
2250.54	121.548
2255.39	120.529
2260.23	114.24
2265.07	117.145
2269.9	118.682
2274.74	109.553
2279.57	121.636
2284.39	116.383
2289.21	129.718
2294.03	120.432
2298.84	125.824
2303.66	117.952
2308.46	124.818
2313.27	121.064
2318.07	122.704
2322.87	139.143
2327.66	123.343
2332.45	123.699
2337.24	122.726
2342.02	125.847
2346.8	122.207
2351.58	128.115
2356.35	131.253
2361.12	126.04
2365.89	124.93
2370.65	141.798
2375.41	126.835
2380.17	129.838
2384.92	129.992
2389.67	127.312
2394.42	121.79
2399.16	121.788
2403.9	120.385
2408.64	113.436
2413.37	138.731
2418.1	130.989
2422.83	131.412
2427.55	128.81
2432.27	130.557
2436.99	132.362
2441.7	124.24
2446.41	131.731
2451.11	136.415
2455.82	148.271
2460.51	148.703
2465.21	130.399
2469.9	146.641
2474.59	141.218
2479.28	132.88
2483.96	139.026
2488.64	123.27
2493.32	145.445
2497.99	134.031
2502.66	132.816
2507.32	137.452
2511.99	143.539
2516.65	139.296
2521.3	143.941
2525.96	135.292
2530.61	144.384
2535.25	138.71
2539.89	141.958
2544.53	137.783
2549.17	136.598
2553.8	147.371
2558.43	138.647
2563.06	150.963
2567.68	133.267
2572.3	150.227
2576.92	138.49
2581.53	150.908
2586.14	154.155
2590.75	142.121
2595.35	149.896
2599.96	151.659
2604.55	150.327
2609.15	152.026
2613.74	155.199
2618.33	158.394
2622.91	160.067
2627.49	155.646
2632.07	149.787
2636.64	153.249
2641.22	141.371
2645.78	160.437
2650.35	159.378
2654.91	159.809
2659.47	158.53
2664.03	160.323
2668.58	166.813
2673.13	162.453
2677.67	159.897
2682.22	168.608
2686.76	167.785
2691.29	171.68
2695.83	172.126
2700.36	174.093
2704.89	166.405
2709.41	182.817
2713.93	175.073
2718.45	162.52
2722.96	169.305
2727.47	167.914
2731.98	182.683
2736.49	171.457
2740.99	166.72
2745.49	170.193
2749.98	167.231
2754.47	175.912
2758.96	172.968
2763.45	160.094
2767.93	178.516
2772.41	164.014
2776.89	172.684
2781.36	171.556
2785.84	167.146
2790.3	169.365
2794.77	168.216
2799.23	166.986
2803.69	177.469
2808.14	187.941
2812.59	179.842
2817.04	180.107
2821.49	182.082
2825.93	158.638
2830.37	186.079
2834.81	167.624
2839.24	171.271
2843.67	161.285
2848.1	166.704
2852.53	184.188
2856.95	177.778
2861.37	181.68
2865.78	185.685
2870.19	160.276
2874.6	171.198
2879.01	190.931
2883.41	170.6
2887.81	187.016
2892.21	161.218
2896.6	170.622
2901	164.158
2905.38	175.355
2909.77	181.229
2914.15	187.016
2918.53	191.03
2922.91	178.919
2927.28	183.028
2931.65	178.146
2936.02	171.338
2940.38	189.837
2944.74	182.903
2949.1	177.688
2953.46	185.249
2957.81	192.819
2962.16	189.442
2966.5	180.587
2970.85	188.262
2975.19	179.415
2979.52	200.032
2983.86	204.167
2988.19	200.982
2992.52	190.398
2996.85	196.534
3001.17	195.287
3005.49	197.823
3009.8	200.364
3014.12	200.991
3018.43	209.287
3022.74	223.332
3027.04	220.176
3031.34	226.467
3035.64	219.275
3039.94	225.461
3044.23	218.213
3048.52	205.112
3052.81	234.395
3057.09	229.029
3061.38	233.306
3065.65	245.354
3069.93	255.498
3074.2	259.847
3078.47	246.682
3082.74	253
3087	277.069
3091.27	275.863
3095.52	276.734
3099.78	287.516
3104.03	276.618
3108.28	271.684
3112.53	286.75
3116.77	305.923
3121.01	280.981
3125.25	306.475
3129.49	311.958
3133.72	309.409
3137.95	331.412
3142.18	343.188
3146.4	336.306
3150.62	335.493
3154.84	344.863
3159.06	343.787
3163.27	332.237
3167.48	375.172
3171.69	344.587
3175.89	360.182
3180.09	339.634
3184.29	378.246
3188.49	334.086
3192.68	364.33
3196.87	365.049
3201.06	387.582
3205.24	384.681
3209.42	356.099
3213.6	361.892
3217.78	361.292
3221.95	334.415
3226.12	353.262
3230.29	352.447
3234.45	342.746
3238.61	341.772
3242.77	343.161
3246.93	317.842
3251.08	316.683
3255.23	304.041
3259.38	309.37
3263.53	301.401
3267.67	321.097
3271.81	326.963
3275.95	302.684
3280.08	310.178
3284.21	303.929
3288.34	309.131
3292.47	321.219
3296.59	296.404
3300.71	287.763
3304.83	306.85
3308.95	295.843
3313.06	307.972
3317.17	280.597
3321.27	311.519
3325.38	302.927
3329.48	299.046
3333.58	304.811
3337.67	329.509
3341.77	301.939
3345.86	338.156
3349.95	293.564
3354.03	310.74
3358.11	328.14
3362.19	297.793
3366.27	312.806
3370.34	296.663
3374.42	299.615
3378.48	314.52
3382.55	302.883
3386.61	308.097
3390.68	296.343
3394.73	318.484
3398.79	294.703
3402.84	307.189
3406.89	295.329
3410.94	305.308
3414.98	303.111
3419.03	325.284
3423.06	298.686
3427.1	303.817
3431.14	311.499
3435.17	302.154
3439.2	300.22
3443.22	293.418
3447.25	284.281
3451.27	294.861
3455.28	288.288
3459.3	319.06
3463.31	295.266
3467.32	308.814
3471.33	272.215
3475.34	277.967
3479.34	268.721
3483.34	292.291
3487.33	272.817
3491.33	281.197
3495.32	261.492
3499.31	264.623
3503.3	265.107
3507.28	252.684
3511.26	278.567
3515.24	247.917
3519.22	258.344
3523.19	271.352
3527.16	250.97
3531.13	253.724
3535.1	259.323
3539.06	265.102
3543.02	265.636
3546.98	237.524
3550.93	237.824
3554.89	258.716
3558.84	243.372
3562.78	243.705
3566.73	270.241
3570.67	239.437
3574.61	268.797
3578.55	266.851
3582.48	270.262
3586.41	241.979
3590.35	237.383
3594.27	240.731
3598.2	225.413
3602.12	228.661
3606.04	221.17
3609.95	210.892
3613.87	216.721
3617.78	219.834
3621.69	206.646
3625.6	214.904
3629.5	220.444
3633.4	212.402
3637.3	193.611
3641.2	202.032
3645.09	199.709
3648.98	202.723
3652.87	170.251
3656.76	200.4
3660.64	186.928
3664.53	197.993
3668.4	184.532
3672.28	184.71
3676.16	193.206
3680.03	204.562
3683.9	174.774
3687.76	189.059
3691.63	189.598
3695.49	184.525
3699.35	185.024
3703.2	196.659
3707.06	177.627
3710.91	183.727
3714.76	172.953
3718.6	193.063
3722.45	173.68
3726.29	168.328
3730.13	182.792
3733.97	194.502
3737.8	172.109
3741.63	158.153
3745.46	189.798
3749.29	190.055
3753.11	193.116
3756.93	170.358
3760.75	170.448
3764.57	173.39
3768.39	173.486
3772.2	167.892
3776.01	173.783
3779.81	185.477
3783.62	171.35
3787.42	174.496
3791.22	166.067
3795.02	169.243
3798.81	155.086
3802.61	178.652
3806.4	170.324
3810.18	153.202
3813.97	179.833
3817.75	162.611
3821.53	174.659
3825.31	180.821
3829.09	169.34
3832.86	172.614
3836.63	190.656
3840.4	176.156
3844.17	170.564
3847.93	155.862
3851.69	167.855
3855.45	173.877
3859.21	159.027
3862.96	168.001
3866.71	198.074
3870.46	174.656
3874.21	171.762
3877.95	177.848
3881.69	157.028
3885.44	163.145
3889.17	175.294
3892.91	166.518
3896.64	190.868
3900.37	185.143
3904.1	176.37
3907.82	173.598
3911.55	170.85
3915.27	162.061
3918.99	171.508
3922.7	156.715
3926.42	144.872
3930.13	166.567
3933.84	163.783
3937.54	164.017
3941.25	164.304
3944.95	167.719
3948.65	152.616
3952.35	171.372
3956.04	171.599
3959.73	159.386
3963.42	162.608
3967.11	153.395
3970.8	165.828
3974.48	159.686
3978.16	156.627
3981.84	162.822
3985.52	162.813
3989.19	178.31
3992.86	162.86
3996.53	156.767
3998.37	159.949