File: Data/3-Raman/raw/bu19(2)w-a-ff2-fi01-v_150 (500nm)_532nm_edge_100%_x100_vis_lwd_h50um_30sx2_01.txt
#Acq. time (s)=	30
#Accumulations=	2
#Range (cm-¹)=	99...4000
#Windows=	1
#Auto scanning=	Off
#Autofocus=	Off
#Macrospot=	Off
#AutoExposure=	Off
#Spike filter=	Multiple accum.
#Delay time (s)=	2
#Binning=	1
#Readout mode=	Signal
#DeNoise=	Off
#ICS correction=	On
#Dark correction=	Off
#Inst. Process=	Off
#Detector Gain=	Best Dynamic
#Detector ADC=	50 kHz HS
#Detector temperature (°C)=	-60.09
#Instrument=	LabRAM HR Evol
#Detector=	SIN-EM FIVIS
#Objective=	x100_VIS_LWD
#Grating=	150 (500nm)
#ND Filter=	100%
#Laser=	532nm_Edge
#Hole=	49.98
#Temperature=	0
#Range=	Visible
#StageXY=	75x50mm Scan+
#StageZ=	Z motor
#X (µm)=	0
#Y (µm)=	0
#Z (µm)=	12.5
#Full time(mm:ss)=	1:05
#Project=	21_11_26
#Sample=	BU19(2)w
#Site=
#Title=	BU19(2)w-A-FF2-FI01-V_150 (500nm)_532nm_Edge_100%_x100_VIS_LWD_H50um_30sX2
#Remark=
#Date=	26.11.2021 14:23
#Acquired=	26.11.2021 14:23:08
102.91	8392.65
107.534	8477.03
112.156	7797.94
116.775	6367.15
121.392	5058.5
126.005	4486.2
130.617	4634.04
135.227	5691.43
139.835	7932.34
144.439	10724.8
149.042	10547.8
153.643	7619.62
158.242	4715.95
162.839	3297.61
167.431	2453.24
172.023	1913.57
176.613	1596.11
181.198	1392.79
185.783	1226.32
190.366	1182.26
194.947	1258.11
199.524	1545.6
204.1	2602.46
208.674	3759.36
213.243	2832.02
217.813	1556.27
222.38	1333.62
226.945	1845.73
231.506	3130.84
236.066	3346.81
240.625	2068.92
245.179	1093.75
249.732	771.006
254.284	658.242
258.831	613.823
263.378	568.276
267.923	560.476
272.464	606.088
277.004	728.042
281.54	803.962
286.076	651.233
290.61	544.98
295.139	497.097
299.669	507.502
304.196	531.341
308.718	569.665
313.241	622.693
317.759	697.437
322.278	873.836
326.794	1250.45
331.305	1655.41
335.817	1677.04
340.324	1542.32
344.832	1592.01
349.334	2022.08
353.837	1988.19
358.338	1389.47
362.834	1049.26
367.33	961.861
371.822	937.883
376.314	1093.32
380.802	1453.34
385.289	2309.18
389.772	3756.99
394.255	4474.81
398.734	4083.82
403.213	3380.82
407.688	2821.56
412.162	2354.63
416.632	2208.1
421.102	2392.45
425.568	2682.23
430.033	2878.08
434.495	2798.77
438.956	2663.71
443.413	2784.49
447.87	3020.32
452.323	3074
456.776	2581.59
461.224	1904.24
465.673	1394.84
470.117	1120.92
474.561	1015.99
479.001	1071.12
483.438	1294.2
487.876	1625.23
492.309	2165.39
496.742	3026.36
501.172	4224
505.601	5297.1
510.025	5852.96
514.448	5528.68
518.871	4785.07
523.289	3977.39
527.707	3468.77
532.121	3228.78
536.533	3158.18
540.945	3203.42
545.353	3313.47
549.758	3188.34
554.164	2972.06
558.565	2562.39
562.965	2234.42
567.364	1883.16
571.759	1587.75
576.151	1405.98
580.544	1362.76
584.933	1426.53
589.319	1566.17
593.706	1871.86
598.088	2189.79
602.468	2739.22
606.848	3677.75
611.224	5637.36
615.598	9404.27
619.972	11945.3
624.341	9511.84
628.709	5712.43
633.074	3415.88
637.44	2259.61
641.801	1661.65
646.16	1289.16
650.517	1035.1
654.874	848.137
659.227	744.355
663.578	641.568
667.927	571.922
672.275	537.576
676.62	510.014
680.962	498.33
685.302	522.453
689.643	543.014
693.979	670.242
698.313	795.362
702.645	905.1
706.975	851.715
711.305	760
715.631	639.52
719.955	580.96
724.276	562.494
728.596	515.659
732.913	443.534
737.231	415.831
741.544	382.791
745.856	395.647
750.165	393.677
754.472	384.401
758.778	382.055
763.081	384.221
767.384	374.966
771.683	386.461
775.98	399.545
780.275	414.045
784.568	416.457
788.859	429.139
793.147	441.916
797.434	487.424
801.719	490.129
806.004	531.695
810.284	572.342
814.563	603.186
818.839	668.242
823.114	803.74
827.386	956.082
831.657	1157.16
835.925	1413.62
840.192	1682.41
844.456	1793.5
848.719	1767.16
852.979	1546.77
857.237	1358.58
861.493	1183.77
865.748	1082.73
870	1052.99
874.25	1190.02
878.499	1293.47
882.745	1220.03
886.989	981.425
891.231	764.116
895.471	638.993
899.71	552.429
903.946	527.914
908.18	496.151
912.412	467.098
916.642	453.558
920.87	465.867
925.096	434.851
929.321	446.718
933.543	441.909
937.763	469.243
941.981	470.663
946.197	462.394
950.412	471.211
954.622	470.536
958.832	463.528
963.04	473.609
967.246	473.098
971.451	482.199
975.653	513.646
979.853	522.867
984.052	560.776
988.248	618.754
992.442	720.129
996.633	789.216
1000.82	851.486
1005.01	823.889
1009.2	759.156
1013.38	705.968
1017.57	687.61
1021.75	670.262
1025.92	667.672
1030.1	747.065
1034.27	813.454
1038.45	972.888
1042.62	1218.75
1046.78	1319.1
1050.95	1326.25
1055.12	1300.19
1059.28	1283.38
1063.44	1392.82
1067.6	1594.83
1071.75	1906.55
1075.91	2331.09
1080.06	3026.8
1084.21	4184.03
1088.36	6052.7
1092.51	7860.91
1096.65	7995.11
1100.8	6120.93
1104.94	3821.25
1109.08	2489.03
1113.21	1769.38
1117.35	1530.88
1121.48	1375.29
1125.61	1353.52
1129.74	1496.74
1133.87	1865.15
1137.99	2389.22
1142.12	2893.22
1146.24	3014.6
1150.36	2645.95
1154.48	2023.18
1158.59	1536.01
1162.71	1201.93
1166.82	946.893
1170.93	810.367
1175.04	700.511
1179.14	616.452
1183.25	558.25
1187.35	482.527
1191.45	464.206
1195.55	457.075
1199.65	436.549
1203.74	427.213
1207.83	448.359
1211.92	460.287
1216.01	482.274
1220.1	520.308
1224.19	546.166
1228.27	590.072
1232.35	658.039
1236.43	697.323
1240.51	848.869
1244.58	1362.52
1248.66	1696.49
1252.73	1224.6
1256.8	1088.3
1260.87	1519.75
1264.93	8218.75
1269	12401.9
1273.06	3874.65
1277.12	1206.7
1281.18	939.789
1285.23	827.031
1289.29	763.243
1293.34	717.399
1297.39	657.292
1301.44	648.465
1305.49	641.525
1309.53	642.601
1313.58	609.331
1317.62	609.105
1321.66	633.923
1325.7	636.331
1329.73	605.485
1333.77	660.965
1337.8	684.003
1341.83	711.848
1345.86	783.458
1349.88	947.491
1353.91	1223.39
1357.93	1123.89
1361.95	1270.53
1365.97	2965.89
1369.99	18860.2
1374	15809
1378.02	3507.51
1382.03	1281.03
1386.04	1156.37
1390.05	1761.38
1394.05	2217.09
1398.06	1195.91
1402.06	710.698
1406.06	590.704
1410.06	574.187
1414.05	491.634
1418.05	407.029
1422.04	384.528
1426.03	361.957
1430.02	330.309
1434.01	293.757
1438	278.927
1441.98	261.139
1445.96	245.291
1449.94	227.461
1453.92	229.333
1457.9	221.322
1461.87	199.489
1465.85	203.217
1469.82	207.907
1473.78	189.047
1477.75	194.725
1481.72	184.688
1485.68	182.491
1489.65	182.241
1493.61	182.006
1497.56	175.927
1501.52	179.617
1505.47	180.413
1509.43	164.736
1513.38	175.316
1517.33	171.333
1521.27	171.254
1525.22	173.126
1529.16	175.98
1533.11	173.038
1537.05	161.379
1540.98	175.894
1544.92	169.088
1548.86	166.161
1552.79	172.921
1556.72	172.879
1560.65	167.001
1564.58	167.884
1568.5	161.979
1572.43	167.666
1576.35	175.273
1580.27	173.213
1584.19	172.115
1588.1	174.86
1592.02	169.895
1595.93	173.591
1599.84	164.789
1603.75	178.098
1607.66	183.739
1611.57	186.502
1615.47	175.858
1619.37	183.45
1623.27	180.492
1627.17	189.051
1631.07	177.533
1634.97	181.388
1638.86	177.577
1642.75	173.811
1646.64	181.575
1650.53	174.027
1654.42	168.395
1658.3	168.503
1662.18	178.21
1666.07	171.554
1669.94	189.87
1673.82	175.446
1677.7	179.276
1681.57	168.598
1685.44	167.49
1689.31	165.41
1693.18	168.09
1697.05	169.782
1700.92	191.497
1704.78	181.638
1708.64	187.954
1712.5	185.658
1716.36	173.897
1720.21	174.486
1724.07	192.065
1727.92	186.009
1731.77	181.829
1735.62	189.872
1739.47	191.308
1743.32	185.247
1747.16	207.157
1751.01	208.656
1754.85	213.011
1758.69	210.059
1762.52	208.384
1766.36	212.129
1770.19	201.095
1774.02	190.143
1777.85	181.966
1781.68	195.268
1785.51	188.105
1789.33	177.199
1793.16	179.378
1796.98	175.939
1800.8	183.759
1804.62	177.369
1808.43	166.24
1812.25	184.295
1816.06	159.895
1819.87	170.314
1823.68	169.368
1827.49	174.05
1831.3	173.024
1835.1	169.127
1838.9	167.091
1842.71	165.973
1846.51	163.879
1850.3	165.562
1854.1	157.799
1857.89	169.651
1861.69	165.545
1865.48	169.814
1869.27	165.724
1873.05	169.081
1876.84	170.611
1880.62	176.763
1884.4	168.221
1888.19	178.121
1891.96	182.688
1895.74	172.536
1899.52	182.629
1903.29	180.839
1907.06	177.241
1910.83	169.972
1914.6	184.887
1918.37	175.844
1922.13	169.664
1925.9	181.077
1929.66	174.932
1933.42	177.148
1937.18	168.187
1940.94	175.989
1944.69	179.14
1948.44	189.8
1952.2	179.699
1955.95	192.042
1959.69	194.905
1963.44	195.824
1967.19	213.634
1970.93	235.119
1974.67	238.67
1978.41	253.408
1982.15	256.839
1985.89	277.969
1989.62	274.749
1993.35	276.151
1997.09	290.506
2000.82	284.34
2004.55	268.954
2008.27	248.058
2012	256.689
2015.72	249.655
2019.44	233.593
2023.16	227.79
2026.88	216.641
2030.6	224.741
2034.31	212.806
2038.03	203.692
2041.74	194.557
2045.45	194.561
2049.16	187.244
2052.86	187.288
2056.57	183.68
2060.27	180.162
2063.98	187.768
2067.67	165.092
2071.37	171.835
2075.07	176.758
2078.77	182.637
2082.46	171.873
2086.15	169.4
2089.84	160.219
2093.53	164.89
2097.22	158.49
2100.9	163.214
2104.59	175.326
2108.27	162.296
2111.95	162.262
2115.63	156.645
2119.31	162.163
2122.98	162.038
2126.66	161.878
2130.33	169.106
2134	167.046
2137.67	164.979
2141.34	165.659
2145	161.703
2148.67	160.51
2152.33	160.235
2155.99	155.384
2159.65	146.894
2163.31	165.864
2166.96	164.728
2170.62	152.686
2174.27	160.77
2177.92	151.582
2181.57	149.703
2185.22	155.096
2188.87	145.066
2192.51	159.655
2196.15	154.296
2199.8	153.518
2203.44	160.052
2207.07	156.583
2210.71	146.732
2214.35	159.763
2217.98	146.25
2221.61	157.495
2225.24	154.067
2228.87	156.144
2232.5	155.463
2236.12	154.794
2239.75	154.117
2243.37	158.997
2246.99	143.458
2250.61	141.828
2254.23	149.523
2257.85	156.325
2261.46	133.23
2265.07	152.182
2268.68	150.574
2272.29	158.396
2275.9	161.494
2279.51	161.728
2283.11	151.473
2286.72	156.311
2290.32	156.428
2293.92	160.306
2297.52	153.785
2301.11	170.935
2304.71	185.234
2308.3	232.676
2311.9	840.319
2315.49	1400.53
2319.08	516.042
2322.66	207.944
2326.25	176.501
2329.84	159.288
2333.42	168.531
2337	163.585
2340.58	169.928
2344.16	164.954
2347.73	156.223
2351.31	172.798
2354.88	166.867
2358.45	162.814
2362.03	153.179
2365.59	155.661
2369.16	149.796
2372.73	159.729
2376.29	153.903
2379.85	161.018
2383.41	160.76
2386.97	160.519
2390.53	152.956
2394.09	160.125
2397.64	147.157
2401.2	153.5
2404.75	153.51
2408.3	155.373
2411.85	154.551
2415.39	154.684
2418.94	153.935
2422.48	161.49
2426.03	151.595
2429.57	150.014
2433.11	150.307
2436.64	147.854
2440.18	154.695
2443.72	150.405
2447.25	149.831
2450.78	139.927
2454.31	153.456
2457.84	156.605
2461.37	142.676
2464.89	143.785
2468.42	156.092
2471.94	153.435
2475.46	164.678
2478.98	152.304
2482.5	151.281
2486.01	153.028
2489.53	154.676
2493.04	152.646
2496.55	155.225
2500.06	144.736
2503.57	145.452
2507.08	143.339
2510.58	151.454
2514.09	150.247
2517.59	152.795
2521.09	152.579
2524.59	140.226
2528.09	146.544
2531.59	152.887
2535.08	139.857
2538.58	147.183
2542.07	140.701
2545.56	141.668
2549.05	143.622
2552.54	148.358
2556.02	145.741
2559.51	151.53
2562.99	144.343
2566.47	144.635
2569.95	157.094
2573.43	151.895
2576.91	135.449
2580.38	140.556
2583.85	143.817
2587.33	144.259
2590.8	144.666
2594.27	144.047
2597.74	138.638
2601.2	151.392
2604.67	147.917
2608.13	144.342
2611.59	146.394
2615.06	152.188
2618.51	147.476
2621.97	155.19
2625.43	140.773
2628.88	153.22
2632.33	152.189
2635.79	158.798
2639.24	143.302
2642.69	152.706
2646.13	144.845
2649.58	145.59
2653.02	152.969
2656.47	151.721
2659.91	153.293
2663.35	148.212
2666.79	147.863
2670.22	143.743
2673.66	145.276
2677.09	146.825
2680.52	146.517
2683.95	142.505
2687.39	147.887
2690.81	148.691
2694.24	138.366
2697.66	155.957
2701.09	143.782
2704.51	147.437
2707.93	154.814
2711.35	136.257
2714.77	154.005
2718.18	150.388
2721.6	153.318
2725.01	143.212
2728.42	137.766
2731.84	142.602
2735.24	147.441
2738.65	141.044
2742.06	145.885
2745.46	146.95
2748.86	147.996
2752.27	150.925
2755.67	145.377
2759.07	150.162
2762.46	147.419
2765.86	155.942
2769.25	152.192
2772.65	133.34
2776.04	151.225
2779.43	153.063
2782.82	152.054
2786.2	142.565
2789.59	138.724
2792.98	150.862
2796.36	146.071
2799.74	148.796
2803.12	146.803
2806.5	150.439
2809.88	159.684
2813.25	148.319
2816.63	142.574
2820	161.121
2823.37	146.063
2826.74	160.893
2830.11	157.074
2833.48	159.802
2836.84	156.038
2840.21	146.712
2843.57	145.799
2846.93	149.581
2850.29	151.555
2853.65	156.369
2857.01	155.567
2860.36	154.784
2863.72	148.401
2867.07	155.132
2870.42	160.942
2873.77	163.935
2877.12	158.465
2880.47	156.745
2883.81	158.785
2887.16	169.305
2890.5	159.071
2893.84	167.706
2897.18	165.913
2900.52	164.095
2903.86	166.98
2907.19	172.684
2910.53	167.018
2913.86	183.105
2917.19	173.629
2920.52	185.888
2923.85	179.216
2927.18	182.931
2930.51	175.278
2933.83	186.498
2937.15	194.844
2940.48	198.463
2943.8	193.597
2947.11	196.277
2950.43	180.144
2953.75	182.828
2957.06	185.514
2960.38	176.962
2963.69	186.263
2967	167.428
2970.31	184.293
2973.62	178.679
2976.92	177.762
2980.23	179.689
2983.53	190.041
2986.84	197.594
2990.14	189.2
2993.44	193.956
2996.73	183.693
3000.03	188.471
3003.33	191.371
3006.62	175.457
3009.91	195.311
3013.2	189.767
3016.49	199.299
3019.78	186.208
3023.07	186.307
3026.35	185.462
3029.64	179.898
3032.92	184.717
3036.2	186.696
3039.48	188.672
3042.76	186.866
3046.04	189.795
3049.32	189.887
3052.59	189.979
3055.86	195.765
3059.14	191.114
3062.41	201.578
3065.68	201.638
3068.94	186.488
3072.21	190.276
3075.48	204.326
3078.74	203.398
3082	195.77
3085.26	203.483
3088.52	211.195
3091.78	207.577
3095.04	212.523
3098.29	207.695
3101.55	212.509
3104.8	214.431
3108.05	220.261
3111.3	215.594
3114.55	219.423
3117.8	228.034
3121.04	229.035
3124.29	227.179
3127.53	217.697
3130.77	232.979
3134.02	242.552
3137.25	234.01
3140.49	238.8
3143.73	241.68
3146.96	232.167
3150.2	243.647
3153.43	253.227
3156.66	257.077
3159.89	259.98
3163.12	251.425
3166.35	261
3169.57	267.69
3172.8	271.497
3176.02	291.514
3179.24	270.477
3182.46	285.692
3185.68	295.185
3188.9	296.058
3192.12	299.782
3195.33	302.55
3198.55	299.596
3201.76	316.636
3204.97	332.726
3208.18	326.929
3211.39	324.004
3214.6	342.985
3217.8	343.91
3221.01	337.225
3224.21	334.358
3227.41	354.355
3230.61	351.531
3233.81	352.538
3237.01	368.747
3240.21	362.199
3243.4	369.95
3246.59	376.774
3249.79	375.98
3252.98	380.944
3256.17	405.96
3259.36	418.584
3262.54	413.015
3265.73	426.488
3268.92	449.458
3272.1	466.654
3275.28	466.626
3278.46	458.951
3281.64	487.467
3284.82	506.33
3288	519.462
3291.17	542.073
3294.35	523.723
3297.52	552.049
3300.69	552.744
3303.86	563.084
3307.03	586.591
3310.2	620.476
3313.36	632.364
3316.53	653.69
3319.69	688.246
3322.85	688.596
3326.02	711.681
3329.18	760.278
3332.33	792.74
3335.49	824.263
3338.65	878.469
3341.8	905.308
3344.95	930.255
3348.11	959.182
3351.26	1012.84
3354.41	1068.36
3357.56	1092.89
3360.7	1142.94
3363.85	1192.2
3366.99	1229.24
3370.13	1300.33
3373.28	1352.64
3376.42	1368.34
3379.56	1452.11
3382.69	1488.79
3385.83	1556.64
3388.97	1686.18
3392.1	1768.56
3395.23	1821.6
3398.36	1925.37
3401.49	2047.39
3404.62	2180.25
3407.75	2275.58
3410.88	2403.57
3414	2587.92
3417.13	2775.82
3420.25	2966.67
3423.37	3167.06
3426.49	3448.13
3429.61	3729.75
3432.73	4020.5
3435.84	4370.59
3438.96	4821.67
3442.07	5234
3445.18	5927.49
3448.29	7041.85
3451.4	8764.22
3454.51	11015.2
3457.62	12818.5
3460.72	12434.9
3463.83	10613.2
3466.93	8630.48
3470.03	7569.62
3473.13	6867.04
3476.23	6488.1
3479.33	6219.89
3482.43	6067.74
3485.53	5977.4
3488.62	6028.31
3491.71	6096.14
3494.81	6019.31
3497.9	6024.37
3500.99	6129
3504.07	6290.28
3507.16	6299.63
3510.25	6591.51
3513.33	6842.38
3516.41	7050.96
3519.5	7343.27
3522.58	7946.13
3525.66	8467.27
3528.73	9006.96
3531.81	9567.73
3534.89	10103.1
3537.96	10283.4
3541.03	10261.7
3544.11	9639.29
3547.18	8743.15
3550.25	7674.78
3553.32	6503.82
3556.38	5428.53
3559.45	4525.25
3562.51	3826.36
3565.58	3257.62
3568.64	2794.14
3571.7	2479.08
3574.76	2173.98
3577.82	1945.73
3580.87	1790.3
3583.93	1609.11
3586.98	1483.75
3590.04	1379.27
3593.09	1304.04
3596.14	1213.64
3599.19	1173.41
3602.24	1115.22
3605.29	1049.37
3608.33	1026.09
3611.38	972.568
3614.42	935.119
3617.46	918.458
3620.5	897.139
3623.54	888.15
3626.58	866.941
3629.62	835.44
3632.65	799.212
3635.69	770.514
3638.72	739.21
3641.76	708.022
3644.79	674.102
3647.82	632.823
3650.84	613.946
3653.87	570.69
3656.9	563.414
3659.92	533.868
3662.95	502.33
3665.97	500.799
3668.99	473.588
3672.01	466.27
3675.03	442.929
3678.05	439.412
3681.07	433.082
3684.08	399.311
3687.1	393.876
3690.11	379.93
3693.12	380.18
3696.13	375.697
3699.14	358.811
3702.15	367.596
3705.16	360.255
3708.16	337.701
3711.17	333.137
3714.17	320.935
3717.17	332.465
3720.17	310.718
3723.17	310.812
3726.17	299.453
3729.17	295.681
3732.16	285.221
3735.16	286.16
3738.15	277.546
3741.14	276.525
3744.13	271.665
3747.13	256.324
3750.11	260.935
3753.1	256.972
3756.09	252.06
3759.07	258.546
3762.06	247.949
3765.04	224.081
3768.02	240.966
3771	235.138
3773.98	235.958
3776.96	229.234
3779.94	233.867
3782.91	235.678
3785.89	222.383
3788.86	224.213
3791.83	218.506
3794.8	225.105
3797.77	213.788
3800.74	209.091
3803.71	207.253
3806.68	200.703
3809.64	208.326
3812.61	204.626
3815.57	209.437
3818.53	207.637
3821.49	203.004
3824.45	199.319
3827.41	200.382
3830.36	206.188
3833.32	204.411
3836.27	210.245
3839.23	186.652
3842.18	201.998
3845.13	204.048
3848.08	200.393
3851.03	193.882
3853.98	204.536
3856.92	205.669
3859.87	189.612
3862.81	206.991
3865.75	187.07
3868.7	197.76
3871.64	196.95
3874.57	203.806
3877.51	197.226
3880.45	216.543
3883.39	197.428
3886.32	208.066
3889.25	197.546
3892.18	205.281
3895.12	202.431
3898.05	206.285
3900.97	201.462
3903.9	202.402
3906.83	203.317
3909.75	205.218
3912.68	208.059
3915.6	208.956
3918.52	197.356
3921.44	198.278
3924.36	200.121
3927.28	215.369
3930.2	194.148
3933.11	203.605
3936.03	198.734
3938.94	205.398
3941.86	199.65
3944.77	198.671
3947.68	193.874
3950.59	193.884
3953.49	190.077
3956.4	204.475
3959.31	192.073
3962.21	197.881
3965.12	202.744
3968.02	200.909
3970.92	201.002
3973.82	202.06
3976.72	195.432
3979.61	212.803
3982.51	202.302
3985.41	204.288
3988.3	201.458
3991.19	203.428
3994.09	205.374
3996.98	201.587
3999.87	214.156