File: Data/3-Raman/raw/bu19w-e-ff11-fi09-v_150 (500nm)_633nm_edge_100%_x100_vis_h50um_60sx2_01.txt
#Acq. time (s)=	60
#Accumulations=	2
#Range (cm-¹)=	100...4000
#Windows=	1
#Auto scanning=	Off
#Autofocus=	Off
#Macrospot=	Off
#AutoExposure=	Off
#Spike filter=	Multiple accum.
#Delay time (s)=	2
#Binning=	1
#Readout mode=	Signal
#DeNoise=	Off
#ICS correction=	On
#Dark correction=	Off
#Inst. Process=	Off
#Detector Gain=	Best Dynamic
#Detector ADC=	50 kHz HS
#Detector temperature (°C)=	-60.09
#Instrument=	LabRAM HR Evol
#Detector=	SIN-EM FIVIS
#Objective=	x100_VIS
#Grating=	150 (500nm)
#ND Filter=	100%
#Laser=	633nm_Edge
#Hole=	49.98
#Temperature=	0
#Range=	Visible
#StageXY=	75x50mm Scan+
#StageZ=	Z motor
#X (µm)=	0
#Y (µm)=	0
#Z (µm)=	-270.7
#Full time(mm:ss)=	2:04
#Project=	21_11_04
#Sample=	BU19w
#Site=
#Title=	BU19w-E-FF11-FI09-V_150 (500nm)_633nm_Edge_100%_x100_VIS_H50um_60sX2
#Remark=
#Date=	04.11.2021 16:10
#Acquired=	04.11.2021 16:10:44
102.881	232.153
109.397	207.563
115.908	181.019
122.414	189.752
128.914	173.613
135.409	191.856
141.898	182.291
148.383	168.93
154.861	205.389
161.335	232.331
167.801	167.269
174.264	136.611
180.721	121.216
187.173	118.205
193.62	124.704
200.061	118.827
206.496	127.397
212.926	118.759
219.352	161.621
225.772	217.726
232.185	273.559
238.595	196.29
244.999	156.278
251.397	152.405
257.791	159.902
264.178	167.426
270.561	164.547
276.939	179.717
283.31	173.982
289.678	149.248
296.039	136.811
302.396	148.045
308.746	166.803
315.093	284.689
321.433	391.146
327.768	302.351
334.099	189.115
340.423	157.01
346.743	161.664
353.058	161.573
359.367	181.197
365.671	157.503
371.971	130.104
378.265	115.889
384.553	114.86
390.837	123.364
397.116	116.965
403.389	107.817
409.657	115.593
415.92	127.106
422.178	144.289
428.431	168.73
434.678	172.114
440.921	166.991
447.158	173.111
453.391	183.833
459.618	152.603
465.84	128.173
472.057	127.147
478.27	119.712
484.477	122.522
490.679	120.674
496.876	131.887
503.068	123.547
509.255	156.264
515.436	151.72
521.613	156.607
527.785	149.419
533.952	140.415
540.113	132.298
546.27	128.758
552.423	124.135
558.568	115.671
564.711	105.143
570.848	106.784
576.979	105.512
583.107	108.935
589.228	135.737
595.345	143.958
601.458	141.195
607.565	144.207
613.667	147.308
619.764	145.858
625.856	128.469
631.944	102.315
638.026	108.931
644.104	121.015
650.177	120.825
656.244	109.268
662.308	112.714
668.365	92.8396
674.418	87.1909
680.467	84.3943
686.511	80.7336
692.549	79.9582
698.582	81.0759
704.611	82.1798
710.635	79.4701
716.655	83.1736
722.669	78.4302
728.679	81.135
734.683	80.0535
740.683	87.3879
746.678	76.992
752.669	78.7885
758.654	86.2421
764.635	78.0034
770.611	85.7192
776.582	90.6564
782.549	85.187
788.511	85.2944
794.466	72.1505
800.419	83.4556
806.366	81.4928
812.309	85.1425
818.247	77.4535
824.18	86.6334
830.108	86.4406
836.033	89.2235
841.952	81.8704
847.865	85.766
853.776	87.8421
859.681	91.8419
865.58	97.7628
871.476	101.796
877.366	105.724
883.253	108.647
889.134	109.595
895.012	110.479
900.883	107.445
906.751	103.405
912.614	101.248
918.473	117.957
924.326	115.059
930.174	127.365
936.019	134.179
941.859	162.994
947.693	179.749
953.525	195.688
959.35	189.638
965.171	195.845
970.988	226.898
976.801	288.476
982.608	320.803
988.411	300.193
994.209	252.815
1000	214.242
1005.79	202.581
1011.58	222.646
1017.36	263.899
1023.13	240.381
1028.9	200.718
1034.67	158.035
1040.43	158.526
1046.19	151.29
1051.94	140.997
1057.69	125.713
1063.44	115.127
1069.17	116.056
1074.91	120.864
1080.64	153.737
1086.37	176.848
1092.09	230.98
1097.8	245.35
1103.52	188.154
1109.22	159.215
1114.93	149.86
1120.63	142.551
1126.32	140.918
1132.01	157.894
1137.7	185.728
1143.38	212.697
1149.06	264.179
1154.73	213.173
1160.4	136.301
1166.06	116.399
1171.72	113.24
1177.38	104.2
1183.03	92.3127
1188.67	97.171
1194.31	78.6677
1199.95	82.718
1205.58	76.1071
1211.21	76.3914
1216.84	73.7504
1222.46	71.1177
1228.07	72.4579
1233.68	80.792
1239.29	63.9461
1244.89	80.2261
1250.49	79.292
1256.08	81.3265
1261.67	83.257
1267.26	75.0829
1272.84	139.331
1278.42	127.984
1283.99	80.6389
1289.56	82.5191
1295.12	77.4572
1300.68	75.4503
1306.23	68.5216
1311.78	74.7025
1317.33	75.9459
1322.87	64.1027
1328.41	68.4135
1333.94	76.8174
1339.47	72.9919
1345	71.1192
1350.52	70.2308
1356.04	69.3096
1361.55	79.6447
1367.06	76.5653
1372.56	78.5924
1378.06	252.124
1383.56	108.297
1389.05	73.3606
1394.53	83.634
1400.02	94.0367
1405.5	74.6181
1410.97	74.7513
1416.44	76.9789
1421.91	75.0859
1427.37	77.3535
1432.83	75.4729
1438.28	73.576
1443.73	78.99
1449.17	69.7193
1454.62	71.8986
1460.05	75.0803
1465.48	83.4736
1470.91	71.9028
1476.34	75.0481
1481.76	71.9289
1487.17	76.1857
1492.59	75.2299
1497.99	77.471
1503.4	77.6348
1508.8	77.8297
1514.19	76.9916
1519.59	77.2425
1524.97	75.372
1530.36	70.271
1535.74	79.148
1541.11	79.3699
1546.48	78.4131
1551.85	76.2544
1557.21	69.6774
1562.57	81.4785
1567.93	76.0045
1573.28	80.2324
1578.62	76.9651
1583.97	78.0497
1589.3	77.0049
1594.64	78.1495
1599.97	70.699
1605.3	77.3186
1610.62	80.774
1615.94	75.6135
1621.25	73.7212
1626.56	81.6752
1631.87	88.5779
1637.17	80.0066
1642.47	83.4235
1647.76	79.1245
1653.05	85.8623
1658.34	84.8079
1663.62	82.6161
1668.9	77.0783
1674.18	75.9706
1679.45	82.6107
1684.71	85.8763
1689.98	82.4835
1695.23	81.3598
1700.49	87.0019
1705.74	89.6638
1710.99	87.5548
1716.23	74.1998
1721.47	83.363
1726.7	80.1346
1731.94	87.041
1737.16	84.9624
1742.39	87.38
1747.61	77.3696
1752.82	79.7314
1758.03	84.3274
1763.24	78.6939
1768.44	88.9275
1773.64	92.3847
1778.84	89.0786
1784.03	89.2169
1789.22	81.4222
1794.41	93.0187
1799.59	89.8232
1804.76	83.1875
1809.94	86.8376
1815.11	81.2606
1820.27	80.2812
1825.43	90.8816
1830.59	87.6148
1835.74	86.6713
1840.89	92.6768
1846.04	88.1691
1851.18	89.4823
1856.32	88.4245
1861.45	85.0649
1866.58	91.1199
1871.71	86.571
1876.83	92.5845
1881.95	96.2381
1887.07	95.1495
1892.18	89.2601
1897.29	86.9077
1902.39	94.1002
1907.49	93.0964
1912.59	82.6548
1917.68	90.0823
1922.77	102.128
1927.86	91.5573
1932.94	98.9271
1938.02	95.4882
1943.09	85.9934
1948.16	89.6941
1953.23	105.409
1958.29	87.3686
1963.35	90.9992
1968.41	86.1663
1973.46	101.777
1978.51	106.537
1983.55	93.2421
1988.59	95.6057
1993.63	90.7668
1998.66	95.5668
2003.69	90.7759
2008.72	93.2332
2013.74	100.534
2018.76	90.9637
2023.77	104.302
2028.78	95.9875
2033.79	107.046
2038.79	93.9213
2043.79	95.3269
2048.79	104.056
2053.78	103.021
2058.77	97.1255
2063.76	99.7916
2068.74	93.8782
2073.72	101.456
2078.69	101.658
2083.66	106.774
2088.63	100.737
2093.59	92.2481
2098.55	98.6644
2103.51	106.371
2108.46	102.915
2113.41	114.482
2118.36	107.308
2123.3	106.375
2128.24	100.369
2133.17	105.695
2138.11	104.674
2143.03	113.804
2147.96	119.113
2152.88	111.625
2157.79	107.914
2162.71	99.0472
2167.62	113.142
2172.52	102.972
2177.43	112.005
2182.32	104.339
2187.22	119.686
2192.11	109.484
2197	112.126
2201.89	107.138
2206.77	111.175
2211.64	107.541
2216.52	114.244
2221.39	104.181
2226.26	103.149
2231.12	108.614
2235.98	110.194
2240.84	111.778
2245.69	110.754
2250.54	108.408
2255.39	112.626
2260.23	110.277
2265.07	110.526
2269.9	102.769
2274.74	98.9299
2279.57	113.66
2284.39	115.053
2289.21	113.753
2294.03	120.432
2298.84	119.167
2303.66	111.288
2308.46	118.143
2313.27	102.336
2318.07	117.34
2322.87	129.732
2327.66	115.255
2332.45	114.235
2337.24	122.726
2342.02	113.602
2346.8	122.207
2351.58	118.523
2356.35	110.637
2361.12	115.02
2365.89	119.409
2370.65	118.28
2375.41	128.221
2380.17	125.672
2384.92	123.04
2389.67	127.312
2394.42	123.182
2399.16	113.437
2403.9	121.777
2408.64	123.179
2413.37	117.817
2418.1	126.786
2422.83	125.79
2427.55	120.363
2432.27	120.677
2436.99	132.362
2441.7	117.141
2446.41	118.914
2451.11	123.559
2455.82	119.619
2460.51	121.405
2465.21	118.872
2469.9	130.749
2474.59	116.596
2479.28	124.166
2483.96	120.101
2488.64	136.399
2493.32	129.366
2497.99	117.918
2502.66	125.479
2507.32	130.102
2511.99	133.234
2516.65	131.926
2521.3	127.702
2525.96	130.856
2530.61	129.575
2535.25	129.808
2539.89	136.012
2544.53	124.377
2549.17	138.091
2553.8	142.882
2558.43	134.151
2563.06	137.444
2567.68	130.255
2572.3	132.109
2576.92	129.409
2581.53	143.325
2586.14	142.005
2590.75	123.881
2595.35	134.678
2599.96	128.796
2604.55	138.117
2609.15	139.803
2613.74	127.676
2618.33	127.787
2622.91	144.749
2627.49	129.577
2632.07	142.106
2636.64	139.387
2641.22	141.371
2645.78	149.586
2650.35	137.609
2654.91	147.336
2659.47	149.159
2664.03	141.554
2668.58	152.716
2673.13	131.061
2677.67	144.143
2682.22	141.694
2686.76	140.749
2691.29	142.933
2695.83	140.103
2700.36	154.839
2704.89	161.581
2709.41	137.717
2713.93	139.575
2718.45	146.349
2722.96	145.003
2727.47	158.179
2731.98	146.959
2736.49	147.079
2740.99	145.575
2745.49	147.392
2749.98	147.653
2754.47	148.093
2758.96	154.933
2763.45	145.316
2767.93	142.319
2772.41	150.827
2776.89	149.549
2781.36	150.008
2785.84	145.525
2790.3	140.999
2794.77	144.783
2799.23	141.812
2803.69	147.19
2808.14	147.487
2812.59	149.446
2817.04	156.431
2821.49	144.819
2825.93	141.672
2830.37	145.294
2834.81	147.203
2839.24	144.004
2843.67	142.511
2848.1	161.574
2852.53	153.347
2856.95	160.602
2861.37	159.293
2865.78	149.412
2870.19	163.741
2874.6	159.032
2879.01	154.314
2883.41	144.354
2887.81	155.408
2892.21	150.646
2896.6	161.782
2901	144.636
2905.38	166.453
2909.77	166.945
2914.15	161.961
2918.53	155.155
2922.91	157.341
2927.28	155.98
2931.65	160.06
2936.02	162.273
2940.38	158.954
2944.74	155.604
2949.1	170.398
2953.46	143.272
2957.81	165.404
2962.16	149.174
2966.5	162.253
2970.85	158.874
2975.19	157.334
2979.52	168.69
2983.86	165.366
2988.19	167.64
2992.52	155.105
2996.85	166.728
3001.17	178.468
3005.49	164.072
3009.8	168.381
3014.12	178.344
3018.43	165.725
3022.74	172.013
3027.04	168.706
3031.34	178.689
3035.64	169.483
3039.94	167.897
3044.23	179.761
3048.52	172.371
3052.81	190.024
3057.09	171.047
3061.38	175.221
3065.65	181.349
3069.93	173.894
3074.2	191.722
3078.47	188.181
3082.74	188.529
3087	188.955
3091.27	171.801
3095.52	184.161
3099.78	196.618
3104.03	193.335
3108.28	196.05
3112.53	190.833
3116.77	203.614
3121.01	202.427
3125.25	189.144
3129.49	200.181
3133.72	209.336
3137.95	214.443
3142.18	190.66
3146.4	214.201
3150.62	210.851
3154.84	215.669
3159.06	241.382
3163.27	210.662
3167.48	230.148
3171.69	232.886
3175.89	243.994
3180.09	221.133
3184.29	219.319
3188.49	236.512
3192.68	228.37
3196.87	224.564
3201.06	231.695
3205.24	238.952
3209.42	222.697
3213.6	217.135
3217.78	226.757
3221.95	210.235
3226.12	219.832
3230.29	225.083
3234.45	212.701
3238.61	231.166
3242.77	218.779
3246.93	210.779
3251.08	211.495
3255.23	191.849
3259.38	199.122
3263.53	195.29
3267.67	207.635
3271.81	206.203
3275.95	190.748
3280.08	202.589
3284.21	205.295
3288.34	210.301
3292.47	215.298
3296.59	215.671
3300.71	181.441
3304.83	195.689
3308.95	189.107
3313.06	198.729
3317.17	189.781
3321.27	204.179
3325.38	200.002
3329.48	181.773
3333.58	189.477
3337.67	194.871
3341.77	181.163
3345.86	195.774
3349.95	198.482
3354.03	198.826
3358.11	184.952
3362.19	192.549
3366.27	185.766
3370.34	190.969
3374.42	188.914
3378.48	177.144
3382.55	208.76
3386.61	184.858
3390.68	172.967
3394.73	182.856
3398.79	195.256
3402.84	200.341
3406.89	188.378
3410.94	193.402
3414.98	195.987
3419.03	179.089
3423.06	167.02
3427.1	184.242
3431.14	177.127
3435.17	177.378
3439.2	199.738
3443.22	187.837
3447.25	193.213
3451.27	178.891
3455.28	181.881
3459.3	189.946
3463.31	180.648
3467.32	176.287
3471.33	189.422
3475.34	182.377
3479.34	180.409
3483.34	191.065
3487.33	173.841
3491.33	194.675
3495.32	177.304
3499.31	190.477
3503.3	193.387
3507.28	170.594
3511.26	188.707
3515.24	175.983
3519.22	173.514
3523.19	165.898
3527.16	184.045
3531.13	171.296
3535.1	169.011
3539.06	179.752
3543.02	174.931
3546.98	180.415
3550.93	185.841
3554.89	183.312
3558.84	199.122
3562.78	157.691
3566.73	178.855
3570.67	176.634
3574.61	182.257
3578.55	182.721
3582.48	185.887
3586.41	175.865
3590.35	184.336
3594.27	174.231
3598.2	172.061
3602.12	188.545
3606.04	162.192
3609.95	173.281
3613.87	181.723
3617.78	157.795
3621.69	160.725
3625.6	155.434
3629.5	158.232
3633.4	179.933
3637.3	166.532
3641.2	153.219
3645.09	156.235
3648.98	180.954
3652.87	167.527
3656.76	173.135
3660.64	148.724
3664.53	173.415
3668.4	179.064
3672.28	171.028
3676.16	152.098
3680.03	149.646
3683.9	172.021
3687.76	153.179
3691.63	159.152
3695.49	156.777
3699.35	143.289
3703.2	160.396
3707.06	152.451
3710.91	161.287
3714.76	156.08
3718.6	150.787
3722.45	165.208
3726.29	165.499
3730.13	154.452
3733.97	168.947
3737.8	160.73
3741.63	155.303
3745.46	158.403
3749.29	144.328
3753.11	161.645
3756.93	161.768
3760.75	164.719
3764.57	156.195
3768.39	141.943
3772.2	162.152
3776.01	162.293
3779.81	171.099
3783.62	139.671
3787.42	157.191
3791.22	151.627
3795.02	154.778
3798.81	157.985
3802.61	158.317
3806.4	155.766
3810.18	147.365
3813.97	150.592
3817.75	156.751
3821.53	157.046
3825.31	157.3
3829.09	157.56
3832.86	146.058
3836.63	146.318
3840.4	152.471
3844.17	137.934
3847.93	149.924
3851.69	147.059
3855.45	167.933
3859.21	135.247
3862.96	165.028
3866.71	156.374
3870.46	156.743
3874.21	150.852
3877.95	147.957
3881.69	148.055
3885.44	142.191
3889.17	151.322
3892.91	148.516
3896.64	157.804
3900.37	155.038
3904.1	161.296
3907.82	155.483
3911.55	173.874
3915.27	143.886
3918.99	147.224
3922.7	156.715
3926.42	147.922
3930.13	132.948
3933.84	157.66
3937.54	148.688
3941.25	145.878
3944.95	146.177
3948.65	149.532
3952.35	146.67
3956.04	146.864
3959.73	153.197
3963.42	159.51
3967.11	150.296
3970.8	162.729
3974.48	150.384
3978.16	153.526
3981.84	144.214
3985.52	138.003
3989.19	156.603
3992.86	144.247
3996.53	128.828
3998.37	150.631