File: Data/3-Raman/raw/bu19w-ff1-fi08-s_150 (500nm)_532nm_edge_100%_x100_vis_h50um_15sx2_01.txt
#Acq. time (s)=	15
#Accumulations=	2
#Range (cm-¹)=	100...5000
#Windows=	1
#Auto scanning=	Off
#Autofocus=	Off
#Macrospot=	Off
#AutoExposure=	Off
#Spike filter=	Multiple accum.
#Delay time (s)=	2
#Binning=	1
#Readout mode=	Signal
#DeNoise=	Off
#ICS correction=	On
#Dark correction=	Off
#Inst. Process=	Off
#Detector Gain=	Best Dynamic
#Detector ADC=	50 kHz HS
#Detector temperature (°C)=	-60.09
#Instrument=	LabRAM HR Evol
#Detector=	SIN-EM FIVIS
#Objective=	x100_VIS
#Grating=	150 (500nm)
#ND Filter=	100%
#Laser=	532nm_Edge
#Hole=	49.98
#Temperature=	0
#Range=	Visible
#StageXY=	75x50mm Scan+
#StageZ=	Z motor
#X (µm)=	0
#Y (µm)=	0
#Z (µm)=	-197
#Full time(s)=	34
#Project=	21_05_14
#Sample=	BU19w
#Site=
#Title=	BU19w-FF1-FI08-S_150 (500nm)_532nm_Edge_100%_x100_VIS_H50um_15sX2
#Remark=
#Date=	14.05.2021 16:11
#Acquired=	14.05.2021 16:11:05
102.699	1963.69
107.322	2020.36
111.942	1948.25
116.56	1920.75
121.173	1908.95
125.787	1905.34
130.398	1975.38
135.006	1899.99
139.613	1884.27
144.215	1857.55
148.817	1980.58
153.417	2216.65
158.014	2748.1
162.607	2626.41
167.2	2206.38
171.79	1996.35
176.379	2191.71
180.963	2951.18
185.547	4586.51
190.128	4032.42
194.705	2538.87
199.282	2037.38
203.857	1954.04
208.43	1917.21
212.998	1929.33
217.566	1931.67
222.132	1909.51
226.693	1946.82
231.254	2058.25
235.813	2131.79
240.368	2371.76
244.923	2645.49
249.475	2551.6
254.023	2294.88
258.571	2166.21
263.117	2233.54
267.658	2400.19
272.199	3250.76
276.738	4431.08
281.273	4231.23
285.807	3013.33
290.34	2517.15
294.868	2550.71
299.396	3039.98
303.919	3222.74
308.443	2712.03
312.964	2331.18
317.481	2246.31
321.998	2405.34
326.51	2673.27
331.023	2669.63
335.533	2409.51
340.039	2360.89
344.544	2424.6
349.046	2521
353.547	2331.26
358.045	2163.7
362.542	2166.17
367.036	2194.01
371.527	2126.24
376.017	2136.98
380.503	2250.68
384.99	2429.05
389.471	2570.68
393.953	2636.23
398.43	2493.8
402.908	2369.11
407.381	2283.71
411.854	2487.13
416.323	2594.14
420.791	2396.64
425.256	2204.42
429.72	2169.68
434.18	2065.35
438.64	2094.63
443.095	2193.32
447.551	2356.26
452.003	2746.68
456.454	2921.14
460.901	2482.17
465.348	2235.49
469.791	2230.82
474.231	2211.93
478.672	2267.16
483.108	2314.44
487.544	2366.12
491.976	2545.81
496.408	2514.7
500.836	2410.09
505.261	2433.93
509.687	2316.27
514.108	2309.92
518.529	2249.33
522.946	2267.39
527.361	2315.63
531.776	2324.17
536.187	2314.34
540.595	2401.8
545.003	2331.57
549.408	2404.06
553.812	2431.46
558.212	2391.65
562.61	2402.26
567.007	2383.12
571.401	2356.32
575.792	2381.5
580.184	2484.33
584.571	2874
588.956	3196.78
593.341	2954.17
597.722	2585.11
602.101	2577.74
606.48	2774.28
610.854	2933.94
615.227	2826.04
619.597	2468.27
623.967	2370.08
628.334	2386.73
632.698	2378.2
637.06	2433.94
641.422	2455.49
645.779	2427.69
650.135	2362.5
654.491	2461.56
658.842	2535.98
663.192	2609.22
667.539	2614.8
671.884	2726.62
676.23	2732.94
680.571	2643.44
684.91	2524.86
689.247	2378.02
693.583	2397.62
697.916	2324.5
702.247	2292.16
706.576	2309.1
710.902	2341.13
715.229	2289.71
719.551	2315.06
723.872	2355.42
728.19	2388.61
732.506	2376.16
736.82	2413.92
741.134	2426.85
745.444	2407.45
749.752	2470.07
754.058	2510.54
758.362	2565.06
762.664	2645.18
766.964	2810.78
771.264	3054.7
775.559	3460.08
779.853	3511.52
784.144	3174.25
788.434	2890.79
792.722	2772.43
797.007	2655
801.29	2602.64
805.572	2568.13
809.851	2581.36
814.13	2543.53
818.406	2509.89
822.679	2550.68
826.95	2511.46
831.219	2541.76
835.486	2534.44
839.752	2503.75
844.015	2602.73
848.276	2631.38
852.535	2557.25
856.792	2542.71
861.047	2566.47
865.3	2610.18
869.551	2566.42
873.8	2554.97
878.047	2557.35
882.292	2587.14
886.534	2599.27
890.775	2605.67
895.014	2614.42
899.251	2555.79
903.486	2591.8
907.719	2658.27
911.95	2659.41
916.179	2594.06
920.406	2617.44
924.63	2693.04
928.853	2650.93
933.074	2709.07
937.293	2668.61
941.51	2767.04
945.723	2865.65
949.936	2915.78
954.147	2888.36
958.356	2916.71
962.563	3001.66
966.768	2976.27
970.971	2995.17
975.172	2903
979.371	2840.28
983.568	2825.44
987.761	2816.45
991.954	2792.37
996.145	2869.05
1000.33	2828.98
1004.52	2835.86
1008.71	2829.58
1012.89	2884
1017.07	2911.84
1021.25	2927.87
1025.43	2997.8
1029.6	3025.13
1033.77	3081.41
1037.95	3097.16
1042.11	3283.58
1046.28	3655.19
1050.45	4200.81
1054.61	4234.66
1058.77	3867.14
1062.93	3517.86
1067.09	3303.74
1071.24	3250.13
1075.4	3333.12
1079.55	3526.12
1083.7	3880.54
1087.85	4275.65
1091.99	4350.3
1096.14	4076.68
1100.28	3868.45
1104.42	3938.33
1108.55	4170.21
1112.69	4106.11
1116.82	3959.13
1120.96	3828.07
1125.09	3853.81
1129.21	3929.02
1133.34	3961.58
1137.46	3779.34
1141.59	3516.72
1145.71	3421.63
1149.83	3467.62
1153.94	3738.63
1158.06	3855.64
1162.17	3642.84
1166.28	3445.97
1170.39	3351.03
1174.5	3192.51
1178.6	3157.61
1182.7	3110.32
1186.8	3168.62
1190.9	3097.68
1195	3105.78
1199.1	3155.59
1203.19	3118.28
1207.28	3085.25
1211.37	3089.03
1215.46	3089.84
1219.54	3237.09
1223.63	3271.53
1227.71	3172.01
1231.79	3236.01
1235.87	3372.9
1239.95	3436.32
1244.02	3313.5
1248.09	3255.02
1252.16	3139.41
1256.23	3117.19
1260.3	3042.41
1264.36	3048.07
1268.43	3060.48
1272.49	3090.04
1276.55	3096.45
1280.6	3028.29
1284.66	3084.86
1288.71	3046.79
1292.76	3113.7
1296.81	3116.05
1300.86	3074.51
1304.91	3074.74
1308.95	3090.21
1312.99	3135.85
1317.03	3175.34
1321.07	3110.73
1325.11	3168.16
1329.14	3154.83
1333.18	3122.18
1337.21	3170.04
1341.24	3173.39
1345.26	3162.53
1349.29	3171.71
1353.31	3167.03
1357.33	3182.21
1361.35	3203.2
1365.37	3189.46
1369.39	3214.61
1373.4	3240.61
1377.41	3164.37
1381.43	3228.19
1385.43	3200.73
1389.44	3197.25
1393.45	3205.01
1397.45	3191.75
1401.45	3274.32
1405.45	3160.25
1409.45	3189.33
1413.44	3219.64
1417.44	3198.56
1421.43	3251.34
1425.42	3255.63
1429.41	3308.2
1433.39	3292.53
1437.38	3351.36
1441.36	3303.67
1445.34	3345.11
1449.32	3333.14
1453.3	3287.93
1457.27	3281.93
1461.24	3355.7
1465.22	3244.7
1469.19	3289.5
1473.15	3265.61
1477.12	3339.09
1481.09	3358.35
1485.05	3344.06
1489.01	3303.44
1492.97	3316.85
1496.93	3276.75
1500.88	3407.58
1504.83	3342.57
1508.79	3375.5
1512.74	3332.66
1516.68	3333.89
1520.63	3343.19
1524.57	3355.59
1528.52	3393.56
1532.46	3360.08
1536.4	3408.02
1540.33	3409.54
1544.27	3373.25
1548.2	3370.91
1552.14	3386.75
1556.07	3438.83
1559.99	3422.68
1563.92	3418.78
1567.84	3420.37
1571.77	3434.38
1575.69	3424.18
1579.61	3382.01
1583.52	3414.93
1587.44	3470.69
1591.35	3524.39
1595.27	3475.12
1599.18	3500.04
1603.09	3539.78
1606.99	3462.81
1610.9	3452.16
1614.8	3469.73
1618.7	3505.63
1622.6	3537.72
1626.5	3538.9
1630.39	3500.62
1634.29	3499.32
1638.18	3540.25
1642.07	3522.95
1645.96	3482.07
1649.85	3569.91
1653.73	3551.23
1657.62	3545.68
1661.5	3520.52
1665.38	3543.73
1669.26	3563.39
1673.13	3571.68
1677.01	3636.69
1680.88	3550.11
1684.75	3582.27
1688.62	3620.55
1692.49	3612.11
1696.35	3617.5
1700.22	3640.29
1704.08	3605.06
1707.94	3663.29
1711.8	3627.05
1715.66	3698.11
1719.51	3633.92
1723.37	3721.61
1727.22	3595.85
1731.07	3680.71
1734.92	3713.71
1738.76	3667.54
1742.61	3662.51
1746.45	3723.99
1750.29	3705.53
1754.13	3642.35
1757.97	3697.74
1761.81	3644.42
1765.64	3680.58
1769.47	3633.6
1773.31	3735.19
1777.14	3720.25
1780.96	3670.87
1784.79	3691.82
1788.61	3681.3
1792.43	3695.22
1796.25	3757.03
1800.07	3722.57
1803.89	3686.59
1807.71	3749.36
1811.52	3795.56
1815.33	3749.99
1819.14	3758.71
1822.95	3723.28
1826.76	3683.23
1830.56	3760.94
1834.37	3778.45
1838.17	3793.46
1841.97	3841.48
1845.77	3817
1849.56	3839.66
1853.36	3801.77
1857.15	3762.09
1860.94	3813.05
1864.73	3875.97
1868.52	3857.47
1872.31	3855.41
1876.09	3867.74
1879.87	3870
1883.66	3854.71
1887.43	3835.54
1891.21	3846.21
1894.99	3806.91
1898.76	3798.07
1902.53	3852.13
1906.31	3918.68
1910.08	3909.82
1913.84	3854.7
1917.61	3869.33
1921.37	3951.11
1925.14	3865.75
1928.9	3931.12
1932.66	3885.08
1936.41	3848.03
1940.17	3901.4
1943.92	3957.64
1947.68	3934.62
1951.43	3917.55
1955.18	3937.15
1958.92	4039.26
1962.67	3998.24
1966.41	4003.74
1970.16	3960.26
1973.9	3969.51
1977.64	3967.63
1981.37	4027.81
1985.11	3953.61
1988.84	4003.28
1992.57	4019.22
1996.31	4001.03
2000.03	4070.39
2003.76	4004.12
2007.49	4079.65
2011.21	4101.25
2014.93	4096.27
2018.65	4068.42
2022.37	4051.61
2026.09	4062.65
2029.81	4001.53
2033.52	4051.38
2037.23	4093.7
2040.94	4040.12
2044.65	4085.73
2048.36	4024.19
2052.07	4073.98
2055.77	4044.79
2059.47	4012.43
2063.17	4042
2066.87	4102.52
2070.57	4051.77
2074.27	4098.87
2077.96	4116.06
2081.65	4109.04
2085.34	4150.59
2089.03	4119.82
2092.72	4172.94
2096.41	4186.97
2100.09	4123.55
2103.77	4140.36
2107.46	4184.33
2111.14	4097.74
2114.81	4249.94
2118.49	4186.13
2122.16	4259.06
2125.84	4249
2129.51	4250.21
2133.18	4242.06
2136.85	4261.98
2140.51	4222.02
2144.18	4254.49
2147.84	4215.98
2151.5	4272.13
2155.16	4259.64
2158.82	4263.92
2162.48	4265.28
2166.13	4345.72
2169.79	4274.2
2173.44	4264.65
2177.09	4284.54
2180.74	4284.8
2184.38	4248.71
2188.03	4253.76
2191.67	4243.02
2195.32	4280.28
2198.96	4336.23
2202.6	4299.85
2206.23	4349.08
2209.87	4279.27
2213.5	4320.53
2217.14	4292.24
2220.77	4309.08
2224.4	4277.19
2228.03	4373.09
2231.65	4412.46
2235.28	4479.83
2238.9	4457.27
2242.52	4511.61
2246.14	4397.81
2249.76	4407.01
2253.38	4412.96
2256.99	4379.82
2260.6	4339.59
2264.21	4461.28
2267.82	4359
2271.44	4420.04
2275.04	4408.78
2278.65	4335.36
2282.25	4383.33
2285.85	4425.7
2289.45	4425.72
2293.05	4402.86
2296.65	4374.59
2300.25	4482.36
2303.84	4433.75
2307.43	4412.8
2311.02	4441.49
2314.62	4460.88
2318.2	4516.33
2321.79	4493.1
2325.38	4443.31
2328.96	4473.16
2332.54	4524.66
2336.12	4426.72
2339.7	4590.86
2343.28	4552.13
2346.85	4530.82
2350.43	4445.76
2354	4495.21
2357.57	4572.12
2361.14	4534.14
2364.71	4570.72
2368.27	4564.38
2371.84	4574.31
2375.4	4565.26
2378.96	4583.54
2382.52	4588.48
2386.08	4636.27
2389.64	4502.2
2393.19	4561.22
2396.75	4594.2
2400.3	4540.31
2403.85	4580.69
2407.4	4598.11
2410.95	4592.7
2414.49	4533.89
2418.04	4593.68
2421.58	4512.59
2425.12	4506.27
2428.66	4519.4
2432.2	4595.56
2435.74	4581.82
2439.27	4570.18
2442.81	4613.76
2446.34	4558
2449.87	4581.71
2453.4	4550.68
2456.93	4603.93
2460.45	4642.97
2463.98	4623.74
2467.5	4601.1
2471.02	4708.72
2474.54	4601.63
2478.06	4602.92
2481.58	4690.96
2485.09	4710.32
2488.61	4685.4
2492.12	4717.4
2495.63	4643.07
2499.14	4674.53
2502.65	4660.17
2506.15	4639.62
2509.66	4713.7
2513.16	4732.73
2516.66	4693.31
2520.16	4702.74
2523.66	4722.98
2527.16	4649.38
2530.66	4641.15
2534.15	4710.89
2537.64	4685.55
2541.13	4713.86
2544.62	4682.83
2548.11	4709.5
2551.6	4772.05
2555.08	4680.97
2558.57	4674.05
2562.05	4698.67
2565.53	4748.28
2569.01	4756.54
2572.49	4674.95
2575.96	4705.66
2579.44	4707.77
2582.91	4763.94
2586.38	4722.17
2589.85	4714.74
2593.32	4726.49
2596.79	4680.46
2600.25	4709.19
2603.72	4723.44
2607.18	4797.6
2610.64	4761.15
2614.1	4708.49
2617.56	4720.37
2621.02	4762.04
2624.47	4707.19
2627.92	4732.25
2631.38	4777.4
2634.83	4792.15
2638.28	4760.99
2641.72	4809.06
2645.17	4695.37
2648.61	4850.96
2652.06	4773.43
2655.5	4754.86
2658.94	4791.73
2662.38	4788.08
2665.82	4791.04
2669.25	4793.4
2672.69	4789.87
2676.12	4813.21
2679.55	4801.91
2682.98	4834.76
2686.41	4822.01
2689.84	4791.82
2693.26	4777.02
2696.69	4814.39
2700.11	4799.48
2703.53	4828.96
2706.95	4799.02
2710.37	4815.95
2713.79	4853.39
2717.2	4768.92
2720.62	4804.42
2724.03	4769.41
2727.44	4775.03
2730.85	4829.95
2734.26	4779.08
2737.66	4807.86
2741.07	4871.52
2744.47	4846.88
2747.87	4851.4
2751.28	4772.09
2754.67	4786.71
2758.07	4844.4
2761.47	4755.62
2764.86	4811.24
2768.26	4847.93
2771.65	4812.72
2775.04	4826.63
2778.43	4867.99
2781.82	4832.62
2785.2	4740.61
2788.59	4873.34
2791.97	4795.94
2795.35	4850.58
2798.73	4842.1
2802.11	4834.6
2805.49	4793.37
2808.87	4863.29
2812.24	4847.78
2815.62	4786.05
2818.99	4891.27
2822.36	4879.62
2825.73	4780.66
2829.1	4837.01
2832.46	4829.97
2835.83	4847.94
2839.19	4837.02
2842.55	4773.06
2845.91	4858.73
2849.27	4816.16
2852.63	4806.04
2855.99	4784.3
2859.34	4791.38
2862.69	4848.3
2866.05	4807.12
2869.4	4813.34
2872.75	4855.13
2876.09	4891.2
2879.44	4895.25
2882.78	4857.41
2886.13	4872.92
2889.47	4792.47
2892.81	4911.77
2896.15	4848.02
2899.49	4806.15
2902.82	4929.09
2906.16	4896.53
2909.49	4859.62
2912.82	4929.62
2916.16	4836.88
2919.49	4981.23
2922.81	4881.4
2926.14	4964.97
2929.46	4986.8
2932.79	5014.99
2936.11	5065.75
2939.43	4964.72
2942.75	4976.89
2946.07	4953.62
2949.39	4921.75
2952.7	4953.62
2956.02	4879.21
2959.33	4872.31
2962.64	4870.89
2965.95	4878.09
2969.26	4874.13
2972.57	4959.33
2975.87	4886.07
2979.17	4940.27
2982.48	4837.06
2985.78	4995.18
2989.08	4834.22
2992.38	4805.84
2995.68	4859.55
2998.97	4903.04
3002.27	4866.34
3005.56	4761.39
3008.85	4814.76
3012.14	4863.72
3015.43	4766.49
3018.72	4767.14
3022	4722.46
3025.29	4766.6
3028.57	4837.21
3031.85	4791.42
3035.14	4799.23
3038.41	4757.91
3041.69	4726.98
3044.97	4805.11
3048.24	4827.23
3051.52	4786.14
3054.79	4725.92
3058.06	4687.84
3061.33	4768.14
3064.6	4798.6
3067.87	4711.67
3071.13	4761.44
3074.4	4733.09
3077.66	4755.02
3080.92	4768.22
3084.18	4739.68
3087.44	4752.81
3090.7	4737.56
3093.95	4798.31
3097.21	4754.17
3100.46	4723.36
3103.71	4752.05
3106.96	4739.13
3110.21	4806.65
3113.46	4793.14
3116.71	4757
3119.95	4798.03
3123.2	4775.19
3126.44	4775.07
3129.68	4745.43
3132.92	4758.61
3136.16	4758.2
3139.4	4823.45
3142.63	4760.93
3145.87	4800.67
3149.1	4742.37
3152.33	4803.13
3155.56	4747.59
3158.79	4800.71
3162.02	4816.63
3165.25	4720.56
3168.47	4825.47
3171.69	4725.94
3174.92	4848.37
3178.14	4789.32
3181.36	4797.18
3184.58	4804.62
3187.79	4772.71
3191.01	4760.8
3194.22	4791.71
3197.43	4745.33
3200.65	4763.85
3203.86	4786.34
3207.07	4823.29
3210.27	4812
3213.48	4748.75
3216.69	4772.16
3219.89	4755.71
3223.09	4753.96
3226.29	4804.7
3229.49	4804.47
3232.69	4722.09
3235.89	4729.93
3239.08	4787.75
3242.28	4762.08
3245.47	4790.71
3248.66	4776.87
3251.85	4772.79
3255.04	4851.77
3258.23	4779.41
3261.42	4699.63
3264.6	4755.73
3267.79	4651.76
3270.97	4763.31
3274.15	4738.25
3277.33	4730.59
3280.51	4760.08
3283.68	4792.37
3286.86	4756.49
3290.04	4778.14
3293.21	4778.76
3296.38	4719.17
3299.55	4805.57
3302.72	4711.21
3305.89	4716.23
3309.06	4783.24
3312.22	4712.97
3315.39	4737.57
3318.55	4836.83
3321.71	4757.83
3324.87	4804.88
3328.03	4705.32
3331.19	4730.94
3334.34	4730.46
3337.5	4774.77
3340.65	4782.24
3343.81	4818.91
3346.96	4762.71
3350.11	4737.71
3353.25	4735.81
3356.4	4769.02
3359.55	4800.01
3362.69	4732.18
3365.84	4730.59
3368.98	4727.25
3372.12	4785.82
3375.26	4720.98
3378.4	4757.52
3381.53	4781.53
3384.67	4749.18
3387.8	4773.66
3390.94	4808.83
3394.07	4756.86
3397.2	4804.83
3400.33	4861.31
3403.46	4961.11
3406.58	4987.31
3409.71	5280.22
3412.83	5702.95
3415.96	6796.85
3419.08	9491.61
3422.2	10874.6
3425.32	8785.45
3428.44	6478.21
3431.55	5461.38
3434.67	5176.25
3437.78	4971.86
3440.89	4916.68
3444	4821.32
3447.12	4715.45
3450.22	4744.23
3453.33	4729.11
3456.44	4735.18
3459.54	4703.04
3462.65	4784.79
3465.75	4694.16
3468.85	4693.27
3471.95	4696.61
3475.05	4693.76
3478.15	4761.17
3481.24	4722.7
3484.34	4836.64
3487.43	4908.37
3490.53	5010.9
3493.62	5108.85
3496.71	5351.43
3499.79	5611.3
3502.88	5735.01
3505.97	5668.73
3509.05	5511.18
3512.14	5160.41
3515.22	5033.71
3518.3	4812.52
3521.38	4737.26
3524.46	4684.83
3527.54	4690.95
3530.61	4559.5
3533.69	4578.49
3536.76	4518.26
3539.83	4464.98
3542.9	4472.85
3545.97	4571.67
3549.04	4496.03
3552.11	4512.1
3555.18	4479.69
3558.24	4477.1
3561.3	4429.89
3564.37	4462.83
3567.43	4456.19
3570.49	4461.11
3573.55	4406.72
3576.61	4422.32
3579.66	4353.14
3582.72	4463.76
3585.77	4439.56
3588.82	4426.34
3591.87	4456.48
3594.92	4394.35
3597.97	4353.95
3601.02	4335.02
3604.07	4432.13
3607.11	4358.75
3610.16	4357.13
3613.2	4357.18
3616.24	4316.72
3619.28	4401.05
3622.32	4308.15
3625.36	4283.47
3628.39	4399.09
3631.43	4319.37
3634.46	4287.51
3637.5	4287.44
3640.53	4305.73
3643.56	4290.29
3646.59	4303.34
3649.62	4296.25
3652.64	4235.57
3655.67	4263.35
3658.69	4226.84
3661.72	4277.29
3664.74	4210.97
3667.76	4267.35
3670.78	4147.84
3673.79	4194.53
3676.81	4182.06
3679.83	4262.05
3682.84	4186.1
3685.86	4209.5
3688.87	4240.63
3691.88	4114.69
3694.89	4149.97
3697.9	4147.83
3700.91	4146.9
3703.91	4164
3706.92	4129.43
3709.92	4123.95
3712.92	4158.82
3715.92	4073.01
3718.92	4115.34
3721.92	4125.87
3724.92	4148.42
3727.92	4103.99
3730.91	4112.53
3733.91	4137.74
3736.9	4169.22
3739.89	4133.59
3742.88	4088.09
3745.87	4153.47
3748.86	4103.45
3751.85	4050.48
3754.83	4091.62
3757.82	4126.03
3760.8	4108.89
3763.78	4105
3766.76	4152.47
3769.74	4073.51
3772.72	4111.26
3775.7	4010.3
3778.67	4111.87
3781.65	4081.24
3784.62	4064.99
3787.6	4070.67
3790.57	4047.66
3793.54	4100.6
3796.51	4000.85
3799.47	4029.98
3802.44	4010.32
3805.41	4038.95
3808.37	4025.31
3811.33	4039.22
3814.3	4033.38
3817.26	4055.13
3820.22	3995.58
3823.18	4013.91
3826.13	4018.17
3829.09	3984.44
3832.04	4002.21
3835	3960.46
3837.95	3968.12
3840.9	3998.58
3843.85	4031.99
3846.8	4004.63
3849.75	3981.28
3852.69	4017.16
3855.64	4004.46
3858.58	3928.74
3861.53	3961.72
3864.47	4008.16
3867.41	4060.13
3870.35	3966.26
3873.29	3994.96
3876.22	3930.16
3879.16	3983.99
3882.1	3995.09
3885.03	3970.27
3887.96	3956.77
3890.89	3960.44
3893.82	3974.24
3896.75	3959.62
3899.68	3946.83
3902.61	3910.38
3905.53	3990.65
3908.46	3986.12
3911.38	3937.03
3914.3	3967.2
3917.23	3905.91
3920.15	3925.74
3923.06	3941.19
3925.98	3860.33
3928.9	3910.47
3931.81	3852.07
3934.73	3908.47
3937.64	3891.1
3940.55	3950.1
3943.46	3916.28
3946.37	3843.58
3949.28	3928.24
3952.19	3834.94
3955.09	3881.8
3958	3842.68
3960.9	3946.51
3963.8	3874.22
3966.71	3845.24
3969.61	3849.99
3972.51	3848.96
3975.4	3865.97
3978.3	3804.85
3981.2	3883.96
3984.09	3846.56
3986.99	3916.85
3989.88	3794.11
3992.77	3861.51
3995.66	3863.53
3998.55	3820.48
4001.43	3848.72
4004.32	3806.85
4007.21	3793
4010.09	3824.39
4012.98	3821.11
4015.86	3789.85
4018.74	3775.92
4021.62	3750.38
4024.5	3820.55
4027.37	3801.87
4030.25	3861.62
4033.13	3815.98
4036	3812.09
4038.87	3794.7
4041.75	3765.04
4044.62	3780.85
4047.49	3738.74
4050.35	3770.51
4053.22	3744.38
4056.09	3745.51
4058.95	3709.51
4061.82	3785.21
4064.68	3751.11
4067.54	3724.71
4070.4	3707.97
4073.26	3733.05
4076.12	3689.88
4078.98	3737.3
4081.83	3709.69
4084.69	3651.73
4087.54	3711.69
4090.4	3729.89
4093.25	3703.16
4096.1	3692.92
4098.95	3709.19
4101.8	3739
4104.64	3716.69
4107.49	3683.38
4110.33	3723.3
4113.18	3696.2
4116.02	3625.6
4118.86	3596.86
4121.7	3668.28
4124.54	3674.41
4127.38	3690.88
4130.22	3699.41
4133.05	3696.02
4135.89	3634.73
4138.72	3703.15
4141.56	3606.66
4144.39	3643.95
4147.22	3618.9
4150.05	3643.43
4152.88	3663.79
4155.7	3623.93
4158.53	3617.43
4161.36	3617.94
4164.18	3619.45
4167	3621.99
4169.82	3548.47
4172.65	3598.31
4175.46	3559.2
4178.28	3575.99
4181.1	3615.51
4183.92	3575.95
4186.73	3565.89
4189.55	3554.21
4192.36	3580.23
4195.17	3637.09
4197.98	3516.75
4200.79	3546.3
4203.6	3552.36
4206.41	3533.82
4209.21	3551.59
4212.02	3589.93
4214.83	3547.89
4217.63	3525.46
4220.43	3584.28
4223.23	3497.75
4226.03	3521.84
4228.83	3579.06
4231.63	3515.84
4234.42	3510.34
4237.22	3480.11
4240.01	3472.74
4242.81	3510.32
4245.6	3523.05
4248.39	3439.67
4251.18	3482.79
4253.97	3510.79
4256.76	3506.61
4259.55	3424.33
4262.33	3441.38
4265.12	3491.83
4267.9	3459.97
4270.68	3518.59
4273.47	3414.5
4276.25	3445.85
4279.03	3432.48
4281.8	3443.05
4284.58	3434.99
4287.36	3425.5
4290.13	3389.44
4292.91	3455.89
4295.68	3471.14
4298.45	3405.16
4301.22	3469.81
4303.99	3348.75
4306.76	3381.02
4309.53	3382.1
4312.3	3404.35
4315.06	3395.61
4317.83	3379.5
4320.59	3330.53
4323.35	3382.12
4326.11	3389.95
4328.87	3369.12
4331.63	3297.26
4334.39	3369.99
4337.15	3404.22
4339.9	3321.6
4342.66	3360.43
4345.41	3316
4348.17	3325.75
4350.92	3341.15
4353.67	3323.06
4356.42	3317.98
4359.17	3285.18
4361.91	3266.77
4364.66	3288.3
4367.41	3323.21
4370.15	3274.9
4372.89	3267.23
4375.63	3287.11
4378.38	3320.18
4381.12	3262.97
4383.86	3213.44
4386.59	3269.9
4389.33	3261.41
4392.07	3245.31
4394.8	3253.67
4397.53	3245.09
4400.27	3272.69
4403	3275.39
4405.73	3195.2
4408.46	3241.49
4411.19	3205.18
4413.92	3241.45
4416.64	3206.02
4419.37	3193.26
4422.09	3263.45
4424.82	3272.15
4427.54	3163.79
4430.26	3173.44
4432.98	3208.09
4435.7	3196.54
4438.42	3192.04
4441.13	3192.7
4443.85	3207.98
4446.57	3174.89
4449.28	3238.22
4451.99	3137.55
4454.71	3179.55
4457.42	3137.25
4460.13	3133
4462.83	3099.43
4465.54	3112.2
4468.25	3092.51
4470.95	3161.51
4473.66	3083.33
4476.36	3093.89
4479.07	3176.46
4481.77	3135.62
4484.47	3105.13
4487.17	3113.65
4489.87	3113.2
4492.56	3107.31
4495.26	3093.79
4497.96	3095.13
4500.65	3030.2
4503.34	3069.49
4506.04	3116.37
4508.73	3066.75
4511.42	3041.55
4514.11	3056.81
4516.8	3023.19
4519.48	3019.75
4522.17	3067.43
4524.85	3042.63
4527.54	3003.02
4530.22	2991.11
4532.9	2937.74
4535.58	2951.52
4538.27	3031.9
4540.94	3006.44
4543.62	3006.78
4546.3	2976.07
4548.98	2953.97
4551.65	2901.42
4554.33	2936.95
4557	2985.47
4559.67	2936.61
4562.34	2935.63
4565.01	2917.94
4567.68	2885.13
4570.35	2938.87
4573.02	2938.82
4575.68	2939.45
4578.35	2914.79
4581.01	2964.05
4583.67	2928.06
4586.34	2855.96
4589	2908.86
4591.66	2904.87
4594.31	2882.17
4596.97	2857.54
4599.63	2825.9
4602.29	2847.07
4604.94	2875.92
4607.59	2828.17
4610.25	2863.66
4612.9	2874.95
4615.55	2863.24
4618.2	2878.21
4620.85	2833.64
4623.5	2789.87
4626.14	2874.95
4628.79	2832.09
4631.43	2813.02
4634.08	2769.26
4636.72	2795.25
4639.36	2785.59
4642	2789.81
4644.64	2875.79
4647.28	2786.03
4649.92	2724.65
4652.56	2798.18
4655.19	2793.26
4657.83	2804.52
4660.46	2778.54
4663.1	2773.8
4665.73	2745.45
4668.36	2751.05
4670.99	2781.23
4673.62	2753.13
4676.24	2764.22
4678.87	2796.55
4681.5	2732.29
4684.12	2718.56
4686.75	2730.65
4689.37	2765.5
4691.99	2723.45
4694.61	2719.59
4697.23	2709.02
4699.85	2741.4
4702.47	2666.12
4705.09	2720.71
4707.7	2731.12
4710.32	2690.56
4712.93	2722.39
4715.55	2681.51
4718.16	2644.08
4720.77	2644.74
4723.38	2666.23
4725.99	2708.41
4728.6	2683.69
4731.21	2693.03
4733.81	2639.88
4736.42	2738.71
4739.02	2661.42
4741.63	2669.02
4744.23	2707.4
4746.83	2650.69
4749.43	2696.5
4752.03	2683.16
4754.63	2634.37
4757.23	2593.77
4759.82	2645.68
4762.42	2634.98
4765.01	2608.78
4767.61	2678.01
4770.2	2636.92
4772.79	2601.54
4775.38	2541.08
4777.97	2592.44
4780.56	2611.86
4783.15	2582.19
4785.74	2573.07
4788.32	2600.62
4790.91	2586.01
4793.49	2562.2
4796.07	2571.92
4798.66	2602.48
4801.24	2582.75
4803.82	2487.42
4806.4	2534.94
4808.98	2557.07
4811.55	2527.56
4814.13	2541.93
4816.71	2533.55
4819.28	2541.3
4821.85	2466.88
4824.43	2476.97
4827	2515.94
4829.57	2525.2
4832.14	2477.39
4834.71	2521.92
4837.28	2518.96
4839.84	2518.45
4842.41	2471.71
4844.97	2514.91
4847.54	2454.52
4850.1	2452.38
4852.66	2489.88
4855.22	2461.77
4857.78	2478.38
4860.34	2468.56
4862.9	2441.15
4865.46	2455.79
4868.01	2461.01
4870.57	2507.06
4873.12	2422.32
4875.68	2425.28
4878.23	2397.26
4880.78	2376.13
4883.33	2414.35
4885.88	2437.19
4888.43	2436.35
4890.98	2416.33
4893.53	2402.19
4896.07	2371.23
4898.62	2407.02
4901.16	2424.81
4903.7	2377.1
4906.25	2436.45
4908.79	2400.06
4911.33	2375.24
4913.87	2372.92
4916.41	2353.94
4918.94	2398.41
4921.48	2342.51
4924.02	2358.41
4926.55	2339.55
4929.08	2398.62
4931.62	2402.11
4934.15	2350.56
4936.68	2328.72
4939.21	2305.04
4941.74	2293.39
4944.27	2302.78
4946.79	2309.83
4949.32	2280.99
4951.85	2361.19
4954.37	2307.18
4956.9	2291.86
4959.42	2325.98
4961.94	2283.67
4964.46	2277.93
4966.98	2310.5
4969.5	2296.89
4972.02	2228.87
4974.53	2263.41
4977.05	2302.9
4979.57	2243.24
4982.08	2253.82
4984.59	2254.78
4987.1	2259.43
4989.62	2277.42
4992.13	2236.96
4994.64	2235.61
4997.15	2252.79
4999.65	2248.08