File: Data/3-Raman/raw/bu19w-e-ff11b-fi02-v_150 (500nm)_532nm_edge_100%_x100_vis_h50um_30sx2_01.txt
#Acq. time (s)=	30
#Accumulations=	2
#Range (cm-¹)=	100...5000
#Windows=	1
#Auto scanning=	Off
#Autofocus=	Off
#Macrospot=	Off
#AutoExposure=	Off
#Spike filter=	Multiple accum.
#Delay time (s)=	2
#Binning=	1
#Readout mode=	Signal
#DeNoise=	Off
#ICS correction=	On
#Dark correction=	Off
#Inst. Process=	Off
#Detector Gain=	Best Dynamic
#Detector ADC=	50 kHz HS
#Detector temperature (°C)=	-60.09
#Instrument=	LabRAM HR Evol
#Detector=	SIN-EM FIVIS
#Objective=	x100_VIS
#Grating=	150 (500nm)
#ND Filter=	100%
#Laser=	532nm_Edge
#Hole=	49.98
#Temperature=	0
#Range=	Visible
#StageXY=	75x50mm Scan+
#StageZ=	Z motor
#X (µm)=	0
#Y (µm)=	0
#Z (µm)=	-251.2
#Full time(mm:ss)=	1:04
#Project=	21_11_04
#Sample=	BU19w
#Site=
#Title=	BU19w-E-FF11b-FI02-V_150 (500nm)_532nm_Edge_100%_x100_VIS_H50um_30sX2
#Remark=
#Date=	04.11.2021 18:20
#Acquired=	04.11.2021 18:20:45
101.869	4733.86
106.493	4333.18
111.113	4522.09
115.732	5965.61
120.349	6584.03
124.964	4888.81
129.577	3192.37
134.185	2633.01
138.793	2398.06
143.399	2191.15
148.003	2027.69
152.602	1903.96
157.201	1879
161.798	1937.73
166.392	2097
170.982	2339.55
175.572	2841.72
180.16	3656.02
184.745	4968.31
189.326	6508.23
193.907	7812.27
198.486	7989.78
203.06	7036.79
207.634	5506.05
212.206	4129.72
216.776	3146.19
221.341	2435.49
225.906	1954.6
230.469	1717.96
235.028	1563.2
239.586	1369.39
244.142	1286.58
248.694	1498.84
253.246	1874.99
257.795	1907.31
262.341	1315.93
266.886	921.234
271.428	790.57
275.967	754.759
280.505	696.137
285.041	657.282
289.573	662.524
294.105	631.785
298.632	620.481
303.159	582.412
307.685	613.498
312.205	619.167
316.726	594.032
321.242	571.035
325.758	599.003
330.272	602.739
334.782	606.907
339.292	882.837
343.797	1518.59
348.302	1599.73
352.803	1085.39
357.304	767.512
361.802	654.065
366.297	638.792
370.791	641.374
375.281	650.429
379.77	662.067
384.256	799.679
388.741	899.868
393.223	1024.5
397.704	928.2
402.18	738.632
406.657	691.719
411.13	705.792
415.602	747.272
420.07	781.849
424.538	822.973
429.002	967.401
433.465	1259.34
437.925	1888.82
442.384	3218.82
446.839	6886.17
451.294	15306.5
455.745	22297.2
460.196	18122.2
464.642	9223.43
469.089	4656.44
473.531	2988.39
477.971	2167.89
482.411	1735.95
486.846	1456.29
491.282	1271.72
495.713	1246.67
500.144	1207.49
504.572	1117.96
508.997	1117.66
513.421	964.717
517.842	859.266
522.263	793.38
526.679	767.032
531.093	722.292
535.507	700.815
539.917	705.977
544.327	658.953
548.733	647.839
553.137	645.927
557.54	607.673
561.94	612.185
566.337	608.827
570.734	601.334
575.127	587.729
579.518	591.019
583.909	581.526
588.295	607.772
592.68	579.102
597.064	572.165
601.445	535.698
605.823	536.085
610.201	534.351
614.575	552.687
618.947	563
623.317	546.728
627.686	544.158
632.052	505.627
636.415	544.466
640.777	508.132
645.138	539.107
649.495	527.565
653.85	521.486
658.205	534.857
662.556	548.474
666.905	536.882
671.252	524.126
675.597	542.82
679.941	598.474
684.282	637.968
688.62	703.891
692.957	653.348
697.293	599.706
701.625	545.146
705.955	524.326
710.283	516.834
714.609	524.906
718.933	519.076
723.257	552.206
727.577	523.564
731.894	506.753
736.21	540.301
740.524	543.47
744.835	532.198
749.147	546.175
753.454	523.383
757.759	544.217
762.063	578.475
766.364	576.206
770.663	595.192
774.96	601.934
779.257	652.497
783.55	731.785
787.841	859.989
792.13	933.055
796.417	1126.42
800.702	1220.7
804.985	949.58
809.266	747.176
813.545	659.257
817.821	603.335
822.096	607.872
826.371	608.189
830.641	594.247
834.91	591.325
839.176	574.018
843.441	584.215
847.703	551.19
851.964	560.829
856.222	549.516
860.479	547.018
864.733	557.644
868.986	562.559
873.236	527.798
877.485	560.99
881.731	566.586
885.975	569.735
890.218	551.85
894.458	560.912
898.696	543.711
902.933	557.213
907.167	535.274
911.399	564.569
915.63	521.727
919.858	555.533
924.084	536.266
928.308	494.066
932.531	512.829
936.749	496.111
940.967	502.85
945.184	510.572
949.398	487.272
953.61	480.175
957.821	492.31
962.029	464.078
966.236	448.707
970.44	459.944
974.642	467.023
978.843	449.775
983.041	455.941
987.236	450.455
991.43	446.042
995.623	443.01
999.813	438.157
1004	451.425
1008.19	435.045
1012.37	437.802
1016.55	445.764
1020.73	477.197
1024.91	439.227
1029.09	448.007
1033.27	440.659
1037.44	475.555
1041.61	458.877
1045.78	469.914
1049.94	491.372
1054.11	545.503
1058.27	597.114
1062.43	622.972
1066.59	700.026
1070.75	864.624
1074.9	955.952
1079.05	751.813
1083.2	592.381
1087.35	523.095
1091.5	508.015
1095.65	493.195
1099.79	484.812
1103.93	479.592
1108.07	468.426
1112.21	471.859
1116.34	477.36
1120.48	474.355
1124.61	477.995
1128.74	469.546
1132.86	484.786
1136.99	511.228
1141.11	523.31
1145.23	597.291
1149.35	715.662
1153.47	744.162
1157.59	667.117
1161.7	570.263
1165.82	511.382
1169.92	469.941
1174.03	487.141
1178.14	482.586
1182.24	482.134
1186.35	485.671
1190.45	464.274
1194.55	476.605
1198.64	483.616
1202.74	497.583
1206.83	508.378
1210.92	523.179
1215.01	540.96
1219.1	587.908
1223.18	588.476
1227.27	622.247
1231.35	602.067
1235.43	599.36
1239.5	652.051
1243.58	656.578
1247.65	699.255
1251.72	898.082
1255.8	1018.33
1259.86	922
1263.93	828.676
1267.99	1038.7
1272.06	2816.92
1276.12	4591.12
1280.18	2867.36
1284.23	1156.78
1288.29	800.431
1292.34	747.579
1296.39	743.899
1300.44	676.668
1304.49	684.861
1308.53	691.985
1312.58	664.78
1316.62	668.582
1320.66	662.149
1324.7	656.517
1328.73	676.882
1332.77	682.112
1336.8	680.075
1340.83	684.922
1344.86	722.636
1348.88	699.372
1352.91	733.928
1356.93	786.273
1360.95	880.022
1364.97	907.238
1368.99	949.362
1373.01	1761.52
1377.02	5617.89
1381.03	6678.43
1385.04	3016.26
1389.05	1101.93
1393.06	882.397
1397.06	1077.7
1401.06	1283.97
1405.06	1017.32
1409.06	784.123
1413.06	711.534
1417.05	704.998
1421.05	695.482
1425.04	640.447
1429.03	614.717
1433.01	610.714
1437	610.684
1440.99	612.616
1444.97	552.288
1448.95	564.963
1452.93	572.617
1456.9	559.488
1460.88	552.197
1464.85	569.35
1468.82	556.919
1472.79	571.106
1476.76	568.528
1480.73	575.67
1484.69	555.355
1488.65	549.711
1492.61	570.467
1496.57	568.771
1500.53	547.658
1504.48	551.974
1508.43	594.338
1512.39	543.458
1516.33	575.177
1520.28	555.5
1524.23	545.579
1528.17	576.43
1532.11	576.315
1536.05	585.913
1539.99	559.667
1543.93	575.099
1547.86	547.899
1551.8	554.612
1555.73	553.515
1559.66	568.79
1563.58	568.504
1567.51	574.93
1571.44	568.739
1575.36	563.51
1579.28	565.024
1583.2	570.375
1587.11	548.7
1591.03	578.064
1594.94	555.43
1598.85	547.25
1602.76	552.567
1606.67	556.04
1610.58	560.491
1614.48	536.22
1618.38	554.198
1622.29	506.067
1626.18	510.687
1630.08	501.023
1633.98	476.195
1637.87	511.669
1641.76	496.516
1645.65	465.177
1649.54	458.775
1653.43	465.821
1657.31	467.082
1661.2	451.991
1665.08	452.181
1668.96	434.049
1672.83	451.357
1676.71	434.976
1680.58	425.121
1684.46	410.353
1688.33	421.467
1692.2	412.36
1696.06	410.864
1699.93	392.112
1703.79	417.201
1707.66	403.088
1711.52	395.595
1715.37	393.814
1719.23	397.734
1723.08	392.209
1726.94	398.922
1730.79	392.384
1734.64	399.027
1738.49	393.44
1742.33	382.227
1746.18	371.083
1750.02	367.63
1753.86	373.617
1757.7	366.81
1761.54	375.428
1765.37	389.449
1769.21	370.127
1773.04	378.861
1776.87	379.261
1780.7	365.798
1784.53	379.434
1788.35	366.977
1792.17	371.356
1796	365.438
1799.82	372.642
1803.64	379.647
1807.45	359.298
1811.27	362.441
1815.08	380.617
1818.89	376.007
1822.7	371.289
1826.51	383.482
1830.32	363.505
1834.12	378.319
1837.92	373.273
1841.72	384.165
1845.52	370.524
1849.32	377.588
1853.12	375.112
1856.91	365.992
1860.7	368.923
1864.5	366.207
1868.28	368.179
1872.07	382.228
1875.86	367.626
1879.64	364.188
1883.42	370.122
1887.21	372.388
1890.98	375.04
1894.76	362.101
1898.54	371.243
1902.31	355.687
1906.08	374.265
1909.85	374.476
1913.62	371.13
1917.39	367.814
1921.16	366.556
1924.92	378.315
1928.68	357.702
1932.44	357.498
1936.2	371.262
1939.96	378.532
1943.71	354.02
1947.47	380.031
1951.22	370.162
1954.97	367.636
1958.72	375.252
1962.46	374.276
1966.21	370.46
1969.95	389.071
1973.7	367.174
1977.43	381.783
1981.17	384.125
1984.91	364.904
1988.65	376.481
1992.38	394.486
1996.11	366.787
1999.84	373.458
2003.57	375.476
2007.3	378.387
2011.02	374.729
2014.75	382.132
2018.47	375.901
2022.19	374.486
2025.91	382.451
2029.62	374.898
2033.34	384.869
2037.05	368.476
2040.76	377.665
2044.47	385.004
2048.18	374.941
2051.89	383.269
2055.59	377.887
2059.3	383.671
2063	375.951
2066.7	376.583
2070.4	365.275
2074.1	378.85
2077.79	368.459
2081.49	380.291
2085.18	377.275
2088.87	388.709
2092.56	381.326
2096.25	385.279
2099.93	398.496
2103.61	377.158
2107.3	371.563
2110.98	365.91
2114.66	377.907
2118.33	391.714
2122.01	380.283
2125.68	401.246
2129.36	381.334
2133.03	365.127
2136.7	385.914
2140.36	408.425
2144.03	381.04
2147.7	381.315
2151.36	377.908
2155.02	374.524
2158.68	374.829
2162.34	376.088
2165.99	376.492
2169.65	371.49
2173.3	383.039
2176.95	361.898
2180.6	376.314
2184.25	357.053
2187.9	383.357
2191.54	380.706
2195.18	379.117
2198.83	368.511
2202.47	357.925
2206.11	372.936
2209.74	356.967
2213.38	365.722
2217.01	390.112
2220.64	366.836
2224.27	352.702
2227.9	362.455
2231.53	386.999
2235.16	371.922
2238.78	384.555
2242.4	369.406
2246.02	367.194
2249.64	383.586
2253.26	375.856
2256.88	360.667
2260.49	389.357
2264.11	391.881
2267.72	377.559
2271.33	390.525
2274.93	369.559
2278.54	382.356
2282.15	378.906
2285.75	374.461
2289.35	383.254
2292.95	380.653
2296.55	380.894
2300.15	370.736
2303.74	380.405
2307.34	400.424
2310.93	403.331
2314.52	435.563
2318.11	737.824
2321.7	1082.39
2325.28	752.921
2328.87	489.246
2332.45	387.612
2336.03	394.625
2339.61	375.202
2343.19	383.999
2346.77	396.472
2350.34	368.59
2353.92	367.906
2357.49	380.265
2361.06	380.443
2364.63	368.529
2368.2	376.164
2371.76	371.819
2375.33	384.114
2378.89	375.14
2382.45	383.749
2386.01	368.451
2389.57	385.412
2393.13	372.124
2396.68	377.31
2400.23	378.034
2403.79	383.54
2407.34	379.948
2410.88	381.082
2414.43	366.719
2417.98	375.385
2421.52	380.455
2425.06	358.902
2428.61	375.217
2432.14	362.998
2435.68	373.978
2439.22	372.043
2442.75	376.646
2446.29	343.013
2449.82	389.754
2453.35	368.314
2456.88	363.481
2460.4	375.261
2463.93	387.007
2467.45	352.266
2470.98	364.9
2474.5	378.933
2478.02	349.418
2481.54	380.339
2485.05	368.708
2488.57	354.998
2492.08	365.9
2495.59	360.674
2499.1	379.901
2502.61	369.052
2506.12	390.845
2509.63	357.483
2513.13	379.155
2516.63	381.332
2520.13	371.514
2523.63	367.951
2527.13	361.066
2530.63	364.454
2534.12	391.888
2537.62	371.425
2541.11	359.358
2544.6	370.532
2548.09	371.734
2551.58	354.464
2555.06	380.734
2558.55	360.018
2562.03	357.79
2565.51	372.456
2568.99	371.456
2572.47	361.204
2575.95	373.458
2579.43	364.238
2582.9	375.726
2586.37	389.18
2589.84	378.911
2593.31	370.285
2596.78	352.964
2600.25	364.326
2603.71	369.98
2607.18	351.473
2610.64	369.104
2614.1	377.81
2617.56	382.855
2621.02	362.748
2624.47	370.436
2627.93	358.804
2631.38	373.049
2634.83	381.43
2638.28	382.968
2641.73	387.308
2645.18	370.517
2648.62	359.482
2652.07	375.087
2655.51	370.559
2658.95	386.854
2662.39	386.932
2665.83	362.398
2669.27	373.798
2672.7	359.722
2676.14	375.799
2679.57	365.641
2683	358.408
2686.43	378.376
2689.86	378.031
2693.29	375.985
2696.71	386.881
2700.13	382.964
2703.56	382.797
2706.98	356.579
2710.4	377.137
2713.82	358.709
2717.23	358.022
2720.65	374.181
2724.06	385.757
2727.47	373.105
2730.88	370.737
2734.29	361.787
2737.7	365.936
2741.11	368.206
2744.51	367.591
2747.91	365.037
2751.32	364.365
2754.72	385.307
2758.11	373.27
2761.51	352.762
2764.91	366.999
2768.3	381.188
2771.7	371.751
2775.09	355.691
2778.48	377.253
2781.87	378.03
2785.25	383.482
2788.64	375.746
2792.03	372.707
2795.41	375.29
2798.79	370.369
2802.17	367.263
2805.55	385.726
2808.93	366.688
2812.3	370.118
2815.68	383.807
2819.05	374.104
2822.42	358.875
2825.79	369.837
2829.16	366.83
2832.53	367.6
2835.89	372.165
2839.26	375.86
2842.62	372.177
2845.98	382.557
2849.34	393.081
2852.7	380.398
2856.06	392.861
2859.41	370.798
2862.77	363.716
2866.12	400.685
2869.47	377.69
2872.82	373.404
2876.17	395.427
2879.52	366.652
2882.87	393.402
2886.21	375.843
2889.55	391.278
2892.89	386.887
2896.23	373.883
2899.57	382.564
2902.91	380.785
2906.25	387.471
2909.58	398.857
2912.91	387.501
2916.25	381.8
2919.58	404.421
2922.91	380.665
2926.23	379.584
2929.56	378.445
2932.88	398.987
2936.21	397.731
2939.53	362.533
2942.85	402.761
2946.17	372.332
2949.49	386.178
2952.8	380.247
2956.12	394.059
2959.43	373.181
2962.74	394.591
2966.06	379.417
2969.37	369.05
2972.67	379.402
2975.98	405.7
2979.28	387.992
2982.59	399.316
2985.89	385.324
2989.19	399.517
2992.49	372.406
2995.79	393.213
2999.09	375.521
3002.38	396.366
3005.68	404.054
3008.97	393.9
3012.26	390.349
3015.55	399.053
3018.84	413.413
3022.13	415.519
3025.41	408.189
3028.7	399.915
3031.98	413.355
3035.26	405.047
3038.54	409.012
3041.82	370.408
3045.1	389.515
3048.38	406.752
3051.65	413.58
3054.92	404.313
3058.2	402.608
3061.47	417.849
3064.73	395.205
3068	416.157
3071.27	415.222
3074.54	434.721
3077.8	422.452
3081.06	436.551
3084.32	428.293
3087.58	428.534
3090.84	417.498
3094.1	446.454
3097.35	436.768
3100.61	461.622
3103.86	450.239
3107.11	440.983
3110.36	449.746
3113.61	448.836
3116.86	455.585
3120.11	452.826
3123.35	453.876
3126.59	466.352
3129.84	464.523
3133.08	483.67
3136.32	493.277
3139.55	484.746
3142.79	502.902
3146.03	498.177
3149.26	501.115
3152.49	513.603
3155.72	509.854
3158.95	516.616
3162.18	538.626
3165.41	514.842
3168.64	561.625
3171.86	537.748
3175.08	549.16
3178.31	566.244
3181.53	564.235
3184.75	567.967
3187.96	575.442
3191.18	580.036
3194.4	568.426
3197.61	577.773
3200.82	595.669
3204.03	605.963
3207.24	623.887
3210.45	603.767
3213.66	602.724
3216.86	601.727
3220.07	636.877
3223.27	628.286
3226.48	650.203
3229.68	641.69
3232.87	637.99
3236.07	632.328
3239.27	659.175
3242.47	656.559
3245.66	649.213
3248.85	644.718
3252.04	684.147
3255.23	656.856
3258.42	683.938
3261.61	657.47
3264.8	675.785
3267.98	669.171
3271.16	671.086
3274.35	684.419
3277.53	691.065
3280.71	670.827
3283.89	702.011
3287.06	695.983
3290.24	680.354
3293.41	707.694
3296.58	688.3
3299.76	693.677
3302.93	712.566
3306.1	711.265
3309.26	727.018
3312.43	714.124
3315.59	744.881
3318.76	729.084
3321.92	716.127
3325.08	732.56
3328.24	739.507
3331.4	753.074
3334.56	764.784
3337.71	762.38
3340.87	777.024
3344.02	779.398
3347.17	767.821
3350.33	779.077
3353.47	784.656
3356.62	784.675
3359.77	816.779
3362.92	810.341
3366.06	825.606
3369.2	834.323
3372.34	844.018
3375.49	858.545
3378.62	852.344
3381.76	820.674
3384.9	852.264
3388.04	865.046
3391.17	886.37
3394.3	850.889
3397.43	862.457
3400.56	874.553
3403.69	873.462
3406.82	899.05
3409.95	912.382
3413.07	920.023
3416.2	884.573
3419.32	902.399
3422.44	909.68
3425.56	900.553
3428.68	902.709
3431.8	910.473
3434.91	915.196
3438.03	896.768
3441.14	913.777
3444.25	905.968
3447.36	922.758
3450.47	926.176
3453.58	919.914
3456.69	896.507
3459.79	911.056
3462.9	915.107
3466	897.256
3469.11	882.165
3472.21	867.853
3475.31	911.634
3478.4	858.859
3481.5	861.057
3484.6	860.436
3487.69	840.986
3490.79	840.552
3493.88	831.873
3496.97	806.194
3500.06	787.064
3503.15	808.529
3506.23	798.725
3509.32	816.271
3512.4	778.927
3515.49	762.422
3518.57	743.763
3521.65	747.972
3524.73	701.9
3527.81	722.365
3530.89	711.343
3533.96	727.568
3537.03	683.002
3540.11	673.4
3543.18	678.315
3546.25	671.71
3549.32	648.632
3552.39	632.921
3555.46	627.524
3558.52	635.48
3561.59	635.891
3564.65	624.792
3567.71	600.315
3570.77	603.523
3573.83	610.226
3576.89	571.433
3579.95	585.702
3583	561.985
3586.06	581.84
3589.11	550.483
3592.16	536.129
3595.21	547.362
3598.27	523.478
3601.31	512.874
3604.36	515.477
3607.41	531.28
3610.45	530.042
3613.5	491.917
3616.54	478.375
3619.58	482.804
3622.62	479.704
3625.66	473.792
3628.69	482.057
3631.73	478.982
3634.77	470.227
3637.8	463.483
3640.83	444.575
3643.86	461.468
3646.89	411.691
3649.92	405.058
3652.95	424.886
3655.98	405.497
3659	402.139
3662.02	407.209
3665.05	397.146
3668.07	384.041
3671.09	394.594
3674.11	374.989
3677.13	360.103
3680.14	371.67
3683.16	364.326
3686.17	348.467
3689.19	362.88
3692.2	347.022
3695.21	341.575
3698.22	354.053
3701.23	351.452
3704.23	341.252
3707.24	352.885
3710.24	345.481
3713.25	336.141
3716.25	337.21
3719.25	345.922
3722.25	333.653
3725.25	330.871
3728.25	329.009
3731.24	329.029
3734.24	325.207
3737.23	322.301
3740.22	331.743
3743.21	332.575
3746.21	327.67
3749.19	316.084
3752.18	313.985
3755.17	323.277
3758.15	329.72
3761.14	308.648
3764.12	311.266
3767.1	328.088
3770.08	312.741
3773.06	319.193
3776.04	332.28
3779.02	309.468
3781.99	316.921
3784.97	323.429
3787.94	317.68
3790.91	341.211
3793.88	308.162
3796.85	306.286
3799.82	307.26
3802.79	308.277
3805.76	311.2
3808.72	320.747
3811.69	310.474
3814.65	331.402
3817.61	312.627
3820.57	310.884
3823.53	316.72
3826.49	301.744
3829.45	309.506
3832.4	330.551
3835.36	333.622
3838.31	312.97
3841.26	314.151
3844.21	292.5
3847.16	313.661
3850.11	317.719
3853.06	314.175
3856	308.722
3858.95	306.13
3861.89	302.581
3864.84	299.006
3867.78	318.41
3870.72	315.775
3873.66	314.086
3876.6	320.06
3879.53	301.998
3882.47	300.217
3885.4	308.969
3888.34	308.089
3891.27	317.773
3894.2	307.251
3897.13	316.883
3900.06	304.358
3902.99	319.715
3905.91	315.793
3908.84	309.032
3911.76	303.205
3914.69	305.998
3917.61	307.801
3920.53	312.548
3923.45	298.032
3926.37	311.315
3929.28	304.419
3932.2	326.257
3935.11	305.05
3938.03	314.561
3940.94	309.772
3943.85	310.695
3946.76	330.782
3949.67	311.647
3952.58	312.643
3955.49	307.904
3958.39	310.855
3961.3	316.698
3964.2	312.974
3967.1	311.183
3970	315.163
3972.9	314.358
3975.8	325.07
3978.7	310.79
3981.6	297.44
3984.49	314.839
3987.39	312.999
3990.28	303.457
3993.17	307.333
3996.06	293.955
3998.95	302.698
4001.84	295.096
4004.73	298.086
4007.61	312.657
4010.5	291.58
4013.38	320.624
4016.27	310.142
4019.15	312.198
4022.03	297.84
4024.91	313.413
4027.79	299.053
4030.66	318.514
4033.54	302.219
4036.42	299.457
4039.29	330.588
4042.16	308.476
4045.03	303.729
4047.9	299.961
4050.77	323.356
4053.64	304.107
4056.51	299.426
4059.38	298.616
4062.24	301.679
4065.1	303.773
4067.97	294.198
4070.83	327.421
4073.69	303.239
4076.55	301.428
4079.41	304.483
4082.26	290.969
4085.12	281.346
4087.97	297.067
4090.83	292.303
4093.68	305.13
4096.53	299.389
4099.38	298.541
4102.23	292.8
4105.08	299.759
4107.93	290.056
4110.77	295.027
4113.62	304.862
4116.46	299.007
4119.3	302.897
4122.14	304.829
4124.98	295.054
4127.82	290.18
4130.66	297.126
4133.5	298.249
4136.33	310.243
4139.17	302.295
4142	315.601
4144.83	325.324
4147.67	311.726
4150.5	289.331
4153.33	299.181
4156.15	301.091
4158.98	291.129
4161.81	298.872
4164.63	296.88
4167.45	294.884
4170.28	305.616
4173.1	302.672
4175.92	303.649
4178.74	306.583
4181.56	289.002
4184.37	288.057
4187.19	292.998
4190	281.315
4192.82	299.032
4195.63	296.231
4198.44	281.712
4201.25	293.64
4204.06	291.859
4206.87	316.569
4209.68	304.971
4212.48	285.489
4215.29	283.68
4218.1	298.76
4220.9	288.251
4223.7	303.337
4226.5	304.59
4229.3	296.995
4232.1	296.326
4234.9	291.728
4237.69	303.999
4240.49	293.468
4243.28	291.866
4246.07	288.286
4248.87	281.69
4251.66	301.007
4254.45	289.374
4257.24	286.694
4260.03	299.029
4262.81	280.314
4265.6	297.714
4268.38	305.124
4271.17	299.463
4273.95	304.864
4276.73	290.042
4279.51	292.313
4282.29	281.43
4285.07	290.725
4287.84	296.958
4290.62	281.908
4293.39	277.97
4296.17	275.078
4298.94	275.247
4301.71	292.638
4304.48	290.758
4307.25	280.753
4310.02	295.132
4312.79	295.323
4315.55	287.335
4318.32	291.52
4321.08	283.473
4323.85	286.597
4326.61	277.488
4329.37	274.494
4332.13	283.696
4334.89	296.988
4337.65	310.258
4340.4	291.99
4343.16	285.953
4345.91	291.158
4348.67	284.151
4351.42	305.723
4354.17	292.666
4356.92	292.856
4359.67	282.813
4362.42	265.579
4365.17	289.311
4367.91	291.532
4370.66	275.324
4373.4	271.363
4376.14	274.573
4378.89	281.871
4381.63	279.92
4384.37	285.18
4387.11	273.024
4389.84	282.572
4392.58	282.917
4395.32	290.702
4398.05	279.714
4400.78	288.335
4403.52	295.914
4406.25	299.372
4408.98	279.995
4411.71	280.305
4414.44	280.573
4417.16	291.248
4419.89	285.141
4422.62	280.113
4425.34	286.584
4428.06	282.619
4430.78	273.42
4433.51	283.036
4436.22	303.123
4438.94	272.93
4441.66	285.654
4444.38	278.468
4447.1	266.012
4449.81	286.089
4452.52	274.651
4455.24	270.553
4457.95	276.938
4460.66	275.954
4463.37	269.745
4466.08	279.307
4468.78	284.683
4471.49	280.6
4474.2	277.591
4476.9	275.658
4479.6	271.635
4482.31	278.18
4485.01	283.679
4487.71	276.476
4490.41	275.601
4493.11	285.244
4495.8	274.72
4498.5	278.015
4501.19	276.002
4503.89	290.916
4506.58	278.306
4509.27	287.969
4511.96	290.213
4514.66	261.68
4517.34	275.612
4520.03	270.44
4522.72	259.976
4525.41	292.058
4528.09	274.136
4530.77	280.703
4533.46	283.021
4536.14	265.084
4538.82	271.682
4541.5	268.695
4544.18	261.421
4546.86	269.127
4549.53	259.713
4552.21	282.464
4554.88	264.534
4557.56	269.16
4560.23	268.503
4562.9	274.359
4565.57	271.676
4568.24	276.65
4570.91	273.893
4573.58	274.076
4576.24	265.433
4578.91	258.004
4581.58	263.716
4584.24	259.714
4586.9	259.9
4589.56	251.348
4592.22	280.945
4594.88	263.646
4597.54	256.197
4600.2	262.916
4602.86	279.544
4605.51	263.37
4608.17	248.264
4610.82	270.437
4613.47	257.502
4616.13	245.639
4618.78	256.868
4621.43	260.427
4624.07	256.267
4626.72	260.905
4629.37	250.08
4632.01	270.17
4634.66	262.606
4637.3	276.033
4639.94	271.761
4642.59	261.946
4645.23	258.83
4647.87	265.764
4650.5	258.334
4653.14	277.688
4655.78	256.9
4658.42	264.735
4661.05	254.934
4663.68	259.68
4666.31	271.115
4668.95	272.427
4671.58	259.211
4674.21	265.018
4676.84	262.981
4679.46	256.446
4682.09	254.387
4684.72	262.44
4687.34	258.134
4689.97	275.21
4692.59	267.536
4695.21	255.318
4697.83	256.615
4700.45	262.434
4703.07	249.053
4705.69	255.974
4708.3	253.849
4710.92	255.105
4713.54	259.755
4716.15	251.943
4718.76	266.766
4721.37	262.33
4723.99	237.47
4726.59	254.584
4729.2	251.309
4731.81	259.384
4734.42	251.568
4737.03	244.872
4739.63	257.478
4742.23	268.95
4744.84	254.242
4747.44	263.406
4750.04	252.048
4752.64	240.696
4755.24	260.068
4757.84	265.781
4760.44	252.167
4763.03	267.035
4765.63	269.396
4768.22	262.701
4770.82	246.906
4773.41	243.587
4776	258.533
4778.59	263.218
4781.18	253.05
4783.77	239.447
4786.36	262.426
4788.94	246.531
4791.53	256.955
4794.11	231.9
4796.7	258.388
4799.28	242.511
4801.86	249.578
4804.44	233.707
4807.02	254.623
4809.6	241.081
4812.18	249.393
4814.76	253.124
4817.33	258.035
4819.91	241.017
4822.48	244.788
4825.06	249.732
4827.63	246.562
4830.2	239.9
4832.77	232.085
4835.34	255.708
4837.91	243.264
4840.48	242.49
4843.04	245.219
4845.61	245.566
4848.17	243.54
4850.74	247.314
4853.3	247.404
4855.86	221.637
4858.42	246.693
4860.98	252.941
4863.54	248.511
4866.1	233.349
4868.66	247.73
4871.21	261.021
4873.77	241.101
4876.32	236.532
4878.88	243.821
4881.43	245.169
4883.98	231.059
4886.53	235.948
4889.08	245.606
4891.63	238.617
4894.18	224.464
4896.72	236.501
4899.27	237.813
4901.81	233.159
4904.36	236.849
4906.9	248.891
4909.44	237.045
4911.98	244.255
4914.52	235.917
4917.06	245.473
4919.6	232.356
4922.14	234.77
4924.67	253.914
4927.21	251.57
4929.74	237.244
4932.28	244.49
4934.81	248.203
4937.34	251.895
4939.87	234.035
4942.4	229.239
4944.93	224.514
4947.46	233.006
4949.99	222.322
4952.51	251.217
4955.04	251.319
4957.56	233.459
4960.08	224.005
4962.61	244.61
4965.13	224.406
4967.65	248.777
4970.17	264.693
4972.69	295.105
4975.2	318.315
4977.72	304.077
4980.24	224.48
4982.75	234.375
4985.27	228.534
4987.78	226.329
4990.29	235.057
4992.8	255.952
4995.31	235.499
4997.82	217.479