File: Data/3-Raman/raw/bu19w-e-ff11-fi01-v_150 (500nm)_633nm_edge_100%_x100_vis_h50um_60sx2_01.txt
#Acq. time (s)=	60
#Accumulations=	2
#Range (cm-¹)=	100...4000
#Windows=	1
#Auto scanning=	Off
#Autofocus=	Off
#Macrospot=	Off
#AutoExposure=	Off
#Spike filter=	Multiple accum.
#Delay time (s)=	2
#Binning=	1
#Readout mode=	Signal
#DeNoise=	Off
#ICS correction=	On
#Dark correction=	Off
#Inst. Process=	Off
#Detector Gain=	Best Dynamic
#Detector ADC=	50 kHz HS
#Detector temperature (°C)=	-60.28
#Instrument=	LabRAM HR Evol
#Detector=	SIN-EM FIVIS
#Objective=	x100_VIS
#Grating=	150 (500nm)
#ND Filter=	100%
#Laser=	633nm_Edge
#Hole=	49.98
#Temperature=	0
#Range=	Visible
#StageXY=	75x50mm Scan+
#StageZ=	Z motor
#X (µm)=	0
#Y (µm)=	0
#Z (µm)=	-289.1
#Full time(mm:ss)=	2:04
#Project=	21_11_04
#Sample=	BU19w
#Site=
#Title=	BU19w-E-FF11-FI01-V_150 (500nm)_633nm_Edge_100%_x100_VIS_H50um_60sX2
#Remark=
#Date=	04.11.2021 16:41
#Acquired=	04.11.2021 16:41:53
102.881	249.315
109.397	216.152
115.908	184.84
122.414	177.325
128.914	169.787
135.409	171.761
141.898	163.153
148.383	154.574
154.861	184.323
161.335	177.721
167.801	139.471
174.264	127.983
180.721	105.885
187.173	110.548
193.62	104.636
200.061	101.647
206.496	107.357
212.926	111.128
219.352	125.387
225.772	176.754
232.185	200.293
238.595	154.466
244.999	119.227
251.397	118.221
257.791	136.178
264.178	130.431
270.561	124.714
276.939	133.246
283.31	136.057
289.678	115.134
296.039	112.195
302.396	117.774
308.746	145.066
315.093	245.031
321.433	286.4
327.768	201.41
334.099	142.898
340.423	123.062
346.743	126.786
353.058	142.731
359.367	137.898
365.671	123.652
371.971	106.619
378.265	101.813
384.553	96.1073
390.837	94.2819
397.116	88.7804
403.389	102.168
409.657	101.439
415.92	101.59
422.178	115.904
428.431	122.412
434.678	123.073
440.921	126.537
447.158	129.95
453.391	141.734
459.618	127.403
465.84	105.801
472.057	96.4085
478.27	93.627
484.477	96.4333
490.679	100.173
496.876	110.449
503.068	121.682
509.255	121.746
515.436	125.577
521.613	124.818
527.785	118.504
533.952	117.873
540.113	101.225
546.27	99.5159
552.423	96.7595
558.568	93.0092
564.711	90.055
570.848	90.7902
576.979	96.1327
583.107	95.8444
589.228	105.884
595.345	115.073
601.458	108.576
607.565	113.406
613.667	114.573
619.764	107.4
625.856	95.5284
631.944	88.1699
638.026	89.1257
644.104	89.937
650.177	92.6166
656.244	89.5715
662.308	90.2647
668.365	76.0445
674.418	74.1356
680.467	75.069
686.511	75.1336
692.549	79.023
698.582	71.703
704.611	73.7271
710.635	80.4106
716.655	70.0162
722.669	67.1588
728.679	69.8793
734.683	69.7542
740.683	76.1724
746.678	76.992
752.669	69.4644
758.654	73.1893
764.635	70.53
770.611	76.351
776.582	76.5648
782.549	79.5392
788.511	67.3873
794.466	73.0937
800.419	74.9686
806.366	76.7822
812.309	78.5569
818.247	72.7594
824.18	69.775
830.108	80.8336
836.033	81.7493
841.952	79.9991
847.865	78.2673
853.776	75.6288
859.681	85.2481
865.58	86.428
871.476	96.1146
877.366	94.3457
883.253	94.4141
889.134	89.6687
895.012	94.3576
900.883	92.2981
906.751	91.129
912.614	86.1784
918.473	88.8201
924.326	103.788
930.174	103.866
936.019	112.522
941.859	134.648
947.693	142.756
953.525	140.457
959.35	140.915
965.171	148.919
970.988	177.009
976.801	192.477
982.608	224.898
988.411	202.523
994.209	166.791
1000	153.166
1005.79	160.635
1011.58	167.342
1017.36	173.228
1023.13	165.829
1028.9	133.653
1034.67	133.057
1040.43	116.124
1046.19	113.588
1051.94	106.111
1057.69	98.5321
1063.44	96.6674
1069.17	103.431
1074.91	107.273
1080.64	116.879
1086.37	142.932
1092.09	180.62
1097.8	176.633
1103.52	143.655
1109.22	125.34
1114.93	113.001
1120.63	114.333
1126.32	113.612
1132.01	125.631
1137.7	145.544
1143.38	177.329
1149.06	212.032
1154.73	167.88
1160.4	107.761
1166.06	100.683
1171.72	81.866
1177.38	87.5671
1183.03	82.5442
1188.67	78.6157
1194.31	80.6222
1199.95	78.8024
1205.58	70.2149
1211.21	74.42
1216.84	67.8108
1222.46	63.1604
1228.07	72.4579
1233.68	73.7666
1239.29	68.9812
1244.89	79.2169
1250.49	83.3324
1256.08	83.347
1261.67	84.2662
1267.26	80.1221
1272.84	238.925
1278.42	110.92
1283.99	77.6337
1289.56	73.517
1295.12	77.4572
1300.68	71.4529
1306.23	80.5254
1311.78	73.6998
1317.33	69.9104
1322.87	76.2166
1328.41	77.5353
1333.94	73.7651
1339.47	71.971
1345	73.1657
1350.52	76.3823
1356.04	71.3632
1361.55	77.5893
1367.06	83.7593
1372.56	99.1394
1378.06	382.551
1383.56	95.979
1389.05	88.751
1394.53	88.765
1400.02	102.258
1405.5	82.8518
1410.97	71.6581
1416.44	76.9789
1421.91	68.8719
1427.37	68.0088
1432.83	68.1859
1438.28	78.7942
1443.73	76.8976
1449.17	71.8161
1454.62	77.1466
1460.05	77.1804
1465.48	70.8738
1470.91	76.1015
1476.34	78.197
1481.76	75.0791
1487.17	75.1349
1492.59	77.3342
1497.99	82.7411
1503.4	72.3535
1508.8	75.7119
1514.19	75.9297
1519.59	75.1117
1524.97	75.372
1530.36	73.4896
1535.74	71.6101
1541.11	79.3699
1546.48	75.1684
1551.85	76.2544
1557.21	80.4801
1562.57	72.845
1567.93	78.1607
1573.28	74.8477
1578.62	74.8122
1583.97	79.1262
1589.3	81.3129
1594.64	79.2275
1599.97	75.0165
1605.3	78.4
1610.62	76.4372
1615.94	82.1413
1621.25	80.2742
1626.56	87.1568
1631.87	78.6748
1637.17	74.4889
1642.47	86.7384
1647.76	82.4444
1653.05	79.2149
1658.34	80.3735
1663.62	88.1608
1668.9	84.8415
1674.18	83.7341
1679.45	85.9373
1684.71	88.0925
1689.98	78.0549
1695.23	83.5737
1700.49	88.1102
1705.74	87.4361
1710.99	84.2087
1716.23	78.6629
1721.47	84.4819
1726.7	84.6177
1731.94	80.3024
1737.16	86.0877
1742.39	87.38
1747.61	84.1465
1752.82	87.648
1758.03	82.0636
1763.24	90.0167
1768.44	86.6618
1773.64	87.8505
1778.84	86.8091
1784.03	88.0804
1789.22	90.5324
1794.41	95.3014
1799.59	90.9675
1804.76	91.2194
1809.94	91.4383
1815.11	91.6343
1820.27	87.212
1825.43	96.6702
1830.59	96.8985
1835.74	92.4882
1840.89	93.8426
1846.04	88.1691
1851.18	90.652
1856.32	91.938
1861.45	92.1048
1866.58	93.4714
1871.71	92.4602
1876.83	90.2257
1881.95	90.334
1887.07	84.5117
1892.18	90.4423
1897.29	94.0022
1902.39	92.9166
1907.49	90.7246
1912.59	96.9262
1917.68	91.2755
1922.77	93.7668
1927.86	101.132
1932.94	92.9315
1938.02	95.4882
1943.09	100.426
1948.16	96.9178
1953.23	98.1806
1958.29	93.394
1963.35	89.7939
1968.41	101.833
1973.46	87.3235
1978.51	110.148
1983.55	96.8515
1988.59	100.416
1993.63	100.384
1998.66	95.5668
2003.69	105.204
2008.72	98.0453
2013.74	104.146
2018.76	101.807
2023.77	98.2726
2028.78	102.024
2033.79	104.627
2038.79	96.3451
2043.79	105.042
2048.79	111.358
2053.78	105.459
2058.77	103.234
2063.76	105.914
2068.74	104.923
2073.72	100.226
2078.69	105.355
2083.66	103.071
2088.63	109.389
2093.59	109.583
2098.55	106.111
2103.51	108.859
2108.46	110.4
2113.41	129.496
2118.36	101.033
2123.3	108.893
2128.24	110.469
2133.17	108.227
2138.11	112.287
2143.03	118.891
2147.96	115.291
2152.88	115.452
2157.79	110.468
2162.71	125.886
2167.62	102.915
2172.52	118.322
2177.43	109.445
2182.32	109.46
2187.22	114.566
2192.11	109.484
2197	113.408
2201.89	112.27
2206.77	117.601
2211.64	107.541
2216.52	116.826
2221.39	110.652
2226.26	121.313
2231.12	108.614
2235.98	115.41
2240.84	110.47
2245.69	119.929
2250.54	118.92
2255.39	117.895
2260.23	111.598
2265.07	114.497
2269.9	125.312
2274.74	122.832
2279.57	117.648
2284.39	119.043
2289.21	112.422
2294.03	119.102
2298.84	115.172
2303.66	108.622
2308.46	124.818
2313.27	129.09
2318.07	136.114
2322.87	143.176
2327.66	119.299
2332.45	127.754
2337.24	133.575
2342.02	120.405
2346.8	115.38
2351.58	118.523
2356.35	125.755
2361.12	132.928
2365.89	130.452
2370.65	123.814
2375.41	118.518
2380.17	117.34
2384.92	134.162
2389.67	125.921
2394.42	128.749
2399.16	131.532
2403.9	132.911
2408.64	125.963
2413.37	133.154
2418.1	125.386
2422.83	114.546
2427.55	118.956
2432.27	129.145
2436.99	129.531
2441.7	134.179
2446.41	128.883
2451.11	139.272
2455.82	126.782
2460.51	128.589
2465.21	130.399
2469.9	130.749
2474.59	135.425
2479.28	127.071
2483.96	133.203
2488.64	133.481
2493.32	142.521
2497.99	132.566
2502.66	137.219
2507.32	130.102
2511.99	145.012
2516.65	127.504
2521.3	133.607
2525.96	129.378
2530.61	141.422
2535.25	140.193
2539.89	146.418
2544.53	134.804
2549.17	144.062
2553.8	127.921
2558.43	140.146
2563.06	140.448
2567.68	136.279
2572.3	151.737
2576.92	143.031
2581.53	138.775
2586.14	138.968
2590.75	139.081
2595.35	142.287
2599.96	150.135
2604.55	145.748
2609.15	138.275
2613.74	144.496
2618.33	146.151
2622.91	141.686
2627.49	154.112
2632.07	148.251
2636.64	156.329
2641.22	152.186
2645.78	146.486
2650.35	148.493
2654.91	156.691
2659.47	138.226
2664.03	149.374
2668.58	144.885
2673.13	153.036
2677.67	156.746
2682.22	144.86
2686.76	151.881
2691.29	157.306
2695.83	135.299
2700.36	146.816
2704.89	153.543
2709.41	155.435
2713.93	147.643
2718.45	151.2
2722.96	149.863
2727.47	148.445
2731.98	148.583
2736.49	156.83
2740.99	153.708
2745.49	145.763
2749.98	147.653
2754.47	156.275
2758.96	151.654
2763.45	158.452
2767.93	165.354
2772.41	155.772
2776.89	154.506
2781.36	156.638
2785.84	153.841
2790.3	152.679
2794.77	153.152
2799.23	166.986
2803.69	157.283
2808.14	154.229
2812.59	164.644
2817.04	161.505
2821.49	158.369
2825.93	162.032
2830.37	162.288
2834.81	157.414
2839.24	154.229
2843.67	161.285
2848.1	158.155
2852.53	149.92
2856.95	176.061
2861.37	143.794
2865.78	163.23
2870.19	167.207
2874.6	146.865
2879.01	176.982
2883.41	158.352
2887.81	171.212
2892.21	154.17
2896.6	160.014
2901	165.932
2905.38	168.234
2909.77	158.017
2914.15	174.488
2918.53	164.124
2922.91	164.533
2927.28	161.389
2931.65	161.869
2936.02	158.646
2940.38	166.221
2944.74	186.543
2949.1	177.688
2953.46	165.173
2957.81	158.093
2962.16	154.665
2966.5	176.92
2970.85	188.262
2975.19	173.895
2979.52	165.003
2983.86	178.3
2988.19	178.754
2992.52	173.68
2996.85	179.768
3001.17	163.517
3005.49	180.947
3009.8	177.788
3014.12	168.908
3018.43	175.195
3022.74	168.212
3027.04	180.144
3031.34	180.6
3035.64	184.804
3039.94	185.166
3044.23	172.071
3048.52	180.075
3052.81	178.449
3057.09	176.845
3061.38	188.774
3065.65	185.228
3069.93	191.38
3074.2	178.097
3078.47	199.881
3082.74	188.529
3087	183.081
3091.27	187.509
3095.52	195.979
3099.78	186.737
3104.03	195.318
3108.28	206.002
3112.53	200.825
3116.77	189.572
3121.01	224.583
3125.25	199.259
3129.49	210.343
3133.72	213.421
3137.95	216.495
3142.18	225.7
3146.4	210.062
3150.62	204.619
3154.84	213.586
3159.06	205.854
3163.27	216.95
3167.48	236.453
3171.69	222.348
3175.89	224.982
3180.09	214.784
3184.29	232.033
3188.49	223.785
3192.68	224.121
3196.87	213.921
3201.06	235.966
3205.24	213.235
3209.42	229.152
3213.6	214.975
3217.78	213.737
3221.95	227.664
3226.12	222.019
3230.29	236.063
3234.45	217.109
3238.61	213.469
3242.77	227.663
3246.93	206.318
3251.08	213.733
3255.23	212.044
3259.38	212.621
3263.53	197.547
3267.67	194.02
3271.81	192.532
3275.95	204.455
3280.08	220.902
3284.21	223.646
3288.34	221.793
3292.47	217.6
3296.59	206.445
3300.71	206.866
3304.83	214.216
3308.95	198.389
3313.06	198.729
3317.17	203.753
3321.27	227.514
3325.38	211.698
3329.48	223.991
3333.58	203.599
3337.67	223.216
3341.77	214.317
3345.86	221.878
3349.95	224.63
3354.03	220.257
3358.11	213.59
3362.19	209.293
3366.27	212.133
3370.34	229.403
3374.42	193.727
3378.48	208.475
3382.55	201.52
3386.61	213.855
3390.68	211.673
3394.73	209.497
3398.79	221.937
3402.84	214.911
3406.89	212.685
3410.94	205.566
3414.98	205.726
3419.03	213.201
3423.06	215.785
3427.1	203.765
3431.14	196.672
3435.17	209.184
3439.2	211.992
3443.22	200.113
3447.25	212.903
3451.27	208.5
3455.28	196.728
3459.3	209.81
3463.31	210.548
3467.32	211.294
3471.33	217.02
3475.34	194.954
3479.34	210.687
3483.34	186.003
3487.33	209.371
3491.33	212.488
3495.32	207.918
3499.31	170.023
3503.3	213.879
3507.28	191.116
3511.26	188.707
3515.24	196.535
3519.22	196.65
3523.19	186.474
3527.16	209.785
3531.13	199.63
3535.1	197.395
3539.06	171.993
3543.02	185.298
3546.98	193.394
3550.93	196.238
3554.89	196.312
3558.84	196.519
3562.78	204.608
3566.73	181.466
3570.67	176.634
3574.61	190.124
3578.55	201.124
3582.48	177.977
3586.41	178.509
3590.35	192.293
3594.27	192.851
3598.2	193.402
3602.12	183.196
3606.04	183.638
3609.95	186.713
3613.87	162.878
3617.78	203.65
3621.69	163.426
3625.6	171.653
3629.5	169.052
3633.4	188.051
3637.3	174.656
3641.2	177.626
3645.09	180.689
3648.98	183.675
3652.87	172.975
3656.76	170.408
3660.64	189.657
3664.53	173.415
3668.4	181.798
3672.28	162.818
3676.16	184.984
3680.03	177.104
3683.9	166.517
3687.76	164.219
3691.63	175.759
3695.49	181.75
3699.35	151.636
3703.2	179.922
3707.06	177.627
3710.91	169.702
3714.76	175.766
3718.6	173.334
3722.45	165.208
3726.29	154.183
3730.13	160.12
3733.97	149.071
3737.8	152.196
3741.63	180.95
3745.46	186.944
3749.29	170.05
3753.11	170.228
3756.93	158.905
3760.75	150.395
3764.57	176.256
3768.39	164.884
3772.2	167.892
3776.01	142.186
3779.81	165.347
3783.62	179.989
3787.42	168.728
3791.22	160.291
3795.02	166.35
3798.81	157.985
3802.61	161.222
3806.4	164.501
3810.18	173.629
3813.97	156.44
3817.75	162.611
3821.53	168.788
3825.31	166.12
3829.09	142.835
3832.86	163.762
3836.63	172.921
3840.4	155.432
3844.17	158.699
3847.93	170.706
3851.69	153
3855.45	153.071
3859.21	156.054
3862.96	170.975
3866.71	165.31
3870.46	156.743
3874.21	153.839
3877.95	153.935
3881.69	154.037
3885.44	178.113
3889.17	160.312
3892.91	166.518
3896.64	172.833
3900.37	164.07
3904.1	155.266
3907.82	155.483
3911.55	164.802
3915.27	140.857
3918.99	171.508
3922.7	141.5
3926.42	160.122
3930.13	148.229
3933.84	148.476
3937.54	164.017
3941.25	155.091
3944.95	149.255
3948.65	155.699
3952.35	149.758
3956.04	143.772
3959.73	153.197
3963.42	140.927
3967.11	156.494
3970.8	153.43
3974.48	153.484
3978.16	162.83
3981.84	141.113
3985.52	144.206
3989.19	165.906
3992.86	159.758
3996.53	150.558
3998.37	159.949