File: Data/3-Raman/raw/bu19w-ff1-fi04-v_150 (500nm)_532nm_edge_100%_x100_vis_h50um_15sx2_01.txt
#Acq. time (s)=	15
#Accumulations=	2
#Range (cm-¹)=	100...5000
#Windows=	1
#Auto scanning=	Off
#Autofocus=	Off
#Macrospot=	Off
#AutoExposure=	Off
#Spike filter=	Multiple accum.
#Delay time (s)=	2
#Binning=	1
#Readout mode=	Signal
#DeNoise=	Off
#ICS correction=	On
#Dark correction=	Off
#Inst. Process=	Off
#Detector Gain=	Best Dynamic
#Detector ADC=	50 kHz HS
#Detector temperature (°C)=	-60.09
#Instrument=	LabRAM HR Evol
#Detector=	SIN-EM FIVIS
#Objective=	x100_VIS
#Grating=	150 (500nm)
#ND Filter=	100%
#Laser=	532nm_Edge
#Hole=	49.98
#Temperature=	0
#Range=	Visible
#StageXY=	75x50mm Scan+
#StageZ=	Z motor
#X (µm)=	0
#Y (µm)=	0
#Z (µm)=	-139.1
#Full time(s)=	34
#Project=	21_05_14
#Sample=	BU19w
#Site=
#Title=	BU19w-FF1-FI04-V_150 (500nm)_532nm_Edge_100%_x100_VIS_H50um_15sX2
#Remark=
#Date=	14.05.2021 14:14
#Acquired=	14.05.2021 14:14:23
102.699	7255.86
107.322	6378.6
111.942	5444.54
116.56	4746.36
121.173	4144
125.787	3676.65
130.398	3317.39
135.006	2998.72
139.613	2763.97
144.215	2486.77
148.817	2312
153.417	2174.95
158.014	2319.19
162.607	2729.28
167.2	2585.84
171.79	2017.15
176.379	1854.05
180.963	1850.22
185.547	2642.8
190.128	4310.1
194.705	4037.36
199.282	2305.28
203.857	1606.65
208.43	1453.65
212.998	1383.86
217.566	1389.9
222.132	1362.89
226.693	1345.35
231.254	1360.56
235.813	1428.31
240.368	1462.6
244.923	1574.86
249.475	1803.6
254.023	1765.43
258.571	1650.65
263.117	1556.86
267.658	1505.66
272.199	1682.68
276.738	2390.35
281.273	3466.76
285.807	3385.38
290.34	2397.03
294.868	1826.62
299.396	1929.11
303.919	2466.24
308.443	2742.49
312.964	2139.09
317.481	1658.73
321.998	1529.24
326.51	1644.39
331.023	1896.54
335.533	1949.64
340.039	1631.41
344.544	1487.24
349.046	1469.73
353.547	1571.13
358.045	1479.73
362.542	1366.81
367.036	1359.68
371.527	1387.77
376.017	1399.6
380.503	1360.75
384.99	1515.52
389.471	1689.47
393.953	1803.36
398.43	1826.24
402.908	1778.77
407.381	1663.53
411.854	1581.97
416.323	1659.85
420.791	1814.74
425.256	1702.37
429.72	1476.04
434.18	1387.67
438.64	1351.62
443.095	1395.54
447.551	1391.24
452.003	1615.59
456.454	2069.41
460.901	2255.93
465.348	1862.62
469.791	1534.39
474.231	1424.01
478.672	1389.29
483.108	1469.33
487.544	1528.69
491.976	1583.5
496.408	1634.93
500.836	1665.14
505.261	1654.43
509.687	1587.92
514.108	1511.24
518.529	1461.23
522.946	1479.03
527.361	1464.54
531.776	1530.35
536.187	1500.24
540.595	1516.41
545.003	1556.89
549.408	1535.97
553.812	1586.34
558.212	1564.87
562.61	1612.49
567.007	1639.37
571.401	1575.28
575.792	1489.94
580.184	1539.38
584.571	1634.08
588.956	1927.38
593.341	2225.4
597.722	2066.61
602.101	1763.6
606.48	1722.1
610.854	1852.09
615.227	2052.25
619.597	1988.41
623.967	1743.46
628.334	1539.92
632.698	1499.59
637.06	1577.86
641.422	1570.48
645.779	1602.26
650.135	1560.33
654.491	1503.62
658.842	1528.19
663.192	1606.15
667.539	1603.06
671.884	1628.75
676.23	1729.53
680.571	1750.9
684.91	1730.36
689.247	1638.26
693.583	1597.86
697.916	1532.7
702.247	1513.78
706.576	1470.95
710.902	1459.21
715.229	1470.07
719.551	1447.54
723.872	1507.62
728.19	1507.5
732.506	1484.75
736.82	1485.01
741.134	1556.37
745.444	1536.63
749.752	1569.7
754.058	1584.51
758.362	1643.96
762.664	1678.62
766.964	1767.97
771.264	1927.61
775.559	2165.26
779.853	2479.92
784.144	2615.09
788.434	2274.76
792.722	1930.39
797.007	1778.99
801.29	1750.31
805.572	1674.15
809.851	1629.09
814.13	1616.31
818.406	1606.7
822.679	1587.64
826.95	1594.1
831.219	1600.65
835.486	1591.68
839.752	1579.26
844.015	1596.29
848.276	1597.8
852.535	1594.77
856.792	1584.03
861.047	1598.47
865.3	1602.41
869.551	1593.92
873.8	1602.55
878.047	1634.97
882.292	1592.3
886.534	1621.07
890.775	1598.18
895.014	1635.43
899.251	1658.47
903.486	1624.96
907.719	1657.56
911.95	1657.73
916.179	1649.98
920.406	1670.35
924.63	1653.9
928.853	1668.99
933.074	1638.11
937.293	1686.03
941.51	1705.8
945.723	1700.6
949.936	1802.57
954.147	1796.91
958.356	1845.74
962.563	1828.83
966.768	1892.73
970.971	1912.48
975.172	1884.65
979.371	1852.03
983.568	1777.21
987.761	1751.88
991.954	1758.4
996.145	1694.31
1000.33	1759.96
1004.52	1733.59
1008.71	1732
1012.89	1738.28
1017.07	1792.52
1021.25	1789.17
1025.43	1806.16
1029.6	1762.3
1033.77	1847.99
1037.95	1852.75
1042.11	1962.05
1046.28	2166.96
1050.45	2454.5
1054.61	2961.25
1058.77	3112.19
1062.93	2700.9
1067.09	2387.4
1071.24	2098.22
1075.4	2111.69
1079.55	2127.11
1083.7	2300.98
1087.85	2579.43
1091.99	2925.76
1096.14	3058.15
1100.28	2832.83
1104.42	2625.04
1108.55	2657.48
1112.69	2817.06
1116.82	2859.96
1120.96	2690.92
1125.09	2654.82
1129.21	2647.83
1133.34	2755.01
1137.46	2728.12
1141.59	2589.07
1145.71	2354.4
1149.83	2242.48
1153.94	2210.58
1158.06	2443.64
1162.17	2682.98
1166.28	2519.34
1170.39	2229.03
1174.5	2143.63
1178.6	2102.5
1182.7	1980.14
1186.8	1933.61
1190.9	1967.62
1195	1956.89
1199.1	1977.15
1203.19	1990.92
1207.28	2023.89
1211.37	2024.47
1215.46	1972.68
1219.54	2010.04
1223.63	2067.47
1227.71	2179.6
1231.79	2124.18
1235.87	2238.44
1239.95	2283.72
1244.02	2401.15
1248.09	2467.35
1252.16	2603.11
1256.23	2879.36
1260.3	2561.42
1264.36	2400.52
1268.43	2581.54
1272.49	5582.74
1276.55	10003.3
1280.6	4966.4
1284.66	2610.03
1288.71	2301.83
1292.76	2242.49
1296.81	2239.43
1300.86	2117.03
1304.91	2119.21
1308.95	2168.84
1312.99	2111.9
1317.03	2137.88
1321.07	2188.73
1325.11	2156.84
1329.14	2197.78
1333.18	2161.51
1337.21	2115.87
1341.24	2157.07
1345.26	2171.03
1349.29	2204.91
1353.31	2310.3
1357.33	2322.05
1361.35	2541.66
1365.37	2541.78
1369.39	2591.54
1373.4	3280.06
1377.41	10965.2
1381.43	14290.8
1385.43	4974.59
1389.44	2713.01
1393.45	2533.59
1397.45	2790.87
1401.45	3209.3
1405.45	2666.47
1409.45	2283.16
1413.44	2223.21
1417.44	2194.72
1421.43	2146.33
1425.42	2124.83
1429.41	2055.22
1433.39	2088.87
1437.38	2045.17
1441.36	2055.85
1445.34	2019.7
1449.32	2004.23
1453.3	2058.35
1457.27	2075.78
1461.24	1991.17
1465.22	1980.06
1469.19	1979.99
1473.15	1996.66
1477.12	1998.16
1481.09	1970.17
1485.05	1964.59
1489.01	2009.79
1492.97	1980.94
1496.93	2021.37
1500.88	2031.9
1504.83	1994.27
1508.79	1966.81
1512.74	1979.21
1516.68	1982.09
1520.63	2011.35
1524.57	2014.52
1528.52	2020.82
1532.46	1991.43
1536.4	2019.23
1540.33	2049.02
1544.27	2056.51
1548.2	2019.44
1552.14	1981.3
1556.07	2015.47
1559.99	2037.74
1563.92	2035.6
1567.84	2039.08
1571.77	2024.12
1575.69	2018.79
1579.61	2042.33
1583.52	2065.73
1587.44	2061.04
1591.35	2065
1595.27	2067
1599.18	2078.7
1603.09	2077.23
1606.99	2073.08
1610.9	2071.87
1614.8	2061.33
1618.7	2093.03
1622.6	2086.44
1626.5	2014.23
1630.39	2100.37
1634.29	2051.92
1638.18	2052.34
1642.07	2079.28
1645.96	2078.7
1649.85	2103.19
1653.73	2044.15
1657.62	2094.36
1661.5	2079.06
1665.38	2115.28
1669.26	2094.38
1673.13	2068.22
1677.01	2115.52
1680.88	2120.46
1684.75	2117.52
1688.62	2106.6
1692.49	2068.5
1696.35	2079.91
1700.22	2125.21
1704.08	2107.99
1707.94	2177.83
1711.8	2099.22
1715.66	2122.33
1719.51	2104.79
1723.37	2068.4
1727.22	2090.17
1731.07	2138.99
1734.92	2126.74
1738.76	2129.16
1742.61	2115.69
1746.45	2126.33
1750.29	2151.08
1754.13	2081.15
1757.97	2127.9
1761.81	2166.42
1765.64	2143.71
1769.47	2169.75
1773.31	2133.93
1777.14	2157.06
1780.96	2116.5
1784.79	2151.73
1788.61	2111.42
1792.43	2146.99
1796.25	2179.82
1800.07	2168.64
1803.89	2163.18
1807.71	2130.3
1811.52	2138.51
1815.33	2131.87
1819.14	2131.99
1822.95	2120.38
1826.76	2164.86
1830.56	2154.03
1834.37	2161.6
1838.17	2147.2
1841.97	2172.78
1845.77	2211.37
1849.56	2151.05
1853.36	2166.76
1857.15	2193.03
1860.94	2133.99
1864.73	2187.69
1868.52	2202.48
1872.31	2138.91
1876.09	2152.54
1879.87	2161.17
1883.66	2165.65
1887.43	2187.2
1891.21	2164.9
1894.99	2158.09
1898.76	2172.1
1902.53	2185.9
1906.31	2161.29
1910.08	2168.54
1913.84	2179.03
1917.61	2182.99
1921.37	2166.47
1925.14	2184.42
1928.9	2177.66
1932.66	2193.24
1936.41	2211.6
1940.17	2179.49
1943.92	2127.07
1947.68	2186.11
1951.43	2128.01
1955.18	2188.14
1958.92	2219.93
1962.67	2191.4
1966.41	2172.04
1970.16	2205.04
1973.9	2191.64
1977.64	2234.92
1981.37	2222.61
1985.11	2228.6
1988.84	2223.21
1992.57	2197.76
1996.31	2250.03
2000.03	2172.08
2003.76	2181.67
2007.49	2202.41
2011.21	2212.83
2014.93	2193.46
2018.65	2217.85
2022.37	2167.12
2026.09	2247.67
2029.81	2195.01
2033.52	2227.78
2037.23	2205
2040.94	2173.2
2044.65	2212.48
2048.36	2201.88
2052.07	2196.15
2055.77	2216.46
2059.47	2192.73
2063.17	2253.32
2066.87	2225.98
2070.57	2191.23
2074.27	2211.85
2077.96	2167.98
2081.65	2206.42
2085.34	2202.78
2089.03	2215.72
2092.72	2235.39
2096.41	2237.86
2100.09	2265.23
2103.77	2252.25
2107.46	2232.36
2111.14	2245.74
2114.81	2245.1
2118.49	2224.27
2122.16	2231.38
2125.84	2225.31
2129.51	2273.48
2133.18	2231.76
2136.85	2202.78
2140.51	2257.37
2144.18	2218.59
2147.84	2246.04
2151.5	2256.91
2155.16	2227.58
2158.82	2261.56
2162.48	2255.67
2166.13	2234.64
2169.79	2210.67
2173.44	2229.53
2177.09	2258.54
2180.74	2240.43
2184.38	2234.18
2188.03	2214.43
2191.67	2290.09
2195.32	2207.31
2198.96	2212.1
2202.6	2258.3
2206.23	2235.54
2209.87	2213.98
2213.5	2189.82
2217.14	2226.2
2220.77	2214.98
2224.4	2291.21
2228.03	2219.97
2231.65	2286.35
2235.28	2230.9
2238.9	2214.04
2242.52	2251.86
2246.14	2202.39
2249.76	2261
2253.38	2213.71
2256.99	2211.17
2260.6	2180.33
2264.21	2177.44
2267.82	2221.06
2271.44	2262.96
2275.04	2206.98
2278.65	2186.79
2282.25	2236.28
2285.85	2261.75
2289.45	2151.63
2293.05	2192.68
2296.65	2239.6
2300.25	2244.73
2303.84	2218.06
2307.43	2248.82
2311.02	2206.29
2314.62	2267.64
2318.2	2588.14
2321.79	3325.68
2325.38	2763.77
2328.96	2298.69
2332.54	2255.96
2336.12	2247.98
2339.7	2257.58
2343.28	2188.04
2346.85	2215.97
2350.43	2226.86
2354	2216.09
2357.57	2255.54
2361.14	2287.3
2364.71	2197.42
2368.27	2224.98
2371.84	2167.6
2375.4	2218.23
2378.96	2203.51
2382.52	2224.98
2386.08	2232.89
2389.64	2207.27
2393.19	2225.35
2396.75	2212.09
2400.3	2187.91
2403.85	2181.04
2407.4	2180.08
2410.95	2164.43
2414.49	2185.87
2418.04	2192.22
2421.58	2196.2
2425.12	2207.24
2428.66	2198.46
2432.2	2200.29
2435.74	2154.21
2439.27	2183.43
2442.81	2205.45
2446.34	2204.43
2449.87	2157.94
2453.4	2202.73
2456.93	2175.11
2460.45	2181.3
2463.98	2135.74
2467.5	2243.69
2471.02	2203.07
2474.54	2174.65
2478.06	2200.82
2481.58	2163.43
2485.09	2161.58
2488.61	2217.03
2492.12	2212.53
2495.63	2190.57
2499.14	2173.71
2502.65	2144.84
2506.15	2162.42
2509.66	2175.09
2513.16	2175.15
2516.66	2204.44
2520.16	2180.72
2523.66	2204.49
2527.16	2178.46
2530.66	2192.46
2534.15	2150.79
2537.64	2150.18
2541.13	2173.53
2544.62	2158.36
2548.11	2165.55
2551.6	2177.69
2555.08	2214.28
2558.57	2170.28
2562.05	2174.37
2565.53	2142.9
2569.01	2131.5
2572.49	2144.81
2575.96	2134.24
2579.44	2197.27
2582.91	2156.83
2586.38	2166.09
2589.85	2141.94
2593.32	2154.98
2596.79	2098.07
2600.25	2178.81
2603.72	2129.5
2607.18	2131.25
2610.64	2124.97
2614.1	2128.26
2617.56	2144.22
2621.02	2188.59
2624.47	2145.83
2627.92	2177.65
2631.38	2194.58
2634.83	2158.03
2638.28	2153.72
2641.72	2173.76
2645.17	2098.13
2648.61	2101.46
2652.06	2146.12
2655.5	2119.76
2658.94	2152.99
2662.38	2161.18
2665.82	2145.76
2669.25	2165.9
2672.69	2155.28
2676.12	2159.04
2679.55	2131.43
2682.98	2133.38
2686.41	2128.25
2689.84	2096.51
2693.26	2133.11
2696.69	2122.61
2700.11	2091.08
2703.53	2101.83
2706.95	2108.67
2710.37	2152.36
2713.79	2077.36
2717.2	2123.81
2720.62	2127.79
2724.03	2125.39
2727.44	2082.09
2730.85	2117.17
2734.26	2133.56
2737.66	2117.19
2741.07	2099.46
2744.47	2118.84
2747.87	2090.32
2751.28	2104.99
2754.67	2106.04
2758.07	2069.71
2761.47	2111.88
2764.86	2093.46
2768.26	2108.51
2771.65	2114.96
2775.04	2155.9
2778.43	2080.63
2781.82	2093.71
2785.2	2101.03
2788.59	2055.67
2791.97	2082.51
2795.35	2096.39
2798.73	2105.08
2802.11	2057.51
2805.49	2073.71
2808.87	2004.57
2812.24	2107.55
2815.62	2068.12
2818.99	2078.52
2822.36	2083.67
2825.73	2055.38
2829.1	2124.26
2832.46	2049.09
2835.83	2062.78
2839.19	2077.8
2842.55	2095.11
2845.91	2078.58
2849.27	2079.8
2852.63	2026.37
2855.99	2032.92
2859.34	2062.27
2862.69	2073.03
2866.05	2053.9
2869.4	2067.42
2872.75	2061.16
2876.09	2011.53
2879.44	2048.44
2882.78	2038.11
2886.13	2044.58
2889.47	2081.44
2892.81	2034.56
2896.15	2045.98
2899.49	2034.37
2902.82	2019.61
2906.16	2064.31
2909.49	2043.49
2912.82	2052.94
2916.16	2022.27
2919.49	2029.28
2922.81	2092.98
2926.14	2058.85
2929.46	2010.49
2932.79	2055.17
2936.11	2062.04
2939.43	2018.02
2942.75	2103.09
2946.07	2019.74
2949.39	1997.57
2952.7	2026.08
2956.02	1967.55
2959.33	2032.36
2962.64	1994.79
2965.95	2071.18
2969.26	1990.83
2972.57	2029.22
2975.87	2040.28
2979.17	2036.82
2982.48	2014.7
2985.78	2019.01
2989.08	2044.98
2992.38	2012.81
2995.68	2069.1
2998.97	2021.11
3002.27	2011.53
3005.56	1981.44
3008.85	2013.56
3012.14	2020.39
3015.43	2021.51
3018.72	2007.49
3022	1975.52
3025.29	2031.36
3028.57	2034.36
3031.85	2041.04
3035.14	2032.5
3038.41	1998.43
3041.69	1987.04
3044.97	1993.73
3048.24	2024.01
3051.52	1994.74
3054.79	1962.53
3058.06	2020.19
3061.33	2007.16
3064.6	1958.26
3067.87	1991.63
3071.13	2012.98
3074.4	1992.71
3077.66	1965.81
3080.92	2012.09
3084.18	2029.39
3087.44	1965.42
3090.7	2022.51
3093.95	1989.2
3097.21	1997.98
3100.46	2034.35
3103.71	2022.87
3106.96	2056.21
3110.21	2062.3
3113.46	2013.13
3116.71	2017.36
3119.95	2019.7
3123.2	2017.25
3126.44	1997.59
3129.68	2055.13
3132.92	2038.31
3136.16	2007.09
3139.4	2019.66
3142.63	2028.41
3145.87	2022.01
3149.1	2003.29
3152.33	2028.37
3155.56	2069.71
3158.79	2025.14
3162.02	2033.05
3165.25	2067.54
3168.47	2049.38
3171.69	2038.76
3174.92	2066.15
3178.14	2023.81
3181.36	2033.04
3184.58	2037.33
3187.79	2093.93
3191.01	2018.97
3194.22	2005.95
3197.43	2068.14
3200.65	2043.69
3203.86	2088.82
3207.07	2090.23
3210.27	2079.41
3213.48	2079.21
3216.69	2083.81
3219.89	2040.88
3223.09	2112.29
3226.29	2074.38
3229.49	2083.25
3232.69	2078.67
3235.89	2048.73
3239.08	2107.52
3242.28	2043.61
3245.47	2041.59
3248.66	2050.23
3251.85	2093.31
3255.04	2020.02
3258.23	2096.33
3261.42	2072.11
3264.6	2078.15
3267.79	2117.39
3270.97	2080.99
3274.15	2062.75
3277.33	2076.65
3280.51	2066.22
3283.68	2093.95
3286.86	2064.25
3290.04	2079.5
3293.21	2104.25
3296.38	2090.8
3299.55	2046.47
3302.72	2130.3
3305.89	2118.66
3309.06	2082.96
3312.22	2101.25
3315.39	2105.22
3318.55	2067.38
3321.71	2110.12
3324.87	2120.62
3328.03	2125.46
3331.19	2090.72
3334.34	2123.25
3337.5	2082.33
3340.65	2120.67
3343.81	2148.07
3346.96	2129.91
3350.11	2139.11
3353.25	2104.23
3356.4	2080.76
3359.55	2116
3362.69	2186.22
3365.84	2153.79
3368.98	2128
3372.12	2114.71
3375.26	2134.57
3378.4	2119.65
3381.53	2127.28
3384.67	2168.17
3387.8	2133.45
3390.94	2224.74
3394.07	2186.41
3397.2	2183.24
3400.33	2244.96
3403.46	2251.94
3406.58	2333.24
3409.71	2349.14
3412.83	2530.25
3415.96	2975.44
3419.08	3825.54
3422.2	5969.14
3425.32	7834.59
3428.44	6211.8
3431.55	3895.39
3434.67	2858.51
3437.78	2482.83
3440.89	2347.89
3444	2230.62
3447.12	2252.6
3450.22	2237.99
3453.33	2163.36
3456.44	2172.25
3459.54	2157.28
3462.65	2091.89
3465.75	2125.16
3468.85	2133.05
3471.95	2132.07
3475.05	2128.45
3478.15	2077.66
3481.24	2136.63
3484.34	2126.68
3487.43	2132.04
3490.53	2150.36
3493.62	2260.27
3496.71	2335.91
3499.79	2440
3502.88	2584.97
3505.97	2683.85
3509.05	2642.37
3512.14	2559.27
3515.22	2395.73
3518.3	2252.62
3521.38	2145.5
3524.46	2087.44
3527.54	2074.33
3530.61	2041.08
3533.69	1968.95
3536.76	1926.69
3539.83	1938.65
3542.9	1916.66
3545.97	1895.45
3549.04	1892.84
3552.11	1893.63
3555.18	1899.46
3558.24	1909.29
3561.3	1858.06
3564.37	1844.55
3567.43	1851.02
3570.49	1847.69
3573.55	1808.12
3576.61	1821.57
3579.66	1784.6
3582.72	1829.98
3585.77	1795.65
3588.82	1769.68
3591.87	1790.08
3594.92	1773.37
3597.97	1773.69
3601.02	1730.32
3604.07	1752.13
3607.11	1713.33
3610.16	1752.02
3613.2	1721.62
3616.24	1690.34
3619.28	1706.36
3622.32	1726.18
3625.36	1692.37
3628.39	1692.47
3631.43	1679.26
3634.46	1708.7
3637.5	1706.42
3640.53	1652.58
3643.56	1641.5
3646.59	1645.22
3649.62	1647.27
3652.64	1625.88
3655.67	1646.19
3658.69	1592.18
3661.72	1600.04
3664.74	1604.38
3667.76	1598.43
3670.78	1589.81
3673.79	1590.7
3676.81	1586.98
3679.83	1549.19
3682.84	1621.02
3685.86	1552.01
3688.87	1569.11
3691.88	1547.45
3694.89	1538.76
3697.9	1541.63
3700.91	1554.08
3703.91	1532.36
3706.92	1547.53
3709.92	1527.4
3712.92	1520.38
3715.92	1521.02
3718.92	1505.36
3721.92	1544.76
3724.92	1526.91
3727.92	1487.04
3730.91	1532.73
3733.91	1515.41
3736.9	1469.39
3739.89	1545.04
3742.88	1527.27
3745.87	1482.74
3748.86	1489.44
3751.85	1527.42
3754.83	1481.87
3757.82	1475.24
3760.8	1423.97
3763.78	1482.61
3766.76	1459.87
3769.74	1474.18
3772.72	1484.82
3775.7	1455.84
3778.67	1442.1
3781.65	1466.19
3784.62	1460.11
3787.6	1452.23
3790.57	1468.15
3793.54	1473.84
3796.51	1447.52
3799.47	1427.98
3802.44	1457.65
3805.41	1466.61
3808.37	1477.54
3811.33	1430.86
3814.3	1460.79
3817.26	1434.03
3820.22	1410.12
3823.18	1414.7
3826.13	1437.33
3829.09	1417.29
3832.04	1403.98
3835	1407.84
3837.95	1396.52
3840.9	1412.75
3843.85	1398.56
3846.8	1413.93
3849.75	1406.53
3852.69	1404.89
3855.64	1378.43
3858.58	1437.97
3861.53	1406.67
3864.47	1458.6
3867.41	1420.45
3870.35	1407.1
3873.29	1423.45
3876.22	1402.22
3879.16	1389.47
3882.1	1418.82
3885.03	1416.34
3887.96	1377.25
3890.89	1391.95
3893.82	1373.79
3896.75	1389.11
3899.68	1359.2
3902.61	1365.63
3905.53	1383.73
3908.46	1393.1
3911.38	1371.59
3914.3	1394.12
3917.23	1402.48
3920.15	1391.46
3923.06	1371.62
3925.98	1368.93
3928.9	1383.35
3931.81	1385.56
3934.73	1374.64
3937.64	1378.43
3940.55	1351.49
3943.46	1360
3946.37	1337.04
3949.28	1350.59
3952.19	1370.89
3955.09	1340.55
3958	1361.06
3960.9	1370.14
3963.8	1362.04
3966.71	1309.89
3969.61	1351.79
3972.51	1362.04
3975.4	1351.1
3978.3	1353.49
3981.2	1292.41
3984.09	1347.57
3986.99	1355.63
3989.88	1328.83
3992.77	1329.18
3995.66	1324.73
3998.55	1323.23
4001.43	1304.41
4004.32	1341.53
4007.21	1328.58
4010.09	1308.86
4012.98	1343.15
4015.86	1326.33
4018.74	1334.58
4021.62	1275.23
4024.5	1319.25
4027.37	1346.87
4030.25	1332.01
4033.13	1346.16
4036	1267.47
4038.87	1309.77
4041.75	1332.51
4044.62	1299.05
4047.49	1272.42
4050.35	1284.64
4053.22	1341.61
4056.09	1274.4
4058.95	1300.29
4061.82	1297.05
4064.68	1299.64
4067.54	1298.32
4070.4	1305.75
4073.26	1286.87
4076.12	1238.73
4078.98	1273.38
4081.83	1261.27
4084.69	1260.82
4087.54	1249.59
4090.4	1303.83
4093.25	1272.15
4096.1	1271.69
4098.95	1253.67
4101.8	1259.05
4104.64	1249.66
4107.49	1254.86
4110.33	1258.06
4113.18	1265.02
4116.02	1249.31
4118.86	1242.34
4121.7	1216.89
4124.54	1254.16
4127.38	1268.14
4130.22	1263.82
4133.05	1256.83
4135.89	1276.59
4138.72	1214.48
4141.56	1261.57
4144.39	1255.1
4147.22	1214.46
4150.05	1203.05
4152.88	1244.11
4155.7	1256.26
4158.53	1230.27
4161.36	1183.16
4164.18	1236.8
4167	1210.26
4169.82	1225.85
4172.65	1207.26
4175.46	1223.89
4178.28	1234.7
4181.1	1213.32
4183.92	1197.85
4186.73	1213.74
4189.55	1209.2
4192.36	1206.79
4195.17	1198.65
4197.98	1193.49
4200.79	1215.78
4203.6	1220.43
4206.41	1234.9
4209.21	1184.52
4212.02	1202.87
4214.83	1204.94
4217.63	1156.11
4220.43	1183.91
4223.23	1148.48
4226.03	1119.93
4228.83	1174.56
4231.63	1181.85
4234.42	1168.46
4237.22	1194.78
4240.01	1167.52
4242.81	1164.13
4245.6	1168.7
4248.39	1194.13
4251.18	1153.6
4253.97	1169.93
4256.76	1176.22
4259.55	1144.45
4262.33	1158.84
4265.12	1175.33
4267.9	1148.63
4270.68	1139.95
4273.47	1118
4276.25	1144.24
4279.03	1112.84
4281.8	1143.98
4284.58	1133.53
4287.36	1137.11
4290.13	1159.85
4292.91	1115.83
4295.68	1143.87
4298.45	1120.18
4301.22	1156.27
4303.99	1124.37
4306.76	1124.98
4309.53	1120.59
4312.3	1110.04
4315.06	1123.73
4317.83	1101.73
4320.59	1116.28
4323.35	1114.48
4326.11	1068.88
4328.87	1099.61
4331.63	1098.75
4334.39	1126.39
4337.15	1111.3
4339.9	1087.15
4342.66	1128.3
4345.41	1085.95
4348.17	1061.98
4350.92	1081.04
4353.67	1090.99
4356.42	1091.67
4359.17	1069.82
4361.91	1064.35
4364.66	1055.8
4367.41	1088.26
4370.15	1055.05
4372.89	1066.84
4375.63	1078.59
4378.38	1080.02
4381.12	1077.38
4383.86	1050.24
4386.59	1046.06
4389.33	1085.42
4392.07	1054.25
4394.8	1081.8
4397.53	1064.45
4400.27	1041.85
4403	1070.01
4405.73	1053.64
4408.46	1075.65
4411.19	1081.93
4413.92	1025.62
4416.64	1048.17
4419.37	1064.42
4422.09	1069.38
4424.82	1034.66
4427.54	1038.57
4430.26	1063.39
4432.98	1053.66
4435.7	1003.01
4438.42	1021.39
4441.13	1067.03
4443.85	1009.87
4446.57	1037.65
4449.28	1021.3
4451.99	1033.24
4454.71	1032.52
4457.42	1030.68
4460.13	1018.4
4462.83	1015.61
4465.54	1013.9
4468.25	1022.77
4470.95	1020.13
4473.66	1018.64
4476.36	1015.13
4479.07	1016.95
4481.77	1034.64
4484.47	1056.54
4487.17	1036.12
4489.87	1026.09
4492.56	997.663
4495.26	991.729
4497.96	1016.53
4500.65	976.508
4503.34	995.953
4506.04	982.583
4508.73	991.483
4511.42	1014.2
4514.11	1009.38
4516.8	971.606
4519.48	953.073
4522.17	985.597
4524.85	971.279
4527.54	963.375
4530.22	981.05
4532.9	957.206
4535.58	997.36
4538.27	973.606
4540.94	961.527
4543.62	966.598
4546.3	964.184
4548.98	937.147
4551.65	923.154
4554.33	988.65
4557	923.445
4559.67	949.779
4562.34	969.907
4565.01	970.121
4567.68	957.012
4570.35	965.512
4573.02	948.128
4575.68	926.961
4578.35	956.015
4581.01	958.62
4583.67	904.84
4586.34	934.907
4589	939.803
4591.66	968.655
4594.31	953.078
4596.97	939.398
4599.63	912.798
4602.29	925.666
4604.94	913.346
4607.59	924.077
4610.25	907.347
4612.9	923.521
4615.55	910.055
4618.2	945.091
4620.85	931.691
4623.5	922.605
4626.14	952.06
4628.79	914.201
4631.43	905.983
4634.08	916.451
4636.72	900.391
4639.36	900.846
4642	904.818
4644.64	922.361
4647.28	897.951
4649.92	910.44
4652.56	902.26
4655.19	866.452
4657.83	889.484
4660.46	904.964
4663.1	867.964
4665.73	876.373
4668.36	865.895
4670.99	876.661
4673.62	916.588
4676.24	892.606
4678.87	884.275
4681.5	874.804
4684.12	887.821
4686.75	897.462
4689.37	885.794
4691.99	896.547
4694.61	877.96
4697.23	903.384
4699.85	887.072
4702.47	823.168
4705.09	832.664
4707.7	873.799
4710.32	868.562
4712.93	889.349
4715.55	880.621
4718.16	876.45
4720.77	863.067
4723.38	858.885
4725.99	867.258
4728.6	867.701
4731.21	839.762
4733.81	900.412
4736.42	830.308
4739.02	871.601
4741.63	825.218
4744.23	830.027
4746.83	848.288
4749.43	846.107
4752.03	862.138
4754.63	825.765
4757.23	857.76
4759.82	840.901
4762.42	827.453
4765.01	833.51
4767.61	859.222
4770.2	865.284
4772.79	827.997
4775.38	874.049
4777.97	836.732
4780.56	854.24
4783.15	819.189
4785.74	856.165
4788.32	803.931
4790.91	855.897
4793.49	827.717
4796.07	837.437
4798.66	803.632
4801.24	818.052
4803.82	834.887
4806.4	836.927
4808.98	822.8
4811.55	801.787
4814.13	779.601
4816.71	802.532
4819.28	827.817
4821.85	817.273
4824.43	814.83
4827	814.646
4829.57	795.994
4832.14	821.529
4834.71	802.932
4837.28	776.186
4839.84	793.854
4842.41	799.69
4844.97	791.372
4847.54	785.282
4850.1	790.426
4852.66	808.02
4855.22	788.025
4857.78	798.621
4860.34	789.019
4862.9	793.242
4865.46	784.315
4868.01	755.641
4870.57	794.229
4873.12	793.61
4875.68	765.721
4878.23	803.043
4880.78	773.831
4883.33	780.222
4885.88	749.766
4888.43	784.748
4890.98	791.155
4893.53	776.112
4896.07	764.586
4898.62	786.439
4901.16	762.934
4903.7	775.259
4906.25	771.949
4908.79	761.403
4911.33	780.597
4913.87	749.563
4916.41	756.773
4918.94	761.636
4921.48	747.38
4924.02	734.353
4926.55	746.384
4929.08	745.348
4931.62	746.886
4934.15	725.689
4936.68	773.847
4939.21	748.794
4941.74	711.784
4944.27	727.667
4946.79	717.216
4949.32	745.143
4951.85	759.875
4954.37	726.656
4956.9	733.131
4959.42	710.834
4961.94	746.388
4964.46	725.591
4966.98	751.682
4969.5	731.844
4972.02	730.073
4974.53	727.071
4977.05	720.451
4979.57	695.676
4982.08	727.839
4984.59	747.952
4987.1	713.472
4989.62	731.181
4992.13	709.962
4994.64	718.001
4997.15	713.944
4999.65	725.758