File: Data/3-Raman/raw/bu19(2)w-a-ff1-fi04-v_150 (500nm)_532nm_edge_100%_x100_vis_lwd_h50um_30sx2_01.txt
#Acq. time (s)=	30
#Accumulations=	2
#Range (cm-¹)=	99...4000
#Windows=	1
#Auto scanning=	Off
#Autofocus=	Off
#Macrospot=	Off
#AutoExposure=	Off
#Spike filter=	Multiple accum.
#Delay time (s)=	2
#Binning=	1
#Readout mode=	Signal
#DeNoise=	Off
#ICS correction=	On
#Dark correction=	Off
#Inst. Process=	Off
#Detector Gain=	Best Dynamic
#Detector ADC=	50 kHz HS
#Detector temperature (°C)=	-60.09
#Instrument=	LabRAM HR Evol
#Detector=	SIN-EM FIVIS
#Objective=	x100_VIS_LWD
#Grating=	150 (500nm)
#ND Filter=	100%
#Laser=	532nm_Edge
#Hole=	49.98
#Temperature=	0
#Range=	Visible
#StageXY=	75x50mm Scan+
#StageZ=	Z motor
#X (µm)=	0
#Y (µm)=	0
#Z (µm)=	-15.3
#Full time(mm:ss)=	1:04
#Project=	21_11_26
#Sample=	BU19(2)w
#Site=
#Title=	BU19(2)w-A-FF1-FI04-V_150 (500nm)_532nm_Edge_100%_x100_VIS_LWD_H50um_30sX2
#Remark=
#Date=	26.11.2021 13:18
#Acquired=	26.11.2021 13:18:24
102.91	4365.63
107.534	5025.66
112.156	5081.45
116.775	4075.65
121.392	3284.96
126.005	3066.45
130.617	3496.98
135.227	4516.53
139.835	6848.84
144.439	9490.08
149.042	9367.34
153.643	6888.27
158.242	4679.17
162.839	3282.91
167.431	2565.9
172.023	2359.07
176.613	2571.27
181.198	2816.77
185.783	2217.17
190.366	1956.57
194.947	1869.73
199.524	1879.56
204.1	2782.28
208.674	3958.74
213.243	2998.36
217.813	1873.03
222.38	1694.38
226.945	2298.15
231.506	3295.85
236.066	3348.03
240.625	2374.16
245.179	2113.69
249.732	1968.05
254.284	1313.44
258.831	1001.95
263.378	941.455
267.923	926.029
272.464	964.037
277.004	1124.49
281.54	1149.3
286.076	975.941
290.61	857.783
295.139	841.848
299.669	828.413
304.196	821.052
308.718	891.359
313.241	908.778
317.759	997.815
322.278	1138.97
326.794	1431.26
331.305	1852.44
335.817	1872.28
340.324	1713.22
344.832	1717.84
349.334	1992.2
353.837	1954.67
358.338	1478
362.834	1286.28
367.33	1188.11
371.822	1220.03
376.314	1339.22
380.802	1661.39
385.289	2464.45
389.772	3640.06
394.255	4150.84
398.734	3650.78
403.213	3135.62
407.688	2618.7
412.162	2341.55
416.632	2318.3
421.102	2404.27
425.568	2684.59
430.033	2820.39
434.495	2748.24
438.956	2609.7
443.413	2730.5
447.87	2969.89
452.323	3017.67
456.776	2617.99
461.224	2076.01
465.673	1629.18
470.117	1405.41
474.561	1392.8
479.001	1434.21
483.438	1574.41
487.876	1874.64
492.309	2348.12
496.742	3057.71
501.172	4098.93
505.601	5081.95
510.025	5566.18
514.448	5248.93
518.871	4575.89
523.289	3896.49
527.707	3447.96
532.121	3228.78
536.533	3175.54
540.945	3330.84
545.353	3391.13
549.758	3270.7
554.164	3105.55
558.565	2856.06
562.965	2508.87
567.364	2130.63
571.759	1882.82
576.151	1701.73
580.544	1680.19
584.933	1658.87
589.319	1854.96
593.706	2076
598.088	2403.04
602.468	2820.83
606.848	3630.2
611.224	5287.12
615.598	8505.49
619.972	10607.3
624.341	8682.84
628.709	5344.66
633.074	3420.45
637.44	2445.86
641.801	1923.44
646.16	1613.88
650.517	1388.33
654.874	1311.9
659.227	1144.15
663.578	1080.27
667.927	1015.17
672.275	1031.63
676.62	986.778
680.962	945.534
685.302	1000.67
689.643	999.525
693.979	1097.01
698.313	1252.57
702.645	1294.2
706.975	1330.91
711.305	1165.48
715.631	1119.02
719.955	1077
724.276	1056.86
728.596	1000.25
732.913	989.334
737.231	928.406
741.544	896.194
745.856	906.997
750.165	916.698
754.472	892.419
758.778	937.976
763.081	933.908
767.384	911.429
771.683	960.855
775.98	943.015
780.275	967.214
784.568	965.097
788.859	965.977
793.147	1003.55
797.434	1000.73
801.719	1028.12
806.004	1048.54
810.284	1110.05
814.563	1139.84
818.839	1191.84
823.114	1273.55
827.386	1412.93
831.657	1601.07
835.925	1780.66
840.192	2006.65
844.456	2112.37
848.719	2069.51
852.979	1932.78
857.237	1768.64
861.493	1643.18
865.748	1548.41
870	1562.16
874.25	1621.66
878.499	1697.03
882.745	1672.14
886.989	1468.59
891.231	1312.01
895.471	1232.93
899.71	1165.03
903.946	1150.78
908.18	1144.67
912.412	1103.61
916.642	1112
920.87	1130.93
925.096	1093.32
929.321	1099.33
933.543	1108.8
937.763	1115.99
941.981	1128.2
946.197	1156.25
950.412	1171.36
954.622	1156.89
958.832	1141.52
963.04	1172.06
967.246	1170.8
971.451	1185.6
975.653	1194.27
979.853	1241.21
984.052	1250.23
988.248	1296.26
992.442	1346.6
996.633	1437.1
1000.82	1536.07
1005.01	1447.77
1009.2	1440.22
1013.38	1349.69
1017.57	1353.38
1021.75	1424.24
1025.92	1365.77
1030.1	1435.92
1034.27	1533.44
1038.45	1695.48
1042.62	1884.89
1046.78	1950.19
1050.95	1961.49
1055.12	1934.12
1059.28	1963.4
1063.44	2099.51
1067.6	2255.27
1071.75	2483.18
1075.91	2892.31
1080.06	3506
1084.21	4625.22
1088.36	6160.3
1092.51	7819.66
1096.65	7881.99
1100.8	6130.16
1104.94	4159.01
1109.08	2969.16
1113.21	2468.15
1117.35	2219.64
1121.48	2134.52
1125.61	2135.12
1129.74	2272.44
1133.87	2530.73
1137.99	2902.04
1142.12	3367.81
1146.24	3505.46
1150.36	3232.33
1154.48	2690.53
1158.59	2286.22
1162.71	1977.08
1166.82	1780.78
1170.93	1644.98
1175.04	1529.37
1179.14	1435.3
1183.25	1387.65
1187.35	1376.67
1191.45	1337.22
1195.55	1295.47
1199.65	1282.07
1203.74	1312.19
1207.83	1303.44
1211.92	1319.08
1216.01	1315.52
1220.1	1341.32
1224.19	1322.96
1228.27	1322.02
1232.35	1340.6
1236.43	1378.15
1240.51	1421.44
1244.58	1582.2
1248.66	1749.4
1252.73	1613
1256.8	1478.86
1260.87	1526.75
1264.93	2967.31
1269	6394.42
1273.06	3135.9
1277.12	1612.11
1281.18	1454.14
1285.23	1400.17
1289.29	1431.39
1293.34	1388.98
1297.39	1372.51
1301.44	1389.14
1305.49	1386.36
1309.53	1363.32
1313.58	1347.18
1317.62	1359.78
1321.66	1376.1
1325.7	1360.69
1329.73	1356.18
1333.77	1395.71
1337.8	1415.61
1341.83	1434.2
1345.86	1421.61
1349.88	1475.81
1353.91	1612.44
1357.93	1576.82
1361.95	1638.35
1365.97	1972.15
1369.99	6676.43
1374	8156.42
1378.02	2665.51
1382.03	1648.45
1386.04	1538.37
1390.05	1709.21
1394.05	2066.5
1398.06	1641.97
1402.06	1380.52
1406.06	1389.81
1410.06	1406.14
1414.05	1383.18
1418.05	1317.79
1422.04	1328.33
1426.03	1304.13
1430.02	1301.98
1434.01	1288.09
1438	1312.68
1441.98	1296.81
1445.96	1280.74
1449.94	1277.44
1453.92	1290.68
1457.9	1292.93
1461.87	1260.47
1465.85	1268.01
1469.82	1232.2
1473.78	1287.97
1477.75	1308.14
1481.72	1285.95
1485.68	1243.19
1489.65	1244.42
1493.61	1269.16
1497.56	1284.12
1501.52	1295.29
1505.47	1281.37
1509.43	1269.78
1513.38	1272.86
1517.33	1263.4
1521.27	1285.13
1525.22	1248.74
1529.16	1304.58
1533.11	1303.36
1537.05	1301.21
1540.98	1295.22
1544.92	1296.99
1548.86	1258.07
1552.79	1281.17
1556.72	1300.22
1560.65	1256.14
1564.58	1311.62
1568.5	1268.27
1572.43	1321.51
1576.35	1305.13
1580.27	1295.48
1584.19	1304.12
1588.1	1333.85
1592.02	1317.29
1595.93	1329.58
1599.84	1291.89
1603.75	1311.97
1607.66	1305.37
1611.57	1328.53
1615.47	1325.88
1619.37	1323.43
1623.27	1340.05
1627.17	1356.86
1631.07	1310.68
1634.97	1326.19
1638.86	1314.84
1642.75	1327.76
1646.64	1348.64
1650.53	1317.91
1654.42	1316.94
1658.3	1345.62
1662.18	1365.64
1666.07	1317.17
1669.94	1321.4
1673.82	1305.99
1677.7	1320.3
1681.57	1300.27
1685.44	1323.12
1689.31	1342.94
1693.18	1311.68
1697.05	1374.04
1700.92	1304.19
1704.78	1338.21
1708.64	1320.44
1712.5	1356.59
1716.36	1357.53
1720.21	1329.21
1724.07	1318.97
1727.92	1345.39
1731.77	1316.03
1735.62	1345.04
1739.47	1330.73
1743.32	1361.12
1747.16	1321.61
1751.01	1366.72
1754.85	1321.22
1758.69	1355.41
1762.52	1327.81
1766.36	1363.29
1770.19	1342.65
1774.02	1339.37
1777.85	1311.92
1781.68	1297.9
1785.51	1301.8
1789.33	1294.63
1793.16	1298.74
1796.98	1286.94
1800.8	1300.41
1804.62	1330.97
1808.43	1321.92
1812.25	1269.33
1816.06	1328.69
1819.87	1274.29
1823.68	1299.74
1827.49	1314.57
1831.3	1273.4
1835.1	1289.42
1838.9	1278.83
1842.71	1271.83
1846.51	1326.52
1850.3	1273.38
1854.1	1282.53
1857.89	1287.57
1861.69	1284.72
1865.48	1313.38
1869.27	1279.83
1873.05	1288.26
1876.84	1307.09
1880.62	1304.72
1884.4	1313.05
1888.19	1311.29
1891.96	1282.5
1895.74	1277.69
1899.52	1312.45
1903.29	1275.99
1907.06	1264.63
1910.83	1278.25
1914.6	1249.02
1918.37	1298.29
1922.13	1270.86
1925.9	1294.4
1929.66	1236.59
1933.42	1267.94
1937.18	1306.83
1940.94	1274.87
1944.69	1290.46
1948.44	1286.42
1952.2	1286.98
1955.95	1270.11
1959.69	1298.58
1963.44	1289.05
1967.19	1343.31
1970.93	1343.61
1974.67	1352.78
1978.41	1304.51
1982.15	1338.47
1985.89	1361.82
1989.62	1370.01
1993.35	1355.61
1997.09	1381.88
2000.82	1313.16
2004.55	1318.85
2008.27	1301.27
2012	1337.82
2015.72	1298.85
2019.44	1276.27
2023.16	1292.95
2026.88	1231.6
2030.6	1307.71
2034.31	1270.89
2038.03	1275.71
2041.74	1252.95
2045.45	1243.81
2049.16	1266.76
2052.86	1245.08
2056.57	1245.45
2060.27	1218.96
2063.98	1232.66
2067.67	1215.43
2071.37	1228.64
2075.07	1207.77
2078.77	1229.44
2082.46	1183.65
2086.15	1189.52
2089.84	1203.27
2093.53	1208.11
2097.22	1194.95
2100.9	1183.42
2104.59	1205.89
2108.27	1219.78
2111.95	1219.52
2115.63	1170.89
2119.31	1224.35
2122.98	1170.48
2126.66	1220.35
2130.33	1199.5
2134	1167.47
2137.67	1216.78
2141.34	1202.07
2145	1173.39
2148.67	1162.2
2152.33	1196.94
2155.99	1164.69
2159.65	1190.25
2163.31	1197.6
2166.96	1179.56
2170.62	1160.87
2174.27	1141.78
2177.92	1153.93
2181.57	1129.83
2185.22	1143.89
2188.87	1140.07
2192.51	1145.79
2196.15	1167.46
2199.8	1162.09
2203.44	1124.01
2207.07	1119.82
2210.71	1128.6
2214.35	1111.93
2217.98	1094.36
2221.61	1117.16
2225.24	1095.02
2228.87	1114.19
2232.5	1121.46
2236.12	1104.81
2239.75	1142.69
2243.37	1094.44
2246.99	1105.42
2250.61	1106.26
2254.23	1109.08
2257.85	1072.81
2261.46	1102.77
2265.07	1063.4
2268.68	1069.97
2272.29	1045.79
2275.9	1067.37
2279.51	1100.98
2283.11	1046.16
2286.72	1095.12
2290.32	1098.78
2293.92	1082.42
2297.52	1070.81
2301.11	1041.24
2304.71	1078.71
2308.3	1098.93
2311.9	1186.3
2315.49	1398.63
2319.08	1178.51
2322.66	1074.77
2326.25	1051.91
2329.84	1080.99
2333.42	1042.82
2337	1089.47
2340.58	1042.63
2344.16	1053.17
2347.73	1035.39
2351.31	1067.22
2354.88	1056.82
2358.45	1008.14
2362.03	1019.18
2365.59	1032.01
2369.16	1005.9
2372.73	1015.32
2376.29	1044.97
2379.85	1006.25
2383.41	1034.12
2386.97	1045.44
2390.53	1009.14
2394.09	1004.34
2397.64	1010.84
2401.2	968.197
2404.75	979.257
2408.3	967.528
2411.85	978.213
2415.39	960.691
2418.94	948.882
2422.48	978.6
2426.03	969.929
2429.57	989.169
2433.11	921.731
2436.64	964.527
2440.18	950.006
2443.72	968.087
2447.25	991.875
2450.78	973.87
2454.31	964.379
2457.84	935.398
2461.37	929.984
2464.89	966.895
2468.42	955.884
2471.94	958.851
2475.46	945.13
2478.98	931.273
2482.5	910.987
2486.01	946.892
2489.53	925.704
2493.04	931.373
2496.55	930.88
2500.06	956.006
2503.57	903.11
2507.08	915.595
2510.58	933.425
2514.09	941.019
2517.59	924.664
2521.09	884.403
2524.59	926.973
2528.09	936.124
2531.59	898.384
2535.08	882.066
2538.58	900.17
2542.07	906.481
2545.56	874.466
2549.05	876.046
2552.54	884.141
2556.02	876.76
2559.51	863.302
2562.99	886.015
2566.47	858.975
2569.95	884.294
2573.43	849.21
2576.91	868.465
2580.38	872.953
2583.85	825.651
2587.33	866.971
2590.8	836.214
2594.27	878.071
2597.74	858.028
2601.2	852.474
2604.67	839.154
2608.13	843.512
2611.59	846.207
2615.06	829.113
2618.51	820.965
2621.97	844.174
2625.43	839.352
2628.88	845.831
2632.33	832.96
2635.79	838.128
2639.24	820.032
2642.69	812.356
2646.13	811.23
2649.58	830.1
2653.02	813.453
2656.47	834.701
2659.91	814.873
2663.35	814.928
2666.79	804.51
2670.22	793.178
2673.66	833.572
2677.09	763.208
2680.52	787.821
2683.95	779.804
2687.39	795.416
2690.81	765.828
2694.24	789.664
2697.66	782.578
2701.09	766.373
2704.51	791.139
2707.93	780.581
2711.35	758.483
2714.77	798.873
2718.18	751.008
2721.6	737.698
2725.01	771.107
2728.42	768.223
2731.84	740.13
2735.24	754.992
2738.65	747.395
2742.06	755.694
2745.46	730.055
2748.86	750.315
2752.27	722.655
2755.67	719.359
2759.07	745.163
2762.46	747.459
2765.86	735.422
2769.25	728.921
2772.65	732.661
2776.04	740.106
2779.43	730.464
2782.82	718.843
2786.2	730.705
2789.59	730.301
2792.98	712.95
2796.36	692.78
2799.74	717.696
2803.12	716.194
2806.5	711.89
2809.88	706.639
2813.25	706.97
2816.63	708.194
2820	718.741
2823.37	704.183
2826.74	696.272
2830.11	695.88
2833.48	706.765
2836.84	701.937
2840.21	687.916
2843.57	699.184
2846.93	670.55
2850.29	683.164
2853.65	653.016
2857.01	661.976
2860.36	681.33
2863.72	668.974
2867.07	686.612
2870.42	665.819
2873.77	703.182
2877.12	670.066
2880.47	662.282
2883.81	675.19
2887.16	657.884
2890.5	666.02
2893.84	672.241
2897.18	686.815
2900.52	670.094
2903.86	666.5
2907.19	662.822
2910.53	651.514
2913.86	648.673
2917.19	676.066
2920.52	632.398
2923.85	647.354
2927.18	658.458
2930.51	670.402
2933.83	664.312
2937.15	644.92
2940.48	650.071
2943.8	640.143
2947.11	650.019
2950.43	646.731
2953.75	656.583
2957.06	640.141
2960.38	651.051
2963.69	640.425
2967	639.228
2970.31	633.535
2973.62	628.895
2976.92	625.216
2980.23	643.22
2983.53	654.587
2986.84	643.471
2990.14	645.532
2993.44	629.771
2996.73	661.013
3000.03	635.915
3003.33	628.654
3006.62	609.16
3009.91	612.287
3013.2	637.11
3016.49	661.032
3019.78	608.594
3023.07	624.009
3026.35	615.848
3029.64	630.351
3032.92	640.132
3036.2	641.384
3039.48	618.03
3042.76	616.42
3046.04	620.502
3049.32	609.438
3052.59	629.632
3055.86	619.526
3059.14	622.663
3062.41	645.523
3065.68	648.562
3068.94	644.879
3072.21	660.036
3075.48	638.576
3078.74	631.057
3082	652.723
3085.26	657.881
3088.52	651.621
3091.78	663.582
3095.04	660.39
3098.29	665.86
3101.55	649.887
3104.8	667.066
3108.05	679.811
3111.3	684.856
3114.55	679.213
3117.8	676.485
3121.04	688.058
3124.29	691.064
3127.53	687.389
3130.77	669.399
3134.02	706.69
3137.25	714.423
3140.49	719.26
3143.73	725.994
3146.96	747.036
3150.2	749.059
3153.43	724.392
3156.66	761.691
3159.89	764.675
3163.12	776.221
3166.35	778.229
3169.57	784.937
3172.8	811.628
3176.02	806.793
3179.24	797.12
3182.46	834.182
3185.68	827.375
3188.9	840.499
3192.12	838.341
3195.33	834.276
3198.55	858.779
3201.76	888.008
3204.97	886.793
3208.18	903.693
3211.39	880.662
3214.6	895.757
3217.8	907.104
3221.01	905.133
3224.21	917.464
3227.41	917.519
3230.61	935.671
3233.81	921.545
3237.01	963.501
3240.21	951.426
3243.4	946.063
3246.59	972.181
3249.79	964.969
3252.98	981.683
3256.17	966.957
3259.36	1004.7
3262.54	1049.01
3265.73	1028.25
3268.92	1028.36
3272.1	1033.13
3275.28	1057.91
3278.46	1035.86
3281.64	1077.58
3284.82	1081.86
3288	1120.49
3291.17	1081.76
3294.35	1107.01
3297.52	1159.83
3300.69	1146.91
3303.86	1141.87
3307.03	1160.34
3310.2	1194.83
3313.36	1239.55
3316.53	1229.05
3319.69	1227.08
3322.85	1281.94
3326.02	1298.83
3329.18	1345.04
3332.33	1351.49
3335.49	1375.03
3338.65	1433.59
3341.8	1487.46
3344.95	1481.9
3348.11	1555.9
3351.26	1568.98
3354.41	1599
3357.56	1627.32
3360.7	1674.58
3363.85	1723.95
3366.99	1742.25
3370.13	1817.25
3373.28	1825.38
3376.42	1872.44
3379.56	1964.96
3382.69	2024.59
3385.83	2063.38
3388.97	2148.75
3392.1	2221
3395.23	2297
3398.36	2350.7
3401.49	2368.79
3404.62	2518.09
3407.75	2652.71
3410.88	2725
3414	2906.83
3417.13	3045.44
3420.25	3200.27
3423.37	3284.41
3426.49	3556.95
3429.61	3710.65
3432.73	3893.5
3435.84	4194.9
3438.96	4535.32
3442.07	4882.81
3445.18	5507.68
3448.29	6449.59
3451.4	7992.99
3454.51	9971.91
3457.62	11350.2
3460.72	10996.3
3463.83	9318.34
3466.93	7756.56
3470.03	6644.36
3473.13	6038.58
3476.23	5672.64
3479.33	5496.88
3482.43	5345.27
3485.53	5280.96
3488.62	5278.49
3491.71	5237.2
3494.81	5314.37
3497.9	5305.46
3500.99	5327.33
3504.07	5409.65
3507.16	5555.11
3510.25	5734.31
3513.33	5876.66
3516.41	6038.78
3519.5	6384.49
3522.58	6803.1
3525.66	7261.36
3528.73	7675.42
3531.81	8212.98
3534.89	8512.06
3537.96	8677.71
3541.03	8492.07
3544.11	7985.31
3547.18	7224.99
3550.25	6349.12
3553.32	5387.31
3556.38	4525.27
3559.45	3866.55
3562.51	3391.68
3565.58	2908.04
3568.64	2632.09
3571.7	2340.64
3574.76	2133.2
3577.82	1890.72
3580.87	1790.3
3583.93	1666.02
3586.98	1563.42
3590.04	1473.15
3593.09	1409.27
3596.14	1341.6
3599.19	1263.42
3602.24	1255.39
3605.29	1206.52
3608.33	1134.9
3611.38	1097.39
3614.42	1086.33
3617.46	1072.4
3620.5	1052.88
3623.54	1024.93
3626.58	990.452
3629.62	960.779
3632.65	941.441
3635.69	897.6
3638.72	878.489
3641.76	841.629
3644.79	806.758
3647.82	748.566
3650.84	753.202
3653.87	745.708
3656.9	713.783
3659.92	640.171
3662.95	629.443
3665.97	623.289
3668.99	607.417
3672.01	584.134
3675.03	566.516
3678.05	536.64
3681.07	541.706
3684.08	515.56
3687.1	510.194
3690.11	494.429
3693.12	489.074
3696.13	481.821
3699.14	490.58
3702.15	466.254
3705.16	442.843
3708.16	448.843
3711.17	428.183
3714.17	414.125
3717.17	434.249
3720.17	419.208
3723.17	421.238
3726.17	383.242
3729.17	389.004
3732.16	383.311
3735.16	405.195
3738.15	376.567
3741.14	385.993
3744.13	372.529
3747.13	376.164
3750.11	361.697
3753.1	364.32
3756.09	340.352
3759.07	350.578
3762.06	340.87
3765.04	351.044
3768.02	350.797
3771	342.062
3773.98	329.585
3776.96	339.833
3779.94	319.854
3782.91	328.249
3785.89	315.869
3788.86	314.843
3791.83	307.23
3794.8	321.376
3797.77	313.839
3800.74	300.657
3803.71	302.618
3806.68	304.596
3809.64	289.578
3812.61	293.47
3815.57	300.209
3818.53	301.286
3821.49	295.752
3824.45	295.902
3827.41	285.651
3830.36	278.235
3833.32	275.552
3836.27	297.571
3839.23	282.591
3842.18	283.748
3845.13	284.906
3848.08	277.503
3851.03	283.44
3853.98	301.798
3856.92	290.609
3859.87	280.358
3862.81	296.862
3865.75	279.887
3868.7	293.528
3871.64	264.996
3874.57	292.043
3877.51	274.005
3880.45	269.358
3883.39	277.167
3886.32	284.949
3889.25	280.217
3892.18	269.702
3895.12	271.67
3898.05	282.26
3900.97	257.236
3903.9	278.363
3906.83	290.797
3909.75	270.58
3912.68	263.797
3915.6	269.482
3918.52	268.423
3921.44	266.451
3924.36	270.187
3927.28	283.482
3930.2	265.095
3933.11	259.177
3936.03	260.03
3938.94	263.81
3941.86	260.934
3944.77	261.863
3947.68	280.04
3950.59	262.82
3953.49	254.234
3956.4	272.473
3959.31	277.333
3962.21	254.419
3965.12	256.426
3968.02	262.285
3970.92	257.608
3973.82	252.935
3976.72	272.26
3979.61	263.722
3982.51	255.16
3985.41	264.854
3988.3	255.308
3991.19	255.367
3994.09	255.395
3996.98	266.056
3999.87	275.755