File: Data/3-Raman/raw/bu19w-e-ff11b-fi07-v_1800 (450-850nm)_532nm_edge_100%_x100_vis_h50um_30sx2_01.txt
#Acq. time (s)=	30
#Accumulations=	2
#Range (cm-¹)=	1200...2400
#Windows=	4
#Auto scanning=	Off
#Autofocus=	Off
#Macrospot=	Off
#AutoExposure=	Off
#Spike filter=	Multiple accum.
#Delay time (s)=	2
#Binning=	1
#Readout mode=	Signal
#DeNoise=	Off
#ICS correction=	On
#Dark correction=	Off
#Inst. Process=	Off
#Detector Gain=	Best Dynamic
#Detector ADC=	50 kHz HS
#Detector temperature (°C)=	-60.09
#Instrument=	LabRAM HR Evol
#Detector=	SIN-EM FIVIS
#Objective=	x100_VIS
#Grating=	1800 (450-850nm)
#ND Filter=	100%
#Laser=	532nm_Edge
#Hole=	49.98
#Temperature=	0
#Range=	Visible
#StageXY=	75x50mm Scan+
#StageZ=	Z motor
#X (µm)=	0
#Y (µm)=	0
#Z (µm)=	-274.1
#Full time(mm:ss)=	4:21
#Project=	21_11_04
#Sample=	BU19w
#Site=
#Title=	BU19w-E-FF11b-FI07-V_1800 (450-850nm)_532nm_Edge_100%_x100_VIS_H50um_30sX2
#Remark=
#Date=	04.11.2021 17:55
#Acquired=	04.11.2021 17:55:30
1200.19	21.0114
1201.3	22.0444
1202.41	21.0172
1203.52	22.0438
1204.63	19.8835
1205.74	17.7018
1206.85	21.9552
1207.97	16.5862
1209.08	17.641
1210.19	20.8299
1211.3	24.0012
1212.41	20.7738
1213.52	26.0822
1214.63	20.7605
1215.74	22.8771
1216.85	21.7811
1217.95	19.6363
1219.06	21.7497
1220.17	18.5609
1221.28	21.7299
1222.39	22.7502
1223.5	22.7127
1224.61	18.4725
1225.71	21.6468
1226.82	25.8532
1227.93	23.6754
1229.03	26.884
1230.14	23.6989
1231.25	23.6438
1232.35	26.7907
1233.46	23.6372
1234.57	23.649
1235.67	25.7602
1236.78	23.6418
1237.88	23.608
1238.99	24.6364
1240.1	21.488
1241.2	21.4867
1242.3	26.7241
1243.41	21.4901
1244.51	23.5823
1245.62	27.7415
1246.72	22.5037
1247.82	22.4882
1248.93	23.5346
1250.03	23.5252
1251.13	26.6401
1252.24	24.5325
1253.34	25.5674
1254.44	25.5825
1255.54	21.4068
1256.65	26.6356
1257.75	29.758
1258.85	27.6595
1259.95	28.7114
1261.05	32.8557
1262.15	43.3846
1263.25	52.7261
1264.35	38.1516
1265.45	27.6885
1266.55	28.7474
1267.66	27.7347
1268.75	26.7172
1269.85	26.7006
1270.95	30.8694
1272.05	26.7009
1273.15	31.9726
1274.25	26.7479
1275.35	26.7565
1276.45	27.8275
1277.54	29.9545
1278.64	33.1352
1279.74	43.6462
1280.84	71.0296
1281.94	222.662
1283.03	488.188
1284.13	234.428
1285.23	71.0639
1286.32	43.6948
1287.42	34.2034
1288.52	33.1542
1289.61	26.8597
1290.71	30.0171
1291.8	23.6973
1292.9	28.9635
1293.99	26.8899
1295.09	29.0208
1296.18	23.7825
1297.28	25.8824
1298.37	27.9835
1299.47	20.5844
1300.56	20.5886
1301.65	23.7655
1302.75	27.9896
1303.84	21.6469
1304.94	25.8607
1306.03	22.6753
1307.12	21.622
1308.21	24.7863
1309.31	24.7996
1310.4	24.7992
1311.49	22.6951
1312.58	20.5884
1313.67	23.7491
1314.76	20.5896
1315.86	21.6515
1316.95	19.5381
1318.04	22.7136
1319.13	19.5432
1320.22	19.5424
1321.31	23.7448
1322.4	20.5641
1323.49	17.3985
1324.58	18.4533
1325.67	24.7415
1326.76	21.58
1327.85	18.4518
1328.93	22.6828
1330.02	20.5673
1331.11	24.7563
1332.2	19.4637
1333.29	23.6412
1334.37	20.4678
1335.46	18.355
1336.55	21.4901
1337.64	22.5246
1338.72	20.4182
1339.81	22.515
1340.9	21.4676
1341.98	20.4077
1343.07	23.5318
1344.16	24.5771
1345.24	20.376
1346.33	21.3909
1347.41	22.4119
1348.5	26.5694
1349.58	22.3852
1350.67	24.4469
1351.75	24.4371
1352.84	21.3402
1353.92	24.4289
1355.01	22.3292
1356.09	20.2556
1357.17	25.4386
1358.26	24.3838
1359.34	26.4419
1360.42	25.3793
1361.5	22.268
1362.59	25.367
1363.67	25.3799
1364.75	22.2619
1365.83	28.4486
1366.92	23.2536
1368	30.4952
1369.08	47.0456
1370.16	29.4496
1371.24	26.3232
1372.32	28.351
1373.4	27.3066
1374.48	27.2981
1375.56	30.3914
1376.64	30.362
1377.72	35.5335
1378.8	37.6293
1379.88	34.4957
1380.96	43.7102
1382.04	42.6102
1383.12	52.8119
1384.2	74.3419
1385.28	160.662
1386.36	750.35
1387.43	598.424
1388.51	111.374
1389.59	52.8572
1390.67	38.4333
1391.74	39.4311
1392.82	27.1252
1393.9	35.3027
1394.97	30.194
1396.05	30.1932
1397.13	32.2205
1398.2	30.1796
1399.28	25.0748
1400.35	24.0633
1401.43	24.07
1402.5	27.1959
1403.58	28.2209
1404.65	30.2596
1405.73	35.3651
1406.8	41.5163
1407.88	66.136
1408.95	61.0293
1410.03	33.3297
1411.1	24.0776
1412.17	23.0642
1413.25	21.0321
1414.32	23.0995
1415.39	27.2087
1416.47	25.1655
1417.54	24.1476
1418.61	23.1238
1419.68	21.0569
1420.75	24.1202
1421.83	22.0834
1422.9	24.2041
1423.97	20.9951
1425.04	23.0671
1426.11	22.0494
1427.18	22.0212
1428.25	18.9423
1429.32	21.0002
1430.39	21.023
1431.46	20.0139
1432.53	21.0201
1433.6	19.9683
1434.67	22.0317
1435.74	22.0288
1436.81	22.0219
1437.88	20.9967
1438.95	18.9549
1440.01	22.0458
1441.08	21.0204
1442.15	19.9977
1443.22	21.0163
1444.29	23.0749
1445.35	17.9524
1446.42	18.9726
1447.49	18.9657
1448.56	22.0519
1449.62	18.9667
1450.69	19.985
1451.75	16.9048
1452.82	17.9332
1453.89	22.0313
1454.95	18.9555
1456.02	18.9612
1457.08	16.9034
1458.15	18.952
1459.21	19.9795
1460.28	16.9013
1461.34	18.9402
1462.41	17.9026
1463.47	17.8926
1464.53	19.9726
1465.6	20.9231
1466.66	15.8135
1467.72	17.8511
1468.79	16.8274
1469.85	18.8532
1470.91	17.8258
1471.97	17.8193
1473.04	14.7599
1474.1	17.809
1475.16	15.7757
1476.22	16.7865
1477.29	19.8306
1478.34	19.8205
1479.41	18.7904
1480.47	16.7423
1481.53	18.7735
1482.59	15.7374
1483.65	16.7524
1484.71	20.7438
1485.77	16.7238
1486.83	17.7326
1487.89	16.7062
1488.95	18.7181
1490.01	16.6916
1491.07	20.7261
1492.12	19.7144
1493.18	15.6681
1494.24	20.7253
1495.3	15.6556
1496.36	16.6545
1497.42	17.6611
1498.47	16.6531
1499.53	17.6674
1500.59	18.6757
1501.64	18.6688
1502.7	15.6329
1503.76	18.6557
1504.81	19.6611
1505.87	18.6378
1506.93	16.6267
1507.98	17.6326
1509.04	17.6335
1510.09	17.6324
1511.15	17.6112
1512.21	16.574
1513.26	19.5747
1514.31	19.5854
1515.37	19.5641
1516.42	19.5524
1517.48	18.5513
1518.53	18.5576
1519.58	17.557
1520.64	14.5481
1521.69	18.5601
1522.75	16.5445
1523.8	17.5276
1524.85	19.529
1525.9	18.5403
1526.95	17.5388
1528.01	17.5325
1529.06	16.5267
1530.11	17.5268
1531.16	17.5354
1532.21	18.5387
1533.27	17.5544
1534.32	17.5523
1535.37	15.5318
1536.42	17.5141
1537.47	19.5036
1538.52	19.4926
1539.57	18.5323
1540.62	17.5471
1541.67	17.5314
1542.72	19.5167
1543.77	16.5015
1544.81	17.5177
1545.86	19.5331
1546.91	18.5371
1547.96	14.5188
1549.01	15.4939
1550.06	19.5571
1551.1	18.5754
1552.15	18.5814
1553.2	18.5581
1554.25	22.5477
1555.3	20.5355
1556.34	19.5326
1557.39	16.5282
1558.43	17.5099
1559.48	16.4944
1560.53	20.4861
1561.57	17.4994
1562.62	17.5008
1563.66	17.5071
1564.71	19.4925
1565.76	17.4876
1566.8	18.5001
1567.84	19.4961
1568.89	15.4911
1569.93	19.4885
1570.98	19.4847
1572.02	16.4788
1573.07	19.4627
1574.11	19.4708
1575.15	21.4862
1576.2	16.4849
1577.24	19.4549
1578.28	21.4341
1579.32	18.4452
1580.37	19.4443
1581.41	18.4353
1582.45	15.44
1583.49	19.4206
1584.53	18.4283
1585.58	17.4277
1586.62	16.4195
1587.66	17.4116
1588.7	18.4153
1589.74	18.4196
1590.78	18.4239
1591.82	18.4146
1592.86	19.3891
1593.9	22.3478
1594.94	19.3779
1595.98	17.3813
1597.02	19.3723
1598.06	17.3796
1599.1	17.3651
1600.14	19.3359
1601.17	17.3316
1602.21	19.2811
1603.25	22.1831
1604.29	21.0508
1605.33	19.7719
1606.37	20.0795
1607.4	20.3562
1608.44	16.448
1609.48	20.7085
1610.51	18.7345
1611.55	17.6814
1612.59	20.1551
1613.62	19.5072
1614.66	19.8582
1615.7	18.3256
1616.73	19.8594
1617.77	22.404
1618.8	21.1034
1619.84	20.0324
1620.87	22.3875
1621.91	18.8029
1622.94	20.1738
1623.98	20.5358
1625.01	19.7911
1626.04	18.6624
1627.08	20.2622
1628.11	20.1767
1629.07	19.2135
1630.12	18.224
1631.16	17.2413
1632.21	18.2392
1633.25	20.1993
1634.3	19.221
1635.34	17.246
1636.39	22.1625
1637.43	21.1682
1638.48	16.2418
1639.52	17.2256
1640.57	20.1862
1641.61	22.1503
1642.65	20.1783
1643.7	22.1412
1644.74	20.1704
1645.78	20.1713
1646.83	18.1961
1647.87	25.0783
1648.91	20.1818
1649.95	24.1262
1651	21.1864
1652.04	19.2176
1653.08	23.1534
1654.12	20.2034
1655.16	20.2195
1656.21	17.2742
1657.25	21.2183
1658.29	17.2638
1659.33	19.2251
1660.37	19.2306
1661.41	20.2308
1662.45	20.2693
1663.49	19.2329
1664.53	22.2299
1665.57	18.292
1666.61	19.2172
1667.65	21.2132
1668.69	20.247
1669.72	15.3079
1670.76	17.2974
1671.8	22.241
1672.84	20.2654
1673.88	18.2957
1674.92	15.3382
1675.95	17.3194
1676.99	21.2778
1678.03	18.2963
1679.07	17.2989
1680.1	13.3398
1681.14	16.3006
1682.18	18.2769
1683.21	18.2755
1684.25	17.2819
1685.29	18.2679
1686.32	17.2867
1687.36	17.2846
1688.39	18.2633
1689.43	17.2631
1690.46	17.2661
1691.5	18.2588
1692.53	18.2506
1693.57	13.3048
1694.6	17.2381
1695.64	17.2427
1696.67	17.2441
1697.7	16.2435
1698.74	16.2353
1699.77	16.236
1700.81	15.2471
1701.84	19.1692
1702.87	19.161
1703.9	15.2295
1704.94	17.195
1705.97	16.2054
1707	16.1899
1708.03	18.1295
1709.06	18.1115
1710.1	16.1535
1711.13	16.1606
1712.16	15.1746
1713.19	14.1725
1714.22	14.1629
1715.25	19.0534
1716.28	17.0903
1717.31	19.0123
1718.34	17.0403
1719.37	17.0373
1720.4	18.9807
1721.43	15.0732
1722.46	17.0011
1723.49	17.9645
1724.52	16.0121
1725.55	16.9597
1726.58	16.9547
1727.6	13.0771
1728.63	15.9249
1729.66	16.9066
1730.69	17.8784
1731.72	15.9451
1732.74	15.9352
1733.77	16.8767
1734.8	13.9656
1735.82	16.8435
1736.85	13.9487
1737.88	13.9394
1738.91	14.8861
1739.93	15.8204
1740.96	15.805
1741.98	14.8399
1743.01	13.8788
1744.03	14.8262
1745.06	16.739
1746.09	15.7714
1747.11	16.7101
1748.13	16.705
1749.16	15.7573
1750.18	16.7273
1751.21	16.7274
1752.23	15.7552
1753.26	12.8803
1754.28	14.7774
1755.3	17.6277
1756.33	16.6568
1757.35	16.6441
1758.37	16.6522
1759.39	16.653
1760.42	13.7929
1761.44	16.636
1762.46	17.5903
1763.48	16.6413
1764.5	15.7041
1765.53	13.805
1766.55	13.8026
1767.57	15.7001
1768.59	15.6875
1769.61	13.7691
1770.63	17.5782
1771.65	15.6908
1772.67	14.7499
1773.69	14.7558
1774.71	15.7134
1775.73	15.7298
1776.75	16.6773
1777.77	12.857
1778.79	18.5539
1779.81	17.6069
1780.83	18.5641
1781.85	16.6684
1782.86	13.8195
1783.88	15.7358
1784.9	17.6511
1785.92	15.7396
1786.94	16.7073
1787.95	12.9187
1788.97	15.8084
1789.99	17.7355
1791	15.8041
1792.02	16.7603
1793.04	15.8072
1794.05	16.7679
1795.07	13.9154
1796.09	17.7682
1797.1	16.8207
1798.12	16.8274
1799.13	15.8603
1800.15	16.8112
1801.16	13.9274
1802.18	14.8936
1803.19	16.8285
1804.21	16.8369
1805.22	15.8898
1806.24	15.9008
1807.25	14.939
1808.26	12.0489
1809.28	16.8715
1810.29	17.8361
1811.3	17.8348
1812.32	14.9482
1813.33	18.8162
1814.34	14.9734
1815.36	15.947
1816.37	17.8841
1817.38	14.0036
1818.39	17.8783
1819.4	19.8175
1820.42	15.9582
1821.43	14.0319
1822.44	17.9088
1823.45	16.9378
1824.46	17.9108
1825.47	16.9478
1826.48	17.9178
1827.49	15.0182
1828.5	17.9194
1829.51	14.0422
1830.52	16.9424
1831.53	15.9829
1832.54	15.0238
1833.55	15.0265
1834.56	18.8796
1835.57	14.9929
1836.58	17.9326
1837.58	16.9159
1838.59	13.0754
1839.6	17.9327
1840.61	15.9494
1841.62	13.9928
1842.62	16.8793
1843.63	14.9501
1844.64	17.8435
1845.65	16.8958
1846.65	13.0169
1847.66	17.8193
1848.67	16.8491
1849.67	14.9066
1850.68	15.8508
1851.68	18.7245
1852.69	14.8831
1853.69	19.6705
1854.7	13.9008
1855.71	15.8044
1856.71	16.7608
1857.72	13.8806
1858.72	13.8679
1859.72	13.8623
1860.73	17.6974
1861.73	13.8753
1862.74	16.7317
1863.74	10.9862
1864.74	15.7497
1865.75	13.8205
1866.75	16.652
1867.75	15.6863
1868.76	16.6372
1869.76	15.6831
1870.76	16.6317
1871.76	15.6737
1872.77	14.7146
1873.77	16.6056
1874.77	19.4326
1875.77	12.777
1876.77	18.4329
1877.77	15.6482
1878.78	15.6277
1879.78	14.6754
1880.78	15.6199
1881.78	16.5334
1882.78	16.5111
1883.78	16.4945
1884.78	16.5095
1885.78	14.6375
1886.78	14.628
1887.78	15.5555
1888.77	14.5932
1889.77	14.5921
1890.77	13.6568
1891.77	14.5958
1892.77	13.6427
1893.77	19.2691
1894.76	14.562
1895.76	17.3884
1896.76	14.5784
1897.76	14.5792
1898.75	13.6278
1899.75	15.4996
1900.75	12.6856
1901.75	13.6373
1902.74	15.5179
1903.74	16.4536
1904.74	17.3913
1905.73	16.4395
1906.73	17.3719
1907.72	19.2583
1908.72	11.7479
1909.71	14.5839
1910.71	12.7152
1911.7	12.7157
1912.7	15.5406
1913.69	14.6113
1914.69	15.5672
1915.68	15.5683
1916.68	14.6163
1917.67	15.5556
1918.66	16.5147
1919.66	16.5358
1920.65	16.5406
1921.64	16.5511
1922.64	13.7084
1923.63	14.6479
1924.62	14.6442
1925.61	16.5499
1926.61	14.6741
1927.6	15.6293
1928.59	14.6888
1929.58	13.7547
1930.57	16.6152
1931.57	16.6098
1932.56	14.7049
1933.55	14.7168
1934.54	16.6688
1935.53	16.6785
1936.52	14.7664
1937.51	15.7061
1938.5	17.6153
1939.49	17.6266
1940.48	14.7871
1941.47	16.6912
1942.46	15.755
1943.45	12.8757
1944.44	14.8029
1945.42	16.7293
1946.41	17.6941
1947.4	15.7777
1948.39	15.7775
1949.38	16.7486
1950.37	14.8572
1951.35	13.9194
1952.34	15.8469
1953.33	14.8819
1954.32	12.9343
1955.3	15.8134
1956.29	14.8808
1957.28	16.8148
1958.26	12.9761
1959.25	18.7356
1960.23	13.9229
1961.22	16.7938
1962.21	15.8372
1963.19	11.04
1964.18	13.9236
1965.16	15.8436
1966.15	15.8558
1967.13	13.9377
1968.12	14.9011
1969.1	15.8489
1970.09	17.7543
1971.07	13.9083
1972.05	16.7888
1973.04	14.8626
1974.02	13.8981
1975.01	14.8609
1975.99	14.8678
1976.97	17.7444
1977.95	16.7758
1978.94	16.774
1979.92	16.7734
1980.9	14.848
1981.88	14.8447
1982.87	17.7023
1983.85	16.7379
1984.83	15.7716
1985.81	15.7739
1986.79	17.5506
1987.77	15.9428
1988.75	17.4695
1989.73	16.2894
1990.72	15.4432
1991.7	15.8067
1992.68	16.3754
1993.66	15.9578
1994.63	14.8929
1995.61	14.8411
1996.59	15.8664
1997.57	17.58
1998.55	16.2796
1999.53	16.1174
2000.51	16.8964
2001.49	16.8453
2002.47	13.7223
2003.45	14.7989
2004.42	16.5424
2005.4	15.3797
2006.38	15.9533
2007.36	15.3216
2008.31	13.6835
2009.3	15.5534
2010.29	13.6571
2011.28	15.5392
2012.27	11.7689
2013.26	15.5135
2014.24	15.4857
2015.23	18.3069
2016.22	17.3864
2017.21	14.5611
2018.2	14.5393
2019.18	12.647
2020.17	16.3897
2021.16	14.5181
2022.15	15.447
2023.14	16.3672
2024.12	16.3511
2025.11	14.4637
2026.1	15.397
2027.08	13.5678
2028.07	14.446
2029.06	15.4472
2030.04	16.3192
2031.03	13.5292
2032.01	15.4068
2033	14.49
2033.98	16.3428
2034.97	14.4721
2035.95	16.3653
2036.94	15.4283
2037.92	15.4216
2038.91	14.4775
2039.89	17.2627
2040.87	16.3155
2041.86	14.4453
2042.84	15.3748
2043.83	15.3942
2044.81	17.2284
2045.79	16.3802
2046.78	13.5345
2047.76	17.2463
2048.74	14.4572
2049.72	14.4743
2050.71	16.348
2051.69	15.4073
2052.67	14.4809
2053.65	15.4327
2054.63	16.3692
2055.62	15.4266
2056.6	13.5534
2057.58	13.5593
2058.56	14.5072
2059.54	15.4471
2060.52	14.5079
2061.5	12.6399
2062.48	14.5183
2063.46	16.4015
2064.44	16.4092
2065.42	17.366
2066.4	16.4356
2067.38	17.3838
2068.36	14.5719
2069.34	15.497
2070.31	15.5132
2071.29	17.42
2072.27	18.3611
2073.25	12.7106
2074.23	16.4841
2075.21	15.5679
2076.18	14.6325
2077.16	17.447
2078.14	13.6797
2079.12	17.4708
2080.09	16.5374
2081.07	15.5896
2082.05	14.6467
2083.02	17.4818
2084	17.4816
2084.98	13.7028
2085.95	15.6042
2086.93	13.7213
2087.9	16.5625
2088.88	16.5683
2089.85	14.6833
2090.83	15.6372
2091.8	14.7048
2092.78	16.6224
2093.75	15.6866
2094.73	14.7346
2095.7	13.7758
2096.68	13.7717
2097.65	16.6127
2098.62	12.8128
2099.6	16.6077
2100.57	16.6158
2101.54	19.4713
2102.52	14.7183
2103.49	13.7639
2104.46	12.8204
2105.44	13.7804
2106.41	18.5383
2107.38	12.8314
2108.35	15.6671
2109.32	16.6244
2110.3	16.6247
2111.27	15.6711
2112.24	18.5203
2113.21	13.7811
2114.18	15.6806
2115.15	15.6795
2116.12	15.6706
2117.09	15.6691
2118.06	17.5554
2119.03	16.5909
2120	15.6342
2120.97	16.5912
2121.94	14.7079
2122.91	15.6644
2123.88	16.6078
2124.85	15.6337
2125.82	16.5615
2126.79	14.6566
2127.76	16.5428
2128.72	15.5962
2129.69	15.5926
2130.66	16.5316
2131.63	17.467
2132.6	14.6259
2133.56	15.571
2134.53	17.4588
2135.5	12.7355
2136.47	16.4981
2137.43	14.6187
2138.4	17.4417
2139.37	16.4923
2140.33	14.5995
2141.3	18.3603
2142.26	16.4767
2143.23	16.437
2144.19	14.5785
2145.16	17.3952
2146.13	16.4497
2147.09	15.5026
2148.06	15.4955
2149.02	16.422
2149.98	13.592
2150.95	17.3445
2151.91	17.3522
2152.88	16.4039
2153.84	14.5201
2154.8	14.4965
2155.77	18.2185
2156.73	13.5452
2157.69	14.4877
2158.66	18.2244
2159.62	16.3428
2160.58	14.4642
2161.54	16.3261
2162.51	15.3914
2163.47	18.1816
2164.43	16.3044
2165.39	14.4439
2166.35	15.3698
2167.32	14.4252
2168.28	16.2691
2169.24	16.281
2170.2	17.229
2171.16	14.4229
2172.12	14.4031
2173.08	16.2589
2174.04	16.2645
2175	12.5459
2175.96	15.3301
2176.92	12.5408
2177.88	14.3974
2178.84	16.2485
2179.8	14.3918
2180.76	16.2458
2181.72	12.528
2182.68	16.2316
2183.63	14.3638
2184.59	14.3636
2185.55	14.3704
2186.51	16.2405
2187.47	15.3252
2188.43	19.027
2189.38	15.2974
2190.34	18.0785
2191.3	17.1553
2192.25	15.3063
2193.21	13.4614
2194.17	15.34
2195.12	17.1915
2196.08	17.1712
2197.04	19.0136
2197.99	16.2385
2198.95	17.1872
2199.9	15.3559
2200.86	16.3096
2201.81	17.152
2202.77	16.2743
2203.72	16.318
2204.68	16.2927
2205.63	15.3409
2206.59	17.1998
2207.54	15.3525
2208.49	14.4329
2209.45	18.1602
2210.4	13.5107
2211.36	13.5207
2212.31	14.4582
2213.26	16.3154
2214.22	16.3334
2215.17	16.3386
2216.12	16.3386
2217.07	17.2719
2218.03	18.2073
2218.98	13.5475
2219.93	16.3554
2220.88	15.4142
2221.83	17.2693
2222.78	17.276
2223.74	14.4899
2224.69	14.5043
2225.64	16.3921
2226.59	16.4053
2227.54	15.4729
2228.49	12.6565
2229.44	15.4758
2230.39	14.5501
2231.34	17.3821
2232.29	18.3365
2233.24	17.4096
2234.19	14.5881
2235.14	14.5749
2236.09	13.6377
2237.04	19.2924
2237.98	16.4937
2238.93	14.6234
2239.88	15.5553
2240.83	13.6808
2241.78	13.6853
2242.73	14.6325
2243.67	15.5708
2244.62	14.6413
2245.57	13.7107
2246.52	10.8811
2247.46	15.6165
2248.41	13.7208
2249.36	15.617
2250.3	14.6625
2251.25	17.4903
2252.2	14.6622
2253.14	14.6855
2254.09	15.6449
2255.03	14.6966
2255.98	13.7552
2256.92	13.7648
2257.87	17.5687
2258.81	19.4777
2259.76	16.6344
2260.7	15.6952
2261.65	16.6532
2262.59	15.7128
2263.54	16.6879
2264.48	15.7545
2265.42	14.8065
2266.37	13.8405
2267.31	16.6928
2268.26	12.8727
2269.2	15.7483
2270.14	16.7224
2271.08	16.7339
2272.03	12.9152
2272.97	14.8321
2273.91	14.8356
2274.85	14.8396
2275.79	15.8044
2276.74	14.8605
2277.68	15.8438
2278.62	17.768
2279.56	17.7504
2280.5	12.9426
2281.44	15.816
2282.38	15.827
2283.32	15.8497
2284.26	16.8322
2285.2	16.8417
2286.14	17.795
2287.08	17.8165
2288.02	13.9667
2288.96	14.9149
2289.9	19.7074
2290.84	15.87
2291.78	13.9593
2292.72	15.8984
2293.66	14.9386
2294.6	14.9298
2295.54	17.8102
2296.47	17.8
2297.41	15.8898
2298.35	16.8685
2299.29	16.8813
2300.23	17.8482
2301.16	13.0309
2302.1	16.8895
2303.04	15.9236
2303.97	15.9314
2304.91	15.9407
2305.85	14.9808
2306.78	15.9479
2307.72	16.9081
2308.65	17.8772
2309.59	17.8948
2310.53	16.9274
2311.46	13.0346
2312.4	15.9206
2313.33	15.9342
2314.27	16.9223
2315.2	14.9878
2316.14	15.9342
2317.07	16.8997
2318	15.9332
2318.94	15.9237
2319.87	17.8518
2320.81	15.9289
2321.74	16.9119
2322.67	14.9847
2323.61	19.8235
2324.54	18.8441
2325.47	22.6876
2326.41	29.4207
2327.34	67.9545
2328.27	101.691
2329.2	31.303
2330.13	22.6333
2331.07	15.8934
2332	18.7818
2332.93	13.9586
2333.86	15.8759
2334.79	17.7909
2335.72	16.8298
2336.66	14.9028
2337.59	17.7831
2338.52	14.8984
2339.45	16.8193
2340.38	14.8869
2341.31	14.868
2342.24	14.8592
2343.17	16.7749
2344.1	16.7766
2345.02	15.8122
2345.95	14.8437
2346.88	15.7972
2347.81	16.7474
2348.74	16.6853
2349.67	15.6414
2350.6	17.4529
2351.53	15.2772
2352.45	16.5272
2353.38	16.5483
2354.31	14.1449
2355.24	18.2838
2356.17	14.1523
2357.09	15.9181
2358.02	16.1686
2358.95	15.8378
2359.87	15.4938
2360.8	16.3064
2361.73	15.4199
2362.65	15.8973
2363.58	17.3127
2364.5	13.1448
2365.43	17.4584
2366.36	14.2684
2367.28	14.0852
2368.2	17.9421
2368.98	14.6283
2369.92	15.557
2370.86	13.6606
2371.79	15.5366
2372.73	15.5276
2373.67	16.4604
2374.6	15.5088
2375.54	15.4994
2376.48	15.4913
2377.41	13.6076
2378.35	14.5349
2379.28	13.5814
2380.22	13.5745
2381.15	17.3172
2382.09	14.5079
2383.02	15.44
2383.96	14.5033
2384.89	14.4986
2385.83	17.2892
2386.76	11.6685
2387.69	17.2578
2388.63	14.4568
2389.56	17.2511
2390.5	15.3872
2391.43	17.2545
2392.36	14.4511
2393.3	11.6364
2394.23	13.4875
2395.16	14.4226
2396.09	16.3303
2397.02	14.4558
2397.96	15.3882
2398.89	15.387
2399.82	14.4556