File: Data/3-Raman/raw/bu19w-ff07b-fi06-v_1800 (450-850nm)_532nm_edge_100%_x100_vis_lwd_h50um_60sx2_01.txt
#Acq. time (s)=	60
#Accumulations=	2
#Range (cm-¹)=	1220...2360
#Windows=	3
#Auto scanning=	Off
#Autofocus=	Off
#Macrospot=	Off
#AutoExposure=	Off
#Spike filter=	Multiple accum.
#Delay time (s)=	2
#Binning=	1
#Readout mode=	Signal
#DeNoise=	Off
#ICS correction=	On
#Dark correction=	Off
#Inst. Process=	Off
#Detector Gain=	Best Dynamic
#Detector ADC=	50 kHz HS
#Detector temperature (°C)=	-60.09
#Instrument=	LabRAM HR Evol
#Detector=	SIN-EM FIVIS
#Objective=	x100_VIS_LWD
#Grating=	1800 (450-850nm)
#ND Filter=	100%
#Laser=	532nm_Edge
#Hole=	49.98
#Temperature=	0
#Range=	Visible
#StageXY=	75x50mm Scan+
#StageZ=	Z motor
#X (µm)=	0
#Y (µm)=	0
#Z (µm)=	-27
#Full time(mm:ss)=	6:18
#Project=	21_05_28
#Sample=	BU19w
#Site=
#Title=	BU19w-FF07b-FI06-V_1800 (450-850nm)_532nm_Edge_100%_x100_VIS_LWD_H50um_60sX2
#Remark=
#Date=	28.05.2021 16:25
#Acquired=	28.05.2021 16:25:46
1220.15	171.294
1220.98	156.42
1221.81	169.035
1222.64	159.281
1223.48	168.58
1224.31	173.702
1225.14	167.308
1225.97	166.313
1226.8	177.869
1227.63	194.43
1228.46	181.398
1229.29	196.476
1230.12	198.599
1230.95	228.936
1231.78	244.316
1232.61	274.74
1233.44	276.794
1234.27	288.421
1235.1	261.204
1235.93	247.612
1236.76	227.563
1237.59	221.052
1238.42	204.03
1239.25	215.445
1240.08	193.391
1240.91	205.986
1241.74	208.031
1242.57	216.41
1243.4	208.079
1244.23	228.01
1245.05	212.201
1245.88	247.599
1246.71	256.973
1247.54	278.919
1248.37	270.362
1249.19	290.263
1250.02	318.475
1250.85	323.474
1251.68	341.057
1252.51	289.711
1253.33	321.919
1254.16	293.855
1254.99	273.057
1255.81	266.798
1256.64	236.58
1257.47	225.055
1258.29	235.44
1259.12	199.871
1259.95	201.042
1260.77	201.913
1261.6	214.402
1262.43	231.685
1263.25	237.25
1264.08	258.808
1264.9	223.138
1265.73	202.181
1266.56	169.829
1267.38	164.718
1268.21	178.509
1269.03	173.392
1269.86	169.167
1270.68	154.385
1271.51	164.793
1272.33	162.805
1273.16	159.809
1273.98	154.692
1274.81	168.35
1275.63	158.958
1276.45	166.403
1277.28	170.702
1278.1	159.255
1278.93	176.186
1279.75	170.925
1280.57	194.056
1281.4	238.392
1282.22	396.352
1283.04	782.155
1283.87	1658.62
1284.69	1394.65
1285.51	442.713
1286.34	239.567
1287.16	202.663
1287.98	166.799
1288.8	183.658
1289.63	158.482
1290.45	163.802
1291.27	159.564
1292.09	150.081
1292.91	153.228
1293.74	153.359
1294.56	151.327
1295.38	147.197
1296.2	142.156
1297.02	141.093
1297.84	152.626
1298.66	144.147
1299.48	148.303
1300.31	146.238
1301.13	155.731
1301.95	150.512
1302.77	142.074
1303.59	143.08
1304.41	144.137
1305.23	143.032
1306.05	126.057
1306.87	153.448
1307.69	146.079
1308.51	145.025
1309.33	142.97
1310.15	136.663
1310.97	128.222
1311.79	130.36
1312.61	132.52
1313.43	145.157
1314.25	133.524
1315.06	127.23
1315.88	142.065
1316.7	135.707
1317.52	141.008
1318.34	134.696
1319.16	146.316
1319.98	135.753
1320.79	142.06
1321.61	148.278
1322.43	121.823
1323.25	135.477
1324.06	132.334
1324.88	141.824
1325.7	134.34
1326.52	135.191
1327.34	131.117
1328.15	131.262
1328.97	135.57
1329.79	133.458
1330.6	141.838
1331.42	133.273
1332.24	143.662
1333.05	137.21
1333.87	139.187
1334.69	128.584
1335.5	141.099
1336.32	141.032
1337.13	131.552
1337.95	128.344
1338.76	125.138
1339.58	145.029
1340.4	139.809
1341.21	139.802
1342.03	137.657
1342.84	129.185
1343.66	136.482
1344.47	135.438
1345.29	130.14
1346.1	130.018
1346.91	142.395
1347.73	143.334
1348.54	138.083
1349.36	136.967
1350.17	143.139
1350.99	127.439
1351.8	142.978
1352.61	138.875
1353.43	138.041
1354.24	126.321
1355.05	136.634
1355.87	133.52
1356.68	135.546
1357.49	131.349
1358.31	142.697
1359.12	140.543
1359.93	138.39
1360.75	135.185
1361.56	136.206
1362.37	128.919
1363.18	140.307
1363.99	147.619
1364.81	148.618
1365.62	155.764
1366.43	146.349
1367.24	145.207
1368.05	155.567
1368.87	161.799
1369.68	207.285
1370.49	150.35
1371.3	151.288
1372.11	152.151
1372.92	148.95
1373.73	134.473
1374.54	146.807
1375.35	143.702
1376.16	141.649
1376.97	154.904
1377.78	170.379
1378.6	154.121
1379.4	153.076
1380.21	159.103
1381.03	168.153
1381.83	160.829
1382.64	179.103
1383.45	195.355
1384.26	211.717
1385.07	271.364
1385.88	455.356
1386.69	1155.05
1387.5	3843.78
1388.31	1313
1389.12	383.462
1389.93	254.03
1390.73	190.169
1391.54	197.257
1392.35	165.375
1393.16	169.406
1393.97	154.012
1394.78	157.059
1395.58	143.82
1396.39	146.873
1397.2	153.967
1398.01	151.89
1398.81	151.93
1399.62	142.772
1400.43	140.765
1401.23	131.59
1402.04	146.015
1402.85	146.241
1403.66	143.208
1404.46	154.412
1405.27	150.247
1406.07	168.626
1406.88	176.814
1407.69	203.51
1408.49	263.023
1409.3	306.171
1410.11	192.33
1410.91	164.505
1411.72	156.233
1412.52	149.147
1413.33	132.003
1414.13	127.707
1414.94	128.844
1415.74	135.016
1416.55	138.137
1417.35	132.023
1418.16	138.21
1418.96	123.841
1419.77	126.878
1420.57	129.886
1421.38	132.914
1422.18	131.987
1422.98	126.085
1423.79	143.092
1424.59	131.699
1425.4	134.813
1426.2	129.764
1427	128.639
1427.81	128.513
1428.61	128.501
1429.41	132.637
1430.22	123.506
1431.02	133.894
1431.82	116.49
1432.62	121.551
1433.43	128.58
1434.23	125.444
1435.03	120.406
1435.83	127.569
1436.64	118.321
1437.44	122.397
1438.24	132.638
1439.04	129.599
1439.84	123.518
1440.65	128.692
1441.45	137.913
1442.25	133.818
1443.05	125.619
1443.85	110.2
1444.65	122.555
1445.45	121.573
1446.26	119.493
1447.05	125.619
1447.85	119.433
1448.66	119.486
1449.46	131.781
1450.26	117.373
1451.06	116.322
1451.86	125.513
1452.66	118.336
1453.46	126.566
1454.26	122.453
1455.06	121.423
1455.86	117.351
1456.66	105.042
1457.45	118.323
1458.25	123.439
1459.05	127.556
1459.85	120.383
1460.65	118.308
1461.45	121.336
1462.25	124.345
1463.05	125.288
1463.84	122.182
1464.64	118.237
1465.44	123.023
1466.24	127.1
1467.04	115.798
1467.84	109.659
1468.63	116.793
1469.43	121.855
1470.23	106.494
1471.03	120.729
1471.82	125.762
1472.62	115.568
1473.42	112.479
1474.22	122.625
1475.01	120.612
1475.81	106.345
1476.61	108.347
1477.4	122.546
1478.2	116.417
1478.99	113.313
1479.79	110.201
1480.59	124.316
1481.38	115.146
1482.18	124.338
1482.98	111.179
1483.77	122.363
1484.57	105.96
1485.36	119.821
1486.16	117.074
1486.95	117.04
1487.75	117.992
1488.54	117.926
1489.34	108.766
1490.13	119.882
1490.93	116.797
1491.72	116.77
1492.52	110.703
1493.31	111.704
1494.1	109.679
1494.9	126.867
1495.69	114.635
1496.49	118.615
1497.28	119.6
1498.08	116.562
1498.87	111.526
1499.66	113.57
1500.46	116.605
1501.25	122.63
1502.04	121.599
1502.83	113.475
1503.63	121.497
1504.42	120.51
1505.21	115.443
1506	104.274
1506.8	114.36
1507.59	126.468
1508.38	122.421
1509.17	110.338
1509.97	133.542
1510.76	120.374
1511.55	109.18
1512.34	111.022
1513.13	109.936
1513.93	121.021
1514.72	109.976
1515.51	120.926
1516.3	123.849
1517.09	107.782
1517.88	104.794
1518.67	109.835
1519.46	115.879
1520.25	114.861
1521.04	115.885
1521.83	114.881
1522.63	123.871
1523.42	105.741
1524.21	115.678
1525	123.679
1525.79	115.703
1526.57	121.787
1527.36	118.761
1528.15	114.723
1528.94	116.695
1529.73	119.677
1530.52	113.679
1531.31	119.744
1532.1	112.717
1532.89	113.78
1533.68	128.902
1534.47	123.878
1535.25	118.826
1536.04	124.716
1536.83	126.592
1537.62	124.532
1538.41	116.463
1539.2	116.515
1539.98	118.719
1540.77	116.833
1541.56	113.754
1542.35	112.667
1543.14	126.601
1543.92	109.507
1544.71	119.565
1545.5	112.658
1546.28	114.692
1547.07	111.711
1547.86	118.672
1548.64	118.706
1549.43	121.439
1550.22	118.75
1551	119.993
1551.79	116.918
1552.58	122.03
1553.36	118.879
1554.15	125.84
1554.93	128.734
1555.72	118.707
1556.51	121.699
1557.29	116.71
1558.08	112.651
1558.86	111.553
1559.65	118.473
1560.43	123.428
1561.22	121.419
1562	113.508
1562.79	118.505
1563.57	116.49
1564.36	116.586
1565.14	121.395
1565.92	120.198
1566.71	119.381
1567.49	124.557
1568.28	124.481
1569.06	123.454
1569.84	128.417
1570.63	118.43
1571.41	116.403
1572.19	129.349
1572.98	133.28
1573.76	122.255
1574.54	126.32
1575.33	121.413
1576.11	118.418
1576.89	119.336
1577.68	123.202
1578.46	111.16
1579.24	117.138
1580.02	124.149
1580.81	116.163
1581.59	125.08
1582.37	109.09
1583.15	120.026
1583.93	111.045
1584.72	121.028
1585.5	130.981
1586.28	111.998
1587.06	118.913
1587.84	115.907
1588.62	130.871
1589.4	120.962
1590.18	117.988
1590.97	110.046
1591.75	121.98
1592.53	114.922
1593.31	114.827
1594.09	123.662
1594.87	113.757
1595.65	114.727
1596.43	115.71
1597.21	109.769
1597.99	114.74
1598.77	120.621
1599.55	118.572
1600.33	125.453
1601.11	123.365
1601.89	113.361
1602.66	119.225
1603.44	118.168
1604.22	122.108
1605	119.149
1605.78	110.272
1606.56	121.195
1607.34	113.296
1608.12	127.14
1608.89	118.202
1609.67	124.034
1610.45	122.944
1611.23	113.99
1612.01	111.033
1612.79	126.838
1613.56	119.918
1614.34	113.959
1615.12	119.877
1615.9	119.855
1616.67	113.965
1617.45	113.958
1618.23	120.849
1619	127.701
1619.78	124.69
1620.56	118.752
1621.33	126.66
1622.11	121.753
1622.89	119.514
1623.66	115.162
1624.44	122.298
1625.21	111.469
1625.99	115.396
1626.77	105.832
1627.54	111.301
1628.32	120.101
1629.09	112.352
1629.87	111.064
1630.64	107.045
1631.42	117.62
1632.2	105.43
1632.97	112.539
1633.75	109.876
1634.52	103.414
1635.29	103.473
1636.07	105.95
1636.84	105.15
1637.62	103.788
1638.39	111.996
1639.17	103.794
1639.94	106.94
1640.71	109.165
1641.49	107.601
1642.26	94.7148
1643.04	96.8562
1643.81	105.252
1644.58	107.111
1645.36	96.4242
1646.12	87.0816
1646.9	97.8792
1647.68	93.915
1648.47	102.794
1649.25	98.9415
1650.03	94.0042
1650.81	103.928
1651.59	105.936
1652.38	96.0878
1653.16	99.0157
1653.94	98.05
1654.72	102.996
1655.5	100.109
1656.28	104.13
1657.07	102.164
1657.85	91.2827
1658.63	105.063
1659.41	100.087
1660.19	105.981
1660.97	98.1427
1661.75	109.048
1662.53	95.3607
1663.31	110.197
1664.09	94.2668
1664.87	98.3037
1665.65	113.985
1666.43	88.5067
1667.21	99.2076
1667.99	100.147
1668.77	99.2186
1669.55	101.245
1670.33	98.2855
1671.11	101.314
1671.89	90.4408
1672.67	103.299
1673.45	100.343
1674.23	103.346
1675.01	99.4375
1675.79	108.365
1676.56	99.468
1677.34	99.4614
1678.12	98.4262
1678.9	99.3645
1679.68	97.358
1680.46	108.201
1681.23	111.142
1682.01	103.237
1682.79	98.296
1683.57	103.232
1684.35	95.3046
1685.13	102.203
1685.9	95.2909
1686.68	96.3119
1687.46	110.14
1688.23	104.18
1689.01	102.155
1689.79	98.1522
1690.57	99.1453
1691.34	98.1829
1692.12	99.1883
1692.89	98.1578
1693.67	96.1045
1694.45	95.064
1695.22	97.0331
1696	100.993
1696.78	101.998
1697.55	96.0271
1698.33	97.9362
1699.1	105.775
1699.88	96.9256
1700.65	100.839
1701.43	108.685
1702.2	103.709
1702.98	96.7909
1703.75	88.9121
1704.53	94.8263
1705.3	111.522
1706.08	105.603
1706.85	96.6921
1707.63	104.467
1708.4	106.324
1709.18	101.338
1709.95	98.3837
1710.73	99.3816
1711.5	101.371
1712.27	98.4216
1713.05	107.106
1713.82	101.129
1714.59	96.2098
1715.37	107.958
1716.14	95.254
1716.91	109.83
1717.69	102.857
1718.46	109.564
1719.23	98.8254
1720.01	95.9101
1720.78	98.7948
1721.55	102.617
1722.32	100.596
1723.1	103.441
1723.87	95.6478
1724.64	102.407
1725.41	107.146
1726.18	110.957
1726.96	106.083
1727.73	100.268
1728.5	104.031
1729.27	96.0129
1730.04	106.745
1730.81	100.915
1731.59	106.794
1732.36	100.008
1733.13	100.92
1733.9	102.735
1734.67	99.7453
1735.44	98.6937
1736.21	103.466
1736.98	110.16
1737.75	105.307
1738.52	105.241
1739.29	99.3967
1740.06	102.146
1740.83	109.723
1741.6	109.652
1742.37	100.049
1743.14	102.896
1743.91	105.725
1744.68	103.78
1745.45	102.825
1746.22	97.041
1746.99	97.9196
1747.76	101.665
1748.53	104.526
1749.3	98.8266
1750.06	96.0231
1750.83	104.673
1751.6	106.572
1752.37	107.441
1753.14	105.462
1753.91	102.544
1754.68	109.16
1755.44	107.211
1756.21	98.5683
1756.98	105.137
1757.75	95.5858
1758.51	108.951
1759.28	96.5878
1760.05	108.948
1760.82	97.4989
1761.59	103.152
1762.35	104.092
1763.12	104.114
1763.88	93.6683
1764.65	101.35
1765.42	103.291
1766.19	101.395
1766.95	94.7148
1767.72	103.249
1768.48	114.641
1769.25	101.193
1770.02	90.6878
1770.78	105.935
1771.55	99.366
1772.31	106.057
1773.08	111.816
1773.84	98.5248
1774.61	110.924
1775.38	108.126
1776.14	108.203
1776.91	105.319
1777.67	101.46
1778.44	100.451
1779.2	102.28
1779.97	108.015
1780.73	109.946
1781.5	110.918
1782.26	103.351
1783.02	99.5866
1783.79	106.301
1784.55	100.642
1785.32	102.566
1786.08	106.358
1786.84	99.7184
1787.61	105.558
1788.37	106.712
1789.13	116.378
1789.9	113.578
1790.66	99.2209
1791.42	102.964
1792.19	101.996
1792.95	101.065
1793.71	101.084
1794.48	101.081
1795.24	106.014
1796	106.093
1796.76	99.4324
1797.53	101.409
1798.29	112.019
1799.05	104.321
1799.81	101.384
1800.57	107.109
1801.34	106.134
1802.1	102.31
1802.86	101.397
1803.62	96.6471
1804.38	98.6022
1805.14	86.1528
1805.9	103.552
1806.67	95.8892
1807.43	107.464
1808.19	110.362
1808.95	108.446
1809.71	104.604
1810.47	108.467
1811.23	98.8164
1811.99	95.9258
1812.75	110.43
1813.51	104.682
1814.27	103.792
1815.03	104.841
1815.79	102.932
1816.55	96.1902
1817.31	102.912
1818.07	108.662
1818.83	113.547
1819.59	101.981
1820.35	110.719
1821.11	113.659
1821.87	103.067
1822.62	96.3162
1823.38	105.031
1824.14	106.954
1824.9	100.207
1825.66	102.171
1826.42	106.049
1827.18	99.2857
1827.93	113.849
1828.69	104.136
1829.45	107.989
1830.21	107.96
1830.97	106.016
1831.72	107.029
1832.48	106.107
1833.24	109.044
1833.99	104.219
1834.75	103.142
1835.51	115.604
1836.27	103.172
1837.02	104.191
1837.78	99.1474
1838.54	108.777
1839.29	100.284
1840.05	106.097
1840.81	89.44
1841.56	109.596
1842.32	106.586
1843.08	107.551
1843.83	99.8332
1844.59	105.631
1845.34	103.69
1846.1	103.805
1846.86	101.819
1847.61	113.105
1848.37	109.329
1849.12	101.568
1849.88	108.215
1850.63	108.111
1851.39	111.889
1852.14	110.906
1852.9	103.225
1853.65	110.875
1854.41	110.774
1855.16	113.591
1855.91	101.057
1856.67	103.924
1857.42	108.69
1858.18	99.0703
1858.93	112.394
1859.68	107.55
1860.44	100.878
1861.19	107.628
1861.95	97.1322
1862.7	103.775
1863.45	107.526
1864.21	109.376
1864.96	112.174
1865.71	116.834
1866.46	105.256
1867.22	106.079
1867.97	103.155
1868.72	103.15
1869.47	107.895
1870.23	105.977
1870.98	105.968
1871.73	104.037
1872.48	102.097
1873.24	110.595
1873.99	102.016
1874.74	114.273
1875.49	106.593
1876.24	101.728
1876.99	108.267
1877.75	99.6048
1878.5	102.669
1879.25	107.519
1880	102.729
1880.75	103.679
1881.5	109.263
1882.25	107.2
1883	107.966
1883.75	107.993
1884.5	100.397
1885.25	109.914
1886	102.452
1886.75	108.101
1887.5	107.076
1888.25	109.809
1889	104.989
1889.75	108.719
1890.5	102.185
1891.25	97.4753
1892	106.879
1892.75	110.612
1893.5	115.161
1894.25	111.359
1895	105.689
1895.75	104.78
1896.5	106.71
1897.25	108.639
1897.99	108.643
1898.74	110.474
1899.49	114.166
1900.24	101.919
1900.99	106.642
1901.74	108.59
1902.49	117.117
1903.23	103.916
1903.98	101.074
1904.73	115.165
1905.47	116.095
1906.22	102.856
1906.97	106.582
1907.72	108.473
1908.47	108.516
1909.21	104.803
1909.96	103.954
1910.71	100.285
1911.45	107.857
1912.2	112.553
1912.95	103.133
1913.69	107.885
1914.44	114.572
1915.18	107.093
1915.93	105.208
1916.68	110.828
1917.42	105.122
1918.17	102.298
1918.92	106.152
1919.66	101.547
1920.41	107.242
1921.15	112.967
1921.9	102.614
1922.64	116.781
1923.39	109.18
1924.13	106.304
1924.88	104.396
1925.62	102.568
1926.37	115.9
1927.11	113.143
1927.86	111.295
1928.6	100.908
1929.34	110.438
1930.09	108.637
1930.83	116.304
1931.58	104.898
1932.32	111.498
1933.07	105.771
1933.81	111.541
1934.55	107.996
1935.3	112.021
1936.04	111.985
1936.78	116.711
1937.53	113.778
1938.27	116.584
1939.01	109.036
1939.76	110.994
1940.5	109.146
1941.24	107.359
1941.98	103.443
1942.73	113.145
1943.47	107.342
1944.21	114.066
1944.95	110.324
1945.69	99.8902
1946.44	102.808
1947.18	99.9393
1947.92	110.444
1948.66	104.702
1949.4	110.503
1950.15	116.35
1950.89	107.864
1951.63	111.825
1952.37	120.531
1953.11	108.088
1953.85	114.684
1954.59	115.462
1955.33	98.2
1956.07	110.801
1956.81	107.059
1957.55	109.05
1958.29	108.128
1959.03	109.071
1959.78	108.079
1960.52	108.028
1961.26	117.57
1962	104.131
1962.74	112.784
1963.47	106.078
1964.21	107.069
1964.95	97.4616
1965.69	116.675
1966.43	111.946
1967.17	106.212
1967.91	109.111
1968.65	115.836
1969.39	105.189
1970.13	96.4663
1970.87	103.137
1971.6	109.821
1972.34	106.008
1973.08	105.025
1973.82	102.093
1974.56	103.997
1975.3	114.568
1976.03	102.147
1976.77	105.038
1977.51	101.182
1978.25	108.807
1978.99	99.2021
1979.72	102.086
1980.46	121.231
1981.2	103.94
1981.93	120.199
1982.67	114.414
1983.41	106.676
1984.15	105.691
1984.88	102.786
1985.62	116.127
1986.35	122.862
1987.09	115.228
1987.83	109.41
1988.56	111.157
1989.3	107.142
1990.04	106.119
1990.77	110.963
1991.51	120.593
1992.24	107.288
1992.98	108.202
1993.71	112.856
1994.45	108.916
1995.18	104.975
1995.92	116.289
1996.66	110.611
1997.39	113.502
1998.13	115.397
1998.86	114.402
1999.59	115.966
2000.33	102.61
2001.06	108.479
2001.8	106.715
2002.53	108.85
2003.27	113.334
2004	102.021
2004.73	104.023
2005.47	111.951
2006.2	112.916
2006.94	104.41
2007.67	106.194
2008.4	102.118
2009.14	106.253
2009.87	103.964
2010.6	100.173
2011.34	101.33
2012.07	105.125
2012.8	99.4471
2013.54	105.104
2014.27	97.1849
2015	104.307
2015.73	100.489
2016.46	105.289
2017.2	97.6037
2017.93	100.852
2018.66	99.8664
2019.39	100.443
2020.13	99.3927
2020.86	100.986
2021.59	96.6114
2022.32	99.6437
2023.05	101.373
2023.78	98.3769
2024.52	101.959
2025.25	95.9276
2025.98	98.3457
2026.71	102.109
2027.38	97.7791
2028.12	93.8835
2028.86	97.9658
2029.6	100.503
2030.33	96.5402
2031.08	93.7859
2031.81	104.037
2032.55	94.802
2033.29	87.4015
2034.03	100.484
2034.77	92.8188
2035.51	101.351
2036.25	99.6111
2036.99	97.7135
2037.73	97.6992
2038.47	102.331
2039.2	99.4782
2039.94	93.8104
2040.68	99.333
2041.42	101.151
2042.16	103.915
2042.9	103.884
2043.63	99.3017
2044.37	98.4239
2045.11	93.6124
2045.85	92.9524
2046.59	98.5469
2047.32	97.5138
2048.06	105.807
2048.8	100.237
2049.53	93.7827
2050.27	96.6738
2051.01	96.6898
2051.75	103.177
2052.48	101.333
2053.22	98.5796
2053.96	94.9321
2054.69	93.0764
2055.43	92.1081
2056.17	99.5639
2056.9	99.5464
2057.64	106.117
2058.37	96.8231
2059.11	103.435
2059.85	106.26
2060.58	92.1814
2061.32	101.579
2062.05	98.7816
2062.79	98.8149
2063.52	99.8018
2064.26	102.643
2065	99.8828
2065.73	99.9678
2066.46	105.642
2067.2	99.101
2067.93	104.785
2068.67	97.2992
2069.4	97.2588
2070.14	91.5744
2070.87	108.641
2071.61	103.08
2072.34	97.4582
2073.08	99.3306
2073.81	87.0939
2074.54	105.965
2075.28	98.5372
2076.01	103.366
2076.74	91.0909
2077.48	105.156
2078.21	102.351
2078.94	105.217
2079.68	102.482
2080.41	108.201
2081.14	104.405
2081.88	108.178
2082.61	93.0821
2083.34	96.8592
2084.08	107.252
2084.81	101.588
2085.54	104.425
2086.27	100.713
2087	104.545
2087.74	99.8425
2088.47	100.799
2089.2	97.0404
2089.93	99.935
2090.66	95.2211
2091.39	102.836
2092.13	99.135
2092.86	105.878
2093.59	96.4566
2094.32	106.96
2095.05	89.8354
2095.78	99.293
2096.51	103.071
2097.24	106.831
2097.97	105.847
2098.71	102.98
2099.44	100.121
2100.17	95.3791
2100.9	105.864
2101.63	94.5071
2102.36	105.904
2103.09	112.504
2103.82	99.1946
2104.55	104.919
2105.28	117.32
2106.01	100.275
2106.74	102.197
2107.47	108.853
2108.2	110.673
2108.92	100.169
2109.66	96.4212
2110.38	104.973
2111.11	107.823
2111.84	102.092
2112.57	104.947
2113.3	98.3474
2114.03	103.122
2114.76	105.018
2115.48	111.658
2116.21	102.117
2116.94	103.034
2117.67	95.4274
2118.4	99.1662
2119.13	100.042
2119.85	101.878
2120.58	104.706
2121.31	109.5
2122.04	95.3448
2122.76	97.2893
2123.49	109.654
2124.22	101.072
2124.95	102.851
2125.67	103.686
2126.4	100.769
2127.13	96.9233
2127.85	116.758
2128.58	107.288
2129.31	104.44
2130.03	107.258
2130.76	94.951
2131.49	108.131
2132.21	108.094
2132.94	100.494
2133.66	108.052
2134.39	108.062
2135.11	104.279
2135.84	99.5263
2136.57	108.879
2137.29	107.007
2138.02	102.317
2138.74	100.406
2139.47	107.942
2140.19	104.105
2140.92	105.957
2141.64	110.634
2142.37	107.78
2143.09	102.266
2143.82	108.538
2144.54	104.87
2145.27	97.3165
2145.99	110.467
2146.71	104.8
2147.44	101.942
2148.16	111.299
2148.89	106.559
2149.61	113.971
2150.33	101.706
2151.06	104.518
2151.78	100.812
2152.5	106.443
2153.23	96.0802
2153.95	107.29
2154.67	99.6897
2155.4	101.443
2156.12	102.304
2156.84	105.09
2157.57	116.33
2158.29	105.156
2159.01	105.141
2159.73	106.955
2160.46	109.678
2161.18	104.043
2161.9	105.886
2162.62	104.952
2163.34	107.714
2164.07	111.407
2164.79	105.746
2165.51	110.424
2166.23	111.343
2166.95	106.635
2167.67	99.1147
2168.4	112.025
2169.12	105.54
2169.84	102.841
2170.56	106.633
2171.28	109.383
2172	109.222
2172.72	116.604
2173.44	110.096
2174.16	103.624
2174.88	111.993
2175.6	100.826
2176.32	104.523
2177.04	109.149
2177.76	109.152
2178.48	107.255
2179.2	109.097
2179.92	109.1
2180.64	108.16
2181.36	113.712
2182.08	110.895
2182.8	112.715
2183.52	110.779
2184.24	112.579
2184.96	116.299
2185.68	108.918
2186.4	116.4
2187.12	100.723
2187.83	102.632
2188.55	105.366
2189.27	118.274
2189.99	109.848
2190.71	108.009
2191.43	103.387
2192.14	109.908
2192.86	120.156
2193.58	100.73
2194.3	109.223
2195.01	106.429
2195.73	110.092
2196.45	111.842
2197.17	121.054
2197.88	109.915
2198.6	109.988
2199.32	112.881
2200.04	107.438
2200.75	114.11
2201.47	115.965
2202.19	103.366
2202.9	118.598
2203.62	126.223
2204.34	118.894
2205.05	107.524
2205.77	112.028
2206.49	104.611
2207.2	114.84
2207.92	113.983
2208.63	116.845
2209.35	113.155
2210.07	110.366
2210.78	127.189
2211.5	107.676
2212.21	108.673
2212.93	106.792
2213.64	113.275
2214.36	109.638
2215.07	113.424
2215.79	114.374
2216.5	119.038
2217.22	108.761
2217.93	108.771
2218.65	116.261
2219.36	111.652
2220.08	114.492
2220.79	116.349
2221.5	112.538
2222.22	114.35
2222.93	108.778
2223.65	113.515
2224.36	113.619
2225.07	111.826
2225.79	116.596
2226.5	119.475
2227.21	110.171
2227.93	111.123
2228.64	112.975
2229.35	116.717
2230.06	112.113
2230.78	115.935
2231.49	112.261
2232.2	117.029
2232.92	118.979
2233.63	113.4
2234.34	112.477
2235.05	113.37
2235.77	106.732
2236.48	105.81
2237.19	117.143
2237.9	116.329
2238.61	110.78
2239.32	125.006
2240.04	113.618
2240.75	108.005
2241.46	108.041
2242.17	109.957
2242.88	110.926
2243.59	109.946
2244.3	116.552
2245.02	119.502
2245.73	115.81
2246.44	114.933
2247.15	112.142
2247.86	114.048
2248.57	121.599
2249.28	119.691
2249.99	122.567
2250.7	119.661
2251.41	121.489
2252.12	114.892
2252.83	119.714
2253.54	119.859
2254.25	121.828
2254.96	118.037
2255.67	122.795
2256.38	117.16
2257.09	126.714
2257.8	114.423
2258.51	115.395
2259.22	118.294
2259.93	116.431
2260.63	119.321
2261.34	114.647
2262.05	114.672
2262.76	115.682
2263.47	110.064
2264.18	115.916
2264.88	116.97
2265.59	110.329
2266.3	116.023
2267.01	111.174
2267.72	117.798
2268.43	110.128
2269.13	110.182
2269.84	115.056
2270.55	117.06
2271.25	116.168
2271.96	118.137
2272.67	113.374
2273.38	115.309
2274.08	92.3598
2274.79	112.479
2275.5	113.457
2276.2	110.638
2276.91	106.879
2277.62	114.664
2278.32	121.49
2279.03	109.007
2279.74	121.4
2280.44	118.432
2281.15	113.593
2281.86	120.299
2282.56	110.769
2283.27	107.981
2283.97	123.506
2284.68	119.756
2285.38	107.306
2286.09	108.204
2286.79	115.947
2287.5	110.272
2288.2	117.044
2288.91	116.021
2289.61	116.857
2290.32	111.035
2291.02	119.72
2291.73	106.346
2292.43	114.112
2293.14	112.257
2293.84	104.576
2294.55	110.316
2295.25	111.232
2295.95	110.227
2296.66	116.894
2297.36	107.326
2298.07	114.165
2298.77	116.161
2299.47	123.952
2300.18	118.167
2300.88	108.56
2301.58	109.558
2302.29	118.228
2302.99	118.225
2303.69	115.331
2304.4	115.386
2305.1	114.476
2305.8	119.336
2306.51	114.538
2307.21	117.433
2307.91	117.4
2308.61	114.484
2309.32	117.438
2310.02	119.465
2310.72	116.567
2311.42	106.763
2312.12	118.246
2312.82	119.16
2313.53	121.168
2314.23	125.149
2314.93	122.372
2315.63	118.444
2316.33	116.382
2317.03	117.319
2317.73	115.444
2318.44	114.425
2319.14	109.546
2319.84	116.271
2320.54	117.245
2321.24	118.267
2321.94	112.561
2322.64	130.026
2323.34	123.274
2324.04	112.654
2324.74	125.17
2325.44	123.132
2326.14	139.466
2326.84	146.128
2327.54	183.642
2328.24	328.196
2328.94	357.982
2329.64	182.518
2330.34	142.066
2331.04	134.342
2331.74	118.99
2332.44	119.908
2333.14	120.823
2333.84	123.672
2334.53	114.942
2335.23	121.649
2335.93	112.042
2336.63	124.518
2337.33	106.236
2338.03	120.635
2338.73	117.741
2339.42	116.786
2340.12	122.518
2340.82	118.603
2341.52	106.012
2342.22	121.294
2342.91	115.512
2343.61	119.34
2344.31	119.351
2345	114.545
2345.7	119.27
2346.4	116.353
2347.1	114.415
2347.79	118.245
2348.49	119.233
2349.19	110.565
2349.88	118.052
2350.58	116.709
2351.28	123.941
2351.97	113.09
2352.67	121.586
2353.37	123.375
2354.06	112.866
2354.76	121.495
2355.45	117.659
2356.15	118.558
2356.85	119.372
2357.54	114.558
2358.24	115.473
2358.93	117.323
2359.63	121.09
2359.86	116.318