File: Data/3-Raman/raw/bu19w-ff2-fi03-s_150 (500nm)_532nm_edge_100%_x100_vis_h50um_15sx2_01.txt
#Acq. time (s)=	15
#Accumulations=	2
#Range (cm-¹)=	100...5000
#Windows=	1
#Auto scanning=	Off
#Autofocus=	Off
#Macrospot=	Off
#AutoExposure=	Off
#Spike filter=	Multiple accum.
#Delay time (s)=	2
#Binning=	1
#Readout mode=	Signal
#DeNoise=	Off
#ICS correction=	On
#Dark correction=	Off
#Inst. Process=	Off
#Detector Gain=	Best Dynamic
#Detector ADC=	50 kHz HS
#Detector temperature (°C)=	-60.09
#Instrument=	LabRAM HR Evol
#Detector=	SIN-EM FIVIS
#Objective=	x100_VIS
#Grating=	150 (500nm)
#ND Filter=	100%
#Laser=	532nm_Edge
#Hole=	49.98
#Temperature=	0
#Range=	Visible
#StageXY=	75x50mm Scan+
#StageZ=	Z motor
#X (µm)=	0
#Y (µm)=	0
#Z (µm)=	-210.8
#Full time(s)=	35
#Project=	21_05_14
#Sample=	BU19w
#Site=
#Title=	BU19w-FF2-FI03-S_150 (500nm)_532nm_Edge_100%_x100_VIS_H50um_15sX2
#Remark=
#Date=	14.05.2021 17:32
#Acquired=	14.05.2021 17:32:40
102.699	1794.18
107.322	1809.91
111.942	1733.23
116.56	1670.19
121.173	1823.56
125.787	2033.8
130.398	1950.71
135.006	1849.49
139.613	1571.76
144.215	1509.76
148.817	1516.58
153.417	1838.93
158.014	2380.46
162.607	2077.73
167.2	1560.07
171.79	1429.81
176.379	1401.4
180.963	1747.47
185.547	2202.43
190.128	2009.18
194.705	1626.32
199.282	1380.48
203.857	1310.64
208.43	1328.9
212.998	1337.38
217.566	1304.29
222.132	1295.63
226.693	1415.03
231.254	1568.28
235.813	1635.94
240.368	1917.79
244.923	2254.06
249.475	1836.49
254.023	1550
258.571	1445.15
263.117	1552
267.658	1795.74
272.199	2649.24
276.738	4015.42
281.273	4002.25
285.807	2899.41
290.34	1939.58
294.868	1844.84
299.396	1914.51
303.919	1836.43
308.443	1685.95
312.964	1600.52
317.481	1552.89
321.998	1728.52
326.51	1983.31
331.023	1953.23
335.533	1652.29
340.039	1661.45
344.544	2038.91
349.046	2251.59
353.547	1987.7
358.045	1644.74
362.542	1630.47
367.036	1677.63
371.527	1675.02
376.017	1510.26
380.503	1479.81
384.99	1545.65
389.471	1594.24
393.953	1677.17
398.43	1565.43
402.908	1402.34
407.381	1488.55
411.854	1863.13
416.323	2121.08
420.791	1694.35
425.256	1345.28
429.72	1249.14
434.18	1209.14
438.64	1196.68
443.095	1199.61
447.551	1201.29
452.003	1286.72
456.454	1321.06
460.901	1290.87
465.348	1313.3
469.791	1288.93
474.231	1339.59
478.672	1381.1
483.108	1461.17
487.544	1567.13
491.976	1698.56
496.408	1745.05
500.836	1602.68
505.261	1504.08
509.687	1384.45
514.108	1293.95
518.529	1286.74
522.946	1246.69
527.361	1245.99
531.776	1303.55
536.187	1311.48
540.595	1304.33
545.003	1301.76
549.408	1325.92
553.812	1341.4
558.212	1364.26
562.61	1334.98
567.007	1310.22
571.401	1301.92
575.792	1332.2
580.184	1469.85
584.571	1821.78
588.956	2017.08
593.341	1744.84
597.722	1527.69
602.101	1582.42
606.48	1785.53
610.854	2016.69
615.227	1780.29
619.597	1546.16
623.967	1454.69
628.334	1545.63
632.698	1646.97
637.06	1571
641.422	1458.43
645.779	1438.78
650.135	1399.22
654.491	1456.87
658.842	1606.67
663.192	1695.79
667.539	1763.76
671.884	1830.72
676.23	1821.77
680.571	1743.05
684.91	1499.05
689.247	1383.14
693.583	1310.79
697.916	1260.94
702.247	1235.7
706.576	1209.1
710.902	1224.7
715.229	1193.48
719.551	1179.75
723.872	1199.44
728.19	1227.35
732.506	1189.5
736.82	1215.73
741.134	1239.11
745.444	1238.46
749.752	1291.8
754.058	1299.49
758.362	1327.18
762.664	1379.93
766.964	1492.2
771.264	1703.98
775.559	1907.84
779.853	1980.73
784.144	1848.19
788.434	1656.53
792.722	1533.62
797.007	1414.72
801.29	1403.87
805.572	1369.56
809.851	1294.8
814.13	1280.84
818.406	1278.87
822.679	1311.38
826.95	1272.52
831.219	1270.05
835.486	1363.43
839.752	1281.39
844.015	1376.68
848.276	1328.65
852.535	1311.42
856.792	1346.01
861.047	1303.33
865.3	1281.16
869.551	1285.13
873.8	1290.92
878.047	1236.22
882.292	1266.51
886.534	1273.19
890.775	1275.39
895.014	1277.67
899.251	1287.39
903.486	1317.87
907.719	1338.07
911.95	1340.79
916.179	1308.64
920.406	1337.04
924.63	1351.63
928.853	1312.3
933.074	1373.05
937.293	1428.87
941.51	1542.12
945.723	1694.19
949.936	1675.68
954.147	1637.18
958.356	1562.84
962.563	1529.25
966.768	1543.58
970.971	1501.03
975.172	1526.47
979.371	1548.04
983.568	1543.22
987.761	1639.71
991.954	1842
996.145	2228.19
1000.33	2332.65
1004.52	1936.41
1008.71	1718.17
1012.89	1593.47
1017.07	1555.86
1021.25	1620.55
1025.43	1736.75
1029.6	2006.96
1033.77	2097.88
1037.95	2026.56
1042.11	2194.2
1046.28	2560.28
1050.45	2753.69
1054.61	2652.16
1058.77	2205.19
1062.93	1894.47
1067.09	1785.96
1071.24	1721.58
1075.4	1790.43
1079.55	1947.29
1083.7	2278.19
1087.85	2700.22
1091.99	2773.42
1096.14	2554.02
1100.28	2407.73
1104.42	2458.45
1108.55	2624.82
1112.69	2608.16
1116.82	2415.82
1120.96	2256.46
1125.09	2293.29
1129.21	2379.72
1133.34	2388.02
1137.46	2172.75
1141.59	1978.18
1145.71	1854.78
1149.83	1930.01
1153.94	2117.72
1158.06	2131.93
1162.17	2022.42
1166.28	1945.61
1170.39	1881.5
1174.5	1755.19
1178.6	1635.16
1182.7	1560.56
1186.8	1528.1
1190.9	1499.41
1195	1575.63
1199.1	1520.45
1203.19	1512.13
1207.28	1500.81
1211.37	1481.58
1215.46	1542.15
1219.54	1651.99
1223.63	1698.22
1227.71	1623.81
1231.79	1557.26
1235.87	1625.73
1239.95	1689.44
1244.02	1607.59
1248.09	1515.95
1252.16	1498.55
1256.23	1440.43
1260.3	1453.46
1264.36	1440.71
1268.43	1476.38
1272.49	1388.79
1276.55	1434.5
1280.6	1436.99
1284.66	1467.23
1288.71	1448.14
1292.76	1432.72
1296.81	1447.44
1300.86	1425.63
1304.91	1407.6
1308.95	1417.84
1312.99	1439.68
1317.03	1455.97
1321.07	1436.84
1325.11	1486.32
1329.14	1477.74
1333.18	1499.67
1337.21	1486.16
1341.24	1477.52
1345.26	1502.71
1349.29	1479.07
1353.31	1486.36
1357.33	1450.97
1361.35	1524.6
1365.37	1480.77
1369.39	1527.08
1373.4	1530.3
1377.41	1486.36
1381.43	1501.11
1385.43	1479.04
1389.44	1482.73
1393.45	1504.8
1397.45	1472.01
1401.45	1470.41
1405.45	1469.99
1409.45	1488.42
1413.44	1456.66
1417.44	1517.6
1421.43	1491.62
1425.42	1513.5
1429.41	1513.15
1433.39	1595.17
1437.38	1565.35
1441.36	1586.93
1445.34	1545.98
1449.32	1569.15
1453.3	1555.47
1457.27	1544.64
1461.24	1548.14
1465.22	1514.91
1469.19	1527.11
1473.15	1529.51
1477.12	1529.62
1481.09	1527.68
1485.05	1552.02
1489.01	1506
1492.97	1539.22
1496.93	1543.18
1500.88	1479.29
1504.83	1516.96
1508.79	1548.09
1512.74	1498.6
1516.68	1524.05
1520.63	1537
1524.57	1529.68
1528.52	1514.77
1532.46	1516.47
1536.4	1508.48
1540.33	1539.31
1544.27	1564.3
1548.2	1562.17
1552.14	1557.04
1556.07	1586.52
1559.99	1569.31
1563.92	1574.21
1567.84	1593.47
1571.77	1577.86
1575.69	1573.82
1579.61	1597.69
1583.52	1578.09
1587.44	1590.19
1591.35	1605.15
1595.27	1579.69
1599.18	1604.29
1603.09	1590.67
1606.99	1594.5
1610.9	1629.98
1614.8	1627.32
1618.7	1588.33
1622.6	1621.19
1626.5	1592.15
1630.39	1592.15
1634.29	1619.23
1638.18	1647.33
1642.07	1628.08
1645.96	1608.99
1649.85	1636.99
1653.73	1589.15
1657.62	1665.02
1661.5	1620.68
1665.38	1644.26
1669.26	1649.26
1673.13	1652.94
1677.01	1649.46
1680.88	1649.04
1684.75	1618.71
1688.62	1676.37
1692.49	1641.69
1696.35	1648.92
1700.22	1667.25
1704.08	1683.25
1707.94	1676.02
1711.8	1695.22
1715.66	1707.8
1719.51	1672.22
1723.37	1691.39
1727.22	1708.35
1731.07	1690.45
1734.92	1658.6
1738.76	1720.05
1742.61	1693.58
1746.45	1703.2
1750.29	1709.07
1754.13	1715.66
1757.97	1677.92
1761.81	1689.22
1765.64	1704.48
1769.47	1710.61
1773.31	1679.88
1777.14	1718.29
1780.96	1695.72
1784.79	1721.85
1788.61	1683.61
1792.43	1727.81
1796.25	1748.65
1800.07	1720.89
1803.89	1728.19
1807.71	1726.96
1811.52	1734.86
1815.33	1719.55
1819.14	1747.02
1822.95	1725.08
1826.76	1745.18
1830.56	1783.63
1834.37	1744.44
1838.17	1753.03
1841.97	1785.68
1845.77	1759.06
1849.56	1817.45
1853.36	1789.81
1857.15	1801
1860.94	1776.38
1864.73	1792.8
1868.52	1823.27
1872.31	1863.16
1876.09	1831.12
1879.87	1780.3
1883.66	1804.64
1887.43	1851.28
1891.21	1838.21
1894.99	1803.85
1898.76	1818.75
1902.53	1850.81
1906.31	1865.62
1910.08	1846.83
1913.84	1865.3
1917.61	1813.39
1921.37	1869.34
1925.14	1847.79
1928.9	1859.86
1932.66	1896.22
1936.41	1868.27
1940.17	1887.83
1943.92	1886.31
1947.68	1932.84
1951.43	1901.74
1955.18	1930.77
1958.92	1925
1962.67	1932.21
1966.41	1927.93
1970.16	1927.36
1973.9	1937.66
1977.64	1967.2
1981.37	1871.11
1985.11	1967.24
1988.84	1989.29
1992.57	2002.4
1996.31	1984.5
2000.03	1962.7
2003.76	1952.36
2007.49	1959.8
2011.21	1997.48
2014.93	2028.16
2018.65	1994.09
2022.37	2043.44
2026.09	2003.17
2029.81	1989.1
2033.52	2011.73
2037.23	1988.94
2040.94	2046.84
2044.65	2039.43
2048.36	2033.38
2052.07	2017.52
2055.77	2024
2059.47	2039.48
2063.17	2019.85
2066.87	2016.96
2070.57	2066.7
2074.27	2090.79
2077.96	2083.72
2081.65	2075.62
2085.34	2053.23
2089.03	2083.83
2092.72	2122.95
2096.41	2143.93
2100.09	2104.33
2103.77	2129.48
2107.46	2104.95
2111.14	2121.16
2114.81	2138.21
2118.49	2139.74
2122.16	2155.28
2125.84	2208.63
2129.51	2149.41
2133.18	2198.47
2136.85	2179.7
2140.51	2220.49
2144.18	2192.82
2147.84	2182.65
2151.5	2226.64
2155.16	2240.4
2158.82	2202.13
2162.48	2225.54
2166.13	2203.64
2169.79	2208.85
2173.44	2170.34
2177.09	2278.56
2180.74	2233.15
2184.38	2283.29
2188.03	2257.18
2191.67	2309.2
2195.32	2312.97
2198.96	2296.89
2202.6	2276.55
2206.23	2321.43
2209.87	2318.3
2213.5	2349.28
2217.14	2299.63
2220.77	2358.39
2224.4	2363.94
2228.03	2415.46
2231.65	2412.89
2235.28	2490.85
2238.9	2561.51
2242.52	2563.68
2246.14	2489.6
2249.76	2450.92
2253.38	2438.48
2256.99	2386.83
2260.6	2422.74
2264.21	2426.82
2267.82	2376.05
2271.44	2405.07
2275.04	2424.71
2278.65	2427.4
2282.25	2429.83
2285.85	2415.78
2289.45	2434.36
2293.05	2483.14
2296.65	2442.21
2300.25	2499.57
2303.84	2508.05
2307.43	2470.62
2311.02	2476.45
2314.62	2506.49
2318.2	2505.7
2321.79	2507.64
2325.38	2538.7
2328.96	2494.22
2332.54	2569.15
2336.12	2558.82
2339.7	2544.42
2343.28	2534.49
2346.85	2579.6
2350.43	2577.65
2354	2568.09
2357.57	2618.96
2361.14	2618.37
2364.71	2590.95
2368.27	2597.43
2371.84	2600.48
2375.4	2639.25
2378.96	2657.95
2382.52	2612.46
2386.08	2651.07
2389.64	2635.96
2393.19	2671.07
2396.75	2674.03
2400.3	2668.1
2403.85	2649.42
2407.4	2696.33
2410.95	2692.11
2414.49	2657.13
2418.04	2676
2421.58	2637.37
2425.12	2693.43
2428.66	2641.21
2432.2	2711.58
2435.74	2695.43
2439.27	2691.49
2442.81	2705.39
2446.34	2714.97
2449.87	2756.15
2453.4	2765.75
2456.93	2715.48
2460.45	2757.13
2463.98	2777.07
2467.5	2755.19
2471.02	2805.41
2474.54	2851.91
2478.06	2766.47
2481.58	2782.36
2485.09	2809.82
2488.61	2845.63
2492.12	2838.51
2495.63	2817.52
2499.14	2812.96
2502.65	2816.66
2506.15	2865.66
2509.66	2899.34
2513.16	2815.47
2516.66	2896.72
2520.16	2867.95
2523.66	2869.49
2527.16	2921.4
2530.66	2874.81
2534.15	2850.34
2537.64	2901.19
2541.13	2927.42
2544.62	2825.03
2548.11	2936.22
2551.6	2919.46
2555.08	2908.07
2558.57	2960.65
2562.05	2924.41
2565.53	2892.75
2569.01	2938.34
2572.49	2991.31
2575.96	2932.52
2579.44	2868.94
2582.91	2950.59
2586.38	2943.24
2589.85	2982.76
2593.32	2976.61
2596.79	2983.68
2600.25	2981.45
2603.72	2969.22
2607.18	2941.33
2610.64	2997.62
2614.1	3030.28
2617.56	3010.95
2621.02	3009.25
2624.47	2981.68
2627.92	3043.91
2631.38	3014.25
2634.83	3026.8
2638.28	3034.94
2641.72	3064.31
2645.17	3053.35
2648.61	3084.72
2652.06	3056.16
2655.5	3077.29
2658.94	3010.77
2662.38	3060.45
2665.82	3063.68
2669.25	3114.51
2672.69	3104.52
2676.12	3046.26
2679.55	3034.68
2682.98	3132.16
2686.41	3062.53
2689.84	3087.21
2693.26	3029
2696.69	3078.51
2700.11	3121.04
2703.53	3066.98
2706.95	3036.76
2710.37	3091.08
2713.79	3096.73
2717.2	3067.63
2720.62	3124.76
2724.03	3075.82
2727.44	3124.31
2730.85	3120.31
2734.26	3100.34
2737.66	3146.94
2741.07	3094.51
2744.47	3130.58
2747.87	3137.6
2751.28	3112.56
2754.67	3136.71
2758.07	3145.31
2761.47	3150.15
2764.86	3098.96
2768.26	3156.41
2771.65	3106.24
2775.04	3175.2
2778.43	3145.67
2781.82	3073.51
2785.2	3180.01
2788.59	3116.18
2791.97	3209.98
2795.35	3166.89
2798.73	3161.6
2802.11	3156.34
2805.49	3146.39
2808.87	3198.04
2812.24	3179.33
2815.62	3183.69
2818.99	3167.96
2822.36	3162.12
2825.73	3167.68
2829.1	3106.48
2832.46	3200.57
2835.83	3177.78
2839.19	3154.66
2842.55	3128.46
2845.91	3132.09
2849.27	3154
2852.63	3172.43
2855.99	3140.76
2859.34	3131.08
2862.69	3195.5
2866.05	3214.28
2869.4	3236.6
2872.75	3206.2
2876.09	3179.4
2879.44	3182.64
2882.78	3240.32
2886.13	3191.2
2889.47	3197.02
2892.81	3215.12
2896.15	3218.62
2899.49	3224.44
2902.82	3247.74
2906.16	3242.43
2909.49	3228.23
2912.82	3199.83
2916.16	3231.37
2919.49	3323.18
2922.81	3350.56
2926.14	3323.37
2929.46	3354.6
2932.79	3476.56
2936.11	3397.44
2939.43	3423.05
2942.75	3422.29
2946.07	3398.23
2949.39	3318.62
2952.7	3294.43
2956.02	3359.06
2959.33	3347.22
2962.64	3328.71
2965.95	3303.48
2969.26	3302.1
2972.57	3343.27
2975.87	3344.48
2979.17	3335.58
2982.48	3344.69
2985.78	3267.68
2989.08	3301.55
2992.38	3269.81
2995.68	3221.37
2998.97	3209.61
3002.27	3231.53
3005.56	3157.79
3008.85	3224.43
3012.14	3143.4
3015.43	3177.19
3018.72	3172.28
3022	3222.07
3025.29	3178.52
3028.57	3174.58
3031.85	3231.93
3035.14	3132.2
3038.41	3157.28
3041.69	3138.86
3044.97	3149.91
3048.24	3175.05
3051.52	3173.85
3054.79	3143.18
3058.06	3137.72
3061.33	3107.76
3064.6	3136.91
3067.87	3129.57
3071.13	3180.46
3074.4	3154.29
3077.66	3167.01
3080.92	3155.89
3084.18	3104.59
3087.44	3187.69
3090.7	3137.62
3093.95	3169.88
3097.21	3140.76
3100.46	3097.4
3103.71	3146.31
3106.96	3191.62
3110.21	3186.51
3113.46	3144.18
3116.71	3190.54
3119.95	3158.84
3123.2	3169.01
3126.44	3139.08
3129.68	3161.56
3132.92	3158.27
3136.16	3204.39
3139.4	3188.46
3142.63	3213.52
3145.87	3173.9
3149.1	3193.53
3152.33	3255.98
3155.56	3241.22
3158.79	3226.39
3162.02	3248.78
3165.25	3278.58
3168.47	3189.78
3171.69	3253.53
3174.92	3271.2
3178.14	3262.04
3181.36	3255.83
3184.58	3234.07
3187.79	3298.91
3191.01	3244.55
3194.22	3260.69
3197.43	3273.87
3200.65	3291.9
3203.86	3295.75
3207.07	3272.15
3210.27	3305.84
3213.48	3323.6
3216.69	3295.75
3219.89	3296.51
3223.09	3254.76
3226.29	3309.21
3229.49	3264.03
3232.69	3318.54
3235.89	3305.1
3239.08	3314.82
3242.28	3329.5
3245.47	3340.4
3248.66	3359.21
3251.85	3353.4
3255.04	3279.85
3258.23	3328.06
3261.42	3326.18
3264.6	3273.17
3267.79	3288.57
3270.97	3296.06
3274.15	3333.16
3277.33	3297.14
3280.51	3330.1
3283.68	3266.63
3286.86	3304.99
3290.04	3283.45
3293.21	3304.78
3296.38	3321.18
3299.55	3391.75
3302.72	3292.28
3305.89	3348.49
3309.06	3369.89
3312.22	3400.46
3315.39	3272.41
3318.55	3330.27
3321.71	3370.98
3324.87	3351.06
3328.03	3364.32
3331.19	3351.3
3334.34	3383.89
3337.5	3349.75
3340.65	3438.25
3343.81	3385.92
3346.96	3415.67
3350.11	3459.62
3353.25	3522.76
3356.4	3571
3359.55	3649.86
3362.69	3801.49
3365.84	3944.91
3368.98	4264.95
3372.12	4228.94
3375.26	4088.31
3378.4	3799.49
3381.53	3728.52
3384.67	3628.44
3387.8	3617.27
3390.94	3550.4
3394.07	3551.19
3397.2	3531
3400.33	3678.35
3403.46	3622.19
3406.58	3701.15
3409.71	3914.6
3412.83	4260.9
3415.96	5327.01
3419.08	7787.97
3422.2	8594.62
3425.32	6340.51
3428.44	4653.48
3431.55	3912.58
3434.67	3753.92
3437.78	3653.86
3440.89	3607.47
3444	3551.72
3447.12	3518.83
3450.22	3470.14
3453.33	3538.62
3456.44	3479.89
3459.54	3455.36
3462.65	3468.75
3465.75	3535.93
3468.85	3493.76
3471.95	3543.66
3475.05	3540.79
3478.15	3594.88
3481.24	3613.03
3484.34	3789.11
3487.43	3896.39
3490.53	4075.64
3493.62	4426.66
3496.71	4849.63
3499.79	5375.55
3502.88	5695.42
3505.97	5546.24
3509.05	5079.96
3512.14	4516.95
3515.22	4113.62
3518.3	3873.26
3521.38	3657.21
3524.46	3568.7
3527.54	3444.94
3530.61	3407.47
3533.69	3252.95
3536.76	3264
3539.83	3255.63
3542.9	3248.56
3545.97	3191.52
3549.04	3188.76
3552.11	3104.05
3555.18	3145.58
3558.24	3143.01
3561.3	3136.87
3564.37	3086.88
3567.43	3095.77
3570.49	3045.35
3573.55	3085.6
3576.61	2996.74
3579.66	3076.46
3582.72	3003.18
3585.77	3005.7
3588.82	2994.66
3591.87	2991.05
3594.92	2985.31
3597.97	3006.04
3601.02	2983.91
3604.07	2965.32
3607.11	2910.72
3610.16	2908.06
3613.2	2914.71
3616.24	2903.46
3619.28	2861.23
3622.32	2887.97
3625.36	2910.16
3628.39	2822.97
3631.43	2891.04
3634.46	2871.98
3637.5	2841.2
3640.53	2857.79
3643.56	2859.09
3646.59	2831.73
3649.62	2818.84
3652.64	2845.18
3655.67	2853.67
3658.69	2811.14
3661.72	2822.79
3664.74	2767.27
3667.76	2788.18
3670.78	2832.04
3673.79	2719.44
3676.81	2738.14
3679.83	2683.09
3682.84	2751.81
3685.86	2739.32
3688.87	2713.65
3691.88	2691.82
3694.89	2717.83
3697.9	2752.73
3700.91	2711.93
3703.91	2685.3
3706.92	2686.91
3709.92	2724.42
3712.92	2725.47
3715.92	2726.6
3718.92	2707.55
3721.92	2639.66
3724.92	2701.97
3727.92	2690.76
3730.91	2745.02
3733.91	2714.21
3736.9	2701.26
3739.89	2708.94
3742.88	2657.38
3745.87	2725.41
3748.86	2647.74
3751.85	2682.12
3754.83	2674.76
3757.82	2692.99
3760.8	2692.98
3763.78	2682.53
3766.76	2694.97
3769.74	2647.1
3772.72	2694.04
3775.7	2700.47
3778.67	2721.25
3781.65	2671.25
3784.62	2657.28
3787.6	2719.92
3790.57	2722.51
3793.54	2685.75
3796.51	2697.28
3799.47	2608.13
3802.44	2676.85
3805.41	2644.61
3808.37	2678.66
3811.33	2690.14
3814.3	2675.2
3817.26	2692.54
3820.22	2657.88
3823.18	2601.58
3826.13	2638.18
3829.09	2681.42
3832.04	2715.43
3835	2665.15
3837.95	2655.71
3840.9	2633.86
3843.85	2669.12
3846.8	2666.42
3849.75	2675.32
3852.69	2659.51
3855.64	2633.19
3858.58	2656.59
3861.53	2637.8
3864.47	2633.33
3867.41	2616.21
3870.35	2621
3873.29	2624.76
3876.22	2610.02
3879.16	2676.64
3882.1	2619.99
3885.03	2625.54
3887.96	2634.8
3890.89	2598.78
3893.82	2636.51
3896.75	2620.03
3899.68	2656.38
3902.61	2653.87
3905.53	2645.85
3908.46	2654.05
3911.38	2648.55
3914.3	2615.83
3917.23	2638.35
3920.15	2609.64
3923.06	2611.31
3925.98	2626.14
3928.9	2636.85
3931.81	2646.11
3934.73	2610.92
3937.64	2638.6
3940.55	2626.86
3943.46	2564.42
3946.37	2618.07
3949.28	2625.05
3952.19	2594.77
3955.09	2648.06
3958	2572.16
3960.9	2573.98
3963.8	2611.42
3966.71	2590.52
3969.61	2561.06
3972.51	2609.34
3975.4	2576.83
3978.3	2631.54
3981.2	2621.83
3984.09	2632.16
3986.99	2619.41
3989.88	2592.73
3992.77	2626.13
3995.66	2567.18
3998.55	2576.67
4001.43	2591.98
4004.32	2570.82
4007.21	2641.27
4010.09	2619.17
4012.98	2616.37
4015.86	2574.97
4018.74	2599.17
4021.62	2608.9
4024.5	2583.91
4027.37	2637.2
4030.25	2553.3
4033.13	2584.45
4036	2561.56
4038.87	2555.14
4041.75	2608.36
4044.62	2610.21
4047.49	2580.23
4050.35	2624.08
4053.22	2571.14
4056.09	2563.84
4058.95	2568.04
4061.82	2593.61
4064.68	2586.15
4067.54	2576.7
4070.4	2621.71
4073.26	2588.84
4076.12	2603.62
4078.98	2544.33
4081.83	2554.22
4084.69	2551.38
4087.54	2490.89
4090.4	2520.28
4093.25	2510.61
4096.1	2590.76
4098.95	2582.12
4101.8	2539.12
4104.64	2567.3
4107.49	2523.91
4110.33	2590.02
4113.18	2541.29
4116.02	2539.24
4118.86	2464.61
4121.7	2573.23
4124.54	2575.36
4127.38	2544.61
4130.22	2531.08
4133.05	2491.62
4135.89	2494.86
4138.72	2521.47
4141.56	2491.35
4144.39	2571.37
4147.22	2530.24
4150.05	2468.29
4152.88	2493.61
4155.7	2590.34
4158.53	2543.2
4161.36	2495.93
4164.18	2493.66
4167	2495.34
4169.82	2516.74
4172.65	2514.76
4175.46	2516.72
4178.28	2499.23
4181.1	2480.93
4183.92	2461.74
4186.73	2477.88
4189.55	2507.96
4192.36	2532.55
4195.17	2466.36
4197.98	2542.35
4200.79	2462.45
4203.6	2510.06
4206.41	2466.36
4209.21	2491.37
4212.02	2486.85
4214.83	2479.24
4217.63	2465.41
4220.43	2460.04
4223.23	2469.2
4226.03	2435.01
4228.83	2447.53
4231.63	2454.31
4234.42	2447.47
4237.22	2430.76
4240.01	2450.85
4242.81	2444.23
4245.6	2455.52
4248.39	2455.63
4251.18	2503.55
4253.97	2472.41
4256.76	2454.08
4259.55	2447.81
4262.33	2402.49
4265.12	2416.49
4267.9	2440.65
4270.68	2422.46
4273.47	2409.97
4276.25	2386.91
4279.03	2429.25
4281.8	2408.77
4284.58	2406.16
4287.36	2378.98
4290.13	2417.41
4292.91	2423.63
4295.68	2407.85
4298.45	2393
4301.22	2385.09
4303.99	2428.95
4306.76	2459.71
4309.53	2406.35
4312.3	2404.66
4315.06	2450.44
4317.83	2451.29
4320.59	2360.33
4323.35	2351.65
4326.11	2293.07
4328.87	2349.47
4331.63	2304.97
4334.39	2381.67
4337.15	2362.73
4339.9	2335.88
4342.66	2389.67
4345.41	2361.14
4348.17	2405.14
4350.92	2365.82
4353.67	2353.17
4356.42	2304.53
4359.17	2372.43
4361.91	2322.73
4364.66	2322.15
4367.41	2310.31
4370.15	2345.52
4372.89	2304.56
4375.63	2336.35
4378.38	2292.03
4381.12	2310.43
4383.86	2332.33
4386.59	2305.65
4389.33	2327.96
4392.07	2294.78
4394.8	2248.88
4397.53	2303.29
4400.27	2318.4
4403	2322.08
4405.73	2246.97
4408.46	2302.58
4411.19	2292.39
4413.92	2255.94
4416.64	2295.97
4419.37	2267.04
4422.09	2270.79
4424.82	2269.35
4427.54	2291.96
4430.26	2319.79
4432.98	2223
4435.7	2287.28
4438.42	2289.61
4441.13	2235.26
4443.85	2279.42
4446.57	2209.14
4449.28	2222.7
4451.99	2236.15
4454.71	2231.62
4457.42	2238.49
4460.13	2252.88
4462.83	2246.34
4465.54	2231.42
4468.25	2200.82
4470.95	2245.13
4473.66	2191.69
4476.36	2204.8
4479.07	2228.64
4481.77	2222.98
4484.47	2198.17
4487.17	2220.87
4489.87	2190.3
4492.56	2199.09
4495.26	2160.84
4497.96	2205.21
4500.65	2150.65
4503.34	2173.71
4506.04	2203.26
4508.73	2132.03
4511.42	2162.68
4514.11	2211.5
4516.8	2138.17
4519.48	2200.09
4522.17	2154.7
4524.85	2192.16
4527.54	2162.67
4530.22	2092.66
4532.9	2132.52
4535.58	2082.77
4538.27	2132.53
4540.94	2121.34
4543.62	2158.4
4546.3	2128.06
4548.98	2042.01
4551.65	2139.72
4554.33	2080.94
4557	2085.15
4559.67	2106.97
4562.34	2055.86
4565.01	2091.2
4567.68	2050.12
4570.35	2049.88
4573.02	2091.09
4575.68	2021.72
4578.35	2031.06
4581.01	2094.16
4583.67	2043.38
4586.34	1994.65
4589	2097.24
4591.66	2066.65
4594.31	2043.25
4596.97	2060.77
4599.63	2056.94
4602.29	2022.67
4604.94	1997.09
4607.59	2045.03
4610.25	2010.65
4612.9	2021.2
4615.55	2053.81
4618.2	2009.62
4620.85	2009.39
4623.5	1997.97
4626.14	1986.36
4628.79	1978.1
4631.43	1958.45
4634.08	2024.82
4636.72	2017.16
4639.36	2001.57
4642	1999.69
4644.64	2011.67
4647.28	1977.49
4649.92	1969.38
4652.56	2028
4655.19	1970.83
4657.83	2029.36
4660.46	1982.44
4663.1	1935.45
4665.73	1954.64
4668.36	1993.18
4670.99	1912.97
4673.62	1905.49
4676.24	1964.18
4678.87	1962.25
4681.5	1926.59
4684.12	1956.13
4686.75	1912.52
4689.37	1948.97
4691.99	1959.33
4694.61	1967.38
4697.23	1912.28
4699.85	1930.55
4702.47	1911.31
4705.09	1914.62
4707.7	1889.56
4710.32	1911.97
4712.93	1906.07
4715.55	1904.52
4718.16	1879.24
4720.77	1910.31
4723.38	1931.5
4725.99	1906.38
4728.6	1913.03
4731.21	1881.09
4733.81	1899.1
4736.42	1873.73
4739.02	1885.91
4741.63	1895.56
4744.23	1856.32
4746.83	1849.62
4749.43	1865.76
4752.03	1888.74
4754.63	1876.33
4757.23	1834.48
4759.82	1853.17
4762.42	1834.29
4765.01	1863.58
4767.61	1830.76
4770.2	1840.65
4772.79	1882.54
4775.38	1866.27
4777.97	1849.95
4780.56	1854.19
4783.15	1848.18
4785.74	1833.01
4788.32	1880.8
4790.91	1842.9
4793.49	1857.64
4796.07	1854.28
4798.66	1844.17
4801.24	1822.68
4803.82	1859.96
4806.4	1807.88
4808.98	1806.24
4811.55	1850.85
4814.13	1819.45
4816.71	1790.53
4819.28	1777.69
4821.85	1810.05
4824.43	1762.47
4827	1792.45
4829.57	1782.12
4832.14	1814.82
4834.71	1789.54
4837.28	1739.85
4839.84	1783.68
4842.41	1707.76
4844.97	1774.57
4847.54	1742.66
4850.1	1741.29
4852.66	1725.93
4855.22	1761.43
4857.78	1732.21
4860.34	1753.31
4862.9	1750.09
4865.46	1729.98
4868.01	1708.33
4870.57	1760.81
4873.12	1701.61
4875.68	1698.11
4878.23	1743.19
4880.78	1699.1
4883.33	1732.18
4885.88	1666.61
4888.43	1697.41
4890.98	1710.3
4893.53	1699.34
4896.07	1706.16
4898.62	1711.8
4901.16	1673.21
4903.7	1734.93
4906.25	1655.54
4908.79	1690.61
4911.33	1700.35
4913.87	1711.15
4916.41	1665.86
4918.94	1710.25
4921.48	1663.83
4924.02	1670.07
4926.55	1657.1
4929.08	1635.94
4931.62	1682.14
4934.15	1669.74
4936.68	1664.4
4939.21	1676.56
4941.74	1651.65
4944.27	1660.76
4946.79	1661.52
4949.32	1652.74
4951.85	1660.69
4954.37	1647.13
4956.9	1612.17
4959.42	1649.4
4961.94	1659.37
4964.46	1611.96
4966.98	1641.4
4969.5	1530.66
4972.02	1639.49
4974.53	1638.48
4977.05	1587.9
4979.57	1629.3
4982.08	1611.43
4984.59	1631.18
4987.1	1570.85
4989.62	1606.41
4992.13	1637.11
4994.64	1605.91
4997.15	1565.07
4999.65	1555.89