File: Data/3-Raman/raw/bu19(2)w-a-ff1-fi06-v_150 (500nm)_532nm_edge_100%_x100_vis_lwd_h50um_30sx2_01.txt
#Acq. time (s)=	30
#Accumulations=	2
#Range (cm-¹)=	99...4000
#Windows=	1
#Auto scanning=	Off
#Autofocus=	Off
#Macrospot=	Off
#AutoExposure=	Off
#Spike filter=	Multiple accum.
#Delay time (s)=	2
#Binning=	1
#Readout mode=	Signal
#DeNoise=	Off
#ICS correction=	On
#Dark correction=	Off
#Inst. Process=	Off
#Detector Gain=	Best Dynamic
#Detector ADC=	50 kHz HS
#Detector temperature (°C)=	-60.28
#Instrument=	LabRAM HR Evol
#Detector=	SIN-EM FIVIS
#Objective=	x100_VIS_LWD
#Grating=	150 (500nm)
#ND Filter=	100%
#Laser=	532nm_Edge
#Hole=	49.98
#Temperature=	0
#Range=	Visible
#StageXY=	75x50mm Scan+
#StageZ=	Z motor
#X (µm)=	0
#Y (µm)=	0
#Z (µm)=	-16.9
#Full time(mm:ss)=	1:04
#Project=	21_11_26
#Sample=	BU19(2)w
#Site=
#Title=	BU19(2)w-A-FF1-FI06-V_150 (500nm)_532nm_Edge_100%_x100_VIS_LWD_H50um_30sX2
#Remark=
#Date=	26.11.2021 13:44
#Acquired=	26.11.2021 13:44:14
102.91	4631.27
107.534	6284.1
112.156	6463.96
116.775	5164.89
121.392	3812.93
126.005	3506.72
130.617	4262.43
135.227	6257.3
139.835	10415.8
144.439	15184.3
149.042	15401.3
153.643	10734
158.242	6675.16
162.839	4278.99
167.431	3038.54
172.023	2299.1
176.613	1927.69
181.198	1631.34
185.783	1512.57
190.366	1415.9
194.947	1521.11
199.524	1918.7
204.1	3437.94
208.674	5431.41
213.243	4007.4
217.813	2183.68
222.38	1827.68
226.945	2498.68
231.506	4494.89
236.066	4919.11
240.625	2954.12
245.179	1606.16
249.732	1169.61
254.284	994.366
258.831	925.297
263.378	851.503
267.923	867.735
272.464	890.021
277.004	1103.88
281.54	1265.62
286.076	1040.16
290.61	831.11
295.139	782.366
299.669	807.748
304.196	822.269
308.718	908.418
313.241	941.648
317.759	1068.35
322.278	1321.4
326.794	1887.51
331.305	2582.53
335.817	2702.66
340.324	2330.63
344.832	2404.49
349.334	2966.48
353.837	2889.79
358.338	2101.26
362.834	1641.82
367.33	1492.17
371.822	1517.71
376.314	1754.24
380.802	2206.17
385.289	3550.14
389.772	5734.04
394.255	6637.85
398.734	5878.32
403.213	4886.73
407.688	3943.27
412.162	3412.76
416.632	3289.93
421.102	3628.57
425.568	4077.91
430.033	4283.86
434.495	4189.05
438.956	4083.34
443.413	4144.75
447.87	4541.32
452.323	4581.95
456.776	4001.26
461.224	2905.47
465.673	2159.09
470.117	1795.7
474.561	1685.1
479.001	1728.2
483.438	2032.08
487.876	2456.2
492.309	3299
496.742	4565.96
501.172	6339.76
505.601	8163.4
510.025	8980.94
514.448	8707.75
518.871	7399.2
523.289	6292.29
527.707	5422.51
532.121	5160.39
536.533	5061.08
540.945	5242.12
545.353	5410.4
549.758	5311.19
554.164	4977.81
558.565	4381.31
562.965	3778.07
567.364	3172.52
571.759	2627.42
576.151	2304.71
580.544	2189.44
584.933	2254.54
589.319	2480.3
593.706	2920.92
598.088	3464.75
602.468	4298.98
606.848	5469.92
611.224	8465.39
615.598	14095.9
619.972	17960.9
624.341	14591.9
628.709	8774.51
633.074	5317.21
637.44	3497.11
641.801	2628.8
646.16	2046.08
650.517	1684.4
654.874	1437.55
659.227	1230.72
663.578	1105.27
667.927	1002.7
672.275	919.702
676.62	892.101
680.962	854.52
685.302	867.395
689.643	931.439
693.979	1112.61
698.313	1318.52
702.645	1444.02
706.975	1383.41
711.305	1222.61
715.631	1080.84
719.955	985.889
724.276	944.247
728.596	917.794
732.913	804.011
737.231	779.046
741.544	720.913
745.856	718.486
750.165	708.845
754.472	716.306
758.778	728.662
763.081	730.86
767.384	737.078
771.683	738.905
775.98	727.405
780.275	780.976
784.568	759.357
788.859	804.705
793.147	841.35
797.434	878.465
801.719	891.694
806.004	960.57
810.284	953.903
814.563	1039.77
818.839	1102.74
823.114	1274.65
827.386	1545.03
831.657	1819.18
835.925	2179.67
840.192	2590.07
844.456	2783.21
848.719	2655.43
852.979	2377.23
857.237	2086.1
861.493	1832.67
865.748	1716.84
870	1702.92
874.25	1911.62
878.499	2036.98
882.745	1921.72
886.989	1575.63
891.231	1283.69
895.471	1125.43
899.71	1058.78
903.946	982.581
908.18	928.859
912.412	915.252
916.642	891.438
920.87	905.283
925.096	888.561
929.321	907.951
933.543	884.355
937.763	908.99
941.981	896.884
946.197	908.217
950.412	890.658
954.622	911.763
958.832	908.43
963.04	931.803
967.246	930.798
971.451	961.745
975.653	958.913
979.853	999.645
984.052	1039.47
988.248	1169.23
992.442	1291.58
996.633	1416.99
1000.82	1492.62
1005.01	1472.18
1009.2	1352.03
1013.38	1306.07
1017.57	1253.25
1021.75	1285.6
1025.92	1275.04
1030.1	1345.14
1034.27	1515.28
1038.45	1796.88
1042.62	2150.27
1046.78	2352.46
1050.95	2317.36
1055.12	2233.07
1059.28	2258.47
1063.44	2425.43
1067.6	2706.43
1071.75	3140.54
1075.91	3754.52
1080.06	4882.15
1084.21	6800.02
1088.36	9672.64
1092.51	12384.1
1096.65	12530.2
1100.8	9563.79
1104.94	6273.57
1109.08	4034.64
1113.21	2978.21
1117.35	2506.97
1121.48	2330.19
1125.61	2396.33
1129.74	2546.34
1133.87	3047.83
1137.99	3771.78
1142.12	4610.77
1146.24	4890.56
1150.36	4351.51
1154.48	3418.73
1158.59	2664.93
1162.71	2163.9
1166.82	1801.42
1170.93	1504.67
1175.04	1336.59
1179.14	1183.98
1183.25	1099.52
1187.35	1049.84
1191.45	978.166
1195.55	935.135
1199.65	868.502
1203.74	896.689
1207.83	881.992
1211.92	864.367
1216.01	885.264
1220.1	848.712
1224.19	883.815
1228.27	869.818
1232.35	863.208
1236.43	891.273
1240.51	913.821
1244.58	1036
1248.66	1149.46
1252.73	1006.94
1256.8	984.411
1260.87	1008
1264.93	2618.22
1269	4501.08
1273.06	1950.1
1277.12	984.929
1281.18	916.683
1285.23	849.152
1289.29	837.706
1293.34	813.052
1297.39	806.379
1301.44	801.638
1305.49	819.922
1309.53	786.745
1313.58	814.962
1317.62	812.644
1321.66	780.949
1325.7	839.555
1329.73	794.416
1333.77	797.474
1337.8	793.243
1341.83	809.896
1345.86	857.359
1349.88	868.741
1353.91	962.689
1357.93	933.177
1361.95	949.301
1365.97	1283.26
1369.99	5739.53
1374	5502.27
1378.02	1781.12
1382.03	933.318
1386.04	907.272
1390.05	1035.96
1394.05	1250.53
1398.06	951.704
1402.06	805.261
1406.06	776.931
1410.06	783.162
1414.05	731.287
1418.05	736.6
1422.04	737.959
1426.03	741.196
1430.02	695.673
1434.01	706.499
1438	713.361
1441.98	708.383
1445.96	691.454
1449.94	677.45
1453.92	690.959
1457.9	700.441
1461.87	692.053
1465.85	670.664
1469.82	661.074
1473.78	658.472
1477.75	676.386
1481.72	674.575
1485.68	661.958
1489.65	672.778
1493.61	678.741
1497.56	685.678
1501.52	695.591
1505.47	659.893
1509.43	669.148
1513.38	698.837
1517.33	659.607
1521.27	668.035
1525.22	670.68
1529.16	641.38
1533.11	655.799
1537.05	694.461
1540.98	695.338
1544.92	666.178
1548.86	663.19
1552.79	675.7
1556.72	661.007
1560.65	696.564
1564.58	690.403
1568.5	686.112
1572.43	686.608
1576.35	734.409
1580.27	669.21
1584.19	700.514
1588.1	672.946
1592.02	674.285
1595.93	714.078
1599.84	684.619
1603.75	670.628
1607.66	713.37
1611.57	697.585
1615.47	663.661
1619.37	725.659
1623.27	706.17
1627.17	700.208
1631.07	695.299
1634.97	692.53
1638.86	670.581
1642.75	680.399
1646.64	705.701
1650.53	701.381
1654.42	699.968
1658.3	688.893
1662.18	719.085
1666.07	687.659
1669.94	709.971
1673.82	694.574
1677.7	725.276
1681.57	726.747
1685.44	703.073
1689.31	688.97
1693.18	726.474
1697.05	704.475
1700.92	733.994
1704.78	749.914
1708.64	728.501
1712.5	745.958
1716.36	750.078
1720.21	764.615
1724.07	747.967
1727.92	755.81
1731.77	785.108
1735.62	785.271
1739.47	776.924
1743.32	788.116
1747.16	788.126
1751.01	814.641
1754.85	807.028
1758.69	789.692
1762.52	829.358
1766.36	798.851
1770.19	780.696
1774.02	760.106
1777.85	761.837
1781.68	747.985
1785.51	748.219
1789.33	752.278
1793.16	753.576
1796.98	747.39
1800.8	749.606
1804.62	751.346
1808.43	714.409
1812.25	745.194
1816.06	757.025
1819.87	769.479
1823.68	748.708
1827.49	731.576
1831.3	739.712
1835.1	730.684
1838.9	741.318
1842.71	762.157
1846.51	767.741
1850.3	740.575
1854.1	779.63
1857.89	760.392
1861.69	772.7
1865.48	783.934
1869.27	755.274
1873.05	782.407
1876.84	725.444
1880.62	748.126
1884.4	748.009
1888.19	771.859
1891.96	782.752
1895.74	766.982
1899.52	765.938
1903.29	765.228
1907.06	759.144
1910.83	753.13
1914.6	767.672
1918.37	769.375
1922.13	766.953
1925.9	770.157
1929.66	763.299
1933.42	774.152
1937.18	793.414
1940.94	792.184
1944.69	784.379
1948.44	796.223
1952.2	798.087
1955.95	804.324
1959.69	827.993
1963.44	798.791
1967.19	866.273
1970.93	854.595
1974.67	889.505
1978.41	917.607
1982.15	911.803
1985.89	951.637
1989.62	966.053
1993.35	959.776
1997.09	895.689
2000.82	898.478
2004.55	942.033
2008.27	927.1
2012	887.119
2015.72	909.886
2019.44	877.925
2023.16	863.951
2026.88	873.433
2030.6	859.143
2034.31	837.951
2038.03	856.422
2041.74	846.436
2045.45	807.083
2049.16	829.091
2052.86	809.141
2056.57	823.125
2060.27	818.295
2063.98	793.767
2067.67	812.585
2071.37	809.421
2075.07	808.102
2078.77	841.978
2082.46	808.406
2086.15	799.663
2089.84	811.312
2093.53	778.931
2097.22	821.264
2100.9	815.139
2104.59	809.661
2108.27	811.479
2111.95	785.273
2115.63	786.944
2119.31	825.684
2122.98	812.049
2126.66	821.452
2130.33	821.439
2134	815.794
2137.67	808.26
2141.34	801.531
2145	829.709
2148.67	822.784
2152.33	825.049
2155.99	840.173
2159.65	826.906
2163.31	815.611
2166.96	808.126
2170.62	798.981
2174.27	815.69
2177.92	814.354
2181.57	799.478
2185.22	820.965
2188.87	814.464
2192.51	805.552
2196.15	826.095
2199.8	785.812
2203.44	828.534
2207.07	808.479
2210.71	815.94
2214.35	811.634
2217.98	808.274
2221.61	810.434
2225.24	805.286
2228.87	838.755
2232.5	799.458
2236.12	801.693
2239.75	802.058
2243.37	799.622
2246.99	820.359
2250.61	798.419
2254.23	833.322
2257.85	825.491
2261.46	812.938
2265.07	809.607
2268.68	799.78
2272.29	820.18
2275.9	805.588
2279.51	796.381
2283.11	819.655
2286.72	807.056
2290.32	836.015
2293.92	821.393
2297.52	820.973
2301.11	828.159
2304.71	851.318
2308.3	851.567
2311.9	1042.22
2315.49	1324.69
2319.08	993.7
2322.66	858.774
2326.25	829.51
2329.84	841.817
2333.42	812.444
2337	855.641
2340.58	842.109
2344.16	849.21
2347.73	837.409
2351.31	825.589
2354.88	838.075
2358.45	849.528
2362.03	832.011
2365.59	848.005
2369.16	826.89
2372.73	843.093
2376.29	831.444
2379.85	858.61
2383.41	853.55
2386.97	844.91
2390.53	830.006
2394.09	829.989
2397.64	858.644
2401.2	849.062
2404.75	857.365
2408.3	828.197
2411.85	872.733
2415.39	839.515
2418.94	834.924
2422.48	837.814
2426.03	824.324
2429.57	841.463
2433.11	835.709
2436.64	857.924
2440.18	848.734
2443.72	809.766
2447.25	817.305
2450.78	826.924
2454.31	845.181
2457.84	872.38
2461.37	846.168
2464.89	833.01
2468.42	802.151
2471.94	848.377
2475.46	799.798
2478.98	849.227
2482.5	834.64
2486.01	862.138
2489.53	857.064
2493.04	863.74
2496.55	858.661
2500.06	854.832
2503.57	864.759
2507.08	851.163
2510.58	876.571
2514.09	831.241
2517.59	863.361
2521.09	870.49
2524.59	849.224
2528.09	885.273
2531.59	862.356
2535.08	836.832
2538.58	874.333
2542.07	872.343
2545.56	832.012
2549.05	849.262
2552.54	861.032
2556.02	840.672
2559.51	858.668
2562.99	863.737
2566.47	833.861
2569.95	862.851
2573.43	833.32
2576.91	826.284
2580.38	845.688
2583.85	836.025
2587.33	849.944
2590.8	848.546
2594.27	881.874
2597.74	869.462
2601.2	862.025
2604.67	851.6
2608.13	869.407
2611.59	866.366
2615.06	893.445
2618.51	892.061
2621.97	855.705
2625.43	858.57
2628.88	873.689
2632.33	872.328
2635.79	860.197
2639.24	884.255
2642.69	884.161
2646.13	865.727
2649.58	927.478
2653.02	903.995
2656.47	889.872
2659.91	842.399
2663.35	869.856
2666.79	904.66
2670.22	892.148
2673.66	875.885
2677.09	872.036
2680.52	876.761
2683.95	871.38
2687.39	883.122
2690.81	897.273
2694.24	895.884
2697.66	912.93
2701.09	890.147
2704.51	882.299
2707.93	895.878
2711.35	866.373
2714.77	900.303
2718.18	910.242
2721.6	895.21
2725.01	902.657
2728.42	888.71
2731.84	890.68
2735.24	884.178
2738.65	866.415
2742.06	896.419
2745.46	901.888
2748.86	892.203
2752.27	883.454
2755.67	916.018
2759.07	924.981
2762.46	898.175
2765.86	926.698
2769.25	930.587
2772.65	909.819
2776.04	925.721
2779.43	897.185
2782.82	910.911
2786.2	892.561
2789.59	921.223
2792.98	931.018
2796.36	907.895
2799.74	935.492
2803.12	913.182
2806.5	917.161
2809.88	909.873
2813.25	891.316
2816.63	912.004
2820	933.57
2823.37	902.979
2826.74	910.796
2830.11	941.046
2833.48	936.917
2836.84	921.787
2840.21	908.683
2843.57	925.568
2846.93	919.385
2850.29	923.787
2853.65	932.146
2857.01	926.392
2860.36	929.172
2863.72	954.54
2867.07	945.322
2870.42	924.827
2873.77	940.864
2877.12	957.842
2880.47	935.291
2883.81	972.028
2887.16	933.299
2890.5	951.12
2893.84	952.853
2897.18	932.613
2900.52	947.212
2903.86	943.696
2907.19	949.524
2910.53	965.679
2913.86	953.375
2917.19	971.283
2920.52	954.983
2923.85	969.849
2927.18	984.615
2930.51	973.713
2933.83	967.43
2937.15	981.769
2940.48	990.428
2943.8	1040.53
2947.11	988.914
2950.43	1002.32
2953.75	965.84
2957.06	1020.56
2960.38	914.851
2963.69	962.28
2967	983.464
2970.31	948.662
2973.62	977.812
2976.92	971.36
2980.23	989.461
2983.53	996.193
2986.84	984.215
2990.14	989.19
2993.44	995.141
2996.73	984.238
3000.03	995.937
3003.33	1001.99
3006.62	986.416
3009.91	1004.79
3013.2	974.265
3016.49	1014.4
3019.78	1006.47
3023.07	996.622
3026.35	986.772
3029.64	1006.2
3032.92	989.725
3036.2	978.855
3039.48	960.381
3042.76	1002.45
3046.04	1014.29
3049.32	1018.57
3052.59	1027.59
3055.86	1012.95
3059.14	1037.14
3062.41	974.687
3065.68	1007.24
3068.94	1002.67
3072.21	1012.12
3075.48	1031.11
3078.74	1005.61
3082	1019.61
3085.26	992.75
3088.52	1038.89
3091.78	1010.34
3095.04	990.348
3098.29	1015.66
3101.55	1022.61
3104.8	1020.81
3108.05	1048.02
3111.3	1011.34
3114.55	1005.73
3117.8	997.351
3121.04	1003.28
3124.29	1025.4
3127.53	1016.08
3130.77	1021.96
3134.02	1026.92
3137.25	1019.45
3140.49	1044.33
3143.73	1022.49
3146.96	1029.26
3150.2	1034.19
3153.43	1049.63
3156.66	1047.86
3159.89	1045.17
3163.12	1041.48
3166.35	1076.92
3169.57	1025.43
3172.8	1059.75
3176.02	1055.84
3179.24	1069.03
3182.46	1060.25
3185.68	1091.56
3188.9	1068.38
3192.12	1082.36
3195.33	1087.75
3198.55	1081.69
3201.76	1119.41
3204.97	1096.23
3208.18	1113.08
3211.39	1104.28
3214.6	1125.05
3217.8	1123.06
3221.01	1163.88
3224.21	1156.22
3227.41	1120.14
3230.61	1144.97
3233.81	1148.01
3237.01	1181.42
3240.21	1207.49
3243.4	1172.7
3246.59	1197.96
3249.79	1210.86
3252.98	1182.88
3256.17	1222.65
3259.36	1226.16
3262.54	1226.63
3265.73	1246.99
3268.92	1246.16
3272.1	1271.95
3275.28	1313.91
3278.46	1357.75
3281.64	1363.09
3284.82	1342.42
3288	1371.4
3291.17	1389.75
3294.35	1417.72
3297.52	1399.89
3300.69	1446.85
3303.86	1465.54
3307.03	1465.76
3310.2	1464.89
3313.36	1529.36
3316.53	1588.89
3319.69	1598
3322.85	1609.88
3326.02	1660.59
3329.18	1654.45
3332.33	1758.97
3335.49	1803.93
3338.65	1834.83
3341.8	1877.14
3344.95	1964.71
3348.11	1972.57
3351.26	1986.56
3354.41	2132.48
3357.56	2202.28
3360.7	2240.16
3363.85	2288.69
3366.99	2349.56
3370.13	2427.56
3373.28	2538.74
3376.42	2592.71
3379.56	2683.69
3382.69	2772.05
3385.83	2865.1
3388.97	3006.74
3392.1	3084.22
3395.23	3198.56
3398.36	3397.46
3401.49	3567.18
3404.62	3749.85
3407.75	3946.53
3410.88	4155.26
3414	4367.15
3417.13	4641.29
3420.25	4888.84
3423.37	5289.88
3426.49	5650.17
3429.61	5982.97
3432.73	6420.1
3435.84	6891.25
3438.96	7400.73
3442.07	8163.78
3445.18	9203.96
3448.29	10870.1
3451.4	13644.2
3454.51	17161.3
3457.62	20276.7
3460.72	20143.4
3463.83	17086.5
3466.93	13940.5
3470.03	11829.6
3473.13	10612.2
3476.23	9957.32
3479.33	9414.77
3482.43	9292.4
3485.53	9121.32
3488.62	9177.75
3491.71	9170.41
3494.81	9148.57
3497.9	9351.9
3500.99	9414.9
3504.07	9407.37
3507.16	9804.5
3510.25	9944.96
3513.33	10389.9
3516.41	10928.5
3519.5	11373.2
3522.58	12170.8
3525.66	13009
3528.73	13657.4
3531.81	14609.1
3534.89	15375
3537.96	15757.7
3541.03	15468.8
3544.11	14581.4
3547.18	13139
3550.25	11573.4
3553.32	9937.47
3556.38	8375.7
3559.45	7102.31
3562.51	6108.63
3565.58	5321.06
3568.64	4625
3571.7	4165.93
3574.76	3831.61
3577.82	3534.37
3580.87	3290.84
3583.93	3034.7
3586.98	2880.73
3590.04	2698.32
3593.09	2600.96
3596.14	2534.86
3599.19	2409.83
3602.24	2368.24
3605.29	2261.1
3608.33	2211.61
3611.38	2112.98
3614.42	2137.21
3617.46	2040.44
3620.5	2089.24
3623.54	2003.17
3626.58	2010.6
3629.62	1946.53
3632.65	1905.02
3635.69	1825.79
3638.72	1838.38
3641.76	1805.1
3644.79	1725
3647.82	1754.5
3650.84	1662.12
3653.87	1588.81
3656.9	1600.96
3659.92	1543.28
3662.95	1543.71
3665.97	1523.13
3668.99	1466
3672.01	1487.44
3675.03	1403.32
3678.05	1411.69
3681.07	1402.2
3684.08	1392.63
3687.1	1363.2
3690.11	1368.79
3693.12	1351.7
3696.13	1365.87
3699.14	1367.46
3702.15	1313.38
3705.16	1313.34
3708.16	1317.08
3711.17	1309.26
3714.17	1250.93
3717.17	1267.55
3720.17	1262.38
3723.17	1238.96
3726.17	1254.46
3729.17	1236.53
3732.16	1236.59
3735.16	1247.96
3738.15	1207.78
3741.14	1211.28
3744.13	1207.98
3747.13	1195.07
3750.11	1177.3
3753.1	1216.46
3756.09	1179.6
3759.07	1186.46
3762.06	1192.33
3765.04	1181.99
3768.02	1153.7
3771	1153.93
3773.98	1166.55
3776.96	1143.33
3779.94	1164.61
3782.91	1106.6
3785.89	1129.86
3788.86	1096.52
3791.83	1119.9
3794.8	1134.02
3797.77	1136.9
3800.74	1115.31
3803.71	1108.03
3806.68	1114.02
3809.64	1111.54
3812.61	1129.93
3815.57	1113.37
3818.53	1116.7
3821.49	1148.46
3824.45	1107.38
3827.41	1090.97
3830.36	1112.47
3833.32	1089.4
3836.27	1089.19
3839.23	1072.89
3842.18	1084.14
3845.13	1081.12
3848.08	1104.78
3851.03	1098.03
3853.98	1083.71
3856.92	1101.83
3859.87	1100.9
3862.81	1087.54
3865.75	1113.33
3868.7	1120.96
3871.64	1117.01
3874.57	1080.41
3877.51	1098.42
3880.45	1107.68
3883.39	1095.7
3886.32	1088.38
3889.25	1105.01
3892.18	1115.82
3895.12	1124.67
3898.05	1116.06
3900.97	1114.05
3903.9	1108.16
3906.83	1126.18
3909.75	1127.98
3912.68	1100.84
3915.6	1064.96
3918.52	1066.49
3921.44	1103.73
3924.36	1090.82
3927.28	1103.71
3930.2	1087.71
3933.11	1083.18
3936.03	1057.84
3938.94	1122.75
3941.86	1087.3
3944.77	1109.21
3947.68	1091.92
3950.59	1080.48
3953.49	1114.13
3956.4	1087.5
3959.31	1065.74
3962.21	1069.9
3965.12	1103.83
3968.02	1088.94
3970.92	1132.61
3973.82	1075.57
3976.72	1121.21
3979.61	1091.88
3982.51	1117.23
3985.41	1128.15
3988.3	1105.37
3991.19	1120.05
3994.09	1096.13
3996.98	1078.18
3999.87	1113.13