File: Data/3-Raman/raw/bu19(2)w-a-ff1-fi07-v_1800 (450-850nm)_532nm_edge_100%_x100_vis_lwd_h100um_30sx2_01.txt
#Acq. time (s)=	30
#Accumulations=	2
#Range (cm-¹)=	1200...2365
#Windows=	3
#Auto scanning=	Off
#Autofocus=	Off
#Macrospot=	Off
#AutoExposure=	Off
#Spike filter=	Multiple accum.
#Delay time (s)=	2
#Binning=	1
#Readout mode=	Signal
#DeNoise=	Off
#ICS correction=	On
#Dark correction=	Off
#Inst. Process=	Off
#Detector Gain=	Best Dynamic
#Detector ADC=	50 kHz HS
#Detector temperature (°C)=	-60.28
#Instrument=	LabRAM HR Evol
#Detector=	SIN-EM FIVIS
#Objective=	x100_VIS_LWD
#Grating=	1800 (450-850nm)
#ND Filter=	100%
#Laser=	532nm_Edge
#Hole=	100.021
#Temperature=	0
#Range=	Visible
#StageXY=	75x50mm Scan+
#StageZ=	Z motor
#X (µm)=	0
#Y (µm)=	0
#Z (µm)=	-66.9
#Full time(mm:ss)=	3:24
#Project=	21_11_26
#Sample=	BU19(2)w
#Site=
#Title=	BU19(2)w-A-FF1-FI07-V_1800 (450-850nm)_532nm_Edge_100%_x100_VIS_LWD_H100um_30sX2
#Remark=
#Date=	26.11.2021 16:46
#Acquired=	26.11.2021 16:46:02
1202.72	87.6466
1203.84	100.591
1204.95	88.6906
1206.06	84.2648
1207.17	84.1027
1208.28	88.2935
1209.39	88.1991
1210.5	81.7431
1211.61	84.8179
1212.72	82.5685
1213.83	76.1012
1214.94	84.6067
1216.05	79.2661
1217.16	79.1488
1218.27	79.0575
1219.38	80.0665
1220.49	82.1504
1221.6	73.6378
1222.71	75.6555
1223.81	73.399
1224.92	74.368
1226.03	76.4814
1227.14	77.5195
1228.25	79.4483
1229.35	67.6992
1230.46	75.2548
1231.57	79.2437
1232.67	76.0893
1233.78	75.0202
1234.89	70.843
1235.99	79.2834
1237.1	78.2119
1238.2	83.3583
1239.31	80.1118
1240.41	76.9369
1241.52	74.8458
1242.62	75.863
1243.73	61.2088
1244.83	73.7846
1245.94	89.4237
1247.04	82.0444
1248.14	85.1616
1249.25	72.5605
1250.35	86.153
1251.45	77.7135
1252.56	82.8759
1253.66	82.8158
1254.76	80.7718
1255.87	80.782
1256.97	86.0193
1258.07	95.3943
1259.17	96.3864
1260.27	96.4461
1261.37	126.591
1262.48	155.093
1263.58	198.471
1264.68	162.489
1265.78	111.122
1266.88	100.67
1267.98	91.3511
1269.08	105.088
1270.18	93.5629
1271.28	87.1934
1272.38	93.4797
1273.47	97.7797
1274.57	93.6753
1275.67	95.7818
1276.77	104.251
1277.87	116.942
1278.97	124.408
1280.07	160.192
1281.16	301.145
1282.26	817.122
1283.36	1918.34
1284.45	1457.49
1285.55	372.074
1286.65	158.254
1287.75	121.344
1288.84	111.838
1289.94	96.1055
1291.03	97.1821
1292.13	91.9022
1293.22	81.3628
1294.32	94.1121
1295.42	88.8581
1296.51	81.6444
1297.61	83.7433
1298.7	90.0293
1299.79	79.4226
1300.89	78.3878
1301.98	77.34
1303.08	76.3013
1304.17	68.8777
1305.26	77.3141
1306.35	79.3542
1307.45	73.0077
1308.54	67.7359
1309.63	65.6432
1310.73	64.5952
1311.82	78.3225
1312.91	73.0774
1314	67.7731
1315.09	65.6649
1316.18	67.8083
1317.28	67.7938
1318.37	66.7556
1319.46	65.6992
1320.55	62.5276
1321.64	69.8709
1322.73	64.5306
1323.82	70.8308
1324.91	65.5593
1326	68.674
1327.09	71.7138
1328.18	71.8332
1329.27	69.8061
1330.35	67.6837
1331.44	64.4615
1332.53	68.5755
1333.62	72.6862
1334.71	67.3515
1335.79	67.2925
1336.88	65.1507
1337.97	70.3618
1339.06	66.1145
1340.14	67.156
1341.23	72.3945
1342.32	70.27
1343.4	67.0675
1344.49	68.1039
1345.58	62.8417
1346.66	62.7505
1347.75	67.885
1348.83	68.8924
1349.92	69.8812
1351	72.9454
1352.09	62.4894
1353.17	66.6875
1354.25	63.6267
1355.34	66.593
1356.42	64.5045
1357.51	71.7391
1358.59	73.7661
1359.67	67.4882
1360.76	67.4205
1361.84	71.5391
1362.92	71.5091
1364	79.8157
1365.09	90.1652
1366.17	83.8756
1367.25	77.579
1368.33	86.8756
1369.41	164.441
1370.5	92.0372
1371.58	85.7595
1372.66	84.6004
1373.74	82.4779
1374.82	94.8114
1375.9	98.9259
1376.98	91.6689
1378.06	94.7209
1379.14	107.243
1380.22	106.155
1381.3	111.074
1382.38	140.747
1383.46	168.238
1384.54	273.74
1385.61	652.665
1386.69	2955.86
1387.77	3384.46
1388.85	561.585
1389.93	216.661
1391	152.759
1392.08	112.676
1393.16	111.561
1394.23	105.376
1395.31	94.1102
1396.39	87.9947
1397.46	87.9468
1398.54	82.8104
1399.62	87.9588
1400.69	84.9152
1401.77	83.9274
1402.84	85.0779
1403.92	89.2612
1404.99	90.2219
1406.07	114.767
1407.14	156.756
1408.22	243.947
1409.29	239.913
1410.37	132.255
1411.44	87.029
1412.51	75.7392
1413.59	65.6699
1414.66	65.5893
1415.73	64.5898
1416.81	65.6345
1417.88	65.6624
1418.95	62.5886
1420.02	62.5705
1421.1	63.5448
1422.17	62.5196
1423.24	64.7054
1424.31	65.5151
1425.38	62.4385
1426.45	65.5306
1427.52	58.2893
1428.59	55.1597
1429.67	55.173
1430.74	57.2684
1431.81	56.3128
1432.87	55.2532
1433.95	54.144
1435.01	52.1108
1436.08	52.1078
1437.15	49.016
1438.22	55.1451
1439.29	50.0391
1440.36	46.9977
1441.43	52.1356
1442.49	48.0255
1443.56	52.1215
1444.63	53.1334
1445.7	48.0427
1446.77	50.0756
1447.83	44.9279
1448.9	44.9391
1449.97	43.9039
1451.03	51.0549
1452.1	45.911
1453.17	43.8571
1454.23	44.8862
1455.3	46.9297
1456.36	44.8882
1457.43	42.8181
1458.49	45.8814
1459.56	41.7885
1460.62	42.8042
1461.69	46.8784
1462.75	45.8199
1463.82	42.7089
1464.88	48.895
1465.94	37.5222
1467.01	40.5681
1468.07	45.6591
1469.13	40.5502
1470.2	43.5791
1471.26	41.5162
1472.32	48.6189
1473.39	45.5536
1474.45	43.4933
1475.51	36.3732
1476.57	43.4799
1477.63	39.3876
1478.69	44.4533
1479.76	42.3894
1480.82	36.2513
1481.88	36.2351
1482.94	42.3498
1484	44.3861
1485.06	42.2644
1486.12	38.1966
1487.18	46.3041
1488.24	41.2138
1489.3	38.1415
1490.36	39.1398
1491.42	37.0937
1492.48	41.1313
1493.53	34.0469
1494.59	39.0976
1495.65	37.0575
1496.71	41.0565
1497.77	39.0236
1498.82	40.028
1499.88	39.025
1500.94	39.0253
1502	43.0436
1503.05	42.0155
1504.11	37.9583
1505.17	38.9678
1506.22	43.9673
1507.28	40.9456
1508.34	41.9506
1509.39	39.9332
1510.45	38.9288
1511.5	44.9322
1512.56	38.8113
1513.61	39.769
1514.67	38.7873
1515.72	36.7431
1516.78	40.7174
1517.83	39.7055
1518.88	38.7149
1519.94	38.7228
1520.99	38.715
1522.05	40.7261
1523.1	39.7028
1524.15	42.6601
1525.2	44.6416
1526.26	41.6521
1527.31	40.6692
1528.36	33.6369
1529.41	40.633
1530.47	39.6169
1531.52	33.6281
1532.57	37.6277
1533.62	44.6857
1534.67	36.6652
1535.72	34.6398
1536.77	39.595
1537.82	41.5496
1538.87	39.5219
1539.92	35.5739
1540.97	36.6331
1542.02	42.6197
1543.07	37.5687
1544.12	38.5225
1545.17	35.5418
1546.22	37.577
1547.27	37.5823
1548.32	37.5598
1549.37	41.538
1550.42	36.5441
1551.46	42.6736
1552.51	41.668
1553.56	35.6142
1554.61	40.5977
1555.65	39.5566
1556.7	39.5503
1557.75	42.5589
1558.79	38.5172
1559.84	38.47
1560.89	39.4467
1561.93	35.4528
1562.98	39.4695
1564.02	37.4591
1565.07	41.4893
1566.11	42.2285
1567.16	33.4138
1568.2	37.4357
1569.25	33.4422
1570.29	39.4185
1571.34	39.4144
1572.38	40.3919
1573.43	40.3638
1574.47	37.3619
1575.51	41.3922
1576.56	33.4007
1577.6	39.3463
1578.64	36.3062
1579.69	42.2822
1580.73	37.3056
1581.77	38.2823
1582.81	37.2611
1583.85	37.2507
1584.9	39.2417
1585.94	37.2445
1586.98	36.2174
1588.02	36.2003
1589.06	43.1769
1590.1	38.2123
1591.14	39.2162
1592.18	38.2091
1593.22	42.149
1594.26	41.0909
1595.3	39.1084
1596.34	37.1052
1597.38	39.093
1598.42	44.0588
1599.46	36.0761
1600.5	41.9992
1601.54	38.9774
1602.58	34.9753
1603.62	32.9633
1604.66	37.8964
1605.69	38.8858
1606.73	31.976
1607.77	38.879
1608.81	36.3151
1609.84	42.3146
1610.88	40.5209
1611.92	38.2061
1612.95	40.2626
1613.99	38.6664
1615.03	36.9277
1616.06	38.8341
1617.1	38.8655
1618.13	38.2183
1619.17	40.3482
1620.2	37.7099
1621.24	36.1717
1622.27	39.4391
1623.31	40.3205
1624.34	38.7652
1625.38	38.1943
1626.41	36.792
1627.45	38.6186
1628.48	38.7768
1629.51	38.9588
1630.55	40.7341
1631.53	35.0317
1632.57	41.9418
1633.62	37.9924
1634.66	36.0259
1635.71	43.9034
1636.75	38.9547
1637.8	39.9131
1638.84	34.9753
1639.89	40.8771
1640.93	40.8798
1641.98	37.9219
1643.02	38.8942
1644.06	40.852
1645.11	31.9764
1646.15	38.8703
1647.19	37.8674
1648.24	39.8178
1649.28	38.8652
1650.32	44.7658
1651.37	36.9205
1652.41	38.8943
1653.45	34.9402
1654.49	38.8853
1655.53	36.9262
1656.57	38.9343
1657.62	38.931
1658.66	37.9263
1659.7	40.8585
1660.74	35.9182
1661.78	39.8867
1662.82	38.9398
1663.86	40.9164
1664.9	40.885
1665.94	37.8695
1666.98	36.9262
1668.02	35.9151
1669.06	36.9052
1670.1	40.879
1671.14	35.9625
1672.18	37.9286
1673.21	37.9286
1674.25	41.8887
1675.29	40.9193
1676.33	41.9145
1677.37	35.976
1678.4	38.9223
1679.44	41.8585
1680.48	37.886
1681.52	38.8567
1682.55	38.8517
1683.59	40.8207
1684.63	34.8806
1685.66	41.7819
1686.7	41.782
1687.73	34.8733
1688.77	41.7658
1689.81	35.8119
1690.84	40.7309
1691.88	38.7681
1692.91	35.7991
1693.95	38.717
1694.98	41.6388
1696.01	36.7149
1697.05	38.6921
1698.08	41.6111
1699.12	41.5784
1700.15	30.7484
1701.18	33.6874
1702.22	35.6325
1703.25	38.5541
1704.28	36.5753
1705.32	37.5609
1706.35	34.601
1707.38	38.49
1708.41	38.4428
1709.44	34.4746
1710.48	36.4205
1711.51	37.4082
1712.54	33.4887
1713.57	38.3232
1714.6	39.2557
1715.63	40.2281
1716.66	42.1767
1717.69	35.2897
1718.72	42.0456
1719.75	38.1307
1720.78	43.9662
1721.81	39.06
1722.84	41.9325
1723.87	38.9839
1724.9	37.0258
1725.93	39.8784
1726.96	41.7974
1727.99	41.7808
1729.02	43.6272
1730.05	44.5445
1731.07	35.8264
1732.1	36.8308
1733.13	43.5733
1734.16	40.6168
1735.18	41.5247
1736.21	38.5926
1737.24	42.4189
1738.26	40.4666
1739.29	40.427
1740.32	40.3605
1741.34	35.5186
1742.37	42.1919
1743.4	42.1745
1744.42	46.9324
1745.45	38.3097
1746.47	37.3347
1747.5	44.9312
1748.52	37.2634
1749.55	38.2225
1750.57	35.3827
1751.6	43.0419
1752.62	43.9519
1753.64	42.0015
1754.67	40.0575
1755.69	42.8908
1756.71	46.657
1757.74	41.8474
1758.76	35.1963
1759.78	39.002
1760.81	42.7926
1761.83	38.0065
1762.85	43.7038
1763.87	37.9999
1764.89	40.8792
1765.92	43.7496
1766.94	47.5501
1767.96	40.8696
1768.98	44.6531
1770	43.6178
1771.02	43.637
1772.04	53.178
1773.06	43.6905
1774.08	44.6576
1775.1	42.7637
1776.12	49.4736
1777.14	44.7034
1778.16	43.7181
1779.18	38.9182
1780.2	42.7138
1781.22	44.628
1782.24	42.7326
1783.26	42.7573
1784.28	48.4962
1785.29	41.8465
1786.31	42.7853
1787.33	39.9387
1788.35	42.8796
1789.37	41.0237
1790.38	41.0564
1791.4	39.1302
1792.42	40.053
1793.43	42.9355
1794.45	42.9406
1795.47	41.0568
1796.48	40.139
1797.5	35.3616
1798.51	36.3368
1799.53	39.2135
1800.55	38.2219
1801.56	35.3247
1802.58	39.1706
1803.59	39.1947
1804.61	39.2084
1805.62	38.2751
1806.64	42.1558
1807.65	41.1995
1808.66	31.5591
1809.68	39.2716
1810.69	35.416
1811.7	41.1914
1812.72	36.3726
1813.73	35.423
1814.74	38.3483
1815.76	42.2395
1816.77	35.4783
1817.78	41.2493
1818.79	35.4544
1819.8	39.3272
1820.82	36.4404
1821.83	39.3572
1822.84	39.3698
1823.85	39.3658
1824.86	36.4592
1825.87	37.4369
1826.88	42.2776
1827.89	39.3796
1828.9	36.4678
1829.91	36.4521
1830.92	36.4334
1831.93	37.4119
1832.94	36.4611
1833.95	36.4671
1834.96	36.4384
1835.97	39.2802
1836.98	40.3923
1837.99	39.2924
1839	39.2851
1840	38.3662
1841.01	39.2535
1842.02	33.3846
1843.03	36.2452
1844.04	37.2055
1845.04	36.2378
1846.05	38.1741
1847.06	40.1394
1848.07	36.1463
1849.07	31.3349
1850.08	37.0789
1851.09	32.2243
1852.09	37.0001
1853.1	37.9539
1854.1	36.9745
1855.11	35.9724
1856.11	38.8072
1857.12	34.9658
1858.12	35.9057
1859.13	35.8718
1860.13	38.7102
1861.14	36.8097
1862.14	34.9118
1863.15	34.8845
1864.15	32.9382
1865.15	36.7283
1866.16	36.6769
1867.16	38.5144
1868.16	33.7072
1869.17	34.6497
1870.17	37.4906
1871.17	36.5296
1872.17	35.5614
1873.18	38.3837
1874.18	35.5164
1875.18	37.3757
1876.18	38.2629
1877.18	35.3801
1878.18	34.3801
1879.19	38.2176
1880.19	32.563
1881.19	37.2885
1882.19	35.3384
1883.19	35.2593
1884.19	38.044
1885.19	31.4593
1886.19	33.3838
1887.19	40.9269
1888.19	37.1107
1889.19	34.2305
1890.19	38.9132
1891.19	38.9334
1892.18	35.1538
1893.18	38.899
1894.18	37.8949
1895.18	35.0547
1896.18	36.0016
1897.18	33.2002
1898.17	36.9675
1899.17	34.1211
1900.17	38.7908
1901.16	36.9065
1902.16	36.9312
1903.16	37.8817
1904.16	38.8033
1905.15	36.9123
1906.15	35.9536
1907.14	43.4365
1908.14	37.8026
1909.14	34.9961
1910.13	41.608
1911.13	35.0632
1912.12	34.1273
1913.12	38.8267
1914.11	36.0144
1915.11	37.9323
1916.1	34.1681
1917.1	35.09
1918.09	39.7821
1919.08	36.9744
1920.08	37.0224
1921.07	35.1355
1922.06	31.3776
1923.06	37.9878
1924.05	38.9129
1925.04	35.1108
1926.04	35.1311
1927.03	32.3276
1928.02	35.1852
1929.01	37.0913
1930	36.1698
1931	37.1543
1931.99	39.0449
1932.98	37.1208
1933.97	35.2252
1934.96	38.1791
1935.95	35.3982
1936.94	38.2185
1937.93	41.9891
1938.92	38.1747
1939.91	34.3822
1940.9	42.0286
1941.89	41.1093
1942.88	34.441
1943.87	34.4166
1944.86	36.3469
1945.85	32.5557
1946.84	36.3993
1947.83	36.3896
1948.82	37.3371
1949.8	31.6167
1950.79	36.4481
1951.78	34.5817
1952.77	34.6062
1953.76	35.5669
1954.74	38.3622
1955.73	41.2122
1956.72	32.6416
1957.7	35.5507
1958.69	37.4872
1959.68	34.5883
1960.66	40.3288
1961.65	35.4978
1962.63	38.374
1963.62	38.3763
1964.61	36.4641
1965.59	37.4159
1966.58	36.4716
1967.56	39.3688
1968.55	39.3719
1969.53	43.1899
1970.52	38.3385
1971.5	45.9859
1972.48	39.2665
1973.47	44.0495
1974.45	40.1834
1975.44	45.9345
1976.42	40.1999
1977.4	44.0358
1978.39	44.0095
1979.37	38.2407
1980.35	41.1159
1981.33	41.0896
1982.31	38.1973
1983.3	46.7846
1984.28	45.7916
1985.26	46.7225
1986.24	48.6149
1987.22	40.0225
1988.21	50.4996
1989.19	46.5809
1990.17	47.4102
1991.15	48.5751
1992.13	49.612
1993.11	51.6894
1994.09	49.7213
1995.07	47.1111
1996.05	50.4614
1997.03	51.331
1998.01	53.5644
1998.99	54.7564
1999.97	53.7965
2000.95	49.9132
2001.92	54.0488
2002.9	55.8571
2003.88	55.3124
2004.86	52.317
2005.84	54.9687
2006.81	51.7526
2007.79	53.6264
2008.77	55.3685
2009.75	50.84
2010.73	54.0396
2011.7	50.8257
2012.68	55.9757
2013.67	50.2674
2014.66	53.9401
2015.64	50.1613
2016.63	53.9374
2017.62	53.0319
2018.61	51.0822
2019.6	54.7522
2020.58	49.1069
2021.57	46.2965
2022.56	49.091
2023.55	49.0435
2024.54	48.9999
2025.52	47.0664
2026.51	44.2278
2027.5	49.9528
2028.48	49.8932
2029.47	45.2922
2030.45	46.0858
2031.44	43.3049
2032.43	43.3104
2033.41	46.1677
2034.4	43.3673
2035.38	43.2993
2036.37	41.5195
2037.35	47.1158
2038.34	46.1658
2039.32	44.2669
2040.31	39.5603
2041.29	45.1146
2042.27	44.1601
2043.26	45.0715
2044.24	42.324
2045.23	42.2973
2046.21	43.3166
2047.19	39.5412
2048.17	42.2859
2049.16	43.2274
2050.14	38.6065
2051.12	42.371
2052.11	40.4775
2053.09	42.3574
2054.07	39.5964
2055.05	36.8013
2056.03	34.912
2057.01	37.7031
2058	36.7754
2058.98	42.4163
2059.96	43.3712
2060.94	39.6102
2061.92	39.6246
2062.9	40.5686
2063.88	36.8437
2064.86	37.7938
2065.84	32.1976
2066.82	39.7279
2067.8	39.7436
2068.78	36.0008
2069.76	37.8687
2070.73	38.803
2071.71	38.8265
2072.69	36.0543
2073.67	33.2217
2074.65	39.8201
2075.63	34.2102
2076.6	37.0778
2077.58	39.8881
2078.56	36.1035
2079.54	37.0657
2080.51	32.3767
2081.49	39.9326
2082.47	34.2616
2083.45	36.1544
2084.42	36.1501
2085.4	38.0399
2086.37	40.8865
2087.35	36.1858
2088.32	33.3552
2089.3	36.1987
2090.28	36.2216
2091.25	35.284
2092.23	35.3091
2093.2	35.3516
2094.18	36.334
2095.15	36.3393
2096.13	39.1674
2097.1	35.3554
2098.07	34.3824
2099.05	38.1685
2100.02	35.314
2101	33.4205
2101.97	33.4395
2102.94	37.234
2103.92	34.3654
2104.89	33.4208
2105.86	38.1927
2106.83	33.4551
2107.8	31.5537
2108.78	34.3697
2109.75	37.2172
2110.72	37.2233
2111.69	36.2685
2112.66	32.457
2113.63	39.1246
2114.61	34.377
2115.58	30.5733
2116.55	32.4575
2117.52	31.4937
2118.49	33.3781
2119.46	36.1877
2120.43	33.3161
2121.4	33.3219
2122.37	33.3497
2123.34	36.2151
2124.31	36.2106
2125.28	34.2657
2126.25	34.2164
2127.21	37.0211
2128.18	35.1131
2129.15	35.1054
2130.12	28.4798
2131.09	35.0832
2132.06	33.1728
2133.02	35.9822
2133.99	35.0354
2134.96	36.9229
2135.93	36.9131
2136.89	34.049
2137.86	34.997
2138.83	32.1548
2139.79	34.046
2140.76	34.9576
2141.73	32.1214
2142.69	36.8094
2143.66	32.1254
2144.62	34.8808
2145.59	36.7609
2146.55	36.7522
2147.52	33.9163
2148.48	33.8979
2149.45	33.8753
2150.42	35.7092
2151.38	35.6985
2152.34	36.6519
2153.31	36.6376
2154.27	32.8685
2155.24	35.6273
2156.2	34.6437
2157.16	33.6948
2158.13	32.7716
2159.09	32.7744
2160.05	32.7533
2161.01	31.788
2161.98	33.6406
2162.94	33.6366
2163.9	30.8224
2164.86	33.594
2165.83	33.5915
2166.79	33.5827
2167.75	30.7631
2168.71	33.5075
2169.67	34.4478
2170.63	33.5571
2171.59	32.615
2172.56	33.4881
2173.51	31.616
2174.48	33.4814
2175.44	28.8333
2176.4	33.4709
2177.36	32.5298
2178.32	34.3876
2179.28	34.3652
2180.23	30.6513
2181.19	33.4292
2182.15	36.2005
2183.11	36.1849
2184.07	33.3688
2185.03	33.3562
2185.99	32.4396
2186.95	32.4638
2187.9	38.07
2188.86	29.6967
2189.82	37.0824
2190.78	35.2105
2191.73	35.2165
2192.69	32.444
2193.65	31.5331
2194.6	33.4361
2195.56	33.431
2196.52	29.6815
2197.47	32.435
2198.43	30.5775
2199.38	36.1825
2200.34	40.883
2201.3	30.7022
2202.25	33.3849
2203.21	35.3008
2204.16	39.1604
2205.12	36.2915
2206.07	33.4139
2207.03	32.4796
2207.98	31.567
2208.93	33.4528
2209.89	33.4615
2210.84	35.3322
2211.8	34.421
2212.75	33.5089
2213.7	29.7631
2214.66	32.5746
2215.61	31.6602
2216.56	29.7931
2217.51	30.7214
2218.47	33.5227
2219.42	30.7341
2220.37	33.5522
2221.32	29.8058
2222.27	38.1792
2223.23	31.6442
2224.18	33.5382
2225.13	32.6366
2226.08	33.6031
2227.03	32.691
2227.98	32.707
2228.93	28.9471
2229.88	30.8224
2230.83	31.7861
2231.78	30.8734
2232.73	31.8362
2233.68	30.9171
2234.63	33.7511
2235.58	32.7842
2236.53	31.8376
2237.48	31.8482
2238.43	30.9488
2239.38	28.1543
2240.33	31.9124
2241.27	33.8118
2242.22	30.0445
2243.17	31.9413
2244.12	32.8707
2245.07	33.828
2246.01	31.9765
2246.96	26.3207
2247.91	31.0631
2248.85	28.2167
2249.8	31.0547
2250.75	32.939
2251.69	34.803
2252.64	26.2985
2253.59	32.9646
2254.53	31.097
2255.48	29.2024
2256.42	29.2083
2257.37	29.2268
2258.32	30.189
2259.26	29.2479
2260.2	33.061
2261.15	29.271
2262.1	30.2395
2263.04	32.1578
2263.98	30.2868
2264.93	30.328
2265.87	33.2121
2266.81	29.3751
2267.76	35.0748
2268.7	32.1914
2269.65	32.2108
2270.59	33.2049
2271.53	24.6225
2272.47	30.3744
2273.42	32.2921
2274.36	29.4262
2275.3	31.3459
2276.24	36.1397
2277.18	28.5034
2278.13	33.3384
2279.07	29.5173
2280.01	30.4539
2280.95	30.4221
2281.89	25.6142
2282.83	29.4617
2283.77	30.4541
2284.71	32.4256
2285.65	29.5581
2286.59	29.5389
2287.54	28.6069
2288.47	33.4354
2289.41	32.4449
2290.35	36.2476
2291.29	36.2487
2292.23	31.4711
2293.17	34.3856
2294.11	27.6543
2295.05	30.5277
2295.99	29.5461
2296.93	32.4063
2297.86	32.4255
2298.8	29.565
2299.74	34.4113
2300.68	36.3413
2301.61	38.2896
2302.55	32.4959
2303.49	30.5602
2304.43	28.6362
2305.36	33.4818
2306.3	32.5265
2307.24	30.5975
2308.17	31.5521
2309.11	33.4786
2310.04	30.6057
2310.98	27.7115
2311.92	29.5983
2312.85	32.464
2313.79	30.5407
2314.72	32.5117
2315.66	30.5959
2316.59	27.6573
2317.52	31.507
2318.46	32.4762
2319.39	32.4541
2320.33	33.4066
2321.26	38.24
2322.2	38.2713
2323.13	39.2607
2324.06	43.1368
2325	43.1221
2325.93	52.7292
2326.86	99.9604
2327.79	288.835
2328.73	192.385
2329.66	69.9288
2330.59	48.7317
2331.52	37.1662
2332.46	32.3581
2333.39	35.2246
2334.32	31.3567
2335.25	34.2183
2336.18	32.2936
2337.11	34.2067
2338.04	31.3135
2338.97	31.3055
2339.91	34.188
2340.84	34.1674
2341.77	37.0027
2342.7	30.26
2343.63	36.0042
2344.56	32.1677
2345.49	35.9944
2346.41	30.2173
2347.34	34.0372
2348.27	31.1624
2349.2	34.9941
2350.13	32.0702
2351.06	34.7701
2351.99	32.042
2352.91	33.8993
2353.84	37.6585
2354.77	30.9891
2355.7	36.7054
2356.63	30.0128
2357.55	35.6792
2358.48	31.8556
2359.41	31.8387
2360.33	31.8186
2361.26	33.6839
2362.19	33.6478
2363.11	27.9327
2364.04	31.6994
2364.97	32.6251