File: Data/3-Raman/raw/bu19(2)w-a-ff1-fi09-v_1800 (450-850nm)_532nm_edge_100%_x100_vis_lwd_h100um_30sx2_01.txt
#Acq. time (s)=	30
#Accumulations=	2
#Range (cm-¹)=	1200...2365
#Windows=	3
#Auto scanning=	Off
#Autofocus=	Off
#Macrospot=	Off
#AutoExposure=	Off
#Spike filter=	Multiple accum.
#Delay time (s)=	2
#Binning=	1
#Readout mode=	Signal
#DeNoise=	Off
#ICS correction=	On
#Dark correction=	Off
#Inst. Process=	Off
#Detector Gain=	Best Dynamic
#Detector ADC=	50 kHz HS
#Detector temperature (°C)=	-60.09
#Instrument=	LabRAM HR Evol
#Detector=	SIN-EM FIVIS
#Objective=	x100_VIS_LWD
#Grating=	1800 (450-850nm)
#ND Filter=	100%
#Laser=	532nm_Edge
#Hole=	100.021
#Temperature=	0
#Range=	Visible
#StageXY=	75x50mm Scan+
#StageZ=	Z motor
#X (µm)=	0
#Y (µm)=	0
#Z (µm)=	-56
#Full time(mm:ss)=	3:17
#Project=	21_11_26
#Sample=	BU19(2)w
#Site=
#Title=	BU19(2)w-A-FF1-FI09-V_1800 (450-850nm)_532nm_Edge_100%_x100_VIS_LWD_H100um_30sX2
#Remark=
#Date=	26.11.2021 16:30
#Acquired=	26.11.2021 16:30:03
1202.72	66.1382
1203.84	75.8455
1204.95	75.7888
1206.06	70.3079
1207.17	77.6725
1208.28	69.0249
1209.39	70.0194
1210.5	62.5027
1211.61	78.4128
1212.72	68.7115
1213.83	70.7748
1214.94	66.5048
1216.05	72.8764
1217.16	70.6421
1218.27	64.1895
1219.38	69.4519
1220.49	65.1763
1221.6	73.6337
1222.71	71.4156
1223.81	74.4514
1224.92	69.0845
1226.03	73.3089
1227.14	72.2361
1228.25	75.2298
1229.35	79.2517
1230.46	78.4096
1231.57	72.9336
1232.67	73.9815
1233.78	80.2657
1234.89	67.6835
1235.99	69.8141
1237.1	79.2556
1238.2	79.1515
1239.31	81.1525
1240.41	83.2179
1241.52	82.1756
1242.62	80.0461
1243.73	86.3582
1244.83	85.3064
1245.94	91.5089
1247.04	94.5956
1248.14	91.4307
1249.25	92.4227
1250.35	98.6934
1251.45	101.737
1252.56	91.2189
1253.66	98.4574
1254.76	100.598
1255.87	108.966
1256.97	137.188
1258.07	155.949
1259.17	149.604
1260.27	177.897
1261.37	235.076
1262.48	317.136
1263.58	319.415
1264.68	225.24
1265.78	174.857
1266.88	167.542
1267.98	149.919
1269.08	148.021
1270.18	156.399
1271.28	154.157
1272.38	146.844
1273.47	155.398
1274.57	159.741
1275.67	175.492
1276.77	188.221
1277.87	216.743
1278.97	255.849
1280.07	421.038
1281.16	1116.34
1282.26	3489.66
1283.36	4256.16
1284.45	1549.99
1285.55	519.504
1286.65	283.552
1287.75	223.433
1288.84	193.905
1289.94	168.744
1291.03	162.467
1292.13	157.18
1293.22	149.796
1294.32	127.833
1295.42	141.571
1296.51	139.752
1297.61	130.219
1298.7	125.917
1299.79	119.513
1300.89	120.602
1301.98	115.336
1303.08	109.025
1304.17	104.757
1305.26	106.855
1306.35	110.979
1307.45	103.571
1308.54	112.014
1309.63	102.548
1310.73	94.1192
1311.82	106.795
1312.91	99.4517
1314	102.584
1315.09	99.4227
1316.18	98.4145
1317.28	93.1144
1318.37	99.4786
1319.46	83.6334
1320.55	102.647
1321.64	94.1266
1322.73	95.0928
1323.82	92.9468
1324.91	88.7307
1326	92.8835
1327.09	99.0395
1328.18	92.8823
1329.27	98.2656
1330.35	98.249
1331.44	87.6225
1332.53	96.9657
1333.62	91.5784
1334.71	94.6221
1335.79	90.3439
1336.88	93.4298
1337.97	95.4853
1339.06	92.2654
1340.14	99.5888
1341.23	95.4041
1342.32	97.4581
1343.4	96.3235
1344.49	82.715
1345.58	99.3982
1346.66	89.8607
1347.75	94.9625
1348.83	92.8305
1349.92	96.9263
1351	88.5223
1352.09	101.971
1353.17	95.7885
1354.25	104.213
1355.34	103.968
1356.42	103.953
1357.51	103.899
1358.59	98.6404
1359.67	99.6047
1360.76	105.723
1361.84	122.259
1362.92	123.245
1364	135.711
1365.09	138.808
1366.17	128.337
1367.25	136.463
1368.33	170.565
1369.41	289.509
1370.5	145.75
1371.58	140.46
1372.66	143.346
1373.74	149.428
1374.82	158.649
1375.9	163.791
1376.98	176.069
1378.06	176.003
1379.14	209.276
1380.22	209.166
1381.3	251.924
1382.38	315.349
1383.46	429.787
1384.54	810.931
1385.61	2425.92
1386.69	9709.75
1387.77	4615.7
1388.85	938.676
1389.93	465.132
1391	313.701
1392.08	251.973
1393.16	209.799
1394.23	199.483
1395.31	176.955
1396.39	168.818
1397.46	165.66
1398.54	157.438
1399.62	151.361
1400.69	159.599
1401.77	162.742
1402.84	161.961
1403.92	175.455
1404.99	204.056
1406.07	252.11
1407.14	356.583
1408.22	524.829
1409.29	430.626
1410.37	247.102
1411.44	162.819
1412.51	140.244
1413.59	120.076
1414.66	112.748
1415.73	111.77
1416.81	99.4787
1417.88	102.605
1418.95	96.4545
1420.02	92.3184
1421.1	87.1094
1422.17	86.0856
1423.24	88.3203
1424.31	91.1038
1425.38	84.9514
1426.45	83.9463
1427.52	78.7366
1428.59	76.6114
1429.67	70.4857
1430.74	66.4439
1431.81	68.5789
1432.87	72.6415
1433.95	64.3364
1435.01	63.3312
1436.08	64.3526
1437.15	70.4763
1438.22	66.3587
1439.29	60.2319
1440.36	59.2482
1441.43	65.4148
1442.49	57.2016
1443.56	62.3223
1444.63	59.2312
1445.7	52.0932
1446.77	57.2015
1447.83	58.2027
1448.9	47.9618
1449.97	54.1041
1451.03	54.0752
1452.1	53.0286
1453.17	50.9742
1454.23	52.0043
1455.3	53.0224
1456.36	47.9073
1457.43	49.9339
1458.49	50.9471
1459.56	40.7074
1460.62	47.8696
1461.69	50.9174
1462.75	47.8093
1463.82	46.7411
1464.88	41.6726
1465.94	45.6289
1467.01	39.4897
1468.07	46.6208
1469.13	45.5915
1470.2	39.4429
1471.26	40.4382
1472.32	44.4864
1473.39	40.4033
1474.45	40.3806
1475.51	39.3667
1476.57	36.2972
1477.63	39.327
1478.69	42.3592
1479.76	40.2964
1480.82	41.2646
1481.88	41.2463
1482.94	38.227
1484	39.2468
1485.06	40.1753
1486.12	40.1603
1487.18	42.1884
1488.24	45.2018
1489.3	38.0783
1490.36	40.088
1491.42	41.0746
1492.48	42.0784
1493.53	37.0155
1494.59	38.0223
1495.65	40.0244
1496.71	38.9726
1497.77	41.9863
1498.82	40.9719
1499.88	35.9311
1500.94	40.9786
1502	39.95
1503.05	38.9229
1504.11	41.925
1505.17	40.9179
1506.22	32.8176
1507.28	36.8478
1508.34	33.8221
1509.39	38.8578
1510.45	33.8218
1511.5	34.7948
1512.56	40.7529
1513.61	41.7081
1514.67	40.7274
1515.72	38.6813
1516.78	37.6396
1517.83	36.6279
1518.88	37.642
1519.94	38.6527
1520.99	35.6351
1522.05	35.6387
1523.1	41.6379
1524.15	39.5835
1525.2	32.5532
1526.26	38.575
1527.31	38.5927
1528.36	39.5769
1529.41	38.5574
1530.47	36.5403
1531.52	40.5696
1532.57	41.5622
1533.62	40.6007
1534.67	39.601
1535.72	37.574
1536.77	41.5236
1537.82	37.4745
1538.87	39.4474
1539.92	40.5047
1540.97	31.5445
1542.02	37.5339
1543.07	41.4979
1544.12	39.4469
1545.17	35.4659
1546.22	37.5009
1547.27	37.5059
1548.32	31.4753
1549.37	34.4558
1550.42	31.4615
1551.46	40.5883
1552.51	35.5662
1553.56	44.5662
1554.61	29.4911
1555.65	41.4818
1556.7	36.4669
1557.75	33.464
1558.79	36.4363
1559.84	38.3908
1560.89	36.3691
1561.93	36.3727
1562.98	36.3893
1564.02	32.3793
1565.07	39.4075
1566.11	37.174
1567.16	33.3329
1568.2	36.3549
1569.25	38.3602
1570.29	32.3412
1571.34	36.3344
1572.38	37.3131
1573.43	36.2883
1574.47	33.2865
1575.51	35.3144
1576.56	35.3162
1577.6	32.2761
1578.64	40.2107
1579.69	37.2138
1580.73	40.2133
1581.77	35.2077
1582.81	32.1955
1583.85	37.166
1584.9	34.1763
1585.94	38.1553
1586.98	35.1367
1588.02	36.1147
1589.06	39.11
1590.1	36.1348
1591.14	35.1462
1592.18	35.1353
1593.22	33.109
1594.26	35.0435
1595.3	36.0403
1596.34	39.9972
1597.38	38.0118
1598.42	38.0105
1599.46	29.0402
1600.5	31.9922
1601.54	35.9163
1602.58	34.8863
1603.62	31.885
1604.66	37.8069
1605.69	34.8408
1606.73	33.8645
1607.77	33.0197
1608.81	38.4888
1609.84	34.2272
1610.88	37.0316
1611.92	38.6735
1612.95	34.7164
1613.99	35.2225
1615.03	36.2485
1616.06	34.7666
1617.1	35.7338
1618.13	35.956
1619.17	35.8016
1620.2	37.1877
1621.24	36.8684
1622.27	36.6335
1623.31	36.9421
1624.34	37.0894
1625.38	34.4675
1626.41	35.4213
1627.45	35.6301
1628.48	35.7419
1629.51	34.8337
1630.55	38.1722
1631.53	37.9662
1632.57	35.024
1633.62	36.9885
1634.66	37.9799
1635.71	37.9735
1636.75	36.9689
1637.8	33.9911
1638.84	37.915
1639.89	36.9274
1640.93	33.9768
1641.98	35.9426
1643.02	38.885
1644.06	38.8754
1645.11	35.9043
1646.15	38.8641
1647.19	34.911
1648.24	34.8966
1649.28	36.8934
1650.32	41.8107
1651.37	31.9932
1652.41	38.8943
1653.45	35.9264
1654.49	38.8873
1655.53	32.9855
1656.57	39.9253
1657.62	37.949
1658.66	35.959
1659.7	35.935
1660.74	38.8842
1661.78	31.0155
1662.82	38.95
1663.86	36.9755
1664.9	37.9352
1665.94	31.9665
1666.98	37.9278
1668.02	36.9172
1669.06	36.9215
1670.1	33.9818
1671.14	35.9809
1672.18	35.9712
1673.21	33.9949
1674.25	36.9662
1675.29	35.9949
1676.33	34.021
1677.37	36.0005
1678.4	35.98
1679.44	34.9647
1680.48	37.9135
1681.52	32.9577
1682.55	34.9296
1683.59	36.8998
1684.63	37.8751
1685.66	36.8773
1686.7	39.8405
1687.73	33.9202
1688.77	36.8645
1689.81	37.8221
1690.84	35.8363
1691.88	36.8331
1692.91	31.8919
1693.95	34.8147
1694.98	35.7704
1696.01	35.7726
1697.05	30.852
1698.08	39.6866
1699.12	35.7201
1700.15	33.7474
1701.18	37.6704
1702.22	39.6146
1703.25	36.6388
1704.28	36.6263
1705.32	35.6477
1706.35	35.6365
1707.38	36.5811
1708.41	29.6745
1709.44	36.489
1710.48	36.4777
1711.51	35.5078
1712.54	39.4243
1713.57	38.3835
1714.6	37.3632
1715.63	38.3367
1716.66	39.3095
1717.69	37.3053
1718.72	34.3189
1719.75	33.3289
1720.78	32.3504
1721.81	36.2102
1722.84	40.0584
1723.87	40.0254
1724.9	40.0096
1725.93	38.0121
1726.96	37.9947
1727.99	38.949
1729.02	37.9018
1730.05	37.8602
1731.07	33.0082
1732.1	33.0436
1733.13	36.8907
1734.16	35.8737
1735.18	39.6794
1736.21	31.9372
1737.24	40.5784
1738.26	33.8203
1739.29	41.4736
1740.32	35.651
1741.34	35.6065
1742.37	35.5784
1743.4	30.7782
1744.42	42.2398
1745.45	40.3147
1746.47	41.2522
1747.5	33.5637
1748.52	40.222
1749.55	38.3185
1750.57	40.2577
1751.6	37.4038
1752.62	43.0958
1753.64	36.3758
1754.67	40.1586
1755.69	42.0399
1756.71	37.2381
1757.74	39.098
1758.76	39.1076
1759.78	39.1082
1760.81	40.0457
1761.83	39.0655
1762.85	42.8623
1763.87	34.3069
1764.89	40.9905
1765.92	37.1978
1766.94	41.9517
1767.96	38.129
1768.98	43.8172
1770	38.0369
1771.02	40.9042
1772.04	37.1315
1773.06	40.0042
1774.08	40.0186
1775.1	42.8852
1776.12	42.9239
1777.14	37.2015
1778.16	47.6531
1779.18	39.0438
1780.2	39.9856
1781.22	34.284
1782.24	35.2432
1783.26	37.1694
1784.28	36.2321
1785.29	39.1159
1786.31	37.1948
1787.33	37.2095
1788.35	37.2771
1789.37	39.2442
1790.38	39.2762
1791.4	39.2681
1792.42	38.2766
1793.43	40.2015
1794.45	37.3322
1795.47	36.4033
1796.48	31.6401
1797.5	39.3495
1798.51	37.4433
1799.53	34.5524
1800.55	35.4867
1801.56	38.3544
1802.58	35.4769
1803.59	36.4606
1804.61	37.4358
1805.62	34.5764
1806.64	34.6009
1807.65	38.4623
1808.66	38.4615
1809.68	38.4639
1810.69	36.5375
1811.7	36.5294
1812.72	34.6035
1813.73	36.5481
1814.74	34.6471
1815.76	27.9056
1816.77	38.5417
1817.78	33.6851
1818.79	38.5187
1819.8	37.5606
1820.82	35.6409
1821.83	33.7205
1822.84	33.7316
1823.85	35.6644
1824.86	37.5988
1825.87	41.4832
1826.88	37.6087
1827.89	36.6479
1828.9	39.5498
1829.91	37.5973
1830.92	34.6749
1831.93	39.5277
1832.94	41.4865
1833.95	34.7092
1834.96	36.6202
1835.97	32.6921
1836.98	35.7217
1837.99	36.5738
1839	39.471
1840	37.584
1841.01	35.5727
1842.02	40.3317
1843.03	36.4352
1844.04	36.4319
1845.04	35.4651
1846.05	42.2271
1847.06	35.5038
1848.07	34.4162
1849.07	32.4939
1850.08	35.3519
1851.09	36.2661
1852.09	37.1993
1853.1	31.4325
1854.1	30.4567
1855.11	34.257
1856.11	34.2207
1857.12	35.1701
1858.12	31.3237
1859.13	35.1215
1860.13	37.9615
1861.14	35.1053
1862.14	35.1212
1863.15	32.2258
1864.15	31.2386
1865.15	32.1667
1866.16	31.1688
1867.16	31.1129
1868.16	34.8736
1869.17	32.9649
1870.17	31.0544
1871.17	31.0458
1872.17	33.881
1873.18	33.857
1874.18	36.6872
1875.18	32.8572
1876.18	29.0182
1877.18	34.6591
1878.18	37.4394
1879.19	31.8218
1880.19	28.0566
1881.19	35.6239
1882.19	33.6776
1883.19	32.66
1884.19	28.8521
1885.19	31.6922
1886.19	35.5059
1887.19	36.442
1888.19	33.5743
1889.19	32.5839
1890.19	37.2686
1891.19	34.4629
1892.18	37.2773
1893.18	33.4923
1894.18	33.4376
1895.18	35.2978
1896.18	32.4867
1897.18	32.505
1898.17	32.5104
1899.17	30.6079
1900.17	38.0995
1901.16	38.0952
1902.16	36.2412
1903.16	35.3112
1904.16	37.1751
1905.15	37.1656
1906.15	35.2682
1907.14	36.1791
1908.14	36.1806
1909.14	37.1328
1910.13	37.1638
1911.13	39.0895
1912.12	42.8656
1913.12	39.0882
1914.11	36.2769
1915.11	32.5364
1916.1	33.4891
1917.1	35.3556
1918.09	32.507
1919.08	32.5252
1920.08	34.457
1921.07	31.6257
1922.06	37.3224
1923.06	34.4773
1924.05	35.4049
1925.04	36.3293
1926.04	33.5151
1927.03	37.3359
1928.02	34.515
1929.01	33.5791
1930	36.4487
1931	34.5862
1931.99	37.4273
1932.98	36.454
1933.97	34.5593
1934.96	35.6081
1935.95	36.637
1936.94	36.5988
1937.93	37.5158
1938.92	36.5587
1939.91	37.5292
1940.9	35.6457
1941.89	33.7671
1942.88	38.5516
1943.87	37.572
1944.86	42.3697
1945.85	31.8953
1946.84	30.9573
1947.83	37.6431
1948.82	32.8547
1949.8	34.7864
1950.79	33.8741
1951.78	33.9235
1952.77	38.7504
1953.76	36.8309
1954.74	34.8325
1955.73	33.8531
1956.72	32.9481
1957.7	35.8582
1958.69	36.8346
1959.68	37.7804
1960.66	34.8771
1961.65	31.9705
1962.63	33.8877
1963.62	35.81
1964.61	34.8582
1965.59	33.8909
1966.58	37.749
1967.56	38.7253
1968.55	35.8452
1969.53	31.0182
1970.52	33.8601
1971.5	34.7963
1972.48	38.6301
1973.47	37.6596
1974.45	41.4668
1975.44	42.4259
1976.42	39.5677
1977.4	36.69
1978.39	36.6684
1979.37	41.4461
1980.35	42.4055
1981.33	38.5474
1982.31	39.4882
1983.3	43.2899
1984.28	40.3873
1985.26	40.3657
1986.24	40.3495
1987.22	39.4045
1988.21	47.0167
1989.19	38.3873
1990.17	40.4334
1991.15	43.9377
1992.13	42.8454
1993.11	39.8155
1994.09	45.548
1995.07	47.0364
1996.05	46.9968
1997.03	42.9583
1998.01	48.4851
1998.99	45.7252
1999.97	46.6007
2000.95	48.65
2001.92	48.4492
2002.9	48.5065
2003.88	47.6999
2004.86	47.1954
2005.84	45.1259
2006.81	49.6094
2007.79	48.6394
2008.77	48.9793
2009.75	48.9778
2010.73	45.2138
2011.7	48.2512
2012.68	50.1769
2013.67	47.297
2014.66	50.9748
2015.64	44.3817
2016.63	41.5824
2017.62	47.2467
2018.61	47.1819
2019.6	50.8579
2020.58	49.8977
2021.57	46.1511
2022.56	43.3276
2023.55	45.1568
2024.54	46.0515
2025.52	46.9226
2026.51	46.8825
2027.5	41.393
2028.48	45.0801
2029.47	38.6006
2030.45	43.1458
2031.44	40.3639
2032.43	39.436
2033.41	44.1579
2034.4	42.2925
2035.38	39.4265
2036.37	39.5095
2037.35	43.2366
2038.34	41.3533
2039.32	41.3261
2040.31	40.356
2041.29	36.5847
2042.27	34.7023
2043.26	40.2765
2044.24	34.7253
2045.23	34.7034
2046.21	41.3129
2047.19	36.6062
2048.17	41.2193
2049.16	34.7014
2050.14	32.8717
2051.12	37.5664
2052.11	34.7423
2053.09	39.4227
2054.07	35.7239
2055.05	40.4114
2056.03	34.7807
2057.01	35.7029
2058	38.5149
2058.98	39.4792
2059.96	35.752
2060.94	32.93
2061.92	37.6233
2062.9	36.6942
2063.88	29.2188
2064.86	33.9162
2065.84	35.8241
2066.82	32.0888
2067.8	35.8593
2068.78	35.8748
2069.76	35.8637
2070.73	31.1608
2071.71	35.8809
2072.69	34.0467
2073.67	37.8051
2074.65	31.221
2075.63	33.1441
2076.6	33.179
2077.58	34.1046
2078.56	32.2083
2079.54	33.1686
2080.51	35.0902
2081.49	33.198
2082.47	34.1413
2083.45	36.0345
2084.42	36.9756
2085.4	36.9758
2086.37	35.0958
2087.35	31.337
2088.32	29.4517
2089.3	35.1347
2090.28	30.421
2091.25	34.2197
2092.23	32.3478
2093.2	35.2357
2094.18	35.268
2095.15	39.0764
2096.13	32.4015
2097.1	36.1911
2098.07	33.3191
2099.05	27.6147
2100.02	34.2519
2101	34.2571
2101.97	33.3273
2102.94	33.3231
2103.92	32.3554
2104.89	35.2088
2105.86	33.3313
2106.83	34.2955
2107.8	31.4439
2108.78	34.2603
2109.75	34.2589
2110.72	34.2647
2111.69	37.1102
2112.66	33.2988
2113.63	34.2663
2114.61	32.3693
2115.58	32.3675
2116.55	37.101
2117.52	31.3879
2118.49	34.2219
2119.46	30.3931
2120.43	32.264
2121.4	34.1656
2122.37	33.246
2123.34	28.5176
2124.31	27.5648
2125.28	29.4233
2126.25	28.4344
2127.21	35.9736
2128.18	27.4485
2129.15	29.3329
2130.12	29.3243
2131.09	32.1487
2132.06	34.9616
2133.02	27.3896
2133.99	32.1054
2134.96	30.2182
2135.93	31.1537
2136.89	33.0086
2137.86	32.0711
2138.83	29.2302
2139.79	32.0639
2140.76	34.8616
2141.73	29.2004
2142.69	34.8315
2143.66	32.0305
2144.62	31.0256
2145.59	34.7864
2146.55	33.8384
2147.52	31.9437
2148.48	27.2304
2149.45	32.8442
2150.42	32.8044
2151.38	35.6069
2152.34	35.6228
2153.31	31.8591
2154.27	33.7152
2155.24	32.7302
2156.2	31.7507
2157.16	36.408
2158.13	32.6828
2159.09	30.8167
2160.05	32.6654
2161.01	30.7672
2161.98	30.7546
2162.94	33.5499
2163.9	32.6011
2164.86	31.6444
2165.83	34.4379
2166.79	34.4292
2167.75	32.5403
2168.71	32.4935
2169.67	32.5038
2170.63	28.8175
2171.59	36.2558
2172.56	33.4054
2173.51	32.4628
2174.48	27.8234
2175.44	31.5401
2176.4	35.2483
2177.36	33.3781
2178.32	31.5204
2179.28	35.2138
2180.23	31.5004
2181.19	28.7084
2182.15	31.4815
2183.11	32.3958
2184.07	32.3641
2185.03	33.2787
2185.99	34.2165
2186.95	28.6763
2187.9	31.4925
2188.86	32.406
2189.82	32.3701
2190.78	27.7196
2191.73	32.3603
2192.69	30.5147
2193.65	30.5312
2194.6	32.4333
2195.56	29.6403
2196.52	35.18
2197.47	30.5075
2198.43	33.2887
2199.38	33.325
2200.34	39.882
2201.3	34.3585
2202.25	27.7431
2203.21	33.3706
2204.16	30.6883
2205.12	32.4949
2206.07	33.3454
2207.03	29.6225
2207.98	33.3597
2208.93	38.0405
2209.89	31.532
2210.84	34.3341
2211.8	32.4904
2212.75	32.5104
2213.7	30.6303
2214.66	32.5097
2215.61	25.0607
2216.56	29.729
2217.51	32.5249
2218.47	31.5922
2219.42	30.6712
2220.37	32.5551
2221.32	27.8749
2222.27	30.6487
2223.23	31.5829
2224.18	32.5429
2225.13	32.5762
2226.08	30.7337
2227.03	27.9452
2227.98	27.9589
2228.93	32.6386
2229.88	31.7016
2230.83	27.9741
2231.78	31.7552
2232.73	31.779
2233.68	29.9194
2234.63	30.871
2235.58	30.8471
2236.53	32.7225
2237.48	34.6157
2238.43	32.7784
2239.38	32.8168
2240.33	30.9154
2241.27	29.9845
2242.22	27.1603
2243.17	33.7767
2244.12	30.9309
2245.07	35.6644
2246.01	29.089
2246.96	32.8917
2247.91	31.0124
2248.85	30.059
2249.8	34.7902
2250.75	30.051
2251.69	31.9175
2252.64	30.0327
2253.59	32.9163
2254.53	31.0492
2255.48	33.8957
2256.42	32.9549
2257.37	32.9767
2258.32	34.8908
2259.26	29.2021
2260.2	32.0651
2261.15	29.2259
2262.1	30.1949
2263.04	33.0656
2263.98	30.243
2264.93	31.2391
2265.87	32.2138
2266.81	29.3325
2267.76	30.2624
2268.7	24.5218
2269.65	28.3529
2270.59	29.3424
2271.53	32.2305
2272.47	30.3343
2273.42	28.4249
2274.36	31.301
2275.3	32.2643
2276.24	31.3132
2277.18	33.2577
2278.13	36.1801
2279.07	31.4009
2280.01	35.2158
2280.95	24.6325
2281.89	32.287
2282.83	31.3439
2283.77	28.4986
2284.71	27.5822
2285.65	32.4107
2286.59	31.4284
2287.54	31.4619
2288.47	37.2556
2289.41	38.1878
2290.35	33.3308
2291.29	35.2551
2292.23	34.327
2293.17	37.2444
2294.11	31.4788
2295.05	32.424
2295.99	32.4045
2296.93	30.4526
2297.86	28.5454
2298.8	35.3183
2299.74	33.4183
2300.68	29.5608
2301.61	34.4012
2302.55	31.5035
2303.49	30.5334
2304.43	28.6098
2305.36	29.5919
2306.3	28.6354
2307.24	35.4051
2308.17	33.4598
2309.11	35.3865
2310.04	35.417
2310.98	34.4596
2311.92	31.5069
2312.85	35.3362
2313.79	33.4142
2314.72	33.4563
2315.66	31.5416
2316.59	37.2961
2317.52	35.3487
2318.46	35.3533
2319.39	38.2255
2320.33	38.2117
2321.26	38.2208
2322.2	46.9472
2323.13	46.9759
2324.06	55.6893
2325	65.3383
2325.93	99.0625
2326.86	301.594
2327.79	831.587
2328.73	239.599
2329.66	90.1418
2330.59	56.4222
2331.52	43.8931
2332.46	41.9775
2333.39	34.2479
2334.32	35.1926
2335.25	38.0521
2336.18	36.1279
2337.11	36.1175
2338.04	37.0696
2338.97	32.2552
2339.91	34.177
2340.84	32.2354
2341.77	36.0329
2342.7	34.0853
2343.63	33.1189
2344.56	35.0345
2345.49	33.1103
2346.41	29.2514
2347.34	31.157
2348.27	30.1975
2349.2	31.1567
2350.13	33.9759
2351.06	31.9091
2351.99	32.0363
2352.91	36.756
2353.84	35.7482
2354.77	30.0319
2355.7	35.7485
2356.63	29.057
2357.55	33.774
2358.48	34.7038
2359.41	34.686
2360.33	35.6141
2361.26	34.6307
2362.19	29.8561
2363.11	32.6652
2364.04	33.5912
2364.97	27.8968