File: Data/3-Raman/raw/bu19w-ff07b-fi03-v_150 (500nm)_532nm_edge_100%_x100_vis_lwd_h50um_15sx2_01.txt
#Acq. time (s)=	15
#Accumulations=	2
#Range (cm-¹)=	50...5000
#Windows=	1
#Auto scanning=	Off
#Autofocus=	Off
#Macrospot=	Off
#AutoExposure=	Off
#Spike filter=	Multiple accum.
#Delay time (s)=	2
#Binning=	1
#Readout mode=	Signal
#DeNoise=	Off
#ICS correction=	On
#Dark correction=	Off
#Inst. Process=	Off
#Detector Gain=	Best Dynamic
#Detector ADC=	50 kHz HS
#Detector temperature (°C)=	-60.09
#Instrument=	LabRAM HR Evol
#Detector=	SIN-EM FIVIS
#Objective=	x100_VIS_LWD
#Grating=	150 (500nm)
#ND Filter=	100%
#Laser=	532nm_Edge
#Hole=	49.98
#Temperature=	0
#Range=	Visible
#StageXY=	75x50mm Scan+
#StageZ=	Z motor
#X (µm)=	0
#Y (µm)=	0
#Z (µm)=	-48.6
#Full time(s)=	34
#Project=	21_05_28
#Sample=	BU19w
#Site=
#Title=	BU19w-FF07b-FI03-V_150 (500nm)_532nm_Edge_100%_x100_VIS_LWD_H50um_15sX2
#Remark=
#Date=	28.05.2021 15:47
#Acquired=	28.05.2021 15:47:30
51.5961	14701.3
56.2453	12886.5
60.8921	10510.3
65.5367	9204.22
70.1768	12051.9
74.8167	10741.4
79.4543	5465.45
84.0897	3636.38
88.7227	2931.63
93.3513	2492.02
97.9798	2216.42
102.606	2008.5
107.23	1882.03
111.851	1822.37
116.469	1842.48
121.086	1729.5
125.7	1577.4
130.313	1519.14
134.921	1494.8
139.529	1487.95
144.134	1470.26
148.738	1480.84
153.337	1377.4
157.936	1376.22
162.532	1464.71
167.126	2002.62
171.716	2854.74
176.306	2380.39
180.894	1652.14
185.477	1615.32
190.06	1985.93
194.64	3951.7
199.219	6974.48
203.793	4777.4
208.367	2384.54
212.939	1644.42
217.506	1438.87
222.073	1466.92
226.638	1453.23
231.199	1470.99
235.759	1438.53
240.318	1617.15
244.872	1902.61
249.425	1992.41
253.977	2472.8
258.524	2976.62
263.071	2637.14
267.616	2233.99
272.156	1926.24
276.697	1910.11
281.233	2541.53
285.769	4401.13
290.303	6476.19
294.832	5252.06
299.361	3176.95
303.886	2447.36
308.411	2749.65
312.934	3748.83
317.452	3627.07
321.97	2598.38
326.484	2030.62
330.998	1999.83
335.507	2420.6
340.017	3032.27
344.524	2805.71
349.027	2172.78
353.53	2050.46
358.028	2330.9
362.527	2555.29
367.021	2180.43
371.515	1815.4
376.004	1696.76
380.494	1821.32
384.979	1780.83
389.465	1696.78
393.946	1899.84
398.427	2175.24
402.903	2354.54
407.38	2280.9
411.852	2014.54
416.324	1788.58
420.792	1666.83
425.26	1916.53
429.723	2099.78
434.187	1744.58
438.646	1473.05
443.105	1451.21
447.56	1446.52
452.015	1447.55
456.466	1549.41
460.914	2021.97
465.362	2802.01
469.807	2780.79
474.251	2021.98
478.69	1632.11
483.13	1579.02
487.566	1558.79
491.999	1632.3
496.432	1770.03
500.861	1920.58
505.29	2094.2
509.715	2065.84
514.138	1994.71
518.56	1786.09
522.979	1684.46
527.395	1613.29
531.811	1596.76
536.223	1564.34
540.635	1581.74
545.042	1618.78
549.448	1660.6
553.853	1674.37
558.255	1689.49
562.654	1673.87
567.053	1692.36
571.448	1730.58
575.841	1692.47
580.232	1632.19
584.622	1580.25
589.009	1651.42
593.393	1960.26
597.777	2825.06
602.157	3261.7
606.535	2582.96
610.913	2060.14
615.287	2034.53
619.659	2451.04
624.029	2795.49
628.398	2386.55
632.763	1903.03
637.127	1656.29
641.488	1605.64
645.849	1673.33
650.206	1727.83
654.561	1727.67
658.914	1674.91
663.267	1653.04
667.615	1717.99
671.962	1886.27
676.307	2073.25
680.649	2061.24
684.991	2120.54
689.33	2288.63
693.666	1985.17
698	1793.63
702.332	1613.95
706.662	1535.36
710.992	1518.36
715.318	1492.99
719.641	1465.06
723.963	1480.33
728.283	1453.22
732.6	1487.7
736.918	1430.8
741.231	1470.63
745.542	1504.15
749.852	1532.35
754.159	1503.13
758.464	1565.88
762.767	1594.59
767.068	1634.51
771.369	1758.25
775.666	1905.43
779.961	2227.59
784.254	2801.23
788.545	3578.34
792.834	3433.2
797.12	2741.1
801.405	2189.89
805.688	1930.49
809.968	1767.61
814.247	1698.49
818.524	1623.03
822.798	1590.43
827.071	1568.16
831.341	1557.02
835.612	1567.94
839.878	1511.48
844.142	1571.73
848.405	1551.98
852.665	1550.07
856.923	1602.18
861.18	1524.19
865.434	1552.8
869.686	1545.65
873.936	1566.72
878.185	1554.44
882.431	1545.12
886.675	1541.74
890.915	1561.41
895.155	1501.09
899.393	1540.2
903.63	1569.63
907.864	1539.39
912.096	1557.16
916.326	1566.08
920.554	1586.52
924.78	1565.32
929.004	1592.8
933.227	1588.82
937.447	1607.2
941.665	1628.29
945.881	1618.09
950.095	1714.59
954.305	1824.04
958.516	1902.52
962.724	1988.5
966.93	1958.75
971.134	2005.7
975.337	2077.37
979.537	2137.55
983.735	2023.34
987.93	1854.14
992.124	1847.15
996.316	1774.82
1000.51	1701.4
1004.7	1723.66
1008.88	1734.56
1013.06	1744.46
1017.25	1751.8
1021.43	1760.19
1025.61	1753.25
1029.78	1757.4
1033.96	1796.21
1038.13	1851.29
1042.3	1893.39
1046.47	1986.34
1050.63	2136.73
1054.8	2472.6
1058.96	3253.58
1063.12	4205.77
1067.28	4005.11
1071.44	3176.09
1075.59	2634.1
1079.74	2395.43
1083.89	2373.53
1088.04	2572.36
1092.19	2934.43
1096.33	3670.71
1100.48	4356.33
1104.62	4201.92
1108.76	3620.87
1112.89	3272.97
1117.03	3388.29
1121.16	3716.21
1125.29	3589.18
1129.42	3390.58
1133.55	3320.26
1137.68	3497.98
1141.8	3737.67
1145.92	3536.38
1150.04	3211.75
1154.16	2753.46
1158.27	2712.41
1162.39	2940.07
1166.5	3402.1
1170.61	3574.16
1174.72	3099.44
1178.82	2709.38
1182.93	2448.56
1187.03	2202.94
1191.13	2097.36
1195.23	2003.82
1199.33	1950.9
1203.42	1988.35
1207.51	1990.91
1211.6	2011.75
1215.69	1955.82
1219.78	1984.99
1223.86	1948.98
1227.95	2032.88
1232.03	2145.23
1236.11	2230.93
1240.18	2158.88
1244.26	2178.33
1248.33	2330.37
1252.41	2498.63
1256.48	2315.95
1260.54	2137.46
1264.61	2068.08
1268.67	1944.93
1272.74	1900
1276.8	1902.14
1280.86	2430.61
1284.91	2752.6
1288.97	1918.43
1293.02	1806.84
1297.07	1831.86
1301.12	1822.46
1305.17	1837.9
1309.21	1816.92
1313.25	1794.73
1317.3	1834.36
1321.34	1786.96
1325.37	1817.42
1329.41	1730.02
1333.44	1824.28
1337.48	1800.43
1341.5	1849.38
1345.53	1794.09
1349.56	1806.74
1353.59	1796.5
1357.61	1828.09
1361.63	1765.23
1365.65	1843.45
1369.66	1870.33
1373.68	1822.56
1377.69	1834.34
1381.7	2000.1
1385.72	3289.9
1389.72	2804.71
1393.73	1960.2
1397.73	1819.23
1401.74	1842.5
1405.74	1955.39
1409.73	1941.4
1413.73	1849.67
1417.73	1841.75
1421.72	1835.77
1425.71	1814.72
1429.7	1762.14
1433.69	1824.26
1437.67	1853.75
1441.66	1800.33
1445.64	1844.37
1449.62	1835.97
1453.6	1863.76
1457.57	1847.96
1461.55	1814.1
1465.52	1829.92
1469.49	1863.28
1473.46	1866.39
1477.43	1843.74
1481.39	1872.82
1485.36	1812.66
1489.32	1804.32
1493.28	1830.29
1497.24	1801.65
1501.19	1812.22
1505.15	1837.67
1509.1	1853.88
1513.05	1817.75
1517	1819.62
1520.95	1838.18
1524.9	1831.64
1528.84	1806.82
1532.78	1858.82
1536.72	1843.01
1540.66	1872.81
1544.6	1882.25
1548.53	1862.65
1552.46	1872.1
1556.4	1880.36
1560.32	1811.84
1564.25	1856.39
1568.18	1878.46
1572.1	1879.1
1576.02	1859.43
1579.94	1858.05
1583.86	1875.9
1587.78	1845.41
1591.69	1886.16
1595.61	1888.33
1599.52	1863.59
1603.43	1904.34
1607.34	1871.45
1611.24	1914.4
1615.15	1880.77
1619.05	1905.87
1622.95	1908.81
1626.85	1922.58
1630.74	1900.23
1634.64	1918.7
1638.53	1922.72
1642.42	1912.88
1646.31	1923.56
1650.2	1944.03
1654.09	1908.97
1657.97	1952.43
1661.86	1916.13
1665.74	1916.89
1669.62	1956.87
1673.49	1941.44
1677.37	1934.55
1681.24	1966
1685.12	1919.16
1688.99	1922.1
1692.86	1929.43
1696.72	1965.15
1700.59	1925.94
1704.45	1917.91
1708.31	1932.34
1712.17	1970.04
1716.03	1924.21
1719.89	1922.15
1723.74	2012.64
1727.6	1944.36
1731.45	1926.8
1735.3	1961.04
1739.14	1981.8
1742.99	1982.62
1746.83	1999.38
1750.68	1943.87
1754.52	1972.77
1758.36	1926.69
1762.19	1948.8
1766.03	2002
1769.86	1961.27
1773.69	2021.85
1777.53	1986.75
1781.35	2010.02
1785.18	1981.42
1789	1964.17
1792.83	2006.91
1796.65	1976.64
1800.47	1991.3
1804.29	1995.29
1808.1	2005.73
1811.92	1983.89
1815.73	2018.27
1819.54	2017.82
1823.35	1965.89
1827.16	2010.77
1830.97	2000.37
1834.77	2026.21
1838.58	1987.66
1842.38	1996.83
1846.18	2004.56
1849.97	1997.52
1853.77	2015.78
1857.56	2046.54
1861.36	2022.42
1865.15	2040.06
1868.93	1989.12
1872.72	2068.33
1876.51	2041.3
1880.29	2056.05
1884.07	2080.86
1887.86	2041.24
1891.63	2063.87
1895.41	2066.29
1899.19	2067.8
1902.96	2035.24
1906.73	2054.62
1910.5	2041.06
1914.27	2029.16
1918.04	2047.83
1921.8	2014.26
1925.57	2042.81
1929.33	2030.07
1933.09	2075.13
1936.85	2057.87
1940.6	2065.68
1944.36	2049.14
1948.11	2062.51
1951.87	2067.72
1955.61	2103.08
1959.36	2081.02
1963.11	2097.7
1966.86	2077.65
1970.6	2065.38
1974.34	2073
1978.08	2066.12
1981.82	2137.5
1985.56	2067.23
1989.29	2108.88
1993.02	2082.05
1996.75	2093.02
2000.49	2082.2
2004.21	2104.86
2007.94	2095.76
2011.67	2083.44
2015.39	2075.84
2019.11	2117.01
2022.83	2139.93
2026.55	2115.56
2030.27	2100.47
2033.98	2178.86
2037.69	2131.67
2041.41	2117.24
2045.12	2164.89
2048.82	2135.68
2052.53	2082.16
2056.24	2094.69
2059.94	2123
2063.64	2169.22
2067.34	2168.29
2071.04	2140.82
2074.74	2143.73
2078.43	2125.54
2082.13	2106.51
2085.82	2141.89
2089.51	2134.86
2093.2	2093.41
2096.88	2118.94
2100.57	2121.78
2104.25	2149.95
2107.94	2174.95
2111.62	2212.62
2115.3	2157.24
2118.97	2171.31
2122.65	2157.56
2126.32	2214.8
2129.99	2167.79
2133.66	2199.34
2137.33	2168.75
2141	2197.85
2144.67	2231.12
2148.33	2181.35
2151.99	2181.29
2155.66	2203.32
2159.31	2162.2
2162.97	2198.25
2166.63	2210.81
2170.28	2176.33
2173.94	2221.17
2177.59	2265.53
2181.24	2202.77
2184.89	2232.75
2188.53	2245.12
2192.18	2200.15
2195.82	2216.13
2199.46	2243.56
2203.1	2228.43
2206.74	2277.54
2210.38	2264.99
2214.01	2258.22
2217.65	2236.87
2221.28	2228.37
2224.91	2232.83
2228.54	2222.42
2232.16	2248.01
2235.79	2240.6
2239.41	2284.01
2243.04	2288.56
2246.66	2275.39
2250.28	2276.23
2253.89	2268.95
2257.51	2286.1
2261.12	2272.41
2264.74	2247.16
2268.35	2269.9
2271.96	2264.09
2275.57	2220.91
2279.17	2259.02
2282.78	2287.21
2286.38	2268.17
2289.98	2287.83
2293.58	2212.61
2297.18	2232.96
2300.78	2313.07
2304.37	2273.5
2307.97	2289.33
2311.56	2261.23
2315.15	2238.47
2318.74	2300.62
2322.33	2279.8
2325.91	2384.41
2329.5	2447.92
2333.08	2309.86
2336.66	2346.28
2340.24	2297.54
2343.82	2320.15
2347.4	2256.06
2350.97	2286.62
2354.54	2264.61
2358.12	2321.84
2361.69	2267.88
2365.26	2341.4
2368.82	2292.36
2372.39	2337.59
2375.95	2330.71
2379.52	2322.98
2383.08	2307.29
2386.64	2251.39
2390.19	2365.99
2393.75	2335.79
2397.31	2323.79
2400.86	2312.58
2404.41	2331.98
2407.96	2310.43
2411.51	2337.54
2415.06	2285.38
2418.6	2368.77
2422.15	2345.99
2425.69	2313.56
2429.23	2367.47
2432.77	2348.98
2436.31	2278.08
2439.84	2321.38
2443.38	2368.79
2446.91	2319.38
2450.44	2346.95
2453.97	2289.67
2457.5	2353.8
2461.03	2357.7
2464.55	2312.35
2468.08	2356.47
2471.6	2337.42
2475.12	2359.75
2478.64	2330.77
2482.16	2372.9
2485.67	2324.61
2489.19	2335.17
2492.7	2358.25
2496.21	2349.93
2499.72	2327.47
2503.23	2352.93
2506.74	2397.53
2510.25	2351.02
2513.75	2368.11
2517.25	2400.58
2520.75	2394.42
2524.25	2383.83
2527.75	2382.14
2531.25	2392.14
2534.74	2346.17
2538.24	2371.08
2541.73	2414.98
2545.22	2330.84
2548.71	2381.54
2552.2	2356.64
2555.68	2388.78
2559.17	2400.85
2562.65	2364.74
2566.13	2395.57
2569.61	2397.45
2573.09	2411.18
2576.57	2380.46
2580.04	2390.42
2583.51	2374.19
2586.99	2387.15
2590.46	2349.29
2593.93	2374.66
2597.4	2408.31
2600.86	2370.23
2604.33	2431.31
2607.79	2342.56
2611.25	2379.27
2614.71	2359.64
2618.17	2343.76
2621.63	2397.99
2625.09	2420.04
2628.54	2363.62
2631.99	2388.45
2635.45	2357.02
2638.9	2402.57
2642.34	2392.06
2645.79	2437.5
2649.24	2419.64
2652.68	2346.94
2656.12	2420.38
2659.56	2378.16
2663.01	2424.88
2666.44	2386.11
2669.88	2349.35
2673.32	2434.88
2676.75	2407.82
2680.18	2340.04
2683.61	2380.51
2687.04	2387.17
2690.47	2352.48
2693.9	2436.07
2697.32	2372.87
2700.75	2404.28
2704.17	2445.04
2707.59	2419.85
2711.01	2333.12
2714.43	2338
2717.84	2414.13
2721.26	2365.02
2724.67	2401.96
2728.08	2389.67
2731.49	2384.97
2734.9	2396.04
2738.31	2422.13
2741.71	2424.7
2745.12	2414.59
2748.52	2416.33
2751.92	2379.55
2755.32	2381.09
2758.72	2350.35
2762.12	2411.93
2765.52	2398.49
2768.91	2385.6
2772.3	2394.93
2775.7	2418.18
2779.09	2388.25
2782.47	2351.42
2785.86	2395.37
2789.25	2338.56
2792.63	2408.61
2796.01	2355.45
2799.4	2352.1
2802.78	2369.02
2806.15	2387.8
2809.53	2414.93
2812.91	2416.61
2816.28	2383.54
2819.65	2397.2
2823.03	2417.74
2826.4	2338.78
2829.76	2404.58
2833.13	2423.12
2836.5	2388.07
2839.86	2398.16
2843.22	2364
2846.59	2357.41
2849.95	2383.39
2853.3	2396.88
2856.66	2362.47
2860.02	2402.2
2863.37	2386.12
2866.72	2404.79
2870.08	2400.05
2873.43	2356.63
2876.77	2352.53
2880.12	2344.59
2883.47	2381.78
2886.81	2351.88
2890.15	2409.67
2893.5	2328.52
2896.84	2353.51
2900.17	2317.67
2903.51	2387.39
2906.85	2350.86
2910.18	2340.62
2913.52	2360.49
2916.85	2365.05
2920.18	2369.25
2923.51	2357.24
2926.83	2353.52
2930.16	2329.63
2933.48	2385.76
2936.81	2396.15
2940.13	2373.53
2943.45	2394.29
2946.77	2393.44
2950.09	2362.56
2953.4	2355.14
2956.72	2344.99
2960.03	2335.24
2963.34	2323.83
2966.65	2349.15
2969.96	2338.6
2973.27	2381.92
2976.58	2391.58
2979.88	2336.89
2983.19	2358.86
2986.49	2348.13
2989.79	2315
2993.09	2351.43
2996.39	2332.57
2999.68	2293.15
3002.98	2334.53
3006.27	2290.35
3009.57	2287.72
3012.86	2286.16
3016.15	2295
3019.43	2288.71
3022.72	2341.8
3026.01	2307.19
3029.29	2241.41
3032.57	2283.22
3035.86	2257.84
3039.14	2257.91
3042.41	2239.08
3045.69	2274.23
3048.97	2253.55
3052.24	2241.38
3055.52	2271.91
3058.79	2244.53
3062.06	2229.69
3065.33	2247.43
3068.6	2297.17
3071.86	2266.71
3075.13	2276.97
3078.39	2233.59
3081.65	2219.83
3084.91	2239.26
3088.17	2259.56
3091.43	2238.7
3094.69	2223.65
3097.95	2239.02
3101.2	2205.43
3104.45	2231.32
3107.7	2163.12
3110.95	2201.15
3114.2	2232.79
3117.45	2202.74
3120.7	2222.26
3123.94	2216.07
3127.18	2228.89
3130.43	2225.45
3133.67	2205.84
3136.91	2186.16
3140.14	2206.4
3143.38	2217.07
3146.61	2202.02
3149.85	2182.33
3153.08	2208.47
3156.31	2168.7
3159.54	2191.94
3162.77	2181.72
3166	2154.33
3169.22	2162.99
3172.45	2159.09
3175.67	2182.78
3178.89	2219.63
3182.11	2162
3185.33	2165.48
3188.55	2144.87
3191.77	2182.35
3194.98	2159.78
3198.2	2161
3201.41	2187.88
3204.62	2159.62
3207.83	2162.87
3211.04	2189.05
3214.25	2105
3217.45	2136.24
3220.66	2162.71
3223.86	2119.82
3227.06	2155.15
3230.26	2133.44
3233.46	2159.47
3236.66	2100.67
3239.85	2090.85
3243.05	2179.23
3246.24	2110.6
3249.44	2123.88
3252.63	2166.95
3255.82	2167.19
3259.01	2146.38
3262.19	2126.19
3265.38	2107.61
3268.56	2139.34
3271.75	2150.81
3274.93	2129.67
3278.11	2121.87
3281.29	2093.58
3284.47	2116.47
3287.64	2090.73
3290.82	2079.14
3293.99	2120.15
3297.17	2082.92
3300.34	2108.61
3303.51	2112.87
3306.68	2097.55
3309.84	2162.87
3313.01	2089.98
3316.18	2134.82
3319.34	2139.68
3322.5	2095.17
3325.66	2118.94
3328.82	2080.24
3331.98	2067.18
3335.14	2084.51
3338.29	2081.23
3341.45	2114.9
3344.6	2142.93
3347.75	2130.94
3350.9	2098.73
3354.05	2108.91
3357.2	2105.2
3360.35	2133.65
3363.49	2102.96
3366.64	2064.76
3369.78	2082.31
3372.92	2143.37
3376.06	2124.49
3379.2	2129.29
3382.34	2118.14
3385.48	2102.15
3388.61	2091.05
3391.75	2130.13
3394.88	2182.41
3398.01	2205.76
3401.14	2182.02
3404.27	2230.55
3407.4	2231.88
3410.52	2328.44
3413.65	2503.2
3416.77	2746.28
3419.89	3286.08
3423.01	4586.72
3426.13	8124.23
3429.25	12641.4
3432.37	11253.7
3435.49	6419.58
3438.6	3887.21
3441.72	3022.83
3444.83	2600.46
3447.94	2366.68
3451.05	2315.1
3454.16	2234.67
3457.26	2232.34
3460.37	2148.83
3463.47	2093.93
3466.58	2167.24
3469.68	2115.78
3472.78	2095.33
3475.88	2104.93
3478.98	2140.17
3482.07	2165.06
3485.17	2203.2
3488.26	2252.77
3491.36	2363.04
3494.45	2467.27
3497.54	2648.72
3500.63	2919.49
3503.72	3304.25
3506.81	3821.06
3509.89	4304.38
3512.98	4624.81
3516.06	4223.24
3519.14	3732.09
3522.22	3255.37
3525.3	2830.91
3528.38	2556.9
3531.45	2462.62
3534.53	2279.92
3537.61	2173.56
3540.68	2154.28
3543.75	2044.36
3546.82	2057.74
3549.89	1991.33
3552.96	2032.12
3556.03	1984.8
3559.09	1942.5
3562.16	1964.55
3565.22	1939.79
3568.28	1912.83
3571.34	1962.31
3574.4	1887.59
3577.46	1885.98
3580.52	1895.59
3583.57	1873.74
3586.63	1887.76
3589.68	1894.18
3592.73	1866.23
3595.78	1877.1
3598.83	1854.63
3601.88	1853.96
3604.93	1882.43
3607.97	1822.75
3611.02	1852.94
3614.06	1848.03
3617.1	1859.11
3620.14	1825.9
3623.18	1869.22
3626.22	1810.72
3629.26	1834.39
3632.3	1835.32
3635.33	1807.91
3638.36	1870.38
3641.4	1798.52
3644.43	1782.39
3647.46	1852.36
3650.49	1840.9
3653.51	1801.47
3656.54	1740.05
3659.57	1769.99
3662.59	1762.15
3665.61	1792.6
3668.63	1817.54
3671.65	1811.8
3674.67	1760.87
3677.69	1769.45
3680.71	1768.69
3683.72	1739.48
3686.74	1799.15
3689.75	1731.21
3692.76	1734.24
3695.77	1773.31
3698.78	1726.74
3701.79	1748.8
3704.79	1765.2
3707.8	1710.35
3710.81	1766.43
3713.81	1740.66
3716.81	1742.23
3719.81	1729.65
3722.81	1727.31
3725.81	1717.21
3728.81	1726.95
3731.8	1747.04
3734.8	1779.34
3737.79	1724.78
3740.78	1756.72
3743.77	1674.24
3746.76	1715.33
3749.75	1715.33
3752.74	1685.75
3755.73	1688.47
3758.71	1742.46
3761.7	1679.7
3764.68	1708.8
3767.66	1691.5
3770.64	1697.06
3773.62	1725.48
3776.6	1653.79
3779.58	1739.12
3782.55	1696.98
3785.53	1665.28
3788.5	1679.95
3791.47	1697.55
3794.44	1705.04
3797.41	1631.49
3800.38	1704.35
3803.35	1668.88
3806.32	1682.59
3809.28	1691.64
3812.24	1680.01
3815.21	1686.37
3818.17	1690.89
3821.13	1694.54
3824.09	1639.53
3827.04	1667.95
3830	1675.57
3832.96	1649.04
3835.91	1635.92
3838.86	1623.82
3841.82	1635.47
3844.77	1675.66
3847.72	1691.2
3850.67	1663.95
3853.61	1626.27
3856.56	1672.55
3859.5	1634.86
3862.45	1618.16
3865.39	1640.56
3868.33	1610.33
3871.27	1617.29
3874.21	1638.6
3877.15	1628.19
3880.09	1641.6
3883.02	1618.33
3885.96	1625.6
3888.89	1653.9
3891.82	1635.04
3894.75	1643.97
3897.68	1619.99
3900.61	1619.87
3903.54	1612.97
3906.47	1593.37
3909.39	1585.51
3912.31	1585.19
3915.24	1639.47
3918.16	1595.65
3921.08	1630.88
3924	1598.57
3926.92	1640.93
3929.83	1618.86
3932.75	1584.29
3935.67	1604.72
3938.58	1603.45
3941.49	1568.95
3944.4	1597.51
3947.31	1582.11
3950.22	1583.14
3953.13	1582.38
3956.04	1621.91
3958.94	1558.14
3961.85	1548.07
3964.75	1591.75
3967.65	1543.5
3970.55	1567.23
3973.45	1554.56
3976.35	1543.76
3979.25	1551.11
3982.15	1539.13
3985.04	1540.57
3987.94	1555.41
3990.83	1573.08
3993.72	1524.19
3996.61	1585.27
3999.5	1544.32
4002.39	1570.83
4005.28	1527.07
4008.16	1509.37
4011.05	1550.48
4013.93	1523.12
4016.81	1571.01
4019.7	1527.25
4022.58	1502.76
4025.46	1516.89
4028.33	1497.24
4031.21	1546.22
4034.09	1537.25
4036.96	1539.91
4039.84	1521.34
4042.71	1500.77
4045.58	1505.11
4048.45	1500.81
4051.32	1519.87
4054.19	1484.69
4057.05	1507.87
4059.92	1520.32
4062.78	1498.73
4065.65	1498.5
4068.51	1463.26
4071.37	1446.44
4074.23	1492.88
4077.09	1491.6
4079.95	1478.61
4082.81	1491.93
4085.66	1507.22
4088.52	1509.76
4091.37	1452.77
4094.22	1478.83
4097.07	1503.82
4099.92	1492.75
4102.77	1447.42
4105.62	1461.67
4108.47	1529.54
4111.31	1485.93
4114.16	1464.62
4117	1489.17
4119.84	1432.27
4122.69	1444.88
4125.53	1412.64
4128.36	1416.65
4131.2	1432.8
4134.04	1452.11
4136.88	1460.14
4139.71	1469.26
4142.54	1421.29
4145.38	1420.2
4148.21	1472.53
4151.04	1411.45
4153.87	1434.22
4156.69	1462.35
4159.52	1401.76
4162.35	1420.97
4165.17	1415.92
4168	1444.09
4170.82	1426.36
4173.64	1393.07
4176.46	1430.23
4179.28	1408.72
4182.1	1439.15
4184.91	1412.91
4187.73	1397.51
4190.54	1426.17
4193.36	1410.04
4196.17	1417.55
4198.98	1411.56
4201.79	1415.31
4204.6	1428.94
4207.41	1401.3
4210.22	1436.52
4213.02	1404.89
4215.83	1446.97
4218.63	1414.18
4221.44	1416.71
4224.24	1364.86
4227.04	1372.95
4229.84	1375.37
4232.64	1384.77
4235.43	1383.47
4238.23	1350.51
4241.02	1413.83
4243.82	1367.96
4246.61	1358.9
4249.4	1379.65
4252.19	1373.36
4254.98	1326.03
4257.77	1354.51
4260.56	1359
4263.35	1352.53
4266.13	1355.13
4268.92	1361.86
4271.7	1367.57
4274.48	1362.17
4277.26	1339.32
4280.04	1351.58
4282.82	1390.04
4285.6	1323.23
4288.38	1320.93
4291.15	1340.75
4293.93	1339.25
4296.7	1322.75
4299.47	1301.27
4302.25	1258.33
4305.02	1280.29
4307.79	1308.36
4310.55	1287.76
4313.32	1318.08
4316.09	1309.58
4318.85	1298.9
4321.62	1304.41
4324.38	1302.69
4327.14	1243.87
4329.9	1289.99
4332.66	1302.36
4335.42	1247.57
4338.18	1312.87
4340.94	1275.51
4343.69	1275.85
4346.45	1256.96
4349.2	1265.71
4351.95	1309.19
4354.7	1295.87
4357.45	1265
4360.2	1278.08
4362.95	1234.81
4365.7	1282.75
4368.44	1251.74
4371.19	1240.3
4373.93	1244
4376.68	1251.78
4379.42	1236.87
4382.16	1254.79
4384.9	1247.12
4387.64	1261.32
4390.37	1234.86
4393.11	1203.4
4395.85	1233.72
4398.58	1248.72
4401.31	1190.19
4404.05	1194.62
4406.78	1243.76
4409.51	1216.18
4412.24	1171.74
4414.96	1212.42
4417.69	1212.47
4420.42	1221.39
4423.14	1222.23
4425.87	1204.34
4428.59	1198.97
4431.31	1208.23
4434.03	1212.25
4436.75	1191.08
4439.47	1207.54
4442.19	1208.17
4444.91	1178.42
4447.62	1161.15
4450.34	1174.31
4453.05	1182.13
4455.76	1190.99
4458.47	1195.53
4461.19	1188.46
4463.89	1172.08
4466.6	1160.91
4469.31	1146.65
4472.02	1153.5
4474.72	1137.27
4477.43	1160.13
4480.13	1183.12
4482.83	1144.98
4485.53	1136.36
4488.23	1167.8
4490.93	1164.33
4493.63	1167.98
4496.33	1125.91
4499.02	1132.74
4501.72	1144.82
4504.41	1134.55
4507.11	1145.59
4509.8	1125.92
4512.49	1130.64
4515.18	1151.32
4517.87	1157.18
4520.56	1113.15
4523.24	1144.69
4525.93	1149.66
4528.61	1124.8
4531.3	1103.15
4533.98	1100.68
4536.66	1128.12
4539.34	1112.94
4542.02	1055.07
4544.7	1082.63
4547.38	1104.92
4550.05	1089.78
4552.73	1104.74
4555.4	1089.87
4558.08	1089.1
4560.75	1087.58
4563.42	1072.23
4566.09	1078.77
4568.76	1081.3
4571.43	1060.38
4574.1	1074.05
4576.77	1073.17
4579.43	1072.81
4582.1	1060.95
4584.76	1031.83
4587.42	1065.26
4590.08	1060.5
4592.74	1041.44
4595.4	1040.99
4598.06	1060.33
4600.72	1027.12
4603.38	1020.31
4606.03	1066.13
4608.69	1038.6
4611.34	1029.7
4613.99	994.375
4616.64	1045.81
4619.29	1001.68
4621.94	1024.7
4624.59	1031.19
4627.24	1005.61
4629.89	1038.46
4632.53	1054.76
4635.18	1049.91
4637.82	1002.94
4640.46	1006.82
4643.1	991.896
4645.74	1011.55
4648.38	988.228
4651.02	985.097
4653.66	1003.48
4656.3	994.712
4658.93	980.405
4661.57	1015.9
4664.2	992.438
4666.83	985.559
4669.46	1016.48
4672.09	1010.58
4674.72	985.6
4677.35	989.729
4679.98	951.194
4682.61	988.952
4685.23	993.047
4687.86	990.399
4690.48	952.869
4693.1	958.102
4695.73	963.259
4698.34	972.92
4700.96	960.041
4703.58	929.039
4706.2	954.424
4708.82	916.484
4711.43	936.167
4714.05	934.351
4716.66	952.876
4719.28	984.964
4721.89	933.184
4724.5	945.937
4727.11	935.015
4729.72	943.43
4732.33	935.969
4734.93	944.405
4737.54	945.991
4740.14	924.787
4742.75	922.863
4745.35	929.965
4747.95	919.934
4750.55	902.941
4753.15	916.7
4755.75	920.201
4758.35	930.526
4760.95	923.867
4763.54	922.966
4766.14	864.026
4768.73	892.996
4771.33	896.981
4773.92	935.012
4776.51	913.738
4779.1	910.723
4781.69	903.121
4784.28	888.665
4786.87	883.353
4789.45	889.482
4792.04	919.688
4794.63	850.329
4797.21	892.076
4799.79	874.341
4802.37	850.901
4804.95	878.03
4807.53	874.281
4810.11	899.361
4812.69	847.299
4815.27	901.275
4817.84	866.533
4820.42	865.299
4822.99	881.419
4825.57	873.26
4828.14	884.788
4830.71	852.21
4833.28	849.882
4835.85	847.582
4838.42	864.051
4840.98	857.275
4843.55	846.927
4846.12	871.566
4848.68	846.876
4851.24	820.69
4853.81	857.388
4856.37	857.817
4858.93	839.066
4861.49	852.046
4864.05	798.7
4866.61	799.325
4869.16	834.3
4871.72	845.85
4874.27	803.902
4876.83	809.224
4879.38	795.566
4881.93	819.832
4884.49	814.377
4887.04	832.683
4889.58	823.674
4892.13	834.891
4894.68	819.888
4897.23	817.948
4899.77	814.788
4902.32	821.148
4904.86	811.993
4907.4	796.821
4909.95	784
4912.49	830.714
4915.03	818.846
4917.57	806.895
4920.1	803.397
4922.64	764.051
4925.18	799.985
4927.71	777.426
4930.25	795.396
4932.78	778.918
4935.31	786.499
4937.84	776.044
4940.38	787.118
4942.9	796.644
4945.43	774.142
4947.96	793.68
4950.49	789.234
4953.01	746.48
4955.54	769.571
4958.06	803.632
4960.59	772.939
4963.11	754.298
4965.63	755.089
4968.15	766.868
4970.67	766.385
4973.19	757.417
4975.71	725.458
4978.22	735.746
4980.74	763.032
4983.25	752.825
4985.77	762.025
4988.28	749.416
4990.79	719.79
4993.3	694.938
4995.81	710.186
4998.32	741.428