File: Data/3-Raman/raw/bu19w-e-ff11-fi10-v_150 (500nm)_633nm_edge_100%_x100_vis_h50um_60sx2_01.txt
#Acq. time (s)=	60
#Accumulations=	2
#Range (cm-¹)=	100...4000
#Windows=	1
#Auto scanning=	Off
#Autofocus=	Off
#Macrospot=	Off
#AutoExposure=	Off
#Spike filter=	Multiple accum.
#Delay time (s)=	2
#Binning=	1
#Readout mode=	Signal
#DeNoise=	Off
#ICS correction=	On
#Dark correction=	Off
#Inst. Process=	Off
#Detector Gain=	Best Dynamic
#Detector ADC=	50 kHz HS
#Detector temperature (°C)=	-60.09
#Instrument=	LabRAM HR Evol
#Detector=	SIN-EM FIVIS
#Objective=	x100_VIS
#Grating=	150 (500nm)
#ND Filter=	100%
#Laser=	633nm_Edge
#Hole=	49.98
#Temperature=	0
#Range=	Visible
#StageXY=	75x50mm Scan+
#StageZ=	Z motor
#X (µm)=	0
#Y (µm)=	0
#Z (µm)=	-270.9
#Full time(mm:ss)=	2:05
#Project=	21_11_04
#Sample=	BU19w
#Site=
#Title=	BU19w-E-FF11-FI10-V_150 (500nm)_633nm_Edge_100%_x100_VIS_H50um_60sX2
#Remark=
#Date=	04.11.2021 11:53
#Acquired=	04.11.2021 11:53:51
102.881	266.476
109.397	232.376
115.908	202.035
122.414	196.444
128.914	196.57
135.409	196.64
141.898	186.119
148.383	178.501
154.861	182.408
161.335	183.469
167.801	213.28
174.264	175.917
180.721	152.838
187.173	141.176
193.62	137.126
200.061	142.688
206.496	125.489
212.926	126.39
219.352	133.015
225.772	148.168
232.185	168.893
238.595	229.56
244.999	188.579
251.397	150.506
257.791	144.718
264.178	143.712
270.561	153.166
276.939	138.937
283.31	160.708
289.678	164.41
296.039	142.492
302.396	116.828
308.746	139.396
315.093	150.607
321.433	203.358
327.768	286.313
334.099	251.368
340.423	173.041
346.743	149.41
353.058	144.615
359.367	166.136
365.671	157.503
371.971	156.406
378.265	124.334
384.553	121.423
390.837	115.859
397.116	116.025
403.389	113.467
409.657	118.424
415.92	115.765
422.178	117.796
428.431	129.028
434.678	136.276
440.921	154.761
447.158	144.963
453.391	141.734
459.618	157.27
465.84	153.342
472.057	120.627
478.27	115.986
484.477	114.136
490.679	118.81
496.876	115.109
503.068	117.953
509.255	121.746
515.436	121.843
521.613	137.908
527.785	132.556
533.952	139.476
540.113	140.773
546.27	122.155
552.423	123.191
558.568	112.839
564.711	112.687
570.848	100.198
576.979	98.9464
583.107	104.26
589.228	106.817
595.345	117.869
601.458	131.876
607.565	126.473
613.667	130.473
619.764	138.354
625.856	130.352
631.944	126.833
638.026	112.704
644.104	113.481
650.177	107.661
656.244	125.213
662.308	106.166
668.365	102.17
674.418	96.5162
680.467	99.3148
686.511	89.1336
692.549	86.5045
698.582	95.1353
704.611	96.2678
710.635	93.5772
716.655	89.7523
722.669	84.0659
728.679	91.4528
734.683	87.5439
740.683	84.584
746.678	85.3911
752.669	90.9099
758.654	78.7834
764.635	86.4109
770.611	85.7192
776.582	87.8381
782.549	86.1282
788.511	94.7192
794.466	83.4683
800.419	82.5126
806.366	91.8561
812.309	78.5569
818.247	91.536
824.18	89.4432
830.108	90.1785
836.033	91.0921
841.952	82.8061
847.865	93.2646
853.776	85.0237
859.681	85.2481
865.58	94.9291
871.476	93.2737
877.366	100.983
883.253	105.801
889.134	101.055
895.012	104.789
900.883	104.605
906.751	105.294
912.614	101.248
918.473	103.858
924.326	104.727
930.174	101.046
936.019	112.522
941.859	113.86
947.693	123.785
953.525	143.314
959.35	149.513
965.171	148.919
970.988	159.74
976.801	168.478
982.608	228.734
988.411	253.273
994.209	241.345
1000	209.47
1005.79	171.121
1011.58	155.9
1017.36	163.684
1023.13	174.431
1028.9	177.724
1034.67	162.839
1040.43	139.252
1046.19	137.756
1051.94	127.43
1057.69	123.772
1063.44	112.212
1069.17	117.027
1074.91	110.185
1080.64	112.999
1086.37	131.304
1092.09	145.755
1097.8	172.761
1103.52	195.893
1109.22	165.99
1114.93	141.13
1120.63	130.875
1126.32	129.215
1132.01	120.743
1137.7	136.723
1143.38	147.856
1149.06	161.853
1154.73	201.357
1160.4	166.808
1166.06	122.292
1171.72	114.22
1177.38	96.3727
1183.03	93.2896
1188.67	92.288
1194.31	94.3035
1199.95	87.6126
1205.58	80.0352
1211.21	79.3485
1216.84	75.7303
1222.46	78.0802
1228.07	75.4562
1233.68	78.7847
1239.29	77.0374
1244.89	81.2352
1250.49	76.2617
1256.08	88.3984
1261.67	88.3029
1267.26	80.1221
1272.84	78.9711
1278.42	90.8437
1283.99	163.782
1289.56	81.5189
1295.12	79.4561
1300.68	73.4516
1306.23	76.5241
1311.78	74.7025
1317.33	79.9695
1322.87	77.2261
1328.41	82.6029
1333.94	74.7825
1339.47	80.138
1345	75.2123
1350.52	79.4581
1356.04	81.6313
1361.55	76.5617
1367.06	82.7316
1372.56	88.8659
1378.06	87.8071
1383.56	130.88
1389.05	138
1394.53	79.5293
1400.02	86.8426
1405.5	84.9102
1410.97	87.1239
1416.44	79.0454
1421.91	79.2286
1427.37	76.3152
1432.83	78.5959
1438.28	77.7505
1443.73	78.99
1449.17	81.2518
1454.62	78.1963
1460.05	77.1804
1465.48	82.4236
1470.91	76.1015
1476.34	79.2466
1481.76	76.1291
1487.17	83.5416
1492.59	82.5951
1497.99	85.9032
1503.4	77.6348
1508.8	82.0653
1514.19	79.1155
1519.59	77.2425
1524.97	79.6484
1530.36	83.1451
1535.74	81.3017
1541.11	84.7692
1546.48	78.4131
1551.85	76.2544
1557.21	86.9617
1562.57	87.9536
1567.93	82.473
1573.28	80.2324
1578.62	86.653
1583.97	89.8917
1589.3	85.6208
1594.64	88.9288
1599.97	90.1278
1605.3	85.9697
1610.62	84.0267
1615.94	87.5811
1621.25	89.0115
1626.56	90.4457
1631.87	94.0797
1637.17	81.1102
1642.47	81.2136
1647.76	91.2975
1653.05	91.4018
1658.34	87.0251
1663.62	85.943
1668.9	92.6048
1674.18	85.9522
1679.45	87.0462
1684.71	91.4167
1689.98	89.1265
1695.23	88.0014
1700.49	90.3268
1705.74	81.8669
1710.99	92.0162
1716.23	88.705
1721.47	95.6716
1726.7	85.7384
1731.94	82.5486
1737.16	86.0877
1742.39	83.9975
1747.61	89.7939
1752.82	94.4337
1758.03	97.9104
1763.24	90.0167
1768.44	84.3961
1773.64	92.3847
1778.84	86.8091
1784.03	89.2169
1789.22	87.1161
1794.41	99.8667
1799.59	96.6887
1804.76	88.9246
1809.94	94.8888
1815.11	88.1764
1820.27	87.212
1825.43	88.5661
1830.59	88.7753
1835.74	92.4882
1840.89	99.6713
1846.04	89.3369
1851.18	101.179
1856.32	93.1092
1861.45	93.2781
1866.58	93.4714
1871.71	101.883
1876.83	92.5845
1881.95	92.6956
1887.07	95.1495
1892.18	99.9003
1897.29	86.9077
1902.39	97.6512
1907.49	94.2824
1912.59	96.9262
1917.68	92.4686
1922.77	94.9613
1927.86	92.7541
1932.94	100.126
1938.02	97.8904
1943.09	98.0204
1948.16	99.3257
1953.23	95.7713
1958.29	100.625
1963.35	99.4362
1968.41	100.628
1973.46	102.982
1978.51	101.722
1983.55	104.07
1988.59	101.619
1993.63	94.3734
1998.66	99.1731
2003.69	100.395
2008.72	101.654
2013.74	93.3099
2018.76	109.036
2023.77	101.89
2028.78	100.817
2033.79	100.999
2038.79	98.7689
2043.79	103.827
2048.79	101.622
2053.78	104.24
2058.77	105.677
2063.76	102.241
2068.74	107.377
2073.72	91.6179
2078.69	97.9613
2083.66	109.243
2088.63	104.445
2093.59	107.107
2098.55	107.352
2103.51	106.371
2108.46	110.4
2113.41	111.979
2118.36	113.584
2123.3	108.893
2128.24	114.257
2133.17	112.024
2138.11	103.406
2143.03	115.076
2147.96	108.921
2152.88	112.901
2157.79	105.36
2162.71	99.0472
2167.62	113.142
2172.52	110.647
2177.43	103.045
2182.32	105.62
2187.22	110.726
2192.11	115.887
2197	112.126
2201.89	107.138
2206.77	107.319
2211.64	115.269
2216.52	121.989
2221.39	114.534
2226.26	120.016
2231.12	116.419
2235.98	106.282
2240.84	109.163
2245.69	102.89
2250.54	114.978
2255.39	109.991
2260.23	116.881
2265.07	111.85
2269.9	112.052
2274.74	120.177
2279.57	118.977
2284.39	113.723
2289.21	109.761
2294.03	124.425
2298.84	123.161
2303.66	113.953
2308.46	122.148
2313.27	117.051
2318.07	115.999
2322.87	108.222
2327.66	130.083
2332.45	114.235
2337.24	124.082
2342.02	113.602
2346.8	124.938
2351.58	119.894
2356.35	125.755
2361.12	120.53
2365.89	119.409
2370.65	122.431
2375.41	124.062
2380.17	115.951
2384.92	118.869
2389.67	125.921
2394.42	123.182
2399.16	119.005
2403.9	130.127
2408.64	127.354
2413.37	127.577
2418.1	129.588
2422.83	121.574
2427.55	118.956
2432.27	127.734
2436.99	116.79
2441.7	119.981
2446.41	133.155
2451.11	126.416
2455.82	132.513
2460.51	128.589
2465.21	120.313
2469.9	124.97
2474.59	128.183
2479.28	127.071
2483.96	134.658
2488.64	123.27
2493.32	126.442
2497.99	132.566
2502.66	121.076
2507.32	133.042
2511.99	128.817
2516.65	133.4
2521.3	145.418
2525.96	139.728
2530.61	134.018
2535.25	122.391
2539.89	130.066
2544.53	142.252
2549.17	129.134
2553.8	144.378
2558.43	137.148
2563.06	134.439
2567.68	133.267
2572.3	123.05
2576.92	129.409
2581.53	134.225
2586.14	134.411
2590.75	126.921
2595.35	131.634
2599.96	136.417
2604.55	127.434
2609.15	141.331
2613.74	132.263
2618.33	138.499
2622.91	138.622
2627.49	138.778
2632.07	137.497
2636.64	134.766
2641.22	141.371
2645.78	130.985
2650.35	151.603
2654.91	134.863
2659.47	136.664
2664.03	138.426
2668.58	132.354
2673.13	138.909
2677.67	144.143
2682.22	146.443
2686.76	137.568
2691.29	155.709
2695.83	144.906
2700.36	150.025
2704.89	147.112
2709.41	142.549
2713.93	128.28
2718.45	146.349
2722.96	145.003
2727.47	135.466
2731.98	148.583
2736.49	140.578
2740.99	155.335
2745.49	152.278
2749.98	146.021
2754.47	143.184
2758.96	146.736
2763.45	137.106
2767.93	139.029
2772.41	140.937
2776.89	142.939
2781.36	143.378
2785.84	145.525
2790.3	152.679
2794.77	149.804
2799.23	153.56
2803.69	158.965
2808.14	149.173
2812.59	142.691
2817.04	142.902
2821.49	149.9
2825.93	148.458
2830.37	152.092
2834.81	147.203
2839.24	154.229
2843.67	154.459
2848.1	141.057
2852.53	151.634
2856.95	138.272
2861.37	159.293
2865.78	142.502
2870.19	151.612
2874.6	153.818
2879.01	149.083
2883.41	144.354
2887.81	139.604
2892.21	147.122
2896.6	156.478
2901	137.537
2905.38	157.552
2909.77	154.446
2914.15	149.434
2918.53	167.711
2922.91	162.735
2927.28	154.176
2931.65	163.677
2936.02	149.581
2940.38	151.688
2944.74	148.325
2949.1	148.529
2953.46	152.397
2957.81	148.955
2962.16	156.496
2966.5	153.086
2970.85	164.384
2975.19	162.854
2979.52	163.159
2983.86	161.671
2988.19	175.049
2992.52	142.102
2996.85	142.511
3001.17	185.943
3005.49	158.446
3009.8	151.449
3014.12	167.021
3018.43	169.513
3022.74	168.212
3027.04	166.8
3031.34	167.222
3035.64	173.314
3039.94	165.978
3044.23	164.381
3048.52	178.149
3052.81	166.874
3057.09	167.182
3061.38	157.796
3065.65	185.228
3069.93	150.579
3074.2	185.883
3078.47	182.33
3082.74	180.714
3087	183.081
3091.27	175.728
3095.52	184.161
3099.78	196.618
3104.03	181.437
3108.28	188.089
3112.53	192.832
3116.77	179.542
3121.01	188.328
3125.25	205.328
3129.49	177.826
3133.72	192.997
3137.95	179.557
3142.18	198.905
3146.4	197.645
3150.62	188.001
3154.84	194.832
3159.06	205.854
3163.27	214.854
3167.48	204.926
3171.69	209.703
3175.89	199.632
3180.09	208.436
3184.29	217.2
3188.49	219.542
3192.68	200.753
3196.87	201.149
3201.06	199.663
3205.24	193.948
3209.42	211.938
3213.6	221.457
3217.78	224.587
3221.95	212.413
3226.12	215.457
3230.29	229.475
3234.45	214.905
3238.61	217.894
3242.77	198.789
3246.93	210.779
3251.08	200.305
3255.23	205.312
3259.38	228.371
3263.53	220.124
3267.67	205.366
3271.81	206.203
3275.95	204.455
3280.08	214.034
3284.21	221.352
3288.34	214.898
3292.47	217.6
3296.59	201.831
3300.71	218.423
3304.83	211.9
3308.95	198.389
3313.06	208.026
3317.17	201.425
3321.27	206.512
3325.38	200.002
3329.48	228.682
3333.58	215.368
3337.67	206.681
3341.77	221.422
3345.86	228.997
3349.95	212.745
3354.03	208.351
3358.11	227.908
3362.19	230.82
3366.27	214.53
3370.34	212.588
3374.42	210.573
3378.48	242.217
3382.55	230.481
3386.61	206.606
3390.68	214.093
3394.73	204.654
3398.79	219.512
3402.84	217.339
3406.89	222.408
3410.94	215.297
3414.98	232.507
3419.03	235.13
3423.06	220.662
3427.1	230.608
3431.14	240.648
3435.17	223.863
3439.2	221.795
3443.22	209.935
3447.25	217.826
3451.27	213.435
3455.28	231.372
3459.3	209.81
3463.31	198.09
3467.32	218.796
3471.33	222.037
3475.34	220.11
3479.34	208.164
3483.34	196.126
3487.33	216.985
3491.33	202.309
3495.32	220.674
3499.31	216.045
3503.3	221.563
3507.28	219.335
3511.26	206.679
3515.24	209.381
3519.22	176.085
3523.19	199.334
3527.16	209.785
3531.13	184.175
3535.1	199.975
3539.06	208.202
3543.02	161.973
3546.98	195.99
3550.93	198.837
3554.89	201.513
3558.84	191.313
3562.78	191.576
3566.73	181.466
3570.67	187.101
3574.61	190.124
3578.55	187.979
3582.48	193.797
3586.41	189.088
3590.35	184.336
3594.27	190.191
3598.2	188.066
3602.12	185.87
3606.04	183.638
3609.95	184.027
3613.87	181.723
3617.78	182.071
3621.69	185.036
3625.6	171.653
3629.5	185.281
3633.4	169.11
3637.3	163.825
3641.2	177.626
3645.09	167.104
3648.98	175.511
3652.87	156.63
3656.76	162.229
3660.64	178.741
3664.53	173.415
3668.4	157.194
3672.28	184.71
3676.16	168.541
3680.03	157.883
3683.9	163.764
3687.76	166.979
3691.63	170.223
3695.49	145.678
3699.35	173.895
3703.2	152.027
3707.06	152.451
3710.91	169.702
3714.76	153.268
3718.6	170.516
3722.45	162.384
3726.29	157.012
3730.13	157.286
3733.97	160.429
3737.8	149.351
3741.63	152.454
3745.46	158.403
3749.29	158.618
3753.11	164.506
3756.93	173.221
3760.75	153.26
3764.57	147.597
3768.39	141.943
3772.2	156.413
3776.01	159.42
3779.81	162.472
3783.62	151.191
3787.42	151.422
3791.22	151.627
3795.02	163.457
3798.81	152.188
3802.61	146.698
3806.4	138.297
3810.18	156.12
3813.97	159.364
3817.75	150.891
3821.53	162.917
3825.31	160.24
3829.09	142.835
3832.86	169.663
3836.63	167.009
3840.4	164.313
3844.17	161.665
3847.93	143.987
3851.69	138.146
3855.45	156.044
3859.21	132.275
3862.96	156.107
3866.71	144.46
3870.46	156.743
3874.21	144.878
3877.95	156.924
3881.69	148.055
3885.44	151.171
3889.17	145.329
3892.91	151.516
3896.64	151.793
3900.37	161.059
3904.1	137.177
3907.82	149.445
3911.55	134.563
3915.27	152.974
3918.99	156.331
3922.7	156.715
3926.42	147.922
3930.13	154.342
3933.84	148.476
3937.54	151.754
3941.25	148.949
3944.95	149.255
3948.65	155.699
3952.35	137.407
3956.04	131.404
3959.73	147.007
3963.42	156.413
3967.11	153.395
3970.8	137.932
3974.48	131.779
3978.16	147.323
3981.84	144.214
3985.52	156.61
3989.19	131.795
3992.86	138.043
3996.53	131.932
3998.37	131.996