File: Data/3-Raman/raw/bu19w-ff2-fi02-v_150 (500nm)_532nm_edge_100%_x100_vis_h50um_15sx2_02.txt
#Acq. time (s)=	15
#Accumulations=	2
#Range (cm-¹)=	100...5000
#Windows=	1
#Auto scanning=	Off
#Autofocus=	Off
#Macrospot=	Off
#AutoExposure=	Off
#Spike filter=	Multiple accum.
#Delay time (s)=	2
#Binning=	1
#Readout mode=	Signal
#DeNoise=	Off
#ICS correction=	On
#Dark correction=	Off
#Inst. Process=	Off
#Detector Gain=	Best Dynamic
#Detector ADC=	50 kHz HS
#Detector temperature (°C)=	-60.09
#Instrument=	LabRAM HR Evol
#Detector=	SIN-EM FIVIS
#Objective=	x100_VIS
#Grating=	150 (500nm)
#ND Filter=	100%
#Laser=	532nm_Edge
#Hole=	49.98
#Temperature=	0
#Range=	Visible
#StageXY=	75x50mm Scan+
#StageZ=	Z motor
#X (µm)=	0
#Y (µm)=	0
#Z (µm)=	-183.9
#Full time(s)=	34
#Project=	21_05_14
#Sample=	BU19w
#Site=
#Title=	BU19w-FF2-FI02-V_150 (500nm)_532nm_Edge_100%_x100_VIS_H50um_15sX2
#Remark=
#Date=	14.05.2021 17:17
#Acquired=	14.05.2021 17:17:14
102.699	1248.26
107.322	1208.48
111.942	1088.16
116.56	1025.18
121.173	1036.46
125.787	1036.97
130.398	957.781
135.006	1016.82
139.613	949.21
144.215	939.528
148.817	965.432
153.417	1208.58
158.014	1701.55
162.607	1563.35
167.2	1109.61
171.79	885.295
176.379	929.167
180.963	1047.75
185.547	1503.97
190.128	1528.44
194.705	1201.85
199.282	958.445
203.857	913.108
208.43	891.026
212.998	920.329
217.566	872.585
222.132	866.405
226.693	1016.5
231.254	1249.37
235.813	1297.64
240.368	1494.33
244.923	1872.39
249.475	1624.52
254.023	1183.65
258.571	1066.99
263.117	1030.82
267.658	1224.07
272.199	1871.87
276.738	3036.25
281.273	2876.75
285.807	1921.43
290.34	1355.95
294.868	1208.23
299.396	1263.57
303.919	1302.86
308.443	1194.85
312.964	1125.17
317.481	1133.19
321.998	1376.13
326.51	1692.81
331.023	1677.04
335.533	1415.13
340.039	1346.59
344.544	1655.6
349.046	1941.48
353.547	1788.99
358.045	1392.44
362.542	1261.35
367.036	1304.69
371.527	1287.24
376.017	1195.1
380.503	1072.13
384.99	1139.5
389.471	1219.34
393.953	1256.52
398.43	1186.19
402.908	1031.89
407.381	1024.31
411.854	1190.48
416.323	1365.37
420.791	1258.81
425.256	1003.51
429.72	928.185
434.18	900.25
438.64	924.361
443.095	882.843
447.551	940.981
452.003	1007.18
456.454	1022.66
460.901	982.144
465.348	959.245
469.791	957.745
474.231	993.7
478.672	1025.74
483.108	1093.98
487.544	1181.6
491.976	1309.22
496.408	1333.56
500.836	1273
505.261	1186.03
509.687	1063.05
514.108	986.496
518.529	1009.4
522.946	964.638
527.361	949.959
531.776	949.456
536.187	986.07
540.595	941.597
545.003	958.488
549.408	982.396
553.812	1038.41
558.212	1022.18
562.61	1022.77
567.007	1000.71
571.401	979.168
575.792	984.72
580.184	1052.66
584.571	1318.98
588.956	1526.57
593.341	1362.89
597.722	1135.13
602.101	1130.63
606.48	1329.1
610.854	1321.95
615.227	1229.53
619.597	1106.19
623.967	975.312
628.334	937.663
632.698	1014.01
637.06	1076.1
641.422	1089.1
645.779	1077.51
650.135	1105.55
654.491	1134.13
658.842	1289.32
663.192	1395.1
667.539	1468.39
671.884	1513.66
676.23	1536.05
680.571	1456
684.91	1237.57
689.247	1095.7
693.583	1039.36
697.916	988.066
702.247	952.043
706.576	962.917
710.902	985.711
715.229	973.111
719.551	943.463
723.872	966.889
728.19	1001.42
732.506	950.805
736.82	1001.89
741.134	987.337
745.444	976.42
749.752	1019.54
754.058	1032.49
758.362	1064.33
762.664	1104.72
766.964	1195.21
771.264	1372.42
775.559	1644.88
779.853	1673.02
784.144	1468.05
788.434	1254.68
792.722	1154.49
797.007	1117.58
801.29	1093.73
805.572	1057.27
809.851	1041.89
814.13	1065.26
818.406	1009.35
822.679	1036.23
826.95	1010.42
831.219	1057.37
835.486	1026.02
839.752	1040.89
844.015	1038.99
848.276	1056.19
852.535	1038
856.792	1019.84
861.047	1058.85
865.3	1034.72
869.551	1022.5
873.8	1029.78
878.047	1054.38
882.292	1021.63
886.534	1019.1
890.775	1044.98
895.014	1017.47
899.251	1046.51
903.486	1054.19
907.719	1045.65
911.95	1074.69
916.179	1069.92
920.406	1079.23
924.63	1062.26
928.853	1074.88
933.074	1133.74
937.293	1140.63
941.51	1237.22
945.723	1332.18
949.936	1361.12
954.147	1307.08
958.356	1255.49
962.563	1199.92
966.768	1178.51
970.971	1176.54
975.172	1155.59
979.371	1150.84
983.568	1113.34
987.761	1116.95
991.954	1114.94
996.145	1136.07
1000.33	1114.09
1004.52	1112.36
1008.71	1131.09
1012.89	1120.7
1017.07	1124.12
1021.25	1131.77
1025.43	1188.98
1029.6	1144.78
1033.77	1244.63
1037.95	1287.59
1042.11	1371.04
1046.28	1665.22
1050.45	2060.89
1054.61	2117.6
1058.77	1802.9
1062.93	1513.37
1067.09	1398.64
1071.24	1365.86
1075.4	1414.92
1079.55	1481.65
1083.7	1735.45
1087.85	2082.85
1091.99	2177.46
1096.14	1991.37
1100.28	1805.41
1104.42	1983.22
1108.55	2172.64
1112.69	2135.34
1116.82	2009.36
1120.96	1834.23
1125.09	1886.82
1129.21	1969.37
1133.34	1992.32
1137.46	1871.96
1141.59	1641.89
1145.71	1519.98
1149.83	1556.69
1153.94	1650.32
1158.06	1778.93
1162.17	1705.57
1166.28	1590.65
1170.39	1530.88
1174.5	1468.75
1178.6	1324.29
1182.7	1244.85
1186.8	1245.79
1190.9	1238.15
1195	1258.77
1199.1	1195.26
1203.19	1239.69
1207.28	1211.9
1211.37	1225.81
1215.46	1289.07
1219.54	1358.3
1223.63	1425.3
1227.71	1313.37
1231.79	1301.3
1235.87	1277.89
1239.95	1344.86
1244.02	1372.02
1248.09	1274.35
1252.16	1311.79
1256.23	1234.58
1260.3	1222.46
1264.36	1210.52
1268.43	1357.15
1272.49	1963.56
1276.55	1540.95
1280.6	1229.91
1284.66	1227.81
1288.71	1194.45
1292.76	1241.35
1296.81	1201.58
1300.86	1216
1304.91	1185.85
1308.95	1226.31
1312.99	1227.03
1317.03	1244.45
1321.07	1200.3
1325.11	1235
1329.14	1212.62
1333.18	1214.88
1337.21	1212.86
1341.24	1212.69
1345.26	1257.33
1349.29	1217.21
1353.31	1263.73
1357.33	1244.61
1361.35	1235.43
1365.37	1276.08
1369.39	1278.24
1373.4	1897.22
1377.41	2351.48
1381.43	1491.26
1385.43	1261.49
1389.44	1254.39
1393.45	1264.58
1397.45	1382.38
1401.45	1293.08
1405.45	1286.67
1409.45	1256.7
1413.44	1206.07
1417.44	1272.81
1421.43	1261.53
1425.42	1233.02
1429.41	1250.51
1433.39	1235.75
1437.38	1239.54
1441.36	1231.53
1445.34	1282.48
1449.32	1279.09
1453.3	1277.41
1457.27	1271.68
1461.24	1240.97
1465.22	1203.18
1469.19	1243.2
1473.15	1248.83
1477.12	1265.94
1481.09	1296.64
1485.05	1285.12
1489.01	1240.44
1492.97	1261.31
1496.93	1238.34
1500.88	1246.77
1504.83	1246.72
1508.79	1276.07
1512.74	1263.64
1516.68	1262.04
1520.63	1261.52
1524.57	1282.41
1528.52	1273.37
1532.46	1251.85
1536.4	1257.47
1540.33	1278.64
1544.27	1273.63
1548.2	1256.04
1552.14	1249.02
1556.07	1286.35
1559.99	1292.52
1563.92	1286.94
1567.84	1283.18
1571.77	1283.25
1575.69	1307.41
1579.61	1313.16
1583.52	1284.15
1587.44	1282.07
1591.35	1309.8
1595.27	1318.25
1599.18	1302.73
1603.09	1313.32
1606.99	1311.56
1610.9	1303.13
1614.8	1323.6
1618.7	1295.28
1622.6	1304.33
1626.5	1282.04
1630.39	1325.11
1634.29	1302.37
1638.18	1317.96
1642.07	1342.6
1645.96	1311.83
1649.85	1303.16
1653.73	1327.09
1657.62	1292.35
1661.5	1333.35
1665.38	1291.47
1669.26	1325.27
1673.13	1339.56
1677.01	1358.29
1680.88	1305.31
1684.75	1347.25
1688.62	1335.25
1692.49	1332.59
1696.35	1333.57
1700.22	1340.96
1704.08	1336.6
1707.94	1358.59
1711.8	1357.6
1715.66	1384.13
1719.51	1350.15
1723.37	1400.14
1727.22	1347.21
1731.07	1376.1
1734.92	1377.72
1738.76	1412.75
1742.61	1375.83
1746.45	1382.37
1750.29	1384.06
1754.13	1404.9
1757.97	1356.9
1761.81	1357.78
1765.64	1366.46
1769.47	1396.47
1773.31	1368.19
1777.14	1406.21
1780.96	1426.08
1784.79	1394.77
1788.61	1385.93
1792.43	1424.92
1796.25	1404.84
1800.07	1424.59
1803.89	1400.54
1807.71	1421.62
1811.52	1410.43
1815.33	1412.91
1819.14	1391.29
1822.95	1402.42
1826.76	1415.1
1830.56	1356.69
1834.37	1390.37
1838.17	1390.86
1841.97	1418.3
1845.77	1435.3
1849.56	1392.02
1853.36	1446.54
1857.15	1410.84
1860.94	1402.95
1864.73	1419.28
1868.52	1457.97
1872.31	1462.49
1876.09	1452.42
1879.87	1441.85
1883.66	1467.56
1887.43	1417.79
1891.21	1426.86
1894.99	1465.26
1898.76	1423.99
1902.53	1440.23
1906.31	1444.69
1910.08	1455.98
1913.84	1450.07
1917.61	1457.64
1921.37	1466.68
1925.14	1425.83
1928.9	1486.31
1932.66	1452.08
1936.41	1459.63
1940.17	1497.09
1943.92	1448.81
1947.68	1471.32
1951.43	1492.38
1955.18	1468.62
1958.92	1460.07
1962.67	1511.49
1966.41	1491.37
1970.16	1512.71
1973.9	1506.55
1977.64	1478.56
1981.37	1483.14
1985.11	1489.31
1988.84	1492.55
1992.57	1517.73
1996.31	1550
2000.03	1507.81
2003.76	1509.46
2007.49	1517.01
2011.21	1513.41
2014.93	1508.38
2018.65	1514.48
2022.37	1525.82
2026.09	1505.92
2029.81	1497.66
2033.52	1554.91
2037.23	1525.69
2040.94	1521.28
2044.65	1532.21
2048.36	1518.74
2052.07	1516.46
2055.77	1513.53
2059.47	1533.85
2063.17	1525.34
2066.87	1525.27
2070.57	1506.79
2074.27	1527.09
2077.96	1553.19
2081.65	1551.5
2085.34	1516.36
2089.03	1528.39
2092.72	1556.08
2096.41	1522.75
2100.09	1557.43
2103.77	1558.39
2107.46	1589.76
2111.14	1580.06
2114.81	1572.18
2118.49	1542.45
2122.16	1544.66
2125.84	1589.38
2129.51	1575.37
2133.18	1578.93
2136.85	1628.43
2140.51	1588.96
2144.18	1598.25
2147.84	1554.18
2151.5	1576.31
2155.16	1595.71
2158.82	1649.89
2162.48	1603.76
2166.13	1588.1
2169.79	1601.18
2173.44	1594.86
2177.09	1589.58
2180.74	1615.38
2184.38	1602.08
2188.03	1585.89
2191.67	1629.41
2195.32	1646.26
2198.96	1632.3
2202.6	1604.86
2206.23	1626.05
2209.87	1634.75
2213.5	1627.13
2217.14	1645.21
2220.77	1660.66
2224.4	1631.05
2228.03	1661.17
2231.65	1614.9
2235.28	1661.95
2238.9	1689.6
2242.52	1671.84
2246.14	1656.79
2249.76	1687.48
2253.38	1636.38
2256.99	1690.73
2260.6	1640.28
2264.21	1666.48
2267.82	1729.79
2271.44	1673.81
2275.04	1653.71
2278.65	1678.19
2282.25	1657.5
2285.85	1686.27
2289.45	1676.01
2293.05	1687.44
2296.65	1691.42
2300.25	1654.54
2303.84	1674.09
2307.43	1696.21
2311.02	1682.09
2314.62	1724.55
2318.2	1797.91
2321.79	1760.6
2325.38	1739.59
2328.96	1726.26
2332.54	1697.51
2336.12	1715.77
2339.7	1707.41
2343.28	1728
2346.85	1707.08
2350.43	1736.68
2354	1647.48
2357.57	1747.68
2361.14	1704.2
2364.71	1724.98
2368.27	1714.48
2371.84	1751.38
2375.4	1730.73
2378.96	1735.25
2382.52	1721.54
2386.08	1731.08
2389.64	1752.87
2393.19	1740.21
2396.75	1729.07
2400.3	1778.28
2403.85	1701.66
2407.4	1720.68
2410.95	1723.92
2414.49	1714.62
2418.04	1700.15
2421.58	1727.39
2425.12	1713.66
2428.66	1739.08
2432.2	1777
2435.74	1751.31
2439.27	1734.93
2442.81	1754.94
2446.34	1766.81
2449.87	1740.7
2453.4	1758.14
2456.93	1751.48
2460.45	1767.56
2463.98	1786.78
2467.5	1816.19
2471.02	1746.12
2474.54	1753.97
2478.06	1738.88
2481.58	1753.64
2485.09	1772.08
2488.61	1761.31
2492.12	1815.54
2495.63	1795.1
2499.14	1764.71
2502.65	1766.43
2506.15	1800.54
2509.66	1821.34
2513.16	1792.26
2516.66	1793.34
2520.16	1781.53
2523.66	1812.33
2527.16	1797.75
2530.66	1812.97
2534.15	1823.17
2537.64	1764.52
2541.13	1816.43
2544.62	1774.24
2548.11	1772.82
2551.6	1797.55
2555.08	1790.97
2558.57	1795.5
2562.05	1794.24
2565.53	1803.83
2569.01	1782.24
2572.49	1800.22
2575.96	1784.87
2579.44	1794.09
2582.91	1803.43
2586.38	1828.69
2589.85	1795.16
2593.32	1777.02
2596.79	1806.05
2600.25	1834.41
2603.72	1850.55
2607.18	1852.91
2610.64	1786.09
2614.1	1833.35
2617.56	1837.7
2621.02	1829.19
2624.47	1860.49
2627.92	1807.91
2631.38	1847.13
2634.83	1824.33
2638.28	1860.62
2641.72	1853.32
2645.17	1873.66
2648.61	1812.49
2652.06	1851.02
2655.5	1809.14
2658.94	1815.56
2662.38	1845.35
2665.82	1834.44
2669.25	1826.17
2672.69	1810.69
2676.12	1843.31
2679.55	1819.13
2682.98	1802.94
2686.41	1840.13
2689.84	1829.03
2693.26	1847.2
2696.69	1900.16
2700.11	1834.29
2703.53	1863.8
2706.95	1893.85
2710.37	1809.06
2713.79	1859.53
2717.2	1834.99
2720.62	1830.28
2724.03	1830.37
2727.44	1852.15
2730.85	1820.53
2734.26	1815.05
2737.66	1813.32
2741.07	1848.82
2744.47	1868.01
2747.87	1817.69
2751.28	1850.98
2754.67	1835.9
2758.07	1842.73
2761.47	1865.97
2764.86	1849.39
2768.26	1871.04
2771.65	1857.72
2775.04	1871.4
2778.43	1854.63
2781.82	1887.59
2785.2	1861.16
2788.59	1842.25
2791.97	1838.23
2795.35	1809.99
2798.73	1838.6
2802.11	1896.24
2805.49	1839.49
2808.87	1802.38
2812.24	1860.65
2815.62	1842.95
2818.99	1873.14
2822.36	1842.98
2825.73	1866.11
2829.1	1858.67
2832.46	1850.66
2835.83	1866.24
2839.19	1855.16
2842.55	1839.81
2845.91	1853.9
2849.27	1862.35
2852.63	1842.37
2855.99	1812.28
2859.34	1836.72
2862.69	1837.85
2866.05	1826.88
2869.4	1857.06
2872.75	1833.66
2876.09	1868.49
2879.44	1798.8
2882.78	1860.84
2886.13	1801.1
2889.47	1822.62
2892.81	1877.65
2896.15	1844.55
2899.49	1836.66
2902.82	1832.27
2906.16	1823.96
2909.49	1851.39
2912.82	1859.9
2916.16	1878.46
2919.49	1839.17
2922.81	1836.73
2926.14	1849.04
2929.46	1897.15
2932.79	1894.72
2936.11	1890.4
2939.43	1893.63
2942.75	1856.39
2946.07	1859.78
2949.39	1862.17
2952.7	1851.33
2956.02	1864.27
2959.33	1935.69
2962.64	1883.16
2965.95	1849.86
2969.26	1853.89
2972.57	1841.63
2975.87	1836.67
2979.17	1851.95
2982.48	1840.12
2985.78	1828.42
2989.08	1847.76
2992.38	1801.43
2995.68	1822.86
2998.97	1811.43
3002.27	1824.35
3005.56	1812.05
3008.85	1820.54
3012.14	1815
3015.43	1778.3
3018.72	1805.66
3022	1809.44
3025.29	1800.04
3028.57	1820.86
3031.85	1800.03
3035.14	1789.49
3038.41	1831.93
3041.69	1825.2
3044.97	1732.38
3048.24	1795.7
3051.52	1825.07
3054.79	1798.48
3058.06	1792.51
3061.33	1783.25
3064.6	1764.66
3067.87	1776.19
3071.13	1815.71
3074.4	1763.23
3077.66	1761.98
3080.92	1812.92
3084.18	1729.52
3087.44	1739.39
3090.7	1753.47
3093.95	1853.26
3097.21	1766
3100.46	1809
3103.71	1778.39
3106.96	1773.54
3110.21	1763.41
3113.46	1756.07
3116.71	1797.38
3119.95	1782.53
3123.2	1741.93
3126.44	1751.76
3129.68	1794.96
3132.92	1788.59
3136.16	1733.5
3139.4	1770.84
3142.63	1738.57
3145.87	1773.13
3149.1	1787.75
3152.33	1761.29
3155.56	1773.01
3158.79	1742.72
3162.02	1750.59
3165.25	1765.98
3168.47	1776.45
3171.69	1773.48
3174.92	1759.88
3178.14	1765.29
3181.36	1744.04
3184.58	1764.6
3187.79	1754.55
3191.01	1769.28
3194.22	1793.5
3197.43	1773.84
3200.65	1714.26
3203.86	1809.93
3207.07	1760.97
3210.27	1736.89
3213.48	1743.38
3216.69	1756.56
3219.89	1765.97
3223.09	1739.39
3226.29	1742.36
3229.49	1739.77
3232.69	1773.22
3235.89	1779.37
3239.08	1739.05
3242.28	1737.86
3245.47	1785.26
3248.66	1768.03
3251.85	1721.29
3255.04	1761.37
3258.23	1760.23
3261.42	1742.6
3264.6	1771.52
3267.79	1744.83
3270.97	1761.94
3274.15	1714.1
3277.33	1749.08
3280.51	1759.79
3283.68	1737.08
3286.86	1702.8
3290.04	1727.76
3293.21	1725.99
3296.38	1715.59
3299.55	1691.35
3302.72	1698.24
3305.89	1719.19
3309.06	1757.89
3312.22	1732.76
3315.39	1702.87
3318.55	1775.35
3321.71	1723.62
3324.87	1748.65
3328.03	1761.36
3331.19	1740.14
3334.34	1756.87
3337.5	1717.1
3340.65	1711.35
3343.81	1718.18
3346.96	1766.99
3350.11	1751.72
3353.25	1729.1
3356.4	1717.87
3359.55	1727.59
3362.69	1718.52
3365.84	1768.02
3368.98	1722.3
3372.12	1723.95
3375.26	1739.86
3378.4	1770.07
3381.53	1722.71
3384.67	1757.71
3387.8	1745.47
3390.94	1770.23
3394.07	1800.93
3397.2	1800.33
3400.33	1797.2
3403.46	1836.02
3406.58	1904.52
3409.71	2017.97
3412.83	2276.89
3415.96	3054.56
3419.08	4907.25
3422.2	6104.66
3425.32	4571.49
3428.44	2918.51
3431.55	2260.65
3434.67	1967.88
3437.78	1882.52
3440.89	1806.84
3444	1825.22
3447.12	1803.51
3450.22	1769.14
3453.33	1797.64
3456.44	1760.17
3459.54	1804.47
3462.65	1751.71
3465.75	1762.5
3468.85	1808.75
3471.95	1841.22
3475.05	1853.93
3478.15	1920.64
3481.24	1957.99
3484.34	2046.4
3487.43	2200.95
3490.53	2414.61
3493.62	2710.35
3496.71	2977.31
3499.79	3502.76
3502.88	3928.12
3505.97	3898.34
3509.05	3501.04
3512.14	2962.85
3515.22	2582.01
3518.3	2313.79
3521.38	2083.3
3524.46	2018.57
3527.54	1921.41
3530.61	1847.5
3533.69	1782.96
3536.76	1761.53
3539.83	1703.57
3542.9	1674.07
3545.97	1725.42
3549.04	1634.79
3552.11	1633.58
3555.18	1652.5
3558.24	1647.96
3561.3	1643.03
3564.37	1647.44
3567.43	1637.71
3570.49	1632.44
3573.55	1647.84
3576.61	1620.49
3579.66	1571.19
3582.72	1636.51
3585.77	1589.86
3588.82	1618.93
3591.87	1593.87
3594.92	1579.12
3597.97	1655.29
3601.02	1634.69
3604.07	1576.11
3607.11	1628.21
3610.16	1555.41
3613.2	1554.41
3616.24	1584.61
3619.28	1594.08
3622.32	1577.19
3625.36	1552.87
3628.39	1557.75
3631.43	1561.57
3634.46	1574.11
3637.5	1537.98
3640.53	1542.5
3643.56	1571.87
3646.59	1549.24
3649.62	1544.69
3652.64	1545.98
3655.67	1577.54
3658.69	1520.64
3661.72	1510.54
3664.74	1567.63
3667.76	1540.92
3670.78	1523.78
3673.79	1533.13
3676.81	1530.32
3679.83	1505.73
3682.84	1556.73
3685.86	1474.44
3688.87	1504.74
3691.88	1489.66
3694.89	1512.22
3697.9	1524.56
3700.91	1498.08
3703.91	1514.31
3706.92	1510.47
3709.92	1502.68
3712.92	1509.92
3715.92	1483.91
3718.92	1499.64
3721.92	1513.34
3724.92	1483.11
3727.92	1530.84
3730.91	1507.97
3733.91	1509.7
3736.9	1520.8
3739.89	1516.49
3742.88	1522.51
3745.87	1505.56
3748.86	1517.95
3751.85	1542.61
3754.83	1488.51
3757.82	1472.4
3760.8	1508.32
3763.78	1495.87
3766.76	1465.55
3769.74	1477.97
3772.72	1500.89
3775.7	1500.26
3778.67	1514.85
3781.65	1484.13
3784.62	1482.77
3787.6	1523.02
3790.57	1464.37
3793.54	1480.44
3796.51	1494.71
3799.47	1486.52
3802.44	1480.32
3805.41	1474.16
3808.37	1431.23
3811.33	1480.97
3814.3	1441.88
3817.26	1469.04
3820.22	1479.23
3823.18	1422.27
3826.13	1448.7
3829.09	1469.45
3832.04	1451.42
3835	1467.66
3837.95	1406.02
3840.9	1472.66
3843.85	1427.11
3846.8	1444.41
3849.75	1442.76
3852.69	1438.28
3855.64	1444.32
3858.58	1436.06
3861.53	1443.02
3864.47	1433.71
3867.41	1465.48
3870.35	1425.32
3873.29	1419.61
3876.22	1434.87
3879.16	1424.05
3882.1	1458.22
3885.03	1454.79
3887.96	1447.44
3890.89	1440.99
3893.82	1454.58
3896.75	1455.47
3899.68	1430.36
3902.61	1420.43
3905.53	1450.05
3908.46	1412.32
3911.38	1421.56
3914.3	1398.92
3917.23	1401.52
3920.15	1426.98
3923.06	1411.92
3925.98	1417.84
3928.9	1421.68
3931.81	1418.13
3934.73	1393.8
3937.64	1394.71
3940.55	1425.21
3943.46	1419.36
3946.37	1423.21
3949.28	1383.14
3952.19	1399.62
3955.09	1363.54
3958	1423.34
3960.9	1389.31
3963.8	1422.45
3966.71	1352.09
3969.61	1392.1
3972.51	1369.73
3975.4	1390.48
3978.3	1387.12
3981.2	1406.8
3984.09	1394.68
3986.99	1375.83
3989.88	1386.54
3992.77	1393.64
3995.66	1413.27
3998.55	1373.29
4001.43	1378.57
4004.32	1395.48
4007.21	1345.93
4010.09	1373.46
4012.98	1390.41
4015.86	1389.05
4018.74	1378.02
4021.62	1400.78
4024.5	1388.81
4027.37	1358.47
4030.25	1395.83
4033.13	1368.41
4036	1396.2
4038.87	1365.94
4041.75	1360.61
4044.62	1410.49
4047.49	1347.07
4050.35	1390.36
4053.22	1409.54
4056.09	1329.74
4058.95	1368.3
4061.82	1364.11
4064.68	1377.43
4067.54	1385.88
4070.4	1358.31
4073.26	1353.09
4076.12	1346.87
4078.98	1366.95
4081.83	1347.07
4084.69	1344.71
4087.54	1343.27
4090.4	1363.38
4093.25	1351.26
4096.1	1358.65
4098.95	1335.78
4101.8	1354.88
4104.64	1338.67
4107.49	1360.54
4110.33	1335.38
4113.18	1277.74
4116.02	1338.37
4118.86	1343.13
4121.7	1306.92
4124.54	1340.28
4127.38	1328.83
4130.22	1360.78
4133.05	1340.13
4135.89	1303.05
4138.72	1326.08
4141.56	1328.1
4144.39	1343.18
4147.22	1325.09
4150.05	1312.73
4152.88	1291.11
4155.7	1337.5
4158.53	1305.6
4161.36	1316.19
4164.18	1308.2
4167	1311
4169.82	1306.04
4172.65	1296.25
4175.46	1308.97
4178.28	1304.14
4181.1	1297.44
4183.92	1315.24
4186.73	1295.93
4189.55	1316.86
4192.36	1315.48
4195.17	1304.45
4197.98	1294.46
4200.79	1294.25
4203.6	1320.54
4206.41	1298.73
4209.21	1314.22
4212.02	1312
4214.83	1280.7
4217.63	1288.12
4220.43	1296.34
4223.23	1278.77
4226.03	1266.16
4228.83	1322.92
4231.63	1291.77
4234.42	1296.36
4237.22	1242.44
4240.01	1278.86
4242.81	1294.53
4245.6	1284.33
4248.39	1232.05
4251.18	1290.5
4253.97	1237.96
4256.76	1275.36
4259.55	1210.62
4262.33	1265.24
4265.12	1254.73
4267.9	1249.25
4270.68	1225.59
4273.47	1222.89
4276.25	1269.42
4279.03	1243.17
4281.8	1250.13
4284.58	1256.95
4287.36	1223.14
4290.13	1231.74
4292.91	1249.55
4295.68	1249.29
4298.45	1265.21
4301.22	1216.13
4303.99	1250.26
4306.76	1215.38
4309.53	1194.79
4312.3	1219.87
4315.06	1222.42
4317.83	1249.31
4320.59	1228.27
4323.35	1233.61
4326.11	1229.79
4328.87	1238.14
4331.63	1229.15
4334.39	1208.92
4337.15	1226.46
4339.9	1235.98
4342.66	1233.33
4345.41	1234.89
4348.17	1176.29
4350.92	1237.29
4353.67	1188.08
4356.42	1229.73
4359.17	1208.98
4361.91	1188.24
4364.66	1175.67
4367.41	1174.38
4370.15	1205.84
4372.89	1188.97
4375.63	1207.96
4378.38	1168.35
4381.12	1187.33
4383.86	1180.81
4386.59	1184.98
4389.33	1213.18
4392.07	1188.42
4394.8	1177.94
4397.53	1193.82
4400.27	1202.46
4403	1196.57
4405.73	1156.46
4408.46	1161.95
4411.19	1172.48
4413.92	1142.29
4416.64	1157.63
4419.37	1142.65
4422.09	1156.01
4424.82	1187.17
4427.54	1200.6
4430.26	1123.02
4432.98	1161.49
4435.7	1144.43
4438.42	1171.27
4441.13	1144.63
4443.85	1132.63
4446.57	1155.22
4449.28	1155.72
4451.99	1107.83
4454.71	1149.18
4457.42	1147.36
4460.13	1135.11
4462.83	1131.32
4465.54	1154.91
4468.25	1128.04
4470.95	1084.38
4473.66	1164.09
4476.36	1135.36
4479.07	1143.61
4481.77	1127.6
4484.47	1136.87
4487.17	1110.17
4489.87	1131.93
4492.56	1099.28
4495.26	1119.87
4497.96	1142.6
4500.65	1123.81
4503.34	1095.6
4506.04	1111.97
4508.73	1084.85
4511.42	1120.35
4514.11	1101.77
4516.8	1111.85
4519.48	1109.35
4522.17	1116.44
4524.85	1107.52
4527.54	1095.45
4530.22	1088.69
4532.9	1104.39
4535.58	1091.28
4538.27	1062.26
4540.94	1103.7
4543.62	1101.4
4546.3	1048.77
4548.98	1068.96
4551.65	1067.98
4554.33	1070.28
4557	1080.49
4559.67	1055.37
4562.34	1080.01
4565.01	1065.35
4567.68	1063.29
4570.35	1057.78
4573.02	1042.56
4575.68	1052.94
4578.35	1074.5
4581.01	1043.54
4583.67	1051.92
4586.34	1047.21
4589	1044.53
4591.66	1043.96
4594.31	1042.65
4596.97	1030.11
4599.63	1071.4
4602.29	1036.24
4604.94	1038.27
4607.59	1023.89
4610.25	1011.64
4612.9	1010.32
4615.55	1015.63
4618.2	1050.77
4620.85	1046.29
4623.5	1054.96
4626.14	1027.12
4628.79	1024.68
4631.43	1013.22
4634.08	1029.28
4636.72	1019.93
4639.36	1019.33
4642	1021.17
4644.64	1009.99
4647.28	1031.23
4649.92	1013.89
4652.56	1009.26
4655.19	1007.98
4657.83	967.558
4660.46	988.706
4663.1	1000.98
4665.73	984.871
4668.36	989.034
4670.99	1012.22
4673.62	1010.77
4676.24	970.029
4678.87	985.335
4681.5	1000.66
4684.12	1003.65
4686.75	1033.63
4689.37	973.642
4691.99	1011.5
4694.61	1002.01
4697.23	1000.44
4699.85	957.09
4702.47	970.062
4705.09	1003.38
4707.7	972.207
4710.32	957.964
4712.93	982.19
4715.55	953.11
4718.16	942.169
4720.77	992.272
4723.38	950.727
4725.99	935.323
4728.6	961.906
4731.21	961.269
4733.81	969.718
4736.42	931.468
4739.02	962.57
4741.63	977.636
4744.23	959.736
4746.83	948.422
4749.43	965.598
4752.03	962.294
4754.63	991.943
4757.23	932.892
4759.82	911.498
4762.42	967.544
4765.01	916.69
4767.61	953.867
4770.2	951.984
4772.79	939.842
4775.38	900.31
4777.97	944.108
4780.56	921.665
4783.15	931.234
4785.74	919.076
4788.32	929.813
4790.91	918.873
4793.49	929.678
4796.07	929.148
4798.66	928.679
4801.24	894.978
4803.82	929.12
4806.4	920.907
4808.98	921.835
4811.55	913.611
4814.13	888.087
4816.71	918.087
4819.28	906.491
4821.85	919.215
4824.43	916.902
4827	921.484
4829.57	906.468
4832.14	907.699
4834.71	891.564
4837.28	890.658
4839.84	909.685
4842.41	899.285
4844.97	887.581
4847.54	909.799
4850.1	883.279
4852.66	889.115
4855.22	926.915
4857.78	874.062
4860.34	888.163
4862.9	894.833
4865.46	887.156
4868.01	862.153
4870.57	881.884
4873.12	854.064
4875.68	867.739
4878.23	894.447
4880.78	899.734
4883.33	857.471
4885.88	888.898
4888.43	857.333
4890.98	850.685
4893.53	871.413
4896.07	868.279
4898.62	843.678
4901.16	848.832
4903.7	854.038
4906.25	859.114
4908.79	865.312
4911.33	853.461
4913.87	839.152
4916.41	829.643
4918.94	848.851
4921.48	839.384
4924.02	874.173
4926.55	849.169
4929.08	848.154
4931.62	840.172
4934.15	852.52
4936.68	834.893
4939.21	862.519
4941.74	837.499
4944.27	847.448
4946.79	850.234
4949.32	808.687
4951.85	822.248
4954.37	819.063
4956.9	826.799
4959.42	831.008
4961.94	832.995
4964.46	797.849
4966.98	825.222
4969.5	836.824
4972.02	827.899
4974.53	850.365
4977.05	828.125
4979.57	779.23
4982.08	815.107
4984.59	808.614
4987.1	791.195
4989.62	789.53
4992.13	819.468
4994.64	798.388
4997.15	816.371
4999.65	801.447