File: Data/3-Raman/raw/bu19w-ff07b-fi02-v_150 (500nm)_532nm_edge_100%_x100_vis_lwd_h50um_15sx2_01.txt
#Acq. time (s)=	15
#Accumulations=	2
#Range (cm-¹)=	50...5000
#Windows=	1
#Auto scanning=	Off
#Autofocus=	Off
#Macrospot=	Off
#AutoExposure=	Off
#Spike filter=	Multiple accum.
#Delay time (s)=	2
#Binning=	1
#Readout mode=	Signal
#DeNoise=	Off
#ICS correction=	On
#Dark correction=	Off
#Inst. Process=	Off
#Detector Gain=	Best Dynamic
#Detector ADC=	50 kHz HS
#Detector temperature (°C)=	-60.09
#Instrument=	LabRAM HR Evol
#Detector=	SIN-EM FIVIS
#Objective=	x100_VIS_LWD
#Grating=	150 (500nm)
#ND Filter=	100%
#Laser=	532nm_Edge
#Hole=	49.98
#Temperature=	0
#Range=	Visible
#StageXY=	75x50mm Scan+
#StageZ=	Z motor
#X (µm)=	0
#Y (µm)=	0
#Z (µm)=	-44.8
#Full time(s)=	34
#Project=	21_05_28
#Sample=	BU19w
#Site=
#Title=	BU19w-FF07b-FI02-V_150 (500nm)_532nm_Edge_100%_x100_VIS_LWD_H50um_15sX2
#Remark=
#Date=	28.05.2021 15:42
#Acquired=	28.05.2021 15:42:54
51.5961	16282.4
56.2453	15374.7
60.8921	12981.6
65.5367	10731.5
70.1768	10924.6
74.8167	9784.26
79.4543	6192.24
84.0897	4453.26
88.7227	3683.17
93.3513	3078.01
97.9798	2686.77
102.606	2314.05
107.23	2134.97
111.851	1898.27
116.469	1777.9
121.086	1692.32
125.7	1522.99
130.313	1469.76
134.921	1417.14
139.529	1378.37
144.134	1326.37
148.738	1307.64
153.337	1222.78
157.936	1222.96
162.532	1212.32
167.126	1473.65
171.716	1924.58
176.306	1695.21
180.894	1288.8
185.477	1242.23
190.06	1412.23
194.64	2434.87
199.219	4245.36
203.793	3189.62
208.367	1697.12
212.939	1238.36
217.506	1162.47
222.073	1111.04
226.638	1121.86
231.199	1132.43
235.759	1159.98
240.318	1169.06
244.872	1315.78
249.425	1375.61
253.977	1682.43
258.524	2002.05
263.071	1826.37
267.616	1630.4
272.156	1411.77
276.697	1363.33
281.233	1649.72
285.769	2639.47
290.303	3928.88
294.832	3368.04
299.361	2085.35
303.886	1695.08
308.411	1782.12
312.934	2401.22
317.452	2409.74
321.97	1816.37
326.484	1463.97
330.998	1411.18
335.507	1581.8
340.017	1953.91
344.524	1842.32
349.027	1527.22
353.53	1399.1
358.028	1565.3
362.527	1695.75
367.021	1523.25
371.515	1291.76
376.004	1263.72
380.494	1342.69
384.979	1268.06
389.465	1202.51
393.946	1296.47
398.427	1489.14
402.903	1543.58
407.38	1592.4
411.852	1475.98
416.324	1277.89
420.792	1242.59
425.26	1349.06
429.723	1473.44
434.187	1274.5
438.646	1139.57
443.105	1077.99
447.56	1060.7
452.015	1088.45
456.466	1158.39
460.914	1364.26
465.362	1862.31
469.807	1919.1
474.251	1397.48
478.69	1211.64
483.13	1157.56
487.566	1113.59
491.999	1149.3
496.432	1302.12
500.861	1338.1
505.29	1408.28
509.715	1459.91
514.138	1350.81
518.56	1272.97
522.979	1215.24
527.395	1216.76
531.811	1154.92
536.223	1147.65
540.635	1168.21
545.042	1210.75
549.448	1204.7
553.853	1206.59
558.255	1196.16
562.654	1239.62
567.053	1198.59
571.448	1245.35
575.841	1236.26
580.232	1193.74
584.622	1158.85
589.009	1178.45
593.393	1363.74
597.777	1838.19
602.157	2122.51
606.535	1775.75
610.913	1451.45
615.287	1476.61
619.659	1714.3
624.029	1965.34
628.398	1708.1
632.763	1411.71
637.127	1252.93
641.488	1186.08
645.849	1246.85
650.206	1253.44
654.561	1268.48
658.914	1197.66
663.267	1252.99
667.615	1266.81
671.962	1304.05
676.307	1426.31
680.649	1436.52
684.991	1488.91
689.33	1543.06
693.666	1438.03
698	1260.4
702.332	1190.19
706.662	1165.62
710.992	1111.74
715.318	1113.43
719.641	1109.62
723.963	1106.45
728.283	1084.97
732.6	1127.21
736.918	1075.5
741.231	1140.43
745.542	1119.22
749.852	1144.89
754.159	1109.14
758.464	1132.63
762.767	1172.81
767.068	1184.11
771.369	1234.07
775.666	1314.19
779.961	1500.4
784.254	1820.11
788.545	2144.57
792.834	2124.58
797.12	1830.16
801.405	1525.39
805.688	1396.04
809.968	1321.17
814.247	1257.51
818.524	1209.44
822.798	1167.93
827.071	1175.16
831.341	1194.62
835.612	1163.42
839.878	1161.87
844.142	1133.7
848.405	1129.37
852.665	1132.09
856.923	1163.47
861.18	1152.92
865.434	1176.29
869.686	1170.64
873.936	1127.4
878.185	1124.57
882.431	1139
886.675	1147.43
890.915	1140.97
895.155	1127.58
899.393	1162.88
903.63	1165.97
907.864	1169.59
912.096	1172.88
916.326	1137.93
920.554	1175.18
924.78	1168.73
929.004	1183.17
933.227	1199
937.447	1187.84
941.665	1189.22
945.881	1221.45
950.095	1215.1
954.305	1342.32
958.516	1398.02
962.724	1443.14
966.93	1447.95
971.134	1424.31
975.337	1478.38
979.537	1503.96
983.735	1457.8
987.93	1379.88
992.124	1294.75
996.316	1294.2
1000.51	1262.67
1004.7	1237.71
1008.88	1305.3
1013.06	1275.22
1017.25	1274.57
1021.43	1315.47
1025.61	1252.63
1029.78	1302.43
1033.96	1312.31
1038.13	1342.17
1042.3	1362.62
1046.47	1440.4
1050.63	1517.44
1054.8	1706.17
1058.96	2116.7
1063.12	2700.66
1067.28	2625.38
1071.44	2096.25
1075.59	1779.23
1079.74	1651.64
1083.89	1605.36
1088.04	1754.05
1092.19	1970.21
1096.33	2449.03
1100.48	2912.94
1104.62	2823.28
1108.76	2439.97
1112.89	2194.73
1117.03	2305.22
1121.16	2414.8
1125.29	2379.01
1129.42	2276.57
1133.55	2209.24
1137.68	2252.84
1141.8	2345.74
1145.92	2326.2
1150.04	2102.86
1154.16	1886.01
1158.27	1835.27
1162.39	1943.02
1166.5	2212.17
1170.61	2301.1
1174.72	2113.89
1178.82	1854.49
1182.93	1691.2
1187.03	1581.17
1191.13	1463.38
1195.23	1451.04
1199.33	1408.67
1203.42	1421.13
1207.51	1436.44
1211.6	1463.87
1215.69	1424.57
1219.78	1401.73
1223.86	1388.25
1227.95	1468.39
1232.03	1483.7
1236.11	1543.1
1240.18	1523.36
1244.26	1542.25
1248.33	1612.64
1252.41	1718.84
1256.48	1655.67
1260.54	1603.72
1264.61	1562.94
1268.67	1460.32
1272.74	1430.89
1276.8	1452.57
1280.86	2189.51
1284.91	2700.31
1288.97	1676.93
1293.02	1391
1297.07	1376.54
1301.12	1424.41
1305.17	1324.88
1309.21	1355.26
1313.25	1370.36
1317.3	1347.68
1321.34	1331.79
1325.37	1348.61
1329.41	1331.05
1333.44	1323.42
1337.48	1350.45
1341.5	1362.15
1345.53	1378.65
1349.56	1345.21
1353.59	1347.74
1357.61	1374.17
1361.63	1363.7
1365.65	1381.23
1369.66	1456.24
1373.68	1374.44
1377.69	1422.22
1381.7	1596.23
1385.72	3402.14
1389.72	3088.19
1393.73	1638.34
1397.73	1406.64
1401.74	1420.91
1405.74	1510.02
1409.73	1525.42
1413.73	1403.9
1417.73	1357.26
1421.72	1361.9
1425.71	1374.25
1429.7	1355.3
1433.69	1351.29
1437.67	1346.25
1441.66	1379.74
1445.64	1383.4
1449.62	1385.98
1453.6	1354.79
1457.57	1352.08
1461.55	1364.89
1465.52	1329.02
1469.49	1370.8
1473.46	1339.03
1477.43	1366
1481.39	1361.39
1485.36	1383.1
1489.32	1376.32
1493.28	1340.39
1497.24	1360.13
1501.19	1357.58
1505.15	1352.36
1509.1	1396.12
1513.05	1376.79
1517	1337.17
1520.95	1352.08
1524.9	1340.87
1528.84	1372.44
1532.78	1368.31
1536.72	1362.27
1540.66	1361.12
1544.6	1361.91
1548.53	1406.31
1552.46	1388.7
1556.4	1381.57
1560.32	1361.66
1564.25	1362.9
1568.18	1370.77
1572.1	1418.14
1576.02	1399.77
1579.94	1349.51
1583.86	1392.83
1587.78	1376.23
1591.69	1375.99
1595.61	1383.43
1599.52	1396.61
1603.43	1370.53
1607.34	1383.08
1611.24	1391.81
1615.15	1359.42
1619.05	1383.78
1622.95	1371.64
1626.85	1384.62
1630.74	1406.39
1634.64	1398.94
1638.53	1398.12
1642.42	1462.79
1646.31	1380.27
1650.2	1399.41
1654.09	1384.11
1657.97	1399.39
1661.86	1425.21
1665.74	1397.91
1669.62	1411.77
1673.49	1412.7
1677.37	1409.7
1681.24	1406.9
1685.12	1404.7
1688.99	1425.4
1692.86	1418.94
1696.72	1438.11
1700.59	1446.48
1704.45	1388.73
1708.31	1397.51
1712.17	1391.71
1716.03	1419.11
1719.89	1417.14
1723.74	1398.23
1727.6	1443.32
1731.45	1439.11
1735.3	1420.97
1739.14	1422.39
1742.99	1400.3
1746.83	1453.8
1750.68	1424.33
1754.52	1463.22
1758.36	1428.67
1762.19	1408.58
1766.03	1409.71
1769.86	1432.75
1773.69	1427.71
1777.53	1459.93
1781.35	1432.14
1785.18	1457.71
1789	1402.18
1792.83	1462.68
1796.65	1417.38
1800.47	1479.96
1804.29	1434.48
1808.1	1456.61
1811.92	1474.84
1815.73	1430.57
1819.54	1380.91
1823.35	1454.48
1827.16	1441.92
1830.97	1445
1834.77	1429.8
1838.58	1455.8
1842.38	1470.23
1846.18	1443.9
1849.97	1470.35
1853.77	1457.63
1857.56	1436.17
1861.36	1481.49
1865.15	1468.75
1868.93	1436.72
1872.72	1466.13
1876.51	1461.5
1880.29	1467.16
1884.07	1478.03
1887.86	1443.83
1891.63	1440.8
1895.41	1509.58
1899.19	1469.77
1902.96	1466.5
1906.73	1507.7
1910.5	1478.17
1914.27	1446.37
1918.04	1492.14
1921.8	1477.98
1925.57	1460.21
1929.33	1457.48
1933.09	1492.99
1936.85	1475.5
1940.6	1466.28
1944.36	1471.95
1948.11	1502.01
1951.87	1459.65
1955.61	1507.7
1959.36	1494.9
1963.11	1503.19
1966.86	1498.25
1970.6	1520.06
1974.34	1505.63
1978.08	1478.75
1981.82	1514.36
1985.56	1523.45
1989.29	1538.86
1993.02	1495.3
1996.75	1516.66
2000.49	1524.66
2004.21	1503.07
2007.94	1462.92
2011.67	1530.43
2015.39	1502.97
2019.11	1486.45
2022.83	1522.1
2026.55	1460.6
2030.27	1497.2
2033.98	1529.92
2037.69	1518.31
2041.41	1531.28
2045.12	1514.83
2048.82	1526.79
2052.53	1528.07
2056.24	1505.63
2059.94	1514.2
2063.64	1519.14
2067.34	1524.47
2071.04	1525.34
2074.74	1540.07
2078.43	1538.33
2082.13	1524.64
2085.82	1516.26
2089.51	1548.78
2093.2	1541.61
2096.88	1532.38
2100.57	1516.36
2104.25	1516.54
2107.94	1564.83
2111.62	1542.18
2115.3	1540.88
2118.97	1552.39
2122.65	1546.55
2126.32	1539.46
2129.99	1535.84
2133.66	1566.33
2137.33	1553.2
2141	1571.21
2144.67	1548.38
2148.33	1523.68
2151.99	1537.6
2155.66	1567.12
2159.31	1557.24
2162.97	1553.99
2166.63	1575.63
2170.28	1595.68
2173.94	1565.34
2177.59	1582.73
2181.24	1582.12
2184.89	1590.53
2188.53	1562.99
2192.18	1560.62
2195.82	1623.52
2199.46	1581.2
2203.1	1563.6
2206.74	1611.03
2210.38	1579.32
2214.01	1583.45
2217.65	1588.59
2221.28	1597.46
2224.91	1632.2
2228.54	1571.12
2232.16	1652.9
2235.79	1630.66
2239.41	1610.14
2243.04	1621.04
2246.66	1633.77
2250.28	1641.03
2253.89	1623.34
2257.51	1630
2261.12	1607.66
2264.74	1596.28
2268.35	1624.44
2271.96	1583.5
2275.57	1640.85
2279.17	1618.71
2282.78	1629.4
2286.38	1595.7
2289.98	1644.15
2293.58	1595.03
2297.18	1614.03
2300.78	1596.19
2304.37	1601.73
2307.97	1598.41
2311.56	1594.85
2315.15	1609.06
2318.74	1612.57
2322.33	1653.6
2325.91	1685.04
2329.5	1792.81
2333.08	1668.78
2336.66	1635.37
2340.24	1615.95
2343.82	1632.14
2347.4	1649.94
2350.97	1635.71
2354.54	1615.84
2358.12	1606.21
2361.69	1601.15
2365.26	1614.68
2368.82	1622.7
2372.39	1607.93
2375.95	1630.06
2379.52	1626.32
2383.08	1641.22
2386.64	1638.76
2390.19	1651.28
2393.75	1627.39
2397.31	1627.89
2400.86	1615.19
2404.41	1621.71
2407.96	1607.35
2411.51	1641.37
2415.06	1618.91
2418.6	1631.72
2422.15	1624.57
2425.69	1642.67
2429.23	1635.4
2432.77	1648.77
2436.31	1643.09
2439.84	1633.84
2443.38	1667.51
2446.91	1667.77
2450.44	1633.74
2453.97	1639.23
2457.5	1654.95
2461.03	1656.09
2464.55	1660.84
2468.08	1637.78
2471.6	1666.08
2475.12	1630.26
2478.64	1671.57
2482.16	1653.72
2485.67	1678.6
2489.19	1663.81
2492.7	1649.98
2496.21	1641.81
2499.72	1643.61
2503.23	1636.44
2506.74	1663.56
2510.25	1669.71
2513.75	1654.56
2517.25	1625.93
2520.75	1669.09
2524.25	1672.06
2527.75	1656.36
2531.25	1649.42
2534.74	1656.58
2538.24	1649.46
2541.73	1698.1
2545.22	1684.79
2548.71	1690.68
2552.2	1632.87
2555.68	1685.52
2559.17	1681.66
2562.65	1672.26
2566.13	1661.69
2569.61	1652.53
2573.09	1672.73
2576.57	1633.37
2580.04	1678.7
2583.51	1688.57
2586.99	1683.35
2590.46	1692.84
2593.93	1697.68
2597.4	1682.24
2600.86	1690.16
2604.33	1666.35
2607.79	1698.06
2611.25	1640.1
2614.71	1711.52
2618.17	1667.39
2621.63	1643.66
2625.09	1660.93
2628.54	1668.12
2631.99	1681.76
2635.45	1686.33
2638.9	1640.54
2642.34	1683.58
2645.79	1686.03
2649.24	1658.76
2652.68	1676.93
2656.12	1696.5
2659.56	1699.5
2663.01	1682.4
2666.44	1670.89
2669.88	1691.44
2673.32	1689.23
2676.75	1721.08
2680.18	1659.42
2683.61	1638.56
2687.04	1677.13
2690.47	1660.77
2693.9	1682.28
2697.32	1654.07
2700.75	1679.32
2704.17	1677.62
2707.59	1695.52
2711.01	1659.74
2714.43	1650.33
2717.84	1673.83
2721.26	1647.36
2724.67	1645.31
2728.08	1651.8
2731.49	1670.56
2734.9	1692.07
2738.31	1699.57
2741.71	1691.99
2745.12	1654.95
2748.52	1627.96
2751.92	1688.39
2755.32	1644.32
2758.72	1658.38
2762.12	1653.64
2765.52	1672.96
2768.91	1667.52
2772.3	1645.78
2775.7	1663.47
2779.09	1638.48
2782.47	1673.53
2785.86	1685.84
2789.25	1675.5
2792.63	1659.47
2796.01	1651.87
2799.4	1663.04
2802.78	1630.78
2806.15	1630.45
2809.53	1662.87
2812.91	1682.97
2816.28	1665.54
2819.65	1638.76
2823.03	1646.83
2826.4	1645.77
2829.76	1630.86
2833.13	1631.1
2836.5	1661.45
2839.86	1658.54
2843.22	1644.78
2846.59	1637.93
2849.95	1635.4
2853.3	1621.11
2856.66	1643.03
2860.02	1635.29
2863.37	1604.32
2866.72	1635.22
2870.08	1638.04
2873.43	1653.91
2876.77	1623.68
2880.12	1634.76
2883.47	1644.87
2886.81	1627.5
2890.15	1653.49
2893.5	1640.69
2896.84	1659.61
2900.17	1629.13
2903.51	1609.72
2906.85	1598.63
2910.18	1616.72
2913.52	1630.91
2916.85	1633.63
2920.18	1605.83
2923.51	1655.5
2926.83	1653
2930.16	1657.81
2933.48	1674.7
2936.81	1661.13
2940.13	1669.25
2943.45	1703.75
2946.77	1655.4
2950.09	1643.87
2953.4	1624.77
2956.72	1648.96
2960.03	1619.88
2963.34	1642.58
2966.65	1629.73
2969.96	1655.82
2973.27	1654.07
2976.58	1651.45
2979.88	1611.57
2983.19	1630.6
2986.49	1603.75
2989.79	1595.76
2993.09	1595.33
2996.39	1615.65
2999.68	1649.24
3002.98	1645.22
3006.27	1552.77
3009.57	1610.96
3012.86	1604.31
3016.15	1579.79
3019.43	1594.79
3022.72	1590.92
3026.01	1569.12
3029.29	1578.47
3032.57	1591.59
3035.86	1618.82
3039.14	1594.02
3042.41	1609.88
3045.69	1586.04
3048.97	1580.18
3052.24	1599.9
3055.52	1586.5
3058.79	1555.95
3062.06	1565.67
3065.33	1576.57
3068.6	1574.95
3071.86	1555.9
3075.13	1569.66
3078.39	1548.01
3081.65	1567.58
3084.91	1581.86
3088.17	1624.55
3091.43	1537.59
3094.69	1520.94
3097.95	1613.56
3101.2	1549.36
3104.45	1554.27
3107.7	1581.79
3110.95	1573.88
3114.2	1619.74
3117.45	1566.72
3120.7	1586.11
3123.94	1555.01
3127.18	1598.19
3130.43	1577.49
3133.67	1559.67
3136.91	1585.65
3140.14	1567.69
3143.38	1573.54
3146.61	1570.83
3149.85	1585.37
3153.08	1559.9
3156.31	1556.29
3159.54	1557.49
3162.77	1596.81
3166	1565.52
3169.22	1607.57
3172.45	1598.92
3175.67	1576.85
3178.89	1573.73
3182.11	1588.71
3185.33	1581.79
3188.55	1609.01
3191.77	1568.49
3194.98	1596.61
3198.2	1575.14
3201.41	1612.7
3204.62	1616.98
3207.83	1621.32
3211.04	1615.26
3214.25	1621.69
3217.45	1583.51
3220.66	1577.68
3223.86	1597.59
3227.06	1596.74
3230.26	1597.82
3233.46	1601.88
3236.66	1607.74
3239.85	1596.82
3243.05	1591.69
3246.24	1618.08
3249.44	1576.83
3252.63	1555.72
3255.82	1612.87
3259.01	1586.04
3262.19	1592.38
3265.38	1573.66
3268.56	1584.33
3271.75	1576.69
3274.93	1601.43
3278.11	1543.05
3281.29	1624.73
3284.47	1581.98
3287.64	1579.37
3290.82	1580.45
3293.99	1569.26
3297.17	1631.38
3300.34	1600.15
3303.51	1593.1
3306.68	1547.59
3309.84	1573.3
3313.01	1612.03
3316.18	1608.83
3319.34	1599.9
3322.5	1609.88
3325.66	1566.83
3328.82	1591.05
3331.98	1624.72
3335.14	1617.82
3338.29	1594.08
3341.45	1616.72
3344.6	1614.86
3347.75	1590.78
3350.9	1603.86
3354.05	1585.81
3357.2	1620.73
3360.35	1614.26
3363.49	1579.69
3366.64	1634.74
3369.78	1615.39
3372.92	1593.26
3376.06	1614.72
3379.2	1637.23
3382.34	1601.24
3385.48	1654.02
3388.61	1603.88
3391.75	1630.37
3394.88	1678.59
3398.01	1667.7
3401.14	1715.56
3404.27	1701.02
3407.4	1742.67
3410.52	1787.34
3413.65	1834.92
3416.77	1992.66
3419.89	2222.98
3423.01	2856.98
3426.13	4393.09
3429.25	7118.17
3432.37	7189.73
3435.49	4467.98
3438.6	2758.04
3441.72	2208.79
3444.83	1951.66
3447.94	1793.49
3451.05	1764.09
3454.16	1732.57
3457.26	1658.19
3460.37	1625.54
3463.47	1663.26
3466.58	1652.38
3469.68	1622.3
3472.78	1652.66
3475.88	1638.95
3478.98	1633.88
3482.07	1686.56
3485.17	1726.93
3488.26	1714.48
3491.36	1759.89
3494.45	1791.59
3497.54	1889.25
3500.63	2045.2
3503.72	2192.62
3506.81	2519.57
3509.89	2758.59
3512.98	2863.74
3516.06	2745.41
3519.14	2456.23
3522.22	2219.68
3525.3	1984.23
3528.38	1856.69
3531.45	1723.41
3534.53	1643.49
3537.61	1592.05
3540.68	1602.14
3543.75	1527.01
3546.82	1539.41
3549.89	1497.16
3552.96	1491.35
3556.03	1484.46
3559.09	1431.44
3562.16	1493.89
3565.22	1420.62
3568.28	1433.32
3571.34	1402.87
3574.4	1393.53
3577.46	1409.86
3580.52	1409.95
3583.57	1376.73
3586.63	1380.38
3589.68	1402.03
3592.73	1353.33
3595.78	1385.19
3598.83	1353.43
3601.88	1360.52
3604.93	1322.01
3607.97	1357.24
3611.02	1291.24
3614.06	1357.55
3617.1	1346.29
3620.14	1362.46
3623.18	1318.31
3626.22	1361.93
3629.26	1289.68
3632.3	1342.7
3635.33	1288.27
3638.36	1304.79
3641.4	1302.67
3644.43	1302.57
3647.46	1289.64
3650.49	1242.48
3653.51	1290.53
3656.54	1289.88
3659.57	1272.34
3662.59	1285.72
3665.61	1264.01
3668.63	1257.72
3671.65	1257.37
3674.67	1258.03
3677.69	1241.77
3680.71	1223.68
3683.72	1231.96
3686.74	1233.64
3689.75	1215.49
3692.76	1207.77
3695.77	1208.58
3698.78	1231.9
3701.79	1218.52
3704.79	1179.49
3707.8	1182.19
3710.81	1210.41
3713.81	1162.5
3716.81	1209.52
3719.81	1206.23
3722.81	1219.92
3725.81	1220.19
3728.81	1208.91
3731.8	1159.46
3734.8	1199.4
3737.79	1181.12
3740.78	1180.82
3743.77	1186.1
3746.76	1191.27
3749.75	1148.78
3752.74	1212.66
3755.73	1206.19
3758.71	1191.21
3761.7	1229.32
3764.68	1173.47
3767.66	1199.15
3770.64	1172.85
3773.62	1165.61
3776.6	1170.75
3779.58	1171.23
3782.55	1193.51
3785.53	1131.75
3788.5	1158.83
3791.47	1164.26
3794.44	1151.01
3797.41	1126.52
3800.38	1182.33
3803.35	1151.46
3806.32	1171.63
3809.28	1172.01
3812.24	1126.15
3815.21	1164.43
3818.17	1161.16
3821.13	1141.84
3824.09	1148.1
3827.04	1143.07
3830	1129.53
3832.96	1147.26
3835.91	1127.16
3838.86	1152.68
3841.82	1159.23
3844.77	1146.75
3847.72	1134.29
3850.67	1129.47
3853.61	1146.64
3856.56	1120.92
3859.5	1136.24
3862.45	1116.22
3865.39	1133.42
3868.33	1127.66
3871.27	1130.43
3874.21	1129.32
3877.15	1095.54
3880.09	1118.24
3883.02	1126.44
3885.96	1125.86
3888.89	1146.34
3891.82	1133.13
3894.75	1104.47
3897.68	1112.21
3900.61	1115.97
3903.54	1094.7
3906.47	1089.65
3909.39	1088.57
3912.31	1087.38
3915.24	1158.15
3918.16	1107.78
3921.08	1085.49
3924	1120.58
3926.92	1107.55
3929.83	1071.41
3932.75	1092.76
3935.67	1078.91
3938.58	1115.09
3941.49	1109.33
3944.4	1089.1
3947.31	1086.17
3950.22	1088.14
3953.13	1072.95
3956.04	1105.69
3958.94	1067.66
3961.85	1090.98
3964.75	1063.57
3967.65	1089.89
3970.55	1056.82
3973.45	1072.69
3976.35	1075.11
3979.25	1046.72
3982.15	1069.17
3985.04	1067.59
3987.94	1059.21
3990.83	1056.57
3993.72	1077.85
3996.61	1062.78
3999.5	1054.41
4002.39	1069.21
4005.28	1023.34
4008.16	1092.16
4011.05	1048.27
4013.93	1067.97
4016.81	1068.4
4019.7	1048.57
4022.58	1040.3
4025.46	1047.48
4028.33	1041.16
4031.21	1054.17
4034.09	1034.35
4036.96	1036.77
4039.84	1057.63
4042.71	1034.89
4045.58	1054.6
4048.45	1017.18
4051.32	1044.76
4054.19	1043.31
4057.05	1033.23
4059.92	1030.87
4062.78	1042.07
4065.65	1028.98
4068.51	1022.68
4071.37	1031.92
4074.23	1048.96
4077.09	1022.16
4079.95	1066.45
4082.81	1041.57
4085.66	1016.68
4088.52	1026.83
4091.37	1011.62
4094.22	1024.78
4097.07	997.823
4099.92	1031.49
4102.77	1034.85
4105.62	1025.46
4108.47	1007.14
4111.31	996.652
4114.16	1004.63
4117	1002.73
4119.84	991.87
4122.69	975.156
4125.53	1016.3
4128.36	1005.6
4131.2	987.346
4134.04	986.85
4136.88	991.562
4139.71	1014.62
4142.54	988.785
4145.38	1000.45
4148.21	980.221
4151.04	967.892
4153.87	1018.01
4156.69	1001.17
4159.52	991.749
4162.35	996.394
4165.17	987.473
4168	973.648
4170.82	977.477
4173.64	956.912
4176.46	969.624
4179.28	965.712
4182.1	973.616
4184.91	969.818
4187.73	986.619
4190.54	980.947
4193.36	961.722
4196.17	940.626
4198.98	969.619
4201.79	983.902
4204.6	957.042
4207.41	997.842
4210.22	972.903
4213.02	960.674
4215.83	975.955
4218.63	961.33
4221.44	986.032
4224.24	966.301
4227.04	953.314
4229.84	933.551
4232.64	949.4
4235.43	965.405
4238.23	946.792
4241.02	949.01
4243.82	941.313
4246.61	923.695
4249.4	948.852
4252.19	950.019
4254.98	956.158
4257.77	929.195
4260.56	953.255
4263.35	953.341
4266.13	931.371
4268.92	957.675
4271.7	937.721
4274.48	924.743
4277.26	901.458
4280.04	972.917
4282.82	914.061
4285.6	881.313
4288.38	926.32
4291.15	921.668
4293.93	935.199
4296.7	936.717
4299.47	879.51
4302.25	917.503
4305.02	958.569
4307.79	870.717
4310.55	914.891
4313.32	915.492
4316.09	925.094
4318.85	931.566
4321.62	885.045
4324.38	921.91
4327.14	881.352
4329.9	895.811
4332.66	895.913
4335.42	895.051
4338.18	873.717
4340.94	868.854
4343.69	899.673
4346.45	896.953
4349.2	891.252
4351.95	914.134
4354.7	907.67
4357.45	878.602
4360.2	882.23
4362.95	903.206
4365.7	870.019
4368.44	878.727
4371.19	901.894
4373.93	899.271
4376.68	850.433
4379.42	846.66
4382.16	878.817
4384.9	869.952
4387.64	863.33
4390.37	833.365
4393.11	872.527
4395.85	849.503
4398.58	858.85
4401.31	839.189
4404.05	854.635
4406.78	858.749
4409.51	858.754
4412.24	852.414
4414.96	839.687
4417.69	853.994
4420.42	825.21
4423.14	841.421
4425.87	850.397
4428.59	832.226
4431.31	840.168
4434.03	828.221
4436.75	823.545
4439.47	846.063
4442.19	839.168
4444.91	822.848
4447.62	818
4450.34	795.3
4453.05	812.419
4455.76	804.324
4458.47	880.225
4461.19	818.412
4463.89	832.39
4466.6	822.16
4469.31	826.707
4472.02	768.12
4474.72	813.839
4477.43	810.142
4480.13	809.669
4482.83	794.463
4485.53	860.587
4488.23	807.26
4490.93	787.685
4493.63	832.455
4496.33	801.951
4499.02	805.471
4501.72	822.721
4504.41	822.958
4507.11	792.53
4509.8	765.285
4512.49	815.483
4515.18	768.077
4517.87	783.313
4520.56	781.596
4523.24	787.404
4525.93	802.792
4528.61	777.727
4531.3	804.857
4533.98	768.08
4536.66	782.485
4539.34	787.331
4542.02	784.755
4544.7	774.681
4547.38	786.021
4550.05	778.11
4552.73	780.984
4555.4	764.68
4558.08	762.424
4560.75	787.297
4563.42	764.952
4566.09	761.135
4568.76	758.588
4571.43	733.861
4574.1	776.64
4576.77	742.045
4579.43	765.363
4582.1	742.284
4584.76	707.304
4587.42	745.951
4590.08	722.447
4592.74	740.299
4595.4	752.767
4598.06	728.193
4600.72	726.471
4603.38	739.111
4606.03	738.682
4608.69	756.894
4611.34	729.07
4613.99	723.132
4616.64	727.067
4619.29	725.546
4621.94	705.342
4624.59	719.241
4627.24	714.353
4629.89	735.924
4632.53	735.402
4635.18	703.809
4637.82	728.554
4640.46	726.748
4643.1	733.815
4645.74	733.305
4648.38	717.45
4651.02	712.848
4653.66	702.934
4656.3	723.883
4658.93	728.476
4661.57	712.413
4664.2	725.479
4666.83	692.63
4669.46	712.15
4672.09	694.809
4674.72	721.13
4677.35	726.175
4679.98	702.032
4682.61	682.326
4685.23	710.925
4687.86	693.448
4690.48	711.978
4693.1	699.003
4695.73	690.457
4698.34	699.939
4700.96	674.456
4703.58	711.04
4706.2	695.616
4708.82	663.193
4711.43	678.226
4714.05	667.232
4716.66	677.714
4719.28	672.313
4721.89	711.078
4724.5	665.953
4727.11	676.454
4729.72	665.45
4732.33	676.009
4734.93	687.717
4737.54	675.546
4740.14	688.332
4742.75	655.614
4745.35	691.075
4747.95	665.061
4750.55	677.633
4753.15	659.501
4755.75	686.878
4758.35	656.206
4760.95	635.835
4763.54	673.577
4766.14	668.097
4768.73	657.067
4771.33	672.308
4773.92	654.337
4776.51	662.617
4779.1	660.631
4781.69	655.206
4784.28	633.781
4786.87	655.797
4789.45	652.668
4792.04	644.983
4794.63	646.479
4797.21	633.105
4799.79	659.913
4802.37	621.393
4804.95	619.617
4807.53	632.862
4810.11	655.388
4812.69	628.418
4815.27	654.477
4817.84	642.539
4820.42	639.87
4822.99	637.192
4825.57	641.472
4828.14	605.137
4830.71	622.165
4833.28	638.139
4835.85	606.414
4838.42	644.684
4840.98	605.995
4843.55	631.537
4846.12	621.877
4848.68	589.82
4851.24	618.602
4853.81	609.398
4856.37	622.638
4858.93	623.559
4861.49	619.723
4864.05	585.005
4866.61	629.181
4869.16	607.247
4871.72	623.289
4874.27	602.482
4876.83	586.317
4879.38	580.804
4881.93	589.495
4884.49	581.528
4887.04	609.208
4889.58	592.927
4892.13	595.67
4894.68	584.103
4897.23	585.61
4899.77	583.524
4902.32	567.111
4904.86	594.825
4907.4	598.661
4909.95	604.868
4912.49	579.887
4915.03	596.664
4917.57	551.268
4920.1	602.697
4922.64	588.421
4925.18	571.759
4927.71	580.231
4930.25	593.409
4932.78	551.758
4935.31	579.557
4937.84	583.38
4940.38	578.816
4942.9	584.764
4945.43	598.119
4947.96	563.663
4950.49	584.285
4953.01	585.792
4955.54	571.63
4958.06	594.772
4960.59	585.56
4963.11	567.977
4965.63	557.743
4968.15	575.302
4970.67	545.695
4973.19	578.775
4975.71	563.574
4978.22	555.588
4980.74	573.03
4983.25	565.073
4985.77	559.546
4988.28	573.44
4990.79	541.209
4993.3	536.86
4995.81	575.087
4998.32	561.097