File: Data/3-Raman/raw/bu19w-e-ff11-fi02-v_150 (500nm)_633nm_edge_100%_x100_vis_h50um_60sx2_01.txt
#Acq. time (s)=	60
#Accumulations=	2
#Range (cm-¹)=	100...4000
#Windows=	1
#Auto scanning=	Off
#Autofocus=	Off
#Macrospot=	Off
#AutoExposure=	Off
#Spike filter=	Multiple accum.
#Delay time (s)=	2
#Binning=	1
#Readout mode=	Signal
#DeNoise=	Off
#ICS correction=	On
#Dark correction=	Off
#Inst. Process=	Off
#Detector Gain=	Best Dynamic
#Detector ADC=	50 kHz HS
#Detector temperature (°C)=	-60.09
#Instrument=	LabRAM HR Evol
#Detector=	SIN-EM FIVIS
#Objective=	x100_VIS
#Grating=	150 (500nm)
#ND Filter=	100%
#Laser=	633nm_Edge
#Hole=	49.98
#Temperature=	0
#Range=	Visible
#StageXY=	75x50mm Scan+
#StageZ=	Z motor
#X (µm)=	0
#Y (µm)=	0
#Z (µm)=	-280.8
#Full time(mm:ss)=	2:04
#Project=	21_11_04
#Sample=	BU19w
#Site=
#Title=	BU19w-E-FF11-FI02-V_150 (500nm)_633nm_Edge_100%_x100_VIS_H50um_60sX2
#Remark=
#Date=	04.11.2021 16:26
#Acquired=	04.11.2021 16:26:08
102.881	202.598
109.397	188.477
115.908	159.049
122.414	163.942
128.914	158.308
135.409	163.149
141.898	172.722
148.383	165.102
154.861	199.644
161.335	181.553
167.801	138.512
174.264	125.107
180.721	121.216
187.173	109.591
193.62	115.148
200.061	114.055
206.496	114.037
212.926	117.805
219.352	135.876
225.772	194.858
232.185	211.711
238.595	160.169
244.999	125.877
251.397	143.859
257.791	144.718
264.178	135.174
270.561	125.662
276.939	151.265
283.31	146.486
289.678	128.4
296.039	131.131
302.396	140.478
308.746	166.803
315.093	262.972
321.433	321.316
327.768	217.447
334.099	165.535
340.423	141.922
346.743	144.696
353.058	153.094
359.367	154.841
365.671	123.652
371.971	116.952
378.265	102.751
384.553	111.109
390.837	96.1581
397.116	102.873
403.389	108.759
409.657	109.931
415.92	117.655
422.178	130.096
428.431	133.755
434.678	140.049
440.921	145.353
447.158	144.963
453.391	149.218
459.618	132.069
465.84	108.598
472.057	102.929
478.27	104.806
484.477	116
490.679	118.81
496.876	116.974
503.068	128.21
509.255	131.075
515.436	133.98
521.613	141.648
527.785	133.493
533.952	136.658
540.113	127.59
546.27	110.835
552.423	112.807
558.568	95.842
564.711	100.428
570.848	98.3168
576.979	102.698
583.107	114.546
589.228	115.213
595.345	115.073
601.458	126.284
607.565	136.74
613.667	123.926
619.764	133.664
625.856	104.94
631.944	99.4858
638.026	98.557
644.104	110.655
650.177	113.303
656.244	96.137
662.308	95.877
668.365	83.509
674.418	85.3259
680.467	84.3943
686.511	84.4669
692.549	82.7637
698.582	82.9505
704.611	76.5446
710.635	81.351
716.655	81.2939
722.669	81.248
728.679	83.011
734.683	79.1172
740.683	87.3879
746.678	78.8585
752.669	86.2478
758.654	88.1068
764.635	77.0692
770.611	82.9088
776.582	80.3225
782.549	77.6566
788.511	84.352
794.466	84.4114
800.419	85.3416
806.366	89.0297
812.309	90.7873
818.247	80.27
824.18	88.5066
830.108	88.3096
836.033	84.5521
841.952	80.9348
847.865	81.0793
853.776	90.6606
859.681	91.8419
865.58	101.541
871.476	100.849
877.366	101.931
883.253	116.238
889.134	118.135
895.012	110.479
900.883	111.231
906.751	111.904
912.614	104.073
918.473	105.738
924.326	106.606
930.174	117.965
936.019	125.705
941.859	143.152
947.693	158.881
953.525	155.693
959.35	163.843
965.171	166.157
970.988	199.075
976.801	239.516
982.608	262.301
988.411	239.867
994.209	197.377
1000	170.344
1005.79	169.214
1011.58	172.109
1017.36	190.408
1023.13	191.635
1028.9	149.94
1034.67	139.782
1040.43	140.216
1046.19	141.623
1051.94	123.554
1057.69	109.21
1063.44	115.127
1069.17	113.143
1074.91	119.893
1080.64	144.037
1086.37	178.786
1092.09	212.579
1097.8	209.54
1103.52	156.231
1109.22	142.761
1114.93	133.37
1120.63	135.74
1126.32	135.067
1132.01	147.14
1137.7	174.947
1143.38	199.925
1149.06	238.597
1154.73	184.619
1160.4	128.428
1166.06	111.488
1171.72	117.162
1177.38	100.286
1183.03	91.3359
1188.67	94.2412
1194.31	85.5084
1199.95	85.6548
1205.58	81.9992
1211.21	83.2913
1216.84	80.68
1222.46	79.0749
1228.07	80.4533
1233.68	83.8029
1239.29	78.0444
1244.89	77.1987
1250.49	86.3626
1256.08	88.3984
1261.67	80.2295
1267.26	90.2003
1272.84	181.583
1278.42	118.95
1283.99	81.6406
1289.56	86.52
1295.12	82.4545
1300.68	88.4418
1306.23	84.5267
1311.78	79.7161
1317.33	79.9695
1322.87	79.2451
1328.41	78.5488
1333.94	76.8174
1339.47	82.1797
1345	76.2356
1350.52	79.4581
1356.04	81.6313
1361.55	85.8107
1367.06	88.8979
1372.56	97.0847
1378.06	321.959
1383.56	100.085
1389.05	78.4908
1394.53	86.7126
1400.02	107.397
1405.5	72.5596
1410.97	73.7202
1416.44	82.1452
1421.91	82.3356
1427.37	84.6216
1432.83	81.719
1438.28	88.1868
1443.73	84.2212
1449.17	84.397
1454.62	79.2459
1460.05	83.4808
1465.48	79.2737
1470.91	80.3002
1476.34	76.0977
1481.76	71.9289
1487.17	81.4399
1492.59	84.6994
1497.99	84.8492
1503.4	78.691
1508.8	82.0653
1514.19	83.3633
1519.59	83.635
1524.97	90.3394
1530.36	79.9266
1535.74	87.7628
1541.11	89.0887
1546.48	85.984
1551.85	83.8258
1557.21	88.042
1562.57	87.9536
1567.93	87.8633
1573.28	93.1557
1578.62	84.5001
1583.97	84.509
1589.3	92.0828
1594.64	86.7729
1599.97	91.2072
1605.3	87.0511
1610.62	92.7004
1615.94	85.4052
1621.25	85.735
1626.56	89.3494
1631.87	85.2769
1637.17	100.974
1642.47	88.9483
1647.76	79.1245
1653.05	88.0781
1658.34	84.8079
1663.62	93.7056
1668.9	89.2777
1674.18	92.6065
1679.45	90.3728
1684.71	93.6329
1689.98	93.5551
1695.23	100.178
1700.49	92.5434
1705.74	93.0053
1710.99	83.0934
1716.23	93.1681
1721.47	81.1251
1726.7	94.7046
1731.94	103.888
1737.16	89.4637
1742.39	89.635
1747.61	85.276
1752.82	94.4337
1758.03	92.2508
1763.24	99.075
1768.44	90.0603
1773.64	91.2512
1778.84	97.0219
1784.03	102.855
1789.22	87.1161
1794.41	103.291
1799.59	96.6887
1804.76	98.1039
1809.94	101.79
1815.11	96.2449
1820.27	91.8325
1825.43	103.617
1830.59	94.5776
1835.74	102.959
1840.89	104.334
1846.04	94.0081
1851.18	97.6702
1856.32	102.479
1861.45	103.838
1866.58	105.229
1871.71	106.594
1876.83	98.4816
1881.95	102.142
1887.07	91.6036
1892.18	108.176
1897.29	104.644
1902.39	104.753
1907.49	108.514
1912.59	99.3047
1917.68	109.173
1922.77	103.323
1927.86	105.919
1932.94	114.516
1938.02	101.494
1943.09	102.831
1948.16	107.753
1953.23	111.432
1958.29	104.24
1963.35	103.052
1968.41	112.679
1973.46	105.39
1978.51	108.945
1983.55	107.68
1988.59	111.239
1993.63	112.407
1998.66	108.79
2003.69	107.609
2008.72	107.669
2013.74	117.39
2018.76	105.422
2023.77	123.594
2028.78	115.306
2033.79	107.046
2038.79	115.735
2043.79	111.113
2048.79	116.227
2053.78	116.432
2058.77	125.225
2063.76	112.036
2068.74	112.286
2073.72	128.511
2078.69	133.696
2083.66	124.055
2088.63	116.805
2093.59	129.395
2098.55	114.798
2103.51	121.3
2108.46	126.616
2113.41	124.491
2118.36	124.879
2123.3	129.035
2128.24	111.732
2133.17	127.214
2138.11	124.975
2143.03	122.705
2147.96	121.661
2152.88	133.312
2157.79	129.625
2162.71	124.608
2167.62	128.483
2172.52	114.485
2177.43	128.646
2182.32	133.785
2187.22	122.246
2192.11	122.29
2197	121.096
2201.89	127.667
2206.77	131.739
2211.64	124.284
2216.52	132.316
2221.39	137.829
2226.26	121.313
2231.12	133.329
2235.98	136.276
2240.84	123.544
2245.69	136.968
2250.54	137.317
2255.39	125.798
2260.23	134.05
2265.07	130.381
2269.9	126.638
2274.74	138.767
2279.57	137.588
2284.39	133.674
2289.21	121.735
2294.03	131.078
2298.84	132.482
2303.66	132.613
2308.46	134.162
2313.27	134.441
2318.07	162.934
2322.87	137.798
2327.66	142.215
2332.45	138.57
2337.24	133.575
2342.02	143.533
2346.8	138.593
2351.58	136.336
2356.35	138.125
2361.12	141.193
2365.89	145.637
2370.65	132.114
2375.41	155.944
2380.17	143.724
2384.92	141.114
2389.67	128.703
2394.42	144.06
2399.16	134.315
2403.9	149.612
2408.64	142.665
2413.37	145.703
2418.1	137.994
2422.83	137.034
2427.55	144.295
2432.27	154.551
2436.99	142.272
2441.7	146.958
2446.41	144.548
2451.11	129.273
2455.82	151.136
2460.51	145.83
2465.21	143.367
2469.9	149.53
2474.59	144.115
2479.28	145.95
2483.96	149.216
2488.64	156.822
2493.32	157.139
2497.99	154.539
2502.66	146.025
2507.32	141.862
2511.99	170.039
2516.65	155.511
2521.3	151.323
2525.96	169.3
2530.61	142.903
2535.25	150.578
2539.89	153.85
2544.53	148.21
2549.17	161.977
2553.8	162.332
2558.43	168.625
2563.06	158.473
2567.68	155.855
2572.3	169.854
2576.92	161.193
2581.53	156.975
2586.14	152.637
2590.75	175.561
2595.35	160.548
2599.96	160.805
2604.55	177.798
2609.15	152.026
2613.74	164.374
2618.33	155.334
2622.91	166.193
2627.49	158.713
2632.07	175.904
2636.64	182.512
2641.22	173.817
2645.78	166.637
2650.35	167.152
2654.91	169.164
2659.47	177.272
2664.03	169.708
2668.58	190.308
2673.13	167.162
2677.67	167.773
2682.22	159.109
2686.76	170.966
2691.29	166.888
2695.83	167.323
2700.36	170.884
2704.89	159.974
2709.41	173.153
2713.93	167.006
2718.45	175.457
2722.96	172.545
2727.47	174.403
2731.98	172.94
2736.49	176.332
2740.99	165.094
2745.49	171.822
2749.98	163.968
2754.47	185.73
2758.96	172.968
2763.45	166.662
2767.93	170.29
2772.41	173.904
2776.89	175.989
2781.36	164.926
2785.84	185.441
2790.3	177.708
2794.77	178.259
2799.23	173.699
2803.69	184.198
2808.14	171.085
2812.59	169.71
2817.04	166.578
2821.49	202.408
2825.93	177.302
2830.37	196.275
2834.81	169.326
2839.24	172.975
2843.67	180.059
2848.1	183.801
2852.53	173.908
2856.95	172.625
2861.37	179.958
2865.78	175.321
2870.19	182.801
2874.6	179.888
2879.01	180.469
2883.41	184.598
2887.81	190.528
2892.21	178.837
2896.6	175.927
2901	192.552
2905.38	182.476
2909.77	193.727
2914.15	167.33
2918.53	176.68
2922.91	189.708
2927.28	190.241
2931.65	188.998
2936.02	193.095
2940.38	180.754
2944.74	181.083
2949.1	194.09
2953.46	194.375
2957.81	180.025
2962.16	189.442
2966.5	180.587
2970.85	201.118
2975.19	184.936
2979.52	205.562
2983.86	183.843
2988.19	195.425
2992.52	199.686
2996.85	176.042
3001.17	180.336
3005.49	195.948
3009.8	202.245
3014.12	197.216
3018.43	186.559
3022.74	196.722
3027.04	210.645
3031.34	178.689
3035.64	213.53
3039.94	206.273
3044.23	204.755
3048.52	205.112
3052.81	195.812
3057.09	203.904
3061.38	200.391
3065.65	224.019
3069.93	208.867
3074.2	217.026
3078.47	205.731
3082.74	219.788
3087	216.368
3091.27	207.143
3095.52	219.614
3099.78	226.258
3104.03	229.027
3108.28	223.915
3112.53	236.793
3116.77	223.675
3121.01	220.555
3125.25	251.855
3129.49	244.892
3133.72	225.674
3137.95	245.224
3142.18	246.312
3146.4	234.897
3150.62	248.244
3154.84	255.261
3159.06	243.472
3163.27	240.007
3167.48	249.064
3171.69	247.639
3175.89	250.332
3180.09	259.223
3184.29	229.914
3188.49	253.481
3192.68	238.992
3196.87	241.592
3201.06	253.049
3205.24	238.952
3209.42	250.668
3213.6	260.346
3217.78	233.266
3221.95	240.735
3226.12	237.331
3230.29	240.455
3234.45	241.355
3238.61	253.288
3242.77	243.211
3246.93	253.158
3251.08	224.923
3255.23	225.507
3259.38	250.871
3263.53	235.928
3267.67	232.596
3271.81	235.824
3275.95	222.73
3280.08	230.058
3284.21	235.115
3288.34	208.003
3292.47	215.298
3296.59	224.898
3300.71	234.602
3304.83	230.427
3308.95	237.834
3313.06	231.27
3317.17	217.725
3321.27	225.18
3325.38	232.751
3329.48	219.3
3333.58	229.491
3337.67	211.405
3341.77	214.317
3345.86	226.624
3349.95	241.269
3354.03	220.257
3358.11	220.749
3362.19	226.036
3366.27	197.751
3370.34	229.403
3374.42	229.825
3378.48	208.475
3382.55	220.827
3386.61	238.02
3390.68	231.026
3394.73	221.607
3398.79	207.384
3402.84	227.053
3406.89	210.254
3410.94	212.864
3414.98	234.941
3419.03	235.13
3423.06	223.1
3427.1	247.69
3431.14	221.103
3435.17	196.951
3439.2	234.049
3443.22	219.757
3447.25	232.594
3451.27	198.63
3455.28	221.474
3459.3	199.878
3463.31	218.023
3467.32	206.293
3471.33	222.037
3475.34	215.079
3479.34	200.594
3483.34	218.902
3487.33	209.371
3491.33	217.577
3495.32	218.123
3499.31	213.488
3503.3	224.124
3507.28	211.639
3511.26	219.516
3515.24	214.519
3519.22	219.785
3523.19	199.334
3527.16	212.359
3531.13	220.237
3535.1	207.716
3539.06	203.03
3543.02	213.805
3546.98	203.778
3550.93	211.833
3554.89	219.714
3558.84	196.519
3562.78	186.363
3566.73	215.409
3570.67	228.97
3574.61	205.859
3578.55	230.044
3582.48	217.528
3586.41	197.021
3590.35	208.207
3594.27	219.451
3598.2	198.737
3602.12	225.986
3606.04	199.724
3609.95	186.713
3613.87	189.799
3617.78	211.742
3621.69	214.75
3625.6	193.278
3629.5	190.69
3633.4	204.285
3637.3	220.689
3641.2	202.032
3645.09	210.578
3648.98	208.165
3652.87	197.491
3656.76	203.127
3660.64	203.301
3664.53	195.262
3668.4	198.201
3672.28	209.338
3676.16	201.427
3680.03	196.324
3683.9	196.792
3687.76	200.099
3691.63	203.437
3695.49	195.624
3699.35	198.936
3703.2	191.08
3707.06	197.207
3710.91	200.557
3714.76	201.076
3718.6	198.7
3722.45	176.504
3726.29	199.447
3730.13	182.792
3733.97	203.02
3737.8	197.712
3741.63	183.799
3745.46	201.214
3749.29	178.624
3753.11	190.255
3756.93	196.126
3760.75	187.636
3764.57	196.318
3768.39	193.559
3772.2	190.852
3776.01	185.272
3779.81	202.73
3783.62	197.268
3787.42	188.917
3791.22	197.837
3795.02	195.281
3798.81	181.176
3802.61	204.796
3806.4	179.058
3810.18	182.383
3813.97	203.226
3817.75	200.7
3821.53	195.207
3825.31	186.702
3829.09	187.011
3832.86	193.269
3836.63	205.436
3840.4	196.88
3844.17	179.463
3847.93	185.55
3851.69	182.709
3855.45	197.655
3859.21	200.641
3862.96	176.922
3866.71	198.074
3870.46	180.627
3874.21	171.762
3877.95	201.76
3881.69	186.938
3885.44	196.073
3889.17	172.298
3892.91	196.521
3896.64	181.851
3900.37	176.112
3904.1	200.489
3907.82	200.769
3911.55	182.946
3915.27	165.091
3918.99	189.722
3922.7	187.145
3926.42	184.521
3930.13	172.68
3933.84	200.519
3937.54	167.083
3941.25	191.944
3944.95	183.106
3948.65	171.114
3952.35	202.25
3956.04	205.609
3959.73	184.145
3963.42	187.386
3967.11	175.087
3970.8	184.426
3974.48	175.189
3978.16	184.541
3981.84	181.43
3985.52	169.015
3989.19	175.209
3992.86	196.983
3996.53	162.975
3998.37	181.689