File: Data/3-Raman/raw/bu19(2)w-a-ff1-fi05-v_1800 (450-850nm)_532nm_edge_100%_x100_vis_lwd_h100um_30sx2_01.txt
#Acq. time (s)=	30
#Accumulations=	2
#Range (cm-¹)=	1200...2365
#Windows=	3
#Auto scanning=	Off
#Autofocus=	Off
#Macrospot=	Off
#AutoExposure=	Off
#Spike filter=	Multiple accum.
#Delay time (s)=	2
#Binning=	1
#Readout mode=	Signal
#DeNoise=	Off
#ICS correction=	On
#Dark correction=	Off
#Inst. Process=	Off
#Detector Gain=	Best Dynamic
#Detector ADC=	50 kHz HS
#Detector temperature (°C)=	-60.09
#Instrument=	LabRAM HR Evol
#Detector=	SIN-EM FIVIS
#Objective=	x100_VIS_LWD
#Grating=	1800 (450-850nm)
#ND Filter=	100%
#Laser=	532nm_Edge
#Hole=	100.021
#Temperature=	0
#Range=	Visible
#StageXY=	75x50mm Scan+
#StageZ=	Z motor
#X (µm)=	0
#Y (µm)=	0
#Z (µm)=	-9.7
#Full time(mm:ss)=	3:23
#Project=	21_11_26
#Sample=	BU19(2)w
#Site=
#Title=	BU19(2)w-A-FF1-FI05-V_1800 (450-850nm)_532nm_Edge_100%_x100_VIS_LWD_H100um_30sX2
#Remark=
#Date=	26.11.2021 13:31
#Acquired=	26.11.2021 13:31:21
1202.72	126.362
1203.84	116.729
1204.95	114.495
1206.06	115.4
1207.17	111.965
1208.28	111.846
1209.39	108.52
1210.5	106.33
1211.61	109.368
1212.72	103.889
1213.83	109.116
1214.94	103.777
1216.05	105.885
1217.16	102.541
1218.27	100.301
1219.38	110.847
1220.49	95.9485
1221.6	106.517
1222.71	108.492
1223.81	105.119
1224.92	92.3278
1226.03	98.6662
1227.14	98.6452
1228.25	96.3141
1229.35	96.0841
1230.46	94.2348
1231.57	97.1206
1232.67	98.1697
1233.78	97.0966
1234.89	95.0305
1235.99	106.637
1237.1	93.9975
1238.2	93.8756
1239.31	95.8602
1240.41	97.9215
1241.52	91.6401
1242.62	94.7476
1243.73	108.403
1244.83	95.8212
1245.94	98.8732
1247.04	99.8632
1248.14	94.605
1249.25	93.5042
1250.35	95.5922
1251.45	95.5047
1252.56	97.5224
1253.66	97.4529
1254.76	93.3296
1255.87	97.5195
1256.97	102.761
1258.07	106.912
1259.17	101.636
1260.27	95.4334
1261.37	126.623
1262.48	124.806
1263.58	129.684
1264.68	115.451
1265.78	111.157
1266.88	99.6607
1267.98	103.94
1269.08	105.124
1270.18	108.265
1271.28	102.929
1272.38	106.078
1273.47	109.345
1274.57	113.644
1275.67	108.41
1276.77	110.591
1277.87	115.933
1278.97	123.398
1280.07	149.716
1281.16	296.981
1282.26	684.538
1283.36	723.159
1284.45	283.159
1285.55	146.735
1286.65	115.124
1287.75	116.127
1288.84	108.728
1289.94	110.896
1291.03	95.1243
1292.13	90.8984
1293.22	91.9439
1294.32	97.3259
1295.42	92.0733
1296.51	88.0375
1297.61	99.6466
1298.7	96.4191
1299.79	94.2541
1300.89	86.8892
1301.98	85.8431
1303.08	84.8073
1304.17	91.1081
1305.26	84.7615
1306.35	85.741
1307.45	86.7767
1308.54	85.7257
1309.63	83.639
1310.73	85.7602
1311.82	84.7154
1312.91	81.5858
1314	82.613
1315.09	81.5625
1316.18	77.3772
1317.28	78.4178
1318.37	82.6654
1319.46	80.554
1320.55	82.6655
1321.64	77.3268
1322.73	78.309
1323.82	81.4418
1324.91	84.6071
1326	83.4948
1327.09	86.5111
1328.18	85.6023
1329.27	85.7023
1330.35	86.7432
1331.44	82.4516
1332.53	86.5406
1333.62	80.1168
1334.71	72.6745
1335.79	77.8573
1336.88	84.0973
1337.97	73.5808
1339.06	83.9929
1340.14	82.9399
1341.23	79.8021
1342.32	78.7223
1343.4	85.9727
1344.49	76.5494
1345.58	78.6013
1346.66	83.7085
1347.75	80.4773
1348.83	87.7325
1349.92	85.5843
1351	84.4744
1352.09	86.4888
1353.17	78.2164
1354.25	84.5415
1355.34	82.2646
1356.42	85.3701
1357.51	87.4025
1358.59	87.3446
1359.67	86.2435
1360.76	84.0863
1361.84	95.451
1362.92	91.271
1364	83.0126
1365.09	86.1126
1366.17	96.3842
1367.25	94.2095
1368.33	100.405
1369.41	104.565
1370.5	96.265
1371.58	93.0827
1372.66	96.0389
1373.74	99.0622
1374.82	105.21
1375.9	97.992
1376.98	104.123
1378.06	119.523
1379.14	124.869
1380.22	126.863
1381.3	139.968
1382.38	151.12
1383.46	152.952
1384.54	231.806
1385.61	547.067
1386.69	1720.42
1387.77	591.145
1388.85	203.003
1389.93	143.855
1391	115.951
1392.08	110.732
1393.16	105.525
1394.23	91.1551
1395.31	92.1708
1396.39	92.1971
1397.46	97.2632
1398.54	95.1941
1399.62	90.1151
1400.69	86.0492
1401.77	91.2073
1402.84	85.1894
1403.92	90.4
1404.99	98.5421
1406.07	104.628
1407.14	127.145
1408.22	142.559
1409.29	125.163
1410.37	98.5189
1411.44	92.2694
1412.51	77.9055
1413.59	75.0342
1414.66	83.153
1415.73	70.8687
1416.81	78.078
1417.88	74.0023
1418.95	72.9861
1420.02	71.9387
1421.1	69.8264
1422.17	73.9358
1423.24	72.0304
1424.31	73.8428
1425.38	77.9458
1426.45	70.7846
1427.52	72.7625
1428.59	73.7155
1429.67	67.5898
1430.74	69.6965
1431.81	68.7572
1432.87	68.7173
1433.95	73.7352
1435.01	69.66
1436.08	70.6823
1437.15	63.4882
1438.22	66.542
1439.29	80.9055
1440.36	60.4585
1441.43	68.6773
1442.49	69.6933
1443.56	72.7635
1444.63	67.621
1445.7	66.6461
1446.77	65.5969
1447.83	70.6971
1448.9	76.8704
1449.97	62.5004
1451.03	67.5934
1452.1	70.6416
1453.17	65.5137
1454.23	69.6213
1455.3	61.4169
1456.36	64.5042
1457.43	66.5252
1458.49	65.4879
1459.56	63.4482
1460.62	62.4128
1461.69	64.4313
1462.75	62.3384
1463.82	70.4603
1464.88	66.442
1465.94	72.3694
1467.01	68.2635
1468.07	57.029
1469.13	64.159
1470.2	63.0964
1471.26	65.0997
1472.32	53.8615
1473.39	60.9773
1474.45	62.9811
1475.51	67.0611
1476.57	65.0006
1477.63	59.8817
1478.69	57.8243
1479.76	68.9604
1480.82	64.8249
1481.88	62.7701
1482.94	66.8736
1484	66.8843
1485.06	63.7044
1486.12	64.6967
1487.18	67.7419
1488.24	65.6797
1489.3	60.5648
1490.36	61.5579
1491.42	67.59
1492.48	54.4376
1493.53	61.5054
1494.59	59.4797
1495.65	60.4637
1496.71	65.4508
1497.77	64.4212
1498.82	61.3882
1499.88	68.4665
1500.94	57.3649
1502	60.3675
1503.05	66.3954
1504.11	63.3352
1505.17	65.3565
1506.22	67.311
1507.28	60.2615
1508.34	63.2827
1509.39	65.2969
1510.45	55.2269
1511.5	66.2514
1512.56	67.1255
1513.61	65.0415
1514.67	64.0764
1515.72	57.9967
1516.78	68.9722
1517.83	66.9541
1518.88	63.9684
1519.94	59.9708
1520.99	58.9579
1522.05	61.9768
1523.1	64.9572
1524.15	65.8835
1525.2	65.8532
1526.26	64.8768
1527.31	67.9162
1528.36	63.8807
1529.41	68.8633
1530.47	59.829
1531.52	67.8823
1532.57	58.8531
1533.62	62.9251
1534.67	61.9298
1535.72	63.9043
1536.77	62.813
1537.82	60.743
1538.87	63.7027
1539.92	63.795
1540.97	65.9032
1542.02	60.8493
1543.07	61.7884
1544.12	67.7161
1545.17	64.7539
1546.22	58.8047
1547.27	61.8207
1548.32	63.7894
1549.37	64.7511
1550.42	68.7759
1551.46	61.9466
1552.51	60.9423
1553.56	63.905
1554.61	68.8689
1555.65	66.8023
1556.7	61.7863
1557.75	63.7971
1558.79	57.7374
1559.84	60.6692
1560.89	59.6368
1561.93	64.6434
1562.98	62.6755
1564.02	53.662
1565.07	67.7125
1566.11	64.3189
1567.16	60.5892
1568.2	62.6331
1569.25	60.6459
1570.29	61.6127
1571.34	69.6034
1572.38	61.5779
1573.43	65.531
1574.47	58.5343
1575.51	63.5844
1576.56	68.5874
1577.6	61.5173
1578.64	63.4379
1579.69	58.4464
1580.73	62.4501
1581.77	63.4163
1582.81	60.3895
1583.85	65.3555
1584.9	65.3563
1585.94	60.3703
1586.98	62.3125
1588.02	65.2711
1589.06	63.301
1590.1	59.34
1591.14	64.3342
1592.18	65.3139
1593.22	69.2296
1594.26	66.1472
1595.3	67.1505
1596.34	61.1655
1597.38	71.1032
1598.42	64.1507
1599.46	67.0689
1600.5	60.078
1601.54	61.9915
1602.58	66.8757
1603.62	64.837
1604.66	66.7976
1605.69	62.8463
1606.73	64.8512
1607.77	67.8182
1608.81	63.9827
1609.84	71.7915
1610.88	67.7638
1611.92	66.1908
1612.95	64.2185
1613.99	68.1744
1615.03	63.2901
1616.06	64.0798
1617.1	68.8036
1618.13	66.8947
1619.17	69.7809
1620.2	73.1359
1621.24	65.8535
1622.27	67.6883
1623.31	69.1883
1624.34	65.0746
1625.38	70.2454
1626.41	66.8851
1627.45	65.9782
1628.48	68.023
1629.51	66.5727
1630.55	70.9106
1631.53	66.616
1632.57	66.6425
1633.62	72.5449
1634.66	76.5011
1635.71	73.5336
1636.75	69.5572
1637.8	69.5133
1638.84	70.4724
1639.89	69.4838
1640.93	77.3677
1641.98	72.4408
1643.02	72.4214
1644.06	69.4527
1645.11	69.4186
1646.15	73.3717
1647.19	66.4529
1648.24	72.3275
1649.28	71.405
1650.32	74.3517
1651.37	68.5045
1652.41	69.4991
1653.45	70.4639
1654.49	71.4604
1655.53	68.53
1656.57	71.5588
1657.62	69.5822
1658.66	71.5264
1659.7	70.4944
1660.74	72.4512
1661.78	69.5399
1662.82	70.603
1663.86	64.6795
1664.9	68.5813
1665.94	59.6127
1666.98	67.5837
1668.02	70.5029
1669.06	69.5261
1670.1	60.6831
1671.14	69.6212
1672.18	65.6509
1673.21	73.562
1674.25	67.6433
1675.29	67.6783
1676.33	67.6904
1677.37	68.6826
1678.4	67.6559
1679.44	65.6297
1680.48	67.5779
1681.52	68.5383
1682.55	65.5687
1683.59	61.6087
1684.63	64.5519
1685.66	65.5227
1686.7	62.5625
1687.73	59.6103
1688.77	65.5043
1689.81	67.427
1690.84	67.4054
1691.88	62.492
1692.91	65.4407
1693.95	66.3573
1694.98	64.3326
1696.01	60.3974
1697.05	65.3379
1698.08	69.2198
1699.12	67.1997
1700.15	63.2567
1701.18	58.3169
1702.22	65.1655
1703.25	58.2418
1704.28	70.0116
1705.32	65.1083
1706.35	64.1069
1707.38	59.1341
1708.41	60.0437
1709.44	53.1107
1710.48	57.0102
1711.51	63.881
1712.54	66.8187
1713.57	66.7124
1714.6	62.7302
1715.63	67.6099
1716.66	65.6504
1717.69	55.8062
1718.72	63.5017
1719.75	58.6047
1720.78	62.4918
1721.81	66.3239
1722.84	59.4511
1723.87	61.3444
1724.9	61.3205
1725.93	58.3223
1726.96	62.1722
1727.99	67.9619
1729.02	64.9213
1730.05	66.7824
1731.07	59.9813
1732.1	62.9474
1733.13	63.8825
1734.16	62.8279
1735.18	67.5612
1736.21	65.5663
1737.24	64.5689
1738.26	67.4112
1739.29	68.3084
1740.32	66.2798
1741.34	67.1562
1742.37	68.0621
1743.4	68.9937
1744.42	58.4304
1745.45	67.0222
1746.47	62.2113
1747.5	61.1845
1748.52	61.1429
1749.55	61.1528
1750.57	61.1985
1751.6	61.2208
1752.62	63.0682
1753.64	63.0097
1754.67	62.9561
1755.69	65.7769
1756.71	68.5699
1757.74	63.7368
1758.76	64.705
1759.78	62.8038
1760.81	66.5877
1761.83	69.3917
1762.85	63.6783
1763.87	67.485
1764.89	64.6774
1765.92	72.3188
1766.94	66.5975
1767.96	73.2345
1768.98	66.5398
1770	72.1108
1771.02	69.2952
1772.04	71.2506
1773.06	73.191
1774.08	69.4118
1775.1	69.4305
1776.12	66.6349
1777.14	66.6304
1778.16	69.4412
1779.18	66.5228
1780.2	62.7006
1781.22	69.3813
1782.24	62.7319
1783.26	67.5347
1784.28	67.5659
1785.29	58.0668
1786.31	65.6782
1787.33	66.6602
1788.35	64.8714
1789.37	62.0907
1790.38	67.8935
1791.4	64.047
1792.42	67.8231
1793.43	66.8825
1794.45	64.0179
1795.47	60.2349
1796.48	65.1001
1797.5	57.4595
1798.51	62.2919
1799.53	60.359
1800.55	61.2744
1801.56	58.3702
1802.58	55.4957
1803.59	63.2229
1804.61	64.2095
1805.62	59.4468
1806.64	58.527
1807.65	62.3939
1808.66	64.3212
1809.68	57.5782
1810.69	56.6174
1811.7	61.4257
1812.72	65.288
1813.73	53.7415
1814.74	61.512
1815.76	59.6226
1816.77	56.7317
1817.78	54.7611
1818.79	61.5297
1819.8	64.4438
1820.82	58.6676
1821.83	63.5307
1822.84	55.8098
1823.85	55.8056
1824.86	53.8676
1825.87	62.599
1826.88	54.8508
1827.89	52.9251
1828.9	50.9814
1829.91	57.7403
1830.92	55.7768
1831.93	57.7313
1832.94	62.6073
1833.95	63.59
1834.96	58.6991
1835.97	60.5393
1836.98	60.7593
1837.99	60.5624
1839	61.521
1840	52.88
1841.01	59.5417
1842.02	52.6698
1843.03	60.3365
1844.04	62.2613
1845.04	57.4356
1846.05	59.3781
1847.06	57.5004
1848.07	60.1854
1849.07	55.3784
1850.08	61.1037
1851.09	57.1802
1852.09	58.0983
1853.1	60.9711
1854.1	59.0224
1855.11	53.2027
1856.11	56.0205
1857.12	57.9232
1858.12	63.6415
1859.13	61.6712
1860.13	61.6232
1861.14	59.7326
1862.14	48.2773
1863.15	57.8045
1864.15	56.7933
1865.15	56.746
1866.16	49.9935
1867.16	58.4721
1868.16	51.7378
1869.17	57.4316
1870.17	61.2186
1871.17	55.5014
1872.17	54.5259
1873.18	61.1342
1874.18	56.3593
1875.18	53.4579
1876.18	52.4274
1877.18	58.0419
1878.18	56.0644
1879.19	57.0996
1880.19	62.8223
1881.19	58.0767
1882.19	53.2596
1883.19	58.8027
1884.19	67.216
1885.19	63.475
1886.19	56.9438
1887.19	61.6518
1888.19	60.6445
1889.19	54.9068
1890.19	59.5776
1891.19	58.6687
1892.18	51.1178
1893.18	52.0317
1894.18	64.1652
1895.18	59.4339
1896.18	55.6899
1897.18	54.7822
1898.17	58.5552
1899.17	59.4565
1900.17	60.3506
1901.16	62.2235
1902.16	56.6265
1903.16	54.7627
1904.16	60.3789
1905.15	62.2445
1906.15	52.8179
1907.14	58.4105
1908.14	56.5353
1909.14	54.6764
1910.13	62.2469
1911.13	58.5524
1912.12	59.5072
1913.12	60.435
1914.11	63.287
1915.11	59.5721
1916.1	58.6469
1917.1	54.8408
1918.09	60.4658
1919.08	61.4451
1920.08	60.5828
1921.07	63.4248
1922.06	57.7987
1923.06	58.7317
1924.05	58.7028
1925.04	55.8357
1926.04	60.5973
1927.03	57.8227
1928.02	58.8023
1929.01	55.9808
1930	58.8681
1931	53.2316
1931.99	54.171
1932.98	56.9818
1933.97	64.5789
1934.96	57.1494
1935.95	56.3177
1936.94	57.212
1937.93	60.0138
1938.92	59.0546
1939.91	59.0844
1940.9	55.3085
1941.89	52.493
1942.88	61.103
1943.87	56.2928
1944.86	63.9674
1945.85	58.2918
1946.84	54.5017
1947.83	60.2267
1948.82	58.3028
1949.8	62.1637
1950.79	61.2893
1951.78	60.421
1952.77	60.4668
1953.76	62.3911
1954.74	57.4612
1955.73	53.5946
1956.72	58.4809
1957.7	61.4146
1958.69	62.4033
1959.68	64.3005
1960.66	61.3826
1961.65	54.6175
1962.63	58.4539
1963.62	61.3392
1964.61	60.3946
1965.59	62.3039
1966.58	64.2552
1967.56	67.1657
1968.55	62.3671
1969.53	61.3682
1970.52	57.4563
1971.5	62.2146
1972.48	67.9658
1973.47	55.4786
1974.45	63.1074
1975.44	62.15
1976.42	64.0968
1977.4	72.7307
1978.39	69.8137
1979.37	64.0368
1980.35	73.6245
1981.33	61.1258
1982.31	69.7193
1983.3	60.1009
1984.28	73.4468
1985.26	67.6721
1986.24	73.381
1987.22	70.5345
1988.21	76.2118
1989.19	78.7976
1990.17	73.1421
1991.15	75.6885
1992.13	74.2223
1993.11	79.9358
1994.09	76.7161
1995.07	73.8546
1996.05	77.7276
1997.03	76.0095
1998.01	74.0362
1998.99	78.7656
1999.97	82.0861
2000.95	75.0172
2001.92	79.6321
2002.9	80.4529
2003.88	83.2369
2004.86	78.1202
2005.84	81.8124
2006.81	82.6045
2007.79	80.4313
2008.77	79.6773
2009.75	82.5854
2010.73	81.2169
2011.7	77.8103
2012.68	83.5799
2013.67	82.5425
2014.66	80.528
2015.64	74.8602
2016.63	73.9514
2017.62	82.4556
2018.61	80.4658
2019.6	76.595
2020.58	70.9397
2021.57	76.5592
2022.56	79.3447
2023.55	68.9778
2024.54	73.5901
2025.52	78.1578
2026.51	78.0911
2027.5	75.4885
2028.48	68.8599
2029.47	69.9021
2030.45	66.8891
2031.44	72.5155
2032.43	72.5257
2033.41	70.7473
2034.4	73.5578
2035.38	68.7765
2036.37	67.9865
2037.35	71.7043
2038.34	67.9425
2039.32	70.7006
2040.31	68.7711
2041.29	75.2285
2042.27	69.5993
2043.26	63.9777
2044.24	74.3113
2045.23	62.1456
2046.21	66.0082
2047.19	63.1445
2048.17	63.0621
2049.16	60.2788
2050.14	63.1445
2051.12	62.2561
2052.11	62.2182
2053.09	62.2368
2054.07	62.3024
2055.05	61.3853
2056.03	60.4187
2057.01	60.3971
2058	62.2794
2058.98	66.0684
2059.96	60.481
2060.94	61.3925
2061.92	61.4154
2062.9	58.6181
2063.88	65.2121
2064.86	60.5481
2065.84	55.912
2066.82	56.8835
2067.8	58.7852
2068.78	61.6304
2069.76	56.9132
2070.73	57.8452
2071.71	58.8208
2072.69	60.7845
2073.67	66.4205
2074.65	57.0176
2075.63	58.9721
2076.6	57.1466
2077.58	58.0594
2078.56	56.1565
2079.54	50.5223
2080.51	57.1846
2081.49	58.1254
2082.47	57.1782
2083.45	58.1287
2084.42	54.3426
2085.4	56.2326
2086.37	55.3034
2087.35	54.3977
2088.32	56.3037
2089.3	55.3645
2090.28	58.2418
2091.25	55.4158
2092.23	59.2493
2093.2	58.3722
2094.18	54.6238
2095.15	57.4843
2096.13	50.7982
2097.1	55.5318
2098.07	53.5964
2099.05	58.3264
2100.02	49.7743
2101	54.5275
2101.97	47.9106
2102.94	58.3516
2103.92	57.3703
2104.89	53.5815
2105.86	60.2671
2106.83	56.4898
2107.8	54.5893
2108.78	56.432
2109.75	54.5302
2110.72	60.2394
2111.69	53.5828
2112.66	54.5135
2113.63	56.4423
2114.61	60.2499
2115.58	56.4456
2116.55	54.5178
2117.52	60.1922
2118.49	56.3697
2119.46	47.7763
2120.43	52.4761
2121.4	55.3292
2122.37	57.2738
2123.34	53.5079
2124.31	53.5017
2125.28	58.1693
2126.25	53.3531
2127.21	51.4109
2128.18	54.2235
2129.15	53.2668
2130.12	56.0868
2131.09	53.2339
2132.06	57.9223
2133.02	55.0542
2133.99	47.5004
2134.96	56.938
2135.93	56.9234
2136.89	50.2693
2137.86	52.1631
2138.83	54.9694
2139.79	48.3803
2140.76	53.9895
2141.73	52.0896
2142.69	53.9427
2143.66	55.8657
2144.62	53.8726
2145.59	51.9921
2146.55	50.0999
2147.52	58.5342
2148.48	57.5642
2149.45	50.9557
2150.42	56.5194
2151.38	55.5658
2152.34	52.777
2153.31	55.5693
2154.27	59.2863
2155.24	48.9069
2156.2	54.4463
2157.16	56.2919
2158.13	53.5081
2159.09	50.7094
2160.05	53.4797
2161.01	58.0944
2161.98	53.4063
2162.94	54.3335
2163.9	50.5771
2164.86	57.0615
2165.83	56.1263
2166.79	53.3173
2167.75	50.4826
2168.71	53.1988
2169.67	52.2858
2170.63	56.0727
2171.59	53.2619
2172.56	55.0294
2173.51	54.078
2174.48	51.3023
2175.44	50.3718
2176.4	53.1457
2177.36	50.3401
2178.32	49.4114
2179.28	51.2362
2180.23	52.1654
2181.19	52.154
2182.15	52.1344
2183.11	52.1122
2184.07	53.9151
2185.03	50.1889
2185.99	49.278
2186.95	48.3875
2187.9	56.797
2188.86	48.4153
2189.82	52.9983
2190.78	48.338
2191.73	56.6913
2192.69	52.9981
2193.65	52.099
2194.6	54.0317
2195.56	48.4474
2196.52	55.8243
2197.47	53.9147
2198.43	48.3459
2199.38	52.1132
2200.34	59.6263
2201.3	54.1356
2202.25	56.7401
2203.21	51.254
2204.16	53.3032
2205.12	50.408
2206.07	53.0743
2207.03	53.0674
2207.98	50.3064
2208.93	43.828
2209.89	50.3586
2210.84	46.6439
2211.8	48.536
2212.75	49.4985
2213.7	48.5427
2214.66	51.363
2215.61	49.5268
2216.56	47.6604
2217.51	50.4533
2218.47	50.4546
2219.42	49.5415
2220.37	48.6306
2221.32	45.8151
2222.27	46.7045
2223.23	48.5725
2224.18	48.6115
2225.13	45.8544
2226.08	46.8333
2227.03	49.6801
2227.98	50.6427
2228.93	49.6908
2229.88	46.8787
2230.83	43.1636
2231.78	49.7755
2232.73	43.2318
2233.68	48.9065
2234.63	52.6884
2235.58	47.9449
2236.53	47.9363
2237.48	48.8936
2238.43	45.191
2239.38	44.3
2240.33	39.5638
2241.27	43.3529
2242.22	50.9122
2243.17	50.9277
2244.12	47.1306
2245.07	52.8148
2246.01	44.3685
2246.96	53.8569
2247.91	44.4148
2248.85	51.0284
2249.8	48.1886
2250.75	51.9613
2251.69	50.0284
2252.64	44.3644
2253.59	50.1092
2254.53	46.361
2255.48	46.3639
2256.42	49.2191
2257.37	49.2513
2258.32	51.1725
2259.26	51.1885
2260.2	49.3087
2261.15	48.3783
2262.1	43.6497
2263.04	46.5266
2263.98	47.5312
2264.93	40.9147
2265.87	41.8948
2266.81	47.6007
2267.76	48.5155
2268.7	50.3909
2269.65	53.2842
2270.59	46.6616
2271.53	40.9567
2272.47	44.8042
2273.42	48.6377
2274.36	42.9038
2275.3	45.7835
2276.24	46.75
2277.18	47.7492
2278.13	46.8508
2279.07	46.8801
2280.01	46.8438
2280.95	45.8365
2281.89	46.7715
2282.83	49.6711
2283.77	44.9259
2284.71	44.9973
2285.65	44.0623
2286.59	44.9958
2287.54	46.0063
2288.47	39.282
2289.41	45.0247
2290.35	43.0423
2291.29	45.9279
2292.23	42.1219
2293.17	52.7515
2294.11	46.9929
2295.05	48.8922
2295.99	46.937
2296.93	47.8585
2297.86	46.9244
2298.8	46.9689
2299.74	46.0426
2300.68	45.0789
2301.61	52.8223
2302.55	46.0626
2303.49	43.1596
2304.43	47.9962
2305.36	45.1255
2306.3	45.1404
2307.24	44.1796
2308.17	46.0956
2309.11	41.2566
2310.04	44.1923
2310.98	42.2693
2311.92	47.0306
2312.85	47.9495
2313.79	48.926
2314.72	51.887
2315.66	42.2454
2316.59	47.0193
2317.52	46.9984
2318.46	44.1065
2319.39	45.0418
2320.33	54.6739
2321.26	46.9649
2322.2	45.0711
2323.13	54.7643
2324.06	49.9412
2325	53.7905
2325.93	55.6602
2326.86	80.6969
2327.79	111.479
2328.73	61.3319
2329.66	57.4373
2330.59	57.4306
2331.52	46.8262
2332.46	47.8005
2333.39	44.8801
2334.32	44.8564
2335.25	44.8231
2336.18	43.8596
2337.11	45.7693
2338.04	48.6408
2338.97	43.8232
2339.91	44.7831
2340.84	38.9919
2341.77	40.8611
2342.7	42.7436
2343.63	49.4435
2344.56	48.4822
2345.49	43.6793
2346.41	48.4304
2347.34	41.7126
2348.27	43.6244
2349.2	46.4992
2350.13	44.5132
2351.06	46.2015
2351.99	46.3853
2352.91	47.2661
2353.84	43.3841
2354.77	48.1464
2355.7	47.1938
2356.63	38.589
2357.55	46.1458
2358.48	44.2165
2359.41	48.943
2360.33	47.0136
2361.26	42.2243
2362.19	47.8645
2363.11	46.8682
2364.04	44.0005
2364.97	46.8098