File: Data/3-Raman/raw/bu19w-ff07b-fi10-v_150 (500nm)_532nm_edge_100%_x100_vis_lwd_h50um_15sx2_01.txt
#Acq. time (s)=	15
#Accumulations=	2
#Range (cm-¹)=	50...5000
#Windows=	1
#Auto scanning=	Off
#Autofocus=	Off
#Macrospot=	Off
#AutoExposure=	Off
#Spike filter=	Multiple accum.
#Delay time (s)=	2
#Binning=	1
#Readout mode=	Signal
#DeNoise=	Off
#ICS correction=	On
#Dark correction=	Off
#Inst. Process=	Off
#Detector Gain=	Best Dynamic
#Detector ADC=	50 kHz HS
#Detector temperature (°C)=	-60.09
#Instrument=	LabRAM HR Evol
#Detector=	SIN-EM FIVIS
#Objective=	x100_VIS_LWD
#Grating=	150 (500nm)
#ND Filter=	100%
#Laser=	532nm_Edge
#Hole=	49.98
#Temperature=	0
#Range=	Visible
#StageXY=	75x50mm Scan+
#StageZ=	Z motor
#X (µm)=	0
#Y (µm)=	0
#Z (µm)=	-31.5
#Full time(s)=	34
#Project=	21_05_28
#Sample=	BU19w
#Site=
#Title=	BU19w-FF07b-FI10-V_150 (500nm)_532nm_Edge_100%_x100_VIS_LWD_H50um_15sX2
#Remark=
#Date=	28.05.2021 16:54
#Acquired=	28.05.2021 16:54:34
51.5961	25095
56.2453	19201.3
60.8921	14706.6
65.5367	13549.7
70.1768	10936.2
74.8167	7051.97
79.4543	5251.68
84.0897	4279.83
88.7227	3510.31
93.3513	3031.78
97.9798	2699.25
102.606	2322.78
107.23	2229.66
111.851	2125.99
116.469	1894.64
121.086	1692.32
125.7	1592.24
130.313	1566.05
134.921	1518.23
139.529	1420.23
144.134	1387.86
148.738	1295.36
153.337	1252.23
157.936	1327.17
162.532	1725.67
167.126	2178.95
171.716	1728.76
176.306	1304.9
180.894	1237.42
185.477	1466.08
190.06	2686.84
194.64	4251.4
199.219	3116.28
203.793	1652
208.367	1205.42
212.939	1091.59
217.506	1058.51
222.073	1056.01
226.638	1014.26
231.199	1044.42
235.759	1217.4
240.318	1420.58
244.872	1529.29
249.425	2024.1
253.977	2310.83
258.524	1964.34
263.071	1652.55
267.616	1324.36
272.156	1340.18
276.697	1777.96
281.233	3203.12
285.769	4633.76
290.303	3571.21
294.832	2161.4
299.361	1692.71
303.886	1821.67
308.411	2470.6
312.934	2363.49
317.452	1692.23
321.97	1371.25
326.484	1379.03
330.998	1735.12
335.507	2139.79
340.017	1928.64
344.524	1474.45
349.027	1457.88
353.53	1742.74
358.028	1908.62
362.527	1589.2
367.021	1276.66
371.515	1214.05
376.004	1268.52
380.494	1242.88
384.979	1142.88
389.465	1238.68
393.946	1373.54
398.427	1541.92
402.903	1516.07
407.38	1317.95
411.852	1146.66
416.324	1139.26
420.792	1352.49
425.26	1424.57
429.723	1153.2
434.187	932.521
438.646	921.168
443.105	924.247
447.56	923.499
452.015	1007.48
456.466	1246.46
460.914	1796.07
465.362	1712.76
469.807	1284.3
474.251	1054.71
478.69	1028.93
483.13	1043.15
487.566	1084.45
491.999	1200.51
496.432	1342.76
500.861	1428.42
505.29	1418.69
509.715	1299.18
514.138	1195.9
518.56	1089.22
522.979	1029.17
527.395	994.795
531.811	1025.38
536.223	996.018
540.635	1026.89
545.042	1003.26
549.448	1044.61
553.853	1052.21
558.255	1083.57
562.654	1078.66
567.053	1117.64
571.448	1040.19
575.841	1090.68
580.232	1029.32
584.622	1108.74
589.009	1335.35
593.393	2040.78
597.777	2350.91
602.157	1773.39
606.535	1372.71
610.913	1412.91
615.287	1727.73
619.659	1854.36
624.029	1648.33
628.398	1211.26
632.763	1098.63
637.127	1039.25
641.488	1074.05
645.849	1164.53
650.206	1145.98
654.561	1072.01
658.914	1105.41
663.267	1115.47
667.615	1301.95
671.962	1401.28
676.307	1437.58
680.649	1528.65
684.991	1540.43
689.33	1377.87
693.666	1177.28
698	1041.3
702.332	949.808
706.662	962.323
710.992	932.522
715.318	896.692
719.641	931.903
723.963	890.225
728.283	923.442
732.6	910.247
736.918	868.435
741.231	891.65
745.542	900.231
749.852	939.292
754.159	963.513
758.464	991.967
762.767	1010.15
767.068	1079.06
771.369	1199.49
775.666	1427.55
779.961	1830.74
784.254	2281.36
788.545	2125.79
792.834	1704.19
797.12	1352.1
801.405	1154.63
805.688	1098.03
809.968	1025.38
814.247	1002.38
818.524	960.839
822.798	964.383
827.071	973.701
831.341	931.349
835.612	940.765
839.878	937.987
844.142	937.302
848.405	926.335
852.665	908.208
856.923	915.454
861.18	920.463
865.434	947.311
869.686	900.115
873.936	903.352
878.185	914.022
882.431	923.351
886.675	946.45
890.915	915.496
895.155	940.825
899.393	901.568
903.63	945.687
907.864	934.264
912.096	937.975
916.326	924.943
920.554	916.068
924.78	945.655
929.004	955.247
933.227	983.144
937.447	1003.36
941.665	1023.24
945.881	1054.67
950.095	1156.4
954.305	1244.27
958.516	1289.46
962.724	1231.58
966.93	1219.64
971.134	1332.01
975.337	1296.04
979.537	1228.49
983.735	1163.38
987.93	1095.12
992.124	1043.95
996.316	1052.83
1000.51	1000.92
1004.7	1044.6
1008.88	1006.73
1013.06	1003.9
1017.25	1019.97
1021.43	1037.13
1025.61	1087.17
1029.78	1097.37
1033.96	1113.62
1038.13	1146.85
1042.3	1208.08
1046.47	1351.01
1050.63	1619.41
1054.8	2190.62
1058.96	2761.82
1063.12	2611.01
1067.28	2060.66
1071.44	1668.51
1075.59	1466.76
1079.74	1490.18
1083.89	1657.26
1088.04	1979.58
1092.19	2645.68
1096.33	3072.21
1100.48	2978.59
1104.62	2473.25
1108.76	2231.57
1112.89	2343.67
1117.03	2553.83
1121.16	2405.63
1125.29	2219.83
1129.42	2186.63
1133.55	2285.01
1137.68	2409.76
1141.8	2308.76
1145.92	1974.26
1150.04	1765.87
1154.16	1679.72
1158.27	1877.58
1162.39	2229.95
1166.5	2281.31
1170.61	2015.33
1174.72	1721.11
1178.82	1559.92
1182.93	1412.34
1187.03	1246.13
1191.13	1230.51
1195.23	1193.08
1199.33	1190.14
1203.42	1267.35
1207.51	1211
1211.6	1194.49
1215.69	1146.83
1219.78	1173.06
1223.86	1239.53
1227.95	1382.16
1232.03	1330.57
1236.11	1319.16
1240.18	1368.48
1244.26	1473.35
1248.33	1550.75
1252.41	1495.18
1256.48	1349.01
1260.54	1340.85
1264.61	1179.83
1268.67	1187.98
1272.74	1268.51
1276.8	2423.96
1280.86	2536.1
1284.91	1391.13
1288.97	1137.58
1293.02	1134.25
1297.07	1103.55
1301.12	1122.09
1305.17	1077.94
1309.21	1099.23
1313.25	1081.07
1317.3	1078.65
1321.34	1068.95
1325.37	1055.85
1329.41	1107.95
1333.44	1114.65
1337.48	1093.89
1341.5	1087.02
1345.53	1063.07
1349.56	1066.1
1353.59	1078.1
1357.61	1114.93
1361.63	1144.6
1365.65	1153.58
1369.66	1147.89
1373.68	1155.32
1377.69	1639.13
1381.7	3927.79
1385.72	2620.4
1389.72	1312.54
1393.73	1175.72
1397.73	1136.83
1401.74	1265.27
1405.74	1272.55
1409.73	1159.71
1413.73	1071.54
1417.73	1102.68
1421.72	1082.51
1425.71	1090.81
1429.7	1073.87
1433.69	1055.06
1437.67	1030.3
1441.66	1068.75
1445.64	1078.39
1449.62	1046.52
1453.6	1079.59
1457.57	1043.51
1461.55	1062.45
1465.52	1053.47
1469.49	1062.13
1473.46	1039.5
1477.43	1057.98
1481.39	1031.2
1485.36	1066.07
1489.32	1048
1493.28	1057.38
1497.24	1095.03
1501.19	1061.63
1505.15	1083.93
1509.1	1082.2
1513.05	1089.29
1517	1043.04
1520.95	1044.5
1524.9	1061.54
1528.84	1084.48
1532.78	1052.28
1536.72	1054.05
1540.66	1069.41
1544.6	1055.71
1548.53	1078.83
1552.46	1067.07
1556.4	1085.21
1560.32	1075.1
1564.25	1076.48
1568.18	1098.07
1572.1	1104.08
1576.02	1067.57
1579.94	1076.42
1583.86	1081.38
1587.78	1085.28
1591.69	1061.23
1595.61	1086.26
1599.52	1083.37
1603.43	1059.46
1607.34	1091.4
1611.24	1077.3
1615.15	1094.92
1619.05	1096.39
1622.95	1115.03
1626.85	1084.05
1630.74	1100.13
1634.64	1103.17
1638.53	1088.92
1642.42	1115.17
1646.31	1065.98
1650.2	1083
1654.09	1100.09
1657.97	1112.31
1661.86	1097.61
1665.74	1105.73
1669.62	1100.29
1673.49	1095.45
1677.37	1095.36
1681.24	1103.32
1685.12	1089.88
1688.99	1106.08
1692.86	1100.96
1696.72	1094.72
1700.59	1092.15
1704.45	1079.81
1708.31	1078.7
1712.17	1144.8
1716.03	1088.38
1719.89	1106
1723.74	1106.6
1727.6	1084.49
1731.45	1116.8
1735.3	1110.62
1739.14	1081.88
1742.99	1110.06
1746.83	1126.08
1750.68	1094.39
1754.52	1094.75
1758.36	1113.35
1762.19	1081.84
1766.03	1144.2
1769.86	1094.65
1773.69	1102.28
1777.53	1115.54
1781.35	1133.87
1785.18	1112.31
1789	1107.62
1792.83	1086.12
1796.65	1117.11
1800.47	1115.26
1804.29	1093.86
1808.1	1087.4
1811.92	1098.71
1815.73	1094.74
1819.54	1154.45
1823.35	1086.5
1827.16	1139.11
1830.97	1120.64
1834.77	1144.31
1838.58	1128.21
1842.38	1111.96
1846.18	1118.03
1849.97	1122.34
1853.77	1115.82
1857.56	1102.48
1861.36	1139.22
1865.15	1117.03
1868.93	1136.84
1872.72	1118.7
1876.51	1122.14
1880.29	1158.87
1884.07	1118.55
1887.86	1143.74
1891.63	1103.03
1895.41	1171.87
1899.19	1140.4
1902.96	1137.95
1906.73	1169.79
1910.5	1140.98
1914.27	1156.82
1918.04	1157.07
1921.8	1152.52
1925.57	1125.84
1929.33	1180
1933.09	1166.59
1936.85	1164.28
1940.6	1175.92
1944.36	1157.64
1948.11	1177.71
1951.87	1140.6
1955.61	1140.52
1959.36	1176.47
1963.11	1125.63
1966.86	1150.8
1970.6	1186.85
1974.34	1164.27
1978.08	1167.73
1981.82	1168.17
1985.56	1159.99
1989.29	1173.15
1993.02	1171.18
1996.75	1184.79
2000.49	1175.85
2004.21	1165.15
2007.94	1218.1
2011.67	1173.75
2015.39	1205.04
2019.11	1190.9
2022.83	1162.77
2026.55	1164.73
2030.27	1176.8
2033.98	1172.04
2037.69	1197.89
2041.41	1202.59
2045.12	1188.88
2048.82	1219.14
2052.53	1163.57
2056.24	1209.72
2059.94	1176.79
2063.64	1159.21
2067.34	1167.61
2071.04	1164.16
2074.74	1191.17
2078.43	1198.02
2082.13	1191.08
2085.82	1204.38
2089.51	1195.84
2093.2	1182.1
2096.88	1196.81
2100.57	1227.13
2104.25	1197.52
2107.94	1195.59
2111.62	1211.15
2115.3	1226.66
2118.97	1213.2
2122.65	1226.19
2126.32	1184.16
2129.99	1212.46
2133.66	1213.73
2137.33	1220.47
2141	1224.2
2144.67	1242.48
2148.33	1229.34
2151.99	1237.33
2155.66	1220.6
2159.31	1204.88
2162.97	1231.4
2166.63	1224.27
2170.28	1245.64
2173.94	1255.64
2177.59	1204.91
2181.24	1255.41
2184.89	1242.13
2188.53	1248.3
2192.18	1223.11
2195.82	1242.11
2199.46	1250.47
2203.1	1236.19
2206.74	1253.13
2210.38	1249.29
2214.01	1269.42
2217.65	1248.41
2221.28	1249.41
2224.91	1246.8
2228.54	1235.8
2232.16	1297.69
2235.79	1252.68
2239.41	1286.17
2243.04	1287.29
2246.66	1268.85
2250.28	1259.72
2253.89	1252.56
2257.51	1264.15
2261.12	1300.06
2264.74	1242.28
2268.35	1277.31
2271.96	1276.11
2275.57	1212.39
2279.17	1270.73
2282.78	1279.27
2286.38	1266.08
2289.98	1265.13
2293.58	1275.36
2297.18	1233.59
2300.78	1277.99
2304.37	1302.32
2307.97	1239.2
2311.56	1282.99
2315.15	1289.62
2318.74	1242.01
2322.33	1546.55
2325.91	1562.95
2329.5	1325.82
2333.08	1265.63
2336.66	1304.43
2340.24	1286.45
2343.82	1285.32
2347.4	1315.92
2350.97	1277.01
2354.54	1269.02
2358.12	1298.31
2361.69	1313.42
2365.26	1316.37
2368.82	1321.25
2372.39	1259.77
2375.95	1272.34
2379.52	1307.05
2383.08	1288.38
2386.64	1315.88
2390.19	1294.84
2393.75	1263.1
2397.31	1331.74
2400.86	1288.02
2404.41	1275.28
2407.96	1273.69
2411.51	1293.74
2415.06	1299.44
2418.6	1306.38
2422.15	1285.02
2425.69	1256.54
2429.23	1321.52
2432.77	1292.65
2436.31	1299.18
2439.84	1339.31
2443.38	1319.2
2446.91	1297.15
2450.44	1306.15
2453.97	1291.96
2457.5	1321.04
2461.03	1284.09
2464.55	1290.3
2468.08	1321.83
2471.6	1330.88
2475.12	1339.6
2478.64	1337.73
2482.16	1326.66
2485.67	1325.46
2489.19	1308.39
2492.7	1334.35
2496.21	1278.84
2499.72	1340.09
2503.23	1331.51
2506.74	1315.26
2510.25	1339.78
2513.75	1309.42
2517.25	1323.13
2520.75	1333.32
2524.25	1313.86
2527.75	1330.91
2531.25	1344.57
2534.74	1322.4
2538.24	1325.57
2541.73	1313.36
2545.22	1334.08
2548.71	1295.37
2552.2	1358.34
2555.68	1340.36
2559.17	1330.41
2562.65	1323.23
2566.13	1311.96
2569.61	1328.09
2573.09	1325.94
2576.57	1349.35
2580.04	1377.84
2583.51	1340.58
2586.99	1319.15
2590.46	1343.74
2593.93	1362.99
2597.4	1338.27
2600.86	1354.9
2604.33	1314.03
2607.79	1308.67
2611.25	1327.15
2614.71	1361.05
2618.17	1341.7
2621.63	1344.82
2625.09	1323.65
2628.54	1338.63
2631.99	1346.66
2635.45	1333.23
2638.9	1316.55
2642.34	1350.41
2645.79	1352.36
2649.24	1332.26
2652.68	1333.83
2656.12	1354.06
2659.56	1370.13
2663.01	1349.05
2666.44	1351.55
2669.88	1338.92
2673.32	1348.84
2676.75	1327.98
2680.18	1357.96
2683.61	1329.26
2687.04	1347.77
2690.47	1348.47
2693.9	1351.51
2697.32	1373.82
2700.75	1347.08
2704.17	1368.79
2707.59	1318.95
2711.01	1342.58
2714.43	1368.37
2717.84	1321.83
2721.26	1332.33
2724.67	1340.23
2728.08	1368.8
2731.49	1330.18
2734.9	1373.78
2738.31	1321.89
2741.71	1358.94
2745.12	1331.94
2748.52	1341.36
2751.92	1343.29
2755.32	1368.62
2758.72	1351.46
2762.12	1368.22
2765.52	1376.15
2768.91	1341.46
2772.3	1349.89
2775.7	1343.12
2779.09	1381.33
2782.47	1290.34
2785.86	1350.84
2789.25	1350.09
2792.63	1359.63
2796.01	1340
2799.4	1321.33
2802.78	1396.27
2806.15	1328.64
2809.53	1351.93
2812.91	1295.56
2816.28	1360.76
2819.65	1356.69
2823.03	1357.5
2826.4	1351.04
2829.76	1370.78
2833.13	1372.06
2836.5	1357.76
2839.86	1352.08
2843.22	1361.57
2846.59	1343.43
2849.95	1332.29
2853.3	1334.51
2856.66	1350.58
2860.02	1358.46
2863.37	1354.34
2866.72	1309.96
2870.08	1319.91
2873.43	1349.53
2876.77	1371.64
2880.12	1306.21
2883.47	1318.81
2886.81	1370.95
2890.15	1336.29
2893.5	1336.45
2896.84	1342.91
2900.17	1338.77
2903.51	1332.53
2906.85	1353.56
2910.18	1371.63
2913.52	1369.74
2916.85	1382.88
2920.18	1346.62
2923.51	1324.5
2926.83	1327.79
2930.16	1356.39
2933.48	1358.37
2936.81	1364.85
2940.13	1346.81
2943.45	1421.12
2946.77	1345.69
2950.09	1386.12
2953.4	1370.03
2956.72	1329.59
2960.03	1331.67
2963.34	1370.46
2966.65	1332.39
2969.96	1350.07
2973.27	1315.47
2976.58	1370.97
2979.88	1345.09
2983.19	1304.95
2986.49	1363.45
2989.79	1320.64
2993.09	1337.03
2996.39	1337.53
2999.68	1331.52
3002.98	1311.38
3006.27	1331.69
3009.57	1338.94
3012.86	1310.48
3016.15	1318.77
3019.43	1319.49
3022.72	1318.3
3026.01	1343.54
3029.29	1348.05
3032.57	1337.43
3035.86	1353.19
3039.14	1300.84
3042.41	1350.64
3045.69	1356.96
3048.97	1315.95
3052.24	1313.75
3055.52	1321.06
3058.79	1317.88
3062.06	1310.49
3065.33	1315.63
3068.6	1301.62
3071.86	1342.37
3075.13	1345.89
3078.39	1334.65
3081.65	1303.08
3084.91	1328.57
3088.17	1358.77
3091.43	1318.14
3094.69	1349.78
3097.95	1348.35
3101.2	1330.68
3104.45	1343.17
3107.7	1357.24
3110.95	1372.09
3114.2	1350.34
3117.45	1349.64
3120.7	1375.64
3123.94	1347.36
3127.18	1373.35
3130.43	1367.86
3133.67	1381.45
3136.91	1362.6
3140.14	1366.55
3143.38	1387.64
3146.61	1400.16
3149.85	1356.51
3153.08	1399.67
3156.31	1379.82
3159.54	1384.81
3162.77	1369.72
3166	1405.2
3169.22	1399.53
3172.45	1399.47
3175.67	1394.59
3178.89	1439.21
3182.11	1426.55
3185.33	1421.56
3188.55	1449.78
3191.77	1427.42
3194.98	1462.25
3198.2	1442.73
3201.41	1449.86
3204.62	1482.75
3207.83	1483.31
3211.04	1463.96
3214.25	1447.58
3217.45	1431.29
3220.66	1437.84
3223.86	1500.57
3227.06	1437.87
3230.26	1465.58
3233.46	1499.12
3236.66	1502.11
3239.85	1487.35
3243.05	1458.38
3246.24	1471.37
3249.44	1469.14
3252.63	1457.51
3255.82	1479.3
3259.01	1523.99
3262.19	1480.65
3265.38	1463.81
3268.56	1519.37
3271.75	1512.68
3274.93	1525.01
3278.11	1475.23
3281.29	1500.6
3284.47	1504.67
3287.64	1490.65
3290.82	1518.47
3293.99	1514.94
3297.17	1501.82
3300.34	1535.4
3303.51	1536.94
3306.68	1488.6
3309.84	1525.75
3313.01	1533.16
3316.18	1546.16
3319.34	1528.75
3322.5	1565.34
3325.66	1537.48
3328.82	1563.61
3331.98	1534.9
3335.14	1568.7
3338.29	1571.43
3341.45	1538.41
3344.6	1523.39
3347.75	1580.41
3350.9	1568.04
3354.05	1599
3357.2	1546.26
3360.35	1536.96
3363.49	1604.21
3366.64	1607.39
3369.78	1620.1
3372.92	1621.57
3376.06	1606.23
3379.2	1568.28
3382.34	1642.82
3385.48	1643.62
3388.61	1697.53
3391.75	1660.66
3394.88	1685.22
3398.01	1695.17
3401.14	1711.77
3404.27	1753.22
3407.4	1813.91
3410.52	1936.65
3413.65	2063.39
3416.77	2399.48
3419.89	3298.47
3423.01	5698.22
3426.13	8880.2
3429.25	7841.87
3432.37	4568.6
3435.49	2867.74
3438.6	2226.38
3441.72	1993.11
3444.83	1831.44
3447.94	1755.34
3451.05	1709.75
3454.16	1730.66
3457.26	1719.13
3460.37	1692.14
3463.47	1691.78
3466.58	1659.03
3469.68	1665
3472.78	1667.83
3475.88	1688.2
3478.98	1717.15
3482.07	1762.21
3485.17	1787.41
3488.26	1871.25
3491.36	1975.1
3494.45	2136.98
3497.54	2351.54
3500.63	2731.81
3503.72	3117.56
3506.81	3592.05
3509.89	3695.86
3512.98	3475.55
3516.06	2989.99
3519.14	2506.09
3522.22	2204.61
3525.3	1952.17
3528.38	1834.99
3531.45	1725.3
3534.53	1583.06
3537.61	1559.01
3540.68	1515.31
3543.75	1507.19
3546.82	1479.93
3549.89	1429.13
3552.96	1434.63
3556.03	1418.25
3559.09	1368.03
3562.16	1378.36
3565.22	1341.99
3568.28	1366.04
3571.34	1287.19
3574.4	1311.03
3577.46	1312.17
3580.52	1331.23
3583.57	1315.08
3586.63	1291.23
3589.68	1290.13
3592.73	1250.95
3595.78	1261.03
3598.83	1239.73
3601.88	1222.24
3604.93	1245.33
3607.97	1212.48
3611.02	1215.59
3614.06	1171.38
3617.1	1213.12
3620.14	1168.03
3623.18	1167.38
3626.22	1208.25
3629.26	1178.48
3632.3	1209.89
3635.33	1178.13
3638.36	1148.58
3641.4	1173.76
3644.43	1128.52
3647.46	1144.73
3650.49	1140.86
3653.51	1107.98
3656.54	1125.42
3659.57	1075.73
3662.59	1123.77
3665.61	1088.75
3668.63	1075.82
3671.65	1089.53
3674.67	1100.48
3677.69	1050.15
3680.71	1057.44
3683.72	1079.79
3686.74	1062.47
3689.75	1036.64
3692.76	1033.54
3695.77	1051.29
3698.78	1034.72
3701.79	1032.59
3704.79	981.088
3707.8	1021.65
3710.81	1054.54
3713.81	1016.06
3716.81	1004.05
3719.81	1006.38
3722.81	1009.54
3725.81	996.43
3728.81	1015.6
3731.8	1006.13
3734.8	1016.56
3737.79	1011.64
3740.78	996.157
3743.77	985.323
3746.76	999.143
3749.75	982.431
3752.74	996.063
3755.73	960.297
3758.71	993.86
3761.7	987.53
3764.68	991.547
3767.66	959.604
3770.64	959.004
3773.62	989.703
3776.6	1006.27
3779.58	967.123
3782.55	965.856
3785.53	974.048
3788.5	993.619
3791.47	976.435
3794.44	998.106
3797.41	946.237
3800.38	958.61
3803.35	970.171
3806.32	969.511
3809.28	959.431
3812.24	976.814
3815.21	916.701
3818.17	964.399
3821.13	958.235
3824.09	952.091
3827.04	946.957
3830	940.878
3832.96	956.604
3835.91	938.271
3838.86	909.512
3841.82	948.202
3844.77	969.819
3847.72	956.265
3850.67	934.157
3853.61	960.698
3856.56	952.946
3859.5	942.326
3862.45	958.466
3865.39	952.57
3868.33	935.169
3871.27	922.454
3874.21	965.321
3877.15	958.298
3880.09	929.069
3883.02	953.512
3885.96	919.236
3888.89	943.508
3891.82	945.638
3894.75	903.484
3897.68	933.333
3900.61	932.302
3903.54	951.435
3906.47	940.644
3909.39	923.24
3912.31	925.934
3915.24	936.222
3918.16	908.988
3921.08	940.502
3924	936.297
3926.92	911.844
3929.83	920.885
3932.75	899.215
3935.67	928.544
3938.58	898.678
3941.49	907.284
3944.4	934.952
3947.31	890.863
3950.22	907.183
3953.13	907.295
3956.04	890.206
3958.94	902.887
3961.85	909.869
3964.75	903.479
3967.65	904.808
3970.55	916.738
3973.45	922.947
3976.35	903.21
3979.25	888.199
3982.15	891.378
3985.04	882.044
3987.94	891.894
3990.83	890.176
3993.72	879.694
3996.61	913.634
3999.5	899.453
4002.39	908.415
4005.28	871.168
4008.16	857.062
4011.05	885.367
4013.93	905.003
4016.81	884.146
4019.7	880.643
4022.58	876.166
4025.46	873.622
4028.33	891.386
4031.21	865.669
4034.09	879.606
4036.96	871.309
4039.84	892.087
4042.71	851.839
4045.58	872.452
4048.45	869.862
4051.32	864.409
4054.19	871.609
4057.05	865.314
4059.92	852.178
4062.78	830.252
4065.65	871.495
4068.51	857.336
4071.37	858.717
4074.23	870.805
4077.09	864.378
4079.95	853.065
4082.81	857.337
4085.66	880.148
4088.52	873.663
4091.37	861.317
4094.22	838.281
4097.07	854.231
4099.92	849.72
4102.77	863.76
4105.62	845.507
4108.47	848.659
4111.31	852.806
4114.16	846.085
4117	833.405
4119.84	839.199
4122.69	848.919
4125.53	830.362
4128.36	817.696
4131.2	848.325
4134.04	846.781
4136.88	826.873
4139.71	836.288
4142.54	841.03
4145.38	830.202
4148.21	819.706
4151.04	819.061
4153.87	824.102
4156.69	816.113
4159.52	835.183
4162.35	810.518
4165.17	808.466
4168	815.204
4170.82	829.804
4173.64	826.846
4176.46	808.265
4179.28	814.131
4182.1	787.793
4184.91	808.426
4187.73	813.459
4190.54	818.516
4193.36	811.958
4196.17	840.736
4198.98	788.336
4201.79	824.085
4204.6	825.577
4207.41	829.981
4210.22	820.657
4213.02	852.567
4215.83	808.789
4218.63	821.536
4221.44	787.939
4224.24	780.835
4227.04	779.536
4229.84	813.954
4232.64	799.989
4235.43	791.048
4238.23	786.1
4241.02	805.988
4243.82	787.163
4246.61	783.274
4249.4	789.297
4252.19	814.231
4254.98	764.227
4257.77	775.08
4260.56	775.928
4263.35	783.836
4266.13	780.745
4268.92	787.757
4271.7	756.519
4274.48	746.346
4277.26	760.211
4280.04	783.08
4282.82	775.613
4285.6	768.052
4288.38	770.5
4291.15	770.84
4293.93	750.893
4296.7	732.047
4299.47	745.682
4302.25	748.102
4305.02	754.575
4307.79	729.574
4310.55	741.158
4313.32	740.628
4316.09	764.385
4318.85	736.196
4321.62	764.936
4324.38	767.156
4327.14	752.026
4329.9	754.233
4332.66	735.983
4335.42	740.187
4338.18	741.258
4340.94	722.092
4343.69	708.015
4346.45	729.698
4349.2	760.651
4351.95	729.368
4354.7	743.196
4357.45	721.18
4360.2	731.867
4362.95	726.147
4365.7	713.324
4368.44	742.434
4371.19	722.438
4373.93	749.478
4376.68	724.177
4379.42	742.945
4382.16	707.265
4384.9	697.297
4387.64	701.874
4390.37	712.916
4393.11	719.976
4395.85	690.447
4398.58	729.583
4401.31	735.649
4404.05	701.226
4406.78	712.424
4409.51	698.744
4412.24	700.551
4414.96	709.544
4417.69	697.68
4420.42	687.588
4423.14	673.45
4425.87	709.447
4428.59	691.171
4431.31	692.733
4434.03	691.143
4436.75	683.234
4439.47	706.711
4442.19	684.019
4444.91	670.76
4447.62	688.925
4450.34	687.16
4453.05	704.237
4455.76	682.44
4458.47	702.603
4461.19	688.055
4463.89	685.158
4466.6	669.616
4469.31	687.782
4472.02	673.355
4474.72	663.187
4477.43	711.049
4480.13	667.251
4482.83	690.998
4485.53	664.062
4488.23	657.122
4490.93	668.13
4493.63	638.762
4496.33	649.5
4499.02	654.015
4501.72	671.209
4504.41	658.684
4507.11	660
4509.8	651.792
4512.49	661.618
4515.18	656.608
4517.87	648.423
4520.56	643.448
4523.24	652.36
4525.93	664.471
4528.61	669.132
4531.3	645.057
4533.98	647.618
4536.66	642.736
4539.34	652.817
4542.02	642.655
4544.7	651.716
4547.38	623.359
4550.05	651.727
4552.73	637.33
4555.4	655.21
4558.08	629.175
4560.75	637.694
4563.42	596.76
4566.09	636.89
4568.76	632.968
4571.43	638.399
4574.1	631.189
4576.77	633.48
4579.43	616.527
4582.1	603.072
4584.76	583.158
4587.42	596.652
4590.08	593.77
4592.74	603.914
4595.4	606.472
4598.06	599.271
4600.72	599.653
4603.38	593.587
4606.03	591.931
4608.69	612.201
4611.34	598.507
4613.99	591.354
4616.64	597.371
4619.29	578.126
4621.94	600.724
4624.59	593.581
4627.24	596.306
4629.89	583.55
4632.53	585.117
4635.18	591.022
4637.82	591.362
4640.46	572.875
4643.1	572.099
4645.74	572.566
4648.38	583.171
4651.02	589.502
4653.66	571.586
4656.3	585.682
4658.93	574.643
4661.57	589.679
4664.2	592.559
4666.83	559.583
4669.46	567.818
4672.09	555.959
4674.72	567.602
4677.35	564.679
4679.98	550.514
4682.61	568.886
4685.23	569.302
4687.86	561.845
4690.48	537.501
4693.1	564.948
4695.73	554.057
4698.34	564.576
4700.96	540.129
4703.58	541.61
4706.2	562.257
4708.82	569.339
4711.43	541.336
4714.05	555.178
4716.66	562.214
4719.28	552.237
4721.89	558.097
4724.5	545.798
4727.11	557.38
4729.72	546.316
4732.33	539.785
4734.93	555.966
4737.54	532.369
4740.14	540.548
4742.75	535.067
4745.35	538.641
4747.95	534.21
4750.55	551.323
4753.15	529.763
4755.75	516.155
4758.35	537.827
4760.95	540.203
4763.54	552.868
4766.14	524.567
4768.73	527.135
4771.33	516.064
4773.92	531.114
4776.51	519.934
4779.1	520.168
4781.69	543.244
4784.28	519.483
4786.87	510.573
4789.45	516.529
4792.04	512.209
4794.63	529.666
4797.21	533.412
4799.79	508.551
4802.37	498.606
4804.95	500.173
4807.53	506.404
4810.11	508.084
4812.69	485.57
4815.27	489.56
4817.84	521.305
4820.42	511.549
4822.99	504.082
4825.57	479.221
4828.14	518.108
4830.71	503.658
4833.28	477.586
4835.85	503.889
4838.42	474.324
4840.98	472.758
4843.55	486.383
4846.12	476.518
4848.68	493.571
4851.24	499.934
4853.81	507.146
4856.37	479.178
4858.93	501.085
4861.49	500.614
4864.05	484.651
4866.61	467.307
4869.16	478.348
4871.72	475.31
4874.27	461.488
4876.83	486.72
4879.38	519.105
4881.93	460.079
4884.49	462.728
4887.04	473.696
4889.58	475.174
4892.13	457.613
4894.68	487.646
4897.23	467.654
4899.77	475.045
4902.32	457.386
4904.86	467.149
4907.4	448.249
4909.95	478.282
4912.49	480.751
4915.03	456.905
4917.57	466.458
4920.1	445.004
4922.64	461.776
4925.18	477.362
4927.71	449.963
4930.25	457.158
4932.78	441.765
4935.31	447.975
4937.84	457.729
4940.38	455.511
4942.9	444.708
4945.43	448.44
4947.96	451.05
4950.49	450.049
4953.01	469.473
4955.54	443.268
4958.06	443.528
4960.59	452.233
4963.11	446.568
4965.63	422.97
4968.15	446.386
4970.67	438.365
4973.19	448.415
4975.71	450.013
4978.22	431.049
4980.74	407.233
4983.25	446.365
4985.77	428.601
4988.28	427.804
4990.79	434.303
4993.3	455.388
4995.81	435.119
4998.32	447.781