File: Data/3-Raman/raw/bu19w-e-ff11-fi06-l_150 (500nm)_633nm_edge_100%_x100_vis_h50um_60sx2_01.txt
#Acq. time (s)=	60
#Accumulations=	2
#Range (cm-¹)=	100...4000
#Windows=	1
#Auto scanning=	Off
#Autofocus=	Off
#Macrospot=	Off
#AutoExposure=	Off
#Spike filter=	Multiple accum.
#Delay time (s)=	2
#Binning=	1
#Readout mode=	Signal
#DeNoise=	Off
#ICS correction=	On
#Dark correction=	Off
#Inst. Process=	Off
#Detector Gain=	Best Dynamic
#Detector ADC=	50 kHz HS
#Detector temperature (°C)=	-60.09
#Instrument=	LabRAM HR Evol
#Detector=	SIN-EM FIVIS
#Objective=	x100_VIS
#Grating=	150 (500nm)
#ND Filter=	100%
#Laser=	633nm_Edge
#Hole=	49.98
#Temperature=	0
#Range=	Visible
#StageXY=	75x50mm Scan+
#StageZ=	Z motor
#X (µm)=	0
#Y (µm)=	0
#Z (µm)=	-271.9
#Full time(mm:ss)=	2:04
#Project=	21_11_04
#Sample=	BU19w
#Site=
#Title=	BU19w-E-FF11-FI06-L_150 (500nm)_633nm_Edge_100%_x100_VIS_H50um_60sX2
#Remark=
#Date=	04.11.2021 15:55
#Acquired=	04.11.2021 15:55:14
102.881	450.482
109.397	421.33
115.908	391.174
122.414	395.277
128.914	394.574
135.409	410.026
141.898	417.691
148.383	413.951
154.861	464.878
161.335	514.96
167.801	360.899
174.264	295.751
180.721	283.158
187.173	256.032
193.62	248.93
200.061	248.63
206.496	238.095
212.926	243.718
219.352	314.183
225.772	486.43
232.185	621.811
238.595	442.485
244.999	307.331
251.397	312.882
257.791	339.258
264.178	330.584
270.561	322.928
276.939	366.546
283.31	338.956
289.678	270.541
296.039	252.32
302.396	297.51
308.746	379.44
315.093	629.338
321.433	913.933
327.768	620.267
334.099	400.397
340.423	329.579
346.743	322.857
353.058	332.096
359.367	362.865
365.671	302.313
371.971	237.193
378.265	208.787
384.553	192.683
390.837	189.971
397.116	188.365
403.389	197.273
409.657	205.236
415.92	231.058
422.178	250.258
428.431	315.245
434.678	320.179
440.921	318.46
447.158	334.493
453.391	354.1
459.618	303.806
465.84	232.576
472.057	208.187
478.27	216.6
484.477	212.899
490.679	215.722
496.876	234.413
503.068	258.75
509.255	290.605
515.436	314.177
521.613	299.658
527.785	294.622
533.952	276.603
540.113	243.41
546.27	221.199
552.423	218.535
558.568	194.989
564.711	174.923
570.848	178.287
576.979	187.107
583.107	208.988
589.228	235.557
595.345	259.497
601.458	263.285
607.565	276.747
613.667	272.637
619.764	272.487
625.856	211.292
631.944	205.101
638.026	194.756
644.104	181.287
650.177	203.569
656.244	193.681
662.308	163.225
668.365	136.693
674.418	118.897
680.467	123.561
686.511	112.467
692.549	108.014
698.582	112.944
704.611	111.295
710.635	111.446
716.655	101.97
722.669	113.184
728.679	106.46
734.683	103.461
740.683	98.6035
746.678	102.189
752.669	106.761
758.654	106.754
764.635	109.765
770.611	110.077
776.582	105.688
782.549	103.072
788.511	95.6617
794.466	107.99
800.419	101.373
806.366	106.93
812.309	110.544
818.247	112.19
824.18	110.984
830.108	106.999
836.033	120.055
841.952	119.297
847.865	119.51
853.776	125.422
859.681	137.998
865.58	155.381
871.476	163.347
877.366	179.684
883.253	172.223
889.134	194.994
895.012	176.861
900.883	172.763
906.751	151.567
912.614	170.002
918.473	177.17
924.326	193.018
930.174	206.322
936.019	240.581
941.859	292.445
947.693	344.796
953.525	381.377
959.35	387.396
965.171	396.957
970.988	499.367
976.801	648.47
982.608	725.523
988.411	642.04
994.209	481.257
1000	436.595
1005.79	434.238
1011.58	466.746
1017.36	513.958
1023.13	474.548
1028.9	367.425
1034.67	309.826
1040.43	292.478
1046.19	268.261
1051.94	254.376
1057.69	226.672
1063.44	210.337
1069.17	210.261
1074.91	237.359
1080.64	281.77
1086.37	379.375
1092.09	506.994
1097.8	526.027
1103.52	407.749
1109.22	299.557
1114.93	274.016
1120.63	262.236
1126.32	268.67
1132.01	311.389
1137.7	354.304
1143.38	473.041
1149.06	607.563
1154.73	443.577
1160.4	274.077
1166.06	200.874
1171.72	173.046
1177.38	153.12
1183.03	144.086
1188.67	146.001
1194.31	113.848
1199.95	111.106
1205.58	97.7117
1211.21	101.034
1216.84	96.519
1222.46	90.0161
1228.07	92.4463
1233.68	90.8283
1239.29	95.1639
1244.89	88.2991
1250.49	87.3727
1256.08	95.4702
1261.67	91.3304
1267.26	91.2081
1272.84	89.0311
1278.42	81.8095
1283.99	87.651
1289.56	83.5193
1295.12	88.4512
1300.68	83.4451
1306.23	87.5276
1311.78	86.7352
1317.33	75.9459
1322.87	84.2925
1328.41	75.5082
1333.94	83.9396
1339.47	88.3049
1345	82.3754
1350.52	82.5339
1356.04	91.8994
1361.55	89.9214
1367.06	93.0088
1372.56	113.522
1378.06	92.942
1383.56	86.7404
1389.05	82.5949
1394.53	76.4507
1400.02	79.6486
1405.5	78.7349
1410.97	84.0307
1416.44	82.1452
1421.91	83.3713
1427.37	87.7365
1432.83	82.76
1438.28	81.925
1443.73	85.2674
1449.17	83.3486
1454.62	81.3451
1460.05	77.1804
1465.48	80.3236
1470.91	78.2009
1476.34	81.3459
1481.76	76.1291
1487.17	82.4907
1492.59	81.5429
1497.99	83.7951
1503.4	81.8598
1508.8	84.1831
1514.19	88.6731
1519.59	86.8312
1524.97	90.3394
1530.36	88.5093
1535.74	89.9165
1541.11	84.7692
1546.48	85.984
1551.85	93.5604
1557.21	93.4433
1562.57	81.4785
1567.93	88.9414
1573.28	83.4632
1578.62	85.5766
1583.97	85.5855
1589.3	93.1598
1594.64	93.2405
1599.97	93.3659
1605.3	93.5393
1610.62	93.7846
1615.94	99.5487
1621.25	92.288
1626.56	101.409
1631.87	88.5779
1637.17	96.5597
1642.47	94.473
1647.76	97.9373
1653.05	99.1571
1658.34	95.8939
1663.62	94.8145
1668.9	90.3867
1674.18	93.7156
1679.45	93.6994
1684.71	91.4167
1689.98	88.0193
1695.23	90.2153
1700.49	90.3268
1705.74	95.2329
1710.99	100.939
1716.23	89.8208
1721.47	92.3147
1726.7	103.671
1731.94	102.765
1737.16	93.965
1742.39	100.91
1747.61	98.8298
1752.82	93.3027
1758.03	99.0423
1763.24	102.472
1768.44	96.8573
1773.64	88.9841
1778.84	93.6176
1784.03	91.49
1789.22	96.2262
1794.41	106.715
1799.59	94.4002
1804.76	94.6616
1809.94	102.94
1815.11	100.855
1820.27	97.6081
1825.43	98.9857
1830.59	96.8985
1835.74	99.4684
1840.89	96.1741
1846.04	103.35
1851.18	96.5005
1856.32	94.2804
1861.45	97.9713
1866.58	104.053
1871.71	99.5272
1876.83	96.1228
1881.95	100.961
1887.07	93.9676
1892.18	99.9003
1897.29	104.644
1902.39	108.304
1907.49	107.328
1912.59	107.63
1917.68	107.979
1922.77	98.5448
1927.86	97.5414
1932.94	97.728
1938.02	106.298
1943.09	99.2231
1948.16	102.937
1953.23	110.227
1958.29	101.83
1963.35	104.257
1968.41	103.038
1973.46	104.186
1978.51	104.129
1983.55	105.273
1988.59	108.834
1993.63	113.609
1998.66	117.205
2003.69	111.216
2008.72	111.278
2013.74	100.534
2018.76	103.012
2023.77	117.565
2028.78	110.476
2033.79	121.561
2038.79	109.676
2043.79	109.899
2048.79	110.141
2053.78	107.898
2058.77	109.343
2063.76	112.036
2068.74	123.33
2073.72	118.673
2078.69	125.07
2083.66	125.289
2088.63	113.097
2093.59	130.633
2098.55	124.727
2103.51	137.473
2108.46	121.627
2113.41	129.496
2118.36	128.644
2123.3	116.446
2128.24	124.357
2133.17	118.353
2138.11	122.437
2143.03	126.52
2147.96	139.496
2152.88	126.934
2157.79	124.517
2162.71	124.608
2167.62	122.091
2172.52	125.997
2177.43	133.766
2182.32	119.702
2187.22	126.086
2192.11	126.131
2197	139.037
2201.89	128.951
2206.77	134.309
2211.64	117.844
2216.52	123.28
2221.39	122.299
2226.26	113.529
2231.12	124.224
2235.98	133.667
2240.84	111.778
2245.69	133.036
2250.54	125.49
2255.39	127.115
2260.23	120.843
2265.07	133.029
2269.9	135.921
2274.74	130.8
2279.57	120.306
2284.39	121.703
2289.21	135.04
2294.03	131.078
2298.84	131.15
2303.66	125.949
2308.46	131.493
2313.27	125.077
2318.07	124.045
2322.87	121.666
2327.66	124.691
2332.45	125.051
2337.24	132.219
2342.02	134.01
2346.8	126.304
2351.58	133.596
2356.35	123.007
2361.12	128.795
2365.89	129.072
2370.65	129.348
2375.41	128.221
2380.17	134.004
2384.92	121.65
2389.67	139.835
2394.42	142.668
2399.16	123.18
2403.9	137.086
2408.64	131.53
2413.37	140.126
2418.1	130.989
2422.83	131.412
2427.55	130.218
2432.27	129.145
2436.99	132.362
2441.7	138.439
2446.41	144.548
2451.11	140.7
2455.82	126.782
2460.51	144.393
2465.21	141.926
2469.9	137.972
2474.59	147.012
2479.28	134.332
2483.96	137.57
2488.64	139.317
2493.32	142.521
2497.99	145.75
2502.66	143.09
2507.32	144.802
2511.99	139.123
2516.65	155.511
2521.3	148.37
2525.96	145.643
2530.61	147.345
2535.25	150.578
2539.89	144.931
2544.53	164.595
2549.17	153.02
2553.8	141.386
2558.43	152.137
2563.06	146.456
2567.68	145.314
2572.3	154.756
2576.92	152.112
2581.53	150.908
2586.14	142.005
2590.75	149.721
2595.35	155.983
2599.96	147.087
2604.55	151.853
2609.15	158.138
2613.74	150.612
2618.33	147.682
2622.91	155.471
2627.49	167.913
2632.07	160.541
2636.64	154.789
2641.22	155.277
2645.78	169.737
2650.35	168.707
2654.91	158.25
2659.47	161.654
2664.03	146.246
2668.58	171.512
2673.13	165.592
2677.67	167.773
2682.22	170.191
2686.76	155.062
2691.29	179.665
2695.83	173.728
2700.36	162.861
2704.89	180.875
2709.41	166.71
2713.93	160.551
2718.45	156.052
2722.96	153.103
2727.47	185.759
2731.98	174.564
2736.49	153.58
2740.99	168.347
2745.49	166.936
2749.98	170.494
2754.47	157.912
2758.96	166.41
2763.45	184.724
2767.93	163.708
2772.41	172.256
2776.89	167.726
2781.36	176.529
2785.84	182.114
2790.3	176.04
2794.77	158.173
2799.23	183.769
2803.69	175.787
2808.14	172.771
2812.59	166.333
2817.04	166.578
2821.49	161.757
2825.93	170.515
2830.37	174.183
2834.81	177.835
2839.24	171.271
2843.67	171.526
2848.1	175.253
2852.53	163.627
2856.95	184.649
2861.37	178.236
2865.78	175.321
2870.19	165.474
2874.6	181.626
2879.01	173.495
2883.41	189.847
2887.81	172.968
2892.21	171.789
2896.6	177.695
2901	169.482
2905.38	182.476
2909.77	175.872
2914.15	178.068
2918.53	164.124
2922.91	187.91
2927.28	170.406
2931.65	174.529
2936.02	176.777
2940.38	182.57
2944.74	192.003
2949.1	188.623
2953.46	170.648
2957.81	185.508
2962.16	185.781
2966.5	204.42
2970.85	180.915
2975.19	194.137
2979.52	188.97
2983.86	181.995
2988.19	188.016
2992.52	207.116
2996.85	190.946
3001.17	208.368
3005.49	203.449
3009.8	187.195
3014.12	210.427
3018.43	218.757
3022.74	223.332
3027.04	214.457
3031.34	201.622
3035.64	226.935
3039.94	225.461
3044.23	235.516
3048.52	220.519
3052.81	228.608
3057.09	252.222
3061.38	244.923
3065.65	262.81
3069.93	243.84
3074.2	252.061
3078.47	270.083
3082.74	268.629
3087	275.111
3091.27	262.119
3095.52	274.764
3099.78	275.66
3104.03	304.378
3108.28	287.607
3112.53	304.734
3116.77	287.869
3121.01	293.066
3125.25	302.429
3129.49	336.345
3133.72	317.578
3137.95	337.568
3142.18	343.188
3146.4	352.863
3150.62	377.04
3154.84	353.198
3159.06	352.146
3163.27	374.16
3167.48	381.478
3171.69	363.556
3175.89	358.07
3180.09	384.073
3184.29	376.127
3188.49	391.358
3192.68	377.076
3196.87	382.077
3201.06	374.769
3205.24	369.68
3209.42	405.588
3213.6	374.856
3217.78	378.651
3221.95	358.38
3226.12	331.388
3230.29	387.582
3234.45	360.38
3238.61	368.318
3242.77	347.603
3246.93	360.221
3251.08	356.967
3255.23	337.699
3259.38	331.869
3263.53	335.266
3267.67	357.404
3271.81	356.584
3275.95	350.657
3280.08	330.78
3284.21	308.517
3288.34	322.921
3292.47	332.733
3296.59	333.31
3300.71	310.877
3304.83	325.377
3308.95	330.648
3313.06	338.188
3317.17	313.198
3321.27	323.186
3325.38	323.98
3329.48	341.264
3333.58	349.532
3337.67	341.319
3341.77	354.038
3345.86	354.767
3349.95	331.596
3354.03	341.695
3358.11	347.232
3362.19	355.199
3366.27	351.158
3370.34	327.89
3374.42	347.746
3378.48	360.313
3382.55	355.978
3386.61	334.678
3390.68	354.402
3394.73	333.016
3398.79	338.363
3402.84	353.328
3406.89	322.066
3410.94	339.366
3414.98	334.761
3419.03	337.467
3423.06	335.26
3427.1	357.503
3431.14	350.589
3435.17	348.64
3439.2	346.785
3443.22	335.159
3447.25	331.046
3451.27	339.275
3455.28	332.83
3459.3	361.27
3463.31	327.658
3467.32	331.319
3471.33	319.884
3475.34	313.185
3479.34	319.185
3483.34	304.944
3487.33	293.119
3491.33	314.279
3495.32	317.617
3499.31	290.19
3503.3	300.967
3507.28	298.859
3511.26	281.135
3515.24	299.299
3519.22	294.332
3523.19	284.212
3527.16	276.711
3531.13	261.451
3535.1	261.903
3539.06	275.448
3543.02	270.82
3546.98	292.038
3550.93	269.015
3554.89	276.917
3558.84	261.592
3562.78	282.802
3566.73	270.241
3570.67	283.923
3574.61	289.776
3578.55	282.626
3582.48	272.898
3586.41	279.004
3590.35	263.906
3594.27	267.332
3598.2	244.086
3602.12	217.963
3606.04	234.575
3609.95	235.071
3613.87	216.721
3617.78	230.623
3621.69	228.256
3625.6	198.685
3629.5	228.558
3633.4	217.814
3637.3	223.397
3641.2	202.032
3645.09	216.012
3648.98	240.818
3652.87	211.111
3656.76	194.947
3660.64	216.946
3664.53	200.724
3668.4	200.935
3672.28	201.129
3676.16	176.763
3680.03	199.07
3683.9	177.526
3687.76	194.579
3691.63	184.062
3695.49	170.651
3699.35	190.589
3703.2	185.501
3707.06	180.424
3710.91	183.727
3714.76	201.076
3718.6	181.789
3722.45	182.152
3726.29	179.644
3730.13	171.456
3733.97	183.144
3737.8	172.109
3741.63	175.25
3745.46	186.944
3749.29	175.766
3753.11	170.228
3756.93	164.631
3760.75	176.177
3764.57	153.329
3768.39	162.016
3772.2	173.632
3776.01	179.527
3779.81	173.974
3783.62	174.229
3787.42	186.033
3791.22	168.955
3795.02	166.35
3798.81	166.682
3802.61	167.032
3806.4	161.589
3810.18	167.792
3813.97	173.985
3817.75	162.611
3821.53	157.046
3825.31	172.001
3829.09	172.286
3832.86	169.663
3836.63	196.568
3840.4	170.235
3844.17	170.564
3847.93	179.613
3851.69	176.767
3855.45	179.822
3859.21	156.054
3862.96	176.922
3866.71	165.31
3870.46	171.67
3874.21	186.698
3877.95	174.859
3881.69	151.046
3885.44	163.145
3889.17	175.294
3892.91	163.517
3896.64	172.833
3900.37	158.049
3904.1	167.325
3907.82	179.636
3911.55	176.898
3915.27	180.236
3918.99	144.188
3922.7	171.93
3926.42	166.221
3930.13	181.849
3933.84	163.783
3937.54	164.017
3941.25	179.66
3944.95	149.255
3948.65	164.948
3952.35	186.811
3956.04	159.231
3959.73	165.576
3963.42	165.705
3967.11	159.593
3970.8	175.127
3974.48	178.29
3978.16	165.932
3981.84	165.923
3985.52	172.116
3989.19	165.906
3992.86	156.656
3996.53	153.663
3998.37	169.266