File: Data/3-Raman/raw/bu19w-ff-ore1-fi07-rim_150 (500nm)_532nm_edge_100%_x100_vis_lwd_h50um_15sx2_01.txt
#Acq. time (s)=	15
#Accumulations=	2
#Range (cm-¹)=	50...5000
#Windows=	1
#Auto scanning=	Off
#Autofocus=	Off
#Macrospot=	Off
#AutoExposure=	Off
#Spike filter=	Multiple accum.
#Delay time (s)=	2
#Binning=	1
#Readout mode=	Signal
#DeNoise=	Off
#ICS correction=	On
#Dark correction=	Off
#Inst. Process=	Off
#Detector Gain=	Best Dynamic
#Detector ADC=	50 kHz HS
#Detector temperature (°C)=	-60.09
#Instrument=	LabRAM HR Evol
#Detector=	SIN-EM FIVIS
#Objective=	x100_VIS_LWD
#Grating=	150 (500nm)
#ND Filter=	100%
#Laser=	532nm_Edge
#Hole=	49.98
#Temperature=	0
#Range=	Visible
#StageXY=	75x50mm Scan+
#StageZ=	Z motor
#X (µm)=	0
#Y (µm)=	0
#Z (µm)=	-6.7
#Full time(s)=	34
#Project=	21_05_28
#Sample=	BU19w
#Site=
#Title=	BU19w-FF-ore1-FI07-rim_150 (500nm)_532nm_Edge_100%_x100_VIS_LWD_H50um_15sX2
#Remark=
#Date=	28.05.2021 15:16
#Acquired=	28.05.2021 15:16:32
51.5961	4114.18
56.2453	4620.01
60.8921	4766.82
65.5367	4364.81
70.1768	3904.9
74.8167	3612.91
79.4543	3341.64
84.0897	3172.64
88.7227	3041.85
93.3513	2924.32
97.9798	2782.84
102.606	2627.08
107.23	2628.37
111.851	2598.85
116.469	2817.44
121.086	3729.8
125.7	7788.08
130.313	9558.68
134.921	5446.02
139.529	3514.57
144.134	3269.5
148.738	3174.82
153.337	2971.37
157.936	2706.46
162.532	2726.65
167.126	2898.94
171.716	3115.43
176.306	3487.7
180.894	4103.74
185.477	5051.48
190.06	6772.45
194.64	9463.65
199.219	13019.9
203.793	16268.6
208.367	17144.3
212.939	15141
217.506	11779.4
222.073	8437.67
226.638	6378.42
231.199	4903.11
235.759	3956.41
240.318	3320.38
244.872	2929.86
249.425	2721.35
253.977	2516.64
258.524	2678.53
263.071	3784.63
267.616	4020.45
272.156	2454.06
276.697	1615.5
281.233	1465.55
285.769	1306.71
290.303	1259.11
294.832	1207.25
299.361	1137.19
303.886	1082.78
308.411	1100.96
312.934	1074.31
317.452	1050.12
321.97	1072.07
326.484	1029.57
330.998	1030.43
335.507	1015.36
340.017	1052.48
344.524	1080.23
349.027	1297.69
353.53	3087.36
358.028	4316.68
362.527	2489.45
367.021	1516.07
371.515	1300.13
376.004	1209.74
380.494	1188.76
384.979	1169.36
389.465	1235.06
393.946	1344.64
398.427	1535.92
402.903	2020.83
407.38	1723.66
411.852	1333.32
416.324	1315.81
420.792	1360.76
425.26	1398.61
429.723	1480.5
434.187	1649.39
438.646	1889.89
443.105	2330.28
447.56	3382.64
452.015	5402.36
456.466	10690.9
460.914	29033
465.362	38247.2
469.807	38182.3
474.251	18346.9
478.69	9145.54
483.13	5764.45
487.566	4316.25
491.999	3601.54
496.432	2939.21
500.861	2602.66
505.29	2478.22
509.715	2789.73
514.138	2699.89
518.56	2200.97
522.979	1941.03
527.395	1711.56
531.811	1662.69
536.223	1568.97
540.635	1529.62
545.042	1491.27
549.448	1448.31
553.853	1371.42
558.255	1340.1
562.654	1313.74
567.053	1333.88
571.448	1237.28
575.841	1276.38
580.232	1290.79
584.622	1300.08
589.009	1273.96
593.393	1290.02
597.777	1315.26
602.157	1287.11
606.535	1264.03
610.913	1237.22
615.287	1265.26
619.659	1221.25
624.029	1220.71
628.398	1228.4
632.763	1230.03
637.127	1224.36
641.488	1189.51
645.849	1202.26
650.206	1173.42
654.561	1194.23
658.914	1154.38
663.267	1166.61
667.615	1159.12
671.962	1142.39
676.307	1155.81
680.649	1173.6
684.991	1213.42
689.33	1230.54
693.666	1333.29
698	1472.8
702.332	1345.61
706.662	1279.56
710.992	1230.48
715.318	1180.8
719.641	1192.86
723.963	1141.36
728.283	1156.14
732.6	1176.94
736.918	1180.73
741.231	1169.83
745.542	1156.47
749.852	1177.64
754.159	1152.04
758.464	1210.28
762.767	1155.98
767.068	1158.41
771.369	1179.42
775.666	1205.27
779.961	1227.7
784.254	1252.67
788.545	1291.82
792.834	1459.24
797.12	1596.64
801.405	1799.33
805.688	2429.74
809.968	3001.36
814.247	2429.79
818.524	1694.53
822.798	1419.89
827.071	1355.7
831.341	1337.82
835.612	1302.3
839.878	1308.55
844.142	1324.58
848.405	1252.95
852.665	1299.72
856.923	1253.86
861.18	1266.39
865.434	1279.78
869.686	1238.83
873.936	1288.85
878.185	1320.86
882.431	1297.73
886.675	1273.04
890.915	1293.46
895.155	1273.07
899.393	1225.76
903.63	1252.78
907.864	1247.67
912.096	1260.56
916.326	1256.86
920.554	1269.11
924.78	1243.09
929.004	1262.73
933.227	1249.47
937.447	1213.58
941.665	1223.49
945.881	1210.76
950.095	1223.64
954.305	1214.43
958.516	1181.96
962.724	1217.76
966.93	1176.1
971.134	1169.68
975.337	1183.66
979.537	1128.9
983.735	1134.79
987.93	1202.04
992.124	1169.88
996.316	1150.22
1000.51	1157.76
1004.7	1214.36
1008.88	1196.92
1013.06	1153.93
1017.25	1194.67
1021.43	1184.3
1025.61	1189.65
1029.78	1190.29
1033.96	1214.03
1038.13	1174.6
1042.3	1249.65
1046.47	1215.85
1050.63	1211.51
1054.8	1257.77
1058.96	1260.08
1063.12	1335.83
1067.28	1425.48
1071.44	1415.85
1075.59	1614.11
1079.74	2154.79
1083.89	2588.4
1088.04	2104.76
1092.19	1529.86
1096.33	1395.99
1100.48	1286.95
1104.62	1297.27
1108.76	1237.6
1112.89	1225.64
1117.03	1206.87
1121.16	1247.91
1125.29	1257.62
1129.42	1223.88
1133.55	1244.65
1137.68	1253.86
1141.8	1306.16
1145.92	1285.82
1150.04	1341.28
1154.16	1460.02
1158.27	1675.33
1162.39	1753.1
1166.5	1527.93
1170.61	1325.16
1174.72	1301.53
1178.82	1270.49
1182.93	1273.42
1187.03	1245.1
1191.13	1250
1195.23	1231.98
1199.33	1248.35
1203.42	1220.51
1207.51	1247.56
1211.6	1262.34
1215.69	1251.86
1219.78	1276.82
1223.86	1284.75
1227.95	1307.96
1232.03	1320.57
1236.11	1327.16
1240.18	1299.53
1244.26	1311.59
1248.33	1259.27
1252.41	1254.56
1256.48	1304.06
1260.54	1272.88
1264.61	1272.86
1268.67	1345.18
1272.74	1312.61
1276.8	1308.07
1280.86	1315.52
1284.91	1348.9
1288.97	1281.47
1293.02	1319.52
1297.07	1292.93
1301.12	1272.24
1305.17	1267.43
1309.21	1268.57
1313.25	1274.6
1317.3	1281.18
1321.34	1270.36
1325.37	1252.03
1329.41	1270.75
1333.44	1273.24
1337.48	1283.3
1341.5	1268.1
1345.53	1311.74
1349.56	1283.41
1353.59	1297.99
1357.61	1292.72
1361.63	1278.44
1365.65	1302.05
1369.66	1327.76
1373.68	1330.03
1377.69	1420.25
1381.7	1479.02
1385.72	1451.73
1389.72	1391.28
1393.73	1361.75
1397.73	1354.45
1401.74	1353.92
1405.74	1298.17
1409.73	1331.23
1413.73	1333.88
1417.73	1300.03
1421.72	1308.59
1425.71	1319.93
1429.7	1295.06
1433.69	1299.94
1437.67	1343.29
1441.66	1304.71
1445.64	1360.7
1449.62	1325.79
1453.6	1315.33
1457.57	1331.38
1461.55	1311.69
1465.52	1325.08
1469.49	1351.14
1473.46	1327.25
1477.43	1346.38
1481.39	1348.65
1485.36	1293.08
1489.32	1319.65
1493.28	1334.54
1497.24	1351.36
1501.19	1300.15
1505.15	1335.83
1509.1	1325.17
1513.05	1339.88
1517	1352.7
1520.95	1334.61
1524.9	1362.21
1528.84	1403.47
1532.78	1353.77
1536.72	1372.93
1540.66	1371.78
1544.6	1426.83
1548.53	1380.15
1552.46	1380.95
1556.4	1359.3
1560.32	1419.75
1564.25	1397.73
1568.18	1398.81
1572.1	1392.05
1576.02	1424.87
1579.94	1436.36
1583.86	1415.97
1587.78	1421.51
1591.69	1453
1595.61	1431.51
1599.52	1443.7
1603.43	1426.22
1607.34	1456
1611.24	1451.26
1615.15	1438.97
1619.05	1456.58
1622.95	1477.92
1626.85	1467.9
1630.74	1473.38
1634.64	1434.36
1638.53	1460.34
1642.42	1494.39
1646.31	1482.79
1650.2	1502.01
1654.09	1509.81
1657.97	1481.01
1661.86	1451.15
1665.74	1478.64
1669.62	1474.26
1673.49	1456.92
1677.37	1453.92
1681.24	1447.24
1685.12	1467.09
1688.99	1454.16
1692.86	1417.98
1696.72	1440.02
1700.59	1458.9
1704.45	1450.71
1708.31	1432.72
1712.17	1407.85
1716.03	1432.38
1719.89	1431.33
1723.74	1450.14
1727.6	1422.6
1731.45	1406.22
1735.3	1428.47
1739.14	1462.62
1742.99	1463.75
1746.83	1402.59
1750.68	1430.83
1754.52	1418.67
1758.36	1449.08
1762.19	1467.05
1766.03	1434.77
1769.86	1428.11
1773.69	1423.06
1777.53	1436.66
1781.35	1467.55
1785.18	1473.58
1789	1453.61
1792.83	1458.93
1796.65	1433.33
1800.47	1455.52
1804.29	1440.13
1808.1	1473.57
1811.92	1439.96
1815.73	1415.48
1819.54	1449.79
1823.35	1462.03
1827.16	1494.75
1830.97	1428.97
1834.77	1437.33
1838.58	1461.45
1842.38	1497.51
1846.18	1436.39
1849.97	1463.78
1853.77	1447.33
1857.56	1453.93
1861.36	1448.85
1865.15	1442.7
1868.93	1434.86
1872.72	1469.83
1876.51	1470.75
1880.29	1457.01
1884.07	1471.58
1887.86	1463.16
1891.63	1467.49
1895.41	1470.01
1899.19	1466.09
1902.96	1454.54
1906.73	1451.54
1910.5	1478.17
1914.27	1477.72
1918.04	1476.45
1921.8	1497.4
1925.57	1503.74
1929.33	1483.46
1933.09	1472.53
1936.85	1465.25
1940.6	1504.56
1944.36	1510.31
1948.11	1499.2
1951.87	1454.96
1955.61	1498.31
1959.36	1500.53
1963.11	1520.1
1966.86	1497.31
1970.6	1509.73
1974.34	1500
1978.08	1493.74
1981.82	1493.77
1985.56	1515.04
1989.29	1536.06
1993.02	1544.66
1996.75	1531.53
2000.49	1524.66
2004.21	1512.33
2007.94	1571.94
2011.67	1550.71
2015.39	1546.19
2019.11	1542.44
2022.83	1523.94
2026.55	1541.22
2030.27	1542.05
2033.98	1558.29
2037.69	1539.36
2041.41	1550.5
2045.12	1530.39
2048.82	1557.01
2052.53	1574.78
2056.24	1583.5
2059.94	1560.04
2063.64	1538.43
2067.34	1576.9
2071.04	1562.19
2074.74	1534.53
2078.43	1547.57
2082.13	1567.26
2085.82	1573.81
2089.51	1547.85
2093.2	1558.33
2096.88	1558.41
2100.57	1554.49
2104.25	1587.23
2107.94	1601.1
2111.62	1566.36
2115.3	1534.38
2118.97	1567.26
2122.65	1570.7
2126.32	1572.86
2129.99	1625.73
2133.66	1591.32
2137.33	1582.77
2141	1621.04
2144.67	1588
2148.33	1595.42
2151.99	1619.32
2155.66	1567.12
2159.31	1552.67
2162.97	1623.44
2166.63	1584.76
2170.28	1582.91
2173.94	1603.59
2177.59	1598.21
2181.24	1585.76
2184.89	1599.63
2188.53	1577.54
2192.18	1630.67
2195.82	1614.42
2199.46	1602.15
2203.1	1613.76
2206.74	1569.03
2210.38	1600.35
2214.01	1593.52
2217.65	1590.43
2221.28	1599.3
2224.91	1606.44
2228.54	1622.71
2232.16	1591.09
2235.79	1615.88
2239.41	1568.49
2243.04	1593.23
2246.66	1613.34
2250.28	1601.04
2253.89	1620.54
2257.51	1644
2261.12	1635.71
2264.74	1598.16
2268.35	1631
2271.96	1608.88
2275.57	1622.02
2279.17	1599.84
2282.78	1629.4
2286.38	1629.7
2289.98	1638.48
2293.58	1587.46
2297.18	1651.89
2300.78	1587.66
2304.37	1612.15
2307.97	1603.15
2311.56	1607.18
2315.15	1624.23
2318.74	1636.26
2322.33	1581.6
2325.91	1626.36
2329.5	1608.47
2333.08	1625.35
2336.66	1628.77
2340.24	1594.3
2343.82	1611.47
2347.4	1603.97
2350.97	1650.7
2354.54	1627.06
2358.12	1663.12
2361.69	1605.81
2365.26	1610.04
2368.82	1645.88
2372.39	1638.49
2375.95	1624.52
2379.52	1622.63
2383.08	1603.45
2386.64	1613
2390.19	1614.53
2393.75	1649.42
2397.31	1601.3
2400.86	1628.93
2404.41	1650.12
2407.96	1626.6
2411.51	1615.68
2415.06	1645.53
2418.6	1633.55
2422.15	1646.65
2425.69	1643.59
2429.23	1683.4
2432.77	1671.89
2436.31	1629.19
2439.84	1652.42
2443.38	1669.37
2446.91	1652.83
2450.44	1632.81
2453.97	1636.41
2457.5	1661.53
2461.03	1653.26
2464.55	1685.36
2468.08	1629.3
2471.6	1655.69
2475.12	1665.18
2478.64	1654.6
2482.16	1619.79
2485.67	1674.83
2489.19	1592.35
2492.7	1634.01
2496.21	1648.37
2499.72	1622.07
2503.23	1649.53
2506.74	1647.69
2510.25	1652
2513.75	1651.77
2517.25	1666.8
2520.75	1656.1
2524.25	1647.07
2527.75	1666.53
2531.25	1679.9
2534.74	1666.74
2538.24	1672.53
2541.73	1687.02
2545.22	1646.03
2548.71	1639.88
2552.2	1662.45
2555.68	1642.03
2559.17	1651.08
2562.65	1700.1
2566.13	1655.18
2569.61	1699.15
2573.09	1672.73
2576.57	1688.68
2580.04	1678.7
2583.51	1687.63
2586.99	1688.08
2590.46	1648.25
2593.93	1675.81
2597.4	1684.15
2600.86	1661.5
2604.33	1711.35
2607.79	1661.61
2611.25	1639.14
2614.71	1659.67
2618.17	1643.37
2621.63	1660.96
2625.09	1701.28
2628.54	1673.89
2631.99	1680.8
2635.45	1668.1
2638.9	1716.26
2642.34	1679.75
2645.79	1655.44
2649.24	1653.03
2652.68	1701.71
2656.12	1671.77
2659.56	1659.63
2663.01	1642.63
2666.44	1648.22
2669.88	1662.22
2673.32	1659.14
2676.75	1663.85
2680.18	1714.66
2683.61	1660.99
2687.04	1650.07
2690.47	1650.51
2693.9	1686.94
2697.32	1714.59
2700.75	1676.53
2704.17	1694.36
2707.59	1685.29
2711.01	1673.69
2714.43	1683.83
2717.84	1679.41
2721.26	1682.78
2724.67	1699.43
2728.08	1665.81
2731.49	1659.34
2734.9	1672.41
2738.31	1672.39
2741.71	1676.98
2745.12	1666.22
2748.52	1691.85
2751.92	1667.71
2755.32	1663.14
2758.72	1677.21
2762.12	1713.93
2765.52	1686.15
2768.91	1696.73
2772.3	1664.62
2775.7	1642.74
2779.09	1684.63
2782.47	1677.3
2785.86	1710.31
2789.25	1662.34
2792.63	1704.59
2796.01	1674.41
2799.4	1668.67
2802.78	1689.88
2806.15	1667.01
2809.53	1660.06
2812.91	1674.55
2816.28	1673.95
2819.65	1694.81
2823.03	1692.56
2826.4	1655.1
2829.76	1666.29
2833.13	1641.35
2836.5	1697.78
2839.86	1682.76
2843.22	1706.27
2846.59	1664.03
2849.95	1701.62
2853.3	1653.78
2856.66	1654.24
2860.02	1705.43
2863.37	1692.34
2866.72	1663.34
2870.08	1662.44
2873.43	1699.95
2876.77	1694.21
2880.12	1702.54
2883.47	1686.33
2886.81	1691.64
2890.15	1669.54
2893.5	1631.24
2896.84	1652.99
2900.17	1693.44
2903.51	1630.54
2906.85	1651.61
2910.18	1700.94
2913.52	1694.31
2916.85	1687.56
2920.18	1676.78
2923.51	1662.12
2926.83	1685.14
2930.16	1692.78
2933.48	1665.26
2936.81	1704.53
2940.13	1728.65
2943.45	1692.44
2946.77	1713.77
2950.09	1703.13
2953.4	1704.67
2956.72	1701.56
2960.03	1720.33
2963.34	1671.67
2966.65	1663.49
2969.96	1681.14
2973.27	1690.65
2976.58	1717.12
2979.88	1697.9
2983.19	1687.85
2986.49	1739.86
2989.79	1670.87
2993.09	1692.07
2996.39	1691.76
2999.68	1704.7
3002.98	1715.75
3006.27	1751.28
3009.57	1721.09
3012.86	1684.36
3016.15	1750.35
3019.43	1762.61
3022.72	1707.89
3026.01	1705.97
3029.29	1684.24
3032.57	1675.68
3035.86	1715.24
3039.14	1725.47
3042.41	1713.02
3045.69	1736.55
3048.97	1718.46
3052.24	1735.4
3055.52	1731.55
3058.79	1761.76
3062.06	1759.18
3065.33	1761.6
3068.6	1755.27
3071.86	1755.19
3075.13	1753.6
3078.39	1824.9
3081.65	1773.3
3084.91	1733.64
3088.17	1825.77
3091.43	1819.75
3094.69	1837.59
3097.95	1817.93
3101.2	1850.78
3104.45	1847.15
3107.7	1842.48
3110.95	1857.54
3114.2	1922.45
3117.45	1879.02
3120.7	1907.99
3123.94	1910.31
3127.18	1941.17
3130.43	1934.82
3133.67	1939.94
3136.91	1989.8
3140.14	1977.61
3143.38	2017.82
3146.61	1981.77
3149.85	1986.84
3153.08	2033.93
3156.31	2028.47
3159.54	2072.68
3162.77	2045.27
3166	2112.34
3169.22	2096.19
3172.45	2103.74
3175.67	2110.26
3178.89	2146.17
3182.11	2117.17
3185.33	2186.46
3188.55	2195.4
3191.77	2200.46
3194.98	2209.33
3198.2	2210.53
3201.41	2227.88
3204.62	2289.1
3207.83	2284.69
3211.04	2288.01
3214.25	2300.04
3217.45	2269.42
3220.66	2337.74
3223.86	2339.56
3227.06	2346.36
3230.26	2351.31
3233.46	2414.48
3236.66	2349.04
3239.85	2417.36
3243.05	2398.25
3246.24	2381.15
3249.44	2394.55
3252.63	2452.06
3255.82	2404.75
3259.01	2432.75
3262.19	2433.69
3265.38	2456.25
3268.56	2484.2
3271.75	2465.1
3274.93	2450.62
3278.11	2468.59
3281.29	2486.99
3284.47	2453.39
3287.64	2469.47
3290.82	2509.17
3293.99	2476.61
3297.17	2516.37
3300.34	2450.45
3303.51	2466.05
3306.68	2519.06
3309.84	2484.28
3313.01	2521.38
3316.18	2582
3319.34	2559.94
3322.5	2554.87
3325.66	2536.58
3328.82	2585.51
3331.98	2590
3335.14	2575.76
3338.29	2572.15
3341.45	2599.87
3344.6	2671.95
3347.75	2662.61
3350.9	2651.1
3354.05	2694.23
3357.2	2714.09
3360.35	2692.63
3363.49	2718.62
3366.64	2765.43
3369.78	2818.08
3372.92	2768.97
3376.06	2776.8
3379.2	2777.19
3382.34	2758.82
3385.48	2814.05
3388.61	2794.84
3391.75	2852.32
3394.88	2872.79
3398.01	2880.23
3401.14	2850.42
3404.27	2906.21
3407.4	2887.34
3410.52	2892.37
3413.65	2926.82
3416.77	2935.88
3419.89	2914.23
3423.01	2960.02
3426.13	2921.25
3429.25	2922.02
3432.37	2909.98
3435.49	2921.2
3438.6	2917.44
3441.72	2907.35
3444.83	2899.11
3447.94	2950.36
3451.05	2867.07
3454.16	2932.08
3457.26	2894.09
3460.37	2897.62
3463.47	2870.66
3466.58	2848.33
3469.68	2839.86
3472.78	2792.03
3475.88	2830.4
3478.98	2792.21
3482.07	2757.98
3485.17	2782.46
3488.26	2769.33
3491.36	2719.83
3494.45	2782.46
3497.54	2660.04
3500.63	2703.51
3503.72	2631.05
3506.81	2565.75
3509.89	2613.53
3512.98	2527.71
3516.06	2576.09
3519.14	2536.2
3522.22	2464.48
3525.3	2429.25
3528.38	2423.84
3531.45	2427.69
3534.53	2389.46
3537.61	2344.42
3540.68	2348.71
3543.75	2309.64
3546.82	2279.61
3549.89	2245.5
3552.96	2240.1
3556.03	2212.74
3559.09	2168.69
3562.16	2139.75
3565.22	2136.85
3568.28	2089.09
3571.34	2048.59
3574.4	2105.7
3577.46	2051.96
3580.52	1980.95
3583.57	2025.5
3586.63	1933.29
3589.68	1979.53
3592.73	1936.38
3595.78	1918.8
3598.83	1934.21
3601.88	1865.32
3604.93	1862.55
3607.97	1812.34
3611.02	1791.48
3614.06	1798.89
3617.1	1765.61
3620.14	1716.41
3623.18	1754.13
3626.22	1726.81
3629.26	1715.65
3632.3	1666.71
3635.33	1688.35
3638.36	1653.93
3641.4	1630.1
3644.43	1622.45
3647.46	1636.87
3650.49	1594.38
3653.51	1556.82
3656.54	1547.39
3659.57	1500
3662.59	1556.89
3665.61	1494.86
3668.63	1461.29
3671.65	1492.16
3674.67	1427.84
3677.69	1436.23
3680.71	1426.76
3683.72	1438.94
3686.74	1417.1
3689.75	1352.7
3692.76	1373.48
3695.77	1381.98
3698.78	1360.82
3701.79	1329.51
3704.79	1305.74
3707.8	1321.83
3710.81	1295
3713.81	1308.94
3716.81	1325.58
3719.81	1298.54
3722.81	1295.13
3725.81	1280.17
3728.81	1288.9
3731.8	1268.97
3734.8	1242.25
3737.79	1301.08
3740.78	1263.64
3743.77	1256.51
3746.76	1285.43
3749.75	1248.59
3752.74	1232.61
3755.73	1253.65
3758.71	1267.11
3761.7	1253.02
3764.68	1230.31
3767.66	1216.19
3770.64	1248.55
3773.62	1226.13
3776.6	1229.35
3779.58	1269.5
3782.55	1221.84
3785.53	1197.85
3788.5	1210.75
3791.47	1202.02
3794.44	1228.4
3797.41	1181.26
3800.38	1186.11
3803.35	1180.73
3806.32	1238.69
3809.28	1206.02
3812.24	1215.94
3815.21	1204.14
3818.17	1222.64
3821.13	1204.3
3824.09	1192.6
3827.04	1203.71
3830	1170.29
3832.96	1208.92
3835.91	1202.14
3838.86	1194.48
3841.82	1183.95
3844.77	1198.12
3847.72	1181.89
3850.67	1187.59
3853.61	1180.01
3856.56	1169.59
3859.5	1193.55
3862.45	1193.66
3865.39	1187
3868.33	1186.08
3871.27	1167.8
3874.21	1193.58
3877.15	1174.24
3880.09	1176.82
3883.02	1177.36
3885.96	1182.56
3888.89	1156.91
3891.82	1155.25
3894.75	1175.64
3897.68	1173.76
3900.61	1155.4
3903.54	1162.01
3906.47	1183.86
3909.39	1177.96
3912.31	1140.24
3915.24	1192.73
3918.16	1147.16
3921.08	1141.18
3924	1126.34
3926.92	1161.27
3929.83	1117.43
3932.75	1153.12
3935.67	1120.09
3938.58	1162.01
3941.49	1129.44
3944.4	1127.4
3947.31	1139.79
3950.22	1083.35
3953.13	1125.62
3956.04	1141.13
3958.94	1160.58
3961.85	1141.77
3964.75	1142.17
3967.65	1126.34
3970.55	1134.53
3973.45	1110.13
3976.35	1132.73
3979.25	1106.29
3982.15	1097.04
3985.04	1117.58
3987.94	1127.49
3990.83	1128.71
3993.72	1147.11
3996.61	1114.74
3999.5	1099.65
4002.39	1097.13
4005.28	1114.84
4008.16	1091.2
4011.05	1134.06
4013.93	1101.72
4016.81	1115.67
4019.7	1119.02
4022.58	1115.6
4025.46	1116.05
4028.33	1083.67
4031.21	1088.97
4034.09	1093.34
4036.96	1094.82
4039.84	1111.84
4042.71	1116.25
4045.58	1104.01
4048.45	1099.56
4051.32	1071.91
4054.19	1099.58
4057.05	1060.41
4059.92	1080.4
4062.78	1086.76
4065.65	1078.55
4068.51	1085.89
4071.37	1065
4074.23	1062.59
4077.09	1103
4079.95	1083.99
4082.81	1041.57
4085.66	1067.39
4088.52	1068.79
4091.37	1083.84
4094.22	1034.55
4097.07	1040.8
4099.92	1065.69
4102.77	1073.96
4105.62	1050.89
4108.47	1064.86
4111.31	1055.37
4114.16	1068.25
4117	1051.67
4119.84	1034.93
4122.69	1024.09
4125.53	1048.6
4128.36	1021.26
4131.2	1026.51
4134.04	1061.29
4136.88	1018.03
4139.71	1050.87
4142.54	1041.62
4145.38	1065.03
4148.21	1038.95
4151.04	1034.47
4153.87	1067.95
4156.69	1010.96
4159.52	1028.93
4162.35	1029.66
4165.17	1044.21
4168	1036.24
4170.82	1034.2
4173.64	995.052
4176.46	1026.34
4179.28	1033.19
4182.1	1028.39
4184.91	1007.96
4187.73	1014.01
4190.54	993.668
4193.36	1024.37
4196.17	979.798
4198.98	978.438
4201.79	994.687
4204.6	986.474
4207.41	1013.55
4210.22	1028.89
4213.02	995.071
4215.83	1001.52
4218.63	1006.62
4221.44	1001.8
4224.24	982.086
4227.04	1010.58
4229.84	979.018
4232.64	988.979
4235.43	988.191
4238.23	990.436
4241.02	967.881
4243.82	987.061
4246.61	988.429
4249.4	964.807
4252.19	1001.94
4254.98	966.155
4257.77	950.211
4260.56	949.247
4263.35	994.464
4266.13	940.409
4268.92	963.707
4271.7	973.961
4274.48	941.878
4277.26	945.85
4280.04	956.761
4282.82	938.315
4285.6	949.067
4288.38	948.58
4291.15	930.778
4293.93	947.351
4296.7	955.968
4299.47	945.41
4302.25	954.021
4305.02	961.614
4307.79	931.642
4310.55	933.179
4313.32	916.509
4316.09	928.146
4318.85	953.952
4321.62	923.725
4324.38	933.11
4327.14	952.635
4329.9	931.461
4332.66	899.988
4335.42	930.71
4338.18	917.53
4340.94	939.178
4343.69	933.315
4346.45	925.508
4349.2	938.187
4351.95	937.613
4354.7	925.037
4357.45	930.736
4360.2	917.008
4362.95	910.37
4365.7	900.744
4368.44	917.667
4371.19	912.149
4373.93	891.063
4376.68	896.624
4379.42	921.622
4382.16	897.308
4384.9	867.896
4387.64	889.04
4390.37	879.692
4393.11	886.957
4395.85	860.864
4398.58	895.045
4401.31	877.499
4404.05	909.573
4406.78	903.373
4409.51	910.705
4412.24	894.021
4414.96	876.128
4417.69	898.804
4420.42	896.106
4423.14	847.681
4425.87	847.265
4428.59	892.828
4431.31	851.67
4434.03	846.009
4436.75	863.335
4439.47	883.782
4442.19	840.216
4444.91	832.288
4447.62	848.432
4450.34	888.742
4453.05	837.627
4455.76	846.352
4458.47	825.572
4461.19	856.258
4463.89	834.494
4466.6	856.877
4469.31	856.176
4472.02	857.619
4474.72	838.07
4477.43	841.768
4480.13	843.427
4482.83	846.195
4485.53	841.568
4488.23	855.897
4490.93	837.411
4493.63	805.994
4496.33	819.948
4499.02	830.89
4501.72	814.245
4504.41	847.334
4507.11	810.555
4509.8	802.409
4512.49	828.217
4515.18	810.541
4517.87	792.872
4520.56	786.909
4523.24	821.431
4525.93	792.152
4528.61	802.214
4531.3	812.314
4533.98	830.977
4536.66	783.552
4539.34	805.479
4542.02	781.55
4544.7	794.997
4547.38	784.951
4550.05	789.892
4552.73	798.137
4555.4	812.976
4558.08	767.797
4560.75	766.847
4563.42	774.656
4566.09	782.743
4568.76	772.666
4571.43	797.863
4574.1	773.383
4576.77	780.043
4579.43	769.709
4582.1	777.087
4584.76	767.199
4587.42	771.016
4590.08	795.51
4592.74	781.761
4595.4	742.942
4598.06	755.508
4600.72	757.083
4603.38	755.524
4606.03	774.822
4608.69	741.547
4611.34	744.431
4613.99	748.389
4616.64	785.32
4619.29	736.547
4621.94	776.922
4624.59	764.435
4627.24	755.173
4629.89	748.07
4632.53	753.082
4635.18	755.779
4637.82	716.384
4640.46	737.818
4643.1	730.492
4645.74	733.305
4648.38	731.877
4651.02	757.297
4653.66	751.911
4656.3	706.05
4658.93	729.591
4661.57	722.454
4664.2	727.713
4666.83	716.109
4669.46	707.674
4672.09	711.605
4674.72	739.06
4677.35	736.269
4679.98	703.154
4682.61	682.326
4685.23	714.297
4687.86	708.071
4690.48	717.607
4693.1	683.232
4695.73	683.694
4698.34	712.347
4700.96	734.282
4703.58	725.723
4706.2	711.438
4708.82	692.593
4711.43	711.034
4714.05	713.638
4716.66	701.493
4719.28	697.235
4721.89	707.678
4724.5	692.024
4727.11	701.403
4729.72	682.469
4732.33	677.144
4734.93	680.903
4737.54	652.819
4740.14	663.323
4742.75	677.221
4745.35	667.186
4747.95	688.955
4750.55	701.529
4753.15	677.709
4755.75	658.424
4758.35	661.897
4760.95	635.835
4763.54	690.659
4766.14	664.68
4768.73	663.906
4771.33	659.763
4773.92	657.76
4776.51	653.485
4779.1	688.038
4781.69	640.354
4784.28	664.641
4786.87	630.64
4789.45	641.228
4792.04	651.851
4794.63	667.093
4797.21	650.293
4799.79	642.712
4802.37	640.902
4804.95	657.517
4807.53	648.956
4810.11	650.785
4812.69	642.242
4815.27	649.864
4817.84	629.838
4820.42	625.997
4822.99	640.664
4825.57	650.744
4828.14	651.552
4830.71	645.402
4833.28	635.812
4835.85	625.055
4838.42	629.515
4840.98	609.501
4843.55	604.614
4846.12	640.633
4848.68	652.03
4851.24	642.1
4853.81	612.923
4856.37	604.999
4858.93	615.315
4861.49	598.496
4864.05	610.979
4866.61	624.454
4869.16	619.073
4871.72	585.406
4874.27	596.558
4876.83	633.744
4879.38	622.333
4881.93	646.486
4884.49	602.912
4887.04	618.717
4889.58	592.927
4892.13	602.811
4894.68	615.065
4897.23	603.483
4899.77	601.405
4902.32	583.808
4904.86	586.472
4907.4	602.242
4909.95	591.732
4912.49	596.609
4915.03	597.859
4917.57	579.937
4920.1	590.75
4922.64	588.421
4925.18	601.632
4927.71	586.207
4930.25	573.091
4932.78	576.865
4935.31	575.968
4937.84	580.986
4940.38	568.042
4942.9	578.779
4945.43	574.171
4947.96	587.623
4950.49	566.307
4953.01	551.016
4955.54	587.225
4958.06	559.961
4960.59	585.56
4963.11	572.786
4965.63	581.809
4968.15	588.555
4970.67	562.578
4973.19	573.947
4975.71	559.949
4978.22	572.515
4980.74	539.145
4983.25	534.79
4985.77	571.671
4988.28	560.09
4990.79	547.283
4993.3	552.667
4995.81	548.31
4998.32	542.82