File: Data/3-Raman/raw/bu19w-d-ffore2-fi12-v_1800 (450-850nm)_532nm_edge_100%_x100_vis_lwd_h50um_30sx2_01.txt
#Acq. time (s)=	30
#Accumulations=	2
#Range (cm-¹)=	1200...2365
#Windows=	3
#Auto scanning=	Off
#Autofocus=	Off
#Macrospot=	Off
#AutoExposure=	Off
#Spike filter=	Multiple accum.
#Delay time (s)=	2
#Binning=	1
#Readout mode=	Signal
#DeNoise=	Off
#ICS correction=	On
#Dark correction=	Off
#Inst. Process=	Off
#Detector Gain=	Best Dynamic
#Detector ADC=	50 kHz HS
#Detector temperature (°C)=	-60.09
#Instrument=	LabRAM HR Evol
#Detector=	SIN-EM FIVIS
#Objective=	x100_VIS_LWD
#Grating=	1800 (450-850nm)
#ND Filter=	100%
#Laser=	532nm_Edge
#Hole=	49.98
#Temperature=	0
#Range=	Visible
#StageXY=	75x50mm Scan+
#StageZ=	Z motor
#X (µm)=	0
#Y (µm)=	0
#Z (µm)=	33.2
#Full time(mm:ss)=	3:22
#Project=	21_11_22
#Sample=	BU19w
#Site=
#Title=	BU19w-D-FFore2-FI12-V_1800 (450-850nm)_532nm_Edge_100%_x100_VIS_LWD_H50um_30sX2
#Remark=
#Date=	22.11.2021 14:29
#Acquired=	22.11.2021 14:29:18
1202.84	23.0832
1203.95	21.9677
1205.06	23.014
1206.17	27.2679
1207.29	21.9109
1208.39	21.8782
1209.51	20.7822
1210.62	27.1515
1211.72	20.7597
1212.84	23.95
1213.94	24.9787
1215.05	21.7651
1216.16	27.0566
1217.27	21.7411
1218.38	25.9756
1219.49	23.8246
1220.6	28.0079
1221.71	25.8639
1222.81	32.1992
1223.92	25.8604
1225.03	31.0701
1226.14	34.1466
1227.24	31.0812
1228.35	33.0954
1229.46	32.0417
1230.56	33.0851
1231.67	38.3513
1232.78	32.0614
1233.88	32.0555
1234.99	34.1151
1236.09	29.8797
1237.2	29.8689
1238.3	27.7754
1239.41	27.7646
1240.51	28.8223
1241.62	27.7738
1242.72	27.7496
1243.83	21.4522
1244.93	26.6802
1246.03	26.6644
1247.14	23.5265
1248.24	31.866
1249.34	25.5776
1250.45	24.5161
1251.55	26.617
1252.65	23.4892
1253.75	24.5385
1254.86	24.5331
1255.96	22.4329
1257.06	29.7591
1258.16	33.8989
1259.26	30.8281
1260.36	34.919
1261.46	31.9001
1262.56	51.724
1263.66	56.9472
1264.76	36.0806
1265.86	30.8918
1266.96	31.9411
1268.06	31.9109
1269.16	30.866
1270.26	27.759
1271.36	28.8348
1272.46	25.6913
1273.56	33.0593
1274.66	27.8328
1275.76	31.0132
1276.85	33.1241
1277.95	34.1749
1279.05	35.2514
1280.15	46.8149
1281.24	78.2886
1282.34	224.86
1283.44	535.501
1284.53	191.051
1285.63	60.5006
1286.73	39.4753
1287.82	36.3274
1288.92	27.8976
1290.01	25.7895
1291.11	28.9825
1292.21	31.0988
1293.3	29.0507
1294.4	29.048
1295.49	26.9177
1296.58	27.9601
1297.68	26.912
1298.77	24.8032
1299.87	25.8665
1300.96	29.0244
1302.05	22.6867
1303.15	25.832
1304.24	24.7715
1305.33	24.7734
1306.42	24.7801
1307.52	22.6738
1308.61	25.8432
1309.7	24.7996
1310.79	27.9588
1311.88	27.9605
1312.98	22.6936
1314.07	21.634
1315.16	26.9223
1316.25	23.7544
1317.34	19.5287
1318.43	26.9059
1319.52	20.5522
1320.61	24.7619
1321.7	24.7634
1322.79	22.6405
1323.88	24.7054
1324.97	19.478
1326.06	19.5024
1327.15	25.829
1328.23	27.9159
1329.32	23.6654
1330.41	25.7365
1331.5	22.5573
1332.59	22.5383
1333.67	25.6695
1334.76	20.4189
1335.85	25.6391
1336.94	21.4486
1338.02	24.5921
1339.11	24.583
1340.2	24.5612
1341.28	22.4667
1342.37	23.5019
1343.45	22.4258
1344.54	20.3128
1345.63	21.3449
1346.71	26.537
1347.8	23.3945
1348.88	26.4961
1349.96	21.3094
1351.05	25.5007
1352.13	23.3604
1353.22	24.3968
1354.3	24.3841
1355.39	23.3309
1356.47	26.4256
1357.55	24.3283
1358.63	25.3558
1359.72	21.2045
1360.8	23.2825
1361.88	26.3886
1362.97	25.3313
1364.05	28.4052
1365.13	27.3691
1366.21	25.3084
1367.29	29.4364
1368.37	36.6415
1369.45	35.5573
1370.54	29.3485
1371.62	27.2783
1372.7	32.428
1373.78	30.3545
1374.86	34.4589
1375.94	37.6085
1377.02	40.6818
1378.09	43.6809
1379.18	42.6105
1380.25	51.7816
1381.33	49.6997
1382.41	55.9023
1383.49	64.1654
1384.57	90.6452
1385.65	189.032
1386.72	1036.65
1387.8	337.851
1388.88	78.3536
1389.96	51.6739
1391.03	41.4202
1392.11	36.3004
1393.19	33.2414
1394.26	33.2248
1395.34	30.1482
1396.42	28.1138
1397.49	25.0525
1398.57	25.0639
1399.64	30.2289
1400.72	23.0721
1401.79	29.2117
1402.87	26.1171
1403.94	29.184
1405.02	31.2428
1406.09	31.2518
1407.17	43.5697
1408.24	68.1218
1409.31	53.7628
1410.39	32.3356
1411.46	28.1901
1412.53	24.0977
1413.61	27.1861
1414.68	27.1987
1415.75	22.0655
1416.82	24.1153
1417.9	21.0164
1418.97	21.0167
1420.04	23.1167
1421.11	19.9681
1422.18	22.0158
1423.26	24.0763
1424.33	25.078
1425.4	21.9823
1426.47	23.0125
1427.54	24.0574
1428.61	18.9562
1429.68	23.0494
1430.75	16.8699
1431.82	17.8998
1432.89	18.9245
1433.96	21.992
1435.02	23.0103
1436.09	23.0181
1437.16	20.9841
1438.23	20.9902
1439.3	28.1656
1440.37	19.9617
1441.43	19.9571
1442.5	17.9212
1443.57	17.9154
1444.64	20.9847
1445.7	23.0421
1446.77	23.039
1447.84	20.978
1448.9	20.9707
1449.97	21.9941
1451.04	15.8493
1452.1	18.9223
1453.17	17.9016
1454.23	20.9682
1455.3	16.8671
1456.36	17.8946
1457.43	18.9166
1458.49	17.8844
1459.56	20.9422
1460.62	18.8788
1461.69	16.852
1462.75	18.8452
1463.81	19.8594
1464.88	18.8356
1465.94	17.813
1467	22.8985
1468.07	21.8678
1469.13	19.8196
1470.19	16.762
1471.25	18.7891
1472.32	21.8457
1473.38	22.8557
1474.44	19.7936
1475.5	15.7199
1476.56	20.7897
1477.62	17.7229
1478.68	22.7888
1479.75	17.7285
1480.81	17.7319
1481.87	15.6697
1482.93	20.7289
1483.99	19.7188
1485.05	19.7091
1486.11	18.6812
1487.17	22.7227
1488.22	19.6774
1489.28	21.6975
1490.34	19.673
1491.4	18.6614
1492.46	17.6437
1493.52	16.6169
1494.58	15.603
1495.63	14.5928
1496.69	19.6434
1497.75	20.6546
1498.81	17.619
1499.86	19.6301
1500.92	18.6117
1501.98	17.6054
1503.03	16.5822
1504.09	18.5987
1505.15	19.6065
1506.2	21.622
1507.26	17.5943
1508.31	16.5717
1509.37	19.5549
1510.42	17.5254
1511.48	20.55
1512.53	19.5288
1513.59	17.5054
1514.64	18.5052
1515.7	16.506
1516.75	19.5204
1517.8	17.5116
1518.86	17.5148
1519.91	18.5104
1520.96	22.4971
1522.02	21.4858
1523.07	19.4909
1524.12	16.4942
1525.17	19.4941
1526.23	18.4852
1527.28	18.4798
1528.33	19.4938
1529.38	17.4871
1530.43	19.5112
1531.48	20.5175
1532.53	17.5004
1533.59	20.4803
1534.64	19.458
1535.69	22.4452
1536.74	20.4755
1537.79	19.5063
1538.84	20.4966
1539.89	20.4765
1540.94	18.4532
1541.98	17.4637
1543.03	24.4917
1544.08	19.4877
1545.13	17.4752
1546.18	17.4657
1547.23	18.4713
1548.28	20.5335
1549.33	21.5379
1550.37	20.5192
1551.42	19.5017
1552.47	20.4861
1553.52	20.4843
1554.56	21.4892
1555.61	23.4742
1556.65	22.4478
1557.7	20.4376
1558.75	14.4437
1559.79	17.4517
1560.84	21.4478
1561.88	19.4635
1562.93	22.3297
1563.98	19.4268
1565.02	19.4418
1566.07	23.446
1567.11	22.4348
1568.15	22.4341
1569.2	23.4227
1570.24	20.4135
1571.29	25.4021
1572.33	19.4314
1573.37	21.4327
1574.42	24.4021
1575.46	20.386
1576.5	18.3906
1577.55	20.3903
1578.59	19.3844
1579.63	21.3658
1580.67	23.3537
1581.72	20.3664
1582.76	18.3731
1583.8	22.3404
1584.84	22.3318
1585.88	22.3393
1586.92	18.3651
1587.96	19.3661
1589	21.3534
1590.04	21.3336
1591.08	21.3029
1592.12	25.2808
1593.16	24.2789
1594.2	20.3081
1595.24	23.2892
1596.28	24.2611
1597.32	23.2528
1598.36	21.2461
1599.4	18.2554
1600.44	22.1953
1601.48	22.1903
1602.51	23.1811
1603.55	26.1593
1604.59	28.1434
1605.63	21.215
1606.66	25.1501
1607.7	18.3566
1608.74	25.7424
1609.77	23.6927
1610.81	22.4211
1611.85	22.6468
1612.88	21.9326
1613.92	25.1185
1614.95	22.2062
1615.99	22.0144
1617.03	27.6477
1618.06	22.494
1619.1	24.1968
1620.13	23.0502
1621.17	25.6366
1622.2	25.4491
1623.23	22.3033
1624.27	21.7397
1625.3	25.672
1626.34	28.9072
1627.37	23.6253
1628.4	21.5715
1629.44	23.0299
1630.47	25.5109
1631.29	23.675
1632.33	23.6734
1633.38	23.663
1634.42	27.5862
1635.47	21.6697
1636.51	22.6515
1637.56	22.6505
1638.6	23.6386
1639.65	26.5842
1640.69	23.6265
1641.73	23.6139
1642.78	24.6033
1643.82	22.6255
1644.86	25.5659
1645.91	24.5923
1646.95	23.6162
1647.99	22.6486
1649.03	23.64
1650.08	27.5748
1651.12	25.6067
1652.16	25.6133
1653.2	25.6399
1654.24	25.6437
1655.28	25.6334
1656.33	21.6729
1657.37	23.6353
1658.41	24.6363
1659.45	23.6459
1660.49	26.6523
1661.53	24.6479
1662.57	24.6249
1663.61	23.6957
1664.65	21.6736
1665.69	21.6657
1666.72	21.6878
1667.76	22.688
1668.8	19.7198
1669.84	20.71
1670.88	19.7231
1671.92	22.6992
1672.96	21.7172
1674	22.7078
1675.03	18.7407
1676.07	20.7031
1677.11	23.6582
1678.15	21.6722
1679.18	23.6452
1680.22	22.6547
1681.25	20.6744
1682.29	20.6669
1683.33	17.7034
1684.36	20.672
1685.4	20.6619
1686.43	20.6469
1687.47	20.6344
1688.51	20.6415
1689.54	18.6684
1690.58	18.6503
1691.61	18.6323
1692.64	22.5717
1693.68	19.6216
1694.71	17.6378
1695.75	17.6225
1696.78	20.5706
1697.81	20.5644
1698.85	19.5713
1699.88	16.6074
1700.91	16.6017
1701.95	17.5859
1702.98	17.5818
1704.01	17.5647
1705.04	19.5058
1706.08	19.4789
1707.11	16.5328
1708.14	17.5152
1709.17	17.5175
1710.2	22.3835
1711.23	16.4926
1712.27	18.4402
1713.3	18.4433
1714.33	15.4944
1715.36	16.4402
1716.39	17.4027
1717.42	16.4278
1718.45	18.359
1719.48	17.3678
1720.51	17.3515
1721.54	17.3456
1722.56	13.4437
1723.59	17.3109
1724.62	17.2995
1725.65	17.2852
1726.68	19.1726
1727.71	14.3413
1728.74	18.2217
1729.76	15.3157
1730.79	15.2965
1731.82	17.2024
1732.85	15.2566
1733.87	17.1724
1734.9	16.1996
1735.93	15.2237
1736.95	16.1602
1737.98	18.0543
1739.01	16.1234
1740.03	16.1163
1741.06	18.9781
1742.08	15.1442
1743.11	16.0958
1744.13	13.212
1745.16	15.1087
1746.18	17.0184
1747.21	16.0739
1748.23	15.1259
1749.26	17.9781
1750.28	12.2343
1751.31	16.0384
1752.33	15.074
1753.35	15.0605
1754.38	16.944
1755.4	15.0425
1756.42	18.8492
1757.44	15.9901
1758.47	16.9298
1759.49	17.8735
1760.51	15.9741
1761.53	16.9323
1762.56	15.0378
1763.58	15.9887
1764.6	14.0794
1765.62	15.023
1766.64	16.8949
1767.66	15.9489
1768.68	17.8617
1769.7	15.9669
1770.72	16.9246
1771.74	13.1193
1772.76	15.9889
1773.78	17.8978
1774.8	18.8381
1775.82	16.918
1776.84	13.101
1777.86	15.0094
1778.88	15.964
1779.9	15.0204
1780.92	15.0263
1781.94	15.0356
1782.95	17.8938
1783.97	16.9427
1784.99	16.0124
1786.01	14.1238
1787.03	15.0944
1788.04	14.137
1789.06	16.0365
1790.08	14.1233
1791.09	16.0414
1792.11	15.0878
1793.13	15.109
1794.14	14.1584
1795.16	17.0491
1796.17	15.1255
1797.19	14.153
1798.21	16.0671
1799.22	17.9886
1800.24	14.1535
1801.25	16.0823
1802.27	12.2432
1803.28	14.179
1804.29	15.1465
1805.31	15.1456
1806.32	15.1461
1807.34	17.0752
1808.35	14.1794
1809.36	13.2146
1810.38	13.2203
1811.39	19.0214
1812.4	15.1719
1813.41	17.1068
1814.43	17.1017
1815.44	16.1279
1816.45	15.1664
1817.46	16.1387
1818.47	15.1775
1819.49	16.1513
1820.5	13.2473
1821.51	17.1166
1822.52	16.1533
1823.53	16.1532
1824.54	17.124
1825.55	14.2181
1826.56	14.2113
1827.57	17.1093
1828.58	14.2062
1829.59	15.1811
1830.6	19.0622
1831.61	16.1496
1832.62	12.2503
1833.63	16.1934
1834.64	16.1285
1835.65	16.0969
1836.65	16.1384
1837.66	14.178
1838.67	16.0801
1839.68	17.0224
1840.69	15.0941
1841.7	15.0928
1842.7	16.0561
1843.71	15.1146
1844.72	15.0553
1845.72	16.9854
1846.73	13.1223
1847.74	15.9872
1848.74	13.0924
1849.75	15.0097
1850.75	17.8842
1851.76	15.945
1852.76	14.9702
1853.77	16.8806
1854.78	15.9164
1855.78	14.946
1856.79	15.8875
1857.79	16.8476
1858.79	13.0287
1859.8	15.8904
1860.8	13.0073
1861.81	16.8161
1862.81	15.8412
1863.81	16.7654
1864.82	12.9358
1865.82	13.8818
1866.82	13.8786
1867.83	14.8247
1868.83	15.7693
1869.83	14.8086
1870.83	13.8513
1871.84	18.5799
1872.84	16.6607
1873.84	13.7984
1874.84	16.5964
1875.84	17.5827
1876.84	17.5972
1877.84	15.6994
1878.84	14.7315
1879.84	14.6965
1880.84	15.6452
1881.84	15.6212
1882.85	14.6949
1883.85	13.7559
1884.84	16.5693
1885.84	14.662
1886.84	15.5906
1887.84	12.7722
1888.84	14.6524
1889.84	16.5286
1890.84	18.379
1891.84	14.6117
1892.83	11.7941
1893.83	15.561
1894.83	12.7434
1895.83	15.557
1896.83	11.7855
1897.82	15.5391
1898.82	11.7883
1899.82	17.4372
1900.81	18.3691
1901.81	15.5439
1902.81	15.5395
1903.8	15.524
1904.8	15.5215
1905.79	15.5274
1906.79	17.4188
1907.79	14.615
1908.78	14.6198
1909.78	13.6738
1910.77	14.618
1911.77	17.4611
1912.76	15.5819
1913.76	17.4608
1914.75	13.6779
1915.74	14.6256
1916.74	14.6444
1917.73	13.7017
1918.72	15.6028
1919.72	13.7111
1920.71	19.3745
1921.7	12.7493
1922.7	12.7536
1923.69	13.7129
1924.68	15.6157
1925.67	16.5681
1926.66	14.682
1927.66	15.646
1928.65	20.3937
1929.64	13.739
1930.63	13.7355
1931.62	15.6714
1932.61	14.7561
1933.61	13.7916
1934.6	14.7309
1935.59	14.7229
1936.58	17.5899
1937.57	18.5524
1938.56	15.7098
1939.55	12.8409
1940.54	16.6618
1941.52	14.7559
1942.51	12.8573
1943.5	14.7781
1944.49	13.82
1945.48	12.8604
1946.47	14.778
1947.46	15.7527
1948.44	14.8169
1949.43	18.671
1950.42	17.7164
1951.41	14.8033
1952.39	11.914
1953.38	16.7292
1954.37	15.7838
1955.36	16.7528
1956.34	17.7086
1957.33	17.6987
1958.31	16.7251
1959.3	15.7622
1960.29	13.8434
1961.27	10.9651
1962.26	14.804
1963.24	14.808
1964.23	18.6608
1965.21	12.8936
1966.2	16.7318
1967.18	14.7911
1968.17	17.658
1969.15	14.7765
1970.14	15.7335
1971.12	17.638
1972.1	16.6775
1973.09	14.7666
1974.07	14.7674
1975.05	12.8418
1976.04	16.6686
1977.02	17.6273
1978	14.7427
1978.98	16.651
1979.97	15.6845
1980.95	15.6702
1981.93	16.6189
1982.91	16.6092
1983.89	17.5712
1984.88	15.6484
1985.86	13.7072
1986.84	16.5336
1987.82	16.54
1988.8	17.5023
1989.78	17.5119
1990.76	14.8413
1991.74	18.9367
1992.72	17.2161
1993.7	17.2476
1994.68	15.5224
1995.66	15.3793
1996.64	14.8185
1997.62	16.9031
1998.6	17.6556
1999.57	14.5527
2000.55	15.2004
2001.53	18.0171
2002.51	15.2702
2003.49	15.3606
2004.47	15.7992
2005.44	16.3852
2006.42	13.3207
2007.4	16.1791
2008.38	16.5548
2009.35	16.8719
2010.33	16.2854
2011.3	16.2798
2012.18	18.5954
2013.17	16.7243
2014.16	16.741
2015.15	16.7231
2016.14	15.7592
2017.13	16.6821
2018.11	16.6803
2019.1	18.5521
2020.09	14.7929
2021.08	15.7142
2022.06	16.6288
2023.05	16.6078
2024.04	15.7013
2025.02	15.7134
2026.01	15.7472
2027	15.6937
2027.98	16.6017
2028.97	14.7438
2029.96	18.4997
2030.94	18.5178
2031.93	16.6033
2032.91	13.8324
2033.9	18.5056
2034.88	13.8332
2035.87	17.5622
2036.85	15.6816
2037.83	18.4625
2038.82	16.5873
2039.8	16.5774
2040.79	19.3856
2041.77	11.9303
2042.75	17.5289
2043.74	16.6176
2044.72	16.5872
2045.7	14.7191
2046.69	19.3964
2047.67	15.6804
2048.65	14.7389
2049.63	15.6747
2050.62	14.7505
2051.6	16.6336
2052.58	17.562
2053.56	14.7506
2054.54	13.8156
2055.52	17.566
2056.5	16.6413
2057.48	19.4458
2058.46	11.9601
2059.45	15.707
2060.43	14.7788
2061.4	16.6591
2062.39	14.7953
2063.37	16.6857
2064.34	14.8124
2065.32	15.7597
2066.3	18.5809
2067.28	17.6256
2068.26	15.769
2069.24	15.7869
2070.22	16.7245
2071.2	18.6085
2072.18	14.8545
2073.15	17.7087
2074.13	13.9295
2075.11	17.6912
2076.09	16.7565
2077.06	17.7189
2078.04	18.6674
2079.02	17.719
2080	17.7228
2080.97	17.7204
2081.95	12.9958
2082.93	16.7762
2083.9	17.7372
2084.88	16.7974
2085.85	13.9596
2086.83	14.9147
2087.8	17.7615
2088.78	17.7711
2089.75	15.8947
2090.73	15.9107
2091.7	16.8685
2092.68	17.8106
2093.65	15.9032
2094.63	14.9442
2095.6	16.8367
2096.57	16.834
2097.55	17.7837
2098.52	14.9458
2099.5	17.7955
2100.47	19.6839
2101.44	19.6834
2102.41	16.8452
2103.39	18.7566
2104.36	16.8589
2105.33	15.8945
2106.3	20.6326
2107.27	18.7421
2108.25	16.8414
2109.22	14.9354
2110.19	16.8391
2111.16	19.6985
2112.13	14.9449
2113.1	16.8402
2114.07	17.7801
2115.04	18.7244
2116.01	18.7061
2116.99	17.7425
2117.96	19.6366
2118.92	18.703
2119.9	14.9188
2120.86	17.7688
2121.83	14.9068
2122.8	16.7764
2123.77	14.8672
2124.74	14.858
2125.71	16.7444
2126.68	15.7957
2127.65	15.7915
2128.61	14.8382
2129.58	15.7734
2130.55	18.5993
2131.52	17.6573
2132.48	16.7107
2133.45	17.6385
2134.42	15.7511
2135.39	18.5787
2136.35	16.7006
2137.32	16.6803
2138.28	17.6148
2139.25	17.6052
2140.22	13.8543
2141.18	15.6967
2142.15	16.6423
2143.12	16.6407
2144.08	16.6342
2145.05	13.8071
2146.01	17.5548
2146.98	16.5973
2147.94	17.5235
2148.9	16.5941
2149.87	17.5301
2150.83	15.6457
2151.8	15.6268
2152.76	18.4073
2153.72	15.5928
2154.69	16.5292
2155.65	15.6004
2156.61	15.5933
2157.58	10.9109
2158.54	16.5034
2159.5	18.3663
2160.47	16.4941
2161.43	19.281
2162.39	17.4107
2163.35	15.5453
2164.31	16.4664
2165.27	18.3017
2166.24	16.4408
2167.2	15.5289
2168.16	17.3918
2169.12	14.5752
2170.08	15.4956
2171.04	15.4974
2172	14.5697
2172.96	16.4249
2173.92	15.4894
2174.88	13.6312
2175.84	16.4088
2176.8	14.5518
2177.76	13.6212
2178.72	13.6169
2179.68	15.4664
2180.64	15.4535
2181.59	16.3704
2182.55	15.4475
2183.51	13.6019
2184.47	16.4027
2185.43	14.5454
2186.38	16.3868
2187.34	18.227
2188.3	16.3756
2189.26	18.2351
2190.21	17.316
2191.17	14.5501
2192.13	15.4843
2193.08	15.4722
2194.04	15.4543
2195	14.5216
2195.95	13.6055
2196.91	14.5521
2197.86	14.5791
2198.82	18.2894
2199.78	14.5471
2200.73	17.3516
2201.69	15.5271
2202.64	14.551
2203.59	15.4826
2204.55	15.4818
2205.5	15.4943
2206.46	16.4329
2207.41	14.5717
2208.37	14.5802
2209.32	14.5906
2210.27	18.318
2211.23	13.653
2212.18	12.7327
2213.13	9.93296
2214.09	17.3997
2215.04	15.5333
2215.99	17.4047
2216.94	15.5457
2217.9	13.6763
2218.85	14.5983
2219.8	15.5271
2220.75	13.669
2221.7	14.6194
2222.65	14.6331
2223.6	17.4556
2224.55	14.6542
2225.5	16.5275
2226.46	13.7117
2227.41	15.5994
2228.36	15.6121
2229.31	16.5646
2230.26	13.7547
2231.21	13.7629
2232.16	15.6385
2233.11	14.6889
2234.05	15.6321
2235	16.5928
2235.95	11.8979
2236.9	16.6163
2237.85	18.4978
2238.8	11.9034
2239.75	13.7955
2240.69	14.7349
2241.64	14.7354
2242.59	13.8091
2243.54	14.7654
2244.48	15.7189
2245.43	14.7709
2246.38	15.7135
2247.32	14.7693
2248.27	14.7567
2249.22	12.8643
2250.16	13.826
2251.11	16.6845
2252.06	15.7404
2253	19.5351
2253.95	16.7015
2254.89	12.9131
2255.84	15.7655
2256.78	14.8223
2257.73	16.7295
2258.67	12.9356
2259.62	13.8918
2260.56	14.8581
2261.51	15.8339
2262.45	14.893
2263.39	13.9345
2264.34	10.1052
2265.28	14.8653
2266.22	13.9157
2267.17	12.9769
2268.11	17.767
2269.05	15.8651
2270	17.7819
2270.94	14.9145
2271.88	13.0027
2272.82	13.0043
2273.77	15.8899
2274.71	14.9481
2275.65	12.0822
2276.59	18.8001
2277.53	17.8172
2278.47	14.9312
2279.41	16.8517
2280.36	15.9077
2281.3	13.0511
2282.24	14.9863
2283.18	14.0168
2284.12	15.9508
2285.06	16.9288
2286	16.9191
2286.94	13.0481
2287.88	13.0447
2288.82	14.9817
2289.75	14.993
2290.69	16.9301
2291.63	15.9614
2292.57	13.0623
2293.51	14.0121
2294.45	14.9791
2295.39	14.9948
2296.32	15.0067
2297.26	16.9396
2298.2	14.0508
2299.14	14.0528
2300.07	15.0153
2301.01	15.0155
2301.95	13.0924
2302.89	12.1314
2303.82	15.0345
2304.76	15.0301
2305.69	15.992
2306.63	16.9682
2307.57	17.9465
2308.5	17.9293
2309.44	16.9384
2310.37	15.9695
2311.31	15.9898
2312.24	13.1062
2313.18	16.9588
2314.11	14.0446
2315.05	15.0181
2315.98	15.0056
2316.92	14.0327
2317.85	14.999
2318.78	15.9752
2319.72	14.0567
2320.65	17.9256
2321.58	17.9254
2322.52	16.9385
2323.45	18.8541
2324.38	17.8728
2325.32	16.9016
2326.25	24.603
2327.18	53.4938
2328.11	62.1458
2329.05	26.5309
2329.98	21.6957
2330.91	16.8728
2331.84	12.051
2332.77	14.9335
2333.7	14.931
2334.63	13.9664
2335.56	13.9624
2336.5	12.0398
2337.43	15.8776
2338.36	11.0617
2339.29	17.7621
2340.22	13.9211
2341.15	14.8782
2342.08	12.9606
2343.01	12.9507
2343.93	16.7756
2344.86	14.8574
2345.79	15.8184
2346.72	14.8434
2347.65	16.7032
2348.58	16.7692
2349.51	14.8096
2350.44	13.827
2351.36	14.7745
2352.29	15.7326
2353.22	12.8673
2354.15	14.751
2355.07	11.8897
2356	14.7331
2356.93	12.827
2357.86	16.6097
2358.78	14.697
2359.71	13.7342
2360.63	14.6708
2361.56	12.7709
2362.49	14.6523
2363.41	17.4578
2364.34	14.6421
2364.8	14.6471