File: Data/3-Raman/raw/bu19(2)w-a-ff1-fi08-v_1800 (450-850nm)_532nm_edge_100%_x100_vis_lwd_h100um_30sx2_01.txt
#Acq. time (s)=	30
#Accumulations=	2
#Range (cm-¹)=	1200...2365
#Windows=	3
#Auto scanning=	Off
#Autofocus=	Off
#Macrospot=	Off
#AutoExposure=	Off
#Spike filter=	Multiple accum.
#Delay time (s)=	2
#Binning=	1
#Readout mode=	Signal
#DeNoise=	Off
#ICS correction=	On
#Dark correction=	Off
#Inst. Process=	Off
#Detector Gain=	Best Dynamic
#Detector ADC=	50 kHz HS
#Detector temperature (°C)=	-60.09
#Instrument=	LabRAM HR Evol
#Detector=	SIN-EM FIVIS
#Objective=	x100_VIS_LWD
#Grating=	1800 (450-850nm)
#ND Filter=	100%
#Laser=	532nm_Edge
#Hole=	100.021
#Temperature=	0
#Range=	Visible
#StageXY=	75x50mm Scan+
#StageZ=	Z motor
#X (µm)=	0
#Y (µm)=	0
#Z (µm)=	-63.9
#Full time(mm:ss)=	3:23
#Project=	21_11_26
#Sample=	BU19(2)w
#Site=
#Title=	BU19(2)w-A-FF1-FI08-V_1800 (450-850nm)_532nm_Edge_100%_x100_VIS_LWD_H100um_30sX2
#Remark=
#Date=	26.11.2021 16:41
#Acquired=	26.11.2021 16:41:21
1202.72	95.1745
1203.84	102.742
1204.95	88.69
1206.06	84.2638
1207.17	81.9583
1208.28	89.3622
1209.39	90.3356
1210.5	77.4655
1211.61	73.0759
1212.72	76.1709
1213.83	82.4865
1214.94	79.2796
1216.05	76.0686
1217.16	80.2073
1218.27	82.238
1219.38	76.8781
1220.49	74.7205
1221.6	76.8129
1222.71	74.5905
1223.81	70.2217
1224.92	79.6399
1226.03	70.1394
1227.14	77.512
1228.25	78.3872
1229.35	86.6046
1230.46	79.4607
1231.57	82.3868
1232.67	80.2828
1233.78	79.2125
1234.89	76.0875
1235.99	79.2732
1237.1	76.0992
1238.2	75.999
1239.31	80.1006
1240.41	81.1181
1241.52	82.1721
1242.62	80.0425
1243.73	77.9684
1244.83	79.013
1245.94	79.9847
1247.04	87.2645
1248.14	84.1012
1249.25	86.1431
1250.35	86.1384
1251.45	83.9684
1252.56	93.3029
1253.66	88.0178
1254.76	92.241
1255.87	100.607
1256.97	101.67
1258.07	116.262
1259.17	110.981
1260.27	116.272
1261.37	145.351
1262.48	179.121
1263.58	222.435
1264.68	170.839
1265.78	140.364
1266.88	126.778
1267.98	101.792
1269.08	106.115
1270.18	110.302
1271.28	111.243
1272.38	104.971
1273.47	108.237
1274.57	116.729
1275.67	113.593
1276.77	113.677
1277.87	131.629
1278.97	153.831
1280.07	196.984
1281.16	416.828
1282.26	1176.03
1283.36	2351.79
1284.45	1521.6
1285.55	385.74
1286.65	194.033
1287.75	153.95
1288.84	128.649
1289.94	121.351
1291.03	106.635
1292.13	109.779
1293.22	95.0255
1294.32	98.3016
1295.42	96.2123
1296.51	93.2412
1297.61	95.3381
1298.7	91.056
1299.79	83.615
1300.89	93.1401
1301.98	87.8699
1303.08	86.8336
1304.17	79.4057
1305.26	79.3942
1306.35	83.542
1307.45	86.6867
1308.54	80.3607
1309.63	83.547
1310.73	86.7226
1311.82	77.2336
1312.91	76.2113
1314	84.6284
1315.09	77.243
1316.18	79.392
1317.28	77.2632
1318.37	74.1147
1319.46	73.0584
1320.55	76.2252
1321.64	77.2243
1322.73	68.7128
1323.82	70.7936
1324.91	78.1751
1326	69.6898
1327.09	71.6755
1328.18	72.8484
1329.27	72.9324
1330.35	66.5895
1331.44	77.0704
1332.53	79.0609
1333.62	72.6459
1334.71	72.5607
1335.79	74.5953
1336.88	70.3516
1337.97	76.6083
1339.06	73.4031
1340.14	73.3968
1341.23	76.5408
1342.32	78.6019
1343.4	76.4377
1344.49	77.4729
1345.58	70.1151
1346.66	71.0574
1347.75	76.1815
1348.83	64.6786
1349.92	77.1258
1351	76.0215
1352.09	77.0012
1353.17	74.965
1354.25	83.3691
1355.34	81.0936
1356.42	75.8862
1357.51	75.8453
1358.59	79.945
1359.67	78.8481
1360.76	91.2027
1361.84	87.0271
1362.92	88.0263
1364	92.1949
1365.09	97.3649
1366.17	82.7903
1367.25	88.8988
1368.33	108.531
1369.41	190.237
1370.5	99.2208
1371.58	92.9367
1372.66	101.048
1373.74	103.037
1374.82	106.091
1375.9	105.054
1376.98	117.358
1378.06	116.283
1379.14	123.685
1380.22	129.801
1381.3	150.098
1382.38	172.538
1383.46	204.087
1384.54	338.274
1385.61	856.824
1386.69	3883.24
1387.77	3545.23
1388.85	589.197
1389.93	253.572
1391	180.386
1392.08	152.575
1393.16	126.858
1394.23	111.456
1395.31	114.517
1396.39	111.478
1397.46	100.164
1398.54	107.299
1399.62	97.1076
1400.69	101.232
1401.77	108.445
1402.84	97.3241
1403.92	102.545
1404.99	108.626
1406.07	135.21
1407.14	187.442
1408.22	286.945
1409.29	286
1410.37	159.888
1411.44	103.361
1412.51	91.0434
1413.59	77.9333
1414.66	74.7594
1415.73	75.8171
1416.81	69.6761
1417.88	72.788
1418.95	72.7983
1420.02	74.8322
1421.1	74.7699
1422.17	69.6384
1423.24	70.81
1424.31	64.4209
1425.38	71.5992
1426.45	67.5127
1427.52	60.2692
1428.59	65.3282
1429.67	64.32
1430.74	58.2226
1431.81	59.3207
1432.87	60.3107
1433.95	54.0722
1435.01	56.1373
1436.08	55.1093
1437.15	55.0893
1438.22	56.096
1439.29	59.1858
1440.36	55.1256
1441.43	52.0613
1442.49	52.0526
1443.56	57.1735
1444.63	56.1336
1445.7	54.123
1446.77	48.9741
1447.83	40.7506
1448.9	51.0161
1449.97	53.0561
1451.03	53.0275
1452.1	54.0304
1453.17	49.9267
1454.23	49.9318
1455.3	47.8758
1456.36	48.909
1457.43	49.9106
1458.49	46.8262
1459.56	40.6839
1460.62	46.8216
1461.69	44.7497
1462.75	46.7622
1463.82	42.6276
1464.88	46.7663
1465.94	40.5019
1467.01	40.4858
1468.07	39.4557
1469.13	44.5471
1470.2	43.4957
1471.26	43.4701
1472.32	43.4434
1473.39	42.4148
1474.45	41.3733
1475.51	45.4486
1476.57	42.377
1477.63	45.4038
1478.69	41.3173
1479.76	46.3669
1480.82	38.1944
1481.88	41.2208
1482.94	43.2777
1484	43.2829
1485.06	41.1629
1486.12	41.1475
1487.18	40.1359
1488.24	43.1501
1489.3	38.052
1490.36	40.0617
1491.42	40.0369
1492.48	44.0739
1493.53	44.0654
1494.59	40.0173
1495.65	42.0186
1496.71	40.9647
1497.77	40.95
1498.82	35.8986
1499.88	38.9322
1500.94	40.9512
1502	37.9042
1503.05	39.9041
1504.11	42.9056
1505.17	44.9237
1506.22	42.8649
1507.28	39.8427
1508.34	41.855
1509.39	38.8296
1510.45	40.8482
1511.5	38.7941
1512.56	40.7244
1513.61	43.6874
1514.67	41.7033
1515.72	38.6525
1516.78	37.6107
1517.83	41.6121
1518.88	39.6189
1519.94	42.6367
1520.99	37.6122
1522.05	40.6262
1523.1	40.6055
1524.15	38.5521
1525.2	43.5392
1526.26	36.5416
1527.31	38.5628
1528.36	38.5449
1529.41	40.5307
1530.47	40.5156
1531.52	42.5434
1532.57	40.5299
1533.62	42.5761
1534.67	36.5612
1535.72	39.5486
1536.77	36.4864
1537.82	36.4434
1538.87	40.4161
1539.92	38.4715
1540.97	38.5325
1542.02	37.5026
1543.07	44.47
1544.12	32.4152
1545.17	36.435
1546.22	36.4676
1547.27	40.4797
1548.32	42.458
1549.37	30.4208
1550.42	37.4361
1551.46	41.5602
1552.51	37.5421
1553.56	38.514
1554.61	38.482
1555.65	43.4527
1556.7	44.4473
1557.75	38.4402
1558.79	33.4004
1559.84	35.3582
1560.89	42.3324
1561.93	42.337
1562.98	35.3559
1564.02	35.3457
1565.07	40.3747
1566.11	36.1457
1567.16	36.2959
1568.2	35.3215
1569.25	35.3267
1570.29	36.3048
1571.34	33.3023
1572.38	36.28
1573.43	35.2557
1574.47	39.2414
1575.51	36.2792
1576.56	35.2817
1577.6	33.2396
1578.64	39.179
1579.69	40.1697
1580.73	37.1867
1581.77	39.1598
1582.81	40.1302
1583.85	38.1268
1584.9	36.1331
1585.94	39.1159
1586.98	42.0681
1588.02	37.0739
1589.06	37.0837
1590.1	34.1077
1591.14	36.1062
1592.18	36.095
1593.22	36.0572
1594.26	35.0073
1595.3	34.0169
1596.34	42.9404
1597.38	35.9886
1598.42	37.9738
1599.46	36.9436
1600.5	40.882
1601.54	41.824
1602.58	36.8289
1603.62	45.6932
1604.66	37.7696
1605.69	42.7141
1606.73	38.7735
1607.77	39.693
1608.81	42.4317
1609.84	39.2696
1610.88	40.4685
1611.92	40.2273
1612.95	36.8586
1613.99	37.5105
1615.03	40.1434
1616.06	36.4094
1617.1	40.6197
1618.13	34.4623
1619.17	40.6556
1620.2	37.3888
1621.24	39.3148
1622.27	39.687
1623.31	37.959
1624.34	35.981
1625.38	38.2311
1626.41	38.9891
1627.45	39.4905
1628.48	38.843
1629.51	40.6564
1630.55	37.9443
1631.53	35.126
1632.57	36.1238
1633.62	40.0586
1634.66	37.1075
1635.71	37.1007
1636.75	33.1406
1637.8	40.9953
1638.84	41.9637
1639.89	40.9757
1640.93	38.0253
1641.98	40.9752
1643.02	39.9787
1644.06	38.0001
1645.11	40.9316
1646.15	40.9402
1647.19	36.0022
1648.24	39.9206
1649.28	38.9686
1650.32	44.8696
1651.37	38.0102
1652.41	38.9992
1653.45	42.9275
1654.49	41.9477
1655.53	44.9201
1656.57	41.0153
1657.62	43.9736
1658.66	43.9545
1659.7	38.0088
1660.74	36.0273
1661.78	38.023
1662.82	39.05
1663.86	38.0631
1664.9	38.0342
1665.94	40.9395
1666.98	38.0258
1668.02	37.0148
1669.06	39.9797
1670.1	40.9929
1671.14	41.0197
1672.18	38.0436
1673.21	38.0441
1674.25	37.0608
1675.29	39.0571
1676.33	42.0316
1677.37	37.0834
1678.4	38.0512
1679.44	37.034
1680.48	38.9935
1681.52	40.9523
1682.55	42.9236
1683.59	36.99
1684.63	35.9895
1685.66	37.9539
1686.7	37.9541
1687.73	41.9111
1688.77	33.0025
1689.81	40.8694
1690.84	34.9365
1691.88	41.8536
1692.91	39.8717
1693.95	31.9426
1694.98	38.8103
1696.01	40.7828
1697.05	37.8343
1698.08	36.8157
1699.12	36.7869
1700.15	37.7657
1701.18	40.7035
1702.22	33.7963
1703.25	35.737
1704.28	40.6363
1705.32	39.6581
1706.35	39.6455
1707.38	36.66
1708.41	38.5763
1709.44	42.4419
1710.48	39.4919
1711.51	39.5019
1712.54	40.48
1713.57	42.3709
1714.6	40.3692
1715.63	39.3884
1716.66	42.3144
1717.69	43.2328
1718.72	33.4183
1719.75	42.1645
1720.78	39.238
1721.81	41.1459
1722.84	35.2709
1723.87	40.0964
1724.9	42.0216
1725.93	38.082
1726.96	41.9403
1727.99	39.9867
1729.02	39.9039
1730.05	42.7574
1731.07	44.659
1732.1	37.9428
1733.13	39.8553
1734.16	41.7282
1735.18	44.5625
1736.21	43.5534
1737.24	39.6807
1738.26	41.577
1739.29	37.6941
1740.32	41.4696
1741.34	42.376
1742.37	39.4703
1743.4	36.5828
1744.42	42.3008
1745.45	41.3318
1746.47	48.0054
1747.5	37.4437
1748.52	39.3265
1749.55	34.558
1750.57	43.1825
1751.6	41.2855
1752.62	41.2427
1753.64	42.1582
1754.67	42.1219
1755.69	45.9078
1756.71	43.9587
1757.74	43.9087
1758.76	42.9678
1759.78	41.0652
1760.81	43.9044
1761.83	41.9705
1762.85	43.8652
1763.87	40.0636
1764.89	43.8964
1765.92	40.1046
1766.94	49.6176
1767.96	45.7922
1768.98	41.9639
1770	43.7829
1771.02	46.6529
1772.04	47.6389
1773.06	41.0029
1774.08	47.6805
1775.1	36.2659
1776.12	43.9229
1777.14	46.7786
1778.16	49.603
1779.18	44.7988
1780.2	49.5457
1781.22	41.9431
1782.24	44.8087
1783.26	48.6469
1784.28	49.6222
1785.29	40.1113
1786.31	35.3278
1787.33	42.976
1788.35	44.9667
1789.37	44.0719
1790.38	45.0663
1791.4	41.2233
1792.42	40.2298
1793.43	41.1968
1794.45	41.202
1795.47	38.3579
1796.48	39.3577
1797.5	38.424
1798.51	35.5552
1799.53	38.4325
1800.55	43.2068
1801.56	40.3088
1802.58	41.2741
1803.59	41.3001
1804.61	38.4297
1805.62	34.6079
1806.64	38.486
1807.65	38.4928
1808.66	36.5637
1809.68	36.5653
1810.69	37.5307
1811.7	35.5939
1812.72	34.6315
1813.73	35.6108
1814.74	40.4681
1815.76	36.6299
1816.77	37.6011
1817.78	42.4054
1818.79	39.51
1819.8	38.5517
1820.82	41.4671
1821.83	39.5493
1822.84	39.5625
1823.85	42.4629
1824.86	42.4611
1825.87	41.5048
1826.88	36.6613
1827.89	40.5437
1828.9	39.5699
1829.91	38.5854
1830.92	39.5346
1831.93	37.6094
1832.94	37.6282
1833.95	38.6044
1834.96	42.4499
1835.97	40.447
1836.98	38.6505
1837.99	37.5573
1839	41.4217
1840	38.5678
1841.01	36.5541
1842.02	38.4145
1843.03	35.4838
1844.04	38.3739
1845.04	40.3007
1846.05	38.379
1847.06	36.481
1848.07	38.2774
1849.07	39.2438
1850.08	36.3237
1851.09	38.1972
1852.09	38.1684
1853.1	37.2022
1854.1	37.1835
1855.11	35.2231
1856.11	38.0593
1857.12	40.9233
1858.12	40.9042
1859.13	36.0835
1860.13	36.0543
1861.14	39.8918
1862.14	39.91
1863.15	36.0546
1864.15	39.8412
1865.15	38.8528
1866.16	38.7995
1867.16	36.8263
1868.16	37.7269
1869.17	34.8667
1870.17	34.8565
1871.17	39.5988
1872.17	33.8799
1873.18	32.9059
1874.18	33.8378
1875.18	35.6993
1876.18	40.3773
1877.18	38.4389
1878.18	35.5463
1879.19	34.6555
1880.19	37.52
1881.19	32.7781
1882.19	35.5623
1883.19	32.6535
1884.19	31.6722
1885.19	33.5704
1886.19	37.3861
1887.19	37.3774
1888.19	32.6222
1889.19	37.2835
1890.19	41.9652
1891.19	37.2782
1892.18	37.2664
1893.18	35.3634
1894.18	38.125
1895.18	36.2248
1896.18	38.1124
1897.18	36.2531
1898.17	35.3185
1899.17	36.2342
1900.17	39.9636
1901.16	34.3219
1902.16	41.8667
1903.16	40.9384
1904.16	35.2777
1905.15	39.0284
1906.15	35.2503
1907.14	34.2826
1908.14	40.8579
1909.14	38.0531
1910.13	37.1439
1911.13	37.1857
1912.12	39.0769
1913.12	33.4158
1914.11	41.909
1915.11	40.0601
1916.1	39.128
1917.1	33.446
1918.09	37.1968
1919.08	34.3877
1920.08	34.4322
1921.07	41.0493
1922.06	36.351
1923.06	37.2877
1924.05	39.1589
1925.04	38.1915
1926.04	39.1598
1927.03	42.9866
1928.02	40.1689
1929.01	34.4974
1930	33.574
1931	44.9989
1931.99	37.3966
1932.98	37.3715
1933.97	44.0169
1934.96	37.4793
1935.95	34.6968
1936.94	35.6127
1937.93	35.5779
1938.92	36.5246
1939.91	36.5419
1940.9	35.6106
1941.89	39.4565
1942.88	39.4701
1943.87	33.7191
1944.86	36.604
1945.85	37.5919
1946.84	33.7883
1947.83	41.4295
1948.82	38.5525
1949.8	39.5307
1950.79	37.6665
1951.78	33.8829
1952.77	33.9072
1953.76	36.7893
1954.74	35.749
1955.73	35.7267
1956.72	42.5022
1957.7	36.7753
1958.69	37.7518
1959.68	36.7751
1960.66	40.5944
1961.65	40.5626
1962.63	34.8015
1963.62	38.6434
1964.61	33.8509
1965.59	38.6443
1966.58	41.5439
1967.56	41.5604
1968.55	35.7962
1969.53	39.6167
1970.52	43.4085
1971.5	39.5423
1972.48	38.5792
1973.47	38.5673
1974.45	39.4978
1975.44	40.4563
1976.42	43.3513
1977.4	39.5143
1978.39	44.2846
1979.37	42.3502
1980.35	44.2678
1981.33	44.2406
1982.31	45.1788
1983.3	39.4048
1984.28	43.2002
1985.26	47.9574
1986.24	47.9384
1987.22	47.9519
1988.21	51.7355
1989.19	49.6648
1990.17	48.4586
1991.15	46.1403
1992.13	48.9327
1993.11	49.7253
1994.09	54.0348
1995.07	52.7202
1996.05	50.9555
1997.03	49.9214
1998.01	52.3079
1998.99	54.8597
1999.97	54.4213
2000.95	55.3529
2001.92	54.217
2002.9	53.0028
2003.88	54.7284
2004.86	56.3442
2005.84	56.7714
2006.81	54.8742
2007.79	57.0629
2008.77	56.6523
2009.75	52.3716
2010.73	51.7715
2011.7	49.3722
2012.68	50.1362
2013.67	50.0782
2014.66	55.6294
2015.64	48.0958
2016.63	51.8717
2017.62	54.7241
2018.61	59.3414
2019.6	52.692
2020.58	47.0481
2021.57	49.858
2022.56	47.0336
2023.55	48.8595
2024.54	50.6858
2025.52	45.0164
2026.51	47.7761
2027.5	45.0948
2028.48	50.6459
2029.47	48.8537
2030.45	52.4346
2031.44	46.8577
2032.43	46.8645
2033.41	42.2504
2034.4	50.6667
2035.38	44.0547
2036.37	45.0835
2037.35	45.0688
2038.34	44.1199
2039.32	44.0911
2040.31	41.2519
2041.29	44.0073
2042.27	43.9858
2043.26	43.0344
2044.24	41.2179
2045.23	43.0568
2046.21	45.0129
2047.19	42.1697
2048.17	40.2504
2049.16	43.0568
2050.14	44.0375
2051.12	43.1356
2052.11	42.1759
2053.09	43.1228
2054.07	39.4283
2055.05	42.2464
2056.03	39.4199
2057.01	39.406
2058	38.4793
2058.98	38.508
2059.96	36.6529
2060.94	42.2533
2061.92	41.3332
2062.9	38.5322
2063.88	39.4921
2064.86	38.5689
2065.84	37.6663
2066.82	40.5056
2067.8	39.5828
2068.78	35.8404
2069.76	35.8295
2070.73	35.8248
2071.71	36.7871
2072.69	34.9544
2073.67	38.7128
2074.65	35.8959
2075.63	37.8252
2076.6	37.8656
2077.58	36.9018
2078.56	35.005
2079.54	37.8549
2080.51	36.002
2081.49	38.8341
2082.47	36.9431
2083.45	36.0018
2084.42	34.1081
2085.4	35.0533
2086.37	32.2274
2087.35	35.0892
2088.32	35.0979
2089.3	36.9958
2090.28	35.1254
2091.25	36.0831
2092.23	33.2645
2093.2	39.0024
2094.18	33.3355
2095.15	32.39
2096.13	35.2208
2097.1	38.0598
2098.07	36.1362
2099.05	34.2276
2100.02	35.1701
2101	33.2772
2101.97	37.0959
2102.94	39.9409
2103.92	34.2236
2104.89	37.0775
2105.86	35.2014
2106.83	35.2161
2107.8	33.3154
2108.78	32.331
2109.75	36.1287
2110.72	34.2351
2111.69	35.1809
2112.66	38.9673
2113.63	33.2868
2114.61	34.2408
2115.58	38.0406
2116.55	34.2223
2117.52	31.3591
2118.49	37.0409
2119.46	33.2093
2120.43	32.2355
2121.4	34.1372
2122.37	34.1664
2123.34	31.3372
2124.31	34.1812
2125.28	34.1352
2126.25	35.9798
2127.21	35.0001
2128.18	29.3117
2129.15	34.977
2130.12	33.0772
2131.09	31.1767
2132.06	31.1574
2133.02	32.081
2133.99	38.6843
2134.96	35.8538
2135.93	34.9012
2136.89	36.7527
2137.86	36.759
2138.83	38.6295
2139.79	37.6944
2140.76	34.8354
2141.73	33.8832
2142.69	37.6295
2143.66	36.7149
2144.62	34.7606
2145.59	28.1792
2146.55	35.693
2147.52	36.6167
2148.48	30.9621
2149.45	33.7577
2150.42	34.6545
2151.38	30.8951
2152.34	36.5358
2153.31	29.9593
2154.27	37.4388
2155.24	31.7699
2156.2	34.5297
2157.16	34.5154
2158.13	33.5932
2159.09	34.5313
2160.05	35.4438
2161.01	31.6766
2161.98	35.3956
2162.94	33.5262
2163.9	35.375
2164.86	34.4165
2165.83	34.4146
2166.79	30.6794
2167.75	33.4482
2168.71	36.1892
2169.67	32.4809
2170.63	36.2444
2171.59	30.6473
2172.56	32.4535
2173.51	29.6531
2174.48	31.5185
2175.44	33.3766
2176.4	31.5094
2177.36	35.2139
2178.32	30.5695
2179.28	33.3351
2180.23	29.6217
2181.19	33.3286
2182.15	37.0285
2183.11	34.2299
2184.07	33.2698
2185.03	36.9639
2185.99	32.3416
2186.95	35.1494
2187.9	34.258
2188.86	30.5286
2189.82	33.2769
2190.78	33.2611
2191.73	31.4127
2192.69	31.422
2193.65	34.2236
2194.6	33.3428
2195.56	32.4087
2196.52	31.4462
2197.47	31.4155
2198.43	36.0521
2199.38	36.0917
2200.34	38.9325
2201.3	34.3393
2202.25	35.1529
2203.21	33.3516
2204.16	34.404
2205.12	37.1358
2206.07	34.2565
2207.03	35.1818
2207.98	30.5506
2208.93	34.2981
2209.89	32.4451
2210.84	36.1792
2211.8	34.3369
2212.75	31.5596
2213.7	30.6125
2214.66	34.3579
2215.61	32.5118
2216.56	33.4462
2217.51	26.9061
2218.47	31.5749
2219.42	30.6541
2220.37	33.4727
2221.32	31.5957
2222.27	33.4327
2223.23	33.4336
2224.18	30.6573
2225.13	28.8177
2226.08	32.5903
2227.03	32.6151
2227.98	30.7561
2228.93	32.6225
2229.88	31.6857
2230.83	30.7738
2231.78	30.8001
2232.73	31.7634
2233.68	31.7857
2234.63	32.7381
2235.58	34.5941
2236.53	32.7073
2237.48	33.6598
2238.43	26.1681
2239.38	33.7454
2240.33	32.7867
2241.27	32.8002
2242.22	27.1458
2243.17	30.9301
2244.12	34.6915
2245.07	31.8736
2246.01	36.6376
2246.96	32.8778
2247.91	34.7845
2248.85	33.8306
2249.8	32.8839
2250.75	29.0913
2251.69	32.8496
2252.64	32.8567
2253.59	31.956
2254.53	31.9841
2255.48	34.8309
2256.42	31.9936
2257.37	31.0657
2258.32	31.0797
2259.26	32.9894
2260.2	33.9536
2261.15	31.1154
2262.1	30.1827
2263.04	28.2933
2263.98	31.1842
2264.93	31.2273
2265.87	33.1573
2266.81	34.0947
2267.76	27.3887
2268.7	31.1848
2269.65	33.1122
2270.59	36.9741
2271.53	30.3073
2272.47	33.1932
2273.42	32.2414
2274.36	30.3332
2275.3	29.3817
2276.24	26.5148
2277.18	31.3303
2278.13	31.3708
2279.07	34.2721
2280.01	32.3264
2280.95	28.4579
2281.89	27.485
2282.83	25.5804
2283.77	34.2495
2284.71	33.3428
2285.65	33.3637
2286.59	28.5337
2287.54	30.4898
2288.47	33.393
2289.41	35.2909
2290.35	32.3605
2291.29	33.3233
2292.23	28.5432
2293.17	38.1992
2294.11	33.3981
2295.05	32.4157
2295.99	33.3591
2296.93	26.5962
2297.86	32.3883
2298.8	37.2378
2299.74	31.4815
2300.68	32.4471
2301.61	29.5678
2302.55	27.6354
2303.49	27.6308
2304.43	31.4986
2305.36	36.3467
2306.3	34.4266
2307.24	30.5654
2308.17	35.3856
2309.11	30.549
2310.04	33.4763
2310.98	32.5184
2311.92	32.4665
2312.85	32.435
2313.79	29.5469
2314.72	35.3834
2315.66	33.4701
2316.59	33.4263
2317.52	31.4806
2318.46	37.2794
2319.39	35.3244
2320.33	34.3467
2321.26	32.4244
2322.2	34.3833
2323.13	36.3373
2324.06	43.114
2325	44.0665
2325.93	56.57
2326.86	107.658
2327.79	301.347
2328.73	192.365
2329.66	76.652
2330.59	52.5653
2331.52	38.1106
2332.46	35.2301
2333.39	33.2814
2334.32	35.1889
2335.25	34.2017
2336.18	31.3158
2337.11	30.3451
2338.04	30.3371
2338.97	36.0967
2339.91	32.2516
2340.84	36.0752
2341.77	30.273
2342.7	35.0413
2343.63	28.3233
2344.56	35.0321
2345.49	35.0249
2346.41	34.0378
2347.34	33.0698
2348.27	33.068
2349.2	34.0276
2350.13	33.018
2351.06	30.9558
2351.99	38.7228
2352.91	30.0765
2353.84	32.889
2354.77	31.936
2355.7	33.8419
2356.63	34.7685
2357.55	31.8713
2358.48	32.8023
2359.41	25.1858
2360.33	34.6641
2361.26	33.6817
2362.19	30.8033
2363.11	33.6116
2364.04	32.6449
2364.97	30.7337