File: Data/3-Raman/raw/bu19w-ff-ore1-fi07-v_150 (500nm)_532nm_edge_100%_x100_vis_h50um_15sx2_01.txt
#Acq. time (s)=	15
#Accumulations=	2
#Range (cm-¹)=	100...5000
#Windows=	1
#Auto scanning=	Off
#Autofocus=	Off
#Macrospot=	Off
#AutoExposure=	Off
#Spike filter=	Multiple accum.
#Delay time (s)=	2
#Binning=	1
#Readout mode=	Signal
#DeNoise=	Off
#ICS correction=	On
#Dark correction=	Off
#Inst. Process=	Off
#Detector Gain=	Best Dynamic
#Detector ADC=	50 kHz HS
#Detector temperature (°C)=	-60.09
#Instrument=	LabRAM HR Evol
#Detector=	SIN-EM FIVIS
#Objective=	x100_VIS
#Grating=	150 (500nm)
#ND Filter=	100%
#Laser=	532nm_Edge
#Hole=	49.98
#Temperature=	0
#Range=	Visible
#StageXY=	75x50mm Scan+
#StageZ=	Z motor
#X (µm)=	0
#Y (µm)=	0
#Z (µm)=	-3.7
#Full time(s)=	34
#Project=	21_05_14
#Sample=	BU19w
#Site=
#Title=	BU19w-FF-ore1-FI07-V_150 (500nm)_532nm_Edge_100%_x100_VIS_H50um_15sX2
#Remark=
#Date=	14.05.2021 18:53
#Acquired=	14.05.2021 18:53:58
102.699	1592.26
107.322	1463.75
111.942	1357.87
116.56	1291.87
121.173	1228.29
125.787	1179.02
130.398	1348.79
135.006	1276.72
139.613	1105.46
144.215	1147.22
148.817	1468.71
153.417	3301.98
158.014	3781.16
162.607	2044.67
167.2	1403.39
171.79	1418.8
176.379	2479.21
180.963	6332.35
185.547	6285.58
190.128	2648.93
194.705	1278.91
199.282	1040.41
203.857	966.928
208.43	1053.7
212.998	955.797
217.566	917.835
222.132	927.548
226.693	1082.52
231.254	1132.07
235.813	1158.41
240.368	1317.38
244.923	1261.47
249.475	1117.73
254.023	1071.67
258.571	1125.36
263.117	1465.74
267.658	2577.4
272.199	4849.15
276.738	4892.79
281.273	2827.08
285.807	1814.78
290.34	1863.14
294.868	3099.85
299.396	4003.62
303.919	2741.55
308.443	1668.89
312.964	1326.98
317.481	1388.66
321.998	1773.48
326.51	1769.07
331.023	1359.84
335.533	1159.91
340.039	1225.21
344.544	1340.36
349.046	1188.36
353.547	977.392
358.045	951.214
362.542	1066.01
367.036	1200.7
371.527	1092.15
376.017	1297.35
380.503	1752.8
384.99	1885.51
389.471	1983.61
393.953	1981.23
398.43	1730.53
402.908	1426.24
407.381	1499.26
411.854	1786.01
416.323	1465.89
420.791	1031.01
425.256	862.086
429.72	867.051
434.18	849.747
438.64	922.013
443.095	1296.99
447.551	2363.3
452.003	3107.27
456.454	2055.31
460.901	1308.54
465.348	1027.47
469.791	940.129
474.231	936.247
478.672	987.17
483.108	1105.64
487.544	1236.35
491.976	1317.36
496.408	1287.2
500.836	1181.62
505.261	1139.77
509.687	1026.05
514.108	1001.52
518.529	1049.84
522.946	1069.83
527.361	1160.42
531.776	1261.89
536.187	1328.85
540.595	1361.12
545.003	1396.85
549.408	1356.09
553.812	1371.58
558.212	1396.73
562.61	1288.72
567.007	1037.67
571.401	975.722
575.792	1046.44
580.184	1467.57
584.571	2206.27
588.956	1925.11
593.341	1361.76
597.722	1185.06
602.101	1402.38
606.48	1502.38
610.854	1261.78
615.227	982.601
619.597	886.208
623.967	823.508
628.334	898.808
632.698	1047.14
637.06	1138.96
641.422	1042.22
645.779	896.878
650.135	840.443
654.491	859.295
658.842	884.381
663.192	929.878
667.539	1012.31
671.884	1137.93
676.23	1205.33
680.571	1071.39
684.91	885.572
689.247	833.894
693.583	784.687
697.916	759.922
702.247	761.076
706.576	771.565
710.902	739.984
715.229	769.606
719.551	735.305
723.872	733.21
728.19	775.494
732.506	767.545
736.82	795.966
741.134	827.015
745.444	863.474
749.752	928.04
754.058	1104.59
758.362	1190.14
762.664	1552.21
766.964	2191.12
771.264	3191.55
775.559	3595.44
779.853	2806.45
784.144	1897.92
788.434	1383.85
792.722	1134.65
797.007	1004.22
801.29	944.164
805.572	884.633
809.851	850.558
814.13	821.078
818.406	782.725
822.679	817.208
826.95	802.279
831.219	787.377
835.486	751.457
839.752	770.597
844.015	778.556
848.276	760.569
852.535	754.662
856.792	781.822
861.047	743.895
865.3	750.873
869.551	743.388
873.8	744.49
878.047	748.745
882.292	741.759
886.534	723.566
890.775	743.933
895.014	742.098
899.251	765.488
903.486	753.614
907.719	756.487
911.95	766.398
916.179	751.268
920.406	762.095
924.63	790.109
928.853	791.25
933.074	805.37
937.293	829.89
941.51	845.676
945.723	881.534
949.936	887.69
954.147	952.494
958.356	1033.21
962.563	1113.87
966.768	1131.82
970.971	988.847
975.172	933.052
979.371	892.387
983.568	845.46
987.761	833.348
991.954	837.659
996.145	838.418
1000.33	852.141
1004.52	859.626
1008.71	868.391
1012.89	882.184
1017.07	932.237
1021.25	937.539
1025.43	983.963
1029.6	1079.6
1033.77	1210.46
1037.95	1491.26
1042.11	2091.97
1046.28	3299.08
1050.45	3785.99
1054.61	2924.2
1058.77	2057.37
1062.93	1546
1067.09	1322.02
1071.24	1314.59
1075.4	1432.65
1079.55	1746.69
1083.7	2238.83
1087.85	2509.23
1091.99	2332.89
1096.14	2247.03
1100.28	2694.54
1104.42	3523.39
1108.55	3522.05
1112.69	3020.86
1116.82	2607.33
1120.96	2523.66
1125.09	2687.5
1129.21	2694.9
1133.34	2288.58
1137.46	1821.66
1141.59	1518.48
1145.71	1464.35
1149.83	1602.07
1153.94	1733.9
1158.06	1634.43
1162.17	1361.87
1166.28	1185.12
1170.39	1079.2
1174.5	1008.19
1178.6	979.451
1182.7	994.953
1186.8	1035.33
1190.9	1055.78
1195	1090.12
1199.1	1058.66
1203.19	987.583
1207.28	954.415
1211.37	955.875
1215.46	993.648
1219.54	1121.94
1223.63	1101.21
1227.71	1138.12
1231.79	1303.3
1235.87	1529.77
1239.95	1422.77
1244.02	1272.2
1248.09	1169.53
1252.16	1017.17
1256.23	937.804
1260.3	917.472
1264.36	1151.47
1268.43	2763.9
1272.49	1579.38
1276.55	959.514
1280.6	889.136
1284.66	855.592
1288.71	870.294
1292.76	828.407
1296.81	833.802
1300.86	835.021
1304.91	851.21
1308.95	837.194
1312.99	830.951
1317.03	860.69
1321.07	864.119
1325.11	842.933
1329.14	859.129
1333.18	846.855
1337.21	858.46
1341.24	844.938
1345.26	856.343
1349.29	880.67
1353.31	899.967
1357.33	880.503
1361.35	893.765
1365.37	943.836
1369.39	2116.58
1373.4	3639.09
1377.41	1294.22
1381.43	918.19
1385.43	885.455
1389.44	886.293
1393.45	1089.34
1397.45	906.651
1401.45	823.137
1405.45	839.217
1409.45	814.957
1413.44	835.123
1417.44	794.088
1421.43	799.38
1425.42	807.365
1429.41	797.306
1433.39	817.084
1437.38	790.327
1441.36	787.294
1445.34	753.501
1449.32	772.981
1453.3	772.558
1457.27	769.118
1461.24	774.316
1465.22	755.735
1469.19	774.606
1473.15	793.463
1477.12	744.471
1481.09	789.538
1485.05	763.058
1489.01	761.056
1492.97	771.802
1496.93	741.64
1500.88	750.592
1504.83	767.474
1508.79	789.348
1512.74	758.768
1516.68	792.351
1520.63	774.565
1524.57	783.02
1528.52	786.709
1532.46	786.587
1536.4	780.652
1540.33	797.03
1544.27	784.331
1548.2	800.705
1552.14	786.997
1556.07	811.899
1559.99	778.607
1563.92	811.046
1567.84	782.476
1571.77	774.197
1575.69	806.456
1579.61	778.833
1583.52	768.565
1587.44	809.297
1591.35	802.813
1595.27	751.156
1599.18	777.414
1603.09	783.579
1606.99	808.997
1610.9	773.057
1614.8	776.533
1618.7	787.701
1622.6	789.297
1626.5	793.919
1630.39	807.32
1634.29	781.614
1638.18	788.478
1642.07	768.774
1645.96	810.486
1649.85	783.241
1653.73	777.056
1657.62	776.562
1661.5	794.243
1665.38	835.827
1669.26	778.244
1673.13	813.734
1677.01	792.298
1680.88	767.63
1684.75	792.81
1688.62	795.784
1692.49	812.951
1696.35	818.49
1700.22	798.086
1704.08	798.531
1707.94	785.5
1711.8	811.333
1715.66	799.246
1719.51	795.732
1723.37	783.721
1727.22	825.254
1731.07	799.012
1734.92	784.126
1738.76	792.539
1742.61	806.488
1746.45	789.063
1750.29	796.265
1754.13	794.518
1757.97	777.959
1761.81	810.955
1765.64	782.361
1769.47	805.35
1773.31	771.788
1777.14	794.169
1780.96	786.049
1784.79	795.744
1788.61	773.705
1792.43	793.809
1796.25	792.363
1800.07	802.833
1803.89	787.595
1807.71	807.169
1811.52	804.947
1815.33	787.361
1819.14	791.183
1822.95	790.13
1826.76	802.095
1830.56	812.884
1834.37	789.59
1838.17	834.89
1841.97	784.081
1845.77	787.798
1849.56	800.729
1853.36	802.072
1857.15	814.396
1860.94	824.633
1864.73	779.096
1868.52	801.534
1872.31	777.745
1876.09	822.501
1879.87	788.939
1883.66	780.52
1887.43	791.038
1891.21	789.119
1894.99	815.667
1898.76	818.506
1902.53	803.198
1906.31	779.684
1910.08	817.177
1913.84	800.468
1917.61	808.979
1921.37	801.144
1925.14	779.456
1928.9	820.977
1932.66	797.501
1936.41	800.022
1940.17	825.898
1943.92	793.027
1947.68	814.69
1951.43	794.778
1955.18	802.646
1958.92	774.414
1962.67	820.309
1966.41	821.027
1970.16	803.496
1973.9	828.953
1977.64	798.956
1981.37	824.073
1985.11	792.029
1988.84	810.348
1992.57	780.959
1996.31	797.05
2000.03	799.995
2003.76	814.14
2007.49	838.069
2011.21	836.079
2014.93	792.989
2018.65	819.37
2022.37	826.811
2026.09	826.45
2029.81	814.949
2033.52	828.952
2037.23	831.74
2040.94	817.18
2044.65	800.666
2048.36	802.64
2052.07	820.292
2055.77	805.109
2059.47	787.804
2063.17	801.047
2066.87	800.615
2070.57	800.206
2074.27	799.814
2077.96	774.509
2081.65	801.956
2085.34	796.493
2089.03	820.621
2092.72	808.94
2096.41	825.306
2100.09	813.363
2103.77	819.888
2107.46	818.825
2111.14	824.196
2114.81	840.693
2118.49	827.194
2122.16	814.32
2125.84	829.22
2129.51	796.712
2133.18	816.048
2136.85	813.982
2140.51	815.456
2144.18	811.322
2147.84	818.205
2151.5	797.556
2155.16	826.47
2158.82	825.171
2162.48	835.891
2166.13	805.676
2169.79	816.759
2173.44	792.649
2177.09	817.771
2180.74	816.563
2184.38	805.359
2188.03	828.194
2191.67	828.584
2195.32	824.725
2198.96	832.786
2202.6	821.821
2206.23	797.264
2209.87	840.481
2213.5	832.581
2217.14	815.494
2220.77	802.982
2224.4	847.521
2228.03	826.668
2231.65	818.765
2235.28	824.733
2238.9	819.553
2242.52	822.696
2246.14	797.024
2249.76	824.423
2253.38	800.702
2256.99	835.787
2260.6	809.14
2264.21	820.816
2267.82	790.452
2271.44	827.728
2275.04	833.686
2278.65	818.57
2282.25	786.97
2285.85	793.29
2289.45	790.02
2293.05	787.662
2296.65	781.565
2300.25	800.98
2303.84	808.851
2307.43	827.015
2311.02	912.375
2314.62	1153.96
2318.2	949.884
2321.79	815.68
2325.38	769.317
2328.96	809.996
2332.54	837.201
2336.12	806.785
2339.7	790.458
2343.28	801.328
2346.85	805.51
2350.43	826.477
2354	784.759
2357.57	811.175
2361.14	794.672
2364.71	815.387
2368.27	802.808
2371.84	793.139
2375.4	790.806
2378.96	801.486
2382.52	787.373
2386.08	796.378
2389.64	817.455
2393.19	802.925
2396.75	797.855
2400.3	806.891
2403.85	783.232
2407.4	771.624
2410.95	774.091
2414.49	794.154
2418.04	768.449
2421.58	760.311
2425.12	796.635
2428.66	787.971
2432.2	776.655
2435.74	783.054
2439.27	789.535
2442.81	785.827
2446.34	751.328
2449.87	780.573
2453.4	787.192
2456.93	759.242
2460.45	791.185
2463.98	777.618
2467.5	786.59
2471.02	785.023
2474.54	830.529
2478.06	778.231
2481.58	788.029
2485.09	784.192
2488.61	786.929
2492.12	797.26
2495.63	766.114
2499.14	764.192
2502.65	784.403
2506.15	786.717
2509.66	767.541
2513.16	785.767
2516.66	757.704
2520.16	799.767
2523.66	745.928
2527.16	784.984
2530.66	759.444
2534.15	767.382
2537.64	767.162
2541.13	795.871
2544.62	763.159
2548.11	748.031
2551.6	770.909
2555.08	758.163
2558.57	783.414
2562.05	747.716
2565.53	786.645
2569.01	758.749
2572.49	754.266
2575.96	779.032
2579.44	747.497
2582.91	763.987
2586.38	765.309
2589.85	768.134
2593.32	776.403
2596.79	770.612
2600.25	770.594
2603.72	784.603
2607.18	792.321
2610.64	779.045
2614.1	791.072
2617.56	773.996
2621.02	766.365
2624.47	769.079
2627.92	757.255
2631.38	762.561
2634.83	757.059
2638.28	786.873
2641.72	765.72
2645.17	791.397
2648.61	769.154
2652.06	757.257
2655.5	790.814
2658.94	755.891
2662.38	765.468
2665.82	748.586
2669.25	780.627
2672.69	789.157
2676.12	753.719
2679.55	767.203
2682.98	738.818
2686.41	739.875
2689.84	746.056
2693.26	743.63
2696.69	771.141
2700.11	736.414
2703.53	754.54
2706.95	747.217
2710.37	733.579
2713.79	746.138
2717.2	747.691
2720.62	748.432
2724.03	753.9
2727.44	753.853
2730.85	788.381
2734.26	752.718
2737.66	739.491
2741.07	754.266
2744.47	747.299
2747.87	747.852
2751.28	741.803
2754.67	763.822
2758.07	757.718
2761.47	749.498
2764.86	738.342
2768.26	754.352
2771.65	762.78
2775.04	739.044
2778.43	740.628
2781.82	728.023
2785.2	727.625
2788.59	761.063
2791.97	733.32
2795.35	726.342
2798.73	761.431
2802.11	731.777
2805.49	738.702
2808.87	753.995
2812.24	719.662
2815.62	755.398
2818.99	751.964
2822.36	730.94
2825.73	724.908
2829.1	743.187
2832.46	734.58
2835.83	736.342
2839.19	741.972
2842.55	732.847
2845.91	746.313
2849.27	744.286
2852.63	746.756
2855.99	724.072
2859.34	737.027
2862.69	752.848
2866.05	753.736
2869.4	726.391
2872.75	745.967
2876.09	743.914
2879.44	742.789
2882.78	722.743
2886.13	740.352
2889.47	741.989
2892.81	738.679
2896.15	722.025
2899.49	733.622
2902.82	717.673
2906.16	738.572
2909.49	745.195
2912.82	724.373
2916.16	725.177
2919.49	739.168
2922.81	738.948
2926.14	735.743
2929.46	725.894
2932.79	731.932
2936.11	719.098
2939.43	741.151
2942.75	707.621
2946.07	754.169
2949.39	744.21
2952.7	727.659
2956.02	737.539
2959.33	710.926
2962.64	716.211
2965.95	708.526
2969.26	744.275
2972.57	757.382
2975.87	743.583
2979.17	695.832
2982.48	711.926
2985.78	718.693
2989.08	717.973
2992.38	724.798
2995.68	726.982
2998.97	723.537
3002.27	708.763
3005.56	723.219
3008.85	710.42
3012.14	709.891
3015.43	722.538
3018.72	698.401
3022	703.486
3025.29	708.593
3028.57	713.702
3031.85	710.278
3035.14	708.704
3038.41	717.541
3041.69	715.98
3044.97	699.295
3048.24	735.618
3051.52	712.304
3054.79	717.399
3058.06	744.23
3061.33	710.168
3064.6	742.59
3067.87	716.075
3071.13	707.981
3074.4	715.44
3077.66	745.653
3080.92	729.815
3084.18	713.159
3087.44	727.001
3090.7	730.574
3093.95	710.597
3097.21	734.445
3100.46	708.861
3103.71	743.414
3106.96	719.03
3110.21	747.722
3113.46	734.514
3116.71	741.332
3119.95	727.205
3123.2	726.401
3126.44	714.141
3129.68	722.846
3132.92	742.981
3136.16	735.44
3139.4	754.573
3142.63	730.8
3145.87	743.295
3149.1	737.702
3152.33	746.391
3155.56	750.323
3158.79	753.286
3162.02	756.251
3165.25	734.352
3168.47	772.514
3171.69	756.246
3174.92	747.554
3178.14	756.961
3181.36	747.309
3184.58	759.528
3187.79	726.894
3191.01	780.997
3194.22	744.552
3197.43	776.682
3200.65	762.159
3203.86	794.313
3207.07	787.466
3210.27	792.088
3213.48	763.472
3216.69	791.951
3219.89	795.709
3223.09	787.174
3226.29	747.271
3229.49	779.733
3232.69	769.331
3235.89	794.27
3239.08	802.163
3242.28	785.345
3245.47	799.008
3248.66	790.823
3251.85	807.468
3255.04	810.775
3258.23	793.942
3261.42	781.759
3264.6	804.8
3267.79	813.425
3270.97	810.522
3274.15	819.081
3277.33	805.542
3280.51	830.973
3283.68	815.346
3286.86	797.755
3290.04	795.483
3293.21	833.222
3296.38	828.986
3299.55	825.92
3302.72	846.504
3305.89	851.746
3309.06	833.087
3312.22	859.019
3315.39	832.693
3318.55	828.183
3321.71	842.626
3324.87	867.462
3328.03	851.601
3331.19	859.44
3334.34	842.786
3337.5	868.698
3340.65	858.738
3343.81	855.553
3346.96	846.024
3350.11	867.614
3353.25	877.037
3356.4	861.054
3359.55	851.775
3362.69	866.097
3365.84	858.779
3368.98	840.16
3372.12	877.313
3375.26	875.83
3378.4	876.297
3381.53	968.405
3384.67	960.428
3387.8	998.83
3390.94	990.931
3394.07	1004.41
3397.2	1096.12
3400.33	1217.58
3403.46	1384.02
3406.58	1765.73
3409.71	2605.14
3412.83	4793.33
3415.96	10668.8
3419.08	14683.6
3422.2	9272.23
3425.32	4094.15
3428.44	2250.11
3431.55	1548.32
3434.67	1290.13
3437.78	1114.24
3440.89	1021.51
3444	1009.67
3447.12	937.75
3450.22	950.561
3453.33	894.774
3456.44	895.074
3459.54	879.175
3462.65	901.276
3465.75	849.211
3468.85	837.763
3471.95	883.427
3475.05	885.553
3478.15	868.805
3481.24	899.359
3484.34	950.703
3487.43	962.416
3490.53	1094.29
3493.62	1228.97
3496.71	1332.32
3499.79	1441.37
3502.88	1466.15
3505.97	1348.75
3509.05	1176.43
3512.14	1050.33
3515.22	941.263
3518.3	914.318
3521.38	850.568
3524.46	809.031
3527.54	809.435
3530.61	774.79
3533.69	784.088
3536.76	754.537
3539.83	754.784
3542.9	735.799
3545.97	722.19
3549.04	716.019
3552.11	720.101
3555.18	698.754
3558.24	699.236
3561.3	686.295
3564.37	700.767
3567.43	674.519
3570.49	687.966
3573.55	676.68
3576.61	680.539
3579.66	686.24
3582.72	646.351
3585.77	671.885
3588.82	688.815
3591.87	662.097
3594.92	655.244
3597.97	668.272
3601.02	667.036
3604.07	657.225
3607.11	614.302
3610.16	648.914
3613.2	634.33
3616.24	640.545
3619.28	622.252
3622.32	614.372
3625.36	620.676
3628.39	599.641
3631.43	626.603
3634.46	610.349
3637.5	589.506
3640.53	613.895
3643.56	606.446
3646.59	581.024
3649.62	589.552
3652.64	557.943
3655.67	581.643
3658.69	547.357
3661.72	576.993
3664.74	572.489
3667.76	584.033
3670.78	557.919
3673.79	576.164
3676.81	553.861
3679.83	571.202
3682.84	542.231
3685.86	554.865
3688.87	549.545
3691.88	537.605
3694.89	538.828
3697.9	564.773
3700.91	563.264
3703.91	544.659
3706.92	552.586
3709.92	544.313
3712.92	535.011
3715.92	532.38
3718.92	524.947
3721.92	541.262
3724.92	543.251
3727.92	533.771
3730.91	564.24
3733.91	530.845
3736.9	548.82
3739.89	555.301
3742.88	538.895
3745.87	543.37
3748.86	522.136
3751.85	528.448
3754.83	534.763
3757.82	542.961
3760.8	549.211
3763.78	534.611
3766.76	523.85
3769.74	512.204
3772.72	538.429
3775.7	510.797
3778.67	529.512
3781.65	497.229
3784.62	512.196
3787.6	532.845
3790.57	522.416
3793.54	520.538
3796.51	527.186
3799.47	517.85
3802.44	508.55
3805.41	511.541
3808.37	512.674
3811.33	510.044
3814.3	502.694
3817.26	511.445
3820.22	503.175
3823.18	518.612
3826.13	505.648
3829.09	507.834
3832.04	512.909
3835	494.286
3837.95	511.755
3840.9	514.028
3843.85	483.001
3846.8	501.472
3849.75	491.404
3852.69	497.554
3855.64	483.667
3858.58	507.042
3861.53	512.255
3864.47	505.986
3867.41	482.425
3870.35	512.503
3873.29	503.268
3876.22	499.731
3879.16	475.965
3882.1	506.893
3885.03	473.395
3887.96	498.502
3890.89	499.562
3893.82	493.835
3896.75	489.002
3899.68	489.928
3902.61	501.356
3905.53	499.372
3908.46	476.22
3911.38	494.351
3914.3	500.883
3917.23	475.815
3920.15	501.577
3923.06	488.871
3925.98	472.293
3928.9	485.394
3931.81	491.866
3934.73	489.816
3937.64	493.629
3940.55	507.945
3943.46	486.842
3946.37	462.914
3949.28	489.773
3952.19	471.647
3955.09	476.545
3958	469.016
3960.9	483.55
3963.8	489.491
3966.71	464.768
3969.61	463.074
3972.51	471.938
3975.4	478.864
3978.3	482.874
3981.2	461.884
3984.09	476.433
3986.99	476.562
3989.88	472.76
3992.77	471.925
3995.66	452.806
3998.55	476.056
4001.43	444.435
4004.32	462.911
4007.21	456.355
4010.09	471.962
4012.98	461.542
4015.86	493.573
4018.74	460.948
4021.62	475.618
4024.5	438.139
4027.37	467.321
4030.25	473.335
4033.13	457.105
4036	477.661
4038.87	453.699
4041.75	460.64
4044.62	448.197
4047.49	454.195
4050.35	467.009
4053.22	473.081
4056.09	456.84
4058.95	451.241
4061.82	467.987
4064.68	467.247
4067.54	467.473
4070.4	424.867
4073.26	451.354
4076.12	457.399
4078.98	436.156
4081.83	444.149
4084.69	453.113
4087.54	429.867
4090.4	452.507
4093.25	423.399
4096.1	468.516
4098.95	433.53
4101.8	442.5
4104.64	440.681
4107.49	453.512
4110.33	458.501
4113.18	431.134
4116.02	428.182
4118.86	438.904
4121.7	427.159
4124.54	416.423
4127.38	433.156
4130.22	426.498
4133.05	437.564
4135.89	437.618
4138.72	443.986
4141.56	434.873
4144.39	438.919
4147.22	443
4150.05	427.458
4152.88	422.538
4155.7	441.919
4158.53	432.917
4161.36	425.036
4164.18	421.071
4167	449.387
4169.82	413.181
4172.65	431.759
4175.46	454.251
4178.28	429.823
4181.1	422.046
4183.92	429.936
4186.73	439.805
4189.55	445.806
4192.36	446.979
4195.17	436.451
4197.98	458.28
4200.79	471.303
4203.6	439.199
4206.41	438.474
4209.21	446.59
4212.02	435.039
4214.83	420.669
4217.63	429.045
4220.43	433.428
4223.23	428.89
4226.03	426.336
4228.83	409.982
4231.63	422.337
4234.42	442.696
4237.22	422.418
4240.01	408.061
4242.81	418.57
4245.6	436.083
4248.39	404.697
4251.18	410.181
4253.97	423.656
4256.76	404.089
4259.55	428.605
4262.33	408.027
4265.12	407.522
4267.9	407.026
4270.68	403.492
4273.47	402.922
4276.25	413.381
4279.03	413.716
4281.8	394.805
4284.58	409.205
4287.36	398.267
4290.13	396.405
4292.91	417.868
4295.68	388.723
4298.45	395.03
4301.22	399.29
4303.99	402.54
4306.76	394.63
4309.53	369.465
4312.3	383.912
4315.06	408.491
4317.83	390.314
4320.59	404.672
4323.35	389.481
4326.11	390.581
4328.87	398.793
4331.63	387.643
4334.39	379.538
4337.15	372.472
4339.9	380.733
4342.66	385.957
4345.41	390.208
4348.17	392.436
4350.92	395.75
4353.67	388.874
4356.42	373.777
4359.17	375.025
4361.91	376.286
4364.66	390.866
4367.41	378.814
4370.15	391.347
4372.89	375.113
4375.63	385.541
4378.38	382.604
4381.12	370.43
4383.86	407.656
4386.59	378.186
4389.33	375.544
4392.07	367.929
4394.8	395.402
4397.53	388.624
4400.27	382.859
4403	371.885
4405.73	377.525
4408.46	389.395
4411.19	355.438
4413.92	374.514
4416.64	374.757
4419.37	358.284
4422.09	370.028
4424.82	359.858
4427.54	363.264
4430.26	354.115
4432.98	354.361
4435.7	370.302
4438.42	356.884
4441.13	367.562
4443.85	355.16
4446.57	363.729
4449.28	378.589
4451.99	351.418
4454.71	348.379
4457.42	358.978
4460.13	346.475
4462.83	372.9
4465.54	351.996
4468.25	354.257
4470.95	348.119
4473.66	367.301
4476.36	384.43
4479.07	362.556
4481.77	366.007
4484.47	369.444
4487.17	354.894
4489.87	346.616
4492.56	344.551
4495.26	360.581
4497.96	350.142
4500.65	345.99
4503.34	342.939
4506.04	348.385
4508.73	343.226
4511.42	340.19
4514.11	344.601
4516.8	353.263
4519.48	351.356
4522.17	342.007
4524.85	346.467
4527.54	342.427
4530.22	350.108
4532.9	335.422
4535.58	353.799
4538.27	336.997
4540.94	331.911
4543.62	335.394
4546.3	326.035
4548.98	331.672
4551.65	368.511
4554.33	328.118
4557	357.654
4559.67	333.473
4562.34	331.938
4565.01	343.573
4567.68	339.97
4570.35	332.692
4573.02	327.259
4575.68	340.483
4578.35	315.773
4581.01	322.806
4583.67	327.398
4586.34	326.536
4589	328.904
4591.66	322.521
4594.31	321.698
4596.97	326.248
4599.63	342.915
4602.29	325.707
4604.94	331.478
4607.59	319.725
4610.25	315.623
4612.9	314.799
4615.55	323.881
4618.2	333.011
4620.85	303.585
4623.5	312.682
4626.14	325.08
4628.79	327.565
4631.43	317.84
4634.08	324.657
4636.72	325.956
4639.36	302.866
4642	310.841
4644.64	314.479
4647.28	331.525
4649.92	300.884
4652.56	315.986
4655.19	311.477
4657.83	302.815
4660.46	293.095
4663.1	319.129
4665.73	313.749
4668.36	324.081
4670.99	318.735
4673.62	302.166
4676.24	312.496
4678.87	310.479
4681.5	318.57
4684.12	314.308
4686.75	321.286
4689.37	302.398
4691.99	309.368
4694.61	311.825
4697.23	293.981
4699.85	320.159
4702.47	307.911
4705.09	310.341
4707.7	313.889
4710.32	301.592
4712.93	293.808
4715.55	306.377
4718.16	291.772
4720.77	316.779
4723.38	308.972
4725.99	310.262
4728.6	296.8
4731.21	298.09
4733.81	303.924
4736.42	288.136
4739.02	311.002
4741.63	296.305
4744.23	297.535
4746.83	300.969
4749.43	311.244
4752.03	288.517
4754.63	302.193
4757.23	306.79
4759.82	301.176
4762.42	295.559
4765.01	283.154
4767.61	289.068
4770.2	288.048
4772.79	298.444
4775.38	282.596
4777.97	283.861
4780.56	290.842
4783.15	285.258
4785.74	286.532
4788.32	292.39
4790.91	278.811
4793.49	282.398
4796.07	294.049
4798.66	295.411
4801.24	270.388
4803.82	287.872
4806.4	304.285
4808.98	302.288
4811.55	281.865
4814.13	284.488
4816.71	276.755
4819.28	273.625
4821.85	292.504
4824.43	282.436
4827	292.065
4829.57	288.977
4832.14	268.409
4834.71	296.799
4837.28	272.746
4839.84	283.728
4842.41	278.28
4844.97	285.692
4847.54	275.465
4850.1	286.199
4852.66	256.803
4855.22	278.369
4857.78	265.814
4860.34	281.497
4862.9	275.833
4865.46	266.561
4868.01	272.788
4870.57	268.297
4873.12	275.6
4875.68	268.685
4878.23	271.242
4880.78	247.65
4883.33	273.939
4885.88	270.534
4888.43	281.415
4890.98	280.387
4893.53	271.014
4896.07	258.04
4898.62	270.096
4901.16	265.446
4903.7	271.549
4906.25	265.675
4908.79	271.716
4911.33	275.329
4913.87	261.003
4916.41	269.38
4918.94	258.658
4921.48	256.296
4924.02	259.921
4926.55	265.926
4929.08	265.982
4931.62	246.969
4934.15	256.653
4936.68	253.161
4939.21	273.54
4941.74	261.606
4944.27	264.116
4946.79	253.452
4949.32	261.969
4951.85	246.494
4954.37	255.02
4956.9	247.98
4959.42	263.784
4961.94	266.438
4964.46	261.935
4966.98	265.831
4969.5	250.383
4972.02	259.058
4974.53	260.488
4977.05	247.409
4979.57	257.322
4982.08	239.381
4984.59	239.612
4987.1	258.064
4989.62	244.943
4992.13	237.871
4994.64	235.68
4997.15	248.143
4999.65	245.989