File: Data/3-Raman/raw/bu19w-d-ff2-fi10-v_1800 (450-850nm)_532nm_edge_100%_x100_vis_lwd_h50um_30sx2_01.txt
#Acq. time (s)=	30
#Accumulations=	2
#Range (cm-¹)=	1200...2365
#Windows=	3
#Auto scanning=	Off
#Autofocus=	Off
#Macrospot=	Off
#AutoExposure=	Off
#Spike filter=	Multiple accum.
#Delay time (s)=	2
#Binning=	1
#Readout mode=	Signal
#DeNoise=	Off
#ICS correction=	On
#Dark correction=	Off
#Inst. Process=	Off
#Detector Gain=	Best Dynamic
#Detector ADC=	50 kHz HS
#Detector temperature (°C)=	-60.09
#Instrument=	LabRAM HR Evol
#Detector=	SIN-EM FIVIS
#Objective=	x100_VIS_LWD
#Grating=	1800 (450-850nm)
#ND Filter=	100%
#Laser=	532nm_Edge
#Hole=	49.98
#Temperature=	0
#Range=	Visible
#StageXY=	75x50mm Scan+
#StageZ=	Z motor
#X (µm)=	0
#Y (µm)=	0
#Z (µm)=	64.1
#Full time(mm:ss)=	3:19
#Project=	21_11_22
#Sample=	BU19w
#Site=
#Title=	BU19w-D-FF2-FI10-V_1800 (450-850nm)_532nm_Edge_100%_x100_VIS_LWD_H50um_30sX2
#Remark=
#Date=	22.11.2021 13:57
#Acquired=	22.11.2021 13:57:50
1202.84	61.7341
1203.95	60.5419
1205.06	50.8381
1206.17	62.5454
1207.29	58.2375
1208.39	57.0798
1209.51	60.1951
1210.62	54.811
1211.72	56.9292
1212.84	57.9815
1213.94	57.895
1215.05	61.0114
1216.16	64.152
1217.27	54.5738
1218.38	58.7946
1219.49	56.5984
1220.6	53.3176
1221.71	57.4754
1222.81	56.4173
1223.92	59.5721
1225.03	56.2774
1226.14	52.9842
1227.24	61.559
1228.35	60.3317
1229.46	63.4746
1230.56	73.9615
1231.67	82.3919
1232.78	85.5811
1233.88	91.8688
1234.99	86.5015
1236.09	80.1023
1237.2	69.5879
1238.3	69.5917
1239.41	58.0344
1240.51	58.0506
1241.62	61.1915
1242.72	64.2766
1243.83	62.1402
1244.93	63.1702
1246.03	63.1293
1247.14	69.4006
1248.24	73.517
1249.34	73.4604
1250.45	73.4053
1251.55	82.8369
1252.65	77.628
1253.75	76.5959
1254.86	74.4873
1255.96	64.0081
1257.06	67.1812
1258.16	62.9293
1259.26	67.2281
1260.36	60.7952
1261.46	62.0468
1262.56	61.9791
1263.66	65.1082
1264.76	62.0291
1265.86	57.9194
1266.96	54.7765
1268.06	57.8608
1269.16	66.2332
1270.26	66.3085
1271.36	59.0274
1272.46	57.9823
1273.56	60.1222
1274.66	59.1171
1275.76	59.168
1276.85	66.5412
1277.95	59.1728
1279.05	59.2107
1280.15	59.1882
1281.24	70.6741
1282.34	75.0361
1283.44	160.325
1284.53	178.151
1285.63	66.5429
1286.73	63.4183
1287.82	61.3275
1288.92	58.157
1290.01	51.8311
1291.11	51.888
1292.21	46.6242
1293.3	49.8901
1294.4	44.5981
1295.49	54.0716
1296.58	52.9859
1297.68	43.4942
1298.77	51.944
1299.87	46.6738
1300.96	40.3167
1302.05	48.756
1303.15	46.6006
1304.24	42.3677
1305.33	51.8606
1306.42	44.4857
1307.52	46.6004
1308.61	49.7697
1309.7	47.6782
1310.79	48.7155
1311.88	45.5481
1312.98	49.7927
1314.07	48.7254
1315.16	44.5109
1316.25	46.6226
1317.34	47.6757
1318.43	46.5844
1319.52	43.373
1320.61	48.6248
1321.7	45.4608
1322.79	42.2676
1323.88	45.3466
1324.97	43.3121
1326.06	48.6391
1327.15	46.518
1328.23	47.5301
1329.32	45.3522
1330.41	47.3906
1331.5	52.583
1332.59	44.142
1333.67	45.1589
1334.76	43.0409
1335.85	50.3341
1336.94	49.2799
1338.02	44.0441
1339.11	46.1178
1340.2	48.165
1341.28	45.0185
1342.37	46.0398
1343.45	44.9287
1344.54	39.6559
1345.63	50.0544
1346.71	44.8079
1347.8	46.8505
1348.88	49.9304
1349.96	44.7543
1351.05	46.8863
1352.13	45.7286
1353.22	47.7979
1354.3	44.6539
1355.39	47.7354
1356.47	42.5119
1357.55	47.6486
1358.63	46.5928
1359.72	49.6778
1360.8	46.5824
1361.88	44.5055
1362.97	47.5681
1364.05	43.3779
1365.13	49.5725
1366.21	48.5481
1367.29	53.7001
1368.37	56.7499
1369.45	61.8201
1370.54	54.5582
1371.62	53.5064
1372.7	56.5908
1373.78	54.5031
1374.86	62.7108
1375.94	70.0283
1377.02	73.082
1378.09	77.0363
1379.18	83.1204
1380.25	100.436
1381.33	101.396
1382.41	107.643
1383.49	100.541
1384.57	104.386
1385.65	104.401
1386.72	224.774
1387.8	288.018
1388.88	86.9581
1389.96	68.4575
1391.03	61.2637
1392.11	53.0687
1393.19	52.0592
1394.26	54.0756
1395.34	49.9673
1396.42	48.961
1397.49	46.9272
1398.57	51.042
1399.64	45.9862
1400.72	49.1085
1401.79	53.1742
1402.87	42.8833
1403.94	49.0162
1405.02	52.1026
1406.09	46.9864
1407.17	45.9689
1408.24	64.3655
1409.31	63.3233
1410.39	46.0306
1411.46	43.9157
1412.53	45.9882
1413.61	40.864
1414.68	47.0446
1415.75	44.9948
1416.82	40.8711
1417.9	40.8348
1418.97	41.8586
1420.04	38.8549
1421.11	44.8817
1422.18	40.7695
1423.26	41.8086
1424.33	41.7641
1425.4	42.7437
1426.47	40.7039
1427.54	36.6358
1428.61	40.7853
1429.68	43.8373
1430.75	40.6961
1431.82	42.7549
1432.89	41.7268
1433.96	45.8081
1435.02	40.6719
1436.09	42.7313
1437.16	42.7589
1438.23	40.717
1439.3	47.8866
1440.37	39.6785
1441.43	41.716
1442.5	40.7207
1443.57	39.6782
1444.64	37.6094
1445.7	41.7195
1446.77	35.5575
1447.84	39.6365
1448.9	37.5697
1449.97	37.5641
1451.04	39.6167
1452.1	41.6598
1453.17	41.666
1454.23	42.6704
1455.3	38.5621
1456.36	40.6145
1457.43	39.5811
1458.49	37.5121
1459.56	38.5059
1460.62	40.5125
1461.69	42.6002
1462.75	34.3082
1463.81	38.3746
1464.88	39.3839
1465.94	41.415
1467	37.3074
1468.07	40.3406
1469.13	33.1871
1470.19	36.2325
1471.25	36.211
1472.32	37.2315
1473.38	36.1975
1474.44	39.2268
1475.5	40.2257
1476.56	38.1636
1477.62	42.1786
1478.68	43.1731
1479.75	40.1546
1480.81	38.1283
1481.87	31.9665
1482.93	42.0808
1483.99	42.0837
1485.05	36.9954
1486.11	35.9494
1487.17	40.9941
1488.22	39.9576
1489.28	48.0383
1490.34	40.9525
1491.4	33.871
1492.46	36.8858
1493.52	42.9027
1494.58	37.8406
1495.63	36.8258
1496.69	35.8213
1497.75	38.8495
1498.81	42.8671
1499.86	32.7596
1500.92	40.8051
1501.98	40.8062
1503.03	38.7506
1504.09	37.7427
1505.15	39.7549
1506.2	39.7519
1507.26	38.7472
1508.31	38.7085
1509.37	43.6539
1510.42	33.5618
1511.48	38.6027
1512.53	43.5841
1513.59	38.5259
1514.64	38.516
1515.7	35.5183
1516.75	33.5181
1517.8	35.5166
1518.86	36.5232
1519.91	39.5128
1520.96	35.4568
1522.02	38.4414
1523.07	41.4596
1524.12	36.467
1525.17	37.4516
1526.23	39.4371
1527.28	34.415
1528.33	42.4507
1529.38	40.4369
1530.43	37.468
1531.48	43.4894
1532.53	35.4448
1533.59	43.4017
1534.64	32.3478
1535.69	41.321
1536.74	43.3809
1537.79	37.4338
1538.84	34.4006
1539.89	40.3693
1540.94	43.3188
1541.98	35.3371
1543.03	46.3862
1544.08	38.3782
1545.13	41.3587
1546.18	40.3314
1547.23	37.3356
1548.28	43.4689
1549.33	38.4461
1550.37	40.4211
1551.42	43.3952
1552.47	46.3574
1553.52	36.3335
1554.56	39.341
1555.61	45.3114
1556.65	40.256
1557.7	42.2303
1558.75	44.2334
1559.79	41.2538
1560.84	41.2418
1561.88	39.2708
1562.93	41.0119
1563.98	41.1853
1565.02	44.2136
1566.07	44.221
1567.11	41.1964
1568.15	42.191
1569.2	42.1676
1570.24	36.1479
1571.29	44.1256
1572.33	44.1653
1573.37	43.1688
1574.42	42.1155
1575.46	38.074
1576.5	44.0491
1577.55	45.0558
1578.59	47.0253
1579.63	44.0058
1580.67	42.0013
1581.72	46.9801
1582.76	43.9858
1583.8	47.9293
1584.84	43.9273
1585.88	47.9201
1586.92	43.9524
1587.96	45.9533
1589	43.9484
1590.04	43.903
1591.08	44.8281
1592.12	42.8454
1593.16	47.7928
1594.2	47.7944
1595.24	43.8197
1596.28	48.739
1597.32	49.6935
1598.36	50.6257
1599.4	43.6418
1600.44	44.5881
1601.48	47.5405
1602.51	44.5749
1603.55	52.5061
1604.59	48.5553
1605.63	49.5366
1606.66	43.5567
1607.7	44.74
1608.74	45.6732
1609.77	44.6129
1610.81	51.2186
1611.85	45.5399
1612.88	51.976
1613.92	54.656
1614.95	51.2383
1615.99	53.747
1617.03	47.0283
1618.06	51.0984
1619.1	51.9343
1620.13	53.7716
1621.17	50.3259
1622.2	49.9045
1623.23	51.2428
1624.27	50.7978
1625.3	53.5891
1626.34	53.9656
1627.37	47.9929
1628.4	55.3871
1629.44	56.5735
1630.47	51.383
1631.29	54.8023
1632.33	57.7562
1633.38	59.702
1634.42	57.6943
1635.47	51.7669
1636.51	54.7145
1637.56	57.6661
1638.6	55.7066
1639.65	55.6895
1640.69	56.6636
1641.73	54.6665
1642.78	53.6953
1643.82	49.7382
1644.86	46.7667
1645.91	52.6885
1646.95	60.5805
1647.99	58.6565
1649.03	51.7748
1650.08	56.6878
1651.12	53.7372
1652.16	54.737
1653.2	52.8205
1654.24	58.7508
1655.28	54.7808
1656.33	57.7062
1657.37	52.7532
1658.41	56.732
1659.45	48.8319
1660.49	53.859
1661.53	54.7859
1662.57	52.7625
1663.61	52.8906
1664.65	56.7309
1665.69	53.7514
1666.72	52.8196
1667.76	52.8493
1668.8	52.8423
1669.84	49.8826
1670.88	50.8765
1671.92	53.867
1672.96	51.9067
1674	49.9298
1675.03	48.9201
1676.07	48.8818
1677.11	47.8709
1678.15	55.7543
1679.18	46.8568
1680.22	46.8516
1681.25	42.8908
1682.29	45.8378
1683.33	48.7984
1684.36	43.8741
1685.4	43.853
1686.43	45.7949
1687.47	43.7949
1688.51	45.7838
1689.54	42.825
1690.58	41.798
1691.61	45.6987
1692.64	42.7408
1693.68	43.7384
1694.71	42.7228
1695.75	42.6864
1696.78	42.6776
1697.81	43.6487
1698.85	39.6946
1699.88	42.6109
1700.91	44.562
1701.95	44.5676
1702.98	47.5057
1704.01	43.534
1705.04	38.5817
1706.08	44.4045
1707.11	39.4891
1708.14	40.4768
1709.17	45.3801
1710.2	39.4475
1711.23	41.3498
1712.27	37.4291
1713.3	39.3895
1714.33	41.2964
1715.36	41.2216
1716.39	38.2736
1717.42	45.0871
1718.45	39.2106
1719.48	39.1699
1720.51	34.2778
1721.54	38.1499
1722.56	33.2508
1723.59	38.0741
1724.62	39.9868
1725.65	37.0505
1726.68	40.8193
1727.71	34.0525
1728.74	36.0206
1729.76	39.8704
1730.79	39.8214
1731.82	39.7659
1732.85	33.9432
1733.87	36.8108
1734.9	31.9788
1735.93	42.5194
1736.95	38.618
1737.98	39.5232
1739.01	38.5313
1740.03	40.4295
1741.06	38.4951
1742.08	33.6967
1743.11	37.5117
1744.13	29.8283
1745.16	36.4825
1746.18	36.4841
1747.21	36.5078
1748.23	33.6584
1749.26	28.8524
1750.28	35.505
1751.31	35.4753
1752.33	35.4509
1753.35	36.372
1754.38	34.4243
1755.4	36.33
1756.42	35.3799
1757.44	35.3708
1758.47	31.5429
1759.49	37.2334
1760.51	31.5334
1761.53	35.3522
1762.56	29.6602
1763.58	39.1782
1764.6	36.3096
1765.62	36.2904
1766.64	33.3755
1767.66	37.1838
1768.68	38.161
1769.7	36.2754
1770.72	32.4821
1771.74	35.3442
1772.76	33.468
1773.78	30.6132
1774.8	37.2604
1775.82	38.1804
1776.84	31.4955
1777.86	36.2667
1778.88	36.2733
1779.9	40.1064
1780.92	32.4967
1781.94	34.4251
1782.95	33.4634
1783.97	38.2399
1784.99	33.519
1786.01	36.4469
1787.03	34.5624
1788.04	29.7727
1789.06	34.5277
1790.08	32.618
1791.09	29.748
1792.11	30.7155
1793.13	38.4394
1794.14	33.6621
1795.16	31.7553
1796.17	31.7538
1797.19	35.5732
1798.21	34.5962
1799.22	33.6363
1800.24	34.6159
1801.25	36.5533
1802.27	33.6914
1803.28	30.8272
1804.29	34.6907
1805.31	33.7254
1806.32	29.8709
1807.34	33.7289
1808.35	27.9376
1809.36	30.8285
1810.38	35.6659
1811.39	30.8625
1812.4	33.7867
1813.41	35.7242
1814.43	32.8145
1815.44	29.9013
1816.45	35.7092
1817.46	30.8878
1818.47	35.7367
1819.49	31.8794
1820.5	35.7518
1821.51	32.8419
1822.52	33.8199
1823.53	28.9774
1824.54	32.8557
1825.55	34.7947
1826.56	33.8102
1827.57	33.7953
1828.58	31.8626
1829.59	35.7523
1830.6	36.7312
1831.61	35.7519
1832.62	36.6547
1833.63	29.0456
1834.64	33.77
1835.65	32.7377
1836.65	37.6671
1837.66	33.7385
1838.67	33.6696
1839.68	32.6588
1840.69	28.802
1841.7	32.658
1842.7	35.5494
1843.71	33.6721
1844.72	34.503
1845.72	34.5131
1846.73	32.5602
1847.74	31.5547
1848.74	32.4878
1849.75	32.4808
1850.75	33.4292
1851.76	33.3892
1852.76	30.4803
1853.77	37.1745
1854.78	36.2025
1855.78	27.5608
1856.79	35.1818
1857.79	32.3214
1858.79	33.2956
1859.8	33.2764
1860.8	34.1985
1861.81	33.2155
1862.81	33.1741
1863.81	31.211
1864.82	38.7696
1865.82	33.0531
1866.82	32.0957
1867.83	32.0863
1868.83	34.9252
1869.83	33.0017
1870.83	35.8317
1871.84	32.0044
1872.84	30.067
1873.84	32.8603
1874.84	33.7255
1875.84	37.5916
1876.84	31.9406
1877.84	30.9862
1878.84	29.051
1879.84	33.7
1880.84	34.6552
1881.84	30.8321
1882.85	29.9225
1883.85	30.8776
1884.84	32.7279
1885.84	34.5661
1886.84	36.4194
1887.84	34.5531
1888.84	32.6618
1889.84	35.4717
1890.84	33.5294
1891.84	33.512
1892.83	36.3348
1893.83	35.4143
1894.83	38.2468
1895.83	33.5257
1896.83	33.4975
1897.82	29.7301
1898.82	34.4487
1899.82	32.5838
1900.81	31.6275
1901.81	35.3795
1902.81	33.4898
1903.8	34.396
1904.8	35.33
1905.79	34.4042
1906.79	34.4283
1907.79	28.8202
1908.78	31.6556
1909.78	33.5305
1910.77	33.5365
1911.77	33.5686
1912.76	33.5839
1913.76	31.681
1914.75	36.3729
1915.74	30.7269
1916.74	30.7665
1917.73	34.5501
1918.72	30.7938
1919.72	34.5756
1920.71	28.885
1921.7	32.6453
1922.7	34.5476
1923.69	35.5302
1924.68	34.6071
1925.67	31.776
1926.66	36.5359
1927.66	39.421
1928.65	38.4751
1929.64	31.8088
1930.63	28.0064
1931.62	30.9283
1932.61	32.9108
1933.61	34.7916
1934.6	31.9034
1935.59	34.7417
1936.58	35.717
1937.57	34.7831
1938.56	33.8662
1939.55	35.7592
1940.54	31.9531
1941.52	31.9594
1942.51	33.8979
1943.5	31.0517
1944.49	33.9171
1945.48	31.9971
1946.47	32.9652
1947.46	33.0032
1948.44	35.931
1949.43	32.1212
1950.42	33.092
1951.41	33.9826
1952.39	35.8639
1953.38	34.9588
1954.37	31.1484
1955.36	35.0084
1956.34	36.9197
1957.33	34.9783
1958.31	35.9109
1959.3	34.9447
1960.29	31.1078
1961.27	35.9143
1962.26	32.0696
1963.24	29.1969
1964.23	32.0961
1965.21	33.0585
1966.2	32.0832
1967.18	33.0032
1968.17	32.9788
1969.15	40.6455
1970.14	31.0486
1971.12	32.9408
1972.1	31.9784
1973.09	32.9511
1974.07	32.9534
1975.05	34.8539
1976.04	33.8776
1977.02	31.0023
1978	33.8581
1978.98	35.7576
1979.97	29.0368
1980.95	35.7064
1981.93	33.7772
1982.91	30.89
1983.89	37.5941
1984.88	34.7031
1985.86	31.7677
1986.84	32.6525
1987.82	32.665
1988.8	32.7124
1989.78	30.9554
1990.76	30.2675
1991.74	33.6222
1992.72	34.1576
1993.7	37.9708
1994.68	31.6479
1995.66	34.4088
1996.64	35.4587
1997.62	35.5448
1998.6	33.528
1999.57	33.0298
2000.55	35.7024
2001.53	37.2438
2002.51	30.4378
2003.49	34.8234
2004.47	32.1772
2005.44	33.5693
2006.42	35.9917
2007.4	33.3977
2008.38	33.5166
2009.35	33.3415
2010.33	34.3839
2011.3	31.9509
2012.18	33.0801
2013.17	36.8467
2014.16	34.0636
2015.15	35.9048
2016.14	33.973
2017.13	33.0069
2018.11	35.8127
2019.1	31.1269
2020.09	37.6498
2021.08	35.7453
2022.06	34.7678
2023.05	30.0603
2024.04	33.8471
2025.02	32.9378
2026.01	31.134
2027	32.8962
2027.98	35.6422
2028.97	35.6596
2029.96	34.7706
2030.94	36.6747
2031.93	34.7121
2032.91	33.8467
2033.9	33.8453
2034.88	34.7838
2035.87	31.9591
2036.85	31.9348
2037.83	34.6976
2038.82	39.3383
2039.8	36.5197
2040.79	34.679
2041.77	30.0266
2042.75	33.7615
2043.74	34.7392
2044.72	32.8105
2045.7	37.465
2046.69	35.6285
2047.67	35.6661
2048.65	31.9135
2049.63	31.9172
2050.62	33.8074
2051.6	33.8352
2052.58	32.8862
2053.56	30.0682
2054.54	35.6766
2055.52	34.7634
2056.5	31.0409
2057.48	35.7141
2058.46	35.7208
2059.45	34.7891
2060.43	30.1235
2061.4	35.7588
2062.39	33.909
2063.37	30.1815
2064.34	38.6447
2065.32	31.1455
2066.3	33.0275
2067.28	33.9378
2068.26	39.6279
2069.24	39.673
2070.22	36.8388
2071.2	30.249
2072.18	34.0439
2073.15	29.3752
2074.13	35.9743
2075.11	36.8899
2076.09	35.0211
2077.06	35.0578
2078.04	34.1196
2079.02	38.8364
2080	38.8445
2080.97	29.3898
2081.95	35.0598
2082.93	37.8957
2083.9	33.1996
2084.88	35.1042
2085.85	35.1077
2086.83	30.3922
2087.8	31.3484
2088.78	32.3127
2089.75	35.2002
2090.73	33.3348
2091.7	36.2016
2092.68	35.2335
2093.65	37.1184
2094.63	35.1972
2095.6	33.2854
2096.57	35.1778
2097.55	32.3315
2098.52	34.251
2099.5	32.3519
2100.47	36.1301
2101.44	38.0275
2102.41	32.3499
2103.39	33.3198
2104.36	33.3262
2105.33	35.1976
2106.3	36.126
2107.27	36.1421
2108.25	34.2403
2109.22	31.3775
2110.19	35.185
2111.16	34.2512
2112.13	38.0496
2113.1	34.2364
2114.07	35.166
2115.04	33.257
2116.01	37.9665
2116.99	35.0909
2117.96	35.0881
2118.92	36.0624
2119.9	32.2893
2120.86	33.243
2121.83	37.0053
2122.8	34.1043
2123.77	36.9073
2124.74	34.0479
2125.71	33.0932
2126.68	35.9211
2127.65	38.7461
2128.61	34.9468
2129.58	34.9263
2130.55	28.3095
2131.52	34.918
2132.48	38.6865
2133.45	39.5945
2134.42	32.0479
2135.39	35.8172
2136.35	37.7196
2137.32	33.9051
2138.28	37.6571
2139.25	32.93
2140.22	35.7911
2141.18	33.8152
2142.15	33.8266
2143.12	29.1222
2144.08	37.569
2145.05	26.2761
2146.01	30.0164
2146.98	33.7338
2147.94	32.7739
2148.9	37.4778
2149.87	33.7231
2150.83	31.8292
2151.8	35.535
2152.76	32.6767
2153.72	30.7867
2154.69	38.2651
2155.65	36.4093
2156.61	32.6554
2157.58	27.9564
2158.54	34.4732
2159.5	33.5337
2160.47	37.2511
2161.43	31.637
2162.39	32.5573
2163.35	32.5535
2164.31	33.4633
2165.27	32.4835
2166.24	35.2704
2167.2	36.2421
2168.16	34.3817
2169.12	37.1154
2170.08	38.0224
2171.04	36.1684
2172	37.1018
2172.96	33.3765
2173.92	38.0075
2174.88	32.433
2175.84	28.7007
2176.8	31.4857
2177.76	35.1947
2178.72	35.1835
2179.68	35.1679
2180.64	35.1384
2181.59	33.2634
2182.55	36.0515
2183.51	31.4359
2184.47	35.1853
2185.43	37.9703
2186.38	37.934
2187.34	34.1941
2188.3	36.0534
2189.26	32.3536
2190.21	37.9364
2191.17	30.5503
2192.13	32.4189
2193.08	29.6069
2194.04	39.7783
2195	34.1999
2195.95	37.9422
2196.91	35.2013
2197.86	34.3351
2198.82	35.2367
2199.78	36.1186
2200.73	36.152
2201.69	35.304
2202.64	34.2688
2203.59	36.1327
2204.55	34.2708
2205.5	36.1599
2206.46	38.9707
2207.41	38.0434
2208.37	36.2016
2209.32	36.2276
2210.27	34.3547
2211.23	36.2151
2212.18	31.5828
2213.13	38.1218
2214.09	29.7137
2215.04	36.2504
2215.99	29.7212
2216.94	35.3448
2217.9	36.2784
2218.85	34.3799
2219.8	37.1694
2220.75	29.7205
2221.7	34.4295
2222.65	34.4617
2223.6	27.9295
2224.55	33.5737
2225.5	29.8187
2226.46	35.437
2227.41	36.4041
2228.36	32.6773
2229.31	30.8236
2230.26	31.7863
2231.21	30.8639
2232.16	37.436
2233.11	33.6526
2234.05	35.5396
2235	34.6407
2235.95	33.7394
2236.9	37.5189
2237.85	34.6794
2238.8	31.8689
2239.75	29.0479
2240.69	29.9821
2241.64	31.8707
2242.59	32.8562
2243.54	31.935
2244.48	33.843
2245.43	32.893
2246.38	30.9925
2247.32	35.7283
2248.27	30.0243
2249.22	30.9669
2250.16	28.1628
2251.11	34.8279
2252.06	31.9917
2253	31.9948
2253.95	32.0159
2254.89	31.0845
2255.84	31.0916
2256.78	31.1053
2257.73	33.9693
2258.67	28.2846
2259.62	29.2457
2260.56	28.3211
2261.51	31.2245
2262.45	36.9833
2263.39	32.1996
2264.34	29.3079
2265.28	32.1469
2266.22	32.1559
2267.17	33.1485
2268.11	33.176
2269.05	35.1094
2270	36.0732
2270.94	31.2952
2271.88	28.4289
2272.82	27.4749
2273.77	30.3721
2274.71	28.4865
2275.65	28.5156
2276.59	29.4673
2277.53	30.3883
2278.47	31.3284
2279.41	32.2932
2280.36	30.4035
2281.3	29.4945
2282.24	31.443
2283.18	32.3886
2284.12	28.5592
2285.06	31.4752
2286	33.3826
2286.94	29.4871
2287.88	29.4794
2288.82	32.3941
2289.75	30.4921
2290.69	33.4027
2291.63	28.5744
2292.57	33.3704
2293.51	29.4907
2294.45	30.4625
2295.39	26.6399
2296.32	34.3755
2297.26	31.4898
2298.2	27.6409
2299.14	31.5056
2300.07	34.3949
2301.01	31.4997
2301.95	28.6199
2302.89	27.6651
2303.82	35.4052
2304.76	28.6305
2305.69	28.622
2306.63	34.4389
2307.57	30.5911
2308.5	35.3938
2309.44	29.5518
2310.37	29.5445
2311.31	27.6489
2312.24	30.5832
2313.18	29.5852
2314.11	25.692
2315.05	31.5019
2315.98	33.4062
2316.92	32.4233
2317.85	25.6707
2318.78	29.5511
2319.72	29.5783
2320.65	31.5148
2321.58	31.5139
2322.52	33.408
2323.45	31.4491
2324.38	30.4559
2325.32	30.4428
2326.25	36.2113
2327.18	48.7225
2328.11	72.7828
2329.05	40.0646
2329.98	37.144
2330.91	33.2755
2331.84	32.2882
2332.77	28.4352
2333.7	30.3531
2334.63	28.4235
2335.56	30.3373
2336.5	32.2592
2337.43	28.4013
2338.36	27.4114
2339.29	32.1765
2340.22	27.371
2341.15	28.3264
2342.08	27.3666
2343.01	29.2612
2343.93	33.0793
2344.86	30.2002
2345.79	33.0797
2346.72	27.3013
2347.65	28.1672
2348.58	29.2354
2349.51	28.1924
2350.44	30.9932
2351.36	27.1724
2352.29	30.0401
2353.22	26.2147
2354.15	27.1279
2355.07	23.3074
2356	29.9442
2356.93	28.9803
2357.86	24.2084
2358.78	31.7657
2359.71	27.9437
2360.63	25.085
2361.56	27.9074
2362.49	28.8329
2363.41	27.8392
2364.34	28.8122
2364.8	25.0419