File: Data/3-Raman/raw/bu19w-e-ff11-fi09-s_150 (500nm)_633nm_edge_100%_x100_vis_h50um_60sx2_01.txt
#Acq. time (s)=	60
#Accumulations=	2
#Range (cm-¹)=	100...4000
#Windows=	1
#Auto scanning=	Off
#Autofocus=	Off
#Macrospot=	Off
#AutoExposure=	Off
#Spike filter=	Multiple accum.
#Delay time (s)=	2
#Binning=	1
#Readout mode=	Signal
#DeNoise=	Off
#ICS correction=	On
#Dark correction=	Off
#Inst. Process=	Off
#Detector Gain=	Best Dynamic
#Detector ADC=	50 kHz HS
#Detector temperature (°C)=	-60.09
#Instrument=	LabRAM HR Evol
#Detector=	SIN-EM FIVIS
#Objective=	x100_VIS
#Grating=	150 (500nm)
#ND Filter=	100%
#Laser=	633nm_Edge
#Hole=	49.98
#Temperature=	0
#Range=	Visible
#StageXY=	75x50mm Scan+
#StageZ=	Z motor
#X (µm)=	0
#Y (µm)=	0
#Z (µm)=	-269.3
#Full time(mm:ss)=	2:04
#Project=	21_11_04
#Sample=	BU19w
#Site=
#Title=	BU19w-E-FF11-FI09-S_150 (500nm)_633nm_Edge_100%_x100_VIS_H50um_60sX2
#Remark=
#Date=	04.11.2021 16:13
#Acquired=	04.11.2021 16:13:38
102.881	246.454
109.397	226.65
115.908	223.05
122.414	210.783
128.914	237.701
135.409	256.924
141.898	261.715
148.383	256.985
154.861	314.547
161.335	330.053
167.801	233.41
174.264	192.214
180.721	166.253
187.173	159.362
193.62	160.06
200.061	166.549
206.496	173.203
212.926	184.577
219.352	243.623
225.772	394.956
232.185	469.57
238.595	306.555
244.999	244.63
251.397	236.917
257.791	262.391
264.178	245.211
270.561	248.954
276.939	278.347
283.31	251.728
289.678	217.475
296.039	193.619
302.396	224.67
308.746	303.836
315.093	514.141
321.433	670.469
327.768	474.988
334.099	302.302
340.423	262.626
346.743	252.158
353.058	272.743
359.367	277.208
365.671	224.266
371.971	181.77
378.265	157.177
384.553	143.927
390.837	144.941
397.116	152.665
403.389	170.907
409.657	165.604
415.92	182.862
422.178	227.55
428.431	254.749
434.678	263.593
440.921	251.663
447.158	256.617
453.391	264.289
459.618	219.805
465.84	158.935
472.057	165.338
478.27	149.524
484.477	162.586
490.679	163.539
496.876	171.033
503.068	201.872
509.255	236.495
515.436	237.617
521.613	236.08
527.785	230.92
533.952	202.404
540.113	187.854
546.27	163.659
552.423	160.951
558.568	141.166
564.711	128.717
570.848	132.187
576.979	130.834
583.107	148.208
589.228	193.576
595.345	209.182
601.458	217.618
607.565	221.678
613.667	216.52
619.764	190.882
625.856	177.41
631.944	155.122
638.026	161.747
644.104	156.801
650.177	153.734
656.244	156.164
662.308	121.132
668.365	103.103
674.418	98.3812
680.467	90.922
686.511	78.8669
692.549	83.6989
698.582	85.7624
704.611	83.119
710.635	86.0534
716.655	80.3541
722.669	84.0659
728.679	83.949
734.683	74.4357
740.683	80.8455
746.678	81.6582
752.669	80.6534
758.654	79.7157
764.635	81.7401
770.611	80.0983
776.582	77.5042
782.549	70.1263
788.511	87.1794
794.466	84.4114
800.419	81.5696
806.366	81.4928
812.309	86.0833
818.247	84.9642
824.18	90.3798
830.108	81.7681
836.033	94.8292
841.952	96.841
847.865	97.014
853.776	96.2975
859.681	105.971
865.58	116.654
871.476	127.364
877.366	132.274
883.253	141.858
889.134	144.703
895.012	137.98
900.883	127.324
906.751	122.292
912.614	118.201
918.473	141.454
924.326	134.784
930.174	159.324
936.019	188.792
941.859	228.192
947.693	264.17
953.525	278.533
959.35	311.923
965.171	346.2
970.988	441.803
976.801	571.672
982.608	600.846
988.411	535.751
994.209	421.04
1000	338.302
1005.79	331.279
1011.58	346.603
1017.36	379.384
1023.13	340.738
1028.9	274.491
1034.67	252.184
1040.43	234.657
1046.19	215.092
1051.94	196.233
1057.69	182.988
1063.44	177.305
1069.17	185.01
1074.91	217.943
1080.64	253.641
1086.37	318.327
1092.09	360.755
1097.8	379.881
1103.52	296.501
1109.22	227.934
1114.93	215.818
1120.63	204.826
1126.32	207.232
1132.01	243.929
1137.7	277.857
1143.38	346.307
1149.06	400.942
1154.73	317.544
1160.4	183.538
1166.06	148.814
1171.72	126.966
1177.38	117.898
1183.03	105.012
1188.67	102.054
1194.31	84.5311
1199.95	83.697
1205.58	77.0891
1211.21	75.4057
1216.84	71.7705
1222.46	72.1123
1228.07	71.4585
1233.68	70.7557
1239.29	68.9812
1244.89	70.1348
1250.49	71.2113
1256.08	72.2341
1261.67	67.1102
1267.26	71.0516
1272.84	71.9291
1278.42	68.7602
1283.99	70.6217
1289.56	64.5149
1295.12	66.4633
1300.68	74.451
1306.23	67.5213
1311.78	66.6808
1317.33	66.8927
1322.87	64.1027
1328.41	64.3593
1333.94	67.6604
1339.47	65.8458
1345	68.0493
1350.52	59.9781
1356.04	72.39
1361.55	63.2019
1367.06	64.2326
1372.56	70.3736
1378.06	71.3753
1383.56	68.2632
1389.05	67.2045
1394.53	64.1365
1400.02	69.3713
1405.5	64.3259
1410.97	66.5028
1416.44	63.5463
1421.91	61.6222
1427.37	70.0854
1432.83	65.0629
1438.28	62.0961
1443.73	71.6665
1449.17	63.4288
1454.62	69.7993
1460.05	69.8299
1465.48	71.9238
1470.91	70.8531
1476.34	71.8992
1481.76	65.6285
1487.17	65.6773
1492.59	66.8126
1497.99	63.7686
1503.4	71.2972
1508.8	61.9461
1514.19	62.1243
1519.59	70.85
1524.97	67.8882
1530.36	64.9068
1535.74	68.3796
1541.11	65.3317
1546.48	68.6791
1551.85	69.7647
1557.21	68.5971
1562.57	73.9242
1567.93	74.9264
1573.28	72.6938
1578.62	73.7358
1583.97	76.9731
1589.3	69.466
1594.64	66.2924
1599.97	72.8578
1605.3	74.0745
1610.62	73.1845
1615.94	75.6135
1621.25	75.9055
1626.56	78.3863
1631.87	75.3738
1637.17	73.3854
1642.47	69.0592
1647.76	70.2714
1653.05	81.4307
1658.34	77.0477
1663.62	68.1999
1668.9	71.5331
1674.18	78.1888
1679.45	73.7398
1684.71	75.9036
1689.98	72.5191
1695.23	69.1835
1700.49	77.0271
1705.74	71.8424
1710.99	70.8246
1716.23	76.4314
1721.47	75.5302
1726.7	80.1346
1731.94	80.3024
1737.16	75.9598
1742.39	73.8502
1747.61	67.2043
1752.82	85.3861
1758.03	83.1955
1763.24	69.6356
1768.44	84.3961
1773.64	79.9156
1778.84	75.4615
1784.03	84.6708
1789.22	81.4222
1794.41	87.3121
1799.59	76.0923
1804.76	77.4504
1809.94	78.7865
1815.11	88.1764
1820.27	81.4363
1825.43	72.3579
1830.59	85.2939
1835.74	79.6911
1840.89	83.3509
1846.04	84.6656
1851.18	74.2761
1856.32	79.055
1861.45	92.1048
1866.58	82.8897
1871.71	77.1483
1876.83	87.8668
1881.95	87.9723
1887.07	86.8757
1892.18	83.3488
1897.29	82.178
1902.39	86.9983
1907.49	80.0511
1912.59	94.5476
1917.68	84.1166
1922.77	87.7944
1927.86	87.9668
1932.94	83.3386
1938.02	85.8793
1943.09	90.8042
1948.16	87.2862
1953.23	98.1806
1958.29	83.7533
1963.35	92.2045
1968.41	88.5766
1973.46	89.7325
1978.51	88.4799
1983.55	87.2265
1988.59	82.3773
1993.63	79.9469
1998.66	90.7584
2003.69	90.7759
2008.72	88.4212
2013.74	93.3099
2018.76	94.5782
2023.77	95.861
2028.78	105.647
2033.79	94.9508
2038.79	87.8619
2043.79	95.3269
2048.79	93.103
2053.78	95.7059
2058.77	100.791
2063.76	92.445
2068.74	98.7869
2073.72	102.686
2078.69	101.658
2083.66	95.6644
2088.63	105.681
2093.59	99.6775
2098.55	96.1823
2103.51	107.615
2108.46	106.657
2113.41	109.477
2118.36	112.329
2123.3	103.858
2128.24	107.944
2133.17	112.024
2138.11	99.5993
2143.03	103.632
2147.96	110.195
2152.88	103.971
2157.79	101.529
2162.71	105.437
2167.62	99.0793
2172.52	106.81
2177.43	104.325
2182.32	101.779
2187.22	110.726
2192.11	109.484
2197	110.845
2201.89	108.421
2206.77	98.3221
2211.64	112.693
2216.52	100.044
2221.39	97.7099
2226.26	101.851
2231.12	113.817
2235.98	99.7615
2240.84	106.548
2245.69	108.133
2250.54	109.722
2255.39	107.357
2260.23	119.522
2265.07	103.908
2269.9	100.117
2274.74	102.914
2279.57	108.342
2284.39	111.063
2289.21	119.075
2294.03	123.094
2298.84	108.515
2303.66	103.291
2308.46	120.813
2313.27	117.051
2318.07	109.293
2322.87	123.01
2327.66	108.515
2332.45	112.884
2337.24	110.521
2342.02	113.602
2346.8	119.477
2351.58	115.783
2356.35	114.76
2361.12	113.643
2365.89	113.887
2370.65	111.363
2375.41	117.131
2380.17	114.563
2384.92	113.308
2389.67	114.79
2394.42	116.222
2399.16	120.397
2403.9	121.777
2408.64	114.828
2413.37	115.028
2418.1	114.178
2422.83	115.952
2427.55	124.587
2432.27	119.265
2436.99	113.959
2441.7	112.881
2446.41	118.914
2451.11	119.274
2455.82	135.378
2460.51	121.405
2465.21	124.636
2469.9	124.97
2474.59	125.286
2479.28	129.975
2483.96	121.556
2488.64	113.058
2493.32	124.98
2497.99	120.848
2502.66	128.414
2507.32	116.871
2511.99	124.401
2516.65	142.245
2521.3	123.273
2525.96	127.899
2530.61	129.575
2535.25	113.49
2539.89	140.472
2544.53	134.804
2549.17	126.148
2553.8	124.928
2558.43	129.654
2563.06	132.937
2567.68	125.738
2572.3	120.03
2576.92	140.004
2581.53	125.125
2586.14	135.93
2590.75	128.441
2595.35	134.678
2599.96	144.038
2604.55	141.17
2609.15	135.219
2613.74	126.147
2618.33	141.56
2622.91	138.622
2627.49	137.244
2632.07	143.642
2636.64	144.007
2641.22	138.281
2645.78	141.835
2650.35	142.274
2654.91	144.218
2659.47	139.788
2664.03	141.554
2668.58	137.053
2673.13	148.327
2677.67	134.691
2682.22	140.111
2686.76	132.797
2691.29	144.53
2695.83	140.103
2700.36	146.816
2704.89	153.543
2709.41	142.549
2713.93	144.415
2718.45	149.583
2722.96	149.863
2727.47	153.312
2731.98	146.959
2736.49	158.455
2740.99	139.069
2745.49	160.421
2749.98	149.285
2754.47	161.185
2758.96	161.491
2763.45	156.81
2767.93	150.546
2772.41	154.124
2776.89	164.421
2781.36	153.323
2785.84	153.841
2790.3	156.016
2794.77	166.542
2799.23	161.951
2803.69	150.554
2808.14	144.116
2812.59	141.003
2817.04	156.431
2821.49	149.9
2825.93	160.335
2830.37	148.693
2834.81	150.606
2839.24	161.046
2843.67	151.045
2848.1	141.057
2852.53	156.774
2856.95	150.296
2861.37	161.015
2865.78	156.321
2870.19	156.81
2874.6	150.341
2879.01	150.827
2883.41	146.104
2887.81	167.7
2892.21	157.694
2896.6	154.709
2901	151.735
2905.38	157.552
2909.77	156.232
2914.15	156.592
2918.53	165.918
2922.91	162.735
2927.28	166.799
2931.65	160.06
2936.02	153.207
2940.38	142.605
2944.74	153.784
2949.1	164.931
2953.46	159.698
2957.81	174.542
2962.16	149.174
2966.5	165.92
2970.85	160.711
2975.19	161.014
2979.52	170.534
2983.86	156.128
2988.19	163.935
2992.52	171.823
2996.85	159.277
3001.17	169.124
3005.49	154.696
3009.8	172.144
3014.12	168.908
3018.43	173.301
3022.74	173.914
3027.04	178.238
3031.34	178.689
3035.64	184.804
3039.94	181.328
3044.23	187.452
3048.52	187.778
3052.81	199.67
3057.09	194.24
3061.38	198.455
3065.65	200.744
3069.93	189.437
3074.2	209.24
3078.47	195.981
3082.74	198.297
3087	192.871
3091.27	222.85
3095.52	221.584
3099.78	210.45
3104.03	211.181
3108.28	217.944
3112.53	224.804
3116.77	225.681
3121.01	220.555
3125.25	231.626
3129.49	236.763
3133.72	250.182
3137.95	249.328
3142.18	233.945
3146.4	239.036
3150.62	242.012
3154.84	234.423
3159.06	241.382
3163.27	271.449
3167.48	244.86
3171.69	266.607
3175.89	254.557
3180.09	261.339
3184.29	274.413
3188.49	264.087
3192.68	277.23
3196.87	277.778
3201.06	259.456
3205.24	264.669
3209.42	261.426
3213.6	262.507
3217.78	267.985
3221.95	238.557
3226.12	259.205
3230.29	249.238
3234.45	245.764
3238.61	242.227
3242.77	252.095
3246.93	237.545
3251.08	251.779
3255.23	245.701
3259.38	221.621
3263.53	229.155
3267.67	221.25
3271.81	217.596
3275.95	211.308
3280.08	220.902
3284.21	212.177
3288.34	233.285
3292.47	215.298
3296.59	227.205
3300.71	211.489
3304.83	209.585
3308.95	223.912
3313.06	212.675
3317.17	217.725
3321.27	232.18
3325.38	209.359
3329.48	216.955
3333.58	210.661
3337.67	237.388
3341.77	221.422
3345.86	195.774
3349.95	234.138
3354.03	196.445
3358.11	211.203
3362.19	218.86
3366.27	214.53
3370.34	219.795
3374.42	208.166
3378.48	201.245
3382.55	223.24
3386.61	201.773
3390.68	218.931
3394.73	204.654
3398.79	212.235
3402.84	210.054
3406.89	202.962
3410.94	186.104
3414.98	210.595
3419.03	210.765
3423.06	206.032
3427.1	215.966
3431.14	206.444
3435.17	214.077
3439.2	214.443
3443.22	195.203
3447.25	203.058
3451.27	198.63
3455.28	196.728
3459.3	194.912
3463.31	203.073
3467.32	186.289
3471.33	186.913
3475.34	210.047
3479.34	182.932
3483.34	193.595
3487.33	194.144
3491.33	204.854
3495.32	205.367
3499.31	187.921
3503.3	180.58
3507.28	193.681
3511.26	181.005
3515.24	178.552
3519.22	191.508
3523.19	183.902
3527.16	189.193
3531.13	176.447
3535.1	184.493
3539.06	190.098
3543.02	177.523
3546.98	180.415
3550.93	191.039
3554.89	185.912
3558.84	183.505
3562.78	207.214
3566.73	194.521
3570.67	181.868
3574.61	197.992
3578.55	193.237
3582.48	183.251
3586.41	181.154
3590.35	181.684
3594.27	187.531
3598.2	193.402
3602.12	164.475
3606.04	175.596
3609.95	157.162
3613.87	168.262
3617.78	163.189
3621.69	182.335
3625.6	182.465
3629.5	158.232
3633.4	160.993
3637.3	169.24
3641.2	169.49
3645.09	150.801
3648.98	137.416
3652.87	167.527
3656.76	148.596
3660.64	165.097
3664.53	162.491
3668.4	159.928
3672.28	149.136
3676.16	146.617
3680.03	138.663
3683.9	158.259
3687.76	158.699
3691.63	153.616
3695.49	159.552
3699.35	168.33
3703.2	157.606
3707.06	155.248
3710.91	141.652
3714.76	150.455
3718.6	142.331
3722.45	156.736
3726.29	140.038
3730.13	137.448
3733.97	166.107
3737.8	157.885
3741.63	152.454
3745.46	155.549
3749.29	155.76
3753.11	150.201
3756.93	156.042
3760.75	153.26
3764.57	147.597
3768.39	147.678
3772.2	139.193
3776.01	156.548
3779.81	142.343
3783.62	148.311
3787.42	142.769
3791.22	151.627
3795.02	154.778
3798.81	157.985
3802.61	152.508
3806.4	141.208
3810.18	150.284
3813.97	147.668
3817.75	150.891
3821.53	154.11
3825.31	154.36
3829.09	160.505
3832.86	128.354
3836.63	146.318
3840.4	164.313
3844.17	134.968
3847.93	152.893
3851.69	155.971
3855.45	159.016
3859.21	150.109
3862.96	132.32
3866.71	141.481
3870.46	138.829
3874.21	147.865
3877.95	144.968
3881.69	136.091
3885.44	148.178
3889.17	154.319
3892.91	136.514
3896.64	154.799
3900.37	146.007
3904.1	143.206
3907.82	152.464
3911.55	161.778
3915.27	143.886
3918.99	150.259
3922.7	138.457
3926.42	141.822
3930.13	132.948
3933.84	120.924
3937.54	145.622
3941.25	148.949
3944.95	143.1
3948.65	131.034
3952.35	125.056
3956.04	149.956
3959.73	156.291
3963.42	147.121
3967.11	131.703
3970.8	153.43
3974.48	153.484
3978.16	141.12
3981.84	141.113
3985.52	138.003
3989.19	141.098
3992.86	144.247
3996.53	141.245
3998.37	150.631