File: Data/3-Raman/raw/bu19w-ff-ore2-fi08-v_150 (500nm)_532nm_edge_100%_x100_vis_lwd_h50um_15sx2_01.txt
#Acq. time (s)=	15
#Accumulations=	2
#Range (cm-¹)=	50...5000
#Windows=	1
#Auto scanning=	Off
#Autofocus=	Off
#Macrospot=	Off
#AutoExposure=	Off
#Spike filter=	Multiple accum.
#Delay time (s)=	2
#Binning=	1
#Readout mode=	Signal
#DeNoise=	Off
#ICS correction=	On
#Dark correction=	Off
#Inst. Process=	Off
#Detector Gain=	Best Dynamic
#Detector ADC=	50 kHz HS
#Detector temperature (°C)=	-60.09
#Instrument=	LabRAM HR Evol
#Detector=	SIN-EM FIVIS
#Objective=	x100_VIS_LWD
#Grating=	150 (500nm)
#ND Filter=	100%
#Laser=	532nm_Edge
#Hole=	49.98
#Temperature=	0
#Range=	Visible
#StageXY=	75x50mm Scan+
#StageZ=	Z motor
#X (µm)=	0
#Y (µm)=	0
#Z (µm)=	-19.9
#Full time(s)=	35
#Project=	21_05_28
#Sample=	BU19w
#Site=
#Title=	BU19w-FF-ore2-FI08-V_150 (500nm)_532nm_Edge_100%_x100_VIS_LWD_H50um_15sX2
#Remark=
#Date=	28.05.2021 15:12
#Acquired=	28.05.2021 15:12:10
51.5961	23026.5
56.2453	23714.9
60.8921	20676.8
65.5367	16052.8
70.1768	12306.7
74.8167	9732.42
79.4543	7637.04
84.0897	6141.06
88.7227	5227.58
93.3513	4329.95
97.9798	3682.38
102.606	3129.68
107.23	2830.22
111.851	2634.94
116.469	2436.15
121.086	2837.48
125.7	4977.08
130.313	6638.91
134.921	4256.34
139.529	2469.25
144.134	2150.35
148.738	2081.54
153.337	1897.68
157.936	1757.51
162.532	1715.87
167.126	1772.42
171.716	1851.15
176.306	1982.74
180.894	2268.71
185.477	2675.89
190.06	3458.7
194.64	4659.96
199.219	6419.12
203.793	8256.32
208.367	8910.05
212.939	8129.15
217.506	6409.16
222.073	4741.95
226.638	3574.68
231.199	2784.93
235.759	2315.69
240.318	1978.56
244.872	1665.93
249.425	1557.23
253.977	1491.23
258.524	1604.2
263.071	2075.56
267.616	2287.42
272.156	1599.84
276.697	1141.46
281.233	997.831
285.769	971.096
290.303	931.752
294.832	918.336
299.361	867.325
303.886	829.583
308.411	876.743
312.934	841.798
317.452	839.729
321.97	826.398
326.484	822.078
330.998	809.238
335.507	835.791
340.017	847.88
344.524	829.792
349.027	921.114
353.53	1553.56
358.028	2266.3
362.527	1588
367.021	1040.84
371.515	942.67
376.004	909.857
380.494	908.558
384.979	925.019
389.465	951.763
393.946	991.769
398.427	1118.51
402.903	1428.75
407.38	1409.83
411.852	1027.78
416.324	1017.22
420.792	994.423
425.26	1019.91
429.723	1084.92
434.187	1119.38
438.646	1268.73
443.105	1505.2
447.56	1977.75
452.015	3004.83
456.466	5224.79
460.914	13327.8
465.362	25647.9
469.807	22538.5
474.251	10863.5
478.69	5357.79
483.13	3512.38
487.566	2691.61
491.999	2238.67
496.432	1916.32
500.861	1677.4
505.29	1479.99
509.715	1609.08
514.138	1624.79
518.56	1499.48
522.979	1346.99
527.395	1254.91
531.811	1209.28
536.223	1145.33
540.635	1138.09
545.042	1141.2
549.448	1113.06
553.853	1121.86
558.255	1084.73
562.654	1057.82
567.053	1013.57
571.448	1015.99
575.841	1044.83
580.232	1048.73
584.622	1022.18
589.009	1040.88
593.393	1053
597.777	1063.44
602.157	1020.73
606.535	1039.86
610.913	996.917
615.287	1020.96
619.659	1016.28
624.029	1033.7
628.398	1019.38
632.763	1049.5
637.127	998.115
641.488	995.164
645.849	1005.6
650.206	1017.95
654.561	1005.76
658.914	994.922
663.267	1008.64
667.615	1011.75
671.962	1007.86
676.307	1046.48
680.649	1021.91
684.991	1018.55
689.33	1060.89
693.666	1124.91
698	1189.98
702.332	1183.49
706.662	1099.72
710.992	1044.54
715.318	995.514
719.641	1023.01
723.963	1034.37
728.283	1053.35
732.6	1030.03
736.918	1001.95
741.231	1028.48
745.542	1026.66
749.852	1053.38
754.159	1015.44
758.464	1013.35
762.767	1043.8
767.068	1039.94
771.369	1045.58
775.666	1066.35
779.961	1074.72
784.254	1095.6
788.545	1165.9
792.834	1249.59
797.12	1298.13
801.405	1399.97
805.688	1550
809.968	1858.87
814.247	1642.41
818.524	1322.74
822.798	1164.63
827.071	1164.15
831.341	1129.63
835.612	1120.43
839.878	1097.9
844.142	1150.25
848.405	1156.95
852.665	1129.88
856.923	1127.09
861.18	1117.67
865.434	1136.66
869.686	1145.35
873.936	1107.64
878.185	1096.06
882.431	1152.14
886.675	1132.14
890.915	1181.27
895.155	1125.41
899.393	1130.35
903.63	1095.43
907.864	1117.54
912.096	1137.15
916.326	1136.85
920.554	1110.4
924.78	1103
929.004	1114.37
933.227	1061.54
937.447	1134.21
941.665	1072.5
945.881	1131.64
950.095	1072.08
954.305	1104.65
958.516	1109.58
962.724	1097.64
966.93	1079.46
971.134	1059.34
975.337	1104.15
979.537	1105.59
983.735	1117.84
987.93	1100.41
992.124	1103.21
996.316	1104.7
1000.51	1084.64
1004.7	1113.56
1008.88	1094.92
1013.06	1111.37
1017.25	1119.04
1021.43	1128.84
1025.61	1098.92
1029.78	1137.96
1033.96	1123.23
1038.13	1119.1
1042.3	1087.65
1046.47	1147.74
1050.63	1143.52
1054.8	1146.46
1058.96	1186.05
1063.12	1216.64
1067.28	1266.68
1071.44	1302.62
1075.59	1281.78
1079.74	1509.97
1083.89	1763.15
1088.04	1618.53
1092.19	1320.52
1096.33	1196.49
1100.48	1188.46
1104.62	1199.01
1108.76	1154.86
1112.89	1163.42
1117.03	1181.39
1121.16	1175.55
1125.29	1144.36
1129.42	1191.17
1133.55	1168.87
1137.68	1174.88
1141.8	1192.13
1145.92	1170.56
1150.04	1191.85
1154.16	1306.33
1158.27	1454.49
1162.39	1462.04
1166.5	1387.57
1170.61	1220.96
1174.72	1177.82
1178.82	1189.12
1182.93	1190.07
1187.03	1144.38
1191.13	1172.04
1195.23	1163.39
1199.33	1188.1
1203.42	1158.39
1207.51	1211
1211.6	1178.29
1215.69	1192.28
1219.78	1179.11
1223.86	1236.51
1227.95	1268.86
1232.03	1277.53
1236.11	1253.18
1240.18	1213.59
1244.26	1235.7
1248.33	1265.26
1252.41	1284.51
1256.48	1270.1
1260.54	1316.86
1264.61	1420.9
1268.67	1372.21
1272.74	1330.65
1276.8	1327.13
1280.86	1591.78
1284.91	3165.86
1288.97	2205.22
1293.02	1399.06
1297.07	1285.88
1301.12	1296.43
1305.17	1282.55
1309.21	1278.65
1313.25	1260.49
1317.3	1314.43
1321.34	1299.56
1325.37	1241.97
1329.41	1258.7
1333.44	1260.19
1337.48	1252.24
1341.5	1261.1
1345.53	1250.82
1349.56	1298.36
1353.59	1263.17
1357.61	1291.73
1361.63	1298.27
1365.65	1309.97
1369.66	1339.62
1373.68	1366.55
1377.69	1368.98
1381.7	1463.26
1385.72	2587.91
1389.72	4381.53
1393.73	2047.8
1397.73	1459.81
1401.74	1366.73
1405.74	1367.15
1409.73	1563.86
1413.73	1431.51
1417.73	1327.66
1421.72	1322.41
1425.71	1332.77
1429.7	1300
1433.69	1315.74
1437.67	1282.07
1441.66	1293.85
1445.64	1292.59
1449.62	1278.42
1453.6	1299.55
1457.57	1275.18
1461.55	1305.78
1465.52	1273.91
1469.49	1299.04
1473.46	1283.05
1477.43	1274.77
1481.39	1262.43
1485.36	1269.6
1489.32	1252.23
1493.28	1289.65
1497.24	1245.13
1501.19	1299.17
1505.15	1286.22
1509.1	1314.48
1513.05	1266.06
1517	1297.37
1520.95	1293.86
1524.9	1286.56
1528.84	1302.63
1532.78	1280.09
1536.72	1289.57
1540.66	1297.16
1544.6	1318.31
1548.53	1298.77
1552.46	1302.48
1556.4	1332.18
1560.32	1308.41
1564.25	1295.17
1568.18	1348.53
1572.1	1371.76
1576.02	1295.47
1579.94	1325.39
1583.86	1328.22
1587.78	1329.02
1591.69	1343.27
1595.61	1316.11
1599.52	1349.53
1603.43	1336.93
1607.34	1364.85
1611.24	1328.52
1615.15	1375.71
1619.05	1342.59
1622.95	1352.49
1626.85	1353.99
1630.74	1386.29
1634.64	1353.95
1638.53	1352.17
1642.42	1388.09
1646.31	1340.98
1650.2	1330.38
1654.09	1373.56
1657.97	1360.99
1661.86	1360.84
1665.74	1370.03
1669.62	1361.78
1673.49	1399.24
1677.37	1376.05
1681.24	1365.59
1685.12	1359.59
1688.99	1357.31
1692.86	1385.41
1696.72	1356.81
1700.59	1359.57
1704.45	1354.41
1708.31	1329.94
1712.17	1337.58
1716.03	1343.3
1719.89	1356.62
1723.74	1320.84
1727.6	1373.62
1731.45	1354.54
1735.3	1375.03
1739.14	1384.97
1742.99	1381.63
1746.83	1374.66
1750.68	1357.41
1754.52	1368.55
1758.36	1351.7
1762.19	1350.1
1766.03	1388.36
1769.86	1374.24
1773.69	1350.53
1777.53	1369.64
1781.35	1419.09
1785.18	1364.36
1789	1383.48
1792.83	1355.89
1796.65	1420.2
1800.47	1400.06
1804.29	1404.37
1808.1	1372.79
1811.92	1376.8
1815.73	1365.48
1819.54	1373.36
1823.35	1427.12
1827.16	1385.32
1830.97	1389.37
1834.77	1399.65
1838.58	1378.61
1842.38	1398.77
1846.18	1399.77
1849.97	1392.5
1853.77	1406.13
1857.56	1344.57
1861.36	1397.56
1865.15	1399.89
1868.93	1416.29
1872.72	1390.16
1876.51	1381.06
1880.29	1420.09
1884.07	1446.69
1887.86	1418.98
1891.63	1402.14
1895.41	1383.51
1899.19	1419.17
1902.96	1431.53
1906.73	1423.92
1910.5	1426.58
1914.27	1377.21
1918.04	1411.84
1921.8	1412.34
1925.57	1439.83
1929.33	1416.64
1933.09	1424.18
1936.85	1418.66
1940.6	1437.34
1944.36	1479.44
1948.11	1442.96
1951.87	1446.51
1955.61	1470.14
1959.36	1424.45
1963.11	1427.12
1966.86	1424.07
1970.6	1416.81
1974.34	1441.86
1978.08	1436.59
1981.82	1424.54
1985.56	1445.9
1989.29	1451.17
1993.02	1458.97
1996.75	1409.75
2000.49	1451.37
2004.21	1414.19
2007.94	1460.15
2011.67	1466.84
2015.39	1482.74
2019.11	1457.08
2022.83	1457.02
2026.55	1442.28
2030.27	1438.61
2033.98	1449.37
2037.69	1452.39
2041.41	1451.62
2045.12	1453.48
2048.82	1472.77
2052.53	1473.12
2056.24	1474.48
2059.94	1467.44
2063.64	1433.75
2067.34	1474.81
2071.04	1447.94
2074.74	1473.61
2078.43	1466.19
2082.13	1473.68
2085.82	1477.28
2089.51	1454.04
2093.2	1466.36
2096.88	1453.37
2100.57	1445.68
2104.25	1454.23
2107.94	1473.68
2111.62	1507.78
2115.3	1488.82
2118.97	1518.01
2122.65	1469.48
2126.32	1509.77
2129.99	1486.73
2133.66	1451.58
2137.33	1469.09
2141	1494.61
2144.67	1453.48
2148.33	1515.4
2151.99	1513.72
2155.66	1479.11
2159.31	1490.43
2162.97	1469
2166.63	1482.54
2170.28	1496.32
2173.94	1467.87
2177.59	1483.5
2181.24	1473.82
2184.89	1526.85
2188.53	1477.5
2192.18	1465.1
2195.82	1479.7
2199.46	1522.89
2203.1	1454.16
2206.74	1464.95
2210.38	1466.87
2214.01	1501.05
2217.65	1529.91
2221.28	1475.32
2224.91	1513.54
2228.54	1506.64
2232.16	1485.91
2235.79	1516.07
2239.41	1509.25
2243.04	1507.01
2246.66	1469.41
2250.28	1509.89
2253.89	1527.38
2257.51	1490.94
2261.12	1478.63
2264.74	1510.12
2268.35	1501.54
2271.96	1531.8
2275.57	1513.72
2279.17	1479.14
2282.78	1514.27
2286.38	1523.92
2289.98	1498.59
2293.58	1526.94
2297.18	1474.92
2300.78	1494.86
2304.37	1517.4
2307.97	1539.65
2311.56	1471.63
2315.15	1519.01
2318.74	1493.15
2322.33	1528.55
2325.91	1579.99
2329.5	1885.45
2333.08	1715.04
2336.66	1534.49
2340.24	1489.8
2343.82	1456.38
2347.4	1519.52
2350.97	1527.07
2354.54	1507.4
2358.12	1536.23
2361.69	1474.51
2365.26	1470.64
2368.82	1487.28
2372.39	1505.15
2375.95	1492.34
2379.52	1527.59
2383.08	1512.24
2386.64	1525.61
2390.19	1494.19
2393.75	1524.62
2397.31	1511.45
2400.86	1507.96
2404.41	1486.07
2407.96	1519.35
2411.51	1507.45
2415.06	1505.07
2418.6	1557.28
2422.15	1517.83
2425.69	1482.32
2429.23	1511.69
2432.77	1539.62
2436.31	1502.19
2439.84	1513.06
2443.38	1516.64
2446.91	1531.47
2450.44	1517.68
2453.97	1477.79
2457.5	1504.46
2461.03	1499.75
2464.55	1516.58
2468.08	1512.34
2471.6	1482.9
2475.12	1497.2
2478.64	1493.33
2482.16	1507.63
2485.67	1508.15
2489.19	1533.11
2492.7	1480.89
2496.21	1487.99
2499.72	1519.95
2503.23	1500.81
2506.74	1508.55
2510.25	1490.77
2513.75	1491.76
2517.25	1520.97
2520.75	1532.74
2524.25	1510.08
2527.75	1523.22
2531.25	1521.94
2534.74	1537.5
2538.24	1529.5
2541.73	1522.8
2545.22	1518.67
2548.71	1493.95
2552.2	1521.02
2555.68	1535.61
2559.17	1527.82
2562.65	1511.67
2566.13	1534.26
2569.61	1483.78
2573.09	1498.87
2576.57	1504.95
2580.04	1510.41
2583.51	1499.01
2586.99	1520.65
2590.46	1501.21
2593.93	1524.63
2597.4	1516.45
2600.86	1541.15
2604.33	1506.47
2607.79	1493.77
2611.25	1486.5
2614.71	1539.65
2618.17	1518.47
2621.63	1454.36
2625.09	1483.16
2628.54	1517.31
2631.99	1535.81
2635.45	1491.55
2638.9	1483.34
2642.34	1483.49
2645.79	1500.55
2649.24	1502.19
2652.68	1537.78
2656.12	1469.16
2659.56	1502.07
2663.01	1469.32
2666.44	1520.67
2669.88	1460.51
2673.32	1521.86
2676.75	1499.67
2680.18	1455.33
2683.61	1526.43
2687.04	1536.24
2690.47	1488.31
2693.9	1498.73
2697.32	1520
2700.75	1481.09
2704.17	1491.58
2707.59	1473.29
2711.01	1505.34
2714.43	1493.99
2717.84	1495.04
2721.26	1507.55
2724.67	1519.36
2728.08	1524.78
2731.49	1505.04
2734.9	1481.44
2738.31	1521.5
2741.71	1488.41
2745.12	1503.78
2748.52	1513.32
2751.92	1476.82
2755.32	1485.3
2758.72	1474.79
2762.12	1479.38
2765.52	1481.68
2768.91	1501.66
2772.3	1503.49
2775.7	1475.97
2779.09	1504.72
2782.47	1494.65
2785.86	1509.87
2789.25	1451.66
2792.63	1467.73
2796.01	1460.24
2799.4	1514.71
2802.78	1488.2
2806.15	1471.11
2809.53	1495.22
2812.91	1514.53
2816.28	1479.49
2819.65	1478.11
2823.03	1437.76
2826.4	1462.03
2829.76	1469.6
2833.13	1486.67
2836.5	1470.48
2839.86	1486.22
2843.22	1492
2846.59	1495.34
2849.95	1455.4
2853.3	1469.87
2856.66	1471.11
2860.02	1466.94
2863.37	1470.44
2866.72	1443.06
2870.08	1479.45
2873.43	1449.11
2876.77	1428.07
2880.12	1470.96
2883.47	1469.59
2886.81	1465.27
2890.15	1472.23
2893.5	1492.35
2896.84	1463.92
2900.17	1480.64
2903.51	1478.22
2906.85	1449.12
2910.18	1470.05
2913.52	1485.18
2916.85	1482.23
2920.18	1481.9
2923.51	1453.12
2926.83	1466.76
2930.16	1471.67
2933.48	1485.85
2936.81	1463.92
2940.13	1469.38
2943.45	1466.34
2946.77	1494.43
2950.09	1461.37
2953.4	1456.51
2956.72	1462.04
2960.03	1491.27
2963.34	1462.42
2966.65	1447.76
2969.96	1448.55
2973.27	1496.5
2976.58	1424.44
2979.88	1464.25
2983.19	1451.35
2986.49	1442.3
2989.79	1447.4
2993.09	1445.05
2996.39	1468.14
2999.68	1512.94
3002.98	1470.31
3006.27	1440.82
3009.57	1472.6
3012.86	1494.12
3016.15	1463.88
3019.43	1462.8
3022.72	1475.83
3026.01	1465.29
3029.29	1471.76
3032.57	1444.2
3035.86	1492.15
3039.14	1495.66
3042.41	1440.52
3045.69	1481.92
3048.97	1438.12
3052.24	1479.56
3055.52	1484.12
3058.79	1452.57
3062.06	1471.75
3065.33	1462.71
3068.6	1466.76
3071.86	1488.52
3075.13	1481.48
3078.39	1507.23
3081.65	1471.83
3084.91	1456.64
3088.17	1440.4
3091.43	1529.99
3094.69	1500.02
3097.95	1501.39
3101.2	1468.54
3104.45	1480.1
3107.7	1470.47
3110.95	1532.96
3114.2	1515.02
3117.45	1516.26
3120.7	1530.87
3123.94	1534.06
3127.18	1470.53
3130.43	1548.91
3133.67	1550.14
3136.91	1558.96
3140.14	1523.84
3143.38	1543.99
3146.61	1564.15
3149.85	1554.86
3153.08	1561.81
3156.31	1576.32
3159.54	1535.55
3162.77	1612.08
3166	1582.7
3169.22	1614.25
3172.45	1610.37
3175.67	1584.48
3178.89	1608.07
3182.11	1573.45
3185.33	1618.98
3188.55	1607.1
3191.77	1629.5
3194.98	1649.02
3198.2	1649.44
3201.41	1652.7
3204.62	1629.36
3207.83	1646.06
3211.04	1653.32
3214.25	1639.76
3217.45	1631.07
3220.66	1669
3223.86	1671.79
3227.06	1651.91
3230.26	1688.2
3233.46	1711.31
3236.66	1726.69
3239.85	1720.56
3243.05	1733.58
3246.24	1687.62
3249.44	1724.55
3252.63	1715.92
3255.82	1737.85
3259.01	1667.18
3262.19	1729.89
3265.38	1714.07
3268.56	1745.77
3271.75	1698.96
3274.93	1780.06
3278.11	1725.48
3281.29	1774.65
3284.47	1732.78
3287.64	1729.16
3290.82	1714.9
3293.99	1738.91
3297.17	1774.27
3300.34	1698.22
3303.51	1775.88
3306.68	1738.84
3309.84	1742.56
3313.01	1712.75
3316.18	1780.68
3319.34	1769.71
3322.5	1818.41
3325.66	1778.97
3328.82	1743.39
3331.98	1810.02
3335.14	1768.03
3338.29	1783.85
3341.45	1816.75
3344.6	1781.77
3347.75	1786.86
3350.9	1766.93
3354.05	1795.05
3357.2	1822.43
3360.35	1825.41
3363.49	1804.08
3366.64	1820.52
3369.78	1862.53
3372.92	1816.89
3376.06	1868.66
3379.2	1862.01
3382.34	1877.17
3385.48	1851.61
3388.61	1875.37
3391.75	1876.46
3394.88	1845.27
3398.01	1882.74
3401.14	1880.53
3404.27	1884.17
3407.4	1926.95
3410.52	1917.63
3413.65	1942.49
3416.77	1867.85
3419.89	1902.62
3423.01	1926.76
3426.13	1870.34
3429.25	1877.52
3432.37	1906.41
3435.49	1914.85
3438.6	1908.53
3441.72	1915.81
3444.83	1907.77
3447.94	1933.68
3451.05	1904.23
3454.16	1871.67
3457.26	1909.56
3460.37	1904.31
3463.47	1887.63
3466.58	1857.57
3469.68	1882.32
3472.78	1869.73
3475.88	1883.31
3478.98	1845.86
3482.07	1851.11
3485.17	1796.86
3488.26	1828.75
3491.36	1825.96
3494.45	1800.08
3497.54	1748.68
3500.63	1795.27
3503.72	1780.59
3506.81	1797.67
3509.89	1785.53
3512.98	1721.07
3516.06	1732.29
3519.14	1717.62
3522.22	1676.41
3525.3	1656.11
3528.38	1687.77
3531.45	1642.22
3534.53	1661.43
3537.61	1597.72
3540.68	1609.69
3543.75	1612.92
3546.82	1603.61
3549.89	1569.92
3552.96	1567.93
3556.03	1555.4
3559.09	1548.79
3562.16	1530.83
3565.22	1542.84
3568.28	1509.13
3571.34	1496.74
3574.4	1494.05
3577.46	1465.82
3580.52	1462.12
3583.57	1476.33
3586.63	1414.52
3589.68	1430.47
3592.73	1408.32
3595.78	1403.2
3598.83	1427.33
3601.88	1402.19
3604.93	1397.74
3607.97	1397.93
3611.02	1347.03
3614.06	1351.88
3617.1	1380.29
3620.14	1360.58
3623.18	1350.38
3626.22	1314.79
3629.26	1331.14
3632.3	1325.74
3635.33	1330.63
3638.36	1295.38
3641.4	1313.96
3644.43	1258.35
3647.46	1280.23
3650.49	1260.35
3653.51	1288.64
3656.54	1234.43
3659.57	1272.34
3662.59	1235.81
3665.61	1231.97
3668.63	1226.61
3671.65	1242.28
3674.67	1218.41
3677.69	1204.96
3680.71	1140.56
3683.72	1163.91
3686.74	1151.36
3689.75	1168.18
3692.76	1156.64
3695.77	1170.68
3698.78	1146.58
3701.79	1133.14
3704.79	1152.91
3707.8	1139.44
3710.81	1137.23
3713.81	1145.38
3716.81	1136.28
3719.81	1122.49
3722.81	1110.45
3725.81	1134.49
3728.81	1089.88
3731.8	1131.84
3734.8	1111.79
3737.79	1102.09
3740.78	1110.38
3743.77	1112.83
3746.76	1091.4
3749.75	1082.24
3752.74	1107.21
3755.73	1060.93
3758.71	1111.51
3761.7	1087.09
3764.68	1102.4
3767.66	1068.49
3770.64	1081.07
3773.62	1087.11
3776.6	1102.69
3779.58	1104.14
3782.55	1084.88
3785.53	1056.2
3788.5	1079.53
3791.47	1067.99
3794.44	1076.44
3797.41	1084.04
3800.38	1090.77
3803.35	1077.81
3806.32	1092.29
3809.28	1045.41
3812.24	1082.67
3815.21	1067.04
3818.17	1051.43
3821.13	1061.39
3824.09	1078.03
3827.04	1041.7
3830	1052.74
3832.96	1070.43
3835.91	1023.7
3838.86	1051.99
3841.82	1028.05
3844.77	1062.09
3847.72	1041.94
3850.67	1039.91
3853.61	1063.68
3856.56	1042.66
3859.5	1058.86
3862.45	1041.65
3865.39	1033.9
3868.33	1029.02
3871.27	1022.13
3874.21	1010.4
3877.15	1056.19
3880.09	1015.49
3883.02	1032.29
3885.96	1034.56
3888.89	1019.45
3891.82	1001.41
3894.75	1023.69
3897.68	1016.04
3900.61	1015
3903.54	1021.63
3906.47	1009.86
3909.39	1028.97
3912.31	1058.55
3915.24	1005.39
3918.16	999.263
3921.08	1027.88
3924	988.127
3926.92	1031.76
3929.83	987.04
3932.75	1008.44
3935.67	995.586
3938.58	961.877
3941.49	988.676
3944.4	1020.17
3947.31	982.773
3950.22	1020.16
3953.13	980.07
3956.04	1023.33
3958.94	980.483
3961.85	978.864
3964.75	1005.09
3967.65	1004.54
3970.55	989.655
3973.45	1006.46
3976.35	994.443
3979.25	972.743
3982.15	998.055
3985.04	984.909
3987.94	989.978
3990.83	961.352
3993.72	1030.72
3996.61	955.009
3999.5	999.552
4002.39	947.891
4005.28	965.556
4008.16	983.284
4011.05	956.697
4013.93	947.433
4016.81	957.463
4019.7	975.221
4022.58	958.231
4025.46	959.584
4028.33	985.115
4031.21	953.638
4034.09	967.615
4036.96	965.165
4039.84	936.618
4042.71	924.48
4045.58	974.181
4048.45	962.906
4051.32	941.978
4054.19	927.873
4057.05	943.934
4059.92	948.321
4062.78	954.62
4065.65	956.068
4068.51	921.526
4071.37	927.804
4074.23	917.533
4077.09	957.877
4079.95	900.81
4082.81	922.648
4085.66	897.702
4088.52	901.956
4091.37	914.997
4094.22	919.326
4097.07	906.979
4099.92	908.355
4102.77	904.822
4105.62	930.596
4108.47	924.966
4111.31	898.797
4114.16	931.232
4117	923.45
4119.84	898.897
4122.69	903.72
4125.53	912.566
4128.36	934.16
4131.2	935.458
4134.04	904.572
4136.88	908.237
4139.71	896.058
4142.54	905.611
4145.38	907.498
4148.21	892.134
4151.04	892.497
4153.87	895.592
4156.69	881.715
4159.52	906.616
4162.35	883.89
4165.17	876.939
4168	913.987
4170.82	888.482
4173.64	888.457
4176.46	881.61
4179.28	872.808
4182.1	859.188
4184.91	879.829
4187.73	876.071
4190.54	877.226
4193.36	894.181
4196.17	860.322
4198.98	900.045
4201.79	876.05
4204.6	874.631
4207.41	895.751
4210.22	870.75
4213.02	850.602
4215.83	855.989
4218.63	878.635
4221.44	871.71
4224.24	851.865
4227.04	877.286
4229.84	843.606
4232.64	858.368
4235.43	881.199
4238.23	831.729
4241.02	897.363
4243.82	831.916
4246.61	865.933
4249.4	820.211
4252.19	849.176
4254.98	847.197
4257.77	830.121
4260.56	844.054
4263.35	870.093
4266.13	847.021
4268.92	833.001
4271.7	809.873
4274.48	822.946
4277.26	851.013
4280.04	818.422
4282.82	848.374
4285.6	857.042
4288.38	836.268
4291.15	841.699
4293.93	844.059
4296.7	832.356
4299.47	820.707
4302.25	824.181
4305.02	803.29
4307.79	810.807
4310.55	834.628
4313.32	832.127
4316.09	801.003
4318.85	811.495
4321.62	775.115
4324.38	801.772
4327.14	815.162
4329.9	803.124
4332.66	816.457
4335.42	802.336
4338.18	808.506
4340.94	795.473
4343.69	825.252
4346.45	818.425
4349.2	761.671
4351.95	778.366
4354.7	784.06
4357.45	782.513
4360.2	759.485
4362.95	789.602
4365.7	762.483
4368.44	787.524
4371.19	775.762
4373.93	798.725
4376.68	811.427
4379.42	740.892
4382.16	802.8
4384.9	776.431
4387.64	799.57
4390.37	774.685
4393.11	763.268
4395.85	761.712
4398.58	780.256
4401.31	794.667
4404.05	759.273
4406.78	742.52
4409.51	773.554
4412.24	773.362
4414.96	774.095
4417.69	737.279
4420.42	782.464
4423.14	787.17
4425.87	757.474
4428.59	760.131
4431.31	745.015
4434.03	737.185
4436.75	785.849
4439.47	755.956
4442.19	746.917
4444.91	765.159
4447.62	749.789
4450.34	732.306
4453.05	721.042
4455.76	732.875
4458.47	734.134
4461.19	730.106
4463.89	740.896
4466.6	764.298
4469.31	710.937
4472.02	749.167
4474.72	730.612
4477.43	731.078
4480.13	725.273
4482.83	742.73
4485.53	720.061
4488.23	687.784
4490.93	699.87
4493.63	719.203
4496.33	715.139
4499.02	720.74
4501.72	718.888
4504.41	690.479
4507.11	718.314
4509.8	718.615
4512.49	736.959
4515.18	714.996
4517.87	706.84
4520.56	702.958
4523.24	690.64
4525.93	712.351
4528.61	691.49
4531.3	718.565
4533.98	712.646
4536.66	671.539
4539.34	681.642
4542.02	723.855
4544.7	710.525
4547.38	674.726
4550.05	691.356
4552.73	678.068
4555.4	688.481
4558.08	692.576
4560.75	681.821
4563.42	680.856
4566.09	668.221
4568.76	699.027
4571.43	682.876
4574.1	673.522
4576.77	682.334
4579.43	668.674
4582.1	659.627
4584.76	660.477
4587.42	688.193
4590.08	677.737
4592.74	649.74
4595.4	658.876
4598.06	673.565
4600.72	671.808
4603.38	640.636
4606.03	674.068
4608.69	675.778
4611.34	674.212
4613.99	640.77
4616.64	657.822
4619.29	658.437
4621.94	652.483
4624.59	639.877
4627.24	631.61
4629.89	667.466
4632.53	634.844
4635.18	665.107
4637.82	643.362
4640.46	640.402
4643.1	615.297
4645.74	642.404
4648.38	628.67
4651.02	643.952
4653.66	633.921
4656.3	621.346
4658.93	629.265
4661.57	635.425
4664.2	626.068
4666.83	649.026
4669.46	630.473
4672.09	622.025
4674.72	639.323
4677.35	624.118
4679.98	627.957
4682.61	644.139
4685.23	606.394
4687.86	615.836
4690.48	637.685
4693.1	604.376
4695.73	613.803
4698.34	608.569
4700.96	624.789
4703.58	617.289
4706.2	609.724
4708.82	610.047
4711.43	625.054
4714.05	600.452
4716.66	634.684
4719.28	594.15
4721.89	614.757
4724.5	597.941
4727.11	568.721
4729.72	610.989
4732.33	616.979
4734.93	621.842
4737.54	598.276
4740.14	593.978
4742.75	581.694
4745.35	596.657
4747.95	589.964
4750.55	587.737
4753.15	617.393
4755.75	586.72
4758.35	610.675
4760.95	583.465
4763.54	602.974
4766.14	573.55
4768.73	585.263
4771.33	597.037
4773.92	577.893
4776.51	578.149
4779.1	602.39
4781.69	568.378
4784.28	559.487
4786.87	591.761
4789.45	585.17
4792.04	568.295
4794.63	536.537
4797.21	568.935
4799.79	581.939
4802.37	549.098
4804.95	564.489
4807.53	545.491
4810.11	563.323
4812.69	544.322
4815.27	551.837
4817.84	582.499
4820.42	553.167
4822.99	543.436
4825.57	534.85
4828.14	543.637
4830.71	544.322
4833.28	555.536
4835.85	549.326
4838.42	559.504
4840.98	546.389
4843.55	543.742
4846.12	563.265
4848.68	552.26
4851.24	552.806
4853.81	550.632
4856.37	557.963
4858.93	549.368
4861.49	531.276
4864.05	543.683
4866.61	542.927
4869.16	548.119
4871.72	562.914
4874.27	536.132
4876.83	516.362
4879.38	545.209
4881.93	508.759
4884.49	515
4887.04	536.697
4889.58	532.266
4892.13	527.832
4894.68	534.088
4897.23	508.164
4899.77	542.993
4902.32	551.606
4904.86	522.038
4907.4	536.586
4909.95	515.302
4912.49	497.473
4915.03	517.826
4917.57	493.932
4920.1	517.877
4922.64	531.072
4925.18	521.574
4927.71	536.012
4930.25	484.648
4932.78	497.957
4935.31	518.551
4937.84	502.006
4940.38	502.199
4942.9	502.167
4945.43	501.127
4947.96	503.762
4950.49	526.755
4953.01	500.651
4955.54	504.45
4958.06	485.54
4960.59	488.267
4963.11	506.672
4965.63	472.307
4968.15	496.988
4970.67	486.603
4973.19	495.489
4975.71	514.042
4978.22	489.086
4980.74	478.635
4983.25	491.183
4985.77	490.436
4988.28	506.69
4990.79	498.69
4993.3	477.276
4995.81	491.106
4998.32	494.082