File: Data/3-Raman/raw/bu19w-ff1-fi08-v_150 (500nm)_532nm_edge_100%_x100_vis_h50um_15sx2_01.txt
#Acq. time (s)=	15
#Accumulations=	2
#Range (cm-¹)=	100...5000
#Windows=	1
#Auto scanning=	Off
#Autofocus=	Off
#Macrospot=	Off
#AutoExposure=	Off
#Spike filter=	Multiple accum.
#Delay time (s)=	2
#Binning=	1
#Readout mode=	Signal
#DeNoise=	Off
#ICS correction=	On
#Dark correction=	Off
#Inst. Process=	Off
#Detector Gain=	Best Dynamic
#Detector ADC=	50 kHz HS
#Detector temperature (°C)=	-60.09
#Instrument=	LabRAM HR Evol
#Detector=	SIN-EM FIVIS
#Objective=	x100_VIS
#Grating=	150 (500nm)
#ND Filter=	100%
#Laser=	532nm_Edge
#Hole=	49.98
#Temperature=	0
#Range=	Visible
#StageXY=	75x50mm Scan+
#StageZ=	Z motor
#X (µm)=	0
#Y (µm)=	0
#Z (µm)=	-193.5
#Full time(s)=	34
#Project=	21_05_14
#Sample=	BU19w
#Site=
#Title=	BU19w-FF1-FI08-V_150 (500nm)_532nm_Edge_100%_x100_VIS_H50um_15sX2
#Remark=
#Date=	14.05.2021 16:09
#Acquired=	14.05.2021 16:09:27
102.699	1420.26
107.322	1405.22
111.942	1318.1
116.56	1231.09
121.173	1295.12
125.787	1243.25
130.398	1263.68
135.006	1253.32
139.613	1197.74
144.215	1181.63
148.817	1255.12
153.417	1640.26
158.014	2333.89
162.607	2011.6
167.2	1440.11
171.79	1327.03
176.379	1498.04
180.963	2579.3
185.547	4385.9
190.128	3428.14
194.705	1944.37
199.282	1345
203.857	1238.47
208.43	1195.58
212.998	1232.2
217.566	1180.77
222.132	1161.12
226.693	1240.22
231.254	1437.54
235.813	1504.04
240.368	1836.03
244.923	2172.36
249.475	2026.54
254.023	1760.56
258.571	1474.34
263.117	1486.4
267.658	1769.04
272.199	2966.97
276.738	4392.3
281.273	3749.05
285.807	2398.91
290.34	1860.71
294.868	1912.88
299.396	2626.29
303.919	2718.4
308.443	2011.32
312.964	1578.64
317.481	1535.86
321.998	1681.13
326.51	1947
331.023	1935.14
335.533	1652.29
340.039	1508.83
344.544	1655.6
349.046	1771.46
353.547	1678.86
358.045	1430.71
362.542	1419.54
367.036	1463.67
371.527	1424.88
376.017	1363.51
380.503	1462.97
384.99	1637.24
389.471	1812.43
393.953	2012.48
398.43	1874.09
402.908	1631.79
407.381	1590.92
411.854	1981.76
416.323	2344.6
420.791	1863.13
425.256	1413.63
429.72	1340.84
434.18	1259.65
438.64	1262.41
443.095	1331.01
447.551	1514.36
452.003	2002.02
456.454	2094.08
460.901	1713.89
465.348	1432.1
469.791	1326.52
474.231	1390.01
478.672	1393.96
483.108	1442.52
487.544	1583.43
491.976	1679.97
496.408	1721.86
500.836	1646.63
505.261	1519.11
509.687	1408.73
514.108	1357.52
518.529	1347.98
522.946	1355.35
527.361	1365.1
531.776	1376.45
536.187	1430.76
540.595	1435.28
545.003	1454.84
549.408	1443.13
553.812	1531.78
558.212	1524.28
562.61	1502.64
567.007	1432.64
571.401	1336.38
575.792	1408.78
580.184	1614.61
584.571	2052.7
588.956	2361.11
593.341	2012.32
597.722	1700.15
602.101	1686.6
606.48	2014.31
610.854	2175.62
615.227	1937.32
619.597	1573.52
623.967	1419.31
628.334	1367.35
632.698	1392.19
637.06	1456.71
641.422	1472.15
645.779	1494.8
650.135	1409.5
654.491	1462.57
658.842	1537.29
663.192	1648.14
667.539	1737.73
671.884	1827.34
676.23	1880.26
680.571	1765.47
684.91	1554.92
689.247	1427.7
693.583	1358.82
697.916	1349.29
702.247	1322.81
706.576	1268.41
710.902	1306.61
715.229	1271.06
719.551	1319.27
723.872	1286.36
728.19	1315.46
732.506	1316.2
736.82	1322.09
741.134	1363.3
745.444	1372.86
749.752	1335.86
754.058	1427.92
758.362	1459.73
762.664	1543.26
766.964	1709.91
771.264	1940.97
775.559	2341.67
779.853	2389.16
784.144	2101.25
788.434	1838.69
792.722	1637.23
797.007	1534.68
801.29	1476.46
805.572	1426.74
809.851	1423.46
814.13	1393.03
818.406	1366.88
822.679	1376.32
826.95	1370.54
831.219	1382.46
835.486	1405.33
839.752	1434.73
844.015	1405.37
848.276	1408.07
852.535	1363.24
856.792	1376.87
861.047	1389.23
865.3	1456.09
869.551	1360.96
873.8	1372.12
878.047	1389.59
882.292	1378.02
886.534	1374.61
890.775	1407.99
895.014	1395.84
899.251	1411.08
903.486	1422.05
907.719	1401.97
911.95	1438.15
916.179	1422.06
920.406	1464.32
924.63	1454.9
928.853	1474.53
933.074	1527.57
937.293	1554.24
941.51	1597.75
945.723	1735.84
949.936	1775.91
954.147	1768.16
958.356	1774.49
962.563	1843.7
966.768	1844.98
970.971	1780.99
975.172	1706.62
979.371	1612.65
983.568	1542.16
987.761	1550.82
991.954	1524.51
996.145	1555.55
1000.33	1540.43
1004.52	1568.99
1008.71	1549.07
1012.89	1553.01
1017.07	1570.78
1021.25	1642.96
1025.43	1621.43
1029.6	1739.87
1033.77	1775.38
1037.95	1876.21
1042.11	2140.95
1046.28	2678.27
1050.45	3331.9
1054.61	3321.15
1058.77	2742.63
1062.93	2223.99
1067.09	2108.2
1071.24	2092.99
1075.4	2168.02
1079.55	2450.36
1083.7	3039.49
1087.85	3574.66
1091.99	3638.03
1096.14	3181.36
1100.28	2964.97
1104.42	3172.84
1108.55	3450.6
1112.69	3309.24
1116.82	2949.61
1120.96	2739.87
1125.09	2816.18
1129.21	2904.68
1133.34	2866.75
1137.46	2557.71
1141.59	2295.97
1145.71	2176.18
1149.83	2355.92
1153.94	2651.14
1158.06	2762.58
1162.17	2504.42
1166.28	2231.45
1170.39	2131.06
1174.5	1957.13
1178.6	1868.83
1182.7	1778.58
1186.8	1763.2
1190.9	1756.56
1195	1813.79
1199.1	1823.22
1203.19	1763.21
1207.28	1738.02
1211.37	1728.26
1215.46	1803.29
1219.54	1907.45
1223.63	1962.11
1227.71	1872.16
1231.79	1861.22
1235.87	1948.58
1239.95	2013.05
1244.02	1948.97
1248.09	1811.45
1252.16	1765.2
1256.23	1742.21
1260.3	1725.45
1264.36	1664.9
1268.43	1850.11
1272.49	2083.94
1276.55	1876.35
1280.6	1714.44
1284.66	1671.45
1288.71	1654.52
1292.76	1618.04
1296.81	1664.08
1300.86	1612.09
1304.91	1631.36
1308.95	1661.79
1312.99	1639.23
1317.03	1703.75
1321.07	1663.32
1325.11	1621.03
1329.14	1661.52
1333.18	1703.24
1337.21	1691.39
1341.24	1681.38
1345.26	1744.11
1349.29	1713.05
1353.31	1697.07
1357.33	1749.6
1361.35	1766.24
1365.37	1764.56
1369.39	1766.04
1373.4	2145.77
1377.41	2396.8
1381.43	1949.12
1385.43	1735.96
1389.44	1718.95
1393.45	1702.68
1397.45	1767.5
1401.45	1776.81
1405.45	1700.61
1409.45	1661.96
1413.44	1707.24
1417.44	1722.91
1421.43	1679.24
1425.42	1722.87
1429.41	1728.4
1433.39	1707.73
1437.38	1747.01
1441.36	1728.1
1445.34	1726.59
1449.32	1713.19
1453.3	1697.46
1457.27	1718.08
1461.24	1761.78
1465.22	1731.26
1469.19	1735.37
1473.15	1737.57
1477.12	1754.09
1481.09	1760.67
1485.05	1741.69
1489.01	1753.99
1492.97	1725.46
1496.93	1741.86
1500.88	1751.71
1504.83	1733.74
1508.79	1779.31
1512.74	1746.19
1516.68	1751.13
1520.63	1736.83
1524.57	1758.52
1528.52	1746.47
1532.46	1776.24
1536.4	1782.75
1540.33	1780.6
1544.27	1765.83
1548.2	1767.56
1552.14	1788.54
1556.07	1803.41
1559.99	1842.24
1563.92	1797.65
1567.84	1813.86
1571.77	1798.09
1575.69	1792.93
1579.61	1777.09
1583.52	1809.38
1587.44	1793.36
1591.35	1795.63
1595.27	1817.1
1599.18	1832.85
1603.09	1782.61
1606.99	1803.58
1610.9	1840.86
1614.8	1835.22
1618.7	1827.75
1622.6	1814.57
1626.5	1850.56
1630.39	1855.35
1634.29	1814.51
1638.18	1868.51
1642.07	1828.29
1645.96	1897.52
1649.85	1830.76
1653.73	1854.09
1657.62	1873.45
1661.5	1812.87
1665.38	1882.65
1669.26	1866.54
1673.13	1865.39
1677.01	1860.87
1680.88	1906.35
1684.75	1870.03
1688.62	1881.42
1692.49	1881.89
1696.35	1880.18
1700.22	1891.46
1704.08	1899.43
1707.94	1912.67
1711.8	1903.86
1715.66	1906.55
1719.51	1887.56
1723.37	1935.5
1727.22	1903.96
1731.07	1934.42
1734.92	1947.91
1738.76	1910.59
1742.61	1859.44
1746.45	1930.11
1750.29	1874.36
1754.13	1868.72
1757.97	1900.59
1761.81	1923.17
1765.64	1930.13
1769.47	1919.73
1773.31	1945.06
1777.14	1942.8
1780.96	1933.63
1784.79	1920.91
1788.61	1922.33
1792.43	1915.36
1796.25	1941.22
1800.07	1925.95
1803.89	1940.04
1807.71	1914.49
1811.52	1963.09
1815.33	1961.09
1819.14	1948.94
1822.95	1951.5
1826.76	1986.61
1830.56	1988.15
1834.37	1955.38
1838.17	1940.24
1841.97	1952.92
1845.77	1960.81
1849.56	1959.89
1853.36	1989.98
1857.15	1980.22
1860.94	1992.44
1864.73	1995.36
1868.52	1992.94
1872.31	1988.08
1876.09	1979.82
1879.87	1972.12
1883.66	1984.22
1887.43	2004.97
1891.21	2009.38
1894.99	1946.47
1898.76	1977.94
1902.53	1989.81
1906.31	2030.49
1910.08	2008.14
1913.84	2020.32
1917.61	1986.18
1921.37	1982.26
1925.14	2055.52
1928.9	1995.53
1932.66	2017.26
1936.41	2038.07
1940.17	2015.9
1943.92	2006.22
1947.68	1995.69
1951.43	2062.29
1955.18	2018.12
1958.92	2036.77
1962.67	2061.81
1966.41	2050.92
1970.16	2086.84
1973.9	2053.87
1977.64	2063.62
1981.37	2086.12
1985.11	2066.18
1988.84	2038.68
1992.57	2056.36
1996.31	2108.91
2000.03	2086.84
2003.76	2098.46
2007.49	2123.08
2011.21	2073.86
2014.93	2064.89
2018.65	2047.28
2022.37	2104.82
2026.09	2079.17
2029.81	2087.93
2033.52	2073.98
2037.23	2030.14
2040.94	2055.08
2044.65	2062.32
2048.36	2076.42
2052.07	2099.05
2055.77	2101.9
2059.47	2119.32
2063.17	2064.89
2066.87	2127.45
2070.57	2086.99
2074.27	2104.65
2077.96	2137.42
2081.65	2136.85
2085.34	2083.89
2089.03	2147.92
2092.72	2153.61
2096.41	2111.39
2100.09	2148.97
2103.77	2147.15
2107.46	2157.96
2111.14	2149.05
2114.81	2127.06
2118.49	2137.89
2122.16	2181.27
2125.84	2145.59
2129.51	2138.3
2133.18	2167.96
2136.85	2185.24
2140.51	2163.33
2144.18	2133.92
2147.84	2134.87
2151.5	2163.35
2155.16	2167.14
2158.82	2188.42
2162.48	2180.8
2166.13	2116.1
2169.79	2195.18
2173.44	2194.01
2177.09	2225.77
2180.74	2164.92
2184.38	2200.53
2188.03	2174.41
2191.67	2200.91
2195.32	2184.54
2198.96	2182.93
2202.6	2181.64
2206.23	2208.12
2209.87	2189.28
2213.5	2188.9
2217.14	2212.43
2220.77	2169.02
2224.4	2172.43
2228.03	2184.01
2231.65	2195.84
2235.28	2234.6
2238.9	2230.72
2242.52	2226.8
2246.14	2248.86
2249.76	2221.89
2253.38	2158.68
2256.99	2177.53
2260.6	2206.53
2264.21	2172.75
2267.82	2186.31
2271.44	2241.31
2275.04	2213.58
2278.65	2219.81
2282.25	2181.52
2285.85	2177.65
2289.45	2239.57
2293.05	2220.12
2296.65	2204.57
2300.25	2235.26
2303.84	2223.75
2307.43	2189.1
2311.02	2206.29
2314.62	2261.01
2318.2	2320.94
2321.79	2299.34
2325.38	2260.67
2328.96	2242.01
2332.54	2249.36
2336.12	2243.27
2339.7	2263.22
2343.28	2266.91
2346.85	2217.85
2350.43	2313.85
2354	2235.7
2357.57	2290.95
2361.14	2261.26
2364.71	2277.24
2368.27	2273.15
2371.84	2262.87
2375.4	2281.94
2378.96	2288.32
2382.52	2306.9
2386.08	2254.03
2389.64	2280.7
2393.19	2278.55
2396.75	2263.42
2400.3	2272.22
2403.85	2257.12
2407.4	2261.69
2410.95	2292.91
2414.49	2246.5
2418.04	2285.11
2421.58	2271.72
2425.12	2205.39
2428.66	2262.24
2432.2	2263.27
2435.74	2259.11
2439.27	2236.47
2442.81	2293.12
2446.34	2268.95
2449.87	2254.52
2453.4	2294.84
2456.93	2356.8
2460.45	2346.22
2463.98	2312.11
2467.5	2312.58
2471.02	2307.86
2474.54	2323.69
2478.06	2305.47
2481.58	2376.33
2485.09	2298.01
2488.61	2365.49
2492.12	2326.09
2495.63	2306.78
2499.14	2301
2502.65	2242.95
2506.15	2338.7
2509.66	2304.49
2513.16	2361.02
2516.66	2347.35
2520.16	2333.54
2523.66	2301.6
2527.16	2300.43
2530.66	2285.72
2534.15	2395.36
2537.64	2330.09
2541.13	2294.41
2544.62	2333.8
2548.11	2335.57
2551.6	2345.1
2555.08	2306.91
2558.57	2351.17
2562.05	2349.1
2565.53	2361.8
2569.01	2378.03
2572.49	2330.22
2575.96	2333.34
2579.44	2303.72
2582.91	2312.75
2586.38	2354.69
2589.85	2289.2
2593.32	2325.4
2596.79	2332.83
2600.25	2369.18
2603.72	2336.56
2607.18	2349.13
2610.64	2344.82
2614.1	2329.03
2617.56	2402.7
2621.02	2350.99
2624.47	2353.35
2627.92	2362.04
2631.38	2332.79
2634.83	2326.8
2638.28	2339.55
2641.72	2390.9
2645.17	2360.82
2648.61	2404.74
2652.06	2347.92
2655.5	2369.59
2658.94	2380.46
2662.38	2351.25
2665.82	2375
2669.25	2396.46
2672.69	2356.2
2676.12	2379.2
2679.55	2344.62
2682.98	2363.01
2686.41	2359.49
2689.84	2369.58
2693.26	2342.65
2696.69	2344.14
2700.11	2349.73
2703.53	2337.08
2706.95	2417.41
2710.37	2344.01
2713.79	2372.47
2717.2	2349.29
2720.62	2377.73
2724.03	2387.74
2727.44	2380.27
2730.85	2374.5
2734.26	2359.33
2737.66	2360.09
2741.07	2394.22
2744.47	2305.78
2747.87	2345.09
2751.28	2387.22
2754.67	2365.83
2758.07	2413.49
2761.47	2379.46
2764.86	2403.5
2768.26	2384.62
2771.65	2392.93
2775.04	2376.34
2778.43	2444.12
2781.82	2374.19
2785.2	2354.08
2788.59	2435.5
2791.97	2353.11
2795.35	2423.18
2798.73	2362.17
2802.11	2361.28
2805.49	2403.47
2808.87	2396.78
2812.24	2378.77
2815.62	2437.17
2818.99	2373.52
2822.36	2454.04
2825.73	2345.34
2829.1	2410.35
2832.46	2370.5
2835.83	2371.11
2839.19	2347.95
2842.55	2407.26
2845.91	2402.09
2849.27	2356.98
2852.63	2413.06
2855.99	2358.26
2859.34	2362.7
2862.69	2382.22
2866.05	2426.31
2869.4	2396.11
2872.75	2407.12
2876.09	2395.49
2879.44	2413.01
2882.78	2408.67
2886.13	2367.33
2889.47	2425.28
2892.81	2422.09
2896.15	2393.98
2899.49	2416.55
2902.82	2434.98
2906.16	2397.4
2909.49	2447.55
2912.82	2418.2
2916.16	2432.87
2919.49	2422.75
2922.81	2432.43
2926.14	2458.62
2929.46	2451.6
2932.79	2447.8
2936.11	2471.34
2939.43	2507.1
2942.75	2467.49
2946.07	2457.28
2949.39	2437.61
2952.7	2473.29
2956.02	2469.89
2959.33	2419.97
2962.64	2443.18
2965.95	2461.32
2969.26	2403.53
2972.57	2428.78
2975.87	2442.8
2979.17	2402.8
2982.48	2454.9
2985.78	2443.37
2989.08	2468.53
2992.38	2403.62
2995.68	2458.2
2998.97	2406.62
3002.27	2416.94
3005.56	2416.22
3008.85	2407.14
3012.14	2388.76
3015.43	2404.22
3018.72	2415.87
3022	2407.71
3025.29	2501.56
3028.57	2419.79
3031.85	2431.39
3035.14	2372.9
3038.41	2387.23
3041.69	2458.37
3044.97	2406.58
3048.24	2405.8
3051.52	2414.63
3054.79	2425.31
3058.06	2408.19
3061.33	2415.14
3064.6	2420.42
3067.87	2420.61
3071.13	2454.93
3074.4	2405.19
3077.66	2432.26
3080.92	2430.35
3084.18	2453.59
3087.44	2439.32
3090.7	2439.84
3093.95	2455.01
3097.21	2434.37
3100.46	2401.38
3103.71	2452.84
3106.96	2412.15
3110.21	2410.7
3113.46	2449.17
3116.71	2451.58
3119.95	2485.45
3123.2	2439.28
3126.44	2457.81
3129.68	2442.05
3132.92	2446.26
3136.16	2440.82
3139.4	2446.76
3142.63	2447.92
3145.87	2464.46
3149.1	2471.56
3152.33	2503.39
3155.56	2457.03
3158.79	2441.14
3162.02	2434.79
3165.25	2496.03
3168.47	2476.91
3171.69	2438.59
3174.92	2505.04
3178.14	2475.03
3181.36	2478.47
3184.58	2492.19
3187.79	2469.53
3191.01	2527.88
3194.22	2439.44
3197.43	2493.86
3200.65	2419.77
3203.86	2540.94
3207.07	2473.74
3210.27	2498.05
3213.48	2505.43
3216.69	2490.96
3219.89	2485.1
3223.09	2523.24
3226.29	2493.92
3229.49	2494.29
3232.69	2513.53
3235.89	2493.22
3239.08	2505.51
3242.28	2514.15
3245.47	2521.85
3248.66	2527.87
3251.85	2456.74
3255.04	2526.81
3258.23	2543.19
3261.42	2560.18
3264.6	2539.54
3267.79	2531.03
3270.97	2522.31
3274.15	2523.15
3277.33	2524.54
3280.51	2454.73
3283.68	2521.42
3286.86	2522.97
3290.04	2539.92
3293.21	2514.91
3296.38	2500.29
3299.55	2554.88
3302.72	2549.03
3305.89	2523.85
3309.06	2580.05
3312.22	2555.21
3315.39	2522.75
3318.55	2540.49
3321.71	2554.4
3324.87	2537.08
3328.03	2566.15
3331.19	2546.19
3334.34	2555.74
3337.5	2513.61
3340.65	2503.59
3343.81	2548.75
3346.96	2571.06
3350.11	2589.65
3353.25	2510.47
3356.4	2505.87
3359.55	2563.81
3362.69	2568.12
3365.84	2517.86
3368.98	2543.12
3372.12	2556.43
3375.26	2581.22
3378.4	2614.72
3381.53	2584.78
3384.67	2632.55
3387.8	2683.26
3390.94	2694.4
3394.07	2643.86
3397.2	2664.72
3400.33	2771.45
3403.46	2864.43
3406.58	2962.54
3409.71	3200.87
3412.83	3818.95
3415.96	5342.26
3419.08	8398.46
3422.2	9525.14
3425.32	6918.1
3428.44	4349.84
3431.55	3380.72
3434.67	3038.93
3437.78	2831.18
3440.89	2730.53
3444	2719.95
3447.12	2672.14
3450.22	2644.89
3453.33	2606.22
3456.44	2609.09
3459.54	2633.72
3462.65	2620.21
3465.75	2652.06
3468.85	2631.82
3471.95	2638.91
3475.05	2685.06
3478.15	2710.46
3481.24	2709.42
3484.34	2743.48
3487.43	2822.11
3490.53	3006.35
3493.62	3186.84
3496.71	3440.44
3499.79	3660.24
3502.88	3852.72
3505.97	3779.62
3509.05	3543.41
3512.14	3272.35
3515.22	3013.83
3518.3	2876.6
3521.38	2804.28
3524.46	2700.7
3527.54	2607.66
3530.61	2619.93
3533.69	2560.92
3536.76	2493.89
3539.83	2517.36
3542.9	2450.93
3545.97	2455.64
3549.04	2457.15
3552.11	2487.49
3555.18	2412.29
3558.24	2428.15
3561.3	2438.74
3564.37	2453.87
3567.43	2439.74
3570.49	2425.19
3573.55	2372.41
3576.61	2400.14
3579.66	2372.67
3582.72	2392.4
3585.77	2373.17
3588.82	2403.98
3591.87	2411.89
3594.92	2374.13
3597.97	2376.13
3601.02	2384.57
3604.07	2389
3607.11	2378.23
3610.16	2359.81
3613.2	2380.04
3616.24	2340.8
3619.28	2357.39
3622.32	2332.54
3625.36	2325.77
3628.39	2347.22
3631.43	2340.23
3634.46	2341.16
3637.5	2389.55
3640.53	2329.98
3643.56	2347.21
3646.59	2319.86
3649.62	2305.98
3652.64	2347.87
3655.67	2294.13
3658.69	2320.74
3661.72	2287.72
3664.74	2328.12
3667.76	2291.35
3670.78	2288.74
3673.79	2253.22
3676.81	2302.8
3679.83	2278.67
3682.84	2276.23
3685.86	2285.21
3688.87	2229.89
3691.88	2242.79
3694.89	2261.94
3697.9	2271.9
3700.91	2274.41
3703.91	2262.68
3706.92	2303
3709.92	2274.71
3712.92	2281.29
3715.92	2267.01
3718.92	2285.88
3721.92	2239.79
3724.92	2268.7
3727.92	2297.46
3730.91	2251.72
3733.91	2254.31
3736.9	2261.44
3739.89	2246.42
3742.88	2235.01
3745.87	2290.9
3748.86	2253.4
3751.85	2284.24
3754.83	2303.7
3757.82	2244.4
3760.8	2264.61
3763.78	2273.4
3766.76	2240.68
3769.74	2258.33
3772.72	2235.5
3775.7	2256.3
3778.67	2236.61
3781.65	2264.21
3784.62	2183.32
3787.6	2227.19
3790.57	2273.24
3793.54	2210.99
3796.51	2213.05
3799.47	2206.88
3802.44	2208.44
3805.41	2256.35
3808.37	2200.48
3811.33	2213.66
3814.3	2221.22
3817.26	2178.73
3820.22	2196.84
3823.18	2194.27
3826.13	2178.5
3829.09	2160.79
3832.04	2203.94
3835	2196.98
3837.95	2207.15
3840.9	2190.68
3843.85	2184.69
3846.8	2199.71
3849.75	2220.61
3852.69	2208.22
3855.64	2180.56
3858.58	2188.26
3861.53	2194.9
3864.47	2201.54
3867.41	2212.83
3870.35	2236.51
3873.29	2192.98
3876.22	2156.86
3879.16	2184.83
3882.1	2166.43
3885.03	2239.13
3887.96	2231
3890.89	2143.93
3893.82	2180.66
3896.75	2161.32
3899.68	2187.13
3902.61	2152.03
3905.53	2171.95
3908.46	2174.47
3911.38	2168.13
3914.3	2150.96
3917.23	2190.86
3920.15	2160.38
3923.06	2147.86
3925.98	2129.39
3928.9	2168.22
3931.81	2144.19
3934.73	2126.37
3937.64	2142.57
3940.55	2173.97
3943.46	2152.73
3946.37	2138.41
3949.28	2163.52
3952.19	2126.48
3955.09	2098.23
3958	2128.54
3960.9	2121.58
3963.8	2163.64
3966.71	2168.44
3969.61	2127.26
3972.51	2076.43
3975.4	2140.72
3978.3	2104.95
3981.2	2129.67
3984.09	2098.52
3986.99	2073.12
3989.88	2091.59
3992.77	2106.58
3995.66	2138.92
3998.55	2092.43
4001.43	2141.28
4004.32	2129.58
4007.21	2124.68
4010.09	2065.74
4012.98	2133.13
4015.86	2085.74
4018.74	2067.27
4021.62	2086.44
4024.5	2101.81
4027.37	2094.97
4030.25	2064.01
4033.13	2051.41
4036	2097.93
4038.87	2078.69
4041.75	2067.79
4044.62	2059.77
4047.49	2065.45
4050.35	2118.76
4053.22	2077.19
4056.09	2088.07
4058.95	2093.97
4061.82	2072.65
4064.68	2075.63
4067.54	2027.99
4070.4	2049.39
4073.26	2069.8
4076.12	2057.08
4078.98	2030.69
4081.83	2005.25
4084.69	1992.43
4087.54	2024.42
4090.4	2038.97
4093.25	2045.7
4096.1	2069.97
4098.95	2046.44
4101.8	2019.85
4104.64	2037.11
4107.49	2050.34
4110.33	1994.02
4113.18	2031.37
4116.02	2000.95
4118.86	2034.03
4121.7	2061.42
4124.54	1985.23
4127.38	2016.01
4130.22	2032.6
4133.05	2046.7
4135.89	2003.83
4138.72	1968.32
4141.56	2027.61
4144.39	2017.46
4147.22	2038.78
4150.05	2027.61
4152.88	2001.06
4155.7	2006.99
4158.53	2033.49
4161.36	1996.06
4164.18	2018.3
4167	2013.19
4169.82	2002.34
4172.65	1986.68
4175.46	1991.57
4178.28	1997.53
4181.1	1990.9
4183.92	1995.12
4186.73	1955.39
4189.55	1997.07
4192.36	1974.44
4195.17	1989.26
4197.98	1959.09
4200.79	1949.46
4203.6	1949.65
4206.41	2000.88
4209.21	2026.6
4212.02	2014.94
4214.83	1965.58
4217.63	1921.59
4220.43	1940.32
4223.23	1943.09
4226.03	1992.37
4228.83	1958.91
4231.63	1978.99
4234.42	1919.01
4237.22	1996.93
4240.01	1923.01
4242.81	1943.54
4245.6	1959.13
4248.39	1956.62
4251.18	1937.99
4253.97	1966.22
4256.76	1940.33
4259.55	1911.43
4262.33	1952.81
4265.12	1928.07
4267.9	1919.41
4270.68	1931.82
4273.47	1934.93
4276.25	1890.25
4279.03	1943.3
4281.8	1929.54
4284.58	1883.15
4287.36	1949.84
4290.13	1890.9
4292.91	1872.55
4295.68	1887.87
4298.45	1874.74
4301.22	1888.89
4303.99	1878.69
4306.76	1924.39
4309.53	1895.1
4312.3	1879.9
4315.06	1920.36
4317.83	1915.95
4320.59	1857.42
4323.35	1879.18
4326.11	1883.65
4328.87	1820.8
4331.63	1900.52
4334.39	1864.07
4337.15	1871.53
4339.9	1879.2
4342.66	1813.54
4345.41	1872.49
4348.17	1908.09
4350.92	1837.81
4353.67	1859.54
4356.42	1859.68
4359.17	1839.31
4361.91	1825.11
4364.66	1814.99
4367.41	1855.11
4370.15	1824.4
4372.89	1831.43
4375.63	1812.71
4378.38	1811.33
4381.12	1822.35
4383.86	1800.78
4386.59	1801.4
4389.33	1820.02
4392.07	1819
4394.8	1844.69
4397.53	1806.51
4400.27	1818.97
4403	1787.85
4405.73	1801.42
4408.46	1778.53
4411.19	1768.86
4413.92	1785.06
4416.64	1764.33
4419.37	1817.49
4422.09	1768.72
4424.82	1773.18
4427.54	1747.32
4430.26	1795.68
4432.98	1800.07
4435.7	1799.13
4438.42	1816.91
4441.13	1796.91
4443.85	1788.39
4446.57	1799.75
4449.28	1764.82
4451.99	1784.41
4454.71	1793.39
4457.42	1764.41
4460.13	1753.41
4462.83	1778.24
4465.54	1769.45
4468.25	1764.97
4470.95	1726.9
4473.66	1756.41
4476.36	1739.69
4479.07	1773.73
4481.77	1775.11
4484.47	1735.17
4487.17	1735.33
4489.87	1782.82
4492.56	1743.93
4495.26	1702.3
4497.96	1699.86
4500.65	1756.44
4503.34	1705.15
4506.04	1729.2
4508.73	1735.23
4511.42	1707.32
4514.11	1691.15
4516.8	1705.76
4519.48	1674.92
4522.17	1711.1
4524.85	1687.63
4527.54	1685.51
4530.22	1675.94
4532.9	1711.24
4535.58	1659.06
4538.27	1692.46
4540.94	1688.42
4543.62	1656.64
4546.3	1687.99
4548.98	1659.43
4551.65	1667.68
4554.33	1664.22
4557	1632.3
4559.67	1608.11
4562.34	1630.55
4565.01	1668.09
4567.68	1641.29
4570.35	1700.36
4573.02	1656.92
4575.68	1626.39
4578.35	1664.74
4581.01	1615.12
4583.67	1627.19
4586.34	1623.96
4589	1639.06
4591.66	1616.97
4594.31	1607.4
4596.97	1610.48
4599.63	1607.38
4602.29	1597.88
4604.94	1646.43
4607.59	1620.56
4610.25	1620.93
4612.9	1610.26
4615.55	1612.81
4618.2	1608.91
4620.85	1623.71
4623.5	1584.37
4626.14	1544.82
4628.79	1572.65
4631.43	1578.15
4634.08	1553.6
4636.72	1562.26
4639.36	1580.77
4642	1618.48
4644.64	1603.45
4647.28	1568.78
4649.92	1561.15
4652.56	1576.59
4655.19	1623.14
4657.83	1583.23
4660.46	1567.08
4663.1	1559.88
4665.73	1586.64
4668.36	1561.07
4670.99	1565.67
4673.62	1554.56
4676.24	1577.07
4678.87	1507.48
4681.5	1564.76
4684.12	1543.43
4686.75	1574.92
4689.37	1550.28
4691.99	1581.78
4694.61	1571.53
4697.23	1568.08
4699.85	1543.2
4702.47	1553.12
4705.09	1540.4
4707.7	1533.25
4710.32	1558.88
4712.93	1543.77
4715.55	1562.47
4718.16	1541.58
4720.77	1541.96
4723.38	1525.58
4725.99	1528.62
4728.6	1481.73
4731.21	1531.33
4733.81	1530.98
4736.42	1504.33
4739.02	1494.74
4741.63	1512.24
4744.23	1487.68
4746.83	1502.57
4749.43	1462.91
4752.03	1490.39
4754.63	1455.19
4757.23	1502.08
4759.82	1505.88
4762.42	1465.27
4765.01	1489.84
4767.61	1467.01
4770.2	1481.31
4772.79	1448.85
4775.38	1510.03
4777.97	1484.41
4780.56	1502.21
4783.15	1492.6
4785.74	1505.87
4788.32	1482.55
4790.91	1484.51
4793.49	1457.81
4796.07	1424.39
4798.66	1466.73
4801.24	1455.27
4803.82	1437.06
4806.4	1451.25
4808.98	1420.47
4811.55	1447.37
4814.13	1452.45
4816.71	1399.95
4819.28	1430.6
4821.85	1432.4
4824.43	1430.74
4827	1459.16
4829.57	1419.3
4832.14	1431.71
4834.71	1447.84
4837.28	1432.64
4839.84	1392.9
4842.41	1407.81
4844.97	1421.42
4847.54	1406.69
4850.1	1432.17
4852.66	1409.77
4855.22	1440.1
4857.78	1419.84
4860.34	1408.67
4862.9	1432.32
4865.46	1408.46
4868.01	1398.26
4870.57	1429.14
4873.12	1381.56
4875.68	1413.41
4878.23	1394.2
4880.78	1376.03
4883.33	1364.94
4885.88	1390.72
4888.43	1376.14
4890.98	1423.36
4893.53	1368.17
4896.07	1366.48
4898.62	1345.71
4901.16	1372.57
4903.7	1381.62
4906.25	1349.87
4908.79	1356.19
4911.33	1343.2
4913.87	1350.41
4916.41	1356.46
4918.94	1348.24
4921.48	1369.9
4924.02	1388.04
4926.55	1384.61
4929.08	1347.84
4931.62	1348.46
4934.15	1357.45
4936.68	1340.02
4939.21	1343.76
4941.74	1315.21
4944.27	1357.71
4946.79	1314
4949.32	1363.8
4951.85	1334.43
4954.37	1294.3
4956.9	1351.58
4959.42	1310.51
4961.94	1330.99
4964.46	1349.42
4966.98	1331.57
4969.5	1274.84
4972.02	1308.58
4974.53	1337.5
4977.05	1298.75
4979.57	1308.4
4982.08	1282.96
4984.59	1315.74
4987.1	1309.75
4989.62	1312.24
4992.13	1300.08
4994.64	1297.76
4997.15	1273.64
4999.65	1306.85