File: Data/3-Raman/raw/bu19w-ff2-fi02-v_150 (500nm)_532nm_edge_100%_x100_vis_h50um_15sx2_01.txt
#Acq. time (s)=	15
#Accumulations=	2
#Range (cm-¹)=	100...5000
#Windows=	1
#Auto scanning=	Off
#Autofocus=	Off
#Macrospot=	Off
#AutoExposure=	Off
#Spike filter=	Multiple accum.
#Delay time (s)=	2
#Binning=	1
#Readout mode=	Signal
#DeNoise=	Off
#ICS correction=	On
#Dark correction=	Off
#Inst. Process=	Off
#Detector Gain=	Best Dynamic
#Detector ADC=	50 kHz HS
#Detector temperature (°C)=	-60.09
#Instrument=	LabRAM HR Evol
#Detector=	SIN-EM FIVIS
#Objective=	x100_VIS
#Grating=	150 (500nm)
#ND Filter=	100%
#Laser=	532nm_Edge
#Hole=	49.98
#Temperature=	0
#Range=	Visible
#StageXY=	75x50mm Scan+
#StageZ=	Z motor
#X (µm)=	0
#Y (µm)=	0
#Z (µm)=	-182.8
#Full time(s)=	34
#Project=	21_05_14
#Sample=	BU19w
#Site=
#Title=	BU19w-FF2-FI02-V_150 (500nm)_532nm_Edge_100%_x100_VIS_H50um_15sX2
#Remark=
#Date=	14.05.2021 17:15
#Acquired=	14.05.2021 17:15:47
102.699	1330.52
107.322	1334.24
111.942	1203.75
116.56	1130.62
121.173	1077.3
125.787	1096.26
130.398	1036.72
135.006	1056.23
139.613	1057.48
144.215	994.83
148.817	1025.58
153.417	1293.2
158.014	1837.58
162.607	1674.8
167.2	1159.8
171.79	983.185
176.379	989.113
180.963	1140.72
185.547	1600.6
190.128	1620.19
194.705	1326.62
199.282	1101.57
203.857	1010.96
208.43	972.974
212.998	970.473
217.566	997.328
222.132	934.886
226.693	1055.62
231.254	1309.24
235.813	1391.68
240.368	1599.28
244.923	2010.18
249.475	1720.76
254.023	1311.45
258.571	1176.43
263.117	1103.71
267.658	1351.51
272.199	2010.12
276.738	3239.84
281.273	3122.69
285.807	2051.1
290.34	1471.22
294.868	1321.22
299.396	1415.66
303.919	1422.24
308.443	1292.34
312.964	1196.9
317.481	1279.17
321.998	1466.05
326.51	1796.91
331.023	1806.09
335.533	1488.56
340.039	1463.16
344.544	1742.77
349.046	2073.19
353.547	1914.68
358.045	1480.93
362.542	1347.64
367.036	1411.08
371.527	1400.94
376.017	1223.97
380.503	1180.36
384.99	1235.92
389.471	1359.17
393.953	1441.61
398.43	1234.04
402.908	1129.88
407.381	1106.44
411.854	1288.94
416.323	1527.39
420.791	1380.38
425.256	1136.68
429.72	1032.82
434.18	991.861
438.64	945.489
443.095	993.125
447.551	1003.13
452.003	1080
456.454	1108.42
460.901	1110.58
465.348	1049.82
469.791	1069.32
474.231	1091.02
478.672	1114.58
483.108	1201.22
487.544	1303.9
491.976	1420.79
496.408	1445.99
500.836	1372.48
505.261	1287.8
509.687	1178.66
514.108	1111.33
518.529	1059.09
522.946	1066.36
527.361	1022.81
531.776	1057.07
536.187	1026.6
540.595	1048.22
545.003	1066.34
549.408	1141.39
553.812	1171.91
558.212	1143.93
562.61	1180.03
567.007	1091.95
571.401	1083.69
575.792	1110.45
580.184	1208.82
584.571	1397.47
588.956	1659.42
593.341	1484.17
597.722	1310.99
602.101	1258.58
606.48	1398.18
610.854	1492.23
615.227	1319.43
619.597	1195.1
623.967	1112.28
628.334	1098.8
632.698	1151.11
637.06	1184.68
641.422	1208.02
645.779	1188.41
650.135	1201.53
654.491	1237.91
658.842	1389.42
663.192	1582.33
667.539	1626.83
671.884	1624.24
676.23	1678.91
680.571	1574.85
684.91	1380.6
689.247	1229.39
693.583	1144.36
697.916	1087.6
702.247	1103.92
706.576	1053.56
710.902	1093.43
715.229	1050.69
719.551	1048.1
723.872	1075.26
728.19	1100.83
732.506	1077.5
736.82	1099.19
741.134	1076.53
745.444	1119.86
749.752	1152.85
754.058	1156.41
758.362	1181.15
762.664	1223.31
766.964	1364.92
771.264	1505.93
775.559	1746.96
779.853	1784.81
784.144	1629.39
788.434	1434.63
792.722	1299.97
797.007	1235.33
801.29	1187.22
805.572	1182.63
809.851	1188.14
814.13	1159.85
818.406	1157.86
822.679	1145.19
826.95	1151.38
831.219	1170.87
835.486	1113.13
839.752	1137.97
844.015	1159.28
848.276	1181.94
852.535	1160.38
856.792	1147.66
861.047	1137.04
865.3	1137.04
869.551	1137.88
873.8	1141.7
878.047	1161.73
882.292	1169.21
886.534	1155.41
890.775	1139.54
895.014	1149.74
899.251	1182.14
903.486	1169.21
907.719	1179.95
911.95	1187.19
916.179	1175.78
920.406	1232.4
924.63	1209.64
928.853	1216.69
933.074	1206.71
937.293	1276.71
941.51	1369.88
945.723	1450.71
949.936	1512.54
954.147	1418.89
958.356	1402.25
962.563	1325.28
966.768	1322.84
970.971	1312.28
975.172	1280.63
979.371	1272.64
983.568	1223.46
987.761	1253.46
991.954	1242.99
996.145	1189.04
1000.33	1214.84
1004.52	1206.87
1008.71	1237.44
1012.89	1253.8
1017.07	1240.32
1021.25	1284.38
1025.43	1298.96
1029.6	1333.88
1033.77	1349.29
1037.95	1429.42
1042.11	1574.43
1046.28	1774.71
1050.45	2206.24
1054.61	2307.07
1058.77	1959.17
1062.93	1694.45
1067.09	1522.5
1071.24	1526.98
1075.4	1556.78
1079.55	1656.26
1083.7	1904.28
1087.85	2224.29
1091.99	2375.09
1096.14	2145.38
1100.28	2009.26
1104.42	2077.24
1108.55	2337.99
1112.69	2367.68
1116.82	2116.32
1120.96	2089.2
1125.09	2110.48
1129.21	2136.17
1133.34	2153.27
1137.46	2010.55
1141.59	1806.44
1145.71	1682.74
1149.83	1683.54
1153.94	1863.9
1158.06	1975.04
1162.17	1832.52
1166.28	1772.26
1170.39	1720.63
1174.5	1639.79
1178.6	1474.58
1182.7	1351.8
1186.8	1410.04
1190.9	1343.68
1195	1394.71
1199.1	1398.12
1203.19	1407.42
1207.28	1323.41
1211.37	1385.54
1215.46	1405.02
1219.54	1471.95
1223.63	1553.74
1227.71	1487.61
1231.79	1424.28
1235.87	1463.81
1239.95	1501.67
1244.02	1468.84
1248.09	1455.05
1252.16	1410.66
1256.23	1394.47
1260.3	1350.46
1264.36	1355.64
1268.43	1494.42
1272.49	2108.01
1276.55	1783.96
1280.6	1408.85
1284.66	1334.44
1288.71	1330.36
1292.76	1375.31
1296.81	1330.56
1300.86	1365.16
1304.91	1344.1
1308.95	1345.26
1312.99	1358.04
1317.03	1313.95
1321.07	1347.26
1325.11	1321.45
1329.14	1337.15
1333.18	1337.22
1337.21	1394.06
1341.24	1406.57
1345.26	1361.07
1349.29	1365.56
1353.31	1359.14
1357.33	1382.51
1361.35	1385.96
1365.37	1385.84
1369.39	1432.28
1373.4	2042.21
1377.41	2597.81
1381.43	1765.98
1385.43	1457.38
1389.44	1352.81
1393.45	1450.65
1397.45	1473.98
1401.45	1436.92
1405.45	1363.54
1409.45	1385.87
1413.44	1388.58
1417.44	1363.62
1421.43	1366.2
1425.42	1374.25
1429.41	1376.89
1433.39	1402.62
1437.38	1384.68
1441.36	1414.17
1445.34	1394
1449.32	1362.95
1453.3	1363.19
1457.27	1399.79
1461.24	1385.7
1465.22	1367.4
1469.19	1379.75
1473.15	1405.86
1477.12	1370.83
1481.09	1382.79
1485.05	1412.22
1489.01	1429.85
1492.97	1434.88
1496.93	1380.53
1500.88	1393.68
1504.83	1428.5
1508.79	1400.43
1512.74	1415.11
1516.68	1433.8
1520.63	1414.78
1524.57	1406.53
1528.52	1424.61
1532.46	1405.97
1536.4	1413.51
1540.33	1432.72
1544.27	1410.25
1548.2	1395.54
1552.14	1423.38
1556.07	1444.18
1559.99	1460.92
1563.92	1427.19
1567.84	1430.11
1571.77	1428.14
1575.69	1439.65
1579.61	1461.7
1583.52	1454.73
1587.44	1459.24
1591.35	1456.03
1595.27	1448.01
1599.18	1456.39
1603.09	1440
1606.99	1455.43
1610.9	1459.37
1614.8	1449.11
1618.7	1446.59
1622.6	1493.87
1626.5	1445.71
1630.39	1422.74
1634.29	1467.02
1638.18	1426.15
1642.07	1490.13
1645.96	1469.99
1649.85	1455.69
1653.73	1477.8
1657.62	1504.62
1661.5	1495.75
1665.38	1495.26
1669.26	1460.83
1673.13	1479.91
1677.01	1458.23
1680.88	1480.05
1684.75	1440.3
1688.62	1517.31
1692.49	1480.92
1696.35	1531.38
1700.22	1529.86
1704.08	1520.4
1707.94	1504
1711.8	1534.94
1715.66	1492.97
1719.51	1539.04
1723.37	1531.15
1727.22	1475.11
1731.07	1547.82
1734.92	1518.16
1738.76	1541.64
1742.61	1537.96
1746.45	1564.64
1750.29	1505.71
1754.13	1499.52
1757.97	1557.31
1761.81	1505.4
1765.64	1502.97
1769.47	1533.09
1773.31	1533.81
1777.14	1560.86
1780.96	1538.04
1784.79	1553.64
1788.61	1537.58
1792.43	1559.95
1796.25	1522.26
1800.07	1559.1
1803.89	1556.83
1807.71	1532.82
1811.52	1550.95
1815.33	1567.65
1819.14	1565.85
1822.95	1533.56
1826.76	1548.08
1830.56	1595.14
1834.37	1562.7
1838.17	1589.35
1841.97	1577.09
1845.77	1562.93
1849.56	1561.63
1853.36	1567.2
1857.15	1584.45
1860.94	1592.92
1864.73	1602.33
1868.52	1578.5
1872.31	1581.86
1876.09	1595.59
1879.87	1583.87
1883.66	1603.86
1887.43	1623.95
1891.21	1570.42
1894.99	1593.15
1898.76	1587.78
1902.53	1558.99
1906.31	1540.49
1910.08	1599.79
1913.84	1635.54
1917.61	1590.7
1921.37	1639.78
1925.14	1595.54
1928.9	1605.25
1932.66	1602.92
1936.41	1621.97
1940.17	1627.02
1943.92	1623.06
1947.68	1633.6
1951.43	1625.7
1955.18	1647.09
1958.92	1614.11
1962.67	1645.78
1966.41	1674.44
1970.16	1659.06
1973.9	1614.33
1977.64	1663.91
1981.37	1647.68
1985.11	1639.6
1988.84	1669.62
1992.57	1678.67
1996.31	1656.77
2000.03	1675.5
2003.76	1670.35
2007.49	1660.92
2011.21	1665.26
2014.93	1670.92
2018.65	1661.21
2022.37	1655
2026.09	1653.36
2029.81	1679.77
2033.52	1687.66
2037.23	1683.16
2040.94	1735.54
2044.65	1685.11
2048.36	1684.49
2052.07	1664.86
2055.77	1662.92
2059.47	1658.65
2063.17	1675.17
2066.87	1664.3
2070.57	1686.66
2074.27	1698.05
2077.96	1734.66
2081.65	1710.13
2085.34	1713.27
2089.03	1708.58
2092.72	1707.56
2096.41	1687.34
2100.09	1712.76
2103.77	1743.48
2107.46	1752.5
2111.14	1739.97
2114.81	1720.89
2118.49	1730.09
2122.16	1751.6
2125.84	1708.96
2129.51	1745.73
2133.18	1756.47
2136.85	1743.85
2140.51	1748.46
2144.18	1749.2
2147.84	1715.89
2151.5	1776.27
2155.16	1740.39
2158.82	1746.8
2162.48	1740.72
2166.13	1736.74
2169.79	1769.72
2173.44	1738.73
2177.09	1729.74
2180.74	1757.32
2184.38	1764.88
2188.03	1804.2
2191.67	1745.9
2195.32	1771.04
2198.96	1773.6
2202.6	1790.12
2206.23	1774.08
2209.87	1791.23
2213.5	1810.42
2217.14	1792.98
2220.77	1753.51
2224.4	1829.93
2228.03	1799.49
2231.65	1825.48
2235.28	1849.75
2238.9	1810.98
2242.52	1825.89
2246.14	1808.29
2249.76	1791.76
2253.38	1739.91
2256.99	1820.61
2260.6	1795.65
2264.21	1781.79
2267.82	1797.42
2271.44	1810.27
2275.04	1818.65
2278.65	1794.25
2282.25	1801.96
2285.85	1801.56
2289.45	1841.49
2293.05	1784.89
2296.65	1826.81
2300.25	1810.85
2303.84	1820.03
2307.43	1864.93
2311.02	1851.77
2314.62	1844.92
2318.2	1932.46
2321.79	1931.03
2325.38	1855.91
2328.96	1839.61
2332.54	1828.64
2336.12	1827.87
2339.7	1855.06
2343.28	1867.89
2346.85	1837.35
2350.43	1846.13
2354	1864.09
2357.57	1843.66
2361.14	1860.43
2364.71	1815.94
2368.27	1866.42
2371.84	1879.02
2375.4	1862.76
2378.96	1840.33
2382.52	1888.13
2386.08	1862.51
2389.64	1863.03
2393.19	1836.5
2396.75	1866.55
2400.3	1890.99
2403.85	1862.07
2407.4	1894.9
2410.95	1879.94
2414.49	1822.1
2418.04	1891.46
2421.58	1881.2
2425.12	1853.89
2428.66	1859.24
2432.2	1868.7
2435.74	1872
2439.27	1894.98
2442.81	1941.48
2446.34	1893.05
2449.87	1886.03
2453.4	1895.37
2456.93	1880.45
2460.45	1950.4
2463.98	1908.44
2467.5	1911.5
2471.02	1924.56
2474.54	1894.51
2478.06	1903.86
2481.58	1932.63
2485.09	1887.8
2488.61	1927.62
2492.12	1908.45
2495.63	1915.05
2499.14	1949.09
2502.65	1922.46
2506.15	1904.07
2509.66	1967.49
2513.16	1948.39
2516.66	1942.75
2520.16	1919.53
2523.66	1894.65
2527.16	1943.75
2530.66	1907.15
2534.15	1910.84
2537.64	1937.05
2541.13	1911.47
2544.62	1954.3
2548.11	1953.01
2551.6	1933.51
2555.08	1905.83
2558.57	1935.58
2562.05	1910.42
2565.53	1919.34
2569.01	1976.48
2572.49	1923.82
2575.96	1919.17
2579.44	1904.3
2582.91	1970.68
2586.38	1916.83
2589.85	1938.62
2593.32	1939.82
2596.79	1934.88
2600.25	1928.16
2603.72	1964.62
2607.18	1958.49
2610.64	1929.13
2614.1	1943.82
2617.56	1908.81
2621.02	1933.93
2624.47	1970.97
2627.92	1931.79
2631.38	1952.71
2634.83	1983.51
2638.28	1965.98
2641.72	1970.97
2645.17	1957.72
2648.61	1977.48
2652.06	1949.07
2655.5	1965.87
2658.94	1928.35
2662.38	1991.92
2665.82	1969.34
2669.25	1960.74
2672.69	1984.39
2676.12	1986.65
2679.55	1956.58
2682.98	1995.23
2686.41	1936.17
2689.84	1967.89
2693.26	1951.51
2696.69	1921.57
2700.11	1993.39
2703.53	1933.54
2706.95	1961.74
2710.37	1938.38
2713.79	1954.48
2717.2	1923.5
2720.62	1998.15
2724.03	1966.67
2727.44	1975.53
2730.85	1994.58
2734.26	1978.99
2737.66	1981.2
2741.07	1936.12
2744.47	1952.56
2747.87	1954
2751.28	1993.04
2754.67	1962.03
2758.07	1930.32
2761.47	1988.46
2764.86	1959.64
2768.26	1983.18
2771.65	1964.19
2775.04	1950.53
2778.43	1974.22
2781.82	1931.82
2785.2	1954.29
2788.59	1955.07
2791.97	1952.86
2795.35	1931.12
2798.73	1948.38
2802.11	1952.5
2805.49	1981.89
2808.87	1974.62
2812.24	1967.26
2815.62	2002.71
2818.99	1934.76
2822.36	1979.18
2825.73	1977.06
2829.1	1977.95
2832.46	1928.91
2835.83	2009.69
2839.19	1950.18
2842.55	1946.96
2845.91	1942.46
2849.27	1966.87
2852.63	1960.06
2855.99	1968.41
2859.34	1875.09
2862.69	1958.72
2866.05	1942.27
2869.4	1950.03
2872.75	1945.53
2876.09	1943.77
2879.44	1954.24
2882.78	1958.9
2886.13	1966.25
2889.47	1952.03
2892.81	1950.44
2896.15	1962.76
2899.49	1949.23
2902.82	1972.3
2906.16	1964.01
2909.49	1975.36
2912.82	1956.42
2916.16	1927.66
2919.49	1958.35
2922.81	1957.76
2926.14	1989.86
2929.46	1967.99
2932.79	2014.58
2936.11	2053.56
2939.43	1952.06
2942.75	1996.69
2946.07	1955.76
2949.39	1982.52
2952.7	1933.06
2956.02	1924.36
2959.33	1926.31
2962.64	1958.21
2965.95	1928.63
2969.26	1915.79
2972.57	1930.74
2975.87	1979.29
2979.17	1897
2982.48	1950.87
2985.78	1966.43
2989.08	1942.61
2992.38	1965.83
2995.68	1939.4
2998.97	1937.43
3002.27	1922.17
3005.56	1920.27
3008.85	1925.05
3012.14	1916.75
3015.43	1903.67
3018.72	1901.86
3022	1916.07
3025.29	1906.73
3028.57	1941.78
3031.85	1909.67
3035.14	1892.56
3038.41	1858.42
3041.69	1879.15
3044.97	1911.34
3048.24	1885.7
3051.52	1899.95
3054.79	1891.41
3058.06	1911.09
3061.33	1862
3064.6	1890.88
3067.87	1890.08
3071.13	1878.31
3074.4	1884.61
3077.66	1887.12
3080.92	1888.79
3084.18	1888.95
3087.44	1897.04
3090.7	1903.67
3093.95	1855.16
3097.21	1892.44
3100.46	1861.29
3103.71	1928.69
3106.96	1849.68
3110.21	1885.25
3113.46	1856.99
3116.71	1861.19
3119.95	1881.59
3123.2	1853.39
3126.44	1860.39
3129.68	1838.8
3132.92	1874.37
3136.16	1846.94
3139.4	1853.78
3142.63	1867.28
3145.87	1878.02
3149.1	1862.14
3152.33	1854.77
3155.56	1842.66
3158.79	1857.22
3162.02	1892.77
3165.25	1893.86
3168.47	1904.33
3171.69	1860.32
3174.92	1859.1
3178.14	1856.87
3181.36	1879.48
3184.58	1898.1
3187.79	1853.7
3191.01	1856.95
3194.22	1826.84
3197.43	1859.56
3200.65	1835.18
3203.86	1862.28
3207.07	1848.52
3210.27	1846.3
3213.48	1868.96
3216.69	1811.74
3219.89	1881.07
3223.09	1840.23
3226.29	1863.18
3229.49	1869.17
3232.69	1814.14
3235.89	1862.18
3239.08	1854.26
3242.28	1814.06
3245.47	1839.58
3248.66	1884.34
3251.85	1846.25
3255.04	1822.45
3258.23	1823.25
3261.42	1849.57
3264.6	1852.71
3267.79	1824.12
3270.97	1838.36
3274.15	1837.32
3277.33	1815.93
3280.51	1841.89
3283.68	1808.65
3286.86	1815.33
3290.04	1815.46
3293.21	1836.52
3296.38	1847.96
3299.55	1835.11
3302.72	1801.02
3305.89	1823.81
3309.06	1829.18
3312.22	1780.24
3315.39	1833.82
3318.55	1814.23
3321.71	1829.72
3324.87	1824.37
3328.03	1812.43
3331.19	1790.22
3334.34	1836.19
3337.5	1840.73
3340.65	1802.83
3343.81	1806.8
3346.96	1804.69
3350.11	1768.69
3353.25	1865.77
3356.4	1861.14
3359.55	1848.26
3362.69	1834.5
3365.84	1811.41
3368.98	1821.37
3372.12	1761.71
3375.26	1842.78
3378.4	1835.26
3381.53	1764.3
3384.67	1829.59
3387.8	1856.19
3390.94	1807.16
3394.07	1882.38
3397.2	1883.74
3400.33	1885.42
3403.46	1946.18
3406.58	1988.17
3409.71	2105.52
3412.83	2389.28
3415.96	3224.23
3419.08	5120.92
3422.2	6369.02
3425.32	4874.12
3428.44	3097.07
3431.55	2323.67
3434.67	2105.34
3437.78	1937.88
3440.89	1904.17
3444	1923.47
3447.12	1859.77
3450.22	1873.01
3453.33	1870.02
3456.44	1849.63
3459.54	1822.54
3462.65	1852.44
3465.75	1863.14
3468.85	1851.42
3471.95	1947.33
3475.05	1926.82
3478.15	2009.56
3481.24	2047.78
3484.34	2128.57
3487.43	2242.49
3490.53	2460.86
3493.62	2779.23
3496.71	3216.89
3499.79	3658.36
3502.88	4003.53
3505.97	4011.4
3509.05	3662.04
3512.14	3074.8
3515.22	2742.88
3518.3	2422.97
3521.38	2234.1
3524.46	2120.46
3527.54	1970.49
3530.61	1985.37
3533.69	1889.65
3536.76	1822.88
3539.83	1804.59
3542.9	1810.94
3545.97	1776.43
3549.04	1749.17
3552.11	1750.84
3555.18	1714.01
3558.24	1712.35
3561.3	1717.87
3564.37	1727.99
3567.43	1687.01
3570.49	1714.94
3573.55	1671.55
3576.61	1693.52
3579.66	1686.91
3582.72	1664.01
3585.77	1681.85
3588.82	1668.23
3591.87	1690.55
3594.92	1647.35
3597.97	1628.76
3601.02	1631.85
3604.07	1643.3
3607.11	1663.2
3610.16	1666.95
3613.2	1623.37
3616.24	1632.75
3619.28	1654.46
3622.32	1612.08
3625.36	1645.24
3628.39	1663.26
3631.43	1616.18
3634.46	1664.46
3637.5	1633.96
3640.53	1612.12
3643.56	1635.85
3646.59	1635.81
3649.62	1626.56
3652.64	1652.21
3655.67	1594.46
3658.69	1602.54
3661.72	1604.75
3664.74	1622.29
3667.76	1590.89
3670.78	1614.33
3673.79	1606.75
3676.81	1618.14
3679.83	1621.95
3682.84	1586.98
3685.86	1609.72
3688.87	1584.26
3691.88	1573.98
3694.89	1570.04
3697.9	1575.77
3700.91	1588.24
3703.91	1548.5
3706.92	1620.7
3709.92	1574.94
3712.92	1571.74
3715.92	1559.08
3718.92	1561.52
3721.92	1567.61
3724.92	1554.53
3727.92	1579.41
3730.91	1537.5
3733.91	1556.35
3736.9	1556.97
3739.89	1616.42
3742.88	1552.95
3745.87	1553.1
3748.86	1598.71
3751.85	1579.65
3754.83	1588.15
3757.82	1549.22
3760.8	1541.49
3763.78	1555.53
3766.76	1533.69
3769.74	1520.53
3772.72	1544.38
3775.7	1533.34
3778.67	1528.07
3781.65	1571.02
3784.62	1479.94
3787.6	1525.85
3790.57	1516.28
3793.54	1535.19
3796.51	1516.43
3799.47	1546
3802.44	1567.2
3805.41	1502.5
3808.37	1517.23
3811.33	1538.64
3814.3	1542.13
3817.26	1527.71
3820.22	1514.26
3823.18	1526.47
3826.13	1493.25
3829.09	1524.45
3832.04	1523.54
3835	1506.6
3837.95	1485.85
3840.9	1534.48
3843.85	1500.4
3846.8	1491.08
3849.75	1513.3
3852.69	1506.02
3855.64	1476.79
3858.58	1493.41
3861.53	1480.33
3864.47	1494.98
3867.41	1507.64
3870.35	1494.36
3873.29	1461.83
3876.22	1482.87
3879.16	1495.14
3882.1	1489.93
3885.03	1493.24
3887.96	1493.58
3890.89	1519.84
3893.82	1507.47
3896.75	1492.97
3899.68	1468.82
3902.61	1491.57
3905.53	1513.5
3908.46	1483.44
3911.38	1462.87
3914.3	1512.25
3917.23	1466.82
3920.15	1465.37
3923.06	1499.23
3925.98	1498.39
3928.9	1477.27
3931.81	1483.26
3934.73	1457.96
3937.64	1503.87
3940.55	1468.3
3943.46	1469.14
3946.37	1433.74
3949.28	1500.92
3952.19	1443.67
3955.09	1457.41
3958	1452.08
3960.9	1474.61
3963.8	1446.42
3966.71	1480.64
3969.61	1481.36
3972.51	1443.66
3975.4	1414.5
3978.3	1425.56
3981.2	1470.24
3984.09	1434.11
3986.99	1485.47
3989.88	1440.4
3992.77	1453.3
3995.66	1450.81
3998.55	1432.98
4001.43	1472.94
4004.32	1445.57
4007.21	1474.12
4010.09	1463.13
4012.98	1445.39
4015.86	1420.89
4018.74	1427.25
4021.62	1406.57
4024.5	1441.95
4027.37	1392.3
4030.25	1406.47
4033.13	1428.39
4036	1396.2
4038.87	1401.77
4041.75	1428.42
4044.62	1431.81
4047.49	1438.2
4050.35	1410.73
4053.22	1422.15
4056.09	1368.58
4058.95	1451.84
4061.82	1425.35
4064.68	1409.52
4067.54	1384.91
4070.4	1406
4073.26	1449.5
4076.12	1407.27
4078.98	1403.01
4081.83	1452.38
4084.69	1399.33
4087.54	1391.09
4090.4	1440.51
4093.25	1390.33
4096.1	1399.69
4098.95	1384.66
4101.8	1379.33
4104.64	1379.76
4107.49	1349.77
4110.33	1377.46
4113.18	1377.57
4116.02	1413.73
4118.86	1387.17
4121.7	1378.36
4124.54	1354.96
4127.38	1371.91
4130.22	1373.51
4133.05	1389.13
4135.89	1347.16
4138.72	1360.35
4141.56	1385.82
4144.39	1354.92
4147.22	1394.59
4150.05	1363.65
4152.88	1337.14
4155.7	1350.23
4158.53	1353.54
4161.36	1344.56
4164.18	1346.35
4167	1372.61
4169.82	1366.68
4172.65	1334.39
4175.46	1343.2
4178.28	1407.8
4181.1	1320.91
4183.92	1344.59
4186.73	1324.31
4189.55	1340.35
4192.36	1338.98
4195.17	1365.19
4197.98	1310.14
4200.79	1403.12
4203.6	1338.21
4206.41	1348.81
4209.21	1349.6
4212.02	1313.97
4214.83	1360.41
4217.63	1354.13
4220.43	1308.17
4223.23	1332.08
4226.03	1320.51
4228.83	1315.01
4231.63	1309.59
4234.42	1310.24
4237.22	1294.06
4240.01	1288.8
4242.81	1301.5
4245.6	1290.31
4248.39	1297.92
4251.18	1307.48
4253.97	1301.98
4256.76	1346.46
4259.55	1314.89
4262.33	1285.31
4265.12	1301.96
4267.9	1328.75
4270.68	1266.89
4273.47	1304.58
4276.25	1284.56
4279.03	1281.56
4281.8	1271.36
4284.58	1326.75
4287.36	1305.12
4290.13	1302.62
4292.91	1262.72
4295.68	1239.15
4298.45	1291.58
4301.22	1335.87
4303.99	1306.1
4306.76	1268.2
4309.53	1245.61
4312.3	1256.48
4315.06	1242.77
4317.83	1252.36
4320.59	1299.53
4323.35	1242.78
4326.11	1245.07
4328.87	1266.67
4331.63	1229.15
4334.39	1282.28
4337.15	1265.18
4339.9	1254.33
4342.66	1262.9
4345.41	1213.47
4348.17	1250.79
4350.92	1261.8
4353.67	1235.1
4356.42	1254.28
4359.17	1207.96
4361.91	1229.2
4364.66	1233.05
4367.41	1195.91
4370.15	1205.84
4372.89	1196.15
4375.63	1242.87
4378.38	1251.55
4381.12	1204.8
4383.86	1250.73
4386.59	1243.64
4389.33	1230.69
4392.07	1206.99
4394.8	1170.7
4397.53	1215.55
4400.27	1174.48
4403	1220.43
4405.73	1192.81
4408.46	1240.97
4411.19	1188.09
4413.92	1176.67
4416.64	1206.62
4419.37	1197.93
4422.09	1214.46
4424.82	1210.15
4427.54	1204.78
4430.26	1158.59
4432.98	1226.39
4435.7	1187.38
4438.42	1156.6
4441.13	1177.14
4443.85	1147.32
4446.57	1163.62
4449.28	1167.27
4451.99	1184.53
4454.71	1159.69
4457.42	1176.8
4460.13	1162.45
4462.83	1192.33
4465.54	1161.22
4468.25	1179.63
4470.95	1154.95
4473.66	1127.2
4476.36	1161.73
4479.07	1173.16
4481.77	1169.85
4484.47	1170.7
4487.17	1166.23
4489.87	1168.97
4492.56	1173.38
4495.26	1165.4
4497.96	1130.94
4500.65	1141.82
4503.34	1141.19
4506.04	1124.69
4508.73	1138.96
4511.42	1116.1
4514.11	1133.63
4516.8	1141.6
4519.48	1112.54
4522.17	1136.65
4524.85	1100.07
4527.54	1089.06
4530.22	1114.27
4532.9	1137.45
4535.58	1072.07
4538.27	1106.05
4540.94	1140.04
4543.62	1111.03
4546.3	1087.32
4548.98	1089.32
4551.65	1093.73
4554.33	1087.46
4557	1064.36
4559.67	1101.7
4562.34	1094.05
4565.01	1078.33
4567.68	1094.74
4570.35	1083.83
4573.02	1092.49
4575.68	1095.3
4578.35	1074.5
4581.01	1074.02
4583.67	1082.43
4586.34	1082.09
4589	1052.17
4591.66	1082.17
4594.31	1073.24
4596.97	1080.39
4599.63	1084.53
4602.29	1070.18
4604.94	1051.42
4607.59	1076.54
4610.25	1058.85
4612.9	1067.46
4615.55	1029.93
4618.2	1070.59
4620.85	1040.78
4623.5	1039.52
4626.14	1050.3
4628.79	1063.34
4631.43	1045.28
4634.08	1042.55
4636.72	1040.96
4639.36	1048.13
4642	1041.12
4644.64	1034.4
4647.28	1055.66
4649.92	1041.69
4652.56	1071.68
4655.19	1002.41
4657.83	1053.44
4660.46	1032.25
4663.1	1006.57
4665.73	1047.51
4668.36	1009.18
4670.99	998.778
4673.62	1016.38
4676.24	1039.6
4678.87	998.81
4681.5	1005.15
4684.12	1010.4
4686.75	1004.37
4689.37	1017.57
4691.99	995.725
4694.61	1004.27
4697.23	1021.88
4699.85	1027.11
4702.47	1020.91
4705.09	978.507
4707.7	1000.49
4710.32	971.544
4712.93	982.19
4715.55	978.028
4718.16	1026.02
4720.77	1020.61
4723.38	1030.1
4725.99	1006.79
4728.6	949.421
4731.21	954.456
4733.81	978.807
4736.42	1004.21
4739.02	1010.33
4741.63	1003.8
4744.23	1005.25
4746.83	957.525
4749.43	947.389
4752.03	964.57
4754.63	956.659
4757.23	952.245
4759.82	950.212
4762.42	977.795
4765.01	989.615
4767.61	950.447
4770.2	980.504
4772.79	978.646
4775.38	971.102
4777.97	996.654
4780.56	954.806
4783.15	979.253
4785.74	978.556
4788.32	957.278
4790.91	946.353
4793.49	956.028
4796.07	944.051
4798.66	940.152
4801.24	947.792
4803.82	980.834
4806.4	923.208
4808.98	916.078
4811.55	948.195
4814.13	927.327
4816.71	930.798
4819.28	901.863
4821.85	944.701
4824.43	951.699
4827	923.807
4829.57	925.075
4832.14	922.837
4834.71	920.719
4837.28	919.86
4839.84	917.875
4842.41	920.375
4844.97	927.472
4847.54	900.402
4850.1	899.734
4852.66	870.311
4855.22	893.958
4857.78	938.895
4860.34	917.67
4862.9	903.102
4865.46	897.795
4868.01	909.492
4870.57	915.051
4873.12	907.406
4875.68	893.836
4878.23	903.943
4880.78	881.918
4883.33	901.444
4885.88	907.925
4888.43	900.17
4890.98	894.737
4893.53	890.473
4896.07	849.209
4898.62	869.913
4901.16	877.464
4903.7	861.2
4906.25	873.443
4908.79	849.785
4911.33	874.962
4913.87	874.988
4916.41	857.119
4918.94	894.25
4921.48	857.306
4924.02	877.758
4926.55	859.926
4929.08	851.74
4931.62	842.564
4934.15	854.913
4936.68	915.09
4939.21	857.731
4941.74	830.315
4944.27	874.997
4946.79	843.043
4949.32	862.64
4951.85	864.23
4954.37	850.266
4956.9	855.62
4959.42	845.429
4961.94	840.212
4964.46	837.591
4966.98	843.306
4969.5	844.064
4972.02	839.976
4974.53	840.695
4977.05	829.335
4979.57	863.995
4982.08	861.165
4984.59	831.665
4987.1	850.701
4989.62	822.351
4992.13	819.468
4994.64	833.71
4997.15	841.978
4999.65	817.317