File: Data/3-Raman/raw/bu19(2)w-a-ff1-fi01-v_150 (500nm)_532nm_edge_100%_x100_vis_lwd_h50um_30sx2_01.txt
#Acq. time (s)=	30
#Accumulations=	2
#Range (cm-¹)=	99...4000
#Windows=	1
#Auto scanning=	Off
#Autofocus=	Off
#Macrospot=	Off
#AutoExposure=	Off
#Spike filter=	Multiple accum.
#Delay time (s)=	2
#Binning=	1
#Readout mode=	Signal
#DeNoise=	Off
#ICS correction=	On
#Dark correction=	Off
#Inst. Process=	Off
#Detector Gain=	Best Dynamic
#Detector ADC=	50 kHz HS
#Detector temperature (°C)=	-60.09
#Instrument=	LabRAM HR Evol
#Detector=	SIN-EM FIVIS
#Objective=	x100_VIS_LWD
#Grating=	150 (500nm)
#ND Filter=	100%
#Laser=	532nm_Edge
#Hole=	49.98
#Temperature=	0
#Range=	Visible
#StageXY=	75x50mm Scan+
#StageZ=	Z motor
#X (µm)=	0
#Y (µm)=	0
#Z (µm)=	-47.2
#Full time(mm:ss)=	1:05
#Project=	21_11_26
#Sample=	BU19(2)w
#Site=
#Title=	BU19(2)w-A-FF1-FI01-V_150 (500nm)_532nm_Edge_100%_x100_VIS_LWD_H50um_30sX2
#Remark=
#Date=	26.11.2021 11:42
#Acquired=	26.11.2021 11:42:58
102.91	6191.44
107.534	5203.84
112.156	4591.16
116.775	4358.82
121.392	4384.28
126.005	3817.14
130.617	3068.58
135.227	2546.44
139.835	2388.01
144.439	2532.86
149.042	3192.06
153.643	4620.61
158.242	5626.9
162.839	4813.17
167.431	3197.73
172.023	2094.71
176.613	1569.19
181.198	1219.07
185.783	995.127
190.366	867.887
194.947	814.071
199.524	737.021
204.1	707.65
208.674	750.404
213.243	987.631
217.813	1646.78
222.38	1855.81
226.945	1121.87
231.506	740.084
236.066	764.164
240.625	1171.51
245.179	1752.56
249.732	1475.58
254.284	832.393
258.831	532.305
263.378	409.037
267.923	402.595
272.464	392.531
277.004	370.386
281.54	359.269
286.076	405.279
290.61	486.784
295.139	452.182
299.669	371.358
304.196	334.142
308.718	338.144
313.241	326.868
317.759	327.741
322.278	356.953
326.794	387.695
331.305	422.464
335.817	526.07
340.324	747.993
344.832	893.371
349.334	832.622
353.837	763.308
358.338	904.982
362.834	1081.58
367.33	902.006
371.822	643.786
376.314	537.966
380.802	520.125
385.289	544.647
389.772	631.088
394.255	873.766
398.734	1419.65
403.213	2019.64
407.688	2082.91
412.162	1795.84
416.632	1482.93
421.102	1244.97
425.568	1098.97
430.033	1113.2
434.495	1225.16
438.956	1368.55
443.413	1320.94
447.87	1305.81
452.323	1286.75
456.776	1359.19
461.224	1484.21
465.673	1397.2
470.117	1118.56
474.561	831.692
479.001	657.664
483.438	580.843
487.876	558.837
492.309	586.01
496.742	707.68
501.172	888.806
505.601	1176.94
510.025	1633.37
514.448	2179.68
518.871	2708.32
523.289	2812.43
527.707	2545.07
532.121	2128.81
536.533	1814.35
540.945	1637.33
545.353	1609.5
549.758	1613.02
554.164	1652.31
558.565	1676.72
562.965	1618.34
567.364	1494.62
571.759	1251.18
576.151	1060.93
580.544	917.453
584.933	770.496
589.319	704.352
593.706	725.268
598.088	725.392
602.468	838.258
606.848	996.847
611.224	1195.25
615.598	1483.39
619.972	2039.94
624.341	3351.92
628.709	5266.99
633.074	5567.44
637.44	3830.76
641.801	2228.67
646.16	1425.22
650.517	982.519
654.874	761.325
659.227	609.95
663.578	517.687
667.927	460.825
672.275	399.649
676.62	364.617
680.962	338.774
685.302	327.583
689.643	300.806
693.979	298.071
698.313	320.269
702.645	348.288
706.975	385.924
711.305	460.929
715.631	465.463
719.955	452.733
724.276	380.064
728.596	345.09
732.913	316.971
737.231	328.704
741.544	313.809
745.856	261.319
750.165	262.64
754.472	253.445
758.778	251.515
763.081	261.943
767.384	252.026
771.683	242.584
775.98	240.616
780.275	254.413
784.568	259.387
788.859	255.716
793.147	248.819
797.434	275.932
801.719	277.795
806.004	287.566
810.284	285.346
814.563	298.569
818.839	310.746
823.114	332.829
827.386	350.619
831.657	394.898
835.925	432.628
840.192	532.13
844.456	664.771
848.719	770.754
852.979	897.183
857.237	937.504
861.493	838.943
865.748	752.461
870	664.784
874.25	602.426
878.499	572.986
882.745	563.217
886.989	606.769
891.231	643.208
895.471	579.274
899.71	463.52
903.946	385.762
908.18	332.394
912.412	316.631
916.642	276.243
920.87	276.929
925.096	273.196
929.321	253.194
933.543	263.642
937.763	267.602
941.981	246.844
946.197	247.501
950.412	252.415
954.622	258.448
958.832	266.622
963.04	264.179
967.246	267.08
971.451	280.62
975.653	268.75
979.853	274.942
984.052	291.773
988.248	283.177
992.442	298.951
996.633	329.766
1000.82	362.954
1005.01	404.783
1009.2	439.344
1013.38	437.839
1017.57	418.105
1021.75	370.59
1025.92	379.469
1030.1	358.314
1034.27	359.458
1038.45	374.105
1042.62	400.212
1046.78	443.248
1050.95	535.919
1055.12	658.842
1059.28	694.302
1063.44	680.851
1067.6	655.705
1071.75	678.851
1075.91	731.046
1080.06	813.084
1084.21	999.164
1088.36	1230.61
1092.51	1645.4
1096.65	2285.57
1100.8	3308.99
1104.94	3944.07
1109.08	3528.97
1113.21	2436.53
1117.35	1511.52
1121.48	1052.23
1125.61	812.723
1129.74	705.699
1133.87	682.473
1137.99	705.125
1142.12	751.426
1146.24	931.805
1150.36	1196.99
1154.48	1363.06
1158.59	1343.04
1162.71	1115.23
1166.82	856.074
1170.93	664.903
1175.04	546.904
1179.14	452.683
1183.25	382.285
1187.35	341.726
1191.45	312.377
1195.55	269.741
1199.65	258.866
1203.74	261.216
1207.83	261.5
1211.92	239.511
1216.01	251.995
1220.1	248.317
1224.19	255.749
1228.27	268.215
1232.35	291.739
1236.43	306.422
1240.51	338.249
1244.58	345.998
1248.66	399.791
1252.73	524.685
1256.8	882.523
1260.87	880.067
1264.93	628.672
1269	610.256
1273.06	1384.77
1277.12	6761.04
1281.18	5599.05
1285.23	1471.56
1289.29	606.267
1293.34	500.921
1297.39	461.867
1301.44	412.66
1305.49	380.48
1309.53	368.424
1313.58	363.381
1317.62	365.262
1321.66	362.026
1325.7	354.635
1329.73	357.261
1333.77	365.865
1337.8	348.265
1341.83	362.677
1345.86	380.993
1349.88	386.273
1353.91	389.553
1357.93	486.206
1361.95	616.178
1365.97	682.457
1369.99	644.863
1374	851.324
1378.02	3518.36
1382.03	12849.3
1386.04	6495.63
1390.05	1317.46
1394.05	664.881
1398.06	673.037
1402.06	1207.15
1406.06	1116.87
1410.06	530.815
1414.05	380.19
1418.05	347.825
1422.04	301.601
1426.03	271.097
1430.02	244.399
1434.01	212.789
1438	204.875
1441.98	184.13
1445.96	177.182
1449.94	162.332
1453.92	156.341
1457.9	168.086
1461.87	146.292
1465.85	140.234
1469.82	133.198
1473.78	131.105
1477.75	129.98
1481.72	125.901
1485.68	125.738
1489.65	115.794
1493.61	122.476
1497.56	118.422
1501.52	112.443
1505.47	121.086
1509.43	115.169
1513.38	118.011
1517.33	111.148
1521.27	122.74
1525.22	125.601
1529.16	115.865
1533.11	113.905
1537.05	114.855
1540.98	109.994
1544.92	113.856
1548.86	125.468
1552.79	112.859
1556.72	115.737
1560.65	108.914
1564.58	107.891
1568.5	112.66
1572.43	115.482
1576.35	110.572
1580.27	114.349
1584.19	110.405
1588.1	117.055
1592.02	124.654
1595.93	114.926
1599.84	113.863
1603.75	123.372
1607.66	111.779
1611.57	125.134
1615.47	126.982
1619.37	132.678
1623.27	125.914
1627.17	125.875
1631.07	121.067
1634.97	126.828
1638.86	126.841
1642.75	123.056
1646.64	138.457
1650.53	129.921
1654.42	124.258
1658.3	130.098
1662.18	119.607
1666.07	126.383
1669.94	122.574
1673.82	123.533
1677.7	132.174
1681.57	119.604
1685.44	124.298
1689.31	121.301
1693.18	119.243
1697.05	106.652
1700.92	123.685
1704.78	113.941
1708.64	127.999
1712.5	113.484
1716.36	118.932
1720.21	121.525
1724.07	119.392
1727.92	124.791
1731.77	122.629
1735.62	128.925
1739.47	124.888
1743.32	117.121
1747.16	114.053
1751.01	129.655
1754.85	118.339
1758.69	130.302
1762.52	117.419
1766.36	137.861
1770.19	134.218
1774.02	130.636
1777.85	131.704
1781.68	130.956
1785.51	119.024
1789.33	118.289
1793.16	112.873
1796.98	116.824
1800.8	116.083
1804.62	107.738
1808.43	118.205
1812.25	117.365
1816.06	111.785
1819.87	117.474
1823.68	109.924
1827.49	112.732
1831.3	112.678
1835.1	104.114
1838.9	115.316
1842.71	107.671
1846.51	115.983
1850.3	110.219
1854.1	101.609
1857.89	110.764
1861.69	107.721
1865.48	109.332
1869.27	105.376
1873.05	104.228
1876.84	108.655
1880.62	114.919
1884.4	108.307
1888.19	115.526
1891.96	113.662
1895.74	104.442
1899.52	109.946
1903.29	114.577
1907.06	118.314
1910.83	111.933
1914.6	109.272
1918.37	110.306
1922.13	108.64
1925.9	113.463
1929.66	109.971
1933.42	111.125
1937.18	115.075
1940.94	113.436
1944.69	104.303
1948.44	120.441
1952.2	116.827
1955.95	112.22
1959.69	119.761
1963.44	122.566
1967.19	115.034
1970.93	120.61
1974.67	125.196
1978.41	132.559
1982.15	140.817
1985.89	147.16
1989.62	156.266
1993.35	148.553
1997.09	156.641
2000.82	156.318
2004.55	159.706
2008.27	159.367
2012	159.912
2015.72	154.943
2019.44	144.562
2023.16	149.874
2026.88	143.358
2030.6	135.028
2034.31	134.09
2038.03	135.032
2041.74	137.792
2045.45	129.554
2049.16	122.235
2052.86	123.18
2056.57	122.301
2060.27	117.816
2063.98	118.904
2067.67	121.865
2071.37	114.71
2075.07	113.07
2078.77	115.13
2082.46	109.795
2086.15	111.851
2089.84	94.2738
2093.53	106.366
2097.22	115.73
2100.9	106.484
2104.59	109.288
2108.27	120.443
2111.95	115.769
2115.63	102.726
2119.31	108.264
2122.98	108.18
2126.66	96.9415
2130.33	103.317
2134	105.04
2137.67	115.994
2141.34	105.671
2145	113.791
2148.67	105.32
2152.33	108.813
2155.99	100.381
2159.65	104.793
2163.31	99.1527
2166.96	101.757
2170.62	101.639
2174.27	99.741
2177.92	102.42
2181.57	105.111
2185.22	103.246
2188.87	100.501
2192.51	103.253
2196.15	106.96
2199.8	101.586
2203.44	105.334
2207.07	98.1496
2210.71	95.5358
2214.35	104.83
2217.98	101.321
2221.61	98.7214
2225.24	100.718
2228.87	104.556
2232.5	103.796
2236.12	104.89
2239.75	96.7282
2243.37	111.715
2246.99	97.0318
2250.61	104.627
2254.23	101.079
2257.85	97.5283
2261.46	101.442
2265.07	111.912
2268.68	102.728
2272.29	101.054
2275.9	102.17
2279.51	101.375
2283.11	101.454
2286.72	111.921
2290.32	98.7717
2293.92	102.615
2297.52	95.1099
2301.11	96.1214
2304.71	109.435
2308.3	112.31
2311.9	114.223
2315.49	116.118
2319.08	190.969
2322.66	759.302
2326.25	704.586
2329.84	246.259
2333.42	119.435
2337	109.843
2340.58	111.559
2344.16	118.899
2347.73	113.062
2351.31	118.476
2354.88	109.842
2358.45	106.832
2362.03	103.827
2365.59	115.7
2369.16	108.057
2372.73	111.579
2376.29	109.534
2379.85	108.422
2383.41	109.17
2386.97	111.765
2390.53	112.535
2394.09	110.573
2397.64	103.147
2401.2	108.596
2404.75	104.02
2408.3	113.207
2411.85	103.187
2415.39	112.456
2418.94	101.551
2422.48	108.12
2426.03	111.047
2429.57	107.548
2433.11	102.209
2436.64	104.286
2440.18	111.957
2443.72	99.1835
2447.25	107.823
2450.78	110.912
2454.31	109.343
2457.84	101.111
2461.37	99.3553
2464.89	96.6423
2468.42	98.5594
2471.94	95.8378
2475.46	98.6182
2478.98	106.094
2482.5	101.326
2486.01	101.234
2489.53	96.3785
2493.04	99.1023
2496.55	102.702
2500.06	107.264
2503.57	95.8765
2507.08	105.987
2510.58	100.193
2514.09	99.0791
2517.59	90.5623
2521.09	99.7099
2524.59	96.7236
2528.09	95.6926
2531.59	100.231
2535.08	101.085
2538.58	102.89
2542.07	107.486
2545.56	99.2139
2549.05	102.059
2552.54	98.4433
2556.02	97.6234
2559.51	96.8492
2562.99	100.715
2566.47	92.5479
2569.95	103.952
2573.43	105.158
2576.91	107.328
2580.38	93.5475
2583.85	92.8916
2587.33	112.096
2590.8	101.977
2594.27	106.015
2597.74	104.335
2601.2	103.634
2604.67	90.4736
2608.13	101.183
2611.59	100.316
2615.06	104.179
2618.51	95.5951
2621.97	101.378
2625.43	101.376
2628.88	98.4641
2632.33	101.299
2635.79	103.147
2639.24	100.168
2642.69	104.836
2646.13	98.9538
2649.58	98.8101
2653.02	105.315
2656.47	102.257
2659.91	101.088
2663.35	101.807
2666.79	98.7331
2670.22	102.27
2673.66	99.2012
2677.09	103.669
2680.52	98.7702
2683.95	101.389
2687.39	101.235
2690.81	94.6215
2694.24	91.778
2697.66	93.5741
2701.09	94.4588
2704.51	106.508
2707.93	101.815
2711.35	99.984
2714.77	102.825
2718.18	95.4474
2721.6	102.989
2725.01	99.3622
2728.42	102.274
2731.84	96.7826
2735.24	97.826
2738.65	97.9345
2742.06	101.791
2745.46	100.94
2748.86	105.711
2752.27	102.027
2755.67	100.212
2759.07	96.4993
2762.46	101.263
2765.86	99.4069
2769.25	109.786
2772.65	95.6464
2776.04	105.999
2779.43	93.7216
2782.82	97.4463
2786.2	99.278
2789.59	101.104
2792.98	106.684
2796.36	108.496
2799.74	98.1023
2803.12	107.406
2806.5	104.51
2809.88	95.0614
2813.25	105.274
2816.63	107.982
2820	107.881
2823.37	100.331
2826.74	104.93
2830.11	106.736
2833.48	102.963
2836.84	102.007
2840.21	113.178
2843.57	96.4231
2846.93	111.37
2850.29	105.855
2853.65	101.29
2857.01	110.719
2860.36	108.021
2863.72	113.758
2867.07	106.39
2870.42	105.574
2873.77	110.386
2877.12	109.562
2880.47	119.088
2883.81	104.129
2887.16	107.054
2890.5	108.093
2893.84	109.127
2897.18	117.699
2900.52	113.968
2903.86	104.54
2907.19	118.75
2910.53	116.866
2913.86	115.919
2917.19	113.072
2920.52	113.993
2923.85	117.744
2927.18	114.864
2930.51	115.749
2933.83	126.063
2937.15	121.247
2940.48	127.752
2943.8	121.057
2947.11	120.967
2950.43	127.465
2953.75	134.889
2957.06	128.216
2960.38	129.084
2963.69	120.578
2967	134.599
2970.31	125.206
2973.62	122.402
2976.92	133.673
2980.23	122.451
2983.53	129.04
2986.84	131.886
2990.14	130.045
2993.44	128.208
2996.73	123.558
3000.03	135.831
3003.33	135.887
3006.62	135.003
3009.91	136.953
3013.2	143.62
3016.49	141.818
3019.78	152.266
3023.07	136.31
3026.35	144.878
3029.64	137.402
3032.92	142.199
3036.2	135.65
3039.48	145.168
3042.76	151.858
3046.04	148.144
3049.32	140.64
3052.59	142.603
3055.86	148.364
3059.14	151.279
3062.41	157.942
3065.68	156.091
3068.94	153.271
3072.21	163.704
3075.48	148.385
3078.74	168.313
3082	174.913
3085.26	174.075
3088.52	162.787
3091.78	173.377
3095.04	173.537
3098.29	176.327
3101.55	177.328
3104.8	184.953
3108.05	171.737
3111.3	188.942
3114.55	204.192
3117.8	188.045
3121.04	192.847
3124.29	200.508
3127.53	205.312
3130.77	213.922
3134.02	216.82
3137.25	210.18
3140.49	222.594
3143.73	214.032
3146.96	230.261
3150.2	227.436
3153.43	244.643
3156.66	238.952
3159.89	242.807
3163.12	239.021
3166.35	264.817
3169.57	262.918
3172.8	259.091
3176.02	272.43
3179.24	275.247
3182.46	284.738
3185.68	283.74
3188.9	295.104
3192.12	295.016
3195.33	287.303
3198.55	290.07
3201.76	301.399
3204.97	303.214
3208.18	313.604
3211.39	325.907
3214.6	323.005
3217.8	339.153
3221.01	331.517
3224.21	346.724
3227.41	336.281
3230.61	344.871
3233.81	351.586
3237.01	362.086
3240.21	345.065
3243.4	359.476
3246.59	369.153
3249.79	355.013
3252.98	381.898
3256.17	402.143
3259.36	404.265
3262.54	385.322
3265.73	399.743
3268.92	399.784
3272.1	429.398
3275.28	429.373
3278.46	418.834
3281.64	422.535
3284.82	439.519
3288	446.957
3291.17	450.535
3294.35	452.241
3297.52	441.544
3300.69	474.665
3303.86	474.552
3307.03	496.2
3310.2	509.218
3313.36	481.281
3316.53	507.476
3319.69	535.514
3322.85	518.935
3326.02	563.947
3329.18	568.198
3332.33	569.62
3335.49	589.029
3338.65	605.629
3341.8	626.97
3344.95	652.074
3348.11	672.606
3351.26	692.35
3354.41	707.37
3357.56	737.55
3360.7	769.659
3363.85	807.525
3366.99	789.787
3370.13	840
3373.28	849.706
3376.42	894.446
3379.56	906.212
3382.69	958.666
3385.83	960.076
3388.97	989.949
3392.1	1035.01
3395.23	1063.03
3398.36	1115.43
3401.49	1168.52
3404.62	1236.03
3407.75	1264.85
3410.88	1305.2
3414	1390.35
3417.13	1428.64
3420.25	1500.26
3423.37	1612.87
3426.49	1711.9
3429.61	1815.46
3432.73	1884.44
3435.84	1983.59
3438.96	2172.92
3442.07	2317.58
3445.18	2458.3
3448.29	2668.05
3451.4	2932.85
3454.51	3374.15
3457.62	4035.73
3460.72	5087.83
3463.83	6227.59
3466.93	6363.03
3470.03	5713.4
3473.13	4683.09
3476.23	3980.18
3479.33	3578.63
3482.43	3295.11
3485.53	3160.45
3488.62	3071.53
3491.71	3029.43
3494.81	3007.06
3497.9	3000.63
3500.99	2980.79
3504.07	3001.59
3507.16	2985.13
3510.25	3030.82
3513.33	3087.75
3516.41	3195.06
3519.5	3301.16
3522.58	3442.74
3525.66	3589.9
3528.73	3736.5
3531.81	3996.74
3534.89	4228.88
3537.96	4556.21
3541.03	4718.66
3544.11	4907.68
3547.18	4935.46
3550.25	4877
3553.32	4496.75
3556.38	4007.91
3559.45	3425.52
3562.51	2954.17
3565.58	2489.29
3568.64	2120.36
3571.7	1808.7
3574.76	1568.02
3577.82	1406.07
3580.87	1245.86
3583.93	1117.8
3586.98	1002.92
3590.04	939.267
3593.09	868.883
3596.14	821.259
3599.19	763.168
3602.24	749.633
3605.29	709.522
3608.33	651.42
3611.38	628.363
3614.42	615.695
3617.46	588.852
3620.5	539.416
3623.54	579.679
3626.58	555.804
3629.62	527.274
3632.65	510.045
3635.69	506.93
3638.72	487.004
3641.76	469.976
3644.79	436.073
3647.82	417.334
3650.84	420.118
3653.87	391.909
3656.9	396.128
3659.92	367.358
3662.95	351.678
3665.97	335.907
3668.99	316.196
3672.01	304.089
3675.03	296.701
3678.05	289.323
3681.07	272.506
3684.08	266.05
3687.1	264.318
3690.11	237.042
3693.12	244.774
3696.13	249.675
3699.14	236.521
3702.15	227.198
3705.16	232.101
3708.16	223.709
3711.17	218.131
3714.17	205.874
3717.17	206.899
3720.17	204.132
3723.17	206.097
3726.17	190.907
3729.17	192.835
3732.16	184.275
3735.16	181.409
3738.15	173.764
3741.14	180.384
3744.13	170.802
3747.13	172.627
3750.11	180.136
3753.1	167.673
3756.09	165.666
3759.07	160.82
3762.06	168.302
3765.04	159.652
3768.02	171.848
3771	156.601
3773.98	161.246
3776.96	146.993
3779.94	149.769
3782.91	145.941
3785.89	148.728
3788.86	150.577
3791.83	149.604
3794.8	149.598
3797.77	148.661
3800.74	143.013
3803.71	142.103
3806.68	145.923
3809.64	142.191
3812.61	136.575
3815.57	147.032
3818.53	137.636
3821.49	144.327
3824.45	135.878
3827.41	139.746
3830.36	142.672
3833.32	136.116
3836.27	142.853
3839.23	136.308
3842.18	140.211
3845.13	142.215
3848.08	130.898
3851.03	130.049
3853.98	139.695
3856.92	136.954
3859.87	136.119
3862.81	141.022
3865.75	130.614
3868.7	135.511
3871.64	126.029
3874.57	139.547
3877.51	145.4
3880.45	139.721
3883.39	129.217
3886.32	138.871
3889.25	137.945
3892.18	137.976
3895.12	133.191
3898.05	140.89
3900.97	140.879
3903.9	129.326
3906.83	135.064
3909.75	138.894
3912.68	136.944
3915.6	130.177
3918.52	132.051
3921.44	134.906
3924.36	143.492
3927.28	133.826
3930.2	128.952
3933.11	141.325
3936.03	137.438
3938.94	141.241
3941.86	130.706
3944.77	124.947
3947.68	129.728
3950.59	133.564
3953.49	131.666
3956.4	134.561
3959.31	133.637
3962.21	132.719
3965.12	128.932
3968.02	131.861
3970.92	143.435
3973.82	129.107
3976.72	134.929
3979.61	141.708
3982.51	135.028
3985.41	141.8
3988.3	139.914
3991.19	134.176
3994.09	132.267
3996.98	146.74
3999.87	141.006