File: Data/3-Raman/raw/bu19w-d-ff2-fi09-v_1800 (450-850nm)_532nm_edge_100%_x100_vis_lwd_h50um_30sx2_01.txt
#Acq. time (s)=	30
#Accumulations=	2
#Range (cm-¹)=	1200...2365
#Windows=	3
#Auto scanning=	Off
#Autofocus=	Off
#Macrospot=	Off
#AutoExposure=	Off
#Spike filter=	Multiple accum.
#Delay time (s)=	2
#Binning=	1
#Readout mode=	Signal
#DeNoise=	Off
#ICS correction=	On
#Dark correction=	Off
#Inst. Process=	Off
#Detector Gain=	Best Dynamic
#Detector ADC=	50 kHz HS
#Detector temperature (°C)=	-60.09
#Instrument=	LabRAM HR Evol
#Detector=	SIN-EM FIVIS
#Objective=	x100_VIS_LWD
#Grating=	1800 (450-850nm)
#ND Filter=	100%
#Laser=	532nm_Edge
#Hole=	49.98
#Temperature=	0
#Range=	Visible
#StageXY=	75x50mm Scan+
#StageZ=	Z motor
#X (µm)=	0
#Y (µm)=	0
#Z (µm)=	70.2
#Full time(mm:ss)=	3:18
#Project=	21_11_22
#Sample=	BU19w
#Site=
#Title=	BU19w-D-FF2-FI09-V_1800 (450-850nm)_532nm_Edge_100%_x100_VIS_LWD_H50um_30sX2
#Remark=
#Date=	22.11.2021 13:31
#Acquired=	22.11.2021 13:31:07
1202.84	47.7768
1203.95	49.827
1205.06	55.1221
1206.17	48.6474
1207.29	43.2782
1208.39	48.5475
1209.51	49.5441
1210.62	49.4952
1211.72	40.9687
1212.84	43.0891
1213.94	41.962
1215.05	39.7886
1216.16	44.005
1217.27	41.8615
1218.38	36.5445
1219.49	44.9674
1220.6	41.7096
1221.71	42.7146
1222.81	39.5457
1223.92	42.7042
1225.03	43.6611
1226.14	47.7551
1227.24	44.7255
1228.35	54.0542
1229.46	65.6042
1230.56	80.2936
1231.67	76.1175
1232.78	90.8695
1233.88	89.7995
1234.99	92.8347
1236.09	73.8462
1237.2	67.528
1238.3	66.4845
1239.41	54.9295
1240.51	54.9458
1241.62	57.0396
1242.72	50.7033
1243.83	53.81
1244.93	59.0289
1246.03	62.1294
1247.14	65.2641
1248.24	71.4753
1249.34	72.4657
1250.45	81.8041
1251.55	77.6684
1252.65	76.6367
1253.75	79.7836
1254.86	67.2328
1255.96	61.9772
1257.06	64.1056
1258.16	66.118
1259.26	55.7901
1260.36	53.5583
1261.46	64.2016
1262.56	69.3584
1263.66	97.5697
1264.76	73.6017
1265.86	50.6543
1266.96	44.3695
1268.06	45.3717
1269.16	45.3716
1270.26	43.3275
1271.36	44.4162
1272.46	48.6154
1273.56	43.4007
1274.66	40.2817
1275.76	46.6261
1276.85	43.4788
1277.95	51.8899
1279.05	57.1868
1280.15	58.2184
1281.24	97.0327
1282.34	215.205
1283.44	776.487
1284.53	642.472
1285.63	121.355
1286.73	60.3489
1287.82	58.2583
1288.92	49.8235
1290.01	44.5523
1291.11	43.5475
1292.21	38.2828
1293.3	35.1909
1294.4	37.2987
1295.49	40.4413
1296.58	37.2523
1297.68	37.2603
1298.77	35.1503
1299.87	31.989
1300.96	34.0861
1302.05	34.0804
1303.15	34.0487
1304.24	37.2026
1305.33	29.8197
1306.42	37.2109
1307.52	34.0491
1308.61	35.1069
1309.7	31.9535
1310.79	31.9412
1311.88	37.2193
1312.98	27.7299
1314.07	33.0034
1315.16	27.7289
1316.25	29.8409
1317.34	29.8385
1318.43	31.9275
1319.52	34.0049
1320.61	27.6631
1321.7	29.7712
1322.79	33.9655
1323.88	32.8521
1324.97	31.8514
1326.06	37.1649
1327.15	33.9919
1328.23	30.799
1329.32	28.6466
1330.41	32.8107
1331.5	30.6708
1332.59	36.9371
1333.67	33.7659
1334.76	27.4614
1335.85	30.579
1336.94	30.5745
1338.02	31.6218
1339.11	28.4669
1340.2	31.5769
1341.28	31.5709
1342.37	31.554
1343.45	31.508
1344.54	34.5945
1345.63	27.2797
1346.71	30.382
1347.8	32.4371
1348.88	29.29
1349.96	32.4265
1351.05	30.3785
1352.13	38.6148
1353.22	31.3346
1354.3	31.3158
1355.39	32.3313
1356.47	31.2684
1357.55	30.2
1358.63	29.1513
1359.72	35.3503
1360.8	31.2158
1361.88	33.2836
1362.97	38.4266
1364.05	41.4837
1365.13	38.3768
1366.21	39.4184
1367.29	38.372
1368.37	44.5342
1369.45	70.2497
1370.54	41.3409
1371.62	37.2038
1372.7	43.3807
1373.78	47.4785
1374.86	38.1917
1375.94	45.4698
1377.02	54.7198
1378.09	59.7428
1379.18	58.6538
1380.25	74.9798
1381.33	69.8054
1382.41	89.3649
1383.49	92.5186
1384.57	118.925
1385.65	219.364
1386.72	1091.69
1387.8	1143.42
1388.88	153.755
1389.96	82.9916
1391.03	57.3729
1392.11	52.2493
1393.19	50.2169
1394.26	45.0737
1395.34	43.0146
1396.42	38.9366
1397.49	39.9714
1398.57	35.891
1399.64	37.9932
1400.72	39.0553
1401.79	32.8698
1402.87	42.0736
1403.94	34.8833
1405.02	34.8909
1406.09	44.1288
1407.17	56.4476
1408.24	111.729
1409.31	101.456
1410.39	45.2271
1411.46	37.9839
1412.53	30.8143
1413.61	33.9025
1414.68	26.7237
1415.75	28.7817
1416.82	30.8275
1417.9	31.8271
1418.97	28.7452
1420.04	31.8881
1421.11	28.7084
1422.18	24.5998
1423.26	25.6334
1424.33	30.7299
1425.4	26.6021
1426.47	26.6072
1427.54	26.6281
1428.61	23.5811
1429.68	25.6176
1430.75	23.5286
1431.82	21.4843
1432.89	28.6546
1433.96	22.4972
1435.02	23.5129
1436.09	23.5186
1437.16	25.5837
1438.23	19.4358
1439.3	27.6342
1440.37	22.504
1441.43	22.4963
1442.5	21.4864
1443.57	18.3999
1444.64	18.3905
1445.7	25.5728
1446.77	21.465
1447.84	19.402
1448.9	21.4419
1449.97	20.4136
1451.04	19.39
1452.1	24.5097
1453.17	21.4382
1454.23	21.4271
1455.3	21.4209
1456.36	20.3977
1457.43	21.4169
1458.49	20.3809
1459.56	20.3643
1460.62	20.3433
1461.69	18.3162
1462.75	19.2805
1463.81	18.2514
1464.88	23.346
1465.94	21.3004
1467	20.2648
1468.07	22.2892
1469.13	15.1465
1470.19	24.3047
1471.25	21.2373
1472.32	19.2028
1473.38	19.1935
1474.44	22.2324
1475.5	20.1885
1476.56	17.1246
1477.62	17.1034
1478.68	21.1523
1479.75	18.1193
1480.81	19.136
1481.87	21.1212
1482.93	18.071
1483.99	20.0978
1485.05	21.0979
1486.11	21.0779
1487.17	25.1162
1488.22	18.0223
1489.28	18.0179
1490.34	23.0679
1491.4	16.9991
1492.46	22.0425
1493.52	16.9702
1494.58	17.9721
1495.63	16.9594
1496.69	15.9514
1497.75	20.9981
1498.81	14.9322
1499.86	15.9328
1500.92	18.9466
1501.98	16.9295
1503.03	14.8964
1504.09	15.9028
1505.15	18.9233
1506.2	19.9288
1507.26	16.9062
1508.31	18.902
1509.37	16.8519
1510.42	18.8378
1511.48	18.8476
1512.53	17.8248
1513.59	22.8193
1514.64	16.7973
1515.7	17.8044
1516.75	21.8202
1517.8	18.8054
1518.86	20.8133
1519.91	21.8047
1520.96	16.768
1522.02	18.7606
1523.07	19.768
1524.12	19.7765
1525.17	16.7604
1526.23	16.7514
1527.28	18.7466
1528.33	17.7548
1529.38	17.7495
1530.43	19.7722
1531.48	18.77
1532.53	20.7642
1533.59	17.7284
1534.64	18.7062
1535.69	18.6921
1536.74	19.7188
1537.79	16.7417
1538.84	19.735
1539.89	21.7148
1540.94	17.6867
1541.98	18.6961
1543.03	27.7268
1544.08	19.7158
1545.13	18.7016
1546.18	18.6886
1547.23	19.6923
1548.28	16.7379
1549.33	17.7398
1550.37	18.7274
1551.42	18.7108
1552.47	19.6928
1553.52	21.6918
1554.56	20.6909
1555.61	23.6745
1556.65	16.6452
1557.7	22.6302
1558.75	18.6335
1559.79	18.6414
1560.84	17.6351
1561.88	18.6481
1562.93	18.5278
1563.98	21.603
1565.02	21.618
1566.07	20.621
1567.11	17.6096
1568.15	20.6046
1569.2	18.5945
1570.24	24.57
1571.29	15.5809
1572.33	19.5907
1573.37	24.5875
1574.42	16.5703
1575.46	22.5297
1576.5	21.5286
1577.55	21.5326
1578.59	18.5298
1579.63	23.4974
1580.67	15.5219
1581.72	22.4927
1582.76	18.5048
1583.8	20.4782
1584.84	16.4879
1585.88	20.4723
1586.92	20.4778
1587.96	24.4649
1589	22.4657
1590.04	23.4364
1591.08	18.4322
1592.12	19.4266
1593.16	19.4171
1594.2	19.4167
1595.24	21.402
1596.28	19.3948
1597.32	21.3623
1598.36	23.3173
1599.4	23.2907
1600.44	22.2782
1601.48	18.3156
1602.51	21.2813
1603.55	22.2781
1604.59	20.3012
1605.63	20.2968
1606.66	20.2754
1607.7	20.3192
1608.74	21.2127
1609.77	24.8434
1610.81	22.4579
1611.85	20.1983
1612.88	20.9644
1613.92	23.4889
1614.95	22.8746
1615.99	22.5528
1617.03	24.4585
1618.06	20.198
1619.1	22.8856
1620.13	25.7749
1621.17	23.5336
1622.2	23.9367
1623.23	25.9088
1624.27	21.4672
1625.3	23.6806
1626.34	24.8778
1627.37	23.2138
1628.4	23.734
1629.44	22.9897
1630.47	26.6887
1631.29	22.9811
1632.33	24.95
1633.38	24.9384
1634.42	22.9522
1635.47	24.9115
1636.51	26.8767
1637.56	19
1638.6	23.9248
1639.65	21.9478
1640.69	23.9111
1641.73	20.9464
1642.78	22.9182
1643.82	24.8753
1644.86	24.864
1645.91	25.8569
1646.95	21.9276
1647.99	22.9278
1649.03	21.9475
1650.08	24.8966
1651.12	24.898
1652.16	21.9463
1653.2	20.9808
1654.24	27.8923
1655.28	22.9468
1656.33	28.8493
1657.37	22.9215
1658.41	24.9075
1659.45	25.8894
1660.49	21.9804
1661.53	23.9295
1662.57	21.9339
1663.61	22.9741
1664.65	21.9401
1665.69	21.9315
1666.72	20.965
1667.76	23.9406
1668.8	21.9599
1669.84	22.9496
1670.88	22.951
1671.92	22.9603
1672.96	24.9464
1674	19.998
1675.03	20.9782
1676.07	21.9497
1677.11	22.927
1678.15	19.9526
1679.18	19.9491
1680.22	19.9458
1681.25	21.9162
1682.29	19.9326
1683.33	23.8808
1684.36	18.9478
1685.4	22.8878
1686.43	21.8838
1687.47	21.87
1688.51	17.9297
1689.54	15.9554
1690.58	19.8832
1691.61	18.8785
1692.64	16.906
1693.68	22.8227
1694.71	21.8212
1695.75	20.8179
1696.78	17.8607
1697.81	16.8706
1698.85	17.845
1699.88	18.8126
1700.91	20.7705
1701.95	21.7548
1702.98	18.8018
1704.01	19.7647
1705.04	18.7611
1706.08	15.7967
1707.11	14.8092
1708.14	17.7488
1709.17	17.7503
1710.2	18.7028
1711.23	19.6546
1712.27	14.7637
1713.3	17.6959
1714.33	19.6269
1715.36	15.694
1716.39	15.6826
1717.42	15.6806
1718.45	18.5846
1719.48	17.5926
1720.51	18.5467
1721.54	18.5398
1722.56	15.6056
1723.59	16.5635
1724.62	19.4576
1725.65	19.4411
1726.68	17.461
1727.71	16.4906
1728.74	16.5065
1729.76	18.4312
1730.79	16.4778
1731.82	17.4178
1732.85	16.434
1733.87	16.424
1734.9	16.4126
1735.93	16.3969
1736.95	20.2099
1737.98	17.3067
1739.01	17.2908
1740.03	16.3254
1741.06	17.2728
1742.08	15.3518
1743.11	20.1277
1744.13	18.1947
1745.16	15.3139
1746.18	18.1775
1747.21	16.2775
1748.23	16.2847
1749.26	18.1802
1750.28	16.2533
1751.31	16.2389
1752.33	15.2737
1753.35	17.1641
1754.38	17.1422
1755.4	14.2883
1756.42	15.2393
1757.44	15.2344
1758.47	15.223
1759.49	18.0677
1760.51	17.1183
1761.53	17.1249
1762.56	15.2296
1763.58	18.0838
1764.6	13.3179
1765.62	15.2124
1766.64	15.1841
1767.66	13.2867
1768.68	18.9996
1769.7	14.2505
1770.72	17.1101
1771.74	13.304
1772.76	16.1729
1773.78	16.1744
1774.8	19.0204
1775.82	15.1956
1776.84	14.2332
1777.86	15.1894
1778.88	16.1432
1779.9	16.1517
1780.92	15.204
1781.94	18.0746
1782.95	15.2081
1783.97	17.118
1784.99	18.0984
1786.01	16.2125
1787.03	13.3505
1788.04	17.1851
1789.06	17.1655
1790.08	15.2518
1791.09	14.2948
1792.11	16.2154
1793.13	17.1974
1794.14	16.2475
1795.16	15.2929
1796.17	16.2528
1797.19	16.2398
1798.21	16.2314
1799.22	16.2308
1800.24	15.2774
1801.25	17.206
1802.27	17.2171
1803.28	14.3393
1804.29	13.3785
1805.31	14.3405
1806.32	16.2681
1807.34	16.2682
1808.35	15.2999
1809.36	15.2985
1810.38	16.2692
1811.39	16.2791
1812.4	17.2579
1813.41	15.3261
1814.43	16.287
1815.44	16.2788
1816.45	15.3165
1817.46	17.255
1818.47	15.3261
1819.49	14.3632
1820.5	17.2664
1821.51	16.2948
1822.52	15.3303
1823.53	15.3293
1824.54	15.3304
1825.55	14.3612
1826.56	15.3221
1827.57	16.2826
1828.58	19.1889
1829.59	12.4142
1830.6	18.232
1831.61	14.3496
1832.62	16.2577
1833.63	14.3861
1834.64	15.2962
1835.65	16.232
1836.65	14.3347
1837.66	15.2792
1838.67	12.3501
1839.68	15.2254
1840.69	14.2607
1841.7	16.1879
1842.7	15.2211
1843.71	15.2435
1844.72	16.146
1845.72	13.2608
1846.73	16.1356
1847.74	14.1908
1848.74	15.138
1849.75	16.0941
1850.75	14.1676
1851.76	14.1497
1852.76	16.05
1853.77	16.0438
1854.78	14.1215
1855.78	15.0654
1856.79	14.0941
1857.79	14.0964
1858.79	15.0597
1859.8	16.9632
1860.8	16.9454
1861.81	15.0208
1862.81	14.0474
1863.81	14.974
1864.82	16.8517
1865.82	14.944
1866.82	16.8411
1867.83	15.8851
1868.83	14.9284
1869.83	15.8666
1870.83	13.9589
1871.84	16.7899
1872.84	13.9251
1873.84	15.7955
1874.84	15.7571
1875.84	18.6325
1876.84	14.859
1877.84	14.8546
1878.84	12.9414
1879.84	14.7971
1880.84	14.801
1881.84	13.835
1882.85	15.7368
1883.85	15.7418
1884.84	16.6659
1885.84	13.8158
1886.84	14.7443
1887.84	13.8083
1888.84	18.5128
1889.84	14.7384
1890.84	15.6513
1891.84	15.6423
1892.83	14.7034
1893.83	14.7103
1894.83	14.7135
1895.83	14.7047
1896.83	16.5705
1897.82	14.6861
1898.82	13.7541
1899.82	11.8781
1900.81	12.8113
1901.81	11.8666
1902.81	11.862
1903.8	15.6056
1904.8	15.6024
1905.79	14.6679
1906.79	15.6174
1907.79	16.5766
1908.78	15.6395
1909.78	17.5181
1910.77	15.6363
1911.77	14.7071
1912.76	11.8818
1913.76	15.648
1914.75	14.6937
1915.74	14.6978
1916.74	13.7713
1917.73	15.6618
1918.72	15.6726
1919.72	14.7258
1920.71	17.5523
1921.7	15.6511
1922.7	17.5463
1923.69	13.7788
1924.68	13.7868
1925.67	14.7375
1926.66	15.6937
1927.66	14.7595
1928.65	19.5064
1929.64	15.6979
1930.63	13.7959
1931.62	13.8287
1932.61	12.9077
1933.61	14.8027
1934.6	15.7404
1935.59	13.8275
1936.58	15.7405
1937.57	14.7948
1938.56	17.6724
1939.55	14.8021
1940.54	15.76
1941.52	13.853
1942.51	12.9082
1943.5	15.7846
1944.49	13.8694
1945.48	12.909
1946.47	13.8691
1947.46	13.884
1948.44	17.7414
1949.43	16.7958
1950.42	13.9181
1951.41	17.7238
1952.39	13.873
1953.38	13.8929
1954.37	15.8253
1955.36	14.8714
1956.34	15.8267
1957.33	14.8565
1958.31	16.7635
1959.3	11.9608
1960.29	13.8802
1961.27	15.8021
1962.26	13.879
1963.24	14.8425
1964.23	14.8496
1965.21	17.7332
1966.2	15.8029
1967.18	16.7423
1968.17	14.8105
1969.15	16.7247
1970.14	13.844
1971.12	12.8733
1972.1	16.7049
1973.09	14.7932
1974.07	17.6709
1975.05	18.6199
1976.04	13.8174
1977.02	14.775
1978	14.7653
1978.98	17.6306
1979.97	13.7908
1980.95	13.7773
1981.93	16.6384
1982.91	16.6279
1983.89	17.5891
1984.88	11.8427
1985.86	14.6774
1986.84	16.5492
1987.82	13.6977
1988.8	15.6249
1989.78	14.6399
1990.76	13.7416
1991.74	15.5171
1992.72	15.1823
1993.7	15.3937
1994.68	13.6136
1995.66	13.1339
1996.64	16.5789
1997.62	15.7534
1998.6	14.2898
1999.57	13.3889
2000.55	14.8108
2001.53	13.3482
2002.51	13.6655
2003.49	12.4538
2004.47	14.1266
2005.44	16.291
2006.42	16.1205
2007.4	14.7925
2008.38	14.9133
2009.35	14.0673
2010.33	14.5039
2011.3	14.3293
2012.18	14.9499
2013.17	14.0158
2014.16	14.969
2015.15	14.0139
2016.14	15.8664
2017.13	16.7891
2018.11	16.787
2019.1	13.0391
2020.09	14.899
2021.08	14.8851
2022.06	14.8667
2023.05	13.915
2024.04	13.9376
2025.02	14.8829
2026.01	13.04
2027	13.9297
2027.98	14.8403
2028.97	12.048
2029.96	15.7999
2030.94	17.6854
2031.93	15.773
2032.91	16.7389
2033.9	12.0641
2034.88	16.7396
2035.87	12.0571
2036.85	14.8489
2037.83	14.8323
2038.82	14.8233
2039.8	14.8142
2040.79	15.7559
2041.77	12.9626
2042.75	15.7624
2043.74	14.8483
2044.72	15.7534
2045.7	12.9528
2046.69	15.7619
2047.67	16.7124
2048.65	15.7702
2049.63	15.7719
2050.62	15.7821
2051.6	16.7303
2052.58	14.853
2053.56	15.7814
2054.54	12.0417
2055.52	15.7906
2056.5	15.8003
2057.48	15.7968
2058.46	14.8633
2059.45	12.9921
2060.43	14.8727
2061.4	16.7528
2062.39	15.8268
2063.37	16.7788
2064.34	13.0265
2065.32	14.9124
2066.3	13.0332
2067.28	15.8391
2068.26	15.8606
2069.24	14.9365
2070.22	14.9325
2071.2	16.816
2072.18	15.8874
2073.15	14.023
2074.13	15.9069
2075.11	14.9515
2076.09	13.0713
2077.06	17.8079
2078.04	14.9764
2079.02	14.9731
2080	13.0858
2080.97	14.9734
2081.95	14.9733
2082.93	16.8634
2083.9	15.9322
2084.88	14.0449
2085.85	16.8855
2086.83	14.0536
2087.8	15.9523
2088.78	16.9085
2089.75	16.9292
2090.73	15.9955
2091.7	16.0023
2092.68	16.9446
2093.65	15.0373
2094.63	15.9774
2095.6	15.971
2096.57	13.1211
2097.55	13.1211
2098.52	15.0283
2099.5	14.0784
2100.47	15.0193
2101.44	16.9171
2102.41	15.9766
2103.39	15.0354
2104.36	15.0381
2105.33	14.0749
2106.3	14.0662
2107.27	14.0721
2108.25	18.821
2109.22	15.9643
2110.19	15.0182
2111.16	14.0745
2112.13	15.0233
2113.1	15.018
2114.07	16.9082
2115.04	18.802
2116.01	14.0408
2116.99	14.9762
2117.96	14.0271
2118.92	15.9339
2119.9	15.944
2120.86	15.946
2121.83	14.9822
2122.8	14.9577
2123.77	15.8881
2124.74	15.878
2125.71	14.9282
2126.68	14.9246
2127.65	13.9754
2128.61	15.856
2129.58	15.8465
2130.55	15.8412
2131.52	16.7861
2132.48	13.952
2133.45	16.7676
2134.42	16.7655
2135.39	17.7073
2136.35	13.9419
2137.32	13.9246
2138.28	13.9181
2139.25	12.9689
2140.22	15.8089
2141.18	15.7663
2142.15	13.891
2143.12	17.6498
2144.08	16.7029
2145.05	15.7542
2146.01	14.8063
2146.98	16.6651
2147.94	14.7792
2148.9	15.7235
2149.87	15.7216
2150.83	11.0262
2151.8	14.757
2152.76	14.7344
2153.72	15.6585
2154.69	15.6603
2155.65	17.535
2156.61	14.7238
2157.58	13.7759
2158.54	15.6347
2159.5	18.4303
2160.47	15.6252
2161.43	13.7518
2162.39	17.4738
2163.35	13.7446
2164.31	14.6665
2165.27	12.7848
2166.24	14.6431
2167.2	14.6596
2168.16	17.4532
2169.12	15.5659
2170.08	15.5564
2171.04	14.6286
2172	17.4181
2172.96	16.4848
2173.92	16.4779
2174.88	15.5484
2175.84	14.6109
2176.8	16.4675
2177.76	11.8228
2178.72	16.4595
2179.68	16.452
2180.64	16.4381
2181.59	17.3542
2182.55	14.5776
2183.51	18.2956
2184.47	16.4591
2185.43	14.6015
2186.38	14.5872
2187.34	17.3555
2188.3	19.2122
2189.26	16.4351
2190.21	15.5146
2191.17	13.6752
2192.13	17.3974
2193.08	17.3836
2194.04	15.5078
2195	17.3574
2195.95	17.3718
2196.91	15.5343
2197.86	16.4941
2198.82	16.48
2199.78	17.3871
2200.73	16.4726
2201.69	18.376
2202.64	17.3913
2203.59	16.4631
2204.55	14.602
2205.5	14.6134
2206.46	16.4825
2207.41	18.3468
2208.37	15.5613
2209.32	15.5721
2210.27	14.6359
2211.23	16.4988
2212.18	15.581
2213.13	17.4498
2214.09	18.3805
2215.04	14.6466
2215.99	17.4514
2216.94	16.5266
2217.9	16.526
2218.85	17.4455
2219.8	16.5062
2220.75	16.5168
2221.7	16.5349
2222.65	17.4864
2223.6	16.5629
2224.55	17.5113
2225.5	18.4465
2226.46	14.6926
2227.41	16.5808
2228.36	16.594
2229.31	17.5471
2230.26	19.441
2231.21	13.8049
2232.16	14.7392
2233.11	15.6707
2234.05	16.6138
2235	15.6918
2235.95	16.6534
2236.9	16.6565
2237.85	15.7086
2238.8	19.4922
2239.75	15.7229
2240.69	18.549
2241.64	17.6057
2242.59	15.7378
2243.54	15.7494
2244.48	17.6495
2245.43	15.7548
2246.38	16.6969
2247.32	17.6454
2248.27	17.6302
2249.22	15.7373
2250.16	17.649
2251.11	16.7203
2252.06	13.8797
2253	15.7773
2253.95	16.7364
2254.89	16.7458
2255.84	14.85
2256.78	16.7569
2257.73	13.911
2258.67	16.7749
2259.62	15.8286
2260.56	18.7023
2261.51	13.958
2262.45	15.8805
2263.39	13.9664
2264.34	15.8619
2265.28	14.8966
2266.22	15.8545
2267.17	13.9627
2268.11	15.8857
2269.05	16.8518
2270	13.9847
2270.94	14.9441
2271.88	13.032
2272.82	14.9482
2273.77	15.9186
2274.71	14.9765
2275.65	14.0312
2276.59	14.0269
2277.53	17.8447
2278.47	16.8755
2279.41	15.9199
2280.36	14.0149
2281.3	16.9232
2282.24	15.9746
2283.18	16.9281
2284.12	11.1637
2285.06	15.0271
2286	15.0182
2286.94	14.9958
2287.88	14.0304
2288.82	16.9304
2289.75	15.9798
2290.69	15.9898
2291.63	14.0575
2292.57	15.011
2293.51	14.9967
2294.45	15.0013
2295.39	14.0532
2296.32	15.0283
2297.26	15.0317
2298.2	14.0719
2299.14	16.0041
2300.07	15.0358
2301.01	14.0705
2301.95	14.0781
2302.89	12.151
2303.82	17.9536
2304.76	13.1165
2305.69	13.1124
2306.63	16.0199
2307.57	13.1276
2308.5	14.0811
2309.44	13.0953
2310.37	11.1618
2311.31	14.0742
2312.24	15.0578
2313.18	14.0756
2314.11	13.0952
2315.05	14.0678
2315.98	14.0558
2316.92	16.9427
2317.85	16.944
2318.78	17.9214
2319.72	16.9712
2320.65	16.0059
2321.58	16.0053
2322.52	19.8494
2323.45	19.8323
2324.38	23.6709
2325.32	26.5527
2326.25	37.141
2327.18	98.7792
2328.11	215.276
2329.05	56.4149
2329.98	28.4472
2330.91	14.9586
2331.84	18.7941
2332.77	13.9821
2333.7	14.9409
2334.63	14.9374
2335.56	13.0105
2336.5	14.9324
2337.43	13.9646
2338.36	12.9899
2339.29	14.8935
2340.22	15.8461
2341.15	13.9272
2342.08	14.885
2343.01	13.9155
2343.93	18.6974
2344.86	13.9064
2345.79	14.8668
2346.72	14.8492
2347.65	15.7551
2348.58	15.817
2349.51	13.8599
2350.44	13.8316
2351.36	14.7788
2352.29	14.7838
2353.22	12.8711
2354.15	12.8523
2355.07	17.5957
2356	10.9359
2356.93	13.7792
2357.86	12.8169
2358.78	13.7511
2359.71	10.8953
2360.63	13.726
2361.56	17.5009
2362.49	14.6531
2363.41	15.5711
2364.34	14.6423
2364.8	14.6471