File: Data/3-Raman/raw/bu19w-ff-ore2-fi06-v_150 (500nm)_532nm_edge_100%_x100_vis_lwd_h50um_15sx2_01.txt
#Acq. time (s)=	15
#Accumulations=	2
#Range (cm-¹)=	50...5000
#Windows=	1
#Auto scanning=	Off
#Autofocus=	Off
#Macrospot=	Off
#AutoExposure=	Off
#Spike filter=	Multiple accum.
#Delay time (s)=	2
#Binning=	1
#Readout mode=	Signal
#DeNoise=	Off
#ICS correction=	On
#Dark correction=	Off
#Inst. Process=	Off
#Detector Gain=	Best Dynamic
#Detector ADC=	50 kHz HS
#Detector temperature (°C)=	-60.09
#Instrument=	LabRAM HR Evol
#Detector=	SIN-EM FIVIS
#Objective=	x100_VIS_LWD
#Grating=	150 (500nm)
#ND Filter=	100%
#Laser=	532nm_Edge
#Hole=	49.98
#Temperature=	0
#Range=	Visible
#StageXY=	75x50mm Scan+
#StageZ=	Z motor
#X (µm)=	0
#Y (µm)=	0
#Z (µm)=	-9.9
#Full time(s)=	35
#Project=	21_05_28
#Sample=	BU19w
#Site=
#Title=	BU19w-FF-ore2-FI06-V_150 (500nm)_532nm_Edge_100%_x100_VIS_LWD_H50um_15sX2
#Remark=
#Date=	28.05.2021 15:07
#Acquired=	28.05.2021 15:07:37
51.5961	481.068
56.2453	596.414
60.8921	678.104
65.5367	668.172
70.1768	606.743
74.8167	647.985
79.4543	623.06
84.0897	622.715
88.7227	631.919
93.3513	624.097
97.9798	649.392
102.606	651.626
107.23	708.333
111.851	750.972
116.469	937.075
121.086	1552.28
125.7	4295.66
130.313	6448.79
134.921	3519.11
139.529	1665.25
144.134	1363.26
148.738	1397.31
153.337	1302.54
157.936	1157.98
162.532	1158.41
167.126	1248.35
171.716	1406.87
176.306	1603.45
180.894	1981.22
185.477	2430.02
190.06	3333.93
194.64	4748.04
199.219	6820.35
203.793	8969.47
208.367	9839.65
212.939	9019.54
217.506	7039.01
222.073	5092.93
226.638	3737.3
231.199	2828.93
235.759	2244.84
240.318	1872.33
244.872	1573.21
249.425	1468.25
253.977	1425.47
258.524	1509.3
263.071	2174.02
267.616	2423.44
272.156	1507.62
276.697	948.69
281.233	828.194
285.769	726.353
290.303	714.727
294.832	665.839
299.361	677.692
303.886	656.728
308.411	639.127
312.934	606.849
317.452	630.557
321.97	628.16
326.484	610.946
330.998	607.382
335.507	588.729
340.017	636.06
344.524	642.864
349.027	707.124
353.53	1285.35
358.028	1964.85
362.527	1330.62
367.021	864.87
371.515	762.146
376.004	746.719
380.494	695.699
384.979	684.285
389.465	727.535
393.946	862.905
398.427	991.362
402.903	1353.4
407.38	1122.26
411.852	855.39
416.324	781.429
420.792	798.256
425.26	857.1
429.723	895.366
434.187	970.128
438.646	1093.78
443.105	1399.57
447.56	2039.91
452.015	3196.12
456.466	5768.46
460.914	15028
465.362	29683.4
469.807	26049.9
474.251	12481.1
478.69	5998.45
483.13	3742.37
487.566	2766.2
491.999	2187.46
496.432	1810.66
500.861	1563.91
505.29	1380.52
509.715	1374.34
514.138	1406.3
518.56	1338.84
522.979	1245.29
527.395	1153.18
531.811	1080.89
536.223	1012.22
540.635	973.602
545.042	939.509
549.448	917.01
553.853	898.994
558.255	854.901
562.654	857.489
567.053	851.673
571.448	801.611
575.841	853.401
580.232	830.652
584.622	800.091
589.009	828.27
593.393	855.667
597.777	846.782
602.157	811.033
606.535	844.004
610.913	811.022
615.287	802.789
619.659	798.794
624.029	781.687
628.398	832.066
632.763	800.406
637.127	784.437
641.488	823.682
645.849	797.507
650.206	814.477
654.561	772.74
658.914	769.399
663.267	777.933
667.615	749.884
671.962	778.361
676.307	798.529
680.649	789.326
684.991	805.771
689.33	874.491
693.666	942.161
698	1031.24
702.332	985.586
706.662	850.62
710.992	837.309
715.318	811.346
719.641	793.552
723.963	804.637
728.283	794.669
732.6	816.453
736.918	800.544
741.231	792.138
745.542	774.933
749.852	821.809
754.159	823.53
758.464	800.663
762.767	807.111
767.068	854.418
771.369	823.641
775.666	840.747
779.961	878.51
784.254	924.157
788.545	959.342
792.834	1121.6
797.12	1262.88
801.405	1316.36
805.688	1451.03
809.968	1645.55
814.247	1485.15
818.524	1134.64
822.798	980.887
827.071	953.886
831.341	890.592
835.612	912.106
839.878	919.238
844.142	900.892
848.405	904.266
852.665	903.796
856.923	914.351
861.18	894.023
865.434	909.881
869.686	882.52
873.936	893.467
878.185	877.834
882.431	877.375
886.675	912.589
890.915	912.228
895.155	912.595
899.393	917.832
903.63	890.346
907.864	889.802
912.096	910.913
916.326	878.453
920.554	925.785
924.78	882.073
929.004	878.914
933.227	909.046
937.447	887.528
941.665	897.942
945.881	894.304
950.095	887.445
954.305	837.15
958.516	887.133
962.724	912.658
966.93	891.498
971.134	890.656
975.337	839.11
979.537	865.084
983.735	892.261
987.93	882.342
992.124	846.06
996.316	886.618
1000.51	867.391
1004.7	867.401
1008.88	868.606
1013.06	854.938
1017.25	875.099
1021.43	887.825
1025.61	904.644
1029.78	857.073
1033.96	891.431
1038.13	889.623
1042.3	913.922
1046.47	925.326
1050.63	904.513
1054.8	941.866
1058.96	962.908
1063.12	1023.62
1067.28	1140.49
1071.44	1125.44
1075.59	1125.02
1079.74	1319.33
1083.89	1539.96
1088.04	1387.82
1092.19	1107.05
1096.33	1021.67
1100.48	964.824
1104.62	951.329
1108.76	946.464
1112.89	942.057
1117.03	935.843
1121.16	927.906
1125.29	949.463
1129.42	899.896
1133.55	935.406
1137.68	930.776
1141.8	972.297
1145.92	997.679
1150.04	1004.28
1154.16	1083.54
1158.27	1258.43
1162.39	1315.47
1166.5	1159.49
1170.61	1011.54
1174.72	976.791
1178.82	928.534
1182.93	919.433
1187.03	941.917
1191.13	961.737
1195.23	955.591
1199.33	971.618
1203.42	936.385
1207.51	941.887
1211.6	952.455
1215.69	942.812
1219.78	947.416
1223.86	969.213
1227.95	932.971
1232.03	970.283
1236.11	942.258
1240.18	963.778
1244.26	952.113
1248.33	948.818
1252.41	952.025
1256.48	961.44
1260.54	968.029
1264.61	950.766
1268.67	969.71
1272.74	967.794
1276.8	992.965
1280.86	963.907
1284.91	964.791
1288.97	970.537
1293.02	971.135
1297.07	933.308
1301.12	969.929
1305.17	955.988
1309.21	972.218
1313.25	963.135
1317.3	955.721
1321.34	957.174
1325.37	962.284
1329.41	1001.43
1333.44	980.145
1337.48	968.616
1341.5	999.976
1345.53	987.172
1349.56	990.341
1353.59	958.695
1357.61	986.8
1361.63	981.013
1365.65	972.453
1369.66	973.955
1373.68	994.436
1377.69	1005.17
1381.7	962.863
1385.72	988.003
1389.72	960.168
1393.73	1005.44
1397.73	999.959
1401.74	968.777
1405.74	1017.35
1409.73	1005.94
1413.73	1026.17
1417.73	1024.73
1421.72	1026.24
1425.71	996.987
1429.7	970.187
1433.69	988.902
1437.67	1057.94
1441.66	1018.39
1445.64	1039.89
1449.62	1060.33
1453.6	1008.57
1457.57	1007.03
1461.55	1047.68
1465.52	1015.09
1469.49	1008.07
1473.46	1009.06
1477.43	1039.34
1481.39	1044.92
1485.36	1004.43
1489.32	1030.41
1493.28	1027.13
1497.24	1057.02
1501.19	1048
1505.15	1037.25
1509.1	1037.49
1513.05	1031.01
1517	1034.3
1520.95	1045.47
1524.9	1048.94
1528.84	1036.97
1532.78	1060.04
1536.72	1061.8
1540.66	1054.88
1544.6	1037.3
1548.53	1071.08
1552.46	1051.57
1556.4	1070.68
1560.32	1026.69
1564.25	1044.55
1568.18	1064.22
1572.1	1077.02
1576.02	1057.91
1579.94	1064.84
1583.86	1091.99
1587.78	1058.31
1591.69	1082.41
1595.61	1090.1
1599.52	1094.9
1603.43	1065.22
1607.34	1092.36
1611.24	1115.65
1615.15	1087.25
1619.05	1097.35
1622.95	1088.22
1626.85	1102.24
1630.74	1098.22
1634.64	1084.98
1638.53	1110.93
1642.42	1094.1
1646.31	1099.52
1650.2	1117.52
1654.09	1139.43
1657.97	1082.55
1661.86	1090.88
1665.74	1117.27
1669.62	1100.29
1673.49	1094.49
1677.37	1107.86
1681.24	1111.01
1685.12	1132.11
1688.99	1104.17
1692.86	1074.14
1696.72	1091.85
1700.59	1106.47
1704.45	1142.74
1708.31	1093.93
1712.17	1093.52
1716.03	1097.86
1719.89	1109.79
1723.74	1107.54
1727.6	1109.92
1731.45	1131.83
1735.3	1118.12
1739.14	1110.88
1742.99	1108.2
1746.83	1140.04
1750.68	1114.83
1754.52	1120.73
1758.36	1103.15
1762.19	1139.39
1766.03	1129.34
1769.86	1107.66
1773.69	1140.4
1777.53	1096.92
1781.35	1143.19
1785.18	1172.98
1789	1110.43
1792.83	1155.43
1796.65	1158.4
1800.47	1128.42
1804.29	1151.26
1808.1	1161.81
1811.92	1164.7
1815.73	1125.87
1819.54	1157.29
1823.35	1124.24
1827.16	1149.48
1830.97	1147.99
1834.77	1197.07
1838.58	1163.04
1842.38	1143.93
1846.18	1166.86
1849.97	1188.01
1853.77	1172.01
1857.56	1187.54
1861.36	1152.27
1865.15	1168.21
1868.93	1135.91
1872.72	1150.2
1876.51	1157.28
1880.29	1176.4
1884.07	1161.87
1887.86	1164.91
1891.63	1158.25
1895.41	1180.15
1899.19	1150.52
1902.96	1171.08
1906.73	1179.92
1910.5	1206.39
1914.27	1177.1
1918.04	1173.68
1921.8	1193.21
1925.57	1176.78
1929.33	1203.2
1933.09	1189.84
1936.85	1165.21
1940.6	1191.79
1944.36	1152.03
1948.11	1199.27
1951.87	1173.44
1955.61	1204.38
1959.36	1183.05
1963.11	1189.5
1966.86	1212.78
1970.6	1175.59
1974.34	1176.47
1978.08	1208.01
1981.82	1167.23
1985.56	1245.95
1989.29	1209.54
1993.02	1211.23
1996.75	1198.73
2000.49	1218.52
2004.21	1190.14
2007.94	1208.86
2011.67	1242.87
2015.39	1239.06
2019.11	1234.96
2022.83	1220.52
2026.55	1205.95
2030.27	1225.31
2033.98	1220.55
2037.69	1253.74
2041.41	1195.27
2045.12	1248.39
2048.82	1233.79
2052.53	1211.19
2056.24	1233.54
2059.94	1229.97
2063.64	1206.04
2067.34	1239.35
2071.04	1216.68
2074.74	1224.4
2078.43	1260.9
2082.13	1238.33
2085.82	1229.44
2089.51	1227.42
2093.2	1228.55
2096.88	1231.2
2100.57	1224.34
2104.25	1265.42
2107.94	1251.4
2111.62	1262.29
2115.3	1229.45
2118.97	1255.95
2122.65	1265.19
2126.32	1248.17
2129.99	1225.43
2133.66	1277.59
2137.33	1262.98
2141	1277.73
2144.67	1290.39
2148.33	1256.01
2151.99	1254.78
2155.66	1262.77
2159.31	1241.49
2162.97	1246.94
2166.63	1268.99
2170.28	1280.28
2173.94	1278.41
2177.59	1287.76
2181.24	1258.14
2184.89	1265.78
2188.53	1249.21
2192.18	1276.79
2195.82	1293.08
2199.46	1278.71
2203.1	1323.75
2206.74	1276.87
2210.38	1302.31
2214.01	1303.29
2217.65	1290.59
2221.28	1304.51
2224.91	1294.63
2228.54	1293.84
2232.16	1274.62
2235.79	1282.26
2239.41	1295.43
2243.04	1275.23
2246.66	1346.85
2250.28	1321.1
2253.89	1322.43
2257.51	1282.81
2261.12	1329.04
2264.74	1320.95
2268.35	1319.53
2271.96	1327.81
2275.57	1296.2
2279.17	1309.39
2282.78	1287.76
2286.38	1306.69
2289.98	1310.5
2293.58	1299.95
2297.18	1302.68
2300.78	1319.66
2304.37	1351.59
2307.97	1294.17
2311.56	1361.67
2315.15	1294.36
2318.74	1319.72
2322.33	1299.29
2325.91	1322.57
2329.5	1326.76
2333.08	1341.16
2336.66	1306.32
2340.24	1352.35
2343.82	1320.09
2347.4	1294.34
2350.97	1365.98
2354.54	1320.44
2358.12	1339.36
2361.69	1346.01
2365.26	1311.73
2368.82	1313.83
2372.39	1299.59
2375.95	1344.44
2379.52	1342.12
2383.08	1341.81
2386.64	1340.72
2390.19	1368.33
2393.75	1358.53
2397.31	1332.66
2400.86	1377.83
2404.41	1344.93
2407.96	1370.86
2411.51	1335.01
2415.06	1365.54
2418.6	1341.31
2422.15	1329.19
2425.69	1322.89
2429.23	1371.37
2432.77	1354.63
2436.31	1354.8
2439.84	1372.76
2443.38	1360.18
2446.91	1383.04
2450.44	1366.99
2453.97	1377.37
2457.5	1384.06
2461.03	1380.15
2464.55	1385.53
2468.08	1368.99
2471.6	1328.05
2475.12	1356.58
2478.64	1363.19
2482.16	1387.92
2485.67	1387.61
2489.19	1389.25
2492.7	1396.35
2496.21	1412.96
2499.72	1363.51
2503.23	1351.15
2506.74	1361.01
2510.25	1365.87
2513.75	1332.67
2517.25	1405.8
2520.75	1396.39
2524.25	1400.87
2527.75	1396.55
2531.25	1387.06
2534.74	1375.02
2538.24	1393.86
2541.73	1381.63
2545.22	1388.54
2548.71	1407.13
2552.2	1406.4
2555.68	1404.21
2559.17	1411.97
2562.65	1390.99
2566.13	1416.13
2569.61	1384.02
2573.09	1406.33
2576.57	1399.96
2580.04	1413.57
2583.51	1406.59
2586.99	1399.56
2590.46	1377.89
2593.93	1412.44
2597.4	1420.21
2600.86	1383.55
2604.33	1426.04
2607.79	1385.4
2611.25	1426.02
2614.71	1422.51
2618.17	1407.03
2621.63	1400.55
2625.09	1427.43
2628.54	1406.83
2631.99	1386.02
2635.45	1420.54
2638.9	1422.95
2642.34	1398.28
2645.79	1404.95
2649.24	1425.82
2652.68	1450.1
2656.12	1424.45
2659.56	1400.51
2663.01	1409.66
2666.44	1363.83
2669.88	1422.81
2673.32	1405.26
2676.75	1423.68
2680.18	1382.31
2683.61	1408.69
2687.04	1428.01
2690.47	1397.88
2693.9	1427.91
2697.32	1413.85
2700.75	1434.56
2704.17	1419.02
2707.59	1379.38
2711.01	1431.87
2714.43	1400.94
2717.84	1427.99
2721.26	1405.96
2724.67	1451.25
2728.08	1424.84
2731.49	1426.5
2734.9	1489.86
2738.31	1429.66
2741.71	1403.03
2745.12	1435.23
2748.52	1417.47
2751.92	1435.44
2755.32	1410.96
2758.72	1407.01
2762.12	1418.15
2765.52	1455.3
2768.91	1416.85
2772.3	1414.91
2775.7	1394.94
2779.09	1434.08
2782.47	1440.04
2785.86	1413.89
2789.25	1403.7
2792.63	1450.81
2796.01	1420.78
2799.4	1425.53
2802.78	1423.47
2806.15	1385.82
2809.53	1428.73
2812.91	1430.31
2816.28	1429.94
2819.65	1417.4
2823.03	1407.9
2826.4	1436.85
2829.76	1404.34
2833.13	1451.27
2836.5	1407.13
2839.86	1421.01
2843.22	1425.85
2846.59	1435.7
2849.95	1404.1
2853.3	1425.06
2856.66	1451.49
2860.02	1393.99
2863.37	1389.92
2866.72	1417.75
2870.08	1405.31
2873.43	1431.26
2876.77	1416.78
2880.12	1430.48
2883.47	1418.7
2886.81	1392.64
2890.15	1455.24
2893.5	1456.45
2896.84	1408.14
2900.17	1441.86
2903.51	1441.33
2906.85	1452.91
2910.18	1409.48
2913.52	1423.67
2916.85	1472.77
2920.18	1457.31
2923.51	1418.13
2926.83	1414.76
2930.16	1377.18
2933.48	1386.69
2936.81	1455.43
2940.13	1471.26
2943.45	1449.39
2946.77	1456.77
2950.09	1435.04
2953.4	1440.53
2956.72	1430.1
2960.03	1440.57
2963.34	1461.48
2966.65	1451.51
2969.96	1418.54
2973.27	1415.83
2976.58	1399.12
2979.88	1437.98
2983.19	1400.68
2986.49	1431.97
2989.79	1425.81
2993.09	1445.05
2996.39	1453.1
2999.68	1433.04
3002.98	1402.6
3006.27	1421.06
3009.57	1403.88
3012.86	1421.61
3016.15	1417.71
3019.43	1410
3022.72	1381.5
3026.01	1384.13
3029.29	1397.16
3032.57	1425.3
3035.86	1400.46
3039.14	1394.47
3042.41	1393.21
3045.69	1408.08
3048.97	1380.35
3052.24	1369.65
3055.52	1395
3058.79	1402.3
3062.06	1362.67
3065.33	1394.39
3068.6	1388.93
3071.86	1408.8
3075.13	1402.78
3078.39	1406.72
3081.65	1361.85
3084.91	1372.21
3088.17	1396.74
3091.43	1375.14
3094.69	1385.92
3097.95	1391.13
3101.2	1361.1
3104.45	1384.06
3107.7	1371.52
3110.95	1391.13
3114.2	1388.41
3117.45	1343.92
3120.7	1386.12
3123.94	1402.61
3127.18	1321.9
3130.43	1365.95
3133.67	1386.22
3136.91	1354.97
3140.14	1372.27
3143.38	1382.87
3146.61	1423.04
3149.85	1390.84
3153.08	1323.36
3156.31	1334.99
3159.54	1348.56
3162.77	1366.86
3166	1373.71
3169.22	1391.89
3172.45	1380.39
3175.67	1327.8
3178.89	1340.94
3182.11	1338.79
3185.33	1379.59
3188.55	1345.85
3191.77	1341.63
3194.98	1348.85
3198.2	1375.09
3201.41	1350.82
3204.62	1334.24
3207.83	1362.44
3211.04	1336.46
3214.25	1343.87
3217.45	1359.94
3220.66	1361.74
3223.86	1346.47
3227.06	1340.84
3230.26	1330.49
3233.46	1338.31
3236.66	1366.03
3239.85	1337.9
3243.05	1308.87
3246.24	1384.68
3249.44	1347.14
3252.63	1340.22
3255.82	1337.14
3259.01	1308.25
3262.19	1342.18
3265.38	1313.85
3268.56	1333.09
3271.75	1330.23
3274.93	1339.7
3278.11	1309.04
3281.29	1334.45
3284.47	1323.33
3287.64	1326.56
3290.82	1331.58
3293.99	1354.82
3297.17	1324.63
3300.34	1309.73
3303.51	1301.8
3306.68	1304.96
3309.84	1326.06
3313.01	1313.66
3316.18	1271.78
3319.34	1313.41
3322.5	1308.48
3325.66	1299.78
3328.82	1317.6
3331.98	1344.87
3335.14	1309.85
3338.29	1306.14
3341.45	1310.08
3344.6	1334.8
3347.75	1332.49
3350.9	1303.16
3354.05	1309.65
3357.2	1321.94
3360.35	1311.67
3363.49	1317.59
3366.64	1351.83
3369.78	1332.4
3372.92	1302.63
3376.06	1319.25
3379.2	1312.33
3382.34	1340.43
3385.48	1303.26
3388.61	1261.44
3391.75	1298.14
3394.88	1313.04
3398.01	1298.26
3401.14	1276.6
3404.27	1317.64
3407.4	1294.29
3410.52	1279.53
3413.65	1341.8
3416.77	1288.58
3419.89	1320.06
3423.01	1276.08
3426.13	1300.51
3429.25	1306.58
3432.37	1277.14
3435.49	1283.73
3438.6	1256.6
3441.72	1261.14
3444.83	1277.09
3447.94	1281.33
3451.05	1283.63
3454.16	1264.77
3457.26	1276.37
3460.37	1288.73
3463.47	1276.32
3466.58	1262.92
3469.68	1284.46
3472.78	1251.7
3475.88	1225.07
3478.98	1280.89
3482.07	1280.88
3485.17	1250.67
3488.26	1280.08
3491.36	1273.79
3494.45	1249.91
3497.54	1280.73
3500.63	1254.85
3503.72	1280.87
3506.81	1240.7
3509.89	1249.54
3512.98	1258.92
3516.06	1233.72
3519.14	1238.7
3522.22	1278.14
3525.3	1244.09
3528.38	1208.38
3531.45	1227.77
3534.53	1249.73
3537.61	1264.49
3540.68	1254.82
3543.75	1242.85
3546.82	1258.06
3549.89	1248.66
3552.96	1237.04
3556.03	1236.66
3559.09	1212.82
3562.16	1256.2
3565.22	1224.51
3568.28	1195.46
3571.34	1250.21
3574.4	1229.47
3577.46	1236.29
3580.52	1219.3
3583.57	1231.62
3586.63	1223.89
3589.68	1253.15
3592.73	1239.57
3595.78	1200.38
3598.83	1207.52
3601.88	1227.92
3604.93	1208.41
3607.97	1226.68
3611.02	1211.81
3614.06	1203.51
3617.1	1196.12
3620.14	1179.35
3623.18	1207
3626.22	1188.45
3629.26	1225.6
3632.3	1208.95
3635.33	1209.2
3638.36	1185.28
3641.4	1196.35
3644.43	1202.85
3647.46	1192.72
3650.49	1196.37
3653.51	1205.84
3656.54	1221.28
3659.57	1209.31
3662.59	1201.92
3665.61	1190.52
3668.63	1220.96
3671.65	1192.31
3674.67	1195.77
3677.69	1211.57
3680.71	1164.17
3683.72	1165.8
3686.74	1188.25
3689.75	1212.65
3692.76	1150.01
3695.77	1161.2
3698.78	1174.07
3701.79	1198.6
3704.79	1188.03
3707.8	1160.34
3710.81	1202.81
3713.81	1221.45
3716.81	1170.52
3719.81	1163.41
3722.81	1177.09
3725.81	1184
3728.81	1207.01
3731.8	1170.88
3734.8	1212.73
3737.79	1178.26
3740.78	1171.31
3743.77	1150.89
3746.76	1168.44
3749.75	1147.83
3752.74	1182.26
3755.73	1169.16
3758.71	1150.41
3761.7	1166.74
3764.68	1152.62
3767.66	1138.55
3770.64	1157.71
3773.62	1140.07
3776.6	1162.24
3779.58	1172.17
3782.55	1138.72
3785.53	1130.8
3788.5	1155.05
3791.47	1151.05
3794.44	1136.85
3797.41	1159.55
3800.38	1150.24
3803.35	1127.85
3806.32	1161.24
3809.28	1149.33
3812.24	1159.23
3815.21	1142.68
3818.17	1141.29
3821.13	1140.89
3824.09	1132.95
3827.04	1162.97
3830	1133.32
3832.96	1141.57
3835.91	1109.12
3838.86	1162.18
3841.82	1110.75
3844.77	1121.07
3847.72	1127.62
3850.67	1097.08
3853.61	1139.01
3856.56	1136.19
3859.5	1103.76
3862.45	1121
3865.39	1135.33
3868.33	1130.53
3871.27	1071.01
3874.21	1100.55
3877.15	1117.61
3880.09	1102.88
3883.02	1112.99
3885.96	1117.21
3888.89	1101.16
3891.82	1121.59
3894.75	1135.25
3897.68	1141.06
3900.61	1135.21
3903.54	1127.4
3906.47	1130.98
3909.39	1152.01
3912.31	1108.53
3915.24	1115.88
3918.16	1078.97
3921.08	1099.89
3924	1107.14
3926.92	1126.73
3929.83	1106.88
3932.75	1108.09
3935.67	1094.24
3938.58	1088.28
3941.49	1099.75
3944.4	1103.46
3947.31	1072.77
3950.22	1096.76
3953.13	1095.94
3956.04	1089.41
3958.94	1082.03
3961.85	1068.94
3964.75	1082.74
3967.65	1084.14
3970.55	1064.49
3973.45	1089.01
3976.35	1071.27
3979.25	1050.56
3982.15	1040.34
3985.04	1098.35
3987.94	1102.49
3990.83	1063.31
3993.72	1059.58
3996.61	1085.87
3999.5	1070.78
4002.39	1100.02
4005.28	1086.91
4008.16	1090.24
4011.05	1100.32
4013.93	1053.51
4016.81	1075.16
4019.7	1061.11
4022.58	1049.95
4025.46	1068.73
4028.33	1026.66
4031.21	1048.37
4034.09	1063.36
4036.96	1099.66
4039.84	1076.99
4042.71	1066.86
4045.58	1054.6
4048.45	1086.96
4051.32	1079.66
4054.19	1044.28
4057.05	1071.09
4059.92	1091.08
4062.78	1062.47
4065.65	1055.22
4068.51	1040.18
4071.37	1026.08
4074.23	1043.12
4077.09	1051.38
4079.95	1032.35
4082.81	1035.73
4085.66	1052.76
4088.52	1049.27
4091.37	1044.8
4094.22	1031.62
4097.07	1042.76
4099.92	1039.31
4102.77	1043.65
4105.62	1017.64
4108.47	1012.03
4111.31	1027.97
4114.16	1029.1
4117	1016.43
4119.84	1021.23
4122.69	1030.94
4125.53	1030
4128.36	1033.01
4131.2	1030.42
4134.04	993.706
4136.88	1029.79
4139.71	1038.13
4142.54	1028.9
4145.38	1019.04
4148.21	1023.29
4151.04	988.454
4153.87	1001.36
4156.69	1000.19
4159.52	1039.7
4162.35	1005.2
4165.17	999.211
4168	974.626
4170.82	1021.49
4173.64	1008.74
4176.46	994.073
4179.28	986.248
4182.1	1007.85
4184.91	1020.68
4187.73	993.467
4190.54	982.904
4193.36	1007.73
4196.17	980.777
4198.98	996.076
4201.79	971.156
4204.6	1009.04
4207.41	1027.29
4210.22	1000.41
4213.02	966.57
4215.83	973.005
4218.63	994.802
4221.44	993.917
4224.24	985.045
4227.04	1006.63
4229.84	1005.71
4232.64	987.989
4235.43	1006.02
4238.23	989.445
4241.02	986.752
4243.82	990.045
4246.61	955.564
4249.4	963.81
4252.19	986.961
4254.98	981.149
4257.77	997.246
4260.56	950.249
4263.35	999.478
4266.13	985.597
4268.92	956.669
4271.7	942.754
4274.48	981.185
4277.26	998.313
4280.04	954.741
4282.82	953.473
4285.6	971.315
4288.38	942.509
4291.15	955.072
4293.93	935.199
4296.7	966.1
4299.47	939.327
4302.25	947.934
4305.02	920.003
4307.79	956.012
4310.55	927.083
4313.32	948.025
4316.09	923.06
4318.85	949.882
4321.62	921.689
4324.38	945.327
4327.14	973.001
4329.9	939.609
4332.66	915.267
4335.42	943.955
4338.18	947.078
4340.94	927.967
4343.69	939.432
4346.45	917.35
4349.2	950.431
4351.95	929.446
4354.7	918.908
4357.45	953.225
4360.2	923.145
4362.95	902.183
4365.7	920.203
4368.44	906.395
4371.19	923.429
4373.93	944.414
4376.68	924.339
4379.42	910.326
4382.16	915.798
4384.9	916.198
4387.64	885.955
4390.37	912.635
4393.11	917.88
4395.85	889.783
4398.58	902.284
4401.31	913.738
4404.05	910.609
4406.78	885.731
4409.51	902.393
4412.24	896.101
4414.96	877.169
4417.69	887.341
4420.42	889.85
4423.14	894.63
4425.87	906.777
4428.59	902.231
4431.31	920.682
4434.03	899.376
4436.75	894.748
4439.47	925.692
4442.19	887.39
4444.91	882.634
4447.62	880.963
4450.34	883.492
4453.05	854.432
4455.76	855.809
4458.47	888.633
4461.19	864.668
4463.89	862.889
4466.6	871.605
4469.31	847.756
4472.02	869.202
4474.72	846.498
4477.43	850.201
4480.13	872.965
4482.83	846.195
4485.53	848.964
4488.23	873.871
4490.93	845.875
4493.63	833.513
4496.33	852.767
4499.02	821.358
4501.72	866.162
4504.41	837.796
4507.11	847.663
4509.8	841.655
4512.49	858.99
4515.18	839.205
4517.87	816.238
4520.56	835.792
4523.24	844.824
4525.93	823.008
4528.61	835.218
4531.3	797.399
4533.98	820.316
4536.66	829.423
4539.34	839.642
4542.02	843.519
4544.7	819.59
4547.38	840.599
4550.05	815.597
4552.73	844.234
4555.4	826.928
4558.08	790.364
4560.75	819.585
4563.42	785.437
4566.09	820.556
4568.76	802.987
4571.43	783.761
4574.1	820.057
4576.77	826.726
4579.43	788.177
4582.1	804.277
4584.76	766.11
4587.42	769.926
4590.08	808.595
4592.74	795.945
4595.4	808.447
4598.06	788.284
4600.72	793.16
4603.38	770.842
4606.03	794.535
4608.69	783.201
4611.34	760.888
4613.99	816.474
4616.64	790.815
4619.29	777.253
4621.94	780.226
4624.59	744.594
4627.24	746.347
4629.89	762.424
4632.53	795.074
4635.18	771.259
4637.82	752.894
4640.46	755.531
4643.1	760.398
4645.74	763.236
4648.38	735.206
4651.02	759.519
4653.66	766.382
4656.3	756.204
4658.93	756.344
4661.57	750.348
4664.2	746.702
4666.83	737.352
4669.46	740.121
4672.09	736.24
4674.72	753.628
4677.35	742.998
4679.98	746.926
4682.61	728.376
4685.23	733.405
4687.86	730.567
4690.48	759.256
4693.1	726.04
4695.73	728.785
4698.34	723.627
4700.96	741.055
4703.58	738.148
4706.2	735.172
4708.82	726.516
4711.43	726.873
4714.05	730.616
4716.66	726.405
4719.28	709.695
4721.89	730.342
4724.5	735.099
4727.11	708.207
4729.72	709.7
4732.33	708.93
4734.93	705.89
4737.54	752.816
4740.14	733.804
4742.75	718.162
4745.35	716.102
4747.95	716.263
4750.55	702.667
4753.15	723.231
4755.75	718.747
4758.35	707.427
4760.95	704.143
4763.54	684.965
4766.14	694.297
4768.73	699.238
4771.33	673.449
4773.92	719.371
4776.51	694.578
4779.1	658.347
4781.69	690.622
4784.28	662.355
4786.87	676.38
4789.45	691.565
4792.04	714.804
4794.63	712.902
4797.21	694.983
4799.79	688.579
4802.37	683.361
4804.95	696.566
4807.53	675.398
4810.11	677.254
4812.69	654.914
4815.27	682.155
4817.84	676.023
4820.42	683.8
4822.99	663.814
4825.57	656.539
4828.14	656.193
4830.71	655.859
4833.28	671.878
4835.85	665.833
4838.42	665.687
4840.98	693.651
4843.55	667.826
4846.12	652.356
4848.68	670.811
4851.24	673.824
4853.81	666.988
4856.37	666.146
4858.93	668.309
4861.49	645.668
4864.05	652.301
4866.61	669.354
4869.16	678.201
4871.72	622.105
4874.27	645.136
4876.83	642.044
4879.38	637.758
4881.93	639.362
4884.49	631.424
4887.04	632.982
4889.58	622.662
4892.13	644.467
4894.68	654.362
4897.23	653.525
4899.77	631.207
4902.32	618.395
4904.86	618.69
4907.4	621.342
4909.95	638.306
4912.49	630.052
4915.03	632.5
4917.57	631.301
4920.1	619.422
4922.64	626.654
4925.18	617.166
4927.71	611.305
4930.25	610.142
4932.78	590.017
4935.31	614.247
4937.84	628.853
4940.38	601.562
4942.9	625.464
4945.43	619.673
4947.96	601.999
4950.49	603.462
4953.01	596.585
4955.54	612.418
4958.06	615.177
4960.59	584.359
4963.11	602.837
4965.63	595.046
4968.15	584.94
4970.67	609.611
4973.19	593.259
4975.71	597.4
4978.22	603.952
4980.74	594.814
4983.25	589.299
4985.77	578.945
4988.28	578.294
4990.79	586.158
4993.3	580.635
4995.81	600.646
4998.32	601.306