File: Data/3-Raman/raw/bu19w-ff-ore1-fi06-v_150 (500nm)_532nm_edge_100%_x100_vis_h50um_15sx2_01.txt
#Acq. time (s)=	15
#Accumulations=	2
#Range (cm-¹)=	100...5000
#Windows=	1
#Auto scanning=	Off
#Autofocus=	Off
#Macrospot=	Off
#AutoExposure=	Off
#Spike filter=	Multiple accum.
#Delay time (s)=	2
#Binning=	1
#Readout mode=	Signal
#DeNoise=	Off
#ICS correction=	On
#Dark correction=	Off
#Inst. Process=	Off
#Detector Gain=	Best Dynamic
#Detector ADC=	50 kHz HS
#Detector temperature (°C)=	-60.09
#Instrument=	LabRAM HR Evol
#Detector=	SIN-EM FIVIS
#Objective=	x100_VIS
#Grating=	150 (500nm)
#ND Filter=	100%
#Laser=	532nm_Edge
#Hole=	49.98
#Temperature=	0
#Range=	Visible
#StageXY=	75x50mm Scan+
#StageZ=	Z motor
#X (µm)=	0
#Y (µm)=	0
#Z (µm)=	-3.2
#Full time(s)=	35
#Project=	21_05_14
#Sample=	BU19w
#Site=
#Title=	BU19w-FF-ore1-FI06-V_150 (500nm)_532nm_Edge_100%_x100_VIS_H50um_15sX2
#Remark=
#Date=	14.05.2021 18:47
#Acquired=	14.05.2021 18:47:31
102.699	2087.08
107.322	1943.15
111.942	1768.03
116.56	1675.15
121.173	1610.7
125.787	1501.42
130.398	1456.1
135.006	1408.52
139.613	1347.84
144.215	1319.27
148.817	1461.34
153.417	1921.1
158.014	2009.15
162.607	1386.99
167.2	1132.87
171.79	1103.1
176.379	1157.94
180.963	1621.47
185.547	1762.07
190.128	1455.05
194.705	1130.9
199.282	954.775
203.857	924.116
208.43	960.743
212.998	895.868
217.566	886.038
222.132	1014.37
226.693	1254.89
231.254	1404.55
235.813	1521.13
240.368	2192.37
244.923	1852.88
249.475	1232.25
254.023	998.647
258.571	956.343
263.117	1138.94
267.658	1796.96
272.199	3163.44
276.738	3476.15
281.273	2168.01
285.807	1336.09
290.34	1129.05
294.868	1141.41
299.396	1210.03
303.919	1096.99
308.443	1035.21
312.964	1081.4
317.481	1285.26
321.998	1791.7
326.51	1971.21
331.023	1510.6
335.533	1360.96
340.039	1752.79
344.544	2229.96
349.046	2060.02
353.547	1492.12
358.045	1256.13
362.542	1287.72
367.036	1376.41
371.527	1107.71
376.017	994.212
380.503	1075.73
384.99	1179.27
389.471	1295.28
393.953	1115.91
398.43	879.919
402.908	833.52
407.381	842.182
411.854	940.164
416.323	897.039
420.791	806.748
425.256	721.843
429.72	713.039
434.18	693.539
438.64	691.95
443.095	703.341
447.551	772.132
452.003	809.851
456.454	791.227
460.901	757.082
465.348	780.452
469.791	787.453
474.231	824.859
478.672	936.906
483.108	1006.56
487.544	1126.86
491.976	1186.03
496.408	1163.17
500.836	1039.34
505.261	891.112
509.687	793.672
514.108	748.396
518.529	708.948
522.946	721.889
527.361	730.248
531.776	709.922
536.187	737.092
540.595	746.904
545.003	851.796
549.408	802.512
553.812	799.266
558.212	769.387
562.61	727.906
567.007	743.173
571.401	713.845
575.792	853.272
580.184	1168.93
584.571	1533.98
588.956	1384.65
593.341	974.143
597.722	947.931
602.101	1095.52
606.48	1227.16
610.854	1046.09
615.227	842.636
619.597	733.472
623.967	727.632
628.334	781.1
632.698	836.912
637.06	870.367
641.422	800.963
645.779	816.851
650.135	881.58
654.491	1023.51
658.842	1209.7
663.192	1298.65
667.539	1398.22
671.884	1415.5
676.23	1305.44
680.571	1017.57
684.91	836.405
689.247	719.143
693.583	679.69
697.916	650.323
702.247	656.1
706.576	639.52
710.902	642.367
715.229	651.551
719.551	648.666
723.872	638.384
728.19	628.642
732.506	632.927
736.82	648.88
741.134	659.918
745.444	670.336
749.752	712.269
754.058	784.649
758.362	853.149
762.664	963.766
766.964	1291.23
771.264	1640.56
775.559	1718.11
779.853	1450.54
784.144	1075.76
788.434	883.74
792.722	808.418
797.007	730.195
801.29	701.112
805.572	660.313
809.851	655.924
814.13	651.693
818.406	623.21
822.679	641.109
826.95	607.353
831.219	637.505
835.486	640.089
839.752	629.385
844.015	616.334
848.276	611.654
852.535	630.079
856.792	678.24
861.047	657.998
865.3	626.552
869.551	638.995
873.8	607.333
878.047	624.959
882.292	622.597
886.534	603.607
890.775	616.775
895.014	600.075
899.251	641.795
903.486	614.719
907.719	603.782
911.95	599.813
916.179	610.844
920.406	626.18
924.63	640.585
928.853	644.066
933.074	662.647
937.293	678.806
941.51	778.279
945.723	780.086
949.936	765.066
954.147	691.61
958.356	698.202
962.563	730.362
966.768	686.096
970.971	677.082
975.172	635.281
979.371	682.663
983.568	641.11
987.761	686.255
991.954	675.736
996.145	657.282
1000.33	643.215
1004.52	642.994
1008.71	654.617
1012.89	674.549
1017.07	690.25
1021.25	688.88
1025.43	728.763
1029.6	777.251
1033.77	830.288
1037.95	953.832
1042.11	1253.9
1046.28	1791.72
1050.45	1913.42
1054.61	1576.69
1058.77	1253.85
1062.93	1022.77
1067.09	944.15
1071.24	959.921
1075.4	1021.69
1079.55	1291.44
1083.7	1642.23
1087.85	1846.43
1091.99	1672.08
1096.14	1513.93
1100.28	1595.42
1104.42	1817.65
1108.55	1833.75
1112.69	1662.52
1116.82	1500.02
1120.96	1557.85
1125.09	1644.77
1129.21	1713.54
1133.34	1542.29
1137.46	1269.36
1141.59	1148.24
1145.71	1164.58
1149.83	1278.25
1153.94	1411.98
1158.06	1313.43
1162.17	1100.75
1166.28	999.378
1170.39	895.635
1174.5	803.151
1178.6	779.752
1182.7	766.654
1186.8	746.856
1190.9	812.968
1195	788.583
1199.1	792.592
1203.19	774.106
1207.28	726.329
1211.37	802.207
1215.46	878.705
1219.54	976.106
1223.63	937.661
1227.71	886.76
1231.79	982.351
1235.87	1088.98
1239.95	1044.23
1244.02	916.84
1248.09	898.987
1252.16	834.413
1256.23	768.93
1260.3	748.478
1264.36	911.267
1268.43	2080.56
1272.49	1250.36
1276.55	748.631
1280.6	726.287
1284.66	688.598
1288.71	688.081
1292.76	697.474
1296.81	715.911
1300.86	677.794
1304.91	689.939
1308.95	678.929
1312.99	677.762
1317.03	677.372
1321.07	694.013
1325.11	683.093
1329.14	682.383
1333.18	696.437
1337.21	668.247
1341.24	684.045
1345.26	705.722
1349.29	742.272
1353.31	734.982
1357.33	738.63
1361.35	789.782
1365.37	871.651
1369.39	1755.18
1373.4	2804.65
1377.41	1111.94
1381.43	746.86
1385.43	740.75
1389.44	750.47
1393.45	836.326
1397.45	784.516
1401.45	696.045
1405.45	671.67
1409.45	665.08
1413.44	655.569
1417.44	638.133
1421.43	633.48
1425.42	646.386
1429.41	628.464
1433.39	650.212
1437.38	650.131
1441.36	644.149
1445.34	651.85
1449.32	622.035
1453.3	631.555
1457.27	640.029
1461.24	637.47
1465.22	667.23
1469.19	651.809
1473.15	654.104
1477.12	621.944
1481.09	633.882
1485.05	628.142
1489.01	656.588
1492.97	630.411
1496.93	641.326
1500.88	641.628
1504.83	625.547
1508.79	636.822
1512.74	642.259
1516.68	642.906
1520.63	641.671
1524.57	646.295
1528.52	643.231
1532.46	677.056
1536.4	642.063
1540.33	655.551
1544.27	653.529
1548.2	650.543
1552.14	653.329
1556.07	663.753
1559.99	642.145
1563.92	664.99
1567.84	651.016
1571.77	659.251
1575.69	663.601
1579.61	672.738
1583.52	650.991
1587.44	655.237
1591.35	666.205
1595.27	673.301
1599.18	680.417
1603.09	673.216
1606.99	682.396
1610.9	669.535
1614.8	686.472
1618.7	673.736
1622.6	669.634
1626.5	692.466
1630.39	663.754
1634.29	683.972
1638.18	663.049
1642.07	681.598
1645.96	673.408
1649.85	685.396
1653.73	684.904
1657.62	661.303
1661.5	665.473
1665.38	665.682
1669.26	656.148
1673.13	666.656
1677.01	652.001
1680.88	644.732
1684.75	647.006
1688.62	649.179
1692.49	646.438
1696.35	633.099
1700.22	625.398
1704.08	653.777
1707.94	651.495
1711.8	641.574
1715.66	659.177
1719.51	644.614
1723.37	647.053
1727.22	628.698
1731.07	665.765
1734.92	653.985
1738.76	638.421
1742.61	644.352
1746.45	639.341
1750.29	616.118
1754.13	619.195
1757.97	636.005
1761.81	613.206
1765.64	634.71
1769.47	644.559
1773.31	610.825
1777.14	633.006
1780.96	622.775
1784.79	630.334
1788.61	634.222
1792.43	606.258
1796.25	635.487
1800.07	634.459
1803.89	631.3
1807.71	636.594
1811.52	624.813
1815.33	624.134
1819.14	630.776
1822.95	604.273
1826.76	622.909
1830.56	638.526
1834.37	636.098
1838.17	657.094
1841.97	630.929
1845.77	634.837
1849.56	640.489
1853.36	628.095
1857.15	660.384
1860.94	624.411
1864.73	661.093
1868.52	633.717
1872.31	636.168
1876.09	648.857
1879.87	644.154
1883.66	624.876
1887.43	633.659
1891.21	655.682
1894.99	628.887
1898.76	605.023
1902.53	655.907
1906.31	635.076
1910.08	607.006
1913.84	638.067
1917.61	616.783
1921.37	664.149
1925.14	602.328
1928.9	630.485
1932.66	624.313
1936.41	651.679
1940.17	644.546
1943.92	652.502
1947.68	654.285
1951.43	637.982
1955.18	626.994
1958.92	657.947
1962.67	641.879
1966.41	654.85
1970.16	666.531
1973.9	658.383
1977.64	616.417
1981.37	637.102
1985.11	623.075
1988.84	622.09
1992.57	654.443
1996.31	650.359
2000.03	635.086
2003.76	652.329
2007.49	667.411
2011.21	636.377
2014.93	657.074
2018.65	651.553
2022.37	646.333
2026.09	639.64
2029.81	609.953
2033.52	639.451
2037.23	643.145
2040.94	652.371
2044.65	652.344
2048.36	633.229
2052.07	655.409
2055.77	649.311
2059.47	640.979
2063.17	622.73
2066.87	642.242
2070.57	668.299
2074.27	645.488
2077.96	671.735
2081.65	630.341
2085.34	645.09
2089.03	661.791
2092.72	654.679
2096.41	675.588
2100.09	644.087
2103.77	648.749
2107.46	660.733
2111.14	650.339
2114.81	659.449
2118.49	641.412
2122.16	625.008
2125.84	662.357
2129.51	687.459
2133.18	646.828
2136.85	663.467
2140.51	626.458
2144.18	637.369
2147.84	653.737
2151.5	661.802
2155.16	656.139
2158.82	673.394
2162.48	652.369
2166.13	662.505
2169.79	655.503
2173.44	639.674
2177.09	656.674
2180.74	675.541
2184.38	651.654
2188.03	652.641
2191.67	677.518
2195.32	668.068
2198.96	661.397
2202.6	631.995
2206.23	675.732
2209.87	660.214
2213.5	663.957
2217.14	680.572
2220.77	654.06
2224.4	654.17
2228.03	654.234
2231.65	676.531
2235.28	652.663
2238.9	657.403
2242.52	651.011
2246.14	634.366
2249.76	646.597
2253.38	636.551
2256.99	633.965
2260.6	644.411
2264.21	645.496
2267.82	651.43
2271.44	653.618
2275.04	648.004
2278.65	660.99
2282.25	634.958
2285.85	615.639
2289.45	629.274
2293.05	638.172
2296.65	624.4
2300.25	640.878
2303.84	630.685
2307.43	652.608
2311.02	696.249
2314.62	888.575
2318.2	743.325
2321.79	644.307
2325.38	627.464
2328.96	637.134
2332.54	618.35
2336.12	639.117
2339.7	629.639
2343.28	665.192
2346.85	641.503
2350.43	635.643
2354	636.304
2357.57	622.01
2361.14	631.925
2364.71	636.253
2368.27	635.112
2371.84	659.947
2375.4	612.609
2378.96	638.332
2382.52	629.99
2386.08	623.592
2389.64	632.024
2393.19	638.763
2396.75	631.043
2400.3	636.44
2403.85	626.494
2407.4	613.907
2410.95	611.656
2414.49	636.15
2418.04	638.764
2421.58	617.551
2425.12	605.664
2428.66	616.975
2432.2	617.341
2435.74	632.663
2439.27	607.156
2442.81	640.321
2446.34	598.912
2449.87	619.301
2453.4	614.245
2456.93	603.91
2460.45	637.566
2463.98	639.92
2467.5	636.538
2471.02	633.022
2474.54	622.071
2478.06	608.538
2481.58	630.706
2485.09	622.367
2488.61	623.436
2492.12	624.575
2495.63	629.291
2499.14	624.737
2502.65	631.167
2506.15	618.834
2509.66	638.144
2513.16	621.272
2516.66	629.642
2520.16	639.536
2523.66	613.668
2527.16	623.275
2530.66	610.787
2534.15	628.949
2537.64	602.935
2541.13	617.78
2544.62	622.808
2548.11	626.054
2551.6	620.149
2555.08	603.474
2558.57	606.23
2562.05	604.586
2565.53	593.826
2569.01	612.135
2572.49	606.315
2575.96	625.01
2579.44	615.613
2582.91	603.347
2586.38	625.99
2589.85	609.472
2593.32	627.882
2596.79	615.058
2600.25	602.221
2603.72	631.229
2607.18	608.038
2610.64	608.164
2614.1	615.279
2617.56	627.941
2621.02	623.182
2624.47	614.398
2627.92	608.397
2631.38	614.752
2634.83	600.757
2638.28	621.165
2641.72	606.932
2645.17	606.085
2648.61	629.915
2652.06	608.756
2655.5	604.628
2658.94	630.778
2662.38	609.443
2665.82	602.359
2669.25	610.291
2672.69	591.985
2676.12	621.619
2679.55	618.531
2682.98	592.268
2686.41	613.066
2689.84	608.122
2693.26	575.068
2696.69	606.395
2700.11	601.505
2703.53	592.753
2706.95	605.864
2710.37	612.634
2713.79	603.706
2717.2	597.687
2720.62	613.202
2724.03	593.317
2727.44	601.493
2730.85	592.807
2734.26	597.209
2737.66	606.317
2741.07	608.763
2744.47	583.842
2747.87	610.597
2751.28	602.568
2754.67	590.633
2758.07	623.034
2761.47	596.866
2764.86	595.102
2768.26	619.596
2771.65	613.899
2775.04	593.025
2778.43	585.251
2781.82	600.96
2785.2	578.055
2788.59	613.457
2791.97	600.843
2795.35	604.268
2798.73	588.783
2802.11	599.579
2805.49	605.67
2808.87	608.906
2812.24	576.571
2815.62	618.987
2818.99	607.266
2822.36	601.264
2825.73	576.663
2829.1	605.266
2832.46	606.948
2835.83	586.372
2839.19	607.83
2842.55	620.102
2845.91	599.941
2849.27	598.695
2852.63	594.509
2855.99	601.601
2859.34	591.025
2862.69	588.88
2866.05	597.079
2869.4	599.613
2872.75	619.994
2876.09	599.93
2879.44	584.529
2882.78	599.221
2886.13	600.681
2889.47	584.24
2892.81	605.405
2896.15	599.087
2899.49	604.966
2902.82	585.209
2906.16	590.006
2909.49	606.092
2912.82	597.572
2916.16	608.808
2919.49	593.51
2922.81	588.605
2926.14	593.036
2929.46	632.383
2932.79	616.786
2936.11	591.783
2939.43	617.704
2942.75	584.27
2946.07	600.795
2949.39	606.933
2952.7	592.368
2956.02	603.27
2959.33	602.997
2962.64	606.457
2965.95	615.681
2969.26	582.945
2972.57	612.002
2975.87	609.409
2979.17	605.744
2982.48	624.636
2985.78	597.581
2989.08	608.093
2992.38	599.849
2995.68	625.477
2998.97	635.152
3002.27	625.988
3005.56	624.405
3008.85	616.262
3012.14	627.927
3015.43	634.872
3018.72	609.745
3022	615.727
3025.29	622.674
3028.57	617.345
3031.85	620.489
3035.14	657.643
3038.41	630.509
3041.69	672.444
3044.97	639.64
3048.24	639.935
3051.52	663.017
3054.79	633.947
3058.06	634.184
3061.33	677.909
3064.6	655.282
3067.87	668.622
3071.13	684.271
3074.4	668.977
3077.66	695.406
3080.92	691.878
3084.18	702.72
3087.44	666.22
3090.7	689.696
3093.95	694.436
3097.21	681.204
3100.46	712.664
3103.71	724.389
3106.96	720.934
3110.21	728.684
3113.46	756.411
3116.71	728.952
3119.95	751.016
3123.2	750.218
3126.44	766.546
3129.68	773.355
3132.92	759.185
3136.16	762.132
3139.4	781.266
3142.63	797.54
3145.87	802.415
3149.1	834.981
3152.33	801.714
3155.56	818.057
3158.79	847.745
3162.02	844.043
3165.25	863.186
3168.47	884.169
3171.69	855.488
3174.92	863.002
3178.14	943.936
3181.36	909.457
3184.58	911.147
3187.79	925.181
3191.01	942.057
3194.22	977.968
3197.43	966.209
3200.65	952.58
3203.86	960.885
3207.07	991.113
3210.27	969.06
3213.48	998.46
3216.69	991.723
3219.89	1010.69
3223.09	1019.28
3226.29	1015.55
3229.49	1037.58
3232.69	1011.98
3235.89	1036.03
3239.08	1018.3
3242.28	1025.38
3245.47	1049.62
3248.66	1057.77
3251.85	1056.43
3255.04	1052.24
3258.23	1077.53
3261.42	1062.56
3264.6	1074.18
3267.79	1090.46
3270.97	1077.99
3274.15	1055.01
3277.33	1115.92
3280.51	1062.94
3283.68	1078.7
3286.86	1085.77
3290.04	1070.97
3293.21	1101.91
3296.38	1147.06
3299.55	1125.82
3302.72	1140.57
3305.89	1124.72
3309.06	1139.14
3312.22	1164.83
3315.39	1172.41
3318.55	1186.57
3321.71	1155.24
3324.87	1166.55
3328.03	1173.14
3331.19	1203.41
3334.34	1191.23
3337.5	1224.48
3340.65	1208.65
3343.81	1226.06
3346.96	1238.16
3350.11	1265.37
3353.25	1246.51
3356.4	1288.05
3359.55	1277.9
3362.69	1306.45
3365.84	1330.38
3368.98	1321.33
3372.12	1331.31
3375.26	1372.53
3378.4	1382.71
3381.53	1353.12
3384.67	1403.05
3387.8	1418.04
3390.94	1453.96
3394.07	1460.92
3397.2	1468.6
3400.33	1546.76
3403.46	1622.37
3406.58	1691.59
3409.71	1913.29
3412.83	2635.98
3415.96	4328.04
3419.08	6480.2
3422.2	5623.65
3425.32	3316.08
3428.44	2203.33
3431.55	1781.31
3434.67	1643.32
3437.78	1569.48
3440.89	1508.16
3444	1499
3447.12	1466.93
3450.22	1470.87
3453.33	1467.16
3456.44	1455.62
3459.54	1464.98
3462.65	1453.35
3465.75	1454.91
3468.85	1528.08
3471.95	1567.43
3475.05	1551.97
3478.15	1618.9
3481.24	1708.45
3484.34	1860.32
3487.43	2036.7
3490.53	2378.75
3493.62	2848.1
3496.71	3356.49
3499.79	3751.71
3502.88	3640.64
3505.97	3166.25
3509.05	2624.48
3512.14	2112.42
3515.22	1803.97
3518.3	1611.7
3521.38	1489.55
3524.46	1393.99
3527.54	1303.12
3530.61	1257.32
3533.69	1181.56
3536.76	1149.03
3539.83	1116.36
3542.9	1047.3
3545.97	1027.31
3549.04	1027
3552.11	970.694
3555.18	975.985
3558.24	934.05
3561.3	928.795
3564.37	898.82
3567.43	908.682
3570.49	887.102
3573.55	891.966
3576.61	875.927
3579.66	866.455
3582.72	857.849
3585.77	827.41
3588.82	815.864
3591.87	778.687
3594.92	801.169
3597.97	765.836
3601.02	760.771
3604.07	766.052
3607.11	742.932
3610.16	720.753
3613.2	717.459
3616.24	708.518
3619.28	699.621
3622.32	690.756
3625.36	696.081
3628.39	673.124
3631.43	652.025
3634.46	690.349
3637.5	642.199
3640.53	628.948
3643.56	626.206
3646.59	595.138
3649.62	598.022
3652.64	587.085
3655.67	543.087
3658.69	568.065
3661.72	562.863
3664.74	549.872
3667.76	518.041
3670.78	506.041
3673.79	504.438
3676.81	516.087
3679.83	502.223
3682.84	497.793
3685.86	504.724
3688.87	488.011
3691.88	484.555
3694.89	485.751
3697.9	487.004
3700.91	481.646
3703.91	500.972
3706.92	468.011
3709.92	470.154
3712.92	470.334
3715.92	482.9
3718.92	434.521
3721.92	477.472
3724.92	445.17
3727.92	453.777
3730.91	452.821
3733.91	452.766
3736.9	444.102
3739.89	440.149
3742.88	454.232
3745.87	430.227
3748.86	433.767
3751.85	449.632
3754.83	440.811
3757.82	438.637
3760.8	444.96
3763.78	441.8
3766.76	443.403
3769.74	436.532
3772.72	441.994
3775.7	427.633
3778.67	423.704
3781.65	424.51
3784.62	421.558
3787.6	421.462
3790.57	448.797
3793.54	417.658
3796.51	428.073
3799.47	415.885
3802.44	422.611
3805.41	412.35
3808.37	443.687
3811.33	435.357
3814.3	401.493
3817.26	403.573
3820.22	401.877
3823.18	427.677
3826.13	426.033
3829.09	412.052
3832.04	423.708
3835	414.516
3837.95	421.473
3840.9	425.583
3843.85	429.704
3846.8	406.226
3849.75	401.798
3852.69	406.916
3855.64	409.184
3858.58	408.596
3861.53	404.16
3864.47	402.587
3867.41	399.066
3870.35	414.7
3873.29	408.275
3876.22	410.441
3879.16	414.488
3882.1	402.151
3885.03	403.227
3887.96	404.282
3890.89	417.824
3893.82	400.55
3896.75	393.798
3899.68	410.116
3902.61	408.103
3905.53	393.634
3908.46	393.566
3911.38	400.189
3914.3	401.955
3917.23	412.437
3920.15	413.261
3923.06	403.474
3925.98	390.78
3928.9	399.145
3931.81	390.332
3934.73	380.649
3937.64	387.339
3940.55	396.877
3943.46	400.675
3946.37	392.065
3949.28	365.295
3952.19	379.711
3955.09	396.083
3958	367.452
3960.9	399.204
3963.8	378.265
3966.71	369.8
3969.61	390.134
3972.51	390.321
3975.4	374.157
3978.3	385.819
3981.2	384.022
3984.09	404.319
3986.99	381.346
3989.88	385.23
3992.77	388.219
3995.66	372.927
3998.55	378.823
4001.43	383.765
4004.32	375.242
4007.21	359.976
4010.09	382.294
4012.98	368.944
4015.86	384.533
4018.74	378.895
4021.62	374.217
4024.5	375.341
4027.37	368.734
4030.25	391.142
4033.13	366.167
4036	369.256
4038.87	361.7
4041.75	377.328
4044.62	375.517
4047.49	361.126
4050.35	352.561
4053.22	345.956
4056.09	357.802
4058.95	364.782
4061.82	386.345
4064.68	364.171
4067.54	372.13
4070.4	354.786
4073.26	377.346
4076.12	360.95
4078.98	366.956
4081.83	365.168
4084.69	359.467
4087.54	368.388
4090.4	367.571
4093.25	350.147
4096.1	350.288
4098.95	340.665
4101.8	333.953
4104.64	362.425
4107.49	363.495
4110.33	352.806
4113.18	370.452
4116.02	355.758
4118.86	364.53
4121.7	359.635
4124.54	335.193
4127.38	378.338
4130.22	349.131
4133.05	347.406
4135.89	358.229
4138.72	332.378
4141.56	332.147
4144.39	344.969
4147.22	371.533
4150.05	336.384
4152.88	354.971
4155.7	334.253
4158.53	349.758
4161.36	330.149
4164.18	338.911
4167	339.852
4169.82	356.461
4172.65	319.296
4175.46	342.767
4178.28	348.651
4181.1	337.93
4183.92	337.003
4186.73	340.983
4189.55	343.04
4192.36	352.002
4195.17	337.502
4197.98	339.667
4200.79	359.485
4203.6	371.479
4206.41	330.451
4209.21	334.574
4212.02	354.422
4214.83	328.171
4217.63	329.542
4220.43	318.044
4223.23	333.143
4226.03	330.497
4228.83	333.821
4231.63	339.157
4234.42	333.634
4237.22	339.026
4240.01	339.471
4242.81	322.015
4245.6	329.429
4248.39	324.855
4251.18	334.24
4253.97	332.623
4256.76	320.968
4259.55	328.347
4262.33	336.761
4265.12	323.104
4267.9	325.52
4270.68	317.857
4273.47	318.203
4276.25	341.708
4279.03	321.779
4281.8	312.912
4284.58	314.111
4287.36	319.322
4290.13	316.415
4292.91	297.319
4295.68	311.688
4298.45	320.993
4301.22	319.128
4303.99	327.413
4306.76	335.715
4309.53	319.661
4312.3	320.859
4315.06	308.785
4317.83	305.839
4320.59	302.868
4323.35	300.893
4326.11	316.233
4328.87	298.968
4331.63	302.066
4334.39	309.234
4337.15	307.251
4339.9	309.377
4342.66	321.716
4345.41	288.193
4348.17	307.723
4350.92	301.791
4353.67	295.871
4356.42	305.26
4359.17	310.56
4361.91	315.875
4364.66	297.632
4367.41	301.924
4370.15	290.817
4372.89	280.693
4375.63	291.081
4378.38	296.325
4381.12	292.336
4383.86	305.871
4386.59	316.442
4389.33	305.484
4392.07	296.717
4394.8	301.332
4397.53	305.828
4400.27	294.786
4403	284.749
4405.73	301.708
4408.46	306.213
4411.19	300.275
4413.92	290.131
4416.64	294.489
4419.37	287.357
4422.09	275.042
4424.82	301.362
4427.54	303.678
4430.26	290.301
4432.98	298.878
4435.7	281.262
4438.42	275.131
4441.13	303.592
4443.85	296.404
4446.57	290.248
4449.28	279.872
4451.99	292.586
4454.71	300.036
4457.42	286.447
4460.13	286.539
4462.83	299.266
4465.54	273.073
4468.25	287.933
4470.95	274.387
4473.66	273.5
4476.36	282.126
4479.07	289.728
4481.77	291.01
4484.47	267.966
4487.17	286.137
4489.87	288.406
4492.56	271.513
4495.26	274.804
4497.96	275.982
4500.65	287.707
4503.34	279.333
4506.04	262.482
4508.73	276.384
4511.42	268.013
4514.11	279.822
4516.8	281.017
4519.48	267.371
4522.17	268.606
4524.85	258.121
4527.54	290.237
4530.22	257.386
4532.9	283.162
4535.58	262.014
4538.27	283.59
4540.94	280.601
4543.62	257.296
4546.3	270.357
4548.98	262.015
4551.65	277.322
4554.33	248.639
4557	258.694
4559.67	261.283
4562.34	274.726
4565.01	267.825
4567.68	268.397
4570.35	262.137
4573.02	262.133
4575.68	264.458
4578.35	275.554
4581.01	257.483
4583.67	268.565
4586.34	248.037
4589	256.905
4591.66	261.4
4594.31	255.064
4596.97	270.507
4599.63	260.878
4602.29	262.208
4604.94	254.773
4607.59	253.916
4610.25	259.634
4612.9	231.292
4615.55	254.596
4618.2	266.959
4620.85	255.099
4623.5	263.05
4626.14	265.473
4628.79	242.498
4631.43	245.981
4634.08	250.545
4636.72	257.334
4639.36	246.39
4642	258.757
4644.64	262.343
4647.28	257.113
4649.92	236.37
4652.56	247.996
4655.19	253.528
4657.83	244.817
4660.46	236.15
4663.1	245.355
4665.73	256.704
4668.36	244.6
4670.99	258.237
4673.62	252.833
4676.24	255.271
4678.87	252.089
4681.5	254.519
4684.12	255.832
4686.75	239.136
4689.37	251.716
4691.99	222.587
4694.61	229.499
4697.23	230.783
4699.85	236.59
4702.47	251.414
4705.09	235.724
4707.7	252.808
4710.32	231.428
4712.93	254.181
4715.55	249.745
4718.16	252.114
4720.77	243.109
4723.38	250.012
4725.99	235.391
4728.6	236.646
4731.21	236.769
4733.81	232.346
4736.42	251.763
4739.02	243.912
4741.63	233.745
4744.23	250.885
4746.83	225.869
4749.43	241.826
4752.03	237.301
4754.63	231.624
4757.23	220.274
4759.82	246.52
4762.42	226.083
4765.01	228.46
4767.61	236.614
4770.2	223.023
4772.79	225.402
4775.38	234.64
4777.97	225.604
4780.56	235.987
4783.15	224.662
4785.74	215.614
4788.32	237.46
4790.91	229.575
4793.49	218.242
4796.07	232.144
4798.66	223.135
4801.24	233.647
4803.82	218.921
4806.4	239.862
4808.98	225.133
4811.55	221.918
4814.13	214.087
4816.71	230.533
4819.28	219.247
4821.85	243.85
4824.43	229.08
4827	235.161
4829.57	230.833
4832.14	210.186
4834.71	226.827
4837.28	222.518
4839.84	207.677
4842.41	238.442
4844.97	218.815
4847.54	226.128
4850.1	208.625
4852.66	213.317
4855.22	228.933
4857.78	230.451
4860.34	227.204
4862.9	217.949
4865.46	213.367
4868.01	217.166
4870.57	220.915
4873.12	208.034
4875.68	217.676
4878.23	211.889
4880.78	212.017
4883.33	215.705
4885.88	220.589
4888.43	219.539
4890.98	208.951
4893.53	215.024
4896.07	205.598
4898.62	212.857
4901.16	204.602
4903.7	213.062
4906.25	210.749
4908.79	204.832
4911.33	214.41
4913.87	216.806
4916.41	209.651
4918.94	194.142
4921.48	204.917
4924.02	209.73
4926.55	224.095
4929.08	207.406
4931.62	214.677
4934.15	212.382
4936.68	219.646
4939.21	210.093
4941.74	202.939
4944.27	205.424
4946.79	210.311
4949.32	199.624
4951.85	191.318
4954.37	202.216
4956.9	204.748
4959.42	201.293
4961.94	206.294
4964.46	212.559
4966.98	200.73
4969.5	200.91
4972.02	208.333
4974.53	198.841
4977.05	195.387
4979.57	199.197
4982.08	201.807
4984.59	185.017
4987.1	187.628
4989.62	196.319
4992.13	203.802
4994.64	193.05
4997.15	193.271
4999.65	205.703