File: Data/3-Raman/raw/bu19(2)w-a-ff1-fi03-l_150 (500nm)_532nm_edge_100%_x100_vis_lwd_h50um_30sx2_01.txt
#Acq. time (s)=	30
#Accumulations=	2
#Range (cm-¹)=	99...4000
#Windows=	1
#Auto scanning=	Off
#Autofocus=	Off
#Macrospot=	Off
#AutoExposure=	Off
#Spike filter=	Multiple accum.
#Delay time (s)=	2
#Binning=	1
#Readout mode=	Signal
#DeNoise=	Off
#ICS correction=	On
#Dark correction=	Off
#Inst. Process=	Off
#Detector Gain=	Best Dynamic
#Detector ADC=	50 kHz HS
#Detector temperature (°C)=	-60.09
#Instrument=	LabRAM HR Evol
#Detector=	SIN-EM FIVIS
#Objective=	x100_VIS_LWD
#Grating=	150 (500nm)
#ND Filter=	100%
#Laser=	532nm_Edge
#Hole=	49.98
#Temperature=	0
#Range=	Visible
#StageXY=	75x50mm Scan+
#StageZ=	Z motor
#X (µm)=	0
#Y (µm)=	0
#Z (µm)=	-10.5
#Full time(mm:ss)=	1:04
#Project=	21_11_26
#Sample=	BU19(2)w
#Site=
#Title=	BU19(2)w-A-FF1-FI03-L_150 (500nm)_532nm_Edge_100%_x100_VIS_LWD_H50um_30sX2
#Remark=
#Date=	26.11.2021 12:16
#Acquired=	26.11.2021 12:16:14
102.91	11314.7
107.534	11366.5
112.156	12465.6
116.775	14802.9
121.392	14847.1
126.005	13192.7
130.617	11166.3
135.227	10736.2
139.835	11687.7
144.439	14319.7
149.042	19445.3
153.643	25714.3
158.242	25812.4
162.839	19809.5
167.431	14202.1
172.023	11088
176.613	9331.34
181.198	8331.65
185.783	7604.44
190.366	7145.54
194.947	6762.72
199.524	6631.96
204.1	6630.63
208.674	7214.77
213.243	9124.73
217.813	11836.9
222.38	9533.43
226.945	6927.45
231.506	6369.85
236.066	7247.64
240.625	9774.42
245.179	10268.3
249.732	7521.73
254.284	5790.22
258.831	5261.6
263.378	5007.52
267.923	5021.21
272.464	4940.31
277.004	4876.85
281.54	4968.57
286.076	5232.28
290.61	5361.9
295.139	4980.08
299.669	4734.05
304.196	4611.65
308.718	4746.81
313.241	4732.59
317.759	4815.17
322.278	4994.3
326.794	5165.03
331.305	5529.5
335.817	6349.6
340.324	7177.25
344.832	7323.73
349.334	6889.9
353.837	6993.1
358.338	7927.12
362.834	7851.18
367.33	6688.73
371.822	6152.73
376.314	5987.19
380.802	6115.82
385.289	6330.54
389.772	7042.02
394.255	8712.97
398.734	11467
403.213	12891.1
407.688	12092.3
412.162	10919.5
416.632	9728.79
421.102	9139.07
425.568	8899.68
430.033	9307.7
434.495	9884.13
438.956	10225.7
443.413	10105.7
447.87	9975.66
452.323	10025.8
456.776	10782.6
461.224	10808.3
465.673	9955.86
470.117	8663.44
474.561	7576.79
479.001	7196.83
483.438	7094.46
487.876	7218.27
492.309	7616.97
496.742	8212.92
501.172	9364.6
505.601	11050.5
510.025	13328.9
514.448	15687.8
518.871	16838.7
523.289	16301.9
527.707	14636.3
532.121	13202.6
536.533	12343.9
540.945	11938.6
545.353	11948.1
549.758	12062.6
554.164	12320.6
558.565	12260.6
562.965	11869.2
567.364	11288
571.759	10352.3
576.151	9613.73
580.544	9035.8
584.933	8597.32
589.319	8574.45
593.706	8717.4
598.088	8992.25
602.468	9785.34
606.848	10409.4
611.224	11345.6
615.598	13150.5
619.972	16774.4
624.341	24264
628.709	29810.5
633.074	25194.3
637.44	17500.4
641.801	12993.1
646.16	10791.8
650.517	9688.59
654.874	9001.68
659.227	8567.2
663.578	8182.41
667.927	8141.24
672.275	7995.81
676.62	7860.97
680.962	7739
685.302	7833.43
689.643	7759.02
693.979	7801.67
698.313	7907.23
702.645	8100.06
706.975	8456.27
711.305	8764.37
715.631	8684.34
719.955	8561.43
724.276	8316.92
728.596	8364.07
732.913	8352.56
737.231	8268.53
741.544	8239.9
745.856	8168.61
750.165	8223.17
754.472	8272.24
758.778	8250.48
763.081	8285.14
767.384	8338.09
771.683	8356.6
775.98	8419.34
780.275	8495.41
784.568	8542.07
788.859	8601.01
793.147	8628.12
797.434	8777.49
801.719	8731.56
806.004	8945.34
810.284	8971.08
814.563	9031.29
818.839	9198.64
823.114	9271.34
827.386	9484.32
831.657	9685.2
835.925	10040.8
840.192	10456.8
844.456	10993.3
848.719	11612.1
852.979	11904.9
857.237	11909.8
861.493	11557.4
865.748	11513.7
870	11226.5
874.25	10992.5
878.499	10970.1
882.745	11050.3
886.989	11374.6
891.231	11288.6
895.471	10783.6
899.71	10477.7
903.946	10367.8
908.18	10220.7
912.412	10251.8
916.642	10249.1
920.87	10251.8
925.096	10311.9
929.321	10261.6
933.543	10278.8
937.763	10407.5
941.981	10491.1
946.197	10578.4
950.412	10672.4
954.622	10797.8
958.832	10808
963.04	10886.6
967.246	10894
971.451	10942
975.653	10902.1
979.853	10960.1
984.052	10972.5
988.248	11213.3
992.442	11235.8
996.633	11378.8
1000.82	11620.4
1005.01	11832.1
1009.2	12010
1013.38	12001.5
1017.57	11875.8
1021.75	11915.9
1025.92	11924.7
1030.1	11979.2
1034.27	12136.7
1038.45	12239.8
1042.62	12384.2
1046.78	12755.2
1050.95	13378.8
1055.12	13629
1059.28	13668.7
1063.44	13611.2
1067.6	13728.8
1071.75	13993.8
1075.91	14321.5
1080.06	14977.7
1084.21	15946.7
1088.36	17296.3
1092.51	19746.4
1096.65	23351.8
1100.8	27243.9
1104.94	27586
1109.08	23757.9
1113.21	19336.7
1117.35	16710.2
1121.48	15359.5
1125.61	14832.6
1129.74	14661.3
1133.87	14623.8
1137.99	14959.4
1142.12	15656.7
1146.24	16800.8
1150.36	17757
1154.48	17907.5
1158.59	17296.5
1162.71	16114.4
1166.82	15174.5
1170.93	14637.7
1175.04	14181.9
1179.14	13960
1183.25	13793.7
1187.35	13769.2
1191.45	13585.1
1195.55	13514.2
1199.65	13574.9
1203.74	13490
1207.83	13378.1
1211.92	13533.7
1216.01	13547.6
1220.1	13461
1224.19	13530.6
1228.27	13594.7
1232.35	13717.7
1236.43	13673
1240.51	13719.3
1244.58	13752.5
1248.66	13757.1
1252.73	13836
1256.8	13904.1
1260.87	14077.6
1264.93	14011.3
1269	14082.9
1273.06	14098.8
1277.12	14069.5
1281.18	14036.6
1285.23	13946.9
1289.29	14158.5
1293.34	14147.1
1297.39	14091.2
1301.44	14150.9
1305.49	14148.3
1309.53	14099.4
1313.58	14269.6
1317.62	14250.2
1321.66	14378.8
1325.7	14373
1329.73	14462.8
1333.77	14400.2
1337.8	14472.3
1341.83	14562.6
1345.86	14661
1349.88	14527.4
1353.91	14688.1
1357.93	14769.4
1361.95	14861.1
1365.97	14990.8
1369.99	15208.4
1374	15649.1
1378.02	15609.1
1382.03	15270.5
1386.04	14996.3
1390.05	14976.4
1394.05	14876.9
1398.06	14938.3
1402.06	14894.1
1406.06	14855.3
1410.06	14852.5
1414.05	14842.2
1418.05	14903.2
1422.04	15069.7
1426.03	15027.9
1430.02	15001.2
1434.01	15087.3
1438	15064.5
1441.98	15130.8
1445.96	15108.8
1449.94	15156
1453.92	15216.4
1457.9	15172.6
1461.87	15165.6
1465.85	15279.6
1469.82	15252.9
1473.78	15202.8
1477.75	15294
1481.72	15296.7
1485.68	15386.5
1489.65	15318.5
1493.61	15324.1
1497.56	15427.5
1501.52	15447.6
1505.47	15467.4
1509.43	15466.2
1513.38	15517.7
1517.33	15591.3
1521.27	15581.2
1525.22	15654.5
1529.16	15544.9
1533.11	15608.8
1537.05	15678.9
1540.98	15754.4
1544.92	15670
1548.86	15653.5
1552.79	15811.4
1556.72	15789.1
1560.65	15768.3
1564.58	15776.7
1568.5	15903.4
1572.43	15874.1
1576.35	15850.4
1580.27	15864.7
1584.19	15872.7
1588.1	15945
1592.02	15891.7
1595.93	16037.2
1599.84	16015.3
1603.75	16042.7
1607.66	16201.2
1611.57	16138.4
1615.47	16276.2
1619.37	16248.5
1623.27	16229.5
1627.17	16284.7
1631.07	16256
1634.97	16280.4
1638.86	16349.1
1642.75	16314.7
1646.64	16443.8
1650.53	16275.6
1654.42	16385.2
1658.3	16309.2
1662.18	16300.7
1666.07	16160.2
1669.94	16313.9
1673.82	16212.6
1677.7	16187.3
1681.57	16297.3
1685.44	16236.9
1689.31	16183.8
1693.18	16099.8
1697.05	16083.4
1700.92	16154.1
1704.78	16218.3
1708.64	16237.8
1712.5	16239.7
1716.36	16277.6
1720.21	16222.4
1724.07	16145.2
1727.92	16229
1731.77	16174.3
1735.62	16205.7
1739.47	16221.9
1743.32	16138.9
1747.16	16124.2
1751.01	16249.6
1754.85	16124.3
1758.69	16215.4
1762.52	16096.6
1766.36	16226.3
1770.19	16225.6
1774.02	16126.8
1777.85	16180.1
1781.68	16136.4
1785.51	16173.8
1789.33	16026.9
1793.16	15980.6
1796.98	16016.1
1800.8	16049.1
1804.62	15991.9
1808.43	16148.9
1812.25	15898.9
1816.06	16012.6
1819.87	15967.5
1823.68	15876.7
1827.49	15981.9
1831.3	16003.5
1835.1	15965.3
1838.9	16014.8
1842.71	15975.2
1846.51	15985.4
1850.3	15976.1
1854.1	15987.3
1857.89	16083.2
1861.69	16030.8
1865.48	15964.8
1869.27	15998.2
1873.05	15896
1876.84	15908.4
1880.62	15890.6
1884.4	15938.6
1888.19	16026.8
1891.96	15875.5
1895.74	15996.2
1899.52	15790.3
1903.29	15911.5
1907.06	15854.6
1910.83	15762.3
1914.6	15712.6
1918.37	15596.6
1922.13	15741.7
1925.9	15661.1
1929.66	15621.9
1933.42	15745.7
1937.18	15761.6
1940.94	15577.1
1944.69	15647.8
1948.44	15620.3
1952.2	15636.6
1955.95	15591.1
1959.69	15655.8
1963.44	15692.6
1967.19	15648.8
1970.93	15685.4
1974.67	15744.3
1978.41	15720.2
1982.15	15701.8
1985.89	15812.5
1989.62	15781
1993.35	15585.1
1997.09	15741.7
2000.82	15784.4
2004.55	15777.6
2008.27	15715.4
2012	15584.3
2015.72	15600.5
2019.44	15518.6
2023.16	15617.6
2026.88	15540.9
2030.6	15537.3
2034.31	15436
2038.03	15394.1
2041.74	15471.6
2045.45	15319.9
2049.16	15384.6
2052.86	15288.5
2056.57	15228.9
2060.27	15213.9
2063.98	15146.8
2067.67	15104.3
2071.37	15105.4
2075.07	15167.5
2078.77	15101.5
2082.46	15028.9
2086.15	14943
2089.84	14984
2093.53	15105.3
2097.22	14984
2100.9	14954.8
2104.59	14920.4
2108.27	14838.7
2111.95	14822.6
2115.63	14813.4
2119.31	14850.7
2122.98	14789.1
2126.66	14813.5
2130.33	14654.8
2134	14748.6
2137.67	14771
2141.34	14652.3
2145	14656
2148.67	14572.3
2152.33	14652.1
2155.99	14531.4
2159.65	14476.6
2163.31	14391.8
2166.96	14432.7
2170.62	14330.2
2174.27	14365
2177.92	14345.7
2181.57	14334.6
2185.22	14178.4
2188.87	14253.4
2192.51	14190.2
2196.15	14210.2
2199.8	14233.4
2203.44	14005.7
2207.07	14125.8
2210.71	13999.9
2214.35	13987.3
2217.98	13947
2221.61	14052.9
2225.24	13870.1
2228.87	13848.9
2232.5	13809.5
2236.12	13787.7
2239.75	13820.1
2243.37	13761.4
2246.99	13766
2250.61	13669.9
2254.23	13654.1
2257.85	13696.4
2261.46	13588.1
2265.07	13565.7
2268.68	13520.3
2272.29	13452.4
2275.9	13501
2279.51	13464
2283.11	13463.2
2286.72	13352.5
2290.32	13278.4
2293.92	13306.4
2297.52	13191.9
2301.11	13082.4
2304.71	13211.3
2308.3	13093.8
2311.9	13069.3
2315.49	13000
2319.08	13050.8
2322.66	13106.1
2326.25	13030.4
2329.84	13051.7
2333.42	12886.3
2337	12995.8
2340.58	12984.7
2344.16	12896
2347.73	12751.6
2351.31	12817.5
2354.88	12782.4
2358.45	12745.7
2362.03	12806.1
2365.59	12739.6
2369.16	12668.6
2372.73	12669.5
2376.29	12589.1
2379.85	12392.9
2383.41	12378.6
2386.97	12463
2390.53	12395
2394.09	12338.8
2397.64	12253.4
2401.2	12204.4
2404.75	12186.9
2408.3	12110.4
2411.85	12143.5
2415.39	12159.4
2418.94	12095.6
2422.48	11957.1
2426.03	11952.9
2429.57	11997
2433.11	11911.3
2436.64	11882.5
2440.18	11836.3
2443.72	11824.3
2447.25	11787.2
2450.78	11778.6
2454.31	11708.2
2457.84	11738.8
2461.37	11629.3
2464.89	11614.5
2468.42	11665.4
2471.94	11527.5
2475.46	11571.4
2478.98	11520
2482.5	11577
2486.01	11449.8
2489.53	11420.2
2493.04	11411.8
2496.55	11302.3
2500.06	11318.9
2503.57	11442
2507.08	11301.4
2510.58	11138.2
2514.09	11159.7
2517.59	11160.5
2521.09	11115.1
2524.59	11149.1
2528.09	11046.3
2531.59	10881.8
2535.08	10836.4
2538.58	10911.4
2542.07	10838.6
2545.56	10826.3
2549.05	10839.1
2552.54	10687.8
2556.02	10685.4
2559.51	10680.8
2562.99	10638.2
2566.47	10692.3
2569.95	10605.5
2573.43	10532.2
2576.91	10537.3
2580.38	10525.7
2583.85	10400.6
2587.33	10418.3
2590.8	10400.3
2594.27	10390
2597.74	10326.4
2601.2	10299.9
2604.67	10303.9
2608.13	10254
2611.59	10093.5
2615.06	10136.1
2618.51	10071.1
2621.97	10060.4
2625.43	10067.9
2628.88	10039
2632.33	10027.7
2635.79	9932.32
2639.24	10030.7
2642.69	9926.83
2646.13	9897.78
2649.58	9871.94
2653.02	9907.73
2656.47	9830.45
2659.91	9780.85
2663.35	9753.09
2666.79	9762.3
2670.22	9729.74
2673.66	9684.57
2677.09	9612.1
2680.52	9551.68
2683.95	9577.71
2687.39	9557.59
2690.81	9452.37
2694.24	9386.05
2697.66	9392.33
2701.09	9369.11
2704.51	9269.02
2707.93	9346.05
2711.35	9222.24
2714.77	9260.32
2718.18	9142.93
2721.6	9142.7
2725.01	9192.17
2728.42	9104.26
2731.84	9094.29
2735.24	9036.97
2738.65	8971.08
2742.06	8965.6
2745.46	9027.8
2748.86	8902.77
2752.27	8903.66
2755.67	8805.92
2759.07	8796.5
2762.46	8782.52
2765.86	8770.89
2769.25	8705.11
2772.65	8749.06
2776.04	8690.47
2779.43	8754.73
2782.82	8693.44
2786.2	8687.06
2789.59	8601.37
2792.98	8541.78
2796.36	8572.16
2799.74	8612.82
2803.12	8455.03
2806.5	8388.49
2809.88	8460.46
2813.25	8389.6
2816.63	8350.14
2820	8361.96
2823.37	8292
2826.74	8268.05
2830.11	8254.08
2833.48	8197.45
2836.84	8151.69
2840.21	8079.4
2843.57	8079.51
2846.93	8116.03
2850.29	8100.51
2853.65	7954.28
2857.01	8060.03
2860.36	7933.27
2863.72	7987.89
2867.07	7958.61
2870.42	7855.17
2873.77	7843.97
2877.12	7909.6
2880.47	7815.12
2883.81	7882.24
2887.16	7768.69
2890.5	7747.26
2893.84	7693.22
2897.18	7747.83
2900.52	7722.87
2903.86	7642.76
2907.19	7649.65
2910.53	7638.85
2913.86	7600.03
2917.19	7529.45
2920.52	7541.01
2923.85	7475.54
2927.18	7485.06
2930.51	7445.29
2933.83	7493.45
2937.15	7424.36
2940.48	7423.26
2943.8	7374.13
2947.11	7445.8
2950.43	7374.61
2953.75	7352.13
2957.06	7388.16
2960.38	7325.85
2963.69	7357.15
2967	7233.17
2970.31	7286.83
2973.62	7232.06
2976.92	7261.98
2980.23	7199.28
2983.53	7178.88
2986.84	7214.29
2990.14	7143.11
2993.44	7152.9
2996.73	7165.91
3000.03	7246.98
3003.33	7206.72
3006.62	7166.45
3009.91	7155.9
3013.2	7156.07
3016.49	7132.83
3019.78	7154.63
3023.07	7035.78
3026.35	7191.5
3029.64	7117.06
3032.92	7135
3036.2	7183.78
3039.48	7152.97
3042.76	7090.96
3046.04	7135.06
3049.32	7143.26
3052.59	7168.52
3055.86	7101.09
3059.14	7209.71
3062.41	7171.89
3065.68	7209.15
3068.94	7239.82
3072.21	7238.57
3075.48	7284.13
3078.74	7294.37
3082	7285.19
3085.26	7302.14
3088.52	7363.36
3091.78	7408.65
3095.04	7416.43
3098.29	7402.4
3101.55	7502.46
3104.8	7548.83
3108.05	7567.36
3111.3	7582.92
3114.55	7695.05
3117.8	7693.64
3121.04	7696.25
3124.29	7808.4
3127.53	7851.86
3130.77	7918.92
3134.02	7981.35
3137.25	8066.45
3140.49	8100.61
3143.73	8096.53
3146.96	8119.19
3150.2	8315.94
3153.43	8349.83
3156.66	8361.43
3159.89	8437.18
3163.12	8625.26
3166.35	8624.46
3169.57	8685.84
3172.8	8809.58
3176.02	8837.51
3179.24	8879.95
3182.46	8988.08
3185.68	8979.05
3188.9	9257.88
3192.12	9216.98
3195.33	9361.9
3198.55	9428.46
3201.76	9466.22
3204.97	9595.74
3208.18	9611.32
3211.39	9753.9
3214.6	9781.97
3217.8	9879.2
3221.01	9923.17
3224.21	10026.5
3227.41	10038.5
3230.61	10074.5
3233.81	10094.2
3237.01	10191.2
3240.21	10208.7
3243.4	10290.5
3246.59	10275.8
3249.79	10401.2
3252.98	10326.5
3256.17	10395.1
3259.36	10475.1
3262.54	10546.9
3265.73	10619.2
3268.92	10686.2
3272.1	10657.6
3275.28	10682.7
3278.46	10777.5
3281.64	10794.5
3284.82	10868.7
3288	10895.3
3291.17	10960.2
3294.35	11081.1
3297.52	11147.2
3300.69	11151.5
3303.86	11238.4
3307.03	11373.6
3310.2	11393.5
3313.36	11492.3
3316.53	11432.7
3319.69	11677.4
3322.85	11748.8
3326.02	11746.3
3329.18	11952
3332.33	12099.1
3335.49	12189.2
3338.65	12315.1
3341.8	12367.2
3344.95	12672.3
3348.11	12636.2
3351.26	12849.2
3354.41	12976.3
3357.56	13216.1
3360.7	13307.6
3363.85	13501.6
3366.99	13714
3370.13	13857.4
3373.28	13970.4
3376.42	14190.8
3379.56	14332.7
3382.69	14502.8
3385.83	14608.2
3388.97	14836
3392.1	14990.4
3395.23	15279.7
3398.36	15452.7
3401.49	15647.7
3404.62	15899.5
3407.75	16135.2
3410.88	16377.1
3414	16653.3
3417.13	16885.9
3420.25	17292.3
3423.37	17628
3426.49	17956.5
3429.61	18291.7
3432.73	18728.4
3435.84	19273.1
3438.96	19748.2
3442.07	20241.7
3445.18	20998.8
3448.29	21828.5
3451.4	22997.1
3454.51	25114.9
3457.62	28513.9
3460.72	30902.8
3463.83	30878.9
3466.93	30853.3
3470.03	30823.2
3473.13	27695.2
3476.23	25181
3479.33	23669.7
3482.43	22698.8
3485.53	22152.4
3488.62	21859.5
3491.71	21466.5
3494.81	21492
3497.9	21278.9
3500.99	21103.2
3504.07	21121.4
3507.16	21066.5
3510.25	20880.4
3513.33	20994
3516.41	21167.9
3519.5	21436.1
3522.58	21897.9
3525.66	22342.3
3528.73	22986.6
3531.81	23775.1
3534.89	24512.6
3537.96	25303.4
3541.03	26057.6
3544.11	26346.3
3547.18	25967.9
3550.25	25014.3
3553.32	23148.4
3556.38	21020.4
3559.45	18811.3
3562.51	16978.3
3565.58	15310.4
3568.64	13881.6
3571.7	12680.8
3574.76	11889.3
3577.82	11111.5
3580.87	10569.7
3583.93	10046.9
3586.98	9617.12
3590.04	9189.27
3593.09	8836.25
3596.14	8507.83
3599.19	8239.47
3602.24	8025.29
3605.29	7906.03
3608.33	7572.46
3611.38	7407.5
3614.42	7213.03
3617.46	7074.25
3620.5	6873.66
3623.54	6747.2
3626.58	6577.72
3629.62	6424.83
3632.65	6251
3635.69	6128.81
3638.72	5933.92
3641.76	5792.61
3644.79	5573.92
3647.82	5431.93
3650.84	5215.96
3653.87	5092.93
3656.9	4953.25
3659.92	4807.63
3662.95	4642.43
3665.97	4474.21
3668.99	4384.81
3672.01	4228.49
3675.03	4073.16
3678.05	4010.4
3681.07	3872.23
3684.08	3769.59
3687.1	3656.47
3690.11	3617.14
3693.12	3577.86
3696.13	3451.39
3699.14	3412.26
3702.15	3355.79
3705.16	3277.42
3708.16	3268.24
3711.17	3169.31
3714.17	3162.28
3717.17	3116.8
3720.17	3087.67
3723.17	2997.21
3726.17	2971.2
3729.17	2936.34
3732.16	2883.16
3735.16	2825.89
3738.15	2753.08
3741.14	2761.92
3744.13	2746.63
3747.13	2724.46
3750.11	2704.89
3753.1	2651.89
3756.09	2638.79
3759.07	2612.5
3762.06	2599.43
3765.04	2564.37
3768.02	2539.85
3771	2516.49
3773.98	2465.03
3776.96	2425.15
3779.94	2427.96
3782.91	2381.81
3785.89	2405.61
3788.86	2386.1
3791.83	2383.75
3794.8	2333.63
3797.77	2317.69
3800.74	2351.92
3803.71	2311.89
3806.68	2287.06
3809.64	2272.69
3812.61	2283.96
3815.57	2293.41
3818.53	2237.65
3821.49	2233.05
3824.45	2221.87
3827.41	2193.78
3830.36	2191.28
3833.32	2162.2
3836.27	2172.22
3839.23	2184.26
3842.18	2138.33
3845.13	2117.05
3848.08	2114.83
3851.03	2108.89
3853.98	2094.47
3856.92	2107.75
3859.87	2075.23
3862.81	2061.78
3865.75	2089.34
3868.7	2091.09
3871.64	2061.03
3874.57	2071.15
3877.51	2046.64
3880.45	2034.35
3883.39	2025.68
3886.32	2010.02
3889.25	2024
3892.18	2026.37
3895.12	2007.48
3898.05	1979.67
3900.97	1953.55
3903.9	1991.81
3906.83	1966.36
3909.75	1969.99
3912.68	1910.97
3915.6	1953.62
3918.52	1953.87
3921.44	1887.24
3924.36	1895.15
3927.28	1894.19
3930.2	1859.5
3933.11	1864.06
3936.03	1832.66
3938.94	1891.68
3941.86	1856.22
3944.77	1851.23
3947.68	1844.44
3950.59	1826.34
3953.49	1813.15
3956.4	1823.99
3959.31	1805.3
3962.21	1772.31
3965.12	1799.77
3968.02	1790.92
3970.92	1765.84
3973.82	1794.54
3976.72	1790.58
3979.61	1779.76
3982.51	1733.26
3985.41	1789.57
3988.3	1745.81
3991.19	1731.78
3994.09	1753.14
3996.98	1722.87
3999.87	1728.16