File: Data/3-Raman/raw/bu19w-ff-ore2-fi05-s_150 (500nm)_532nm_edge_100%_x100_vis_lwd_h50um_15sx2_01.txt
#Acq. time (s)=	15
#Accumulations=	2
#Range (cm-¹)=	50...5000
#Windows=	1
#Auto scanning=	Off
#Autofocus=	Off
#Macrospot=	Off
#AutoExposure=	Off
#Spike filter=	Multiple accum.
#Delay time (s)=	2
#Binning=	1
#Readout mode=	Signal
#DeNoise=	Off
#ICS correction=	On
#Dark correction=	Off
#Inst. Process=	Off
#Detector Gain=	Best Dynamic
#Detector ADC=	50 kHz HS
#Detector temperature (°C)=	-60.09
#Instrument=	LabRAM HR Evol
#Detector=	SIN-EM FIVIS
#Objective=	x100_VIS_LWD
#Grating=	150 (500nm)
#ND Filter=	100%
#Laser=	532nm_Edge
#Hole=	49.98
#Temperature=	0
#Range=	Visible
#StageXY=	75x50mm Scan+
#StageZ=	Z motor
#X (µm)=	0
#Y (µm)=	0
#Z (µm)=	-26.7
#Full time(s)=	34
#Project=	21_05_28
#Sample=	BU19w
#Site=
#Title=	BU19w-FF-ore2-FI05-S_150 (500nm)_532nm_Edge_100%_x100_VIS_LWD_H50um_15sX2
#Remark=
#Date=	28.05.2021 15:01
#Acquired=	28.05.2021 15:01:19
51.5961	632.6
56.2453	812.564
60.8921	934.994
65.5367	979.229
70.1768	941.321
74.8167	950.167
79.4543	942.448
84.0897	924.333
88.7227	962.596
93.3513	935.209
97.9798	1002.47
102.606	1022.02
107.23	1094.58
111.851	1152.9
116.469	1370.53
121.086	2108.74
125.7	5319.64
130.313	9384.6
134.921	6035.31
139.529	2871.86
144.134	2382.79
148.738	2287.91
153.337	2151.68
157.936	1961.03
162.532	1980.51
167.126	2111.6
171.716	2349.27
176.306	2747.46
180.894	3346.48
185.477	4266.14
190.06	5714.35
194.64	8256.31
199.219	11863.9
203.793	15747.5
208.367	17840.3
212.939	16408.1
217.506	12896
222.073	9373.22
226.638	6747.69
231.199	5129.22
235.759	4044.37
240.318	3289.86
244.872	2857.88
249.425	2620.18
253.977	2447.23
258.524	2494.81
263.071	3570.69
267.616	4225.69
272.156	2704.01
276.697	1745.23
281.233	1431.62
285.769	1317.61
290.303	1215.46
294.832	1145.34
299.361	1142.05
303.886	1093.74
308.411	1099.74
312.934	1099.88
317.452	1056.2
321.97	1083.01
326.484	1040.49
330.998	1092.08
335.507	1039.47
340.017	1045.26
344.524	1114.98
349.027	1271.39
353.53	2592.85
358.028	4222.18
362.527	2816.27
367.021	1590.28
371.515	1313.28
376.004	1294.91
380.494	1214.02
384.979	1166.96
389.465	1242.29
393.946	1433.76
398.427	1557.51
402.903	1858.16
407.38	1956.34
411.852	1464.09
416.324	1367.94
420.792	1364.3
425.26	1441.08
429.723	1517
434.187	1643.52
438.646	1826.48
443.105	2299.76
447.56	3279.45
452.015	5261.53
456.466	9596.49
460.914	24807.8
465.362	38247.2
469.807	38182.3
474.251	24570.7
478.69	11339.3
483.13	6923.76
487.566	5014.36
491.999	3947.2
496.432	3301.45
500.861	2804.16
505.29	2486.32
509.715	2660.22
514.138	2717.23
518.56	2503.76
522.979	2112.08
527.395	1895.37
531.811	1784.14
536.223	1714.82
540.635	1645.45
545.042	1650.08
549.448	1573.59
553.853	1549.01
558.255	1504.93
562.654	1473.54
567.053	1424.08
571.448	1404.4
575.841	1423.1
580.232	1366.15
584.622	1379.8
589.009	1409.25
593.393	1439.72
597.777	1406.01
602.157	1456
606.535	1346.67
610.913	1372.11
615.287	1353.89
619.659	1359.03
624.029	1358.69
628.398	1352.89
632.763	1368.29
637.127	1391.19
641.488	1325.55
645.849	1329.18
650.206	1344.89
654.561	1321.03
658.914	1325.23
663.267	1321.18
667.615	1335.96
671.962	1250.92
676.307	1369.95
680.649	1327.53
684.991	1410.52
689.33	1399.07
693.666	1510.47
698	1679.61
702.332	1640.78
706.662	1423.66
710.992	1352.58
715.318	1340.27
719.641	1334.58
723.963	1377.85
728.283	1394.48
732.6	1392.77
736.918	1350.46
741.231	1367.72
745.542	1367.56
749.852	1378.72
754.159	1401.52
758.464	1327.31
762.767	1400.53
767.068	1437.81
771.369	1429.24
775.666	1427.55
779.961	1453.84
784.254	1500.44
788.545	1540.36
792.834	1735.08
797.12	1953.53
801.405	2072.17
805.688	2538.61
809.968	3108.02
814.247	2742.11
818.524	2067.43
822.798	1762.07
827.071	1634.21
831.341	1575.75
835.612	1560.23
839.878	1587.57
844.142	1579.46
848.405	1543.16
852.665	1554.49
856.923	1534.94
861.18	1560.55
865.434	1535.18
869.686	1554.44
873.936	1494.24
878.185	1527.03
882.431	1510.09
886.675	1585.43
890.915	1574.48
895.155	1561.89
899.393	1545.62
903.63	1520.8
907.864	1579.52
912.096	1590.72
916.326	1523.91
920.554	1554.13
924.78	1585.79
929.004	1570.22
933.227	1556.6
937.447	1522.47
941.665	1486.93
945.881	1522.94
950.095	1456.31
954.305	1498.98
958.516	1487.42
962.724	1525
966.93	1485.12
971.134	1466.74
975.337	1516.55
979.537	1490.19
983.735	1476.86
987.93	1491.04
992.124	1461.95
996.316	1452.99
1000.51	1502.17
1004.7	1502.97
1008.88	1493.36
1013.06	1508.24
1017.25	1490.81
1021.43	1538.36
1025.61	1540.83
1029.78	1503.22
1033.96	1547.32
1038.13	1517.22
1042.3	1558.73
1046.47	1532.99
1050.63	1558.86
1054.8	1558.82
1058.96	1617.54
1063.12	1692.33
1067.28	1765.15
1071.44	1839.4
1075.59	1869.11
1079.74	2257.92
1083.89	2763.84
1088.04	2506.15
1092.19	1938.24
1096.33	1698.33
1100.48	1673.7
1104.62	1624.78
1108.76	1581.87
1112.89	1618.38
1117.03	1616.46
1121.16	1567.91
1125.29	1597.4
1129.42	1591.81
1133.55	1593.83
1137.68	1603.6
1141.8	1614.33
1145.92	1651.13
1150.04	1679.3
1154.16	1796.27
1158.27	1988
1162.39	2127.77
1166.5	1995.44
1170.61	1774.96
1174.72	1663.38
1178.82	1587.73
1182.93	1583.15
1187.03	1607.89
1191.13	1640.85
1195.23	1612.78
1199.33	1622.09
1203.42	1583.05
1207.51	1634.47
1211.6	1635.02
1215.69	1607.38
1219.78	1663.64
1223.86	1750.01
1227.95	1749.13
1232.03	1762.92
1236.11	1816.03
1240.18	1751.19
1244.26	1658.08
1248.33	1697.49
1252.41	1678.9
1256.48	1665.66
1260.54	1676.68
1264.61	1670.97
1268.67	1649.56
1272.74	1686.5
1276.8	1655.28
1280.86	1692.24
1284.91	1675.69
1288.97	1643.72
1293.02	1687.03
1297.07	1643.49
1301.12	1648.12
1305.17	1641.36
1309.21	1654.64
1313.25	1633.45
1317.3	1687.25
1321.34	1640.94
1325.37	1667.52
1329.41	1651.63
1333.44	1645.62
1337.48	1690.19
1341.5	1673.3
1345.53	1691.22
1349.56	1653.23
1353.59	1638.29
1357.61	1690.03
1361.63	1650.22
1365.65	1672.22
1369.66	1667.73
1373.68	1664.63
1377.69	1691.38
1381.7	1708.53
1385.72	1709.68
1389.72	1680.66
1393.73	1708.22
1397.73	1719.77
1401.74	1712.47
1405.74	1721.87
1409.73	1686.1
1413.73	1662.29
1417.73	1692.76
1421.72	1733.1
1425.71	1779.17
1429.7	1789.79
1433.69	1695.9
1437.67	1728.35
1441.66	1760.84
1445.64	1732.83
1449.62	1762.95
1453.6	1739.47
1457.57	1775.99
1461.55	1766.82
1465.52	1725.6
1469.49	1730.57
1473.46	1774.08
1477.43	1740.73
1481.39	1746.43
1485.36	1730.47
1489.32	1763.28
1493.28	1743.44
1497.24	1771.44
1501.19	1783.02
1505.15	1774.46
1509.1	1746
1513.05	1789.58
1517	1760.4
1520.95	1796.46
1524.9	1786.05
1528.84	1769
1532.78	1799.69
1536.72	1810.05
1540.66	1825.32
1544.6	1823.15
1548.53	1780.29
1552.46	1791.69
1556.4	1827.09
1560.32	1839.91
1564.25	1810.91
1568.18	1814.64
1572.1	1857.84
1576.02	1821.77
1579.94	1812.7
1583.86	1854.69
1587.78	1817.47
1591.69	1825.51
1595.61	1813.31
1599.52	1835.73
1603.43	1901.46
1607.34	1868.57
1611.24	1913.44
1615.15	1851.06
1619.05	1928.86
1622.95	1871.46
1626.85	1875.67
1630.74	1883
1634.64	1876.58
1638.53	1917.93
1642.42	1885.11
1646.31	1882.36
1650.2	1852.94
1654.09	1904.17
1657.97	1879.46
1661.86	1874.82
1665.74	1879.41
1669.62	1876.11
1673.49	1908.75
1677.37	1870.14
1681.24	1862.25
1685.12	1877.89
1688.99	1920.19
1692.86	1885.37
1696.72	1862.8
1700.59	1874.36
1704.45	1882.63
1708.31	1910.45
1712.17	1913.06
1716.03	1894.83
1719.89	1853.11
1723.74	1906.94
1727.6	1885.02
1731.45	1903.3
1735.3	1916.97
1739.14	1898.55
1742.99	1917.3
1746.83	1879.28
1750.68	1923.42
1754.52	1913.37
1758.36	1879.39
1762.19	1904.25
1766.03	1899.88
1769.86	1894.39
1773.69	1909.34
1777.53	1914.15
1781.35	1915.88
1785.18	1931.01
1789	1944.54
1792.83	1954.45
1796.65	1920.34
1800.47	1895.42
1804.29	1940.72
1808.1	1981.24
1811.92	1923.56
1815.73	1962.61
1819.54	1922.52
1823.35	1945.13
1827.16	1965.49
1830.97	1953.23
1834.77	1953.66
1838.58	1942.48
1842.38	1963.92
1846.18	1933.19
1849.97	1964.69
1853.77	1952.1
1857.56	1943.72
1861.36	1946.88
1865.15	1943.29
1868.93	1931.56
1872.72	2009.03
1876.51	1971.02
1880.29	1988.67
1884.07	1990.53
1887.86	1966.68
1891.63	1971.83
1895.41	1985.32
1899.19	1986.84
1902.96	1968.98
1906.73	2015.03
1910.5	1983.02
1914.27	1995.96
1918.04	1944.45
1921.8	2000.39
1925.57	2021.51
1929.33	2005.95
1933.09	2019.33
1936.85	2022.46
1940.6	1993.79
1944.36	2037.91
1948.11	1985.65
1951.87	2028.31
1955.61	2065.52
1959.36	1994.6
1963.11	2072.35
1966.86	2036.33
1970.6	2047.55
1974.34	2039.24
1978.08	2071.74
1981.82	1999.96
1985.56	2081.25
1989.29	2066.9
1993.02	2039.21
1996.75	2053.97
2000.49	2049.73
2004.21	2058.56
2007.94	2037.56
2011.67	2041.96
2015.39	2060.2
2019.11	2021.55
2022.83	2118.84
2026.55	2035.87
2030.27	2018.08
2033.98	2070.86
2037.69	2038.29
2041.41	2067.8
2045.12	2030.3
2048.82	2056.93
2052.53	2094.06
2056.24	2100.18
2059.94	2091.82
2063.64	2032.41
2067.34	2078.16
2071.04	2029.33
2074.74	2078.2
2078.43	2095.95
2082.13	2075.93
2085.82	2039.79
2089.51	2060.55
2093.2	2018.16
2096.88	2092.91
2100.57	2056.68
2104.25	2054.15
2107.94	2073.57
2111.62	2118.7
2115.3	2099.6
2118.97	2110.9
2122.65	2111.13
2126.32	2120.18
2129.99	2103.85
2133.66	2079.04
2137.33	2117.91
2141	2122.17
2144.67	2101.21
2148.33	2086.61
2151.99	2082.12
2155.66	2092.39
2159.31	2054.21
2162.97	2126.05
2166.63	2105.86
2170.28	2112.53
2173.94	2135.55
2177.59	2087.09
2181.24	2134.52
2184.89	2078.11
2188.53	2152.35
2192.18	2111
2195.82	2117.82
2199.46	2133.32
2203.1	2112.61
2206.74	2109.55
2210.38	2107.75
2214.01	2136.45
2217.65	2115.83
2221.28	2089.7
2224.91	2147.29
2228.54	2060.28
2232.16	2114.22
2235.79	2103.83
2239.41	2154.42
2243.04	2185.65
2246.66	2145.39
2250.28	2135.8
2253.89	2165.54
2257.51	2177.84
2261.12	2097.58
2264.74	2172.24
2268.35	2167.64
2271.96	2171.97
2275.57	2166.3
2279.17	2172.26
2282.78	2157.91
2286.38	2206.78
2289.98	2077.05
2293.58	2160.6
2297.18	2162.93
2300.78	2153.98
2304.37	2134.22
2307.97	2156.64
2311.56	2138
2315.15	2140.84
2318.74	2179.31
2322.33	2189.8
2325.91	2178.1
2329.5	2149.2
2333.08	2164.46
2336.66	2170.91
2340.24	2177.98
2343.82	2139.69
2347.4	2181
2350.97	2182.67
2354.54	2155.23
2358.12	2149.23
2361.69	2144.96
2365.26	2134.17
2368.82	2189.41
2372.39	2148.69
2375.95	2137.52
2379.52	2199.34
2383.08	2119.35
2386.64	2155.72
2390.19	2172.15
2393.75	2190.81
2397.31	2190.84
2400.86	2198.03
2404.41	2162.43
2407.96	2207.76
2411.51	2207.29
2415.06	2232.14
2418.6	2147.29
2422.15	2174.83
2425.69	2181.78
2429.23	2178.22
2432.77	2154.73
2436.31	2228.03
2439.84	2184.8
2443.38	2162.04
2446.91	2171.88
2450.44	2170.99
2453.97	2164.83
2457.5	2216.47
2461.03	2172.17
2464.55	2137.93
2468.08	2167.83
2471.6	2187.29
2475.12	2193.65
2478.64	2218.55
2482.16	2170.25
2485.67	2188.06
2489.19	2161.22
2492.7	2143.14
2496.21	2216.75
2499.72	2196.32
2503.23	2208.89
2506.74	2175.28
2510.25	2188.85
2513.75	2182.98
2517.25	2176.73
2520.75	2208.91
2524.25	2186.68
2527.75	2176.89
2531.25	2182.44
2534.74	2208.62
2538.24	2189.29
2541.73	2205.54
2545.22	2194.25
2548.71	2182.04
2552.2	2207.82
2555.68	2237.02
2559.17	2203.45
2562.65	2193.01
2566.13	2172.34
2569.61	2155.98
2573.09	2212.08
2576.57	2182.67
2580.04	2172.3
2583.51	2210.09
2586.99	2162.01
2590.46	2186.13
2593.93	2174.99
2597.4	2177.72
2600.86	2191.62
2604.33	2204.41
2607.79	2227.47
2611.25	2216.07
2614.71	2182.97
2618.17	2189.08
2621.63	2188.51
2625.09	2214.41
2628.54	2148.44
2631.99	2182.98
2635.45	2178.55
2638.9	2200.32
2642.34	2214.94
2645.79	2192.75
2649.24	2223.93
2652.68	2186.83
2656.12	2206.35
2659.56	2186.43
2663.01	2187.17
2666.44	2141.41
2669.88	2218.34
2673.32	2157.49
2676.75	2181.72
2680.18	2198.68
2683.61	2201.1
2687.04	2208.03
2690.47	2162.31
2693.9	2214.31
2697.32	2136.37
2700.75	2228.39
2704.17	2205.98
2707.59	2220.87
2711.01	2208.49
2714.43	2185.39
2717.84	2197.16
2721.26	2212.17
2724.67	2200.44
2728.08	2208.47
2731.49	2178.32
2734.9	2173.24
2738.31	2187.84
2741.71	2171.39
2745.12	2184.54
2748.52	2137.25
2751.92	2121.89
2755.32	2178.78
2758.72	2229.84
2762.12	2176.44
2765.52	2143.14
2768.91	2168.86
2772.3	2211.18
2775.7	2202.41
2779.09	2181.03
2782.47	2149.94
2785.86	2177.05
2789.25	2198.42
2792.63	2176.45
2796.01	2183.55
2799.4	2174.67
2802.78	2156.08
2806.15	2142.23
2809.53	2160.18
2812.91	2166.76
2816.28	2119.9
2819.65	2110.45
2823.03	2198.41
2826.4	2141.04
2829.76	2174.33
2833.13	2195.77
2836.5	2117.92
2839.86	2121.5
2843.22	2128.3
2846.59	2211.09
2849.95	2121.31
2853.3	2145.76
2856.66	2150.38
2860.02	2145
2863.37	2159.54
2866.72	2162.95
2870.08	2157.94
2873.43	2137.73
2876.77	2098.61
2880.12	2134.65
2883.47	2107.56
2886.81	2086.84
2890.15	2144.39
2893.5	2158.45
2896.84	2147.42
2900.17	2157.83
2903.51	2158.44
2906.85	2125.67
2910.18	2132.44
2913.52	2112.57
2916.85	2148.36
2920.18	2114.77
2923.51	2152.96
2926.83	2112.45
2930.16	2128.37
2933.48	2074.14
2936.81	2147.06
2940.13	2112.38
2943.45	2152.18
2946.77	2162.8
2950.09	2147.14
2953.4	2117.32
2956.72	2073.53
2960.03	2124.01
2963.34	2070.47
2966.65	2127.79
2969.96	2112.57
2973.27	2112.73
2976.58	2111.1
2979.88	2127.65
2983.19	2112.04
2986.49	2125.66
2989.79	2100.92
2993.09	2167.33
2996.39	2108.01
2999.68	2117.37
3002.98	2090.97
3006.27	2122.89
3009.57	2087.24
3012.86	2076.14
3016.15	2060.37
3019.43	2125.6
3022.72	2039.94
3026.01	2094.83
3029.29	2068.59
3032.57	2118.82
3035.86	2104.71
3039.14	2073.5
3042.41	2030.92
3045.69	2084.91
3048.97	2050.88
3052.24	2077.45
3055.52	2027.33
3058.79	2024.49
3062.06	2062.73
3065.33	2011.16
3068.6	2061.81
3071.86	2047.49
3075.13	2084.5
3078.39	2051.53
3081.65	2070.99
3084.91	2061.87
3088.17	2026.05
3091.43	1988.85
3094.69	1987.83
3097.95	2061.27
3101.2	2044.74
3104.45	2059.21
3107.7	2038.48
3110.95	2061.23
3114.2	2030.02
3117.45	2010.41
3120.7	2000.37
3123.94	1995.08
3127.18	2006.91
3130.43	1995.81
3133.67	1999.98
3136.91	2014.59
3140.14	2017.64
3143.38	2018.77
3146.61	2011.32
3149.85	1989.7
3153.08	2022.48
3156.31	1972.19
3159.54	1969.65
3162.77	2016.65
3166	1993.05
3169.22	1982.62
3172.45	1946.29
3175.67	1975.71
3178.89	2033.59
3182.11	2031.32
3185.33	1984.27
3188.55	1980.87
3191.77	1970.74
3194.98	1999.69
3198.2	1970.47
3201.41	1987.9
3204.62	1970.18
3207.83	1999.17
3211.04	2011.11
3214.25	1945.17
3217.45	1981.17
3220.66	1921.09
3223.86	1999.01
3227.06	2021.01
3230.26	1962.2
3233.46	1920.64
3236.66	1938.9
3239.85	1915.7
3243.05	1944.98
3246.24	1966.75
3249.44	1910.4
3252.63	1963.84
3255.82	1918.17
3259.01	1958.32
3262.19	1952.39
3265.38	1909.88
3268.56	1928.23
3271.75	1917.72
3274.93	1978.74
3278.11	1932.75
3281.29	1967.53
3284.47	1934.17
3287.64	1954.3
3290.82	1925.62
3293.99	1937.16
3297.17	1929.55
3300.34	1922.94
3303.51	1931.05
3306.68	1924.38
3309.84	1868.08
3313.01	1875.24
3316.18	1924.04
3319.34	1932.88
3322.5	1906.55
3325.66	1916.28
3328.82	1876.8
3331.98	1949.94
3335.14	1912.57
3338.29	1891.47
3341.45	1919.59
3344.6	1872.3
3347.75	1872.64
3350.9	1892.3
3354.05	1875.17
3357.2	1859.19
3360.35	1832.95
3363.49	1915.34
3366.64	1888.42
3369.78	1883.28
3372.92	1918.8
3376.06	1890.37
3379.2	1869.56
3382.34	1858.27
3385.48	1884.7
3388.61	1878.21
3391.75	1813.99
3394.88	1878.42
3398.01	1826.85
3401.14	1864.41
3404.27	1827.24
3407.4	1851.91
3410.52	1838.7
3413.65	1835.87
3416.77	1866.9
3419.89	1835.88
3423.01	1830.4
3426.13	1865.57
3429.25	1818.33
3432.37	1882.54
3435.49	1816.5
3438.6	1830.26
3441.72	1817.51
3444.83	1833.35
3447.94	1841.17
3451.05	1791.74
3454.16	1867.86
3457.26	1802.92
3460.37	1785.38
3463.47	1807.77
3466.58	1817.67
3469.68	1789.32
3472.78	1828.02
3475.88	1772.5
3478.98	1788.13
3482.07	1757.49
3485.17	1791.19
3488.26	1802.31
3491.36	1779.71
3494.45	1788.76
3497.54	1784.53
3500.63	1764.14
3503.72	1755.13
3506.81	1793.9
3509.89	1745.96
3512.98	1834.02
3516.06	1762.39
3519.14	1804.18
3522.22	1749.85
3525.3	1767.37
3528.38	1728.35
3531.45	1785.72
3534.53	1750.19
3537.61	1725.16
3540.68	1724.84
3543.75	1732.82
3546.82	1736.73
3549.89	1741.88
3552.96	1750.39
3556.03	1737
3559.09	1733.34
3562.16	1724.96
3565.22	1694.42
3568.28	1729.93
3571.34	1718.62
3574.4	1696.04
3577.46	1722.85
3580.52	1716.32
3583.57	1670.77
3586.63	1691.45
3589.68	1718.75
3592.73	1631.11
3595.78	1688.49
3598.83	1690.72
3601.88	1673.06
3604.93	1651.45
3607.97	1681.77
3611.02	1683.67
3614.06	1700.6
3617.1	1687.23
3620.14	1672.99
3623.18	1646.59
3626.22	1680.61
3629.26	1688.32
3632.3	1662.01
3635.33	1657.29
3638.36	1699.1
3641.4	1661.15
3644.43	1643.15
3647.46	1618.99
3650.49	1647.07
3653.51	1638.68
3656.54	1702.46
3659.57	1636.41
3662.59	1652.93
3665.61	1584.37
3668.63	1611.14
3671.65	1620.39
3674.67	1629.73
3677.69	1577.82
3680.71	1619.45
3683.72	1646.86
3686.74	1595.83
3689.75	1613.87
3692.76	1632.93
3695.77	1629.28
3698.78	1619.62
3701.79	1607.46
3704.79	1607.62
3707.8	1560.26
3710.81	1613.41
3713.81	1601.82
3716.81	1583.37
3719.81	1599.27
3722.81	1557.86
3725.81	1599.14
3728.81	1585.06
3731.8	1601.33
3734.8	1574.6
3737.79	1602.91
3740.78	1566.34
3743.77	1571.47
3746.76	1594.54
3749.75	1603.16
3752.74	1566.06
3755.73	1558.41
3758.71	1598.24
3761.7	1531.79
3764.68	1529.72
3767.66	1545.69
3770.64	1571.21
3773.62	1560.92
3776.6	1541.3
3779.58	1552.03
3782.55	1509
3785.53	1550.07
3788.5	1563.83
3791.47	1520.1
3794.44	1556.86
3797.41	1580.52
3800.38	1530.66
3803.35	1507.42
3806.32	1534.31
3809.28	1566.93
3812.24	1530.67
3815.21	1547.38
3818.17	1511.16
3821.13	1478.76
3824.09	1517.38
3827.04	1575.1
3830	1526.73
3832.96	1535.21
3835.91	1487.85
3838.86	1498.44
3841.82	1529.96
3844.77	1493.02
3847.72	1482.71
3850.67	1530.57
3853.61	1478.47
3856.56	1485.49
3859.5	1519.28
3862.45	1491.96
3865.39	1497.99
3868.33	1473.38
3871.27	1495.57
3874.21	1487.06
3877.15	1489.99
3880.09	1464.9
3883.02	1494.4
3885.96	1495.86
3888.89	1485.68
3891.82	1497.54
3894.75	1513.18
3897.68	1452.65
3900.61	1484.28
3903.54	1461.05
3906.47	1490.51
3909.39	1424.99
3912.31	1441.04
3915.24	1434.84
3918.16	1471.76
3921.08	1483.01
3924	1448.84
3926.92	1418.37
3929.83	1447.24
3932.75	1456.85
3935.67	1422.75
3938.58	1459.81
3941.49	1442.56
3944.4	1415.59
3947.31	1467.22
3950.22	1451.01
3953.13	1434.91
3956.04	1435.15
3958.94	1426.9
3961.85	1453.2
3964.75	1459.47
3967.65	1417.87
3970.55	1398.37
3973.45	1400.98
3976.35	1440.05
3979.25	1408.92
3982.15	1422.84
3985.04	1398.29
3987.94	1422.7
3990.83	1393.21
3993.72	1443.39
3996.61	1441.9
3999.5	1402.84
4002.39	1409.08
4005.28	1380.67
4008.16	1387.97
4011.05	1354.8
4013.93	1407.41
4016.81	1403.15
4019.7	1393.1
4022.58	1359.87
4025.46	1386.49
4028.33	1371.62
4031.21	1384.78
4034.09	1358.34
4036.96	1410.25
4039.84	1345.15
4042.71	1357.42
4045.58	1402.41
4048.45	1339.93
4051.32	1376.36
4054.19	1365.37
4057.05	1360.33
4059.92	1366.88
4062.78	1376.3
4065.65	1374.07
4068.51	1335.85
4071.37	1334.54
4074.23	1356.59
4077.09	1362.07
4079.95	1355.84
4082.81	1347.66
4085.66	1360.94
4088.52	1332.2
4091.37	1349.32
4094.22	1337.25
4097.07	1311.38
4099.92	1316.85
4102.77	1313.48
4105.62	1340.39
4108.47	1342.69
4111.31	1329.36
4114.16	1329.56
4117	1344.31
4119.84	1324.61
4122.69	1320.6
4125.53	1315.76
4128.36	1298.23
4131.2	1286.93
4134.04	1285.6
4136.88	1321.92
4139.71	1290.93
4142.54	1289.19
4145.38	1316.48
4148.21	1290.49
4151.04	1275.35
4153.87	1283.4
4156.69	1303.72
4159.52	1298.03
4162.35	1297.71
4165.17	1266.25
4168	1287.6
4170.82	1301.18
4173.64	1295.28
4176.46	1278.65
4179.28	1312.88
4182.1	1269.96
4184.91	1298.47
4187.73	1278.15
4190.54	1274.5
4193.36	1208.39
4196.17	1251.07
4198.98	1250.85
4201.79	1274.12
4204.6	1260.19
4207.41	1248.16
4210.22	1265.61
4213.02	1288.92
4215.83	1246.37
4218.63	1276.36
4221.44	1254.1
4224.24	1244.5
4227.04	1238.67
4229.84	1230.07
4232.64	1235.36
4235.43	1231.89
4238.23	1236.43
4241.02	1221.15
4243.82	1216.8
4246.61	1204.54
4249.4	1252.01
4252.19	1242.56
4254.98	1225.06
4257.77	1223.42
4260.56	1224.75
4263.35	1230.17
4266.13	1186.43
4268.92	1242.21
4271.7	1199.46
4274.48	1228.12
4277.26	1203.12
4280.04	1194.06
4282.82	1183.88
4285.6	1172.56
4288.38	1201.53
4291.15	1193.97
4293.93	1224.82
4296.7	1187.99
4299.47	1203.94
4302.25	1171.1
4305.02	1189.97
4307.79	1169.25
4310.55	1171.93
4313.32	1177.79
4316.09	1125.47
4318.85	1161.53
4321.62	1168.02
4324.38	1199.86
4327.14	1177.68
4329.9	1163.69
4332.66	1156.69
4335.42	1137.53
4338.18	1168.18
4340.94	1156.26
4343.69	1145.36
4346.45	1137.64
4349.2	1165.72
4351.95	1184.65
4354.7	1092.58
4357.45	1134.16
4360.2	1147.15
4362.95	1137.58
4365.7	1116.84
4368.44	1155.41
4371.19	1111.09
4373.93	1129.09
4376.68	1139.9
4379.42	1141.37
4382.16	1110.98
4384.9	1096.05
4387.64	1103.97
4390.37	1145.3
4393.11	1100.32
4395.85	1096.35
4398.58	1111.18
4401.31	1118.75
4404.05	1080.6
4406.78	1101.59
4409.51	1087.34
4412.24	1078.13
4414.96	1091.65
4417.69	1084.3
4420.42	1086.9
4423.14	1079.29
4425.87	1090.53
4428.59	1068.36
4431.31	1095.3
4434.03	1068.89
4436.75	1085.32
4439.47	1061.9
4442.19	1082.37
4444.91	1089.26
4447.62	1057.26
4450.34	1038.88
4453.05	1057.14
4455.76	1074.36
4458.47	1055.74
4461.19	1037.08
4463.89	1051.14
4466.6	1036.77
4469.31	1064.56
4472.02	1057.68
4474.72	1052.99
4477.43	1035.74
4480.13	1021.71
4482.83	1053.13
4485.53	1026.47
4488.23	1027.18
4490.93	1037.37
4493.63	1053.67
4496.33	1046.51
4499.02	1048.01
4501.72	1017.67
4504.41	1037.04
4507.11	1013.06
4509.8	1017.73
4512.49	1008.61
4515.18	1026.05
4517.87	1030.79
4520.56	1030.26
4523.24	990.502
4525.93	1010.27
4528.61	1044.95
4531.3	1020.05
4533.98	983.42
4536.66	1013.98
4539.34	988.033
4542.02	1002.71
4544.7	986.395
4547.38	996.84
4550.05	988.034
4552.73	958.943
4555.4	973.961
4558.08	960.15
4560.75	953.043
4563.42	982.74
4566.09	993.419
4568.76	982.753
4571.43	954.073
4574.1	944.884
4576.77	987.403
4579.43	921.803
4582.1	915.211
4584.76	962.129
4587.42	953.008
4590.08	943.816
4592.74	939.968
4595.4	946.009
4598.06	958.724
4600.72	917.792
4603.38	933.874
4606.03	948.952
4608.69	918.028
4611.34	918.881
4613.99	921.897
4616.64	920.511
4619.29	942.275
4621.94	936.602
4624.59	924.266
4627.24	897.492
4629.89	957.861
4632.53	898.947
4635.18	917.218
4637.82	932.129
4640.46	916.046
4643.1	904.392
4645.74	889.611
4648.38	931.631
4651.02	895.088
4653.66	874.354
4656.3	903.321
4658.93	905.718
4661.57	917.712
4664.2	917.6
4666.83	890.525
4669.46	895.641
4672.09	885.167
4674.72	881.381
4677.35	888.794
4679.98	886.098
4682.61	874.389
4685.23	894.136
4687.86	876.793
4690.48	853.811
4693.1	887.132
4695.73	882.095
4698.34	884.934
4700.96	881.026
4703.58	888.376
4706.2	861.75
4708.82	889.346
4711.43	864.894
4714.05	882.285
4716.66	850.964
4719.28	859.224
4721.89	843.661
4724.5	838.251
4727.11	865.839
4729.72	846.988
4732.33	838.342
4734.93	822.876
4737.54	842.586
4740.14	874.767
4742.75	812.552
4745.35	821.896
4747.95	864.181
4750.55	846.045
4753.15	864.35
4755.75	820.043
4758.35	839.465
4760.95	857.836
4763.54	826.171
4766.14	827.574
4768.73	799.536
4771.33	794.339
4773.92	833.467
4776.51	803.016
4779.1	762.266
4781.69	819.721
4784.28	821.229
4786.87	802.165
4789.45	789.951
4792.04	829.264
4794.63	825.134
4797.21	834.781
4799.79	795.22
4802.37	818.77
4804.95	804.526
4807.53	782.312
4810.11	800.391
4812.69	811.587
4815.27	774.416
4817.84	805.339
4820.42	791.312
4822.99	799.238
4825.57	784.022
4828.14	768.75
4830.71	790.632
4833.28	756.808
4835.85	790.494
4838.42	782.372
4840.98	775.463
4843.55	755.621
4846.12	768.408
4848.68	770.581
4851.24	765.468
4853.81	773.941
4856.37	747.283
4858.93	775.474
4861.49	791.901
4864.05	723.139
4866.61	768.605
4869.16	785.815
4871.72	716.812
4874.27	769.542
4876.83	742.826
4879.38	762.343
4881.93	759.279
4884.49	738.345
4887.04	743.531
4889.58	751.12
4892.13	751.58
4894.68	738.911
4897.23	741.694
4899.77	744.455
4902.32	719.772
4904.86	748.752
4907.4	738.328
4909.95	752.951
4912.49	716.05
4915.03	732.84
4917.57	720.89
4920.1	680.348
4922.64	718.65
4925.18	722.317
4927.71	716.475
4930.25	735.636
4932.78	698.814
4935.31	723.1
4937.84	713.817
4940.38	714.093
4942.9	699.682
4945.43	696.309
4947.96	713.414
4950.49	698.146
4953.01	712.904
4955.54	717.986
4958.06	699.202
4960.59	686.457
4963.11	714.63
4965.63	690.109
4968.15	681.326
4970.67	713.323
4973.19	699.479
4975.71	677.134
4978.22	672.872
4980.74	673.477
4983.25	691.048
4985.77	667.454
4988.28	666.889
4990.79	693.063
4993.3	692.506
4995.81	661.502
4998.32	690.253