File: Data/3-Raman/raw/bu19w-e-ff11-fi02-l_150 (500nm)_633nm_edge_100%_x100_vis_h50um_60sx2_01.txt
#Acq. time (s)=	60
#Accumulations=	2
#Range (cm-¹)=	100...4000
#Windows=	1
#Auto scanning=	Off
#Autofocus=	Off
#Macrospot=	Off
#AutoExposure=	Off
#Spike filter=	Multiple accum.
#Delay time (s)=	2
#Binning=	1
#Readout mode=	Signal
#DeNoise=	Off
#ICS correction=	On
#Dark correction=	Off
#Inst. Process=	Off
#Detector Gain=	Best Dynamic
#Detector ADC=	50 kHz HS
#Detector temperature (°C)=	-60.09
#Instrument=	LabRAM HR Evol
#Detector=	SIN-EM FIVIS
#Objective=	x100_VIS
#Grating=	150 (500nm)
#ND Filter=	100%
#Laser=	633nm_Edge
#Hole=	49.98
#Temperature=	0
#Range=	Visible
#StageXY=	75x50mm Scan+
#StageZ=	Z motor
#X (µm)=	0
#Y (µm)=	0
#Z (µm)=	-281.7
#Full time(mm:ss)=	2:04
#Project=	21_11_04
#Sample=	BU19w
#Site=
#Title=	BU19w-E-FF11-FI02-L_150 (500nm)_633nm_Edge_100%_x100_VIS_H50um_60sX2
#Remark=
#Date=	04.11.2021 16:29
#Acquired=	04.11.2021 16:29:18
102.881	238.827
109.397	224.741
115.908	223.05
122.414	227.989
128.914	232.918
135.409	254.053
141.898	269.37
148.383	267.513
154.861	347.103
161.335	346.34
167.801	239.162
174.264	191.255
180.721	168.17
187.173	163.19
193.62	170.572
200.061	161.777
206.496	171.295
212.926	175.038
219.352	231.228
225.772	365.418
232.185	434.364
238.595	283.742
244.999	223.729
251.397	232.169
257.791	247.208
264.178	249.954
270.561	227.141
276.939	234.722
283.31	235.61
289.678	200.419
296.039	208.767
302.396	225.616
308.746	288.715
315.093	515.085
321.433	669.525
327.768	455.177
334.099	283.437
340.423	243.766
346.743	264.413
353.058	284.991
359.367	266.854
365.671	233.669
371.971	180.83
378.265	165.622
384.553	142.051
390.837	151.508
397.116	150.786
403.389	150.191
409.657	156.168
415.92	174.357
422.178	191.597
428.431	227.336
434.678	215.496
440.921	228.143
447.158	258.493
453.391	271.773
459.618	228.205
465.84	186.9
472.057	167.201
478.27	159.772
484.477	164.449
490.679	172.857
496.876	180.354
503.068	208.399
509.255	240.227
515.436	246.02
521.613	243.56
527.785	243.098
533.952	230.581
540.113	198.212
546.27	172.148
552.423	176.055
558.568	157.219
564.711	152.292
570.848	143.477
576.979	151.468
583.107	164.104
589.228	175.851
595.345	179.365
601.458	198.046
607.565	207.677
613.667	211.843
619.764	194.634
625.856	149.175
631.944	156.065
638.026	133.453
644.104	149.267
650.177	160.316
656.244	144.909
662.308	121.132
668.365	117.099
674.418	107.706
680.467	99.3148
686.511	97.5336
692.549	104.273
698.582	97.9472
704.611	95.3286
710.635	100.161
716.655	96.331
722.669	91.5801
728.679	96.1427
734.683	95.9705
740.683	97.6689
746.678	103.123
752.669	97.4367
758.654	99.295
764.635	92.9501
770.611	101.645
776.582	95.3537
782.549	94.5999
788.511	96.6042
794.466	93.8428
800.419	97.6006
806.366	94.6824
812.309	101.136
818.247	104.68
824.18	100.682
830.108	104.196
836.033	104.172
841.952	109.94
847.865	119.51
853.776	112.269
859.681	129.521
865.58	144.047
871.476	149.143
877.366	150.289
883.253	160.836
889.134	155.141
895.012	152.205
900.883	147.204
906.751	148.734
912.614	145.514
918.473	153.673
924.326	169.536
930.174	180.003
936.019	211.391
941.859	241.421
947.693	292.626
953.525	289.008
959.35	311.923
965.171	318.428
970.988	376.564
976.801	484.313
982.608	503.023
988.411	477.341
994.209	369.425
1000	346.891
1005.79	319.839
1011.58	361.859
1017.36	400.382
1023.13	339.782
1028.9	276.407
1034.67	252.184
1040.43	237.548
1046.19	217.992
1051.94	202.047
1057.69	180.076
1063.44	179.248
1069.17	185.981
1074.91	193.673
1080.64	243.942
1086.37	321.234
1092.09	420.8
1097.8	408.917
1103.52	327.457
1109.22	268.585
1114.93	229.397
1120.63	228.179
1126.32	222.835
1132.01	275.215
1137.7	327.842
1143.38	406.236
1149.06	487.526
1154.73	360.868
1160.4	223.887
1166.06	183.193
1171.72	160.3
1177.38	139.422
1183.03	127.479
1188.67	129.399
1194.31	107.985
1199.95	96.4228
1205.58	105.568
1211.21	98.0767
1216.84	93.5492
1222.46	91.0107
1228.07	96.444
1233.68	94.8428
1239.29	93.1498
1244.89	89.3083
1250.49	95.4534
1256.08	90.4189
1261.67	91.3304
1267.26	90.2003
1272.84	76.9591
1278.42	85.8247
1283.99	88.6527
1289.56	90.5209
1295.12	90.4501
1300.68	91.4398
1306.23	88.5279
1311.78	90.746
1317.33	86.0049
1322.87	78.2356
1328.41	85.6435
1333.94	86.9919
1339.47	82.1797
1345	76.2356
1350.52	84.5845
1356.04	86.7653
1361.55	85.8107
1367.06	94.0365
1372.56	97.0847
1378.06	94.9959
1383.56	93.926
1389.05	87.725
1394.53	92.8697
1400.02	93.009
1405.5	84.9102
1410.97	94.3412
1416.44	93.5112
1421.91	88.5496
1427.37	80.4684
1432.83	83.801
1438.28	85.0559
1443.73	93.6372
1449.17	83.3486
1454.62	100.238
1460.05	84.5309
1465.48	89.7735
1470.91	87.6479
1476.34	83.4451
1481.76	96.0802
1487.17	88.7958
1492.59	88.9081
1497.99	89.0653
1503.4	85.0286
1508.8	95.8311
1514.19	86.5492
1519.59	90.0275
1524.97	86.063
1530.36	88.5093
1535.74	92.0702
1541.11	96.6477
1546.48	85.984
1551.85	96.8052
1557.21	97.7644
1562.57	99.8247
1567.93	97.566
1573.28	88.8479
1578.62	99.5702
1583.97	102.81
1589.3	99.6217
1594.64	101.864
1599.97	93.3659
1605.3	96.7835
1610.62	106.795
1615.94	93.0209
1621.25	97.7488
1626.56	101.409
1631.87	96.2803
1637.17	97.6633
1642.47	101.103
1647.76	105.684
1653.05	103.589
1658.34	100.328
1663.62	101.468
1668.9	92.6048
1674.18	92.6065
1679.45	91.4817
1684.71	100.281
1689.98	95.7694
1695.23	102.392
1700.49	94.76
1705.74	98.5745
1710.99	107.631
1716.23	99.8629
1721.47	106.861
1726.7	107.033
1731.94	102.765
1737.16	97.341
1742.39	106.547
1747.61	108.995
1752.82	114.791
1758.03	101.306
1763.24	111.53
1768.44	114.983
1773.64	110.522
1778.84	106.1
1784.03	109.674
1789.22	107.614
1794.41	122.693
1799.59	112.708
1804.76	110.725
1809.94	115.592
1815.11	106.619
1820.27	112.625
1825.43	108.247
1830.59	124.75
1835.74	108.775
1840.89	111.329
1846.04	111.525
1851.18	111.707
1856.32	111.848
1861.45	120.264
1866.58	108.756
1871.71	110.128
1876.83	119.711
1881.95	110.408
1887.07	110.515
1892.18	116.452
1897.29	118.833
1902.39	118.957
1907.49	116.815
1912.59	120.712
1917.68	109.173
1922.77	114.073
1927.86	121.478
1932.94	122.909
1938.02	118.309
1943.09	119.669
1948.16	119.793
1953.23	122.274
1958.29	117.496
1963.35	115.105
1968.41	125.935
1973.46	123.457
1978.51	123.39
1983.55	129.336
1988.59	130.481
1993.63	114.811
1998.66	129.226
2003.69	118.43
2008.72	131.73
2013.74	122.206
2018.76	129.518
2023.77	122.389
2028.78	128.587
2033.79	128.819
2038.79	118.159
2043.79	131.757
2048.79	129.614
2053.78	123.747
2058.77	130.112
2063.76	134.076
2068.74	130.693
2073.72	133.43
2078.69	125.07
2083.66	128.993
2088.63	140.29
2093.59	135.586
2098.55	143.343
2103.51	138.717
2108.46	144.081
2113.41	140.756
2118.36	147.471
2123.3	142.883
2128.24	150.869
2133.17	134.809
2138.11	137.663
2143.03	148.136
2147.96	145.865
2152.88	151.172
2157.79	138.565
2162.71	130.998
2167.62	139.989
2172.52	131.114
2177.43	144.007
2182.32	146.587
2187.22	150.408
2192.11	144.059
2197	146.725
2201.89	145.631
2206.77	142.021
2211.64	135.875
2216.52	132.316
2221.39	128.77
2226.26	147.263
2231.12	148.938
2235.98	149.316
2240.84	150.998
2245.69	150.075
2250.54	147.829
2255.39	153.461
2260.23	145.936
2265.07	142.294
2269.9	153.16
2274.74	158.686
2279.57	148.223
2284.39	160.276
2289.21	152.336
2294.03	152.37
2298.84	148.459
2303.66	152.604
2308.46	162.196
2313.27	143.805
2318.07	140.137
2322.87	157.964
2327.66	157.043
2332.45	148.033
2337.24	156.629
2342.02	144.894
2346.8	163.171
2351.58	158.26
2356.35	143.622
2361.12	154.968
2365.89	144.257
2370.65	168.083
2375.41	155.944
2380.17	171.497
2384.92	152.236
2389.67	157.923
2394.42	153.803
2399.16	170.504
2403.9	163.529
2408.64	152.408
2413.37	162.434
2418.1	164.612
2422.83	160.927
2427.55	158.373
2432.27	157.374
2436.99	159.259
2441.7	162.577
2446.41	153.093
2451.11	162.127
2455.82	151.136
2460.51	163.071
2465.21	163.54
2469.9	155.309
2474.59	165.841
2479.28	169.185
2483.96	176.876
2488.64	162.658
2493.32	155.677
2497.99	163.328
2502.66	169.506
2507.32	171.264
2511.99	165.622
2516.65	168.777
2521.3	180.85
2525.96	160.429
2530.61	169.558
2535.25	177.281
2539.89	167.228
2544.53	172.042
2549.17	179.891
2553.8	169.813
2558.43	167.126
2563.06	179.503
2567.68	175.431
2572.3	165.325
2576.92	168.761
2581.53	181.242
2586.14	167.824
2590.75	178.601
2595.35	192.506
2599.96	186.716
2604.55	191.533
2609.15	182.584
2613.74	188.839
2618.33	184.411
2622.91	192.233
2627.49	189.382
2632.07	180.512
2636.64	184.052
2641.22	190.813
2645.78	169.737
2650.35	184.256
2654.91	194.11
2659.47	210.072
2664.03	196.298
2668.58	180.91
2673.13	193.845
2677.67	200.855
2682.22	198.688
2686.76	199.593
2691.29	182.859
2695.83	196.144
2700.36	194.952
2704.89	177.659
2709.41	187.649
2713.93	189.596
2718.45	193.245
2722.96	206.568
2727.47	197.116
2731.98	195.674
2736.49	192.584
2740.99	202.504
2745.49	202.766
2749.98	212.914
2754.47	202.094
2758.96	195.921
2763.45	194.576
2767.93	211.422
2772.41	200.278
2776.89	194.166
2781.36	203.049
2785.84	197.083
2790.3	199.401
2794.77	191.649
2799.23	208.942
2803.69	194.291
2808.14	203.111
2812.59	213.615
2817.04	183.49
2821.49	202.408
2825.93	199.358
2830.37	208.17
2834.81	199.958
2839.24	205.355
2843.67	195.42
2848.1	197.48
2852.53	179.048
2856.95	200.108
2861.37	197.179
2865.78	216.776
2870.19	210.524
2874.6	212.911
2879.01	210.112
2883.41	221.343
2887.81	199.308
2892.21	215.838
2896.6	216.593
2901	222.722
2905.38	214.52
2909.77	200.869
2914.15	217.439
2918.53	203.585
2922.91	196.901
2927.28	211.88
2931.65	217.935
2936.02	205.787
2940.38	208.003
2944.74	208.382
2949.1	210.492
2953.46	208.976
2957.81	211.095
2962.16	222.389
2966.5	219.087
2970.85	213.975
2975.19	227.26
2979.52	227.686
2983.86	222.644
2988.19	219.506
2992.52	220.119
2996.85	230.066
3001.17	215.843
3005.49	222.2
3009.8	234.228
3014.12	236.848
3018.43	239.591
3022.74	229.034
3027.04	227.801
3031.34	241.755
3035.64	242.256
3039.94	236.974
3044.23	254.742
3048.52	255.186
3052.81	259.475
3057.09	254.155
3061.38	272.029
3065.65	274.448
3069.93	272.984
3074.2	267.633
3078.47	254.483
3082.74	282.305
3087	273.153
3091.27	291.571
3095.52	288.552
3099.78	269.732
3104.03	286.532
3108.28	309.501
3112.53	298.739
3116.77	307.929
3121.01	299.109
3125.25	324.681
3129.49	293.667
3133.72	307.366
3137.95	308.839
3142.18	324.637
3146.4	328.028
3150.62	333.415
3154.84	344.863
3159.06	324.978
3163.27	351.103
3167.48	343.645
3171.69	342.48
3175.89	358.07
3180.09	356.563
3184.29	357.055
3188.49	359.54
3192.68	351.583
3196.87	371.435
3201.06	338.467
3205.24	346.106
3209.42	353.948
3213.6	329.484
3217.78	346.102
3221.95	316.986
3226.12	335.763
3230.29	321.704
3234.45	320.705
3238.61	317.439
3242.77	307.623
3246.93	315.611
3251.08	307.73
3255.23	306.285
3259.38	311.62
3263.53	305.916
3267.67	291.597
3271.81	279.115
3275.95	286.694
3280.08	280.419
3284.21	292.46
3288.34	297.639
3292.47	284.377
3296.59	287.177
3300.71	283.141
3304.83	292.955
3308.95	286.561
3313.06	300.999
3317.17	287.583
3321.27	281.183
3325.38	281.875
3329.48	296.7
3333.58	290.688
3337.67	291.716
3341.77	278.257
3345.86	293.068
3349.95	284.056
3354.03	275.023
3358.11	263.706
3362.19	264.307
3366.27	269.66
3370.34	272.641
3374.42	277.956
3378.48	256.678
3382.55	290.816
3386.61	269.434
3390.68	272.152
3394.73	279.734
3398.79	280.15
3402.84	270.764
3406.89	227.269
3410.94	271.249
3414.98	249.549
3419.03	274.116
3423.06	276.742
3427.1	255.011
3431.14	257.75
3435.17	260.562
3439.2	243.852
3443.22	268.864
3447.25	252.284
3451.27	265.252
3455.28	263.542
3459.3	269.401
3463.31	225.499
3467.32	256.303
3471.33	257.162
3475.34	280.483
3479.34	258.628
3483.34	249.27
3487.33	265.203
3491.33	230.301
3495.32	235.981
3499.31	254.396
3503.3	236.931
3507.28	255.249
3511.26	270.865
3515.24	255.624
3519.22	250.632
3523.19	258.492
3527.16	240.674
3531.13	248.572
3535.1	233.52
3539.06	246.998
3543.02	247.495
3546.98	242.716
3550.93	243.023
3554.89	240.515
3558.84	251.18
3562.78	248.918
3566.73	272.852
3570.67	228.97
3574.61	239.95
3578.55	261.593
3582.48	233.348
3586.41	241.979
3590.35	253.297
3594.27	262.012
3598.2	246.754
3602.12	236.684
3606.04	223.851
3609.95	253.876
3613.87	227.49
3617.78	217.136
3621.69	203.945
3625.6	223.013
3629.5	220.444
3633.4	212.402
3637.3	228.813
3641.2	212.88
3645.09	218.729
3648.98	208.165
3652.87	197.491
3656.76	214.033
3660.64	225.132
3664.53	211.648
3668.4	231.007
3672.28	212.075
3676.16	212.389
3680.03	215.545
3683.9	213.306
3687.76	194.579
3691.63	203.437
3695.49	226.147
3699.35	201.718
3703.2	193.87
3707.06	200.005
3710.91	222.997
3714.76	198.264
3718.6	221.248
3722.45	201.921
3726.29	207.935
3730.13	205.464
3733.97	194.502
3737.8	203.402
3741.63	195.198
3745.46	195.506
3749.29	210.061
3753.11	216.004
3756.93	196.126
3760.75	216.283
3764.57	202.05
3768.39	207.897
3772.2	199.462
3776.01	205.379
3779.81	196.979
3783.62	197.268
3787.42	177.38
3791.22	215.165
3795.02	201.067
3798.81	195.67
3802.61	184.461
3806.4	176.147
3810.18	191.137
3813.97	185.681
3817.75	191.91
3821.53	195.207
3825.31	189.642
3829.09	184.066
3832.86	196.219
3836.63	199.524
3840.4	196.88
3844.17	185.395
3847.93	194.457
3851.69	197.564
3855.45	203.6
3859.21	179.834
3862.96	203.683
3866.71	192.117
3870.46	165.699
3874.21	198.647
3877.95	201.76
3881.69	183.947
3885.44	190.086
3889.17	205.259
3892.91	202.521
3896.64	208.903
3900.37	188.153
3904.1	188.429
3907.82	188.693
3911.55	188.993
3915.27	183.266
3918.99	183.65
3922.7	196.274
3926.42	181.471
3930.13	178.792
3933.84	188.274
3937.54	203.871
3941.25	204.229
3944.95	198.493
3948.65	180.364
3952.35	186.811
3956.04	193.242
3959.73	193.43
3963.42	190.483
3967.11	178.186
3970.8	187.525
3974.48	199.995
3978.16	175.237
3981.84	200.039
3985.52	193.825
3989.19	200.018
3992.86	184.575
3996.53	187.81
3998.37	194.112