File: Data/3-Raman/raw/bu20-j-ff1-fi02-s_1800 (450-850nm)_532nm_edge_100%_x100_vis_lwd_h30um_30sx2_01.txt
#Acq. time (s)=	30
#Accumulations=	2
#Range=	Off
#Autofocus=	Off
#Macrospot=	Off
#AutoExposure=	Off
#Spike filter=	Multiple accum.
#Delay time (s)=	2
#Binning=	1
#Readout mode=	Signal
#DeNoise=	Off
#ICS correction=	On
#Dark correction=	Off
#Inst. Process=	Off
#Detector Gain=	Best Dynamic
#Detector ADC=	50 kHz HS
#Detector temperature (°C)=	-60.09
#Instrument=	LabRAM HR Evol
#Detector=	SIN-EM FIVIS
#Objective=	x100_VIS_LWD
#Grating=	1800 (450-850nm)
#ND Filter=	100%
#Laser=	532nm_Edge
#Spectro (cm-¹)=	3360
#Hole=	30.0125
#Temperature=	0
#Range=	Visible
#StageXY=	75x50mm Scan+
#StageZ=	Z motor
#X (µm)=	0
#Y (µm)=	0
#Z (µm)=	-16.5
#Full time(mm:ss)=	1:04
#Project=	21_08_11
#Sample=	BU20
#Site=
#Title=	BU20-J-FF1-FI02-S_1800 (450-850nm)_532nm_Edge_100%_x100_VIS_LWD_H30um_30sX2
#Remark=
#Date=	11.08.2021 17:24
#Acquired=	11.08.2021 17:24:45
3515.51	541.792
3515.13	567.492
3514.74	557.17
3514.36	568.651
3513.98	583.765
3513.6	584.661
3513.21	615.103
3512.83	602.679
3512.45	619.801
3512.06	630.293
3511.68	612.216
3511.3	609.678
3510.91	630.248
3510.53	619.359
3510.15	622.211
3509.76	609.021
3509.38	595.989
3509	579.875
3508.61	593.185
3508.23	551.81
3507.84	568.139
3507.46	548.675
3507.08	536.798
3506.69	515.373
3506.31	497.464
3505.93	491.122
3505.54	482.397
3505.16	459.066
3504.77	476.212
3504.39	438.326
3504.01	415.341
3503.62	431.519
3503.24	394.493
3502.85	392.655
3502.47	394.767
3502.09	376.816
3501.7	374.991
3501.32	369.33
3500.93	350.369
3500.55	330.351
3500.16	317.768
3499.78	316.731
3499.4	306.193
3499.01	306.206
3498.63	297.702
3498.24	311.081
3497.86	290.138
3497.47	282.52
3497.09	274.878
3496.7	272.901
3496.32	266.224
3495.93	271.056
3495.55	265.394
3495.17	250.226
3494.78	249.328
3494.4	249.367
3494.01	241.764
3493.63	236.962
3493.24	250.238
3492.86	242.671
3492.47	235.065
3492.09	225.25
3491.7	230.196
3491.32	230.144
3490.93	229.012
3490.55	214.725
3490.16	214.624
3489.78	214.359
3489.39	226.646
3489.01	216.99
3488.62	205.504
3488.23	211.286
3487.85	211.319
3487.46	198.96
3487.08	205.707
3486.69	209.583
3486.31	213.455
3485.92	200.134
3485.54	214.526
3485.15	208.884
3484.76	190.856
3484.38	206.253
3483.99	198.654
3483.61	190.129
3483.22	194.967
3482.84	198.837
3482.45	189.28
3482.06	181.613
3481.68	184.371
3481.29	184.458
3480.91	185.186
3480.52	194.478
3480.13	181.162
3479.75	180.3
3479.36	187.901
3478.98	191.672
3478.59	186.862
3478.2	188.761
3477.82	187.037
3477.43	188.203
3477.04	199.751
3476.66	175.11
3476.27	185.532
3475.88	185.922
3475.5	170.935
3475.11	188.38
3474.73	186.828
3474.34	183.944
3473.95	179.403
3473.57	184.029
3473.18	183.346
3472.79	187.724
3472.41	186.189
3472.02	177.987
3471.63	181.815
3471.24	188.79
3470.86	176.341
3470.47	188.293
3470.08	179.792
3469.7	170.68
3469.31	182.96
3468.92	175.217
3468.54	168.57
3468.15	186.699
3467.76	186.755
3467.38	176.407
3466.99	173.548
3466.6	189.935
3466.21	182.279
3465.83	188.945
3465.44	188.923
3465.05	184.148
3464.66	188.994
3464.28	184.224
3463.89	178.497
3463.5	179.499
3463.11	183.393
3462.73	168.049
3462.34	173.859
3461.95	170.025
3461.56	173.887
3461.18	174.846
3460.79	189.288
3460.4	170.04
3460.01	177.744
3459.62	186.497
3459.24	175.013
3458.85	187.443
3458.46	190.248
3458.07	178.72
3457.68	180.666
3457.3	184.451
3456.91	178.635
3456.52	182.48
3456.13	180.62
3455.74	181.677
3455.36	194.22
3454.97	183.618
3454.58	179.793
3454.19	193.309
3453.8	184.651
3453.41	179.857
3453.03	184.662
3452.64	190.547
3452.25	179.101
3451.86	187.757
3451.47	186.773
3451.08	192.618
3450.69	194.461
3450.31	195.38
3449.92	190.527
3449.53	192.419
3449.14	187.566
3448.75	187.554
3448.36	198.134
3447.97	208.692
3447.58	186.706
3447.19	200.885
3446.81	194.447
3446.42	198.537
3446.03	205.623
3445.64	188.423
3445.25	191.496
3444.86	214.515
3444.47	211.761
3444.08	202.079
3443.69	213.987
3443.3	202.886
3442.91	208.85
3442.52	214.511
3442.14	213.51
3441.75	221.208
3441.36	222.148
3440.97	221.23
3440.58	216.473
3440.19	232.965
3439.8	231.16
3439.41	231.477
3439.02	251.331
3438.63	248.028
3438.24	254.797
3437.85	265.284
3437.46	258.251
3437.07	271.705
3436.68	287.17
3436.29	296.907
3435.9	297.954
3435.51	325.073
3435.12	345.441
3434.73	369.694
3434.34	411.107
3433.95	417.833
3433.56	459.355
3433.17	502.701
3432.78	560.703
3432.39	602.54
3432	695.652
3431.61	756.748
3431.22	856.312
3430.83	980.282
3430.44	1041.75
3430.05	1130.26
3429.66	1208.7
3429.27	1148.66
3428.88	1136.61
3428.48	1072.33
3428.09	956.078
3427.7	862.051
3427.31	792.804
3426.92	696.84
3426.53	657.378
3426.14	581.255
3425.75	513.013
3425.36	470.523
3424.97	457.797
3424.58	409.579
3424.19	387.453
3423.79	368.212
3423.4	352.799
3423.01	346.946
3422.62	343.042
3422.23	315.977
3421.84	310.98
3421.45	284.829
3421.06	270.328
3420.67	254.901
3420.27	267.474
3419.88	254.037
3419.49	252.065
3419.1	249.107
3418.71	236.512
3418.32	239.218
3417.93	239.187
3417.53	228.611
3417.14	227.603
3416.75	221.814
3416.36	219.934
3415.97	220.855
3415.58	219.823
3415.19	214.996
3414.79	212.116
3414.4	215.022
3414.01	199.681
3413.62	206.422
3413.22	203.51
3412.83	196.728
3412.44	209.147
3412.05	199.455
3411.66	199.417
3411.27	200.382
3410.87	202.358
3410.48	204.334
3410.09	195.673
3409.7	195.663
3409.3	187.959
3408.91	197.55
3408.52	193.693
3408.13	182.207
3407.73	196.472
3407.34	199.448
3406.95	190.812
3406.56	186.273
3406.17	201.329
3405.77	196.51
3405.38	196.27
3404.99	193.363
3404.59	186.678
3404.2	192.357
3403.81	179.084
3403.42	192.275
3403.02	183.89
3402.63	184.934
3402.24	193.333
3401.84	190.949
3401.45	190.582
3401.06	206.592
3400.67	191.024
3400.27	189.437
3399.88	193.047
3399.49	194.73
3399.09	204.008
3398.7	196.561
3398.31	192.591
3397.91	195.902
3397.52	191.989
3397.13	202.543
3396.73	200.847
3396.34	198.855
3395.95	190.168
3395.55	196.784
3395.16	210.911
3394.77	204.114
3394.37	212.739
3393.98	210.908
3393.59	209.088
3393.19	199.681
3392.8	210.239
3392.4	206.982
3392.01	209.991
3391.62	220.831
3391.22	215.488
3390.83	216.615
3390.44	230.216
3390.04	229.206
3389.65	224.258
3389.25	231.668
3388.86	230.57
3388.47	230.826
3388.07	232.524
3387.68	234.422
3387.28	251.492
3386.89	266.598
3386.49	262.775
3386.1	265.617
3385.71	295.165
3385.31	286.632
3384.92	295.301
3384.52	310.786
3384.13	306.244
3383.73	319.612
3383.34	338.492
3382.95	354.563
3382.55	356.274
3382.16	355.177
3381.76	379.043
3381.37	410.599
3380.97	393.491
3380.58	396.397
3380.18	384.01
3379.79	415.471
3379.39	396.341
3379	392.463
3378.6	387.59
3378.21	367.493
3377.81	361.774
3377.42	358.046
3377.02	366.674
3376.63	345.63
3376.23	340.794
3375.84	311.149
3375.44	311.084
3375.05	291.038
3374.65	296.721
3374.25	284.226
3373.86	283.423
3373.46	268.313
3373.07	272.254
3372.67	253.229
3372.28	251.299
3371.88	244.559
3371.49	245.466
3371.09	227.247
3370.7	220.557
3370.3	222.491
3369.9	232
3369.51	221.496
3369.11	208.157
3368.72	217.706
3368.32	215.819
3367.93	204.38
3367.53	206.268
3367.13	194.826
3366.74	203.464
3366.34	194.843
3365.95	192.879
3365.55	204.276
3365.15	184.271
3364.76	182.406
3364.36	182.42
3363.97	187.151
3363.57	187.178
3363.17	183.421
3362.78	187.272
3362.38	189.196
3361.98	179.675
3361.59	166.313
3361.19	171.011
3360.79	173.829
3360.4	176.646
3360	169.938
3359.6	165.132
3359.21	167.955
3358.81	161.284
3358.41	166.045
3358.02	175.595
3357.62	161.391
3357.22	160.476
3356.83	163.321
3356.43	172.803
3356.03	162.269
3355.64	166.986
3355.24	161.259
3354.84	156.492
3354.44	165.056
3354.05	161.254
3353.65	155.549
3353.25	155.551
3352.86	152.698
3352.46	155.576
3352.06	158.471
3351.67	156.565
3351.27	161.311
3350.87	146.119
3350.47	156.623
3350.08	158.538
3349.68	146.15
3349.28	150.872
3348.88	154.626
3348.49	149.818
3348.09	155.452
3347.69	147.807
3347.29	144.005
3346.9	149.738
3346.5	153.592
3346.1	143.195
3345.7	143.231
3345.3	147.034
3344.91	148.955
3344.51	154.651
3344.11	149.896
3343.71	154.711
3343.31	137.6
3342.92	143.3
3342.52	139.499
3342.12	147.138
3341.72	141.466
3341.32	132.942
3340.93	147.257
3340.53	139.648
3340.13	147.288
3339.73	153.973
3339.33	144.449
3338.93	139.699
3338.54	140.615
3338.14	132.135
3337.74	140.835
3337.34	147.6
3336.94	141.885
3336.54	143.728
3336.14	142.721
3335.74	137.964
3335.35	135.115
3334.95	146.623
3334.55	143.83
3334.15	137.176
3333.75	135.273
3333.35	126.683
3332.95	141.98
3332.55	139.103
3332.16	131.444
3331.76	140.03
3331.36	135.257
3330.96	134.257
3330.56	131.338
3330.16	136.104
3329.76	125.662
3329.36	137.185
3328.96	137.304
3328.56	133.542
3328.16	134.514
3327.76	140.261
3327.37	127.796
3326.97	137.305
3326.57	130.527
3326.17	131.476
3325.77	141.015
3325.37	126.778
3324.97	134.134
3324.57	137.053
3324.17	130.488
3323.77	135.346
3323.37	138.238
3322.97	142.1
3322.57	135.387
3322.17	126.719
3321.77	133.46
3321.37	131.629
3320.97	130.811
3320.57	125.109
3320.17	127.002
3319.77	130.8
3319.37	134.589
3318.97	137.396
3318.57	134.491
3318.17	131.606
3317.77	128.79
3317.37	129.782
3316.97	129.821
3316.57	138.444
3316.17	143.34
3315.77	133.574
3315.37	133.602
3314.97	125.228
3314.57	130.141
3314.17	129.114
3313.77	129.913
3313.37	126.892
3312.97	138.551
3312.56	127.112
3312.16	138.46
3311.76	131.737
3311.36	119.298
3310.96	125.048
3310.56	127.939
3310.16	125.063
3309.76	130.808
3309.36	129.847
3308.96	121.249
3308.56	127.986
3308.15	128.058
3307.75	131.033
3307.35	128.203
3306.95	120.564
3306.55	126.339
3306.15	128.236
3305.75	125.376
3305.35	127.325
3304.94	131.171
3304.54	138.945
3304.14	121.746
3303.74	131.462
3303.34	128.51
3302.94	113.96
3302.53	131.404
3302.13	118.982
3301.73	128.446
3301.33	125.483
3300.93	111.067
3300.53	119.721
3300.13	120.779
3299.72	125.655
3299.32	125.508
3298.92	125.449
3298.52	122.559
3298.12	112.985
3297.71	136.176
3297.31	122.78
3296.91	133.405
3296.51	124.728
3296.11	119.886
3295.7	123.698
3295.3	116.941
3294.9	124.603
3294.5	122.654
3294.1	114.015
3293.69	123.672
3293.29	121.769
3292.89	122.744
3292.49	117.916
3292.08	119.831
3291.68	123.898
3291.28	115.078
3290.88	121.753
3290.47	112.031
3290.07	125.39
3289.67	124.485
3289.27	119.758
3288.86	127.493
3288.46	115.972
3288.06	119.831
3287.65	125.637
3287.25	107.386
3286.85	118.963
3286.45	130.545
3286.04	115.146
3285.64	116.098
3285.24	124.731
3284.83	117.932
3284.43	114.032
3284.03	112.017
3283.62	121.62
3283.22	124.761
3282.82	122.847
3282.41	117.851
3282.01	119.414
3281.61	115.998
3281.2	117.927
3280.8	121.766
3280.4	125.615
3279.99	121.738
3279.59	123.631
3279.19	122.668
3278.78	119.783
3278.38	114.028
3277.98	119.83
3277.57	111.189
3277.17	119.871
3276.76	112.176
3276.36	111.204
3275.96	122.738
3275.55	113.104
3275.15	120.734
3274.74	124.583
3274.34	114.117
3273.94	116.706
3273.53	122.453
3273.13	122.538
3272.72	119.697
3272.32	117.829
3271.92	114.015
3271.51	125.545
3271.11	118.84
3270.7	123.682
3270.3	124.674
3269.9	120.851
3269.49	114.117
3269.09	120.861
3268.68	121.811
3268.28	114.073
3267.87	117.894
3267.47	120.746
3267.06	113.029
3266.66	123.609
3266.25	113.053
3265.85	122.728
3265.44	128.575
3265.04	120.939
3264.64	123.846
3264.23	118.058
3263.83	121.892
3263.42	116.07
3263.02	120.826
3262.61	116.938
3262.21	120.746
3261.8	112.068
3261.4	129.39
3260.99	117.856
3260.59	123.698
3260.18	118.817
3259.78	119.896
3259.37	117.075
3258.96	109.339
3258.56	112.252
3258.15	113.203
3257.75	112.197
3257.34	115.052
3256.94	119.813
3256.53	119.763
3256.13	124.529
3255.72	118.724
3255.31	119.668
3254.91	119.697
3254.5	111.038
3254.1	110.049
3253.69	113.881
3253.29	116.776
3252.88	113.922
3252.47	112.999
3252.07	114.947
3251.66	117.84
3251.26	120.712
3250.85	119.71
3250.44	116.756
3250.04	117.631
3249.63	114.708
3249.23	107.997
3248.82	116.678
3248.41	109.999
3248.01	111.032
3247.6	118.74
3247.2	115.825
3246.79	115.782
3246.38	116.681
3245.98	112.744
3245.57	118.431
3245.16	111.612
3244.76	112.553
3244.35	118.376
3243.94	114.579
3243.54	116.499
3243.13	112.712
3242.72	109.861
3242.32	117.563
3241.91	101.262
3241.5	113.73
3241.1	113.737
3240.69	110.856
3240.28	115.635
3239.88	111.786
3239.47	113.718
3239.06	114.674
3238.65	112.771
3238.25	106.021
3237.84	113.645
3237.43	119.366
3237.03	111.693
3236.62	122.256
3236.21	108.877
3235.8	110.836
3235.4	111.83
3234.99	115.68
3234.58	115.653
3234.18	110.846
3233.77	107.954
3233.36	109.86
3232.95	114.649
3232.54	107.934
3232.14	116.574
3231.73	112.762
3231.32	113.66
3230.91	107.875
3230.51	110.826
3230.1	110.73
3229.69	102.122
3229.28	105.197
3228.87	106.848
3228.47	107.803
3228.06	108.875
3227.65	112.537
3227.24	102.019
3226.83	104.751
3226.43	108.517
3226.02	107.072
3225.61	110.911
3225.2	107.911
3224.79	104.01
3224.39	107.752
3223.98	108.648
3223.57	97.1577
3223.16	110.585
3222.75	115.391
3222.34	112.539
3221.94	102.023
3221.53	109.671
3221.12	104.842
3220.71	104.783
3220.3	111.432
3219.89	107.575
3219.48	105.659
3219.07	102.84
3218.67	106.654
3218.26	115.221
3217.85	105.793
3217.44	100.243
3217.03	96.9764
3216.62	102.117
3216.21	96.2325
3215.8	107.549
3215.39	101.867
3214.99	111.481
3214.58	101.94
3214.17	100.96
3213.76	106.667
3213.35	104.75
3212.94	108.593
3212.53	104.766
3212.12	99.9815
3211.71	105.717
3211.3	96.1405
3210.89	95.1734
3210.48	98.029
3210.07	106.649
3209.66	101.929
3209.25	94.3163
3208.84	106.793
3208.44	104.879
3208.02	100.057
3207.62	96.2214
3207.21	103.863
3206.8	104.812
3206.39	99.0694
3205.98	107.697
3205.57	108.653
3205.16	105.759
3204.75	100.935
3204.34	100.929
3203.93	103.815
3203.52	95.2177
3203.11	100.019
3202.7	93.3421
3202.29	101.975
3201.88	101.999
3201.47	102.96
3201.06	105.798
3200.65	96.2044
3200.23	97.1492
3199.82	98.0965
3199.41	96.1794
3199	95.2339
3198.59	96.2136
3198.39	91.4588