File: Data/3-Raman/raw/bu20-j-ff1-fi02-v_1800 (450-850nm)_532nm_edge_100%_x100_vis_lwd_h30um_60sx2_01.txt
#Acq. time (s)=	60
#Accumulations=	2
#Range (cm-¹)=	1200...2360
#Windows=	3
#Auto scanning=	Off
#Autofocus=	Off
#Macrospot=	Off
#AutoExposure=	Off
#Spike filter=	Multiple accum.
#Delay time (s)=	2
#Binning=	1
#Readout mode=	Signal
#DeNoise=	Off
#ICS correction=	On
#Dark correction=	Off
#Inst. Process=	Off
#Detector Gain=	Best Dynamic
#Detector ADC=	50 kHz HS
#Detector temperature (°C)=	-60.09
#Instrument=	LabRAM HR Evol
#Detector=	SIN-EM FIVIS
#Objective=	x100_VIS_LWD
#Grating=	1800 (450-850nm)
#ND Filter=	100%
#Laser=	532nm_Edge
#Hole=	30.0125
#Temperature=	0
#Range=	Visible
#StageXY=	75x50mm Scan+
#StageZ=	Z motor
#X (µm)=	0
#Y (µm)=	0
#Z (µm)=	-17.3
#Full time(mm:ss)=	6:23
#Project=	21_08_11
#Sample=	BU20
#Site=
#Title=	BU20-J-FF1-FI02-V_1800 (450-850nm)_532nm_Edge_100%_x100_VIS_LWD_H30um_60sX2
#Remark=
#Date=	11.08.2021 17:12
#Acquired=	11.08.2021 17:12:55
1201.69	34.9324
1202.8	37.1484
1203.91	34.9342
1205.02	35.9836
1206.14	35.9163
1207.25	31.5837
1208.36	35.8327
1209.47	39.0206
1210.58	34.6992
1211.69	35.7153
1212.8	35.6761
1213.91	33.5362
1215.02	33.534
1216.13	29.2447
1217.24	33.4546
1218.35	31.3049
1219.45	31.2904
1220.56	33.4064
1221.67	31.2543
1222.78	33.3107
1223.89	31.1515
1225	36.4202
1226.1	39.5935
1227.21	43.7441
1228.32	43.6158
1229.43	50.1019
1230.53	59.4912
1231.64	70.9294
1232.74	74.0592
1233.85	82.4781
1234.96	72.0064
1236.06	67.8095
1237.17	54.0866
1238.27	52.9628
1239.38	49.7912
1240.48	40.358
1241.59	39.297
1242.69	40.3583
1243.8	43.5062
1244.9	43.4801
1246.01	46.58
1247.11	50.76
1248.21	54.9071
1249.32	53.863
1250.42	60.0997
1251.52	64.2335
1252.63	54.7912
1253.73	55.845
1254.83	47.5135
1255.93	47.5168
1257.03	44.3857
1258.14	46.4587
1259.24	44.364
1260.34	41.2206
1261.44	41.2354
1262.54	53.7383
1263.64	85.1899
1264.74	87.2689
1265.84	50.6785
1266.94	38.1696
1268.04	36.13
1269.14	39.2914
1270.24	30.8795
1271.34	35.0537
1272.44	36.1411
1273.54	34.0819
1274.64	37.2364
1275.74	36.211
1276.84	33.0874
1277.93	41.5269
1279.03	39.4485
1280.13	45.752
1281.23	64.7369
1282.33	130.01
1283.42	549.085
1284.52	1179.74
1285.62	173.229
1286.71	76.3306
1287.81	47.8819
1288.91	39.4791
1290	36.3435
1291.1	31.0699
1292.19	33.1767
1293.29	28.9817
1294.38	35.3254
1295.48	32.2165
1296.57	34.3504
1297.67	35.3779
1298.76	30.0891
1299.86	30.0914
1300.95	29.0357
1302.04	29.049
1303.14	31.1517
1304.23	23.7587
1305.32	25.8526
1306.42	30.0561
1307.51	30.0593
1308.6	25.8455
1309.69	25.856
1310.79	32.1886
1311.88	27.9797
1312.97	26.9201
1314.06	29.0283
1315.15	30.098
1316.24	29.0427
1317.33	29.0483
1318.43	26.94
1319.52	30.1082
1320.61	25.8736
1321.7	25.8464
1322.79	28.9925
1323.88	26.8879
1324.97	27.9393
1326.06	26.8295
1327.15	26.8611
1328.23	27.9554
1329.32	27.9583
1330.41	23.7243
1331.5	30.0071
1332.59	27.8662
1333.68	24.6821
1334.76	28.8569
1335.85	27.7886
1336.94	31.9692
1338.03	23.567
1339.11	28.7955
1340.2	28.8002
1341.29	28.794
1342.37	25.6306
1343.46	26.6688
1344.54	24.5723
1345.63	24.5456
1346.72	27.6396
1347.8	27.6199
1348.89	27.6039
1349.97	32.7886
1351.06	27.5593
1352.14	29.6437
1353.23	27.6251
1354.31	29.6119
1355.39	26.49
1356.48	33.7551
1357.56	26.4707
1358.64	25.4138
1359.73	28.5029
1360.81	29.5215
1361.89	24.335
1362.98	28.4786
1364.06	29.5209
1365.14	37.7808
1366.22	27.4038
1367.3	29.4557
1368.38	33.5994
1369.47	89.4222
1370.55	35.6418
1371.63	36.6257
1372.71	38.6523
1373.79	28.334
1374.87	33.4773
1375.95	41.7164
1377.03	36.532
1378.11	41.7468
1379.19	44.8374
1380.27	45.7846
1381.35	51.9097
1382.43	54.9001
1383.51	65.1007
1384.59	80.519
1385.66	154.533
1386.74	700.735
1387.82	2212
1388.9	193.537
1389.98	77.4109
1391.05	53.8026
1392.13	46.5881
1393.21	45.5438
1394.28	39.393
1395.36	39.4104
1396.44	37.351
1397.51	31.1958
1398.59	33.2516
1399.66	28.1468
1400.74	35.3287
1401.82	33.3108
1402.89	28.2315
1403.97	34.3709
1405.04	34.3538
1406.12	41.5099
1407.19	57.924
1408.27	116.391
1409.34	149.255
1410.41	51.7668
1411.49	40.4656
1412.56	34.3908
1413.63	33.3252
1414.71	29.2599
1415.78	31.3198
1416.85	31.334
1417.92	26.2039
1419	29.288
1420.07	28.2394
1421.14	25.1467
1422.21	29.2934
1423.28	27.1602
1424.36	30.2344
1425.43	32.3161
1426.5	29.2174
1427.57	24.0629
1428.64	27.1367
1429.71	23.0575
1430.78	24.114
1431.85	26.1631
1432.92	27.1571
1433.99	28.1687
1435.06	26.1304
1436.13	21.0019
1437.2	24.0684
1438.26	31.2447
1439.33	23.06
1440.4	26.1489
1441.47	26.1428
1442.54	23.075
1443.61	26.14
1444.67	26.1633
1445.74	25.1305
1446.81	24.0975
1447.87	24.095
1448.94	22.0504
1450.01	22.0389
1451.07	25.1061
1452.14	22.0273
1453.21	22.034
1454.27	17.9327
1455.34	22.0336
1456.4	22.0318
1457.47	22.024
1458.53	25.1008
1459.6	23.0515
1460.66	20.995
1461.73	24.0532
1462.79	21.9874
1463.86	18.9273
1464.92	21.9648
1465.98	19.9054
1467.05	21.9342
1468.11	23.9709
1469.17	26.0003
1470.24	20.8879
1471.3	20.8768
1472.36	21.8915
1473.42	19.846
1474.48	21.8829
1475.55	18.8257
1476.61	21.8678
1477.67	25.9298
1478.73	22.8646
1479.79	19.7979
1480.85	21.8116
1481.91	22.8391
1482.97	18.7859
1484.04	21.8138
1485.1	19.7117
1486.15	23.8026
1487.22	23.8035
1488.28	22.7736
1489.33	18.716
1490.39	20.7331
1491.45	18.7034
1492.51	21.735
1493.57	18.7004
1494.63	19.7115
1495.69	20.699
1496.74	22.7088
1497.8	19.6794
1498.86	19.6825
1499.92	19.687
1500.97	21.6986
1502.03	19.6763
1503.09	19.6621
1504.14	19.6649
1505.2	22.6793
1506.26	19.6449
1507.31	21.6657
1508.37	18.6411
1509.42	18.6425
1510.48	22.6631
1511.53	21.62
1512.59	19.5807
1513.64	19.5857
1514.7	21.5856
1515.75	20.5596
1516.81	22.559
1517.86	17.5515
1518.92	20.5664
1519.97	19.5612
1521.02	18.563
1522.08	19.5601
1523.13	17.5382
1524.18	23.5315
1525.24	18.5301
1526.29	17.5417
1527.34	17.5369
1528.39	18.5318
1529.44	21.531
1530.5	16.5303
1531.55	21.5434
1532.6	19.5499
1533.65	17.5553
1534.7	19.5557
1535.75	19.5329
1536.8	17.5088
1537.85	18.4958
1538.9	18.5046
1539.95	20.5492
1541	20.5499
1542.05	27.5394
1543.1	20.5092
1544.15	17.5051
1545.2	16.524
1546.25	16.528
1547.3	16.5325
1548.35	18.5341
1549.39	18.4984
1550.44	18.5899
1551.49	23.5827
1552.54	17.5739
1553.58	15.5454
1554.63	18.5333
1555.68	17.5321
1556.73	16.5292
1557.77	13.5174
1558.82	16.5024
1559.87	18.4904
1560.91	15.4901
1561.96	18.5029
1563	14.5
1564.05	18.5142
1565.09	16.4415
1566.14	17.494
1567.18	18.508
1568.23	14.4995
1569.27	18.4869
1570.32	16.4902
1571.36	19.4796
1572.41	19.4701
1573.45	17.4649
1574.49	17.4802
1575.54	18.4874
1576.58	17.4749
1577.62	14.4598
1578.67	18.443
1579.71	17.4509
1580.75	19.4402
1581.79	17.4354
1582.84	17.4311
1583.88	17.4301
1584.92	14.4429
1585.96	19.4124
1587	14.4272
1588.04	18.4091
1589.08	21.4052
1590.13	19.4181
1591.17	16.4312
1592.21	17.4119
1593.25	17.3895
1594.29	17.383
1595.33	16.3886
1596.37	17.3819
1597.41	16.3926
1598.44	17.3729
1599.48	20.3369
1600.52	20.3191
1601.56	15.3455
1602.6	17.3105
1603.64	19.28
1604.67	15.3262
1605.71	18.3764
1606.75	13.6579
1607.79	18.3041
1608.82	18.7582
1609.86	17.2155
1610.9	17.5054
1611.93	16.3566
1612.97	18.3659
1614.01	16.559
1615.04	16.5964
1616.08	15.4963
1617.12	16.5056
1618.15	17.9889
1619.19	17.5009
1620.22	17.0103
1621.26	17.5782
1622.29	16.5847
1623.33	16.5809
1624.36	16.3674
1625.39	15.7074
1626.43	16.6856
1627.46	16.4879
1628.5	15.0488
1629.53	14.2918
1630.41	16.2516
1631.46	19.2159
1632.5	18.2443
1633.55	19.2176
1634.59	18.2349
1635.64	16.2585
1636.68	17.2341
1637.73	18.2125
1638.77	14.2731
1639.82	18.2094
1640.86	16.2474
1641.91	19.196
1642.95	16.2409
1644	17.2173
1645.04	13.2843
1646.08	16.2332
1647.12	15.244
1648.17	24.1009
1649.21	15.2582
1650.25	19.2061
1651.29	17.2454
1652.34	18.2289
1653.38	18.2287
1654.42	20.2056
1655.46	14.3072
1656.5	18.2619
1657.54	19.2431
1658.59	18.2472
1659.63	17.2513
1660.67	13.3163
1661.71	16.2745
1662.75	18.2835
1663.79	17.275
1664.83	17.2858
1665.87	15.3248
1666.91	18.2614
1667.95	16.2775
1668.99	17.2853
1670.02	14.324
1671.06	16.308
1672.1	14.3337
1673.14	16.3121
1674.18	18.2982
1675.22	17.3188
1676.25	19.2998
1677.29	18.3066
1678.33	16.3153
1679.37	17.2968
1680.4	16.3024
1681.44	13.3368
1682.48	16.3003
1683.51	15.3112
1684.55	17.2811
1685.58	17.2808
1686.62	16.3004
1687.66	16.2949
1688.69	14.3113
1689.73	16.2726
1690.76	17.2678
1691.8	16.2846
1692.83	14.3004
1693.87	15.2721
1694.9	18.2246
1695.94	14.2893
1696.97	14.2843
1698	16.2404
1699.04	17.2193
1700.07	16.233
1701.1	15.2451
1702.14	16.2165
1703.17	13.2641
1704.2	14.2486
1705.24	15.23
1706.27	14.2371
1707.3	16.1844
1708.33	16.1628
1709.36	15.1736
1710.4	14.1976
1711.43	15.1823
1712.46	14.1888
1713.49	13.1905
1714.52	17.0922
1715.55	16.1215
1716.58	17.0842
1717.61	17.0546
1718.64	15.0912
1719.67	15.0925
1720.7	15.082
1721.73	14.0966
1722.76	16.0259
1723.79	14.0786
1724.82	13.0946
1725.85	15.0205
1726.88	15.9806
1727.9	15.0102
1728.93	14.9573
1729.96	14.9656
1730.99	14.0137
1732.02	15.9432
1733.04	13.9982
1734.07	14.9424
1735.1	15.8871
1736.13	15.8789
1737.15	14.9085
1738.18	12.9749
1739.21	15.8388
1740.23	15.815
1741.26	17.7166
1742.28	12.9236
1743.31	13.8766
1744.33	12.9127
1745.36	15.7812
1746.38	17.6768
1747.41	16.7055
1748.44	14.7968
1749.46	17.6717
1750.48	14.8167
1751.51	14.8103
1752.53	15.751
1753.56	15.7393
1754.58	15.7284
1755.6	13.8126
1756.63	13.7963
1757.65	15.6959
1758.67	15.7009
1759.69	13.797
1760.72	16.6432
1761.74	14.7334
1762.76	14.7376
1763.78	14.7415
1764.81	15.7064
1765.83	16.6611
1766.85	14.7539
1767.87	12.8434
1768.89	17.5783
1769.91	18.5246
1770.93	14.734
1771.95	17.5969
1772.97	16.6554
1773.99	13.8048
1775.01	17.6237
1776.03	17.6367
1777.05	16.675
1778.07	14.7584
1779.09	12.8433
1780.11	16.6568
1781.13	19.5176
1782.15	17.6254
1783.17	18.5879
1784.18	15.7401
1785.2	13.8335
1786.22	14.7877
1787.24	17.6719
1788.25	22.4969
1789.27	19.6457
1790.29	18.6939
1791.31	18.6753
1792.32	22.5094
1793.34	15.809
1794.36	19.6399
1795.37	14.8789
1796.39	17.7726
1797.4	19.7073
1798.42	17.7889
1799.44	15.8565
1800.45	17.7702
1801.47	18.731
1802.48	17.7801
1803.5	14.9066
1804.51	17.8031
1805.53	21.6734
1806.54	16.866
1807.55	16.867
1808.57	17.8333
1809.58	19.7648
1810.59	17.8353
1811.61	17.8354
1812.62	15.9161
1813.63	19.7871
1814.65	17.8757
1815.66	20.7809
1816.67	17.8836
1817.68	18.8345
1818.7	16.9119
1819.71	18.8531
1820.72	20.7968
1821.73	18.8731
1822.74	17.9099
1823.75	17.9061
1824.76	19.8497
1825.77	18.8846
1826.78	17.9196
1827.8	18.8934
1828.81	18.8864
1829.82	18.8812
1830.83	19.85
1831.83	18.892
1832.84	20.8395
1833.85	16.9661
1834.86	15.9668
1835.87	18.8737
1836.88	20.8313
1837.89	15.9413
1838.9	20.8316
1839.91	18.8789
1840.91	20.7709
1841.92	15.9165
1842.93	20.7397
1843.94	13.9863
1844.94	16.8798
1845.95	18.8383
1846.96	17.8114
1847.96	20.7122
1848.97	15.882
1849.98	18.7457
1850.98	16.8079
1851.99	19.6847
1852.99	21.6027
1854	18.7034
1855.01	18.6867
1856.01	17.7194
1857.02	16.7587
1858.02	17.7052
1859.02	18.6441
1860.03	19.6009
1861.03	17.7018
1862.04	19.6128
1863.04	18.6387
1864.04	18.6249
1865.05	17.6522
1866.05	15.7185
1867.05	18.5469
1868.06	18.5373
1869.06	17.5868
1870.06	15.6822
1871.07	16.6299
1872.07	16.6213
1873.07	17.5618
1874.07	16.6009
1875.07	20.3731
1876.08	18.4492
1877.08	18.4162
1878.08	19.3991
1879.08	21.3157
1880.08	16.5692
1881.08	20.3418
1882.08	19.3532
1883.08	18.4792
1884.08	15.5568
1885.08	20.2865
1886.08	19.3611
1887.08	16.5107
1888.08	17.4329
1889.08	18.3567
1890.08	17.4217
1891.08	20.2484
1892.07	18.3609
1893.07	17.3944
1894.07	18.3223
1895.07	21.1407
1896.07	18.3324
1897.07	17.4019
1898.06	16.4578
1899.06	17.3839
1900.06	19.2566
1901.05	16.4484
1902.05	16.4621
1903.05	21.158
1904.04	17.3933
1905.04	17.391
1906.04	17.3762
1907.03	20.1902
1908.03	16.4414
1909.02	17.3916
1910.02	15.5317
1911.01	14.6006
1912.01	14.5987
1913	15.5416
1914	18.3867
1914.99	17.457
1915.99	16.5111
1916.98	13.6709
1917.98	16.5018
1918.97	18.4096
1919.96	18.426
1920.96	14.655
1921.95	16.5508
1922.94	18.4335
1923.94	15.5895
1924.93	13.7021
1925.92	14.6633
1926.91	14.6768
1927.9	15.6313
1928.9	16.5879
1929.89	16.6068
1930.88	12.8176
1931.87	17.5559
1932.86	14.7031
1933.85	15.6804
1934.84	16.6807
1935.83	12.8662
1936.83	17.6193
1937.82	16.6547
1938.81	13.8095
1939.8	13.8169
1940.79	14.7919
1941.78	14.7769
1942.76	13.844
1943.75	13.8397
1944.74	10.9862
1945.73	15.7768
1946.72	14.8241
1947.71	14.8214
1948.7	17.6943
1949.69	13.8828
1950.67	14.8647
1951.66	14.8828
1952.65	15.8511
1953.64	13.9111
1954.62	12.9326
1955.61	14.8647
1956.6	14.8845
1957.58	16.8177
1958.57	14.8964
1959.56	13.929
1960.54	14.8798
1961.53	14.8754
1962.51	14.8782
1963.5	13.9213
1964.48	16.8035
1965.47	14.8859
1966.46	12.9754
1967.44	14.9005
1968.43	12.9767
1969.41	15.8429
1970.39	13.9124
1971.38	11.9891
1972.36	12.951
1973.35	14.8594
1974.33	13.8984
1975.31	16.7817
1976.3	14.8684
1977.28	13.9057
1978.26	15.8153
1979.24	13.8986
1980.23	16.7695
1981.21	16.7619
1982.19	13.8839
1983.17	12.9149
1984.16	10.9979
1985.14	14.805
1986.12	13.823
1987.1	15.6119
1988.08	13.7249
1989.06	13.853
1990.04	14.158
1991.02	14.3208
1992	15.1341
1992.98	12.6757
1993.96	14.4108
1994.94	14.1233
1995.92	13.7338
1996.9	12.4427
1997.88	14.2571
1998.86	12.8655
1999.84	11.8759
2000.82	14.9524
2001.8	12.6172
2002.78	12.947
2003.76	13.4557
2004.73	13.7059
2005.71	13.8108
2006.69	13.2765
2007.67	14.6398
2008.64	13.9936
2009.62	12.491
2010.52	14.5986
2011.51	12.7132
2012.5	14.5905
2013.48	11.7485
2014.47	11.7306
2015.46	16.431
2016.45	13.6284
2017.44	11.7393
2018.43	12.6588
2019.41	12.6452
2020.4	14.5162
2021.39	13.5808
2022.38	13.5714
2023.36	14.4938
2024.35	14.4778
2025.34	12.5943
2026.32	16.3404
2027.31	16.3718
2028.3	16.353
2029.28	16.358
2030.27	15.3782
2031.25	15.3954
2032.24	13.5439
2033.23	13.5591
2034.21	14.4623
2035.2	14.4805
2036.18	16.3585
2037.17	15.4275
2038.15	11.6813
2039.13	11.6736
2040.12	13.527
2041.1	13.5178
2042.09	14.442
2043.07	12.583
2044.05	13.5273
2045.04	12.5926
2046.02	12.6205
2047	12.5969
2047.99	15.3826
2048.97	12.5944
2049.95	11.676
2050.93	12.6088
2051.92	13.5416
2052.9	14.4837
2053.88	13.5637
2054.86	13.5619
2055.84	14.4903
2056.82	12.6193
2057.8	14.4968
2058.78	14.5091
2059.77	13.5732
2060.75	9.82931
2061.73	13.5767
2062.71	14.5208
2063.69	12.6537
2064.67	13.5995
2065.65	10.7971
2066.63	10.8015
2067.61	11.7473
2068.58	15.5116
2069.56	12.6782
2070.54	14.5803
2071.52	13.6557
2072.5	10.8274
2073.48	12.711
2074.45	12.7196
2075.43	12.7415
2076.41	14.6309
2077.39	10.8446
2078.37	14.6245
2079.34	14.6405
2080.32	11.8124
2081.3	11.8101
2082.27	10.8675
2083.25	12.7566
2084.23	14.647
2085.2	14.6478
2086.18	12.7695
2087.15	12.7759
2088.13	11.8309
2089.11	14.6771
2090.08	14.6844
2091.06	15.6388
2092.03	11.8623
2093	14.7263
2093.98	12.8352
2094.95	16.6332
2095.93	13.775
2096.9	11.87
2097.88	11.8656
2098.85	13.7612
2099.82	15.6593
2100.8	12.8202
2101.77	14.722
2102.74	14.7157
2103.72	13.7642
2104.69	13.7719
2105.66	15.6829
2106.63	11.8846
2107.6	16.6292
2108.58	15.6662
2109.55	12.8247
2110.52	14.7248
2111.49	13.7705
2112.46	14.7226
2113.43	13.7822
2114.4	14.7311
2115.38	11.8776
2116.35	18.5185
2117.32	15.6672
2118.29	13.7558
2119.26	15.6399
2120.23	15.6348
2121.2	12.8019
2122.17	11.8629
2123.14	12.8167
2124.1	12.8085
2125.07	11.84
2126.04	15.6121
2127.01	15.601
2127.98	14.6515
2128.95	14.6499
2129.92	15.5917
2130.88	12.7512
2131.85	14.6328
2132.82	12.7387
2133.79	11.7969
2134.75	13.6836
2135.72	13.6747
2136.69	12.7274
2137.65	15.5598
2138.62	16.5038
2139.59	18.3743
2140.55	15.5404
2141.52	15.5326
2142.49	13.654
2143.45	12.6859
2144.42	15.5217
2145.38	15.5137
2146.35	15.5086
2147.31	16.4403
2148.28	15.4936
2149.24	18.2919
2150.21	15.4654
2151.17	17.3463
2152.14	15.4742
2153.1	13.5908
2154.06	16.3883
2155.03	16.3622
2155.99	17.2827
2156.95	12.612
2157.92	19.1618
2158.88	17.2877
2159.84	17.2727
2160.8	17.2628
2161.77	15.3932
2162.73	16.3222
2163.69	17.2473
2164.65	16.3055
2165.61	19.1034
2166.58	19.0922
2167.54	19.0694
2168.5	19.989
2169.46	19.0784
2170.42	19.0902
2171.38	18.1331
2172.34	17.1887
2173.3	17.1892
2174.26	18.1236
2175.22	17.1916
2176.18	19.0439
2177.14	18.1148
2178.1	18.1084
2179.06	18.1057
2180.02	18.1053
2180.98	19.0297
2181.94	19.9497
2182.9	18.0827
2183.85	22.7012
2184.81	20.8518
2185.77	19.9364
2186.73	18.1016
2187.69	18.1097
2188.64	18.0948
2189.6	16.2226
2190.56	19.0067
2191.52	18.0842
2192.47	20.8758
2193.43	19.0398
2194.39	19.0573
2195.34	19.9752
2196.3	19.9513
2197.26	18.0867
2198.21	19.9548
2199.17	16.2634
2200.12	20.0178
2201.08	20.9596
2202.03	22.7342
2202.99	22.7796
2203.94	20.0473
2204.9	20.0022
2205.85	19.0641
2206.81	22.7813
2207.76	22.8007
2208.71	20.0218
2209.67	18.1611
2210.62	17.2404
2211.57	20.9844
2212.53	21.9185
2213.48	17.2489
2214.43	18.2019
2215.39	18.2063
2216.34	19.1388
2217.29	18.2064
2218.24	20.0767
2219.2	19.1552
2220.15	19.1586
2221.1	21.0143
2222.05	19.136
2223	17.2789
2223.95	19.1691
2224.91	19.1876
2225.86	22.0168
2226.81	17.3454
2227.76	22.0356
2228.71	21.0931
2229.66	21.1081
2230.61	23.0032
2231.56	19.2649
2232.51	21.1614
2233.46	19.2943
2234.41	21.1739
2235.36	21.1581
2236.31	19.2817
2237.25	17.4167
2238.2	18.3833
2239.15	18.3956
2240.1	18.3817
2241.05	20.2868
2242	19.3503
2242.94	24.0697
2243.89	20.2901
2244.84	20.3157
2245.79	21.2793
2246.73	19.3995
2247.68	19.4015
2248.63	19.3974
2249.57	18.4562
2250.52	19.3882
2251.47	15.6002
2252.41	20.3443
2253.36	18.4794
2254.3	12.8006
2255.25	13.7491
2256.2	20.399
2257.14	20.4129
2258.09	20.4191
2259.03	16.6288
2259.98	22.3398
2260.92	20.4552
2261.86	15.703
2262.81	19.5269
2263.75	22.4175
2264.7	19.5776
2265.64	19.5815
2266.58	15.7464
2267.53	19.5506
2268.47	17.6427
2269.41	17.6622
2270.36	16.7245
2271.3	21.5179
2272.24	18.6562
2273.18	21.5317
2274.13	19.6224
2275.07	17.7129
2276.01	17.7242
2276.95	18.7013
2277.89	16.8064
2278.84	20.6481
2279.78	13.9091
2280.72	18.6932
2281.66	17.7344
2282.6	18.7088
2283.54	17.778
2284.48	17.798
2285.42	17.8005
2286.36	18.7601
2287.3	17.8186
2288.24	14.928
2289.18	14.9103
2290.12	16.8235
2291.06	15.8749
2292	17.8134
2292.93	15.9006
2293.87	14.937
2294.81	16.8542
2295.75	18.7687
2296.69	12.991
2297.63	16.8582
2298.56	15.9085
2299.5	14.9519
2300.44	15.9213
2301.38	15.9271
2302.31	13.9945
2303.25	15.924
2304.19	15.9331
2305.12	16.9077
2306.06	15.948
2307	16.913
2307.93	12.0764
2308.87	14.0142
2309.8	14.0269
2310.74	13.0555
2311.68	13.9971
2312.61	13.9908
2313.55	14.0067
2314.48	15.9602
2315.41	14.0183
2316.35	17.8634
2317.28	14.9723
2318.22	16.8968
2319.15	16.8872
2320.09	15.9218
2321.02	18.8284
2321.95	15.9494
2322.89	16.9194
2323.82	18.8557
2324.75	27.5324
2325.69	28.4749
2326.62	44.8457
2327.55	119.029
2328.48	260.682
2329.42	65.0115
2330.35	28.4096
2331.28	17.8227
2332.21	16.8533
2333.14	15.8823
2334.07	15.8721
2335.01	14.9051
2335.94	14.9049
2336.87	15.8636
2337.8	13.9376
2338.73	12.9764
2339.66	15.8565
2340.59	21.6045
2341.52	15.8248
2342.45	19.6516
2343.38	12.9402
2344.31	14.8589
2345.24	14.8503
2346.17	12.9277
2347.1	16.7544
2348.02	14.8441
2348.95	13.8772
2349.88	14.8009
2350.81	14.8233
2351.74	11.9308
2352.67	10.9534
2353.59	13.8107
2354.52	10.9582
2355.45	15.7171
2356.38	11.8909
2357.3	12.8334
2358.23	13.7767
2359.16	12.8223
2359.85	12.8144