File: Data/3-Raman/raw/bu20-b-ff4-fi02-v_150 (500nm)_633nm_edge_100%_x100_vis_lwd_h30um_60sx4_01.txt
#Acq. time (s)=	60
#Accumulations=	4
#Range (cm-¹)=	100...4000
#Windows=	1
#Auto scanning=	Off
#Autofocus=	Off
#Macrospot=	Off
#AutoExposure=	Off
#Spike filter=	Multiple accum.
#Delay time (s)=	2
#Binning=	1
#Readout mode=	Signal
#DeNoise=	Off
#ICS correction=	On
#Dark correction=	Off
#Inst. Process=	Off
#Detector Gain=	Best Dynamic
#Detector ADC=	50 kHz HS
#Detector temperature (°C)=	-60.09
#Instrument=	LabRAM HR Evol
#Detector=	SIN-EM FIVIS
#Objective=	x100_VIS_LWD
#Grating=	150 (500nm)
#ND Filter=	100%
#Laser=	633nm_Edge
#Hole=	30.0125
#Temperature=	40
#Range=	Visible
#StageXY=	75x50mm Scan+
#StageZ=	Z motor
#X (µm)=	0
#Y (µm)=	0
#Z (µm)=	470.9
#Full time(mm:ss)=	4:05
#Project=	21_08_11
#Sample=	BU20
#Site=
#Title=	BU20-B-FF4-FI01-L_150 (500nm)_633nm_Edge_100%_x100_VIS_LWD_H30um_60sX4
#Remark=
#Date=	13.08.2021 11:50
#Acquired=	13.08.2021 11:50:50
100.12	692.454
106.638	498.728
113.152	394.837
119.66	309.14
126.162	246.875
132.659	205.546
139.151	173.037
145.637	157.434
152.118	135.457
158.594	119.248
165.064	103.986
171.529	98.9051
177.989	83.5464
184.441	79.9635
190.89	76.0199
197.334	76.225
203.772	71.4211
210.205	71.0772
216.631	68.5072
223.054	76.7338
229.471	77.9056
235.881	107.932
242.288	140.45
248.689	105.904
255.083	88.1149
261.474	89.0234
267.858	92.7895
274.238	98.788
280.613	107.63
286.982	154.978
293.346	142.543
299.704	102.363
306.058	81.1493
312.406	78.8721
318.749	75.9764
325.086	91.677
331.418	143.853
337.746	117.415
344.068	86.9
350.384	75.2356
356.697	77.3729
363.003	86.3911
369.304	95.6998
375.601	97.1623
381.892	82.3713
388.177	68.3021
394.457	58.6758
400.733	59.1149
407.004	63.6384
413.269	61.8684
419.529	62.8996
425.784	67.6437
432.034	80.7135
438.279	100.298
444.518	111.006
450.753	112.241
456.982	104.16
463.207	99.3134
469.426	88.3531
475.64	74.0525
481.85	61.3361
488.054	70.349
494.253	57.3184
500.447	54.5344
506.635	62.9568
512.819	62.6888
518.999	60.8862
525.173	60.3685
531.342	58.6327
537.505	54.7193
543.664	59.2321
549.819	57.7173
555.966	58.0793
562.111	61.8055
568.25	58.2384
574.383	55.257
580.513	61.316
586.636	59.9125
592.756	65.4088
598.871	75.9265
604.979	117.062
611.084	101.074
617.183	90.7197
623.277	89.7454
629.367	86.2332
635.451	94.1714
641.532	98.1857
647.606	85.4678
653.675	74.6495
659.741	95.6766
665.801	97.9184
671.856	87.1713
677.907	66.6781
683.952	64.2151
689.992	58.705
696.028	47.9133
702.059	50.8316
708.086	52.8006
714.107	52.797
720.123	51.198
726.135	51.1573
732.141	47.9436
738.143	52.2216
744.14	47.4656
750.133	50.8256
756.12	48.6231
762.103	48.6825
768.081	47.5647
774.054	51.7691
780.023	46.2473
785.987	46.6301
791.946	49.5054
797.9	47.6317
803.848	45.0861
809.793	44.7206
815.733	44.9503
821.669	43.2841
827.6	46.6048
833.525	51.2255
839.446	45.0268
845.363	49.7935
851.273	52.4015
857.181	50.9644
863.083	51.4188
868.98	50.9296
874.874	50.3912
880.761	53.2838
886.645	51.0861
892.523	53.9123
898.398	54.1677
904.267	47.7389
910.133	52.0156
915.992	51.8828
921.849	49.9406
927.699	50.2569
933.545	55.6524
939.387	56.1347
945.224	67.3883
951.056	74.9502
956.884	86.3513
962.708	91.0597
968.526	99.5563
974.34	107.673
980.149	115.947
985.955	154.434
991.755	200.404
997.551	210.234
1003.34	168.634
1009.13	141.226
1014.91	141.363
1020.69	147.235
1026.46	175.622
1032.23	193.342
1037.99	145.165
1043.75	102.813
1049.51	89.8773
1055.26	80.36
1061	73.9829
1066.74	66.8575
1072.48	71.0461
1078.21	75.8484
1083.94	87.0859
1089.67	97.0347
1095.38	86.9723
1101.1	105.941
1106.81	102.753
1112.51	79.5896
1118.22	62.689
1123.91	60.2459
1129.6	58.7619
1135.29	60.8684
1140.98	64.2929
1146.65	70.9551
1152.33	69.7358
1158	88.7672
1163.66	69.3044
1169.32	54.7853
1174.98	52.3923
1180.63	52.2921
1186.28	50.9444
1191.93	47.0448
1197.56	46.4538
1203.2	46.2538
1208.83	43.1394
1214.46	45.6156
1220.08	46.8184
1225.69	44.718
1231.31	46.2569
1236.92	41.7375
1242.52	46.8901
1248.12	51.3344
1253.72	56.0779
1259.31	57.7269
1264.89	89.5772
1270.48	61.5876
1276.05	73.5158
1281.63	287.891
1287.2	240.691
1292.76	72.4742
1298.33	66.1229
1303.88	52.4864
1309.43	49.238
1314.98	50.7285
1320.53	46.1959
1326.07	51.096
1331.6	48.5943
1337.13	51.8239
1342.66	50.2662
1348.18	45.5885
1353.7	49.773
1359.22	53.5961
1364.73	59.0987
1370.23	71.7562
1375.73	69.3329
1381.23	78.5442
1386.72	707.928
1392.21	173.909
1397.7	63.1688
1403.18	63.5976
1408.65	115.214
1414.13	60.0438
1419.59	52.9377
1425.06	47.884
1430.52	46.6217
1435.97	40.4847
1441.42	42.323
1446.87	41.0326
1452.31	36.5465
1457.75	39.0234
1463.19	35.5276
1468.62	33.7684
1474.04	34.8109
1479.46	36.5705
1484.88	34.8395
1490.3	34.5253
1495.7	36.6875
1501.11	36.0556
1506.51	35.0802
1511.91	31.2872
1517.3	32.8036
1522.69	36.1161
1528.08	34.4568
1533.46	36.7382
1538.83	30.3806
1544.21	33.6948
1549.58	32.6337
1554.94	34.7703
1560.3	35.0874
1565.66	34.6937
1571.01	35.0157
1576.36	34.9849
1581.7	35.3436
1587.04	32.8411
1592.38	32.8625
1597.71	32.1825
1603.04	33.3144
1608.37	36.2773
1613.68	34.5801
1619	32.5298
1624.31	35.5734
1629.62	34.6085
1634.93	29.9464
1640.23	36.2561
1645.52	32.9954
1650.81	35.9905
1656.1	33.0669
1661.39	35.6666
1666.67	33.8248
1671.94	32.3474
1677.22	35.2996
1682.48	30.1146
1687.75	29.3486
1693.01	29.3327
1698.26	32.2989
1703.52	31.313
1708.77	30.3356
1714.01	35.8638
1719.25	32.9826
1724.49	33.0335
1729.72	33.8506
1734.95	32.7955
1740.18	31.7319
1745.4	35.1787
1750.61	30.7085
1755.83	32.2513
1761.04	34.53
1766.24	27.748
1771.44	33.0527
1776.64	30.055
1781.84	28.9613
1787.02	32.4242
1792.21	32.4965
1797.39	32.5728
1802.57	30.3703
1807.75	32.7498
1812.92	33.2041
1818.08	29.0453
1823.25	32.9636
1828.41	31.4933
1833.56	30.0197
1838.71	32.8089
1843.86	31.3133
1849	32.5337
1854.14	29.8452
1859.28	29.8941
1864.41	29.1694
1869.54	32.7613
1874.67	32.8083
1879.79	31.2756
1884.9	27.3711
1890.02	33.2991
1895.13	29.3597
1900.23	29.7688
1905.34	29.0316
1910.43	32.266
1915.53	30.7842
1920.62	31.6311
1925.71	31.291
1930.79	31.3519
1935.87	29.4077
1940.94	28.2489
1946.02	32.2925
1951.08	29.5084
1956.15	30.726
1961.21	36.358
1966.27	25.5122
1971.32	34.7374
1976.37	31.5069
1981.42	33.0935
1986.46	30.6711
1991.5	28.255
1996.53	28.2492
2001.56	31.457
2006.59	30.6689
2011.61	29.4882
2016.63	31.9212
2021.65	28.3236
2026.66	28.7587
2031.67	27.9985
2036.68	30.8777
2041.68	27.299
2046.68	29.789
2051.67	29.0422
2056.66	26.6488
2061.65	28.747
2066.63	29.2213
2071.61	30.5117
2076.59	30.1646
2081.56	31.0438
2086.53	28.6203
2091.49	31.9612
2096.46	31.2031
2101.41	27.9623
2106.37	32.6034
2111.32	31.4465
2116.26	32.7977
2121.21	32.0609
2126.15	30.0539
2131.09	28.8719
2136.02	26.83
2140.95	29.8541
2145.87	28.6425
2150.79	31.2376
2155.71	27.8716
2160.63	28.3224
2165.54	30.8929
2170.45	30.4766
2175.35	26.2344
2180.25	30.5114
2185.15	30.0811
2190.04	28.8055
2194.93	32.2368
2199.82	27.5698
2204.7	31.4649
2209.58	30.6671
2214.46	30.7343
2219.33	31.6729
2224.2	27.0015
2229.06	30.5353
2233.92	25.8365
2238.78	28.949
2243.64	30.7678
2248.49	26.034
2253.34	30.0461
2258.18	30.123
2263.02	28.4338
2267.86	25.8399
2272.69	28.5348
2277.52	30.3413
2282.35	29.4788
2287.17	31.2611
2291.99	29.4955
2296.81	30.3921
2301.62	29.9727
2306.43	26.012
2311.24	27.844
2316.04	27.0143
2320.84	29.3217
2325.63	30.7442
2330.43	37.1296
2335.21	27.7629
2340	32.3789
2344.78	27.4914
2349.56	28.504
2354.33	31.3448
2359.11	30.9714
2363.87	25.5145
2368.64	28.7954
2373.4	27.4693
2378.16	26.1364
2382.91	29.8794
2387.66	28.5156
2392.41	27.6019
2397.16	28.0697
2401.9	28.9979
2406.64	26.6721
2411.37	28.556
2416.1	29.1125
2420.83	26.4477
2425.55	28.8299
2430.27	29.8411
2434.99	25.2125
2439.7	29.0712
2444.41	26.787
2449.12	28.2943
2453.83	27.901
2458.53	25.5908
2463.22	29.0232
2467.92	31.5086
2472.61	30.1422
2477.3	29.7378
2481.98	28.844
2486.66	31.3367
2491.34	26.5327
2496.01	38.2973
2500.68	27.618
2505.35	29.6261
2510.01	25.2582
2514.67	30.6932
2519.33	33.6857
2523.99	29.8001
2528.64	29.8449
2533.28	30.3881
2537.93	29.4564
2542.57	30.5088
2547.21	29.0843
2551.84	30.1448
2556.47	28.7074
2561.1	28.2637
2565.73	29.3331
2570.35	28.9059
2574.97	28.9807
2579.58	28.0357
2584.19	30.6116
2588.8	30.1414
2593.41	26.6161
2598.01	23.611
2602.61	30.7617
2607.2	29.2707
2611.8	30.8255
2616.38	27.7903
2620.97	23.7323
2625.55	28.3548
2630.13	28.9073
2634.71	25.3826
2639.28	28.032
2643.85	29.152
2648.42	26.6579
2652.98	27.7797
2657.54	27.3132
2662.1	29.4415
2666.65	28.9555
2671.2	30.0521
2675.75	24.8962
2680.29	27.6521
2684.84	27.7779
2689.37	28.9659
2693.91	29.0753
2698.44	29.6559
2702.97	26.5069
2707.49	27.0938
2712.02	27.1404
2716.53	23.9687
2721.05	29.4107
2725.56	26.2135
2730.07	30.5739
2734.58	25.1832
2739.08	25.7409
2743.58	34.4523
2748.08	30.1576
2752.57	30.7857
2757.06	28.125
2761.55	26.5256
2766.04	27.6715
2770.52	29.9192
2775	25.5842
2779.47	27.8608
2783.94	32.9378
2788.41	29.7165
2792.88	27.5822
2797.34	28.219
2801.8	26.6094
2806.26	31.1573
2810.71	27.8419
2815.16	26.7598
2819.61	25.1076
2824.05	26.8444
2828.49	29.7193
2832.93	34.2993
2837.37	28.6698
2841.8	28.1427
2846.23	31.0374
2850.65	29.955
2855.08	37.4622
2859.5	28.3816
2863.91	27.8873
2868.33	25.6682
2872.74	27.4829
2877.15	27.5694
2881.55	33.4863
2885.95	28.3472
2890.35	26.6853
2894.75	30.8927
2899.14	30.4188
2903.53	38.8187
2907.91	31.8027
2912.3	26.521
2916.68	28.371
2921.05	29.6385
2925.43	27.9158
2929.8	29.2015
2934.17	34.717
2938.53	29.3462
2942.9	32.432
2947.26	30.0523
2951.61	30.7041
2955.97	25.8769
2960.32	32.0105
2964.66	29.0068
2969.01	29.6701
2973.35	30.3384
2977.69	27.3252
2982.03	30.4559
2986.36	29.2965
2990.69	29.9936
2995.01	28.8379
2999.34	31.4148
3003.66	25.9013
3007.98	30.9992
3012.29	26.0694
3016.6	26.7901
3020.91	33.2147
3025.22	30.7829
3029.52	26.4098
3033.82	28.3839
3038.12	30.3503
3042.41	29.777
3046.71	29.1887
3051	30.5237
3055.28	33.1526
3059.56	26.1186
3063.84	30.0406
3068.12	26.8576
3072.39	26.9046
3076.67	29.5523
3080.93	29.6075
3085.2	29.6685
3089.46	31.0501
3093.72	30.4867
3097.98	31.2448
3102.23	32.0085
3106.48	36.1004
3110.73	32.2503
3114.98	33.0445
3119.22	33.175
3123.46	33.3162
3127.7	28.7333
3131.93	30.9112
3136.16	35.1574
3140.39	34.6334
3144.61	32.7135
3148.84	31.4597
3153.06	35.0315
3157.27	29.57
3161.49	37.3337
3165.7	36.0411
3169.91	38.939
3174.11	34.8268
3178.31	34.8925
3182.51	37.7683
3186.71	35.6957
3190.9	34.3198
3195.1	37.9228
3199.28	36.5999
3203.47	38.872
3207.65	38.3068
3211.83	41.3368
3216.01	38.628
3220.18	38.0608
3224.36	38.213
3228.52	36.1746
3232.69	39.2502
3236.85	34.9693
3241.01	35.1068
3245.17	37.4877
3249.33	33.158
3253.48	39.23
3257.63	33.3273
3261.77	37.195
3265.92	28.2877
3270.06	36.7516
3274.2	36.143
3278.33	38.5011
3282.47	33.2315
3286.59	37.8917
3290.72	33.363
3294.85	34.1904
3298.97	37.33
3303.09	33.5514
3307.2	35.9366
3311.32	35.2279
3315.43	32.9644
3319.54	34.5819
3323.64	38.5574
3327.74	28.5047
3331.84	35.6427
3335.94	31.84
3340.04	34.3039
3344.13	35.9596
3348.22	32.0633
3352.3	50.3652
3356.39	37.7499
3360.47	31.4621
3364.54	34.7258
3368.62	37.1987
3372.69	36.4727
3376.76	36.5315
3380.83	35.7789
3384.89	35.8254
3388.96	36.6741
3393.02	39.9398
3397.07	41.6118
3401.13	34.3881
3405.18	37.6596
3409.23	39.3178
3413.27	34.4792
3417.31	42.6264
3421.36	37.7825
3425.39	45.9397
3429.43	35.4067
3433.46	40.3428
3437.49	37.1419
3441.52	30.6665
3445.54	36.4692
3449.56	33.2756
3453.58	36.659
3457.6	33.4709
3461.61	37.7343
3465.63	31.2098
3469.63	34.6581
3473.64	35.5904
3477.64	34.8595
3481.64	34.1219
3485.64	32.5304
3489.64	28.3838
3493.63	31.8576
3497.62	33.6338
3501.61	37.9681
3505.59	32.9036
3509.58	39.7842
3513.56	32.1052
3517.53	26.9845
3521.51	38.9996
3525.48	30.4491
3529.45	36.4744
3533.42	32.2279
3537.38	34.0177
3541.34	35.8218
3545.3	35.8857
3549.26	33.3413
3553.21	29.8922
3557.16	33.3875
3561.11	40.375
3565.06	36.0898
3569	36.1695
3572.94	33.622
3576.88	40.7043
3580.82	33.795
3584.75	46.2221
3588.68	44.5925
3592.61	45.6077
3596.54	50.1812
3600.46	41.4083
3604.38	34.3709
3608.3	37.132
3612.21	31.8275
3616.13	36.3837
3620.04	32.8495
3623.94	35.5825
3627.85	34.7041
3631.75	29.3071
3635.65	33.8343
3639.55	28.4531
3643.44	29.4109
3647.34	26.7562
3651.23	33.1258
3655.12	33.1597
3659	34.0989
3662.88	29.5744
3666.76	29.6026
3670.64	26.8973
3674.52	32.4071
3678.39	34.2925
3682.26	27.9521
3686.13	33.5403
3689.99	30.87
3693.85	30.9546
3697.71	32.8871
3701.57	32.0476
3705.43	27.4737
3709.28	33.1542
3713.13	33.2446
3716.98	38.9536
3720.82	33.3908
3724.66	30.6261
3728.5	28.7908
3732.34	34.5188
3736.18	31.7422
3740.01	30.8497
3743.84	29.9488
3747.67	27.1362
3751.49	35.7477
3755.32	31.0088
3759.14	35.8013
3762.96	33.9081
3766.77	28.1893
3770.58	34.9044
3774.4	33.9782
3778.2	32.0944
3782.01	44.6072
3785.81	36.0306
3789.61	26.4592
3793.41	32.2803
3797.21	46.8244
3801	31.4415
3804.79	29.5712
3808.58	34.4991
3812.37	35.5462
3816.15	35.6174
3819.93	31.776
3823.71	40.6473
3827.49	31.8814
3831.26	30.9569
3835.04	31.9993
3838.8	26.1348
3842.57	32.1163
3846.34	38.0909
3850.1	32.1751
3853.86	39.1254
3857.62	34.1843
3861.37	36.17
3865.12	35.2141
3868.87	35.3
3872.62	33.3484
3876.37	28.3885
3880.11	27.4095
3883.85	35.4096
3887.59	35.4428
3891.33	31.4839
3895.06	34.5434
3898.79	37.6053
3902.52	37.6644
3906.25	32.6894
3909.97	30.72
3913.69	34.8083
3917.41	37.9088
3921.13	37.9981
3924.84	33.0101
3928.56	34.099
3932.27	32.1244
3935.97	35.2356
3939.68	30.1754
3943.38	30.2369
3947.08	36.4562
3950.78	31.3735
3954.48	32.4466
3958.17	31.4539
3961.86	33.543
3965.55	31.5
3969.24	31.5088
3972.92	31.5188
3976.6	33.597
3980.29	33.6002
3983.96	34.6302
3987.64	38.7625
3991.31	35.6671
3994.98	38.7895
3998.65	32.6133