File: Data/3-Raman/raw/bu20-b-ff4-fi03-v_150 (500nm)_633nm_edge_100%_x100_vis_lwd_h30um_60sx4_01.txt
#Acq. time (s)=	60
#Accumulations=	4
#Range (cm-¹)=	100...4000
#Windows=	1
#Auto scanning=	Off
#Autofocus=	Off
#Macrospot=	Off
#AutoExposure=	Off
#Spike filter=	Multiple accum.
#Delay time (s)=	2
#Binning=	1
#Readout mode=	Signal
#DeNoise=	Off
#ICS correction=	On
#Dark correction=	Off
#Inst. Process=	Off
#Detector Gain=	Best Dynamic
#Detector ADC=	50 kHz HS
#Detector temperature (°C)=	-60.09
#Instrument=	LabRAM HR Evol
#Detector=	SIN-EM FIVIS
#Objective=	x100_VIS_LWD
#Grating=	150 (500nm)
#ND Filter=	100%
#Laser=	633nm_Edge
#Hole=	30.0125
#Temperature=	40
#Range=	Visible
#StageXY=	75x50mm Scan+
#StageZ=	Z motor
#X (µm)=	0
#Y (µm)=	0
#Z (µm)=	450.4
#Full time(mm:ss)=	4:05
#Project=	21_08_11
#Sample=	BU20
#Site=
#Title=	BU20-B-FF4-FI03-V_150 (500nm)_633nm_Edge_100%_x100_VIS_LWD_H30um_60sX4
#Remark=
#Date=	13.08.2021 14:15
#Acquired=	13.08.2021 14:15:56
100.12	291.184
106.638	238.633
113.152	209.593
119.66	187.141
126.162	157.943
132.659	153.561
139.151	143.054
145.637	130.637
152.118	121.416
158.594	115.097
165.064	111.654
171.529	107.853
177.989	99.8404
184.441	101.67
190.89	100.244
197.334	101.686
203.772	102.28
210.205	101.289
216.631	102.522
223.054	113.909
229.471	143.594
235.881	158.648
242.288	127.149
248.689	114.136
255.083	113.743
261.474	123.178
267.858	128.83
274.238	164.857
280.613	175.59
286.982	158.453
293.346	133.703
299.704	113.403
306.058	104.785
312.406	111.617
318.749	142.043
325.086	171.56
331.418	141.023
337.746	112.699
344.068	109.529
350.384	109.791
356.697	113.784
363.003	124.334
369.304	111.049
375.601	101.23
381.892	94.5628
388.177	89.8712
394.457	96.8542
400.733	93.6116
407.004	92.5507
413.269	102.169
419.529	106.094
425.784	117.154
432.034	133.893
438.279	140.794
444.518	135.743
450.753	131.598
456.982	128.448
463.207	111.436
469.426	102.018
475.64	96.0974
481.85	93.9452
488.054	97.3705
494.253	93.0453
500.447	93.9981
506.635	92.803
512.819	96.911
518.999	95.7673
525.173	95.3105
531.342	97.0957
537.505	95.7979
543.664	91.9119
549.819	91.6871
555.966	93.9658
562.111	89.7988
568.25	85.5524
574.383	91.5733
580.513	89.3997
586.636	101.618
592.756	121.651
598.871	136.171
604.979	123.28
611.084	118.828
617.183	119.762
623.277	121.697
629.367	117.648
635.451	108.635
641.532	115.152
647.606	119.028
653.675	123.477
659.741	126.58
665.801	110.995
671.856	100.534
677.907	89.9921
683.952	88.1598
689.992	84.2424
696.028	76.9423
702.059	85.5535
708.086	84.763
714.107	83.5039
720.123	81.8854
726.135	78.3786
732.141	80.1143
738.143	81.2162
744.14	78.5905
750.133	71.3423
756.12	76.8959
762.103	84.7666
768.081	83.1212
774.054	74.2911
780.023	77.2879
785.987	84.311
791.946	74.651
797.9	82.8445
803.848	72.1064
809.793	77.6727
815.733	81.2864
821.669	72.3485
827.6	79.9608
833.525	82.9884
839.446	76.8104
845.363	81.3242
851.273	73.6749
857.181	82.6407
863.083	79.4083
868.98	79.3114
874.874	77.5613
880.761	79.2142
886.645	80.8204
892.523	78.576
898.398	76.9087
904.267	84.2914
910.133	83.1306
915.992	84.7993
921.849	85.3216
927.699	84.7008
933.545	87.633
939.387	96.7026
945.224	109.052
951.056	110.445
956.884	117.838
962.708	126.144
968.526	132.795
974.34	158.55
980.149	188.873
985.955	226.939
991.755	209.014
997.551	176.176
1003.34	161.323
1009.13	164.101
1014.91	182.706
1020.69	204.218
1026.46	184.235
1032.23	145.686
1037.99	123.35
1043.75	107.318
1049.51	99.8816
1055.26	92.9718
1061	95.0284
1066.74	95.3488
1072.48	101.471
1078.21	106.252
1083.94	114.23
1089.67	117.055
1095.38	122.794
1101.1	118.196
1106.81	93.0749
1112.51	82.8183
1118.22	81.1555
1123.91	75.5104
1129.6	85.4571
1135.29	85.9991
1140.98	89.1593
1146.65	98.1572
1152.33	106.819
1158	84.173
1163.66	72.5812
1169.32	74.4098
1174.98	75.5689
1180.63	70.5374
1186.28	65.593
1191.93	68.5324
1197.56	68.6213
1203.2	67.5011
1208.83	64.7911
1214.46	66.3649
1220.08	67.0016
1225.69	64.0017
1231.31	65.294
1236.92	65.2044
1242.52	66.7218
1248.12	72.2048
1253.72	84.3695
1259.31	83.9818
1264.89	75.1239
1270.48	103.541
1276.05	307.628
1281.63	117.796
1287.2	67.8871
1292.76	75.4731
1298.33	66.7892
1303.88	71.1482
1309.43	64.5936
1314.98	66.8009
1320.53	64.3383
1326.07	65.9358
1331.6	65.8648
1337.13	64.3976
1342.66	62.8753
1348.18	63.6873
1353.7	67.2192
1359.22	72.4318
1364.73	72.4601
1370.23	76.8939
1375.73	172.048
1381.23	415.993
1386.72	96.9788
1392.21	71.9919
1397.7	81.9996
1403.18	94.1107
1408.65	71.6012
1414.13	64.517
1419.59	56.7312
1425.06	57.9103
1430.52	56.3273
1435.97	53.3425
1441.42	54.1665
1446.87	59.8901
1452.31	56.481
1457.75	53.0229
1463.19	51.9788
1468.62	56.8639
1474.04	57.2018
1479.46	49.8689
1484.88	56.5486
1490.3	53.4528
1495.7	51.0816
1501.11	52.2366
1506.51	55.529
1511.91	58.1553
1517.3	57.2733
1522.69	54.6189
1528.08	50.1676
1533.46	54.3009
1538.83	54.4694
1544.21	53.5153
1549.58	52.4664
1554.94	54.5876
1560.3	54.1606
1565.66	56.9839
1571.01	50.8177
1576.36	54.3611
1581.7	56.1551
1587.04	53.6585
1592.38	51.8976
1597.71	58.0723
1603.04	50.9621
1608.37	57.2135
1613.68	49.426
1619	53.974
1624.31	52.7216
1629.62	52.5536
1634.93	50.1556
1640.23	50.2432
1645.52	50.6913
1650.81	50.3866
1656.1	50.4316
1661.39	52.6683
1666.67	49.351
1671.94	50.0923
1677.22	48.9759
1682.48	48.9593
1687.75	46.6994
1693.01	46.674
1698.26	45.5875
1703.52	49.1003
1708.77	47.0853
1714.01	46.6415
1719.25	51.2442
1724.49	51.6965
1729.72	49.1862
1734.95	50.0365
1740.18	48.6305
1745.4	52.1096
1750.61	48.7944
1755.83	48.4713
1761.04	43.2096
1766.24	45.4916
1771.44	48.1625
1776.64	45.9331
1781.84	46.376
1787.02	48.7312
1792.21	51.1203
1797.39	49.3355
1802.57	47.561
1807.75	45.7731
1812.92	55.852
1818.08	44.0489
1823.25	49.9273
1828.41	43.0859
1833.56	45.5138
1838.71	51.8342
1843.86	44.9278
1849	42.2743
1854.14	49.742
1859.28	45.9158
1864.41	45.6138
1869.54	46.1012
1874.67	42.6311
1879.79	45.0448
1884.9	47.4563
1890.02	45.1213
1895.13	41.5765
1900.23	43.9633
1905.34	42.8561
1910.43	40.58
1915.53	44.2895
1920.62	49.1377
1925.71	42.8507
1930.79	45.3305
1935.87	49.4129
1940.94	47.8829
1946.02	42.7224
1951.08	40.7497
1956.15	45.9885
1961.21	49.6156
1966.27	46.0023
1971.32	45.1788
1976.37	44.7518
1981.42	43.5229
1986.46	41.4962
1991.5	42.2824
1996.53	41.0715
2001.56	44.2803
2006.59	42.295
2011.61	43.9314
2016.63	45.5731
2021.65	43.1885
2026.66	40.423
2031.67	42.5013
2036.68	43.7939
2041.68	41.8584
2046.68	39.9213
2051.67	44.0711
2056.66	44.1434
2061.65	41.3876
2066.63	41.0733
2071.61	44.4365
2076.59	44.1183
2081.56	43.3792
2086.53	42.6216
2091.49	41.8589
2096.46	44.4282
2101.41	41.6328
2106.37	35.0954
2111.32	39.7767
2116.26	41.9894
2121.21	37.9283
2126.15	43.925
2131.09	38.1446
2136.02	43.3083
2140.95	40.8642
2145.87	40.5238
2150.79	41.4376
2155.71	41.9137
2160.63	42.3771
2165.54	41.1196
2170.45	42.8377
2175.35	40.3114
2180.25	41.1798
2185.15	43.735
2190.04	42.0347
2194.93	41.6302
2199.82	42.5302
2204.7	38.3143
2209.58	42.2477
2214.46	41.4806
2219.33	38.5677
2224.2	40.3943
2229.06	42.2296
2233.92	42.7713
2238.78	37.2202
2243.64	39.9326
2248.49	36.5351
2253.34	37.0642
2258.18	38.0386
2263.02	41.218
2267.86	39.9746
2272.69	39.1524
2277.52	37.4284
2282.35	40.5611
2287.17	37.9124
2291.99	37.4793
2296.81	40.5967
2301.62	36.1893
2306.43	37.573
2311.24	40.7636
2316.04	39.0703
2320.84	41.4085
2325.63	40.6182
2330.43	34.8793
2335.21	35.8887
2340	36.9074
2344.78	38.397
2349.56	37.6253
2354.33	37.2934
2359.11	40.6069
2363.87	38.3867
2368.64	35.7063
2373.4	37.1644
2378.16	40.0142
2382.91	39.1443
2387.66	39.6436
2392.41	40.1271
2397.16	39.2047
2401.9	38.7412
2406.64	36.877
2411.37	37.3782
2416.1	38.4285
2420.83	37.6822
2425.55	37.7367
2430.27	37.83
2434.99	38.4078
2439.7	41.8341
2444.41	41.0102
2449.12	34.4763
2453.83	35.532
2458.53	35.6358
2463.22	32.861
2467.92	40.6485
2472.61	35.9295
2477.3	37.9581
2481.98	35.146
2486.66	37.6527
2491.34	34.8089
2496.01	55.8604
2500.68	36.4167
2505.35	34.523
2510.01	37.029
2514.67	33.1486
2519.33	34.1775
2523.99	35.7109
2528.64	38.231
2533.28	36.8116
2537.93	33.912
2542.57	35.9656
2547.21	30.5758
2551.84	38.6152
2556.47	34.6985
2561.1	37.7683
2565.73	34.3473
2570.35	32.9276
2574.97	36.0368
2579.58	38.1386
2584.19	38.2013
2588.8	35.7137
2593.41	37.7694
2598.01	34.274
2602.61	32.7956
2607.2	36.9065
2611.8	34.9016
2616.38	36.4589
2620.97	35.9813
2625.55	34.4856
2630.13	36.5818
2634.71	36.6638
2639.28	35.2329
2643.85	35.3436
2648.42	36.4928
2652.98	38.6838
2657.54	33.5563
2662.1	38.3
2666.65	35.7379
2671.2	33.7107
2675.75	32.7581
2680.29	33.4459
2684.84	34.6563
2689.37	33.2178
2693.91	37.0777
2698.44	34.4649
2702.97	32.3974
2707.49	33.532
2712.02	37.3516
2716.53	34.7412
2721.05	35.3469
2725.56	34.3208
2730.07	34.9029
2734.58	31.6821
2739.08	32.2438
2743.58	33.9097
2748.08	35.048
2752.57	30.2408
2757.06	33.5861
2761.55	35.8232
2766.04	35.3428
2770.52	33.762
2775	34.3873
2779.47	40.5499
2783.94	31.2771
2788.41	32.4937
2792.88	31.4827
2797.34	33.8069
2801.8	35.5726
2806.26	36.7712
2810.71	35.1539
2815.16	32.9568
2819.61	36.9561
2824.05	34.1913
2828.49	33.1158
2832.93	37.7009
2837.37	34.347
2841.8	33.2596
2846.23	35.0239
2850.65	38.5136
2855.08	43.1817
2859.5	35.8353
2863.91	34.2122
2868.33	33.1668
2872.74	33.8474
2877.15	33.9539
2881.55	34.651
2885.95	33.6075
2890.35	30.7907
2894.75	35.0118
2899.14	32.7814
2903.53	44.1526
2907.91	32.9916
2912.3	33.6727
2916.68	34.9411
2921.05	33.2311
2925.43	33.9191
2929.8	34.0183
2934.17	43.1698
2938.53	37.2122
2942.9	36.6754
2947.26	31.8736
2951.61	33.7441
2955.97	33.1833
2960.32	33.8397
2964.66	35.7242
2969.01	33.9524
2973.35	32.79
2977.69	34.6938
2982.03	35.9934
2986.36	36.081
2990.69	33.0857
2995.01	36.9001
2999.34	40.1238
3003.66	36.5114
3007.98	35.383
3012.29	32.9794
3016.6	33.724
3020.91	33.8474
3025.22	33.3217
3029.52	35.9554
3033.82	35.4001
3038.12	34.184
3042.41	34.9
3046.71	32.3963
3051	34.3793
3055.28	33.1526
3059.56	34.5024
3063.84	35.2089
3068.12	35.2708
3072.39	29.4978
3076.67	37.3464
3080.93	35.4639
3085.2	33.5808
3089.46	38.8943
3093.72	31.7979
3097.98	39.796
3102.23	36.6283
3106.48	35.438
3110.73	38.2349
3114.98	42.3904
3119.22	37.1962
3123.46	36.6815
3127.7	40.2266
3131.93	38.3842
3136.16	39.2534
3140.39	35.3192
3144.61	37.5344
3148.84	38.3739
3153.06	37.8063
3157.27	38.6149
3161.49	42.9163
3165.7	36.0411
3169.91	43.1486
3174.11	36.9375
3178.31	40.5317
3182.51	46.9456
3186.71	45.5916
3190.9	45.6417
3195.1	39.3405
3199.28	38.7319
3203.47	40.2985
3207.65	46.8989
3211.83	37.7423
3216.01	42.9601
3220.18	40.2357
3224.36	46.2195
3228.52	43.4826
3232.69	39.9839
3236.85	41.5951
3241.01	39.5414
3245.17	42.684
3249.33	41.3544
3253.48	40.7245
3257.63	43.0634
3261.77	40.2006
3265.92	41.8658
3270.06	36.7516
3274.2	40.7084
3278.33	40.0259
3282.47	36.2873
3286.59	39.4227
3290.72	40.2657
3294.85	41.8737
3298.97	41.1785
3303.09	41.2644
3307.2	41.3464
3311.32	40.6476
3315.43	40.7207
3319.54	33.8048
3323.64	45.5679
3327.74	44.9046
3331.84	42.693
3335.94	42.0602
3340.04	39.8241
3344.13	47.0241
3348.22	38.3968
3352.3	64.642
3356.39	38.5447
3360.47	43.4098
3364.54	41.1122
3368.62	38.7986
3372.69	46.0918
3376.76	41.3488
3380.83	42.2111
3384.89	47.0963
3388.96	42.3162
3393.02	44.781
3397.07	41.6118
3401.13	44.0977
3405.18	44.9485
3409.23	45.8033
3413.27	43.4033
3417.31	51.5576
3421.36	45.9078
3425.39	55.6968
3429.43	42.7322
3433.46	48.4929
3437.49	43.6724
3441.52	49.4753
3445.54	42.206
3449.56	42.3134
3453.58	36.659
3457.6	44.2147
3461.61	41.0516
3465.63	37.8679
3469.63	40.5041
3473.64	43.1272
3477.64	40.7394
3481.64	45.0746
3485.64	37.6001
3489.64	36.8566
3493.63	31.8576
3497.62	39.5942
3501.61	43.9406
3505.59	40.5953
3509.58	41.4953
3513.56	38.9543
3517.53	44.1175
3521.51	44.9996
3525.48	39.0263
3529.45	39.0491
3533.42	38.2438
3537.38	37.4625
3541.34	37.5481
3545.3	38.4799
3549.26	37.6713
3553.21	37.6902
3557.16	36.8564
3561.11	43.8481
3565.06	42.1772
3569	43.1419
3572.94	45.8481
3576.88	43.3304
3580.82	44.3285
3584.75	48.8634
3588.68	51.6566
3592.61	40.2942
3596.54	43.9641
3600.46	36.9558
3604.38	38.8346
3608.3	35.3425
3612.21	31.8275
3616.13	35.4853
3620.04	36.4495
3623.94	37.3841
3627.85	38.3097
3631.75	33.8159
3635.65	35.6388
3639.55	38.3891
3643.44	33.0307
3647.34	34.9191
3651.23	33.1258
3655.12	38.6107
3659	32.2803
3662.88	36.8543
3666.76	31.4243
3670.64	32.3679
3674.52	36.9714
3678.39	33.3781
3682.26	37.1167
3686.13	31.7025
3689.99	32.7129
3693.85	32.8026
3697.71	32.8871
3701.57	31.1187
3705.43	32.1303
3709.28	36.8899
3713.13	36.054
3716.98	35.199
3720.82	33.3908
3724.66	37.2225
3728.5	36.3425
3732.34	35.4645
3736.18	35.5323
3740.01	31.7989
3743.84	34.7026
3747.67	34.7534
3751.49	30.9813
3755.32	33.8711
3759.14	31.0278
3762.96	31.9978
3766.77	36.7895
3770.58	36.817
3774.4	35.8924
3778.2	36.8847
3782.01	45.5665
3785.81	31.2265
3789.61	31.2699
3793.41	32.2803
3797.21	50.6862
3801	31.4415
3804.79	35.3885
3808.58	31.5837
3812.37	30.6769
3816.15	38.5448
3819.93	33.7315
3823.71	34.7705
3827.49	37.7672
3831.26	37.8362
3835.04	32.9839
3838.8	30.0797
3842.57	32.1163
3846.34	37.1015
3850.1	31.1851
3853.86	41.1065
3857.62	33.1935
3861.37	43.1067
3865.12	36.2061
3868.87	30.3282
3872.62	36.3348
3876.37	37.3533
3880.11	30.3997
3883.85	32.4172
3887.59	32.4476
3891.33	31.4839
3895.06	29.5371
3898.79	33.5941
3902.52	29.6294
3906.25	32.6894
3909.97	34.7488
3913.69	32.7905
3917.41	38.9197
3921.13	34.9582
3924.84	30.9787
3928.56	37.1527
3932.27	39.2631
3935.97	34.2143
3939.68	34.267
3943.38	35.3618
3947.08	30.2946
3950.78	32.4021
3954.48	35.5368
3958.17	29.3914
3961.86	33.543
3965.55	36.6639
3969.24	31.5088
3972.92	36.6858
3976.6	34.6307
3980.29	34.6341
3983.96	34.6302
3987.64	35.6615
3991.31	33.5995
3994.98	34.652
3998.65	36.7547