File: Data/3-Raman/raw/bu20-j-ff1-fi02-v_150 (500nm)_532nm_edge_100%_x100_vis_lwd_h30um_30sx2_01.txt
#Acq. time (s)=	30
#Accumulations=	2
#Range (cm-¹)=	50...5000
#Windows=	1
#Auto scanning=	Off
#Autofocus=	Off
#Macrospot=	Off
#AutoExposure=	Off
#Spike filter=	Multiple accum.
#Delay time (s)=	2
#Binning=	1
#Readout mode=	Signal
#DeNoise=	Off
#ICS correction=	On
#Dark correction=	Off
#Inst. Process=	Off
#Detector Gain=	Best Dynamic
#Detector ADC=	50 kHz HS
#Detector temperature (°C)=	-60.09
#Instrument=	LabRAM HR Evol
#Detector=	SIN-EM FIVIS
#Objective=	x100_VIS_LWD
#Grating=	150 (500nm)
#ND Filter=	100%
#Laser=	532nm_Edge
#Hole=	30.0125
#Temperature=	0
#Range=	Visible
#StageXY=	75x50mm Scan+
#StageZ=	Z motor
#X (µm)=	0
#Y (µm)=	0
#Z (µm)=	-17.8
#Full time(mm:ss)=	1:04
#Project=	21_08_11
#Sample=	BU20
#Site=
#Title=	BU20-J-FF1-FI02-V_150 (500nm)_532nm_Edge_100%_x100_VIS_LWD_H30um_30sX2
#Remark=
#Date=	11.08.2021 15:25
#Acquired=	11.08.2021 15:25:10
51.8432	13487.6
56.4921	9589.39
61.1386	6845.22
65.7829	4771.6
70.4227	3737.03
75.0623	2961.76
79.6997	2456.88
84.3347	2066.95
88.9675	1744.87
93.5958	1575.69
98.2239	1447.87
102.85	1301.22
107.473	1119.37
112.095	999.606
116.712	898.34
121.328	880.293
125.943	830.235
130.555	784.426
135.163	726.622
139.77	694.93
144.376	776.522
148.979	1006.53
153.577	1203
158.176	1139.48
162.772	741.791
167.366	536.893
171.956	581.936
176.545	776.315
181.132	973.166
185.715	1129.68
190.298	792.047
194.878	530.279
199.457	422.642
204.03	393.27
208.604	398.132
213.176	414.007
217.743	451.897
222.309	625.529
226.874	786.803
231.435	971.024
235.995	1258.87
240.553	1305.68
245.106	1026.54
249.66	659.991
254.211	530.302
258.758	586.976
263.305	941.339
267.849	1738.28
272.389	2336.11
276.93	2136.61
281.465	1351.59
286.001	809.972
290.534	666.336
295.064	647.733
299.593	663.235
304.117	637.356
308.642	589.226
313.164	722.236
317.682	1004.01
322.2	1256.8
326.714	1168.53
331.227	959.849
335.737	981.363
340.246	1255.75
344.753	1385.56
349.255	1169.05
353.758	815.993
358.256	739.711
362.754	765.883
367.248	688.625
371.741	536.224
376.231	526.415
380.72	601.839
385.205	665.232
389.69	631.156
394.171	501.439
398.652	396.151
403.128	357.013
407.604	408.479
412.076	437.905
416.548	397.358
421.016	293.579
425.483	248.3
429.947	250.097
434.41	234.42
438.869	260.066
443.328	291.639
447.782	333.581
452.237	375.053
456.687	352.827
461.135	320.793
465.583	316.102
470.027	343.78
474.471	389.069
478.91	486.46
483.35	536.225
487.785	624.059
492.218	642.86
496.651	575.102
501.08	472.897
505.509	403.102
509.933	328.968
514.355	290.731
518.778	259.436
523.196	253.691
527.612	256.078
532.028	257.378
536.439	257.566
540.849	270.504
545.258	281.123
549.664	288.299
554.067	298.909
558.47	295.403
562.869	293.407
567.266	298.929
571.662	334.585
576.055	486.25
580.445	691.091
584.836	839.71
589.222	668.975
593.606	433.608
597.99	397.702
602.37	447.028
606.747	451.128
611.123	389.468
615.499	305.197
619.87	275.06
624.24	281.131
628.609	321.596
632.974	345.624
637.337	362.808
641.698	361.853
646.059	396.176
650.416	471.522
654.77	617.313
659.123	723.639
663.473	774.272
667.824	806.287
672.17	772.403
676.514	648.373
680.856	459.919
685.196	321.828
689.536	249.362
693.872	216.842
698.206	198.44
702.538	207.354
706.868	179.349
711.197	178.725
715.523	169.049
719.846	165.92
724.168	180.837
728.487	174.523
732.804	184.801
737.122	200.841
741.435	195.003
745.746	229.741
750.055	258.124
754.362	300.724
758.667	396.529
762.97	564.494
767.27	829.66
771.569	1057.34
775.868	1000.45
780.163	746.365
784.455	493.782
788.746	350.67
793.034	286.264
797.321	249.446
801.605	210.668
805.888	205.087
810.168	187.483
814.446	176.509
818.723	173.252
822.997	160.099
827.269	166.792
831.539	164.694
835.807	157.081
840.074	147.242
844.338	137.373
848.602	155.022
852.862	148.325
857.12	148.248
861.376	161.385
865.63	159.057
869.882	139.092
874.132	145.497
878.378	146.366
882.624	138.438
886.868	145.77
891.11	142.08
895.35	136.223
899.587	148.024
903.823	156.8
908.057	141.484
912.289	165.055
916.519	147.553
920.747	149.502
924.973	177.211
929.197	201.556
933.419	248.568
937.638	295.427
941.856	358.139
946.072	401.354
950.284	340.932
954.496	287.17
958.706	244.229
962.914	225.873
967.12	218.2
971.324	202.089
975.526	201.941
979.726	192.289
983.922	184.798
988.118	161.425
992.312	174.083
996.504	173.11
1000.69	159.514
1004.88	163.959
1009.07	186.508
1013.25	186.763
1017.43	208.287
1021.61	215.988
1025.79	240.721
1029.97	265.418
1034.14	346.616
1038.31	515.957
1042.48	812.529
1046.65	1091.09
1050.82	1097.57
1054.98	805.941
1059.14	542.88
1063.3	422.262
1067.46	361.094
1071.62	414.464
1075.77	558.372
1079.93	731.472
1084.08	930.203
1088.22	950.851
1092.37	861.275
1096.52	827.047
1100.66	981.967
1104.8	1114.76
1108.94	1128.12
1113.08	998.961
1117.21	943.952
1121.34	994.297
1125.47	1045.56
1129.6	1007.47
1133.73	814.763
1137.86	674.487
1141.98	567.691
1146.1	609.854
1150.22	728.197
1154.34	718.452
1158.45	645.5
1162.57	534.133
1166.68	463.887
1170.79	383.229
1174.9	277.8
1179	234.294
1183.1	225.844
1187.21	222.455
1191.31	209.733
1195.41	210.3
1199.5	215.898
1203.6	202.072
1207.69	224.854
1211.78	275.867
1215.87	330.652
1219.95	364.042
1224.04	312.925
1228.12	297.211
1232.2	341.702
1236.28	384.387
1240.36	370.187
1244.43	332.987
1248.51	318.939
1252.58	312.031
1256.65	246.246
1260.72	354.36
1264.78	867.838
1268.85	1134.08
1272.91	1204.53
1276.97	382.891
1281.03	206.472
1285.08	191.569
1289.14	177.622
1293.19	166.649
1297.24	176.8
1301.29	169.807
1305.33	158.745
1309.38	159.771
1313.42	165.81
1317.47	162.718
1321.5	150.538
1325.54	166.472
1329.58	151.226
1333.61	163.077
1337.64	174.845
1341.67	172.543
1345.7	188.202
1349.73	204.798
1353.75	210.396
1357.77	231.873
1361.79	269.105
1365.81	709.034
1369.83	1546.86
1373.85	1917.03
1377.86	1258.38
1381.87	312.712
1385.88	213.149
1389.89	278.05
1393.89	293.814
1397.9	275.243
1401.9	180.758
1405.9	153.226
1409.9	146.39
1413.89	132.657
1417.89	126.805
1421.88	120.945
1425.87	115.06
1429.86	111.085
1433.85	115.036
1437.83	115.024
1441.82	105.147
1445.8	105.12
1449.78	98.1851
1453.76	97.1512
1457.73	102.027
1461.71	97.0243
1465.68	90.0309
1469.65	93.8636
1473.62	93.7752
1477.59	112.304
1481.55	97.4711
1485.52	96.3653
1489.48	91.3477
1493.44	97.0859
1497.4	96.9624
1501.35	91.0119
1505.31	93.8418
1509.26	98.6391
1513.21	88.8645
1517.16	91.7267
1521.11	96.5368
1525.05	92.6199
1528.99	93.5613
1532.94	92.5759
1536.88	99.3448
1540.82	100.302
1544.75	91.5676
1548.69	90.5876
1552.62	102.201
1556.55	101.205
1560.48	104.067
1564.41	104.98
1568.33	96.2117
1572.25	107.74
1576.18	101.871
1580.1	96.9699
1584.01	99.7875
1587.93	116.078
1591.85	102.502
1595.76	102.411
1599.67	99.438
1603.58	97.4396
1607.49	111.77
1611.39	105.947
1615.3	113.557
1619.2	103.934
1623.1	109.628
1627	113.427
1630.89	112.451
1634.79	98.1158
1638.68	120.14
1642.57	114.445
1646.46	106.846
1650.35	119.385
1654.24	107.956
1658.12	94.5805
1662	106.166
1665.89	94.6715
1669.76	108.158
1673.64	93.7299
1677.52	92.7614
1681.39	98.4582
1685.26	100.29
1689.13	104.027
1693	100.071
1696.87	94.1998
1700.73	95.9676
1704.6	93.8959
1708.46	96.5687
1712.32	94.4634
1716.18	88.5817
1720.03	89.3458
1723.89	97.6572
1727.74	90.8593
1731.59	93.4696
1735.44	83.8941
1739.29	89.311
1743.13	92.8262
1746.98	90.7479
1750.82	98.0333
1754.66	91.4067
1758.5	87.6327
1762.34	84.9459
1766.17	86.7999
1770	86.8554
1773.84	86.0187
1777.67	88.9013
1781.5	86.2335
1785.32	81.7008
1789.15	90.2567
1792.97	88.5391
1796.79	87.7559
1800.61	84.1444
1804.43	82.3432
1808.24	92.7868
1812.06	87.2084
1815.87	92.9266
1819.68	91.0562
1823.49	85.3908
1827.3	90.0881
1831.11	85.3271
1834.91	82.4347
1838.71	86.1232
1842.51	84.1494
1846.31	84.0371
1850.11	87.6922
1853.91	97.8405
1857.7	87.3732
1861.49	87.176
1865.28	89.7635
1869.07	86.782
1872.86	89.3795
1876.64	90.1376
1880.43	85.3606
1884.21	95.3853
1887.99	86.0533
1891.77	94.335
1895.55	79.5948
1899.32	91.5427
1903.09	86.9723
1906.87	87.9359
1910.64	81.5382
1914.4	85.3084
1918.17	91.8584
1921.94	85.5455
1925.7	85.6966
1929.46	95.1477
1933.22	84.1802
1936.98	89.9415
1940.74	85.4498
1944.49	83.747
1948.24	90.4645
1952	79.3031
1955.75	88.7498
1959.49	87.824
1963.24	84.0568
1966.99	94.3723
1970.73	91.5042
1974.47	81.1095
1978.21	97.8816
1981.95	94.9532
1985.68	87.3442
1989.42	86.2785
1993.15	80.5438
1996.88	87.8262
2000.61	76.5128
2004.34	89.32
2008.07	92.8194
2011.79	95.3632
2015.52	91.4664
2019.24	85.8019
2022.96	94.8596
2026.68	97.5528
2030.39	82.8376
2034.11	88.3307
2037.82	88.3431
2041.53	86.5224
2045.24	92.0146
2048.95	83.7805
2052.66	89.2978
2056.36	83.8273
2060.06	78.4041
2063.77	86.7869
2067.47	86.0154
2071.16	91.6982
2074.86	84.4765
2078.56	101.286
2082.25	95.922
2085.94	87.7372
2089.63	86.8416
2093.32	96.1521
2097.01	102.728
2100.69	90.677
2104.38	90.6865
2108.06	81.3789
2111.74	91.5887
2115.42	91.5672
2119.09	86.8842
2122.77	82.1691
2126.44	84.8704
2130.12	93.1087
2133.79	96.6946
2137.46	95.6429
2141.12	91.8084
2144.79	100.869
2148.45	96.0998
2152.11	89.5089
2155.78	96.6925
2159.43	90.1301
2163.09	100.961
2166.75	90.7901
2170.4	94.3326
2174.05	97.0014
2177.71	109.696
2181.36	89.636
2185	98.6911
2188.65	103.23
2192.29	95.9792
2195.94	101.509
2199.58	97.9535
2203.22	107.172
2206.86	99.0787
2210.49	91.8959
2214.13	106.683
2217.76	96.7559
2221.39	107.009
2225.02	96.14
2228.65	99.9702
2232.28	95.5125
2235.91	94.7457
2239.53	100.452
2243.15	97.8297
2246.77	92.4079
2250.39	96.2778
2254.01	104.83
2257.62	85.4165
2261.24	91.1789
2264.85	87.5819
2268.46	90.5547
2272.07	93.5593
2275.68	93.7144
2279.29	95.7345
2282.89	85.4157
2286.49	87.3746
2290.09	86.4922
2293.69	87.4897
2297.29	93.2255
2300.89	88.5534
2304.48	95.2279
2308.08	132.217
2311.67	276.319
2315.26	315.175
2318.85	290.472
2322.44	129.305
2326.02	98.8811
2329.61	87.4307
2333.19	91.0947
2336.77	90.9685
2340.35	93.6528
2343.93	90.6816
2347.5	98.0262
2351.08	89.421
2354.65	79.9079
2358.22	86.2833
2361.79	86.1113
2365.36	84.0811
2368.93	90.4109
2372.5	80.0792
2376.06	80.8601
2379.62	79.799
2383.18	85.199
2386.74	82.313
2390.3	83.1243
2393.86	81.1979
2397.41	86.6352
2400.96	92.0952
2404.52	91.1925
2408.07	84.7924
2411.61	83.0168
2415.16	91.3522
2418.71	84.103
2422.25	89.7319
2425.79	83.4176
2429.33	78.9496
2432.87	79.1059
2436.41	80.2081
2439.95	84.1095
2443.48	83.3778
2447.01	77.9746
2450.54	81.926
2454.07	82.1556
2457.6	78.5577
2461.13	89.9502
2464.65	84.3987
2468.18	83.4694
2471.7	88.3014
2475.22	76.901
2478.74	78.7399
2482.26	78.6986
2485.77	77.6808
2489.29	82.2561
2492.8	69.975
2496.31	80.1729
2499.82	81.959
2503.33	79.0222
2506.84	83.5567
2510.35	88.9853
2513.85	75.803
2517.35	85.9006
2520.85	82.0717
2524.35	81.9016
2527.85	69.7968
2531.35	78.0522
2534.84	82.6168
2538.33	75.2038
2541.83	77.9641
2545.32	77.0714
2548.8	75.282
2552.29	81.8151
2555.78	79.1333
2559.26	82.0367
2562.74	73.815
2566.23	85.1326
2569.71	76.9416
2573.18	82.7546
2576.66	91.429
2580.14	82.2987
2583.61	85.3823
2587.08	75.2331
2590.55	82.082
2594.02	75.6098
2597.49	75.7747
2600.96	76.9149
2604.42	82.8357
2607.89	83.9327
2611.35	87.8374
2614.81	72.5003
2618.27	75.4214
2621.72	84.0816
2625.18	76.3895
2628.63	87.8925
2632.09	83.0491
2635.54	83.946
2638.99	80.0263
2642.44	89.5007
2645.88	84.597
2649.33	82.5627
2652.77	70.0338
2656.22	85.1107
2659.66	71.6421
2663.1	81.8934
2666.53	76.034
2669.97	84.333
2673.41	81.3109
2676.84	79.2534
2680.27	78.1534
2683.7	78.9438
2687.13	78.8311
2690.56	83.4302
2693.99	76.8619
2697.41	87.0504
2700.83	77.7036
2704.26	82.3159
2707.68	80.4315
2711.1	84.1775
2714.51	84.2215
2717.93	79.626
2721.34	81.563
2724.76	72.3161
2728.17	79.8703
2731.58	69.675
2734.99	83.7962
2738.39	84.8266
2741.8	80.2231
2745.21	78.412
2748.61	80.3484
2752.01	64.4197
2755.41	80.4567
2758.81	76.7353
2762.21	83.3685
2765.6	66.43
2769	85.2839
2772.39	83.3953
2775.78	82.4406
2779.17	77.7047
2782.56	80.4938
2785.95	85.1564
2789.33	85.1093
2792.71	85.0579
2796.1	86.8848
2799.48	77.4411
2802.86	85.8219
2806.24	84.8182
2809.61	73.5122
2812.99	78.1272
2816.36	70.5765
2819.74	81.7193
2823.11	79.7912
2826.48	86.2694
2829.85	85.2899
2833.21	84.324
2836.58	84.3055
2839.94	80.5758
2843.31	85.2466
2846.67	85.2813
2850.03	84.4162
2853.38	81.6939
2856.74	88.3053
2860.1	91.2001
2863.45	85.6825
2866.8	88.5937
2870.15	86.8177
2873.5	82.2137
2876.85	87.9434
2880.2	90.8583
2883.55	89.0625
2886.89	90.0861
2890.23	75.0604
2893.57	97.7973
2896.91	87.453
2900.25	86.5439
2903.59	80.8902
2906.93	88.4722
2910.26	91.316
2913.59	93.2083
2916.92	86.5758
2920.25	91.2853
2923.58	86.5312
2926.91	95.0046
2930.24	94.955
2933.56	82.6173
2936.88	97.6479
2940.2	94.7432
2943.52	87.1335
2946.84	98.3645
2950.16	94.5312
2953.48	102.918
2956.79	97.2109
2960.11	101.853
2963.42	95.2366
2966.73	97.0767
2970.04	98.0101
2973.34	97.0771
2976.65	113.98
2979.96	96.1799
2983.26	103.704
2986.56	95.2803
2989.86	101.881
2993.16	105.671
2996.46	101.953
2999.76	104.817
3003.05	108.621
3006.34	109.609
3009.64	114.37
3012.93	111.609
3016.22	108.845
3019.51	111.733
3022.79	126.886
3026.08	126.01
3029.36	111.913
3032.65	120.476
3035.93	124.314
3039.21	132.882
3042.49	123.481
3045.76	137.741
3049.04	136.859
3052.31	135.979
3055.59	136.997
3058.86	146.545
3062.13	143.719
3065.4	139.964
3068.66	146.629
3071.93	151.347
3075.2	155.025
3078.46	165.462
3081.72	148.38
3084.98	163.652
3088.24	177.044
3091.5	160.098
3094.76	179.232
3098.01	166.828
3101.27	175.428
3104.52	188.771
3107.77	179.359
3111.02	186.089
3114.27	184.206
3117.52	203.284
3120.76	194.757
3124.01	223.375
3127.25	206.269
3130.49	224.409
3133.73	219.684
3136.97	220.668
3140.21	229.27
3143.44	224.522
3146.68	230.265
3149.91	240.792
3153.15	265.631
3156.38	261.852
3159.61	259.03
3162.83	273.376
3166.06	270.545
3169.29	278.186
3172.51	283.9
3175.73	281.966
3178.96	313.403
3182.18	305.718
3185.4	310.434
3188.61	305.581
3191.83	320.74
3195.04	318.737
3198.26	332.923
3201.47	351.857
3204.68	337.474
3207.89	356.423
3211.1	359.204
3214.31	366.767
3217.51	356.274
3220.72	369.566
3223.92	360.995
3227.12	376.238
3230.32	381.983
3233.52	382.989
3236.72	388.746
3239.91	397.438
3243.11	387.112
3246.3	399.659
3249.49	387.443
3252.69	395.276
3255.88	382.135
3259.06	406.196
3262.25	397.75
3265.44	399.749
3268.62	410.292
3271.8	418.886
3274.99	416.952
3278.17	425.507
3281.35	402.458
3284.52	420.407
3287.7	425.938
3290.88	441.929
3294.05	439.824
3297.22	451.04
3300.39	426.093
3303.56	454.532
3306.73	433.37
3309.9	461.628
3313.07	469.83
3316.23	466.6
3319.4	465.261
3322.56	488.551
3325.72	479.61
3328.88	482.041
3332.04	503.39
3335.19	500.182
3338.35	502.686
3341.5	506.159
3344.66	534.175
3347.81	509.517
3350.96	527.385
3354.11	533.946
3357.26	532.077
3360.4	540.613
3363.55	556.75
3366.69	539.903
3369.83	581.561
3372.98	577.039
3376.12	581.071
3379.26	603.082
3382.39	613.791
3385.53	635.843
3388.66	653.235
3391.8	640.369
3394.93	689.918
3398.06	721.438
3401.19	774.203
3404.32	869.843
3407.45	1089.26
3410.57	1602.14
3413.7	2865.25
3416.82	4171.04
3419.94	4213.22
3423.07	2886.74
3426.18	1616.51
3429.3	1087.01
3432.42	894.239
3435.54	794.834
3438.65	734.471
3441.76	698.076
3444.88	702.674
3447.99	695.709
3451.1	675.366
3454.2	685.45
3457.31	695.486
3460.42	713.036
3463.52	714.381
3466.63	723.279
3469.73	781.369
3472.83	789.986
3475.93	877.396
3479.02	952.41
3482.12	1050.04
3485.22	1227.88
3488.31	1520.78
3491.4	1855.17
3494.5	2337.92
3497.59	2726.9
3500.68	2926
3503.76	2714.79
3506.85	2232.02
3509.94	1754.27
3513.02	1356.66
3516.1	1109.57
3519.18	900.019
3522.27	799.993
3525.35	695.444
3528.42	650.704
3531.5	586.769
3534.58	556.626
3537.65	520.589
3540.72	495.062
3543.79	459.272
3546.86	452.762
3549.93	447.434
3553	432.538
3556.07	396.801
3559.13	388.535
3562.2	383.083
3565.26	371.871
3568.32	365.347
3571.38	359.848
3574.44	347.559
3577.5	347.607
3580.56	327.708
3583.61	320.111
3586.67	321.025
3589.72	307.706
3592.77	307.63
3595.82	288.588
3598.87	277.116
3601.92	273.224
3604.97	271.199
3608.01	256.86
3611.06	258.607
3614.1	254.668
3617.14	246.005
3620.18	235.476
3623.22	232.516
3626.26	218.254
3629.3	222.864
3632.33	218.036
3635.37	207.564
3638.4	203.737
3641.44	197.115
3644.47	189.582
3647.5	184.904
3650.52	175.485
3653.55	163.226
3656.58	150.858
3659.6	151.946
3662.63	133.246
3665.65	136.157
3668.67	136.194
3671.69	132.488
3674.71	125.954
3677.73	120.365
3680.74	112.884
3683.76	121.456
3686.77	118.692
3689.78	109.304
3692.8	107.483
3695.81	111.341
3698.82	109.501
3701.82	101.987
3704.83	91.6144
3707.84	103.075
3710.84	96.478
3713.84	92.7187
3716.85	90.8502
3719.85	85.1772
3722.85	89.0098
3725.84	84.2671
3728.84	87.1337
3731.84	90.9466
3734.83	90.9411
3737.82	88.0693
3740.82	97.5646
3743.81	78.4978
3746.8	88.9227
3749.79	78.417
3752.77	86.9167
3755.76	84.0134
3758.75	87.7561
3761.73	82.0099
3764.71	82.8977
3767.69	80.9466
3770.67	76.1661
3773.65	76.1264
3776.63	84.5993
3779.61	78.8972
3782.58	81.7047
3785.56	82.6236
3788.53	66.5541
3791.5	76.925
3794.47	75.0353
3797.44	79.7586
3800.41	74.1045
3803.38	68.4575
3806.34	74.1448
3809.31	71.3349
3812.27	75.1435
3815.24	72.3378
3818.2	78.9919
3821.16	86.6016
3824.12	82.8585
3827.07	64.904
3830.03	82.007
3832.99	76.3642
3835.94	75.4675
3838.89	66.9731
3841.85	78.4301
3844.8	75.6332
3847.75	75.6902
3850.69	74.798
3853.64	72.0008
3856.59	70.1547
3859.53	76.9044
3862.48	75.0601
3865.42	67.4671
3868.36	75.1848
3871.3	79.0749
3874.24	61.8666
3877.18	77.2646
3880.11	71.5451
3883.05	70.6159
3885.98	77.3665
3888.92	68.7344
3891.85	72.5952
3894.78	70.683
3897.71	64.9144
3900.64	80.2954
3903.56	74.5162
3906.49	68.733
3909.42	78.3365
3912.34	81.2025
3915.26	71.5699
3918.18	68.665
3921.1	73.4507
3924.02	69.582
3926.94	70.5055
3929.86	71.421
3932.78	72.3355
3935.69	69.4351
3938.6	76.1268
3941.52	62.719
3944.43	77.0742
3947.34	69.412
3950.24	75.1609
3953.15	73.2553
3956.06	72.3106
3958.96	72.3295
3961.87	68.5187
3964.77	70.4606
3967.68	68.5719
3970.57	71.4823
3973.48	78.2369
3976.37	70.5896
3979.27	65.8131
3982.17	69.6794
3985.06	62.971
3987.96	62.0261
3990.85	63.9624
3993.74	66.8574
3996.63	66.877
3999.52	65.9338
4002.41	67.8813
4005.3	69.8318
4008.18	68.8962
4011.07	66.9963
4013.95	70.8803
4016.83	67.05
4019.72	68.0422
4022.6	70.9659
4025.47	70.0288
4028.35	73.9239
4031.23	65.2553
4034.11	69.154
4036.98	58.5427
4039.85	64.3817
4042.73	62.4742
4045.6	67.3379
4048.47	73.1786
4051.34	62.5435
4054.2	64.5137
4057.07	70.3759
4059.94	63.6141
4062.8	64.617
4065.67	66.5937
4068.53	62.7358
4071.39	67.6311
4074.25	64.7424
4077.11	60.8752
4079.97	58.953
4082.82	63.853
4085.68	70.7085
4088.53	66.8329
4091.39	69.7873
4094.24	60.0553
4097.09	58.1236
4099.94	58.1499
4102.79	60.129
4105.64	61.1299
4108.48	54.2962
4111.33	65.0759
4114.17	58.2335
4117.02	64.1084
4119.86	58.2292
4122.7	62.1394
4125.54	62.1432
4128.38	57.2539
4131.22	63.1505
4134.05	62.2026
4136.89	60.2945
4139.72	61.2333
4142.56	66.0368
4145.39	60.1758
4148.22	61.1748
4151.05	53.3667
4153.88	60.2294
4156.71	62.1733
4159.53	55.2825
4162.36	65.0555
4165.18	54.2882
4168.01	63.083
4170.83	66.99
4173.65	55.2534
4176.47	63.0769
4179.29	60.143
4182.11	68.9511
4184.92	65.0468
4187.74	70.9287
4190.55	68.9862
4193.37	65.097
4196.18	82.7567
4198.99	79.8691
4201.8	83.8363
4204.61	80.9456
4207.42	71.1745
4210.23	69.2529
4213.03	65.3599
4215.84	60.4791
4218.64	65.4778
4221.44	56.6762
4224.25	63.639
4227.05	61.7179
4229.85	64.7498
4232.64	66.7987
4235.44	62.9174
4238.24	60.0213
4241.03	65.066
4243.83	67.1416
4246.62	57.2745
4249.41	65.3288
4252.2	59.4167
4254.99	68.4862
4257.78	58.552
4260.57	66.6321
4263.35	58.6836
4266.14	57.7488
4268.92	50.7827
4271.71	57.8932
4274.49	53.9307
4277.27	45.911
4280.05	54.0287
4282.83	53.0603
4285.61	54.107
4288.38	56.1598
4291.16	53.1469
4293.93	59.2441
4296.71	54.2109
4299.48	55.259
4302.25	48.186
4305.02	47.1958
4307.79	54.3282
4310.56	59.4393
4313.33	52.3619
4316.09	45.2657
4318.86	46.3008
4321.62	56.4946
4324.38	52.4349
4327.15	61.6096
4329.91	47.3638
4332.67	51.443
4335.42	46.3584
4338.18	57.5689
4340.94	53.5093
4343.69	53.5235
4346.45	54.5645
4349.2	52.5499
4351.95	49.5123
4354.71	51.5949
4357.45	45.4926
4360.2	51.6595
4362.95	59.877
4365.7	52.7487
4368.44	48.6794
4371.19	51.7906
4373.93	47.7109
4376.68	51.8401
4379.42	48.779
4382.16	46.7423
4384.9	56.0131
4387.64	55.0236
4390.37	45.8186
4393.11	51.0302
4395.85	55.2717
4398.58	46.0258
4401.31	55.4026
4404.05	47.1697
4406.78	46.1875
4409.51	49.3615
4412.24	50.455
4414.96	53.6256
4417.69	48.4629
4420.42	53.6963
4423.14	51.6482
4425.87	44.3773
4428.59	48.5904
4431.31	46.5352
4434.03	48.6619
4436.75	50.7888
4439.47	51.868
4442.19	45.6043
4444.9	49.8254
4447.62	61.3931
4450.33	49.8734
4453.05	49.8925
4455.76	49.9114
4458.47	49.9249
4461.18	49.9368
4463.89	46.8013
4466.6	49.9736
4469.31	49.9946
4472.01	46.8587
4474.72	48.992
4477.42	49.0238
4480.13	53.2797
4482.83	50.1539
4485.53	49.136
4488.23	53.3992
4490.93	54.491
4493.63	49.2179
4496.32	47.1139
4499.02	51.3708
4501.71	52.4482
4504.41	48.2246
4507.1	56.726
4509.79	47.2031
4512.48	53.5904
4515.17	48.3064
4517.86	41.9562
4520.55	56.8576
4523.24	47.3226
4525.92	52.6723
4528.61	46.3161
4531.29	52.7382
4533.97	45.3107
4536.65	49.6098
4539.34	44.3087
4542.01	44.3439
4544.69	48.6566
4547.37	45.486
4550.05	46.5954
4552.72	49.8571
4555.4	47.766
4558.07	44.6043
4560.74	50.0577
4563.42	42.5975
4566.08	51.3348
4568.75	47.1201
4571.42	51.5338
4574.09	43.9606
4576.76	43.9724
4579.42	47.2633
4582.09	48.4079
4584.75	49.554
4587.41	44.1399
4590.07	47.4396
4592.73	47.4652
4595.39	48.5885
4598.05	40.9741
4600.71	43.1882
4603.37	37.7532
4606.02	43.2636
4608.68	44.3996
4611.33	43.3433
4613.98	49.9715
4616.63	46.718
4619.28	48.9628
4621.93	44.6057
4624.58	45.7502
4627.23	45.7896
4629.88	46.9321
4632.52	44.7579
4635.16	45.8919
4637.81	47.0249
4640.45	48.1578
4643.09	42.6483
4645.73	48.2281
4648.37	43.8419
4651.01	42.7904
4653.65	43.9798
4656.28	49.5952
4658.92	45.1514
4661.55	47.4264
4664.19	45.2443
4666.82	45.2848
4669.45	39.7235
4672.08	45.3547
4674.71	44.2696
4677.34	45.4255
4679.97	43.2147
4682.59	39.8763
4685.22	44.4019
4687.84	44.4343
4690.47	38.8392
4693.09	46.7546
4695.71	40.0217
4698.33	45.689
4700.95	43.4626
4703.57	43.4901
4706.19	41.2539
4708.8	44.668
4711.42	45.8213
4714.03	40.1835
4716.65	44.7301
4719.26	39.0835
4721.87	48.1622
4724.48	41.3763
4727.09	40.261
4729.7	41.4161
4732.31	48.2491
4734.92	43.7306
4737.52	41.4781
4740.13	39.2218
4742.73	39.2359
4745.33	39.2479
4747.94	36.9797
4750.54	46.0865
4753.14	43.8156
4755.74	43.8194
4758.33	40.4089
4760.93	40.417
4763.53	43.8438
4766.12	46.1371
4768.72	40.4652
4771.31	42.77
4773.9	40.5061
4776.49	45.0903
4779.08	41.6843
4781.67	39.4174
4784.26	40.5781
4786.85	39.4531
4789.44	32.6068
4792.02	38.3469
4794.61	40.6583
4797.19	42.9746
4799.77	39.5641
4802.35	44.1849
4804.93	47.6684
4807.51	40.8169
4810.09	42.0102
4812.67	38.5975
4815.25	34.0262
4817.82	38.6856
4820.4	42.2023
4822.97	39.9395
4825.55	41.1491
4828.12	37.7181
4830.69	41.2526
4833.26	38.9816
4835.83	42.5329
4838.4	43.7659
4840.96	36.8234
4843.53	48.5889
4846.1	41.622
4848.66	39.3276
4851.22	42.8883
4853.79	39.3723
4856.35	41.7523
4858.91	38.2806
4861.47	43.0518
4864.03	37.1942
4866.58	43.1305
4869.14	36.0737
4871.7	39.6631
4874.25	40.8801
4876.81	42.0955
4879.36	40.9388
4881.91	39.7777
4884.46	32.6726
4887.01	38.6356
4889.56	37.4698
4892.11	41.0633
4894.66	38.7049
4897.2	43.4917
4899.75	32.7844
4902.29	36.3783
4904.84	39.9759
4907.38	38.798
4909.92	36.4253
4912.46	37.6246
4915	38.8224
4917.54	40.0162
4920.08	42.4104
4922.62	37.6355
4925.15	38.8348
4927.69	37.6472
4930.22	34.063
4932.76	41.2494
4935.29	30.5051
4937.82	36.5004
4940.35	41.3031
4942.88	41.2981
4945.41	36.5236
4947.93	36.5415
4950.46	37.756
4952.99	42.5733
4955.51	38.9904
4958.04	41.4153
4960.56	40.242
4963.08	37.8691
4965.6	35.5033
4968.12	35.5479
4970.64	35.5798
4973.16	38.0261
4975.68	33.2262
4978.19	36.882
4980.71	39.3362
4983.23	39.372
4985.74	34.5591
4988.25	40.6617
4990.76	44.3472
4993.27	39.5245
4995.78	37.1265
4998.29	37.1682