File: Data/3-Raman/raw/bu20-b-ff4-fi01-v_150 (500nm)_633nm_edge_100%_x100_vis_lwd_h30um_60sx2_01.txt
#Acq. time (s)=	60
#Accumulations=	2
#Range (cm-¹)=	100...4000
#Windows=	1
#Auto scanning=	Off
#Autofocus=	Off
#Macrospot=	Off
#AutoExposure=	Off
#Spike filter=	Multiple accum.
#Delay time (s)=	2
#Binning=	1
#Readout mode=	Signal
#DeNoise=	Off
#ICS correction=	On
#Dark correction=	Off
#Inst. Process=	Off
#Detector Gain=	Best Dynamic
#Detector ADC=	50 kHz HS
#Detector temperature (°C)=	-60.09
#Instrument=	LabRAM HR Evol
#Detector=	SIN-EM FIVIS
#Objective=	x100_VIS_LWD
#Grating=	150 (500nm)
#ND Filter=	100%
#Laser=	633nm_Edge
#Hole=	30.0125
#Temperature=	39.9
#Range=	Visible
#StageXY=	75x50mm Scan+
#StageZ=	Z motor
#X (µm)=	0
#Y (µm)=	0
#Z (µm)=	469.1
#Full time(mm:ss)=	2:05
#Project=	21_08_11
#Sample=	BU20
#Site=
#Title=	BU20-B-FF4-FI01-V_150 (500nm)_633nm_Edge_100%_x100_VIS_LWD_H30um_60sX2
#Remark=
#Date=	13.08.2021 11:43
#Acquired=	13.08.2021 11:43:40
100.12	674.345
106.638	486.963
113.152	400.566
119.66	346.409
126.162	266.319
132.659	221.492
139.151	196.64
145.637	186.146
152.118	166.09
158.594	154.687
165.064	138.489
171.529	140.448
177.989	126.039
184.441	114.439
190.89	116.181
197.334	103.596
203.772	110.233
210.205	114.964
216.631	107.291
223.054	120.582
229.471	123.284
235.881	162.135
242.288	207.588
248.689	163.843
255.083	136.206
261.474	133.298
267.858	136.102
274.238	147.471
280.613	174.009
286.982	228.912
293.346	224.943
299.704	170.815
306.058	143.232
312.406	125.156
318.749	129.773
325.086	155.206
331.418	212.714
337.746	211.724
344.068	147.557
350.384	122.042
356.697	115.353
363.003	137.818
369.304	161.17
375.601	152.549
381.892	131.763
388.177	114.879
394.457	112.188
400.733	98.3157
407.004	96.6361
413.269	105.318
419.529	115.868
425.784	114.001
432.034	127.914
438.279	158.687
444.518	173.319
450.753	174.683
456.982	163.947
463.207	162.725
469.426	139.284
475.64	125.284
481.85	115.995
488.054	104.825
494.253	114.171
500.447	101.145
506.635	112.39
512.819	97.5332
518.999	106.045
525.173	102.486
531.342	98.972
537.505	108.655
543.664	106.052
549.819	103.325
555.966	99.632
562.111	101.437
568.25	97.4826
574.383	97.2086
580.513	98.7609
586.636	104.108
592.756	106.736
598.871	137.413
604.979	170.23
611.084	160.254
617.183	145.682
623.277	148.01
629.367	151.261
635.451	157.057
641.532	149.399
647.606	132.201
653.675	130.05
659.741	152.177
665.801	162.99
671.856	140.313
677.907	117.969
683.952	105.885
689.992	91.094
696.028	92.2371
702.059	89.62
708.086	88.8366
714.107	89.7706
720.123	84.0774
726.135	91.5199
732.141	88.5473
738.143	87.4516
744.14	88.2393
750.133	83.4658
756.12	90.877
762.103	83.5223
768.081	84.6807
774.054	82.1112
780.023	87.9483
785.987	86.195
791.946	84.3949
797.9	84.4165
803.848	79.647
809.793	85.2046
815.733	85.9851
821.669	82.0367
827.6	85.5721
833.525	83.6112
839.446	81.796
845.363	87.5679
851.273	88.6915
857.181	85.1497
863.083	90.1009
868.98	88.4566
874.874	85.7755
880.761	91.5469
886.645	86.8305
892.523	98.1805
898.398	90.4901
904.267	86.4972
910.133	90.988
915.992	90.7557
921.849	92.5231
927.699	91.5896
933.545	103.937
939.387	106.137
945.224	103.686
951.056	119.318
956.884	130.243
962.708	141.135
968.526	154.848
974.34	163.669
980.149	179.917
985.955	235.244
991.755	301.802
997.551	315.589
1003.34	248.421
1009.13	225.421
1014.91	221.823
1020.69	225.866
1026.46	263.672
1032.23	280.658
1037.99	226.65
1043.75	166.529
1049.51	149.58
1055.26	135.335
1061	120.93
1066.74	118.012
1072.48	114.095
1078.21	114.986
1083.94	131.356
1089.67	146.763
1095.38	151.516
1101.1	153.348
1106.81	158.243
1112.51	121.564
1118.22	115.173
1123.91	102.792
1129.6	98.1536
1135.29	105.255
1140.98	102.574
1146.65	120.443
1152.33	120.602
1158	138.319
1163.66	123.372
1169.32	93.7073
1174.98	88.6262
1180.63	83.5697
1186.28	81.5436
1191.93	82.5319
1197.56	73.8371
1203.2	71.0968
1208.83	78.2414
1214.46	75.5868
1220.08	73.9499
1225.69	67.3264
1231.31	75.6475
1236.92	73.9207
1242.52	73.1083
1248.12	79.2738
1253.72	83.3591
1259.31	89.3674
1264.89	118.484
1270.48	91.1228
1276.05	93.9462
1281.63	264.165
1287.2	242.692
1292.76	95.466
1298.33	87.4422
1303.88	79.4793
1309.43	81.6182
1314.98	74.8371
1320.53	83.1526
1326.07	79.4265
1331.6	72.6375
1337.13	72.8933
1342.66	78.2108
1348.18	76.3223
1353.7	72.3504
1359.22	75.514
1364.73	87.8772
1370.23	94.0194
1375.73	81.6588
1381.23	94.9718
1386.72	637.802
1392.21	194.429
1397.7	81.6572
1403.18	84.8539
1408.65	123.113
1414.13	89.2915
1419.59	77.0786
1425.06	75.1969
1430.52	71.2324
1435.97	73.498
1441.42	65.3133
1446.87	66.5251
1452.31	68.7215
1457.75	67.7223
1463.19	61.4295
1468.62	57.2138
1474.04	61.4001
1479.46	59.3177
1484.88	64.6019
1490.3	66.7722
1495.7	64.7736
1501.11	68.0658
1506.51	61.8752
1511.91	66.2865
1517.3	59.0464
1522.69	57.1097
1528.08	62.6649
1533.46	54.3009
1538.83	60.941
1544.21	60.002
1549.58	64.366
1554.94	55.6685
1560.3	55.6001
1565.66	57.703
1571.01	63.0283
1576.36	57.5905
1581.7	55.4375
1587.04	67.2974
1592.38	66.2637
1597.71	63.1064
1603.04	58.8855
1608.37	56.8525
1613.68	55.9437
1619	57.2452
1624.31	61.843
1629.62	59.8781
1634.93	56.7695
1640.23	57.9729
1645.52	61.3826
1650.81	53.7088
1656.1	60.4071
1661.39	53.7771
1666.67	53.787
1671.94	60.4434
1677.22	60.4344
1682.48	57.0884
1687.75	58.1435
1693.01	59.2188
1698.26	53.7084
1703.52	55.0294
1708.77	60.8572
1714.01	55.1893
1719.25	58.6979
1724.49	54.3094
1729.72	60.0334
1734.95	62.4051
1740.18	58.0187
1745.4	58.1295
1750.61	54.8231
1755.83	66.2001
1761.04	57.1726
1766.24	48.1343
1771.44	51.5622
1776.64	52.738
1781.84	59.6263
1787.02	50.6273
1792.21	57.5816
1797.39	52.0023
1802.57	57.8754
1807.75	58.0303
1812.92	52.3972
1818.08	50.2042
1823.25	59.5657
1828.41	56.2243
1833.56	52.8735
1838.71	54.1638
1843.86	55.4304
1849	54.3527
1854.14	50.9124
1859.28	47.4789
1864.41	41.6985
1869.54	54.733
1874.67	58.3477
1879.79	59.6007
1884.9	52.5761
1890.02	46.6976
1895.13	52.6111
1900.23	55.0033
1905.34	50.3609
1910.43	43.3513
1915.53	55.4115
1920.62	48.3419
1925.71	53.2146
1930.79	56.9128
1935.87	54.6142
1940.94	52.2905
1946.02	47.5362
1951.08	54.8014
1956.15	50.005
1961.21	58.454
1966.27	52.4306
1971.32	47.5883
1976.37	53.5818
1981.42	51.1445
1986.46	51.1185
1991.5	53.5042
1996.53	49.8869
2001.56	55.9013
2006.59	53.5202
2011.61	51.153
2016.63	45.1715
2021.65	48.8131
2026.66	48.8696
2031.67	50.1555
2036.68	47.8302
2041.68	51.5647
2046.68	49.2431
2051.67	53.0072
2056.66	49.4324
2061.65	48.3195
2066.63	48.4297
2071.61	47.3033
2076.59	54.7887
2081.56	49.958
2086.53	54.9756
2091.49	47.6326
2096.46	42.7751
2101.41	52.8177
2106.37	51.7086
2111.32	48.1069
2116.26	50.7633
2121.21	49.663
2126.15	52.3317
2131.09	48.6817
2136.02	43.7309
2140.95	43.8284
2145.87	52.8295
2150.79	45.2626
2155.71	50.4241
2160.63	47.9138
2165.54	49.2156
2170.45	55.625
2175.35	51.829
2180.25	48.0075
2185.15	49.2819
2190.04	51.8499
2194.93	46.754
2199.82	51.9338
2204.7	49.4448
2209.58	50.826
2214.46	52.2269
2219.33	51.0645
2224.2	52.491
2229.06	53.924
2233.92	50.1531
2238.78	54.1978
2243.64	49.0975
2248.49	54.4745
2253.34	51.9776
2258.18	57.3877
2263.02	53.5613
2267.86	49.6922
2272.69	51.0972
2277.52	55.146
2282.35	60.5092
2287.17	57.8662
2291.99	52.5597
2296.81	53.9071
2301.62	53.9509
2306.43	47.3553
2311.24	48.7826
2316.04	48.8936
2320.84	50.3617
2325.63	50.4923
2330.43	58.7322
2335.21	46.723
2340	50.9458
2344.78	57.9363
2349.56	49.939
2354.33	48.7331
2359.11	50.2424
2363.87	43.4436
2368.64	46.303
2373.4	47.7828
2378.16	49.266
2382.91	46.5563
2387.66	46.5986
2392.41	49.4051
2397.16	43.8443
2401.9	45.2368
2406.64	46.6181
2411.37	42.4857
2416.1	46.8129
2420.83	45.6399
2425.55	44.2997
2430.27	48.6386
2434.99	43.1204
2439.7	48.9247
2444.41	46.2254
2449.12	46.3646
2453.83	45.0708
2458.53	43.7675
2463.22	43.8946
2467.92	44.0158
2472.61	48.4687
2477.3	41.3428
2481.98	47.2654
2486.66	47.3695
2491.34	46.0062
2496.01	54.8847
2500.68	46.193
2505.35	43.3374
2510.01	37.5195
2514.67	40.515
2519.33	44.9962
2523.99	40.6365
2528.64	39.2176
2533.28	46.694
2537.93	37.8726
2542.57	43.9029
2547.21	43.9994
2551.84	51.57
2556.47	48.6778
2561.1	41.27
2565.73	44.3757
2570.35	41.4737
2574.97	38.5569
2579.58	44.7055
2584.19	43.261
2588.8	46.3519
2593.41	43.3461
2598.01	46.4603
2602.61	43.4732
2607.2	41.9971
2611.8	40.5063
2616.38	39.0084
2620.97	40.5746
2625.55	37.551
2630.13	42.2097
2634.71	40.766
2639.28	42.4338
2643.85	37.9235
2648.42	39.5986
2652.98	36.6068
2657.54	41.3601
2662.1	41.4265
2666.65	38.3465
2671.2	38.4145
2675.75	43.2408
2680.29	40.2931
2684.84	38.8891
2689.37	32.6863
2693.91	39.2116
2698.44	39.274
2702.97	44.1782
2707.49	41.0431
2712.02	34.6644
2716.53	41.2047
2721.05	36.4262
2725.56	38.1042
2730.07	43.0199
2734.58	41.4304
2739.08	43.0821
2743.58	38.2502
2748.08	38.3083
2752.57	35.1448
2757.06	35.2245
2761.55	43.4801
2766.04	38.6305
2770.52	40.3497
2775	42.0901
2779.47	37.2397
2783.94	37.3664
2788.41	30.8274
2792.88	39.2837
2797.34	42.7476
2801.8	39.4939
2806.26	39.5781
2810.71	44.7157
2815.16	34.6469
2819.61	44.8551
2824.05	33.061
2828.49	39.9088
2832.93	46.7717
2837.37	38.321
2841.8	36.6708
2846.23	36.7323
2850.65	26.5316
2855.08	40.3219
2859.5	35.262
2863.91	42.2622
2868.33	42.3959
2872.74	39.0547
2877.15	35.6952
2881.55	39.31
2885.95	41.2058
2890.35	37.8286
2894.75	32.658
2899.14	41.6413
2903.53	48.8938
2907.91	34.7749
2912.3	40.2284
2916.68	36.733
2921.05	42.2124
2925.43	40.5229
2929.8	37.0288
2934.17	42.566
2938.53	31.7665
2942.9	35.463
2947.26	37.3377
2951.61	39.2161
2955.97	39.272
2960.32	41.1564
2964.66	37.5562
2969.01	37.6229
2973.35	35.8544
2977.69	35.9219
2982.03	43.3766
2986.36	39.7816
2990.69	36.1779
2995.01	38.1405
2999.34	30.7927
3003.66	36.5114
3007.98	36.6355
3012.29	38.633
3016.6	42.5489
3020.91	44.6026
3025.22	40.9381
3029.52	37.2282
3033.82	39.2272
3038.12	39.2956
3042.41	37.4614
3046.71	35.6038
3051	37.5923
3055.28	39.59
3059.56	41.5963
3063.84	51.3597
3068.12	43.684
3072.39	43.7605
3076.67	41.8929
3080.93	41.971
3085.2	36.189
3089.46	50.0069
3093.72	40.3211
3097.98	42.4271
3102.23	38.6082
3106.48	44.7115
3110.73	36.905
3114.98	51.0687
3119.22	41.2175
3123.46	39.3737
3127.7	41.5788
3131.93	45.8572
3136.16	44.0321
3140.39	42.1773
3144.61	46.4876
3148.84	50.8195
3153.06	46.8243
3157.27	42.7895
3161.49	49.1967
3165.7	43.0394
3169.91	43.1486
3174.11	45.3804
3178.31	45.466
3182.51	54.0051
3186.71	56.1943
3190.9	54.1332
3195.1	47.8466
3199.28	45.8387
3203.47	46.0045
3207.65	39.7388
3211.83	46.3691
3216.01	44.4042
3220.18	46.7604
3224.36	49.131
3228.52	47.1366
3232.69	49.5213
3236.85	49.6932
3241.01	45.4541
3245.17	47.8804
3249.33	39.119
3253.48	45.9552
3257.63	55.0463
3261.77	55.2289
3265.92	53.1808
3270.06	42.056
3274.2	46.7957
3278.33	46.8875
3282.47	49.2743
3286.59	37.8917
3290.72	40.2657
3294.85	40.337
3298.97	40.4088
3303.09	40.4931
3307.2	42.892
3311.32	45.293
3315.43	43.0476
3319.54	38.4675
3323.64	47.9047
3327.74	43.3427
3331.84	43.4763
3335.94	43.6326
3340.04	46.1329
3344.13	41.4919
3348.22	46.3137
3352.3	67.8146
3356.39	41.7236
3360.47	37.0377
3364.54	39.5156
3368.62	41.9985
3372.69	44.4886
3376.76	44.5604
3380.83	49.4472
3384.89	47.0963
3388.96	49.5704
3393.02	44.781
3397.07	52.1158
3401.13	49.7617
3405.18	49.8078
3409.23	37.6965
3413.27	47.4597
3417.31	47.498
3421.36	45.0953
3425.39	57.323
3429.43	42.7322
3433.46	40.3428
3437.49	47.7539
3441.52	42.9331
3445.54	45.4841
3449.56	45.5998
3453.58	43.2494
3457.6	43.3882
3461.61	41.0516
3465.63	36.2033
3469.63	41.3392
3473.64	43.9646
3477.64	34.0195
3481.64	34.1219
3485.64	46.8945
3489.64	41.9403
3493.63	44.6007
3497.62	49.8121
3501.61	37.1148
3505.59	42.3046
3509.58	39.7842
3513.56	34.6736
3517.53	39.8342
3521.51	47.571
3525.48	39.884
3529.45	39.9073
3533.42	39.9626
3537.38	37.4625
3541.34	34.9586
3545.3	45.3976
3549.26	37.6713
3553.21	35.0909
3557.16	40.3252
3561.11	32.5605
3565.06	50.8736
3569	40.5272
3572.94	53.7078
3576.88	43.3304
3580.82	48.7174
3584.75	54.1459
3588.68	54.3057
3592.61	62.4339
3596.54	54.622
3600.46	54.7658
3604.38	41.5129
3608.3	36.2372
3612.21	44.3792
3616.13	39.0787
3620.04	33.7495
3623.94	33.7808
3627.85	41.9153
3631.75	33.8159
3635.65	36.5411
3639.55	31.1629
3643.44	33.9357
3647.34	34.0121
3651.23	28.588
3655.12	36.7937
3659	39.5547
3662.88	34.1243
3666.76	34.1569
3670.64	36.9268
3674.52	39.7101
3678.39	31.5491
3682.26	39.8661
3686.13	34.4592
3689.99	34.5559
3693.85	31.8786
3697.71	40.2983
3701.57	37.6211
3705.43	32.1303
3709.28	43.4274
3713.13	32.3081
3716.98	29.5672
3720.82	40.9155
3724.66	35.3378
3728.5	29.7348
3732.34	41.1388
3736.18	32.6897
3740.01	32.7481
3743.84	29.9488
3747.67	32.8491
3751.49	32.8879
3755.32	32.917
3759.14	35.8013
3762.96	32.9529
3766.77	35.8339
3770.58	35.8607
3774.4	35.8924
3778.2	41.6749
3782.01	50.363
3785.81	30.2657
3789.61	33.1942
3793.41	41.9163
3797.21	50.6862
3801	42.0832
3804.79	36.358
3808.58	36.4427
3812.37	30.6769
3816.15	36.5932
3819.93	36.6647
3823.71	36.7295
3827.49	30.9005
3831.26	42.75
3835.04	33.9685
3838.8	34.0246
3842.57	34.0927
3846.34	43.0377
3850.1	34.1551
3853.86	40.1159
3857.62	43.102
3861.37	40.1338
3865.12	43.1497
3868.87	37.2888
3872.62	34.3439
3876.37	31.3768
3880.11	37.3766
3883.85	34.4121
3887.59	37.4395
3891.33	37.4808
3895.06	34.5434
3898.79	37.6053
3902.52	34.6513
3906.25	40.736
3909.97	31.7272
3913.69	28.7547
3917.41	34.8761
3921.13	31.9184
3924.84	31.9944
3928.56	41.2242
3932.27	35.1838
3935.97	38.2996
3939.68	29.1525
3943.38	32.2868
3947.08	35.4293
3950.78	35.488
3954.48	32.4466
3958.17	35.5791
3961.86	35.6072
3965.55	41.8279
3969.24	38.7404
3972.92	29.452
3976.6	38.7657
3980.29	38.7695
3983.96	35.6639
3987.64	32.5605
3991.31	35.6671
3994.98	38.7895
3998.65	35.7193