File: Data/3-Raman/raw/bu20-b-ff4-fi01-l_150 (500nm)_633nm_edge_100%_x100_vis_lwd_h30um_60sx2_01.txt
#Acq. time (s)=	60
#Accumulations=	2
#Range (cm-¹)=	100...4000
#Windows=	1
#Auto scanning=	Off
#Autofocus=	Off
#Macrospot=	Off
#AutoExposure=	Off
#Spike filter=	Multiple accum.
#Delay time (s)=	2
#Binning=	1
#Readout mode=	Signal
#DeNoise=	Off
#ICS correction=	On
#Dark correction=	Off
#Inst. Process=	Off
#Detector Gain=	Best Dynamic
#Detector ADC=	50 kHz HS
#Detector temperature (°C)=	-60.09
#Instrument=	LabRAM HR Evol
#Detector=	SIN-EM FIVIS
#Objective=	x100_VIS_LWD
#Grating=	150 (500nm)
#ND Filter=	100%
#Laser=	633nm_Edge
#Hole=	30.0125
#Temperature=	40
#Range=	Visible
#StageXY=	75x50mm Scan+
#StageZ=	Z motor
#X (µm)=	0
#Y (µm)=	0
#Z (µm)=	471.2
#Full time(mm:ss)=	2:04
#Project=	21_08_11
#Sample=	BU20
#Site=
#Title=	BU20-B-FF4-FI01-L_150 (500nm)_633nm_Edge_100%_x100_VIS_LWD_H30um_60sX2
#Remark=
#Date=	13.08.2021 11:47
#Acquired=	13.08.2021 11:47:19
100.12	420.81
106.638	391.574
113.152	358.552
119.66	342.587
126.162	306.482
132.659	292.293
139.151	290.415
145.637	273.237
152.118	268.52
158.594	236.101
165.064	235.287
171.529	241.111
177.989	213.259
184.441	206.373
190.89	194.592
197.334	206.714
203.772	176.087
210.205	179.84
216.631	172.142
223.054	182.541
229.471	200.397
235.881	252.474
242.288	335.846
248.689	250.276
255.083	210.242
261.474	221.531
267.858	226.204
274.238	246.101
280.613	293.492
286.982	394.79
293.346	361.329
299.704	262.61
306.058	193.34
312.406	176.163
318.749	187.346
325.086	221.251
331.418	326.853
337.746	295.658
344.068	204.129
350.384	161.623
356.697	176.561
363.003	202.729
369.304	226.015
375.601	208.875
381.892	180.529
388.177	156.142
394.457	138.475
400.733	125.599
407.004	130.577
413.269	127.043
419.529	134.785
425.784	159.412
432.034	170.395
438.279	216.135
444.518	248.471
450.753	255.234
456.982	241.483
463.207	227.069
469.426	190.526
475.64	151.365
481.85	129.97
488.054	125.324
494.253	127.219
500.447	127.247
506.635	133.842
512.819	125.533
518.999	124.731
525.173	124.013
531.342	125.239
537.505	116.18
543.664	117.364
549.819	106.156
555.966	114.742
562.111	114.647
568.25	114.436
574.383	109.418
580.513	110.93
586.636	126.517
592.756	124.448
598.871	179.336
604.979	238.321
611.084	210.713
617.183	186.904
623.277	180.9
629.367	187.074
635.451	204.221
641.532	196.529
647.606	173.601
653.675	172.304
659.741	203.684
665.801	211.56
671.856	178.538
677.907	136.62
683.952	123.61
689.992	106.977
696.028	95.9828
702.059	93.3737
708.086	92.5969
714.107	87.8906
720.123	86.8956
726.135	84.0106
732.141	75.4292
738.143	86.5163
744.14	76.1005
750.133	73.2075
756.12	78.7601
762.103	82.5891
768.081	80.938
774.054	78.3575
780.023	71.0171
785.987	73.0067
791.946	72.1364
797.9	74.0413
803.848	74.9341
809.793	74.8482
815.733	76.5878
821.669	74.5362
827.6	82.7664
833.525	85.4796
839.446	77.122
845.363	81.012
851.273	82.1217
857.181	86.0906
863.083	76.8924
868.98	80.8881
874.874	83.8799
880.761	81.1115
886.645	92.5243
892.523	83.9514
898.398	82.9098
904.267	83.6612
910.133	77.7877
915.992	90.7557
921.849	84.0692
927.699	90.6502
933.545	86.0653
939.387	102.363
945.224	122.625
951.056	139.284
956.884	159.821
962.708	174.624
968.526	189.365
974.34	203.027
980.149	245.167
985.955	340.649
991.755	430.941
997.551	464.551
1003.34	369.532
1009.13	308.345
1014.91	296.241
1020.69	324.235
1026.46	368.949
1032.23	414.99
1037.99	303.644
1043.75	219.625
1049.51	172.816
1055.26	160.558
1061	145.214
1066.74	118.984
1072.48	124.776
1078.21	128.57
1083.94	154.622
1089.67	173.887
1095.38	173.783
1101.1	185.276
1106.81	204.7
1112.51	142.874
1118.22	106.425
1123.91	97.9199
1129.6	98.1536
1135.29	97.4221
1140.98	113.371
1146.65	122.41
1152.33	123.555
1158	146.195
1163.66	138.117
1169.32	96.651
1174.98	84.709
1180.63	75.7503
1186.28	70.8014
1191.93	64.9511
1197.56	66.0133
1203.2	60.3097
1208.83	59.5422
1214.46	60.7658
1220.08	60.0533
1225.69	49.3727
1231.31	58.6143
1236.92	59.8406
1242.52	61.0076
1248.12	56.0471
1253.72	55.0675
1259.31	61.0929
1264.89	54.9564
1270.48	63.937
1276.05	51.7458
1281.63	57.6451
1287.2	60.548
1292.76	59.4788
1298.33	52.4653
1303.88	56.4853
1309.43	57.5834
1314.98	53.7421
1320.53	52.9153
1326.07	53.1196
1331.6	59.4307
1337.13	54.5426
1342.66	53.6741
1348.18	51.7353
1353.7	53.878
1359.22	57.0208
1364.73	51.9041
1370.23	51.8905
1375.73	55.9799
1381.23	60.0632
1386.72	59.0082
1392.21	61.0478
1397.7	52.8974
1403.18	51.9409
1408.65	44.8151
1414.13	51.0975
1419.59	50.1787
1425.06	48.2297
1430.52	46.2751
1435.97	46.3924
1441.42	49.6381
1446.87	50.8105
1452.31	45.6395
1457.75	44.6232
1463.19	46.7284
1468.62	59.3134
1474.04	40.4086
1479.46	40.42
1484.88	45.6941
1490.3	50.9992
1495.7	51.0816
1501.11	42.739
1506.51	47.0674
1511.91	49.3171
1517.3	48.4074
1522.69	48.5699
1528.08	45.5258
1533.46	53.2256
1538.83	49.0764
1544.21	47.0286
1549.58	39.485
1554.94	42.6972
1560.3	48.0428
1565.66	46.9174
1571.01	47.9446
1576.36	45.7494
1581.7	46.8258
1587.04	55.4531
1592.38	50.1018
1597.71	55.5552
1603.04	52.4027
1608.37	50.3551
1613.68	52.6849
1619	49.6125
1624.31	49.8027
1629.62	49.99
1634.93	53.4626
1640.23	49.139
1645.52	52.5346
1650.81	50.3866
1656.1	54.8651
1661.39	48.2331
1666.67	52.678
1671.94	50.462
1677.22	48.2367
1682.48	41.5692
1687.75	51.4985
1693.01	44.8292
1698.26	48.1714
1703.52	42.8006
1708.77	39.6409
1714.01	40.6951
1719.25	46.3993
1724.49	43.1116
1729.72	40.9573
1734.95	45.5389
1740.18	43.3732
1745.4	38.9411
1750.61	40.1282
1755.83	48.0941
1761.04	40.1906
1766.24	42.4714
1771.44	45.896
1776.64	44.7989
1781.84	41.4544
1787.02	43.8012
1792.21	39.3379
1797.39	41.7161
1802.57	40.6847
1807.75	45.39
1812.92	43.1845
1818.08	43.2795
1823.25	37.59
1828.41	45.7909
1833.56	37.7668
1838.71	42.5157
1843.86	41.427
1849	34.4818
1854.14	43.89
1859.28	39.2726
1864.41	45.2223
1869.54	38.2542
1874.67	40.6666
1879.79	39.5371
1884.9	37.2168
1890.02	37.2398
1895.13	34.877
1900.23	39.6261
1905.34	43.2511
1910.43	40.9759
1915.53	35.1535
1920.62	38.7929
1925.71	38.8646
1930.79	42.5348
1935.87	35.4092
1940.94	40.2697
1946.02	36.7052
1951.08	39.1438
1956.15	39.1605
1961.21	48.8121
1966.27	37.967
1971.32	41.5645
1976.37	39.1328
1981.42	37.9071
1986.46	34.2794
1991.5	40.2785
1996.53	34.2597
2001.56	34.2621
2006.59	35.4797
2011.61	39.117
2016.63	42.7624
2021.65	41.5815
2026.66	41.6297
2031.67	42.9041
2036.68	39.3539
2041.68	35.792
2046.68	41.9478
2051.67	35.9474
2056.66	36.0063
2061.65	40.9798
2066.63	41.0733
2071.61	37.4741
2076.59	43.7079
2081.56	40.0897
2086.53	38.9153
2091.49	45.1581
2096.46	40.2953
2101.41	36.6617
2106.37	36.7567
2111.32	33.1126
2116.26	34.4689
2121.21	39.6047
2126.15	38.4606
2131.09	36.0371
2136.02	33.5904
2140.95	42.558
2145.87	43.9185
2150.79	37.6126
2155.71	33.8288
2160.63	36.4145
2165.54	38.989
2170.45	40.2802
2175.35	40.3114
2180.25	40.3263
2185.15	39.0415
2190.04	36.4869
2194.93	37.7875
2199.82	35.2637
2204.7	39.1705
2209.58	34.0984
2214.46	38.0418
2219.33	39.4295
2224.2	34.346
2229.06	42.2296
2233.92	39.7317
2238.78	35.9142
2243.64	37.3141
2248.49	38.7228
2253.34	36.1869
2258.18	38.9181
2263.02	35.0463
2267.86	35.1158
2272.69	39.1524
2277.52	41.8578
2282.35	37.9013
2287.17	36.5821
2291.99	36.5922
2296.81	32.6105
2301.62	33.9691
2306.43	36.6837
2311.24	36.754
2316.04	40.8563
2320.84	35.5889
2325.63	37.0277
2330.43	33.0791
2335.21	35.8887
2340	34.6432
2344.78	34.7618
2349.56	36.2571
2354.33	30.8872
2359.11	37.8539
2363.87	33.7894
2368.64	35.2455
2373.4	38.0877
2378.16	31.2249
2382.91	34.0486
2387.66	34.0796
2392.41	35.4881
2397.16	36.8849
2401.9	38.2773
2406.64	31.3107
2411.37	38.3068
2416.1	35.6337
2420.83	33.0011
2425.55	33.0489
2430.27	31.7208
2434.99	33.2239
2439.7	36.1617
2444.41	33.4245
2449.12	34.9518
2453.83	35.0551
2458.53	39.4625
2463.22	35.2596
2467.92	31.0275
2472.61	34.0004
2477.3	34.0897
2481.98	35.6308
2486.66	32.7943
2491.34	35.7826
2496.01	41.7124
2500.68	30.0621
2505.35	27.1777
2510.01	34.5768
2514.67	36.0951
2519.33	34.6692
2523.99	36.2034
2528.64	37.7377
2533.28	33.3528
2537.93	33.417
2542.57	31.997
2547.21	27.5928
2551.84	39.6117
2556.47	30.7044
2561.1	36.7679
2565.73	29.3331
2570.35	33.933
2574.97	38.5569
2579.58	37.1283
2584.19	32.6355
2588.8	38.7532
2593.41	32.6997
2598.01	32.7507
2602.61	34.3209
2607.2	40.4699
2611.8	31.335
2616.38	32.8895
2620.97	32.919
2625.55	32.9529
2630.13	29.9305
2634.71	34.6127
2639.28	31.6325
2643.85	31.7319
2648.42	28.7284
2652.98	36.6068
2657.54	33.5563
2662.1	33.6102
2666.65	32.0858
2671.2	32.1427
2675.75	35.3788
2680.29	37.1329
2684.84	32.5399
2689.37	29.4974
2693.91	36.0107
2698.44	34.4649
2702.97	24.9005
2707.49	39.4336
2712.02	29.8275
2716.53	34.7412
2721.05	31.5693
2725.56	31.6183
2730.07	34.9029
2734.58	31.6821
2739.08	28.4504
2743.58	31.7395
2748.08	30.1576
2752.57	35.1448
2757.06	30.3094
2761.55	30.3541
2766.04	33.699
2770.52	33.762
2775	32.1865
2779.47	32.2744
2783.94	35.7057
2788.41	25.8284
2792.88	32.5971
2797.34	27.6602
2801.8	26.0492
2806.26	34.5256
2810.71	31.2167
2815.16	31.2667
2819.61	34.6992
2824.05	29.6702
2828.49	38.2105
2832.93	39.9686
2837.37	31.5084
2841.8	34.9652
2846.23	36.7323
2850.65	35.0902
2855.08	36.8903
2859.5	35.262
2863.91	33.6372
2868.33	32.0132
2872.74	39.0547
2877.15	30.4715
2881.55	32.3215
2885.95	35.9454
2890.35	34.3097
2894.75	27.3621
2899.14	32.7814
2903.53	41.782
2907.91	36.5583
2912.3	31.2888
2916.68	33.1493
2921.05	35.0273
2925.43	33.3188
2929.8	27.9974
2934.17	38.9434
2938.53	31.7665
2942.9	39.1003
2947.26	31.8736
2951.61	33.7441
2955.97	35.6188
2960.32	26.523
2964.66	28.3962
2969.01	32.1171
2973.35	37.6931
2977.69	32.2376
2982.03	28.6101
2986.36	32.3803
2990.69	32.4673
2995.01	32.5589
2999.34	34.5252
3003.66	38.3838
3007.98	36.6355
3012.29	36.7485
3016.6	34.9847
3020.91	35.1127
3025.22	42.8422
3029.52	31.5008
3033.82	37.3137
3038.12	37.3788
3042.41	37.4614
3046.71	37.5284
3051	39.5201
3055.28	35.7275
3059.56	35.7922
3063.84	35.8549
3068.12	45.6255
3072.39	41.8156
3076.67	43.8414
3080.93	38.0667
3085.2	47.926
3089.46	38.2406
3093.72	48.1886
3097.98	52.2939
3102.23	48.5077
3106.48	52.6602
3110.73	48.8742
3114.98	49.066
3119.22	59.3129
3123.46	47.4504
3127.7	47.6635
3131.93	54.0096
3136.16	54.2721
3140.39	50.407
3144.61	63.0165
3148.84	54.968
3153.06	46.8243
3157.27	53.226
3161.49	59.6641
3165.7	57.7358
3169.91	57.8822
3174.11	55.934
3178.31	58.1541
3182.51	66.7122
3186.71	66.797
3190.9	68.9933
3195.1	69.1117
3199.28	82.0832
3203.47	71.6815
3207.65	78.4036
3211.83	70.0929
3216.01	79.0611
3220.18	77.209
3224.36	88.4357
3228.52	71.253
3232.69	75.9327
3236.85	73.9877
3241.01	80.9305
3245.17	90.1932
3249.33	90.5326
3253.48	79.5809
3257.63	88.7481
3261.77	82.2798
3265.92	87.1261
3270.06	85.2486
3274.2	83.3191
3278.33	81.1955
3282.47	79.068
3286.59	83.8211
3290.72	81.6819
3294.85	86.4365
3298.97	86.5903
3303.09	72.8875
3307.2	79.9879
3311.32	91.7474
3315.43	89.5856
3319.54	85.0948
3323.64	94.6409
3327.74	85.5141
3331.84	92.8278
3335.94	81.3689
3340.04	86.3513
3344.13	91.2821
3348.22	93.8149
3352.3	115.404
3356.39	94.1761
3360.47	96.7759
3364.54	108.967
3368.62	94.7966
3372.69	99.7989
3376.76	90.3251
3380.83	109.749
3384.89	107.476
3388.96	107.604
3393.02	110.137
3397.07	107.868
3401.13	120.156
3405.18	120.268
3409.23	110.657
3413.27	115.607
3417.31	130.315
3421.36	127.973
3425.39	123.183
3429.43	123.313
3433.46	113.693
3437.49	123.67
3441.52	111.626
3445.54	124.159
3449.56	129.405
3453.58	119.863
3457.6	107.851
3461.61	108.227
3465.63	103.616
3469.63	111.491
3473.64	109.283
3477.64	114.658
3481.64	104.893
3485.64	102.661
3489.64	110.57
3493.63	110.865
3497.62	100.901
3501.61	106.225
3505.59	108.966
3509.58	96.252
3513.56	98.8839
3517.53	101.513
3521.51	91.2848
3525.48	96.4935
3529.45	99.1245
3533.42	91.5273
3537.38	94.3022
3541.34	78.9806
3545.3	94.6864
3549.26	87.0336
3553.21	81.8788
3557.16	87.1544
3561.11	87.2621
3565.06	76.9626
3569	82.3618
3572.94	74.667
3576.88	80.0956
3580.82	80.3179
3584.75	96.4061
3588.68	96.6906
3592.61	102.285
3596.54	83.9314
3600.46	81.4809
3604.38	57.5824
3608.3	63.0796
3612.21	63.2067
3616.13	63.3345
3620.04	60.7491
3623.94	55.4005
3627.85	47.3237
3631.75	41.9317
3635.65	50.0748
3639.55	44.712
3643.44	52.9397
3647.34	53.0589
3651.23	47.6466
3655.12	44.9701
3659	36.8268
3662.88	39.5842
3666.76	50.5522
3670.64	42.3974
3674.52	39.7101
3678.39	42.5227
3682.26	37.1167
3686.13	39.9727
3689.99	31.7915
3693.85	37.4227
3697.71	31.9607
3701.57	40.4078
3705.43	37.7181
3709.28	35.0221
3713.13	32.3081
3716.98	35.199
3720.82	40.9155
3724.66	29.6838
3728.5	35.3985
3732.34	38.3016
3736.18	35.5323
3740.01	38.4434
3743.84	32.8011
3747.67	29.9926
3751.49	35.7477
3755.32	32.917
3759.14	35.8013
3762.96	30.0874
3766.77	27.2338
3770.58	41.5984
3774.4	33.021
3778.2	30.1784
3782.01	41.7293
3785.81	33.1482
3789.61	30.3078
3793.41	33.2439
3797.21	50.6862
3801	33.3763
3804.79	36.358
3808.58	33.5273
3812.37	36.5201
3816.15	36.5932
3819.93	36.6647
3823.71	36.7295
3827.49	36.7863
3831.26	30.9569
3835.04	33.9685
3838.8	31.0659
3842.57	34.0927
3846.34	37.1015
3850.1	31.1851
3853.86	40.1159
3857.62	31.2118
3861.37	37.161
3865.12	37.198
3868.87	31.3226
3872.62	34.3439
3876.37	37.3533
3880.11	31.3964
3883.85	34.4121
3887.59	37.4395
3891.33	28.4854
3895.06	34.5434
3898.79	37.6053
3902.52	34.6513
3906.25	31.6836
3909.97	34.7488
3913.69	34.8083
3917.41	37.9088
3921.13	25.8387
3924.84	35.0415
3928.56	35.1169
3932.27	35.1838
3935.97	32.1716
3939.68	35.2899
3943.38	35.3618
3947.08	35.4293
3950.78	32.4021
3954.48	35.5368
3958.17	32.4852
3961.86	32.5109
3965.55	32.5328
3969.24	35.6411
3972.92	35.6524
3976.6	32.5632
3980.29	32.5664
3983.96	32.5627
3987.64	29.4595
3991.31	35.6671
3994.98	38.7895
3998.65	38.8254