File: Data/3-Raman/raw/bu20-b-ff4-fi03-l_150 (500nm)_633nm_edge_100%_x100_vis_lwd_h30um_60sx4_01.txt
#Acq. time (s)=	60
#Accumulations=	4
#Range (cm-¹)=	100...4000
#Windows=	1
#Auto scanning=	Off
#Autofocus=	Off
#Macrospot=	Off
#AutoExposure=	Off
#Spike filter=	Multiple accum.
#Delay time (s)=	2
#Binning=	1
#Readout mode=	Signal
#DeNoise=	Off
#ICS correction=	On
#Dark correction=	Off
#Inst. Process=	Off
#Detector Gain=	Best Dynamic
#Detector ADC=	50 kHz HS
#Detector temperature (°C)=	-60.09
#Instrument=	LabRAM HR Evol
#Detector=	SIN-EM FIVIS
#Objective=	x100_VIS_LWD
#Grating=	150 (500nm)
#ND Filter=	100%
#Laser=	633nm_Edge
#Hole=	30.0125
#Temperature=	39.9
#Range=	Visible
#StageXY=	75x50mm Scan+
#StageZ=	Z motor
#X (µm)=	0
#Y (µm)=	0
#Z (µm)=	-0.2
#Full time(mm:ss)=	4:05
#Project=	21_08_11
#Sample=	BU20
#Site=
#Title=	BU20-B-FF4-FI03-L_150 (500nm)_633nm_Edge_100%_x100_VIS_LWD_H30um_60sX4
#Remark=
#Date=	13.08.2021 14:27
#Acquired=	13.08.2021 14:27:06
100.12	215.886
106.638	209.38
113.152	195.27
119.66	183
126.162	174.518
132.659	171.102
139.151	166.339
145.637	157.115
152.118	152.688
158.594	154.368
165.064	146.795
171.529	134.377
177.989	128.275
184.441	131.996
190.89	115.225
197.334	118.873
203.772	122.959
210.205	117.19
216.631	114.92
223.054	134.562
229.471	177.231
235.881	187.494
242.288	144.251
248.689	130.916
255.083	128.613
261.474	147.529
267.858	160.761
274.238	202.792
280.613	221.423
286.982	187.837
293.346	142.227
299.704	117.82
306.058	111.718
312.406	117.285
318.749	154.312
325.086	202.696
331.418	161.147
337.746	119.93
344.068	108.9
350.384	117.33
356.697	123.828
363.003	132.801
369.304	124.519
375.601	101.856
381.892	98.9393
388.177	93.6224
394.457	88.4049
400.733	94.5524
407.004	90.9793
413.269	98.0764
419.529	102.31
425.784	121.254
432.034	150.886
438.279	153.351
444.518	154.218
450.753	147.833
456.982	135.61
463.207	108.949
469.426	101.086
475.64	94.545
481.85	87.1128
488.054	86.8104
494.253	89.9386
500.447	86.8511
506.635	89.3831
512.819	82.2888
518.999	84.867
525.173	80.3354
531.342	80.8349
537.505	80.119
543.664	78.4001
549.819	79.7348
555.966	82.948
562.111	81.3065
568.25	78.6454
574.383	79.3635
580.513	79.7264
586.636	95.7044
592.756	123.205
598.871	140.829
604.979	115.507
611.084	111.041
617.183	112.892
623.277	120.13
629.367	117.962
635.451	112.094
641.532	106.983
647.606	106.795
653.675	128.798
659.741	124.707
665.801	108.193
671.856	91.8329
677.907	79.7339
683.952	71.3674
689.992	65.2451
696.028	63.5203
702.059	69.2874
708.086	66.5883
714.107	66.8971
720.123	62.4709
726.135	63.6728
732.141	62.9358
738.143	65.3159
744.14	64.8956
750.133	63.26
756.12	62.6042
762.103	59.2589
768.081	60.0407
774.054	62.4045
780.023	61.6108
785.987	62.3304
791.946	58.935
797.9	62.0941
803.848	60.7956
809.793	59.1568
815.733	59.0462
821.669	63.2854
827.6	64.3739
833.525	64.9271
839.446	63.0998
845.363	61.9687
851.273	60.8483
857.181	61.3141
863.083	58.6521
868.98	63.5437
874.874	60.185
880.761	66.8814
886.645	58.9941
892.523	65.6117
898.398	62.3797
904.267	60.9734
910.133	66.4731
915.992	67.5573
921.849	62.7779
927.699	74.3676
933.545	71.9563
939.387	84.7524
945.224	98.3207
951.056	116.466
956.884	124.2
962.708	121.998
968.526	141.424
974.34	171.669
980.149	216.38
985.955	257.283
991.755	236.117
997.551	193.682
1003.34	168.634
1009.13	179.987
1014.91	203.378
1020.69	241.465
1026.46	226.984
1032.23	157.52
1037.99	119.18
1043.75	105.066
1049.51	98.9135
1055.26	87.7977
1061	83.0486
1066.74	86.9309
1072.48	88.8481
1078.21	101.401
1083.94	99.3651
1089.67	111.243
1095.38	128.603
1101.1	118.841
1106.81	85.0095
1112.51	72.8091
1118.22	69.1684
1123.91	62.5193
1129.6	69.5051
1135.29	70.0069
1140.98	83.2699
1146.65	91.2747
1152.33	101.568
1158	82.204
1163.66	64.7169
1169.32	55.1123
1174.98	58.9209
1180.63	53.2696
1186.28	49.9679
1191.93	51.9284
1197.56	49.0618
1203.2	46.9075
1208.83	47.4041
1214.46	47.2623
1220.08	47.811
1225.69	45.7155
1231.31	48.2608
1236.92	46.4309
1242.52	50.9237
1248.12	52.0076
1253.72	43.953
1259.31	48.3021
1264.89	49.9145
1270.48	49.1694
1276.05	47.3918
1281.63	50.9616
1287.2	45.2025
1292.76	52.4813
1298.33	44.4706
1303.88	45.1549
1309.43	45.8998
1314.98	46.3756
1320.53	45.524
1326.07	40.978
1331.6	45.208
1337.13	44.6875
1342.66	45.1544
1348.18	41.8321
1353.7	44.2997
1359.22	44.007
1364.73	45.052
1370.23	47.4379
1375.73	53.2408
1381.23	43.2934
1386.72	44.2989
1392.21	42.2375
1397.7	35.7785
1403.18	43.7126
1408.65	42.0678
1414.13	43.8716
1419.59	41.2121
1425.06	42.698
1430.52	39.6891
1435.97	40.4847
1441.42	41.278
1446.87	42.4294
1452.31	43.1914
1457.75	37.6235
1463.19	40.0779
1468.62	42.8666
1474.04	41.1083
1479.46	43.2197
1484.88	39.7416
1490.3	39.4324
1495.7	42.6558
1501.11	37.8144
1506.51	36.4905
1511.91	40.4789
1517.3	38.1231
1522.69	37.1836
1528.08	42.3122
1533.46	40.3224
1538.83	41.5262
1544.21	42.3437
1549.58	37.682
1554.94	37.6528
1560.3	41.925
1565.66	41.1651
1571.01	41.4802
1576.36	42.8789
1581.7	40.3671
1587.04	46.839
1592.38	36.0948
1597.71	38.6549
1603.04	43.0386
1608.37	42.4138
1613.68	41.4599
1619	40.8894
1624.31	43.2353
1629.62	43.0317
1634.93	43.5417
1640.23	38.4646
1645.52	43.6867
1650.81	43.3731
1656.1	41.934
1661.39	44.5371
1666.67	37.1518
1671.94	39.7411
1677.22	40.1048
1682.48	37.8742
1687.75	38.9469
1693.01	35.2361
1698.26	38.9432
1703.52	39.0949
1708.77	37.0354
1714.01	35.1205
1719.25	38.9456
1724.49	38.2592
1729.72	38.7131
1734.95	39.1672
1740.18	39.6179
1745.4	35.9312
1750.61	36.7371
1755.83	36.0234
1761.04	36.4169
1766.24	37.1861
1771.44	35.6969
1776.64	34.5916
1781.84	32.7471
1787.02	33.9412
1792.21	36.6774
1797.39	34.0967
1802.57	34.9545
1807.75	32.3667
1812.92	35.8911
1818.08	37.8936
1823.25	35.6623
1828.41	34.9711
1833.56	35.0553
1838.71	34.7503
1843.86	31.7023
1849	34.0922
1854.14	33.7466
1859.28	30.2849
1864.41	35.0424
1869.54	33.546
1874.67	34.7729
1879.79	30.0954
1884.9	36.0353
1890.02	33.2991
1895.13	34.877
1900.23	30.9517
1905.34	31.7965
1910.43	31.0783
1915.53	33.5647
1920.62	32.4269
1925.71	35.2771
1930.79	32.9495
1935.87	34.2089
1940.94	30.2523
1946.02	34.2983
1951.08	31.9173
1956.15	35.9474
1961.21	39.1702
1966.27	33.5475
1971.32	31.9263
1976.37	33.5137
1981.42	31.489
1986.46	34.2794
1991.5	26.6519
1996.53	31.0541
2001.56	35.0635
2006.59	31.8716
2011.61	33.099
2016.63	33.1258
2021.65	31.9394
2026.66	34.3897
2031.67	36.8613
2036.68	31.685
2041.68	34.1743
2046.68	31.4102
2051.67	34.3226
2056.66	32.7515
2061.65	34.0479
2066.63	32.0821
2071.61	37.4741
2076.59	34.679
2081.56	34.7444
2086.53	33.9737
2091.49	32.3736
2096.46	34.5093
2101.41	29.6193
2106.37	31.7728
2111.32	33.5291
2116.26	33.6333
2121.21	33.3182
2126.15	36.359
2131.09	34.7727
2136.02	33.1678
2140.95	31.1245
2145.87	35.0075
2150.79	32.9376
2155.71	28.7226
2160.63	31.7296
2165.54	31.7452
2170.45	30.4766
2175.35	28.3673
2180.25	28.8045
2185.15	30.0811
2190.04	32.6462
2194.93	31.3828
2199.82	31.8442
2204.7	33.1772
2209.58	32.3828
2214.46	32.4537
2219.33	29.9492
2224.2	31.3218
2229.06	35.2997
2233.92	34.0868
2238.78	31.561
2243.64	31.2042
2248.49	32.1597
2253.34	31.8006
2258.18	30.123
2263.02	30.6379
2267.86	32.4656
2272.69	32.074
2277.52	33.4419
2282.35	31.6953
2287.17	27.7137
2291.99	29.9391
2296.81	30.3921
2301.62	31.3048
2306.43	28.6799
2311.24	32.7445
2316.04	31.926
2320.84	31.1123
2325.63	29.8465
2330.43	28.5785
2335.21	31.3744
2340	31.4732
2344.78	32.0354
2349.56	30.7843
2354.33	32.2599
2359.11	31.4302
2363.87	27.8131
2368.64	30.1776
2373.4	33.9327
2378.16	30.7623
2382.91	33.1221
2387.66	30.8339
2392.41	28.5297
2397.16	27.1417
2401.9	29.9259
2406.64	30.8468
2411.37	29.949
2416.1	30.5099
2420.83	30.6606
2425.55	30.705
2430.27	31.7208
2434.99	31.3389
2439.7	31.4347
2444.41	30.1057
2449.12	30.672
2453.83	30.2857
2458.53	28.4608
2463.22	29.9827
2467.92	35.357
2472.61	27.2485
2477.3	29.2543
2481.98	31.2679
2486.66	29.8792
2491.34	30.4274
2496.01	40.2488
2500.68	30.5509
2505.35	28.1571
2510.01	30.1627
2514.67	25.7823
2519.33	32.7022
2523.99	28.815
2528.64	29.8449
2533.28	33.847
2537.93	31.4367
2542.57	34.4774
2547.21	31.073
2551.84	36.1239
2556.47	29.7059
2561.1	30.7649
2565.73	28.3302
2570.35	30.9167
2574.97	32.0047
2579.58	30.5614
2584.19	32.1295
2588.8	28.1151
2593.41	33.2067
2598.01	26.6576
2602.61	30.7617
2607.2	31.816
2611.8	33.3731
2616.38	29.83
2620.97	25.7738
2625.55	31.9311
2630.13	30.4422
2634.71	29.9977
2639.28	29.0607
2643.85	32.2478
2648.42	29.7636
2652.98	30.8951
2657.54	27.3132
2662.1	29.4415
2666.65	27.9121
2671.2	30.0521
2675.75	29.0892
2680.29	32.3925
2684.84	27.7779
2689.37	30.5604
2693.91	32.2763
2698.44	31.2589
2702.97	32.3974
2707.49	32.459
2712.02	30.9024
2716.53	28.2777
2721.05	32.109
2725.56	32.1588
2730.07	25.1626
2734.58	27.891
2739.08	31.16
2743.58	30.1118
2748.08	30.701
2752.57	30.2408
2757.06	26.4866
2761.55	30.3541
2766.04	30.9592
2770.52	32.664
2775	33.2869
2779.47	30.6193
2783.94	28.5092
2788.41	26.9392
2792.88	28.6966
2797.34	27.6602
2801.8	28.29
2806.26	27.2275
2810.71	29.5293
2815.16	29.0133
2819.61	30.7497
2824.05	31.3656
2828.49	30.8515
2832.93	34.2993
2837.37	26.9666
2841.8	26.4371
2846.23	27.0509
2850.65	31.6668
2855.08	35.1745
2859.5	28.955
2863.91	31.9122
2868.33	31.4364
2872.74	30.3758
2877.15	31.0519
2881.55	31.7392
2885.95	31.2696
2890.35	32.5502
2894.75	31.4812
2899.14	31.0095
2903.53	45.9305
2907.91	30.6138
2912.3	30.6928
2916.68	30.7601
2921.05	32.6323
2925.43	30.3171
2929.8	29.2015
2934.17	40.1509
2938.53	31.7665
2942.9	28.7948
2947.26	30.6594
2951.61	31.9201
2955.97	30.139
2960.32	29.5716
2964.66	30.8389
2969.01	30.8936
2973.35	30.3384
2977.69	32.2376
2982.03	31.6865
2986.36	33.6139
2990.69	33.0857
2995.01	31.9388
2999.34	30.7927
3003.66	34.639
3007.98	27.868
3012.29	36.7485
3016.6	33.724
3020.91	34.48
3025.22	29.5135
3029.52	37.8646
3033.82	33.4866
3038.12	37.3788
3042.41	31.6981
3046.71	34.3208
3051	36.3071
3055.28	36.3713
3059.56	39.6616
3063.84	29.3946
3068.12	33.3293
3072.39	37.2774
3076.67	34.7483
3080.93	36.1146
3085.2	41.4054
3089.46	40.2017
3093.72	38.3542
3097.98	42.4271
3102.23	40.5881
3106.48	39.4123
3110.73	39.5648
3114.98	47.7309
3119.22	40.5472
3123.46	45.4312
3127.7	48.3396
3131.93	47.8953
3136.16	46.7628
3140.39	46.2921
3144.61	52.6859
3148.84	49.4367
3153.06	51.6802
3157.27	46.9641
3161.49	56.175
3165.7	50.7375
3169.91	56.479
3174.11	55.2304
3178.31	51.1051
3182.51	55.417
3186.71	63.2627
3190.9	59.0866
3195.1	59.188
3199.28	57.9202
3203.47	63.8357
3207.65	60.5032
3211.83	71.5307
3216.01	62.4546
3220.18	68.5094
3224.36	72.4227
3228.52	58.0986
3232.69	55.3905
3236.85	66.6257
3241.01	64.6705
3245.17	63.4693
3249.33	67.4337
3253.48	67.6251
3257.63	64.0334
3261.77	68.0029
3265.92	70.5306
3270.06	68.5777
3274.2	75.71
3278.33	70.5219
3282.47	73.7205
3286.59	69.2768
3290.72	73.2452
3294.85	73.375
3298.97	65.0389
3303.09	68.2598
3307.2	66.0769
3311.32	63.8747
3315.43	80.278
3319.54	70.3295
3323.64	75.9464
3327.74	76.9236
3331.84	70.8938
3335.94	75.8657
3340.04	72.9451
3344.13	72.3144
3348.22	83.523
3352.3	100.334
3356.39	79.8709
3360.47	78.4562
3364.54	87.4133
3368.62	77.1972
3372.69	89.3781
3376.76	88.7193
3380.83	96.0804
3384.89	89.7648
3388.96	93.9017
3393.02	95.6136
3397.07	90.8996
3401.13	99.9279
3405.18	100.831
3409.23	86.3371
3413.27	95.325
3417.31	96.2139
3421.36	97.0971
3425.39	102.856
3429.43	100.522
3433.46	106.358
3437.49	89.3855
3441.52	99.3596
3445.54	88.0998
3449.56	91.6105
3453.58	94.3248
3457.6	92.9748
3461.61	94.9578
3465.63	82.8099
3469.63	83.9311
3473.64	94.2098
3477.64	91.1387
3481.64	91.4129
3485.64	84.917
3489.64	88.5406
3493.63	82.8298
3497.62	87.2776
3501.61	90.0142
3505.59	75.6355
3509.58	85.9851
3513.56	86.898
3517.53	78.3835
3521.51	91.2848
3525.48	75.9082
3529.45	71.6615
3533.42	73.4797
3537.38	76.2168
3541.34	72.9383
3545.3	60.0978
3549.26	64.5175
3553.21	63.6835
3557.16	62.0054
3561.11	68.1599
3565.06	74.3537
3569	65.8023
3572.94	64.1874
3576.88	65.2144
3580.82	75.929
3584.75	72.6347
3588.68	66.6679
3592.61	67.7474
3596.54	59.0628
3600.46	56.5468
3604.38	49.5476
3608.3	55.0269
3612.21	51.5516
3616.13	55.2493
3620.04	50.8493
3623.94	49.0948
3627.85	46.4223
3631.75	46.4405
3635.65	42.8568
3639.55	46.5185
3643.44	47.51
3647.34	36.7331
3651.23	44.0164
3655.12	43.1531
3659	40.464
3662.88	41.4042
3666.76	37.8003
3670.64	38.7503
3674.52	36.9714
3678.39	35.207
3682.26	34.3673
3686.13	38.1349
3689.99	34.5559
3693.85	31.8786
3697.71	41.2247
3701.57	35.7632
3705.43	31.199
3709.28	35.956
3713.13	33.2446
3716.98	36.1377
3720.82	33.3908
3724.66	33.4532
3728.5	29.7348
3732.34	27.8987
3736.18	31.7422
3740.01	31.7989
3743.84	32.8011
3747.67	33.8012
3751.49	34.7944
3755.32	31.9629
3759.14	32.9372
3762.96	34.8632
3766.77	31.056
3770.58	34.9044
3774.4	33.021
3778.2	34.0105
3782.01	44.6072
3785.81	32.1874
3789.61	33.1942
3793.41	39.0255
3797.21	46.8244
3801	32.4089
3804.79	32.4798
3808.58	38.3863
3812.37	30.6769
3816.15	34.6415
3819.93	34.7092
3823.71	34.7705
3827.49	36.7863
3831.26	34.8879
3835.04	28.0609
3838.8	30.0797
3842.57	27.1753
3846.34	41.059
3850.1	32.1751
3853.86	37.1444
3857.62	32.2026
3861.37	41.1248
3865.12	34.2222
3868.87	29.3338
3872.62	35.3393
3876.37	33.369
3880.11	31.3964
3883.85	35.4096
3887.59	31.4492
3891.33	33.4828
3895.06	35.5446
3898.79	40.6137
3902.52	33.6469
3906.25	32.6894
3909.97	32.7344
3913.69	29.7636
3917.41	35.887
3921.13	34.9582
3924.84	34.0258
3928.56	30.0275
3932.27	33.1442
3935.97	33.193
3939.68	36.3128
3943.38	37.4117
3947.08	39.537
3950.78	35.488
3954.48	36.5668
3958.17	31.4539
3961.86	35.6072
3965.55	34.5984
3969.24	31.5088
3972.92	36.6858
3976.6	30.4957
3980.29	36.7018
3983.96	31.529
3987.64	35.6615
3991.31	34.6333
3994.98	32.5832
3998.65	33.6487