File: Data/3-Raman/raw/bu20-j-ff1-fi03-v_1800 (450-850nm)_532nm_edge_100%_x100_vis_lwd_h30um_60sx2_01.txt
#Acq. time (s)=	60
#Accumulations=	2
#Range (cm-¹)=	1200...2360
#Windows=	3
#Auto scanning=	Off
#Autofocus=	Off
#Macrospot=	Off
#AutoExposure=	Off
#Spike filter=	Multiple accum.
#Delay time (s)=	2
#Binning=	1
#Readout mode=	Signal
#DeNoise=	Off
#ICS correction=	On
#Dark correction=	Off
#Inst. Process=	Off
#Detector Gain=	Best Dynamic
#Detector ADC=	50 kHz HS
#Detector temperature (°C)=	-60.09
#Instrument=	LabRAM HR Evol
#Detector=	SIN-EM FIVIS
#Objective=	x100_VIS_LWD
#Grating=	1800 (450-850nm)
#ND Filter=	100%
#Laser=	532nm_Edge
#Hole=	30.0125
#Temperature=	0
#Range=	Visible
#StageXY=	75x50mm Scan+
#StageZ=	Z motor
#X (µm)=	0
#Y (µm)=	0
#Z (µm)=	-19.4
#Full time(mm:ss)=	6:25
#Project=	21_08_11
#Sample=	BU20
#Site=
#Title=	BU20-J-FF1-FI03-V_1800 (450-850nm)_532nm_Edge_100%_x100_VIS_LWD_H30um_60sX2
#Remark=
#Date=	11.08.2021 17:05
#Acquired=	11.08.2021 17:05:31
1201.69	34.9324
1202.8	33.9181
1203.91	34.9342
1205.02	35.9836
1206.14	34.8442
1207.25	36.9369
1208.36	32.6238
1209.47	39.0206
1210.58	42.1729
1211.69	35.7153
1212.8	32.4812
1213.91	35.6655
1215.02	33.534
1216.13	34.562
1217.24	35.5787
1218.35	33.4273
1219.45	33.4118
1220.56	35.5275
1221.67	37.6111
1222.78	38.5981
1223.89	39.5994
1225	42.7541
1226.1	43.8169
1227.21	42.69
1228.32	55.1766
1229.43	59.5949
1230.53	68.9677
1231.64	73.031
1232.74	96.1193
1233.85	98.2383
1234.96	90.9277
1236.06	75.1686
1237.17	66.6893
1238.27	56.1091
1239.38	51.8877
1240.48	47.6958
1241.59	48.7282
1242.69	43.5031
1243.8	44.5546
1244.9	43.4801
1246.01	50.767
1247.11	51.8066
1248.21	49.6779
1249.32	58.0466
1250.42	65.3257
1251.52	63.189
1252.63	61.053
1253.73	60.0203
1254.83	55.8676
1255.93	54.8271
1257.03	41.2526
1258.14	52.7228
1259.24	44.364
1260.34	46.4384
1261.44	45.4112
1262.54	59.9991
1263.64	90.4163
1264.74	84.1334
1265.84	47.5437
1266.94	35.0324
1268.04	34.0355
1269.14	33.0048
1270.24	39.2536
1271.34	39.2392
1272.44	35.0935
1273.54	30.9359
1274.64	38.2853
1275.74	35.1614
1276.84	28.8858
1277.93	29.9624
1279.03	36.2927
1280.13	46.8037
1281.23	68.9474
1282.33	136.327
1283.42	531.22
1284.52	1225.05
1285.62	173.229
1286.71	57.3795
1287.81	48.9343
1288.91	40.5319
1290	37.397
1291.1	34.2296
1292.19	32.1235
1293.29	31.0895
1294.38	34.2709
1295.48	33.2728
1296.57	30.1227
1297.67	30.0976
1298.76	27.9776
1299.86	31.1472
1300.95	27.9799
1302.04	27.9926
1303.14	25.8718
1304.23	25.8706
1305.32	30.0734
1306.42	24.7831
1307.51	29.0046
1308.6	26.9004
1309.69	27.9666
1310.79	39.5762
1311.88	25.868
1312.97	27.9758
1314.06	25.8615
1315.15	25.8737
1316.24	29.0427
1317.33	27.992
1318.43	24.827
1319.52	26.9389
1320.61	31.1539
1321.7	26.9013
1322.79	30.0467
1323.88	26.8879
1324.97	27.9393
1326.06	24.7252
1327.15	28.9678
1328.23	29.0104
1329.32	24.7932
1330.41	23.7243
1331.5	28.9542
1332.59	25.7631
1333.68	26.7827
1334.76	25.7088
1335.85	28.8372
1336.94	28.8247
1338.03	18.3299
1339.11	28.7955
1340.2	29.8474
1341.29	23.5588
1342.37	24.5845
1343.46	24.5771
1344.54	25.6179
1345.63	28.7236
1346.72	27.6396
1347.8	26.5777
1348.89	25.5206
1349.97	26.5431
1351.06	27.5593
1352.14	26.5233
1353.23	29.71
1354.31	25.4558
1355.39	25.4512
1356.48	28.562
1357.56	26.4707
1358.64	25.4138
1359.73	25.3935
1360.81	29.5215
1361.89	31.5838
1362.98	26.4074
1364.06	30.5567
1365.14	34.6756
1366.22	27.4038
1367.3	32.5563
1368.38	30.4979
1369.47	78.0506
1370.55	29.4432
1371.63	32.4989
1372.71	33.4986
1373.79	28.334
1374.87	32.4472
1375.95	34.5062
1377.03	34.4738
1378.11	32.4698
1379.19	38.6529
1380.27	40.6402
1381.35	44.7143
1382.43	39.5076
1383.51	49.7226
1384.59	77.4419
1385.66	150.426
1386.74	715.109
1387.82	2185.41
1388.9	199.697
1389.98	78.4362
1391.05	52.7778
1392.13	41.4685
1393.21	43.4969
1394.28	40.4162
1395.36	37.3631
1396.44	33.2577
1397.51	35.287
1398.59	34.2747
1399.66	27.1233
1400.74	37.3767
1401.82	36.3856
1402.89	36.4443
1403.97	31.2929
1405.04	35.3793
1406.12	43.5598
1407.19	56.8988
1408.27	116.391
1409.34	132.842
1410.41	48.6915
1411.49	36.3679
1412.56	29.2579
1413.63	26.1474
1414.71	32.3399
1415.78	31.3198
1416.85	29.2793
1417.92	28.2591
1419	31.3433
1420.07	29.2663
1421.14	29.2523
1422.21	27.2377
1423.28	23.0605
1424.36	28.1846
1425.43	27.1865
1426.5	28.1923
1427.57	27.1348
1428.64	30.2088
1429.71	29.2062
1430.78	26.1663
1431.85	23.0851
1432.92	23.0579
1433.99	28.1687
1435.06	24.0809
1436.13	22.0264
1437.2	23.0442
1438.26	32.2691
1439.33	24.0848
1440.4	22.0471
1441.47	26.1428
1442.54	23.075
1443.61	24.0898
1444.67	27.1893
1445.74	23.079
1446.81	18.9704
1447.87	23.0697
1448.94	25.1272
1450.01	22.0389
1451.07	21.0071
1452.14	18.9538
1453.21	24.0837
1454.27	19.9821
1455.34	19.9839
1456.4	18.9576
1457.47	19.9752
1458.53	18.9537
1459.6	19.978
1460.66	22.0191
1461.73	23.0297
1462.79	23.01
1463.86	19.9504
1464.92	20.9431
1465.98	20.9262
1467.05	22.9543
1468.11	20.9108
1469.17	20.9022
1470.24	19.869
1471.3	18.8401
1472.36	16.8005
1473.42	21.8815
1474.48	21.8829
1475.55	20.861
1476.61	19.8336
1477.67	21.8624
1478.73	20.8322
1479.79	18.7826
1480.85	19.7826
1481.91	19.7939
1482.97	16.755
1484.04	21.8138
1485.1	19.7117
1486.15	24.8154
1487.22	17.726
1488.28	17.7128
1489.33	19.7277
1490.39	19.7218
1491.45	20.7254
1492.51	20.7241
1493.57	20.722
1494.63	18.7007
1495.69	18.6796
1496.74	17.6624
1497.8	19.6794
1498.86	20.6918
1499.92	18.6774
1500.97	17.6617
1502.03	20.6853
1503.09	20.6704
1504.14	18.6565
1505.2	20.6633
1506.26	21.6597
1507.31	18.6426
1508.37	20.6564
1509.42	18.6425
1510.48	21.6559
1511.53	20.6144
1512.59	16.5683
1513.64	17.5769
1514.7	18.5737
1515.75	19.5567
1516.81	18.5485
1517.86	21.5632
1518.92	18.5599
1519.97	20.5643
1521.02	16.5562
1522.08	19.5601
1523.13	16.536
1524.18	17.5234
1525.24	18.5301
1526.29	18.5441
1527.34	17.5369
1528.39	16.5283
1529.44	19.5281
1530.5	17.5321
1531.55	18.5374
1532.6	16.5422
1533.65	18.5584
1534.7	18.5528
1535.75	14.5245
1536.8	19.5098
1537.85	17.496
1538.9	18.5046
1539.95	17.542
1541	17.5426
1542.05	26.538
1543.1	19.5088
1544.15	18.5053
1545.2	16.524
1546.25	17.5296
1547.3	16.5325
1548.35	18.5341
1549.39	14.4987
1550.44	17.5851
1551.49	21.5757
1552.54	18.5781
1553.58	18.5542
1554.63	15.5279
1555.68	18.5339
1556.73	16.5292
1557.77	17.5225
1558.82	16.5024
1559.87	17.491
1560.91	14.4907
1561.96	16.5025
1563	16.5
1564.05	15.5119
1565.09	15.445
1566.14	19.4933
1567.18	17.5076
1568.23	15.4994
1569.27	19.4861
1570.32	16.4902
1571.36	14.4848
1572.41	19.4701
1573.45	18.4629
1574.49	16.4813
1575.54	17.4881
1576.58	14.4792
1577.62	16.4543
1578.67	16.4492
1579.71	14.4593
1580.75	13.4586
1581.79	16.4391
1582.84	14.4429
1583.88	16.4341
1584.92	16.4351
1585.96	18.4168
1587	16.4171
1588.04	15.4238
1589.08	15.4316
1590.13	16.4307
1591.17	15.4353
1592.21	15.422
1593.25	15.4022
1594.29	13.4098
1595.33	17.3818
1596.37	15.3954
1597.41	17.3861
1598.44	14.3947
1599.48	17.3607
1600.52	19.3279
1601.56	10.3953
1602.6	15.3322
1603.64	17.3025
1604.67	16.315
1605.71	12.4766
1606.75	13.1619
1607.79	16.7889
1608.82	14.4005
1609.86	17.7769
1610.9	14.5446
1611.93	14.8457
1612.97	14.4394
1614.01	14.6099
1615.04	16.482
1616.08	14.4349
1617.12	14.5407
1618.15	15.3342
1619.19	14.7733
1620.22	13.9282
1621.26	12.9543
1622.29	14.6344
1623.33	14.7084
1624.36	14.2152
1625.39	12.3994
1626.43	13.8051
1627.46	14.3914
1628.5	14.7472
1629.53	13.9947
1630.41	15.2666
1631.46	13.3033
1632.5	17.2581
1633.55	14.29
1634.59	12.3209
1635.64	15.2732
1636.68	13.2949
1637.73	13.2902
1638.77	15.2574
1639.82	14.2722
1640.86	12.3087
1641.91	12.3051
1642.95	16.2409
1644	14.2658
1645.04	17.2204
1646.08	15.2494
1647.12	15.244
1648.17	22.1334
1649.21	15.2582
1650.25	17.2362
1651.29	15.2745
1652.34	14.2875
1653.38	17.2433
1654.42	17.2486
1655.46	15.2939
1656.5	14.3133
1657.54	13.3222
1658.59	14.3019
1659.63	17.2513
1660.67	16.2755
1661.71	14.3018
1662.75	14.3303
1663.79	13.3265
1664.83	15.3103
1665.87	16.3135
1666.91	14.313
1667.95	14.3044
1668.99	17.2853
1670.02	14.324
1671.06	14.3313
1672.1	16.3107
1673.14	14.3349
1674.18	17.3091
1675.22	11.3809
1676.25	13.3614
1677.29	11.3798
1678.33	14.3377
1679.37	15.3201
1680.4	13.3383
1681.44	14.3247
1682.48	11.3608
1683.51	14.3234
1684.55	18.2686
1685.58	15.3058
1686.62	12.3488
1687.66	13.3322
1688.69	15.2983
1689.73	14.3002
1690.76	16.281
1691.8	14.3107
1692.83	14.3004
1693.87	13.3015
1694.9	14.2841
1695.94	14.2893
1696.97	14.2843
1698	14.2718
1699.04	13.2835
1700.07	16.233
1701.1	13.278
1702.14	13.268
1703.17	13.2641
1704.2	14.2486
1705.24	14.2474
1706.27	13.2553
1707.3	12.2609
1708.33	14.2037
1709.36	10.2789
1710.4	12.2393
1711.43	16.1618
1712.46	13.2103
1713.49	16.1218
1714.52	13.1854
1715.55	15.1444
1716.58	13.1793
1717.61	12.1818
1718.64	15.0912
1719.67	14.1188
1720.7	12.1629
1721.73	13.1244
1722.76	15.0546
1723.79	14.0786
1724.82	16.0045
1725.85	15.0205
1726.88	13.075
1727.9	14.0418
1728.93	13.0273
1729.96	14.0001
1730.99	12.0807
1732.02	14.977
1733.04	13.0328
1734.07	12.0503
1735.1	12.9986
1736.13	15.8789
1737.15	13.9466
1738.18	12.9749
1739.21	11.9991
1740.23	14.8565
1741.26	13.886
1742.28	13.8809
1743.31	12.9196
1744.33	11.9562
1745.36	15.7812
1746.38	14.8103
1747.41	13.8417
1748.44	11.9329
1749.46	12.8956
1750.48	14.8167
1751.51	11.9438
1752.53	13.8418
1753.56	14.7854
1754.58	15.7284
1755.6	11.9074
1756.63	11.8934
1757.65	13.7934
1758.67	13.7977
1759.69	16.6515
1760.72	12.839
1761.74	13.7828
1762.76	11.8852
1763.78	13.7904
1764.81	18.5621
1765.83	13.8049
1766.85	13.802
1767.87	12.8434
1768.89	14.7277
1769.91	14.7247
1770.93	13.7835
1771.95	17.5969
1772.97	15.7037
1773.99	16.6609
1775.01	13.8131
1776.03	16.6833
1777.05	13.8164
1778.07	14.7584
1779.09	15.6974
1780.11	13.8014
1781.13	12.8531
1782.15	12.8618
1783.17	14.775
1784.18	13.8322
1785.2	13.8335
1786.22	12.8797
1787.24	17.6719
1788.25	21.5396
1789.27	14.8541
1790.29	13.9006
1791.31	16.7598
1792.32	21.5515
1793.34	14.8509
1794.36	17.7238
1795.37	18.7186
1796.39	16.8119
1797.4	17.7847
1798.42	18.7504
1799.44	16.8175
1800.45	19.6913
1801.47	16.8099
1802.48	15.8579
1803.5	16.8301
1804.51	16.8408
1805.53	15.8938
1806.54	15.9022
1807.55	17.8308
1808.57	14.9414
1809.58	18.8006
1810.59	18.7994
1811.61	17.8354
1812.62	13.9869
1813.63	17.8566
1814.65	16.9094
1815.66	17.8813
1816.67	16.9169
1817.68	18.8345
1818.7	17.8783
1819.71	17.8863
1820.72	19.8295
1821.73	18.8731
1822.74	16.9418
1823.75	18.874
1824.76	16.9449
1825.77	21.7899
1826.78	15.9823
1827.8	17.9245
1828.81	17.9179
1829.82	15.9764
1830.83	21.7866
1831.83	20.8297
1832.84	16.9624
1833.85	17.9356
1834.86	16.9345
1835.87	17.9058
1836.88	16.9557
1837.89	16.9074
1838.9	18.8938
1839.91	17.9108
1840.91	17.8726
1841.92	18.8104
1842.93	16.8812
1843.94	18.8091
1844.94	18.8089
1845.95	18.8383
1846.96	17.8114
1847.96	20.7122
1848.97	16.8445
1849.98	17.7844
1850.98	17.7684
1851.99	17.7643
1852.99	13.9217
1854	17.7442
1855.01	17.7284
1856.01	19.635
1857.02	19.6316
1858.02	18.6622
1859.02	18.6441
1860.03	20.557
1861.03	16.7449
1862.04	18.656
1863.04	18.6387
1864.04	15.7595
1865.05	19.5605
1866.05	16.6712
1867.05	16.6446
1868.06	17.5866
1869.06	19.488
1870.06	19.484
1871.07	18.5305
1872.07	19.4707
1873.07	15.6633
1874.07	18.4982
1875.07	19.4255
1876.08	17.5031
1877.08	16.5274
1878.08	20.3454
1879.08	18.4736
1880.08	16.5692
1881.08	18.4496
1882.08	19.3532
1883.08	17.5316
1884.08	17.4425
1885.08	18.3994
1886.08	15.5833
1887.08	17.4542
1888.08	20.2598
1889.08	16.474
1890.08	15.5383
1891.08	17.423
1892.07	17.4193
1893.07	16.4542
1894.07	13.6243
1895.07	18.3219
1896.07	17.3923
1897.07	16.4613
1898.06	19.2791
1899.06	13.6252
1900.06	15.4993
1901.05	19.2682
1902.05	16.4621
1903.05	16.4562
1904.04	18.3334
1905.04	17.391
1906.04	16.437
1907.03	15.4948
1908.03	16.4414
1909.02	19.2717
1910.02	18.3556
1911.01	17.4265
1912.01	19.3079
1913	18.3673
1914	16.5009
1914.99	17.457
1915.99	17.4546
1916.98	14.6138
1917.98	17.4447
1918.97	15.5773
1919.96	15.5912
1920.96	17.4914
1921.95	12.7678
1922.94	17.4882
1923.94	13.6999
1924.93	16.537
1925.92	14.6633
1926.91	13.7299
1927.9	15.6313
1928.9	12.7964
1929.89	13.7599
1930.88	14.7165
1931.87	14.709
1932.86	13.7545
1933.85	13.7797
1934.84	14.7744
1935.83	16.6784
1936.83	16.6669
1937.82	14.7513
1938.81	14.7619
1939.8	13.8169
1940.79	14.7919
1941.78	13.8235
1942.76	13.844
1943.75	13.8397
1944.74	13.8522
1945.73	11.9521
1946.72	12.9113
1947.71	14.8214
1948.7	11.9556
1949.69	12.9254
1950.67	13.9057
1951.66	12.0023
1952.65	13.9298
1953.64	15.8299
1954.62	13.8906
1955.61	15.8237
1956.6	14.8845
1957.58	14.8956
1958.57	15.8574
1959.56	12.9684
1960.54	13.9198
1961.53	12.956
1962.51	15.8381
1963.5	13.9213
1964.48	17.7637
1965.47	13.9255
1966.46	13.9366
1967.44	12.0165
1968.43	13.9379
1969.41	12.0022
1970.39	12.9529
1971.38	15.8256
1972.36	13.9103
1973.35	12.9421
1974.33	13.8984
1975.31	12.9459
1976.3	12.9499
1977.28	13.9057
1978.26	15.8153
1979.24	12.9401
1980.23	14.853
1981.21	11.015
1982.19	13.8839
1983.17	12.9149
1984.16	12.9105
1985.14	13.8492
1986.12	14.7136
1987.1	12.0618
1988.08	12.8355
1989.06	13.3666
1990.04	12.614
1991.02	12.0674
1992	11.7293
1992.98	13.6544
1993.96	12.5078
1994.94	12.9213
1995.92	11.3586
1996.9	12.6866
1997.88	13.7326
1998.86	12.3614
1999.84	13.4217
2000.82	12.4615
2001.8	13.1267
2002.78	11.2556
2003.76	11.8372
2004.73	13.8418
2005.71	13.2616
2006.69	13.1005
2007.67	12.2557
2008.64	14.3679
2009.62	11.7791
2010.52	12.7149
2011.51	10.8298
2012.5	13.6492
2013.48	15.5081
2014.47	12.669
2015.46	16.431
2016.45	11.7486
2017.44	12.6785
2018.43	9.84575
2019.41	14.5185
2020.4	12.6431
2021.39	11.7076
2022.38	10.7635
2023.36	13.5587
2024.35	11.6756
2025.34	12.5943
2026.32	14.4729
2027.31	13.5652
2028.3	14.4841
2029.28	14.4885
2030.27	13.5142
2031.25	15.3954
2032.24	11.6758
2033.23	13.5591
2034.21	10.7301
2035.2	12.6121
2036.18	14.489
2037.17	13.5575
2038.15	12.6158
2039.13	10.7397
2040.12	11.6612
2041.1	14.4501
2042.09	11.6468
2043.07	9.78679
2044.05	10.7285
2045.04	10.7271
2046.02	12.6205
2047	11.6638
2047.99	13.5181
2048.97	12.5944
2049.95	11.676
2050.93	12.6088
2051.92	13.5416
2052.9	13.5493
2053.88	10.7574
2054.86	13.5619
2055.84	13.5555
2056.82	11.6846
2057.8	12.6262
2058.78	12.637
2059.77	11.701
2060.75	12.6377
2061.73	13.5767
2062.71	11.7104
2063.69	12.6537
2064.67	10.7858
2065.65	13.6137
2066.63	12.6801
2067.61	12.6871
2068.58	12.6913
2069.56	12.6782
2070.54	14.5803
2071.52	11.7721
2072.5	12.7104
2073.48	13.6526
2074.45	12.7196
2075.43	12.7415
2076.41	10.8552
2077.39	12.7306
2078.37	11.794
2079.34	8.97319
2080.32	14.6474
2081.3	14.6445
2082.27	12.7575
2083.25	11.8117
2084.23	13.7021
2085.2	12.7578
2086.18	14.6613
2087.15	13.7223
2088.13	11.8309
2089.11	14.6771
2090.08	12.7897
2091.06	12.7954
2092.03	14.7093
2093	13.7762
2093.98	12.8352
2094.95	12.8313
2095.93	13.775
2096.9	14.7188
2097.88	11.8656
2098.85	14.7102
2099.82	12.8121
2100.8	12.8202
2101.77	9.97295
2102.74	14.7157
2103.72	11.8657
2104.69	12.8221
2105.66	13.7819
2106.63	12.8354
2107.6	11.878
2108.58	12.8178
2109.55	11.8747
2110.52	11.8749
2111.49	12.8208
2112.46	12.8229
2113.43	12.8317
2114.4	13.7807
2115.38	14.7282
2116.35	12.8205
2117.32	13.7681
2118.29	12.8071
2119.26	14.692
2120.23	12.7921
2121.2	11.8536
2122.17	13.761
2123.14	13.7661
2124.1	13.7573
2125.07	11.84
2126.04	14.6659
2127.01	14.6555
2127.98	14.6515
2128.95	15.5951
2129.92	16.5367
2130.88	13.6957
2131.85	15.5769
2132.82	10.8515
2133.79	13.6843
2134.75	11.7962
2135.72	14.6178
2136.69	12.7274
2137.65	14.6168
2138.62	11.7884
2139.59	13.6629
2140.55	13.6567
2141.52	16.474
2142.49	13.654
2143.45	12.6859
2144.42	13.6403
2145.38	14.5735
2146.35	10.809
2147.31	15.5009
2148.28	12.6766
2149.24	17.3538
2150.21	15.4654
2151.17	14.5334
2152.14	16.412
2153.1	12.6535
2154.06	15.4518
2155.03	16.3622
2155.99	18.2169
2156.95	16.3489
2157.92	14.4882
2158.88	14.4843
2159.84	15.4054
2160.8	17.2628
2161.77	16.3261
2162.73	17.2549
2163.69	15.3827
2164.65	19.1008
2165.61	16.3078
2166.58	16.2982
2167.54	18.1392
2168.5	17.1998
2169.46	17.2171
2170.42	19.0902
2171.38	15.3434
2172.34	17.1887
2173.3	19.9767
2174.26	15.3353
2175.22	19.0501
2176.18	17.186
2177.14	19.0438
2178.1	19.037
2179.06	20.8912
2180.02	19.0337
2180.98	17.1731
2181.94	18.0939
2182.9	19.01
2183.85	18.9949
2184.81	17.1448
2185.77	18.0819
2186.73	19.0299
2187.69	19.9671
2188.64	19.0227
2189.6	18.0766
2190.56	17.1524
2191.52	19.939
2192.47	19.0202
2193.43	18.111
2194.39	19.0573
2195.34	19.9752
2196.3	19.0233
2197.26	19.0142
2198.21	19.9548
2199.17	18.1221
2200.12	20.0178
2201.08	20.028
2202.03	19.0225
2202.99	19.9903
2203.94	20.9797
2204.9	20.9325
2205.85	24.6439
2206.81	17.2022
2207.76	20.9394
2208.71	19.0906
2209.67	18.1611
2210.62	18.1723
2211.57	18.1865
2212.53	18.1877
2213.48	20.9784
2214.43	19.1354
2215.39	20.0737
2216.34	20.0723
2217.29	21.0073
2218.24	19.1429
2219.2	20.0896
2220.15	21.9623
2221.1	18.2124
2222.05	21.9364
2223	21.0149
2223.95	21.0393
2224.91	21.9956
2225.86	18.2693
2226.81	18.283
2227.76	22.0356
2228.71	20.1557
2229.66	19.2318
2230.61	21.1254
2231.56	18.3252
2232.51	18.3398
2233.46	21.1766
2234.41	21.1739
2235.36	19.2774
2236.31	21.1628
2237.25	18.3581
2238.2	19.3261
2239.15	20.2823
2240.1	21.2097
2241.05	19.3432
2242	17.4625
2242.94	19.3502
2243.89	21.2338
2244.84	20.3157
2245.79	20.3335
2246.73	19.3995
2247.68	19.4015
2248.63	17.505
2249.57	23.1886
2250.52	18.4424
2251.47	18.4366
2252.41	20.3443
2253.36	19.427
2254.3	20.3861
2255.25	19.4383
2256.2	17.5526
2257.14	18.514
2258.09	18.5196
2259.03	18.5292
2259.98	15.6854
2260.92	17.601
2261.86	16.6546
2262.81	20.4794
2263.75	19.5557
2264.7	16.7126
2265.64	16.7159
2266.58	15.7464
2267.53	18.5969
2268.47	16.6891
2269.41	19.5716
2270.36	14.8131
2271.3	18.6489
2272.24	15.786
2273.18	17.7038
2274.13	17.708
2275.07	20.5853
2276.01	17.7242
2276.95	14.8651
2277.89	16.8064
2278.84	18.7273
2279.78	16.7868
2280.72	17.7346
2281.66	19.6516
2282.6	16.7899
2283.54	17.778
2284.48	17.798
2285.42	16.8383
2286.36	18.7601
2287.3	18.7818
2288.24	15.8911
2289.18	15.8722
2290.12	16.8235
2291.06	14.9128
2292	14.9247
2292.93	17.828
2293.87	14.937
2294.81	17.8173
2295.75	17.8062
2296.69	15.8779
2297.63	13.9682
2298.56	10.1236
2299.5	13.9873
2300.44	14.9564
2301.38	15.9271
2302.31	16.89
2303.25	17.8542
2304.19	13.0362
2305.12	14.0092
2306.06	12.0819
2307	14.9801
2307.93	14.9748
2308.87	13.0477
2309.8	14.9943
2310.74	15.9567
2311.68	13.9971
2312.61	13.9908
2313.55	14.0067
2314.48	14.9929
2315.41	15.9519
2316.35	16.8978
2317.28	16.9042
2318.22	14.0002
2319.15	14.9572
2320.09	14.9568
2321.02	17.8629
2321.95	16.916
2322.89	15.9526
2323.82	22.7235
2324.75	26.5663
2325.69	38.1274
2326.62	48.7034
2327.55	119.029
2328.48	309.831
2329.42	73.6796
2330.35	32.2618
2331.28	17.8227
2332.21	16.8533
2333.14	13.9572
2334.07	16.834
2335.01	15.8667
2335.94	15.8665
2336.87	16.8251
2337.8	15.86
2338.73	15.86
2339.66	15.8565
2340.59	19.6841
2341.52	12.9475
2342.45	15.8171
2343.38	12.9402
2344.31	14.8589
2345.24	14.8503
2346.17	13.8853
2347.1	12.9248
2348.02	11.0134
2348.95	13.8772
2349.88	15.7558
2350.81	13.867
2351.74	14.7942
2352.67	13.8109
2353.59	11.9058
2354.52	14.7697
2355.45	11.9069
2356.38	13.7934
2357.3	14.7346
2358.23	17.5772
2359.16	16.6214
2359.85	12.8144