File: Data/3-Raman/raw/bu20-j-ff1-fi03-s_1800 (450-850nm)_532nm_edge_100%_x100_vis_lwd_h30um_30sx2_01.txt
#Acq. time (s)=	30
#Accumulations=	2
#Range=	Off
#Autofocus=	Off
#Macrospot=	Off
#AutoExposure=	Off
#Spike filter=	Multiple accum.
#Delay time (s)=	2
#Binning=	1
#Readout mode=	Signal
#DeNoise=	Off
#ICS correction=	On
#Dark correction=	Off
#Inst. Process=	Off
#Detector Gain=	Best Dynamic
#Detector ADC=	50 kHz HS
#Detector temperature (°C)=	-60.09
#Instrument=	LabRAM HR Evol
#Detector=	SIN-EM FIVIS
#Objective=	x100_VIS_LWD
#Grating=	1800 (450-850nm)
#ND Filter=	100%
#Laser=	532nm_Edge
#Spectro (cm-¹)=	3360
#Hole=	30.0125
#Temperature=	0
#Range=	Visible
#StageXY=	75x50mm Scan+
#StageZ=	Z motor
#X (µm)=	0
#Y (µm)=	0
#Z (µm)=	-19.5
#Full time(mm:ss)=	1:05
#Project=	21_08_11
#Sample=	BU20
#Site=
#Title=	BU20-J-FF1-FI03-S_1800 (450-850nm)_532nm_Edge_100%_x100_VIS_LWD_H30um_30sX2
#Remark=
#Date=	11.08.2021 17:27
#Acquired=	11.08.2021 17:27:49
3515.51	617.9
3515.13	645.505
3514.74	644.718
3514.36	668.581
3513.98	675.112
3513.6	675.048
3513.21	693.12
3512.83	733.014
3512.45	724.449
3512.06	740.654
3511.68	723.528
3511.3	729.615
3510.91	729.185
3510.53	726.784
3510.15	714.426
3509.76	721.221
3509.38	706.164
3509	677.868
3508.61	670.123
3508.23	653.522
3507.84	643.383
3507.46	612.331
3507.08	615.865
3506.69	580.212
3506.31	574.582
3505.93	554.83
3505.54	541.447
3505.16	505.59
3504.77	498.053
3504.39	488.774
3504.01	464.82
3503.62	461.968
3503.24	413.528
3502.85	400.27
3502.47	412.862
3502.09	395.872
3501.7	395.956
3501.32	378.861
3500.93	360.856
3500.55	362.767
3500.16	337.778
3499.78	334.83
3499.4	328.098
3499.01	316.682
3498.63	293.892
3498.24	311.081
3497.86	298.714
3497.47	282.52
3497.09	283.453
3496.7	274.806
3496.32	265.272
3495.93	252.001
3495.55	250.147
3495.17	244.507
3494.78	229.306
3494.4	236.97
3494.01	225.551
3493.63	234.101
3493.24	224.499
3492.86	196.902
3492.47	218.854
3492.09	221.44
3491.7	202.553
3491.32	204.414
3490.93	199.493
3490.55	190.814
3490.16	203.152
3489.78	211.495
3489.39	189.428
3489.01	191.237
3488.62	201.689
3488.23	185.531
3487.85	184.606
3487.46	180.83
3487.08	178.025
3486.69	176.165
3486.31	181.938
3485.92	167.654
3485.54	171.525
3485.15	177.336
3484.76	177.463
3484.38	174.669
3483.99	165.146
3483.61	170.973
3483.22	158.56
3482.84	162.424
3482.45	163.403
3482.06	161.487
3481.68	160.427
3481.29	157.628
3480.91	150.732
3480.52	155.296
3480.13	155.35
3479.75	147.779
3479.36	153.477
3478.98	153.433
3478.59	151.497
3478.2	153.398
3477.82	145.899
3477.43	147.977
3477.04	156.639
3476.66	142.487
3476.27	160.603
3475.88	151.51
3475.5	141.249
3475.11	146.198
3474.73	161.981
3474.34	148.404
3473.95	146.871
3473.57	143.877
3473.18	152.709
3472.79	139.957
3472.41	145.984
3472.02	144.405
3471.63	143.437
3471.24	144.819
3470.86	135.019
3470.47	135.59
3470.08	139.519
3469.7	145.679
3469.31	143.582
3468.92	147.375
3468.54	125.347
3468.15	144.464
3467.76	138.746
3467.38	128.34
3466.99	139.896
3466.6	146.659
3466.21	138.032
3465.83	139.906
3465.44	140.851
3465.05	136.068
3464.66	146.675
3464.28	141.895
3463.89	138.083
3463.5	141.963
3463.11	136.221
3462.73	133.38
3462.34	140.147
3461.95	145.942
3461.56	134.389
3461.18	138.239
3460.79	144.013
3460.4	136.321
3460.01	136.319
3459.62	136.379
3459.24	138.371
3458.85	150.822
3458.46	140.157
3458.07	143.073
3457.68	133.452
3457.3	136.292
3456.91	143.004
3456.52	141.073
3456.13	140.161
3455.74	138.306
3455.36	140.243
3454.97	144.099
3454.58	131.591
3454.19	141.246
3453.8	142.224
3453.41	142.246
3453.03	143.198
3452.64	144.237
3452.25	145.308
3451.86	143.352
3451.47	152.025
3451.08	150.136
3450.69	142.347
3450.31	147.138
3449.92	152.904
3449.53	149.017
3449.14	145.135
3448.75	140.304
3448.36	155.711
3447.97	167.243
3447.58	153.899
3447.19	148.857
3446.81	153.917
3446.42	147.333
3446.03	172.878
3445.64	154.69
3445.25	162.555
3444.86	161.489
3444.47	165.453
3444.08	160.603
3443.69	163.015
3443.3	173.971
3442.91	177.016
3442.52	176.911
3442.14	177.845
3441.75	188.437
3441.36	182.633
3440.97	176.888
3440.58	188.51
3440.19	195.343
3439.8	197.379
3439.41	209.248
3439.02	216.598
3438.63	216.118
3438.24	235.457
3437.85	240.157
3437.46	247.632
3437.07	256.262
3436.68	279.448
3436.29	288.217
3435.9	308.578
3435.51	340.53
3435.12	344.474
3434.73	368.728
3434.34	420.769
3433.95	449.714
3433.56	495.099
3433.17	559.683
3432.78	594.51
3432.39	696.279
3432	819.238
3431.61	890.037
3431.22	1035.98
3430.83	1168.52
3430.44	1293.63
3430.05	1420.67
3429.66	1503.77
3429.27	1549.07
3428.88	1492.79
3428.48	1481.76
3428.09	1302.95
3427.7	1187.55
3427.31	1084.86
3426.92	915.777
3426.53	828.114
3426.14	727.896
3425.75	658.76
3425.36	594.066
3424.97	557.171
3424.58	480.014
3424.19	448.249
3423.79	408.749
3423.4	378.861
3423.01	353.701
3422.62	349.796
3422.23	315.012
3421.84	310.016
3421.45	292.54
3421.06	262.619
3420.67	261.647
3420.27	254.943
3419.88	243.432
3419.49	243.39
3419.1	223.088
3418.71	214.354
3418.32	211.302
3417.93	213.199
3417.53	197.809
3417.14	196.806
3416.75	190.057
3416.36	189.134
3415.97	187.173
3415.58	195.772
3415.19	176.518
3414.79	179.408
3414.4	174.615
3414.01	167.925
3413.62	162.155
3413.22	159.248
3412.83	159.211
3412.44	162.029
3412.05	157.161
3411.66	166.742
3411.27	161.939
3410.87	154.292
3410.48	160.102
3410.09	158.173
3409.7	152.396
3409.3	159.116
3408.91	148.523
3408.52	153.32
3408.13	150.477
3407.73	141.71
3407.34	147.544
3406.95	147.555
3406.56	147.007
3406.17	144.63
3405.77	146.541
3405.38	148.282
3404.99	138.665
3404.59	142.528
3404.2	136.712
3403.81	139.714
3403.42	138.572
3403.02	135.877
3402.63	147.467
3402.24	137.684
3401.84	150.749
3401.45	132.975
3401.06	144.279
3400.67	130.7
3400.27	137.642
3399.88	146.103
3399.49	131.574
3399.09	140.645
3398.7	136.301
3398.31	141.934
3397.91	134.593
3397.52	135.494
3397.13	147.957
3396.73	139.491
3396.34	142.313
3395.95	143.225
3395.55	138.371
3395.16	139.172
3394.77	141.016
3394.37	140.073
3393.98	139.171
3393.59	143.061
3393.19	137.43
3392.8	142.235
3392.4	134.323
3392.01	138.24
3391.62	135.933
3391.22	125.661
3390.83	129.587
3390.44	138.701
3390.04	136.761
3389.65	134.364
3389.25	139.001
3388.86	138.915
3388.47	143.848
3388.07	144.671
3387.68	141.799
3387.28	132.188
3386.89	144.506
3386.49	138.779
3386.1	138.769
3385.71	148.298
3385.31	151.185
3384.92	151.228
3384.52	157.064
3384.13	140.939
3383.73	151.446
3383.34	156.117
3382.95	151.274
3382.55	159.775
3382.16	157.803
3381.76	164.49
3381.37	163.572
3380.97	171.228
3380.58	171.248
3380.18	185.565
3379.79	177.923
3379.39	175.993
3379	175.011
3378.6	176.871
3378.21	174.929
3377.81	170.163
3377.42	170.203
3377.02	174.993
3376.63	159.705
3376.23	156.813
3375.84	162.484
3375.44	160.544
3375.05	161.476
3374.65	161.458
3374.25	158.538
3373.86	149.095
3373.46	147.262
3373.07	149.239
3372.67	152.128
3372.28	149.254
3371.88	139.68
3371.49	142.513
3371.09	147.21
3370.7	138.622
3370.3	144.357
3369.9	138.628
3369.51	148.14
3369.11	135.754
3368.72	133.863
3368.32	138.639
3367.93	130.06
3367.53	131.954
3367.13	130.043
3366.74	131.037
3366.34	131.96
3365.95	122.395
3365.55	134.756
3365.15	128.085
3364.76	127.16
3364.36	128.123
3363.97	131.911
3363.57	116.688
3363.17	120.534
3362.78	118.653
3362.38	118.664
3361.98	128.203
3361.59	122.471
3361.19	116.707
3360.79	111.917
3360.4	122.367
3360	124.24
3359.6	114.688
3359.21	123.23
3358.81	110.853
3358.41	117.516
3358.02	123.249
3357.62	119.496
3357.22	113.809
3356.83	109.992
3356.43	113.774
3356.03	116.586
3355.64	116.557
3355.24	110.836
3354.84	124.147
3354.44	111.781
3354.05	117.492
3353.65	111.786
3353.25	111.788
3352.86	110.837
3352.46	103.242
3352.06	113.738
3351.67	111.832
3351.27	110.871
3350.87	112.802
3350.47	109.017
3350.08	115.69
3349.68	107.113
3349.28	110.893
3348.88	108.952
3348.49	107.013
3348.09	119.322
3347.69	109.786
3347.29	106.934
3346.9	106.956
3346.5	107.942
3346.1	112.748
3345.7	109.921
3345.3	109.918
3344.91	114.691
3344.51	111.824
3344.11	112.779
3343.71	104.252
3343.31	108.08
3342.92	105.214
3342.52	100.458
3342.12	106.187
3341.72	101.456
3341.32	103.399
3340.93	103.414
3340.53	108.191
3340.13	113.922
3339.73	105.35
3339.33	105.357
3338.93	102.509
3338.54	106.296
3338.14	93.9733
3337.74	106.462
3337.34	101.743
3336.94	103.667
3336.54	104.573
3336.14	104.535
3335.74	94.0446
3335.35	103.604
3334.95	105.549
3334.55	105.602
3334.15	99.8948
3333.75	102.77
3333.35	99.912
3332.95	97.9997
3332.55	94.1691
3332.16	97.9855
3331.76	101.797
3331.36	97.978
3330.96	96.034
3330.56	104.592
3330.16	109.361
3329.76	94.1272
3329.36	99.901
3328.96	95.2037
3328.56	91.4215
3328.16	97.1755
3327.76	96.2199
3327.37	91.4196
3326.97	102.859
3326.57	97.0584
3326.17	99.9221
3325.77	89.3894
3325.37	89.4625
3324.97	94.9916
3324.57	104.58
3324.17	99.8973
3323.77	96.1288
3323.37	97.1017
3322.97	102.867
3322.57	99.0283
3322.17	97.0712
3321.77	102.846
3321.37	104.825
3320.97	95.3531
3320.57	97.3074
3320.17	103.039
3319.77	97.2614
3319.37	96.2719
3318.97	95.2676
3318.57	100.03
3318.17	93.3205
3317.77	97.1911
3317.37	96.2589
3316.97	92.4557
3316.57	91.4978
3316.17	89.6476
3315.77	99.103
3315.37	90.5046
3314.97	88.7628
3314.57	91.7232
3314.17	90.7157
3313.77	85.8096
3313.37	90.5004
3312.97	89.6507
3312.56	88.7389
3312.16	93.4244
3311.76	96.2876
3311.36	91.5097
3310.96	90.5523
3310.56	93.4387
3310.16	95.3544
3309.76	97.2679
3309.36	92.4744
3308.96	96.3283
3308.56	91.5555
3308.15	88.7293
3307.75	89.755
3307.35	89.7904
3306.95	89.8227
3306.55	98.4774
3306.15	92.6946
3305.75	91.7499
3305.35	91.7699
3304.94	91.7719
3304.54	94.7132
3304.14	88.0615
3303.74	93.9018
3303.34	83.2669
3302.94	95.688
3302.53	96.7482
3302.13	91.0429
3301.73	92.8469
3301.33	91.8285
3300.93	92.7963
3300.53	89.9106
3300.13	92.8701
3299.72	93.8804
3299.32	81.2674
3298.92	84.113
3298.52	85.0707
3298.12	89.9076
3297.71	89.9818
3297.31	90.0384
3296.91	90.0605
3296.51	85.239
3296.11	93.8868
3295.7	92.894
3295.3	87.1042
3294.9	83.2291
3294.5	88.0221
3294.1	91.8856
3293.69	92.8745
3293.29	90.003
3292.89	90.0125
3292.49	89.039
3292.08	89.9937
3291.68	89.1871
3291.28	94.8548
3290.88	91.9162
3290.47	87.0281
3290.07	90.7993
3289.67	94.6852
3289.27	92.8248
3288.86	89.0047
3288.46	89.0238
3288.06	90.9558
3287.65	86.1645
3287.25	92.9391
3286.85	88.1387
3286.45	97.788
3286.04	89.1297
3285.64	94.9016
3285.24	89.0935
3284.83	84.2372
3284.43	92.8616
3284.03	91.8254
3283.62	86.0471
3283.22	84.2982
3282.82	90.0878
3282.41	82.2553
3282.01	92.5581
3281.61	85.1936
3281.2	84.2338
3280.8	81.3378
3280.4	89.0374
3279.99	89.9804
3279.59	87.0705
3279.19	84.1842
3278.78	84.1849
3278.38	89.0088
3277.98	88.0679
3277.57	84.2338
3277.17	83.2838
3276.76	83.2896
3276.36	84.2451
3275.96	87.12
3275.55	90.9647
3275.15	86.1015
3274.74	90.9121
3274.34	91.0044
3273.94	85.9684
3273.53	85.9571
3273.13	86.0165
3272.72	87.009
3272.32	91.8582
3271.92	92.8479
3271.51	89.95
3271.11	85.161
3270.7	85.1819
3270.3	84.2392
3269.9	90.0367
3269.49	84.2636
3269.09	83.3028
3268.68	84.2568
3268.28	85.1937
3267.87	87.097
3267.47	78.4128
3267.06	88.0183
3266.66	89.9412
3266.25	89.9616
3265.85	92.8881
3265.44	93.9033
3265.04	92.9931
3264.64	90.114
3264.23	82.4
3263.83	89.1306
3263.42	77.5404
3263.02	90.9806
3262.61	85.1768
3262.21	88.0336
3261.8	84.1712
3261.4	81.2893
3260.99	83.221
3260.59	77.4916
3260.18	83.2203
3259.78	86.19
3259.37	88.1672
3258.96	77.5491
3258.56	83.3459
3258.15	86.227
3257.75	88.1201
3257.34	78.4661
3256.94	85.1686
3256.53	91.8666
3256.13	80.2946
3255.72	91.8071
3255.31	81.2202
3254.91	82.2018
3254.5	83.1586
3254.1	83.1372
3253.69	86.9727
3253.29	86.9816
3252.88	86.0422
3252.47	87.0329
3252.07	85.1284
3251.66	84.1714
3251.26	85.1236
3250.85	77.4028
3250.44	84.0836
3250.04	79.2207
3249.63	86.8707
3249.23	85.9177
3248.82	83.0671
3248.41	85.982
3248.01	77.3861
3247.6	73.5513
3247.2	81.2219
3246.79	88.8784
3246.38	84.9899
3245.98	82.9988
3245.57	78.1551
3245.16	78.0807
3244.76	70.4056
3244.35	81.9527
3243.94	83.8967
3243.54	71.4337
3243.13	90.649
3242.72	89.7115
3242.32	82.0542
3241.91	78.2264
3241.5	82.0584
3241.1	87.8224
3240.69	81.1023
3240.28	87.806
3239.88	83
3239.47	84.9288
3239.06	79.1682
3238.65	73.4212
3238.25	78.1966
3237.84	81.0381
3237.43	76.2215
3237.03	81.9724
3236.62	84.8601
3236.21	76.2617
3235.8	81.0879
3235.4	71.5133
3234.99	79.1997
3234.58	85.9
3234.18	82.0552
3233.77	78.207
3233.36	84.9137
3232.95	77.2323
3232.54	82.0295
3232.14	90.6683
3231.73	79.1734
3231.32	73.3752
3230.91	78.1497
3230.51	77.242
3230.1	79.0929
3229.69	78.1499
3229.28	86.9434
3228.87	79.058
3228.47	80.0139
3228.06	77.2195
3227.65	72.3108
3227.24	80.945
3226.83	84.6621
3226.43	81.746
3226.02	73.4619
3225.61	73.4604
3225.2	71.4611
3224.79	70.4583
3224.39	79.0181
3223.98	82.8019
3223.57	76.0989
3223.16	74.2022
3222.75	77.0872
3222.34	78.0587
3221.94	76.1579
3221.53	74.2315
3221.12	72.2881
3220.71	74.1612
3220.3	81.7803
3219.89	72.1947
3219.48	79.842
3219.07	70.3136
3218.67	74.1317
3218.26	74.105
3217.85	71.3266
3217.44	75.3025
3217.03	73.0906
3216.62	79.1043
3216.21	71.3365
3215.8	77.9132
3215.39	74.1283
3214.99	71.2902
3214.58	76.0961
3214.17	73.2076
3213.76	77.9677
3213.35	74.1383
3212.94	78.9334
3212.53	77.9762
3212.12	77.976
3211.71	73.1887
3211.3	69.3551
3210.89	75.0866
3210.48	75.0759
3210.07	73.1716
3209.66	66.5171
3209.25	73.2507
3208.84	74.2286
3208.44	76.1452
3208.02	78.0346
3207.62	65.5837
3207.21	76.1026
3206.8	80.8822
3206.39	74.1824
3205.98	66.5329
3205.57	72.2757
3205.16	73.2176
3204.75	75.1035
3204.34	73.1852
3203.93	74.1539
3203.52	72.2506
3203.11	72.2626
3202.7	68.4509
3202.29	75.1644
3201.88	69.4357
3201.47	76.1425
3201.06	68.4577
3200.65	71.3157
3200.23	69.3923
3199.82	67.4712
3199.41	69.3832
3199	69.3916
3198.59	77.0666
3198.39	75.1782