File: Data/3-Raman/raw/bu20-b-ff4-fi02-l_150 (500nm)_633nm_edge_100%_x100_vis_lwd_h30um_60sx4_01.txt
#Acq. time (s)=	60
#Accumulations=	4
#Range (cm-¹)=	100...4000
#Windows=	1
#Auto scanning=	Off
#Autofocus=	Off
#Macrospot=	Off
#AutoExposure=	Off
#Spike filter=	Multiple accum.
#Delay time (s)=	2
#Binning=	1
#Readout mode=	Signal
#DeNoise=	Off
#ICS correction=	On
#Dark correction=	Off
#Inst. Process=	Off
#Detector Gain=	Best Dynamic
#Detector ADC=	50 kHz HS
#Detector temperature (°C)=	-60.09
#Instrument=	LabRAM HR Evol
#Detector=	SIN-EM FIVIS
#Objective=	x100_VIS_LWD
#Grating=	150 (500nm)
#ND Filter=	100%
#Laser=	633nm_Edge
#Hole=	30.0125
#Temperature=	39.9
#Range=	Visible
#StageXY=	75x50mm Scan+
#StageZ=	Z motor
#X (µm)=	0
#Y (µm)=	0
#Z (µm)=	470.9
#Full time(mm:ss)=	4:05
#Project=	21_08_11
#Sample=	BU20
#Site=
#Title=	BU20-B-FF4-FI02-L_150 (500nm)_633nm_Edge_100%_x100_VIS_LWD_H30um_60sX4
#Remark=
#Date=	13.08.2021 11:55
#Acquired=	13.08.2021 11:55:24
100.12	450.993
106.638	406.836
113.152	382.742
119.66	346.728
126.162	328.477
132.659	300.266
139.151	297.751
145.637	286.955
152.118	275.221
158.594	243.445
165.064	236.565
171.529	239.833
177.989	214.218
184.441	212.757
190.89	204.154
197.334	193.665
203.772	181.495
210.205	184.61
216.631	165.466
223.054	169.196
229.471	179.135
235.881	246.769
242.288	326.662
248.689	239.195
255.083	196.637
261.474	196.231
267.858	211.661
274.238	241.991
280.613	300.762
286.982	393.21
293.346	352.489
299.704	235.797
306.058	176.638
312.406	167.662
318.749	160.919
325.086	208.671
331.418	331.884
337.746	257.621
344.068	181.186
350.384	148.743
356.697	161.18
363.003	173.566
369.304	209.412
375.601	192.604
381.892	157.396
388.177	127.07
394.457	118.134
400.733	119.327
407.004	112.978
413.269	116.023
419.529	119.021
425.784	133.868
432.034	158.123
438.279	211.426
444.518	240.016
450.753	237.126
456.982	221.865
463.207	203.756
469.426	160.713
475.64	131.494
481.85	120.343
488.054	115.385
494.253	112.307
500.447	102.699
506.635	104.306
512.819	106.244
518.999	108.848
525.173	102.486
531.342	96.4703
537.505	93.2893
543.664	99.7676
549.819	96.4052
555.966	96.4841
562.111	98.2912
568.25	98.4245
574.383	98.4609
580.513	96.5766
586.636	97.883
592.756	111.708
598.871	148.903
604.979	235.834
611.084	182.369
617.183	159.423
623.277	162.419
629.367	177.65
635.451	183.784
641.532	166.052
647.606	151.646
653.675	154.463
659.741	179.023
665.801	193.19
671.856	157.716
677.907	119.212
683.952	97.4888
689.992	81.1281
696.028	80.6879
702.059	72.4155
708.086	68.4684
714.107	67.2104
720.123	65.2891
726.135	66.4888
732.141	66.3715
738.143	65.3159
744.14	64.8956
750.133	60.4622
756.12	61.3614
762.103	58.6367
768.081	62.8478
774.054	58.338
780.023	59.1025
785.987	58.5624
791.946	59.2493
797.9	59.5789
803.848	62.3666
809.793	59.1568
815.733	61.2389
821.669	60.1602
827.6	58.1391
833.525	58.0763
839.446	63.723
845.363	62.9053
851.273	62.0997
857.181	59.4323
863.083	59.5955
868.98	64.4898
874.874	68.0833
880.761	70.9924
886.645	66.5859
892.523	70.9872
898.398	67.4333
904.267	63.1792
910.133	59.5586
915.992	58.7796
921.849	63.7173
927.699	65.287
933.545	71.3292
939.387	86.9537
945.224	98.3207
951.056	124.072
956.884	157.913
962.708	163.78
968.526	174.343
974.34	183.188
980.149	229.494
985.955	301.681
991.755	409.896
997.551	420.945
1003.34	322.804
1009.13	280.069
1014.91	271.117
1020.69	307.999
1026.46	381.072
1032.23	419.468
1037.99	287.283
1043.75	180.044
1049.51	150.871
1055.26	122.076
1061	113.484
1066.74	107.976
1072.48	101.795
1078.21	116.926
1083.94	146.867
1089.67	151.929
1095.38	145.384
1101.1	181.406
1106.81	185.021
1112.51	121.887
1118.22	89.9028
1123.91	81.3563
1129.6	70.4818
1135.29	77.5134
1140.98	92.4312
1146.65	107.006
1152.33	114.695
1158	150.789
1163.66	118.129
1169.32	74.0828
1174.98	65.776
1180.63	64.0212
1186.28	57.4549
1191.93	52.9051
1197.56	49.7137
1203.2	51.8108
1208.83	44.4516
1214.46	42.6514
1220.08	43.1788
1225.69	42.0582
1231.31	40.2452
1236.92	43.0785
1242.52	43.865
1248.12	43.9288
1253.72	37.8905
1259.31	45.6093
1264.89	41.5114
1270.48	48.1625
1276.05	40.6933
1281.63	43.6097
1287.2	42.8673
1292.76	45.817
1298.33	43.1381
1303.88	40.1562
1309.43	44.5645
1314.98	38.3394
1320.53	36.4528
1326.07	39.2917
1331.6	38.7739
1337.13	37.2113
1342.66	37.3163
1348.18	39.4417
1353.7	40.1947
1359.22	33.0481
1364.73	36.487
1370.23	39.2176
1375.73	39.5454
1381.23	46.0314
1386.72	48.0618
1392.21	39.5015
1397.7	35.0938
1403.18	36.17
1408.65	33.1391
1414.13	35.6134
1419.59	32.9352
1425.06	34.0547
1430.52	30.3301
1435.97	32.8395
1441.42	32.9179
1446.87	32.6514
1452.31	33.399
1457.75	31.6737
1463.19	33.4274
1468.62	29.5692
1474.04	33.4115
1479.46	32.721
1484.88	28.5369
1490.3	31.3707
1495.7	33.1767
1501.11	29.7238
1506.51	31.202
1511.91	31.9943
1517.3	31.385
1522.69	32.202
1528.08	30.8861
1533.46	30.6451
1538.83	33.2569
1544.21	31.8929
1549.58	32.2731
1554.94	32.9687
1560.3	34.3677
1565.66	33.9746
1571.01	32.8609
1576.36	33.9084
1581.7	30.3202
1587.04	37.5071
1592.38	35.3765
1597.71	37.5762
1603.04	31.1535
1608.37	38.8041
1613.68	37.4769
1619	36.5279
1624.31	34.8437
1629.62	39.0032
1634.93	37.2952
1640.23	38.4646
1645.52	40.0001
1650.81	40.42
1656.1	40.4561
1661.39	35.6666
1666.67	37.1518
1671.94	39.3714
1677.22	31.973
1682.48	34.1791
1687.75	32.302
1693.01	33.7602
1698.26	33.4063
1703.52	30.5719
1708.77	29.2189
1714.01	32.519
1719.25	30.3738
1724.49	27.0614
1729.72	28.614
1734.95	28.6726
1740.18	30.2298
1745.4	31.7925
1750.61	29.2013
1755.83	30.7425
1761.04	23.9634
1766.24	26.993
1771.44	25.8755
1776.64	24.3842
1781.84	29.3399
1787.02	25.9773
1792.21	30.5961
1797.39	26.4773
1802.57	28.0782
1807.75	30.8346
1812.92	30.9009
1818.08	28.2759
1823.25	29.1082
1828.41	28.7884
1833.56	26.9209
1838.71	28.1496
1843.86	26.2565
1849	30.5855
1854.14	28.6748
1859.28	28.331
1864.41	25.6455
1869.54	27.2684
1874.67	27.7004
1879.79	25.3746
1884.9	24.6143
1890.02	28.9643
1895.13	27.3893
1900.23	28.586
1905.34	27.4516
1910.43	29.0988
1915.53	24.0315
1920.62	27.2545
1925.71	29.2979
1930.79	26.1599
1935.87	23.8062
1940.94	28.2489
1946.02	27.4788
1951.08	26.2966
1956.15	28.7177
1961.21	31.1353
1966.27	29.1281
1971.32	28.7136
1976.37	25.4865
1981.42	26.2742
1986.46	25.8599
1991.5	27.4535
1996.53	27.8485
2001.56	25.0454
2006.59	28.2635
2011.61	26.2786
2016.63	24.6938
2021.65	27.1184
2026.66	28.3565
2031.67	28.8042
2036.68	26.8414
2041.68	25.6813
2046.68	26.952
2051.67	24.5742
2056.66	31.9378
2061.65	32.8246
2066.63	28.8126
2071.61	27.2352
2076.59	26.8814
2081.56	30.2215
2086.53	28.6203
2091.49	27.0124
2096.46	22.9374
2101.41	28.7908
2106.37	26.7888
2111.32	28.531
2116.26	31.9621
2121.21	26.1936
2126.15	30.4743
2131.09	28.4504
2136.02	27.6751
2140.95	27.3134
2145.87	31.1885
2150.79	29.1126
2155.71	26.595
2160.63	24.9152
2165.54	28.7624
2170.45	27.9191
2175.35	27.9407
2180.25	31.3649
2185.15	28.3744
2190.04	25.3915
2194.93	28.394
2199.82	28.4247
2204.7	24.1873
2209.58	25.9491
2214.46	32.4537
2219.33	28.6564
2224.2	30.4577
2229.06	27.5034
2233.92	26.2707
2238.78	27.2077
2243.64	25.5307
2248.49	25.1589
2253.34	28.7302
2258.18	26.1653
2263.02	24.4663
2267.86	24.9565
2272.69	25.438
2277.52	23.6973
2282.35	27.2624
2287.17	24.6098
2291.99	29.052
2296.81	26.8426
2301.62	27.7525
2306.43	28.2353
2311.24	31.8535
2316.04	25.6747
2320.84	27.5311
2325.63	28.0513
2330.43	26.3282
2335.21	24.6029
2340	26.9447
2344.78	27.9458
2349.56	23.0312
2354.33	26.3113
2359.11	26.8418
2363.87	26.4339
2368.64	24.6488
2373.4	26.0843
2378.16	24.2861
2382.91	25.7102
2387.66	28.5156
2392.41	25.2824
2397.16	29.9255
2401.9	26.2141
2406.64	24.3528
2411.37	28.556
2416.1	26.3177
2420.83	22.7029
2425.55	26.9548
2430.27	27.0214
2434.99	23.7987
2439.7	26.7077
2444.41	29.1575
2449.12	24.49
2453.83	26.9471
2458.53	26.0692
2463.22	26.6246
2467.92	27.6602
2472.61	28.2131
2477.3	26.8366
2481.98	23.9963
2486.66	26.9642
2491.34	26.0458
2496.01	40.2488
2500.68	26.1516
2505.35	25.7086
2510.01	26.2391
2514.67	27.2555
2519.33	25.8175
2523.99	26.3522
2528.64	29.3516
2533.28	26.9293
2537.93	26.486
2542.57	25.0519
2547.21	22.6211
2551.84	31.6396
2556.47	26.7104
2561.1	26.2628
2565.73	22.8146
2570.35	23.8788
2574.97	26.4606
2579.58	26.0151
2584.19	25.5518
2588.8	26.5953
2593.41	24.0812
2598.01	28.1808
2602.61	29.2363
2607.2	29.2707
2611.8	24.2019
2616.38	24.7308
2620.97	26.2842
2625.55	24.2677
2630.13	27.3724
2634.71	29.4849
2639.28	28.5464
2643.85	25.5403
2648.42	27.6931
2652.98	25.7027
2657.54	28.3537
2662.1	26.315
2666.65	29.999
2671.2	27.4389
2675.75	25.4203
2680.29	27.1254
2684.84	25.1324
2689.37	26.84
2693.91	26.9413
2698.44	23.7781
2702.97	26.5069
2707.49	27.0938
2712.02	27.6778
2716.53	23.4301
2721.05	27.7918
2725.56	27.2945
2730.07	27.3271
2734.58	25.1832
2739.08	24.1151
2743.58	28.4842
2748.08	29.0709
2752.57	25.3369
2757.06	30.3094
2761.55	28.1664
2766.04	23.8358
2770.52	25.5274
2775	30.5359
2779.47	28.4125
2783.94	27.9556
2788.41	28.0501
2792.88	29.2538
2797.34	29.3366
2801.8	26.6094
2806.26	26.6661
2810.71	26.1545
2815.16	26.1965
2819.61	29.0571
2824.05	26.8444
2828.49	28.5871
2832.93	30.8977
2837.37	26.3989
2841.8	29.2798
2846.23	29.3289
2850.65	30.5256
2855.08	32.3148
2859.5	28.3816
2863.91	26.7373
2868.33	26.8219
2872.74	30.3758
2877.15	31.0519
2881.55	31.1568
2885.95	27.7627
2890.35	30.7907
2894.75	27.9506
2899.14	32.1908
2903.53	39.4114
2907.91	26.4527
2912.3	28.9049
2916.68	28.371
2921.05	29.6385
2925.43	31.5178
2929.8	28.5994
2934.17	35.3207
2938.53	31.7665
2942.9	30.0072
2947.26	27.0167
2951.61	28.2721
2955.97	29.5301
2960.32	31.4008
2964.66	30.8389
2969.01	32.1171
2973.35	34.6286
2977.69	29.1674
2982.03	32.917
2986.36	26.2127
2990.69	27.5199
2995.01	33.7993
2999.34	28.9265
3003.66	33.3908
3007.98	30.373
3012.29	31.0949
3016.6	34.9847
3020.91	35.1127
3025.22	35.8605
3029.52	34.0463
3033.82	37.9515
3038.12	38.0177
3042.41	40.0229
3046.71	34.3208
3051	34.3793
3055.28	38.3025
3059.56	38.3718
3063.84	42.3153
3068.12	39.801
3072.39	38.574
3076.67	40.5939
3080.93	40.0189
3085.2	40.1013
3089.46	38.2406
3093.72	43.5992
3097.98	45.7161
3102.23	46.5278
3106.48	43.3867
3110.73	46.2144
3114.98	47.7309
3119.22	47.2493
3123.46	50.8156
3127.7	49.0156
3131.93	51.2922
3136.16	52.2241
3140.39	54.5218
3144.61	49.2424
3148.84	55.6595
3153.06	56.536
3157.27	56.7048
3161.49	61.0597
3165.7	68.933
3169.91	64.1967
3174.11	62.9697
3178.31	67.3178
3182.51	73.7717
3186.71	67.5038
3190.9	73.9467
3195.1	73.3647
3199.28	72.1337
3203.47	78.1007
3207.65	81.9837
3211.83	73.6874
3216.01	76.173
3220.18	73.5841
3224.36	84.0685
3228.52	78.561
3232.69	84.7365
3236.85	76.9325
3241.01	85.3651
3245.17	82.0276
3249.33	83.0813
3253.48	84.0643
3257.63	82.7567
3261.77	85.2854
3265.92	87.126
3270.06	83.733
3274.2	81.7973
3278.33	85.7699
3282.47	88.9993
3286.59	92.2415
3290.72	84.7497
3294.85	79.5216
3298.97	84.2812
3303.09	83.6857
3307.2	81.5335
3311.32	87.8762
3315.43	89.5856
3319.54	92.0889
3323.64	99.3146
3327.74	91.7617
3331.84	102.228
3335.94	88.4444
3340.04	101.335
3344.13	92.0725
3348.22	93.8149
3352.3	130.474
3356.39	100.534
3360.47	115.096
3364.54	108.967
3368.62	105.196
3372.69	107.815
3376.76	114.412
3380.83	116.985
3384.89	122.772
3388.96	118.082
3393.02	118.206
3397.07	124.027
3401.13	114.492
3405.18	123.507
3409.23	127.682
3413.27	130.21
3417.31	136.81
3421.36	126.348
3425.39	144.324
3429.43	132.266
3433.46	122.658
3437.49	130.201
3441.52	123.075
3445.54	129.896
3449.56	126.118
3453.58	131.396
3457.6	121.9
3461.61	114.862
3465.63	131.081
3469.63	128.193
3473.64	122.682
3477.64	125.578
3481.64	120.058
3485.64	120.405
3489.64	123.279
3493.63	117.661
3497.62	113.674
3501.61	117.317
3505.59	105.548
3509.58	105.663
3513.56	107.445
3517.53	97.2298
3521.51	104.999
3525.48	94.778
3529.45	105.132
3533.42	95.8244
3537.38	96.0246
3541.34	86.7492
3545.3	95.5511
3549.26	88.7657
3553.21	80.1459
3557.16	82.8184
3561.11	82.9207
3565.06	83.9196
3569	85.848
3572.94	90.3863
3576.88	86.2231
3580.82	89.0958
3584.75	92.8844
3588.68	94.9245
3592.61	96.9718
3596.54	80.3787
3600.46	72.5759
3604.38	69.1881
3608.3	72.9219
3612.21	64.9998
3616.13	64.2329
3620.04	58.9492
3623.94	52.6981
3627.85	53.6336
3631.75	47.3422
3635.65	53.6838
3639.55	51.0349
3643.44	48.4149
3647.34	49.431
3651.23	39.4786
3655.12	47.6955
3659	46.8291
3662.88	45.9541
3666.76	38.7111
3670.64	31.4561
3674.52	41.5358
3678.39	41.6083
3682.26	36.2003
3686.13	39.0538
3689.99	36.3989
3693.85	31.8786
3697.71	44.0039
3701.57	36.6922
3705.43	31.199
3709.28	35.956
3713.13	37.9269
3716.98	41.7695
3720.82	33.3908
3724.66	27.7991
3728.5	36.3425
3732.34	34.5188
3736.18	30.7947
3740.01	29.9004
3743.84	31.8503
3747.67	35.7055
3751.49	34.7944
3755.32	32.917
3759.14	31.9825
3762.96	33.9081
3766.77	30.1005
3770.58	33.9482
3774.4	34.9353
3778.2	32.0944
3782.01	44.6072
3785.81	30.2657
3789.61	29.3456
3793.41	39.9891
3797.21	44.8935
3801	34.3438
3804.79	33.4494
3808.58	34.4991
3812.37	29.703
3816.15	34.6415
3819.93	31.776
3823.71	35.75
3827.49	36.7863
3831.26	35.8706
3835.04	33.9685
3838.8	35.0108
3842.57	27.1753
3846.34	39.0802
3850.1	36.1351
3853.86	28.2297
3857.62	33.1935
3861.37	38.1519
3865.12	33.2302
3868.87	35.3
3872.62	36.3348
3876.37	34.3651
3880.11	34.3865
3883.85	27.4299
3887.59	29.4524
3891.33	31.4839
3895.06	28.5358
3898.79	34.5969
3902.52	34.6513
3906.25	35.7069
3909.97	35.756
3913.69	34.8083
3917.41	29.8216
3921.13	37.9981
3924.84	31.9944
3928.56	27.9917
3932.27	36.2036
3935.97	37.2783
3939.68	32.2212
3943.38	32.2868
3947.08	32.3485
3950.78	33.4307
3954.48	29.3564
3958.17	30.4227
3961.86	31.4788
3965.55	33.5656
3969.24	29.4427
3972.92	32.5522
3976.6	28.4282
3980.29	35.6679
3983.96	38.7651
3987.64	36.6952
3991.31	32.5656
3994.98	32.5832
3998.65	29.5073