File: Data/3-Raman/raw/bu20-j-ff1-fi01-v_1800 (450-850nm)_532nm_edge_100%_x100_vis_lwd_h30um_60sx2_02.txt
#Acq. time (s)=	60
#Accumulations=	2
#Range (cm-¹)=	1200...2365
#Windows=	3
#Auto scanning=	Off
#Autofocus=	Off
#Macrospot=	Off
#AutoExposure=	Off
#Spike filter=	Multiple accum.
#Delay time (s)=	2
#Binning=	1
#Readout mode=	Signal
#DeNoise=	Off
#ICS correction=	On
#Dark correction=	Off
#Inst. Process=	Off
#Detector Gain=	Best Dynamic
#Detector ADC=	50 kHz EM
#Detector EM gain=	150
#Detector temperature (°C)=	-60.09
#Instrument=	LabRAM HR Evol
#Detector=	SIN-EM FIVIS
#Objective=	x100_VIS_LWD
#Grating=	1800 (450-850nm)
#ND Filter=	100%
#Laser=	532nm_Edge
#Hole=	30.0125
#Temperature=	40
#Range=	Visible
#StageXY=	75x50mm Scan+
#StageZ=	Z motor
#X (µm)=	0
#Y (µm)=	0
#Z (µm)=	63.6
#Full time(mm:ss)=	6:19
#Project=	21_08_11
#Sample=	BU20
#Site=
#Title=	BU20-J-FF1-FI01-V_1800 (450-850nm)_532nm_Edge_100%_x100_VIS_LWD_H30um_60sX2
#Remark=
#Date=	13.08.2021 15:05
#Acquired=	13.08.2021 15:05:04
1202.73	376.903
1203.84	379.395
1204.95	387.802
1206.06	382.796
1207.18	397.23
1208.29	372.257
1209.4	368.835
1210.51	363.036
1211.62	388.108
1212.73	380.21
1213.84	369.427
1214.95	381.121
1216.06	379.692
1217.17	375.994
1218.28	378.854
1219.38	356.406
1220.49	378.62
1221.6	369.794
1222.71	392.376
1223.82	390.732
1224.93	381.071
1226.03	393.831
1227.14	399.593
1228.25	384.733
1229.36	404.076
1230.46	422.279
1231.57	452.9
1232.67	442.266
1233.78	468.591
1234.89	445.693
1235.99	439.461
1237.1	422.228
1238.2	396.457
1239.31	395.19
1240.41	408.815
1241.52	410.79
1242.62	407.772
1243.73	405.716
1244.83	419.111
1245.94	398.817
1247.04	419.684
1248.14	423.573
1249.25	446.594
1250.35	445.284
1251.45	437.643
1252.56	447.743
1253.66	424.82
1254.76	408.295
1255.86	413.546
1256.97	427.163
1258.07	402.998
1259.17	429.018
1260.27	417.461
1261.37	430.004
1262.47	483.267
1263.58	545.478
1264.68	595.72
1265.77	470.2
1266.88	442.317
1267.98	440.866
1269.08	419.126
1270.17	417.685
1271.27	430.049
1272.37	433.668
1273.47	427.831
1274.57	413.271
1275.67	426.109
1276.77	427.485
1277.87	439.43
1278.97	436.569
1280.06	441.734
1281.16	481.031
1282.26	631.653
1283.36	1387.18
1284.45	3903.44
1285.55	1141.47
1286.65	569.598
1287.74	492.497
1288.84	433.725
1289.93	418.227
1291.03	410.756
1292.13	418.147
1293.22	406.76
1294.32	394.392
1295.41	389.694
1296.51	392.138
1297.6	405.552
1298.69	398.033
1299.79	369.535
1300.88	396.992
1301.98	370.768
1303.07	378.061
1304.16	388.588
1305.26	395.724
1306.35	381.766
1307.44	386.026
1308.54	388.195
1309.63	390.479
1310.72	380.982
1311.81	404.372
1312.9	378.993
1314	374.722
1315.09	386.509
1316.18	379.142
1317.27	381.316
1318.36	376.102
1319.45	383.476
1320.54	378.091
1321.63	400.911
1322.72	380.614
1323.81	379.598
1324.9	383.79
1325.99	383.007
1327.08	392.875
1328.17	369.195
1329.26	377.705
1330.35	384.885
1331.43	383.275
1332.52	377.539
1333.61	373.93
1334.7	389.323
1335.78	370.177
1336.87	378.397
1337.96	379.179
1339.05	382.189
1340.13	361.309
1341.22	406.27
1342.31	386.052
1343.39	363.951
1344.48	383.762
1345.57	384.406
1346.65	362.993
1347.74	383.56
1348.82	371.889
1349.91	369.538
1350.99	376.494
1352.08	374.428
1353.16	372.06
1354.24	362.606
1355.33	381.2
1356.41	382.219
1357.5	394.482
1358.58	377.591
1359.66	375.227
1360.75	384.297
1361.83	370.728
1362.91	398.681
1363.99	380.152
1365.08	407.849
1366.16	392.987
1367.24	393.759
1368.32	426.965
1369.4	506.566
1370.48	416.356
1371.56	406.531
1372.65	423.642
1373.73	404.925
1374.81	451.167
1375.89	446.033
1376.97	439.401
1378.05	477.186
1379.13	496.834
1380.21	540.212
1381.28	537.658
1382.37	551.103
1383.44	549.527
1384.52	594.873
1385.6	749.531
1386.68	1619.7
1387.76	6710.74
1388.84	1340.8
1389.91	648.951
1390.99	569.82
1392.07	517.095
1393.14	437.025
1394.22	427.697
1395.3	437.096
1396.37	443.108
1397.45	420.376
1398.53	407.199
1399.6	441.139
1400.68	403.467
1401.75	401.725
1402.83	396.253
1403.9	414.488
1404.98	402.008
1406.05	394.609
1407.13	469.536
1408.2	592.71
1409.28	806.271
1410.35	503.354
1411.43	410.808
1412.5	394.101
1413.57	388.599
1414.64	365.489
1415.72	384.043
1416.79	369.833
1417.86	369.93
1418.93	372.021
1420.01	387.156
1421.08	363.333
1422.15	365.858
1423.22	381.142
1424.29	374.118
1425.36	385.747
1426.44	377.289
1427.51	360.441
1428.58	370.69
1429.65	364.798
1430.72	360.148
1431.79	358.095
1432.86	356.664
1433.93	350.265
1435	347.382
1436.07	344.233
1437.13	359.5
1438.2	342.147
1439.27	365.865
1440.34	356.854
1441.41	352.679
1442.48	346.647
1443.55	347.511
1444.61	362.153
1445.68	357.987
1446.75	358.906
1447.81	334.241
1448.88	355.889
1449.95	344.428
1451.01	340.221
1452.08	348.338
1453.15	336.146
1454.21	345.331
1455.28	357.647
1456.34	347.399
1457.41	347.263
1458.47	344.236
1459.54	344.241
1460.6	342.074
1461.67	343.925
1462.73	335.453
1463.8	334.525
1464.86	347.431
1465.92	338.932
1466.99	340.75
1468.05	343.756
1469.11	349.749
1470.18	360.707
1471.24	330.982
1472.3	340.085
1473.36	355.201
1474.43	345.034
1475.49	334.804
1476.55	345.828
1477.61	340.659
1478.67	358.734
1479.73	342.175
1480.79	351.028
1481.86	319.733
1482.91	338.14
1483.98	338.916
1485.04	342.749
1486.1	340.411
1487.16	353.525
1488.22	339.092
1489.28	331.836
1490.33	336.802
1491.39	327.563
1492.45	343.72
1493.51	321.444
1494.57	329.546
1495.63	327.159
1496.68	328.016
1497.74	325.971
1498.8	333.083
1499.86	336.194
1500.91	337.1
1501.97	336.019
1503.03	326.704
1504.09	333.799
1505.14	333.662
1506.2	345.54
1507.25	337.584
1508.31	328.485
1509.37	339.581
1510.42	340.468
1511.48	343.944
1512.53	333.389
1513.59	328.42
1514.64	331.33
1515.7	327.959
1516.75	332.871
1517.8	325.953
1518.86	335.075
1519.91	335.053
1520.97	326.104
1522.02	330.023
1523.07	331.751
1524.13	322.442
1525.18	330.527
1526.23	322.761
1527.28	334.71
1528.33	339.589
1529.39	328.484
1530.44	334.597
1531.49	336.675
1532.54	339.84
1533.59	338.065
1534.64	325.934
1535.69	335.58
1536.74	331.175
1537.8	313.952
1538.85	325.042
1539.9	320.736
1540.95	335.817
1542	329.489
1543.05	347.178
1544.09	320.079
1545.14	344.484
1546.19	339.572
1547.24	340.681
1548.29	330.573
1549.34	331.933
1550.39	341.568
1551.43	334.197
1552.48	345.473
1553.53	328.976
1554.58	327.597
1555.62	332.609
1556.67	342.601
1557.72	333.449
1558.76	332.066
1559.81	341.83
1560.86	339.774
1561.9	322.049
1562.95	315.006
1563.99	328.242
1565.04	340.967
1566.08	340.917
1567.13	320.149
1568.17	339.981
1569.22	339.759
1570.26	326.806
1571.31	326.671
1572.35	331.502
1573.39	350.297
1574.44	326.612
1575.48	326.783
1576.53	339.539
1577.57	335.09
1578.61	343.938
1579.65	331.063
1580.7	329.997
1581.74	326.795
1582.78	337.668
1583.82	334.651
1584.86	335.678
1585.91	344.463
1586.95	328.349
1587.99	336.332
1589.03	347.453
1590.07	336.572
1591.11	345.557
1592.15	331.342
1593.19	348.817
1594.23	336.728
1595.27	349.664
1596.31	339.689
1597.35	340.769
1598.39	350.454
1599.43	330.362
1600.47	332.065
1601.51	336.626
1602.54	328.421
1603.58	336.166
1604.62	345.085
1605.66	332.337
1606.7	341.371
1607.73	358.693
1608.77	347.097
1609.81	339.679
1610.84	350.77
1611.88	336.41
1612.92	336.515
1613.95	334.778
1614.99	336.009
1616.03	335.922
1617.06	342.787
1618.1	342.783
1619.13	348.623
1620.17	341.717
1621.2	340.525
1622.24	343.25
1623.27	343.523
1624.31	342.381
1625.34	349.866
1626.37	340.915
1627.41	354.488
1628.44	342.458
1629.48	351.194
1630.51	338.367
1631.29	343.873
1632.33	328.392
1633.38	352.777
1634.42	339.077
1635.47	331.108
1636.52	334.874
1637.56	336.707
1638.6	344.524
1639.65	358.287
1640.69	365.332
1641.74	341.599
1642.78	348.44
1643.82	336.521
1644.87	352.267
1645.91	361.094
1646.95	337.35
1648	340.322
1649.04	358.336
1650.08	350.601
1651.13	345.888
1652.17	354.758
1653.21	358.643
1654.25	331.151
1655.29	356.127
1656.33	352.403
1657.38	340.47
1658.42	361.034
1659.46	323.34
1660.5	344.21
1661.54	341.495
1662.58	340.023
1663.62	339.499
1664.66	337.967
1665.7	359.971
1666.74	341.585
1667.78	342.341
1668.82	334.836
1669.86	336.776
1670.9	333.087
1671.93	326.208
1672.97	342.049
1674.01	337.255
1675.05	340.423
1676.09	336.5
1677.12	341.418
1678.16	328.317
1679.2	344.972
1680.24	326.068
1681.27	333.914
1682.31	334.904
1683.35	337.846
1684.38	331.805
1685.42	326.85
1686.45	331.925
1687.49	347.646
1688.53	327.715
1689.56	339.302
1690.6	328.565
1691.63	329.644
1692.67	330.442
1693.7	316.324
1694.74	321.133
1695.77	325.175
1696.8	324.154
1697.84	334.685
1698.87	322.735
1699.91	326.652
1700.94	311.814
1701.97	325.351
1703.01	326.217
1704.04	321.317
1705.07	316.387
1706.1	319.159
1707.14	319.829
1708.17	317.449
1709.2	325.993
1710.23	333.851
1711.26	320.287
1712.3	319.087
1713.33	321.502
1714.36	315.482
1715.39	325.372
1716.42	318.319
1717.45	324.598
1718.48	309.629
1719.51	315.452
1720.54	310.456
1721.57	320.871
1722.6	323.471
1723.63	306.834
1724.66	302.705
1725.69	310.102
1726.71	308.026
1727.74	309.946
1728.77	315.515
1729.8	313.873
1730.83	308.293
1731.85	312.12
1732.88	310.929
1733.91	300.837
1734.94	308.157
1735.97	311.829
1736.99	304.924
1738.02	314.321
1739.04	295.742
1740.07	304.85
1741.1	305.53
1742.12	314.974
1743.15	310.101
1744.17	302.254
1745.2	307.988
1746.23	311.552
1747.25	304.559
1748.28	306.426
1749.3	308.497
1750.32	301.099
1751.35	301.998
1752.37	304.562
1753.4	313.871
1754.42	301.246
1755.44	294.395
1756.47	306.431
1757.49	302.457
1758.51	305.451
1759.54	305.452
1760.56	314.832
1761.58	297.534
1762.6	304.271
1763.63	300.511
1764.65	302.686
1765.67	298.95
1766.69	310.32
1767.71	305.421
1768.73	312.699
1769.75	306.758
1770.77	303.151
1771.79	297.682
1772.82	310.244
1773.84	302.743
1774.86	312.399
1775.87	302.208
1776.89	297.317
1777.91	305.679
1778.93	304.447
1779.95	313.131
1780.97	300.842
1781.99	305.79
1783.01	297.381
1784.03	299.504
1785.05	303.4
1786.06	300.497
1787.08	300.791
1788.1	312.051
1789.12	300.889
1790.13	301.029
1791.15	302.659
1792.17	311.27
1793.18	303.688
1794.2	318.081
1795.22	306.189
1796.23	301.615
1797.25	303.758
1798.27	312.512
1799.28	310.443
1800.3	313.154
1801.31	312.173
1802.33	302.707
1803.34	305.814
1804.36	305.023
1805.37	315.91
1806.38	310.321
1807.4	309.385
1808.41	316.171
1809.43	307.551
1810.44	298.868
1811.45	305.604
1812.47	306.712
1813.48	313.644
1814.49	306.267
1815.5	314.117
1816.52	303.536
1817.53	310.017
1818.54	316
1819.55	312.264
1820.56	302.741
1821.58	311.628
1822.59	313.657
1823.6	322.297
1824.61	309.828
1825.62	305.06
1826.63	304.132
1827.64	306.178
1828.65	311.879
1829.66	306
1830.67	332.096
1831.68	312.904
1832.69	304.354
1833.7	308.301
1834.71	310.701
1835.72	312.377
1836.73	311.101
1837.74	315.99
1838.75	308.067
1839.75	311.914
1840.76	309.233
1841.77	308.744
1842.78	302.888
1843.78	306.719
1844.79	306.725
1845.8	313.856
1846.81	314.968
1847.81	306.396
1848.82	315.764
1849.83	304.792
1850.83	316.019
1851.84	306.313
1852.84	299.571
1853.85	305.072
1854.85	303.847
1855.86	296.923
1856.87	313.171
1857.87	302.463
1858.88	307.913
1859.88	309.764
1860.88	297.543
1861.89	293.746
1862.89	312.599
1863.9	304.715
1864.9	296.803
1865.9	306.827
1866.91	299.666
1867.91	307.06
1868.91	309.918
1869.92	310.802
1870.92	303.157
1871.92	301.107
1872.92	300.932
1873.92	307.397
1874.93	306.127
1875.93	320.784
1876.93	295.758
1877.93	301.153
1878.93	315.471
1879.93	306.75
1880.93	300.007
1881.93	311.659
1882.93	306.1
1883.94	304.561
1884.94	291.536
1885.94	302.225
1886.93	309.501
1887.93	303.491
1888.93	294.652
1889.93	302.241
1890.93	298.546
1891.93	301.329
1892.93	300.032
1893.93	301.65
1894.92	295.013
1895.92	294.223
1896.92	294.41
1897.92	307.553
1898.92	302.593
1899.91	294.016
1900.91	297.919
1901.91	301.006
1902.9	300.931
1903.9	295.219
1904.9	302.701
1905.89	294.946
1906.89	305.184
1907.88	297.817
1908.88	296.088
1909.88	300.216
1910.87	306.128
1911.87	290.095
1912.86	298.575
1913.86	299.813
1914.85	304.77
1915.85	299.09
1916.84	295.126
1917.83	300.77
1918.83	295.44
1919.82	306.157
1920.81	299.675
1921.81	296.973
1922.8	301.567
1923.79	301.428
1924.79	299.526
1925.78	297.951
1926.77	311.501
1927.76	299.348
1928.76	315.609
1929.75	304.566
1930.74	308.574
1931.73	302.745
1932.72	304.504
1933.71	304.918
1934.7	303.971
1935.69	298.31
1936.68	307.662
1937.67	301.706
1938.67	305.684
1939.66	302.993
1940.64	301.537
1941.63	306.036
1942.62	305.559
1943.61	299.627
1944.6	298.019
1945.59	306.901
1946.58	307.012
1947.57	299.298
1948.56	298.378
1949.55	302.486
1950.53	302.978
1951.52	298.587
1952.51	307.375
1953.5	305.187
1954.48	295.066
1955.47	299.107
1956.46	313.016
1957.44	302.697
1958.43	315.255
1959.42	305.503
1960.4	300.505
1961.39	307.095
1962.38	299.477
1963.36	301.449
1964.35	304.383
1965.33	300.569
1966.32	305.618
1967.3	295.113
1968.29	300.887
1969.27	306.346
1970.26	296.508
1971.24	299.252
1972.23	300.277
1973.21	306.802
1974.19	310.553
1975.18	305.88
1976.16	307.915
1977.14	300.193
1978.12	300.026
1979.11	296.183
1980.09	306.675
1981.07	306.517
1982.06	306.435
1983.04	310.941
1984.02	307.956
1985	298.204
1985.98	303.087
1986.96	294.494
1987.95	297.903
1988.93	304.733
1989.91	299.481
1990.89	299.639
1991.87	297.931
1992.85	313.31
1993.83	304.793
1994.81	304.312
1995.79	305.491
1996.77	296.744
1997.75	297.899
1998.73	302.566
1999.71	300.081
2000.69	297.38
2001.66	301.566
2002.64	296.202
2003.62	299.592
2004.6	301.698
2005.58	298.525
2006.55	301.212
2007.53	299.662
2008.51	298.624
2009.49	306.885
2010.46	294.979
2011.44	293.863
2012.41	298.425
2013.4	291.405
2014.39	292.794
2015.38	304.199
2016.37	295.127
2017.36	293.046
2018.34	300.1
2019.33	297.882
2020.32	296.882
2021.31	298.783
2022.3	299.532
2023.28	295.507
2024.27	297.061
2025.26	290.161
2026.24	303.396
2027.23	291.914
2028.22	292.185
2029.2	298.322
2030.19	297.295
2031.18	294.845
2032.16	303.536
2033.15	297.328
2034.13	307.032
2035.12	297.008
2036.1	304.758
2037.09	291.727
2038.07	292.515
2039.06	296.991
2040.04	293.887
2041.02	301.123
2042.01	296.321
2042.99	293.572
2043.98	305.072
2044.96	293.654
2045.94	300.216
2046.93	293.027
2047.91	291.799
2048.89	294.781
2049.87	289.538
2050.85	292.358
2051.84	300.705
2052.82	296.195
2053.8	298.393
2054.78	297.444
2055.77	297.295
2056.75	289.77
2057.73	293.654
2058.71	305.153
2059.69	307.982
2060.67	290.186
2061.65	291.191
2062.63	299.767
2063.61	298.056
2064.59	298.221
2065.57	303.24
2066.55	302.437
2067.53	296.021
2068.51	298.018
2069.49	302.402
2070.47	284.033
2071.45	321.131
2072.42	299.409
2073.4	299.412
2074.38	302.419
2075.36	294.442
2076.34	309.623
2077.31	297.991
2078.29	301.914
2079.27	304.127
2080.25	296.737
2081.22	296.676
2082.2	300.506
2083.18	306.159
2084.15	301.442
2085.13	292.013
2086.11	310.242
2087.08	307.568
2088.06	300.027
2089.03	295.421
2090.01	296.524
2090.98	296.653
2091.96	299.851
2092.93	298.303
2093.91	305.187
2094.88	301.314
2095.86	301.155
2096.83	297.242
2097.8	303.768
2098.78	302.751
2099.75	316.028
2100.73	302.923
2101.7	300.136
2102.67	301.922
2103.64	306.605
2104.62	294.421
2105.59	300.34
2106.56	295.679
2107.53	299.351
2108.51	307.629
2109.48	300.192
2110.45	310.646
2111.42	297.258
2112.39	307.742
2113.36	307.955
2114.34	295.566
2115.31	310.724
2116.28	305.799
2117.25	304.81
2118.22	302.653
2119.19	301.44
2120.16	302.269
2121.13	295.845
2122.1	303.677
2123.07	307.601
2124.04	300.79
2125.01	301.237
2125.97	307.53
2126.94	295.951
2127.91	301.538
2128.88	298.676
2129.85	304.28
2130.82	297.54
2131.78	311.551
2132.75	312.33
2133.72	291.61
2134.69	302.929
2135.66	299.931
2136.62	302.63
2137.59	303.673
2138.55	301.758
2139.52	290.232
2140.49	306.104
2141.45	297.489
2142.42	306.967
2143.39	292.201
2144.35	302.894
2145.32	295.236
2146.28	305.48
2147.25	306.27
2148.21	302.371
2149.18	297.388
2150.14	309.314
2151.11	298.157
2152.07	301.993
2153.04	306.502
2154	292.213
2154.96	301.089
2155.93	295.21
2156.89	300.81
2157.85	304.719
2158.82	296.239
2159.78	302.523
2160.74	290.207
2161.7	293.869
2162.67	296.607
2163.63	297.409
2164.59	289.759
2165.55	296.335
2166.52	298.971
2167.48	298.64
2168.44	296.575
2169.4	293.128
2170.36	305.45
2171.32	298.55
2172.28	299.185
2173.24	295.462
2174.2	295.553
2175.16	289.937
2176.12	297.279
2177.08	302.843
2178.04	300.896
2179	300.832
2179.96	300.83
2180.92	292.415
2181.88	288.582
2182.84	299.548
2183.8	302.997
2184.75	307.675
2185.71	301.355
2186.67	289.604
2187.63	304.627
2188.59	304.383
2189.54	302.212
2190.5	306.892
2191.46	310.67
2192.41	296.884
2193.37	306.451
2194.33	295.634
2195.29	304.756
2196.24	296.965
2197.2	298.655
2198.15	294.2
2199.11	302.938
2200.06	302.562
2201.02	297.205
2201.98	304.276
2202.93	294.756
2203.89	301.146
2204.84	296.826
2205.79	297.568
2206.75	292.891
2207.7	298.72
2208.66	290.543
2209.61	298.019
2210.57	307.521
2211.52	303.098
2212.47	310.598
2213.43	307.672
2214.38	298.691
2215.33	304.371
2216.28	297.821
2217.24	308.105
2218.19	294.139
2219.14	293.397
2220.09	301.866
2221.05	304.491
2222	295.908
2222.95	300.733
2223.9	308.556
2224.85	292.008
2225.8	303.535
2226.75	299.08
2227.71	305.691
2228.66	294.37
2229.61	304.879
2230.56	307.946
2231.51	307.285
2232.46	304.71
2233.41	294.581
2234.36	307.736
2235.3	306.554
2236.25	308.504
2237.2	304.059
2238.15	297.886
2239.1	304.716
2240.05	298.827
2241	301.937
2241.95	303.934
2242.89	299.232
2243.84	301.988
2244.79	297.627
2245.74	307.354
2246.68	300.919
2247.63	300.017
2248.58	298.061
2249.52	314.231
2250.47	305.498
2251.42	312.945
2252.36	310.345
2253.31	295.655
2254.25	305.317
2255.2	310.061
2256.15	292.216
2257.09	317.101
2258.04	301.058
2258.98	304.063
2259.93	310.849
2260.87	313.95
2261.82	303.585
2262.76	309.555
2263.7	308.096
2264.65	306.543
2265.59	310.443
2266.54	307.307
2267.48	301.378
2268.42	302.301
2269.37	299.761
2270.31	300.075
2271.25	307.935
2272.19	304.235
2273.14	311.01
2274.08	308.211
2275.02	310.214
2275.96	308.483
2276.91	304.953
2277.85	301.548
2278.79	310.208
2279.73	296.422
2280.67	302.932
2281.61	303.873
2282.55	307
2283.49	294.029
2284.43	303.993
2285.37	303.116
2286.31	303.019
2287.25	303.376
2288.19	303.383
2289.13	303.043
2290.07	310.514
2291.01	295.354
2291.95	302.332
2292.89	309.332
2293.83	302.602
2294.77	307.235
2295.71	306.106
2296.64	292.528
2297.58	303.433
2298.52	298.873
2299.46	311.576
2300.4	302.015
2301.33	297.306
2302.27	303.054
2303.21	296.279
2304.14	301.274
2305.08	311.097
2306.02	297.694
2306.96	302.509
2307.89	299.494
2308.83	302.502
2309.76	299.884
2310.7	303.679
2311.63	299.254
2312.57	300.074
2313.5	302.336
2314.44	305.652
2315.38	302.612
2316.31	305.133
2317.24	311.02
2318.18	298.357
2319.11	304.94
2320.05	308.786
2320.98	303.175
2321.91	313.174
2322.85	322.915
2323.78	321.034
2324.71	322.68
2325.65	331.093
2326.58	396.393
2327.51	549.375
2328.45	1076.5
2329.38	517.206
2330.31	348.625
2331.24	334.286
2332.17	322.627
2333.11	308.989
2334.04	298.216
2334.97	295.22
2335.9	307.72
2336.83	308.622
2337.76	308.551
2338.69	301.819
2339.62	308.487
2340.55	295.755
2341.48	309.79
2342.41	300.048
2343.34	299.065
2344.27	297.179
2345.2	300.851
2346.13	300.692
2347.06	295.835
2347.99	292.09
2348.92	307.234
2349.85	295.097
2350.77	305.854
2351.7	300.645
2352.63	301.966
2353.56	296.214
2354.49	296.349
2355.41	293.391
2356.34	299.66
2357.27	296.6
2358.2	297.392
2359.12	299.193
2360.05	297.046
2360.98	290.128
2361.9	296.451
2362.83	297.168
2363.76	294.187
2364.68	295.905
2364.91	299.643