File: Data/3-Raman/raw/bu20-j-ff1-fi01-s_1800 (450-850nm)_532nm_edge_100%_x100_vis_lwd_h30um_30sx2_01.txt
#Acq. time (s)=	30
#Accumulations=	2
#Range=	Off
#Autofocus=	Off
#Macrospot=	Off
#AutoExposure=	Off
#Spike filter=	Multiple accum.
#Delay time (s)=	2
#Binning=	1
#Readout mode=	Signal
#DeNoise=	Off
#ICS correction=	On
#Dark correction=	Off
#Inst. Process=	Off
#Detector Gain=	Best Dynamic
#Detector ADC=	50 kHz HS
#Detector temperature (°C)=	-60.09
#Instrument=	LabRAM HR Evol
#Detector=	SIN-EM FIVIS
#Objective=	x100_VIS_LWD
#Grating=	1800 (450-850nm)
#ND Filter=	100%
#Laser=	532nm_Edge
#Spectro (cm-¹)=	3360
#Hole=	30.0125
#Temperature=	0
#Range=	Visible
#StageXY=	75x50mm Scan+
#StageZ=	Z motor
#X (µm)=	0
#Y (µm)=	0
#Z (µm)=	-8.5
#Full time(mm:ss)=	1:04
#Project=	21_08_11
#Sample=	BU20
#Site=
#Title=	BU20-J-FF1-FI01-S_1800 (450-850nm)_532nm_Edge_100%_x100_VIS_LWD_H30um_30sX2
#Remark=
#Date=	11.08.2021 16:44
#Acquired=	11.08.2021 16:44:50
3515.51	563.673
3515.13	605.547
3514.74	589.525
3514.36	611.478
3513.98	605.65
3513.6	608.447
3513.21	619.86
3512.83	660.712
3512.45	634.071
3512.06	664.543
3511.68	656.931
3511.3	639.186
3510.91	636.907
3510.53	660.238
3510.15	634.57
3509.76	626.136
3509.38	605.487
3509	613.174
3508.61	597.934
3508.23	580.327
3507.84	577.663
3507.46	587.629
3507.08	575.855
3506.69	565.909
3506.31	557.445
3505.93	545.321
3505.54	536.685
3505.16	523.63
3504.77	524.641
3504.39	519.233
3504.01	484.802
3503.62	512.399
3503.24	499.183
3502.85	447.865
3502.47	480.482
3502.09	457.801
3501.7	464.57
3501.32	459.875
3500.93	430.453
3500.55	440.945
3500.16	440.683
3499.78	429.135
3499.4	424.289
3499.01	459.547
3498.63	426.31
3498.24	425.414
3497.86	425.441
3497.47	405.437
3497.09	408.267
3496.7	416.733
3496.32	414.814
3495.93	404.44
3495.55	415.006
3495.17	397.026
3494.78	379.952
3494.4	391.454
3494.01	384.819
3493.63	379.997
3493.24	394.184
3492.86	374.256
3492.47	379.06
3492.09	366.21
3491.7	375.081
3491.32	374.997
3490.93	399.462
3490.55	374.454
3490.16	379.058
3489.78	384.319
3489.39	355.476
3489.01	361.968
3488.62	380.969
3488.23	367.723
3487.85	364.919
3487.46	354.503
3487.08	361.3
3486.69	368.084
3486.31	362.443
3485.92	377.819
3485.54	377.928
3485.15	374.27
3484.76	374.537
3484.38	361.302
3483.99	364.279
3483.61	361.581
3483.22	369.335
3482.84	362.698
3482.45	368.496
3482.06	357.955
3481.68	376.883
3481.29	360.772
3480.91	363.194
3480.52	360.764
3480.13	358.979
3479.75	359.166
3479.36	380.106
3478.98	360.878
3478.59	339.793
3478.2	370.354
3477.82	360.202
3477.43	354.856
3477.04	370.282
3476.66	366.052
3476.27	345.656
3475.88	357.984
3475.5	341.391
3475.11	353.273
3474.73	360.754
3474.34	361.645
3473.95	353.543
3473.57	366.625
3473.18	358.554
3472.79	349.176
3472.41	366.156
3472.02	344.94
3471.63	368.906
3471.24	367.544
3470.86	349.319
3470.47	355.026
3470.08	361.023
3469.7	368.765
3469.31	369.281
3468.92	371.077
3468.54	351.067
3468.15	368.12
3467.76	366.309
3467.38	347.527
3466.99	360.077
3466.6	375.542
3466.21	349.649
3465.83	361.063
3465.44	374.482
3465.05	357.238
3464.66	358.272
3464.28	376.624
3463.89	378.645
3463.5	368.141
3463.11	355.714
3462.73	360.655
3462.34	363.611
3461.95	382.917
3461.56	363.669
3461.18	367.513
3460.79	372.315
3460.4	370.426
3460.01	371.385
3459.62	368.656
3459.24	347.615
3458.85	354.167
3458.46	369.418
3458.07	368.52
3457.68	362.777
3457.3	374.2
3456.91	376.048
3456.52	378.922
3456.13	370.391
3455.74	365.764
3455.36	379.283
3454.97	379.284
3454.58	377.42
3454.19	366.854
3453.8	380.39
3453.41	377.554
3453.03	384.271
3452.64	375.787
3452.25	385.718
3451.86	382.754
3451.47	371.133
3451.08	373.166
3450.69	372.998
3450.31	375.806
3449.92	371.889
3449.53	372.783
3449.14	389.115
3448.75	367.876
3448.36	371.683
3447.97	373.525
3447.58	359.42
3447.19	387.799
3446.81	385.516
3446.42	387.896
3446.03	390.54
3445.64	389.857
3445.25	367.074
3444.86	398.661
3444.47	388.309
3444.08	389.208
3443.69	391.909
3443.3	404.325
3442.91	396.96
3442.52	403.473
3442.14	395.693
3441.75	375.428
3441.36	401.408
3440.97	413.059
3440.58	407.393
3440.19	402.744
3439.8	413.579
3439.41	416.079
3439.02	423.066
3438.63	416.281
3438.24	426.918
3437.85	435.375
3437.46	437.821
3437.07	458.955
3436.68	452.232
3436.29	461.05
3435.9	451.519
3435.51	483.504
3435.12	487.482
3434.73	507.907
3434.34	545.406
3433.95	529.899
3433.56	550.164
3433.17	590.589
3432.78	637.975
3432.39	667.288
3432	720.755
3431.61	755.783
3431.22	811.878
3430.83	915.605
3430.44	950.076
3430.05	1028
3429.66	1098.78
3429.27	1088.84
3428.88	1072.9
3428.48	1069.43
3428.09	991.828
3427.7	910.345
3427.31	884.375
3426.92	819.329
3426.53	725.865
3426.14	722.107
3425.75	649.108
3425.36	626.882
3424.97	618.919
3424.58	587.112
3424.19	551.506
3423.79	558.35
3423.4	542.954
3423.01	507.148
3422.62	526.383
3422.23	501.221
3421.84	484.551
3421.45	502.668
3421.06	449.584
3420.67	478.481
3420.27	478.561
3419.88	450.711
3419.49	462.199
3419.1	462.076
3418.71	440.751
3418.32	457.74
3417.93	440.354
3417.53	436.527
3417.14	438.363
3416.75	456.618
3416.36	426.874
3415.97	437.379
3415.58	427.621
3415.19	435.283
3414.79	430.484
3414.4	410.322
3414.01	411.391
3413.62	421.987
3413.22	434.444
3412.83	406.444
3412.44	426.468
3412.05	426.304
3411.66	399.315
3411.27	427.192
3410.87	397.506
3410.48	413.957
3410.09	424.519
3409.7	422.574
3409.3	431.199
3408.91	411.923
3408.52	425.355
3408.13	400.471
3407.73	433.777
3407.34	423.407
3406.95	429.207
3406.56	424.74
3406.17	416.592
3405.77	438.663
3405.38	421.812
3404.99	437.106
3404.59	423.745
3404.2	447.553
3403.81	437.386
3403.42	430.101
3403.02	441.24
3402.63	422.226
3402.24	435.119
3401.84	449.375
3401.45	429.65
3401.06	437.629
3400.67	440.934
3400.27	451.292
3399.88	445.973
3399.49	444.482
3399.09	444.977
3398.7	426.121
3398.31	459.255
3397.91	451.677
3397.52	448.614
3397.13	465.896
3396.73	462.572
3396.34	479.648
3395.95	480.45
3395.55	451.502
3395.16	472.994
3394.77	484.233
3394.37	455.596
3393.98	495.945
3393.59	493.296
3393.19	493.696
3392.8	520.569
3392.4	499.528
3392.01	509.431
3391.62	514.636
3391.22	504.079
3390.83	525.52
3390.44	556.236
3390.04	547.521
3389.65	533.151
3389.25	576.542
3388.86	593.372
3388.47	606.456
3388.07	628.817
3387.68	640.245
3387.28	649.489
3386.89	669.117
3386.49	686.266
3386.1	709.107
3385.71	722.414
3385.31	761.649
3384.92	799.077
3384.52	855.974
3384.13	850.89
3383.73	912.018
3383.34	940.044
3382.95	971.111
3382.55	1031.62
3382.16	1071.25
3381.76	1117.1
3381.37	1165.99
3380.97	1227.22
3380.58	1234.03
3380.18	1251.25
3379.79	1269.31
3379.39	1255.8
3379	1284.21
3378.6	1275.28
3378.21	1248.33
3377.81	1255.01
3377.42	1197.14
3377.02	1159.15
3376.63	1139.86
3376.23	1106.27
3375.84	1039.23
3375.44	1019.96
3375.05	972.192
3374.65	930.17
3374.25	920.282
3373.86	876.943
3373.46	864.034
3373.07	852.998
3372.67	801.655
3372.28	764.389
3371.88	757.514
3371.49	709.707
3371.09	704.609
3370.7	693.111
3370.3	668.427
3369.9	650.266
3369.51	643.529
3369.11	640.666
3368.72	593.094
3368.32	596.004
3367.93	569.311
3367.53	554.018
3367.13	566.376
3366.74	551.307
3366.34	550.23
3365.95	530.061
3365.55	517.595
3365.15	498.531
3364.76	504.356
3364.36	488.201
3363.97	485.26
3363.57	472.945
3363.17	466.413
3362.78	451.263
3362.38	447.493
3361.98	424.643
3361.59	416.974
3361.19	422.525
3360.79	408.141
3360.4	418.524
3360	422.226
3359.6	415.448
3359.21	386.819
3358.81	405.827
3358.41	398.222
3358.02	390.686
3357.62	384.197
3357.22	370
3356.83	389.971
3356.43	379.406
3356.03	374.503
3355.64	374.41
3355.24	378.175
3354.84	374.344
3354.44	363.883
3354.05	352.476
3353.65	361.996
3353.25	336.314
3352.86	342.975
3352.46	352.545
3352.06	337.406
3351.67	356.434
3351.27	334.518
3350.87	346.021
3350.47	342.285
3350.08	342.308
3349.68	340.381
3349.28	333.631
3348.88	328.758
3348.49	330.55
3348.09	322.788
3347.69	328.407
3347.29	335.061
3346.9	333.227
3346.5	339.044
3346.1	303.992
3345.7	331.668
3345.3	314.528
3344.91	317.422
3344.51	312.633
3344.11	306.93
3343.71	314.659
3343.31	314.717
3342.92	311.833
3342.52	316.609
3342.12	315.704
3341.72	313.893
3341.32	314.962
3340.93	300.71
3340.53	315.042
3340.13	317.933
3339.73	299.843
3339.33	320.84
3338.93	290.364
3338.54	309.354
3338.14	307.679
3337.74	295.515
3337.34	297.587
3336.94	303.356
3336.54	307.988
3336.14	291.647
3335.74	295.5
3335.35	293.625
3334.95	295.634
3334.55	291.004
3334.15	287.257
3333.75	309.264
3333.35	307.385
3332.95	302.604
3332.55	294.936
3332.16	293.956
3331.76	282.45
3331.36	294.89
3330.96	296.702
3330.56	284.167
3330.16	288.924
3329.76	282.382
3329.36	291.099
3328.96	289.438
3328.56	279.051
3328.16	282.91
3327.76	287.702
3327.37	284.789
3326.97	284.657
3326.57	275.875
3326.17	277.774
3325.77	290.157
3325.37	284.653
3324.97	284.02
3324.57	284.134
3324.17	281.529
3323.77	276.908
3323.37	297.045
3322.97	280.851
3322.57	276.992
3322.17	277.824
3321.77	275.053
3321.37	273.31
3320.97	287.976
3320.57	280.418
3320.17	273.654
3319.77	280.285
3319.37	272.531
3318.97	266.653
3318.57	283.818
3318.17	278.047
3317.77	281.998
3317.37	283.03
3316.97	280.241
3316.57	271.619
3316.17	263.19
3315.77	266.668
3315.37	275.345
3314.97	269.167
3314.57	273.249
3314.17	278.867
3313.77	287.151
3313.37	260.009
3312.97	258.405
3312.56	270.054
3312.16	283.148
3311.76	277.366
3311.36	261.114
3310.96	281.239
3310.56	267.858
3310.16	272.647
3309.76	263.054
3309.36	265.924
3308.96	250.645
3308.56	268.914
3308.15	266.188
3307.75	248.146
3307.35	277.054
3306.95	274.272
3306.55	257.002
3306.15	271.36
3305.75	277.171
3305.35	258.013
3304.94	262.823
3304.54	272.601
3304.14	267.072
3303.74	261.48
3303.34	247.875
3302.94	263.022
3302.53	262.327
3302.13	264.458
3301.73	265.071
3301.33	261.062
3300.93	265.888
3300.53	262.039
3300.13	247.814
3299.72	259.495
3299.32	274.578
3298.92	259.068
3298.52	257.135
3298.12	260.107
3297.71	262.247
3297.31	265.3
3296.91	265.365
3296.51	266.312
3296.11	260.476
3295.7	263.28
3295.3	259.388
3294.9	259.309
3294.5	261.18
3294.1	261.225
3293.69	252.638
3293.29	270.972
3292.89	254.634
3292.49	269.042
3292.08	261.319
3291.68	259.848
3291.28	251.823
3290.88	256.499
3290.47	255.314
3290.07	251.259
3289.67	255.218
3289.27	238.074
3288.86	241.034
3288.46	243.973
3288.06	249.768
3287.65	262.345
3287.25	245.109
3286.85	258.636
3286.45	250.973
3286.04	237.519
3285.64	260.618
3285.24	250.907
3284.83	249.824
3284.43	251.64
3284.03	256.246
3283.62	233.144
3283.22	250.004
3282.82	259.665
3282.41	245.804
3282.01	244.104
3281.61	259.431
3281.2	255.59
3280.8	240.163
3280.4	260.374
3279.99	252.619
3279.59	242.932
3279.19	240.045
3278.78	234.275
3278.38	244.895
3277.98	257.466
3277.57	245
3277.17	258.517
3276.76	252.757
3276.36	245.996
3275.96	240.182
3275.55	247.867
3275.15	235.216
3274.74	244.837
3274.34	247.012
3273.94	246.379
3273.53	252.109
3273.13	241.711
3272.72	246.606
3272.32	258.261
3271.92	242.944
3271.51	245.799
3271.11	253.558
3270.7	245.921
3270.3	254.643
3269.9	250.851
3269.49	234.494
3269.09	258.576
3268.68	243.141
3268.28	239.216
3267.87	244.93
3267.47	237.163
3267.06	248.664
3266.66	249.623
3266.25	245.831
3265.85	251.712
3265.44	254.743
3265.04	247.179
3264.64	247.211
3264.23	238.526
3263.83	236.557
3263.42	253.812
3263.02	245.985
3262.61	241.094
3262.21	247.745
3261.8	250.59
3261.4	236.172
3260.99	246.777
3260.59	244.989
3260.18	240.04
3259.78	247.977
3259.37	243.303
3258.96	238.427
3258.56	252.928
3258.15	246.156
3257.75	249.914
3257.34	245.989
3256.94	237.221
3256.53	243.855
3256.13	250.5
3255.72	239.852
3255.31	243.661
3254.91	247.567
3254.5	254.283
3254.1	248.451
3253.69	225.36
3253.29	234.995
3252.88	251.397
3252.47	243.788
3252.07	236.147
3251.66	233.275
3251.26	241.905
3250.85	232.208
3250.44	240.719
3250.04	219.417
3249.63	240.454
3249.23	242.394
3248.82	242.479
3248.41	247.378
3248.01	227.352
3247.6	232.191
3247.2	240.782
3246.79	235.888
3246.38	230.001
3245.98	243.239
3245.57	229.67
3245.16	227.536
3244.76	229.417
3244.35	238.19
3243.94	229.637
3243.54	226.766
3243.13	233.577
3242.72	237.472
3242.32	230.808
3241.91	219.322
3241.5	231.779
3241.1	235.633
3240.69	224.111
3240.28	243.266
3239.88	232.688
3239.47	231.755
3239.06	229.828
3238.65	226.982
3238.25	236.509
3237.84	228.729
3237.43	218.118
3237.03	235.371
3236.62	228.691
3236.21	214.396
3235.8	231.748
3235.4	227.979
3234.99	228.959
3234.58	217.389
3234.18	238.488
3233.77	219.267
3233.36	233.633
3232.95	213.468
3232.54	221.144
3232.14	234.586
3231.73	220.246
3231.32	222.044
3230.91	224.86
3230.51	215.414
3230.1	223.857
3229.69	231.573
3229.28	215.677
3228.87	214.175
3228.47	211.294
3228.06	221.107
3227.65	226.51
3227.24	224.634
3226.83	220.504
3226.43	207.95
3226.02	220.386
3225.61	203.097
3225.2	220.139
3224.79	213.292
3224.39	208.32
3223.98	217.774
3223.57	200.537
3223.16	213.99
3222.75	230.304
3222.34	221.725
3221.94	214.104
3221.53	209.285
3221.12	203.46
3220.71	218.656
3220.3	209.951
3219.89	210.847
3219.48	212.753
3219.07	200.418
3218.67	213.786
3218.26	199.366
3217.85	209.193
3217.44	212.478
3217.03	203.029
3216.62	211.424
3216.21	219.755
3215.8	217.488
3215.39	201.342
3214.99	207.172
3214.58	215.845
3214.17	204.311
3213.76	195.637
3213.35	205.196
3212.94	210.967
3212.53	206.183
3212.12	209.052
3211.71	198.518
3211.3	212.848
3210.89	204.216
3210.48	190.798
3210.07	207.08
3209.66	202.423
3209.25	199.644
3208.84	205.446
3208.44	204.491
3208.02	206.337
3207.62	198.666
3207.21	197.675
3206.8	197.659
3206.39	188.088
3205.98	196.727
3205.57	203.425
3205.16	202.425
3204.75	185.128
3204.34	197.552
3203.93	196.627
3203.52	196.656
3203.11	194.774
3202.7	200.566
3202.29	196.768
3201.88	200.645
3201.47	186.286
3201.06	203.458
3200.65	193.845
3200.23	183.291
3199.82	189.015
3199.41	202.407
3199	184.247
3198.59	199.607
3198.39	190.1