File: Data/3-Raman/raw/bu32-a-incc-fi03-v_1800 (450-850nm)_532nm_edge_100%_x100_vis_lwd_h30um_40sx2_01.txt
#Acq. time (s)=	40
#Accumulations=	2
#Range (cm-¹)=	1200...2365
#Windows=	3
#Auto scanning=	Off
#Autofocus=	Off
#Macrospot=	Off
#AutoExposure=	Off
#Spike filter=	Multiple accum.
#Delay time (s)=	2
#Binning=	1
#Readout mode=	Signal
#DeNoise=	Off
#ICS correction=	On
#Dark correction=	Off
#Inst. Process=	Off
#Detector Gain=	Best Dynamic
#Detector ADC=	50 kHz EM
#Detector EM gain=	400
#Detector temperature (°C)=	-60.09
#Instrument=	LabRAM HR Evol
#Detector=	SIN-EM FIVIS
#Objective=	x100_VIS_LWD
#Grating=	1800 (450-850nm)
#ND Filter=	100%
#Laser=	532nm_Edge
#Hole=	30.0125
#Temperature=	0
#Range=	Visible
#StageXY=	75x50mm Scan+
#StageZ=	Z motor
#X (µm)=	0
#Y (µm)=	0
#Z (µm)=	10.2
#Full time(mm:ss)=	4:24
#Project=	21_11_26
#Sample=	BU32
#Site=
#Title=	BU32-A-incC-FI03-V_1800 (450-850nm)_532nm_Edge_100%_x100_VIS_LWD_H30um_40sX2
#Remark=
#Date=	26.11.2021 18:11
#Acquired=	26.11.2021 18:11:05
1202.72	477.486
1203.84	475.537
1204.95	478.431
1206.06	509.947
1207.17	512.202
1208.28	519.163
1209.39	438.431
1210.5	485.264
1211.61	502.674
1212.72	487.077
1213.83	458.949
1214.94	480.193
1216.05	449.24
1217.16	456.037
1218.27	477.828
1219.38	456.313
1220.49	462.484
1221.6	449.611
1222.71	476.553
1223.81	452.425
1224.92	440.299
1226.03	475.173
1227.14	446.584
1228.25	448.742
1229.35	503.375
1230.46	440.472
1231.57	451.851
1232.67	450.807
1233.78	458.071
1234.89	476.117
1235.99	444.799
1237.1	493.056
1238.2	443.093
1239.31	462.5
1240.41	451.863
1241.52	448.772
1242.62	486.335
1243.73	440.371
1244.83	438.276
1245.94	417.98
1247.04	479.51
1248.14	460.565
1249.25	446.716
1250.35	479.135
1251.45	442.139
1252.56	461.666
1253.66	469.7
1254.76	472.059
1255.87	454.386
1256.97	467.024
1258.07	442.899
1259.17	449.983
1260.27	429.39
1261.37	455.001
1262.48	418.355
1263.58	456.868
1264.68	427.991
1265.78	455.799
1266.88	462.082
1267.98	490.781
1269.08	490.391
1270.18	448.498
1271.28	447.037
1272.38	441.855
1273.47	456.006
1274.57	449.106
1275.67	456.507
1276.77	469.456
1277.87	474.05
1278.97	452.401
1280.07	456.698
1281.16	447.243
1282.26	446.498
1283.36	452.615
1284.45	453.338
1285.55	452.026
1286.65	461.456
1287.75	451.8
1288.84	420.113
1289.94	453.007
1291.03	422.588
1292.13	416.225
1293.22	438.32
1294.32	448.347
1295.42	476.931
1296.51	445.174
1297.61	449.341
1298.7	454.37
1299.79	453.076
1300.89	463.775
1301.98	459.62
1303.08	440.732
1304.17	415.225
1305.26	431.023
1306.35	441.205
1307.45	432.686
1308.54	434.829
1309.63	434.963
1310.73	451.919
1311.82	445.658
1312.91	476.495
1314	432.012
1315.09	446.835
1316.18	416.436
1317.28	464.949
1318.37	433.405
1319.46	418.638
1320.55	441.888
1321.64	414.135
1322.73	429.586
1323.82	444.198
1324.91	467.422
1326	450.256
1327.09	443.209
1328.18	443.965
1329.27	432.891
1330.35	439.166
1331.44	453.557
1332.53	429.754
1333.62	429.191
1334.71	433.963
1335.79	459.836
1336.88	456.409
1337.97	452.039
1339.06	433.886
1340.14	475.759
1341.23	460.09
1342.32	432.699
1343.4	475.209
1344.49	451.113
1345.58	457.175
1346.66	444.015
1347.75	447.656
1348.83	459.957
1349.92	475.254
1351	462.4
1352.09	461.02
1353.17	474.836
1354.25	457.606
1355.34	450.317
1356.42	468.973
1357.51	462.515
1358.59	427.977
1359.67	448.422
1360.76	449.034
1361.84	472.719
1362.92	452.872
1364	446.809
1365.09	467.501
1366.17	442.268
1367.25	453.163
1368.33	465.551
1369.41	465.679
1370.5	435.578
1371.58	406.297
1372.66	460.37
1373.74	430.172
1374.82	460.945
1375.9	457.841
1376.98	461.753
1378.06	467.766
1379.14	475.738
1380.22	503.321
1381.3	477.61
1382.38	513.07
1383.46	502.079
1384.54	501.796
1385.61	504.321
1386.69	461.603
1387.77	470.637
1388.85	459.578
1389.93	433.818
1391	439.322
1392.08	412.334
1393.16	460.133
1394.23	430.284
1395.31	421.053
1396.39	430.399
1397.46	413.814
1398.54	450.553
1399.62	420.045
1400.69	400.742
1401.77	413.22
1402.84	422.052
1403.92	433.741
1404.99	443.703
1406.07	449.574
1407.14	438.174
1408.22	427.025
1409.29	419.974
1410.37	433.411
1411.44	385.843
1412.51	425.736
1413.59	409.43
1414.66	420.243
1415.73	401.958
1416.81	445.223
1417.88	420.774
1418.95	420.855
1420.02	402.264
1421.1	432.752
1422.17	407.118
1423.24	414.139
1424.31	412.796
1425.38	400.511
1426.45	441.659
1427.52	436.109
1428.59	421.371
1429.67	418.425
1430.74	424.94
1431.81	433.695
1432.87	416.025
1433.95	394.934
1435.01	440.161
1436.08	435.041
1437.15	432.867
1438.22	422.52
1439.29	470.82
1440.36	436.311
1441.43	445.666
1442.49	444.599
1443.56	435.352
1444.63	432.195
1445.7	419.199
1446.77	430.352
1447.83	408.67
1448.9	405.724
1449.97	438.482
1451.03	443.406
1452.1	423.79
1453.17	409.433
1454.23	408.48
1455.3	424.853
1456.36	422.908
1457.43	412.499
1458.49	431.901
1459.56	395.097
1460.62	428.854
1461.69	416.385
1462.75	419.178
1463.82	390.188
1464.88	420.303
1465.94	397.661
1467.01	429.171
1468.07	429.106
1469.13	422.935
1470.2	432.865
1471.26	402.087
1472.32	406.97
1473.39	382.473
1474.45	404.684
1475.51	417.99
1476.57	412.763
1477.63	403.415
1478.69	433.773
1479.76	428.42
1480.82	402.599
1481.88	409.561
1482.94	431.174
1484	420.091
1485.06	416.201
1486.12	374.548
1487.18	407.019
1488.24	396.691
1489.3	411.558
1490.36	417.523
1491.42	404.164
1492.48	404.13
1493.53	420.262
1494.59	408.124
1495.65	414.028
1496.71	411.618
1497.77	425.639
1498.82	412.504
1499.88	396.452
1500.94	423.746
1502	390.284
1503.05	383.082
1504.11	381.889
1505.17	396.051
1506.22	408.804
1507.28	396.754
1508.34	378.624
1509.39	404.834
1510.45	402.886
1511.5	415.625
1512.56	398.752
1513.61	389.287
1514.67	382.506
1515.72	397.24
1516.78	416.942
1517.83	391.817
1518.88	382.942
1519.94	441.243
1520.99	386.019
1522.05	425.226
1523.1	398.975
1524.15	416.569
1525.2	383.35
1526.26	394.534
1527.31	405.771
1528.36	388.593
1529.41	403.481
1530.47	375.333
1531.52	417.666
1532.57	413.601
1533.62	413.036
1534.67	419.124
1535.72	398.884
1536.77	397.347
1537.82	380.928
1538.87	438.683
1539.92	404.291
1540.97	393.921
1542.02	405.708
1543.07	433.352
1544.12	405.87
1545.17	410.124
1546.22	424.543
1547.27	398.59
1548.32	428.434
1549.37	399.172
1550.42	430.348
1551.46	407.496
1552.51	415.546
1553.56	436.318
1554.61	395.903
1555.65	385.545
1556.7	396.535
1557.75	385.58
1558.79	406.298
1559.84	415.848
1560.89	415.645
1561.93	413.725
1562.98	420.948
1564.02	395.875
1565.07	409.199
1566.11	416.726
1567.16	403.458
1568.2	407.768
1569.25	401.867
1570.29	413.667
1571.34	411.66
1572.38	434.452
1573.43	415.226
1574.47	429.161
1575.51	421.58
1576.56	422.641
1577.6	417.163
1578.64	441.617
1579.69	394.734
1580.73	400.835
1581.77	428.571
1582.81	422.359
1583.85	411.325
1584.9	408.36
1585.94	413.322
1586.98	401.072
1588.02	418.834
1589.06	406.043
1590.1	430.092
1591.14	388.388
1592.18	433.118
1593.22	424.764
1594.26	406.283
1595.3	407.353
1596.34	391.326
1597.38	398.326
1598.42	410.269
1599.46	414.877
1600.5	386.83
1601.54	423.078
1602.58	410.785
1603.62	402.523
1604.66	401.449
1605.69	409.401
1606.73	409.589
1607.77	415.461
1608.81	432.063
1609.84	408.562
1610.88	408.783
1611.92	429.287
1612.95	424.051
1613.99	401.583
1615.03	410.048
1616.06	396.012
1617.1	408.027
1618.13	395.426
1619.17	410.836
1620.2	416.681
1621.24	416.805
1622.27	413.34
1623.31	418.253
1624.34	420.977
1625.38	410.138
1626.41	406.174
1627.45	414.326
1628.48	425.718
1629.51	413.017
1630.55	408.967
1631.53	390.028
1632.57	451.302
1633.62	429.577
1634.66	416.861
1635.71	414.847
1636.75	444.215
1637.8	448.876
1638.84	403.453
1639.89	409.351
1640.93	412.367
1641.98	410.391
1643.02	415.218
1644.06	397.426
1645.11	424.792
1646.15	406.216
1647.19	393.261
1648.24	410.826
1649.28	409.228
1650.32	458.424
1651.37	411.551
1652.41	429.363
1653.45	416.446
1654.49	392.879
1655.53	388.116
1656.57	429.973
1657.62	411.222
1658.66	406.133
1659.7	396.026
1660.74	403.844
1661.78	414.988
1662.82	405.58
1663.86	406.611
1664.9	404.354
1665.94	422.548
1666.98	388.531
1668.02	418.9
1669.06	395.291
1670.1	398.54
1671.14	394.88
1672.18	396.777
1673.21	407.688
1674.25	409.759
1675.29	388.225
1676.33	392.27
1677.37	386.363
1678.4	405.952
1679.44	394.8
1680.48	387.728
1681.52	389.562
1682.55	410.292
1683.59	384.573
1684.63	396.32
1685.66	405.123
1686.7	399.232
1687.73	384.507
1688.77	409.015
1689.81	402.795
1690.84	394.791
1691.88	408.748
1692.91	396.852
1693.95	402.362
1694.98	410.913
1696.01	411.954
1697.05	396.298
1698.08	407.785
1699.12	409.462
1700.15	377.95
1701.18	381.777
1702.22	398.287
1703.25	398.029
1704.28	369.429
1705.32	393.078
1706.35	401.823
1707.38	380.819
1708.41	396.066
1709.44	409.272
1710.48	394.488
1711.51	378.95
1712.54	400.512
1713.57	369.575
1714.6	382.85
1715.63	388.701
1716.66	409.199
1717.69	395.007
1718.72	373.889
1719.75	394.182
1720.78	380.524
1721.81	379.209
1722.84	387.567
1723.87	411.544
1724.9	372.575
1725.93	382.706
1726.96	398.059
1727.99	371.774
1729.02	354.583
1730.05	369.665
1731.07	352.06
1732.1	374.7
1733.13	371.634
1734.16	380.773
1735.18	373.534
1736.21	380.862
1737.24	393.182
1738.26	373.709
1739.29	383.939
1740.32	373.741
1741.34	365.629
1742.37	377.809
1743.4	358.539
1744.42	378.437
1745.45	379.305
1746.47	401.142
1747.5	364.403
1748.52	364.172
1749.55	348.017
1750.57	367.407
1751.6	359.911
1752.62	376.75
1753.64	373.554
1754.67	356.088
1755.69	378.76
1756.71	363.174
1757.74	367.534
1758.76	368.599
1759.78	375.289
1760.81	346.636
1761.83	356.856
1762.85	360.625
1763.87	381.579
1764.89	366.637
1765.92	377.269
1766.94	360.098
1767.96	383.77
1768.98	362.669
1770	380.984
1771.02	358.38
1772.04	364.378
1773.06	364.583
1774.08	382.823
1775.1	358.185
1776.12	385.218
1777.14	354.707
1778.16	383.048
1779.18	368.438
1780.2	368.367
1781.22	396.091
1782.24	363.825
1783.26	358.346
1784.28	371.875
1785.29	374.985
1786.31	334.815
1787.33	394.14
1788.35	333.693
1789.37	364.827
1790.38	369.941
1791.4	375.637
1792.42	350.433
1793.43	371.613
1794.45	375.518
1795.47	360.503
1796.48	367.627
1797.5	344.847
1798.51	385.398
1799.53	363.242
1800.55	365.869
1801.56	374.396
1802.58	372.543
1803.59	365.115
1804.61	354.694
1805.62	371.357
1806.64	362.015
1807.65	363.071
1808.66	375.616
1809.68	346.742
1810.69	360.279
1811.7	374.683
1812.72	361.236
1813.73	376.856
1814.74	341.468
1815.76	366.852
1816.77	372.727
1817.78	365.732
1818.79	351.292
1819.8	389.087
1820.82	371.855
1821.83	373.972
1822.84	358.636
1823.85	352.822
1824.86	361.541
1825.87	367.479
1826.88	367.494
1827.89	372.44
1828.9	383.077
1829.91	362.61
1830.92	370.203
1831.93	393.584
1832.94	381.216
1833.95	369.683
1834.96	363.613
1835.97	372.72
1836.98	359.531
1837.99	385.481
1839	367.056
1840	364.65
1841.01	391.003
1842.02	365.175
1843.03	388.965
1844.04	379.31
1845.04	351.339
1846.05	340.82
1847.06	365.296
1848.07	367.877
1849.07	375.641
1850.08	390.736
1851.09	376.793
1852.09	340.046
1853.1	350.579
1854.1	363.867
1855.11	353.887
1856.11	347.788
1857.12	348.685
1858.12	343.757
1859.13	369.295
1860.13	361.377
1861.14	385.435
1862.14	344.49
1863.15	358.599
1864.15	376.428
1865.15	356.085
1866.16	374.692
1867.16	378.808
1868.16	360.254
1869.17	359.253
1870.17	349.673
1871.17	345.803
1872.17	370.365
1873.18	365.381
1874.18	349.089
1875.18	347.809
1876.18	353.914
1877.18	347.852
1878.18	355.841
1879.19	355.479
1880.19	350.076
1881.19	346.238
1882.19	359.9
1883.19	365.734
1884.19	348.368
1885.19	367.397
1886.19	356.532
1887.19	356.477
1888.19	342.92
1889.19	343.388
1890.19	342.243
1891.19	357.519
1892.18	344.249
1893.18	346.911
1894.18	342.609
1895.18	346.199
1896.18	365.099
1897.18	350.287
1898.17	361.661
1899.17	336.997
1900.17	332.06
1901.16	353.65
1902.16	344.515
1903.16	357.807
1904.16	357.663
1905.15	356.654
1906.15	353.685
1907.14	356.243
1908.14	360.977
1909.14	340.455
1910.13	362.393
1911.13	355.296
1912.12	364.811
1913.12	381.697
1914.11	341.355
1915.11	346.399
1916.1	340.861
1917.1	339.741
1918.09	371.619
1919.08	361.48
1920.08	349.699
1921.07	360.152
1922.06	355.711
1923.06	364.163
1924.05	347.936
1925.04	343.98
1926.04	341.374
1927.03	346.487
1928.02	337.227
1929.01	360.105
1930	365.138
1931	350.335
1931.99	356.936
1932.98	372.853
1933.97	343.494
1934.96	346.387
1935.95	361.448
1936.94	355.377
1937.93	333.161
1938.92	347.418
1939.91	367.614
1940.9	349.752
1941.89	379.646
1942.88	355.939
1943.87	373.852
1944.86	371.249
1945.85	375.428
1946.84	365.155
1947.83	367.961
1948.82	351.655
1949.8	338.481
1950.79	368.652
1951.78	363.458
1952.77	370.473
1953.76	358.024
1954.74	371.635
1955.73	354.19
1956.72	321.196
1957.7	357.038
1958.69	369.709
1959.68	361.895
1960.66	360.745
1961.65	353.77
1962.63	359.531
1963.62	385.501
1964.61	349.128
1965.59	351.962
1966.58	352.146
1967.56	359.036
1968.55	383.129
1969.53	356.972
1970.52	346.011
1971.5	375.538
1972.48	364.976
1973.47	332.281
1974.45	341.649
1975.44	358.926
1976.42	357.188
1977.4	366.801
1978.39	361.815
1979.37	339.649
1980.35	351.177
1981.33	368.227
1982.31	378.622
1983.3	355.414
1984.28	379.075
1985.26	336.824
1986.24	356.78
1987.22	363.592
1988.21	370.008
1989.19	362.391
1990.17	352.85
1991.15	362.979
1992.13	363.328
1993.11	357.808
1994.09	368.897
1995.07	348.102
1996.05	350.613
1997.03	356.208
1998.01	359.886
1998.99	356.833
1999.97	345.838
2000.95	363.367
2001.92	364.374
2002.9	357.497
2003.88	353.898
2004.86	342.321
2005.84	348.653
2006.81	344.366
2007.79	363.228
2008.77	348.629
2009.75	337.955
2010.73	345.765
2011.7	351.127
2012.68	368.834
2013.67	371.231
2014.66	338.693
2015.64	347.931
2016.63	351.834
2017.62	363.341
2018.61	336.57
2019.6	362.295
2020.58	349.955
2021.57	339.657
2022.56	368.584
2023.55	346.717
2024.54	370.716
2025.52	350.614
2026.51	354.982
2027.5	343.758
2028.48	373.244
2029.47	359.799
2030.45	348.433
2031.44	364.448
2032.43	328.106
2033.41	364.038
2034.4	321.081
2035.38	341.114
2036.37	358.682
2037.35	343.61
2038.34	350.985
2039.32	344.221
2040.31	356.988
2041.29	365.954
2042.27	351.8
2043.26	369.349
2044.24	357.654
2045.23	355.573
2046.21	344.162
2047.19	349.436
2048.17	352.713
2049.16	345.341
2050.14	341.06
2051.12	345.988
2052.11	350.453
2053.09	335.623
2054.07	341.598
2055.05	351.062
2056.03	361.174
2057.01	337.686
2058	349.919
2058.98	355.804
2059.96	356.909
2060.94	378.298
2061.92	370.025
2062.9	346.697
2063.88	356.282
2064.86	340.482
2065.84	352.07
2066.82	357.922
2067.8	344.924
2068.78	344.145
2069.76	351.565
2070.73	344.951
2071.71	364.919
2072.69	339.068
2073.67	353.127
2074.65	354.153
2075.63	364.966
2076.6	345.544
2077.58	382.164
2078.56	376.408
2079.54	352.076
2080.51	342.036
2081.49	366.588
2082.47	361.86
2083.45	350.566
2084.42	369.437
2085.4	361.89
2086.37	376.186
2087.35	361.339
2088.32	361.44
2089.3	340.674
2090.28	339.011
2091.25	375.127
2092.23	352.654
2093.2	364.493
2094.18	342.98
2095.15	344.946
2096.13	349.495
2097.1	338.948
2098.07	368.162
2099.05	358.575
2100.02	351.874
2101	364.278
2101.97	353.107
2102.94	365.422
2103.92	349.093
2104.89	365.3
2105.86	353.198
2106.83	360.961
2107.8	348.619
2108.78	339.717
2109.75	363.458
2110.72	331.233
2111.69	365.398
2112.66	362.432
2113.63	358.834
2114.61	346.53
2115.58	348.424
2116.55	353.011
2117.52	347.173
2118.49	356.526
2119.46	371.335
2120.43	320.83
2121.4	363.552
2122.37	358.184
2123.34	344.153
2124.31	346.971
2125.28	337.979
2126.25	364.955
2127.21	358.944
2128.18	340.828
2129.15	336.985
2130.12	362.417
2131.09	346.246
2132.06	344.153
2133.02	370.365
2133.99	335.432
2134.96	353.377
2135.93	343.862
2136.89	347.306
2137.86	342.66
2138.83	338.76
2139.79	336.008
2140.76	370.575
2141.73	368.591
2142.69	358.981
2143.66	354.544
2144.62	321.868
2145.59	348.205
2146.55	365.057
2147.52	357.385
2148.48	354.388
2149.45	360.735
2150.42	329.368
2151.38	344.279
2152.34	347.258
2153.31	333.072
2154.27	341.327
2155.24	363.293
2156.2	337.571
2157.16	342.111
2158.13	365.606
2159.09	330.138
2160.05	355.16
2161.01	352.96
2161.98	346.297
2162.94	345.338
2163.9	344.248
2164.86	340.269
2165.83	358.896
2166.79	365.338
2167.75	338.064
2168.71	365.476
2169.67	358.166
2170.63	335.327
2171.59	335.229
2172.56	346.743
2173.51	359.62
2174.48	351.351
2175.44	338.345
2176.4	354.99
2177.36	319.577
2178.32	337.24
2179.28	353.745
2180.23	337.977
2181.19	348.127
2182.15	344.295
2183.11	350.653
2184.07	320.661
2185.03	348.35
2185.99	337.352
2186.95	363.597
2187.9	324.988
2188.86	360.124
2189.82	358.807
2190.78	345.669
2191.73	329.053
2192.69	329.161
2193.65	346.06
2194.6	343.776
2195.56	353.032
2196.52	348.028
2197.47	356.048
2198.43	365.317
2199.38	360.158
2200.34	379.276
2201.3	356.631
2202.25	351.727
2203.21	351.402
2204.16	348.935
2205.12	360.408
2206.07	379.991
2207.03	354.855
2207.98	341.113
2208.93	340.458
2209.89	376.885
2210.84	351.835
2211.8	363.246
2212.75	346.693
2213.7	354.934
2214.66	359.771
2215.61	348.8
2216.56	346.018
2217.51	342.241
2218.47	359.068
2219.42	351.76
2220.37	348.204
2221.32	345.326
2222.27	357.143
2223.23	339.423
2224.18	322.89
2225.13	342.879
2226.08	344.149
2227.03	339.737
2227.98	329.605
2228.93	367.025
2229.88	351.106
2230.83	344.845
2231.78	328.245
2232.73	336.024
2233.68	359.793
2234.63	368.404
2235.58	359.666
2236.53	358.675
2237.48	339.056
2238.43	335.762
2239.38	357.866
2240.33	335.078
2241.27	360.7
2242.22	356.079
2243.17	372.251
2244.12	356.058
2245.07	346.777
2246.01	350.978
2246.96	339.867
2247.91	351.378
2248.85	347.525
2249.8	343.747
2250.75	336.105
2251.69	332.062
2252.64	343.493
2253.59	343.991
2254.53	350.942
2255.48	345.29
2256.42	352.967
2257.37	334.23
2258.32	352.436
2259.26	328.81
2260.2	358.42
2261.15	339.566
2262.1	331.22
2263.04	359.003
2263.98	330.822
2264.93	348.473
2265.87	328.645
2266.81	325.618
2267.76	338.718
2268.7	356.626
2269.65	335.868
2270.59	349.665
2271.53	359.477
2272.47	347.245
2273.42	327.215
2274.36	359.825
2275.3	339.804
2276.24	348.503
2277.18	342.113
2278.13	353.126
2279.07	349.521
2280.01	335.827
2280.95	335.493
2281.89	338.21
2282.83	351.814
2283.77	349.34
2284.71	345.105
2285.65	328.971
2286.59	356.666
2287.54	345.506
2288.47	331.216
2289.41	357.907
2290.35	326.683
2291.29	369.974
2292.23	352.059
2293.17	365.839
2294.11	348.673
2295.05	359.08
2295.99	351.174
2296.93	351.847
2297.86	341.482
2298.8	337.967
2299.74	340.185
2300.68	363.357
2301.61	361.622
2302.55	337.481
2303.49	348.055
2304.43	362.63
2305.36	334.838
2306.3	360.089
2307.24	351.453
2308.17	335.877
2309.11	366.748
2310.04	356.438
2310.98	329.463
2311.92	338.605
2312.85	352.761
2313.79	344.171
2314.72	351.382
2315.66	337.093
2316.59	340.525
2317.52	340.387
2318.46	316.296
2319.39	343.12
2320.33	358.444
2321.26	349.852
2322.2	346.288
2323.13	324.271
2324.06	347.557
2325	336.816
2325.93	342.234
2326.86	348.696
2327.79	373.474
2328.73	339.651
2329.66	353.878
2330.59	325.914
2331.52	346.088
2332.46	343.293
2333.39	360.406
2334.32	344.835
2335.25	364.789
2336.18	331.132
2337.11	338.737
2338.04	335.776
2338.97	344.357
2339.91	345.324
2340.84	338.405
2341.77	338.95
2342.7	345.387
2343.63	345.32
2344.56	339.563
2345.49	357.714
2346.41	331.564
2347.34	334.344
2348.27	360.187
2349.2	353.517
2350.13	334.805
2351.06	343.67
2351.99	353.651
2352.91	363.602
2353.84	346.873
2354.77	340.211
2355.7	328.793
2356.63	334.267
2357.55	337.652
2358.48	341.259
2359.41	342.044
2360.33	337.097
2361.26	332.982
2362.19	347.801
2363.11	358.815
2364.04	329.276
2364.97	326.247