File: Data/3-Raman/raw/bu32-a-incc-fi02-v_1800 (450-850nm)_532nm_edge_100%_x100_vis_lwd_h30um_40sx2_01.txt
#Acq. time (s)=	40
#Accumulations=	2
#Range (cm-¹)=	1200...2365
#Windows=	3
#Auto scanning=	Off
#Autofocus=	Off
#Macrospot=	Off
#AutoExposure=	Off
#Spike filter=	Multiple accum.
#Delay time (s)=	2
#Binning=	1
#Readout mode=	Signal
#DeNoise=	Off
#ICS correction=	On
#Dark correction=	Off
#Inst. Process=	Off
#Detector Gain=	Best Dynamic
#Detector ADC=	50 kHz EM
#Detector EM gain=	400
#Detector temperature (°C)=	-60.09
#Instrument=	LabRAM HR Evol
#Detector=	SIN-EM FIVIS
#Objective=	x100_VIS_LWD
#Grating=	1800 (450-850nm)
#ND Filter=	100%
#Laser=	532nm_Edge
#Hole=	30.0125
#Temperature=	0
#Range=	Visible
#StageXY=	75x50mm Scan+
#StageZ=	Z motor
#X (µm)=	0
#Y (µm)=	0
#Z (µm)=	1.4
#Full time(mm:ss)=	4:20
#Project=	21_11_26
#Sample=	BU32
#Site=
#Title=	BU32-A-incC-FI02-V_1800 (450-850nm)_532nm_Edge_100%_x100_VIS_LWD_H30um_40sX2
#Remark=
#Date=	26.11.2021 17:41
#Acquired=	26.11.2021 17:41:20
1202.72	420.489
1203.84	410.975
1204.95	396.703
1206.06	404.709
1207.17	431.798
1208.28	399.228
1209.39	404.155
1210.5	431.755
1211.61	439.631
1212.72	398.531
1213.83	430.103
1214.94	416.206
1216.05	405.48
1217.16	413.392
1218.27	407.616
1219.38	390.379
1220.49	413.539
1221.6	439.902
1222.71	412.844
1223.81	428.987
1224.92	388.373
1226.03	408.451
1227.14	410.479
1228.25	404.281
1229.35	390.711
1230.46	415.995
1231.57	411.672
1232.67	409.568
1233.78	416.83
1234.89	410.681
1235.99	371.963
1237.1	428.636
1238.2	411.288
1239.31	413.944
1240.41	386.544
1241.52	386.58
1242.62	391.67
1243.73	416.948
1244.83	402.264
1245.94	406.079
1247.04	368.167
1248.14	380.632
1249.25	403.424
1250.35	392.953
1251.45	406.181
1252.56	415.282
1253.66	392.032
1254.76	389.116
1255.87	399.616
1256.97	394.475
1258.07	400.641
1259.17	418.173
1260.27	417.394
1261.37	432.576
1262.48	403.191
1263.58	386.468
1264.68	492.3
1265.78	421.801
1266.88	420.758
1267.98	401.287
1269.08	407.053
1270.18	380.862
1271.28	393.059
1272.38	396.235
1273.47	398.796
1274.57	394.977
1275.67	399.215
1276.77	376.417
1277.87	422.952
1278.97	401.248
1280.07	393.955
1281.16	397.112
1282.26	399.481
1283.36	411.921
1284.45	716.509
1285.55	922.075
1286.65	441.759
1287.75	389.994
1288.84	409.881
1289.94	405.904
1291.03	410.222
1292.13	400.69
1293.22	406.979
1294.32	413.796
1295.42	408.614
1296.51	385.16
1297.61	411.517
1298.7	422.893
1299.79	407.883
1300.89	391.106
1301.98	429.173
1303.08	371.183
1304.17	398.489
1305.26	393.162
1306.35	390.707
1307.45	403.282
1308.54	386.427
1309.63	381.262
1310.73	399.254
1311.82	411.973
1312.91	392.101
1314	403.581
1315.09	382.498
1316.18	383.744
1317.28	371.001
1318.37	393.294
1319.46	383.797
1320.55	395.416
1321.64	394.078
1322.73	402.153
1323.82	397.785
1324.91	390.419
1326	398.583
1327.09	410.546
1328.18	400.7
1329.27	392.732
1330.35	366.298
1331.44	384.956
1332.53	402.289
1333.62	396.495
1334.71	392.894
1335.79	410.396
1336.88	395.457
1337.97	400.533
1339.06	404.401
1340.14	398.095
1341.23	387.646
1342.32	393.773
1343.4	405.973
1344.49	397.561
1345.58	398.411
1346.66	382.19
1347.75	399.449
1348.83	389.876
1349.92	411.46
1351	383.036
1352.09	382.745
1353.17	387.138
1354.25	400.017
1355.34	400.122
1356.42	387.603
1357.51	383.251
1358.59	387.153
1359.67	402.431
1360.76	378.208
1361.84	388.44
1362.92	375.862
1364	368.728
1365.09	395.629
1366.17	381.83
1367.25	402.082
1368.33	424.799
1369.41	389.753
1370.5	413.413
1371.58	386.204
1372.66	385.637
1373.74	375.059
1374.82	385.235
1375.9	394.487
1376.98	380.911
1378.06	382.826
1379.14	350.444
1380.22	415.179
1381.3	392.721
1382.38	414.903
1383.46	380.447
1384.54	424.308
1385.61	429.831
1386.69	434.288
1387.77	1083.6
1388.85	754.091
1389.93	433.176
1391	419.187
1392.08	399.376
1393.16	406.224
1394.23	383.549
1395.31	393.753
1396.39	398.987
1397.46	381.384
1398.54	386.41
1399.62	386.566
1400.69	383.621
1401.77	378.671
1402.84	396.676
1403.92	384.72
1404.99	375.213
1406.07	400.596
1407.14	381
1408.22	408.786
1409.29	547.354
1410.37	431.557
1411.44	389.103
1412.51	389.025
1413.59	395.218
1414.66	378.328
1415.73	376.441
1416.81	383.744
1417.88	391.11
1418.95	399.397
1420.02	404.432
1421.1	390.762
1422.17	379.49
1423.24	390.563
1424.31	389.28
1425.38	371.857
1426.45	369.903
1427.52	383.882
1428.59	367.134
1429.67	389.767
1430.74	403.425
1431.81	389.565
1432.87	380.115
1433.95	367.258
1435.01	375.577
1436.08	386.842
1437.15	373.404
1438.22	378.423
1439.29	425.675
1440.36	400.351
1441.43	397.381
1442.49	376.826
1443.56	411.663
1444.63	416.702
1445.7	410.867
1446.77	412.782
1447.83	390.07
1448.9	388.134
1449.97	395.249
1451.03	403.257
1452.1	393.891
1453.17	389.771
1454.23	372.409
1455.3	393.897
1456.36	372.462
1457.43	402.02
1458.49	385.56
1459.56	374.352
1460.62	380.442
1461.69	359.791
1462.75	360.564
1463.82	389.891
1464.88	352.445
1465.94	382.033
1467.01	387.009
1468.07	404.283
1469.13	361.385
1470.2	366.246
1471.26	374.206
1472.32	383.166
1473.39	383.098
1474.45	374.768
1475.51	358.542
1476.57	343.15
1477.63	373.488
1478.69	366.23
1479.76	362.941
1480.82	384.877
1481.88	382.704
1482.94	375.862
1484	373.898
1485.06	356.913
1486.12	362.883
1487.18	372.039
1488.24	368.807
1489.3	377.612
1490.36	367.389
1491.42	376.29
1492.48	375.237
1493.53	370.133
1494.59	365.063
1495.65	350.763
1496.71	349.41
1497.77	364.448
1498.82	357.36
1499.88	350.371
1500.94	376.642
1502	369.426
1503.05	361.212
1504.11	377.16
1505.17	372.152
1506.22	374.839
1507.28	359.753
1508.34	355.72
1509.39	366.805
1510.45	365.849
1511.5	371.56
1512.56	374.857
1513.61	366.409
1514.67	356.591
1515.72	360.294
1516.78	369.99
1517.83	352.883
1518.88	372.069
1519.94	376.18
1520.99	377.131
1522.05	373.182
1523.1	368.004
1524.15	386.621
1525.2	374.434
1526.26	375.587
1527.31	355.733
1528.36	384.654
1529.41	351.454
1530.47	353.35
1531.52	359.588
1532.57	345.503
1533.62	379.962
1534.67	372.995
1535.72	370.813
1536.77	376.309
1537.82	366.9
1538.87	365.674
1539.92	369.211
1540.97	349.754
1542.02	364.564
1543.07	375.215
1544.12	358.785
1545.17	364.003
1546.22	351.328
1547.27	371.434
1548.32	379.25
1549.37	356.009
1550.42	356.127
1551.46	377.237
1552.51	364.191
1553.56	376.961
1554.61	358.634
1555.65	396.379
1556.7	379.312
1557.75	355.321
1558.79	346.021
1559.84	363.624
1560.89	389.419
1561.93	355.499
1562.98	355.682
1564.02	361.608
1565.07	390.91
1566.11	359.72
1567.16	377.186
1568.2	362.475
1569.25	379.552
1570.29	376.36
1571.34	352.359
1572.38	364.179
1573.43	367.944
1574.47	360.912
1575.51	377.239
1576.56	381.282
1577.6	350.885
1578.64	375.401
1579.69	378.359
1580.73	374.474
1581.77	384.268
1582.81	370.099
1583.85	378.985
1584.9	341.146
1585.94	378.971
1586.98	378.678
1588.02	367.585
1589.06	378.653
1590.1	357.881
1591.14	342.041
1592.18	362.873
1593.22	379.441
1594.26	361.01
1595.3	359.081
1596.34	340.08
1597.38	349.051
1598.42	391.778
1599.46	375.546
1600.5	370.326
1601.54	369.919
1602.58	358.655
1603.62	366.248
1604.66	385.935
1605.69	348.39
1606.73	351.51
1607.77	376.98
1608.81	359.246
1609.84	369.786
1610.88	359.738
1611.92	361.454
1612.95	362.558
1613.99	336.721
1615.03	363.156
1616.06	358.327
1617.1	362.597
1618.13	352.328
1619.17	356.04
1620.2	351.611
1621.24	350.938
1622.27	354.72
1623.31	364.943
1624.34	357.269
1625.38	355.948
1626.41	364.963
1627.45	350.231
1628.48	358.328
1629.51	362.216
1630.55	339.525
1631.53	371.668
1632.57	337.342
1633.62	350.115
1634.66	354.136
1635.71	361.983
1636.75	351.967
1637.8	360.619
1638.84	345.737
1639.89	363.447
1640.93	385.161
1641.98	345.772
1643.02	359.472
1644.06	340.705
1645.11	371.047
1646.15	344.582
1647.19	352.309
1648.24	376.771
1649.28	360.376
1650.32	388.903
1651.37	365.61
1652.41	345.966
1653.45	357.699
1654.49	390.29
1655.53	384.541
1656.57	358.292
1657.62	347.435
1658.66	374.93
1659.7	354.98
1660.74	367.735
1661.78	350.237
1662.82	356.559
1663.86	378.332
1664.9	344.5
1665.94	366.717
1666.98	352.374
1668.02	358.093
1669.06	349.276
1670.1	343.6
1671.14	348.795
1672.18	362.561
1673.21	355.675
1674.25	358.721
1675.29	360.902
1676.33	364.94
1677.37	362
1678.4	351.924
1679.44	348.716
1680.48	341.662
1681.52	359.319
1682.55	366.218
1683.59	360.26
1684.63	362.137
1685.66	348.235
1686.7	365.053
1687.73	346.368
1688.77	366.943
1689.81	351.873
1690.84	353.747
1691.88	335.122
1692.91	373.558
1693.95	337.69
1694.98	351.216
1696.01	357.173
1697.05	359.24
1698.08	347.125
1699.12	342.94
1700.15	355.71
1701.18	361.511
1702.22	344.602
1703.25	364.03
1704.28	352.14
1705.32	345.325
1706.35	368.817
1707.38	351.771
1708.41	350.386
1709.44	356.795
1710.48	357.686
1711.51	353.887
1712.54	360.757
1713.57	363.13
1714.6	345.153
1715.63	319.745
1716.66	348.059
1717.69	355.409
1718.72	345.072
1719.75	362.456
1720.78	371.192
1721.81	335.84
1722.84	367.565
1723.87	337.179
1724.9	358.42
1725.93	346.276
1726.96	353.89
1727.99	343.12
1729.02	336.623
1730.05	341.099
1731.07	365.019
1732.1	344.184
1733.13	331.471
1734.16	358.031
1735.18	326.733
1736.21	344.697
1737.24	345.488
1738.26	331.813
1739.29	348.806
1740.32	350.175
1741.34	346.882
1742.37	347.586
1743.4	348.426
1744.42	361.634
1745.45	334.767
1746.47	341.322
1747.5	346.674
1748.52	349.318
1749.55	332.206
1750.57	340.115
1751.6	353.641
1752.62	333.236
1753.64	317.672
1754.67	332.672
1755.69	341.061
1756.71	336.936
1757.74	355.594
1758.76	357.606
1759.78	340.505
1760.81	351.819
1761.83	344.923
1762.85	344.89
1763.87	349.679
1764.89	344.228
1765.92	341.521
1766.94	346.248
1767.96	341.375
1768.98	329.805
1770	344.384
1771.02	341.711
1772.04	338.186
1773.06	336.473
1774.08	359.46
1775.1	365.285
1776.12	359.917
1777.14	340.845
1778.16	336.808
1779.18	329.852
1780.2	328.836
1781.22	339.411
1782.24	339.504
1783.26	350.208
1784.28	346.571
1785.29	338.214
1786.31	323.809
1787.33	344.954
1788.35	362.821
1789.37	316.429
1790.38	397.223
1791.4	320.492
1792.42	326.935
1793.43	338.527
1794.45	367.339
1795.47	336.972
1796.48	338.307
1797.5	352.982
1798.51	346.424
1799.53	353.115
1800.55	344.22
1801.56	345.069
1802.58	337.447
1803.59	333.838
1804.61	328.212
1805.62	360.256
1806.64	360.54
1807.65	351.958
1808.66	338.478
1809.68	352.98
1810.69	346.271
1811.7	344.288
1812.72	331.801
1813.73	335.828
1814.74	334.2
1815.76	363.444
1816.77	338.385
1817.78	331.412
1818.79	324.695
1819.8	352.817
1820.82	337.502
1821.83	352.179
1822.84	349.418
1823.85	341.667
1824.86	354.259
1825.87	334.047
1826.88	340.84
1827.89	344.809
1828.9	335.102
1829.91	362.106
1830.92	358.083
1831.93	379.523
1832.94	362.3
1833.95	350.762
1834.96	374.737
1835.97	354.81
1836.98	345.437
1837.99	354.981
1839	341.397
1840	347.676
1841.01	329.573
1842.02	347.303
1843.03	352.782
1844.04	309.366
1845.04	336.378
1846.05	341.294
1847.06	345.486
1848.07	337.549
1849.07	329.903
1850.08	324.829
1851.09	333.069
1852.09	348.205
1853.1	342.415
1854.1	329.791
1855.11	361.078
1856.11	345.394
1857.12	332.882
1858.12	328.918
1859.13	360.209
1860.13	344.651
1861.14	348.617
1862.14	344.973
1863.15	351.432
1864.15	351.113
1865.15	326.015
1866.16	349.43
1867.16	321.222
1868.16	358.839
1869.17	336.923
1870.17	337.803
1871.17	332.986
1872.17	342.352
1873.18	328.841
1874.18	333.444
1875.18	346.403
1876.18	326
1877.18	322.806
1878.18	314.776
1879.19	347.458
1880.19	332.579
1881.19	343.892
1882.19	338.651
1883.19	332.268
1884.19	327.189
1885.19	337.721
1886.19	319.265
1887.19	331.486
1888.19	328.328
1889.19	325.051
1890.19	359.686
1891.19	326.936
1892.18	328.741
1893.18	328.586
1894.18	345.93
1895.18	325.094
1896.18	341.168
1897.18	334.803
1898.17	325.479
1899.17	338.442
1900.17	328.807
1901.16	339.123
1902.16	321.516
1903.16	325.392
1904.16	336.544
1905.15	318.617
1906.15	338.217
1907.14	314.493
1908.14	326.735
1909.14	328.749
1910.13	332.806
1911.13	336.973
1912.12	321.05
1913.12	319.106
1914.11	329.618
1915.11	333.706
1916.1	349.867
1917.1	327.994
1918.09	326.883
1919.08	330.865
1920.08	321.875
1921.07	328.542
1922.06	357.174
1923.06	324.968
1924.05	336.167
1925.04	336.941
1926.04	319.204
1927.03	337.542
1928.02	321.647
1929.01	317.04
1930	343.848
1931	347.06
1931.99	324.235
1932.98	324.042
1933.97	327.886
1934.96	318.361
1935.95	321.914
1936.94	331.127
1937.93	347.969
1938.92	328.904
1939.91	326.227
1940.9	338.84
1941.89	314.336
1942.88	356.468
1943.87	344.805
1944.86	350.775
1945.85	347.287
1946.84	344.646
1947.83	319.725
1948.82	334.977
1949.8	334.23
1950.79	324.153
1951.78	328.486
1952.77	327.788
1953.76	337.427
1954.74	343.414
1955.73	337.481
1956.72	319.814
1957.7	339.324
1958.69	331.801
1959.68	357.63
1960.66	326.711
1961.65	336.075
1962.63	336.077
1963.62	350.524
1964.61	336.226
1965.59	332.34
1966.58	331.553
1967.56	331.705
1968.55	345.217
1969.53	350.79
1970.52	334.078
1971.5	349.223
1972.48	324.272
1973.47	329.95
1974.45	324.943
1975.44	346.053
1976.42	332.799
1977.4	330.899
1978.39	346.066
1979.37	327.739
1980.35	351.727
1981.33	329.497
1982.31	339.906
1983.3	335.865
1984.28	339.453
1985.26	354.588
1986.24	322.924
1987.22	333.548
1988.21	331.387
1989.19	344.758
1990.17	330.36
1991.15	342.066
1992.13	324.519
1993.11	333.451
1994.09	334.117
1995.07	338.793
1996.05	341.428
1997.03	338.799
1998.01	330.399
1998.99	322.592
1999.97	340.068
2000.95	326.8
2001.92	333.967
2002.9	330.677
2003.88	329.917
2004.86	332.813
2005.84	339.582
2006.81	339.245
2007.79	322.328
2008.77	335.062
2009.75	325.855
2010.73	334.469
2011.7	325.482
2012.68	330.066
2013.67	317.458
2014.66	336.654
2015.64	324.305
2016.63	328.198
2017.62	334.991
2018.61	339.226
2019.6	307.789
2020.58	318.889
2021.57	327.322
2022.56	313.18
2023.55	320.365
2024.54	325.693
2025.52	337.39
2026.51	312.855
2027.5	328.639
2028.48	319.844
2029.47	325.027
2030.45	334.288
2031.44	314.836
2032.43	332.62
2033.41	345.194
2034.4	334.015
2035.38	314.83
2036.37	342.63
2037.35	321.953
2038.34	326.53
2039.32	329.123
2040.31	343.771
2041.29	329.438
2042.27	312.504
2043.26	320.753
2044.24	317.395
2045.23	346.103
2046.21	321.593
2047.19	334.355
2048.17	328.331
2049.16	320.02
2050.14	320.377
2051.12	325.29
2052.11	316.695
2053.09	325.204
2054.07	334.909
2055.05	313.502
2056.03	331.112
2057.01	313.242
2058	303.03
2058.98	311.684
2059.96	330.555
2060.94	316.392
2061.92	325.881
2062.9	321.272
2063.88	334.59
2064.86	339.406
2065.84	325.656
2066.82	327.735
2067.8	321.3
2068.78	323.329
2069.76	328.876
2070.73	326.962
2071.71	336.576
2072.69	337.05
2073.67	331.338
2074.65	332.359
2075.63	336.545
2076.6	313.314
2077.58	332.024
2078.56	324.393
2079.54	334.955
2080.51	331.512
2081.49	319.215
2082.47	330.549
2083.45	321.141
2084.42	340.959
2085.4	323.015
2086.37	325.009
2087.35	332.827
2088.32	349.955
2089.3	332.028
2090.28	336.042
2091.25	320.988
2092.23	321.233
2093.2	341.578
2094.18	342.855
2095.15	323.905
2096.13	317.065
2097.1	322.675
2098.07	340.507
2099.05	322.385
2100.02	332.772
2101	331.883
2101.97	322.591
2102.94	330.16
2103.92	331.885
2104.89	335.746
2105.86	326.474
2106.83	333.274
2107.8	319.029
2108.78	339.598
2109.75	320.6
2110.72	335.865
2111.69	327.284
2112.66	337.625
2113.63	353.016
2114.61	318.854
2115.58	336.904
2116.55	338.646
2117.52	336.613
2118.49	345.021
2119.46	317.169
2120.43	340.615
2121.4	334.056
2122.37	313.483
2123.34	324.106
2124.31	352.555
2125.28	321.752
2126.25	345.911
2127.21	316.273
2128.18	324.646
2129.15	355.781
2130.12	342.461
2131.09	329.131
2132.06	325.16
2133.02	331.566
2133.99	324.001
2134.96	325.902
2135.93	333.376
2136.89	350.028
2137.86	321.811
2138.83	336.77
2139.79	332.132
2140.76	315.833
2141.73	334.583
2142.69	338.169
2143.66	325.237
2144.62	333.048
2145.59	333.999
2146.55	309.491
2147.52	335.67
2148.48	318.596
2149.45	335.291
2150.42	319.892
2151.38	335.744
2152.34	316.21
2153.31	324.536
2154.27	328.11
2155.24	314.538
2156.2	304.768
2157.16	313.99
2158.13	341.212
2159.09	322.564
2160.05	311.16
2161.01	332.333
2161.98	310.75
2162.94	321.922
2163.9	324.572
2164.86	320.607
2165.83	325.257
2166.79	323.321
2167.75	318.422
2168.71	328.197
2169.67	330.174
2170.63	327.786
2171.59	319.313
2172.56	318.772
2173.51	314.006
2174.48	324.311
2175.44	321.527
2176.4	312.159
2177.36	311.129
2178.32	317.644
2179.28	325.805
2180.23	332.32
2181.19	331.331
2182.15	328.432
2183.11	313.46
2184.07	340.041
2185.03	326.955
2185.99	323.364
2186.95	326.406
2187.9	310.046
2188.86	331.262
2189.82	335.541
2190.78	320.559
2191.73	325.263
2192.69	330.936
2193.65	341.339
2194.6	313.022
2195.56	319.493
2196.52	334.022
2197.47	325.357
2198.43	325.35
2199.38	324.789
2200.34	351.297
2201.3	333.262
2202.25	317.292
2203.21	345.745
2204.16	322.718
2205.12	345.422
2206.07	325.994
2207.03	332.47
2207.98	318.715
2208.93	326.42
2209.89	343.285
2210.84	328.473
2211.8	329.615
2212.75	337.293
2213.7	330.619
2214.66	313.986
2215.61	331.925
2216.56	323.541
2217.51	326.301
2218.47	321.653
2219.42	330.207
2220.37	319.163
2221.32	322.832
2222.27	317.865
2223.23	346.826
2224.18	323.758
2225.13	329.716
2226.08	320.672
2227.03	311.555
2227.98	322.976
2228.93	314.458
2229.88	315.412
2230.83	327.889
2231.78	320.667
2232.73	329.381
2233.68	333.387
2234.63	317.515
2235.58	330.448
2236.53	336.984
2237.48	323.943
2238.43	319.685
2239.38	342.713
2240.33	324.646
2241.27	329.508
2242.22	341.866
2243.17	327.822
2244.12	325.803
2245.07	342.944
2246.01	323.507
2246.96	332.243
2247.91	331.447
2248.85	311.511
2249.8	323.819
2250.75	338.89
2251.69	317.827
2252.64	323.579
2253.59	346.78
2254.53	324.345
2255.48	323.431
2256.42	317.824
2257.37	331.332
2258.32	314.401
2259.26	329.71
2260.2	328.907
2261.15	316.696
2262.1	320.705
2263.04	316.113
2263.98	320.289
2264.93	337.926
2265.87	322.867
2266.81	320.798
2267.76	317.683
2268.7	326.069
2269.65	330.098
2270.59	344.843
2271.53	321.19
2272.47	343.375
2273.42	331.956
2274.36	355.954
2275.3	311.042
2276.24	339.843
2277.18	324.819
2278.13	340.608
2279.07	341.797
2280.01	311.793
2280.95	329.7
2281.89	314.21
2282.83	338.35
2283.77	332.02
2284.71	337.373
2285.65	336.632
2286.59	312.386
2287.54	307.916
2288.47	335.033
2289.41	333.806
2290.35	341.069
2291.29	337.247
2292.23	337.587
2293.17	349.428
2294.11	334.182
2295.05	321.477
2295.99	330.922
2296.93	337.383
2297.86	334.712
2298.8	334.081
2299.74	329.544
2300.68	346.928
2301.61	349.044
2302.55	312.357
2303.49	308.457
2304.43	328.813
2305.36	345.435
2306.3	326.238
2307.24	321.462
2308.17	326.187
2309.11	324.21
2310.04	323.532
2310.98	321.698
2311.92	326.023
2312.85	330.541
2313.79	313.257
2314.72	334.926
2315.66	341.905
2316.59	351.128
2317.52	327.811
2318.46	324.966
2319.39	330.551
2320.33	341.054
2321.26	345.97
2322.2	344.335
2323.13	321.352
2324.06	338.835
2325	318.43
2325.93	350.906
2326.86	342.889
2327.79	368.636
2328.73	422.526
2329.66	341.339
2330.59	334.567
2331.52	341.257
2332.46	326.9
2333.39	323.805
2334.32	322.686
2335.25	332.077
2336.18	308.036
2337.11	336.801
2338.04	313.653
2338.97	332.811
2339.91	335.7
2340.84	332.63
2341.77	331.263
2342.7	328.119
2343.63	345.31
2344.56	328.05
2345.49	340.452
2346.41	316.232
2347.34	323.803
2348.27	321.879
2349.2	325.739
2350.13	323.324
2351.06	333.195
2351.99	335.491
2352.91	337.838
2353.84	328.767
2354.77	330.68
2355.7	315.45
2356.63	322.838
2357.55	316.728
2358.48	327
2359.41	311.642
2360.33	325.701
2361.26	332.98
2362.19	314.634
2363.11	328.52
2364.04	323.598
2364.97	332.866