File: Data/3-Raman/raw/bu32-a-incc-fi04-v_1800 (450-850nm)_532nm_edge_100%_x100_vis_lwd_h30um_40sx2_01.txt
#Acq. time (s)=	40
#Accumulations=	2
#Range (cm-¹)=	1200...2365
#Windows=	3
#Auto scanning=	Off
#Autofocus=	Off
#Macrospot=	Off
#AutoExposure=	Off
#Spike filter=	Multiple accum.
#Delay time (s)=	2
#Binning=	1
#Readout mode=	Signal
#DeNoise=	Off
#ICS correction=	On
#Dark correction=	Off
#Inst. Process=	Off
#Detector Gain=	Best Dynamic
#Detector ADC=	50 kHz EM
#Detector EM gain=	400
#Detector temperature (°C)=	-60.09
#Instrument=	LabRAM HR Evol
#Detector=	SIN-EM FIVIS
#Objective=	x100_VIS_LWD
#Grating=	1800 (450-850nm)
#ND Filter=	100%
#Laser=	532nm_Edge
#Hole=	30.0125
#Temperature=	0
#Range=	Visible
#StageXY=	75x50mm Scan+
#StageZ=	Z motor
#X (µm)=	0
#Y (µm)=	0
#Z (µm)=	14.5
#Full time(mm:ss)=	4:22
#Project=	21_11_26
#Sample=	BU32
#Site=
#Title=	BU32-A-incC-FI04-V_1800 (450-850nm)_532nm_Edge_100%_x100_VIS_LWD_H30um_40sX2
#Remark=
#Date=	26.11.2021 18:22
#Acquired=	26.11.2021 18:22:23
1202.72	460.279
1203.84	495.967
1204.95	513.886
1206.06	484.147
1207.17	517.513
1208.28	511.612
1209.39	517.49
1210.5	501.214
1211.61	471.632
1212.72	473.117
1213.83	484.387
1214.94	482.194
1216.05	462.938
1217.16	507.969
1218.27	465.985
1219.38	481.604
1220.49	485.632
1221.6	458.954
1222.71	487.991
1223.81	520.904
1224.92	473.849
1226.03	480.206
1227.14	489.607
1228.25	471.644
1229.35	511.501
1230.46	486.538
1231.57	494.624
1232.67	501.974
1233.78	452.491
1234.89	461.066
1235.99	471.783
1237.1	449.598
1238.2	435.371
1239.31	487.279
1240.41	485.008
1241.52	454.652
1242.62	474.387
1243.73	435.745
1244.83	439.928
1245.94	465.7
1247.04	474.856
1248.14	456.946
1249.25	450.409
1250.35	482.816
1251.45	481.333
1252.56	455.919
1253.66	454.553
1254.76	495.523
1255.87	461.135
1256.97	484.207
1258.07	440.226
1259.17	461.911
1260.27	453.848
1261.37	450.209
1262.48	449.089
1263.58	472.909
1264.68	467.087
1265.78	469.764
1266.88	458.269
1267.98	492.184
1269.08	458.265
1270.18	495.97
1271.28	473.523
1272.38	494.498
1273.47	491.934
1274.57	468.275
1275.67	480.912
1276.77	451.876
1277.87	460.646
1278.97	483.144
1280.07	464.295
1281.16	460.088
1282.26	477.234
1283.36	489.638
1284.45	484.014
1285.55	435.351
1286.65	459.515
1287.75	493.006
1288.84	445.511
1289.94	469.985
1291.03	439.559
1292.13	448.979
1293.22	470.008
1294.32	454.757
1295.42	440.091
1296.51	451.578
1297.61	436.712
1298.7	438.567
1299.79	455.214
1300.89	424.723
1301.98	446.952
1303.08	426.992
1304.17	462.722
1305.26	445.773
1306.35	482.303
1307.45	450.56
1308.54	443.2
1309.63	451.766
1310.73	452.884
1311.82	462.443
1312.91	481.662
1314	461.444
1315.09	472.035
1316.18	443.751
1317.28	452.116
1318.37	422.67
1319.46	475.503
1320.55	442.75
1321.64	467.77
1322.73	423.038
1323.82	455.565
1324.91	485.105
1326	435.248
1327.09	468.189
1328.18	458.44
1329.27	477.97
1330.35	471.567
1331.44	443.757
1332.53	417.849
1333.62	435.158
1334.71	453.56
1335.79	451.078
1336.88	450.789
1337.97	434.88
1339.06	448.145
1340.14	456.496
1341.23	430.341
1342.32	469.949
1343.4	471.621
1344.49	449.605
1345.58	449.383
1346.66	480.064
1347.75	464.881
1348.83	470.909
1349.92	471.604
1351	452.497
1352.09	475.028
1353.17	451.384
1354.25	450.785
1355.34	471.553
1356.42	448.635
1357.51	454.636
1358.59	457.452
1359.67	463.344
1360.76	462.893
1361.84	449.272
1362.92	422.173
1364	446.126
1365.09	478.199
1366.17	450.875
1367.25	416.264
1368.33	464.819
1369.41	459.766
1370.5	450.328
1371.58	443.742
1372.66	450.308
1373.74	422.165
1374.82	448.807
1375.9	462.176
1376.98	442.388
1378.06	530.746
1379.14	461.484
1380.22	496.275
1381.3	496.272
1382.38	473.143
1383.46	458.091
1384.54	475.25
1385.61	478.766
1386.69	483.262
1387.77	477.881
1388.85	496.533
1389.93	441.061
1391	469.098
1392.08	456.417
1393.16	435.577
1394.23	432.332
1395.31	448.672
1396.39	434.472
1397.46	432.196
1398.54	433.117
1399.62	459.896
1400.69	445.715
1401.77	416.213
1402.84	436.324
1403.92	430.564
1404.99	411.789
1406.07	418.692
1407.14	441.113
1408.22	415.6
1409.29	392.126
1410.37	444.525
1411.44	427.677
1412.51	430.664
1413.59	443.134
1414.66	459.024
1415.73	424.318
1416.81	413.149
1417.88	432.856
1418.95	430.873
1420.02	434.87
1421.1	436.574
1422.17	440.703
1423.24	430.297
1424.31	448.366
1425.38	434.02
1426.45	448.495
1427.52	407.055
1428.59	453.763
1429.67	415.993
1430.74	455.299
1431.81	401.476
1432.87	435.101
1433.95	413.967
1435.01	450.992
1436.08	437.663
1437.15	440.597
1438.22	443.55
1439.29	469.308
1440.36	462.469
1441.43	443.106
1442.49	436.9
1443.56	416.363
1444.63	440.877
1445.7	444.294
1446.77	429.785
1447.83	410.141
1448.9	449.234
1449.97	463.516
1451.03	415.116
1452.1	445.704
1453.17	416.991
1454.23	432.424
1455.3	460.055
1456.36	415.059
1457.43	414.887
1458.49	437.349
1459.56	417.953
1460.62	415.839
1461.69	421.795
1462.75	416.384
1463.82	402.718
1464.88	428.745
1465.94	414.224
1467.01	391.641
1468.07	411.973
1469.13	437.41
1470.2	422.854
1471.26	440.971
1472.32	411.199
1473.39	419.27
1474.45	426.185
1475.51	405.895
1476.57	423.045
1477.63	434.019
1478.69	435.887
1479.76	424.423
1480.82	412.8
1481.88	381.193
1482.94	429.173
1484	426.202
1485.06	413.162
1486.12	406.956
1487.18	411.049
1488.24	401.719
1489.3	408.472
1490.36	427.577
1491.42	420.267
1492.48	410.108
1493.53	416.118
1494.59	419.132
1495.65	399.756
1496.71	437.727
1497.77	428.516
1498.82	408.303
1499.88	432.618
1500.94	390.245
1502	397.149
1503.05	386.905
1504.11	397.798
1505.17	420.017
1506.22	416.614
1507.28	414.629
1508.34	418.656
1509.39	428.733
1510.45	392.512
1511.5	427.397
1512.56	404.454
1513.61	416.05
1514.67	414.298
1515.72	416.946
1516.78	398.511
1517.83	413.482
1518.88	404.605
1519.94	436.815
1520.99	421.706
1522.05	426.794
1523.1	420.589
1524.15	409.09
1525.2	394.888
1526.26	410.074
1527.31	415.296
1528.36	442.189
1529.41	414.976
1530.47	394.823
1531.52	392.067
1532.57	409.034
1533.62	404.444
1534.67	404.501
1535.72	424.361
1536.77	414.762
1537.82	436.318
1538.87	419.053
1539.92	391.634
1540.97	395.276
1542.02	417.07
1543.07	440.682
1544.12	447.177
1545.17	398.414
1546.22	393.783
1547.27	403.878
1548.32	424.693
1549.37	436.451
1550.42	416.573
1551.46	411.753
1552.51	395.694
1553.56	418.473
1554.61	431.194
1555.65	415.781
1556.7	396.708
1557.75	395.759
1558.79	390.429
1559.84	428.977
1560.89	436.749
1561.93	449.815
1562.98	439.046
1564.02	431.955
1565.07	407.273
1566.11	394.881
1567.16	412.492
1568.2	440.792
1569.25	422.89
1570.29	433.666
1571.34	395.67
1572.38	396.48
1573.43	417.195
1574.47	430.119
1575.51	445.512
1576.56	394.602
1577.6	391.136
1578.64	394.667
1579.69	392.637
1580.73	413.685
1581.77	408.508
1582.81	420.225
1583.85	425.115
1584.9	408.194
1585.94	405.177
1586.98	406.852
1588.02	378.832
1589.06	425.732
1590.1	403.98
1591.14	410.062
1592.18	404.989
1593.22	410.573
1594.26	419.909
1595.3	433.887
1596.34	408.899
1597.38	408.936
1598.42	435.769
1599.46	412.548
1600.5	385.481
1601.54	448.465
1602.58	400.497
1603.62	428.821
1604.66	396.089
1605.69	395.129
1606.73	406.183
1607.77	405.357
1608.81	386.416
1609.84	423.905
1610.88	411.473
1611.92	426.87
1612.95	426.847
1613.99	417.546
1615.03	399.303
1616.06	415.583
1617.1	411.891
1618.13	423.585
1619.17	428.147
1620.2	398.113
1621.24	400.102
1622.27	415.133
1623.31	405.736
1624.34	409.199
1625.38	398.981
1626.41	415.142
1627.45	413.916
1628.48	413.528
1629.51	407.08
1630.55	402.245
1631.53	406.822
1632.57	435.59
1633.62	405.99
1634.66	430.731
1635.71	428.724
1636.75	423.612
1637.8	414.507
1638.84	398.631
1639.89	424.224
1640.93	418.39
1641.98	400.668
1643.02	422.238
1644.06	437.916
1645.11	419.034
1646.15	419.162
1647.19	406.209
1648.24	409.026
1649.28	366.091
1650.32	457.621
1651.37	432.43
1652.41	397.039
1653.45	400.886
1654.49	421.669
1655.53	429.743
1656.57	399.602
1657.62	388.754
1658.66	399.467
1659.7	398.246
1660.74	404.1
1661.78	397.49
1662.82	392.02
1663.86	399.973
1664.9	387.855
1665.94	402.133
1666.98	432.274
1668.02	423.155
1669.06	416.333
1670.1	397.874
1671.14	399.163
1672.18	419.847
1673.21	410.009
1674.25	435.818
1675.29	418.265
1676.33	403.522
1677.37	452.059
1678.4	422.161
1679.44	406.063
1680.48	399.983
1681.52	401.82
1682.55	418.606
1683.59	392.894
1684.63	395.758
1685.66	386.794
1686.7	401.647
1687.73	382.979
1688.77	403.545
1689.81	404.244
1690.84	406.112
1691.88	389.488
1692.91	411.151
1693.95	409.755
1694.98	413.382
1696.01	394.727
1697.05	410.609
1698.08	408.307
1699.12	396.214
1700.15	380.454
1701.18	389.207
1702.22	408.671
1703.25	400.552
1704.28	381.783
1705.32	399.547
1706.35	411.245
1707.38	411.833
1708.41	390.779
1709.44	400.083
1710.48	361.814
1711.51	388.381
1712.54	390.364
1713.57	384.875
1714.6	387.397
1715.63	412.793
1716.66	369.802
1717.69	399.571
1718.72	370.662
1719.75	403.621
1720.78	389.97
1721.81	381.846
1722.84	408.674
1723.87	392.829
1724.9	398.528
1725.93	378.58
1726.96	379.406
1727.99	386.073
1729.02	385.298
1730.05	387.801
1731.07	381.776
1732.1	392.861
1733.13	386.897
1734.16	373.835
1735.18	390.701
1736.21	378.769
1737.24	374.741
1738.26	375.48
1739.29	392.442
1740.32	391.832
1741.34	381.791
1742.37	386.308
1743.4	368
1744.42	354.416
1745.45	397.383
1746.47	389.58
1747.5	394.887
1748.52	386.055
1749.55	381.371
1750.57	367.349
1751.6	359.861
1752.62	374.797
1753.64	355.388
1754.67	377.041
1755.69	381.601
1756.71	386.969
1757.74	368.484
1758.76	371.459
1759.78	371.495
1760.81	365.684
1761.83	366.392
1762.85	397.738
1763.87	403.491
1764.89	366.687
1765.92	363.046
1766.94	394.433
1767.96	387.649
1768.98	370.359
1770	382.972
1771.02	369.877
1772.04	373.989
1773.06	377.061
1774.08	393.41
1775.1	368.782
1776.12	349.127
1777.14	392.018
1778.16	375.572
1779.18	377.158
1780.2	388.512
1781.22	362.94
1782.24	377.331
1783.26	356.622
1784.28	374.923
1785.29	411.436
1786.31	374.127
1787.33	368.582
1788.35	382.675
1789.37	359.302
1790.38	374.961
1791.4	372.997
1792.42	398.561
1793.43	380.485
1794.45	384.399
1795.47	361.726
1796.48	360.216
1797.5	378.759
1798.51	403.95
1799.53	363.534
1800.55	372.894
1801.56	374.702
1802.58	365.172
1803.59	376.011
1804.61	358.869
1805.62	367.841
1806.64	351.757
1807.65	374.984
1808.66	379.826
1809.68	387.594
1810.69	378.968
1811.7	355.779
1812.72	372.227
1813.73	365.671
1814.74	376.63
1815.76	374.022
1816.77	371.205
1817.78	369.05
1818.79	364.28
1819.8	370.189
1820.82	371.329
1821.83	387.965
1822.84	370.707
1823.85	347.476
1824.86	397.828
1825.87	369.892
1826.88	389.285
1827.89	370.024
1828.9	383.575
1829.91	353.431
1830.92	387.174
1831.93	388.294
1832.94	401.125
1833.95	379.911
1834.96	374.812
1835.97	389.715
1836.98	382.416
1837.99	381.207
1839	373.435
1840	386.549
1841.01	402.231
1842.02	387.978
1843.03	361.597
1844.04	369.312
1845.04	362.571
1846.05	364.606
1847.06	360.134
1848.07	383.924
1849.07	379.182
1850.08	344.254
1851.09	360.165
1852.09	362.808
1853.1	348.382
1854.1	347.281
1855.11	386.229
1856.11	372.445
1857.12	371.43
1858.12	354.055
1859.13	368.113
1860.13	381.237
1861.14	358.445
1862.14	360.555
1863.15	357.448
1864.15	391.53
1865.15	375.004
1866.16	353.546
1867.16	358.659
1868.16	355.353
1869.17	359.114
1870.17	355.244
1871.17	373.241
1872.17	354.098
1873.18	362.426
1874.18	363.226
1875.18	388.493
1876.18	349.1
1877.18	374.265
1878.18	365.226
1879.19	365.83
1880.19	357.6
1881.19	329.154
1882.19	342.85
1883.19	373.26
1884.19	359.665
1885.19	379.649
1886.19	346.147
1887.19	363.092
1888.19	366.513
1889.19	341.531
1890.19	374.282
1891.19	338.722
1892.18	349.007
1893.18	351.674
1894.18	360.534
1895.18	350.033
1896.18	356.723
1897.18	361.66
1898.17	349.527
1899.17	353.083
1900.17	350.022
1901.16	343.435
1902.16	366.266
1903.16	351.355
1904.16	369.086
1905.15	343.64
1906.15	363.238
1907.14	362.982
1908.14	332.033
1909.14	366.944
1910.13	357.874
1911.13	347.009
1912.12	367.833
1913.12	348.936
1914.11	367.007
1915.11	353.217
1916.1	364.673
1917.1	352.232
1918.09	356.774
1919.08	349.461
1920.08	368.843
1921.07	352.849
1922.06	372.996
1923.06	376.725
1924.05	368.063
1925.04	359.382
1926.04	351.121
1927.03	377.072
1928.02	362.156
1929.01	359.468
1930	361.66
1931	371.542
1931.99	358.214
1932.98	365.601
1933.97	366.612
1934.96	352.443
1935.95	357.982
1936.94	366.217
1937.93	359.235
1938.92	363.026
1939.91	373.711
1940.9	371.111
1941.89	370.497
1942.88	367.793
1943.87	348.5
1944.86	381.211
1945.85	355.777
1946.84	370.362
1947.83	357.876
1948.82	354.008
1949.8	368.588
1950.79	361.438
1951.78	353.358
1952.77	363.251
1953.76	359.453
1954.74	365.405
1955.73	385.337
1956.72	353.36
1957.7	383.474
1958.69	370.214
1959.68	368.173
1960.66	383.355
1961.65	367.736
1962.63	346.631
1963.62	344.767
1964.61	376.566
1965.59	358.281
1966.58	369.042
1967.56	349.995
1968.55	380.823
1969.53	356.597
1970.52	345.647
1971.5	338.73
1972.48	345.443
1973.47	368.388
1974.45	367.199
1975.44	360.52
1976.42	378.931
1977.4	369.368
1978.39	359.596
1979.37	367.152
1980.35	352.807
1981.33	341.123
1982.31	374.522
1983.3	362.811
1984.28	357.78
1985.26	357.617
1986.24	338.385
1987.22	359.54
1988.21	384.123
1989.19	347.871
1990.17	360.042
1991.15	358.455
1992.13	366.787
1993.11	363.367
1994.09	361.219
1995.07	351.428
1996.05	344.663
1997.03	354.18
1998.01	354.311
1998.99	357.08
1999.97	338.446
2000.95	340.937
2001.92	354.665
2002.9	338.734
2003.88	341.922
2004.86	353.115
2005.84	344.094
2006.81	372.652
2007.79	362.313
2008.77	360.93
2009.75	344.669
2010.73	362.239
2011.7	363.981
2012.68	334.792
2013.67	352.278
2014.66	364.844
2015.64	362.811
2016.63	362.029
2017.62	386.702
2018.61	341.133
2019.6	350.923
2020.58	330.161
2021.57	341.408
2022.56	353.482
2023.55	334.437
2024.54	368.731
2025.52	356.101
2026.51	362.332
2027.5	338.04
2028.48	337.643
2029.47	355.021
2030.45	369.787
2031.44	350.354
2032.43	342.013
2033.41	342.454
2034.4	335.016
2035.38	333.563
2036.37	343.637
2037.35	346.338
2038.34	349.041
2039.32	349.754
2040.31	364.386
2041.29	349.102
2042.27	352.667
2043.26	331.087
2044.24	334.275
2045.23	381.62
2046.21	369.335
2047.19	355.92
2048.17	340.548
2049.16	362.081
2050.14	335.418
2051.12	344.083
2052.11	347.618
2053.09	346.801
2054.07	382.716
2055.05	347.297
2056.03	352.738
2057.01	342.342
2058	359.253
2058.98	365.15
2059.96	356.901
2060.94	355.833
2061.92	347.553
2062.9	353.253
2063.88	379.714
2064.86	357.365
2065.84	332.375
2066.82	349.486
2067.8	327.093
2068.78	353.566
2069.76	360.048
2070.73	338.401
2071.71	341.444
2072.69	349.462
2073.67	355.048
2074.65	369.262
2075.63	356.526
2076.6	371.082
2077.58	357.684
2078.56	331.184
2079.54	335.145
2080.51	348.713
2081.49	348.702
2082.47	374.212
2083.45	341.188
2084.42	342.108
2085.4	338.342
2086.37	369.649
2087.35	367.1
2088.32	353.01
2089.3	350.231
2090.28	346.684
2091.25	365.749
2092.23	366.032
2093.2	360.801
2094.18	342.139
2095.15	348.861
2096.13	359.112
2097.1	380.862
2098.07	354.042
2099.05	355.85
2100.02	343.459
2101	359.661
2101.97	366.537
2102.94	365.557
2103.92	334.042
2104.89	364.492
2105.86	348.592
2106.83	362.06
2107.8	350.672
2108.78	340.82
2109.75	334.171
2110.72	341.842
2111.69	345.612
2112.66	367.345
2113.63	345.699
2114.61	360.007
2115.58	369.506
2116.55	364.587
2117.52	334.059
2118.49	348.165
2119.46	351.605
2120.43	374.08
2121.4	347.628
2122.37	361.223
2123.34	350.045
2124.31	343.374
2125.28	359.035
2126.25	350.958
2127.21	345.908
2128.18	345.763
2129.15	365.554
2130.12	328.608
2131.09	349.296
2132.06	347.204
2133.02	344.162
2133.99	359.248
2134.96	335.673
2135.93	358.244
2136.89	336.225
2137.86	348.552
2138.83	356.906
2139.79	334.363
2140.76	341.615
2141.73	354.709
2142.69	363.935
2143.66	362.331
2144.62	335.283
2145.59	325.895
2146.55	354.034
2147.52	358.585
2148.48	357.469
2149.45	367.572
2150.42	348.387
2151.38	331.426
2152.34	354.097
2153.31	344.599
2154.27	373.466
2155.24	325.209
2156.2	350.936
2157.16	366.683
2158.13	357.483
2159.09	369.685
2160.05	347.047
2161.01	328.057
2161.98	335.4
2162.94	353.103
2163.9	342.687
2164.86	343.371
2165.83	352.682
2166.79	344.222
2167.75	345.826
2168.71	336.042
2169.67	329.654
2170.63	349.618
2171.59	350.451
2172.56	348.93
2173.51	353.447
2174.48	327.521
2175.44	335.893
2176.4	342.32
2177.36	377.511
2178.32	334.798
2179.28	364.304
2180.23	336.47
2181.19	352.193
2182.15	363.212
2183.11	351.011
2184.07	370.145
2185.03	361.685
2185.99	373.869
2186.95	331.497
2187.9	357.868
2188.86	340.076
2189.82	341.565
2190.78	359.028
2191.73	359.108
2192.69	357.375
2193.65	359.444
2194.6	340.453
2195.56	344.136
2196.52	341.929
2197.47	361.088
2198.43	338.82
2199.38	341.993
2200.34	379.69
2201.3	356.118
2202.25	379.075
2203.21	347.173
2204.16	364.302
2205.12	349.655
2206.07	373.914
2207.03	350.64
2207.98	367.597
2208.93	354.864
2209.89	344.733
2210.84	358.803
2211.8	348.782
2212.75	352.744
2213.7	368.446
2214.66	370.494
2215.61	351.131
2216.56	350.22
2217.51	352.98
2218.47	359.541
2219.42	335.422
2220.37	339.338
2221.32	345.809
2222.27	360.429
2223.23	343.646
2224.18	357.958
2225.13	348.052
2226.08	360.568
2227.03	339.303
2227.98	372.311
2228.93	349.721
2229.88	354.431
2230.83	365.069
2231.78	348.491
2232.73	358.171
2233.68	346.208
2234.63	335.05
2235.58	336.685
2236.53	347.926
2237.48	358.413
2238.43	347.612
2239.38	331.999
2240.33	345.058
2241.27	357.479
2242.22	347.199
2243.17	373.755
2244.12	336.803
2245.07	337.902
2246.01	337.368
2246.96	340.441
2247.91	358.58
2248.85	336.75
2249.8	335.813
2250.75	350.884
2251.69	360.069
2252.64	345.029
2253.59	346.48
2254.53	344.905
2255.48	358.219
2256.42	345.985
2257.37	351.924
2258.32	346.401
2259.26	355.075
2260.2	347.634
2261.15	347.796
2262.1	349.925
2263.04	354.872
2263.98	361.957
2264.93	343.384
2265.87	340.75
2266.81	346.313
2267.76	341.273
2268.7	358.229
2269.65	327.934
2270.59	335.991
2271.53	329.544
2272.47	356.519
2273.42	334.58
2274.36	347.097
2275.3	356.752
2276.24	362.586
2277.18	340.877
2278.13	340.374
2279.07	359.815
2280.01	352.834
2280.95	354.404
2281.89	354.24
2282.83	356.349
2283.77	330.841
2284.71	355.429
2285.65	347.004
2286.59	341.99
2287.54	346.223
2288.47	338.68
2289.41	342.265
2290.35	325.485
2291.29	350.51
2292.23	331.616
2293.17	393.548
2294.11	361.942
2295.05	350.188
2295.99	346.141
2296.93	355.479
2297.86	354.747
2298.8	338.72
2299.74	350.588
2300.68	350.613
2301.61	368.177
2302.55	350.795
2303.49	341.104
2304.43	341.2
2305.36	345.274
2306.3	355.071
2307.24	366.734
2308.17	347.291
2309.11	354.01
2310.04	356.264
2310.98	350.574
2311.92	345.197
2312.85	362.246
2313.79	330.494
2314.72	375.386
2315.66	334.034
2316.59	339.405
2317.52	332.511
2318.46	334.498
2319.39	326.566
2320.33	355.407
2321.26	359.365
2322.2	335.525
2323.13	363.773
2324.06	344.526
2325	336.688
2325.93	341.144
2326.86	380.414
2327.79	356.966
2328.73	353.029
2329.66	345.096
2330.59	357.59
2331.52	352.723
2332.46	363.42
2333.39	353.566
2334.32	342.812
2335.25	343.537
2336.18	336.81
2337.11	342.494
2338.04	359.723
2338.97	344.274
2339.91	362.545
2340.84	354.659
2341.77	335.997
2342.7	337.646
2343.63	334.707
2344.56	346.208
2345.49	363.402
2346.41	324.801
2347.34	359.181
2348.27	347.686
2349.2	348.679
2350.13	339.538
2351.06	350.286
2351.99	339.277
2352.91	329.219
2353.84	347.789
2354.77	332.557
2355.7	340.196
2356.63	337.096
2357.55	343.333
2358.48	345.989
2359.41	323.026
2360.33	346.576
2361.26	322.535
2362.19	346.844
2363.11	346.502
2364.04	338.734
2364.97	327.192