File: Data/3-Raman/raw/bu32-a-incc-fi05-v_1800 (450-850nm)_532nm_edge_100%_x100_vis_lwd_h30um_40sx2_01.txt
#Acq. time (s)=	40
#Accumulations=	2
#Range (cm-¹)=	1200...2365
#Windows=	3
#Auto scanning=	Off
#Autofocus=	Off
#Macrospot=	Off
#AutoExposure=	Off
#Spike filter=	Multiple accum.
#Delay time (s)=	2
#Binning=	1
#Readout mode=	Signal
#DeNoise=	Off
#ICS correction=	On
#Dark correction=	Off
#Inst. Process=	Off
#Detector Gain=	Best Dynamic
#Detector ADC=	50 kHz EM
#Detector EM gain=	400
#Detector temperature (°C)=	-60.09
#Instrument=	LabRAM HR Evol
#Detector=	SIN-EM FIVIS
#Objective=	x100_VIS_LWD
#Grating=	1800 (450-850nm)
#ND Filter=	100%
#Laser=	532nm_Edge
#Hole=	30.0125
#Temperature=	0
#Range=	Visible
#StageXY=	75x50mm Scan+
#StageZ=	Z motor
#X (µm)=	0
#Y (µm)=	0
#Z (µm)=	14.6
#Full time(mm:ss)=	4:22
#Project=	21_11_26
#Sample=	BU32
#Site=
#Title=	BU32-A-incC-FI05-V_1800 (450-850nm)_532nm_Edge_100%_x100_VIS_LWD_H30um_40sX2
#Remark=
#Date=	26.11.2021 18:16
#Acquired=	26.11.2021 18:16:44
1202.72	510.824
1203.84	551.897
1204.95	542.883
1206.06	552.807
1207.17	539.953
1208.28	535.083
1209.39	561.237
1210.5	566.303
1211.61	522.733
1212.72	561.434
1213.83	531.082
1214.94	554.419
1216.05	508.523
1217.16	558.787
1218.27	522.04
1219.38	559.891
1220.49	512.959
1221.6	524.427
1222.71	534.302
1223.81	535.405
1224.92	556.941
1226.03	507.329
1227.14	486.097
1228.25	514.468
1229.35	515.329
1230.46	543.042
1231.57	504.724
1232.67	528.869
1233.78	508.778
1234.89	513.156
1235.99	512.317
1237.1	502.721
1238.2	559.795
1239.31	540.24
1240.41	520.116
1241.52	518.053
1242.62	529.365
1243.73	526.366
1244.83	531.582
1245.94	570.869
1247.04	538.082
1248.14	503.398
1249.25	501.003
1250.35	534.44
1251.45	513.04
1252.56	521.002
1253.66	539.402
1254.76	497.922
1255.87	537.661
1256.97	489.709
1258.07	518.808
1259.17	512.257
1260.27	474.969
1261.37	522.409
1262.48	524.57
1263.58	523.144
1264.68	578.141
1265.78	488.73
1266.88	492.896
1267.98	518.461
1269.08	474.088
1270.18	499.208
1271.28	479.88
1272.38	542.707
1273.47	504.558
1274.57	538.586
1275.67	471.489
1276.77	527.468
1277.87	547.843
1278.97	498.893
1280.07	498.966
1281.16	507.366
1282.26	531.898
1283.36	530.583
1284.45	630.05
1285.55	932.344
1286.65	540.469
1287.75	523.384
1288.84	520.065
1289.94	514.031
1291.03	524.681
1292.13	508.799
1293.22	536.127
1294.32	504.073
1295.42	493.622
1296.51	507.323
1297.61	499.829
1298.7	494.24
1299.79	484.451
1300.89	487.742
1301.98	485.676
1303.08	455.148
1304.17	484.516
1305.26	487.61
1306.35	487.165
1307.45	480.718
1308.54	470.18
1309.63	504.062
1310.73	532.609
1311.82	488.338
1312.91	510.723
1314	503.146
1315.09	507.392
1316.18	546.71
1317.28	492.735
1318.37	472.794
1319.46	473.848
1320.55	504.467
1321.64	496.7
1322.73	470.91
1323.82	532.927
1324.91	460.174
1326	506.209
1327.09	461.165
1328.18	469.306
1329.27	462.459
1330.35	522.503
1331.44	511.498
1332.53	460.213
1333.62	504.778
1334.71	457.987
1335.79	491.153
1336.88	507.598
1337.97	485.362
1339.06	475.531
1340.14	513.187
1341.23	478.642
1342.32	477.388
1343.4	468.577
1344.49	501.976
1345.58	512.166
1346.66	467.58
1347.75	511.825
1348.83	518.857
1349.92	511.169
1351	461.836
1352.09	509.3
1353.17	488.784
1354.25	487.167
1355.34	454.836
1356.42	511.907
1357.51	507.475
1358.59	463.538
1359.67	469.409
1360.76	467.898
1361.84	464.617
1362.92	488.232
1364	457.296
1365.09	483.139
1366.17	488.906
1367.25	448.034
1368.33	475.899
1369.41	494.614
1370.5	462.411
1371.58	474.386
1372.66	475.733
1373.74	497.022
1374.82	457.689
1375.9	481.344
1376.98	468.739
1378.06	487.074
1379.14	532.173
1380.22	460.77
1381.3	466.99
1382.38	434.626
1383.46	480.135
1384.54	513.668
1385.61	503.867
1386.69	545.344
1387.77	987.421
1388.85	702.942
1389.93	500.006
1391	526.909
1392.08	479.329
1393.16	486.095
1394.23	476.674
1395.31	502.206
1396.39	470.606
1397.46	491.826
1398.54	496.81
1399.62	489.832
1400.69	504.309
1401.77	486.085
1402.84	453.981
1403.92	515.982
1404.99	466.353
1406.07	490.633
1407.14	496.618
1408.22	525.446
1409.29	584.035
1410.37	511.315
1411.44	515.902
1412.51	469.676
1413.59	456.559
1414.66	485.755
1415.73	492.115
1416.81	461.439
1417.88	492.457
1418.95	507.94
1420.02	494.437
1421.1	498.13
1422.17	482.74
1423.24	479.614
1424.31	474.936
1425.38	473.908
1426.45	483.25
1427.52	466.353
1428.59	495.581
1429.67	489.559
1430.74	499.189
1431.81	480.307
1432.87	474.891
1433.95	488.505
1435.01	480.456
1436.08	480.432
1437.15	473.093
1438.22	485.238
1439.29	492.556
1440.36	500.075
1441.43	498.141
1442.49	472.431
1443.56	469.307
1444.63	498.921
1445.7	498.266
1446.77	466.288
1447.83	497.879
1448.9	504.165
1449.97	487.659
1451.03	508.929
1452.1	484.139
1453.17	497.416
1454.23	484.154
1455.3	518.939
1456.36	459.594
1457.43	467.583
1458.49	522.802
1459.56	493.16
1460.62	494.094
1461.69	442.655
1462.75	458.702
1463.82	478.719
1464.88	484.347
1465.94	478.825
1467.01	468.449
1468.07	449.988
1469.13	438.685
1470.2	460.806
1471.26	444.247
1472.32	496.937
1473.39	475.452
1474.45	429.406
1475.51	438.618
1476.57	469.985
1477.63	495.157
1478.69	489.869
1479.76	506.801
1480.82	462.594
1481.88	444.141
1482.94	447.481
1484	456.685
1485.06	455.719
1486.12	492.036
1487.18	509.296
1488.24	468.504
1489.3	500.484
1490.36	450.755
1491.42	445.437
1492.48	453.459
1493.53	421.032
1494.59	444.249
1495.65	468.297
1496.71	496.088
1497.77	453.538
1498.82	465.604
1499.88	448.53
1500.94	485.897
1502	486.692
1503.05	449.161
1504.11	458.997
1505.17	499.359
1506.22	458.589
1507.28	467.676
1508.34	474.711
1509.39	451.521
1510.45	458.625
1511.5	456.176
1512.56	447.224
1513.61	443.694
1514.67	480.12
1515.72	489.718
1516.78	450.139
1517.83	476.116
1518.88	421.11
1519.94	462.34
1520.99	464.266
1522.05	466.337
1523.1	456.086
1524.15	471.577
1525.2	431.294
1526.26	503.587
1527.31	502.831
1528.36	430.476
1529.41	505.418
1530.47	510.257
1531.52	438.425
1532.57	483.421
1533.62	421.731
1534.67	470.928
1535.72	470.687
1536.77	425.959
1537.82	454.484
1538.87	462.18
1539.92	441.823
1540.97	462.586
1542.02	420.184
1543.07	501.841
1544.12	464.245
1545.17	462.51
1546.22	463.939
1547.27	477.041
1548.32	462.754
1549.37	497.49
1550.42	448.587
1551.46	470.966
1552.51	505.096
1553.56	456.541
1554.61	469.216
1555.65	465.771
1556.7	459.698
1557.75	444.72
1558.79	454.346
1559.84	496.8
1560.89	452.552
1561.93	439.619
1562.98	448.833
1564.02	502.719
1565.07	505.1
1566.11	481.139
1567.16	436.183
1568.2	476.484
1569.25	453.577
1570.29	459.323
1571.34	471.278
1572.38	466.043
1573.43	456.747
1574.47	441.702
1575.51	436.114
1576.56	466.13
1577.6	461.561
1578.64	442.059
1579.69	453.967
1580.73	473.025
1581.77	426.935
1582.81	479.469
1583.85	453.454
1584.9	486.323
1585.94	445.436
1586.98	444.076
1588.02	451.842
1589.06	462.924
1590.1	483.984
1591.14	443.267
1592.18	469.037
1593.22	452.656
1594.26	438.067
1595.3	451.04
1596.34	455.825
1597.38	460.819
1598.42	467.772
1599.46	470.308
1600.5	446.158
1601.54	477.35
1602.58	447.149
1603.62	447.721
1604.66	481.214
1605.69	449.593
1606.73	447.798
1607.77	472.683
1608.81	476.533
1609.84	469.876
1610.88	445.598
1611.92	430.768
1612.95	457.625
1613.99	439.309
1615.03	441.238
1616.06	431.841
1617.1	447.458
1618.13	432.088
1619.17	456.254
1620.2	452.997
1621.24	438.736
1622.27	447.996
1623.31	439.673
1624.34	462.507
1625.38	446.459
1626.41	450.756
1627.45	456.367
1628.48	437.291
1629.51	433.94
1630.55	419.309
1631.53	460.859
1632.57	429.507
1633.62	469.84
1634.66	458.097
1635.71	458.028
1636.75	449.919
1637.8	433.879
1638.84	433.718
1639.89	410.063
1640.93	459.328
1641.98	431.73
1643.02	444.406
1644.06	440.366
1645.11	455.886
1646.15	452.058
1647.19	463.656
1648.24	475.276
1649.28	441.228
1650.32	467.761
1651.37	424.81
1652.41	459.353
1653.45	455.275
1654.49	453.373
1655.53	424.95
1656.57	458.923
1657.62	447.059
1658.66	450.816
1659.7	451.509
1660.74	476.059
1661.78	466.509
1662.82	420.582
1663.86	443.328
1664.9	414.368
1665.94	396.046
1666.98	459.713
1668.02	428.84
1669.06	429.884
1670.1	486.474
1671.14	418.6
1672.18	422.447
1673.21	472.878
1674.25	414.626
1675.29	456.389
1676.33	419.853
1677.37	455.495
1678.4	429.523
1679.44	448.981
1680.48	447.798
1681.52	458.481
1682.55	440.658
1683.59	432.696
1684.63	439.471
1685.66	468.98
1686.7	446.284
1687.73	434.511
1688.77	444.164
1689.81	471.447
1690.84	450.58
1691.88	490.192
1692.91	475.304
1693.95	423.542
1694.98	435.011
1696.01	449.825
1697.05	464.706
1698.08	461.348
1699.12	440.334
1700.15	454.062
1701.18	424.4
1702.22	428.084
1703.25	444.491
1704.28	448.277
1705.32	447.354
1706.35	446.24
1707.38	473.266
1708.41	431.528
1709.44	403.545
1710.48	466.077
1711.51	419.203
1712.54	444.662
1713.57	447.865
1714.6	424.893
1715.63	439.513
1716.66	464.871
1717.69	453.516
1718.72	425.464
1719.75	433.058
1720.78	449.557
1721.81	436.488
1722.84	434.08
1723.87	414.303
1724.9	429.673
1725.93	405.776
1726.96	426.912
1727.99	425.785
1729.02	425.87
1730.05	411.883
1731.07	439.6
1732.1	422.695
1733.13	445.67
1734.16	432.501
1735.18	464.68
1736.21	448.798
1737.24	411.032
1738.26	458.838
1739.29	451.679
1740.32	430.805
1741.34	449.433
1742.37	428.979
1743.4	442.215
1744.42	459.179
1745.45	412.182
1746.47	440.677
1747.5	408.65
1748.52	430.325
1749.55	423.711
1750.57	413.516
1751.6	394.545
1752.62	401.778
1753.64	428.122
1754.67	406.779
1755.69	433.213
1756.71	433.744
1757.74	443.716
1758.76	436.219
1759.78	434.329
1760.81	456.06
1761.83	434.812
1762.85	450.912
1763.87	444.281
1764.89	415.09
1765.92	445.713
1766.94	423.754
1767.96	421.69
1768.98	423.381
1770	442.514
1771.02	387.618
1772.04	441.159
1773.06	411.892
1774.08	447.264
1775.1	435.002
1776.12	444.93
1777.14	435.366
1778.16	432.199
1779.18	427.044
1780.2	446.925
1781.22	416.583
1782.24	402.392
1783.26	416.927
1784.28	438.091
1785.29	443.131
1786.31	413.415
1787.33	423.128
1788.35	427.734
1789.37	415.89
1790.38	433.488
1791.4	435.319
1792.42	433.989
1793.43	425.475
1794.45	417.87
1795.47	448.907
1796.48	400.416
1797.5	425.688
1798.51	420.106
1799.53	430.612
1800.55	429.328
1801.56	419.564
1802.58	456.126
1803.59	425.661
1804.61	440.254
1805.62	438.677
1806.64	445.746
1807.65	398.613
1808.66	439.089
1809.68	412.13
1810.69	414.083
1811.7	428.458
1812.72	442.959
1813.73	450.882
1814.74	436.784
1815.76	405.201
1816.77	409.128
1817.78	446.529
1818.79	403.092
1819.8	441.847
1820.82	429.453
1821.83	416.094
1822.84	429.794
1823.85	411.373
1824.86	436.529
1825.87	430.851
1826.88	421.163
1827.89	444.509
1828.9	427.027
1829.91	413.303
1830.92	429.566
1831.93	422.925
1832.94	428.964
1833.95	421.299
1834.96	444.235
1835.97	405.799
1836.98	431.545
1837.99	461.116
1839	446.533
1840	449.061
1841.01	428.8
1842.02	422.188
1843.03	417.932
1844.04	451.663
1845.04	414.024
1846.05	444.03
1847.06	421.255
1848.07	428.434
1849.07	427.522
1850.08	428.122
1851.09	417.953
1852.09	425.329
1853.1	423.352
1854.1	407.792
1855.11	425.55
1856.11	427.023
1857.12	436.505
1858.12	420.032
1859.13	412.957
1860.13	424.106
1861.14	402.26
1862.14	409.149
1863.15	442.321
1864.15	385.521
1865.15	403.341
1866.16	420.911
1867.16	423.02
1868.16	409.141
1869.17	397.654
1870.17	418.461
1871.17	433.565
1872.17	411.519
1873.18	444.466
1874.18	425.271
1875.18	422.001
1876.18	429.867
1877.18	411.405
1878.18	395.666
1879.19	421.839
1880.19	429.723
1881.19	432.481
1882.19	402.505
1883.19	407.282
1884.19	452.986
1885.19	432.447
1886.19	426.365
1887.19	438.549
1888.19	434.321
1889.19	410.155
1890.19	410.831
1891.19	426.128
1892.18	428.83
1893.18	422.959
1894.18	415.697
1895.18	378.834
1896.18	403.361
1897.18	378.208
1898.17	385.804
1899.17	366.743
1900.17	420.01
1901.16	411.512
1902.16	388.298
1903.16	435.445
1904.16	419.264
1905.15	407.881
1906.15	419.905
1907.14	410.185
1908.14	424.296
1909.14	397.202
1910.13	383.43
1911.13	398.939
1912.12	408.445
1913.12	392.336
1914.11	429.246
1915.11	402.285
1916.1	396.746
1917.1	434.246
1918.09	400.064
1919.08	397.469
1920.08	402.723
1921.07	391.431
1922.06	408.745
1923.06	432.296
1924.05	393.333
1925.04	426.176
1926.04	441.57
1927.03	383.361
1928.02	401.569
1929.01	446.246
1930	439.001
1931	434.701
1931.99	411.844
1932.98	414.424
1933.97	415.415
1934.96	399.466
1935.95	425.118
1936.94	428.49
1937.93	429.989
1938.92	390.904
1939.91	398.72
1940.9	398.017
1941.89	416.485
1942.88	418.547
1943.87	405.869
1944.86	389.902
1945.85	414.148
1946.84	428.746
1947.83	436.302
1948.82	434.307
1949.8	413.511
1950.79	407.359
1951.78	418.521
1952.77	403.47
1953.76	389.081
1954.74	410.267
1955.73	416.73
1956.72	427.012
1957.7	424.51
1958.69	395.865
1959.68	409.158
1960.66	401.237
1961.65	415.323
1962.63	416.265
1963.62	404.785
1964.61	424.092
1965.59	374.084
1966.58	397.316
1967.56	406.129
1968.55	403.29
1969.53	385.746
1970.52	402.562
1971.5	411.887
1972.48	416.651
1973.47	381.044
1974.45	425.823
1975.44	437.333
1976.42	411.637
1977.4	419.314
1978.39	418.113
1979.37	384.404
1980.35	429.464
1981.33	404.293
1982.31	410.821
1983.3	416.284
1984.28	413.095
1985.26	409.05
1986.24	414.622
1987.22	389.878
1988.21	444.026
1989.19	401.268
1990.17	391.685
1991.15	401.3
1992.13	397.993
1993.11	397.237
1994.09	407.808
1995.07	411.095
1996.05	401.906
1997.03	397.044
1998.01	406.045
1998.99	398.217
1999.97	395.419
2000.95	402.149
2001.92	402.619
2002.9	398.026
2003.88	417.03
2004.86	404.269
2005.84	402.975
2006.81	414.829
2007.79	420.03
2008.77	409.672
2009.75	405.167
2010.73	405.471
2011.7	387.255
2012.68	397.504
2013.67	406.448
2014.66	400.142
2015.64	429.061
2016.63	439.567
2017.62	404.142
2018.61	407.342
2019.6	430.146
2020.58	414.025
2021.57	402.787
2022.56	423.264
2023.55	424.729
2024.54	379.489
2025.52	385.509
2026.51	393.575
2027.5	384.312
2028.48	388.525
2029.47	375.096
2030.45	400.061
2031.44	392.763
2032.43	392.82
2033.41	415.744
2034.4	412.046
2035.38	378.739
2036.37	423.503
2037.35	392.511
2038.34	432.585
2039.32	394.936
2040.31	385.254
2041.29	412.837
2042.27	389.335
2043.26	420.84
2044.24	398.004
2045.23	427.591
2046.21	403.242
2047.19	442.992
2048.17	452.672
2049.16	401.495
2050.14	412.207
2051.12	411.578
2052.11	409.465
2053.09	417.066
2054.07	405.357
2055.05	403.611
2056.03	400.603
2057.01	386.445
2058	439.821
2058.98	414.892
2059.96	407.594
2060.94	413.987
2061.92	427.256
2062.9	408.618
2063.88	386.374
2064.86	410.892
2065.84	409.404
2066.82	427.492
2067.8	427.673
2068.78	425.987
2069.76	417.406
2070.73	412.66
2071.71	407.28
2072.69	425.737
2073.67	405.883
2074.65	400.324
2075.63	380.071
2076.6	412.577
2077.58	407.644
2078.56	383.953
2079.54	408.7
2080.51	405.325
2081.49	432.704
2082.47	416.632
2083.45	387.385
2084.42	391.129
2085.4	434.607
2086.37	409.217
2087.35	410.472
2088.32	382.19
2089.3	411.59
2090.28	393.867
2091.25	397.777
2092.23	384.798
2093.2	418.51
2094.18	403.697
2095.15	388.556
2096.13	395.926
2097.1	417.658
2098.07	423.085
2099.05	415.378
2100.02	421.949
2101	402.089
2101.97	402.333
2102.94	416.538
2103.92	411.569
2104.89	404.996
2105.86	418.57
2106.83	408.295
2107.8	428.273
2108.78	357.554
2109.75	409.781
2110.72	425.06
2111.69	381.32
2112.66	423.926
2113.63	410.854
2114.61	423.262
2115.58	420.398
2116.55	399.299
2117.52	420.028
2118.49	411.312
2119.46	409.94
2120.43	398.252
2121.4	422.978
2122.37	370.223
2123.34	402.706
2124.31	406.464
2125.28	386.014
2126.25	392.093
2127.21	419.156
2128.18	437.881
2129.15	410.386
2130.12	423.509
2131.09	415.818
2132.06	384.409
2133.02	406.817
2133.99	415.286
2134.96	395.481
2135.93	411.427
2136.89	430.829
2137.86	414.881
2138.83	421.318
2139.79	394.067
2140.76	429.522
2141.73	398.323
2142.69	435.757
2143.66	405.938
2144.62	389.14
2145.59	398.55
2146.55	404.107
2147.52	443.398
2148.48	397.149
2149.45	402.527
2150.42	412.359
2151.38	397.25
2152.34	409.627
2153.31	426.354
2154.27	437.367
2155.24	408.663
2156.2	428.666
2157.16	414.484
2158.13	423.049
2159.09	428.71
2160.05	412.568
2161.01	414.043
2161.98	396.157
2162.94	388.66
2163.9	408.993
2164.86	385.394
2165.83	431.038
2166.79	384.356
2167.75	387.785
2168.71	410.474
2169.67	420.845
2170.63	399.009
2171.59	410.06
2172.56	408.433
2173.51	398.056
2174.48	411.166
2175.44	407.45
2176.4	394.34
2177.36	431.365
2178.32	384.001
2179.28	420.898
2180.23	432.056
2181.19	409.692
2182.15	402.122
2183.11	410.309
2184.07	371.915
2185.03	424.599
2185.99	417.332
2186.95	437.143
2187.9	420.899
2188.86	423.496
2189.82	410.979
2190.78	416.353
2191.73	406.238
2192.69	421.208
2193.65	400.103
2194.6	407.187
2195.56	414.573
2196.52	420.645
2197.47	391.486
2198.43	429.506
2199.38	429.987
2200.34	456.641
2201.3	400.581
2202.25	415.957
2203.21	380.387
2204.16	437.769
2205.12	423.913
2206.07	442.411
2207.03	414.475
2207.98	399.834
2208.93	414.117
2209.89	431.935
2210.84	396.648
2211.8	448.168
2212.75	440.994
2213.7	419.351
2214.66	385.03
2215.61	402.077
2216.56	419.834
2217.51	418.844
2218.47	431.004
2219.42	414.382
2220.37	396.835
2221.32	414.5
2222.27	430.917
2223.23	402.926
2224.18	384.573
2225.13	390.589
2226.08	397.519
2227.03	405.328
2227.98	387.724
2228.93	422.313
2229.88	431.708
2230.83	386.096
2231.78	406.163
2232.73	409.298
2233.68	386.074
2234.63	405.043
2235.58	418.847
2236.53	431.95
2237.48	387.893
2238.43	393.14
2239.38	427.572
2240.33	415.122
2241.27	379.452
2242.22	413.523
2243.17	397.611
2244.12	405.94
2245.07	388.179
2246.01	429.291
2246.96	389.849
2247.91	414.628
2248.85	398.457
2249.8	424.012
2250.75	396.48
2251.69	426.422
2252.64	421.795
2253.59	411.983
2254.53	402.876
2255.48	401.965
2256.42	387.837
2257.37	410.881
2258.32	394.933
2259.26	393.166
2260.2	421.85
2261.15	403.02
2262.1	420.401
2263.04	405.385
2263.98	410.612
2264.93	414.054
2265.87	403.817
2266.81	426.527
2267.76	401.383
2268.7	383.016
2269.65	423.334
2270.59	406.664
2271.53	383.051
2272.47	423.441
2273.42	390.024
2274.36	394.889
2275.3	415.077
2276.24	408.469
2277.18	377.209
2278.13	394.981
2279.07	404.845
2280.01	418.94
2280.95	412.765
2281.89	430.777
2282.83	397.437
2283.77	425.734
2284.71	402.385
2285.65	445.95
2286.59	416.825
2287.54	385.506
2288.47	381.826
2289.41	398.846
2290.35	401.214
2291.29	418.545
2292.23	392.012
2293.17	449.17
2294.11	395.415
2295.05	409.646
2295.99	418.074
2296.93	385.977
2297.86	405.473
2298.8	420.326
2299.74	410.072
2300.68	398.518
2301.61	419.959
2302.55	442.141
2303.49	382.247
2304.43	401.653
2305.36	407.689
2306.3	399.14
2307.24	390.505
2308.17	430.955
2309.11	413.501
2310.04	388.722
2310.98	415.925
2311.92	407.541
2312.85	408.119
2313.79	410.157
2314.72	420.348
2315.66	400.294
2316.59	420.063
2317.52	397.68
2318.46	423.815
2319.39	414.855
2320.33	415.676
2321.26	397.443
2322.2	414.202
2323.13	423.158
2324.06	392.315
2325	423.121
2325.93	412.989
2326.86	427.106
2327.79	458.564
2328.73	486.404
2329.66	443.701
2330.59	417.651
2331.52	417.583
2332.46	392.645
2333.39	403.946
2334.32	398.934
2335.25	395.765
2336.18	415.96
2337.11	435.078
2338.04	409.019
2338.97	403.163
2339.91	408.932
2340.84	393.328
2341.77	420.667
2342.7	396.354
2343.63	414.486
2344.56	423.102
2345.49	401.937
2346.41	425.548
2347.34	411.063
2348.27	382.323
2349.2	409.166
2350.13	388.451
2351.06	392.296
2351.99	393.869
2352.91	411.386
2353.84	413.633
2354.77	391.726
2355.7	394.596
2356.63	411.443
2357.55	408.071
2358.48	393.575
2359.41	407.63
2360.33	358.966
2361.26	388.973
2362.19	422.682
2363.11	419.417
2364.04	386.999
2364.97	401.9