File: Data/3-Raman/raw/bu32-b-ff2-fi01-l_150 (500nm)_532nm_edge_100%_x100_vis_lwd_h30um_30sx2_01.txt
#Acq. time (s)=	30
#Accumulations=	2
#Range (cm-¹)=	100...5000
#Windows=	1
#Auto scanning=	Off
#Autofocus=	Off
#Macrospot=	Off
#AutoExposure=	Off
#Spike filter=	Multiple accum.
#Delay time (s)=	2
#Binning=	1
#Readout mode=	Signal
#DeNoise=	Off
#ICS correction=	On
#Dark correction=	Off
#Inst. Process=	Off
#Detector Gain=	Best Dynamic
#Detector ADC=	50 kHz HS
#Detector temperature (°C)=	-60.09
#Instrument=	LabRAM HR Evol
#Detector=	SIN-EM FIVIS
#Objective=	x100_VIS_LWD
#Grating=	150 (500nm)
#ND Filter=	100%
#Laser=	532nm_Edge
#Hole=	30.0125
#Temperature=	40
#Range=	Visible
#StageXY=	75x50mm Scan+
#StageZ=	Z motor
#X (µm)=	0
#Y (µm)=	0
#Z (µm)=	77
#Full time(mm:ss)=	1:05
#Project=	21_08_11
#Sample=	BU32
#Site=
#Title=	BU32-B-FF2-FI01-L_150 (500nm)_532nm_Edge_100%_x100_VIS_LWD_H30um_30sX2
#Remark=
#Date=	13.08.2021 15:23
#Acquired=	13.08.2021 15:23:42
102.095	6470.95
106.719	6059.95
111.341	5733.76
115.96	5425.96
120.577	5193.87
125.19	4890.83
129.802	4726.79
134.413	4514.21
139.021	4423.39
143.624	4252.29
148.228	4086.46
152.829	4112.68
157.428	4424.23
162.022	4740.96
166.617	4626.75
171.209	4000.36
175.799	3310.31
180.384	3103.04
184.969	2926.67
189.552	2825.07
194.133	2684.42
198.71	2607.4
203.286	2564.55
207.86	2503.19
212.43	2418.63
216.999	2299.86
221.566	2209.24
226.131	2010.82
230.692	1890.26
235.253	1800.17
239.811	1777.15
244.365	1711.11
248.919	1609.7
253.47	1518.07
258.018	1559.23
262.565	1521.31
267.11	1512.65
271.65	1457.92
276.191	1436.11
280.727	1364.99
285.263	1367.28
289.797	1312.4
294.326	1338.3
298.856	1419.13
303.383	1424.78
307.906	1427.49
312.428	1373.91
316.947	1316.41
321.465	1254.53
325.981	1237.22
330.493	1249.37
335.005	1275.77
339.512	1361.82
344.019	1472.45
348.524	1594
353.025	1581.09
357.526	1437.39
362.022	1310.13
366.518	1210.94
371.01	1171
375.502	1177.12
379.99	1164.74
384.477	1224.63
388.961	1235.03
393.444	1325.48
397.923	1349.05
402.401	1453.9
406.878	1567.55
411.35	1599.8
415.823	1626.43
420.291	1597.22
424.758	1552.05
429.222	1528.91
433.684	1482.57
438.145	1454.29
442.602	1408.98
447.059	1369.18
451.512	1381.73
455.965	1378.01
460.413	1397.01
464.862	1298.34
469.306	1260.86
473.75	1210.89
478.19	1225.81
482.63	1254.6
487.065	1360.69
491.499	1495.07
495.932	1676.13
500.361	1850.1
504.79	2013.24
509.215	2221.98
513.638	2302.23
518.06	2403.24
522.479	2428.72
526.897	2335.81
531.311	2257.16
535.723	2167.34
540.135	2108.74
544.543	2112.54
548.948	2154.71
553.354	2129.35
557.755	2006.4
562.157	1938.13
566.554	1801.05
570.949	1662.88
575.344	1599.91
579.734	1622.07
584.123	1746.66
588.512	1989.19
592.896	2232.68
597.279	2273.6
601.659	2070.54
606.039	1667.09
610.415	1454.75
614.789	1270.83
619.163	1140.33
623.532	1067.86
627.9	1035.31
632.267	987.809
636.631	938.688
640.992	950.56
645.351	946.149
649.71	987.098
654.065	1032.07
658.418	989.296
662.769	956.443
667.12	923.407
671.466	827.056
675.811	763.667
680.154	716.369
684.494	721.862
688.834	697.092
693.171	683.553
697.505	677.976
701.837	661.384
706.169	642.793
710.497	661.388
714.823	626.017
719.146	627.069
723.468	614.24
727.788	613.932
732.107	615.273
736.423	588.954
740.737	587.508
745.048	585.274
749.357	593.622
753.665	583.137
757.972	568.9
762.275	564.889
766.576	535.924
770.875	549.348
775.172	540.725
779.467	534.907
783.76	519.346
788.051	524.146
792.34	490.487
796.629	509.471
800.914	493.436
805.196	475.612
809.477	477.776
813.756	478.916
818.032	477.942
822.307	458.253
826.58	447.486
830.85	444.46
835.119	455.769
839.385	448.307
843.649	454.028
847.912	458.486
852.172	468.173
856.431	475.647
860.687	537.086
864.941	624.772
869.194	639.508
873.444	580.48
877.692	498.435
881.938	439.539
886.183	432.027
890.425	394.889
894.665	409.912
898.903	403.875
903.14	418.316
907.374	408.328
911.606	432.469
915.836	439.517
920.064	474.52
924.291	473.68
928.515	512.315
932.737	591.197
936.957	636.584
941.176	696.651
945.392	742.535
949.606	808.504
953.818	879.818
958.029	991.478
962.237	1109.37
966.443	1292.95
970.645	1523.01
974.848	1720.13
979.048	1778.4
983.246	1670.69
987.443	1401.08
991.637	1235.49
995.83	1166.07
1000.02	1293.35
1004.21	1541.1
1008.39	1954.4
1012.58	2462.58
1016.76	2737.05
1020.94	2812.68
1025.12	2629.56
1029.29	2305.24
1033.47	1997.07
1037.64	1663.52
1041.81	1310.46
1045.98	1091.4
1050.15	949.187
1054.31	871.965
1058.47	862.509
1062.64	900.304
1066.79	949.181
1070.95	960.947
1075.1	921.32
1079.26	868.368
1083.41	801.991
1087.56	721.661
1091.7	660.58
1095.85	634.031
1099.99	654.036
1104.13	685.273
1108.27	715.622
1112.41	697.273
1116.55	644.45
1120.68	571.195
1124.81	499.454
1128.94	450.175
1133.07	414.177
1137.19	396.396
1141.32	410.365
1145.44	378.161
1149.56	368.413
1153.67	348.109
1157.79	349.302
1161.9	338.028
1166.02	323.545
1170.13	307.954
1174.23	307.736
1178.34	286.86
1182.45	285.563
1186.55	294.461
1190.65	285.718
1194.75	269.755
1198.84	279.306
1202.94	277.528
1207.03	287.923
1211.12	266.872
1215.21	277.262
1219.3	269.488
1223.38	271.842
1227.47	276.249
1231.55	262.726
1235.63	277.431
1239.7	290.289
1243.78	306.06
1247.85	296.973
1251.93	337.972
1256	361.096
1260.06	408.292
1264.13	456.616
1268.19	451.047
1272.26	426.496
1276.32	394.864
1280.38	350.089
1284.43	323.265
1288.49	313.442
1292.54	296.521
1296.59	285.579
1300.64	286.693
1304.69	285.738
1308.73	292.823
1312.78	276.695
1316.82	280.625
1320.86	291.538
1324.89	263.092
1328.93	272.851
1332.96	274.533
1337	264.09
1341.03	274.646
1345.06	289.128
1349.08	289.593
1353.11	313.944
1357.13	348.155
1361.15	425.841
1365.17	553.804
1369.19	756.567
1373.2	969.795
1377.22	964.776
1381.23	770.803
1385.24	536.096
1389.25	401.099
1393.25	327.272
1397.26	300.819
1401.26	266.449
1405.26	267.514
1409.26	239.037
1413.25	242.115
1417.25	224.48
1421.24	235.453
1425.23	217.765
1429.22	219.714
1433.21	211.801
1437.2	217.712
1441.18	212.762
1445.16	215.68
1449.14	196.871
1453.12	212.568
1457.1	211.466
1461.07	214.27
1465.05	208.143
1469.02	208.895
1472.99	207.71
1476.95	197.673
1480.92	205.269
1484.88	209.896
1488.85	200.814
1492.81	215.193
1496.77	203.224
1500.72	203.961
1504.68	212.513
1508.63	219.165
1512.58	216.113
1516.53	217.93
1520.48	220.74
1524.42	214.833
1528.37	227.369
1532.31	232.172
1536.25	235.042
1540.19	239.856
1544.12	243.701
1548.06	221.387
1551.99	245.578
1555.92	248.424
1559.85	256.071
1563.78	272.391
1567.7	284.797
1571.63	279.769
1575.55	278.607
1579.47	309.28
1583.39	300.364
1587.31	312.635
1591.22	325.839
1595.13	340.937
1599.05	343.518
1602.96	363.403
1606.86	357.409
1610.77	390.749
1614.67	398.201
1618.58	410.492
1622.48	425.622
1626.38	434.103
1630.27	437.854
1634.17	433.128
1638.06	441.788
1641.95	436.197
1645.84	414.408
1649.73	428.109
1653.62	404.43
1657.5	386.447
1661.39	377.07
1665.27	375.302
1669.15	350.417
1673.02	352.335
1676.9	320.583
1680.77	315.586
1684.65	298.992
1688.52	273.772
1692.39	262.917
1696.25	274.051
1700.12	260.274
1703.98	237.904
1707.84	235.549
1711.7	222.706
1715.56	212.761
1719.42	207.596
1723.27	206.231
1727.13	183.193
1730.98	193.116
1734.83	178.629
1738.68	181.962
1742.52	165.658
1746.37	175.511
1750.21	168.697
1754.05	161.968
1757.89	163.691
1761.73	163.825
1765.56	163.855
1769.4	164.868
1773.23	154.807
1777.06	141.009
1780.89	146.796
1784.71	148.892
1788.54	151.946
1792.36	144.715
1796.18	152.474
1800	142.396
1803.82	144.432
1807.64	147.399
1811.45	141.872
1815.27	150.459
1819.08	138.232
1822.89	142.005
1826.7	137.26
1830.5	139.081
1834.31	149.343
1838.11	143.56
1841.91	143.408
1845.71	154.492
1849.51	140.239
1853.3	137.202
1857.1	141.616
1860.89	137.573
1864.68	142.837
1868.47	149.02
1872.26	135.735
1876.04	152.123
1879.83	146.308
1883.61	143.338
1887.39	150.51
1891.17	143.113
1894.95	153.213
1898.72	153.188
1902.5	162.431
1906.27	157.904
1910.04	158.915
1913.81	152.609
1917.58	151.841
1921.34	157.637
1925.1	157.915
1928.87	157.293
1932.63	156.683
1936.38	167.247
1940.14	172.247
1943.9	169.777
1947.65	155.116
1951.4	173.126
1955.15	163.868
1958.9	170.483
1962.65	161.074
1966.39	170.438
1970.14	172.236
1973.88	173.028
1977.62	184.088
1981.36	164.214
1985.09	170.525
1988.83	180.529
1992.56	181.159
1996.29	193.835
2000.02	189.724
2003.75	186.563
2007.48	194.484
2011.21	194.025
2014.93	188.976
2018.65	191.379
2022.37	200.295
2026.09	191.909
2029.81	203.69
2033.52	208.227
2037.23	197.284
2040.95	208.289
2044.66	202.801
2048.37	201.893
2052.07	212.93
2055.78	201.085
2059.48	202.161
2063.18	201.533
2066.88	211.07
2070.58	205.917
2074.28	214.593
2077.97	214.068
2081.67	216.337
2085.36	207.449
2089.05	204.802
2092.74	211.336
2096.43	204.964
2100.11	213.432
2103.8	216.25
2107.48	210.66
2111.16	213.406
2114.84	198.48
2118.51	217.923
2122.19	204.758
2125.86	199.918
2129.54	209.883
2133.21	204.07
2136.88	211.199
2140.55	207.196
2144.21	193.038
2147.87	200.07
2151.54	196.055
2155.2	192.06
2158.86	208.222
2162.52	199.683
2166.17	200.326
2169.83	189.153
2173.48	185.366
2177.13	192.552
2180.78	195.207
2184.43	188.756
2188.08	192.361
2191.72	193.313
2195.36	181.601
2199.01	182.669
2202.65	191.055
2206.29	197.663
2209.92	179.638
2213.56	195.463
2217.19	178.337
2220.82	169.427
2224.45	181.654
2228.08	183.774
2231.71	186.826
2235.33	171.422
2238.96	172.624
2242.58	186.803
2246.2	187.093
2249.82	171.582
2253.44	179.327
2257.06	178.717
2260.67	169.686
2264.28	174.651
2267.9	196.536
2271.5	178.128
2275.11	170.905
2278.72	178.697
2282.32	168.459
2285.93	169.53
2289.53	175.329
2293.13	166.925
2296.73	164.192
2300.32	165.25
2303.92	167.23
2307.52	158.75
2311.11	170.149
2314.7	150.243
2318.29	171.067
2321.88	179.525
2325.46	166.096
2329.05	167.8
2332.63	165.704
2336.21	166.419
2339.79	178.407
2343.37	159.321
2346.95	166.55
2350.52	159.692
2354.09	165.005
2357.67	163.755
2361.24	155.98
2364.81	158.457
2368.37	164.643
2371.94	152.327
2375.5	161.304
2379.07	162.87
2382.63	164.451
2386.19	158.685
2389.74	158.473
2393.3	157.376
2396.85	151.744
2400.41	157.167
2403.96	153.509
2407.51	156.289
2411.06	153.631
2414.61	162.942
2418.15	152.093
2421.7	155.964
2425.24	149.746
2428.78	156.47
2432.32	150.3
2435.86	156.189
2439.39	155.616
2442.93	160.64
2446.46	158.225
2449.99	156.764
2453.52	147.815
2457.05	157.539
2460.58	154.915
2464.1	153.209
2467.63	141.944
2471.15	154.374
2474.67	159.02
2478.19	162.68
2481.71	166.364
2485.22	160.566
2488.74	155.622
2492.25	156.406
2495.77	155.231
2499.28	160.665
2502.78	151.07
2506.29	157.352
2509.8	161.714
2513.3	155.835
2516.8	163.018
2520.31	166.498
2523.81	161.519
2527.3	153.019
2530.8	151.042
2534.3	171.245
2537.79	161.026
2541.28	162.843
2544.77	157.355
2548.26	154.702
2551.75	164.993
2555.24	162.391
2558.72	160.792
2562.2	153.619
2565.68	161.369
2569.16	170.136
2572.64	156.559
2576.12	167.308
2579.6	156.528
2583.07	154.18
2586.54	156.546
2590.01	165.526
2593.48	160.204
2596.95	153.874
2600.42	163.8
2603.88	167.057
2607.35	171.191
2610.81	158.873
2614.27	163.708
2617.73	159.004
2621.19	156.15
2624.64	164.796
2628.1	173.394
2631.55	156.992
2635	168.397
2638.45	161.518
2641.9	165.157
2645.35	162.06
2648.79	154.188
2652.24	168.226
2655.68	165.046
2659.12	161.844
2662.56	167.162
2666	164.879
2669.44	164.489
2672.87	165.031
2676.31	170.288
2679.74	172.739
2683.17	174.283
2686.6	183.347
2690.03	167.337
2693.45	179.366
2696.88	168.063
2700.3	169.841
2703.73	179.067
2707.15	178.059
2710.57	169.739
2713.98	180.058
2717.4	181.114
2720.81	171.955
2724.23	180.527
2727.64	176.056
2731.05	180.937
2734.46	173.648
2737.87	184.15
2741.27	189.037
2744.68	183.567
2748.08	181.82
2751.48	189.476
2754.88	196.187
2758.28	184.052
2761.68	187.923
2765.08	196.457
2768.47	204.022
2771.86	201.188
2775.25	197.394
2778.64	203.929
2782.03	195.366
2785.42	193.383
2788.81	203.622
2792.19	202.562
2795.58	211.829
2798.96	212.637
2802.34	210.594
2805.71	196.371
2809.09	215.882
2812.47	210.083
2815.84	219.241
2819.22	212.497
2822.59	221.665
2825.96	222.456
2829.33	214.872
2832.69	228.757
2836.06	238.016
2839.42	226.821
2842.79	241.755
2846.15	245.57
2849.51	237.353
2852.87	252.52
2856.22	252.732
2859.58	267.008
2862.93	265.429
2866.29	254.485
2869.64	271.67
2872.99	272.905
2876.34	272.252
2879.68	276.298
2883.03	282.226
2886.38	289.086
2889.72	295.95
2893.06	305.646
2896.4	295.427
2899.74	299.341
2903.08	292.805
2906.41	327.862
2909.75	316.531
2913.08	330.724
2916.41	331.647
2919.74	345.764
2923.07	358.908
2926.4	350.268
2929.72	359.537
2933.05	366.865
2936.37	362.803
2939.69	389.861
2943.01	381.078
2946.33	411.858
2949.65	407.8
2952.97	431.933
2956.28	428.802
2959.6	451.093
2962.91	456.513
2966.22	469.458
2969.53	490.977
2972.84	474.134
2976.14	494.822
2979.45	520.298
2982.75	527.891
2986.05	540.212
2989.36	574.168
2992.65	566.836
2995.95	602.752
2999.25	615.228
3002.54	635.232
3005.84	643.962
3009.13	638.634
3012.42	662.529
3015.71	705.311
3019	720.781
3022.29	754.179
3025.57	735.705
3028.86	797.49
3032.14	813.974
3035.42	833.271
3038.7	879.04
3041.98	896.473
3045.26	925.298
3048.54	948.478
3051.81	967.887
3055.08	1013.89
3058.36	1032.39
3061.63	1080.92
3064.9	1112.56
3068.16	1140.28
3071.43	1176.32
3074.7	1191.34
3077.96	1262.6
3081.22	1292.63
3084.48	1359.86
3087.74	1400.51
3091	1394.11
3094.26	1462
3097.51	1512.79
3100.77	1597.85
3104.02	1634.12
3107.27	1691.19
3110.52	1763.3
3113.77	1798.69
3117.02	1881.87
3120.26	1935.6
3123.51	1994.12
3126.75	2054.54
3129.99	2093.95
3133.24	2203.93
3136.47	2256.69
3139.71	2313.16
3142.95	2424.9
3146.19	2473.74
3149.42	2558.04
3152.65	2629.07
3155.88	2700.01
3159.11	2799.66
3162.34	2827.69
3165.57	2971.2
3168.8	3041.93
3172.02	3116.26
3175.24	3187.58
3178.46	3298.69
3181.69	3382.05
3184.9	3457.83
3188.12	3491.22
3191.34	3561.66
3194.55	3709.24
3197.77	3770.94
3200.98	3837.27
3204.19	3867.55
3207.4	3970.28
3210.61	4056.96
3213.82	4122.96
3217.02	4182.58
3220.23	4209.85
3223.43	4292.43
3226.63	4324.08
3229.83	4413.86
3233.03	4497.35
3236.23	4463.48
3239.43	4563.86
3242.62	4556.96
3245.82	4661.76
3249.01	4718.05
3252.2	4702.39
3255.39	4738.36
3258.58	4864.03
3261.77	4882.15
3264.95	4913.91
3268.14	4914.42
3271.32	4997.55
3274.5	5023.04
3277.68	5056.13
3280.86	5109.15
3284.04	5044.74
3287.22	5148.42
3290.39	5181.92
3293.57	5213.94
3296.74	5242.86
3299.91	5258.47
3303.08	5268.67
3306.25	5381.2
3309.42	5465.51
3312.59	5528.89
3315.75	5534.87
3318.91	5646.96
3322.08	5692.29
3325.24	5700.66
3328.4	5729.87
3331.56	5895.31
3334.71	5912.58
3337.87	5924.67
3341.02	6028.71
3344.18	6053.55
3347.33	6166.58
3350.48	6300.92
3353.63	6289.98
3356.78	6397.59
3359.92	6493.29
3363.07	6536.06
3366.21	6626.16
3369.36	6756.27
3372.5	6839.57
3375.64	6822.74
3378.78	6876.08
3381.92	7046.05
3385.05	7128.87
3388.19	7147.12
3391.32	7286.63
3394.46	7283.99
3397.59	7357.94
3400.72	7395.4
3403.85	7558.83
3406.97	7587.47
3410.1	7600.42
3413.22	7708.42
3416.35	7558.45
3419.47	7620.36
3422.59	7693.11
3425.71	7607.8
3428.83	7642.3
3431.95	7608.92
3435.06	7583.54
3438.18	7573.53
3441.29	7570.22
3444.41	7671.7
3447.52	7507.34
3450.63	7516.44
3453.73	7604.44
3456.84	7562.66
3459.95	7545.54
3463.05	7558.72
3466.16	7553.43
3469.26	7602.1
3472.36	7509.86
3475.46	7585.92
3478.56	7453.11
3481.65	7287.75
3484.75	7328.82
3487.84	7166.36
3490.94	7157.12
3494.03	7053.62
3497.12	6892.39
3500.21	6770.37
3503.3	6622.24
3506.39	6478.74
3509.47	6376.84
3512.55	6123.38
3515.64	6021.82
3518.72	5951.63
3521.8	5786.04
3524.88	5664.04
3527.96	5520
3531.04	5350.5
3534.11	5258.16
3537.19	5127.37
3540.26	4979.11
3543.33	4886.93
3546.4	4768.26
3549.47	4620.87
3552.54	4592.19
3555.61	4473.19
3558.67	4317.92
3561.74	4229.74
3564.8	4132.99
3567.86	4014.66
3570.92	3923.18
3573.98	3794.61
3577.04	3697.5
3580.1	3580.13
3583.15	3541.2
3586.21	3416.57
3589.26	3364.98
3592.31	3252.29
3595.37	3223.93
3598.41	3131.81
3601.46	3061.55
3604.51	2963.56
3607.56	2931.66
3610.6	2818.45
3613.64	2716.56
3616.69	2695.91
3619.73	2648.03
3622.77	2545.62
3625.81	2461.31
3628.84	2353.68
3631.88	2295.94
3634.91	2219.3
3637.95	2143.3
3640.98	2047.86
3644.01	1956.44
3647.04	1874.95
3650.07	1802.31
3653.1	1679.19
3656.13	1580.25
3659.15	1522.55
3662.17	1392.09
3665.2	1328.08
3668.22	1238.85
3671.24	1160.24
3674.26	1090.09
3677.28	1016.16
3680.29	957.301
3683.31	873.747
3686.32	812.8
3689.33	797.226
3692.35	719.159
3695.36	701.641
3698.37	651.727
3701.37	604.745
3704.38	580.481
3707.39	549.528
3710.39	528.926
3713.4	502.557
3716.4	473.246
3719.4	466.788
3722.4	427.899
3725.4	415.614
3728.39	414.715
3731.39	386.168
3734.38	376.628
3737.38	349.909
3740.37	351.728
3743.36	328.761
3746.35	344.782
3749.34	324.629
3752.33	304.475
3755.32	303.33
3758.3	299.348
3761.28	289.673
3764.27	283.777
3767.25	291.152
3770.23	289.076
3773.21	268.116
3776.19	264.212
3779.16	260.327
3782.14	264.018
3785.11	242.215
3788.09	247.816
3791.06	248.71
3794.03	247.757
3797	228.89
3799.97	245.905
3802.94	234.634
3805.9	232.813
3808.87	232.888
3811.83	221.636
3814.8	217
3817.76	219.932
3820.72	225.715
3823.68	221.095
3826.63	218.38
3829.59	212.821
3832.55	213.893
3835.5	212.14
3838.45	217.045
3841.41	221.007
3844.36	208.801
3847.31	215.621
3850.26	211.027
3853.2	198.811
3856.15	216.163
3859.09	213.488
3862.04	198.383
3864.98	214.815
3867.92	203.503
3870.86	217.073
3873.8	199.008
3876.74	208.74
3879.68	198.296
3882.61	196.465
3885.55	204.22
3888.48	208.119
3891.41	196.627
3894.34	211.085
3897.27	197.63
3900.2	199.539
3903.13	197.596
3906.06	204.279
3908.98	198.49
3911.91	193.645
3914.83	195.508
3917.75	206.96
3920.67	207.882
3923.59	202.042
3926.51	213.453
3929.43	202.78
3932.34	188.276
3935.26	193.946
3938.17	208.271
3941.08	193.905
3944	197.714
3946.91	203.448
3949.81	193.883
3952.72	204.44
3955.63	199.685
3958.54	200.694
3961.44	198.838
3964.34	201.784
3967.25	195.153
3970.15	200.999
3973.05	200.138
3975.95	195.43
3978.84	200.312
3981.74	175.391
3984.63	190.828
3987.53	193.764
3990.42	196.695
3993.32	181.325
3996.21	197.736
3999.1	186.242
4001.98	187.266
4004.87	179.626
4007.76	193.187
4010.64	189.41
4013.53	171.163
4016.41	168.339
4019.29	179.988
4022.17	183.921
4025.05	173.371
4027.93	182.141
4030.81	188.019
4033.68	177.467
4036.56	176.582
4039.43	189.258
4042.3	180.633
4045.18	184.565
4048.05	182.694
4050.92	174.044
4053.78	164.426
4056.65	170.343
4059.52	171.405
4062.38	167.604
4065.24	167.687
4068.11	162.907
4070.97	160.065
4073.83	165.982
4076.69	148.526
4079.55	154.437
4082.4	149.631
4085.26	149.697
4088.11	155.61
4090.97	145.91
4093.82	148.907
4096.67	147.988
4099.52	146.098
4102.37	155.935
4105.22	154.039
4108.06	147.231
4110.91	140.421
4113.76	138.486
4116.6	147.302
4119.44	145.331
4122.28	144.341
4125.12	146.304
4127.96	145.335
4130.8	141.468
4133.64	148.393
4136.47	140.669
4139.31	142.568
4142.14	133.57
4144.97	139.426
4147.81	134.578
4150.64	127.778
4153.47	131.719
4156.29	138.549
4159.12	133.572
4161.95	128.646
4164.77	121.784
4167.59	130.57
4170.42	133.492
4173.24	136.422
4176.06	131.532
4178.88	120.775
4181.7	126.653
4184.51	127.646
4187.33	130.603
4190.14	120.844
4192.96	117.951
4195.77	126.819
4198.58	115.138
4201.39	120.107
4204.2	112.332
4207.01	121.232
4209.82	120.322
4212.62	117.442
4215.43	119.474
4218.23	116.657
4221.04	117.77
4223.84	115.915
4226.64	117.003
4229.44	112.182
4232.24	114.282
4235.03	111.448
4237.83	112.581
4240.63	118.686
4243.42	114.865
4246.21	111.04
4249	109.193
4251.8	109.327
4254.59	101.462
4257.37	106.578
4260.16	104.691
4262.95	98.7926
4265.73	100.918
4268.52	104.06
4271.3	105.196
4274.08	106.331
4276.87	95.3402
4279.65	105.52
4282.43	95.4977
4285.2	106.687
4287.98	108.77
4290.76	98.6952
4293.53	93.6712
4296.3	102.84
4299.08	93.7796
4301.85	94.8434
4304.62	91.8474
4307.39	89.8634
4310.16	88.8976
4312.92	94.039
4315.69	90.0168
4318.46	96.1578
4321.22	91.0997
4323.98	92.1398
4326.75	87.0658
4329.51	87.0854
4332.27	94.2261
4335.02	89.1482
4337.78	90.1736
4340.54	85.1014
4343.29	88.1829
4346.05	84.1366
4348.8	85.1964
4351.56	85.2369
4354.31	80.1927
4357.06	80.2439
4359.81	80.2949
4362.55	81.3646
4365.3	81.4194
4368.05	81.4672
4370.79	85.6252
4373.54	69.2531
4376.28	82.6305
4379.02	82.6631
4381.76	87.8298
4384.5	74.5081
4387.24	75.5856
4389.98	78.754
4392.72	84.0043
4395.45	83.1401
4398.19	85.3148
4400.92	75.0649
4403.65	72.039
4406.38	72.1233
4409.11	79.4839
4411.84	80.6114
4414.57	70.2766
4417.3	76.5927
4420.02	73.5021
4422.75	73.5519
4425.47	68.386
4428.2	74.7062
4430.92	74.7621
4433.64	72.7236
4436.36	79.0554
4439.08	72.8184
4441.8	68.6634
4444.51	72.8967
4447.23	72.9321
4449.94	71.9177
4452.66	66.6947
4455.37	71.9737
4458.08	73.0453
4460.79	73.0629
4463.5	73.0901
4466.21	71.0115
4468.92	67.8832
4471.62	65.8083
4474.33	66.8976
4477.03	75.3736
4479.74	71.2079
4482.44	70.2075
4485.14	70.262
4487.84	69.2535
4490.54	73.5308
4493.24	67.2101
4495.94	67.2258
4498.63	73.6093
4501.33	57.7439
4504.02	70.4783
4506.71	67.3249
4509.41	62.0498
4512.1	65.2595
4514.79	66.3504
4517.48	64.2577
4520.16	69.6045
4522.85	64.3316
4525.54	66.4998
4528.22	69.7339
4530.91	60.1906
4533.59	54.9004
4536.27	69.8736
4538.95	69.9249
4541.63	64.6388
4544.31	66.8282
4546.99	59.3924
4549.66	55.1579
4552.34	65.9297
4555.02	67.0762
4557.69	63.9371
4560.36	61.8845
4563.03	65.2268
4565.7	62.1203
4568.37	63.3491
4571.04	71.0529
4573.71	53.7298
4576.38	62.4247
4579.04	62.4668
4581.71	62.5354
4584.37	64.7947
4587.03	58.3024
4589.69	60.5215
4592.36	56.1904
4595.02	56.2249
4597.67	60.6368
4600.33	58.4888
4602.99	56.349
4605.64	56.3998
4608.3	61.9319
4610.95	64.1837
4613.6	54.3578
4616.26	62.0994
4618.91	56.6568
4621.56	60.0166
4624.2	54.5625
4626.85	63.4361
4629.5	55.7596
4632.14	54.6988
4634.79	58.0513
4637.43	55.872
4640.07	59.2243
4642.72	57.0432
4645.36	55.981
4648	59.3704
4650.63	55.0043
4653.27	52.8717
4655.91	51.8254
4658.54	57.408
4661.18	54.1136
4663.81	56.4068
4666.45	54.2248
4669.08	55.3826
4671.71	56.5471
4674.34	53.2297
4676.97	54.3925
4679.59	52.1889
4682.22	57.8428
4684.85	54.5131
4687.47	50.0538
4690.09	48.9656
4692.72	54.6356
4695.34	50.1634
4697.96	47.9406
4700.58	50.231
4703.2	52.5228
4705.82	44.6412
4708.43	51.4494
4711.05	56
4713.66	52.6312
4716.28	48.1248
4718.89	49.2763
4721.5	48.1605
4724.11	51.5757
4726.72	55.0006
4729.33	51.6245
4731.94	50.5159
4734.55	48.2705
4737.15	51.7026
4739.76	49.4505
4742.36	52.8811
4744.97	52.8969
4747.57	52.909
4750.17	51.7754
4752.77	44.953
4755.37	47.2335
4757.97	48.3759
4760.56	50.6617
4763.16	48.3972
4765.76	47.2735
4768.35	43.8801
4770.94	46.1889
4773.54	51.9131
4776.13	45.0874
4778.72	49.6755
4781.31	47.4122
4783.9	46.2903
4786.48	47.455
4789.07	48.6209
4791.66	48.6453
4794.24	46.3813
4796.83	44.1165
4799.41	48.7334
4801.99	44.1799
4804.57	49.9593
4807.15	48.8579
4809.73	45.4566
4812.31	46.6556
4814.88	50.1663
4817.46	47.9155
4820.04	44.507
4822.61	48.0347
4825.18	39.9828
4827.76	41.1928
4830.33	42.4065
4832.9	48.2814
4835.47	42.524
4838.04	46.0897
4840.6	48.5021
4843.17	45.0673
4845.74	46.3031
4848.3	48.7109
4850.86	47.5844
4853.43	44.0741
4855.99	41.7437
4858.55	41.8054
4861.11	43.0439
4863.67	48.9959
4866.23	41.9451
4868.78	41.9805
4871.34	46.761
4873.89	38.5064
4876.45	40.9055
4879	46.8674
4881.55	44.5235
4884.1	40.9859
4886.66	41.0098
4889.2	44.603
4891.75	49.3909
4894.3	43.4651
4896.85	45.8716
4899.39	47.087
4901.94	43.532
4904.48	43.5526
4907.02	41.1839
4909.57	40.0059
4912.11	38.8183
4914.65	41.211
4917.19	43.5998
4919.73	41.2151
4922.26	44.8036
4924.8	40.0291
4927.33	41.2316
4929.87	42.4291
4932.4	42.4428
4934.93	43.6609
4937.47	42.4818
4940	40.104
4942.53	44.8898
4945.05	38.9165
4947.58	40.1331
4950.11	43.7463
4952.64	32.9769
4955.16	46.1861
4957.68	43.8124
4960.21	43.8416
4962.73	41.471
4965.25	39.1078
4967.77	36.7466
4970.29	36.7813
4972.81	36.8144
4975.33	42.8868
4977.84	46.5505
4980.36	40.5414
4982.88	34.5218
4985.39	40.6167
4987.9	38.2289
4990.41	41.9114
4992.93	37.0874
4995.44	37.1217
4997.95	34.7255