File: Data/3-Raman/raw/bu32-b-ff2-fi02-l_150 (500nm)_532nm_edge_100%_x100_vis_lwd_h30um_30sx2_01.txt
#Acq. time (s)=	30
#Accumulations=	2
#Range (cm-¹)=	100...5000
#Windows=	1
#Auto scanning=	Off
#Autofocus=	Off
#Macrospot=	Off
#AutoExposure=	Off
#Spike filter=	Multiple accum.
#Delay time (s)=	2
#Binning=	1
#Readout mode=	Signal
#DeNoise=	Off
#ICS correction=	On
#Dark correction=	Off
#Inst. Process=	Off
#Detector Gain=	Best Dynamic
#Detector ADC=	50 kHz HS
#Detector temperature (°C)=	-60.09
#Instrument=	LabRAM HR Evol
#Detector=	SIN-EM FIVIS
#Objective=	x100_VIS_LWD
#Grating=	150 (500nm)
#ND Filter=	100%
#Laser=	532nm_Edge
#Hole=	30.0125
#Temperature=	40
#Range=	Visible
#StageXY=	75x50mm Scan+
#StageZ=	Z motor
#X (µm)=	0
#Y (µm)=	0
#Z (µm)=	65.3
#Full time(mm:ss)=	1:04
#Project=	21_08_11
#Sample=	BU32
#Site=
#Title=	BU32-B-FF2-FI02-L_150 (500nm)_532nm_Edge_100%_x100_VIS_LWD_H30um_30sX2
#Remark=
#Date=	13.08.2021 15:32
#Acquired=	13.08.2021 15:32:47
102.095	2537.37
106.719	2247.17
111.341	2087.55
115.96	1915.89
120.577	1815.16
125.19	1763.02
129.802	1766.14
134.413	1880.77
139.021	1862.32
143.624	1808.53
148.228	1817.5
152.829	2067.08
157.428	2748.21
162.022	3476.54
166.617	3487.97
171.209	2570.83
175.799	1768.64
180.384	1483.32
184.969	1407.37
189.552	1418.34
194.133	1466.06
198.71	1513.8
203.286	1596.96
207.86	1741.16
212.43	1818.1
216.999	1745.84
221.566	1576.98
226.131	1475.25
230.692	1483.24
235.253	1593.7
239.811	1774.7
244.365	1862.4
248.919	1710.88
253.47	1474.23
258.018	1485.01
262.565	1577.23
267.11	1612.24
271.65	1530.72
276.191	1415.5
280.727	1375.89
285.263	1293.37
289.797	1314.82
294.326	1422.06
298.856	1572.29
303.383	1748.56
307.906	1712.62
312.428	1563.84
316.947	1389.37
321.465	1248.45
325.981	1228.72
330.493	1253
335.005	1368.57
339.512	1597.71
344.019	1909.93
348.524	2170.16
353.025	2094.76
357.526	1756.81
362.022	1363.99
366.518	1143.9
371.01	1049.06
375.502	1018.81
379.99	1016.82
384.477	1033.27
388.961	1130.15
393.444	1248.4
397.923	1473.81
402.401	1694.32
406.878	1939.89
411.35	2075.4
415.823	2245
420.291	2340.57
424.758	2448.71
429.222	2655.73
433.684	2634.31
438.145	2465.31
442.602	2311.52
447.059	2164.3
451.512	2349.82
455.965	2571.06
460.413	2622.85
464.862	2249.86
469.306	1796.94
473.75	1491.46
478.19	1416.74
482.63	1427.41
487.065	1610.1
491.499	1883.82
495.932	2336.83
500.361	2797.45
504.79	3247.44
509.215	3709.09
513.638	4077.89
518.06	4293.94
522.479	4462.76
526.897	4369.31
531.311	4262.76
535.723	3931.31
540.135	3818.44
544.543	3874.45
548.948	3842.52
553.354	3902.93
557.755	3719.7
562.157	3418.22
566.554	3104.29
570.949	2760.32
575.344	2583.59
579.734	2574.41
584.123	2792.27
588.512	3206.92
592.896	3548.35
597.279	3589.33
601.659	3196.22
606.039	2635.08
610.415	2183.54
614.789	1840.06
619.163	1649.3
623.532	1504.59
627.9	1355.09
632.267	1295.18
636.631	1190.07
640.992	1250.08
645.351	1282.3
649.71	1402.06
654.065	1534.68
658.418	1581.62
662.769	1430.4
667.12	1218.17
671.466	1002.3
675.811	820.026
680.154	750.08
684.494	651.299
688.834	631.234
693.171	618.93
697.505	601.962
701.837	595.413
706.169	630.507
710.497	617.707
714.823	601.313
719.146	569.705
723.468	535.419
727.788	519.047
732.107	503.405
736.423	500.695
740.737	507.214
745.048	488.199
749.357	480.658
753.665	470.236
757.972	490.12
762.275	466.159
766.576	449.864
770.875	438.921
775.172	419.576
779.467	427.372
783.76	424.215
788.051	386.067
792.34	383.451
796.629	370.675
800.914	376.816
805.196	359.046
809.477	360.119
813.756	372.246
818.032	353.644
822.307	361.431
826.58	361.622
830.85	360.745
835.119	360.978
839.385	378.828
843.649	375.69
847.912	384.554
852.172	372.223
856.431	389.667
860.687	403.778
864.941	453.029
869.194	429.455
873.444	425.612
877.692	399.735
881.938	402.317
886.183	403.626
890.425	398.157
894.665	401.225
898.903	411.464
903.14	449.785
907.374	456.048
911.606	470.358
915.836	518.446
920.064	595.444
924.291	677.379
928.515	800.459
932.737	964.924
936.957	1129.98
941.176	1296.38
945.392	1504.85
949.606	1729.61
953.818	2035.15
958.029	2356.02
962.237	2679.6
966.443	3181.14
970.645	3819.99
974.848	4275.16
979.048	4439.91
983.246	3900.05
987.443	3309.77
991.637	2830.24
995.83	2683.06
1000.02	2952.83
1004.21	3578.21
1008.39	4678.55
1012.58	5752.4
1016.76	6622.92
1020.94	6740.3
1025.12	6371.9
1029.29	5740.95
1033.47	5012.71
1037.64	4204.96
1041.81	3270.54
1045.98	2622.88
1050.15	2184.67
1054.31	1992.53
1058.47	2073.51
1062.64	2233.62
1066.79	2382.68
1070.95	2511.67
1075.1	2351.12
1079.26	2165.45
1083.41	1919.07
1087.56	1678.7
1091.7	1567.14
1095.85	1478.38
1099.99	1599.95
1104.13	1786.62
1108.27	1984.43
1112.41	1932.67
1116.55	1714.29
1120.68	1347.73
1124.81	1088.19
1128.94	885.532
1133.07	761.287
1137.19	652.796
1141.32	610.668
1145.44	582.934
1149.56	529.176
1153.67	466.724
1157.79	433.918
1161.9	387.571
1166.02	372.051
1170.13	353.348
1174.23	320.108
1178.34	337.331
1182.45	291.737
1186.55	272.878
1190.65	276.485
1194.75	261.565
1198.84	271.137
1202.94	265.307
1207.03	261.517
1211.12	262.821
1215.21	234.839
1219.3	232.213
1223.38	225.614
1227.47	224.107
1231.55	224.693
1235.63	224.444
1239.7	229.334
1243.78	197.217
1247.85	222.106
1251.93	225.149
1256	230.242
1260.06	243.376
1264.13	251.564
1268.19	256.811
1272.26	253.091
1276.32	232.303
1280.38	216.483
1284.43	207.634
1288.49	221.875
1292.54	195.835
1296.59	211.036
1300.64	213.131
1304.69	206.114
1308.73	201.095
1312.78	204.119
1316.82	199.007
1320.86	197.883
1324.89	202.727
1328.93	213.557
1332.96	213.303
1337	200.949
1341.03	211.612
1345.06	202.24
1349.08	210.839
1353.11	211.452
1357.13	233.925
1361.15	229.528
1365.17	259.828
1369.19	307.865
1373.2	356.825
1377.22	394.883
1381.23	355.111
1385.24	279.124
1389.25	241.643
1393.25	205.222
1397.26	199.397
1401.26	186.662
1405.26	186.718
1409.26	174.965
1413.25	173.08
1417.25	177.117
1421.24	160.424
1425.23	164.435
1429.22	164.415
1433.21	176.254
1437.2	176.243
1441.18	154.511
1445.16	157.441
1449.14	160.359
1453.12	169.166
1457.1	164.145
1461.07	165.997
1465.05	156.968
1469.02	172.523
1472.99	160.57
1476.95	164.319
1480.92	166.077
1484.88	159.012
1488.85	162.703
1492.81	172.252
1496.77	163.262
1500.72	156.256
1504.68	152.212
1508.63	169.598
1512.58	179.204
1516.53	162.598
1520.48	170.285
1524.42	177.977
1528.37	165.315
1532.31	176.916
1536.25	168.164
1540.19	176.863
1544.12	176.841
1548.06	173.912
1551.99	188.422
1555.92	172.88
1559.85	180.557
1563.78	170.789
1567.7	172.619
1571.63	187.963
1575.55	183.002
1579.47	187.691
1583.39	201.046
1587.31	188.352
1591.22	199.739
1595.13	208.217
1599.05	192.658
1602.96	205.944
1606.86	221.162
1610.77	215.272
1614.67	208.445
1618.58	236.14
1622.48	226.456
1626.38	214.898
1630.27	231.129
1634.17	225.418
1638.06	233.1
1641.95	241.8
1645.84	222.774
1649.73	240.182
1653.62	216.368
1657.5	222.267
1661.39	207.989
1665.27	208.074
1669.15	221.594
1673.02	220.63
1676.9	205.231
1680.77	195.5
1684.65	193.409
1688.52	188.428
1692.39	182.462
1696.25	190.831
1700.12	191.504
1703.98	181.646
1707.84	165.122
1711.7	174.271
1715.56	164.428
1719.42	161.253
1723.27	176.028
1727.13	153.053
1730.98	158.346
1734.83	157.062
1738.68	156.703
1742.52	161.925
1746.37	162.475
1750.21	162.191
1754.05	164.752
1757.89	164.618
1761.73	162.897
1765.56	161.999
1769.4	150.006
1773.23	154.807
1777.06	160.554
1780.89	148.66
1784.71	147.025
1788.54	148.206
1792.36	148.461
1796.18	147.783
1800	149.915
1803.82	147.255
1807.64	142.69
1811.45	155.069
1815.27	141.97
1819.08	159.934
1822.89	152.384
1826.7	157.07
1830.5	154.167
1834.31	156.881
1838.11	142.618
1841.91	151.871
1845.71	149.796
1849.51	156.186
1853.3	163.424
1857.1	148.159
1860.89	150.631
1864.68	160.517
1868.47	154.591
1872.26	157.971
1876.04	153.048
1879.83	156.462
1883.61	159.009
1887.39	162.478
1891.17	155.998
1894.95	152.293
1898.72	161.469
1902.5	151.388
1906.27	161.587
1910.04	170.891
1913.81	168.285
1917.58	161.994
1921.34	171.506
1925.1	171.808
1928.87	164.717
1932.63	165.981
1936.38	174.701
1940.14	150.774
1943.9	156.682
1947.65	171.986
1951.4	169.373
1955.15	171.38
1958.9	171.422
1962.65	171.405
1966.39	166.682
1970.14	184.438
1973.88	188.971
1977.62	168.162
1981.36	175.442
1985.09	179.869
1988.83	172.132
1992.56	181.159
1996.29	184.538
2000.02	188.797
2003.75	175.453
2007.48	175.082
2011.21	185.729
2014.93	197.252
2018.65	190.461
2022.37	191.129
2026.09	195.574
2029.81	189.958
2033.52	174.362
2037.23	201.861
2040.95	193.64
2044.66	195.477
2048.37	191.821
2052.07	205.604
2055.78	199.253
2059.48	194.827
2063.18	192.352
2066.88	190.837
2070.58	190.254
2074.28	203.517
2077.97	194.65
2081.67	207.072
2085.36	196.311
2089.05	209.446
2092.74	203.904
2096.43	201.245
2100.11	195.763
2103.8	216.25
2107.48	201.359
2111.16	209.686
2114.84	204.988
2118.51	200.267
2122.19	197.329
2125.86	199.918
2129.54	202.47
2133.21	203.145
2136.88	193.637
2140.55	211.811
2144.21	208.702
2147.87	207.429
2151.54	206.156
2155.2	206.728
2158.86	193.577
2162.52	216.133
2166.17	212.191
2169.83	204.65
2173.48	209.96
2177.13	204.388
2180.78	207.948
2184.43	208.769
2188.08	196.908
2191.72	212.417
2195.36	197.986
2199.01	209.09
2202.65	205.647
2206.29	204.967
2209.92	209.807
2213.56	205.533
2217.19	209.511
2220.82	205.241
2224.45	200.969
2228.08	203.118
2231.71	207.123
2235.33	213.006
2238.96	209.647
2242.58	198.855
2246.2	205.663
2249.82	210.641
2253.44	209.137
2257.06	220.713
2260.67	207.083
2264.28	208.364
2267.9	210.608
2271.5	211.968
2275.11	197.27
2278.72	211.701
2282.32	208.097
2285.93	203.531
2289.53	210.3
2293.13	204.755
2296.73	215.295
2300.32	213.547
2303.92	212.709
2307.52	217.511
2311.11	215.648
2314.7	209.961
2318.29	226.984
2321.88	206.999
2325.46	225.72
2329.05	208.45
2332.63	216.69
2336.21	211.678
2339.79	207.593
2343.37	203.498
2346.95	210.651
2350.52	214.016
2354.09	201.464
2357.67	218.806
2361.24	204.404
2364.81	218.865
2368.37	214.732
2371.94	210.665
2375.5	225.086
2379.07	208.086
2382.63	215.123
2386.19	218.479
2389.74	209.919
2393.3	210.599
2396.85	213.175
2400.41	213.986
2403.96	216.746
2407.51	216.788
2411.06	215.084
2414.61	218.94
2418.15	213.665
2421.7	220.374
2425.24	210.566
2428.78	210.011
2432.32	220.595
2435.86	222.928
2439.39	216.934
2442.93	221.172
2446.46	216.1
2449.99	223.214
2453.52	222.896
2457.05	215.852
2460.58	218.011
2464.1	225.807
2467.63	237.202
2471.15	227.076
2474.67	227.913
2478.19	226.809
2481.71	227.632
2485.22	228.371
2488.74	222.384
2492.25	228.738
2495.77	231.205
2499.28	218.748
2502.78	227.774
2506.29	227.39
2509.8	216.706
2513.3	227.473
2516.8	227.11
2520.31	235.137
2523.81	226.311
2527.3	237.156
2530.8	226.794
2534.3	244.175
2537.79	233.003
2541.28	240.343
2544.77	244.108
2548.26	237.826
2551.75	228.772
2555.24	234.565
2558.72	248.834
2562.2	222.306
2565.68	246.007
2569.16	228.868
2572.64	226.66
2576.12	230.107
2579.6	220.456
2583.07	238.107
2586.54	229.379
2590.01	230.029
2593.48	228.659
2596.95	225.333
2600.42	226.836
2603.88	252.262
2607.35	228.735
2610.81	244.31
2614.27	237.64
2617.73	227.217
2621.19	239.751
2624.64	240.709
2628.1	242.56
2631.55	253.972
2635	248.038
2638.45	242.997
2641.9	249.411
2645.35	242.373
2648.79	239.158
2652.24	243.522
2655.68	242.099
2659.12	238.731
2662.56	241.982
2666	257.476
2669.44	253.096
2672.87	249.662
2676.31	241.593
2679.74	244.83
2683.17	235.959
2686.6	245.862
2690.03	259.629
2693.45	258.567
2696.88	253.724
2700.3	257.321
2703.73	257.206
2707.15	251.514
2710.57	248.795
2713.98	252.639
2717.4	258.401
2720.81	251.175
2724.23	249.566
2727.64	241.435
2731.05	250.132
2734.46	264.451
2737.87	259.121
2741.27	272.532
2744.68	250.234
2748.08	263.569
2751.48	249.658
2754.88	269.58
2758.28	263.133
2761.68	270.816
2765.08	268.068
2768.47	271.873
2771.86	261.497
2775.25	267.118
2778.64	277.4
2782.03	261.272
2785.42	273.371
2788.81	264.755
2792.19	254.26
2795.58	271.949
2798.96	264.271
2802.34	272.506
2805.71	277.918
2809.09	278.633
2812.47	286.818
2815.84	289.361
2819.22	280.684
2822.59	277.664
2825.96	284.948
2829.33	289.448
2832.69	285.596
2836.06	283.663
2839.42	285.506
2842.79	288.336
2846.15	267.005
2849.51	296.108
2852.87	287.06
2856.22	295.711
2859.58	291.323
2862.93	290.708
2866.29	304.163
2869.64	298.884
2872.99	302.027
2876.34	291.06
2879.68	308.305
2883.03	302.015
2886.38	307.95
2889.72	303.502
2893.06	309.425
2896.4	295.427
2899.74	316.365
2903.08	311.726
2906.41	317.453
2909.75	312.746
2913.08	319.369
2916.41	318.4
2919.74	314.546
2923.07	327.699
2926.4	327.578
2929.72	328.355
2933.05	334.759
2936.37	336.383
2939.69	352.148
2943.01	353.757
2946.33	343.136
2949.65	347.594
2952.97	357.672
2956.28	345.202
2959.6	364.724
2962.91	347.663
2966.22	362.529
2969.53	359.674
2972.84	365.332
2976.14	367.247
2979.45	378.612
2982.75	382.427
2986.05	402.226
2989.36	388.256
2992.65	392.136
2995.95	399.799
2999.25	401.849
3002.54	412.36
3005.84	427.583
3009.13	433.443
3012.42	439.332
3015.71	436.756
3019	446.422
3022.29	459.865
3025.57	451.616
3028.86	487.749
3032.14	484.227
3035.42	499.584
3038.7	507.375
3041.98	498.146
3045.26	495.543
3048.54	525.143
3051.81	525.398
3055.08	537.043
3058.36	551.523
3061.63	581.014
3064.9	580.24
3068.16	579.394
3071.43	619.243
3074.7	622.456
3077.96	619.682
3081.22	643.233
3084.48	641.746
3087.74	652.557
3091	677.815
3094.26	713.647
3097.51	729.542
3100.77	728.804
3104.02	746.933
3107.27	778.754
3110.52	787.655
3113.77	787.732
3117.02	802.161
3120.26	819.476
3123.51	857.753
3126.75	871.261
3129.99	910.474
3133.24	920.171
3136.47	944.141
3139.71	984.273
3142.95	990.077
3146.19	1018.77
3149.42	1043.72
3152.65	1064.89
3155.88	1094.6
3159.11	1105.27
3162.34	1131.17
3165.57	1179.99
3168.8	1199.12
3172.02	1236.29
3175.24	1287.72
3178.46	1303.73
3181.69	1343.57
3184.9	1343.36
3188.12	1382.09
3191.34	1393.11
3194.55	1458.44
3197.77	1473.22
3200.98	1494.63
3204.19	1510.37
3207.4	1578.5
3210.61	1593.38
3213.82	1640.72
3217.02	1643.44
3220.23	1668.05
3223.43	1726.96
3226.63	1745.14
3229.83	1755.74
3233.03	1824.53
3236.23	1823.74
3239.43	1866.19
3242.62	1916.39
3245.82	1983.88
3249.01	1984.71
3252.2	2016.26
3255.39	2079.38
3258.58	2085.26
3261.77	2147.19
3264.95	2183.06
3268.14	2192.84
3271.32	2220.55
3274.5	2281.55
3277.68	2261.33
3280.86	2300.81
3284.04	2317.88
3287.22	2344.53
3290.39	2357.59
3293.57	2351.78
3296.74	2397.32
3299.91	2428.56
3303.08	2429.9
3306.25	2438.21
3309.42	2422.51
3312.59	2454.91
3315.75	2430.14
3318.91	2500.22
3322.08	2492.36
3325.24	2512
3328.4	2525.95
3331.56	2589.1
3334.71	2594.7
3337.87	2605.23
3341.02	2628.21
3344.18	2743.64
3347.33	2745.57
3350.48	2797.22
3353.63	2820.52
3356.78	2846.99
3359.92	2905.65
3363.07	2949.6
3366.21	3017.2
3369.36	3033.13
3372.5	3110.53
3375.64	3110.94
3378.78	3154.94
3381.92	3277.57
3385.05	3320.75
3388.19	3389.81
3391.32	3459.93
3394.46	3571.68
3397.59	3687.26
3400.72	3759.56
3403.85	3845.6
3406.97	3926.48
3410.1	3951.65
3413.22	3929.17
3416.35	3928.57
3419.47	3870.49
3422.59	3833.91
3425.71	3842.32
3428.83	3765.06
3431.95	3768.41
3435.06	3758.59
3438.18	3719.24
3441.29	3763.4
3444.41	3796.02
3447.52	3728.63
3450.63	3794.68
3453.73	3853.43
3456.84	3858.69
3459.95	3941.42
3463.05	3931.71
3466.16	3972.16
3469.26	4114.46
3472.36	4197.85
3475.46	4265.33
3478.56	4246.82
3481.65	4301.35
3484.75	4240.61
3487.84	4237.86
3490.94	4197.99
3494.03	4181.03
3497.12	4069.58
3500.21	4013.55
3503.3	3940.72
3506.39	3823.91
3509.47	3777.88
3512.55	3648.8
3515.64	3585.44
3518.72	3478.96
3521.8	3300.46
3524.88	3144.8
3527.96	3069.29
3531.04	2910.09
3534.11	2830.44
3537.19	2717.32
3540.26	2633.72
3543.33	2537.16
3546.4	2548.64
3549.47	2413.66
3552.54	2411.2
3555.61	2362.15
3558.67	2336.17
3561.74	2337.65
3564.8	2264.73
3567.86	2170.56
3570.92	2078.93
3573.98	1998.54
3577.04	1920.12
3580.1	1837.73
3583.15	1803.56
3586.21	1736.03
3589.26	1734.88
3592.31	1737.3
3595.37	1690.4
3598.41	1674.63
3601.46	1596.36
3604.51	1567.22
3607.56	1537.98
3610.6	1504.97
3613.64	1475.7
3616.69	1444.52
3619.73	1405.9
3622.77	1373.98
3625.81	1343.09
3628.84	1317.02
3631.88	1277.72
3634.91	1230.86
3637.95	1211.63
3640.98	1165.3
3644.01	1111.58
3647.04	1096.74
3650.07	1035.47
3653.1	971.57
3656.13	916.76
3659.15	863.108
3662.17	813.036
3665.2	788.177
3668.22	759.146
3671.24	718.019
3674.26	699.527
3677.28	640.466
3680.29	613.485
3683.31	574.149
3686.32	552.742
3689.33	501.046
3692.35	484.332
3695.36	484.658
3698.37	464.977
3701.37	430.199
3704.38	424.8
3707.39	410.84
3710.39	413.921
3713.4	404.613
3716.4	368.609
3719.4	381.139
3722.4	375.542
3725.4	351.82
3728.39	345.199
3731.39	340.456
3734.38	322.348
3737.38	319.441
3740.37	317.459
3743.36	320.197
3746.35	326.71
3749.34	303.716
3752.33	304.475
3755.32	291.938
3758.3	297.45
3761.28	292.518
3764.27	279.039
3767.25	269.374
3770.23	277.721
3773.21	273.79
3776.19	286.899
3779.16	271.666
3782.14	251.738
3785.11	261.101
3788.09	258.201
3791.06	258.149
3794.03	258.139
3797	253.431
3799.97	254.401
3802.94	258.239
3805.9	258.314
3808.87	254.618
3811.83	235.813
3814.8	236.856
3817.76	243.581
3820.72	242.751
3823.68	251.395
3826.63	234.486
3829.59	241.26
3832.55	230.967
3835.5	230.174
3838.45	229.393
3841.41	235.265
3844.36	241.143
3847.31	237.516
3850.26	238.656
3853.2	232.185
3856.15	221.889
3859.09	227.816
3862.04	222.284
3864.98	228.211
3867.92	235.106
3870.86	232.407
3873.8	233.534
3876.74	217.378
3879.68	224.223
3882.61	212.798
3885.55	230.168
3888.48	208.119
3891.41	235.087
3894.34	235.127
3897.27	212.056
3900.2	217.81
3903.13	222.596
3906.06	220.622
3908.98	214.831
3911.91	223.436
3914.83	218.566
3917.75	219.445
3920.67	217.484
3923.59	212.6
3926.51	211.535
3929.43	220.037
3932.34	212.23
3935.26	215.017
3938.17	219.762
3941.08	218.802
3944	219.736
3946.91	205.363
3949.81	208.245
3952.72	213.058
3955.63	207.347
3958.54	225.601
3961.44	206.504
3964.34	210.411
3967.25	205.702
3970.15	216.35
3973.05	212.617
3975.95	206.954
3978.84	211.841
3981.74	212.872
3984.63	208.133
3987.53	218.765
3990.42	197.656
3993.32	212.107
3996.21	213.132
3999.1	194.904
4001.98	202.671
4004.87	197.926
4007.76	197.041
4010.64	201.941
4013.53	194.307
4016.41	202.103
4019.29	200.254
4022.17	199.369
4025.05	188.824
4027.93	189.871
4030.81	194.786
4033.68	199.711
4036.56	187.226
4039.43	189.258
4042.3	180.633
4045.18	173.908
4048.05	203.047
4050.92	187.619
4053.78	193.527
4056.65	184.902
4059.52	191.799
4062.38	187.036
4065.24	195.878
4068.11	190.139
4070.97	194.122
4073.83	182.532
4076.69	185.535
4079.55	171.002
4082.4	173.026
4085.26	187.731
4088.11	178.049
4090.97	165.43
4093.82	179.177
4096.67	175.338
4099.52	177.37
4102.37	175.488
4105.22	176.533
4108.06	176.579
4110.91	175.649
4113.76	172.74
4116.6	175.685
4119.44	167.84
4122.28	174.677
4125.12	160.005
4127.96	176.653
4130.8	169.86
4133.64	165.045
4136.47	164.196
4139.31	159.225
4142.14	158.034
4144.97	154.103
4147.81	157.089
4150.64	159.111
4153.47	160.119
4156.29	160.09
4159.12	159.015
4161.95	159.952
4164.77	163.846
4167.59	163.824
4170.42	152.074
4173.24	154.025
4176.06	161.849
4178.88	165.76
4181.7	149.147
4184.51	154.055
4187.33	153.104
4190.14	152.156
4192.96	139.486
4195.77	159.136
4198.58	151.394
4201.39	150.501
4204.2	149.613
4207.01	151.663
4209.82	141.931
4212.62	148.891
4215.43	148.973
4218.23	146.19
4221.04	147.336
4223.84	146.497
4226.64	146.624
4229.44	140.846
4232.24	134.071
4235.03	133.242
4237.83	147.298
4240.63	137.556
4243.42	146.689
4246.21	145.896
4249	146.089
4251.8	146.269
4254.59	143.446
4257.37	139.602
4260.16	131.74
4262.95	144.929
4265.73	145.1
4268.52	135.228
4271.3	131.369
4274.08	140.599
4276.87	141.749
4279.65	139.852
4282.43	131.878
4285.2	135.002
4287.98	142.159
4290.76	141.21
4293.53	135.19
4296.3	138.302
4299.08	134.333
4301.85	141.504
4304.62	135.488
4307.39	137.587
4310.16	134.616
4312.92	132.671
4315.69	125.617
4318.46	125.666
4321.22	131.815
4323.98	110.466
4326.75	126.78
4329.51	120.697
4332.27	118.674
4335.02	124.808
4337.78	129.911
4340.54	133.003
4343.29	125.903
4346.05	123.91
4348.8	119.887
4351.56	121.986
4354.31	124.12
4357.06	122.155
4359.81	120.187
4362.55	105.928
4365.3	124.433
4368.05	110.16
4370.79	115.363
4373.54	107.214
4376.28	110.345
4379.02	113.469
4381.76	115.566
4384.5	125.893
4387.24	116.721
4389.98	115.815
4392.72	122.141
4395.45	121.354
4398.19	120.475
4400.92	114.409
4403.65	117.646
4406.38	121.935
4409.11	116.888
4411.84	112.856
4414.57	110.881
4417.3	105.771
4420.02	117.291
4422.75	122.586
4425.47	105.972
4428.2	115.455
4430.92	112.405
4433.64	111.44
4436.36	101.044
4439.08	122.062
4441.8	115.837
4444.51	114.852
4447.23	122.253
4449.94	113.913
4452.66	108.707
4455.37	111.901
4458.08	116.137
4460.79	122.472
4463.5	112.001
4466.21	117.301
4468.92	106.824
4471.62	119.508
4474.33	109.038
4477.03	117.541
4479.74	110.24
4482.44	111.382
4485.14	118.864
4487.84	109.431
4490.54	113.735
4493.24	106.372
4495.94	107.455
4498.63	104.324
4501.33	109.66
4504.02	111.811
4506.71	99.132
4509.41	114.023
4512.1	114.071
4514.79	105.63
4517.48	101.432
4520.16	103.61
4522.85	103.675
4525.54	98.4196
4528.22	106.996
4530.91	104.934
4533.59	96.4755
4536.27	99.7432
4538.95	109.424
4541.63	108.444
4544.31	98.9057
4546.99	103.268
4549.66	104.425
4552.34	95.9465
4555.02	103.566
4557.69	99.3979
4560.36	99.5533
4563.03	104.039
4565.7	97.772
4568.37	92.5872
4571.04	96.0028
4573.71	96.0624
4576.38	99.3366
4579.04	100.49
4581.71	98.4253
4584.37	99.6423
4587.03	92.0851
4589.69	94.3263
4592.36	102.016
4595.02	99.8948
4597.67	92.3209
4600.33	94.566
4602.99	89.1737
4605.64	90.3492
4608.3	94.816
4610.95	94.9042
4613.6	84.0075
4616.26	97.2708
4618.91	86.3603
4621.56	87.5472
4624.2	93.142
4626.85	88.8105
4629.5	89.9883
4632.14	84.5345
4634.79	89.012
4637.43	85.7441
4640.07	90.2203
4642.72	78.0882
4645.36	96.9968
4648	88.2233
4650.63	90.5627
4653.27	79.5858
4655.91	86.3757
4658.54	84.1612
4661.18	86.4702
4663.81	82.097
4666.45	88.884
4669.08	86.7102
4671.71	77.8223
4674.34	81.2453
4676.97	86.9159
4679.59	82.4922
4682.22	85.9218
4684.85	75.8688
4687.47	68.0507
4690.09	81.6093
4692.72	72.6597
4695.34	80.5997
4697.96	84.0371
4700.58	78.4507
4703.2	84.1495
4705.82	70.6348
4708.43	84.2414
4711.05	77.4949
4713.66	74.1365
4716.28	85.4923
4718.89	80.9944
4721.5	84.4225
4724.11	81.0475
4726.72	74.2791
4729.33	70.9128
4731.94	77.7604
4734.55	76.665
4737.15	76.7016
4739.76	77.8704
4742.36	76.7629
4744.97	76.7858
4747.57	72.252
4750.17	74.5338
4752.77	76.8183
4755.37	76.8256
4757.97	81.3853
4760.56	80.2618
4763.16	74.5886
4765.76	83.7253
4768.35	76.9326
4770.94	72.4196
4773.54	59.8998
4776.13	77.048
4778.72	69.089
4781.31	73.6888
4783.9	73.7216
4786.48	73.7553
4789.07	62.3492
4791.66	74.9709
4794.24	65.85
4796.83	75.0553
4799.41	71.6667
4801.99	75.1632
4804.57	70.6322
4807.15	68.4011
4809.73	71.925
4812.31	73.1513
4814.88	70.9248
4817.46	69.8528
4820.04	73.4077
4822.61	72.3414
4825.18	67.797
4827.76	71.3622
4830.33	67.9666
4832.9	64.5692
4835.47	68.1549
4838.04	68.2594
4840.6	66.0329
4843.17	68.4789
4845.74	66.231
4848.3	68.6647
4850.86	68.7331
4853.43	64.0544
4855.99	71.1406
4858.55	70.0683
4861.11	73.7053
4863.67	74.9697
4866.23	67.9392
4868.78	60.9013
4871.34	69.2537
4873.89	58.6483
4876.45	69.3615
4879	63.4787
4881.55	69.4567
4884.1	68.3098
4886.66	61.2176
4889.2	67.2019
4891.75	60.1022
4894.3	66.0908
4896.85	68.5095
4899.39	62.584
4901.94	64.9998
4904.48	63.8374
4907.02	65.0586
4909.57	67.4727
4912.11	66.2898
4914.65	56.7398
4917.19	60.323
4919.73	65.1079
4922.26	61.5303
4924.8	62.7322
4927.33	69.9145
4929.87	62.7472
4932.4	61.5719
4934.93	62.7999
4937.47	62.8253
4940	62.8495
4942.53	59.2546
4945.05	58.0754
4947.58	59.3011
4950.11	65.3198
4952.64	56.96
4955.16	58.1824
4957.68	65.4185
4960.21	57.0542
4962.73	58.2999
4965.25	58.3608
4967.77	62.0475
4970.29	60.9003
4972.81	58.5409
4975.33	57.3837
4977.84	51.3869
4980.36	52.6433
4982.88	68.438
4985.39	60.0158
4987.9	63.7149
4990.41	58.9189
4992.93	62.6229
4995.44	60.2466
4997.95	62.7496