File: Data/3-Raman/raw/bu32-b-ff2-fi04-v_1800 (450-850nm)_532nm_edge_100%_x100_vis_lwd_h30um_30sx2_01.txt
#Acq. time (s)=	30
#Accumulations=	2
#Range (cm-¹)=	1200...2999
#Windows=	5
#Auto scanning=	Off
#Autofocus=	Off
#Macrospot=	Off
#AutoExposure=	Off
#Spike filter=	Multiple accum.
#Delay time (s)=	2
#Binning=	1
#Readout mode=	Signal
#DeNoise=	Off
#ICS correction=	On
#Dark correction=	Off
#Inst. Process=	Off
#Detector Gain=	Best Dynamic
#Detector ADC=	50 kHz EM
#Detector EM gain=	150
#Detector temperature (°C)=	-60.09
#Instrument=	LabRAM HR Evol
#Detector=	SIN-EM FIVIS
#Objective=	x100_VIS_LWD
#Grating=	1800 (450-850nm)
#ND Filter=	100%
#Laser=	532nm_Edge
#Hole=	30.0125
#Temperature=	40
#Range=	Visible
#StageXY=	75x50mm Scan+
#StageZ=	Z motor
#X (µm)=	0
#Y (µm)=	0
#Z (µm)=	71.2
#Full time(mm:ss)=	5:34
#Project=	21_08_11
#Sample=	BU32
#Site=
#Title=	BU32-B-FF2-FI04-V_1800 (450-850nm)_532nm_Edge_100%_x100_VIS_LWD_H30um_30sX2
#Remark=
#Date=	13.08.2021 15:57
#Acquired=	13.08.2021 15:57:04
1200.05	337.31
1201.44	332.198
1202.83	337.013
1204.22	331.137
1205.61	328.362
1207	329.825
1208.39	332.646
1209.78	331.34
1211.16	328.608
1212.55	334.459
1213.94	333.235
1215.33	328.928
1216.71	321.979
1218.1	334.312
1219.49	329.873
1220.87	333.996
1222.26	321.757
1223.64	325.319
1225.03	330.428
1226.41	326.19
1227.79	329.49
1229.18	322.973
1230.56	320.079
1231.94	326.756
1233.33	323.553
1234.71	323.741
1236.09	323.798
1237.47	331.74
1238.86	325.009
1240.24	316.56
1241.62	326.949
1243	329.156
1244.38	332.269
1245.76	325.559
1247.14	323.399
1248.52	326.321
1249.9	331.486
1251.27	325.921
1252.65	324.567
1254.03	318.443
1255.41	327.884
1256.79	323.798
1258.16	335.122
1259.54	323.773
1260.92	333.79
1262.29	326.953
1263.67	355.438
1265.04	352.194
1266.42	325.074
1267.79	329.76
1269.17	330.042
1270.54	326.523
1271.92	330.825
1273.29	335.495
1274.66	327.261
1276.04	330.691
1277.41	329.991
1278.78	321.915
1280.15	330.258
1281.53	336.83
1282.9	381.611
1284.27	793.441
1285.64	391.744
1287.01	338.963
1288.38	334.679
1289.75	336.034
1291.12	323.338
1292.49	330.681
1293.86	333.234
1295.23	333.573
1296.6	319.191
1297.96	328.447
1299.33	330.388
1300.7	324.133
1302.07	321.124
1303.43	333.671
1304.8	333.586
1306.17	330.094
1307.53	326.961
1308.9	324.965
1310.26	321.855
1311.63	321.982
1312.99	328.32
1314.36	328.317
1315.72	322.142
1317.08	329.534
1318.45	338.07
1319.81	327.501
1321.17	336.679
1322.53	331.113
1323.9	327.927
1325.26	330.9
1326.62	327.261
1327.98	323.761
1329.34	324.947
1330.7	325.714
1332.06	333.567
1333.42	322.526
1334.78	329.489
1336.14	331.318
1337.5	324.827
1338.86	325.643
1340.22	327.799
1341.58	327.676
1342.93	326.316
1344.29	322.1
1345.65	329.008
1347	327.405
1348.36	333.45
1349.72	320.654
1351.07	320.307
1352.43	320.463
1353.78	324.526
1355.14	321.953
1356.49	325.086
1357.85	326.929
1359.2	312.138
1360.56	314.903
1361.91	321.013
1363.26	309.687
1364.61	322.054
1365.97	317.553
1367.32	314.197
1368.67	327.751
1370.02	337.927
1371.37	319.946
1372.72	316.431
1374.07	321.44
1375.42	330.69
1376.77	324.131
1378.12	318.522
1379.47	320.5
1380.82	322.975
1382.17	331.583
1383.52	338.319
1384.87	332.48
1386.21	390.317
1387.56	1230.38
1388.91	406.588
1390.26	343.529
1391.6	342.122
1392.95	331.629
1394.3	333.561
1395.64	325.514
1396.99	330.41
1398.33	330.451
1399.68	318.315
1401.02	331.814
1402.37	320.135
1403.71	330.348
1405.05	325.077
1406.39	323.892
1407.74	331.182
1409.08	379.525
1410.42	334.174
1411.76	327.865
1413.11	319.372
1414.45	322.357
1415.79	318.333
1417.13	321.598
1418.47	324.747
1419.81	318.395
1421.15	322.29
1422.49	330.197
1423.83	324.823
1425.17	327.1
1426.51	320.877
1427.84	320.472
1429.18	320.607
1430.52	312.853
1431.86	319.086
1433.19	320.63
1434.53	334.056
1435.87	310.443
1437.2	311.351
1438.54	321.682
1439.87	310.677
1441.21	328.098
1442.54	312.794
1443.88	314.718
1445.21	312.898
1446.55	316.884
1447.88	314.774
1449.21	314.822
1450.55	316.698
1451.88	318.623
1453.21	312.576
1454.54	315.611
1455.88	315.687
1457.21	320.643
1458.54	314.528
1459.87	320.651
1461.2	322.522
1462.53	315.054
1463.86	319.208
1465.19	317.433
1466.52	318.27
1467.85	314.177
1469.18	314.042
1470.51	308.707
1471.83	317.698
1473.16	312.484
1474.49	310.432
1475.82	318.477
1477.14	310.175
1478.47	314.058
1479.79	313.719
1481.12	318.564
1482.45	315.75
1483.77	307.579
1485.1	312.355
1486.42	311.04
1487.75	310.871
1489.07	311.62
1490.39	307.457
1491.72	309.38
1493.04	312.36
1494.36	317.448
1495.69	309.98
1497.01	317.925
1498.33	312.869
1499.65	310.953
1500.97	309.836
1502.29	314.758
1503.62	311.591
1504.93	308.508
1506.26	307.265
1507.58	308.34
1508.89	316.4
1510.21	308.288
1511.53	304.691
1512.85	305.197
1514.17	309.375
1515.49	307.968
1516.81	310.813
1518.12	307.924
1519.44	307.006
1520.76	309.034
1522.07	309.953
1523.39	304.577
1524.71	309.452
1526.02	300.682
1527.34	309.651
1528.65	309.513
1529.97	305.439
1531.28	305.608
1532.59	310.791
1533.91	314.978
1535.22	314.705
1536.54	308.2
1537.85	307.932
1539.16	303.295
1540.47	306.889
1541.79	313.527
1543.1	311.142
1544.41	307.186
1545.72	307.533
1547.03	301.625
1548.34	312.578
1549.65	307.227
1550.96	311.279
1552.27	301.301
1553.58	319.937
1554.89	309.533
1556.2	310.508
1557.5	310.509
1558.81	302.046
1560.12	305.818
1561.43	309.926
1562.74	299.023
1564.04	304.232
1565.35	307.318
1566.65	306.835
1567.96	307.958
1569.27	305.783
1570.57	305.807
1571.88	309.633
1573.18	306.39
1574.48	301.655
1575.79	301.79
1577.09	301.356
1578.4	307.055
1579.7	310.126
1581	303.033
1582.3	309.807
1583.61	301.764
1584.91	310.773
1586.21	305.565
1587.51	307.428
1588.81	307.604
1590.11	301.726
1591.41	306.692
1592.72	306.313
1594.01	293.995
1595.31	301.954
1596.61	305.94
1597.91	306.92
1599.21	303.62
1600.51	306.201
1601.81	298.917
1603.1	301.329
1604.4	296.551
1605.7	305.965
1607	301.307
1608.29	301.573
1609.59	301.087
1610.88	305.439
1612.18	301.731
1613.48	301.849
1614.77	301.018
1616.07	297.998
1617.36	299.027
1618.65	305.84
1619.95	299.275
1621.24	303.844
1622.54	300.454
1623.83	296.725
1625.12	302.237
1626.41	297.785
1627.56	303.505
1628.87	301.524
1630.17	301.424
1631.48	303.518
1632.79	310.481
1634.1	303.59
1635.4	308.45
1636.71	298.392
1638.01	294.323
1639.32	307.115
1640.62	294.428
1641.93	304.182
1643.23	302.161
1644.54	298.081
1645.84	308.956
1647.15	301.926
1648.45	293.225
1649.75	300.244
1651.05	300.555
1652.36	298.558
1653.66	303.516
1654.96	299.764
1656.26	300.081
1657.56	299.007
1658.86	306.703
1660.16	297.787
1661.46	295.088
1662.77	298.462
1664.07	303.086
1665.36	294.338
1666.66	299.872
1667.96	302.858
1669.26	303.244
1670.56	302.485
1671.86	297.538
1673.15	307.46
1674.45	297.766
1675.75	299.858
1677.05	300.852
1678.34	303.562
1679.64	301.431
1680.94	294.401
1682.23	297.367
1683.53	300.297
1684.82	300.189
1686.12	305.193
1687.41	300.251
1688.71	308.924
1690	299.863
1691.29	301.013
1692.59	298.901
1693.88	301.498
1695.17	309.343
1696.47	299.583
1697.76	299.264
1699.05	300.109
1700.34	303.007
1701.63	294.954
1702.92	297.728
1704.21	297.746
1705.5	297.698
1706.79	297.361
1708.08	297.889
1709.37	294.661
1710.66	300.635
1711.95	299.664
1713.24	293.196
1714.53	300.822
1715.82	296.016
1717.11	295.547
1718.39	293.084
1719.68	293.087
1720.97	297.697
1722.25	297.332
1723.54	293.252
1724.83	296.807
1726.11	298.485
1727.4	303.223
1728.68	298.2
1729.97	295.447
1731.25	295.737
1732.54	296.551
1733.82	293.155
1735.1	291.744
1736.39	290.593
1737.67	289.412
1738.95	290.022
1740.24	286.586
1741.52	292.044
1742.8	290.024
1744.08	286.951
1745.36	285.973
1746.65	293.278
1747.93	290.184
1749.21	288.418
1750.49	294.423
1751.77	292.301
1753.05	294.857
1754.33	288.868
1755.6	287.683
1756.88	292.037
1758.16	286.412
1759.44	289.283
1760.72	285.311
1762	292.788
1763.27	291.914
1764.55	290.296
1765.83	288.475
1767.1	289.338
1768.38	287.254
1769.66	288.681
1770.93	288.976
1772.21	292.072
1773.48	286.53
1774.76	296.184
1776.03	295.533
1777.31	294.379
1778.58	296.923
1779.85	283.618
1781.13	286.575
1782.4	287.764
1783.67	288.915
1784.94	287.185
1786.22	288.122
1787.49	290.572
1788.76	287.343
1790.03	290.481
1791.3	294.016
1792.57	293.133
1793.84	290.352
1795.11	302.318
1796.38	301.653
1797.65	296.124
1798.92	289.373
1800.19	296.834
1801.46	297.775
1802.73	292.232
1804	292.432
1805.26	302.4
1806.53	296.841
1807.8	293.975
1809.07	294.997
1810.33	295.017
1811.6	297.899
1812.87	285.552
1814.13	290.706
1815.4	295.747
1816.66	304.504
1817.93	288.858
1819.19	298.687
1820.46	300.793
1821.72	297.129
1822.99	292.348
1824.25	294.295
1825.51	302.155
1826.77	296.399
1828.04	299.379
1829.3	296.353
1830.56	298.19
1831.82	298.395
1833.09	292.736
1834.35	293.476
1835.61	297.913
1836.87	306.184
1838.13	289.938
1839.39	298.509
1840.65	291.9
1841.91	298.077
1843.17	296.14
1844.43	291.315
1845.69	297.385
1846.94	292.689
1848.2	295.632
1849.46	288.595
1850.72	287.227
1851.97	302.473
1853.23	292.799
1854.49	300.114
1855.74	300.76
1857	295.913
1858.26	294.703
1859.51	295.414
1860.77	297.515
1862.02	298.5
1863.28	288.605
1864.53	291.199
1865.78	289.735
1867.04	281.537
1868.29	292.807
1869.54	297.516
1870.8	288.914
1872.05	298.239
1873.3	302.795
1874.56	295.824
1875.81	300.01
1877.06	286.187
1878.31	283.847
1879.56	290.673
1880.81	293.447
1882.06	289.842
1883.31	293.59
1884.56	295.169
1885.81	295.59
1887.06	293.425
1888.31	296.74
1889.56	290.868
1890.81	291.969
1892.05	288.127
1893.3	285.723
1894.55	297.806
1895.8	287.619
1897.04	289.717
1898.29	294.308
1899.54	289.35
1900.78	294.128
1902.03	285.968
1903.27	291.491
1904.52	287.667
1905.76	279.936
1907.01	293.929
1908.25	288.448
1909.5	304.76
1910.74	287.275
1911.98	291.974
1913.23	291.108
1914.47	290.539
1915.71	289.661
1916.96	298.879
1918.2	287.667
1919.44	295.714
1920.68	295.852
1921.92	290.35
1923.16	284.519
1924.41	286.254
1925.65	285.613
1926.89	292.585
1928.12	288.962
1929.36	292.107
1930.6	296.226
1931.84	292.287
1933.08	286.507
1934.32	296.99
1935.56	299.261
1936.8	292.391
1938.03	287.434
1939.27	295.321
1940.51	294.8
1941.75	292.661
1942.98	294.905
1944.22	299.815
1945.45	288.706
1946.69	297.441
1947.92	292.598
1949.16	295.663
1950.4	293.324
1951.63	289.969
1952.86	293.996
1954.1	293.284
1955.33	297.115
1956.56	293.839
1957.8	296.977
1959.03	291.136
1960.26	293.816
1961.5	296.545
1962.73	291.816
1963.96	290.002
1965.19	292.87
1966.42	307.56
1967.65	298.977
1968.88	310.346
1970.11	291.742
1971.34	301.162
1972.57	292.57
1973.8	294.263
1975.03	295.305
1976.26	294.49
1977.49	288.623
1978.72	292.337
1979.95	288.498
1981.17	295.013
1982.4	290.519
1983.63	290.498
1984.85	295.19
1986.08	297.621
1987.31	295.377
1988.53	289.192
1989.76	288.698
1990.98	289.119
1992.21	291.703
1993.43	292.826
1994.66	290.603
1995.88	289.424
1997.11	288.546
1998.33	290.485
1999.55	291.212
2000.78	289.832
2002	288.972
2003.22	291.972
2004.45	287.423
2005.59	284.46
2006.83	285.431
2008.06	289.785
2009.3	291.271
2010.54	291.972
2011.77	285.329
2013.01	288.733
2014.25	276.865
2015.48	291.066
2016.72	292.283
2017.95	284.32
2019.19	289.476
2020.42	287.513
2021.66	289.381
2022.89	282.516
2024.12	284.041
2025.36	287.329
2026.59	282.231
2027.82	285.691
2029.06	290.221
2030.29	282.416
2031.52	291.138
2032.75	288.799
2033.98	293.234
2035.21	285.892
2036.45	284.208
2037.68	285.107
2038.91	279.275
2040.14	287.327
2041.37	287.116
2042.6	282.304
2043.83	284.559
2045.05	282.671
2046.28	286.716
2047.51	284.314
2048.74	285.412
2049.97	293.304
2051.2	290.387
2052.42	289.567
2053.65	288.078
2054.88	283.393
2056.1	288.841
2057.33	282.365
2058.56	286.399
2059.78	282.694
2061.01	288.356
2062.23	285.637
2063.46	285.855
2064.68	288.878
2065.91	289.216
2067.13	289.365
2068.35	289.557
2069.58	285.494
2070.8	291.558
2072.02	291.901
2073.25	288.108
2074.47	282.664
2075.69	284.139
2076.91	290.589
2078.13	285.858
2079.35	288.089
2080.58	293.864
2081.8	288.186
2083.02	290.103
2084.24	290.107
2085.46	285.427
2086.68	290.46
2087.9	290.553
2089.12	285.969
2090.33	287.087
2091.55	296.841
2092.77	297.301
2093.99	289.029
2095.21	290.79
2096.43	292.574
2097.64	290.485
2098.86	289.459
2100.08	285.681
2101.29	296.344
2102.51	291.521
2103.73	295.219
2104.94	288.792
2106.16	291.842
2107.37	299.402
2108.59	292.435
2109.8	291.644
2111.01	290.672
2112.23	291.574
2113.44	294.656
2114.66	290.827
2115.87	291.624
2117.08	290.589
2118.29	291.241
2119.51	289.047
2120.72	290.036
2121.93	292.258
2123.14	291.461
2124.35	292.101
2125.57	284.934
2126.78	292.188
2127.99	286.413
2129.2	289.199
2130.41	294.773
2131.62	293.635
2132.82	288.743
2134.03	288.794
2135.24	290.613
2136.45	290.364
2137.66	289.505
2138.87	292.422
2140.08	288.254
2141.28	290.945
2142.49	296.621
2143.7	283.835
2144.9	294.298
2146.11	296.097
2147.32	291.228
2148.52	291.045
2149.73	291.584
2150.93	291.573
2152.14	294.478
2153.34	283.035
2154.55	286.321
2155.75	288.696
2156.96	292.413
2158.16	294.436
2159.36	285.841
2160.57	301.415
2161.77	289.205
2162.97	297.498
2164.17	288.868
2165.38	283.286
2166.58	284.985
2167.78	282.659
2168.98	283.666
2170.18	288.704
2171.38	289.199
2172.58	278.728
2173.78	285.312
2174.98	281.587
2176.18	292.626
2177.38	287.975
2178.58	290.602
2179.78	292.478
2180.98	290.55
2182.18	282.053
2183.38	283.619
2184.57	290.049
2185.77	287.456
2186.97	287.853
2188.16	289.649
2189.36	291.117
2190.56	288.346
2191.76	285.663
2192.95	283.081
2194.15	290.062
2195.34	288.016
2196.54	289.472
2197.73	287.574
2198.93	296.357
2200.12	290.49
2201.31	299.642
2202.51	281.861
2203.7	281.608
2204.89	291.198
2206.09	291.08
2207.28	290.231
2208.47	288.655
2209.67	290.577
2210.86	285.21
2212.05	290.118
2213.24	285.288
2214.43	284.696
2215.62	295.039
2216.81	288.473
2218	290.381
2219.19	296.204
2220.38	296.248
2221.57	294.084
2222.76	282.015
2223.95	293.613
2225.14	289.302
2226.33	289.607
2227.51	287.891
2228.7	290.617
2229.89	298.382
2231.08	297.779
2232.27	290.557
2233.45	293.648
2234.64	288.857
2235.82	285.901
2237.01	287.964
2238.2	296.016
2239.38	306.554
2240.57	298.125
2241.75	287.86
2242.94	291.67
2244.12	296.377
2245.3	301.56
2246.49	295.202
2247.67	290.55
2248.85	293.317
2250.04	292.371
2251.22	299.699
2252.4	291.44
2253.59	297.62
2254.77	302.461
2255.95	294.069
2257.13	293.374
2258.31	295.394
2259.49	293.678
2260.67	291.061
2261.85	295.976
2263.03	299.185
2264.21	291.137
2265.39	293.266
2266.57	302.525
2267.75	293.69
2268.93	293.87
2270.11	295.264
2271.29	290.728
2272.47	301.386
2273.64	290.952
2274.82	299.661
2276	294.123
2277.17	300.288
2278.35	296.784
2279.53	300.329
2280.71	291.424
2281.88	301.048
2283.06	296.662
2284.23	300.084
2285.41	298.286
2286.58	301.259
2287.76	291.905
2288.93	299.274
2290.1	294.171
2291.28	297.36
2292.45	293.817
2293.62	302.631
2294.8	304.341
2295.97	303.067
2297.14	296.509
2298.31	296.873
2299.49	299.037
2300.66	300.131
2301.83	298.24
2303	297.241
2304.17	301.278
2305.34	304.364
2306.51	306.402
2307.68	298.556
2308.85	302.508
2310.02	303.766
2311.19	295.572
2312.36	297.188
2313.53	293.652
2314.7	297.974
2315.87	298.507
2317.03	305.157
2318.2	295.456
2319.37	299.126
2320.54	300.175
2321.7	298.6
2322.87	305.514
2324.03	303.614
2325.2	304.18
2326.37	298.076
2327.53	318.057
2328.7	345.908
2329.86	304.375
2331.03	296.669
2332.19	296.621
2333.36	303.183
2334.52	297.168
2335.68	294.283
2336.85	297.084
2338.01	300.847
2339.17	292.201
2340.34	299.671
2341.5	300.196
2342.66	302.787
2343.82	297.053
2344.98	300.537
2346.14	298.705
2347.31	291.128
2348.47	294.944
2349.63	297.398
2350.79	291.632
2351.95	294.25
2353.11	294.762
2354.27	296.845
2355.43	295.342
2356.59	292.768
2357.74	296.387
2358.9	294.258
2360.06	292.551
2361.22	292.849
2362.38	291.832
2363.53	290.744
2364.69	288.261
2365.74	293.474
2366.92	291.976
2368.09	292.761
2369.26	291.547
2370.43	294.984
2371.6	294.773
2372.77	296.431
2373.94	291.521
2375.11	288.431
2376.28	286.396
2377.45	290.909
2378.62	293.438
2379.79	288.386
2380.96	296.729
2382.13	284.541
2383.29	287.266
2384.46	288.163
2385.63	286.036
2386.8	296.833
2387.97	288.254
2389.13	287.234
2390.3	288.146
2391.47	297.521
2392.63	289.833
2393.8	293.095
2394.96	291.146
2396.13	281.847
2397.29	295.645
2398.46	284.436
2399.62	290.046
2400.79	285.303
2401.95	287.037
2403.12	296.618
2404.28	288.769
2405.44	283.419
2406.61	289.097
2407.77	280.682
2408.93	290.881
2410.09	289.028
2411.26	283.449
2412.42	292.945
2413.58	290.205
2414.74	285.428
2415.9	284.291
2417.06	290.012
2418.22	290.239
2419.38	288.773
2420.54	292.619
2421.7	290.49
2422.86	286.113
2424.02	282.576
2425.18	293.181
2426.34	292.53
2427.5	292.69
2428.66	285.105
2429.81	281.319
2430.97	287.002
2432.13	302.453
2433.29	290.55
2434.44	289.673
2435.6	288.08
2436.76	289.259
2437.91	298.649
2439.07	294.209
2440.23	289.859
2441.38	298.433
2442.53	293.938
2443.69	297.962
2444.84	296.286
2446	287.972
2447.15	296.841
2448.31	289.287
2449.46	294.089
2450.61	292.559
2451.77	290.967
2452.92	292.863
2454.07	309.032
2455.22	293.22
2456.38	294.501
2457.53	298.467
2458.68	289.915
2459.83	289.166
2460.98	300.763
2462.14	296.936
2463.29	295.145
2464.43	294.893
2465.59	291.09
2466.74	292.916
2467.88	299.54
2469.03	307.083
2470.18	290.028
2471.33	297.849
2472.48	300.087
2473.63	294.338
2474.78	292.664
2475.92	302.826
2477.07	298.172
2478.22	295.059
2479.37	292.814
2480.51	297.29
2481.66	297.016
2482.81	297.95
2483.95	293.078
2485.1	299.767
2486.24	296.006
2487.39	289.086
2488.53	298.487
2489.68	297.437
2490.82	302.249
2491.97	292.483
2493.11	292.781
2494.25	296.338
2495.4	301.887
2496.54	297.264
2497.69	292.098
2498.83	294.261
2499.97	294.214
2501.11	296.542
2502.25	307.666
2503.4	288.591
2504.54	292.155
2505.68	295.912
2506.82	294.234
2507.96	294.286
2509.1	297.119
2510.24	296.743
2511.38	292.295
2512.52	292.146
2513.66	289.488
2514.8	295.034
2515.94	302.067
2517.08	295.895
2518.21	289.936
2519.35	298.338
2520.49	292.033
2521.63	287.398
2522.77	288.965
2523.9	296.433
2525.04	298.144
2526.18	305.078
2527.31	289.855
2528.45	289.009
2529.58	295.723
2530.72	286.252
2531.86	289.785
2532.99	283.916
2534.13	297.169
2535.26	293.237
2536.4	288.516
2537.53	288.315
2538.66	297.36
2539.8	296.153
2540.93	291.437
2542.06	299.171
2543.2	293.648
2544.33	294.366
2545.46	294.379
2546.59	295.174
2547.73	298.01
2548.86	294.417
2549.99	288.123
2551.12	296.801
2552.25	295.116
2553.38	295.926
2554.51	292.166
2555.64	294.287
2556.77	293.801
2557.9	293.919
2559.03	301.461
2560.16	301.364
2561.29	297.639
2562.42	297.813
2563.55	298.301
2564.67	297.87
2565.8	296.957
2566.93	293.226
2568.06	298.859
2569.18	289.497
2570.31	291.636
2571.44	296.906
2572.56	288.876
2573.69	298.619
2574.81	296.535
2575.94	298.731
2577.06	295.167
2578.19	298.474
2579.31	293.182
2580.44	297.244
2581.56	308.821
2582.69	294.616
2583.81	300.426
2584.94	292.97
2586.06	304.926
2587.18	294.835
2588.3	299.31
2589.43	297.502
2590.55	297.497
2591.67	299.459
2592.79	297.805
2593.91	303.939
2595.04	298.418
2596.16	302.4
2597.28	307.791
2598.4	296.051
2599.52	306.094
2600.64	301.357
2601.76	300.94
2602.88	301.881
2604	300.952
2605.12	300.09
2606.24	301.106
2607.35	295.454
2608.47	303.678
2609.59	307.746
2610.71	307.863
2611.83	297.095
2612.94	309.581
2614.06	305.882
2615.18	300.602
2616.29	302.743
2617.41	308.723
2618.53	297.13
2619.64	302.536
2620.76	297.286
2621.87	321.18
2622.99	305.73
2624.1	302.904
2625.22	305.861
2626.33	311.882
2627.45	316.892
2628.56	292.484
2629.67	306.012
2630.79	310.022
2631.9	302.348
2633.01	294.508
2634.12	306.029
2635.24	310.371
2636.35	302.153
2637.46	309.537
2638.57	298.809
2639.68	310.649
2640.8	308.072
2641.91	299.633
2643.02	299.962
2644.13	300.625
2645.24	307.156
2646.35	301.184
2647.46	304.905
2648.57	305.332
2649.67	308.038
2650.78	294.461
2651.89	302.871
2653	307.589
2654.11	303.562
2655.22	298.415
2656.32	292.635
2657.43	306.253
2658.54	294.497
2659.65	299.737
2660.75	292.019
2661.86	307.013
2662.96	297.635
2664.07	299.316
2665.18	298.253
2666.28	303.89
2667.39	303.703
2668.49	291.855
2669.6	292.721
2670.7	309.953
2671.8	296.367
2672.91	291.191
2674.01	293.795
2675.11	297.833
2676.22	294.436
2677.32	295.138
2678.42	312.94
2679.53	287.155
2680.63	300.313
2681.73	298.512
2682.83	295.217
2683.93	298.188
2685.03	294.716
2686.14	300.424
2687.24	296.84
2688.34	295.837
2689.44	299.894
2690.54	288.02
2691.64	291.678
2692.74	298.204
2693.84	289.251
2694.93	295.812
2696.03	294.855
2697.13	292.231
2698.23	291.336
2699.33	291.551
2700.43	291.605
2701.52	293.726
2702.62	291.315
2703.72	295.369
2704.81	291.816
2705.9	298.791
2707.01	289.394
2708.12	292.931
2709.23	286.468
2710.34	295.021
2711.45	293.943
2712.56	291.634
2713.67	296.434
2714.78	294.116
2715.89	287.551
2716.99	292.959
2718.1	297.674
2719.21	304.533
2720.32	293.691
2721.43	295.691
2722.54	303
2723.64	292.615
2724.75	291.043
2725.86	300.357
2726.96	308.797
2728.07	293.88
2729.18	298.678
2730.28	293.283
2731.39	302.119
2732.49	299.236
2733.6	292.388
2734.71	295.259
2735.81	301.359
2736.91	299.621
2738.02	287.323
2739.12	292.201
2740.23	298.701
2741.33	299.513
2742.43	298.966
2743.54	310.716
2744.64	303.551
2745.74	294.976
2746.84	290.01
2747.95	295.74
2749.05	297.715
2750.15	300.562
2751.25	302.73
2752.35	298.407
2753.45	294.729
2754.55	306.949
2755.66	296.372
2756.76	299.448
2757.86	298.648
2758.96	296.717
2760.05	303.342
2761.15	298.953
2762.25	292.806
2763.35	293.994
2764.45	298.073
2765.55	301.811
2766.65	300.659
2767.75	289.02
2768.84	293.76
2769.94	310.1
2771.04	292.128
2772.13	295.6
2773.23	298.514
2774.33	297.143
2775.42	299.909
2776.52	296.841
2777.61	294.905
2778.71	302.565
2779.81	299.422
2780.9	300.322
2782	292.793
2783.09	294.474
2784.18	294.233
2785.28	294.426
2786.37	298.421
2787.47	297.232
2788.56	293.972
2789.65	298.546
2790.74	295.592
2791.84	296.303
2792.93	295.51
2794.02	299.182
2795.11	288.826
2796.2	294.301
2797.3	297.961
2798.39	300.634
2799.48	303.635
2800.57	293.135
2801.66	299.671
2802.75	296.977
2803.84	302.334
2804.93	291.666
2806.02	300.238
2807.11	303.025
2808.2	301.072
2809.28	290.613
2810.37	296.169
2811.46	296.789
2812.55	301.241
2813.64	298.565
2814.73	296.538
2815.81	297.285
2816.9	301.87
2817.99	303.373
2819.07	299.404
2820.16	302.642
2821.25	298.388
2822.33	288.881
2823.42	289.643
2824.5	299.121
2825.59	290.565
2826.67	299.209
2827.76	291.889
2828.84	292.466
2829.93	303.664
2831.01	290.648
2832.09	299.802
2833.18	297.74
2834.26	299.657
2835.34	298.002
2836.43	295.353
2837.51	297.206
2838.59	292.446
2839.67	293.555
2840.75	293.139
2841.84	295.852
2842.92	298.478
2844	306.744
2845.08	295.38
2846.16	301.327
2847.24	291.233
2848.32	298.398
2849.4	305.072
2850.48	294.962
2851.56	296.957
2852.64	297.807
2853.72	296.015
2854.8	297.977
2855.87	297.991
2856.95	298.912
2858.03	295.242
2859.11	298.044
2860.19	298.058
2861.26	303.246
2862.34	295.128
2863.42	300.569
2864.49	301.332
2865.57	306.193
2866.65	292.283
2867.72	298.95
2868.8	298.412
2869.87	288.882
2870.95	297.389
2872.02	300.073
2873.1	291.642
2874.17	305.26
2875.25	304.657
2876.32	309.322
2877.4	306.517
2878.47	298.165
2879.54	298.003
2880.62	299.894
2881.69	303.042
2882.76	294.641
2883.83	309.455
2884.9	296.473
2885.98	305.225
2887.05	304.382
2888.12	303.774
2889.19	300.121
2890.26	293.42
2891.33	292.425
2892.4	292.538
2893.47	303.244
2894.54	305.732
2895.61	303.425
2896.68	292.839
2897.75	296.692
2898.82	303.412
2899.89	296.986
2900.96	298.947
2902.03	306.488
2903.09	311.316
2904.16	305.854
2905.23	300.257
2906.3	306.652
2907.36	297.002
2908.43	298.131
2909.5	307.568
2910.57	301
2911.63	300.139
2912.7	299.29
2913.76	302.055
2914.83	307.598
2915.89	302.845
2916.96	306.692
2918.02	302.893
2919.09	299.971
2920.15	310.23
2921.22	305.26
2922.28	302.219
2923.34	306.939
2924.41	305.983
2925.47	311.657
2926.53	297.339
2927.6	300.121
2928.66	299.04
2929.72	312.851
2930.78	304.95
2931.84	303.191
2932.91	319.069
2933.97	292.613
2935.03	304.754
2936.09	297.002
2937.15	307.551
2938.21	301.802
2939.27	300.562
2940.33	299.711
2941.39	303.139
2942.45	299.539
2943.51	304.427
2944.57	295.187
2945.63	300.303
2946.68	299.873
2947.74	301.917
2948.8	290.538
2949.86	306.422
2950.92	304.617
2951.97	293.371
2953.03	304.617
2954.09	303.337
2955.14	298.342
2956.2	297.383
2957.25	297.497
2958.31	304.151
2959.37	309.825
2960.42	295.536
2961.48	301.077
2962.53	293.148
2963.59	297.109
2964.64	286.971
2965.7	301.905
2966.75	295.015
2967.8	290.078
2968.86	296.744
2969.91	289.257
2970.96	299.689
2972.02	299.716
2973.07	296.903
2974.12	299.663
2975.17	304.238
2976.22	299.54
2977.28	298.697
2978.33	291.378
2979.38	292.415
2980.43	288.532
2981.48	296.911
2982.53	289.183
2983.58	294.662
2984.63	289.809
2985.68	295.457
2986.73	302.22
2987.78	297.588
2988.83	299.605
2989.88	297.716
2990.93	296.789
2991.98	300.711
2993.02	302.516
2994.07	290.198
2995.12	302.7
2996.17	304.007
2997.21	297.498
2998.26	299.569
2999.31	300.553
2999.94	300.469