File: Data/3-Raman/raw/bu32-a-incc-fi01-v_1800 (450-850nm)_532nm_edge_100%_x100_vis_lwd_h30um_40sx2_01.txt
#Acq. time (s)=	40
#Accumulations=	2
#Range (cm-¹)=	1200...2365
#Windows=	3
#Auto scanning=	Off
#Autofocus=	Off
#Macrospot=	Off
#AutoExposure=	Off
#Spike filter=	Multiple accum.
#Delay time (s)=	2
#Binning=	1
#Readout mode=	Signal
#DeNoise=	Off
#ICS correction=	On
#Dark correction=	Off
#Inst. Process=	Off
#Detector Gain=	Best Dynamic
#Detector ADC=	50 kHz EM
#Detector EM gain=	400
#Detector temperature (°C)=	-60.09
#Instrument=	LabRAM HR Evol
#Detector=	SIN-EM FIVIS
#Objective=	x100_VIS_LWD
#Grating=	1800 (450-850nm)
#ND Filter=	100%
#Laser=	532nm_Edge
#Hole=	30.0125
#Temperature=	0
#Range=	Visible
#StageXY=	75x50mm Scan+
#StageZ=	Z motor
#X (µm)=	0
#Y (µm)=	0
#Z (µm)=	3.9
#Full time(mm:ss)=	4:22
#Project=	21_11_26
#Sample=	BU32
#Site=
#Title=	BU32-A-incC-FI01-V_1800 (450-850nm)_532nm_Edge_100%_x100_VIS_LWD_H30um_40sX2
#Remark=
#Date=	26.11.2021 17:46
#Acquired=	26.11.2021 17:46:55
1202.72	446.299
1203.84	463.701
1204.95	448.323
1206.06	489.543
1207.17	456.473
1208.28	441.012
1209.39	467.289
1210.5	415.774
1211.61	437.557
1212.72	461.478
1213.83	439.76
1214.94	446.098
1216.05	461.986
1217.16	444.314
1218.27	427.893
1219.38	469.012
1220.49	443.356
1221.6	456.993
1222.71	462.746
1223.81	431.242
1224.92	449.755
1226.03	413.887
1227.14	414.865
1228.25	428.677
1229.35	417.158
1230.46	453.057
1231.57	436.031
1232.67	446.542
1233.78	421.24
1234.89	449.779
1235.99	461.551
1237.1	427.816
1238.2	441.97
1239.31	412.093
1240.41	418.243
1241.52	429.821
1242.62	426.52
1243.73	452.864
1244.83	440.284
1245.94	436.741
1247.04	434.409
1248.14	396.635
1249.25	399.554
1250.35	428.833
1251.45	437.858
1252.56	446.943
1253.66	421.593
1254.76	464.641
1255.87	429.213
1256.97	423.042
1258.07	417.721
1259.17	420.641
1260.27	445.981
1261.37	476.787
1262.48	434.959
1263.58	475.51
1264.68	495.856
1265.78	456.713
1266.88	429.551
1267.98	421.603
1269.08	420.07
1270.18	430.55
1271.28	433.29
1272.38	432.29
1273.47	433.853
1274.57	463.64
1275.67	452.158
1276.77	427.309
1277.87	429.763
1278.97	428.053
1280.07	437.603
1281.16	424.99
1282.26	441.069
1283.36	455.603
1284.45	615.078
1285.55	794.143
1286.65	451.803
1287.75	437.938
1288.84	447.295
1289.94	440.189
1291.03	446.63
1292.13	440.261
1293.22	433.918
1294.32	438.666
1295.42	450.371
1296.51	422.784
1297.61	441.746
1298.7	449.945
1299.79	466.595
1300.89	423.446
1301.98	419.283
1303.08	419.395
1304.17	401.286
1305.26	431.865
1306.35	434.659
1307.45	418.756
1308.54	444.101
1309.63	442.125
1310.73	439.03
1311.82	462.316
1312.91	445.643
1314	428.612
1315.09	426.541
1316.18	423.593
1317.28	428.803
1318.37	441.614
1319.46	401.49
1320.55	447.98
1321.64	459.282
1322.73	452.539
1323.82	431.291
1324.91	414.444
1326	412.063
1327.09	439.793
1328.18	440.541
1329.27	448.452
1330.35	441.008
1331.44	421.666
1332.53	451.585
1333.62	427.865
1334.71	427.387
1335.79	423.887
1336.88	424.674
1337.97	411.93
1339.06	454.544
1340.14	409.498
1341.23	429.429
1342.32	440.781
1343.4	430.984
1344.49	447.678
1345.58	418.197
1346.66	442.669
1347.75	428.584
1348.83	397.12
1349.92	458.282
1351	431.911
1352.09	431.591
1353.17	448.508
1354.25	433.333
1355.34	409.471
1356.42	434.363
1357.51	446.612
1358.59	419.346
1359.67	435.647
1360.76	446.63
1361.84	428.881
1362.92	445.287
1364	444.398
1365.09	418.482
1366.17	404.671
1367.25	437.311
1368.33	443.496
1369.41	421.903
1370.5	420.754
1371.58	401.81
1372.66	431.137
1373.74	430.842
1374.82	454.401
1375.9	429.661
1376.98	429.464
1378.06	443.722
1379.14	431.033
1380.22	453.484
1381.3	424.787
1382.38	430.507
1383.46	409.374
1384.54	445.025
1385.61	454.678
1386.69	473.541
1387.77	960.914
1388.85	650.826
1389.93	442.666
1391	446.103
1392.08	418.083
1393.16	429.02
1394.23	416.577
1395.31	419.624
1396.39	421.802
1397.46	401.127
1398.54	424.568
1399.62	425.769
1400.69	406.467
1401.77	401.534
1402.84	414.451
1403.92	443.583
1404.99	418.654
1406.07	416.336
1407.14	414.168
1408.22	447.097
1409.29	482.099
1410.37	455.54
1411.44	426.395
1412.51	427.342
1413.59	427.479
1414.66	395.167
1415.73	440.522
1416.81	414.988
1417.88	403.88
1418.95	414.232
1420.02	402.832
1421.1	419.972
1422.17	437.456
1423.24	437.337
1424.31	430.786
1425.38	412.347
1426.45	439.135
1427.52	408.988
1428.59	422.941
1429.67	411.8
1430.74	400.882
1431.81	428.079
1432.87	406.306
1433.95	421.078
1435.01	421.225
1436.08	400.733
1437.15	417.005
1438.22	415.877
1439.29	420.12
1440.36	415.304
1441.43	446.186
1442.49	407.177
1443.56	389.726
1444.63	399.903
1445.7	406.373
1446.77	438.041
1447.83	410.202
1448.9	457.508
1449.97	434.883
1451.03	425.455
1452.1	419.164
1453.17	402.756
1454.23	418.195
1455.3	400.75
1456.36	426.47
1457.43	412.984
1458.49	418.042
1459.56	408.897
1460.62	405.77
1461.69	420.956
1462.75	412.487
1463.82	395.769
1464.88	406.441
1465.94	413.433
1467.01	430.651
1468.07	390.8
1469.13	388.71
1470.2	389.485
1471.26	393.366
1472.32	402.325
1473.39	394.116
1474.45	419.372
1475.51	418.429
1476.57	382.675
1477.63	416.053
1478.69	426.071
1479.76	397.352
1480.82	403.023
1481.88	376.503
1482.94	390.983
1484	434.725
1485.06	402.427
1486.12	382.051
1487.18	425.667
1488.24	413.301
1489.3	424.104
1490.36	373.41
1491.42	392.428
1492.48	387.337
1493.53	438.851
1494.59	387.286
1495.65	392.184
1496.71	398.878
1497.77	403.818
1498.82	389.671
1499.88	402.886
1500.94	383.739
1502	405.794
1503.05	403.628
1504.11	404.439
1505.17	401.458
1506.22	379.948
1507.28	381.999
1508.34	389.058
1509.39	391.082
1510.45	396.184
1511.5	408.926
1512.56	419.198
1513.61	395.653
1514.67	418.005
1515.72	407.614
1516.78	399.226
1517.83	400.17
1518.88	389.29
1519.94	390.402
1520.99	431.487
1522.05	424.545
1523.1	392.275
1524.15	383.825
1525.2	386.669
1526.26	414.883
1527.31	382.025
1528.36	376.876
1529.41	397.777
1530.47	401.671
1531.52	400.932
1532.57	397.87
1533.62	395.28
1534.67	422.428
1535.72	398.174
1536.77	415.659
1537.82	402.218
1538.87	402.978
1539.92	396.563
1540.97	375.15
1542.02	401.978
1543.07	428.621
1544.12	381.14
1545.17	401.388
1546.22	395.765
1547.27	400.86
1548.32	414.678
1549.37	408.439
1550.42	421.596
1551.46	446.912
1552.51	421.827
1553.56	411.489
1554.61	375.1
1555.65	411.837
1556.7	403.792
1557.75	401.852
1558.79	406.539
1559.84	404.086
1560.89	395.891
1561.93	408.959
1562.98	384.174
1564.02	388.103
1565.07	408.424
1566.11	404.012
1567.16	398.683
1568.2	411.984
1569.25	405.083
1570.29	402.886
1571.34	420.865
1572.38	406.691
1573.43	377.495
1574.47	397.421
1575.51	384.813
1576.56	399.856
1577.6	396.398
1578.64	395.948
1579.69	407.884
1580.73	407.007
1581.77	419.785
1582.81	399.628
1583.85	409.512
1584.9	406.545
1585.94	402.541
1586.98	394.277
1588.02	413.034
1589.06	407.205
1590.1	398.397
1591.14	412.454
1592.18	377.519
1593.22	417.958
1594.26	391.536
1595.3	409.492
1596.34	411.34
1597.38	420.326
1598.42	413.394
1599.46	378.295
1600.5	412.757
1601.54	443.029
1602.58	400.029
1603.62	406.608
1604.66	415.418
1605.69	419.413
1606.73	392.893
1607.77	410.428
1608.81	426.313
1609.84	417.188
1610.88	418.104
1611.92	385.793
1612.95	393.889
1613.99	389.302
1615.03	403.013
1616.06	412.65
1617.1	387.639
1618.13	393.679
1619.17	395.691
1620.2	385.917
1621.24	396.032
1622.27	398.922
1623.31	391.573
1624.34	398.021
1625.38	397.175
1626.41	396.286
1627.45	396.033
1628.48	394.497
1629.51	391.024
1630.55	376.76
1631.53	364.631
1632.57	362.818
1633.62	397.264
1634.66	385.522
1635.71	382.52
1636.75	357.714
1637.8	387.035
1638.84	364.266
1639.89	371.144
1640.93	377.104
1641.98	369.215
1643.02	388.812
1644.06	371.021
1645.11	395.442
1646.15	384.727
1647.19	356.036
1648.24	370.659
1649.28	377.878
1650.32	387.698
1651.37	373.267
1652.41	386.14
1653.45	382.096
1654.49	380.198
1655.53	405.003
1656.57	369.889
1657.62	388.639
1658.66	379.608
1659.7	381.345
1660.74	406.909
1661.78	367.729
1662.82	386.91
1663.86	391.887
1664.9	359.028
1665.94	366.431
1666.98	367.881
1668.02	401.218
1669.06	363.782
1670.1	371.943
1671.14	352.441
1672.18	411.668
1673.21	364.255
1674.25	366.311
1675.29	368.492
1676.33	364.611
1677.37	348.8
1678.4	359.5
1679.44	365.18
1680.48	353.174
1681.52	359.955
1682.55	354.996
1683.59	369.779
1684.63	379.55
1685.66	367.616
1686.7	382.456
1687.73	356.856
1688.77	398.158
1689.81	375.168
1690.84	360.262
1691.88	373.215
1692.91	356.384
1693.95	384.604
1694.98	385.284
1696.01	393.213
1697.05	364.736
1698.08	375.261
1699.12	371.052
1700.15	373.977
1701.18	372.883
1702.22	360.879
1703.25	365.553
1704.28	371.342
1705.32	384.179
1706.35	378.185
1707.38	372.904
1708.41	379.333
1709.44	351.431
1710.48	384.624
1711.51	371.037
1712.54	382.801
1713.57	370.467
1714.6	357.362
1715.63	354.417
1716.66	377.842
1717.69	347.101
1718.72	348.46
1719.75	359.996
1720.78	367.755
1721.81	361.583
1722.84	371.899
1723.87	379.375
1724.9	346.236
1725.93	363.187
1726.96	369.821
1727.99	372.604
1729.02	350.573
1730.05	366.621
1731.07	350.945
1732.1	360.049
1733.13	332.834
1734.16	364.211
1735.18	351.207
1736.21	357.591
1737.24	369.917
1738.26	350.454
1739.29	371.269
1740.32	363.964
1741.34	352.026
1742.37	346.02
1743.4	363.129
1744.42	369.627
1745.45	357.102
1746.47	363.645
1747.5	354.64
1748.52	349.639
1749.55	354.482
1750.57	354.762
1751.6	362.553
1752.62	358.373
1753.64	365.686
1754.67	359.665
1755.69	347.068
1756.71	344.837
1757.74	355.871
1758.76	375.007
1759.78	345.532
1760.81	360.646
1761.83	336.626
1762.85	350.85
1763.87	352.782
1764.89	353.04
1765.92	340.813
1766.94	349.343
1767.96	369.208
1768.98	349.06
1770	338.91
1771.02	352.382
1772.04	364.076
1773.06	347.152
1774.08	367.284
1775.1	339.779
1776.12	352.493
1777.14	351.526
1778.16	344.62
1779.18	356.689
1780.2	354.712
1781.22	347.205
1782.24	353.962
1783.26	355.144
1784.28	357.226
1785.29	346.964
1786.31	333.506
1787.33	354.652
1788.35	350.542
1789.37	339.561
1790.38	374.364
1791.4	358.011
1792.42	344.31
1793.43	379.853
1794.45	363.634
1795.47	371.624
1796.48	362.434
1797.5	365.593
1798.51	346.538
1799.53	363.8
1800.55	377.951
1801.56	344.208
1802.58	361.56
1803.59	364.695
1804.61	335.033
1805.62	346.862
1806.64	349.059
1807.65	350.107
1808.66	375.177
1809.68	372.329
1810.69	358.869
1811.7	353.024
1812.72	357.89
1813.73	344.563
1814.74	342.939
1815.76	350.925
1816.77	357.759
1817.78	366.226
1818.79	348.883
1819.8	363.476
1820.82	358.8
1821.83	357.036
1822.84	367.825
1823.85	350.391
1824.86	348.458
1825.87	377.629
1826.88	355.366
1827.89	380.649
1828.9	369
1829.91	366.935
1830.92	353.223
1831.93	363.035
1832.94	350.644
1833.95	378.844
1834.96	377.608
1835.97	352.834
1836.98	395.88
1837.99	372.351
1839	360.697
1840	360.218
1841.01	390.444
1842.02	352.061
1843.03	350.778
1844.04	360.412
1845.04	368.128
1846.05	348.926
1847.06	356.02
1848.07	355.74
1849.07	355.796
1850.08	341.077
1851.09	352.173
1852.09	343.286
1853.1	350.935
1854.1	352.7
1855.11	365.74
1856.11	340.467
1857.12	337.529
1858.12	353.665
1859.13	354.317
1860.13	356.922
1861.14	348.455
1862.14	349.593
1863.15	355.087
1864.15	334.694
1865.15	342.067
1866.16	356.873
1867.16	345.782
1868.16	342.478
1869.17	342.426
1870.17	349.003
1871.17	344.179
1872.17	344.037
1873.18	334.317
1874.18	337.964
1875.18	353.758
1876.18	346.594
1877.18	332.968
1878.18	348.53
1879.19	338.693
1880.19	348.422
1881.19	345.527
1882.19	347.84
1883.19	323.507
1884.19	343.876
1885.19	335.556
1886.19	356.746
1887.19	344.415
1888.19	351.613
1889.19	346.415
1890.19	363.148
1891.19	352.061
1892.18	354.797
1893.18	341.448
1894.18	323.991
1895.18	340.738
1896.18	357.753
1897.18	357.979
1898.17	359.945
1899.17	338.099
1900.17	335.974
1901.16	335.952
1902.16	350.306
1903.16	350.429
1904.16	336.179
1905.15	334.23
1906.15	360.397
1907.14	338.53
1908.14	330.109
1909.14	357.492
1910.13	347.464
1911.13	332.812
1912.12	351.737
1913.12	326.238
1914.11	340.519
1915.11	356.878
1916.1	324.919
1917.1	329.462
1918.09	350.97
1919.08	347.418
1920.08	346.951
1921.07	333.777
1922.06	352.954
1923.06	349.11
1924.05	348.952
1925.04	341.213
1926.04	353.729
1927.03	341.816
1928.02	338.233
1929.01	344.052
1930	338.636
1931	341.84
1931.99	340.844
1932.98	346.329
1933.97	354.918
1934.96	337.858
1935.95	354.806
1936.94	328.726
1937.93	336.043
1938.92	344.583
1939.91	360.964
1940.9	345.954
1941.89	351.033
1942.88	334.946
1943.87	350.959
1944.86	355.974
1945.85	355.356
1946.84	354.63
1947.83	339.266
1948.82	332.52
1949.8	348.99
1950.79	357.136
1951.78	328.891
1952.77	344.518
1953.76	332.062
1954.74	346.68
1955.73	334.991
1956.72	333.634
1957.7	356.996
1958.69	332.179
1959.68	348.394
1960.66	350.128
1961.65	354.671
1962.63	331.636
1963.62	334.559
1964.61	327.933
1965.59	336.526
1966.58	345.345
1967.56	357.996
1968.55	343.629
1969.53	329.98
1970.52	340.16
1971.5	363.93
1972.48	348.568
1973.47	323.545
1974.45	337.707
1975.44	348.269
1976.42	353.236
1977.4	340.782
1978.39	331.97
1979.37	343.356
1980.35	343.377
1981.33	358.511
1982.31	340.173
1983.3	357.184
1984.28	347.361
1985.26	345.277
1986.24	346.109
1987.22	355.782
1988.21	341.178
1989.19	350.712
1990.17	332.963
1991.15	339.786
1992.13	334.54
1993.11	353.406
1994.09	333.256
1995.07	341.585
1996.05	358.104
1997.03	333.262
1998.01	333.36
1998.99	339.482
1999.97	338.907
2000.95	333.706
2001.92	332.168
2002.9	332.975
2003.88	341.949
2004.86	344.065
2005.84	341.3
2006.81	337.506
2007.79	332.032
2008.77	337.745
2009.75	335.24
2010.73	327.453
2011.7	354.506
2012.68	331.573
2013.67	337.775
2014.66	320.317
2015.64	334.257
2016.63	325.948
2017.62	336.499
2018.61	329.472
2019.6	336.468
2020.58	312.901
2021.57	333.512
2022.56	345.588
2023.55	328.42
2024.54	319.721
2025.52	337.027
2026.51	328.349
2027.5	341.371
2028.48	350.31
2029.47	339.638
2030.45	340.46
2031.44	320.079
2032.43	350.931
2033.41	321.475
2034.4	322.445
2035.38	337.81
2036.37	335.731
2037.35	359.94
2038.34	324.311
2039.32	328.775
2040.31	333.156
2041.29	330.024
2042.27	317.751
2043.26	331.589
2044.24	325.447
2045.23	325.25
2046.21	326.857
2047.19	332.148
2048.17	317.737
2049.16	339.263
2050.14	349.913
2051.12	328.691
2052.11	344.372
2053.09	351.958
2054.07	328.965
2055.05	324.395
2056.03	324.236
2057.01	344.692
2058	348.513
2058.98	331.006
2059.96	333.973
2060.94	314.194
2061.92	337.728
2062.9	326.567
2063.88	328.644
2064.86	340.96
2065.84	337.535
2066.82	339.622
2067.8	339.771
2068.78	335.231
2069.76	333.258
2070.73	337.922
2071.71	358.828
2072.69	343.328
2073.67	326.318
2074.65	341.465
2075.63	322.09
2076.6	339.437
2077.58	332.658
2078.56	337.292
2079.54	326.153
2080.51	351.048
2081.49	339.697
2082.47	326.466
2083.45	342.573
2084.42	345.382
2085.4	339.725
2086.37	355.906
2087.35	337.259
2088.32	330.73
2089.3	337.411
2090.28	320.591
2091.25	316.904
2092.23	346.545
2093.2	351.731
2094.18	334.96
2095.15	333.122
2096.13	326.277
2097.1	346.135
2098.07	339.271
2099.05	325.895
2100.02	332.486
2101	342.04
2101.97	331.806
2102.94	330.827
2103.92	345.843
2104.89	339.264
2105.86	321.444
2106.83	329.193
2107.8	332.061
2108.78	328.875
2109.75	351.667
2110.72	321.341
2111.69	346.96
2112.66	333.554
2113.63	354.646
2114.61	343.293
2115.58	352.791
2116.55	334.579
2117.52	361.036
2118.49	342.857
2119.46	339.663
2120.43	341.299
2121.4	354.646
2122.37	332.195
2123.34	333.338
2124.31	329.514
2125.28	341.401
2126.25	322.934
2127.21	336.824
2128.18	332.899
2129.15	336.621
2130.12	333.702
2131.09	332.658
2132.06	336.24
2133.02	331.315
2133.99	351.118
2134.96	359.629
2135.93	328.411
2136.89	325.272
2137.86	327.223
2138.83	364.803
2139.79	344.145
2140.76	341.026
2141.73	337.167
2142.69	324.75
2143.66	341.955
2144.62	324.348
2145.59	345.985
2146.55	328.996
2147.52	357.048
2148.48	347.478
2149.45	313.468
2150.42	331.849
2151.38	336.45
2152.34	332.861
2153.31	328.995
2154.27	326.945
2155.24	330.218
2156.2	352.2
2157.16	334.316
2158.13	353.137
2159.09	331.688
2160.05	333.358
2161.01	315.313
2161.98	330.122
2162.94	319.837
2163.9	322.489
2164.86	321.322
2165.83	334.359
2166.79	323.106
2167.75	319.139
2168.71	329.844
2169.67	329.032
2170.63	340.613
2171.59	308.863
2172.56	344.586
2173.51	338.884
2174.48	332.469
2175.44	318.534
2176.4	337.972
2177.36	328.575
2178.32	344.383
2179.28	351.6
2180.23	313.55
2181.19	332.988
2182.15	344.939
2183.11	334.6
2184.07	337.064
2185.03	337.878
2185.99	317.609
2186.95	343.839
2187.9	336.787
2188.86	324.572
2189.82	327.004
2190.78	335.201
2191.73	330.638
2192.69	343.734
2193.65	323.519
2194.6	351.877
2195.56	331.392
2196.52	327.339
2197.47	344.655
2198.43	323.314
2199.38	323.68
2200.34	373.44
2201.3	346.128
2202.25	339.402
2203.21	346.499
2204.16	359.889
2205.12	351.772
2206.07	336.048
2207.03	330.439
2207.98	339.939
2208.93	330.905
2209.89	363.605
2210.84	353.458
2211.8	344.364
2212.75	339.926
2213.7	327.657
2214.66	353.939
2215.61	330.829
2216.56	344.853
2217.51	315.872
2218.47	331.764
2219.42	355.269
2220.37	319.94
2221.32	320.807
2222.27	323.311
2223.23	336.401
2224.18	330.146
2225.13	332.37
2226.08	338.314
2227.03	334.835
2227.98	328.453
2228.93	339.623
2229.88	324.641
2230.83	337.127
2231.78	346.824
2232.73	339.578
2233.68	356.766
2234.63	338.081
2235.58	345.356
2236.53	341.547
2237.48	336.976
2238.43	332.738
2239.38	335.029
2240.33	340.541
2241.27	326.543
2242.22	333.238
2243.17	358.843
2244.12	339.826
2245.07	319.209
2246.01	346.065
2246.96	334.952
2247.91	335.105
2248.85	349.236
2249.8	326.533
2250.75	347.281
2251.69	354.576
2252.64	330.077
2253.59	340.028
2254.53	324.225
2255.48	323.312
2256.42	335.725
2257.37	335.96
2258.32	338.025
2259.26	334.344
2260.2	340.198
2261.15	340.354
2262.1	335.817
2263.04	316.953
2263.98	335.43
2264.93	364.544
2265.87	328.49
2266.81	315.917
2267.76	323.301
2268.7	342.173
2269.65	336.673
2270.59	325.633
2271.53	337.341
2272.47	340.404
2273.42	347.165
2274.36	325.228
2275.3	325.303
2276.24	347.407
2277.18	319.931
2278.13	333.794
2279.07	343.624
2280.01	346.252
2280.95	344.949
2281.89	339.997
2282.83	328.67
2283.77	325.21
2284.71	346.902
2285.65	331.733
2286.59	333.459
2287.54	311.683
2288.47	338.803
2289.41	336.61
2290.35	340.987
2291.29	317.936
2292.23	349.057
2293.17	346.459
2294.11	339.887
2295.05	351.264
2295.99	332.772
2296.93	348.853
2297.86	336.563
2298.8	339.79
2299.74	356.48
2300.68	326.6
2301.61	340.288
2302.55	348.965
2303.49	351.818
2304.43	321.989
2305.36	336.676
2306.3	326.174
2307.24	336.864
2308.17	331.922
2309.11	332.844
2310.04	348.615
2310.98	343.889
2311.92	327.896
2312.85	327.589
2313.79	340.229
2314.72	340.67
2315.66	340.884
2316.59	333.687
2317.52	334.518
2318.46	341.333
2319.39	328.57
2320.33	343.9
2321.26	344.957
2322.2	331.729
2323.13	324.205
2324.06	345.559
2325	337.719
2325.93	342.172
2326.86	350.566
2327.79	360.883
2328.73	401.281
2329.66	370.198
2330.59	330.676
2331.52	331.589
2332.46	339.388
2333.39	330.51
2334.32	326.501
2335.25	345.508
2336.18	348.397
2337.11	331.001
2338.04	329.004
2338.97	336.626
2339.91	327.982
2340.84	328.76
2341.77	333.156
2342.7	339.599
2343.63	338.576
2344.56	338.572
2345.49	330.845
2346.41	342.07
2347.34	337.188
2348.27	341.968
2349.2	319.019
2350.13	349.123
2351.06	312.245
2351.99	355.541
2352.91	332.101
2353.84	336.376
2354.77	326.857
2355.7	327.825
2356.63	326.637
2357.55	326.229
2358.48	329.843
2359.41	334.435
2360.33	323.797
2361.26	328.233
2362.19	350.639
2363.11	317.158
2364.04	328.328
2364.97	320.573