File: Data/3-Raman/raw/bu32-b-ff2-fi05-v_1800 (450-850nm)_532nm_edge_100%_x100_vis_lwd_h30um_30sx2_01.txt
#Acq. time (s)=	30
#Accumulations=	2
#Range (cm-¹)=	1200...2999
#Windows=	5
#Auto scanning=	Off
#Autofocus=	Off
#Macrospot=	Off
#AutoExposure=	Off
#Spike filter=	Multiple accum.
#Delay time (s)=	2
#Binning=	1
#Readout mode=	Signal
#DeNoise=	Off
#ICS correction=	On
#Dark correction=	Off
#Inst. Process=	Off
#Detector Gain=	Best Dynamic
#Detector ADC=	50 kHz EM
#Detector EM gain=	150
#Detector temperature (°C)=	-60.09
#Instrument=	LabRAM HR Evol
#Detector=	SIN-EM FIVIS
#Objective=	x100_VIS_LWD
#Grating=	1800 (450-850nm)
#ND Filter=	100%
#Laser=	532nm_Edge
#Hole=	30.0125
#Temperature=	39.9
#Range=	Visible
#StageXY=	75x50mm Scan+
#StageZ=	Z motor
#X (µm)=	0
#Y (µm)=	0
#Z (µm)=	57.1
#Full time(mm:ss)=	5:33
#Project=	21_08_11
#Sample=	BU32
#Site=
#Title=	BU32-B-FF2-FI05-V_1800 (450-850nm)_532nm_Edge_100%_x100_VIS_LWD_H30um_30sX2
#Remark=
#Date=	13.08.2021 16:03
#Acquired=	13.08.2021 16:03:49
1200.05	327.611
1201.44	324.672
1202.83	327.323
1204.22	325.761
1205.61	327.289
1207	322.329
1208.39	323.019
1209.78	317.445
1211.16	327.541
1212.55	327.003
1213.94	316.2
1215.33	325.735
1216.71	325.167
1218.1	317.331
1219.49	325.63
1220.87	324.453
1222.26	317.523
1223.64	323.206
1225.03	327.261
1226.41	321.968
1227.79	328.437
1229.18	320.862
1230.56	328.503
1231.94	323.604
1233.33	323.553
1234.71	317.435
1236.09	318.542
1237.47	321.242
1238.86	315.573
1240.24	323.898
1241.62	321.709
1243	335.446
1244.38	319.691
1245.76	323.465
1247.14	324.445
1248.52	321.091
1249.9	325.212
1251.27	323.832
1252.65	322.479
1254.03	327.839
1255.41	324.751
1256.79	318.575
1258.16	330.946
1259.54	330.04
1260.92	336.919
1262.29	337.399
1263.67	385.755
1265.04	367.87
1266.42	349.115
1267.79	336.041
1269.17	338.425
1270.54	334.895
1271.92	331.872
1273.29	327.108
1274.66	337.75
1276.04	332.791
1277.41	344.704
1278.78	340.851
1280.15	337.62
1281.53	381.039
1282.9	515.123
1284.27	1609.01
1285.64	540.228
1287.01	370.544
1288.38	344.151
1289.75	348.675
1291.12	344.402
1292.49	345.424
1293.86	343.78
1295.23	333.573
1296.6	330.817
1297.96	327.391
1299.33	331.444
1300.7	326.244
1302.07	329.574
1303.43	333.671
1304.8	337.808
1306.17	330.094
1307.53	333.289
1308.9	336.57
1310.26	326.076
1311.63	326.204
1312.99	329.375
1314.36	326.206
1315.72	334.816
1317.08	326.365
1318.45	337.014
1319.81	330.671
1321.17	334.568
1322.53	332.168
1323.9	328.982
1325.26	325.631
1326.62	327.261
1327.98	334.306
1329.34	315.452
1330.7	326.768
1332.06	336.724
1333.42	329.88
1334.78	327.39
1336.14	321.882
1337.5	329.018
1338.86	332.973
1340.22	328.846
1341.58	328.723
1342.93	322.133
1344.29	325.237
1345.65	325.875
1347	320.107
1348.36	326.156
1349.72	330.023
1351.07	325.507
1352.43	333.989
1353.78	324.526
1355.14	333.377
1356.49	325.086
1357.85	335.232
1359.2	326.657
1360.56	327.333
1361.91	334.475
1363.26	327.295
1364.61	336.552
1365.97	325.828
1367.32	320.398
1368.67	334.988
1370.02	347.228
1371.37	334.395
1372.72	337.045
1374.07	329.682
1375.42	328.629
1376.77	335.45
1378.12	356.662
1379.47	354.508
1380.82	346.632
1382.17	362.38
1383.52	363.949
1384.87	395.076
1386.21	537.199
1387.56	2672.3
1388.91	550.331
1390.26	382.497
1391.6	359.536
1392.95	352.1
1394.3	325.375
1395.64	325.514
1396.99	332.456
1398.33	331.474
1399.68	326.503
1401.02	334.886
1402.37	335.526
1403.71	338.555
1405.05	345.587
1406.39	329.016
1407.74	358.866
1409.08	449.276
1410.42	354.676
1411.76	327.865
1413.11	321.426
1414.45	322.357
1415.79	320.387
1417.13	334.955
1418.47	320.637
1419.81	324.557
1421.15	319.211
1422.49	334.311
1423.83	324.823
1425.17	318.897
1426.51	327.028
1427.84	333.783
1429.18	321.632
1430.52	314.905
1431.86	313.956
1433.19	316.533
1434.53	334.056
1435.87	317.615
1437.2	312.376
1438.54	315.536
1439.87	313.753
1441.21	317.845
1442.54	316.896
1443.88	321.894
1445.21	315.975
1446.55	323.037
1447.88	319.9
1449.21	317.899
1450.55	310.548
1451.88	313.501
1453.21	306.427
1454.54	307.413
1455.88	311.587
1457.21	311.423
1458.54	313.504
1459.87	309.382
1461.2	308.188
1462.53	311.985
1463.86	317.162
1465.19	309.267
1466.52	315.209
1467.85	311.117
1469.18	307.925
1470.51	304.632
1471.83	303.442
1473.16	308.413
1474.49	308.396
1475.82	306.267
1477.14	307.124
1478.47	308.976
1479.79	307.628
1481.12	311.462
1482.45	314.734
1483.77	310.624
1485.1	306.29
1486.42	303.948
1487.75	306.82
1489.07	302.514
1490.39	307.457
1491.72	309.38
1493.04	305.283
1494.36	307.338
1495.69	304.932
1497.01	307.832
1498.33	304.795
1499.65	305.905
1500.97	307.818
1502.29	308.705
1503.62	307.557
1504.93	304.475
1506.26	306.258
1507.58	312.37
1508.89	307.331
1510.21	305.266
1511.53	306.703
1512.85	304.193
1514.17	301.339
1515.49	307.968
1516.81	303.795
1518.12	304.915
1519.44	300.986
1520.76	310.037
1522.07	301.929
1523.39	300.57
1524.71	301.44
1526.02	303.689
1527.34	305.643
1528.65	301.5
1529.97	302.435
1531.28	305.608
1532.59	300.765
1533.91	299.931
1535.22	302.678
1536.54	306.198
1537.85	305.933
1539.16	302.294
1540.47	307.892
1541.79	304.512
1543.1	305.139
1544.41	303.184
1545.72	301.523
1547.03	302.628
1548.34	308.571
1549.65	312.231
1550.96	302.242
1552.27	300.297
1553.58	303.89
1554.89	305.526
1556.2	303.496
1557.5	300.493
1558.81	305.046
1560.12	306.818
1561.43	304.927
1562.74	301.023
1564.04	296.226
1565.35	303.339
1566.65	304.836
1567.96	297.96
1569.27	297.788
1570.57	302.809
1571.88	298.646
1573.18	300.402
1574.48	300.656
1575.79	301.79
1577.09	307.343
1578.4	307.055
1579.7	309.129
1581	303.033
1582.3	298.85
1583.61	301.764
1584.91	305.793
1586.21	305.565
1587.51	300.463
1588.81	301.631
1590.11	307.701
1591.41	302.709
1592.72	302.335
1594.01	300.948
1595.31	305.927
1596.61	295.014
1597.91	303.94
1599.21	295.682
1600.51	298.167
1601.81	297.815
1603.1	299.002
1604.4	299.587
1605.7	307.775
1607	306.209
1608.29	300.803
1609.59	300.241
1610.88	299.042
1612.18	301.992
1613.48	299.738
1614.77	301.654
1616.07	304.33
1617.36	307.675
1618.65	305.031
1619.95	303.264
1621.24	299.624
1622.54	298.948
1623.83	296.897
1625.12	303.236
1626.41	298.972
1627.56	306.461
1628.87	298.567
1630.17	296.499
1631.48	298.59
1632.79	302.596
1634.1	301.619
1635.4	305.494
1636.71	301.346
1638.01	296.292
1639.32	307.115
1640.62	302.306
1641.93	298.275
1643.23	304.13
1644.54	301.032
1645.84	299.117
1647.15	298.976
1648.45	296.177
1649.75	298.275
1651.05	296.613
1652.36	298.558
1653.66	299.574
1654.96	305.68
1656.26	295.146
1657.56	300.981
1658.86	298.813
1660.16	299.759
1661.46	297.062
1662.77	303.404
1664.07	297.163
1665.36	300.264
1666.66	295.927
1667.96	295.952
1669.26	308.183
1670.56	303.473
1671.86	304.458
1673.15	301.529
1674.45	301.723
1675.75	303.816
1677.05	297.883
1678.34	302.573
1679.64	303.407
1680.94	299.34
1682.23	298.355
1683.53	302.272
1684.82	298.214
1686.12	301.242
1687.41	303.214
1688.71	299.054
1690	295.918
1691.29	300.026
1692.59	293.969
1693.88	290.659
1695.17	296.536
1696.47	296.626
1697.76	307.139
1699.05	300.109
1700.34	291.201
1701.63	296.921
1702.92	297.728
1704.21	294.798
1705.5	294.751
1706.79	293.435
1708.08	290.05
1709.37	293.682
1710.66	300.635
1711.95	294.767
1713.24	295.15
1714.53	294.962
1715.82	292.109
1717.11	295.547
1718.39	296.979
1719.68	299.903
1720.97	296.724
1722.25	294.417
1723.54	292.281
1724.83	292.927
1726.11	287.825
1727.4	288.691
1728.68	294.34
1729.97	299.309
1731.25	287.039
1732.54	295.585
1733.82	286.404
1735.1	286.93
1736.39	297.328
1737.67	289.412
1738.95	289.062
1740.24	293.295
1741.52	284.384
1742.8	289.066
1744.08	285.994
1745.36	289.799
1746.65	284.68
1747.93	288.275
1749.21	286.508
1750.49	288.688
1751.77	289.436
1753.05	288.177
1754.33	287.914
1755.6	287.683
1756.88	287.281
1758.16	288.315
1759.44	285.477
1760.72	285.311
1762	293.739
1763.27	284.307
1764.55	286.489
1765.83	292.283
1767.1	286.483
1768.38	292.961
1769.66	293.429
1770.93	288.026
1772.21	291.121
1773.48	286.53
1774.76	282.851
1776.03	284.093
1777.31	292.473
1778.58	289.31
1779.85	289.328
1781.13	287.527
1782.4	286.811
1783.67	296.544
1784.94	288.139
1786.22	287.168
1787.49	293.44
1788.76	290.217
1790.03	291.439
1791.3	287.312
1792.57	292.175
1793.84	283.644
1795.11	287.922
1796.38	294.928
1797.65	288.432
1798.92	287.45
1800.19	294.912
1801.46	287.208
1802.73	296.077
1804	295.318
1805.26	298.547
1806.53	291.058
1807.8	295.903
1809.07	294.033
1810.33	290.196
1811.6	290.186
1812.87	290.375
1814.13	292.638
1815.4	291.881
1816.66	290.971
1817.93	289.824
1819.19	291.92
1820.46	293.055
1821.72	300.032
1822.99	294.284
1824.25	296.232
1825.51	297.313
1826.77	300.273
1828.04	294.534
1829.3	289.573
1830.56	295.286
1831.82	290.645
1833.09	295.643
1834.35	293.476
1835.61	293.077
1836.87	293.588
1838.13	289.938
1839.39	295.602
1840.65	291.9
1841.91	290.359
1843.17	288.423
1844.43	299.032
1845.69	289.661
1846.94	294.615
1848.2	286.965
1849.46	294.367
1850.72	290.109
1851.97	286.149
1853.23	291.839
1854.49	287.649
1855.74	292.139
1857	291.125
1858.26	289.918
1859.51	286.81
1860.77	287.949
1862.02	293.717
1863.28	289.561
1864.53	292.154
1865.78	290.689
1867.04	288.195
1868.29	289.005
1869.54	286.11
1870.8	287.964
1872.05	290.64
1873.3	290.455
1874.56	288.239
1875.81	288.653
1877.06	287.132
1878.31	286.685
1879.56	283.099
1880.81	283.981
1882.06	281.345
1883.31	284.149
1884.56	288.567
1885.81	282.368
1887.06	287.764
1888.31	292.03
1889.56	282.396
1890.81	292.91
1892.05	283.419
1893.3	281.964
1894.55	284.653
1895.8	285.739
1897.04	283.132
1898.29	280.204
1899.54	279.955
1900.78	288.49
1902.03	290.671
1903.27	283.968
1904.52	283.907
1905.76	289.33
1907.01	283.599
1908.25	283.751
1909.5	290.651
1910.74	284.449
1911.98	289.149
1913.23	288.282
1914.47	287.709
1915.71	287.774
1916.96	287.565
1918.2	289.553
1919.44	288.156
1920.68	284.509
1921.92	287.513
1923.16	282.628
1924.41	285.309
1925.65	289.396
1926.89	285.01
1928.12	286.12
1929.36	293.055
1930.6	284.833
1931.84	288.492
1933.08	287.455
1934.32	288.423
1935.56	284.965
1936.8	290.486
1938.03	289.338
1939.27	283.889
1940.51	291.938
1941.75	284.081
1942.98	289.179
1944.22	284.538
1945.45	291.574
1946.69	296.485
1947.92	284.949
1949.16	291.836
1950.4	291.407
1951.63	290.929
1952.86	295.918
1954.1	289.45
1955.33	294.24
1956.56	290.958
1957.8	296.016
1959.03	288.253
1960.26	289.015
1961.5	289.827
1962.73	283.177
1963.96	291.923
1965.19	289.029
1966.42	282.57
1967.65	293.209
1968.88	286.325
1970.11	292.702
1971.34	290.612
1972.57	287.773
1973.8	290.429
1975.03	290.511
1976.26	282.979
1977.49	286.705
1978.72	288.503
1979.95	287.54
1981.17	289.266
1982.4	290.822
1983.63	288.345
1984.85	289.305
1986.08	286.921
1987.31	289.392
1988.53	285.586
1989.76	285.68
1990.98	285.525
1992.21	284.633
1993.43	287.591
1994.66	285.797
1995.88	290.607
1997.11	285.076
1998.33	286.971
1999.55	287.478
2000.78	286.149
2002	282.964
2003.22	285.567
2004.45	289.143
2005.59	286.35
2006.83	285.431
2008.06	291.673
2009.3	284.672
2010.54	278.786
2011.77	285.329
2013.01	284.971
2014.25	282.496
2015.48	286.371
2016.72	287.584
2017.95	284.32
2019.19	280.107
2020.42	281.894
2021.66	287.508
2022.89	280.645
2024.12	280.303
2025.36	282.664
2026.59	281.297
2027.82	282.89
2029.06	280.859
2030.29	280.552
2031.52	283.673
2032.75	278.518
2033.98	283.895
2035.21	285.892
2036.45	282.339
2037.68	282.303
2038.91	279.275
2040.14	278.931
2041.37	285.251
2042.6	280.44
2043.83	285.492
2045.05	277.074
2046.28	284.848
2047.51	284.314
2048.74	287.278
2049.97	281.161
2051.2	281.984
2052.42	282.094
2053.65	282.466
2054.88	279.652
2056.1	282.297
2057.33	290.779
2058.56	280.783
2059.78	290.183
2061.01	283.675
2062.23	284.701
2063.46	283.043
2064.68	278.561
2065.91	281.703
2067.13	284.668
2068.35	290.497
2069.58	280.798
2070.8	282.153
2072.02	285.31
2073.25	285.283
2074.47	283.607
2075.69	283.195
2076.91	288.702
2078.13	283.028
2079.35	283.366
2080.58	287.249
2081.8	283.461
2083.02	283.489
2084.24	289.162
2085.46	289.207
2086.68	280.052
2087.9	288.66
2089.12	290.703
2090.33	289.93
2091.55	287.357
2092.77	283.053
2093.99	282.374
2095.21	286.989
2096.43	289.724
2097.64	290.485
2098.86	291.357
2100.08	290.427
2101.29	286.846
2102.51	289.621
2103.73	291.422
2104.94	284.992
2106.16	286.138
2107.37	286.095
2108.59	287.688
2109.8	284.995
2111.01	286.872
2112.23	288.724
2113.44	294.656
2114.66	286.075
2115.87	282.125
2117.08	283.942
2118.29	292.189
2119.51	286.204
2120.72	290.036
2121.93	289.411
2123.14	288.613
2124.35	285.462
2125.57	293.454
2126.78	286.514
2127.99	282.632
2129.2	287.309
2130.41	285.325
2131.62	283.249
2132.82	287.8
2134.03	284.075
2135.24	287.782
2136.45	288.478
2137.66	285.733
2138.87	283.932
2140.08	292.023
2141.28	290.945
2142.49	290.03
2143.7	284.775
2144.9	285.836
2146.11	281.997
2147.32	282.773
2148.52	288.229
2149.73	284.083
2150.93	283.135
2152.14	282.287
2153.34	284.909
2154.55	278.835
2155.75	283.09
2156.96	284.939
2158.16	287.893
2159.36	281.171
2160.57	291.15
2161.77	284.54
2162.97	282.576
2164.17	284.209
2165.38	283.286
2166.58	281.26
2167.78	280.799
2168.98	288.316
2170.18	281.254
2171.38	284.549
2172.58	288.019
2173.78	284.383
2174.98	286.234
2176.18	291.697
2177.38	281.472
2178.58	283.174
2179.78	284.122
2180.98	283.124
2182.18	284.837
2183.38	279.911
2184.57	285.416
2185.77	280.037
2186.97	284.139
2188.16	285.936
2189.36	279.064
2190.56	284.638
2191.76	286.591
2192.95	279.368
2194.15	278.906
2195.34	277.796
2196.54	286.688
2197.73	282.008
2198.93	300.073
2200.12	283.972
2201.31	281.961
2202.51	286.512
2203.7	287.203
2204.89	280.964
2206.09	286.43
2207.28	285.579
2208.47	283.068
2209.67	287.783
2210.86	280.55
2212.05	289.185
2213.24	279.694
2214.43	284.696
2215.62	282.901
2216.81	281.005
2218	283.845
2219.19	294.336
2220.38	289.706
2221.57	293.15
2222.76	281.081
2223.95	286.132
2225.14	282.748
2226.33	289.607
2227.51	284.14
2228.7	287.805
2229.89	291.814
2231.08	282.749
2232.27	286.796
2233.45	293.648
2234.64	289.798
2235.82	284.961
2237.01	287.964
2238.2	281.875
2239.38	297.122
2240.57	287.747
2241.75	290.691
2242.94	290.726
2244.12	286.938
2245.3	291.162
2246.49	293.31
2247.67	283.925
2248.85	288.586
2250.04	290.479
2251.22	286.463
2252.4	284.817
2253.59	289.09
2254.77	291.083
2255.95	288.377
2257.13	294.323
2258.31	292.545
2259.49	285.125
2260.67	289.159
2261.85	291.217
2263.03	288.704
2264.21	293.046
2265.39	296.131
2266.57	291.073
2267.75	293.69
2268.93	291.007
2270.11	289.531
2271.29	290.728
2272.47	286.077
2273.64	293.823
2274.82	290.087
2276	298.913
2277.17	291.654
2278.35	297.744
2279.53	291.693
2280.71	289.507
2281.88	292.419
2283.06	294.742
2284.23	285.657
2285.41	288.664
2286.58	292.597
2287.76	298.648
2288.93	294.462
2290.1	295.132
2291.28	290.624
2292.45	297.67
2293.62	299.74
2294.8	292.783
2295.97	296.332
2297.14	293.621
2298.31	299.765
2299.49	300.002
2300.66	296.27
2301.83	296.31
2303	290.485
2304.17	293.553
2305.34	289.87
2306.51	296.736
2307.68	296.624
2308.85	293.81
2310.02	296.027
2311.19	293.64
2312.36	294.293
2313.53	296.55
2314.7	291.202
2315.87	294.643
2317.03	290.672
2318.2	287.731
2319.37	286.582
2320.54	294.384
2321.7	292.802
2322.87	291.012
2324.03	299.746
2325.2	309.008
2326.37	306.758
2327.53	336.369
2328.7	400.829
2329.86	302.449
2331.03	293.779
2332.19	293.732
2333.36	298.37
2334.52	289.474
2335.68	294.283
2336.85	292.277
2338.01	289.313
2339.17	287.396
2340.34	288.146
2341.5	291.564
2342.66	287.599
2343.82	293.184
2344.98	292.804
2346.14	290.636
2347.31	292.4
2348.47	288.565
2349.63	285.234
2350.79	288.824
2351.95	294.622
2353.11	287.957
2354.27	291.413
2355.43	287.355
2356.59	286.468
2357.74	288.565
2358.9	287.546
2360.06	290.341
2361.22	289.755
2362.38	286.817
2363.53	283.654
2364.69	284.102
2365.74	281.207
2366.92	290.086
2368.09	288.039
2369.26	283.999
2370.43	290.272
2371.6	283.471
2372.77	286.08
2373.94	284.938
2375.11	282.794
2376.28	284.518
2377.45	284.341
2378.62	282.188
2379.79	286.513
2380.96	280.816
2382.13	286.413
2383.29	288.202
2384.46	286.291
2385.63	286.036
2386.8	282.832
2387.97	277.06
2389.13	285.369
2390.3	279.753
2391.47	287.262
2392.63	279.582
2393.8	281.93
2394.96	279.054
2396.13	281.847
2397.29	281.655
2398.46	284.436
2399.62	282.585
2400.79	285.303
2401.95	284.241
2403.12	278.021
2404.28	285.975
2405.44	278.758
2406.61	286.299
2407.77	283.479
2408.93	286.219
2410.09	282.502
2411.26	283.449
2412.42	284.548
2413.58	281.807
2414.74	280.764
2415.9	275.902
2417.06	283.484
2418.22	283.706
2419.38	284.101
2420.54	286.075
2421.7	283.952
2422.86	281.438
2424.02	285.383
2425.18	283.814
2426.34	280.341
2427.5	282.371
2428.66	282.291
2429.81	286.945
2430.97	283.25
2432.13	280.85
2433.29	287.729
2434.44	281.209
2435.6	290.904
2436.76	286.432
2437.91	280.749
2439.07	285.723
2440.23	296.468
2441.38	281.433
2442.53	292.993
2443.69	286.611
2444.84	288.713
2446	284.183
2447.15	286.409
2448.31	287.39
2449.46	282.705
2450.61	286.86
2451.77	294.771
2452.92	291.913
2454.07	289.064
2455.22	291.316
2456.38	293.548
2457.53	284.163
2458.68	287.054
2459.83	285.348
2460.98	291.215
2462.14	290.253
2463.29	291.324
2464.43	287.233
2465.59	293.005
2466.74	288.13
2467.88	292.841
2469.03	299.429
2470.18	290.028
2471.33	286.356
2472.48	290.5
2473.63	293.382
2474.78	288.826
2475.92	289.409
2477.07	297.213
2478.22	293.143
2479.37	294.728
2480.51	285.782
2481.66	286.477
2482.81	289.328
2483.95	286.374
2485.1	289.232
2486.24	291.217
2487.39	286.215
2488.53	288.92
2489.68	293.611
2490.82	286.945
2491.97	288.66
2493.11	288.966
2494.25	295.382
2495.4	292.334
2496.54	287.736
2497.69	288.293
2498.83	288.547
2499.97	289.453
2501.11	296.542
2502.25	284.876
2503.4	285.743
2504.54	285.515
2505.68	289.273
2506.82	288.539
2507.96	283.844
2509.1	289.525
2510.24	286.315
2511.38	292.295
2512.52	291.2
2513.66	283.812
2514.8	292.197
2515.94	287.908
2517.08	286.472
2518.21	297.467
2519.35	282.339
2520.49	287.322
2521.63	288.34
2522.77	291.789
2523.9	286.081
2525.04	291.56
2526.18	289.12
2527.31	286.103
2528.45	289.009
2529.58	282.58
2530.72	291.883
2531.86	285.096
2532.99	285.79
2534.13	286.857
2535.26	296.048
2536.4	288.516
2537.53	289.251
2538.66	284.269
2539.8	289.614
2540.93	290.503
2542.06	283.277
2543.2	287.102
2544.33	288.759
2545.46	284.099
2546.59	279.294
2547.73	291.471
2548.86	285.07
2549.99	284.381
2551.12	282.757
2552.25	296.053
2553.38	289.371
2554.51	282.802
2555.64	289.601
2556.77	290.046
2557.9	290.162
2559.03	289.252
2560.16	281.649
2561.29	291.066
2562.42	294.994
2563.55	293.596
2564.67	288.444
2565.8	284.701
2566.93	287.569
2568.06	295.088
2569.18	288.554
2570.31	293.523
2571.44	291.232
2572.56	286.981
2573.69	287.243
2574.81	292.745
2575.94	302.524
2577.06	287.575
2578.19	288.018
2579.31	293.182
2580.44	294.385
2581.56	296.43
2582.69	290.802
2583.81	288.027
2584.94	285.336
2586.06	290.588
2587.18	289.091
2588.3	294.514
2589.43	296.542
2590.55	291.739
2591.67	298.499
2592.79	301.647
2593.91	292.397
2595.04	293.605
2596.16	295.659
2597.28	295.248
2598.4	304.73
2599.52	294.507
2600.64	291.699
2601.76	290.296
2602.88	297.043
2604	298.049
2605.12	292.346
2606.24	298.201
2607.35	301.267
2608.47	298.827
2609.59	296.097
2610.71	301.065
2611.83	294.182
2612.94	298.906
2614.06	298.114
2615.18	299.629
2616.29	296.902
2617.41	301.906
2618.53	296.156
2619.64	305.454
2620.76	297.286
2621.87	300.741
2622.99	300.862
2624.1	293.164
2625.22	300.991
2626.33	299.212
2627.45	300.316
2628.56	296.383
2629.67	299.19
2630.79	294.423
2631.9	297.471
2633.01	293.533
2634.12	301.156
2635.24	293.831
2636.35	298.254
2637.46	295.91
2638.57	300.756
2639.68	292.146
2640.8	305.147
2641.91	294.785
2643.02	292.196
2644.13	297.716
2645.24	296.498
2646.35	299.247
2647.46	293.29
2648.57	295.67
2649.67	290.656
2650.78	301.219
2651.89	299.013
2653	293.126
2654.11	293.925
2655.22	287.826
2656.32	291.672
2657.43	296.622
2658.54	287.76
2659.65	293.012
2660.75	291.058
2661.86	291.663
2662.96	290.936
2664.07	287.841
2665.18	291.561
2666.28	293.378
2667.39	287.467
2668.49	294.717
2669.6	298.442
2670.7	294.693
2671.8	295.414
2672.91	292.142
2674.01	288.09
2675.11	288.317
2676.22	287.788
2677.32	286.597
2678.42	292.077
2679.53	286.207
2680.63	287.05
2681.73	293.773
2682.83	283.035
2683.93	290.659
2685.03	284.01
2686.14	290.728
2687.24	286.654
2688.34	282.359
2689.44	290.603
2690.54	289.366
2691.64	288.169
2692.74	285.139
2693.84	284.742
2694.93	287.512
2696.03	286.818
2697.13	288.007
2698.23	285.067
2699.33	286.481
2700.43	282.958
2701.52	279.433
2702.62	284.897
2703.72	282.1
2704.81	290.687
2705.9	284.697
2707.01	292.213
2708.12	291.053
2709.23	283.651
2710.34	288.445
2711.45	289.247
2712.56	284.133
2713.67	283.3
2714.78	286.599
2715.89	281.913
2716.99	284.508
2718.1	280.771
2719.21	283.855
2720.32	290.867
2721.43	288.157
2722.54	295.472
2723.64	289.792
2724.75	290.101
2725.86	296.591
2726.96	289.968
2728.07	280.693
2729.18	287.371
2730.28	291.397
2731.39	282.293
2732.49	284.132
2733.6	284.843
2734.71	285.826
2735.81	287.189
2736.91	288.279
2738.02	286.378
2739.12	290.31
2740.23	295.865
2741.33	291.955
2742.43	287.612
2743.54	287.034
2744.64	285.528
2745.74	290.233
2746.84	294.748
2747.95	280.574
2749.05	286.337
2750.15	290.132
2751.25	294.189
2752.35	285.103
2753.45	284.27
2754.55	290.793
2755.66	293.522
2756.76	284.238
2757.86	287.235
2758.96	291.962
2760.05	286.225
2761.15	293.241
2762.25	291.855
2763.35	286.383
2764.45	289.502
2765.55	289.434
2766.65	293.048
2767.75	295.675
2768.84	292.809
2769.94	304.393
2771.04	285.467
2772.13	288.926
2773.23	282.3
2774.33	292.381
2775.42	290.388
2776.52	291.132
2777.61	291.1
2778.71	293.05
2779.81	290.867
2780.9	284.166
2782	291.842
2783.09	295.424
2784.18	288.538
2785.28	289.677
2786.37	290.818
2787.47	292.484
2788.56	291.128
2789.65	286.225
2790.74	286.118
2791.84	288.729
2792.93	289.827
2794.02	289.714
2795.11	287.879
2796.2	293.354
2797.3	290.394
2798.39	284.562
2799.48	292.284
2800.57	291.244
2801.66	280.764
2802.75	296.032
2803.84	290.997
2804.93	286.002
2806.02	289.853
2807.11	284.145
2808.2	288.802
2809.28	288.726
2810.37	294.283
2811.46	283.598
2812.55	289.945
2813.64	284.438
2814.73	289.007
2815.81	293.522
2816.9	287.764
2817.99	285.527
2819.07	280.633
2820.16	286.664
2821.25	284.313
2822.33	291.704
2823.42	282.144
2824.5	280.367
2825.59	285.879
2826.67	287.954
2827.76	299.398
2828.84	297.153
2829.93	283.045
2831.01	285.96
2832.09	285.749
2833.18	291.186
2834.26	286.547
2835.34	287.694
2836.43	293.478
2837.51	284.081
2838.59	293.383
2839.67	292.617
2840.75	288.442
2841.84	289.299
2842.92	280.645
2844	298.301
2845.08	289.754
2846.16	287.246
2847.24	287.475
2848.32	287.138
2849.4	283.483
2850.48	286.508
2851.56	287.559
2852.64	287.473
2853.72	289.437
2854.8	285.757
2855.87	291.411
2856.95	287.632
2858.03	291.481
2859.11	290.522
2860.19	292.417
2861.26	297.595
2862.34	292.299
2863.42	285.494
2864.49	292.857
2865.57	293.003
2866.65	295.111
2867.72	289.519
2868.8	291.802
2869.87	291.714
2870.95	298.333
2872.02	292.524
2873.1	286.923
2874.17	306.205
2875.25	294.249
2876.32	290.404
2877.4	283.812
2878.47	294.379
2879.54	293.273
2880.62	288.542
2881.69	293.572
2882.76	290.851
2883.83	295.26
2884.9	293.632
2885.98	292.902
2887.05	296.796
2888.12	291.433
2889.19	291.573
2890.26	297.218
2891.33	299.071
2892.4	291.588
2893.47	292.788
2894.54	293.389
2895.61	294.864
2896.68	291.888
2897.75	293.839
2898.82	289.145
2899.89	291.275
2900.96	296.091
2902.03	290.307
2903.09	294.179
2904.16	292.515
2905.23	299.304
2906.3	298.081
2907.36	291.29
2908.43	292.416
2909.5	289.476
2910.57	289.57
2911.63	308.715
2912.7	295.477
2913.76	297.291
2914.83	293.314
2915.89	294.274
2916.96	298.12
2918.02	291.463
2919.09	290.448
2920.15	290.246
2921.22	290.996
2922.28	291.764
2923.34	297.436
2924.41	290.779
2925.47	294.554
2926.53	294.489
2927.6	296.322
2928.66	292.394
2929.72	294.783
2930.78	297.35
2931.84	294.637
2932.91	293.429
2933.97	291.663
2935.03	295.26
2936.09	299.849
2937.15	292.363
2938.21	290.414
2939.27	296.77
2940.33	294.968
2941.39	291.735
2942.45	290.06
2943.51	297.789
2944.57	291.403
2945.63	289.882
2946.68	296.089
2947.74	301.917
2948.8	294.323
2949.86	298.856
2950.92	287.589
2951.97	291.479
2953.03	299.886
2954.09	290.108
2955.14	297.398
2956.2	292.663
2957.25	289.942
2958.31	292.816
2959.37	293.767
2960.42	287.038
2961.48	298.245
2962.53	284.664
2963.59	292.393
2964.64	294.522
2965.7	286.81
2966.75	297.842
2967.8	295.729
2968.86	297.686
2969.91	291.141
2970.96	294.035
2972.02	293.119
2973.07	300.673
2974.12	287.412
2975.17	289.167
2976.22	287.294
2977.28	294.928
2978.33	295.149
2979.38	286.773
2980.43	285.704
2981.48	287.485
2982.53	290.125
2983.58	290.897
2984.63	296.395
2985.68	286.989
2986.73	297.512
2987.78	286.288
2988.83	295.836
2989.88	292.063
2990.93	290.194
2991.98	295.998
2993.02	292.15
2994.07	296.794
2995.12	296.099
2996.17	290.789
2997.21	294.664
2998.26	286.338
2999.31	294.882
2999.94	292.91