File: Data/3-Raman/raw/bu32-a-incc-fi03-l_150 (500nm)_532nm_edge_100%_x100_vis_lwd_h30um_15sx2_01.txt
#Acq. time (s)=	15
#Accumulations=	2
#Range (cm-¹)=	99...4000
#Windows=	1
#Auto scanning=	Off
#Autofocus=	Off
#Macrospot=	Off
#AutoExposure=	Off
#Spike filter=	Multiple accum.
#Delay time (s)=	2
#Binning=	1
#Readout mode=	Signal
#DeNoise=	Off
#ICS correction=	On
#Dark correction=	Off
#Inst. Process=	Off
#Detector Gain=	Best Dynamic
#Detector ADC=	50 kHz HS
#Detector temperature (°C)=	-60.09
#Instrument=	LabRAM HR Evol
#Detector=	SIN-EM FIVIS
#Objective=	x100_VIS_LWD
#Grating=	150 (500nm)
#ND Filter=	100%
#Laser=	532nm_Edge
#Hole=	30.0125
#Temperature=	0
#Range=	Visible
#StageXY=	75x50mm Scan+
#StageZ=	Z motor
#X (µm)=	0
#Y (µm)=	0
#Z (µm)=	9
#Full time(s)=	34
#Project=	21_11_26
#Sample=	BU32
#Site=
#Title=	BU32-A-incC-FI03-L_150 (500nm)_532nm_Edge_100%_x100_VIS_LWD_H30um_15sX2
#Remark=
#Date=	26.11.2021 17:19
#Acquired=	26.11.2021 17:19:14
102.91	1518.4
107.534	1494.55
112.156	1427.93
116.775	1379.25
121.392	1349.06
126.005	1363.48
130.617	1325.33
135.227	1317.29
139.835	1249.1
144.439	1230.46
149.042	1189.73
153.643	1143.03
158.242	1107.72
162.839	1071.43
167.431	996.113
172.023	990.75
176.613	926.832
181.198	886.32
185.783	844.665
190.366	839.752
194.947	847.099
199.524	816.534
204.1	810.403
208.674	809.116
213.243	787.047
217.813	816.356
222.38	751.497
226.945	750.153
231.506	736.417
236.066	721.405
240.625	711.211
245.179	666.742
249.732	680.802
254.284	704.52
258.831	748.876
263.378	740.887
267.923	739.002
272.464	693.452
277.004	645.599
281.54	619.784
286.076	571.268
290.61	569.228
295.139	555.365
299.669	528.166
304.196	493.605
308.718	507.52
313.241	494.867
317.759	512.589
322.278	490.734
326.794	475.064
331.305	474.441
335.817	500.761
340.324	479.606
344.832	518.287
349.334	463.232
353.837	499.892
358.338	482.697
362.834	483.03
367.33	447.113
371.822	482.391
376.314	470.795
380.802	476.831
385.289	485.669
389.772	514.153
394.255	526.909
398.734	552.386
403.213	585.499
407.688	587.701
412.162	587.915
416.632	595.423
421.102	589.103
425.568	615.256
430.033	666.98
434.495	773.878
438.956	850.721
443.413	891.388
447.87	888.328
452.323	972.25
456.776	1040.97
461.224	1106.54
465.673	1129.89
470.117	1002.18
474.561	897.429
479.001	759.564
483.438	719.778
487.876	653.239
492.309	652.351
496.742	649.626
501.172	618.979
505.601	558.107
510.025	525.57
514.448	510.384
518.871	479.027
523.289	453.618
527.707	451.443
532.121	453.984
536.533	486.72
540.945	570.489
545.353	657.826
549.758	744.159
554.164	953.544
558.565	1152.06
562.965	1020.8
567.364	790.384
571.759	709.443
576.151	652.837
580.544	681.096
584.933	763.662
589.319	856.706
593.706	871.569
598.088	835.42
602.468	767.978
606.848	787.401
611.224	777
615.598	742.547
619.972	715.657
624.341	643.702
628.709	605.907
633.074	544.461
637.44	510.197
641.801	466.998
646.16	476.218
650.517	448.678
654.874	443.773
659.227	444.791
663.578	447.223
667.927	421.147
672.275	426.782
676.62	398.431
680.962	383.72
685.302	355.581
689.643	375.589
693.979	351.557
698.313	344.862
702.645	354.996
706.975	337.893
711.305	345.557
715.631	362.152
719.955	353.75
724.276	354.163
728.596	346.22
732.913	348.612
737.231	344.546
741.544	349.996
745.856	347.108
750.165	354.14
754.472	356.178
758.778	346.044
763.081	357.297
767.384	351.495
771.683	356.347
775.98	337.307
780.275	353.075
784.568	356.726
788.859	347.398
793.147	341.505
797.434	354.14
801.719	347.106
806.004	345.849
810.284	344.725
814.563	360.152
818.839	352.546
823.114	368.037
827.386	358.324
831.657	371.766
835.925	348.858
840.192	351.261
844.456	350.315
848.719	359.17
852.979	358.984
857.237	376.435
861.493	380.637
865.748	378.157
870	393.152
874.25	380.566
878.499	377.787
882.745	366.173
886.989	379.572
891.231	367.625
895.471	377.315
899.71	363.768
903.946	408.55
908.18	385.534
912.412	412.973
916.642	427.609
920.87	474.504
925.096	519.989
929.321	592.937
933.543	697.497
937.763	810.315
941.981	1042.53
946.197	1248.2
950.412	1582.27
954.622	1924.24
958.832	2413.43
963.04	3236.59
967.246	4387.44
971.451	5174.75
975.653	4935.56
979.853	4250.21
984.052	3579.12
988.248	2952.98
992.442	2381.56
996.633	1986.54
1000.82	1663.23
1005.01	1462.63
1009.2	1247.91
1013.38	1106.03
1017.57	1030.62
1021.75	961.402
1025.92	903.573
1030.1	864.545
1034.27	832.682
1038.45	776.496
1042.62	760.456
1046.78	743.358
1050.95	704.82
1055.12	702.305
1059.28	729.202
1063.44	762.068
1067.6	765.077
1071.75	773.208
1075.91	758.219
1080.06	751.621
1084.21	705.384
1088.36	678.155
1092.51	680.128
1096.65	683.356
1100.8	738.123
1104.94	722.082
1109.08	671.674
1113.21	658.48
1117.35	661.766
1121.48	632.356
1125.61	594.364
1129.74	579.992
1133.87	557.549
1137.99	545.126
1142.12	519.27
1146.24	490.343
1150.36	476.631
1154.48	441.975
1158.59	456.624
1162.71	442.275
1166.82	410.234
1170.93	416.274
1175.04	392.266
1179.14	339.383
1183.25	346.269
1187.35	356.114
1191.45	357.515
1195.55	338.328
1199.65	326.263
1203.74	347.779
1207.83	340.712
1211.92	336.734
1216.01	338.854
1220.1	332.937
1224.19	330.112
1228.27	339.404
1232.35	318.761
1236.43	330.416
1240.51	329.255
1244.58	314.044
1248.66	334.906
1252.73	332.983
1256.8	340.124
1260.87	324.34
1264.93	341.593
1269	335.916
1273.06	333.287
1277.12	336.672
1281.18	331.011
1285.23	317.238
1289.29	325.523
1293.34	302.566
1297.39	318.824
1301.44	309.873
1305.49	313.959
1309.53	306.936
1313.58	338.181
1317.62	310.85
1321.66	330.808
1325.7	330.49
1329.73	331.132
1333.77	322.704
1337.8	329.223
1341.83	338.665
1345.86	345.041
1349.88	336.432
1353.91	341.792
1357.93	341.188
1361.95	352.456
1365.97	348.899
1369.99	376.047
1374	388.401
1378.02	361.35
1382.03	332.448
1386.04	309.644
1390.05	328.259
1394.05	306.603
1398.06	298.854
1402.06	304.866
1406.06	298.062
1410.06	293.254
1414.05	297.347
1418.05	315.263
1422.04	294.69
1426.03	307.638
1430.02	308.585
1434.01	313.506
1438	302.623
1441.98	299.644
1445.96	303.529
1449.94	302.46
1453.92	309.23
1457.9	298.217
1461.87	306.868
1465.85	309.499
1469.82	304.242
1473.78	291.181
1477.75	298.709
1481.72	299.321
1485.68	301.869
1489.65	303.41
1493.61	294.235
1497.56	299.71
1501.52	307.151
1505.47	310.738
1509.43	299.829
1513.38	295.755
1517.33	299.469
1521.27	309.033
1525.22	306.001
1529.16	309.782
1533.11	297.121
1537.05	306.765
1540.98	305.755
1544.92	306.684
1548.86	326.993
1552.79	303.702
1556.72	318.155
1560.65	317.06
1564.58	310.125
1568.5	308.968
1572.43	317.453
1576.35	319.162
1580.27	324.714
1584.19	317.714
1588.1	307.811
1592.02	326.795
1595.93	323.619
1599.84	325.254
1603.75	328.833
1607.66	333.418
1611.57	333.211
1615.47	332.07
1619.37	324.271
1623.27	334.653
1627.17	344.121
1631.07	336.404
1634.97	318.267
1638.86	338.402
1642.75	321.286
1646.64	330.093
1650.53	334.151
1654.42	329.594
1658.3	332.685
1662.18	328.079
1666.07	321.484
1669.94	338.882
1673.82	320.609
1677.7	326.35
1681.57	321.344
1685.44	312.423
1689.31	311.163
1693.18	328.039
1697.05	297.955
1700.92	316.615
1704.78	298.917
1708.64	310.719
1712.5	315.762
1716.36	310.361
1720.21	287.972
1724.07	295.884
1727.92	297.144
1731.77	309.627
1735.62	301.45
1739.47	299.824
1743.32	299.102
1747.16	296.537
1751.01	296.022
1754.85	291.904
1758.69	300.946
1762.52	295.636
1766.36	296.61
1770.19	284.692
1774.02	293.35
1777.85	284.351
1781.68	281.951
1785.51	291.726
1789.33	290.345
1793.16	275.859
1796.98	269.773
1800.8	290.913
1804.62	284.637
1808.43	294.335
1812.25	282.335
1816.06	274.982
1819.87	301.47
1823.68	290.142
1827.49	289.14
1831.3	273.915
1835.1	294.441
1838.9	294.174
1842.71	292.921
1846.51	286.905
1850.3	303.453
1854.1	305.765
1857.89	292.099
1861.69	285.857
1865.48	288.916
1869.27	296.632
1873.05	280.258
1876.84	306.545
1880.62	279.221
1884.4	277.911
1888.19	289.505
1891.96	281.165
1895.74	285.72
1899.52	293.955
1903.29	272.869
1907.06	289.571
1910.83	292.5
1914.6	287.243
1918.37	297.689
1922.13	296.333
1925.9	292.224
1929.66	291.863
1933.42	284.088
1937.18	282.796
1940.94	282.423
1944.69	290.459
1948.44	286.34
1952.2	290.427
1955.95	295.341
1959.69	296.349
1963.44	299.136
1967.19	301.904
1970.93	290.497
1974.67	297.752
1978.41	297.438
1982.15	301.751
1985.89	290.116
1989.62	283.145
1993.35	286.396
1997.09	298.873
2000.82	301.039
2004.55	286.545
2008.27	295.175
2012	291.712
2015.72	299.311
2019.44	295.089
2023.16	298.373
2026.88	306.411
2030.6	297.061
2034.31	304.335
2038.03	290.662
2041.74	294.353
2045.45	286.118
2049.16	298.033
2052.86	276.124
2056.57	297.278
2060.27	303.938
2063.98	291.522
2067.67	288.337
2071.37	284.242
2075.07	303.211
2078.77	288.057
2082.46	287.691
2086.15	290.069
2089.84	300.469
2093.53	293.086
2097.22	296.064
2100.9	298.993
2104.59	301.821
2108.27	299.945
2111.95	311.041
2115.63	288.655
2119.31	288.548
2122.98	281.826
2126.66	296.391
2130.33	302.538
2134	295.685
2137.67	310.087
2141.34	305.015
2145	293.462
2148.67	299.403
2152.33	294.3
2155.99	297.475
2159.65	303.397
2163.31	295.63
2166.96	287.932
2170.62	298.536
2174.27	295.58
2177.92	284.501
2181.57	289.851
2185.22	272.442
2188.87	296.954
2192.51	292.473
2196.15	285.378
2199.8	287.448
2203.44	276.786
2207.07	288.971
2210.71	302.149
2214.35	276.953
2217.98	288.375
2221.61	291.573
2225.24	302.155
2228.87	274.058
2232.5	294.78
2236.12	301.732
2239.75	294.813
2243.37	279.52
2246.99	286.453
2250.61	288.77
2254.23	282.743
2257.85	286.985
2261.46	296.846
2265.07	286.102
2268.68	277.226
2272.29	288.12
2275.9	286.735
2279.51	301.295
2283.11	288.319
2286.72	271.537
2290.32	290.644
2293.92	286.093
2297.52	285.33
2301.11	285.523
2304.71	296.09
2308.3	290.49
2311.9	289.585
2315.49	289.584
2319.08	282.899
2322.66	294.153
2326.25	294.8
2329.84	275.564
2333.42	287.495
2337	286.156
2340.58	294.197
2344.16	279.624
2347.73	292.272
2351.31	290.806
2354.88	287.46
2358.45	275.712
2362.03	281.683
2365.59	292.271
2369.16	279.649
2372.73	282.883
2376.29	294.402
2379.85	273.593
2383.41	283.288
2386.97	277.344
2390.53	267.788
2394.09	299.603
2397.64	279.185
2401.2	274.467
2404.75	280.901
2408.3	279.121
2411.85	285.713
2415.39	282.286
2418.94	270.65
2422.48	276.511
2426.03	286.141
2429.57	276.487
2433.11	272.403
2436.64	279.486
2440.18	289.415
2443.72	280.787
2447.25	283.326
2450.78	280.321
2454.31	274.531
2457.84	288.285
2461.37	268.871
2464.89	288.984
2468.42	290.962
2471.94	291.29
2475.46	289.249
2478.98	278.675
2482.5	272.872
2486.01	288.635
2489.53	275.972
2493.04	274.762
2496.55	280.905
2500.06	289.94
2503.57	287.629
2507.08	297.417
2510.58	290.326
2514.09	265.606
2517.59	284.691
2521.09	291.709
2524.59	283.692
2528.09	277.832
2531.59	294.227
2535.08	279.252
2538.58	293.905
2542.07	273.559
2545.56	289.335
2549.05	291.4
2552.54	282.389
2556.02	290.094
2559.51	265.524
2562.99	285.437
2566.47	281.364
2569.95	281.091
2573.43	296.78
2576.91	275.116
2580.38	275.942
2583.85	279.618
2587.33	286.153
2590.8	290.754
2594.27	295.226
2597.74	278.704
2601.2	276.517
2604.67	281.952
2608.13	274.777
2611.59	279.829
2615.06	281.812
2618.51	268.531
2621.97	286.836
2625.43	290.674
2628.88	268.495
2632.33	282.774
2635.79	285.453
2639.24	276.539
2642.69	274.296
2646.13	292.081
2649.58	288.793
2653.02	291.166
2656.47	281.087
2659.91	281.432
2663.35	281.744
2666.79	283.917
2670.22	272.876
2673.66	281.619
2677.09	282.861
2680.52	275.714
2683.95	285.476
2687.39	282.244
2690.81	268.949
2694.24	263.221
2697.66	276.067
2701.09	274.07
2704.51	275.806
2707.93	277.55
2711.35	277.63
2714.77	281.49
2718.18	275.168
2721.6	287.53
2725.01	277.561
2728.42	288.142
2731.84	280.062
2735.24	285.053
2738.65	286.306
2742.06	282.858
2745.46	282.163
2748.86	272.97
2752.27	274.111
2755.67	291.225
2759.07	280.083
2762.46	292.484
2765.86	282.202
2769.25	283.181
2772.65	269.977
2776.04	279.365
2779.43	259.501
2782.82	281.982
2786.2	279.954
2789.59	297.669
2792.98	278.694
2796.36	285.097
2799.74	295.246
2803.12	282.819
2806.5	282.6
2809.88	287.994
2813.25	291.491
2816.63	293.094
2820	283.48
2823.37	297.26
2826.74	279.348
2830.11	287.581
2833.48	287.458
2836.84	282.731
2840.21	269.671
2843.57	285.543
2846.93	287.512
2850.29	282.126
2853.65	294.534
2857.01	280.767
2860.36	279.172
2863.72	295.397
2867.07	293.861
2870.42	290.446
2873.77	281.367
2877.12	272.258
2880.47	279.128
2883.81	295.425
2887.16	284.376
2890.5	294.068
2893.84	280.14
2897.18	291.648
2900.52	301.235
2903.86	289.968
2907.19	282.444
2910.53	307.068
2913.86	307.067
2917.19	301.367
2920.52	284.272
2923.85	283.247
2927.18	297.323
2930.51	307.563
2933.83	289.426
2937.15	303.353
2940.48	300.287
2943.8	305.705
2947.11	306.417
2950.43	303.376
2953.75	292.807
2957.06	315.139
2960.38	312.148
2963.69	284.79
2967	316.566
2970.31	319.347
2973.62	310.93
2976.92	313.781
2980.23	317.622
2983.53	303.597
2986.84	312.114
2990.14	329.104
2993.44	301.031
2996.73	319.936
3000.03	321.012
3003.33	328.668
3006.62	315.634
3009.91	321.439
3013.2	327.266
3016.49	322.742
3019.78	312.547
3023.07	333.465
3026.35	333.643
3029.64	347.991
3032.92	343.451
3036.2	330.381
3039.48	346.607
3042.76	338.251
3046.04	351.665
3049.32	360.359
3052.59	364.324
3055.86	337.019
3059.14	372.27
3062.41	378.017
3065.68	373.386
3068.94	369.655
3072.21	376.282
3075.48	369.303
3078.74	380.72
3082	387.273
3085.26	393.211
3088.52	400.085
3091.78	406.129
3095.04	400.798
3098.29	390.201
3101.55	405.526
3104.8	421.73
3108.05	417.211
3111.3	425.001
3114.55	428.852
3117.8	415.602
3121.04	440.453
3124.29	419.591
3127.53	455.878
3130.77	456.906
3134.02	458.896
3137.25	456.106
3140.49	471.403
3143.73	494.324
3146.96	493.415
3150.2	507.796
3153.43	521.238
3156.66	527.985
3159.89	511.85
3163.12	533.861
3166.35	540.609
3169.57	518.679
3172.8	540.608
3176.02	566.329
3179.24	569.099
3182.46	578.538
3185.68	605.152
3188.9	584.011
3192.12	610.526
3195.33	594.141
3198.55	606.337
3201.76	638.509
3204.97	650.696
3208.18	646.719
3211.39	621.84
3214.6	652.195
3217.8	643.582
3221.01	674.926
3224.21	664.436
3227.41	689.209
3230.61	704.488
3233.81	713.163
3237.01	709.422
3240.21	680.134
3243.4	732.759
3246.59	734.971
3249.79	735.282
3252.98	729.945
3256.17	737.024
3259.36	750.778
3262.54	741.518
3265.73	768.443
3268.92	770.431
3272.1	760.879
3275.28	780.895
3278.46	779.882
3281.64	800.668
3284.82	793.616
3288	788.495
3291.17	814.778
3294.35	807.744
3297.52	812.116
3300.69	828.878
3303.86	820.113
3307.03	827.317
3310.2	835.384
3313.36	848.062
3316.53	840.73
3319.69	888.412
3322.85	874.37
3326.02	848.998
3329.18	902.21
3332.33	933.609
3335.49	929.126
3338.65	911.512
3341.8	949.654
3344.95	921.768
3348.11	955.411
3351.26	957.225
3354.41	926.037
3357.56	996.753
3360.7	982.693
3363.85	966.861
3366.99	1006.68
3370.13	1022.06
3373.28	1015.78
3376.42	1023.78
3379.56	1049.77
3382.69	1057.89
3385.83	1056.51
3388.97	1067.52
3392.1	1080.45
3395.23	1103.75
3398.36	1109.75
3401.49	1107.84
3404.62	1125.95
3407.75	1094.81
3410.88	1154.95
3414	1124.75
3417.13	1125.67
3420.25	1154.16
3423.37	1173.04
3426.49	1158.29
3429.61	1179.6
3432.73	1152.06
3435.84	1181.56
3438.96	1181.2
3442.07	1167.62
3445.18	1161.65
3448.29	1155.44
3451.4	1158.74
3454.51	1157.11
3457.62	1164.97
3460.72	1143.16
3463.83	1149.88
3466.93	1133.73
3470.03	1125.98
3473.13	1121.84
3476.23	1136.04
3479.33	1121.9
3482.43	1115.39
3485.53	1114.59
3488.62	1078.93
3491.71	1091.61
3494.81	1099.87
3497.9	1059.96
3500.99	1060.56
3504.07	1048.93
3507.16	1028.66
3510.25	1031
3513.33	1018.9
3516.41	990.079
3519.5	1002.53
3522.58	969.316
3525.66	950.864
3528.73	958.307
3531.81	936.051
3534.89	919.24
3537.96	899.159
3541.03	884.837
3544.11	868.06
3547.18	843.584
3550.25	851.809
3553.32	859.833
3556.38	825.227
3559.45	820.062
3562.51	788.378
3565.58	770.708
3568.64	774.703
3571.7	749.555
3574.76	754.374
3577.82	725.084
3580.87	714.699
3583.93	708.997
3586.98	703.229
3590.04	668.06
3593.09	674.534
3596.14	676.248
3599.19	654.212
3602.24	643.558
3605.29	630.949
3608.33	612.628
3611.38	598.104
3614.42	596.794
3617.46	589.796
3620.5	580.946
3623.54	573.076
3626.58	560.518
3629.62	525.389
3632.65	522.29
3635.69	501.281
3638.72	500.179
3641.76	495.38
3644.79	475.588
3647.82	456.856
3650.84	469.987
3653.87	450.248
3656.9	444.998
3659.92	415.335
3662.95	412.88
3665.97	399.979
3668.99	386.881
3672.01	370.093
3675.03	366.513
3678.05	368.615
3681.07	352.794
3684.08	353
3687.1	335.244
3690.11	335.455
3693.12	305.375
3696.13	311.265
3699.14	307.62
3702.15	294.551
3705.16	307.095
3708.16	279.755
3711.17	289.416
3714.17	289.555
3717.17	288.707
3720.17	296.443
3723.17	264.166
3726.17	274.697
3729.17	277.588
3732.16	271.889
3735.16	275.685
3738.15	274.689
3741.14	249.872
3744.13	267.859
3747.13	254.422
3750.11	256.183
3753.1	270.271
3756.09	252.06
3759.07	265.187
3762.06	255.534
3765.04	255.348
3768.02	255.168
3771	266.363
3773.98	250.144
3776.96	266.1
3779.94	255.6
3782.91	244.18
3785.89	249.768
3788.86	244.982
3791.83	243.047
3794.8	256.251
3797.77	247.768
3800.74	249.682
3803.71	248.798
3806.68	252.649
3809.64	252.731
3812.61	242.432
3815.57	249.15
3818.53	250.205
3821.49	244.646
3824.45	254.239
3827.41	235.437
3830.36	241.263
3833.32	234.764
3836.27	251.06
3839.23	239.846
3842.18	253.33
3845.13	224.024
3848.08	231.808
3851.03	237.708
3853.98	242.678
3856.92	249.57
3859.87	234.508
3862.81	234.717
3865.75	244.482
3868.7	240.856
3871.64	243.912
3874.57	241.211
3877.51	243.294
3880.45	238.63
3883.39	242.582
3886.32	237.858
3889.25	226.384
3892.18	242.78
3895.12	244.744
3898.05	221.673
3900.97	241.85
3903.9	232.21
3906.83	247.538
3909.75	246.55
3912.68	245.538
3915.6	232.974
3918.52	235.77
3921.44	236.686
3924.36	236.593
3927.28	242.23
3930.2	222.91
3933.11	250.553
3936.03	220.762
3938.94	229.338
3941.86	239.868
3944.77	234.097
3947.68	243.659
3950.59	238.884
3953.49	228.38
3956.4	237.037
3959.31	241.888
3962.21	221.838
3965.12	240.129
3968.02	237.351
3970.92	229.785
3973.82	223.178
3976.72	223.282
3979.61	224.332
3982.51	232.095
3985.41	223.516
3988.3	233.191
3991.19	232.283
3994.09	223.651
3996.98	230.453
3999.87	226.668