File: Data/3-Raman/raw/bu32-b-ff2-fi02-v_1800 (450-850nm)_532nm_edge_100%_x100_vis_lwd_h30um_30sx2_01.txt
#Acq. time (s)=	30
#Accumulations=	2
#Range (cm-¹)=	1200...2999
#Windows=	5
#Auto scanning=	Off
#Autofocus=	Off
#Macrospot=	Off
#AutoExposure=	Off
#Spike filter=	Multiple accum.
#Delay time (s)=	2
#Binning=	1
#Readout mode=	Signal
#DeNoise=	Off
#ICS correction=	On
#Dark correction=	Off
#Inst. Process=	Off
#Detector Gain=	Best Dynamic
#Detector ADC=	50 kHz EM
#Detector EM gain=	150
#Detector temperature (°C)=	-60.09
#Instrument=	LabRAM HR Evol
#Detector=	SIN-EM FIVIS
#Objective=	x100_VIS_LWD
#Grating=	1800 (450-850nm)
#ND Filter=	100%
#Laser=	532nm_Edge
#Hole=	30.0125
#Temperature=	40
#Range=	Visible
#StageXY=	75x50mm Scan+
#StageZ=	Z motor
#X (µm)=	0
#Y (µm)=	0
#Z (µm)=	65
#Full time(mm:ss)=	5:33
#Project=	21_08_11
#Sample=	BU32
#Site=
#Title=	BU32-B-FF2-FI02-V_1800 (450-850nm)_532nm_Edge_100%_x100_VIS_LWD_H30um_30sX2
#Remark=
#Date=	13.08.2021 16:12
#Acquired=	13.08.2021 16:12:23
1200.05	359.941
1201.44	353.699
1202.83	354.241
1204.22	360.165
1205.61	355.189
1207	350.171
1208.39	339.063
1209.78	355.923
1211.16	351.013
1212.55	345.111
1213.94	351.334
1215.33	342.767
1216.71	346.42
1218.1	345.987
1219.49	344.722
1220.87	333.996
1222.26	338.691
1223.64	349.612
1225.03	344.152
1226.41	342.025
1227.79	342.122
1229.18	340.916
1230.56	341.137
1231.94	340.415
1233.33	341.411
1234.71	344.763
1236.09	333.26
1237.47	353.786
1238.86	358.558
1240.24	346.959
1241.62	340.571
1243	354.315
1244.38	345.896
1245.76	347.542
1247.14	334.911
1248.52	343.055
1249.9	340.897
1251.27	334.278
1252.65	348.57
1254.03	342.456
1255.41	353.989
1256.79	338.421
1258.16	353.914
1259.54	339.44
1260.92	362.997
1262.29	356.201
1263.67	386.8
1265.04	374.141
1266.42	354.341
1267.79	346.51
1269.17	352.045
1270.54	351.64
1271.92	343.388
1273.29	362.754
1274.66	347.19
1276.04	353.787
1277.41	343.654
1278.78	352.424
1280.15	352.345
1281.53	369.46
1282.9	497.251
1284.27	1320.29
1285.64	501.264
1287.01	387.387
1288.38	352.57
1289.75	359.209
1291.12	345.455
1292.49	359.115
1293.86	346.943
1295.23	342.018
1296.6	349.841
1297.96	347.457
1299.33	352.555
1300.7	361.086
1302.07	355.983
1303.43	348.454
1304.8	337.808
1306.17	340.64
1307.53	342.781
1308.9	346.066
1310.26	344.016
1311.63	346.262
1312.99	343.099
1314.36	349.431
1315.72	354.884
1317.08	355.939
1318.45	360.256
1319.81	351.8
1321.17	338.79
1322.53	340.604
1323.9	342.689
1325.26	343.546
1326.62	351.464
1327.98	335.361
1329.34	346.048
1330.7	348.904
1332.06	346.194
1333.42	347.74
1334.78	350.475
1336.14	343.9
1337.5	353.118
1338.86	337.161
1340.22	353.981
1341.58	349.661
1342.93	347.234
1344.29	348.244
1345.65	337.364
1347	342.003
1348.36	351.165
1349.72	350.845
1351.07	337.986
1352.43	340.232
1353.78	359.891
1355.14	353.11
1356.49	347.935
1357.85	354.952
1359.2	341.175
1360.56	343.907
1361.91	357.257
1363.26	344.902
1364.61	364.511
1365.97	346.516
1367.32	342.103
1368.67	342.226
1370.02	373.063
1371.37	350.908
1372.72	345.291
1374.07	361.62
1375.42	353.354
1376.77	340.595
1378.12	349.447
1379.47	350.386
1380.82	363.09
1382.17	351.088
1383.52	352.672
1384.87	397.129
1386.21	486.868
1387.56	2142.95
1388.91	525.69
1390.26	390.701
1391.6	362.609
1392.95	359.265
1394.3	368.35
1395.64	343.939
1396.99	345.754
1398.33	337.613
1399.68	335.715
1401.02	359.465
1402.37	357.074
1403.71	351.892
1405.05	354.816
1406.39	351.566
1407.74	374.246
1409.08	461.585
1410.42	372.102
1411.76	353.479
1413.11	344.018
1414.45	345.969
1415.79	344.005
1417.13	342.147
1418.47	341.19
1419.81	345.099
1421.15	347.95
1422.49	357.97
1423.83	333.021
1425.17	340.43
1426.51	346.506
1427.84	349.141
1429.18	339.045
1430.52	349.78
1431.86	344.736
1433.19	356.483
1434.53	368.897
1435.87	344.253
1437.2	346.174
1438.54	337.049
1439.87	342.463
1441.21	339.376
1442.54	336.382
1443.88	348.547
1445.21	337.519
1446.55	332.267
1447.88	344.508
1449.21	337.383
1450.55	332.072
1451.88	350.383
1453.21	335.122
1454.54	335.08
1455.88	338.236
1457.21	342.156
1458.54	344.24
1459.87	352.409
1461.2	350.167
1462.53	342.672
1463.86	334.555
1465.19	341.929
1466.52	336.631
1467.85	343.759
1469.18	343.611
1470.51	330.102
1471.83	346.209
1473.16	338.949
1474.49	336.895
1475.82	341.879
1477.14	326.447
1478.47	338.451
1479.79	327.933
1481.12	330.738
1482.45	347.223
1483.77	330.927
1485.1	340.659
1486.42	332.316
1487.75	333.148
1489.07	330.843
1490.39	335.776
1491.72	349.822
1493.04	334.599
1494.36	333.623
1495.69	343.301
1497.01	337.101
1498.33	334.063
1499.65	337.203
1500.97	338.095
1502.29	337.962
1503.62	332.767
1504.93	328.671
1506.26	329.429
1507.58	338.569
1508.89	332.523
1510.21	339.52
1511.53	332.848
1512.85	334.311
1514.17	327.455
1515.49	331.04
1516.81	336.881
1518.12	323.972
1519.44	348.141
1520.76	328.098
1522.07	317.978
1523.39	337.64
1524.71	342.5
1526.02	326.741
1527.34	331.698
1528.65	328.545
1529.97	325.468
1531.28	342.682
1532.59	337.86
1533.91	336.043
1535.22	328.736
1536.54	328.213
1537.85	331.927
1539.16	335.326
1540.47	346.003
1541.79	336.566
1543.1	337.154
1544.41	321.195
1545.72	319.554
1547.03	330.686
1548.34	331.613
1549.65	334.247
1550.96	340.399
1552.27	333.44
1553.58	331.972
1554.89	336.58
1556.2	333.545
1557.5	326.536
1558.81	327.05
1560.12	327.805
1561.43	333.92
1562.74	328.025
1564.04	349.266
1565.35	335.165
1566.65	334.82
1567.96	345.953
1569.27	336.761
1570.57	327.793
1571.88	332.606
1573.18	331.341
1574.48	333.618
1575.79	329.771
1577.09	322.311
1578.4	331.978
1579.7	340.042
1581	335.928
1582.3	331.723
1583.61	319.69
1584.91	335.675
1586.21	325.471
1587.51	336.28
1588.81	325.522
1590.11	335.583
1591.41	332.581
1592.72	317.253
1594.01	331.738
1595.31	335.726
1596.61	325.806
1597.91	335.724
1599.21	333.386
1600.51	337.376
1601.81	325.026
1603.1	334.304
1604.4	329.878
1605.7	328.313
1607	323.72
1608.29	323.293
1609.59	318.745
1610.88	330.037
1612.18	323.163
1613.48	329.203
1614.77	329.755
1616.07	329.525
1617.36	321.919
1618.65	324.565
1619.95	323.881
1621.24	322.544
1622.54	316.941
1623.83	321.521
1625.12	318.238
1626.41	324.67
1627.56	318.286
1628.87	317.289
1630.17	314.23
1631.48	324.212
1632.79	318.366
1634.1	323.304
1635.4	316.334
1636.71	308.239
1638.01	321.885
1639.32	312.037
1640.62	320.031
1641.93	310.088
1643.23	319.878
1644.54	323.659
1645.84	321.748
1647.15	317.662
1648.45	321.76
1649.75	316.979
1651.05	329.132
1652.36	334.03
1653.66	315.341
1654.96	324.415
1656.26	326.733
1657.56	318.743
1658.86	311.634
1660.16	319.48
1661.46	330.617
1662.77	324.158
1664.07	320.857
1665.36	324.957
1666.66	314.669
1667.96	317.655
1669.26	325.963
1670.56	320.278
1671.86	323.239
1673.15	321.301
1674.45	316.562
1675.75	321.63
1677.05	325.593
1678.34	326.304
1679.64	324.162
1680.94	325.026
1682.23	322.065
1683.53	307.211
1684.82	320.926
1686.12	321.983
1687.41	328.893
1688.71	324.715
1690	316.632
1691.29	313.843
1692.59	326.522
1693.88	316.277
1695.17	323.136
1696.47	321.263
1697.76	318.952
1699.05	316.837
1700.34	326.617
1701.63	330.349
1702.92	311.485
1704.21	311.504
1705.5	304.576
1706.79	315.026
1708.08	320.427
1709.37	320.113
1710.66	325.117
1711.95	314.353
1713.24	314.697
1714.53	316.449
1715.82	314.578
1717.11	318.957
1718.39	318.401
1719.68	317.429
1720.97	323.965
1722.25	318.709
1723.54	328.209
1724.83	313.296
1726.11	309.145
1727.4	316.785
1728.68	309.781
1729.97	314.758
1731.25	323.765
1732.54	318.768
1733.82	323.049
1735.1	310.039
1736.39	321.384
1737.67	320.18
1738.95	314.991
1740.24	312.465
1741.52	313.11
1742.8	316.824
1744.08	310.863
1745.36	314.666
1746.65	316.205
1747.93	313.093
1749.21	312.293
1750.49	309.718
1751.77	301.854
1753.05	312.033
1754.33	316.515
1755.6	316.261
1756.88	310.111
1758.16	319.715
1759.44	306.412
1760.72	310.038
1762	315.603
1763.27	316.636
1764.55	310.284
1765.83	316.085
1767.1	306.47
1768.38	308.179
1769.66	311.471
1770.93	317.494
1772.21	321.565
1773.48	316.04
1774.76	308.565
1776.03	305.066
1777.31	321.054
1778.58	313.102
1779.85	307.411
1781.13	309.425
1782.4	323.972
1783.67	314.66
1784.94	314.854
1786.22	312.927
1787.49	316.38
1788.76	317.993
1790.03	313.489
1791.3	313.17
1792.57	311.334
1793.84	322.932
1795.11	316.714
1796.38	320.866
1797.65	311.507
1798.92	322.059
1800.19	326.613
1801.46	309.301
1802.73	313.381
1804	310.709
1805.26	313.956
1806.53	313.225
1807.8	317.108
1809.07	324.882
1810.33	310.442
1811.6	323.928
1812.87	325.105
1814.13	330.304
1815.4	326.675
1816.66	320.938
1817.93	318.807
1819.19	325.752
1820.46	326.907
1821.72	325.196
1822.99	322.357
1824.25	320.433
1825.51	316.682
1826.77	316.74
1828.04	317.787
1829.3	319.596
1830.56	321.426
1831.82	319.709
1833.09	316.969
1834.35	314.785
1835.61	322.094
1836.87	314.904
1838.13	312.166
1839.39	318.862
1840.65	315.097
1841.91	311.582
1843.17	327.972
1844.43	325.077
1845.69	319.592
1846.94	320.611
1848.2	324.521
1849.46	314.568
1850.72	315.085
1851.97	321.677
1853.23	310.079
1854.49	314.496
1855.74	315.127
1857	325.601
1858.26	316.71
1859.51	303.062
1860.77	326.214
1862.02	316.678
1863.28	311.541
1864.53	323.661
1865.78	315.469
1867.04	322.436
1868.29	327.982
1869.54	307.021
1870.8	320.277
1872.05	321.034
1873.3	320.83
1874.56	323.321
1875.81	315.152
1877.06	314.523
1878.31	318.855
1879.56	314.344
1880.81	318.059
1882.06	312.5
1883.31	314.358
1884.56	314.029
1885.81	307.867
1887.06	305.69
1888.31	325.001
1889.56	308.753
1890.81	313.631
1892.05	316.375
1893.3	310.16
1894.55	316.595
1895.8	322.397
1897.04	316.995
1898.29	306.532
1899.54	315.654
1900.78	312.922
1902.03	310.426
1903.27	322.52
1904.52	315.87
1905.76	313.754
1907.01	305.198
1908.25	299.723
1909.5	316.988
1910.74	318.357
1911.98	314.579
1913.23	307.124
1914.47	312.235
1915.71	314.193
1916.96	317.736
1918.2	314.076
1919.44	318.389
1920.68	312.866
1921.92	331.018
1923.16	302.478
1924.41	317.43
1925.65	302.637
1926.89	308.682
1928.12	304.121
1929.36	313.92
1930.6	309.518
1931.84	314.114
1933.08	318.762
1934.32	319.835
1935.56	323.087
1936.8	319.059
1938.03	319.794
1939.27	316.279
1940.51	319.605
1941.75	312.68
1942.98	313.038
1944.22	317.957
1945.45	325.989
1946.69	318.482
1947.92	307.897
1949.16	316.714
1950.4	313.454
1951.63	323.575
1952.86	330.505
1954.1	321.079
1955.33	308.617
1956.56	322.647
1957.8	317.16
1959.03	318.04
1960.26	321.661
1961.5	320.537
1962.73	322.534
1963.96	315.93
1965.19	319.756
1966.42	322.938
1967.65	320.127
1968.88	321.876
1970.11	329.17
1971.34	313.631
1972.57	313.673
1973.8	322.059
1975.03	319.274
1976.26	319.43
1977.49	317.389
1978.72	313.423
1979.95	318.21
1981.17	322.79
1982.4	322.819
1983.63	322.997
1984.85	309.611
1986.08	318.791
1987.31	312.522
1988.53	326.519
1989.76	310.773
1990.98	321.464
1992.21	312.448
1993.43	314.543
1994.66	312.056
1995.88	312.186
1997.11	311.704
1998.33	309.414
1999.55	308.69
2000.78	306.235
2002	304.604
2003.22	309.264
2004.45	307.506
2005.59	301.471
2006.83	294.882
2008.06	308.664
2009.3	301.64
2010.54	304.216
2011.77	308.871
2013.01	303.781
2014.25	299.39
2015.48	307.967
2016.72	309.2
2017.95	319.039
2019.19	304.465
2020.42	298.752
2021.66	296.873
2022.89	307.774
2024.12	307.399
2025.36	306.919
2026.59	304.66
2027.82	313.7
2029.06	310.817
2030.29	306.65
2031.52	307.001
2032.75	308.426
2033.98	312.845
2035.21	312.052
2036.45	304.776
2037.68	301.933
2038.91	308.23
2040.14	303.186
2041.37	305.76
2042.6	309.323
2043.83	312.548
2045.05	315.323
2046.28	304.46
2047.51	298.297
2048.74	294.739
2049.97	306.381
2051.2	308.128
2052.42	299.842
2053.65	310.525
2054.88	308.646
2056.1	296.319
2057.33	314.154
2058.56	314.477
2059.78	307.032
2061.01	306.144
2062.23	309.986
2063.46	307.411
2064.68	317.016
2065.91	303.301
2067.13	310.974
2068.35	304.599
2069.58	301.459
2070.8	317.892
2072.02	310.734
2073.25	309.763
2074.47	309.989
2075.69	309.627
2076.91	299.08
2078.13	315.105
2079.35	308.869
2080.58	305.203
2081.8	314.642
2083.02	307.113
2084.24	319.401
2085.46	301.494
2086.68	307.49
2087.9	309.482
2089.12	311.535
2090.33	311.722
2091.55	309.17
2092.77	312.498
2093.99	315.65
2095.21	311.696
2096.43	304.923
2097.64	313.268
2098.86	309.389
2100.08	314.154
2101.29	313.441
2102.51	313.361
2103.73	314.204
2104.94	303.992
2106.16	302.299
2107.37	315.56
2108.59	305.727
2109.8	311.594
2111.01	307.77
2112.23	308.669
2113.44	314.616
2114.66	313.637
2115.87	319.172
2117.08	317.179
2118.29	299.779
2119.51	308.948
2120.72	309.941
2121.93	311.235
2123.14	318.044
2124.35	297.791
2125.57	307.653
2126.78	317.719
2127.99	312.881
2129.2	313.771
2130.41	311.779
2131.62	316.295
2132.82	314.221
2134.03	316.163
2135.24	309.484
2136.45	306.39
2137.66	315.909
2138.87	308.458
2140.08	307.095
2141.28	313.543
2142.49	308.863
2143.7	306.391
2144.9	311.223
2146.11	316.777
2147.32	315.654
2148.52	306.067
2149.73	310.335
2150.93	315.948
2152.14	306.67
2153.34	306.465
2154.55	320.006
2155.75	304.579
2156.96	303.623
2158.16	315.934
2159.36	310.129
2160.57	304.215
2161.77	300.4
2162.97	312.419
2164.17	310.3
2165.38	304.719
2166.58	319.444
2167.78	324.499
2168.98	304.127
2170.18	301.742
2171.38	311.516
2172.58	301.956
2173.78	300.182
2174.98	308.537
2176.18	317.708
2177.38	313.057
2178.58	307.314
2179.78	302.692
2180.98	307.259
2182.18	313.599
2183.38	307.717
2184.57	298.389
2185.77	311.565
2186.97	319.424
2188.16	310.073
2189.36	305.951
2190.56	318.015
2191.76	299.576
2192.95	296.075
2194.15	315.164
2195.34	311.243
2196.54	306.172
2197.73	312.62
2198.93	312.15
2200.12	310.973
2201.31	316.392
2202.51	326.513
2203.7	311.448
2204.89	307.944
2206.09	305.96
2207.28	321.858
2208.47	311.934
2209.67	295.233
2210.86	318.765
2212.05	315.305
2213.24	314.189
2214.43	305.232
2215.62	319.314
2216.81	305.277
2218	308.121
2219.19	302.745
2220.38	315.873
2221.57	309.955
2222.76	309.096
2223.95	319.795
2225.14	312.708
2226.33	314.913
2227.51	321.65
2228.7	306.554
2229.89	312.456
2231.08	319.384
2232.27	324.408
2233.45	313.413
2234.64	318.966
2235.82	316.936
2237.01	317.137
2238.2	306.386
2239.38	322.59
2240.57	323.597
2241.75	312.399
2242.94	315.268
2244.12	313.366
2245.3	311.959
2246.49	317.91
2247.67	316.103
2248.85	315.079
2250.04	316.972
2251.22	326.171
2252.4	318.881
2253.59	314.681
2254.77	317.632
2255.95	313.99
2257.13	318.059
2258.31	312.491
2259.49	317.439
2260.67	318.646
2261.85	309.299
2263.03	329.676
2264.21	311.183
2265.39	318.102
2266.57	324.475
2267.75	307.993
2268.93	320.585
2270.11	320.108
2271.29	314.637
2272.47	316.694
2273.64	317.75
2274.82	311.149
2276	318.074
2277.17	320.435
2278.35	324.637
2279.53	327.195
2280.71	324.976
2281.88	325.975
2283.06	329.304
2284.23	330.862
2285.41	315.606
2286.58	318.584
2287.76	319.843
2288.93	325.256
2290.1	323.011
2291.28	315.644
2292.45	326.57
2293.62	324.798
2294.8	328.418
2295.97	311.726
2297.14	321.539
2298.31	312.295
2299.49	326.047
2300.66	309.781
2301.83	327.196
2303	315.577
2304.17	321.557
2305.34	328.519
2306.51	315.101
2307.68	327.542
2308.85	317.005
2310.02	318.277
2311.19	313.924
2312.36	311.661
2313.53	322.631
2314.7	326.03
2315.87	320.726
2317.03	317.711
2318.2	306.077
2319.37	330.003
2320.54	317.548
2321.7	325.657
2322.87	324.851
2324.03	331.654
2325.2	339.909
2326.37	349.203
2327.53	371.066
2328.7	458.641
2329.86	341.94
2331.03	322.675
2332.19	325.513
2333.36	327.245
2334.52	318.325
2335.68	316.403
2336.85	324.004
2338.01	323.916
2339.17	303.736
2340.34	314.079
2341.5	326.091
2342.66	316.276
2343.82	321.892
2344.98	327.907
2346.14	318.773
2347.31	331.242
2348.47	311.781
2349.63	320.731
2350.79	325.364
2351.95	309.552
2353.11	312.312
2354.27	309.69
2355.43	318.682
2356.59	328.231
2357.74	311.74
2358.9	316.759
2360.06	311.777
2361.22	307.699
2362.38	313.439
2363.53	304.335
2364.69	312.564
2365.74	319.896
2366.92	328.827
2368.09	309.76
2369.26	301.926
2370.43	314.775
2371.6	314.55
2372.77	301.136
2373.94	309.388
2375.11	312.859
2376.28	299.542
2377.45	312.493
2378.62	301.876
2379.79	315.539
2380.96	305.153
2382.13	299.517
2383.29	305.981
2384.46	297.519
2385.63	314.079
2386.8	300.567
2387.97	311.576
2389.13	299.357
2390.3	301.201
2391.47	314.309
2392.63	301.948
2393.8	303.33
2394.96	309.75
2396.13	315.445
2397.29	304.971
2398.46	303.087
2399.62	307.766
2400.79	303.95
2401.95	309.404
2403.12	304.056
2404.28	311.125
2405.44	306.727
2406.61	316.142
2407.77	299.332
2408.93	314.189
2410.09	298.352
2411.26	311.421
2412.42	296.676
2413.58	314.467
2414.74	309.68
2415.9	302.001
2417.06	308.662
2418.22	308.904
2419.38	310.268
2420.54	317.861
2421.7	314.776
2422.86	308.553
2424.02	300.354
2425.18	315.661
2426.34	300.969
2427.5	313.329
2428.66	312.302
2429.81	311.326
2430.97	315.14
2432.13	307.15
2433.29	307.476
2434.44	308.483
2435.6	305.026
2436.76	308.103
2437.91	311.838
2439.07	307.411
2440.23	302.133
2441.38	318.265
2442.53	322.292
2443.69	304.583
2444.84	320.897
2446	317.337
2447.15	313.911
2448.31	301.617
2449.46	326.344
2450.61	321.056
2451.77	319.494
2452.92	314.733
2454.07	318.541
2455.22	326.54
2456.38	311.657
2457.53	313.724
2458.68	321.386
2459.83	313.024
2460.98	319.859
2462.14	323.67
2463.29	320.934
2464.43	314.042
2465.59	327.476
2466.74	308.232
2467.88	314.852
2469.03	320.476
2470.18	321.615
2471.33	314.13
2472.48	315.427
2473.63	319.185
2474.78	314.734
2475.92	313.367
2477.07	330.769
2478.22	332.421
2479.37	317.694
2480.51	327.978
2481.66	313.304
2482.81	319.985
2483.95	315.107
2485.1	314.132
2486.24	319.955
2487.39	319.718
2488.53	311.881
2489.68	305.088
2490.82	312.77
2491.97	309.688
2493.11	314.716
2494.25	314.501
2495.4	318.128
2496.54	314.413
2497.69	313.982
2498.83	308.545
2499.97	308.496
2501.11	311.749
2502.25	318.112
2503.4	324.665
2504.54	317.766
2505.68	309.19
2506.82	317.962
2507.96	327.512
2509.1	305.662
2510.24	321.393
2511.38	317.835
2512.52	322.4
2513.66	315.978
2514.8	313.946
2515.94	314.338
2517.08	315.685
2518.21	317.235
2519.35	313.396
2520.49	308.047
2521.63	314.724
2522.77	311.555
2523.9	308.667
2525.04	314.133
2526.18	316.342
2527.31	319.873
2528.45	304.023
2529.58	307.927
2530.72	320.977
2531.86	314.169
2532.99	315.775
2534.13	311.23
2535.26	326.964
2536.4	307.251
2537.53	306.101
2538.66	320.737
2539.8	324.181
2540.93	322.262
2542.06	305.715
2543.2	314.222
2544.33	308.383
2545.46	302.79
2546.59	314.79
2547.73	318.562
2548.86	314.979
2549.99	312.445
2551.12	318.335
2552.25	318.538
2553.38	316.529
2554.51	324.941
2555.64	308.345
2556.77	316.329
2557.9	312.699
2559.03	323.061
2560.16	328.59
2561.29	321.112
2562.42	310.965
2563.55	301.124
2564.67	317.665
2565.8	315.811
2566.93	314.912
2568.06	326.2
2569.18	304.585
2570.31	307.68
2571.44	312.98
2572.56	327.708
2573.69	320.423
2574.81	310.746
2575.94	318.646
2577.06	312.251
2578.19	320.337
2579.31	319.835
2580.44	317.25
2581.56	307.867
2582.69	334.661
2583.81	327.13
2584.94	309.193
2586.06	329.779
2587.18	341.74
2588.3	326.171
2589.43	317.655
2590.55	315.731
2591.67	317.695
2592.79	325.664
2593.91	320.29
2595.04	331.148
2596.16	322.624
2597.28	319.37
2598.4	318.231
2599.52	325.406
2600.64	311.982
2601.76	331.905
2602.88	322.2
2604	322.241
2605.12	316.547
2606.24	332.088
2607.35	317.735
2608.47	315.32
2609.59	326.192
2610.71	325.344
2611.83	318.455
2612.94	315.404
2614.06	324.332
2615.18	312.276
2616.29	319.292
2617.41	332.096
2618.53	330.253
2619.64	325.883
2620.76	329.346
2621.87	324.1
2622.99	327.151
2624.1	317.513
2625.22	331.188
2626.33	329.426
2627.45	325.668
2628.56	322.707
2629.67	325.503
2630.79	319.771
2631.9	328.681
2633.01	322.789
2634.12	328.445
2635.24	335.668
2636.35	326.52
2637.46	320.245
2638.57	328.009
2639.68	332.073
2640.8	334.394
2641.91	319.997
2643.02	314.523
2644.13	325.839
2645.24	327.504
2646.35	312.805
2647.46	332.008
2648.57	325.623
2649.67	318.66
2650.78	321.494
2651.89	317.34
2653	316.267
2654.11	317.054
2655.22	327.294
2656.32	318.626
2657.43	326.477
2658.54	325.294
2659.65	315.108
2660.75	310.27
2661.86	330.999
2662.96	321.561
2664.07	327.048
2665.18	315.46
2666.28	310.579
2667.39	303.703
2668.49	332.868
2669.6	325.139
2670.7	315.675
2671.8	312.567
2672.91	315.932
2674.01	320.417
2675.11	324.476
2676.22	311.533
2677.32	321.71
2678.42	304.405
2679.53	314.638
2680.63	315.47
2681.73	314.622
2682.83	322.691
2683.93	305.217
2685.03	317.516
2686.14	319.629
2687.24	315.001
2688.34	314.48
2689.44	316.331
2690.54	323.409
2691.64	319.401
2692.74	315.742
2693.84	316.064
2694.93	318.767
2696.03	316.915
2697.13	316.251
2698.23	317.11
2699.33	316.734
2700.43	308.35
2701.52	312.243
2702.62	316.034
2703.72	309.216
2704.81	310.975
2705.9	308.187
2707.01	304.427
2708.12	301.381
2709.23	310.888
2710.34	314.752
2711.45	306.151
2712.56	320.704
2713.67	314.257
2714.78	314.789
2715.89	314.803
2716.99	309.86
2718.1	309.881
2719.21	323.332
2720.32	319.107
2721.43	307.933
2722.54	306.764
2723.64	314.255
2724.75	305.171
2725.86	322.955
2726.96	314.446
2728.07	310.834
2729.18	314.695
2730.28	324.403
2731.39	312.504
2732.49	309.619
2733.6	312.195
2734.71	318.842
2735.81	307.972
2736.91	312.853
2738.02	316.622
2739.12	314.896
2740.23	314.77
2741.33	312.741
2742.43	314.103
2743.54	317.347
2744.64	322.523
2745.74	325.327
2746.84	317.494
2747.95	318.49
2749.05	314.782
2750.15	315.732
2751.25	324.557
2752.35	319.315
2753.45	320.398
2754.55	310.75
2755.66	312.521
2756.76	318.46
2757.86	305.306
2758.96	320.492
2760.05	318.556
2761.15	309.426
2762.25	319.424
2763.35	324.44
2764.45	320.928
2765.55	317.045
2766.65	312.077
2767.75	327.049
2768.84	307.069
2769.94	329.125
2771.04	330.19
2772.13	312.764
2773.23	317.588
2774.33	327.619
2775.42	321.807
2776.52	321.578
2777.61	316.785
2778.71	321.594
2779.81	319.383
2780.9	315.529
2782	320.361
2783.09	309.673
2784.18	313.216
2785.28	318.17
2786.37	315.528
2787.47	321.922
2788.56	313.887
2789.65	317.502
2790.74	325.909
2791.84	315.236
2792.93	313.506
2794.02	308.65
2795.11	317.235
2796.2	305.656
2797.3	317.825
2798.39	313.869
2799.48	321.607
2800.57	313.938
2801.66	317.632
2802.75	306.435
2803.84	316.506
2804.93	304.88
2806.02	310.624
2807.11	320.961
2808.2	318.06
2809.28	313.258
2810.37	307.488
2811.46	318.459
2812.55	306.89
2813.64	318.344
2814.73	307.835
2815.81	326.449
2816.9	318.798
2817.99	321.218
2819.07	318.176
2820.16	316.74
2821.25	328.414
2822.33	318.052
2823.42	311.202
2824.5	306.622
2825.59	312.123
2826.67	325.472
2827.76	312.537
2828.84	304.652
2829.93	325.22
2831.01	315.963
2832.09	322.287
2833.18	310.848
2834.26	316.513
2835.34	312.058
2836.43	316.918
2837.51	323.458
2838.59	316.816
2839.67	327.319
2840.75	309.112
2841.84	311.769
2842.92	328.514
2844	321.752
2845.08	323.512
2846.16	313.53
2847.24	318.478
2848.32	319.98
2849.4	322.907
2850.48	310.932
2851.56	323.27
2852.64	316.596
2853.72	320.448
2854.8	319.597
2855.87	303.631
2856.95	321.471
2858.03	316.868
2859.11	321.549
2860.19	325.326
2861.26	309.838
2862.34	319.644
2863.42	317.529
2864.49	321.107
2865.57	311.846
2866.65	325.282
2867.72	324.412
2868.8	317.299
2869.87	323.812
2870.95	318.159
2872.02	334.044
2873.1	312.406
2874.17	319.436
2875.25	316.956
2876.32	329.187
2877.4	318.815
2878.47	321.829
2879.54	331.115
2880.62	315.031
2881.69	321.982
2882.76	309.799
2883.83	307.562
2884.9	320.153
2885.98	310.913
2887.05	320.501
2888.12	318.013
2889.19	309.619
2890.26	323.807
2891.33	307.616
2892.4	313.433
2893.47	317.504
2894.54	316.176
2895.61	311.034
2896.68	320.411
2897.75	320.465
2898.82	319.581
2899.89	324.591
2900.96	327.508
2902.03	314.103
2903.09	328.452
2904.16	328.722
2905.23	321.227
2906.3	316.175
2907.36	324.608
2908.43	308.608
2909.5	326.613
2910.57	322.909
2911.63	318.243
2912.7	336.463
2913.76	327.782
2914.83	342.834
2915.89	345.7
2916.96	327.647
2918.02	319.086
2919.09	326.635
2920.15	323.552
2921.22	322.378
2922.28	317.424
2923.34	310.74
2924.41	327.839
2925.47	316.408
2926.53	322.988
2927.6	319.116
2928.66	329.418
2929.72	327.114
2930.78	320.15
2931.84	306.993
2932.91	323.817
2933.97	319.214
2935.03	311.399
2936.09	315.031
2937.15	315.145
2938.21	322.682
2939.27	327.111
2940.33	320.577
2941.39	321.194
2942.45	324.185
2943.51	331.93
2944.57	322.624
2945.63	334.406
2946.68	327.307
2947.74	327.471
2948.8	308.519
2949.86	324.391
2950.92	317.861
2951.97	323.655
2953.03	314.077
2954.09	314.677
2955.14	317.225
2956.2	319.097
2957.25	318.275
2958.31	312.652
2959.37	317.381
2960.42	315.365
2961.48	314.29
2962.53	315.77
2963.59	322.576
2964.64	308.682
2965.7	308.509
2966.75	316.693
2967.8	314.565
2968.86	313.701
2969.91	325.06
2970.96	316.653
2972.02	312.911
2973.07	322.352
2974.12	304.374
2975.17	328.727
2976.22	308.017
2977.28	323.196
2978.33	315.895
2979.38	326.263
2980.43	326.249
2981.48	327.073
2982.53	333.456
2983.58	320.08
2984.63	326.505
2985.68	314.276
2986.73	322.933
2987.78	326.782
2988.83	315.621
2989.88	307.137
2990.93	324.113
2991.98	304.482
2993.02	318.537
2994.07	326.002
2995.12	331.932
2996.17	328.554
2997.21	319.22
2998.26	308.074
2999.31	312.84
2999.94	329.76