File: Data/3-Raman/raw/bu32-b-ff2-fi04-v_150 (500nm)_532nm_edge_100%_x100_vis_lwd_h30um_30sx2_01.txt
#Acq. time (s)=	30
#Accumulations=	2
#Range (cm-¹)=	100...5000
#Windows=	1
#Auto scanning=	Off
#Autofocus=	Off
#Macrospot=	Off
#AutoExposure=	Off
#Spike filter=	Multiple accum.
#Delay time (s)=	2
#Binning=	1
#Readout mode=	Signal
#DeNoise=	Off
#ICS correction=	On
#Dark correction=	Off
#Inst. Process=	Off
#Detector Gain=	Best Dynamic
#Detector ADC=	50 kHz HS
#Detector temperature (°C)=	-60.09
#Instrument=	LabRAM HR Evol
#Detector=	SIN-EM FIVIS
#Objective=	x100_VIS_LWD
#Grating=	150 (500nm)
#ND Filter=	100%
#Laser=	532nm_Edge
#Hole=	30.0125
#Temperature=	40
#Range=	Visible
#StageXY=	75x50mm Scan+
#StageZ=	Z motor
#X (µm)=	0
#Y (µm)=	0
#Z (µm)=	68.5
#Full time(mm:ss)=	1:04
#Project=	21_08_11
#Sample=	BU32
#Site=
#Title=	BU32-B-FF2-FI04-V_150 (500nm)_532nm_Edge_100%_x100_VIS_LWD_H30um_30sX2
#Remark=
#Date=	13.08.2021 15:43
#Acquired=	13.08.2021 15:43:25
102.095	1118.09
106.719	923.914
111.341	795.819
115.96	680.031
120.577	609.184
125.19	550.984
129.802	533.979
134.413	534.456
139.021	542.381
143.624	515.933
148.228	516.566
152.829	621.535
157.428	982.686
162.022	1254
166.617	1087.96
171.209	701.915
175.799	471.677
180.384	377.406
184.969	362.699
189.552	384.708
194.133	407.953
198.71	470.347
203.286	494.806
207.86	538.8
212.43	582.795
216.999	549.742
221.566	516.693
226.131	468.925
230.692	482.191
235.253	524.719
239.811	600.115
244.365	565.491
248.919	549.164
253.47	487.755
258.018	526.233
262.565	569.504
267.11	575.062
271.65	566.057
276.191	487.997
280.727	486.501
285.263	488.877
289.797	486.77
294.326	548.065
298.856	614.45
303.383	628.704
307.906	640.329
312.428	576.47
316.947	493.121
321.465	463.986
325.981	466.612
330.493	474.484
335.005	514.042
339.512	601.174
344.019	731.73
348.524	797.896
353.025	756.124
357.526	582.013
362.022	493.767
366.518	406.441
371.01	391.528
375.502	367.587
379.99	366.198
384.477	391.763
388.961	420.115
393.444	496.83
397.923	571.65
402.401	645.313
406.878	756.026
411.35	830.518
415.823	826.545
420.291	839.676
424.758	891.351
429.222	949.61
433.684	914.926
438.145	865.999
442.602	812.76
447.059	801.57
451.512	853.681
455.965	909.472
460.413	865.263
464.862	743.674
469.306	620.142
473.75	526.5
478.19	535.89
482.63	562.207
487.065	635.765
491.499	769.939
495.932	903.961
500.361	1108.9
504.79	1281.05
509.215	1472.65
513.638	1591.27
518.06	1662.45
522.479	1690.22
526.897	1661.83
531.311	1587.48
535.723	1509.9
540.135	1436.91
544.543	1457.63
548.948	1479.59
553.354	1466.57
557.755	1401.63
562.157	1283.79
566.554	1125.73
570.949	1034.62
575.344	941.833
579.734	997.45
584.123	1121.35
588.512	1301.3
592.896	1428.53
597.279	1405.9
601.659	1198.8
606.039	950.439
610.415	784.894
614.789	684.556
619.163	605.18
623.532	541.059
627.9	493.955
632.267	457.626
636.631	456.489
640.992	463.562
645.351	504.803
649.71	534.416
654.065	569.436
658.418	597.451
662.769	533.63
667.12	461.987
671.466	343.146
675.811	319.556
680.154	280.367
684.494	270.488
688.834	248.364
693.171	235.65
697.505	248.721
701.837	239.843
706.169	228.412
710.497	246.971
714.823	243.108
719.146	234.518
723.468	228.018
727.788	218.576
732.107	200.571
736.423	213.291
740.737	224.486
745.048	210.518
749.357	194.862
753.665	194.755
757.972	205.389
762.275	194.654
766.576	202.858
770.875	176.795
775.172	171.721
779.467	191.236
783.76	184.177
788.051	172.874
792.34	190.346
796.629	180.105
800.914	160.078
805.196	176.499
809.477	169.888
813.756	181.999
818.032	187.547
822.307	186.492
826.58	168.977
830.85	178.996
835.119	180.213
839.385	169.287
843.649	168.26
847.912	171.587
852.172	173.704
856.431	161.489
860.687	203.266
864.941	173.395
869.194	188.608
873.444	180.679
877.692	184.788
881.938	193.222
886.183	181.878
890.425	197.717
894.665	186.225
898.903	191.366
903.14	203.461
907.374	214.196
911.606	238.697
915.836	250.303
920.064	275.858
924.291	317.403
928.515	344.59
932.737	420.443
936.957	474.622
941.176	544.577
945.392	604.613
949.606	704.973
953.818	812.673
958.029	925.486
962.237	1099.8
966.443	1251.54
970.645	1514.52
974.848	1687.27
979.048	1687.28
983.246	1473.71
987.443	1241.23
991.637	1086.27
995.83	1097.26
1000.02	1193.74
1004.21	1479.56
1008.39	1877.9
1012.58	2344.47
1016.76	2574.07
1020.94	2598.33
1025.12	2435.29
1029.29	2145.05
1033.47	1826.15
1037.64	1510.88
1041.81	1230.52
1045.98	989.234
1050.15	810.022
1054.31	778.673
1058.47	804.338
1062.64	857.056
1066.79	927.095
1070.95	946.268
1075.1	915.049
1079.26	848.574
1083.41	733.471
1087.56	662.687
1091.7	607.981
1095.85	611.405
1099.99	653.01
1104.13	714.956
1108.27	763.637
1112.41	738.079
1116.55	624.072
1120.68	534.508
1124.81	435.173
1128.94	346.957
1133.07	330.215
1137.19	298.963
1141.32	271.693
1145.44	263.941
1149.56	244.75
1153.67	230.526
1157.79	206.898
1161.9	202.817
1166.02	186.283
1170.13	171.773
1174.23	176.807
1178.34	158.108
1182.45	152.815
1186.55	150.571
1190.65	154.401
1194.75	149.978
1198.84	144.504
1202.94	154.296
1207.03	148.785
1211.12	146.349
1215.21	146.964
1219.3	154.641
1223.38	166.321
1227.47	154.92
1231.55	151.63
1235.63	175.457
1239.7	169.377
1243.78	180.241
1247.85	192.159
1251.93	238.128
1256	231.241
1260.06	259.368
1264.13	195.55
1268.19	328.899
1272.26	921.652
1276.32	891.581
1280.38	788.077
1284.43	325.276
1288.49	185.651
1292.54	175.698
1296.59	171.75
1300.64	160.73
1304.69	158.743
1308.73	155.736
1312.78	176.903
1316.82	161.725
1320.86	159.616
1324.89	166.508
1328.93	168.333
1332.96	158.095
1337	160.86
1341.03	180.596
1345.06	167.285
1349.08	174.952
1353.11	166.674
1357.13	211.078
1361.15	197.801
1365.17	209.347
1369.19	233.74
1373.2	734.872
1377.22	1502.13
1381.23	1266.28
1385.24	834.419
1389.25	273.141
1393.25	211.127
1397.26	307.712
1401.26	268.419
1405.26	266.529
1409.26	172.994
1413.25	161.246
1417.25	157.383
1421.24	157.462
1425.23	155.546
1429.22	137.753
1433.21	145.644
1437.2	140.698
1441.18	130.816
1445.16	141.648
1449.14	123.846
1453.12	114.915
1457.1	120.767
1461.07	139.398
1465.05	121.54
1469.02	117.473
1472.99	113.43
1476.95	105.458
1480.92	121.006
1484.88	115.956
1488.85	113.844
1492.81	116.624
1496.77	112.577
1500.72	118.288
1504.68	116.225
1508.63	124.89
1512.58	116.07
1516.53	116.974
1520.48	130.503
1524.42	116.873
1528.37	120.714
1532.31	115.844
1536.25	119.702
1540.19	123.562
1544.12	125.484
1548.06	128.375
1551.99	111.891
1555.92	130.265
1559.85	123.437
1563.78	113.698
1567.7	114.596
1571.63	121.282
1575.55	128.922
1579.47	112.422
1583.39	118.12
1587.31	125.728
1591.22	127.544
1595.13	126.469
1599.05	122.513
1602.96	127.215
1606.86	116.578
1610.77	124.177
1614.67	116.442
1618.58	136.511
1622.48	124
1626.38	116.303
1630.27	131.595
1634.17	122.999
1638.06	126.841
1641.95	124.012
1645.84	127.915
1649.73	118.413
1653.62	127.134
1657.5	130.096
1661.39	133.055
1665.27	130.226
1669.15	123.535
1673.02	120.649
1676.9	112.949
1680.77	128.252
1684.65	124.3
1688.52	114.591
1692.39	125.951
1696.25	113.351
1700.12	127.51
1703.98	130.156
1707.84	129.909
1711.7	125.836
1715.56	130.31
1719.42	120.585
1723.27	124.116
1727.13	125.739
1730.98	114.178
1734.83	122.368
1738.68	125.83
1742.52	132.993
1746.37	124.301
1750.21	133.377
1754.05	120.199
1757.89	127.521
1761.73	113.703
1765.56	119.294
1769.4	127.715
1773.23	125.984
1777.06	119.601
1780.89	124.427
1784.71	133.956
1788.54	117.349
1792.36	115.678
1796.18	129.017
1800	117.019
1803.82	127.496
1807.64	133.272
1811.45	124.904
1815.27	124.047
1819.08	120.304
1822.89	134.456
1826.7	122.166
1830.5	120.222
1834.31	131.441
1838.11	136.97
1841.91	130.242
1845.71	127.256
1849.51	122.416
1853.3	129.709
1857.1	140.681
1860.89	130.112
1864.68	131.671
1868.47	134.164
1872.26	145
1876.04	129.929
1879.83	129.693
1883.61	123.059
1887.39	133.02
1891.17	124.707
1894.95	132.969
1898.72	140.308
1902.5	149.547
1906.27	130.282
1910.04	136.805
1913.81	136.011
1917.58	132.457
1921.34	138.222
1925.1	129.203
1928.87	124.813
1932.63	134.366
1936.38	137.432
1940.14	141.438
1943.9	150.134
1947.65	149.492
1951.4	149.667
1955.15	139.452
1958.9	130.093
1962.65	146.986
1966.39	140.388
1970.14	142.2
1973.88	132.702
1977.62	155.983
1981.36	141.757
1985.09	138.756
1988.83	154.406
1992.56	142.04
1996.29	142.703
2000.02	147.976
2003.75	146.751
2007.48	149.212
2011.21	158.077
2014.93	147.594
2018.65	145.484
2022.37	150.794
2026.09	150.688
2029.81	157.917
2033.52	136.835
2037.23	151.51
2040.95	154.271
2044.66	137.795
2048.37	149.703
2052.07	138.748
2055.78	146.119
2059.48	162.738
2063.18	163.889
2066.88	155.889
2070.58	153.401
2074.28	154.599
2077.97	153.963
2081.67	150.556
2085.36	153.615
2089.05	160.22
2092.74	160.244
2096.43	146.403
2100.11	148.333
2103.8	153.933
2107.48	154.856
2111.16	159.473
2114.84	160.365
2118.51	160.306
2122.19	181.543
2125.86	164.665
2129.54	159.845
2133.21	157.796
2136.88	164.06
2140.55	162.896
2144.21	168.16
2147.87	161.436
2151.54	158.405
2155.2	158.14
2158.86	173.442
2162.52	164.955
2166.17	171.122
2169.83	162.717
2173.48	171.702
2177.13	181.627
2180.78	156.985
2184.43	174.201
2188.08	172.352
2191.72	175.119
2195.36	162.485
2199.01	159.892
2202.65	162.785
2206.29	183.056
2209.92	166.84
2213.56	178.068
2217.19	177.42
2220.82	180.447
2224.45	166.938
2228.08	173.641
2231.71	176.677
2235.33	168.649
2238.96	177.251
2242.58	173.824
2246.2	181.522
2249.82	178.092
2253.44	169.08
2257.06	170.317
2260.67	171.556
2264.28	174.651
2267.9	180.588
2271.5	180.948
2275.11	180.321
2278.72	180.583
2282.32	184.503
2285.93	189.364
2289.53	180.055
2293.13	174.491
2296.73	191.636
2300.32	173.773
2303.92	183.337
2307.52	164.436
2311.11	199.534
2314.7	209.013
2318.29	295.221
2321.88	311.208
2325.46	262.63
2329.05	203.724
2332.63	198.75
2336.21	193.763
2339.79	183.115
2343.37	189.399
2346.95	177.81
2350.52	187.791
2354.09	193.051
2357.67	179.617
2361.24	170.88
2364.81	198.419
2368.37	193.398
2371.94	193.071
2375.5	195.506
2379.07	180.403
2382.63	197.618
2386.19	182.602
2389.74	195.22
2393.3	185.823
2396.85	180.167
2400.41	197.49
2403.96	202.082
2407.51	201.205
2411.06	179.313
2414.61	203.334
2418.15	194.366
2421.7	187.249
2425.24	195.822
2428.78	199.856
2432.32	190.072
2435.86	202.536
2439.39	199.282
2442.93	196.028
2446.46	203.032
2449.99	200.752
2453.52	197.556
2457.05	213.03
2460.58	202.002
2464.1	208.836
2467.63	188.159
2471.15	211.969
2474.67	223.195
2478.19	188.143
2481.71	195.584
2485.22	196.352
2488.74	218.623
2492.25	196.799
2495.77	199.315
2499.28	207.506
2502.78	196.905
2506.29	214.317
2509.8	220.434
2513.3	225.612
2516.8	193.671
2520.31	206.383
2523.81	205.022
2527.3	211.268
2530.8	207.394
2534.3	191.555
2537.79	207.165
2541.28	197.902
2544.77	216.421
2548.26	208.271
2551.75	221.377
2555.24	206.806
2558.72	217.324
2562.2	223.234
2565.68	225.545
2569.16	211.155
2572.64	222.921
2576.12	211.361
2579.6	225.156
2583.07	208.874
2586.54	222.758
2590.01	219.595
2593.48	211.545
2596.95	214.852
2600.42	212.51
2603.88	208.223
2607.35	213.39
2610.81	213.591
2614.27	215.556
2617.73	214.728
2621.19	212.845
2624.64	221.49
2628.1	214.702
2631.55	222.286
2635	236.523
2638.45	225.742
2641.9	218.773
2645.35	233.768
2648.79	221.973
2652.24	236.85
2655.68	231.635
2659.12	220.696
2662.56	219.252
2666	238.578
2669.44	239.899
2672.87	242.139
2676.31	233.149
2679.74	232.659
2683.17	229.418
2686.6	222.535
2690.03	229.797
2693.45	232.478
2696.88	234.171
2700.3	215.442
2703.73	237.671
2707.15	222.69
2710.57	238.564
2713.98	230.307
2717.4	237.915
2720.81	217.623
2724.23	234.638
2727.64	232.095
2731.05	233.301
2734.46	228.879
2737.87	229.133
2741.27	220.934
2744.68	230.515
2748.08	232.561
2751.48	231.791
2754.88	240.411
2758.28	237.714
2761.68	235.021
2765.08	223.782
2768.47	248.314
2771.86	241.708
2775.25	240.736
2778.64	235.013
2782.03	253.74
2785.42	251.727
2788.81	238.421
2792.19	231.701
2795.58	246.586
2798.96	233.291
2802.34	235.921
2805.71	244.175
2809.09	245.853
2812.47	245.643
2815.84	238.875
2819.22	239.585
2822.59	241.265
2825.96	226.186
2829.33	231.652
2832.69	241.802
2836.06	253.853
2839.42	259.424
2842.79	247.345
2846.15	255.821
2849.51	256.006
2852.87	249.719
2856.22	244.323
2859.58	255.785
2862.93	260.748
2866.29	246.049
2869.64	254.779
2872.99	244.722
2876.34	260.967
2879.68	245.232
2883.03	265.264
2886.38	257.961
2889.72	260.077
2893.06	255.571
2896.4	264.229
2899.74	257.727
2903.08	251.178
2906.41	263.519
2909.75	280.572
2913.08	268.27
2916.41	250.273
2919.74	265.354
2923.07	272.846
2926.4	269.909
2929.72	240.478
2933.05	260.158
2936.37	256.18
2939.69	260.693
2943.01	271.795
2946.33	258.411
2949.65	248.819
2952.97	263.672
2956.28	261.602
2959.6	255.823
2962.91	254.765
2966.22	251.847
2969.53	264.949
2972.84	258.405
2976.14	264.061
2979.45	260.384
2982.75	266.995
2986.05	254.852
2989.36	269.948
2992.65	265.338
2995.95	261.678
2999.25	258.969
3002.54	281.646
3005.84	266.71
3009.13	267.784
3012.42	262.28
3015.71	261.488
3019	271.059
3022.29	257.053
3025.57	268.516
3028.86	261.108
3032.14	257.467
3035.42	260.427
3038.7	260.544
3041.98	255.932
3045.26	274.986
3048.54	270.385
3051.81	263.883
3055.08	257.383
3058.36	267.937
3061.63	263.235
3064.9	281.343
3068.16	257.667
3071.43	257.662
3074.7	278.28
3077.96	255.554
3081.22	259.284
3084.48	284.114
3087.74	257.701
3091	277.871
3094.26	288.597
3097.51	270.429
3100.77	274.312
3104.02	280.04
3107.27	285.908
3110.52	278.416
3113.77	261.308
3117.02	299.442
3120.26	272.841
3123.51	290.045
3126.75	290.103
3129.99	273.952
3133.24	282.58
3136.47	281.67
3139.71	287.417
3142.95	288.395
3146.19	286.514
3149.42	282.744
3152.65	282.794
3155.88	288.554
3159.11	299.095
3162.34	323.941
3165.57	294.4
3168.8	293.457
3172.02	296.309
3175.24	302.966
3178.46	304.825
3181.69	300.001
3184.9	313.308
3188.12	315.13
3191.34	314.082
3194.55	328.281
3197.77	317.698
3200.98	327.113
3204.19	349.864
3207.4	330.737
3210.61	337.327
3213.82	353.451
3217.02	352.472
3220.23	352.446
3223.43	347.675
3226.63	357.209
3229.83	360.092
3233.03	364.907
3236.23	391.583
3239.43	412.646
3242.62	397.562
3245.82	420.592
3249.01	411.239
3252.2	423.849
3255.39	443.163
3258.58	437.672
3261.77	458.85
3264.95	474.246
3268.14	478.116
3271.32	499.134
3274.5	483.821
3277.68	496.204
3280.86	489.382
3284.04	496.79
3287.22	523.285
3290.39	512.519
3293.57	515.151
3296.74	499.66
3299.91	527.989
3303.08	509.78
3306.25	494.303
3309.42	510.178
3312.59	526.901
3315.75	498.941
3318.91	512.756
3322.08	534.111
3325.24	541.229
3328.4	518.059
3331.56	516.685
3334.71	527.631
3337.87	515.004
3341.02	528.851
3344.18	531.377
3347.33	550.058
3350.48	541.533
3353.63	550.909
3356.78	564.119
3359.92	598.097
3363.07	589.731
3366.21	578.545
3369.36	604.174
3372.5	597.761
3375.64	637.67
3378.78	656.866
3381.92	679.894
3385.05	686.841
3388.19	670.205
3391.32	735.904
3394.46	739.147
3397.59	803.76
3400.72	814.864
3403.85	851.679
3406.97	844.952
3410.1	855.375
3413.22	847.712
3416.35	829.348
3419.47	822.341
3422.59	802.846
3425.71	795.571
3428.83	757.595
3431.95	735.731
3435.06	760.502
3438.18	755.492
3441.29	744.854
3444.41	781.912
3447.52	758.698
3450.63	786.011
3453.73	795.077
3456.84	788.878
3459.95	823.487
3463.05	854.224
3466.16	923.814
3469.26	944.746
3472.36	991.994
3475.46	1004.42
3478.56	1030.12
3481.65	1037.86
3484.75	1086.26
3487.84	1057.22
3490.94	1068.02
3494.03	1032.87
3497.12	1028.83
3500.21	1007.75
3503.3	960.312
3506.39	964.578
3509.47	904.788
3512.55	892.788
3515.64	870.608
3518.72	826.576
3521.8	786.63
3524.88	750.963
3527.96	727.098
3531.04	672.648
3534.11	648.24
3537.19	629.18
3540.26	617.728
3543.33	586.734
3546.4	623.588
3549.47	583.455
3552.54	588.5
3555.61	591.602
3558.67	566.416
3561.74	547.835
3564.8	567.012
3567.86	530.202
3570.92	521.985
3573.98	493.589
3577.04	479.437
3580.1	468.087
3583.15	458.596
3586.21	468.03
3589.26	443.321
3592.31	455.538
3595.37	460.155
3598.41	435.355
3601.46	421.94
3604.51	428.369
3607.56	410.158
3610.6	430.735
3613.64	400.231
3616.69	398.083
3619.73	412
3622.77	420.261
3625.81	404.011
3628.84	396.285
3631.88	394.195
3634.91	357.254
3637.95	359.961
3640.98	367.42
3644.01	365.509
3647.04	360.875
3650.07	338.257
3653.1	358.987
3656.13	334.094
3659.15	321.255
3662.17	312.127
3665.2	314.234
3668.22	305.826
3671.24	302.2
3674.26	296.697
3677.28	289.319
3680.29	272.503
3683.31	269.827
3686.32	265.259
3689.33	251.233
3692.35	242.876
3695.36	260.095
3698.37	236.518
3701.37	242.372
3704.38	248.235
3707.39	239.855
3710.39	234.286
3713.4	233.449
3716.4	229.726
3719.4	237.438
3722.4	240.366
3725.4	228.04
3728.39	246.162
3731.39	219.511
3734.38	213.788
3737.38	227.084
3740.37	226.077
3743.36	215.526
3746.35	238.256
3749.34	221.014
3752.33	216.125
3755.32	210.29
3758.3	226.29
3761.28	203.388
3764.27	209.872
3767.25	209.724
3770.23	225.678
3773.21	220.829
3776.19	210.33
3779.16	214.97
3782.14	217.732
3785.11	209.164
3788.09	210.998
3791.06	207.18
3794.03	205.284
3797	207.181
3799.97	212.866
3802.94	208.196
3805.9	196.923
3808.87	210.214
3811.83	198.008
3814.8	212.272
3817.76	201.013
3820.72	200.163
3823.68	198.37
3826.63	196.59
3829.59	206.185
3832.55	182.592
3835.5	193.157
3838.45	199.947
3841.41	193.44
3844.36	191.678
3847.31	200.389
3850.26	200.548
3853.2	195.95
3856.15	208.528
3859.09	185.787
3862.04	184.998
3864.98	206.203
3867.92	200.63
3870.86	184.488
3873.8	179.826
3876.74	186.667
3879.68	194.455
3882.61	193.583
3885.55	193.649
3888.48	186.009
3891.41	199.511
3894.34	187.044
3897.27	196.669
3900.2	195.692
3903.13	180.288
3906.06	196.589
3908.98	177.343
3911.91	189.801
3914.83	183.979
3917.75	187.753
3920.67	180.036
3923.59	184.766
3926.51	190.429
3929.43	173.058
3932.34	185.402
3935.26	186.284
3938.17	174.756
3941.08	187.203
3944	172.82
3946.91	174.726
3949.81	193.883
3952.72	186.246
3955.63	183.404
3958.54	178.661
3961.44	178.715
3964.34	176.86
3967.25	185.563
3970.15	171.257
3973.05	193.419
3975.95	173.342
3978.84	173.411
3981.74	169.625
3984.63	192.751
3987.53	187.032
3990.42	192.847
3993.32	173.629
3996.21	178.492
3999.1	184.317
4001.98	174.75
4004.87	170.958
4007.76	164.281
4010.64	176.879
4013.53	161.52
4016.41	170.268
4019.29	176.127
4022.17	173.301
4025.05	168.542
4027.93	164.748
4030.81	172.552
4033.68	171.664
4036.56	174.647
4039.43	174.737
4042.3	183.539
4045.18	164.22
4048.05	161.372
4050.92	160.47
4053.78	151.815
4056.65	164.519
4059.52	171.405
4062.38	168.575
4065.24	167.687
4068.11	168.742
4070.97	167.85
4073.83	170.85
4076.69	161.187
4079.55	169.053
4082.4	168.152
4085.26	166.276
4088.11	166.341
4090.97	164.454
4093.82	166.483
4096.67	167.524
4099.52	165.643
4102.37	153.002
4105.22	162.841
4108.06	164.84
4110.91	158.035
4113.76	161.974
4116.6	156.11
4119.44	157.075
4122.28	157.063
4125.12	148.261
4127.96	160.016
4130.8	149.3
4133.64	152.311
4136.47	163.216
4139.31	170.983
4142.14	159.991
4144.97	162.909
4147.81	160.025
4150.64	162.048
4153.47	145.429
4156.29	153.236
4159.12	146.293
4161.95	155.06
4164.77	156.998
4167.59	155.999
4170.42	164.787
4173.24	155.003
4176.06	152.069
4178.88	157.937
4181.7	154.037
4184.51	149.165
4187.33	153.104
4190.14	146.285
4192.96	156.126
4195.77	145.426
4198.58	156.294
4201.39	154.423
4204.2	153.537
4207.01	143.81
4209.82	145.86
4212.62	146.925
4215.43	152.906
4218.23	140.283
4221.04	140.437
4223.84	131.699
4226.64	145.636
4229.44	147.764
4232.24	143.966
4235.03	145.13
4237.83	143.33
4240.63	151.461
4243.42	142.711
4246.21	141.912
4249	141.103
4251.8	140.279
4254.59	157.441
4257.37	147.608
4260.16	145.766
4262.95	139.914
4265.73	140.08
4268.52	144.277
4271.3	143.449
4274.08	142.614
4276.87	137.714
4279.65	132.783
4282.43	140.973
4285.2	141.069
4287.98	143.171
4290.76	132.1
4293.53	143.292
4296.3	138.302
4299.08	130.278
4301.85	142.519
4304.62	141.577
4307.39	135.557
4310.16	134.616
4312.92	145.888
4315.69	138.839
4318.46	132.789
4321.22	147.083
4323.98	129.81
4326.75	137.981
4329.51	129.864
4332.27	129.879
4335.02	129.902
4337.78	136.025
4340.54	134.022
4343.29	131
4346.05	137.168
4348.8	145.395
4351.56	135.256
4354.31	135.357
4357.06	130.332
4359.81	125.301
4362.55	129.467
4365.3	131.602
4368.05	137.828
4370.79	139.974
4373.54	140.045
4376.28	138.06
4379.02	126.819
4381.76	127.893
4384.5	132.059
4387.24	135.231
4389.98	124.05
4392.72	128.326
4395.45	134.78
4398.19	125.646
4400.92	123.728
4403.65	130.085
4406.38	139.577
4409.11	115.849
4411.84	125.338
4414.57	120.251
4417.3	119.318
4420.02	119.376
4422.75	131.976
4425.47	117.457
4428.2	134.262
4430.92	116.587
4433.64	139.692
4436.36	124.08
4439.08	119.967
4441.8	118.982
4444.51	124.291
4447.23	128.549
4449.94	122.313
4452.66	122.361
4455.37	122.408
4458.08	129.8
4460.79	130.882
4463.5	134.086
4466.21	121.509
4468.92	138.398
4471.62	126.878
4474.33	128.001
4477.03	119.649
4479.74	115.515
4482.44	113.493
4485.14	122.034
4487.84	121.061
4490.54	114.793
4493.24	127.54
4495.94	118.042
4498.63	124.447
4501.33	125.553
4504.02	121.35
4506.71	117.156
4509.41	118.266
4512.1	102.399
4514.79	116.246
4517.48	120.55
4520.16	108.923
4522.85	107.928
4525.54	113.316
4528.22	111.255
4530.91	120.914
4533.59	115.664
4536.27	112.544
4538.95	115.83
4541.63	118.059
4544.31	113.875
4546.99	108.618
4549.66	108.709
4552.34	113.099
4555.02	107.859
4557.69	116.591
4560.36	112.468
4563.03	109.43
4565.7	115.058
4568.37	112.079
4571.04	122.037
4573.71	114.515
4576.38	113.45
4579.04	111.354
4581.71	113.651
4584.37	106.176
4587.03	116.06
4589.69	97.5978
4592.36	117.291
4595.02	111.904
4597.67	108.709
4600.33	106.592
4602.99	101.209
4605.64	102.396
4608.3	100.297
4610.95	106.973
4613.6	109.265
4616.26	108.262
4618.91	107.263
4621.56	102.964
4624.2	109.676
4626.85	103.153
4629.5	96.6132
4632.14	101.11
4634.79	104.492
4637.43	113.404
4640.07	114.574
4642.72	101.349
4645.36	110.299
4648	102.65
4650.63	97.2299
4653.27	102.961
4655.91	95.2919
4658.54	98.6526
4661.18	93.1646
4663.81	108.904
4666.45	105.655
4669.08	100.136
4671.71	97.9777
4674.34	99.1753
4676.97	90.2804
4679.59	103.817
4682.22	93.7839
4684.85	96.1005
4687.47	105.169
4690.09	104.122
4692.72	113.214
4695.34	99.7632
4697.96	98.7013
4700.58	101.026
4703.2	102.222
4705.82	107.93
4708.43	93.2874
4711.05	89.9394
4713.66	99.0372
4716.28	96.8158
4718.89	94.5878
4721.5	102.554
4724.11	94.6499
4726.72	92.4236
4729.33	90.2011
4731.94	92.5179
4734.55	91.4301
4737.15	98.2917
4739.76	92.6487
4742.36	106.331
4744.97	93.8493
4747.57	92.7329
4750.17	102.982
4752.77	93.8891
4755.37	87.069
4757.97	96.1826
4760.56	104.17
4763.16	92.8087
4765.76	95.1165
4768.35	94.0287
4770.94	82.6838
4773.54	92.9873
4776.13	90.7455
4778.72	83.9345
4781.31	88.5409
4783.9	101.153
4786.48	88.6207
4789.07	90.9497
4791.66	89.8507
4794.24	101.352
4796.83	89.9517
4799.41	83.1334
4801.99	92.3762
4804.57	95.8989
4807.15	79.8971
4809.73	98.3935
4812.31	90.4312
4814.88	90.53
4817.46	95.2538
4820.04	89.5921
4822.61	82.7585
4825.18	93.2932
4827.76	99.2109
4830.33	86.5558
4832.9	79.6935
4835.47	79.8053
4838.04	89.2623
4840.6	84.7325
4843.17	91.8905
4845.74	84.9867
4848.3	87.4448
4850.86	100.456
4853.43	85.21
4855.99	88.7788
4858.55	84.1997
4861.11	91.3946
4863.67	79.6922
4866.23	82.1178
4868.78	78.6396
4871.34	85.8272
4873.89	83.5294
4876.45	89.5179
4879	83.6495
4881.55	75.3932
4884.1	83.7538
4886.66	83.8027
4889.2	90.9901
4891.75	72.0037
4894.3	79.1899
4896.85	80.4242
4899.39	82.8492
4901.94	79.3117
4904.48	82.929
4907.02	85.3522
4909.57	75.8321
4912.11	83.0115
4914.65	83.0193
4917.19	92.5749
4919.73	78.2489
4922.26	79.4517
4924.8	78.2658
4927.33	84.2559
4929.87	79.4798
4932.4	79.5055
4934.93	80.7428
4937.47	84.3653
4940	78.4122
4942.53	76.0134
4945.05	78.4318
4947.58	84.4591
4950.11	72.511
4952.64	74.9474
4955.16	78.5763
4957.68	82.2232
4960.21	83.4793
4962.73	70.3204
4965.25	83.6305
4967.77	77.71
4970.29	80.1954
4972.81	80.2674
4975.33	71.8807
4977.84	80.4054
4980.36	76.8471
4982.88	73.2832
4985.39	69.7153
4987.9	80.7055
4990.41	75.9264
4992.93	74.7827
4995.44	76.069
4997.95	71.2787