File: Data/3-Raman/raw/bu32-b-ff2-fi03-v_1800 (450-850nm)_532nm_edge_100%_x100_vis_lwd_h30um_30sx2_01.txt
#Acq. time (s)=	30
#Accumulations=	2
#Range (cm-¹)=	1200...2999
#Windows=	5
#Auto scanning=	Off
#Autofocus=	Off
#Macrospot=	Off
#AutoExposure=	Off
#Spike filter=	Multiple accum.
#Delay time (s)=	2
#Binning=	1
#Readout mode=	Signal
#DeNoise=	Off
#ICS correction=	On
#Dark correction=	Off
#Inst. Process=	Off
#Detector Gain=	Best Dynamic
#Detector ADC=	50 kHz EM
#Detector EM gain=	150
#Detector temperature (°C)=	-60.09
#Instrument=	LabRAM HR Evol
#Detector=	SIN-EM FIVIS
#Objective=	x100_VIS_LWD
#Grating=	1800 (450-850nm)
#ND Filter=	100%
#Laser=	532nm_Edge
#Hole=	30.0125
#Temperature=	40
#Range=	Visible
#StageXY=	75x50mm Scan+
#StageZ=	Z motor
#X (µm)=	0
#Y (µm)=	0
#Z (µm)=	80.2
#Full time(mm:ss)=	5:26
#Project=	21_08_11
#Sample=	BU32
#Site=
#Title=	BU32-B-FF2-FI03-V_1800 (450-850nm)_532nm_Edge_100%_x100_VIS_LWD_H30um_30sX2
#Remark=
#Date=	13.08.2021 15:49
#Acquired=	13.08.2021 15:49:24
1200.05	327.611
1201.44	326.823
1202.83	327.323
1204.22	322.536
1205.61	326.216
1207	319.116
1208.39	321.95
1209.78	331.34
1211.16	329.675
1212.55	329.133
1213.94	325.782
1215.33	320.412
1216.71	324.104
1218.1	325.822
1219.49	326.691
1220.87	322.333
1222.26	334.458
1223.64	315.813
1225.03	332.54
1226.41	342.025
1227.79	323.174
1229.18	321.918
1230.56	322.185
1231.94	324.655
1233.33	325.654
1234.71	326.895
1236.09	326.952
1237.47	328.591
1238.86	320.815
1240.24	315.512
1241.62	325.901
1243	338.591
1244.38	332.269
1245.76	342.308
1247.14	329.678
1248.52	340.963
1249.9	330.44
1251.27	340.545
1252.65	331.872
1254.03	328.883
1255.41	334.149
1256.79	345.732
1258.16	349.738
1259.54	341.529
1260.92	352.566
1262.29	367.692
1263.67	432.798
1265.04	403.403
1266.42	364.793
1267.79	349.651
1269.17	345.759
1270.54	344.314
1271.92	350.716
1273.29	341.785
1274.66	346.141
1276.04	348.538
1277.41	353.112
1278.78	357.684
1280.15	368.122
1281.53	410.511
1282.9	619.199
1284.27	2439.33
1285.64	693.977
1287.01	407.387
1288.38	375.724
1289.75	369.743
1291.12	358.094
1292.49	355.955
1293.86	363.816
1295.23	350.463
1296.6	358.297
1297.96	345.345
1299.33	340.944
1300.7	350.528
1302.07	333.8
1303.43	347.398
1304.8	329.363
1306.17	331.149
1307.53	342.781
1308.9	336.57
1310.26	338.74
1311.63	338.872
1312.99	333.598
1314.36	333.595
1315.72	342.21
1317.08	345.377
1318.45	338.07
1319.81	332.783
1321.17	337.734
1322.53	326.895
1323.9	334.254
1325.26	334.061
1326.62	339.888
1327.98	341.689
1329.34	343.938
1330.7	336.255
1332.06	335.672
1333.42	330.93
1334.78	334.735
1336.14	337.609
1337.5	342.64
1338.86	335.067
1340.22	333.035
1341.58	336.051
1342.93	345.142
1344.29	343.015
1345.65	334.231
1347	338.875
1348.36	336.576
1349.72	331.064
1351.07	326.547
1352.43	336.07
1353.78	338.048
1355.14	339.609
1356.49	321.97
1357.85	351.838
1359.2	329.768
1360.56	332.512
1361.91	335.511
1363.26	333.509
1364.61	342.765
1365.97	341.344
1367.32	335.902
1368.67	344.294
1370.02	375.13
1371.37	345.748
1372.72	353.537
1374.07	333.803
1375.42	350.263
1376.77	338.537
1378.12	354.601
1379.47	366.875
1380.82	347.661
1382.17	383.938
1383.52	391.63
1384.87	418.678
1386.21	697.434
1387.56	3786.19
1388.91	744.385
1390.26	455.305
1391.6	374.901
1392.95	362.335
1394.3	349.932
1395.64	361.341
1396.99	345.754
1398.33	345.797
1399.68	349.02
1401.02	367.658
1402.37	360.152
1403.71	336.503
1405.05	361.994
1406.39	360.791
1407.74	398.854
1409.08	558.005
1410.42	391.578
1411.76	349.381
1413.11	348.126
1414.45	335.703
1415.79	329.629
1417.13	331.873
1418.47	329.886
1419.81	328.665
1421.15	330.501
1422.49	334.311
1423.83	329.947
1425.17	340.43
1426.51	332.154
1427.84	330.711
1429.18	321.632
1430.52	317.982
1431.86	326.268
1433.19	323.703
1434.53	342.254
1435.87	318.639
1437.2	317.497
1438.54	326.805
1439.87	326.057
1441.21	321.946
1442.54	331.254
1443.88	316.768
1445.21	318.027
1446.55	316.884
1447.88	325.027
1449.21	313.797
1450.55	323.872
1451.88	316.574
1453.21	318.725
1454.54	310.487
1455.88	317.737
1457.21	319.619
1458.54	310.43
1459.87	313.48
1461.2	314.331
1462.53	311.985
1463.86	317.162
1465.19	311.309
1466.52	314.189
1467.85	310.097
1469.18	317.101
1470.51	312.782
1471.83	309.552
1473.16	310.449
1474.49	310.432
1475.82	304.232
1477.14	312.209
1478.47	308.976
1479.79	309.658
1481.12	310.448
1482.45	320.826
1483.77	310.624
1485.1	313.366
1486.42	316.105
1487.75	307.833
1489.07	309.596
1490.39	303.412
1491.72	312.413
1493.04	306.294
1494.36	308.349
1495.69	301.903
1497.01	314.897
1498.33	305.804
1499.65	309.944
1500.97	306.808
1502.29	301.644
1503.62	308.566
1504.93	305.483
1506.26	315.325
1507.58	312.37
1508.89	305.316
1510.21	302.244
1511.53	309.719
1512.85	308.209
1514.17	319.419
1515.49	297.936
1516.81	309.81
1518.12	304.915
1519.44	302.993
1520.76	304.017
1522.07	303.935
1523.39	304.577
1524.71	304.445
1526.02	302.687
1527.34	305.643
1528.65	303.503
1529.97	306.44
1531.28	304.606
1532.59	305.778
1533.91	306.953
1535.22	306.687
1536.54	308.2
1537.85	302.933
1539.16	313.304
1540.47	307.892
1541.79	310.522
1543.1	308.141
1544.41	304.185
1545.72	302.525
1547.03	300.623
1548.34	299.554
1549.65	309.229
1550.96	302.242
1552.27	309.336
1553.58	306.898
1554.89	304.524
1556.2	304.498
1557.5	300.493
1558.81	304.046
1560.12	302.82
1561.43	306.926
1562.74	301.023
1564.04	300.229
1565.35	303.339
1566.65	304.836
1567.96	301.959
1569.27	303.784
1570.57	304.807
1571.88	301.642
1573.18	300.402
1574.48	298.658
1575.79	307.786
1577.09	305.347
1578.4	311.042
1579.7	306.138
1581	300.043
1582.3	302.834
1583.61	300.768
1584.91	300.812
1586.21	308.551
1587.51	300.463
1588.81	303.622
1590.11	301.726
1591.41	306.692
1592.72	304.324
1594.01	306.907
1595.31	306.921
1596.61	298.987
1597.91	296.987
1599.21	304.612
1600.51	303.074
1601.81	295.443
1603.1	300.536
1604.4	293.629
1605.7	299.695
1607	300.426
1608.29	296.559
1609.59	301.694
1610.88	304.134
1612.18	297.117
1613.48	299.875
1614.77	301.267
1616.07	299.572
1617.36	298.547
1618.65	297.471
1619.95	299.68
1621.24	300.071
1622.54	299.816
1623.83	299.305
1625.12	296.681
1626.41	302.938
1627.56	298.578
1628.87	303.494
1630.17	303.395
1631.48	299.576
1632.79	297.668
1634.1	298.661
1635.4	299.581
1636.71	304.3
1638.01	309.089
1639.32	303.178
1640.62	295.413
1641.93	298.275
1643.23	297.24
1644.54	305.951
1645.84	293.213
1647.15	299.96
1648.45	296.177
1649.75	296.306
1651.05	303.511
1652.36	298.558
1653.66	300.56
1654.96	296.806
1656.26	300.081
1657.56	297.033
1658.86	301.772
1660.16	305.675
1661.46	300.023
1662.77	303.404
1664.07	302.099
1665.36	293.35
1666.66	296.913
1667.96	299.898
1669.26	299.293
1670.56	303.473
1671.86	293.584
1673.15	306.472
1674.45	295.788
1675.75	300.847
1677.05	302.831
1678.34	299.607
1679.64	300.442
1680.94	304.28
1682.23	303.294
1683.53	295.358
1684.82	298.214
1686.12	297.291
1687.41	302.226
1688.71	300.041
1690	298.877
1691.29	294.105
1692.59	299.887
1693.88	297.556
1695.17	300.477
1696.47	297.612
1697.76	295.326
1699.05	299.125
1700.34	303.99
1701.63	297.904
1702.92	295.763
1704.21	297.746
1705.5	299.663
1706.79	295.398
1708.08	299.849
1709.37	298.577
1710.66	300.635
1711.95	296.726
1713.24	291.241
1714.53	295.938
1715.82	304.809
1717.11	295.547
1718.39	296.979
1719.68	294.06
1720.97	296.724
1722.25	298.304
1723.54	299.078
1724.83	297.776
1726.11	295.578
1727.4	294.504
1728.68	293.375
1729.97	291.585
1731.25	297.67
1732.54	288.823
1733.82	290.262
1735.1	291.744
1736.39	292.517
1737.67	294.22
1738.95	293.863
1740.24	294.254
1741.52	288.214
1742.8	290.981
1744.08	289.82
1745.36	291.712
1746.65	296.144
1747.93	290.184
1749.21	283.643
1750.49	291.555
1751.77	285.615
1753.05	287.223
1754.33	296.494
1755.6	287.683
1756.88	289.183
1758.16	287.363
1759.44	290.235
1760.72	294.821
1762	286.134
1763.27	290.012
1764.55	286.489
1765.83	287.523
1767.1	288.387
1768.38	291.058
1769.66	282.034
1770.93	289.927
1772.21	289.218
1773.48	286.53
1774.76	286.661
1776.03	290.766
1777.31	291.521
1778.58	282.648
1779.85	284.569
1781.13	288.479
1782.4	292.528
1783.67	286.055
1784.94	288.139
1786.22	285.26
1787.49	280.058
1788.76	287.343
1790.03	290.481
1791.3	293.058
1792.57	292.175
1793.84	287.477
1795.11	296.56
1796.38	288.203
1797.65	292.278
1798.92	285.527
1800.19	290.109
1801.46	292.972
1802.73	289.348
1804	291.47
1805.26	292.769
1806.53	293.95
1807.8	290.12
1809.07	287.285
1810.33	295.981
1811.6	286.33
1812.87	299.058
1814.13	288.775
1815.4	290.915
1816.66	287.104
1817.93	294.655
1819.19	294.82
1820.46	287.252
1821.72	299.064
1822.99	293.316
1824.25	295.263
1825.51	291.502
1826.77	295.43
1828.04	293.565
1829.3	296.353
1830.56	286.573
1831.82	292.582
1833.09	301.459
1834.35	290.57
1835.61	292.11
1836.87	298.432
1838.13	291.87
1839.39	295.602
1840.65	289.967
1841.91	291.324
1843.17	291.317
1844.43	293.244
1845.69	300.282
1846.94	295.578
1848.2	294.669
1849.46	290.519
1850.72	292.991
1851.97	286.149
1853.23	286.079
1854.49	284.772
1855.74	285.434
1857	293.998
1858.26	288.962
1859.51	288.722
1860.77	293.688
1862.02	289.89
1863.28	291.472
1864.53	292.154
1865.78	282.111
1867.04	291.999
1868.29	288.054
1869.54	291.813
1870.8	288.914
1872.05	296.339
1873.3	289.506
1874.56	289.187
1875.81	283.921
1877.06	286.187
1878.31	290.47
1879.56	288.78
1880.81	294.393
1882.06	294.562
1883.31	288.869
1884.56	291.397
1885.81	285.202
1887.06	289.651
1888.31	288.261
1889.56	287.102
1890.81	286.318
1892.05	290.952
1893.3	281.024
1894.55	286.532
1895.8	283.86
1897.04	282.191
1898.29	289.607
1899.54	286.531
1900.78	290.369
1902.03	281.264
1903.27	293.371
1904.52	288.608
1905.76	285.573
1907.01	285.477
1908.25	288.448
1909.5	290.651
1910.74	284.449
1911.98	286.323
1913.23	285.456
1914.47	288.653
1915.71	286.831
1916.96	284.737
1918.2	285.78
1919.44	282.487
1920.68	288.29
1921.92	284.676
1923.16	285.464
1924.41	284.364
1925.65	289.396
1926.89	289.745
1928.12	288.015
1929.36	292.107
1930.6	295.277
1931.84	290.39
1933.08	286.507
1934.32	294.134
1935.56	287.824
1936.8	286.677
1938.03	292.193
1939.27	285.794
1940.51	294.8
1941.75	285.988
1942.98	290.133
1944.22	287.402
1945.45	290.618
1946.69	293.616
1947.92	284.949
1949.16	294.707
1950.4	293.324
1951.63	289.009
1952.86	289.192
1954.1	284.658
1955.33	286.573
1956.56	296.72
1957.8	298.9
1959.03	292.097
1960.26	286.134
1961.5	289.827
1962.73	289.896
1963.96	292.883
1965.19	290.949
1966.42	287.376
1967.65	294.171
1968.88	294.973
1970.11	288.863
1971.34	292.53
1972.57	292.57
1973.8	293.304
1975.03	291.47
1976.26	287.775
1977.49	289.581
1978.72	288.503
1979.95	287.54
1981.17	295.013
1982.4	292.828
1983.63	288.937
1984.85	286.859
1986.08	291.517
1987.31	294.011
1988.53	290.778
1989.76	289.621
1990.98	289.807
1992.21	289.773
1993.43	287.51
1994.66	287.58
1995.88	286.949
1997.11	290.495
1998.33	287.646
1999.55	285.373
2000.78	288.415
2002	284.311
2003.22	286.055
2004.45	287.86
2005.59	286.35
2006.83	287.321
2008.06	287.898
2009.3	283.73
2010.54	282.553
2011.77	286.27
2013.01	287.793
2014.25	280.619
2015.48	283.555
2016.72	291.343
2017.95	289.012
2019.19	289.476
2020.42	281.894
2021.66	280.952
2022.89	284.387
2024.12	285.909
2025.36	289.195
2026.59	284.101
2027.82	287.559
2029.06	282.731
2030.29	284.28
2031.52	290.205
2032.75	281.322
2033.98	286.697
2035.21	279.352
2036.45	286.078
2037.68	284.173
2038.91	279.275
2040.14	285.461
2041.37	287.116
2042.6	280.44
2043.83	281.76
2045.05	279.872
2046.28	288.583
2047.51	284.314
2048.74	282.614
2049.97	290.502
2051.2	291.321
2052.42	283.028
2053.65	276.854
2054.88	280.587
2056.1	285.102
2057.33	287.039
2058.56	280.783
2059.78	276.142
2061.01	282.739
2062.23	283.764
2063.46	281.169
2064.68	286.064
2065.91	283.581
2067.13	285.607
2068.35	285.796
2069.58	281.737
2070.8	287.796
2072.02	287.193
2073.25	288.108
2074.47	287.376
2075.69	295.467
2076.91	284.928
2078.13	285.858
2079.35	281.477
2080.58	290.084
2081.8	290.076
2083.02	285.379
2084.24	284.437
2085.46	291.098
2086.68	284.783
2087.9	296.232
2089.12	292.597
2090.33	289.93
2091.55	287.357
2092.77	305.849
2093.99	283.324
2095.21	295.541
2096.43	291.624
2097.64	287.637
2098.86	287.561
2100.08	289.478
2101.29	290.645
2102.51	289.621
2103.73	288.575
2104.94	284.992
2106.16	297.545
2107.37	286.095
2108.59	287.688
2109.8	288.795
2111.01	295.421
2112.23	289.674
2113.44	288.953
2114.66	292.728
2115.87	284.025
2117.08	294.388
2118.29	291.241
2119.51	292.838
2120.72	285.297
2121.93	288.462
2123.14	285.765
2124.35	297.791
2125.57	283.988
2126.78	289.351
2127.99	280.742
2129.2	295.814
2130.41	286.27
2131.62	292.691
2132.82	292.518
2134.03	289.738
2135.24	284.008
2136.45	281.879
2137.66	295.163
2138.87	291.479
2140.08	285.428
2141.28	280.588
2142.49	283.438
2143.7	287.594
2144.9	287.717
2146.11	289.517
2147.32	290.289
2148.52	284.473
2149.73	291.584
2150.93	284.072
2152.14	285.1
2153.34	288.658
2154.55	284.449
2155.75	285.893
2156.96	282.136
2158.16	282.284
2159.36	287.71
2160.57	293.017
2161.77	286.406
2162.97	293.767
2164.17	283.277
2165.38	283.286
2166.58	288.71
2167.78	283.588
2168.98	279.016
2170.18	287.773
2171.38	282.689
2172.58	276.87
2173.78	286.242
2174.98	286.234
2176.18	287.981
2177.38	287.975
2178.58	282.246
2179.78	282.265
2180.98	276.626
2182.18	284.837
2183.38	283.619
2184.57	286.342
2185.77	281.892
2186.97	288.782
2188.16	289.649
2189.36	285.554
2190.56	283.71
2191.76	287.518
2192.95	289.578
2194.15	282.625
2195.34	287.086
2196.54	286.688
2197.73	288.501
2198.93	301.002
2200.12	283.041
2201.31	285.683
2202.51	287.443
2203.7	287.203
2204.89	285.616
2206.09	281.781
2207.28	288.37
2208.47	286.793
2209.67	286.851
2210.86	288.007
2212.05	287.32
2213.24	284.355
2214.43	284.696
2215.62	291.304
2216.81	290.34
2218	286.646
2219.19	288.729
2220.38	286.903
2221.57	284.748
2222.76	287.618
2223.95	285.197
2225.14	280.876
2226.33	289.607
2227.51	291.642
2228.7	285.93
2229.89	288.06
2231.08	283.688
2232.27	293.378
2233.45	294.589
2234.64	285.093
2235.82	284.961
2237.01	288.905
2238.2	296.958
2239.38	296.179
2240.57	288.69
2241.75	286.916
2242.94	287.894
2244.12	294.489
2245.3	287.38
2246.49	294.256
2247.67	295.282
2248.85	290.478
2250.04	293.317
2251.22	287.409
2252.4	286.709
2253.59	293.829
2254.77	296.772
2255.95	294.069
2257.13	298.121
2258.31	295.394
2259.49	287.976
2260.67	296.769
2261.85	298.831
2263.03	295.374
2264.21	300.683
2265.39	291.355
2266.57	286.301
2267.75	292.736
2268.93	294.824
2270.11	295.264
2271.29	291.685
2272.47	293.732
2273.64	292.866
2274.82	297.746
2276	297.955
2277.17	299.329
2278.35	291.021
2279.53	298.41
2280.71	294.3
2281.88	296.254
2283.06	296.662
2284.23	289.504
2285.41	290.588
2286.58	297.409
2287.76	296.722
2288.93	299.274
2290.1	297.055
2291.28	297.36
2292.45	293.817
2293.62	297.812
2294.8	306.267
2295.97	296.332
2297.14	294.583
2298.31	288.199
2299.49	296.143
2300.66	292.41
2301.83	292.449
2303	294.345
2304.17	296.45
2305.34	290.836
2306.51	298.669
2307.68	299.522
2308.85	295.743
2310.02	296.995
2311.19	299.435
2312.36	302.977
2313.53	300.414
2314.7	299.909
2315.87	305.269
2317.03	296.466
2318.2	292.559
2319.37	295.266
2320.54	304.036
2321.7	309.23
2322.87	305.514
2324.03	315.217
2325.2	315.768
2326.37	325.086
2327.53	404.799
2328.7	570.411
2329.86	340.014
2331.03	306.301
2332.19	297.584
2333.36	298.37
2334.52	301.976
2335.68	293.322
2336.85	299.968
2338.01	299.886
2339.17	291.24
2340.34	297.751
2341.5	304.991
2342.66	285.189
2343.82	304.456
2344.98	298.401
2346.14	291.298
2347.31	290.337
2348.47	292.329
2349.63	293.207
2350.79	290.357
2351.95	294.185
2353.11	293.358
2354.27	289.983
2355.43	291.785
2356.59	292.098
2357.74	289.042
2358.9	291.483
2360.06	292.243
2361.22	290.442
2362.38	291.599
2363.53	289.747
2364.69	288.354
2365.74	284.981
2366.92	290.086
2368.09	288.039
2369.26	300.039
2370.43	288.387
2371.6	288.18
2372.77	288.903
2373.94	289.64
2375.11	285.613
2376.28	285.457
2377.45	288.094
2378.62	288.751
2379.79	283.704
2380.96	287.368
2382.13	293.901
2383.29	286.331
2384.46	295.647
2385.63	289.775
2386.8	291.233
2387.97	288.254
2389.13	288.166
2390.3	285.348
2391.47	289.127
2392.63	279.582
2393.8	285.652
2394.96	284.635
2396.13	293.98
2397.29	289.116
2398.46	290.031
2399.62	290.979
2400.79	283.438
2401.95	283.309
2403.12	282.67
2404.28	289.701
2405.44	287.148
2406.61	285.367
2407.77	287.209
2408.93	287.152
2410.09	286.231
2411.26	289.976
2412.42	289.213
2413.58	284.607
2414.74	298.487
2415.9	285.223
2417.06	283.484
2418.22	282.773
2419.38	294.381
2420.54	291.684
2421.7	280.216
2422.86	290.788
2424.02	288.19
2425.18	281.941
2426.34	285.029
2427.5	287.062
2428.66	283.229
2429.81	285.069
2430.97	285.126
2432.13	280.85
2433.29	287.729
2434.44	285.911
2435.6	291.845
2436.76	286.432
2437.91	279.806
2439.07	286.665
2440.23	287.026
2441.38	298.433
2442.53	292.993
2443.69	287.557
2444.84	294.393
2446	291.761
2447.15	283.563
2448.31	290.236
2449.46	290.294
2450.61	298.259
2451.77	290.017
2452.92	290.962
2454.07	290.965
2455.22	287.508
2456.38	285.924
2457.53	292.745
2458.68	300.405
2459.83	294.892
2460.98	297.898
2462.14	299.801
2463.29	284.638
2464.43	297.765
2465.59	291.09
2466.74	294.83
2467.88	291.884
2469.03	302.299
2470.18	289.07
2471.33	294.018
2472.48	290.5
2473.63	289.56
2474.78	286.907
2475.92	287.493
2477.07	295.296
2478.22	294.101
2479.37	292.814
2480.51	296.331
2481.66	300.849
2482.81	299.866
2483.95	294.994
2485.1	291.147
2486.24	295.048
2487.39	302.488
2488.53	298.487
2489.68	301.262
2490.82	295.554
2491.97	293.439
2493.11	294.688
2494.25	289.647
2495.4	294.244
2496.54	292.5
2497.69	286.39
2498.83	288.547
2499.97	291.358
2501.11	291.789
2502.25	290.574
2503.4	291.439
2504.54	287.412
2505.68	295.912
2506.82	294.234
2507.96	285.743
2509.1	304.713
2510.24	296.743
2511.38	292.295
2512.52	295.928
2513.66	288.542
2514.8	287.469
2515.94	295.459
2517.08	300.607
2518.21	288.053
2519.35	293.632
2520.49	286.38
2521.63	288.34
2522.77	290.847
2523.9	299.256
2525.04	290.62
2526.18	298.507
2527.31	291.731
2528.45	293.701
2529.58	287.274
2530.72	296.575
2531.86	286.034
2532.99	292.349
2534.13	289.669
2535.26	288.553
2536.4	288.516
2537.53	290.187
2538.66	289.879
2539.8	293.351
2540.93	288.635
2542.06	286.082
2543.2	293.648
2544.33	292.497
2545.46	285.034
2546.59	293.306
2547.73	295.207
2548.86	286.005
2549.99	290.929
2551.12	289.311
2552.25	293.242
2553.38	289.371
2554.51	290.293
2555.64	289.601
2556.77	301.31
2557.9	298.614
2559.03	296.765
2560.16	287.282
2561.29	292.944
2562.42	298.752
2563.55	287.95
2564.67	295.985
2565.8	291.3
2566.93	289.455
2568.06	297.917
2569.18	286.668
2570.31	287.86
2571.44	292.178
2572.56	290.77
2573.69	292.931
2574.81	293.692
2575.94	295.886
2577.06	296.116
2578.19	299.425
2579.31	297.941
2580.44	288.669
2581.56	298.336
2582.69	304.15
2583.81	293.75
2584.94	294.879
2586.06	300.147
2587.18	300.578
2588.3	297.391
2589.43	296.542
2590.55	293.659
2591.67	306.177
2592.79	295.883
2593.91	295.282
2595.04	303.232
2596.16	304.326
2597.28	299.108
2598.4	299.909
2599.52	299.335
2600.64	299.426
2601.76	297.07
2602.88	296.076
2604	301.92
2605.12	293.314
2606.24	294.328
2607.35	303.204
2608.47	304.648
2609.59	303.863
2610.71	302.036
2611.83	293.211
2612.94	296.965
2614.06	304.911
2615.18	291.846
2616.29	309.557
2617.41	305.801
2618.53	302.001
2619.64	296.699
2620.76	301.172
2621.87	298.795
2622.99	305.73
2624.1	311.67
2625.22	303.913
2626.33	314.806
2627.45	302.267
2628.56	304.183
2629.67	301.139
2630.79	303.198
2631.9	307.224
2633.01	313.037
2634.12	293.359
2635.24	295.777
2636.35	295.33
2637.46	303.697
2638.57	300.756
2639.68	300.91
2640.8	294.423
2641.91	304.482
2643.02	299.962
2644.13	304.504
2645.24	300.374
2646.35	307.963
2647.46	296.194
2648.57	293.737
2649.67	297.416
2650.78	292.53
2651.89	295.155
2653	289.269
2654.11	292.961
2655.22	294.564
2656.32	300.336
2657.43	288.918
2658.54	300.271
2659.65	309.344
2660.75	299.703
2661.86	295.5
2662.96	290.936
2664.07	294.535
2665.18	295.385
2666.28	300.067
2667.39	300.838
2668.49	295.67
2669.6	292.721
2670.7	296.601
2671.8	291.602
2672.91	283.578
2674.01	295.696
2675.11	305.445
2676.22	288.738
2677.32	291.342
2678.42	290.181
2679.53	291.893
2680.63	286.102
2681.73	297.564
2682.83	294.302
2683.93	296.136
2685.03	293.521
2686.14	292.527
2687.24	286.12
2688.34	289.91
2689.44	289.564
2690.54	295.152
2691.64	290.577
2692.74	289.506
2693.84	291.233
2694.93	287.664
2696.03	287.176
2697.13	290.243
2698.23	288.891
2699.33	294.359
2700.43	290.921
2701.52	292.734
2702.62	285.96
2703.72	291.746
2704.81	292.822
2705.9	284.697
2707.01	288.454
2708.12	299.503
2709.23	293.043
2710.34	293.142
2711.45	282.673
2712.56	292.572
2713.67	288.929
2714.78	286.599
2715.89	292.25
2716.99	290.142
2718.1	297.674
2719.21	292.315
2720.32	288.985
2721.43	286.274
2722.54	296.413
2723.64	296.379
2724.75	292.927
2725.86	291.883
2726.96	306.914
2728.07	285.403
2729.18	287.371
2730.28	294.226
2731.39	290.79
2732.49	293.572
2733.6	293.331
2734.71	294.315
2735.81	288.133
2736.91	295.84
2738.02	294.884
2739.12	297.875
2740.23	291.139
2741.33	296.679
2742.43	284.774
2743.54	287.981
2744.64	301.654
2745.74	288.336
2746.84	292.853
2747.95	292.897
2749.05	295.819
2750.15	293.925
2751.25	284.699
2752.35	296.507
2753.45	300.433
2754.55	295.545
2755.66	296.372
2756.76	299.448
2757.86	296.746
2758.96	292.913
2760.05	290.98
2761.15	298.001
2762.25	289.954
2763.35	287.334
2764.45	293.311
2765.55	297.051
2766.65	293.999
2767.75	289.02
2768.84	295.661
2769.94	293.929
2771.04	292.128
2772.13	296.554
2773.23	300.421
2774.33	296.19
2775.42	294.196
2776.52	288.278
2777.61	287.295
2778.71	291.147
2779.81	290.867
2780.9	288.918
2782	293.743
2783.09	293.524
2784.18	293.284
2785.28	291.576
2786.37	294.62
2787.47	290.584
2788.56	297.766
2789.65	295.703
2790.74	288.96
2791.84	297.249
2792.93	289.827
2794.02	295.395
2795.11	288.826
2796.2	296.193
2797.3	294.177
2798.39	292.125
2799.48	297.014
2800.57	292.19
2801.66	293.054
2802.75	287.52
2803.84	292.886
2804.93	293.554
2806.02	301.182
2807.11	295.473
2808.2	287.858
2809.28	295.331
2810.37	291.453
2811.46	287.367
2812.55	293.71
2813.64	292.914
2814.73	290.89
2815.81	294.463
2816.9	292.466
2817.99	292.102
2819.07	281.571
2820.16	300.762
2821.25	294.634
2822.33	298.291
2823.42	292.455
2824.5	284.118
2825.59	298.064
2826.67	292.644
2827.76	297.52
2828.84	282.154
2829.93	296.166
2831.01	291.586
2832.09	291.37
2833.18	292.122
2834.26	289.357
2835.34	291.442
2836.43	283.164
2837.51	295.331
2838.59	287.759
2839.67	289.804
2840.75	287.502
2841.84	295.852
2842.92	296.601
2844	297.363
2845.08	288.816
2846.16	292.878
2847.24	290.294
2848.32	291.83
2849.4	292.869
2850.48	295.902
2851.56	294.138
2852.64	293.11
2853.72	290.377
2854.8	299.857
2855.87	290.471
2856.95	301.731
2858.03	285.839
2859.11	294.283
2860.19	289.596
2861.26	294.77
2862.34	295.128
2863.42	299.627
2864.49	290.974
2865.57	291.119
2866.65	292.283
2867.72	296.121
2868.8	296.524
2869.87	292.658
2870.95	292.669
2872.02	300.073
2873.1	294.473
2874.17	295.809
2875.25	297.087
2876.32	293.241
2877.4	291.38
2878.47	301.005
2879.54	296.111
2880.62	290.434
2881.69	303.042
2882.76	291.799
2883.83	297.153
2884.9	296.473
2885.98	300.486
2887.05	301.537
2888.12	303.774
2889.19	297.272
2890.26	289.622
2891.33	300.97
2892.4	300.136
2893.47	300.393
2894.54	295.288
2895.61	305.327
2896.68	301.396
2897.75	296.692
2898.82	300.559
2899.89	296.986
2900.96	295.138
2902.03	294.114
2903.09	298.939
2904.16	293.468
2905.23	295.491
2906.3	300.938
2907.36	297.002
2908.43	299.083
2909.5	308.52
2910.57	296.238
2911.63	302.045
2912.7	307.868
2913.76	296.338
2914.83	301.885
2915.89	324.749
2916.96	308.597
2918.02	303.846
2919.09	299.971
2920.15	296.907
2921.22	297.653
2922.28	297.467
2923.34	302.187
2924.41	294.58
2925.47	294.554
2926.53	295.439
2927.6	301.07
2928.66	300.938
2929.72	297.636
2930.78	304.95
2931.84	300.34
2932.91	298.177
2933.97	286.913
2935.03	296.209
2936.09	298.9
2937.15	295.211
2938.21	298.006
2939.27	302.459
2940.33	298.762
2941.39	305.039
2942.45	298.591
2943.51	298.737
2944.57	297.079
2945.63	307.881
2946.68	307.441
2947.74	297.185
2948.8	298.109
2949.86	296.965
2950.92	301.779
2951.97	299.049
2953.03	299.886
2954.09	296.723
2955.14	297.398
2956.2	305.88
2957.25	293.719
2958.31	299.428
2959.37	305.102
2960.42	298.369
2961.48	292.583
2962.53	295.975
2963.59	298.996
2964.64	296.41
2965.7	298.132
2966.75	293.13
2967.8	290.078
2968.86	292.034
2969.91	296.794
2970.96	293.092
2972.02	294.061
2973.07	301.616
2974.12	300.605
2975.17	295.76
2976.22	295.772
2977.28	284.563
2978.33	299.864
2979.38	293.355
2980.43	296.076
2981.48	304.451
2982.53	298.603
2983.58	296.545
2984.63	304.864
2985.68	302.044
2986.73	295.629
2987.78	307.006
2988.83	295.836
2989.88	296.774
2990.93	298.674
2991.98	299.768
2993.02	295.919
2994.07	300.562
2995.12	298.928
2996.17	303.063
2997.21	296.553
2998.26	295.789
2999.31	294.882
2999.94	302.359