File: Data/3-Raman/maps/bu20-G-ff1-FI01_CLS_burangaite_raw.txt
#Acq. time (s)=	1
#Accumulations=	1
#Range (cm-¹)=	100...4000
#Windows=	1
#Auto scanning=	Off
#Autofocus=	Off
#SWIFT=	On
#Macrospot=	Off
#AutoExposure=	Off
#Spike filter=	Off
#Delay time (s)=	0
#Binning=	1
#Readout mode=	Signal
#DeNoise=	Lite
#ICS correction=	Off
#Dark correction=	Off
#Inst. Process=	Off
#Detector temperature (°C)=	-60.09
#Instrument=	LabRAM HR Evol
#Detector=	SIN-EM FIVIS
#Objective=	x100_VIS
#Grating=	150 (500nm)
#ND Filter=	100%
#Laser=	532nm_Edge
#Hole=	30.0125
#Temperature=	0
#Range=	Visible
#StageXY=	75x50mm Scan+
#StageZ=	Z motor
#Z (µm)=	1887.6
#Full time(mm:ss)=	31:39
#Project=	Buranga
#Sample=	BU18FA20_G
#Site=	G_trl1
#Title=	20-G_trl1_MI01_topbb_1
#Remark=
#Date=	30.07.2019 16:51
#Cursor=	Rectangle 9 points
#Y (µm)=	-10.8896 ... -8.3655
#X (µm)=	-8.60704 ... -6.60704
#Generated=	29.03.2022 09:29:50
103.656	445.466
108.278	372.007
112.899	320.416
117.517	291.026
122.131	264.006
126.744	233.276
131.355	189.705
135.964	150.735
140.571	116.494
145.173	90.2981
149.776	69.7826
154.375	64.2718
158.973	63.4844
163.566	74.2756
168.159	83.5569
172.75	84.0849
177.339	64.9651
181.923	39.7557
186.507	22.4113
191.089	15.3575
195.668	12.2379
200.243	15.2312
204.818	15.6481
209.391	14.7061
213.96	14.5963
218.528	12.4354
223.094	13.3003
227.655	15.6324
232.217	22.328
236.776	34.8528
241.331	48.1581
245.886	68.5038
250.439	85.5175
254.987	100.063
259.535	106.63
264.081	89.087
268.622	61.2431
273.164	38.416
277.703	28.5938
282.238	58.4406
286.773	112.071
291.305	116.779
295.833	95.0747
300.362	59.986
304.885	46.7754
309.409	42.4364
313.93	46.5194
318.448	54.1186
322.965	66.0989
327.477	82.1746
331.99	101.457
336.5	120.811
341.007	137.191
345.513	149.501
350.014	159.705
354.516	164.917
359.013	165.226
363.51	158.359
368.005	143.686
372.496	125.88
376.987	109.31
381.473	97.4828
385.96	90.1081
390.442	86.3374
394.923	90.8601
399.401	94.0015
403.879	93.6724
408.352	80.5556
412.825	65.0736
417.294	54.5832
421.763	48.6188
426.227	47.8211
430.692	51.1203
435.152	53.3453
439.612	54.7533
444.068	55.9808
448.524	57.5398
452.976	60.5886
457.427	66.3539
461.874	73.1895
466.32	79.757
470.765	85.5645
475.205	88.5309
479.646	90.6636
484.083	92.5753
488.519	95.424
492.951	94.6969
497.381	97.3103
501.811	101.187
506.237	107.287
510.663	114.951
515.084	119.502
519.504	122.748
523.923	118.59
528.338	109.35
532.753	98.3632
537.164	86.3908
541.572	74.6716
545.981	63.0643
550.385	52.252
554.788	41.9455
559.19	33.0361
563.588	27.4508
567.986	25.6905
572.38	30.458
576.771	45.3572
581.163	68.0756
585.551	94.7754
589.936	136.743
594.319	173.686
598.702	189.787
603.081	185.481
607.458	160.18
611.835	133.145
616.208	110.564
620.578	91.8563
624.949	76.1685
629.315	66.1429
633.68	60.2092
638.042	56.3795
642.404	53.4537
646.762	51.4749
651.118	45.5839
655.472	41.7533
659.825	40.56
664.175	41.8573
668.523	45.3192
672.868	50.5986
677.213	54.2867
681.555	56.2253
685.894	54.1812
690.231	48.5701
694.566	39.2509
698.901	29.6311
703.232	19.9743
707.561	12.9459
711.888	8.66686
716.212	5.01771
720.537	3.00795
724.858	1.69517
729.176	0.971333
733.493	0.787592
737.807	0.77383
742.119	0.878987
746.432	1.51658
750.74	1.78087
755.046	2.16383
759.35	3.40373
763.652	5.48614
767.952	8.72763
772.25	16.1823
776.546	26.3323
780.842	37.6142
785.133	47.01
789.423	51.2914
793.711	49.0605
797.997	41.3882
802.28	33.0325
806.562	25.1935
810.841	20.5416
815.119	17.6276
819.394	15.7637
823.668	14.6616
827.941	13.8149
832.211	12.9151
836.478	12.1393
840.743	11.2373
845.006	10.9605
849.268	10.9983
853.527	11.0701
857.784	11.1461
862.039	11.1752
866.293	11.6611
870.544	12.9687
874.793	14.7813
879.04	16.1223
883.285	16.7575
887.528	16.7575
891.769	16.0687
896.008	15.2448
900.246	15.7837
904.481	17.3106
908.714	20.0461
912.945	23.348
917.174	26.3882
921.401	29.3271
925.626	32.2332
929.849	34.576
934.068	37.0772
938.287	40.0787
942.504	43.7715
946.72	49.4395
950.933	54.5349
955.144	58.4039
959.353	60.8893
963.56	65.0613
967.765	70.6079
971.968	82.239
976.17	96.9666
980.367	116.025
984.564	133.045
988.759	143.99
992.953	146.546
997.144	137.807
1001.33	134.083
1005.52	154.345
1009.71	181.824
1013.89	261.924
1018.07	319.518
1022.25	351.09
1026.43	359.588
1030.6	338.661
1034.78	321.987
1038.94	321.924
1043.11	303.709
1047.28	274.213
1051.45	244.484
1055.61	218.132
1059.77	195.981
1063.93	177.032
1068.09	154.289
1072.25	129.577
1076.4	109.795
1080.55	96.8301
1084.7	92.6991
1088.85	98.5327
1092.99	111.23
1097.14	131.643
1101.28	152.09
1105.42	164.354
1109.56	168.211
1113.69	167.198
1117.83	161.632
1121.96	152.872
1126.09	142.873
1130.22	134.076
1134.35	128.086
1138.47	125.164
1142.59	119.89
1146.71	110.694
1150.83	98.5263
1154.95	85.6521
1159.06	79.4162
1163.18	74.7105
1167.29	70.1431
1171.4	65.5504
1175.5	60.2218
1179.61	55.2391
1183.71	50.2944
1187.81	46.6044
1191.91	45.4295
1196.01	46.4921
1200.1	50.3732
1204.2	54.2202
1208.29	56.0885
1212.38	55.134
1216.47	51.4538
1220.55	48.1294
1224.64	46.2347
1228.72	45.3669
1232.8	42.8058
1236.88	40.5328
1240.95	37.9511
1245.03	36.479
1249.1	35.7398
1253.17	36.929
1257.24	43.2615
1261.31	52.1348
1265.37	61.0736
1269.44	59.3549
1273.5	82.321
1277.56	264.746
1281.61	423.863
1285.67	303.104
1289.72	95.5729
1293.77	52.7272
1297.83	35.2334
1301.87	24.2088
1305.92	21.0674
1309.96	19.0399
1314.01	18.5518
1318.05	18.4815
1322.09	18.9046
1326.12	19.6854
1330.16	20.0121
1334.19	19.6385
1338.22	19.927
1342.25	19.5456
1346.28	19.7167
1350.3	21.4054
1354.33	22.391
1358.35	25.5683
1362.37	32.7008
1366.39	39.216
1370.4	52.3968
1374.42	68.3146
1378.43	130.525
1382.44	536.693
1386.45	746.993
1390.46	395.728
1394.46	110.912
1398.46	75.0261
1402.47	73.8306
1406.46	75.4937
1410.46	60.3331
1414.46	44.5668
1418.45	31.9454
1422.45	22.5829
1426.43	15.9558
1430.42	12.5127
1434.41	9.99352
1438.39	8.88003
1442.38	8.48996
1446.36	8.72539
1450.34	8.35236
1454.31	7.44029
1458.29	5.89654
1462.27	4.09593
1466.24	2.7781
1470.21	2.67068
1474.18	2.96215
1478.14	3.22124
1482.11	3.91691
1486.07	4.57075
1490.03	5.41665
1493.99	5.48478
1497.95	4.63516
1501.9	4.21114
1505.86	3.73869
1509.81	3.71939
1513.76	4.08407
1517.71	4.63436
1521.65	5.0241
1525.6	6.25897
1529.54	7.06355
1533.48	7.17423
1537.42	7.07275
1541.36	6.96711
1545.29	6.79545
1549.23	7.03208
1553.16	6.79925
1557.09	6.17996
1561.02	5.71517
1564.94	5.72119
1568.87	5.42988
1572.79	5.17259
1576.71	5.46427
1580.63	6.28766
1584.55	7.40046
1588.47	8.31822
1592.38	7.93392
1596.29	7.45436
1600.2	6.24939
1604.11	5.15217
1608.02	4.21548
1611.92	3.80681
1615.83	3.47084
1619.73	4.88513
1623.63	6.48519
1627.53	7.71484
1631.42	8.76511
1635.32	8.00371
1639.21	7.4496
1643.1	7.11982
1646.99	5.61124
1650.88	4.57367
1654.76	3.6576
1658.64	2.7489
1662.53	1.71394
1666.41	0.970432
1670.28	0.544823
1674.16	0.858812
1678.04	1.06044
1681.91	1.82149
1685.78	2.93402
1689.65	4.3183
1693.52	5.5776
1697.38	6.71278
1701.25	7.33537
1705.11	7.3946
1708.97	6.63531
1712.83	5.65377
1716.69	4.69292
1720.54	4.13696
1724.4	4.60797
1728.25	5.54208
1732.1	6.8735
1735.95	8.31273
1739.79	9.70881
1743.64	10.0374
1747.48	10.2134
1751.33	10.4616
1755.17	9.33256
1759	8.11526
1762.84	6.30132
1766.68	5.21842
1770.51	4.49583
1774.34	4.47615
1778.17	4.57152
1782	5.23699
1785.82	5.81374
1789.65	5.82518
1793.47	5.59608
1797.29	5.31866
1801.11	5.70626
1804.93	6.25863
1808.74	7.04901
1812.56	7.94321
1816.37	8.45999
1820.18	8.75411
1823.99	8.52331
1827.79	7.85137
1831.6	6.80458
1835.4	5.54494
1839.2	4.58219
1843	4.10458
1846.8	4.10729
1850.6	4.89226
1854.39	5.93368
1858.19	7.11287
1861.98	8.38257
1865.77	9.4844
1869.56	10.0377
1873.34	10.054
1877.13	9.38914
1880.91	8.25642
1884.69	7.60031
1888.47	6.48126
1892.25	5.32774
1896.03	4.31719
1899.8	4.51349
1903.57	5.23587
1907.34	6.46092
1911.11	7.5302
1914.88	7.79307
1918.65	7.93696
1922.41	8.32414
1926.18	8.07148
1929.94	7.95358
1933.7	8.64683
1937.45	9.39846
1941.21	11.5512
1944.96	12.1337
1948.72	9.62178
1952.47	6.99051
1956.22	5.78912
1959.96	5.73344
1963.71	7.51296
1967.45	8.15669
1971.2	8.28568
1974.94	8.0908
1978.68	8.13116
1982.42	7.88203
1986.15	7.2607
1989.89	6.73013
1993.62	6.28025
1997.35	6.14031
2001.08	5.79695
2004.8	5.39535
2008.53	5.27993
2012.25	5.03977
2015.98	5.46449
2019.7	5.96362
2023.42	6.3744
2027.13	6.32885
2030.85	6.30071
2034.56	6.3057
2038.28	6.20068
2041.99	6.34434
2045.7	6.1483
2049.41	5.98769
2053.11	5.68061
2056.82	5.4748
2060.52	4.67777
2064.22	4.22452
2067.92	4.55494
2071.62	4.39905
2075.31	5.26222
2079.01	6.24879
2082.7	7.06744
2086.39	7.4469
2090.08	7.99305
2093.77	7.23266
2097.45	6.18464
2101.14	5.48004
2104.82	4.46012
2108.5	4.57333
2112.18	4.79721
2115.86	4.63367
2119.54	4.27674
2123.21	3.67314
2126.88	3.67772
2130.56	4.28414
2134.23	5.06067
2137.89	6.28874
2141.56	6.67656
2145.23	6.66334
2148.89	5.98561
2152.55	5.28217
2156.21	4.5392
2159.87	3.7454
2163.53	3.48662
2167.18	3.21647
2170.84	2.86674
2174.49	3.66246
2178.14	3.8184
2181.79	3.7263
2185.44	3.97251
2189.08	4.62468
2192.73	5.53049
2196.37	6.88244
2200.01	7.92372
2203.65	8.17436
2207.29	8.35699
2210.92	6.77049
2214.56	5.07348
2218.19	6.94815
2221.82	7.8409
2225.45	8.69083
2229.08	9.71207
2232.7	10.2302
2236.33	10.0421
2239.95	9.4795
2243.57	8.30849
2247.19	6.69804
2250.81	5.58264
2254.43	4.29979
2258.04	3.67642
2261.66	3.79971
2265.27	4.33852
2268.88	5.48933
2272.49	7.91822
2276.1	9.79968
2279.7	11.2137
2283.31	12.1995
2286.91	11.4865
2290.51	10.0974
2294.11	8.4509
2297.71	6.85462
2301.3	5.47122
2304.9	4.73342
2308.49	5.05961
2312.08	6.82105
2315.67	9.89115
2319.26	12.994
2322.85	16.3339
2326.43	18.0467
2330.02	17.7895
2333.6	15.7068
2337.18	13.4268
2340.76	11.1489
2344.34	9.21367
2347.91	8.99581
2351.49	8.18386
2355.06	7.09767
2358.63	7.50301
2362.2	8.20653
2365.77	8.60221
2369.33	9.21783
2372.9	10.028
2376.46	11.2358
2380.02	12.3998
2383.58	13.1394
2387.14	13.2633
2390.7	13.1041
2394.25	12.6676
2397.81	11.5474
2401.36	10.5091
2404.91	9.1711
2408.46	8.23346
2412.01	7.24058
2415.56	6.59098
2419.1	6.5577
2422.64	6.30175
2426.18	6.72013
2429.72	6.67385
2433.26	6.68135
2436.8	6.54441
2440.34	6.19737
2443.87	6.15672
2447.4	6.1365
2450.93	5.70588
2454.46	5.28156
2457.99	4.61117
2461.52	4.25767
2465.04	4.27847
2468.56	4.40278
2472.09	4.46848
2475.61	4.87236
2479.13	4.39673
2482.64	4.08049
2486.16	4.50771
2489.67	4.93436
2493.18	6.10245
2496.69	7.22999
2500.2	7.93056
2503.71	8.25131
2507.22	8.01474
2510.72	5.37967
2514.23	3.99727
2517.73	2.95819
2521.23	3.0024
2524.73	3.08939
2528.23	3.12591
2531.72	2.92109
2535.21	3.05271
2538.71	3.3847
2542.2	4.13363
2545.69	4.56894
2549.18	4.73278
2552.66	4.41669
2556.15	3.98475
2559.63	3.69895
2563.12	3.67414
2566.6	3.46259
2570.08	3.21636
2573.55	3.39596
2577.03	3.53597
2580.5	3.66431
2583.98	3.30602
2587.45	2.75555
2590.92	3.15898
2594.39	3.69143
2597.86	4.46826
2601.32	5.23191
2604.79	5.90112
2608.25	6.59188
2611.71	6.83518
2615.17	6.81496
2618.63	6.22519
2622.08	6.25883
2625.54	6.94046
2628.99	7.41042
2632.45	8.30398
2635.9	9.02581
2639.35	8.82327
2642.79	8.49708
2646.24	7.56385
2649.69	5.6601
2653.13	4.49477
2656.57	3.95466
2660.01	3.83113
2663.45	4.66195
2666.89	5.39097
2670.32	5.90617
2673.76	6.43553
2677.19	7.34063
2680.62	8.583
2684.05	9.20139
2687.48	9.70841
2690.91	10.5542
2694.33	11.4965
2697.76	11.523
2701.18	11.9741
2704.6	12.2382
2708.02	12.4249
2711.44	12.2689
2714.86	12.1616
2718.27	11.6098
2721.69	10.3631
2725.1	9.5494
2728.51	8.87462
2731.92	8.60993
2735.33	8.85702
2738.74	8.46604
2742.14	7.81174
2745.55	6.8807
2748.95	5.61927
2752.35	5.18788
2755.75	6.44203
2759.15	7.61469
2762.54	7.89322
2765.94	7.74383
2769.33	7.6922
2772.72	7.8832
2776.12	8.41368
2779.51	8.8447
2782.89	8.69696
2786.28	9.04726
2789.67	9.8994
2793.05	9.98458
2796.43	9.92723
2799.81	8.79927
2803.19	6.99328
2806.57	6.18186
2809.95	5.62401
2813.32	5.02138
2816.69	4.90149
2820.06	5.50192
2823.44	7.29811
2826.81	8.85743
2830.17	9.74045
2833.54	9.14587
2836.9	7.8948
2840.27	7.04057
2843.63	7.27959
2846.99	6.73545
2850.35	6.19091
2853.71	5.74405
2857.06	5.5383
2860.42	6.05035
2863.77	5.76279
2867.12	5.2195
2870.48	4.71621
2873.83	4.20808
2877.17	4.46571
2880.52	5.3523
2883.86	6.70164
2887.21	8.44357
2890.55	9.85911
2893.89	10.4135
2897.23	10.4328
2900.57	9.55852
2903.91	8.44172
2907.24	7.41096
2910.57	6.58471
2913.91	6.28951
2917.24	6.37998
2920.57	6.14456
2923.9	5.67306
2927.22	5.4857
2930.55	5.22706
2933.87	4.68969
2937.19	5.43939
2940.51	5.70474
2943.83	6.36902
2947.15	8.32117
2950.47	9.77789
2953.79	10.1158
2957.1	9.7389
2960.41	9.73871
2963.72	9.30081
2967.03	8.98005
2970.34	8.3756
2973.65	7.72951
2976.95	8.41066
2980.26	10.2221
2983.56	11.4055
2986.86	13.238
2990.16	14.1881
2993.46	15.2095
2996.76	16.7086
3000.06	16.3648
3003.35	15.349
3006.64	14.2943
3009.94	13.5769
3013.23	13.5082
3016.51	13.9436
3019.8	14.849
3023.09	15.4145
3026.38	16.937
3029.66	17.753
3032.94	17.2696
3036.22	16.6761
3039.5	15.9091
3042.78	15.9642
3046.05	17.902
3049.33	20.1455
3052.6	18.5973
3055.88	18.6356
3059.15	19.6724
3062.42	20.4534
3065.69	21.4966
3068.95	21.7777
3072.22	21.7075
3075.48	21.5922
3078.75	21.4365
3082.01	22.1705
3085.27	23.076
3088.53	22.6272
3091.79	22.2486
3095.04	23.0451
3098.3	24.114
3101.55	25.0701
3104.8	25.8111
3108.05	26.2697
3111.3	25.6992
3114.55	24.6068
3117.8	23.4292
3121.04	22.9046
3124.29	23.6347
3127.53	24.4638
3130.77	25.2477
3134.01	26.5965
3137.25	28.4889
3140.49	29.9666
3143.72	31.0855
3146.96	32.0258
3150.19	32.3896
3153.42	32.3778
3156.65	32.7104
3159.88	32.9322
3163.11	33.7001
3166.34	35.101
3169.56	37.3534
3172.79	40.0385
3176.01	42.5837
3179.23	45.1816
3182.45	49.8318
3185.67	53.7913
3188.88	56.8677
3192.1	61.6958
3195.31	68.4887
3198.53	73.8705
3201.74	79.1968
3204.95	83.37
3208.16	89.1565
3211.37	97.1178
3214.57	108.714
3217.78	122.184
3220.98	138.936
3224.18	157.741
3227.39	179.906
3230.59	207.591
3233.78	235.422
3236.98	260.775
3240.18	282.451
3243.37	294.103
3246.56	294.794
3249.76	285.92
3252.95	269.097
3256.14	248.491
3259.32	226.352
3262.51	204.708
3265.7	185.537
3268.88	168.604
3272.06	152.814
3275.24	139.323
3278.42	127.389
3281.6	116.964
3284.78	110.287
3287.96	105.385
3291.13	97.9334
3294.31	91.5563
3297.48	86.0867
3300.65	81.7633
3303.82	76.9567
3306.99	73.4839
3310.15	71.1596
3313.32	69.1094
3316.48	68.1172
3319.65	66.4472
3322.81	62.7309
3325.97	58.6536
3329.13	54.1613
3332.28	50.1019
3335.44	46.7173
3338.6	43.7452
3341.75	41.2775
3344.9	39.133
3348.05	36.4964
3351.2	33.9502
3354.35	31.7999
3357.5	30.078
3360.65	28.1425
3363.79	25.8709
3366.94	22.936
3370.08	20.949
3373.22	19.6137
3376.36	18.7783
3379.5	18.3318
3382.63	17.5062
3385.77	17.1958
3388.9	17.5003
3392.04	17.865
3395.17	18.7527
3398.3	19.3807
3401.43	15.6497
3404.56	14.5617
3407.69	15.9301
3410.81	23.8491
3413.94	37.7137
3417.06	50.9256
3420.18	75.7155
3423.3	137.641
3426.42	240.197
3429.54	261.4
3432.65	209.604
3435.77	119.628
3438.88	67.135
3442	38.8421
3445.11	21.0013
3448.22	14.1923
3451.33	10.2038
3454.43	9.02495
3457.54	11.0452
3460.65	12.4421
3463.75	14.1376
3466.85	14.6896
3469.95	16.3204
3473.05	17.6344
3476.15	20.1089
3479.25	24.2307
3482.35	31.0385
3485.44	40.9796
3488.54	53.9112
3491.63	66.8895
3494.72	82.5832
3497.81	106.378
3500.9	130.566
3503.99	160.188
3507.07	182.433
3510.16	193.779
3513.24	185.032
3516.32	156.869
3519.41	124.253
3522.49	94.6513
3525.56	68.8783
3528.64	48.6697
3531.72	37.9296
3534.79	30.7961
3537.87	25.5597
3540.94	21.9293
3544.01	18.6707
3547.08	14.3953
3550.15	12.7925
3553.22	12.0927
3556.28	10.337
3559.35	10.5974
3562.41	11.5813
3565.47	12.9707
3568.54	14.3039
3571.6	14.1022
3574.65	13.309
3577.71	12.5187
3580.77	12.0998
3583.82	12.6248
3586.88	13.0907
3589.93	13.2502
3592.98	12.7503
3596.03	10.2216
3599.08	9.38072
3602.13	8.76303
3605.18	12.8797
3608.22	24.6294
3611.27	42.8349
3614.31	77.1564
3617.35	115.724
3620.39	152.455
3623.43	177.121
3626.47	170.438
3629.5	150.266
3632.54	126.449
3635.57	103.749
3638.61	85.8076
3641.64	74.3208
3644.67	68.0891
3647.7	65.5428
3650.73	62.6422
3653.75	57.5688
3656.78	47.5952
3659.8	36.4537
3662.83	26.3789
3665.85	18.2098
3668.87	12.0646
3671.89	8.24918
3674.91	5.52516
3677.92	3.88363
3680.94	3.61089
3683.96	2.20392
3686.97	1.18703
3689.98	0.803787
3692.99	0.988866
3696	2.48373
3699.01	2.06059
3702.02	1.05306
3705.02	1.40303
3708.03	2.58723
3711.03	3.99309
3714.03	6.03643
3717.04	7.45507
3720.04	8.36495
3723.04	8.54901
3726.03	8.67766
3729.03	8.21859
3732.03	7.6898
3735.02	8.35897
3738.01	8.07595
3741	8.37989
3743.99	8.73664
3746.98	9.02725
3749.97	9.50693
3752.96	9.6462
3755.95	10.2324
3758.93	10.347
3761.91	10.0802
3764.9	9.7459
3767.88	10.0768
3770.86	10.4426
3773.84	10.2474
3776.81	11.0975
3779.79	12.1458
3782.77	12.1627
3785.74	12.5726
3788.71	13.2109
3791.68	13.6958
3794.65	14.504
3797.62	14.6804
3800.59	14.1008
3803.56	13.8717
3806.52	14.1618
3809.49	14.6732
3812.45	14.8604
3815.41	15.6059
3818.37	16.0496
3821.33	17
3824.29	18.518
3827.25	18.8592
3830.21	18.9198
3833.16	18.264
3836.11	16.7199
3839.07	15.4217
3842.02	14.6573
3844.97	13.6564
3847.92	14.1169
3850.87	15.3262
3853.81	16.7823
3856.76	18.6848
3859.7	19.6662
3862.65	19.1717
3865.59	19.0106
3868.53	18.5129
3871.47	18.3894
3874.41	19.3224
3877.34	19.8714
3880.28	20.069
3883.22	19.6878
3886.15	18.9001
3889.08	17.9822
3892.01	17.0494
3894.94	16.9286
3897.87	17.0254
3900.8	17.0648
3903.73	17.5844
3906.65	17.3693
3909.58	17.1744
3912.5	16.9243
3915.42	17.4168
3918.35	18.2328
3921.27	18.8457
3924.18	19.2515
3927.1	18.9466
3930.02	18.9167
3932.93	18.829
3935.85	18.3074
3938.76	17.9776
3941.67	17.7454
3944.58	17.1435
3947.49	16.5554
3950.4	16.2962
3953.31	15.4243
3956.22	14.7784
3959.12	13.4991
3962.02	12.1117
3964.93	11.7913
3967.83	11.2965
3970.73	11.1474
3973.63	11.8055
3976.53	12.3862
3979.42	12.5999
3982.32	12.7471
3985.21	11.766
3988.11	10.7715
3991	11.1674
3993.89	7.67953
3996.78	5.92499
3999.67	10.081