File: Data/3-Raman/maps/bu20-G-ff1-FI01_CLS_Carbonic phase_raw.txt
#Acq. time (s)=	1
#Accumulations=	1
#Range (cm-¹)=	100...4000
#Windows=	1
#Auto scanning=	Off
#Autofocus=	Off
#SWIFT=	On
#Macrospot=	Off
#AutoExposure=	Off
#Spike filter=	Off
#Delay time (s)=	0
#Binning=	1
#Readout mode=	Signal
#DeNoise=	Lite
#ICS correction=	Off
#Dark correction=	Off
#Inst. Process=	Off
#Detector temperature (°C)=	-60.09
#Instrument=	LabRAM HR Evol
#Detector=	SIN-EM FIVIS
#Objective=	x100_VIS
#Grating=	150 (500nm)
#ND Filter=	100%
#Laser=	532nm_Edge
#Hole=	30.0125
#Temperature=	0
#Range=	Visible
#StageXY=	75x50mm Scan+
#StageZ=	Z motor
#Z (µm)=	1887.6
#Full time(mm:ss)=	31:39
#Project=	Buranga
#Sample=	BU18FA20_G
#Site=	G_trl1
#Title=	20-G_trl1_MI01_topbb_1
#Remark=
#Date=	30.07.2019 16:51
#Cursor=	Rectangle 9 points
#Y (µm)=	-0.793193 ... 1.73091
#X (µm)=	-11.607 ... -9.60704
#Generated=	29.03.2022 09:29:34
103.656	1279.48
108.278	1044.34
112.899	866.902
117.517	722.377
122.131	599.227
126.744	496.602
131.355	411.994
135.964	341.597
140.571	282.658
145.173	235.426
149.776	198.534
154.375	169.317
158.973	147.687
163.566	130.859
168.159	115.94
172.75	100.305
177.339	84.4534
181.923	70.6678
186.507	58.1687
191.089	53.0085
195.668	52.0298
200.243	45.8524
204.818	39.0839
209.391	29.7625
213.96	20.4097
218.528	12.108
223.094	7.21609
227.655	5.32289
232.217	9.54953
236.776	18.4925
241.331	31.4837
245.886	44.8674
250.439	54.1838
254.987	53.9739
259.535	47.6187
264.081	36.2385
268.622	25.5831
273.164	20.179
277.703	38.1918
282.238	72.6869
286.773	106.115
291.305	111.612
295.833	92.8744
300.362	65.0756
304.885	43.4102
309.409	28.3882
313.93	19.854
318.448	16.4252
322.965	19.0899
327.477	27.2083
331.99	38.4917
336.5	49.1206
341.007	57.2053
345.513	62.6299
350.014	66.0472
354.516	67.7972
359.013	66.734
363.51	62.1473
368.005	54.8351
372.496	45.9695
376.987	39.5646
381.473	34.4137
385.96	31.225
390.442	28.545
394.923	26.619
399.401	25.6617
403.879	23.6539
408.352	20.7139
412.825	17.9863
417.294	16.8192
421.763	16.1223
426.227	15.6669
430.692	14.4455
435.152	13.0806
439.612	11.0734
444.068	9.14418
448.524	8.07212
452.976	7.60598
457.427	7.34494
461.874	7.28608
466.32	7.58366
470.765	7.45075
475.205	6.72246
479.646	7.36384
484.083	9.30443
488.519	12.9756
492.951	18.4715
497.381	25.2787
501.811	30.4618
506.237	33.58
510.663	32.442
515.084	27.9204
519.504	23.2155
523.923	18.3677
528.338	14.1883
532.753	10.7963
537.164	8.51518
541.572	7.02726
545.981	6.38787
550.385	6.43963
554.788	6.86673
559.19	7.34893
563.588	7.93713
567.986	8.5303
572.38	9.65604
576.771	10.8847
581.163	13.4916
585.551	18.0563
589.936	24.9811
594.319	31.4134
598.702	35.3722
603.081	35.7598
607.458	32.8958
611.835	28.4696
616.208	24.1181
620.578	20.4318
624.949	17.4469
629.315	15.7308
633.68	14.9455
638.042	14.1563
642.404	13.3724
646.762	12.6854
651.118	13.0798
655.472	14.7022
659.825	18.7333
664.175	25.5173
668.523	33.8146
672.868	41.4229
677.213	47.9476
681.555	51.1136
685.894	50.3123
690.231	45.4373
694.566	35.7091
698.901	26.4252
703.232	18.5745
707.561	12.2838
711.888	8.19179
716.212	5.58115
720.537	4.60548
724.858	4.7161
729.176	5.17643
733.493	5.86081
737.807	5.81796
742.119	6.02515
746.432	6.54393
750.74	6.15929
755.046	5.48977
759.35	5.45916
763.652	6.75486
767.952	10.9732
772.25	18.4161
776.546	27.5309
780.842	41.1107
785.133	51.6187
789.423	54.4
793.711	49.5509
797.997	39.1492
802.28	28.0121
806.562	19.1565
810.841	12.2276
815.119	8.42136
819.394	6.71299
823.668	6.84597
827.941	7.47412
832.211	7.59685
836.478	7.90243
840.743	7.79082
845.006	8.10708
849.268	7.33164
853.527	6.47969
857.784	5.94688
862.039	5.38821
866.293	4.39674
870.544	3.35817
874.793	2.17525
879.04	1.80547
883.285	2.67619
887.528	3.22714
891.769	4.005
896.008	4.30517
900.246	4.48862
904.481	4.7562
908.714	4.83391
912.945	4.66182
917.174	4.36461
921.401	3.79916
925.626	2.8346
929.849	2.31371
934.068	3.64414
938.287	6.42008
942.504	9.82666
946.72	14.1887
950.933	18.2376
955.144	20.9645
959.353	22.0291
963.56	21.0628
967.765	18.4106
971.968	15.3859
976.17	12.8668
980.367	10.871
984.564	9.85358
988.759	9.92661
992.953	9.42996
997.144	9.03878
1001.33	7.57042
1005.52	6.23609
1009.71	5.67567
1013.89	5.73711
1018.07	6.58648
1022.25	7.62288
1026.43	8.08083
1030.6	8.29518
1034.78	8.74258
1038.94	10.1732
1043.11	13.4571
1047.28	21.4189
1051.45	30.4967
1055.61	43.3204
1059.77	56.1585
1063.93	57.7074
1068.09	49.8546
1072.25	39.1017
1076.4	29.616
1080.55	25.7652
1084.7	25.8082
1088.85	31.6318
1092.99	39.3577
1097.14	47.6458
1101.28	54.3225
1105.42	58.3526
1109.56	61.1549
1113.69	63.6413
1117.83	66.2988
1121.96	67.6643
1126.09	68.3238
1130.22	68.2367
1134.35	68.0227
1138.47	67.4818
1142.59	64.6806
1146.71	60.3945
1150.83	55.7288
1154.95	51.6402
1159.06	49.147
1163.18	48.5241
1167.29	47.6461
1171.4	45.6775
1175.5	42.9158
1179.61	38.5101
1183.71	32.7993
1187.81	26.799
1191.91	21.1011
1196.01	17.6342
1200.1	15.2958
1204.2	14.2155
1208.29	14.2391
1212.38	15.9756
1216.47	19.4906
1220.55	23.9345
1224.64	28.4935
1228.72	32.2025
1232.8	36.4226
1236.88	40.075
1240.95	44.7627
1245.03	51.6429
1249.1	61.2164
1253.17	76.2581
1257.24	101.131
1261.31	128.529
1265.37	134.767
1269.44	134.593
1273.5	210.714
1277.56	699.125
1281.61	1034.73
1285.67	746.446
1289.72	232.082
1293.77	118.031
1297.83	86.9665
1301.87	69.5813
1305.92	60.392
1309.96	54.478
1314.01	51.5019
1318.05	50.1299
1322.09	49.352
1326.12	48.8071
1330.16	48.37
1334.19	47.6253
1338.22	46.9922
1342.25	46.1835
1346.28	46.4751
1350.3	48.7794
1354.33	53.9972
1358.35	63.7587
1362.37	77.331
1366.39	106.651
1370.4	130.263
1374.42	146.437
1378.43	399.485
1382.44	1342.23
1386.45	1766.72
1390.46	1072.1
1394.46	277.603
1398.46	178.081
1402.47	174.216
1406.46	179.728
1410.46	147.318
1414.46	97.5798
1418.45	72.0007
1422.45	55.4116
1426.43	42.697
1430.42	35.0603
1434.41	29.0906
1438.39	25.1349
1442.38	22.2975
1446.36	19.6961
1450.34	17.4809
1454.31	15.0934
1458.29	13.9005
1462.27	13.0932
1466.24	11.9579
1470.21	11.0085
1474.18	10.3119
1478.14	9.26682
1482.11	8.4114
1486.07	8.07525
1490.03	8.35043
1493.99	8.67068
1497.95	9.51524
1501.9	10.3077
1505.86	10.4759
1509.81	10.2713
1513.76	9.92414
1517.71	9.1155
1521.65	8.31099
1525.6	8.22291
1529.54	7.61855
1533.48	7.1332
1537.42	7.03211
1541.36	7.54917
1545.29	8.13887
1549.23	8.44204
1553.16	8.13078
1557.09	7.93074
1561.02	7.20412
1564.94	5.93489
1568.87	5.10604
1572.79	4.64363
1576.71	5.36709
1580.63	6.32292
1584.55	7.41487
1588.47	8.50828
1592.38	8.70069
1596.29	9.2264
1600.2	8.54476
1604.11	7.62473
1608.02	7.62055
1611.92	7.9192
1615.83	7.95728
1619.73	7.8276
1623.63	7.17225
1627.53	6.30959
1631.42	5.61605
1635.32	5.53588
1639.21	6.03919
1643.1	6.90167
1646.99	8.56326
1650.88	9.09495
1654.76	8.74409
1658.64	8.21565
1662.53	8.31967
1666.41	9.21496
1670.28	9.46777
1674.16	9.78203
1678.04	9.06145
1681.91	8.09334
1685.78	8.0405
1689.65	7.98576
1693.52	8.22324
1697.38	8.59051
1701.25	8.67743
1705.11	8.4839
1708.97	8.27259
1712.83	7.62582
1716.69	6.99861
1720.54	6.44919
1724.4	5.55399
1728.25	4.563
1732.1	3.54401
1735.95	2.74162
1739.79	2.479
1743.64	3.20525
1747.48	4.35912
1751.33	5.70042
1755.17	7.22358
1759	8.70732
1762.84	9.48358
1766.68	10.5637
1770.51	10.9118
1774.34	10.4649
1778.17	9.60633
1782	8.49786
1785.82	7.67631
1789.65	7.27701
1793.47	7.08937
1797.29	7.0171
1801.11	7.27789
1804.93	7.73311
1808.74	8.31983
1812.56	9.01101
1816.37	9.37862
1820.18	8.95842
1823.99	8.09086
1827.79	6.79162
1831.6	5.69825
1835.4	5.43017
1839.2	5.62693
1843	6.82469
1846.8	8.69607
1850.6	10.306
1854.39	10.861
1858.19	10.9005
1861.98	9.40803
1865.77	8.33989
1869.56	7.69079
1873.34	6.93954
1877.13	7.24755
1880.91	8.00611
1884.69	8.78496
1888.47	9.63752
1892.25	10.2258
1896.03	10.2494
1899.8	9.97413
1903.57	9.28258
1907.34	8.42295
1911.11	7.7502
1914.88	7.49797
1918.65	7.58942
1922.41	6.92914
1926.18	6.99028
1929.94	6.99977
1933.7	6.59291
1937.45	6.63142
1941.21	6.72923
1944.96	6.81792
1948.72	6.75967
1952.47	5.90641
1956.22	5.73406
1959.96	5.58577
1963.71	5.89839
1967.45	7.2927
1971.2	8.81269
1974.94	9.15936
1978.68	9.40475
1982.42	9.65299
1986.15	9.31791
1989.89	9.18677
1993.62	9.11315
1997.35	8.66252
2001.08	8.3099
2004.8	8.10521
2008.53	8.52919
2012.25	8.88337
2015.98	9.0068
2019.7	8.60897
2023.42	8.68602
2027.13	9.22867
2030.85	9.77769
2034.56	10.2111
2038.28	10.681
2041.99	10.4824
2045.7	9.77436
2049.41	9.64598
2053.11	9.00381
2056.82	8.804
2060.52	8.96989
2064.22	8.85677
2067.92	8.87117
2071.62	8.51741
2075.31	7.86041
2079.01	7.23716
2082.7	7.14538
2086.39	7.30063
2090.08	8.07196
2093.77	8.53348
2097.45	8.08738
2101.14	7.84799
2104.82	7.37542
2108.5	6.67696
2112.18	6.01322
2115.86	5.73439
2119.54	6.18143
2123.21	6.90187
2126.88	8.20628
2130.56	9.49417
2134.23	9.77634
2137.89	9.50562
2141.56	8.86843
2145.23	7.42401
2148.89	6.37178
2152.55	5.88871
2156.21	5.69193
2159.87	6.47538
2163.53	7.47093
2167.18	8.26754
2170.84	8.63194
2174.49	9.00657
2178.14	9.30737
2181.79	9.50522
2185.44	9.52671
2189.08	9.28787
2192.73	9.61518
2196.37	9.7769
2200.01	9.56296
2203.65	8.82243
2207.29	8.2529
2210.92	8.21541
2214.56	8.60732
2218.19	9.12756
2221.82	9.29123
2225.45	9.31891
2229.08	9.42323
2232.7	9.78295
2236.33	10.2781
2239.95	10.7786
2243.57	10.9178
2247.19	11.1489
2250.81	11.1841
2254.43	11.4593
2258.04	11.8479
2261.66	12.1952
2265.27	12.5121
2268.88	13.4934
2272.49	13.7294
2276.1	13.2164
2279.7	11.8065
2283.31	10.2601
2286.91	9.30557
2290.51	8.71724
2294.11	8.37423
2297.71	7.74994
2301.3	7.52931
2304.9	8.14088
2308.49	9.74256
2312.08	13.8148
2315.67	19.6362
2319.26	25.6595
2322.85	36.6716
2326.43	40.7329
2330.02	33.9252
2333.6	24.7432
2337.18	16.7742
2340.76	11.235
2344.34	9.38519
2347.91	8.4852
2351.49	8.75279
2355.06	9.06611
2358.63	9.40032
2362.2	9.66643
2365.77	10.1429
2369.33	9.8266
2372.9	9.44754
2376.46	9.60586
2380.02	9.41499
2383.58	8.87811
2387.14	8.71405
2390.7	9.14308
2394.25	9.15485
2397.81	9.49505
2401.36	9.80999
2404.91	9.30894
2408.46	9.06119
2412.01	8.83866
2415.56	7.90177
2419.1	7.43335
2422.64	7.09104
2426.18	6.79327
2429.72	6.81421
2433.26	6.9052
2436.8	7.11171
2440.34	7.46731
2443.87	8.20802
2447.4	8.84463
2450.93	8.94378
2454.46	8.51285
2457.99	7.62346
2461.52	6.83015
2465.04	6.01637
2468.56	5.17872
2472.09	5.2458
2475.61	6.28548
2479.13	7.69019
2482.64	9.01773
2486.16	10.2542
2489.67	10.8566
2493.18	10.8381
2496.69	10.2387
2500.2	9.49781
2503.71	8.84196
2507.22	8.32077
2510.72	7.66466
2514.23	7.51394
2517.73	7.59329
2521.23	7.94655
2524.73	8.51814
2528.23	9.06295
2531.72	9.19542
2535.21	9.13409
2538.71	9.43747
2542.2	9.25184
2545.69	8.76709
2549.18	8.76604
2552.66	8.54023
2556.15	8.17118
2559.63	7.75547
2563.12	8.43251
2566.6	8.78944
2570.08	9.19376
2573.55	9.52558
2577.03	10.2504
2580.5	11.0494
2583.98	11.456
2587.45	11.6971
2590.92	11.408
2594.39	10.2401
2597.86	9.23719
2601.32	8.58466
2604.79	8.23731
2608.25	8.18412
2611.71	7.94343
2615.17	7.57772
2618.63	7.98061
2622.08	8.44259
2625.54	8.83708
2628.99	9.26404
2632.45	9.26811
2635.9	8.83741
2639.35	8.70607
2642.79	8.056
2646.24	7.02015
2649.69	6.43834
2653.13	5.77824
2656.57	5.59534
2660.01	6.94577
2663.45	8.03826
2666.89	9.13282
2670.32	9.80508
2673.76	10.0543
2677.19	9.60949
2680.62	9.11134
2684.05	8.63629
2687.48	8.18989
2690.91	8.64101
2694.33	8.96951
2697.76	8.89524
2701.18	8.34577
2704.6	7.27683
2708.02	6.6959
2711.44	6.46569
2714.86	6.62842
2718.27	6.8811
2721.69	7.54623
2725.1	7.32778
2728.51	7.04883
2731.92	6.76423
2735.33	5.6098
2738.74	4.29707
2742.14	4.05097
2745.55	3.95138
2748.95	4.70445
2752.35	5.99352
2755.75	6.06978
2759.15	6.08642
2762.54	5.76276
2765.94	5.21953
2769.33	4.69822
2772.72	4.45363
2776.12	4.99049
2779.51	5.26212
2782.89	5.42518
2786.28	5.4112
2789.67	5.79121
2793.05	5.95954
2796.43	6.14307
2799.81	5.76611
2803.19	5.79178
2806.57	5.55321
2809.95	5.25775
2813.32	5.26978
2816.69	5.69662
2820.06	6.44139
2823.44	7.49743
2826.81	8.13991
2830.17	8.54957
2833.54	8.55597
2836.9	8.06573
2840.27	7.90415
2843.63	7.71947
2846.99	7.31395
2850.35	6.86965
2853.71	6.14752
2857.06	5.88504
2860.42	5.88117
2863.77	6.1571
2867.12	6.39557
2870.48	6.64546
2873.83	6.89107
2877.17	6.75344
2880.52	7.03771
2883.86	7.08677
2887.21	7.03515
2890.55	6.96794
2893.89	7.11965
2897.23	7.29695
2900.57	7.17133
2903.91	7.4331
2907.24	7.43407
2910.57	8.1694
2913.91	8.98962
2917.24	9.41191
2920.57	9.46701
2923.9	9.13477
2927.22	8.61987
2930.55	7.9663
2933.87	7.33277
2937.19	6.8597
2940.51	6.59301
2943.83	6.65308
2947.15	7.37024
2950.47	6.48052
2953.79	5.58937
2957.1	5.88354
2960.41	6.31815
2963.72	7.27043
2967.03	8.43742
2970.34	8.7498
2973.65	8.95979
2976.95	8.62411
2980.26	8.05398
2983.56	7.1633
2986.86	6.47578
2990.16	6.20866
2993.46	6.71422
2996.76	7.16119
3000.06	7.30494
3003.35	7.56823
3006.64	7.46851
3009.94	7.22378
3013.23	6.65208
3016.51	5.96694
3019.8	5.42633
3023.09	4.88334
3026.38	4.22883
3029.66	3.69371
3032.94	4.21863
3036.22	5.26627
3039.5	6.58328
3042.78	8.44175
3046.05	7.62815
3049.33	5.98904
3052.6	4.57137
3055.88	3.58806
3059.15	3.74879
3062.42	5.01075
3065.69	5.72421
3068.95	6.58357
3072.22	7.4661
3075.48	7.49195
3078.75	7.25531
3082.01	7.38448
3085.27	7.68375
3088.53	8.75578
3091.79	9.11935
3095.04	8.57656
3098.3	7.69828
3101.55	6.78595
3104.8	5.93885
3108.05	5.55483
3111.3	5.20085
3114.55	4.84391
3117.8	4.8178
3121.04	5.51877
3124.29	6.81933
3127.53	8.53283
3130.77	9.13412
3134.01	9.17179
3137.25	8.36111
3140.49	6.50714
3143.72	4.56717
3146.96	2.68818
3150.19	2.3792
3153.42	3.06131
3156.65	4.30734
3159.88	5.99524
3163.11	7.23357
3166.34	7.87669
3169.56	7.97313
3172.79	7.85274
3176.01	7.66232
3179.23	7.70883
3182.45	8.14994
3185.67	6.8111
3188.88	4.97428
3192.1	4.37884
3195.31	3.96159
3198.53	4.48534
3201.74	5.01321
3204.95	5.23596
3208.16	5.69024
3211.37	5.70451
3214.57	5.54509
3217.78	5.31767
3220.98	5.24235
3224.18	5.31787
3227.39	4.83464
3230.59	4.25529
3233.78	3.91093
3236.98	3.60591
3240.18	3.78272
3243.37	3.99047
3246.56	4.56052
3249.76	4.98691
3252.95	5.10591
3256.14	5.60234
3259.32	6.04203
3262.51	6.3506
3265.7	6.41577
3268.88	5.86175
3272.06	5.22174
3275.24	4.73604
3278.42	4.18346
3281.6	4.71814
3284.78	5.81501
3287.96	6.39265
3291.13	6.65848
3294.31	6.47811
3297.48	5.35327
3300.65	4.05814
3303.82	3.05981
3306.99	2.89781
3310.15	3.54609
3313.32	4.44942
3316.48	5.24127
3319.65	5.64043
3322.81	5.83461
3325.97	5.1569
3329.13	4.28111
3332.28	3.51948
3335.44	3.07019
3338.6	3.38773
3341.75	4.45915
3344.9	5.39916
3348.05	6.09852
3351.2	6.28885
3354.35	6.09127
3357.5	5.76779
3360.65	5.46192
3363.79	5.14421
3366.94	5.37992
3370.08	6.25862
3373.22	6.53573
3376.36	7.32094
3379.5	7.88045
3382.63	8.28162
3385.77	8.6815
3388.9	9.0196
3392.04	9.52464
3395.17	8.75919
3398.3	7.89124
3401.43	6.95097
3404.56	7.15372
3407.69	11.0429
3410.81	16.2853
3413.94	25.9577
3417.06	44.3888
3420.18	71.4442
3423.3	126.351
3426.42	239.298
3429.54	278.648
3432.65	200.428
3435.77	124.321
3438.88	73.3147
3442	40.5768
3445.11	23.3332
3448.22	13.9998
3451.33	9.6636
3454.43	8.48894
3457.54	8.04986
3460.65	8.44773
3463.75	9.29323
3466.85	10.0395
3469.95	11.0126
3473.05	13.1232
3476.15	15.607
3479.25	18.2166
3482.35	21.2831
3485.44	24.8876
3488.54	28.0097
3491.63	42.5298
3494.72	59.9889
3497.81	86.6762
3500.9	119.501
3503.99	150.071
3507.07	178.433
3510.16	197.046
3513.24	191.152
3516.32	171.159
3519.41	141.153
3522.49	105.983
3525.56	76.3301
3528.64	51.5791
3531.72	37.8878
3534.79	28.0704
3537.87	22.0015
3540.94	18.9831
3544.01	17.9377
3547.08	16.3611
3550.15	15.1322
3553.22	14.4625
3556.28	13.587
3559.35	12.4759
3562.41	10.8068
3565.47	8.24928
3568.54	6.66971
3571.6	5.70711
3574.65	5.61943
3577.71	6.7972
3580.77	8.71365
3583.82	10.5053
3586.88	11.8016
3589.93	11.5206
3592.98	9.66966
3596.03	7.27387
3599.08	5.58728
3602.13	4.37064
3605.18	4.20358
3608.22	5.20424
3611.27	5.99301
3614.31	6.75778
3617.35	7.2269
3620.39	7.14786
3623.43	6.98292
3626.47	6.68161
3629.5	6.6683
3632.54	6.90091
3635.57	8.12211
3638.61	8.58664
3641.64	8.54124
3644.67	7.64853
3647.7	6.29402
3650.73	5.24369
3653.75	5.20631
3656.78	5.62855
3659.8	6.83769
3662.83	7.61322
3665.85	8.35084
3668.87	8.54728
3671.89	8.3658
3674.91	7.61818
3677.92	6.17334
3680.94	4.88892
3683.96	4.09459
3686.97	3.80464
3689.98	3.99844
3692.99	4.65017
3696	5.64518
3699.01	6.68534
3702.02	7.71988
3705.02	8.41002
3708.03	8.36135
3711.03	8.29502
3714.03	7.47599
3717.04	7.36619
3720.04	7.69374
3723.04	7.46208
3726.03	7.22499
3729.03	6.96504
3732.03	6.28032
3735.02	5.30626
3738.01	4.51067
3741	3.98744
3743.99	4.11255
3746.98	4.51863
3749.97	4.94013
3752.96	5.13685
3755.95	5.33827
3758.93	5.7549
3761.91	6.20606
3764.9	7.39547
3767.88	8.19164
3770.86	8.30774
3773.84	8.25156
3776.81	7.92746
3779.79	7.45504
3782.77	6.70617
3785.74	6.0981
3788.71	5.58418
3791.68	5.64511
3794.65	5.85166
3797.62	6.2079
3800.59	6.89692
3803.56	7.84525
3806.52	7.53696
3809.49	7.73345
3812.45	7.59441
3815.41	7.27999
3818.37	7.3746
3821.33	6.98573
3824.29	6.82024
3827.25	7.20252
3830.21	7.50509
3833.16	7.66196
3836.11	7.31479
3839.07	7.0084
3842.02	6.55683
3844.97	6.41035
3847.92	6.16467
3850.87	6.04026
3853.81	6.04573
3856.76	6.22626
3859.7	6.4218
3862.65	7.39154
3865.59	8.22125
3868.53	9.14829
3871.47	9.79313
3874.41	9.52201
3877.34	9.15876
3880.28	8.93866
3883.22	8.36922
3886.15	8.32712
3889.08	8.69643
3892.01	9.27823
3894.94	9.62348
3897.87	9.27719
3900.8	8.79363
3903.73	8.16718
3906.65	7.67219
3909.58	7.51523
3912.5	8.17043
3915.42	8.77183
3918.35	10.2817
3921.27	10.8709
3924.18	11.2442
3927.1	10.8878
3930.02	9.91745
3932.93	8.98833
3935.85	8.33154
3938.76	7.9355
3941.67	8.52201
3944.58	9.06943
3947.49	9.95209
3950.4	11.3927
3953.31	11.8933
3956.22	11.4323
3959.12	10.8266
3962.02	10.4674
3964.93	10.7373
3967.83	11.8021
3970.73	12.6621
3973.63	13.029
3976.53	13.0502
3979.42	12.6986
3982.32	11.6501
3985.21	10.442
3988.11	8.97347
3991	8.22174
3993.89	8.63028
3996.78	13.887
3999.67	10.4875