File: Data/3-Raman/maps/BU20b-area2-blue_150 (500nm)_633nm_Edge_100%_x50_VIS_LWD_H100um_15sX2.txt
#Acq. time (s)=	15
#Accumulations=	2
#Range (cm-¹)=	100...4000
#Windows=	1
#Auto scanning=	Off
#Autofocus=	Off
#Macrospot=	Off
#AutoExposure=	Off
#Spike filter=	Single accum. (Size=4)
#Delay time (s)=	0
#Binning=	1
#Readout mode=	Signal
#DeNoise=	Standard
#ICS correction=	On
#Dark correction=	Off
#Inst. Process=	On
#Detector Gain=	Best Dynamic
#Detector ADC=	50 kHz HS
#Detector temperature (°C)=	-60.09
#Instrument=	LabRAM HR Evol
#Detector=	SIN-EM FIVIS
#Objective=	x50_VIS_LWD
#Grating=	150 (500nm)
#ND Filter=	100%
#Laser=	633nm_Edge
#Hole=	100.021
#Temperature=	0
#Range=	Visible
#StageXY=	75x50mm Scan+
#StageZ=	Z motor
#X (µm)=	0
#Y (µm)=	0
#Z (µm)=	62.4
#Project=	20_05_11
#Sample=	BU20b
#Site=
#Title=	BU20b-area2-blue_150 (500nm)_633nm_Edge_100%_x50_VIS_LWD_H100um_15sX2
#Remark=
#Date=	11.05.2020 19:02
#Acquired=	11.05.2020 19:02:26
#Data Range:Extract=	06.04.2022 14:33:06
#Base:Fit=	06.04.2022 14:33:15
#Base:Edit=	06.04.2022 14:34:11
#Base:Edit=	06.04.2022 14:34:14
#Base:Edit=	06.04.2022 14:34:14
#Base:Edit=	06.04.2022 14:34:15
#Base:Sub=	06.04.2022 14:34:18
#Correction:Shift=	06.04.2022 14:44:50
104.122	-9.28052
110.635	54.8478
117.143	121.5
123.646	250.56
130.143	1108.76
136.634	693.493
143.121	287.88
149.602	257.77
156.077	388.878
162.546	305.496
169.011	533.294
175.471	870.1
181.925	624.099
188.374	321.563
194.818	31.9612
201.254	-74.9502
207.687	-48.1586
214.115	39.4825
220.537	76.4868
226.953	43.036
233.365	12.3907
239.771	-7.78821
246.171	31.9774
252.567	7.85583
258.958	158.872
265.342	643.165
271.722	244.032
278.096	67.1577
284.466	58.3235
290.829	78.7249
297.188	89.0056
303.541	80.6121
309.89	65.9797
316.232	181.717
322.57	294.172
328.902	187.58
335.229	246.298
341.552	277.085
347.868	343.363
354.179	435.973
360.487	601.669
366.788	360.842
373.084	533.291
379.376	531.111
385.661	368.027
391.942	436.879
398.217	506.468
404.487	537.731
410.752	420.088
417.013	130.319
423.268	31.2515
429.518	65.5735
435.763	141.27
442.002	277.142
448.237	275.288
454.466	169.211
460.691	230.237
466.91	483.518
473.125	444.497
479.334	384.293
485.538	496.037
491.737	576.146
497.93	498.021
504.12	435.74
510.304	470.494
516.483	613.184
522.657	857.483
528.825	1021.89
534.989	619.406
541.149	381.193
547.303	323.065
553.451	276.548
559.595	195.998
565.735	126.963
571.868	78.376
577.998	67.995
584.121	97.8
590.241	205.383
596.354	311.265
602.464	460.351
608.568	798.839
614.668	834.466
620.761	587.804
626.852	451.709
632.936	296.203
639.016	275.256
645.091	406.618
651.16	372.841
657.226	175.292
663.286	91.7528
669.34	71.2164
675.392	69.7628
681.437	60.3905
687.477	42.9402
693.513	44.0593
699.543	48.3112
705.571	43.0083
711.592	25.3544
717.608	10.2148
723.62	-1.68469
729.626	-10.2006
735.628	-14.8468
741.625	-15.8621
747.618	-13.7095
753.605	-9.073
759.588	-3.23242
765.566	3.43433
771.539	11.9229
777.508	22.1625
783.472	36.1665
789.431	52.9711
795.385	71.1328
801.333	88.906
807.278	100.238
813.219	102.538
819.154	94.9302
825.085	77.1453
831.01	64.955
836.931	56.064
842.848	53.1565
848.759	53.0289
854.666	55.5475
860.569	60.939
866.465	70.1855
872.359	84.4061
878.246	99.3467
884.13	129.388
890.009	146.783
895.883	145.394
901.752	118.967
907.618	83.2905
913.478	54.2417
919.334	50.502
925.184	55.4877
931.03	63.7515
936.873	76.4543
942.709	97.0356
948.542	126.326
954.37	161.806
960.193	206.291
966.012	257.988
971.825	309.537
977.636	377.085
983.441	605.957
989.241	883.135
995.036	852.557
1000.83	673.17
1006.61	665.063
1012.4	790.613
1018.17	1178.75
1023.95	2067.86
1029.71	2393.21
1035.48	1684.93
1041.24	1465.34
1046.99	2132.84
1052.74	2299.04
1058.49	1176.62
1064.23	767.654
1069.97	816.46
1075.7	687.35
1081.43	454.193
1087.15	371.613
1092.87	371.244
1098.58	439.045
1104.29	533.182
1110	530.495
1115.7	423.279
1121.4	285.129
1127.09	198.856
1132.78	156.314
1138.46	141.861
1144.14	140.722
1149.81	140.891
1155.49	133.036
1161.15	137.408
1166.81	147.117
1172.47	160.878
1178.12	178.214
1183.77	187.701
1189.41	180.827
1195.05	150.71
1200.69	152.437
1206.32	177.714
1211.94	194.031
1217.56	196.551
1223.18	174.212
1228.79	156.755
1234.4	136.475
1240.01	111.699
1245.61	86.749
1251.2	64.0378
1256.79	46.1182
1262.38	34.4938
1267.96	27.2391
1273.54	21.9911
1279.12	17.1572
1284.69	12.8608
1290.25	8.07935
1295.81	4.13452
1301.37	2.3689
1306.92	2.9469
1312.47	6.17322
1318.01	11.8245
1323.55	16.7465
1329.09	19.8026
1334.62	20.3184
1340.15	19.6238
1345.67	17.9961
1351.19	16.0192
1356.7	14.1196
1362.21	12.8507
1367.72	10.5452
1373.22	8.05078
1378.72	7.32288
1384.21	6.56262
1389.7	6.50305
1395.18	7.91858
1400.66	11.0962
1406.14	15.0001
1411.61	18.2588
1417.08	20.4984
1422.54	21.5437
1428	21.3146
1433.46	20.5499
1438.91	19.4294
1444.36	18.1329
1449.8	16.757
1455.24	15.6605
1460.67	14.5441
1466.1	13.3831
1471.53	12.5463
1476.95	12.0294
1482.37	12.0254
1487.78	13.4663
1493.19	15.3369
1498.6	15.7085
1504	14.6244
1509.4	12.4508
1514.79	10.0303
1520.18	6.61426
1525.56	0.291992
1530.95	4.14429
1536.32	9.64856
1541.7	12.1442
1547.06	13.0535
1552.43	13.5219
1557.79	13.214
1563.15	12.1195
1568.5	10.674
1573.85	10.2175
1579.19	10.0093
1584.53	10.6953
1589.87	12.4106
1595.2	15.2935
1600.53	19.1469
1605.85	21.8397
1611.17	21.9403
1616.49	20.8137
1621.8	18.7726
1627.11	16.8005
1632.41	15.14
1637.71	13.0225
1643.01	10.7214
1648.3	9.32678
1653.59	8.65588
1658.87	7.33618
1664.16	5.09509
1669.43	2.00928
1674.7	-1.00134
1679.97	-2.91321
1685.24	-1.72156
1690.5	0.490845
1695.75	4.34692
1701.01	8.19324
1706.25	9.36951
1711.5	8.25366
1716.74	6.19287
1721.98	4.82874
1727.21	6.21619
1732.44	9.09912
1737.66	13.1523
1742.89	16.5438
1748.1	18.9049
1753.31	17.9392
1758.52	12.9875
1763.73	3.86877
1768.93	-6.39941
1774.13	-13.0341
1779.32	-16.5613
1784.51	-16.6589
1789.7	-15.3458
1794.88	-14.7615
1800.06	-14.1213
1805.23	-12.9717
1810.41	-11.0647
1815.57	-7.74585
1820.74	-2.37756
1825.9	0.756226
1831.05	-1.49011
1836.2	-4.22559
1841.35	-5.94788
1846.49	-1.40222
1851.63	2.81519
1856.77	5.04419
1861.9	5.44861
1867.03	4.13208
1872.16	0.428101
1877.28	-3.82532
1882.39	-7.8501
1887.51	-10.8517
1892.62	-11.8496
1897.72	-11.3589
1902.82	-8.61548
1907.92	-4.77979
1913.02	-0.93103
1918.11	2.28235
1923.2	4.65637
1928.28	5.36865
1933.36	4.40271
1938.43	4.21375
1943.51	3.60632
1948.57	1.73315
1953.64	-0.277588
1958.7	-1.37158
1963.76	-2.37756
1968.81	-3.72632
1973.86	-4.68884
1978.91	-6.56958
1983.95	-8.66699
1988.99	-8.67163
1994.02	-7.2356
1999.05	-4.21265
2004.08	-0.521851
2009.1	2.3125
2014.12	3.39148
2019.14	2.46741
2024.15	-0.662598
2029.16	-8.35779
2034.17	-9.63745
2039.17	-7.2312
2044.17	-3.08728
2049.16	0.697632
2054.15	2.18396
2059.14	3.42102
2064.12	4.18982
2069.1	3.84851
2074.08	3.12634
2079.05	2.88782
2084.02	4.6051
2088.98	4.79138
2093.94	9.86401
2098.9	14.1412
2103.86	14.8251
2108.81	14.9199
2113.76	15.1688
2118.7	15.5796
2123.64	16.2382
2128.57	16.0826
2133.51	14.991
2138.44	14.3226
2143.36	14.7642
2148.28	15.5002
2153.2	15.4386
2158.12	14.1511
2163.03	13.5903
2167.94	13.9612
2172.84	14.1106
2177.74	13.1726
2182.64	11.4985
2187.53	9.73584
2192.42	8.15454
2197.31	6.78503
2202.19	5.01843
2207.07	3.58716
2211.95	3.99792
2216.82	6.05664
2221.69	8.75208
2226.55	11.2137
2231.41	12.2526
2236.27	12.5729
2241.13	12.272
2245.98	10.7719
2250.83	10.7048
2255.67	10.4385
2260.51	7.63416
2265.35	0.838745
2270.18	-0.786865
2275.01	2.88928
2279.84	4.38391
2284.66	5.46069
2289.48	6.91016
2294.3	8.27185
2299.11	9.42944
2303.92	10.2731
2308.73	11.4474
2313.53	13.535
2318.33	18.067
2323.12	23.1107
2327.92	26.6968
2332.7	28.4557
2337.49	27.8842
2342.27	24.4055
2347.05	20.4351
2351.83	16.6678
2356.6	14.0039
2361.36	12.36
2366.13	11.6113
2370.89	11.2765
2375.65	10.8749
2380.4	9.67761
2385.15	7.27527
2389.9	5.09912
2394.65	3.0105
2399.39	1.52795
2404.12	1.11072
2408.86	1.65979
2413.59	1.05237
2418.32	-1.66724
2423.04	-2.38245
2427.76	-1.65808
2432.48	-0.784668
2437.19	0.0955811
2441.9	0.846802
2446.61	1.7417
2451.32	3.29993
2456.02	4.90234
2460.71	4.62646
2465.41	3.17249
2470.1	2.99988
2474.79	3.34058
2479.47	4.29651
2484.15	5.6792
2488.83	7.2655
2493.5	9.57666
2498.17	10.624
2502.84	10.3402
2507.5	9.10352
2512.17	7.27356
2516.82	3.38501
2521.48	-1.88049
2526.13	-8.85583
2530.78	-12.9587
2535.42	-11.0776
2540.06	-7.86035
2544.7	-4.31897
2549.33	-0.651611
2553.97	1.83496
2558.59	3.46326
2563.22	-5.36462
2567.84	-9.72705
2572.46	-10.4707
2577.07	-6.47339
2581.68	-1.37646
2586.29	-0.623657
2590.9	0.209229
2595.5	2.75269
2600.1	4.14758
2604.69	3.93909
2609.29	2.854
2613.88	1.18372
2618.46	-1.37134
2623.04	-1.63855
2627.62	0.268311
2632.2	3.53394
2636.77	6.43433
2641.34	4.31042
2645.91	-6.07739
2650.47	-12.6041
2655.03	-5.75854
2659.59	-1.81067
2664.14	-4.2041
2668.69	-5.0177
2673.24	-1.7511
2677.79	1.99084
2682.33	5.10071
2686.87	6.97351
2691.4	5.86023
2695.93	6.19458
2700.46	6.33862
2704.99	2.39148
2709.51	0.419189
2714.03	-1.57336
2718.54	-4.96289
2723.05	-8.52014
2727.56	-11.3308
2732.07	-13.553
2736.57	-15.1046
2741.07	-16.4729
2745.57	-18.2297
2750.07	-19.3031
2754.56	-19.5979
2759.04	-18.365
2763.53	-13.7874
2768.01	-7.40576
2772.49	-2.20032
2776.96	1.55591
2781.44	5.0708
2785.9	8.48694
2790.37	10.4867
2794.83	9.72668
2799.29	8.33557
2803.75	7.00525
2808.2	5.21558
2812.65	1.79968
2817.1	-4.91577
2821.54	-9.93201
2825.99	-12.2875
2830.42	-11.8464
2834.86	-9.31213
2839.29	-7.77734
2843.72	-6.95288
2848.15	-6.77954
2852.57	-7.11938
2856.99	-8.33997
2861.41	-9.31104
2865.82	-6.31848
2870.23	-1.22485
2874.64	3.89868
2879.04	8.38586
2883.44	12.2222
2887.84	15.2787
2892.24	17.5936
2896.63	20.6982
2901.02	21.0565
2905.41	19.2659
2909.79	17.5106
2914.17	15.2849
2918.55	13.1826
2922.92	12.5778
2927.29	14.63
2931.66	18.7292
2936.03	24.1295
2940.39	29.0284
2944.75	31.0996
2949.11	32.2238
2953.46	32.9763
2957.81	34.8596
2962.16	38.2412
2966.5	41.8291
2970.84	44.1027
2975.18	44.553
2979.52	43.8676
2983.85	43.9027
2988.18	45.7023
2992.51	48.3096
2996.83	51.2806
3001.15	55.3157
3005.47	59.2897
3009.78	62.9567
3014.1	67.1123
3018.41	71.4767
3022.71	75.5295
3027.02	79.5299
3031.32	83.1512
3035.61	86.9221
3039.91	92.689
3044.2	103.774
3048.49	115.231
3052.77	125.055
3057.06	133.545
3061.34	140.5
3065.61	145.813
3069.89	149.807
3074.16	152.245
3078.43	147.171
3082.69	124.728
3086.96	125.579
3091.22	130.803
3095.47	137.996
3099.73	144.668
3103.98	147.263
3108.23	147.41
3112.47	144.329
3116.71	138.494
3120.95	131.635
3125.19	126.75
3129.42	127.214
3133.65	130.964
3137.88	136.717
3142.11	144.027
3146.33	150.214
3150.55	151.706
3154.77	146.391
3158.98	140.416
3163.19	138.395
3167.4	137.28
3171.6	138.715
3175.81	142.606
3180.01	150.48
3184.2	161.204
3188.4	171.396
3192.59	182.686
3196.78	197.807
3200.96	214.078
3205.15	233.914
3209.33	261.088
3213.5	320.432
3217.68	398.015
3221.85	523.541
3226.02	706.557
3230.18	959.194
3234.35	1216.92
3238.51	1450.09
3242.66	1622.61
3246.82	1698.49
3250.97	1701.69
3255.12	1617.74
3259.27	1466.74
3263.41	1267.59
3267.55	1021.48
3271.69	824.3
3275.83	713.636
3279.96	653.133
3284.09	653.306
3288.22	678.727
3292.34	623.057
3296.46	511.118
3300.58	352.93
3304.7	254.484
3308.81	199.705
3312.92	165.705
3317.03	147.155
3321.14	135.364
3325.24	125.617
3329.34	118.538
3333.44	107.495
3337.53	96.1981
3341.62	86.8574
3345.71	80.9
3349.8	82.3519
3353.88	85.1416
3357.96	84.8448
3362.04	82.6042
3366.11	78.2639
3370.19	73.8274
3374.26	70.2111
3378.32	67.6753
3382.39	65.7485
3386.45	64.5887
3390.51	64.0081
3394.57	61.6564
3398.62	56.1992
3402.67	49.9025
3406.72	44.6382
3410.77	40.3301
3414.81	36.4868
3418.85	32.8308
3422.89	27.5851
3426.92	20.7147
3430.96	13.6357
3434.98	5.5813
3439.01	-0.111328
3443.04	2.33667
3447.06	10.0754
3451.08	17.6327
3455.09	19.0735
3459.11	17.1486
3463.12	13.4069
3467.13	10.4657
3471.13	8.57666
3475.14	7.33008
3479.14	7.2356
3483.14	9.15063
3487.13	10.6057
3491.13	12.3252
3495.12	13.5764
3499.1	12.8491
3503.09	10.3108
3507.07	6.82202
3511.05	2.92651
3515.03	-0.750244
3519	-4.71167
3522.98	-8.59595
3526.95	-9.60547
3530.91	-7.64258
3534.88	-5.73169
3538.84	-5.37085
3542.8	-6.69702
3546.75	-8.1582
3550.71	-9.30005
3554.66	-11.2124
3558.61	-11.2039
3562.55	-7.16919
3566.5	-2.93774
3570.44	-2.94946
3574.38	6.72314
3578.31	17.9956
3582.25	25.3538
3586.18	24.833
3590.1	13.9978
3594.03	16.574
3597.95	32.6587
3601.87	37.7249
3605.79	51.9297
3609.71	91.429
3613.62	150.401
3617.53	310.392
3621.44	702.172
3625.34	1255.09
3629.25	1248.94
3633.15	791.702
3637.05	395.97
3640.94	193.323
3644.83	92.2598
3648.72	57.5234
3652.61	35.3152
3656.5	30.3335
3660.38	31.0117
3664.26	33.1157
3668.14	20.5796
3672.01	8.86401
3675.88	5.07764
3679.75	5.95996
3683.62	9.41431
3687.49	16.7507
3691.35	24.5186
3695.21	29.74
3699.07	33.418
3702.92	37.0093
3706.77	40.7366
3710.62	42.866
3714.47	41.394
3718.32	39.3279
3722.16	36.2781
3726	33.2527
3729.84	32.8813
3733.67	35.2915
3737.51	40.2788
3741.34	46.0342
3745.16	51.8999
3748.99	56.217
3752.81	55.7712
3756.63	52.0259
3760.45	45.6138
3764.27	38.113
3768.08	33.6519
3771.89	35.4272
3775.7	38.3472
3779.5	37.3105
3783.31	37.2366
3787.11	37.5537
3790.91	40.6348
3794.7	40.9648
3798.5	36.8533
3802.29	37.488
3806.08	45.6794
3809.86	44.8042
3813.65	43.1489
3817.43	45.0955
3821.21	50.6829
3824.99	54.4297
3828.76	57.053
3832.53	56.675
3836.3	53.45
3840.07	50.2744
3843.83	40.051
3847.6	33.76
3851.36	36.123
3855.11	39.3147
3858.87	43.7263
3862.62	48.4431
3866.37	52.8743
3870.12	51.9165
3873.86	45.3879
3877.61	42.9919
3881.35	43.469
3885.09	45.6804
3888.82	44.4463
3892.56	35.9319
3896.29	23.2
3900.02	13.4038
3903.74	3.45337
3907.47	-5.63989
3911.19	-8.13892
3914.91	-2.93066
3918.63	9.37476
3922.34	28.1509
3926.05	28.1118
3929.76	38.1819
3933.47	52.1252
3937.18	60.1614
3940.88	55.5486
3944.58	50.074
3948.28	45.835
3951.97	44.5457
3955.67	44.2056
3959.36	44.3235
3963.05	44.2507
3966.74	50.9285
3970.42	49.1233
3974.1	46.1394
3977.78	36.9187
3981.46	26.1294
3985.13	18.2437
3988.81	16.1445
3992.48	16.1514
3996.15	24.9082
3999.81	54.2163