File: Data/3-Raman/maps/bu20-G-ff1-FI01_CLS_Montebrasite_raw.txt
#Acq. time (s)=	1
#Accumulations=	1
#Range (cm-¹)=	100...4000
#Windows=	1
#Auto scanning=	Off
#Autofocus=	Off
#SWIFT=	On
#Macrospot=	Off
#AutoExposure=	Off
#Spike filter=	Off
#Delay time (s)=	0
#Binning=	1
#Readout mode=	Signal
#DeNoise=	Lite
#ICS correction=	Off
#Dark correction=	Off
#Inst. Process=	Off
#Detector temperature (°C)=	-60.09
#Instrument=	LabRAM HR Evol
#Detector=	SIN-EM FIVIS
#Objective=	x100_VIS
#Grating=	150 (500nm)
#ND Filter=	100%
#Laser=	532nm_Edge
#Hole=	30.0125
#Temperature=	0
#Range=	Visible
#StageXY=	75x50mm Scan+
#StageZ=	Z motor
#Z (µm)=	1887.6
#Full time(mm:ss)=	31:39
#Project=	Buranga
#Sample=	BU18FA20_G
#Site=	G_trl1
#Title=	20-G_trl1_MI01_topbb_1
#Remark=
#Date=	30.07.2019 16:51
#Cursor=	Rectangle 9 points
#Y (µm)=	-5.8414 ... -3.3173
#X (µm)=	4.39296 ... 6.39296
#Generated=	29.03.2022 09:29:06
103.656	11.3454
108.278	5.66936
112.899	24.6647
117.517	33.4058
122.131	32.9201
126.744	91.1619
131.355	267.915
135.964	424.946
140.571	404.136
145.173	170.403
149.776	41.8504
154.375	32.4071
158.973	52.1121
163.566	83.9544
168.159	187.97
172.75	214.995
177.339	136.243
181.923	78.1141
186.507	87.6547
191.089	133.078
195.668	175.349
200.243	160.627
204.818	114.154
209.391	77.0271
213.96	50.4992
218.528	33.947
223.094	25.8518
227.655	27.272
232.217	34.9989
236.776	49.7032
241.331	68.6471
245.886	88.3513
250.439	114.653
254.987	137.563
259.535	145.727
264.081	138.972
268.622	161.887
273.164	212.5
277.703	254.756
282.238	399.75
286.773	807.516
291.305	1411.92
295.833	1565.36
300.362	1152.53
304.885	847.857
309.409	704.295
313.93	586.827
318.448	493.894
322.965	418.914
327.477	341.116
331.99	272.796
336.5	222.305
341.007	184.07
345.513	155.896
350.014	142.479
354.516	142.324
359.013	148.365
363.51	149.958
368.005	140.749
372.496	136.285
376.987	142.055
381.473	154.106
385.96	169.888
390.442	187.599
394.923	203.496
399.401	214.52
403.879	219.421
408.352	217.816
412.825	208.946
417.294	193.202
421.763	171.146
426.227	142.789
430.692	108.134
435.152	67.0135
439.612	34.127
444.068	12.482
448.524	2.37464
452.976	1.67223
457.427	10.8268
461.874	25.8663
466.32	44.287
470.765	65.5274
475.205	88.5569
479.646	114.56
484.083	140.253
488.519	162.22
492.951	176.926
497.381	176.17
501.811	158.287
506.237	131.479
510.663	100.509
515.084	71.7375
519.504	48.4962
523.923	30.3923
528.338	19.3001
532.753	13.2276
537.164	10.1618
541.572	9.535
545.981	9.13336
550.385	8.46214
554.788	7.1804
559.19	7.54241
563.588	9.0339
567.986	11.9662
572.38	23.1037
576.771	36.9579
581.163	44.3623
585.551	88.3753
589.936	218.808
594.319	445.185
598.702	580.258
603.081	439.627
607.458	277.251
611.835	181.086
616.208	131.344
620.578	117.773
624.949	148.476
629.315	194.455
633.68	290.163
638.042	502.693
642.404	798.53
646.762	842.175
651.118	490.056
655.472	223.117
659.825	106.031
664.175	83.8991
668.523	86.5711
672.868	91.3552
677.213	94.6318
681.555	89.8825
685.894	81.0578
690.231	68.5808
694.566	51.7621
698.901	33.8933
703.232	17.7085
707.561	5.82078
711.888	0.42197
716.212	1.36374
720.537	4.40758
724.858	8.70234
729.176	14.0131
733.493	17.9315
737.807	19.7882
742.119	19.2357
746.432	16.7285
750.74	12.9187
755.046	11.1128
759.35	14.9647
763.652	24.5025
767.952	42.6693
772.25	68.579
776.546	101.519
780.842	159.636
785.133	255.279
789.423	351.989
793.711	438.303
797.997	404.257
802.28	307.211
806.562	207.149
810.841	127.996
815.119	78.983
819.394	48.0353
823.668	32.4527
827.941	20.7384
832.211	14.503
836.478	10.3972
840.743	7.64247
845.006	6.66283
849.268	5.80011
853.527	5.79836
857.784	6.4924
862.039	6.36598
866.293	6.27559
870.544	6.5051
874.793	7.29196
879.04	6.97554
883.285	6.77364
887.528	7.19648
891.769	7.60498
896.008	8.34391
900.246	9.04606
904.481	10.248
908.714	12.0936
912.945	14.6707
917.174	17.1037
921.401	18.6556
925.626	20.0728
929.849	21.0023
934.068	22.8236
938.287	27.4801
942.504	35.0099
946.72	45.3216
950.933	57.4243
955.144	69.7736
959.353	81.9087
963.56	93.3272
967.765	103.649
971.968	114.692
976.17	132.659
980.367	149.098
984.564	182.93
988.759	247.232
992.953	339.441
997.144	543.322
1001.33	1019.58
1005.52	1737.07
1009.71	2187.08
1013.89	1904.88
1018.07	1169.75
1022.25	676.784
1026.43	452.335
1030.6	420.786
1034.78	742.274
1038.94	1110.34
1043.11	1396.44
1047.28	1552.89
1051.45	1594.25
1055.61	1599.52
1059.77	1401.48
1063.93	974.225
1068.09	531.007
1072.25	273.844
1076.4	210.198
1080.55	143.97
1084.7	141.295
1088.85	153.332
1092.99	200.706
1097.14	287.007
1101.28	438.306
1105.42	491.554
1109.56	430.362
1113.69	337.116
1117.83	272.882
1121.96	225.532
1126.09	192.231
1130.22	169.777
1134.35	157.993
1138.47	151.391
1142.59	144.241
1146.71	136.273
1150.83	117.296
1154.95	107.496
1159.06	105.953
1163.18	107.981
1167.29	108.19
1171.4	108.9
1175.5	106.834
1179.61	102.909
1183.71	96.452
1187.81	85.8913
1191.91	71.3864
1196.01	56.7656
1200.1	43.8421
1204.2	34.1354
1208.29	27.4706
1212.38	24.4409
1216.47	25.0242
1220.55	28.5497
1224.64	33.3014
1228.72	37.7287
1232.8	41.9671
1236.88	44.9627
1240.95	46.7535
1245.03	47.317
1249.1	46.07
1253.17	43.1411
1257.24	38.6287
1261.31	32.8156
1265.37	26.7625
1269.44	23.0875
1273.5	21.5478
1277.56	21.9029
1281.61	23.0418
1285.67	21.9548
1289.72	18.9484
1293.77	15.8529
1297.83	13.8165
1301.87	11.9611
1305.92	10.8418
1309.96	10.5223
1314.01	10.1695
1318.05	10.1325
1322.09	9.84885
1326.12	8.94025
1330.16	7.96095
1334.19	7.60105
1338.22	7.38039
1342.25	7.41068
1346.28	8.02158
1350.3	7.84136
1354.33	7.8386
1358.35	8.1018
1362.37	7.85356
1366.39	8.71867
1370.4	11.0241
1374.42	13.8833
1378.43	17.0377
1382.44	20.3102
1386.45	19.9955
1390.46	16.3534
1394.46	12.1243
1398.46	7.53496
1402.47	6.05658
1406.46	5.60714
1410.46	5.82594
1414.46	7.35868
1418.45	8.64588
1422.45	9.59572
1426.43	10.8963
1430.42	11.5911
1434.41	10.9522
1438.39	9.75782
1442.38	7.17119
1446.36	4.32078
1450.34	1.9132
1454.31	0.62625
1458.29	-0.378991
1462.27	0.735579
1466.24	2.46494
1470.21	4.07491
1474.18	5.86838
1478.14	7.1196
1482.11	6.49055
1486.07	6.0535
1490.03	4.9226
1493.99	4.00138
1497.95	3.36695
1501.9	3.7763
1505.86	3.42262
1509.81	3.36138
1513.76	3.65802
1517.71	3.95073
1521.65	5.32378
1525.6	5.85029
1529.54	5.99996
1533.48	6.1546
1537.42	6.14933
1541.36	6.09594
1545.29	6.05409
1549.23	6.34254
1553.16	6.61379
1557.09	7.90049
1561.02	10.1833
1564.94	12.3417
1568.87	15.1834
1572.79	16.9591
1576.71	17.028
1580.63	17.08
1584.55	16.2856
1588.47	15.8579
1592.38	15.6613
1596.29	14.7701
1600.2	13.4997
1604.11	13.0089
1608.02	12.9224
1611.92	12.5233
1615.83	12.1024
1619.73	11.4369
1623.63	10.5138
1627.53	10.6054
1631.42	10.8637
1635.32	10.5019
1639.21	10.4543
1643.1	9.81611
1646.99	8.94272
1650.88	8.32854
1654.76	7.71111
1658.64	6.93131
1662.53	6.13097
1666.41	5.43213
1670.28	4.39599
1674.16	4.18109
1678.04	5.60735
1681.91	6.0683
1685.78	6.50627
1689.65	6.77452
1693.52	6.32689
1697.38	6.19885
1701.25	6.513
1705.11	6.31924
1708.97	6.29456
1712.83	6.87631
1716.69	6.71281
1720.54	6.37604
1724.4	6.40842
1728.25	5.51822
1732.1	4.88961
1735.95	4.79741
1739.79	4.66982
1743.64	5.05518
1747.48	5.47861
1751.33	5.66872
1755.17	6.1396
1759	6.27343
1762.84	6.2605
1766.68	6.16243
1770.51	5.75834
1774.34	5.47572
1778.17	5.91807
1782	6.46163
1785.82	6.20476
1789.65	6.1528
1793.47	6.42209
1797.29	6.65037
1801.11	7.17043
1804.93	7.30889
1808.74	7.36098
1812.56	7.38743
1816.37	7.15384
1820.18	6.78516
1823.99	6.48121
1827.79	6.0816
1831.6	5.33375
1835.4	5.12487
1839.2	5.12195
1843	5.12242
1846.8	5.5418
1850.6	6.40608
1854.39	6.56156
1858.19	6.9801
1861.98	7.58731
1865.77	7.79227
1869.56	7.59694
1873.34	7.88776
1877.13	7.96577
1880.91	8.30622
1884.69	8.92332
1888.47	9.69137
1892.25	10.5792
1896.03	11.2766
1899.8	11.6674
1903.57	11.6336
1907.34	10.7142
1911.11	9.15192
1914.88	7.58471
1918.65	6.01718
1922.41	5.05281
1926.18	5.87243
1929.94	6.77095
1933.7	7.48417
1937.45	7.96225
1941.21	8.13416
1944.96	7.38719
1948.72	6.28186
1952.47	5.19471
1956.22	4.52771
1959.96	5.06723
1963.71	6.36803
1967.45	6.89734
1971.2	7.37156
1974.94	8.01592
1978.68	7.69072
1982.42	7.06812
1986.15	6.41004
1989.89	4.46117
1993.62	2.98963
1997.35	2.05463
2001.08	1.02848
2004.8	0.576573
2008.53	0.381734
2012.25	0.975113
2015.98	2.21606
2019.7	4.02383
2023.42	5.86744
2027.13	7.68881
2030.85	8.98196
2034.56	8.89701
2038.28	8.17157
2041.99	7.2559
2045.7	5.96595
2049.41	5.75541
2053.11	5.86914
2056.82	5.77175
2060.52	5.726
2064.22	6.27458
2067.92	5.8889
2071.62	5.42302
2075.31	4.61205
2079.01	3.85586
2082.7	3.58784
2086.39	3.84471
2090.08	3.71749
2093.77	4.40579
2097.45	5.00856
2101.14	4.64058
2104.82	4.16096
2108.5	3.80558
2112.18	4.19578
2115.86	4.75829
2119.54	6.11681
2123.21	7.63731
2126.88	8.97481
2130.56	9.66882
2134.23	9.77467
2137.89	9.23051
2141.56	8.28169
2145.23	6.54841
2148.89	5.42041
2152.55	4.46168
2156.21	4.8063
2159.87	5.20236
2163.53	5.30772
2167.18	4.85299
2170.84	5.08611
2174.49	5.52646
2178.14	5.85571
2181.79	6.96743
2185.44	8.03284
2189.08	8.11704
2192.73	8.31489
2196.37	9.26934
2200.01	9.38152
2203.65	9.63351
2207.29	10.5819
2210.92	10.2707
2214.56	9.52827
2218.19	8.80152
2221.82	7.90412
2225.45	7.43857
2229.08	7.80454
2232.7	8.14058
2236.33	8.75764
2239.95	9.08253
2243.57	9.03305
2247.19	8.72636
2250.81	7.58497
2254.43	5.86884
2258.04	4.79617
2261.66	4.66605
2265.27	4.92185
2268.88	5.807
2272.49	7.09881
2276.1	7.59399
2279.7	9.35714
2283.31	9.34865
2286.91	8.49837
2290.51	7.75649
2294.11	6.82087
2297.71	6.27812
2301.3	6.3588
2304.9	6.86884
2308.49	7.39843
2312.08	8.1841
2315.67	9.4797
2319.26	9.84492
2322.85	10.3776
2326.43	11.2375
2330.02	11.4769
2333.6	12.1153
2337.18	12.4602
2340.76	12.1371
2344.34	11.6012
2347.91	11.572
2351.49	10.9721
2355.06	10.5427
2358.63	10.7993
2362.2	10.9894
2365.77	11.5192
2369.33	11.9965
2372.9	11.6055
2376.46	11.4759
2380.02	11.2339
2383.58	10.7966
2387.14	10.3087
2390.7	10.0651
2394.25	9.53307
2397.81	9.03257
2401.36	8.38797
2404.91	7.18609
2408.46	5.89212
2412.01	4.8957
2415.56	3.79631
2419.1	3.64488
2422.64	4.11967
2426.18	4.5088
2429.72	5.32681
2433.26	6.14824
2436.8	6.62414
2440.34	7.12274
2443.87	7.48897
2447.4	6.78233
2450.93	5.97847
2454.46	4.89482
2457.99	3.76861
2461.52	3.33215
2465.04	3.37342
2468.56	3.8361
2472.09	4.45817
2475.61	5.54006
2479.13	6.34365
2482.64	6.6729
2486.16	6.52675
2489.67	5.99722
2493.18	5.4722
2496.69	4.94214
2500.2	4.55424
2503.71	4.56248
2507.22	5.12041
2510.72	5.32696
2514.23	5.84576
2517.73	5.8368
2521.23	5.31324
2524.73	5.30081
2528.23	5.37989
2531.72	5.40927
2535.21	5.5307
2538.71	6.15122
2542.2	6.63428
2545.69	7.5465
2549.18	8.42922
2552.66	9.37683
2556.15	10.0176
2559.63	10.2825
2563.12	10.1213
2566.6	9.5793
2570.08	8.20366
2573.55	7.08843
2577.03	6.34593
2580.5	5.66038
2583.98	4.89996
2587.45	4.28426
2590.92	3.93961
2594.39	3.77661
2597.86	4.81862
2601.32	6.65212
2604.79	7.78291
2608.25	9.0024
2611.71	9.10169
2615.17	7.73703
2618.63	6.87364
2622.08	5.11335
2625.54	4.39361
2628.99	4.96526
2632.45	6.07627
2635.9	6.51542
2639.35	6.45986
2642.79	6.44297
2646.24	5.67365
2649.69	5.32173
2653.13	5.20757
2656.57	5.31591
2660.01	6.34381
2663.45	7.28468
2666.89	7.64981
2670.32	7.61097
2673.76	6.7753
2677.19	5.09569
2680.62	3.982
2684.05	3.83864
2687.48	4.22193
2690.91	5.07828
2694.33	5.97766
2697.76	6.26378
2701.18	7.14009
2704.6	7.94576
2708.02	7.64386
2711.44	7.18738
2714.86	6.37445
2718.27	5.69387
2721.69	5.47923
2725.1	5.22847
2728.51	5.02996
2731.92	5.56056
2735.33	6.27245
2738.74	6.87045
2742.14	7.24584
2745.55	6.91584
2748.95	6.1214
2752.35	5.13524
2755.75	4.42798
2759.15	3.12864
2762.54	2.11686
2765.94	2.64354
2769.33	3.20872
2772.72	4.30167
2776.12	5.10386
2779.51	4.84515
2782.89	4.48516
2786.28	3.7599
2789.67	2.97178
2793.05	3.11746
2796.43	2.69494
2799.81	2.31631
2803.19	3.48773
2806.57	4.54502
2809.95	5.31312
2813.32	6.33222
2816.69	6.72113
2820.06	6.79933
2823.44	6.88035
2826.81	6.53829
2830.17	5.87608
2833.54	5.09431
2836.9	4.48762
2840.27	3.86735
2843.63	3.44893
2846.99	3.25132
2850.35	2.61447
2853.71	2.48154
2857.06	2.9502
2860.42	3.8378
2863.77	5.38539
2867.12	6.39506
2870.48	7.02476
2873.83	7.58926
2877.17	8.24632
2880.52	7.99178
2883.86	7.53645
2887.21	7.21783
2890.55	6.36473
2893.89	5.93856
2897.23	6.96341
2900.57	7.02635
2903.91	7.38123
2907.24	7.57846
2910.57	7.24646
2913.91	7.15166
2917.24	6.73471
2920.57	5.86283
2923.9	4.94507
2927.22	4.05194
2930.55	3.43977
2933.87	3.40723
2937.19	4.13891
2940.51	5.07375
2943.83	6.30448
2947.15	7.16674
2950.47	7.74036
2953.79	7.64863
2957.1	7.38189
2960.41	7.27809
2963.72	7.54872
2967.03	7.75022
2970.34	7.40082
2973.65	7.40937
2976.95	7.39147
2980.26	6.66371
2983.56	5.76158
2986.86	4.93321
2990.16	3.87955
2993.46	3.43569
2996.76	3.63438
3000.06	3.61779
3003.35	3.6779
3006.64	4.35624
3009.94	4.57053
3013.23	4.99882
3016.51	6.17039
3019.8	5.9306
3023.09	5.82755
3026.38	6.40479
3029.66	6.18758
3032.94	6.2264
3036.22	6.40253
3039.5	4.92725
3042.78	4.18547
3046.05	3.62266
3049.33	2.75349
3052.6	2.74565
3055.88	2.93702
3059.15	3.4501
3062.42	7.96876
3065.69	6.44706
3068.95	6.16378
3072.22	5.58464
3075.48	5.42225
3078.75	5.00774
3082.01	5.73678
3085.27	6.89109
3088.53	8.14061
3091.79	9.36822
3095.04	10.3297
3098.3	9.83746
3101.55	8.97673
3104.8	7.83274
3108.05	6.69808
3111.3	6.76167
3114.55	8.16851
3117.8	8.18094
3121.04	7.95114
3124.29	6.98663
3127.53	5.32073
3130.77	4.18692
3134.01	3.39012
3137.25	2.88986
3140.49	3.61633
3143.72	5.47018
3146.96	6.84384
3150.19	8.74435
3153.42	10.8666
3156.65	11.5226
3159.88	11.8667
3163.11	11.9691
3166.34	11.3621
3169.56	10.4574
3172.79	9.85993
3176.01	8.79181
3179.23	8.08123
3182.45	7.8926
3185.67	8.37089
3188.88	9.42188
3192.1	11.1202
3195.31	12.2587
3198.53	13.4695
3201.74	14.0762
3204.95	14.5834
3208.16	15.1637
3211.37	16.4401
3214.57	17.3481
3217.78	18.0462
3220.98	18.327
3224.18	17.9081
3227.39	17.8643
3230.59	18.9398
3233.78	19.8834
3236.98	20.6947
3240.18	20.677
3243.37	19.7848
3246.56	19.5999
3249.76	19.55
3252.95	19.8165
3256.14	20.578
3259.32	21.1313
3262.51	21.0519
3265.7	20.7641
3268.88	20.5225
3272.06	19.3915
3275.24	18.513
3278.42	18.6056
3281.6	19.1224
3284.78	20.5356
3287.96	22.6271
3291.13	22.6045
3294.31	22.6616
3297.48	22.1988
3300.65	21.6693
3303.82	22.7749
3306.99	25.6202
3310.15	28.1556
3313.32	31.2752
3316.48	34.4613
3319.65	36.4026
3322.81	38.35
3325.97	40.8465
3329.13	42.6105
3332.28	45.6603
3335.44	50.3749
3338.6	57.2661
3341.75	67.5111
3344.9	81.5079
3348.05	97.3365
3351.2	120.015
3354.35	150.339
3357.5	181.668
3360.65	225.778
3363.79	326.956
3366.94	454.065
3370.08	711.432
3373.22	1132.14
3376.36	1457.55
3379.5	1473.88
3382.63	1123.96
3385.77	760.21
3388.9	503.786
3392.04	378.154
3395.17	279.923
3398.3	214.293
3401.43	180.226
3404.56	149.126
3407.69	138.752
3410.81	130.642
3413.94	119.935
3417.06	144.642
3420.18	198.858
3423.3	323.8
3426.42	555.073
3429.54	626.859
3432.65	442.02
3435.77	229.189
3438.88	146.459
3442	95.1961
3445.11	68.5465
3448.22	52.2899
3451.33	42.7582
3454.43	39.5293
3457.54	38.2831
3460.65	36.0979
3463.75	35.7744
3466.85	38.4337
3469.95	40.5916
3473.05	44.7791
3476.15	50.5132
3479.25	58.08
3482.35	66.4012
3485.44	79.1732
3488.54	93.2017
3491.63	113.155
3494.72	137.562
3497.81	178.996
3500.9	229.793
3503.99	296.789
3507.07	357.391
3510.16	413.886
3513.24	401.678
3516.32	335.357
3519.41	273.811
3522.49	212.617
3525.56	161.27
3528.64	122.946
3531.72	96.538
3534.79	76.2934
3537.87	63.3135
3540.94	53.8051
3544.01	47.9254
3547.08	43.3879
3550.15	38.5619
3553.22	32.6088
3556.28	28.0577
3559.35	24.2337
3562.41	20.9817
3565.47	18.5664
3568.54	17.8133
3571.6	16.8324
3574.65	16.5455
3577.71	16.7966
3580.77	17.1245
3583.82	17.8916
3586.88	18.9085
3589.93	19.3889
3592.98	19.7868
3596.03	18.4908
3599.08	16.5846
3602.13	14.8754
3605.18	13.4249
3608.22	12.5199
3611.27	11.7734
3614.31	11.5872
3617.35	11.2144
3620.39	10.7835
3623.43	10.0973
3626.47	8.44698
3629.5	7.27344
3632.54	6.57412
3635.57	6.31082
3638.61	7.48548
3641.64	9.09201
3644.67	10.4163
3647.7	11.3216
3650.73	11.6047
3653.75	9.57084
3656.78	8.31847
3659.8	7.75729
3662.83	6.84354
3665.85	8.29168
3668.87	9.27959
3671.89	8.67866
3674.91	8.45721
3677.92	8.25184
3680.94	7.27666
3683.96	6.45124
3686.97	5.94291
3689.98	5.20453
3692.99	4.94853
3696	5.32983
3699.01	5.72717
3702.02	6.6188
3705.02	7.39395
3708.03	7.2849
3711.03	7.37863
3714.03	7.54967
3717.04	7.73658
3720.04	7.36198
3723.04	6.73392
3726.03	5.88869
3729.03	5.26738
3732.03	5.29261
3735.02	4.63577
3738.01	3.33501
3741	2.60576
3743.99	1.75185
3746.98	1.98897
3749.97	3.36469
3752.96	4.72783
3755.95	5.72086
3758.93	6.8077
3761.91	6.71741
3764.9	7.05194
3767.88	7.57939
3770.86	7.30243
3773.84	7.00506
3776.81	6.85765
3779.79	6.23841
3782.77	5.74049
3785.74	5.76217
3788.71	5.53098
3791.68	5.49789
3794.65	5.70187
3797.62	5.72553
3800.59	5.95579
3803.56	6.01389
3806.52	6.0129
3809.49	6.7861
3812.45	8.31386
3815.41	7.52763
3818.37	6.60197
3821.33	5.45372
3824.29	4.79757
3827.25	6.19426
3830.21	7.47918
3833.16	7.59088
3836.11	7.84273
3839.07	7.98374
3842.02	7.80016
3844.97	8.36836
3847.92	9.21267
3850.87	8.81433
3853.81	8.77048
3856.76	9.50138
3859.7	9.63665
3862.65	9.1113
3865.59	8.52246
3868.53	7.42961
3871.47	6.85837
3874.41	6.24226
3877.34	5.55604
3880.28	5.08754
3883.22	5.12652
3886.15	5.22695
3889.08	5.82685
3892.01	6.3073
3894.94	7.01079
3897.87	7.58568
3900.8	7.96407
3903.73	8.07742
3906.65	8.24408
3909.58	8.4434
3912.5	9.27899
3915.42	10.4283
3918.35	11.3321
3921.27	11.6073
3924.18	11.2302
3927.1	11.0149
3930.02	10.3975
3932.93	10.1939
3935.85	10.4678
3938.76	9.70556
3941.67	8.66723
3944.58	7.76265
3947.49	6.41704
3950.4	6.2268
3953.31	6.72632
3956.22	6.84452
3959.12	7.15719
3962.02	7.8145
3964.93	8.3736
3967.83	8.88697
3970.73	9.33877
3973.63	9.61665
3976.53	9.99046
3979.42	11.3181
3982.32	11.0231
3985.21	10.3672
3988.11	8.96062
3991	5.79497
3993.89	6.50043
3996.78	13.1779
3999.67	3.69565