File: Data/3-Raman/maps/bu20-G-ff1-FI01_CLS_wardite_raw.txt
#Acq. time (s)=	1
#Accumulations=	1
#Range (cm-¹)=	100...4000
#Windows=	1
#Auto scanning=	Off
#Autofocus=	Off
#SWIFT=	On
#Macrospot=	Off
#AutoExposure=	Off
#Spike filter=	Off
#Delay time (s)=	0
#Binning=	1
#Readout mode=	Signal
#DeNoise=	Lite
#ICS correction=	Off
#Dark correction=	Off
#Inst. Process=	Off
#Detector temperature (°C)=	-60.09
#Instrument=	LabRAM HR Evol
#Detector=	SIN-EM FIVIS
#Objective=	x100_VIS
#Grating=	150 (500nm)
#ND Filter=	100%
#Laser=	532nm_Edge
#Hole=	30.0125
#Temperature=	0
#Range=	Visible
#StageXY=	75x50mm Scan+
#StageZ=	Z motor
#Z (µm)=	1887.6
#Full time(mm:ss)=	31:39
#Project=	Buranga
#Sample=	BU18FA20_G
#Site=	G_trl1
#Title=	20-G_trl1_MI01_topbb_1
#Remark=
#Date=	30.07.2019 16:51
#Cursor=	Rectangle 20 points
#Y (µm)=	6.77912 ... 10.5653
#X (µm)=	3.39296 ... 7.39296
#Generated=	29.03.2022 09:38:49
103.656	3.3835
108.278	23.2569
112.899	44.4775
117.517	56.2748
122.131	63.0856
126.744	68.2071
131.355	73.0338
135.964	77.6471
140.571	82.6124
145.173	88.7188
149.776	93.0734
154.375	78.5796
158.973	57.4675
163.566	130.137
168.159	295.336
172.75	607.834
177.339	756.744
181.923	528.801
186.507	338.714
191.089	238.873
195.668	183.936
200.243	147.806
204.818	126.729
209.391	119.572
213.96	141.688
218.528	195.216
223.094	243.15
227.655	215.254
232.217	172.708
236.776	172.755
241.331	194.117
245.886	234.638
250.439	368.933
254.987	554.287
259.535	610.91
264.081	371.214
268.622	150.241
273.164	92.3214
277.703	147.956
282.238	355.3
286.773	625.912
291.305	643.255
295.833	451.931
300.362	250.147
304.885	164.368
309.409	129.263
313.93	121.794
318.448	136.937
322.965	179.06
327.477	238.782
331.99	326.286
336.5	384.822
341.007	388.996
345.513	366.322
350.014	336.216
354.516	365.177
359.013	395.746
363.51	351.156
368.005	283.108
372.496	221.931
376.987	183.62
381.473	167.175
385.96	167.446
390.442	180.74
394.923	208.8
399.401	242.303
403.879	231.179
408.352	152.817
412.825	85.4578
417.294	49.8261
421.763	38.7548
426.227	35.768
430.692	34.6551
435.152	28.7445
439.612	25.3884
444.068	25.42
448.524	30.7691
452.976	40.0512
457.427	51.6132
461.874	65.3453
466.32	80.5342
470.765	98.2321
475.205	122.454
479.646	150.021
484.083	170.583
488.519	175.019
492.951	170.204
497.381	175.411
501.811	181.965
506.237	184.114
510.663	161.589
515.084	122.307
519.504	78.6878
523.923	40.8435
528.338	15.5509
532.753	4.42273
537.164	4.33633
541.572	10.7343
545.981	18.5599
550.385	24.5375
554.788	27.889
559.19	29.1334
563.588	30.5626
567.986	34.9378
572.38	46.2413
576.771	60.6194
581.163	87.7866
585.551	134.496
589.936	200.788
594.319	280.32
598.702	336.159
603.081	378.188
607.458	407.165
611.835	422.742
616.208	443.032
620.578	452.228
624.949	388.59
629.315	276.533
633.68	180.643
638.042	122.755
642.404	96.6572
646.762	91.2514
651.118	97.3803
655.472	113.479
659.825	137.849
664.175	168.353
668.523	200.767
672.868	229.796
677.213	250.215
681.555	248.616
685.894	225.742
690.231	187.769
694.566	139.759
698.901	92.6825
703.232	56.6111
707.561	32.5671
711.888	18.5818
716.212	11.5635
720.537	7.85972
724.858	6.15951
729.176	5.29469
733.493	4.16342
737.807	2.59069
742.119	0.910594
746.432	0.276545
750.74	1.46936
755.046	7.38439
759.35	19.3582
763.652	36.9299
767.952	62.9069
772.25	98.2536
776.546	151.502
780.842	230.985
785.133	329.396
789.423	345.582
793.711	285.194
797.997	189.481
802.28	119.87
806.562	74.9682
810.841	44.9188
815.119	27.2941
819.394	17.9949
823.668	12.7146
827.941	9.40908
832.211	7.92879
836.478	6.58985
840.743	5.41208
845.006	4.98372
849.268	4.95501
853.527	4.98284
857.784	5.51791
862.039	6.48915
866.293	7.71035
870.544	9.88579
874.793	12.6775
879.04	15.4928
883.285	18.4273
887.528	21.1306
891.769	22.4486
896.008	22.7584
900.246	22.6393
904.481	22.2396
908.714	21.5619
912.945	20.91
917.174	19.9602
921.401	19.3331
925.626	19.5273
929.849	21.8757
934.068	27.5668
938.287	38.0316
942.504	53.8477
946.72	73.2131
950.933	96.1891
955.144	117.716
959.353	138.303
963.56	151.921
967.765	150.062
971.968	148.278
976.17	165.427
980.367	219.045
984.564	363.106
988.759	630.733
992.953	849.057
997.144	766.746
1001.33	504.291
1005.52	295.576
1009.71	191.064
1013.89	145.468
1018.07	125.676
1022.25	138.069
1026.43	172.992
1030.6	227.615
1034.78	308.974
1038.94	442.248
1043.11	635.897
1047.28	859.168
1051.45	918.966
1055.61	815.347
1059.77	686.645
1063.93	560.598
1068.09	465.646
1072.25	389.186
1076.4	341.723
1080.55	322.167
1084.7	321.263
1088.85	338.866
1092.99	379.943
1097.14	431.432
1101.28	453.705
1105.42	452.203
1109.56	447.157
1113.69	445.379
1117.83	445.84
1121.96	444.94
1126.09	442.908
1130.22	438.766
1134.35	446.841
1138.47	465.506
1142.59	463.403
1146.71	404.619
1150.83	323.228
1154.95	283.996
1159.06	276.974
1163.18	281.69
1167.29	279.051
1171.4	262.576
1175.5	234.807
1179.61	202.692
1183.71	166.458
1187.81	128.418
1191.91	94.753
1196.01	71.7992
1200.1	56.3877
1204.2	48.2614
1208.29	44.7163
1212.38	44.5955
1216.47	48.393
1220.55	56.4353
1224.64	67.5647
1228.72	79.9059
1232.8	90.0887
1236.88	96.0182
1240.95	98.3386
1245.03	97.6208
1249.1	94.3074
1253.17	85.0703
1257.24	71.2901
1261.31	56.3549
1265.37	43.858
1269.44	33.5844
1273.5	26.3401
1277.56	21.7521
1281.61	18.8552
1285.67	17.3576
1289.72	16.6151
1293.77	16.0556
1297.83	15.6323
1301.87	15.2824
1305.92	15.1125
1309.96	15.3672
1314.01	15.1147
1318.05	14.8355
1322.09	14.7051
1326.12	14.3158
1330.16	13.6384
1334.19	13.0229
1338.22	12.3627
1342.25	11.8448
1346.28	11.1006
1350.3	10.4516
1354.33	9.72174
1358.35	9.09883
1362.37	8.39361
1366.39	7.95793
1370.4	7.92723
1374.42	8.3323
1378.43	9.39945
1382.44	10.3056
1386.45	10.4704
1390.46	9.52188
1394.46	8.313
1398.46	7.26409
1402.47	6.45572
1406.46	6.04151
1410.46	6.0402
1414.46	5.98489
1418.45	6.00538
1422.45	5.93423
1426.43	5.8257
1430.42	5.63996
1434.41	5.51857
1438.39	5.11009
1442.38	4.87212
1446.36	4.79463
1450.34	4.82994
1454.31	5.01163
1458.29	5.15619
1462.27	5.50816
1466.24	5.6677
1470.21	5.63059
1474.18	5.54618
1478.14	5.3747
1482.11	5.08266
1486.07	5.19291
1490.03	5.55599
1493.99	5.93192
1497.95	6.55469
1501.9	7.33726
1505.86	7.8461
1509.81	8.0626
1513.76	8.21409
1517.71	7.77623
1521.65	7.44857
1525.6	6.8253
1529.54	6.24377
1533.48	6.1444
1537.42	6.15747
1541.36	6.17383
1545.29	5.963
1549.23	5.26901
1553.16	4.83928
1557.09	4.75768
1561.02	4.69538
1564.94	4.75539
1568.87	5.20028
1572.79	5.92868
1576.71	6.54361
1580.63	6.58426
1584.55	6.27437
1588.47	5.83842
1592.38	4.78202
1596.29	4.36682
1600.2	4.28274
1604.11	4.25628
1608.02	4.69387
1611.92	4.95306
1615.83	4.88104
1619.73	4.59944
1623.63	4.38757
1627.53	4.13432
1631.42	3.95719
1635.32	4.36705
1639.21	4.77402
1643.1	5.01915
1646.99	5.35722
1650.88	5.35489
1654.76	5.0557
1658.64	5.15104
1662.53	5.04754
1666.41	5.24346
1670.28	5.30267
1674.16	5.59593
1678.04	6.00865
1681.91	6.60823
1685.78	6.87142
1689.65	7.26828
1693.52	7.27618
1697.38	6.50601
1701.25	5.59774
1705.11	5.56318
1708.97	5.89608
1712.83	6.70262
1716.69	7.5296
1720.54	8.34473
1724.4	8.74506
1728.25	8.58999
1732.1	8.16167
1735.95	7.8144
1739.79	7.83845
1743.64	7.9041
1747.48	8.08532
1751.33	8.10029
1755.17	7.81021
1759	8.16129
1762.84	8.07402
1766.68	7.71915
1770.51	7.53922
1774.34	7.16861
1778.17	7.25137
1782	7.40602
1785.82	7.18927
1789.65	7.09148
1793.47	6.94657
1797.29	6.83875
1801.11	6.41657
1804.93	5.73054
1808.74	4.53261
1812.56	3.35543
1816.37	2.50442
1820.18	2.11393
1823.99	2.2383
1827.79	2.92637
1831.6	3.28312
1835.4	3.50427
1839.2	3.84683
1843	4.04761
1846.8	4.06655
1850.6	4.0817
1854.39	3.96732
1858.19	3.35466
1861.98	2.86544
1865.77	2.11041
1869.56	2.29736
1873.34	2.77247
1877.13	3.52244
1880.91	4.40444
1884.69	4.69179
1888.47	4.80459
1892.25	5.13008
1896.03	5.29596
1899.8	5.36731
1903.57	5.41138
1907.34	5.47348
1911.11	5.54954
1914.88	5.47095
1918.65	5.43123
1922.41	5.6447
1926.18	5.89371
1929.94	5.88785
1933.7	5.92941
1937.45	5.74977
1941.21	5.52007
1944.96	5.30682
1948.72	4.78443
1952.47	4.12623
1956.22	4.02133
1959.96	4.05214
1963.71	4.45627
1967.45	4.9793
1971.2	5.43601
1974.94	5.92174
1978.68	6.24761
1982.42	6.57789
1986.15	6.85271
1989.89	6.93175
1993.62	6.95455
1997.35	6.82598
2001.08	6.83667
2004.8	6.94698
2008.53	6.35793
2012.25	5.61077
2015.98	5.19032
2019.7	4.81584
2023.42	4.80088
2027.13	5.25559
2030.85	6.1117
2034.56	7.24011
2038.28	7.91522
2041.99	8.06704
2045.7	8.13538
2049.41	7.74275
2053.11	7.31098
2056.82	7.02703
2060.52	6.99109
2064.22	6.84245
2067.92	6.97465
2071.62	7.14092
2075.31	7.22306
2079.01	7.0417
2082.7	6.71535
2086.39	6.53323
2090.08	6.62105
2093.77	6.84461
2097.45	7.16747
2101.14	7.45981
2104.82	7.50779
2108.5	7.86289
2112.18	8.66765
2115.86	9.65673
2119.54	10.2297
2123.21	10.6673
2126.88	11.0939
2130.56	11.0361
2134.23	10.6858
2137.89	10.2045
2141.56	10.1835
2145.23	10.2512
2148.89	10.6887
2152.55	11.0343
2156.21	11.0359
2159.87	11.3268
2163.53	12.081
2167.18	12.408
2170.84	12.4724
2174.49	12.8943
2178.14	13.1872
2181.79	13.2958
2185.44	14.0545
2189.08	14.3927
2192.73	14.9041
2196.37	15.3661
2200.01	15.3731
2203.65	15.0295
2207.29	14.7088
2210.92	14.9553
2214.56	15.8658
2218.19	16.8294
2221.82	18.2673
2225.45	19.5694
2229.08	20.5092
2232.7	20.4329
2236.33	19.3444
2239.95	18.3517
2243.57	17.0779
2247.19	15.4275
2250.81	13.9266
2254.43	12.641
2258.04	12.0683
2261.66	12.4674
2265.27	13.0491
2268.88	13.3919
2272.49	13.6475
2276.1	13.4824
2279.7	13.0247
2283.31	12.8546
2286.91	12.1597
2290.51	11.5653
2294.11	11.6614
2297.71	11.7412
2301.3	12.0449
2304.9	12.4149
2308.49	12.2688
2312.08	11.6904
2315.67	11.4429
2319.26	10.8151
2322.85	10.274
2326.43	9.38935
2330.02	8.62889
2333.6	8.44454
2337.18	8.57137
2340.76	8.91833
2344.34	9.75742
2347.91	10.5723
2351.49	11.19
2355.06	11.7126
2358.63	11.9484
2362.2	11.3882
2365.77	10.5064
2369.33	9.24597
2372.9	8.03542
2376.46	7.63527
2380.02	8.38981
2383.58	9.23846
2387.14	9.7897
2390.7	9.82027
2394.25	9.56286
2397.81	9.29072
2401.36	8.9113
2404.91	8.07328
2408.46	7.50941
2412.01	7.34828
2415.56	6.91466
2419.1	6.74392
2422.64	6.86738
2426.18	6.87017
2429.72	6.55689
2433.26	6.34571
2436.8	6.02993
2440.34	5.99447
2443.87	6.30783
2447.4	6.60406
2450.93	6.66414
2454.46	6.47358
2457.99	6.20222
2461.52	5.24425
2465.04	4.63455
2468.56	4.3042
2472.09	4.42209
2475.61	4.86498
2479.13	5.45842
2482.64	5.58252
2486.16	5.53461
2489.67	5.52006
2493.18	5.58451
2496.69	5.37246
2500.2	5.25024
2503.71	4.97087
2507.22	4.92879
2510.72	4.93527
2514.23	5.20147
2517.73	5.15059
2521.23	4.90897
2524.73	4.34676
2528.23	3.39126
2531.72	2.42171
2535.21	1.76467
2538.71	1.91132
2542.2	2.24142
2545.69	2.79329
2549.18	3.43832
2552.66	3.96891
2556.15	4.13683
2559.63	4.07047
2563.12	3.60442
2566.6	2.99812
2570.08	2.71158
2573.55	2.44087
2577.03	2.58392
2580.5	2.97606
2583.98	3.2857
2587.45	3.88554
2590.92	4.73871
2594.39	5.07678
2597.86	5.15737
2601.32	4.74812
2604.79	3.87412
2608.25	3.95088
2611.71	3.34117
2615.17	3.12488
2618.63	2.83885
2622.08	3.04344
2625.54	2.8975
2628.99	2.44903
2632.45	2.02923
2635.9	1.38811
2639.35	1.32899
2642.79	1.8929
2646.24	2.93117
2649.69	4.06807
2653.13	4.94954
2656.57	5.68881
2660.01	5.83012
2663.45	5.84369
2666.89	5.43603
2670.32	4.56592
2673.76	3.8811
2677.19	3.42299
2680.62	3.70199
2684.05	4.42253
2687.48	5.31383
2690.91	6.06058
2694.33	6.44651
2697.76	6.65314
2701.18	6.95712
2704.6	7.18997
2708.02	7.22047
2711.44	6.72349
2714.86	6.07127
2718.27	5.46005
2721.69	4.86069
2725.1	4.64804
2728.51	5.27096
2731.92	5.82426
2735.33	6.83907
2738.74	7.85745
2742.14	9.0158
2745.55	10.9204
2748.95	12.2631
2752.35	13.1583
2755.75	13.8063
2759.15	14.0813
2762.54	14.7312
2765.94	15.2987
2769.33	15.6096
2772.72	16.6966
2776.12	18.0976
2779.51	19.1036
2782.89	19.8846
2786.28	20.7773
2789.67	21.6441
2793.05	23.1038
2796.43	24.365
2799.81	25.9804
2803.19	27.4888
2806.57	29.5281
2809.95	31.5601
2813.32	33.5696
2816.69	35.9368
2820.06	38.1343
2823.44	40.4549
2826.81	42.7479
2830.17	45.0057
2833.54	47.8271
2836.9	51.2725
2840.27	54.2375
2843.63	57.6183
2846.99	60.9731
2850.35	63.7244
2853.71	66.2298
2857.06	68.7571
2860.42	71.326
2863.77	74.1801
2867.12	76.958
2870.48	78.9945
2873.83	80.4553
2877.17	81.0789
2880.52	81.7231
2883.86	81.3109
2887.21	79.1746
2890.55	77.6745
2893.89	76.5142
2897.23	76.5918
2900.57	77.0283
2903.91	77.2282
2907.24	76.7908
2910.57	75.4579
2913.91	73.8895
2917.24	72.3701
2920.57	70.6459
2923.9	69.661
2927.22	68.7995
2930.55	67.8472
2933.87	66.7974
2937.19	65.4322
2940.51	63.8829
2943.83	62.117
2947.15	59.9456
2950.47	57.7284
2953.79	55.849
2957.1	54.5927
2960.41	53.5001
2963.72	52.4874
2967.03	51.3823
2970.34	50.4154
2973.65	49.3855
2976.95	48.1673
2980.26	46.7407
2983.56	45.3085
2986.86	45.4369
2990.16	44.6807
2993.46	42.5005
2996.76	41.3721
3000.06	39.9241
3003.35	39.3204
3006.64	39.0966
3009.94	33.0507
3013.23	32.6865
3016.51	33.751
3019.8	34.1829
3023.09	33.0531
3026.38	33.2019
3029.66	31.0031
3032.94	30.5395
3036.22	30.3549
3039.5	30.2886
3042.78	29.9606
3046.05	29.8508
3049.33	26.6185
3052.6	25.0471
3055.88	24.8319
3059.15	23.3328
3062.42	22.9838
3065.69	23.0629
3068.95	22.5872
3072.22	21.6501
3075.48	20.439
3078.75	19.3036
3082.01	18.748
3085.27	18.1028
3088.53	17.8569
3091.79	17.7149
3095.04	17.438
3098.3	17.0101
3101.55	16.7507
3104.8	16.3093
3108.05	15.9254
3111.3	14.5816
3114.55	13.2232
3117.8	11.9862
3121.04	10.2022
3124.29	10.13
3127.53	9.79679
3130.77	9.25023
3134.01	9.59995
3137.25	9.12747
3140.49	9.22146
3143.72	9.17976
3146.96	9.21971
3150.19	8.65822
3153.42	8.78157
3156.65	7.75023
3159.88	7.30771
3163.11	7.37706
3166.34	7.19954
3169.56	6.71546
3172.79	5.94586
3176.01	5.36826
3179.23	4.88479
3182.45	3.98603
3185.67	3.14793
3188.88	3.24206
3192.1	4.09221
3195.31	5.04387
3198.53	5.8123
3201.74	6.1549
3204.95	6.50988
3208.16	6.89657
3211.37	7.61378
3214.57	8.90888
3217.78	10.5384
3220.98	13.1078
3224.18	17.4907
3227.39	22.8528
3230.59	28.6379
3233.78	35.0923
3236.98	42.0799
3240.18	49.8218
3243.37	58.4339
3246.56	67.3128
3249.76	77.2415
3252.95	88.2129
3256.14	99.6027
3259.32	110.298
3262.51	119.467
3265.7	126.15
3268.88	129.298
3272.06	128.035
3275.24	122.731
3278.42	114.237
3281.6	104.259
3284.78	94.107
3287.96	83.9627
3291.13	74.3327
3294.31	65.2105
3297.48	57.0937
3300.65	50.5084
3303.82	44.9606
3306.99	40.8417
3310.15	37.4329
3313.32	34.8426
3316.48	32.3007
3319.65	29.8502
3322.81	27.9936
3325.97	26.6423
3329.13	25.5296
3332.28	24.6099
3335.44	23.3726
3338.6	21.6983
3341.75	20.2892
3344.9	18.9824
3348.05	18.1112
3351.2	17.5415
3354.35	17.2623
3357.5	17.6174
3360.65	17.0627
3363.79	16.8147
3366.94	16.2589
3370.08	15.6033
3373.22	15.1076
3376.36	14.8905
3379.5	15.343
3382.63	16.2416
3385.77	17.6404
3388.9	19.4819
3392.04	21.6069
3395.17	24.659
3398.3	29.0654
3401.43	36.1106
3404.56	44.3484
3407.69	52.1805
3410.81	71.8967
3413.94	100.329
3417.06	150.625
3420.18	298.044
3423.3	697.673
3426.42	1408.41
3429.54	1692.94
3432.65	1238.4
3435.77	587.465
3438.88	259.976
3442	140.01
3445.11	93.8775
3448.22	67.9699
3451.33	52.1867
3454.43	42.9245
3457.54	37.7661
3460.65	35.4183
3463.75	36.1827
3466.85	39.8612
3469.95	46.2865
3473.05	54.1947
3476.15	65.597
3479.25	78.8795
3482.35	94.8048
3485.44	118.534
3488.54	154.529
3491.63	206.641
3494.72	283.863
3497.81	391.677
3500.9	548.56
3503.99	766.709
3507.07	1007.15
3510.16	1172.73
3513.24	1158.95
3516.32	981.125
3519.41	736.794
3522.49	526.558
3525.56	373.246
3528.64	268.052
3531.72	226.294
3534.79	193.052
3537.87	245.731
3540.94	643.262
3544.01	1990.21
3547.08	2571.01
3550.15	1357.66
3553.22	405.728
3556.28	139.005
3559.35	83.6939
3562.41	58.4244
3565.47	42.738
3568.54	32.8704
3571.6	26.6299
3574.65	22.0991
3577.71	19.7966
3580.77	19.8814
3583.82	22.8395
3586.88	29.0079
3589.93	37.1489
3592.98	45.7119
3596.03	56.5687
3599.08	84.7307
3602.13	156.611
3605.18	461.295
3608.22	1325.15
3611.27	1825.16
3614.31	1173.17
3617.35	524.232
3620.39	216.435
3623.43	96.5084
3626.47	54.3664
3629.5	33.1438
3632.54	19.8124
3635.57	11.654
3638.61	7.62095
3641.64	5.79115
3644.67	4.75208
3647.7	4.31396
3650.73	3.99997
3653.75	3.06822
3656.78	2.49383
3659.8	2.43927
3662.83	2.58417
3665.85	3.28501
3668.87	3.76961
3671.89	4.3984
3674.91	4.82064
3677.92	5.0064
3680.94	4.95425
3683.96	5.01616
3686.97	5.18358
3689.98	5.79558
3692.99	5.73452
3696	5.56998
3699.01	5.88632
3702.02	5.93121
3705.02	6.40454
3708.03	6.68884
3711.03	7.30394
3714.03	7.85667
3717.04	8.04944
3720.04	8.02812
3723.04	7.88879
3726.03	7.86777
3729.03	7.97556
3732.03	8.59811
3735.02	9.24387
3738.01	10.2651
3741	11.3346
3743.99	12.2318
3746.98	13.1167
3749.97	13.8576
3752.96	14.7302
3755.95	15.5672
3758.93	16.0779
3761.91	16.1688
3764.9	15.8959
3767.88	15.4342
3770.86	15.2413
3773.84	15.7001
3776.81	16.4545
3779.79	17.55
3782.77	18.4673
3785.74	19.4306
3788.71	20.2341
3791.68	20.7601
3794.65	20.6169
3797.62	20.2272
3800.59	20.058
3803.56	19.9998
3806.52	20.3989
3809.49	21.026
3812.45	21.5713
3815.41	21.9685
3818.37	22.3601
3821.33	22.9695
3824.29	23.3147
3827.25	23.5247
3830.21	24.2688
3833.16	25.1113
3836.11	25.6072
3839.07	25.8343
3842.02	25.489
3844.97	25.0158
3847.92	24.5682
3850.87	24.1157
3853.81	23.6573
3856.76	23.6218
3859.7	23.6571
3862.65	24.2087
3865.59	25.1243
3868.53	25.832
3871.47	25.8756
3874.41	25.8983
3877.34	25.8385
3880.28	25.7734
3883.22	25.9192
3886.15	26.4219
3889.08	26.8432
3892.01	27.1159
3894.94	26.8342
3897.87	26.5839
3900.8	26.1705
3903.73	25.7234
3906.65	25.6569
3909.58	25.3195
3912.5	25.1366
3915.42	25.0142
3918.35	24.7699
3921.27	24.6224
3924.18	24.3544
3927.1	23.6679
3930.02	23.0416
3932.93	22.6433
3935.85	22.4444
3938.76	22.4214
3941.67	22.3796
3944.58	22.5406
3947.49	22.5114
3950.4	22.7166
3953.31	22.2444
3956.22	21.5156
3959.12	20.3989
3962.02	18.8722
3964.93	17.5877
3967.83	16.2506
3970.73	15.2411
3973.63	14.363
3976.53	13.6867
3979.42	13.1991
3982.32	12.7494
3985.21	12.326
3988.11	10.8025
3991	8.46443
3993.89	6.11533
3996.78	8.21115
3999.67	5.90535