File: Data/3-Raman/maps/burangaite-Ph1_BU22C_150 (500nm)_633nm_Edge_100%_x50_VIS_LWD_H100um_20sX2.txt
#Acq. time (s)=	20
#Accumulations=	2
#Range (cm-¹)=	100...4000
#Windows=	1
#Auto scanning=	Off
#Autofocus=	Off
#Macrospot=	Off
#AutoExposure=	Off
#Spike filter=	Multiple accum.
#Delay time (s)=	1
#Binning=	1
#Readout mode=	Signal
#DeNoise=	Standard
#ICS correction=	On
#Dark correction=	Off
#Inst. Process=	On
#Detector Gain=	Best Dynamic
#Detector ADC=	50 kHz HS
#Detector temperature (°C)=	-60.09
#Instrument=	LabRAM HR Evol
#Detector=	SIN-EM FIVIS
#Objective=	x50_VIS_LWD
#Grating=	150 (500nm)
#ND Filter=	100%
#Laser=	633nm_Edge
#Hole=	100.021
#Temperature=	0
#Range=	Visible
#StageXY=	75x50mm Scan+
#StageZ=	Z motor
#X (µm)=	0
#Y (µm)=	0
#Z (µm)=	130.6
#Project=	20_05_08
#Sample=	BU20
#Site=
#Title=	burangaite-Ph1_BU22C_150 (500nm)_633nm_Edge_100%_x50_VIS_LWD_H100um_20sX2
#Remark=
#Date=	08.05.2020 18:21
#Acquired=	08.05.2020 18:21:43
#Data Range:Extract=	06.04.2022 14:33:06
#Base:Fit=	06.04.2022 14:33:15
#Base:Edit=	06.04.2022 14:35:29
#Base:Edit=	06.04.2022 14:35:32
#Base:Edit=	06.04.2022 14:35:33
#Base:Edit=	06.04.2022 14:35:33
#Base:Edit=	06.04.2022 14:35:34
#Base:Edit=	06.04.2022 14:35:34
#Base:Sub=	06.04.2022 14:35:37
#Correction:Shift=	06.04.2022 14:44:50
103.773	666.378
110.286	359.453
116.795	130.956
123.297	46.4441
129.795	155.256
136.287	254.022
142.774	280.847
149.255	257.227
155.731	188.89
162.201	14.9824
168.667	-156.666
175.125	-196.688
181.58	-91.2678
188.029	128.323
194.473	292.858
200.911	338.673
207.343	461.615
213.771	346.536
220.194	245.636
226.611	284.622
233.022	543.867
239.429	752.907
245.83	577.282
252.225	300.672
258.616	168.392
265	157.372
271.381	260.696
277.756	315.826
284.125	332.25
290.489	342.171
296.848	405.12
303.202	587.968
309.55	919.609
315.894	1168.15
322.231	1347.63
328.563	1429.66
334.892	1443.53
341.213	1366.05
347.53	1219.9
353.843	997.102
360.149	706.957
366.451	559.728
372.748	491.505
379.039	448.891
385.325	360.139
391.605	232.475
397.881	125.499
404.153	54.2773
410.418	34.5688
416.678	43.4915
422.933	70.4365
429.183	112.273
435.428	161.126
441.668	237.33
447.903	333.151
454.133	438.735
460.358	582.739
466.577	765.97
472.792	929.703
479.001	1058.4
485.206	1184.67
491.406	1296.16
497.6	1383.36
503.788	1398.44
509.973	1317.8
516.152	1165.33
522.327	982.099
528.496	818.273
534.659	682.299
540.819	562.911
546.974	450.388
553.123	363.185
559.267	321.86
565.406	331.446
571.54	400.277
577.669	525.627
583.794	766.005
589.913	749.776
596.028	610.798
602.137	498.931
608.242	462.352
614.341	499.609
620.436	627.374
626.526	760.542
632.611	779.516
638.691	616.536
644.765	457.532
650.836	332.362
656.901	260.811
662.961	201.072
669.018	163.563
675.068	133.077
681.113	94.7993
687.154	51.6237
693.191	-0.600586
699.222	-35.4156
705.248	-60.0065
711.269	-62.5637
717.286	-64.2461
723.298	-58.6621
729.305	-50.7692
735.307	-39.933
741.305	-32.696
747.298	-19.5583
753.286	-7.70667
759.269	2.80859
765.246	13.8848
771.219	27.1265
777.188	42.4971
783.152	50.2729
789.112	79.7699
795.066	113.046
801.016	153.265
806.961	194.51
812.901	216.402
818.836	223.188
824.767	215.215
830.694	202.997
836.614	198.947
842.531	199.805
848.443	208.67
854.35	217.947
860.253	218.656
866.151	212.498
872.043	198.246
877.932	177.964
883.815	158.873
889.695	141.266
895.569	127.373
901.439	118.196
907.304	112.324
913.165	110.01
919.02	110.808
924.871	117.521
930.718	133.449
936.56	157.478
942.397	192.274
948.23	236.075
954.058	290.345
959.881	380.702
965.7	591.908
971.515	754.473
977.325	886.82
983.13	962.24
988.93	1022.26
994.726	1133.88
1000.52	1453.11
1006.3	1963.38
1012.09	2279.07
1017.87	2109.53
1023.64	2136.28
1029.41	2325.42
1035.17	2156.79
1040.93	1950.45
1046.69	1835.74
1052.44	1716.26
1058.18	1571.47
1063.92	1424.19
1069.66	1281.85
1075.39	1129.67
1081.12	949.549
1086.85	828.717
1092.56	672.778
1098.28	615.411
1103.99	534.359
1109.7	530.314
1115.4	598.058
1121.09	667.726
1126.79	691.426
1132.47	632.027
1138.16	515.021
1143.84	393.718
1149.51	319.465
1155.18	268.801
1160.85	235.052
1166.51	213.391
1172.17	192.167
1177.82	206.835
1183.47	256.049
1189.11	301.314
1194.75	305.033
1200.38	274.2
1206.01	258.424
1211.64	256.516
1217.26	248.591
1222.88	224.1
1228.49	184.955
1234.1	143.697
1239.71	103.446
1245.31	63.0647
1250.9	30.9678
1256.5	9.83447
1262.08	-1.62195
1267.67	-7.57593
1273.24	-7.47644
1278.82	-3.38098
1284.39	0.217041
1289.95	2.8446
1295.51	4.18494
1301.07	4.45776
1306.62	3.73743
1312.17	1.75964
1317.72	2.44287
1323.26	1.35889
1328.79	-0.0378418
1334.32	-7.40918
1339.85	-4.91614
1345.38	2.49792
1350.89	15.1586
1356.41	35.7533
1361.92	49.5654
1367.42	47.5144
1372.93	50.4396
1378.42	51.3287
1383.92	50.6512
1389.41	48.332
1394.89	44.7539
1400.37	40.7463
1405.85	38.5337
1411.32	35.2581
1416.79	28.9235
1422.25	24.8245
1427.71	21.8563
1433.17	19.8843
1438.62	17.2178
1444.07	14.4657
1449.51	13.8165
1454.95	12.3721
1460.38	7.922
1465.81	1.47058
1471.24	-3.07739
1476.66	-5.39954
1482.08	-7.26196
1487.49	-8.58521
1492.9	-6.69983
1498.31	-2.59875
1503.71	-0.439697
1509.11	0
1514.5	0.70166
1519.89	3.30713
1525.28	8.78894
1530.66	16.485
1536.03	25.3055
1541.41	35.7693
1546.78	45.4276
1552.14	51.9023
1557.5	54.7474
1562.86	56.5919
1568.21	59.5127
1573.56	60.3678
1578.91	60.0601
1584.25	58.9249
1589.58	55.4042
1594.92	46.8862
1600.24	39.4741
1605.57	30.7833
1610.89	22.5579
1616.2	17.3672
1621.52	13.1196
1626.83	8.0968
1632.13	4.38416
1637.43	1.57642
1642.73	-3.17932
1648.02	-7.57507
1653.31	-10.2339
1658.59	-10.8164
1663.87	-9.58032
1669.15	-7.0249
1674.42	-7.16156
1679.69	-8.77454
1684.95	-11.2475
1690.22	-14.8686
1695.47	-14.9963
1700.73	-13.9369
1705.97	-13.576
1711.22	-12.8987
1716.46	-11.936
1721.7	-11.8372
1726.93	-14.9258
1732.16	-18.0915
1737.38	-21.2424
1742.61	-24.0155
1747.82	-27.4637
1753.04	-30.9023
1758.25	-34.1459
1763.45	-36.4404
1768.65	-38.5338
1773.85	-39.8848
1779.05	-40.4086
1784.24	-40.3872
1789.42	-40.2263
1794.6	-40.2084
1799.78	-40.3166
1804.96	-40.8097
1810.13	-41.9377
1815.3	-43.4116
1820.46	-44.7469
1825.62	-46.3579
1830.77	-47.017
1835.93	-45.9502
1841.07	-44.8481
1846.22	-42.4603
1851.36	-37.8621
1856.49	-33.5604
1861.63	-28.9739
1866.76	-24.3522
1871.88	-19.8036
1877	-16.9774
1882.12	-14.7811
1887.23	-11.8146
1892.34	-10.0168
1897.45	-10.0038
1902.55	-11.4135
1907.65	-14.6345
1912.74	-17.2385
1917.84	-18.3372
1922.92	-17.6091
1928.01	-15.3633
1933.09	-11.5206
1938.16	-7.83112
1943.23	-6.72797
1948.3	-9.21997
1953.37	-10.1107
1958.43	-10.1349
1963.49	-9.80933
1968.54	-8.47144
1973.59	-6.27203
1978.63	-2.18304
1983.68	-0.464783
1988.72	-0.164856
1993.75	-2.25873
1998.78	-8.72101
2003.81	-11.4533
2008.83	-10.2808
2013.85	-6.64166
2018.87	-1.52222
2023.88	5.21051
2028.89	10.7162
2033.9	14.6428
2038.9	17.7502
2043.9	20.8199
2048.89	25.0548
2053.88	27.6495
2058.87	23.6343
2063.85	20.3624
2068.83	17.8851
2073.81	16.4628
2078.78	16.2903
2083.75	17.6939
2088.72	20.8029
2093.68	26.2845
2098.64	32.6402
2103.59	37.1871
2108.54	39.8538
2113.49	42.291
2118.43	48.9073
2123.37	50.0906
2128.31	49.4536
2133.24	47.9325
2138.17	42.2809
2143.1	40.8244
2148.02	38.3942
2152.94	36.4423
2157.85	34.9329
2162.77	31.2853
2167.67	27.8209
2172.58	24.2968
2177.48	20.739
2182.38	17.0324
2187.27	15.5341
2192.16	16.218
2197.05	15.7281
2201.93	14.5722
2206.81	11.8111
2211.68	8.65863
2216.56	7.54169
2221.43	6.86066
2226.29	5.77539
2231.15	3.84747
2236.01	1.9444
2240.87	2.48096
2245.72	-0.156616
2250.57	-3.14978
2255.41	-10.5938
2260.25	-8.54907
2265.09	-2.16815
2269.92	3.68726
2274.75	4.96899
2279.58	-3.84955
2284.4	-11.8238
2289.22	-18.5712
2294.04	-23.2365
2298.85	-25.0523
2303.66	-24.0621
2308.47	-20.254
2313.27	-15.1845
2318.07	-11.1684
2322.87	-10.4372
2327.66	-11.3517
2332.45	-12.2075
2337.23	-13.8585
2342.01	-16.3234
2346.79	-20.2261
2351.57	-23.1521
2356.34	-24.6144
2361.11	-25.3448
2365.87	-25.1337
2370.64	-23.7204
2375.39	-22.1649
2380.15	-21.6088
2384.9	-22.6425
2389.65	-24.3339
2394.39	-26.02
2399.13	-26.3163
2403.87	-28.0478
2408.61	-29.6285
2413.34	-29.3196
2418.06	-27.2902
2422.79	-23.6953
2427.51	-20.5557
2432.23	-17.1471
2436.94	-13.7006
2441.65	-11.0391
2446.36	-10.2548
2451.06	-11.2826
2455.77	-13.2462
2460.46	-15.385
2465.16	-17.406
2469.85	-18.941
2474.54	-19.4212
2479.22	-17.8827
2483.9	-19.5185
2488.58	-23.7632
2493.25	-28.215
2497.92	-31.3397
2502.59	-33.243
2507.26	-34.3809
2511.92	-34.6583
2516.57	-32.8067
2521.23	-30.225
2525.88	-29.2308
2530.53	-31.317
2535.17	-35.0223
2539.81	-37.8715
2544.45	-39.1685
2549.09	-40.1213
2553.72	-40.8225
2558.35	-39.4548
2562.97	-37.6196
2567.59	-35.5489
2572.21	-33.7054
2576.83	-32.0709
2581.44	-30.6744
2586.05	-29.1915
2590.65	-27.549
2595.25	-25.7819
2599.85	-23.7333
2604.45	-22.4085
2609.04	-20.9852
2613.63	-18.1648
2618.22	-14.5923
2622.8	-12.6868
2627.38	-14.5062
2631.95	-22.1478
2636.53	-26.4255
2641.1	-28.8173
2645.67	-29.5396
2650.23	-27.0717
2654.79	-24.442
2659.35	-22.234
2663.9	-21.8268
2668.45	-22.787
2673	-22.8976
2677.54	-20.6515
2682.08	-18.7352
2686.62	-18.538
2691.16	-19.4402
2695.69	-22.0864
2700.22	-24.9178
2704.74	-25.3578
2709.27	-24.7948
2713.78	-24.1212
2718.3	-23.816
2722.81	-24.4942
2727.32	-27.1188
2731.83	-28.6838
2736.33	-28.4799
2740.83	-29.2883
2745.33	-31.3
2749.82	-33.8331
2754.32	-36.7459
2758.8	-39.871
2763.29	-43.907
2767.77	-44.4048
2772.25	-42.5154
2776.72	-37.4614
2781.2	-31.6556
2785.67	-29.1702
2790.13	-28.8262
2794.59	-28.1089
2799.05	-28.9634
2803.51	-33.7023
2807.96	-38.0894
2812.41	-41.3196
2816.86	-43.3391
2821.31	-43.9913
2825.75	-43.7138
2830.19	-42.9736
2834.62	-41.4962
2839.05	-40.0855
2843.48	-40.4418
2847.91	-44.1471
2852.33	-48.5053
2856.75	-49.7043
2861.17	-47.5861
2865.58	-44.1023
2869.99	-40.1621
2874.4	-36.3355
2878.81	-32.7165
2883.21	-30.0298
2887.61	-28.8125
2892	-30.3883
2896.4	-31.3255
2900.78	-28.8214
2905.17	-24.7086
2909.56	-21.8055
2913.94	-20.0779
2918.31	-19.7974
2922.69	-21.9017
2927.06	-24.7163
2931.43	-25.6114
2935.79	-26.4622
2940.16	-28.9283
2944.52	-30.5599
2948.87	-29.6621
2953.23	-25.4094
2957.58	-20.317
2961.92	-18.769
2966.27	-18.2136
2970.61	-18.0942
2974.95	-18.2256
2979.29	-18.5815
2983.62	-18.9598
2987.95	-19.0271
2992.28	-17.0422
2996.6	-13.7181
3000.92	-10.6543
3005.24	-9.30832
3009.55	-8.36337
3013.87	-5.62125
3018.18	-2.5062
3022.48	0.36731
3026.78	3.48526
3031.09	6.77307
3035.38	9.22278
3039.68	9.1456
3043.97	6.98318
3048.26	0.499023
3052.54	-2.6857
3056.83	-2.44672
3061.11	1.00137
3065.39	6.35321
3069.66	12.2936
3073.93	16.3489
3078.2	16.8567
3082.46	15.968
3086.73	14.1412
3090.99	12.2452
3095.24	10.2447
3099.5	8.57214
3103.75	7.73148
3108	8.33673
3112.24	10.1291
3116.49	13.3426
3120.73	16.9449
3124.96	19.2254
3129.2	22.0653
3133.43	24.8473
3137.66	25.2911
3141.88	22.6447
3146.1	23.6446
3150.32	25.7212
3154.54	27.6033
3158.75	29.4809
3162.97	31.7642
3167.17	37.0132
3171.38	42.1579
3175.58	44.3812
3179.78	47.5694
3183.98	52.085
3188.17	57.6057
3192.36	64.449
3196.55	77.5121
3200.74	97.8598
3204.92	127.099
3209.1	160.982
3213.28	199.004
3217.45	242.079
3221.63	285.039
3225.79	319.958
3229.96	346.564
3234.12	362.532
3238.28	367.128
3242.44	359.843
3246.6	342.462
3250.75	318.549
3254.9	288.808
3259.05	260.508
3263.19	235.125
3267.33	212.434
3271.47	192.431
3275.6	174.558
3279.74	155.622
3283.87	134.831
3288	112.365
3292.12	87.1628
3296.24	65.2445
3300.36	48.4758
3304.48	36.6244
3308.59	31.4873
3312.7	29.7363
3316.81	27.7043
3320.92	25.3226
3325.02	22.3881
3329.12	18.6038
3333.21	14.0139
3337.31	8.88486
3341.4	3.22858
3345.49	-1.47476
3349.58	-2.71069
3353.66	-5.69946
3357.74	-2.96811
3361.82	-0.194244
3365.9	3.16547
3369.97	7.97314
3374.04	10.3268
3378.11	8.39734
3382.17	2.83127
3386.23	-0.942139
3390.29	-3.11926
3394.35	-4.43979
3398.4	-3.87476
3402.45	-2.25134
3406.5	-2.79803
3410.55	-5.46887
3414.59	-10.1028
3418.63	-15.2649
3422.67	-21.2962
3426.71	-0.362183
3430.74	-9.5311
3434.77	-24.3846
3438.8	-27.1538
3442.82	-29.4923
3446.84	-32.4544
3450.86	-34.4106
3454.88	-34.5453
3458.89	-33.2744
3462.9	-30.9468
3466.91	-28.8418
3470.92	-27.8506
3474.92	-27.9149
3478.92	-28.5026
3482.92	-29.7895
3486.92	-31.964
3490.91	-41.1992
3494.9	-36.9556
3498.89	-30.5831
3502.88	-28.7622
3506.86	-29.1908
3510.84	-31.637
3514.82	-35.5644
3518.79	-39.7348
3522.76	-42.9066
3526.73	-44.5968
3530.7	-44.3017
3534.66	-42.4073
3538.63	-39.7974
3542.58	-37.4984
3546.54	-35.1834
3550.5	-33.33
3554.45	-31.9249
3558.4	-31.0967
3562.34	-31.1812
3566.29	-30.5085
3570.23	-28.5498
3574.17	-26.2363
3578.1	-17.8876
3582.04	-23.9628
3585.97	-7.85864
3589.89	8.75089
3593.82	52.8171
3597.74	169.759
3601.66	236.235
3605.58	252.595
3609.5	293.449
3613.41	303.112
3617.32	265.85
3621.23	160.64
3625.13	68.617
3629.04	10.9388
3632.94	-20.5183
3636.84	-24.3962
3640.73	-28.8305
3644.62	-29.5747
3648.51	-31.5491
3652.4	-34.9694
3656.29	-38.375
3660.17	-41.1603
3664.05	-42.9112
3667.93	-43.766
3671.8	-43.0589
3675.68	-40.177
3679.55	-35.7674
3683.41	-32.8495
3687.28	-32.9808
3691.14	-36.0322
3695	-40.0704
3698.86	-42.0702
3702.71	-42.5765
3706.57	-42.2855
3710.42	-39.3064
3714.27	-35.96
3718.11	-33.5264
3721.95	-32.3817
3725.79	-32.0746
3729.63	-32.3583
3733.47	-33.1379
3737.3	-33.7215
3741.13	-34.9479
3744.96	-36.1299
3748.78	-34.499
3752.61	-32.3127
3756.43	-30.7583
3760.25	-29.7744
3764.06	-29.25
3767.88	-29.0727
3771.69	-29.279
3775.5	-31.6016
3779.3	-34.1164
3783.1	-34.4721
3786.91	-32.9914
3790.7	-31.0297
3794.5	-29.3712
3798.29	-28.0293
3802.08	-26.8954
3805.87	-25.9942
3809.66	-25.5522
3813.44	-25.7697
3817.23	-26.9619
3821.01	-28.8729
3824.78	-30.729
3828.56	-32.3348
3832.33	-31.9056
3836.1	-31.3528
3839.87	-29.9901
3843.63	-28.5841
3847.39	-28.072
3851.15	-28.8894
3854.91	-31.0083
3858.67	-31.6911
3862.42	-29.7507
3866.17	-26.7673
3869.92	-25.2651
3873.66	-25.7679
3877.41	-27.6352
3881.15	-30.528
3884.89	-32.2855
3888.62	-32.8017
3892.36	-32.4697
3896.09	-32.3836
3899.82	-33.9755
3903.54	-35.2214
3907.27	-36.8631
3910.99	-39.721
3914.71	-40.9992
3918.43	-41.4108
3922.14	-41.7673
3925.85	-41.2213
3929.56	-40.6873
3933.27	-40.7406
3936.98	-42.0564
3940.68	-44.7727
3944.38	-47.0249
3948.08	-49.71
3951.78	-54.1108
3955.47	-58.6739
3959.16	-61.9819
3962.85	-62.7858
3966.54	-63.3388
3970.22	-64.8248
3973.9	-67.2133
3977.58	-70.2945
3981.26	-74.3445
3984.94	-79.8908
3988.61	-87.2255
3992.28	-92.6915
3995.95	-96.99
3999.61	-104.674