File: Data/3-Raman/maps/burangaite2-Ph1_BU22C_150 (500nm)_633nm_Edge_100%_x50_VIS_LWD_H100um_20sX2.txt
#Acq. time (s)=	20
#Accumulations=	2
#Range (cm-¹)=	100...4000
#Windows=	1
#Auto scanning=	Off
#Autofocus=	Off
#Macrospot=	Off
#AutoExposure=	Off
#Spike filter=	Multiple accum.
#Delay time (s)=	1
#Binning=	1
#Readout mode=	Signal
#DeNoise=	Standard
#ICS correction=	On
#Dark correction=	Off
#Inst. Process=	On
#Detector Gain=	Best Dynamic
#Detector ADC=	50 kHz HS
#Detector temperature (°C)=	-60.09
#Instrument=	LabRAM HR Evol
#Detector=	SIN-EM FIVIS
#Objective=	x50_VIS_LWD
#Grating=	150 (500nm)
#ND Filter=	100%
#Laser=	633nm_Edge
#Hole=	100.021
#Temperature=	0
#Range=	Visible
#StageXY=	75x50mm Scan+
#StageZ=	Z motor
#X (µm)=	0
#Y (µm)=	0
#Z (µm)=	135.8
#Project=	20_05_08
#Sample=	BU20
#Site=
#Title=	burangaite2-Ph1_BU22C_150 (500nm)_633nm_Edge_100%_x50_VIS_LWD_H100um_20sX2
#Remark=
#Date=	08.05.2020 18:30
#Acquired=	08.05.2020 18:30:01
#Data Range:Extract=	06.04.2022 14:33:06
#Base:Fit=	06.04.2022 14:33:15
#Base:Edit=	06.04.2022 14:34:43
#Base:Edit=	06.04.2022 14:34:44
#Base:Edit=	06.04.2022 14:34:47
#Base:Edit=	06.04.2022 14:34:50
#Base:Edit=	06.04.2022 14:34:51
#Base:Edit=	06.04.2022 14:34:52
#Base:Edit=	06.04.2022 14:34:52
#Base:Edit=	06.04.2022 14:34:53
#Base:Sub=	06.04.2022 14:34:54
#Correction:Shift=	06.04.2022 14:44:50
103.773	578.808
110.286	492.871
116.795	316.189
123.297	154.021
129.795	98.0259
136.287	89.5214
142.774	82.7435
149.255	53.1254
155.731	5.74194
162.201	-61.5614
168.667	-122.061
175.125	-140.472
181.58	-113.121
188.029	-65.5913
194.473	16.5704
200.911	101.533
207.343	139.816
213.771	148.341
220.194	153.302
226.611	188.151
233.022	332.233
239.429	575.083
245.83	480.501
252.225	150.292
258.616	90.7406
265	193.414
271.381	377.468
277.756	587.467
284.125	521.06
290.489	390.598
296.848	292.719
303.202	346.751
309.55	471.564
315.894	587.161
322.231	679.176
328.563	731.677
334.892	734.6
341.213	677.903
347.53	587.167
353.843	676.673
360.149	627.256
366.451	550.644
372.748	573.171
379.039	681.126
385.325	807.731
391.605	709.328
397.881	476.225
404.153	289.921
410.418	177.041
416.678	117.627
422.933	95.1062
429.183	96.4991
435.428	118.093
441.668	153.182
447.903	190.273
454.133	239.104
460.358	317.191
466.577	445.723
472.792	559.654
479.001	588.105
485.206	595.258
491.406	604.86
497.6	616.972
503.788	582.976
509.973	532.486
516.152	470.133
522.327	408.681
528.496	349.974
534.659	291.775
540.819	239.79
546.974	173.234
553.123	109.188
559.267	92.5217
565.406	180.024
571.54	282.354
577.669	494.099
583.794	777.444
589.913	918.666
596.028	823.299
602.137	613.873
608.242	449.332
614.341	380.073
620.436	436.824
626.526	531.693
632.611	529.631
638.691	417.842
644.765	259.707
650.836	142.939
656.901	93.4838
662.961	68.1742
669.018	48.3495
675.068	30.0341
681.113	13.0823
687.154	-3.09839
693.191	-16.8328
699.222	-27.7549
705.248	-36.6896
711.269	-43.2825
717.286	-46.2985
723.298	-42.433
729.305	-32.1688
735.307	-17.5031
741.305	-2.3197
747.298	8.88416
753.286	14.7529
759.269	16.9634
765.246	19.5961
771.219	24.6296
777.188	33.1207
783.152	45.3401
789.112	61.0873
795.066	78.7186
801.016	95.4446
806.961	109.498
812.901	119.609
818.836	126.057
824.767	129.968
830.694	134.023
836.614	139.969
842.531	148.175
848.443	158.328
854.35	169.946
860.253	180.638
866.151	186.083
872.043	185.128
877.932	178.234
883.815	169.074
889.695	160.248
895.569	153.362
901.439	149.205
907.304	149.083
913.165	154.901
919.02	166.929
924.871	185.505
930.718	208.948
936.56	238.833
942.397	280.999
948.23	340.447
954.058	441.369
959.881	620.89
965.7	875.979
971.515	1089.62
977.325	1168.27
983.13	1166.24
988.93	1152.03
994.726	1345.5
1000.52	1773.99
1006.3	2437.79
1012.09	2679.67
1017.87	2424.55
1023.64	2509.7
1029.41	2887.27
1035.17	2476.67
1040.93	1719.8
1046.69	1299.55
1052.44	1100.07
1058.18	952.905
1063.92	846.144
1069.66	768.412
1075.39	711.867
1081.12	664.557
1086.85	615.647
1092.56	554.991
1098.28	476.5
1103.99	408.192
1109.7	385.116
1115.4	398.656
1121.09	441.166
1126.79	463.779
1132.47	449.676
1138.16	414.86
1143.84	368.109
1149.51	321.359
1155.18	281.498
1160.85	250.326
1166.51	229.509
1172.17	219.642
1177.82	219.751
1183.47	226.643
1189.11	232.331
1194.75	231.06
1200.38	221.855
1206.01	208.161
1211.64	196.551
1217.26	186.322
1222.88	174.069
1228.49	157.268
1234.1	136.07
1239.71	113.146
1245.31	92.2287
1250.9	74.8792
1256.5	62.1715
1262.08	54.2293
1267.67	50.5169
1273.24	49.4439
1278.82	49.2715
1284.39	49.1666
1289.95	48.308
1295.51	45.9686
1301.07	43.0933
1306.62	40.923
1312.17	40.7664
1317.72	43.1599
1323.26	46.668
1328.79	49.2204
1334.32	49.3064
1339.85	47.6142
1345.38	44.4167
1350.89	40.1789
1356.41	36.9039
1361.92	36.1344
1367.42	38.2356
1372.93	41.733
1378.42	44.2408
1383.92	44.2209
1389.41	42.6204
1394.89	40.9704
1400.37	40.2529
1405.85	40.2318
1411.32	40.18
1416.79	40.2764
1422.25	41.2471
1427.71	42.1546
1433.17	41.9339
1438.62	40.5167
1444.07	38.3665
1449.51	35.7128
1454.95	32.6886
1460.38	29.0771
1465.81	25.7506
1471.24	23.7348
1476.66	22.7254
1482.08	21.1911
1487.49	18.3276
1492.9	14.6691
1498.31	11.5958
1503.71	9.93665
1509.11	10.5363
1514.5	13.27
1519.89	17.7067
1525.28	22.627
1530.66	24.4039
1536.03	22.5247
1541.41	18.9516
1546.78	16.7551
1552.14	17.5823
1557.5	20.8854
1562.86	24.7485
1568.21	27.435
1573.56	28.1813
1578.91	27.0717
1584.25	24.1152
1589.58	19.204
1594.92	12.8671
1600.24	6.5741
1605.57	2.15332
1610.89	0.297424
1616.2	0
1621.52	0.775208
1626.83	2.14227
1632.13	3.28748
1637.43	3.01599
1642.73	1.14661
1648.02	-1.47369
1653.31	-4.2196
1658.59	-6.36292
1663.87	-7.53723
1669.15	-7.01135
1674.42	-4.39056
1679.69	-0.87384
1684.95	1.2774
1690.22	0.940674
1695.47	-0.577637
1700.73	-0.952576
1705.97	-0.492798
1711.22	0.209656
1716.46	0.846802
1721.7	1.95667
1726.93	3.03601
1732.16	2.72406
1737.38	-0.672058
1742.61	-5.0589
1747.82	-8.27704
1753.04	-9.84912
1758.25	-10.6101
1763.45	-11.3089
1768.65	-13.2955
1773.85	-15.9846
1779.05	-18.9849
1784.24	-21.187
1789.42	-21.1169
1794.6	-18.5905
1799.78	-14.91
1804.96	-11.5572
1810.13	-9.58661
1815.3	-9.11768
1820.46	-9.17572
1825.62	-9.43341
1830.77	-9.21252
1835.93	-8.32849
1841.07	-6.92169
1846.22	-5.99469
1851.36	-5.96289
1856.49	-5.78064
1861.63	-4.625
1866.76	-1.87714
1871.88	1.92383
1877	6.94318
1882.12	12.3442
1887.23	15.8141
1892.34	15.5293
1897.45	12.425
1902.55	9.42139
1907.65	8.55725
1912.74	9.62433
1917.84	11.8911
1922.92	14.899
1928.01	17.7831
1933.09	19.4116
1938.16	19.878
1943.23	20.0306
1948.3	21.1515
1953.37	23.3973
1958.43	25.8899
1963.49	27.4879
1968.54	28.0055
1973.59	28.1707
1978.63	27.9886
1983.68	28.0296
1988.72	28.3228
1993.75	29.1669
1998.78	30.4591
2003.81	33.0039
2008.83	35.6545
2013.85	38.0747
2018.87	39.1741
2023.88	39.5613
2028.89	39.3659
2033.9	38.8516
2038.9	38.5427
2043.9	40.0218
2048.89	42.5487
2053.88	46.1764
2058.87	50.6784
2063.85	55.1441
2068.83	58.9793
2073.81	62.1472
2078.78	64.1882
2083.75	64.4386
2088.72	62.5626
2093.68	60.336
2098.64	59.7097
2103.59	61.533
2108.54	64.7452
2113.49	68.1119
2118.43	70.751
2123.37	71.7981
2128.31	70.9695
2133.24	69.4761
2138.17	68.8978
2143.1	70.352
2148.02	72.8405
2152.94	74.6638
2157.85	75.0039
2162.77	74.1107
2167.67	72.5489
2172.58	70.7114
2177.48	69.1778
2182.38	68.699
2187.27	68.919
2192.16	68.8289
2197.05	67.298
2201.93	65.5579
2206.81	64.5752
2211.68	64.5685
2216.56	65.6552
2221.43	67.9066
2226.29	71.0836
2231.15	73.7085
2236.01	74.8585
2240.87	73.9535
2245.72	71.3172
2250.57	68.3713
2255.41	66.3187
2260.25	65.4243
2265.09	65.733
2269.92	67.0445
2274.75	67.7451
2279.58	66.8738
2284.4	64.4013
2289.22	61.5269
2294.04	59.3382
2298.85	58.8257
2303.66	59.7752
2308.47	60.8581
2313.27	60.9346
2318.07	59.442
2322.87	56.9786
2327.66	54.6211
2332.45	54.6363
2337.23	55.4491
2342.01	56.3782
2346.79	56.9507
2351.57	57.0175
2356.34	57.0421
2361.11	56.8294
2365.87	56.1189
2370.64	54.8823
2375.39	54.4586
2380.15	54.4792
2384.9	54.1706
2389.65	53.319
2394.39	52.4045
2399.13	51.7191
2403.87	51.0944
2408.61	50.1723
2413.34	48.7313
2418.06	46.4816
2422.79	44.4167
2427.51	44.1487
2432.23	46.4377
2436.94	48.5707
2441.65	48.2759
2446.36	45.7332
2451.06	43.9008
2455.77	43.2861
2460.46	42.2738
2465.16	40.3365
2469.85	38.6574
2474.54	38.3443
2479.22	39.6824
2483.9	41.4063
2488.58	41.7272
2493.25	39.5923
2497.92	35.3763
2502.59	31.2637
2507.26	29.2622
2511.92	30.139
2516.57	32.758
2521.23	34.9902
2525.88	36.1981
2530.53	37.8124
2535.17	40.5154
2539.81	47.0315
2544.45	31.3197
2549.09	16.8853
2553.72	25.4569
2558.35	31.395
2562.97	34.7131
2567.59	36.277
2572.21	36.537
2576.83	36.1418
2581.44	34.5679
2586.05	32.7418
2590.65	31.2473
2595.25	30.3864
2599.85	30.5875
2604.45	31.0504
2609.04	31.6153
2613.63	32.2048
2618.22	32.3666
2622.8	31.9569
2627.38	31.5915
2631.95	31.1496
2636.53	30.7912
2641.1	30.7449
2645.67	31.4267
2650.23	31.378
2654.79	29.9249
2659.35	28.1019
2663.9	26.3723
2668.45	24.4704
2673	22.1392
2677.54	20.0087
2682.08	19.5854
2686.62	21.4124
2691.16	23.6989
2695.69	25.2174
2700.22	25.7138
2704.74	25.7072
2709.27	24.9788
2713.78	23.1262
2718.3	20.186
2722.81	18.3322
2727.32	18.377
2731.83	18.2903
2736.33	17.4099
2740.83	16.2937
2745.33	14.8935
2749.82	13.0309
2754.32	11.3353
2758.8	8.88263
2763.29	6.06793
2767.77	5.64319
2772.25	8.72083
2776.72	13.4568
2781.2	18.278
2785.67	20.6894
2790.13	21.2309
2794.59	19.7284
2799.05	15.7327
2803.51	13.841
2807.96	10.5511
2812.41	8.49783
2816.86	9.91373
2821.31	11.8801
2825.75	13.6978
2830.19	15.0982
2834.62	16.0902
2839.05	16.9021
2843.48	17.7305
2847.91	18.6393
2852.33	20.4159
2856.75	22.3844
2861.17	23.2342
2865.58	23.3897
2869.99	23.0762
2874.4	22.5326
2878.81	21.6816
2883.21	20.8575
2887.61	20.9054
2892	23.6577
2896.4	26.6535
2900.78	28.0486
2905.17	29.4044
2909.56	31.2115
2913.94	32.7553
2918.31	34.0654
2922.69	34.7697
2927.06	35.3187
2931.43	36.8104
2935.79	36.5795
2940.16	34.9955
2944.52	35.3212
2948.87	36.5003
2953.23	38.1323
2957.58	39.9388
2961.92	42.1425
2966.27	43.8067
2970.61	44.0099
2974.95	42.1314
2979.29	38.867
2983.62	36.4716
2987.95	36.7565
2992.28	37.7076
2996.6	38.2843
3000.92	38.9774
3005.24	40.8657
3009.55	43.1208
3013.87	42.8373
3018.18	42.6103
3022.48	43.3415
3026.78	44.9141
3031.09	47.6469
3035.38	50.7881
3039.68	54.1383
3043.97	56.8653
3048.26	58.9715
3052.54	60.8188
3056.83	63.1993
3061.11	65.6152
3065.39	69.6443
3069.66	74.7086
3073.93	80.1143
3078.2	82.3372
3082.46	80.8274
3086.73	77.9717
3090.99	75.9016
3095.24	74.5379
3099.5	73.8847
3103.75	76.1988
3108	77.2348
3112.24	77.8531
3116.49	77.5492
3120.73	75.6941
3124.96	72.9634
3129.2	73.212
3133.43	74.643
3137.66	76.6795
3141.88	80.0693
3146.1	84.4701
3150.32	88.987
3154.54	92.5873
3158.75	95.4903
3162.97	97.3683
3167.17	100.976
3171.38	105.221
3175.58	110.432
3179.78	116.537
3183.98	123.776
3188.17	132.374
3192.36	143.078
3196.55	155.68
3200.74	175.517
3204.92	205.756
3209.1	239.273
3213.28	285.122
3217.45	337.795
3221.63	395.081
3225.79	446.132
3229.96	490.633
3234.12	523.98
3238.28	542.917
3242.44	550.127
3246.6	543.277
3250.75	524.096
3254.9	496.816
3259.05	469.92
3263.19	444.903
3267.33	424.29
3271.47	398.364
3275.6	368.709
3279.74	335.094
3283.87	299.115
3288	263.599
3292.12	229.098
3296.24	195.823
3300.36	169.913
3304.48	162.947
3308.59	149.714
3312.7	133.793
3316.81	118.852
3320.92	105.532
3325.02	98.781
3329.12	92.957
3333.21	85.2678
3337.31	79.5282
3341.4	76.9903
3345.49	75.8236
3349.58	73.1607
3353.66	71.4219
3357.74	70.1297
3361.82	68.9442
3365.9	67.7487
3369.97	66.0042
3374.04	63.5662
3378.11	62.9276
3382.17	63.0977
3386.23	61.8852
3390.29	60.4437
3394.35	59.4571
3398.4	60.1122
3402.45	60.9886
3406.5	62.1435
3410.55	62.1606
3414.59	61.067
3418.63	58.0287
3422.67	53.2821
3426.71	47.405
3430.74	40.1571
3434.77	35.2416
3438.8	32.1783
3442.82	31.2943
3446.84	32.5135
3450.86	34.7354
3454.88	35.4339
3458.89	35.3535
3462.9	35.3147
3466.91	33.4511
3470.92	30.104
3474.92	25.4644
3478.92	21.5637
3482.92	19.8797
3486.92	18.1136
3490.91	16.9149
3494.9	17.5216
3498.89	20.3489
3502.88	24.2046
3506.86	25.8421
3510.84	25.9613
3514.82	23.1072
3518.79	18.9153
3522.76	10.1523
3526.73	7.69861
3530.7	8.51086
3534.66	12.8377
3538.63	17.5907
3542.58	19.2717
3546.54	22.3772
3550.5	22.2199
3554.45	19.3861
3558.4	18.9906
3562.34	23.2112
3566.29	29.7743
3570.23	39.2011
3574.17	51.1132
3578.1	56.2298
3582.04	77.6185
3585.97	101.886
3589.89	218.154
3593.82	517.335
3597.74	1046.19
3601.66	1187.23
3605.58	882.598
3609.5	781.274
3613.41	734.426
3617.32	575.789
3621.23	342.354
3625.13	152.197
3629.04	83.8116
3632.94	52.4338
3636.84	32.1969
3640.73	20.1169
3644.62	13.0293
3648.51	7.74506
3652.4	6.78545
3656.29	9.49471
3660.17	5.76756
3664.05	0.848312
3667.93	-6.89049
3671.8	-7.26064
3675.68	-7.03815
3679.55	-4.97223
3683.41	-1.1402
3687.28	3.44029
3691.14	9.12813
3695	9.04362
3698.86	2.7336
3702.71	-1.07631
3706.57	-4.13115
3710.42	-6.35959
3714.27	-7.69093
3718.11	-8.59082
3721.95	-8.66183
3725.79	-7.79741
3729.63	-6.00456
3733.47	-2.60547
3737.3	0.804001
3741.13	2.82765
3744.96	3.4584
3748.78	3.37495
3752.61	2.9404
3756.43	3.38914
3760.25	3.35818
3764.06	1.82664
3767.88	1.94666
3771.69	2.83981
3775.5	3.96977
3779.3	5.19429
3783.1	6.51479
3786.91	7.78754
3790.7	8.9644
3794.5	10.2575
3798.29	11.4373
3802.08	12.4359
3805.87	13.1985
3809.66	13.8678
3813.44	13.6219
3817.23	13.1434
3821.01	12.9253
3824.78	13.5582
3828.56	14.853
3832.33	16.7744
3836.1	19.1382
3839.87	21.7879
3843.63	24.5807
3847.39	26.8534
3851.15	27.4002
3854.91	22.9389
3858.67	19.4368
3862.42	20.9713
3866.17	17.0156
3869.92	19.5931
3873.66	25.5779
3877.41	28.0465
3881.15	27.9286
3884.89	26.5075
3888.62	27.7503
3892.36	29.3805
3896.09	31.0847
3899.82	32.7487
3903.54	34.4018
3907.27	35.9648
3910.99	37.8826
3914.71	39.6449
3918.43	41.0329
3922.14	41.4532
3925.85	40.5802
3929.56	38.7129
3933.27	37.0489
3936.98	38.4423
3940.68	39.4349
3944.38	40.4039
3948.08	42.075
3951.78	42.0796
3955.47	38.8111
3959.16	34.9862
3962.85	32.3596
3966.54	30.4659
3970.22	29.0732
3973.9	26.085
3977.58	24.477
3981.26	22.9786
3984.94	20.9592
3988.61	18.2014
3992.28	14.8497
3995.95	10.8966
3999.61	6.48312