File: Data/3-Raman/maps/burangaite_BU20C_150 (500nm)_633nm_Edge_100%_x100_VIS_H100um_20sX2.txt
#Acq. time (s)=	20
#Accumulations=	2
#Range (cm-¹)=	100...4000
#Windows=	1
#Auto scanning=	Off
#Autofocus=	Off
#Macrospot=	Off
#AutoExposure=	Off
#Spike filter=	Multiple accum.
#Delay time (s)=	1
#Binning=	1
#Readout mode=	Signal
#DeNoise=	Standard
#ICS correction=	On
#Dark correction=	Off
#Inst. Process=	On
#Detector Gain=	Best Dynamic
#Detector ADC=	50 kHz HS
#Detector temperature (°C)=	-60.09
#Instrument=	LabRAM HR Evol
#Detector=	SIN-EM FIVIS
#Objective=	x100_VIS
#Grating=	150 (500nm)
#ND Filter=	100%
#Laser=	633nm_Edge
#Hole=	100.021
#Temperature=	0
#Range=	Visible
#StageXY=	75x50mm Scan+
#StageZ=	Z motor
#X (µm)=	0
#Y (µm)=	0
#Z (µm)=	36.9
#Project=	20_05_08
#Sample=	BU20
#Site=
#Title=	burangaite_BU20C_150 (500nm)_633nm_Edge_100%_x100_VIS_H100um_20sX2
#Remark=
#Date=	08.05.2020 17:31
#Acquired=	08.05.2020 17:31:53
#Data Range:Extract=	06.04.2022 14:33:06
#Base:Fit=	06.04.2022 14:33:15
#Base:Sub=	06.04.2022 14:34:05
#Correction:Shift=	06.04.2022 14:44:50
103.773	388.264
110.286	-103.93
116.795	-171.626
123.297	-146.562
129.795	-92.3678
136.287	-30.4506
142.774	46.6356
149.255	109.336
155.731	128.476
162.201	37.2106
168.667	-62.7677
175.125	-59.6976
181.58	52.3011
188.029	245.47
194.473	439.685
200.911	503.553
207.343	584.513
213.771	666.117
220.194	655.113
226.611	603.29
233.022	892.064
239.429	1136.14
245.83	886.974
252.225	609.497
258.616	539.206
265	683.911
271.381	989.892
277.756	1158.16
284.125	1166.07
290.489	1008.61
296.848	884.027
303.202	971.995
309.55	1259.18
315.894	1543.09
322.231	1695.71
328.563	1788.6
334.892	1812.07
341.213	1757.92
347.53	1628.71
353.843	1472.05
360.149	1228.55
366.451	1004.51
372.748	889.619
379.039	799.758
385.325	777.334
391.605	834.627
397.881	926.359
404.153	741.03
410.418	556
416.678	482.011
422.933	458.061
429.183	502.732
435.428	572.323
441.668	641.25
447.903	667.928
454.133	680.071
460.358	780.028
466.577	954.503
472.792	1134.27
479.001	1283.55
485.206	1404.67
491.406	1514.9
497.6	1540.06
503.788	1576.62
509.973	1616.51
516.152	1502.32
522.327	1332.66
528.496	1159.23
534.659	1012.54
540.819	875.265
546.974	764.571
553.123	668.283
559.267	593.727
565.406	560.488
571.54	567.961
577.669	647.52
583.794	943.739
589.913	954.907
596.028	818.039
602.137	647.279
608.242	518.331
614.341	474.623
620.436	547.602
626.526	786.137
632.611	983.738
638.691	1054.78
644.765	835.127
650.836	590.934
656.901	430.895
662.961	347.634
669.018	277.026
675.068	220.66
681.113	170.701
687.154	123.709
693.191	73.9771
699.222	29.5729
705.248	-6.95142
711.269	-33.1508
717.286	-49.3379
723.298	-57.1471
729.305	-60.1348
735.307	-61.3312
741.305	-60.7881
747.298	-58.2852
753.286	-53.6365
759.269	-46.7578
765.246	-38.1514
771.219	-29.4557
777.188	-20.8456
783.152	-10.2552
789.112	6.81726
795.066	28.0991
801.016	51.3528
806.961	80.6848
812.901	97.1252
818.836	105.491
824.767	105.443
830.694	96.6603
836.614	83.0865
842.531	76.171
848.443	77.8217
854.35	86.7966
860.253	89.7692
866.151	87.0898
872.043	69.6171
877.932	46.4392
883.815	22.5377
889.695	3.81702
895.569	-11.9553
901.439	-24.5228
907.304	-30.0918
913.165	-28.0792
919.02	-26.9244
924.871	-19.6075
930.718	-3.9126
936.56	23.8607
942.397	44.8202
948.23	75.1504
954.058	118.243
959.881	177.056
965.7	296.207
971.515	481.18
977.325	715.887
983.13	956.124
988.93	1060.48
994.726	1047.95
1000.52	1217
1006.3	1793.55
1012.09	2465.06
1017.87	2377.44
1023.64	1992.05
1029.41	2273.32
1035.17	2194.73
1040.93	1906.3
1046.69	1722.1
1052.44	1553.77
1058.18	1401.05
1063.92	1254.25
1069.66	1121.39
1075.39	978.917
1081.12	833.039
1086.85	697.982
1092.56	577.967
1098.28	536.702
1103.99	452.806
1109.7	440.071
1115.4	462.246
1121.09	565.271
1126.79	633.039
1132.47	599.852
1138.16	527.468
1143.84	425.063
1149.51	323.699
1155.18	213.707
1160.85	124.475
1166.51	104.439
1172.17	93.8319
1177.82	138.101
1183.47	191.011
1189.11	206.054
1194.75	207.511
1200.38	186.538
1206.01	165.532
1211.64	147.236
1217.26	145.893
1222.88	138.039
1228.49	122.719
1234.1	97.819
1239.71	60.1012
1245.31	23.6351
1250.9	-8.60681
1256.5	-34.1127
1262.08	-51.9951
1267.67	-61.2966
1273.24	-59.6171
1278.82	-55.9319
1284.39	-52.7941
1289.95	-50.7753
1295.51	-50.2469
1301.07	-48.3558
1306.62	-45.0468
1312.17	-41.1664
1317.72	-36.9993
1323.26	-32.8007
1328.79	-29.5902
1334.32	-27.29
1339.85	-23.9607
1345.38	-20.0476
1350.89	-16.7011
1356.41	-12.3513
1361.92	-6.88043
1367.42	-1.80005
1372.93	2.24023
1378.42	5.14825
1383.92	6.98828
1389.41	7.65894
1394.89	6.27484
1400.37	2.34747
1405.85	0.358154
1411.32	0.685425
1416.79	2.32587
1422.25	3.50647
1427.71	3.65021
1433.17	0.806763
1438.62	-4.5752
1444.07	-9.41577
1449.51	-13.4517
1454.95	-16.6042
1460.38	-18.7548
1465.81	-19.8781
1471.24	-19.2444
1476.66	-17.1794
1482.08	-14.0193
1487.49	-10.6067
1492.9	-6.75092
1498.31	-2.9635
1503.71	-0.499817
1509.11	0
1514.5	1.09882
1519.89	4.49237
1525.28	10.8057
1530.66	15.9507
1536.03	16.7836
1541.41	23.7879
1546.78	33.3133
1552.14	40.4304
1557.5	44.5807
1562.86	50.6465
1568.21	55.9334
1573.56	57.099
1578.91	55.371
1584.25	50.3488
1589.58	41.6968
1594.92	33.4536
1600.24	27.53
1605.57	23.1121
1610.89	20.1401
1616.2	17.311
1621.52	13.5541
1626.83	8.55609
1632.13	2.78558
1637.43	-2.13092
1642.73	-5.41888
1648.02	-7.35315
1653.31	-8.1264
1658.59	-8.21973
1663.87	-7.86774
1669.15	-8.09229
1674.42	-7.69916
1679.69	-7.44281
1684.95	-7.31958
1690.22	-8.20026
1695.47	-11.3049
1700.73	-14.5112
1705.97	-16.981
1711.22	-18.6548
1716.46	-19.387
1721.7	-19.3754
1726.93	-18.7127
1732.16	-18.4481
1737.38	-19.6008
1742.61	-23.1753
1747.82	-25.9341
1753.04	-30.0901
1758.25	-34.1627
1763.45	-37.6446
1768.65	-41.4604
1773.85	-46.7497
1779.05	-52.4996
1784.24	-56.9446
1789.42	-59.2878
1794.6	-58.1006
1799.78	-54.3412
1804.96	-51.0447
1810.13	-48.1976
1815.3	-47.6214
1820.46	-48.174
1825.62	-50.5118
1830.77	-52.5936
1835.93	-57.5185
1841.07	-60.7375
1846.22	-62.1962
1851.36	-61.4438
1856.49	-59.2563
1861.63	-56.1334
1866.76	-52.6782
1871.88	-48.7362
1877	-44.4477
1882.12	-41.6563
1887.23	-40.7162
1892.34	-39.8151
1897.45	-38.449
1902.55	-36.7249
1907.65	-36.8333
1912.74	-38.1674
1917.84	-38.1098
1922.92	-40.1104
1928.01	-43.0982
1933.09	-45.8206
1938.16	-46.9534
1943.23	-46.327
1948.3	-41.6059
1953.37	-38.0417
1958.43	-36.781
1963.49	-37.4747
1968.54	-42.5648
1973.59	-48.8255
1978.63	-52.6025
1983.68	-52.3311
1988.72	-47.5005
1993.75	-42.0207
1998.78	-38.7388
2003.81	-37.2405
2008.83	-35.8514
2013.85	-34.5662
2018.87	-33.6725
2023.88	-33.7757
2028.89	-32.6819
2033.9	-32.3475
2038.9	-32.1244
2043.9	-32.1453
2048.89	-31.5264
2053.88	-28.6855
2058.87	-23.4437
2063.85	-19.8298
2068.83	-20.1058
2073.81	-20.5646
2078.78	-23.1746
2083.75	-19.049
2088.72	-11.9602
2093.68	-17.689
2098.64	-17.387
2103.59	-13.1474
2108.54	-9.20941
2113.49	-5.86249
2118.43	-3.13904
2123.37	-1.02661
2128.31	0.471802
2133.24	1.25555
2138.17	1.18933
2143.1	0.303955
2148.02	-0.249634
2152.94	-1.28717
2157.85	-4.74695
2162.77	-8.07263
2167.67	-11.7237
2172.58	-12.3036
2177.48	-12.5229
2182.38	-14.8695
2187.27	-18.304
2192.16	-21.1023
2197.05	-23.9444
2201.93	-26.756
2206.81	-29.8146
2211.68	-32.5178
2216.56	-34.4936
2221.43	-34.4489
2226.29	-34.5023
2231.15	-34.7941
2236.01	-34.3613
2240.87	-33.56
2245.72	-35.3087
2250.57	-38.9156
2255.41	-40.3242
2260.25	-40.4725
2265.09	-39.5386
2269.92	-38.1362
2274.75	-38.1817
2279.58	-39.0214
2284.4	-39.7893
2289.22	-40.4404
2294.04	-41.0557
2298.85	-41.7224
2303.66	-42.397
2308.47	-41.5272
2313.27	-40.5458
2318.07	-41.2012
2322.87	-43.7621
2327.66	-47.9071
2332.45	-52.8649
2337.23	-57.0012
2342.01	-59.9639
2346.79	-59.9884
2351.57	-56.9094
2356.34	-54.0041
2361.11	-51.8214
2365.87	-50.7297
2370.64	-50.3943
2375.39	-50.8082
2380.15	-51.8117
2384.9	-53.2216
2389.65	-54.7
2394.39	-55.5692
2399.13	-55.4029
2403.87	-54.2596
2408.61	-52.0995
2413.34	-49.1984
2418.06	-46.3787
2422.79	-44.5502
2427.51	-44.213
2432.23	-44.1475
2436.94	-44.1522
2441.65	-43.8168
2446.36	-43.4775
2451.06	-43.1671
2455.77	-43.0137
2460.46	-42.3268
2465.16	-41.9301
2469.85	-42.1177
2474.54	-45.1127
2479.22	-50.5973
2483.9	-51.9402
2488.58	-53.1835
2493.25	-53.9054
2497.92	-51.4945
2502.59	-47.7913
2507.26	-44.9591
2511.92	-43.0532
2516.57	-44.5981
2521.23	-46.0697
2525.88	-47.4111
2530.53	-48.2246
2535.17	-47.4283
2539.81	-47.0283
2544.45	-47.8533
2549.09	-49.522
2553.72	-54.1169
2558.35	-59.4004
2562.97	-63.0356
2567.59	-62.5931
2572.21	-51.8081
2576.83	-43.5562
2581.44	-42.4528
2586.05	-42.3488
2590.65	-45.746
2595.25	-46.347
2599.85	-45.2841
2604.45	-43.8728
2609.04	-41.7588
2613.63	-39.2558
2618.22	-37.5774
2622.8	-39.4467
2627.38	-43.9888
2631.95	-47.6702
2636.53	-49.0613
2641.1	-48.2329
2645.67	-45.3802
2650.23	-47.7534
2654.79	-50.5909
2659.35	-49.0526
2663.9	-43.5118
2668.45	-32.7139
2673	-32.8832
2677.54	-37.002
2682.08	-41.186
2686.62	-44.2452
2691.16	-45.459
2695.69	-45.2482
2700.22	-40.6658
2704.74	-40.579
2709.27	-38.9552
2713.78	-40.58
2718.3	-40.8233
2722.81	-42.6535
2727.32	-45.5484
2731.83	-48.2718
2736.33	-50.8563
2740.83	-50.3278
2745.33	-48.6116
2749.82	-45.7368
2754.32	-44.1044
2758.8	-51.8383
2763.29	-57.1481
2767.77	-59.2876
2772.25	-58.2548
2776.72	-55.31
2781.2	-51.453
2785.67	-46.8242
2790.13	-44.0099
2794.59	-43.2972
2799.05	-43.5696
2803.51	-44.4017
2807.96	-43.248
2812.41	-41.1788
2816.86	-41.2716
2821.31	-42.3333
2825.75	-46.3989
2830.19	-52.7017
2834.62	-60.8287
2839.05	-63.9354
2843.48	-60.028
2847.91	-55.7067
2852.33	-53.5366
2856.75	-57.3476
2861.17	-60.3509
2865.58	-59.8266
2869.99	-58.7498
2874.4	-57.2881
2878.81	-54.9386
2883.21	-55.2526
2887.61	-58.1622
2892	-59.6745
2896.4	-59.0369
2900.78	-56.8757
2905.17	-54.1794
2909.56	-57.5303
2913.94	-59.4299
2918.31	-57.2708
2922.69	-53.2851
2927.06	-51.9797
2931.43	-49.2443
2935.79	-47.711
2940.16	-53.2985
2944.52	-54.2993
2948.87	-53.8339
2953.23	-53.5935
2957.58	-53.7668
2961.92	-55.1014
2966.27	-54.6922
2970.61	-55.8759
2974.95	-56.6814
2979.29	-55.0154
2983.62	-52.2914
2987.95	-54.2764
2992.28	-58.5456
2996.6	-62.1512
3000.92	-60.929
3005.24	-54.7637
3009.55	-46.8344
3013.87	-43.5228
3018.18	-44.6725
3022.48	-50.2217
3026.78	-54.5681
3031.09	-58.0219
3035.38	-60.015
3039.68	-57.8864
3043.97	-49.0167
3048.26	-51.3998
3052.54	-50.8982
3056.83	-47.8887
3061.11	-44.9769
3065.39	-42.8326
3069.66	-47.2761
3073.93	-54.6885
3078.2	-60.0031
3082.46	-59.738
3086.73	-55.696
3090.99	-51.5458
3095.24	-49.0337
3099.5	-46.1952
3103.75	-43.0126
3108	-42.6776
3112.24	-47.7129
3116.49	-51.5263
3120.73	-51.8918
3124.96	-49.8494
3129.2	-47.237
3133.43	-44.9107
3137.66	-41.9993
3141.88	-38.2772
3146.1	-35.9645
3150.32	-34.8574
3154.54	-34.1954
3158.75	-33.3054
3162.97	-31.7182
3167.17	-29.3392
3171.38	-23.5624
3175.58	-20.5331
3179.78	-20.8497
3183.98	-21.1299
3188.17	-20.5347
3192.36	-19.4201
3196.55	-16.9968
3200.74	-12.2632
3204.92	-4.49817
3209.1	3.84589
3213.28	12.011
3217.45	24.9493
3221.63	43.5558
3225.79	67.5483
3229.96	82.8124
3234.12	117.37
3238.28	164.509
3242.44	212.121
3246.6	244.371
3250.75	263.512
3254.9	274.11
3259.05	274.446
3263.19	271.077
3267.33	264.987
3271.47	252.565
3275.6	235.859
3279.74	214.276
3283.87	184.092
3288	151.895
3292.12	123.538
3296.24	97.7584
3300.36	69.7316
3304.48	45.3755
3308.59	26.2574
3312.7	16.8224
3316.81	2.16241
3320.92	-7.83997
3325.02	-7.68597
3329.12	-2.97394
3333.21	-11.1629
3337.31	-20.7804
3341.4	-29.736
3345.49	-36.5118
3349.58	-37.5753
3353.66	-39.6678
3357.74	-38.224
3361.82	-31.748
3365.9	-28.4985
3369.97	-28.2333
3374.04	-27.5975
3378.11	-33.7513
3382.17	-41.0174
3386.23	-44.327
3390.29	-41.5382
3394.35	-41.0686
3398.4	-38.7306
3402.45	-35.7772
3406.5	-31.7197
3410.55	-32.0441
3414.59	-31.6918
3418.63	-30.7462
3422.67	-34.0601
3426.71	-39.6512
3430.74	-43.3811
3434.77	-45.7804
3438.8	-43.2912
3442.82	-39.8828
3446.84	-42.592
3450.86	-49.8788
3454.88	-54.8692
3458.89	-59.0504
3462.9	-61.0723
3466.91	-60.1248
3470.92	-56.1259
3474.92	-54.6469
3478.92	-55.9652
3482.92	-50.6462
3486.92	-54.3537
3490.91	-59.0904
3494.9	-66.1961
3498.89	-62.7093
3502.88	-56.6392
3506.86	-56.7943
3510.84	-58.597
3514.82	-56.6653
3518.79	-54.5901
3522.76	-53.5018
3526.73	-53.4579
3530.7	-52.3172
3534.66	-50.9972
3538.63	-48.8955
3542.58	-48.8851
3546.54	-48.6045
3550.5	-45.8397
3554.45	-43.7946
3558.4	-41.456
3562.34	-38.7859
3566.29	-35.6409
3570.23	-29.5923
3574.17	-26.5451
3578.1	0.646667
3582.04	21.723
3585.97	64.5643
3589.89	150.502
3593.82	418.692
3597.74	1061.28
3601.66	1354.1
3605.58	822.089
3609.5	300.823
3613.41	163.006
3617.32	83.8093
3621.23	27.8543
3625.13	-7.27808
3629.04	-31.9687
3632.94	-40.9498
3636.84	-45.9621
3640.73	-51.8832
3644.62	-56.7155
3648.51	-54.0333
3652.4	-52.1376
3656.29	-53.4552
3660.17	-57.7514
3664.05	-58.2072
3667.93	-57.6826
3671.8	-56.5807
3675.68	-54.1975
3679.55	-55.4344
3683.41	-57.9597
3687.28	-59.0319
3691.14	-60.0275
3695	-59.7622
3698.86	-56.7716
3702.71	-54.7018
3706.57	-54.9684
3710.42	-54.9242
3714.27	-54.366
3718.11	-55.0088
3721.95	-53.7632
3725.79	-51.2423
3729.63	-50.3309
3733.47	-49.993
3737.3	-50.5561
3741.13	-49.9914
3744.96	-47.1754
3748.78	-49.894
3752.61	-51.4978
3756.43	-51.0651
3760.25	-50.413
3764.06	-50.6659
3767.88	-49.3337
3771.69	-45.9846
3775.5	-44.6872
3779.3	-48.3729
3783.1	-52.4587
3786.91	-63.8344
3790.7	-62.7049
3794.5	-57.3952
3798.29	-48.6075
3802.08	-47.8351
3805.87	-42.366
3809.66	-45.821
3813.44	-47.6547
3817.23	-47.2261
3821.01	-41.8573
3824.78	-35.1181
3828.56	-41.2781
3832.33	-46.1731
3836.1	-48.9423
3839.87	-48.3592
3843.63	-45.213
3847.39	-40.6831
3851.15	-37.5464
3854.91	-38.0896
3858.67	-37.4954
3862.42	-35.311
3866.17	-34.5509
3869.92	-32.9599
3873.66	-34.2493
3877.41	-34.1794
3881.15	-34.3014
3884.89	-35.8038
3888.62	-36.5285
3892.36	-39.0807
3896.09	-42.0556
3899.82	-45.2836
3903.54	-47.405
3907.27	-44.3158
3910.99	-40.0817
3914.71	-38.8839
3918.43	-41.524
3922.14	-45.409
3925.85	-49.9366
3929.56	-54.9875
3933.27	-57.3836
3936.98	-59.065
3940.68	-59.68
3944.38	-58.2274
3948.08	-56.6262
3951.78	-58.6927
3955.47	-59.1007
3959.16	-60.0995
3962.85	-62.6501
3966.54	-61.4595
3970.22	-60.2199
3973.9	-59.4716
3977.58	-58.8978
3981.26	-57.6172
3984.94	-61.219
3988.61	-63.2585
3992.28	-62.8355
3995.95	-65.1314
3999.61	-73.7328